t_recv,kind,type,name,detail
0.0264,Node,ADDED,kind-control-plane,taints=1
0.0315,Node,ADDED,kind-worker,taints=0
0.0328,Node,ADDED,kind-worker2,taints=0
0.0341,Node,ADDED,kind-worker3,taints=0
0.0354,Node,ADDED,kind-worker4,taints=0
0.0367,Node,ADDED,kind-worker5,taints=0
0.0472,TaskRequest,ADDED,eval-conflicts-rho020-r7-000,phase=None job=None
0.051,TaskRequest,MODIFIED,eval-conflicts-rho020-r7-000,phase=Pending job=None
0.0663,Job,ADDED,eval-conflicts-rho020-r7-000,
0.0688,Event,ADDED,eval-conflicts-rho005-r0-019-4hkwr.18d464fe7e22dffc,"reason=FailedScheduling count=None msg=0/6 nodes are available: 1 c_wall violated: 1 conflicting context pair(s) with node memory, 5 node(s) had untolerated taint(s). no new claims to deallocate, preemption: 0/6 nodes are available: 1 No preemption victims found for incoming pod, 5 Preemption is not helpful for scheduling."
0.0697,Event,ADDED,eval-conflicts-rho005-r0-023-fjlcb.18d464ff709d92ad,"reason=FailedScheduling count=None msg=0/6 nodes are available: 1 c_wall violated: 1 conflicting context pair(s) with node memory, 5 node(s) had untolerated taint(s). no new claims to deallocate, preemption: 0/6 nodes are available: 1 No preemption victims found for incoming pod, 5 Preemption is not helpful for scheduling."
0.0701,Event,ADDED,eval-conflicts-rho005-r0-027-ds6bj.18d4650060790d9c,"reason=FailedScheduling count=None msg=0/6 nodes are available: 1 c_wall violated: 1 conflicting context pair(s) with node memory, 5 node(s) had untolerated taint(s). no new claims to deallocate, preemption: 0/6 nodes are available: 1 No preemption victims found for incoming pod, 5 Preemption is not helpful for scheduling."
0.0703,Event,ADDED,eval-conflicts-rho005-r0-027-ds6bj.18d4650097d065c8,"reason=FailedScheduling count=None msg=0/6 nodes are available: 1 c_wall violated: 2 conflicting context pair(s) with node memory, 5 node(s) had untolerated taint(s). no new claims to deallocate, preemption: 0/6 nodes are available: 1 No preemption victims found for incoming pod, 5 Preemption is not helpful for scheduling."
0.0704,TaskRequest,MODIFIED,eval-conflicts-rho020-r7-000,phase=Scheduled job=None
0.0712,Event,ADDED,eval-conflicts-rho005-r0-061-pnqk4.18d4650845afd151,reason=Scheduled count=None msg=Successfully assigned compute/eval-conflicts-rho005-r0-061-pnqk4 to kind-worker4
0.0716,Event,ADDED,eval-conflicts-rho005-r0-062-x6bfx.18d46508801105a4,reason=Scheduled count=None msg=Successfully assigned compute/eval-conflicts-rho005-r0-062-x6bfx to kind-worker4
0.0719,Event,ADDED,eval-conflicts-rho005-r0-063-kczx5.18d46508bc066969,reason=Scheduled count=None msg=Successfully assigned compute/eval-conflicts-rho005-r0-063-kczx5 to kind-worker5
0.0723,Event,ADDED,eval-conflicts-rho005-r0-064-bch9f.18d46508f7448fcc,reason=Scheduled count=None msg=Successfully assigned compute/eval-conflicts-rho005-r0-064-bch9f to kind-worker4
0.0724,Event,ADDED,eval-conflicts-rho005-r0-065-g77tb.18d4650932cd1247,reason=Scheduled count=None msg=Successfully assigned compute/eval-conflicts-rho005-r0-065-g77tb to kind-worker3
0.0726,Event,ADDED,eval-conflicts-rho005-r0-066-k48g2.18d465096eab3624,reason=Scheduled count=None msg=Successfully assigned compute/eval-conflicts-rho005-r0-066-k48g2 to kind-worker
0.0727,Event,ADDED,eval-conflicts-rho005-r0-067-8rbjq.18d46509aab3aba6,reason=Scheduled count=None msg=Successfully assigned compute/eval-conflicts-rho005-r0-067-8rbjq to kind-worker
0.0733,Event,ADDED,eval-conflicts-rho005-r0-068-9h654.18d46509e6256171,reason=Scheduled count=None msg=Successfully assigned compute/eval-conflicts-rho005-r0-068-9h654 to kind-worker
0.0738,Event,ADDED,eval-conflicts-rho005-r0-069-2gq4l.18d4650a22237c43,reason=Scheduled count=None msg=Successfully assigned compute/eval-conflicts-rho005-r0-069-2gq4l to kind-worker
0.0741,Event,ADDED,eval-conflicts-rho005-r0-070-gbrrg.18d4650a5e8b730a,reason=Scheduled count=None msg=Successfully assigned compute/eval-conflicts-rho005-r0-070-gbrrg to kind-worker
0.0743,Event,ADDED,eval-conflicts-rho005-r0-071-ckxhl.18d4650a98bd3cb6,reason=Scheduled count=None msg=Successfully assigned compute/eval-conflicts-rho005-r0-071-ckxhl to kind-worker3
0.0748,Event,ADDED,eval-conflicts-rho005-r0-072-66m8b.18d4650ad4a46704,reason=Scheduled count=None msg=Successfully assigned compute/eval-conflicts-rho005-r0-072-66m8b to kind-worker
0.075,Event,ADDED,eval-conflicts-rho005-r0-073-bdltg.18d4650b10d35b55,reason=Scheduled count=None msg=Successfully assigned compute/eval-conflicts-rho005-r0-073-bdltg to kind-worker
0.0754,Event,ADDED,eval-conflicts-rho005-r0-073.18d4650e6314d681,reason=Completed count=1 msg=Job completed
0.0769,Pod,ADDED,eval-conflicts-rho020-r7-000-dmf94,phase=Pending node=None
0.0772,Event,ADDED,eval-conflicts-rho005-r0-074-vthbv.18d4650b4bb024a1,reason=Scheduled count=None msg=Successfully assigned compute/eval-conflicts-rho005-r0-074-vthbv to kind-worker3
0.0774,Event,ADDED,eval-conflicts-rho005-r0-074.18d4650ea2aa0bf0,reason=Completed count=1 msg=Job completed
0.0775,Event,ADDED,eval-conflicts-rho005-r0-075-j7nb8.18d4650b885b2d98,reason=Scheduled count=None msg=Successfully assigned compute/eval-conflicts-rho005-r0-075-j7nb8 to kind-worker
0.0777,Event,ADDED,eval-conflicts-rho005-r0-075.18d4650edb0890b9,reason=Completed count=1 msg=Job completed
0.0779,Event,ADDED,eval-conflicts-rho005-r0-076-5qdcs.18d4650bc2171e3b,"reason=FailedScheduling count=None msg=0/6 nodes are available: 6 node(s) had untolerated taint(s). no new claims to deallocate, preemption: 0/6 nodes are available: 6 Preemption is not helpful for scheduling."
0.0781,Event,ADDED,eval-conflicts-rho005-r0-076-5qdcs.18d4650bfc97615d,reason=Scheduled count=None msg=Successfully assigned compute/eval-conflicts-rho005-r0-076-5qdcs to kind-worker4
0.0783,Event,ADDED,eval-conflicts-rho005-r0-076.18d4650f5bf2cf77,reason=Completed count=1 msg=Job completed
0.0784,Event,ADDED,eval-conflicts-rho005-r0-077-jdd6h.18d4650bfe009f8c,"reason=FailedScheduling count=None msg=0/6 nodes are available: 1 c_wall violated: 1 conflicting context pair(s) with node memory, 5 node(s) had untolerated taint(s). no new claims to deallocate, preemption: 0/6 nodes are available: 1 No preemption victims found for incoming pod, 5 Preemption is not helpful for scheduling."
0.0787,Event,ADDED,eval-conflicts-rho005-r0-077-jdd6h.18d4650bfe9e23e5,"reason=FailedScheduling count=None msg=0/6 nodes are available: 1 c_wall violated: 1 conflicting context pair(s) with node memory, 5 node(s) had untolerated taint(s). no new claims to deallocate, preemption: 0/6 nodes are available: 1 No preemption victims found for incoming pod, 5 Preemption is not helpful for scheduling."
0.0789,Event,ADDED,eval-conflicts-rho005-r0-077-jdd6h.18d4650ccebfd5a5,reason=Scheduled count=None msg=Successfully assigned compute/eval-conflicts-rho005-r0-077-jdd6h to kind-worker2
0.0791,Event,ADDED,eval-conflicts-rho005-r0-077.18d4650ff2cf14fc,reason=Completed count=1 msg=Job completed
0.0795,Event,ADDED,eval-conflicts-rho005-r0-078-76f9q.18d4650c3a272232,reason=Scheduled count=None msg=Successfully assigned compute/eval-conflicts-rho005-r0-078-76f9q to kind-worker4
0.0797,Event,ADDED,eval-conflicts-rho005-r0-078.18d4650f980dac5b,reason=Completed count=1 msg=Job completed
0.0799,Event,ADDED,eval-conflicts-rho005-r0-079-9csz2.18d4650c75d8bcad,reason=Scheduled count=None msg=Successfully assigned compute/eval-conflicts-rho005-r0-079-9csz2 to kind-worker4
0.08,Event,ADDED,eval-conflicts-rho005-r0-079.18d4650fd3d44e6a,reason=Completed count=1 msg=Job completed
0.0808,Job,MODIFIED,eval-conflicts-rho020-r7-000,
0.0811,Event,ADDED,eval-conflicts-rho005-r0-080-6nt5s.18d4650cb101565b,"reason=FailedScheduling count=None msg=0/6 nodes are available: 1 c_wall violated: 1 conflicting context pair(s) with node memory, 5 node(s) had untolerated taint(s). no new claims to deallocate, preemption: 0/6 nodes are available: 1 No preemption victims found for incoming pod, 5 Preemption is not helpful for scheduling."
0.0814,Event,ADDED,eval-conflicts-rho005-r0-080-6nt5s.18d4650cb1847a32,"reason=FailedScheduling count=None msg=0/6 nodes are available: 1 c_wall violated: 1 conflicting context pair(s) with node memory, 5 node(s) had untolerated taint(s). no new claims to deallocate, preemption: 0/6 nodes are available: 1 No preemption victims found for incoming pod, 5 Preemption is not helpful for scheduling."
0.0816,Event,ADDED,eval-conflicts-rho005-r0-080-6nt5s.18d4650ccf28de7c,reason=Scheduled count=None msg=Successfully assigned compute/eval-conflicts-rho005-r0-080-6nt5s to kind-worker2
0.0818,TaskRequest,MODIFIED,eval-conflicts-rho020-r7-000,phase=Scheduled job=None
0.0821,Event,ADDED,eval-conflicts-rho005-r0-080.18d465102e54364a,reason=Completed count=1 msg=Job completed
0.0823,Event,ADDED,eval-conflicts-rho005-r0-081-tbpg9.18d4650cecc17815,reason=Scheduled count=None msg=Successfully assigned compute/eval-conflicts-rho005-r0-081-tbpg9 to kind-worker2
0.0825,Event,ADDED,eval-conflicts-rho005-r0-081.18d465102e298173,reason=Completed count=1 msg=Job completed
0.0826,Event,ADDED,eval-conflicts-rho005-r0-082-lmfq6.18d4650d28b01d30,reason=Scheduled count=None msg=Successfully assigned compute/eval-conflicts-rho005-r0-082-lmfq6 to kind-worker4
0.0829,Event,ADDED,eval-conflicts-rho005-r0-082.18d4651087c58290,reason=Completed count=1 msg=Job completed
0.0832,Event,ADDED,eval-conflicts-rho005-r0-083-bw7p2.18d4650d64a5d805,reason=Scheduled count=None msg=Successfully assigned compute/eval-conflicts-rho005-r0-083-bw7p2 to kind-worker2
0.0837,Event,ADDED,eval-conflicts-rho005-r0-083.18d465106a34f245,reason=Completed count=1 msg=Job completed
0.084,Event,ADDED,eval-conflicts-rho005-r0-084-p27ws.18d4650da017ff90,reason=Scheduled count=None msg=Successfully assigned compute/eval-conflicts-rho005-r0-084-p27ws to kind-worker5
0.0842,Event,ADDED,eval-conflicts-rho005-r0-084.18d46511019787ac,reason=Completed count=1 msg=Job completed
0.0843,Event,ADDED,eval-conflicts-rho005-r0-085-5rtlm.18d4650ddbbd33c8,reason=Scheduled count=None msg=Successfully assigned compute/eval-conflicts-rho005-r0-085-5rtlm to kind-worker5
0.0845,Event,ADDED,eval-conflicts-rho005-r0-085.18d465113d5d5da1,reason=Completed count=1 msg=Job completed
0.0848,Event,ADDED,eval-conflicts-rho005-r0-086-npssb.18d4650e17c1788c,reason=Scheduled count=None msg=Successfully assigned compute/eval-conflicts-rho005-r0-086-npssb to kind-worker5
0.085,Event,ADDED,eval-conflicts-rho005-r0-086.18d4651179a02e04,reason=Completed count=1 msg=Job completed
0.0852,Event,ADDED,eval-conflicts-rho005-r0-087-2rd6m.18d4650e5293178b,reason=Scheduled count=None msg=Successfully assigned compute/eval-conflicts-rho005-r0-087-2rd6m to kind-worker5
0.0853,Event,ADDED,eval-conflicts-rho005-r0-087-2rd6m.18d4650e6bc20514,"reason=Pulled count=1 msg=Container image ""busybox:musl"" already present on machine"
0.0859,Event,ADDED,eval-conflicts-rho005-r0-087-2rd6m.18d4650e6cdc865c,reason=Created count=1 msg=Created container: task
0.0861,Event,ADDED,eval-conflicts-rho005-r0-087-2rd6m.18d4650e6edaf7be,reason=Started count=1 msg=Started container task
0.0863,Event,ADDED,eval-conflicts-rho005-r0-087.18d46511b5840430,reason=Completed count=1 msg=Job completed
0.0866,Event,ADDED,eval-conflicts-rho005-r0-088-79zml.18d4650e8e3142a1,reason=Scheduled count=None msg=Successfully assigned compute/eval-conflicts-rho005-r0-088-79zml to kind-worker5
0.0868,Event,ADDED,eval-conflicts-rho005-r0-088-79zml.18d4650ea6f9093f,"reason=Pulled count=1 msg=Container image ""busybox:musl"" already present on machine"
0.087,Event,ADDED,eval-conflicts-rho005-r0-088-79zml.18d4650ea864048e,reason=Created count=1 msg=Created container: task
0.0871,Event,ADDED,eval-conflicts-rho005-r0-088-79zml.18d4650ead10b189,reason=Started count=1 msg=Started container task
0.088,Event,ADDED,eval-conflicts-rho005-r0-088.18d4650e8d551026,reason=SuccessfulCreate count=1 msg=Created pod: eval-conflicts-rho005-r0-088-79zml
0.0882,Event,ADDED,eval-conflicts-rho005-r0-088.18d46511f1cd328a,reason=Completed count=1 msg=Job completed
0.0885,Event,ADDED,eval-conflicts-rho005-r0-089-m85tr.18d4650ec9e2cc91,reason=Scheduled count=None msg=Successfully assigned compute/eval-conflicts-rho005-r0-089-m85tr to kind-worker2
0.0887,Event,ADDED,eval-conflicts-rho005-r0-089-m85tr.18d4650ee3193cc5,"reason=Pulled count=1 msg=Container image ""busybox:musl"" already present on machine"
0.089,Event,ADDED,eval-conflicts-rho005-r0-089-m85tr.18d4650ee4b5f9cd,reason=Created count=1 msg=Created container: task
0.0893,Event,ADDED,eval-conflicts-rho005-r0-089-m85tr.18d4650ee8f69377,reason=Started count=1 msg=Started container task
0.0895,Event,ADDED,eval-conflicts-rho005-r0-089.18d4650ec8ecdd4c,reason=SuccessfulCreate count=1 msg=Created pod: eval-conflicts-rho005-r0-089-m85tr
0.0905,Pod,MODIFIED,eval-conflicts-rho020-r7-000-dmf94,phase=Pending node=kind-worker5
0.0908,Event,ADDED,eval-conflicts-rho005-r0-089.18d465120d14364f,reason=Completed count=1 msg=Job completed
0.0909,Event,ADDED,eval-conflicts-rho005-r0-090-m48ht.18d4650f060d9fe0,reason=Scheduled count=None msg=Successfully assigned compute/eval-conflicts-rho005-r0-090-m48ht to kind-worker2
0.0911,Event,ADDED,eval-conflicts-rho005-r0-090-m48ht.18d4650f1ea6363d,"reason=Pulled count=1 msg=Container image ""busybox:musl"" already present on machine"
0.0913,Event,ADDED,eval-conflicts-rho005-r0-090-m48ht.18d4650f2000bf68,reason=Created count=1 msg=Created container: task
0.0917,Event,ADDED,eval-conflicts-rho005-r0-090-m48ht.18d4650f24a024a4,reason=Started count=1 msg=Started container task
0.0919,Event,ADDED,eval-conflicts-rho005-r0-090.18d4650f052d8d3f,reason=SuccessfulCreate count=1 msg=Created pod: eval-conflicts-rho005-r0-090-m48ht
0.0921,Event,ADDED,eval-conflicts-rho005-r0-090.18d465124934d507,reason=Completed count=1 msg=Job completed
0.0925,Event,ADDED,eval-conflicts-rho005-r0-091-czqms.18d4650f409f1407,"reason=FailedScheduling count=None msg=0/6 nodes are available: 1 c_wall violated: 2 conflicting context pair(s) with node memory, 5 node(s) had untolerated taint(s). no new claims to deallocate, preemption: 0/6 nodes are available: 1 No preemption victims found for incoming pod, 5 Preemption is not helpful for scheduling."
0.0927,Event,ADDED,eval-conflicts-rho005-r0-091-czqms.18d4650f411bd9bc,"reason=FailedScheduling count=None msg=0/6 nodes are available: 1 c_wall violated: 2 conflicting context pair(s) with node memory, 5 node(s) had untolerated taint(s). no new claims to deallocate, preemption: 0/6 nodes are available: 1 No preemption victims found for incoming pod, 5 Preemption is not helpful for scheduling."
0.0928,Event,ADDED,eval-conflicts-rho005-r0-091-czqms.18d465101c040d1f,reason=Scheduled count=None msg=Successfully assigned compute/eval-conflicts-rho005-r0-091-czqms to kind-worker3
0.093,Event,ADDED,eval-conflicts-rho005-r0-091-czqms.18d4651036224ab8,"reason=Pulled count=1 msg=Container image ""busybox:musl"" already present on machine"
0.0933,Event,ADDED,eval-conflicts-rho005-r0-091-czqms.18d4651037326bf6,reason=Created count=1 msg=Created container: task
0.0935,Event,ADDED,eval-conflicts-rho005-r0-091-czqms.18d465103a550789,reason=Started count=1 msg=Started container task
0.0937,Event,ADDED,eval-conflicts-rho005-r0-091.18d4650f4055dddc,reason=SuccessfulCreate count=1 msg=Created pod: eval-conflicts-rho005-r0-091-czqms
0.0941,Event,ADDED,eval-conflicts-rho005-r0-091.18d465134dee677b,reason=Completed count=1 msg=Job completed
0.0942,Event,ADDED,eval-conflicts-rho005-r0-092-mfwb7.18d4650f7c21fe3a,reason=Scheduled count=None msg=Successfully assigned compute/eval-conflicts-rho005-r0-092-mfwb7 to kind-worker5
0.0944,Event,ADDED,eval-conflicts-rho005-r0-092-mfwb7.18d4650f955b2b27,"reason=Pulled count=1 msg=Container image ""busybox:musl"" already present on machine"
0.0946,Event,ADDED,eval-conflicts-rho005-r0-092-mfwb7.18d4650f966e5a3d,reason=Created count=1 msg=Created container: task
0.0949,Event,ADDED,eval-conflicts-rho005-r0-092-mfwb7.18d4650f9899df90,reason=Started count=1 msg=Started container task
0.0951,Event,ADDED,eval-conflicts-rho005-r0-092.18d4650f7b9fdfdc,reason=SuccessfulCreate count=1 msg=Created pod: eval-conflicts-rho005-r0-092-mfwb7
0.0953,Event,ADDED,eval-conflicts-rho005-r0-092.18d46512e040a9d9,reason=Completed count=1 msg=Job completed
0.0955,Event,ADDED,eval-conflicts-rho005-r0-093-wlpmg.18d4650fb82d373a,reason=Scheduled count=None msg=Successfully assigned compute/eval-conflicts-rho005-r0-093-wlpmg to kind-worker5
0.0957,Event,ADDED,eval-conflicts-rho005-r0-093-wlpmg.18d4650fd245846f,"reason=Pulled count=1 msg=Container image ""busybox:musl"" already present on machine"
0.0959,Event,ADDED,eval-conflicts-rho005-r0-093-wlpmg.18d4650fd3b9617b,reason=Created count=1 msg=Created container: task
0.096,Event,ADDED,eval-conflicts-rho005-r0-093-wlpmg.18d4650fd9c05a11,reason=Started count=1 msg=Started container task
0.0963,Event,ADDED,eval-conflicts-rho005-r0-093.18d4650fb79c56d2,reason=SuccessfulCreate count=1 msg=Created pod: eval-conflicts-rho005-r0-093-wlpmg
0.0965,Event,ADDED,eval-conflicts-rho005-r0-093.18d465131c2ae7a0,reason=Completed count=1 msg=Job completed
0.0967,Event,ADDED,eval-conflicts-rho005-r0-094-24qhz.18d4650ff3b5fc71,"reason=FailedScheduling count=None msg=0/6 nodes are available: 6 node(s) had untolerated taint(s). no new claims to deallocate, preemption: 0/6 nodes are available: 6 Preemption is not helpful for scheduling."
0.0976,Event,ADDED,eval-conflicts-rho005-r0-094-24qhz.18d465101be4657c,"reason=FailedScheduling count=None msg=0/6 nodes are available: 1 c_wall violated: 1 conflicting context pair(s) with node memory, 5 node(s) had untolerated taint(s). no new claims to deallocate, preemption: 0/6 nodes are available: 1 No preemption victims found for incoming pod, 5 Preemption is not helpful for scheduling."
0.0981,Event,ADDED,eval-conflicts-rho005-r0-094-24qhz.18d465101d004dbe,"reason=FailedScheduling count=None msg=0/6 nodes are available: 1 c_wall violated: 1 conflicting context pair(s) with node memory, 5 node(s) had untolerated taint(s). no new claims to deallocate, preemption: 0/6 nodes are available: 1 No preemption victims found for incoming pod, 5 Preemption is not helpful for scheduling."
0.0984,Event,ADDED,eval-conflicts-rho005-r0-094-24qhz.18d465108dc18ac8,reason=Scheduled count=None msg=Successfully assigned compute/eval-conflicts-rho005-r0-094-24qhz to kind-worker
0.0987,Event,ADDED,eval-conflicts-rho005-r0-094-24qhz.18d46510a7fda74d,"reason=Pulled count=1 msg=Container image ""busybox:musl"" already present on machine"
0.1004,Node,MODIFIED,kind-worker5,taints=0
0.1008,Event,ADDED,eval-conflicts-rho005-r0-094-24qhz.18d46510a965c0ca,reason=Created count=1 msg=Created container: task
0.101,Event,ADDED,eval-conflicts-rho005-r0-094-24qhz.18d46510adfde25b,reason=Started count=1 msg=Started container task
0.1011,Event,ADDED,eval-conflicts-rho005-r0-094.18d4650ff3a69048,reason=SuccessfulCreate count=1 msg=Created pod: eval-conflicts-rho005-r0-094-24qhz
0.1015,Event,ADDED,eval-conflicts-rho005-r0-094.18d46513c210b4a0,reason=Completed count=1 msg=Job completed
0.1017,Event,ADDED,eval-conflicts-rho005-r0-095-5q8h6.18d465102f46c9dc,"reason=FailedScheduling count=None msg=0/6 nodes are available: 1 c_wall violated: 1 conflicting context pair(s) with node memory, 5 node(s) had untolerated taint(s). no new claims to deallocate, preemption: 0/6 nodes are available: 1 No preemption victims found for incoming pod, 5 Preemption is not helpful for scheduling."
0.102,Event,ADDED,eval-conflicts-rho005-r0-095-5q8h6.18d465102fdee5c6,"reason=FailedScheduling count=None msg=0/6 nodes are available: 1 c_wall violated: 1 conflicting context pair(s) with node memory, 5 node(s) had untolerated taint(s). no new claims to deallocate, preemption: 0/6 nodes are available: 1 No preemption victims found for incoming pod, 5 Preemption is not helpful for scheduling."
0.1035,Pod,MODIFIED,eval-conflicts-rho020-r7-000-dmf94,phase=Pending node=kind-worker5
0.104,Event,ADDED,eval-conflicts-rho005-r0-095-5q8h6.18d465108e63f997,reason=Scheduled count=None msg=Successfully assigned compute/eval-conflicts-rho005-r0-095-5q8h6 to kind-worker
0.1043,Event,ADDED,eval-conflicts-rho005-r0-095-5q8h6.18d46510a85a3cfc,"reason=Pulled count=1 msg=Container image ""busybox:musl"" already present on machine"
0.1047,Event,ADDED,eval-conflicts-rho005-r0-095-5q8h6.18d46510a9c12507,reason=Created count=1 msg=Created container: task
0.1049,Event,ADDED,eval-conflicts-rho005-r0-095-5q8h6.18d46510adfde251,reason=Started count=1 msg=Started container task
0.1052,Event,ADDED,eval-conflicts-rho005-r0-095.18d465102f0aca5c,reason=SuccessfulCreate count=1 msg=Created pod: eval-conflicts-rho005-r0-095-5q8h6
0.1054,Event,ADDED,eval-conflicts-rho005-r0-095.18d46513c1eca996,reason=Completed count=1 msg=Job completed
0.1059,Event,ADDED,eval-conflicts-rho005-r0-096-v646d.18d465106af9d633,reason=Scheduled count=None msg=Successfully assigned compute/eval-conflicts-rho005-r0-096-v646d to kind-worker3
0.1061,Event,ADDED,eval-conflicts-rho005-r0-096-v646d.18d4651085db5d68,"reason=Pulled count=1 msg=Container image ""busybox:musl"" already present on machine"
0.1064,Event,ADDED,eval-conflicts-rho005-r0-096-v646d.18d4651086fbf0ae,reason=Created count=1 msg=Created container: task
0.1066,Event,ADDED,eval-conflicts-rho005-r0-096-v646d.18d465108b6917c3,reason=Started count=1 msg=Started container task
0.1068,Event,ADDED,eval-conflicts-rho005-r0-096.18d465106a59bf13,reason=SuccessfulCreate count=1 msg=Created pod: eval-conflicts-rho005-r0-096-v646d
0.1071,Event,ADDED,eval-conflicts-rho005-r0-096.18d46513c5393be6,reason=Completed count=1 msg=Job completed
0.1073,Event,ADDED,eval-conflicts-rho005-r0-097-w5vf8.18d46510a69d3a75,reason=Scheduled count=None msg=Successfully assigned compute/eval-conflicts-rho005-r0-097-w5vf8 to kind-worker
0.1075,Event,ADDED,eval-conflicts-rho005-r0-097-w5vf8.18d46510bfc4a55d,"reason=Pulled count=1 msg=Container image ""busybox:musl"" already present on machine"
0.1076,Event,ADDED,eval-conflicts-rho005-r0-097-w5vf8.18d46510c0d64f8f,reason=Created count=1 msg=Created container: task
0.1079,Event,ADDED,eval-conflicts-rho005-r0-097-w5vf8.18d46510c3dad691,reason=Started count=1 msg=Started container task
0.1081,Event,ADDED,eval-conflicts-rho005-r0-097.18d46510a574f0c7,reason=SuccessfulCreate count=1 msg=Created pod: eval-conflicts-rho005-r0-097-w5vf8
0.1083,Event,ADDED,eval-conflicts-rho005-r0-097.18d46513fdd6cb83,reason=Completed count=1 msg=Job completed
0.1085,Event,ADDED,eval-conflicts-rho005-r0-098-6z6jf.18d46510e2f24fc8,reason=Scheduled count=None msg=Successfully assigned compute/eval-conflicts-rho005-r0-098-6z6jf to kind-worker4
0.109,Event,ADDED,eval-conflicts-rho005-r0-098-6z6jf.18d46510fc6e21cf,"reason=Pulled count=1 msg=Container image ""busybox:musl"" already present on machine"
0.1095,Event,ADDED,eval-conflicts-rho005-r0-098-6z6jf.18d46510fd7cf029,reason=Created count=1 msg=Created container: task
0.1097,Event,ADDED,eval-conflicts-rho005-r0-098-6z6jf.18d4651101a7588a,reason=Started count=1 msg=Started container task
0.1101,Event,ADDED,eval-conflicts-rho005-r0-098.18d46510e1ea112a,reason=SuccessfulCreate count=1 msg=Created pod: eval-conflicts-rho005-r0-098-6z6jf
0.1103,Event,ADDED,eval-conflicts-rho005-r0-098.18d4651442b459ef,reason=Completed count=1 msg=Job completed
0.1104,Event,ADDED,eval-conflicts-rho005-r0-099-wlbl4.18d465111e25774a,reason=Scheduled count=None msg=Successfully assigned compute/eval-conflicts-rho005-r0-099-wlbl4 to kind-worker3
0.1106,Event,ADDED,eval-conflicts-rho005-r0-099-wlbl4.18d4651137ef3bf4,"reason=Pulled count=1 msg=Container image ""busybox:musl"" already present on machine"
0.1109,Event,ADDED,eval-conflicts-rho005-r0-099-wlbl4.18d46511390aa4ea,reason=Created count=1 msg=Created container: task
0.1111,Event,ADDED,eval-conflicts-rho005-r0-099-wlbl4.18d465113bcad671,reason=Started count=1 msg=Started container task
0.1113,Event,ADDED,eval-conflicts-rho005-r0-099.18d465111d3a3f4c,reason=SuccessfulCreate count=1 msg=Created pod: eval-conflicts-rho005-r0-099-wlbl4
0.1124,Node,MODIFIED,kind-worker5,taints=0
0.1127,Event,ADDED,eval-conflicts-rho005-r0-099.18d4651478a055c5,reason=Completed count=1 msg=Job completed
0.1128,Event,ADDED,eval-conflicts-rho005-r1-000-lvblz.18d46519a7c0df94,reason=Scheduled count=None msg=Successfully assigned compute/eval-conflicts-rho005-r1-000-lvblz to kind-worker5
0.113,Event,ADDED,eval-conflicts-rho005-r1-000-lvblz.18d46519c4a59834,"reason=Pulled count=1 msg=Container image ""busybox:musl"" already present on machine"
0.1132,Event,ADDED,eval-conflicts-rho005-r1-000-lvblz.18d46519c5df9f89,reason=Created count=1 msg=Created container: task
0.1135,Event,ADDED,eval-conflicts-rho005-r1-000-lvblz.18d46519ca4099f7,reason=Started count=1 msg=Started container task
0.1137,Event,ADDED,eval-conflicts-rho005-r1-000.18d46519a6c05cb0,reason=SuccessfulCreate count=1 msg=Created pod: eval-conflicts-rho005-r1-000-lvblz
0.1139,Event,ADDED,eval-conflicts-rho005-r1-000.18d4651caf618cfc,reason=Completed count=1 msg=Job completed
0.1141,Event,ADDED,eval-conflicts-rho005-r1-001-6r8kk.18d46519e2e420cf,reason=Scheduled count=None msg=Successfully assigned compute/eval-conflicts-rho005-r1-001-6r8kk to kind-worker
0.1143,Event,ADDED,eval-conflicts-rho005-r1-001-6r8kk.18d46519fcc25827,"reason=Pulled count=1 msg=Container image ""busybox:musl"" already present on machine"
0.1145,Event,ADDED,eval-conflicts-rho005-r1-001-6r8kk.18d46519fde0d6a1,reason=Created count=1 msg=Created container: task
0.1147,Event,ADDED,eval-conflicts-rho005-r1-001-6r8kk.18d46519ffeff9d7,reason=Started count=1 msg=Started container task
0.1149,Event,ADDED,eval-conflicts-rho005-r1-001.18d46519e1eb9892,reason=SuccessfulCreate count=1 msg=Created pod: eval-conflicts-rho005-r1-001-6r8kk
0.115,Event,ADDED,eval-conflicts-rho005-r1-001.18d4651d1ddf25ec,reason=Completed count=1 msg=Job completed
0.1152,Event,ADDED,eval-conflicts-rho005-r1-002-4mk7n.18d4651a1e03e7e1,reason=Scheduled count=None msg=Successfully assigned compute/eval-conflicts-rho005-r1-002-4mk7n to kind-worker5
0.1154,Event,ADDED,eval-conflicts-rho005-r1-002-4mk7n.18d4651a37755b8d,"reason=Pulled count=1 msg=Container image ""busybox:musl"" already present on machine"
0.1155,Event,ADDED,eval-conflicts-rho005-r1-002-4mk7n.18d4651a38cb827b,reason=Created count=1 msg=Created container: task
0.1157,Event,ADDED,eval-conflicts-rho005-r1-002-4mk7n.18d4651a3cb034ca,reason=Started count=1 msg=Started container task
0.1159,Event,ADDED,eval-conflicts-rho005-r1-002.18d4651a1d1a3a68,reason=SuccessfulCreate count=1 msg=Created pod: eval-conflicts-rho005-r1-002-4mk7n
0.116,Event,ADDED,eval-conflicts-rho005-r1-002.18d4651d62590e75,reason=Completed count=1 msg=Job completed
0.1162,Event,ADDED,eval-conflicts-rho005-r1-003-d8mkb.18d4651a5ace6f49,reason=Scheduled count=None msg=Successfully assigned compute/eval-conflicts-rho005-r1-003-d8mkb to kind-worker2
0.1164,Event,ADDED,eval-conflicts-rho005-r1-003-d8mkb.18d4651a766e6cfb,"reason=Pulled count=1 msg=Container image ""busybox:musl"" already present on machine"
0.1165,Event,ADDED,eval-conflicts-rho005-r1-003-d8mkb.18d4651a77c82e4f,reason=Created count=1 msg=Created container: task
0.1168,Event,ADDED,eval-conflicts-rho005-r1-003-d8mkb.18d4651a79da60bc,reason=Started count=1 msg=Started container task
0.1169,Event,ADDED,eval-conflicts-rho005-r1-003.18d4651a59c2c79e,reason=SuccessfulCreate count=1 msg=Created pod: eval-conflicts-rho005-r1-003-d8mkb
0.1171,Event,ADDED,eval-conflicts-rho005-r1-003.18d4651db850a2f8,reason=Completed count=1 msg=Job completed
0.1172,Event,ADDED,eval-conflicts-rho005-r1-004-xs6db.18d4651a95180235,reason=Scheduled count=None msg=Successfully assigned compute/eval-conflicts-rho005-r1-004-xs6db to kind-worker2
0.1175,Event,ADDED,eval-conflicts-rho005-r1-004-xs6db.18d4651aafb1a50f,"reason=Pulled count=1 msg=Container image ""busybox:musl"" already present on machine"
0.1177,Event,ADDED,eval-conflicts-rho005-r1-004-xs6db.18d4651ab0cc3c18,reason=Created count=1 msg=Created container: task
0.118,Event,ADDED,eval-conflicts-rho005-r1-004-xs6db.18d4651ab8605b30,reason=Started count=1 msg=Started container task
0.1184,Event,ADDED,eval-conflicts-rho005-r1-004.18d4651a940cdac4,reason=SuccessfulCreate count=1 msg=Created pod: eval-conflicts-rho005-r1-004-xs6db
0.1186,Event,ADDED,eval-conflicts-rho005-r1-004.18d4651df3d12936,reason=Completed count=1 msg=Job completed
0.1188,Event,ADDED,eval-conflicts-rho005-r1-005-dc6m8.18d4651ad0ae5cf2,reason=Scheduled count=None msg=Successfully assigned compute/eval-conflicts-rho005-r1-005-dc6m8 to kind-worker5
0.119,Event,ADDED,eval-conflicts-rho005-r1-005-dc6m8.18d4651aea2694a4,"reason=Pulled count=1 msg=Container image ""busybox:musl"" already present on machine"
0.1193,Event,ADDED,eval-conflicts-rho005-r1-005-dc6m8.18d4651aeb4f3b90,reason=Created count=1 msg=Created container: task
0.1194,Event,ADDED,eval-conflicts-rho005-r1-005-dc6m8.18d4651af334f034,reason=Started count=1 msg=Started container task
0.1196,Event,ADDED,eval-conflicts-rho005-r1-005.18d4651acfc6f3dd,reason=SuccessfulCreate count=1 msg=Created pod: eval-conflicts-rho005-r1-005-dc6m8
0.1198,Event,ADDED,eval-conflicts-rho005-r1-005.18d4651e1587d570,reason=Completed count=1 msg=Job completed
0.1202,Event,ADDED,eval-conflicts-rho005-r1-006-99j7w.18d4651b10a43a3d,reason=Scheduled count=None msg=Successfully assigned compute/eval-conflicts-rho005-r1-006-99j7w to kind-worker4
0.1204,Event,ADDED,eval-conflicts-rho005-r1-006-99j7w.18d4651b2b7cbdd5,"reason=Pulled count=1 msg=Container image ""busybox:musl"" already present on machine"
0.1205,Event,ADDED,eval-conflicts-rho005-r1-006-99j7w.18d4651b2c9b5408,reason=Created count=1 msg=Created container: task
0.1208,Event,ADDED,eval-conflicts-rho005-r1-006-99j7w.18d4651b331dc26b,reason=Started count=1 msg=Started container task
0.121,Event,ADDED,eval-conflicts-rho005-r1-006.18d4651b0fe7227b,reason=SuccessfulCreate count=1 msg=Created pod: eval-conflicts-rho005-r1-006-99j7w
0.1212,Event,ADDED,eval-conflicts-rho005-r1-006.18d4651e4c30d2b6,reason=Completed count=1 msg=Job completed
0.1213,Event,ADDED,eval-conflicts-rho005-r1-007-pgjl9.18d4651b48be54ca,reason=Scheduled count=None msg=Successfully assigned compute/eval-conflicts-rho005-r1-007-pgjl9 to kind-worker4
0.1215,Event,ADDED,eval-conflicts-rho005-r1-007-pgjl9.18d4651b6471a480,"reason=Pulled count=1 msg=Container image ""busybox:musl"" already present on machine"
0.1217,Event,ADDED,eval-conflicts-rho005-r1-007-pgjl9.18d4651b65807400,reason=Created count=1 msg=Created container: task
0.122,Event,ADDED,eval-conflicts-rho005-r1-007-pgjl9.18d4651b6ad9bdcb,reason=Started count=1 msg=Started container task
0.1222,Event,ADDED,eval-conflicts-rho005-r1-007.18d4651b47fba204,reason=SuccessfulCreate count=1 msg=Created pod: eval-conflicts-rho005-r1-007-pgjl9
0.1228,Event,ADDED,eval-conflicts-rho005-r1-007.18d4651e87f55442,reason=Completed count=1 msg=Job completed
0.123,Event,ADDED,eval-conflicts-rho005-r1-008-bm7xd.18d4651b84c030f5,reason=Scheduled count=None msg=Successfully assigned compute/eval-conflicts-rho005-r1-008-bm7xd to kind-worker5
0.1232,Event,ADDED,eval-conflicts-rho005-r1-008-bm7xd.18d4651ba00af8bf,"reason=Pulled count=1 msg=Container image ""busybox:musl"" already present on machine"
0.1235,Event,ADDED,eval-conflicts-rho005-r1-008-bm7xd.18d4651ba126450d,reason=Created count=1 msg=Created container: task
0.1237,Event,ADDED,eval-conflicts-rho005-r1-008-bm7xd.18d4651ba8eb79d4,reason=Started count=1 msg=Started container task
0.1239,Event,ADDED,eval-conflicts-rho005-r1-008.18d4651b83d09d48,reason=SuccessfulCreate count=1 msg=Created pod: eval-conflicts-rho005-r1-008-bm7xd
0.1241,Event,ADDED,eval-conflicts-rho005-r1-008.18d4651ec8b81b57,reason=Completed count=1 msg=Job completed
0.1243,Event,ADDED,eval-conflicts-rho005-r1-009-cz9xp.18d4651bbf3767c3,reason=Scheduled count=None msg=Successfully assigned compute/eval-conflicts-rho005-r1-009-cz9xp to kind-worker5
0.1245,Event,ADDED,eval-conflicts-rho005-r1-009-cz9xp.18d4651bde645f6d,"reason=Pulled count=1 msg=Container image ""busybox:musl"" already present on machine"
0.1247,Event,ADDED,eval-conflicts-rho005-r1-009-cz9xp.18d4651bdf8e5ca3,reason=Created count=1 msg=Created container: task
0.125,Event,ADDED,eval-conflicts-rho005-r1-009-cz9xp.18d4651be3545a92,reason=Started count=1 msg=Started container task
0.1252,Event,ADDED,eval-conflicts-rho005-r1-009.18d4651bbe3dbda9,reason=SuccessfulCreate count=1 msg=Created pod: eval-conflicts-rho005-r1-009-cz9xp
0.1254,Event,ADDED,eval-conflicts-rho005-r1-009.18d4651f0476d01a,reason=Completed count=1 msg=Job completed
0.1255,Event,ADDED,eval-conflicts-rho005-r1-010-6js4b.18d4651bfac5da06,reason=Scheduled count=None msg=Successfully assigned compute/eval-conflicts-rho005-r1-010-6js4b to kind-worker4
0.1258,Event,ADDED,eval-conflicts-rho005-r1-010-6js4b.18d4651c1575dc9a,"reason=Pulled count=1 msg=Container image ""busybox:musl"" already present on machine"
0.1259,Event,ADDED,eval-conflicts-rho005-r1-010-6js4b.18d4651c16a40e16,reason=Created count=1 msg=Created container: task
0.1261,Event,ADDED,eval-conflicts-rho005-r1-010-6js4b.18d4651c1ba60a20,reason=Started count=1 msg=Started container task
0.1263,Event,ADDED,eval-conflicts-rho005-r1-010.18d4651bf9d73de8,reason=SuccessfulCreate count=1 msg=Created pod: eval-conflicts-rho005-r1-010-6js4b
0.1265,Event,ADDED,eval-conflicts-rho005-r1-010.18d4651eff86827b,reason=Completed count=1 msg=Job completed
0.1266,Event,ADDED,eval-conflicts-rho005-r1-011-zbqtc.18d4651c38bcd7b4,reason=Scheduled count=None msg=Successfully assigned compute/eval-conflicts-rho005-r1-011-zbqtc to kind-worker3
0.1268,Event,ADDED,eval-conflicts-rho005-r1-011-zbqtc.18d4651c5757d1c6,"reason=Pulled count=1 msg=Container image ""busybox:musl"" already present on machine"
0.127,Event,ADDED,eval-conflicts-rho005-r1-011-zbqtc.18d4651c589061c9,reason=Created count=1 msg=Created container: task
0.1271,Event,ADDED,eval-conflicts-rho005-r1-011-zbqtc.18d4651c611a4809,reason=Started count=1 msg=Started container task
0.1273,Event,ADDED,eval-conflicts-rho005-r1-011.18d4651c37e16ca7,reason=SuccessfulCreate count=1 msg=Created pod: eval-conflicts-rho005-r1-011-zbqtc
0.1275,Event,ADDED,eval-conflicts-rho005-r1-011.18d4651f70d2b273,reason=Completed count=1 msg=Job completed
0.1278,Event,ADDED,eval-conflicts-rho005-r1-012-97sf8.18d4651c74732d35,reason=Scheduled count=None msg=Successfully assigned compute/eval-conflicts-rho005-r1-012-97sf8 to kind-worker4
0.128,Event,ADDED,eval-conflicts-rho005-r1-012-97sf8.18d4651c9191ef6a,"reason=Pulled count=1 msg=Container image ""busybox:musl"" already present on machine"
0.1282,Event,ADDED,eval-conflicts-rho005-r1-012-97sf8.18d4651c92ce27ec,reason=Created count=1 msg=Created container: task
0.1283,Event,ADDED,eval-conflicts-rho005-r1-012-97sf8.18d4651c9bb526d0,reason=Started count=1 msg=Started container task
0.1289,Event,ADDED,eval-conflicts-rho005-r1-012.18d4651c737630c2,reason=SuccessfulCreate count=1 msg=Created pod: eval-conflicts-rho005-r1-012-97sf8
0.1291,Event,ADDED,eval-conflicts-rho005-r1-012.18d4651f772aa45d,reason=Completed count=1 msg=Job completed
0.1293,Event,ADDED,eval-conflicts-rho005-r1-013-sqxsc.18d4651cada68459,"reason=FailedScheduling count=None msg=0/6 nodes are available: 1 c_wall violated: 1 conflicting context pair(s) with node memory, 5 node(s) had untolerated taint(s). no new claims to deallocate, preemption: 0/6 nodes are available: 1 No preemption victims found for incoming pod, 5 Preemption is not helpful for scheduling."
0.1295,Event,ADDED,eval-conflicts-rho005-r1-013-sqxsc.18d4651cae4c0041,"reason=FailedScheduling count=None msg=0/6 nodes are available: 1 c_wall violated: 1 conflicting context pair(s) with node memory, 5 node(s) had untolerated taint(s). no new claims to deallocate, preemption: 0/6 nodes are available: 1 No preemption victims found for incoming pod, 5 Preemption is not helpful for scheduling."
0.1297,Event,ADDED,eval-conflicts-rho005-r1-013-sqxsc.18d4651ced1c9355,"reason=FailedScheduling count=None msg=0/6 nodes are available: 1 c_wall violated: 2 conflicting context pair(s) with node memory, 5 node(s) had untolerated taint(s). no new claims to deallocate, preemption: 0/6 nodes are available: 1 No preemption victims found for incoming pod, 5 Preemption is not helpful for scheduling."
0.1299,Event,ADDED,eval-conflicts-rho005-r1-013-sqxsc.18d4651ec12c47da,reason=Scheduled count=None msg=Successfully assigned compute/eval-conflicts-rho005-r1-013-sqxsc to kind-worker
0.1307,Event,ADDED,eval-conflicts-rho005-r1-013-sqxsc.18d4651eda59e8de,"reason=Pulled count=1 msg=Container image ""busybox:musl"" already present on machine"
0.1309,Event,ADDED,eval-conflicts-rho005-r1-013-sqxsc.18d4651edbee8a2d,reason=Created count=1 msg=Created container: task
0.131,Event,ADDED,eval-conflicts-rho005-r1-013-sqxsc.18d4651ede0ef168,reason=Started count=1 msg=Started container task
0.1312,Event,ADDED,eval-conflicts-rho005-r1-013.18d4651cad582ff3,reason=SuccessfulCreate count=1 msg=Created pod: eval-conflicts-rho005-r1-013-sqxsc
0.1315,Event,ADDED,eval-conflicts-rho005-r1-013.18d46521feee2296,reason=Completed count=1 msg=Job completed
0.1317,Event,ADDED,eval-conflicts-rho005-r1-014-cbhx6.18d4651cec4c9d2d,reason=Scheduled count=None msg=Successfully assigned compute/eval-conflicts-rho005-r1-014-cbhx6 to kind-worker3
0.1318,Event,ADDED,eval-conflicts-rho005-r1-014-cbhx6.18d4651d0a062b8c,"reason=Pulled count=1 msg=Container image ""busybox:musl"" already present on machine"
0.132,Event,ADDED,eval-conflicts-rho005-r1-014-cbhx6.18d4651d0b32d317,reason=Created count=1 msg=Created container: task
0.1322,Event,ADDED,eval-conflicts-rho005-r1-014-cbhx6.18d4651d1134f258,reason=Started count=1 msg=Started container task
0.1324,Event,ADDED,eval-conflicts-rho005-r1-014.18d4651cebc86f46,reason=SuccessfulCreate count=1 msg=Created pod: eval-conflicts-rho005-r1-014-cbhx6
0.1325,Event,ADDED,eval-conflicts-rho005-r1-014.18d46520246022a6,reason=Completed count=1 msg=Job completed
0.1327,Event,ADDED,eval-conflicts-rho005-r1-015-7ddxn.18d4651d24f0fd3a,reason=Scheduled count=None msg=Successfully assigned compute/eval-conflicts-rho005-r1-015-7ddxn to kind-worker3
0.1328,Event,ADDED,eval-conflicts-rho005-r1-015-7ddxn.18d4651d3f95ab7c,"reason=Pulled count=1 msg=Container image ""busybox:musl"" already present on machine"
0.133,Event,ADDED,eval-conflicts-rho005-r1-015-7ddxn.18d4651d41126832,reason=Created count=1 msg=Created container: task
0.1332,Event,ADDED,eval-conflicts-rho005-r1-015-7ddxn.18d4651d451836a2,reason=Started count=1 msg=Started container task
0.1333,Event,ADDED,eval-conflicts-rho005-r1-015.18d4651d24773f72,reason=SuccessfulCreate count=1 msg=Created pod: eval-conflicts-rho005-r1-015-7ddxn
0.1335,Event,ADDED,eval-conflicts-rho005-r1-015.18d465205fe34bfc,reason=Completed count=1 msg=Job completed
0.1337,Event,ADDED,eval-conflicts-rho005-r1-016-sh69z.18d4651d60ba49d2,reason=Scheduled count=None msg=Successfully assigned compute/eval-conflicts-rho005-r1-016-sh69z to kind-worker3
0.1339,Event,ADDED,eval-conflicts-rho005-r1-016-sh69z.18d4651d7a521bf6,"reason=Pulled count=1 msg=Container image ""busybox:musl"" already present on machine"
0.1341,Event,ADDED,eval-conflicts-rho005-r1-016-sh69z.18d4651d7b97a0cb,reason=Created count=1 msg=Created container: task
0.1342,Event,ADDED,eval-conflicts-rho005-r1-016-sh69z.18d4651d82b055a4,reason=Started count=1 msg=Started container task
0.1344,Event,ADDED,eval-conflicts-rho005-r1-016.18d4651d6035d8a8,reason=SuccessfulCreate count=1 msg=Created pod: eval-conflicts-rho005-r1-016-sh69z
0.1345,Event,ADDED,eval-conflicts-rho005-r1-016.18d465209bfc372c,reason=Completed count=1 msg=Job completed
0.1347,Event,ADDED,eval-conflicts-rho005-r1-017-vmkmx.18d4651d9c99c216,reason=Scheduled count=None msg=Successfully assigned compute/eval-conflicts-rho005-r1-017-vmkmx to kind-worker3
0.1349,Event,ADDED,eval-conflicts-rho005-r1-017-vmkmx.18d4651db6b79aa7,"reason=Pulled count=1 msg=Container image ""busybox:musl"" already present on machine"
0.1351,Event,ADDED,eval-conflicts-rho005-r1-017-vmkmx.18d4651db7e584cf,reason=Created count=1 msg=Created container: task
0.1352,Event,ADDED,eval-conflicts-rho005-r1-017-vmkmx.18d4651dbc882d6b,reason=Started count=1 msg=Started container task
0.1354,Event,ADDED,eval-conflicts-rho005-r1-017.18d4651d9c19ecd7,reason=SuccessfulCreate count=1 msg=Created pod: eval-conflicts-rho005-r1-017-vmkmx
0.1355,Event,ADDED,eval-conflicts-rho005-r1-017.18d46520d7f9d555,reason=Completed count=1 msg=Job completed
0.1357,Event,ADDED,eval-conflicts-rho005-r1-018-gxhlh.18d4651dd74567b6,reason=Scheduled count=None msg=Successfully assigned compute/eval-conflicts-rho005-r1-018-gxhlh to kind-worker3
0.1359,Event,ADDED,eval-conflicts-rho005-r1-018-gxhlh.18d4651df1105f9f,"reason=Pulled count=1 msg=Container image ""busybox:musl"" already present on machine"
0.136,Event,ADDED,eval-conflicts-rho005-r1-018-gxhlh.18d4651df224bb4f,reason=Created count=1 msg=Created container: task
0.1362,Event,ADDED,eval-conflicts-rho005-r1-018-gxhlh.18d4651df6719148,reason=Started count=1 msg=Started container task
0.1364,Event,ADDED,eval-conflicts-rho005-r1-018.18d4651dd6b32b6e,reason=SuccessfulCreate count=1 msg=Created pod: eval-conflicts-rho005-r1-018-gxhlh
0.1366,Event,ADDED,eval-conflicts-rho005-r1-018.18d4652113eb11b4,reason=Completed count=1 msg=Job completed
0.1367,Event,ADDED,eval-conflicts-rho005-r1-019-c4c9k.18d4651e12ff23dc,reason=Scheduled count=None msg=Successfully assigned compute/eval-conflicts-rho005-r1-019-c4c9k to kind-worker3
0.1369,Event,ADDED,eval-conflicts-rho005-r1-019-c4c9k.18d4651e2c45d6c8,"reason=Pulled count=1 msg=Container image ""busybox:musl"" already present on machine"
0.1371,Event,ADDED,eval-conflicts-rho005-r1-019-c4c9k.18d4651e2d6f2ea4,reason=Created count=1 msg=Created container: task
0.1373,Event,ADDED,eval-conflicts-rho005-r1-019-c4c9k.18d4651e2fa50946,reason=Started count=1 msg=Started container task
0.1374,Event,ADDED,eval-conflicts-rho005-r1-019.18d4651e12658208,reason=SuccessfulCreate count=1 msg=Created pod: eval-conflicts-rho005-r1-019-c4c9k
0.1376,Event,ADDED,eval-conflicts-rho005-r1-019.18d465214fb2d745,reason=Completed count=1 msg=Job completed
0.1377,Event,ADDED,eval-conflicts-rho005-r1-020-pf7ct.18d4651e4e0fb795,"reason=FailedScheduling count=None msg=0/6 nodes are available: 6 node(s) had untolerated taint(s). no new claims to deallocate, preemption: 0/6 nodes are available: 6 Preemption is not helpful for scheduling."
0.1379,Event,ADDED,eval-conflicts-rho005-r1-020-pf7ct.18d4651ec16043d0,reason=Scheduled count=None msg=Successfully assigned compute/eval-conflicts-rho005-r1-020-pf7ct to kind-worker
0.1381,Event,ADDED,eval-conflicts-rho005-r1-020-pf7ct.18d4651edaf6b7c0,"reason=Pulled count=1 msg=Container image ""busybox:musl"" already present on machine"
0.1385,Event,ADDED,eval-conflicts-rho005-r1-020-pf7ct.18d4651edcdab42a,reason=Created count=1 msg=Created container: task
0.1389,Event,ADDED,eval-conflicts-rho005-r1-020-pf7ct.18d4651edefc4f9c,reason=Started count=1 msg=Started container task
0.1391,Event,ADDED,eval-conflicts-rho005-r1-020.18d4651e4e059ce3,reason=SuccessfulCreate count=1 msg=Created pod: eval-conflicts-rho005-r1-020-pf7ct
0.1393,Event,ADDED,eval-conflicts-rho005-r1-020.18d46521fec73b04,reason=Completed count=1 msg=Job completed
0.1395,Event,ADDED,eval-conflicts-rho005-r1-021-kr5rq.18d4651e89a33ec8,"reason=FailedScheduling count=None msg=0/6 nodes are available: 6 node(s) had untolerated taint(s). no new claims to deallocate, preemption: 0/6 nodes are available: 6 Preemption is not helpful for scheduling."
0.1397,Event,ADDED,eval-conflicts-rho005-r1-021-kr5rq.18d4651ec1d1bf27,reason=Scheduled count=None msg=Successfully assigned compute/eval-conflicts-rho005-r1-021-kr5rq to kind-worker
0.1398,Event,ADDED,eval-conflicts-rho005-r1-021-kr5rq.18d4651edb42d0ec,"reason=Pulled count=1 msg=Container image ""busybox:musl"" already present on machine"
0.14,Event,ADDED,eval-conflicts-rho005-r1-021-kr5rq.18d4651edd364443,reason=Created count=1 msg=Created container: task
0.1402,Event,ADDED,eval-conflicts-rho005-r1-021-kr5rq.18d4651edf5f5138,reason=Started count=1 msg=Started container task
0.1404,Event,ADDED,eval-conflicts-rho005-r1-021.18d4651e899039f0,reason=SuccessfulCreate count=1 msg=Created pod: eval-conflicts-rho005-r1-021-kr5rq
0.1407,Event,ADDED,eval-conflicts-rho005-r1-021.18d46521c40c6d44,reason=Completed count=1 msg=Job completed
0.1408,Event,ADDED,eval-conflicts-rho005-r1-022-zvf78.18d4651ec55f1ec7,reason=Scheduled count=None msg=Successfully assigned compute/eval-conflicts-rho005-r1-022-zvf78 to kind-worker
0.141,Event,ADDED,eval-conflicts-rho005-r1-022-zvf78.18d4651edcfbb27d,"reason=Pulled count=1 msg=Container image ""busybox:musl"" already present on machine"
0.1412,Event,ADDED,eval-conflicts-rho005-r1-022-zvf78.18d4651ede517f18,reason=Created count=1 msg=Created container: task
0.1416,Event,ADDED,eval-conflicts-rho005-r1-022-zvf78.18d4651ee052b37b,reason=Started count=1 msg=Started container task
0.1417,Event,ADDED,eval-conflicts-rho005-r1-022.18d4651ec4da5e54,reason=SuccessfulCreate count=1 msg=Created pod: eval-conflicts-rho005-r1-022-zvf78
0.1419,Event,ADDED,eval-conflicts-rho005-r1-022.18d46521fecc48b1,reason=Completed count=1 msg=Job completed
0.1421,Event,ADDED,eval-conflicts-rho005-r1-023-lpr7p.18d4651f007e2553,"reason=FailedScheduling count=None msg=0/6 nodes are available: 1 c_wall violated: 1 conflicting context pair(s) with node memory, 5 node(s) had untolerated taint(s). no new claims to deallocate, preemption: 0/6 nodes are available: 1 No preemption victims found for incoming pod, 5 Preemption is not helpful for scheduling."
0.1423,Event,ADDED,eval-conflicts-rho005-r1-023-lpr7p.18d4651f01272de5,"reason=FailedScheduling count=None msg=0/6 nodes are available: 1 c_wall violated: 1 conflicting context pair(s) with node memory, 5 node(s) had untolerated taint(s). no new claims to deallocate, preemption: 0/6 nodes are available: 1 No preemption victims found for incoming pod, 5 Preemption is not helpful for scheduling."
0.1425,Event,ADDED,eval-conflicts-rho005-r1-023-lpr7p.18d4651f9b0d2091,reason=Scheduled count=None msg=Successfully assigned compute/eval-conflicts-rho005-r1-023-lpr7p to kind-worker2
0.1426,Event,ADDED,eval-conflicts-rho005-r1-023-lpr7p.18d4651fb4287921,"reason=Pulled count=1 msg=Container image ""busybox:musl"" already present on machine"
0.1428,Event,ADDED,eval-conflicts-rho005-r1-023-lpr7p.18d4651fb5abf127,reason=Created count=1 msg=Created container: task
0.143,Event,ADDED,eval-conflicts-rho005-r1-023-lpr7p.18d4651fb9d719fe,reason=Started count=1 msg=Started container task
0.1432,Event,ADDED,eval-conflicts-rho005-r1-023.18d4651f00372e44,reason=SuccessfulCreate count=1 msg=Created pod: eval-conflicts-rho005-r1-023-lpr7p
0.1433,Event,ADDED,eval-conflicts-rho005-r1-023.18d46522d9f33c1e,reason=Completed count=1 msg=Job completed
0.1435,Event,ADDED,eval-conflicts-rho005-r1-024-kqpnt.18d4651f3cdee7eb,reason=Scheduled count=None msg=Successfully assigned compute/eval-conflicts-rho005-r1-024-kqpnt to kind-worker
0.1437,Event,ADDED,eval-conflicts-rho005-r1-024-kqpnt.18d4651f560c7a61,"reason=Pulled count=1 msg=Container image ""busybox:musl"" already present on machine"
0.1439,Event,ADDED,eval-conflicts-rho005-r1-024-kqpnt.18d4651f57268965,reason=Created count=1 msg=Created container: task
0.1443,Event,ADDED,eval-conflicts-rho005-r1-024-kqpnt.18d4651f5be26ac9,reason=Started count=1 msg=Started container task
0.1445,Event,ADDED,eval-conflicts-rho005-r1-024.18d4651f3c472f85,reason=SuccessfulCreate count=1 msg=Created pod: eval-conflicts-rho005-r1-024-kqpnt
0.1447,Event,ADDED,eval-conflicts-rho005-r1-024.18d4652276b75448,reason=Completed count=1 msg=Job completed
0.1449,Event,ADDED,eval-conflicts-rho005-r1-025-6r989.18d4651f7842824f,reason=Scheduled count=None msg=Successfully assigned compute/eval-conflicts-rho005-r1-025-6r989 to kind-worker
0.1452,Event,ADDED,eval-conflicts-rho005-r1-025-6r989.18d4651f90d94e6e,"reason=Pulled count=1 msg=Container image ""busybox:musl"" already present on machine"
0.1454,Event,ADDED,eval-conflicts-rho005-r1-025-6r989.18d4651f922bb093,reason=Created count=1 msg=Created container: task
0.1456,Event,ADDED,eval-conflicts-rho005-r1-025-6r989.18d4651f945967ca,reason=Started count=1 msg=Started container task
0.1459,Event,ADDED,eval-conflicts-rho005-r1-025.18d4651f77a9205e,reason=SuccessfulCreate count=1 msg=Created pod: eval-conflicts-rho005-r1-025-6r989
0.1461,Event,ADDED,eval-conflicts-rho005-r1-025.18d46522b2905e09,reason=Completed count=1 msg=Job completed
0.1462,Event,ADDED,eval-conflicts-rho005-r1-026-5p6gx.18d4651fb4ba2c81,reason=Scheduled count=None msg=Successfully assigned compute/eval-conflicts-rho005-r1-026-5p6gx to kind-worker2
0.1464,Event,ADDED,eval-conflicts-rho005-r1-026-5p6gx.18d4651fcdff3687,"reason=Pulled count=1 msg=Container image ""busybox:musl"" already present on machine"
0.1466,Event,ADDED,eval-conflicts-rho005-r1-026-5p6gx.18d4651fcf0bcc6a,reason=Created count=1 msg=Created container: task
0.1468,Event,ADDED,eval-conflicts-rho005-r1-026-5p6gx.18d4651fd112e631,reason=Started count=1 msg=Started container task
0.147,Event,ADDED,eval-conflicts-rho005-r1-026.18d4651fb34e082f,reason=SuccessfulCreate count=1 msg=Created pod: eval-conflicts-rho005-r1-026-5p6gx
0.1472,Event,ADDED,eval-conflicts-rho005-r1-026.18d4652315b2fc12,reason=Completed count=1 msg=Job completed
0.1473,Event,ADDED,eval-conflicts-rho005-r1-027-6dvdg.18d4651fef9b0922,reason=Scheduled count=None msg=Successfully assigned compute/eval-conflicts-rho005-r1-027-6dvdg to kind-worker2
0.1475,Event,ADDED,eval-conflicts-rho005-r1-027-6dvdg.18d4652008d0403a,"reason=Pulled count=1 msg=Container image ""busybox:musl"" already present on machine"
0.1476,Event,ADDED,eval-conflicts-rho005-r1-027-6dvdg.18d4652009e43e72,reason=Created count=1 msg=Created container: task
0.1478,Event,ADDED,eval-conflicts-rho005-r1-027-6dvdg.18d465200be0acf6,reason=Started count=1 msg=Started container task
0.148,Event,ADDED,eval-conflicts-rho005-r1-027.18d4651feea0fdec,reason=SuccessfulCreate count=1 msg=Created pod: eval-conflicts-rho005-r1-027-6dvdg
0.1481,Event,ADDED,eval-conflicts-rho005-r1-027.18d4652351db7439,reason=Completed count=1 msg=Job completed
0.1483,Event,ADDED,eval-conflicts-rho005-r1-028-fr6lk.18d465202b6ca139,reason=Scheduled count=None msg=Successfully assigned compute/eval-conflicts-rho005-r1-028-fr6lk to kind-worker2
0.1485,Event,ADDED,eval-conflicts-rho005-r1-028-fr6lk.18d46520449268cd,"reason=Pulled count=1 msg=Container image ""busybox:musl"" already present on machine"
0.1486,Event,ADDED,eval-conflicts-rho005-r1-028-fr6lk.18d4652045b28f45,reason=Created count=1 msg=Created container: task
0.1488,Event,ADDED,eval-conflicts-rho005-r1-028-fr6lk.18d4652047a95bcf,reason=Started count=1 msg=Started container task
0.149,Event,ADDED,eval-conflicts-rho005-r1-028.18d465202a626baa,reason=SuccessfulCreate count=1 msg=Created pod: eval-conflicts-rho005-r1-028-fr6lk
0.1491,Event,ADDED,eval-conflicts-rho005-r1-028.18d465238dd1592e,reason=Completed count=1 msg=Job completed
0.1494,Event,ADDED,eval-conflicts-rho005-r1-029-r22dn.18d4652066cb0ca3,reason=Scheduled count=None msg=Successfully assigned compute/eval-conflicts-rho005-r1-029-r22dn to kind-worker2
0.1495,Event,ADDED,eval-conflicts-rho005-r1-029-r22dn.18d465207fe15a59,"reason=Pulled count=1 msg=Container image ""busybox:musl"" already present on machine"
0.1497,Event,ADDED,eval-conflicts-rho005-r1-029-r22dn.18d46520811879d7,reason=Created count=1 msg=Created container: task
0.15,Event,ADDED,eval-conflicts-rho005-r1-029-r22dn.18d465208517ee5e,reason=Started count=1 msg=Started container task
0.1501,Event,ADDED,eval-conflicts-rho005-r1-029.18d4652065e1d1c7,reason=SuccessfulCreate count=1 msg=Created pod: eval-conflicts-rho005-r1-029-r22dn
0.1503,Event,ADDED,eval-conflicts-rho005-r1-029.18d46523c9ad099a,reason=Completed count=1 msg=Job completed
0.1506,Event,ADDED,eval-conflicts-rho005-r1-030-9ndlf.18d46520a3532022,reason=Scheduled count=None msg=Successfully assigned compute/eval-conflicts-rho005-r1-030-9ndlf to kind-worker5
0.1508,Event,ADDED,eval-conflicts-rho005-r1-030-9ndlf.18d46520bbd9eea0,"reason=Pulled count=1 msg=Container image ""busybox:musl"" already present on machine"
0.151,Event,ADDED,eval-conflicts-rho005-r1-030-9ndlf.18d46520bd0a4f49,reason=Created count=1 msg=Created container: task
0.1513,Event,ADDED,eval-conflicts-rho005-r1-030-9ndlf.18d46520bf3a5453,reason=Started count=1 msg=Started container task
0.1515,Event,ADDED,eval-conflicts-rho005-r1-030.18d46520a25186cf,reason=SuccessfulCreate count=1 msg=Created pod: eval-conflicts-rho005-r1-030-9ndlf
0.1517,Event,ADDED,eval-conflicts-rho005-r1-030.18d46523eba3552d,reason=Completed count=1 msg=Job completed
0.1518,Event,ADDED,eval-conflicts-rho005-r1-031-8r9wh.18d46520def942d5,reason=Scheduled count=None msg=Successfully assigned compute/eval-conflicts-rho005-r1-031-8r9wh to kind-worker5
0.1521,Event,ADDED,eval-conflicts-rho005-r1-031-8r9wh.18d46520f775fc46,"reason=Pulled count=1 msg=Container image ""busybox:musl"" already present on machine"
0.1522,Event,ADDED,eval-conflicts-rho005-r1-031-8r9wh.18d46520f890c60d,reason=Created count=1 msg=Created container: task
0.1524,Event,ADDED,eval-conflicts-rho005-r1-031-8r9wh.18d46520fd0c6773,reason=Started count=1 msg=Started container task
0.1528,Event,ADDED,eval-conflicts-rho005-r1-031.18d46520ddbb939f,reason=SuccessfulCreate count=1 msg=Created pod: eval-conflicts-rho005-r1-031-8r9wh
0.153,Event,ADDED,eval-conflicts-rho005-r1-031.18d465242749adee,reason=Completed count=1 msg=Job completed
0.1531,Event,ADDED,eval-conflicts-rho005-r1-032-fghdz.18d46521199d11e6,reason=Scheduled count=None msg=Successfully assigned compute/eval-conflicts-rho005-r1-032-fghdz to kind-worker5
0.1533,Event,ADDED,eval-conflicts-rho005-r1-032-fghdz.18d4652131fdeed8,"reason=Pulled count=1 msg=Container image ""busybox:musl"" already present on machine"
0.1537,Event,ADDED,eval-conflicts-rho005-r1-032-fghdz.18d4652133264503,reason=Created count=1 msg=Created container: task
0.1539,Event,ADDED,eval-conflicts-rho005-r1-032-fghdz.18d4652139902ebc,reason=Started count=1 msg=Started container task
0.1541,Event,ADDED,eval-conflicts-rho005-r1-032.18d4652118b22990,reason=SuccessfulCreate count=1 msg=Created pod: eval-conflicts-rho005-r1-032-fghdz
0.1542,Event,ADDED,eval-conflicts-rho005-r1-032.18d465246344cc2b,reason=Completed count=1 msg=Job completed
0.1545,Event,ADDED,eval-conflicts-rho005-r1-033-v4pwv.18d46521551d653d,reason=Scheduled count=None msg=Successfully assigned compute/eval-conflicts-rho005-r1-033-v4pwv to kind-worker4
0.1547,Event,ADDED,eval-conflicts-rho005-r1-033-v4pwv.18d465216d6cc8d8,"reason=Pulled count=1 msg=Container image ""busybox:musl"" already present on machine"
0.1549,Event,ADDED,eval-conflicts-rho005-r1-033-v4pwv.18d465216e8b6a79,reason=Created count=1 msg=Created container: task
0.1552,Event,ADDED,eval-conflicts-rho005-r1-033-v4pwv.18d4652170acc482,reason=Started count=1 msg=Started container task
0.1554,Event,ADDED,eval-conflicts-rho005-r1-033.18d465215449be6a,reason=SuccessfulCreate count=1 msg=Created pod: eval-conflicts-rho005-r1-033-v4pwv
0.1555,Event,ADDED,eval-conflicts-rho005-r1-033.18d46524995cdfa6,reason=Completed count=1 msg=Job completed
0.1557,Event,ADDED,eval-conflicts-rho005-r1-034-7dvqh.18d465219144176f,reason=Scheduled count=None msg=Successfully assigned compute/eval-conflicts-rho005-r1-034-7dvqh to kind-worker5
0.1559,Event,ADDED,eval-conflicts-rho005-r1-034-7dvqh.18d46521aaf3ac1c,"reason=Pulled count=1 msg=Container image ""busybox:musl"" already present on machine"
0.1561,Event,ADDED,eval-conflicts-rho005-r1-034-7dvqh.18d46521ac1bbdcb,reason=Created count=1 msg=Created container: task
0.1563,Event,ADDED,eval-conflicts-rho005-r1-034-7dvqh.18d46521b071645f,reason=Started count=1 msg=Started container task
0.1564,Event,ADDED,eval-conflicts-rho005-r1-034.18d46521900cada5,reason=SuccessfulCreate count=1 msg=Created pod: eval-conflicts-rho005-r1-034-7dvqh
0.1566,Event,ADDED,eval-conflicts-rho005-r1-034.18d46524da9e1b9f,reason=Completed count=1 msg=Job completed
0.1568,Event,ADDED,eval-conflicts-rho005-r1-035-l7slt.18d46521cd0ced6d,reason=Scheduled count=None msg=Successfully assigned compute/eval-conflicts-rho005-r1-035-l7slt to kind-worker5
0.1569,Event,ADDED,eval-conflicts-rho005-r1-035-l7slt.18d46521e5edc2d6,"reason=Pulled count=1 msg=Container image ""busybox:musl"" already present on machine"
0.1571,Event,ADDED,eval-conflicts-rho005-r1-035-l7slt.18d46521e6fd38bd,reason=Created count=1 msg=Created container: task
0.1573,Event,ADDED,eval-conflicts-rho005-r1-035-l7slt.18d46521e9470b02,reason=Started count=1 msg=Started container task
0.1574,Event,ADDED,eval-conflicts-rho005-r1-035.18d46521cbde73f7,reason=SuccessfulCreate count=1 msg=Created pod: eval-conflicts-rho005-r1-035-l7slt
0.1577,Event,ADDED,eval-conflicts-rho005-r1-035.18d4652516606fac,reason=Completed count=1 msg=Job completed
0.158,Event,ADDED,eval-conflicts-rho005-r1-036-znhxf.18d46522081e50a4,reason=Scheduled count=None msg=Successfully assigned compute/eval-conflicts-rho005-r1-036-znhxf to kind-worker4
0.1582,Event,ADDED,eval-conflicts-rho005-r1-036-znhxf.18d46522220422ca,"reason=Pulled count=1 msg=Container image ""busybox:musl"" already present on machine"
0.1583,Event,ADDED,eval-conflicts-rho005-r1-036-znhxf.18d465222313b891,reason=Created count=1 msg=Created container: task
0.1586,Event,ADDED,eval-conflicts-rho005-r1-036-znhxf.18d4652225203e23,reason=Started count=1 msg=Started container task
0.1588,Event,ADDED,eval-conflicts-rho005-r1-036.18d4652207344294,reason=SuccessfulCreate count=1 msg=Created pod: eval-conflicts-rho005-r1-036-znhxf
0.159,Event,ADDED,eval-conflicts-rho005-r1-036.18d465254cb08b37,reason=Completed count=1 msg=Job completed
0.1591,Event,ADDED,eval-conflicts-rho005-r1-037-6lvlj.18d4652243ea5794,reason=Scheduled count=None msg=Successfully assigned compute/eval-conflicts-rho005-r1-037-6lvlj to kind-worker4
0.1594,Event,ADDED,eval-conflicts-rho005-r1-037-6lvlj.18d465225ca08b0a,"reason=Pulled count=1 msg=Container image ""busybox:musl"" already present on machine"
0.1596,Event,ADDED,eval-conflicts-rho005-r1-037-6lvlj.18d465225dbbf15a,reason=Created count=1 msg=Created container: task
0.1597,Event,ADDED,eval-conflicts-rho005-r1-037-6lvlj.18d465225fc51bd8,reason=Started count=1 msg=Started container task
0.1599,Event,ADDED,eval-conflicts-rho005-r1-037.18d4652242ef22f0,reason=SuccessfulCreate count=1 msg=Created pod: eval-conflicts-rho005-r1-037-6lvlj
0.1601,Event,ADDED,eval-conflicts-rho005-r1-037.18d46525888cb182,reason=Completed count=1 msg=Job completed
0.1603,Event,ADDED,eval-conflicts-rho005-r1-038-gtdkk.18d465227f8202bf,reason=Scheduled count=None msg=Successfully assigned compute/eval-conflicts-rho005-r1-038-gtdkk to kind-worker5
0.1605,Event,ADDED,eval-conflicts-rho005-r1-038-gtdkk.18d465229880ea63,"reason=Pulled count=1 msg=Container image ""busybox:musl"" already present on machine"
0.1607,Event,ADDED,eval-conflicts-rho005-r1-038-gtdkk.18d465229998c14b,reason=Created count=1 msg=Created container: task
0.1608,Event,ADDED,eval-conflicts-rho005-r1-038-gtdkk.18d465229d1c195f,reason=Started count=1 msg=Started container task
0.161,Event,ADDED,eval-conflicts-rho005-r1-038.18d465227e885dba,reason=SuccessfulCreate count=1 msg=Created pod: eval-conflicts-rho005-r1-038-gtdkk
0.1612,Event,ADDED,eval-conflicts-rho005-r1-038.18d46525c9e92e5d,reason=Completed count=1 msg=Job completed
0.1615,Event,ADDED,eval-conflicts-rho005-r1-039-rd7km.18d46522bae23eed,reason=Scheduled count=None msg=Successfully assigned compute/eval-conflicts-rho005-r1-039-rd7km to kind-worker5
0.1617,Event,ADDED,eval-conflicts-rho005-r1-039-rd7km.18d46522d4412cb9,"reason=Pulled count=1 msg=Container image ""busybox:musl"" already present on machine"
0.1619,Event,ADDED,eval-conflicts-rho005-r1-039-rd7km.18d46522d5525ef4,reason=Created count=1 msg=Created container: task
0.1621,Event,ADDED,eval-conflicts-rho005-r1-039-rd7km.18d46522d76b0d67,reason=Started count=1 msg=Started container task
0.1623,Event,ADDED,eval-conflicts-rho005-r1-039.18d46522b9fe7d25,reason=SuccessfulCreate count=1 msg=Created pod: eval-conflicts-rho005-r1-039-rd7km
0.1624,Event,ADDED,eval-conflicts-rho005-r1-039.18d46526058fff3f,reason=Completed count=1 msg=Job completed
0.1626,Event,ADDED,eval-conflicts-rho005-r1-040-fgznd.18d46522f6a927c0,reason=Scheduled count=None msg=Successfully assigned compute/eval-conflicts-rho005-r1-040-fgznd to kind-worker3
0.1628,Event,ADDED,eval-conflicts-rho005-r1-040-fgznd.18d46523108e948b,"reason=Pulled count=1 msg=Container image ""busybox:musl"" already present on machine"
0.163,Event,ADDED,eval-conflicts-rho005-r1-040-fgznd.18d4652311999191,reason=Created count=1 msg=Created container: task
0.1631,Event,ADDED,eval-conflicts-rho005-r1-040-fgznd.18d46523149c025d,reason=Started count=1 msg=Started container task
0.1633,Event,ADDED,eval-conflicts-rho005-r1-040.18d46522f5cfd04d,reason=SuccessfulCreate count=1 msg=Created pod: eval-conflicts-rho005-r1-040-fgznd
0.1635,Event,ADDED,eval-conflicts-rho005-r1-040.18d46526368dc098,reason=Completed count=1 msg=Job completed
0.1636,Event,ADDED,eval-conflicts-rho005-r1-041-s2rh5.18d4652332504920,reason=Scheduled count=None msg=Successfully assigned compute/eval-conflicts-rho005-r1-041-s2rh5 to kind-worker3
0.1638,Event,ADDED,eval-conflicts-rho005-r1-041-s2rh5.18d465234cc6e862,"reason=Pulled count=1 msg=Container image ""busybox:musl"" already present on machine"
0.164,Event,ADDED,eval-conflicts-rho005-r1-041-s2rh5.18d465234de3c613,reason=Created count=1 msg=Created container: task
0.1642,Event,ADDED,eval-conflicts-rho005-r1-041-s2rh5.18d4652351b29c27,reason=Started count=1 msg=Started container task
0.1644,Event,ADDED,eval-conflicts-rho005-r1-041.18d46523318a98fa,reason=SuccessfulCreate count=1 msg=Created pod: eval-conflicts-rho005-r1-041-s2rh5
0.1646,Event,ADDED,eval-conflicts-rho005-r1-041.18d465267297f090,reason=Completed count=1 msg=Job completed
0.165,Event,ADDED,eval-conflicts-rho005-r1-042-mqwb9.18d465236e294b40,reason=Scheduled count=None msg=Successfully assigned compute/eval-conflicts-rho005-r1-042-mqwb9 to kind-worker4
0.1653,Event,ADDED,eval-conflicts-rho005-r1-042-mqwb9.18d4652389659400,"reason=Pulled count=1 msg=Container image ""busybox:musl"" already present on machine"
0.1656,Event,ADDED,eval-conflicts-rho005-r1-042-mqwb9.18d465238a7d6fbb,reason=Created count=1 msg=Created container: task
0.1659,Event,ADDED,eval-conflicts-rho005-r1-042-mqwb9.18d465238ccab58d,reason=Started count=1 msg=Started container task
0.1664,Event,ADDED,eval-conflicts-rho005-r1-042.18d465236d4923c6,reason=SuccessfulCreate count=1 msg=Created pod: eval-conflicts-rho005-r1-042-mqwb9
0.1666,Event,ADDED,eval-conflicts-rho005-r1-042.18d46526b3804560,reason=Completed count=1 msg=Job completed
0.1668,Event,ADDED,eval-conflicts-rho005-r1-043-b7qb4.18d46523a9becdb0,reason=Scheduled count=None msg=Successfully assigned compute/eval-conflicts-rho005-r1-043-b7qb4 to kind-worker
0.1671,Event,ADDED,eval-conflicts-rho005-r1-043-b7qb4.18d46523c2f99c6f,"reason=Pulled count=1 msg=Container image ""busybox:musl"" already present on machine"
0.1673,Event,ADDED,eval-conflicts-rho005-r1-043-b7qb4.18d46523c41079ed,reason=Created count=1 msg=Created container: task
0.1675,Event,ADDED,eval-conflicts-rho005-r1-043-b7qb4.18d46523cd74bcfe,reason=Started count=1 msg=Started container task
0.1677,Event,ADDED,eval-conflicts-rho005-r1-043.18d46523a8f16fa6,reason=SuccessfulCreate count=1 msg=Created pod: eval-conflicts-rho005-r1-043-b7qb4
0.1681,Event,ADDED,eval-conflicts-rho005-r1-043.18d46526e630f701,reason=Completed count=1 msg=Job completed
0.1682,Event,ADDED,eval-conflicts-rho005-r1-044-qkl7p.18d46523e50afe0a,reason=Scheduled count=None msg=Successfully assigned compute/eval-conflicts-rho005-r1-044-qkl7p to kind-worker
0.1684,Event,ADDED,eval-conflicts-rho005-r1-044-qkl7p.18d46523fed2f3aa,"reason=Pulled count=1 msg=Container image ""busybox:musl"" already present on machine"
0.1686,Event,ADDED,eval-conflicts-rho005-r1-044-qkl7p.18d46523fff96d11,reason=Created count=1 msg=Created container: task
0.1688,Event,ADDED,eval-conflicts-rho005-r1-044-qkl7p.18d4652401f9ddc7,reason=Started count=1 msg=Started container task
0.169,Event,ADDED,eval-conflicts-rho005-r1-044.18d46523e410f599,reason=SuccessfulCreate count=1 msg=Created pod: eval-conflicts-rho005-r1-044-qkl7p
0.1692,Event,ADDED,eval-conflicts-rho005-r1-044.18d4652722193c25,reason=Completed count=1 msg=Job completed
0.1693,Event,ADDED,eval-conflicts-rho005-r1-045-f56nk.18d46524204456b0,reason=Scheduled count=None msg=Successfully assigned compute/eval-conflicts-rho005-r1-045-f56nk to kind-worker
0.1695,Event,ADDED,eval-conflicts-rho005-r1-045-f56nk.18d46524397dbe43,"reason=Pulled count=1 msg=Container image ""busybox:musl"" already present on machine"
0.1698,Event,ADDED,eval-conflicts-rho005-r1-045-f56nk.18d465243a948c16,reason=Created count=1 msg=Created container: task
0.1699,Event,ADDED,eval-conflicts-rho005-r1-045-f56nk.18d465243c81a9ae,reason=Started count=1 msg=Started container task
0.1703,Event,ADDED,eval-conflicts-rho005-r1-045.18d465241f9dddb4,reason=SuccessfulCreate count=1 msg=Created pod: eval-conflicts-rho005-r1-045-f56nk
0.1705,Event,ADDED,eval-conflicts-rho005-r1-045.18d465275e1ad3b9,reason=Completed count=1 msg=Job completed
0.1707,Event,ADDED,eval-conflicts-rho005-r1-046-2stbm.18d465245c06f457,reason=Scheduled count=None msg=Successfully assigned compute/eval-conflicts-rho005-r1-046-2stbm to kind-worker2
0.171,Event,ADDED,eval-conflicts-rho005-r1-046-2stbm.18d4652474182b33,"reason=Pulled count=1 msg=Container image ""busybox:musl"" already present on machine"
0.1712,Event,ADDED,eval-conflicts-rho005-r1-046-2stbm.18d46524752be352,reason=Created count=1 msg=Created container: task
0.1714,Event,ADDED,eval-conflicts-rho005-r1-046-2stbm.18d46524790f469b,reason=Started count=1 msg=Started container task
0.1716,Event,ADDED,eval-conflicts-rho005-r1-046.18d465245b2388d7,reason=SuccessfulCreate count=1 msg=Created pod: eval-conflicts-rho005-r1-046-2stbm
0.1719,Event,ADDED,eval-conflicts-rho005-r1-046.18d4652785c68487,reason=Completed count=1 msg=Job completed
0.1722,Event,ADDED,eval-conflicts-rho005-r1-047-lq78v.18d4652499990871,reason=Scheduled count=None msg=Successfully assigned compute/eval-conflicts-rho005-r1-047-lq78v to kind-worker2
0.1724,Event,ADDED,eval-conflicts-rho005-r1-047-lq78v.18d46524b20bd10e,"reason=Pulled count=1 msg=Container image ""busybox:musl"" already present on machine"
0.1726,Event,ADDED,eval-conflicts-rho005-r1-047-lq78v.18d46524b31a4eb1,reason=Created count=1 msg=Created container: task
0.1728,Event,ADDED,eval-conflicts-rho005-r1-047-lq78v.18d46524b553c27c,reason=Started count=1 msg=Started container task
0.173,Event,ADDED,eval-conflicts-rho005-r1-047.18d465249858c1e2,reason=SuccessfulCreate count=1 msg=Created pod: eval-conflicts-rho005-r1-047-lq78v
0.1732,Event,ADDED,eval-conflicts-rho005-r1-047.18d46527c1ef5401,reason=Completed count=1 msg=Job completed
0.1733,Event,ADDED,eval-conflicts-rho005-r1-048-nn2jm.18d46524d3d32625,reason=Scheduled count=None msg=Successfully assigned compute/eval-conflicts-rho005-r1-048-nn2jm to kind-worker2
0.1735,Event,ADDED,eval-conflicts-rho005-r1-048-nn2jm.18d46524ecd7a388,"reason=Pulled count=1 msg=Container image ""busybox:musl"" already present on machine"
0.1737,Event,ADDED,eval-conflicts-rho005-r1-048-nn2jm.18d46524ee02e6a5,reason=Created count=1 msg=Created container: task
0.1738,Event,ADDED,eval-conflicts-rho005-r1-048-nn2jm.18d46524f01a08b8,reason=Started count=1 msg=Started container task
0.174,Event,ADDED,eval-conflicts-rho005-r1-048.18d46524d27e8c1a,reason=SuccessfulCreate count=1 msg=Created pod: eval-conflicts-rho005-r1-048-nn2jm
0.1742,Event,ADDED,eval-conflicts-rho005-r1-048.18d46527fdf51f6f,reason=Completed count=1 msg=Job completed
0.1743,Event,ADDED,eval-conflicts-rho005-r1-049-v7w7h.18d465250f4aa497,reason=Scheduled count=None msg=Successfully assigned compute/eval-conflicts-rho005-r1-049-v7w7h to kind-worker
0.1745,Event,ADDED,eval-conflicts-rho005-r1-049-v7w7h.18d46525290eb7e6,"reason=Pulled count=1 msg=Container image ""busybox:musl"" already present on machine"
0.1747,Event,ADDED,eval-conflicts-rho005-r1-049-v7w7h.18d465252a17ca75,reason=Created count=1 msg=Created container: task
0.1748,Event,ADDED,eval-conflicts-rho005-r1-049-v7w7h.18d465252c112059,reason=Started count=1 msg=Started container task
0.175,Event,ADDED,eval-conflicts-rho005-r1-049.18d465250e2fa04d,reason=SuccessfulCreate count=1 msg=Created pod: eval-conflicts-rho005-r1-049-v7w7h
0.1752,Event,ADDED,eval-conflicts-rho005-r1-049.18d465284d0e0b21,reason=Completed count=1 msg=Job completed
0.1753,Event,ADDED,eval-conflicts-rho005-r1-050-hw2qt.18d465254b613909,reason=Scheduled count=None msg=Successfully assigned compute/eval-conflicts-rho005-r1-050-hw2qt to kind-worker2
0.1755,Event,ADDED,eval-conflicts-rho005-r1-050-hw2qt.18d4652564c46c89,"reason=Pulled count=1 msg=Container image ""busybox:musl"" already present on machine"
0.1757,Event,ADDED,eval-conflicts-rho005-r1-050-hw2qt.18d4652565ed38d5,reason=Created count=1 msg=Created container: task
0.1758,Event,ADDED,eval-conflicts-rho005-r1-050-hw2qt.18d465256a2f5b51,reason=Started count=1 msg=Started container task
0.176,Event,ADDED,eval-conflicts-rho005-r1-050.18d465254aa95c3e,reason=SuccessfulCreate count=1 msg=Created pod: eval-conflicts-rho005-r1-050-hw2qt
0.1762,Event,ADDED,eval-conflicts-rho005-r1-050.18d46528753eaef5,reason=Completed count=1 msg=Job completed
0.1764,Event,ADDED,eval-conflicts-rho005-r1-051-qf94w.18d4652585eead1e,reason=Scheduled count=None msg=Successfully assigned compute/eval-conflicts-rho005-r1-051-qf94w to kind-worker
0.1766,Event,ADDED,eval-conflicts-rho005-r1-051-qf94w.18d465259f61c403,"reason=Pulled count=1 msg=Container image ""busybox:musl"" already present on machine"
0.1767,Event,ADDED,eval-conflicts-rho005-r1-051-qf94w.18d46525a093067f,reason=Created count=1 msg=Created container: task
0.1769,Event,ADDED,eval-conflicts-rho005-r1-051-qf94w.18d46525a2ffce0b,reason=Started count=1 msg=Started container task
0.1771,Event,ADDED,eval-conflicts-rho005-r1-051.18d4652585406c3d,reason=SuccessfulCreate count=1 msg=Created pod: eval-conflicts-rho005-r1-051-qf94w
0.1773,Event,ADDED,eval-conflicts-rho005-r1-051.18d46528c5f3a532,reason=Completed count=1 msg=Job completed
0.1774,Event,ADDED,eval-conflicts-rho005-r1-052-4lvf6.18d46525c1b8d71a,reason=Scheduled count=None msg=Successfully assigned compute/eval-conflicts-rho005-r1-052-4lvf6 to kind-worker2
0.1776,Event,ADDED,eval-conflicts-rho005-r1-052-4lvf6.18d46525dcc972ae,"reason=Pulled count=1 msg=Container image ""busybox:musl"" already present on machine"
0.1778,Event,ADDED,eval-conflicts-rho005-r1-052-4lvf6.18d46525ddf2af5e,reason=Created count=1 msg=Created container: task
0.178,Event,ADDED,eval-conflicts-rho005-r1-052-4lvf6.18d46525e30973d5,reason=Started count=1 msg=Started container task
0.1781,Event,ADDED,eval-conflicts-rho005-r1-052.18d46525c0c55477,reason=SuccessfulCreate count=1 msg=Created pod: eval-conflicts-rho005-r1-052-4lvf6
0.1783,Event,ADDED,eval-conflicts-rho005-r1-052.18d465292915556f,reason=Completed count=1 msg=Job completed
0.1785,Event,ADDED,eval-conflicts-rho005-r1-053-klxmw.18d46525fdd91f37,reason=Scheduled count=None msg=Successfully assigned compute/eval-conflicts-rho005-r1-053-klxmw to kind-worker2
0.1786,Event,ADDED,eval-conflicts-rho005-r1-053-klxmw.18d465261717462f,"reason=Pulled count=1 msg=Container image ""busybox:musl"" already present on machine"
0.1788,Event,ADDED,eval-conflicts-rho005-r1-053-klxmw.18d46526183970a0,reason=Created count=1 msg=Created container: task
0.179,Event,ADDED,eval-conflicts-rho005-r1-053-klxmw.18d465261a6401ed,reason=Started count=1 msg=Started container task
0.1791,Event,ADDED,eval-conflicts-rho005-r1-053.18d46525fd5a5c0d,reason=SuccessfulCreate count=1 msg=Created pod: eval-conflicts-rho005-r1-053-klxmw
0.1793,Event,ADDED,eval-conflicts-rho005-r1-053.18d4652929c862f4,reason=Completed count=1 msg=Job completed
0.1794,Event,ADDED,eval-conflicts-rho005-r1-054-gv87s.18d4652638b90407,reason=Scheduled count=None msg=Successfully assigned compute/eval-conflicts-rho005-r1-054-gv87s to kind-worker2
0.1796,Event,ADDED,eval-conflicts-rho005-r1-054-gv87s.18d465265307339d,"reason=Pulled count=1 msg=Container image ""busybox:musl"" already present on machine"
0.1798,Event,ADDED,eval-conflicts-rho005-r1-054-gv87s.18d465265431cfd5,reason=Created count=1 msg=Created container: task
0.18,Event,ADDED,eval-conflicts-rho005-r1-054-gv87s.18d465265657caa0,reason=Started count=1 msg=Started container task
0.1804,Event,ADDED,eval-conflicts-rho005-r1-054.18d465263832a94b,reason=SuccessfulCreate count=1 msg=Created pod: eval-conflicts-rho005-r1-054-gv87s
0.1806,Event,ADDED,eval-conflicts-rho005-r1-054.18d465296517376d,reason=Completed count=1 msg=Job completed
0.1807,Event,ADDED,eval-conflicts-rho005-r1-055-2kvx2.18d4652674d2a977,reason=Scheduled count=None msg=Successfully assigned compute/eval-conflicts-rho005-r1-055-2kvx2 to kind-worker2
0.1809,Event,ADDED,eval-conflicts-rho005-r1-055-2kvx2.18d465268d9bcb8f,"reason=Pulled count=1 msg=Container image ""busybox:musl"" already present on machine"
0.1812,Event,ADDED,eval-conflicts-rho005-r1-055-2kvx2.18d465268eeaf474,reason=Created count=1 msg=Created container: task
0.1814,Event,ADDED,eval-conflicts-rho005-r1-055-2kvx2.18d46526933c4ac0,reason=Started count=1 msg=Started container task
0.1816,Event,ADDED,eval-conflicts-rho005-r1-055.18d465267434a572,reason=SuccessfulCreate count=1 msg=Created pod: eval-conflicts-rho005-r1-055-2kvx2
0.1819,Event,ADDED,eval-conflicts-rho005-r1-055.18d46529a0d57913,reason=Completed count=1 msg=Job completed
0.182,Event,ADDED,eval-conflicts-rho005-r1-056-6m2xk.18d46526af49fde7,"reason=FailedScheduling count=None msg=0/6 nodes are available: 6 node(s) had untolerated taint(s). no new claims to deallocate, preemption: 0/6 nodes are available: 6 Preemption is not helpful for scheduling."
0.1822,Event,ADDED,eval-conflicts-rho005-r1-056-6m2xk.18d4652795184e83,reason=Scheduled count=None msg=Successfully assigned compute/eval-conflicts-rho005-r1-056-6m2xk to kind-worker5
0.1824,Event,ADDED,eval-conflicts-rho005-r1-056-6m2xk.18d46527b18efd22,"reason=Pulled count=1 msg=Container image ""busybox:musl"" already present on machine"
0.1827,Event,ADDED,eval-conflicts-rho005-r1-056-6m2xk.18d46527b3ab65dd,reason=Created count=1 msg=Created container: task
0.1828,Event,ADDED,eval-conflicts-rho005-r1-056-6m2xk.18d46527b79a1706,reason=Started count=1 msg=Started container task
0.183,Event,ADDED,eval-conflicts-rho005-r1-056.18d46526af3d08f4,reason=SuccessfulCreate count=1 msg=Created pod: eval-conflicts-rho005-r1-056-6m2xk
0.1832,Event,ADDED,eval-conflicts-rho005-r1-056.18d4652aee60b725,reason=Completed count=1 msg=Job completed
0.1835,Event,ADDED,eval-conflicts-rho005-r1-057-mc7mn.18d46526eac6f42a,"reason=FailedScheduling count=None msg=0/6 nodes are available: 6 node(s) had untolerated taint(s). no new claims to deallocate, preemption: 0/6 nodes are available: 6 Preemption is not helpful for scheduling."
0.1837,Event,ADDED,eval-conflicts-rho005-r1-057-mc7mn.18d465279552d146,reason=Scheduled count=None msg=Successfully assigned compute/eval-conflicts-rho005-r1-057-mc7mn to kind-worker5
0.1839,Event,ADDED,eval-conflicts-rho005-r1-057-mc7mn.18d46527b28ff77a,"reason=Pulled count=1 msg=Container image ""busybox:musl"" already present on machine"
0.1842,Event,ADDED,eval-conflicts-rho005-r1-057-mc7mn.18d46527b5742d9b,reason=Created count=1 msg=Created container: task
0.1844,Event,ADDED,eval-conflicts-rho005-r1-057-mc7mn.18d46527b8a5a2a7,reason=Started count=1 msg=Started container task
0.1845,Event,ADDED,eval-conflicts-rho005-r1-057.18d46526eabe298c,reason=SuccessfulCreate count=1 msg=Created pod: eval-conflicts-rho005-r1-057-mc7mn
0.1847,Event,ADDED,eval-conflicts-rho005-r1-057.18d4652aee327077,reason=Completed count=1 msg=Job completed
0.185,Event,ADDED,eval-conflicts-rho005-r1-058-nzshk.18d46527266a87fe,"reason=FailedScheduling count=None msg=0/6 nodes are available: 6 node(s) had untolerated taint(s). no new claims to deallocate, preemption: 0/6 nodes are available: 6 Preemption is not helpful for scheduling."
0.1851,Event,ADDED,eval-conflicts-rho005-r1-058-nzshk.18d46527958d550c,reason=Scheduled count=None msg=Successfully assigned compute/eval-conflicts-rho005-r1-058-nzshk to kind-worker5
0.1853,Event,ADDED,eval-conflicts-rho005-r1-058-nzshk.18d46527b274b72b,"reason=Pulled count=1 msg=Container image ""busybox:musl"" already present on machine"
0.1856,Event,ADDED,eval-conflicts-rho005-r1-058-nzshk.18d46527b54ec156,reason=Created count=1 msg=Created container: task
0.1858,Event,ADDED,eval-conflicts-rho005-r1-058-nzshk.18d46527b872f39c,reason=Started count=1 msg=Started container task
0.186,Event,ADDED,eval-conflicts-rho005-r1-058.18d46527265ffae1,reason=SuccessfulCreate count=1 msg=Created pod: eval-conflicts-rho005-r1-058-nzshk
0.1862,Event,ADDED,eval-conflicts-rho005-r1-058.18d4652aee602d85,reason=Completed count=1 msg=Job completed
0.1864,Event,ADDED,eval-conflicts-rho005-r1-059-wf87z.18d4652762207cb8,"reason=FailedScheduling count=None msg=0/6 nodes are available: 6 node(s) had untolerated taint(s). no new claims to deallocate, preemption: 0/6 nodes are available: 6 Preemption is not helpful for scheduling."
0.1866,Event,ADDED,eval-conflicts-rho005-r1-059-wf87z.18d4652795e5497a,reason=Scheduled count=None msg=Successfully assigned compute/eval-conflicts-rho005-r1-059-wf87z to kind-worker5
0.1868,Event,ADDED,eval-conflicts-rho005-r1-059-wf87z.18d46527b2b53753,"reason=Pulled count=1 msg=Container image ""busybox:musl"" already present on machine"
0.187,Event,ADDED,eval-conflicts-rho005-r1-059-wf87z.18d46527b5c8e5d5,reason=Created count=1 msg=Created container: task
0.1872,Event,ADDED,eval-conflicts-rho005-r1-059-wf87z.18d46527b8cb6db1,reason=Started count=1 msg=Started container task
0.1874,Event,ADDED,eval-conflicts-rho005-r1-059.18d46527620c9b61,reason=SuccessfulCreate count=1 msg=Created pod: eval-conflicts-rho005-r1-059-wf87z
0.1875,Event,ADDED,eval-conflicts-rho005-r1-059.18d4652aee5f3507,reason=Completed count=1 msg=Job completed
0.1877,Event,ADDED,eval-conflicts-rho005-r1-060-nk8vs.18d465279e9401b0,reason=Scheduled count=None msg=Successfully assigned compute/eval-conflicts-rho005-r1-060-nk8vs to kind-worker5
0.1879,Event,ADDED,eval-conflicts-rho005-r1-060-nk8vs.18d46527b982e0cf,"reason=Pulled count=1 msg=Container image ""busybox:musl"" already present on machine"
0.1881,Event,ADDED,eval-conflicts-rho005-r1-060-nk8vs.18d46527ba98cbe5,reason=Created count=1 msg=Created container: task
0.1883,Event,ADDED,eval-conflicts-rho005-r1-060-nk8vs.18d46527be566845,reason=Started count=1 msg=Started container task
0.1886,Event,ADDED,eval-conflicts-rho005-r1-060.18d465279e14746f,reason=SuccessfulCreate count=1 msg=Created pod: eval-conflicts-rho005-r1-060-nk8vs
0.1887,Event,ADDED,eval-conflicts-rho005-r1-060.18d4652aeebd4952,reason=Completed count=1 msg=Job completed
0.1889,Event,ADDED,eval-conflicts-rho005-r1-061-fzgh4.18d46527da821681,reason=Scheduled count=None msg=Successfully assigned compute/eval-conflicts-rho005-r1-061-fzgh4 to kind-worker3
0.1892,Event,ADDED,eval-conflicts-rho005-r1-061-fzgh4.18d46527f4abce17,"reason=Pulled count=1 msg=Container image ""busybox:musl"" already present on machine"
0.1893,Event,ADDED,eval-conflicts-rho005-r1-061-fzgh4.18d46527f5d834b1,reason=Created count=1 msg=Created container: task
0.1895,Event,ADDED,eval-conflicts-rho005-r1-061-fzgh4.18d46527fa0cc40e,reason=Started count=1 msg=Started container task
0.1897,Event,ADDED,eval-conflicts-rho005-r1-061.18d46527d9818961,reason=SuccessfulCreate count=1 msg=Created pod: eval-conflicts-rho005-r1-061-fzgh4
0.1901,Event,ADDED,eval-conflicts-rho005-r1-061.18d4652b1d321d3e,reason=Completed count=1 msg=Job completed
0.1903,Event,ADDED,eval-conflicts-rho005-r1-062-frnmc.18d4652816d468f8,reason=Scheduled count=None msg=Successfully assigned compute/eval-conflicts-rho005-r1-062-frnmc to kind-worker5
0.1905,Event,ADDED,eval-conflicts-rho005-r1-062-frnmc.18d46528306ef550,"reason=Pulled count=1 msg=Container image ""busybox:musl"" already present on machine"
0.1907,Event,ADDED,eval-conflicts-rho005-r1-062-frnmc.18d465283188f513,reason=Created count=1 msg=Created container: task
0.191,Event,ADDED,eval-conflicts-rho005-r1-062-frnmc.18d46528353a453d,reason=Started count=1 msg=Started container task
0.1912,Event,ADDED,eval-conflicts-rho005-r1-062.18d4652815ddd385,reason=SuccessfulCreate count=1 msg=Created pod: eval-conflicts-rho005-r1-062-frnmc
0.1914,Event,ADDED,eval-conflicts-rho005-r1-062.18d4652b65d8a6bc,reason=Completed count=1 msg=Job completed
0.1917,Event,ADDED,eval-conflicts-rho005-r1-063-xvrs2.18d465285199215a,reason=Scheduled count=None msg=Successfully assigned compute/eval-conflicts-rho005-r1-063-xvrs2 to kind-worker4
0.1919,Event,ADDED,eval-conflicts-rho005-r1-063-xvrs2.18d465286c071170,"reason=Pulled count=1 msg=Container image ""busybox:musl"" already present on machine"
0.1923,Event,ADDED,eval-conflicts-rho005-r1-063-xvrs2.18d465286d33dd43,reason=Created count=1 msg=Created container: task
0.1925,Event,ADDED,eval-conflicts-rho005-r1-063-xvrs2.18d465287206a661,reason=Started count=1 msg=Started container task
0.1927,Event,ADDED,eval-conflicts-rho005-r1-063.18d46528509a4c10,reason=SuccessfulCreate count=1 msg=Created pod: eval-conflicts-rho005-r1-063-xvrs2
0.1929,Event,ADDED,eval-conflicts-rho005-r1-063.18d4652b9b00b353,reason=Completed count=1 msg=Job completed
0.1931,Event,ADDED,eval-conflicts-rho005-r1-064-th4n6.18d465288d4b59d4,reason=Scheduled count=None msg=Successfully assigned compute/eval-conflicts-rho005-r1-064-th4n6 to kind-worker4
0.1934,Event,ADDED,eval-conflicts-rho005-r1-064-th4n6.18d46528a65c4b26,"reason=Pulled count=1 msg=Container image ""busybox:musl"" already present on machine"
0.1936,Event,ADDED,eval-conflicts-rho005-r1-064-th4n6.18d46528a7833e91,reason=Created count=1 msg=Created container: task
0.1939,Event,ADDED,eval-conflicts-rho005-r1-064-th4n6.18d46528abdb1e10,reason=Started count=1 msg=Started container task
0.1941,Event,ADDED,eval-conflicts-rho005-r1-064.18d465288c24b08c,reason=SuccessfulCreate count=1 msg=Created pod: eval-conflicts-rho005-r1-064-th4n6
0.1942,Event,ADDED,eval-conflicts-rho005-r1-064.18d4652bd6c024bc,reason=Completed count=1 msg=Job completed
0.1944,Event,ADDED,eval-conflicts-rho005-r1-065-bv9lg.18d46528c94dfc82,reason=Scheduled count=None msg=Successfully assigned compute/eval-conflicts-rho005-r1-065-bv9lg to kind-worker4
0.1946,Event,ADDED,eval-conflicts-rho005-r1-065-bv9lg.18d46528e2cf341f,"reason=Pulled count=1 msg=Container image ""busybox:musl"" already present on machine"
0.1948,Event,ADDED,eval-conflicts-rho005-r1-065-bv9lg.18d46528e3e467ee,reason=Created count=1 msg=Created container: task
0.1949,Event,ADDED,eval-conflicts-rho005-r1-065-bv9lg.18d46528e8f2c250,reason=Started count=1 msg=Started container task
0.1951,Event,ADDED,eval-conflicts-rho005-r1-065.18d46528c80997e6,reason=SuccessfulCreate count=1 msg=Created pod: eval-conflicts-rho005-r1-065-bv9lg
0.1953,Event,ADDED,eval-conflicts-rho005-r1-065.18d4652c124e082a,reason=Completed count=1 msg=Job completed
0.1955,Event,ADDED,eval-conflicts-rho005-r1-066-89gnx.18d4652904f7e05e,reason=Scheduled count=None msg=Successfully assigned compute/eval-conflicts-rho005-r1-066-89gnx to kind-worker3
0.1957,Event,ADDED,eval-conflicts-rho005-r1-066-89gnx.18d465291ed090b0,"reason=Pulled count=1 msg=Container image ""busybox:musl"" already present on machine"
0.196,Event,ADDED,eval-conflicts-rho005-r1-066-89gnx.18d465291ff8c5fa,reason=Created count=1 msg=Created container: task
0.1962,Event,ADDED,eval-conflicts-rho005-r1-066-89gnx.18d46529244bb0f4,reason=Started count=1 msg=Started container task
0.1964,Event,ADDED,eval-conflicts-rho005-r1-066.18d4652903bdc9a0,reason=SuccessfulCreate count=1 msg=Created pod: eval-conflicts-rho005-r1-066-89gnx
0.1966,Event,ADDED,eval-conflicts-rho005-r1-066.18d4652c47b999a1,reason=Completed count=1 msg=Job completed
0.1968,Event,ADDED,eval-conflicts-rho005-r1-067-msvdm.18d46529410c6354,reason=Scheduled count=None msg=Successfully assigned compute/eval-conflicts-rho005-r1-067-msvdm to kind-worker4
0.197,Event,ADDED,eval-conflicts-rho005-r1-067-msvdm.18d465295a2114a8,"reason=Pulled count=1 msg=Container image ""busybox:musl"" already present on machine"
0.1972,Event,ADDED,eval-conflicts-rho005-r1-067-msvdm.18d465295b3289f6,reason=Created count=1 msg=Created container: task
0.1975,Event,ADDED,eval-conflicts-rho005-r1-067-msvdm.18d465295e190234,reason=Started count=1 msg=Started container task
0.1977,Event,ADDED,eval-conflicts-rho005-r1-067.18d465293fd24f17,reason=SuccessfulCreate count=1 msg=Created pod: eval-conflicts-rho005-r1-067-msvdm
0.1979,Event,ADDED,eval-conflicts-rho005-r1-067.18d4652c8b113072,reason=Completed count=1 msg=Job completed
0.198,Event,ADDED,eval-conflicts-rho005-r1-068-7l2md.18d465297be63fee,reason=Scheduled count=None msg=Successfully assigned compute/eval-conflicts-rho005-r1-068-7l2md to kind-worker5
0.1985,Event,ADDED,eval-conflicts-rho005-r1-068-7l2md.18d465299583ee1a,"reason=Pulled count=1 msg=Container image ""busybox:musl"" already present on machine"
0.1988,Event,ADDED,eval-conflicts-rho005-r1-068-7l2md.18d4652996af1daa,reason=Created count=1 msg=Created container: task
0.1991,Event,ADDED,eval-conflicts-rho005-r1-068-7l2md.18d4652998cd41bd,reason=Started count=1 msg=Started container task
0.1995,Event,ADDED,eval-conflicts-rho005-r1-068.18d465297a8a8251,reason=SuccessfulCreate count=1 msg=Created pod: eval-conflicts-rho005-r1-068-7l2md
0.1999,Event,ADDED,eval-conflicts-rho005-r1-068.18d4652ccbe86b5f,reason=Completed count=1 msg=Job completed
0.2001,Event,ADDED,eval-conflicts-rho005-r1-069-tt9cw.18d46529b7e2e5d9,reason=Scheduled count=None msg=Successfully assigned compute/eval-conflicts-rho005-r1-069-tt9cw to kind-worker4
0.2003,Event,ADDED,eval-conflicts-rho005-r1-069-tt9cw.18d46529d2f670e6,"reason=Pulled count=1 msg=Container image ""busybox:musl"" already present on machine"
0.2006,Event,ADDED,eval-conflicts-rho005-r1-069-tt9cw.18d46529d408be12,reason=Created count=1 msg=Created container: task
0.2008,Event,ADDED,eval-conflicts-rho005-r1-069-tt9cw.18d46529d882decc,reason=Started count=1 msg=Started container task
0.201,Event,ADDED,eval-conflicts-rho005-r1-069.18d46529b6533ac6,reason=SuccessfulCreate count=1 msg=Created pod: eval-conflicts-rho005-r1-069-tt9cw
0.2011,Event,ADDED,eval-conflicts-rho005-r1-069.18d4652d02f63777,reason=Completed count=1 msg=Job completed
0.2014,Event,ADDED,eval-conflicts-rho005-r1-070-ptnqz.18d46529f2dbac92,reason=Scheduled count=None msg=Successfully assigned compute/eval-conflicts-rho005-r1-070-ptnqz to kind-worker3
0.2016,Event,ADDED,eval-conflicts-rho005-r1-070-ptnqz.18d4652a0cbfc43c,"reason=Pulled count=1 msg=Container image ""busybox:musl"" already present on machine"
0.2018,Event,ADDED,eval-conflicts-rho005-r1-070-ptnqz.18d4652a0e27a996,reason=Created count=1 msg=Created container: task
0.202,Event,ADDED,eval-conflicts-rho005-r1-070-ptnqz.18d4652a118025a6,reason=Started count=1 msg=Started container task
0.2023,Event,ADDED,eval-conflicts-rho005-r1-070.18d46529f1ef516d,reason=SuccessfulCreate count=1 msg=Created pod: eval-conflicts-rho005-r1-070-ptnqz
0.2025,Event,ADDED,eval-conflicts-rho005-r1-070.18d4652d3713a116,reason=Completed count=1 msg=Job completed
0.2026,Event,ADDED,eval-conflicts-rho005-r1-071-xdcgj.18d4652a2e9f7b77,reason=Scheduled count=None msg=Successfully assigned compute/eval-conflicts-rho005-r1-071-xdcgj to kind-worker4
0.2029,Event,ADDED,eval-conflicts-rho005-r1-071-xdcgj.18d4652a4827335d,"reason=Pulled count=1 msg=Container image ""busybox:musl"" already present on machine"
0.2031,Event,ADDED,eval-conflicts-rho005-r1-071-xdcgj.18d4652a49b27bf3,reason=Created count=1 msg=Created container: task
0.2032,Event,ADDED,eval-conflicts-rho005-r1-071-xdcgj.18d4652a4b85eedf,reason=Started count=1 msg=Started container task
0.2034,Event,ADDED,eval-conflicts-rho005-r1-071.18d4652a2dd68143,reason=SuccessfulCreate count=1 msg=Created pod: eval-conflicts-rho005-r1-071-xdcgj
0.2036,Event,ADDED,eval-conflicts-rho005-r1-071.18d4652d7a53a08d,reason=Completed count=1 msg=Job completed
0.2037,Event,ADDED,eval-conflicts-rho005-r1-072-kk2kr.18d4652a6a05b05b,reason=Scheduled count=None msg=Successfully assigned compute/eval-conflicts-rho005-r1-072-kk2kr to kind-worker4
0.2039,Event,ADDED,eval-conflicts-rho005-r1-072-kk2kr.18d4652a8305ef0b,"reason=Pulled count=1 msg=Container image ""busybox:musl"" already present on machine"
0.2041,Event,ADDED,eval-conflicts-rho005-r1-072-kk2kr.18d4652a841b1247,reason=Created count=1 msg=Created container: task
0.2042,Event,ADDED,eval-conflicts-rho005-r1-072-kk2kr.18d4652a861d6b42,reason=Started count=1 msg=Started container task
0.2044,Event,ADDED,eval-conflicts-rho005-r1-072.18d4652a69650c27,reason=SuccessfulCreate count=1 msg=Created pod: eval-conflicts-rho005-r1-072-kk2kr
0.2047,Event,ADDED,eval-conflicts-rho005-r1-072.18d4652db566dadb,reason=Completed count=1 msg=Job completed
0.2049,Event,ADDED,eval-conflicts-rho005-r1-073-58hht.18d4652aa56b09a6,reason=Scheduled count=None msg=Successfully assigned compute/eval-conflicts-rho005-r1-073-58hht to kind-worker
0.2051,Event,ADDED,eval-conflicts-rho005-r1-073-58hht.18d4652abf78e2a2,"reason=Pulled count=1 msg=Container image ""busybox:musl"" already present on machine"
0.2053,Event,ADDED,eval-conflicts-rho005-r1-073-58hht.18d4652ac0c58554,reason=Created count=1 msg=Created container: task
0.2056,Event,ADDED,eval-conflicts-rho005-r1-073-58hht.18d4652ac463ada3,reason=Started count=1 msg=Started container task
0.2058,Event,ADDED,eval-conflicts-rho005-r1-073.18d4652aa4f9eba7,reason=SuccessfulCreate count=1 msg=Created pod: eval-conflicts-rho005-r1-073-58hht
0.206,Event,ADDED,eval-conflicts-rho005-r1-073.18d4652de7930a8e,reason=Completed count=1 msg=Job completed
0.2061,Event,ADDED,eval-conflicts-rho005-r1-074-8l6xj.18d4652ae0cb1e38,reason=Scheduled count=None msg=Successfully assigned compute/eval-conflicts-rho005-r1-074-8l6xj to kind-worker
0.2064,Event,ADDED,eval-conflicts-rho005-r1-074-8l6xj.18d4652afb60febf,"reason=Pulled count=1 msg=Container image ""busybox:musl"" already present on machine"
0.2066,Event,ADDED,eval-conflicts-rho005-r1-074-8l6xj.18d4652afc978abf,reason=Created count=1 msg=Created container: task
0.2068,Event,ADDED,eval-conflicts-rho005-r1-074-8l6xj.18d4652aff6761e7,reason=Started count=1 msg=Started container task
0.207,Event,ADDED,eval-conflicts-rho005-r1-074.18d4652ae040a1d0,reason=SuccessfulCreate count=1 msg=Created pod: eval-conflicts-rho005-r1-074-8l6xj
0.2073,Event,ADDED,eval-conflicts-rho005-r1-074.18d4652de7c5c7f4,reason=Completed count=1 msg=Job completed
0.2074,Event,ADDED,eval-conflicts-rho005-r1-075-s5sxq.18d4652b1c40b7e3,reason=Scheduled count=None msg=Successfully assigned compute/eval-conflicts-rho005-r1-075-s5sxq to kind-worker
0.2076,Event,ADDED,eval-conflicts-rho005-r1-075-s5sxq.18d4652b35f3c5d7,"reason=Pulled count=1 msg=Container image ""busybox:musl"" already present on machine"
0.2078,Event,ADDED,eval-conflicts-rho005-r1-075-s5sxq.18d4652b370df829,reason=Created count=1 msg=Created container: task
0.2081,Event,ADDED,eval-conflicts-rho005-r1-075-s5sxq.18d4652b3bde3c05,reason=Started count=1 msg=Started container task
0.2082,Event,ADDED,eval-conflicts-rho005-r1-075.18d4652b1bb6fa9b,reason=SuccessfulCreate count=1 msg=Created pod: eval-conflicts-rho005-r1-075-s5sxq
0.2084,Event,ADDED,eval-conflicts-rho005-r1-075.18d4652e5f2b69cc,reason=Completed count=1 msg=Job completed
0.2085,Event,ADDED,eval-conflicts-rho005-r1-076-vs292.18d4652b5833d3a4,reason=Scheduled count=None msg=Successfully assigned compute/eval-conflicts-rho005-r1-076-vs292 to kind-worker
0.2087,Event,ADDED,eval-conflicts-rho005-r1-076-vs292.18d4652b719de68f,"reason=Pulled count=1 msg=Container image ""busybox:musl"" already present on machine"
0.2089,Event,ADDED,eval-conflicts-rho005-r1-076-vs292.18d4652b72a45eef,reason=Created count=1 msg=Created container: task
0.209,Event,ADDED,eval-conflicts-rho005-r1-076-vs292.18d4652b7487e823,reason=Started count=1 msg=Started container task
0.2092,Event,ADDED,eval-conflicts-rho005-r1-076.18d4652b57b18ee0,reason=SuccessfulCreate count=1 msg=Created pod: eval-conflicts-rho005-r1-076-vs292
0.2094,Event,ADDED,eval-conflicts-rho005-r1-076.18d4652e9b026dfd,reason=Completed count=1 msg=Job completed
0.2095,Event,ADDED,eval-conflicts-rho005-r1-077-9fvdk.18d4652b93eb8d74,reason=Scheduled count=None msg=Successfully assigned compute/eval-conflicts-rho005-r1-077-9fvdk to kind-worker2
0.2098,Event,ADDED,eval-conflicts-rho005-r1-077-9fvdk.18d4652bae0dc309,"reason=Pulled count=1 msg=Container image ""busybox:musl"" already present on machine"
0.21,Event,ADDED,eval-conflicts-rho005-r1-077-9fvdk.18d4652baf1e8e03,reason=Created count=1 msg=Created container: task
0.2102,Event,ADDED,eval-conflicts-rho005-r1-077-9fvdk.18d4652bb10f70b9,reason=Started count=1 msg=Started container task
0.2103,Event,ADDED,eval-conflicts-rho005-r1-077.18d4652b92dfbea0,reason=SuccessfulCreate count=1 msg=Created pod: eval-conflicts-rho005-r1-077-9fvdk
0.2107,Event,ADDED,eval-conflicts-rho005-r1-077.18d4652ec40bb400,reason=Completed count=1 msg=Job completed
0.211,Event,ADDED,eval-conflicts-rho005-r1-078-q96gg.18d4652bd0d6ce50,reason=Scheduled count=None msg=Successfully assigned compute/eval-conflicts-rho005-r1-078-q96gg to kind-worker2
0.2112,Event,ADDED,eval-conflicts-rho005-r1-078-q96gg.18d4652be9cdb110,"reason=Pulled count=1 msg=Container image ""busybox:musl"" already present on machine"
0.2114,Event,ADDED,eval-conflicts-rho005-r1-078-q96gg.18d4652beae797f4,reason=Created count=1 msg=Created container: task
0.2118,Event,ADDED,eval-conflicts-rho005-r1-078-q96gg.18d4652bed1151a6,reason=Started count=1 msg=Started container task
0.212,Event,ADDED,eval-conflicts-rho005-r1-078.18d4652bcfa9c0e6,reason=SuccessfulCreate count=1 msg=Created pod: eval-conflicts-rho005-r1-078-q96gg
0.2122,Event,ADDED,eval-conflicts-rho005-r1-078.18d4652eff88cea3,reason=Completed count=1 msg=Job completed
0.2124,Event,ADDED,eval-conflicts-rho005-r1-079-nqnqv.18d4652c0b0f3fc8,reason=Scheduled count=None msg=Successfully assigned compute/eval-conflicts-rho005-r1-079-nqnqv to kind-worker2
0.2126,Event,ADDED,eval-conflicts-rho005-r1-079-nqnqv.18d4652c240da088,"reason=Pulled count=1 msg=Container image ""busybox:musl"" already present on machine"
0.2128,Event,ADDED,eval-conflicts-rho005-r1-079-nqnqv.18d4652c252d4657,reason=Created count=1 msg=Created container: task
0.213,Event,ADDED,eval-conflicts-rho005-r1-079-nqnqv.18d4652c293f6ed1,reason=Started count=1 msg=Started container task
0.2133,Event,ADDED,eval-conflicts-rho005-r1-079.18d4652c0a36175c,reason=SuccessfulCreate count=1 msg=Created pod: eval-conflicts-rho005-r1-079-nqnqv
0.2135,Event,ADDED,eval-conflicts-rho005-r1-079.18d4652f3b636824,reason=Completed count=1 msg=Job completed
0.2137,Event,ADDED,eval-conflicts-rho005-r1-080-vsrms.18d4652c46bd710e,reason=Scheduled count=None msg=Successfully assigned compute/eval-conflicts-rho005-r1-080-vsrms to kind-worker
0.2138,Event,ADDED,eval-conflicts-rho005-r1-080-vsrms.18d4652c60532d47,"reason=Pulled count=1 msg=Container image ""busybox:musl"" already present on machine"
0.2141,Event,ADDED,eval-conflicts-rho005-r1-080-vsrms.18d4652c61619c09,reason=Created count=1 msg=Created container: task
0.2143,Event,ADDED,eval-conflicts-rho005-r1-080-vsrms.18d4652c65ccf5af,reason=Started count=1 msg=Started container task
0.2145,Event,ADDED,eval-conflicts-rho005-r1-080.18d4652c45c38eb5,reason=SuccessfulCreate count=1 msg=Created pod: eval-conflicts-rho005-r1-080-vsrms
0.2147,Event,ADDED,eval-conflicts-rho005-r1-080.18d4652f8a6543cb,reason=Completed count=1 msg=Job completed
0.2149,Event,ADDED,eval-conflicts-rho005-r1-081-hbrdr.18d4652c82bf942e,reason=Scheduled count=None msg=Successfully assigned compute/eval-conflicts-rho005-r1-081-hbrdr to kind-worker2
0.2151,Event,ADDED,eval-conflicts-rho005-r1-081-hbrdr.18d4652c9cb91c6e,"reason=Pulled count=1 msg=Container image ""busybox:musl"" already present on machine"
0.2152,Event,ADDED,eval-conflicts-rho005-r1-081-hbrdr.18d4652c9dd9b8f6,reason=Created count=1 msg=Created container: task
0.2154,Event,ADDED,eval-conflicts-rho005-r1-081-hbrdr.18d4652ca0c79cc9,reason=Started count=1 msg=Started container task
0.2156,Event,ADDED,eval-conflicts-rho005-r1-081.18d4652c81c826c3,reason=SuccessfulCreate count=1 msg=Created pod: eval-conflicts-rho005-r1-081-hbrdr
0.2158,Event,ADDED,eval-conflicts-rho005-r1-081.18d4652fb2b47389,reason=Completed count=1 msg=Job completed
0.2159,Event,ADDED,eval-conflicts-rho005-r1-082-2glzb.18d4652cbead97fc,"reason=FailedScheduling count=None msg=0/6 nodes are available: 2 c_wall violated: 1 conflicting context pair(s) with node memory, 4 node(s) had untolerated taint(s). no new claims to deallocate, preemption: 0/6 nodes are available: 2 No preemption victims found for incoming pod, 4 Preemption is not helpful for scheduling."
0.2162,Event,ADDED,eval-conflicts-rho005-r1-082-2glzb.18d4652cbf68e63a,"reason=FailedScheduling count=None msg=0/6 nodes are available: 2 c_wall violated: 1 conflicting context pair(s) with node memory, 4 node(s) had untolerated taint(s). no new claims to deallocate, preemption: 0/6 nodes are available: 2 No preemption victims found for incoming pod, 4 Preemption is not helpful for scheduling."
0.2164,Event,ADDED,eval-conflicts-rho005-r1-082-2glzb.18d4652cef51ad4f,"reason=FailedScheduling count=None msg=0/6 nodes are available: 1 c_wall violated: 1 conflicting context pair(s) with node memory, 5 node(s) had untolerated taint(s). no new claims to deallocate, preemption: 0/6 nodes are available: 1 No preemption victims found for incoming pod, 5 Preemption is not helpful for scheduling."
0.2167,Event,ADDED,eval-conflicts-rho005-r1-082-2glzb.18d4652eb3fcd416,reason=Scheduled count=None msg=Successfully assigned compute/eval-conflicts-rho005-r1-082-2glzb to kind-worker5
0.2168,Event,ADDED,eval-conflicts-rho005-r1-082-2glzb.18d4652ecf43e6e4,"reason=Pulled count=1 msg=Container image ""busybox:musl"" already present on machine"
0.2171,Event,ADDED,eval-conflicts-rho005-r1-082-2glzb.18d4652ed0957495,reason=Created count=1 msg=Created container: task
0.2173,Event,ADDED,eval-conflicts-rho005-r1-082-2glzb.18d4652ed5aab377,reason=Started count=1 msg=Started container task
0.2175,Event,ADDED,eval-conflicts-rho005-r1-082.18d4652cbe2efff8,reason=SuccessfulCreate count=1 msg=Created pod: eval-conflicts-rho005-r1-082-2glzb
0.2176,Event,ADDED,eval-conflicts-rho005-r1-082.18d46531f29c9c53,reason=Completed count=1 msg=Job completed
0.2178,Event,ADDED,eval-conflicts-rho005-r1-083-mtkgg.18d4652cfa75923f,reason=Scheduled count=None msg=Successfully assigned compute/eval-conflicts-rho005-r1-083-mtkgg to kind-worker2
0.2179,Event,ADDED,eval-conflicts-rho005-r1-083-mtkgg.18d4652d140814b7,"reason=Pulled count=1 msg=Container image ""busybox:musl"" already present on machine"
0.2182,Event,ADDED,eval-conflicts-rho005-r1-083-mtkgg.18d4652d15262a26,reason=Created count=1 msg=Created container: task
0.2184,Event,ADDED,eval-conflicts-rho005-r1-083-mtkgg.18d4652d19dd4fa5,reason=Started count=1 msg=Started container task
0.2186,Event,ADDED,eval-conflicts-rho005-r1-083.18d4652cf9600636,reason=SuccessfulCreate count=1 msg=Created pod: eval-conflicts-rho005-r1-083-mtkgg
0.2189,Event,ADDED,eval-conflicts-rho005-r1-083.18d465302a96861b,reason=Completed count=1 msg=Job completed
0.2191,Event,ADDED,eval-conflicts-rho005-r1-084-z8hvw.18d4652d3593cb02,reason=Scheduled count=None msg=Successfully assigned compute/eval-conflicts-rho005-r1-084-z8hvw to kind-worker2
0.2192,Event,ADDED,eval-conflicts-rho005-r1-084-z8hvw.18d4652d4f726ca9,"reason=Pulled count=1 msg=Container image ""busybox:musl"" already present on machine"
0.2194,Event,ADDED,eval-conflicts-rho005-r1-084-z8hvw.18d4652d508b6772,reason=Created count=1 msg=Created container: task
0.2198,Event,ADDED,eval-conflicts-rho005-r1-084-z8hvw.18d4652d52b0f98e,reason=Started count=1 msg=Started container task
0.2199,Event,ADDED,eval-conflicts-rho005-r1-084.18d4652d350416ee,reason=SuccessfulCreate count=1 msg=Created pod: eval-conflicts-rho005-r1-084-z8hvw
0.2201,Event,ADDED,eval-conflicts-rho005-r1-084.18d465306661dc59,reason=Completed count=1 msg=Job completed
0.2204,Event,ADDED,eval-conflicts-rho005-r1-085-9lzbw.18d4652d707f82b0,reason=Scheduled count=None msg=Successfully assigned compute/eval-conflicts-rho005-r1-085-9lzbw to kind-worker2
0.2206,Event,ADDED,eval-conflicts-rho005-r1-085-9lzbw.18d4652d8a61800c,"reason=Pulled count=1 msg=Container image ""busybox:musl"" already present on machine"
0.2207,Event,ADDED,eval-conflicts-rho005-r1-085-9lzbw.18d4652d8b97f356,reason=Created count=1 msg=Created container: task
0.2209,Event,ADDED,eval-conflicts-rho005-r1-085-9lzbw.18d4652d8db478f7,reason=Started count=1 msg=Started container task
0.2214,Event,ADDED,eval-conflicts-rho005-r1-085.18d4652d6ff3e682,reason=SuccessfulCreate count=1 msg=Created pod: eval-conflicts-rho005-r1-085-9lzbw
0.2216,Event,ADDED,eval-conflicts-rho005-r1-085.18d46530a25619a1,reason=Completed count=1 msg=Job completed
0.2217,Event,ADDED,eval-conflicts-rho005-r1-086-dzcgr.18d4652dac5d97b0,reason=Scheduled count=None msg=Successfully assigned compute/eval-conflicts-rho005-r1-086-dzcgr to kind-worker2
0.2219,Event,ADDED,eval-conflicts-rho005-r1-086-dzcgr.18d4652dc6328259,"reason=Pulled count=1 msg=Container image ""busybox:musl"" already present on machine"
0.2221,Event,ADDED,eval-conflicts-rho005-r1-086-dzcgr.18d4652dc74a4558,reason=Created count=1 msg=Created container: task
0.2223,Event,ADDED,eval-conflicts-rho005-r1-086-dzcgr.18d4652dc9507010,reason=Started count=1 msg=Started container task
0.2224,Event,ADDED,eval-conflicts-rho005-r1-086.18d4652daba80031,reason=SuccessfulCreate count=1 msg=Created pod: eval-conflicts-rho005-r1-086-dzcgr
0.2226,Event,ADDED,eval-conflicts-rho005-r1-086.18d46530dff31c03,reason=Completed count=1 msg=Job completed
0.2227,Event,ADDED,eval-conflicts-rho005-r1-087-jjbk6.18d4652de77116fb,"reason=FailedScheduling count=None msg=0/6 nodes are available: 6 node(s) had untolerated taint(s). no new claims to deallocate, preemption: 0/6 nodes are available: 6 Preemption is not helpful for scheduling."
0.2229,Event,ADDED,eval-conflicts-rho005-r1-087-jjbk6.18d4652eb460d347,reason=Scheduled count=None msg=Successfully assigned compute/eval-conflicts-rho005-r1-087-jjbk6 to kind-worker5
0.2231,Event,ADDED,eval-conflicts-rho005-r1-087-jjbk6.18d4652ed0eb8af0,"reason=Pulled count=1 msg=Container image ""busybox:musl"" already present on machine"
0.2233,Event,ADDED,eval-conflicts-rho005-r1-087-jjbk6.18d4652ed33ae2ef,reason=Created count=1 msg=Created container: task
0.2235,Event,ADDED,eval-conflicts-rho005-r1-087-jjbk6.18d4652ed71ed1f2,reason=Started count=1 msg=Started container task
0.2236,Event,ADDED,eval-conflicts-rho005-r1-087.18d4652de76658e7,reason=SuccessfulCreate count=1 msg=Created pod: eval-conflicts-rho005-r1-087-jjbk6
0.2238,Event,ADDED,eval-conflicts-rho005-r1-087.18d46531b6a04e83,reason=Completed count=1 msg=Job completed
0.224,Event,ADDED,eval-conflicts-rho005-r1-088-pcvk7.18d4652e22dbd537,"reason=FailedScheduling count=None msg=0/6 nodes are available: 6 node(s) had untolerated taint(s). no new claims to deallocate, preemption: 0/6 nodes are available: 6 Preemption is not helpful for scheduling."
0.2241,Event,ADDED,eval-conflicts-rho005-r1-088-pcvk7.18d4652eb4887c79,reason=Scheduled count=None msg=Successfully assigned compute/eval-conflicts-rho005-r1-088-pcvk7 to kind-worker5
0.2243,Event,ADDED,eval-conflicts-rho005-r1-088-pcvk7.18d4652ed12cb183,"reason=Pulled count=1 msg=Container image ""busybox:musl"" already present on machine"
0.2244,Event,ADDED,eval-conflicts-rho005-r1-088-pcvk7.18d4652ed42c469b,reason=Created count=1 msg=Created container: task
0.2246,Event,ADDED,eval-conflicts-rho005-r1-088-pcvk7.18d4652ed73a590b,reason=Started count=1 msg=Started container task
0.2248,Event,ADDED,eval-conflicts-rho005-r1-088.18d4652e22d02489,reason=SuccessfulCreate count=1 msg=Created pod: eval-conflicts-rho005-r1-088-pcvk7
0.2249,Event,ADDED,eval-conflicts-rho005-r1-088.18d46531f2bc70e5,reason=Completed count=1 msg=Job completed
0.2251,Event,ADDED,eval-conflicts-rho005-r1-089-r74d6.18d4652e5e9887be,"reason=FailedScheduling count=None msg=0/6 nodes are available: 6 node(s) had untolerated taint(s). no new claims to deallocate, preemption: 0/6 nodes are available: 6 Preemption is not helpful for scheduling."
0.2253,Event,ADDED,eval-conflicts-rho005-r1-089-r74d6.18d4652eb4be7b5a,reason=Scheduled count=None msg=Successfully assigned compute/eval-conflicts-rho005-r1-089-r74d6 to kind-worker5
0.2254,Event,ADDED,eval-conflicts-rho005-r1-089-r74d6.18d4652ed0db14c7,"reason=Pulled count=1 msg=Container image ""busybox:musl"" already present on machine"
0.2257,Event,ADDED,eval-conflicts-rho005-r1-089-r74d6.18d4652ed2938bc2,reason=Created count=1 msg=Created container: task
0.2259,Event,ADDED,eval-conflicts-rho005-r1-089-r74d6.18d4652ed7024381,reason=Started count=1 msg=Started container task
0.2261,Event,ADDED,eval-conflicts-rho005-r1-089.18d4652e5e8dbb45,reason=SuccessfulCreate count=1 msg=Created pod: eval-conflicts-rho005-r1-089-r74d6
0.2262,Event,ADDED,eval-conflicts-rho005-r1-089.18d46531f279e66c,reason=Completed count=1 msg=Job completed
0.2265,Event,ADDED,eval-conflicts-rho005-r1-090-n9zld.18d4652e9a038ca4,"reason=FailedScheduling count=None msg=0/6 nodes are available: 6 node(s) had untolerated taint(s). no new claims to deallocate, preemption: 0/6 nodes are available: 6 Preemption is not helpful for scheduling."
0.2267,Event,ADDED,eval-conflicts-rho005-r1-090-n9zld.18d4652eb4fa6a67,reason=Scheduled count=None msg=Successfully assigned compute/eval-conflicts-rho005-r1-090-n9zld to kind-worker5
0.2269,Event,ADDED,eval-conflicts-rho005-r1-090-n9zld.18d4652ed10be210,"reason=Pulled count=1 msg=Container image ""busybox:musl"" already present on machine"
0.2272,Event,ADDED,eval-conflicts-rho005-r1-090-n9zld.18d4652ed3f3f851,reason=Created count=1 msg=Created container: task
0.2274,Event,ADDED,eval-conflicts-rho005-r1-090-n9zld.18d4652ed739e034,reason=Started count=1 msg=Started container task
0.2276,Event,ADDED,eval-conflicts-rho005-r1-090.18d4652e99fd80ac,reason=SuccessfulCreate count=1 msg=Created pod: eval-conflicts-rho005-r1-090-n9zld
0.2277,Event,ADDED,eval-conflicts-rho005-r1-090.18d46531f2c064e9,reason=Completed count=1 msg=Job completed
0.228,Event,ADDED,eval-conflicts-rho005-r1-091-kqlh2.18d4652ed68bc2c9,reason=Scheduled count=None msg=Successfully assigned compute/eval-conflicts-rho005-r1-091-kqlh2 to kind-worker3
0.2281,Event,ADDED,eval-conflicts-rho005-r1-091-kqlh2.18d4652eefaeb411,"reason=Pulled count=1 msg=Container image ""busybox:musl"" already present on machine"
0.2283,Event,ADDED,eval-conflicts-rho005-r1-091-kqlh2.18d4652ef0f78fbb,reason=Created count=1 msg=Created container: task
0.2285,Event,ADDED,eval-conflicts-rho005-r1-091-kqlh2.18d4652ef5bf2396,reason=Started count=1 msg=Started container task
0.2286,Event,ADDED,eval-conflicts-rho005-r1-091.18d4652ed5bd180c,reason=SuccessfulCreate count=1 msg=Created pod: eval-conflicts-rho005-r1-091-kqlh2
0.2288,Event,ADDED,eval-conflicts-rho005-r1-091.18d465321e966f2f,reason=Completed count=1 msg=Job completed
0.229,Event,ADDED,eval-conflicts-rho005-r1-092-gz6gn.18d4652f1326c27b,reason=Scheduled count=None msg=Successfully assigned compute/eval-conflicts-rho005-r1-092-gz6gn to kind-worker5
0.2292,Event,ADDED,eval-conflicts-rho005-r1-092-gz6gn.18d4652f2c3cfb08,"reason=Pulled count=1 msg=Container image ""busybox:musl"" already present on machine"
0.2294,Event,ADDED,eval-conflicts-rho005-r1-092-gz6gn.18d4652f2d49de5e,reason=Created count=1 msg=Created container: task
0.2296,Event,ADDED,eval-conflicts-rho005-r1-092-gz6gn.18d4652f3153afc8,reason=Started count=1 msg=Started container task
0.2298,Event,ADDED,eval-conflicts-rho005-r1-092.18d4652f116ee448,reason=SuccessfulCreate count=1 msg=Created pod: eval-conflicts-rho005-r1-092-gz6gn
0.23,Event,ADDED,eval-conflicts-rho005-r1-092.18d4653267574d48,reason=Completed count=1 msg=Job completed
0.2302,Event,ADDED,eval-conflicts-rho005-r1-093-56qsw.18d4652f4e5182ed,reason=Scheduled count=None msg=Successfully assigned compute/eval-conflicts-rho005-r1-093-56qsw to kind-worker3
0.2304,Event,ADDED,eval-conflicts-rho005-r1-093-56qsw.18d4652f670ce33e,"reason=Pulled count=1 msg=Container image ""busybox:musl"" already present on machine"
0.2305,Event,ADDED,eval-conflicts-rho005-r1-093-56qsw.18d4652f68191fe9,reason=Created count=1 msg=Created container: task
0.2307,Event,ADDED,eval-conflicts-rho005-r1-093-56qsw.18d4652f6c8f52ab,reason=Started count=1 msg=Started container task
0.2331,Event,ADDED,eval-conflicts-rho005-r1-093.18d4652f4d38a5a5,reason=SuccessfulCreate count=1 msg=Created pod: eval-conflicts-rho005-r1-093-56qsw
0.2333,Event,ADDED,eval-conflicts-rho005-r1-093.18d465329562ef0a,reason=Completed count=1 msg=Job completed
0.2335,Event,ADDED,eval-conflicts-rho005-r1-094-dfrl7.18d4652f890e5598,reason=Scheduled count=None msg=Successfully assigned compute/eval-conflicts-rho005-r1-094-dfrl7 to kind-worker
0.2338,Event,ADDED,eval-conflicts-rho005-r1-094-dfrl7.18d4652fa2559ab0,"reason=Pulled count=1 msg=Container image ""busybox:musl"" already present on machine"
0.234,Event,ADDED,eval-conflicts-rho005-r1-094-dfrl7.18d4652fa36c6017,reason=Created count=1 msg=Created container: task
0.2342,Event,ADDED,eval-conflicts-rho005-r1-094-dfrl7.18d4652fa84d9ad4,reason=Started count=1 msg=Started container task
0.2344,Event,ADDED,eval-conflicts-rho005-r1-094.18d4652f883f641d,reason=SuccessfulCreate count=1 msg=Created pod: eval-conflicts-rho005-r1-094-dfrl7
0.2346,Event,ADDED,eval-conflicts-rho005-r1-094.18d46532cf93da9c,reason=Completed count=1 msg=Job completed
0.2348,Event,ADDED,eval-conflicts-rho005-r1-095-29mxx.18d4652fc5887dfa,reason=Scheduled count=None msg=Successfully assigned compute/eval-conflicts-rho005-r1-095-29mxx to kind-worker
0.2351,Event,ADDED,eval-conflicts-rho005-r1-095-29mxx.18d4652fde5107b5,"reason=Pulled count=1 msg=Container image ""busybox:musl"" already present on machine"
0.2353,Event,ADDED,eval-conflicts-rho005-r1-095-29mxx.18d4652fdf662d43,reason=Created count=1 msg=Created container: task
0.2354,Event,ADDED,eval-conflicts-rho005-r1-095-29mxx.18d4652fe15e4684,reason=Started count=1 msg=Started container task
0.2356,Event,ADDED,eval-conflicts-rho005-r1-095.18d4652fc43b2a58,reason=SuccessfulCreate count=1 msg=Created pod: eval-conflicts-rho005-r1-095-29mxx
0.236,Event,ADDED,eval-conflicts-rho005-r1-095.18d465330b6f7347,reason=Completed count=1 msg=Job completed
0.2362,Event,ADDED,eval-conflicts-rho005-r1-096-j4xzx.18d46530007d5197,reason=Scheduled count=None msg=Successfully assigned compute/eval-conflicts-rho005-r1-096-j4xzx to kind-worker
0.2364,Event,ADDED,eval-conflicts-rho005-r1-096-j4xzx.18d4653019961463,"reason=Pulled count=1 msg=Container image ""busybox:musl"" already present on machine"
0.2366,Event,ADDED,eval-conflicts-rho005-r1-096-j4xzx.18d465301ab3056c,reason=Created count=1 msg=Created container: task
0.237,Event,ADDED,eval-conflicts-rho005-r1-096-j4xzx.18d465301e7ed4b8,reason=Started count=1 msg=Started container task
0.2372,Event,ADDED,eval-conflicts-rho005-r1-096.18d4652fff6fc92f,reason=SuccessfulCreate count=1 msg=Created pod: eval-conflicts-rho005-r1-096-j4xzx
0.2374,Event,ADDED,eval-conflicts-rho005-r1-096.18d46533473ed629,reason=Completed count=1 msg=Job completed
0.2377,Event,ADDED,eval-conflicts-rho005-r1-097-vgwdz.18d465303c1a4de2,reason=Scheduled count=None msg=Successfully assigned compute/eval-conflicts-rho005-r1-097-vgwdz to kind-worker4
0.2379,Event,ADDED,eval-conflicts-rho005-r1-097-vgwdz.18d4653055428419,"reason=Pulled count=1 msg=Container image ""busybox:musl"" already present on machine"
0.2381,Event,ADDED,eval-conflicts-rho005-r1-097-vgwdz.18d4653056581a3c,reason=Created count=1 msg=Created container: task
0.2383,Event,ADDED,eval-conflicts-rho005-r1-097-vgwdz.18d465305832b0e6,reason=Started count=1 msg=Started container task
0.2385,Event,ADDED,eval-conflicts-rho005-r1-097.18d465303af99f81,reason=SuccessfulCreate count=1 msg=Created pod: eval-conflicts-rho005-r1-097-vgwdz
0.2387,Event,ADDED,eval-conflicts-rho005-r1-097.18d465338ae966cd,reason=Completed count=1 msg=Job completed
0.2389,Event,ADDED,eval-conflicts-rho005-r1-098-v7gcf.18d46530784a3d70,reason=Scheduled count=None msg=Successfully assigned compute/eval-conflicts-rho005-r1-098-v7gcf to kind-worker
0.2393,Event,ADDED,eval-conflicts-rho005-r1-098-v7gcf.18d465309127acbd,"reason=Pulled count=1 msg=Container image ""busybox:musl"" already present on machine"
0.2396,Event,ADDED,eval-conflicts-rho005-r1-098-v7gcf.18d4653092b4932a,reason=Created count=1 msg=Created container: task
0.2398,Event,ADDED,eval-conflicts-rho005-r1-098-v7gcf.18d4653096304afc,reason=Started count=1 msg=Started container task
0.24,Event,ADDED,eval-conflicts-rho005-r1-098.18d4653076a97149,reason=SuccessfulCreate count=1 msg=Created pod: eval-conflicts-rho005-r1-098-v7gcf
0.2402,Event,ADDED,eval-conflicts-rho005-r1-098.18d46533bf648850,reason=Completed count=1 msg=Job completed
0.2404,Event,ADDED,eval-conflicts-rho005-r1-099-p27kx.18d46530b3be88cd,reason=Scheduled count=None msg=Successfully assigned compute/eval-conflicts-rho005-r1-099-p27kx to kind-worker
0.2406,Event,ADDED,eval-conflicts-rho005-r1-099-p27kx.18d46530cf385074,"reason=Pulled count=1 msg=Container image ""busybox:musl"" already present on machine"
0.2408,Event,ADDED,eval-conflicts-rho005-r1-099-p27kx.18d46530d051dd45,reason=Created count=1 msg=Created container: task
0.2411,Event,ADDED,eval-conflicts-rho005-r1-099-p27kx.18d46530d468089b,reason=Started count=1 msg=Started container task
0.2413,Event,ADDED,eval-conflicts-rho005-r1-099.18d46530b269e19b,reason=SuccessfulCreate count=1 msg=Created pod: eval-conflicts-rho005-r1-099-p27kx
0.2415,Event,ADDED,eval-conflicts-rho005-r1-099.18d46533fb69a2aa,reason=Completed count=1 msg=Job completed
0.2419,Event,ADDED,eval-conflicts-rho005-r2-000-qj7l7.18d465391012ceb5,reason=Scheduled count=None msg=Successfully assigned compute/eval-conflicts-rho005-r2-000-qj7l7 to kind-worker2
0.2421,Event,ADDED,eval-conflicts-rho005-r2-000-qj7l7.18d4653928f7c3ce,"reason=Pulled count=1 msg=Container image ""busybox:musl"" already present on machine"
0.2423,Event,ADDED,eval-conflicts-rho005-r2-000-qj7l7.18d465392a307a6b,reason=Created count=1 msg=Created container: task
0.2424,Event,ADDED,eval-conflicts-rho005-r2-000-qj7l7.18d465392e09b995,reason=Started count=1 msg=Started container task
0.2427,Event,ADDED,eval-conflicts-rho005-r2-000.18d465390f27e414,reason=SuccessfulCreate count=1 msg=Created pod: eval-conflicts-rho005-r2-000-qj7l7
0.2429,Event,ADDED,eval-conflicts-rho005-r2-000.18d4653c4d432da7,reason=Completed count=1 msg=Job completed
0.2431,Event,ADDED,eval-conflicts-rho005-r2-001-fk9xv.18d46539509117e4,reason=Scheduled count=None msg=Successfully assigned compute/eval-conflicts-rho005-r2-001-fk9xv to kind-worker5
0.2433,Event,ADDED,eval-conflicts-rho005-r2-001-fk9xv.18d465397c5e3eb7,"reason=Pulled count=1 msg=Container image ""busybox:musl"" already present on machine"
0.2435,Event,ADDED,eval-conflicts-rho005-r2-001-fk9xv.18d465397d721cbc,reason=Created count=1 msg=Created container: task
0.2437,Event,ADDED,eval-conflicts-rho005-r2-001-fk9xv.18d46539820bdc3e,reason=Started count=1 msg=Started container task
0.2439,Event,ADDED,eval-conflicts-rho005-r2-001.18d465394ae25756,reason=SuccessfulCreate count=1 msg=Created pod: eval-conflicts-rho005-r2-001-fk9xv
0.2441,Event,ADDED,eval-conflicts-rho005-r2-001.18d4653cabec7937,reason=Completed count=1 msg=Job completed
0.2442,Event,ADDED,eval-conflicts-rho005-r2-002-578z7.18d4653986d6de30,reason=Scheduled count=None msg=Successfully assigned compute/eval-conflicts-rho005-r2-002-578z7 to kind-worker
0.2444,Event,ADDED,eval-conflicts-rho005-r2-002-578z7.18d465399fbaae1d,"reason=Pulled count=1 msg=Container image ""busybox:musl"" already present on machine"
0.2445,Event,ADDED,eval-conflicts-rho005-r2-002-578z7.18d46539a0f590c7,reason=Created count=1 msg=Created container: task
0.2447,Event,ADDED,eval-conflicts-rho005-r2-002-578z7.18d46539a5f8541d,reason=Started count=1 msg=Started container task
0.2449,Event,ADDED,eval-conflicts-rho005-r2-002.18d4653985c803c8,reason=SuccessfulCreate count=1 msg=Created pod: eval-conflicts-rho005-r2-002-578z7
0.2451,Event,ADDED,eval-conflicts-rho005-r2-002.18d4653cd960ea1f,reason=Completed count=1 msg=Job completed
0.2452,Event,ADDED,eval-conflicts-rho005-r2-003-m9jf9.18d46539c2e062e8,reason=Scheduled count=None msg=Successfully assigned compute/eval-conflicts-rho005-r2-003-m9jf9 to kind-worker
0.2454,Event,ADDED,eval-conflicts-rho005-r2-003-m9jf9.18d46539dc9b11bd,"reason=Pulled count=1 msg=Container image ""busybox:musl"" already present on machine"
0.2455,Event,ADDED,eval-conflicts-rho005-r2-003-m9jf9.18d46539ddbc2c00,reason=Created count=1 msg=Created container: task
0.2457,Event,ADDED,eval-conflicts-rho005-r2-003-m9jf9.18d46539e18dd3af,reason=Started count=1 msg=Started container task
0.2459,Event,ADDED,eval-conflicts-rho005-r2-003.18d46539c1ed65c2,reason=SuccessfulCreate count=1 msg=Created pod: eval-conflicts-rho005-r2-003-m9jf9
0.246,Event,ADDED,eval-conflicts-rho005-r2-003.18d4653d152fd124,reason=Completed count=1 msg=Job completed
0.2462,Event,ADDED,eval-conflicts-rho005-r2-004-4sjhs.18d46539fe534503,reason=Scheduled count=None msg=Successfully assigned compute/eval-conflicts-rho005-r2-004-4sjhs to kind-worker5
0.2464,Event,ADDED,eval-conflicts-rho005-r2-004-4sjhs.18d4653a17a7f2d3,"reason=Pulled count=1 msg=Container image ""busybox:musl"" already present on machine"
0.2468,Event,ADDED,eval-conflicts-rho005-r2-004-4sjhs.18d4653a18cfedd8,reason=Created count=1 msg=Created container: task
0.2472,Event,ADDED,eval-conflicts-rho005-r2-004-4sjhs.18d4653a1aebc59d,reason=Started count=1 msg=Started container task
0.2474,Event,ADDED,eval-conflicts-rho005-r2-004.18d46539fd5de6d2,reason=SuccessfulCreate count=1 msg=Created pod: eval-conflicts-rho005-r2-004-4sjhs
0.2478,Event,ADDED,eval-conflicts-rho005-r2-004.18d4653d5f23e811,reason=Completed count=1 msg=Job completed
0.2479,Event,ADDED,eval-conflicts-rho005-r2-005-prnmf.18d4653a3951de0a,reason=Scheduled count=None msg=Successfully assigned compute/eval-conflicts-rho005-r2-005-prnmf to kind-worker5
0.2482,Event,ADDED,eval-conflicts-rho005-r2-005-prnmf.18d4653a52a7b17f,"reason=Pulled count=1 msg=Container image ""busybox:musl"" already present on machine"
0.2484,Event,ADDED,eval-conflicts-rho005-r2-005-prnmf.18d4653a53d4612b,reason=Created count=1 msg=Created container: task
0.2487,Event,ADDED,eval-conflicts-rho005-r2-005-prnmf.18d4653a55f0d7c8,reason=Started count=1 msg=Started container task
0.2489,Event,ADDED,eval-conflicts-rho005-r2-005.18d4653a38608af2,reason=SuccessfulCreate count=1 msg=Created pod: eval-conflicts-rho005-r2-005-prnmf
0.249,Event,ADDED,eval-conflicts-rho005-r2-005.18d4653d9b2c5896,reason=Completed count=1 msg=Job completed
0.2492,Event,ADDED,eval-conflicts-rho005-r2-006-c78c5.18d4653a74578fe1,reason=Scheduled count=None msg=Successfully assigned compute/eval-conflicts-rho005-r2-006-c78c5 to kind-worker
0.2496,Event,ADDED,eval-conflicts-rho005-r2-006-c78c5.18d4653a8e7cd0c0,"reason=Pulled count=1 msg=Container image ""busybox:musl"" already present on machine"
0.2498,Event,ADDED,eval-conflicts-rho005-r2-006-c78c5.18d4653a8f9fce1c,reason=Created count=1 msg=Created container: task
0.2499,Event,ADDED,eval-conflicts-rho005-r2-006-c78c5.18d4653a918de63a,reason=Started count=1 msg=Started container task
0.2503,Event,ADDED,eval-conflicts-rho005-r2-006.18d4653a73854b30,reason=SuccessfulCreate count=1 msg=Created pod: eval-conflicts-rho005-r2-006-c78c5
0.2505,Event,ADDED,eval-conflicts-rho005-r2-006.18d4653dc955d547,reason=Completed count=1 msg=Job completed
0.2507,Event,ADDED,eval-conflicts-rho005-r2-007-zrgl2.18d4653ab10ef764,reason=Scheduled count=None msg=Successfully assigned compute/eval-conflicts-rho005-r2-007-zrgl2 to kind-worker
0.2509,Event,ADDED,eval-conflicts-rho005-r2-007-zrgl2.18d4653acbdf2fb7,"reason=Pulled count=1 msg=Container image ""busybox:musl"" already present on machine"
0.2512,Event,ADDED,eval-conflicts-rho005-r2-007-zrgl2.18d4653acd15a742,reason=Created count=1 msg=Created container: task
0.2514,Event,ADDED,eval-conflicts-rho005-r2-007-zrgl2.18d4653acf529ec7,reason=Started count=1 msg=Started container task
0.2516,Event,ADDED,eval-conflicts-rho005-r2-007.18d4653ab05fe55e,reason=SuccessfulCreate count=1 msg=Created pod: eval-conflicts-rho005-r2-007-zrgl2
0.2517,Event,ADDED,eval-conflicts-rho005-r2-007.18d4653e04f3af78,reason=Completed count=1 msg=Job completed
0.252,Event,ADDED,eval-conflicts-rho005-r2-008-fmpxh.18d4653aec466610,reason=Scheduled count=None msg=Successfully assigned compute/eval-conflicts-rho005-r2-008-fmpxh to kind-worker4
0.2521,Event,ADDED,eval-conflicts-rho005-r2-008-fmpxh.18d4653b079448fd,"reason=Pulled count=1 msg=Container image ""busybox:musl"" already present on machine"
0.2523,Event,ADDED,eval-conflicts-rho005-r2-008-fmpxh.18d4653b08c0fb69,reason=Created count=1 msg=Created container: task
0.2528,Event,ADDED,eval-conflicts-rho005-r2-008-fmpxh.18d4653b0ba31da5,reason=Started count=1 msg=Started container task
0.2531,Event,ADDED,eval-conflicts-rho005-r2-008.18d4653aeb5971e2,reason=SuccessfulCreate count=1 msg=Created pod: eval-conflicts-rho005-r2-008-fmpxh
0.2534,Event,ADDED,eval-conflicts-rho005-r2-008.18d4653e4746fe79,reason=Completed count=1 msg=Job completed
0.2536,Event,ADDED,eval-conflicts-rho005-r2-009-nkqqv.18d4653b27a9aab5,reason=Scheduled count=None msg=Successfully assigned compute/eval-conflicts-rho005-r2-009-nkqqv to kind-worker
0.2539,Event,ADDED,eval-conflicts-rho005-r2-009-nkqqv.18d4653b42476dae,"reason=Pulled count=1 msg=Container image ""busybox:musl"" already present on machine"
0.2541,Event,ADDED,eval-conflicts-rho005-r2-009-nkqqv.18d4653b43647998,reason=Created count=1 msg=Created container: task
0.2543,Event,ADDED,eval-conflicts-rho005-r2-009-nkqqv.18d4653b45686038,reason=Started count=1 msg=Started container task
0.2547,Event,ADDED,eval-conflicts-rho005-r2-009.18d4653b26c6a14f,reason=SuccessfulCreate count=1 msg=Created pod: eval-conflicts-rho005-r2-009-nkqqv
0.2549,Event,ADDED,eval-conflicts-rho005-r2-009.18d4653e7c8a03ea,reason=Completed count=1 msg=Job completed
0.2551,Event,ADDED,eval-conflicts-rho005-r2-010-l75kw.18d4653b62f8507e,reason=Scheduled count=None msg=Successfully assigned compute/eval-conflicts-rho005-r2-010-l75kw to kind-worker3
0.2553,Event,ADDED,eval-conflicts-rho005-r2-010-l75kw.18d4653b7c4f30ac,"reason=Pulled count=1 msg=Container image ""busybox:musl"" already present on machine"
0.2556,Event,ADDED,eval-conflicts-rho005-r2-010-l75kw.18d4653b7d61a78e,reason=Created count=1 msg=Created container: task
0.2558,Event,ADDED,eval-conflicts-rho005-r2-010-l75kw.18d4653b7f589bdb,reason=Started count=1 msg=Started container task
0.256,Event,ADDED,eval-conflicts-rho005-r2-010.18d4653b628d47a9,reason=SuccessfulCreate count=1 msg=Created pod: eval-conflicts-rho005-r2-010-l75kw
0.2562,Event,ADDED,eval-conflicts-rho005-r2-010.18d4653eb837c096,reason=Completed count=1 msg=Job completed
0.2565,Event,ADDED,eval-conflicts-rho005-r2-011-m7pg8.18d4653b9e5ee83b,reason=Scheduled count=None msg=Successfully assigned compute/eval-conflicts-rho005-r2-011-m7pg8 to kind-worker3
0.2567,Event,ADDED,eval-conflicts-rho005-r2-011-m7pg8.18d4653bb86c8491,"reason=Pulled count=1 msg=Container image ""busybox:musl"" already present on machine"
0.2569,Event,ADDED,eval-conflicts-rho005-r2-011-m7pg8.18d4653bb9787ce9,reason=Created count=1 msg=Created container: task
0.2572,Event,ADDED,eval-conflicts-rho005-r2-011-m7pg8.18d4653bbb991ddf,reason=Started count=1 msg=Started container task
0.2574,Event,ADDED,eval-conflicts-rho005-r2-011.18d4653b9ddd6f5e,reason=SuccessfulCreate count=1 msg=Created pod: eval-conflicts-rho005-r2-011-m7pg8
0.2575,Event,ADDED,eval-conflicts-rho005-r2-011.18d4653ef4431587,reason=Completed count=1 msg=Job completed
0.2577,Event,ADDED,eval-conflicts-rho005-r2-012-x6nng.18d4653bda9a9f98,reason=Scheduled count=None msg=Successfully assigned compute/eval-conflicts-rho005-r2-012-x6nng to kind-worker3
0.2579,Event,ADDED,eval-conflicts-rho005-r2-012-x6nng.18d4653bf4194771,"reason=Pulled count=1 msg=Container image ""busybox:musl"" already present on machine"
0.2581,Event,ADDED,eval-conflicts-rho005-r2-012-x6nng.18d4653bf542ff21,reason=Created count=1 msg=Created container: task
0.2582,Event,ADDED,eval-conflicts-rho005-r2-012-x6nng.18d4653bf94ddefe,reason=Started count=1 msg=Started container task
0.2584,Event,ADDED,eval-conflicts-rho005-r2-012.18d4653bda1c05a2,reason=SuccessfulCreate count=1 msg=Created pod: eval-conflicts-rho005-r2-012-x6nng
0.2586,Event,ADDED,eval-conflicts-rho005-r2-012.18d4653f301e57af,reason=Completed count=1 msg=Job completed
0.2587,Event,ADDED,eval-conflicts-rho005-r2-013-spv66.18d4653c15d078a5,reason=Scheduled count=None msg=Successfully assigned compute/eval-conflicts-rho005-r2-013-spv66 to kind-worker2
0.2589,Event,ADDED,eval-conflicts-rho005-r2-013-spv66.18d4653c2ec58871,"reason=Pulled count=1 msg=Container image ""busybox:musl"" already present on machine"
0.2592,Event,ADDED,eval-conflicts-rho005-r2-013-spv66.18d4653c2fd72cdc,reason=Created count=1 msg=Created container: task
0.2594,Event,ADDED,eval-conflicts-rho005-r2-013-spv66.18d4653c31c0b47e,reason=Started count=1 msg=Started container task
0.2595,Event,ADDED,eval-conflicts-rho005-r2-013.18d4653c1505ef06,reason=SuccessfulCreate count=1 msg=Created pod: eval-conflicts-rho005-r2-013-spv66
0.2597,Event,ADDED,eval-conflicts-rho005-r2-013.18d4653f56750791,reason=Completed count=1 msg=Job completed
0.2599,Event,ADDED,eval-conflicts-rho005-r2-014-t877c.18d4653c51bc92fb,reason=Scheduled count=None msg=Successfully assigned compute/eval-conflicts-rho005-r2-014-t877c to kind-worker2
0.2601,Event,ADDED,eval-conflicts-rho005-r2-014-t877c.18d4653c6ac8cb09,"reason=Pulled count=1 msg=Container image ""busybox:musl"" already present on machine"
0.2602,Event,ADDED,eval-conflicts-rho005-r2-014-t877c.18d4653c6bde3e9b,reason=Created count=1 msg=Created container: task
0.2605,Event,ADDED,eval-conflicts-rho005-r2-014-t877c.18d4653c6dc927e2,reason=Started count=1 msg=Started container task
0.2606,Event,ADDED,eval-conflicts-rho005-r2-014.18d4653c50e19705,reason=SuccessfulCreate count=1 msg=Created pod: eval-conflicts-rho005-r2-014-t877c
0.2609,Event,ADDED,eval-conflicts-rho005-r2-014.18d4653f56d04bc9,reason=Completed count=1 msg=Job completed
0.261,Event,ADDED,eval-conflicts-rho005-r2-015-2cwjc.18d4653c8d374505,reason=Scheduled count=None msg=Successfully assigned compute/eval-conflicts-rho005-r2-015-2cwjc to kind-worker2
0.2613,Event,ADDED,eval-conflicts-rho005-r2-015-2cwjc.18d4653ca66b76c8,"reason=Pulled count=1 msg=Container image ""busybox:musl"" already present on machine"
0.2614,Event,ADDED,eval-conflicts-rho005-r2-015-2cwjc.18d4653ca7788eb9,reason=Created count=1 msg=Created container: task
0.2616,Event,ADDED,eval-conflicts-rho005-r2-015-2cwjc.18d4653ca9701f0a,reason=Started count=1 msg=Started container task
0.2618,Event,ADDED,eval-conflicts-rho005-r2-015.18d4653c8c34fa0b,reason=SuccessfulCreate count=1 msg=Created pod: eval-conflicts-rho005-r2-015-2cwjc
0.262,Event,ADDED,eval-conflicts-rho005-r2-015.18d4653fcdf12683,reason=Completed count=1 msg=Job completed
0.2621,Event,ADDED,eval-conflicts-rho005-r2-016-78n99.18d4653cc8cabf4f,reason=Scheduled count=None msg=Successfully assigned compute/eval-conflicts-rho005-r2-016-78n99 to kind-worker2
0.2623,Event,ADDED,eval-conflicts-rho005-r2-016-78n99.18d4653ce23e426a,"reason=Pulled count=1 msg=Container image ""busybox:musl"" already present on machine"
0.2625,Event,ADDED,eval-conflicts-rho005-r2-016-78n99.18d4653ce363fc8d,reason=Created count=1 msg=Created container: task
0.2626,Event,ADDED,eval-conflicts-rho005-r2-016-78n99.18d4653ce56326ef,reason=Started count=1 msg=Started container task
0.2628,Event,ADDED,eval-conflicts-rho005-r2-016.18d4653cc81a2e8d,reason=SuccessfulCreate count=1 msg=Created pod: eval-conflicts-rho005-r2-016-78n99
0.263,Event,ADDED,eval-conflicts-rho005-r2-016.18d4653fce9599bb,reason=Completed count=1 msg=Job completed
0.2631,Event,ADDED,eval-conflicts-rho005-r2-017-pzs87.18d4653d038e0b86,"reason=FailedScheduling count=None msg=0/6 nodes are available: 1 c_wall violated: 1 conflicting context pair(s) with node memory, 5 node(s) had untolerated taint(s). no new claims to deallocate, preemption: 0/6 nodes are available: 1 No preemption victims found for incoming pod, 5 Preemption is not helpful for scheduling."
0.2633,Event,ADDED,eval-conflicts-rho005-r2-017-pzs87.18d4653d040bc466,"reason=FailedScheduling count=None msg=0/6 nodes are available: 1 c_wall violated: 1 conflicting context pair(s) with node memory, 5 node(s) had untolerated taint(s). no new claims to deallocate, preemption: 0/6 nodes are available: 1 No preemption victims found for incoming pod, 5 Preemption is not helpful for scheduling."
0.2634,Event,ADDED,eval-conflicts-rho005-r2-017-pzs87.18d4653f2a5a27e1,reason=Scheduled count=None msg=Successfully assigned compute/eval-conflicts-rho005-r2-017-pzs87 to kind-worker5
0.2637,Event,ADDED,eval-conflicts-rho005-r2-017-pzs87.18d4653f451297ca,"reason=Pulled count=1 msg=Container image ""busybox:musl"" already present on machine"
0.2638,Event,ADDED,eval-conflicts-rho005-r2-017-pzs87.18d4653f46a96c23,reason=Created count=1 msg=Created container: task
0.264,Event,ADDED,eval-conflicts-rho005-r2-017-pzs87.18d4653f490ccc27,reason=Started count=1 msg=Started container task
0.2642,Event,ADDED,eval-conflicts-rho005-r2-017.18d4653d0352a404,reason=SuccessfulCreate count=1 msg=Created pod: eval-conflicts-rho005-r2-017-pzs87
0.2644,Event,ADDED,eval-conflicts-rho005-r2-017.18d4654282308fcc,reason=Completed count=1 msg=Job completed
0.2645,Event,ADDED,eval-conflicts-rho005-r2-018-pp46n.18d4653d3f96d090,reason=Scheduled count=None msg=Successfully assigned compute/eval-conflicts-rho005-r2-018-pp46n to kind-worker2
0.2647,Event,ADDED,eval-conflicts-rho005-r2-018-pp46n.18d4653d58bba7f7,"reason=Pulled count=1 msg=Container image ""busybox:musl"" already present on machine"
0.2648,Event,ADDED,eval-conflicts-rho005-r2-018-pp46n.18d4653d59c789e3,reason=Created count=1 msg=Created container: task
0.265,Event,ADDED,eval-conflicts-rho005-r2-018-pp46n.18d4653d5bc3d345,reason=Started count=1 msg=Started container task
0.2652,Event,ADDED,eval-conflicts-rho005-r2-018.18d4653d3efd448c,reason=SuccessfulCreate count=1 msg=Created pod: eval-conflicts-rho005-r2-018-pp46n
0.2653,Event,ADDED,eval-conflicts-rho005-r2-018.18d465404636406b,reason=Completed count=1 msg=Job completed
0.2655,Event,ADDED,eval-conflicts-rho005-r2-019-xljsg.18d4653d7adfcd67,reason=Scheduled count=None msg=Successfully assigned compute/eval-conflicts-rho005-r2-019-xljsg to kind-worker2
0.2656,Event,ADDED,eval-conflicts-rho005-r2-019-xljsg.18d4653d93eaf024,"reason=Pulled count=1 msg=Container image ""busybox:musl"" already present on machine"
0.2658,Event,ADDED,eval-conflicts-rho005-r2-019-xljsg.18d4653d94f9152a,reason=Created count=1 msg=Created container: task
0.266,Event,ADDED,eval-conflicts-rho005-r2-019-xljsg.18d4653d96eb043b,reason=Started count=1 msg=Started container task
0.2661,Event,ADDED,eval-conflicts-rho005-r2-019.18d4653d7a5f5c9e,reason=SuccessfulCreate count=1 msg=Created pod: eval-conflicts-rho005-r2-019-xljsg
0.2663,Event,ADDED,eval-conflicts-rho005-r2-019.18d4654081f46475,reason=Completed count=1 msg=Job completed
0.2664,Event,ADDED,eval-conflicts-rho005-r2-020-psspl.18d4653db73d4f99,reason=Scheduled count=None msg=Successfully assigned compute/eval-conflicts-rho005-r2-020-psspl to kind-worker2
0.2668,Event,ADDED,eval-conflicts-rho005-r2-020-psspl.18d4653dcf816caa,"reason=Pulled count=1 msg=Container image ""busybox:musl"" already present on machine"
0.2669,Event,ADDED,eval-conflicts-rho005-r2-020-psspl.18d4653dd09c3ab8,reason=Created count=1 msg=Created container: task
0.2671,Event,ADDED,eval-conflicts-rho005-r2-020-psspl.18d4653dd485352e,reason=Started count=1 msg=Started container task
0.2673,Event,ADDED,eval-conflicts-rho005-r2-020.18d4653db6c0d8a0,reason=SuccessfulCreate count=1 msg=Created pod: eval-conflicts-rho005-r2-020-psspl
0.2676,Event,ADDED,eval-conflicts-rho005-r2-020.18d46540f99a8b69,reason=Completed count=1 msg=Job completed
0.2677,Event,ADDED,eval-conflicts-rho005-r2-021-sbnjd.18d4653df3443693,reason=Scheduled count=None msg=Successfully assigned compute/eval-conflicts-rho005-r2-021-sbnjd to kind-worker2
0.2679,Event,ADDED,eval-conflicts-rho005-r2-021-sbnjd.18d4653e0c85f161,"reason=Pulled count=1 msg=Container image ""busybox:musl"" already present on machine"
0.2681,Event,ADDED,eval-conflicts-rho005-r2-021-sbnjd.18d4653e0d97ae4d,reason=Created count=1 msg=Created container: task
0.2683,Event,ADDED,eval-conflicts-rho005-r2-021-sbnjd.18d4653e121ae04e,reason=Started count=1 msg=Started container task
0.2684,Event,ADDED,eval-conflicts-rho005-r2-021.18d4653df21f3941,reason=SuccessfulCreate count=1 msg=Created pod: eval-conflicts-rho005-r2-021-sbnjd
0.2686,Event,ADDED,eval-conflicts-rho005-r2-021.18d465413548e5f8,reason=Completed count=1 msg=Job completed
0.2688,Event,ADDED,eval-conflicts-rho005-r2-022-qzphv.18d4653e2e796042,reason=Scheduled count=None msg=Successfully assigned compute/eval-conflicts-rho005-r2-022-qzphv to kind-worker2
0.2689,Event,ADDED,eval-conflicts-rho005-r2-022-qzphv.18d4653e47451ebb,"reason=Pulled count=1 msg=Container image ""busybox:musl"" already present on machine"
0.2692,Event,ADDED,eval-conflicts-rho005-r2-022-qzphv.18d4653e489fad33,reason=Created count=1 msg=Created container: task
0.2693,Event,ADDED,eval-conflicts-rho005-r2-022-qzphv.18d4653e4c61d4b4,reason=Started count=1 msg=Started container task
0.2695,Event,ADDED,eval-conflicts-rho005-r2-022.18d4653e2dadd4fa,reason=SuccessfulCreate count=1 msg=Created pod: eval-conflicts-rho005-r2-022-qzphv
0.2697,Event,ADDED,eval-conflicts-rho005-r2-022.18d46541714dd489,reason=Completed count=1 msg=Job completed
0.2698,Event,ADDED,eval-conflicts-rho005-r2-023-sv5nd.18d4653e68cb2ef5,"reason=FailedScheduling count=None msg=0/6 nodes are available: 6 node(s) had untolerated taint(s). no new claims to deallocate, preemption: 0/6 nodes are available: 6 Preemption is not helpful for scheduling."
0.27,Event,ADDED,eval-conflicts-rho005-r2-023-sv5nd.18d4653f2a8ab766,reason=Scheduled count=None msg=Successfully assigned compute/eval-conflicts-rho005-r2-023-sv5nd to kind-worker5
0.2702,Event,ADDED,eval-conflicts-rho005-r2-023-sv5nd.18d4653f563367e6,"reason=Pulled count=1 msg=Container image ""busybox:musl"" already present on machine"
0.2703,Event,ADDED,eval-conflicts-rho005-r2-023-sv5nd.18d4653f57addd2e,reason=Created count=1 msg=Created container: task
0.2705,Event,ADDED,eval-conflicts-rho005-r2-023-sv5nd.18d4653f5c0ba659,reason=Started count=1 msg=Started container task
0.2706,Event,ADDED,eval-conflicts-rho005-r2-023.18d4653e68c93e83,reason=SuccessfulCreate count=1 msg=Created pod: eval-conflicts-rho005-r2-023-sv5nd
0.2708,Event,ADDED,eval-conflicts-rho005-r2-023.18d46542841252de,reason=Completed count=1 msg=Job completed
0.271,Event,ADDED,eval-conflicts-rho005-r2-024-qd594.18d4653ea4899b3f,"reason=FailedScheduling count=None msg=0/6 nodes are available: 6 node(s) had untolerated taint(s). no new claims to deallocate, preemption: 0/6 nodes are available: 6 Preemption is not helpful for scheduling."
0.2711,Event,ADDED,eval-conflicts-rho005-r2-024-qd594.18d4653f2e1f9fc1,reason=Scheduled count=None msg=Successfully assigned compute/eval-conflicts-rho005-r2-024-qd594 to kind-worker5
0.2713,Event,ADDED,eval-conflicts-rho005-r2-024-qd594.18d4653f45d6ba30,"reason=Pulled count=1 msg=Container image ""busybox:musl"" already present on machine"
0.2714,Event,ADDED,eval-conflicts-rho005-r2-024-qd594.18d4653f47f100e5,reason=Created count=1 msg=Created container: task
0.2716,Event,ADDED,eval-conflicts-rho005-r2-024-qd594.18d4653f4a7cb8d9,reason=Started count=1 msg=Started container task
0.2721,Event,ADDED,eval-conflicts-rho005-r2-024.18d4653ea47e5f3c,reason=SuccessfulCreate count=1 msg=Created pod: eval-conflicts-rho005-r2-024-qd594
0.2723,Event,ADDED,eval-conflicts-rho005-r2-024.18d465428201eb5a,reason=Completed count=1 msg=Job completed
0.2725,Event,ADDED,eval-conflicts-rho005-r2-025-j9mqc.18d4653ee12bafb6,"reason=FailedScheduling count=None msg=0/6 nodes are available: 6 node(s) had untolerated taint(s). no new claims to deallocate, preemption: 0/6 nodes are available: 6 Preemption is not helpful for scheduling."
0.2727,Event,ADDED,eval-conflicts-rho005-r2-025-j9mqc.18d4653f2e1f3455,reason=Scheduled count=None msg=Successfully assigned compute/eval-conflicts-rho005-r2-025-j9mqc to kind-worker5
0.2731,Event,ADDED,eval-conflicts-rho005-r2-025-j9mqc.18d4653f461e90c8,"reason=Pulled count=1 msg=Container image ""busybox:musl"" already present on machine"
0.2733,Event,ADDED,eval-conflicts-rho005-r2-025-j9mqc.18d4653f48369aa4,reason=Created count=1 msg=Created container: task
0.2734,Event,ADDED,eval-conflicts-rho005-r2-025-j9mqc.18d4653f4a7cee18,reason=Started count=1 msg=Started container task
0.2737,Event,ADDED,eval-conflicts-rho005-r2-025.18d4653ee120f5c8,reason=SuccessfulCreate count=1 msg=Created pod: eval-conflicts-rho005-r2-025-j9mqc
0.2738,Event,ADDED,eval-conflicts-rho005-r2-025.18d4654283e9e0e3,reason=Completed count=1 msg=Job completed
0.274,Event,ADDED,eval-conflicts-rho005-r2-026-7ff7b.18d4653f1c62ff57,"reason=FailedScheduling count=None msg=0/6 nodes are available: 6 node(s) had untolerated taint(s). no new claims to deallocate, preemption: 0/6 nodes are available: 6 Preemption is not helpful for scheduling."
0.2741,Event,ADDED,eval-conflicts-rho005-r2-026-7ff7b.18d4653f2e8a34d7,reason=Scheduled count=None msg=Successfully assigned compute/eval-conflicts-rho005-r2-026-7ff7b to kind-worker5
0.2743,Event,ADDED,eval-conflicts-rho005-r2-026-7ff7b.18d4653f4801a238,"reason=Pulled count=1 msg=Container image ""busybox:musl"" already present on machine"
0.2744,Event,ADDED,eval-conflicts-rho005-r2-026-7ff7b.18d4653f49ccef55,reason=Created count=1 msg=Created container: task
0.2746,Event,ADDED,eval-conflicts-rho005-r2-026-7ff7b.18d4653f4bbecf55,reason=Started count=1 msg=Started container task
0.2748,Event,ADDED,eval-conflicts-rho005-r2-026.18d4653f1c53a18c,reason=SuccessfulCreate count=1 msg=Created pod: eval-conflicts-rho005-r2-026-7ff7b
0.2749,Event,ADDED,eval-conflicts-rho005-r2-026.18d465428348af53,reason=Completed count=1 msg=Job completed
0.2751,Event,ADDED,eval-conflicts-rho005-r2-027-24vdc.18d4653f58b42793,reason=Scheduled count=None msg=Successfully assigned compute/eval-conflicts-rho005-r2-027-24vdc to kind-worker3
0.2752,Event,ADDED,eval-conflicts-rho005-r2-027-24vdc.18d4653f73e36f99,"reason=Pulled count=1 msg=Container image ""busybox:musl"" already present on machine"
0.2755,Event,ADDED,eval-conflicts-rho005-r2-027-24vdc.18d4653f753d2221,reason=Created count=1 msg=Created container: task
0.2757,Event,ADDED,eval-conflicts-rho005-r2-027-24vdc.18d4653f77409dfc,reason=Started count=1 msg=Started container task
0.2758,Event,ADDED,eval-conflicts-rho005-r2-027.18d4653f579e111b,reason=SuccessfulCreate count=1 msg=Created pod: eval-conflicts-rho005-r2-027-24vdc
0.276,Event,ADDED,eval-conflicts-rho005-r2-027.18d46542b047e1e9,reason=Completed count=1 msg=Job completed
0.2762,Event,ADDED,eval-conflicts-rho005-r2-028-x4mnx.18d4653f94bfaf4f,reason=Scheduled count=None msg=Successfully assigned compute/eval-conflicts-rho005-r2-028-x4mnx to kind-worker5
0.2764,Event,ADDED,eval-conflicts-rho005-r2-028-x4mnx.18d4653fac8e72b4,"reason=Pulled count=1 msg=Container image ""busybox:musl"" already present on machine"
0.2766,Event,ADDED,eval-conflicts-rho005-r2-028-x4mnx.18d4653fada32712,reason=Created count=1 msg=Created container: task
0.2768,Event,ADDED,eval-conflicts-rho005-r2-028-x4mnx.18d4653fb143c0fb,reason=Started count=1 msg=Started container task
0.277,Event,ADDED,eval-conflicts-rho005-r2-028.18d4653f93ae19a8,reason=SuccessfulCreate count=1 msg=Created pod: eval-conflicts-rho005-r2-028-x4mnx
0.2772,Event,ADDED,eval-conflicts-rho005-r2-028.18d46542fa466e9e,reason=Completed count=1 msg=Job completed
0.2773,Event,ADDED,eval-conflicts-rho005-r2-029-cnsz5.18d4653fd02266b7,reason=Scheduled count=None msg=Successfully assigned compute/eval-conflicts-rho005-r2-029-cnsz5 to kind-worker3
0.2776,Event,ADDED,eval-conflicts-rho005-r2-029-cnsz5.18d4653fe925be46,"reason=Pulled count=1 msg=Container image ""busybox:musl"" already present on machine"
0.2778,Event,ADDED,eval-conflicts-rho005-r2-029-cnsz5.18d4653fea519a9a,reason=Created count=1 msg=Created container: task
0.2779,Event,ADDED,eval-conflicts-rho005-r2-029-cnsz5.18d4653feedf8f56,reason=Started count=1 msg=Started container task
0.2781,Event,ADDED,eval-conflicts-rho005-r2-029.18d4653fcf1f7e81,reason=SuccessfulCreate count=1 msg=Created pod: eval-conflicts-rho005-r2-029-cnsz5
0.2783,Event,ADDED,eval-conflicts-rho005-r2-029.18d4654328c9ab79,reason=Completed count=1 msg=Job completed
0.2785,Event,ADDED,eval-conflicts-rho005-r2-030-7b5ms.18d465400b61d9e7,reason=Scheduled count=None msg=Successfully assigned compute/eval-conflicts-rho005-r2-030-7b5ms to kind-worker
0.2786,Event,ADDED,eval-conflicts-rho005-r2-030-7b5ms.18d465402427d04e,"reason=Pulled count=1 msg=Container image ""busybox:musl"" already present on machine"
0.2788,Event,ADDED,eval-conflicts-rho005-r2-030-7b5ms.18d465402536c05d,reason=Created count=1 msg=Created container: task
0.279,Event,ADDED,eval-conflicts-rho005-r2-030-7b5ms.18d4654027338355,reason=Started count=1 msg=Started container task
0.2792,Event,ADDED,eval-conflicts-rho005-r2-030.18d465400a7ca671,reason=SuccessfulCreate count=1 msg=Created pod: eval-conflicts-rho005-r2-030-7b5ms
0.2793,Event,ADDED,eval-conflicts-rho005-r2-030.18d4654364937114,reason=Completed count=1 msg=Job completed
0.2795,Event,ADDED,eval-conflicts-rho005-r2-031-g8zdm.18d465404789bf7c,reason=Scheduled count=None msg=Successfully assigned compute/eval-conflicts-rho005-r2-031-g8zdm to kind-worker
0.2796,Event,ADDED,eval-conflicts-rho005-r2-031-g8zdm.18d4654060589a68,"reason=Pulled count=1 msg=Container image ""busybox:musl"" already present on machine"
0.2798,Event,ADDED,eval-conflicts-rho005-r2-031-g8zdm.18d465406162937c,reason=Created count=1 msg=Created container: task
0.28,Event,ADDED,eval-conflicts-rho005-r2-031-g8zdm.18d465406352626b,reason=Started count=1 msg=Started container task
0.2801,Event,ADDED,eval-conflicts-rho005-r2-031.18d4654046586aea,reason=SuccessfulCreate count=1 msg=Created pod: eval-conflicts-rho005-r2-031-g8zdm
0.2803,Event,ADDED,eval-conflicts-rho005-r2-031.18d46543a0615c0e,reason=Completed count=1 msg=Job completed
0.2805,Event,ADDED,eval-conflicts-rho005-r2-032-rxh78.18d4654082f32bb8,reason=Scheduled count=None msg=Successfully assigned compute/eval-conflicts-rho005-r2-032-rxh78 to kind-worker4
0.2806,Event,ADDED,eval-conflicts-rho005-r2-032-rxh78.18d465409c32c14c,"reason=Pulled count=1 msg=Container image ""busybox:musl"" already present on machine"
0.2808,Event,ADDED,eval-conflicts-rho005-r2-032-rxh78.18d465409d47b31d,reason=Created count=1 msg=Created container: task
0.281,Event,ADDED,eval-conflicts-rho005-r2-032-rxh78.18d465409f39b341,reason=Started count=1 msg=Started container task
0.2811,Event,ADDED,eval-conflicts-rho005-r2-032.18d46540817c9769,reason=SuccessfulCreate count=1 msg=Created pod: eval-conflicts-rho005-r2-032-rxh78
0.2813,Event,ADDED,eval-conflicts-rho005-r2-032.18d46543e1fc24ed,reason=Completed count=1 msg=Job completed
0.2814,Event,ADDED,eval-conflicts-rho005-r2-033-zkrnn.18d46540c24aa633,reason=Scheduled count=None msg=Successfully assigned compute/eval-conflicts-rho005-r2-033-zkrnn to kind-worker
0.2817,Event,ADDED,eval-conflicts-rho005-r2-033-zkrnn.18d46540dbf53005,"reason=Pulled count=1 msg=Container image ""busybox:musl"" already present on machine"
0.2819,Event,ADDED,eval-conflicts-rho005-r2-033-zkrnn.18d46540dd279c88,reason=Created count=1 msg=Created container: task
0.2821,Event,ADDED,eval-conflicts-rho005-r2-033-zkrnn.18d46540e0aa1102,reason=Started count=1 msg=Started container task
0.2823,Event,ADDED,eval-conflicts-rho005-r2-033.18d46540bd62910c,reason=SuccessfulCreate count=1 msg=Created pod: eval-conflicts-rho005-r2-033-zkrnn
0.2824,Event,ADDED,eval-conflicts-rho005-r2-033.18d4654416c0ed79,reason=Completed count=1 msg=Job completed
0.2827,Event,ADDED,eval-conflicts-rho005-r2-034-kj9pc.18d46540fbdd2fc4,reason=Scheduled count=None msg=Successfully assigned compute/eval-conflicts-rho005-r2-034-kj9pc to kind-worker
0.2829,Event,ADDED,eval-conflicts-rho005-r2-034-kj9pc.18d46541157af27b,"reason=Pulled count=1 msg=Container image ""busybox:musl"" already present on machine"
0.2831,Event,ADDED,eval-conflicts-rho005-r2-034-kj9pc.18d4654116a07545,reason=Created count=1 msg=Created container: task
0.2833,Event,ADDED,eval-conflicts-rho005-r2-034-kj9pc.18d465411a2fa221,reason=Started count=1 msg=Started container task
0.2835,Event,ADDED,eval-conflicts-rho005-r2-034.18d46540f8a6e1df,reason=SuccessfulCreate count=1 msg=Created pod: eval-conflicts-rho005-r2-034-kj9pc
0.2836,Event,ADDED,eval-conflicts-rho005-r2-034.18d465445294199d,reason=Completed count=1 msg=Job completed
0.2838,Event,ADDED,eval-conflicts-rho005-r2-035-rm8nk.18d4654135f0b403,reason=Scheduled count=None msg=Successfully assigned compute/eval-conflicts-rho005-r2-035-rm8nk to kind-worker
0.284,Event,ADDED,eval-conflicts-rho005-r2-035-rm8nk.18d465414f0da69d,"reason=Pulled count=1 msg=Container image ""busybox:musl"" already present on machine"
0.2841,Event,ADDED,eval-conflicts-rho005-r2-035-rm8nk.18d4654150595ebd,reason=Created count=1 msg=Created container: task
0.2843,Event,ADDED,eval-conflicts-rho005-r2-035-rm8nk.18d4654153e5def1,reason=Started count=1 msg=Started container task
0.2845,Event,ADDED,eval-conflicts-rho005-r2-035.18d46541343046a3,reason=SuccessfulCreate count=1 msg=Created pod: eval-conflicts-rho005-r2-035-rm8nk
0.2848,Event,ADDED,eval-conflicts-rho005-r2-035.18d465448e5e8c7b,reason=Completed count=1 msg=Job completed
0.2849,Event,ADDED,eval-conflicts-rho005-r2-036-pm54q.18d46541716e3e87,reason=Scheduled count=None msg=Successfully assigned compute/eval-conflicts-rho005-r2-036-pm54q to kind-worker4
0.2851,Event,ADDED,eval-conflicts-rho005-r2-036-pm54q.18d465418a63d184,"reason=Pulled count=1 msg=Container image ""busybox:musl"" already present on machine"
0.2854,Event,ADDED,eval-conflicts-rho005-r2-036-pm54q.18d465418b8f0d57,reason=Created count=1 msg=Created container: task
0.2856,Event,ADDED,eval-conflicts-rho005-r2-036-pm54q.18d465418da5f07e,reason=Started count=1 msg=Started container task
0.2858,Event,ADDED,eval-conflicts-rho005-r2-036.18d465416fcc387f,reason=SuccessfulCreate count=1 msg=Created pod: eval-conflicts-rho005-r2-036-pm54q
0.286,Event,ADDED,eval-conflicts-rho005-r2-036.18d46544d05fa7e8,reason=Completed count=1 msg=Job completed
0.2862,Event,ADDED,eval-conflicts-rho005-r2-037-h528z.18d46541ace779b0,reason=Scheduled count=None msg=Successfully assigned compute/eval-conflicts-rho005-r2-037-h528z to kind-worker4
0.2864,Event,ADDED,eval-conflicts-rho005-r2-037-h528z.18d46541ca9abdd9,"reason=Pulled count=1 msg=Container image ""busybox:musl"" already present on machine"
0.2866,Event,ADDED,eval-conflicts-rho005-r2-037-h528z.18d46541cc465487,reason=Created count=1 msg=Created container: task
0.2868,Event,ADDED,eval-conflicts-rho005-r2-037-h528z.18d46541d1ce967f,reason=Started count=1 msg=Started container task
0.287,Event,ADDED,eval-conflicts-rho005-r2-037.18d46541ab8de05b,reason=SuccessfulCreate count=1 msg=Created pod: eval-conflicts-rho005-r2-037-h528z
0.2871,Event,ADDED,eval-conflicts-rho005-r2-037.18d465450ca4e9e5,reason=Completed count=1 msg=Job completed
0.2873,Event,ADDED,eval-conflicts-rho005-r2-038-8bxd6.18d46541e8593938,reason=Scheduled count=None msg=Successfully assigned compute/eval-conflicts-rho005-r2-038-8bxd6 to kind-worker
0.2876,Event,ADDED,eval-conflicts-rho005-r2-038-8bxd6.18d46542034e8ac8,"reason=Pulled count=1 msg=Container image ""busybox:musl"" already present on machine"
0.2878,Event,ADDED,eval-conflicts-rho005-r2-038-8bxd6.18d4654204a61e0f,reason=Created count=1 msg=Created container: task
0.288,Event,ADDED,eval-conflicts-rho005-r2-038-8bxd6.18d4654209674ad1,reason=Started count=1 msg=Started container task
0.2881,Event,ADDED,eval-conflicts-rho005-r2-038.18d46541e74a39f4,reason=SuccessfulCreate count=1 msg=Created pod: eval-conflicts-rho005-r2-038-8bxd6
0.2884,Event,ADDED,eval-conflicts-rho005-r2-038.18d46545427bef4a,reason=Completed count=1 msg=Job completed
0.2886,Event,ADDED,eval-conflicts-rho005-r2-039-w8wts.18d4654223733f38,reason=Scheduled count=None msg=Successfully assigned compute/eval-conflicts-rho005-r2-039-w8wts to kind-worker
0.2888,Event,ADDED,eval-conflicts-rho005-r2-039-w8wts.18d465423d199fa7,"reason=Pulled count=1 msg=Container image ""busybox:musl"" already present on machine"
0.289,Event,ADDED,eval-conflicts-rho005-r2-039-w8wts.18d465423e448016,reason=Created count=1 msg=Created container: task
0.2892,Event,ADDED,eval-conflicts-rho005-r2-039-w8wts.18d46542407be83d,reason=Started count=1 msg=Started container task
0.2893,Event,ADDED,eval-conflicts-rho005-r2-039.18d4654222c2b479,reason=SuccessfulCreate count=1 msg=Created pod: eval-conflicts-rho005-r2-039-w8wts
0.2895,Event,ADDED,eval-conflicts-rho005-r2-039.18d465457eaf2125,reason=Completed count=1 msg=Job completed
0.2897,Event,ADDED,eval-conflicts-rho005-r2-040-snwrn.18d465425eb53393,"reason=FailedScheduling count=None msg=0/6 nodes are available: 6 node(s) had untolerated taint(s). no new claims to deallocate, preemption: 0/6 nodes are available: 6 Preemption is not helpful for scheduling."
0.2898,Event,ADDED,eval-conflicts-rho005-r2-040-snwrn.18d465430e280615,reason=Scheduled count=None msg=Successfully assigned compute/eval-conflicts-rho005-r2-040-snwrn to kind-worker2
0.2901,Event,ADDED,eval-conflicts-rho005-r2-040-snwrn.18d465432c6ae306,"reason=Pulled count=1 msg=Container image ""busybox:musl"" already present on machine"
0.2903,Event,ADDED,eval-conflicts-rho005-r2-040-snwrn.18d465432f1029e7,reason=Created count=1 msg=Created container: task
0.2905,Event,ADDED,eval-conflicts-rho005-r2-040-snwrn.18d46543337d81cd,reason=Started count=1 msg=Started container task
0.2907,Event,ADDED,eval-conflicts-rho005-r2-040.18d465425eac1579,reason=SuccessfulCreate count=1 msg=Created pod: eval-conflicts-rho005-r2-040-snwrn
0.2908,Event,ADDED,eval-conflicts-rho005-r2-040.18d46546594dfdc1,reason=Completed count=1 msg=Job completed
0.291,Event,ADDED,eval-conflicts-rho005-r2-041-dqhlz.18d465429a3f812f,"reason=FailedScheduling count=None msg=0/6 nodes are available: 6 node(s) had untolerated taint(s). no new claims to deallocate, preemption: 0/6 nodes are available: 6 Preemption is not helpful for scheduling."
0.2912,Event,ADDED,eval-conflicts-rho005-r2-041-dqhlz.18d465430e3646a4,reason=Scheduled count=None msg=Successfully assigned compute/eval-conflicts-rho005-r2-041-dqhlz to kind-worker2
0.2914,Event,ADDED,eval-conflicts-rho005-r2-041-dqhlz.18d465432c8c9d4c,"reason=Pulled count=1 msg=Container image ""busybox:musl"" already present on machine"
0.2916,Event,ADDED,eval-conflicts-rho005-r2-041-dqhlz.18d465432f35578f,reason=Created count=1 msg=Created container: task
0.2919,Event,ADDED,eval-conflicts-rho005-r2-041-dqhlz.18d465433342e25b,reason=Started count=1 msg=Started container task
0.2921,Event,ADDED,eval-conflicts-rho005-r2-041.18d465429a337435,reason=SuccessfulCreate count=1 msg=Created pod: eval-conflicts-rho005-r2-041-dqhlz
0.2922,Event,ADDED,eval-conflicts-rho005-r2-041.18d465461e574792,reason=Completed count=1 msg=Job completed
0.2925,Event,ADDED,eval-conflicts-rho005-r2-042-k9x5v.18d46542d5a4401f,"reason=FailedScheduling count=None msg=0/6 nodes are available: 6 node(s) had untolerated taint(s). no new claims to deallocate, preemption: 0/6 nodes are available: 6 Preemption is not helpful for scheduling."
0.2927,Event,ADDED,eval-conflicts-rho005-r2-042-k9x5v.18d465430e849b61,reason=Scheduled count=None msg=Successfully assigned compute/eval-conflicts-rho005-r2-042-k9x5v to kind-worker2
0.2929,Event,ADDED,eval-conflicts-rho005-r2-042-k9x5v.18d465432d2a5360,"reason=Pulled count=1 msg=Container image ""busybox:musl"" already present on machine"
0.293,Event,ADDED,eval-conflicts-rho005-r2-042-k9x5v.18d465432f8f9eb3,reason=Created count=1 msg=Created container: task
0.2935,Event,ADDED,eval-conflicts-rho005-r2-042-k9x5v.18d46543337e4d87,reason=Started count=1 msg=Started container task
0.2937,Event,ADDED,eval-conflicts-rho005-r2-042.18d46542d59576fd,reason=SuccessfulCreate count=1 msg=Created pod: eval-conflicts-rho005-r2-042-k9x5v
0.2939,Event,ADDED,eval-conflicts-rho005-r2-042.18d4654659938bc4,reason=Completed count=1 msg=Job completed
0.294,Event,ADDED,eval-conflicts-rho005-r2-043-sgw6j.18d46543120c9a39,reason=Scheduled count=None msg=Successfully assigned compute/eval-conflicts-rho005-r2-043-sgw6j to kind-worker2
0.2942,Event,ADDED,eval-conflicts-rho005-r2-043-sgw6j.18d465432c0096d4,"reason=Pulled count=1 msg=Container image ""busybox:musl"" already present on machine"
0.2944,Event,ADDED,eval-conflicts-rho005-r2-043-sgw6j.18d465432df91a5b,reason=Created count=1 msg=Created container: task
0.2946,Event,ADDED,eval-conflicts-rho005-r2-043-sgw6j.18d46543329a55ac,reason=Started count=1 msg=Started container task
0.2947,Event,ADDED,eval-conflicts-rho005-r2-043.18d465431119ba25,reason=SuccessfulCreate count=1 msg=Created pod: eval-conflicts-rho005-r2-043-sgw6j
0.2949,Event,ADDED,eval-conflicts-rho005-r2-043.18d4654658ebc826,reason=Completed count=1 msg=Job completed
0.295,Event,ADDED,eval-conflicts-rho005-r2-044-4rlbj.18d465434d53e96b,reason=Scheduled count=None msg=Successfully assigned compute/eval-conflicts-rho005-r2-044-4rlbj to kind-worker2
0.2952,Event,ADDED,eval-conflicts-rho005-r2-044-4rlbj.18d4654369953ed4,"reason=Pulled count=1 msg=Container image ""busybox:musl"" already present on machine"
0.2954,Event,ADDED,eval-conflicts-rho005-r2-044-4rlbj.18d465436aef8af2,reason=Created count=1 msg=Created container: task
0.2955,Event,ADDED,eval-conflicts-rho005-r2-044-4rlbj.18d465436ea1d188,reason=Started count=1 msg=Started container task
0.2957,Event,ADDED,eval-conflicts-rho005-r2-044.18d465434cd238dc,reason=SuccessfulCreate count=1 msg=Created pod: eval-conflicts-rho005-r2-044-4rlbj
0.2959,Event,ADDED,eval-conflicts-rho005-r2-044.18d4654695875d0d,reason=Completed count=1 msg=Job completed
0.296,Event,ADDED,eval-conflicts-rho005-r2-045-6grjd.18d46543893161ff,reason=Scheduled count=None msg=Successfully assigned compute/eval-conflicts-rho005-r2-045-6grjd to kind-worker2
0.2962,Event,ADDED,eval-conflicts-rho005-r2-045-6grjd.18d46543a302d18d,"reason=Pulled count=1 msg=Container image ""busybox:musl"" already present on machine"
0.2963,Event,ADDED,eval-conflicts-rho005-r2-045-6grjd.18d46543a41ba9b6,reason=Created count=1 msg=Created container: task
0.2965,Event,ADDED,eval-conflicts-rho005-r2-045-6grjd.18d46543a6460683,reason=Started count=1 msg=Started container task
0.2967,Event,ADDED,eval-conflicts-rho005-r2-045.18d46543889179fb,reason=SuccessfulCreate count=1 msg=Created pod: eval-conflicts-rho005-r2-045-6grjd
0.2968,Event,ADDED,eval-conflicts-rho005-r2-045.18d46546d24d5f24,reason=Completed count=1 msg=Job completed
0.297,Event,ADDED,eval-conflicts-rho005-r2-046-dkjnx.18d46543c4a42ad5,reason=Scheduled count=None msg=Successfully assigned compute/eval-conflicts-rho005-r2-046-dkjnx to kind-worker2
0.2972,Event,ADDED,eval-conflicts-rho005-r2-046-dkjnx.18d46543e1895bb3,"reason=Pulled count=1 msg=Container image ""busybox:musl"" already present on machine"
0.2973,Event,ADDED,eval-conflicts-rho005-r2-046-dkjnx.18d46543e2f645a6,reason=Created count=1 msg=Created container: task
0.2975,Event,ADDED,eval-conflicts-rho005-r2-046-dkjnx.18d46543e91e30f9,reason=Started count=1 msg=Started container task
0.2977,Event,ADDED,eval-conflicts-rho005-r2-046.18d46543c40f4381,reason=SuccessfulCreate count=1 msg=Created pod: eval-conflicts-rho005-r2-046-dkjnx
0.2978,Event,ADDED,eval-conflicts-rho005-r2-046.18d465470e203eaf,reason=Completed count=1 msg=Job completed
0.298,Event,ADDED,eval-conflicts-rho005-r2-047-hsxlr.18d4654400891e6b,reason=Scheduled count=None msg=Successfully assigned compute/eval-conflicts-rho005-r2-047-hsxlr to kind-worker5
0.2982,Event,ADDED,eval-conflicts-rho005-r2-047-hsxlr.18d465441e4ba98d,"reason=Pulled count=1 msg=Container image ""busybox:musl"" already present on machine"
0.2983,Event,ADDED,eval-conflicts-rho005-r2-047-hsxlr.18d465441f57b2ef,reason=Created count=1 msg=Created container: task
0.2985,Event,ADDED,eval-conflicts-rho005-r2-047-hsxlr.18d465442337de1e,reason=Started count=1 msg=Started container task
0.2987,Event,ADDED,eval-conflicts-rho005-r2-047.18d46543ff64ef65,reason=SuccessfulCreate count=1 msg=Created pod: eval-conflicts-rho005-r2-047-hsxlr
0.2988,Event,ADDED,eval-conflicts-rho005-r2-047.18d465472edb9682,reason=Completed count=1 msg=Job completed
0.299,Event,ADDED,eval-conflicts-rho005-r2-048-smlpc.18d465443bfc06e9,reason=Scheduled count=None msg=Successfully assigned compute/eval-conflicts-rho005-r2-048-smlpc to kind-worker5
0.2991,Event,ADDED,eval-conflicts-rho005-r2-048-smlpc.18d4654455255e51,"reason=Pulled count=1 msg=Container image ""busybox:musl"" already present on machine"
0.2993,Event,ADDED,eval-conflicts-rho005-r2-048-smlpc.18d4654456c85fbe,reason=Created count=1 msg=Created container: task
0.2995,Event,ADDED,eval-conflicts-rho005-r2-048-smlpc.18d465445a44acff,reason=Started count=1 msg=Started container task
0.2996,Event,ADDED,eval-conflicts-rho005-r2-048.18d465443af77dc9,reason=SuccessfulCreate count=1 msg=Created pod: eval-conflicts-rho005-r2-048-smlpc
0.2998,Event,ADDED,eval-conflicts-rho005-r2-048.18d465476abb5635,reason=Completed count=1 msg=Job completed
0.2999,Event,ADDED,eval-conflicts-rho005-r2-049-2h2rh.18d4654477550c42,reason=Scheduled count=None msg=Successfully assigned compute/eval-conflicts-rho005-r2-049-2h2rh to kind-worker5
0.3001,Event,ADDED,eval-conflicts-rho005-r2-049-2h2rh.18d4654490434e16,"reason=Pulled count=1 msg=Container image ""busybox:musl"" already present on machine"
0.3003,Event,ADDED,eval-conflicts-rho005-r2-049-2h2rh.18d465449149d0fb,reason=Created count=1 msg=Created container: task
0.3006,Event,ADDED,eval-conflicts-rho005-r2-049-2h2rh.18d465449337d43e,reason=Started count=1 msg=Started container task
0.3008,Event,ADDED,eval-conflicts-rho005-r2-049.18d46544766e5e6e,reason=SuccessfulCreate count=1 msg=Created pod: eval-conflicts-rho005-r2-049-2h2rh
0.301,Event,ADDED,eval-conflicts-rho005-r2-049.18d46547a6c8f076,reason=Completed count=1 msg=Job completed
0.3012,Event,ADDED,eval-conflicts-rho005-r2-050-6942j.18d46544b352a716,reason=Scheduled count=None msg=Successfully assigned compute/eval-conflicts-rho005-r2-050-6942j to kind-worker5
0.3014,Event,ADDED,eval-conflicts-rho005-r2-050-6942j.18d46544cc083c2d,"reason=Pulled count=1 msg=Container image ""busybox:musl"" already present on machine"
0.3016,Event,ADDED,eval-conflicts-rho005-r2-050-6942j.18d46544cd15f3c9,reason=Created count=1 msg=Created container: task
0.3017,Event,ADDED,eval-conflicts-rho005-r2-050-6942j.18d46544cf08802d,reason=Started count=1 msg=Started container task
0.302,Event,ADDED,eval-conflicts-rho005-r2-050.18d46544b2736043,reason=SuccessfulCreate count=1 msg=Created pod: eval-conflicts-rho005-r2-050-6942j
0.3022,Event,ADDED,eval-conflicts-rho005-r2-050.18d46547e27ac4d3,reason=Completed count=1 msg=Job completed
0.3023,Event,ADDED,eval-conflicts-rho005-r2-051-bbv9x.18d46544eeb89287,reason=Scheduled count=None msg=Successfully assigned compute/eval-conflicts-rho005-r2-051-bbv9x to kind-worker4
0.3025,Event,ADDED,eval-conflicts-rho005-r2-051-bbv9x.18d465450874a16b,"reason=Pulled count=1 msg=Container image ""busybox:musl"" already present on machine"
0.3028,Event,ADDED,eval-conflicts-rho005-r2-051-bbv9x.18d465450999451a,reason=Created count=1 msg=Created container: task
0.303,Event,ADDED,eval-conflicts-rho005-r2-051-bbv9x.18d465450ddc8d1f,reason=Started count=1 msg=Started container task
0.3032,Event,ADDED,eval-conflicts-rho005-r2-051.18d46544edd03cf6,reason=SuccessfulCreate count=1 msg=Created pod: eval-conflicts-rho005-r2-051-bbv9x
0.3034,Event,ADDED,eval-conflicts-rho005-r2-051.18d465485295b835,reason=Completed count=1 msg=Job completed
0.3035,Event,ADDED,eval-conflicts-rho005-r2-052-flvdb.18d465452ad5340e,reason=Scheduled count=None msg=Successfully assigned compute/eval-conflicts-rho005-r2-052-flvdb to kind-worker4
0.3037,Event,ADDED,eval-conflicts-rho005-r2-052-flvdb.18d4654543cd08a8,"reason=Pulled count=1 msg=Container image ""busybox:musl"" already present on machine"
0.3039,Event,ADDED,eval-conflicts-rho005-r2-052-flvdb.18d4654544f15468,reason=Created count=1 msg=Created container: task
0.3041,Event,ADDED,eval-conflicts-rho005-r2-052-flvdb.18d4654549b9d47f,reason=Started count=1 msg=Started container task
0.3043,Event,ADDED,eval-conflicts-rho005-r2-052.18d46545296e3448,reason=SuccessfulCreate count=1 msg=Created pod: eval-conflicts-rho005-r2-052-flvdb
0.3044,Event,ADDED,eval-conflicts-rho005-r2-052.18d465488f027460,reason=Completed count=1 msg=Job completed
0.3046,Event,ADDED,eval-conflicts-rho005-r2-053-dkjzw.18d46545667ef693,reason=Scheduled count=None msg=Successfully assigned compute/eval-conflicts-rho005-r2-053-dkjzw to kind-worker5
0.3048,Event,ADDED,eval-conflicts-rho005-r2-053-dkjzw.18d465457f98e7b9,"reason=Pulled count=1 msg=Container image ""busybox:musl"" already present on machine"
0.3049,Event,ADDED,eval-conflicts-rho005-r2-053-dkjzw.18d4654580be55e2,reason=Created count=1 msg=Created container: task
0.3051,Event,ADDED,eval-conflicts-rho005-r2-053-dkjzw.18d4654583a9ae57,reason=Started count=1 msg=Started container task
0.3052,Event,ADDED,eval-conflicts-rho005-r2-053.18d4654565412738,reason=SuccessfulCreate count=1 msg=Created pod: eval-conflicts-rho005-r2-053-dkjzw
0.3054,Event,ADDED,eval-conflicts-rho005-r2-053.18d46548968042b2,reason=Completed count=1 msg=Job completed
0.3056,Event,ADDED,eval-conflicts-rho005-r2-054-vwclv.18d46545a2aef883,reason=Scheduled count=None msg=Successfully assigned compute/eval-conflicts-rho005-r2-054-vwclv to kind-worker4
0.3058,Event,ADDED,eval-conflicts-rho005-r2-054-vwclv.18d46545bcd13a74,"reason=Pulled count=1 msg=Container image ""busybox:musl"" already present on machine"
0.306,Event,ADDED,eval-conflicts-rho005-r2-054-vwclv.18d46545bde84169,reason=Created count=1 msg=Created container: task
0.3062,Event,ADDED,eval-conflicts-rho005-r2-054-vwclv.18d46545c1923e37,reason=Started count=1 msg=Started container task
0.3064,Event,ADDED,eval-conflicts-rho005-r2-054.18d46545a1dfe718,reason=SuccessfulCreate count=1 msg=Created pod: eval-conflicts-rho005-r2-054-vwclv
0.3065,Event,ADDED,eval-conflicts-rho005-r2-054.18d4654909beeffc,reason=Completed count=1 msg=Job completed
0.3067,Event,ADDED,eval-conflicts-rho005-r2-055-9fbq5.18d46545ddcddb8e,reason=Scheduled count=None msg=Successfully assigned compute/eval-conflicts-rho005-r2-055-9fbq5 to kind-worker3
0.3069,Event,ADDED,eval-conflicts-rho005-r2-055-9fbq5.18d46545f7538204,"reason=Pulled count=1 msg=Container image ""busybox:musl"" already present on machine"
0.307,Event,ADDED,eval-conflicts-rho005-r2-055-9fbq5.18d46545f866bc84,reason=Created count=1 msg=Created container: task
0.3072,Event,ADDED,eval-conflicts-rho005-r2-055-9fbq5.18d4654601a82afe,reason=Started count=1 msg=Started container task
0.3073,Event,ADDED,eval-conflicts-rho005-r2-055.18d46545dcd5ced5,reason=SuccessfulCreate count=1 msg=Created pod: eval-conflicts-rho005-r2-055-9fbq5
0.3075,Event,ADDED,eval-conflicts-rho005-r2-055.18d465493ab0cc6e,reason=Completed count=1 msg=Job completed
0.3077,Event,ADDED,eval-conflicts-rho005-r2-056-5f47h.18d46546192314cf,reason=Scheduled count=None msg=Successfully assigned compute/eval-conflicts-rho005-r2-056-5f47h to kind-worker4
0.3078,Event,ADDED,eval-conflicts-rho005-r2-056-5f47h.18d4654632a4f4f2,"reason=Pulled count=1 msg=Container image ""busybox:musl"" already present on machine"
0.308,Event,ADDED,eval-conflicts-rho005-r2-056-5f47h.18d4654633af69de,reason=Created count=1 msg=Created container: task
0.3082,Event,ADDED,eval-conflicts-rho005-r2-056-5f47h.18d465463592c63d,reason=Started count=1 msg=Started container task
0.3083,Event,ADDED,eval-conflicts-rho005-r2-056.18d4654617eadb28,reason=SuccessfulCreate count=1 msg=Created pod: eval-conflicts-rho005-r2-056-5f47h
0.3085,Event,ADDED,eval-conflicts-rho005-r2-056.18d4654949115cf3,reason=Completed count=1 msg=Job completed
0.3087,Event,ADDED,eval-conflicts-rho005-r2-057-z5cdf.18d4654653d457da,reason=Scheduled count=None msg=Successfully assigned compute/eval-conflicts-rho005-r2-057-z5cdf to kind-worker4
0.3088,Event,ADDED,eval-conflicts-rho005-r2-057-z5cdf.18d465466d0a7574,"reason=Pulled count=1 msg=Container image ""busybox:musl"" already present on machine"
0.309,Event,ADDED,eval-conflicts-rho005-r2-057-z5cdf.18d465466e131a2a,reason=Created count=1 msg=Created container: task
0.3092,Event,ADDED,eval-conflicts-rho005-r2-057-z5cdf.18d465467025da10,reason=Started count=1 msg=Started container task
0.3093,Event,ADDED,eval-conflicts-rho005-r2-057.18d465465356e890,reason=SuccessfulCreate count=1 msg=Created pod: eval-conflicts-rho005-r2-057-z5cdf
0.3096,Event,ADDED,eval-conflicts-rho005-r2-057.18d46549bf3309e5,reason=Completed count=1 msg=Job completed
0.3097,Event,ADDED,eval-conflicts-rho005-r2-058-27pjr.18d465468f9f4c18,reason=Scheduled count=None msg=Successfully assigned compute/eval-conflicts-rho005-r2-058-27pjr to kind-worker4
0.3099,Event,ADDED,eval-conflicts-rho005-r2-058-27pjr.18d46546a9f5495a,"reason=Pulled count=1 msg=Container image ""busybox:musl"" already present on machine"
0.31,Event,ADDED,eval-conflicts-rho005-r2-058-27pjr.18d46546ab1b37e8,reason=Created count=1 msg=Created container: task
0.3102,Event,ADDED,eval-conflicts-rho005-r2-058-27pjr.18d46546ae199538,reason=Started count=1 msg=Started container task
0.3104,Event,ADDED,eval-conflicts-rho005-r2-058.18d465468f0d8945,reason=SuccessfulCreate count=1 msg=Created pod: eval-conflicts-rho005-r2-058-27pjr
0.3105,Event,ADDED,eval-conflicts-rho005-r2-058.18d46549bf32dfdc,reason=Completed count=1 msg=Job completed
0.3107,Event,ADDED,eval-conflicts-rho005-r2-059-mmrj4.18d46546cb768617,reason=Scheduled count=None msg=Successfully assigned compute/eval-conflicts-rho005-r2-059-mmrj4 to kind-worker4
0.3109,Event,ADDED,eval-conflicts-rho005-r2-059-mmrj4.18d46546e4223941,"reason=Pulled count=1 msg=Container image ""busybox:musl"" already present on machine"
0.3111,Event,ADDED,eval-conflicts-rho005-r2-059-mmrj4.18d46546e53e6852,reason=Created count=1 msg=Created container: task
0.3112,Event,ADDED,eval-conflicts-rho005-r2-059-mmrj4.18d46546e8d22747,reason=Started count=1 msg=Started container task
0.3114,Event,ADDED,eval-conflicts-rho005-r2-059.18d46546cadbbd67,reason=SuccessfulCreate count=1 msg=Created pod: eval-conflicts-rho005-r2-059-mmrj4
0.3116,Event,ADDED,eval-conflicts-rho005-r2-059.18d46549fe341061,reason=Completed count=1 msg=Job completed
0.3117,Event,ADDED,eval-conflicts-rho005-r2-060-dthp7.18d46547080fb7f9,reason=Scheduled count=None msg=Successfully assigned compute/eval-conflicts-rho005-r2-060-dthp7 to kind-worker
0.3119,Event,ADDED,eval-conflicts-rho005-r2-060-dthp7.18d4654721ead54b,"reason=Pulled count=1 msg=Container image ""busybox:musl"" already present on machine"
0.3121,Event,ADDED,eval-conflicts-rho005-r2-060-dthp7.18d465472307f489,reason=Created count=1 msg=Created container: task
0.3122,Event,ADDED,eval-conflicts-rho005-r2-060-dthp7.18d465472beef1ea,reason=Started count=1 msg=Started container task
0.3124,Event,ADDED,eval-conflicts-rho005-r2-060.18d4654707b51665,reason=SuccessfulCreate count=1 msg=Created pod: eval-conflicts-rho005-r2-060-dthp7
0.3126,Event,ADDED,eval-conflicts-rho005-r2-060.18d4654a6add7258,reason=Completed count=1 msg=Job completed
0.3127,Event,ADDED,eval-conflicts-rho005-r2-061-s29pd.18d4654743857b2b,reason=Scheduled count=None msg=Successfully assigned compute/eval-conflicts-rho005-r2-061-s29pd to kind-worker
0.3129,Event,ADDED,eval-conflicts-rho005-r2-061-s29pd.18d465475e24bf40,"reason=Pulled count=1 msg=Container image ""busybox:musl"" already present on machine"
0.313,Event,ADDED,eval-conflicts-rho005-r2-061-s29pd.18d465475f36b62b,reason=Created count=1 msg=Created container: task
0.3138,Event,ADDED,eval-conflicts-rho005-r2-061-s29pd.18d4654761bde2c4,reason=Started count=1 msg=Started container task
0.314,Event,ADDED,eval-conflicts-rho005-r2-061.18d4654742f312d6,reason=SuccessfulCreate count=1 msg=Created pod: eval-conflicts-rho005-r2-061-s29pd
0.3142,Event,ADDED,eval-conflicts-rho005-r2-061.18d4654aa6a020a3,reason=Completed count=1 msg=Job completed
0.3145,Event,ADDED,eval-conflicts-rho005-r2-062-v6kf8.18d465477f8b79a8,reason=Scheduled count=None msg=Successfully assigned compute/eval-conflicts-rho005-r2-062-v6kf8 to kind-worker
0.3148,Event,ADDED,eval-conflicts-rho005-r2-062-v6kf8.18d4654799047115,"reason=Pulled count=1 msg=Container image ""busybox:musl"" already present on machine"
0.315,Event,ADDED,eval-conflicts-rho005-r2-062-v6kf8.18d465479a1fdfff,reason=Created count=1 msg=Created container: task
0.3152,Event,ADDED,eval-conflicts-rho005-r2-062-v6kf8.18d465479c9c841f,reason=Started count=1 msg=Started container task
0.3156,Event,ADDED,eval-conflicts-rho005-r2-062.18d465477eedf697,reason=SuccessfulCreate count=1 msg=Created pod: eval-conflicts-rho005-r2-062-v6kf8
0.3158,Event,ADDED,eval-conflicts-rho005-r2-062.18d4654add6e14be,reason=Completed count=1 msg=Job completed
0.316,Event,ADDED,eval-conflicts-rho005-r2-063-4bp9x.18d46547ba4a5ad8,reason=Scheduled count=None msg=Successfully assigned compute/eval-conflicts-rho005-r2-063-4bp9x to kind-worker
0.3161,Event,ADDED,eval-conflicts-rho005-r2-063-4bp9x.18d46547d35e3071,"reason=Pulled count=1 msg=Container image ""busybox:musl"" already present on machine"
0.3165,Event,ADDED,eval-conflicts-rho005-r2-063-4bp9x.18d46547d46f6b46,reason=Created count=1 msg=Created container: task
0.3167,Event,ADDED,eval-conflicts-rho005-r2-063-4bp9x.18d46547d697cb88,reason=Started count=1 msg=Started container task
0.3169,Event,ADDED,eval-conflicts-rho005-r2-063.18d46547b9c5524f,reason=SuccessfulCreate count=1 msg=Created pod: eval-conflicts-rho005-r2-063-4bp9x
0.317,Event,ADDED,eval-conflicts-rho005-r2-063.18d4654b1bb07305,reason=Completed count=1 msg=Job completed
0.3174,Event,ADDED,eval-conflicts-rho005-r2-064-4pfm4.18d46547f67ce292,reason=Scheduled count=None msg=Successfully assigned compute/eval-conflicts-rho005-r2-064-4pfm4 to kind-worker2
0.3176,Event,ADDED,eval-conflicts-rho005-r2-064-4pfm4.18d465480f89a027,"reason=Pulled count=1 msg=Container image ""busybox:musl"" already present on machine"
0.3178,Event,ADDED,eval-conflicts-rho005-r2-064-4pfm4.18d4654810c34d59,reason=Created count=1 msg=Created container: task
0.3181,Event,ADDED,eval-conflicts-rho005-r2-064-4pfm4.18d4654813911596,reason=Started count=1 msg=Started container task
0.3183,Event,ADDED,eval-conflicts-rho005-r2-064.18d46547f567a680,reason=SuccessfulCreate count=1 msg=Created pod: eval-conflicts-rho005-r2-064-4pfm4
0.3185,Event,ADDED,eval-conflicts-rho005-r2-064.18d4654b40d6c70a,reason=Completed count=1 msg=Job completed
0.3187,Event,ADDED,eval-conflicts-rho005-r2-065-c77cv.18d46548312e6b4f,"reason=FailedScheduling count=None msg=0/6 nodes are available: 2 c_wall violated: 1 conflicting context pair(s) with node memory, 4 node(s) had untolerated taint(s). no new claims to deallocate, preemption: 0/6 nodes are available: 2 No preemption victims found for incoming pod, 4 Preemption is not helpful for scheduling."
0.3191,Event,ADDED,eval-conflicts-rho005-r2-065-c77cv.18d4654835a3f952,"reason=FailedScheduling count=None msg=0/6 nodes are available: 2 c_wall violated: 1 conflicting context pair(s) with node memory, 4 node(s) had untolerated taint(s). no new claims to deallocate, preemption: 0/6 nodes are available: 2 No preemption victims found for incoming pod, 4 Preemption is not helpful for scheduling."
0.3192,Event,ADDED,eval-conflicts-rho005-r2-065-c77cv.18d46548a55d838c,reason=Scheduled count=None msg=Successfully assigned compute/eval-conflicts-rho005-r2-065-c77cv to kind-worker5
0.3195,Event,ADDED,eval-conflicts-rho005-r2-065-c77cv.18d46548bef41d95,"reason=Pulled count=1 msg=Container image ""busybox:musl"" already present on machine"
0.3198,Event,ADDED,eval-conflicts-rho005-r2-065-c77cv.18d46548c259c4c7,reason=Created count=1 msg=Created container: task
0.32,Event,ADDED,eval-conflicts-rho005-r2-065-c77cv.18d46548c8854354,reason=Started count=1 msg=Started container task
0.3202,Event,ADDED,eval-conflicts-rho005-r2-065.18d4654830949ed5,reason=SuccessfulCreate count=1 msg=Created pod: eval-conflicts-rho005-r2-065-c77cv
0.3203,Event,ADDED,eval-conflicts-rho005-r2-065.18d4654bdaee3e23,reason=Completed count=1 msg=Job completed
0.3206,Event,ADDED,eval-conflicts-rho005-r2-066-rwh48.18d465486cbcbd57,reason=Scheduled count=None msg=Successfully assigned compute/eval-conflicts-rho005-r2-066-rwh48 to kind-worker2
0.3208,Event,ADDED,eval-conflicts-rho005-r2-066-rwh48.18d4654886178046,"reason=Pulled count=1 msg=Container image ""busybox:musl"" already present on machine"
0.321,Event,ADDED,eval-conflicts-rho005-r2-066-rwh48.18d46548873f9113,reason=Created count=1 msg=Created container: task
0.3212,Event,ADDED,eval-conflicts-rho005-r2-066-rwh48.18d465488a50bd70,reason=Started count=1 msg=Started container task
0.3214,Event,ADDED,eval-conflicts-rho005-r2-066.18d465486be0f747,reason=SuccessfulCreate count=1 msg=Created pod: eval-conflicts-rho005-r2-066-rwh48
0.3216,Event,ADDED,eval-conflicts-rho005-r2-066.18d4654bb898766d,reason=Completed count=1 msg=Job completed
0.3217,Event,ADDED,eval-conflicts-rho005-r2-067-p74vj.18d46548aaa4a894,reason=Scheduled count=None msg=Successfully assigned compute/eval-conflicts-rho005-r2-067-p74vj to kind-worker5
0.322,Event,ADDED,eval-conflicts-rho005-r2-067-p74vj.18d46548c684facd,"reason=Pulled count=1 msg=Container image ""busybox:musl"" already present on machine"
0.3223,Event,ADDED,eval-conflicts-rho005-r2-067-p74vj.18d46548c7a2bf91,reason=Created count=1 msg=Created container: task
0.3225,Event,ADDED,eval-conflicts-rho005-r2-067-p74vj.18d46548d261a5a9,reason=Started count=1 msg=Started container task
0.3226,Event,ADDED,eval-conflicts-rho005-r2-067.18d46548a767e419,reason=SuccessfulCreate count=1 msg=Created pod: eval-conflicts-rho005-r2-067-p74vj
0.3229,Event,ADDED,eval-conflicts-rho005-r2-067.18d4654c16e69859,reason=Completed count=1 msg=Job completed
0.3232,Event,ADDED,eval-conflicts-rho005-r2-068-wrfv9.18d46548e45a0ab3,reason=Scheduled count=None msg=Successfully assigned compute/eval-conflicts-rho005-r2-068-wrfv9 to kind-worker5
0.3234,Event,ADDED,eval-conflicts-rho005-r2-068-wrfv9.18d46548fe79cdce,"reason=Pulled count=1 msg=Container image ""busybox:musl"" already present on machine"
0.3237,Event,ADDED,eval-conflicts-rho005-r2-068-wrfv9.18d46548ffb9dc7c,reason=Created count=1 msg=Created container: task
0.3239,Event,ADDED,eval-conflicts-rho005-r2-068-wrfv9.18d4654901b047b2,reason=Started count=1 msg=Started container task
0.3241,Event,ADDED,eval-conflicts-rho005-r2-068.18d46548e3251fa3,reason=SuccessfulCreate count=1 msg=Created pod: eval-conflicts-rho005-r2-068-wrfv9
0.3243,Event,ADDED,eval-conflicts-rho005-r2-068.18d4654c16bbf764,reason=Completed count=1 msg=Job completed
0.3246,Event,ADDED,eval-conflicts-rho005-r2-069-8t7q5.18d46549201ba15c,reason=Scheduled count=None msg=Successfully assigned compute/eval-conflicts-rho005-r2-069-8t7q5 to kind-worker5
0.3248,Event,ADDED,eval-conflicts-rho005-r2-069-8t7q5.18d4654939e66dc4,"reason=Pulled count=1 msg=Container image ""busybox:musl"" already present on machine"
0.325,Event,ADDED,eval-conflicts-rho005-r2-069-8t7q5.18d465493b3e4b7f,reason=Created count=1 msg=Created container: task
0.3253,Event,ADDED,eval-conflicts-rho005-r2-069-8t7q5.18d4654941b1360d,reason=Started count=1 msg=Started container task
0.3255,Event,ADDED,eval-conflicts-rho005-r2-069.18d465491ef3ad85,reason=SuccessfulCreate count=1 msg=Created pod: eval-conflicts-rho005-r2-069-8t7q5
0.3256,Event,ADDED,eval-conflicts-rho005-r2-069.18d4654c533defe8,reason=Completed count=1 msg=Job completed
0.3258,Event,ADDED,eval-conflicts-rho005-r2-070-pzcx4.18d465495bde2bad,reason=Scheduled count=None msg=Successfully assigned compute/eval-conflicts-rho005-r2-070-pzcx4 to kind-worker2
0.3261,Event,ADDED,eval-conflicts-rho005-r2-070-pzcx4.18d465497604bc06,"reason=Pulled count=1 msg=Container image ""busybox:musl"" already present on machine"
0.3263,Event,ADDED,eval-conflicts-rho005-r2-070-pzcx4.18d46549770ed3d5,reason=Created count=1 msg=Created container: task
0.3265,Event,ADDED,eval-conflicts-rho005-r2-070-pzcx4.18d465497b284795,reason=Started count=1 msg=Started container task
0.3266,Event,ADDED,eval-conflicts-rho005-r2-070.18d465495b1fd171,reason=SuccessfulCreate count=1 msg=Created pod: eval-conflicts-rho005-r2-070-pzcx4
0.3272,Event,ADDED,eval-conflicts-rho005-r2-070.18d4654ca811b25b,reason=Completed count=1 msg=Job completed
0.3274,Event,ADDED,eval-conflicts-rho005-r2-071-6h4k7.18d4654996fddfd1,reason=Scheduled count=None msg=Successfully assigned compute/eval-conflicts-rho005-r2-071-6h4k7 to kind-worker2
0.3276,Event,ADDED,eval-conflicts-rho005-r2-071-6h4k7.18d46549b50ffa58,"reason=Pulled count=1 msg=Container image ""busybox:musl"" already present on machine"
0.3279,Event,ADDED,eval-conflicts-rho005-r2-071-6h4k7.18d46549b638cde9,reason=Created count=1 msg=Created container: task
0.3281,Event,ADDED,eval-conflicts-rho005-r2-071-6h4k7.18d46549beb26271,reason=Started count=1 msg=Started container task
0.3283,Event,ADDED,eval-conflicts-rho005-r2-071.18d465499647ce36,reason=SuccessfulCreate count=1 msg=Created pod: eval-conflicts-rho005-r2-071-6h4k7
0.3285,Event,ADDED,eval-conflicts-rho005-r2-071.18d4654ce307c0b9,reason=Completed count=1 msg=Job completed
0.3288,Event,ADDED,eval-conflicts-rho005-r2-072-nkwkm.18d46549d54d5003,reason=Scheduled count=None msg=Successfully assigned compute/eval-conflicts-rho005-r2-072-nkwkm to kind-worker2
0.329,Event,ADDED,eval-conflicts-rho005-r2-072-nkwkm.18d46549f312a64b,"reason=Pulled count=1 msg=Container image ""busybox:musl"" already present on machine"
0.3292,Event,ADDED,eval-conflicts-rho005-r2-072-nkwkm.18d46549f42d1024,reason=Created count=1 msg=Created container: task
0.3293,Event,ADDED,eval-conflicts-rho005-r2-072-nkwkm.18d46549fdf25860,reason=Started count=1 msg=Started container task
0.3296,Event,ADDED,eval-conflicts-rho005-r2-072.18d46549d47e7e98,reason=SuccessfulCreate count=1 msg=Created pod: eval-conflicts-rho005-r2-072-nkwkm
0.3297,Event,ADDED,eval-conflicts-rho005-r2-072.18d4654d1ff69fa8,reason=Completed count=1 msg=Job completed
0.3299,Event,ADDED,eval-conflicts-rho005-r2-073-67bfm.18d4654a139cb05f,reason=Scheduled count=None msg=Successfully assigned compute/eval-conflicts-rho005-r2-073-67bfm to kind-worker5
0.3302,Event,ADDED,eval-conflicts-rho005-r2-073-67bfm.18d4654a2e07aee9,"reason=Pulled count=1 msg=Container image ""busybox:musl"" already present on machine"
0.3304,Event,ADDED,eval-conflicts-rho005-r2-073-67bfm.18d4654a2f6bea84,reason=Created count=1 msg=Created container: task
0.3306,Event,ADDED,eval-conflicts-rho005-r2-073-67bfm.18d4654a36242642,reason=Started count=1 msg=Started container task
0.3308,Event,ADDED,eval-conflicts-rho005-r2-073.18d4654a12b3ee9b,reason=SuccessfulCreate count=1 msg=Created pod: eval-conflicts-rho005-r2-073-67bfm
0.3311,Event,ADDED,eval-conflicts-rho005-r2-073.18d4654d7dd3a31a,reason=Completed count=1 msg=Job completed
0.3312,Event,ADDED,eval-conflicts-rho005-r2-074-tx6cp.18d4654a49f75307,reason=Scheduled count=None msg=Successfully assigned compute/eval-conflicts-rho005-r2-074-tx6cp to kind-worker5
0.3314,Event,ADDED,eval-conflicts-rho005-r2-074-tx6cp.18d4654a651156fc,"reason=Pulled count=1 msg=Container image ""busybox:musl"" already present on machine"
0.3316,Event,ADDED,eval-conflicts-rho005-r2-074-tx6cp.18d4654a665f90cb,reason=Created count=1 msg=Created container: task
0.3318,Event,ADDED,eval-conflicts-rho005-r2-074-tx6cp.18d4654a6fefe4b3,reason=Started count=1 msg=Started container task
0.332,Event,ADDED,eval-conflicts-rho005-r2-074.18d4654a49789927,reason=SuccessfulCreate count=1 msg=Created pod: eval-conflicts-rho005-r2-074-tx6cp
0.3321,Event,ADDED,eval-conflicts-rho005-r2-074.18d4654d428588bc,reason=Completed count=1 msg=Job completed
0.3323,Event,ADDED,eval-conflicts-rho005-r2-075-4qwf7.18d4654a85828e74,reason=Scheduled count=None msg=Successfully assigned compute/eval-conflicts-rho005-r2-075-4qwf7 to kind-worker5
0.3325,Event,ADDED,eval-conflicts-rho005-r2-075-4qwf7.18d4654a9e4a0c99,"reason=Pulled count=1 msg=Container image ""busybox:musl"" already present on machine"
0.3326,Event,ADDED,eval-conflicts-rho005-r2-075-4qwf7.18d4654a9f563830,reason=Created count=1 msg=Created container: task
0.3328,Event,ADDED,eval-conflicts-rho005-r2-075-4qwf7.18d4654aa1567862,reason=Started count=1 msg=Started container task
0.333,Event,ADDED,eval-conflicts-rho005-r2-075.18d4654a84ce4a51,reason=SuccessfulCreate count=1 msg=Created pod: eval-conflicts-rho005-r2-075-4qwf7
0.3331,Event,ADDED,eval-conflicts-rho005-r2-075.18d4654db9c27a05,reason=Completed count=1 msg=Job completed
0.3333,Event,ADDED,eval-conflicts-rho005-r2-076-mzbl9.18d4654ac1c5f571,reason=Scheduled count=None msg=Successfully assigned compute/eval-conflicts-rho005-r2-076-mzbl9 to kind-worker5
0.3335,Event,ADDED,eval-conflicts-rho005-r2-076-mzbl9.18d4654adb57858f,"reason=Pulled count=1 msg=Container image ""busybox:musl"" already present on machine"
0.3336,Event,ADDED,eval-conflicts-rho005-r2-076-mzbl9.18d4654adc742470,reason=Created count=1 msg=Created container: task
0.3339,Event,ADDED,eval-conflicts-rho005-r2-076-mzbl9.18d4654ae31b96df,reason=Started count=1 msg=Started container task
0.3341,Event,ADDED,eval-conflicts-rho005-r2-076.18d4654ac13efa11,reason=SuccessfulCreate count=1 msg=Created pod: eval-conflicts-rho005-r2-076-mzbl9
0.3344,Event,ADDED,eval-conflicts-rho005-r2-076.18d4654df596aa7f,reason=Completed count=1 msg=Job completed
0.3345,Event,ADDED,eval-conflicts-rho005-r2-077-h2c7t.18d4654afc5f13b7,reason=Scheduled count=None msg=Successfully assigned compute/eval-conflicts-rho005-r2-077-h2c7t to kind-worker5
0.3347,Event,ADDED,eval-conflicts-rho005-r2-077-h2c7t.18d4654b155dfc5e,"reason=Pulled count=1 msg=Container image ""busybox:musl"" already present on machine"
0.3349,Event,ADDED,eval-conflicts-rho005-r2-077-h2c7t.18d4654b169aef2a,reason=Created count=1 msg=Created container: task
0.3352,Event,ADDED,eval-conflicts-rho005-r2-077-h2c7t.18d4654b1b6c6c49,reason=Started count=1 msg=Started container task
0.3354,Event,ADDED,eval-conflicts-rho005-r2-077.18d4654afbdfd020,reason=SuccessfulCreate count=1 msg=Created pod: eval-conflicts-rho005-r2-077-h2c7t
0.3356,Event,ADDED,eval-conflicts-rho005-r2-077.18d4654e3125e99f,reason=Completed count=1 msg=Job completed
0.3359,Event,ADDED,eval-conflicts-rho005-r2-078-86pkp.18d4654b3775fc4f,reason=Scheduled count=None msg=Successfully assigned compute/eval-conflicts-rho005-r2-078-86pkp to kind-worker3
0.3361,Event,ADDED,eval-conflicts-rho005-r2-078-86pkp.18d4654b5455fc9b,"reason=Pulled count=1 msg=Container image ""busybox:musl"" already present on machine"
0.3363,Event,ADDED,eval-conflicts-rho005-r2-078-86pkp.18d4654b5566a34c,reason=Created count=1 msg=Created container: task
0.3364,Event,ADDED,eval-conflicts-rho005-r2-078-86pkp.18d4654b61044338,reason=Started count=1 msg=Started container task
0.3367,Event,ADDED,eval-conflicts-rho005-r2-078.18d4654b370c87a9,reason=SuccessfulCreate count=1 msg=Created pod: eval-conflicts-rho005-r2-078-86pkp
0.3369,Event,ADDED,eval-conflicts-rho005-r2-078.18d4654e9672cac6,reason=Completed count=1 msg=Job completed
0.3371,Event,ADDED,eval-conflicts-rho005-r2-079-lgdwb.18d4654b76d16909,reason=Scheduled count=None msg=Successfully assigned compute/eval-conflicts-rho005-r2-079-lgdwb to kind-worker3
0.3374,Event,ADDED,eval-conflicts-rho005-r2-079-lgdwb.18d4654b9071a4a1,"reason=Pulled count=1 msg=Container image ""busybox:musl"" already present on machine"
0.3376,Event,ADDED,eval-conflicts-rho005-r2-079-lgdwb.18d4654b919c49df,reason=Created count=1 msg=Created container: task
0.338,Event,ADDED,eval-conflicts-rho005-r2-079-lgdwb.18d4654b93bfae6a,reason=Started count=1 msg=Started container task
0.3382,Event,ADDED,eval-conflicts-rho005-r2-079.18d4654b7635641a,reason=SuccessfulCreate count=1 msg=Created pod: eval-conflicts-rho005-r2-079-lgdwb
0.3385,Event,ADDED,eval-conflicts-rho005-r2-079.18d4654ed239ccfe,reason=Completed count=1 msg=Job completed
0.3387,Event,ADDED,eval-conflicts-rho005-r2-080-zv2vm.18d4654baf4fce91,reason=Scheduled count=None msg=Successfully assigned compute/eval-conflicts-rho005-r2-080-zv2vm to kind-worker3
0.3389,Event,ADDED,eval-conflicts-rho005-r2-080-zv2vm.18d4654bc86540ea,"reason=Pulled count=1 msg=Container image ""busybox:musl"" already present on machine"
0.3391,Event,ADDED,eval-conflicts-rho005-r2-080-zv2vm.18d4654bc974c6b5,reason=Created count=1 msg=Created container: task
0.3395,Event,ADDED,eval-conflicts-rho005-r2-080-zv2vm.18d4654bcc0e402c,reason=Started count=1 msg=Started container task
0.3396,Event,ADDED,eval-conflicts-rho005-r2-080.18d4654baebddadf,reason=SuccessfulCreate count=1 msg=Created pod: eval-conflicts-rho005-r2-080-zv2vm
0.3398,Event,ADDED,eval-conflicts-rho005-r2-080.18d4654f0e8b0c97,reason=Completed count=1 msg=Job completed
0.3401,Event,ADDED,eval-conflicts-rho005-r2-081-6lfxm.18d4654beae85bc4,reason=Scheduled count=None msg=Successfully assigned compute/eval-conflicts-rho005-r2-081-6lfxm to kind-worker
0.3402,Event,ADDED,eval-conflicts-rho005-r2-081-6lfxm.18d4654c043efad0,"reason=Pulled count=1 msg=Container image ""busybox:musl"" already present on machine"
0.3404,Event,ADDED,eval-conflicts-rho005-r2-081-6lfxm.18d4654c05636ab3,reason=Created count=1 msg=Created container: task
0.3406,Event,ADDED,eval-conflicts-rho005-r2-081-6lfxm.18d4654c07dec9f8,reason=Started count=1 msg=Started container task
0.3408,Event,ADDED,eval-conflicts-rho005-r2-081.18d4654be9ddad3b,reason=SuccessfulCreate count=1 msg=Created pod: eval-conflicts-rho005-r2-081-6lfxm
0.341,Event,ADDED,eval-conflicts-rho005-r2-081.18d4654f4c6e1f22,reason=Completed count=1 msg=Job completed
0.3411,Event,ADDED,eval-conflicts-rho005-r2-082-9cd8d.18d4654c27701641,reason=Scheduled count=None msg=Successfully assigned compute/eval-conflicts-rho005-r2-082-9cd8d to kind-worker
0.3413,Event,ADDED,eval-conflicts-rho005-r2-082-9cd8d.18d4654c404f204c,"reason=Pulled count=1 msg=Container image ""busybox:musl"" already present on machine"
0.3419,Event,ADDED,eval-conflicts-rho005-r2-082-9cd8d.18d4654c416122e3,reason=Created count=1 msg=Created container: task
0.3421,Event,ADDED,eval-conflicts-rho005-r2-082-9cd8d.18d4654c4668a46a,reason=Started count=1 msg=Started container task
0.3422,Event,ADDED,eval-conflicts-rho005-r2-082.18d4654c265b05d5,reason=SuccessfulCreate count=1 msg=Created pod: eval-conflicts-rho005-r2-082-9cd8d
0.3427,Event,ADDED,eval-conflicts-rho005-r2-082.18d4654f890a7f69,reason=Completed count=1 msg=Job completed
0.3429,Event,ADDED,eval-conflicts-rho005-r2-083-4xfmk.18d4654c62abba67,reason=Scheduled count=None msg=Successfully assigned compute/eval-conflicts-rho005-r2-083-4xfmk to kind-worker4
0.3431,Event,ADDED,eval-conflicts-rho005-r2-083-4xfmk.18d4654c7c5b2d7f,"reason=Pulled count=1 msg=Container image ""busybox:musl"" already present on machine"
0.3433,Event,ADDED,eval-conflicts-rho005-r2-083-4xfmk.18d4654c7d6f8f46,reason=Created count=1 msg=Created container: task
0.3436,Event,ADDED,eval-conflicts-rho005-r2-083-4xfmk.18d4654c804b6652,reason=Started count=1 msg=Started container task
0.3438,Event,ADDED,eval-conflicts-rho005-r2-083.18d4654c61d19347,reason=SuccessfulCreate count=1 msg=Created pod: eval-conflicts-rho005-r2-083-4xfmk
0.344,Event,ADDED,eval-conflicts-rho005-r2-083.18d4654f8f7736f8,reason=Completed count=1 msg=Job completed
0.3441,Event,ADDED,eval-conflicts-rho005-r2-084-qtftk.18d4654c9dd25427,reason=Scheduled count=None msg=Successfully assigned compute/eval-conflicts-rho005-r2-084-qtftk to kind-worker
0.3445,Event,ADDED,eval-conflicts-rho005-r2-084-qtftk.18d4654cb60a49ab,"reason=Pulled count=1 msg=Container image ""busybox:musl"" already present on machine"
0.3446,Event,ADDED,eval-conflicts-rho005-r2-084-qtftk.18d4654cb723715c,reason=Created count=1 msg=Created container: task
0.3448,Event,ADDED,eval-conflicts-rho005-r2-084-qtftk.18d4654cb8fb06a6,reason=Started count=1 msg=Started container task
0.3451,Event,ADDED,eval-conflicts-rho005-r2-084.18d4654c9ca5b464,reason=SuccessfulCreate count=1 msg=Created pod: eval-conflicts-rho005-r2-084-qtftk
0.3453,Event,ADDED,eval-conflicts-rho005-r2-084.18d46550009cab9a,reason=Completed count=1 msg=Job completed
0.3455,Event,ADDED,eval-conflicts-rho005-r2-085-qjjkk.18d4654cda19e192,reason=Scheduled count=None msg=Successfully assigned compute/eval-conflicts-rho005-r2-085-qjjkk to kind-worker
0.3456,Event,ADDED,eval-conflicts-rho005-r2-085-qjjkk.18d4654cf3a4e3e2,"reason=Pulled count=1 msg=Container image ""busybox:musl"" already present on machine"
0.3459,Event,ADDED,eval-conflicts-rho005-r2-085-qjjkk.18d4654cf4c1490f,reason=Created count=1 msg=Created container: task
0.3461,Event,ADDED,eval-conflicts-rho005-r2-085-qjjkk.18d4654cf877f0f3,reason=Started count=1 msg=Started container task
0.3463,Event,ADDED,eval-conflicts-rho005-r2-085.18d4654cd8e15730,reason=SuccessfulCreate count=1 msg=Created pod: eval-conflicts-rho005-r2-085-qjjkk
0.3465,Event,ADDED,eval-conflicts-rho005-r2-085.18d465503cb0fa64,reason=Completed count=1 msg=Job completed
0.3467,Event,ADDED,eval-conflicts-rho005-r2-086-2pz62.18d4654d15721ef9,reason=Scheduled count=None msg=Successfully assigned compute/eval-conflicts-rho005-r2-086-2pz62 to kind-worker
0.3468,Event,ADDED,eval-conflicts-rho005-r2-086-2pz62.18d4654d2ea00158,"reason=Pulled count=1 msg=Container image ""busybox:musl"" already present on machine"
0.347,Event,ADDED,eval-conflicts-rho005-r2-086-2pz62.18d4654d2fb558e7,reason=Created count=1 msg=Created container: task
0.3473,Event,ADDED,eval-conflicts-rho005-r2-086-2pz62.18d4654d31afb9a1,reason=Started count=1 msg=Started container task
0.3475,Event,ADDED,eval-conflicts-rho005-r2-086.18d4654d143b9f92,reason=SuccessfulCreate count=1 msg=Created pod: eval-conflicts-rho005-r2-086-2pz62
0.3476,Event,ADDED,eval-conflicts-rho005-r2-086.18d46550789036d5,reason=Completed count=1 msg=Job completed
0.3478,Event,ADDED,eval-conflicts-rho005-r2-087-kdhwh.18d4654d514ae984,reason=Scheduled count=None msg=Successfully assigned compute/eval-conflicts-rho005-r2-087-kdhwh to kind-worker4
0.348,Event,ADDED,eval-conflicts-rho005-r2-087-kdhwh.18d4654d6b5b0d82,"reason=Pulled count=1 msg=Container image ""busybox:musl"" already present on machine"
0.3482,Event,ADDED,eval-conflicts-rho005-r2-087-kdhwh.18d4654d6c90d8cd,reason=Created count=1 msg=Created container: task
0.3483,Event,ADDED,eval-conflicts-rho005-r2-087-kdhwh.18d4654d73587609,reason=Started count=1 msg=Started container task
0.3492,Event,ADDED,eval-conflicts-rho005-r2-087.18d4654d503b42cb,reason=SuccessfulCreate count=1 msg=Created pod: eval-conflicts-rho005-r2-087-kdhwh
0.3494,Event,ADDED,eval-conflicts-rho005-r2-087.18d46550b9d4b98a,reason=Completed count=1 msg=Job completed
0.3496,Event,ADDED,eval-conflicts-rho005-r2-088-rsbq5.18d4654d8d6f5fca,reason=Scheduled count=None msg=Successfully assigned compute/eval-conflicts-rho005-r2-088-rsbq5 to kind-worker4
0.3498,Event,ADDED,eval-conflicts-rho005-r2-088-rsbq5.18d4654da7764046,"reason=Pulled count=1 msg=Container image ""busybox:musl"" already present on machine"
0.35,Event,ADDED,eval-conflicts-rho005-r2-088-rsbq5.18d4654da8882e48,reason=Created count=1 msg=Created container: task
0.3502,Event,ADDED,eval-conflicts-rho005-r2-088-rsbq5.18d4654dac2ba7f2,reason=Started count=1 msg=Started container task
0.3504,Event,ADDED,eval-conflicts-rho005-r2-088.18d4654d8c9591ff,reason=SuccessfulCreate count=1 msg=Created pod: eval-conflicts-rho005-r2-088-rsbq5
0.3506,Event,ADDED,eval-conflicts-rho005-r2-088.18d46550f59e7c18,reason=Completed count=1 msg=Job completed
0.3508,Event,ADDED,eval-conflicts-rho005-r2-089-qp8z8.18d4654dc9072cec,reason=Scheduled count=None msg=Successfully assigned compute/eval-conflicts-rho005-r2-089-qp8z8 to kind-worker
0.351,Event,ADDED,eval-conflicts-rho005-r2-089-qp8z8.18d4654de28ea230,"reason=Pulled count=1 msg=Container image ""busybox:musl"" already present on machine"
0.3512,Event,ADDED,eval-conflicts-rho005-r2-089-qp8z8.18d4654de3aaa227,reason=Created count=1 msg=Created container: task
0.3514,Event,ADDED,eval-conflicts-rho005-r2-089-qp8z8.18d4654de599f256,reason=Started count=1 msg=Started container task
0.3516,Event,ADDED,eval-conflicts-rho005-r2-089.18d4654dc80df6ff,reason=SuccessfulCreate count=1 msg=Created pod: eval-conflicts-rho005-r2-089-qp8z8
0.3517,Event,ADDED,eval-conflicts-rho005-r2-089.18d465512b828a12,reason=Completed count=1 msg=Job completed
0.3519,Event,ADDED,eval-conflicts-rho005-r2-090-pmdhh.18d4654e0389e243,reason=Scheduled count=None msg=Successfully assigned compute/eval-conflicts-rho005-r2-090-pmdhh to kind-worker4
0.3521,Event,ADDED,eval-conflicts-rho005-r2-090-pmdhh.18d4654e1d7f7c70,"reason=Pulled count=1 msg=Container image ""busybox:musl"" already present on machine"
0.3523,Event,ADDED,eval-conflicts-rho005-r2-090-pmdhh.18d4654e1ef0e744,reason=Created count=1 msg=Created container: task
0.3524,Event,ADDED,eval-conflicts-rho005-r2-090-pmdhh.18d4654e22b6dfec,reason=Started count=1 msg=Started container task
0.3526,Event,ADDED,eval-conflicts-rho005-r2-090.18d4654e02b590b9,reason=SuccessfulCreate count=1 msg=Created pod: eval-conflicts-rho005-r2-090-pmdhh
0.3528,Event,ADDED,eval-conflicts-rho005-r2-090.18d4655131610c99,reason=Completed count=1 msg=Job completed
0.3529,Event,ADDED,eval-conflicts-rho005-r2-091-lbdzp.18d4654e3e0a7488,"reason=FailedScheduling count=None msg=0/6 nodes are available: 6 node(s) had untolerated taint(s). no new claims to deallocate, preemption: 0/6 nodes are available: 6 Preemption is not helpful for scheduling."
0.3531,Event,ADDED,eval-conflicts-rho005-r2-091-lbdzp.18d4654ef8ebded0,reason=Scheduled count=None msg=Successfully assigned compute/eval-conflicts-rho005-r2-091-lbdzp to kind-worker2
0.3532,Event,ADDED,eval-conflicts-rho005-r2-091-lbdzp.18d4654f1e8db358,"reason=Pulled count=1 msg=Container image ""busybox:musl"" already present on machine"
0.3534,Event,ADDED,eval-conflicts-rho005-r2-091-lbdzp.18d4654f203cf7dc,reason=Created count=1 msg=Created container: task
0.3536,Event,ADDED,eval-conflicts-rho005-r2-091-lbdzp.18d4654f25378d91,reason=Started count=1 msg=Started container task
0.3537,Event,ADDED,eval-conflicts-rho005-r2-091.18d4654e3e04ed8b,reason=SuccessfulCreate count=1 msg=Created pod: eval-conflicts-rho005-r2-091-lbdzp
0.354,Event,ADDED,eval-conflicts-rho005-r2-091.18d4655242f15da1,reason=Completed count=1 msg=Job completed
0.3542,Event,ADDED,eval-conflicts-rho005-r2-092-bzpcz.18d4654e7a13207a,"reason=FailedScheduling count=None msg=0/6 nodes are available: 6 node(s) had untolerated taint(s). no new claims to deallocate, preemption: 0/6 nodes are available: 6 Preemption is not helpful for scheduling."
0.3543,Event,ADDED,eval-conflicts-rho005-r2-092-bzpcz.18d4654ef95877c9,reason=Scheduled count=None msg=Successfully assigned compute/eval-conflicts-rho005-r2-092-bzpcz to kind-worker2
0.3547,Event,ADDED,eval-conflicts-rho005-r2-092-bzpcz.18d4654f163e46fe,"reason=Pulled count=1 msg=Container image ""busybox:musl"" already present on machine"
0.3548,Event,ADDED,eval-conflicts-rho005-r2-092-bzpcz.18d4654f17747c2d,reason=Created count=1 msg=Created container: task
0.355,Event,ADDED,eval-conflicts-rho005-r2-092-bzpcz.18d4654f1bd70f5c,reason=Started count=1 msg=Started container task
0.3552,Event,ADDED,eval-conflicts-rho005-r2-092.18d4654e7a0273c1,reason=SuccessfulCreate count=1 msg=Created pod: eval-conflicts-rho005-r2-092-bzpcz
0.3556,Event,ADDED,eval-conflicts-rho005-r2-092.18d4655242b2d40b,reason=Completed count=1 msg=Job completed
0.3558,Event,ADDED,eval-conflicts-rho005-r2-093-rnqpr.18d4654eb58ac50c,"reason=FailedScheduling count=None msg=0/6 nodes are available: 6 node(s) had untolerated taint(s). no new claims to deallocate, preemption: 0/6 nodes are available: 6 Preemption is not helpful for scheduling."
0.356,Event,ADDED,eval-conflicts-rho005-r2-093-rnqpr.18d4654ef98c2035,reason=Scheduled count=None msg=Successfully assigned compute/eval-conflicts-rho005-r2-093-rnqpr to kind-worker2
0.3563,Event,ADDED,eval-conflicts-rho005-r2-093-rnqpr.18d4654f1eed88cb,"reason=Pulled count=1 msg=Container image ""busybox:musl"" already present on machine"
0.3565,Event,ADDED,eval-conflicts-rho005-r2-093-rnqpr.18d4654f20f05483,reason=Created count=1 msg=Created container: task
0.3566,Event,ADDED,eval-conflicts-rho005-r2-093-rnqpr.18d4654f25d9cc50,reason=Started count=1 msg=Started container task
0.3568,Event,ADDED,eval-conflicts-rho005-r2-093.18d4654eb57f2625,reason=SuccessfulCreate count=1 msg=Created pod: eval-conflicts-rho005-r2-093-rnqpr
0.357,Event,ADDED,eval-conflicts-rho005-r2-093.18d4655243edaa21,reason=Completed count=1 msg=Job completed
0.3572,Event,ADDED,eval-conflicts-rho005-r2-094-x4hhz.18d4654ef16d85e2,"reason=FailedScheduling count=None msg=0/6 nodes are available: 6 node(s) had untolerated taint(s). no new claims to deallocate, preemption: 0/6 nodes are available: 6 Preemption is not helpful for scheduling."
0.3573,Event,ADDED,eval-conflicts-rho005-r2-094-x4hhz.18d4654ef9e765a7,reason=Scheduled count=None msg=Successfully assigned compute/eval-conflicts-rho005-r2-094-x4hhz to kind-worker2
0.3575,Event,ADDED,eval-conflicts-rho005-r2-094-x4hhz.18d4654f1f1562c8,"reason=Pulled count=1 msg=Container image ""busybox:musl"" already present on machine"
0.3577,Event,ADDED,eval-conflicts-rho005-r2-094-x4hhz.18d4654f215409ba,reason=Created count=1 msg=Created container: task
0.3579,Event,ADDED,eval-conflicts-rho005-r2-094-x4hhz.18d4654f25d9cc64,reason=Started count=1 msg=Started container task
0.3585,Event,ADDED,eval-conflicts-rho005-r2-094.18d4654ef163c740,reason=SuccessfulCreate count=1 msg=Created pod: eval-conflicts-rho005-r2-094-x4hhz
0.3588,Event,ADDED,eval-conflicts-rho005-r2-094.18d465524350d79e,reason=Completed count=1 msg=Job completed
0.3589,Event,ADDED,eval-conflicts-rho005-r2-095-r97wg.18d4654f2d27adf8,reason=Scheduled count=None msg=Successfully assigned compute/eval-conflicts-rho005-r2-095-r97wg to kind-worker2
0.3591,Event,ADDED,eval-conflicts-rho005-r2-095-r97wg.18d4654f457118e2,"reason=Pulled count=1 msg=Container image ""busybox:musl"" already present on machine"
0.3592,Event,ADDED,eval-conflicts-rho005-r2-095-r97wg.18d4654f4684a440,reason=Created count=1 msg=Created container: task
0.3594,Event,ADDED,eval-conflicts-rho005-r2-095-r97wg.18d4654f48617dbc,reason=Started count=1 msg=Started container task
0.3597,Event,ADDED,eval-conflicts-rho005-r2-095.18d4654f2c9eb708,reason=SuccessfulCreate count=1 msg=Created pod: eval-conflicts-rho005-r2-095-r97wg
0.3599,Event,ADDED,eval-conflicts-rho005-r2-095.18d465527ee1777c,reason=Completed count=1 msg=Job completed
0.36,Event,ADDED,eval-conflicts-rho005-r2-096-tnzwd.18d4654f69b3f651,reason=Scheduled count=None msg=Successfully assigned compute/eval-conflicts-rho005-r2-096-tnzwd to kind-worker2
0.3602,Event,ADDED,eval-conflicts-rho005-r2-096-tnzwd.18d4654f832ee8c9,"reason=Pulled count=1 msg=Container image ""busybox:musl"" already present on machine"
0.3604,Event,ADDED,eval-conflicts-rho005-r2-096-tnzwd.18d4654f845fc6ef,reason=Created count=1 msg=Created container: task
0.3605,Event,ADDED,eval-conflicts-rho005-r2-096-tnzwd.18d4654f86a52305,reason=Started count=1 msg=Started container task
0.3607,Event,ADDED,eval-conflicts-rho005-r2-096.18d4654f692b73cc,reason=SuccessfulCreate count=1 msg=Created pod: eval-conflicts-rho005-r2-096-tnzwd
0.3609,Event,ADDED,eval-conflicts-rho005-r2-096.18d46552bae8ecb1,reason=Completed count=1 msg=Job completed
0.361,Event,ADDED,eval-conflicts-rho005-r2-097-vwfr6.18d4654fa3fece52,reason=Scheduled count=None msg=Successfully assigned compute/eval-conflicts-rho005-r2-097-vwfr6 to kind-worker2
0.3612,Event,ADDED,eval-conflicts-rho005-r2-097-vwfr6.18d4654fbd9c8f7e,"reason=Pulled count=1 msg=Container image ""busybox:musl"" already present on machine"
0.3614,Event,ADDED,eval-conflicts-rho005-r2-097-vwfr6.18d4654fbec85b39,reason=Created count=1 msg=Created container: task
0.3615,Event,ADDED,eval-conflicts-rho005-r2-097-vwfr6.18d4654fc36be26b,reason=Started count=1 msg=Started container task
0.3617,Event,ADDED,eval-conflicts-rho005-r2-097.18d4654fa38e1d90,reason=SuccessfulCreate count=1 msg=Created pod: eval-conflicts-rho005-r2-097-vwfr6
0.3619,Event,ADDED,eval-conflicts-rho005-r2-097.18d46552f6d0068d,reason=Completed count=1 msg=Job completed
0.3621,Event,ADDED,eval-conflicts-rho005-r2-098-xjwx9.18d4654fe11c72e1,reason=Scheduled count=None msg=Successfully assigned compute/eval-conflicts-rho005-r2-098-xjwx9 to kind-worker5
0.3623,Event,ADDED,eval-conflicts-rho005-r2-098-xjwx9.18d4654ffafdf670,"reason=Pulled count=1 msg=Container image ""busybox:musl"" already present on machine"
0.3625,Event,ADDED,eval-conflicts-rho005-r2-098-xjwx9.18d4654ffc35046e,reason=Created count=1 msg=Created container: task
0.3629,Event,ADDED,eval-conflicts-rho005-r2-098-xjwx9.18d4655000e0fe29,reason=Started count=1 msg=Started container task
0.3631,Event,ADDED,eval-conflicts-rho005-r2-098.18d4654fe003313a,reason=SuccessfulCreate count=1 msg=Created pod: eval-conflicts-rho005-r2-098-xjwx9
0.3633,Event,ADDED,eval-conflicts-rho005-r2-098.18d465531860b4dd,reason=Completed count=1 msg=Job completed
0.3636,Event,ADDED,eval-conflicts-rho005-r2-099-qqdb4.18d465501c7009b3,reason=Scheduled count=None msg=Successfully assigned compute/eval-conflicts-rho005-r2-099-qqdb4 to kind-worker5
0.3637,Event,ADDED,eval-conflicts-rho005-r2-099-qqdb4.18d46550363a15d4,"reason=Pulled count=1 msg=Container image ""busybox:musl"" already present on machine"
0.3639,Event,ADDED,eval-conflicts-rho005-r2-099-qqdb4.18d4655037710edd,reason=Created count=1 msg=Created container: task
0.3641,Event,ADDED,eval-conflicts-rho005-r2-099-qqdb4.18d465503bf21bb0,reason=Started count=1 msg=Started container task
0.3644,Event,ADDED,eval-conflicts-rho005-r2-099.18d465501b48b3c8,reason=SuccessfulCreate count=1 msg=Created pod: eval-conflicts-rho005-r2-099-qqdb4
0.3645,Event,ADDED,eval-conflicts-rho005-r2-099.18d4655354373810,reason=Completed count=1 msg=Job completed
0.3647,Event,ADDED,eval-conflicts-rho005-r3-000-gxfpd.18d4655804eb2cb1,reason=Scheduled count=None msg=Successfully assigned compute/eval-conflicts-rho005-r3-000-gxfpd to kind-worker
0.3649,Event,ADDED,eval-conflicts-rho005-r3-000-gxfpd.18d465581e9b989d,"reason=Pulled count=1 msg=Container image ""busybox:musl"" already present on machine"
0.3651,Event,ADDED,eval-conflicts-rho005-r3-000-gxfpd.18d465581fb321f6,reason=Created count=1 msg=Created container: task
0.3653,Event,ADDED,eval-conflicts-rho005-r3-000-gxfpd.18d4655821b3a157,reason=Started count=1 msg=Started container task
0.3654,Event,ADDED,eval-conflicts-rho005-r3-000.18d4655803e4530e,reason=SuccessfulCreate count=1 msg=Created pod: eval-conflicts-rho005-r3-000-gxfpd
0.3656,Event,ADDED,eval-conflicts-rho005-r3-000.18d4655b34da1ae1,reason=Completed count=1 msg=Job completed
0.3658,Event,ADDED,eval-conflicts-rho005-r3-001-flgnk.18d465583efb8b95,reason=Scheduled count=None msg=Successfully assigned compute/eval-conflicts-rho005-r3-001-flgnk to kind-worker2
0.366,Event,ADDED,eval-conflicts-rho005-r3-001-flgnk.18d4655857bebf52,"reason=Pulled count=1 msg=Container image ""busybox:musl"" already present on machine"
0.3661,Event,ADDED,eval-conflicts-rho005-r3-001-flgnk.18d4655858e94faa,reason=Created count=1 msg=Created container: task
0.3663,Event,ADDED,eval-conflicts-rho005-r3-001-flgnk.18d465585d0e8e84,reason=Started count=1 msg=Started container task
0.3665,Event,ADDED,eval-conflicts-rho005-r3-001.18d465583df33370,reason=SuccessfulCreate count=1 msg=Created pod: eval-conflicts-rho005-r3-001-flgnk
0.3666,Event,ADDED,eval-conflicts-rho005-r3-001.18d4655b99164d26,reason=Completed count=1 msg=Job completed
0.3668,Event,ADDED,eval-conflicts-rho005-r3-002-d9fzw.18d46558797ae1be,reason=Scheduled count=None msg=Successfully assigned compute/eval-conflicts-rho005-r3-002-d9fzw to kind-worker
0.3669,Event,ADDED,eval-conflicts-rho005-r3-002-d9fzw.18d4655893e1878d,"reason=Pulled count=1 msg=Container image ""busybox:musl"" already present on machine"
0.3671,Event,ADDED,eval-conflicts-rho005-r3-002-d9fzw.18d4655895016c66,reason=Created count=1 msg=Created container: task
0.3673,Event,ADDED,eval-conflicts-rho005-r3-002-d9fzw.18d465589934a0df,reason=Started count=1 msg=Started container task
0.3674,Event,ADDED,eval-conflicts-rho005-r3-002.18d4655878b60fc4,reason=SuccessfulCreate count=1 msg=Created pod: eval-conflicts-rho005-r3-002-d9fzw
0.3676,Event,ADDED,eval-conflicts-rho005-r3-002.18d4655bac91d5d4,reason=Completed count=1 msg=Job completed
0.3677,Event,ADDED,eval-conflicts-rho005-r3-003-cvftq.18d46558b52aaa18,reason=Scheduled count=None msg=Successfully assigned compute/eval-conflicts-rho005-r3-003-cvftq to kind-worker5
0.3679,Event,ADDED,eval-conflicts-rho005-r3-003-cvftq.18d46558cf1d38e1,"reason=Pulled count=1 msg=Container image ""busybox:musl"" already present on machine"
0.3681,Event,ADDED,eval-conflicts-rho005-r3-003-cvftq.18d46558d03845be,reason=Created count=1 msg=Created container: task
0.3682,Event,ADDED,eval-conflicts-rho005-r3-003-cvftq.18d46558d21ecf7f,reason=Started count=1 msg=Started container task
0.3684,Event,ADDED,eval-conflicts-rho005-r3-003.18d46558b479285e,reason=SuccessfulCreate count=1 msg=Created pod: eval-conflicts-rho005-r3-003-cvftq
0.3686,Event,ADDED,eval-conflicts-rho005-r3-003.18d4655bbb5b61d6,reason=Completed count=1 msg=Job completed
0.3687,Event,ADDED,eval-conflicts-rho005-r3-004-kctcz.18d46558f13144b0,reason=Scheduled count=None msg=Successfully assigned compute/eval-conflicts-rho005-r3-004-kctcz to kind-worker5
0.3689,Event,ADDED,eval-conflicts-rho005-r3-004-kctcz.18d465590a4c2b24,"reason=Pulled count=1 msg=Container image ""busybox:musl"" already present on machine"
0.3691,Event,ADDED,eval-conflicts-rho005-r3-004-kctcz.18d465590b665a14,reason=Created count=1 msg=Created container: task
0.3693,Event,ADDED,eval-conflicts-rho005-r3-004-kctcz.18d465590fc690a3,reason=Started count=1 msg=Started container task
0.3695,Event,ADDED,eval-conflicts-rho005-r3-004.18d46558f0296e53,reason=SuccessfulCreate count=1 msg=Created pod: eval-conflicts-rho005-r3-004-kctcz
0.3696,Event,ADDED,eval-conflicts-rho005-r3-004.18d4655bf70bf949,reason=Completed count=1 msg=Job completed
0.3698,Event,ADDED,eval-conflicts-rho005-r3-005-kzbp5.18d465592c650e60,reason=Scheduled count=None msg=Successfully assigned compute/eval-conflicts-rho005-r3-005-kzbp5 to kind-worker5
0.3732,Event,ADDED,eval-conflicts-rho005-r3-005-kzbp5.18d46559454ed08d,"reason=Pulled count=1 msg=Container image ""busybox:musl"" already present on machine"
0.3734,Event,ADDED,eval-conflicts-rho005-r3-005-kzbp5.18d46559466be948,reason=Created count=1 msg=Created container: task
0.3736,Event,ADDED,eval-conflicts-rho005-r3-005-kzbp5.18d465594a03f3e0,reason=Started count=1 msg=Started container task
0.3739,Event,ADDED,eval-conflicts-rho005-r3-005.18d465592b71f2ca,reason=SuccessfulCreate count=1 msg=Created pod: eval-conflicts-rho005-r3-005-kzbp5
0.374,Event,ADDED,eval-conflicts-rho005-r3-005.18d4655c333dfa5a,reason=Completed count=1 msg=Job completed
0.3742,Event,ADDED,eval-conflicts-rho005-r3-006-7l6nk.18d4655967e2501f,reason=Scheduled count=None msg=Successfully assigned compute/eval-conflicts-rho005-r3-006-7l6nk to kind-worker
0.3743,Event,ADDED,eval-conflicts-rho005-r3-006-7l6nk.18d4655982f333ec,"reason=Pulled count=1 msg=Container image ""busybox:musl"" already present on machine"
0.3745,Event,ADDED,eval-conflicts-rho005-r3-006-7l6nk.18d46559840238e3,reason=Created count=1 msg=Created container: task
0.3747,Event,ADDED,eval-conflicts-rho005-r3-006-7l6nk.18d46559883ab70d,reason=Started count=1 msg=Started container task
0.3748,Event,ADDED,eval-conflicts-rho005-r3-006.18d46559672029fb,reason=SuccessfulCreate count=1 msg=Created pod: eval-conflicts-rho005-r3-006-7l6nk
0.375,Event,ADDED,eval-conflicts-rho005-r3-006.18d4655c9b890cc9,reason=Completed count=1 msg=Job completed
0.3752,Event,ADDED,eval-conflicts-rho005-r3-007-7ntss.18d46559a3ff153c,reason=Scheduled count=None msg=Successfully assigned compute/eval-conflicts-rho005-r3-007-7ntss to kind-worker
0.3753,Event,ADDED,eval-conflicts-rho005-r3-007-7ntss.18d46559bdc881ab,"reason=Pulled count=1 msg=Container image ""busybox:musl"" already present on machine"
0.3755,Event,ADDED,eval-conflicts-rho005-r3-007-7ntss.18d46559bedd6d97,reason=Created count=1 msg=Created container: task
0.3757,Event,ADDED,eval-conflicts-rho005-r3-007-7ntss.18d46559c2c3cd72,reason=Started count=1 msg=Started container task
0.3758,Event,ADDED,eval-conflicts-rho005-r3-007.18d46559a33d29ed,reason=SuccessfulCreate count=1 msg=Created pod: eval-conflicts-rho005-r3-007-7ntss
0.376,Event,ADDED,eval-conflicts-rho005-r3-007.18d4655cd74eece8,reason=Completed count=1 msg=Job completed
0.3761,Event,ADDED,eval-conflicts-rho005-r3-008-77x62.18d46559df9bac45,reason=Scheduled count=None msg=Successfully assigned compute/eval-conflicts-rho005-r3-008-77x62 to kind-worker4
0.3764,Event,ADDED,eval-conflicts-rho005-r3-008-77x62.18d46559f8ce0331,"reason=Pulled count=1 msg=Container image ""busybox:musl"" already present on machine"
0.3765,Event,ADDED,eval-conflicts-rho005-r3-008-77x62.18d46559f9ede247,reason=Created count=1 msg=Created container: task
0.3767,Event,ADDED,eval-conflicts-rho005-r3-008-77x62.18d46559ff30d62d,reason=Started count=1 msg=Started container task
0.377,Event,ADDED,eval-conflicts-rho005-r3-008.18d46559deb91486,reason=SuccessfulCreate count=1 msg=Created pod: eval-conflicts-rho005-r3-008-77x62
0.3772,Event,ADDED,eval-conflicts-rho005-r3-008.18d4655d18dbbd0a,reason=Completed count=1 msg=Job completed
0.3774,Event,ADDED,eval-conflicts-rho005-r3-009-btlpk.18d4655a1a71ab5e,reason=Scheduled count=None msg=Successfully assigned compute/eval-conflicts-rho005-r3-009-btlpk to kind-worker3
0.3775,Event,ADDED,eval-conflicts-rho005-r3-009-btlpk.18d4655a3478885f,"reason=Pulled count=1 msg=Container image ""busybox:musl"" already present on machine"
0.3778,Event,ADDED,eval-conflicts-rho005-r3-009-btlpk.18d4655a358bb21e,reason=Created count=1 msg=Created container: task
0.378,Event,ADDED,eval-conflicts-rho005-r3-009-btlpk.18d4655a3791f97f,reason=Started count=1 msg=Started container task
0.3782,Event,ADDED,eval-conflicts-rho005-r3-009.18d4655a1a0da70d,reason=SuccessfulCreate count=1 msg=Created pod: eval-conflicts-rho005-r3-009-btlpk
0.3784,Event,ADDED,eval-conflicts-rho005-r3-009.18d4655d4a7d1b9d,reason=Completed count=1 msg=Job completed
0.3786,Event,ADDED,eval-conflicts-rho005-r3-010-gqbrj.18d4655a57dca045,reason=Scheduled count=None msg=Successfully assigned compute/eval-conflicts-rho005-r3-010-gqbrj to kind-worker3
0.3788,Event,ADDED,eval-conflicts-rho005-r3-010-gqbrj.18d4655a70f55354,"reason=Pulled count=1 msg=Container image ""busybox:musl"" already present on machine"
0.379,Event,ADDED,eval-conflicts-rho005-r3-010-gqbrj.18d4655a7211c7f3,reason=Created count=1 msg=Created container: task
0.3794,Event,ADDED,eval-conflicts-rho005-r3-010-gqbrj.18d4655a776dadac,reason=Started count=1 msg=Started container task
0.3796,Event,ADDED,eval-conflicts-rho005-r3-010.18d4655a569e0cce,reason=SuccessfulCreate count=1 msg=Created pod: eval-conflicts-rho005-r3-010-gqbrj
0.3797,Event,ADDED,eval-conflicts-rho005-r3-010.18d4655d868de49c,reason=Completed count=1 msg=Job completed
0.3799,Event,ADDED,eval-conflicts-rho005-r3-011-kbdvk.18d4655a91b07d07,reason=Scheduled count=None msg=Successfully assigned compute/eval-conflicts-rho005-r3-011-kbdvk to kind-worker3
0.3802,Event,ADDED,eval-conflicts-rho005-r3-011-kbdvk.18d4655aaba11900,"reason=Pulled count=1 msg=Container image ""busybox:musl"" already present on machine"
0.3807,Event,ADDED,eval-conflicts-rho005-r3-011-kbdvk.18d4655aacc25aaf,reason=Created count=1 msg=Created container: task
0.3808,Event,ADDED,eval-conflicts-rho005-r3-011-kbdvk.18d4655aaef33e88,reason=Started count=1 msg=Started container task
0.381,Event,ADDED,eval-conflicts-rho005-r3-011.18d4655a912abac2,reason=SuccessfulCreate count=1 msg=Created pod: eval-conflicts-rho005-r3-011-kbdvk
0.3812,Event,ADDED,eval-conflicts-rho005-r3-011.18d4655dc2242d3b,reason=Completed count=1 msg=Job completed
0.3814,Event,ADDED,eval-conflicts-rho005-r3-012-fzpjz.18d4655ace6c8f15,reason=Scheduled count=None msg=Successfully assigned compute/eval-conflicts-rho005-r3-012-fzpjz to kind-worker3
0.3816,Event,ADDED,eval-conflicts-rho005-r3-012-fzpjz.18d4655ae856af54,"reason=Pulled count=1 msg=Container image ""busybox:musl"" already present on machine"
0.382,Event,ADDED,eval-conflicts-rho005-r3-012-fzpjz.18d4655ae96dbf79,reason=Created count=1 msg=Created container: task
0.3822,Event,ADDED,eval-conflicts-rho005-r3-012-fzpjz.18d4655aec40f6e7,reason=Started count=1 msg=Started container task
0.3823,Event,ADDED,eval-conflicts-rho005-r3-012.18d4655acdaf3faa,reason=SuccessfulCreate count=1 msg=Created pod: eval-conflicts-rho005-r3-012-fzpjz
0.3825,Event,ADDED,eval-conflicts-rho005-r3-012.18d4655dfe750b16,reason=Completed count=1 msg=Job completed
0.3828,Event,ADDED,eval-conflicts-rho005-r3-013-kn6qk.18d4655b09d1e552,reason=Scheduled count=None msg=Successfully assigned compute/eval-conflicts-rho005-r3-013-kn6qk to kind-worker3
0.383,Event,ADDED,eval-conflicts-rho005-r3-013-kn6qk.18d4655b22a3b7e8,"reason=Pulled count=1 msg=Container image ""busybox:musl"" already present on machine"
0.3832,Event,ADDED,eval-conflicts-rho005-r3-013-kn6qk.18d4655b23b6b194,reason=Created count=1 msg=Created container: task
0.3834,Event,ADDED,eval-conflicts-rho005-r3-013-kn6qk.18d4655b25e9ada3,reason=Started count=1 msg=Started container task
0.3836,Event,ADDED,eval-conflicts-rho005-r3-013.18d4655b093fe6e3,reason=SuccessfulCreate count=1 msg=Created pod: eval-conflicts-rho005-r3-013-kn6qk
0.3837,Event,ADDED,eval-conflicts-rho005-r3-013.18d4655e3a6d2d54,reason=Completed count=1 msg=Job completed
0.3839,Event,ADDED,eval-conflicts-rho005-r3-014-cxhzx.18d4655b44841bf8,reason=Scheduled count=None msg=Successfully assigned compute/eval-conflicts-rho005-r3-014-cxhzx to kind-worker3
0.3842,Event,ADDED,eval-conflicts-rho005-r3-014-cxhzx.18d4655b5e0269f6,"reason=Pulled count=1 msg=Container image ""busybox:musl"" already present on machine"
0.3843,Event,ADDED,eval-conflicts-rho005-r3-014-cxhzx.18d4655b5f220a83,reason=Created count=1 msg=Created container: task
0.3845,Event,ADDED,eval-conflicts-rho005-r3-014-cxhzx.18d4655b612a09bb,reason=Started count=1 msg=Started container task
0.3847,Event,ADDED,eval-conflicts-rho005-r3-014.18d4655b440a9fdc,reason=SuccessfulCreate count=1 msg=Created pod: eval-conflicts-rho005-r3-014-cxhzx
0.3849,Event,ADDED,eval-conflicts-rho005-r3-014.18d4655e75d7a696,reason=Completed count=1 msg=Job completed
0.385,Event,ADDED,eval-conflicts-rho005-r3-015-qx92j.18d4655b80cb2c9f,reason=Scheduled count=None msg=Successfully assigned compute/eval-conflicts-rho005-r3-015-qx92j to kind-worker3
0.3852,Event,ADDED,eval-conflicts-rho005-r3-015-qx92j.18d4655b99d34876,"reason=Pulled count=1 msg=Container image ""busybox:musl"" already present on machine"
0.3858,Event,ADDED,eval-conflicts-rho005-r3-015-qx92j.18d4655b9af7a0d4,reason=Created count=1 msg=Created container: task
0.3862,Event,ADDED,eval-conflicts-rho005-r3-015-qx92j.18d4655b9d131820,reason=Started count=1 msg=Started container task
0.3864,Event,ADDED,eval-conflicts-rho005-r3-015.18d4655b8033b550,reason=SuccessfulCreate count=1 msg=Created pod: eval-conflicts-rho005-r3-015-qx92j
0.3865,Event,ADDED,eval-conflicts-rho005-r3-015.18d4655eb1a8488a,reason=Completed count=1 msg=Job completed
0.3868,Event,ADDED,eval-conflicts-rho005-r3-016-9nptm.18d4655bbba0c0e7,"reason=FailedScheduling count=None msg=0/6 nodes are available: 6 node(s) had untolerated taint(s). no new claims to deallocate, preemption: 0/6 nodes are available: 6 Preemption is not helpful for scheduling."
0.3869,Event,ADDED,eval-conflicts-rho005-r3-016-9nptm.18d4655d3227a12a,reason=Scheduled count=None msg=Successfully assigned compute/eval-conflicts-rho005-r3-016-9nptm to kind-worker2
0.3871,Event,ADDED,eval-conflicts-rho005-r3-016-9nptm.18d4655d50f29b40,"reason=Pulled count=1 msg=Container image ""busybox:musl"" already present on machine"
0.3873,Event,ADDED,eval-conflicts-rho005-r3-016-9nptm.18d4655d54325421,reason=Created count=1 msg=Created container: task
0.3875,Event,ADDED,eval-conflicts-rho005-r3-016-9nptm.18d4655d5aadeb9a,reason=Started count=1 msg=Started container task
0.3877,Event,ADDED,eval-conflicts-rho005-r3-016.18d4655bbb952d0d,reason=SuccessfulCreate count=1 msg=Created pod: eval-conflicts-rho005-r3-016-9nptm
0.3879,Event,ADDED,eval-conflicts-rho005-r3-016.18d4656081fd4c3a,reason=Completed count=1 msg=Job completed
0.3881,Event,ADDED,eval-conflicts-rho005-r3-017-w7brq.18d4655bf7346b7c,"reason=FailedScheduling count=None msg=0/6 nodes are available: 6 node(s) had untolerated taint(s). no new claims to deallocate, preemption: 0/6 nodes are available: 6 Preemption is not helpful for scheduling."
0.3883,Event,ADDED,eval-conflicts-rho005-r3-017-w7brq.18d4655d32dccfc3,reason=Scheduled count=None msg=Successfully assigned compute/eval-conflicts-rho005-r3-017-w7brq to kind-worker2
0.3885,Event,ADDED,eval-conflicts-rho005-r3-017-w7brq.18d4655d511432af,"reason=Pulled count=1 msg=Container image ""busybox:musl"" already present on machine"
0.3886,Event,ADDED,eval-conflicts-rho005-r3-017-w7brq.18d4655d540f6d69,reason=Created count=1 msg=Created container: task
0.3889,Event,ADDED,eval-conflicts-rho005-r3-017-w7brq.18d4655d5aada1e4,reason=Started count=1 msg=Started container task
0.3891,Event,ADDED,eval-conflicts-rho005-r3-017.18d4655bf72c037b,reason=SuccessfulCreate count=1 msg=Created pod: eval-conflicts-rho005-r3-017-w7brq
0.3893,Event,ADDED,eval-conflicts-rho005-r3-017.18d46560815a20dc,reason=Completed count=1 msg=Job completed
0.3895,Event,ADDED,eval-conflicts-rho005-r3-018-cjknf.18d4655c3295dc20,"reason=FailedScheduling count=None msg=0/6 nodes are available: 6 node(s) had untolerated taint(s). no new claims to deallocate, preemption: 0/6 nodes are available: 6 Preemption is not helpful for scheduling."
0.3896,Event,ADDED,eval-conflicts-rho005-r3-018-cjknf.18d4655d32dd1ee7,reason=Scheduled count=None msg=Successfully assigned compute/eval-conflicts-rho005-r3-018-cjknf to kind-worker2
0.3898,Event,ADDED,eval-conflicts-rho005-r3-018-cjknf.18d4655d513589ff,"reason=Pulled count=1 msg=Container image ""busybox:musl"" already present on machine"
0.39,Event,ADDED,eval-conflicts-rho005-r3-018-cjknf.18d4655d5488ab20,reason=Created count=1 msg=Created container: task
0.3902,Event,ADDED,eval-conflicts-rho005-r3-018-cjknf.18d4655d5aade960,reason=Started count=1 msg=Started container task
0.3904,Event,ADDED,eval-conflicts-rho005-r3-018.18d4655c3288085a,reason=SuccessfulCreate count=1 msg=Created pod: eval-conflicts-rho005-r3-018-cjknf
0.3905,Event,ADDED,eval-conflicts-rho005-r3-018.18d46560473162d6,reason=Completed count=1 msg=Job completed
0.3907,Event,ADDED,eval-conflicts-rho005-r3-019-9r97w.18d4655c6ed50d6f,"reason=FailedScheduling count=None msg=0/6 nodes are available: 6 node(s) had untolerated taint(s). no new claims to deallocate, preemption: 0/6 nodes are available: 6 Preemption is not helpful for scheduling."
0.3908,Event,ADDED,eval-conflicts-rho005-r3-019-9r97w.18d4655d36be453a,reason=Scheduled count=None msg=Successfully assigned compute/eval-conflicts-rho005-r3-019-9r97w to kind-worker2
0.391,Event,ADDED,eval-conflicts-rho005-r3-019-9r97w.18d4655d4e057616,"reason=Pulled count=1 msg=Container image ""busybox:musl"" already present on machine"
0.3912,Event,ADDED,eval-conflicts-rho005-r3-019-9r97w.18d4655d4f624c1c,reason=Created count=1 msg=Created container: task
0.3914,Event,ADDED,eval-conflicts-rho005-r3-019-9r97w.18d4655d53070ab4,reason=Started count=1 msg=Started container task
0.3915,Event,ADDED,eval-conflicts-rho005-r3-019.18d4655c6eccaacf,reason=SuccessfulCreate count=1 msg=Created pod: eval-conflicts-rho005-r3-019-9r97w
0.3917,Event,ADDED,eval-conflicts-rho005-r3-019.18d4656082e4ee7b,reason=Completed count=1 msg=Job completed
0.3918,Event,ADDED,eval-conflicts-rho005-r3-020-zvgdg.18d4655ca9ce4819,"reason=FailedScheduling count=None msg=0/6 nodes are available: 6 node(s) had untolerated taint(s). no new claims to deallocate, preemption: 0/6 nodes are available: 6 Preemption is not helpful for scheduling."
0.392,Event,ADDED,eval-conflicts-rho005-r3-020-zvgdg.18d4655d33610fcd,reason=Scheduled count=None msg=Successfully assigned compute/eval-conflicts-rho005-r3-020-zvgdg to kind-worker2
0.3922,Event,ADDED,eval-conflicts-rho005-r3-020-zvgdg.18d4655d4e1ebba1,"reason=Pulled count=1 msg=Container image ""busybox:musl"" already present on machine"
0.3923,Event,ADDED,eval-conflicts-rho005-r3-020-zvgdg.18d4655d4fb6a7d5,reason=Created count=1 msg=Created container: task
0.3925,Event,ADDED,eval-conflicts-rho005-r3-020-zvgdg.18d4655d5303a63f,reason=Started count=1 msg=Started container task
0.3927,Event,ADDED,eval-conflicts-rho005-r3-020.18d4655ca9c0fe59,reason=SuccessfulCreate count=1 msg=Created pod: eval-conflicts-rho005-r3-020-zvgdg
0.3931,Event,ADDED,eval-conflicts-rho005-r3-020.18d46560815a0f16,reason=Completed count=1 msg=Job completed
0.3933,Event,ADDED,eval-conflicts-rho005-r3-021-zjnpj.18d4655ce5390a4e,"reason=FailedScheduling count=None msg=0/6 nodes are available: 6 node(s) had untolerated taint(s). no new claims to deallocate, preemption: 0/6 nodes are available: 6 Preemption is not helpful for scheduling."
0.3937,Event,ADDED,eval-conflicts-rho005-r3-021-zjnpj.18d4655d331beac3,"reason=FailedScheduling count=None msg=0/6 nodes are available: 1 c_wall violated: 2 conflicting context pair(s) with node memory, 5 node(s) had untolerated taint(s). no new claims to deallocate, preemption: 0/6 nodes are available: 1 No preemption victims found for incoming pod, 5 Preemption is not helpful for scheduling."
0.394,Event,ADDED,eval-conflicts-rho005-r3-021-zjnpj.18d4655d373b5512,"reason=FailedScheduling count=None msg=0/6 nodes are available: 1 c_wall violated: 2 conflicting context pair(s) with node memory, 5 node(s) had untolerated taint(s). no new claims to deallocate, preemption: 0/6 nodes are available: 1 No preemption victims found for incoming pod, 5 Preemption is not helpful for scheduling."
0.3942,Event,ADDED,eval-conflicts-rho005-r3-021-zjnpj.18d4655dfcee6f36,reason=Scheduled count=None msg=Successfully assigned compute/eval-conflicts-rho005-r3-021-zjnpj to kind-worker5
0.3944,Event,ADDED,eval-conflicts-rho005-r3-021-zjnpj.18d4655e17d23bb9,"reason=Pulled count=1 msg=Container image ""busybox:musl"" already present on machine"
0.3947,Event,ADDED,eval-conflicts-rho005-r3-021-zjnpj.18d4655e1929b093,reason=Created count=1 msg=Created container: task
0.3949,Event,ADDED,eval-conflicts-rho005-r3-021-zjnpj.18d4655e1d823a6b,reason=Started count=1 msg=Started container task
0.3953,Event,ADDED,eval-conflicts-rho005-r3-021.18d4655ce530ab4c,reason=SuccessfulCreate count=1 msg=Created pod: eval-conflicts-rho005-r3-021-zjnpj
0.3955,Event,ADDED,eval-conflicts-rho005-r3-021.18d465611b706e1a,reason=Completed count=1 msg=Job completed
0.3957,Event,ADDED,eval-conflicts-rho005-r3-022-2vdlc.18d4655d2146d8a1,"reason=FailedScheduling count=None msg=0/6 nodes are available: 6 node(s) had untolerated taint(s). no new claims to deallocate, preemption: 0/6 nodes are available: 6 Preemption is not helpful for scheduling."
0.3959,Event,ADDED,eval-conflicts-rho005-r3-022-2vdlc.18d4655d3cb590b6,reason=Scheduled count=None msg=Successfully assigned compute/eval-conflicts-rho005-r3-022-2vdlc to kind-worker2
0.3962,Event,ADDED,eval-conflicts-rho005-r3-022-2vdlc.18d4655d530a41ce,"reason=Pulled count=1 msg=Container image ""busybox:musl"" already present on machine"
0.3964,Event,ADDED,eval-conflicts-rho005-r3-022-2vdlc.18d4655d551aa622,reason=Created count=1 msg=Created container: task
0.3966,Event,ADDED,eval-conflicts-rho005-r3-022-2vdlc.18d4655d5aadcd90,reason=Started count=1 msg=Started container task
0.3968,Event,ADDED,eval-conflicts-rho005-r3-022.18d4655d213d57bd,reason=SuccessfulCreate count=1 msg=Created pod: eval-conflicts-rho005-r3-022-2vdlc
0.3969,Event,ADDED,eval-conflicts-rho005-r3-022.18d4656082785ed9,reason=Completed count=1 msg=Job completed
0.3971,Event,ADDED,eval-conflicts-rho005-r3-023-vpzh4.18d4655d5ccbf5df,reason=Scheduled count=None msg=Successfully assigned compute/eval-conflicts-rho005-r3-023-vpzh4 to kind-worker2
0.3973,Event,ADDED,eval-conflicts-rho005-r3-023-vpzh4.18d4655d7746f532,"reason=Pulled count=1 msg=Container image ""busybox:musl"" already present on machine"
0.3974,Event,ADDED,eval-conflicts-rho005-r3-023-vpzh4.18d4655d78f81f49,reason=Created count=1 msg=Created container: task
0.3976,Event,ADDED,eval-conflicts-rho005-r3-023-vpzh4.18d4655d7e29fba4,reason=Started count=1 msg=Started container task
0.3978,Event,ADDED,eval-conflicts-rho005-r3-023.18d4655d5c3d2fd4,reason=SuccessfulCreate count=1 msg=Created pod: eval-conflicts-rho005-r3-023-vpzh4
0.3979,Event,ADDED,eval-conflicts-rho005-r3-023.18d46560be65b49a,reason=Completed count=1 msg=Job completed
0.3981,Event,ADDED,eval-conflicts-rho005-r3-024-mlh47.18d4655d98d625c9,reason=Scheduled count=None msg=Successfully assigned compute/eval-conflicts-rho005-r3-024-mlh47 to kind-worker2
0.3983,Event,ADDED,eval-conflicts-rho005-r3-024-mlh47.18d4655db252fe3c,"reason=Pulled count=1 msg=Container image ""busybox:musl"" already present on machine"
0.3984,Event,ADDED,eval-conflicts-rho005-r3-024-mlh47.18d4655db3ce931a,reason=Created count=1 msg=Created container: task
0.3986,Event,ADDED,eval-conflicts-rho005-r3-024-mlh47.18d4655dbdd54886,reason=Started count=1 msg=Started container task
0.3988,Event,ADDED,eval-conflicts-rho005-r3-024.18d4655d9849cab1,reason=SuccessfulCreate count=1 msg=Created pod: eval-conflicts-rho005-r3-024-mlh47
0.3989,Event,ADDED,eval-conflicts-rho005-r3-024.18d46560face5ad3,reason=Completed count=1 msg=Job completed
0.3991,Event,ADDED,eval-conflicts-rho005-r3-025-gfltv.18d4655dd4f3e061,"reason=FailedScheduling count=None msg=0/6 nodes are available: 1 c_wall violated: 1 conflicting context pair(s) with node memory, 5 node(s) had untolerated taint(s). no new claims to deallocate, preemption: 0/6 nodes are available: 1 No preemption victims found for incoming pod, 5 Preemption is not helpful for scheduling."
0.3993,Event,ADDED,eval-conflicts-rho005-r3-025-gfltv.18d4655dd57e298f,"reason=FailedScheduling count=None msg=0/6 nodes are available: 1 c_wall violated: 1 conflicting context pair(s) with node memory, 5 node(s) had untolerated taint(s). no new claims to deallocate, preemption: 0/6 nodes are available: 1 No preemption victims found for incoming pod, 5 Preemption is not helpful for scheduling."
0.3994,Event,ADDED,eval-conflicts-rho005-r3-025-gfltv.18d4655dfe3a39d0,reason=Scheduled count=None msg=Successfully assigned compute/eval-conflicts-rho005-r3-025-gfltv to kind-worker5
0.3996,Event,ADDED,eval-conflicts-rho005-r3-025-gfltv.18d4655e18a8b430,"reason=Pulled count=1 msg=Container image ""busybox:musl"" already present on machine"
0.4,Event,ADDED,eval-conflicts-rho005-r3-025-gfltv.18d4655e19f8309c,reason=Created count=1 msg=Created container: task
0.4002,Event,ADDED,eval-conflicts-rho005-r3-025-gfltv.18d4655e1dbad35a,reason=Started count=1 msg=Started container task
0.4004,Event,ADDED,eval-conflicts-rho005-r3-025.18d4655dd4b30d7c,reason=SuccessfulCreate count=1 msg=Created pod: eval-conflicts-rho005-r3-025-gfltv
0.4006,Event,ADDED,eval-conflicts-rho005-r3-025.18d465611b95f733,reason=Completed count=1 msg=Job completed
0.401,Event,ADDED,eval-conflicts-rho005-r3-026-ddvb2.18d4655e10b67acc,reason=Scheduled count=None msg=Successfully assigned compute/eval-conflicts-rho005-r3-026-ddvb2 to kind-worker5
0.4012,Event,ADDED,eval-conflicts-rho005-r3-026-ddvb2.18d4655e2be19e03,"reason=Pulled count=1 msg=Container image ""busybox:musl"" already present on machine"
0.4014,Event,ADDED,eval-conflicts-rho005-r3-026-ddvb2.18d4655e2d2a26d5,reason=Created count=1 msg=Created container: task
0.4017,Event,ADDED,eval-conflicts-rho005-r3-026-ddvb2.18d4655e330f204e,reason=Started count=1 msg=Started container task
0.4019,Event,ADDED,eval-conflicts-rho005-r3-026.18d4655e0f3b6b49,reason=SuccessfulCreate count=1 msg=Created pod: eval-conflicts-rho005-r3-026-ddvb2
0.4021,Event,ADDED,eval-conflicts-rho005-r3-026.18d465615784f04d,reason=Completed count=1 msg=Job completed
0.4022,Event,ADDED,eval-conflicts-rho005-r3-027-sgg9q.18d4655e4c929cf9,reason=Scheduled count=None msg=Successfully assigned compute/eval-conflicts-rho005-r3-027-sgg9q to kind-worker5
0.4026,Event,ADDED,eval-conflicts-rho005-r3-027-sgg9q.18d4655e657f0939,"reason=Pulled count=1 msg=Container image ""busybox:musl"" already present on machine"
0.4028,Event,ADDED,eval-conflicts-rho005-r3-027-sgg9q.18d4655e66f994bd,reason=Created count=1 msg=Created container: task
0.403,Event,ADDED,eval-conflicts-rho005-r3-027-sgg9q.18d4655e6b0187f9,reason=Started count=1 msg=Started container task
0.4032,Event,ADDED,eval-conflicts-rho005-r3-027.18d4655e4bc6afdb,reason=SuccessfulCreate count=1 msg=Created pod: eval-conflicts-rho005-r3-027-sgg9q
0.4035,Event,ADDED,eval-conflicts-rho005-r3-027.18d46561931467d6,reason=Completed count=1 msg=Job completed
0.4037,Event,ADDED,eval-conflicts-rho005-r3-028-cltp9.18d4655e8811bf88,reason=Scheduled count=None msg=Successfully assigned compute/eval-conflicts-rho005-r3-028-cltp9 to kind-worker5
0.4039,Event,ADDED,eval-conflicts-rho005-r3-028-cltp9.18d4655ea26db2fb,"reason=Pulled count=1 msg=Container image ""busybox:musl"" already present on machine"
0.4042,Event,ADDED,eval-conflicts-rho005-r3-028-cltp9.18d4655ea37a82cf,reason=Created count=1 msg=Created container: task
0.4044,Event,ADDED,eval-conflicts-rho005-r3-028-cltp9.18d4655ea599d7e8,reason=Started count=1 msg=Started container task
0.4046,Event,ADDED,eval-conflicts-rho005-r3-028.18d4655e86c40d21,reason=SuccessfulCreate count=1 msg=Created pod: eval-conflicts-rho005-r3-028-cltp9
0.4048,Event,ADDED,eval-conflicts-rho005-r3-028.18d46561cf8e9259,reason=Completed count=1 msg=Job completed
0.4051,Event,ADDED,eval-conflicts-rho005-r3-029-jgmdq.18d4655ec2c65d6e,reason=Scheduled count=None msg=Successfully assigned compute/eval-conflicts-rho005-r3-029-jgmdq to kind-worker
0.4053,Event,ADDED,eval-conflicts-rho005-r3-029-jgmdq.18d4655edd2deeb0,"reason=Pulled count=1 msg=Container image ""busybox:musl"" already present on machine"
0.4055,Event,ADDED,eval-conflicts-rho005-r3-029-jgmdq.18d4655ede3e814f,reason=Created count=1 msg=Created container: task
0.4057,Event,ADDED,eval-conflicts-rho005-r3-029-jgmdq.18d4655ee02ed29d,reason=Started count=1 msg=Started container task
0.4059,Event,ADDED,eval-conflicts-rho005-r3-029.18d4655ec1e224bd,reason=SuccessfulCreate count=1 msg=Created pod: eval-conflicts-rho005-r3-029-jgmdq
0.4061,Event,ADDED,eval-conflicts-rho005-r3-029.18d46561fbf57a68,reason=Completed count=1 msg=Job completed
0.4062,Event,ADDED,eval-conflicts-rho005-r3-030-nvxnt.18d4655efee3de66,reason=Scheduled count=None msg=Successfully assigned compute/eval-conflicts-rho005-r3-030-nvxnt to kind-worker
0.4064,Event,ADDED,eval-conflicts-rho005-r3-030-nvxnt.18d4655f17f85df6,"reason=Pulled count=1 msg=Container image ""busybox:musl"" already present on machine"
0.4066,Event,ADDED,eval-conflicts-rho005-r3-030-nvxnt.18d4655f190a8453,reason=Created count=1 msg=Created container: task
0.4069,Event,ADDED,eval-conflicts-rho005-r3-030-nvxnt.18d4655f1aee2dc6,reason=Started count=1 msg=Started container task
0.407,Event,ADDED,eval-conflicts-rho005-r3-030.18d4655efda124eb,reason=SuccessfulCreate count=1 msg=Created pod: eval-conflicts-rho005-r3-030-nvxnt
0.4074,Event,ADDED,eval-conflicts-rho005-r3-030.18d4656237c1a8fe,reason=Completed count=1 msg=Job completed
0.4076,Event,ADDED,eval-conflicts-rho005-r3-031-xh6tn.18d4655f3b54c515,reason=Scheduled count=None msg=Successfully assigned compute/eval-conflicts-rho005-r3-031-xh6tn to kind-worker4
0.4078,Event,ADDED,eval-conflicts-rho005-r3-031-xh6tn.18d4655f558194b0,"reason=Pulled count=1 msg=Container image ""busybox:musl"" already present on machine"
0.4079,Event,ADDED,eval-conflicts-rho005-r3-031-xh6tn.18d4655f56aec022,reason=Created count=1 msg=Created container: task
0.4085,Event,ADDED,eval-conflicts-rho005-r3-031-xh6tn.18d4655f58ee341e,reason=Started count=1 msg=Started container task
0.4088,Event,ADDED,eval-conflicts-rho005-r3-031.18d4655f3a096936,reason=SuccessfulCreate count=1 msg=Created pod: eval-conflicts-rho005-r3-031-xh6tn
0.4089,Event,ADDED,eval-conflicts-rho005-r3-031.18d465623971e4ec,reason=Completed count=1 msg=Job completed
0.4092,Event,ADDED,eval-conflicts-rho005-r3-032-l6dsn.18d4655f777db044,reason=Scheduled count=None msg=Successfully assigned compute/eval-conflicts-rho005-r3-032-l6dsn to kind-worker
0.4094,Event,ADDED,eval-conflicts-rho005-r3-032-l6dsn.18d4655f911ee6a4,"reason=Pulled count=1 msg=Container image ""busybox:musl"" already present on machine"
0.4096,Event,ADDED,eval-conflicts-rho005-r3-032-l6dsn.18d4655f92278f37,reason=Created count=1 msg=Created container: task
0.4098,Event,ADDED,eval-conflicts-rho005-r3-032-l6dsn.18d4655f940643a7,reason=Started count=1 msg=Started container task
0.4101,Event,ADDED,eval-conflicts-rho005-r3-032.18d4655f75d3c1f8,reason=SuccessfulCreate count=1 msg=Created pod: eval-conflicts-rho005-r3-032-l6dsn
0.4103,Event,ADDED,eval-conflicts-rho005-r3-032.18d46562ae8aa250,reason=Completed count=1 msg=Job completed
0.4105,Event,ADDED,eval-conflicts-rho005-r3-033-gqpkq.18d4655fb2096c62,reason=Scheduled count=None msg=Successfully assigned compute/eval-conflicts-rho005-r3-033-gqpkq to kind-worker4
0.4111,Event,ADDED,eval-conflicts-rho005-r3-033-gqpkq.18d4655fcb47a181,"reason=Pulled count=1 msg=Container image ""busybox:musl"" already present on machine"
0.4113,Event,ADDED,eval-conflicts-rho005-r3-033-gqpkq.18d4655fcc5adf0a,reason=Created count=1 msg=Created container: task
0.4115,Event,ADDED,eval-conflicts-rho005-r3-033-gqpkq.18d4655fd06e5669,reason=Started count=1 msg=Started container task
0.4116,Event,ADDED,eval-conflicts-rho005-r3-033.18d4655fb0c4cd05,reason=SuccessfulCreate count=1 msg=Created pod: eval-conflicts-rho005-r3-033-gqpkq
0.4118,Event,ADDED,eval-conflicts-rho005-r3-033.18d46562ecccc78e,reason=Completed count=1 msg=Job completed
0.412,Event,ADDED,eval-conflicts-rho005-r3-034-w2cqv.18d4655fed7b4646,reason=Scheduled count=None msg=Successfully assigned compute/eval-conflicts-rho005-r3-034-w2cqv to kind-worker
0.4122,Event,ADDED,eval-conflicts-rho005-r3-034-w2cqv.18d4656006c5ead0,"reason=Pulled count=1 msg=Container image ""busybox:musl"" already present on machine"
0.4123,Event,ADDED,eval-conflicts-rho005-r3-034-w2cqv.18d4656007f29b4c,reason=Created count=1 msg=Created container: task
0.4125,Event,ADDED,eval-conflicts-rho005-r3-034-w2cqv.18d465600d1f028a,reason=Started count=1 msg=Started container task
0.4129,Event,ADDED,eval-conflicts-rho005-r3-034.18d4655fec52d80e,reason=SuccessfulCreate count=1 msg=Created pod: eval-conflicts-rho005-r3-034-w2cqv
0.4131,Event,ADDED,eval-conflicts-rho005-r3-034.18d4656326503198,reason=Completed count=1 msg=Job completed
0.4132,Event,ADDED,eval-conflicts-rho005-r3-035-gb9w2.18d4656028e307c0,reason=Scheduled count=None msg=Successfully assigned compute/eval-conflicts-rho005-r3-035-gb9w2 to kind-worker4
0.4134,Event,ADDED,eval-conflicts-rho005-r3-035-gb9w2.18d4656041c51e7e,"reason=Pulled count=1 msg=Container image ""busybox:musl"" already present on machine"
0.4136,Event,ADDED,eval-conflicts-rho005-r3-035-gb9w2.18d4656042d582c4,reason=Created count=1 msg=Created container: task
0.4139,Event,ADDED,eval-conflicts-rho005-r3-035-gb9w2.18d4656044ea0d4d,reason=Started count=1 msg=Started container task
0.4141,Event,ADDED,eval-conflicts-rho005-r3-035.18d4656027ae1a66,reason=SuccessfulCreate count=1 msg=Created pod: eval-conflicts-rho005-r3-035-gb9w2
0.4142,Event,ADDED,eval-conflicts-rho005-r3-035.18d465636461bd2d,reason=Completed count=1 msg=Job completed
0.4145,Event,ADDED,eval-conflicts-rho005-r3-036-rp686.18d4656064dc28f6,reason=Scheduled count=None msg=Successfully assigned compute/eval-conflicts-rho005-r3-036-rp686 to kind-worker
0.4147,Event,ADDED,eval-conflicts-rho005-r3-036-rp686.18d465607dd4f54f,"reason=Pulled count=1 msg=Container image ""busybox:musl"" already present on machine"
0.4148,Event,ADDED,eval-conflicts-rho005-r3-036-rp686.18d465607f016285,reason=Created count=1 msg=Created container: task
0.4152,Event,ADDED,eval-conflicts-rho005-r3-036-rp686.18d4656083c5249d,reason=Started count=1 msg=Started container task
0.4154,Event,ADDED,eval-conflicts-rho005-r3-036.18d4656063e3a7ee,reason=SuccessfulCreate count=1 msg=Created pod: eval-conflicts-rho005-r3-036-rp686
0.4156,Event,ADDED,eval-conflicts-rho005-r3-036.18d465639de905d4,reason=Completed count=1 msg=Job completed
0.4157,Event,ADDED,eval-conflicts-rho005-r3-037-rfw6r.18d465609fb0dfbc,reason=Scheduled count=None msg=Successfully assigned compute/eval-conflicts-rho005-r3-037-rfw6r to kind-worker
0.4161,Event,ADDED,eval-conflicts-rho005-r3-037-rfw6r.18d46560b9302928,"reason=Pulled count=1 msg=Container image ""busybox:musl"" already present on machine"
0.4163,Event,ADDED,eval-conflicts-rho005-r3-037-rfw6r.18d46560ba99b497,reason=Created count=1 msg=Created container: task
0.4165,Event,ADDED,eval-conflicts-rho005-r3-037-rfw6r.18d46560be439668,reason=Started count=1 msg=Started container task
0.4167,Event,ADDED,eval-conflicts-rho005-r3-037.18d465609eca4b98,reason=SuccessfulCreate count=1 msg=Created pod: eval-conflicts-rho005-r3-037-rfw6r
0.4169,Event,ADDED,eval-conflicts-rho005-r3-037.18d46563d9baec76,reason=Completed count=1 msg=Job completed
0.4171,Event,ADDED,eval-conflicts-rho005-r3-038-fpb4p.18d46560db552d48,reason=Scheduled count=None msg=Successfully assigned compute/eval-conflicts-rho005-r3-038-fpb4p to kind-worker3
0.4173,Event,ADDED,eval-conflicts-rho005-r3-038-fpb4p.18d46560f62a1590,"reason=Pulled count=1 msg=Container image ""busybox:musl"" already present on machine"
0.4176,Event,ADDED,eval-conflicts-rho005-r3-038-fpb4p.18d46560f74cc3b2,reason=Created count=1 msg=Created container: task
0.4178,Event,ADDED,eval-conflicts-rho005-r3-038-fpb4p.18d46560f9309099,reason=Started count=1 msg=Started container task
0.4182,Event,ADDED,eval-conflicts-rho005-r3-038.18d46560da68489e,reason=SuccessfulCreate count=1 msg=Created pod: eval-conflicts-rho005-r3-038-fpb4p
0.4184,Event,ADDED,eval-conflicts-rho005-r3-038.18d46564108a664b,reason=Completed count=1 msg=Job completed
0.4187,Event,ADDED,eval-conflicts-rho005-r3-039-xmc9m.18d4656118458e62,reason=Scheduled count=None msg=Successfully assigned compute/eval-conflicts-rho005-r3-039-xmc9m to kind-worker4
0.4188,Event,ADDED,eval-conflicts-rho005-r3-039-xmc9m.18d465613168aa3c,"reason=Pulled count=1 msg=Container image ""busybox:musl"" already present on machine"
0.419,Event,ADDED,eval-conflicts-rho005-r3-039-xmc9m.18d465613295c34c,reason=Created count=1 msg=Created container: task
0.4194,Event,ADDED,eval-conflicts-rho005-r3-039-xmc9m.18d465613c04b2bc,reason=Started count=1 msg=Started container task
0.4196,Event,ADDED,eval-conflicts-rho005-r3-039.18d46561175a2b91,reason=SuccessfulCreate count=1 msg=Created pod: eval-conflicts-rho005-r3-039-xmc9m
0.4198,Event,ADDED,eval-conflicts-rho005-r3-039.18d4656454822522,reason=Completed count=1 msg=Job completed
0.4199,Event,ADDED,eval-conflicts-rho005-r3-040-xm7pz.18d4656152438952,reason=Scheduled count=None msg=Successfully assigned compute/eval-conflicts-rho005-r3-040-xm7pz to kind-worker3
0.4203,Event,ADDED,eval-conflicts-rho005-r3-040-xm7pz.18d465616bfcec6a,"reason=Pulled count=1 msg=Container image ""busybox:musl"" already present on machine"
0.4204,Event,ADDED,eval-conflicts-rho005-r3-040-xm7pz.18d465616d1cb6a8,reason=Created count=1 msg=Created container: task
0.4206,Event,ADDED,eval-conflicts-rho005-r3-040-xm7pz.18d465616f481201,reason=Started count=1 msg=Started container task
0.4208,Event,ADDED,eval-conflicts-rho005-r3-040.18d4656151b700aa,reason=SuccessfulCreate count=1 msg=Created pod: eval-conflicts-rho005-r3-040-xm7pz
0.421,Event,ADDED,eval-conflicts-rho005-r3-040.18d4656487f2d484,reason=Completed count=1 msg=Job completed
0.4211,Event,ADDED,eval-conflicts-rho005-r3-041-76kch.18d465618e1304e8,"reason=FailedScheduling count=None msg=0/6 nodes are available: 1 c_wall violated: 1 conflicting context pair(s) with node memory, 5 node(s) had untolerated taint(s). no new claims to deallocate, preemption: 0/6 nodes are available: 1 No preemption victims found for incoming pod, 5 Preemption is not helpful for scheduling."
0.4213,Event,ADDED,eval-conflicts-rho005-r3-041-76kch.18d465618ebbf5cf,"reason=FailedScheduling count=None msg=0/6 nodes are available: 1 c_wall violated: 1 conflicting context pair(s) with node memory, 5 node(s) had untolerated taint(s). no new claims to deallocate, preemption: 0/6 nodes are available: 1 No preemption victims found for incoming pod, 5 Preemption is not helpful for scheduling."
0.4215,Event,ADDED,eval-conflicts-rho005-r3-041-76kch.18d46561e6d9ca14,reason=Scheduled count=None msg=Successfully assigned compute/eval-conflicts-rho005-r3-041-76kch to kind-worker2
0.4217,Event,ADDED,eval-conflicts-rho005-r3-041-76kch.18d4656200ee6068,"reason=Pulled count=1 msg=Container image ""busybox:musl"" already present on machine"
0.4218,Event,ADDED,eval-conflicts-rho005-r3-041-76kch.18d46562021b86df,reason=Created count=1 msg=Created container: task
0.422,Event,ADDED,eval-conflicts-rho005-r3-041-76kch.18d4656204395284,reason=Started count=1 msg=Started container task
0.4222,Event,ADDED,eval-conflicts-rho005-r3-041.18d465618dd44d20,reason=SuccessfulCreate count=1 msg=Created pod: eval-conflicts-rho005-r3-041-76kch
0.4223,Event,ADDED,eval-conflicts-rho005-r3-041.18d465652eb77612,reason=Completed count=1 msg=Job completed
0.4225,Event,ADDED,eval-conflicts-rho005-r3-042-lswxf.18d46561ca93644c,reason=Scheduled count=None msg=Successfully assigned compute/eval-conflicts-rho005-r3-042-lswxf to kind-worker3
0.4227,Event,ADDED,eval-conflicts-rho005-r3-042-lswxf.18d46561e362d13f,"reason=Pulled count=1 msg=Container image ""busybox:musl"" already present on machine"
0.423,Event,ADDED,eval-conflicts-rho005-r3-042-lswxf.18d46561e477b0bc,reason=Created count=1 msg=Created container: task
0.4231,Event,ADDED,eval-conflicts-rho005-r3-042-lswxf.18d46561e69acff2,reason=Started count=1 msg=Started container task
0.4233,Event,ADDED,eval-conflicts-rho005-r3-042.18d46561ca095d52,reason=SuccessfulCreate count=1 msg=Created pod: eval-conflicts-rho005-r3-042-lswxf
0.4235,Event,ADDED,eval-conflicts-rho005-r3-042.18d4656500c1c6be,reason=Completed count=1 msg=Job completed
0.4236,Event,ADDED,eval-conflicts-rho005-r3-043-bws44.18d46562052fd23b,reason=Scheduled count=None msg=Successfully assigned compute/eval-conflicts-rho005-r3-043-bws44 to kind-worker3
0.4238,Event,ADDED,eval-conflicts-rho005-r3-043-bws44.18d465621e8991da,"reason=Pulled count=1 msg=Container image ""busybox:musl"" already present on machine"
0.424,Event,ADDED,eval-conflicts-rho005-r3-043-bws44.18d465621f94a43e,reason=Created count=1 msg=Created container: task
0.4241,Event,ADDED,eval-conflicts-rho005-r3-043-bws44.18d4656221a2a962,reason=Started count=1 msg=Started container task
0.4243,Event,ADDED,eval-conflicts-rho005-r3-043.18d46562047a8e75,reason=SuccessfulCreate count=1 msg=Created pod: eval-conflicts-rho005-r3-043-bws44
0.4244,Event,ADDED,eval-conflicts-rho005-r3-043.18d465653c7c1b09,reason=Completed count=1 msg=Job completed
0.4249,Event,ADDED,eval-conflicts-rho005-r3-044-g4t28.18d4656240eae81e,reason=Scheduled count=None msg=Successfully assigned compute/eval-conflicts-rho005-r3-044-g4t28 to kind-worker2
0.4251,Event,ADDED,eval-conflicts-rho005-r3-044-g4t28.18d465625a2d903a,"reason=Pulled count=1 msg=Container image ""busybox:musl"" already present on machine"
0.4253,Event,ADDED,eval-conflicts-rho005-r3-044-g4t28.18d465625b44e73e,reason=Created count=1 msg=Created container: task
0.4254,Event,ADDED,eval-conflicts-rho005-r3-044-g4t28.18d465625e2bc61f,reason=Started count=1 msg=Started container task
0.4258,Event,ADDED,eval-conflicts-rho005-r3-044.18d4656240048fb4,reason=SuccessfulCreate count=1 msg=Created pod: eval-conflicts-rho005-r3-044-g4t28
0.426,Event,ADDED,eval-conflicts-rho005-r3-044.18d465656adff80c,reason=Completed count=1 msg=Job completed
0.4262,Event,ADDED,eval-conflicts-rho005-r3-045-tglhh.18d465627cb3bac7,reason=Scheduled count=None msg=Successfully assigned compute/eval-conflicts-rho005-r3-045-tglhh to kind-worker2
0.4266,Event,ADDED,eval-conflicts-rho005-r3-045-tglhh.18d465629610168a,"reason=Pulled count=1 msg=Container image ""busybox:musl"" already present on machine"
0.4267,Event,ADDED,eval-conflicts-rho005-r3-045-tglhh.18d4656297223949,reason=Created count=1 msg=Created container: task
0.4269,Event,ADDED,eval-conflicts-rho005-r3-045-tglhh.18d46562991ab4ad,reason=Started count=1 msg=Started container task
0.4271,Event,ADDED,eval-conflicts-rho005-r3-045.18d465627c0454de,reason=SuccessfulCreate count=1 msg=Created pod: eval-conflicts-rho005-r3-045-tglhh
0.4275,Event,ADDED,eval-conflicts-rho005-r3-045.18d46565a71cca43,reason=Completed count=1 msg=Job completed
0.4276,Event,ADDED,eval-conflicts-rho005-r3-046-8v9bp.18d46562b87d1fcb,reason=Scheduled count=None msg=Successfully assigned compute/eval-conflicts-rho005-r3-046-8v9bp to kind-worker5
0.4278,Event,ADDED,eval-conflicts-rho005-r3-046-8v9bp.18d46562d3cc073a,"reason=Pulled count=1 msg=Container image ""busybox:musl"" already present on machine"
0.428,Event,ADDED,eval-conflicts-rho005-r3-046-8v9bp.18d46562d4e6721d,reason=Created count=1 msg=Created container: task
0.4284,Event,ADDED,eval-conflicts-rho005-r3-046-8v9bp.18d46562d726590f,reason=Started count=1 msg=Started container task
0.4285,Event,ADDED,eval-conflicts-rho005-r3-046.18d46562b7c2ac98,reason=SuccessfulCreate count=1 msg=Created pod: eval-conflicts-rho005-r3-046-8v9bp
0.4287,Event,ADDED,eval-conflicts-rho005-r3-046.18d4656602c83b62,reason=Completed count=1 msg=Job completed
0.429,Event,ADDED,eval-conflicts-rho005-r3-047-p87zm.18d46562f48ae586,reason=Scheduled count=None msg=Successfully assigned compute/eval-conflicts-rho005-r3-047-p87zm to kind-worker5
0.4292,Event,ADDED,eval-conflicts-rho005-r3-047-p87zm.18d465630e1e96a5,"reason=Pulled count=1 msg=Container image ""busybox:musl"" already present on machine"
0.4294,Event,ADDED,eval-conflicts-rho005-r3-047-p87zm.18d465630f39e258,reason=Created count=1 msg=Created container: task
0.4296,Event,ADDED,eval-conflicts-rho005-r3-047-p87zm.18d46563112a3303,reason=Started count=1 msg=Started container task
0.43,Event,ADDED,eval-conflicts-rho005-r3-047.18d46562f365e4f0,reason=SuccessfulCreate count=1 msg=Created pod: eval-conflicts-rho005-r3-047-p87zm
0.4302,Event,ADDED,eval-conflicts-rho005-r3-047.18d465663e2725de,reason=Completed count=1 msg=Job completed
0.4304,Event,ADDED,eval-conflicts-rho005-r3-048-c4cg4.18d465632f327c34,reason=Scheduled count=None msg=Successfully assigned compute/eval-conflicts-rho005-r3-048-c4cg4 to kind-worker5
0.4307,Event,ADDED,eval-conflicts-rho005-r3-048-c4cg4.18d46563490282bc,"reason=Pulled count=1 msg=Container image ""busybox:musl"" already present on machine"
0.4309,Event,ADDED,eval-conflicts-rho005-r3-048-c4cg4.18d465634a26c1cb,reason=Created count=1 msg=Created container: task
0.431,Event,ADDED,eval-conflicts-rho005-r3-048-c4cg4.18d465634f172475,reason=Started count=1 msg=Started container task
0.4312,Event,ADDED,eval-conflicts-rho005-r3-048.18d465632e59bf11,reason=SuccessfulCreate count=1 msg=Created pod: eval-conflicts-rho005-r3-048-c4cg4
0.4315,Event,ADDED,eval-conflicts-rho005-r3-048.18d465667a4cd244,reason=Completed count=1 msg=Job completed
0.4317,Event,ADDED,eval-conflicts-rho005-r3-049-t7gpf.18d465636b93eda8,reason=Scheduled count=None msg=Successfully assigned compute/eval-conflicts-rho005-r3-049-t7gpf to kind-worker5
0.4319,Event,ADDED,eval-conflicts-rho005-r3-049-t7gpf.18d4656384d238ab,"reason=Pulled count=1 msg=Container image ""busybox:musl"" already present on machine"
0.4321,Event,ADDED,eval-conflicts-rho005-r3-049-t7gpf.18d4656385e66b61,reason=Created count=1 msg=Created container: task
0.4323,Event,ADDED,eval-conflicts-rho005-r3-049-t7gpf.18d4656387ed28af,reason=Started count=1 msg=Started container task
0.4324,Event,ADDED,eval-conflicts-rho005-r3-049.18d465636a9d0115,reason=SuccessfulCreate count=1 msg=Created pod: eval-conflicts-rho005-r3-049-t7gpf
0.4326,Event,ADDED,eval-conflicts-rho005-r3-049.18d46566b6112ff3,reason=Completed count=1 msg=Job completed
0.4328,Event,ADDED,eval-conflicts-rho005-r3-050-95mt4.18d46563a6fd0fdf,reason=Scheduled count=None msg=Successfully assigned compute/eval-conflicts-rho005-r3-050-95mt4 to kind-worker
0.433,Event,ADDED,eval-conflicts-rho005-r3-050-95mt4.18d46563c11eeda8,"reason=Pulled count=1 msg=Container image ""busybox:musl"" already present on machine"
0.4331,Event,ADDED,eval-conflicts-rho005-r3-050-95mt4.18d46563c23f0495,reason=Created count=1 msg=Created container: task
0.4333,Event,ADDED,eval-conflicts-rho005-r3-050-95mt4.18d46563c546fe4c,reason=Started count=1 msg=Started container task
0.4335,Event,ADDED,eval-conflicts-rho005-r3-050.18d46563a6152f5d,reason=SuccessfulCreate count=1 msg=Created pod: eval-conflicts-rho005-r3-050-95mt4
0.4336,Event,ADDED,eval-conflicts-rho005-r3-050.18d46566e2f35808,reason=Completed count=1 msg=Job completed
0.434,Event,ADDED,eval-conflicts-rho005-r3-051-qfwbb.18d46563e28ffaf3,reason=Scheduled count=None msg=Successfully assigned compute/eval-conflicts-rho005-r3-051-qfwbb to kind-worker
0.4342,Event,ADDED,eval-conflicts-rho005-r3-051-qfwbb.18d46563fbdd8388,"reason=Pulled count=1 msg=Container image ""busybox:musl"" already present on machine"
0.4345,Event,ADDED,eval-conflicts-rho005-r3-051-qfwbb.18d46563fce72380,reason=Created count=1 msg=Created container: task
0.4347,Event,ADDED,eval-conflicts-rho005-r3-051-qfwbb.18d465640206ff3e,reason=Started count=1 msg=Started container task
0.4348,Event,ADDED,eval-conflicts-rho005-r3-051.18d46563e14f0ceb,reason=SuccessfulCreate count=1 msg=Created pod: eval-conflicts-rho005-r3-051-qfwbb
0.4354,Event,ADDED,eval-conflicts-rho005-r3-051.18d465671ef95f0c,reason=Completed count=1 msg=Job completed
0.4357,Event,ADDED,eval-conflicts-rho005-r3-052-bwshb.18d465641e3ad2ae,reason=Scheduled count=None msg=Successfully assigned compute/eval-conflicts-rho005-r3-052-bwshb to kind-worker
0.4359,Event,ADDED,eval-conflicts-rho005-r3-052-bwshb.18d4656438205e7e,"reason=Pulled count=1 msg=Container image ""busybox:musl"" already present on machine"
0.4361,Event,ADDED,eval-conflicts-rho005-r3-052-bwshb.18d465643931cb09,reason=Created count=1 msg=Created container: task
0.4364,Event,ADDED,eval-conflicts-rho005-r3-052-bwshb.18d465643b36695f,reason=Started count=1 msg=Started container task
0.4366,Event,ADDED,eval-conflicts-rho005-r3-052.18d465641cefa070,reason=SuccessfulCreate count=1 msg=Created pod: eval-conflicts-rho005-r3-052-bwshb
0.4368,Event,ADDED,eval-conflicts-rho005-r3-052.18d465675ad344d1,reason=Completed count=1 msg=Job completed
0.4372,Event,ADDED,eval-conflicts-rho005-r3-053-dtc6p.18d4656458cabd57,"reason=FailedScheduling count=None msg=0/6 nodes are available: 1 c_wall violated: 1 conflicting context pair(s) with node memory, 1 c_wall violated: 2 conflicting context pair(s) with node memory, 4 node(s) had untolerated taint(s). no new claims to deallocate, preemption: 0/6 nodes are available: 2 No preemption victims found for incoming pod, 4 Preemption is not helpful for scheduling."
0.4374,Event,ADDED,eval-conflicts-rho005-r3-053-dtc6p.18d4656459896248,"reason=FailedScheduling count=None msg=0/6 nodes are available: 1 c_wall violated: 1 conflicting context pair(s) with node memory, 1 c_wall violated: 2 conflicting context pair(s) with node memory, 4 node(s) had untolerated taint(s). no new claims to deallocate, preemption: 0/6 nodes are available: 2 No preemption victims found for incoming pod, 4 Preemption is not helpful for scheduling."
0.4376,Event,ADDED,eval-conflicts-rho005-r3-053-dtc6p.18d46564eead4506,reason=Scheduled count=None msg=Successfully assigned compute/eval-conflicts-rho005-r3-053-dtc6p to kind-worker3
0.4379,Event,ADDED,eval-conflicts-rho005-r3-053-dtc6p.18d4656507d1a7b6,"reason=Pulled count=1 msg=Container image ""busybox:musl"" already present on machine"
0.4381,Event,ADDED,eval-conflicts-rho005-r3-053-dtc6p.18d4656508e3679e,reason=Created count=1 msg=Created container: task
0.4383,Event,ADDED,eval-conflicts-rho005-r3-053-dtc6p.18d465650afd2092,reason=Started count=1 msg=Started container task
0.4385,Event,ADDED,eval-conflicts-rho005-r3-053.18d4656458509eb5,reason=SuccessfulCreate count=1 msg=Created pod: eval-conflicts-rho005-r3-053-dtc6p
0.4388,Event,ADDED,eval-conflicts-rho005-r3-053.18d4656844135fc5,reason=Completed count=1 msg=Job completed
0.4389,Event,ADDED,eval-conflicts-rho005-r3-054-lkdlp.18d4656495af112b,reason=Scheduled count=None msg=Successfully assigned compute/eval-conflicts-rho005-r3-054-lkdlp to kind-worker
0.4391,Event,ADDED,eval-conflicts-rho005-r3-054-lkdlp.18d46564afba3c8a,"reason=Pulled count=1 msg=Container image ""busybox:musl"" already present on machine"
0.4393,Event,ADDED,eval-conflicts-rho005-r3-054-lkdlp.18d46564b14fc9f5,reason=Created count=1 msg=Created container: task
0.4396,Event,ADDED,eval-conflicts-rho005-r3-054-lkdlp.18d46564b7ab8684,reason=Started count=1 msg=Started container task
0.4398,Event,ADDED,eval-conflicts-rho005-r3-054.18d4656494c3b966,reason=SuccessfulCreate count=1 msg=Created pod: eval-conflicts-rho005-r3-054-lkdlp
0.4399,Event,ADDED,eval-conflicts-rho005-r3-054.18d46567d2a78990,reason=Completed count=1 msg=Job completed
0.4403,Event,ADDED,eval-conflicts-rho005-r3-055-4flh4.18d46564d0f379be,reason=Scheduled count=None msg=Successfully assigned compute/eval-conflicts-rho005-r3-055-4flh4 to kind-worker5
0.4404,Event,ADDED,eval-conflicts-rho005-r3-055-4flh4.18d46564ec5e580c,"reason=Pulled count=1 msg=Container image ""busybox:musl"" already present on machine"
0.4406,Event,ADDED,eval-conflicts-rho005-r3-055-4flh4.18d46564ed9552f5,reason=Created count=1 msg=Created container: task
0.4408,Event,ADDED,eval-conflicts-rho005-r3-055-4flh4.18d46564f1f20e80,reason=Started count=1 msg=Started container task
0.4412,Event,ADDED,eval-conflicts-rho005-r3-055.18d46564d004a4c5,reason=SuccessfulCreate count=1 msg=Created pod: eval-conflicts-rho005-r3-055-4flh4
0.4414,Event,ADDED,eval-conflicts-rho005-r3-055.18d465681d186c4d,reason=Completed count=1 msg=Job completed
0.4416,Event,ADDED,eval-conflicts-rho005-r3-056-lh476.18d465650c19e413,reason=Scheduled count=None msg=Successfully assigned compute/eval-conflicts-rho005-r3-056-lh476 to kind-worker
0.4419,Event,ADDED,eval-conflicts-rho005-r3-056-lh476.18d465652702c9b3,"reason=Pulled count=1 msg=Container image ""busybox:musl"" already present on machine"
0.4422,Event,ADDED,eval-conflicts-rho005-r3-056-lh476.18d46565280ecfc4,reason=Created count=1 msg=Created container: task
0.4424,Event,ADDED,eval-conflicts-rho005-r3-056-lh476.18d465652b5aa576,reason=Started count=1 msg=Started container task
0.4426,Event,ADDED,eval-conflicts-rho005-r3-056.18d465650b6926e1,reason=SuccessfulCreate count=1 msg=Created pod: eval-conflicts-rho005-r3-056-lh476
0.4428,Event,ADDED,eval-conflicts-rho005-r3-056.18d465684923fe2e,reason=Completed count=1 msg=Job completed
0.443,Event,ADDED,eval-conflicts-rho005-r3-057-p6xrs.18d4656548922f2a,reason=Scheduled count=None msg=Successfully assigned compute/eval-conflicts-rho005-r3-057-p6xrs to kind-worker3
0.4432,Event,ADDED,eval-conflicts-rho005-r3-057-p6xrs.18d465656185a51b,"reason=Pulled count=1 msg=Container image ""busybox:musl"" already present on machine"
0.4434,Event,ADDED,eval-conflicts-rho005-r3-057-p6xrs.18d4656562a3176b,reason=Created count=1 msg=Created container: task
0.4436,Event,ADDED,eval-conflicts-rho005-r3-057-p6xrs.18d465656574dba4,reason=Started count=1 msg=Started container task
0.444,Event,ADDED,eval-conflicts-rho005-r3-057.18d4656547cb2ab4,reason=SuccessfulCreate count=1 msg=Created pod: eval-conflicts-rho005-r3-057-p6xrs
0.4442,Event,ADDED,eval-conflicts-rho005-r3-057.18d465688033d3a7,reason=Completed count=1 msg=Job completed
0.4443,Event,ADDED,eval-conflicts-rho005-r3-058-fw526.18d46565832a3a81,reason=Scheduled count=None msg=Successfully assigned compute/eval-conflicts-rho005-r3-058-fw526 to kind-worker
0.4446,Event,ADDED,eval-conflicts-rho005-r3-058-fw526.18d465659c3567d5,"reason=Pulled count=1 msg=Container image ""busybox:musl"" already present on machine"
0.4449,Event,ADDED,eval-conflicts-rho005-r3-058-fw526.18d465659d471722,reason=Created count=1 msg=Created container: task
0.4451,Event,ADDED,eval-conflicts-rho005-r3-058-fw526.18d46565a01f5602,reason=Started count=1 msg=Started container task
0.4454,Event,ADDED,eval-conflicts-rho005-r3-058.18d46565828c0745,reason=SuccessfulCreate count=1 msg=Created pod: eval-conflicts-rho005-r3-058-fw526
0.4456,Event,ADDED,eval-conflicts-rho005-r3-058.18d46568c153bc9d,reason=Completed count=1 msg=Job completed
0.4458,Event,ADDED,eval-conflicts-rho005-r3-059-799jl.18d46565c00c14fc,reason=Scheduled count=None msg=Successfully assigned compute/eval-conflicts-rho005-r3-059-799jl to kind-worker3
0.446,Event,ADDED,eval-conflicts-rho005-r3-059-799jl.18d46565da456efb,"reason=Pulled count=1 msg=Container image ""busybox:musl"" already present on machine"
0.4464,Event,ADDED,eval-conflicts-rho005-r3-059-799jl.18d46565db7964ac,reason=Created count=1 msg=Created container: task
0.4466,Event,ADDED,eval-conflicts-rho005-r3-059-799jl.18d46565dd82f74d,reason=Started count=1 msg=Started container task
0.4468,Event,ADDED,eval-conflicts-rho005-r3-059.18d46565bf1ed456,reason=SuccessfulCreate count=1 msg=Created pod: eval-conflicts-rho005-r3-059-799jl
0.447,Event,ADDED,eval-conflicts-rho005-r3-059.18d46568f8887e2e,reason=Completed count=1 msg=Job completed
0.4472,Event,ADDED,eval-conflicts-rho005-r3-060-fggn9.18d46565fb0b0597,reason=Scheduled count=None msg=Successfully assigned compute/eval-conflicts-rho005-r3-060-fggn9 to kind-worker4
0.4473,Event,ADDED,eval-conflicts-rho005-r3-060-fggn9.18d465661587697e,"reason=Pulled count=1 msg=Container image ""busybox:musl"" already present on machine"
0.4475,Event,ADDED,eval-conflicts-rho005-r3-060-fggn9.18d46566169c64ad,reason=Created count=1 msg=Created container: task
0.4477,Event,ADDED,eval-conflicts-rho005-r3-060-fggn9.18d465661a9a1eba,reason=Started count=1 msg=Started container task
0.4479,Event,ADDED,eval-conflicts-rho005-r3-060.18d46565fa4d3b91,reason=SuccessfulCreate count=1 msg=Created pod: eval-conflicts-rho005-r3-060-fggn9
0.4482,Event,ADDED,eval-conflicts-rho005-r3-060.18d465693a8319bc,reason=Completed count=1 msg=Job completed
0.4483,Event,ADDED,eval-conflicts-rho005-r3-061-6phl8.18d4656636a9845d,reason=Scheduled count=None msg=Successfully assigned compute/eval-conflicts-rho005-r3-061-6phl8 to kind-worker4
0.4487,Event,ADDED,eval-conflicts-rho005-r3-061-6phl8.18d46566512aff15,"reason=Pulled count=1 msg=Container image ""busybox:musl"" already present on machine"
0.4489,Event,ADDED,eval-conflicts-rho005-r3-061-6phl8.18d465665247e636,reason=Created count=1 msg=Created container: task
0.449,Event,ADDED,eval-conflicts-rho005-r3-061-6phl8.18d46566550c3355,reason=Started count=1 msg=Started container task
0.4493,Event,ADDED,eval-conflicts-rho005-r3-061.18d4656635c9441d,reason=SuccessfulCreate count=1 msg=Created pod: eval-conflicts-rho005-r3-061-6phl8
0.4495,Event,ADDED,eval-conflicts-rho005-r3-061.18d46569768610ec,reason=Completed count=1 msg=Job completed
0.4499,Event,ADDED,eval-conflicts-rho005-r3-062-4544n.18d4656672ff4d4d,reason=Scheduled count=None msg=Successfully assigned compute/eval-conflicts-rho005-r3-062-4544n to kind-worker4
0.4501,Event,ADDED,eval-conflicts-rho005-r3-062-4544n.18d465668d8419c8,"reason=Pulled count=1 msg=Container image ""busybox:musl"" already present on machine"
0.4505,Event,ADDED,eval-conflicts-rho005-r3-062-4544n.18d465668e983809,reason=Created count=1 msg=Created container: task
0.4507,Event,ADDED,eval-conflicts-rho005-r3-062-4544n.18d46566909eea67,reason=Started count=1 msg=Started container task
0.4508,Event,ADDED,eval-conflicts-rho005-r3-062.18d465667209f717,reason=SuccessfulCreate count=1 msg=Created pod: eval-conflicts-rho005-r3-062-4544n
0.451,Event,ADDED,eval-conflicts-rho005-r3-062.18d46569b24b624c,reason=Completed count=1 msg=Job completed
0.4513,Event,ADDED,eval-conflicts-rho005-r3-063-6bmxz.18d46566adf096dc,reason=Scheduled count=None msg=Successfully assigned compute/eval-conflicts-rho005-r3-063-6bmxz to kind-worker2
0.4515,Event,ADDED,eval-conflicts-rho005-r3-063-6bmxz.18d46566c7d28a0d,"reason=Pulled count=1 msg=Container image ""busybox:musl"" already present on machine"
0.4517,Event,ADDED,eval-conflicts-rho005-r3-063-6bmxz.18d46566c8e70ac9,reason=Created count=1 msg=Created container: task
0.4519,Event,ADDED,eval-conflicts-rho005-r3-063-6bmxz.18d46566caead26d,reason=Started count=1 msg=Started container task
0.4521,Event,ADDED,eval-conflicts-rho005-r3-063.18d46566acf33b03,reason=SuccessfulCreate count=1 msg=Created pod: eval-conflicts-rho005-r3-063-6bmxz
0.4522,Event,ADDED,eval-conflicts-rho005-r3-063.18d46569da5cee27,reason=Completed count=1 msg=Job completed
0.4524,Event,ADDED,eval-conflicts-rho005-r3-064-62dwk.18d46566e94affa4,reason=Scheduled count=None msg=Successfully assigned compute/eval-conflicts-rho005-r3-064-62dwk to kind-worker2
0.4526,Event,ADDED,eval-conflicts-rho005-r3-064-62dwk.18d4656702e01bc7,"reason=Pulled count=1 msg=Container image ""busybox:musl"" already present on machine"
0.4527,Event,ADDED,eval-conflicts-rho005-r3-064-62dwk.18d4656703e84cda,reason=Created count=1 msg=Created container: task
0.4529,Event,ADDED,eval-conflicts-rho005-r3-064-62dwk.18d4656705bd1d38,reason=Started count=1 msg=Started container task
0.4534,Event,ADDED,eval-conflicts-rho005-r3-064.18d46566e820650b,reason=SuccessfulCreate count=1 msg=Created pod: eval-conflicts-rho005-r3-064-62dwk
0.4536,Event,ADDED,eval-conflicts-rho005-r3-064.18d4656a15bf46e1,reason=Completed count=1 msg=Job completed
0.4538,Event,ADDED,eval-conflicts-rho005-r3-065-v8bqx.18d46567250c6d4d,reason=Scheduled count=None msg=Successfully assigned compute/eval-conflicts-rho005-r3-065-v8bqx to kind-worker2
0.454,Event,ADDED,eval-conflicts-rho005-r3-065-v8bqx.18d465673e705dbd,"reason=Pulled count=1 msg=Container image ""busybox:musl"" already present on machine"
0.4543,Event,ADDED,eval-conflicts-rho005-r3-065-v8bqx.18d465673f8a4e3b,reason=Created count=1 msg=Created container: task
0.4544,Event,ADDED,eval-conflicts-rho005-r3-065-v8bqx.18d4656743fece11,reason=Started count=1 msg=Started container task
0.4546,Event,ADDED,eval-conflicts-rho005-r3-065.18d4656723db46e7,reason=SuccessfulCreate count=1 msg=Created pod: eval-conflicts-rho005-r3-065-v8bqx
0.4548,Event,ADDED,eval-conflicts-rho005-r3-065.18d4656a51dc9759,reason=Completed count=1 msg=Job completed
0.455,Event,ADDED,eval-conflicts-rho005-r3-066-6qhf9.18d46567601d4bf3,reason=Scheduled count=None msg=Successfully assigned compute/eval-conflicts-rho005-r3-066-6qhf9 to kind-worker2
0.4552,Event,ADDED,eval-conflicts-rho005-r3-066-6qhf9.18d465677a4657b5,"reason=Pulled count=1 msg=Container image ""busybox:musl"" already present on machine"
0.4554,Event,ADDED,eval-conflicts-rho005-r3-066-6qhf9.18d465677b573906,reason=Created count=1 msg=Created container: task
0.4557,Event,ADDED,eval-conflicts-rho005-r3-066-6qhf9.18d465677d52ad47,reason=Started count=1 msg=Started container task
0.4559,Event,ADDED,eval-conflicts-rho005-r3-066.18d465675f3f252c,reason=SuccessfulCreate count=1 msg=Created pod: eval-conflicts-rho005-r3-066-6qhf9
0.4561,Event,ADDED,eval-conflicts-rho005-r3-066.18d4656a8daec7a4,reason=Completed count=1 msg=Job completed
0.4562,Event,ADDED,eval-conflicts-rho005-r3-067-8v7zz.18d465679cd40a2f,reason=Scheduled count=None msg=Successfully assigned compute/eval-conflicts-rho005-r3-067-8v7zz to kind-worker2
0.4565,Event,ADDED,eval-conflicts-rho005-r3-067-8v7zz.18d46567b5ae2eb6,"reason=Pulled count=1 msg=Container image ""busybox:musl"" already present on machine"
0.4567,Event,ADDED,eval-conflicts-rho005-r3-067-8v7zz.18d46567b6bc634f,reason=Created count=1 msg=Created container: task
0.4569,Event,ADDED,eval-conflicts-rho005-r3-067-8v7zz.18d46567ba62b854,reason=Started count=1 msg=Started container task
0.4572,Event,ADDED,eval-conflicts-rho005-r3-067.18d465679c11d987,reason=SuccessfulCreate count=1 msg=Created pod: eval-conflicts-rho005-r3-067-8v7zz
0.4573,Event,ADDED,eval-conflicts-rho005-r3-067.18d4656ac98ede60,reason=Completed count=1 msg=Job completed
0.4575,Event,ADDED,eval-conflicts-rho005-r3-068-7c75b.18d46567d7728fbf,reason=Scheduled count=None msg=Successfully assigned compute/eval-conflicts-rho005-r3-068-7c75b to kind-worker4
0.4577,Event,ADDED,eval-conflicts-rho005-r3-068-7c75b.18d46567f062a4fb,"reason=Pulled count=1 msg=Container image ""busybox:musl"" already present on machine"
0.4579,Event,ADDED,eval-conflicts-rho005-r3-068-7c75b.18d46567f1705112,reason=Created count=1 msg=Created container: task
0.4581,Event,ADDED,eval-conflicts-rho005-r3-068-7c75b.18d46567f5c17975,reason=Started count=1 msg=Started container task
0.4583,Event,ADDED,eval-conflicts-rho005-r3-068.18d46567d69388d6,reason=SuccessfulCreate count=1 msg=Created pod: eval-conflicts-rho005-r3-068-7c75b
0.4586,Event,ADDED,eval-conflicts-rho005-r3-068.18d4656add33bf0d,reason=Completed count=1 msg=Job completed
0.4589,Event,ADDED,eval-conflicts-rho005-r3-069-88tfb.18d4656812e65fec,reason=Scheduled count=None msg=Successfully assigned compute/eval-conflicts-rho005-r3-069-88tfb to kind-worker4
0.4591,Event,ADDED,eval-conflicts-rho005-r3-069-88tfb.18d465682bbc7dd2,"reason=Pulled count=1 msg=Container image ""busybox:musl"" already present on machine"
0.4593,Event,ADDED,eval-conflicts-rho005-r3-069-88tfb.18d465682cf0224d,reason=Created count=1 msg=Created container: task
0.4596,Event,ADDED,eval-conflicts-rho005-r3-069-88tfb.18d4656830654359,reason=Started count=1 msg=Started container task
0.4598,Event,ADDED,eval-conflicts-rho005-r3-069.18d46568122af7fb,reason=SuccessfulCreate count=1 msg=Created pod: eval-conflicts-rho005-r3-069-88tfb
0.46,Event,ADDED,eval-conflicts-rho005-r3-069.18d4656b1891ef69,reason=Completed count=1 msg=Job completed
0.4601,Event,ADDED,eval-conflicts-rho005-r3-070-5q8nk.18d465684e4da74d,"reason=FailedScheduling count=None msg=0/6 nodes are available: 1 c_wall violated: 1 conflicting context pair(s) with node memory, 5 node(s) had untolerated taint(s). no new claims to deallocate, preemption: 0/6 nodes are available: 1 No preemption victims found for incoming pod, 5 Preemption is not helpful for scheduling."
0.4605,Event,ADDED,eval-conflicts-rho005-r3-070-5q8nk.18d465684ecee5c7,"reason=FailedScheduling count=None msg=0/6 nodes are available: 1 c_wall violated: 1 conflicting context pair(s) with node memory, 5 node(s) had untolerated taint(s). no new claims to deallocate, preemption: 0/6 nodes are available: 1 No preemption victims found for incoming pod, 5 Preemption is not helpful for scheduling."
0.4608,Event,ADDED,eval-conflicts-rho005-r3-070-5q8nk.18d46569b2ae38ab,reason=Scheduled count=None msg=Successfully assigned compute/eval-conflicts-rho005-r3-070-5q8nk to kind-worker3
0.461,Event,ADDED,eval-conflicts-rho005-r3-070-5q8nk.18d46569ce41a81e,"reason=Pulled count=1 msg=Container image ""busybox:musl"" already present on machine"
0.4615,Event,ADDED,eval-conflicts-rho005-r3-070-5q8nk.18d46569cff7e927,reason=Created count=1 msg=Created container: task
0.4619,Event,ADDED,eval-conflicts-rho005-r3-070-5q8nk.18d46569d8d98b52,reason=Started count=1 msg=Started container task
0.4621,Event,ADDED,eval-conflicts-rho005-r3-070.18d465684e11bc58,reason=SuccessfulCreate count=1 msg=Created pod: eval-conflicts-rho005-r3-070-5q8nk
0.4624,Event,ADDED,eval-conflicts-rho005-r3-070.18d4656cf0d012f7,reason=Completed count=1 msg=Job completed
0.4626,Event,ADDED,eval-conflicts-rho005-r3-071-qtz8z.18d465688a8ecbf9,"reason=FailedScheduling count=None msg=0/6 nodes are available: 1 c_wall violated: 1 conflicting context pair(s) with node memory, 5 node(s) had untolerated taint(s). no new claims to deallocate, preemption: 0/6 nodes are available: 1 No preemption victims found for incoming pod, 5 Preemption is not helpful for scheduling."
0.4629,Event,ADDED,eval-conflicts-rho005-r3-071-qtz8z.18d465688b0e45c1,"reason=FailedScheduling count=None msg=0/6 nodes are available: 1 c_wall violated: 1 conflicting context pair(s) with node memory, 5 node(s) had untolerated taint(s). no new claims to deallocate, preemption: 0/6 nodes are available: 1 No preemption victims found for incoming pod, 5 Preemption is not helpful for scheduling."
0.4631,Event,ADDED,eval-conflicts-rho005-r3-071-qtz8z.18d46569b2e0a4bf,reason=Scheduled count=None msg=Successfully assigned compute/eval-conflicts-rho005-r3-071-qtz8z to kind-worker3
0.4634,Event,ADDED,eval-conflicts-rho005-r3-071-qtz8z.18d46569ce6559e6,"reason=Pulled count=1 msg=Container image ""busybox:musl"" already present on machine"
0.4636,Event,ADDED,eval-conflicts-rho005-r3-071-qtz8z.18d46569d098d253,reason=Created count=1 msg=Created container: task
0.4638,Event,ADDED,eval-conflicts-rho005-r3-071-qtz8z.18d46569d8d7f5c0,reason=Started count=1 msg=Started container task
0.4642,Event,ADDED,eval-conflicts-rho005-r3-071.18d465688a516b6f,reason=SuccessfulCreate count=1 msg=Created pod: eval-conflicts-rho005-r3-071-qtz8z
0.4644,Event,ADDED,eval-conflicts-rho005-r3-071.18d4656cf0cf8042,reason=Completed count=1 msg=Job completed
0.4645,Event,ADDED,eval-conflicts-rho005-r3-072-mvdhh.18d46568c608326c,reason=Scheduled count=None msg=Successfully assigned compute/eval-conflicts-rho005-r3-072-mvdhh to kind-worker2
0.4647,Event,ADDED,eval-conflicts-rho005-r3-072-mvdhh.18d46568df8fb165,"reason=Pulled count=1 msg=Container image ""busybox:musl"" already present on machine"
0.4649,Event,ADDED,eval-conflicts-rho005-r3-072-mvdhh.18d46568e0aa1750,reason=Created count=1 msg=Created container: task
0.4651,Event,ADDED,eval-conflicts-rho005-r3-072-mvdhh.18d46568e2a0855a,reason=Started count=1 msg=Started container task
0.4652,Event,ADDED,eval-conflicts-rho005-r3-072.18d46568c5773df1,reason=SuccessfulCreate count=1 msg=Created pod: eval-conflicts-rho005-r3-072-mvdhh
0.4654,Event,ADDED,eval-conflicts-rho005-r3-072.18d4656bf4188a47,reason=Completed count=1 msg=Job completed
0.4656,Event,ADDED,eval-conflicts-rho005-r3-073-ndv9b.18d4656900f3aa4a,"reason=FailedScheduling count=None msg=0/6 nodes are available: 6 node(s) had untolerated taint(s). no new claims to deallocate, preemption: 0/6 nodes are available: 6 Preemption is not helpful for scheduling."
0.4657,Event,ADDED,eval-conflicts-rho005-r3-073-ndv9b.18d46569b35f719f,reason=Scheduled count=None msg=Successfully assigned compute/eval-conflicts-rho005-r3-073-ndv9b to kind-worker3
0.466,Event,ADDED,eval-conflicts-rho005-r3-073-ndv9b.18d46569d023043c,"reason=Pulled count=1 msg=Container image ""busybox:musl"" already present on machine"
0.4663,Event,ADDED,eval-conflicts-rho005-r3-073-ndv9b.18d46569d2e741f9,reason=Created count=1 msg=Created container: task
0.4665,Event,ADDED,eval-conflicts-rho005-r3-073-ndv9b.18d46569d8d96e91,reason=Started count=1 msg=Started container task
0.4667,Event,ADDED,eval-conflicts-rho005-r3-073.18d4656900ea558a,reason=SuccessfulCreate count=1 msg=Created pod: eval-conflicts-rho005-r3-073-ndv9b
0.4668,Event,ADDED,eval-conflicts-rho005-r3-073.18d4656ceff656b2,reason=Completed count=1 msg=Job completed
0.4671,Event,ADDED,eval-conflicts-rho005-r3-074-g2wzc.18d465693cbc27ce,"reason=FailedScheduling count=None msg=0/6 nodes are available: 6 node(s) had untolerated taint(s). no new claims to deallocate, preemption: 0/6 nodes are available: 6 Preemption is not helpful for scheduling."
0.4672,Event,ADDED,eval-conflicts-rho005-r3-074-g2wzc.18d46569b38a1453,reason=Scheduled count=None msg=Successfully assigned compute/eval-conflicts-rho005-r3-074-g2wzc to kind-worker3
0.4674,Event,ADDED,eval-conflicts-rho005-r3-074-g2wzc.18d46569cf839699,"reason=Pulled count=1 msg=Container image ""busybox:musl"" already present on machine"
0.4676,Event,ADDED,eval-conflicts-rho005-r3-074-g2wzc.18d46569d24eb671,reason=Created count=1 msg=Created container: task
0.4678,Event,ADDED,eval-conflicts-rho005-r3-074-g2wzc.18d46569d8db0cc3,reason=Started count=1 msg=Started container task
0.4679,Event,ADDED,eval-conflicts-rho005-r3-074.18d465693cb0f6d5,reason=SuccessfulCreate count=1 msg=Created pod: eval-conflicts-rho005-r3-074-g2wzc
0.4681,Event,ADDED,eval-conflicts-rho005-r3-074.18d4656cf0491211,reason=Completed count=1 msg=Job completed
0.4683,Event,ADDED,eval-conflicts-rho005-r3-075-q5j9x.18d46569787ad9fe,"reason=FailedScheduling count=None msg=0/6 nodes are available: 6 node(s) had untolerated taint(s). no new claims to deallocate, preemption: 0/6 nodes are available: 6 Preemption is not helpful for scheduling."
0.4684,Event,ADDED,eval-conflicts-rho005-r3-075-q5j9x.18d46569b3cd02dc,reason=Scheduled count=None msg=Successfully assigned compute/eval-conflicts-rho005-r3-075-q5j9x to kind-worker3
0.4687,Event,ADDED,eval-conflicts-rho005-r3-075-q5j9x.18d46569cff91ff0,"reason=Pulled count=1 msg=Container image ""busybox:musl"" already present on machine"
0.4688,Event,ADDED,eval-conflicts-rho005-r3-075-q5j9x.18d46569d2d68ff3,reason=Created count=1 msg=Created container: task
0.4692,Event,ADDED,eval-conflicts-rho005-r3-075-q5j9x.18d46569d8d96e9c,reason=Started count=1 msg=Started container task
0.4695,Event,ADDED,eval-conflicts-rho005-r3-075.18d46569786fb760,reason=SuccessfulCreate count=1 msg=Created pod: eval-conflicts-rho005-r3-075-q5j9x
0.4697,Event,ADDED,eval-conflicts-rho005-r3-075.18d4656ceff6bbcb,reason=Completed count=1 msg=Job completed
0.47,Event,ADDED,eval-conflicts-rho005-r3-076-4wlnv.18d46569b49cc251,"reason=FailedScheduling count=None msg=0/6 nodes are available: 1 c_wall violated: 1 conflicting context pair(s) with node memory, 5 node(s) had untolerated taint(s). no new claims to deallocate, preemption: 0/6 nodes are available: 1 No preemption victims found for incoming pod, 5 Preemption is not helpful for scheduling."
0.4702,Event,ADDED,eval-conflicts-rho005-r3-076-4wlnv.18d46569b7d7cb38,"reason=FailedScheduling count=None msg=0/6 nodes are available: 1 c_wall violated: 1 conflicting context pair(s) with node memory, 5 node(s) had untolerated taint(s). no new claims to deallocate, preemption: 0/6 nodes are available: 1 No preemption victims found for incoming pod, 5 Preemption is not helpful for scheduling."
0.4704,Event,ADDED,eval-conflicts-rho005-r3-076-4wlnv.18d46569d1d1b795,reason=Scheduled count=None msg=Successfully assigned compute/eval-conflicts-rho005-r3-076-4wlnv to kind-worker5
0.4706,Event,ADDED,eval-conflicts-rho005-r3-076-4wlnv.18d46569ebb5716e,"reason=Pulled count=1 msg=Container image ""busybox:musl"" already present on machine"
0.4708,Event,ADDED,eval-conflicts-rho005-r3-076-4wlnv.18d46569ece2915b,reason=Created count=1 msg=Created container: task
0.471,Event,ADDED,eval-conflicts-rho005-r3-076-4wlnv.18d46569eef1d3d1,reason=Started count=1 msg=Started container task
0.4711,Event,ADDED,eval-conflicts-rho005-r3-076.18d46569b451261b,reason=SuccessfulCreate count=1 msg=Created pod: eval-conflicts-rho005-r3-076-4wlnv
0.4714,Event,ADDED,eval-conflicts-rho005-r3-076.18d4656d02efbcb6,reason=Completed count=1 msg=Job completed
0.4716,Event,ADDED,eval-conflicts-rho005-r3-077-tbrhr.18d46569f0267816,reason=Scheduled count=None msg=Successfully assigned compute/eval-conflicts-rho005-r3-077-tbrhr to kind-worker3
0.4718,Event,ADDED,eval-conflicts-rho005-r3-077-tbrhr.18d4656a0a16c5b9,"reason=Pulled count=1 msg=Container image ""busybox:musl"" already present on machine"
0.4721,Event,ADDED,eval-conflicts-rho005-r3-077-tbrhr.18d4656a0b2d5286,reason=Created count=1 msg=Created container: task
0.4722,Event,ADDED,eval-conflicts-rho005-r3-077-tbrhr.18d4656a0d167082,reason=Started count=1 msg=Started container task
0.4724,Event,ADDED,eval-conflicts-rho005-r3-077.18d46569ef2b1a06,reason=SuccessfulCreate count=1 msg=Created pod: eval-conflicts-rho005-r3-077-tbrhr
0.4726,Event,ADDED,eval-conflicts-rho005-r3-077.18d4656d2bb040b3,reason=Completed count=1 msg=Job completed
0.4729,Event,ADDED,eval-conflicts-rho005-r3-078-wn2r2.18d4656a2c4d0932,reason=Scheduled count=None msg=Successfully assigned compute/eval-conflicts-rho005-r3-078-wn2r2 to kind-worker3
0.4731,Event,ADDED,eval-conflicts-rho005-r3-078-wn2r2.18d4656a45b46fe0,"reason=Pulled count=1 msg=Container image ""busybox:musl"" already present on machine"
0.4732,Event,ADDED,eval-conflicts-rho005-r3-078-wn2r2.18d4656a46c56403,reason=Created count=1 msg=Created container: task
0.4734,Event,ADDED,eval-conflicts-rho005-r3-078-wn2r2.18d4656a48b73c70,reason=Started count=1 msg=Started container task
0.4737,Event,ADDED,eval-conflicts-rho005-r3-078.18d4656a2b8fe3e1,reason=SuccessfulCreate count=1 msg=Created pod: eval-conflicts-rho005-r3-078-wn2r2
0.474,Event,ADDED,eval-conflicts-rho005-r3-078.18d4656d67961bbf,reason=Completed count=1 msg=Job completed
0.4741,Event,ADDED,eval-conflicts-rho005-r3-079-dk6z9.18d4656a672a58e3,reason=Scheduled count=None msg=Successfully assigned compute/eval-conflicts-rho005-r3-079-dk6z9 to kind-worker5
0.4744,Event,ADDED,eval-conflicts-rho005-r3-079-dk6z9.18d4656a8029b555,"reason=Pulled count=1 msg=Container image ""busybox:musl"" already present on machine"
0.4745,Event,ADDED,eval-conflicts-rho005-r3-079-dk6z9.18d4656a813fc69b,reason=Created count=1 msg=Created container: task
0.4747,Event,ADDED,eval-conflicts-rho005-r3-079-dk6z9.18d4656a8453eb2c,reason=Started count=1 msg=Started container task
0.4749,Event,ADDED,eval-conflicts-rho005-r3-079.18d4656a666d2d0e,reason=SuccessfulCreate count=1 msg=Created pod: eval-conflicts-rho005-r3-079-dk6z9
0.4751,Event,ADDED,eval-conflicts-rho005-r3-079.18d4656db86b95ce,reason=Completed count=1 msg=Job completed
0.4753,Event,ADDED,eval-conflicts-rho005-r3-080-f5mws.18d4656aa3e18688,reason=Scheduled count=None msg=Successfully assigned compute/eval-conflicts-rho005-r3-080-f5mws to kind-worker
0.4754,Event,ADDED,eval-conflicts-rho005-r3-080-f5mws.18d4656abd64e977,"reason=Pulled count=1 msg=Container image ""busybox:musl"" already present on machine"
0.4756,Event,ADDED,eval-conflicts-rho005-r3-080-f5mws.18d4656abe8297fa,reason=Created count=1 msg=Created container: task
0.4758,Event,ADDED,eval-conflicts-rho005-r3-080-f5mws.18d4656ac06bccd9,reason=Started count=1 msg=Started container task
0.476,Event,ADDED,eval-conflicts-rho005-r3-080.18d4656aa281eff4,reason=SuccessfulCreate count=1 msg=Created pod: eval-conflicts-rho005-r3-080-f5mws
0.4761,Event,ADDED,eval-conflicts-rho005-r3-080.18d4656de710ff3a,reason=Completed count=1 msg=Job completed
0.4763,Event,ADDED,eval-conflicts-rho005-r3-081-zb476.18d4656adecd4cdb,reason=Scheduled count=None msg=Successfully assigned compute/eval-conflicts-rho005-r3-081-zb476 to kind-worker
0.4764,Event,ADDED,eval-conflicts-rho005-r3-081-zb476.18d4656af80d9427,"reason=Pulled count=1 msg=Container image ""busybox:musl"" already present on machine"
0.4766,Event,ADDED,eval-conflicts-rho005-r3-081-zb476.18d4656af91a7dc3,reason=Created count=1 msg=Created container: task
0.4768,Event,ADDED,eval-conflicts-rho005-r3-081-zb476.18d4656afb165875,reason=Started count=1 msg=Started container task
0.4771,Event,ADDED,eval-conflicts-rho005-r3-081.18d4656add971410,reason=SuccessfulCreate count=1 msg=Created pod: eval-conflicts-rho005-r3-081-zb476
0.4773,Event,ADDED,eval-conflicts-rho005-r3-081.18d4656de7843b0a,reason=Completed count=1 msg=Job completed
0.4775,Event,ADDED,eval-conflicts-rho005-r3-082-gv858.18d4656b1aaa565c,reason=Scheduled count=None msg=Successfully assigned compute/eval-conflicts-rho005-r3-082-gv858 to kind-worker5
0.4777,Event,ADDED,eval-conflicts-rho005-r3-082-gv858.18d4656b33a24cde,"reason=Pulled count=1 msg=Container image ""busybox:musl"" already present on machine"
0.478,Event,ADDED,eval-conflicts-rho005-r3-082-gv858.18d4656b34b20cc4,reason=Created count=1 msg=Created container: task
0.4782,Event,ADDED,eval-conflicts-rho005-r3-082-gv858.18d4656b369f18e0,reason=Started count=1 msg=Started container task
0.4785,Event,ADDED,eval-conflicts-rho005-r3-082.18d4656b192ea91e,reason=SuccessfulCreate count=1 msg=Created pod: eval-conflicts-rho005-r3-082-gv858
0.4788,Event,ADDED,eval-conflicts-rho005-r3-082.18d4656e6ce475fe,reason=Completed count=1 msg=Job completed
0.479,Event,ADDED,eval-conflicts-rho005-r3-083-2bv95.18d4656b55a0d034,reason=Scheduled count=None msg=Successfully assigned compute/eval-conflicts-rho005-r3-083-2bv95 to kind-worker5
0.4792,Event,ADDED,eval-conflicts-rho005-r3-083-2bv95.18d4656b6f0ca569,"reason=Pulled count=1 msg=Container image ""busybox:musl"" already present on machine"
0.4793,Event,ADDED,eval-conflicts-rho005-r3-083-2bv95.18d4656b7042a175,reason=Created count=1 msg=Created container: task
0.4797,Event,ADDED,eval-conflicts-rho005-r3-083-2bv95.18d4656b73e74d83,reason=Started count=1 msg=Started container task
0.4799,Event,ADDED,eval-conflicts-rho005-r3-083.18d4656b549ffc6c,reason=SuccessfulCreate count=1 msg=Created pod: eval-conflicts-rho005-r3-083-2bv95
0.4801,Event,ADDED,eval-conflicts-rho005-r3-083.18d4656eac92ec8a,reason=Completed count=1 msg=Job completed
0.4804,Event,ADDED,eval-conflicts-rho005-r3-084-j6v46.18d4656b923626c1,reason=Scheduled count=None msg=Successfully assigned compute/eval-conflicts-rho005-r3-084-j6v46 to kind-worker
0.4808,Event,ADDED,eval-conflicts-rho005-r3-084-j6v46.18d4656bac2af9ad,"reason=Pulled count=1 msg=Container image ""busybox:musl"" already present on machine"
0.4809,Event,ADDED,eval-conflicts-rho005-r3-084-j6v46.18d4656bad642acd,reason=Created count=1 msg=Created container: task
0.4811,Event,ADDED,eval-conflicts-rho005-r3-084-j6v46.18d4656bb1e01450,reason=Started count=1 msg=Started container task
0.4815,Event,ADDED,eval-conflicts-rho005-r3-084.18d4656b90fc76d6,reason=SuccessfulCreate count=1 msg=Created pod: eval-conflicts-rho005-r3-084-j6v46
0.4817,Event,ADDED,eval-conflicts-rho005-r3-084.18d4656e9791f750,reason=Completed count=1 msg=Job completed
0.4818,Event,ADDED,eval-conflicts-rho005-r3-085-t2cdx.18d4656bcd39557c,reason=Scheduled count=None msg=Successfully assigned compute/eval-conflicts-rho005-r3-085-t2cdx to kind-worker5
0.482,Event,ADDED,eval-conflicts-rho005-r3-085-t2cdx.18d4656be6177850,"reason=Pulled count=1 msg=Container image ""busybox:musl"" already present on machine"
0.4823,Event,ADDED,eval-conflicts-rho005-r3-085-t2cdx.18d4656be7411451,reason=Created count=1 msg=Created container: task
0.4825,Event,ADDED,eval-conflicts-rho005-r3-085-t2cdx.18d4656bec182808,reason=Started count=1 msg=Started container task
0.4827,Event,ADDED,eval-conflicts-rho005-r3-085.18d4656bcc45d8d9,reason=SuccessfulCreate count=1 msg=Created pod: eval-conflicts-rho005-r3-085-t2cdx
0.4832,Event,ADDED,eval-conflicts-rho005-r3-085.18d4656f22353eeb,reason=Completed count=1 msg=Job completed
0.4834,Event,ADDED,eval-conflicts-rho005-r3-086-9xhcb.18d4656c08e72d79,reason=Scheduled count=None msg=Successfully assigned compute/eval-conflicts-rho005-r3-086-9xhcb to kind-worker
0.4835,Event,ADDED,eval-conflicts-rho005-r3-086-9xhcb.18d4656c223ca550,"reason=Pulled count=1 msg=Container image ""busybox:musl"" already present on machine"
0.4837,Event,ADDED,eval-conflicts-rho005-r3-086-9xhcb.18d4656c23613eda,reason=Created count=1 msg=Created container: task
0.4841,Event,ADDED,eval-conflicts-rho005-r3-086-9xhcb.18d4656c25783370,reason=Started count=1 msg=Started container task
0.4843,Event,ADDED,eval-conflicts-rho005-r3-086.18d4656c07e451eb,reason=SuccessfulCreate count=1 msg=Created pod: eval-conflicts-rho005-r3-086-9xhcb
0.4845,Event,ADDED,eval-conflicts-rho005-r3-086.18d4656f0fc7d434,reason=Completed count=1 msg=Job completed
0.4847,Event,ADDED,eval-conflicts-rho005-r3-087-mbt4r.18d4656c439566e8,reason=Scheduled count=None msg=Successfully assigned compute/eval-conflicts-rho005-r3-087-mbt4r to kind-worker
0.485,Event,ADDED,eval-conflicts-rho005-r3-087-mbt4r.18d4656c5f4dc03a,"reason=Pulled count=1 msg=Container image ""busybox:musl"" already present on machine"
0.4852,Event,ADDED,eval-conflicts-rho005-r3-087-mbt4r.18d4656c6095fd26,reason=Created count=1 msg=Created container: task
0.4854,Event,ADDED,eval-conflicts-rho005-r3-087-mbt4r.18d4656c69988a86,reason=Started count=1 msg=Started container task
0.4856,Event,ADDED,eval-conflicts-rho005-r3-087.18d4656c43051fa8,reason=SuccessfulCreate count=1 msg=Created pod: eval-conflicts-rho005-r3-087-mbt4r
0.4859,Event,ADDED,eval-conflicts-rho005-r3-087.18d4656f8bdb59e6,reason=Completed count=1 msg=Job completed
0.4861,Event,ADDED,eval-conflicts-rho005-r3-088-k6pw6.18d4656c80d37909,reason=Scheduled count=None msg=Successfully assigned compute/eval-conflicts-rho005-r3-088-k6pw6 to kind-worker
0.4863,Event,ADDED,eval-conflicts-rho005-r3-088-k6pw6.18d4656c9a58f92b,"reason=Pulled count=1 msg=Container image ""busybox:musl"" already present on machine"
0.4868,Event,ADDED,eval-conflicts-rho005-r3-088-k6pw6.18d4656c9b6aa02c,reason=Created count=1 msg=Created container: task
0.4869,Event,ADDED,eval-conflicts-rho005-r3-088-k6pw6.18d4656c9d969cfd,reason=Started count=1 msg=Started container task
0.4871,Event,ADDED,eval-conflicts-rho005-r3-088.18d4656c802b1bce,reason=SuccessfulCreate count=1 msg=Created pod: eval-conflicts-rho005-r3-088-k6pw6
0.4874,Event,ADDED,eval-conflicts-rho005-r3-088.18d4656fc852a4ba,reason=Completed count=1 msg=Job completed
0.4875,Event,ADDED,eval-conflicts-rho005-r3-089-v5q4b.18d4656cbad9a360,reason=Scheduled count=None msg=Successfully assigned compute/eval-conflicts-rho005-r3-089-v5q4b to kind-worker
0.4879,Event,ADDED,eval-conflicts-rho005-r3-089-v5q4b.18d4656cd4159928,"reason=Pulled count=1 msg=Container image ""busybox:musl"" already present on machine"
0.4884,Event,ADDED,eval-conflicts-rho005-r3-089-v5q4b.18d4656cd5204594,reason=Created count=1 msg=Created container: task
0.4887,Event,ADDED,eval-conflicts-rho005-r3-089-v5q4b.18d4656cd72d323b,reason=Started count=1 msg=Started container task
0.4889,Event,ADDED,eval-conflicts-rho005-r3-089.18d4656cba35a9df,reason=SuccessfulCreate count=1 msg=Created pod: eval-conflicts-rho005-r3-089-v5q4b
0.489,Event,ADDED,eval-conflicts-rho005-r3-089.18d46570062250a6,reason=Completed count=1 msg=Job completed
0.4892,Event,ADDED,eval-conflicts-rho005-r3-090-xrpk4.18d4656cfd00a575,"reason=FailedScheduling count=None msg=0/6 nodes are available: 1 c_wall violated: 1 conflicting context pair(s) with node memory, 5 node(s) had untolerated taint(s). no new claims to deallocate, preemption: 0/6 nodes are available: 1 No preemption victims found for incoming pod, 5 Preemption is not helpful for scheduling."
0.4895,Event,ADDED,eval-conflicts-rho005-r3-090-xrpk4.18d4656cfd915ed2,"reason=FailedScheduling count=None msg=0/6 nodes are available: 1 c_wall violated: 1 conflicting context pair(s) with node memory, 5 node(s) had untolerated taint(s). no new claims to deallocate, preemption: 0/6 nodes are available: 1 No preemption victims found for incoming pod, 5 Preemption is not helpful for scheduling."
0.4896,Event,ADDED,eval-conflicts-rho005-r3-090-xrpk4.18d4656d18dfad14,reason=Scheduled count=None msg=Successfully assigned compute/eval-conflicts-rho005-r3-090-xrpk4 to kind-worker4
0.4898,Event,ADDED,eval-conflicts-rho005-r3-090-xrpk4.18d4656d3278ba7e,"reason=Pulled count=1 msg=Container image ""busybox:musl"" already present on machine"
0.4901,Event,ADDED,eval-conflicts-rho005-r3-090-xrpk4.18d4656d33a6bc57,reason=Created count=1 msg=Created container: task
0.4903,Event,ADDED,eval-conflicts-rho005-r3-090-xrpk4.18d4656d38a47f7b,reason=Started count=1 msg=Started container task
0.4904,Event,ADDED,eval-conflicts-rho005-r3-090.18d4656cfcaf3d7b,reason=SuccessfulCreate count=1 msg=Created pod: eval-conflicts-rho005-r3-090-xrpk4
0.4908,Event,ADDED,eval-conflicts-rho005-r3-090.18d465707740d9b5,reason=Completed count=1 msg=Job completed
0.491,Event,ADDED,eval-conflicts-rho005-r3-091-6br57.18d4656d31e5bb7f,reason=Scheduled count=None msg=Successfully assigned compute/eval-conflicts-rho005-r3-091-6br57 to kind-worker4
0.4912,Event,ADDED,eval-conflicts-rho005-r3-091-6br57.18d4656d4c20f3d3,"reason=Pulled count=1 msg=Container image ""busybox:musl"" already present on machine"
0.4914,Event,ADDED,eval-conflicts-rho005-r3-091-6br57.18d4656d4d3c6647,reason=Created count=1 msg=Created container: task
0.492,Event,ADDED,eval-conflicts-rho005-r3-091-6br57.18d4656d4f1cc957,reason=Started count=1 msg=Started container task
0.4921,Event,ADDED,eval-conflicts-rho005-r3-091.18d4656d31718a41,reason=SuccessfulCreate count=1 msg=Created pod: eval-conflicts-rho005-r3-091-6br57
0.4923,Event,ADDED,eval-conflicts-rho005-r3-091.18d465703c359a40,reason=Completed count=1 msg=Job completed
0.4925,Event,ADDED,eval-conflicts-rho005-r3-092-j72fl.18d4656d6d9539a4,reason=Scheduled count=None msg=Successfully assigned compute/eval-conflicts-rho005-r3-092-j72fl to kind-worker4
0.4927,Event,ADDED,eval-conflicts-rho005-r3-092-j72fl.18d4656d86ac4757,"reason=Pulled count=1 msg=Container image ""busybox:musl"" already present on machine"
0.4929,Event,ADDED,eval-conflicts-rho005-r3-092-j72fl.18d4656d87c573c2,reason=Created count=1 msg=Created container: task
0.493,Event,ADDED,eval-conflicts-rho005-r3-092-j72fl.18d4656d89ae5ff4,reason=Started count=1 msg=Started container task
0.4933,Event,ADDED,eval-conflicts-rho005-r3-092.18d4656d6d0187d9,reason=SuccessfulCreate count=1 msg=Created pod: eval-conflicts-rho005-r3-092-j72fl
0.4935,Event,ADDED,eval-conflicts-rho005-r3-092.18d46570b2cf7435,reason=Completed count=1 msg=Job completed
0.4937,Event,ADDED,eval-conflicts-rho005-r3-093-wrt5k.18d4656daa76c035,reason=Scheduled count=None msg=Successfully assigned compute/eval-conflicts-rho005-r3-093-wrt5k to kind-worker4
0.4939,Event,ADDED,eval-conflicts-rho005-r3-093-wrt5k.18d4656dc582445b,"reason=Pulled count=1 msg=Container image ""busybox:musl"" already present on machine"
0.4942,Event,ADDED,eval-conflicts-rho005-r3-093-wrt5k.18d4656dc6926578,reason=Created count=1 msg=Created container: task
0.4943,Event,ADDED,eval-conflicts-rho005-r3-093-wrt5k.18d4656dcddcfb8b,reason=Started count=1 msg=Started container task
0.4945,Event,ADDED,eval-conflicts-rho005-r3-093.18d4656da9ecfead,reason=SuccessfulCreate count=1 msg=Created pod: eval-conflicts-rho005-r3-093-wrt5k
0.4947,Event,ADDED,eval-conflicts-rho005-r3-093.18d46570ee991004,reason=Completed count=1 msg=Job completed
0.4948,Event,ADDED,eval-conflicts-rho005-r3-094-swtxx.18d4656de92da976,reason=Scheduled count=None msg=Successfully assigned compute/eval-conflicts-rho005-r3-094-swtxx to kind-worker2
0.495,Event,ADDED,eval-conflicts-rho005-r3-094-swtxx.18d4656e03115f92,"reason=Pulled count=1 msg=Container image ""busybox:musl"" already present on machine"
0.4952,Event,ADDED,eval-conflicts-rho005-r3-094-swtxx.18d4656e04334c68,reason=Created count=1 msg=Created container: task
0.4954,Event,ADDED,eval-conflicts-rho005-r3-094-swtxx.18d4656e061a8cb1,reason=Started count=1 msg=Started container task
0.4955,Event,ADDED,eval-conflicts-rho005-r3-094.18d4656de81f85f6,reason=SuccessfulCreate count=1 msg=Created pod: eval-conflicts-rho005-r3-094-swtxx
0.4957,Event,ADDED,eval-conflicts-rho005-r3-094.18d4657118fd2aa4,reason=Completed count=1 msg=Job completed
0.4958,Event,ADDED,eval-conflicts-rho005-r3-095-86nqd.18d4656e218b4e01,reason=Scheduled count=None msg=Successfully assigned compute/eval-conflicts-rho005-r3-095-86nqd to kind-worker2
0.496,Event,ADDED,eval-conflicts-rho005-r3-095-86nqd.18d4656e3f4a6232,"reason=Pulled count=1 msg=Container image ""busybox:musl"" already present on machine"
0.4962,Event,ADDED,eval-conflicts-rho005-r3-095-86nqd.18d4656e406ac8bd,reason=Created count=1 msg=Created container: task
0.4963,Event,ADDED,eval-conflicts-rho005-r3-095-86nqd.18d4656e487cd7fb,reason=Started count=1 msg=Started container task
0.4965,Event,ADDED,eval-conflicts-rho005-r3-095.18d4656e20909ae1,reason=SuccessfulCreate count=1 msg=Created pod: eval-conflicts-rho005-r3-095-86nqd
0.4967,Event,ADDED,eval-conflicts-rho005-r3-095.18d4657154b9d7d1,reason=Completed count=1 msg=Job completed
0.4968,Event,ADDED,eval-conflicts-rho005-r3-096-prn74.18d4656e5d206fb1,reason=Scheduled count=None msg=Successfully assigned compute/eval-conflicts-rho005-r3-096-prn74 to kind-worker2
0.497,Event,ADDED,eval-conflicts-rho005-r3-096-prn74.18d4656e79cef141,"reason=Pulled count=1 msg=Container image ""busybox:musl"" already present on machine"
0.4972,Event,ADDED,eval-conflicts-rho005-r3-096-prn74.18d4656e7b247fb4,reason=Created count=1 msg=Created container: task
0.4974,Event,ADDED,eval-conflicts-rho005-r3-096-prn74.18d4656e81704a5f,reason=Started count=1 msg=Started container task
0.4976,Event,ADDED,eval-conflicts-rho005-r3-096.18d4656e5c3eeb8d,reason=SuccessfulCreate count=1 msg=Created pod: eval-conflicts-rho005-r3-096-prn74
0.4977,Event,ADDED,eval-conflicts-rho005-r3-096.18d4657190d565fa,reason=Completed count=1 msg=Job completed
0.4979,Event,ADDED,eval-conflicts-rho005-r3-097-7ns6b.18d4656e993ca2cf,reason=Scheduled count=None msg=Successfully assigned compute/eval-conflicts-rho005-r3-097-7ns6b to kind-worker2
0.4981,Event,ADDED,eval-conflicts-rho005-r3-097-7ns6b.18d4656ec5eefada,"reason=Pulled count=1 msg=Container image ""busybox:musl"" already present on machine"
0.4983,Event,ADDED,eval-conflicts-rho005-r3-097-7ns6b.18d4656ec708b33c,reason=Created count=1 msg=Created container: task
0.4985,Event,ADDED,eval-conflicts-rho005-r3-097-7ns6b.18d4656ecfef9d95,reason=Started count=1 msg=Started container task
0.4987,Event,ADDED,eval-conflicts-rho005-r3-097.18d4656e985b687b,reason=SuccessfulCreate count=1 msg=Created pod: eval-conflicts-rho005-r3-097-7ns6b
0.4989,Event,ADDED,eval-conflicts-rho005-r3-097.18d465720c9c7899,reason=Completed count=1 msg=Job completed
0.4991,Event,ADDED,eval-conflicts-rho005-r3-098-8mrzk.18d4656ed3d044c5,reason=Scheduled count=None msg=Successfully assigned compute/eval-conflicts-rho005-r3-098-8mrzk to kind-worker2
0.4995,Event,ADDED,eval-conflicts-rho005-r3-098-8mrzk.18d4656ef308891f,"reason=Pulled count=1 msg=Container image ""busybox:musl"" already present on machine"
0.4996,Event,ADDED,eval-conflicts-rho005-r3-098-8mrzk.18d4656ef48c1430,reason=Created count=1 msg=Created container: task
0.4998,Event,ADDED,eval-conflicts-rho005-r3-098-8mrzk.18d4656efbddd454,reason=Started count=1 msg=Started container task
0.5,Event,ADDED,eval-conflicts-rho005-r3-098.18d4656ed2c60428,reason=SuccessfulCreate count=1 msg=Created pod: eval-conflicts-rho005-r3-098-8mrzk
0.5002,Event,ADDED,eval-conflicts-rho005-r3-098.18d465720c7e26ba,reason=Completed count=1 msg=Job completed
0.5004,Event,ADDED,eval-conflicts-rho005-r3-099-r9jxj.18d4656f102f2923,reason=Scheduled count=None msg=Successfully assigned compute/eval-conflicts-rho005-r3-099-r9jxj to kind-worker3
0.5006,Event,ADDED,eval-conflicts-rho005-r3-099-r9jxj.18d4656f2f1483f8,"reason=Pulled count=1 msg=Container image ""busybox:musl"" already present on machine"
0.5007,Event,ADDED,eval-conflicts-rho005-r3-099-r9jxj.18d4656f30584b10,reason=Created count=1 msg=Created container: task
0.5009,Event,ADDED,eval-conflicts-rho005-r3-099-r9jxj.18d4656f38ba4458,reason=Started count=1 msg=Started container task
0.5011,Event,ADDED,eval-conflicts-rho005-r3-099.18d4656f0f092c4a,reason=SuccessfulCreate count=1 msg=Created pod: eval-conflicts-rho005-r3-099-r9jxj
0.5012,Event,ADDED,eval-conflicts-rho005-r3-099.18d465724e96d9de,reason=Completed count=1 msg=Job completed
0.5014,Event,ADDED,eval-conflicts-rho005-r4-000-gs4k8.18d4657791fbec79,reason=Scheduled count=None msg=Successfully assigned compute/eval-conflicts-rho005-r4-000-gs4k8 to kind-worker2
0.5018,Event,ADDED,eval-conflicts-rho005-r4-000-gs4k8.18d46577af5de506,"reason=Pulled count=1 msg=Container image ""busybox:musl"" already present on machine"
0.502,Event,ADDED,eval-conflicts-rho005-r4-000-gs4k8.18d46577b07fd32b,reason=Created count=1 msg=Created container: task
0.5024,Event,ADDED,eval-conflicts-rho005-r4-000-gs4k8.18d46577b7db11da,reason=Started count=1 msg=Started container task
0.5028,Event,ADDED,eval-conflicts-rho005-r4-000.18d4657791146d65,reason=SuccessfulCreate count=1 msg=Created pod: eval-conflicts-rho005-r4-000-gs4k8
0.503,Event,ADDED,eval-conflicts-rho005-r4-000.18d4657ae629265c,reason=Completed count=1 msg=Job completed
0.5032,Event,ADDED,eval-conflicts-rho005-r4-001-pt7rg.18d46577cc5c8136,reason=Scheduled count=None msg=Successfully assigned compute/eval-conflicts-rho005-r4-001-pt7rg to kind-worker
0.5034,Event,ADDED,eval-conflicts-rho005-r4-001-pt7rg.18d46577e838d9c9,"reason=Pulled count=1 msg=Container image ""busybox:musl"" already present on machine"
0.5036,Event,ADDED,eval-conflicts-rho005-r4-001-pt7rg.18d46577e94bcbdd,reason=Created count=1 msg=Created container: task
0.5038,Event,ADDED,eval-conflicts-rho005-r4-001-pt7rg.18d46577f014dc32,reason=Started count=1 msg=Started container task
0.5039,Event,ADDED,eval-conflicts-rho005-r4-001.18d46577cb5cd25a,reason=SuccessfulCreate count=1 msg=Created pod: eval-conflicts-rho005-r4-001-pt7rg
0.5041,Event,ADDED,eval-conflicts-rho005-r4-001.18d4657b3219896e,reason=Completed count=1 msg=Job completed
0.5043,Event,ADDED,eval-conflicts-rho005-r4-002-gtpxk.18d465780cb7b449,reason=Scheduled count=None msg=Successfully assigned compute/eval-conflicts-rho005-r4-002-gtpxk to kind-worker5
0.5045,Event,ADDED,eval-conflicts-rho005-r4-002-gtpxk.18d46578274efdab,"reason=Pulled count=1 msg=Container image ""busybox:musl"" already present on machine"
0.5047,Event,ADDED,eval-conflicts-rho005-r4-002-gtpxk.18d46578287caabb,reason=Created count=1 msg=Created container: task
0.5048,Event,ADDED,eval-conflicts-rho005-r4-002-gtpxk.18d465782c0b3923,reason=Started count=1 msg=Started container task
0.505,Event,ADDED,eval-conflicts-rho005-r4-002.18d465780b04d4b7,reason=SuccessfulCreate count=1 msg=Created pod: eval-conflicts-rho005-r4-002-gtpxk
0.5052,Event,ADDED,eval-conflicts-rho005-r4-002.18d4657b3f7e0b51,reason=Completed count=1 msg=Job completed
0.5055,Event,ADDED,eval-conflicts-rho005-r4-003-8kbp6.18d46578437dda11,reason=Scheduled count=None msg=Successfully assigned compute/eval-conflicts-rho005-r4-003-8kbp6 to kind-worker5
0.5057,Event,ADDED,eval-conflicts-rho005-r4-003-8kbp6.18d465785d9aa992,"reason=Pulled count=1 msg=Container image ""busybox:musl"" already present on machine"
0.5059,Event,ADDED,eval-conflicts-rho005-r4-003-8kbp6.18d465785eaa014d,reason=Created count=1 msg=Created container: task
0.5061,Event,ADDED,eval-conflicts-rho005-r4-003-8kbp6.18d4657862e630a0,reason=Started count=1 msg=Started container task
0.5064,Event,ADDED,eval-conflicts-rho005-r4-003.18d46578426752b9,reason=SuccessfulCreate count=1 msg=Created pod: eval-conflicts-rho005-r4-003-8kbp6
0.5065,Event,ADDED,eval-conflicts-rho005-r4-003.18d4657b7b464635,reason=Completed count=1 msg=Job completed
0.5067,Event,ADDED,eval-conflicts-rho005-r4-004-9cstz.18d465787edff262,reason=Scheduled count=None msg=Successfully assigned compute/eval-conflicts-rho005-r4-004-9cstz to kind-worker
0.5069,Event,ADDED,eval-conflicts-rho005-r4-004-9cstz.18d465789983415a,"reason=Pulled count=1 msg=Container image ""busybox:musl"" already present on machine"
0.507,Event,ADDED,eval-conflicts-rho005-r4-004-9cstz.18d465789b1ab50c,reason=Created count=1 msg=Created container: task
0.5072,Event,ADDED,eval-conflicts-rho005-r4-004-9cstz.18d465789ea9edad,reason=Started count=1 msg=Started container task
0.5074,Event,ADDED,eval-conflicts-rho005-r4-004.18d465787dbe1a6c,reason=SuccessfulCreate count=1 msg=Created pod: eval-conflicts-rho005-r4-004-9cstz
0.5075,Event,ADDED,eval-conflicts-rho005-r4-004.18d4657ba9aa9847,reason=Completed count=1 msg=Job completed
0.5077,Event,ADDED,eval-conflicts-rho005-r4-005-xpnmq.18d46578ba77f033,reason=Scheduled count=None msg=Successfully assigned compute/eval-conflicts-rho005-r4-005-xpnmq to kind-worker2
0.5078,Event,ADDED,eval-conflicts-rho005-r4-005-xpnmq.18d46578d3d4e113,"reason=Pulled count=1 msg=Container image ""busybox:musl"" already present on machine"
0.508,Event,ADDED,eval-conflicts-rho005-r4-005-xpnmq.18d46578d4e92648,reason=Created count=1 msg=Created container: task
0.5082,Event,ADDED,eval-conflicts-rho005-r4-005-xpnmq.18d46578db24ee90,reason=Started count=1 msg=Started container task
0.5084,Event,ADDED,eval-conflicts-rho005-r4-005.18d46578b94a51e7,reason=SuccessfulCreate count=1 msg=Created pod: eval-conflicts-rho005-r4-005-xpnmq
0.5085,Event,ADDED,eval-conflicts-rho005-r4-005.18d4657c10d0c089,reason=Completed count=1 msg=Job completed
0.5087,Event,ADDED,eval-conflicts-rho005-r4-006-bw7nq.18d46578fa8cdb25,reason=Scheduled count=None msg=Successfully assigned compute/eval-conflicts-rho005-r4-006-bw7nq to kind-worker5
0.5088,Event,ADDED,eval-conflicts-rho005-r4-006-bw7nq.18d46579162f188b,"reason=Pulled count=1 msg=Container image ""busybox:musl"" already present on machine"
0.509,Event,ADDED,eval-conflicts-rho005-r4-006-bw7nq.18d465791744a6a2,reason=Created count=1 msg=Created container: task
0.5092,Event,ADDED,eval-conflicts-rho005-r4-006-bw7nq.18d465791e0423b6,reason=Started count=1 msg=Started container task
0.5095,Event,ADDED,eval-conflicts-rho005-r4-006.18d46578f7759a1e,reason=SuccessfulCreate count=1 msg=Created pod: eval-conflicts-rho005-r4-006-bw7nq
0.5097,Event,ADDED,eval-conflicts-rho005-r4-006.18d4657c2f7b63ee,reason=Completed count=1 msg=Job completed
0.5099,Event,ADDED,eval-conflicts-rho005-r4-007-9ssjl.18d4657931a778e0,reason=Scheduled count=None msg=Successfully assigned compute/eval-conflicts-rho005-r4-007-9ssjl to kind-worker2
0.5104,Event,ADDED,eval-conflicts-rho005-r4-007-9ssjl.18d465794beed4a0,"reason=Pulled count=1 msg=Container image ""busybox:musl"" already present on machine"
0.5106,Event,ADDED,eval-conflicts-rho005-r4-007-9ssjl.18d465794d2290dc,reason=Created count=1 msg=Created container: task
0.5107,Event,ADDED,eval-conflicts-rho005-r4-007-9ssjl.18d46579533df171,reason=Started count=1 msg=Started container task
0.5109,Event,ADDED,eval-conflicts-rho005-r4-007.18d4657930cf6147,reason=SuccessfulCreate count=1 msg=Created pod: eval-conflicts-rho005-r4-007-9ssjl
0.5113,Event,ADDED,eval-conflicts-rho005-r4-007.18d4657c87d1498e,reason=Completed count=1 msg=Job completed
0.5114,Event,ADDED,eval-conflicts-rho005-r4-008-2psmb.18d465796d9c6854,reason=Scheduled count=None msg=Successfully assigned compute/eval-conflicts-rho005-r4-008-2psmb to kind-worker4
0.5116,Event,ADDED,eval-conflicts-rho005-r4-008-2psmb.18d465798bec7cc0,"reason=Pulled count=1 msg=Container image ""busybox:musl"" already present on machine"
0.5118,Event,ADDED,eval-conflicts-rho005-r4-008-2psmb.18d465798d113c94,reason=Created count=1 msg=Created container: task
0.5122,Event,ADDED,eval-conflicts-rho005-r4-008-2psmb.18d4657995842a05,reason=Started count=1 msg=Started container task
0.5124,Event,ADDED,eval-conflicts-rho005-r4-008.18d465796cb71625,reason=SuccessfulCreate count=1 msg=Created pod: eval-conflicts-rho005-r4-008-2psmb
0.5127,Event,ADDED,eval-conflicts-rho005-r4-008.18d4657cd588aa45,reason=Completed count=1 msg=Job completed
0.513,Event,ADDED,eval-conflicts-rho005-r4-009-rdcnl.18d46579a849a15c,reason=Scheduled count=None msg=Successfully assigned compute/eval-conflicts-rho005-r4-009-rdcnl to kind-worker5
0.5132,Event,ADDED,eval-conflicts-rho005-r4-009-rdcnl.18d46579c290cf3c,"reason=Pulled count=1 msg=Container image ""busybox:musl"" already present on machine"
0.5134,Event,ADDED,eval-conflicts-rho005-r4-009-rdcnl.18d46579c3b99ff8,reason=Created count=1 msg=Created container: task
0.5135,Event,ADDED,eval-conflicts-rho005-r4-009-rdcnl.18d46579c69ce52e,reason=Started count=1 msg=Started container task
0.5139,Event,ADDED,eval-conflicts-rho005-r4-009.18d46579a7725824,reason=SuccessfulCreate count=1 msg=Created pod: eval-conflicts-rho005-r4-009-rdcnl
0.5141,Event,ADDED,eval-conflicts-rho005-r4-009.18d4657ce1fabd48,reason=Completed count=1 msg=Job completed
0.5142,Event,ADDED,eval-conflicts-rho005-r4-010-2jd5h.18d46579e4ec1619,reason=Scheduled count=None msg=Successfully assigned compute/eval-conflicts-rho005-r4-010-2jd5h to kind-worker4
0.5145,Event,ADDED,eval-conflicts-rho005-r4-010-2jd5h.18d4657a039ee5f8,"reason=Pulled count=1 msg=Container image ""busybox:musl"" already present on machine"
0.5146,Event,ADDED,eval-conflicts-rho005-r4-010-2jd5h.18d4657a05f199b0,reason=Created count=1 msg=Created container: task
0.5148,Event,ADDED,eval-conflicts-rho005-r4-010-2jd5h.18d4657a0d0344bc,reason=Started count=1 msg=Started container task
0.515,Event,ADDED,eval-conflicts-rho005-r4-010.18d46579e3f3b339,reason=SuccessfulCreate count=1 msg=Created pod: eval-conflicts-rho005-r4-010-2jd5h
0.5152,Event,ADDED,eval-conflicts-rho005-r4-010.18d4657d4d3dd4dc,reason=Completed count=1 msg=Job completed
0.5153,Event,ADDED,eval-conflicts-rho005-r4-011-rb9kt.18d4657a20651591,reason=Scheduled count=None msg=Successfully assigned compute/eval-conflicts-rho005-r4-011-rb9kt to kind-worker5
0.5155,Event,ADDED,eval-conflicts-rho005-r4-011-rb9kt.18d4657a3b5070f8,"reason=Pulled count=1 msg=Container image ""busybox:musl"" already present on machine"
0.5157,Event,ADDED,eval-conflicts-rho005-r4-011-rb9kt.18d4657a3ca6785c,reason=Created count=1 msg=Created container: task
0.5158,Event,ADDED,eval-conflicts-rho005-r4-011-rb9kt.18d4657a3f04f2aa,reason=Started count=1 msg=Started container task
0.516,Event,ADDED,eval-conflicts-rho005-r4-011.18d4657a1f91587d,reason=SuccessfulCreate count=1 msg=Created pod: eval-conflicts-rho005-r4-011-rb9kt
0.5162,Event,ADDED,eval-conflicts-rho005-r4-011.18d4657d59961e11,reason=Completed count=1 msg=Job completed
0.5165,Event,ADDED,eval-conflicts-rho005-r4-012-9x4zf.18d4657a5bff63c7,reason=Scheduled count=None msg=Successfully assigned compute/eval-conflicts-rho005-r4-012-9x4zf to kind-worker4
0.5166,Event,ADDED,eval-conflicts-rho005-r4-012-9x4zf.18d4657a755a16eb,"reason=Pulled count=1 msg=Container image ""busybox:musl"" already present on machine"
0.5168,Event,ADDED,eval-conflicts-rho005-r4-012-9x4zf.18d4657a76cd9a83,reason=Created count=1 msg=Created container: task
0.517,Event,ADDED,eval-conflicts-rho005-r4-012-9x4zf.18d4657a78eb2635,reason=Started count=1 msg=Started container task
0.5171,Event,ADDED,eval-conflicts-rho005-r4-012.18d4657a5b15f9ff,reason=SuccessfulCreate count=1 msg=Created pod: eval-conflicts-rho005-r4-012-9x4zf
0.5173,Event,ADDED,eval-conflicts-rho005-r4-012.18d4657d88fd9a5d,reason=Completed count=1 msg=Job completed
0.5174,Event,ADDED,eval-conflicts-rho005-r4-013-gzsb9.18d4657a97266a6a,reason=Scheduled count=None msg=Successfully assigned compute/eval-conflicts-rho005-r4-013-gzsb9 to kind-worker3
0.5176,Event,ADDED,eval-conflicts-rho005-r4-013-gzsb9.18d4657ab10d729a,"reason=Pulled count=1 msg=Container image ""busybox:musl"" already present on machine"
0.5178,Event,ADDED,eval-conflicts-rho005-r4-013-gzsb9.18d4657ab261442c,reason=Created count=1 msg=Created container: task
0.5181,Event,ADDED,eval-conflicts-rho005-r4-013-gzsb9.18d4657ab44fefa4,reason=Started count=1 msg=Started container task
0.5182,Event,ADDED,eval-conflicts-rho005-r4-013.18d4657a963daab1,reason=SuccessfulCreate count=1 msg=Created pod: eval-conflicts-rho005-r4-013-gzsb9
0.5185,Event,ADDED,eval-conflicts-rho005-r4-013.18d4657df9781372,reason=Completed count=1 msg=Job completed
0.5187,Event,ADDED,eval-conflicts-rho005-r4-014-5lgxm.18d4657ad285a60b,reason=Scheduled count=None msg=Successfully assigned compute/eval-conflicts-rho005-r4-014-5lgxm to kind-worker3
0.5189,Event,ADDED,eval-conflicts-rho005-r4-014-5lgxm.18d4657aefbfaff9,"reason=Pulled count=1 msg=Container image ""busybox:musl"" already present on machine"
0.519,Event,ADDED,eval-conflicts-rho005-r4-014-5lgxm.18d4657af0d5f51a,reason=Created count=1 msg=Created container: task
0.5193,Event,ADDED,eval-conflicts-rho005-r4-014-5lgxm.18d4657af4724c4b,reason=Started count=1 msg=Started container task
0.5194,Event,ADDED,eval-conflicts-rho005-r4-014.18d4657ad1d4044b,reason=SuccessfulCreate count=1 msg=Created pod: eval-conflicts-rho005-r4-014-5lgxm
0.5196,Event,ADDED,eval-conflicts-rho005-r4-014.18d4657e35769bcf,reason=Completed count=1 msg=Job completed
0.5198,Event,ADDED,eval-conflicts-rho005-r4-015-qmmb4.18d4657b0ebf53c7,reason=Scheduled count=None msg=Successfully assigned compute/eval-conflicts-rho005-r4-015-qmmb4 to kind-worker4
0.5199,Event,ADDED,eval-conflicts-rho005-r4-015-qmmb4.18d4657b27b954f1,"reason=Pulled count=1 msg=Container image ""busybox:musl"" already present on machine"
0.5201,Event,ADDED,eval-conflicts-rho005-r4-015-qmmb4.18d4657b28e31f01,reason=Created count=1 msg=Created container: task
0.5203,Event,ADDED,eval-conflicts-rho005-r4-015-qmmb4.18d4657b370cd156,reason=Started count=1 msg=Started container task
0.5205,Event,ADDED,eval-conflicts-rho005-r4-015.18d4657b0dbc13bc,reason=SuccessfulCreate count=1 msg=Created pod: eval-conflicts-rho005-r4-015-qmmb4
0.5207,Event,ADDED,eval-conflicts-rho005-r4-015.18d4657e7806aff5,reason=Completed count=1 msg=Job completed
0.5208,Event,ADDED,eval-conflicts-rho005-r4-016-wd9sb.18d4657b4ab11b57,reason=Scheduled count=None msg=Successfully assigned compute/eval-conflicts-rho005-r4-016-wd9sb to kind-worker3
0.521,Event,ADDED,eval-conflicts-rho005-r4-016-wd9sb.18d4657b66c57911,"reason=Pulled count=1 msg=Container image ""busybox:musl"" already present on machine"
0.5213,Event,ADDED,eval-conflicts-rho005-r4-016-wd9sb.18d4657b67e1af3f,reason=Created count=1 msg=Created container: task
0.5215,Event,ADDED,eval-conflicts-rho005-r4-016-wd9sb.18d4657b6b83d171,reason=Started count=1 msg=Started container task
0.5217,Event,ADDED,eval-conflicts-rho005-r4-016.18d4657b49f573e1,reason=SuccessfulCreate count=1 msg=Created pod: eval-conflicts-rho005-r4-016-wd9sb
0.522,Event,ADDED,eval-conflicts-rho005-r4-016.18d4657ead6e70c8,reason=Completed count=1 msg=Job completed
0.5221,Event,ADDED,eval-conflicts-rho005-r4-017-bltf2.18d4657b852b6045,reason=Scheduled count=None msg=Successfully assigned compute/eval-conflicts-rho005-r4-017-bltf2 to kind-worker
0.5223,Event,ADDED,eval-conflicts-rho005-r4-017-bltf2.18d4657b9de8e98b,"reason=Pulled count=1 msg=Container image ""busybox:musl"" already present on machine"
0.5225,Event,ADDED,eval-conflicts-rho005-r4-017-bltf2.18d4657b9f027785,reason=Created count=1 msg=Created container: task
0.5227,Event,ADDED,eval-conflicts-rho005-r4-017-bltf2.18d4657ba2d4d877,reason=Started count=1 msg=Started container task
0.5229,Event,ADDED,eval-conflicts-rho005-r4-017.18d4657b846fc22f,reason=SuccessfulCreate count=1 msg=Created pod: eval-conflicts-rho005-r4-017-bltf2
0.5231,Event,ADDED,eval-conflicts-rho005-r4-017.18d4657eb44549af,reason=Completed count=1 msg=Job completed
0.5233,Event,ADDED,eval-conflicts-rho005-r4-018-hwcc2.18d4657bc1706454,reason=Scheduled count=None msg=Successfully assigned compute/eval-conflicts-rho005-r4-018-hwcc2 to kind-worker
0.5236,Event,ADDED,eval-conflicts-rho005-r4-018-hwcc2.18d4657bdb788305,"reason=Pulled count=1 msg=Container image ""busybox:musl"" already present on machine"
0.5238,Event,ADDED,eval-conflicts-rho005-r4-018-hwcc2.18d4657bdc8c431e,reason=Created count=1 msg=Created container: task
0.5239,Event,ADDED,eval-conflicts-rho005-r4-018-hwcc2.18d4657be066fc60,reason=Started count=1 msg=Started container task
0.5242,Event,ADDED,eval-conflicts-rho005-r4-018.18d4657bc08cf7b0,reason=SuccessfulCreate count=1 msg=Created pod: eval-conflicts-rho005-r4-018-hwcc2
0.5244,Event,ADDED,eval-conflicts-rho005-r4-018.18d4657ef0fcb154,reason=Completed count=1 msg=Job completed
0.5245,Event,ADDED,eval-conflicts-rho005-r4-019-4pwfx.18d4657bfcb1bb6e,reason=Scheduled count=None msg=Successfully assigned compute/eval-conflicts-rho005-r4-019-4pwfx to kind-worker
0.5247,Event,ADDED,eval-conflicts-rho005-r4-019-4pwfx.18d4657c16d9554f,"reason=Pulled count=1 msg=Container image ""busybox:musl"" already present on machine"
0.5249,Event,ADDED,eval-conflicts-rho005-r4-019-4pwfx.18d4657c1803bda6,reason=Created count=1 msg=Created container: task
0.5251,Event,ADDED,eval-conflicts-rho005-r4-019-4pwfx.18d4657c1c7bbd07,reason=Started count=1 msg=Started container task
0.5253,Event,ADDED,eval-conflicts-rho005-r4-019.18d4657bfbd8c91c,reason=SuccessfulCreate count=1 msg=Created pod: eval-conflicts-rho005-r4-019-4pwfx
0.5255,Event,ADDED,eval-conflicts-rho005-r4-019.18d4657f2cdf5da5,reason=Completed count=1 msg=Job completed
0.5256,Event,ADDED,eval-conflicts-rho005-r4-020-7b9hm.18d4657c38784275,reason=Scheduled count=None msg=Successfully assigned compute/eval-conflicts-rho005-r4-020-7b9hm to kind-worker
0.5259,Event,ADDED,eval-conflicts-rho005-r4-020-7b9hm.18d4657c5178de32,"reason=Pulled count=1 msg=Container image ""busybox:musl"" already present on machine"
0.5261,Event,ADDED,eval-conflicts-rho005-r4-020-7b9hm.18d4657c529088b9,reason=Created count=1 msg=Created container: task
0.5262,Event,ADDED,eval-conflicts-rho005-r4-020-7b9hm.18d4657c54a38198,reason=Started count=1 msg=Started container task
0.5264,Event,ADDED,eval-conflicts-rho005-r4-020.18d4657c374c0a5d,reason=SuccessfulCreate count=1 msg=Created pod: eval-conflicts-rho005-r4-020-7b9hm
0.5267,Event,ADDED,eval-conflicts-rho005-r4-020.18d4657f68690f03,reason=Completed count=1 msg=Job completed
0.527,Event,ADDED,eval-conflicts-rho005-r4-021-s54j9.18d4657c749efd71,reason=Scheduled count=None msg=Successfully assigned compute/eval-conflicts-rho005-r4-021-s54j9 to kind-worker
0.5271,Event,ADDED,eval-conflicts-rho005-r4-021-s54j9.18d4657c8fa5e47c,"reason=Pulled count=1 msg=Container image ""busybox:musl"" already present on machine"
0.5273,Event,ADDED,eval-conflicts-rho005-r4-021-s54j9.18d4657c90cc305f,reason=Created count=1 msg=Created container: task
0.5277,Event,ADDED,eval-conflicts-rho005-r4-021-s54j9.18d4657c94c201bd,reason=Started count=1 msg=Started container task
0.5279,Event,ADDED,eval-conflicts-rho005-r4-021.18d4657c73c6ca3f,reason=SuccessfulCreate count=1 msg=Created pod: eval-conflicts-rho005-r4-021-s54j9
0.5281,Event,ADDED,eval-conflicts-rho005-r4-021.18d4657fa5306fad,reason=Completed count=1 msg=Job completed
0.5284,Event,ADDED,eval-conflicts-rho005-r4-022-7sfjh.18d4657cb0b4920b,reason=Scheduled count=None msg=Successfully assigned compute/eval-conflicts-rho005-r4-022-7sfjh to kind-worker
0.5286,Event,ADDED,eval-conflicts-rho005-r4-022-7sfjh.18d4657ccb24e1b5,"reason=Pulled count=1 msg=Container image ""busybox:musl"" already present on machine"
0.5288,Event,ADDED,eval-conflicts-rho005-r4-022-7sfjh.18d4657ccc647320,reason=Created count=1 msg=Created container: task
0.529,Event,ADDED,eval-conflicts-rho005-r4-022-7sfjh.18d4657ccea15082,reason=Started count=1 msg=Started container task
0.5294,Event,ADDED,eval-conflicts-rho005-r4-022.18d4657cafc9b446,reason=SuccessfulCreate count=1 msg=Created pod: eval-conflicts-rho005-r4-022-7sfjh
0.5296,Event,ADDED,eval-conflicts-rho005-r4-022.18d4657fe03e56d7,reason=Completed count=1 msg=Job completed
0.5298,Event,ADDED,eval-conflicts-rho005-r4-023-x7fcz.18d4657ceb232883,reason=Scheduled count=None msg=Successfully assigned compute/eval-conflicts-rho005-r4-023-x7fcz to kind-worker
0.5301,Event,ADDED,eval-conflicts-rho005-r4-023-x7fcz.18d4657d0409bcb7,"reason=Pulled count=1 msg=Container image ""busybox:musl"" already present on machine"
0.5303,Event,ADDED,eval-conflicts-rho005-r4-023-x7fcz.18d4657d05152c93,reason=Created count=1 msg=Created container: task
0.5305,Event,ADDED,eval-conflicts-rho005-r4-023-x7fcz.18d4657d06f5894b,reason=Started count=1 msg=Started container task
0.5307,Event,ADDED,eval-conflicts-rho005-r4-023.18d4657cea8dab30,reason=SuccessfulCreate count=1 msg=Created pod: eval-conflicts-rho005-r4-023-x7fcz
0.531,Event,ADDED,eval-conflicts-rho005-r4-023.18d465801c310541,reason=Completed count=1 msg=Job completed
0.5312,Event,ADDED,eval-conflicts-rho005-r4-024-lwqx8.18d4657d26373a3d,reason=Scheduled count=None msg=Successfully assigned compute/eval-conflicts-rho005-r4-024-lwqx8 to kind-worker
0.5314,Event,ADDED,eval-conflicts-rho005-r4-024-lwqx8.18d4657d41734f86,"reason=Pulled count=1 msg=Container image ""busybox:musl"" already present on machine"
0.5316,Event,ADDED,eval-conflicts-rho005-r4-024-lwqx8.18d4657d4289ba9e,reason=Created count=1 msg=Created container: task
0.5319,Event,ADDED,eval-conflicts-rho005-r4-024-lwqx8.18d4657d465a6b09,reason=Started count=1 msg=Started container task
0.532,Event,ADDED,eval-conflicts-rho005-r4-024.18d4657d25b373a1,reason=SuccessfulCreate count=1 msg=Created pod: eval-conflicts-rho005-r4-024-lwqx8
0.5322,Event,ADDED,eval-conflicts-rho005-r4-024.18d465805824a46d,reason=Completed count=1 msg=Job completed
0.5326,Event,ADDED,eval-conflicts-rho005-r4-025-mp8ww.18d4657d61dca02d,reason=Scheduled count=None msg=Successfully assigned compute/eval-conflicts-rho005-r4-025-mp8ww to kind-worker
0.5328,Event,ADDED,eval-conflicts-rho005-r4-025-mp8ww.18d4657d7b112517,"reason=Pulled count=1 msg=Container image ""busybox:musl"" already present on machine"
0.5329,Event,ADDED,eval-conflicts-rho005-r4-025-mp8ww.18d4657d7c1aee8a,reason=Created count=1 msg=Created container: task
0.5331,Event,ADDED,eval-conflicts-rho005-r4-025-mp8ww.18d4657d8143fd69,reason=Started count=1 msg=Started container task
0.5335,Event,ADDED,eval-conflicts-rho005-r4-025.18d4657d614645fe,reason=SuccessfulCreate count=1 msg=Created pod: eval-conflicts-rho005-r4-025-mp8ww
0.5337,Event,ADDED,eval-conflicts-rho005-r4-025.18d4658093bc5c79,reason=Completed count=1 msg=Job completed
0.5339,Event,ADDED,eval-conflicts-rho005-r4-026-958nl.18d4657d9dbfca61,reason=Scheduled count=None msg=Successfully assigned compute/eval-conflicts-rho005-r4-026-958nl to kind-worker
0.5341,Event,ADDED,eval-conflicts-rho005-r4-026-958nl.18d4657db68564b1,"reason=Pulled count=1 msg=Container image ""busybox:musl"" already present on machine"
0.5344,Event,ADDED,eval-conflicts-rho005-r4-026-958nl.18d4657db793db50,reason=Created count=1 msg=Created container: task
0.5346,Event,ADDED,eval-conflicts-rho005-r4-026-958nl.18d4657dbc089359,reason=Started count=1 msg=Started container task
0.5348,Event,ADDED,eval-conflicts-rho005-r4-026.18d4657d9d3a3be8,reason=SuccessfulCreate count=1 msg=Created pod: eval-conflicts-rho005-r4-026-958nl
0.5353,Event,ADDED,eval-conflicts-rho005-r4-026.18d46580cf9ab944,reason=Completed count=1 msg=Job completed
0.5355,Event,ADDED,eval-conflicts-rho005-r4-027-z8lmk.18d4657dd87e2bbb,"reason=FailedScheduling count=None msg=0/6 nodes are available: 6 node(s) had untolerated taint(s). no new claims to deallocate, preemption: 0/6 nodes are available: 6 Preemption is not helpful for scheduling."
0.5356,Event,ADDED,eval-conflicts-rho005-r4-027-z8lmk.18d4657e36376284,reason=Scheduled count=None msg=Successfully assigned compute/eval-conflicts-rho005-r4-027-z8lmk to kind-worker2
0.5358,Event,ADDED,eval-conflicts-rho005-r4-027-z8lmk.18d4657e50abed50,"reason=Pulled count=1 msg=Container image ""busybox:musl"" already present on machine"
0.5362,Event,ADDED,eval-conflicts-rho005-r4-027-z8lmk.18d4657e524c3ee1,reason=Created count=1 msg=Created container: task
0.5364,Event,ADDED,eval-conflicts-rho005-r4-027-z8lmk.18d4657e5723559c,reason=Started count=1 msg=Started container task
0.5366,Event,ADDED,eval-conflicts-rho005-r4-027.18d4657dd873b7e5,reason=SuccessfulCreate count=1 msg=Created pod: eval-conflicts-rho005-r4-027-z8lmk
0.5368,Event,ADDED,eval-conflicts-rho005-r4-027.18d465816ea83896,reason=Completed count=1 msg=Job completed
0.537,Event,ADDED,eval-conflicts-rho005-r4-028-krbtp.18d4657e1464d2e4,"reason=FailedScheduling count=None msg=0/6 nodes are available: 6 node(s) had untolerated taint(s). no new claims to deallocate, preemption: 0/6 nodes are available: 6 Preemption is not helpful for scheduling."
0.5371,Event,ADDED,eval-conflicts-rho005-r4-028-krbtp.18d4657e364e2c31,reason=Scheduled count=None msg=Successfully assigned compute/eval-conflicts-rho005-r4-028-krbtp to kind-worker2
0.5373,Event,ADDED,eval-conflicts-rho005-r4-028-krbtp.18d4657e50ff4c40,"reason=Pulled count=1 msg=Container image ""busybox:musl"" already present on machine"
0.5378,Event,ADDED,eval-conflicts-rho005-r4-028-krbtp.18d4657e52b7d0d9,reason=Created count=1 msg=Created container: task
0.5381,Event,ADDED,eval-conflicts-rho005-r4-028-krbtp.18d4657e57235592,reason=Started count=1 msg=Started container task
0.5383,Event,ADDED,eval-conflicts-rho005-r4-028.18d4657e1456a98b,reason=SuccessfulCreate count=1 msg=Created pod: eval-conflicts-rho005-r4-028-krbtp
0.5385,Event,ADDED,eval-conflicts-rho005-r4-028.18d465816ea8d2b4,reason=Completed count=1 msg=Job completed
0.5388,Event,ADDED,eval-conflicts-rho005-r4-029-hkzvr.18d4657e50925586,reason=Scheduled count=None msg=Successfully assigned compute/eval-conflicts-rho005-r4-029-hkzvr to kind-worker2
0.539,Event,ADDED,eval-conflicts-rho005-r4-029-hkzvr.18d4657e69ec0e9e,"reason=Pulled count=1 msg=Container image ""busybox:musl"" already present on machine"
0.5393,Event,ADDED,eval-conflicts-rho005-r4-029-hkzvr.18d4657e6afc2908,reason=Created count=1 msg=Created container: task
0.5396,Event,ADDED,eval-conflicts-rho005-r4-029-hkzvr.18d4657e6e4eb937,reason=Started count=1 msg=Started container task
0.5398,Event,ADDED,eval-conflicts-rho005-r4-029.18d4657e4fe4c387,reason=SuccessfulCreate count=1 msg=Created pod: eval-conflicts-rho005-r4-029-hkzvr
0.54,Event,ADDED,eval-conflicts-rho005-r4-029.18d46581aab176c7,reason=Completed count=1 msg=Job completed
0.5402,Event,ADDED,eval-conflicts-rho005-r4-030-gbxwl.18d4657e8be38346,reason=Scheduled count=None msg=Successfully assigned compute/eval-conflicts-rho005-r4-030-gbxwl to kind-worker2
0.5406,Event,ADDED,eval-conflicts-rho005-r4-030-gbxwl.18d4657ea576e9c7,"reason=Pulled count=1 msg=Container image ""busybox:musl"" already present on machine"
0.5407,Event,ADDED,eval-conflicts-rho005-r4-030-gbxwl.18d4657ea6a983c8,reason=Created count=1 msg=Created container: task
0.5409,Event,ADDED,eval-conflicts-rho005-r4-030-gbxwl.18d4657ea89e2840,reason=Started count=1 msg=Started container task
0.5413,Event,ADDED,eval-conflicts-rho005-r4-030.18d4657e8b40395a,reason=SuccessfulCreate count=1 msg=Created pod: eval-conflicts-rho005-r4-030-gbxwl
0.5415,Event,ADDED,eval-conflicts-rho005-r4-030.18d46581e6813154,reason=Completed count=1 msg=Job completed
0.5417,Event,ADDED,eval-conflicts-rho005-r4-031-md2kt.18d4657ec7f6d7b8,reason=Scheduled count=None msg=Successfully assigned compute/eval-conflicts-rho005-r4-031-md2kt to kind-worker2
0.5419,Event,ADDED,eval-conflicts-rho005-r4-031-md2kt.18d4657ee23296f9,"reason=Pulled count=1 msg=Container image ""busybox:musl"" already present on machine"
0.5423,Event,ADDED,eval-conflicts-rho005-r4-031-md2kt.18d4657ee352203b,reason=Created count=1 msg=Created container: task
0.5425,Event,ADDED,eval-conflicts-rho005-r4-031-md2kt.18d4657ee54d9fed,reason=Started count=1 msg=Started container task
0.5426,Event,ADDED,eval-conflicts-rho005-r4-031.18d4657ec77228d1,reason=SuccessfulCreate count=1 msg=Created pod: eval-conflicts-rho005-r4-031-md2kt
0.5428,Event,ADDED,eval-conflicts-rho005-r4-031.18d46582232008d8,reason=Completed count=1 msg=Job completed
0.5431,Event,ADDED,eval-conflicts-rho005-r4-032-mgq7p.18d4657f045c0ea8,reason=Scheduled count=None msg=Successfully assigned compute/eval-conflicts-rho005-r4-032-mgq7p to kind-worker5
0.5433,Event,ADDED,eval-conflicts-rho005-r4-032-mgq7p.18d4657f1feb2c47,"reason=Pulled count=1 msg=Container image ""busybox:musl"" already present on machine"
0.5435,Event,ADDED,eval-conflicts-rho005-r4-032-mgq7p.18d4657f20f87cc8,reason=Created count=1 msg=Created container: task
0.5438,Event,ADDED,eval-conflicts-rho005-r4-032-mgq7p.18d4657f25fb8262,reason=Started count=1 msg=Started container task
0.544,Event,ADDED,eval-conflicts-rho005-r4-032.18d4657f0349d424,reason=SuccessfulCreate count=1 msg=Created pod: eval-conflicts-rho005-r4-032-mgq7p
0.5441,Event,ADDED,eval-conflicts-rho005-r4-032.18d4658240daa689,reason=Completed count=1 msg=Job completed
0.5443,Event,ADDED,eval-conflicts-rho005-r4-033-5s4r2.18d4657f3fa8e086,reason=Scheduled count=None msg=Successfully assigned compute/eval-conflicts-rho005-r4-033-5s4r2 to kind-worker5
0.5446,Event,ADDED,eval-conflicts-rho005-r4-033-5s4r2.18d4657f59f77dfe,"reason=Pulled count=1 msg=Container image ""busybox:musl"" already present on machine"
0.5448,Event,ADDED,eval-conflicts-rho005-r4-033-5s4r2.18d4657f5b1caf32,reason=Created count=1 msg=Created container: task
0.545,Event,ADDED,eval-conflicts-rho005-r4-033-5s4r2.18d4657f60f8f828,reason=Started count=1 msg=Started container task
0.5453,Event,ADDED,eval-conflicts-rho005-r4-033.18d4657f3e9a82c3,reason=SuccessfulCreate count=1 msg=Created pod: eval-conflicts-rho005-r4-033-5s4r2
0.5456,Event,ADDED,eval-conflicts-rho005-r4-033.18d465827cd4a7d3,reason=Completed count=1 msg=Job completed
0.5458,Event,ADDED,eval-conflicts-rho005-r4-034-7jplf.18d4657f7af787a8,reason=Scheduled count=None msg=Successfully assigned compute/eval-conflicts-rho005-r4-034-7jplf to kind-worker5
0.546,Event,ADDED,eval-conflicts-rho005-r4-034-7jplf.18d4657f97d2c7aa,"reason=Pulled count=1 msg=Container image ""busybox:musl"" already present on machine"
0.5462,Event,ADDED,eval-conflicts-rho005-r4-034-7jplf.18d4657f9920ce41,reason=Created count=1 msg=Created container: task
0.5464,Event,ADDED,eval-conflicts-rho005-r4-034-7jplf.18d4657f9d61e49b,reason=Started count=1 msg=Started container task
0.5466,Event,ADDED,eval-conflicts-rho005-r4-034.18d4657f79fda153,reason=SuccessfulCreate count=1 msg=Created pod: eval-conflicts-rho005-r4-034-7jplf
0.5467,Event,ADDED,eval-conflicts-rho005-r4-034.18d46582bab75b44,reason=Completed count=1 msg=Job completed
0.5469,Event,ADDED,eval-conflicts-rho005-r4-035-m9x8x.18d4657fb6da8c21,reason=Scheduled count=None msg=Successfully assigned compute/eval-conflicts-rho005-r4-035-m9x8x to kind-worker5
0.5471,Event,ADDED,eval-conflicts-rho005-r4-035-m9x8x.18d4657fcfa38a9d,"reason=Pulled count=1 msg=Container image ""busybox:musl"" already present on machine"
0.5472,Event,ADDED,eval-conflicts-rho005-r4-035-m9x8x.18d4657fd0bd4e85,reason=Created count=1 msg=Created container: task
0.5474,Event,ADDED,eval-conflicts-rho005-r4-035-m9x8x.18d4657fd2b37f59,reason=Started count=1 msg=Started container task
0.5476,Event,ADDED,eval-conflicts-rho005-r4-035.18d4657fb603a554,reason=SuccessfulCreate count=1 msg=Created pod: eval-conflicts-rho005-r4-035-m9x8x
0.5477,Event,ADDED,eval-conflicts-rho005-r4-035.18d46582f6c9cbcf,reason=Completed count=1 msg=Job completed
0.5479,Event,ADDED,eval-conflicts-rho005-r4-036-lq2dm.18d4657ff26ed8a2,reason=Scheduled count=None msg=Successfully assigned compute/eval-conflicts-rho005-r4-036-lq2dm to kind-worker5
0.5482,Event,ADDED,eval-conflicts-rho005-r4-036-lq2dm.18d465800e883b6a,"reason=Pulled count=1 msg=Container image ""busybox:musl"" already present on machine"
0.5483,Event,ADDED,eval-conflicts-rho005-r4-036-lq2dm.18d465800faceb6f,reason=Created count=1 msg=Created container: task
0.5487,Event,ADDED,eval-conflicts-rho005-r4-036-lq2dm.18d46580166a53a5,reason=Started count=1 msg=Started container task
0.5489,Event,ADDED,eval-conflicts-rho005-r4-036.18d4657ff1707863,reason=SuccessfulCreate count=1 msg=Created pod: eval-conflicts-rho005-r4-036-lq2dm
0.5492,Event,ADDED,eval-conflicts-rho005-r4-036.18d46583356f0314,reason=Completed count=1 msg=Job completed
0.5494,Event,ADDED,eval-conflicts-rho005-r4-037-lrbsd.18d465802e4da36b,reason=Scheduled count=None msg=Successfully assigned compute/eval-conflicts-rho005-r4-037-lrbsd to kind-worker4
0.5496,Event,ADDED,eval-conflicts-rho005-r4-037-lrbsd.18d4658048401e21,"reason=Pulled count=1 msg=Container image ""busybox:musl"" already present on machine"
0.55,Event,ADDED,eval-conflicts-rho005-r4-037-lrbsd.18d465804959ed0d,reason=Created count=1 msg=Created container: task
0.5503,Event,ADDED,eval-conflicts-rho005-r4-037-lrbsd.18d465804b5a220f,reason=Started count=1 msg=Started container task
0.5505,Event,ADDED,eval-conflicts-rho005-r4-037.18d465802d5b3969,reason=SuccessfulCreate count=1 msg=Created pod: eval-conflicts-rho005-r4-037-lrbsd
0.5507,Event,ADDED,eval-conflicts-rho005-r4-037.18d465835e8099cb,reason=Completed count=1 msg=Job completed
0.551,Event,ADDED,eval-conflicts-rho005-r4-038-mrq4x.18d4658069810da2,reason=Scheduled count=None msg=Successfully assigned compute/eval-conflicts-rho005-r4-038-mrq4x to kind-worker4
0.5512,Event,ADDED,eval-conflicts-rho005-r4-038-mrq4x.18d4658085725628,"reason=Pulled count=1 msg=Container image ""busybox:musl"" already present on machine"
0.5514,Event,ADDED,eval-conflicts-rho005-r4-038-mrq4x.18d465808693abf0,reason=Created count=1 msg=Created container: task
0.5516,Event,ADDED,eval-conflicts-rho005-r4-038-mrq4x.18d465808afeff8e,reason=Started count=1 msg=Started container task
0.5518,Event,ADDED,eval-conflicts-rho005-r4-038.18d46580684c9996,reason=SuccessfulCreate count=1 msg=Created pod: eval-conflicts-rho005-r4-038-mrq4x
0.5522,Event,ADDED,eval-conflicts-rho005-r4-038.18d465839e472062,reason=Completed count=1 msg=Job completed
0.5525,Event,ADDED,eval-conflicts-rho005-r4-039-xq86l.18d46580a4ee3e1d,reason=Scheduled count=None msg=Successfully assigned compute/eval-conflicts-rho005-r4-039-xq86l to kind-worker4
0.5528,Event,ADDED,eval-conflicts-rho005-r4-039-xq86l.18d46580bf382c70,"reason=Pulled count=1 msg=Container image ""busybox:musl"" already present on machine"
0.553,Event,ADDED,eval-conflicts-rho005-r4-039-xq86l.18d46580c05af5ca,reason=Created count=1 msg=Created container: task
0.5531,Event,ADDED,eval-conflicts-rho005-r4-039-xq86l.18d46580c4d6d6c9,reason=Started count=1 msg=Started container task
0.5533,Event,ADDED,eval-conflicts-rho005-r4-039.18d46580a3e5b891,reason=SuccessfulCreate count=1 msg=Created pod: eval-conflicts-rho005-r4-039-xq86l
0.5535,Event,ADDED,eval-conflicts-rho005-r4-039.18d46583da16eb88,reason=Completed count=1 msg=Job completed
0.5537,Event,ADDED,eval-conflicts-rho005-r4-040-v4zgj.18d46580e08dec87,reason=Scheduled count=None msg=Successfully assigned compute/eval-conflicts-rho005-r4-040-v4zgj to kind-worker4
0.554,Event,ADDED,eval-conflicts-rho005-r4-040-v4zgj.18d46580fed38113,"reason=Pulled count=1 msg=Container image ""busybox:musl"" already present on machine"
0.5544,Event,ADDED,eval-conflicts-rho005-r4-040-v4zgj.18d465810004a328,reason=Created count=1 msg=Created container: task
0.5545,Event,ADDED,eval-conflicts-rho005-r4-040-v4zgj.18d4658102fc3e37,reason=Started count=1 msg=Started container task
0.5547,Event,ADDED,eval-conflicts-rho005-r4-040.18d46580dfa28108,reason=SuccessfulCreate count=1 msg=Created pod: eval-conflicts-rho005-r4-040-v4zgj
0.5549,Event,ADDED,eval-conflicts-rho005-r4-040.18d465841652bb4d,reason=Completed count=1 msg=Job completed
0.5552,Event,ADDED,eval-conflicts-rho005-r4-041-hx5bb.18d465811bf2f833,reason=Scheduled count=None msg=Successfully assigned compute/eval-conflicts-rho005-r4-041-hx5bb to kind-worker5
0.5554,Event,ADDED,eval-conflicts-rho005-r4-041-hx5bb.18d46581355b76dc,"reason=Pulled count=1 msg=Container image ""busybox:musl"" already present on machine"
0.5556,Event,ADDED,eval-conflicts-rho005-r4-041-hx5bb.18d46581366e7538,reason=Created count=1 msg=Created container: task
0.5558,Event,ADDED,eval-conflicts-rho005-r4-041-hx5bb.18d465813adf8ec9,reason=Started count=1 msg=Started container task
0.556,Event,ADDED,eval-conflicts-rho005-r4-041.18d465811b05dcdc,reason=SuccessfulCreate count=1 msg=Created pod: eval-conflicts-rho005-r4-041-hx5bb
0.5561,Event,ADDED,eval-conflicts-rho005-r4-041.18d465845ec46b87,reason=Completed count=1 msg=Job completed
0.5563,Event,ADDED,eval-conflicts-rho005-r4-042-cs8gn.18d4658157c37feb,reason=Scheduled count=None msg=Successfully assigned compute/eval-conflicts-rho005-r4-042-cs8gn to kind-worker3
0.5613,Event,ADDED,eval-conflicts-rho005-r4-042-cs8gn.18d4658176068c48,"reason=Pulled count=1 msg=Container image ""busybox:musl"" already present on machine"
0.5615,Event,ADDED,eval-conflicts-rho005-r4-042-cs8gn.18d46581771d61ac,reason=Created count=1 msg=Created container: task
0.5616,Event,ADDED,eval-conflicts-rho005-r4-042-cs8gn.18d465817b9e5e55,reason=Started count=1 msg=Started container task
0.5619,Event,ADDED,eval-conflicts-rho005-r4-042.18d46581570aec0e,reason=SuccessfulCreate count=1 msg=Created pod: eval-conflicts-rho005-r4-042-cs8gn
0.5624,Event,ADDED,eval-conflicts-rho005-r4-042.18d46584c19a07b4,reason=Completed count=1 msg=Job completed
0.5625,Event,ADDED,eval-conflicts-rho005-r4-043-lphpn.18d46581930068a7,reason=Scheduled count=None msg=Successfully assigned compute/eval-conflicts-rho005-r4-043-lphpn to kind-worker3
0.5627,Event,ADDED,eval-conflicts-rho005-r4-043-lphpn.18d46581af6b7787,"reason=Pulled count=1 msg=Container image ""busybox:musl"" already present on machine"
0.5629,Event,ADDED,eval-conflicts-rho005-r4-043-lphpn.18d46581b07adf8c,reason=Created count=1 msg=Created container: task
0.5632,Event,ADDED,eval-conflicts-rho005-r4-043-lphpn.18d46581b4358bba,reason=Started count=1 msg=Started container task
0.5634,Event,ADDED,eval-conflicts-rho005-r4-043.18d4658192278015,reason=SuccessfulCreate count=1 msg=Created pod: eval-conflicts-rho005-r4-043-lphpn
0.5636,Event,ADDED,eval-conflicts-rho005-r4-043.18d465850416212c,reason=Completed count=1 msg=Job completed
0.5638,Event,ADDED,eval-conflicts-rho005-r4-044-skwsl.18d46581cf46620f,reason=Scheduled count=None msg=Successfully assigned compute/eval-conflicts-rho005-r4-044-skwsl to kind-worker3
0.564,Event,ADDED,eval-conflicts-rho005-r4-044-skwsl.18d46581ec5342f6,"reason=Pulled count=1 msg=Container image ""busybox:musl"" already present on machine"
0.5642,Event,ADDED,eval-conflicts-rho005-r4-044-skwsl.18d46581ed5ee772,reason=Created count=1 msg=Created container: task
0.5644,Event,ADDED,eval-conflicts-rho005-r4-044-skwsl.18d46581f219a008,reason=Started count=1 msg=Started container task
0.5646,Event,ADDED,eval-conflicts-rho005-r4-044.18d46581cdbba052,reason=SuccessfulCreate count=1 msg=Created pod: eval-conflicts-rho005-r4-044-skwsl
0.5647,Event,ADDED,eval-conflicts-rho005-r4-044.18d465854140067f,reason=Completed count=1 msg=Job completed
0.5649,Event,ADDED,eval-conflicts-rho005-r4-045-zjnp7.18d465820a912928,reason=Scheduled count=None msg=Successfully assigned compute/eval-conflicts-rho005-r4-045-zjnp7 to kind-worker3
0.5652,Event,ADDED,eval-conflicts-rho005-r4-045-zjnp7.18d4658223ce4569,"reason=Pulled count=1 msg=Container image ""busybox:musl"" already present on machine"
0.5654,Event,ADDED,eval-conflicts-rho005-r4-045-zjnp7.18d465822517855e,reason=Created count=1 msg=Created container: task
0.5656,Event,ADDED,eval-conflicts-rho005-r4-045-zjnp7.18d46582272079fa,reason=Started count=1 msg=Started container task
0.5659,Event,ADDED,eval-conflicts-rho005-r4-045.18d4658209ebe07f,reason=SuccessfulCreate count=1 msg=Created pod: eval-conflicts-rho005-r4-045-zjnp7
0.5665,Event,ADDED,eval-conflicts-rho005-r4-045.18d46585410903bb,reason=Completed count=1 msg=Job completed
0.5668,Event,ADDED,eval-conflicts-rho005-r4-046-qt7sj.18d4658245bb01d1,reason=Scheduled count=None msg=Successfully assigned compute/eval-conflicts-rho005-r4-046-qt7sj to kind-worker4
0.567,Event,ADDED,eval-conflicts-rho005-r4-046-qt7sj.18d465826399ccc6,"reason=Pulled count=1 msg=Container image ""busybox:musl"" already present on machine"
0.5672,Event,ADDED,eval-conflicts-rho005-r4-046-qt7sj.18d4658264b5359b,reason=Created count=1 msg=Created container: task
0.5675,Event,ADDED,eval-conflicts-rho005-r4-046-qt7sj.18d4658269c34e69,reason=Started count=1 msg=Started container task
0.5677,Event,ADDED,eval-conflicts-rho005-r4-046.18d4658244ea3912,reason=SuccessfulCreate count=1 msg=Created pod: eval-conflicts-rho005-r4-046-qt7sj
0.5679,Event,ADDED,eval-conflicts-rho005-r4-046.18d46585bc40abed,reason=Completed count=1 msg=Job completed
0.5682,Event,ADDED,eval-conflicts-rho005-r4-047-zpqp6.18d46582813863cf,reason=Scheduled count=None msg=Successfully assigned compute/eval-conflicts-rho005-r4-047-zpqp6 to kind-worker
0.5684,Event,ADDED,eval-conflicts-rho005-r4-047-zpqp6.18d465829c26161b,"reason=Pulled count=1 msg=Container image ""busybox:musl"" already present on machine"
0.5685,Event,ADDED,eval-conflicts-rho005-r4-047-zpqp6.18d465829d5a4808,reason=Created count=1 msg=Created container: task
0.5687,Event,ADDED,eval-conflicts-rho005-r4-047-zpqp6.18d46582a166fccf,reason=Started count=1 msg=Started container task
0.5689,Event,ADDED,eval-conflicts-rho005-r4-047.18d465828070f033,reason=SuccessfulCreate count=1 msg=Created pod: eval-conflicts-rho005-r4-047-zpqp6
0.5691,Event,ADDED,eval-conflicts-rho005-r4-047.18d46585bc219ebb,reason=Completed count=1 msg=Job completed
0.5693,Event,ADDED,eval-conflicts-rho005-r4-048-j26bb.18d46582bd9fb983,reason=Scheduled count=None msg=Successfully assigned compute/eval-conflicts-rho005-r4-048-j26bb to kind-worker
0.5694,Event,ADDED,eval-conflicts-rho005-r4-048-j26bb.18d46582d698cf4f,"reason=Pulled count=1 msg=Container image ""busybox:musl"" already present on machine"
0.5697,Event,ADDED,eval-conflicts-rho005-r4-048-j26bb.18d46582d7ac252c,reason=Created count=1 msg=Created container: task
0.5699,Event,ADDED,eval-conflicts-rho005-r4-048-j26bb.18d46582db4dbf05,reason=Started count=1 msg=Started container task
0.5701,Event,ADDED,eval-conflicts-rho005-r4-048.18d46582bc7b25be,reason=SuccessfulCreate count=1 msg=Created pod: eval-conflicts-rho005-r4-048-j26bb
0.5703,Event,ADDED,eval-conflicts-rho005-r4-048.18d46585f884e352,reason=Completed count=1 msg=Job completed
0.5705,Event,ADDED,eval-conflicts-rho005-r4-049-xmmzc.18d46582f9d333b2,reason=Scheduled count=None msg=Successfully assigned compute/eval-conflicts-rho005-r4-049-xmmzc to kind-worker2
0.5707,Event,ADDED,eval-conflicts-rho005-r4-049-xmmzc.18d46583180c745c,"reason=Pulled count=1 msg=Container image ""busybox:musl"" already present on machine"
0.5708,Event,ADDED,eval-conflicts-rho005-r4-049-xmmzc.18d46583193539b5,reason=Created count=1 msg=Created container: task
0.571,Event,ADDED,eval-conflicts-rho005-r4-049-xmmzc.18d465831b28eba6,reason=Started count=1 msg=Started container task
0.5712,Event,ADDED,eval-conflicts-rho005-r4-049.18d46582f8dfaf3f,reason=SuccessfulCreate count=1 msg=Created pod: eval-conflicts-rho005-r4-049-xmmzc
0.5714,Event,ADDED,eval-conflicts-rho005-r4-049.18d4658656b53ab2,reason=Completed count=1 msg=Job completed
0.5715,Event,ADDED,eval-conflicts-rho005-r4-050-4jvmx.18d4658337c1db6f,reason=Scheduled count=None msg=Successfully assigned compute/eval-conflicts-rho005-r4-050-4jvmx to kind-worker2
0.5717,Event,ADDED,eval-conflicts-rho005-r4-050-4jvmx.18d4658351a38f92,"reason=Pulled count=1 msg=Container image ""busybox:musl"" already present on machine"
0.5719,Event,ADDED,eval-conflicts-rho005-r4-050-4jvmx.18d4658352b2cd4b,reason=Created count=1 msg=Created container: task
0.572,Event,ADDED,eval-conflicts-rho005-r4-050-4jvmx.18d4658354988538,reason=Started count=1 msg=Started container task
0.5722,Event,ADDED,eval-conflicts-rho005-r4-050.18d4658336927f28,reason=SuccessfulCreate count=1 msg=Created pod: eval-conflicts-rho005-r4-050-4jvmx
0.5724,Event,ADDED,eval-conflicts-rho005-r4-050.18d465869262cf2a,reason=Completed count=1 msg=Job completed
0.5725,Event,ADDED,eval-conflicts-rho005-r4-051-7nt4d.18d465837795765d,reason=Scheduled count=None msg=Successfully assigned compute/eval-conflicts-rho005-r4-051-7nt4d to kind-worker
0.5727,Event,ADDED,eval-conflicts-rho005-r4-051-7nt4d.18d46583917ab1ce,"reason=Pulled count=1 msg=Container image ""busybox:musl"" already present on machine"
0.5728,Event,ADDED,eval-conflicts-rho005-r4-051-7nt4d.18d46583929b3c21,reason=Created count=1 msg=Created container: task
0.573,Event,ADDED,eval-conflicts-rho005-r4-051-7nt4d.18d46583949fb2c9,reason=Started count=1 msg=Started container task
0.5732,Event,ADDED,eval-conflicts-rho005-r4-051.18d465836ed8eefd,reason=SuccessfulCreate count=1 msg=Created pod: eval-conflicts-rho005-r4-051-7nt4d
0.5733,Event,ADDED,eval-conflicts-rho005-r4-051.18d46586a64cbdec,reason=Completed count=1 msg=Job completed
0.5735,Event,ADDED,eval-conflicts-rho005-r4-052-tlccg.18d46583ac9a989d,reason=Scheduled count=None msg=Successfully assigned compute/eval-conflicts-rho005-r4-052-tlccg to kind-worker
0.5737,Event,ADDED,eval-conflicts-rho005-r4-052-tlccg.18d46583c5b50159,"reason=Pulled count=1 msg=Container image ""busybox:musl"" already present on machine"
0.574,Event,ADDED,eval-conflicts-rho005-r4-052-tlccg.18d46583c6c19d4a,reason=Created count=1 msg=Created container: task
0.5743,Event,ADDED,eval-conflicts-rho005-r4-052-tlccg.18d46583d052ec2f,reason=Started count=1 msg=Started container task
0.5744,Event,ADDED,eval-conflicts-rho005-r4-052.18d46583abba4e04,reason=SuccessfulCreate count=1 msg=Created pod: eval-conflicts-rho005-r4-052-tlccg
0.5746,Event,ADDED,eval-conflicts-rho005-r4-052.18d46586e207ee43,reason=Completed count=1 msg=Job completed
0.5747,Event,ADDED,eval-conflicts-rho005-r4-053-mzcrb.18d46583e9109deb,reason=Scheduled count=None msg=Successfully assigned compute/eval-conflicts-rho005-r4-053-mzcrb to kind-worker2
0.575,Event,ADDED,eval-conflicts-rho005-r4-053-mzcrb.18d4658405ccd4ee,"reason=Pulled count=1 msg=Container image ""busybox:musl"" already present on machine"
0.5751,Event,ADDED,eval-conflicts-rho005-r4-053-mzcrb.18d4658406efee73,reason=Created count=1 msg=Created container: task
0.5753,Event,ADDED,eval-conflicts-rho005-r4-053-mzcrb.18d465840f93a1c8,reason=Started count=1 msg=Started container task
0.5755,Event,ADDED,eval-conflicts-rho005-r4-053.18d46583e81df051,reason=SuccessfulCreate count=1 msg=Created pod: eval-conflicts-rho005-r4-053-mzcrb
0.5756,Event,ADDED,eval-conflicts-rho005-r4-053.18d465874590344d,reason=Completed count=1 msg=Job completed
0.5758,Event,ADDED,eval-conflicts-rho005-r4-054-wjj7p.18d4658422e3c637,reason=Scheduled count=None msg=Successfully assigned compute/eval-conflicts-rho005-r4-054-wjj7p to kind-worker
0.576,Event,ADDED,eval-conflicts-rho005-r4-054-wjj7p.18d465843e6237f3,"reason=Pulled count=1 msg=Container image ""busybox:musl"" already present on machine"
0.5761,Event,ADDED,eval-conflicts-rho005-r4-054-wjj7p.18d465843f809bf6,reason=Created count=1 msg=Created container: task
0.5763,Event,ADDED,eval-conflicts-rho005-r4-054-wjj7p.18d465844446a8ff,reason=Started count=1 msg=Started container task
0.5765,Event,ADDED,eval-conflicts-rho005-r4-054.18d46584220bf5eb,reason=SuccessfulCreate count=1 msg=Created pod: eval-conflicts-rho005-r4-054-wjj7p
0.5766,Event,ADDED,eval-conflicts-rho005-r4-054.18d46587595e9b2c,reason=Completed count=1 msg=Job completed
0.5768,Event,ADDED,eval-conflicts-rho005-r4-055-glqsc.18d465845e3956e0,reason=Scheduled count=None msg=Successfully assigned compute/eval-conflicts-rho005-r4-055-glqsc to kind-worker2
0.577,Event,ADDED,eval-conflicts-rho005-r4-055-glqsc.18d465847a42a022,"reason=Pulled count=1 msg=Container image ""busybox:musl"" already present on machine"
0.5771,Event,ADDED,eval-conflicts-rho005-r4-055-glqsc.18d465847b605764,reason=Created count=1 msg=Created container: task
0.5776,Event,ADDED,eval-conflicts-rho005-r4-055-glqsc.18d4658482022414,reason=Started count=1 msg=Started container task
0.5778,Event,ADDED,eval-conflicts-rho005-r4-055.18d465845d7152e3,reason=SuccessfulCreate count=1 msg=Created pod: eval-conflicts-rho005-r4-055-glqsc
0.578,Event,ADDED,eval-conflicts-rho005-r4-055.18d46587bd0b81f5,reason=Completed count=1 msg=Job completed
0.5781,Event,ADDED,eval-conflicts-rho005-r4-056-8txdt.18d465849a01f031,reason=Scheduled count=None msg=Successfully assigned compute/eval-conflicts-rho005-r4-056-8txdt to kind-worker2
0.5784,Event,ADDED,eval-conflicts-rho005-r4-056-8txdt.18d46584b51fd00e,"reason=Pulled count=1 msg=Container image ""busybox:musl"" already present on machine"
0.5785,Event,ADDED,eval-conflicts-rho005-r4-056-8txdt.18d46584b64df4e1,reason=Created count=1 msg=Created container: task
0.5787,Event,ADDED,eval-conflicts-rho005-r4-056-8txdt.18d46584b9d56a54,reason=Started count=1 msg=Started container task
0.5789,Event,ADDED,eval-conflicts-rho005-r4-056.18d465849922cdf2,reason=SuccessfulCreate count=1 msg=Created pod: eval-conflicts-rho005-r4-056-8txdt
0.579,Event,ADDED,eval-conflicts-rho005-r4-056.18d46587f8e8e557,reason=Completed count=1 msg=Job completed
0.5792,Event,ADDED,eval-conflicts-rho005-r4-057-scgzh.18d46584da44230c,reason=Scheduled count=None msg=Successfully assigned compute/eval-conflicts-rho005-r4-057-scgzh to kind-worker2
0.5794,Event,ADDED,eval-conflicts-rho005-r4-057-scgzh.18d46584f849cd6b,"reason=Pulled count=1 msg=Container image ""busybox:musl"" already present on machine"
0.5795,Event,ADDED,eval-conflicts-rho005-r4-057-scgzh.18d46584f9703f0d,reason=Created count=1 msg=Created container: task
0.5797,Event,ADDED,eval-conflicts-rho005-r4-057-scgzh.18d465850325d5e1,reason=Started count=1 msg=Started container task
0.5799,Event,ADDED,eval-conflicts-rho005-r4-057.18d46584d9b38176,reason=SuccessfulCreate count=1 msg=Created pod: eval-conflicts-rho005-r4-057-scgzh
0.58,Event,ADDED,eval-conflicts-rho005-r4-057.18d4658834d1add6,reason=Completed count=1 msg=Job completed
0.5802,Event,ADDED,eval-conflicts-rho005-r4-058-drtg9.18d465851415b5c5,reason=Scheduled count=None msg=Successfully assigned compute/eval-conflicts-rho005-r4-058-drtg9 to kind-worker2
0.5804,Event,ADDED,eval-conflicts-rho005-r4-058-drtg9.18d465852d08a0c0,"reason=Pulled count=1 msg=Container image ""busybox:musl"" already present on machine"
0.5805,Event,ADDED,eval-conflicts-rho005-r4-058-drtg9.18d465852e264db7,reason=Created count=1 msg=Created container: task
0.5807,Event,ADDED,eval-conflicts-rho005-r4-058-drtg9.18d46585375bd540,reason=Started count=1 msg=Started container task
0.5809,Event,ADDED,eval-conflicts-rho005-r4-058.18d465851381e0ea,reason=SuccessfulCreate count=1 msg=Created pod: eval-conflicts-rho005-r4-058-drtg9
0.581,Event,ADDED,eval-conflicts-rho005-r4-058.18d4658870684c3a,reason=Completed count=1 msg=Job completed
0.5812,Event,ADDED,eval-conflicts-rho005-r4-059-zgvtz.18d465854e458509,"reason=FailedScheduling count=None msg=0/6 nodes are available: 6 node(s) had untolerated taint(s). no new claims to deallocate, preemption: 0/6 nodes are available: 6 Preemption is not helpful for scheduling."
0.5813,Event,ADDED,eval-conflicts-rho005-r4-059-zgvtz.18d46585fcfd50fa,reason=Scheduled count=None msg=Successfully assigned compute/eval-conflicts-rho005-r4-059-zgvtz to kind-worker3
0.5815,Event,ADDED,eval-conflicts-rho005-r4-059-zgvtz.18d4658617a3cd71,"reason=Pulled count=1 msg=Container image ""busybox:musl"" already present on machine"
0.5817,Event,ADDED,eval-conflicts-rho005-r4-059-zgvtz.18d4658619824d0c,reason=Created count=1 msg=Created container: task
0.5819,Event,ADDED,eval-conflicts-rho005-r4-059-zgvtz.18d46586290a559d,reason=Started count=1 msg=Started container task
0.5821,Event,ADDED,eval-conflicts-rho005-r4-059.18d465854e3d8fd4,reason=SuccessfulCreate count=1 msg=Created pod: eval-conflicts-rho005-r4-059-zgvtz
0.5823,Event,ADDED,eval-conflicts-rho005-r4-059.18d465896aa9e0dd,reason=Completed count=1 msg=Job completed
0.5824,Event,ADDED,eval-conflicts-rho005-r4-060-gtc9j.18d4658588a7c4f1,"reason=FailedScheduling count=None msg=0/6 nodes are available: 6 node(s) had untolerated taint(s). no new claims to deallocate, preemption: 0/6 nodes are available: 6 Preemption is not helpful for scheduling."
0.5827,Event,ADDED,eval-conflicts-rho005-r4-060-gtc9j.18d46585fd6516f3,reason=Scheduled count=None msg=Successfully assigned compute/eval-conflicts-rho005-r4-060-gtc9j to kind-worker3
0.5829,Event,ADDED,eval-conflicts-rho005-r4-060-gtc9j.18d46586183e30f6,"reason=Pulled count=1 msg=Container image ""busybox:musl"" already present on machine"
0.583,Event,ADDED,eval-conflicts-rho005-r4-060-gtc9j.18d465861a7bfd75,reason=Created count=1 msg=Created container: task
0.5832,Event,ADDED,eval-conflicts-rho005-r4-060-gtc9j.18d46586290cb928,reason=Started count=1 msg=Started container task
0.5834,Event,ADDED,eval-conflicts-rho005-r4-060.18d46585889d7e9f,reason=SuccessfulCreate count=1 msg=Created pod: eval-conflicts-rho005-r4-060-gtc9j
0.5836,Event,ADDED,eval-conflicts-rho005-r4-060.18d465896a134636,reason=Completed count=1 msg=Job completed
0.5838,Event,ADDED,eval-conflicts-rho005-r4-061-jx5zr.18d46585c39f29a6,"reason=FailedScheduling count=None msg=0/6 nodes are available: 6 node(s) had untolerated taint(s). no new claims to deallocate, preemption: 0/6 nodes are available: 6 Preemption is not helpful for scheduling."
0.584,Event,ADDED,eval-conflicts-rho005-r4-061-jx5zr.18d46585fd928458,reason=Scheduled count=None msg=Successfully assigned compute/eval-conflicts-rho005-r4-061-jx5zr to kind-worker3
0.5841,Event,ADDED,eval-conflicts-rho005-r4-061-jx5zr.18d4658618a1ebd0,"reason=Pulled count=1 msg=Container image ""busybox:musl"" already present on machine"
0.5843,Event,ADDED,eval-conflicts-rho005-r4-061-jx5zr.18d465861b09243c,reason=Created count=1 msg=Created container: task
0.5845,Event,ADDED,eval-conflicts-rho005-r4-061-jx5zr.18d465861e961ea9,reason=Started count=1 msg=Started container task
0.5847,Event,ADDED,eval-conflicts-rho005-r4-061.18d46585c398ab4c,reason=SuccessfulCreate count=1 msg=Created pod: eval-conflicts-rho005-r4-061-jx5zr
0.5849,Event,ADDED,eval-conflicts-rho005-r4-061.18d465892e5fd24b,reason=Completed count=1 msg=Job completed
0.585,Event,ADDED,eval-conflicts-rho005-r4-062-97qjg.18d465860171cea8,reason=Scheduled count=None msg=Successfully assigned compute/eval-conflicts-rho005-r4-062-97qjg to kind-worker3
0.5852,Event,ADDED,eval-conflicts-rho005-r4-062-97qjg.18d4658623719a92,"reason=Pulled count=1 msg=Container image ""busybox:musl"" already present on machine"
0.5854,Event,ADDED,eval-conflicts-rho005-r4-062-97qjg.18d4658624c57723,reason=Created count=1 msg=Created container: task
0.5856,Event,ADDED,eval-conflicts-rho005-r4-062-97qjg.18d4658629d858f3,reason=Started count=1 msg=Started container task
0.5857,Event,ADDED,eval-conflicts-rho005-r4-062.18d46585ff8158d8,reason=SuccessfulCreate count=1 msg=Created pod: eval-conflicts-rho005-r4-062-97qjg
0.5859,Event,ADDED,eval-conflicts-rho005-r4-062.18d465896a385e29,reason=Completed count=1 msg=Job completed
0.5861,Event,ADDED,eval-conflicts-rho005-r4-063-22j4r.18d465863cfd7bce,reason=Scheduled count=None msg=Successfully assigned compute/eval-conflicts-rho005-r4-063-22j4r to kind-worker5
0.5862,Event,ADDED,eval-conflicts-rho005-r4-063-22j4r.18d4658656586ae9,"reason=Pulled count=1 msg=Container image ""busybox:musl"" already present on machine"
0.5864,Event,ADDED,eval-conflicts-rho005-r4-063-22j4r.18d4658657a2d565,reason=Created count=1 msg=Created container: task
0.5865,Event,ADDED,eval-conflicts-rho005-r4-063-22j4r.18d4658659a9f9c2,reason=Started count=1 msg=Started container task
0.5867,Event,ADDED,eval-conflicts-rho005-r4-063.18d465863bf30d07,reason=SuccessfulCreate count=1 msg=Created pod: eval-conflicts-rho005-r4-063-22j4r
0.5869,Event,ADDED,eval-conflicts-rho005-r4-063.18d465897daf0335,reason=Completed count=1 msg=Job completed
0.587,Event,ADDED,eval-conflicts-rho005-r4-064-nhf8n.18d465867afa3d37,reason=Scheduled count=None msg=Successfully assigned compute/eval-conflicts-rho005-r4-064-nhf8n to kind-worker5
0.5872,Event,ADDED,eval-conflicts-rho005-r4-064-nhf8n.18d4658693e8c788,"reason=Pulled count=1 msg=Container image ""busybox:musl"" already present on machine"
0.5873,Event,ADDED,eval-conflicts-rho005-r4-064-nhf8n.18d4658694f59fe5,reason=Created count=1 msg=Created container: task
0.5875,Event,ADDED,eval-conflicts-rho005-r4-064-nhf8n.18d46586970b5fe8,reason=Started count=1 msg=Started container task
0.5879,Event,ADDED,eval-conflicts-rho005-r4-064.18d4658679e4f000,reason=SuccessfulCreate count=1 msg=Created pod: eval-conflicts-rho005-r4-064-nhf8n
0.5883,Event,ADDED,eval-conflicts-rho005-r4-064.18d465897e6a1d8e,reason=Completed count=1 msg=Job completed
0.5886,Event,ADDED,eval-conflicts-rho005-r4-065-plzck.18d46586b22952bd,reason=Scheduled count=None msg=Successfully assigned compute/eval-conflicts-rho005-r4-065-plzck to kind-worker5
0.5889,Event,ADDED,eval-conflicts-rho005-r4-065-plzck.18d46586cb1ee976,"reason=Pulled count=1 msg=Container image ""busybox:musl"" already present on machine"
0.5891,Event,ADDED,eval-conflicts-rho005-r4-065-plzck.18d46586cc3ea337,reason=Created count=1 msg=Created container: task
0.5893,Event,ADDED,eval-conflicts-rho005-r4-065-plzck.18d46586ce52b582,reason=Started count=1 msg=Started container task
0.5895,Event,ADDED,eval-conflicts-rho005-r4-065.18d46586b15db434,reason=SuccessfulCreate count=1 msg=Created pod: eval-conflicts-rho005-r4-065-plzck
0.5898,Event,ADDED,eval-conflicts-rho005-r4-065.18d46589f5745857,reason=Completed count=1 msg=Job completed
0.59,Event,ADDED,eval-conflicts-rho005-r4-066-6gfw6.18d46586ee489750,reason=Scheduled count=None msg=Successfully assigned compute/eval-conflicts-rho005-r4-066-6gfw6 to kind-worker5
0.5902,Event,ADDED,eval-conflicts-rho005-r4-066-6gfw6.18d46587106cb2a0,"reason=Pulled count=1 msg=Container image ""busybox:musl"" already present on machine"
0.5904,Event,ADDED,eval-conflicts-rho005-r4-066-6gfw6.18d4658711a0455b,reason=Created count=1 msg=Created container: task
0.5906,Event,ADDED,eval-conflicts-rho005-r4-066-6gfw6.18d465871611e985,reason=Started count=1 msg=Started container task
0.5907,Event,ADDED,eval-conflicts-rho005-r4-066.18d46586ed6b1e47,reason=SuccessfulCreate count=1 msg=Created pod: eval-conflicts-rho005-r4-066-6gfw6
0.5909,Event,ADDED,eval-conflicts-rho005-r4-066.18d4658a312ecfd9,reason=Completed count=1 msg=Job completed
0.5913,Event,ADDED,eval-conflicts-rho005-r4-067-6tdj2.18d465872a3fb08d,reason=Scheduled count=None msg=Successfully assigned compute/eval-conflicts-rho005-r4-067-6tdj2 to kind-worker5
0.5915,Event,ADDED,eval-conflicts-rho005-r4-067-6tdj2.18d46587432adbed,"reason=Pulled count=1 msg=Container image ""busybox:musl"" already present on machine"
0.5917,Event,ADDED,eval-conflicts-rho005-r4-067-6tdj2.18d465874468860a,reason=Created count=1 msg=Created container: task
0.592,Event,ADDED,eval-conflicts-rho005-r4-067-6tdj2.18d465874c6c3f3e,reason=Started count=1 msg=Started container task
0.5923,Event,ADDED,eval-conflicts-rho005-r4-067.18d46587296a7c7e,reason=SuccessfulCreate count=1 msg=Created pod: eval-conflicts-rho005-r4-067-6tdj2
0.5925,Event,ADDED,eval-conflicts-rho005-r4-067.18d4658a6d2c07a1,reason=Completed count=1 msg=Job completed
0.5927,Event,ADDED,eval-conflicts-rho005-r4-068-lf2nm.18d465876542cf71,reason=Scheduled count=None msg=Successfully assigned compute/eval-conflicts-rho005-r4-068-lf2nm to kind-worker
0.5929,Event,ADDED,eval-conflicts-rho005-r4-068-lf2nm.18d465877ee55e1e,"reason=Pulled count=1 msg=Container image ""busybox:musl"" already present on machine"
0.5932,Event,ADDED,eval-conflicts-rho005-r4-068-lf2nm.18d4658780196554,reason=Created count=1 msg=Created container: task
0.5934,Event,ADDED,eval-conflicts-rho005-r4-068-lf2nm.18d4658789b3e596,reason=Started count=1 msg=Started container task
0.5936,Event,ADDED,eval-conflicts-rho005-r4-068.18d4658764625656,reason=SuccessfulCreate count=1 msg=Created pod: eval-conflicts-rho005-r4-068-lf2nm
0.5939,Event,ADDED,eval-conflicts-rho005-r4-068.18d4658a9e282b0c,reason=Completed count=1 msg=Job completed
0.594,Event,ADDED,eval-conflicts-rho005-r4-069-zksgf.18d46587a1678cc7,reason=Scheduled count=None msg=Successfully assigned compute/eval-conflicts-rho005-r4-069-zksgf to kind-worker
0.5943,Event,ADDED,eval-conflicts-rho005-r4-069-zksgf.18d46587bacfd7ac,"reason=Pulled count=1 msg=Container image ""busybox:musl"" already present on machine"
0.5945,Event,ADDED,eval-conflicts-rho005-r4-069-zksgf.18d46587bbf6a7b0,reason=Created count=1 msg=Created container: task
0.5947,Event,ADDED,eval-conflicts-rho005-r4-069-zksgf.18d46587c250b552,reason=Started count=1 msg=Started container task
0.5949,Event,ADDED,eval-conflicts-rho005-r4-069.18d46587a0279303,reason=SuccessfulCreate count=1 msg=Created pod: eval-conflicts-rho005-r4-069-zksgf
0.5951,Event,ADDED,eval-conflicts-rho005-r4-069.18d4658ad9f31e39,reason=Completed count=1 msg=Job completed
0.5954,Event,ADDED,eval-conflicts-rho005-r4-070-cf8s2.18d46587dce5c2e1,reason=Scheduled count=None msg=Successfully assigned compute/eval-conflicts-rho005-r4-070-cf8s2 to kind-worker4
0.5957,Event,ADDED,eval-conflicts-rho005-r4-070-cf8s2.18d46587f6438f3f,"reason=Pulled count=1 msg=Container image ""busybox:musl"" already present on machine"
0.5959,Event,ADDED,eval-conflicts-rho005-r4-070-cf8s2.18d46587f7657fb4,reason=Created count=1 msg=Created container: task
0.5961,Event,ADDED,eval-conflicts-rho005-r4-070-cf8s2.18d46587fc3e064a,reason=Started count=1 msg=Started container task
0.5963,Event,ADDED,eval-conflicts-rho005-r4-070.18d46587dbd4f11b,reason=SuccessfulCreate count=1 msg=Created pod: eval-conflicts-rho005-r4-070-cf8s2
0.5965,Event,ADDED,eval-conflicts-rho005-r4-070.18d4658b12812620,reason=Completed count=1 msg=Job completed
0.5967,Event,ADDED,eval-conflicts-rho005-r4-071-bbtkd.18d4658818c2a855,reason=Scheduled count=None msg=Successfully assigned compute/eval-conflicts-rho005-r4-071-bbtkd to kind-worker
0.5969,Event,ADDED,eval-conflicts-rho005-r4-071-bbtkd.18d46588335c4c1a,"reason=Pulled count=1 msg=Container image ""busybox:musl"" already present on machine"
0.5972,Event,ADDED,eval-conflicts-rho005-r4-071-bbtkd.18d4658834b3988f,reason=Created count=1 msg=Created container: task
0.5974,Event,ADDED,eval-conflicts-rho005-r4-071-bbtkd.18d465883a4f6f19,reason=Started count=1 msg=Started container task
0.5976,Event,ADDED,eval-conflicts-rho005-r4-071.18d465881745ae49,reason=SuccessfulCreate count=1 msg=Created pod: eval-conflicts-rho005-r4-071-bbtkd
0.598,Event,ADDED,eval-conflicts-rho005-r4-071.18d4658b5217b582,reason=Completed count=1 msg=Job completed
0.5982,Event,ADDED,eval-conflicts-rho005-r4-072-vz4g2.18d4658853f9f68f,reason=Scheduled count=None msg=Successfully assigned compute/eval-conflicts-rho005-r4-072-vz4g2 to kind-worker
0.5984,Event,ADDED,eval-conflicts-rho005-r4-072-vz4g2.18d465886d4e921c,"reason=Pulled count=1 msg=Container image ""busybox:musl"" already present on machine"
0.5986,Event,ADDED,eval-conflicts-rho005-r4-072-vz4g2.18d465886ecc6fb3,reason=Created count=1 msg=Created container: task
0.599,Event,ADDED,eval-conflicts-rho005-r4-072-vz4g2.18d465887162c747,reason=Started count=1 msg=Started container task
0.5991,Event,ADDED,eval-conflicts-rho005-r4-072.18d4658852bc5898,reason=SuccessfulCreate count=1 msg=Created pod: eval-conflicts-rho005-r4-072-vz4g2
0.5993,Event,ADDED,eval-conflicts-rho005-r4-072.18d4658b8ddd886f,reason=Completed count=1 msg=Job completed
0.5995,Event,ADDED,eval-conflicts-rho005-r4-073-wj782.18d465888efdaf58,reason=Scheduled count=None msg=Successfully assigned compute/eval-conflicts-rho005-r4-073-wj782 to kind-worker4
0.5997,Event,ADDED,eval-conflicts-rho005-r4-073-wj782.18d46588a7b9cfb7,"reason=Pulled count=1 msg=Container image ""busybox:musl"" already present on machine"
0.5999,Event,ADDED,eval-conflicts-rho005-r4-073-wj782.18d46588a8cc4264,reason=Created count=1 msg=Created container: task
0.6,Event,ADDED,eval-conflicts-rho005-r4-073-wj782.18d46588ab044ea6,reason=Started count=1 msg=Started container task
0.6004,Event,ADDED,eval-conflicts-rho005-r4-073.18d465888e547f5f,reason=SuccessfulCreate count=1 msg=Created pod: eval-conflicts-rho005-r4-073-wj782
0.6006,Event,ADDED,eval-conflicts-rho005-r4-073.18d4658bc668d917,reason=Completed count=1 msg=Job completed
0.6007,Event,ADDED,eval-conflicts-rho005-r4-074-fvkdp.18d46588cab54af5,reason=Scheduled count=None msg=Successfully assigned compute/eval-conflicts-rho005-r4-074-fvkdp to kind-worker4
0.6009,Event,ADDED,eval-conflicts-rho005-r4-074-fvkdp.18d46588e3f8b82f,"reason=Pulled count=1 msg=Container image ""busybox:musl"" already present on machine"
0.6015,Event,ADDED,eval-conflicts-rho005-r4-074-fvkdp.18d46588e515aa72,reason=Created count=1 msg=Created container: task
0.6018,Event,ADDED,eval-conflicts-rho005-r4-074-fvkdp.18d46588e725bc1d,reason=Started count=1 msg=Started container task
0.602,Event,ADDED,eval-conflicts-rho005-r4-074.18d46588c9d60466,reason=SuccessfulCreate count=1 msg=Created pod: eval-conflicts-rho005-r4-074-fvkdp
0.6022,Event,ADDED,eval-conflicts-rho005-r4-074.18d4658c01ac6bd7,reason=Completed count=1 msg=Job completed
0.6024,Event,ADDED,eval-conflicts-rho005-r4-075-4666q.18d4658906b7dd4a,reason=Scheduled count=None msg=Successfully assigned compute/eval-conflicts-rho005-r4-075-4666q to kind-worker
0.6026,Event,ADDED,eval-conflicts-rho005-r4-075-4666q.18d465891fcf9997,"reason=Pulled count=1 msg=Container image ""busybox:musl"" already present on machine"
0.6028,Event,ADDED,eval-conflicts-rho005-r4-075-4666q.18d4658920dcd44f,reason=Created count=1 msg=Created container: task
0.603,Event,ADDED,eval-conflicts-rho005-r4-075-4666q.18d465892306d09e,reason=Started count=1 msg=Started container task
0.6032,Event,ADDED,eval-conflicts-rho005-r4-075.18d4658905ba76d2,reason=SuccessfulCreate count=1 msg=Created pod: eval-conflicts-rho005-r4-075-4666q
0.6033,Event,ADDED,eval-conflicts-rho005-r4-075.18d4658c41735c48,reason=Completed count=1 msg=Job completed
0.6035,Event,ADDED,eval-conflicts-rho005-r4-076-7dt84.18d46589420d66fb,reason=Scheduled count=None msg=Successfully assigned compute/eval-conflicts-rho005-r4-076-7dt84 to kind-worker
0.6038,Event,ADDED,eval-conflicts-rho005-r4-076-7dt84.18d465895df3e806,"reason=Pulled count=1 msg=Container image ""busybox:musl"" already present on machine"
0.6039,Event,ADDED,eval-conflicts-rho005-r4-076-7dt84.18d465895f2c3168,reason=Created count=1 msg=Created container: task
0.6041,Event,ADDED,eval-conflicts-rho005-r4-076-7dt84.18d4658963841585,reason=Started count=1 msg=Started container task
0.6043,Event,ADDED,eval-conflicts-rho005-r4-076.18d465894145cf8e,reason=SuccessfulCreate count=1 msg=Created pod: eval-conflicts-rho005-r4-076-7dt84
0.6045,Event,ADDED,eval-conflicts-rho005-r4-076.18d4658c7d3c78e7,reason=Completed count=1 msg=Job completed
0.6047,Event,ADDED,eval-conflicts-rho005-r4-077-dm4zt.18d465897eb27e89,reason=Scheduled count=None msg=Successfully assigned compute/eval-conflicts-rho005-r4-077-dm4zt to kind-worker4
0.6048,Event,ADDED,eval-conflicts-rho005-r4-077-dm4zt.18d4658997fbee1a,"reason=Pulled count=1 msg=Container image ""busybox:musl"" already present on machine"
0.605,Event,ADDED,eval-conflicts-rho005-r4-077-dm4zt.18d46589990cedda,reason=Created count=1 msg=Created container: task
0.6052,Event,ADDED,eval-conflicts-rho005-r4-077-dm4zt.18d465899af258c6,reason=Started count=1 msg=Started container task
0.6053,Event,ADDED,eval-conflicts-rho005-r4-077.18d465897dcecbc8,reason=SuccessfulCreate count=1 msg=Created pod: eval-conflicts-rho005-r4-077-dm4zt
0.6055,Event,ADDED,eval-conflicts-rho005-r4-077.18d4658cb558c4af,reason=Completed count=1 msg=Job completed
0.6056,Event,ADDED,eval-conflicts-rho005-r4-078-w2w4m.18d46589b924c69b,"reason=FailedScheduling count=None msg=0/6 nodes are available: 6 node(s) had untolerated taint(s). no new claims to deallocate, preemption: 0/6 nodes are available: 6 Preemption is not helpful for scheduling."
0.6059,Event,ADDED,eval-conflicts-rho005-r4-078-w2w4m.18d46589fe794097,reason=Scheduled count=None msg=Successfully assigned compute/eval-conflicts-rho005-r4-078-w2w4m to kind-worker2
0.6061,Event,ADDED,eval-conflicts-rho005-r4-078-w2w4m.18d4658a17c419fa,"reason=Pulled count=1 msg=Container image ""busybox:musl"" already present on machine"
0.6064,Event,ADDED,eval-conflicts-rho005-r4-078-w2w4m.18d4658a192f6b84,reason=Created count=1 msg=Created container: task
0.6066,Event,ADDED,eval-conflicts-rho005-r4-078-w2w4m.18d4658a1cf4ac6f,reason=Started count=1 msg=Started container task
0.6069,Event,ADDED,eval-conflicts-rho005-r4-078.18d46589b916768b,reason=SuccessfulCreate count=1 msg=Created pod: eval-conflicts-rho005-r4-078-w2w4m
0.607,Event,ADDED,eval-conflicts-rho005-r4-078.18d4658d58c5bc5e,reason=Completed count=1 msg=Job completed
0.6073,Event,ADDED,eval-conflicts-rho005-r4-079-t529z.18d46589f3f15863,"reason=FailedScheduling count=None msg=0/6 nodes are available: 6 node(s) had untolerated taint(s). no new claims to deallocate, preemption: 0/6 nodes are available: 6 Preemption is not helpful for scheduling."
0.6075,Event,ADDED,eval-conflicts-rho005-r4-079-t529z.18d46589feaea18b,reason=Scheduled count=None msg=Successfully assigned compute/eval-conflicts-rho005-r4-079-t529z to kind-worker2
0.6077,Event,ADDED,eval-conflicts-rho005-r4-079-t529z.18d4658a17ec0d60,"reason=Pulled count=1 msg=Container image ""busybox:musl"" already present on machine"
0.6079,Event,ADDED,eval-conflicts-rho005-r4-079-t529z.18d4658a198f9452,reason=Created count=1 msg=Created container: task
0.6081,Event,ADDED,eval-conflicts-rho005-r4-079-t529z.18d4658a1d289ffc,reason=Started count=1 msg=Started container task
0.6082,Event,ADDED,eval-conflicts-rho005-r4-079.18d46589f3e47cfb,reason=SuccessfulCreate count=1 msg=Created pod: eval-conflicts-rho005-r4-079-t529z
0.6084,Event,ADDED,eval-conflicts-rho005-r4-079.18d4658d58e920a5,reason=Completed count=1 msg=Job completed
0.6094,Event,ADDED,eval-conflicts-rho005-r4-080-tzzdg.18d4658a30104292,reason=Scheduled count=None msg=Successfully assigned compute/eval-conflicts-rho005-r4-080-tzzdg to kind-worker2
0.6096,Event,ADDED,eval-conflicts-rho005-r4-080-tzzdg.18d4658a4888028b,"reason=Pulled count=1 msg=Container image ""busybox:musl"" already present on machine"
0.6098,Event,ADDED,eval-conflicts-rho005-r4-080-tzzdg.18d4658a49a1616f,reason=Created count=1 msg=Created container: task
0.6099,Event,ADDED,eval-conflicts-rho005-r4-080-tzzdg.18d4658a4d3e1eb8,reason=Started count=1 msg=Started container task
0.6102,Event,ADDED,eval-conflicts-rho005-r4-080.18d4658a2f711d65,reason=SuccessfulCreate count=1 msg=Created pod: eval-conflicts-rho005-r4-080-tzzdg
0.6104,Event,ADDED,eval-conflicts-rho005-r4-080.18d4658d58a32d63,reason=Completed count=1 msg=Job completed
0.6106,Event,ADDED,eval-conflicts-rho005-r4-081-vqsqf.18d4658a6bc73b03,reason=Scheduled count=None msg=Successfully assigned compute/eval-conflicts-rho005-r4-081-vqsqf to kind-worker2
0.6109,Event,ADDED,eval-conflicts-rho005-r4-081-vqsqf.18d4658a84f2b184,"reason=Pulled count=1 msg=Container image ""busybox:musl"" already present on machine"
0.6111,Event,ADDED,eval-conflicts-rho005-r4-081-vqsqf.18d4658a8607adf4,reason=Created count=1 msg=Created container: task
0.6113,Event,ADDED,eval-conflicts-rho005-r4-081-vqsqf.18d4658a8806a5d6,reason=Started count=1 msg=Started container task
0.6114,Event,ADDED,eval-conflicts-rho005-r4-081.18d4658a6b2d0dda,reason=SuccessfulCreate count=1 msg=Created pod: eval-conflicts-rho005-r4-081-vqsqf
0.6118,Event,ADDED,eval-conflicts-rho005-r4-081.18d4658dd0270144,reason=Completed count=1 msg=Job completed
0.6119,Event,ADDED,eval-conflicts-rho005-r4-082-nw2g4.18d4658aa7f61729,reason=Scheduled count=None msg=Successfully assigned compute/eval-conflicts-rho005-r4-082-nw2g4 to kind-worker2
0.6121,Event,ADDED,eval-conflicts-rho005-r4-082-nw2g4.18d4658ac0d6133a,"reason=Pulled count=1 msg=Container image ""busybox:musl"" already present on machine"
0.6123,Event,ADDED,eval-conflicts-rho005-r4-082-nw2g4.18d4658ac21ec6ed,reason=Created count=1 msg=Created container: task
0.6125,Event,ADDED,eval-conflicts-rho005-r4-082-nw2g4.18d4658ac46d4ed8,reason=Started count=1 msg=Started container task
0.6126,Event,ADDED,eval-conflicts-rho005-r4-082.18d4658aa7603809,reason=SuccessfulCreate count=1 msg=Created pod: eval-conflicts-rho005-r4-082-nw2g4
0.6128,Event,ADDED,eval-conflicts-rho005-r4-082.18d4658e0ca9fe1f,reason=Completed count=1 msg=Job completed
0.613,Event,ADDED,eval-conflicts-rho005-r4-083-lkm9s.18d4658ae32f921b,reason=Scheduled count=None msg=Successfully assigned compute/eval-conflicts-rho005-r4-083-lkm9s to kind-worker5
0.6132,Event,ADDED,eval-conflicts-rho005-r4-083-lkm9s.18d4658afbd2b68a,"reason=Pulled count=1 msg=Container image ""busybox:musl"" already present on machine"
0.6134,Event,ADDED,eval-conflicts-rho005-r4-083-lkm9s.18d4658afcf2bf4f,reason=Created count=1 msg=Created container: task
0.6135,Event,ADDED,eval-conflicts-rho005-r4-083-lkm9s.18d4658aff99873e,reason=Started count=1 msg=Started container task
0.6137,Event,ADDED,eval-conflicts-rho005-r4-083.18d4658ae227996c,reason=SuccessfulCreate count=1 msg=Created pod: eval-conflicts-rho005-r4-083-lkm9s
0.6139,Event,ADDED,eval-conflicts-rho005-r4-083.18d4658e2b00f16a,reason=Completed count=1 msg=Job completed
0.614,Event,ADDED,eval-conflicts-rho005-r4-084-dptx8.18d4658b1f662187,reason=Scheduled count=None msg=Successfully assigned compute/eval-conflicts-rho005-r4-084-dptx8 to kind-worker5
0.6143,Event,ADDED,eval-conflicts-rho005-r4-084-dptx8.18d4658b3a723b77,"reason=Pulled count=1 msg=Container image ""busybox:musl"" already present on machine"
0.6144,Event,ADDED,eval-conflicts-rho005-r4-084-dptx8.18d4658b3b89e647,reason=Created count=1 msg=Created container: task
0.6146,Event,ADDED,eval-conflicts-rho005-r4-084-dptx8.18d4658b419a06b1,reason=Started count=1 msg=Started container task
0.6148,Event,ADDED,eval-conflicts-rho005-r4-084.18d4658b1e741afa,reason=SuccessfulCreate count=1 msg=Created pod: eval-conflicts-rho005-r4-084-dptx8
0.6149,Event,ADDED,eval-conflicts-rho005-r4-084.18d4658e66b8b29d,reason=Completed count=1 msg=Job completed
0.6151,Event,ADDED,eval-conflicts-rho005-r4-085-842dd.18d4658b5a7e5cac,reason=Scheduled count=None msg=Successfully assigned compute/eval-conflicts-rho005-r4-085-842dd to kind-worker2
0.6152,Event,ADDED,eval-conflicts-rho005-r4-085-842dd.18d4658b73511e59,"reason=Pulled count=1 msg=Container image ""busybox:musl"" already present on machine"
0.6154,Event,ADDED,eval-conflicts-rho005-r4-085-842dd.18d4658b74629fcd,reason=Created count=1 msg=Created container: task
0.6156,Event,ADDED,eval-conflicts-rho005-r4-085-842dd.18d4658b78753ada,reason=Started count=1 msg=Started container task
0.6158,Event,ADDED,eval-conflicts-rho005-r4-085.18d4658b5989bb3a,reason=SuccessfulCreate count=1 msg=Created pod: eval-conflicts-rho005-r4-085-842dd
0.6159,Event,ADDED,eval-conflicts-rho005-r4-085.18d4658e849cfac4,reason=Completed count=1 msg=Job completed
0.6161,Event,ADDED,eval-conflicts-rho005-r4-086-24s9n.18d4658b95d25fc7,reason=Scheduled count=None msg=Successfully assigned compute/eval-conflicts-rho005-r4-086-24s9n to kind-worker5
0.6163,Event,ADDED,eval-conflicts-rho005-r4-086-24s9n.18d4658bb26623ab,"reason=Pulled count=1 msg=Container image ""busybox:musl"" already present on machine"
0.6164,Event,ADDED,eval-conflicts-rho005-r4-086-24s9n.18d4658bb3870dd4,reason=Created count=1 msg=Created container: task
0.6166,Event,ADDED,eval-conflicts-rho005-r4-086-24s9n.18d4658bb7135fd6,reason=Started count=1 msg=Started container task
0.6169,Event,ADDED,eval-conflicts-rho005-r4-086.18d4658b94f8895e,reason=SuccessfulCreate count=1 msg=Created pod: eval-conflicts-rho005-r4-086-24s9n
0.6171,Event,ADDED,eval-conflicts-rho005-r4-086.18d4658eddd81cad,reason=Completed count=1 msg=Job completed
0.6172,Event,ADDED,eval-conflicts-rho005-r4-087-9n8qx.18d4658bd2c1f723,reason=Scheduled count=None msg=Successfully assigned compute/eval-conflicts-rho005-r4-087-9n8qx to kind-worker5
0.6175,Event,ADDED,eval-conflicts-rho005-r4-087-9n8qx.18d4658beb5fc1d2,"reason=Pulled count=1 msg=Container image ""busybox:musl"" already present on machine"
0.6177,Event,ADDED,eval-conflicts-rho005-r4-087-9n8qx.18d4658bec763521,reason=Created count=1 msg=Created container: task
0.6178,Event,ADDED,eval-conflicts-rho005-r4-087-9n8qx.18d4658bf04e5792,reason=Started count=1 msg=Started container task
0.618,Event,ADDED,eval-conflicts-rho005-r4-087.18d4658bd1be5856,reason=SuccessfulCreate count=1 msg=Created pod: eval-conflicts-rho005-r4-087-9n8qx
0.6183,Event,ADDED,eval-conflicts-rho005-r4-087.18d4658f19b3ded1,reason=Completed count=1 msg=Job completed
0.6184,Event,ADDED,eval-conflicts-rho005-r4-088-279wc.18d4658c0dc705b0,reason=Scheduled count=None msg=Successfully assigned compute/eval-conflicts-rho005-r4-088-279wc to kind-worker3
0.6186,Event,ADDED,eval-conflicts-rho005-r4-088-279wc.18d4658c28df11b4,"reason=Pulled count=1 msg=Container image ""busybox:musl"" already present on machine"
0.6188,Event,ADDED,eval-conflicts-rho005-r4-088-279wc.18d4658c29ff464b,reason=Created count=1 msg=Created container: task
0.619,Event,ADDED,eval-conflicts-rho005-r4-088-279wc.18d4658c2e4fa1be,reason=Started count=1 msg=Started container task
0.6192,Event,ADDED,eval-conflicts-rho005-r4-088.18d4658c0cd4192f,reason=SuccessfulCreate count=1 msg=Created pod: eval-conflicts-rho005-r4-088-279wc
0.6194,Event,ADDED,eval-conflicts-rho005-r4-088.18d4658f3fd83fb2,reason=Completed count=1 msg=Job completed
0.6196,Event,ADDED,eval-conflicts-rho005-r4-089-bp2fj.18d4658c4a252b94,reason=Scheduled count=None msg=Successfully assigned compute/eval-conflicts-rho005-r4-089-bp2fj to kind-worker5
0.6198,Event,ADDED,eval-conflicts-rho005-r4-089-bp2fj.18d4658c64386e1f,"reason=Pulled count=1 msg=Container image ""busybox:musl"" already present on machine"
0.6199,Event,ADDED,eval-conflicts-rho005-r4-089-bp2fj.18d4658c657c837e,reason=Created count=1 msg=Created container: task
0.6201,Event,ADDED,eval-conflicts-rho005-r4-089-bp2fj.18d4658c6a59c0b4,reason=Started count=1 msg=Started container task
0.6204,Event,ADDED,eval-conflicts-rho005-r4-089.18d4658c48b8662c,reason=SuccessfulCreate count=1 msg=Created pod: eval-conflicts-rho005-r4-089-bp2fj
0.6206,Event,ADDED,eval-conflicts-rho005-r4-089.18d4658f916e4719,reason=Completed count=1 msg=Job completed
0.6207,Event,ADDED,eval-conflicts-rho005-r4-090-khq72.18d4658c84687eca,reason=Scheduled count=None msg=Successfully assigned compute/eval-conflicts-rho005-r4-090-khq72 to kind-worker3
0.6209,Event,ADDED,eval-conflicts-rho005-r4-090-khq72.18d4658c9d63c50d,"reason=Pulled count=1 msg=Container image ""busybox:musl"" already present on machine"
0.6212,Event,ADDED,eval-conflicts-rho005-r4-090-khq72.18d4658c9e751723,reason=Created count=1 msg=Created container: task
0.6214,Event,ADDED,eval-conflicts-rho005-r4-090-khq72.18d4658ca0c8bf27,reason=Started count=1 msg=Started container task
0.6216,Event,ADDED,eval-conflicts-rho005-r4-090.18d4658c83b7182a,reason=SuccessfulCreate count=1 msg=Created pod: eval-conflicts-rho005-r4-090-khq72
0.6217,Event,ADDED,eval-conflicts-rho005-r4-090.18d4658fb7670637,reason=Completed count=1 msg=Job completed
0.6219,Event,ADDED,eval-conflicts-rho005-r4-091-m4jrb.18d4658cc0df16da,reason=Scheduled count=None msg=Successfully assigned compute/eval-conflicts-rho005-r4-091-m4jrb to kind-worker5
0.6221,Event,ADDED,eval-conflicts-rho005-r4-091-m4jrb.18d4658cda8b82df,"reason=Pulled count=1 msg=Container image ""busybox:musl"" already present on machine"
0.6222,Event,ADDED,eval-conflicts-rho005-r4-091-m4jrb.18d4658cdbbccec2,reason=Created count=1 msg=Created container: task
0.6224,Event,ADDED,eval-conflicts-rho005-r4-091-m4jrb.18d4658ce4d06b51,reason=Started count=1 msg=Started container task
0.6226,Event,ADDED,eval-conflicts-rho005-r4-091.18d4658cbfe1f705,reason=SuccessfulCreate count=1 msg=Created pod: eval-conflicts-rho005-r4-091-m4jrb
0.6227,Event,ADDED,eval-conflicts-rho005-r4-091.18d4659008d866e1,reason=Completed count=1 msg=Job completed
0.6229,Event,ADDED,eval-conflicts-rho005-r4-092-r4qg9.18d4658cfb84c5b9,reason=Scheduled count=None msg=Successfully assigned compute/eval-conflicts-rho005-r4-092-r4qg9 to kind-worker5
0.6231,Event,ADDED,eval-conflicts-rho005-r4-092-r4qg9.18d4658d157f048e,"reason=Pulled count=1 msg=Container image ""busybox:musl"" already present on machine"
0.6232,Event,ADDED,eval-conflicts-rho005-r4-092-r4qg9.18d4658d16a2dfea,reason=Created count=1 msg=Created container: task
0.6234,Event,ADDED,eval-conflicts-rho005-r4-092-r4qg9.18d4658d218a331b,reason=Started count=1 msg=Started container task
0.6238,Event,ADDED,eval-conflicts-rho005-r4-092.18d4658cfab43316,reason=SuccessfulCreate count=1 msg=Created pod: eval-conflicts-rho005-r4-092-r4qg9
0.6239,Event,ADDED,eval-conflicts-rho005-r4-092.18d4659044bf4ef7,reason=Completed count=1 msg=Job completed
0.6241,Event,ADDED,eval-conflicts-rho005-r4-093-278nk.18d4658d37f468d1,"reason=FailedScheduling count=None msg=0/6 nodes are available: 6 node(s) had untolerated taint(s). no new claims to deallocate, preemption: 0/6 nodes are available: 6 Preemption is not helpful for scheduling."
0.6242,Event,ADDED,eval-conflicts-rho005-r4-093-278nk.18d4658e755adea3,reason=Scheduled count=None msg=Successfully assigned compute/eval-conflicts-rho005-r4-093-278nk to kind-worker
0.6246,Event,ADDED,eval-conflicts-rho005-r4-093-278nk.18d4658e8f49b6e1,"reason=Pulled count=1 msg=Container image ""busybox:musl"" already present on machine"
0.6251,Event,ADDED,eval-conflicts-rho005-r4-093-278nk.18d4658e9080fcca,reason=Created count=1 msg=Created container: task
0.6253,Event,ADDED,eval-conflicts-rho005-r4-093-278nk.18d4658e928ef871,reason=Started count=1 msg=Started container task
0.6257,Event,ADDED,eval-conflicts-rho005-r4-093.18d4658d37e8d4f8,reason=SuccessfulCreate count=1 msg=Created pod: eval-conflicts-rho005-r4-093-278nk
0.6259,Event,ADDED,eval-conflicts-rho005-r4-093.18d46591a13456b1,reason=Completed count=1 msg=Job completed
0.6261,Event,ADDED,eval-conflicts-rho005-r4-094-69gk7.18d4658d729b0d81,"reason=FailedScheduling count=None msg=0/6 nodes are available: 6 node(s) had untolerated taint(s). no new claims to deallocate, preemption: 0/6 nodes are available: 6 Preemption is not helpful for scheduling."
0.6263,Event,ADDED,eval-conflicts-rho005-r4-094-69gk7.18d4658e75995d51,"reason=FailedScheduling count=None msg=0/6 nodes are available: 1 c_wall violated: 1 conflicting context pair(s) with node memory, 5 node(s) had untolerated taint(s). no new claims to deallocate, preemption: 0/6 nodes are available: 1 No preemption victims found for incoming pod, 5 Preemption is not helpful for scheduling."
0.6266,Event,ADDED,eval-conflicts-rho005-r4-094-69gk7.18d4658e774f3af4,"reason=FailedScheduling count=None msg=0/6 nodes are available: 1 c_wall violated: 2 conflicting context pair(s) with node memory, 5 node(s) had untolerated taint(s). no new claims to deallocate, preemption: 0/6 nodes are available: 1 No preemption victims found for incoming pod, 5 Preemption is not helpful for scheduling."
0.6268,Event,ADDED,eval-conflicts-rho005-r4-094-69gk7.18d4658e7acbea77,"reason=FailedScheduling count=None msg=0/6 nodes are available: 1 c_wall violated: 2 conflicting context pair(s) with node memory, 5 node(s) had untolerated taint(s). no new claims to deallocate, preemption: 0/6 nodes are available: 1 No preemption victims found for incoming pod, 5 Preemption is not helpful for scheduling."
0.627,Event,ADDED,eval-conflicts-rho005-r4-094-69gk7.18d4658e820cf52a,reason=Scheduled count=None msg=Successfully assigned compute/eval-conflicts-rho005-r4-094-69gk7 to kind-worker4
0.6273,Event,ADDED,eval-conflicts-rho005-r4-094-69gk7.18d4658e9cb9c50e,"reason=Pulled count=1 msg=Container image ""busybox:musl"" already present on machine"
0.6275,Event,ADDED,eval-conflicts-rho005-r4-094-69gk7.18d4658e9e776271,reason=Created count=1 msg=Created container: task
0.6278,Event,ADDED,eval-conflicts-rho005-r4-094-69gk7.18d4658ea6655207,reason=Started count=1 msg=Started container task
0.6281,Event,ADDED,eval-conflicts-rho005-r4-094.18d4658d728d161e,reason=SuccessfulCreate count=1 msg=Created pod: eval-conflicts-rho005-r4-094-69gk7
0.6283,Event,ADDED,eval-conflicts-rho005-r4-094.18d46591d7f547f6,reason=Completed count=1 msg=Job completed
0.6285,Event,ADDED,eval-conflicts-rho005-r4-095-rhzxf.18d4658dae0961ff,"reason=FailedScheduling count=None msg=0/6 nodes are available: 6 node(s) had untolerated taint(s). no new claims to deallocate, preemption: 0/6 nodes are available: 6 Preemption is not helpful for scheduling."
0.6288,Event,ADDED,eval-conflicts-rho005-r4-095-rhzxf.18d4658e766e11b7,reason=Scheduled count=None msg=Successfully assigned compute/eval-conflicts-rho005-r4-095-rhzxf to kind-worker
0.629,Event,ADDED,eval-conflicts-rho005-r4-095-rhzxf.18d4658e909f957f,"reason=Pulled count=1 msg=Container image ""busybox:musl"" already present on machine"
0.6292,Event,ADDED,eval-conflicts-rho005-r4-095-rhzxf.18d4658e92e8e8d6,reason=Created count=1 msg=Created container: task
0.6294,Event,ADDED,eval-conflicts-rho005-r4-095-rhzxf.18d4658e954cc600,reason=Started count=1 msg=Started container task
0.6295,Event,ADDED,eval-conflicts-rho005-r4-095.18d4658dadfb86a8,reason=SuccessfulCreate count=1 msg=Created pod: eval-conflicts-rho005-r4-095-rhzxf
0.6297,Event,ADDED,eval-conflicts-rho005-r4-095.18d46591a1c59a1f,reason=Completed count=1 msg=Job completed
0.6299,Event,ADDED,eval-conflicts-rho005-r4-096-rz56c.18d4658de9706556,"reason=FailedScheduling count=None msg=0/6 nodes are available: 6 node(s) had untolerated taint(s). no new claims to deallocate, preemption: 0/6 nodes are available: 6 Preemption is not helpful for scheduling."
0.63,Event,ADDED,eval-conflicts-rho005-r4-096-rz56c.18d4658e76a1b9f5,reason=Scheduled count=None msg=Successfully assigned compute/eval-conflicts-rho005-r4-096-rz56c to kind-worker
0.6302,Event,ADDED,eval-conflicts-rho005-r4-096-rz56c.18d4658e90c113fc,"reason=Pulled count=1 msg=Container image ""busybox:musl"" already present on machine"
0.6304,Event,ADDED,eval-conflicts-rho005-r4-096-rz56c.18d4658e92ccc982,reason=Created count=1 msg=Created container: task
0.6305,Event,ADDED,eval-conflicts-rho005-r4-096-rz56c.18d4658e954fb5ec,reason=Started count=1 msg=Started container task
0.6307,Event,ADDED,eval-conflicts-rho005-r4-096.18d4658de9668299,reason=SuccessfulCreate count=1 msg=Created pod: eval-conflicts-rho005-r4-096-rz56c
0.6311,Event,ADDED,eval-conflicts-rho005-r4-096.18d46591a1c7e50d,reason=Completed count=1 msg=Job completed
0.6313,Event,ADDED,eval-conflicts-rho005-r4-097-f7hx7.18d4658e2533a3a8,"reason=FailedScheduling count=None msg=0/6 nodes are available: 6 node(s) had untolerated taint(s). no new claims to deallocate, preemption: 0/6 nodes are available: 6 Preemption is not helpful for scheduling."
0.6315,Event,ADDED,eval-conflicts-rho005-r4-097-f7hx7.18d4658e7681fa2b,"reason=FailedScheduling count=None msg=0/6 nodes are available: 1 c_wall violated: 2 conflicting context pair(s) with node memory, 5 node(s) had untolerated taint(s). no new claims to deallocate, preemption: 0/6 nodes are available: 1 No preemption victims found for incoming pod, 5 Preemption is not helpful for scheduling."
0.6319,Event,ADDED,eval-conflicts-rho005-r4-097-f7hx7.18d4658e7a96f91e,"reason=FailedScheduling count=None msg=0/6 nodes are available: 1 c_wall violated: 2 conflicting context pair(s) with node memory, 5 node(s) had untolerated taint(s). no new claims to deallocate, preemption: 0/6 nodes are available: 1 No preemption victims found for incoming pod, 5 Preemption is not helpful for scheduling."
0.632,Event,ADDED,eval-conflicts-rho005-r4-097-f7hx7.18d4658e82a1a24b,reason=Scheduled count=None msg=Successfully assigned compute/eval-conflicts-rho005-r4-097-f7hx7 to kind-worker4
0.6323,Event,ADDED,eval-conflicts-rho005-r4-097-f7hx7.18d4658e9d28b3e8,"reason=Pulled count=1 msg=Container image ""busybox:musl"" already present on machine"
0.6327,Event,ADDED,eval-conflicts-rho005-r4-097-f7hx7.18d4658e9ee5b1fe,reason=Created count=1 msg=Created container: task
0.6329,Event,ADDED,eval-conflicts-rho005-r4-097-f7hx7.18d4658ea94fcd62,reason=Started count=1 msg=Started container task
0.6331,Event,ADDED,eval-conflicts-rho005-r4-097.18d4658e25296904,reason=SuccessfulCreate count=1 msg=Created pod: eval-conflicts-rho005-r4-097-f7hx7
0.6333,Event,ADDED,eval-conflicts-rho005-r4-097.18d46591d7d36e58,reason=Completed count=1 msg=Job completed
0.6336,Event,ADDED,eval-conflicts-rho005-r4-098-x5vls.18d4658e60b64601,"reason=FailedScheduling count=None msg=0/6 nodes are available: 6 node(s) had untolerated taint(s). no new claims to deallocate, preemption: 0/6 nodes are available: 6 Preemption is not helpful for scheduling."
0.6337,Event,ADDED,eval-conflicts-rho005-r4-098-x5vls.18d4658e777e7a97,reason=Scheduled count=None msg=Successfully assigned compute/eval-conflicts-rho005-r4-098-x5vls to kind-worker
0.6339,Event,ADDED,eval-conflicts-rho005-r4-098-x5vls.18d4658e9084893f,"reason=Pulled count=1 msg=Container image ""busybox:musl"" already present on machine"
0.6341,Event,ADDED,eval-conflicts-rho005-r4-098-x5vls.18d4658e9257b819,reason=Created count=1 msg=Created container: task
0.6343,Event,ADDED,eval-conflicts-rho005-r4-098-x5vls.18d4658e94a20762,reason=Started count=1 msg=Started container task
0.6345,Event,ADDED,eval-conflicts-rho005-r4-098.18d4658e60ac8a3e,reason=SuccessfulCreate count=1 msg=Created pod: eval-conflicts-rho005-r4-098-x5vls
0.6347,Event,ADDED,eval-conflicts-rho005-r4-098.18d46591de3841a6,reason=Completed count=1 msg=Job completed
0.6349,Event,ADDED,eval-conflicts-rho005-r4-099-wfq8m.18d4658e9d9fc500,reason=Scheduled count=None msg=Successfully assigned compute/eval-conflicts-rho005-r4-099-wfq8m to kind-worker4
0.6351,Event,ADDED,eval-conflicts-rho005-r4-099-wfq8m.18d4658eb8328ba4,"reason=Pulled count=1 msg=Container image ""busybox:musl"" already present on machine"
0.6352,Event,ADDED,eval-conflicts-rho005-r4-099-wfq8m.18d4658eb957aa0c,reason=Created count=1 msg=Created container: task
0.6354,Event,ADDED,eval-conflicts-rho005-r4-099-wfq8m.18d4658ebb747182,reason=Started count=1 msg=Started container task
0.6358,Event,ADDED,eval-conflicts-rho005-r4-099.18d4658e9c010dc4,reason=SuccessfulCreate count=1 msg=Created pod: eval-conflicts-rho005-r4-099-wfq8m
0.636,Event,ADDED,eval-conflicts-rho005-r4-099.18d46591d855158c,reason=Completed count=1 msg=Job completed
0.6362,Event,ADDED,eval-conflicts-rho005-r5-000-s8nwz.18d4659723eb690d,reason=Scheduled count=None msg=Successfully assigned compute/eval-conflicts-rho005-r5-000-s8nwz to kind-worker
0.6368,Event,ADDED,eval-conflicts-rho005-r5-000-s8nwz.18d465973dabc813,"reason=Pulled count=1 msg=Container image ""busybox:musl"" already present on machine"
0.6371,Event,ADDED,eval-conflicts-rho005-r5-000-s8nwz.18d465973ef9c235,reason=Created count=1 msg=Created container: task
0.6373,Event,ADDED,eval-conflicts-rho005-r5-000-s8nwz.18d4659741649a7e,reason=Started count=1 msg=Started container task
0.6376,Event,ADDED,eval-conflicts-rho005-r5-000.18d46597230b4d9e,reason=SuccessfulCreate count=1 msg=Created pod: eval-conflicts-rho005-r5-000-s8nwz
0.6379,Event,ADDED,eval-conflicts-rho005-r5-000.18d4659a7f77243f,reason=Completed count=1 msg=Job completed
0.6381,Event,ADDED,eval-conflicts-rho005-r5-001-l94ms.18d465975e6aaa00,reason=Scheduled count=None msg=Successfully assigned compute/eval-conflicts-rho005-r5-001-l94ms to kind-worker
0.6382,Event,ADDED,eval-conflicts-rho005-r5-001-l94ms.18d46597792b2889,"reason=Pulled count=1 msg=Container image ""busybox:musl"" already present on machine"
0.6384,Event,ADDED,eval-conflicts-rho005-r5-001-l94ms.18d465977a50ec19,reason=Created count=1 msg=Created container: task
0.6387,Event,ADDED,eval-conflicts-rho005-r5-001-l94ms.18d465977c60200b,reason=Started count=1 msg=Started container task
0.6388,Event,ADDED,eval-conflicts-rho005-r5-001.18d465975d67dfa3,reason=SuccessfulCreate count=1 msg=Created pod: eval-conflicts-rho005-r5-001-l94ms
0.639,Event,ADDED,eval-conflicts-rho005-r5-001.18d4659abb0667e4,reason=Completed count=1 msg=Job completed
0.6394,Event,ADDED,eval-conflicts-rho005-r5-002-vlbqs.18d465979950ae70,reason=Scheduled count=None msg=Successfully assigned compute/eval-conflicts-rho005-r5-002-vlbqs to kind-worker2
0.6395,Event,ADDED,eval-conflicts-rho005-r5-002-vlbqs.18d46597b1f88552,"reason=Pulled count=1 msg=Container image ""busybox:musl"" already present on machine"
0.6397,Event,ADDED,eval-conflicts-rho005-r5-002-vlbqs.18d46597b310d00c,reason=Created count=1 msg=Created container: task
0.6399,Event,ADDED,eval-conflicts-rho005-r5-002-vlbqs.18d46597b71317dc,reason=Started count=1 msg=Started container task
0.6401,Event,ADDED,eval-conflicts-rho005-r5-002.18d46597989d3cd2,reason=SuccessfulCreate count=1 msg=Created pod: eval-conflicts-rho005-r5-002-vlbqs
0.6403,Event,ADDED,eval-conflicts-rho005-r5-002.18d4659ae227d042,reason=Completed count=1 msg=Job completed
0.6404,Event,ADDED,eval-conflicts-rho005-r5-003-68946.18d46597d642c3b3,reason=Scheduled count=None msg=Successfully assigned compute/eval-conflicts-rho005-r5-003-68946 to kind-worker5
0.6406,Event,ADDED,eval-conflicts-rho005-r5-003-68946.18d46597ef6e41d5,"reason=Pulled count=1 msg=Container image ""busybox:musl"" already present on machine"
0.6408,Event,ADDED,eval-conflicts-rho005-r5-003-68946.18d46597f0880207,reason=Created count=1 msg=Created container: task
0.641,Event,ADDED,eval-conflicts-rho005-r5-003-68946.18d46597f2940d67,reason=Started count=1 msg=Started container task
0.6412,Event,ADDED,eval-conflicts-rho005-r5-003.18d46597d517dd48,reason=SuccessfulCreate count=1 msg=Created pod: eval-conflicts-rho005-r5-003-68946
0.6415,Event,ADDED,eval-conflicts-rho005-r5-003.18d4659b00e713ae,reason=Completed count=1 msg=Job completed
0.6418,Event,ADDED,eval-conflicts-rho005-r5-004-wqhkq.18d4659810688fff,reason=Scheduled count=None msg=Successfully assigned compute/eval-conflicts-rho005-r5-004-wqhkq to kind-worker5
0.6422,Event,ADDED,eval-conflicts-rho005-r5-004-wqhkq.18d465982a1e7747,"reason=Pulled count=1 msg=Container image ""busybox:musl"" already present on machine"
0.6424,Event,ADDED,eval-conflicts-rho005-r5-004-wqhkq.18d465982b2eab99,reason=Created count=1 msg=Created container: task
0.6427,Event,ADDED,eval-conflicts-rho005-r5-004-wqhkq.18d465982d2c0824,reason=Started count=1 msg=Started container task
0.6429,Event,ADDED,eval-conflicts-rho005-r5-004.18d465980f699136,reason=SuccessfulCreate count=1 msg=Created pod: eval-conflicts-rho005-r5-004-wqhkq
0.6433,Event,ADDED,eval-conflicts-rho005-r5-004.18d4659b3cb7bdd5,reason=Completed count=1 msg=Job completed
0.6435,Event,ADDED,eval-conflicts-rho005-r5-005-85vvr.18d465984c5126fc,reason=Scheduled count=None msg=Successfully assigned compute/eval-conflicts-rho005-r5-005-85vvr to kind-worker5
0.6436,Event,ADDED,eval-conflicts-rho005-r5-005-85vvr.18d4659865b882d9,"reason=Pulled count=1 msg=Container image ""busybox:musl"" already present on machine"
0.6439,Event,ADDED,eval-conflicts-rho005-r5-005-85vvr.18d4659866d2cd0a,reason=Created count=1 msg=Created container: task
0.6441,Event,ADDED,eval-conflicts-rho005-r5-005-85vvr.18d465986aa7424b,reason=Started count=1 msg=Started container task
0.6444,Event,ADDED,eval-conflicts-rho005-r5-005.18d465984b86865b,reason=SuccessfulCreate count=1 msg=Created pod: eval-conflicts-rho005-r5-005-85vvr
0.6446,Event,ADDED,eval-conflicts-rho005-r5-005.18d4659b788afa93,reason=Completed count=1 msg=Job completed
0.645,Event,ADDED,eval-conflicts-rho005-r5-006-hnzhd.18d465988731a9ae,reason=Scheduled count=None msg=Successfully assigned compute/eval-conflicts-rho005-r5-006-hnzhd to kind-worker5
0.6453,Event,ADDED,eval-conflicts-rho005-r5-006-hnzhd.18d465989fc5dc81,"reason=Pulled count=1 msg=Container image ""busybox:musl"" already present on machine"
0.6456,Event,ADDED,eval-conflicts-rho005-r5-006-hnzhd.18d46598a0eb0962,reason=Created count=1 msg=Created container: task
0.646,Event,ADDED,eval-conflicts-rho005-r5-006-hnzhd.18d46598a30c4159,reason=Started count=1 msg=Started container task
0.6462,Event,ADDED,eval-conflicts-rho005-r5-006.18d465988673a9bd,reason=SuccessfulCreate count=1 msg=Created pod: eval-conflicts-rho005-r5-006-hnzhd
0.6464,Event,ADDED,eval-conflicts-rho005-r5-006.18d4659bb44bd17c,reason=Completed count=1 msg=Job completed
0.6465,Event,ADDED,eval-conflicts-rho005-r5-007-jrvr4.18d46598c3c5d30a,reason=Scheduled count=None msg=Successfully assigned compute/eval-conflicts-rho005-r5-007-jrvr4 to kind-worker4
0.6468,Event,ADDED,eval-conflicts-rho005-r5-007-jrvr4.18d46598dcc50b89,"reason=Pulled count=1 msg=Container image ""busybox:musl"" already present on machine"
0.647,Event,ADDED,eval-conflicts-rho005-r5-007-jrvr4.18d46598de592801,reason=Created count=1 msg=Created container: task
0.6472,Event,ADDED,eval-conflicts-rho005-r5-007-jrvr4.18d46598e074f227,reason=Started count=1 msg=Started container task
0.6474,Event,ADDED,eval-conflicts-rho005-r5-007.18d46598c24ce715,reason=SuccessfulCreate count=1 msg=Created pod: eval-conflicts-rho005-r5-007-jrvr4
0.6476,Event,ADDED,eval-conflicts-rho005-r5-007.18d4659c1bbf85e3,reason=Completed count=1 msg=Job completed
0.6477,Event,ADDED,eval-conflicts-rho005-r5-008-2c2bn.18d46598ff12862a,reason=Scheduled count=None msg=Successfully assigned compute/eval-conflicts-rho005-r5-008-2c2bn to kind-worker4
0.6479,Event,ADDED,eval-conflicts-rho005-r5-008-2c2bn.18d465991851b80f,"reason=Pulled count=1 msg=Container image ""busybox:musl"" already present on machine"
0.6481,Event,ADDED,eval-conflicts-rho005-r5-008-2c2bn.18d46599198a0cb4,reason=Created count=1 msg=Created container: task
0.6483,Event,ADDED,eval-conflicts-rho005-r5-008-2c2bn.18d465991cfa6a45,reason=Started count=1 msg=Started container task
0.6484,Event,ADDED,eval-conflicts-rho005-r5-008.18d46598fe3329ed,reason=SuccessfulCreate count=1 msg=Created pod: eval-conflicts-rho005-r5-008-2c2bn
0.6486,Event,ADDED,eval-conflicts-rho005-r5-008.18d4659c57a4fd7a,reason=Completed count=1 msg=Job completed
0.6491,Event,ADDED,eval-conflicts-rho005-r5-009-srgwg.18d465993a93ac77,reason=Scheduled count=None msg=Successfully assigned compute/eval-conflicts-rho005-r5-009-srgwg to kind-worker4
0.6495,Event,ADDED,eval-conflicts-rho005-r5-009-srgwg.18d46599543b6378,"reason=Pulled count=1 msg=Container image ""busybox:musl"" already present on machine"
0.6497,Event,ADDED,eval-conflicts-rho005-r5-009-srgwg.18d46599555d922a,reason=Created count=1 msg=Created container: task
0.6499,Event,ADDED,eval-conflicts-rho005-r5-009-srgwg.18d465995767d6b4,reason=Started count=1 msg=Started container task
0.6502,Event,ADDED,eval-conflicts-rho005-r5-009.18d4659939d2f5fe,reason=SuccessfulCreate count=1 msg=Created pod: eval-conflicts-rho005-r5-009-srgwg
0.6504,Event,ADDED,eval-conflicts-rho005-r5-009.18d4659c93c0509b,reason=Completed count=1 msg=Job completed
0.6506,Event,ADDED,eval-conflicts-rho005-r5-010-kcfbr.18d4659975dc6e0b,reason=Scheduled count=None msg=Successfully assigned compute/eval-conflicts-rho005-r5-010-kcfbr to kind-worker3
0.6509,Event,ADDED,eval-conflicts-rho005-r5-010-kcfbr.18d465998f9949f1,"reason=Pulled count=1 msg=Container image ""busybox:musl"" already present on machine"
0.6511,Event,ADDED,eval-conflicts-rho005-r5-010-kcfbr.18d4659990c6529f,reason=Created count=1 msg=Created container: task
0.6513,Event,ADDED,eval-conflicts-rho005-r5-010-kcfbr.18d4659992e910d8,reason=Started count=1 msg=Started container task
0.6514,Event,ADDED,eval-conflicts-rho005-r5-010.18d4659974decfd7,reason=SuccessfulCreate count=1 msg=Created pod: eval-conflicts-rho005-r5-010-kcfbr
0.6517,Event,ADDED,eval-conflicts-rho005-r5-010.18d4659cc83d1b5c,reason=Completed count=1 msg=Job completed
0.6519,Event,ADDED,eval-conflicts-rho005-r5-011-dth2t.18d46599b26929ff,reason=Scheduled count=None msg=Successfully assigned compute/eval-conflicts-rho005-r5-011-dth2t to kind-worker4
0.652,Event,ADDED,eval-conflicts-rho005-r5-011-dth2t.18d46599cb9429e9,"reason=Pulled count=1 msg=Container image ""busybox:musl"" already present on machine"
0.6522,Event,ADDED,eval-conflicts-rho005-r5-011-dth2t.18d46599ccabb0d8,reason=Created count=1 msg=Created container: task
0.6525,Event,ADDED,eval-conflicts-rho005-r5-011-dth2t.18d46599d04e05ae,reason=Started count=1 msg=Started container task
0.6527,Event,ADDED,eval-conflicts-rho005-r5-011.18d46599b12aa9fd,reason=SuccessfulCreate count=1 msg=Created pod: eval-conflicts-rho005-r5-011-dth2t
0.6529,Event,ADDED,eval-conflicts-rho005-r5-011.18d4659d0b99b490,reason=Completed count=1 msg=Job completed
0.6531,Event,ADDED,eval-conflicts-rho005-r5-012-5g62s.18d46599ed376f09,reason=Scheduled count=None msg=Successfully assigned compute/eval-conflicts-rho005-r5-012-5g62s to kind-worker3
0.6533,Event,ADDED,eval-conflicts-rho005-r5-012-5g62s.18d4659a0580ad66,"reason=Pulled count=1 msg=Container image ""busybox:musl"" already present on machine"
0.6534,Event,ADDED,eval-conflicts-rho005-r5-012-5g62s.18d4659a069f2f62,reason=Created count=1 msg=Created container: task
0.6536,Event,ADDED,eval-conflicts-rho005-r5-012-5g62s.18d4659a08ad46aa,reason=Started count=1 msg=Started container task
0.6539,Event,ADDED,eval-conflicts-rho005-r5-012.18d46599ec358226,reason=SuccessfulCreate count=1 msg=Created pod: eval-conflicts-rho005-r5-012-5g62s
0.6541,Event,ADDED,eval-conflicts-rho005-r5-012.18d4659d4022ca58,reason=Completed count=1 msg=Job completed
0.6542,Event,ADDED,eval-conflicts-rho005-r5-013-wdttc.18d4659a2925d1da,reason=Scheduled count=None msg=Successfully assigned compute/eval-conflicts-rho005-r5-013-wdttc to kind-worker3
0.6545,Event,ADDED,eval-conflicts-rho005-r5-013-wdttc.18d4659a42b71077,"reason=Pulled count=1 msg=Container image ""busybox:musl"" already present on machine"
0.6547,Event,ADDED,eval-conflicts-rho005-r5-013-wdttc.18d4659a443531a0,reason=Created count=1 msg=Created container: task
0.6549,Event,ADDED,eval-conflicts-rho005-r5-013-wdttc.18d4659a4e57e1a3,reason=Started count=1 msg=Started container task
0.655,Event,ADDED,eval-conflicts-rho005-r5-013.18d4659a28407818,reason=SuccessfulCreate count=1 msg=Created pod: eval-conflicts-rho005-r5-013-wdttc
0.6554,Event,ADDED,eval-conflicts-rho005-r5-013.18d4659d7c0d5182,reason=Completed count=1 msg=Job completed
0.6555,Event,ADDED,eval-conflicts-rho005-r5-014-vtv75.18d4659a63c1d533,reason=Scheduled count=None msg=Successfully assigned compute/eval-conflicts-rho005-r5-014-vtv75 to kind-worker3
0.6557,Event,ADDED,eval-conflicts-rho005-r5-014-vtv75.18d4659a7ca76708,"reason=Pulled count=1 msg=Container image ""busybox:musl"" already present on machine"
0.6559,Event,ADDED,eval-conflicts-rho005-r5-014-vtv75.18d4659a7daa6bd9,reason=Created count=1 msg=Created container: task
0.6561,Event,ADDED,eval-conflicts-rho005-r5-014-vtv75.18d4659a7fba7584,reason=Started count=1 msg=Started container task
0.6563,Event,ADDED,eval-conflicts-rho005-r5-014.18d4659a631d3f86,reason=SuccessfulCreate count=1 msg=Created pod: eval-conflicts-rho005-r5-014-vtv75
0.6564,Event,ADDED,eval-conflicts-rho005-r5-014.18d4659db7dea73c,reason=Completed count=1 msg=Job completed
0.6566,Event,ADDED,eval-conflicts-rho005-r5-015-8tjr2.18d4659a9fde06c3,reason=Scheduled count=None msg=Successfully assigned compute/eval-conflicts-rho005-r5-015-8tjr2 to kind-worker2
0.6568,Event,ADDED,eval-conflicts-rho005-r5-015-8tjr2.18d4659ab921e76c,"reason=Pulled count=1 msg=Container image ""busybox:musl"" already present on machine"
0.6569,Event,ADDED,eval-conflicts-rho005-r5-015-8tjr2.18d4659aba555207,reason=Created count=1 msg=Created container: task
