t_recv,kind,type,name,detail
0.0218,Node,ADDED,kind-control-plane,taints=1
0.0231,Node,ADDED,kind-worker,taints=0
0.0245,Node,ADDED,kind-worker2,taints=0
0.0258,Node,ADDED,kind-worker3,taints=0
0.0271,Node,ADDED,kind-worker4,taints=0
0.0285,Node,ADDED,kind-worker5,taints=0
0.0639,Event,ADDED,eval-conflicts-rho010-r4-000-5pjn9.18d542d8e74444e4,reason=Scheduled count=None msg=Successfully assigned compute/eval-conflicts-rho010-r4-000-5pjn9 to kind-worker2
0.0644,Event,ADDED,eval-conflicts-rho010-r4-000-5pjn9.18d542d901a5d102,"reason=Pulled count=1 msg=Container image ""busybox:musl"" already present on machine"
0.0646,Event,ADDED,eval-conflicts-rho010-r4-000-5pjn9.18d542d902c43c86,reason=Created count=1 msg=Created container: task
0.0648,Event,ADDED,eval-conflicts-rho010-r4-000-5pjn9.18d542d904b81343,reason=Started count=1 msg=Started container task
0.065,Event,ADDED,eval-conflicts-rho010-r4-000.18d542d8e6668d3f,reason=SuccessfulCreate count=1 msg=Created pod: eval-conflicts-rho010-r4-000-5pjn9
0.0652,Event,ADDED,eval-conflicts-rho010-r4-000.18d542de6e7c5cbf,reason=Completed count=1 msg=Job completed
0.0654,Event,ADDED,eval-conflicts-rho010-r4-001-2whhg.18d542d921d0eecf,reason=Scheduled count=None msg=Successfully assigned compute/eval-conflicts-rho010-r4-001-2whhg to kind-worker2
0.0656,Event,ADDED,eval-conflicts-rho010-r4-001-2whhg.18d542d93bd882a8,"reason=Pulled count=1 msg=Container image ""busybox:musl"" already present on machine"
0.066,Event,ADDED,eval-conflicts-rho010-r4-001-2whhg.18d542d93d095562,reason=Created count=1 msg=Created container: task
0.0662,Event,ADDED,eval-conflicts-rho010-r4-001-2whhg.18d542d93ef7e791,reason=Started count=1 msg=Started container task
0.0663,Event,ADDED,eval-conflicts-rho010-r4-001.18d542d920b9035d,reason=SuccessfulCreate count=1 msg=Created pod: eval-conflicts-rho010-r4-001-2whhg
0.0665,Event,ADDED,eval-conflicts-rho010-r4-001.18d542dead758fb5,reason=Completed count=1 msg=Job completed
0.0669,Event,ADDED,eval-conflicts-rho010-r4-002-p6mbw.18d542d95cd65371,reason=Scheduled count=None msg=Successfully assigned compute/eval-conflicts-rho010-r4-002-p6mbw to kind-worker3
0.0671,Event,ADDED,eval-conflicts-rho010-r4-002-p6mbw.18d542d976003d22,"reason=Pulled count=1 msg=Container image ""busybox:musl"" already present on machine"
0.0673,Event,ADDED,eval-conflicts-rho010-r4-002-p6mbw.18d542d977132fd5,reason=Created count=1 msg=Created container: task
0.0675,Event,ADDED,eval-conflicts-rho010-r4-002-p6mbw.18d542d97b315d68,reason=Started count=1 msg=Started container task
0.0678,Event,ADDED,eval-conflicts-rho010-r4-002.18d542d95c277b44,reason=SuccessfulCreate count=1 msg=Created pod: eval-conflicts-rho010-r4-002-p6mbw
0.068,Event,ADDED,eval-conflicts-rho010-r4-002.18d542df062d8773,reason=Completed count=1 msg=Job completed
0.0682,Event,ADDED,eval-conflicts-rho010-r4-003-gdr6d.18d542d99979ea3a,reason=Scheduled count=None msg=Successfully assigned compute/eval-conflicts-rho010-r4-003-gdr6d to kind-worker4
0.0687,Event,ADDED,eval-conflicts-rho010-r4-003-gdr6d.18d542d9b305d2ff,"reason=Pulled count=1 msg=Container image ""busybox:musl"" already present on machine"
0.0689,Event,ADDED,eval-conflicts-rho010-r4-003-gdr6d.18d542d9b42a7610,reason=Created count=1 msg=Created container: task
0.0691,Event,ADDED,eval-conflicts-rho010-r4-003-gdr6d.18d542d9b6791202,reason=Started count=1 msg=Started container task
0.0693,Event,ADDED,eval-conflicts-rho010-r4-003.18d542d9988f9437,reason=SuccessfulCreate count=1 msg=Created pod: eval-conflicts-rho010-r4-003-gdr6d
0.0697,Event,ADDED,eval-conflicts-rho010-r4-003.18d542df47cb07c5,reason=Completed count=1 msg=Job completed
0.0699,Event,ADDED,eval-conflicts-rho010-r4-004-z5t8s.18d542d9d3e8152b,reason=Scheduled count=None msg=Successfully assigned compute/eval-conflicts-rho010-r4-004-z5t8s to kind-worker2
0.0701,Event,ADDED,eval-conflicts-rho010-r4-004-z5t8s.18d542d9ed461b18,"reason=Pulled count=1 msg=Container image ""busybox:musl"" already present on machine"
0.0702,Event,ADDED,eval-conflicts-rho010-r4-004-z5t8s.18d542d9ee54340c,reason=Created count=1 msg=Created container: task
0.0705,Event,ADDED,eval-conflicts-rho010-r4-004-z5t8s.18d542d9f0311d35,reason=Started count=1 msg=Started container task
0.0707,Event,ADDED,eval-conflicts-rho010-r4-004.18d542d9d2c7065b,reason=SuccessfulCreate count=1 msg=Created pod: eval-conflicts-rho010-r4-004-z5t8s
0.0709,Event,ADDED,eval-conflicts-rho010-r4-004.18d542df62161dad,reason=Completed count=1 msg=Job completed
0.0712,Event,ADDED,eval-conflicts-rho010-r4-005-zr8fr.18d542da100e1e37,reason=Scheduled count=None msg=Successfully assigned compute/eval-conflicts-rho010-r4-005-zr8fr to kind-worker3
0.0714,Event,ADDED,eval-conflicts-rho010-r4-005-zr8fr.18d542da29d2e2b9,"reason=Pulled count=1 msg=Container image ""busybox:musl"" already present on machine"
0.0716,Event,ADDED,eval-conflicts-rho010-r4-005-zr8fr.18d542da2b0f8caf,reason=Created count=1 msg=Created container: task
0.0717,Event,ADDED,eval-conflicts-rho010-r4-005-zr8fr.18d542da2efdc475,reason=Started count=1 msg=Started container task
0.072,Event,ADDED,eval-conflicts-rho010-r4-005.18d542da0eee1b1a,reason=SuccessfulCreate count=1 msg=Created pod: eval-conflicts-rho010-r4-005-zr8fr
0.0722,Event,ADDED,eval-conflicts-rho010-r4-005.18d542dfbd95be67,reason=Completed count=1 msg=Job completed
0.0724,Event,ADDED,eval-conflicts-rho010-r4-006-cd4sn.18d542da4c274924,reason=Scheduled count=None msg=Successfully assigned compute/eval-conflicts-rho010-r4-006-cd4sn to kind-worker4
0.0726,Event,ADDED,eval-conflicts-rho010-r4-006-cd4sn.18d542da660dcfa0,"reason=Pulled count=1 msg=Container image ""busybox:musl"" already present on machine"
0.0729,Event,ADDED,eval-conflicts-rho010-r4-006-cd4sn.18d542da6726b56b,reason=Created count=1 msg=Created container: task
0.0731,Event,ADDED,eval-conflicts-rho010-r4-006-cd4sn.18d542da6b36b491,reason=Started count=1 msg=Started container task
0.0732,Event,ADDED,eval-conflicts-rho010-r4-006.18d542da4ad84d99,reason=SuccessfulCreate count=1 msg=Created pod: eval-conflicts-rho010-r4-006-cd4sn
0.0735,Event,ADDED,eval-conflicts-rho010-r4-006.18d542e002678444,reason=Completed count=1 msg=Job completed
0.0737,Event,ADDED,eval-conflicts-rho010-r4-007-8hnt4.18d542da8765ad80,reason=Scheduled count=None msg=Successfully assigned compute/eval-conflicts-rho010-r4-007-8hnt4 to kind-worker3
0.0739,Event,ADDED,eval-conflicts-rho010-r4-007-8hnt4.18d542daa1019f9a,"reason=Pulled count=1 msg=Container image ""busybox:musl"" already present on machine"
0.0741,Event,ADDED,eval-conflicts-rho010-r4-007-8hnt4.18d542daa2184bee,reason=Created count=1 msg=Created container: task
0.0743,Event,ADDED,eval-conflicts-rho010-r4-007-8hnt4.18d542daa41e9aa7,reason=Started count=1 msg=Started container task
0.0744,Event,ADDED,eval-conflicts-rho010-r4-007.18d542da862f3f57,reason=SuccessfulCreate count=1 msg=Created pod: eval-conflicts-rho010-r4-007-8hnt4
0.0746,Event,ADDED,eval-conflicts-rho010-r4-007.18d542e02eaa1cd4,reason=Completed count=1 msg=Job completed
0.0748,Event,ADDED,eval-conflicts-rho010-r4-008-mvf78.18d542dac3307f58,reason=Scheduled count=None msg=Successfully assigned compute/eval-conflicts-rho010-r4-008-mvf78 to kind-worker5
0.075,Event,ADDED,eval-conflicts-rho010-r4-008-mvf78.18d542dadc0bd16d,"reason=Pulled count=1 msg=Container image ""busybox:musl"" already present on machine"
0.0752,Event,ADDED,eval-conflicts-rho010-r4-008-mvf78.18d542dadd26a779,reason=Created count=1 msg=Created container: task
0.0755,Event,ADDED,eval-conflicts-rho010-r4-008-mvf78.18d542dae204c4b8,reason=Started count=1 msg=Started container task
0.0758,Event,ADDED,eval-conflicts-rho010-r4-008.18d542dac1ea1a94,reason=SuccessfulCreate count=1 msg=Created pod: eval-conflicts-rho010-r4-008-mvf78
0.076,Event,ADDED,eval-conflicts-rho010-r4-008.18d542e0883822e6,reason=Completed count=1 msg=Job completed
0.0762,Event,ADDED,eval-conflicts-rho010-r4-009-m2df7.18d542db0379294b,reason=Scheduled count=None msg=Successfully assigned compute/eval-conflicts-rho010-r4-009-m2df7 to kind-worker3
0.0763,Event,ADDED,eval-conflicts-rho010-r4-009-m2df7.18d542db205132a7,"reason=Pulled count=1 msg=Container image ""busybox:musl"" already present on machine"
0.0766,Event,ADDED,eval-conflicts-rho010-r4-009-m2df7.18d542db21668afd,reason=Created count=1 msg=Created container: task
0.0767,Event,ADDED,eval-conflicts-rho010-r4-009-m2df7.18d542db2594920c,reason=Started count=1 msg=Started container task
0.0769,Event,ADDED,eval-conflicts-rho010-r4-009.18d542dafd87e84f,reason=SuccessfulCreate count=1 msg=Created pod: eval-conflicts-rho010-r4-009-m2df7
0.0773,Event,ADDED,eval-conflicts-rho010-r4-009.18d542e0a951d773,reason=Completed count=1 msg=Job completed
0.0775,Event,ADDED,eval-conflicts-rho010-r4-010-ktqmb.18d542db3a636feb,reason=Scheduled count=None msg=Successfully assigned compute/eval-conflicts-rho010-r4-010-ktqmb to kind-worker3
0.0776,Event,ADDED,eval-conflicts-rho010-r4-010-ktqmb.18d542db53b98dc9,"reason=Pulled count=1 msg=Container image ""busybox:musl"" already present on machine"
0.0778,Event,ADDED,eval-conflicts-rho010-r4-010-ktqmb.18d542db54e10040,reason=Created count=1 msg=Created container: task
0.078,Event,ADDED,eval-conflicts-rho010-r4-010-ktqmb.18d542db5af5cc57,reason=Started count=1 msg=Started container task
0.0782,Event,ADDED,eval-conflicts-rho010-r4-010.18d542db39093689,reason=SuccessfulCreate count=1 msg=Created pod: eval-conflicts-rho010-r4-010-ktqmb
0.0783,Event,ADDED,eval-conflicts-rho010-r4-010.18d542e0e4e6ebac,reason=Completed count=1 msg=Job completed
0.0785,Event,ADDED,eval-conflicts-rho010-r4-011-wsfmp.18d542db75cc73d1,reason=Scheduled count=None msg=Successfully assigned compute/eval-conflicts-rho010-r4-011-wsfmp to kind-worker
0.0787,Event,ADDED,eval-conflicts-rho010-r4-011-wsfmp.18d542db92be0e0e,"reason=Pulled count=1 msg=Container image ""busybox:musl"" already present on machine"
0.0789,Event,ADDED,eval-conflicts-rho010-r4-011-wsfmp.18d542db93fbe7a8,reason=Created count=1 msg=Created container: task
0.079,Event,ADDED,eval-conflicts-rho010-r4-011-wsfmp.18d542db9a5dd5a6,reason=Started count=1 msg=Started container task
0.0793,Event,ADDED,eval-conflicts-rho010-r4-011.18d542db746bc66f,reason=SuccessfulCreate count=1 msg=Created pod: eval-conflicts-rho010-r4-011-wsfmp
0.0795,Event,ADDED,eval-conflicts-rho010-r4-011.18d542e1103ff7d7,reason=Completed count=1 msg=Job completed
0.0797,Event,ADDED,eval-conflicts-rho010-r4-012-nsk22.18d542dbbc1082e5,reason=Scheduled count=None msg=Successfully assigned compute/eval-conflicts-rho010-r4-012-nsk22 to kind-worker2
0.0799,Event,ADDED,eval-conflicts-rho010-r4-012-nsk22.18d542dbd6580809,"reason=Pulled count=1 msg=Container image ""busybox:musl"" already present on machine"
0.0802,Event,ADDED,eval-conflicts-rho010-r4-012-nsk22.18d542dbd7ad3005,reason=Created count=1 msg=Created container: task
0.0804,Event,ADDED,eval-conflicts-rho010-r4-012-nsk22.18d542dbdb51e8a3,reason=Started count=1 msg=Started container task
0.0805,Event,ADDED,eval-conflicts-rho010-r4-012.18d542dbb457df8f,reason=SuccessfulCreate count=1 msg=Created pod: eval-conflicts-rho010-r4-012-nsk22
0.0808,Event,ADDED,eval-conflicts-rho010-r4-012.18d542e1861d443e,reason=Completed count=1 msg=Job completed
0.081,Event,ADDED,eval-conflicts-rho010-r4-013-zxxnz.18d542dbef9a8e3d,"reason=FailedScheduling count=None msg=0/6 nodes are available: 3 c_wall violated: 1 conflicting context pair(s) with node memory, 3 node(s) had untolerated taint(s). no new claims to deallocate, preemption: 0/6 nodes are available: 3 No preemption victims found for incoming pod, 3 Preemption is not helpful for scheduling."
0.0812,Event,ADDED,eval-conflicts-rho010-r4-013-zxxnz.18d542dbf50a0c59,"reason=FailedScheduling count=None msg=0/6 nodes are available: 3 c_wall violated: 1 conflicting context pair(s) with node memory, 3 node(s) had untolerated taint(s). no new claims to deallocate, preemption: 0/6 nodes are available: 3 No preemption victims found for incoming pod, 3 Preemption is not helpful for scheduling."
0.0815,Event,ADDED,eval-conflicts-rho010-r4-013-zxxnz.18d542dd28490349,"reason=FailedScheduling count=None msg=0/6 nodes are available: 2 c_wall violated: 1 conflicting context pair(s) with node memory, 4 node(s) had untolerated taint(s). no new claims to deallocate, preemption: 0/6 nodes are available: 2 No preemption victims found for incoming pod, 4 Preemption is not helpful for scheduling."
0.0817,Event,ADDED,eval-conflicts-rho010-r4-013-zxxnz.18d542dd3878e76d,"reason=FailedScheduling count=None msg=0/6 nodes are available: 1 c_wall violated: 1 conflicting context pair(s) with node memory, 5 node(s) had untolerated taint(s). no new claims to deallocate, preemption: 0/6 nodes are available: 1 No preemption victims found for incoming pod, 5 Preemption is not helpful for scheduling."
0.0819,Event,ADDED,eval-conflicts-rho010-r4-013-zxxnz.18d542e07eb32bd3,reason=Scheduled count=None msg=Successfully assigned compute/eval-conflicts-rho010-r4-013-zxxnz to kind-worker3
0.082,Event,ADDED,eval-conflicts-rho010-r4-013-zxxnz.18d542e09e3707f6,"reason=Pulled count=1 msg=Container image ""busybox:musl"" already present on machine"
0.0824,Event,ADDED,eval-conflicts-rho010-r4-013-zxxnz.18d542e0a379620c,reason=Created count=1 msg=Created container: task
0.0825,Event,ADDED,eval-conflicts-rho010-r4-013-zxxnz.18d542e0a77d477a,reason=Started count=1 msg=Started container task
0.0827,Event,ADDED,eval-conflicts-rho010-r4-013.18d542dbeeee44fd,reason=SuccessfulCreate count=1 msg=Created pod: eval-conflicts-rho010-r4-013-zxxnz
0.083,Event,ADDED,eval-conflicts-rho010-r4-013.18d542e6448f559d,reason=Completed count=1 msg=Job completed
0.0832,Event,ADDED,eval-conflicts-rho010-r4-014-h6c4w.18d542dc2bd274e7,reason=Scheduled count=None msg=Successfully assigned compute/eval-conflicts-rho010-r4-014-h6c4w to kind-worker
0.0834,Event,ADDED,eval-conflicts-rho010-r4-014-h6c4w.18d542dc4caf00b0,"reason=Pulled count=1 msg=Container image ""busybox:musl"" already present on machine"
0.0835,Event,ADDED,eval-conflicts-rho010-r4-014-h6c4w.18d542dc4ddf3545,reason=Created count=1 msg=Created container: task
0.0839,Event,ADDED,eval-conflicts-rho010-r4-014-h6c4w.18d542dc55711597,reason=Started count=1 msg=Started container task
0.084,Event,ADDED,eval-conflicts-rho010-r4-014.18d542dc2a6b141c,reason=SuccessfulCreate count=1 msg=Created pod: eval-conflicts-rho010-r4-014-h6c4w
0.0842,Event,ADDED,eval-conflicts-rho010-r4-014.18d542e1c4b8ce0c,reason=Completed count=1 msg=Job completed
0.0845,Event,ADDED,eval-conflicts-rho010-r4-015-vxq2b.18d542dc641f44cc,reason=Scheduled count=None msg=Successfully assigned compute/eval-conflicts-rho010-r4-015-vxq2b to kind-worker4
0.0847,Event,ADDED,eval-conflicts-rho010-r4-015-vxq2b.18d542dc903c09ca,"reason=Pulled count=1 msg=Container image ""busybox:musl"" already present on machine"
0.0848,Event,ADDED,eval-conflicts-rho010-r4-015-vxq2b.18d542dc916e0fe0,reason=Created count=1 msg=Created container: task
0.085,Event,ADDED,eval-conflicts-rho010-r4-015-vxq2b.18d542dc98e1bc11,reason=Started count=1 msg=Started container task
0.0855,Event,ADDED,eval-conflicts-rho010-r4-015.18d542dc62dc4418,reason=SuccessfulCreate count=1 msg=Created pod: eval-conflicts-rho010-r4-015-vxq2b
0.0857,Event,ADDED,eval-conflicts-rho010-r4-015.18d542e215bc14df,reason=Completed count=1 msg=Job completed
0.0858,Event,ADDED,eval-conflicts-rho010-r4-016-jsb5t.18d542dca393c535,reason=Scheduled count=None msg=Successfully assigned compute/eval-conflicts-rho010-r4-016-jsb5t to kind-worker4
0.086,Event,ADDED,eval-conflicts-rho010-r4-016-jsb5t.18d542dcbfe8ee89,"reason=Pulled count=1 msg=Container image ""busybox:musl"" already present on machine"
0.0863,Event,ADDED,eval-conflicts-rho010-r4-016-jsb5t.18d542dcc12b1d2b,reason=Created count=1 msg=Created container: task
0.0864,Event,ADDED,eval-conflicts-rho010-r4-016-jsb5t.18d542dcca5caf71,reason=Started count=1 msg=Started container task
0.0866,Event,ADDED,eval-conflicts-rho010-r4-016.18d542dca25e8cca,reason=SuccessfulCreate count=1 msg=Created pod: eval-conflicts-rho010-r4-016-jsb5t
0.0868,Event,ADDED,eval-conflicts-rho010-r4-016.18d542e24bb6bb37,reason=Completed count=1 msg=Job completed
0.087,Event,ADDED,eval-conflicts-rho010-r4-017-84r7b.18d542dcdb10378a,reason=Scheduled count=None msg=Successfully assigned compute/eval-conflicts-rho010-r4-017-84r7b to kind-worker5
0.0871,Event,ADDED,eval-conflicts-rho010-r4-017-84r7b.18d542dcf5711f13,"reason=Pulled count=1 msg=Container image ""busybox:musl"" already present on machine"
0.0873,Event,ADDED,eval-conflicts-rho010-r4-017-84r7b.18d542dcf6ab384e,reason=Created count=1 msg=Created container: task
0.0875,Event,ADDED,eval-conflicts-rho010-r4-017-84r7b.18d542dcf88c8b30,reason=Started count=1 msg=Started container task
0.0877,Event,ADDED,eval-conflicts-rho010-r4-017.18d542dcd9f2ad29,reason=SuccessfulCreate count=1 msg=Created pod: eval-conflicts-rho010-r4-017-84r7b
0.0879,Event,ADDED,eval-conflicts-rho010-r4-017.18d542e29d54cb79,reason=Completed count=1 msg=Job completed
0.0882,TaskRequest,ADDED,eval-conflicts-rho030-r3-000,phase=None job=None
0.0885,Event,ADDED,eval-conflicts-rho010-r4-018-s7lkt.18d542dd1a12a253,"reason=FailedScheduling count=None msg=0/6 nodes are available: 3 c_wall violated: 1 conflicting context pair(s) with node memory, 3 node(s) had untolerated taint(s). no new claims to deallocate, preemption: 0/6 nodes are available: 3 No preemption victims found for incoming pod, 3 Preemption is not helpful for scheduling."
0.0887,Event,ADDED,eval-conflicts-rho010-r4-018-s7lkt.18d542dd1f3cb571,"reason=FailedScheduling count=None msg=0/6 nodes are available: 3 c_wall violated: 1 conflicting context pair(s) with node memory, 3 node(s) had untolerated taint(s). no new claims to deallocate, preemption: 0/6 nodes are available: 3 No preemption victims found for incoming pod, 3 Preemption is not helpful for scheduling."
0.0889,Event,ADDED,eval-conflicts-rho010-r4-018-s7lkt.18d542dd2afc1903,"reason=FailedScheduling count=None msg=0/6 nodes are available: 2 c_wall violated: 1 conflicting context pair(s) with node memory, 4 node(s) had untolerated taint(s). no new claims to deallocate, preemption: 0/6 nodes are available: 2 No preemption victims found for incoming pod, 4 Preemption is not helpful for scheduling."
0.0894,Event,ADDED,eval-conflicts-rho010-r4-018-s7lkt.18d542dd389e1460,"reason=FailedScheduling count=None msg=0/6 nodes are available: 1 c_wall violated: 1 conflicting context pair(s) with node memory, 5 node(s) had untolerated taint(s). no new claims to deallocate, preemption: 0/6 nodes are available: 1 No preemption victims found for incoming pod, 5 Preemption is not helpful for scheduling."
0.0896,Event,ADDED,eval-conflicts-rho010-r4-018-s7lkt.18d542e079af29c5,reason=Scheduled count=None msg=Successfully assigned compute/eval-conflicts-rho010-r4-018-s7lkt to kind-worker3
0.0898,Event,ADDED,eval-conflicts-rho010-r4-018-s7lkt.18d542e09c8975ec,"reason=Pulled count=1 msg=Container image ""busybox:musl"" already present on machine"
0.0899,Event,ADDED,eval-conflicts-rho010-r4-018-s7lkt.18d542e0a0c096c3,reason=Created count=1 msg=Created container: task
0.0903,Event,ADDED,eval-conflicts-rho010-r4-018-s7lkt.18d542e0a729693c,reason=Started count=1 msg=Started container task
0.0905,Event,ADDED,eval-conflicts-rho010-r4-018.18d542dd1952cbc3,reason=SuccessfulCreate count=1 msg=Created pod: eval-conflicts-rho010-r4-018-s7lkt
0.0907,Event,ADDED,eval-conflicts-rho010-r4-018.18d542e60fc57899,reason=Completed count=1 msg=Job completed
0.091,Event,ADDED,eval-conflicts-rho010-r4-019-27ghd.18d542dd51d4ba5d,reason=Scheduled count=None msg=Successfully assigned compute/eval-conflicts-rho010-r4-019-27ghd to kind-worker
0.0912,Event,ADDED,eval-conflicts-rho010-r4-019-27ghd.18d542dd6b350b31,"reason=Pulled count=1 msg=Container image ""busybox:musl"" already present on machine"
0.0913,Event,ADDED,eval-conflicts-rho010-r4-019-27ghd.18d542dd6c601ea7,reason=Created count=1 msg=Created container: task
0.0916,Event,ADDED,eval-conflicts-rho010-r4-019-27ghd.18d542dd708b3c6a,reason=Started count=1 msg=Started container task
0.0919,Event,ADDED,eval-conflicts-rho010-r4-019.18d542dd5133785a,reason=SuccessfulCreate count=1 msg=Created pod: eval-conflicts-rho010-r4-019-27ghd
0.092,Event,ADDED,eval-conflicts-rho010-r4-019.18d542e2ea973431,reason=Completed count=1 msg=Job completed
0.0922,Event,ADDED,eval-conflicts-rho010-r4-020-56tjm.18d542dd8d774cf6,reason=Scheduled count=None msg=Successfully assigned compute/eval-conflicts-rho010-r4-020-56tjm to kind-worker
0.0924,Event,ADDED,eval-conflicts-rho010-r4-020-56tjm.18d542dda8e91dfc,"reason=Pulled count=1 msg=Container image ""busybox:musl"" already present on machine"
0.0926,Event,ADDED,eval-conflicts-rho010-r4-020-56tjm.18d542dda9fa2c10,reason=Created count=1 msg=Created container: task
0.0927,Event,ADDED,eval-conflicts-rho010-r4-020-56tjm.18d542ddadfb70e4,reason=Started count=1 msg=Started container task
0.0929,Event,ADDED,eval-conflicts-rho010-r4-020.18d542dd8ce8687a,reason=SuccessfulCreate count=1 msg=Created pod: eval-conflicts-rho010-r4-020-56tjm
0.0931,Event,ADDED,eval-conflicts-rho010-r4-020.18d542e3269510f1,reason=Completed count=1 msg=Job completed
0.0932,Event,ADDED,eval-conflicts-rho010-r4-021-dq9cz.18d542ddc89eff53,"reason=FailedScheduling count=None msg=0/6 nodes are available: 1 c_wall violated: 1 conflicting context pair(s) with node memory, 5 node(s) had untolerated taint(s). no new claims to deallocate, preemption: 0/6 nodes are available: 1 No preemption victims found for incoming pod, 5 Preemption is not helpful for scheduling."
0.0934,Event,ADDED,eval-conflicts-rho010-r4-021-dq9cz.18d542ddc9347f84,"reason=FailedScheduling count=None msg=0/6 nodes are available: 1 c_wall violated: 1 conflicting context pair(s) with node memory, 5 node(s) had untolerated taint(s). no new claims to deallocate, preemption: 0/6 nodes are available: 1 No preemption victims found for incoming pod, 5 Preemption is not helpful for scheduling."
0.0937,Event,ADDED,eval-conflicts-rho010-r4-021-dq9cz.18d542e07eb22ee4,reason=Scheduled count=None msg=Successfully assigned compute/eval-conflicts-rho010-r4-021-dq9cz to kind-worker3
0.0939,Event,ADDED,eval-conflicts-rho010-r4-021-dq9cz.18d542e09dfb9094,"reason=Pulled count=1 msg=Container image ""busybox:musl"" already present on machine"
0.0941,Event,ADDED,eval-conflicts-rho010-r4-021-dq9cz.18d542e0a3177dc2,reason=Created count=1 msg=Created container: task
0.0942,Event,ADDED,eval-conflicts-rho010-r4-021-dq9cz.18d542e0a8049803,reason=Started count=1 msg=Started container task
0.0943,TaskRequest,MODIFIED,eval-conflicts-rho030-r3-000,phase=Pending job=None
0.0946,Event,ADDED,eval-conflicts-rho010-r4-021.18d542ddc85c94fc,reason=SuccessfulCreate count=1 msg=Created pod: eval-conflicts-rho010-r4-021-dq9cz
0.0948,Event,ADDED,eval-conflicts-rho010-r4-021.18d542e64492147d,reason=Completed count=1 msg=Job completed
0.095,Event,ADDED,eval-conflicts-rho010-r4-022-mxz8h.18d542de0847cb28,reason=Scheduled count=None msg=Successfully assigned compute/eval-conflicts-rho010-r4-022-mxz8h to kind-worker
0.0952,Event,ADDED,eval-conflicts-rho010-r4-022-mxz8h.18d542de2562f77e,"reason=Pulled count=1 msg=Container image ""busybox:musl"" already present on machine"
0.0955,Event,ADDED,eval-conflicts-rho010-r4-022-mxz8h.18d542de2713c34e,reason=Created count=1 msg=Created container: task
0.0957,Event,ADDED,eval-conflicts-rho010-r4-022-mxz8h.18d542de307be0ef,reason=Started count=1 msg=Started container task
0.0959,Event,ADDED,eval-conflicts-rho010-r4-022.18d542de07b954df,reason=SuccessfulCreate count=1 msg=Created pod: eval-conflicts-rho010-r4-022-mxz8h
0.0962,Event,ADDED,eval-conflicts-rho010-r4-022.18d542e39e2a59c0,reason=Completed count=1 msg=Job completed
0.0963,Event,ADDED,eval-conflicts-rho010-r4-023-ztcfv.18d542de457f12c5,reason=Scheduled count=None msg=Successfully assigned compute/eval-conflicts-rho010-r4-023-ztcfv to kind-worker
0.0965,Event,ADDED,eval-conflicts-rho010-r4-023-ztcfv.18d542de6adc7f27,"reason=Pulled count=1 msg=Container image ""busybox:musl"" already present on machine"
0.0967,Event,ADDED,eval-conflicts-rho010-r4-023-ztcfv.18d542de6beb139b,reason=Created count=1 msg=Created container: task
0.097,Event,ADDED,eval-conflicts-rho010-r4-023-ztcfv.18d542de709d0271,reason=Started count=1 msg=Started container task
0.0972,Event,ADDED,eval-conflicts-rho010-r4-023.18d542de44f0b223,reason=SuccessfulCreate count=1 msg=Created pod: eval-conflicts-rho010-r4-023-ztcfv
0.0973,Event,ADDED,eval-conflicts-rho010-r4-023.18d542e3d94ec6d6,reason=Completed count=1 msg=Job completed
0.0975,Event,ADDED,eval-conflicts-rho010-r4-024-fqs7m.18d542de80afeee1,reason=Scheduled count=None msg=Successfully assigned compute/eval-conflicts-rho010-r4-024-fqs7m to kind-worker
0.0977,Event,ADDED,eval-conflicts-rho010-r4-024-fqs7m.18d542dea367ceb2,"reason=Pulled count=1 msg=Container image ""busybox:musl"" already present on machine"
0.0979,Event,ADDED,eval-conflicts-rho010-r4-024-fqs7m.18d542dea4a9fec9,reason=Created count=1 msg=Created container: task
0.0981,Event,ADDED,eval-conflicts-rho010-r4-024-fqs7m.18d542deacf94f64,reason=Started count=1 msg=Started container task
0.0984,Event,ADDED,eval-conflicts-rho010-r4-024.18d542de80274f2a,reason=SuccessfulCreate count=1 msg=Created pod: eval-conflicts-rho010-r4-024-fqs7m
0.0986,Event,ADDED,eval-conflicts-rho010-r4-024.18d542e3d9c2a07a,reason=Completed count=1 msg=Job completed
0.0987,Event,ADDED,eval-conflicts-rho010-r4-025-pr4v4.18d542deb7ebbd00,reason=Scheduled count=None msg=Successfully assigned compute/eval-conflicts-rho010-r4-025-pr4v4 to kind-worker
0.0989,Event,ADDED,eval-conflicts-rho010-r4-025-pr4v4.18d542ded4dc93a4,"reason=Pulled count=1 msg=Container image ""busybox:musl"" already present on machine"
0.0993,Event,ADDED,eval-conflicts-rho010-r4-025-pr4v4.18d542ded5f975ae,reason=Created count=1 msg=Created container: task
0.0995,Event,ADDED,eval-conflicts-rho010-r4-025-pr4v4.18d542dedb048cab,reason=Started count=1 msg=Started container task
0.0997,Event,ADDED,eval-conflicts-rho010-r4-025.18d542deb75f3f4c,reason=SuccessfulCreate count=1 msg=Created pod: eval-conflicts-rho010-r4-025-pr4v4
0.1001,Event,ADDED,eval-conflicts-rho010-r4-025.18d542e45148e128,reason=Completed count=1 msg=Job completed
0.1003,Event,ADDED,eval-conflicts-rho010-r4-026-2b77v.18d542def65d4110,"reason=FailedScheduling count=None msg=0/6 nodes are available: 6 node(s) had untolerated taint(s). no new claims to deallocate, preemption: 0/6 nodes are available: 6 Preemption is not helpful for scheduling."
0.1005,Event,ADDED,eval-conflicts-rho010-r4-026-2b77v.18d542e07eb479ff,reason=Scheduled count=None msg=Successfully assigned compute/eval-conflicts-rho010-r4-026-2b77v to kind-worker3
0.1006,Event,ADDED,eval-conflicts-rho010-r4-026-2b77v.18d542e09d6046fd,"reason=Pulled count=1 msg=Container image ""busybox:musl"" already present on machine"
0.101,Event,ADDED,eval-conflicts-rho010-r4-026-2b77v.18d542e0a1a692d3,reason=Created count=1 msg=Created container: task
0.1012,Event,ADDED,eval-conflicts-rho010-r4-026-2b77v.18d542e0a77e2cc0,reason=Started count=1 msg=Started container task
0.1014,Event,ADDED,eval-conflicts-rho010-r4-026.18d542def652accf,reason=SuccessfulCreate count=1 msg=Created pod: eval-conflicts-rho010-r4-026-2b77v
0.1016,Event,ADDED,eval-conflicts-rho010-r4-026.18d542e6449108fd,reason=Completed count=1 msg=Job completed
0.1021,Event,ADDED,eval-conflicts-rho010-r4-027-whv28.18d542df2df7ad92,"reason=FailedScheduling count=None msg=0/6 nodes are available: 6 node(s) had untolerated taint(s). no new claims to deallocate, preemption: 0/6 nodes are available: 6 Preemption is not helpful for scheduling."
0.1022,Event,ADDED,eval-conflicts-rho010-r4-027-whv28.18d542e07f4344d6,reason=Scheduled count=None msg=Successfully assigned compute/eval-conflicts-rho010-r4-027-whv28 to kind-worker3
0.1024,Event,ADDED,eval-conflicts-rho010-r4-027-whv28.18d542e09ed62c7f,"reason=Pulled count=1 msg=Container image ""busybox:musl"" already present on machine"
0.1027,Event,ADDED,eval-conflicts-rho010-r4-027-whv28.18d542e0a3f275c7,reason=Created count=1 msg=Created container: task
0.1029,Event,ADDED,eval-conflicts-rho010-r4-027-whv28.18d542e0a95f7b9c,reason=Started count=1 msg=Started container task
0.103,Event,ADDED,eval-conflicts-rho010-r4-027.18d542df2dec1d2e,reason=SuccessfulCreate count=1 msg=Created pod: eval-conflicts-rho010-r4-027-whv28
0.1032,Event,ADDED,eval-conflicts-rho010-r4-027.18d542e68dbb50ba,reason=Completed count=1 msg=Job completed
0.1034,Event,ADDED,eval-conflicts-rho010-r4-028-kqgn6.18d542df6a31e570,"reason=FailedScheduling count=None msg=0/6 nodes are available: 6 node(s) had untolerated taint(s). no new claims to deallocate, preemption: 0/6 nodes are available: 6 Preemption is not helpful for scheduling."
0.1035,Event,ADDED,eval-conflicts-rho010-r4-028-kqgn6.18d542e07f6b075f,reason=Scheduled count=None msg=Successfully assigned compute/eval-conflicts-rho010-r4-028-kqgn6 to kind-worker3
0.1037,Event,ADDED,eval-conflicts-rho010-r4-028-kqgn6.18d542e09ef69bb0,"reason=Pulled count=1 msg=Container image ""busybox:musl"" already present on machine"
0.1039,Event,ADDED,eval-conflicts-rho010-r4-028-kqgn6.18d542e0a43483d9,reason=Created count=1 msg=Created container: task
0.104,Event,ADDED,eval-conflicts-rho010-r4-028-kqgn6.18d542e0a8dd059e,reason=Started count=1 msg=Started container task
0.1042,Event,ADDED,eval-conflicts-rho010-r4-028.18d542df6a24a065,reason=SuccessfulCreate count=1 msg=Created pod: eval-conflicts-rho010-r4-028-kqgn6
0.1045,Event,ADDED,eval-conflicts-rho010-r4-028.18d542e6942631a7,reason=Completed count=1 msg=Job completed
0.1046,Event,ADDED,eval-conflicts-rho010-r4-029-6rnkl.18d542dfa941b0aa,"reason=FailedScheduling count=None msg=0/6 nodes are available: 6 node(s) had untolerated taint(s). no new claims to deallocate, preemption: 0/6 nodes are available: 6 Preemption is not helpful for scheduling."
0.1048,Event,ADDED,eval-conflicts-rho010-r4-029-6rnkl.18d542e0802e633d,reason=Scheduled count=None msg=Successfully assigned compute/eval-conflicts-rho010-r4-029-6rnkl to kind-worker3
0.105,Event,ADDED,eval-conflicts-rho010-r4-029-6rnkl.18d542e09fe098ff,"reason=Pulled count=1 msg=Container image ""busybox:musl"" already present on machine"
0.1052,Event,ADDED,eval-conflicts-rho010-r4-029-6rnkl.18d542e0a4c71bb3,reason=Created count=1 msg=Created container: task
0.1053,Event,ADDED,eval-conflicts-rho010-r4-029-6rnkl.18d542e0a9cba865,reason=Started count=1 msg=Started container task
0.1055,Event,ADDED,eval-conflicts-rho010-r4-029.18d542dfa9387efa,reason=SuccessfulCreate count=1 msg=Created pod: eval-conflicts-rho010-r4-029-6rnkl
0.1056,Event,ADDED,eval-conflicts-rho010-r4-029.18d542e607c291b7,reason=Completed count=1 msg=Job completed
0.1058,Event,ADDED,eval-conflicts-rho010-r4-030-jwmk7.18d542dfe72081bc,"reason=FailedScheduling count=None msg=0/6 nodes are available: 6 node(s) had untolerated taint(s). no new claims to deallocate, preemption: 0/6 nodes are available: 6 Preemption is not helpful for scheduling."
0.1059,Event,ADDED,eval-conflicts-rho010-r4-030-jwmk7.18d542e0807bd3c4,reason=Scheduled count=None msg=Successfully assigned compute/eval-conflicts-rho010-r4-030-jwmk7 to kind-worker3
0.1061,Event,ADDED,eval-conflicts-rho010-r4-030-jwmk7.18d542e0a16a87e8,"reason=Pulled count=1 msg=Container image ""busybox:musl"" already present on machine"
0.1063,Event,ADDED,eval-conflicts-rho010-r4-030-jwmk7.18d542e0a52a7d42,reason=Created count=1 msg=Created container: task
0.1065,Event,ADDED,eval-conflicts-rho010-r4-030-jwmk7.18d542e0a9cb8334,reason=Started count=1 msg=Started container task
0.1066,Event,ADDED,eval-conflicts-rho010-r4-030.18d542dfe713acf5,reason=SuccessfulCreate count=1 msg=Created pod: eval-conflicts-rho010-r4-030-jwmk7
0.1068,Event,ADDED,eval-conflicts-rho010-r4-030.18d542e6998819ae,reason=Completed count=1 msg=Job completed
0.107,Event,ADDED,eval-conflicts-rho010-r4-031-bxqp4.18d542e0234e94db,"reason=FailedScheduling count=None msg=0/6 nodes are available: 6 node(s) had untolerated taint(s). no new claims to deallocate, preemption: 0/6 nodes are available: 6 Preemption is not helpful for scheduling."
0.1071,Event,ADDED,eval-conflicts-rho010-r4-031-bxqp4.18d542e080d47607,reason=Scheduled count=None msg=Successfully assigned compute/eval-conflicts-rho010-r4-031-bxqp4 to kind-worker3
0.1073,Event,ADDED,eval-conflicts-rho010-r4-031-bxqp4.18d542e0a12fee9f,"reason=Pulled count=1 msg=Container image ""busybox:musl"" already present on machine"
0.1074,Event,ADDED,eval-conflicts-rho010-r4-031-bxqp4.18d542e0a56e9139,reason=Created count=1 msg=Created container: task
0.1076,Event,ADDED,eval-conflicts-rho010-r4-031-bxqp4.18d542e0aa1100b8,reason=Started count=1 msg=Started container task
0.1078,Event,ADDED,eval-conflicts-rho010-r4-031.18d542e02342c893,reason=SuccessfulCreate count=1 msg=Created pod: eval-conflicts-rho010-r4-031-bxqp4
0.1079,Event,ADDED,eval-conflicts-rho010-r4-031.18d542e6448efb2d,reason=Completed count=1 msg=Job completed
0.1081,Event,ADDED,eval-conflicts-rho010-r4-032-f4tst.18d542e0582f6c74,"reason=FailedScheduling count=None msg=0/6 nodes are available: 6 node(s) had untolerated taint(s). no new claims to deallocate, preemption: 0/6 nodes are available: 6 Preemption is not helpful for scheduling."
0.1082,Event,ADDED,eval-conflicts-rho010-r4-032-f4tst.18d542e087c5bffc,reason=Scheduled count=None msg=Successfully assigned compute/eval-conflicts-rho010-r4-032-f4tst to kind-worker3
0.1084,Event,ADDED,eval-conflicts-rho010-r4-032-f4tst.18d542e0a56b6053,"reason=Pulled count=1 msg=Container image ""busybox:musl"" already present on machine"
0.1086,Event,ADDED,eval-conflicts-rho010-r4-032-f4tst.18d542e0a6b998b1,reason=Created count=1 msg=Created container: task
0.1087,Event,ADDED,eval-conflicts-rho010-r4-032-f4tst.18d542e0aa687ad6,reason=Started count=1 msg=Started container task
0.1089,Event,ADDED,eval-conflicts-rho010-r4-032.18d542e058237da5,reason=SuccessfulCreate count=1 msg=Created pod: eval-conflicts-rho010-r4-032-f4tst
0.1091,Event,ADDED,eval-conflicts-rho010-r4-032.18d542e69c7c6428,reason=Completed count=1 msg=Job completed
0.1092,Event,ADDED,eval-conflicts-rho010-r4-033-5p494.18d542e097388abe,reason=Scheduled count=None msg=Successfully assigned compute/eval-conflicts-rho010-r4-033-5p494 to kind-worker3
0.1094,Event,ADDED,eval-conflicts-rho010-r4-033-5p494.18d542e0b190d9d4,"reason=Pulled count=1 msg=Container image ""busybox:musl"" already present on machine"
0.1096,Event,ADDED,eval-conflicts-rho010-r4-033-5p494.18d542e0b29fc984,reason=Created count=1 msg=Created container: task
0.1097,Event,ADDED,eval-conflicts-rho010-r4-033-5p494.18d542e0b84289a9,reason=Started count=1 msg=Started container task
0.1099,Event,ADDED,eval-conflicts-rho010-r4-033.18d542e096659cb8,reason=SuccessfulCreate count=1 msg=Created pod: eval-conflicts-rho010-r4-033-5p494
0.1101,Event,ADDED,eval-conflicts-rho010-r4-033.18d542e6449017fb,reason=Completed count=1 msg=Job completed
0.1102,Event,ADDED,eval-conflicts-rho010-r4-034-dxkwm.18d542e0cfcdc58f,reason=Scheduled count=None msg=Successfully assigned compute/eval-conflicts-rho010-r4-034-dxkwm to kind-worker3
0.1104,Event,ADDED,eval-conflicts-rho010-r4-034-dxkwm.18d542e0ebf287d0,"reason=Pulled count=1 msg=Container image ""busybox:musl"" already present on machine"
0.1108,Event,ADDED,eval-conflicts-rho010-r4-034-dxkwm.18d542e0ecf9d27b,reason=Created count=1 msg=Created container: task
0.111,Event,ADDED,eval-conflicts-rho010-r4-034-dxkwm.18d542e0f2f6a0a5,reason=Started count=1 msg=Started container task
0.1112,Event,ADDED,eval-conflicts-rho010-r4-034.18d542e0cf5f2bb8,reason=SuccessfulCreate count=1 msg=Created pod: eval-conflicts-rho010-r4-034-dxkwm
0.112,Job,ADDED,eval-conflicts-rho030-r3-000,
0.1124,Event,ADDED,eval-conflicts-rho010-r4-034.18d542e6c3372e65,reason=Completed count=1 msg=Job completed
0.1125,Event,ADDED,eval-conflicts-rho010-r4-035-bmwsq.18d542e112963074,reason=Scheduled count=None msg=Successfully assigned compute/eval-conflicts-rho010-r4-035-bmwsq to kind-worker3
0.1127,Event,ADDED,eval-conflicts-rho010-r4-035-bmwsq.18d542e137ebe5da,"reason=Pulled count=1 msg=Container image ""busybox:musl"" already present on machine"
0.1129,Event,ADDED,eval-conflicts-rho010-r4-035-bmwsq.18d542e139211ce8,reason=Created count=1 msg=Created container: task
0.1133,Event,ADDED,eval-conflicts-rho010-r4-035-bmwsq.18d542e143bcc246,reason=Started count=1 msg=Started container task
0.1134,Event,ADDED,eval-conflicts-rho010-r4-035.18d542e111f4bc61,reason=SuccessfulCreate count=1 msg=Created pod: eval-conflicts-rho010-r4-035-bmwsq
0.1136,Event,ADDED,eval-conflicts-rho010-r4-035.18d542e6c35c3a1d,reason=Completed count=1 msg=Job completed
0.1138,Event,ADDED,eval-conflicts-rho010-r4-036-xdbn5.18d542e146b920db,"reason=FailedScheduling count=None msg=0/6 nodes are available: 1 c_wall violated: 2 conflicting context pair(s) with node memory, 5 node(s) had untolerated taint(s). no new claims to deallocate, preemption: 0/6 nodes are available: 1 No preemption victims found for incoming pod, 5 Preemption is not helpful for scheduling."
0.1142,Event,ADDED,eval-conflicts-rho010-r4-036-xdbn5.18d542e14730f0e8,"reason=FailedScheduling count=None msg=0/6 nodes are available: 1 c_wall violated: 2 conflicting context pair(s) with node memory, 5 node(s) had untolerated taint(s). no new claims to deallocate, preemption: 0/6 nodes are available: 1 No preemption victims found for incoming pod, 5 Preemption is not helpful for scheduling."
0.1144,Event,ADDED,eval-conflicts-rho010-r4-036-xdbn5.18d542e5401cef31,reason=Scheduled count=None msg=Successfully assigned compute/eval-conflicts-rho010-r4-036-xdbn5 to kind-worker2
0.1146,Event,ADDED,eval-conflicts-rho010-r4-036-xdbn5.18d542e55e1873b6,"reason=Pulled count=1 msg=Container image ""busybox:musl"" already present on machine"
0.1147,TaskRequest,MODIFIED,eval-conflicts-rho030-r3-000,phase=Scheduled job=None
0.115,Event,ADDED,eval-conflicts-rho010-r4-036-xdbn5.18d542e560937064,reason=Created count=1 msg=Created container: task
0.1152,Event,ADDED,eval-conflicts-rho010-r4-036-xdbn5.18d542e56780943f,reason=Started count=1 msg=Started container task
0.1154,Event,ADDED,eval-conflicts-rho010-r4-036.18d542e1467452ee,reason=SuccessfulCreate count=1 msg=Created pod: eval-conflicts-rho010-r4-036-xdbn5
0.1158,Event,ADDED,eval-conflicts-rho010-r4-036.18d542ead4b217c4,reason=Completed count=1 msg=Job completed
0.1162,Event,ADDED,eval-conflicts-rho010-r4-037-fg4rj.18d542e18845df3d,"reason=FailedScheduling count=None msg=0/6 nodes are available: 1 c_wall violated: 1 conflicting context pair(s) with node memory, 5 node(s) had untolerated taint(s). no new claims to deallocate, preemption: 0/6 nodes are available: 1 No preemption victims found for incoming pod, 5 Preemption is not helpful for scheduling."
0.1165,Event,ADDED,eval-conflicts-rho010-r4-037-fg4rj.18d542e188bfe32f,"reason=FailedScheduling count=None msg=0/6 nodes are available: 1 c_wall violated: 1 conflicting context pair(s) with node memory, 5 node(s) had untolerated taint(s). no new claims to deallocate, preemption: 0/6 nodes are available: 1 No preemption victims found for incoming pod, 5 Preemption is not helpful for scheduling."
0.1166,Event,ADDED,eval-conflicts-rho010-r4-037-fg4rj.18d542e53c1832c0,reason=Scheduled count=None msg=Successfully assigned compute/eval-conflicts-rho010-r4-037-fg4rj to kind-worker2
0.1173,Event,ADDED,eval-conflicts-rho010-r4-037-fg4rj.18d542e55e40e6e6,"reason=Pulled count=1 msg=Container image ""busybox:musl"" already present on machine"
0.1179,Event,ADDED,eval-conflicts-rho010-r4-037-fg4rj.18d542e560ac4ac2,reason=Created count=1 msg=Created container: task
0.1182,Event,ADDED,eval-conflicts-rho010-r4-037-fg4rj.18d542e567822b8f,reason=Started count=1 msg=Started container task
0.1192,Pod,ADDED,eval-conflicts-rho030-r3-000-mh4l5,phase=Pending node=None
0.1196,Event,ADDED,eval-conflicts-rho010-r4-037.18d542e1880865f6,reason=SuccessfulCreate count=1 msg=Created pod: eval-conflicts-rho010-r4-037-fg4rj
0.1198,Event,ADDED,eval-conflicts-rho010-r4-037.18d542ea99b1eb45,reason=Completed count=1 msg=Job completed
0.12,Event,ADDED,eval-conflicts-rho010-r4-038-rsbkb.18d542e1be5a33fe,reason=Scheduled count=None msg=Successfully assigned compute/eval-conflicts-rho010-r4-038-rsbkb to kind-worker3
0.1202,Event,ADDED,eval-conflicts-rho010-r4-038-rsbkb.18d542e1d96cb3e5,"reason=Pulled count=1 msg=Container image ""busybox:musl"" already present on machine"
0.1207,Event,ADDED,eval-conflicts-rho010-r4-038-rsbkb.18d542e1dad1bf5d,reason=Created count=1 msg=Created container: task
0.1211,Event,ADDED,eval-conflicts-rho010-r4-038-rsbkb.18d542e1e082228b,reason=Started count=1 msg=Started container task
0.1214,Event,ADDED,eval-conflicts-rho010-r4-038.18d542e1bdd5a767,reason=SuccessfulCreate count=1 msg=Created pod: eval-conflicts-rho010-r4-038-rsbkb
0.1219,Event,ADDED,eval-conflicts-rho010-r4-038.18d542e77f443c71,reason=Completed count=1 msg=Job completed
0.1226,Event,ADDED,eval-conflicts-rho010-r4-039-25g2s.18d542e1fa0a0ef5,reason=Scheduled count=None msg=Successfully assigned compute/eval-conflicts-rho010-r4-039-25g2s to kind-worker3
0.123,Event,ADDED,eval-conflicts-rho010-r4-039-25g2s.18d542e214a58fc6,"reason=Pulled count=1 msg=Container image ""busybox:musl"" already present on machine"
0.1232,Event,ADDED,eval-conflicts-rho010-r4-039-25g2s.18d542e215d6a576,reason=Created count=1 msg=Created container: task
0.1236,Event,ADDED,eval-conflicts-rho010-r4-039-25g2s.18d542e217f5f7d3,reason=Started count=1 msg=Started container task
0.1238,Event,ADDED,eval-conflicts-rho010-r4-039.18d542e1f982ed98,reason=SuccessfulCreate count=1 msg=Created pod: eval-conflicts-rho010-r4-039-25g2s
0.124,Event,ADDED,eval-conflicts-rho010-r4-039.18d542e7b233cfc6,reason=Completed count=1 msg=Job completed
0.1242,Event,ADDED,eval-conflicts-rho010-r4-040-x9pqt.18d542e23a07de0f,"reason=FailedScheduling count=None msg=0/6 nodes are available: 1 c_wall violated: 1 conflicting context pair(s) with node memory, 5 node(s) had untolerated taint(s). no new claims to deallocate, preemption: 0/6 nodes are available: 1 No preemption victims found for incoming pod, 5 Preemption is not helpful for scheduling."
0.1249,Job,MODIFIED,eval-conflicts-rho030-r3-000,
0.1255,Event,ADDED,eval-conflicts-rho010-r4-040-x9pqt.18d542e23a874d1b,"reason=FailedScheduling count=None msg=0/6 nodes are available: 1 c_wall violated: 1 conflicting context pair(s) with node memory, 5 node(s) had untolerated taint(s). no new claims to deallocate, preemption: 0/6 nodes are available: 1 No preemption victims found for incoming pod, 5 Preemption is not helpful for scheduling."
0.126,Event,ADDED,eval-conflicts-rho010-r4-040-x9pqt.18d542e53d6b7069,reason=Scheduled count=None msg=Successfully assigned compute/eval-conflicts-rho010-r4-040-x9pqt to kind-worker2
0.1263,Event,ADDED,eval-conflicts-rho010-r4-040-x9pqt.18d542e56788e916,"reason=Pulled count=1 msg=Container image ""busybox:musl"" already present on machine"
0.1267,Event,ADDED,eval-conflicts-rho010-r4-040-x9pqt.18d542e569d260e5,reason=Created count=1 msg=Created container: task
0.1269,Event,ADDED,eval-conflicts-rho010-r4-040-x9pqt.18d542e57039cd6c,reason=Started count=1 msg=Started container task
0.127,Event,ADDED,eval-conflicts-rho010-r4-040.18d542e239c752dc,reason=SuccessfulCreate count=1 msg=Created pod: eval-conflicts-rho010-r4-040-x9pqt
0.1272,Event,ADDED,eval-conflicts-rho010-r4-040.18d542ead56caf76,reason=Completed count=1 msg=Job completed
0.1275,Event,ADDED,eval-conflicts-rho010-r4-041-bb56h.18d542e2710a0941,reason=Scheduled count=None msg=Successfully assigned compute/eval-conflicts-rho010-r4-041-bb56h to kind-worker3
0.1278,Event,ADDED,eval-conflicts-rho010-r4-041-bb56h.18d542e28a1adfcb,"reason=Pulled count=1 msg=Container image ""busybox:musl"" already present on machine"
0.1279,Event,ADDED,eval-conflicts-rho010-r4-041-bb56h.18d542e28b9540a0,reason=Created count=1 msg=Created container: task
0.1283,Event,ADDED,eval-conflicts-rho010-r4-041-bb56h.18d542e291e904ee,reason=Started count=1 msg=Started container task
0.1285,Event,ADDED,eval-conflicts-rho010-r4-041.18d542e27086bdb2,reason=SuccessfulCreate count=1 msg=Created pod: eval-conflicts-rho010-r4-041-bb56h
0.1287,Event,ADDED,eval-conflicts-rho010-r4-041.18d542e82a1bec2d,reason=Completed count=1 msg=Job completed
0.1289,Event,ADDED,eval-conflicts-rho010-r4-042-hthmt.18d542e2aca72bfc,reason=Scheduled count=None msg=Successfully assigned compute/eval-conflicts-rho010-r4-042-hthmt to kind-worker3
0.1293,Event,ADDED,eval-conflicts-rho010-r4-042-hthmt.18d542e2cd050785,"reason=Pulled count=1 msg=Container image ""busybox:musl"" already present on machine"
0.1295,Event,ADDED,eval-conflicts-rho010-r4-042-hthmt.18d542e2ce29ed2b,reason=Created count=1 msg=Created container: task
0.1297,Event,ADDED,eval-conflicts-rho010-r4-042-hthmt.18d542e2d2c6ce78,reason=Started count=1 msg=Started container task
0.13,Event,ADDED,eval-conflicts-rho010-r4-042.18d542e2ac11089b,reason=SuccessfulCreate count=1 msg=Created pod: eval-conflicts-rho010-r4-042-hthmt
0.1302,Event,ADDED,eval-conflicts-rho010-r4-042.18d542e868586bfa,reason=Completed count=1 msg=Job completed
0.1304,Event,ADDED,eval-conflicts-rho010-r4-043-4rsdw.18d542e2ec67dace,"reason=FailedScheduling count=None msg=0/6 nodes are available: 1 c_wall violated: 2 conflicting context pair(s) with node memory, 5 node(s) had untolerated taint(s). no new claims to deallocate, preemption: 0/6 nodes are available: 1 No preemption victims found for incoming pod, 5 Preemption is not helpful for scheduling."
0.1306,Event,ADDED,eval-conflicts-rho010-r4-043-4rsdw.18d542e2ece663fa,"reason=FailedScheduling count=None msg=0/6 nodes are available: 1 c_wall violated: 2 conflicting context pair(s) with node memory, 5 node(s) had untolerated taint(s). no new claims to deallocate, preemption: 0/6 nodes are available: 1 No preemption victims found for incoming pod, 5 Preemption is not helpful for scheduling."
0.1308,Event,ADDED,eval-conflicts-rho010-r4-043-4rsdw.18d542e53c5ae11f,reason=Scheduled count=None msg=Successfully assigned compute/eval-conflicts-rho010-r4-043-4rsdw to kind-worker2
0.131,Event,ADDED,eval-conflicts-rho010-r4-043-4rsdw.18d542e55e059060,"reason=Pulled count=1 msg=Container image ""busybox:musl"" already present on machine"
0.1312,Event,ADDED,eval-conflicts-rho010-r4-043-4rsdw.18d542e55fdcda49,reason=Created count=1 msg=Created container: task
0.1314,Event,ADDED,eval-conflicts-rho010-r4-043-4rsdw.18d542e56781b34c,reason=Started count=1 msg=Started container task
0.1315,Event,ADDED,eval-conflicts-rho010-r4-043.18d542e2ec2712b4,reason=SuccessfulCreate count=1 msg=Created pod: eval-conflicts-rho010-r4-043-4rsdw
0.1317,Event,ADDED,eval-conflicts-rho010-r4-043.18d542ead4b05ca3,reason=Completed count=1 msg=Job completed
0.1319,Event,ADDED,eval-conflicts-rho010-r4-044-xpddm.18d542e326c07d22,reason=Scheduled count=None msg=Successfully assigned compute/eval-conflicts-rho010-r4-044-xpddm to kind-worker3
0.1321,Event,ADDED,eval-conflicts-rho010-r4-044-xpddm.18d542e343806826,"reason=Pulled count=1 msg=Container image ""busybox:musl"" already present on machine"
0.1323,Event,ADDED,eval-conflicts-rho010-r4-044-xpddm.18d542e3449dc2c4,reason=Created count=1 msg=Created container: task
0.1328,Event,ADDED,eval-conflicts-rho010-r4-044-xpddm.18d542e348e3045b,reason=Started count=1 msg=Started container task
0.1333,Event,ADDED,eval-conflicts-rho010-r4-044.18d542e326117a14,reason=SuccessfulCreate count=1 msg=Created pod: eval-conflicts-rho010-r4-044-xpddm
0.1336,Event,ADDED,eval-conflicts-rho010-r4-044.18d542e8e3cd7590,reason=Completed count=1 msg=Job completed
0.1338,Event,ADDED,eval-conflicts-rho010-r4-045-qnmmh.18d542e35f8a87c1,reason=Scheduled count=None msg=Successfully assigned compute/eval-conflicts-rho010-r4-045-qnmmh to kind-worker3
0.134,Event,ADDED,eval-conflicts-rho010-r4-045-qnmmh.18d542e37a5822d6,"reason=Pulled count=1 msg=Container image ""busybox:musl"" already present on machine"
0.1347,Job,MODIFIED,eval-conflicts-rho030-r3-000,
0.135,Event,ADDED,eval-conflicts-rho010-r4-045-qnmmh.18d542e37b64f03a,reason=Created count=1 msg=Created container: task
0.1354,Event,ADDED,eval-conflicts-rho010-r4-045-qnmmh.18d542e37dfc1025,reason=Started count=1 msg=Started container task
0.1358,Event,ADDED,eval-conflicts-rho010-r4-045.18d542e35f143eb5,reason=SuccessfulCreate count=1 msg=Created pod: eval-conflicts-rho010-r4-045-qnmmh
0.136,Event,ADDED,eval-conflicts-rho010-r4-045.18d542e91468b592,reason=Completed count=1 msg=Job completed
0.1364,Event,ADDED,eval-conflicts-rho010-r4-046-z9rp4.18d542e39c808f64,reason=Scheduled count=None msg=Successfully assigned compute/eval-conflicts-rho010-r4-046-z9rp4 to kind-worker3
0.1366,Event,ADDED,eval-conflicts-rho010-r4-046-z9rp4.18d542e3bdf4e8a6,"reason=Pulled count=1 msg=Container image ""busybox:musl"" already present on machine"
0.1368,Event,ADDED,eval-conflicts-rho010-r4-046-z9rp4.18d542e3bf1c5d04,reason=Created count=1 msg=Created container: task
0.1377,Event,ADDED,eval-conflicts-rho010-r4-046-z9rp4.18d542e3c656934b,reason=Started count=1 msg=Started container task
0.138,Event,ADDED,eval-conflicts-rho010-r4-046.18d542e39bbf7def,reason=SuccessfulCreate count=1 msg=Created pod: eval-conflicts-rho010-r4-046-z9rp4
0.1383,Event,ADDED,eval-conflicts-rho010-r4-046.18d542e9500c5936,reason=Completed count=1 msg=Job completed
0.1384,Event,ADDED,eval-conflicts-rho010-r4-047-cgg28.18d542e3daedcd6b,reason=Scheduled count=None msg=Successfully assigned compute/eval-conflicts-rho010-r4-047-cgg28 to kind-worker3
0.1388,Event,ADDED,eval-conflicts-rho010-r4-047-cgg28.18d542e3f61f527d,"reason=Pulled count=1 msg=Container image ""busybox:musl"" already present on machine"
0.1392,Event,ADDED,eval-conflicts-rho010-r4-047-cgg28.18d542e3f72e1db4,reason=Created count=1 msg=Created container: task
0.1394,Event,ADDED,eval-conflicts-rho010-r4-047-cgg28.18d542e3fb99a5f6,reason=Started count=1 msg=Started container task
0.1406,Pod,MODIFIED,eval-conflicts-rho030-r3-000-mh4l5,phase=Pending node=kind-worker2
0.1411,Event,ADDED,eval-conflicts-rho010-r4-047.18d542e3da6e452b,reason=SuccessfulCreate count=1 msg=Created pod: eval-conflicts-rho010-r4-047-cgg28
0.1414,Event,ADDED,eval-conflicts-rho010-r4-047.18d542e990450363,reason=Completed count=1 msg=Job completed
0.1416,Event,ADDED,eval-conflicts-rho010-r4-048-f8dlb.18d542e412852044,"reason=FailedScheduling count=None msg=0/6 nodes are available: 1 c_wall violated: 1 conflicting context pair(s) with node memory, 5 node(s) had untolerated taint(s). no new claims to deallocate, preemption: 0/6 nodes are available: 1 No preemption victims found for incoming pod, 5 Preemption is not helpful for scheduling."
0.1419,Event,ADDED,eval-conflicts-rho010-r4-048-f8dlb.18d542e412f97918,"reason=FailedScheduling count=None msg=0/6 nodes are available: 1 c_wall violated: 1 conflicting context pair(s) with node memory, 5 node(s) had untolerated taint(s). no new claims to deallocate, preemption: 0/6 nodes are available: 1 No preemption victims found for incoming pod, 5 Preemption is not helpful for scheduling."
0.1423,Event,ADDED,eval-conflicts-rho010-r4-048-f8dlb.18d542e53d3df973,reason=Scheduled count=None msg=Successfully assigned compute/eval-conflicts-rho010-r4-048-f8dlb to kind-worker2
0.1426,Event,ADDED,eval-conflicts-rho010-r4-048-f8dlb.18d542e5679a9cfa,"reason=Pulled count=1 msg=Container image ""busybox:musl"" already present on machine"
0.1428,Event,ADDED,eval-conflicts-rho010-r4-048-f8dlb.18d542e56a26b1a3,reason=Created count=1 msg=Created container: task
0.1432,Event,ADDED,eval-conflicts-rho010-r4-048-f8dlb.18d542e570397a9a,reason=Started count=1 msg=Started container task
0.1435,Event,ADDED,eval-conflicts-rho010-r4-048.18d542e412492774,reason=SuccessfulCreate count=1 msg=Created pod: eval-conflicts-rho010-r4-048-f8dlb
0.1437,Event,ADDED,eval-conflicts-rho010-r4-048.18d542eb15953456,reason=Completed count=1 msg=Job completed
0.1439,Event,ADDED,eval-conflicts-rho010-r4-049-wspgk.18d542e44dd6d9ee,reason=Scheduled count=None msg=Successfully assigned compute/eval-conflicts-rho010-r4-049-wspgk to kind-worker3
0.1443,Event,ADDED,eval-conflicts-rho010-r4-049-wspgk.18d542e46aba902c,"reason=Pulled count=1 msg=Container image ""busybox:musl"" already present on machine"
0.1445,Event,ADDED,eval-conflicts-rho010-r4-049-wspgk.18d542e46bcdb4ef,reason=Created count=1 msg=Created container: task
0.1449,Event,ADDED,eval-conflicts-rho010-r4-049-wspgk.18d542e46fc087fb,reason=Started count=1 msg=Started container task
0.1454,Event,ADDED,eval-conflicts-rho010-r4-049.18d542e44d52db9d,reason=SuccessfulCreate count=1 msg=Created pod: eval-conflicts-rho010-r4-049-wspgk
0.1458,Event,ADDED,eval-conflicts-rho010-r4-049.18d542ea0a4f2e19,reason=Completed count=1 msg=Job completed
0.1463,Event,ADDED,eval-conflicts-rho010-r4-050-rhjdw.18d542e4897325d3,reason=Scheduled count=None msg=Successfully assigned compute/eval-conflicts-rho010-r4-050-rhjdw to kind-worker3
0.1466,Event,ADDED,eval-conflicts-rho010-r4-050-rhjdw.18d542e4a34d7110,"reason=Pulled count=1 msg=Container image ""busybox:musl"" already present on machine"
0.147,Event,ADDED,eval-conflicts-rho010-r4-050-rhjdw.18d542e4a4dd4904,reason=Created count=1 msg=Created container: task
0.1472,Event,ADDED,eval-conflicts-rho010-r4-050-rhjdw.18d542e4a6b828af,reason=Started count=1 msg=Started container task
0.1474,Event,ADDED,eval-conflicts-rho010-r4-050.18d542e488db4299,reason=SuccessfulCreate count=1 msg=Created pod: eval-conflicts-rho010-r4-050-rhjdw
0.1476,Event,ADDED,eval-conflicts-rho010-r4-050.18d542ea413627de,reason=Completed count=1 msg=Job completed
0.1484,Job,MODIFIED,eval-conflicts-rho030-r3-000,
0.1485,TaskRequest,MODIFIED,eval-conflicts-rho030-r3-000,phase=Scheduled job=None
0.1488,Event,ADDED,eval-conflicts-rho010-r4-051-q2qnx.18d542e4c520e7d2,reason=Scheduled count=None msg=Successfully assigned compute/eval-conflicts-rho010-r4-051-q2qnx to kind-worker3
0.1493,Event,ADDED,eval-conflicts-rho010-r4-051-q2qnx.18d542e4df99857b,"reason=Pulled count=1 msg=Container image ""busybox:musl"" already present on machine"
0.1498,Event,ADDED,eval-conflicts-rho010-r4-051-q2qnx.18d542e4e0af2e88,reason=Created count=1 msg=Created container: task
0.1502,Event,ADDED,eval-conflicts-rho010-r4-051-q2qnx.18d542e4e5ed55a1,reason=Started count=1 msg=Started container task
0.1503,Event,ADDED,eval-conflicts-rho010-r4-051.18d542e4c4975220,reason=SuccessfulCreate count=1 msg=Created pod: eval-conflicts-rho010-r4-051-q2qnx
0.1506,Event,ADDED,eval-conflicts-rho010-r4-051.18d542ea7d3da0f9,reason=Completed count=1 msg=Job completed
0.1509,Event,ADDED,eval-conflicts-rho010-r4-052-hdggw.18d542e50331cabe,"reason=FailedScheduling count=None msg=0/6 nodes are available: 1 c_wall violated: 1 conflicting context pair(s) with node memory, 5 node(s) had untolerated taint(s). no new claims to deallocate, preemption: 0/6 nodes are available: 1 No preemption victims found for incoming pod, 5 Preemption is not helpful for scheduling."
0.152,Event,ADDED,eval-conflicts-rho010-r4-052-hdggw.18d542e503b0fd9c,"reason=FailedScheduling count=None msg=0/6 nodes are available: 1 c_wall violated: 1 conflicting context pair(s) with node memory, 5 node(s) had untolerated taint(s). no new claims to deallocate, preemption: 0/6 nodes are available: 1 No preemption victims found for incoming pod, 5 Preemption is not helpful for scheduling."
0.1523,Event,ADDED,eval-conflicts-rho010-r4-052-hdggw.18d542e5401b2ab1,reason=Scheduled count=None msg=Successfully assigned compute/eval-conflicts-rho010-r4-052-hdggw to kind-worker2
0.1525,Event,ADDED,eval-conflicts-rho010-r4-052-hdggw.18d542e56787bf09,"reason=Pulled count=1 msg=Container image ""busybox:musl"" already present on machine"
0.1553,Node,MODIFIED,kind-worker2,taints=0
0.1557,Event,ADDED,eval-conflicts-rho010-r4-052-hdggw.18d542e5698d536e,reason=Created count=1 msg=Created container: task
0.1558,Event,ADDED,eval-conflicts-rho010-r4-052-hdggw.18d542e57038149a,reason=Started count=1 msg=Started container task
0.156,Event,ADDED,eval-conflicts-rho010-r4-052.18d542e502ec489f,reason=SuccessfulCreate count=1 msg=Created pod: eval-conflicts-rho010-r4-052-hdggw
0.1562,Event,ADDED,eval-conflicts-rho010-r4-052.18d542eb15c1247f,reason=Completed count=1 msg=Job completed
0.1585,Pod,MODIFIED,eval-conflicts-rho030-r3-000-mh4l5,phase=Pending node=kind-worker2
0.1588,Event,ADDED,eval-conflicts-rho010-r4-053-lk79v.18d542e53c255c47,"reason=FailedScheduling count=None msg=0/6 nodes are available: 1 c_wall violated: 1 conflicting context pair(s) with node memory, 5 node(s) had untolerated taint(s). no new claims to deallocate, preemption: 0/6 nodes are available: 1 No preemption victims found for incoming pod, 5 Preemption is not helpful for scheduling."
0.159,Event,ADDED,eval-conflicts-rho010-r4-053-lk79v.18d542e5401bfc01,"reason=FailedScheduling count=None msg=0/6 nodes are available: 1 c_wall violated: 1 conflicting context pair(s) with node memory, 5 node(s) had untolerated taint(s). no new claims to deallocate, preemption: 0/6 nodes are available: 1 No preemption victims found for incoming pod, 5 Preemption is not helpful for scheduling."
0.1592,Event,ADDED,eval-conflicts-rho010-r4-053-lk79v.18d542e69426a0d9,reason=Scheduled count=None msg=Successfully assigned compute/eval-conflicts-rho010-r4-053-lk79v to kind-worker4
0.1596,Event,ADDED,eval-conflicts-rho010-r4-053-lk79v.18d542e6af1072e4,"reason=Pulled count=1 msg=Container image ""busybox:musl"" already present on machine"
0.1598,Event,ADDED,eval-conflicts-rho010-r4-053-lk79v.18d542e6b0964fa8,reason=Created count=1 msg=Created container: task
0.1599,Event,ADDED,eval-conflicts-rho010-r4-053-lk79v.18d542e6b35ea9ff,reason=Started count=1 msg=Started container task
0.1603,Event,ADDED,eval-conflicts-rho010-r4-053.18d542e53bca566c,reason=SuccessfulCreate count=1 msg=Created pod: eval-conflicts-rho010-r4-053-lk79v
0.1606,Event,ADDED,eval-conflicts-rho010-r4-053.18d542ec5b59a661,reason=Completed count=1 msg=Job completed
0.1608,Event,ADDED,eval-conflicts-rho010-r4-054-5gmw5.18d542e578e03d88,"reason=FailedScheduling count=None msg=0/6 nodes are available: 1 c_wall violated: 3 conflicting context pair(s) with node memory, 5 node(s) had untolerated taint(s). no new claims to deallocate, preemption: 0/6 nodes are available: 1 No preemption victims found for incoming pod, 5 Preemption is not helpful for scheduling."
0.1612,Event,ADDED,eval-conflicts-rho010-r4-054-5gmw5.18d542e579657717,"reason=FailedScheduling count=None msg=0/6 nodes are available: 1 c_wall violated: 3 conflicting context pair(s) with node memory, 5 node(s) had untolerated taint(s). no new claims to deallocate, preemption: 0/6 nodes are available: 1 No preemption victims found for incoming pod, 5 Preemption is not helpful for scheduling."
0.1616,Event,ADDED,eval-conflicts-rho010-r4-054-5gmw5.18d542e68d6acf81,reason=Scheduled count=None msg=Successfully assigned compute/eval-conflicts-rho010-r4-054-5gmw5 to kind-worker4
0.1618,Event,ADDED,eval-conflicts-rho010-r4-054-5gmw5.18d542e6ac636e4a,"reason=Pulled count=1 msg=Container image ""busybox:musl"" already present on machine"
0.1621,Event,ADDED,eval-conflicts-rho010-r4-054-5gmw5.18d542e6adcff787,reason=Created count=1 msg=Created container: task
0.1624,Event,ADDED,eval-conflicts-rho010-r4-054-5gmw5.18d542e6b00e23dd,reason=Started count=1 msg=Started container task
0.1626,Event,ADDED,eval-conflicts-rho010-r4-054.18d542e5789f69c0,reason=SuccessfulCreate count=1 msg=Created pod: eval-conflicts-rho010-r4-054-5gmw5
0.1628,Event,ADDED,eval-conflicts-rho010-r4-054.18d542ec1efd9a09,reason=Completed count=1 msg=Job completed
0.163,Event,ADDED,eval-conflicts-rho010-r4-055-zg997.18d542e5b69270b6,reason=Scheduled count=None msg=Successfully assigned compute/eval-conflicts-rho010-r4-055-zg997 to kind-worker2
0.1634,Event,ADDED,eval-conflicts-rho010-r4-055-zg997.18d542e5d9434fbd,"reason=Pulled count=1 msg=Container image ""busybox:musl"" already present on machine"
0.1636,Event,ADDED,eval-conflicts-rho010-r4-055-zg997.18d542e5dabc9676,reason=Created count=1 msg=Created container: task
0.1638,Event,ADDED,eval-conflicts-rho010-r4-055-zg997.18d542e5de72e24d,reason=Started count=1 msg=Started container task
0.164,Event,ADDED,eval-conflicts-rho010-r4-055.18d542e5b30a91fa,reason=SuccessfulCreate count=1 msg=Created pod: eval-conflicts-rho010-r4-055-zg997
0.1644,Event,ADDED,eval-conflicts-rho010-r4-055.18d542eb160c8ce7,reason=Completed count=1 msg=Job completed
0.1648,Event,ADDED,eval-conflicts-rho010-r4-056-2rzzx.18d542e5ef2689ae,"reason=FailedScheduling count=None msg=0/6 nodes are available: 1 c_wall violated: 3 conflicting context pair(s) with node memory, 5 node(s) had untolerated taint(s). no new claims to deallocate, preemption: 0/6 nodes are available: 1 No preemption victims found for incoming pod, 5 Preemption is not helpful for scheduling."
0.1652,Event,ADDED,eval-conflicts-rho010-r4-056-2rzzx.18d542e5efabce51,"reason=FailedScheduling count=None msg=0/6 nodes are available: 1 c_wall violated: 3 conflicting context pair(s) with node memory, 5 node(s) had untolerated taint(s). no new claims to deallocate, preemption: 0/6 nodes are available: 1 No preemption victims found for incoming pod, 5 Preemption is not helpful for scheduling."
0.167,Node,MODIFIED,kind-worker2,taints=0
0.1674,Event,ADDED,eval-conflicts-rho010-r4-056-2rzzx.18d542e694037bfe,reason=Scheduled count=None msg=Successfully assigned compute/eval-conflicts-rho010-r4-056-2rzzx to kind-worker4
0.1676,Event,ADDED,eval-conflicts-rho010-r4-056-2rzzx.18d542e6add52388,"reason=Pulled count=1 msg=Container image ""busybox:musl"" already present on machine"
0.1677,Event,ADDED,eval-conflicts-rho010-r4-056-2rzzx.18d542e6b00946d6,reason=Created count=1 msg=Created container: task
0.1681,Event,ADDED,eval-conflicts-rho010-r4-056-2rzzx.18d542e6b35f7aca,reason=Started count=1 msg=Started container task
0.1683,Event,ADDED,eval-conflicts-rho010-r4-056.18d542e5eee67fc2,reason=SuccessfulCreate count=1 msg=Created pod: eval-conflicts-rho010-r4-056-2rzzx
0.1685,Event,ADDED,eval-conflicts-rho010-r4-056.18d542ec5b237fa9,reason=Completed count=1 msg=Job completed
0.1687,Event,ADDED,eval-conflicts-rho010-r4-057-qb7wt.18d542e62a609a7a,"reason=FailedScheduling count=None msg=0/6 nodes are available: 1 c_wall violated: 1 conflicting context pair(s) with node memory, 5 node(s) had untolerated taint(s). no new claims to deallocate, preemption: 0/6 nodes are available: 1 No preemption victims found for incoming pod, 5 Preemption is not helpful for scheduling."
0.169,Event,ADDED,eval-conflicts-rho010-r4-057-qb7wt.18d542e62ad6f0f0,"reason=FailedScheduling count=None msg=0/6 nodes are available: 1 c_wall violated: 1 conflicting context pair(s) with node memory, 5 node(s) had untolerated taint(s). no new claims to deallocate, preemption: 0/6 nodes are available: 1 No preemption victims found for incoming pod, 5 Preemption is not helpful for scheduling."
0.1695,Event,ADDED,eval-conflicts-rho010-r4-057-qb7wt.18d542e69426514c,reason=Scheduled count=None msg=Successfully assigned compute/eval-conflicts-rho010-r4-057-qb7wt to kind-worker4
0.1699,Event,ADDED,eval-conflicts-rho010-r4-057-qb7wt.18d542e6adb04247,"reason=Pulled count=1 msg=Container image ""busybox:musl"" already present on machine"
0.1703,Event,ADDED,eval-conflicts-rho010-r4-057-qb7wt.18d542e6af93224b,reason=Created count=1 msg=Created container: task
0.1705,Event,ADDED,eval-conflicts-rho010-r4-057-qb7wt.18d542e6b2ea3211,reason=Started count=1 msg=Started container task
0.1707,Event,ADDED,eval-conflicts-rho010-r4-057.18d542e62a2933cd,reason=SuccessfulCreate count=1 msg=Created pod: eval-conflicts-rho010-r4-057-qb7wt
0.1708,Event,ADDED,eval-conflicts-rho010-r4-057.18d542ec1f1e9491,reason=Completed count=1 msg=Job completed
0.1711,Event,ADDED,eval-conflicts-rho010-r4-058-g469p.18d542e67442a191,reason=Scheduled count=None msg=Successfully assigned compute/eval-conflicts-rho010-r4-058-g469p to kind-worker2
0.1712,Event,ADDED,eval-conflicts-rho010-r4-058-g469p.18d542e694019eb8,"reason=Pulled count=1 msg=Container image ""busybox:musl"" already present on machine"
0.1716,Event,ADDED,eval-conflicts-rho010-r4-058-g469p.18d542e697921b49,reason=Created count=1 msg=Created container: task
0.1719,Event,ADDED,eval-conflicts-rho010-r4-058-g469p.18d542e69b406484,reason=Started count=1 msg=Started container task
0.172,Event,ADDED,eval-conflicts-rho010-r4-058.18d542e673b41d42,reason=SuccessfulCreate count=1 msg=Created pod: eval-conflicts-rho010-r4-058-g469p
0.1722,Event,ADDED,eval-conflicts-rho010-r4-058.18d542ec00e285fd,reason=Completed count=1 msg=Job completed
0.1724,Event,ADDED,eval-conflicts-rho010-r4-059-nvmwp.18d542e6acff14c6,reason=Scheduled count=None msg=Successfully assigned compute/eval-conflicts-rho010-r4-059-nvmwp to kind-worker5
0.1728,Event,ADDED,eval-conflicts-rho010-r4-059-nvmwp.18d542e6cb47da1a,"reason=Pulled count=1 msg=Container image ""busybox:musl"" already present on machine"
0.173,Event,ADDED,eval-conflicts-rho010-r4-059-nvmwp.18d542e6cc88e499,reason=Created count=1 msg=Created container: task
0.1732,Event,ADDED,eval-conflicts-rho010-r4-059-nvmwp.18d542e6d7650b43,reason=Started count=1 msg=Started container task
0.1734,Event,ADDED,eval-conflicts-rho010-r4-059.18d542e6abaa445b,reason=SuccessfulCreate count=1 msg=Created pod: eval-conflicts-rho010-r4-059-nvmwp
0.1737,Event,ADDED,eval-conflicts-rho010-r4-059.18d542ec68a163af,reason=Completed count=1 msg=Job completed
0.1739,Event,ADDED,eval-conflicts-rho010-r4-060-7f586.18d542e6e0b6bf64,reason=Scheduled count=None msg=Successfully assigned compute/eval-conflicts-rho010-r4-060-7f586 to kind-worker5
0.1741,Event,ADDED,eval-conflicts-rho010-r4-060-7f586.18d542e7002c4e90,"reason=Pulled count=1 msg=Container image ""busybox:musl"" already present on machine"
0.1743,Event,ADDED,eval-conflicts-rho010-r4-060-7f586.18d542e70150c9b9,reason=Created count=1 msg=Created container: task
0.1745,Event,ADDED,eval-conflicts-rho010-r4-060-7f586.18d542e70746f9fc,reason=Started count=1 msg=Started container task
0.1746,Event,ADDED,eval-conflicts-rho010-r4-060.18d542e6df854ea4,reason=SuccessfulCreate count=1 msg=Created pod: eval-conflicts-rho010-r4-060-7f586
0.1748,Event,ADDED,eval-conflicts-rho010-r4-060.18d542eca89518a8,reason=Completed count=1 msg=Job completed
0.175,Event,ADDED,eval-conflicts-rho010-r4-061-5v4pn.18d542e71b7561a6,reason=Scheduled count=None msg=Successfully assigned compute/eval-conflicts-rho010-r4-061-5v4pn to kind-worker4
0.1752,Event,ADDED,eval-conflicts-rho010-r4-061-5v4pn.18d542e73bdefac4,"reason=Pulled count=1 msg=Container image ""busybox:musl"" already present on machine"
0.1753,Event,ADDED,eval-conflicts-rho010-r4-061-5v4pn.18d542e73d5bdae9,reason=Created count=1 msg=Created container: task
0.1755,Event,ADDED,eval-conflicts-rho010-r4-061-5v4pn.18d542e743b1f885,reason=Started count=1 msg=Started container task
0.1757,Event,ADDED,eval-conflicts-rho010-r4-061.18d542e71a49f087,reason=SuccessfulCreate count=1 msg=Created pod: eval-conflicts-rho010-r4-061-5v4pn
0.1758,Event,ADDED,eval-conflicts-rho010-r4-061.18d542ecd2788254,reason=Completed count=1 msg=Job completed
0.1761,Event,ADDED,eval-conflicts-rho010-r4-062-ghhgs.18d542e7658b0a13,reason=Scheduled count=None msg=Successfully assigned compute/eval-conflicts-rho010-r4-062-ghhgs to kind-worker5
0.1764,Event,ADDED,eval-conflicts-rho010-r4-062-ghhgs.18d542e78875e33f,"reason=Pulled count=1 msg=Container image ""busybox:musl"" already present on machine"
0.1766,Event,ADDED,eval-conflicts-rho010-r4-062-ghhgs.18d542e789937cb5,reason=Created count=1 msg=Created container: task
0.1768,Event,ADDED,eval-conflicts-rho010-r4-062-ghhgs.18d542e790de22bb,reason=Started count=1 msg=Started container task
0.177,Event,ADDED,eval-conflicts-rho010-r4-062.18d542e7566156b7,reason=SuccessfulCreate count=1 msg=Created pod: eval-conflicts-rho010-r4-062-ghhgs
0.1773,Event,ADDED,eval-conflicts-rho010-r4-062.18d542ed17cc144f,reason=Completed count=1 msg=Job completed
0.1775,Event,ADDED,eval-conflicts-rho010-r4-063-vtw4m.18d542e793665e6f,reason=Scheduled count=None msg=Successfully assigned compute/eval-conflicts-rho010-r4-063-vtw4m to kind-worker4
0.1777,Event,ADDED,eval-conflicts-rho010-r4-063-vtw4m.18d542e7b1b9e4a3,"reason=Pulled count=1 msg=Container image ""busybox:musl"" already present on machine"
0.1779,Event,ADDED,eval-conflicts-rho010-r4-063-vtw4m.18d542e7b31f7cff,reason=Created count=1 msg=Created container: task
0.1781,Event,ADDED,eval-conflicts-rho010-r4-063-vtw4m.18d542e7ba4403a5,reason=Started count=1 msg=Started container task
0.1783,Event,ADDED,eval-conflicts-rho010-r4-063.18d542e7926f428b,reason=SuccessfulCreate count=1 msg=Created pod: eval-conflicts-rho010-r4-063-vtw4m
0.1784,Event,ADDED,eval-conflicts-rho010-r4-063.18d542ed43d1b5cf,reason=Completed count=1 msg=Job completed
0.1786,Event,ADDED,eval-conflicts-rho010-r4-064-p2x2f.18d542e7cf61516b,reason=Scheduled count=None msg=Successfully assigned compute/eval-conflicts-rho010-r4-064-p2x2f to kind-worker5
0.1788,Event,ADDED,eval-conflicts-rho010-r4-064-p2x2f.18d542e7edbc4d76,"reason=Pulled count=1 msg=Container image ""busybox:musl"" already present on machine"
0.1789,Event,ADDED,eval-conflicts-rho010-r4-064-p2x2f.18d542e7ef1a3a88,reason=Created count=1 msg=Created container: task
0.1791,Event,ADDED,eval-conflicts-rho010-r4-064-p2x2f.18d542e7f2acaf48,reason=Started count=1 msg=Started container task
0.1793,Event,ADDED,eval-conflicts-rho010-r4-064.18d542e7ce57ef82,reason=SuccessfulCreate count=1 msg=Created pod: eval-conflicts-rho010-r4-064-p2x2f
0.1795,Event,ADDED,eval-conflicts-rho010-r4-064.18d542ed998f09d1,reason=Completed count=1 msg=Job completed
0.1796,Event,ADDED,eval-conflicts-rho010-r4-065-96hkh.18d542e80b222763,reason=Scheduled count=None msg=Successfully assigned compute/eval-conflicts-rho010-r4-065-96hkh to kind-worker5
0.1798,Event,ADDED,eval-conflicts-rho010-r4-065-96hkh.18d542e82c703c23,"reason=Pulled count=1 msg=Container image ""busybox:musl"" already present on machine"
0.18,Event,ADDED,eval-conflicts-rho010-r4-065-96hkh.18d542e82d91a114,reason=Created count=1 msg=Created container: task
0.1801,Event,ADDED,eval-conflicts-rho010-r4-065-96hkh.18d542e82f969325,reason=Started count=1 msg=Started container task
0.1803,Event,ADDED,eval-conflicts-rho010-r4-065.18d542e80a00b629,reason=SuccessfulCreate count=1 msg=Created pod: eval-conflicts-rho010-r4-065-96hkh
0.1805,Event,ADDED,eval-conflicts-rho010-r4-065.18d542ed99680c55,reason=Completed count=1 msg=Job completed
0.1806,Event,ADDED,eval-conflicts-rho010-r4-066-k8gz9.18d542e8460b909b,reason=Scheduled count=None msg=Successfully assigned compute/eval-conflicts-rho010-r4-066-k8gz9 to kind-worker
0.1808,Event,ADDED,eval-conflicts-rho010-r4-066-k8gz9.18d542e867a5118c,"reason=Pulled count=1 msg=Container image ""busybox:musl"" already present on machine"
0.181,Event,ADDED,eval-conflicts-rho010-r4-066-k8gz9.18d542e86920f00a,reason=Created count=1 msg=Created container: task
0.1812,Event,ADDED,eval-conflicts-rho010-r4-066-k8gz9.18d542e8717e9ab5,reason=Started count=1 msg=Started container task
0.1815,Event,ADDED,eval-conflicts-rho010-r4-066.18d542e844f83406,reason=SuccessfulCreate count=1 msg=Created pod: eval-conflicts-rho010-r4-066-k8gz9
0.1817,Event,ADDED,eval-conflicts-rho010-r4-066.18d542ede6823872,reason=Completed count=1 msg=Job completed
0.1819,Event,ADDED,eval-conflicts-rho010-r4-067-8skmk.18d542e87fcbaf50,reason=Scheduled count=None msg=Successfully assigned compute/eval-conflicts-rho010-r4-067-8skmk to kind-worker
0.1821,Event,ADDED,eval-conflicts-rho010-r4-067-8skmk.18d542e8a0d2656d,"reason=Pulled count=1 msg=Container image ""busybox:musl"" already present on machine"
0.1822,Event,ADDED,eval-conflicts-rho010-r4-067-8skmk.18d542e8a2101f61,reason=Created count=1 msg=Created container: task
0.1824,Event,ADDED,eval-conflicts-rho010-r4-067-8skmk.18d542e8a61b7911,reason=Started count=1 msg=Started container task
0.1826,Event,ADDED,eval-conflicts-rho010-r4-067.18d542e87e54cd82,reason=SuccessfulCreate count=1 msg=Created pod: eval-conflicts-rho010-r4-067-8skmk
0.1828,Event,ADDED,eval-conflicts-rho010-r4-067.18d542ee22dc1156,reason=Completed count=1 msg=Job completed
0.1829,Event,ADDED,eval-conflicts-rho010-r4-068-qblbx.18d542e8caffdcb4,reason=Scheduled count=None msg=Successfully assigned compute/eval-conflicts-rho010-r4-068-qblbx to kind-worker
0.1831,Event,ADDED,eval-conflicts-rho010-r4-068-qblbx.18d542e8ef7e4730,"reason=Pulled count=1 msg=Container image ""busybox:musl"" already present on machine"
0.1833,Event,ADDED,eval-conflicts-rho010-r4-068-qblbx.18d542e8f0a2fb55,reason=Created count=1 msg=Created container: task
0.1834,Event,ADDED,eval-conflicts-rho010-r4-068-qblbx.18d542e8f7b6ebff,reason=Started count=1 msg=Started container task
0.1836,Event,ADDED,eval-conflicts-rho010-r4-068.18d542e8c1c9362a,reason=SuccessfulCreate count=1 msg=Created pod: eval-conflicts-rho010-r4-068-qblbx
0.1839,Event,ADDED,eval-conflicts-rho010-r4-068.18d542ee9079f08d,reason=Completed count=1 msg=Job completed
0.184,Event,ADDED,eval-conflicts-rho010-r4-069-xbf7s.18d542e8fab7d8ec,reason=Scheduled count=None msg=Successfully assigned compute/eval-conflicts-rho010-r4-069-xbf7s to kind-worker
0.1842,Event,ADDED,eval-conflicts-rho010-r4-069-xbf7s.18d542e921737a33,"reason=Pulled count=1 msg=Container image ""busybox:musl"" already present on machine"
0.1844,Event,ADDED,eval-conflicts-rho010-r4-069-xbf7s.18d542e922dc4d86,reason=Created count=1 msg=Created container: task
0.1846,Event,ADDED,eval-conflicts-rho010-r4-069-xbf7s.18d542e929812dbc,reason=Started count=1 msg=Started container task
0.1847,Event,ADDED,eval-conflicts-rho010-r4-069.18d542e8f94c1d83,reason=SuccessfulCreate count=1 msg=Created pod: eval-conflicts-rho010-r4-069-xbf7s
0.1849,Event,ADDED,eval-conflicts-rho010-r4-069.18d542ee8f3cb4e1,reason=Completed count=1 msg=Job completed
0.1851,Event,ADDED,eval-conflicts-rho010-r4-070-zjhz7.18d542e93714632a,reason=Scheduled count=None msg=Successfully assigned compute/eval-conflicts-rho010-r4-070-zjhz7 to kind-worker5
0.1853,Event,ADDED,eval-conflicts-rho010-r4-070-zjhz7.18d542e95e3602b8,"reason=Pulled count=1 msg=Container image ""busybox:musl"" already present on machine"
0.1855,Event,ADDED,eval-conflicts-rho010-r4-070-zjhz7.18d542e95f5db460,reason=Created count=1 msg=Created container: task
0.1857,Event,ADDED,eval-conflicts-rho010-r4-070-zjhz7.18d542e968873162,reason=Started count=1 msg=Started container task
0.186,Event,ADDED,eval-conflicts-rho010-r4-070.18d542e935b579f0,reason=SuccessfulCreate count=1 msg=Created pod: eval-conflicts-rho010-r4-070-zjhz7
0.1862,Event,ADDED,eval-conflicts-rho010-r4-070.18d542eef94acb6e,reason=Completed count=1 msg=Job completed
0.1864,Event,ADDED,eval-conflicts-rho010-r4-071-nrtv9.18d542e978477248,reason=Scheduled count=None msg=Successfully assigned compute/eval-conflicts-rho010-r4-071-nrtv9 to kind-worker
0.1867,Event,ADDED,eval-conflicts-rho010-r4-071-nrtv9.18d542e999eda042,"reason=Pulled count=1 msg=Container image ""busybox:musl"" already present on machine"
0.1869,Event,ADDED,eval-conflicts-rho010-r4-071-nrtv9.18d542e99b356204,reason=Created count=1 msg=Created container: task
0.1871,Event,ADDED,eval-conflicts-rho010-r4-071-nrtv9.18d542e9a09af1b4,reason=Started count=1 msg=Started container task
0.1873,Event,ADDED,eval-conflicts-rho010-r4-071.18d542e976dd7530,reason=SuccessfulCreate count=1 msg=Created pod: eval-conflicts-rho010-r4-071-nrtv9
0.1876,Event,ADDED,eval-conflicts-rho010-r4-071.18d542ef0bbfe3a9,reason=Completed count=1 msg=Job completed
0.1878,Event,ADDED,eval-conflicts-rho010-r4-072-q5xdr.18d542e9af80d120,reason=Scheduled count=None msg=Successfully assigned compute/eval-conflicts-rho010-r4-072-q5xdr to kind-worker4
0.188,Event,ADDED,eval-conflicts-rho010-r4-072-q5xdr.18d542e9cdf29fff,"reason=Pulled count=1 msg=Container image ""busybox:musl"" already present on machine"
0.1882,Event,ADDED,eval-conflicts-rho010-r4-072-q5xdr.18d542e9cf4d3cf3,reason=Created count=1 msg=Created container: task
0.1885,Event,ADDED,eval-conflicts-rho010-r4-072-q5xdr.18d542e9d5348d23,reason=Started count=1 msg=Started container task
0.1887,Event,ADDED,eval-conflicts-rho010-r4-072.18d542e9a9c86b09,reason=SuccessfulCreate count=1 msg=Created pod: eval-conflicts-rho010-r4-072-q5xdr
0.1889,Event,ADDED,eval-conflicts-rho010-r4-072.18d542ef68506234,reason=Completed count=1 msg=Job completed
0.1892,Event,ADDED,eval-conflicts-rho010-r4-073-qz8t5.18d542e9e98f7db8,reason=Scheduled count=None msg=Successfully assigned compute/eval-conflicts-rho010-r4-073-qz8t5 to kind-worker2
0.1894,Event,ADDED,eval-conflicts-rho010-r4-073-qz8t5.18d542ea09521aa2,"reason=Pulled count=1 msg=Container image ""busybox:musl"" already present on machine"
0.1895,Event,ADDED,eval-conflicts-rho010-r4-073-qz8t5.18d542ea0aac9f6b,reason=Created count=1 msg=Created container: task
0.1897,Event,ADDED,eval-conflicts-rho010-r4-073-qz8t5.18d542ea1b95ae94,reason=Started count=1 msg=Started container task
0.19,Event,ADDED,eval-conflicts-rho010-r4-073.18d542e9e7f5bc92,reason=SuccessfulCreate count=1 msg=Created pod: eval-conflicts-rho010-r4-073-qz8t5
0.1902,Event,ADDED,eval-conflicts-rho010-r4-073.18d542ef852d0e12,reason=Completed count=1 msg=Job completed
0.1904,Event,ADDED,eval-conflicts-rho010-r4-074-lsmc7.18d542ea260e41dd,reason=Scheduled count=None msg=Successfully assigned compute/eval-conflicts-rho010-r4-074-lsmc7 to kind-worker
0.1905,Event,ADDED,eval-conflicts-rho010-r4-074-lsmc7.18d542ea4a9fb0ef,"reason=Pulled count=1 msg=Container image ""busybox:musl"" already present on machine"
0.1908,Event,ADDED,eval-conflicts-rho010-r4-074-lsmc7.18d542ea4bca3382,reason=Created count=1 msg=Created container: task
0.191,Event,ADDED,eval-conflicts-rho010-r4-074-lsmc7.18d542ea521b856b,reason=Started count=1 msg=Started container task
0.1911,Event,ADDED,eval-conflicts-rho010-r4-074.18d542ea24ca04dd,reason=SuccessfulCreate count=1 msg=Created pod: eval-conflicts-rho010-r4-074-lsmc7
0.1913,Event,ADDED,eval-conflicts-rho010-r4-074.18d542efc12a21c9,reason=Completed count=1 msg=Job completed
0.1914,Event,ADDED,eval-conflicts-rho010-r4-075-vr5r4.18d542ea5dda9f10,reason=Scheduled count=None msg=Successfully assigned compute/eval-conflicts-rho010-r4-075-vr5r4 to kind-worker5
0.1916,Event,ADDED,eval-conflicts-rho010-r4-075-vr5r4.18d542ea83f74351,"reason=Pulled count=1 msg=Container image ""busybox:musl"" already present on machine"
0.1919,Event,ADDED,eval-conflicts-rho010-r4-075-vr5r4.18d542ea852fd47d,reason=Created count=1 msg=Created container: task
0.1922,Event,ADDED,eval-conflicts-rho010-r4-075-vr5r4.18d542ea895849b4,reason=Started count=1 msg=Started container task
0.1924,Event,ADDED,eval-conflicts-rho010-r4-075.18d542ea5c8b8493,reason=SuccessfulCreate count=1 msg=Created pod: eval-conflicts-rho010-r4-075-vr5r4
0.1926,Event,ADDED,eval-conflicts-rho010-r4-075.18d542f020c86bc9,reason=Completed count=1 msg=Job completed
0.1928,Event,ADDED,eval-conflicts-rho010-r4-076-knqmv.18d542eaa06dfbe2,reason=Scheduled count=None msg=Successfully assigned compute/eval-conflicts-rho010-r4-076-knqmv to kind-worker4
0.1931,Event,ADDED,eval-conflicts-rho010-r4-076-knqmv.18d542ead0d09bda,"reason=Pulled count=1 msg=Container image ""busybox:musl"" already present on machine"
0.1933,Event,ADDED,eval-conflicts-rho010-r4-076-knqmv.18d542ead229fe25,reason=Created count=1 msg=Created container: task
0.1934,Event,ADDED,eval-conflicts-rho010-r4-076-knqmv.18d542ead72f85ee,reason=Started count=1 msg=Started container task
0.1937,Event,ADDED,eval-conflicts-rho010-r4-076.18d542ea9f1b2188,reason=SuccessfulCreate count=1 msg=Created pod: eval-conflicts-rho010-r4-076-knqmv
0.1939,Event,ADDED,eval-conflicts-rho010-r4-076.18d542f04c7c5610,reason=Completed count=1 msg=Job completed
0.194,Event,ADDED,eval-conflicts-rho010-r4-077-gfpmw.18d542ead3d769c4,reason=Scheduled count=None msg=Successfully assigned compute/eval-conflicts-rho010-r4-077-gfpmw to kind-worker5
0.1942,Event,ADDED,eval-conflicts-rho010-r4-077-gfpmw.18d542eafbae28f9,"reason=Pulled count=1 msg=Container image ""busybox:musl"" already present on machine"
0.1944,Event,ADDED,eval-conflicts-rho010-r4-077-gfpmw.18d542eafce5e72d,reason=Created count=1 msg=Created container: task
0.1946,Event,ADDED,eval-conflicts-rho010-r4-077-gfpmw.18d542eb09b8817b,reason=Started count=1 msg=Started container task
0.1948,Event,ADDED,eval-conflicts-rho010-r4-077.18d542ead2b582b6,reason=SuccessfulCreate count=1 msg=Created pod: eval-conflicts-rho010-r4-077-gfpmw
0.1949,Event,ADDED,eval-conflicts-rho010-r4-077.18d542f097faddb3,reason=Completed count=1 msg=Job completed
0.1951,Event,ADDED,eval-conflicts-rho010-r4-078-vcgxb.18d542eb17d9a288,reason=Scheduled count=None msg=Successfully assigned compute/eval-conflicts-rho010-r4-078-vcgxb to kind-worker4
0.1953,Event,ADDED,eval-conflicts-rho010-r4-078-vcgxb.18d542eb30acd826,"reason=Pulled count=1 msg=Container image ""busybox:musl"" already present on machine"
0.1954,Event,ADDED,eval-conflicts-rho010-r4-078-vcgxb.18d542eb31c4918a,reason=Created count=1 msg=Created container: task
0.196,Event,ADDED,eval-conflicts-rho010-r4-078-vcgxb.18d542eb33ae8fcd,reason=Started count=1 msg=Started container task
0.1961,Event,ADDED,eval-conflicts-rho010-r4-078.18d542eb16a14853,reason=SuccessfulCreate count=1 msg=Created pod: eval-conflicts-rho010-r4-078-vcgxb
0.1963,Event,ADDED,eval-conflicts-rho010-r4-078.18d542f0c380290f,reason=Completed count=1 msg=Job completed
0.1965,Event,ADDED,eval-conflicts-rho010-r4-079-pptl9.18d542eb49e8c3c5,reason=Scheduled count=None msg=Successfully assigned compute/eval-conflicts-rho010-r4-079-pptl9 to kind-worker
0.1968,Event,ADDED,eval-conflicts-rho010-r4-079-pptl9.18d542eb680cf2af,"reason=Pulled count=1 msg=Container image ""busybox:musl"" already present on machine"
0.197,Event,ADDED,eval-conflicts-rho010-r4-079-pptl9.18d542eb69944969,reason=Created count=1 msg=Created container: task
0.1972,Event,ADDED,eval-conflicts-rho010-r4-079-pptl9.18d542eb6dc665ac,reason=Started count=1 msg=Started container task
0.1975,Event,ADDED,eval-conflicts-rho010-r4-079.18d542eb496b90a5,reason=SuccessfulCreate count=1 msg=Created pod: eval-conflicts-rho010-r4-079-pptl9
0.1977,Event,ADDED,eval-conflicts-rho010-r4-079.18d542f0e5b472f5,reason=Completed count=1 msg=Job completed
0.1979,Event,ADDED,eval-conflicts-rho010-r4-080-wckfc.18d542eb8674be7f,reason=Scheduled count=None msg=Successfully assigned compute/eval-conflicts-rho010-r4-080-wckfc to kind-worker
0.1981,Event,ADDED,eval-conflicts-rho010-r4-080-wckfc.18d542eb9f9bac59,"reason=Pulled count=1 msg=Container image ""busybox:musl"" already present on machine"
0.1984,Event,ADDED,eval-conflicts-rho010-r4-080-wckfc.18d542eba0fcb8f1,reason=Created count=1 msg=Created container: task
0.1986,Event,ADDED,eval-conflicts-rho010-r4-080-wckfc.18d542ebaa01548e,reason=Started count=1 msg=Started container task
0.1989,Event,ADDED,eval-conflicts-rho010-r4-080.18d542eb85ec978b,reason=SuccessfulCreate count=1 msg=Created pod: eval-conflicts-rho010-r4-080-wckfc
0.1991,Event,ADDED,eval-conflicts-rho010-r4-080.18d542f12170758e,reason=Completed count=1 msg=Job completed
0.1992,Event,ADDED,eval-conflicts-rho010-r4-081-8kszw.18d542ebc1761d66,reason=Scheduled count=None msg=Successfully assigned compute/eval-conflicts-rho010-r4-081-8kszw to kind-worker
0.1995,Event,ADDED,eval-conflicts-rho010-r4-081-8kszw.18d542ebedcfd49b,"reason=Pulled count=1 msg=Container image ""busybox:musl"" already present on machine"
0.1997,Event,ADDED,eval-conflicts-rho010-r4-081-8kszw.18d542ebef092f89,reason=Created count=1 msg=Created container: task
0.1999,Event,ADDED,eval-conflicts-rho010-r4-081-8kszw.18d542ebf4a91a4b,reason=Started count=1 msg=Started container task
0.2001,Event,ADDED,eval-conflicts-rho010-r4-081.18d542ebc0dc6b1c,reason=SuccessfulCreate count=1 msg=Created pod: eval-conflicts-rho010-r4-081-8kszw
0.2004,Event,ADDED,eval-conflicts-rho010-r4-081.18d542f15d6891a9,reason=Completed count=1 msg=Job completed
0.2005,Event,ADDED,eval-conflicts-rho010-r4-082-fxvtt.18d542ebfd5c06b7,"reason=FailedScheduling count=None msg=0/6 nodes are available: 1 c_wall violated: 2 conflicting context pair(s) with node memory, 5 node(s) had untolerated taint(s). no new claims to deallocate, preemption: 0/6 nodes are available: 1 No preemption victims found for incoming pod, 5 Preemption is not helpful for scheduling."
0.2008,Event,ADDED,eval-conflicts-rho010-r4-082-fxvtt.18d542ebfddeae27,"reason=FailedScheduling count=None msg=0/6 nodes are available: 1 c_wall violated: 2 conflicting context pair(s) with node memory, 5 node(s) had untolerated taint(s). no new claims to deallocate, preemption: 0/6 nodes are available: 1 No preemption victims found for incoming pod, 5 Preemption is not helpful for scheduling."
0.201,Event,ADDED,eval-conflicts-rho010-r4-082-fxvtt.18d542ee997ae503,reason=Scheduled count=None msg=Successfully assigned compute/eval-conflicts-rho010-r4-082-fxvtt to kind-worker3
0.2013,Event,ADDED,eval-conflicts-rho010-r4-082-fxvtt.18d542eeb8a73f9b,"reason=Pulled count=1 msg=Container image ""busybox:musl"" already present on machine"
0.2015,Event,ADDED,eval-conflicts-rho010-r4-082-fxvtt.18d542eeba8e5951,reason=Created count=1 msg=Created container: task
0.2016,Event,ADDED,eval-conflicts-rho010-r4-082-fxvtt.18d542eec034b87e,reason=Started count=1 msg=Started container task
0.2019,Event,ADDED,eval-conflicts-rho010-r4-082.18d542ebfd22858d,reason=SuccessfulCreate count=1 msg=Created pod: eval-conflicts-rho010-r4-082-fxvtt
0.2021,Event,ADDED,eval-conflicts-rho010-r4-082.18d542f447e97560,reason=Completed count=1 msg=Job completed
0.2023,Event,ADDED,eval-conflicts-rho010-r4-083-8x7sv.18d542ec3c83afa7,reason=Scheduled count=None msg=Successfully assigned compute/eval-conflicts-rho010-r4-083-8x7sv to kind-worker
0.2026,Event,ADDED,eval-conflicts-rho010-r4-083-8x7sv.18d542ec5b7069dd,"reason=Pulled count=1 msg=Container image ""busybox:musl"" already present on machine"
0.2028,Event,ADDED,eval-conflicts-rho010-r4-083-8x7sv.18d542ec5cc701b0,reason=Created count=1 msg=Created container: task
0.203,Event,ADDED,eval-conflicts-rho010-r4-083-8x7sv.18d542ec6222a6bd,reason=Started count=1 msg=Started container task
0.2031,Event,ADDED,eval-conflicts-rho010-r4-083.18d542ec3c06279a,reason=SuccessfulCreate count=1 msg=Created pod: eval-conflicts-rho010-r4-083-8x7sv
0.2034,Event,ADDED,eval-conflicts-rho010-r4-083.18d542f1d5263d38,reason=Completed count=1 msg=Job completed
0.2036,Event,ADDED,eval-conflicts-rho010-r4-084-zhp8r.18d542ec742d4497,"reason=FailedScheduling count=None msg=0/6 nodes are available: 1 c_wall violated: 1 conflicting context pair(s) with node memory, 5 node(s) had untolerated taint(s). no new claims to deallocate, preemption: 0/6 nodes are available: 1 No preemption victims found for incoming pod, 5 Preemption is not helpful for scheduling."
0.2038,Event,ADDED,eval-conflicts-rho010-r4-084-zhp8r.18d542ec74d850eb,"reason=FailedScheduling count=None msg=0/6 nodes are available: 1 c_wall violated: 1 conflicting context pair(s) with node memory, 5 node(s) had untolerated taint(s). no new claims to deallocate, preemption: 0/6 nodes are available: 1 No preemption victims found for incoming pod, 5 Preemption is not helpful for scheduling."
0.2041,Event,ADDED,eval-conflicts-rho010-r4-084-zhp8r.18d542ee99f44255,reason=Scheduled count=None msg=Successfully assigned compute/eval-conflicts-rho010-r4-084-zhp8r to kind-worker3
0.2043,Event,ADDED,eval-conflicts-rho010-r4-084-zhp8r.18d542eebff19c87,"reason=Pulled count=1 msg=Container image ""busybox:musl"" already present on machine"
0.2045,Event,ADDED,eval-conflicts-rho010-r4-084-zhp8r.18d542eec3e81c42,reason=Created count=1 msg=Created container: task
0.2046,Event,ADDED,eval-conflicts-rho010-r4-084-zhp8r.18d542eec8f3d392,reason=Started count=1 msg=Started container task
0.2049,Event,ADDED,eval-conflicts-rho010-r4-084.18d542ec73ecc9be,reason=SuccessfulCreate count=1 msg=Created pod: eval-conflicts-rho010-r4-084-zhp8r
0.2051,Event,ADDED,eval-conflicts-rho010-r4-084.18d542f4491e9f9e,reason=Completed count=1 msg=Job completed
0.2053,Event,ADDED,eval-conflicts-rho010-r4-085-s5sbm.18d542ecb144c5e1,reason=Scheduled count=None msg=Successfully assigned compute/eval-conflicts-rho010-r4-085-s5sbm to kind-worker
0.2056,Event,ADDED,eval-conflicts-rho010-r4-085-s5sbm.18d542eccb25fdd0,"reason=Pulled count=1 msg=Container image ""busybox:musl"" already present on machine"
0.2058,Event,ADDED,eval-conflicts-rho010-r4-085-s5sbm.18d542eccc81308c,reason=Created count=1 msg=Created container: task
0.206,Event,ADDED,eval-conflicts-rho010-r4-085-s5sbm.18d542ecd21f457f,reason=Started count=1 msg=Started container task
0.2062,Event,ADDED,eval-conflicts-rho010-r4-085.18d542ecb0c061c2,reason=SuccessfulCreate count=1 msg=Created pod: eval-conflicts-rho010-r4-085-s5sbm
0.2065,Event,ADDED,eval-conflicts-rho010-r4-085.18d542f24c38555c,reason=Completed count=1 msg=Job completed
0.2066,Event,ADDED,eval-conflicts-rho010-r4-086-kkh98.18d542ececef3dde,"reason=FailedScheduling count=None msg=0/6 nodes are available: 6 node(s) had untolerated taint(s). no new claims to deallocate, preemption: 0/6 nodes are available: 6 Preemption is not helpful for scheduling."
0.2068,Event,ADDED,eval-conflicts-rho010-r4-086-kkh98.18d542ee9a177ac6,reason=Scheduled count=None msg=Successfully assigned compute/eval-conflicts-rho010-r4-086-kkh98 to kind-worker3
0.207,Event,ADDED,eval-conflicts-rho010-r4-086-kkh98.18d542eec0401713,"reason=Pulled count=1 msg=Container image ""busybox:musl"" already present on machine"
0.2076,Event,ADDED,eval-conflicts-rho010-r4-086-kkh98.18d542eec541a074,reason=Created count=1 msg=Created container: task
0.2077,Event,ADDED,eval-conflicts-rho010-r4-086-kkh98.18d542eecafeec79,reason=Started count=1 msg=Started container task
0.2079,Event,ADDED,eval-conflicts-rho010-r4-086.18d542ecece4699a,reason=SuccessfulCreate count=1 msg=Created pod: eval-conflicts-rho010-r4-086-kkh98
0.2082,Event,ADDED,eval-conflicts-rho010-r4-086.18d542f449573664,reason=Completed count=1 msg=Job completed
0.2084,Event,ADDED,eval-conflicts-rho010-r4-087-dh7dk.18d542ed2c30c1ba,"reason=FailedScheduling count=None msg=0/6 nodes are available: 6 node(s) had untolerated taint(s). no new claims to deallocate, preemption: 0/6 nodes are available: 6 Preemption is not helpful for scheduling."
0.2086,Event,ADDED,eval-conflicts-rho010-r4-087-dh7dk.18d542ee9aacddc9,reason=Scheduled count=None msg=Successfully assigned compute/eval-conflicts-rho010-r4-087-dh7dk to kind-worker3
0.2087,Event,ADDED,eval-conflicts-rho010-r4-087-dh7dk.18d542eec03739c8,"reason=Pulled count=1 msg=Container image ""busybox:musl"" already present on machine"
0.2092,Event,ADDED,eval-conflicts-rho010-r4-087-dh7dk.18d542eec4248191,reason=Created count=1 msg=Created container: task
0.2094,Event,ADDED,eval-conflicts-rho010-r4-087-dh7dk.18d542eecae497d5,reason=Started count=1 msg=Started container task
0.2096,Event,ADDED,eval-conflicts-rho010-r4-087.18d542ed2c28295c,reason=SuccessfulCreate count=1 msg=Created pod: eval-conflicts-rho010-r4-087-dh7dk
0.21,Event,ADDED,eval-conflicts-rho010-r4-087.18d542f447e84593,reason=Completed count=1 msg=Job completed
0.2102,Event,ADDED,eval-conflicts-rho010-r4-088-grphk.18d542ed68460d1b,"reason=FailedScheduling count=None msg=0/6 nodes are available: 6 node(s) had untolerated taint(s). no new claims to deallocate, preemption: 0/6 nodes are available: 6 Preemption is not helpful for scheduling."
0.2103,Event,ADDED,eval-conflicts-rho010-r4-088-grphk.18d542ee9a312706,"reason=FailedScheduling count=None msg=0/6 nodes are available: 1 c_wall violated: 1 conflicting context pair(s) with node memory, 5 node(s) had untolerated taint(s). no new claims to deallocate, preemption: 0/6 nodes are available: 1 No preemption victims found for incoming pod, 5 Preemption is not helpful for scheduling."
0.2107,Event,ADDED,eval-conflicts-rho010-r4-088-grphk.18d542eea2755442,"reason=FailedScheduling count=None msg=0/6 nodes are available: 1 c_wall violated: 1 conflicting context pair(s) with node memory, 5 node(s) had untolerated taint(s). no new claims to deallocate, preemption: 0/6 nodes are available: 1 No preemption victims found for incoming pod, 5 Preemption is not helpful for scheduling."
0.2109,Event,ADDED,eval-conflicts-rho010-r4-088-grphk.18d542f35c396267,reason=Scheduled count=None msg=Successfully assigned compute/eval-conflicts-rho010-r4-088-grphk to kind-worker2
0.2113,Event,ADDED,eval-conflicts-rho010-r4-088-grphk.18d542f378c89fd4,"reason=Pulled count=1 msg=Container image ""busybox:musl"" already present on machine"
0.2115,Event,ADDED,eval-conflicts-rho010-r4-088-grphk.18d542f37b50d350,reason=Created count=1 msg=Created container: task
0.2118,Event,ADDED,eval-conflicts-rho010-r4-088-grphk.18d542f37eb01db4,reason=Started count=1 msg=Started container task
0.212,Event,ADDED,eval-conflicts-rho010-r4-088.18d542ed6837ff84,reason=SuccessfulCreate count=1 msg=Created pod: eval-conflicts-rho010-r4-088-grphk
0.2122,Event,ADDED,eval-conflicts-rho010-r4-088.18d542f8dc6ddd3e,reason=Completed count=1 msg=Job completed
0.2124,Event,ADDED,eval-conflicts-rho010-r4-089-xjzlb.18d542ed9d9afae2,"reason=FailedScheduling count=None msg=0/6 nodes are available: 6 node(s) had untolerated taint(s). no new claims to deallocate, preemption: 0/6 nodes are available: 6 Preemption is not helpful for scheduling."
0.2127,Event,ADDED,eval-conflicts-rho010-r4-089-xjzlb.18d542ee9c0052e2,reason=Scheduled count=None msg=Successfully assigned compute/eval-conflicts-rho010-r4-089-xjzlb to kind-worker3
0.2129,Event,ADDED,eval-conflicts-rho010-r4-089-xjzlb.18d542eec06d020f,"reason=Pulled count=1 msg=Container image ""busybox:musl"" already present on machine"
0.2131,Event,ADDED,eval-conflicts-rho010-r4-089-xjzlb.18d542eec59bdd67,reason=Created count=1 msg=Created container: task
0.2133,Event,ADDED,eval-conflicts-rho010-r4-089-xjzlb.18d542eecafeb959,reason=Started count=1 msg=Started container task
0.2135,Event,ADDED,eval-conflicts-rho010-r4-089.18d542ed9d8df2b4,reason=SuccessfulCreate count=1 msg=Created pod: eval-conflicts-rho010-r4-089-xjzlb
0.2137,Event,ADDED,eval-conflicts-rho010-r4-089.18d542f447e93b9c,reason=Completed count=1 msg=Job completed
0.2138,Event,ADDED,eval-conflicts-rho010-r4-090-vk7mz.18d542edd92f0940,"reason=FailedScheduling count=None msg=0/6 nodes are available: 6 node(s) had untolerated taint(s). no new claims to deallocate, preemption: 0/6 nodes are available: 6 Preemption is not helpful for scheduling."
0.2141,Event,ADDED,eval-conflicts-rho010-r4-090-vk7mz.18d542ee9c434444,reason=Scheduled count=None msg=Successfully assigned compute/eval-conflicts-rho010-r4-090-vk7mz to kind-worker3
0.2143,Event,ADDED,eval-conflicts-rho010-r4-090-vk7mz.18d542eec092b599,"reason=Pulled count=1 msg=Container image ""busybox:musl"" already present on machine"
0.2145,Event,ADDED,eval-conflicts-rho010-r4-090-vk7mz.18d542eec5ea3ff5,reason=Created count=1 msg=Created container: task
0.2148,Event,ADDED,eval-conflicts-rho010-r4-090-vk7mz.18d542eecae4224c,reason=Started count=1 msg=Started container task
0.215,Event,ADDED,eval-conflicts-rho010-r4-090.18d542edd921f617,reason=SuccessfulCreate count=1 msg=Created pod: eval-conflicts-rho010-r4-090-vk7mz
0.2152,Event,ADDED,eval-conflicts-rho010-r4-090.18d542f447e9307b,reason=Completed count=1 msg=Job completed
0.2154,Event,ADDED,eval-conflicts-rho010-r4-091-c4thj.18d542ee14c90a5a,"reason=FailedScheduling count=None msg=0/6 nodes are available: 6 node(s) had untolerated taint(s). no new claims to deallocate, preemption: 0/6 nodes are available: 6 Preemption is not helpful for scheduling."
0.2156,Event,ADDED,eval-conflicts-rho010-r4-091-c4thj.18d542eea21ab4ec,reason=Scheduled count=None msg=Successfully assigned compute/eval-conflicts-rho010-r4-091-c4thj to kind-worker3
0.2158,Event,ADDED,eval-conflicts-rho010-r4-091-c4thj.18d542eec0faac39,"reason=Pulled count=1 msg=Container image ""busybox:musl"" already present on machine"
0.2159,Event,ADDED,eval-conflicts-rho010-r4-091-c4thj.18d542eec648f424,reason=Created count=1 msg=Created container: task
0.2162,Event,ADDED,eval-conflicts-rho010-r4-091-c4thj.18d542eecafe4aac,reason=Started count=1 msg=Started container task
0.2163,Event,ADDED,eval-conflicts-rho010-r4-091.18d542ee14be5971,reason=SuccessfulCreate count=1 msg=Created pod: eval-conflicts-rho010-r4-091-c4thj
0.2165,Event,ADDED,eval-conflicts-rho010-r4-091.18d542f447be1608,reason=Completed count=1 msg=Job completed
0.2166,Event,ADDED,eval-conflicts-rho010-r4-092-dbv9f.18d542ee5230b5d4,"reason=FailedScheduling count=None msg=0/6 nodes are available: 6 node(s) had untolerated taint(s). no new claims to deallocate, preemption: 0/6 nodes are available: 6 Preemption is not helpful for scheduling."
0.2168,Event,ADDED,eval-conflicts-rho010-r4-092-dbv9f.18d542eea2259b5a,reason=Scheduled count=None msg=Successfully assigned compute/eval-conflicts-rho010-r4-092-dbv9f to kind-worker3
0.217,Event,ADDED,eval-conflicts-rho010-r4-092-dbv9f.18d542eec1188875,"reason=Pulled count=1 msg=Container image ""busybox:musl"" already present on machine"
0.2172,Event,ADDED,eval-conflicts-rho010-r4-092-dbv9f.18d542eec62d58b2,reason=Created count=1 msg=Created container: task
0.2174,Event,ADDED,eval-conflicts-rho010-r4-092-dbv9f.18d542eecafce73c,reason=Started count=1 msg=Started container task
0.2175,Event,ADDED,eval-conflicts-rho010-r4-092.18d542ee5228a26e,reason=SuccessfulCreate count=1 msg=Created pod: eval-conflicts-rho010-r4-092-dbv9f
0.2177,Event,ADDED,eval-conflicts-rho010-r4-092.18d542f44cd55e60,reason=Completed count=1 msg=Job completed
0.2178,Event,ADDED,eval-conflicts-rho010-r4-093-gvxvm.18d542ee8bf4466b,"reason=FailedScheduling count=None msg=0/6 nodes are available: 6 node(s) had untolerated taint(s). no new claims to deallocate, preemption: 0/6 nodes are available: 6 Preemption is not helpful for scheduling."
0.218,Event,ADDED,eval-conflicts-rho010-r4-093-gvxvm.18d542ee9f5dd11d,"reason=FailedScheduling count=None msg=0/6 nodes are available: 1 c_wall violated: 1 conflicting context pair(s) with node memory, 5 node(s) had untolerated taint(s). no new claims to deallocate, preemption: 0/6 nodes are available: 1 No preemption victims found for incoming pod, 5 Preemption is not helpful for scheduling."
0.2182,Event,ADDED,eval-conflicts-rho010-r4-093-gvxvm.18d542eea2ac6ea9,"reason=FailedScheduling count=None msg=0/6 nodes are available: 1 c_wall violated: 1 conflicting context pair(s) with node memory, 5 node(s) had untolerated taint(s). no new claims to deallocate, preemption: 0/6 nodes are available: 1 No preemption victims found for incoming pod, 5 Preemption is not helpful for scheduling."
0.2183,Event,ADDED,eval-conflicts-rho010-r4-093-gvxvm.18d542f35ce261d2,reason=Scheduled count=None msg=Successfully assigned compute/eval-conflicts-rho010-r4-093-gvxvm to kind-worker2
0.2185,Event,ADDED,eval-conflicts-rho010-r4-093-gvxvm.18d542f37f379fa5,"reason=Pulled count=1 msg=Container image ""busybox:musl"" already present on machine"
0.2187,Event,ADDED,eval-conflicts-rho010-r4-093-gvxvm.18d542f385098b7d,reason=Created count=1 msg=Created container: task
0.2189,Event,ADDED,eval-conflicts-rho010-r4-093-gvxvm.18d542f38894b115,reason=Started count=1 msg=Started container task
0.219,Event,ADDED,eval-conflicts-rho010-r4-093.18d542ee8be6ee94,reason=SuccessfulCreate count=1 msg=Created pod: eval-conflicts-rho010-r4-093-gvxvm
0.2195,Event,ADDED,eval-conflicts-rho010-r4-093.18d542f954811f40,reason=Completed count=1 msg=Job completed
0.2197,Event,ADDED,eval-conflicts-rho010-r4-094-mxtsh.18d542eec84accce,"reason=FailedScheduling count=None msg=0/6 nodes are available: 1 c_wall violated: 1 conflicting context pair(s) with node memory, 5 node(s) had untolerated taint(s). no new claims to deallocate, preemption: 0/6 nodes are available: 1 No preemption victims found for incoming pod, 5 Preemption is not helpful for scheduling."
0.2199,Event,ADDED,eval-conflicts-rho010-r4-094-mxtsh.18d542eec8ef44cf,"reason=FailedScheduling count=None msg=0/6 nodes are available: 1 c_wall violated: 1 conflicting context pair(s) with node memory, 5 node(s) had untolerated taint(s). no new claims to deallocate, preemption: 0/6 nodes are available: 1 No preemption victims found for incoming pod, 5 Preemption is not helpful for scheduling."
0.2202,Event,ADDED,eval-conflicts-rho010-r4-094-mxtsh.18d542f3623f454d,reason=Scheduled count=None msg=Successfully assigned compute/eval-conflicts-rho010-r4-094-mxtsh to kind-worker2
0.2203,Event,ADDED,eval-conflicts-rho010-r4-094-mxtsh.18d542f37f8652cf,"reason=Pulled count=1 msg=Container image ""busybox:musl"" already present on machine"
0.2205,Event,ADDED,eval-conflicts-rho010-r4-094-mxtsh.18d542f385632616,reason=Created count=1 msg=Created container: task
0.2207,Event,ADDED,eval-conflicts-rho010-r4-094-mxtsh.18d542f389174511,reason=Started count=1 msg=Started container task
0.2209,Event,ADDED,eval-conflicts-rho010-r4-094.18d542eec7f73f40,reason=SuccessfulCreate count=1 msg=Created pod: eval-conflicts-rho010-r4-094-mxtsh
0.2211,Event,ADDED,eval-conflicts-rho010-r4-094.18d542f8e4bf1855,reason=Completed count=1 msg=Job completed
0.2213,Event,ADDED,eval-conflicts-rho010-r4-095-p7td6.18d542ef03ea097d,"reason=FailedScheduling count=None msg=0/6 nodes are available: 1 c_wall violated: 1 conflicting context pair(s) with node memory, 5 node(s) had untolerated taint(s). no new claims to deallocate, preemption: 0/6 nodes are available: 1 No preemption victims found for incoming pod, 5 Preemption is not helpful for scheduling."
0.2215,Event,ADDED,eval-conflicts-rho010-r4-095-p7td6.18d542ef04753924,"reason=FailedScheduling count=None msg=0/6 nodes are available: 1 c_wall violated: 1 conflicting context pair(s) with node memory, 5 node(s) had untolerated taint(s). no new claims to deallocate, preemption: 0/6 nodes are available: 1 No preemption victims found for incoming pod, 5 Preemption is not helpful for scheduling."
0.2216,Event,ADDED,eval-conflicts-rho010-r4-095-p7td6.18d542f362ec6e67,reason=Scheduled count=None msg=Successfully assigned compute/eval-conflicts-rho010-r4-095-p7td6 to kind-worker2
0.2218,Event,ADDED,eval-conflicts-rho010-r4-095-p7td6.18d542f37ffa0dfb,"reason=Pulled count=1 msg=Container image ""busybox:musl"" already present on machine"
0.222,Event,ADDED,eval-conflicts-rho010-r4-095-p7td6.18d542f38582b84a,reason=Created count=1 msg=Created container: task
0.2222,Event,ADDED,eval-conflicts-rho010-r4-095-p7td6.18d542f389150546,reason=Started count=1 msg=Started container task
0.2223,Event,ADDED,eval-conflicts-rho010-r4-095.18d542ef03ae72cc,reason=SuccessfulCreate count=1 msg=Created pod: eval-conflicts-rho010-r4-095-p7td6
0.2225,Event,ADDED,eval-conflicts-rho010-r4-095.18d542f8dc3ed396,reason=Completed count=1 msg=Job completed
0.2227,Event,ADDED,eval-conflicts-rho010-r4-096-kd8tq.18d542ef3f73c208,reason=Scheduled count=None msg=Successfully assigned compute/eval-conflicts-rho010-r4-096-kd8tq to kind-worker3
0.2228,Event,ADDED,eval-conflicts-rho010-r4-096-kd8tq.18d542ef5de36ecb,"reason=Pulled count=1 msg=Container image ""busybox:musl"" already present on machine"
0.223,Event,ADDED,eval-conflicts-rho010-r4-096-kd8tq.18d542ef5f22d232,reason=Created count=1 msg=Created container: task
0.2232,Event,ADDED,eval-conflicts-rho010-r4-096-kd8tq.18d542ef67fe6034,reason=Started count=1 msg=Started container task
0.2234,Event,ADDED,eval-conflicts-rho010-r4-096.18d542ef3edc7086,reason=SuccessfulCreate count=1 msg=Created pod: eval-conflicts-rho010-r4-096-kd8tq
0.2235,Event,ADDED,eval-conflicts-rho010-r4-096.18d542f4fb9e4b65,reason=Completed count=1 msg=Job completed
0.2237,Event,ADDED,eval-conflicts-rho010-r4-097-jc9rg.18d542ef7b77237b,reason=Scheduled count=None msg=Successfully assigned compute/eval-conflicts-rho010-r4-097-jc9rg to kind-worker3
0.2239,Event,ADDED,eval-conflicts-rho010-r4-097-jc9rg.18d542ef95ecaccd,"reason=Pulled count=1 msg=Container image ""busybox:musl"" already present on machine"
0.224,Event,ADDED,eval-conflicts-rho010-r4-097-jc9rg.18d542ef99096bb6,reason=Created count=1 msg=Created container: task
0.2242,Event,ADDED,eval-conflicts-rho010-r4-097-jc9rg.18d542ef9f7c9687,reason=Started count=1 msg=Started container task
0.2244,Event,ADDED,eval-conflicts-rho010-r4-097.18d542ef7ae70b36,reason=SuccessfulCreate count=1 msg=Created pod: eval-conflicts-rho010-r4-097-jc9rg
0.2245,Event,ADDED,eval-conflicts-rho010-r4-097.18d542f5370be328,reason=Completed count=1 msg=Job completed
0.2247,Event,ADDED,eval-conflicts-rho010-r4-098-r5j5g.18d542efb8a2a8a6,reason=Scheduled count=None msg=Successfully assigned compute/eval-conflicts-rho010-r4-098-r5j5g to kind-worker3
0.2249,Event,ADDED,eval-conflicts-rho010-r4-098-r5j5g.18d542efd24ad869,"reason=Pulled count=1 msg=Container image ""busybox:musl"" already present on machine"
0.2274,Event,ADDED,eval-conflicts-rho010-r4-098-r5j5g.18d542efd37748ce,reason=Created count=1 msg=Created container: task
0.2276,Event,ADDED,eval-conflicts-rho010-r4-098-r5j5g.18d542efdbbec80c,reason=Started count=1 msg=Started container task
0.2278,Event,ADDED,eval-conflicts-rho010-r4-098.18d542efb82c9646,reason=SuccessfulCreate count=1 msg=Created pod: eval-conflicts-rho010-r4-098-r5j5g
0.228,Event,ADDED,eval-conflicts-rho010-r4-098.18d542f572de943d,reason=Completed count=1 msg=Job completed
0.2285,Event,ADDED,eval-conflicts-rho010-r4-099-zghb7.18d542eff2a21e08,reason=Scheduled count=None msg=Successfully assigned compute/eval-conflicts-rho010-r4-099-zghb7 to kind-worker3
0.2286,Event,ADDED,eval-conflicts-rho010-r4-099-zghb7.18d542f00c711ee3,"reason=Pulled count=1 msg=Container image ""busybox:musl"" already present on machine"
0.2288,Event,ADDED,eval-conflicts-rho010-r4-099-zghb7.18d542f00d986ebb,reason=Created count=1 msg=Created container: task
0.229,Event,ADDED,eval-conflicts-rho010-r4-099-zghb7.18d542f00f81e7f1,reason=Started count=1 msg=Started container task
0.2291,Event,ADDED,eval-conflicts-rho010-r4-099.18d542eff216bf7d,reason=SuccessfulCreate count=1 msg=Created pod: eval-conflicts-rho010-r4-099-zghb7
0.2293,Event,ADDED,eval-conflicts-rho010-r4-099.18d542f572dd8438,reason=Completed count=1 msg=Job completed
0.2294,Event,ADDED,eval-conflicts-rho010-r4-100-lkhq4.18d542f02d76971e,"reason=FailedScheduling count=None msg=0/6 nodes are available: 1 c_wall violated: 1 conflicting context pair(s) with node memory, 5 node(s) had untolerated taint(s). no new claims to deallocate, preemption: 0/6 nodes are available: 1 No preemption victims found for incoming pod, 5 Preemption is not helpful for scheduling."
0.2296,Event,ADDED,eval-conflicts-rho010-r4-100-lkhq4.18d542f02df9a7ff,"reason=FailedScheduling count=None msg=0/6 nodes are available: 1 c_wall violated: 1 conflicting context pair(s) with node memory, 5 node(s) had untolerated taint(s). no new claims to deallocate, preemption: 0/6 nodes are available: 1 No preemption victims found for incoming pod, 5 Preemption is not helpful for scheduling."
0.2298,Event,ADDED,eval-conflicts-rho010-r4-100-lkhq4.18d542f3626d162b,reason=Scheduled count=None msg=Successfully assigned compute/eval-conflicts-rho010-r4-100-lkhq4 to kind-worker2
0.2299,Event,ADDED,eval-conflicts-rho010-r4-100-lkhq4.18d542f37dfff7c6,"reason=Pulled count=1 msg=Container image ""busybox:musl"" already present on machine"
0.2302,Event,ADDED,eval-conflicts-rho010-r4-100-lkhq4.18d542f3839b1ac7,reason=Created count=1 msg=Created container: task
0.2305,Event,ADDED,eval-conflicts-rho010-r4-100-lkhq4.18d542f3865afff8,reason=Started count=1 msg=Started container task
0.2307,Event,ADDED,eval-conflicts-rho010-r4-100.18d542f02d360531,reason=SuccessfulCreate count=1 msg=Created pod: eval-conflicts-rho010-r4-100-lkhq4
0.2308,Event,ADDED,eval-conflicts-rho010-r4-100.18d542f95666167d,reason=Completed count=1 msg=Job completed
0.2311,Event,ADDED,eval-conflicts-rho010-r4-101-lpcxd.18d542f0698176ad,reason=Scheduled count=None msg=Successfully assigned compute/eval-conflicts-rho010-r4-101-lpcxd to kind-worker3
0.2313,Event,ADDED,eval-conflicts-rho010-r4-101-lpcxd.18d542f082963bba,"reason=Pulled count=1 msg=Container image ""busybox:musl"" already present on machine"
0.2315,Event,ADDED,eval-conflicts-rho010-r4-101-lpcxd.18d542f083a0c806,reason=Created count=1 msg=Created container: task
0.2316,Event,ADDED,eval-conflicts-rho010-r4-101-lpcxd.18d542f085c94b3d,reason=Started count=1 msg=Started container task
0.2319,Event,ADDED,eval-conflicts-rho010-r4-101.18d542f068f53f58,reason=SuccessfulCreate count=1 msg=Created pod: eval-conflicts-rho010-r4-101-lpcxd
0.2321,Event,ADDED,eval-conflicts-rho010-r4-101.18d542f626e87ef5,reason=Completed count=1 msg=Job completed
0.2322,Event,ADDED,eval-conflicts-rho010-r4-102-mjs97.18d542f0a5169cce,reason=Scheduled count=None msg=Successfully assigned compute/eval-conflicts-rho010-r4-102-mjs97 to kind-worker3
0.2324,Event,ADDED,eval-conflicts-rho010-r4-102-mjs97.18d542f0bf4d04a8,"reason=Pulled count=1 msg=Container image ""busybox:musl"" already present on machine"
0.2327,Event,ADDED,eval-conflicts-rho010-r4-102-mjs97.18d542f0c0760146,reason=Created count=1 msg=Created container: task
0.2328,Event,ADDED,eval-conflicts-rho010-r4-102-mjs97.18d542f0c28b4f95,reason=Started count=1 msg=Started container task
0.233,Event,ADDED,eval-conflicts-rho010-r4-102.18d542f0a47b2cef,reason=SuccessfulCreate count=1 msg=Created pod: eval-conflicts-rho010-r4-102-mjs97
0.2334,Event,ADDED,eval-conflicts-rho010-r4-102.18d542f626ce7419,reason=Completed count=1 msg=Job completed
0.2336,Event,ADDED,eval-conflicts-rho010-r4-103-q9fws.18d542f0e0e49af9,reason=Scheduled count=None msg=Successfully assigned compute/eval-conflicts-rho010-r4-103-q9fws to kind-worker3
0.2338,Event,ADDED,eval-conflicts-rho010-r4-103-q9fws.18d542f0f8f0525f,"reason=Pulled count=1 msg=Container image ""busybox:musl"" already present on machine"
0.234,Event,ADDED,eval-conflicts-rho010-r4-103-q9fws.18d542f0fa004267,reason=Created count=1 msg=Created container: task
0.2343,Event,ADDED,eval-conflicts-rho010-r4-103-q9fws.18d542f0fbd8534e,reason=Started count=1 msg=Started container task
0.2345,Event,ADDED,eval-conflicts-rho010-r4-103.18d542f0e0510f7f,reason=SuccessfulCreate count=1 msg=Created pod: eval-conflicts-rho010-r4-103-q9fws
0.2349,Event,ADDED,eval-conflicts-rho010-r4-103.18d542f66297e0dd,reason=Completed count=1 msg=Job completed
0.2354,Event,ADDED,eval-conflicts-rho010-r4-104-8zpxj.18d542f11cb8871b,"reason=FailedScheduling count=None msg=0/6 nodes are available: 1 c_wall violated: 2 conflicting context pair(s) with node memory, 5 node(s) had untolerated taint(s). no new claims to deallocate, preemption: 0/6 nodes are available: 1 No preemption victims found for incoming pod, 5 Preemption is not helpful for scheduling."
0.2356,Event,ADDED,eval-conflicts-rho010-r4-104-8zpxj.18d542f11d46bac5,"reason=FailedScheduling count=None msg=0/6 nodes are available: 1 c_wall violated: 2 conflicting context pair(s) with node memory, 5 node(s) had untolerated taint(s). no new claims to deallocate, preemption: 0/6 nodes are available: 1 No preemption victims found for incoming pod, 5 Preemption is not helpful for scheduling."
0.2358,Event,ADDED,eval-conflicts-rho010-r4-104-8zpxj.18d542f35cabc427,reason=Scheduled count=None msg=Successfully assigned compute/eval-conflicts-rho010-r4-104-8zpxj to kind-worker2
0.2359,Event,ADDED,eval-conflicts-rho010-r4-104-8zpxj.18d542f37d9ff59f,"reason=Pulled count=1 msg=Container image ""busybox:musl"" already present on machine"
0.2362,Event,ADDED,eval-conflicts-rho010-r4-104-8zpxj.18d542f381322946,reason=Created count=1 msg=Created container: task
0.2364,Event,ADDED,eval-conflicts-rho010-r4-104-8zpxj.18d542f38549a067,reason=Started count=1 msg=Started container task
0.2365,Event,ADDED,eval-conflicts-rho010-r4-104.18d542f11c6222f3,reason=SuccessfulCreate count=1 msg=Created pod: eval-conflicts-rho010-r4-104-8zpxj
0.2368,Event,ADDED,eval-conflicts-rho010-r4-104.18d542f8f39e0ee8,reason=Completed count=1 msg=Job completed
0.2369,Event,ADDED,eval-conflicts-rho010-r4-105-5625d.18d542f157fd07fb,reason=Scheduled count=None msg=Successfully assigned compute/eval-conflicts-rho010-r4-105-5625d to kind-worker3
0.2371,Event,ADDED,eval-conflicts-rho010-r4-105-5625d.18d542f1711ec528,"reason=Pulled count=1 msg=Container image ""busybox:musl"" already present on machine"
0.2373,Event,ADDED,eval-conflicts-rho010-r4-105-5625d.18d542f17240a8a7,reason=Created count=1 msg=Created container: task
0.2374,Event,ADDED,eval-conflicts-rho010-r4-105-5625d.18d542f176771485,reason=Started count=1 msg=Started container task
0.2376,Event,ADDED,eval-conflicts-rho010-r4-105.18d542f157713d9c,reason=SuccessfulCreate count=1 msg=Created pod: eval-conflicts-rho010-r4-105-5625d
0.2378,Event,ADDED,eval-conflicts-rho010-r4-105.18d542f6da5440d2,reason=Completed count=1 msg=Job completed
0.238,Event,ADDED,eval-conflicts-rho010-r4-106-46qsp.18d542f1938c834e,reason=Scheduled count=None msg=Successfully assigned compute/eval-conflicts-rho010-r4-106-46qsp to kind-worker3
0.2381,Event,ADDED,eval-conflicts-rho010-r4-106-46qsp.18d542f1ad496d60,"reason=Pulled count=1 msg=Container image ""busybox:musl"" already present on machine"
0.2384,Event,ADDED,eval-conflicts-rho010-r4-106-46qsp.18d542f1ae56190c,reason=Created count=1 msg=Created container: task
0.2386,Event,ADDED,eval-conflicts-rho010-r4-106-46qsp.18d542f1b070c15d,reason=Started count=1 msg=Started container task
0.2389,Event,ADDED,eval-conflicts-rho010-r4-106.18d542f192ee1a0d,reason=SuccessfulCreate count=1 msg=Created pod: eval-conflicts-rho010-r4-106-46qsp
0.2391,Event,ADDED,eval-conflicts-rho010-r4-106.18d542f716fb3df6,reason=Completed count=1 msg=Job completed
0.2392,Event,ADDED,eval-conflicts-rho010-r4-107-9p5s9.18d542f1ced48095,"reason=FailedScheduling count=None msg=0/6 nodes are available: 1 c_wall violated: 1 conflicting context pair(s) with node memory, 5 node(s) had untolerated taint(s). no new claims to deallocate, preemption: 0/6 nodes are available: 1 No preemption victims found for incoming pod, 5 Preemption is not helpful for scheduling."
0.2396,Event,ADDED,eval-conflicts-rho010-r4-107-9p5s9.18d542f1cf55a9ff,"reason=FailedScheduling count=None msg=0/6 nodes are available: 1 c_wall violated: 1 conflicting context pair(s) with node memory, 5 node(s) had untolerated taint(s). no new claims to deallocate, preemption: 0/6 nodes are available: 1 No preemption victims found for incoming pod, 5 Preemption is not helpful for scheduling."
0.2397,Event,ADDED,eval-conflicts-rho010-r4-107-9p5s9.18d542f35d1f46e2,reason=Scheduled count=None msg=Successfully assigned compute/eval-conflicts-rho010-r4-107-9p5s9 to kind-worker2
0.2399,Event,ADDED,eval-conflicts-rho010-r4-107-9p5s9.18d542f37ec42a6b,"reason=Pulled count=1 msg=Container image ""busybox:musl"" already present on machine"
0.2401,Event,ADDED,eval-conflicts-rho010-r4-107-9p5s9.18d542f384a8af58,reason=Created count=1 msg=Created container: task
0.2404,Event,ADDED,eval-conflicts-rho010-r4-107-9p5s9.18d542f3884b3598,reason=Started count=1 msg=Started container task
0.2405,Event,ADDED,eval-conflicts-rho010-r4-107.18d542f1ce99084b,reason=SuccessfulCreate count=1 msg=Created pod: eval-conflicts-rho010-r4-107-9p5s9
0.2407,Event,ADDED,eval-conflicts-rho010-r4-107.18d542f8dc980ac4,reason=Completed count=1 msg=Job completed
0.2409,Event,ADDED,eval-conflicts-rho010-r4-108-lmdk8.18d542f20b28855e,"reason=FailedScheduling count=None msg=0/6 nodes are available: 1 c_wall violated: 1 conflicting context pair(s) with node memory, 5 node(s) had untolerated taint(s). no new claims to deallocate, preemption: 0/6 nodes are available: 1 No preemption victims found for incoming pod, 5 Preemption is not helpful for scheduling."
0.2411,Event,ADDED,eval-conflicts-rho010-r4-108-lmdk8.18d542f20bbc75cf,"reason=FailedScheduling count=None msg=0/6 nodes are available: 1 c_wall violated: 1 conflicting context pair(s) with node memory, 5 node(s) had untolerated taint(s). no new claims to deallocate, preemption: 0/6 nodes are available: 1 No preemption victims found for incoming pod, 5 Preemption is not helpful for scheduling."
0.2412,Event,ADDED,eval-conflicts-rho010-r4-108-lmdk8.18d542f35d6f732d,reason=Scheduled count=None msg=Successfully assigned compute/eval-conflicts-rho010-r4-108-lmdk8 to kind-worker2
0.2414,Event,ADDED,eval-conflicts-rho010-r4-108-lmdk8.18d542f37f601fb0,"reason=Pulled count=1 msg=Container image ""busybox:musl"" already present on machine"
0.2416,Event,ADDED,eval-conflicts-rho010-r4-108-lmdk8.18d542f3849082bc,reason=Created count=1 msg=Created container: task
0.2417,Event,ADDED,eval-conflicts-rho010-r4-108-lmdk8.18d542f3884a7d1a,reason=Started count=1 msg=Started container task
0.2419,Event,ADDED,eval-conflicts-rho010-r4-108.18d542f20ae907f2,reason=SuccessfulCreate count=1 msg=Created pod: eval-conflicts-rho010-r4-108-lmdk8
0.2421,Event,ADDED,eval-conflicts-rho010-r4-108.18d542f8debbc801,reason=Completed count=1 msg=Job completed
0.2422,Event,ADDED,eval-conflicts-rho010-r4-109-hpcrc.18d542f246721df6,reason=Scheduled count=None msg=Successfully assigned compute/eval-conflicts-rho010-r4-109-hpcrc to kind-worker3
0.2426,Event,ADDED,eval-conflicts-rho010-r4-109-hpcrc.18d542f25f01c5c2,"reason=Pulled count=1 msg=Container image ""busybox:musl"" already present on machine"
0.2428,Event,ADDED,eval-conflicts-rho010-r4-109-hpcrc.18d542f260179ace,reason=Created count=1 msg=Created container: task
0.243,Event,ADDED,eval-conflicts-rho010-r4-109-hpcrc.18d542f26205898d,reason=Started count=1 msg=Started container task
0.2431,Event,ADDED,eval-conflicts-rho010-r4-109.18d542f245e57589,reason=SuccessfulCreate count=1 msg=Created pod: eval-conflicts-rho010-r4-109-hpcrc
0.2433,Event,ADDED,eval-conflicts-rho010-r4-109.18d542f7ce5af5d3,reason=Completed count=1 msg=Job completed
0.2435,Event,ADDED,eval-conflicts-rho010-r4-110-kh4g6.18d542f281744c7c,"reason=FailedScheduling count=None msg=0/6 nodes are available: 1 c_wall violated: 1 conflicting context pair(s) with node memory, 5 node(s) had untolerated taint(s). no new claims to deallocate, preemption: 0/6 nodes are available: 1 No preemption victims found for incoming pod, 5 Preemption is not helpful for scheduling."
0.2436,Event,ADDED,eval-conflicts-rho010-r4-110-kh4g6.18d542f281edc315,"reason=FailedScheduling count=None msg=0/6 nodes are available: 1 c_wall violated: 1 conflicting context pair(s) with node memory, 5 node(s) had untolerated taint(s). no new claims to deallocate, preemption: 0/6 nodes are available: 1 No preemption victims found for incoming pod, 5 Preemption is not helpful for scheduling."
0.2438,Event,ADDED,eval-conflicts-rho010-r4-110-kh4g6.18d542f35c6dfdf3,reason=Scheduled count=None msg=Successfully assigned compute/eval-conflicts-rho010-r4-110-kh4g6 to kind-worker2
0.244,Event,ADDED,eval-conflicts-rho010-r4-110-kh4g6.18d542f37daeb85d,"reason=Pulled count=1 msg=Container image ""busybox:musl"" already present on machine"
0.2443,Event,ADDED,eval-conflicts-rho010-r4-110-kh4g6.18d542f382f8cd53,reason=Created count=1 msg=Created container: task
0.2444,Event,ADDED,eval-conflicts-rho010-r4-110-kh4g6.18d542f38600c93e,reason=Started count=1 msg=Started container task
0.2446,Event,ADDED,eval-conflicts-rho010-r4-110.18d542f281305d58,reason=SuccessfulCreate count=1 msg=Created pod: eval-conflicts-rho010-r4-110-kh4g6
0.2449,Event,ADDED,eval-conflicts-rho010-r4-110.18d542f8dc98c1a3,reason=Completed count=1 msg=Job completed
0.2451,Event,ADDED,eval-conflicts-rho010-r4-111-5qfr7.18d542f2bd907d43,reason=Scheduled count=None msg=Successfully assigned compute/eval-conflicts-rho010-r4-111-5qfr7 to kind-worker3
0.2453,Event,ADDED,eval-conflicts-rho010-r4-111-5qfr7.18d542f2d67afea2,"reason=Pulled count=1 msg=Container image ""busybox:musl"" already present on machine"
0.2454,Event,ADDED,eval-conflicts-rho010-r4-111-5qfr7.18d542f2d7904455,reason=Created count=1 msg=Created container: task
0.2457,Event,ADDED,eval-conflicts-rho010-r4-111-5qfr7.18d542f2daaf25be,reason=Started count=1 msg=Started container task
0.2459,Event,ADDED,eval-conflicts-rho010-r4-111.18d542f2bd041858,reason=SuccessfulCreate count=1 msg=Created pod: eval-conflicts-rho010-r4-111-5qfr7
0.2461,Event,ADDED,eval-conflicts-rho010-r4-111.18d542f846c56fc3,reason=Completed count=1 msg=Job completed
0.2463,Event,ADDED,eval-conflicts-rho010-r4-112-r5lwc.18d542f2f97a651f,"reason=FailedScheduling count=None msg=0/6 nodes are available: 1 c_wall violated: 1 conflicting context pair(s) with node memory, 5 node(s) had untolerated taint(s). no new claims to deallocate, preemption: 0/6 nodes are available: 1 No preemption victims found for incoming pod, 5 Preemption is not helpful for scheduling."
0.2465,Event,ADDED,eval-conflicts-rho010-r4-112-r5lwc.18d542f2fa0b2e0c,"reason=FailedScheduling count=None msg=0/6 nodes are available: 1 c_wall violated: 1 conflicting context pair(s) with node memory, 5 node(s) had untolerated taint(s). no new claims to deallocate, preemption: 0/6 nodes are available: 1 No preemption victims found for incoming pod, 5 Preemption is not helpful for scheduling."
0.2466,Event,ADDED,eval-conflicts-rho010-r4-112-r5lwc.18d542f35dba2ef8,reason=Scheduled count=None msg=Successfully assigned compute/eval-conflicts-rho010-r4-112-r5lwc to kind-worker2
0.2468,Event,ADDED,eval-conflicts-rho010-r4-112-r5lwc.18d542f37f172207,"reason=Pulled count=1 msg=Container image ""busybox:musl"" already present on machine"
0.2471,Event,ADDED,eval-conflicts-rho010-r4-112-r5lwc.18d542f3844a321c,reason=Created count=1 msg=Created container: task
0.2473,Event,ADDED,eval-conflicts-rho010-r4-112-r5lwc.18d542f387a937c8,reason=Started count=1 msg=Started container task
0.2475,Event,ADDED,eval-conflicts-rho010-r4-112.18d542f2f93bce57,reason=SuccessfulCreate count=1 msg=Created pod: eval-conflicts-rho010-r4-112-r5lwc
0.248,Event,ADDED,eval-conflicts-rho010-r4-112.18d542f8eac3a062,reason=Completed count=1 msg=Job completed
0.2481,Event,ADDED,eval-conflicts-rho010-r4-113-4xqgh.18d542f33525b5f3,reason=Scheduled count=None msg=Successfully assigned compute/eval-conflicts-rho010-r4-113-4xqgh to kind-worker3
0.2483,Event,ADDED,eval-conflicts-rho010-r4-113-4xqgh.18d542f34d4986dc,"reason=Pulled count=1 msg=Container image ""busybox:musl"" already present on machine"
0.2485,Event,ADDED,eval-conflicts-rho010-r4-113-4xqgh.18d542f34e5b469c,reason=Created count=1 msg=Created container: task
0.2488,Event,ADDED,eval-conflicts-rho010-r4-113-4xqgh.18d542f3504c11a3,reason=Started count=1 msg=Started container task
0.249,Event,ADDED,eval-conflicts-rho010-r4-113.18d542f33497f0ae,reason=SuccessfulCreate count=1 msg=Created pod: eval-conflicts-rho010-r4-113-4xqgh
0.2492,Event,ADDED,eval-conflicts-rho010-r4-113.18d542f8c1e36d37,reason=Completed count=1 msg=Job completed
0.2494,Event,ADDED,eval-conflicts-rho010-r4-114-pfjm2.18d542f3708ef16c,reason=Scheduled count=None msg=Successfully assigned compute/eval-conflicts-rho010-r4-114-pfjm2 to kind-worker2
0.2496,Event,ADDED,eval-conflicts-rho010-r4-114-pfjm2.18d542f38ce3a4d4,"reason=Pulled count=1 msg=Container image ""busybox:musl"" already present on machine"
0.2497,Event,ADDED,eval-conflicts-rho010-r4-114-pfjm2.18d542f38df3d6df,reason=Created count=1 msg=Created container: task
0.2499,Event,ADDED,eval-conflicts-rho010-r4-114-pfjm2.18d542f391bc8e9e,reason=Started count=1 msg=Started container task
0.2501,Event,ADDED,eval-conflicts-rho010-r4-114.18d542f36fc23896,reason=SuccessfulCreate count=1 msg=Created pod: eval-conflicts-rho010-r4-114-pfjm2
0.2502,Event,ADDED,eval-conflicts-rho010-r4-114.18d542f8dc6fa244,reason=Completed count=1 msg=Job completed
0.2504,Event,ADDED,eval-conflicts-rho010-r4-115-wtd9r.18d542f3ac485f3e,reason=Scheduled count=None msg=Successfully assigned compute/eval-conflicts-rho010-r4-115-wtd9r to kind-worker2
0.2506,Event,ADDED,eval-conflicts-rho010-r4-115-wtd9r.18d542f3c581a566,"reason=Pulled count=1 msg=Container image ""busybox:musl"" already present on machine"
0.2507,Event,ADDED,eval-conflicts-rho010-r4-115-wtd9r.18d542f3c6960061,reason=Created count=1 msg=Created container: task
0.2509,Event,ADDED,eval-conflicts-rho010-r4-115-wtd9r.18d542f3c8bf51fa,reason=Started count=1 msg=Started container task
0.2511,Event,ADDED,eval-conflicts-rho010-r4-115.18d542f3abaeb032,reason=SuccessfulCreate count=1 msg=Created pod: eval-conflicts-rho010-r4-115-wtd9r
0.2512,Event,ADDED,eval-conflicts-rho010-r4-115.18d542f95507b567,reason=Completed count=1 msg=Job completed
0.2514,Event,ADDED,eval-conflicts-rho010-r4-116-qlkxd.18d542f3e7508225,reason=Scheduled count=None msg=Successfully assigned compute/eval-conflicts-rho010-r4-116-qlkxd to kind-worker2
0.2515,Event,ADDED,eval-conflicts-rho010-r4-116-qlkxd.18d542f4016165d6,"reason=Pulled count=1 msg=Container image ""busybox:musl"" already present on machine"
0.2517,Event,ADDED,eval-conflicts-rho010-r4-116-qlkxd.18d542f4027d7921,reason=Created count=1 msg=Created container: task
0.2519,Event,ADDED,eval-conflicts-rho010-r4-116-qlkxd.18d542f404ae0863,reason=Started count=1 msg=Started container task
0.252,Event,ADDED,eval-conflicts-rho010-r4-116.18d542f3e6c6b741,reason=SuccessfulCreate count=1 msg=Created pod: eval-conflicts-rho010-r4-116-qlkxd
0.2522,Event,ADDED,eval-conflicts-rho010-r4-116.18d542f9905269ac,reason=Completed count=1 msg=Job completed
0.2524,Event,ADDED,eval-conflicts-rho010-r4-117-2vq9m.18d542f42362ebde,reason=Scheduled count=None msg=Successfully assigned compute/eval-conflicts-rho010-r4-117-2vq9m to kind-worker2
0.2526,Event,ADDED,eval-conflicts-rho010-r4-117-2vq9m.18d542f43cbd1518,"reason=Pulled count=1 msg=Container image ""busybox:musl"" already present on machine"
0.2527,Event,ADDED,eval-conflicts-rho010-r4-117-2vq9m.18d542f43dd92fb0,reason=Created count=1 msg=Created container: task
0.2529,Event,ADDED,eval-conflicts-rho010-r4-117-2vq9m.18d542f441b0cc33,reason=Started count=1 msg=Started container task
0.2531,Event,ADDED,eval-conflicts-rho010-r4-117.18d542f422dd3d5d,reason=SuccessfulCreate count=1 msg=Created pod: eval-conflicts-rho010-r4-117-2vq9m
0.2532,Event,ADDED,eval-conflicts-rho010-r4-117.18d542f9cc446145,reason=Completed count=1 msg=Job completed
0.2535,Event,ADDED,eval-conflicts-rho010-r4-118-rp268.18d542f45e304330,"reason=FailedScheduling count=None msg=0/6 nodes are available: 1 c_wall violated: 1 conflicting context pair(s) with node memory, 5 node(s) had untolerated taint(s). no new claims to deallocate, preemption: 0/6 nodes are available: 1 No preemption victims found for incoming pod, 5 Preemption is not helpful for scheduling."
0.2537,Event,ADDED,eval-conflicts-rho010-r4-118-rp268.18d542f45e9ff52a,"reason=FailedScheduling count=None msg=0/6 nodes are available: 1 c_wall violated: 1 conflicting context pair(s) with node memory, 5 node(s) had untolerated taint(s). no new claims to deallocate, preemption: 0/6 nodes are available: 1 No preemption victims found for incoming pod, 5 Preemption is not helpful for scheduling."
0.2538,Event,ADDED,eval-conflicts-rho010-r4-118-rp268.18d542f497908c7a,reason=Scheduled count=None msg=Successfully assigned compute/eval-conflicts-rho010-r4-118-rp268 to kind-worker4
0.254,Event,ADDED,eval-conflicts-rho010-r4-118-rp268.18d542f4b180f402,"reason=Pulled count=1 msg=Container image ""busybox:musl"" already present on machine"
0.2542,Event,ADDED,eval-conflicts-rho010-r4-118-rp268.18d542f4b2958a87,reason=Created count=1 msg=Created container: task
0.2545,Event,ADDED,eval-conflicts-rho010-r4-118-rp268.18d542f4b4879c5b,reason=Started count=1 msg=Started container task
0.2547,Event,ADDED,eval-conflicts-rho010-r4-118.18d542f45deca883,reason=SuccessfulCreate count=1 msg=Created pod: eval-conflicts-rho010-r4-118-rp268
0.2548,Event,ADDED,eval-conflicts-rho010-r4-118.18d542fa1f9b6efb,reason=Completed count=1 msg=Job completed
0.255,Event,ADDED,eval-conflicts-rho010-r4-119-rvz6f.18d542f49aceac34,reason=Scheduled count=None msg=Successfully assigned compute/eval-conflicts-rho010-r4-119-rvz6f to kind-worker4
0.2552,Event,ADDED,eval-conflicts-rho010-r4-119-rvz6f.18d542f4b3d55dcb,"reason=Pulled count=1 msg=Container image ""busybox:musl"" already present on machine"
0.2554,Event,ADDED,eval-conflicts-rho010-r4-119-rvz6f.18d542f4b5149b03,reason=Created count=1 msg=Created container: task
0.2556,Event,ADDED,eval-conflicts-rho010-r4-119-rvz6f.18d542f4b95297cc,reason=Started count=1 msg=Started container task
0.2558,Event,ADDED,eval-conflicts-rho010-r4-119.18d542f4999a085f,reason=SuccessfulCreate count=1 msg=Created pod: eval-conflicts-rho010-r4-119-rvz6f
0.2559,Event,ADDED,eval-conflicts-rho010-r4-119.18d542fa1fc66abe,reason=Completed count=1 msg=Job completed
0.2561,Event,ADDED,eval-conflicts-rho010-r4-120-hbvfq.18d542f4d64e2811,reason=Scheduled count=None msg=Successfully assigned compute/eval-conflicts-rho010-r4-120-hbvfq to kind-worker5
0.2563,Event,ADDED,eval-conflicts-rho010-r4-120-hbvfq.18d542f4ef76834e,"reason=Pulled count=1 msg=Container image ""busybox:musl"" already present on machine"
0.2564,Event,ADDED,eval-conflicts-rho010-r4-120-hbvfq.18d542f4f0902876,reason=Created count=1 msg=Created container: task
0.2566,Event,ADDED,eval-conflicts-rho010-r4-120-hbvfq.18d542f4f2e2b992,reason=Started count=1 msg=Started container task
0.2568,Event,ADDED,eval-conflicts-rho010-r4-120.18d542f4d56c89c6,reason=SuccessfulCreate count=1 msg=Created pod: eval-conflicts-rho010-r4-120-hbvfq
0.2569,Event,ADDED,eval-conflicts-rho010-r4-120.18d542fa6667069a,reason=Completed count=1 msg=Job completed
0.2571,Event,ADDED,eval-conflicts-rho010-r4-121-lxjf7.18d542f5126bbfde,reason=Scheduled count=None msg=Successfully assigned compute/eval-conflicts-rho010-r4-121-lxjf7 to kind-worker4
0.2573,Event,ADDED,eval-conflicts-rho010-r4-121-lxjf7.18d542f52c285925,"reason=Pulled count=1 msg=Container image ""busybox:musl"" already present on machine"
0.2574,Event,ADDED,eval-conflicts-rho010-r4-121-lxjf7.18d542f52d6240d4,reason=Created count=1 msg=Created container: task
0.2576,Event,ADDED,eval-conflicts-rho010-r4-121-lxjf7.18d542f5378ed491,reason=Started count=1 msg=Started container task
0.2578,Event,ADDED,eval-conflicts-rho010-r4-121.18d542f511225d38,reason=SuccessfulCreate count=1 msg=Created pod: eval-conflicts-rho010-r4-121-lxjf7
0.2579,Event,ADDED,eval-conflicts-rho010-r4-121.18d542facfac3c41,reason=Completed count=1 msg=Job completed
0.2581,Event,ADDED,eval-conflicts-rho010-r4-122-txbbl.18d542f54f769262,reason=Scheduled count=None msg=Successfully assigned compute/eval-conflicts-rho010-r4-122-txbbl to kind-worker5
0.2583,Event,ADDED,eval-conflicts-rho010-r4-122-txbbl.18d542f568f93703,"reason=Pulled count=1 msg=Container image ""busybox:musl"" already present on machine"
0.2584,Event,ADDED,eval-conflicts-rho010-r4-122-txbbl.18d542f56a3d2634,reason=Created count=1 msg=Created container: task
0.2586,Event,ADDED,eval-conflicts-rho010-r4-122-txbbl.18d542f56e77e931,reason=Started count=1 msg=Started container task
0.2591,Event,ADDED,eval-conflicts-rho010-r4-122.18d542f54e5b6cac,reason=SuccessfulCreate count=1 msg=Created pod: eval-conflicts-rho010-r4-122-txbbl
0.2594,Event,ADDED,eval-conflicts-rho010-r4-122.18d542fae085bbc5,reason=Completed count=1 msg=Job completed
0.2596,Event,ADDED,eval-conflicts-rho010-r4-123-pbk2n.18d542f5898a3fe8,reason=Scheduled count=None msg=Successfully assigned compute/eval-conflicts-rho010-r4-123-pbk2n to kind-worker4
0.2599,Event,ADDED,eval-conflicts-rho010-r4-123-pbk2n.18d542f5a4667f82,"reason=Pulled count=1 msg=Container image ""busybox:musl"" already present on machine"
0.2602,Event,ADDED,eval-conflicts-rho010-r4-123-pbk2n.18d542f5a5b0fdcb,reason=Created count=1 msg=Created container: task
0.2604,Event,ADDED,eval-conflicts-rho010-r4-123-pbk2n.18d542f5a969f8c5,reason=Started count=1 msg=Started container task
0.2606,Event,ADDED,eval-conflicts-rho010-r4-123.18d542f58862e0f9,reason=SuccessfulCreate count=1 msg=Created pod: eval-conflicts-rho010-r4-123-pbk2n
0.2608,Event,ADDED,eval-conflicts-rho010-r4-123.18d542fb0d454cd4,reason=Completed count=1 msg=Job completed
0.2613,Event,ADDED,eval-conflicts-rho010-r4-124-7krmp.18d542f5c4eabda1,reason=Scheduled count=None msg=Successfully assigned compute/eval-conflicts-rho010-r4-124-7krmp to kind-worker5
0.2617,Event,ADDED,eval-conflicts-rho010-r4-124-7krmp.18d542f5defc018e,"reason=Pulled count=1 msg=Container image ""busybox:musl"" already present on machine"
0.2619,Event,ADDED,eval-conflicts-rho010-r4-124-7krmp.18d542f5e0c0dca2,reason=Created count=1 msg=Created container: task
0.2622,Event,ADDED,eval-conflicts-rho010-r4-124-7krmp.18d542f5e5cdbe0e,reason=Started count=1 msg=Started container task
0.2624,Event,ADDED,eval-conflicts-rho010-r4-124.18d542f5c3b3aef2,reason=SuccessfulCreate count=1 msg=Created pod: eval-conflicts-rho010-r4-124-7krmp
0.2626,Event,ADDED,eval-conflicts-rho010-r4-124.18d542fb5ba308a5,reason=Completed count=1 msg=Job completed
0.2628,Event,ADDED,eval-conflicts-rho010-r4-125-7lwxf.18d542f601a02890,reason=Scheduled count=None msg=Successfully assigned compute/eval-conflicts-rho010-r4-125-7lwxf to kind-worker4
0.263,Event,ADDED,eval-conflicts-rho010-r4-125-7lwxf.18d542f61b46066f,"reason=Pulled count=1 msg=Container image ""busybox:musl"" already present on machine"
0.2632,Event,ADDED,eval-conflicts-rho010-r4-125-7lwxf.18d542f61c5e0169,reason=Created count=1 msg=Created container: task
0.2633,Event,ADDED,eval-conflicts-rho010-r4-125-7lwxf.18d542f61e3a6948,reason=Started count=1 msg=Started container task
0.2636,Event,ADDED,eval-conflicts-rho010-r4-125.18d542f6007c69f5,reason=SuccessfulCreate count=1 msg=Created pod: eval-conflicts-rho010-r4-125-7lwxf
0.2638,Event,ADDED,eval-conflicts-rho010-r4-125.18d542fbce3bcb9d,reason=Completed count=1 msg=Job completed
0.264,Event,ADDED,eval-conflicts-rho010-r4-126-jpcb6.18d542f63d9e667a,reason=Scheduled count=None msg=Successfully assigned compute/eval-conflicts-rho010-r4-126-jpcb6 to kind-worker5
0.2641,Event,ADDED,eval-conflicts-rho010-r4-126-jpcb6.18d542f65aa36733,"reason=Pulled count=1 msg=Container image ""busybox:musl"" already present on machine"
0.2644,Event,ADDED,eval-conflicts-rho010-r4-126-jpcb6.18d542f65be3a6fe,reason=Created count=1 msg=Created container: task
0.2646,Event,ADDED,eval-conflicts-rho010-r4-126-jpcb6.18d542f6608b8836,reason=Started count=1 msg=Started container task
0.2648,Event,ADDED,eval-conflicts-rho010-r4-126.18d542f63c688826,reason=SuccessfulCreate count=1 msg=Created pod: eval-conflicts-rho010-r4-126-jpcb6
0.2651,Event,ADDED,eval-conflicts-rho010-r4-126.18d542fbd34b4bce,reason=Completed count=1 msg=Job completed
0.2653,Event,ADDED,eval-conflicts-rho010-r4-127-lcr9g.18d542f678034cbe,reason=Scheduled count=None msg=Successfully assigned compute/eval-conflicts-rho010-r4-127-lcr9g to kind-worker
0.2655,Event,ADDED,eval-conflicts-rho010-r4-127-lcr9g.18d542f69ccc60fd,"reason=Pulled count=1 msg=Container image ""busybox:musl"" already present on machine"
0.2657,Event,ADDED,eval-conflicts-rho010-r4-127-lcr9g.18d542f69e2c9a3d,reason=Created count=1 msg=Created container: task
0.266,Event,ADDED,eval-conflicts-rho010-r4-127-lcr9g.18d542f6a7bf7589,reason=Started count=1 msg=Started container task
0.2661,Event,ADDED,eval-conflicts-rho010-r4-127.18d542f676e91868,reason=SuccessfulCreate count=1 msg=Created pod: eval-conflicts-rho010-r4-127-lcr9g
0.2663,Event,ADDED,eval-conflicts-rho010-r4-127.18d542fc283266db,reason=Completed count=1 msg=Job completed
0.2665,Event,ADDED,eval-conflicts-rho010-r4-128-r76fj.18d542f6b6eda4c0,reason=Scheduled count=None msg=Successfully assigned compute/eval-conflicts-rho010-r4-128-r76fj to kind-worker
0.2668,Event,ADDED,eval-conflicts-rho010-r4-128-r76fj.18d542f6e4635d45,"reason=Pulled count=1 msg=Container image ""busybox:musl"" already present on machine"
0.267,Event,ADDED,eval-conflicts-rho010-r4-128-r76fj.18d542f6e57cafcd,reason=Created count=1 msg=Created container: task
0.2671,Event,ADDED,eval-conflicts-rho010-r4-128-r76fj.18d542f6eae69523,reason=Started count=1 msg=Started container task
0.2673,Event,ADDED,eval-conflicts-rho010-r4-128.18d542f6b5725d25,reason=SuccessfulCreate count=1 msg=Created pod: eval-conflicts-rho010-r4-128-r76fj
0.2677,Event,ADDED,eval-conflicts-rho010-r4-128.18d542fc647f6545,reason=Completed count=1 msg=Job completed
0.2678,Event,ADDED,eval-conflicts-rho010-r4-129-tvm7p.18d542f6ef20ecb5,reason=Scheduled count=None msg=Successfully assigned compute/eval-conflicts-rho010-r4-129-tvm7p to kind-worker4
0.268,Event,ADDED,eval-conflicts-rho010-r4-129-tvm7p.18d542f70921e7ed,"reason=Pulled count=1 msg=Container image ""busybox:musl"" already present on machine"
0.2683,Event,ADDED,eval-conflicts-rho010-r4-129-tvm7p.18d542f70a3c8ff3,reason=Created count=1 msg=Created container: task
0.2686,Event,ADDED,eval-conflicts-rho010-r4-129-tvm7p.18d542f7167ca785,reason=Started count=1 msg=Started container task
0.2688,Event,ADDED,eval-conflicts-rho010-r4-129.18d542f6edbf5219,reason=SuccessfulCreate count=1 msg=Created pod: eval-conflicts-rho010-r4-129-tvm7p
0.269,Event,ADDED,eval-conflicts-rho010-r4-129.18d542fcb1b73cc4,reason=Completed count=1 msg=Job completed
0.2695,Event,ADDED,eval-conflicts-rho010-r4-130-5ftwl.18d542f72cb480b2,reason=Scheduled count=None msg=Successfully assigned compute/eval-conflicts-rho010-r4-130-5ftwl to kind-worker
0.2697,Event,ADDED,eval-conflicts-rho010-r4-130-5ftwl.18d542f7494d8947,"reason=Pulled count=1 msg=Container image ""busybox:musl"" already present on machine"
0.2699,Event,ADDED,eval-conflicts-rho010-r4-130-5ftwl.18d542f74a7d73eb,reason=Created count=1 msg=Created container: task
0.2703,Event,ADDED,eval-conflicts-rho010-r4-130-5ftwl.18d542f75105da4f,reason=Started count=1 msg=Started container task
0.2705,Event,ADDED,eval-conflicts-rho010-r4-130.18d542f72b4aef89,reason=SuccessfulCreate count=1 msg=Created pod: eval-conflicts-rho010-r4-130-5ftwl
0.2707,Event,ADDED,eval-conflicts-rho010-r4-130.18d542fcd05f0149,reason=Completed count=1 msg=Job completed
0.2709,Event,ADDED,eval-conflicts-rho010-r4-131-sm4g8.18d542f769def903,reason=Scheduled count=None msg=Successfully assigned compute/eval-conflicts-rho010-r4-131-sm4g8 to kind-worker5
0.2712,Event,ADDED,eval-conflicts-rho010-r4-131-sm4g8.18d542f7831d5807,"reason=Pulled count=1 msg=Container image ""busybox:musl"" already present on machine"
0.2714,Event,ADDED,eval-conflicts-rho010-r4-131-sm4g8.18d542f784c7a6aa,reason=Created count=1 msg=Created container: task
0.2715,Event,ADDED,eval-conflicts-rho010-r4-131-sm4g8.18d542f791cba255,reason=Started count=1 msg=Started container task
0.2717,Event,ADDED,eval-conflicts-rho010-r4-131.18d542f7689e31b4,reason=SuccessfulCreate count=1 msg=Created pod: eval-conflicts-rho010-r4-131-sm4g8
0.272,Event,ADDED,eval-conflicts-rho010-r4-131.18d542fcf77a01c0,reason=Completed count=1 msg=Job completed
0.2722,Event,ADDED,eval-conflicts-rho010-r4-132-dhmw5.18d542f7a2506f61,reason=Scheduled count=None msg=Successfully assigned compute/eval-conflicts-rho010-r4-132-dhmw5 to kind-worker
0.2724,Event,ADDED,eval-conflicts-rho010-r4-132-dhmw5.18d542f7c71397b3,"reason=Pulled count=1 msg=Container image ""busybox:musl"" already present on machine"
0.2727,Event,ADDED,eval-conflicts-rho010-r4-132-dhmw5.18d542f7c8558040,reason=Created count=1 msg=Created container: task
0.2729,Event,ADDED,eval-conflicts-rho010-r4-132-dhmw5.18d542f7cdc44740,reason=Started count=1 msg=Started container task
0.2731,Event,ADDED,eval-conflicts-rho010-r4-132.18d542f7a0d88db2,reason=SuccessfulCreate count=1 msg=Created pod: eval-conflicts-rho010-r4-132-dhmw5
0.2732,Event,ADDED,eval-conflicts-rho010-r4-132.18d542fd5097f270,reason=Completed count=1 msg=Job completed
0.2735,Event,ADDED,eval-conflicts-rho010-r4-133-q9j8d.18d542f7e26031f9,reason=Scheduled count=None msg=Successfully assigned compute/eval-conflicts-rho010-r4-133-q9j8d to kind-worker5
0.2737,Event,ADDED,eval-conflicts-rho010-r4-133-q9j8d.18d542f8083127b8,"reason=Pulled count=1 msg=Container image ""busybox:musl"" already present on machine"
0.274,Event,ADDED,eval-conflicts-rho010-r4-133-q9j8d.18d542f809e32580,reason=Created count=1 msg=Created container: task
0.2742,Event,ADDED,eval-conflicts-rho010-r4-133-q9j8d.18d542f80ffd1944,reason=Started count=1 msg=Started container task
0.2746,Event,ADDED,eval-conflicts-rho010-r4-133.18d542f7e109635f,reason=SuccessfulCreate count=1 msg=Created pod: eval-conflicts-rho010-r4-133-q9j8d
0.2748,Event,ADDED,eval-conflicts-rho010-r4-133.18d542fd77fd290b,reason=Completed count=1 msg=Job completed
0.275,Event,ADDED,eval-conflicts-rho010-r4-134-k4rtl.18d542f81e3fa69c,reason=Scheduled count=None msg=Successfully assigned compute/eval-conflicts-rho010-r4-134-k4rtl to kind-worker5
0.2753,Event,ADDED,eval-conflicts-rho010-r4-134-k4rtl.18d542f83c63897f,"reason=Pulled count=1 msg=Container image ""busybox:musl"" already present on machine"
0.2755,Event,ADDED,eval-conflicts-rho010-r4-134-k4rtl.18d542f83d781bcb,reason=Created count=1 msg=Created container: task
0.2757,Event,ADDED,eval-conflicts-rho010-r4-134-k4rtl.18d542f841964a2f,reason=Started count=1 msg=Started container task
0.2759,Event,ADDED,eval-conflicts-rho010-r4-134.18d542f81d3dd49c,reason=SuccessfulCreate count=1 msg=Created pod: eval-conflicts-rho010-r4-134-k4rtl
0.2762,Event,ADDED,eval-conflicts-rho010-r4-134.18d542fd77c66a76,reason=Completed count=1 msg=Job completed
0.2764,Event,ADDED,eval-conflicts-rho010-r4-135-swqqg.18d542f854edd1df,reason=Scheduled count=None msg=Successfully assigned compute/eval-conflicts-rho010-r4-135-swqqg to kind-worker5
0.2766,Event,ADDED,eval-conflicts-rho010-r4-135-swqqg.18d542f8701999ef,"reason=Pulled count=1 msg=Container image ""busybox:musl"" already present on machine"
0.277,Event,ADDED,eval-conflicts-rho010-r4-135-swqqg.18d542f8714574c7,reason=Created count=1 msg=Created container: task
0.2772,Event,ADDED,eval-conflicts-rho010-r4-135-swqqg.18d542f87cbc5029,reason=Started count=1 msg=Started container task
0.2773,Event,ADDED,eval-conflicts-rho010-r4-135.18d542f853f6c379,reason=SuccessfulCreate count=1 msg=Created pod: eval-conflicts-rho010-r4-135-swqqg
0.2775,Event,ADDED,eval-conflicts-rho010-r4-135.18d542fdb3c4353a,reason=Completed count=1 msg=Job completed
0.2778,Event,ADDED,eval-conflicts-rho010-r4-136-bs8kt.18d542f89093e731,reason=Scheduled count=None msg=Successfully assigned compute/eval-conflicts-rho010-r4-136-bs8kt to kind-worker4
0.278,Event,ADDED,eval-conflicts-rho010-r4-136-bs8kt.18d542f8aca72a45,"reason=Pulled count=1 msg=Container image ""busybox:musl"" already present on machine"
0.2782,Event,ADDED,eval-conflicts-rho010-r4-136-bs8kt.18d542f8ade51e56,reason=Created count=1 msg=Created container: task
0.2784,Event,ADDED,eval-conflicts-rho010-r4-136-bs8kt.18d542f8bafa8659,reason=Started count=1 msg=Started container task
0.2787,Event,ADDED,eval-conflicts-rho010-r4-136.18d542f88f6ea463,reason=SuccessfulCreate count=1 msg=Created pod: eval-conflicts-rho010-r4-136-bs8kt
0.2789,Event,ADDED,eval-conflicts-rho010-r4-136.18d542fe59e7b8d1,reason=Completed count=1 msg=Job completed
0.279,Event,ADDED,eval-conflicts-rho010-r4-137-b7nwn.18d542f8cd70bc02,reason=Scheduled count=None msg=Successfully assigned compute/eval-conflicts-rho010-r4-137-b7nwn to kind-worker
0.2794,Event,ADDED,eval-conflicts-rho010-r4-137-b7nwn.18d542f8e9b7532b,"reason=Pulled count=1 msg=Container image ""busybox:musl"" already present on machine"
0.2795,Event,ADDED,eval-conflicts-rho010-r4-137-b7nwn.18d542f8eb724e1b,reason=Created count=1 msg=Created container: task
0.2797,Event,ADDED,eval-conflicts-rho010-r4-137-b7nwn.18d542f8f361880c,reason=Started count=1 msg=Started container task
0.2799,Event,ADDED,eval-conflicts-rho010-r4-137.18d542f8cc664a4c,reason=SuccessfulCreate count=1 msg=Created pod: eval-conflicts-rho010-r4-137-b7nwn
0.2802,Event,ADDED,eval-conflicts-rho010-r4-137.18d542fe7371d078,reason=Completed count=1 msg=Job completed
0.2805,Event,ADDED,eval-conflicts-rho010-r4-138-xtw7d.18d542f9071cc5c3,reason=Scheduled count=None msg=Successfully assigned compute/eval-conflicts-rho010-r4-138-xtw7d to kind-worker
0.2808,Event,ADDED,eval-conflicts-rho010-r4-138-xtw7d.18d542f92423a8d7,"reason=Pulled count=1 msg=Container image ""busybox:musl"" already present on machine"
0.281,Event,ADDED,eval-conflicts-rho010-r4-138-xtw7d.18d542f925d16bae,reason=Created count=1 msg=Created container: task
0.2813,Event,ADDED,eval-conflicts-rho010-r4-138-xtw7d.18d542f929fb8478,reason=Started count=1 msg=Started container task
0.2814,Event,ADDED,eval-conflicts-rho010-r4-138.18d542f906344612,reason=SuccessfulCreate count=1 msg=Created pod: eval-conflicts-rho010-r4-138-xtw7d
0.2816,Event,ADDED,eval-conflicts-rho010-r4-138.18d542feb27694b3,reason=Completed count=1 msg=Job completed
0.2819,Event,ADDED,eval-conflicts-rho010-r4-139-qtk7k.18d542f942cf2edd,reason=Scheduled count=None msg=Successfully assigned compute/eval-conflicts-rho010-r4-139-qtk7k to kind-worker
0.2821,Event,ADDED,eval-conflicts-rho010-r4-139-qtk7k.18d542f95c1449a7,"reason=Pulled count=1 msg=Container image ""busybox:musl"" already present on machine"
0.2822,Event,ADDED,eval-conflicts-rho010-r4-139-qtk7k.18d542f95d3b62a6,reason=Created count=1 msg=Created container: task
0.2826,Event,ADDED,eval-conflicts-rho010-r4-139-qtk7k.18d542f96ae1aa95,reason=Started count=1 msg=Started container task
0.2829,Event,ADDED,eval-conflicts-rho010-r4-139.18d542f941cc5700,reason=SuccessfulCreate count=1 msg=Created pod: eval-conflicts-rho010-r4-139-qtk7k
0.2831,Event,ADDED,eval-conflicts-rho010-r4-139.18d542feef5cc15d,reason=Completed count=1 msg=Job completed
0.2832,Event,ADDED,eval-conflicts-rho010-r4-140-h8klq.18d542f97e65b488,"reason=FailedScheduling count=None msg=0/6 nodes are available: 1 c_wall violated: 1 conflicting context pair(s) with node memory, 5 node(s) had untolerated taint(s). no new claims to deallocate, preemption: 0/6 nodes are available: 1 No preemption victims found for incoming pod, 5 Preemption is not helpful for scheduling."
0.2835,Event,ADDED,eval-conflicts-rho010-r4-140-h8klq.18d542f97ef242c3,"reason=FailedScheduling count=None msg=0/6 nodes are available: 1 c_wall violated: 1 conflicting context pair(s) with node memory, 5 node(s) had untolerated taint(s). no new claims to deallocate, preemption: 0/6 nodes are available: 1 No preemption victims found for incoming pod, 5 Preemption is not helpful for scheduling."
0.2837,Event,ADDED,eval-conflicts-rho010-r4-140-h8klq.18d542fcb99c0f22,reason=Scheduled count=None msg=Successfully assigned compute/eval-conflicts-rho010-r4-140-h8klq to kind-worker3
0.2839,Event,ADDED,eval-conflicts-rho010-r4-140-h8klq.18d542fcdda475e8,"reason=Pulled count=1 msg=Container image ""busybox:musl"" already present on machine"
0.2841,Event,ADDED,eval-conflicts-rho010-r4-140-h8klq.18d542fcdf350144,reason=Created count=1 msg=Created container: task
0.2844,Event,ADDED,eval-conflicts-rho010-r4-140-h8klq.18d542fce2070bda,reason=Started count=1 msg=Started container task
0.2846,Event,ADDED,eval-conflicts-rho010-r4-140.18d542f97e258d10,reason=SuccessfulCreate count=1 msg=Created pod: eval-conflicts-rho010-r4-140-h8klq
0.2847,Event,ADDED,eval-conflicts-rho010-r4-140.18d543029e84acbe,reason=Completed count=1 msg=Job completed
0.285,Event,ADDED,eval-conflicts-rho010-r4-141-rnr8t.18d542f9c1b9b375,"reason=FailedScheduling count=None msg=0/6 nodes are available: 1 c_wall violated: 1 conflicting context pair(s) with node memory, 5 node(s) had untolerated taint(s). no new claims to deallocate, preemption: 0/6 nodes are available: 1 No preemption victims found for incoming pod, 5 Preemption is not helpful for scheduling."
0.2852,Event,ADDED,eval-conflicts-rho010-r4-141-rnr8t.18d542f9c24d9fdc,"reason=FailedScheduling count=None msg=0/6 nodes are available: 1 c_wall violated: 1 conflicting context pair(s) with node memory, 5 node(s) had untolerated taint(s). no new claims to deallocate, preemption: 0/6 nodes are available: 1 No preemption victims found for incoming pod, 5 Preemption is not helpful for scheduling."
0.2854,Event,ADDED,eval-conflicts-rho010-r4-141-rnr8t.18d542fcba2654e6,reason=Scheduled count=None msg=Successfully assigned compute/eval-conflicts-rho010-r4-141-rnr8t to kind-worker3
0.2857,Event,ADDED,eval-conflicts-rho010-r4-141-rnr8t.18d542fce02094f2,"reason=Pulled count=1 msg=Container image ""busybox:musl"" already present on machine"
0.2859,Event,ADDED,eval-conflicts-rho010-r4-141-rnr8t.18d542fce543834a,reason=Created count=1 msg=Created container: task
0.2861,Event,ADDED,eval-conflicts-rho010-r4-141-rnr8t.18d542fce81bd08c,reason=Started count=1 msg=Started container task
0.2862,Event,ADDED,eval-conflicts-rho010-r4-141.18d542f9c180695d,reason=SuccessfulCreate count=1 msg=Created pod: eval-conflicts-rho010-r4-141-rnr8t
0.2865,Event,ADDED,eval-conflicts-rho010-r4-141.18d543025acb9b73,reason=Completed count=1 msg=Job completed
0.2866,Event,ADDED,eval-conflicts-rho010-r4-142-mjddm.18d542f9f8366eed,reason=Scheduled count=None msg=Successfully assigned compute/eval-conflicts-rho010-r4-142-mjddm to kind-worker
0.2868,Event,ADDED,eval-conflicts-rho010-r4-142-mjddm.18d542fa174fb91d,"reason=Pulled count=1 msg=Container image ""busybox:musl"" already present on machine"
0.287,Event,ADDED,eval-conflicts-rho010-r4-142-mjddm.18d542fa189c367e,reason=Created count=1 msg=Created container: task
0.2871,Event,ADDED,eval-conflicts-rho010-r4-142-mjddm.18d542fa1cefeef3,reason=Started count=1 msg=Started container task
0.2873,Event,ADDED,eval-conflicts-rho010-r4-142.18d542f9f7b6fe88,reason=SuccessfulCreate count=1 msg=Created pod: eval-conflicts-rho010-r4-142-mjddm
0.2875,Event,ADDED,eval-conflicts-rho010-r4-142.18d542ffa6b4da1d,reason=Completed count=1 msg=Job completed
0.2877,Event,ADDED,eval-conflicts-rho010-r4-143-ckj9s.18d542fa33d72bd5,reason=Scheduled count=None msg=Successfully assigned compute/eval-conflicts-rho010-r4-143-ckj9s to kind-worker
0.2878,Event,ADDED,eval-conflicts-rho010-r4-143-ckj9s.18d542fa4d5cd875,"reason=Pulled count=1 msg=Container image ""busybox:musl"" already present on machine"
0.288,Event,ADDED,eval-conflicts-rho010-r4-143-ckj9s.18d542fa4e76cd5b,reason=Created count=1 msg=Created container: task
0.2882,Event,ADDED,eval-conflicts-rho010-r4-143-ckj9s.18d542fa529b48c6,reason=Started count=1 msg=Started container task
0.2883,Event,ADDED,eval-conflicts-rho010-r4-143.18d542fa334cac2a,reason=SuccessfulCreate count=1 msg=Created pod: eval-conflicts-rho010-r4-143-ckj9s
0.2885,Event,ADDED,eval-conflicts-rho010-r4-143.18d542ffdb0cc9c0,reason=Completed count=1 msg=Job completed
0.2886,Event,ADDED,eval-conflicts-rho010-r4-144-42nk9.18d542fa70cc2a05,reason=Scheduled count=None msg=Successfully assigned compute/eval-conflicts-rho010-r4-144-42nk9 to kind-worker
0.2888,Event,ADDED,eval-conflicts-rho010-r4-144-42nk9.18d542fa906550f7,"reason=Pulled count=1 msg=Container image ""busybox:musl"" already present on machine"
0.289,Event,ADDED,eval-conflicts-rho010-r4-144-42nk9.18d542fa919e0c14,reason=Created count=1 msg=Created container: task
0.2892,Event,ADDED,eval-conflicts-rho010-r4-144-42nk9.18d542fa94d0bd4d,reason=Started count=1 msg=Started container task
0.2894,Event,ADDED,eval-conflicts-rho010-r4-144.18d542fa70486ee8,reason=SuccessfulCreate count=1 msg=Created pod: eval-conflicts-rho010-r4-144-42nk9
0.2897,Event,ADDED,eval-conflicts-rho010-r4-144.18d543001af61155,reason=Completed count=1 msg=Job completed
0.2898,Event,ADDED,eval-conflicts-rho010-r4-145-ptt8m.18d542faaec37d15,reason=Scheduled count=None msg=Successfully assigned compute/eval-conflicts-rho010-r4-145-ptt8m to kind-worker
0.29,Event,ADDED,eval-conflicts-rho010-r4-145-ptt8m.18d542facb3f1e6d,"reason=Pulled count=1 msg=Container image ""busybox:musl"" already present on machine"
0.2902,Event,ADDED,eval-conflicts-rho010-r4-145-ptt8m.18d542facc75122d,reason=Created count=1 msg=Created container: task
0.2904,Event,ADDED,eval-conflicts-rho010-r4-145-ptt8m.18d542fad108855b,reason=Started count=1 msg=Started container task
0.2905,Event,ADDED,eval-conflicts-rho010-r4-145.18d542faae3c44a0,reason=SuccessfulCreate count=1 msg=Created pod: eval-conflicts-rho010-r4-145-ptt8m
0.2907,Event,ADDED,eval-conflicts-rho010-r4-145.18d5430056c0de80,reason=Completed count=1 msg=Job completed
0.2908,Event,ADDED,eval-conflicts-rho010-r4-146-4wg84.18d542fae3c6e9fd,reason=Scheduled count=None msg=Successfully assigned compute/eval-conflicts-rho010-r4-146-4wg84 to kind-worker
0.291,Event,ADDED,eval-conflicts-rho010-r4-146-4wg84.18d542fb0119e550,"reason=Pulled count=1 msg=Container image ""busybox:musl"" already present on machine"
0.2912,Event,ADDED,eval-conflicts-rho010-r4-146-4wg84.18d542fb022401f6,reason=Created count=1 msg=Created container: task
0.2914,Event,ADDED,eval-conflicts-rho010-r4-146-4wg84.18d542fb0cc0f5f9,reason=Started count=1 msg=Started container task
0.2918,Event,ADDED,eval-conflicts-rho010-r4-146.18d542fae34785b3,reason=SuccessfulCreate count=1 msg=Created pod: eval-conflicts-rho010-r4-146-4wg84
0.292,Event,ADDED,eval-conflicts-rho010-r4-146.18d543009292e6e4,reason=Completed count=1 msg=Job completed
0.2922,Event,ADDED,eval-conflicts-rho010-r4-147-5gnjn.18d542fb1e4cf273,"reason=FailedScheduling count=None msg=0/6 nodes are available: 6 node(s) had untolerated taint(s). no new claims to deallocate, preemption: 0/6 nodes are available: 6 Preemption is not helpful for scheduling."
0.2924,Event,ADDED,eval-conflicts-rho010-r4-147-5gnjn.18d542fcba5bb94e,reason=Scheduled count=None msg=Successfully assigned compute/eval-conflicts-rho010-r4-147-5gnjn to kind-worker3
0.2927,Event,ADDED,eval-conflicts-rho010-r4-147-5gnjn.18d542fce09de80e,"reason=Pulled count=1 msg=Container image ""busybox:musl"" already present on machine"
0.2929,Event,ADDED,eval-conflicts-rho010-r4-147-5gnjn.18d542fce6d6887d,reason=Created count=1 msg=Created container: task
0.2931,Event,ADDED,eval-conflicts-rho010-r4-147-5gnjn.18d542fcea375d27,reason=Started count=1 msg=Started container task
0.2934,Event,ADDED,eval-conflicts-rho010-r4-147.18d542fb1e3daac2,reason=SuccessfulCreate count=1 msg=Created pod: eval-conflicts-rho010-r4-147-5gnjn
0.2936,Event,ADDED,eval-conflicts-rho010-r4-147.18d543025b05d510,reason=Completed count=1 msg=Job completed
0.2938,Event,ADDED,eval-conflicts-rho010-r4-148-lnkws.18d542fb5d6a017a,"reason=FailedScheduling count=None msg=0/6 nodes are available: 6 node(s) had untolerated taint(s). no new claims to deallocate, preemption: 0/6 nodes are available: 6 Preemption is not helpful for scheduling."
0.2939,Event,ADDED,eval-conflicts-rho010-r4-148-lnkws.18d542fcbaf1da81,reason=Scheduled count=None msg=Successfully assigned compute/eval-conflicts-rho010-r4-148-lnkws to kind-worker3
0.2942,Event,ADDED,eval-conflicts-rho010-r4-148-lnkws.18d542fcdfd9f5c5,"reason=Pulled count=1 msg=Container image ""busybox:musl"" already present on machine"
0.2944,Event,ADDED,eval-conflicts-rho010-r4-148-lnkws.18d542fce4e5cc64,reason=Created count=1 msg=Created container: task
0.2946,Event,ADDED,eval-conflicts-rho010-r4-148-lnkws.18d542fce83d9512,reason=Started count=1 msg=Started container task
0.2949,Event,ADDED,eval-conflicts-rho010-r4-148.18d542fb5d5aa5cd,reason=SuccessfulCreate count=1 msg=Created pod: eval-conflicts-rho010-r4-148-lnkws
0.2951,Event,ADDED,eval-conflicts-rho010-r4-148.18d5430220fce815,reason=Completed count=1 msg=Job completed
0.2953,Event,ADDED,eval-conflicts-rho010-r4-149-74z4p.18d542fb95e24f97,"reason=FailedScheduling count=None msg=0/6 nodes are available: 6 node(s) had untolerated taint(s). no new claims to deallocate, preemption: 0/6 nodes are available: 6 Preemption is not helpful for scheduling."
0.2954,Event,ADDED,eval-conflicts-rho010-r4-149-74z4p.18d542fcbaf094b2,reason=Scheduled count=None msg=Successfully assigned compute/eval-conflicts-rho010-r4-149-74z4p to kind-worker3
0.2957,Event,ADDED,eval-conflicts-rho010-r4-149-74z4p.18d542fce04d124f,"reason=Pulled count=1 msg=Container image ""busybox:musl"" already present on machine"
0.2959,Event,ADDED,eval-conflicts-rho010-r4-149-74z4p.18d542fce61ca3e7,reason=Created count=1 msg=Created container: task
0.2961,Event,ADDED,eval-conflicts-rho010-r4-149-74z4p.18d542fce8e0c294,reason=Started count=1 msg=Started container task
0.2963,Event,ADDED,eval-conflicts-rho010-r4-149.18d542fb95d7a30e,reason=SuccessfulCreate count=1 msg=Created pod: eval-conflicts-rho010-r4-149-74z4p
0.2966,Event,ADDED,eval-conflicts-rho010-r4-149.18d543025b2fe9c8,reason=Completed count=1 msg=Job completed
0.2968,Event,ADDED,eval-conflicts-rho010-r4-150-gqg6p.18d542fbd1b1b406,"reason=FailedScheduling count=None msg=0/6 nodes are available: 6 node(s) had untolerated taint(s). no new claims to deallocate, preemption: 0/6 nodes are available: 6 Preemption is not helpful for scheduling."
0.297,Event,ADDED,eval-conflicts-rho010-r4-150-gqg6p.18d542fcbb203128,reason=Scheduled count=None msg=Successfully assigned compute/eval-conflicts-rho010-r4-150-gqg6p to kind-worker3
0.2974,Event,ADDED,eval-conflicts-rho010-r4-150-gqg6p.18d542fceb4e6895,"reason=Pulled count=1 msg=Container image ""busybox:musl"" already present on machine"
0.2975,Event,ADDED,eval-conflicts-rho010-r4-150-gqg6p.18d542fceca8dbee,reason=Created count=1 msg=Created container: task
0.2977,Event,ADDED,eval-conflicts-rho010-r4-150-gqg6p.18d542fcf2b6475e,reason=Started count=1 msg=Started container task
0.2979,Event,ADDED,eval-conflicts-rho010-r4-150.18d542fbd1a9190f,reason=SuccessfulCreate count=1 msg=Created pod: eval-conflicts-rho010-r4-150-gqg6p
0.2982,Event,ADDED,eval-conflicts-rho010-r4-150.18d543025b31dabc,reason=Completed count=1 msg=Job completed
0.2984,Event,ADDED,eval-conflicts-rho010-r4-151-nzsb9.18d542fc0d1a61dc,"reason=FailedScheduling count=None msg=0/6 nodes are available: 6 node(s) had untolerated taint(s). no new claims to deallocate, preemption: 0/6 nodes are available: 6 Preemption is not helpful for scheduling."
0.2985,Event,ADDED,eval-conflicts-rho010-r4-151-nzsb9.18d542fcbe17f934,reason=Scheduled count=None msg=Successfully assigned compute/eval-conflicts-rho010-r4-151-nzsb9 to kind-worker3
0.2988,Event,ADDED,eval-conflicts-rho010-r4-151-nzsb9.18d542fcdffee8aa,"reason=Pulled count=1 msg=Container image ""busybox:musl"" already present on machine"
0.299,Event,ADDED,eval-conflicts-rho010-r4-151-nzsb9.18d542fce3567bdc,reason=Created count=1 msg=Created container: task
0.2991,Event,ADDED,eval-conflicts-rho010-r4-151-nzsb9.18d542fce79b8037,reason=Started count=1 msg=Started container task
0.2993,Event,ADDED,eval-conflicts-rho010-r4-151.18d542fc0d121467,reason=SuccessfulCreate count=1 msg=Created pod: eval-conflicts-rho010-r4-151-nzsb9
0.2995,Event,ADDED,eval-conflicts-rho010-r4-151.18d54302a11422de,reason=Completed count=1 msg=Job completed
0.2997,Event,ADDED,eval-conflicts-rho010-r4-152-9wlgl.18d542fc48c4876d,"reason=FailedScheduling count=None msg=0/6 nodes are available: 6 node(s) had untolerated taint(s). no new claims to deallocate, preemption: 0/6 nodes are available: 6 Preemption is not helpful for scheduling."
0.2998,Event,ADDED,eval-conflicts-rho010-r4-152-9wlgl.18d542fcbe5004c0,reason=Scheduled count=None msg=Successfully assigned compute/eval-conflicts-rho010-r4-152-9wlgl to kind-worker3
0.3,Event,ADDED,eval-conflicts-rho010-r4-152-9wlgl.18d542fce187ba64,"reason=Pulled count=1 msg=Container image ""busybox:musl"" already present on machine"
0.3002,Event,ADDED,eval-conflicts-rho010-r4-152-9wlgl.18d542fce70b3bd0,reason=Created count=1 msg=Created container: task
0.3004,Event,ADDED,eval-conflicts-rho010-r4-152-9wlgl.18d542fcea8f5358,reason=Started count=1 msg=Started container task
0.3005,Event,ADDED,eval-conflicts-rho010-r4-152.18d542fc48bad382,reason=SuccessfulCreate count=1 msg=Created pod: eval-conflicts-rho010-r4-152-9wlgl
0.3007,Event,ADDED,eval-conflicts-rho010-r4-152.18d5430220db8057,reason=Completed count=1 msg=Job completed
0.3009,Event,ADDED,eval-conflicts-rho010-r4-153-2g4zn.18d542fc872e9aa0,"reason=FailedScheduling count=None msg=0/6 nodes are available: 6 node(s) had untolerated taint(s). no new claims to deallocate, preemption: 0/6 nodes are available: 6 Preemption is not helpful for scheduling."
0.3012,Event,ADDED,eval-conflicts-rho010-r4-153-2g4zn.18d542fcbedbe829,reason=Scheduled count=None msg=Successfully assigned compute/eval-conflicts-rho010-r4-153-2g4zn to kind-worker3
0.3014,Event,ADDED,eval-conflicts-rho010-r4-153-2g4zn.18d542fce208c7d6,"reason=Pulled count=1 msg=Container image ""busybox:musl"" already present on machine"
0.3017,Event,ADDED,eval-conflicts-rho010-r4-153-2g4zn.18d542fce78b20d8,reason=Created count=1 msg=Created container: task
0.3019,Event,ADDED,eval-conflicts-rho010-r4-153-2g4zn.18d542fceb4be11b,reason=Started count=1 msg=Started container task
0.3021,Event,ADDED,eval-conflicts-rho010-r4-153.18d542fc8724ef97,reason=SuccessfulCreate count=1 msg=Created pod: eval-conflicts-rho010-r4-153-2g4zn
0.3023,Event,ADDED,eval-conflicts-rho010-r4-153.18d5430220f96b54,reason=Completed count=1 msg=Job completed
0.3025,Event,ADDED,eval-conflicts-rho010-r4-154-rqk48.18d542fcc67fb4ea,reason=Scheduled count=None msg=Successfully assigned compute/eval-conflicts-rho010-r4-154-rqk48 to kind-worker3
0.3026,Event,ADDED,eval-conflicts-rho010-r4-154-rqk48.18d542fce245db4d,"reason=Pulled count=1 msg=Container image ""busybox:musl"" already present on machine"
0.3028,Event,ADDED,eval-conflicts-rho010-r4-154-rqk48.18d542fce788bb79,reason=Created count=1 msg=Created container: task
0.303,Event,ADDED,eval-conflicts-rho010-r4-154-rqk48.18d542fceb4c2257,reason=Started count=1 msg=Started container task
0.3032,Event,ADDED,eval-conflicts-rho010-r4-154.18d542fcc06a42a6,reason=SuccessfulCreate count=1 msg=Created pod: eval-conflicts-rho010-r4-154-rqk48
0.3034,Event,ADDED,eval-conflicts-rho010-r4-154.18d543025b2c5588,reason=Completed count=1 msg=Job completed
0.3035,Event,ADDED,eval-conflicts-rho010-r4-155-vgtch.18d542fd02c748c2,reason=Scheduled count=None msg=Successfully assigned compute/eval-conflicts-rho010-r4-155-vgtch to kind-worker2
0.3041,Event,ADDED,eval-conflicts-rho010-r4-155-vgtch.18d542fd214aa301,"reason=Pulled count=1 msg=Container image ""busybox:musl"" already present on machine"
0.3043,Event,ADDED,eval-conflicts-rho010-r4-155-vgtch.18d542fd226450e3,reason=Created count=1 msg=Created container: task
0.3045,Event,ADDED,eval-conflicts-rho010-r4-155-vgtch.18d542fd244c5d1d,reason=Started count=1 msg=Started container task
0.3048,Event,ADDED,eval-conflicts-rho010-r4-155.18d542fd01bab9a9,reason=SuccessfulCreate count=1 msg=Created pod: eval-conflicts-rho010-r4-155-vgtch
0.305,Event,ADDED,eval-conflicts-rho010-r4-155.18d54302bc7db0c4,reason=Completed count=1 msg=Job completed
0.3052,Event,ADDED,eval-conflicts-rho010-r4-156-sd86l.18d542fd3dbc903c,reason=Scheduled count=None msg=Successfully assigned compute/eval-conflicts-rho010-r4-156-sd86l to kind-worker2
0.3053,Event,ADDED,eval-conflicts-rho010-r4-156-sd86l.18d542fd758a538a,"reason=Pulled count=1 msg=Container image ""busybox:musl"" already present on machine"
0.3056,Event,ADDED,eval-conflicts-rho010-r4-156-sd86l.18d542fd76e0c78f,reason=Created count=1 msg=Created container: task
0.3057,Event,ADDED,eval-conflicts-rho010-r4-156-sd86l.18d542fd866ecd01,reason=Started count=1 msg=Started container task
0.3059,Event,ADDED,eval-conflicts-rho010-r4-156.18d542fd3cc1a449,reason=SuccessfulCreate count=1 msg=Created pod: eval-conflicts-rho010-r4-156-sd86l
0.3061,Event,ADDED,eval-conflicts-rho010-r4-156.18d54302fdf871d1,reason=Completed count=1 msg=Job completed
0.3063,Event,ADDED,eval-conflicts-rho010-r4-157-92kpp.18d542fd78a43466,reason=Scheduled count=None msg=Successfully assigned compute/eval-conflicts-rho010-r4-157-92kpp to kind-worker2
0.3064,Event,ADDED,eval-conflicts-rho010-r4-157-92kpp.18d542fd9b7fdd50,"reason=Pulled count=1 msg=Container image ""busybox:musl"" already present on machine"
0.3066,Event,ADDED,eval-conflicts-rho010-r4-157-92kpp.18d542fd9cb441aa,reason=Created count=1 msg=Created container: task
0.3068,Event,ADDED,eval-conflicts-rho010-r4-157-92kpp.18d542fda967df6a,reason=Started count=1 msg=Started container task
0.307,Event,ADDED,eval-conflicts-rho010-r4-157.18d542fd77a40c6a,reason=SuccessfulCreate count=1 msg=Created pod: eval-conflicts-rho010-r4-157-92kpp
0.3072,Event,ADDED,eval-conflicts-rho010-r4-157.18d5430326880bb8,reason=Completed count=1 msg=Job completed
0.3073,Event,ADDED,eval-conflicts-rho010-r4-158-5d8dz.18d542fdb538ee89,reason=Scheduled count=None msg=Successfully assigned compute/eval-conflicts-rho010-r4-158-5d8dz to kind-worker2
0.3075,Event,ADDED,eval-conflicts-rho010-r4-158-5d8dz.18d542fdd3f6119b,"reason=Pulled count=1 msg=Container image ""busybox:musl"" already present on machine"
0.3078,Event,ADDED,eval-conflicts-rho010-r4-158-5d8dz.18d542fdd522a835,reason=Created count=1 msg=Created container: task
0.3081,Event,ADDED,eval-conflicts-rho010-r4-158-5d8dz.18d542fddd0a7464,reason=Started count=1 msg=Started container task
0.3085,Event,ADDED,eval-conflicts-rho010-r4-158.18d542fdb451f27a,reason=SuccessfulCreate count=1 msg=Created pod: eval-conflicts-rho010-r4-158-5d8dz
0.3087,Event,ADDED,eval-conflicts-rho010-r4-158.18d543036ab39bee,reason=Completed count=1 msg=Job completed
0.3088,Event,ADDED,eval-conflicts-rho010-r4-159-xfrxx.18d542fdeb3d15b7,reason=Scheduled count=None msg=Successfully assigned compute/eval-conflicts-rho010-r4-159-xfrxx to kind-worker2
0.3091,Event,ADDED,eval-conflicts-rho010-r4-159-xfrxx.18d542fe0bd20297,"reason=Pulled count=1 msg=Container image ""busybox:musl"" already present on machine"
0.3095,Event,ADDED,eval-conflicts-rho010-r4-159-xfrxx.18d542fe0cf8864c,reason=Created count=1 msg=Created container: task
0.3096,Event,ADDED,eval-conflicts-rho010-r4-159-xfrxx.18d542fe15965062,reason=Started count=1 msg=Started container task
0.3098,Event,ADDED,eval-conflicts-rho010-r4-159.18d542fdea5a8778,reason=SuccessfulCreate count=1 msg=Created pod: eval-conflicts-rho010-r4-159-xfrxx
0.31,Event,ADDED,eval-conflicts-rho010-r4-159.18d54303a6a6835f,reason=Completed count=1 msg=Job completed
0.3102,Event,ADDED,eval-conflicts-rho010-r4-160-zblnq.18d542fe279ad2e3,reason=Scheduled count=None msg=Successfully assigned compute/eval-conflicts-rho010-r4-160-zblnq to kind-worker4
0.3105,Event,ADDED,eval-conflicts-rho010-r4-160-zblnq.18d542fe46354d64,"reason=Pulled count=1 msg=Container image ""busybox:musl"" already present on machine"
0.3107,Event,ADDED,eval-conflicts-rho010-r4-160-zblnq.18d542fe47646d47,reason=Created count=1 msg=Created container: task
0.3109,Event,ADDED,eval-conflicts-rho010-r4-160-zblnq.18d542fe51e28f82,reason=Started count=1 msg=Started container task
0.3111,Event,ADDED,eval-conflicts-rho010-r4-160.18d542fe26c0e196,reason=SuccessfulCreate count=1 msg=Created pod: eval-conflicts-rho010-r4-160-zblnq
0.3114,Event,ADDED,eval-conflicts-rho010-r4-160.18d54303b852896b,reason=Completed count=1 msg=Job completed
0.3115,Event,ADDED,eval-conflicts-rho010-r4-161-4nxw6.18d542fe6bb5d0e2,reason=Scheduled count=None msg=Successfully assigned compute/eval-conflicts-rho010-r4-161-4nxw6 to kind-worker4
0.3117,Event,ADDED,eval-conflicts-rho010-r4-161-4nxw6.18d542fe90850333,"reason=Pulled count=1 msg=Container image ""busybox:musl"" already present on machine"
0.3119,Event,ADDED,eval-conflicts-rho010-r4-161-4nxw6.18d542fe91c6a7bb,reason=Created count=1 msg=Created container: task
0.3122,Event,ADDED,eval-conflicts-rho010-r4-161-4nxw6.18d542fe9a5276c4,reason=Started count=1 msg=Started container task
0.3124,Event,ADDED,eval-conflicts-rho010-r4-161.18d542fe6a77af14,reason=SuccessfulCreate count=1 msg=Created pod: eval-conflicts-rho010-r4-161-4nxw6
0.3125,Event,ADDED,eval-conflicts-rho010-r4-161.18d5430437ac2415,reason=Completed count=1 msg=Job completed
0.3128,Event,ADDED,eval-conflicts-rho010-r4-162-6kmp6.18d542fe9e2e34a3,reason=Scheduled count=None msg=Successfully assigned compute/eval-conflicts-rho010-r4-162-6kmp6 to kind-worker5
0.313,Event,ADDED,eval-conflicts-rho010-r4-162-6kmp6.18d542febc690ca4,"reason=Pulled count=1 msg=Container image ""busybox:musl"" already present on machine"
0.3132,Event,ADDED,eval-conflicts-rho010-r4-162-6kmp6.18d542febd7e6e11,reason=Created count=1 msg=Created container: task
0.3133,Event,ADDED,eval-conflicts-rho010-r4-162-6kmp6.18d542fec6113706,reason=Started count=1 msg=Started container task
0.3136,Event,ADDED,eval-conflicts-rho010-r4-162.18d542fe9cfc85fe,reason=SuccessfulCreate count=1 msg=Created pod: eval-conflicts-rho010-r4-162-6kmp6
0.3137,Event,ADDED,eval-conflicts-rho010-r4-162.18d54303fc81ff03,reason=Completed count=1 msg=Job completed
0.3139,Event,ADDED,eval-conflicts-rho010-r4-163-ml7gt.18d542fed9cd91cb,reason=Scheduled count=None msg=Successfully assigned compute/eval-conflicts-rho010-r4-163-ml7gt to kind-worker5
0.3141,Event,ADDED,eval-conflicts-rho010-r4-163-ml7gt.18d542ff0be4a417,"reason=Pulled count=1 msg=Container image ""busybox:musl"" already present on machine"
0.3142,Event,ADDED,eval-conflicts-rho010-r4-163-ml7gt.18d542ff0d0f78be,reason=Created count=1 msg=Created container: task
0.3144,Event,ADDED,eval-conflicts-rho010-r4-163-ml7gt.18d542ff14d951ea,reason=Started count=1 msg=Started container task
0.3146,Event,ADDED,eval-conflicts-rho010-r4-163.18d542fed85b5966,reason=SuccessfulCreate count=1 msg=Created pod: eval-conflicts-rho010-r4-163-ml7gt
0.3147,Event,ADDED,eval-conflicts-rho010-r4-163.18d54304b027481e,reason=Completed count=1 msg=Job completed
0.3149,Event,ADDED,eval-conflicts-rho010-r4-164-vbm9b.18d542ff176a5520,reason=Scheduled count=None msg=Successfully assigned compute/eval-conflicts-rho010-r4-164-vbm9b to kind-worker4
0.3151,Event,ADDED,eval-conflicts-rho010-r4-164-vbm9b.18d542ff3674e876,"reason=Pulled count=1 msg=Container image ""busybox:musl"" already present on machine"
0.3152,Event,ADDED,eval-conflicts-rho010-r4-164-vbm9b.18d542ff3791d5a7,reason=Created count=1 msg=Created container: task
0.3155,Event,ADDED,eval-conflicts-rho010-r4-164-vbm9b.18d542ff3c64acb3,reason=Started count=1 msg=Started container task
0.3156,Event,ADDED,eval-conflicts-rho010-r4-164.18d542ff16044695,reason=SuccessfulCreate count=1 msg=Created pod: eval-conflicts-rho010-r4-164-vbm9b
0.3158,Event,ADDED,eval-conflicts-rho010-r4-164.18d54304a4a2409f,reason=Completed count=1 msg=Job completed
0.316,Event,ADDED,eval-conflicts-rho010-r4-165-jt947.18d542ff555a9a2c,reason=Scheduled count=None msg=Successfully assigned compute/eval-conflicts-rho010-r4-165-jt947 to kind-worker4
0.3162,Event,ADDED,eval-conflicts-rho010-r4-165-jt947.18d542ff733cba3b,"reason=Pulled count=1 msg=Container image ""busybox:musl"" already present on machine"
0.3163,Event,ADDED,eval-conflicts-rho010-r4-165-jt947.18d542ff744ca1c1,reason=Created count=1 msg=Created container: task
0.3167,Event,ADDED,eval-conflicts-rho010-r4-165-jt947.18d542ff7abe686f,reason=Started count=1 msg=Started container task
0.3172,Event,ADDED,eval-conflicts-rho010-r4-165.18d542ff53f48847,reason=SuccessfulCreate count=1 msg=Created pod: eval-conflicts-rho010-r4-165-jt947
0.3174,Event,ADDED,eval-conflicts-rho010-r4-165.18d54304e02de446,reason=Completed count=1 msg=Job completed
0.3176,Event,ADDED,eval-conflicts-rho010-r4-166-s2bnn.18d542ff8e82916d,reason=Scheduled count=None msg=Successfully assigned compute/eval-conflicts-rho010-r4-166-s2bnn to kind-worker5
0.3178,Event,ADDED,eval-conflicts-rho010-r4-166-s2bnn.18d542ffb2e8a1cb,"reason=Pulled count=1 msg=Container image ""busybox:musl"" already present on machine"
0.3181,Event,ADDED,eval-conflicts-rho010-r4-166-s2bnn.18d542ffb4b4d3bf,reason=Created count=1 msg=Created container: task
0.3183,Event,ADDED,eval-conflicts-rho010-r4-166-s2bnn.18d542ffbe2c042c,reason=Started count=1 msg=Started container task
0.3185,Event,ADDED,eval-conflicts-rho010-r4-166.18d542ff8d358bd9,reason=SuccessfulCreate count=1 msg=Created pod: eval-conflicts-rho010-r4-166-s2bnn
0.3189,Event,ADDED,eval-conflicts-rho010-r4-166.18d54304ebb252ba,reason=Completed count=1 msg=Job completed
0.3191,Event,ADDED,eval-conflicts-rho010-r4-167-pdcwd.18d542ffc93d3545,reason=Scheduled count=None msg=Successfully assigned compute/eval-conflicts-rho010-r4-167-pdcwd to kind-worker5
0.3192,Event,ADDED,eval-conflicts-rho010-r4-167-pdcwd.18d542ffe1cd300f,"reason=Pulled count=1 msg=Container image ""busybox:musl"" already present on machine"
0.3194,Event,ADDED,eval-conflicts-rho010-r4-167-pdcwd.18d542ffe2e806f4,reason=Created count=1 msg=Created container: task
0.3197,Event,ADDED,eval-conflicts-rho010-r4-167-pdcwd.18d542ffe4ceaaf1,reason=Started count=1 msg=Started container task
0.3198,Event,ADDED,eval-conflicts-rho010-r4-167.18d542ffc7dbf403,reason=SuccessfulCreate count=1 msg=Created pod: eval-conflicts-rho010-r4-167-pdcwd
0.32,Event,ADDED,eval-conflicts-rho010-r4-167.18d5430565827aff,reason=Completed count=1 msg=Job completed
0.3203,Event,ADDED,eval-conflicts-rho010-r4-168-p495d.18d5430003aa304a,reason=Scheduled count=None msg=Successfully assigned compute/eval-conflicts-rho010-r4-168-p495d to kind-worker2
0.3205,Event,ADDED,eval-conflicts-rho010-r4-168-p495d.18d5430025341bee,"reason=Pulled count=1 msg=Container image ""busybox:musl"" already present on machine"
0.3207,Event,ADDED,eval-conflicts-rho010-r4-168-p495d.18d543002663e121,reason=Created count=1 msg=Created container: task
0.3208,Event,ADDED,eval-conflicts-rho010-r4-168-p495d.18d54300298fbffc,reason=Started count=1 msg=Started container task
0.321,Event,ADDED,eval-conflicts-rho010-r4-168.18d54300027770ca,reason=SuccessfulCreate count=1 msg=Created pod: eval-conflicts-rho010-r4-168-p495d
0.3212,Event,ADDED,eval-conflicts-rho010-r4-168.18d54305c08e948c,reason=Completed count=1 msg=Job completed
0.3214,Event,ADDED,eval-conflicts-rho010-r4-169-9tnvn.18d543003f38651a,reason=Scheduled count=None msg=Successfully assigned compute/eval-conflicts-rho010-r4-169-9tnvn to kind-worker2
0.3216,Event,ADDED,eval-conflicts-rho010-r4-169-9tnvn.18d543005b8fd703,"reason=Pulled count=1 msg=Container image ""busybox:musl"" already present on machine"
0.3219,Event,ADDED,eval-conflicts-rho010-r4-169-9tnvn.18d543005ca36e44,reason=Created count=1 msg=Created container: task
0.3221,Event,ADDED,eval-conflicts-rho010-r4-169-9tnvn.18d543005e906844,reason=Started count=1 msg=Started container task
0.3222,Event,ADDED,eval-conflicts-rho010-r4-169.18d543003ded9b17,reason=SuccessfulCreate count=1 msg=Created pod: eval-conflicts-rho010-r4-169-9tnvn
0.3225,Event,ADDED,eval-conflicts-rho010-r4-169.18d54305fc9943e5,reason=Completed count=1 msg=Job completed
0.3226,Event,ADDED,eval-conflicts-rho010-r4-170-ljjx8.18d543007ad3e1a9,reason=Scheduled count=None msg=Successfully assigned compute/eval-conflicts-rho010-r4-170-ljjx8 to kind-worker4
0.3228,Event,ADDED,eval-conflicts-rho010-r4-170-ljjx8.18d5430094aedb05,"reason=Pulled count=1 msg=Container image ""busybox:musl"" already present on machine"
0.323,Event,ADDED,eval-conflicts-rho010-r4-170-ljjx8.18d5430095bad02f,reason=Created count=1 msg=Created container: task
0.3231,Event,ADDED,eval-conflicts-rho010-r4-170-ljjx8.18d54300979ecd68,reason=Started count=1 msg=Started container task
0.3233,Event,ADDED,eval-conflicts-rho010-r4-170.18d54300797d36c5,reason=SuccessfulCreate count=1 msg=Created pod: eval-conflicts-rho010-r4-170-ljjx8
0.3235,Event,ADDED,eval-conflicts-rho010-r4-170.18d543061b90dabd,reason=Completed count=1 msg=Job completed
0.3236,Event,ADDED,eval-conflicts-rho010-r4-171-bblxz.18d54300b732123e,reason=Scheduled count=None msg=Successfully assigned compute/eval-conflicts-rho010-r4-171-bblxz to kind-worker2
0.3238,Event,ADDED,eval-conflicts-rho010-r4-171-bblxz.18d54300d87774b4,"reason=Pulled count=1 msg=Container image ""busybox:musl"" already present on machine"
0.324,Event,ADDED,eval-conflicts-rho010-r4-171-bblxz.18d54300d9898282,reason=Created count=1 msg=Created container: task
0.3241,Event,ADDED,eval-conflicts-rho010-r4-171-bblxz.18d54300dfa4e3f0,reason=Started count=1 msg=Started container task
0.3244,Event,ADDED,eval-conflicts-rho010-r4-171.18d54300b5cc1d5e,reason=SuccessfulCreate count=1 msg=Created pod: eval-conflicts-rho010-r4-171-bblxz
0.3245,Event,ADDED,eval-conflicts-rho010-r4-171.18d543066b08ca67,reason=Completed count=1 msg=Job completed
0.3247,Event,ADDED,eval-conflicts-rho010-r4-172-ttzkl.18d54300f4d6a881,"reason=FailedScheduling count=None msg=0/6 nodes are available: 1 c_wall violated: 1 conflicting context pair(s) with node memory, 1 c_wall violated: 3 conflicting context pair(s) with node memory, 2 c_wall violated: 2 conflicting context pair(s) with node memory, 2 node(s) had untolerated taint(s). no new claims to deallocate, preemption: 0/6 nodes are available: 2 Preemption is not helpful for scheduling, 4 No preemption victims found for incoming pod."
0.3251,Event,ADDED,eval-conflicts-rho010-r4-172-ttzkl.18d54300fa688a44,"reason=FailedScheduling count=None msg=0/6 nodes are available: 1 c_wall violated: 1 conflicting context pair(s) with node memory, 1 c_wall violated: 3 conflicting context pair(s) with node memory, 2 c_wall violated: 2 conflicting context pair(s) with node memory, 2 node(s) had untolerated taint(s). no new claims to deallocate, preemption: 0/6 nodes are available: 2 Preemption is not helpful for scheduling, 4 No preemption victims found for incoming pod."
0.3253,Event,ADDED,eval-conflicts-rho010-r4-172-ttzkl.18d543016ecb76fc,"reason=FailedScheduling count=None msg=0/6 nodes are available: 1 c_wall violated: 1 conflicting context pair(s) with node memory, 2 c_wall violated: 2 conflicting context pair(s) with node memory, 3 node(s) had untolerated taint(s). no new claims to deallocate, preemption: 0/6 nodes are available: 3 No preemption victims found for incoming pod, 3 Preemption is not helpful for scheduling."
0.3255,Event,ADDED,eval-conflicts-rho010-r4-172-ttzkl.18d543017cc777af,"reason=FailedScheduling count=None msg=0/6 nodes are available: 1 c_wall violated: 1 conflicting context pair(s) with node memory, 1 c_wall violated: 2 conflicting context pair(s) with node memory, 4 node(s) had untolerated taint(s). no new claims to deallocate, preemption: 0/6 nodes are available: 2 No preemption victims found for incoming pod, 4 Preemption is not helpful for scheduling."
0.3258,Event,ADDED,eval-conflicts-rho010-r4-172-ttzkl.18d543021dd3f688,"reason=FailedScheduling count=None msg=0/6 nodes are available: 2 c_wall violated: 2 conflicting context pair(s) with node memory, 4 node(s) had untolerated taint(s). no new claims to deallocate, preemption: 0/6 nodes are available: 2 No preemption victims found for incoming pod, 4 Preemption is not helpful for scheduling."
0.326,Event,ADDED,eval-conflicts-rho010-r4-172-ttzkl.18d54302a119cdc4,"reason=FailedScheduling count=None msg=0/6 nodes are available: 1 c_wall violated: 2 conflicting context pair(s) with node memory, 5 node(s) had untolerated taint(s). no new claims to deallocate, preemption: 0/6 nodes are available: 1 No preemption victims found for incoming pod, 5 Preemption is not helpful for scheduling."
0.3262,Event,ADDED,eval-conflicts-rho010-r4-172-ttzkl.18d543047a720d1f,reason=Scheduled count=None msg=Successfully assigned compute/eval-conflicts-rho010-r4-172-ttzkl to kind-worker
0.3264,Event,ADDED,eval-conflicts-rho010-r4-172-ttzkl.18d54304a1fdc23c,"reason=Pulled count=1 msg=Container image ""busybox:musl"" already present on machine"
0.3266,Event,ADDED,eval-conflicts-rho010-r4-172-ttzkl.18d54304a53d252b,reason=Created count=1 msg=Created container: task
0.3268,Event,ADDED,eval-conflicts-rho010-r4-172-ttzkl.18d54304a8f6506c,reason=Started count=1 msg=Started container task
0.3269,Event,ADDED,eval-conflicts-rho010-r4-172.18d54300f3e39f99,reason=SuccessfulCreate count=1 msg=Created pod: eval-conflicts-rho010-r4-172-ttzkl
0.3273,Event,ADDED,eval-conflicts-rho010-r4-172.18d5430a26092165,reason=Completed count=1 msg=Job completed
0.3274,Event,ADDED,eval-conflicts-rho010-r4-173-xxp9l.18d543012e48ae16,reason=Scheduled count=None msg=Successfully assigned compute/eval-conflicts-rho010-r4-173-xxp9l to kind-worker5
0.3276,Event,ADDED,eval-conflicts-rho010-r4-173-xxp9l.18d543014dd6b237,"reason=Pulled count=1 msg=Container image ""busybox:musl"" already present on machine"
0.3279,Event,ADDED,eval-conflicts-rho010-r4-173-xxp9l.18d543014effee59,reason=Created count=1 msg=Created container: task
0.3281,Event,ADDED,eval-conflicts-rho010-r4-173-xxp9l.18d54301578f865a,reason=Started count=1 msg=Started container task
0.3283,Event,ADDED,eval-conflicts-rho010-r4-173.18d543012cd6cddd,reason=SuccessfulCreate count=1 msg=Created pod: eval-conflicts-rho010-r4-173-xxp9l
0.3285,Event,ADDED,eval-conflicts-rho010-r4-173.18d54306c59ae6b2,reason=Completed count=1 msg=Job completed
0.3287,Event,ADDED,eval-conflicts-rho010-r4-174-z9mtg.18d543017469ed81,reason=Scheduled count=None msg=Successfully assigned compute/eval-conflicts-rho010-r4-174-z9mtg to kind-worker4
0.3289,Event,ADDED,eval-conflicts-rho010-r4-174-z9mtg.18d5430192493d82,"reason=Pulled count=1 msg=Container image ""busybox:musl"" already present on machine"
0.3291,Event,ADDED,eval-conflicts-rho010-r4-174-z9mtg.18d54301936aeda5,reason=Created count=1 msg=Created container: task
0.3292,Event,ADDED,eval-conflicts-rho010-r4-174-z9mtg.18d543019e2e251d,reason=Started count=1 msg=Started container task
0.3294,Event,ADDED,eval-conflicts-rho010-r4-174.18d543016a27cdcd,reason=SuccessfulCreate count=1 msg=Created pod: eval-conflicts-rho010-r4-174-z9mtg
0.3296,Event,ADDED,eval-conflicts-rho010-r4-174.18d54307380de082,reason=Completed count=1 msg=Job completed
0.3297,Event,ADDED,eval-conflicts-rho010-r4-175-rfnm2.18d54301a540339e,reason=Scheduled count=None msg=Successfully assigned compute/eval-conflicts-rho010-r4-175-rfnm2 to kind-worker4
0.3299,Event,ADDED,eval-conflicts-rho010-r4-175-rfnm2.18d54301ca1035c7,"reason=Pulled count=1 msg=Container image ""busybox:musl"" already present on machine"
0.3301,Event,ADDED,eval-conflicts-rho010-r4-175-rfnm2.18d54301cb3629ff,reason=Created count=1 msg=Created container: task
0.3303,Event,ADDED,eval-conflicts-rho010-r4-175-rfnm2.18d54301d480ec4b,reason=Started count=1 msg=Started container task
0.3304,Event,ADDED,eval-conflicts-rho010-r4-175.18d54301a3746c19,reason=SuccessfulCreate count=1 msg=Created pod: eval-conflicts-rho010-r4-175-rfnm2
0.3306,Event,ADDED,eval-conflicts-rho010-r4-175.18d54307730d5875,reason=Completed count=1 msg=Job completed
0.3307,Event,ADDED,eval-conflicts-rho010-r4-176-kjnf7.18d54301ede4ed4a,reason=Scheduled count=None msg=Successfully assigned compute/eval-conflicts-rho010-r4-176-kjnf7 to kind-worker5
0.3309,Event,ADDED,eval-conflicts-rho010-r4-176-kjnf7.18d543021e1d3a86,"reason=Pulled count=1 msg=Container image ""busybox:musl"" already present on machine"
0.3312,Event,ADDED,eval-conflicts-rho010-r4-176-kjnf7.18d543021f89cdae,reason=Created count=1 msg=Created container: task
0.3313,Event,ADDED,eval-conflicts-rho010-r4-176-kjnf7.18d5430223a68ad9,reason=Started count=1 msg=Started container task
0.3315,Event,ADDED,eval-conflicts-rho010-r4-176.18d54301ece792b1,reason=SuccessfulCreate count=1 msg=Created pod: eval-conflicts-rho010-r4-176-kjnf7
0.3317,Event,ADDED,eval-conflicts-rho010-r4-176.18d54307ba2aad76,reason=Completed count=1 msg=Job completed
0.3318,Event,ADDED,eval-conflicts-rho010-r4-177-2567f.18d543021baa1a91,reason=Scheduled count=None msg=Successfully assigned compute/eval-conflicts-rho010-r4-177-2567f to kind-worker4
0.332,Event,ADDED,eval-conflicts-rho010-r4-177-2567f.18d543023ef38184,"reason=Pulled count=1 msg=Container image ""busybox:musl"" already present on machine"
0.3322,Event,ADDED,eval-conflicts-rho010-r4-177-2567f.18d543024026f2e3,reason=Created count=1 msg=Created container: task
0.3324,Event,ADDED,eval-conflicts-rho010-r4-177-2567f.18d543024756cba6,reason=Started count=1 msg=Started container task
0.3328,Event,ADDED,eval-conflicts-rho010-r4-177.18d543021ac5d0f2,reason=SuccessfulCreate count=1 msg=Created pod: eval-conflicts-rho010-r4-177-2567f
0.333,Event,ADDED,eval-conflicts-rho010-r4-177.18d54307af2dc90b,reason=Completed count=1 msg=Job completed
0.3331,Event,ADDED,eval-conflicts-rho010-r4-178-8v25r.18d543025ba50a4e,"reason=FailedScheduling count=None msg=0/6 nodes are available: 2 c_wall violated: 2 conflicting context pair(s) with node memory, 4 node(s) had untolerated taint(s). no new claims to deallocate, preemption: 0/6 nodes are available: 2 No preemption victims found for incoming pod, 4 Preemption is not helpful for scheduling."
0.3334,Event,ADDED,eval-conflicts-rho010-r4-178-8v25r.18d543025f375a0d,"reason=FailedScheduling count=None msg=0/6 nodes are available: 2 c_wall violated: 2 conflicting context pair(s) with node memory, 4 node(s) had untolerated taint(s). no new claims to deallocate, preemption: 0/6 nodes are available: 2 No preemption victims found for incoming pod, 4 Preemption is not helpful for scheduling."
0.3336,Event,ADDED,eval-conflicts-rho010-r4-178-8v25r.18d54302a1515d74,"reason=FailedScheduling count=None msg=0/6 nodes are available: 1 c_wall violated: 2 conflicting context pair(s) with node memory, 5 node(s) had untolerated taint(s). no new claims to deallocate, preemption: 0/6 nodes are available: 1 No preemption victims found for incoming pod, 5 Preemption is not helpful for scheduling."
0.3338,Event,ADDED,eval-conflicts-rho010-r4-178-8v25r.18d543047aec5043,reason=Scheduled count=None msg=Successfully assigned compute/eval-conflicts-rho010-r4-178-8v25r to kind-worker
0.334,Event,ADDED,eval-conflicts-rho010-r4-178-8v25r.18d54304a2132197,"reason=Pulled count=1 msg=Container image ""busybox:musl"" already present on machine"
0.3342,Event,ADDED,eval-conflicts-rho010-r4-178-8v25r.18d54304a570e663,reason=Created count=1 msg=Created container: task
0.3344,Event,ADDED,eval-conflicts-rho010-r4-178-8v25r.18d54304a921e0fe,reason=Started count=1 msg=Started container task
0.3345,Event,ADDED,eval-conflicts-rho010-r4-178.18d543025b2c2ca1,reason=SuccessfulCreate count=1 msg=Created pod: eval-conflicts-rho010-r4-178-8v25r
0.3347,Event,ADDED,eval-conflicts-rho010-r4-178.18d54309ea5cad39,reason=Completed count=1 msg=Job completed
0.3349,Event,ADDED,eval-conflicts-rho010-r4-179-m4z64.18d5430293cd049a,reason=Scheduled count=None msg=Successfully assigned compute/eval-conflicts-rho010-r4-179-m4z64 to kind-worker5
0.335,Event,ADDED,eval-conflicts-rho010-r4-179-m4z64.18d54302b923bea7,"reason=Pulled count=1 msg=Container image ""busybox:musl"" already present on machine"
0.3352,Event,ADDED,eval-conflicts-rho010-r4-179-m4z64.18d54302ba7826c9,reason=Created count=1 msg=Created container: task
0.3354,Event,ADDED,eval-conflicts-rho010-r4-179-m4z64.18d54302bdadcd06,reason=Started count=1 msg=Started container task
0.3355,Event,ADDED,eval-conflicts-rho010-r4-179.18d5430292dbda41,reason=SuccessfulCreate count=1 msg=Created pod: eval-conflicts-rho010-r4-179-m4z64
0.3357,Event,ADDED,eval-conflicts-rho010-r4-179.18d5430835eba472,reason=Completed count=1 msg=Job completed
0.3358,Event,ADDED,eval-conflicts-rho010-r4-180-7w8lh.18d54302d438e53c,"reason=FailedScheduling count=None msg=0/6 nodes are available: 6 node(s) had untolerated taint(s). no new claims to deallocate, preemption: 0/6 nodes are available: 6 Preemption is not helpful for scheduling."
0.336,Event,ADDED,eval-conflicts-rho010-r4-180-7w8lh.18d543047b5fe05f,reason=Scheduled count=None msg=Successfully assigned compute/eval-conflicts-rho010-r4-180-7w8lh to kind-worker
0.3362,Event,ADDED,eval-conflicts-rho010-r4-180-7w8lh.18d54304a26458bf,"reason=Pulled count=1 msg=Container image ""busybox:musl"" already present on machine"
0.3363,Event,ADDED,eval-conflicts-rho010-r4-180-7w8lh.18d54304a640d6dc,reason=Created count=1 msg=Created container: task
0.3365,Event,ADDED,eval-conflicts-rho010-r4-180-7w8lh.18d54304aa52cd2a,reason=Started count=1 msg=Started container task
0.3367,Event,ADDED,eval-conflicts-rho010-r4-180.18d54302d42d3946,reason=SuccessfulCreate count=1 msg=Created pod: eval-conflicts-rho010-r4-180-7w8lh
0.3368,Event,ADDED,eval-conflicts-rho010-r4-180.18d5430a264823fd,reason=Completed count=1 msg=Job completed
0.337,Event,ADDED,eval-conflicts-rho010-r4-181-q2lx2.18d543030d26a477,"reason=FailedScheduling count=None msg=0/6 nodes are available: 6 node(s) had untolerated taint(s). no new claims to deallocate, preemption: 0/6 nodes are available: 6 Preemption is not helpful for scheduling."
0.3371,Event,ADDED,eval-conflicts-rho010-r4-181-q2lx2.18d543047b0383ff,"reason=FailedScheduling count=None msg=0/6 nodes are available: 1 c_wall violated: 1 conflicting context pair(s) with node memory, 5 node(s) had untolerated taint(s). no new claims to deallocate, preemption: 0/6 nodes are available: 1 No preemption victims found for incoming pod, 5 Preemption is not helpful for scheduling."
0.3373,Event,ADDED,eval-conflicts-rho010-r4-181-q2lx2.18d5430483bb278b,"reason=FailedScheduling count=None msg=0/6 nodes are available: 1 c_wall violated: 1 conflicting context pair(s) with node memory, 5 node(s) had untolerated taint(s). no new claims to deallocate, preemption: 0/6 nodes are available: 1 No preemption victims found for incoming pod, 5 Preemption is not helpful for scheduling."
0.3375,Event,ADDED,eval-conflicts-rho010-r4-181-q2lx2.18d543061e0602ba,reason=Scheduled count=None msg=Successfully assigned compute/eval-conflicts-rho010-r4-181-q2lx2 to kind-worker3
0.3377,Event,ADDED,eval-conflicts-rho010-r4-181-q2lx2.18d5430644bf9947,"reason=Pulled count=1 msg=Container image ""busybox:musl"" already present on machine"
0.3379,Event,ADDED,eval-conflicts-rho010-r4-181-q2lx2.18d5430648b47d30,reason=Created count=1 msg=Created container: task
0.3381,Event,ADDED,eval-conflicts-rho010-r4-181-q2lx2.18d543064cfee63e,reason=Started count=1 msg=Started container task
0.3382,Event,ADDED,eval-conflicts-rho010-r4-181.18d543030d1c9055,reason=SuccessfulCreate count=1 msg=Created pod: eval-conflicts-rho010-r4-181-q2lx2
0.3384,Event,ADDED,eval-conflicts-rho010-r4-181.18d5430bf20b3249,reason=Completed count=1 msg=Job completed
0.3386,Event,ADDED,eval-conflicts-rho010-r4-182-zswwl.18d54303451dc0d3,"reason=FailedScheduling count=None msg=0/6 nodes are available: 6 node(s) had untolerated taint(s). no new claims to deallocate, preemption: 0/6 nodes are available: 6 Preemption is not helpful for scheduling."
0.3387,Event,ADDED,eval-conflicts-rho010-r4-182-zswwl.18d543047bcb2fb1,"reason=FailedScheduling count=None msg=0/6 nodes are available: 1 c_wall violated: 1 conflicting context pair(s) with node memory, 5 node(s) had untolerated taint(s). no new claims to deallocate, preemption: 0/6 nodes are available: 1 No preemption victims found for incoming pod, 5 Preemption is not helpful for scheduling."
0.3389,Event,ADDED,eval-conflicts-rho010-r4-182-zswwl.18d5430483ee57cf,"reason=FailedScheduling count=None msg=0/6 nodes are available: 1 c_wall violated: 1 conflicting context pair(s) with node memory, 5 node(s) had untolerated taint(s). no new claims to deallocate, preemption: 0/6 nodes are available: 1 No preemption victims found for incoming pod, 5 Preemption is not helpful for scheduling."
0.339,Event,ADDED,eval-conflicts-rho010-r4-182-zswwl.18d543062e0cc429,reason=Scheduled count=None msg=Successfully assigned compute/eval-conflicts-rho010-r4-182-zswwl to kind-worker3
0.3393,Event,ADDED,eval-conflicts-rho010-r4-182-zswwl.18d543065efdb067,"reason=Pulled count=1 msg=Container image ""busybox:musl"" already present on machine"
0.3395,Event,ADDED,eval-conflicts-rho010-r4-182-zswwl.18d543066644860a,reason=Created count=1 msg=Created container: task
0.3396,Event,ADDED,eval-conflicts-rho010-r4-182-zswwl.18d543066b75b907,reason=Started count=1 msg=Started container task
0.3398,Event,ADDED,eval-conflicts-rho010-r4-182.18d5430345130410,reason=SuccessfulCreate count=1 msg=Created pod: eval-conflicts-rho010-r4-182-zswwl
0.34,Event,ADDED,eval-conflicts-rho010-r4-182.18d5430bf20acdf7,reason=Completed count=1 msg=Job completed
0.3401,Event,ADDED,eval-conflicts-rho010-r4-183-5944z.18d5430380fa85bf,"reason=FailedScheduling count=None msg=0/6 nodes are available: 6 node(s) had untolerated taint(s). no new claims to deallocate, preemption: 0/6 nodes are available: 6 Preemption is not helpful for scheduling."
0.3403,Event,ADDED,eval-conflicts-rho010-r4-183-5944z.18d543047e7f7e28,"reason=FailedScheduling count=None msg=0/6 nodes are available: 1 c_wall violated: 1 conflicting context pair(s) with node memory, 5 node(s) had untolerated taint(s). no new claims to deallocate, preemption: 0/6 nodes are available: 1 No preemption victims found for incoming pod, 5 Preemption is not helpful for scheduling."
0.3404,Event,ADDED,eval-conflicts-rho010-r4-183-5944z.18d54304841bceaa,"reason=FailedScheduling count=None msg=0/6 nodes are available: 1 c_wall violated: 2 conflicting context pair(s) with node memory, 5 node(s) had untolerated taint(s). no new claims to deallocate, preemption: 0/6 nodes are available: 1 No preemption victims found for incoming pod, 5 Preemption is not helpful for scheduling."
0.3406,Event,ADDED,eval-conflicts-rho010-r4-183-5944z.18d54304898cd294,"reason=FailedScheduling count=None msg=0/6 nodes are available: 1 c_wall violated: 2 conflicting context pair(s) with node memory, 5 node(s) had untolerated taint(s). no new claims to deallocate, preemption: 0/6 nodes are available: 1 No preemption victims found for incoming pod, 5 Preemption is not helpful for scheduling."
0.3407,Event,ADDED,eval-conflicts-rho010-r4-183-5944z.18d543062e671915,reason=Scheduled count=None msg=Successfully assigned compute/eval-conflicts-rho010-r4-183-5944z to kind-worker3
0.3409,Event,ADDED,eval-conflicts-rho010-r4-183-5944z.18d543065f91ea80,"reason=Pulled count=1 msg=Container image ""busybox:musl"" already present on machine"
0.3411,Event,ADDED,eval-conflicts-rho010-r4-183-5944z.18d543066896ceef,reason=Created count=1 msg=Created container: task
0.3413,Event,ADDED,eval-conflicts-rho010-r4-183-5944z.18d543066d883074,reason=Started count=1 msg=Started container task
0.3414,Event,ADDED,eval-conflicts-rho010-r4-183.18d5430380ef92ec,reason=SuccessfulCreate count=1 msg=Created pod: eval-conflicts-rho010-r4-183-5944z
0.3416,Event,ADDED,eval-conflicts-rho010-r4-183.18d5430bf2e7741f,reason=Completed count=1 msg=Job completed
0.3417,Event,ADDED,eval-conflicts-rho010-r4-184-5ztd7.18d54303be327ba5,"reason=FailedScheduling count=None msg=0/6 nodes are available: 6 node(s) had untolerated taint(s). no new claims to deallocate, preemption: 0/6 nodes are available: 6 Preemption is not helpful for scheduling."
0.3419,Event,ADDED,eval-conflicts-rho010-r4-184-5ztd7.18d54304827cd7cc,reason=Scheduled count=None msg=Successfully assigned compute/eval-conflicts-rho010-r4-184-5ztd7 to kind-worker
0.3421,Event,ADDED,eval-conflicts-rho010-r4-184-5ztd7.18d54304a24707eb,"reason=Pulled count=1 msg=Container image ""busybox:musl"" already present on machine"
0.3422,Event,ADDED,eval-conflicts-rho010-r4-184-5ztd7.18d54304a5c78060,reason=Created count=1 msg=Created container: task
0.3424,Event,ADDED,eval-conflicts-rho010-r4-184-5ztd7.18d54304aa52cd54,reason=Started count=1 msg=Started container task
0.3426,Event,ADDED,eval-conflicts-rho010-r4-184.18d54303be2d31b9,reason=SuccessfulCreate count=1 msg=Created pod: eval-conflicts-rho010-r4-184-5ztd7
0.3427,Event,ADDED,eval-conflicts-rho010-r4-184.18d5430a264b8f3e,reason=Completed count=1 msg=Job completed
0.3429,Event,ADDED,eval-conflicts-rho010-r4-185-t4ngc.18d54303fd698da4,"reason=FailedScheduling count=None msg=0/6 nodes are available: 6 node(s) had untolerated taint(s). no new claims to deallocate, preemption: 0/6 nodes are available: 6 Preemption is not helpful for scheduling."
0.3431,Event,ADDED,eval-conflicts-rho010-r4-185-t4ngc.18d5430482a2036e,reason=Scheduled count=None msg=Successfully assigned compute/eval-conflicts-rho010-r4-185-t4ngc to kind-worker
0.3433,Event,ADDED,eval-conflicts-rho010-r4-185-t4ngc.18d54304a27e2270,"reason=Pulled count=1 msg=Container image ""busybox:musl"" already present on machine"
0.3434,Event,ADDED,eval-conflicts-rho010-r4-185-t4ngc.18d54304a684a7c7,reason=Created count=1 msg=Created container: task
0.3436,Event,ADDED,eval-conflicts-rho010-r4-185-t4ngc.18d54304aa53ea36,reason=Started count=1 msg=Started container task
0.3438,Event,ADDED,eval-conflicts-rho010-r4-185.18d54303fd5e6ff7,reason=SuccessfulCreate count=1 msg=Created pod: eval-conflicts-rho010-r4-185-t4ngc
0.3439,Event,ADDED,eval-conflicts-rho010-r4-185.18d5430a2626bc6f,reason=Completed count=1 msg=Job completed
0.3441,Event,ADDED,eval-conflicts-rho010-r4-186-5xctb.18d54304376db967,"reason=FailedScheduling count=None msg=0/6 nodes are available: 6 node(s) had untolerated taint(s). no new claims to deallocate, preemption: 0/6 nodes are available: 6 Preemption is not helpful for scheduling."
0.3442,Event,ADDED,eval-conflicts-rho010-r4-186-5xctb.18d5430482800b68,"reason=FailedScheduling count=None msg=0/6 nodes are available: 1 c_wall violated: 1 conflicting context pair(s) with node memory, 5 node(s) had untolerated taint(s). no new claims to deallocate, preemption: 0/6 nodes are available: 1 No preemption victims found for incoming pod, 5 Preemption is not helpful for scheduling."
0.3444,Event,ADDED,eval-conflicts-rho010-r4-186-5xctb.18d54304877c089e,"reason=FailedScheduling count=None msg=0/6 nodes are available: 1 c_wall violated: 1 conflicting context pair(s) with node memory, 5 node(s) had untolerated taint(s). no new claims to deallocate, preemption: 0/6 nodes are available: 1 No preemption victims found for incoming pod, 5 Preemption is not helpful for scheduling."
0.3446,Event,ADDED,eval-conflicts-rho010-r4-186-5xctb.18d543062e68ee1b,reason=Scheduled count=None msg=Successfully assigned compute/eval-conflicts-rho010-r4-186-5xctb to kind-worker3
0.3448,Event,ADDED,eval-conflicts-rho010-r4-186-5xctb.18d543065f6c1ca4,"reason=Pulled count=1 msg=Container image ""busybox:musl"" already present on machine"
0.345,Event,ADDED,eval-conflicts-rho010-r4-186-5xctb.18d5430668bbfbd6,reason=Created count=1 msg=Created container: task
0.3451,Event,ADDED,eval-conflicts-rho010-r4-186-5xctb.18d543066d8568df,reason=Started count=1 msg=Started container task
0.3453,Event,ADDED,eval-conflicts-rho010-r4-186.18d5430437631acf,reason=SuccessfulCreate count=1 msg=Created pod: eval-conflicts-rho010-r4-186-5xctb
0.3455,Event,ADDED,eval-conflicts-rho010-r4-186.18d5430bb653e755,reason=Completed count=1 msg=Job completed
0.3456,Event,ADDED,eval-conflicts-rho010-r4-187-6fhwm.18d5430472a3751c,"reason=FailedScheduling count=None msg=0/6 nodes are available: 6 node(s) had untolerated taint(s). no new claims to deallocate, preemption: 0/6 nodes are available: 6 Preemption is not helpful for scheduling."
0.3458,Event,ADDED,eval-conflicts-rho010-r4-187-6fhwm.18d54304831e4390,"reason=FailedScheduling count=None msg=0/6 nodes are available: 1 c_wall violated: 2 conflicting context pair(s) with node memory, 5 node(s) had untolerated taint(s). no new claims to deallocate, preemption: 0/6 nodes are available: 1 No preemption victims found for incoming pod, 5 Preemption is not helpful for scheduling."
0.346,Event,ADDED,eval-conflicts-rho010-r4-187-6fhwm.18d5430487ae26c7,"reason=FailedScheduling count=None msg=0/6 nodes are available: 1 c_wall violated: 2 conflicting context pair(s) with node memory, 5 node(s) had untolerated taint(s). no new claims to deallocate, preemption: 0/6 nodes are available: 1 No preemption victims found for incoming pod, 5 Preemption is not helpful for scheduling."
0.3461,Event,ADDED,eval-conflicts-rho010-r4-187-6fhwm.18d543061d41b672,reason=Scheduled count=None msg=Successfully assigned compute/eval-conflicts-rho010-r4-187-6fhwm to kind-worker3
0.3463,Event,ADDED,eval-conflicts-rho010-r4-187-6fhwm.18d543063924fefa,"reason=Pulled count=1 msg=Container image ""busybox:musl"" already present on machine"
0.3465,Event,ADDED,eval-conflicts-rho010-r4-187-6fhwm.18d543063b29d764,reason=Created count=1 msg=Created container: task
0.3467,Event,ADDED,eval-conflicts-rho010-r4-187-6fhwm.18d5430644b89c20,reason=Started count=1 msg=Started container task
0.3468,Event,ADDED,eval-conflicts-rho010-r4-187.18d54304729944e6,reason=SuccessfulCreate count=1 msg=Created pod: eval-conflicts-rho010-r4-187-6fhwm
0.3473,Event,ADDED,eval-conflicts-rho010-r4-187.18d5430b79c39d6d,reason=Completed count=1 msg=Job completed
0.3475,Event,ADDED,eval-conflicts-rho010-r4-188-4k7sz.18d54304ab3c8a03,"reason=FailedScheduling count=None msg=0/6 nodes are available: 1 c_wall violated: 2 conflicting context pair(s) with node memory, 5 node(s) had untolerated taint(s). no new claims to deallocate, preemption: 0/6 nodes are available: 1 No preemption victims found for incoming pod, 5 Preemption is not helpful for scheduling."
0.3477,Event,ADDED,eval-conflicts-rho010-r4-188-4k7sz.18d54304ac5d3368,"reason=FailedScheduling count=None msg=0/6 nodes are available: 1 c_wall violated: 2 conflicting context pair(s) with node memory, 5 node(s) had untolerated taint(s). no new claims to deallocate, preemption: 0/6 nodes are available: 1 No preemption victims found for incoming pod, 5 Preemption is not helpful for scheduling."
0.348,Event,ADDED,eval-conflicts-rho010-r4-188-4k7sz.18d543062e69f267,reason=Scheduled count=None msg=Successfully assigned compute/eval-conflicts-rho010-r4-188-4k7sz to kind-worker3
0.3481,Event,ADDED,eval-conflicts-rho010-r4-188-4k7sz.18d543065f20434e,"reason=Pulled count=1 msg=Container image ""busybox:musl"" already present on machine"
0.3483,Event,ADDED,eval-conflicts-rho010-r4-188-4k7sz.18d5430667a426bb,reason=Created count=1 msg=Created container: task
0.3487,Event,ADDED,eval-conflicts-rho010-r4-188-4k7sz.18d543066d85ec44,reason=Started count=1 msg=Started container task
0.3488,Event,ADDED,eval-conflicts-rho010-r4-188.18d54304aade9dde,reason=SuccessfulCreate count=1 msg=Created pod: eval-conflicts-rho010-r4-188-4k7sz
0.349,Event,ADDED,eval-conflicts-rho010-r4-188.18d5430bb6548870,reason=Completed count=1 msg=Job completed
0.3492,Event,ADDED,eval-conflicts-rho010-r4-189-7nhtf.18d54304ed32a2ba,reason=Scheduled count=None msg=Successfully assigned compute/eval-conflicts-rho010-r4-189-7nhtf to kind-worker
0.3494,Event,ADDED,eval-conflicts-rho010-r4-189-7nhtf.18d543050fc306d2,"reason=Pulled count=1 msg=Container image ""busybox:musl"" already present on machine"
0.3496,Event,ADDED,eval-conflicts-rho010-r4-189-7nhtf.18d5430510fd224d,reason=Created count=1 msg=Created container: task
0.3498,Event,ADDED,eval-conflicts-rho010-r4-189-7nhtf.18d543051a8a2f27,reason=Started count=1 msg=Started container task
0.3499,Event,ADDED,eval-conflicts-rho010-r4-189.18d54304ec843bbd,reason=SuccessfulCreate count=1 msg=Created pod: eval-conflicts-rho010-r4-189-7nhtf
0.3501,Event,ADDED,eval-conflicts-rho010-r4-189.18d5430aa2eb7700,reason=Completed count=1 msg=Job completed
0.3503,Event,ADDED,eval-conflicts-rho010-r4-190-xg92c.18d5430526b871c8,reason=Scheduled count=None msg=Successfully assigned compute/eval-conflicts-rho010-r4-190-xg92c to kind-worker
0.3505,Event,ADDED,eval-conflicts-rho010-r4-190-xg92c.18d54305488f8f4a,"reason=Pulled count=1 msg=Container image ""busybox:musl"" already present on machine"
0.3506,Event,ADDED,eval-conflicts-rho010-r4-190-xg92c.18d5430549eb1211,reason=Created count=1 msg=Created container: task
0.3508,Event,ADDED,eval-conflicts-rho010-r4-190-xg92c.18d54305520fc0e1,reason=Started count=1 msg=Started container task
0.351,Event,ADDED,eval-conflicts-rho010-r4-190.18d54305263761c4,reason=SuccessfulCreate count=1 msg=Created pod: eval-conflicts-rho010-r4-190-xg92c
0.3512,Event,ADDED,eval-conflicts-rho010-r4-190.18d5430ae30c6633,reason=Completed count=1 msg=Job completed
0.3513,Event,ADDED,eval-conflicts-rho010-r4-191-rgj92.18d543055e7842ea,reason=Scheduled count=None msg=Successfully assigned compute/eval-conflicts-rho010-r4-191-rgj92 to kind-worker
0.3515,Event,ADDED,eval-conflicts-rho010-r4-191-rgj92.18d54305824fe55f,"reason=Pulled count=1 msg=Container image ""busybox:musl"" already present on machine"
0.3517,Event,ADDED,eval-conflicts-rho010-r4-191-rgj92.18d5430583c83241,reason=Created count=1 msg=Created container: task
0.3518,Event,ADDED,eval-conflicts-rho010-r4-191-rgj92.18d5430590f5147a,reason=Started count=1 msg=Started container task
0.352,Event,ADDED,eval-conflicts-rho010-r4-191.18d543055dfd20e6,reason=SuccessfulCreate count=1 msg=Created pod: eval-conflicts-rho010-r4-191-rgj92
0.3522,Event,ADDED,eval-conflicts-rho010-r4-191.18d5430b12d8ba1b,reason=Completed count=1 msg=Job completed
0.3523,Event,ADDED,eval-conflicts-rho010-r4-192-hwpx2.18d54305a2859aae,"reason=FailedScheduling count=None msg=0/6 nodes are available: 1 c_wall violated: 1 conflicting context pair(s) with node memory, 5 node(s) had untolerated taint(s). no new claims to deallocate, preemption: 0/6 nodes are available: 1 No preemption victims found for incoming pod, 5 Preemption is not helpful for scheduling."
0.3525,Event,ADDED,eval-conflicts-rho010-r4-192-hwpx2.18d54305a32a48cb,"reason=FailedScheduling count=None msg=0/6 nodes are available: 1 c_wall violated: 1 conflicting context pair(s) with node memory, 5 node(s) had untolerated taint(s). no new claims to deallocate, preemption: 0/6 nodes are available: 1 No preemption victims found for incoming pod, 5 Preemption is not helpful for scheduling."
0.3527,Event,ADDED,eval-conflicts-rho010-r4-192-hwpx2.18d543062e64c5b7,reason=Scheduled count=None msg=Successfully assigned compute/eval-conflicts-rho010-r4-192-hwpx2 to kind-worker3
0.3528,Event,ADDED,eval-conflicts-rho010-r4-192-hwpx2.18d543065f3fef92,"reason=Pulled count=1 msg=Container image ""busybox:musl"" already present on machine"
0.353,Event,ADDED,eval-conflicts-rho010-r4-192-hwpx2.18d54306686d3f2f,reason=Created count=1 msg=Created container: task
0.3532,Event,ADDED,eval-conflicts-rho010-r4-192-hwpx2.18d543066d86ac01,reason=Started count=1 msg=Started container task
0.3534,Event,ADDED,eval-conflicts-rho010-r4-192.18d54305a23f0f9d,reason=SuccessfulCreate count=1 msg=Created pod: eval-conflicts-rho010-r4-192-hwpx2
0.3535,Event,ADDED,eval-conflicts-rho010-r4-192.18d5430bf1e61caf,reason=Completed count=1 msg=Job completed
0.3537,Event,ADDED,eval-conflicts-rho010-r4-193-q775l.18d54305d6c1f125,reason=Scheduled count=None msg=Successfully assigned compute/eval-conflicts-rho010-r4-193-q775l to kind-worker
0.3538,Event,ADDED,eval-conflicts-rho010-r4-193-q775l.18d54305faa522b6,"reason=Pulled count=1 msg=Container image ""busybox:musl"" already present on machine"
0.354,Event,ADDED,eval-conflicts-rho010-r4-193-q775l.18d54305fbfd9c73,reason=Created count=1 msg=Created container: task
0.3542,Event,ADDED,eval-conflicts-rho010-r4-193-q775l.18d5430606d09c2b,reason=Started count=1 msg=Started container task
0.3544,Event,ADDED,eval-conflicts-rho010-r4-193.18d54305d638f233,reason=SuccessfulCreate count=1 msg=Created pod: eval-conflicts-rho010-r4-193-q775l
0.3545,Event,ADDED,eval-conflicts-rho010-r4-193.18d5430b8b34315c,reason=Completed count=1 msg=Job completed
0.3547,Event,ADDED,eval-conflicts-rho010-r4-194-7clwv.18d54306125a18e4,reason=Scheduled count=None msg=Successfully assigned compute/eval-conflicts-rho010-r4-194-7clwv to kind-worker
0.3553,Event,ADDED,eval-conflicts-rho010-r4-194-7clwv.18d5430638ee0d14,"reason=Pulled count=1 msg=Container image ""busybox:musl"" already present on machine"
0.3557,Event,ADDED,eval-conflicts-rho010-r4-194-7clwv.18d543063aa5c6e9,reason=Created count=1 msg=Created container: task
0.3559,Event,ADDED,eval-conflicts-rho010-r4-194-7clwv.18d5430644bc1428,reason=Started count=1 msg=Started container task
0.3562,Event,ADDED,eval-conflicts-rho010-r4-194.18d5430611afbf8e,reason=SuccessfulCreate count=1 msg=Created pod: eval-conflicts-rho010-r4-194-7clwv
0.3566,Event,ADDED,eval-conflicts-rho010-r4-194.18d5430bca09caa9,reason=Completed count=1 msg=Job completed
0.3568,Event,ADDED,eval-conflicts-rho010-r4-195-j6cl5.18d543064d842e48,reason=Scheduled count=None msg=Successfully assigned compute/eval-conflicts-rho010-r4-195-j6cl5 to kind-worker2
0.357,Event,ADDED,eval-conflicts-rho010-r4-195-j6cl5.18d543066de1cf03,"reason=Pulled count=1 msg=Container image ""busybox:musl"" already present on machine"
0.3572,Event,ADDED,eval-conflicts-rho010-r4-195-j6cl5.18d543066f05bf27,reason=Created count=1 msg=Created container: task
0.3574,Event,ADDED,eval-conflicts-rho010-r4-195-j6cl5.18d543067452fe52,reason=Started count=1 msg=Started container task
0.3575,Event,ADDED,eval-conflicts-rho010-r4-195.18d543064bfc62c2,reason=SuccessfulCreate count=1 msg=Created pod: eval-conflicts-rho010-r4-195-j6cl5
0.3577,Event,ADDED,eval-conflicts-rho010-r4-195.18d5430c06869d28,reason=Completed count=1 msg=Job completed
0.358,Event,ADDED,eval-conflicts-rho010-r4-196-6bg7k.18d5430688b67bab,reason=Scheduled count=None msg=Successfully assigned compute/eval-conflicts-rho010-r4-196-6bg7k to kind-worker2
0.3582,Event,ADDED,eval-conflicts-rho010-r4-196-6bg7k.18d54306ade092ab,"reason=Pulled count=1 msg=Container image ""busybox:musl"" already present on machine"
0.3584,Event,ADDED,eval-conflicts-rho010-r4-196-6bg7k.18d54306af75b208,reason=Created count=1 msg=Created container: task
0.3585,Event,ADDED,eval-conflicts-rho010-r4-196-6bg7k.18d54306ba3a76b5,reason=Started count=1 msg=Started container task
0.3589,Event,ADDED,eval-conflicts-rho010-r4-196.18d54306874e2300,reason=SuccessfulCreate count=1 msg=Created pod: eval-conflicts-rho010-r4-196-6bg7k
0.3591,Event,ADDED,eval-conflicts-rho010-r4-196.18d5430c43c2afff,reason=Completed count=1 msg=Job completed
0.3593,Event,ADDED,eval-conflicts-rho010-r4-197-7bgg4.18d54306c478d996,reason=Scheduled count=None msg=Successfully assigned compute/eval-conflicts-rho010-r4-197-7bgg4 to kind-worker2
0.3596,Event,ADDED,eval-conflicts-rho010-r4-197-7bgg4.18d54306e2dd8287,"reason=Pulled count=1 msg=Container image ""busybox:musl"" already present on machine"
0.3598,Event,ADDED,eval-conflicts-rho010-r4-197-7bgg4.18d54306e3f4f43c,reason=Created count=1 msg=Created container: task
0.36,Event,ADDED,eval-conflicts-rho010-r4-197-7bgg4.18d54306e89aa707,reason=Started count=1 msg=Started container task
0.3601,Event,ADDED,eval-conflicts-rho010-r4-197.18d54306c316ec98,reason=SuccessfulCreate count=1 msg=Created pod: eval-conflicts-rho010-r4-197-7bgg4
0.3604,Event,ADDED,eval-conflicts-rho010-r4-197.18d5430c44480e46,reason=Completed count=1 msg=Job completed
0.3606,Event,ADDED,eval-conflicts-rho010-r4-198-q644s.18d54307006fb0be,reason=Scheduled count=None msg=Successfully assigned compute/eval-conflicts-rho010-r4-198-q644s to kind-worker2
0.3608,Event,ADDED,eval-conflicts-rho010-r4-198-q644s.18d543071bbed321,"reason=Pulled count=1 msg=Container image ""busybox:musl"" already present on machine"
0.361,Event,ADDED,eval-conflicts-rho010-r4-198-q644s.18d543071ceab7c1,reason=Created count=1 msg=Created container: task
0.3612,Event,ADDED,eval-conflicts-rho010-r4-198-q644s.18d5430721418a48,reason=Started count=1 msg=Started container task
0.3614,Event,ADDED,eval-conflicts-rho010-r4-198.18d54306ff25b083,reason=SuccessfulCreate count=1 msg=Created pod: eval-conflicts-rho010-r4-198-q644s
0.3616,Event,ADDED,eval-conflicts-rho010-r4-198.18d5430cbbb2ecae,reason=Completed count=1 msg=Job completed
0.3618,Event,ADDED,eval-conflicts-rho010-r4-199-59k5z.18d543073b8ec028,reason=Scheduled count=None msg=Successfully assigned compute/eval-conflicts-rho010-r4-199-59k5z to kind-worker2
0.3619,Event,ADDED,eval-conflicts-rho010-r4-199-59k5z.18d5430755b5f4dd,"reason=Pulled count=1 msg=Container image ""busybox:musl"" already present on machine"
0.3621,Event,ADDED,eval-conflicts-rho010-r4-199-59k5z.18d5430757174251,reason=Created count=1 msg=Created container: task
0.3623,Event,ADDED,eval-conflicts-rho010-r4-199-59k5z.18d543075b520b88,reason=Started count=1 msg=Started container task
0.3626,Event,ADDED,eval-conflicts-rho010-r4-199.18d543073a487e08,reason=SuccessfulCreate count=1 msg=Created pod: eval-conflicts-rho010-r4-199-59k5z
0.3628,Event,ADDED,eval-conflicts-rho010-r4-199.18d5430cf7d4996d,reason=Completed count=1 msg=Job completed
0.363,Event,ADDED,eval-conflicts-rho020-r0-000-2d4ph.18d5431b150ed5cc,reason=Scheduled count=None msg=Successfully assigned compute/eval-conflicts-rho020-r0-000-2d4ph to kind-worker2
0.3632,Event,ADDED,eval-conflicts-rho020-r0-000-2d4ph.18d5431b31f36e98,"reason=Pulled count=1 msg=Container image ""busybox:musl"" already present on machine"
0.3634,Event,ADDED,eval-conflicts-rho020-r0-000-2d4ph.18d5431b330cd2c2,reason=Created count=1 msg=Created container: task
0.3636,Event,ADDED,eval-conflicts-rho020-r0-000-2d4ph.18d5431b3a2131fe,reason=Started count=1 msg=Started container task
0.3638,Event,ADDED,eval-conflicts-rho020-r0-000.18d5431b13f48856,reason=SuccessfulCreate count=1 msg=Created pod: eval-conflicts-rho020-r0-000-2d4ph
0.3641,Event,ADDED,eval-conflicts-rho020-r0-000.18d54320d8361b71,reason=Completed count=1 msg=Job completed
0.3642,Event,ADDED,eval-conflicts-rho020-r0-001-xndcm.18d5431b4f5cf60a,reason=Scheduled count=None msg=Successfully assigned compute/eval-conflicts-rho020-r0-001-xndcm to kind-worker3
0.3644,Event,ADDED,eval-conflicts-rho020-r0-001-xndcm.18d5431b69f7a613,"reason=Pulled count=1 msg=Container image ""busybox:musl"" already present on machine"
0.3646,Event,ADDED,eval-conflicts-rho020-r0-001-xndcm.18d5431b6b17a73b,reason=Created count=1 msg=Created container: task
0.365,Event,ADDED,eval-conflicts-rho020-r0-001-xndcm.18d5431b6eeae31c,reason=Started count=1 msg=Started container task
0.3652,Event,ADDED,eval-conflicts-rho020-r0-001.18d5431b4e458a4c,reason=SuccessfulCreate count=1 msg=Created pod: eval-conflicts-rho020-r0-001-xndcm
0.3654,Event,ADDED,eval-conflicts-rho020-r0-001.18d54320f43aa85e,reason=Completed count=1 msg=Job completed
0.3658,Event,ADDED,eval-conflicts-rho020-r0-002-6p5cw.18d5431b8aee51f3,reason=Scheduled count=None msg=Successfully assigned compute/eval-conflicts-rho020-r0-002-6p5cw to kind-worker2
0.3659,Event,ADDED,eval-conflicts-rho020-r0-002-6p5cw.18d5431ba5198abe,"reason=Pulled count=1 msg=Container image ""busybox:musl"" already present on machine"
0.3661,Event,ADDED,eval-conflicts-rho020-r0-002-6p5cw.18d5431ba6476cfc,reason=Created count=1 msg=Created container: task
0.3663,Event,ADDED,eval-conflicts-rho020-r0-002-6p5cw.18d5431bae4fcb69,reason=Started count=1 msg=Started container task
0.3665,Event,ADDED,eval-conflicts-rho020-r0-002.18d5431b89e201b7,reason=SuccessfulCreate count=1 msg=Created pod: eval-conflicts-rho020-r0-002-6p5cw
0.3667,Event,ADDED,eval-conflicts-rho020-r0-002.18d543214a26d835,reason=Completed count=1 msg=Job completed
0.3669,Event,ADDED,eval-conflicts-rho020-r0-003-4qbb7.18d5431bc719270e,reason=Scheduled count=None msg=Successfully assigned compute/eval-conflicts-rho020-r0-003-4qbb7 to kind-worker3
0.367,Event,ADDED,eval-conflicts-rho020-r0-003-4qbb7.18d5431be21b116f,"reason=Pulled count=1 msg=Container image ""busybox:musl"" already present on machine"
0.3672,Event,ADDED,eval-conflicts-rho020-r0-003-4qbb7.18d5431be34719a4,reason=Created count=1 msg=Created container: task
0.3674,Event,ADDED,eval-conflicts-rho020-r0-003-4qbb7.18d5431be8440f90,reason=Started count=1 msg=Started container task
0.3675,Event,ADDED,eval-conflicts-rho020-r0-003.18d5431bc61b5c22,reason=SuccessfulCreate count=1 msg=Created pod: eval-conflicts-rho020-r0-003-4qbb7
0.3714,Event,ADDED,eval-conflicts-rho020-r0-003.18d54321665712f6,reason=Completed count=1 msg=Job completed
0.3716,Event,ADDED,eval-conflicts-rho020-r0-004-dv6cr.18d5431c059abad1,reason=Scheduled count=None msg=Successfully assigned compute/eval-conflicts-rho020-r0-004-dv6cr to kind-worker4
0.3718,Event,ADDED,eval-conflicts-rho020-r0-004-dv6cr.18d5431c1de13fee,"reason=Pulled count=1 msg=Container image ""busybox:musl"" already present on machine"
0.372,Event,ADDED,eval-conflicts-rho020-r0-004-dv6cr.18d5431c1f136f6d,reason=Created count=1 msg=Created container: task
0.3722,Event,ADDED,eval-conflicts-rho020-r0-004-dv6cr.18d5431c21017ea7,reason=Started count=1 msg=Started container task
0.3724,Event,ADDED,eval-conflicts-rho020-r0-004.18d5431c04a80957,reason=SuccessfulCreate count=1 msg=Created pod: eval-conflicts-rho020-r0-004-dv6cr
0.3726,Event,ADDED,eval-conflicts-rho020-r0-004.18d5432193c1ebaa,reason=Completed count=1 msg=Job completed
0.3728,Event,ADDED,eval-conflicts-rho020-r0-005-qc4zj.18d5431c3df6febb,reason=Scheduled count=None msg=Successfully assigned compute/eval-conflicts-rho020-r0-005-qc4zj to kind-worker2
0.3729,Event,ADDED,eval-conflicts-rho020-r0-005-qc4zj.18d5431c5837d1ed,"reason=Pulled count=1 msg=Container image ""busybox:musl"" already present on machine"
0.3731,Event,ADDED,eval-conflicts-rho020-r0-005-qc4zj.18d5431c59483cdc,reason=Created count=1 msg=Created container: task
0.3733,Event,ADDED,eval-conflicts-rho020-r0-005-qc4zj.18d5431c5c463525,reason=Started count=1 msg=Started container task
0.3736,Event,ADDED,eval-conflicts-rho020-r0-005.18d5431c3cdb1970,reason=SuccessfulCreate count=1 msg=Created pod: eval-conflicts-rho020-r0-005-qc4zj
0.3737,Event,ADDED,eval-conflicts-rho020-r0-005.18d54321f448ef40,reason=Completed count=1 msg=Job completed
0.3739,Event,ADDED,eval-conflicts-rho020-r0-006-7kxlf.18d5431c79577719,reason=Scheduled count=None msg=Successfully assigned compute/eval-conflicts-rho020-r0-006-7kxlf to kind-worker4
0.3741,Event,ADDED,eval-conflicts-rho020-r0-006-7kxlf.18d5431c921ed4bc,"reason=Pulled count=1 msg=Container image ""busybox:musl"" already present on machine"
0.3744,Event,ADDED,eval-conflicts-rho020-r0-006-7kxlf.18d5431c933dda0f,reason=Created count=1 msg=Created container: task
0.3746,Event,ADDED,eval-conflicts-rho020-r0-006-7kxlf.18d5431c9519266e,reason=Started count=1 msg=Started container task
0.3748,Event,ADDED,eval-conflicts-rho020-r0-006.18d5431c7826e914,reason=SuccessfulCreate count=1 msg=Created pod: eval-conflicts-rho020-r0-006-7kxlf
0.375,Event,ADDED,eval-conflicts-rho020-r0-006.18d543220da0ce9b,reason=Completed count=1 msg=Job completed
0.3752,Event,ADDED,eval-conflicts-rho020-r0-007-h66k5.18d5431cb4bdd2e0,reason=Scheduled count=None msg=Successfully assigned compute/eval-conflicts-rho020-r0-007-h66k5 to kind-worker5
0.3754,Event,ADDED,eval-conflicts-rho020-r0-007-h66k5.18d5431ccec84d8a,"reason=Pulled count=1 msg=Container image ""busybox:musl"" already present on machine"
0.3756,Event,ADDED,eval-conflicts-rho020-r0-007-h66k5.18d5431ccfe57679,reason=Created count=1 msg=Created container: task
0.3759,Event,ADDED,eval-conflicts-rho020-r0-007-h66k5.18d5431cd22b7188,reason=Started count=1 msg=Started container task
0.3761,Event,ADDED,eval-conflicts-rho020-r0-007.18d5431cb383dbe2,reason=SuccessfulCreate count=1 msg=Created pod: eval-conflicts-rho020-r0-007-h66k5
0.3762,Event,ADDED,eval-conflicts-rho020-r0-007.18d5432210ee4316,reason=Completed count=1 msg=Job completed
0.3764,Event,ADDED,eval-conflicts-rho020-r0-008-4vp7r.18d5431cf0b8d497,reason=Scheduled count=None msg=Successfully assigned compute/eval-conflicts-rho020-r0-008-4vp7r to kind-worker2
0.3767,Event,ADDED,eval-conflicts-rho020-r0-008-4vp7r.18d5431d08a456c7,"reason=Pulled count=1 msg=Container image ""busybox:musl"" already present on machine"
0.3769,Event,ADDED,eval-conflicts-rho020-r0-008-4vp7r.18d5431d09dc00ef,reason=Created count=1 msg=Created container: task
0.3771,Event,ADDED,eval-conflicts-rho020-r0-008-4vp7r.18d5431d0ffc35a1,reason=Started count=1 msg=Started container task
0.3773,Event,ADDED,eval-conflicts-rho020-r0-008.18d5431cef498542,reason=SuccessfulCreate count=1 msg=Created pod: eval-conflicts-rho020-r0-008-4vp7r
0.3775,Event,ADDED,eval-conflicts-rho020-r0-008.18d54322a996a5ed,reason=Completed count=1 msg=Job completed
0.3777,Event,ADDED,eval-conflicts-rho020-r0-009-p4577.18d5431d2c79a5f7,reason=Scheduled count=None msg=Successfully assigned compute/eval-conflicts-rho020-r0-009-p4577 to kind-worker3
0.3779,Event,ADDED,eval-conflicts-rho020-r0-009-p4577.18d5431d487deac6,"reason=Pulled count=1 msg=Container image ""busybox:musl"" already present on machine"
0.3781,Event,ADDED,eval-conflicts-rho020-r0-009-p4577.18d5431d498dabee,reason=Created count=1 msg=Created container: task
0.3783,Event,ADDED,eval-conflicts-rho020-r0-009-p4577.18d5431d4d989715,reason=Started count=1 msg=Started container task
0.3785,Event,ADDED,eval-conflicts-rho020-r0-009.18d5431d2b2367ea,reason=SuccessfulCreate count=1 msg=Created pod: eval-conflicts-rho020-r0-009-p4577
0.3786,Event,ADDED,eval-conflicts-rho020-r0-009.18d54322cbfd8117,reason=Completed count=1 msg=Job completed
0.3788,Event,ADDED,eval-conflicts-rho020-r0-010-xdkzq.18d5431d6b4ebdbb,reason=Scheduled count=None msg=Successfully assigned compute/eval-conflicts-rho020-r0-010-xdkzq to kind-worker2
0.379,Event,ADDED,eval-conflicts-rho020-r0-010-xdkzq.18d5431d89e91805,"reason=Pulled count=1 msg=Container image ""busybox:musl"" already present on machine"
0.3791,Event,ADDED,eval-conflicts-rho020-r0-010-xdkzq.18d5431d8b163f89,reason=Created count=1 msg=Created container: task
0.3794,Event,ADDED,eval-conflicts-rho020-r0-010-xdkzq.18d5431d93e43f97,reason=Started count=1 msg=Started container task
0.3796,Event,ADDED,eval-conflicts-rho020-r0-010.18d5431d67690606,reason=SuccessfulCreate count=1 msg=Created pod: eval-conflicts-rho020-r0-010-xdkzq
0.3798,Event,ADDED,eval-conflicts-rho020-r0-010.18d543231fa3b05b,reason=Completed count=1 msg=Job completed
0.38,Event,ADDED,eval-conflicts-rho020-r0-011-hsw6l.18d5431da29018d4,reason=Scheduled count=None msg=Successfully assigned compute/eval-conflicts-rho020-r0-011-hsw6l to kind-worker
0.3803,Event,ADDED,eval-conflicts-rho020-r0-011-hsw6l.18d5431dc545b6dc,"reason=Pulled count=1 msg=Container image ""busybox:musl"" already present on machine"
0.3805,Event,ADDED,eval-conflicts-rho020-r0-011-hsw6l.18d5431dc676b64a,reason=Created count=1 msg=Created container: task
0.3806,Event,ADDED,eval-conflicts-rho020-r0-011-hsw6l.18d5431dcaf34499,reason=Started count=1 msg=Started container task
0.3809,Event,ADDED,eval-conflicts-rho020-r0-011.18d5431da1cb2810,reason=SuccessfulCreate count=1 msg=Created pod: eval-conflicts-rho020-r0-011-hsw6l
0.3811,Event,ADDED,eval-conflicts-rho020-r0-011.18d5432356f24a56,reason=Completed count=1 msg=Job completed
0.3813,Event,ADDED,eval-conflicts-rho020-r0-012-hmnb4.18d5431ddf40e6db,reason=Scheduled count=None msg=Successfully assigned compute/eval-conflicts-rho020-r0-012-hmnb4 to kind-worker
0.3815,Event,ADDED,eval-conflicts-rho020-r0-012-hmnb4.18d5431df9beccfe,"reason=Pulled count=1 msg=Container image ""busybox:musl"" already present on machine"
0.3817,Event,ADDED,eval-conflicts-rho020-r0-012-hmnb4.18d5431dfadc9b13,reason=Created count=1 msg=Created container: task
0.3819,Event,ADDED,eval-conflicts-rho020-r0-012-hmnb4.18d5431dff98e812,reason=Started count=1 msg=Started container task
0.382,Event,ADDED,eval-conflicts-rho020-r0-012.18d5431dddcdb215,reason=SuccessfulCreate count=1 msg=Created pod: eval-conflicts-rho020-r0-012-hmnb4
0.3822,Event,ADDED,eval-conflicts-rho020-r0-012.18d5432392b8dbf1,reason=Completed count=1 msg=Job completed
0.3825,Event,ADDED,eval-conflicts-rho020-r0-013-hnjw8.18d5431e1a89e0f7,reason=Scheduled count=None msg=Successfully assigned compute/eval-conflicts-rho020-r0-013-hnjw8 to kind-worker5
0.3826,Event,ADDED,eval-conflicts-rho020-r0-013-hnjw8.18d5431e36a76904,"reason=Pulled count=1 msg=Container image ""busybox:musl"" already present on machine"
0.3828,Event,ADDED,eval-conflicts-rho020-r0-013-hnjw8.18d5431e37d063d9,reason=Created count=1 msg=Created container: task
0.383,Event,ADDED,eval-conflicts-rho020-r0-013-hnjw8.18d5431e3fc50afd,reason=Started count=1 msg=Started container task
0.3831,Event,ADDED,eval-conflicts-rho020-r0-013.18d5431e190ed97a,reason=SuccessfulCreate count=1 msg=Created pod: eval-conflicts-rho020-r0-013-hnjw8
0.3834,Event,ADDED,eval-conflicts-rho020-r0-013.18d54323b5fcb100,reason=Completed count=1 msg=Job completed
0.3836,Event,ADDED,eval-conflicts-rho020-r0-014-fww99.18d5431e55b8a0d5,reason=Scheduled count=None msg=Successfully assigned compute/eval-conflicts-rho020-r0-014-fww99 to kind-worker5
0.3838,Event,ADDED,eval-conflicts-rho020-r0-014-fww99.18d5431e703c3393,"reason=Pulled count=1 msg=Container image ""busybox:musl"" already present on machine"
0.384,Event,ADDED,eval-conflicts-rho020-r0-014-fww99.18d5431e7167e539,reason=Created count=1 msg=Created container: task
0.3842,Event,ADDED,eval-conflicts-rho020-r0-014-fww99.18d5431e79fab46d,reason=Started count=1 msg=Started container task
0.3844,Event,ADDED,eval-conflicts-rho020-r0-014.18d5431e549482ce,reason=SuccessfulCreate count=1 msg=Created pod: eval-conflicts-rho020-r0-014-fww99
0.3846,Event,ADDED,eval-conflicts-rho020-r0-014.18d54323f5c4a33d,reason=Completed count=1 msg=Job completed
0.3847,Event,ADDED,eval-conflicts-rho020-r0-015-d8ccb.18d5431e91b10034,reason=Scheduled count=None msg=Successfully assigned compute/eval-conflicts-rho020-r0-015-d8ccb to kind-worker5
0.3849,Event,ADDED,eval-conflicts-rho020-r0-015-d8ccb.18d5431eadcca518,"reason=Pulled count=1 msg=Container image ""busybox:musl"" already present on machine"
0.3852,Event,ADDED,eval-conflicts-rho020-r0-015-d8ccb.18d5431eaeeaf288,reason=Created count=1 msg=Created container: task
0.3854,Event,ADDED,eval-conflicts-rho020-r0-015-d8ccb.18d5431eb2421a25,reason=Started count=1 msg=Started container task
0.3856,Event,ADDED,eval-conflicts-rho020-r0-015.18d5431e902eedf3,reason=SuccessfulCreate count=1 msg=Created pod: eval-conflicts-rho020-r0-015-d8ccb
0.3857,Event,ADDED,eval-conflicts-rho020-r0-015.18d54323f6453c2e,reason=Completed count=1 msg=Job completed
0.386,Event,ADDED,eval-conflicts-rho020-r0-016-dz4rg.18d5431ecc830eeb,"reason=FailedScheduling count=None msg=0/6 nodes are available: 1 c_wall violated: 1 conflicting context pair(s) with node memory, 5 node(s) had untolerated taint(s). no new claims to deallocate, preemption: 0/6 nodes are available: 1 No preemption victims found for incoming pod, 5 Preemption is not helpful for scheduling."
0.3862,Event,ADDED,eval-conflicts-rho020-r0-016-dz4rg.18d5431ecd1cd714,"reason=FailedScheduling count=None msg=0/6 nodes are available: 1 c_wall violated: 1 conflicting context pair(s) with node memory, 5 node(s) had untolerated taint(s). no new claims to deallocate, preemption: 0/6 nodes are available: 1 No preemption victims found for incoming pod, 5 Preemption is not helpful for scheduling."
0.3864,Event,ADDED,eval-conflicts-rho020-r0-016-dz4rg.18d5432359ac45dd,reason=Scheduled count=None msg=Successfully assigned compute/eval-conflicts-rho020-r0-016-dz4rg to kind-worker4
0.3867,Event,ADDED,eval-conflicts-rho020-r0-016-dz4rg.18d5432376ca2a7f,"reason=Pulled count=1 msg=Container image ""busybox:musl"" already present on machine"
0.3869,Event,ADDED,eval-conflicts-rho020-r0-016-dz4rg.18d543237ae7e3ae,reason=Created count=1 msg=Created container: task
0.387,Event,ADDED,eval-conflicts-rho020-r0-016-dz4rg.18d543237e9da180,reason=Started count=1 msg=Started container task
0.3873,Event,ADDED,eval-conflicts-rho020-r0-016.18d5431ecc3ab50c,reason=SuccessfulCreate count=1 msg=Created pod: eval-conflicts-rho020-r0-016-dz4rg
0.3874,Event,ADDED,eval-conflicts-rho020-r0-016.18d5432971ea1b7f,reason=Completed count=1 msg=Job completed
0.3876,Event,ADDED,eval-conflicts-rho020-r0-017-vgqs7.18d5431f08ee7351,reason=Scheduled count=None msg=Successfully assigned compute/eval-conflicts-rho020-r0-017-vgqs7 to kind-worker
0.3878,Event,ADDED,eval-conflicts-rho020-r0-017-vgqs7.18d5431f21ec1bca,"reason=Pulled count=1 msg=Container image ""busybox:musl"" already present on machine"
0.388,Event,ADDED,eval-conflicts-rho020-r0-017-vgqs7.18d5431f230e38d2,reason=Created count=1 msg=Created container: task
0.3882,Event,ADDED,eval-conflicts-rho020-r0-017-vgqs7.18d5431f293331be,reason=Started count=1 msg=Started container task
0.3883,Event,ADDED,eval-conflicts-rho020-r0-017.18d5431f0850c6de,reason=SuccessfulCreate count=1 msg=Created pod: eval-conflicts-rho020-r0-017-vgqs7
0.3885,Event,ADDED,eval-conflicts-rho020-r0-017.18d54324bacfca17,reason=Completed count=1 msg=Job completed
0.3887,Event,ADDED,eval-conflicts-rho020-r0-018-g5wpg.18d5431f4415422b,"reason=FailedScheduling count=None msg=0/6 nodes are available: 1 c_wall violated: 1 conflicting context pair(s) with node memory, 5 node(s) had untolerated taint(s). no new claims to deallocate, preemption: 0/6 nodes are available: 1 No preemption victims found for incoming pod, 5 Preemption is not helpful for scheduling."
0.3889,Event,ADDED,eval-conflicts-rho020-r0-018-g5wpg.18d5431f449eb5b8,"reason=FailedScheduling count=None msg=0/6 nodes are available: 1 c_wall violated: 1 conflicting context pair(s) with node memory, 5 node(s) had untolerated taint(s). no new claims to deallocate, preemption: 0/6 nodes are available: 1 No preemption victims found for incoming pod, 5 Preemption is not helpful for scheduling."
0.389,Event,ADDED,eval-conflicts-rho020-r0-018-g5wpg.18d5432359e707a8,reason=Scheduled count=None msg=Successfully assigned compute/eval-conflicts-rho020-r0-018-g5wpg to kind-worker4
0.3892,Event,ADDED,eval-conflicts-rho020-r0-018-g5wpg.18d54323782829b2,"reason=Pulled count=1 msg=Container image ""busybox:musl"" already present on machine"
0.3894,Event,ADDED,eval-conflicts-rho020-r0-018-g5wpg.18d543237b3b48e9,reason=Created count=1 msg=Created container: task
0.3895,Event,ADDED,eval-conflicts-rho020-r0-018-g5wpg.18d543237f999b58,reason=Started count=1 msg=Started container task
0.3897,Event,ADDED,eval-conflicts-rho020-r0-018.18d5431f43d525ea,reason=SuccessfulCreate count=1 msg=Created pod: eval-conflicts-rho020-r0-018-g5wpg
0.3899,Event,ADDED,eval-conflicts-rho020-r0-018.18d543290eefdf4f,reason=Completed count=1 msg=Job completed
0.39,Event,ADDED,eval-conflicts-rho020-r0-019-4wfq7.18d5431f7f3f5f49,"reason=FailedScheduling count=None msg=0/6 nodes are available: 1 c_wall violated: 1 conflicting context pair(s) with node memory, 5 node(s) had untolerated taint(s). no new claims to deallocate, preemption: 0/6 nodes are available: 1 No preemption victims found for incoming pod, 5 Preemption is not helpful for scheduling."
0.3902,Event,ADDED,eval-conflicts-rho020-r0-019-4wfq7.18d5431f7fd80d1f,"reason=FailedScheduling count=None msg=0/6 nodes are available: 1 c_wall violated: 1 conflicting context pair(s) with node memory, 5 node(s) had untolerated taint(s). no new claims to deallocate, preemption: 0/6 nodes are available: 1 No preemption victims found for incoming pod, 5 Preemption is not helpful for scheduling."
0.3903,Event,ADDED,eval-conflicts-rho020-r0-019-4wfq7.18d5432358d8817f,reason=Scheduled count=None msg=Successfully assigned compute/eval-conflicts-rho020-r0-019-4wfq7 to kind-worker4
0.3905,Event,ADDED,eval-conflicts-rho020-r0-019-4wfq7.18d5432387c4aba1,"reason=Pulled count=1 msg=Container image ""busybox:musl"" already present on machine"
0.3907,Event,ADDED,eval-conflicts-rho020-r0-019-4wfq7.18d543238a0ca7e1,reason=Created count=1 msg=Created container: task
0.3908,Event,ADDED,eval-conflicts-rho020-r0-019-4wfq7.18d543238e9b8570,reason=Started count=1 msg=Started container task
0.391,Event,ADDED,eval-conflicts-rho020-r0-019.18d5431f7f046b07,reason=SuccessfulCreate count=1 msg=Created pod: eval-conflicts-rho020-r0-019-4wfq7
0.3912,Event,ADDED,eval-conflicts-rho020-r0-019.18d543295b221993,reason=Completed count=1 msg=Job completed
0.3913,Event,ADDED,eval-conflicts-rho020-r0-020-f4lfp.18d5431fbacfcd2d,reason=Scheduled count=None msg=Successfully assigned compute/eval-conflicts-rho020-r0-020-f4lfp to kind-worker
0.3915,Event,ADDED,eval-conflicts-rho020-r0-020-f4lfp.18d5431fd4d0f6a2,"reason=Pulled count=1 msg=Container image ""busybox:musl"" already present on machine"
0.3917,Event,ADDED,eval-conflicts-rho020-r0-020-f4lfp.18d5431fd5f8f3f0,reason=Created count=1 msg=Created container: task
0.3919,Event,ADDED,eval-conflicts-rho020-r0-020-f4lfp.18d5431fdc4f9846,reason=Started count=1 msg=Started container task
0.3921,Event,ADDED,eval-conflicts-rho020-r0-020.18d5431fba4a4291,reason=SuccessfulCreate count=1 msg=Created pod: eval-conflicts-rho020-r0-020-f4lfp
0.3922,Event,ADDED,eval-conflicts-rho020-r0-020.18d543257a7f0dd5,reason=Completed count=1 msg=Job completed
0.3924,Event,ADDED,eval-conflicts-rho020-r0-021-dsgjh.18d5431ff640a3a9,"reason=FailedScheduling count=None msg=0/6 nodes are available: 1 c_wall violated: 1 conflicting context pair(s) with node memory, 5 node(s) had untolerated taint(s). no new claims to deallocate, preemption: 0/6 nodes are available: 1 No preemption victims found for incoming pod, 5 Preemption is not helpful for scheduling."
0.3926,Event,ADDED,eval-conflicts-rho020-r0-021-dsgjh.18d5431ff6ce52bf,"reason=FailedScheduling count=None msg=0/6 nodes are available: 1 c_wall violated: 1 conflicting context pair(s) with node memory, 5 node(s) had untolerated taint(s). no new claims to deallocate, preemption: 0/6 nodes are available: 1 No preemption victims found for incoming pod, 5 Preemption is not helpful for scheduling."
0.3927,Event,ADDED,eval-conflicts-rho020-r0-021-dsgjh.18d54323597ec4b0,reason=Scheduled count=None msg=Successfully assigned compute/eval-conflicts-rho020-r0-021-dsgjh to kind-worker4
0.3929,Event,ADDED,eval-conflicts-rho020-r0-021-dsgjh.18d5432375024137,"reason=Pulled count=1 msg=Container image ""busybox:musl"" already present on machine"
0.3931,Event,ADDED,eval-conflicts-rho020-r0-021-dsgjh.18d54323768cad05,reason=Created count=1 msg=Created container: task
0.3932,Event,ADDED,eval-conflicts-rho020-r0-021-dsgjh.18d543237d643c53,reason=Started count=1 msg=Started container task
0.3934,Event,ADDED,eval-conflicts-rho020-r0-021.18d5431ff5fedfb8,reason=SuccessfulCreate count=1 msg=Created pod: eval-conflicts-rho020-r0-021-dsgjh
0.3936,Event,ADDED,eval-conflicts-rho020-r0-021.18d5432983883bd7,reason=Completed count=1 msg=Job completed
0.3938,Event,ADDED,eval-conflicts-rho020-r0-022-sqqgh.18d5432032909088,reason=Scheduled count=None msg=Successfully assigned compute/eval-conflicts-rho020-r0-022-sqqgh to kind-worker
0.3941,Event,ADDED,eval-conflicts-rho020-r0-022-sqqgh.18d543204b8fe9a1,"reason=Pulled count=1 msg=Container image ""busybox:musl"" already present on machine"
0.3942,Event,ADDED,eval-conflicts-rho020-r0-022-sqqgh.18d543204cb79459,reason=Created count=1 msg=Created container: task
0.3944,Event,ADDED,eval-conflicts-rho020-r0-022-sqqgh.18d5432058418e5b,reason=Started count=1 msg=Started container task
0.3946,Event,ADDED,eval-conflicts-rho020-r0-022.18d5432031f25365,reason=SuccessfulCreate count=1 msg=Created pod: eval-conflicts-rho020-r0-022-sqqgh
0.3948,Event,ADDED,eval-conflicts-rho020-r0-022.18d54325e71aca22,reason=Completed count=1 msg=Job completed
0.3949,Event,ADDED,eval-conflicts-rho020-r0-023-j7qpz.18d543206df420c3,"reason=FailedScheduling count=None msg=0/6 nodes are available: 1 c_wall violated: 1 conflicting context pair(s) with node memory, 5 node(s) had untolerated taint(s). no new claims to deallocate, preemption: 0/6 nodes are available: 1 No preemption victims found for incoming pod, 5 Preemption is not helpful for scheduling."
0.3951,Event,ADDED,eval-conflicts-rho020-r0-023-j7qpz.18d543206e79fd41,"reason=FailedScheduling count=None msg=0/6 nodes are available: 1 c_wall violated: 1 conflicting context pair(s) with node memory, 5 node(s) had untolerated taint(s). no new claims to deallocate, preemption: 0/6 nodes are available: 1 No preemption victims found for incoming pod, 5 Preemption is not helpful for scheduling."
0.3954,Event,ADDED,eval-conflicts-rho020-r0-023-j7qpz.18d543235a2f016f,reason=Scheduled count=None msg=Successfully assigned compute/eval-conflicts-rho020-r0-023-j7qpz to kind-worker4
0.3956,Event,ADDED,eval-conflicts-rho020-r0-023-j7qpz.18d5432377804bf4,"reason=Pulled count=1 msg=Container image ""busybox:musl"" already present on machine"
0.3958,Event,ADDED,eval-conflicts-rho020-r0-023-j7qpz.18d543237b0d0481,reason=Created count=1 msg=Created container: task
0.396,Event,ADDED,eval-conflicts-rho020-r0-023-j7qpz.18d543237ef80004,reason=Started count=1 msg=Started container task
0.3961,Event,ADDED,eval-conflicts-rho020-r0-023.18d543206dad3abb,reason=SuccessfulCreate count=1 msg=Created pod: eval-conflicts-rho020-r0-023-j7qpz
0.3963,Event,ADDED,eval-conflicts-rho020-r0-023.18d54328d5222103,reason=Completed count=1 msg=Job completed
0.3965,Event,ADDED,eval-conflicts-rho020-r0-024-b6zgn.18d54320a8d0a9af,"reason=FailedScheduling count=None msg=0/6 nodes are available: 6 node(s) had untolerated taint(s). no new claims to deallocate, preemption: 0/6 nodes are available: 6 Preemption is not helpful for scheduling."
0.3967,Event,ADDED,eval-conflicts-rho020-r0-024-b6zgn.18d543235b643f03,reason=Scheduled count=None msg=Successfully assigned compute/eval-conflicts-rho020-r0-024-b6zgn to kind-worker4
0.3968,Event,ADDED,eval-conflicts-rho020-r0-024-b6zgn.18d54323786c09dd,"reason=Pulled count=1 msg=Container image ""busybox:musl"" already present on machine"
0.397,Event,ADDED,eval-conflicts-rho020-r0-024-b6zgn.18d543237b938563,reason=Created count=1 msg=Created container: task
0.3974,Event,ADDED,eval-conflicts-rho020-r0-024-b6zgn.18d543237f9562fc,reason=Started count=1 msg=Started container task
0.3976,Event,ADDED,eval-conflicts-rho020-r0-024.18d54320a8c1011b,reason=SuccessfulCreate count=1 msg=Created pod: eval-conflicts-rho020-r0-024-b6zgn
0.3978,Event,ADDED,eval-conflicts-rho020-r0-024.18d543297b9832ed,reason=Completed count=1 msg=Job completed
0.3979,Event,ADDED,eval-conflicts-rho020-r0-025-fjcgs.18d54320e4c78e72,"reason=FailedScheduling count=None msg=0/6 nodes are available: 6 node(s) had untolerated taint(s). no new claims to deallocate, preemption: 0/6 nodes are available: 6 Preemption is not helpful for scheduling."
0.3982,Event,ADDED,eval-conflicts-rho020-r0-025-fjcgs.18d543235e54ce5e,"reason=FailedScheduling count=None msg=0/6 nodes are available: 1 c_wall violated: 1 conflicting context pair(s) with node memory, 5 node(s) had untolerated taint(s). no new claims to deallocate, preemption: 0/6 nodes are available: 1 No preemption victims found for incoming pod, 5 Preemption is not helpful for scheduling."
0.3984,Event,ADDED,eval-conflicts-rho020-r0-025-fjcgs.18d5432370a72ffd,"reason=FailedScheduling count=None msg=0/6 nodes are available: 1 c_wall violated: 2 conflicting context pair(s) with node memory, 5 node(s) had untolerated taint(s). no new claims to deallocate, preemption: 0/6 nodes are available: 1 No preemption victims found for incoming pod, 5 Preemption is not helpful for scheduling."
0.3986,Event,ADDED,eval-conflicts-rho020-r0-025-fjcgs.18d543237a9d2b23,"reason=FailedScheduling count=None msg=0/6 nodes are available: 1 c_wall violated: 2 conflicting context pair(s) with node memory, 5 node(s) had untolerated taint(s). no new claims to deallocate, preemption: 0/6 nodes are available: 1 No preemption victims found for incoming pod, 5 Preemption is not helpful for scheduling."
0.3989,Event,ADDED,eval-conflicts-rho020-r0-025-fjcgs.18d54323b6eda10e,"reason=FailedScheduling count=None msg=0/6 nodes are available: 1 c_wall violated: 3 conflicting context pair(s) with node memory, 5 node(s) had untolerated taint(s). no new claims to deallocate, preemption: 0/6 nodes are available: 1 No preemption victims found for incoming pod, 5 Preemption is not helpful for scheduling."
0.3991,Event,ADDED,eval-conflicts-rho020-r0-025-fjcgs.18d54326fb154dc4,reason=Scheduled count=None msg=Successfully assigned compute/eval-conflicts-rho020-r0-025-fjcgs to kind-worker3
0.3993,Event,ADDED,eval-conflicts-rho020-r0-025-fjcgs.18d543271996ed39,"reason=Pulled count=1 msg=Container image ""busybox:musl"" already present on machine"
0.3995,Event,ADDED,eval-conflicts-rho020-r0-025-fjcgs.18d543271cd18846,reason=Created count=1 msg=Created container: task
0.3997,Event,ADDED,eval-conflicts-rho020-r0-025-fjcgs.18d543272164ff53,reason=Started count=1 msg=Started container task
0.3998,Event,ADDED,eval-conflicts-rho020-r0-025.18d54320e4bdac0a,reason=SuccessfulCreate count=1 msg=Created pod: eval-conflicts-rho020-r0-025-fjcgs
0.4,Event,ADDED,eval-conflicts-rho020-r0-025.18d5432cfe01f282,reason=Completed count=1 msg=Job completed
0.4002,Event,ADDED,eval-conflicts-rho020-r0-026-ntc75.18d5432124d938d6,"reason=FailedScheduling count=None msg=0/6 nodes are available: 6 node(s) had untolerated taint(s). no new claims to deallocate, preemption: 0/6 nodes are available: 6 Preemption is not helpful for scheduling."
0.4003,Event,ADDED,eval-conflicts-rho020-r0-026-ntc75.18d543235ee7dc01,"reason=FailedScheduling count=None msg=0/6 nodes are available: 1 c_wall violated: 1 conflicting context pair(s) with node memory, 5 node(s) had untolerated taint(s). no new claims to deallocate, preemption: 0/6 nodes are available: 1 No preemption victims found for incoming pod, 5 Preemption is not helpful for scheduling."
0.4005,Event,ADDED,eval-conflicts-rho020-r0-026-ntc75.18d54323716b9dad,"reason=FailedScheduling count=None msg=0/6 nodes are available: 1 c_wall violated: 2 conflicting context pair(s) with node memory, 5 node(s) had untolerated taint(s). no new claims to deallocate, preemption: 0/6 nodes are available: 1 No preemption victims found for incoming pod, 5 Preemption is not helpful for scheduling."
0.401,Event,ADDED,eval-conflicts-rho020-r0-026-ntc75.18d543237c20b423,"reason=FailedScheduling count=None msg=0/6 nodes are available: 1 c_wall violated: 2 conflicting context pair(s) with node memory, 5 node(s) had untolerated taint(s). no new claims to deallocate, preemption: 0/6 nodes are available: 1 No preemption victims found for incoming pod, 5 Preemption is not helpful for scheduling."
0.4011,Event,ADDED,eval-conflicts-rho020-r0-026-ntc75.18d54326fb3b6eae,reason=Scheduled count=None msg=Successfully assigned compute/eval-conflicts-rho020-r0-026-ntc75 to kind-worker3
0.4013,Event,ADDED,eval-conflicts-rho020-r0-026-ntc75.18d5432719be1b2b,"reason=Pulled count=1 msg=Container image ""busybox:musl"" already present on machine"
0.4015,Event,ADDED,eval-conflicts-rho020-r0-026-ntc75.18d543271dc28e83,reason=Created count=1 msg=Created container: task
0.4017,Event,ADDED,eval-conflicts-rho020-r0-026-ntc75.18d54327220ac36e,reason=Started count=1 msg=Started container task
0.4019,Event,ADDED,eval-conflicts-rho020-r0-026.18d5432124cc8c77,reason=SuccessfulCreate count=1 msg=Created pod: eval-conflicts-rho020-r0-026-ntc75
0.4021,Event,ADDED,eval-conflicts-rho020-r0-026.18d5432d08e3ccb0,reason=Completed count=1 msg=Job completed
0.4022,Event,ADDED,eval-conflicts-rho020-r0-027-6fkrt.18d543216086c5fb,"reason=FailedScheduling count=None msg=0/6 nodes are available: 6 node(s) had untolerated taint(s). no new claims to deallocate, preemption: 0/6 nodes are available: 6 Preemption is not helpful for scheduling."
0.4025,Event,ADDED,eval-conflicts-rho020-r0-027-6fkrt.18d543236445991c,reason=Scheduled count=None msg=Successfully assigned compute/eval-conflicts-rho020-r0-027-6fkrt to kind-worker4
0.4028,Event,ADDED,eval-conflicts-rho020-r0-027-6fkrt.18d543237eb72c53,"reason=Pulled count=1 msg=Container image ""busybox:musl"" already present on machine"
0.4031,Event,ADDED,eval-conflicts-rho020-r0-027-6fkrt.18d5432383903640,reason=Created count=1 msg=Created container: task
0.4033,Event,ADDED,eval-conflicts-rho020-r0-027-6fkrt.18d543238784fc67,reason=Started count=1 msg=Started container task
0.4035,Event,ADDED,eval-conflicts-rho020-r0-027.18d54321607d21ba,reason=SuccessfulCreate count=1 msg=Created pod: eval-conflicts-rho020-r0-027-6fkrt
0.4036,Event,ADDED,eval-conflicts-rho020-r0-027.18d5432971b17c86,reason=Completed count=1 msg=Job completed
0.4038,Event,ADDED,eval-conflicts-rho020-r0-028-2fdnl.18d543219773a0ec,"reason=FailedScheduling count=None msg=0/6 nodes are available: 6 node(s) had untolerated taint(s). no new claims to deallocate, preemption: 0/6 nodes are available: 6 Preemption is not helpful for scheduling."
0.4039,Event,ADDED,eval-conflicts-rho020-r0-028-2fdnl.18d543235fc30716,"reason=FailedScheduling count=None msg=0/6 nodes are available: 1 c_wall violated: 1 conflicting context pair(s) with node memory, 5 node(s) had untolerated taint(s). no new claims to deallocate, preemption: 0/6 nodes are available: 1 No preemption victims found for incoming pod, 5 Preemption is not helpful for scheduling."
0.4041,Event,ADDED,eval-conflicts-rho020-r0-028-2fdnl.18d54323767e032a,"reason=FailedScheduling count=None msg=0/6 nodes are available: 1 c_wall violated: 1 conflicting context pair(s) with node memory, 5 node(s) had untolerated taint(s). no new claims to deallocate, preemption: 0/6 nodes are available: 1 No preemption victims found for incoming pod, 5 Preemption is not helpful for scheduling."
0.4043,Event,ADDED,eval-conflicts-rho020-r0-028-2fdnl.18d543271b0fb87c,reason=Scheduled count=None msg=Successfully assigned compute/eval-conflicts-rho020-r0-028-2fdnl to kind-worker2
0.4045,Event,ADDED,eval-conflicts-rho020-r0-028-2fdnl.18d543273a9f8f27,"reason=Pulled count=1 msg=Container image ""busybox:musl"" already present on machine"
0.4046,Event,ADDED,eval-conflicts-rho020-r0-028-2fdnl.18d543273d716849,reason=Created count=1 msg=Created container: task
0.4048,Event,ADDED,eval-conflicts-rho020-r0-028-2fdnl.18d54327467a8844,reason=Started count=1 msg=Started container task
0.405,Event,ADDED,eval-conflicts-rho020-r0-028.18d5432197669c69,reason=SuccessfulCreate count=1 msg=Created pod: eval-conflicts-rho020-r0-028-2fdnl
0.4052,Event,ADDED,eval-conflicts-rho020-r0-028.18d5432d4a8472e0,reason=Completed count=1 msg=Job completed
0.4053,Event,ADDED,eval-conflicts-rho020-r0-029-qmnfv.18d54321d2ddca25,"reason=FailedScheduling count=None msg=0/6 nodes are available: 6 node(s) had untolerated taint(s). no new claims to deallocate, preemption: 0/6 nodes are available: 6 Preemption is not helpful for scheduling."
0.4055,Event,ADDED,eval-conflicts-rho020-r0-029-qmnfv.18d54323647aeb9a,"reason=FailedScheduling count=None msg=0/6 nodes are available: 1 c_wall violated: 1 conflicting context pair(s) with node memory, 5 node(s) had untolerated taint(s). no new claims to deallocate, preemption: 0/6 nodes are available: 1 No preemption victims found for incoming pod, 5 Preemption is not helpful for scheduling."
0.4057,Event,ADDED,eval-conflicts-rho020-r0-029-qmnfv.18d54323789ca971,"reason=FailedScheduling count=None msg=0/6 nodes are available: 1 c_wall violated: 1 conflicting context pair(s) with node memory, 5 node(s) had untolerated taint(s). no new claims to deallocate, preemption: 0/6 nodes are available: 1 No preemption victims found for incoming pod, 5 Preemption is not helpful for scheduling."
0.4058,Event,ADDED,eval-conflicts-rho020-r0-029-qmnfv.18d5432719a392e3,reason=Scheduled count=None msg=Successfully assigned compute/eval-conflicts-rho020-r0-029-qmnfv to kind-worker2
0.4061,Event,ADDED,eval-conflicts-rho020-r0-029-qmnfv.18d543273a5b7776,"reason=Pulled count=1 msg=Container image ""busybox:musl"" already present on machine"
0.4062,Event,ADDED,eval-conflicts-rho020-r0-029-qmnfv.18d543273ca51d5c,reason=Created count=1 msg=Created container: task
0.4064,Event,ADDED,eval-conflicts-rho020-r0-029-qmnfv.18d54327467d4b14,reason=Started count=1 msg=Started container task
0.4066,Event,ADDED,eval-conflicts-rho020-r0-029.18d54321d2d2ce5e,reason=SuccessfulCreate count=1 msg=Created pod: eval-conflicts-rho020-r0-029-qmnfv
0.4068,Event,ADDED,eval-conflicts-rho020-r0-029.18d5432d44722ded,reason=Completed count=1 msg=Job completed
0.407,Event,ADDED,eval-conflicts-rho020-r0-030-5f9bq.18d543220ee03962,"reason=FailedScheduling count=None msg=0/6 nodes are available: 6 node(s) had untolerated taint(s). no new claims to deallocate, preemption: 0/6 nodes are available: 6 Preemption is not helpful for scheduling."
0.4072,Event,ADDED,eval-conflicts-rho020-r0-030-5f9bq.18d543236bf54f8c,"reason=FailedScheduling count=None msg=0/6 nodes are available: 1 c_wall violated: 1 conflicting context pair(s) with node memory, 5 node(s) had untolerated taint(s). no new claims to deallocate, preemption: 0/6 nodes are available: 1 No preemption victims found for incoming pod, 5 Preemption is not helpful for scheduling."
0.4075,Event,ADDED,eval-conflicts-rho020-r0-030-5f9bq.18d5432378d5ca8f,"reason=FailedScheduling count=None msg=0/6 nodes are available: 1 c_wall violated: 1 conflicting context pair(s) with node memory, 5 node(s) had untolerated taint(s). no new claims to deallocate, preemption: 0/6 nodes are available: 1 No preemption victims found for incoming pod, 5 Preemption is not helpful for scheduling."
0.4076,Event,ADDED,eval-conflicts-rho020-r0-030-5f9bq.18d5432719d2c8e3,reason=Scheduled count=None msg=Successfully assigned compute/eval-conflicts-rho020-r0-030-5f9bq to kind-worker2
0.4078,Event,ADDED,eval-conflicts-rho020-r0-030-5f9bq.18d543273a7980ee,"reason=Pulled count=1 msg=Container image ""busybox:musl"" already present on machine"
0.408,Event,ADDED,eval-conflicts-rho020-r0-030-5f9bq.18d543273d2236a7,reason=Created count=1 msg=Created container: task
0.4082,Event,ADDED,eval-conflicts-rho020-r0-030-5f9bq.18d54327467e470b,reason=Started count=1 msg=Started container task
0.4084,Event,ADDED,eval-conflicts-rho020-r0-030.18d543220ed5eda1,reason=SuccessfulCreate count=1 msg=Created pod: eval-conflicts-rho020-r0-030-5f9bq
0.4087,Event,ADDED,eval-conflicts-rho020-r0-030.18d5432d1dc61d7b,reason=Completed count=1 msg=Job completed
0.4089,Event,ADDED,eval-conflicts-rho020-r0-031-8pbnd.18d543224a01b901,"reason=FailedScheduling count=None msg=0/6 nodes are available: 6 node(s) had untolerated taint(s). no new claims to deallocate, preemption: 0/6 nodes are available: 6 Preemption is not helpful for scheduling."
0.4091,Event,ADDED,eval-conflicts-rho020-r0-031-8pbnd.18d543236d12a646,reason=Scheduled count=None msg=Successfully assigned compute/eval-conflicts-rho020-r0-031-8pbnd to kind-worker4
0.4093,Event,ADDED,eval-conflicts-rho020-r0-031-8pbnd.18d543238ebe6dab,"reason=Pulled count=1 msg=Container image ""busybox:musl"" already present on machine"
0.4094,Event,ADDED,eval-conflicts-rho020-r0-031-8pbnd.18d543239185b32a,reason=Created count=1 msg=Created container: task
0.4096,Event,ADDED,eval-conflicts-rho020-r0-031-8pbnd.18d543239694f6aa,reason=Started count=1 msg=Started container task
0.4099,Event,ADDED,eval-conflicts-rho020-r0-031.18d5432249f7bd47,reason=SuccessfulCreate count=1 msg=Created pod: eval-conflicts-rho020-r0-031-8pbnd
0.4101,Event,ADDED,eval-conflicts-rho020-r0-031.18d543295dc2ffb4,reason=Completed count=1 msg=Job completed
0.4102,Event,ADDED,eval-conflicts-rho020-r0-032-xsvh5.18d5432287854930,"reason=FailedScheduling count=None msg=0/6 nodes are available: 6 node(s) had untolerated taint(s). no new claims to deallocate, preemption: 0/6 nodes are available: 6 Preemption is not helpful for scheduling."
0.4104,Event,ADDED,eval-conflicts-rho020-r0-032-xsvh5.18d543236d22c8f9,reason=Scheduled count=None msg=Successfully assigned compute/eval-conflicts-rho020-r0-032-xsvh5 to kind-worker4
0.4106,Event,ADDED,eval-conflicts-rho020-r0-032-xsvh5.18d543238eddb966,"reason=Pulled count=1 msg=Container image ""busybox:musl"" already present on machine"
0.4108,Event,ADDED,eval-conflicts-rho020-r0-032-xsvh5.18d5432391489baa,reason=Created count=1 msg=Created container: task
0.411,Event,ADDED,eval-conflicts-rho020-r0-032-xsvh5.18d54323967e77de,reason=Started count=1 msg=Started container task
0.4111,Event,ADDED,eval-conflicts-rho020-r0-032.18d54322877c5e76,reason=SuccessfulCreate count=1 msg=Created pod: eval-conflicts-rho020-r0-032-xsvh5
0.4113,Event,ADDED,eval-conflicts-rho020-r0-032.18d543290f54ecbb,reason=Completed count=1 msg=Job completed
0.4115,Event,ADDED,eval-conflicts-rho020-r0-033-ss9fx.18d54322c1323faf,"reason=FailedScheduling count=None msg=0/6 nodes are available: 6 node(s) had untolerated taint(s). no new claims to deallocate, preemption: 0/6 nodes are available: 6 Preemption is not helpful for scheduling."
0.4117,Event,ADDED,eval-conflicts-rho020-r0-033-ss9fx.18d543236d7d5f7c,reason=Scheduled count=None msg=Successfully assigned compute/eval-conflicts-rho020-r0-033-ss9fx to kind-worker4
0.4119,Event,ADDED,eval-conflicts-rho020-r0-033-ss9fx.18d543238f01e011,"reason=Pulled count=1 msg=Container image ""busybox:musl"" already present on machine"
0.4121,Event,ADDED,eval-conflicts-rho020-r0-033-ss9fx.18d5432391e43966,reason=Created count=1 msg=Created container: task
0.4123,Event,ADDED,eval-conflicts-rho020-r0-033-ss9fx.18d543239693f590,reason=Started count=1 msg=Started container task
0.4124,Event,ADDED,eval-conflicts-rho020-r0-033.18d54322c1263a96,reason=SuccessfulCreate count=1 msg=Created pod: eval-conflicts-rho020-r0-033-ss9fx
0.4126,Event,ADDED,eval-conflicts-rho020-r0-033.18d54328d5494fd6,reason=Completed count=1 msg=Job completed
0.4127,Event,ADDED,eval-conflicts-rho020-r0-034-ps6mb.18d5432302c439a8,"reason=FailedScheduling count=None msg=0/6 nodes are available: 6 node(s) had untolerated taint(s). no new claims to deallocate, preemption: 0/6 nodes are available: 6 Preemption is not helpful for scheduling."
0.4129,Event,ADDED,eval-conflicts-rho020-r0-034-ps6mb.18d543236d48bc44,"reason=FailedScheduling count=None msg=0/6 nodes are available: 1 c_wall violated: 2 conflicting context pair(s) with node memory, 5 node(s) had untolerated taint(s). no new claims to deallocate, preemption: 0/6 nodes are available: 1 No preemption victims found for incoming pod, 5 Preemption is not helpful for scheduling."
0.4131,Event,ADDED,eval-conflicts-rho020-r0-034-ps6mb.18d543237906439b,"reason=FailedScheduling count=None msg=0/6 nodes are available: 1 c_wall violated: 2 conflicting context pair(s) with node memory, 5 node(s) had untolerated taint(s). no new claims to deallocate, preemption: 0/6 nodes are available: 1 No preemption victims found for incoming pod, 5 Preemption is not helpful for scheduling."
0.4133,Event,ADDED,eval-conflicts-rho020-r0-034-ps6mb.18d54326f3700d10,reason=Scheduled count=None msg=Successfully assigned compute/eval-conflicts-rho020-r0-034-ps6mb to kind-worker3
0.4134,Event,ADDED,eval-conflicts-rho020-r0-034-ps6mb.18d5432722e5afc2,"reason=Pulled count=1 msg=Container image ""busybox:musl"" already present on machine"
0.4136,Event,ADDED,eval-conflicts-rho020-r0-034-ps6mb.18d5432724de7cdb,reason=Created count=1 msg=Created container: task
0.4138,Event,ADDED,eval-conflicts-rho020-r0-034-ps6mb.18d543272831bc76,reason=Started count=1 msg=Started container task
0.414,Event,ADDED,eval-conflicts-rho020-r0-034.18d5432302b81f4e,reason=SuccessfulCreate count=1 msg=Created pod: eval-conflicts-rho020-r0-034-ps6mb
0.4141,Event,ADDED,eval-conflicts-rho020-r0-034.18d5432cfdb734d4,reason=Completed count=1 msg=Job completed
0.4143,Event,ADDED,eval-conflicts-rho020-r0-035-67bk7.18d5432338818e37,"reason=FailedScheduling count=None msg=0/6 nodes are available: 6 node(s) had untolerated taint(s). no new claims to deallocate, preemption: 0/6 nodes are available: 6 Preemption is not helpful for scheduling."
0.4144,Event,ADDED,eval-conflicts-rho020-r0-035-67bk7.18d5432370bb1a9b,reason=Scheduled count=None msg=Successfully assigned compute/eval-conflicts-rho020-r0-035-67bk7 to kind-worker4
0.4146,Event,ADDED,eval-conflicts-rho020-r0-035-67bk7.18d543238ea570ff,"reason=Pulled count=1 msg=Container image ""busybox:musl"" already present on machine"
0.4148,Event,ADDED,eval-conflicts-rho020-r0-035-67bk7.18d5432390bc09c3,reason=Created count=1 msg=Created container: task
0.415,Event,ADDED,eval-conflicts-rho020-r0-035-67bk7.18d54323958f2ada,reason=Started count=1 msg=Started container task
0.4151,Event,ADDED,eval-conflicts-rho020-r0-035.18d5432338777b02,reason=SuccessfulCreate count=1 msg=Created pod: eval-conflicts-rho020-r0-035-67bk7
0.4153,Event,ADDED,eval-conflicts-rho020-r0-035.18d5432966ab6682,reason=Completed count=1 msg=Job completed
0.4155,Event,ADDED,eval-conflicts-rho020-r0-036-xx5qd.18d5432376e47983,"reason=FailedScheduling count=None msg=0/6 nodes are available: 1 c_wall violated: 1 conflicting context pair(s) with node memory, 5 node(s) had untolerated taint(s). no new claims to deallocate, preemption: 0/6 nodes are available: 1 No preemption victims found for incoming pod, 5 Preemption is not helpful for scheduling."
0.4157,Event,ADDED,eval-conflicts-rho020-r0-036-xx5qd.18d543237ead191a,"reason=FailedScheduling count=None msg=0/6 nodes are available: 1 c_wall violated: 1 conflicting context pair(s) with node memory, 5 node(s) had untolerated taint(s). no new claims to deallocate, preemption: 0/6 nodes are available: 1 No preemption victims found for incoming pod, 5 Preemption is not helpful for scheduling."
0.4159,Event,ADDED,eval-conflicts-rho020-r0-036-xx5qd.18d5432710b780c0,reason=Scheduled count=None msg=Successfully assigned compute/eval-conflicts-rho020-r0-036-xx5qd to kind-worker2
0.416,Event,ADDED,eval-conflicts-rho020-r0-036-xx5qd.18d543272a25c578,"reason=Pulled count=1 msg=Container image ""busybox:musl"" already present on machine"
0.4163,Event,ADDED,eval-conflicts-rho020-r0-036-xx5qd.18d543272b696c8f,reason=Created count=1 msg=Created container: task
0.4165,Event,ADDED,eval-conflicts-rho020-r0-036-xx5qd.18d543272da1926e,reason=Started count=1 msg=Started container task
0.4166,Event,ADDED,eval-conflicts-rho020-r0-036.18d5432374641344,reason=SuccessfulCreate count=1 msg=Created pod: eval-conflicts-rho020-r0-036-xx5qd
0.4169,Event,ADDED,eval-conflicts-rho020-r0-036.18d5432d22e20343,reason=Completed count=1 msg=Job completed
0.417,Event,ADDED,eval-conflicts-rho020-r0-037-b7m49.18d54323b0e145f0,reason=Scheduled count=None msg=Successfully assigned compute/eval-conflicts-rho020-r0-037-b7m49 to kind-worker4
0.4172,Event,ADDED,eval-conflicts-rho020-r0-037-b7m49.18d54323d32c5001,"reason=Pulled count=1 msg=Container image ""busybox:musl"" already present on machine"
0.4174,Event,ADDED,eval-conflicts-rho020-r0-037-b7m49.18d54323d4501684,reason=Created count=1 msg=Created container: task
0.4176,Event,ADDED,eval-conflicts-rho020-r0-037-b7m49.18d54323df379cac,reason=Started count=1 msg=Started container task
0.4178,Event,ADDED,eval-conflicts-rho020-r0-037.18d54323af85550a,reason=SuccessfulCreate count=1 msg=Created pod: eval-conflicts-rho020-r0-037-b7m49
0.418,Event,ADDED,eval-conflicts-rho020-r0-037.18d54329ac5851c6,reason=Completed count=1 msg=Job completed
0.4181,Event,ADDED,eval-conflicts-rho020-r0-038-4vkwd.18d543240221037b,reason=Scheduled count=None msg=Successfully assigned compute/eval-conflicts-rho020-r0-038-4vkwd to kind-worker4
0.4183,Event,ADDED,eval-conflicts-rho020-r0-038-4vkwd.18d543241cde5879,"reason=Pulled count=1 msg=Container image ""busybox:musl"" already present on machine"
0.4185,Event,ADDED,eval-conflicts-rho020-r0-038-4vkwd.18d543241def6cc0,reason=Created count=1 msg=Created container: task
0.4186,Event,ADDED,eval-conflicts-rho020-r0-038-4vkwd.18d543242257b5e9,reason=Started count=1 msg=Started container task
0.4188,Event,ADDED,eval-conflicts-rho020-r0-038.18d543240198f4f8,reason=SuccessfulCreate count=1 msg=Created pod: eval-conflicts-rho020-r0-038-4vkwd
0.419,Event,ADDED,eval-conflicts-rho020-r0-038.18d54329df337b18,reason=Completed count=1 msg=Job completed
0.4191,Event,ADDED,eval-conflicts-rho020-r0-039-b57jw.18d543242dae47fb,reason=Scheduled count=None msg=Successfully assigned compute/eval-conflicts-rho020-r0-039-b57jw to kind-worker4
0.4193,Event,ADDED,eval-conflicts-rho020-r0-039-b57jw.18d543244b254259,"reason=Pulled count=1 msg=Container image ""busybox:musl"" already present on machine"
0.4198,Event,ADDED,eval-conflicts-rho020-r0-039-b57jw.18d543244c5f8b7e,reason=Created count=1 msg=Created container: task
0.42,Event,ADDED,eval-conflicts-rho020-r0-039-b57jw.18d5432452d56580,reason=Started count=1 msg=Started container task
0.4202,Event,ADDED,eval-conflicts-rho020-r0-039.18d543242d2a49ce,reason=SuccessfulCreate count=1 msg=Created pod: eval-conflicts-rho020-r0-039-b57jw
0.4205,Event,ADDED,eval-conflicts-rho020-r0-039.18d54329d5135171,reason=Completed count=1 msg=Job completed
0.4207,Event,ADDED,eval-conflicts-rho020-r0-040-77jm4.18d5432467f0d2e0,reason=Scheduled count=None msg=Successfully assigned compute/eval-conflicts-rho020-r0-040-77jm4 to kind-worker4
0.4209,Event,ADDED,eval-conflicts-rho020-r0-040-77jm4.18d5432486431687,"reason=Pulled count=1 msg=Container image ""busybox:musl"" already present on machine"
0.4211,Event,ADDED,eval-conflicts-rho020-r0-040-77jm4.18d54324875b1824,reason=Created count=1 msg=Created container: task
0.4214,Event,ADDED,eval-conflicts-rho020-r0-040-77jm4.18d543249105188e,reason=Started count=1 msg=Started container task
0.4216,Event,ADDED,eval-conflicts-rho020-r0-040.18d54324676a8f7a,reason=SuccessfulCreate count=1 msg=Created pod: eval-conflicts-rho020-r0-040-77jm4
0.4218,Event,ADDED,eval-conflicts-rho020-r0-040.18d5432a0a72d4ab,reason=Completed count=1 msg=Job completed
0.422,Event,ADDED,eval-conflicts-rho020-r0-041-r9x6k.18d54324a79fa4cd,reason=Scheduled count=None msg=Successfully assigned compute/eval-conflicts-rho020-r0-041-r9x6k to kind-worker4
0.4224,Event,ADDED,eval-conflicts-rho020-r0-041-r9x6k.18d54324de598cdf,"reason=Pulled count=1 msg=Container image ""busybox:musl"" already present on machine"
0.4226,Event,ADDED,eval-conflicts-rho020-r0-041-r9x6k.18d54324dfb3e2ea,reason=Created count=1 msg=Created container: task
0.4227,Event,ADDED,eval-conflicts-rho020-r0-041-r9x6k.18d54324e7d5cb18,reason=Started count=1 msg=Started container task
0.4232,Event,ADDED,eval-conflicts-rho020-r0-041.18d543249e6d4679,reason=SuccessfulCreate count=1 msg=Created pod: eval-conflicts-rho020-r0-041-r9x6k
0.4234,Event,ADDED,eval-conflicts-rho020-r0-041.18d5432a75df66c2,reason=Completed count=1 msg=Job completed
0.4235,Event,ADDED,eval-conflicts-rho020-r0-042-9rptg.18d54324e08c3d9c,"reason=FailedScheduling count=None msg=0/6 nodes are available: 1 c_wall violated: 1 conflicting context pair(s) with node memory, 5 node(s) had untolerated taint(s). no new claims to deallocate, preemption: 0/6 nodes are available: 1 No preemption victims found for incoming pod, 5 Preemption is not helpful for scheduling."
0.4238,Event,ADDED,eval-conflicts-rho020-r0-042-9rptg.18d54324e118cb7c,"reason=FailedScheduling count=None msg=0/6 nodes are available: 1 c_wall violated: 1 conflicting context pair(s) with node memory, 5 node(s) had untolerated taint(s). no new claims to deallocate, preemption: 0/6 nodes are available: 1 No preemption victims found for incoming pod, 5 Preemption is not helpful for scheduling."
0.4242,Event,ADDED,eval-conflicts-rho020-r0-042-9rptg.18d5432720b5adac,reason=Scheduled count=None msg=Successfully assigned compute/eval-conflicts-rho020-r0-042-9rptg to kind-worker2
0.4244,Event,ADDED,eval-conflicts-rho020-r0-042-9rptg.18d54327468264e2,"reason=Pulled count=1 msg=Container image ""busybox:musl"" already present on machine"
0.4246,Event,ADDED,eval-conflicts-rho020-r0-042-9rptg.18d5432747c98304,reason=Created count=1 msg=Created container: task
0.4249,Event,ADDED,eval-conflicts-rho020-r0-042-9rptg.18d543275118e1c3,reason=Started count=1 msg=Started container task
0.4251,Event,ADDED,eval-conflicts-rho020-r0-042.18d54324e041ce49,reason=SuccessfulCreate count=1 msg=Created pod: eval-conflicts-rho020-r0-042-9rptg
0.4253,Event,ADDED,eval-conflicts-rho020-r0-042.18d5432d44c8575a,reason=Completed count=1 msg=Job completed
0.4254,Event,ADDED,eval-conflicts-rho020-r0-043-4p4lx.18d543251ba783c7,"reason=FailedScheduling count=None msg=0/6 nodes are available: 1 c_wall violated: 2 conflicting context pair(s) with node memory, 5 node(s) had untolerated taint(s). no new claims to deallocate, preemption: 0/6 nodes are available: 1 No preemption victims found for incoming pod, 5 Preemption is not helpful for scheduling."
0.4258,Event,ADDED,eval-conflicts-rho020-r0-043-4p4lx.18d543251fa522cc,"reason=FailedScheduling count=None msg=0/6 nodes are available: 1 c_wall violated: 2 conflicting context pair(s) with node memory, 5 node(s) had untolerated taint(s). no new claims to deallocate, preemption: 0/6 nodes are available: 1 No preemption victims found for incoming pod, 5 Preemption is not helpful for scheduling."
0.4259,Event,ADDED,eval-conflicts-rho020-r0-043-4p4lx.18d543270eaf62a7,reason=Scheduled count=None msg=Successfully assigned compute/eval-conflicts-rho020-r0-043-4p4lx to kind-worker2
0.4261,Event,ADDED,eval-conflicts-rho020-r0-043-4p4lx.18d54327296cbeb0,"reason=Pulled count=1 msg=Container image ""busybox:musl"" already present on machine"
0.4264,Event,ADDED,eval-conflicts-rho020-r0-043-4p4lx.18d543272ab345ee,reason=Created count=1 msg=Created container: task
0.4265,Event,ADDED,eval-conflicts-rho020-r0-043-4p4lx.18d543272cc72ed7,reason=Started count=1 msg=Started container task
0.4267,Event,ADDED,eval-conflicts-rho020-r0-043.18d543251b121de0,reason=SuccessfulCreate count=1 msg=Created pod: eval-conflicts-rho020-r0-043-4p4lx
0.4269,Event,ADDED,eval-conflicts-rho020-r0-043.18d5432d11d28bf4,reason=Completed count=1 msg=Job completed
0.427,Event,ADDED,eval-conflicts-rho020-r0-044-v8kqr.18d5432551c48fab,reason=Scheduled count=None msg=Successfully assigned compute/eval-conflicts-rho020-r0-044-v8kqr to kind-worker4
0.4272,Event,ADDED,eval-conflicts-rho020-r0-044-v8kqr.18d5432579f0a408,"reason=Pulled count=1 msg=Container image ""busybox:musl"" already present on machine"
0.4274,Event,ADDED,eval-conflicts-rho020-r0-044-v8kqr.18d543257b73f5b4,reason=Created count=1 msg=Created container: task
0.4276,Event,ADDED,eval-conflicts-rho020-r0-044-v8kqr.18d54325827af020,reason=Started count=1 msg=Started container task
0.4277,Event,ADDED,eval-conflicts-rho020-r0-044.18d543255136e7bc,reason=SuccessfulCreate count=1 msg=Created pod: eval-conflicts-rho020-r0-044-v8kqr
0.4279,Event,ADDED,eval-conflicts-rho020-r0-044.18d5432aebb0c9ee,reason=Completed count=1 msg=Job completed
0.428,Event,ADDED,eval-conflicts-rho020-r0-045-tl2fj.18d5432596cba595,reason=Scheduled count=None msg=Successfully assigned compute/eval-conflicts-rho020-r0-045-tl2fj to kind-worker4
0.4286,Event,ADDED,eval-conflicts-rho020-r0-045-tl2fj.18d54325b3ff8df1,"reason=Pulled count=1 msg=Container image ""busybox:musl"" already present on machine"
0.4288,Event,ADDED,eval-conflicts-rho020-r0-045-tl2fj.18d54325b51dffcc,reason=Created count=1 msg=Created container: task
0.429,Event,ADDED,eval-conflicts-rho020-r0-045-tl2fj.18d54325c2c391ca,reason=Started count=1 msg=Started container task
0.4293,Event,ADDED,eval-conflicts-rho020-r0-045.18d543258f95b81a,reason=SuccessfulCreate count=1 msg=Created pod: eval-conflicts-rho020-r0-045-tl2fj
0.4295,Event,ADDED,eval-conflicts-rho020-r0-045.18d5432b2c7bcfb0,reason=Completed count=1 msg=Job completed
0.4296,Event,ADDED,eval-conflicts-rho020-r0-046-jrdjc.18d54325ceeeec2b,reason=Scheduled count=None msg=Successfully assigned compute/eval-conflicts-rho020-r0-046-jrdjc to kind-worker4
0.4298,Event,ADDED,eval-conflicts-rho020-r0-046-jrdjc.18d54325ea1c0e0d,"reason=Pulled count=1 msg=Container image ""busybox:musl"" already present on machine"
0.4301,Event,ADDED,eval-conflicts-rho020-r0-046-jrdjc.18d54325eb3faa25,reason=Created count=1 msg=Created container: task
0.4303,Event,ADDED,eval-conflicts-rho020-r0-046-jrdjc.18d54325f4395254,reason=Started count=1 msg=Started container task
0.4305,Event,ADDED,eval-conflicts-rho020-r0-046.18d54325cd977c05,reason=SuccessfulCreate count=1 msg=Created pod: eval-conflicts-rho020-r0-046-jrdjc
0.4306,Event,ADDED,eval-conflicts-rho020-r0-046.18d5432b6cd36332,reason=Completed count=1 msg=Job completed
0.4309,Event,ADDED,eval-conflicts-rho020-r0-047-swfdn.18d54326044b3767,"reason=FailedScheduling count=None msg=0/6 nodes are available: 1 c_wall violated: 2 conflicting context pair(s) with node memory, 5 node(s) had untolerated taint(s). no new claims to deallocate, preemption: 0/6 nodes are available: 1 No preemption victims found for incoming pod, 5 Preemption is not helpful for scheduling."
0.4312,Event,ADDED,eval-conflicts-rho020-r0-047-swfdn.18d5432604f2be14,"reason=FailedScheduling count=None msg=0/6 nodes are available: 1 c_wall violated: 2 conflicting context pair(s) with node memory, 5 node(s) had untolerated taint(s). no new claims to deallocate, preemption: 0/6 nodes are available: 1 No preemption victims found for incoming pod, 5 Preemption is not helpful for scheduling."
0.4313,Event,ADDED,eval-conflicts-rho020-r0-047-swfdn.18d543270899ec67,reason=Scheduled count=None msg=Successfully assigned compute/eval-conflicts-rho020-r0-047-swfdn to kind-worker2
0.4316,Event,ADDED,eval-conflicts-rho020-r0-047-swfdn.18d5432722ba2c94,"reason=Pulled count=1 msg=Container image ""busybox:musl"" already present on machine"
0.4318,Event,ADDED,eval-conflicts-rho020-r0-047-swfdn.18d54327260f2f01,reason=Created count=1 msg=Created container: task
0.432,Event,ADDED,eval-conflicts-rho020-r0-047-swfdn.18d5432728c8c9e6,reason=Started count=1 msg=Started container task
0.4322,Event,ADDED,eval-conflicts-rho020-r0-047.18d54326037e2a12,reason=SuccessfulCreate count=1 msg=Created pod: eval-conflicts-rho020-r0-047-swfdn
0.4324,Event,ADDED,eval-conflicts-rho020-r0-047.18d5432d23c5c1d7,reason=Completed count=1 msg=Job completed
0.4325,Event,ADDED,eval-conflicts-rho020-r0-048-lgk59.18d5432641019c0b,"reason=FailedScheduling count=None msg=0/6 nodes are available: 1 c_wall violated: 1 conflicting context pair(s) with node memory, 5 node(s) had untolerated taint(s). no new claims to deallocate, preemption: 0/6 nodes are available: 1 No preemption victims found for incoming pod, 5 Preemption is not helpful for scheduling."
0.4327,Event,ADDED,eval-conflicts-rho020-r0-048-lgk59.18d54326418e07ee,"reason=FailedScheduling count=None msg=0/6 nodes are available: 1 c_wall violated: 1 conflicting context pair(s) with node memory, 5 node(s) had untolerated taint(s). no new claims to deallocate, preemption: 0/6 nodes are available: 1 No preemption victims found for incoming pod, 5 Preemption is not helpful for scheduling."
0.4329,Event,ADDED,eval-conflicts-rho020-r0-048-lgk59.18d5432709215c7f,reason=Scheduled count=None msg=Successfully assigned compute/eval-conflicts-rho020-r0-048-lgk59 to kind-worker2
0.4331,Event,ADDED,eval-conflicts-rho020-r0-048-lgk59.18d54327234af5c2,"reason=Pulled count=1 msg=Container image ""busybox:musl"" already present on machine"
0.4333,Event,ADDED,eval-conflicts-rho020-r0-048-lgk59.18d5432726a8ca0e,reason=Created count=1 msg=Created container: task
0.4335,Event,ADDED,eval-conflicts-rho020-r0-048-lgk59.18d54327296717ed,reason=Started count=1 msg=Started container task
0.4336,Event,ADDED,eval-conflicts-rho020-r0-048.18d5432640aab6a5,reason=SuccessfulCreate count=1 msg=Created pod: eval-conflicts-rho020-r0-048-lgk59
0.4338,Event,ADDED,eval-conflicts-rho020-r0-048.18d5432d1dee584f,reason=Completed count=1 msg=Job completed
0.4339,Event,ADDED,eval-conflicts-rho020-r0-049-9lzcm.18d543267d944c48,reason=Scheduled count=None msg=Successfully assigned compute/eval-conflicts-rho020-r0-049-9lzcm to kind-worker4
0.4342,Event,ADDED,eval-conflicts-rho020-r0-049-9lzcm.18d543269e613666,"reason=Pulled count=1 msg=Container image ""busybox:musl"" already present on machine"
0.4344,Event,ADDED,eval-conflicts-rho020-r0-049-9lzcm.18d543269f856b29,reason=Created count=1 msg=Created container: task
0.4346,Event,ADDED,eval-conflicts-rho020-r0-049-9lzcm.18d54326a8df4d1b,reason=Started count=1 msg=Started container task
0.4349,Event,ADDED,eval-conflicts-rho020-r0-049.18d543267d0ca7b1,reason=SuccessfulCreate count=1 msg=Created pod: eval-conflicts-rho020-r0-049-9lzcm
0.4351,Event,ADDED,eval-conflicts-rho020-r0-049.18d5432c1b929118,reason=Completed count=1 msg=Job completed
0.4352,Event,ADDED,eval-conflicts-rho020-r0-050-rvz7x.18d54326bd5f575c,reason=Scheduled count=None msg=Successfully assigned compute/eval-conflicts-rho020-r0-050-rvz7x to kind-worker4
0.4354,Event,ADDED,eval-conflicts-rho020-r0-050-rvz7x.18d54326d88721e1,"reason=Pulled count=1 msg=Container image ""busybox:musl"" already present on machine"
0.4357,Event,ADDED,eval-conflicts-rho020-r0-050-rvz7x.18d54326d9b0be6d,reason=Created count=1 msg=Created container: task
0.4358,Event,ADDED,eval-conflicts-rho020-r0-050-rvz7x.18d54326e130262f,reason=Started count=1 msg=Started container task
0.4361,Event,ADDED,eval-conflicts-rho020-r0-050.18d54326bae87014,reason=SuccessfulCreate count=1 msg=Created pod: eval-conflicts-rho020-r0-050-rvz7x
0.4363,Event,ADDED,eval-conflicts-rho020-r0-050.18d5432c58ccd0a6,reason=Completed count=1 msg=Job completed
0.4365,Event,ADDED,eval-conflicts-rho020-r0-051-pc9hp.18d54326f3c6da91,reason=Scheduled count=None msg=Successfully assigned compute/eval-conflicts-rho020-r0-051-pc9hp to kind-worker3
0.4366,Event,ADDED,eval-conflicts-rho020-r0-051-pc9hp.18d54327230de96e,"reason=Pulled count=1 msg=Container image ""busybox:musl"" already present on machine"
0.4368,Event,ADDED,eval-conflicts-rho020-r0-051-pc9hp.18d543272552a2fb,reason=Created count=1 msg=Created container: task
0.437,Event,ADDED,eval-conflicts-rho020-r0-051-pc9hp.18d5432728988a7b,reason=Started count=1 msg=Started container task
0.4371,Event,ADDED,eval-conflicts-rho020-r0-051.18d54326f2d0201d,reason=SuccessfulCreate count=1 msg=Created pod: eval-conflicts-rho020-r0-051-pc9hp
0.4373,Event,ADDED,eval-conflicts-rho020-r0-051.18d5432c5b3c120b,reason=Completed count=1 msg=Job completed
0.4375,Event,ADDED,eval-conflicts-rho020-r0-052-7zq4d.18d543272f1459eb,reason=Scheduled count=None msg=Successfully assigned compute/eval-conflicts-rho020-r0-052-7zq4d to kind-worker3
0.4377,Event,ADDED,eval-conflicts-rho020-r0-052-7zq4d.18d54327511e6e69,"reason=Pulled count=1 msg=Container image ""busybox:musl"" already present on machine"
0.4378,Event,ADDED,eval-conflicts-rho020-r0-052-7zq4d.18d5432752628012,reason=Created count=1 msg=Created container: task
0.438,Event,ADDED,eval-conflicts-rho020-r0-052-7zq4d.18d5432757305363,reason=Started count=1 msg=Started container task
0.4382,Event,ADDED,eval-conflicts-rho020-r0-052.18d543272dca74fc,reason=SuccessfulCreate count=1 msg=Created pod: eval-conflicts-rho020-r0-052-7zq4d
0.4384,Event,ADDED,eval-conflicts-rho020-r0-052.18d5432d5c47a90f,reason=Completed count=1 msg=Job completed
0.4386,Event,ADDED,eval-conflicts-rho020-r0-053-72wdw.18d543276ac32fa6,reason=Scheduled count=None msg=Successfully assigned compute/eval-conflicts-rho020-r0-053-72wdw to kind-worker4
0.4387,Event,ADDED,eval-conflicts-rho020-r0-053-72wdw.18d5432783ff9041,"reason=Pulled count=1 msg=Container image ""busybox:musl"" already present on machine"
0.439,Event,ADDED,eval-conflicts-rho020-r0-053-72wdw.18d54327852853b0,reason=Created count=1 msg=Created container: task
0.4392,Event,ADDED,eval-conflicts-rho020-r0-053-72wdw.18d543278b2f213a,reason=Started count=1 msg=Started container task
0.4393,Event,ADDED,eval-conflicts-rho020-r0-053.18d5432769d6489c,reason=SuccessfulCreate count=1 msg=Created pod: eval-conflicts-rho020-r0-053-72wdw
0.4395,Event,ADDED,eval-conflicts-rho020-r0-053.18d5432d97f7f860,reason=Completed count=1 msg=Job completed
0.44,Event,ADDED,eval-conflicts-rho020-r0-054-jkg7l.18d54327a66c65a1,reason=Scheduled count=None msg=Successfully assigned compute/eval-conflicts-rho020-r0-054-jkg7l to kind-worker3
0.4402,Event,ADDED,eval-conflicts-rho020-r0-054-jkg7l.18d54327c3f7abd1,"reason=Pulled count=1 msg=Container image ""busybox:musl"" already present on machine"
0.4404,Event,ADDED,eval-conflicts-rho020-r0-054-jkg7l.18d54327c543fdf9,reason=Created count=1 msg=Created container: task
0.4407,Event,ADDED,eval-conflicts-rho020-r0-054-jkg7l.18d54327ca802467,reason=Started count=1 msg=Started container task
0.4409,Event,ADDED,eval-conflicts-rho020-r0-054.18d54327a5389445,reason=SuccessfulCreate count=1 msg=Created pod: eval-conflicts-rho020-r0-054-jkg7l
0.441,Event,ADDED,eval-conflicts-rho020-r0-054.18d5432d6b4a682d,reason=Completed count=1 msg=Job completed
0.4412,Event,ADDED,eval-conflicts-rho020-r0-055-hrfbl.18d54327e2015a54,reason=Scheduled count=None msg=Successfully assigned compute/eval-conflicts-rho020-r0-055-hrfbl to kind-worker3
0.4415,Event,ADDED,eval-conflicts-rho020-r0-055-hrfbl.18d54327ff9c35cc,"reason=Pulled count=1 msg=Container image ""busybox:musl"" already present on machine"
0.4416,Event,ADDED,eval-conflicts-rho020-r0-055-hrfbl.18d5432800c653f7,reason=Created count=1 msg=Created container: task
0.4418,Event,ADDED,eval-conflicts-rho020-r0-055-hrfbl.18d54328052e35f8,reason=Started count=1 msg=Started container task
0.442,Event,ADDED,eval-conflicts-rho020-r0-055.18d54327e0d2002a,reason=SuccessfulCreate count=1 msg=Created pod: eval-conflicts-rho020-r0-055-hrfbl
0.4422,Event,ADDED,eval-conflicts-rho020-r0-055.18d5432d976b72f3,reason=Completed count=1 msg=Job completed
0.4424,Event,ADDED,eval-conflicts-rho020-r0-056-xk5lk.18d543281c6c1276,reason=Scheduled count=None msg=Successfully assigned compute/eval-conflicts-rho020-r0-056-xk5lk to kind-worker5
0.4425,Event,ADDED,eval-conflicts-rho020-r0-056-xk5lk.18d543284ec9021b,"reason=Pulled count=1 msg=Container image ""busybox:musl"" already present on machine"
0.4427,Event,ADDED,eval-conflicts-rho020-r0-056-xk5lk.18d543284fe01745,reason=Created count=1 msg=Created container: task
0.4429,Event,ADDED,eval-conflicts-rho020-r0-056-xk5lk.18d54328553693f0,reason=Started count=1 msg=Started container task
0.4431,Event,ADDED,eval-conflicts-rho020-r0-056.18d543281bbdec14,reason=SuccessfulCreate count=1 msg=Created pod: eval-conflicts-rho020-r0-056-xk5lk
0.4432,Event,ADDED,eval-conflicts-rho020-r0-056.18d5432dcd9e5771,reason=Completed count=1 msg=Job completed
0.4434,Event,ADDED,eval-conflicts-rho020-r0-057-s86v9.18d5432858bfcab8,reason=Scheduled count=None msg=Successfully assigned compute/eval-conflicts-rho020-r0-057-s86v9 to kind-worker5
0.4436,Event,ADDED,eval-conflicts-rho020-r0-057-s86v9.18d54328781435ca,"reason=Pulled count=1 msg=Container image ""busybox:musl"" already present on machine"
0.4437,Event,ADDED,eval-conflicts-rho020-r0-057-s86v9.18d543287953a2e9,reason=Created count=1 msg=Created container: task
0.4439,Event,ADDED,eval-conflicts-rho020-r0-057-s86v9.18d543287dd2ce92,reason=Started count=1 msg=Started container task
0.4441,Event,ADDED,eval-conflicts-rho020-r0-057.18d5432857958d35,reason=SuccessfulCreate count=1 msg=Created pod: eval-conflicts-rho020-r0-057-s86v9
0.4443,Event,ADDED,eval-conflicts-rho020-r0-057.18d5432e0e844971,reason=Completed count=1 msg=Job completed
0.4444,Event,ADDED,eval-conflicts-rho020-r0-058-l4nhm.18d5432899d070ad,reason=Scheduled count=None msg=Successfully assigned compute/eval-conflicts-rho020-r0-058-l4nhm to kind-worker3
0.4446,Event,ADDED,eval-conflicts-rho020-r0-058-l4nhm.18d54328b77469be,"reason=Pulled count=1 msg=Container image ""busybox:musl"" already present on machine"
0.4448,Event,ADDED,eval-conflicts-rho020-r0-058-l4nhm.18d54328b87cdbcc,reason=Created count=1 msg=Created container: task
0.4449,Event,ADDED,eval-conflicts-rho020-r0-058-l4nhm.18d54328bbee4ff6,reason=Started count=1 msg=Started container task
0.4451,Event,ADDED,eval-conflicts-rho020-r0-058.18d5432898e857ad,reason=SuccessfulCreate count=1 msg=Created pod: eval-conflicts-rho020-r0-058-l4nhm
0.4453,Event,ADDED,eval-conflicts-rho020-r0-058.18d5432e3d17a896,reason=Completed count=1 msg=Job completed
0.4454,Event,ADDED,eval-conflicts-rho020-r0-059-znrxv.18d54328cffdda27,reason=Scheduled count=None msg=Successfully assigned compute/eval-conflicts-rho020-r0-059-znrxv to kind-worker5
0.4456,Event,ADDED,eval-conflicts-rho020-r0-059-znrxv.18d54328eb13701c,"reason=Pulled count=1 msg=Container image ""busybox:musl"" already present on machine"
0.4457,Event,ADDED,eval-conflicts-rho020-r0-059-znrxv.18d54328ec98e090,reason=Created count=1 msg=Created container: task
0.4459,Event,ADDED,eval-conflicts-rho020-r0-059-znrxv.18d54328f00aed51,reason=Started count=1 msg=Started container task
0.4461,Event,ADDED,eval-conflicts-rho020-r0-059.18d54328cebe1716,reason=SuccessfulCreate count=1 msg=Created pod: eval-conflicts-rho020-r0-059-znrxv
0.4462,Event,ADDED,eval-conflicts-rho020-r0-059.18d5432e701cca49,reason=Completed count=1 msg=Job completed
0.4464,Event,ADDED,eval-conflicts-rho020-r0-060-vw52p.18d543290ca270c9,reason=Scheduled count=None msg=Successfully assigned compute/eval-conflicts-rho020-r0-060-vw52p to kind-worker5
0.4466,Event,ADDED,eval-conflicts-rho020-r0-060-vw52p.18d543292902a727,"reason=Pulled count=1 msg=Container image ""busybox:musl"" already present on machine"
0.4468,Event,ADDED,eval-conflicts-rho020-r0-060-vw52p.18d543292a1e1ab7,reason=Created count=1 msg=Created container: task
0.447,Event,ADDED,eval-conflicts-rho020-r0-060-vw52p.18d5432931326a89,reason=Started count=1 msg=Started container task
0.4473,Event,ADDED,eval-conflicts-rho020-r0-060.18d543290b18b6e7,reason=SuccessfulCreate count=1 msg=Created pod: eval-conflicts-rho020-r0-060-vw52p
0.4474,Event,ADDED,eval-conflicts-rho020-r0-060.18d5432eadfe4d82,reason=Completed count=1 msg=Job completed
0.4476,Event,ADDED,eval-conflicts-rho020-r0-061-6jptd.18d543294a663cd1,reason=Scheduled count=None msg=Successfully assigned compute/eval-conflicts-rho020-r0-061-6jptd to kind-worker5
0.4479,Event,ADDED,eval-conflicts-rho020-r0-061-6jptd.18d54329660f0990,"reason=Pulled count=1 msg=Container image ""busybox:musl"" already present on machine"
0.4481,Event,ADDED,eval-conflicts-rho020-r0-061-6jptd.18d543296766996a,reason=Created count=1 msg=Created container: task
0.4483,Event,ADDED,eval-conflicts-rho020-r0-061-6jptd.18d5432971936c4f,reason=Started count=1 msg=Started container task
0.4485,Event,ADDED,eval-conflicts-rho020-r0-061.18d543294919b822,reason=SuccessfulCreate count=1 msg=Created pod: eval-conflicts-rho020-r0-061-6jptd
0.4487,Event,ADDED,eval-conflicts-rho020-r0-061.18d5432ef0fe886e,reason=Completed count=1 msg=Job completed
0.4488,Event,ADDED,eval-conflicts-rho020-r0-062-65tjn.18d543299030b108,reason=Scheduled count=None msg=Successfully assigned compute/eval-conflicts-rho020-r0-062-65tjn to kind-worker2
0.449,Event,ADDED,eval-conflicts-rho020-r0-062-65tjn.18d54329ac567bc5,"reason=Pulled count=1 msg=Container image ""busybox:musl"" already present on machine"
0.4492,Event,ADDED,eval-conflicts-rho020-r0-062-65tjn.18d54329ad931e5f,reason=Created count=1 msg=Created container: task
0.4494,Event,ADDED,eval-conflicts-rho020-r0-062-65tjn.18d54329b4007a3d,reason=Started count=1 msg=Started container task
0.4495,Event,ADDED,eval-conflicts-rho020-r0-062.18d543298f1b208b,reason=SuccessfulCreate count=1 msg=Created pod: eval-conflicts-rho020-r0-062-65tjn
0.4497,Event,ADDED,eval-conflicts-rho020-r0-062.18d5432f45b13393,reason=Completed count=1 msg=Job completed
0.4499,Event,ADDED,eval-conflicts-rho020-r0-063-jfjgn.18d54329be94532f,reason=Scheduled count=None msg=Successfully assigned compute/eval-conflicts-rho020-r0-063-jfjgn to kind-worker2
0.4501,Event,ADDED,eval-conflicts-rho020-r0-063-jfjgn.18d54329df56910e,"reason=Pulled count=1 msg=Container image ""busybox:musl"" already present on machine"
0.4503,Event,ADDED,eval-conflicts-rho020-r0-063-jfjgn.18d54329e08b085a,reason=Created count=1 msg=Created container: task
0.4504,Event,ADDED,eval-conflicts-rho020-r0-063-jfjgn.18d54329e55f110b,reason=Started count=1 msg=Started container task
0.4506,Event,ADDED,eval-conflicts-rho020-r0-063.18d54329bd76e56b,reason=SuccessfulCreate count=1 msg=Created pod: eval-conflicts-rho020-r0-063-jfjgn
0.4508,Event,ADDED,eval-conflicts-rho020-r0-063.18d5432f848f2ab6,reason=Completed count=1 msg=Job completed
0.4509,Event,ADDED,eval-conflicts-rho020-r0-064-clfkz.18d5432a006bde05,reason=Scheduled count=None msg=Successfully assigned compute/eval-conflicts-rho020-r0-064-clfkz to kind-worker
0.4511,Event,ADDED,eval-conflicts-rho020-r0-064-clfkz.18d5432a18ca5e1c,"reason=Pulled count=1 msg=Container image ""busybox:musl"" already present on machine"
0.4513,Event,ADDED,eval-conflicts-rho020-r0-064-clfkz.18d5432a19dbcf81,reason=Created count=1 msg=Created container: task
0.4514,Event,ADDED,eval-conflicts-rho020-r0-064-clfkz.18d5432a22b0d66f,reason=Started count=1 msg=Started container task
0.4516,Event,ADDED,eval-conflicts-rho020-r0-064.18d54329ff336f65,reason=SuccessfulCreate count=1 msg=Created pod: eval-conflicts-rho020-r0-064-clfkz
0.4518,Event,ADDED,eval-conflicts-rho020-r0-064.18d5432fbd0492ad,reason=Completed count=1 msg=Job completed
0.4519,Event,ADDED,eval-conflicts-rho020-r0-065-ddnqf.18d5432a36c31b17,reason=Scheduled count=None msg=Successfully assigned compute/eval-conflicts-rho020-r0-065-ddnqf to kind-worker
0.4521,Event,ADDED,eval-conflicts-rho020-r0-065-ddnqf.18d5432a55766a54,"reason=Pulled count=1 msg=Container image ""busybox:musl"" already present on machine"
0.4522,Event,ADDED,eval-conflicts-rho020-r0-065-ddnqf.18d5432a568c3f42,reason=Created count=1 msg=Created container: task
0.4524,Event,ADDED,eval-conflicts-rho020-r0-065-ddnqf.18d5432a587fef7f,reason=Started count=1 msg=Started container task
0.4526,Event,ADDED,eval-conflicts-rho020-r0-065.18d5432a356ba0bf,reason=SuccessfulCreate count=1 msg=Created pod: eval-conflicts-rho020-r0-065-ddnqf
0.4528,Event,ADDED,eval-conflicts-rho020-r0-065.18d5432fecd1b889,reason=Completed count=1 msg=Job completed
0.4529,Event,ADDED,eval-conflicts-rho020-r0-066-qknjq.18d5432a70fbc9e6,"reason=FailedScheduling count=None msg=0/6 nodes are available: 1 c_wall violated: 2 conflicting context pair(s) with node memory, 2 node(s) had untolerated taint(s), 3 c_wall violated: 1 conflicting context pair(s) with node memory. no new claims to deallocate, preemption: 0/6 nodes are available: 2 Preemption is not helpful for scheduling, 4 No preemption victims found for incoming pod."
0.4531,Event,ADDED,eval-conflicts-rho020-r0-066-qknjq.18d5432a76ea054f,"reason=FailedScheduling count=None msg=0/6 nodes are available: 1 c_wall violated: 2 conflicting context pair(s) with node memory, 2 node(s) had untolerated taint(s), 3 c_wall violated: 1 conflicting context pair(s) with node memory. no new claims to deallocate, preemption: 0/6 nodes are available: 2 Preemption is not helpful for scheduling, 4 No preemption victims found for incoming pod."
0.4533,Event,ADDED,eval-conflicts-rho020-r0-066-qknjq.18d5432ba793d74b,"reason=FailedScheduling count=None msg=0/6 nodes are available: 1 c_wall violated: 2 conflicting context pair(s) with node memory, 2 c_wall violated: 1 conflicting context pair(s) with node memory, 3 node(s) had untolerated taint(s). no new claims to deallocate, preemption: 0/6 nodes are available: 3 No preemption victims found for incoming pod, 3 Preemption is not helpful for scheduling."
0.4535,Event,ADDED,eval-conflicts-rho020-r0-066-qknjq.18d5432bb2748447,"reason=FailedScheduling count=None msg=0/6 nodes are available: 2 c_wall violated: 1 conflicting context pair(s) with node memory, 4 node(s) had untolerated taint(s). no new claims to deallocate, preemption: 0/6 nodes are available: 2 No preemption victims found for incoming pod, 4 Preemption is not helpful for scheduling."
0.4537,Event,ADDED,eval-conflicts-rho020-r0-066-qknjq.18d5432c1dd57fa2,"reason=FailedScheduling count=None msg=0/6 nodes are available: 1 c_wall violated: 1 conflicting context pair(s) with node memory, 1 c_wall violated: 2 conflicting context pair(s) with node memory, 4 node(s) had untolerated taint(s). no new claims to deallocate, preemption: 0/6 nodes are available: 2 No preemption victims found for incoming pod, 4 Preemption is not helpful for scheduling."
0.4538,Event,ADDED,eval-conflicts-rho020-r0-066-qknjq.18d5432cc8904866,"reason=FailedScheduling count=None msg=0/6 nodes are available: 1 c_wall violated: 2 conflicting context pair(s) with node memory, 5 node(s) had untolerated taint(s). no new claims to deallocate, preemption: 0/6 nodes are available: 1 No preemption victims found for incoming pod, 5 Preemption is not helpful for scheduling."
0.454,Event,ADDED,eval-conflicts-rho020-r0-066-qknjq.18d5432cceb8b087,reason=Scheduled count=None msg=Successfully assigned compute/eval-conflicts-rho020-r0-066-qknjq to kind-worker4
0.4542,Event,ADDED,eval-conflicts-rho020-r0-066-qknjq.18d5432cefd0992d,"reason=Pulled count=1 msg=Container image ""busybox:musl"" already present on machine"
0.4544,Event,ADDED,eval-conflicts-rho020-r0-066-qknjq.18d5432cf0feb5d1,reason=Created count=1 msg=Created container: task
0.4547,Event,ADDED,eval-conflicts-rho020-r0-066-qknjq.18d5432cf3136c7e,reason=Started count=1 msg=Started container task
0.4549,Event,ADDED,eval-conflicts-rho020-r0-066.18d5432a700f6727,reason=SuccessfulCreate count=1 msg=Created pod: eval-conflicts-rho020-r0-066-qknjq
0.4551,Event,ADDED,eval-conflicts-rho020-r0-066.18d543322f006948,reason=Completed count=1 msg=Job completed
0.4553,Event,ADDED,eval-conflicts-rho020-r0-067-46wxf.18d5432aad35ec1b,reason=Scheduled count=None msg=Successfully assigned compute/eval-conflicts-rho020-r0-067-46wxf to kind-worker
0.4555,Event,ADDED,eval-conflicts-rho020-r0-067-46wxf.18d5432ad278207b,"reason=Pulled count=1 msg=Container image ""busybox:musl"" already present on machine"
0.4558,Event,ADDED,eval-conflicts-rho020-r0-067-46wxf.18d5432ad38cb2f1,reason=Created count=1 msg=Created container: task
0.456,Event,ADDED,eval-conflicts-rho020-r0-067-46wxf.18d5432addd8e44e,reason=Started count=1 msg=Started container task
0.4562,Event,ADDED,eval-conflicts-rho020-r0-067.18d5432aabbdbcc0,reason=SuccessfulCreate count=1 msg=Created pod: eval-conflicts-rho020-r0-067-46wxf
0.4563,Event,ADDED,eval-conflicts-rho020-r0-067.18d54330651e759a,reason=Completed count=1 msg=Job completed
0.4565,Event,ADDED,eval-conflicts-rho020-r0-068-d4xjl.18d5432ae8c7dceb,reason=Scheduled count=None msg=Successfully assigned compute/eval-conflicts-rho020-r0-068-d4xjl to kind-worker
0.4567,Event,ADDED,eval-conflicts-rho020-r0-068-d4xjl.18d5432b03912b5b,"reason=Pulled count=1 msg=Container image ""busybox:musl"" already present on machine"
0.4568,Event,ADDED,eval-conflicts-rho020-r0-068-d4xjl.18d5432b04bafa04,reason=Created count=1 msg=Created container: task
0.457,Event,ADDED,eval-conflicts-rho020-r0-068-d4xjl.18d5432b091963fe,reason=Started count=1 msg=Started container task
0.4572,Event,ADDED,eval-conflicts-rho020-r0-068.18d5432ae76b8db5,reason=SuccessfulCreate count=1 msg=Created pod: eval-conflicts-rho020-r0-068-d4xjl
0.4573,Event,ADDED,eval-conflicts-rho020-r0-068.18d543309ee310a4,reason=Completed count=1 msg=Job completed
0.4575,Event,ADDED,eval-conflicts-rho020-r0-069-zfhlk.18d5432b2509151a,reason=Scheduled count=None msg=Successfully assigned compute/eval-conflicts-rho020-r0-069-zfhlk to kind-worker
0.4576,Event,ADDED,eval-conflicts-rho020-r0-069-zfhlk.18d5432b462eabd2,"reason=Pulled count=1 msg=Container image ""busybox:musl"" already present on machine"
0.4578,Event,ADDED,eval-conflicts-rho020-r0-069-zfhlk.18d5432b4756be8f,reason=Created count=1 msg=Created container: task
0.458,Event,ADDED,eval-conflicts-rho020-r0-069-zfhlk.18d5432b4fa2ea8e,reason=Started count=1 msg=Started container task
0.4581,Event,ADDED,eval-conflicts-rho020-r0-069.18d5432b23a7753c,reason=SuccessfulCreate count=1 msg=Created pod: eval-conflicts-rho020-r0-069-zfhlk
0.4583,Event,ADDED,eval-conflicts-rho020-r0-069.18d543309fdce334,reason=Completed count=1 msg=Job completed
0.4585,Event,ADDED,eval-conflicts-rho020-r0-070-sv277.18d5432b62e0c134,"reason=FailedScheduling count=None msg=0/6 nodes are available: 1 c_wall violated: 2 conflicting context pair(s) with node memory, 2 node(s) had untolerated taint(s), 3 c_wall violated: 1 conflicting context pair(s) with node memory. no new claims to deallocate, preemption: 0/6 nodes are available: 2 Preemption is not helpful for scheduling, 4 No preemption victims found for incoming pod."
0.4587,Event,ADDED,eval-conflicts-rho020-r0-070-sv277.18d5432b6b7c234e,"reason=FailedScheduling count=None msg=0/6 nodes are available: 1 c_wall violated: 2 conflicting context pair(s) with node memory, 2 node(s) had untolerated taint(s), 3 c_wall violated: 1 conflicting context pair(s) with node memory. no new claims to deallocate, preemption: 0/6 nodes are available: 2 Preemption is not helpful for scheduling, 4 No preemption victims found for incoming pod."
0.4588,Event,ADDED,eval-conflicts-rho020-r0-070-sv277.18d5432bac978d20,"reason=FailedScheduling count=None msg=0/6 nodes are available: 1 c_wall violated: 2 conflicting context pair(s) with node memory, 2 c_wall violated: 1 conflicting context pair(s) with node memory, 3 node(s) had untolerated taint(s). no new claims to deallocate, preemption: 0/6 nodes are available: 3 No preemption victims found for incoming pod, 3 Preemption is not helpful for scheduling."
0.459,Event,ADDED,eval-conflicts-rho020-r0-070-sv277.18d5432bb2bfd0b3,"reason=FailedScheduling count=None msg=0/6 nodes are available: 2 c_wall violated: 1 conflicting context pair(s) with node memory, 4 node(s) had untolerated taint(s). no new claims to deallocate, preemption: 0/6 nodes are available: 2 No preemption victims found for incoming pod, 4 Preemption is not helpful for scheduling."
0.4592,Event,ADDED,eval-conflicts-rho020-r0-070-sv277.18d5432c1e21a3e9,"reason=FailedScheduling count=None msg=0/6 nodes are available: 1 c_wall violated: 1 conflicting context pair(s) with node memory, 1 c_wall violated: 2 conflicting context pair(s) with node memory, 4 node(s) had untolerated taint(s). no new claims to deallocate, preemption: 0/6 nodes are available: 2 No preemption victims found for incoming pod, 4 Preemption is not helpful for scheduling."
0.4594,Event,ADDED,eval-conflicts-rho020-r0-070-sv277.18d5432cc83f515f,"reason=FailedScheduling count=None msg=0/6 nodes are available: 1 c_wall violated: 2 conflicting context pair(s) with node memory, 5 node(s) had untolerated taint(s). no new claims to deallocate, preemption: 0/6 nodes are available: 1 No preemption victims found for incoming pod, 5 Preemption is not helpful for scheduling."
0.4595,Event,ADDED,eval-conflicts-rho020-r0-070-sv277.18d5432ccc57e9e8,reason=Scheduled count=None msg=Successfully assigned compute/eval-conflicts-rho020-r0-070-sv277 to kind-worker4
0.4599,Event,ADDED,eval-conflicts-rho020-r0-070-sv277.18d5432ce9b782df,"reason=Pulled count=1 msg=Container image ""busybox:musl"" already present on machine"
0.4601,Event,ADDED,eval-conflicts-rho020-r0-070-sv277.18d5432ceb915921,reason=Created count=1 msg=Created container: task
0.4603,Event,ADDED,eval-conflicts-rho020-r0-070-sv277.18d5432cefc979e0,reason=Started count=1 msg=Started container task
0.4606,Event,ADDED,eval-conflicts-rho020-r0-070.18d5432b611c9a34,reason=SuccessfulCreate count=1 msg=Created pod: eval-conflicts-rho020-r0-070-sv277
0.4607,Event,ADDED,eval-conflicts-rho020-r0-070.18d543322f0173c6,reason=Completed count=1 msg=Job completed
0.4609,Event,ADDED,eval-conflicts-rho020-r0-071-5hchd.18d5432ba2bce0e0,reason=Scheduled count=None msg=Successfully assigned compute/eval-conflicts-rho020-r0-071-5hchd to kind-worker2
0.4611,Event,ADDED,eval-conflicts-rho020-r0-071-5hchd.18d5432bbf03a897,"reason=Pulled count=1 msg=Container image ""busybox:musl"" already present on machine"
0.4612,Event,ADDED,eval-conflicts-rho020-r0-071-5hchd.18d5432bc015fcf1,reason=Created count=1 msg=Created container: task
0.4614,Event,ADDED,eval-conflicts-rho020-r0-071-5hchd.18d5432bc3b475b6,reason=Started count=1 msg=Started container task
0.4616,Event,ADDED,eval-conflicts-rho020-r0-071.18d5432b9bd0913e,reason=SuccessfulCreate count=1 msg=Created pod: eval-conflicts-rho020-r0-071-5hchd
0.4619,Event,ADDED,eval-conflicts-rho020-r0-071.18d5433126cf2b58,reason=Completed count=1 msg=Job completed
0.4621,Event,ADDED,eval-conflicts-rho020-r0-072-dzs95.18d5432bd6101c79,"reason=FailedScheduling count=None msg=0/6 nodes are available: 2 c_wall violated: 1 conflicting context pair(s) with node memory, 4 node(s) had untolerated taint(s). no new claims to deallocate, preemption: 0/6 nodes are available: 2 No preemption victims found for incoming pod, 4 Preemption is not helpful for scheduling."
0.4623,Event,ADDED,eval-conflicts-rho020-r0-072-dzs95.18d5432bd69e8ad6,"reason=FailedScheduling count=None msg=0/6 nodes are available: 2 c_wall violated: 1 conflicting context pair(s) with node memory, 4 node(s) had untolerated taint(s). no new claims to deallocate, preemption: 0/6 nodes are available: 2 No preemption victims found for incoming pod, 4 Preemption is not helpful for scheduling."
0.4627,Event,ADDED,eval-conflicts-rho020-r0-072-dzs95.18d5432cc8664e2a,"reason=FailedScheduling count=None msg=0/6 nodes are available: 1 c_wall violated: 1 conflicting context pair(s) with node memory, 5 node(s) had untolerated taint(s). no new claims to deallocate, preemption: 0/6 nodes are available: 1 No preemption victims found for incoming pod, 5 Preemption is not helpful for scheduling."
0.4629,Event,ADDED,eval-conflicts-rho020-r0-072-dzs95.18d5432ccc9c77ee,reason=Scheduled count=None msg=Successfully assigned compute/eval-conflicts-rho020-r0-072-dzs95 to kind-worker4
0.4631,Event,ADDED,eval-conflicts-rho020-r0-072-dzs95.18d5432ce9d631b0,"reason=Pulled count=1 msg=Container image ""busybox:musl"" already present on machine"
0.4632,Event,ADDED,eval-conflicts-rho020-r0-072-dzs95.18d5432cebe85ef4,reason=Created count=1 msg=Created container: task
0.4636,Event,ADDED,eval-conflicts-rho020-r0-072-dzs95.18d5432cefc8bf7f,reason=Started count=1 msg=Started container task
0.4637,Event,ADDED,eval-conflicts-rho020-r0-072.18d5432bd5bd0d5a,reason=SuccessfulCreate count=1 msg=Created pod: eval-conflicts-rho020-r0-072-dzs95
0.4639,Event,ADDED,eval-conflicts-rho020-r0-072.18d543322f014d87,reason=Completed count=1 msg=Job completed
0.4641,Event,ADDED,eval-conflicts-rho020-r0-073-gbv6q.18d5432c123c662b,reason=Scheduled count=None msg=Successfully assigned compute/eval-conflicts-rho020-r0-073-gbv6q to kind-worker
0.4644,Event,ADDED,eval-conflicts-rho020-r0-073-gbv6q.18d5432c327a69fb,"reason=Pulled count=1 msg=Container image ""busybox:musl"" already present on machine"
0.4646,Event,ADDED,eval-conflicts-rho020-r0-073-gbv6q.18d5432c33caa3ae,reason=Created count=1 msg=Created container: task
0.4647,Event,ADDED,eval-conflicts-rho020-r0-073-gbv6q.18d5432c38ff0b9b,reason=Started count=1 msg=Started container task
0.465,Event,ADDED,eval-conflicts-rho020-r0-073.18d5432c11994e0f,reason=SuccessfulCreate count=1 msg=Created pod: eval-conflicts-rho020-r0-073-gbv6q
0.4652,Event,ADDED,eval-conflicts-rho020-r0-073.18d54331ce7d027d,reason=Completed count=1 msg=Job completed
0.4653,Event,ADDED,eval-conflicts-rho020-r0-074-f6k78.18d5432c5836913b,reason=Scheduled count=None msg=Successfully assigned compute/eval-conflicts-rho020-r0-074-f6k78 to kind-worker5
0.4655,Event,ADDED,eval-conflicts-rho020-r0-074-f6k78.18d5432c842ec2e1,"reason=Pulled count=1 msg=Container image ""busybox:musl"" already present on machine"
0.4657,Event,ADDED,eval-conflicts-rho020-r0-074-f6k78.18d5432c85401b6a,reason=Created count=1 msg=Created container: task
0.4658,Event,ADDED,eval-conflicts-rho020-r0-074-f6k78.18d5432c8ad992d2,reason=Started count=1 msg=Started container task
0.466,Event,ADDED,eval-conflicts-rho020-r0-074.18d5432c5209413e,reason=SuccessfulCreate count=1 msg=Created pod: eval-conflicts-rho020-r0-074-f6k78
0.4662,Event,ADDED,eval-conflicts-rho020-r0-074.18d54331f14cb172,reason=Completed count=1 msg=Job completed
0.4663,Event,ADDED,eval-conflicts-rho020-r0-075-cxfhd.18d5432c8cf0ec8c,reason=Scheduled count=None msg=Successfully assigned compute/eval-conflicts-rho020-r0-075-cxfhd to kind-worker5
0.4666,Event,ADDED,eval-conflicts-rho020-r0-075-cxfhd.18d5432ca7db3369,"reason=Pulled count=1 msg=Container image ""busybox:musl"" already present on machine"
0.4669,Event,ADDED,eval-conflicts-rho020-r0-075-cxfhd.18d5432ca8ea13a3,reason=Created count=1 msg=Created container: task
0.4672,Event,ADDED,eval-conflicts-rho020-r0-075-cxfhd.18d5432cadff2b52,reason=Started count=1 msg=Started container task
0.4674,Event,ADDED,eval-conflicts-rho020-r0-075.18d5432c8c496d04,reason=SuccessfulCreate count=1 msg=Created pod: eval-conflicts-rho020-r0-075-cxfhd
0.4675,Event,ADDED,eval-conflicts-rho020-r0-075.18d543322e3f1e79,reason=Completed count=1 msg=Job completed
0.4677,Event,ADDED,eval-conflicts-rho020-r0-076-csr28.18d5432cda398c0e,reason=Scheduled count=None msg=Successfully assigned compute/eval-conflicts-rho020-r0-076-csr28 to kind-worker4
0.468,Event,ADDED,eval-conflicts-rho020-r0-076-csr28.18d5432cf2ac6d84,"reason=Pulled count=1 msg=Container image ""busybox:musl"" already present on machine"
0.4682,Event,ADDED,eval-conflicts-rho020-r0-076-csr28.18d5432cf3dd4f1b,reason=Created count=1 msg=Created container: task
0.4683,Event,ADDED,eval-conflicts-rho020-r0-076-csr28.18d5432cf8077cc6,reason=Started count=1 msg=Started container task
0.4685,Event,ADDED,eval-conflicts-rho020-r0-076.18d5432cd994c4d5,reason=SuccessfulCreate count=1 msg=Created pod: eval-conflicts-rho020-r0-076-csr28
0.4687,Event,ADDED,eval-conflicts-rho020-r0-076.18d543322ed69dab,reason=Completed count=1 msg=Job completed
0.4689,Event,ADDED,eval-conflicts-rho020-r0-077-xm68m.18d5432d277a94fa,reason=Scheduled count=None msg=Successfully assigned compute/eval-conflicts-rho020-r0-077-xm68m to kind-worker4
0.469,Event,ADDED,eval-conflicts-rho020-r0-077-xm68m.18d5432d44a04613,"reason=Pulled count=1 msg=Container image ""busybox:musl"" already present on machine"
0.4692,Event,ADDED,eval-conflicts-rho020-r0-077-xm68m.18d5432d46268322,reason=Created count=1 msg=Created container: task
0.4694,Event,ADDED,eval-conflicts-rho020-r0-077-xm68m.18d5432d4c6508c3,reason=Started count=1 msg=Started container task
0.4696,Event,ADDED,eval-conflicts-rho020-r0-077.18d5432d26db69e4,reason=SuccessfulCreate count=1 msg=Created pod: eval-conflicts-rho020-r0-077-xm68m
0.4697,Event,ADDED,eval-conflicts-rho020-r0-077.18d54332e32bd4c5,reason=Completed count=1 msg=Job completed
0.4699,Event,ADDED,eval-conflicts-rho020-r0-078-vk5b9.18d5432d5d20c1b1,reason=Scheduled count=None msg=Successfully assigned compute/eval-conflicts-rho020-r0-078-vk5b9 to kind-worker4
0.47,Event,ADDED,eval-conflicts-rho020-r0-078-vk5b9.18d5432d76364dfc,"reason=Pulled count=1 msg=Container image ""busybox:musl"" already present on machine"
0.4702,Event,ADDED,eval-conflicts-rho020-r0-078-vk5b9.18d5432d777eaeb3,reason=Created count=1 msg=Created container: task
0.4704,Event,ADDED,eval-conflicts-rho020-r0-078-vk5b9.18d5432d7b398000,reason=Started count=1 msg=Started container task
0.4706,Event,ADDED,eval-conflicts-rho020-r0-078.18d5432d5c707d2b,reason=SuccessfulCreate count=1 msg=Created pod: eval-conflicts-rho020-r0-078-vk5b9
0.4707,Event,ADDED,eval-conflicts-rho020-r0-078.18d54332e32cdadf,reason=Completed count=1 msg=Job completed
0.4709,Event,ADDED,eval-conflicts-rho020-r0-079-z4rxs.18d5432d839ba03c,reason=Scheduled count=None msg=Successfully assigned compute/eval-conflicts-rho020-r0-079-z4rxs to kind-worker4
0.4712,Event,ADDED,eval-conflicts-rho020-r0-079-z4rxs.18d5432da04ccf7b,"reason=Pulled count=1 msg=Container image ""busybox:musl"" already present on machine"
0.4713,Event,ADDED,eval-conflicts-rho020-r0-079-z4rxs.18d5432da1641d8b,reason=Created count=1 msg=Created container: task
0.4715,Event,ADDED,eval-conflicts-rho020-r0-079-z4rxs.18d5432da4dfa89e,reason=Started count=1 msg=Started container task
0.4718,Event,ADDED,eval-conflicts-rho020-r0-079.18d5432d827a5690,reason=SuccessfulCreate count=1 msg=Created pod: eval-conflicts-rho020-r0-079-z4rxs
0.472,Event,ADDED,eval-conflicts-rho020-r0-079.18d5433321d81434,reason=Completed count=1 msg=Job completed
0.4721,Event,ADDED,eval-conflicts-rho020-r0-080-qmb98.18d5432db6a98e0a,"reason=FailedScheduling count=None msg=0/6 nodes are available: 1 c_wall violated: 1 conflicting context pair(s) with node memory, 1 c_wall violated: 2 conflicting context pair(s) with node memory, 4 node(s) had untolerated taint(s). no new claims to deallocate, preemption: 0/6 nodes are available: 2 No preemption victims found for incoming pod, 4 Preemption is not helpful for scheduling."
0.4723,Event,ADDED,eval-conflicts-rho020-r0-080-qmb98.18d5432db7490715,"reason=FailedScheduling count=None msg=0/6 nodes are available: 1 c_wall violated: 1 conflicting context pair(s) with node memory, 1 c_wall violated: 2 conflicting context pair(s) with node memory, 4 node(s) had untolerated taint(s). no new claims to deallocate, preemption: 0/6 nodes are available: 2 No preemption victims found for incoming pod, 4 Preemption is not helpful for scheduling."
0.4726,Event,ADDED,eval-conflicts-rho020-r0-080-qmb98.18d5432e957104ed,"reason=FailedScheduling count=None msg=0/6 nodes are available: 1 c_wall violated: 1 conflicting context pair(s) with node memory, 5 node(s) had untolerated taint(s). no new claims to deallocate, preemption: 0/6 nodes are available: 1 No preemption victims found for incoming pod, 5 Preemption is not helpful for scheduling."
0.4728,Event,ADDED,eval-conflicts-rho020-r0-080-qmb98.18d5432f219fb937,"reason=FailedScheduling count=None msg=0/6 nodes are available: 1 c_wall violated: 2 conflicting context pair(s) with node memory, 5 node(s) had untolerated taint(s). no new claims to deallocate, preemption: 0/6 nodes are available: 1 No preemption victims found for incoming pod, 5 Preemption is not helpful for scheduling."
0.4729,Event,ADDED,eval-conflicts-rho020-r0-080-qmb98.18d5433059a744d0,reason=Scheduled count=None msg=Successfully assigned compute/eval-conflicts-rho020-r0-080-qmb98 to kind-worker3
0.4733,Event,ADDED,eval-conflicts-rho020-r0-080-qmb98.18d54330728564af,"reason=Pulled count=1 msg=Container image ""busybox:musl"" already present on machine"
0.4735,Event,ADDED,eval-conflicts-rho020-r0-080-qmb98.18d543307426be79,reason=Created count=1 msg=Created container: task
0.4737,Event,ADDED,eval-conflicts-rho020-r0-080-qmb98.18d543307795206f,reason=Started count=1 msg=Started container task
0.474,Event,ADDED,eval-conflicts-rho020-r0-080.18d5432db64f57a9,reason=SuccessfulCreate count=1 msg=Created pod: eval-conflicts-rho020-r0-080-qmb98
0.4742,Event,ADDED,eval-conflicts-rho020-r0-080.18d54335eb4fe0d6,reason=Completed count=1 msg=Job completed
0.4743,Event,ADDED,eval-conflicts-rho020-r0-081-qn4cz.18d5432df0a10d11,reason=Scheduled count=None msg=Successfully assigned compute/eval-conflicts-rho020-r0-081-qn4cz to kind-worker4
0.4745,Event,ADDED,eval-conflicts-rho020-r0-081-qn4cz.18d5432e0e5770ca,"reason=Pulled count=1 msg=Container image ""busybox:musl"" already present on machine"
0.4748,Event,ADDED,eval-conflicts-rho020-r0-081-qn4cz.18d5432e0fb9d9c1,reason=Created count=1 msg=Created container: task
0.475,Event,ADDED,eval-conflicts-rho020-r0-081-qn4cz.18d5432e17934053,reason=Started count=1 msg=Started container task
0.4752,Event,ADDED,eval-conflicts-rho020-r0-081.18d5432defbf7867,reason=SuccessfulCreate count=1 msg=Created pod: eval-conflicts-rho020-r0-081-qn4cz
0.4755,Event,ADDED,eval-conflicts-rho020-r0-081.18d5433392c13900,reason=Completed count=1 msg=Job completed
0.4756,Event,ADDED,eval-conflicts-rho020-r0-082-pkkvj.18d5432e2c71b746,"reason=FailedScheduling count=None msg=0/6 nodes are available: 1 c_wall violated: 1 conflicting context pair(s) with node memory, 1 c_wall violated: 2 conflicting context pair(s) with node memory, 4 node(s) had untolerated taint(s). no new claims to deallocate, preemption: 0/6 nodes are available: 2 No preemption victims found for incoming pod, 4 Preemption is not helpful for scheduling."
0.4758,Event,ADDED,eval-conflicts-rho020-r0-082-pkkvj.18d5432e2d3c0c46,"reason=FailedScheduling count=None msg=0/6 nodes are available: 1 c_wall violated: 1 conflicting context pair(s) with node memory, 1 c_wall violated: 2 conflicting context pair(s) with node memory, 4 node(s) had untolerated taint(s). no new claims to deallocate, preemption: 0/6 nodes are available: 2 No preemption victims found for incoming pod, 4 Preemption is not helpful for scheduling."
0.4761,Event,ADDED,eval-conflicts-rho020-r0-082-pkkvj.18d5432e9391c3a9,"reason=FailedScheduling count=None msg=0/6 nodes are available: 1 c_wall violated: 1 conflicting context pair(s) with node memory, 5 node(s) had untolerated taint(s). no new claims to deallocate, preemption: 0/6 nodes are available: 1 No preemption victims found for incoming pod, 5 Preemption is not helpful for scheduling."
0.4763,Event,ADDED,eval-conflicts-rho020-r0-082-pkkvj.18d5432f216df9c9,"reason=FailedScheduling count=None msg=0/6 nodes are available: 1 c_wall violated: 2 conflicting context pair(s) with node memory, 5 node(s) had untolerated taint(s). no new claims to deallocate, preemption: 0/6 nodes are available: 1 No preemption victims found for incoming pod, 5 Preemption is not helpful for scheduling."
0.4765,Event,ADDED,eval-conflicts-rho020-r0-082-pkkvj.18d54330536634d9,reason=Scheduled count=None msg=Successfully assigned compute/eval-conflicts-rho020-r0-082-pkkvj to kind-worker3
0.4767,Event,ADDED,eval-conflicts-rho020-r0-082-pkkvj.18d543306c067872,"reason=Pulled count=1 msg=Container image ""busybox:musl"" already present on machine"
0.4769,Event,ADDED,eval-conflicts-rho020-r0-082-pkkvj.18d543306da39183,reason=Created count=1 msg=Created container: task
0.4771,Event,ADDED,eval-conflicts-rho020-r0-082-pkkvj.18d54330727b6a71,reason=Started count=1 msg=Started container task
0.4773,Event,ADDED,eval-conflicts-rho020-r0-082.18d5432e2bfd12e8,reason=SuccessfulCreate count=1 msg=Created pod: eval-conflicts-rho020-r0-082-pkkvj
0.4775,Event,ADDED,eval-conflicts-rho020-r0-082.18d54335afd2803c,reason=Completed count=1 msg=Job completed
0.4777,Event,ADDED,eval-conflicts-rho020-r0-083-tw5h4.18d5432e685efc82,reason=Scheduled count=None msg=Successfully assigned compute/eval-conflicts-rho020-r0-083-tw5h4 to kind-worker4
0.4779,Event,ADDED,eval-conflicts-rho020-r0-083-tw5h4.18d5432e85c97005,"reason=Pulled count=1 msg=Container image ""busybox:musl"" already present on machine"
0.478,Event,ADDED,eval-conflicts-rho020-r0-083-tw5h4.18d5432e86ee6c3f,reason=Created count=1 msg=Created container: task
0.4782,Event,ADDED,eval-conflicts-rho020-r0-083-tw5h4.18d5432e8b34bef2,reason=Started count=1 msg=Started container task
0.4785,Event,ADDED,eval-conflicts-rho020-r0-083.18d5432e67a676b6,reason=SuccessfulCreate count=1 msg=Created pod: eval-conflicts-rho020-r0-083-tw5h4
0.4787,Event,ADDED,eval-conflicts-rho020-r0-083.18d54334106617c9,reason=Completed count=1 msg=Job completed
0.479,Event,ADDED,eval-conflicts-rho020-r0-084-fhv4s.18d5432ea3c745c3,reason=Scheduled count=None msg=Successfully assigned compute/eval-conflicts-rho020-r0-084-fhv4s to kind-worker4
0.4792,Event,ADDED,eval-conflicts-rho020-r0-084-fhv4s.18d5432ebd0e5cea,"reason=Pulled count=1 msg=Container image ""busybox:musl"" already present on machine"
0.4794,Event,ADDED,eval-conflicts-rho020-r0-084-fhv4s.18d5432ebe2a643a,reason=Created count=1 msg=Created container: task
0.4795,Event,ADDED,eval-conflicts-rho020-r0-084-fhv4s.18d5432ec844ff61,reason=Started count=1 msg=Started container task
0.4798,Event,ADDED,eval-conflicts-rho020-r0-084.18d5432ea32f163b,reason=SuccessfulCreate count=1 msg=Created pod: eval-conflicts-rho020-r0-084-fhv4s
0.48,Event,ADDED,eval-conflicts-rho020-r0-084.18d543344c608790,reason=Completed count=1 msg=Job completed
0.4802,Event,ADDED,eval-conflicts-rho020-r0-085-x7j8p.18d5432ee2c1be4b,"reason=FailedScheduling count=None msg=0/6 nodes are available: 1 c_wall violated: 1 conflicting context pair(s) with node memory, 5 node(s) had untolerated taint(s). no new claims to deallocate, preemption: 0/6 nodes are available: 1 No preemption victims found for incoming pod, 5 Preemption is not helpful for scheduling."
0.4805,Event,ADDED,eval-conflicts-rho020-r0-085-x7j8p.18d5432ee34081c0,"reason=FailedScheduling count=None msg=0/6 nodes are available: 1 c_wall violated: 1 conflicting context pair(s) with node memory, 5 node(s) had untolerated taint(s). no new claims to deallocate, preemption: 0/6 nodes are available: 1 No preemption victims found for incoming pod, 5 Preemption is not helpful for scheduling."
0.4807,Event,ADDED,eval-conflicts-rho020-r0-085-x7j8p.18d5433060d28889,"reason=FailedScheduling count=None msg=0/6 nodes are available: 2 c_wall violated: 1 conflicting context pair(s) with node memory, 4 node(s) had untolerated taint(s). no new claims to deallocate, preemption: 0/6 nodes are available: 2 No preemption victims found for incoming pod, 4 Preemption is not helpful for scheduling."
0.4809,Event,ADDED,eval-conflicts-rho020-r0-085-x7j8p.18d543318e4ec721,"reason=FailedScheduling count=None msg=0/6 nodes are available: 1 c_wall violated: 1 conflicting context pair(s) with node memory, 5 node(s) had untolerated taint(s). no new claims to deallocate, preemption: 0/6 nodes are available: 1 No preemption victims found for incoming pod, 5 Preemption is not helpful for scheduling."
0.4811,Event,ADDED,eval-conflicts-rho020-r0-085-x7j8p.18d54331ea0df303,"reason=FailedScheduling count=None msg=0/6 nodes are available: 1 c_wall violated: 2 conflicting context pair(s) with node memory, 5 node(s) had untolerated taint(s). no new claims to deallocate, preemption: 0/6 nodes are available: 1 No preemption victims found for incoming pod, 5 Preemption is not helpful for scheduling."
0.4813,Event,ADDED,eval-conflicts-rho020-r0-085-x7j8p.18d5433356561b20,reason=Scheduled count=None msg=Successfully assigned compute/eval-conflicts-rho020-r0-085-x7j8p to kind-worker
0.4815,Event,ADDED,eval-conflicts-rho020-r0-085-x7j8p.18d5433378ca7279,"reason=Pulled count=1 msg=Container image ""busybox:musl"" already present on machine"
0.4816,Event,ADDED,eval-conflicts-rho020-r0-085-x7j8p.18d543337c526d1c,reason=Created count=1 msg=Created container: task
0.4818,Event,ADDED,eval-conflicts-rho020-r0-085-x7j8p.18d543338107d9db,reason=Started count=1 msg=Started container task
0.482,Event,ADDED,eval-conflicts-rho020-r0-085.18d5432ee285be26,reason=SuccessfulCreate count=1 msg=Created pod: eval-conflicts-rho020-r0-085-x7j8p
0.4822,Event,ADDED,eval-conflicts-rho020-r0-085.18d54338cd6a5c85,reason=Completed count=1 msg=Job completed
0.4826,Event,ADDED,eval-conflicts-rho020-r0-086-d9dqt.18d5432f1fc70040,reason=Scheduled count=None msg=Successfully assigned compute/eval-conflicts-rho020-r0-086-d9dqt to kind-worker4
0.4828,Event,ADDED,eval-conflicts-rho020-r0-086-d9dqt.18d5432f41e05260,"reason=Pulled count=1 msg=Container image ""busybox:musl"" already present on machine"
0.4831,Event,ADDED,eval-conflicts-rho020-r0-086-d9dqt.18d5432f43308d28,reason=Created count=1 msg=Created container: task
0.4833,Event,ADDED,eval-conflicts-rho020-r0-086-d9dqt.18d5432f520adafd,reason=Started count=1 msg=Started container task
0.4837,Event,ADDED,eval-conflicts-rho020-r0-086.18d5432f1f31ebe8,reason=SuccessfulCreate count=1 msg=Created pod: eval-conflicts-rho020-r0-086-d9dqt
0.4838,Event,ADDED,eval-conflicts-rho020-r0-086.18d54334c425ad09,reason=Completed count=1 msg=Job completed
0.484,Event,ADDED,eval-conflicts-rho020-r0-087-dld5q.18d5432f54361531,reason=Scheduled count=None msg=Successfully assigned compute/eval-conflicts-rho020-r0-087-dld5q to kind-worker4
0.4843,Event,ADDED,eval-conflicts-rho020-r0-087-dld5q.18d5432f7284628e,"reason=Pulled count=1 msg=Container image ""busybox:musl"" already present on machine"
0.4845,Event,ADDED,eval-conflicts-rho020-r0-087-dld5q.18d5432f73eee11c,reason=Created count=1 msg=Created container: task
0.4847,Event,ADDED,eval-conflicts-rho020-r0-087-dld5q.18d5432f7ce591f4,reason=Started count=1 msg=Started container task
0.4849,Event,ADDED,eval-conflicts-rho020-r0-087.18d5432f539f52da,reason=SuccessfulCreate count=1 msg=Created pod: eval-conflicts-rho020-r0-087-dld5q
0.4853,Event,ADDED,eval-conflicts-rho020-r0-087.18d54334fb4043bf,reason=Completed count=1 msg=Job completed
0.4855,Event,ADDED,eval-conflicts-rho020-r0-088-zxmkn.18d5432f8fa0b98e,"reason=FailedScheduling count=None msg=0/6 nodes are available: 1 c_wall violated: 1 conflicting context pair(s) with node memory, 5 node(s) had untolerated taint(s). no new claims to deallocate, preemption: 0/6 nodes are available: 1 No preemption victims found for incoming pod, 5 Preemption is not helpful for scheduling."
0.4857,Event,ADDED,eval-conflicts-rho020-r0-088-zxmkn.18d5432f905319a7,"reason=FailedScheduling count=None msg=0/6 nodes are available: 1 c_wall violated: 1 conflicting context pair(s) with node memory, 5 node(s) had untolerated taint(s). no new claims to deallocate, preemption: 0/6 nodes are available: 1 No preemption victims found for incoming pod, 5 Preemption is not helpful for scheduling."
0.4861,Event,ADDED,eval-conflicts-rho020-r0-088-zxmkn.18d543305e8fb052,"reason=FailedScheduling count=None msg=0/6 nodes are available: 2 c_wall violated: 1 conflicting context pair(s) with node memory, 4 node(s) had untolerated taint(s). no new claims to deallocate, preemption: 0/6 nodes are available: 2 No preemption victims found for incoming pod, 4 Preemption is not helpful for scheduling."
0.4863,Event,ADDED,eval-conflicts-rho020-r0-088-zxmkn.18d543318eac07c6,"reason=FailedScheduling count=None msg=0/6 nodes are available: 1 c_wall violated: 1 conflicting context pair(s) with node memory, 5 node(s) had untolerated taint(s). no new claims to deallocate, preemption: 0/6 nodes are available: 1 No preemption victims found for incoming pod, 5 Preemption is not helpful for scheduling."
0.4865,Event,ADDED,eval-conflicts-rho020-r0-088-zxmkn.18d54331eb61de0d,"reason=FailedScheduling count=None msg=0/6 nodes are available: 1 c_wall violated: 2 conflicting context pair(s) with node memory, 5 node(s) had untolerated taint(s). no new claims to deallocate, preemption: 0/6 nodes are available: 1 No preemption victims found for incoming pod, 5 Preemption is not helpful for scheduling."
0.4868,Event,ADDED,eval-conflicts-rho020-r0-088-zxmkn.18d54333551c8dfa,reason=Scheduled count=None msg=Successfully assigned compute/eval-conflicts-rho020-r0-088-zxmkn to kind-worker
0.487,Event,ADDED,eval-conflicts-rho020-r0-088-zxmkn.18d5433378f53359,"reason=Pulled count=1 msg=Container image ""busybox:musl"" already present on machine"
0.4872,Event,ADDED,eval-conflicts-rho020-r0-088-zxmkn.18d543337c9cc6b3,reason=Created count=1 msg=Created container: task
0.488,Event,ADDED,eval-conflicts-rho020-r0-088-zxmkn.18d5433381076a83,reason=Started count=1 msg=Started container task
0.4882,Event,ADDED,eval-conflicts-rho020-r0-088.18d5432f8f61d408,reason=SuccessfulCreate count=1 msg=Created pod: eval-conflicts-rho020-r0-088-zxmkn
0.4883,Event,ADDED,eval-conflicts-rho020-r0-088.18d54338cde52c6b,reason=Completed count=1 msg=Job completed
0.4885,Event,ADDED,eval-conflicts-rho020-r0-089-pbrp7.18d5432fd1f22d23,"reason=FailedScheduling count=None msg=0/6 nodes are available: 1 c_wall violated: 1 conflicting context pair(s) with node memory, 5 node(s) had untolerated taint(s). no new claims to deallocate, preemption: 0/6 nodes are available: 1 No preemption victims found for incoming pod, 5 Preemption is not helpful for scheduling."
0.4889,Event,ADDED,eval-conflicts-rho020-r0-089-pbrp7.18d5432fd27436b0,"reason=FailedScheduling count=None msg=0/6 nodes are available: 1 c_wall violated: 1 conflicting context pair(s) with node memory, 5 node(s) had untolerated taint(s). no new claims to deallocate, preemption: 0/6 nodes are available: 1 No preemption victims found for incoming pod, 5 Preemption is not helpful for scheduling."
0.4891,Event,ADDED,eval-conflicts-rho020-r0-089-pbrp7.18d54330606af989,"reason=FailedScheduling count=None msg=0/6 nodes are available: 2 c_wall violated: 1 conflicting context pair(s) with node memory, 4 node(s) had untolerated taint(s). no new claims to deallocate, preemption: 0/6 nodes are available: 2 No preemption victims found for incoming pod, 4 Preemption is not helpful for scheduling."
0.4893,Event,ADDED,eval-conflicts-rho020-r0-089-pbrp7.18d543318a86fc6b,"reason=FailedScheduling count=None msg=0/6 nodes are available: 1 c_wall violated: 1 conflicting context pair(s) with node memory, 5 node(s) had untolerated taint(s). no new claims to deallocate, preemption: 0/6 nodes are available: 1 No preemption victims found for incoming pod, 5 Preemption is not helpful for scheduling."
0.4901,Event,ADDED,eval-conflicts-rho020-r0-089-pbrp7.18d54331e9e95770,"reason=FailedScheduling count=None msg=0/6 nodes are available: 1 c_wall violated: 2 conflicting context pair(s) with node memory, 5 node(s) had untolerated taint(s). no new claims to deallocate, preemption: 0/6 nodes are available: 1 No preemption victims found for incoming pod, 5 Preemption is not helpful for scheduling."
0.4902,Event,ADDED,eval-conflicts-rho020-r0-089-pbrp7.18d543335603f39f,reason=Scheduled count=None msg=Successfully assigned compute/eval-conflicts-rho020-r0-089-pbrp7 to kind-worker
0.4904,Event,ADDED,eval-conflicts-rho020-r0-089-pbrp7.18d5433378ade6d0,"reason=Pulled count=1 msg=Container image ""busybox:musl"" already present on machine"
0.491,Event,ADDED,eval-conflicts-rho020-r0-089-pbrp7.18d543337b2b27ec,reason=Created count=1 msg=Created container: task
0.4913,Event,ADDED,eval-conflicts-rho020-r0-089-pbrp7.18d543337faa0ae5,reason=Started count=1 msg=Started container task
0.4915,Event,ADDED,eval-conflicts-rho020-r0-089.18d5432fd1ae3f25,reason=SuccessfulCreate count=1 msg=Created pod: eval-conflicts-rho020-r0-089-pbrp7
0.4917,Event,ADDED,eval-conflicts-rho020-r0-089.18d54338d29633ad,reason=Completed count=1 msg=Job completed
0.492,Event,ADDED,eval-conflicts-rho020-r0-090-5qcp9.18d54330071bd8f9,reason=Scheduled count=None msg=Successfully assigned compute/eval-conflicts-rho020-r0-090-5qcp9 to kind-worker4
0.4922,Event,ADDED,eval-conflicts-rho020-r0-090-5qcp9.18d543302517adf1,"reason=Pulled count=1 msg=Container image ""busybox:musl"" already present on machine"
0.4924,Event,ADDED,eval-conflicts-rho020-r0-090-5qcp9.18d5433026e15e86,reason=Created count=1 msg=Created container: task
0.4928,Event,ADDED,eval-conflicts-rho020-r0-090-5qcp9.18d543302d71fecb,reason=Started count=1 msg=Started container task
0.493,Event,ADDED,eval-conflicts-rho020-r0-090.18d54330069c6f87,reason=SuccessfulCreate count=1 msg=Created pod: eval-conflicts-rho020-r0-090-5qcp9
0.4932,Event,ADDED,eval-conflicts-rho020-r0-090.18d54335adbcb02d,reason=Completed count=1 msg=Job completed
0.4934,Event,ADDED,eval-conflicts-rho020-r0-091-gxtp7.18d54330432a284c,reason=Scheduled count=None msg=Successfully assigned compute/eval-conflicts-rho020-r0-091-gxtp7 to kind-worker4
0.4938,Event,ADDED,eval-conflicts-rho020-r0-091-gxtp7.18d543305c083c7b,"reason=Pulled count=1 msg=Container image ""busybox:musl"" already present on machine"
0.494,Event,ADDED,eval-conflicts-rho020-r0-091-gxtp7.18d543305d43c3bc,reason=Created count=1 msg=Created container: task
0.4942,Event,ADDED,eval-conflicts-rho020-r0-091-gxtp7.18d5433062765784,reason=Started count=1 msg=Started container task
0.4946,Event,ADDED,eval-conflicts-rho020-r0-091.18d5433042a2d6d2,reason=SuccessfulCreate count=1 msg=Created pod: eval-conflicts-rho020-r0-091-gxtp7
0.4948,Event,ADDED,eval-conflicts-rho020-r0-091.18d54335e9913e5a,reason=Completed count=1 msg=Job completed
0.4949,Event,ADDED,eval-conflicts-rho020-r0-092-2m4zc.18d543307ef8130e,reason=Scheduled count=None msg=Successfully assigned compute/eval-conflicts-rho020-r0-092-2m4zc to kind-worker4
0.4951,Event,ADDED,eval-conflicts-rho020-r0-092-2m4zc.18d54330982e80af,"reason=Pulled count=1 msg=Container image ""busybox:musl"" already present on machine"
0.4955,Event,ADDED,eval-conflicts-rho020-r0-092-2m4zc.18d54330996a14d4,reason=Created count=1 msg=Created container: task
0.4957,Event,ADDED,eval-conflicts-rho020-r0-092-2m4zc.18d543309d839954,reason=Started count=1 msg=Started container task
0.4959,Event,ADDED,eval-conflicts-rho020-r0-092.18d543307e344966,reason=SuccessfulCreate count=1 msg=Created pod: eval-conflicts-rho020-r0-092-2m4zc
0.496,Event,ADDED,eval-conflicts-rho020-r0-092.18d54336257c9ed2,reason=Completed count=1 msg=Job completed
0.4964,Event,ADDED,eval-conflicts-rho020-r0-093-2bnxq.18d54330be580ad0,reason=Scheduled count=None msg=Successfully assigned compute/eval-conflicts-rho020-r0-093-2bnxq to kind-worker3
0.4966,Event,ADDED,eval-conflicts-rho020-r0-093-2bnxq.18d54330d73ad4c5,"reason=Pulled count=1 msg=Container image ""busybox:musl"" already present on machine"
0.4968,Event,ADDED,eval-conflicts-rho020-r0-093-2bnxq.18d54330d8ee82e5,reason=Created count=1 msg=Created container: task
0.4971,Event,ADDED,eval-conflicts-rho020-r0-093-2bnxq.18d54330db249ba4,reason=Started count=1 msg=Started container task
0.4972,Event,ADDED,eval-conflicts-rho020-r0-093.18d54330ba6ce061,reason=SuccessfulCreate count=1 msg=Created pod: eval-conflicts-rho020-r0-093-2bnxq
0.4974,Event,ADDED,eval-conflicts-rho020-r0-093.18d5433627a2aa1f,reason=Completed count=1 msg=Job completed
0.4976,Event,ADDED,eval-conflicts-rho020-r0-094-qs9l8.18d54330f725c97a,reason=Scheduled count=None msg=Successfully assigned compute/eval-conflicts-rho020-r0-094-qs9l8 to kind-worker3
0.4978,Event,ADDED,eval-conflicts-rho020-r0-094-qs9l8.18d543310fa0aaf0,"reason=Pulled count=1 msg=Container image ""busybox:musl"" already present on machine"
0.498,Event,ADDED,eval-conflicts-rho020-r0-094-qs9l8.18d5433110c85e95,reason=Created count=1 msg=Created container: task
0.4981,Event,ADDED,eval-conflicts-rho020-r0-094-qs9l8.18d543311640a7a5,reason=Started count=1 msg=Started container task
0.4983,Event,ADDED,eval-conflicts-rho020-r0-094.18d54330f6033b2e,reason=SuccessfulCreate count=1 msg=Created pod: eval-conflicts-rho020-r0-094-qs9l8
0.4985,Event,ADDED,eval-conflicts-rho020-r0-094.18d54336a011915a,reason=Completed count=1 msg=Job completed
0.4986,Event,ADDED,eval-conflicts-rho020-r0-095-hdw8s.18d5433131504735,reason=Scheduled count=None msg=Successfully assigned compute/eval-conflicts-rho020-r0-095-hdw8s to kind-worker4
0.4988,Event,ADDED,eval-conflicts-rho020-r0-095-hdw8s.18d54331504a0f0a,"reason=Pulled count=1 msg=Container image ""busybox:musl"" already present on machine"
0.499,Event,ADDED,eval-conflicts-rho020-r0-095-hdw8s.18d54331519f04db,reason=Created count=1 msg=Created container: task
0.4992,Event,ADDED,eval-conflicts-rho020-r0-095-hdw8s.18d543315dbc8b43,reason=Started count=1 msg=Started container task
0.4993,Event,ADDED,eval-conflicts-rho020-r0-095.18d5433130ba0bd5,reason=SuccessfulCreate count=1 msg=Created pod: eval-conflicts-rho020-r0-095-hdw8s
0.4995,Event,ADDED,eval-conflicts-rho020-r0-095.18d54336dc76f3f3,reason=Completed count=1 msg=Job completed
0.4997,Event,ADDED,eval-conflicts-rho020-r0-096-ks4p6.18d543316ca2b70f,"reason=FailedScheduling count=None msg=0/6 nodes are available: 2 c_wall violated: 1 conflicting context pair(s) with node memory, 4 node(s) had untolerated taint(s). no new claims to deallocate, preemption: 0/6 nodes are available: 2 No preemption victims found for incoming pod, 4 Preemption is not helpful for scheduling."
0.4999,Event,ADDED,eval-conflicts-rho020-r0-096-ks4p6.18d543316d72be5d,"reason=FailedScheduling count=None msg=0/6 nodes are available: 2 c_wall violated: 1 conflicting context pair(s) with node memory, 4 node(s) had untolerated taint(s). no new claims to deallocate, preemption: 0/6 nodes are available: 2 No preemption victims found for incoming pod, 4 Preemption is not helpful for scheduling."
0.5002,Event,ADDED,eval-conflicts-rho020-r0-096-ks4p6.18d543318e83099e,"reason=FailedScheduling count=None msg=0/6 nodes are available: 1 c_wall violated: 1 conflicting context pair(s) with node memory, 5 node(s) had untolerated taint(s). no new claims to deallocate, preemption: 0/6 nodes are available: 1 No preemption victims found for incoming pod, 5 Preemption is not helpful for scheduling."
0.5005,Event,ADDED,eval-conflicts-rho020-r0-096-ks4p6.18d54331ea507ac0,"reason=FailedScheduling count=None msg=0/6 nodes are available: 1 c_wall violated: 2 conflicting context pair(s) with node memory, 5 node(s) had untolerated taint(s). no new claims to deallocate, preemption: 0/6 nodes are available: 1 No preemption victims found for incoming pod, 5 Preemption is not helpful for scheduling."
0.5008,Event,ADDED,eval-conflicts-rho020-r0-096-ks4p6.18d54333551ed616,reason=Scheduled count=None msg=Successfully assigned compute/eval-conflicts-rho020-r0-096-ks4p6 to kind-worker
0.5012,Event,ADDED,eval-conflicts-rho020-r0-096-ks4p6.18d5433379225cb5,"reason=Pulled count=1 msg=Container image ""busybox:musl"" already present on machine"
0.5015,Event,ADDED,eval-conflicts-rho020-r0-096-ks4p6.18d543337c79cc3f,reason=Created count=1 msg=Created container: task
0.5017,Event,ADDED,eval-conflicts-rho020-r0-096-ks4p6.18d5433381076a7a,reason=Started count=1 msg=Started container task
0.5019,Event,ADDED,eval-conflicts-rho020-r0-096.18d543316c3b6dc1,reason=SuccessfulCreate count=1 msg=Created pod: eval-conflicts-rho020-r0-096-ks4p6
0.5021,Event,ADDED,eval-conflicts-rho020-r0-096.18d54338ce7b04f1,reason=Completed count=1 msg=Job completed
0.5024,Event,ADDED,eval-conflicts-rho020-r0-097-tznp7.18d54331ade7d5bc,"reason=FailedScheduling count=None msg=0/6 nodes are available: 1 c_wall violated: 1 conflicting context pair(s) with node memory, 5 node(s) had untolerated taint(s). no new claims to deallocate, preemption: 0/6 nodes are available: 1 No preemption victims found for incoming pod, 5 Preemption is not helpful for scheduling."
0.5027,Event,ADDED,eval-conflicts-rho020-r0-097-tznp7.18d54331ae709975,"reason=FailedScheduling count=None msg=0/6 nodes are available: 1 c_wall violated: 1 conflicting context pair(s) with node memory, 5 node(s) had untolerated taint(s). no new claims to deallocate, preemption: 0/6 nodes are available: 1 No preemption victims found for incoming pod, 5 Preemption is not helpful for scheduling."
0.5032,Event,ADDED,eval-conflicts-rho020-r0-097-tznp7.18d5433354f6c3a3,reason=Scheduled count=None msg=Successfully assigned compute/eval-conflicts-rho020-r0-097-tznp7 to kind-worker
0.5036,Event,ADDED,eval-conflicts-rho020-r0-097-tznp7.18d54333789bb8b9,"reason=Pulled count=1 msg=Container image ""busybox:musl"" already present on machine"
0.5038,Event,ADDED,eval-conflicts-rho020-r0-097-tznp7.18d543337c13f28d,reason=Created count=1 msg=Created container: task
0.504,Event,ADDED,eval-conflicts-rho020-r0-097-tznp7.18d543338107de8b,reason=Started count=1 msg=Started container task
0.5043,Event,ADDED,eval-conflicts-rho020-r0-097.18d54331ada99cd3,reason=SuccessfulCreate count=1 msg=Created pod: eval-conflicts-rho020-r0-097-tznp7
0.5045,Event,ADDED,eval-conflicts-rho020-r0-097.18d54339088f4f51,reason=Completed count=1 msg=Job completed
0.5047,Event,ADDED,eval-conflicts-rho020-r0-098-zrkwv.18d54331e5b360c1,reason=Scheduled count=None msg=Successfully assigned compute/eval-conflicts-rho020-r0-098-zrkwv to kind-worker3
0.5049,Event,ADDED,eval-conflicts-rho020-r0-098-zrkwv.18d5433216badcf1,"reason=Pulled count=1 msg=Container image ""busybox:musl"" already present on machine"
0.5052,Event,ADDED,eval-conflicts-rho020-r0-098-zrkwv.18d5433217d221ea,reason=Created count=1 msg=Created container: task
0.5054,Event,ADDED,eval-conflicts-rho020-r0-098-zrkwv.18d54332214dba51,reason=Started count=1 msg=Started container task
0.5056,Event,ADDED,eval-conflicts-rho020-r0-098.18d54331e537d244,reason=SuccessfulCreate count=1 msg=Created pod: eval-conflicts-rho020-r0-098-zrkwv
0.5058,Event,ADDED,eval-conflicts-rho020-r0-098.18d543378eb01899,reason=Completed count=1 msg=Job completed
0.5061,Event,ADDED,eval-conflicts-rho020-r0-099-kfjf9.18d5433222fed9c0,"reason=FailedScheduling count=None msg=0/6 nodes are available: 1 c_wall violated: 1 conflicting context pair(s) with node memory, 5 node(s) had untolerated taint(s). no new claims to deallocate, preemption: 0/6 nodes are available: 1 No preemption victims found for incoming pod, 5 Preemption is not helpful for scheduling."
0.5063,Event,ADDED,eval-conflicts-rho020-r0-099-kfjf9.18d5433223a35d47,"reason=FailedScheduling count=None msg=0/6 nodes are available: 1 c_wall violated: 1 conflicting context pair(s) with node memory, 5 node(s) had untolerated taint(s). no new claims to deallocate, preemption: 0/6 nodes are available: 1 No preemption victims found for incoming pod, 5 Preemption is not helpful for scheduling."
0.5065,Event,ADDED,eval-conflicts-rho020-r0-099-kfjf9.18d54333462aea1b,reason=Scheduled count=None msg=Successfully assigned compute/eval-conflicts-rho020-r0-099-kfjf9 to kind-worker
0.5068,Event,ADDED,eval-conflicts-rho020-r0-099-kfjf9.18d543335fb37ea5,"reason=Pulled count=1 msg=Container image ""busybox:musl"" already present on machine"
0.507,Event,ADDED,eval-conflicts-rho020-r0-099-kfjf9.18d5433361c6984f,reason=Created count=1 msg=Created container: task
0.5072,Event,ADDED,eval-conflicts-rho020-r0-099-kfjf9.18d54333654c4391,reason=Started count=1 msg=Started container task
0.5075,Event,ADDED,eval-conflicts-rho020-r0-099.18d5433222c08d66,reason=SuccessfulCreate count=1 msg=Created pod: eval-conflicts-rho020-r0-099-kfjf9
0.5077,Event,ADDED,eval-conflicts-rho020-r0-099.18d54338ccdc4f33,reason=Completed count=1 msg=Job completed
0.5079,Event,ADDED,eval-conflicts-rho020-r0-100-fbsmt.18d543325f69ef41,"reason=FailedScheduling count=None msg=0/6 nodes are available: 1 c_wall violated: 1 conflicting context pair(s) with node memory, 5 node(s) had untolerated taint(s). no new claims to deallocate, preemption: 0/6 nodes are available: 1 No preemption victims found for incoming pod, 5 Preemption is not helpful for scheduling."
0.5081,Event,ADDED,eval-conflicts-rho020-r0-100-fbsmt.18d543326010d71d,"reason=FailedScheduling count=None msg=0/6 nodes are available: 1 c_wall violated: 1 conflicting context pair(s) with node memory, 5 node(s) had untolerated taint(s). no new claims to deallocate, preemption: 0/6 nodes are available: 1 No preemption victims found for incoming pod, 5 Preemption is not helpful for scheduling."
0.5084,Event,ADDED,eval-conflicts-rho020-r0-100-fbsmt.18d5433349b1e8cf,reason=Scheduled count=None msg=Successfully assigned compute/eval-conflicts-rho020-r0-100-fbsmt to kind-worker
0.5086,Event,ADDED,eval-conflicts-rho020-r0-100-fbsmt.18d54333655a672e,"reason=Pulled count=1 msg=Container image ""busybox:musl"" already present on machine"
0.5088,Event,ADDED,eval-conflicts-rho020-r0-100-fbsmt.18d5433366fe3c10,reason=Created count=1 msg=Created container: task
0.5091,Event,ADDED,eval-conflicts-rho020-r0-100-fbsmt.18d543336a5cb135,reason=Started count=1 msg=Started container task
0.5093,Event,ADDED,eval-conflicts-rho020-r0-100.18d543325f1c04db,reason=SuccessfulCreate count=1 msg=Created pod: eval-conflicts-rho020-r0-100-fbsmt
0.5094,Event,ADDED,eval-conflicts-rho020-r0-100.18d5433891c6d78f,reason=Completed count=1 msg=Job completed
0.5096,Event,ADDED,eval-conflicts-rho020-r0-101-rsv4j.18d5433297290643,reason=Scheduled count=None msg=Successfully assigned compute/eval-conflicts-rho020-r0-101-rsv4j to kind-worker3
0.5099,Event,ADDED,eval-conflicts-rho020-r0-101-rsv4j.18d54332b29a4268,"reason=Pulled count=1 msg=Container image ""busybox:musl"" already present on machine"
0.5101,Event,ADDED,eval-conflicts-rho020-r0-101-rsv4j.18d54332b3bc7814,reason=Created count=1 msg=Created container: task
0.5102,Event,ADDED,eval-conflicts-rho020-r0-101-rsv4j.18d54332b819e119,reason=Started count=1 msg=Started container task
0.5104,Event,ADDED,eval-conflicts-rho020-r0-101.18d5433296af85de,reason=SuccessfulCreate count=1 msg=Created pod: eval-conflicts-rho020-r0-101-rsv4j
0.5106,Event,ADDED,eval-conflicts-rho020-r0-101.18d543384174545b,reason=Completed count=1 msg=Job completed
0.5108,Event,ADDED,eval-conflicts-rho020-r0-102-n6gg8.18d54332d274be21,"reason=FailedScheduling count=None msg=0/6 nodes are available: 1 c_wall violated: 1 conflicting context pair(s) with node memory, 5 node(s) had untolerated taint(s). no new claims to deallocate, preemption: 0/6 nodes are available: 1 No preemption victims found for incoming pod, 5 Preemption is not helpful for scheduling."
0.511,Event,ADDED,eval-conflicts-rho020-r0-102-n6gg8.18d54332d3048aea,"reason=FailedScheduling count=None msg=0/6 nodes are available: 1 c_wall violated: 1 conflicting context pair(s) with node memory, 5 node(s) had untolerated taint(s). no new claims to deallocate, preemption: 0/6 nodes are available: 1 No preemption victims found for incoming pod, 5 Preemption is not helpful for scheduling."
0.5113,Event,ADDED,eval-conflicts-rho020-r0-102-n6gg8.18d543334afba300,reason=Scheduled count=None msg=Successfully assigned compute/eval-conflicts-rho020-r0-102-n6gg8 to kind-worker
0.5115,Event,ADDED,eval-conflicts-rho020-r0-102-n6gg8.18d54333645a6cf9,"reason=Pulled count=1 msg=Container image ""busybox:musl"" already present on machine"
0.5116,Event,ADDED,eval-conflicts-rho020-r0-102-n6gg8.18d5433365eccafb,reason=Created count=1 msg=Created container: task
0.512,Event,ADDED,eval-conflicts-rho020-r0-102-n6gg8.18d543336a5ab04c,reason=Started count=1 msg=Started container task
0.5122,Event,ADDED,eval-conflicts-rho020-r0-102.18d54332d232b6c7,reason=SuccessfulCreate count=1 msg=Created pod: eval-conflicts-rho020-r0-102-n6gg8
0.5124,Event,ADDED,eval-conflicts-rho020-r0-102.18d54338cc1344c2,reason=Completed count=1 msg=Job completed
0.5125,Event,ADDED,eval-conflicts-rho020-r0-103-tl7bz.18d543330dd92e5f,"reason=FailedScheduling count=None msg=0/6 nodes are available: 1 c_wall violated: 2 conflicting context pair(s) with node memory, 5 node(s) had untolerated taint(s). no new claims to deallocate, preemption: 0/6 nodes are available: 1 No preemption victims found for incoming pod, 5 Preemption is not helpful for scheduling."
0.5132,Event,ADDED,eval-conflicts-rho020-r0-103-tl7bz.18d543330e66b180,"reason=FailedScheduling count=None msg=0/6 nodes are available: 1 c_wall violated: 2 conflicting context pair(s) with node memory, 5 node(s) had untolerated taint(s). no new claims to deallocate, preemption: 0/6 nodes are available: 1 No preemption victims found for incoming pod, 5 Preemption is not helpful for scheduling."
0.5134,Event,ADDED,eval-conflicts-rho020-r0-103-tl7bz.18d543334e4be6aa,reason=Scheduled count=None msg=Successfully assigned compute/eval-conflicts-rho020-r0-103-tl7bz to kind-worker
0.5137,Event,ADDED,eval-conflicts-rho020-r0-103-tl7bz.18d5433369b7b549,"reason=Pulled count=1 msg=Container image ""busybox:musl"" already present on machine"
0.514,Event,ADDED,eval-conflicts-rho020-r0-103-tl7bz.18d543336e341e93,reason=Created count=1 msg=Created container: task
0.5142,Event,ADDED,eval-conflicts-rho020-r0-103-tl7bz.18d5433378985e60,reason=Started count=1 msg=Started container task
0.5144,Event,ADDED,eval-conflicts-rho020-r0-103.18d543330d9ceff4,reason=SuccessfulCreate count=1 msg=Created pod: eval-conflicts-rho020-r0-103-tl7bz
0.5146,Event,ADDED,eval-conflicts-rho020-r0-103.18d54339086cc73b,reason=Completed count=1 msg=Job completed
0.5148,Event,ADDED,eval-conflicts-rho020-r0-104-9bkt8.18d543334a427a9a,reason=Scheduled count=None msg=Successfully assigned compute/eval-conflicts-rho020-r0-104-9bkt8 to kind-worker
0.515,Event,ADDED,eval-conflicts-rho020-r0-104-9bkt8.18d54333654f60d2,"reason=Pulled count=1 msg=Container image ""busybox:musl"" already present on machine"
0.5152,Event,ADDED,eval-conflicts-rho020-r0-104-9bkt8.18d5433367332ba6,reason=Created count=1 msg=Created container: task
0.5155,Event,ADDED,eval-conflicts-rho020-r0-104-9bkt8.18d543336a5dd62e,reason=Started count=1 msg=Started container task
0.5157,Event,ADDED,eval-conflicts-rho020-r0-104.18d5433348cd942e,reason=SuccessfulCreate count=1 msg=Created pod: eval-conflicts-rho020-r0-104-9bkt8
0.516,Event,ADDED,eval-conflicts-rho020-r0-104.18d5433891589f65,reason=Completed count=1 msg=Job completed
0.5162,Event,ADDED,eval-conflicts-rho020-r0-105-jmmwr.18d54333850861f3,reason=Scheduled count=None msg=Successfully assigned compute/eval-conflicts-rho020-r0-105-jmmwr to kind-worker
0.5164,Event,ADDED,eval-conflicts-rho020-r0-105-jmmwr.18d54333a63296cd,"reason=Pulled count=1 msg=Container image ""busybox:musl"" already present on machine"
0.5166,Event,ADDED,eval-conflicts-rho020-r0-105-jmmwr.18d54333a76db299,reason=Created count=1 msg=Created container: task
0.5207,Event,ADDED,eval-conflicts-rho020-r0-105-jmmwr.18d54333b174d8cd,reason=Started count=1 msg=Started container task
0.521,Event,ADDED,eval-conflicts-rho020-r0-105.18d54333844f7d55,reason=SuccessfulCreate count=1 msg=Created pod: eval-conflicts-rho020-r0-105-jmmwr
0.5212,Event,ADDED,eval-conflicts-rho020-r0-105.18d5433909247d07,reason=Completed count=1 msg=Job completed
0.5214,Event,ADDED,eval-conflicts-rho020-r0-106-q2c54.18d54333c124143f,reason=Scheduled count=None msg=Successfully assigned compute/eval-conflicts-rho020-r0-106-q2c54 to kind-worker
0.5216,Event,ADDED,eval-conflicts-rho020-r0-106-q2c54.18d54333e077fabc,"reason=Pulled count=1 msg=Container image ""busybox:musl"" already present on machine"
0.5219,Event,ADDED,eval-conflicts-rho020-r0-106-q2c54.18d54333e2934701,reason=Created count=1 msg=Created container: task
0.5221,Event,ADDED,eval-conflicts-rho020-r0-106-q2c54.18d54333ece2bf33,reason=Started count=1 msg=Started container task
0.5222,Event,ADDED,eval-conflicts-rho020-r0-106.18d54333c07ecc2c,reason=SuccessfulCreate count=1 msg=Created pod: eval-conflicts-rho020-r0-106-q2c54
0.5224,Event,ADDED,eval-conflicts-rho020-r0-106.18d5433980f0b3f3,reason=Completed count=1 msg=Job completed
0.5226,Event,ADDED,eval-conflicts-rho020-r0-107-srlzc.18d54333ff638f63,reason=Scheduled count=None msg=Successfully assigned compute/eval-conflicts-rho020-r0-107-srlzc to kind-worker3
0.5228,Event,ADDED,eval-conflicts-rho020-r0-107-srlzc.18d543341d65a5d3,"reason=Pulled count=1 msg=Container image ""busybox:musl"" already present on machine"
0.523,Event,ADDED,eval-conflicts-rho020-r0-107-srlzc.18d543341edf6107,reason=Created count=1 msg=Created container: task
0.5232,Event,ADDED,eval-conflicts-rho020-r0-107-srlzc.18d5433423d89837,reason=Started count=1 msg=Started container task
0.5233,Event,ADDED,eval-conflicts-rho020-r0-107.18d54333fec93592,reason=SuccessfulCreate count=1 msg=Created pod: eval-conflicts-rho020-r0-107-srlzc
0.5235,Event,ADDED,eval-conflicts-rho020-r0-107.18d54339a8f207c5,reason=Completed count=1 msg=Job completed
0.5237,Event,ADDED,eval-conflicts-rho020-r0-108-7s979.18d543343a5373d7,reason=Scheduled count=None msg=Successfully assigned compute/eval-conflicts-rho020-r0-108-7s979 to kind-worker3
0.5239,Event,ADDED,eval-conflicts-rho020-r0-108-7s979.18d543345321cf3f,"reason=Pulled count=1 msg=Container image ""busybox:musl"" already present on machine"
0.5242,Event,ADDED,eval-conflicts-rho020-r0-108-7s979.18d54334545586f2,reason=Created count=1 msg=Created container: task
0.5244,Event,ADDED,eval-conflicts-rho020-r0-108-7s979.18d543345855ca01,reason=Started count=1 msg=Started container task
0.5246,Event,ADDED,eval-conflicts-rho020-r0-108.18d543343995c194,reason=SuccessfulCreate count=1 msg=Created pod: eval-conflicts-rho020-r0-108-7s979
0.525,Event,ADDED,eval-conflicts-rho020-r0-108.18d54339e47fa65b,reason=Completed count=1 msg=Job completed
0.5252,Event,ADDED,eval-conflicts-rho020-r0-109-j4drq.18d5433475c9844b,reason=Scheduled count=None msg=Successfully assigned compute/eval-conflicts-rho020-r0-109-j4drq to kind-worker3
0.5254,Event,ADDED,eval-conflicts-rho020-r0-109-j4drq.18d543348fa522ea,"reason=Pulled count=1 msg=Container image ""busybox:musl"" already present on machine"
0.5259,Event,ADDED,eval-conflicts-rho020-r0-109-j4drq.18d5433490c83860,reason=Created count=1 msg=Created container: task
0.5261,Event,ADDED,eval-conflicts-rho020-r0-109-j4drq.18d54334946a202c,reason=Started count=1 msg=Started container task
0.5263,Event,ADDED,eval-conflicts-rho020-r0-109.18d543347496e552,reason=SuccessfulCreate count=1 msg=Created pod: eval-conflicts-rho020-r0-109-j4drq
0.5264,Event,ADDED,eval-conflicts-rho020-r0-109.18d5433a20ba974f,reason=Completed count=1 msg=Job completed
0.5268,Event,ADDED,eval-conflicts-rho020-r0-110-spsck.18d54334afdda761,reason=Scheduled count=None msg=Successfully assigned compute/eval-conflicts-rho020-r0-110-spsck to kind-worker
0.527,Event,ADDED,eval-conflicts-rho020-r0-110-spsck.18d54334c8c5ccc0,"reason=Pulled count=1 msg=Container image ""busybox:musl"" already present on machine"
0.5274,Event,ADDED,eval-conflicts-rho020-r0-110-spsck.18d54334c9ed2156,reason=Created count=1 msg=Created container: task
0.5276,Event,ADDED,eval-conflicts-rho020-r0-110-spsck.18d54334cc1b2cfb,reason=Started count=1 msg=Started container task
0.5278,Event,ADDED,eval-conflicts-rho020-r0-110.18d54334af3eeefe,reason=SuccessfulCreate count=1 msg=Created pod: eval-conflicts-rho020-r0-110-spsck
0.5281,Event,ADDED,eval-conflicts-rho020-r0-110.18d5433a3556fb82,reason=Completed count=1 msg=Job completed
0.5283,Event,ADDED,eval-conflicts-rho020-r0-111-pdhlr.18d54334eb519428,reason=Scheduled count=None msg=Successfully assigned compute/eval-conflicts-rho020-r0-111-pdhlr to kind-worker
0.5285,Event,ADDED,eval-conflicts-rho020-r0-111-pdhlr.18d543350509e816,"reason=Pulled count=1 msg=Container image ""busybox:musl"" already present on machine"
0.5287,Event,ADDED,eval-conflicts-rho020-r0-111-pdhlr.18d5433506389770,reason=Created count=1 msg=Created container: task
0.529,Event,ADDED,eval-conflicts-rho020-r0-111-pdhlr.18d543350a87e52d,reason=Started count=1 msg=Started container task
0.5292,Event,ADDED,eval-conflicts-rho020-r0-111.18d54334ea9d3ecf,reason=SuccessfulCreate count=1 msg=Created pod: eval-conflicts-rho020-r0-111-pdhlr
0.5294,Event,ADDED,eval-conflicts-rho020-r0-111.18d5433a714badbe,reason=Completed count=1 msg=Job completed
0.5297,Event,ADDED,eval-conflicts-rho020-r0-112-v8c2w.18d5433526791102,reason=Scheduled count=None msg=Successfully assigned compute/eval-conflicts-rho020-r0-112-v8c2w to kind-worker2
0.53,Event,ADDED,eval-conflicts-rho020-r0-112-v8c2w.18d5433540213a3d,"reason=Pulled count=1 msg=Container image ""busybox:musl"" already present on machine"
0.5301,Event,ADDED,eval-conflicts-rho020-r0-112-v8c2w.18d54335413a0e0e,reason=Created count=1 msg=Created container: task
0.5303,Event,ADDED,eval-conflicts-rho020-r0-112-v8c2w.18d5433545f8a139,reason=Started count=1 msg=Started container task
0.5307,Event,ADDED,eval-conflicts-rho020-r0-112.18d5433525c5d917,reason=SuccessfulCreate count=1 msg=Created pod: eval-conflicts-rho020-r0-112-v8c2w
0.5309,Event,ADDED,eval-conflicts-rho020-r0-112.18d5433ab41148af,reason=Completed count=1 msg=Job completed
0.531,Event,ADDED,eval-conflicts-rho020-r0-113-7h6lx.18d5433562a320f5,reason=Scheduled count=None msg=Successfully assigned compute/eval-conflicts-rho020-r0-113-7h6lx to kind-worker2
0.5312,Event,ADDED,eval-conflicts-rho020-r0-113-7h6lx.18d5433580b63222,"reason=Pulled count=1 msg=Container image ""busybox:musl"" already present on machine"
0.5316,Event,ADDED,eval-conflicts-rho020-r0-113-7h6lx.18d543358223cd88,reason=Created count=1 msg=Created container: task
0.5318,Event,ADDED,eval-conflicts-rho020-r0-113-7h6lx.18d5433585659d6e,reason=Started count=1 msg=Started container task
0.5319,Event,ADDED,eval-conflicts-rho020-r0-113.18d5433561b78743,reason=SuccessfulCreate count=1 msg=Created pod: eval-conflicts-rho020-r0-113-7h6lx
0.5323,Event,ADDED,eval-conflicts-rho020-r0-113.18d5433af0a546bc,reason=Completed count=1 msg=Job completed
0.5324,Event,ADDED,eval-conflicts-rho020-r0-114-mfz8t.18d543359e328250,reason=Scheduled count=None msg=Successfully assigned compute/eval-conflicts-rho020-r0-114-mfz8t to kind-worker2
0.5326,Event,ADDED,eval-conflicts-rho020-r0-114-mfz8t.18d54335b8b75e0a,"reason=Pulled count=1 msg=Container image ""busybox:musl"" already present on machine"
0.5328,Event,ADDED,eval-conflicts-rho020-r0-114-mfz8t.18d54335b9cfc481,reason=Created count=1 msg=Created container: task
0.5332,Event,ADDED,eval-conflicts-rho020-r0-114-mfz8t.18d54335bef8628e,reason=Started count=1 msg=Started container task
0.5334,Event,ADDED,eval-conflicts-rho020-r0-114.18d543359d3e8085,reason=SuccessfulCreate count=1 msg=Created pod: eval-conflicts-rho020-r0-114-mfz8t
0.5335,Event,ADDED,eval-conflicts-rho020-r0-114.18d5433af122e179,reason=Completed count=1 msg=Job completed
0.5337,Event,ADDED,eval-conflicts-rho020-r0-115-gfvxq.18d54335d9bc8ea5,reason=Scheduled count=None msg=Successfully assigned compute/eval-conflicts-rho020-r0-115-gfvxq to kind-worker2
0.534,Event,ADDED,eval-conflicts-rho020-r0-115-gfvxq.18d54335f499bc8a,"reason=Pulled count=1 msg=Container image ""busybox:musl"" already present on machine"
0.5342,Event,ADDED,eval-conflicts-rho020-r0-115-gfvxq.18d54335f5c6a714,reason=Created count=1 msg=Created container: task
0.5344,Event,ADDED,eval-conflicts-rho020-r0-115-gfvxq.18d54335fbf0ab5b,reason=Started count=1 msg=Started container task
0.535,Event,ADDED,eval-conflicts-rho020-r0-115.18d54335d8cedfd7,reason=SuccessfulCreate count=1 msg=Created pod: eval-conflicts-rho020-r0-115-gfvxq
0.5354,Event,ADDED,eval-conflicts-rho020-r0-115.18d5433b6928b4cf,reason=Completed count=1 msg=Job completed
0.5357,Event,ADDED,eval-conflicts-rho020-r0-116-c5mws.18d54336181f9227,reason=Scheduled count=None msg=Successfully assigned compute/eval-conflicts-rho020-r0-116-c5mws to kind-worker2
0.5359,Event,ADDED,eval-conflicts-rho020-r0-116-c5mws.18d54336322a8931,"reason=Pulled count=1 msg=Container image ""busybox:musl"" already present on machine"
0.5362,Event,ADDED,eval-conflicts-rho020-r0-116-c5mws.18d54336337f9929,reason=Created count=1 msg=Created container: task
0.5363,Event,ADDED,eval-conflicts-rho020-r0-116-c5mws.18d5433637e4521b,reason=Started count=1 msg=Started container task
0.5365,Event,ADDED,eval-conflicts-rho020-r0-116.18d54336175b2b49,reason=SuccessfulCreate count=1 msg=Created pod: eval-conflicts-rho020-r0-116-c5mws
0.5367,Event,ADDED,eval-conflicts-rho020-r0-116.18d5433ba56d0f9e,reason=Completed count=1 msg=Job completed
0.5369,Event,ADDED,eval-conflicts-rho020-r0-117-p5mp5.18d5433650b032c7,reason=Scheduled count=None msg=Successfully assigned compute/eval-conflicts-rho020-r0-117-p5mp5 to kind-worker5
0.5375,Event,ADDED,eval-conflicts-rho020-r0-117-p5mp5.18d543366a60a27e,"reason=Pulled count=1 msg=Container image ""busybox:musl"" already present on machine"
0.5378,Event,ADDED,eval-conflicts-rho020-r0-117-p5mp5.18d543366b78f07b,reason=Created count=1 msg=Created container: task
0.5381,Event,ADDED,eval-conflicts-rho020-r0-117-p5mp5.18d543367072cab6,reason=Started count=1 msg=Started container task
0.5383,Event,ADDED,eval-conflicts-rho020-r0-117.18d543364fd24192,reason=SuccessfulCreate count=1 msg=Created pod: eval-conflicts-rho020-r0-117-p5mp5
0.5385,Event,ADDED,eval-conflicts-rho020-r0-117.18d5433bfd7b6388,reason=Completed count=1 msg=Job completed
0.5386,Event,ADDED,eval-conflicts-rho020-r0-118-cb7ph.18d543368d9368a1,reason=Scheduled count=None msg=Successfully assigned compute/eval-conflicts-rho020-r0-118-cb7ph to kind-worker2
0.5389,Event,ADDED,eval-conflicts-rho020-r0-118-cb7ph.18d54336aa9bba8e,"reason=Pulled count=1 msg=Container image ""busybox:musl"" already present on machine"
0.5391,Event,ADDED,eval-conflicts-rho020-r0-118-cb7ph.18d54336abdf302b,reason=Created count=1 msg=Created container: task
0.5393,Event,ADDED,eval-conflicts-rho020-r0-118-cb7ph.18d54336b01181f4,reason=Started count=1 msg=Started container task
0.5397,Event,ADDED,eval-conflicts-rho020-r0-118.18d543368c58a000,reason=SuccessfulCreate count=1 msg=Created pod: eval-conflicts-rho020-r0-118-cb7ph
0.5399,Event,ADDED,eval-conflicts-rho020-r0-118.18d5433c1eb71ba1,reason=Completed count=1 msg=Job completed
0.5401,Event,ADDED,eval-conflicts-rho020-r0-119-ps69q.18d54336cb0aad09,reason=Scheduled count=None msg=Successfully assigned compute/eval-conflicts-rho020-r0-119-ps69q to kind-worker
0.5403,Event,ADDED,eval-conflicts-rho020-r0-119-ps69q.18d54336e6773bed,"reason=Pulled count=1 msg=Container image ""busybox:musl"" already present on machine"
0.5407,Event,ADDED,eval-conflicts-rho020-r0-119-ps69q.18d54336e7b3e067,reason=Created count=1 msg=Created container: task
0.5409,Event,ADDED,eval-conflicts-rho020-r0-119-ps69q.18d54336eb4936c8,reason=Started count=1 msg=Started container task
0.5413,Event,ADDED,eval-conflicts-rho020-r0-119.18d54336ca109206,reason=SuccessfulCreate count=1 msg=Created pod: eval-conflicts-rho020-r0-119-ps69q
0.5415,Event,ADDED,eval-conflicts-rho020-r0-119.18d5433c4de94c93,reason=Completed count=1 msg=Job completed
0.5419,Event,ADDED,eval-conflicts-rho020-r0-120-j55mz.18d54337045a4fdd,reason=Scheduled count=None msg=Successfully assigned compute/eval-conflicts-rho020-r0-120-j55mz to kind-worker5
0.5421,Event,ADDED,eval-conflicts-rho020-r0-120-j55mz.18d543371dc38b7c,"reason=Pulled count=1 msg=Container image ""busybox:musl"" already present on machine"
0.5422,Event,ADDED,eval-conflicts-rho020-r0-120-j55mz.18d543371eef40b0,reason=Created count=1 msg=Created container: task
0.5426,Event,ADDED,eval-conflicts-rho020-r0-120-j55mz.18d5433723f9f563,reason=Started count=1 msg=Started container task
0.5427,Event,ADDED,eval-conflicts-rho020-r0-120.18d5433703231e17,reason=SuccessfulCreate count=1 msg=Created pod: eval-conflicts-rho020-r0-120-j55mz
0.5429,Event,ADDED,eval-conflicts-rho020-r0-120.18d5433cae480659,reason=Completed count=1 msg=Job completed
0.5431,Event,ADDED,eval-conflicts-rho020-r0-121-c9nfn.18d543373fd841f5,reason=Scheduled count=None msg=Successfully assigned compute/eval-conflicts-rho020-r0-121-c9nfn to kind-worker2
0.5434,Event,ADDED,eval-conflicts-rho020-r0-121-c9nfn.18d543375a6fa46d,"reason=Pulled count=1 msg=Container image ""busybox:musl"" already present on machine"
0.5436,Event,ADDED,eval-conflicts-rho020-r0-121-c9nfn.18d543375b9a7e7c,reason=Created count=1 msg=Created container: task
0.5438,Event,ADDED,eval-conflicts-rho020-r0-121-c9nfn.18d543375db39f16,reason=Started count=1 msg=Started container task
0.5439,Event,ADDED,eval-conflicts-rho020-r0-121.18d543373e9d60bc,reason=SuccessfulCreate count=1 msg=Created pod: eval-conflicts-rho020-r0-121-c9nfn
0.5443,Event,ADDED,eval-conflicts-rho020-r0-121.18d5433ccec9c3ff,reason=Completed count=1 msg=Job completed
0.5444,Event,ADDED,eval-conflicts-rho020-r0-122-g5rw4.18d543377b358e29,reason=Scheduled count=None msg=Successfully assigned compute/eval-conflicts-rho020-r0-122-g5rw4 to kind-worker5
0.5446,Event,ADDED,eval-conflicts-rho020-r0-122-g5rw4.18d54337950585b7,"reason=Pulled count=1 msg=Container image ""busybox:musl"" already present on machine"
0.5448,Event,ADDED,eval-conflicts-rho020-r0-122-g5rw4.18d54337961a3f9c,reason=Created count=1 msg=Created container: task
0.5451,Event,ADDED,eval-conflicts-rho020-r0-122-g5rw4.18d54337981d60de,reason=Started count=1 msg=Started container task
0.5453,Event,ADDED,eval-conflicts-rho020-r0-122.18d5433779dd324b,reason=SuccessfulCreate count=1 msg=Created pod: eval-conflicts-rho020-r0-122-g5rw4
0.5455,Event,ADDED,eval-conflicts-rho020-r0-122.18d5433d25e46cd2,reason=Completed count=1 msg=Job completed
0.5457,Event,ADDED,eval-conflicts-rho020-r0-123-p98fb.18d54337b78704dd,reason=Scheduled count=None msg=Successfully assigned compute/eval-conflicts-rho020-r0-123-p98fb to kind-worker5
0.5459,Event,ADDED,eval-conflicts-rho020-r0-123-p98fb.18d54337d07720f6,"reason=Pulled count=1 msg=Container image ""busybox:musl"" already present on machine"
0.5462,Event,ADDED,eval-conflicts-rho020-r0-123-p98fb.18d54337d1a69846,reason=Created count=1 msg=Created container: task
0.5468,Event,ADDED,eval-conflicts-rho020-r0-123-p98fb.18d54337d3b9583c,reason=Started count=1 msg=Started container task
0.547,Event,ADDED,eval-conflicts-rho020-r0-123.18d54337b65f25bf,reason=SuccessfulCreate count=1 msg=Created pod: eval-conflicts-rho020-r0-123-p98fb
0.5471,Event,ADDED,eval-conflicts-rho020-r0-123.18d5433d63e8ab31,reason=Completed count=1 msg=Job completed
0.5473,Event,ADDED,eval-conflicts-rho020-r0-124-ddjt7.18d54337f1ff9eb1,"reason=FailedScheduling count=None msg=0/6 nodes are available: 2 c_wall violated: 2 conflicting context pair(s) with node memory, 4 node(s) had untolerated taint(s). no new claims to deallocate, preemption: 0/6 nodes are available: 2 No preemption victims found for incoming pod, 4 Preemption is not helpful for scheduling."
0.5476,Event,ADDED,eval-conflicts-rho020-r0-124-ddjt7.18d54337f357a591,"reason=FailedScheduling count=None msg=0/6 nodes are available: 2 c_wall violated: 2 conflicting context pair(s) with node memory, 4 node(s) had untolerated taint(s). no new claims to deallocate, preemption: 0/6 nodes are available: 2 No preemption victims found for incoming pod, 4 Preemption is not helpful for scheduling."
0.5478,Event,ADDED,eval-conflicts-rho020-r0-124-ddjt7.18d54339bb8eb646,"reason=FailedScheduling count=None msg=0/6 nodes are available: 1 c_wall violated: 2 conflicting context pair(s) with node memory, 5 node(s) had untolerated taint(s). no new claims to deallocate, preemption: 0/6 nodes are available: 1 No preemption victims found for incoming pod, 5 Preemption is not helpful for scheduling."
0.5479,Event,ADDED,eval-conflicts-rho020-r0-124-ddjt7.18d5433afeae5f69,reason=Scheduled count=None msg=Successfully assigned compute/eval-conflicts-rho020-r0-124-ddjt7 to kind-worker4
0.5481,Event,ADDED,eval-conflicts-rho020-r0-124-ddjt7.18d5433b1ea90156,"reason=Pulled count=1 msg=Container image ""busybox:musl"" already present on machine"
0.5483,Event,ADDED,eval-conflicts-rho020-r0-124-ddjt7.18d5433b214d9bd1,reason=Created count=1 msg=Created container: task
0.5485,Event,ADDED,eval-conflicts-rho020-r0-124-ddjt7.18d5433b26246c5a,reason=Started count=1 msg=Started container task
0.5487,Event,ADDED,eval-conflicts-rho020-r0-124.18d54337f1823336,reason=SuccessfulCreate count=1 msg=Created pod: eval-conflicts-rho020-r0-124-ddjt7
0.5489,Event,ADDED,eval-conflicts-rho020-r0-124.18d54340ade88f40,reason=Completed count=1 msg=Job completed
0.5492,Event,ADDED,eval-conflicts-rho020-r0-125-7f6f9.18d543382eb0f928,"reason=FailedScheduling count=None msg=0/6 nodes are available: 1 c_wall violated: 1 conflicting context pair(s) with node memory, 1 c_wall violated: 2 conflicting context pair(s) with node memory, 4 node(s) had untolerated taint(s). no new claims to deallocate, preemption: 0/6 nodes are available: 2 No preemption victims found for incoming pod, 4 Preemption is not helpful for scheduling."
0.5496,Event,ADDED,eval-conflicts-rho020-r0-125-7f6f9.18d543382f6e37e6,"reason=FailedScheduling count=None msg=0/6 nodes are available: 1 c_wall violated: 1 conflicting context pair(s) with node memory, 1 c_wall violated: 2 conflicting context pair(s) with node memory, 4 node(s) had untolerated taint(s). no new claims to deallocate, preemption: 0/6 nodes are available: 2 No preemption victims found for incoming pod, 4 Preemption is not helpful for scheduling."
0.5501,Event,ADDED,eval-conflicts-rho020-r0-125-7f6f9.18d543386eb174a7,"reason=FailedScheduling count=None msg=0/6 nodes are available: 2 c_wall violated: 2 conflicting context pair(s) with node memory, 4 node(s) had untolerated taint(s). no new claims to deallocate, preemption: 0/6 nodes are available: 2 No preemption victims found for incoming pod, 4 Preemption is not helpful for scheduling."
0.5503,Event,ADDED,eval-conflicts-rho020-r0-125-7f6f9.18d543399b05028a,"reason=FailedScheduling count=None msg=0/6 nodes are available: 1 c_wall violated: 2 conflicting context pair(s) with node memory, 1 c_wall violated: 3 conflicting context pair(s) with node memory, 4 node(s) had untolerated taint(s). no new claims to deallocate, preemption: 0/6 nodes are available: 2 No preemption victims found for incoming pod, 4 Preemption is not helpful for scheduling."
0.5507,Event,ADDED,eval-conflicts-rho020-r0-125-7f6f9.18d54339bbef18ee,"reason=FailedScheduling count=None msg=0/6 nodes are available: 1 c_wall violated: 2 conflicting context pair(s) with node memory, 5 node(s) had untolerated taint(s). no new claims to deallocate, preemption: 0/6 nodes are available: 1 No preemption victims found for incoming pod, 5 Preemption is not helpful for scheduling."
0.5509,Event,ADDED,eval-conflicts-rho020-r0-125-7f6f9.18d5433a0c11b719,"reason=FailedScheduling count=None msg=0/6 nodes are available: 1 c_wall violated: 3 conflicting context pair(s) with node memory, 5 node(s) had untolerated taint(s). no new claims to deallocate, preemption: 0/6 nodes are available: 1 No preemption victims found for incoming pod, 5 Preemption is not helpful for scheduling."
0.5511,Event,ADDED,eval-conflicts-rho020-r0-125-7f6f9.18d5433afe62034d,"reason=FailedScheduling count=None msg=0/6 nodes are available: 1 c_wall violated: 1 conflicting context pair(s) with node memory, 5 node(s) had untolerated taint(s). no new claims to deallocate, preemption: 0/6 nodes are available: 1 No preemption victims found for incoming pod, 5 Preemption is not helpful for scheduling."
0.5514,Event,ADDED,eval-conflicts-rho020-r0-125-7f6f9.18d5433aff68ff5e,"reason=FailedScheduling count=None msg=0/6 nodes are available: 1 c_wall violated: 1 conflicting context pair(s) with node memory, 5 node(s) had untolerated taint(s). no new claims to deallocate, preemption: 0/6 nodes are available: 1 No preemption victims found for incoming pod, 5 Preemption is not helpful for scheduling."
0.5516,Event,ADDED,eval-conflicts-rho020-r0-125-7f6f9.18d5433bed7d1667,"reason=FailedScheduling count=None msg=0/6 nodes are available: 1 c_wall violated: 2 conflicting context pair(s) with node memory, 5 node(s) had untolerated taint(s). no new claims to deallocate, preemption: 0/6 nodes are available: 1 No preemption victims found for incoming pod, 5 Preemption is not helpful for scheduling."
0.5519,Event,ADDED,eval-conflicts-rho020-r0-125-7f6f9.18d5433c23c51e88,"reason=FailedScheduling count=None msg=0/6 nodes are available: 1 c_wall violated: 3 conflicting context pair(s) with node memory, 5 node(s) had untolerated taint(s). no new claims to deallocate, preemption: 0/6 nodes are available: 1 No preemption victims found for incoming pod, 5 Preemption is not helpful for scheduling."
0.5522,Event,ADDED,eval-conflicts-rho020-r0-125-7f6f9.18d5433cb329c8eb,reason=Scheduled count=None msg=Successfully assigned compute/eval-conflicts-rho020-r0-125-7f6f9 to kind-worker
0.5523,Event,ADDED,eval-conflicts-rho020-r0-125-7f6f9.18d5433cd0819800,"reason=Pulled count=1 msg=Container image ""busybox:musl"" already present on machine"
0.5525,Event,ADDED,eval-conflicts-rho020-r0-125-7f6f9.18d5433cd1d582a2,reason=Created count=1 msg=Created container: task
0.5527,Event,ADDED,eval-conflicts-rho020-r0-125-7f6f9.18d5433cd65a6b12,reason=Started count=1 msg=Started container task
0.5532,Event,ADDED,eval-conflicts-rho020-r0-125.18d543382e4db494,reason=SuccessfulCreate count=1 msg=Created pod: eval-conflicts-rho020-r0-125-7f6f9
0.5534,Event,ADDED,eval-conflicts-rho020-r0-125.18d5434227d8a4c8,reason=Completed count=1 msg=Job completed
0.5536,Event,ADDED,eval-conflicts-rho020-r0-126-rjtbw.18d54338692d2e3d,reason=Scheduled count=None msg=Successfully assigned compute/eval-conflicts-rho020-r0-126-rjtbw to kind-worker5
0.554,Event,ADDED,eval-conflicts-rho020-r0-126-rjtbw.18d5433882541dc1,"reason=Pulled count=1 msg=Container image ""busybox:musl"" already present on machine"
0.5542,Event,ADDED,eval-conflicts-rho020-r0-126-rjtbw.18d543388371d39f,reason=Created count=1 msg=Created container: task
0.5544,Event,ADDED,eval-conflicts-rho020-r0-126-rjtbw.18d54338885cea7b,reason=Started count=1 msg=Started container task
0.5546,Event,ADDED,eval-conflicts-rho020-r0-126.18d54338684fe918,reason=SuccessfulCreate count=1 msg=Created pod: eval-conflicts-rho020-r0-126-rjtbw
0.5549,Event,ADDED,eval-conflicts-rho020-r0-126.18d5433e19ea8849,reason=Completed count=1 msg=Job completed
0.5551,Event,ADDED,eval-conflicts-rho020-r0-127-5gjkp.18d54338a606dff1,reason=Scheduled count=None msg=Successfully assigned compute/eval-conflicts-rho020-r0-127-5gjkp to kind-worker2
0.5553,Event,ADDED,eval-conflicts-rho020-r0-127-5gjkp.18d54338c1f867c9,"reason=Pulled count=1 msg=Container image ""busybox:musl"" already present on machine"
0.5554,Event,ADDED,eval-conflicts-rho020-r0-127-5gjkp.18d54338c34a3a96,reason=Created count=1 msg=Created container: task
0.5558,Event,ADDED,eval-conflicts-rho020-r0-127-5gjkp.18d54338c8e5013d,reason=Started count=1 msg=Started container task
0.556,Event,ADDED,eval-conflicts-rho020-r0-127.18d54338a5278721,reason=SuccessfulCreate count=1 msg=Created pod: eval-conflicts-rho020-r0-127-5gjkp
0.5562,Event,ADDED,eval-conflicts-rho020-r0-127.18d5433e35c60f56,reason=Completed count=1 msg=Job completed
0.5564,Event,ADDED,eval-conflicts-rho020-r0-128-ds4j6.18d54338e03f2c5b,reason=Scheduled count=None msg=Successfully assigned compute/eval-conflicts-rho020-r0-128-ds4j6 to kind-worker5
0.5566,Event,ADDED,eval-conflicts-rho020-r0-128-ds4j6.18d54338fa6a8aff,"reason=Pulled count=1 msg=Container image ""busybox:musl"" already present on machine"
0.5568,Event,ADDED,eval-conflicts-rho020-r0-128-ds4j6.18d54338fb8411d1,reason=Created count=1 msg=Created container: task
0.5569,Event,ADDED,eval-conflicts-rho020-r0-128-ds4j6.18d54338ff2ae564,reason=Started count=1 msg=Started container task
0.5572,Event,ADDED,eval-conflicts-rho020-r0-128.18d54338df61706a,reason=SuccessfulCreate count=1 msg=Created pod: eval-conflicts-rho020-r0-128-ds4j6
0.5574,Event,ADDED,eval-conflicts-rho020-r0-128.18d5433e8e3f4162,reason=Completed count=1 msg=Job completed
0.5575,Event,ADDED,eval-conflicts-rho020-r0-129-qtfbw.18d543391cc13e9e,"reason=FailedScheduling count=None msg=0/6 nodes are available: 2 c_wall violated: 1 conflicting context pair(s) with node memory, 4 node(s) had untolerated taint(s). no new claims to deallocate, preemption: 0/6 nodes are available: 2 No preemption victims found for incoming pod, 4 Preemption is not helpful for scheduling."
0.5579,Event,ADDED,eval-conflicts-rho020-r0-129-qtfbw.18d543391d60f34f,"reason=FailedScheduling count=None msg=0/6 nodes are available: 2 c_wall violated: 1 conflicting context pair(s) with node memory, 4 node(s) had untolerated taint(s). no new claims to deallocate, preemption: 0/6 nodes are available: 2 No preemption victims found for incoming pod, 4 Preemption is not helpful for scheduling."
0.5582,Event,ADDED,eval-conflicts-rho020-r0-129-qtfbw.18d54339bbc07c48,"reason=FailedScheduling count=None msg=0/6 nodes are available: 1 c_wall violated: 1 conflicting context pair(s) with node memory, 5 node(s) had untolerated taint(s). no new claims to deallocate, preemption: 0/6 nodes are available: 1 No preemption victims found for incoming pod, 5 Preemption is not helpful for scheduling."
0.5583,Event,ADDED,eval-conflicts-rho020-r0-129-qtfbw.18d5433afede3c8c,reason=Scheduled count=None msg=Successfully assigned compute/eval-conflicts-rho020-r0-129-qtfbw to kind-worker4
0.5592,Event,ADDED,eval-conflicts-rho020-r0-129-qtfbw.18d5433b1efa6b85,"reason=Pulled count=1 msg=Container image ""busybox:musl"" already present on machine"
0.5596,Event,ADDED,eval-conflicts-rho020-r0-129-qtfbw.18d5433b2265990c,reason=Created count=1 msg=Created container: task
0.5598,Event,ADDED,eval-conflicts-rho020-r0-129-qtfbw.18d5433b27570770,reason=Started count=1 msg=Started container task
0.56,Event,ADDED,eval-conflicts-rho020-r0-129.18d543391c654ac7,reason=SuccessfulCreate count=1 msg=Created pod: eval-conflicts-rho020-r0-129-qtfbw
0.5603,Event,ADDED,eval-conflicts-rho020-r0-129.18d54340ade22ae9,reason=Completed count=1 msg=Job completed
0.5605,Event,ADDED,eval-conflicts-rho020-r0-130-8l4tb.18d54339586f6f0b,reason=Scheduled count=None msg=Successfully assigned compute/eval-conflicts-rho020-r0-130-8l4tb to kind-worker2
0.5606,Event,ADDED,eval-conflicts-rho020-r0-130-8l4tb.18d543397395e87f,"reason=Pulled count=1 msg=Container image ""busybox:musl"" already present on machine"
0.5609,Event,ADDED,eval-conflicts-rho020-r0-130-8l4tb.18d5433974c419ae,reason=Created count=1 msg=Created container: task
0.5611,Event,ADDED,eval-conflicts-rho020-r0-130-8l4tb.18d543397cf9ef54,reason=Started count=1 msg=Started container task
0.5614,Event,ADDED,eval-conflicts-rho020-r0-130.18d543395785701b,reason=SuccessfulCreate count=1 msg=Created pod: eval-conflicts-rho020-r0-130-8l4tb
0.5615,Event,ADDED,eval-conflicts-rho020-r0-130.18d5433eed92f346,reason=Completed count=1 msg=Job completed
0.5617,Event,ADDED,eval-conflicts-rho020-r0-131-nxx2f.18d54339937a7361,reason=Scheduled count=None msg=Successfully assigned compute/eval-conflicts-rho020-r0-131-nxx2f to kind-worker2
0.5619,Event,ADDED,eval-conflicts-rho020-r0-131-nxx2f.18d54339ada014f3,"reason=Pulled count=1 msg=Container image ""busybox:musl"" already present on machine"
0.5621,Event,ADDED,eval-conflicts-rho020-r0-131-nxx2f.18d54339aecc75ee,reason=Created count=1 msg=Created container: task
0.5623,Event,ADDED,eval-conflicts-rho020-r0-131-nxx2f.18d54339b270b65a,reason=Started count=1 msg=Started container task
0.5624,Event,ADDED,eval-conflicts-rho020-r0-131.18d54339929f8bb2,reason=SuccessfulCreate count=1 msg=Created pod: eval-conflicts-rho020-r0-131-nxx2f
0.5626,Event,ADDED,eval-conflicts-rho020-r0-131.18d5433f260dc982,reason=Completed count=1 msg=Job completed
0.5628,Event,ADDED,eval-conflicts-rho020-r0-132-m4x2z.18d54339ce6ac785,"reason=FailedScheduling count=None msg=0/6 nodes are available: 1 c_wall violated: 1 conflicting context pair(s) with node memory, 5 node(s) had untolerated taint(s). no new claims to deallocate, preemption: 0/6 nodes are available: 1 No preemption victims found for incoming pod, 5 Preemption is not helpful for scheduling."
0.563,Event,ADDED,eval-conflicts-rho020-r0-132-m4x2z.18d54339cef84289,"reason=FailedScheduling count=None msg=0/6 nodes are available: 1 c_wall violated: 1 conflicting context pair(s) with node memory, 5 node(s) had untolerated taint(s). no new claims to deallocate, preemption: 0/6 nodes are available: 1 No preemption victims found for incoming pod, 5 Preemption is not helpful for scheduling."
0.5633,Event,ADDED,eval-conflicts-rho020-r0-132-m4x2z.18d5433a0fed43a3,"reason=FailedScheduling count=None msg=0/6 nodes are available: 1 c_wall violated: 2 conflicting context pair(s) with node memory, 5 node(s) had untolerated taint(s). no new claims to deallocate, preemption: 0/6 nodes are available: 1 No preemption victims found for incoming pod, 5 Preemption is not helpful for scheduling."
0.5634,Event,ADDED,eval-conflicts-rho020-r0-132-m4x2z.18d5433afed6cd0b,reason=Scheduled count=None msg=Successfully assigned compute/eval-conflicts-rho020-r0-132-m4x2z to kind-worker4
0.5639,Event,ADDED,eval-conflicts-rho020-r0-132-m4x2z.18d5433b1f0f8ee3,"reason=Pulled count=1 msg=Container image ""busybox:musl"" already present on machine"
0.5641,Event,ADDED,eval-conflicts-rho020-r0-132-m4x2z.18d5433b224c3b9d,reason=Created count=1 msg=Created container: task
0.5642,Event,ADDED,eval-conflicts-rho020-r0-132-m4x2z.18d5433b27557127,reason=Started count=1 msg=Started container task
0.5644,Event,ADDED,eval-conflicts-rho020-r0-132.18d54339ce27f958,reason=SuccessfulCreate count=1 msg=Created pod: eval-conflicts-rho020-r0-132-m4x2z
0.5648,Event,ADDED,eval-conflicts-rho020-r0-132.18d54340713b577f,reason=Completed count=1 msg=Job completed
0.565,Event,ADDED,eval-conflicts-rho020-r0-133-zht2l.18d5433a0a3a11d4,reason=Scheduled count=None msg=Successfully assigned compute/eval-conflicts-rho020-r0-133-zht2l to kind-worker5
0.5652,Event,ADDED,eval-conflicts-rho020-r0-133-zht2l.18d5433a26186306,"reason=Pulled count=1 msg=Container image ""busybox:musl"" already present on machine"
0.5655,Event,ADDED,eval-conflicts-rho020-r0-133-zht2l.18d5433a273dd053,reason=Created count=1 msg=Created container: task
0.5656,Event,ADDED,eval-conflicts-rho020-r0-133-zht2l.18d5433a2b1e98d1,reason=Started count=1 msg=Started container task
0.5658,Event,ADDED,eval-conflicts-rho020-r0-133.18d5433a09bc2022,reason=SuccessfulCreate count=1 msg=Created pod: eval-conflicts-rho020-r0-133-zht2l
0.566,Event,ADDED,eval-conflicts-rho020-r0-133.18d5433fbd3a7478,reason=Completed count=1 msg=Job completed
0.5665,Event,ADDED,eval-conflicts-rho020-r0-134-6lz4p.18d5433a45b3edb5,reason=Scheduled count=None msg=Successfully assigned compute/eval-conflicts-rho020-r0-134-6lz4p to kind-worker5
0.5667,Event,ADDED,eval-conflicts-rho020-r0-134-6lz4p.18d5433a5e14d31b,"reason=Pulled count=1 msg=Container image ""busybox:musl"" already present on machine"
0.5668,Event,ADDED,eval-conflicts-rho020-r0-134-6lz4p.18d5433a5ff0ffaf,reason=Created count=1 msg=Created container: task
0.567,Event,ADDED,eval-conflicts-rho020-r0-134-6lz4p.18d5433a6448e4fa,reason=Started count=1 msg=Started container task
0.5672,Event,ADDED,eval-conflicts-rho020-r0-134.18d5433a45234eae,reason=SuccessfulCreate count=1 msg=Created pod: eval-conflicts-rho020-r0-134-6lz4p
0.5674,Event,ADDED,eval-conflicts-rho020-r0-134.18d5433ff89e4bc3,reason=Completed count=1 msg=Job completed
0.5675,Event,ADDED,eval-conflicts-rho020-r0-135-wxpdc.18d5433a812a8249,"reason=FailedScheduling count=None msg=0/6 nodes are available: 1 c_wall violated: 2 conflicting context pair(s) with node memory, 5 node(s) had untolerated taint(s). no new claims to deallocate, preemption: 0/6 nodes are available: 1 No preemption victims found for incoming pod, 5 Preemption is not helpful for scheduling."
0.5678,Event,ADDED,eval-conflicts-rho020-r0-135-wxpdc.18d5433a81ad7e29,"reason=FailedScheduling count=None msg=0/6 nodes are available: 1 c_wall violated: 2 conflicting context pair(s) with node memory, 5 node(s) had untolerated taint(s). no new claims to deallocate, preemption: 0/6 nodes are available: 1 No preemption victims found for incoming pod, 5 Preemption is not helpful for scheduling."
0.5679,Event,ADDED,eval-conflicts-rho020-r0-135-wxpdc.18d5433afde770c9,reason=Scheduled count=None msg=Successfully assigned compute/eval-conflicts-rho020-r0-135-wxpdc to kind-worker4
0.5681,Event,ADDED,eval-conflicts-rho020-r0-135-wxpdc.18d5433b1e8a4dda,"reason=Pulled count=1 msg=Container image ""busybox:musl"" already present on machine"
0.5683,Event,ADDED,eval-conflicts-rho020-r0-135-wxpdc.18d5433b21740ab0,reason=Created count=1 msg=Created container: task
0.5685,Event,ADDED,eval-conflicts-rho020-r0-135-wxpdc.18d5433b26a3537d,reason=Started count=1 msg=Started container task
0.5686,Event,ADDED,eval-conflicts-rho020-r0-135.18d5433a80e9ce0a,reason=SuccessfulCreate count=1 msg=Created pod: eval-conflicts-rho020-r0-135-wxpdc
0.5688,Event,ADDED,eval-conflicts-rho020-r0-135.18d54340ade2eec4,reason=Completed count=1 msg=Job completed
0.5692,Event,ADDED,eval-conflicts-rho020-r0-136-xbgpj.18d5433abf1238f5,reason=Scheduled count=None msg=Successfully assigned compute/eval-conflicts-rho020-r0-136-xbgpj to kind-worker5
0.5693,Event,ADDED,eval-conflicts-rho020-r0-136-xbgpj.18d5433ad84dc10a,"reason=Pulled count=1 msg=Container image ""busybox:musl"" already present on machine"
0.5695,Event,ADDED,eval-conflicts-rho020-r0-136-xbgpj.18d5433ad9783ea3,reason=Created count=1 msg=Created container: task
0.5697,Event,ADDED,eval-conflicts-rho020-r0-136-xbgpj.18d5433adb985781,reason=Started count=1 msg=Started container task
0.5699,Event,ADDED,eval-conflicts-rho020-r0-136.18d5433abe746f66,reason=SuccessfulCreate count=1 msg=Created pod: eval-conflicts-rho020-r0-136-xbgpj
0.5701,Event,ADDED,eval-conflicts-rho020-r0-136.18d5434072211b86,reason=Completed count=1 msg=Job completed
0.5703,Event,ADDED,eval-conflicts-rho020-r0-137-5sqxt.18d5433af83290f0,"reason=FailedScheduling count=None msg=0/6 nodes are available: 6 node(s) had untolerated taint(s). no new claims to deallocate, preemption: 0/6 nodes are available: 6 Preemption is not helpful for scheduling."
0.5704,Event,ADDED,eval-conflicts-rho020-r0-137-5sqxt.18d5433affaed556,reason=Scheduled count=None msg=Successfully assigned compute/eval-conflicts-rho020-r0-137-5sqxt to kind-worker4
0.5706,Event,ADDED,eval-conflicts-rho020-r0-137-5sqxt.18d5433b1ec9bf2e,"reason=Pulled count=1 msg=Container image ""busybox:musl"" already present on machine"
0.5708,Event,ADDED,eval-conflicts-rho020-r0-137-5sqxt.18d5433b220b84d7,reason=Created count=1 msg=Created container: task
0.5709,Event,ADDED,eval-conflicts-rho020-r0-137-5sqxt.18d5433b27556ae7,reason=Started count=1 msg=Started container task
0.5711,Event,ADDED,eval-conflicts-rho020-r0-137.18d5433af829cf42,reason=SuccessfulCreate count=1 msg=Created pod: eval-conflicts-rho020-r0-137-5sqxt
0.5713,Event,ADDED,eval-conflicts-rho020-r0-137.18d54340713b4d06,reason=Completed count=1 msg=Job completed
0.5714,Event,ADDED,eval-conflicts-rho020-r0-138-sbfxh.18d5433b34066910,"reason=FailedScheduling count=None msg=0/6 nodes are available: 1 c_wall violated: 1 conflicting context pair(s) with node memory, 5 node(s) had untolerated taint(s). no new claims to deallocate, preemption: 0/6 nodes are available: 1 No preemption victims found for incoming pod, 5 Preemption is not helpful for scheduling."
0.5716,Event,ADDED,eval-conflicts-rho020-r0-138-sbfxh.18d5433b34940647,"reason=FailedScheduling count=None msg=0/6 nodes are available: 1 c_wall violated: 1 conflicting context pair(s) with node memory, 5 node(s) had untolerated taint(s). no new claims to deallocate, preemption: 0/6 nodes are available: 1 No preemption victims found for incoming pod, 5 Preemption is not helpful for scheduling."
0.5718,Event,ADDED,eval-conflicts-rho020-r0-138-sbfxh.18d5433caf229c69,reason=Scheduled count=None msg=Successfully assigned compute/eval-conflicts-rho020-r0-138-sbfxh to kind-worker
0.5719,Event,ADDED,eval-conflicts-rho020-r0-138-sbfxh.18d5433ccb1b300b,"reason=Pulled count=1 msg=Container image ""busybox:musl"" already present on machine"
0.5721,Event,ADDED,eval-conflicts-rho020-r0-138-sbfxh.18d5433ccc9cca53,reason=Created count=1 msg=Created container: task
0.5723,Event,ADDED,eval-conflicts-rho020-r0-138-sbfxh.18d5433cd05461bc,reason=Started count=1 msg=Started container task
0.5724,Event,ADDED,eval-conflicts-rho020-r0-138.18d5433b33c9a15e,reason=SuccessfulCreate count=1 msg=Created pod: eval-conflicts-rho020-r0-138-sbfxh
0.5726,Event,ADDED,eval-conflicts-rho020-r0-138.18d54342661c45f5,reason=Completed count=1 msg=Job completed
0.5728,Event,ADDED,eval-conflicts-rho020-r0-139-qxv8m.18d5433b707db2f7,"reason=FailedScheduling count=None msg=0/6 nodes are available: 1 c_wall violated: 1 conflicting context pair(s) with node memory, 5 node(s) had untolerated taint(s). no new claims to deallocate, preemption: 0/6 nodes are available: 1 No preemption victims found for incoming pod, 5 Preemption is not helpful for scheduling."
0.5732,Event,ADDED,eval-conflicts-rho020-r0-139-qxv8m.18d5433b71336ae6,"reason=FailedScheduling count=None msg=0/6 nodes are available: 1 c_wall violated: 1 conflicting context pair(s) with node memory, 5 node(s) had untolerated taint(s). no new claims to deallocate, preemption: 0/6 nodes are available: 1 No preemption victims found for incoming pod, 5 Preemption is not helpful for scheduling."
0.5736,Event,ADDED,eval-conflicts-rho020-r0-139-qxv8m.18d5433cb7739027,"reason=FailedScheduling count=None msg=0/6 nodes are available: 2 c_wall violated: 1 conflicting context pair(s) with node memory, 4 node(s) had untolerated taint(s). no new claims to deallocate, preemption: 0/6 nodes are available: 2 No preemption victims found for incoming pod, 4 Preemption is not helpful for scheduling."
0.5741,Event,ADDED,eval-conflicts-rho020-r0-139-qxv8m.18d5433e694a2b90,reason=Scheduled count=None msg=Successfully assigned compute/eval-conflicts-rho020-r0-139-qxv8m to kind-worker3
0.5743,Event,ADDED,eval-conflicts-rho020-r0-139-qxv8m.18d5433e82d079a1,"reason=Pulled count=1 msg=Container image ""busybox:musl"" already present on machine"
0.5745,Event,ADDED,eval-conflicts-rho020-r0-139-qxv8m.18d5433e83f8c0c5,reason=Created count=1 msg=Created container: task
0.5748,Event,ADDED,eval-conflicts-rho020-r0-139-qxv8m.18d5433e8c2efa52,reason=Started count=1 msg=Started container task
0.5752,Event,ADDED,eval-conflicts-rho020-r0-139.18d5433b703c4e3c,reason=SuccessfulCreate count=1 msg=Created pod: eval-conflicts-rho020-r0-139-qxv8m
0.5753,Event,ADDED,eval-conflicts-rho020-r0-139.18d54343efbf599b,reason=Completed count=1 msg=Job completed
0.5755,Event,ADDED,eval-conflicts-rho020-r0-140-5xwbp.18d5433bab94eac8,"reason=FailedScheduling count=None msg=0/6 nodes are available: 1 c_wall violated: 1 conflicting context pair(s) with node memory, 5 node(s) had untolerated taint(s). no new claims to deallocate, preemption: 0/6 nodes are available: 1 No preemption victims found for incoming pod, 5 Preemption is not helpful for scheduling."
0.5758,Event,ADDED,eval-conflicts-rho020-r0-140-5xwbp.18d5433bac1b18c1,"reason=FailedScheduling count=None msg=0/6 nodes are available: 1 c_wall violated: 1 conflicting context pair(s) with node memory, 5 node(s) had untolerated taint(s). no new claims to deallocate, preemption: 0/6 nodes are available: 1 No preemption victims found for incoming pod, 5 Preemption is not helpful for scheduling."
0.576,Event,ADDED,eval-conflicts-rho020-r0-140-5xwbp.18d5433cb4548d07,reason=Scheduled count=None msg=Successfully assigned compute/eval-conflicts-rho020-r0-140-5xwbp to kind-worker
0.5762,Event,ADDED,eval-conflicts-rho020-r0-140-5xwbp.18d5433ccfa7db2b,"reason=Pulled count=1 msg=Container image ""busybox:musl"" already present on machine"
0.5763,Event,ADDED,eval-conflicts-rho020-r0-140-5xwbp.18d5433cd1079588,reason=Created count=1 msg=Created container: task
0.5765,Event,ADDED,eval-conflicts-rho020-r0-140-5xwbp.18d5433cd5f51b5f,reason=Started count=1 msg=Started container task
0.5767,Event,ADDED,eval-conflicts-rho020-r0-140.18d5433bab5d16d8,reason=SuccessfulCreate count=1 msg=Created pod: eval-conflicts-rho020-r0-140-5xwbp
0.5769,Event,ADDED,eval-conflicts-rho020-r0-140.18d5434265f83ac5,reason=Completed count=1 msg=Job completed
0.577,Event,ADDED,eval-conflicts-rho020-r0-141-knbvx.18d5433bebe41f3d,reason=Scheduled count=None msg=Successfully assigned compute/eval-conflicts-rho020-r0-141-knbvx to kind-worker4
0.5772,Event,ADDED,eval-conflicts-rho020-r0-141-knbvx.18d5433c079f8ff0,"reason=Pulled count=1 msg=Container image ""busybox:musl"" already present on machine"
0.5775,Event,ADDED,eval-conflicts-rho020-r0-141-knbvx.18d5433c08dcc596,reason=Created count=1 msg=Created container: task
0.5777,Event,ADDED,eval-conflicts-rho020-r0-141-knbvx.18d5433c1148d625,reason=Started count=1 msg=Started container task
0.5781,Event,ADDED,eval-conflicts-rho020-r0-141.18d5433beb57d07c,reason=SuccessfulCreate count=1 msg=Created pod: eval-conflicts-rho020-r0-141-knbvx
0.5783,Event,ADDED,eval-conflicts-rho020-r0-141.18d543419d3b4a6b,reason=Completed count=1 msg=Job completed
0.5784,Event,ADDED,eval-conflicts-rho020-r0-142-zh6nt.18d5433c228ebfaa,reason=Scheduled count=None msg=Successfully assigned compute/eval-conflicts-rho020-r0-142-zh6nt to kind-worker4
0.5787,Event,ADDED,eval-conflicts-rho020-r0-142-zh6nt.18d5433c3ba46878,"reason=Pulled count=1 msg=Container image ""busybox:musl"" already present on machine"
0.5789,Event,ADDED,eval-conflicts-rho020-r0-142-zh6nt.18d5433c3cc4cbbb,reason=Created count=1 msg=Created container: task
0.5791,Event,ADDED,eval-conflicts-rho020-r0-142-zh6nt.18d5433c3ecdcb8e,reason=Started count=1 msg=Started container task
0.5793,Event,ADDED,eval-conflicts-rho020-r0-142.18d5433c2223d704,reason=SuccessfulCreate count=1 msg=Created pod: eval-conflicts-rho020-r0-142-zh6nt
0.5795,Event,ADDED,eval-conflicts-rho020-r0-142.18d54341dac74f24,reason=Completed count=1 msg=Job completed
0.5797,Event,ADDED,eval-conflicts-rho020-r0-143-29ct5.18d5433c5ee6d626,reason=Scheduled count=None msg=Successfully assigned compute/eval-conflicts-rho020-r0-143-29ct5 to kind-worker4
0.5799,Event,ADDED,eval-conflicts-rho020-r0-143-29ct5.18d5433c7a3b2d9c,"reason=Pulled count=1 msg=Container image ""busybox:musl"" already present on machine"
0.58,Event,ADDED,eval-conflicts-rho020-r0-143-29ct5.18d5433c7b5bd620,reason=Created count=1 msg=Created container: task
0.5802,Event,ADDED,eval-conflicts-rho020-r0-143-29ct5.18d5433c7f5f7516,reason=Started count=1 msg=Started container task
0.5804,Event,ADDED,eval-conflicts-rho020-r0-143.18d5433c5e6af42d,reason=SuccessfulCreate count=1 msg=Created pod: eval-conflicts-rho020-r0-143-29ct5
0.5806,Event,ADDED,eval-conflicts-rho020-r0-143.18d543421af3b8c1,reason=Completed count=1 msg=Job completed
0.5807,Event,ADDED,eval-conflicts-rho020-r0-144-zt9lg.18d5433c9ae4c2c4,reason=Scheduled count=None msg=Successfully assigned compute/eval-conflicts-rho020-r0-144-zt9lg to kind-worker4
0.5809,Event,ADDED,eval-conflicts-rho020-r0-144-zt9lg.18d5433cc96b87fd,"reason=Pulled count=1 msg=Container image ""busybox:musl"" already present on machine"
0.5811,Event,ADDED,eval-conflicts-rho020-r0-144-zt9lg.18d5433ccaea3f4e,reason=Created count=1 msg=Created container: task
0.5813,Event,ADDED,eval-conflicts-rho020-r0-144-zt9lg.18d5433ccf83a3fe,reason=Started count=1 msg=Started container task
0.5816,Event,ADDED,eval-conflicts-rho020-r0-144.18d5433c9a4b1598,reason=SuccessfulCreate count=1 msg=Created pod: eval-conflicts-rho020-r0-144-zt9lg
0.5817,Event,ADDED,eval-conflicts-rho020-r0-144.18d543424b8d8bbf,reason=Completed count=1 msg=Job completed
0.5819,Event,ADDED,eval-conflicts-rho020-r0-145-kjfp9.18d5433cd58b01ca,reason=Scheduled count=None msg=Successfully assigned compute/eval-conflicts-rho020-r0-145-kjfp9 to kind-worker
0.5821,Event,ADDED,eval-conflicts-rho020-r0-145-kjfp9.18d5433cf00fba5c,"reason=Pulled count=1 msg=Container image ""busybox:musl"" already present on machine"
0.5824,Event,ADDED,eval-conflicts-rho020-r0-145-kjfp9.18d5433cf143400a,reason=Created count=1 msg=Created container: task
0.5826,Event,ADDED,eval-conflicts-rho020-r0-145-kjfp9.18d5433cf67273be,reason=Started count=1 msg=Started container task
0.5828,Event,ADDED,eval-conflicts-rho020-r0-145.18d5433cd4cfc4cf,reason=SuccessfulCreate count=1 msg=Created pod: eval-conflicts-rho020-r0-145-kjfp9
0.5831,Event,ADDED,eval-conflicts-rho020-r0-145.18d5434227d63e8f,reason=Completed count=1 msg=Job completed
0.5833,Event,ADDED,eval-conflicts-rho020-r0-146-jjdjk.18d5433d17b53ec2,reason=Scheduled count=None msg=Successfully assigned compute/eval-conflicts-rho020-r0-146-jjdjk to kind-worker4
0.5835,Event,ADDED,eval-conflicts-rho020-r0-146-jjdjk.18d5433d398da4bf,"reason=Pulled count=1 msg=Container image ""busybox:musl"" already present on machine"
0.5837,Event,ADDED,eval-conflicts-rho020-r0-146-jjdjk.18d5433d3ac31333,reason=Created count=1 msg=Created container: task
0.5841,Event,ADDED,eval-conflicts-rho020-r0-146-jjdjk.18d5433d3def7895,reason=Started count=1 msg=Started container task
0.5842,Event,ADDED,eval-conflicts-rho020-r0-146.18d5433d16ffb3b1,reason=SuccessfulCreate count=1 msg=Created pod: eval-conflicts-rho020-r0-146-jjdjk
0.5844,Event,ADDED,eval-conflicts-rho020-r0-146.18d54342c35513eb,reason=Completed count=1 msg=Job completed
0.5847,Event,ADDED,eval-conflicts-rho020-r0-147-jd7kq.18d5433d4d19b2da,reason=Scheduled count=None msg=Successfully assigned compute/eval-conflicts-rho020-r0-147-jd7kq to kind-worker4
0.5848,Event,ADDED,eval-conflicts-rho020-r0-147-jd7kq.18d5433d698b57cb,"reason=Pulled count=1 msg=Container image ""busybox:musl"" already present on machine"
0.5853,Event,ADDED,eval-conflicts-rho020-r0-147-jd7kq.18d5433d6ad92701,reason=Created count=1 msg=Created container: task
0.5855,Event,ADDED,eval-conflicts-rho020-r0-147-jd7kq.18d5433d72cdbb02,reason=Started count=1 msg=Started container task
0.5859,Event,ADDED,eval-conflicts-rho020-r0-147.18d5433d4c5989e4,reason=SuccessfulCreate count=1 msg=Created pod: eval-conflicts-rho020-r0-147-jd7kq
0.5861,Event,ADDED,eval-conflicts-rho020-r0-147.18d54342ff697aeb,reason=Completed count=1 msg=Job completed
0.5863,Event,ADDED,eval-conflicts-rho020-r0-148-9gbmt.18d5433d8a01de94,reason=Scheduled count=None msg=Successfully assigned compute/eval-conflicts-rho020-r0-148-9gbmt to kind-worker4
0.5865,Event,ADDED,eval-conflicts-rho020-r0-148-9gbmt.18d5433da7317888,"reason=Pulled count=1 msg=Container image ""busybox:musl"" already present on machine"
0.5868,Event,ADDED,eval-conflicts-rho020-r0-148-9gbmt.18d5433da8794e5a,reason=Created count=1 msg=Created container: task
0.587,Event,ADDED,eval-conflicts-rho020-r0-148-9gbmt.18d5433db1a0d625,reason=Started count=1 msg=Started container task
0.5872,Event,ADDED,eval-conflicts-rho020-r0-148.18d5433d89401ec8,reason=SuccessfulCreate count=1 msg=Created pod: eval-conflicts-rho020-r0-148-9gbmt
0.5876,Event,ADDED,eval-conflicts-rho020-r0-148.18d54343004e07f8,reason=Completed count=1 msg=Job completed
0.5878,Event,ADDED,eval-conflicts-rho020-r0-149-k2l46.18d5433dc55aa13e,reason=Scheduled count=None msg=Successfully assigned compute/eval-conflicts-rho020-r0-149-k2l46 to kind-worker4
0.588,Event,ADDED,eval-conflicts-rho020-r0-149-k2l46.18d5433de6430c62,"reason=Pulled count=1 msg=Container image ""busybox:musl"" already present on machine"
0.5881,Event,ADDED,eval-conflicts-rho020-r0-149-k2l46.18d5433de7942a80,reason=Created count=1 msg=Created container: task
0.5885,Event,ADDED,eval-conflicts-rho020-r0-149-k2l46.18d5433df0d25b20,reason=Started count=1 msg=Started container task
0.5887,Event,ADDED,eval-conflicts-rho020-r0-149.18d5433dc4af415e,reason=SuccessfulCreate count=1 msg=Created pod: eval-conflicts-rho020-r0-149-k2l46
0.5889,Event,ADDED,eval-conflicts-rho020-r0-149.18d5434377c41cb9,reason=Completed count=1 msg=Job completed
0.5891,Event,ADDED,eval-conflicts-rho020-r0-150-sq8m2.18d5433e03ecef67,reason=Scheduled count=None msg=Successfully assigned compute/eval-conflicts-rho020-r0-150-sq8m2 to kind-worker4
0.5893,Event,ADDED,eval-conflicts-rho020-r0-150-sq8m2.18d5433e22c01e2f,"reason=Pulled count=1 msg=Container image ""busybox:musl"" already present on machine"
0.5895,Event,ADDED,eval-conflicts-rho020-r0-150-sq8m2.18d5433e23defa06,reason=Created count=1 msg=Created container: task
0.5897,Event,ADDED,eval-conflicts-rho020-r0-150-sq8m2.18d5433e2d7e325e,reason=Started count=1 msg=Started container task
0.5898,Event,ADDED,eval-conflicts-rho020-r0-150.18d5433e0354e2ee,reason=SuccessfulCreate count=1 msg=Created pod: eval-conflicts-rho020-r0-150-sq8m2
0.59,Event,ADDED,eval-conflicts-rho020-r0-150.18d54343b3a839d7,reason=Completed count=1 msg=Job completed
0.5902,Event,ADDED,eval-conflicts-rho020-r0-151-nmjw9.18d5433e3b7579cd,reason=Scheduled count=None msg=Successfully assigned compute/eval-conflicts-rho020-r0-151-nmjw9 to kind-worker4
0.5903,Event,ADDED,eval-conflicts-rho020-r0-151-nmjw9.18d5433e56e2918b,"reason=Pulled count=1 msg=Container image ""busybox:musl"" already present on machine"
0.5912,Event,ADDED,eval-conflicts-rho020-r0-151-nmjw9.18d5433e58249e01,reason=Created count=1 msg=Created container: task
0.5914,Event,ADDED,eval-conflicts-rho020-r0-151-nmjw9.18d5433e5f49423e,reason=Started count=1 msg=Started container task
0.5918,Event,ADDED,eval-conflicts-rho020-r0-151.18d5433e3ab781cb,reason=SuccessfulCreate count=1 msg=Created pod: eval-conflicts-rho020-r0-151-nmjw9
0.5922,Event,ADDED,eval-conflicts-rho020-r0-151.18d54343ef90839b,reason=Completed count=1 msg=Job completed
0.5923,Event,ADDED,eval-conflicts-rho020-r0-152-9z8g7.18d5433e7995a22f,reason=Scheduled count=None msg=Successfully assigned compute/eval-conflicts-rho020-r0-152-9z8g7 to kind-worker3
0.5925,Event,ADDED,eval-conflicts-rho020-r0-152-9z8g7.18d5433ea8775bfc,"reason=Pulled count=1 msg=Container image ""busybox:musl"" already present on machine"
0.5927,Event,ADDED,eval-conflicts-rho020-r0-152-9z8g7.18d5433ea9a3d367,reason=Created count=1 msg=Created container: task
0.5931,Event,ADDED,eval-conflicts-rho020-r0-152-9z8g7.18d5433eaccb2052,reason=Started count=1 msg=Started container task
0.5933,Event,ADDED,eval-conflicts-rho020-r0-152.18d5433e78ac6ac5,reason=SuccessfulCreate count=1 msg=Created pod: eval-conflicts-rho020-r0-152-9z8g7
0.5935,Event,ADDED,eval-conflicts-rho020-r0-152.18d543442b7490b1,reason=Completed count=1 msg=Job completed
0.5937,Event,ADDED,eval-conflicts-rho020-r0-153-b46mk.18d5433eb4340a28,reason=Scheduled count=None msg=Successfully assigned compute/eval-conflicts-rho020-r0-153-b46mk to kind-worker3
0.594,Event,ADDED,eval-conflicts-rho020-r0-153-b46mk.18d5433ed3b2f7bf,"reason=Pulled count=1 msg=Container image ""busybox:musl"" already present on machine"
0.5941,Event,ADDED,eval-conflicts-rho020-r0-153-b46mk.18d5433ed4e0689d,reason=Created count=1 msg=Created container: task
0.5943,Event,ADDED,eval-conflicts-rho020-r0-153-b46mk.18d5433ed84bde12,reason=Started count=1 msg=Started container task
0.5945,Event,ADDED,eval-conflicts-rho020-r0-153.18d5433eb34c8832,reason=SuccessfulCreate count=1 msg=Created pod: eval-conflicts-rho020-r0-153-b46mk
0.5947,Event,ADDED,eval-conflicts-rho020-r0-153.18d5434467528246,reason=Completed count=1 msg=Job completed
0.5948,Event,ADDED,eval-conflicts-rho020-r0-154-j62rp.18d5433eeeee4417,reason=Scheduled count=None msg=Successfully assigned compute/eval-conflicts-rho020-r0-154-j62rp to kind-worker3
0.595,Event,ADDED,eval-conflicts-rho020-r0-154-j62rp.18d5433f073d09ab,"reason=Pulled count=1 msg=Container image ""busybox:musl"" already present on machine"
0.5952,Event,ADDED,eval-conflicts-rho020-r0-154-j62rp.18d5433f08d742e8,reason=Created count=1 msg=Created container: task
0.5953,Event,ADDED,eval-conflicts-rho020-r0-154-j62rp.18d5433f0d13adb1,reason=Started count=1 msg=Started container task
0.5955,Event,ADDED,eval-conflicts-rho020-r0-154.18d5433eed62397e,reason=SuccessfulCreate count=1 msg=Created pod: eval-conflicts-rho020-r0-154-j62rp
0.5957,Event,ADDED,eval-conflicts-rho020-r0-154.18d54344a32e57bd,reason=Completed count=1 msg=Job completed
0.5959,Event,ADDED,eval-conflicts-rho020-r0-155-95jgm.18d5433f29bb10c8,reason=Scheduled count=None msg=Successfully assigned compute/eval-conflicts-rho020-r0-155-95jgm to kind-worker3
0.596,Event,ADDED,eval-conflicts-rho020-r0-155-95jgm.18d5433f44a373e6,"reason=Pulled count=1 msg=Container image ""busybox:musl"" already present on machine"
0.5962,Event,ADDED,eval-conflicts-rho020-r0-155-95jgm.18d5433f45b684da,reason=Created count=1 msg=Created container: task
0.5964,Event,ADDED,eval-conflicts-rho020-r0-155-95jgm.18d5433f4978104a,reason=Started count=1 msg=Started container task
0.5965,Event,ADDED,eval-conflicts-rho020-r0-155.18d5433f28c48cf8,reason=SuccessfulCreate count=1 msg=Created pod: eval-conflicts-rho020-r0-155-95jgm
0.5967,Event,ADDED,eval-conflicts-rho020-r0-155.18d54344de376c65,reason=Completed count=1 msg=Job completed
0.5969,Event,ADDED,eval-conflicts-rho020-r0-156-wwj5g.18d5433f65c3c6ed,reason=Scheduled count=None msg=Successfully assigned compute/eval-conflicts-rho020-r0-156-wwj5g to kind-worker3
0.5971,Event,ADDED,eval-conflicts-rho020-r0-156-wwj5g.18d5433f7fec7bd7,"reason=Pulled count=1 msg=Container image ""busybox:musl"" already present on machine"
0.5973,Event,ADDED,eval-conflicts-rho020-r0-156-wwj5g.18d5433f8366859c,reason=Created count=1 msg=Created container: task
0.5975,Event,ADDED,eval-conflicts-rho020-r0-156-wwj5g.18d5433f9255ddb0,reason=Started count=1 msg=Started container task
0.5979,Event,ADDED,eval-conflicts-rho020-r0-156.18d5433f647c968f,reason=SuccessfulCreate count=1 msg=Created pod: eval-conflicts-rho020-r0-156-wwj5g
0.5981,Event,ADDED,eval-conflicts-rho020-r0-156.18d5434519e25fd4,reason=Completed count=1 msg=Job completed
0.5983,Event,ADDED,eval-conflicts-rho020-r0-157-shkpr.18d5433fa1592122,reason=Scheduled count=None msg=Successfully assigned compute/eval-conflicts-rho020-r0-157-shkpr to kind-worker3
0.5985,Event,ADDED,eval-conflicts-rho020-r0-157-shkpr.18d5433fc9c5eba1,"reason=Pulled count=1 msg=Container image ""busybox:musl"" already present on machine"
0.5987,Event,ADDED,eval-conflicts-rho020-r0-157-shkpr.18d5433fcaff8da6,reason=Created count=1 msg=Created container: task
0.5989,Event,ADDED,eval-conflicts-rho020-r0-157-shkpr.18d5433fd64ec92f,reason=Started count=1 msg=Started container task
0.599,Event,ADDED,eval-conflicts-rho020-r0-157.18d5433fa02bf4b1,reason=SuccessfulCreate count=1 msg=Created pod: eval-conflicts-rho020-r0-157-shkpr
0.5992,Event,ADDED,eval-conflicts-rho020-r0-157.18d5434559a14cf5,reason=Completed count=1 msg=Job completed
0.5995,Event,ADDED,eval-conflicts-rho020-r0-158-7mbp8.18d5433fe1542ce6,reason=Scheduled count=None msg=Successfully assigned compute/eval-conflicts-rho020-r0-158-7mbp8 to kind-worker3
0.5998,Event,ADDED,eval-conflicts-rho020-r0-158-7mbp8.18d5433ffab68663,"reason=Pulled count=1 msg=Container image ""busybox:musl"" already present on machine"
0.6,Event,ADDED,eval-conflicts-rho020-r0-158-7mbp8.18d5433ffc783714,reason=Created count=1 msg=Created container: task
0.6004,Event,ADDED,eval-conflicts-rho020-r0-158-7mbp8.18d5434000f49fee,reason=Started count=1 msg=Started container task
0.6005,Event,ADDED,eval-conflicts-rho020-r0-158.18d5433fe0a603bb,reason=SuccessfulCreate count=1 msg=Created pod: eval-conflicts-rho020-r0-158-7mbp8
0.6007,Event,ADDED,eval-conflicts-rho020-r0-158.18d5434596f6ee45,reason=Completed count=1 msg=Job completed
0.6009,Event,ADDED,eval-conflicts-rho020-r0-159-2fzrp.18d54340193f1f47,reason=Scheduled count=None msg=Successfully assigned compute/eval-conflicts-rho020-r0-159-2fzrp to kind-worker3
0.6014,Event,ADDED,eval-conflicts-rho020-r0-159-2fzrp.18d543403757efe3,"reason=Pulled count=1 msg=Container image ""busybox:musl"" already present on machine"
0.6019,Event,ADDED,eval-conflicts-rho020-r0-159-2fzrp.18d5434038a3cdab,reason=Created count=1 msg=Created container: task
0.6021,Event,ADDED,eval-conflicts-rho020-r0-159-2fzrp.18d543403d239380,reason=Started count=1 msg=Started container task
0.6022,Event,ADDED,eval-conflicts-rho020-r0-159.18d543401876800f,reason=SuccessfulCreate count=1 msg=Created pod: eval-conflicts-rho020-r0-159-2fzrp
0.6026,Event,ADDED,eval-conflicts-rho020-r0-159.18d54345d5314266,reason=Completed count=1 msg=Job completed
0.6028,Event,ADDED,eval-conflicts-rho020-r0-160-cwssq.18d54340567e94b9,reason=Scheduled count=None msg=Successfully assigned compute/eval-conflicts-rho020-r0-160-cwssq to kind-worker
0.603,Event,ADDED,eval-conflicts-rho020-r0-160-cwssq.18d54340725b7f43,"reason=Pulled count=1 msg=Container image ""busybox:musl"" already present on machine"
0.6032,Event,ADDED,eval-conflicts-rho020-r0-160-cwssq.18d5434073b9d850,reason=Created count=1 msg=Created container: task
0.6034,Event,ADDED,eval-conflicts-rho020-r0-160-cwssq.18d5434077e6c402,reason=Started count=1 msg=Started container task
0.6036,Event,ADDED,eval-conflicts-rho020-r0-160.18d54340558a779a,reason=SuccessfulCreate count=1 msg=Created pod: eval-conflicts-rho020-r0-160-cwssq
0.6037,Event,ADDED,eval-conflicts-rho020-r0-160.18d54345e2dd76ca,reason=Completed count=1 msg=Job completed
0.6042,Event,ADDED,eval-conflicts-rho020-r0-161-bggnm.18d54340909c4dd4,reason=Scheduled count=None msg=Successfully assigned compute/eval-conflicts-rho020-r0-161-bggnm to kind-worker3
0.6044,Event,ADDED,eval-conflicts-rho020-r0-161-bggnm.18d54340ab641ef2,"reason=Pulled count=1 msg=Container image ""busybox:musl"" already present on machine"
0.6046,Event,ADDED,eval-conflicts-rho020-r0-161-bggnm.18d54340ae7db1a5,reason=Created count=1 msg=Created container: task
0.6049,Event,ADDED,eval-conflicts-rho020-r0-161-bggnm.18d54340b38b1357,reason=Started count=1 msg=Started container task
0.6051,Event,ADDED,eval-conflicts-rho020-r0-161.18d543408fdd71be,reason=SuccessfulCreate count=1 msg=Created pod: eval-conflicts-rho020-r0-161-bggnm
0.6053,Event,ADDED,eval-conflicts-rho020-r0-161.18d54346495a4a7f,reason=Completed count=1 msg=Job completed
0.6055,Event,ADDED,eval-conflicts-rho020-r0-162-vnz76.18d54340cb126bd1,reason=Scheduled count=None msg=Successfully assigned compute/eval-conflicts-rho020-r0-162-vnz76 to kind-worker
0.6058,Event,ADDED,eval-conflicts-rho020-r0-162-vnz76.18d54340e33bda11,"reason=Pulled count=1 msg=Container image ""busybox:musl"" already present on machine"
0.6059,Event,ADDED,eval-conflicts-rho020-r0-162-vnz76.18d54340e467d410,reason=Created count=1 msg=Created container: task
0.6062,Event,ADDED,eval-conflicts-rho020-r0-162-vnz76.18d54340e9b4ac66,reason=Started count=1 msg=Started container task
0.6064,Event,ADDED,eval-conflicts-rho020-r0-162.18d54340ca372c56,reason=SuccessfulCreate count=1 msg=Created pod: eval-conflicts-rho020-r0-162-vnz76
0.6067,Event,ADDED,eval-conflicts-rho020-r0-162.18d54346581e0f92,reason=Completed count=1 msg=Job completed
0.6068,Event,ADDED,eval-conflicts-rho020-r0-163-kw8fr.18d54341066f5c00,reason=Scheduled count=None msg=Successfully assigned compute/eval-conflicts-rho020-r0-163-kw8fr to kind-worker
0.607,Event,ADDED,eval-conflicts-rho020-r0-163-kw8fr.18d543412028cb80,"reason=Pulled count=1 msg=Container image ""busybox:musl"" already present on machine"
