t_recv,kind,type,name,detail
0.0222,Node,ADDED,kind-control-plane,taints=1
0.0235,Node,ADDED,kind-worker,taints=0
0.0249,Node,ADDED,kind-worker2,taints=0
0.0265,Node,ADDED,kind-worker3,taints=0
0.0277,Node,ADDED,kind-worker4,taints=0
0.03,Node,ADDED,kind-worker5,taints=0
0.0506,TaskRequest,ADDED,eval-sanitize-5-r1-000,phase=None job=None
0.0555,TaskRequest,MODIFIED,eval-sanitize-5-r1-000,phase=Pending job=None
0.062,Event,ADDED,eval-sanitize-1-r1-008-54ljj.18d4a22cff5c738c,"reason=FailedScheduling count=None msg=0/6 nodes are available: 1 c_wall violated: 3 conflicting context pair(s) with node memory, 5 node(s) had untolerated taint(s). no new claims to deallocate, preemption: 0/6 nodes are available: 1 No preemption victims found for incoming pod, 5 Preemption is not helpful for scheduling."
0.0626,Event,ADDED,eval-sanitize-1-r1-008-54ljj.18d4a22d7981125d,"reason=FailedScheduling count=None msg=0/6 nodes are available: 1 c_wall violated: 2 conflicting context pair(s) with node memory, 5 node(s) had untolerated taint(s). no new claims to deallocate, preemption: 0/6 nodes are available: 1 No preemption victims found for incoming pod, 5 Preemption is not helpful for scheduling."
0.0628,Event,ADDED,eval-sanitize-1-r1-008-54ljj.18d4a22db3273eda,"reason=FailedScheduling count=None msg=0/6 nodes are available: 1 c_wall violated: 1 conflicting context pair(s) with node memory, 5 node(s) had untolerated taint(s). no new claims to deallocate, preemption: 0/6 nodes are available: 1 No preemption victims found for incoming pod, 5 Preemption is not helpful for scheduling."
0.063,Event,ADDED,eval-sanitize-1-r1-009-pcsqk.18d4a22d0632282d,"reason=FailedScheduling count=None msg=0/6 nodes are available: 1 c_wall violated: 2 conflicting context pair(s) with node memory, 5 node(s) had untolerated taint(s). no new claims to deallocate, preemption: 0/6 nodes are available: 1 No preemption victims found for incoming pod, 5 Preemption is not helpful for scheduling."
0.0635,Event,ADDED,eval-sanitize-1-r1-009-pcsqk.18d4a22d79aeec40,"reason=FailedScheduling count=None msg=0/6 nodes are available: 1 c_wall violated: 3 conflicting context pair(s) with node memory, 5 node(s) had untolerated taint(s). no new claims to deallocate, preemption: 0/6 nodes are available: 1 No preemption victims found for incoming pod, 5 Preemption is not helpful for scheduling."
0.0638,Event,ADDED,eval-sanitize-1-r1-010-fzljc.18d4a22d03d04d3b,"reason=FailedScheduling count=None msg=0/6 nodes are available: 1 c_wall violated: 3 conflicting context pair(s) with node memory, 5 node(s) had untolerated taint(s). no new claims to deallocate, preemption: 0/6 nodes are available: 1 No preemption victims found for incoming pod, 5 Preemption is not helpful for scheduling."
0.0642,Event,ADDED,eval-sanitize-1-r1-012-snd79.18d4a22d0b52f029,"reason=FailedScheduling count=None msg=0/6 nodes are available: 1 c_wall violated: 4 conflicting context pair(s) with node memory, 5 node(s) had untolerated taint(s). no new claims to deallocate, preemption: 0/6 nodes are available: 1 No preemption victims found for incoming pod, 5 Preemption is not helpful for scheduling."
0.0651,Event,ADDED,eval-sanitize-1-r1-012-snd79.18d4a22d79dce1b8,"reason=FailedScheduling count=None msg=0/6 nodes are available: 1 c_wall violated: 3 conflicting context pair(s) with node memory, 5 node(s) had untolerated taint(s). no new claims to deallocate, preemption: 0/6 nodes are available: 1 No preemption victims found for incoming pod, 5 Preemption is not helpful for scheduling."
0.0656,Event,ADDED,eval-sanitize-1-r1-013-fckpr.18d4a22d048590dd,"reason=FailedScheduling count=None msg=0/6 nodes are available: 1 c_wall violated: 1 conflicting context pair(s) with node memory, 5 node(s) had untolerated taint(s). no new claims to deallocate, preemption: 0/6 nodes are available: 1 No preemption victims found for incoming pod, 5 Preemption is not helpful for scheduling."
0.066,Event,ADDED,eval-sanitize-1-r1-015-qvnqr.18d4a22d0b8b4a44,"reason=FailedScheduling count=None msg=0/6 nodes are available: 1 c_wall violated: 2 conflicting context pair(s) with node memory, 5 node(s) had untolerated taint(s). no new claims to deallocate, preemption: 0/6 nodes are available: 1 No preemption victims found for incoming pod, 5 Preemption is not helpful for scheduling."
0.0662,Event,ADDED,eval-sanitize-1-r1-015-qvnqr.18d4a22d7a0aaddb,"reason=FailedScheduling count=None msg=0/6 nodes are available: 1 c_wall violated: 3 conflicting context pair(s) with node memory, 5 node(s) had untolerated taint(s). no new claims to deallocate, preemption: 0/6 nodes are available: 1 No preemption victims found for incoming pod, 5 Preemption is not helpful for scheduling."
0.0664,Event,ADDED,eval-sanitize-1-r1-016-sj7m6.18d4a22d0538bee0,"reason=FailedScheduling count=None msg=0/6 nodes are available: 1 c_wall violated: 1 conflicting context pair(s) with node memory, 5 node(s) had untolerated taint(s). no new claims to deallocate, preemption: 0/6 nodes are available: 1 No preemption victims found for incoming pod, 5 Preemption is not helpful for scheduling."
0.067,Event,ADDED,eval-sanitize-1-r1-020-ck47z.18d4a22d0565250b,"reason=FailedScheduling count=None msg=0/6 nodes are available: 1 c_wall violated: 3 conflicting context pair(s) with node memory, 5 node(s) had untolerated taint(s). no new claims to deallocate, preemption: 0/6 nodes are available: 1 No preemption victims found for incoming pod, 5 Preemption is not helpful for scheduling."
0.0672,Event,ADDED,eval-sanitize-1-r1-020-ck47z.18d4a22d791e5d49,"reason=FailedScheduling count=None msg=0/6 nodes are available: 1 c_wall violated: 2 conflicting context pair(s) with node memory, 5 node(s) had untolerated taint(s). no new claims to deallocate, preemption: 0/6 nodes are available: 1 No preemption victims found for incoming pod, 5 Preemption is not helpful for scheduling."
0.0674,Event,ADDED,eval-sanitize-1-r1-020-ck47z.18d4a22db387ed0b,"reason=FailedScheduling count=None msg=0/6 nodes are available: 1 c_wall violated: 1 conflicting context pair(s) with node memory, 5 node(s) had untolerated taint(s). no new claims to deallocate, preemption: 0/6 nodes are available: 1 No preemption victims found for incoming pod, 5 Preemption is not helpful for scheduling."
0.0677,Event,ADDED,eval-sanitize-1-r1-021-vdm6r.18d4a22d0599a538,"reason=FailedScheduling count=None msg=0/6 nodes are available: 1 c_wall violated: 3 conflicting context pair(s) with node memory, 5 node(s) had untolerated taint(s). no new claims to deallocate, preemption: 0/6 nodes are available: 1 No preemption victims found for incoming pod, 5 Preemption is not helpful for scheduling."
0.068,Event,ADDED,eval-sanitize-1-r1-021-vdm6r.18d4a22d79549ce8,"reason=FailedScheduling count=None msg=0/6 nodes are available: 1 c_wall violated: 2 conflicting context pair(s) with node memory, 5 node(s) had untolerated taint(s). no new claims to deallocate, preemption: 0/6 nodes are available: 1 No preemption victims found for incoming pod, 5 Preemption is not helpful for scheduling."
0.0681,Event,ADDED,eval-sanitize-1-r1-021-vdm6r.18d4a22db13ff6b2,"reason=FailedScheduling count=None msg=0/6 nodes are available: 1 c_wall violated: 1 conflicting context pair(s) with node memory, 5 node(s) had untolerated taint(s). no new claims to deallocate, preemption: 0/6 nodes are available: 1 No preemption victims found for incoming pod, 5 Preemption is not helpful for scheduling."
0.0685,Event,ADDED,eval-sanitize-1-r1-025-5wqbg.18d4a22d9930b3f8,"reason=FailedScheduling count=None msg=0/6 nodes are available: 1 c_wall violated: 1 conflicting context pair(s) with node memory, 5 node(s) had untolerated taint(s). no new claims to deallocate, preemption: 0/6 nodes are available: 1 No preemption victims found for incoming pod, 5 Preemption is not helpful for scheduling."
0.0687,Event,ADDED,eval-sanitize-1-r1-031-sxkst.18d4a232914a8a2e,"reason=FailedScheduling count=None msg=0/6 nodes are available: 1 c_wall violated: 2 conflicting context pair(s) with node memory, 5 node(s) had untolerated taint(s). no new claims to deallocate, preemption: 0/6 nodes are available: 1 No preemption victims found for incoming pod, 5 Preemption is not helpful for scheduling."
0.0689,Event,ADDED,eval-sanitize-1-r1-032-5nhpx.18d4a23288e712d4,"reason=FailedScheduling count=None msg=0/6 nodes are available: 1 c_wall violated: 1 conflicting context pair(s) with node memory, 5 node(s) had untolerated taint(s). no new claims to deallocate, preemption: 0/6 nodes are available: 1 No preemption victims found for incoming pod, 5 Preemption is not helpful for scheduling."
0.0694,Event,ADDED,eval-sanitize-1-r1-033-mpbml.18d4a23295a06a1d,"reason=FailedScheduling count=None msg=0/6 nodes are available: 1 c_wall violated: 2 conflicting context pair(s) with node memory, 5 node(s) had untolerated taint(s). no new claims to deallocate, preemption: 0/6 nodes are available: 1 No preemption victims found for incoming pod, 5 Preemption is not helpful for scheduling."
0.0696,Event,ADDED,eval-sanitize-1-r1-035-5xqph.18d4a23289d5af13,"reason=FailedScheduling count=None msg=0/6 nodes are available: 1 c_wall violated: 1 conflicting context pair(s) with node memory, 5 node(s) had untolerated taint(s). no new claims to deallocate, preemption: 0/6 nodes are available: 1 No preemption victims found for incoming pod, 5 Preemption is not helpful for scheduling."
0.07,Event,ADDED,eval-sanitize-1-r1-036-ccvfg.18d4a2328c70bfd9,"reason=FailedScheduling count=None msg=0/6 nodes are available: 1 c_wall violated: 1 conflicting context pair(s) with node memory, 5 node(s) had untolerated taint(s). no new claims to deallocate, preemption: 0/6 nodes are available: 1 No preemption victims found for incoming pod, 5 Preemption is not helpful for scheduling."
0.0702,Event,ADDED,eval-sanitize-1-r1-037-4zq86.18d4a2328cac211d,"reason=FailedScheduling count=None msg=0/6 nodes are available: 1 c_wall violated: 2 conflicting context pair(s) with node memory, 5 node(s) had untolerated taint(s). no new claims to deallocate, preemption: 0/6 nodes are available: 1 No preemption victims found for incoming pod, 5 Preemption is not helpful for scheduling."
0.0704,Event,ADDED,eval-sanitize-1-r1-037-4zq86.18d4a232fb66b7a3,"reason=FailedScheduling count=None msg=0/6 nodes are available: 1 c_wall violated: 3 conflicting context pair(s) with node memory, 5 node(s) had untolerated taint(s). no new claims to deallocate, preemption: 0/6 nodes are available: 1 No preemption victims found for incoming pod, 5 Preemption is not helpful for scheduling."
0.0708,Event,ADDED,eval-sanitize-1-r1-037-4zq86.18d4a233309543db,"reason=FailedScheduling count=None msg=0/6 nodes are available: 1 c_wall violated: 1 conflicting context pair(s) with node memory, 5 node(s) had untolerated taint(s). no new claims to deallocate, preemption: 0/6 nodes are available: 1 No preemption victims found for incoming pod, 5 Preemption is not helpful for scheduling."
0.071,Event,ADDED,eval-sanitize-1-r1-038-xhjh9.18d4a2328ceb140e,"reason=FailedScheduling count=None msg=0/6 nodes are available: 1 c_wall violated: 1 conflicting context pair(s) with node memory, 5 node(s) had untolerated taint(s). no new claims to deallocate, preemption: 0/6 nodes are available: 1 No preemption victims found for incoming pod, 5 Preemption is not helpful for scheduling."
0.0712,Event,ADDED,eval-sanitize-1-r1-038-xhjh9.18d4a232fb925183,"reason=FailedScheduling count=None msg=0/6 nodes are available: 1 c_wall violated: 3 conflicting context pair(s) with node memory, 5 node(s) had untolerated taint(s). no new claims to deallocate, preemption: 0/6 nodes are available: 1 No preemption victims found for incoming pod, 5 Preemption is not helpful for scheduling."
0.0714,Event,ADDED,eval-sanitize-1-r1-038-xhjh9.18d4a23331a2c4c8,"reason=FailedScheduling count=None msg=0/6 nodes are available: 1 c_wall violated: 1 conflicting context pair(s) with node memory, 5 node(s) had untolerated taint(s). no new claims to deallocate, preemption: 0/6 nodes are available: 1 No preemption victims found for incoming pod, 5 Preemption is not helpful for scheduling."
0.0716,Event,ADDED,eval-sanitize-1-r1-038-xhjh9.18d4a2336de91c60,"reason=FailedScheduling count=None msg=0/6 nodes are available: 2 c_wall violated: 1 conflicting context pair(s) with node memory, 4 node(s) had untolerated taint(s). no new claims to deallocate, preemption: 0/6 nodes are available: 2 No preemption victims found for incoming pod, 4 Preemption is not helpful for scheduling."
0.0718,Event,ADDED,eval-sanitize-1-r1-038-xhjh9.18d4a233756adb37,"reason=FailedScheduling count=None msg=0/6 nodes are available: 1 c_wall violated: 1 conflicting context pair(s) with node memory, 5 node(s) had untolerated taint(s). no new claims to deallocate, preemption: 0/6 nodes are available: 1 No preemption victims found for incoming pod, 5 Preemption is not helpful for scheduling."
0.072,Event,ADDED,eval-sanitize-1-r1-039-v5lhr.18d4a2328d26df02,"reason=FailedScheduling count=None msg=0/6 nodes are available: 1 c_wall violated: 2 conflicting context pair(s) with node memory, 5 node(s) had untolerated taint(s). no new claims to deallocate, preemption: 0/6 nodes are available: 1 No preemption victims found for incoming pod, 5 Preemption is not helpful for scheduling."
0.0722,Event,ADDED,eval-sanitize-1-r1-039-v5lhr.18d4a232fc06dfd7,"reason=FailedScheduling count=None msg=0/6 nodes are available: 1 c_wall violated: 3 conflicting context pair(s) with node memory, 5 node(s) had untolerated taint(s). no new claims to deallocate, preemption: 0/6 nodes are available: 1 No preemption victims found for incoming pod, 5 Preemption is not helpful for scheduling."
0.0725,Event,ADDED,eval-sanitize-1-r1-039-v5lhr.18d4a23331d45da9,"reason=FailedScheduling count=None msg=0/6 nodes are available: 1 c_wall violated: 1 conflicting context pair(s) with node memory, 5 node(s) had untolerated taint(s). no new claims to deallocate, preemption: 0/6 nodes are available: 1 No preemption victims found for incoming pod, 5 Preemption is not helpful for scheduling."
0.0729,Event,ADDED,eval-sanitize-1-r1-040-xnms4.18d4a2328d61ae1b,"reason=FailedScheduling count=None msg=0/6 nodes are available: 1 c_wall violated: 1 conflicting context pair(s) with node memory, 5 node(s) had untolerated taint(s). no new claims to deallocate, preemption: 0/6 nodes are available: 1 No preemption victims found for incoming pod, 5 Preemption is not helpful for scheduling."
0.0731,Event,ADDED,eval-sanitize-1-r1-041-7b2x4.18d4a2328fc107ba,"reason=FailedScheduling count=None msg=0/6 nodes are available: 1 c_wall violated: 2 conflicting context pair(s) with node memory, 5 node(s) had untolerated taint(s). no new claims to deallocate, preemption: 0/6 nodes are available: 1 No preemption victims found for incoming pod, 5 Preemption is not helpful for scheduling."
0.0738,Job,ADDED,eval-sanitize-5-r1-000,
0.0742,Event,ADDED,eval-sanitize-1-r1-042-q6xs7.18d4a23290b83daf,"reason=FailedScheduling count=None msg=0/6 nodes are available: 1 c_wall violated: 2 conflicting context pair(s) with node memory, 5 node(s) had untolerated taint(s). no new claims to deallocate, preemption: 0/6 nodes are available: 1 No preemption victims found for incoming pod, 5 Preemption is not helpful for scheduling."
0.0744,Event,ADDED,eval-sanitize-1-r1-044-z5qvl.18d4a23290ec741c,"reason=FailedScheduling count=None msg=0/6 nodes are available: 1 c_wall violated: 2 conflicting context pair(s) with node memory, 5 node(s) had untolerated taint(s). no new claims to deallocate, preemption: 0/6 nodes are available: 1 No preemption victims found for incoming pod, 5 Preemption is not helpful for scheduling."
0.0746,Event,ADDED,eval-sanitize-1-r1-044-z5qvl.18d4a232fae6a711,"reason=FailedScheduling count=None msg=0/6 nodes are available: 1 c_wall violated: 3 conflicting context pair(s) with node memory, 5 node(s) had untolerated taint(s). no new claims to deallocate, preemption: 0/6 nodes are available: 1 No preemption victims found for incoming pod, 5 Preemption is not helpful for scheduling."
0.075,Event,ADDED,eval-sanitize-1-r1-044-z5qvl.18d4a23332052492,"reason=FailedScheduling count=None msg=0/6 nodes are available: 1 c_wall violated: 1 conflicting context pair(s) with node memory, 5 node(s) had untolerated taint(s). no new claims to deallocate, preemption: 0/6 nodes are available: 1 No preemption victims found for incoming pod, 5 Preemption is not helpful for scheduling."
0.0752,Event,ADDED,eval-sanitize-1-r1-046-qcrmd.18d4a2329118cac5,"reason=FailedScheduling count=None msg=0/6 nodes are available: 1 c_wall violated: 1 conflicting context pair(s) with node memory, 5 node(s) had untolerated taint(s). no new claims to deallocate, preemption: 0/6 nodes are available: 1 No preemption victims found for incoming pod, 5 Preemption is not helpful for scheduling."
0.0754,Event,ADDED,eval-sanitize-1-r1-046-qcrmd.18d4a232fb122580,"reason=FailedScheduling count=None msg=0/6 nodes are available: 1 c_wall violated: 1 conflicting context pair(s) with node memory, 5 node(s) had untolerated taint(s). no new claims to deallocate, preemption: 0/6 nodes are available: 1 No preemption victims found for incoming pod, 5 Preemption is not helpful for scheduling."
0.0758,Event,ADDED,eval-sanitize-1-r1-047-dr2vt.18d4a232fb3d1a95,"reason=FailedScheduling count=None msg=0/6 nodes are available: 1 c_wall violated: 3 conflicting context pair(s) with node memory, 5 node(s) had untolerated taint(s). no new claims to deallocate, preemption: 0/6 nodes are available: 1 No preemption victims found for incoming pod, 5 Preemption is not helpful for scheduling."
0.076,Event,ADDED,eval-sanitize-1-r1-047-dr2vt.18d4a2332f76f6a9,"reason=FailedScheduling count=None msg=0/6 nodes are available: 1 c_wall violated: 1 conflicting context pair(s) with node memory, 5 node(s) had untolerated taint(s). no new claims to deallocate, preemption: 0/6 nodes are available: 1 No preemption victims found for incoming pod, 5 Preemption is not helpful for scheduling."
0.0762,Event,ADDED,eval-sanitize-1-r1-051-7vljw.18d4a234001fa5d9,"reason=FailedScheduling count=None msg=0/6 nodes are available: 1 c_wall violated: 1 conflicting context pair(s) with node memory, 5 node(s) had untolerated taint(s). no new claims to deallocate, preemption: 0/6 nodes are available: 1 No preemption victims found for incoming pod, 5 Preemption is not helpful for scheduling."
0.0766,Event,ADDED,eval-sanitize-1-r1-052-hz5cp.18d4a2342287faaf,"reason=FailedScheduling count=None msg=0/6 nodes are available: 1 c_wall violated: 1 conflicting context pair(s) with node memory, 5 node(s) had untolerated taint(s). no new claims to deallocate, preemption: 0/6 nodes are available: 1 No preemption victims found for incoming pod, 5 Preemption is not helpful for scheduling."
0.0769,Event,ADDED,eval-sanitize-1-r1-053-nnjhr.18d4a238158e8a17,"reason=FailedScheduling count=None msg=0/6 nodes are available: 1 c_wall violated: 2 conflicting context pair(s) with node memory, 5 node(s) had untolerated taint(s). no new claims to deallocate, preemption: 0/6 nodes are available: 1 No preemption victims found for incoming pod, 5 Preemption is not helpful for scheduling."
0.0771,Event,ADDED,eval-sanitize-1-r1-054-c6l96.18d4a23806f0ea06,"reason=FailedScheduling count=None msg=0/6 nodes are available: 1 c_wall violated: 1 conflicting context pair(s) with node memory, 5 node(s) had untolerated taint(s). no new claims to deallocate, preemption: 0/6 nodes are available: 1 No preemption victims found for incoming pod, 5 Preemption is not helpful for scheduling."
0.0775,Event,ADDED,eval-sanitize-1-r1-057-k6kh2.18d4a23816f7f7ac,"reason=FailedScheduling count=None msg=0/6 nodes are available: 1 c_wall violated: 4 conflicting context pair(s) with node memory, 5 node(s) had untolerated taint(s). no new claims to deallocate, preemption: 0/6 nodes are available: 1 No preemption victims found for incoming pod, 5 Preemption is not helpful for scheduling."
0.0778,Event,ADDED,eval-sanitize-1-r1-057-k6kh2.18d4a23878ad5df5,"reason=FailedScheduling count=None msg=0/6 nodes are available: 1 c_wall violated: 1 conflicting context pair(s) with node memory, 5 node(s) had untolerated taint(s). no new claims to deallocate, preemption: 0/6 nodes are available: 1 No preemption victims found for incoming pod, 5 Preemption is not helpful for scheduling."
0.078,Event,ADDED,eval-sanitize-1-r1-057-k6kh2.18d4a238bb462a54,"reason=FailedScheduling count=None msg=0/6 nodes are available: 1 c_wall violated: 1 conflicting context pair(s) with node memory, 5 node(s) had untolerated taint(s). no new claims to deallocate, preemption: 0/6 nodes are available: 1 No preemption victims found for incoming pod, 5 Preemption is not helpful for scheduling."
0.0781,TaskRequest,MODIFIED,eval-sanitize-5-r1-000,phase=Scheduled job=None
0.0786,Event,ADDED,eval-sanitize-1-r1-057-k6kh2.18d4a238e03ecff2,"reason=FailedScheduling count=None msg=0/6 nodes are available: 2 c_wall violated: 1 conflicting context pair(s) with node memory, 4 node(s) had untolerated taint(s). no new claims to deallocate, preemption: 0/6 nodes are available: 2 No preemption victims found for incoming pod, 4 Preemption is not helpful for scheduling."
0.0788,Event,ADDED,eval-sanitize-1-r1-057-k6kh2.18d4a238eca2d474,"reason=FailedScheduling count=None msg=0/6 nodes are available: 1 c_wall violated: 1 conflicting context pair(s) with node memory, 5 node(s) had untolerated taint(s). no new claims to deallocate, preemption: 0/6 nodes are available: 1 No preemption victims found for incoming pod, 5 Preemption is not helpful for scheduling."
0.0792,Event,ADDED,eval-sanitize-1-r1-059-jg4qr.18d4a2381b39d7a7,"reason=FailedScheduling count=None msg=0/6 nodes are available: 1 c_wall violated: 3 conflicting context pair(s) with node memory, 5 node(s) had untolerated taint(s). no new claims to deallocate, preemption: 0/6 nodes are available: 1 No preemption victims found for incoming pod, 5 Preemption is not helpful for scheduling."
0.0794,Event,ADDED,eval-sanitize-1-r1-059-jg4qr.18d4a23879965327,"reason=FailedScheduling count=None msg=0/6 nodes are available: 1 c_wall violated: 1 conflicting context pair(s) with node memory, 5 node(s) had untolerated taint(s). no new claims to deallocate, preemption: 0/6 nodes are available: 1 No preemption victims found for incoming pod, 5 Preemption is not helpful for scheduling."
0.0796,Event,ADDED,eval-sanitize-1-r1-060-f5kbh.18d4a2381b6c2d02,"reason=FailedScheduling count=None msg=0/6 nodes are available: 1 c_wall violated: 2 conflicting context pair(s) with node memory, 5 node(s) had untolerated taint(s). no new claims to deallocate, preemption: 0/6 nodes are available: 1 No preemption victims found for incoming pod, 5 Preemption is not helpful for scheduling."
0.0804,Event,ADDED,eval-sanitize-1-r1-060-f5kbh.18d4a23879c5cf4b,"reason=FailedScheduling count=None msg=0/6 nodes are available: 1 c_wall violated: 1 conflicting context pair(s) with node memory, 5 node(s) had untolerated taint(s). no new claims to deallocate, preemption: 0/6 nodes are available: 1 No preemption victims found for incoming pod, 5 Preemption is not helpful for scheduling."
0.0811,Event,ADDED,eval-sanitize-1-r1-060-f5kbh.18d4a238bc24fef7,"reason=FailedScheduling count=None msg=0/6 nodes are available: 1 c_wall violated: 2 conflicting context pair(s) with node memory, 5 node(s) had untolerated taint(s). no new claims to deallocate, preemption: 0/6 nodes are available: 1 No preemption victims found for incoming pod, 5 Preemption is not helpful for scheduling."
0.0817,Event,ADDED,eval-sanitize-1-r1-062-dz2tv.18d4a238112100cd,"reason=FailedScheduling count=None msg=0/6 nodes are available: 1 c_wall violated: 1 conflicting context pair(s) with node memory, 5 node(s) had untolerated taint(s). no new claims to deallocate, preemption: 0/6 nodes are available: 1 No preemption victims found for incoming pod, 5 Preemption is not helpful for scheduling."
0.0823,Event,ADDED,eval-sanitize-1-r1-064-624s9.18d4a2381153223b,"reason=FailedScheduling count=None msg=0/6 nodes are available: 1 c_wall violated: 3 conflicting context pair(s) with node memory, 5 node(s) had untolerated taint(s). no new claims to deallocate, preemption: 0/6 nodes are available: 1 No preemption victims found for incoming pod, 5 Preemption is not helpful for scheduling."
0.0828,Event,ADDED,eval-sanitize-1-r1-067-xtj9w.18d4a23811882221,"reason=FailedScheduling count=None msg=0/6 nodes are available: 1 c_wall violated: 1 conflicting context pair(s) with node memory, 5 node(s) had untolerated taint(s). no new claims to deallocate, preemption: 0/6 nodes are available: 1 No preemption victims found for incoming pod, 5 Preemption is not helpful for scheduling."
0.0832,Event,ADDED,eval-sanitize-1-r1-069-7p8r4.18d4a23811bb6e9c,"reason=FailedScheduling count=None msg=0/6 nodes are available: 1 c_wall violated: 2 conflicting context pair(s) with node memory, 5 node(s) had untolerated taint(s). no new claims to deallocate, preemption: 0/6 nodes are available: 1 No preemption victims found for incoming pod, 5 Preemption is not helpful for scheduling."
0.0837,Event,ADDED,eval-sanitize-1-r1-070-8rv27.18d4a2382165ba7c,"reason=FailedScheduling count=None msg=0/6 nodes are available: 1 c_wall violated: 1 conflicting context pair(s) with node memory, 5 node(s) had untolerated taint(s). no new claims to deallocate, preemption: 0/6 nodes are available: 1 No preemption victims found for incoming pod, 5 Preemption is not helpful for scheduling."
0.0842,Event,ADDED,eval-sanitize-1-r1-072-6v2rf.18d4a2389806bd4f,"reason=FailedScheduling count=None msg=0/6 nodes are available: 1 c_wall violated: 1 conflicting context pair(s) with node memory, 5 node(s) had untolerated taint(s). no new claims to deallocate, preemption: 0/6 nodes are available: 1 No preemption victims found for incoming pod, 5 Preemption is not helpful for scheduling."
0.0844,Event,ADDED,eval-sanitize-1-r1-072-6v2rf.18d4a238b86a64ec,"reason=FailedScheduling count=None msg=0/6 nodes are available: 1 c_wall violated: 2 conflicting context pair(s) with node memory, 5 node(s) had untolerated taint(s). no new claims to deallocate, preemption: 0/6 nodes are available: 1 No preemption victims found for incoming pod, 5 Preemption is not helpful for scheduling."
0.0856,Pod,ADDED,eval-sanitize-5-r1-000-7v7fb,phase=Pending node=None
0.0861,Event,ADDED,eval-sanitize-1-r1-075-qnp7w.18d4a239a28251cf,"reason=FailedScheduling count=None msg=0/6 nodes are available: 1 c_wall violated: 2 conflicting context pair(s) with node memory, 5 node(s) had untolerated taint(s). no new claims to deallocate, preemption: 0/6 nodes are available: 1 No preemption victims found for incoming pod, 5 Preemption is not helpful for scheduling."
0.0863,Event,ADDED,eval-sanitize-1-r1-076-27w26.18d4a239a2b39aca,"reason=FailedScheduling count=None msg=0/6 nodes are available: 1 c_wall violated: 1 conflicting context pair(s) with node memory, 5 node(s) had untolerated taint(s). no new claims to deallocate, preemption: 0/6 nodes are available: 1 No preemption victims found for incoming pod, 5 Preemption is not helpful for scheduling."
0.0867,Event,ADDED,eval-sanitize-1-r1-076-27w26.18d4a23d98cb24c5,"reason=FailedScheduling count=None msg=0/6 nodes are available: 1 c_wall violated: 3 conflicting context pair(s) with node memory, 5 node(s) had untolerated taint(s). no new claims to deallocate, preemption: 0/6 nodes are available: 1 No preemption victims found for incoming pod, 5 Preemption is not helpful for scheduling."
0.0869,Event,ADDED,eval-sanitize-1-r1-076-27w26.18d4a23dfb086c9e,"reason=FailedScheduling count=None msg=0/6 nodes are available: 1 c_wall violated: 1 conflicting context pair(s) with node memory, 5 node(s) had untolerated taint(s). no new claims to deallocate, preemption: 0/6 nodes are available: 1 No preemption victims found for incoming pod, 5 Preemption is not helpful for scheduling."
0.0873,Event,ADDED,eval-sanitize-1-r1-076-27w26.18d4a23e88730e81,"reason=FailedScheduling count=None msg=0/6 nodes are available: 1 c_wall violated: 1 conflicting context pair(s) with node memory, 5 node(s) had untolerated taint(s). no new claims to deallocate, preemption: 0/6 nodes are available: 1 No preemption victims found for incoming pod, 5 Preemption is not helpful for scheduling."
0.0879,Event,ADDED,eval-sanitize-1-r1-076-27w26.18d4a23ec4369c8e,"reason=FailedScheduling count=None msg=0/6 nodes are available: 2 c_wall violated: 1 conflicting context pair(s) with node memory, 4 node(s) had untolerated taint(s). no new claims to deallocate, preemption: 0/6 nodes are available: 2 No preemption victims found for incoming pod, 4 Preemption is not helpful for scheduling."
0.0881,Event,ADDED,eval-sanitize-1-r1-076-27w26.18d4a23ed051272e,"reason=FailedScheduling count=None msg=0/6 nodes are available: 1 c_wall violated: 1 conflicting context pair(s) with node memory, 5 node(s) had untolerated taint(s). no new claims to deallocate, preemption: 0/6 nodes are available: 1 No preemption victims found for incoming pod, 5 Preemption is not helpful for scheduling."
0.0883,Event,ADDED,eval-sanitize-1-r1-076-27w26.18d4a23ed71fc8c6,"reason=FailedScheduling count=None msg=0/6 nodes are available: 1 c_wall violated: 2 conflicting context pair(s) with node memory, 5 node(s) had untolerated taint(s). no new claims to deallocate, preemption: 0/6 nodes are available: 1 No preemption victims found for incoming pod, 5 Preemption is not helpful for scheduling."
0.0887,Event,ADDED,eval-sanitize-1-r1-077-2zpts.18d4a239c001051f,"reason=FailedScheduling count=None msg=0/6 nodes are available: 1 c_wall violated: 2 conflicting context pair(s) with node memory, 5 node(s) had untolerated taint(s). no new claims to deallocate, preemption: 0/6 nodes are available: 1 No preemption victims found for incoming pod, 5 Preemption is not helpful for scheduling."
0.089,Event,ADDED,eval-sanitize-1-r1-081-j2c75.18d4a23d9176c292,"reason=FailedScheduling count=None msg=0/6 nodes are available: 1 c_wall violated: 2 conflicting context pair(s) with node memory, 5 node(s) had untolerated taint(s). no new claims to deallocate, preemption: 0/6 nodes are available: 1 No preemption victims found for incoming pod, 5 Preemption is not helpful for scheduling."
0.0891,Event,ADDED,eval-sanitize-1-r1-081-j2c75.18d4a23dff90b876,"reason=FailedScheduling count=None msg=0/6 nodes are available: 1 c_wall violated: 2 conflicting context pair(s) with node memory, 5 node(s) had untolerated taint(s). no new claims to deallocate, preemption: 0/6 nodes are available: 1 No preemption victims found for incoming pod, 5 Preemption is not helpful for scheduling."
0.0899,Job,MODIFIED,eval-sanitize-5-r1-000,
0.0903,Event,ADDED,eval-sanitize-1-r1-084-f4zcw.18d4a23d91d92d58,"reason=FailedScheduling count=None msg=0/6 nodes are available: 1 c_wall violated: 1 conflicting context pair(s) with node memory, 5 node(s) had untolerated taint(s). no new claims to deallocate, preemption: 0/6 nodes are available: 1 No preemption victims found for incoming pod, 5 Preemption is not helpful for scheduling."
0.0905,Event,ADDED,eval-sanitize-1-r1-084-f4zcw.18d4a23dfc0e3626,"reason=FailedScheduling count=None msg=0/6 nodes are available: 1 c_wall violated: 1 conflicting context pair(s) with node memory, 5 node(s) had untolerated taint(s). no new claims to deallocate, preemption: 0/6 nodes are available: 1 No preemption victims found for incoming pod, 5 Preemption is not helpful for scheduling."
0.0907,Event,ADDED,eval-sanitize-1-r1-084-f4zcw.18d4a23e8899a89f,"reason=FailedScheduling count=None msg=0/6 nodes are available: 1 c_wall violated: 2 conflicting context pair(s) with node memory, 5 node(s) had untolerated taint(s). no new claims to deallocate, preemption: 0/6 nodes are available: 1 No preemption victims found for incoming pod, 5 Preemption is not helpful for scheduling."
0.0911,Event,ADDED,eval-sanitize-1-r1-085-7rql6.18d4a23d93dc37bc,"reason=FailedScheduling count=None msg=0/6 nodes are available: 1 c_wall violated: 2 conflicting context pair(s) with node memory, 5 node(s) had untolerated taint(s). no new claims to deallocate, preemption: 0/6 nodes are available: 1 No preemption victims found for incoming pod, 5 Preemption is not helpful for scheduling."
0.0913,Event,ADDED,eval-sanitize-1-r1-086-qvrbj.18d4a23d9a3ed6e6,"reason=FailedScheduling count=None msg=0/6 nodes are available: 1 c_wall violated: 4 conflicting context pair(s) with node memory, 5 node(s) had untolerated taint(s). no new claims to deallocate, preemption: 0/6 nodes are available: 1 No preemption victims found for incoming pod, 5 Preemption is not helpful for scheduling."
0.0916,Event,ADDED,eval-sanitize-1-r1-086-qvrbj.18d4a23dfc4484af,"reason=FailedScheduling count=None msg=0/6 nodes are available: 1 c_wall violated: 1 conflicting context pair(s) with node memory, 5 node(s) had untolerated taint(s). no new claims to deallocate, preemption: 0/6 nodes are available: 1 No preemption victims found for incoming pod, 5 Preemption is not helpful for scheduling."
0.0918,Event,ADDED,eval-sanitize-1-r1-087-6cjgv.18d4a23d94a117ae,"reason=FailedScheduling count=None msg=0/6 nodes are available: 1 c_wall violated: 2 conflicting context pair(s) with node memory, 5 node(s) had untolerated taint(s). no new claims to deallocate, preemption: 0/6 nodes are available: 1 No preemption victims found for incoming pod, 5 Preemption is not helpful for scheduling."
0.092,Event,ADDED,eval-sanitize-1-r1-088-kdrft.18d4a23d9a703cb4,"reason=FailedScheduling count=None msg=0/6 nodes are available: 1 c_wall violated: 2 conflicting context pair(s) with node memory, 5 node(s) had untolerated taint(s). no new claims to deallocate, preemption: 0/6 nodes are available: 1 No preemption victims found for incoming pod, 5 Preemption is not helpful for scheduling."
0.0922,Event,ADDED,eval-sanitize-1-r1-090-lng2f.18d4a23d964cc431,"reason=FailedScheduling count=None msg=0/6 nodes are available: 1 c_wall violated: 2 conflicting context pair(s) with node memory, 5 node(s) had untolerated taint(s). no new claims to deallocate, preemption: 0/6 nodes are available: 1 No preemption victims found for incoming pod, 5 Preemption is not helpful for scheduling."
0.0924,Event,ADDED,eval-sanitize-1-r1-090-lng2f.18d4a23dff4038b5,"reason=FailedScheduling count=None msg=0/6 nodes are available: 1 c_wall violated: 2 conflicting context pair(s) with node memory, 5 node(s) had untolerated taint(s). no new claims to deallocate, preemption: 0/6 nodes are available: 1 No preemption victims found for incoming pod, 5 Preemption is not helpful for scheduling."
0.0927,Event,ADDED,eval-sanitize-1-r1-094-tl9kp.18d4a23dab5a297a,"reason=FailedScheduling count=None msg=0/6 nodes are available: 1 c_wall violated: 2 conflicting context pair(s) with node memory, 5 node(s) had untolerated taint(s). no new claims to deallocate, preemption: 0/6 nodes are available: 1 No preemption victims found for incoming pod, 5 Preemption is not helpful for scheduling."
0.093,Event,ADDED,eval-sanitize-1-r1-095-jmhgd.18d4a23e0766e3ce,"reason=FailedScheduling count=None msg=0/6 nodes are available: 1 c_wall violated: 1 conflicting context pair(s) with node memory, 5 node(s) had untolerated taint(s). no new claims to deallocate, preemption: 0/6 nodes are available: 1 No preemption victims found for incoming pod, 5 Preemption is not helpful for scheduling."
0.0932,Event,ADDED,eval-sanitize-1-r1-095-jmhgd.18d4a23e884a19f9,"reason=FailedScheduling count=None msg=0/6 nodes are available: 1 c_wall violated: 2 conflicting context pair(s) with node memory, 5 node(s) had untolerated taint(s). no new claims to deallocate, preemption: 0/6 nodes are available: 1 No preemption victims found for incoming pod, 5 Preemption is not helpful for scheduling."
0.0935,Event,ADDED,eval-sanitize-1-r1-096-gzvlz.18d4a23e88ca42ec,"reason=FailedScheduling count=None msg=0/6 nodes are available: 1 c_wall violated: 2 conflicting context pair(s) with node memory, 5 node(s) had untolerated taint(s). no new claims to deallocate, preemption: 0/6 nodes are available: 1 No preemption victims found for incoming pod, 5 Preemption is not helpful for scheduling."
0.0938,Event,ADDED,eval-sanitize-1-r1-097-tqtmq.18d4a23ea17aec04,"reason=FailedScheduling count=None msg=0/6 nodes are available: 1 c_wall violated: 2 conflicting context pair(s) with node memory, 5 node(s) had untolerated taint(s). no new claims to deallocate, preemption: 0/6 nodes are available: 1 No preemption victims found for incoming pod, 5 Preemption is not helpful for scheduling."
0.0943,Event,ADDED,eval-sanitize-1-r1-099-vnl6p.18d4a23f0c562dee,"reason=FailedScheduling count=None msg=0/6 nodes are available: 1 c_wall violated: 1 conflicting context pair(s) with node memory, 5 node(s) had untolerated taint(s). no new claims to deallocate, preemption: 0/6 nodes are available: 1 No preemption victims found for incoming pod, 5 Preemption is not helpful for scheduling."
0.0947,Event,ADDED,eval-sanitize-1-r1-100-2mmth.18d4a23f2dcf4dd9,"reason=FailedScheduling count=None msg=0/6 nodes are available: 1 c_wall violated: 1 conflicting context pair(s) with node memory, 5 node(s) had untolerated taint(s). no new claims to deallocate, preemption: 0/6 nodes are available: 1 No preemption victims found for incoming pod, 5 Preemption is not helpful for scheduling."
0.0951,Event,ADDED,eval-sanitize-1-r1-103-2zx4c.18d4a2444e537a52,"reason=FailedScheduling count=None msg=0/6 nodes are available: 1 c_wall violated: 2 conflicting context pair(s) with node memory, 5 node(s) had untolerated taint(s). no new claims to deallocate, preemption: 0/6 nodes are available: 1 No preemption victims found for incoming pod, 5 Preemption is not helpful for scheduling."
0.0953,Event,ADDED,eval-sanitize-1-r1-111-wmwlw.18d4a2444e8fc02c,"reason=FailedScheduling count=None msg=0/6 nodes are available: 1 c_wall violated: 1 conflicting context pair(s) with node memory, 5 node(s) had untolerated taint(s). no new claims to deallocate, preemption: 0/6 nodes are available: 1 No preemption victims found for incoming pod, 5 Preemption is not helpful for scheduling."
0.0957,Event,ADDED,eval-sanitize-1-r1-115-dltsh.18d4a2444ec13291,"reason=FailedScheduling count=None msg=0/6 nodes are available: 1 c_wall violated: 1 conflicting context pair(s) with node memory, 5 node(s) had untolerated taint(s). no new claims to deallocate, preemption: 0/6 nodes are available: 1 No preemption victims found for incoming pod, 5 Preemption is not helpful for scheduling."
0.0959,Event,ADDED,eval-sanitize-1-r1-116-529zn.18d4a2444a1ee163,"reason=FailedScheduling count=None msg=0/6 nodes are available: 1 c_wall violated: 1 conflicting context pair(s) with node memory, 5 node(s) had untolerated taint(s). no new claims to deallocate, preemption: 0/6 nodes are available: 1 No preemption victims found for incoming pod, 5 Preemption is not helpful for scheduling."
0.0963,Event,ADDED,eval-sanitize-1-r1-117-wb2jr.18d4a2444a543432,"reason=FailedScheduling count=None msg=0/6 nodes are available: 1 c_wall violated: 2 conflicting context pair(s) with node memory, 5 node(s) had untolerated taint(s). no new claims to deallocate, preemption: 0/6 nodes are available: 1 No preemption victims found for incoming pod, 5 Preemption is not helpful for scheduling."
0.0967,Event,ADDED,eval-sanitize-1-r1-118-dbnc7.18d4a2444a847876,"reason=FailedScheduling count=None msg=0/6 nodes are available: 1 c_wall violated: 1 conflicting context pair(s) with node memory, 5 node(s) had untolerated taint(s). no new claims to deallocate, preemption: 0/6 nodes are available: 1 No preemption victims found for incoming pod, 5 Preemption is not helpful for scheduling."
0.0969,Event,ADDED,eval-sanitize-1-r1-123-sl7r8.18d4a244712892ea,"reason=FailedScheduling count=None msg=0/6 nodes are available: 1 c_wall violated: 1 conflicting context pair(s) with node memory, 1 c_wall violated: 2 conflicting context pair(s) with node memory, 4 node(s) had untolerated taint(s). no new claims to deallocate, preemption: 0/6 nodes are available: 2 No preemption victims found for incoming pod, 4 Preemption is not helpful for scheduling."
0.0971,Event,ADDED,eval-sanitize-1-r1-123-sl7r8.18d4a24497aa3a5b,"reason=FailedScheduling count=None msg=0/6 nodes are available: 1 c_wall violated: 1 conflicting context pair(s) with node memory, 5 node(s) had untolerated taint(s). no new claims to deallocate, preemption: 0/6 nodes are available: 1 No preemption victims found for incoming pod, 5 Preemption is not helpful for scheduling."
0.0974,Event,ADDED,eval-sanitize-1-r1-125-r4jn5.18d4a2456c5399be,"reason=FailedScheduling count=None msg=0/6 nodes are available: 1 c_wall violated: 2 conflicting context pair(s) with node memory, 5 node(s) had untolerated taint(s). no new claims to deallocate, preemption: 0/6 nodes are available: 1 No preemption victims found for incoming pod, 5 Preemption is not helpful for scheduling."
0.0976,Event,ADDED,eval-sanitize-1-r1-125-r4jn5.18d4a2497328684b,"reason=FailedScheduling count=None msg=0/6 nodes are available: 1 c_wall violated: 1 conflicting context pair(s) with node memory, 5 node(s) had untolerated taint(s). no new claims to deallocate, preemption: 0/6 nodes are available: 1 No preemption victims found for incoming pod, 5 Preemption is not helpful for scheduling."
0.0978,Event,ADDED,eval-sanitize-1-r1-125-r4jn5.18d4a24a75922798,"reason=FailedScheduling count=None msg=0/6 nodes are available: 1 c_wall violated: 1 conflicting context pair(s) with node memory, 5 node(s) had untolerated taint(s). no new claims to deallocate, preemption: 0/6 nodes are available: 1 No preemption victims found for incoming pod, 5 Preemption is not helpful for scheduling."
0.0985,Event,ADDED,eval-sanitize-1-r1-125-r4jn5.18d4a24a9d9d51ea,"reason=FailedScheduling count=None msg=0/6 nodes are available: 2 c_wall violated: 1 conflicting context pair(s) with node memory, 4 node(s) had untolerated taint(s). no new claims to deallocate, preemption: 0/6 nodes are available: 2 No preemption victims found for incoming pod, 4 Preemption is not helpful for scheduling."
0.099,Event,ADDED,eval-sanitize-1-r1-125-r4jn5.18d4a24acc78ba6c,"reason=FailedScheduling count=None msg=0/6 nodes are available: 1 c_wall violated: 1 conflicting context pair(s) with node memory, 5 node(s) had untolerated taint(s). no new claims to deallocate, preemption: 0/6 nodes are available: 1 No preemption victims found for incoming pod, 5 Preemption is not helpful for scheduling."
0.0994,Event,ADDED,eval-sanitize-1-r1-125-r4jn5.18d4a24aea33d2bc,"reason=FailedScheduling count=None msg=0/6 nodes are available: 1 c_wall violated: 1 conflicting context pair(s) with node memory, 5 node(s) had untolerated taint(s). no new claims to deallocate, preemption: 0/6 nodes are available: 1 No preemption victims found for incoming pod, 5 Preemption is not helpful for scheduling."
0.0998,Event,ADDED,eval-sanitize-1-r1-126-sssrt.18d4a2456c2705fa,"reason=FailedScheduling count=None msg=0/6 nodes are available: 1 c_wall violated: 1 conflicting context pair(s) with node memory, 5 node(s) had untolerated taint(s). no new claims to deallocate, preemption: 0/6 nodes are available: 1 No preemption victims found for incoming pod, 5 Preemption is not helpful for scheduling."
0.1,Event,ADDED,eval-sanitize-1-r1-128-944xf.18d4a24594720fd3,"reason=FailedScheduling count=None msg=0/6 nodes are available: 1 c_wall violated: 1 conflicting context pair(s) with node memory, 5 node(s) had untolerated taint(s). no new claims to deallocate, preemption: 0/6 nodes are available: 1 No preemption victims found for incoming pod, 5 Preemption is not helpful for scheduling."
0.1009,Pod,MODIFIED,eval-sanitize-5-r1-000-7v7fb,phase=Pending node=kind-worker
0.1012,Event,ADDED,eval-sanitize-1-r1-131-sqjg8.18d4a249735e9758,"reason=FailedScheduling count=None msg=0/6 nodes are available: 1 c_wall violated: 1 conflicting context pair(s) with node memory, 5 node(s) had untolerated taint(s). no new claims to deallocate, preemption: 0/6 nodes are available: 1 No preemption victims found for incoming pod, 5 Preemption is not helpful for scheduling."
0.1014,Event,ADDED,eval-sanitize-1-r1-133-h9qbg.18d4a24973b8f03e,"reason=FailedScheduling count=None msg=0/6 nodes are available: 1 c_wall violated: 1 conflicting context pair(s) with node memory, 5 node(s) had untolerated taint(s). no new claims to deallocate, preemption: 0/6 nodes are available: 1 No preemption victims found for incoming pod, 5 Preemption is not helpful for scheduling."
0.1016,Event,ADDED,eval-sanitize-1-r1-134-5lb9m.18d4a24975436d98,"reason=FailedScheduling count=None msg=0/6 nodes are available: 1 c_wall violated: 1 conflicting context pair(s) with node memory, 5 node(s) had untolerated taint(s). no new claims to deallocate, preemption: 0/6 nodes are available: 1 No preemption victims found for incoming pod, 5 Preemption is not helpful for scheduling."
0.102,Event,ADDED,eval-sanitize-1-r1-134-5lb9m.18d4a24a763bfa66,"reason=FailedScheduling count=None msg=0/6 nodes are available: 1 c_wall violated: 1 conflicting context pair(s) with node memory, 5 node(s) had untolerated taint(s). no new claims to deallocate, preemption: 0/6 nodes are available: 1 No preemption victims found for incoming pod, 5 Preemption is not helpful for scheduling."
0.1023,Event,ADDED,eval-sanitize-1-r1-134-5lb9m.18d4a24aa28597ff,"reason=FailedScheduling count=None msg=0/6 nodes are available: 2 c_wall violated: 1 conflicting context pair(s) with node memory, 4 node(s) had untolerated taint(s). no new claims to deallocate, preemption: 0/6 nodes are available: 2 No preemption victims found for incoming pod, 4 Preemption is not helpful for scheduling."
0.1025,Event,ADDED,eval-sanitize-1-r1-134-5lb9m.18d4a24acca9c53f,"reason=FailedScheduling count=None msg=0/6 nodes are available: 1 c_wall violated: 1 conflicting context pair(s) with node memory, 5 node(s) had untolerated taint(s). no new claims to deallocate, preemption: 0/6 nodes are available: 1 No preemption victims found for incoming pod, 5 Preemption is not helpful for scheduling."
0.1029,Event,ADDED,eval-sanitize-1-r1-134-5lb9m.18d4a24aea6684d5,"reason=FailedScheduling count=None msg=0/6 nodes are available: 1 c_wall violated: 1 conflicting context pair(s) with node memory, 5 node(s) had untolerated taint(s). no new claims to deallocate, preemption: 0/6 nodes are available: 1 No preemption victims found for incoming pod, 5 Preemption is not helpful for scheduling."
0.1031,Event,ADDED,eval-sanitize-1-r1-135-kqpj2.18d4a249757e3960,"reason=FailedScheduling count=None msg=0/6 nodes are available: 1 c_wall violated: 2 conflicting context pair(s) with node memory, 5 node(s) had untolerated taint(s). no new claims to deallocate, preemption: 0/6 nodes are available: 1 No preemption victims found for incoming pod, 5 Preemption is not helpful for scheduling."
0.1033,Event,ADDED,eval-sanitize-1-r1-136-v5hmk.18d4a24975aadf02,"reason=FailedScheduling count=None msg=0/6 nodes are available: 1 c_wall violated: 1 conflicting context pair(s) with node memory, 5 node(s) had untolerated taint(s). no new claims to deallocate, preemption: 0/6 nodes are available: 1 No preemption victims found for incoming pod, 5 Preemption is not helpful for scheduling."
0.1037,Event,ADDED,eval-sanitize-1-r1-137-2h49b.18d4a24977281892,"reason=FailedScheduling count=None msg=0/6 nodes are available: 1 c_wall violated: 2 conflicting context pair(s) with node memory, 5 node(s) had untolerated taint(s). no new claims to deallocate, preemption: 0/6 nodes are available: 1 No preemption victims found for incoming pod, 5 Preemption is not helpful for scheduling."
0.1039,Event,ADDED,eval-sanitize-1-r1-139-s28q8.18d4a24978aaec00,"reason=FailedScheduling count=None msg=0/6 nodes are available: 1 c_wall violated: 2 conflicting context pair(s) with node memory, 5 node(s) had untolerated taint(s). no new claims to deallocate, preemption: 0/6 nodes are available: 1 No preemption victims found for incoming pod, 5 Preemption is not helpful for scheduling."
0.1041,Event,ADDED,eval-sanitize-1-r1-140-qfqhd.18d4a24979b224a1,"reason=FailedScheduling count=None msg=0/6 nodes are available: 1 c_wall violated: 1 conflicting context pair(s) with node memory, 5 node(s) had untolerated taint(s). no new claims to deallocate, preemption: 0/6 nodes are available: 1 No preemption victims found for incoming pod, 5 Preemption is not helpful for scheduling."
0.1044,Event,ADDED,eval-sanitize-1-r1-140-qfqhd.18d4a24a79da9d01,"reason=FailedScheduling count=None msg=0/6 nodes are available: 1 c_wall violated: 1 conflicting context pair(s) with node memory, 5 node(s) had untolerated taint(s). no new claims to deallocate, preemption: 0/6 nodes are available: 1 No preemption victims found for incoming pod, 5 Preemption is not helpful for scheduling."
0.1046,Event,ADDED,eval-sanitize-1-r1-140-qfqhd.18d4a24a9ce02550,"reason=FailedScheduling count=None msg=0/6 nodes are available: 2 c_wall violated: 1 conflicting context pair(s) with node memory, 4 node(s) had untolerated taint(s). no new claims to deallocate, preemption: 0/6 nodes are available: 2 No preemption victims found for incoming pod, 4 Preemption is not helpful for scheduling."
0.1048,Event,ADDED,eval-sanitize-1-r1-140-qfqhd.18d4a24acc3de956,"reason=FailedScheduling count=None msg=0/6 nodes are available: 1 c_wall violated: 1 conflicting context pair(s) with node memory, 5 node(s) had untolerated taint(s). no new claims to deallocate, preemption: 0/6 nodes are available: 1 No preemption victims found for incoming pod, 5 Preemption is not helpful for scheduling."
0.105,Event,ADDED,eval-sanitize-1-r1-140-qfqhd.18d4a24aea02ad90,"reason=FailedScheduling count=None msg=0/6 nodes are available: 1 c_wall violated: 1 conflicting context pair(s) with node memory, 5 node(s) had untolerated taint(s). no new claims to deallocate, preemption: 0/6 nodes are available: 1 No preemption victims found for incoming pod, 5 Preemption is not helpful for scheduling."
0.1052,Event,ADDED,eval-sanitize-1-r1-141-hfwx8.18d4a24979e4a875,"reason=FailedScheduling count=None msg=0/6 nodes are available: 1 c_wall violated: 2 conflicting context pair(s) with node memory, 5 node(s) had untolerated taint(s). no new claims to deallocate, preemption: 0/6 nodes are available: 1 No preemption victims found for incoming pod, 5 Preemption is not helpful for scheduling."
0.1056,Event,ADDED,eval-sanitize-1-r1-142-wwvlq.18d4a2497a161119,"reason=FailedScheduling count=None msg=0/6 nodes are available: 1 c_wall violated: 1 conflicting context pair(s) with node memory, 5 node(s) had untolerated taint(s). no new claims to deallocate, preemption: 0/6 nodes are available: 1 No preemption victims found for incoming pod, 5 Preemption is not helpful for scheduling."
0.1058,Event,ADDED,eval-sanitize-1-r1-142-wwvlq.18d4a24a003ef08d,"reason=FailedScheduling count=None msg=0/6 nodes are available: 1 c_wall violated: 2 conflicting context pair(s) with node memory, 5 node(s) had untolerated taint(s). no new claims to deallocate, preemption: 0/6 nodes are available: 1 No preemption victims found for incoming pod, 5 Preemption is not helpful for scheduling."
0.106,Event,ADDED,eval-sanitize-1-r1-144-lgngv.18d4a2497a5495b3,"reason=FailedScheduling count=None msg=0/6 nodes are available: 1 c_wall violated: 1 conflicting context pair(s) with node memory, 5 node(s) had untolerated taint(s). no new claims to deallocate, preemption: 0/6 nodes are available: 1 No preemption victims found for incoming pod, 5 Preemption is not helpful for scheduling."
0.1064,Event,ADDED,eval-sanitize-1-r1-147-dbvhw.18d4a24a8499f093,"reason=FailedScheduling count=None msg=0/6 nodes are available: 1 c_wall violated: 2 conflicting context pair(s) with node memory, 5 node(s) had untolerated taint(s). no new claims to deallocate, preemption: 0/6 nodes are available: 1 No preemption victims found for incoming pod, 5 Preemption is not helpful for scheduling."
0.1067,Event,ADDED,eval-sanitize-1-r1-147-dbvhw.18d4a24aa2de5abb,"reason=FailedScheduling count=None msg=0/6 nodes are available: 1 c_wall violated: 1 conflicting context pair(s) with node memory, 1 c_wall violated: 2 conflicting context pair(s) with node memory, 4 node(s) had untolerated taint(s). no new claims to deallocate, preemption: 0/6 nodes are available: 2 No preemption victims found for incoming pod, 4 Preemption is not helpful for scheduling."
0.1069,Event,ADDED,eval-sanitize-1-r1-149-fp4fx.18d4a24aeaa15231,"reason=FailedScheduling count=None msg=0/6 nodes are available: 1 c_wall violated: 1 conflicting context pair(s) with node memory, 5 node(s) had untolerated taint(s). no new claims to deallocate, preemption: 0/6 nodes are available: 1 No preemption victims found for incoming pod, 5 Preemption is not helpful for scheduling."
0.1075,Event,ADDED,eval-sanitize-1-r1-149-fp4fx.18d4a24ecf263492,"reason=FailedScheduling count=None msg=0/6 nodes are available: 1 c_wall violated: 2 conflicting context pair(s) with node memory, 5 node(s) had untolerated taint(s). no new claims to deallocate, preemption: 0/6 nodes are available: 1 No preemption victims found for incoming pod, 5 Preemption is not helpful for scheduling."
0.1081,Event,ADDED,eval-sanitize-1-r1-150-crp5h.18d4a24ecf5393be,"reason=FailedScheduling count=None msg=0/6 nodes are available: 1 c_wall violated: 2 conflicting context pair(s) with node memory, 5 node(s) had untolerated taint(s). no new claims to deallocate, preemption: 0/6 nodes are available: 1 No preemption victims found for incoming pod, 5 Preemption is not helpful for scheduling."
0.1083,Event,ADDED,eval-sanitize-1-r1-150-crp5h.18d4a2505fa87006,"reason=FailedScheduling count=None msg=0/6 nodes are available: 1 c_wall violated: 2 conflicting context pair(s) with node memory, 5 node(s) had untolerated taint(s). no new claims to deallocate, preemption: 0/6 nodes are available: 1 No preemption victims found for incoming pod, 5 Preemption is not helpful for scheduling."
0.1085,TaskRequest,MODIFIED,eval-sanitize-5-r1-000,phase=Scheduled job=None
0.1089,Event,ADDED,eval-sanitize-1-r1-150-crp5h.18d4a250c9cde3a4,"reason=FailedScheduling count=None msg=0/6 nodes are available: 1 c_wall violated: 1 conflicting context pair(s) with node memory, 5 node(s) had untolerated taint(s). no new claims to deallocate, preemption: 0/6 nodes are available: 1 No preemption victims found for incoming pod, 5 Preemption is not helpful for scheduling."
0.1091,Event,ADDED,eval-sanitize-1-r1-153-dcfbm.18d4a24ec6485bab,"reason=FailedScheduling count=None msg=0/6 nodes are available: 1 c_wall violated: 2 conflicting context pair(s) with node memory, 5 node(s) had untolerated taint(s). no new claims to deallocate, preemption: 0/6 nodes are available: 1 No preemption victims found for incoming pod, 5 Preemption is not helpful for scheduling."
0.1094,Event,ADDED,eval-sanitize-1-r1-155-gcvx2.18d4a24ec88281f8,"reason=FailedScheduling count=None msg=0/6 nodes are available: 1 c_wall violated: 2 conflicting context pair(s) with node memory, 5 node(s) had untolerated taint(s). no new claims to deallocate, preemption: 0/6 nodes are available: 1 No preemption victims found for incoming pod, 5 Preemption is not helpful for scheduling."
0.1112,Pod,MODIFIED,eval-sanitize-5-r1-000-7v7fb,phase=Pending node=kind-worker
0.1115,Event,ADDED,eval-sanitize-1-r1-156-rsm5t.18d4a24ec8b7e940,"reason=FailedScheduling count=None msg=0/6 nodes are available: 1 c_wall violated: 1 conflicting context pair(s) with node memory, 5 node(s) had untolerated taint(s). no new claims to deallocate, preemption: 0/6 nodes are available: 1 No preemption victims found for incoming pod, 5 Preemption is not helpful for scheduling."
0.1118,Event,ADDED,eval-sanitize-1-r1-158-nnc85.18d4a24ec8ea6212,"reason=FailedScheduling count=None msg=0/6 nodes are available: 1 c_wall violated: 3 conflicting context pair(s) with node memory, 5 node(s) had untolerated taint(s). no new claims to deallocate, preemption: 0/6 nodes are available: 1 No preemption victims found for incoming pod, 5 Preemption is not helpful for scheduling."
0.1121,Event,ADDED,eval-sanitize-1-r1-159-pzvf4.18d4a24ec91a4263,"reason=FailedScheduling count=None msg=0/6 nodes are available: 1 c_wall violated: 1 conflicting context pair(s) with node memory, 5 node(s) had untolerated taint(s). no new claims to deallocate, preemption: 0/6 nodes are available: 1 No preemption victims found for incoming pod, 5 Preemption is not helpful for scheduling."
0.1123,Event,ADDED,eval-sanitize-1-r1-160-7k4m8.18d4a24ec94b5a44,"reason=FailedScheduling count=None msg=0/6 nodes are available: 1 c_wall violated: 2 conflicting context pair(s) with node memory, 5 node(s) had untolerated taint(s). no new claims to deallocate, preemption: 0/6 nodes are available: 1 No preemption victims found for incoming pod, 5 Preemption is not helpful for scheduling."
0.1125,Event,ADDED,eval-sanitize-1-r1-161-qwktj.18d4a24ec978a917,"reason=FailedScheduling count=None msg=0/6 nodes are available: 1 c_wall violated: 2 conflicting context pair(s) with node memory, 5 node(s) had untolerated taint(s). no new claims to deallocate, preemption: 0/6 nodes are available: 1 No preemption victims found for incoming pod, 5 Preemption is not helpful for scheduling."
0.1129,Event,ADDED,eval-sanitize-1-r1-162-gjc7m.18d4a24ecd5bac4d,"reason=FailedScheduling count=None msg=0/6 nodes are available: 1 c_wall violated: 2 conflicting context pair(s) with node memory, 5 node(s) had untolerated taint(s). no new claims to deallocate, preemption: 0/6 nodes are available: 1 No preemption victims found for incoming pod, 5 Preemption is not helpful for scheduling."
0.1131,Event,ADDED,eval-sanitize-1-r1-163-69g7n.18d4a24ece8cb35e,"reason=FailedScheduling count=None msg=0/6 nodes are available: 1 c_wall violated: 2 conflicting context pair(s) with node memory, 5 node(s) had untolerated taint(s). no new claims to deallocate, preemption: 0/6 nodes are available: 1 No preemption victims found for incoming pod, 5 Preemption is not helpful for scheduling."
0.1133,Event,ADDED,eval-sanitize-1-r1-163-69g7n.18d4a2505de8827c,"reason=FailedScheduling count=None msg=0/6 nodes are available: 1 c_wall violated: 2 conflicting context pair(s) with node memory, 5 node(s) had untolerated taint(s). no new claims to deallocate, preemption: 0/6 nodes are available: 1 No preemption victims found for incoming pod, 5 Preemption is not helpful for scheduling."
0.1146,Node,MODIFIED,kind-worker,taints=0
0.1149,Event,ADDED,eval-sanitize-1-r1-163-69g7n.18d4a250b6580bdd,"reason=FailedScheduling count=None msg=0/6 nodes are available: 1 c_wall violated: 1 conflicting context pair(s) with node memory, 2 c_wall violated: 2 conflicting context pair(s) with node memory, 3 node(s) had untolerated taint(s). no new claims to deallocate, preemption: 0/6 nodes are available: 3 No preemption victims found for incoming pod, 3 Preemption is not helpful for scheduling."
0.1151,Event,ADDED,eval-sanitize-1-r1-163-69g7n.18d4a250ca3871a7,"reason=FailedScheduling count=None msg=0/6 nodes are available: 1 c_wall violated: 1 conflicting context pair(s) with node memory, 5 node(s) had untolerated taint(s). no new claims to deallocate, preemption: 0/6 nodes are available: 1 No preemption victims found for incoming pod, 5 Preemption is not helpful for scheduling."
0.1153,Event,ADDED,eval-sanitize-1-r1-164-m2qzw.18d4a24ecec8230c,"reason=FailedScheduling count=None msg=0/6 nodes are available: 1 c_wall violated: 3 conflicting context pair(s) with node memory, 5 node(s) had untolerated taint(s). no new claims to deallocate, preemption: 0/6 nodes are available: 1 No preemption victims found for incoming pod, 5 Preemption is not helpful for scheduling."
0.1157,Event,ADDED,eval-sanitize-1-r1-164-m2qzw.18d4a2505f70da4a,"reason=FailedScheduling count=None msg=0/6 nodes are available: 1 c_wall violated: 2 conflicting context pair(s) with node memory, 5 node(s) had untolerated taint(s). no new claims to deallocate, preemption: 0/6 nodes are available: 1 No preemption victims found for incoming pod, 5 Preemption is not helpful for scheduling."
0.1159,Event,ADDED,eval-sanitize-1-r1-166-zdpnq.18d4a24ecef8637c,"reason=FailedScheduling count=None msg=0/6 nodes are available: 1 c_wall violated: 1 conflicting context pair(s) with node memory, 5 node(s) had untolerated taint(s). no new claims to deallocate, preemption: 0/6 nodes are available: 1 No preemption victims found for incoming pod, 5 Preemption is not helpful for scheduling."
0.1161,Event,ADDED,eval-sanitize-1-r1-170-gjj5w.18d4a25060324209,"reason=FailedScheduling count=None msg=0/6 nodes are available: 1 c_wall violated: 2 conflicting context pair(s) with node memory, 5 node(s) had untolerated taint(s). no new claims to deallocate, preemption: 0/6 nodes are available: 1 No preemption victims found for incoming pod, 5 Preemption is not helpful for scheduling."
0.1164,Event,ADDED,eval-sanitize-1-r1-174-nzghb.18d4a250ca0134a7,"reason=FailedScheduling count=None msg=0/6 nodes are available: 1 c_wall violated: 1 conflicting context pair(s) with node memory, 5 node(s) had untolerated taint(s). no new claims to deallocate, preemption: 0/6 nodes are available: 1 No preemption victims found for incoming pod, 5 Preemption is not helpful for scheduling."
0.1166,Event,ADDED,eval-sanitize-1-r1-177-rr774.18d4a25466ce03c3,"reason=FailedScheduling count=None msg=0/6 nodes are available: 1 c_wall violated: 1 conflicting context pair(s) with node memory, 5 node(s) had untolerated taint(s). no new claims to deallocate, preemption: 0/6 nodes are available: 1 No preemption victims found for incoming pod, 5 Preemption is not helpful for scheduling."
0.1169,Event,ADDED,eval-sanitize-1-r1-196-jjtkn.18d4a2561e0ff726,"reason=FailedScheduling count=None msg=0/6 nodes are available: 1 c_wall violated: 1 conflicting context pair(s) with node memory, 1 c_wall violated: 2 conflicting context pair(s) with node memory, 4 node(s) had untolerated taint(s). no new claims to deallocate, preemption: 0/6 nodes are available: 2 No preemption victims found for incoming pod, 4 Preemption is not helpful for scheduling."
0.1171,Event,ADDED,eval-sanitize-1-r1-196-jjtkn.18d4a25641b3e82a,"reason=FailedScheduling count=None msg=0/6 nodes are available: 1 c_wall violated: 2 conflicting context pair(s) with node memory, 5 node(s) had untolerated taint(s). no new claims to deallocate, preemption: 0/6 nodes are available: 1 No preemption victims found for incoming pod, 5 Preemption is not helpful for scheduling."
0.1172,Event,ADDED,eval-sanitize-1-r2-007-gqkxz.18d4a26f0041a9b1,"reason=FailedScheduling count=None msg=0/6 nodes are available: 1 c_wall violated: 2 conflicting context pair(s) with node memory, 5 node(s) had untolerated taint(s). no new claims to deallocate, preemption: 0/6 nodes are available: 1 No preemption victims found for incoming pod, 5 Preemption is not helpful for scheduling."
0.1175,Event,ADDED,eval-sanitize-1-r2-007-gqkxz.18d4a26f507c4ec2,"reason=FailedScheduling count=None msg=0/6 nodes are available: 1 c_wall violated: 2 conflicting context pair(s) with node memory, 5 node(s) had untolerated taint(s). no new claims to deallocate, preemption: 0/6 nodes are available: 1 No preemption victims found for incoming pod, 5 Preemption is not helpful for scheduling."
0.1177,Event,ADDED,eval-sanitize-1-r2-007-gqkxz.18d4a26f7ec35dd1,"reason=FailedScheduling count=None msg=0/6 nodes are available: 1 c_wall violated: 1 conflicting context pair(s) with node memory, 1 c_wall violated: 2 conflicting context pair(s) with node memory, 4 node(s) had untolerated taint(s). no new claims to deallocate, preemption: 0/6 nodes are available: 2 No preemption victims found for incoming pod, 4 Preemption is not helpful for scheduling."
0.1179,Event,ADDED,eval-sanitize-1-r2-009-6bkgh.18d4a26ef74eba40,"reason=FailedScheduling count=None msg=0/6 nodes are available: 1 c_wall violated: 1 conflicting context pair(s) with node memory, 5 node(s) had untolerated taint(s). no new claims to deallocate, preemption: 0/6 nodes are available: 1 No preemption victims found for incoming pod, 5 Preemption is not helpful for scheduling."
0.1184,Event,ADDED,eval-sanitize-1-r2-009-6bkgh.18d4a26f50af207d,"reason=FailedScheduling count=None msg=0/6 nodes are available: 1 c_wall violated: 1 conflicting context pair(s) with node memory, 5 node(s) had untolerated taint(s). no new claims to deallocate, preemption: 0/6 nodes are available: 1 No preemption victims found for incoming pod, 5 Preemption is not helpful for scheduling."
0.1186,Event,ADDED,eval-sanitize-1-r2-010-9pm5k.18d4a26f01527480,"reason=FailedScheduling count=None msg=0/6 nodes are available: 1 c_wall violated: 3 conflicting context pair(s) with node memory, 5 node(s) had untolerated taint(s). no new claims to deallocate, preemption: 0/6 nodes are available: 1 No preemption victims found for incoming pod, 5 Preemption is not helpful for scheduling."
0.1188,Event,ADDED,eval-sanitize-1-r2-011-rtrl2.18d4a26f0195eeed,"reason=FailedScheduling count=None msg=0/6 nodes are available: 1 c_wall violated: 3 conflicting context pair(s) with node memory, 5 node(s) had untolerated taint(s). no new claims to deallocate, preemption: 0/6 nodes are available: 1 No preemption victims found for incoming pod, 5 Preemption is not helpful for scheduling."
0.1192,Event,ADDED,eval-sanitize-1-r2-015-s4gn8.18d4a26efa5623d2,"reason=FailedScheduling count=None msg=0/6 nodes are available: 1 c_wall violated: 2 conflicting context pair(s) with node memory, 5 node(s) had untolerated taint(s). no new claims to deallocate, preemption: 0/6 nodes are available: 1 No preemption victims found for incoming pod, 5 Preemption is not helpful for scheduling."
0.1194,Event,ADDED,eval-sanitize-1-r2-015-s4gn8.18d4a26f4d3c9ed2,"reason=FailedScheduling count=None msg=0/6 nodes are available: 1 c_wall violated: 2 conflicting context pair(s) with node memory, 5 node(s) had untolerated taint(s). no new claims to deallocate, preemption: 0/6 nodes are available: 1 No preemption victims found for incoming pod, 5 Preemption is not helpful for scheduling."
0.1195,Event,ADDED,eval-sanitize-1-r2-016-scn2f.18d4a26efa8610ad,"reason=FailedScheduling count=None msg=0/6 nodes are available: 1 c_wall violated: 3 conflicting context pair(s) with node memory, 5 node(s) had untolerated taint(s). no new claims to deallocate, preemption: 0/6 nodes are available: 1 No preemption victims found for incoming pod, 5 Preemption is not helpful for scheduling."
0.1199,Event,ADDED,eval-sanitize-1-r2-019-hnhx9.18d4a26efabdceb9,"reason=FailedScheduling count=None msg=0/6 nodes are available: 1 c_wall violated: 1 conflicting context pair(s) with node memory, 5 node(s) had untolerated taint(s). no new claims to deallocate, preemption: 0/6 nodes are available: 1 No preemption victims found for incoming pod, 5 Preemption is not helpful for scheduling."
0.1201,Event,ADDED,eval-sanitize-1-r2-019-hnhx9.18d4a26f4d6bcce9,"reason=FailedScheduling count=None msg=0/6 nodes are available: 1 c_wall violated: 1 conflicting context pair(s) with node memory, 5 node(s) had untolerated taint(s). no new claims to deallocate, preemption: 0/6 nodes are available: 1 No preemption victims found for incoming pod, 5 Preemption is not helpful for scheduling."
0.1204,Event,ADDED,eval-sanitize-1-r2-020-hhd6m.18d4a26efb7b589f,"reason=FailedScheduling count=None msg=0/6 nodes are available: 1 c_wall violated: 3 conflicting context pair(s) with node memory, 5 node(s) had untolerated taint(s). no new claims to deallocate, preemption: 0/6 nodes are available: 1 No preemption victims found for incoming pod, 5 Preemption is not helpful for scheduling."
0.1206,Event,ADDED,eval-sanitize-1-r2-022-d4pvk.18d4a26efbbe70d1,"reason=FailedScheduling count=None msg=0/6 nodes are available: 1 c_wall violated: 2 conflicting context pair(s) with node memory, 5 node(s) had untolerated taint(s). no new claims to deallocate, preemption: 0/6 nodes are available: 1 No preemption victims found for incoming pod, 5 Preemption is not helpful for scheduling."
0.1208,Event,ADDED,eval-sanitize-1-r2-022-d4pvk.18d4a26f4ee91922,"reason=FailedScheduling count=None msg=0/6 nodes are available: 1 c_wall violated: 2 conflicting context pair(s) with node memory, 5 node(s) had untolerated taint(s). no new claims to deallocate, preemption: 0/6 nodes are available: 1 No preemption victims found for incoming pod, 5 Preemption is not helpful for scheduling."
0.1213,Event,ADDED,eval-sanitize-1-r2-023-mrbjr.18d4a26f00a2adbf,"reason=FailedScheduling count=None msg=0/6 nodes are available: 1 c_wall violated: 2 conflicting context pair(s) with node memory, 5 node(s) had untolerated taint(s). no new claims to deallocate, preemption: 0/6 nodes are available: 1 No preemption victims found for incoming pod, 5 Preemption is not helpful for scheduling."
0.1215,Event,ADDED,eval-sanitize-1-r2-023-mrbjr.18d4a26f50d901aa,"reason=FailedScheduling count=None msg=0/6 nodes are available: 1 c_wall violated: 2 conflicting context pair(s) with node memory, 5 node(s) had untolerated taint(s). no new claims to deallocate, preemption: 0/6 nodes are available: 1 No preemption victims found for incoming pod, 5 Preemption is not helpful for scheduling."
0.1217,Event,ADDED,eval-sanitize-1-r2-023-mrbjr.18d4a26f7f0c9173,"reason=FailedScheduling count=None msg=0/6 nodes are available: 1 c_wall violated: 1 conflicting context pair(s) with node memory, 1 c_wall violated: 2 conflicting context pair(s) with node memory, 4 node(s) had untolerated taint(s). no new claims to deallocate, preemption: 0/6 nodes are available: 2 No preemption victims found for incoming pod, 4 Preemption is not helpful for scheduling."
0.1221,Event,ADDED,eval-sanitize-1-r2-030-knm6p.18d4a27491f94f91,"reason=FailedScheduling count=None msg=0/6 nodes are available: 1 c_wall violated: 1 conflicting context pair(s) with node memory, 5 node(s) had untolerated taint(s). no new claims to deallocate, preemption: 0/6 nodes are available: 1 No preemption victims found for incoming pod, 5 Preemption is not helpful for scheduling."
0.1224,Event,ADDED,eval-sanitize-1-r2-030-knm6p.18d4a27539bd557d,"reason=FailedScheduling count=None msg=0/6 nodes are available: 1 c_wall violated: 1 conflicting context pair(s) with node memory, 1 c_wall violated: 3 conflicting context pair(s) with node memory, 4 node(s) had untolerated taint(s). no new claims to deallocate, preemption: 0/6 nodes are available: 2 No preemption victims found for incoming pod, 4 Preemption is not helpful for scheduling."
0.1225,Event,ADDED,eval-sanitize-1-r2-030-knm6p.18d4a2754b9568b1,"reason=FailedScheduling count=None msg=0/6 nodes are available: 1 c_wall violated: 3 conflicting context pair(s) with node memory, 5 node(s) had untolerated taint(s). no new claims to deallocate, preemption: 0/6 nodes are available: 1 No preemption victims found for incoming pod, 5 Preemption is not helpful for scheduling."
0.1228,Event,ADDED,eval-sanitize-1-r2-031-qgk85.18d4a274922cc725,"reason=FailedScheduling count=None msg=0/6 nodes are available: 1 c_wall violated: 2 conflicting context pair(s) with node memory, 5 node(s) had untolerated taint(s). no new claims to deallocate, preemption: 0/6 nodes are available: 1 No preemption victims found for incoming pod, 5 Preemption is not helpful for scheduling."
0.123,Event,ADDED,eval-sanitize-1-r2-032-4swd9.18d4a274926025d0,"reason=FailedScheduling count=None msg=0/6 nodes are available: 1 c_wall violated: 1 conflicting context pair(s) with node memory, 5 node(s) had untolerated taint(s). no new claims to deallocate, preemption: 0/6 nodes are available: 1 No preemption victims found for incoming pod, 5 Preemption is not helpful for scheduling."
0.1232,Event,ADDED,eval-sanitize-1-r2-033-z8r6s.18d4a274929af1e9,"reason=FailedScheduling count=None msg=0/6 nodes are available: 1 c_wall violated: 1 conflicting context pair(s) with node memory, 5 node(s) had untolerated taint(s). no new claims to deallocate, preemption: 0/6 nodes are available: 1 No preemption victims found for incoming pod, 5 Preemption is not helpful for scheduling."
0.1234,Event,ADDED,eval-sanitize-1-r2-034-mqbqs.18d4a27496c5da65,"reason=FailedScheduling count=None msg=0/6 nodes are available: 1 c_wall violated: 2 conflicting context pair(s) with node memory, 5 node(s) had untolerated taint(s). no new claims to deallocate, preemption: 0/6 nodes are available: 1 No preemption victims found for incoming pod, 5 Preemption is not helpful for scheduling."
0.1238,Event,ADDED,eval-sanitize-1-r2-036-prlm4.18d4a27497d24135,"reason=FailedScheduling count=None msg=0/6 nodes are available: 1 c_wall violated: 1 conflicting context pair(s) with node memory, 5 node(s) had untolerated taint(s). no new claims to deallocate, preemption: 0/6 nodes are available: 1 No preemption victims found for incoming pod, 5 Preemption is not helpful for scheduling."
0.1245,Event,ADDED,eval-sanitize-1-r2-037-hkgzl.18d4a27498043e03,"reason=FailedScheduling count=None msg=0/6 nodes are available: 1 c_wall violated: 1 conflicting context pair(s) with node memory, 5 node(s) had untolerated taint(s). no new claims to deallocate, preemption: 0/6 nodes are available: 1 No preemption victims found for incoming pod, 5 Preemption is not helpful for scheduling."
0.1247,Event,ADDED,eval-sanitize-1-r2-039-pxsc8.18d4a2749832054d,"reason=FailedScheduling count=None msg=0/6 nodes are available: 1 c_wall violated: 2 conflicting context pair(s) with node memory, 5 node(s) had untolerated taint(s). no new claims to deallocate, preemption: 0/6 nodes are available: 1 No preemption victims found for incoming pod, 5 Preemption is not helpful for scheduling."
0.1249,Event,ADDED,eval-sanitize-1-r2-040-8dbzf.18d4a2749870795a,"reason=FailedScheduling count=None msg=0/6 nodes are available: 1 c_wall violated: 1 conflicting context pair(s) with node memory, 5 node(s) had untolerated taint(s). no new claims to deallocate, preemption: 0/6 nodes are available: 1 No preemption victims found for incoming pod, 5 Preemption is not helpful for scheduling."
0.1253,Event,ADDED,eval-sanitize-1-r2-041-c5cqd.18d4a27498a60972,"reason=FailedScheduling count=None msg=0/6 nodes are available: 1 c_wall violated: 2 conflicting context pair(s) with node memory, 5 node(s) had untolerated taint(s). no new claims to deallocate, preemption: 0/6 nodes are available: 1 No preemption victims found for incoming pod, 5 Preemption is not helpful for scheduling."
0.1256,Event,ADDED,eval-sanitize-1-r2-042-zlhwm.18d4a27498d291a4,"reason=FailedScheduling count=None msg=0/6 nodes are available: 1 c_wall violated: 1 conflicting context pair(s) with node memory, 5 node(s) had untolerated taint(s). no new claims to deallocate, preemption: 0/6 nodes are available: 1 No preemption victims found for incoming pod, 5 Preemption is not helpful for scheduling."
0.1258,Event,ADDED,eval-sanitize-1-r2-042-zlhwm.18d4a27539655db8,"reason=FailedScheduling count=None msg=0/6 nodes are available: 1 c_wall violated: 1 conflicting context pair(s) with node memory, 1 c_wall violated: 3 conflicting context pair(s) with node memory, 4 node(s) had untolerated taint(s). no new claims to deallocate, preemption: 0/6 nodes are available: 2 No preemption victims found for incoming pod, 4 Preemption is not helpful for scheduling."
0.1262,Event,ADDED,eval-sanitize-1-r2-042-zlhwm.18d4a2754b6099a4,"reason=FailedScheduling count=None msg=0/6 nodes are available: 1 c_wall violated: 3 conflicting context pair(s) with node memory, 5 node(s) had untolerated taint(s). no new claims to deallocate, preemption: 0/6 nodes are available: 1 No preemption victims found for incoming pod, 5 Preemption is not helpful for scheduling."
0.1264,Event,ADDED,eval-sanitize-1-r2-043-zqfsq.18d4a2749cd23636,"reason=FailedScheduling count=None msg=0/6 nodes are available: 1 c_wall violated: 1 conflicting context pair(s) with node memory, 5 node(s) had untolerated taint(s). no new claims to deallocate, preemption: 0/6 nodes are available: 1 No preemption victims found for incoming pod, 5 Preemption is not helpful for scheduling."
0.1266,Event,ADDED,eval-sanitize-1-r2-044-hkqt8.18d4a2749de687e7,"reason=FailedScheduling count=None msg=0/6 nodes are available: 1 c_wall violated: 1 conflicting context pair(s) with node memory, 5 node(s) had untolerated taint(s). no new claims to deallocate, preemption: 0/6 nodes are available: 1 No preemption victims found for incoming pod, 5 Preemption is not helpful for scheduling."
0.1279,Node,MODIFIED,kind-worker,taints=0
0.1282,Event,ADDED,eval-sanitize-1-r2-045-z5p9v.18d4a2749e1a2b9c,"reason=FailedScheduling count=None msg=0/6 nodes are available: 1 c_wall violated: 1 conflicting context pair(s) with node memory, 5 node(s) had untolerated taint(s). no new claims to deallocate, preemption: 0/6 nodes are available: 1 No preemption victims found for incoming pod, 5 Preemption is not helpful for scheduling."
0.1284,Event,ADDED,eval-sanitize-1-r2-046-dvkm4.18d4a2749ea1219e,"reason=FailedScheduling count=None msg=0/6 nodes are available: 1 c_wall violated: 2 conflicting context pair(s) with node memory, 5 node(s) had untolerated taint(s). no new claims to deallocate, preemption: 0/6 nodes are available: 1 No preemption victims found for incoming pod, 5 Preemption is not helpful for scheduling."
0.1285,Event,ADDED,eval-sanitize-1-r2-047-z9nx5.18d4a2749e58ef4f,"reason=FailedScheduling count=None msg=0/6 nodes are available: 1 c_wall violated: 1 conflicting context pair(s) with node memory, 5 node(s) had untolerated taint(s). no new claims to deallocate, preemption: 0/6 nodes are available: 1 No preemption victims found for incoming pod, 5 Preemption is not helpful for scheduling."
0.1289,Event,ADDED,eval-sanitize-1-r2-050-d9hp6.18d4a2758e82b431,"reason=FailedScheduling count=None msg=0/6 nodes are available: 1 c_wall violated: 1 conflicting context pair(s) with node memory, 5 node(s) had untolerated taint(s). no new claims to deallocate, preemption: 0/6 nodes are available: 1 No preemption victims found for incoming pod, 5 Preemption is not helpful for scheduling."
0.1291,Event,ADDED,eval-sanitize-1-r2-051-c72wk.18d4a27a3a545159,"reason=FailedScheduling count=None msg=0/6 nodes are available: 1 c_wall violated: 1 conflicting context pair(s) with node memory, 5 node(s) had untolerated taint(s). no new claims to deallocate, preemption: 0/6 nodes are available: 1 No preemption victims found for incoming pod, 5 Preemption is not helpful for scheduling."
0.1295,Event,ADDED,eval-sanitize-1-r2-051-c72wk.18d4a27a80af49b9,"reason=FailedScheduling count=None msg=0/6 nodes are available: 1 c_wall violated: 3 conflicting context pair(s) with node memory, 5 node(s) had untolerated taint(s). no new claims to deallocate, preemption: 0/6 nodes are available: 1 No preemption victims found for incoming pod, 5 Preemption is not helpful for scheduling."
0.1297,Event,ADDED,eval-sanitize-1-r2-051-c72wk.18d4a27aaba38239,"reason=FailedScheduling count=None msg=0/6 nodes are available: 1 c_wall violated: 1 conflicting context pair(s) with node memory, 5 node(s) had untolerated taint(s). no new claims to deallocate, preemption: 0/6 nodes are available: 1 No preemption victims found for incoming pod, 5 Preemption is not helpful for scheduling."
0.1299,Event,ADDED,eval-sanitize-1-r2-051-c72wk.18d4a27ac0eea04d,"reason=FailedScheduling count=None msg=0/6 nodes are available: 2 c_wall violated: 1 conflicting context pair(s) with node memory, 4 node(s) had untolerated taint(s). no new claims to deallocate, preemption: 0/6 nodes are available: 2 No preemption victims found for incoming pod, 4 Preemption is not helpful for scheduling."
0.1302,Event,ADDED,eval-sanitize-1-r2-053-6vgfv.18d4a27a3a84d170,"reason=FailedScheduling count=None msg=0/6 nodes are available: 1 c_wall violated: 2 conflicting context pair(s) with node memory, 5 node(s) had untolerated taint(s). no new claims to deallocate, preemption: 0/6 nodes are available: 1 No preemption victims found for incoming pod, 5 Preemption is not helpful for scheduling."
0.1304,Event,ADDED,eval-sanitize-1-r2-054-66ktp.18d4a27a3ab72e9e,"reason=FailedScheduling count=None msg=0/6 nodes are available: 1 c_wall violated: 2 conflicting context pair(s) with node memory, 5 node(s) had untolerated taint(s). no new claims to deallocate, preemption: 0/6 nodes are available: 1 No preemption victims found for incoming pod, 5 Preemption is not helpful for scheduling."
0.1306,Event,ADDED,eval-sanitize-1-r2-055-j5v7t.18d4a27a3ae62e2e,"reason=FailedScheduling count=None msg=0/6 nodes are available: 1 c_wall violated: 1 conflicting context pair(s) with node memory, 5 node(s) had untolerated taint(s). no new claims to deallocate, preemption: 0/6 nodes are available: 1 No preemption victims found for incoming pod, 5 Preemption is not helpful for scheduling."
0.1309,Event,ADDED,eval-sanitize-1-r2-056-pgjd4.18d4a27a3b0f8c26,"reason=FailedScheduling count=None msg=0/6 nodes are available: 1 c_wall violated: 1 conflicting context pair(s) with node memory, 5 node(s) had untolerated taint(s). no new claims to deallocate, preemption: 0/6 nodes are available: 1 No preemption victims found for incoming pod, 5 Preemption is not helpful for scheduling."
0.131,Event,ADDED,eval-sanitize-1-r2-057-cn25z.18d4a27a3b51f79a,"reason=FailedScheduling count=None msg=0/6 nodes are available: 1 c_wall violated: 1 conflicting context pair(s) with node memory, 5 node(s) had untolerated taint(s). no new claims to deallocate, preemption: 0/6 nodes are available: 1 No preemption victims found for incoming pod, 5 Preemption is not helpful for scheduling."
0.1312,Event,ADDED,eval-sanitize-1-r2-058-4rp4s.18d4a27a403dfb82,"reason=FailedScheduling count=None msg=0/6 nodes are available: 1 c_wall violated: 2 conflicting context pair(s) with node memory, 5 node(s) had untolerated taint(s). no new claims to deallocate, preemption: 0/6 nodes are available: 1 No preemption victims found for incoming pod, 5 Preemption is not helpful for scheduling."
0.1314,Event,ADDED,eval-sanitize-1-r2-060-4t8dg.18d4a27a40b0ae52,"reason=FailedScheduling count=None msg=0/6 nodes are available: 1 c_wall violated: 2 conflicting context pair(s) with node memory, 5 node(s) had untolerated taint(s). no new claims to deallocate, preemption: 0/6 nodes are available: 1 No preemption victims found for incoming pod, 5 Preemption is not helpful for scheduling."
0.1316,Event,ADDED,eval-sanitize-1-r2-063-h4ccr.18d4a27a411286e4,"reason=FailedScheduling count=None msg=0/6 nodes are available: 1 c_wall violated: 2 conflicting context pair(s) with node memory, 5 node(s) had untolerated taint(s). no new claims to deallocate, preemption: 0/6 nodes are available: 1 No preemption victims found for incoming pod, 5 Preemption is not helpful for scheduling."
0.1318,Event,ADDED,eval-sanitize-1-r2-065-mdh2v.18d4a27a46378537,"reason=FailedScheduling count=None msg=0/6 nodes are available: 1 c_wall violated: 2 conflicting context pair(s) with node memory, 5 node(s) had untolerated taint(s). no new claims to deallocate, preemption: 0/6 nodes are available: 1 No preemption victims found for incoming pod, 5 Preemption is not helpful for scheduling."
0.132,Event,ADDED,eval-sanitize-1-r2-066-vthn7.18d4a27a46616362,"reason=FailedScheduling count=None msg=0/6 nodes are available: 1 c_wall violated: 2 conflicting context pair(s) with node memory, 5 node(s) had untolerated taint(s). no new claims to deallocate, preemption: 0/6 nodes are available: 1 No preemption victims found for incoming pod, 5 Preemption is not helpful for scheduling."
0.1322,Event,ADDED,eval-sanitize-1-r2-066-vthn7.18d4a27a7cd973a3,"reason=FailedScheduling count=None msg=0/6 nodes are available: 1 c_wall violated: 1 conflicting context pair(s) with node memory, 5 node(s) had untolerated taint(s). no new claims to deallocate, preemption: 0/6 nodes are available: 1 No preemption victims found for incoming pod, 5 Preemption is not helpful for scheduling."
0.1324,Event,ADDED,eval-sanitize-1-r2-068-dv967.18d4a27a46b507cb,"reason=FailedScheduling count=None msg=0/6 nodes are available: 1 c_wall violated: 2 conflicting context pair(s) with node memory, 5 node(s) had untolerated taint(s). no new claims to deallocate, preemption: 0/6 nodes are available: 1 No preemption victims found for incoming pod, 5 Preemption is not helpful for scheduling."
0.1325,Event,ADDED,eval-sanitize-1-r2-068-dv967.18d4a27a7d1c646d,"reason=FailedScheduling count=None msg=0/6 nodes are available: 1 c_wall violated: 1 conflicting context pair(s) with node memory, 5 node(s) had untolerated taint(s). no new claims to deallocate, preemption: 0/6 nodes are available: 1 No preemption victims found for incoming pod, 5 Preemption is not helpful for scheduling."
0.1327,Event,ADDED,eval-sanitize-1-r2-069-7wt98.18d4a27a46ddb5d1,"reason=FailedScheduling count=None msg=0/6 nodes are available: 1 c_wall violated: 2 conflicting context pair(s) with node memory, 5 node(s) had untolerated taint(s). no new claims to deallocate, preemption: 0/6 nodes are available: 1 No preemption victims found for incoming pod, 5 Preemption is not helpful for scheduling."
0.1329,Event,ADDED,eval-sanitize-1-r2-076-9kd86.18d4a27fbfbb14bb,"reason=FailedScheduling count=None msg=0/6 nodes are available: 1 c_wall violated: 1 conflicting context pair(s) with node memory, 5 node(s) had untolerated taint(s). no new claims to deallocate, preemption: 0/6 nodes are available: 1 No preemption victims found for incoming pod, 5 Preemption is not helpful for scheduling."
0.1331,Event,ADDED,eval-sanitize-1-r2-077-8wp8w.18d4a27fbffcadcb,"reason=FailedScheduling count=None msg=0/6 nodes are available: 1 c_wall violated: 1 conflicting context pair(s) with node memory, 5 node(s) had untolerated taint(s). no new claims to deallocate, preemption: 0/6 nodes are available: 1 No preemption victims found for incoming pod, 5 Preemption is not helpful for scheduling."
0.1333,Event,ADDED,eval-sanitize-1-r2-079-pfcxf.18d4a27fc03a951d,"reason=FailedScheduling count=None msg=0/6 nodes are available: 1 c_wall violated: 1 conflicting context pair(s) with node memory, 5 node(s) had untolerated taint(s). no new claims to deallocate, preemption: 0/6 nodes are available: 1 No preemption victims found for incoming pod, 5 Preemption is not helpful for scheduling."
0.134,Event,ADDED,eval-sanitize-1-r2-080-gqrjs.18d4a27fc3a185d3,"reason=FailedScheduling count=None msg=0/6 nodes are available: 1 c_wall violated: 1 conflicting context pair(s) with node memory, 5 node(s) had untolerated taint(s). no new claims to deallocate, preemption: 0/6 nodes are available: 1 No preemption victims found for incoming pod, 5 Preemption is not helpful for scheduling."
0.1343,Event,ADDED,eval-sanitize-1-r2-081-vq5x7.18d4a27fc4c52b75,"reason=FailedScheduling count=None msg=0/6 nodes are available: 1 c_wall violated: 1 conflicting context pair(s) with node memory, 5 node(s) had untolerated taint(s). no new claims to deallocate, preemption: 0/6 nodes are available: 1 No preemption victims found for incoming pod, 5 Preemption is not helpful for scheduling."
0.1345,Event,ADDED,eval-sanitize-1-r2-083-hnlzb.18d4a27fc7ff73f6,"reason=FailedScheduling count=None msg=0/6 nodes are available: 1 c_wall violated: 1 conflicting context pair(s) with node memory, 5 node(s) had untolerated taint(s). no new claims to deallocate, preemption: 0/6 nodes are available: 1 No preemption victims found for incoming pod, 5 Preemption is not helpful for scheduling."
0.1348,Event,ADDED,eval-sanitize-1-r2-086-27qdc.18d4a27fc839b291,"reason=FailedScheduling count=None msg=0/6 nodes are available: 1 c_wall violated: 1 conflicting context pair(s) with node memory, 5 node(s) had untolerated taint(s). no new claims to deallocate, preemption: 0/6 nodes are available: 1 No preemption victims found for incoming pod, 5 Preemption is not helpful for scheduling."
0.135,Event,ADDED,eval-sanitize-1-r2-087-n4x6s.18d4a27fc895e921,"reason=FailedScheduling count=None msg=0/6 nodes are available: 1 c_wall violated: 1 conflicting context pair(s) with node memory, 5 node(s) had untolerated taint(s). no new claims to deallocate, preemption: 0/6 nodes are available: 1 No preemption victims found for incoming pod, 5 Preemption is not helpful for scheduling."
0.1352,Event,ADDED,eval-sanitize-1-r2-088-2rjn4.18d4a27fc99b5e43,"reason=FailedScheduling count=None msg=0/6 nodes are available: 1 c_wall violated: 1 conflicting context pair(s) with node memory, 5 node(s) had untolerated taint(s). no new claims to deallocate, preemption: 0/6 nodes are available: 1 No preemption victims found for incoming pod, 5 Preemption is not helpful for scheduling."
0.1356,Event,ADDED,eval-sanitize-1-r2-089-trzv4.18d4a27fcac9a195,"reason=FailedScheduling count=None msg=0/6 nodes are available: 1 c_wall violated: 2 conflicting context pair(s) with node memory, 5 node(s) had untolerated taint(s). no new claims to deallocate, preemption: 0/6 nodes are available: 1 No preemption victims found for incoming pod, 5 Preemption is not helpful for scheduling."
0.1357,Event,ADDED,eval-sanitize-1-r2-090-th9bk.18d4a27fcafb553a,"reason=FailedScheduling count=None msg=0/6 nodes are available: 1 c_wall violated: 1 conflicting context pair(s) with node memory, 5 node(s) had untolerated taint(s). no new claims to deallocate, preemption: 0/6 nodes are available: 1 No preemption victims found for incoming pod, 5 Preemption is not helpful for scheduling."
0.1361,Event,ADDED,eval-sanitize-1-r2-092-dln26.18d4a27fcb2c84ca,"reason=FailedScheduling count=None msg=0/6 nodes are available: 1 c_wall violated: 1 conflicting context pair(s) with node memory, 5 node(s) had untolerated taint(s). no new claims to deallocate, preemption: 0/6 nodes are available: 1 No preemption victims found for incoming pod, 5 Preemption is not helpful for scheduling."
0.1363,Event,ADDED,eval-sanitize-1-r2-093-pwln4.18d4a27fcb585825,"reason=FailedScheduling count=None msg=0/6 nodes are available: 1 c_wall violated: 1 conflicting context pair(s) with node memory, 5 node(s) had untolerated taint(s). no new claims to deallocate, preemption: 0/6 nodes are available: 1 No preemption victims found for incoming pod, 5 Preemption is not helpful for scheduling."
0.1365,Event,ADDED,eval-sanitize-1-r2-094-75vrs.18d4a27fcc7b6fd8,"reason=FailedScheduling count=None msg=0/6 nodes are available: 1 c_wall violated: 1 conflicting context pair(s) with node memory, 5 node(s) had untolerated taint(s). no new claims to deallocate, preemption: 0/6 nodes are available: 1 No preemption victims found for incoming pod, 5 Preemption is not helpful for scheduling."
0.1368,Event,ADDED,eval-sanitize-1-r2-095-nsvpn.18d4a27fcb848071,"reason=FailedScheduling count=None msg=0/6 nodes are available: 1 c_wall violated: 2 conflicting context pair(s) with node memory, 5 node(s) had untolerated taint(s). no new claims to deallocate, preemption: 0/6 nodes are available: 1 No preemption victims found for incoming pod, 5 Preemption is not helpful for scheduling."
0.137,Event,ADDED,eval-sanitize-1-r2-099-ptdlv.18d4a28542581ec6,"reason=FailedScheduling count=None msg=0/6 nodes are available: 1 c_wall violated: 2 conflicting context pair(s) with node memory, 5 node(s) had untolerated taint(s). no new claims to deallocate, preemption: 0/6 nodes are available: 1 No preemption victims found for incoming pod, 5 Preemption is not helpful for scheduling."
0.1372,Event,ADDED,eval-sanitize-1-r2-099-ptdlv.18d4a2857911e2e1,"reason=FailedScheduling count=None msg=0/6 nodes are available: 1 c_wall violated: 1 conflicting context pair(s) with node memory, 5 node(s) had untolerated taint(s). no new claims to deallocate, preemption: 0/6 nodes are available: 1 No preemption victims found for incoming pod, 5 Preemption is not helpful for scheduling."
0.1376,Event,ADDED,eval-sanitize-1-r2-099-ptdlv.18d4a285d73844d8,"reason=FailedScheduling count=None msg=0/6 nodes are available: 1 c_wall violated: 2 conflicting context pair(s) with node memory, 5 node(s) had untolerated taint(s). no new claims to deallocate, preemption: 0/6 nodes are available: 1 No preemption victims found for incoming pod, 5 Preemption is not helpful for scheduling."
0.1378,Event,ADDED,eval-sanitize-1-r2-099-ptdlv.18d4a285eeff3605,"reason=FailedScheduling count=None msg=0/6 nodes are available: 1 c_wall violated: 1 conflicting context pair(s) with node memory, 1 c_wall violated: 2 conflicting context pair(s) with node memory, 4 node(s) had untolerated taint(s). no new claims to deallocate, preemption: 0/6 nodes are available: 2 No preemption victims found for incoming pod, 4 Preemption is not helpful for scheduling."
0.138,Event,ADDED,eval-sanitize-1-r2-101-jhm66.18d4a285433ea319,"reason=FailedScheduling count=None msg=0/6 nodes are available: 1 c_wall violated: 2 conflicting context pair(s) with node memory, 5 node(s) had untolerated taint(s). no new claims to deallocate, preemption: 0/6 nodes are available: 1 No preemption victims found for incoming pod, 5 Preemption is not helpful for scheduling."
0.1383,Event,ADDED,eval-sanitize-1-r2-104-t6ps7.18d4a28536cdda4e,"reason=FailedScheduling count=None msg=0/6 nodes are available: 1 c_wall violated: 1 conflicting context pair(s) with node memory, 5 node(s) had untolerated taint(s). no new claims to deallocate, preemption: 0/6 nodes are available: 1 No preemption victims found for incoming pod, 5 Preemption is not helpful for scheduling."
0.1385,Event,ADDED,eval-sanitize-1-r2-105-dtkpv.18d4a28536ffb8a6,"reason=FailedScheduling count=None msg=0/6 nodes are available: 1 c_wall violated: 1 conflicting context pair(s) with node memory, 5 node(s) had untolerated taint(s). no new claims to deallocate, preemption: 0/6 nodes are available: 1 No preemption victims found for incoming pod, 5 Preemption is not helpful for scheduling."
0.1387,Event,ADDED,eval-sanitize-1-r2-106-99rts.18d4a28543db1964,"reason=FailedScheduling count=None msg=0/6 nodes are available: 1 c_wall violated: 3 conflicting context pair(s) with node memory, 5 node(s) had untolerated taint(s). no new claims to deallocate, preemption: 0/6 nodes are available: 1 No preemption victims found for incoming pod, 5 Preemption is not helpful for scheduling."
0.139,Event,ADDED,eval-sanitize-1-r2-106-99rts.18d4a2857cbf9696,"reason=FailedScheduling count=None msg=0/6 nodes are available: 1 c_wall violated: 1 conflicting context pair(s) with node memory, 5 node(s) had untolerated taint(s). no new claims to deallocate, preemption: 0/6 nodes are available: 1 No preemption victims found for incoming pod, 5 Preemption is not helpful for scheduling."
0.1392,Event,ADDED,eval-sanitize-1-r2-107-vfmvr.18d4a28538efc8d3,"reason=FailedScheduling count=None msg=0/6 nodes are available: 1 c_wall violated: 1 conflicting context pair(s) with node memory, 5 node(s) had untolerated taint(s). no new claims to deallocate, preemption: 0/6 nodes are available: 1 No preemption victims found for incoming pod, 5 Preemption is not helpful for scheduling."
0.1394,Event,ADDED,eval-sanitize-1-r2-108-4z64w.18d4a28548602c50,"reason=FailedScheduling count=None msg=0/6 nodes are available: 1 c_wall violated: 3 conflicting context pair(s) with node memory, 5 node(s) had untolerated taint(s). no new claims to deallocate, preemption: 0/6 nodes are available: 1 No preemption victims found for incoming pod, 5 Preemption is not helpful for scheduling."
0.1395,Event,ADDED,eval-sanitize-1-r2-108-4z64w.18d4a2857db0589c,"reason=FailedScheduling count=None msg=0/6 nodes are available: 1 c_wall violated: 1 conflicting context pair(s) with node memory, 5 node(s) had untolerated taint(s). no new claims to deallocate, preemption: 0/6 nodes are available: 1 No preemption victims found for incoming pod, 5 Preemption is not helpful for scheduling."
0.1397,Event,ADDED,eval-sanitize-1-r2-109-4vv67.18d4a2854932f320,"reason=FailedScheduling count=None msg=0/6 nodes are available: 1 c_wall violated: 4 conflicting context pair(s) with node memory, 5 node(s) had untolerated taint(s). no new claims to deallocate, preemption: 0/6 nodes are available: 1 No preemption victims found for incoming pod, 5 Preemption is not helpful for scheduling."
0.1399,Event,ADDED,eval-sanitize-1-r2-109-4vv67.18d4a2857ddc8e5d,"reason=FailedScheduling count=None msg=0/6 nodes are available: 1 c_wall violated: 1 conflicting context pair(s) with node memory, 5 node(s) had untolerated taint(s). no new claims to deallocate, preemption: 0/6 nodes are available: 1 No preemption victims found for incoming pod, 5 Preemption is not helpful for scheduling."
0.1402,Event,ADDED,eval-sanitize-1-r2-109-4vv67.18d4a285d26be044,"reason=FailedScheduling count=None msg=0/6 nodes are available: 1 c_wall violated: 1 conflicting context pair(s) with node memory, 5 node(s) had untolerated taint(s). no new claims to deallocate, preemption: 0/6 nodes are available: 1 No preemption victims found for incoming pod, 5 Preemption is not helpful for scheduling."
0.1404,Event,ADDED,eval-sanitize-1-r2-110-47c8s.18d4a285495fcd12,"reason=FailedScheduling count=None msg=0/6 nodes are available: 1 c_wall violated: 4 conflicting context pair(s) with node memory, 5 node(s) had untolerated taint(s). no new claims to deallocate, preemption: 0/6 nodes are available: 1 No preemption victims found for incoming pod, 5 Preemption is not helpful for scheduling."
0.1407,Event,ADDED,eval-sanitize-1-r2-110-47c8s.18d4a2857732b909,"reason=FailedScheduling count=None msg=0/6 nodes are available: 1 c_wall violated: 1 conflicting context pair(s) with node memory, 5 node(s) had untolerated taint(s). no new claims to deallocate, preemption: 0/6 nodes are available: 1 No preemption victims found for incoming pod, 5 Preemption is not helpful for scheduling."
0.1409,Event,ADDED,eval-sanitize-1-r2-112-trcmc.18d4a2853d07538c,"reason=FailedScheduling count=None msg=0/6 nodes are available: 1 c_wall violated: 2 conflicting context pair(s) with node memory, 5 node(s) had untolerated taint(s). no new claims to deallocate, preemption: 0/6 nodes are available: 1 No preemption victims found for incoming pod, 5 Preemption is not helpful for scheduling."
0.1411,Event,ADDED,eval-sanitize-1-r2-112-trcmc.18d4a2857eb9b51d,"reason=FailedScheduling count=None msg=0/6 nodes are available: 1 c_wall violated: 2 conflicting context pair(s) with node memory, 5 node(s) had untolerated taint(s). no new claims to deallocate, preemption: 0/6 nodes are available: 1 No preemption victims found for incoming pod, 5 Preemption is not helpful for scheduling."
0.1414,Event,ADDED,eval-sanitize-1-r2-113-mvvs9.18d4a28549be6de7,"reason=FailedScheduling count=None msg=0/6 nodes are available: 1 c_wall violated: 4 conflicting context pair(s) with node memory, 5 node(s) had untolerated taint(s). no new claims to deallocate, preemption: 0/6 nodes are available: 1 No preemption victims found for incoming pod, 5 Preemption is not helpful for scheduling."
0.1417,Event,ADDED,eval-sanitize-1-r2-113-mvvs9.18d4a28578571003,"reason=FailedScheduling count=None msg=0/6 nodes are available: 1 c_wall violated: 1 conflicting context pair(s) with node memory, 5 node(s) had untolerated taint(s). no new claims to deallocate, preemption: 0/6 nodes are available: 1 No preemption victims found for incoming pod, 5 Preemption is not helpful for scheduling."
0.1419,Event,ADDED,eval-sanitize-1-r2-116-wmxf7.18d4a2853e081fdc,"reason=FailedScheduling count=None msg=0/6 nodes are available: 1 c_wall violated: 2 conflicting context pair(s) with node memory, 5 node(s) had untolerated taint(s). no new claims to deallocate, preemption: 0/6 nodes are available: 1 No preemption victims found for incoming pod, 5 Preemption is not helpful for scheduling."
0.1423,Event,ADDED,eval-sanitize-1-r2-116-wmxf7.18d4a28578de2eb5,"reason=FailedScheduling count=None msg=0/6 nodes are available: 1 c_wall violated: 1 conflicting context pair(s) with node memory, 5 node(s) had untolerated taint(s). no new claims to deallocate, preemption: 0/6 nodes are available: 1 No preemption victims found for incoming pod, 5 Preemption is not helpful for scheduling."
0.1425,Event,ADDED,eval-sanitize-1-r2-116-wmxf7.18d4a285d301a95b,"reason=FailedScheduling count=None msg=0/6 nodes are available: 1 c_wall violated: 2 conflicting context pair(s) with node memory, 5 node(s) had untolerated taint(s). no new claims to deallocate, preemption: 0/6 nodes are available: 1 No preemption victims found for incoming pod, 5 Preemption is not helpful for scheduling."
0.143,Event,ADDED,eval-sanitize-1-r2-116-wmxf7.18d4a285ea590490,"reason=FailedScheduling count=None msg=0/6 nodes are available: 1 c_wall violated: 1 conflicting context pair(s) with node memory, 1 c_wall violated: 2 conflicting context pair(s) with node memory, 4 node(s) had untolerated taint(s). no new claims to deallocate, preemption: 0/6 nodes are available: 2 No preemption victims found for incoming pod, 4 Preemption is not helpful for scheduling."
0.1432,Event,ADDED,eval-sanitize-1-r2-117-m4bs8.18d4a2853e3ecdcc,"reason=FailedScheduling count=None msg=0/6 nodes are available: 1 c_wall violated: 1 conflicting context pair(s) with node memory, 5 node(s) had untolerated taint(s). no new claims to deallocate, preemption: 0/6 nodes are available: 1 No preemption victims found for incoming pod, 5 Preemption is not helpful for scheduling."
0.1434,Event,ADDED,eval-sanitize-1-r2-118-zmhb6.18d4a28542221b77,"reason=FailedScheduling count=None msg=0/6 nodes are available: 1 c_wall violated: 2 conflicting context pair(s) with node memory, 5 node(s) had untolerated taint(s). no new claims to deallocate, preemption: 0/6 nodes are available: 1 No preemption victims found for incoming pod, 5 Preemption is not helpful for scheduling."
0.1437,Event,ADDED,eval-sanitize-1-r2-119-p5wl8.18d4a2857c987424,"reason=FailedScheduling count=None msg=0/6 nodes are available: 1 c_wall violated: 1 conflicting context pair(s) with node memory, 5 node(s) had untolerated taint(s). no new claims to deallocate, preemption: 0/6 nodes are available: 1 No preemption victims found for incoming pod, 5 Preemption is not helpful for scheduling."
0.1439,Event,ADDED,eval-sanitize-1-r2-120-kgzst.18d4a285effd1da3,"reason=FailedScheduling count=None msg=0/6 nodes are available: 1 c_wall violated: 1 conflicting context pair(s) with node memory, 1 c_wall violated: 2 conflicting context pair(s) with node memory, 4 node(s) had untolerated taint(s). no new claims to deallocate, preemption: 0/6 nodes are available: 2 No preemption victims found for incoming pod, 4 Preemption is not helpful for scheduling."
0.1441,Event,ADDED,eval-sanitize-1-r2-121-cskbm.18d4a2866e78142f,"reason=FailedScheduling count=None msg=0/6 nodes are available: 1 c_wall violated: 2 conflicting context pair(s) with node memory, 5 node(s) had untolerated taint(s). no new claims to deallocate, preemption: 0/6 nodes are available: 1 No preemption victims found for incoming pod, 5 Preemption is not helpful for scheduling."
0.1443,Event,ADDED,eval-sanitize-1-r2-122-j55j4.18d4a28689b14424,"reason=FailedScheduling count=None msg=0/6 nodes are available: 1 c_wall violated: 1 conflicting context pair(s) with node memory, 5 node(s) had untolerated taint(s). no new claims to deallocate, preemption: 0/6 nodes are available: 1 No preemption victims found for incoming pod, 5 Preemption is not helpful for scheduling."
0.1445,Event,ADDED,eval-sanitize-1-r2-124-mwcrl.18d4a28aa1865371,"reason=FailedScheduling count=None msg=0/6 nodes are available: 1 c_wall violated: 1 conflicting context pair(s) with node memory, 5 node(s) had untolerated taint(s). no new claims to deallocate, preemption: 0/6 nodes are available: 1 No preemption victims found for incoming pod, 5 Preemption is not helpful for scheduling."
0.1446,Event,ADDED,eval-sanitize-1-r2-126-gxglb.18d4a28aa3fe2ec8,"reason=FailedScheduling count=None msg=0/6 nodes are available: 1 c_wall violated: 1 conflicting context pair(s) with node memory, 5 node(s) had untolerated taint(s). no new claims to deallocate, preemption: 0/6 nodes are available: 1 No preemption victims found for incoming pod, 5 Preemption is not helpful for scheduling."
0.1449,Event,ADDED,eval-sanitize-1-r2-126-gxglb.18d4a28b23341d88,"reason=FailedScheduling count=None msg=0/6 nodes are available: 1 c_wall violated: 3 conflicting context pair(s) with node memory, 5 node(s) had untolerated taint(s). no new claims to deallocate, preemption: 0/6 nodes are available: 1 No preemption victims found for incoming pod, 5 Preemption is not helpful for scheduling."
0.1451,Event,ADDED,eval-sanitize-1-r2-128-55c5p.18d4a28aa42bd079,"reason=FailedScheduling count=None msg=0/6 nodes are available: 1 c_wall violated: 1 conflicting context pair(s) with node memory, 5 node(s) had untolerated taint(s). no new claims to deallocate, preemption: 0/6 nodes are available: 1 No preemption victims found for incoming pod, 5 Preemption is not helpful for scheduling."
0.1453,Event,ADDED,eval-sanitize-1-r2-128-55c5p.18d4a28b236a0219,"reason=FailedScheduling count=None msg=0/6 nodes are available: 1 c_wall violated: 3 conflicting context pair(s) with node memory, 5 node(s) had untolerated taint(s). no new claims to deallocate, preemption: 0/6 nodes are available: 1 No preemption victims found for incoming pod, 5 Preemption is not helpful for scheduling."
0.1456,Event,ADDED,eval-sanitize-1-r2-130-fzpx6.18d4a28aa457ff7f,"reason=FailedScheduling count=None msg=0/6 nodes are available: 1 c_wall violated: 2 conflicting context pair(s) with node memory, 5 node(s) had untolerated taint(s). no new claims to deallocate, preemption: 0/6 nodes are available: 1 No preemption victims found for incoming pod, 5 Preemption is not helpful for scheduling."
0.1458,Event,ADDED,eval-sanitize-1-r2-132-tmgbr.18d4a28aa47f40e5,"reason=FailedScheduling count=None msg=0/6 nodes are available: 1 c_wall violated: 2 conflicting context pair(s) with node memory, 5 node(s) had untolerated taint(s). no new claims to deallocate, preemption: 0/6 nodes are available: 1 No preemption victims found for incoming pod, 5 Preemption is not helpful for scheduling."
0.1462,Event,ADDED,eval-sanitize-1-r2-132-tmgbr.18d4a28b23a62982,"reason=FailedScheduling count=None msg=0/6 nodes are available: 1 c_wall violated: 3 conflicting context pair(s) with node memory, 5 node(s) had untolerated taint(s). no new claims to deallocate, preemption: 0/6 nodes are available: 1 No preemption victims found for incoming pod, 5 Preemption is not helpful for scheduling."
0.1464,Event,ADDED,eval-sanitize-1-r2-132-tmgbr.18d4a28c6dc87e05,"reason=FailedScheduling count=None msg=0/6 nodes are available: 1 c_wall violated: 2 conflicting context pair(s) with node memory, 5 node(s) had untolerated taint(s). no new claims to deallocate, preemption: 0/6 nodes are available: 1 No preemption victims found for incoming pod, 5 Preemption is not helpful for scheduling."
0.1466,Event,ADDED,eval-sanitize-1-r2-132-tmgbr.18d4a28c8724ec94,"reason=FailedScheduling count=None msg=0/6 nodes are available: 1 c_wall violated: 1 conflicting context pair(s) with node memory, 1 c_wall violated: 2 conflicting context pair(s) with node memory, 4 node(s) had untolerated taint(s). no new claims to deallocate, preemption: 0/6 nodes are available: 2 No preemption victims found for incoming pod, 4 Preemption is not helpful for scheduling."
0.1469,Event,ADDED,eval-sanitize-1-r2-133-r8d6f.18d4a28aa4a79dff,"reason=FailedScheduling count=None msg=0/6 nodes are available: 1 c_wall violated: 1 conflicting context pair(s) with node memory, 5 node(s) had untolerated taint(s). no new claims to deallocate, preemption: 0/6 nodes are available: 1 No preemption victims found for incoming pod, 5 Preemption is not helpful for scheduling."
0.1471,Event,ADDED,eval-sanitize-1-r2-134-r7tsb.18d4a28aa4d43ccf,"reason=FailedScheduling count=None msg=0/6 nodes are available: 1 c_wall violated: 2 conflicting context pair(s) with node memory, 5 node(s) had untolerated taint(s). no new claims to deallocate, preemption: 0/6 nodes are available: 1 No preemption victims found for incoming pod, 5 Preemption is not helpful for scheduling."
0.1473,Event,ADDED,eval-sanitize-1-r2-135-k9s8g.18d4a28aa5932336,"reason=FailedScheduling count=None msg=0/6 nodes are available: 1 c_wall violated: 1 conflicting context pair(s) with node memory, 5 node(s) had untolerated taint(s). no new claims to deallocate, preemption: 0/6 nodes are available: 1 No preemption victims found for incoming pod, 5 Preemption is not helpful for scheduling."
0.1476,Event,ADDED,eval-sanitize-1-r2-140-kwsms.18d4a28aab8706c2,"reason=FailedScheduling count=None msg=0/6 nodes are available: 1 c_wall violated: 1 conflicting context pair(s) with node memory, 5 node(s) had untolerated taint(s). no new claims to deallocate, preemption: 0/6 nodes are available: 1 No preemption victims found for incoming pod, 5 Preemption is not helpful for scheduling."
0.1478,Event,ADDED,eval-sanitize-1-r2-140-kwsms.18d4a28b22fdb450,"reason=FailedScheduling count=None msg=0/6 nodes are available: 1 c_wall violated: 3 conflicting context pair(s) with node memory, 5 node(s) had untolerated taint(s). no new claims to deallocate, preemption: 0/6 nodes are available: 1 No preemption victims found for incoming pod, 5 Preemption is not helpful for scheduling."
0.148,Event,ADDED,eval-sanitize-1-r2-141-dnxdp.18d4a28aabcae913,"reason=FailedScheduling count=None msg=0/6 nodes are available: 1 c_wall violated: 2 conflicting context pair(s) with node memory, 5 node(s) had untolerated taint(s). no new claims to deallocate, preemption: 0/6 nodes are available: 1 No preemption victims found for incoming pod, 5 Preemption is not helpful for scheduling."
0.1483,Event,ADDED,eval-sanitize-1-r2-142-c74st.18d4a28ab18ab7c2,"reason=FailedScheduling count=None msg=0/6 nodes are available: 1 c_wall violated: 1 conflicting context pair(s) with node memory, 5 node(s) had untolerated taint(s). no new claims to deallocate, preemption: 0/6 nodes are available: 1 No preemption victims found for incoming pod, 5 Preemption is not helpful for scheduling."
0.1485,Event,ADDED,eval-sanitize-1-r2-144-56g62.18d4a28b3c30f7aa,"reason=FailedScheduling count=None msg=0/6 nodes are available: 1 c_wall violated: 3 conflicting context pair(s) with node memory, 5 node(s) had untolerated taint(s). no new claims to deallocate, preemption: 0/6 nodes are available: 1 No preemption victims found for incoming pod, 5 Preemption is not helpful for scheduling."
0.1487,Event,ADDED,eval-sanitize-1-r2-144-56g62.18d4a28c67ef0040,"reason=FailedScheduling count=None msg=0/6 nodes are available: 1 c_wall violated: 1 conflicting context pair(s) with node memory, 5 node(s) had untolerated taint(s). no new claims to deallocate, preemption: 0/6 nodes are available: 1 No preemption victims found for incoming pod, 5 Preemption is not helpful for scheduling."
0.1489,Event,ADDED,eval-sanitize-1-r2-144-56g62.18d4a28c86b04d65,"reason=FailedScheduling count=None msg=0/6 nodes are available: 2 c_wall violated: 1 conflicting context pair(s) with node memory, 4 node(s) had untolerated taint(s). no new claims to deallocate, preemption: 0/6 nodes are available: 2 No preemption victims found for incoming pod, 4 Preemption is not helpful for scheduling."
0.1491,Event,ADDED,eval-sanitize-1-r2-144-56g62.18d4a28caa90ab5e,"reason=FailedScheduling count=None msg=0/6 nodes are available: 3 c_wall violated: 1 conflicting context pair(s) with node memory, 3 node(s) had untolerated taint(s). no new claims to deallocate, preemption: 0/6 nodes are available: 3 No preemption victims found for incoming pod, 3 Preemption is not helpful for scheduling."
0.1493,Event,ADDED,eval-sanitize-1-r2-144-56g62.18d4a28cd43314e9,"reason=FailedScheduling count=None msg=0/6 nodes are available: 2 c_wall violated: 1 conflicting context pair(s) with node memory, 4 node(s) had untolerated taint(s). no new claims to deallocate, preemption: 0/6 nodes are available: 2 No preemption victims found for incoming pod, 4 Preemption is not helpful for scheduling."
0.1495,Event,ADDED,eval-sanitize-1-r2-144-56g62.18d4a28cdb09dffd,"reason=FailedScheduling count=None msg=0/6 nodes are available: 1 c_wall violated: 1 conflicting context pair(s) with node memory, 5 node(s) had untolerated taint(s). no new claims to deallocate, preemption: 0/6 nodes are available: 1 No preemption victims found for incoming pod, 5 Preemption is not helpful for scheduling."
0.1497,Event,ADDED,eval-sanitize-1-r2-146-p8nn9.18d4a28c6a921e2c,"reason=FailedScheduling count=None msg=0/6 nodes are available: 1 c_wall violated: 2 conflicting context pair(s) with node memory, 5 node(s) had untolerated taint(s). no new claims to deallocate, preemption: 0/6 nodes are available: 1 No preemption victims found for incoming pod, 5 Preemption is not helpful for scheduling."
0.1499,Event,ADDED,eval-sanitize-1-r2-146-p8nn9.18d4a28c878bd79f,"reason=FailedScheduling count=None msg=0/6 nodes are available: 1 c_wall violated: 1 conflicting context pair(s) with node memory, 1 c_wall violated: 2 conflicting context pair(s) with node memory, 4 node(s) had untolerated taint(s). no new claims to deallocate, preemption: 0/6 nodes are available: 2 No preemption victims found for incoming pod, 4 Preemption is not helpful for scheduling."
0.1502,Event,ADDED,eval-sanitize-1-r2-148-x7s9z.18d4a28c6c77bd9a,"reason=FailedScheduling count=None msg=0/6 nodes are available: 1 c_wall violated: 1 conflicting context pair(s) with node memory, 5 node(s) had untolerated taint(s). no new claims to deallocate, preemption: 0/6 nodes are available: 1 No preemption victims found for incoming pod, 5 Preemption is not helpful for scheduling."
0.1504,Event,ADDED,eval-sanitize-1-r2-149-bz4b5.18d4a28c6ac0336d,"reason=FailedScheduling count=None msg=0/6 nodes are available: 1 c_wall violated: 1 conflicting context pair(s) with node memory, 5 node(s) had untolerated taint(s). no new claims to deallocate, preemption: 0/6 nodes are available: 1 No preemption victims found for incoming pod, 5 Preemption is not helpful for scheduling."
0.1507,Event,ADDED,eval-sanitize-1-r2-156-8cdmb.18d4a291d9eec321,"reason=FailedScheduling count=None msg=0/6 nodes are available: 1 c_wall violated: 2 conflicting context pair(s) with node memory, 5 node(s) had untolerated taint(s). no new claims to deallocate, preemption: 0/6 nodes are available: 1 No preemption victims found for incoming pod, 5 Preemption is not helpful for scheduling."
0.1509,Event,ADDED,eval-sanitize-1-r2-171-dqpfr.18d4a291da34cb86,"reason=FailedScheduling count=None msg=0/6 nodes are available: 1 c_wall violated: 1 conflicting context pair(s) with node memory, 5 node(s) had untolerated taint(s). no new claims to deallocate, preemption: 0/6 nodes are available: 1 No preemption victims found for incoming pod, 5 Preemption is not helpful for scheduling."
0.1511,Event,ADDED,eval-sanitize-1-r2-171-dqpfr.18d4a2921839a6d9,"reason=FailedScheduling count=None msg=0/6 nodes are available: 1 c_wall violated: 1 conflicting context pair(s) with node memory, 5 node(s) had untolerated taint(s). no new claims to deallocate, preemption: 0/6 nodes are available: 1 No preemption victims found for incoming pod, 5 Preemption is not helpful for scheduling."
0.1515,Event,ADDED,eval-sanitize-1-r2-172-zmf44.18d4a291dba36d5a,"reason=FailedScheduling count=None msg=0/6 nodes are available: 1 c_wall violated: 1 conflicting context pair(s) with node memory, 5 node(s) had untolerated taint(s). no new claims to deallocate, preemption: 0/6 nodes are available: 1 No preemption victims found for incoming pod, 5 Preemption is not helpful for scheduling."
0.1517,Event,ADDED,eval-sanitize-1-r2-172-zmf44.18d4a292186bd234,"reason=FailedScheduling count=None msg=0/6 nodes are available: 1 c_wall violated: 1 conflicting context pair(s) with node memory, 5 node(s) had untolerated taint(s). no new claims to deallocate, preemption: 0/6 nodes are available: 1 No preemption victims found for incoming pod, 5 Preemption is not helpful for scheduling."
0.1519,Event,ADDED,eval-sanitize-1-r2-176-ghjrj.18d4a292d1c3adb8,"reason=FailedScheduling count=None msg=0/6 nodes are available: 1 c_wall violated: 2 conflicting context pair(s) with node memory, 5 node(s) had untolerated taint(s). no new claims to deallocate, preemption: 0/6 nodes are available: 1 No preemption victims found for incoming pod, 5 Preemption is not helpful for scheduling."
0.1522,Event,ADDED,eval-sanitize-1-r2-177-922j6.18d4a292d6aade74,"reason=FailedScheduling count=None msg=0/6 nodes are available: 1 c_wall violated: 2 conflicting context pair(s) with node memory, 5 node(s) had untolerated taint(s). no new claims to deallocate, preemption: 0/6 nodes are available: 1 No preemption victims found for incoming pod, 5 Preemption is not helpful for scheduling."
0.1524,Event,ADDED,eval-sanitize-1-r2-180-87tk8.18d4a296d711115c,"reason=FailedScheduling count=None msg=0/6 nodes are available: 1 c_wall violated: 1 conflicting context pair(s) with node memory, 1 c_wall violated: 2 conflicting context pair(s) with node memory, 4 node(s) had untolerated taint(s). no new claims to deallocate, preemption: 0/6 nodes are available: 2 No preemption victims found for incoming pod, 4 Preemption is not helpful for scheduling."
0.153,Event,ADDED,eval-sanitize-1-r2-180-87tk8.18d4a296fcf50995,"reason=FailedScheduling count=None msg=0/6 nodes are available: 1 c_wall violated: 1 conflicting context pair(s) with node memory, 5 node(s) had untolerated taint(s). no new claims to deallocate, preemption: 0/6 nodes are available: 1 No preemption victims found for incoming pod, 5 Preemption is not helpful for scheduling."
0.1532,Event,ADDED,eval-sanitize-1-r2-183-v56gf.18d4a296d7711eb3,"reason=FailedScheduling count=None msg=0/6 nodes are available: 1 c_wall violated: 1 conflicting context pair(s) with node memory, 1 c_wall violated: 3 conflicting context pair(s) with node memory, 4 node(s) had untolerated taint(s). no new claims to deallocate, preemption: 0/6 nodes are available: 2 No preemption victims found for incoming pod, 4 Preemption is not helpful for scheduling."
0.1534,Event,ADDED,eval-sanitize-1-r2-185-qmx7n.18d4a296d7d38ed1,"reason=FailedScheduling count=None msg=0/6 nodes are available: 1 c_wall violated: 1 conflicting context pair(s) with node memory, 1 c_wall violated: 2 conflicting context pair(s) with node memory, 4 node(s) had untolerated taint(s). no new claims to deallocate, preemption: 0/6 nodes are available: 2 No preemption victims found for incoming pod, 4 Preemption is not helpful for scheduling."
0.1537,Event,ADDED,eval-sanitize-1-r2-185-qmx7n.18d4a297c781a846,"reason=FailedScheduling count=None msg=0/6 nodes are available: 1 c_wall violated: 2 conflicting context pair(s) with node memory, 5 node(s) had untolerated taint(s). no new claims to deallocate, preemption: 0/6 nodes are available: 1 No preemption victims found for incoming pod, 5 Preemption is not helpful for scheduling."
0.1539,Event,ADDED,eval-sanitize-1-r2-185-qmx7n.18d4a297d80021d1,"reason=FailedScheduling count=None msg=0/6 nodes are available: 1 c_wall violated: 1 conflicting context pair(s) with node memory, 1 c_wall violated: 2 conflicting context pair(s) with node memory, 4 node(s) had untolerated taint(s). no new claims to deallocate, preemption: 0/6 nodes are available: 2 No preemption victims found for incoming pod, 4 Preemption is not helpful for scheduling."
0.1541,Event,ADDED,eval-sanitize-1-r2-185-qmx7n.18d4a29808021370,"reason=FailedScheduling count=None msg=0/6 nodes are available: 1 c_wall violated: 1 conflicting context pair(s) with node memory, 5 node(s) had untolerated taint(s). no new claims to deallocate, preemption: 0/6 nodes are available: 1 No preemption victims found for incoming pod, 5 Preemption is not helpful for scheduling."
0.1543,Event,ADDED,eval-sanitize-1-r2-194-p94gm.18d4a296fcb98d38,"reason=FailedScheduling count=None msg=0/6 nodes are available: 1 c_wall violated: 1 conflicting context pair(s) with node memory, 5 node(s) had untolerated taint(s). no new claims to deallocate, preemption: 0/6 nodes are available: 1 No preemption victims found for incoming pod, 5 Preemption is not helpful for scheduling."
0.1545,Event,ADDED,eval-sanitize-1-r2-199-pc7jp.18d4a2980829d717,"reason=FailedScheduling count=None msg=0/6 nodes are available: 1 c_wall violated: 2 conflicting context pair(s) with node memory, 5 node(s) had untolerated taint(s). no new claims to deallocate, preemption: 0/6 nodes are available: 1 No preemption victims found for incoming pod, 5 Preemption is not helpful for scheduling."
0.1547,Event,ADDED,eval-sanitize-1-r3-007-nkb75.18d4a2ad722cfd6e,"reason=FailedScheduling count=None msg=0/6 nodes are available: 1 c_wall violated: 2 conflicting context pair(s) with node memory, 5 node(s) had untolerated taint(s). no new claims to deallocate, preemption: 0/6 nodes are available: 1 No preemption victims found for incoming pod, 5 Preemption is not helpful for scheduling."
0.155,Event,ADDED,eval-sanitize-1-r3-007-nkb75.18d4a2ada3e5e779,"reason=FailedScheduling count=None msg=0/6 nodes are available: 1 c_wall violated: 1 conflicting context pair(s) with node memory, 5 node(s) had untolerated taint(s). no new claims to deallocate, preemption: 0/6 nodes are available: 1 No preemption victims found for incoming pod, 5 Preemption is not helpful for scheduling."
0.1552,Event,ADDED,eval-sanitize-1-r3-009-8rw5g.18d4a2ad6c3778fe,"reason=FailedScheduling count=None msg=0/6 nodes are available: 1 c_wall violated: 1 conflicting context pair(s) with node memory, 5 node(s) had untolerated taint(s). no new claims to deallocate, preemption: 0/6 nodes are available: 1 No preemption victims found for incoming pod, 5 Preemption is not helpful for scheduling."
0.1554,Event,ADDED,eval-sanitize-1-r3-010-m4snf.18d4a2ad6c69ba9a,"reason=FailedScheduling count=None msg=0/6 nodes are available: 1 c_wall violated: 1 conflicting context pair(s) with node memory, 5 node(s) had untolerated taint(s). no new claims to deallocate, preemption: 0/6 nodes are available: 1 No preemption victims found for incoming pod, 5 Preemption is not helpful for scheduling."
0.1559,Event,ADDED,eval-sanitize-1-r3-017-zdjbn.18d4a2ad6c9ccf2e,"reason=FailedScheduling count=None msg=0/6 nodes are available: 1 c_wall violated: 2 conflicting context pair(s) with node memory, 5 node(s) had untolerated taint(s). no new claims to deallocate, preemption: 0/6 nodes are available: 1 No preemption victims found for incoming pod, 5 Preemption is not helpful for scheduling."
0.1561,Event,ADDED,eval-sanitize-1-r3-017-zdjbn.18d4a2ada7c81ac7,"reason=FailedScheduling count=None msg=0/6 nodes are available: 1 c_wall violated: 2 conflicting context pair(s) with node memory, 5 node(s) had untolerated taint(s). no new claims to deallocate, preemption: 0/6 nodes are available: 1 No preemption victims found for incoming pod, 5 Preemption is not helpful for scheduling."
0.1565,Event,ADDED,eval-sanitize-1-r3-018-hgr2x.18d4a2ad6ccde65c,"reason=FailedScheduling count=None msg=0/6 nodes are available: 1 c_wall violated: 2 conflicting context pair(s) with node memory, 5 node(s) had untolerated taint(s). no new claims to deallocate, preemption: 0/6 nodes are available: 1 No preemption victims found for incoming pod, 5 Preemption is not helpful for scheduling."
0.1567,Event,ADDED,eval-sanitize-1-r3-018-hgr2x.18d4a2ada7fc5ea8,"reason=FailedScheduling count=None msg=0/6 nodes are available: 1 c_wall violated: 2 conflicting context pair(s) with node memory, 5 node(s) had untolerated taint(s). no new claims to deallocate, preemption: 0/6 nodes are available: 1 No preemption victims found for incoming pod, 5 Preemption is not helpful for scheduling."
0.1569,Event,ADDED,eval-sanitize-1-r3-025-662jl.18d4a2add7f73c30,"reason=FailedScheduling count=None msg=0/6 nodes are available: 1 c_wall violated: 1 conflicting context pair(s) with node memory, 5 node(s) had untolerated taint(s). no new claims to deallocate, preemption: 0/6 nodes are available: 1 No preemption victims found for incoming pod, 5 Preemption is not helpful for scheduling."
0.1572,Event,ADDED,eval-sanitize-1-r3-028-lv469.18d4a2ae86ec9b63,"reason=FailedScheduling count=None msg=0/6 nodes are available: 1 c_wall violated: 1 conflicting context pair(s) with node memory, 5 node(s) had untolerated taint(s). no new claims to deallocate, preemption: 0/6 nodes are available: 1 No preemption victims found for incoming pod, 5 Preemption is not helpful for scheduling."
0.1573,Event,ADDED,eval-sanitize-1-r3-036-4tcc4.18d4a2b35023d4f7,"reason=FailedScheduling count=None msg=0/6 nodes are available: 2 c_wall violated: 2 conflicting context pair(s) with node memory, 4 node(s) had untolerated taint(s). no new claims to deallocate, preemption: 0/6 nodes are available: 2 No preemption victims found for incoming pod, 4 Preemption is not helpful for scheduling."
0.1575,Event,ADDED,eval-sanitize-1-r3-036-4tcc4.18d4a2b36b8fe54f,"reason=FailedScheduling count=None msg=0/6 nodes are available: 1 c_wall violated: 2 conflicting context pair(s) with node memory, 5 node(s) had untolerated taint(s). no new claims to deallocate, preemption: 0/6 nodes are available: 1 No preemption victims found for incoming pod, 5 Preemption is not helpful for scheduling."
0.1577,Event,ADDED,eval-sanitize-1-r3-038-7jspz.18d4a2b367da2103,"reason=FailedScheduling count=None msg=0/6 nodes are available: 1 c_wall violated: 2 conflicting context pair(s) with node memory, 5 node(s) had untolerated taint(s). no new claims to deallocate, preemption: 0/6 nodes are available: 1 No preemption victims found for incoming pod, 5 Preemption is not helpful for scheduling."
0.1579,Event,ADDED,eval-sanitize-1-r3-038-7jspz.18d4a2b39f6ed412,"reason=FailedScheduling count=None msg=0/6 nodes are available: 1 c_wall violated: 2 conflicting context pair(s) with node memory, 5 node(s) had untolerated taint(s). no new claims to deallocate, preemption: 0/6 nodes are available: 1 No preemption victims found for incoming pod, 5 Preemption is not helpful for scheduling."
0.1581,Event,ADDED,eval-sanitize-1-r3-039-cqswx.18d4a2b368135f8a,"reason=FailedScheduling count=None msg=0/6 nodes are available: 1 c_wall violated: 2 conflicting context pair(s) with node memory, 5 node(s) had untolerated taint(s). no new claims to deallocate, preemption: 0/6 nodes are available: 1 No preemption victims found for incoming pod, 5 Preemption is not helpful for scheduling."
0.1583,Event,ADDED,eval-sanitize-1-r3-039-cqswx.18d4a2b39f9c50f1,"reason=FailedScheduling count=None msg=0/6 nodes are available: 1 c_wall violated: 2 conflicting context pair(s) with node memory, 5 node(s) had untolerated taint(s). no new claims to deallocate, preemption: 0/6 nodes are available: 1 No preemption victims found for incoming pod, 5 Preemption is not helpful for scheduling."
0.1585,Event,ADDED,eval-sanitize-1-r3-046-kmtzr.18d4a2b3685201c2,"reason=FailedScheduling count=None msg=0/6 nodes are available: 1 c_wall violated: 1 conflicting context pair(s) with node memory, 5 node(s) had untolerated taint(s). no new claims to deallocate, preemption: 0/6 nodes are available: 1 No preemption victims found for incoming pod, 5 Preemption is not helpful for scheduling."
0.1587,Event,ADDED,eval-sanitize-1-r3-049-grv8q.18d4a2b3d259f810,"reason=FailedScheduling count=None msg=0/6 nodes are available: 1 c_wall violated: 1 conflicting context pair(s) with node memory, 5 node(s) had untolerated taint(s). no new claims to deallocate, preemption: 0/6 nodes are available: 1 No preemption victims found for incoming pod, 5 Preemption is not helpful for scheduling."
0.1589,Event,ADDED,eval-sanitize-1-r3-049-grv8q.18d4a2b401fe349f,"reason=FailedScheduling count=None msg=0/6 nodes are available: 1 c_wall violated: 1 conflicting context pair(s) with node memory, 5 node(s) had untolerated taint(s). no new claims to deallocate, preemption: 0/6 nodes are available: 1 No preemption victims found for incoming pod, 5 Preemption is not helpful for scheduling."
0.159,Event,ADDED,eval-sanitize-1-r3-049-grv8q.18d4a2b43c813561,"reason=FailedScheduling count=None msg=0/6 nodes are available: 1 c_wall violated: 2 conflicting context pair(s) with node memory, 5 node(s) had untolerated taint(s). no new claims to deallocate, preemption: 0/6 nodes are available: 1 No preemption victims found for incoming pod, 5 Preemption is not helpful for scheduling."
0.1592,Event,ADDED,eval-sanitize-1-r3-050-tqssj.18d4a2b413f57a89,"reason=FailedScheduling count=None msg=0/6 nodes are available: 1 c_wall violated: 1 conflicting context pair(s) with node memory, 5 node(s) had untolerated taint(s). no new claims to deallocate, preemption: 0/6 nodes are available: 1 No preemption victims found for incoming pod, 5 Preemption is not helpful for scheduling."
0.1594,Event,ADDED,eval-sanitize-1-r3-052-hchnz.18d4a2b44fe2c572,"reason=FailedScheduling count=None msg=0/6 nodes are available: 1 c_wall violated: 2 conflicting context pair(s) with node memory, 5 node(s) had untolerated taint(s). no new claims to deallocate, preemption: 0/6 nodes are available: 1 No preemption victims found for incoming pod, 5 Preemption is not helpful for scheduling."
0.1596,Event,ADDED,eval-sanitize-1-r3-054-j45ls.18d4a2b863e67612,"reason=FailedScheduling count=None msg=0/6 nodes are available: 1 c_wall violated: 1 conflicting context pair(s) with node memory, 5 node(s) had untolerated taint(s). no new claims to deallocate, preemption: 0/6 nodes are available: 1 No preemption victims found for incoming pod, 5 Preemption is not helpful for scheduling."
0.1598,Event,ADDED,eval-sanitize-1-r3-054-j45ls.18d4a2b8c12a4dac,"reason=FailedScheduling count=None msg=0/6 nodes are available: 1 c_wall violated: 2 conflicting context pair(s) with node memory, 5 node(s) had untolerated taint(s). no new claims to deallocate, preemption: 0/6 nodes are available: 1 No preemption victims found for incoming pod, 5 Preemption is not helpful for scheduling."
0.16,Event,ADDED,eval-sanitize-1-r3-058-t4w86.18d4a2b864422b78,"reason=FailedScheduling count=None msg=0/6 nodes are available: 1 c_wall violated: 3 conflicting context pair(s) with node memory, 5 node(s) had untolerated taint(s). no new claims to deallocate, preemption: 0/6 nodes are available: 1 No preemption victims found for incoming pod, 5 Preemption is not helpful for scheduling."
0.1601,Event,ADDED,eval-sanitize-1-r3-059-2mhg4.18d4a2b86fb8bf15,"reason=FailedScheduling count=None msg=0/6 nodes are available: 1 c_wall violated: 2 conflicting context pair(s) with node memory, 5 node(s) had untolerated taint(s). no new claims to deallocate, preemption: 0/6 nodes are available: 1 No preemption victims found for incoming pod, 5 Preemption is not helpful for scheduling."
0.1603,Event,ADDED,eval-sanitize-1-r3-062-74zs8.18d4a2b868787835,"reason=FailedScheduling count=None msg=0/6 nodes are available: 1 c_wall violated: 3 conflicting context pair(s) with node memory, 5 node(s) had untolerated taint(s). no new claims to deallocate, preemption: 0/6 nodes are available: 1 No preemption victims found for incoming pod, 5 Preemption is not helpful for scheduling."
0.1605,Event,ADDED,eval-sanitize-1-r3-063-s4zg9.18d4a2b8697e21fa,"reason=FailedScheduling count=None msg=0/6 nodes are available: 1 c_wall violated: 1 conflicting context pair(s) with node memory, 5 node(s) had untolerated taint(s). no new claims to deallocate, preemption: 0/6 nodes are available: 1 No preemption victims found for incoming pod, 5 Preemption is not helpful for scheduling."
0.1607,Event,ADDED,eval-sanitize-1-r3-063-s4zg9.18d4a2b8bab93aac,"reason=FailedScheduling count=None msg=0/6 nodes are available: 1 c_wall violated: 2 conflicting context pair(s) with node memory, 5 node(s) had untolerated taint(s). no new claims to deallocate, preemption: 0/6 nodes are available: 1 No preemption victims found for incoming pod, 5 Preemption is not helpful for scheduling."
0.1609,Event,ADDED,eval-sanitize-1-r3-064-7gsbw.18d4a2b869b9dc30,"reason=FailedScheduling count=None msg=0/6 nodes are available: 1 c_wall violated: 1 conflicting context pair(s) with node memory, 5 node(s) had untolerated taint(s). no new claims to deallocate, preemption: 0/6 nodes are available: 1 No preemption victims found for incoming pod, 5 Preemption is not helpful for scheduling."
0.1611,Event,ADDED,eval-sanitize-1-r3-064-7gsbw.18d4a2b8c060a050,"reason=FailedScheduling count=None msg=0/6 nodes are available: 1 c_wall violated: 2 conflicting context pair(s) with node memory, 5 node(s) had untolerated taint(s). no new claims to deallocate, preemption: 0/6 nodes are available: 1 No preemption victims found for incoming pod, 5 Preemption is not helpful for scheduling."
0.1613,Event,ADDED,eval-sanitize-1-r3-065-4wgst.18d4a2b869f7f8ec,"reason=FailedScheduling count=None msg=0/6 nodes are available: 1 c_wall violated: 1 conflicting context pair(s) with node memory, 5 node(s) had untolerated taint(s). no new claims to deallocate, preemption: 0/6 nodes are available: 1 No preemption victims found for incoming pod, 5 Preemption is not helpful for scheduling."
0.1616,Event,ADDED,eval-sanitize-1-r3-065-4wgst.18d4a2b8c09a8bff,"reason=FailedScheduling count=None msg=0/6 nodes are available: 1 c_wall violated: 2 conflicting context pair(s) with node memory, 5 node(s) had untolerated taint(s). no new claims to deallocate, preemption: 0/6 nodes are available: 1 No preemption victims found for incoming pod, 5 Preemption is not helpful for scheduling."
0.1618,Event,ADDED,eval-sanitize-1-r3-066-rtjs5.18d4a2b8703ac7ce,"reason=FailedScheduling count=None msg=0/6 nodes are available: 1 c_wall violated: 4 conflicting context pair(s) with node memory, 5 node(s) had untolerated taint(s). no new claims to deallocate, preemption: 0/6 nodes are available: 1 No preemption victims found for incoming pod, 5 Preemption is not helpful for scheduling."
0.1622,Event,ADDED,eval-sanitize-1-r3-066-rtjs5.18d4a2b8ba787a5f,"reason=FailedScheduling count=None msg=0/6 nodes are available: 1 c_wall violated: 1 conflicting context pair(s) with node memory, 5 node(s) had untolerated taint(s). no new claims to deallocate, preemption: 0/6 nodes are available: 1 No preemption victims found for incoming pod, 5 Preemption is not helpful for scheduling."
0.1624,Event,ADDED,eval-sanitize-1-r3-066-rtjs5.18d4a2b98e3a69c9,"reason=FailedScheduling count=None msg=0/6 nodes are available: 1 c_wall violated: 1 conflicting context pair(s) with node memory, 5 node(s) had untolerated taint(s). no new claims to deallocate, preemption: 0/6 nodes are available: 1 No preemption victims found for incoming pod, 5 Preemption is not helpful for scheduling."
0.1626,Event,ADDED,eval-sanitize-1-r3-068-qgkch.18d4a2b86e69c955,"reason=FailedScheduling count=None msg=0/6 nodes are available: 1 c_wall violated: 2 conflicting context pair(s) with node memory, 5 node(s) had untolerated taint(s). no new claims to deallocate, preemption: 0/6 nodes are available: 1 No preemption victims found for incoming pod, 5 Preemption is not helpful for scheduling."
0.163,Event,ADDED,eval-sanitize-1-r3-068-qgkch.18d4a2b8c0cfecad,"reason=FailedScheduling count=None msg=0/6 nodes are available: 1 c_wall violated: 1 conflicting context pair(s) with node memory, 5 node(s) had untolerated taint(s). no new claims to deallocate, preemption: 0/6 nodes are available: 1 No preemption victims found for incoming pod, 5 Preemption is not helpful for scheduling."
0.1632,Event,ADDED,eval-sanitize-1-r3-069-rn2rl.18d4a2b86ea0855e,"reason=FailedScheduling count=None msg=0/6 nodes are available: 1 c_wall violated: 4 conflicting context pair(s) with node memory, 5 node(s) had untolerated taint(s). no new claims to deallocate, preemption: 0/6 nodes are available: 1 No preemption victims found for incoming pod, 5 Preemption is not helpful for scheduling."
0.1634,Event,ADDED,eval-sanitize-1-r3-069-rn2rl.18d4a2b8c1001e6b,"reason=FailedScheduling count=None msg=0/6 nodes are available: 1 c_wall violated: 1 conflicting context pair(s) with node memory, 5 node(s) had untolerated taint(s). no new claims to deallocate, preemption: 0/6 nodes are available: 1 No preemption victims found for incoming pod, 5 Preemption is not helpful for scheduling."
0.1637,Event,ADDED,eval-sanitize-1-r3-069-rn2rl.18d4a2b98e09d9af,"reason=FailedScheduling count=None msg=0/6 nodes are available: 1 c_wall violated: 1 conflicting context pair(s) with node memory, 5 node(s) had untolerated taint(s). no new claims to deallocate, preemption: 0/6 nodes are available: 1 No preemption victims found for incoming pod, 5 Preemption is not helpful for scheduling."
0.1639,Event,ADDED,eval-sanitize-1-r3-072-6rvwj.18d4a2b98ef4b2b4,"reason=FailedScheduling count=None msg=0/6 nodes are available: 1 c_wall violated: 1 conflicting context pair(s) with node memory, 5 node(s) had untolerated taint(s). no new claims to deallocate, preemption: 0/6 nodes are available: 1 No preemption victims found for incoming pod, 5 Preemption is not helpful for scheduling."
0.1641,Event,ADDED,eval-sanitize-1-r3-072-6rvwj.18d4a2b9c5976c2c,"reason=FailedScheduling count=None msg=0/6 nodes are available: 1 c_wall violated: 2 conflicting context pair(s) with node memory, 5 node(s) had untolerated taint(s). no new claims to deallocate, preemption: 0/6 nodes are available: 1 No preemption victims found for incoming pod, 5 Preemption is not helpful for scheduling."
0.1644,Event,ADDED,eval-sanitize-1-r3-073-96rwm.18d4a2b98f23f54c,"reason=FailedScheduling count=None msg=0/6 nodes are available: 1 c_wall violated: 1 conflicting context pair(s) with node memory, 5 node(s) had untolerated taint(s). no new claims to deallocate, preemption: 0/6 nodes are available: 1 No preemption victims found for incoming pod, 5 Preemption is not helpful for scheduling."
0.1646,Event,ADDED,eval-sanitize-1-r3-073-96rwm.18d4a2bdf8e50fed,"reason=FailedScheduling count=None msg=0/6 nodes are available: 1 c_wall violated: 1 conflicting context pair(s) with node memory, 5 node(s) had untolerated taint(s). no new claims to deallocate, preemption: 0/6 nodes are available: 1 No preemption victims found for incoming pod, 5 Preemption is not helpful for scheduling."
0.1648,Event,ADDED,eval-sanitize-1-r3-073-96rwm.18d4a2be429c6b2b,"reason=FailedScheduling count=None msg=0/6 nodes are available: 1 c_wall violated: 2 conflicting context pair(s) with node memory, 5 node(s) had untolerated taint(s). no new claims to deallocate, preemption: 0/6 nodes are available: 1 No preemption victims found for incoming pod, 5 Preemption is not helpful for scheduling."
0.1652,Event,ADDED,eval-sanitize-1-r3-073.18d4a2c4ed788c17,reason=Completed count=1 msg=Job completed
0.1655,Event,ADDED,eval-sanitize-1-r3-074-c2wqb.18d4a2b9925336ca,"reason=FailedScheduling count=None msg=0/6 nodes are available: 1 c_wall violated: 2 conflicting context pair(s) with node memory, 5 node(s) had untolerated taint(s). no new claims to deallocate, preemption: 0/6 nodes are available: 1 No preemption victims found for incoming pod, 5 Preemption is not helpful for scheduling."
0.1657,Event,ADDED,eval-sanitize-1-r3-075-pc6jk.18d4a2b99288d56d,"reason=FailedScheduling count=None msg=0/6 nodes are available: 1 c_wall violated: 1 conflicting context pair(s) with node memory, 5 node(s) had untolerated taint(s). no new claims to deallocate, preemption: 0/6 nodes are available: 1 No preemption victims found for incoming pod, 5 Preemption is not helpful for scheduling."
0.1661,Event,ADDED,eval-sanitize-1-r3-077-mds7t.18d4a2bdf90d469c,"reason=FailedScheduling count=None msg=0/6 nodes are available: 1 c_wall violated: 1 conflicting context pair(s) with node memory, 5 node(s) had untolerated taint(s). no new claims to deallocate, preemption: 0/6 nodes are available: 1 No preemption victims found for incoming pod, 5 Preemption is not helpful for scheduling."
0.1663,Event,ADDED,eval-sanitize-1-r3-077-mds7t.18d4a2bf2ac96f5c,"reason=FailedScheduling count=None msg=0/6 nodes are available: 1 c_wall violated: 2 conflicting context pair(s) with node memory, 5 node(s) had untolerated taint(s). no new claims to deallocate, preemption: 0/6 nodes are available: 1 No preemption victims found for incoming pod, 5 Preemption is not helpful for scheduling."
0.1665,Event,ADDED,eval-sanitize-1-r3-077.18d4a2c5a88231d4,reason=Completed count=1 msg=Job completed
0.167,Event,ADDED,eval-sanitize-1-r3-080-ncnd7.18d4a2bdf9380715,"reason=FailedScheduling count=None msg=0/6 nodes are available: 1 c_wall violated: 1 conflicting context pair(s) with node memory, 5 node(s) had untolerated taint(s). no new claims to deallocate, preemption: 0/6 nodes are available: 1 No preemption victims found for incoming pod, 5 Preemption is not helpful for scheduling."
0.1672,Event,ADDED,eval-sanitize-1-r3-080-ncnd7.18d4a2be42f040da,"reason=FailedScheduling count=None msg=0/6 nodes are available: 1 c_wall violated: 2 conflicting context pair(s) with node memory, 5 node(s) had untolerated taint(s). no new claims to deallocate, preemption: 0/6 nodes are available: 1 No preemption victims found for incoming pod, 5 Preemption is not helpful for scheduling."
0.1674,Event,ADDED,eval-sanitize-1-r3-080.18d4a2c4ed41b3a7,reason=Completed count=1 msg=Job completed
0.1678,Event,ADDED,eval-sanitize-1-r3-081-tckdd.18d4a2be46564a58,"reason=FailedScheduling count=None msg=0/6 nodes are available: 1 c_wall violated: 1 conflicting context pair(s) with node memory, 5 node(s) had untolerated taint(s). no new claims to deallocate, preemption: 0/6 nodes are available: 1 No preemption victims found for incoming pod, 5 Preemption is not helpful for scheduling."
0.168,Event,ADDED,eval-sanitize-1-r3-081.18d4a2c4ba4b50ad,reason=Completed count=1 msg=Job completed
0.1682,Event,ADDED,eval-sanitize-1-r3-083-hx6s2.18d4a2bdfa18dda2,"reason=FailedScheduling count=None msg=0/6 nodes are available: 1 c_wall violated: 1 conflicting context pair(s) with node memory, 5 node(s) had untolerated taint(s). no new claims to deallocate, preemption: 0/6 nodes are available: 1 No preemption victims found for incoming pod, 5 Preemption is not helpful for scheduling."
0.1686,Event,ADDED,eval-sanitize-1-r3-083-hx6s2.18d4a2be4681d898,"reason=FailedScheduling count=None msg=0/6 nodes are available: 1 c_wall violated: 1 conflicting context pair(s) with node memory, 5 node(s) had untolerated taint(s). no new claims to deallocate, preemption: 0/6 nodes are available: 1 No preemption victims found for incoming pod, 5 Preemption is not helpful for scheduling."
0.1688,Event,ADDED,eval-sanitize-1-r3-083-hx6s2.18d4a2bf2b92ee0a,"reason=FailedScheduling count=None msg=0/6 nodes are available: 1 c_wall violated: 2 conflicting context pair(s) with node memory, 5 node(s) had untolerated taint(s). no new claims to deallocate, preemption: 0/6 nodes are available: 1 No preemption victims found for incoming pod, 5 Preemption is not helpful for scheduling."
0.169,Event,ADDED,eval-sanitize-1-r3-083-hx6s2.18d4a2bfc2460820,"reason=FailedScheduling count=None msg=0/6 nodes are available: 1 c_wall violated: 2 conflicting context pair(s) with node memory, 5 node(s) had untolerated taint(s). no new claims to deallocate, preemption: 0/6 nodes are available: 1 No preemption victims found for incoming pod, 5 Preemption is not helpful for scheduling."
0.1693,Event,ADDED,eval-sanitize-1-r3-083.18d4a2c62896a66f,reason=Completed count=1 msg=Job completed
0.1695,Event,ADDED,eval-sanitize-1-r3-085-vgmkw.18d4a2bdfebb8a13,"reason=FailedScheduling count=None msg=0/6 nodes are available: 1 c_wall violated: 1 conflicting context pair(s) with node memory, 5 node(s) had untolerated taint(s). no new claims to deallocate, preemption: 0/6 nodes are available: 1 No preemption victims found for incoming pod, 5 Preemption is not helpful for scheduling."
0.1696,Event,ADDED,eval-sanitize-1-r3-085-vgmkw.18d4a2be475da4f7,"reason=FailedScheduling count=None msg=0/6 nodes are available: 1 c_wall violated: 1 conflicting context pair(s) with node memory, 5 node(s) had untolerated taint(s). no new claims to deallocate, preemption: 0/6 nodes are available: 1 No preemption victims found for incoming pod, 5 Preemption is not helpful for scheduling."
0.17,Event,ADDED,eval-sanitize-1-r3-085.18d4a2c4ba48924e,reason=Completed count=1 msg=Job completed
0.1702,Event,ADDED,eval-sanitize-1-r3-086-rthnh.18d4a2bdfefaf6ab,"reason=FailedScheduling count=None msg=0/6 nodes are available: 1 c_wall violated: 1 conflicting context pair(s) with node memory, 5 node(s) had untolerated taint(s). no new claims to deallocate, preemption: 0/6 nodes are available: 1 No preemption victims found for incoming pod, 5 Preemption is not helpful for scheduling."
0.1703,Event,ADDED,eval-sanitize-1-r3-086-rthnh.18d4a2be478f6e66,"reason=FailedScheduling count=None msg=0/6 nodes are available: 1 c_wall violated: 1 conflicting context pair(s) with node memory, 5 node(s) had untolerated taint(s). no new claims to deallocate, preemption: 0/6 nodes are available: 1 No preemption victims found for incoming pod, 5 Preemption is not helpful for scheduling."
0.1707,Event,ADDED,eval-sanitize-1-r3-086-rthnh.18d4a2bf2fb5af61,"reason=FailedScheduling count=None msg=0/6 nodes are available: 1 c_wall violated: 2 conflicting context pair(s) with node memory, 5 node(s) had untolerated taint(s). no new claims to deallocate, preemption: 0/6 nodes are available: 1 No preemption victims found for incoming pod, 5 Preemption is not helpful for scheduling."
0.1709,Event,ADDED,eval-sanitize-1-r3-086.18d4a2c5ae6f5cc0,reason=Completed count=1 msg=Job completed
0.1711,Event,ADDED,eval-sanitize-1-r3-088-wttmd.18d4a2bdff325da0,"reason=FailedScheduling count=None msg=0/6 nodes are available: 1 c_wall violated: 1 conflicting context pair(s) with node memory, 5 node(s) had untolerated taint(s). no new claims to deallocate, preemption: 0/6 nodes are available: 1 No preemption victims found for incoming pod, 5 Preemption is not helpful for scheduling."
0.1714,Event,ADDED,eval-sanitize-1-r3-088-wttmd.18d4a2be47badc49,"reason=FailedScheduling count=None msg=0/6 nodes are available: 1 c_wall violated: 1 conflicting context pair(s) with node memory, 5 node(s) had untolerated taint(s). no new claims to deallocate, preemption: 0/6 nodes are available: 1 No preemption victims found for incoming pod, 5 Preemption is not helpful for scheduling."
0.1716,Event,ADDED,eval-sanitize-1-r3-088-wttmd.18d4a2bf2fe6f425,"reason=FailedScheduling count=None msg=0/6 nodes are available: 1 c_wall violated: 2 conflicting context pair(s) with node memory, 5 node(s) had untolerated taint(s). no new claims to deallocate, preemption: 0/6 nodes are available: 1 No preemption victims found for incoming pod, 5 Preemption is not helpful for scheduling."
0.1718,Event,ADDED,eval-sanitize-1-r3-088.18d4a2c5b7a392eb,reason=Completed count=1 msg=Job completed
0.1721,Event,ADDED,eval-sanitize-1-r3-090-t68rt.18d4a2bdffb92e01,"reason=FailedScheduling count=None msg=0/6 nodes are available: 1 c_wall violated: 1 conflicting context pair(s) with node memory, 5 node(s) had untolerated taint(s). no new claims to deallocate, preemption: 0/6 nodes are available: 1 No preemption victims found for incoming pod, 5 Preemption is not helpful for scheduling."
0.1723,Event,ADDED,eval-sanitize-1-r3-090-t68rt.18d4a2be47e32875,"reason=FailedScheduling count=None msg=0/6 nodes are available: 1 c_wall violated: 2 conflicting context pair(s) with node memory, 5 node(s) had untolerated taint(s). no new claims to deallocate, preemption: 0/6 nodes are available: 1 No preemption victims found for incoming pod, 5 Preemption is not helpful for scheduling."
0.1725,Event,ADDED,eval-sanitize-1-r3-090.18d4a2c4ba480169,reason=Completed count=1 msg=Job completed
0.1728,Event,ADDED,eval-sanitize-1-r3-091-7j2jf.18d4a2bdfff7caec,"reason=FailedScheduling count=None msg=0/6 nodes are available: 1 c_wall violated: 2 conflicting context pair(s) with node memory, 5 node(s) had untolerated taint(s). no new claims to deallocate, preemption: 0/6 nodes are available: 1 No preemption victims found for incoming pod, 5 Preemption is not helpful for scheduling."
0.1732,Event,ADDED,eval-sanitize-1-r3-091-7j2jf.18d4a2be480a82b1,"reason=FailedScheduling count=None msg=0/6 nodes are available: 1 c_wall violated: 1 conflicting context pair(s) with node memory, 5 node(s) had untolerated taint(s). no new claims to deallocate, preemption: 0/6 nodes are available: 1 No preemption victims found for incoming pod, 5 Preemption is not helpful for scheduling."
0.1734,Event,ADDED,eval-sanitize-1-r3-091.18d4a2c4ba1d823a,reason=Completed count=1 msg=Job completed
0.1737,Event,ADDED,eval-sanitize-1-r3-096-vs8ct.18d4a2bf2af33716,"reason=FailedScheduling count=None msg=0/6 nodes are available: 1 c_wall violated: 1 conflicting context pair(s) with node memory, 5 node(s) had untolerated taint(s). no new claims to deallocate, preemption: 0/6 nodes are available: 1 No preemption victims found for incoming pod, 5 Preemption is not helpful for scheduling."
0.1739,Event,ADDED,eval-sanitize-1-r3-096-vs8ct.18d4a2bfc1d674d2,"reason=FailedScheduling count=None msg=0/6 nodes are available: 1 c_wall violated: 1 conflicting context pair(s) with node memory, 5 node(s) had untolerated taint(s). no new claims to deallocate, preemption: 0/6 nodes are available: 1 No preemption victims found for incoming pod, 5 Preemption is not helpful for scheduling."
0.1741,Event,ADDED,eval-sanitize-1-r3-096.18d4a2c5f955d324,reason=Completed count=1 msg=Job completed
0.1742,Event,ADDED,eval-sanitize-1-r3-097-xz79w.18d4a2bf2b247a15,"reason=FailedScheduling count=None msg=0/6 nodes are available: 1 c_wall violated: 2 conflicting context pair(s) with node memory, 5 node(s) had untolerated taint(s). no new claims to deallocate, preemption: 0/6 nodes are available: 1 No preemption victims found for incoming pod, 5 Preemption is not helpful for scheduling."
0.1746,Event,ADDED,eval-sanitize-1-r3-097.18d4a2c5ab7e3a05,reason=Completed count=1 msg=Job completed
0.1747,Event,ADDED,eval-sanitize-1-r3-098.18d4a2c4ed7951cc,reason=Completed count=1 msg=Job completed
0.1749,Event,ADDED,eval-sanitize-1-r3-099-dxr5s.18d4a2bf2b6d2039,"reason=FailedScheduling count=None msg=0/6 nodes are available: 1 c_wall violated: 1 conflicting context pair(s) with node memory, 5 node(s) had untolerated taint(s). no new claims to deallocate, preemption: 0/6 nodes are available: 1 No preemption victims found for incoming pod, 5 Preemption is not helpful for scheduling."
0.1753,Event,ADDED,eval-sanitize-1-r3-099-dxr5s.18d4a2bfc20e3a5d,"reason=FailedScheduling count=None msg=0/6 nodes are available: 1 c_wall violated: 1 conflicting context pair(s) with node memory, 5 node(s) had untolerated taint(s). no new claims to deallocate, preemption: 0/6 nodes are available: 1 No preemption victims found for incoming pod, 5 Preemption is not helpful for scheduling."
0.1754,Event,ADDED,eval-sanitize-1-r3-099.18d4a2c601e7f8be,reason=Completed count=1 msg=Job completed
0.1756,Event,ADDED,eval-sanitize-1-r3-100.18d4a2c52914e0d8,reason=Completed count=1 msg=Job completed
0.1759,Event,ADDED,eval-sanitize-1-r3-101-mzkbp.18d4a2bfc2749f7c,"reason=FailedScheduling count=None msg=0/6 nodes are available: 1 c_wall violated: 1 conflicting context pair(s) with node memory, 5 node(s) had untolerated taint(s). no new claims to deallocate, preemption: 0/6 nodes are available: 1 No preemption victims found for incoming pod, 5 Preemption is not helpful for scheduling."
0.1761,Event,ADDED,eval-sanitize-1-r3-101.18d4a2c5fd39feb1,reason=Completed count=1 msg=Job completed
0.1762,Event,ADDED,eval-sanitize-1-r3-102-p6wrv.18d4a2bfc74ae04a,"reason=FailedScheduling count=None msg=0/6 nodes are available: 1 c_wall violated: 2 conflicting context pair(s) with node memory, 5 node(s) had untolerated taint(s). no new claims to deallocate, preemption: 0/6 nodes are available: 1 No preemption victims found for incoming pod, 5 Preemption is not helpful for scheduling."
0.1766,Event,ADDED,eval-sanitize-1-r3-102-p6wrv.18d4a2c0103ee4f8,"reason=FailedScheduling count=None msg=0/6 nodes are available: 1 c_wall violated: 2 conflicting context pair(s) with node memory, 5 node(s) had untolerated taint(s). no new claims to deallocate, preemption: 0/6 nodes are available: 1 No preemption victims found for incoming pod, 5 Preemption is not helpful for scheduling."
0.1767,Event,ADDED,eval-sanitize-1-r3-102.18d4a2c962890c28,reason=Completed count=1 msg=Job completed
0.1769,Event,ADDED,eval-sanitize-1-r3-103.18d4a2c5de0d5734,reason=Completed count=1 msg=Job completed
0.1771,Event,ADDED,eval-sanitize-1-r3-104.18d4a2c62c71ddea,reason=Completed count=1 msg=Job completed
0.1774,Event,ADDED,eval-sanitize-1-r3-105.18d4a2c961b9cffa,reason=Completed count=1 msg=Job completed
0.1777,Event,ADDED,eval-sanitize-1-r3-106.18d4a2c961113b00,reason=Completed count=1 msg=Job completed
0.178,Event,ADDED,eval-sanitize-1-r3-107-lf642.18d4a2c3c7777e8c,"reason=FailedScheduling count=None msg=0/6 nodes are available: 1 c_wall violated: 1 conflicting context pair(s) with node memory, 5 node(s) had untolerated taint(s). no new claims to deallocate, preemption: 0/6 nodes are available: 1 No preemption victims found for incoming pod, 5 Preemption is not helpful for scheduling."
0.1802,Event,ADDED,eval-sanitize-1-r3-107-lf642.18d4a2c460516305,"reason=FailedScheduling count=None msg=0/6 nodes are available: 1 c_wall violated: 2 conflicting context pair(s) with node memory, 5 node(s) had untolerated taint(s). no new claims to deallocate, preemption: 0/6 nodes are available: 1 No preemption victims found for incoming pod, 5 Preemption is not helpful for scheduling."
0.1804,Event,ADDED,eval-sanitize-1-r3-107-lf642.18d4a2c466fefeeb,"reason=FailedScheduling count=None msg=0/6 nodes are available: 1 c_wall violated: 2 conflicting context pair(s) with node memory, 5 node(s) had untolerated taint(s). no new claims to deallocate, preemption: 0/6 nodes are available: 1 No preemption victims found for incoming pod, 5 Preemption is not helpful for scheduling."
0.1805,Event,ADDED,eval-sanitize-1-r3-107-lf642.18d4a2c4d9e96949,"reason=FailedScheduling count=None msg=0/6 nodes are available: 1 c_wall violated: 2 conflicting context pair(s) with node memory, 5 node(s) had untolerated taint(s). no new claims to deallocate, preemption: 0/6 nodes are available: 1 No preemption victims found for incoming pod, 5 Preemption is not helpful for scheduling."
0.1809,Event,ADDED,eval-sanitize-1-r3-107-lf642.18d4a2c4e1846cfa,"reason=FailedScheduling count=None msg=0/6 nodes are available: 1 c_wall violated: 2 conflicting context pair(s) with node memory, 5 node(s) had untolerated taint(s). no new claims to deallocate, preemption: 0/6 nodes are available: 1 No preemption victims found for incoming pod, 5 Preemption is not helpful for scheduling."
0.181,Event,ADDED,eval-sanitize-1-r3-107-lf642.18d4a2c57b140e77,reason=Scheduled count=None msg=Successfully assigned compute/eval-sanitize-1-r3-107-lf642 to kind-worker2
0.1812,Event,ADDED,eval-sanitize-1-r3-107-lf642.18d4a2c59ce0a37a,"reason=Pulled count=1 msg=Container image ""busybox:musl"" already present on machine"
0.1814,Event,ADDED,eval-sanitize-1-r3-107-lf642.18d4a2c59f0cf23a,reason=Created count=1 msg=Created container: task
0.1817,Event,ADDED,eval-sanitize-1-r3-107-lf642.18d4a2c5a43aab2d,reason=Started count=1 msg=Started container task
0.1819,Event,ADDED,eval-sanitize-1-r3-107.18d4a2cb2fe4f82e,reason=Completed count=1 msg=Job completed
0.1821,Event,ADDED,eval-sanitize-1-r3-108-p7sdb.18d4a2c3ce3d1e9b,"reason=FailedScheduling count=None msg=0/6 nodes are available: 1 c_wall violated: 3 conflicting context pair(s) with node memory, 5 node(s) had untolerated taint(s). no new claims to deallocate, preemption: 0/6 nodes are available: 1 No preemption victims found for incoming pod, 5 Preemption is not helpful for scheduling."
0.1824,Event,ADDED,eval-sanitize-1-r3-108-p7sdb.18d4a2c456fff231,reason=Scheduled count=None msg=Successfully assigned compute/eval-sanitize-1-r3-108-p7sdb to kind-worker5
0.1826,Event,ADDED,eval-sanitize-1-r3-108-p7sdb.18d4a2c47b8445ee,"reason=Pulled count=1 msg=Container image ""busybox:musl"" already present on machine"
0.1828,Event,ADDED,eval-sanitize-1-r3-108-p7sdb.18d4a2c47dc0f2aa,reason=Created count=1 msg=Created container: task
0.183,Event,ADDED,eval-sanitize-1-r3-108-p7sdb.18d4a2c48660f3b4,reason=Started count=1 msg=Started container task
0.1833,Event,ADDED,eval-sanitize-1-r3-108.18d4a2c9e73d58dc,reason=Completed count=1 msg=Job completed
0.1835,Event,ADDED,eval-sanitize-1-r3-109-plrr7.18d4a2c3c9653e78,"reason=FailedScheduling count=None msg=0/6 nodes are available: 1 c_wall violated: 1 conflicting context pair(s) with node memory, 5 node(s) had untolerated taint(s). no new claims to deallocate, preemption: 0/6 nodes are available: 1 No preemption victims found for incoming pod, 5 Preemption is not helpful for scheduling."
0.1838,Event,ADDED,eval-sanitize-1-r3-109-plrr7.18d4a2c456e53299,"reason=FailedScheduling count=None msg=0/6 nodes are available: 1 c_wall violated: 1 conflicting context pair(s) with node memory, 5 node(s) had untolerated taint(s). no new claims to deallocate, preemption: 0/6 nodes are available: 1 No preemption victims found for incoming pod, 5 Preemption is not helpful for scheduling."
0.184,Event,ADDED,eval-sanitize-1-r3-109-plrr7.18d4a2c4610213c7,"reason=FailedScheduling count=None msg=0/6 nodes are available: 1 c_wall violated: 2 conflicting context pair(s) with node memory, 5 node(s) had untolerated taint(s). no new claims to deallocate, preemption: 0/6 nodes are available: 1 No preemption victims found for incoming pod, 5 Preemption is not helpful for scheduling."
0.1842,Event,ADDED,eval-sanitize-1-r3-109-plrr7.18d4a2c46728e536,"reason=FailedScheduling count=None msg=0/6 nodes are available: 1 c_wall violated: 2 conflicting context pair(s) with node memory, 5 node(s) had untolerated taint(s). no new claims to deallocate, preemption: 0/6 nodes are available: 1 No preemption victims found for incoming pod, 5 Preemption is not helpful for scheduling."
0.1844,Event,ADDED,eval-sanitize-1-r3-109-plrr7.18d4a2c4db904653,"reason=FailedScheduling count=None msg=0/6 nodes are available: 1 c_wall violated: 2 conflicting context pair(s) with node memory, 5 node(s) had untolerated taint(s). no new claims to deallocate, preemption: 0/6 nodes are available: 1 No preemption victims found for incoming pod, 5 Preemption is not helpful for scheduling."
0.1846,Event,ADDED,eval-sanitize-1-r3-109-plrr7.18d4a2c4e1bb44b8,"reason=FailedScheduling count=None msg=0/6 nodes are available: 1 c_wall violated: 2 conflicting context pair(s) with node memory, 5 node(s) had untolerated taint(s). no new claims to deallocate, preemption: 0/6 nodes are available: 1 No preemption victims found for incoming pod, 5 Preemption is not helpful for scheduling."
0.1847,Event,ADDED,eval-sanitize-1-r3-109-plrr7.18d4a2c57b6b9a81,reason=Scheduled count=None msg=Successfully assigned compute/eval-sanitize-1-r3-109-plrr7 to kind-worker2
0.1849,Event,ADDED,eval-sanitize-1-r3-109-plrr7.18d4a2c59d292d68,"reason=Pulled count=1 msg=Container image ""busybox:musl"" already present on machine"
0.1851,Event,ADDED,eval-sanitize-1-r3-109-plrr7.18d4a2c5a0c35f06,reason=Created count=1 msg=Created container: task
0.1852,Event,ADDED,eval-sanitize-1-r3-109-plrr7.18d4a2c5a5a9c99f,reason=Started count=1 msg=Started container task
0.1855,Event,ADDED,eval-sanitize-1-r3-109.18d4a2cb2f04ec0e,reason=Completed count=1 msg=Job completed
0.1857,Event,ADDED,eval-sanitize-1-r3-110-l5k4l.18d4a2c3c99045c8,"reason=FailedScheduling count=None msg=0/6 nodes are available: 1 c_wall violated: 1 conflicting context pair(s) with node memory, 5 node(s) had untolerated taint(s). no new claims to deallocate, preemption: 0/6 nodes are available: 1 No preemption victims found for incoming pod, 5 Preemption is not helpful for scheduling."
0.1859,Event,ADDED,eval-sanitize-1-r3-110-l5k4l.18d4a2c457cd1974,reason=Scheduled count=None msg=Successfully assigned compute/eval-sanitize-1-r3-110-l5k4l to kind-worker5
0.186,Event,ADDED,eval-sanitize-1-r3-110-l5k4l.18d4a2c47bac3ff0,"reason=Pulled count=1 msg=Container image ""busybox:musl"" already present on machine"
0.1864,Event,ADDED,eval-sanitize-1-r3-110-l5k4l.18d4a2c47e9aaadc,reason=Created count=1 msg=Created container: task
0.1865,Event,ADDED,eval-sanitize-1-r3-110-l5k4l.18d4a2c4866219d1,reason=Started count=1 msg=Started container task
0.1867,Event,ADDED,eval-sanitize-1-r3-110.18d4a2c9e76f0250,reason=Completed count=1 msg=Job completed
0.187,Event,ADDED,eval-sanitize-1-r3-111.18d4a2c9626934e9,reason=Completed count=1 msg=Job completed
0.1872,Event,ADDED,eval-sanitize-1-r3-112.18d4a2c961121d32,reason=Completed count=1 msg=Job completed
0.1874,Event,ADDED,eval-sanitize-1-r3-113-2fmbw.18d4a2c3c9b6fd96,"reason=FailedScheduling count=None msg=0/6 nodes are available: 1 c_wall violated: 1 conflicting context pair(s) with node memory, 5 node(s) had untolerated taint(s). no new claims to deallocate, preemption: 0/6 nodes are available: 1 No preemption victims found for incoming pod, 5 Preemption is not helpful for scheduling."
0.1876,Event,ADDED,eval-sanitize-1-r3-113-2fmbw.18d4a2c457a18b84,"reason=FailedScheduling count=None msg=0/6 nodes are available: 1 c_wall violated: 2 conflicting context pair(s) with node memory, 5 node(s) had untolerated taint(s). no new claims to deallocate, preemption: 0/6 nodes are available: 1 No preemption victims found for incoming pod, 5 Preemption is not helpful for scheduling."
0.1878,Event,ADDED,eval-sanitize-1-r3-113-2fmbw.18d4a2c4618adb0e,"reason=FailedScheduling count=None msg=0/6 nodes are available: 1 c_wall violated: 2 conflicting context pair(s) with node memory, 5 node(s) had untolerated taint(s). no new claims to deallocate, preemption: 0/6 nodes are available: 1 No preemption victims found for incoming pod, 5 Preemption is not helpful for scheduling."
0.188,Event,ADDED,eval-sanitize-1-r3-113-2fmbw.18d4a2c4dc50f6bc,"reason=FailedScheduling count=None msg=0/6 nodes are available: 1 c_wall violated: 2 conflicting context pair(s) with node memory, 5 node(s) had untolerated taint(s). no new claims to deallocate, preemption: 0/6 nodes are available: 1 No preemption victims found for incoming pod, 5 Preemption is not helpful for scheduling."
0.1882,Event,ADDED,eval-sanitize-1-r3-113-2fmbw.18d4a2c4e1ebb59f,"reason=FailedScheduling count=None msg=0/6 nodes are available: 1 c_wall violated: 2 conflicting context pair(s) with node memory, 5 node(s) had untolerated taint(s). no new claims to deallocate, preemption: 0/6 nodes are available: 1 No preemption victims found for incoming pod, 5 Preemption is not helpful for scheduling."
0.1883,Event,ADDED,eval-sanitize-1-r3-113-2fmbw.18d4a2c57b97a3e6,reason=Scheduled count=None msg=Successfully assigned compute/eval-sanitize-1-r3-113-2fmbw to kind-worker2
0.1885,Event,ADDED,eval-sanitize-1-r3-113-2fmbw.18d4a2c59d087c84,"reason=Pulled count=1 msg=Container image ""busybox:musl"" already present on machine"
0.1886,Event,ADDED,eval-sanitize-1-r3-113-2fmbw.18d4a2c5a02cf86a,reason=Created count=1 msg=Created container: task
0.1888,Event,ADDED,eval-sanitize-1-r3-113-2fmbw.18d4a2c5a5aa0357,reason=Started count=1 msg=Started container task
0.189,Event,ADDED,eval-sanitize-1-r3-113.18d4a2cb30026f81,reason=Completed count=1 msg=Job completed
0.1892,Event,ADDED,eval-sanitize-1-r3-114-pvxng.18d4a2c3cbdb4683,"reason=FailedScheduling count=None msg=0/6 nodes are available: 1 c_wall violated: 2 conflicting context pair(s) with node memory, 5 node(s) had untolerated taint(s). no new claims to deallocate, preemption: 0/6 nodes are available: 1 No preemption victims found for incoming pod, 5 Preemption is not helpful for scheduling."
0.1893,Event,ADDED,eval-sanitize-1-r3-114-pvxng.18d4a2c45831910b,"reason=FailedScheduling count=None msg=0/6 nodes are available: 1 c_wall violated: 1 conflicting context pair(s) with node memory, 5 node(s) had untolerated taint(s). no new claims to deallocate, preemption: 0/6 nodes are available: 1 No preemption victims found for incoming pod, 5 Preemption is not helpful for scheduling."
0.1895,Event,ADDED,eval-sanitize-1-r3-114-pvxng.18d4a2c461bb868e,"reason=FailedScheduling count=None msg=0/6 nodes are available: 1 c_wall violated: 1 conflicting context pair(s) with node memory, 5 node(s) had untolerated taint(s). no new claims to deallocate, preemption: 0/6 nodes are available: 1 No preemption victims found for incoming pod, 5 Preemption is not helpful for scheduling."
0.1897,Event,ADDED,eval-sanitize-1-r3-114-pvxng.18d4a2c4d527e5c7,"reason=FailedScheduling count=None msg=0/6 nodes are available: 1 c_wall violated: 1 conflicting context pair(s) with node memory, 5 node(s) had untolerated taint(s). no new claims to deallocate, preemption: 0/6 nodes are available: 1 No preemption victims found for incoming pod, 5 Preemption is not helpful for scheduling."
0.1901,Event,ADDED,eval-sanitize-1-r3-114-pvxng.18d4a2c4ddef8a57,"reason=FailedScheduling count=None msg=0/6 nodes are available: 1 c_wall violated: 1 conflicting context pair(s) with node memory, 5 node(s) had untolerated taint(s). no new claims to deallocate, preemption: 0/6 nodes are available: 1 No preemption victims found for incoming pod, 5 Preemption is not helpful for scheduling."
0.1903,Event,ADDED,eval-sanitize-1-r3-114-pvxng.18d4a2c57d69518f,reason=Scheduled count=None msg=Successfully assigned compute/eval-sanitize-1-r3-114-pvxng to kind-worker2
0.1904,Event,ADDED,eval-sanitize-1-r3-114-pvxng.18d4a2c59e2c90cd,"reason=Pulled count=1 msg=Container image ""busybox:musl"" already present on machine"
0.1906,Event,ADDED,eval-sanitize-1-r3-114-pvxng.18d4a2c5a1246017,reason=Created count=1 msg=Created container: task
0.1909,Event,ADDED,eval-sanitize-1-r3-114-pvxng.18d4a2c5a5a9d48a,reason=Started count=1 msg=Started container task
0.1911,Event,ADDED,eval-sanitize-1-r3-114.18d4a2cb2e4b904b,reason=Completed count=1 msg=Job completed
0.1913,Event,ADDED,eval-sanitize-1-r3-115-bpf8x.18d4a2c3cd71e742,"reason=FailedScheduling count=None msg=0/6 nodes are available: 1 c_wall violated: 2 conflicting context pair(s) with node memory, 5 node(s) had untolerated taint(s). no new claims to deallocate, preemption: 0/6 nodes are available: 1 No preemption victims found for incoming pod, 5 Preemption is not helpful for scheduling."
0.1916,Event,ADDED,eval-sanitize-1-r3-115-bpf8x.18d4a2c45c7e96cd,"reason=FailedScheduling count=None msg=0/6 nodes are available: 1 c_wall violated: 2 conflicting context pair(s) with node memory, 5 node(s) had untolerated taint(s). no new claims to deallocate, preemption: 0/6 nodes are available: 1 No preemption victims found for incoming pod, 5 Preemption is not helpful for scheduling."
0.1918,Event,ADDED,eval-sanitize-1-r3-115-bpf8x.18d4a2c465cff916,"reason=FailedScheduling count=None msg=0/6 nodes are available: 1 c_wall violated: 2 conflicting context pair(s) with node memory, 5 node(s) had untolerated taint(s). no new claims to deallocate, preemption: 0/6 nodes are available: 1 No preemption victims found for incoming pod, 5 Preemption is not helpful for scheduling."
0.1919,Event,ADDED,eval-sanitize-1-r3-115-bpf8x.18d4a2c4d6cea22e,reason=Scheduled count=None msg=Successfully assigned compute/eval-sanitize-1-r3-115-bpf8x to kind-worker3
0.1922,Event,ADDED,eval-sanitize-1-r3-115-bpf8x.18d4a2c50cba3cee,"reason=Pulled count=1 msg=Container image ""busybox:musl"" already present on machine"
0.1926,Event,ADDED,eval-sanitize-1-r3-115-bpf8x.18d4a2c50f74b2bd,reason=Created count=1 msg=Created container: task
0.1928,Event,ADDED,eval-sanitize-1-r3-115-bpf8x.18d4a2c515c392e4,reason=Started count=1 msg=Started container task
0.193,Event,ADDED,eval-sanitize-1-r3-115.18d4a2ca82365235,reason=Completed count=1 msg=Job completed
0.1933,Event,ADDED,eval-sanitize-1-r3-116.18d4a2c9612fd64e,reason=Completed count=1 msg=Job completed
0.1935,Event,ADDED,eval-sanitize-1-r3-117.18d4a2c960d897aa,reason=Completed count=1 msg=Job completed
0.1937,Event,ADDED,eval-sanitize-1-r3-118-zbbgb.18d4a2c3cddb273a,"reason=FailedScheduling count=None msg=0/6 nodes are available: 1 c_wall violated: 2 conflicting context pair(s) with node memory, 5 node(s) had untolerated taint(s). no new claims to deallocate, preemption: 0/6 nodes are available: 1 No preemption victims found for incoming pod, 5 Preemption is not helpful for scheduling."
0.1941,Event,ADDED,eval-sanitize-1-r3-118-zbbgb.18d4a2c45fc18f18,"reason=FailedScheduling count=None msg=0/6 nodes are available: 1 c_wall violated: 2 conflicting context pair(s) with node memory, 5 node(s) had untolerated taint(s). no new claims to deallocate, preemption: 0/6 nodes are available: 1 No preemption victims found for incoming pod, 5 Preemption is not helpful for scheduling."
0.1943,Event,ADDED,eval-sanitize-1-r3-118-zbbgb.18d4a2c466d406ee,"reason=FailedScheduling count=None msg=0/6 nodes are available: 1 c_wall violated: 2 conflicting context pair(s) with node memory, 5 node(s) had untolerated taint(s). no new claims to deallocate, preemption: 0/6 nodes are available: 1 No preemption victims found for incoming pod, 5 Preemption is not helpful for scheduling."
0.1945,Event,ADDED,eval-sanitize-1-r3-118-zbbgb.18d4a2c4d9f8e428,reason=Scheduled count=None msg=Successfully assigned compute/eval-sanitize-1-r3-118-zbbgb to kind-worker3
0.1946,Event,ADDED,eval-sanitize-1-r3-118-zbbgb.18d4a2c4f2b1d777,"reason=Pulled count=1 msg=Container image ""busybox:musl"" already present on machine"
0.195,Event,ADDED,eval-sanitize-1-r3-118-zbbgb.18d4a2c4f41bed46,reason=Created count=1 msg=Created container: task
0.1951,Event,ADDED,eval-sanitize-1-r3-118-zbbgb.18d4a2c4fcffc478,reason=Started count=1 msg=Started container task
0.1953,Event,ADDED,eval-sanitize-1-r3-118.18d4a2ca8275aaa0,reason=Completed count=1 msg=Job completed
0.1957,Event,ADDED,eval-sanitize-1-r3-119-n7x4l.18d4a2c3cda82b06,"reason=FailedScheduling count=None msg=0/6 nodes are available: 1 c_wall violated: 2 conflicting context pair(s) with node memory, 5 node(s) had untolerated taint(s). no new claims to deallocate, preemption: 0/6 nodes are available: 1 No preemption victims found for incoming pod, 5 Preemption is not helpful for scheduling."
0.1958,Event,ADDED,eval-sanitize-1-r3-119-n7x4l.18d4a2c45cfb7262,"reason=FailedScheduling count=None msg=0/6 nodes are available: 1 c_wall violated: 2 conflicting context pair(s) with node memory, 5 node(s) had untolerated taint(s). no new claims to deallocate, preemption: 0/6 nodes are available: 1 No preemption victims found for incoming pod, 5 Preemption is not helpful for scheduling."
0.196,Event,ADDED,eval-sanitize-1-r3-119-n7x4l.18d4a2c4666bdaaf,"reason=FailedScheduling count=None msg=0/6 nodes are available: 1 c_wall violated: 2 conflicting context pair(s) with node memory, 5 node(s) had untolerated taint(s). no new claims to deallocate, preemption: 0/6 nodes are available: 1 No preemption victims found for incoming pod, 5 Preemption is not helpful for scheduling."
0.1963,Event,ADDED,eval-sanitize-1-r3-119-n7x4l.18d4a2c4d796dd75,reason=Scheduled count=None msg=Successfully assigned compute/eval-sanitize-1-r3-119-n7x4l to kind-worker3
0.1965,Event,ADDED,eval-sanitize-1-r3-119-n7x4l.18d4a2c50cd4f02c,"reason=Pulled count=1 msg=Container image ""busybox:musl"" already present on machine"
0.1967,Event,ADDED,eval-sanitize-1-r3-119-n7x4l.18d4a2c50fb3030b,reason=Created count=1 msg=Created container: task
0.1968,Event,ADDED,eval-sanitize-1-r3-119-n7x4l.18d4a2c515c44697,reason=Started count=1 msg=Started container task
0.1971,Event,ADDED,eval-sanitize-1-r3-119.18d4a2ca82f9750d,reason=Completed count=1 msg=Job completed
0.1973,Event,ADDED,eval-sanitize-1-r3-120-jdfvw.18d4a2c3ee54b312,"reason=FailedScheduling count=None msg=0/6 nodes are available: 1 c_wall violated: 1 conflicting context pair(s) with node memory, 5 node(s) had untolerated taint(s). no new claims to deallocate, preemption: 0/6 nodes are available: 1 No preemption victims found for incoming pod, 5 Preemption is not helpful for scheduling."
0.1975,Event,ADDED,eval-sanitize-1-r3-120-jdfvw.18d4a2c458bf14e4,"reason=FailedScheduling count=None msg=0/6 nodes are available: 1 c_wall violated: 2 conflicting context pair(s) with node memory, 5 node(s) had untolerated taint(s). no new claims to deallocate, preemption: 0/6 nodes are available: 1 No preemption victims found for incoming pod, 5 Preemption is not helpful for scheduling."
0.1987,Event,ADDED,eval-sanitize-1-r3-120-jdfvw.18d4a2c461e7c269,"reason=FailedScheduling count=None msg=0/6 nodes are available: 1 c_wall violated: 2 conflicting context pair(s) with node memory, 5 node(s) had untolerated taint(s). no new claims to deallocate, preemption: 0/6 nodes are available: 1 No preemption victims found for incoming pod, 5 Preemption is not helpful for scheduling."
0.1988,Event,ADDED,eval-sanitize-1-r3-120-jdfvw.18d4a2c4d5c046b0,"reason=FailedScheduling count=None msg=0/6 nodes are available: 1 c_wall violated: 1 conflicting context pair(s) with node memory, 5 node(s) had untolerated taint(s). no new claims to deallocate, preemption: 0/6 nodes are available: 1 No preemption victims found for incoming pod, 5 Preemption is not helpful for scheduling."
0.199,Event,ADDED,eval-sanitize-1-r3-120-jdfvw.18d4a2c4dfa185cd,"reason=FailedScheduling count=None msg=0/6 nodes are available: 1 c_wall violated: 2 conflicting context pair(s) with node memory, 5 node(s) had untolerated taint(s). no new claims to deallocate, preemption: 0/6 nodes are available: 1 No preemption victims found for incoming pod, 5 Preemption is not helpful for scheduling."
0.1993,Event,ADDED,eval-sanitize-1-r3-120-jdfvw.18d4a2c4e404e96c,"reason=FailedScheduling count=None msg=0/6 nodes are available: 1 c_wall violated: 2 conflicting context pair(s) with node memory, 5 node(s) had untolerated taint(s). no new claims to deallocate, preemption: 0/6 nodes are available: 1 No preemption victims found for incoming pod, 5 Preemption is not helpful for scheduling."
0.1995,Event,ADDED,eval-sanitize-1-r3-120-jdfvw.18d4a2c57d90abae,reason=Scheduled count=None msg=Successfully assigned compute/eval-sanitize-1-r3-120-jdfvw to kind-worker2
0.1997,Event,ADDED,eval-sanitize-1-r3-120-jdfvw.18d4a2c59e0132d8,"reason=Pulled count=1 msg=Container image ""busybox:musl"" already present on machine"
0.2,Event,ADDED,eval-sanitize-1-r3-120-jdfvw.18d4a2c5a1013895,reason=Created count=1 msg=Created container: task
0.2002,Event,ADDED,eval-sanitize-1-r3-120-jdfvw.18d4a2c5a5aa016d,reason=Started count=1 msg=Started container task
0.2003,Event,ADDED,eval-sanitize-1-r3-120.18d4a2cb2f526c8f,reason=Completed count=1 msg=Job completed
0.2005,Event,ADDED,eval-sanitize-1-r3-121-spd64.18d4a2c4611a55ed,reason=Scheduled count=None msg=Successfully assigned compute/eval-sanitize-1-r3-121-spd64 to kind-worker5
0.2008,Event,ADDED,eval-sanitize-1-r3-121-spd64.18d4a2c48663477b,"reason=Pulled count=1 msg=Container image ""busybox:musl"" already present on machine"
0.201,Event,ADDED,eval-sanitize-1-r3-121-spd64.18d4a2c487db6a54,reason=Created count=1 msg=Created container: task
0.2012,Event,ADDED,eval-sanitize-1-r3-121-spd64.18d4a2c48facc54b,reason=Started count=1 msg=Started container task
0.2013,Event,ADDED,eval-sanitize-1-r3-121.18d4a2ca22ebe8dd,reason=Completed count=1 msg=Job completed
0.2016,Event,ADDED,eval-sanitize-1-r3-122-cj4qc.18d4a2c465fe5649,"reason=FailedScheduling count=None msg=0/6 nodes are available: 1 c_wall violated: 1 conflicting context pair(s) with node memory, 5 node(s) had untolerated taint(s). no new claims to deallocate, preemption: 0/6 nodes are available: 1 No preemption victims found for incoming pod, 5 Preemption is not helpful for scheduling."
0.2018,Event,ADDED,eval-sanitize-1-r3-122-cj4qc.18d4a2c46cc3d7e6,"reason=FailedScheduling count=None msg=0/6 nodes are available: 1 c_wall violated: 1 conflicting context pair(s) with node memory, 5 node(s) had untolerated taint(s). no new claims to deallocate, preemption: 0/6 nodes are available: 1 No preemption victims found for incoming pod, 5 Preemption is not helpful for scheduling."
0.202,Event,ADDED,eval-sanitize-1-r3-122-cj4qc.18d4a2c4d714ff0b,reason=Scheduled count=None msg=Successfully assigned compute/eval-sanitize-1-r3-122-cj4qc to kind-worker3
0.2023,Event,ADDED,eval-sanitize-1-r3-122-cj4qc.18d4a2c50cf0a73e,"reason=Pulled count=1 msg=Container image ""busybox:musl"" already present on machine"
0.2025,Event,ADDED,eval-sanitize-1-r3-122-cj4qc.18d4a2c5100d07b2,reason=Created count=1 msg=Created container: task
0.2027,Event,ADDED,eval-sanitize-1-r3-122-cj4qc.18d4a2c515c27870,reason=Started count=1 msg=Started container task
0.2031,Event,ADDED,eval-sanitize-1-r3-122.18d4a2c46500f446,reason=SuccessfulCreate count=1 msg=Created pod: eval-sanitize-1-r3-122-cj4qc
0.2032,Event,ADDED,eval-sanitize-1-r3-122.18d4a2ca81b9be51,reason=Completed count=1 msg=Job completed
0.2034,Event,ADDED,eval-sanitize-1-r3-123-8ks25.18d4a2c4a04bad8a,"reason=FailedScheduling count=None msg=0/6 nodes are available: 1 c_wall violated: 2 conflicting context pair(s) with node memory, 5 node(s) had untolerated taint(s). no new claims to deallocate, preemption: 0/6 nodes are available: 1 No preemption victims found for incoming pod, 5 Preemption is not helpful for scheduling."
0.2036,Event,ADDED,eval-sanitize-1-r3-123-8ks25.18d4a2c4a0cf1ed1,"reason=FailedScheduling count=None msg=0/6 nodes are available: 1 c_wall violated: 2 conflicting context pair(s) with node memory, 5 node(s) had untolerated taint(s). no new claims to deallocate, preemption: 0/6 nodes are available: 1 No preemption victims found for incoming pod, 5 Preemption is not helpful for scheduling."
0.2039,Event,ADDED,eval-sanitize-1-r3-123-8ks25.18d4a2c4d55bb49a,reason=Scheduled count=None msg=Successfully assigned compute/eval-sanitize-1-r3-123-8ks25 to kind-worker3
0.2041,Event,ADDED,eval-sanitize-1-r3-123-8ks25.18d4a2c50ca29dac,"reason=Pulled count=1 msg=Container image ""busybox:musl"" already present on machine"
0.2043,Event,ADDED,eval-sanitize-1-r3-123-8ks25.18d4a2c50ee0cfab,reason=Created count=1 msg=Created container: task
0.2045,Event,ADDED,eval-sanitize-1-r3-123-8ks25.18d4a2c514b4481a,reason=Started count=1 msg=Started container task
0.2047,Event,ADDED,eval-sanitize-1-r3-123.18d4a2c4a0059cd9,reason=SuccessfulCreate count=1 msg=Created pod: eval-sanitize-1-r3-123-8ks25
0.2048,Event,ADDED,eval-sanitize-1-r3-123.18d4a2ca814e21e6,reason=Completed count=1 msg=Job completed
0.205,Event,ADDED,eval-sanitize-1-r3-124-rn6ql.18d4a2c4dcfa4505,"reason=FailedScheduling count=None msg=0/6 nodes are available: 1 c_wall violated: 3 conflicting context pair(s) with node memory, 5 node(s) had untolerated taint(s). no new claims to deallocate, preemption: 0/6 nodes are available: 1 No preemption victims found for incoming pod, 5 Preemption is not helpful for scheduling."
0.2052,Event,ADDED,eval-sanitize-1-r3-124-rn6ql.18d4a2c4e2ec43ad,"reason=FailedScheduling count=None msg=0/6 nodes are available: 1 c_wall violated: 3 conflicting context pair(s) with node memory, 5 node(s) had untolerated taint(s). no new claims to deallocate, preemption: 0/6 nodes are available: 1 No preemption victims found for incoming pod, 5 Preemption is not helpful for scheduling."
0.2053,Event,ADDED,eval-sanitize-1-r3-124-rn6ql.18d4a2c57b84d058,"reason=FailedScheduling count=None msg=0/6 nodes are available: 1 c_wall violated: 1 conflicting context pair(s) with node memory, 5 node(s) had untolerated taint(s). no new claims to deallocate, preemption: 0/6 nodes are available: 1 No preemption victims found for incoming pod, 5 Preemption is not helpful for scheduling."
0.2055,Event,ADDED,eval-sanitize-1-r3-124-rn6ql.18d4a2c581767109,"reason=FailedScheduling count=None msg=0/6 nodes are available: 1 c_wall violated: 1 conflicting context pair(s) with node memory, 5 node(s) had untolerated taint(s). no new claims to deallocate, preemption: 0/6 nodes are available: 1 No preemption victims found for incoming pod, 5 Preemption is not helpful for scheduling."
0.2058,Event,ADDED,eval-sanitize-1-r3-124-rn6ql.18d4a2c598467efb,reason=Scheduled count=None msg=Successfully assigned compute/eval-sanitize-1-r3-124-rn6ql to kind-worker4
0.206,Event,ADDED,eval-sanitize-1-r3-124-rn6ql.18d4a2c5af792644,"reason=Pulled count=1 msg=Container image ""busybox:musl"" already present on machine"
0.2062,Event,ADDED,eval-sanitize-1-r3-124-rn6ql.18d4a2c5b083e42f,reason=Created count=1 msg=Created container: task
0.2065,Event,ADDED,eval-sanitize-1-r3-124-rn6ql.18d4a2c5b5a663f4,reason=Started count=1 msg=Started container task
0.2067,Event,ADDED,eval-sanitize-1-r3-124.18d4a2c4dbfdc45c,reason=SuccessfulCreate count=1 msg=Created pod: eval-sanitize-1-r3-124-rn6ql
0.2068,Event,ADDED,eval-sanitize-1-r3-124.18d4a2cb73456cda,reason=Completed count=1 msg=Job completed
0.207,Event,ADDED,eval-sanitize-1-r3-125-c2ksj.18d4a2c5179dd1f4,"reason=FailedScheduling count=None msg=0/6 nodes are available: 6 node(s) had untolerated taint(s). no new claims to deallocate, preemption: 0/6 nodes are available: 6 Preemption is not helpful for scheduling."
0.2072,Event,ADDED,eval-sanitize-1-r3-125-c2ksj.18d4a2c5808ffc85,"reason=FailedScheduling count=None msg=0/6 nodes are available: 1 c_wall violated: 1 conflicting context pair(s) with node memory, 5 node(s) had untolerated taint(s). no new claims to deallocate, preemption: 0/6 nodes are available: 1 No preemption victims found for incoming pod, 5 Preemption is not helpful for scheduling."
0.2074,Event,ADDED,eval-sanitize-1-r3-125-c2ksj.18d4a2c5819fd956,"reason=FailedScheduling count=None msg=0/6 nodes are available: 1 c_wall violated: 1 conflicting context pair(s) with node memory, 5 node(s) had untolerated taint(s). no new claims to deallocate, preemption: 0/6 nodes are available: 1 No preemption victims found for incoming pod, 5 Preemption is not helpful for scheduling."
0.2076,Event,ADDED,eval-sanitize-1-r3-125-c2ksj.18d4a2c5a195c589,"reason=FailedScheduling count=None msg=0/6 nodes are available: 2 c_wall violated: 1 conflicting context pair(s) with node memory, 4 node(s) had untolerated taint(s). no new claims to deallocate, preemption: 0/6 nodes are available: 2 No preemption victims found for incoming pod, 4 Preemption is not helpful for scheduling."
0.2078,Event,ADDED,eval-sanitize-1-r3-125-c2ksj.18d4a2c5bc783ecf,"reason=FailedScheduling count=None msg=0/6 nodes are available: 1 c_wall violated: 1 conflicting context pair(s) with node memory, 5 node(s) had untolerated taint(s). no new claims to deallocate, preemption: 0/6 nodes are available: 1 No preemption victims found for incoming pod, 5 Preemption is not helpful for scheduling."
0.2079,Event,ADDED,eval-sanitize-1-r3-125-c2ksj.18d4a2c91af84d24,"reason=FailedScheduling count=None msg=0/6 nodes are available: 1 c_wall violated: 1 conflicting context pair(s) with node memory, 5 node(s) had untolerated taint(s). no new claims to deallocate, preemption: 0/6 nodes are available: 1 No preemption victims found for incoming pod, 5 Preemption is not helpful for scheduling."
0.2081,Event,ADDED,eval-sanitize-1-r3-125-c2ksj.18d4a2c92aa10751,"reason=FailedScheduling count=None msg=0/6 nodes are available: 1 c_wall violated: 3 conflicting context pair(s) with node memory, 5 node(s) had untolerated taint(s). no new claims to deallocate, preemption: 0/6 nodes are available: 1 No preemption victims found for incoming pod, 5 Preemption is not helpful for scheduling."
0.2083,Event,ADDED,eval-sanitize-1-r3-125-c2ksj.18d4a2c931671823,"reason=FailedScheduling count=None msg=0/6 nodes are available: 1 c_wall violated: 3 conflicting context pair(s) with node memory, 5 node(s) had untolerated taint(s). no new claims to deallocate, preemption: 0/6 nodes are available: 1 No preemption victims found for incoming pod, 5 Preemption is not helpful for scheduling."
0.2084,Event,ADDED,eval-sanitize-1-r3-125-c2ksj.18d4a2c9cab3c584,"reason=FailedScheduling count=None msg=0/6 nodes are available: 1 c_wall violated: 1 conflicting context pair(s) with node memory, 5 node(s) had untolerated taint(s). no new claims to deallocate, preemption: 0/6 nodes are available: 1 No preemption victims found for incoming pod, 5 Preemption is not helpful for scheduling."
0.2086,Event,ADDED,eval-sanitize-1-r3-125-c2ksj.18d4a2c9d50eaf55,"reason=FailedScheduling count=None msg=0/6 nodes are available: 1 c_wall violated: 1 conflicting context pair(s) with node memory, 5 node(s) had untolerated taint(s). no new claims to deallocate, preemption: 0/6 nodes are available: 1 No preemption victims found for incoming pod, 5 Preemption is not helpful for scheduling."
0.2088,Event,ADDED,eval-sanitize-1-r3-125-c2ksj.18d4a2ca753c63fd,reason=Scheduled count=None msg=Successfully assigned compute/eval-sanitize-1-r3-125-c2ksj to kind-worker3
0.2089,Event,ADDED,eval-sanitize-1-r3-125-c2ksj.18d4a2ca93097ebf,"reason=Pulled count=1 msg=Container image ""busybox:musl"" already present on machine"
0.2091,Event,ADDED,eval-sanitize-1-r3-125-c2ksj.18d4a2ca970d73fd,reason=Created count=1 msg=Created container: task
0.2093,Event,ADDED,eval-sanitize-1-r3-125-c2ksj.18d4a2ca99a34d55,reason=Started count=1 msg=Started container task
0.2094,Event,ADDED,eval-sanitize-1-r3-125.18d4a2c51755911f,reason=SuccessfulCreate count=1 msg=Created pod: eval-sanitize-1-r3-125-c2ksj
0.2096,Event,ADDED,eval-sanitize-1-r3-125.18d4a2cff6be9db9,reason=Completed count=1 msg=Job completed
0.2098,Event,ADDED,eval-sanitize-1-r3-126-mqdzn.18d4a2c553e4d5b1,"reason=FailedScheduling count=None msg=0/6 nodes are available: 6 node(s) had untolerated taint(s). no new claims to deallocate, preemption: 0/6 nodes are available: 6 Preemption is not helpful for scheduling."
0.2099,Event,ADDED,eval-sanitize-1-r3-126-mqdzn.18d4a2c581091d87,"reason=FailedScheduling count=None msg=0/6 nodes are available: 1 c_wall violated: 1 conflicting context pair(s) with node memory, 5 node(s) had untolerated taint(s). no new claims to deallocate, preemption: 0/6 nodes are available: 1 No preemption victims found for incoming pod, 5 Preemption is not helpful for scheduling."
0.2102,Event,ADDED,eval-sanitize-1-r3-126-mqdzn.18d4a2c581d55634,"reason=FailedScheduling count=None msg=0/6 nodes are available: 1 c_wall violated: 1 conflicting context pair(s) with node memory, 5 node(s) had untolerated taint(s). no new claims to deallocate, preemption: 0/6 nodes are available: 1 No preemption victims found for incoming pod, 5 Preemption is not helpful for scheduling."
0.2104,Event,ADDED,eval-sanitize-1-r3-126-mqdzn.18d4a2c5a2b43c5f,"reason=FailedScheduling count=None msg=0/6 nodes are available: 2 c_wall violated: 1 conflicting context pair(s) with node memory, 4 node(s) had untolerated taint(s). no new claims to deallocate, preemption: 0/6 nodes are available: 2 No preemption victims found for incoming pod, 4 Preemption is not helpful for scheduling."
0.2106,Event,ADDED,eval-sanitize-1-r3-126-mqdzn.18d4a2c5bc4e4cb8,"reason=FailedScheduling count=None msg=0/6 nodes are available: 1 c_wall violated: 1 conflicting context pair(s) with node memory, 5 node(s) had untolerated taint(s). no new claims to deallocate, preemption: 0/6 nodes are available: 1 No preemption victims found for incoming pod, 5 Preemption is not helpful for scheduling."
0.2108,Event,ADDED,eval-sanitize-1-r3-126-mqdzn.18d4a2c91acb3838,reason=Scheduled count=None msg=Successfully assigned compute/eval-sanitize-1-r3-126-mqdzn to kind-worker
0.2109,Event,ADDED,eval-sanitize-1-r3-126-mqdzn.18d4a2c934f85fa2,"reason=Pulled count=1 msg=Container image ""busybox:musl"" already present on machine"
0.2111,Event,ADDED,eval-sanitize-1-r3-126-mqdzn.18d4a2c9384219ab,reason=Created count=1 msg=Created container: task
0.2113,Event,ADDED,eval-sanitize-1-r3-126-mqdzn.18d4a2c93c1c8189,reason=Started count=1 msg=Started container task
0.2114,Event,ADDED,eval-sanitize-1-r3-126.18d4a2c553da7206,reason=SuccessfulCreate count=1 msg=Created pod: eval-sanitize-1-r3-126-mqdzn
0.2116,Event,ADDED,eval-sanitize-1-r3-126.18d4a2ce6cbd9054,reason=Completed count=1 msg=Job completed
0.2118,Event,ADDED,eval-sanitize-1-r3-127-2fkps.18d4a2c59106bfb6,reason=Scheduled count=None msg=Successfully assigned compute/eval-sanitize-1-r3-127-2fkps to kind-worker2
0.2119,Event,ADDED,eval-sanitize-1-r3-127-2fkps.18d4a2c5a9c7105b,"reason=Pulled count=1 msg=Container image ""busybox:musl"" already present on machine"
0.2121,Event,ADDED,eval-sanitize-1-r3-127-2fkps.18d4a2c5aace3acb,reason=Created count=1 msg=Created container: task
0.2122,Event,ADDED,eval-sanitize-1-r3-127-2fkps.18d4a2c5ace9dd8b,reason=Started count=1 msg=Started container task
0.2124,Event,ADDED,eval-sanitize-1-r3-127.18d4a2c59070f248,reason=SuccessfulCreate count=1 msg=Created pod: eval-sanitize-1-r3-127-2fkps
0.2126,Event,ADDED,eval-sanitize-1-r3-127.18d4a2cb2da62fdf,reason=Completed count=1 msg=Job completed
0.2127,Event,ADDED,eval-sanitize-1-r3-128-q2jh9.18d4a2c5d57040fc,"reason=FailedScheduling count=None msg=0/6 nodes are available: 1 c_wall violated: 1 conflicting context pair(s) with node memory, 5 node(s) had untolerated taint(s). no new claims to deallocate, preemption: 0/6 nodes are available: 1 No preemption victims found for incoming pod, 5 Preemption is not helpful for scheduling."
0.2131,Event,ADDED,eval-sanitize-1-r3-128-q2jh9.18d4a2c5d5e6cf38,"reason=FailedScheduling count=None msg=0/6 nodes are available: 1 c_wall violated: 1 conflicting context pair(s) with node memory, 5 node(s) had untolerated taint(s). no new claims to deallocate, preemption: 0/6 nodes are available: 1 No preemption victims found for incoming pod, 5 Preemption is not helpful for scheduling."
0.2135,Event,ADDED,eval-sanitize-1-r3-128-q2jh9.18d4a2c91c2b0668,reason=Scheduled count=None msg=Successfully assigned compute/eval-sanitize-1-r3-128-q2jh9 to kind-worker
0.2138,Event,ADDED,eval-sanitize-1-r3-128-q2jh9.18d4a2c9376c02f7,"reason=Pulled count=1 msg=Container image ""busybox:musl"" already present on machine"
0.2147,Event,ADDED,eval-sanitize-1-r3-128-q2jh9.18d4a2c939fca40d,reason=Created count=1 msg=Created container: task
0.2148,Event,ADDED,eval-sanitize-1-r3-128-q2jh9.18d4a2c93d228f5f,reason=Started count=1 msg=Started container task
0.215,Event,ADDED,eval-sanitize-1-r3-128.18d4a2c5d5384edf,reason=SuccessfulCreate count=1 msg=Created pod: eval-sanitize-1-r3-128-q2jh9
0.2152,Event,ADDED,eval-sanitize-1-r3-128.18d4a2cea43f83b9,reason=Completed count=1 msg=Job completed
0.2155,Event,ADDED,eval-sanitize-1-r3-129-lbrhh.18d4a2c609b0c44d,"reason=FailedScheduling count=None msg=0/6 nodes are available: 6 node(s) had untolerated taint(s). no new claims to deallocate, preemption: 0/6 nodes are available: 6 Preemption is not helpful for scheduling."
0.2157,Event,ADDED,eval-sanitize-1-r3-129-lbrhh.18d4a2c91cc1701e,reason=Scheduled count=None msg=Successfully assigned compute/eval-sanitize-1-r3-129-lbrhh to kind-worker
0.2159,Event,ADDED,eval-sanitize-1-r3-129-lbrhh.18d4a2c93c25462e,"reason=Pulled count=1 msg=Container image ""busybox:musl"" already present on machine"
0.2162,Event,ADDED,eval-sanitize-1-r3-129-lbrhh.18d4a2c94086344d,reason=Created count=1 msg=Created container: task
0.2163,Event,ADDED,eval-sanitize-1-r3-129-lbrhh.18d4a2c9433665d4,reason=Started count=1 msg=Started container task
0.2165,Event,ADDED,eval-sanitize-1-r3-129.18d4a2c609a4d3eb,reason=SuccessfulCreate count=1 msg=Created pod: eval-sanitize-1-r3-129-lbrhh
0.2167,Event,ADDED,eval-sanitize-1-r3-129.18d4a2ce682fb356,reason=Completed count=1 msg=Job completed
0.2169,Event,ADDED,eval-sanitize-1-r3-130-ztq2f.18d4a2c643a44036,"reason=FailedScheduling count=None msg=0/6 nodes are available: 6 node(s) had untolerated taint(s). no new claims to deallocate, preemption: 0/6 nodes are available: 6 Preemption is not helpful for scheduling."
0.217,Event,ADDED,eval-sanitize-1-r3-130-ztq2f.18d4a2c91e2f6c7f,reason=Scheduled count=None msg=Successfully assigned compute/eval-sanitize-1-r3-130-ztq2f to kind-worker
0.2172,Event,ADDED,eval-sanitize-1-r3-130-ztq2f.18d4a2c93b420aef,"reason=Pulled count=1 msg=Container image ""busybox:musl"" already present on machine"
0.2174,Event,ADDED,eval-sanitize-1-r3-130-ztq2f.18d4a2c93d738cdf,reason=Created count=1 msg=Created container: task
0.2176,Event,ADDED,eval-sanitize-1-r3-130-ztq2f.18d4a2c9410111da,reason=Started count=1 msg=Started container task
0.2177,Event,ADDED,eval-sanitize-1-r3-130.18d4a2c64392bac1,reason=SuccessfulCreate count=1 msg=Created pod: eval-sanitize-1-r3-130-ztq2f
0.2179,Event,ADDED,eval-sanitize-1-r3-130.18d4a2ce68f3194e,reason=Completed count=1 msg=Job completed
0.218,Event,ADDED,eval-sanitize-1-r3-131-nz749.18d4a2c67d1fdc22,"reason=FailedScheduling count=None msg=0/6 nodes are available: 6 node(s) had untolerated taint(s). no new claims to deallocate, preemption: 0/6 nodes are available: 6 Preemption is not helpful for scheduling."
0.2182,Event,ADDED,eval-sanitize-1-r3-131-nz749.18d4a2c91e37044e,reason=Scheduled count=None msg=Successfully assigned compute/eval-sanitize-1-r3-131-nz749 to kind-worker
0.2184,Event,ADDED,eval-sanitize-1-r3-131-nz749.18d4a2c93c49a65d,"reason=Pulled count=1 msg=Container image ""busybox:musl"" already present on machine"
0.2185,Event,ADDED,eval-sanitize-1-r3-131-nz749.18d4a2c940042a57,reason=Created count=1 msg=Created container: task
0.2187,Event,ADDED,eval-sanitize-1-r3-131-nz749.18d4a2c9427481b8,reason=Started count=1 msg=Started container task
0.2189,Event,ADDED,eval-sanitize-1-r3-131.18d4a2c67d1631fe,reason=SuccessfulCreate count=1 msg=Created pod: eval-sanitize-1-r3-131-nz749
0.219,Event,ADDED,eval-sanitize-1-r3-131.18d4a2ce72a2b19c,reason=Completed count=1 msg=Job completed
0.2192,Event,ADDED,eval-sanitize-1-r3-132-zfd62.18d4a2c6b89c916d,"reason=FailedScheduling count=None msg=0/6 nodes are available: 6 node(s) had untolerated taint(s). no new claims to deallocate, preemption: 0/6 nodes are available: 6 Preemption is not helpful for scheduling."
0.2193,Event,ADDED,eval-sanitize-1-r3-132-zfd62.18d4a2c920a8b880,"reason=FailedScheduling count=None msg=0/6 nodes are available: 1 c_wall violated: 2 conflicting context pair(s) with node memory, 5 node(s) had untolerated taint(s). no new claims to deallocate, preemption: 0/6 nodes are available: 1 No preemption victims found for incoming pod, 5 Preemption is not helpful for scheduling."
0.2195,Event,ADDED,eval-sanitize-1-r3-132-zfd62.18d4a2c92c8597e1,"reason=FailedScheduling count=None msg=0/6 nodes are available: 1 c_wall violated: 3 conflicting context pair(s) with node memory, 5 node(s) had untolerated taint(s). no new claims to deallocate, preemption: 0/6 nodes are available: 1 No preemption victims found for incoming pod, 5 Preemption is not helpful for scheduling."
0.2197,Event,ADDED,eval-sanitize-1-r3-132-zfd62.18d4a2c932a44a90,"reason=FailedScheduling count=None msg=0/6 nodes are available: 1 c_wall violated: 3 conflicting context pair(s) with node memory, 5 node(s) had untolerated taint(s). no new claims to deallocate, preemption: 0/6 nodes are available: 1 No preemption victims found for incoming pod, 5 Preemption is not helpful for scheduling."
0.2198,Event,ADDED,eval-sanitize-1-r3-132-zfd62.18d4a2c9cd6f29c4,"reason=FailedScheduling count=None msg=0/6 nodes are available: 1 c_wall violated: 1 conflicting context pair(s) with node memory, 5 node(s) had untolerated taint(s). no new claims to deallocate, preemption: 0/6 nodes are available: 1 No preemption victims found for incoming pod, 5 Preemption is not helpful for scheduling."
0.22,Event,ADDED,eval-sanitize-1-r3-132-zfd62.18d4a2c9d535c67d,"reason=FailedScheduling count=None msg=0/6 nodes are available: 1 c_wall violated: 1 conflicting context pair(s) with node memory, 5 node(s) had untolerated taint(s). no new claims to deallocate, preemption: 0/6 nodes are available: 1 No preemption victims found for incoming pod, 5 Preemption is not helpful for scheduling."
0.2202,Event,ADDED,eval-sanitize-1-r3-132-zfd62.18d4a2ca757ea233,reason=Scheduled count=None msg=Successfully assigned compute/eval-sanitize-1-r3-132-zfd62 to kind-worker3
0.2203,Event,ADDED,eval-sanitize-1-r3-132-zfd62.18d4a2ca92ad41b8,"reason=Pulled count=1 msg=Container image ""busybox:musl"" already present on machine"
0.2205,Event,ADDED,eval-sanitize-1-r3-132-zfd62.18d4a2ca985193f3,reason=Created count=1 msg=Created container: task
0.2207,Event,ADDED,eval-sanitize-1-r3-132-zfd62.18d4a2ca9bb74f54,reason=Started count=1 msg=Started container task
0.2208,Event,ADDED,eval-sanitize-1-r3-132.18d4a2c6b88e18fe,reason=SuccessfulCreate count=1 msg=Created pod: eval-sanitize-1-r3-132-zfd62
0.221,Event,ADDED,eval-sanitize-1-r3-132.18d4a2cff846ba0c,reason=Completed count=1 msg=Job completed
0.2212,Event,ADDED,eval-sanitize-1-r3-133-2srxf.18d4a2c6f4760738,"reason=FailedScheduling count=None msg=0/6 nodes are available: 6 node(s) had untolerated taint(s). no new claims to deallocate, preemption: 0/6 nodes are available: 6 Preemption is not helpful for scheduling."
0.2213,Event,ADDED,eval-sanitize-1-r3-133-2srxf.18d4a2c9215b6ade,reason=Scheduled count=None msg=Successfully assigned compute/eval-sanitize-1-r3-133-2srxf to kind-worker
0.2215,Event,ADDED,eval-sanitize-1-r3-133-2srxf.18d4a2c93d258857,"reason=Pulled count=1 msg=Container image ""busybox:musl"" already present on machine"
0.2216,Event,ADDED,eval-sanitize-1-r3-133-2srxf.18d4a2c9415bd925,reason=Created count=1 msg=Created container: task
0.2218,Event,ADDED,eval-sanitize-1-r3-133-2srxf.18d4a2c9445d53fe,reason=Started count=1 msg=Started container task
0.222,Event,ADDED,eval-sanitize-1-r3-133.18d4a2c6f4698126,reason=SuccessfulCreate count=1 msg=Created pod: eval-sanitize-1-r3-133-2srxf
0.2221,Event,ADDED,eval-sanitize-1-r3-133.18d4a2ce7e8d7ac2,reason=Completed count=1 msg=Job completed
0.2223,Event,ADDED,eval-sanitize-1-r3-134-vmpl2.18d4a2c730959599,"reason=FailedScheduling count=None msg=0/6 nodes are available: 6 node(s) had untolerated taint(s). no new claims to deallocate, preemption: 0/6 nodes are available: 6 Preemption is not helpful for scheduling."
0.2224,Event,ADDED,eval-sanitize-1-r3-134-vmpl2.18d4a2c921556a0b,"reason=FailedScheduling count=None msg=0/6 nodes are available: 1 c_wall violated: 4 conflicting context pair(s) with node memory, 5 node(s) had untolerated taint(s). no new claims to deallocate, preemption: 0/6 nodes are available: 1 No preemption victims found for incoming pod, 5 Preemption is not helpful for scheduling."
0.2227,Event,ADDED,eval-sanitize-1-r3-134-vmpl2.18d4a2c92cfa20ac,"reason=FailedScheduling count=None msg=0/6 nodes are available: 1 c_wall violated: 4 conflicting context pair(s) with node memory, 5 node(s) had untolerated taint(s). no new claims to deallocate, preemption: 0/6 nodes are available: 1 No preemption victims found for incoming pod, 5 Preemption is not helpful for scheduling."
0.2229,Event,ADDED,eval-sanitize-1-r3-134-vmpl2.18d4a2c9c7f06951,reason=Scheduled count=None msg=Successfully assigned compute/eval-sanitize-1-r3-134-vmpl2 to kind-worker5
0.223,Event,ADDED,eval-sanitize-1-r3-134-vmpl2.18d4a2c9e1b2e408,"reason=Pulled count=1 msg=Container image ""busybox:musl"" already present on machine"
0.2232,Event,ADDED,eval-sanitize-1-r3-134-vmpl2.18d4a2c9e31b6688,reason=Created count=1 msg=Created container: task
0.2234,Event,ADDED,eval-sanitize-1-r3-134-vmpl2.18d4a2c9e7a95b30,reason=Started count=1 msg=Started container task
0.2235,Event,ADDED,eval-sanitize-1-r3-134.18d4a2c7308607dc,reason=SuccessfulCreate count=1 msg=Created pod: eval-sanitize-1-r3-134-vmpl2
0.2237,Event,ADDED,eval-sanitize-1-r3-134.18d4a2cf4fa663b6,reason=Completed count=1 msg=Job completed
0.2239,Event,ADDED,eval-sanitize-1-r3-135-695t8.18d4a2c76b742eae,"reason=FailedScheduling count=None msg=0/6 nodes are available: 6 node(s) had untolerated taint(s). no new claims to deallocate, preemption: 0/6 nodes are available: 6 Preemption is not helpful for scheduling."
0.2241,Event,ADDED,eval-sanitize-1-r3-135-695t8.18d4a2c92422d516,reason=Scheduled count=None msg=Successfully assigned compute/eval-sanitize-1-r3-135-695t8 to kind-worker
0.2242,Event,ADDED,eval-sanitize-1-r3-135-695t8.18d4a2c93d72c881,"reason=Pulled count=1 msg=Container image ""busybox:musl"" already present on machine"
0.2244,Event,ADDED,eval-sanitize-1-r3-135-695t8.18d4a2c94132f7be,reason=Created count=1 msg=Created container: task
0.2246,Event,ADDED,eval-sanitize-1-r3-135-695t8.18d4a2c9446258dd,reason=Started count=1 msg=Started container task
0.2247,Event,ADDED,eval-sanitize-1-r3-135.18d4a2c76b68e6dc,reason=SuccessfulCreate count=1 msg=Created pod: eval-sanitize-1-r3-135-695t8
0.2249,Event,ADDED,eval-sanitize-1-r3-135.18d4a2ce69b38b18,reason=Completed count=1 msg=Job completed
0.2251,Event,ADDED,eval-sanitize-1-r3-136-4bjlg.18d4a2c7a7fcc1f4,"reason=FailedScheduling count=None msg=0/6 nodes are available: 6 node(s) had untolerated taint(s). no new claims to deallocate, preemption: 0/6 nodes are available: 6 Preemption is not helpful for scheduling."
0.2252,Event,ADDED,eval-sanitize-1-r3-136-4bjlg.18d4a2c924281b65,"reason=FailedScheduling count=None msg=0/6 nodes are available: 1 c_wall violated: 3 conflicting context pair(s) with node memory, 5 node(s) had untolerated taint(s). no new claims to deallocate, preemption: 0/6 nodes are available: 1 No preemption victims found for incoming pod, 5 Preemption is not helpful for scheduling."
0.2254,Event,ADDED,eval-sanitize-1-r3-136-4bjlg.18d4a2c92d262a91,"reason=FailedScheduling count=None msg=0/6 nodes are available: 1 c_wall violated: 3 conflicting context pair(s) with node memory, 5 node(s) had untolerated taint(s). no new claims to deallocate, preemption: 0/6 nodes are available: 1 No preemption victims found for incoming pod, 5 Preemption is not helpful for scheduling."
0.2255,Event,ADDED,eval-sanitize-1-r3-136-4bjlg.18d4a2c9c7f006d6,"reason=FailedScheduling count=None msg=0/6 nodes are available: 1 c_wall violated: 1 conflicting context pair(s) with node memory, 5 node(s) had untolerated taint(s). no new claims to deallocate, preemption: 0/6 nodes are available: 1 No preemption victims found for incoming pod, 5 Preemption is not helpful for scheduling."
0.2257,Event,ADDED,eval-sanitize-1-r3-136-4bjlg.18d4a2c9d024fe29,"reason=FailedScheduling count=None msg=0/6 nodes are available: 1 c_wall violated: 1 conflicting context pair(s) with node memory, 5 node(s) had untolerated taint(s). no new claims to deallocate, preemption: 0/6 nodes are available: 1 No preemption victims found for incoming pod, 5 Preemption is not helpful for scheduling."
0.2259,Event,ADDED,eval-sanitize-1-r3-136-4bjlg.18d4a2ca75fd62a0,reason=Scheduled count=None msg=Successfully assigned compute/eval-sanitize-1-r3-136-4bjlg to kind-worker3
0.226,Event,ADDED,eval-sanitize-1-r3-136-4bjlg.18d4a2ca92c76a39,"reason=Pulled count=1 msg=Container image ""busybox:musl"" already present on machine"
0.2262,Event,ADDED,eval-sanitize-1-r3-136-4bjlg.18d4a2ca9885310c,reason=Created count=1 msg=Created container: task
0.2264,Event,ADDED,eval-sanitize-1-r3-136-4bjlg.18d4a2ca9c3aa611,reason=Started count=1 msg=Started container task
0.2265,Event,ADDED,eval-sanitize-1-r3-136.18d4a2c7a7f268f8,reason=SuccessfulCreate count=1 msg=Created pod: eval-sanitize-1-r3-136-4bjlg
0.2267,Event,ADDED,eval-sanitize-1-r3-136.18d4a2cff8463b64,reason=Completed count=1 msg=Job completed
0.2268,Event,ADDED,eval-sanitize-1-r3-137-wbpfb.18d4a2c7e2eebf58,"reason=FailedScheduling count=None msg=0/6 nodes are available: 6 node(s) had untolerated taint(s). no new claims to deallocate, preemption: 0/6 nodes are available: 6 Preemption is not helpful for scheduling."
0.227,Event,ADDED,eval-sanitize-1-r3-137-wbpfb.18d4a2c924d89bd8,"reason=FailedScheduling count=None msg=0/6 nodes are available: 1 c_wall violated: 1 conflicting context pair(s) with node memory, 5 node(s) had untolerated taint(s). no new claims to deallocate, preemption: 0/6 nodes are available: 1 No preemption victims found for incoming pod, 5 Preemption is not helpful for scheduling."
0.2272,Event,ADDED,eval-sanitize-1-r3-137-wbpfb.18d4a2c92d504b5a,"reason=FailedScheduling count=None msg=0/6 nodes are available: 1 c_wall violated: 1 conflicting context pair(s) with node memory, 5 node(s) had untolerated taint(s). no new claims to deallocate, preemption: 0/6 nodes are available: 1 No preemption victims found for incoming pod, 5 Preemption is not helpful for scheduling."
0.2273,Event,ADDED,eval-sanitize-1-r3-137-wbpfb.18d4a2c9c8b05efa,"reason=FailedScheduling count=None msg=0/6 nodes are available: 1 c_wall violated: 1 conflicting context pair(s) with node memory, 5 node(s) had untolerated taint(s). no new claims to deallocate, preemption: 0/6 nodes are available: 1 No preemption victims found for incoming pod, 5 Preemption is not helpful for scheduling."
0.2275,Event,ADDED,eval-sanitize-1-r3-137-wbpfb.18d4a2c9d058a8cb,"reason=FailedScheduling count=None msg=0/6 nodes are available: 1 c_wall violated: 2 conflicting context pair(s) with node memory, 5 node(s) had untolerated taint(s). no new claims to deallocate, preemption: 0/6 nodes are available: 1 No preemption victims found for incoming pod, 5 Preemption is not helpful for scheduling."
0.2276,Event,ADDED,eval-sanitize-1-r3-137-wbpfb.18d4a2c9d959af25,"reason=FailedScheduling count=None msg=0/6 nodes are available: 1 c_wall violated: 2 conflicting context pair(s) with node memory, 5 node(s) had untolerated taint(s). no new claims to deallocate, preemption: 0/6 nodes are available: 1 No preemption victims found for incoming pod, 5 Preemption is not helpful for scheduling."
0.2278,Event,ADDED,eval-sanitize-1-r3-137-wbpfb.18d4a2ca7e352e10,reason=Scheduled count=None msg=Successfully assigned compute/eval-sanitize-1-r3-137-wbpfb to kind-worker3
0.228,Event,ADDED,eval-sanitize-1-r3-137-wbpfb.18d4a2ca9c3cfe43,"reason=Pulled count=1 msg=Container image ""busybox:musl"" already present on machine"
0.2281,Event,ADDED,eval-sanitize-1-r3-137-wbpfb.18d4a2ca9e289d14,reason=Created count=1 msg=Created container: task
0.2283,Event,ADDED,eval-sanitize-1-r3-137-wbpfb.18d4a2caa21ba40c,reason=Started count=1 msg=Started container task
0.2285,Event,ADDED,eval-sanitize-1-r3-137.18d4a2c7e2e2b1db,reason=SuccessfulCreate count=1 msg=Created pod: eval-sanitize-1-r3-137-wbpfb
0.2286,Event,ADDED,eval-sanitize-1-r3-137.18d4a2d031bad7e5,reason=Completed count=1 msg=Job completed
0.2288,Event,ADDED,eval-sanitize-1-r3-138-htcjw.18d4a2c81e87689d,"reason=FailedScheduling count=None msg=0/6 nodes are available: 6 node(s) had untolerated taint(s). no new claims to deallocate, preemption: 0/6 nodes are available: 6 Preemption is not helpful for scheduling."
0.2289,Event,ADDED,eval-sanitize-1-r3-138-htcjw.18d4a2c926a318b9,"reason=FailedScheduling count=None msg=0/6 nodes are available: 1 c_wall violated: 1 conflicting context pair(s) with node memory, 5 node(s) had untolerated taint(s). no new claims to deallocate, preemption: 0/6 nodes are available: 1 No preemption victims found for incoming pod, 5 Preemption is not helpful for scheduling."
0.2291,Event,ADDED,eval-sanitize-1-r3-138-htcjw.18d4a2c92e2c6356,"reason=FailedScheduling count=None msg=0/6 nodes are available: 1 c_wall violated: 1 conflicting context pair(s) with node memory, 5 node(s) had untolerated taint(s). no new claims to deallocate, preemption: 0/6 nodes are available: 1 No preemption victims found for incoming pod, 5 Preemption is not helpful for scheduling."
0.2293,Event,ADDED,eval-sanitize-1-r3-138-htcjw.18d4a2c9c93e78bd,"reason=FailedScheduling count=None msg=0/6 nodes are available: 1 c_wall violated: 1 conflicting context pair(s) with node memory, 5 node(s) had untolerated taint(s). no new claims to deallocate, preemption: 0/6 nodes are available: 1 No preemption victims found for incoming pod, 5 Preemption is not helpful for scheduling."
0.2295,Event,ADDED,eval-sanitize-1-r3-138-htcjw.18d4a2c9d36305b5,"reason=FailedScheduling count=None msg=0/6 nodes are available: 1 c_wall violated: 2 conflicting context pair(s) with node memory, 5 node(s) had untolerated taint(s). no new claims to deallocate, preemption: 0/6 nodes are available: 1 No preemption victims found for incoming pod, 5 Preemption is not helpful for scheduling."
0.2299,Event,ADDED,eval-sanitize-1-r3-138-htcjw.18d4a2c9d9894c23,"reason=FailedScheduling count=None msg=0/6 nodes are available: 1 c_wall violated: 2 conflicting context pair(s) with node memory, 5 node(s) had untolerated taint(s). no new claims to deallocate, preemption: 0/6 nodes are available: 1 No preemption victims found for incoming pod, 5 Preemption is not helpful for scheduling."
0.2301,Event,ADDED,eval-sanitize-1-r3-138-htcjw.18d4a2ca7449e213,reason=Scheduled count=None msg=Successfully assigned compute/eval-sanitize-1-r3-138-htcjw to kind-worker3
0.2304,Event,ADDED,eval-sanitize-1-r3-138-htcjw.18d4a2ca90ad5eb8,"reason=Pulled count=1 msg=Container image ""busybox:musl"" already present on machine"
0.2306,Event,ADDED,eval-sanitize-1-r3-138-htcjw.18d4a2ca93a1223d,reason=Created count=1 msg=Created container: task
0.2307,Event,ADDED,eval-sanitize-1-r3-138-htcjw.18d4a2ca984df044,reason=Started count=1 msg=Started container task
0.2311,Event,ADDED,eval-sanitize-1-r3-138.18d4a2c81e74463b,reason=SuccessfulCreate count=1 msg=Created pod: eval-sanitize-1-r3-138-htcjw
0.2312,Event,ADDED,eval-sanitize-1-r3-138.18d4a2cff8640f87,reason=Completed count=1 msg=Job completed
0.2314,Event,ADDED,eval-sanitize-1-r3-139-fqmb9.18d4a2c85a508821,"reason=FailedScheduling count=None msg=0/6 nodes are available: 6 node(s) had untolerated taint(s). no new claims to deallocate, preemption: 0/6 nodes are available: 6 Preemption is not helpful for scheduling."
0.2316,Event,ADDED,eval-sanitize-1-r3-139-fqmb9.18d4a2c9271ddcc8,"reason=FailedScheduling count=None msg=0/6 nodes are available: 1 c_wall violated: 3 conflicting context pair(s) with node memory, 5 node(s) had untolerated taint(s). no new claims to deallocate, preemption: 0/6 nodes are available: 1 No preemption victims found for incoming pod, 5 Preemption is not helpful for scheduling."
0.2319,Event,ADDED,eval-sanitize-1-r3-139-fqmb9.18d4a2c92e5d2ad5,"reason=FailedScheduling count=None msg=0/6 nodes are available: 1 c_wall violated: 3 conflicting context pair(s) with node memory, 5 node(s) had untolerated taint(s). no new claims to deallocate, preemption: 0/6 nodes are available: 1 No preemption victims found for incoming pod, 5 Preemption is not helpful for scheduling."
0.232,Event,ADDED,eval-sanitize-1-r3-139-fqmb9.18d4a2c9c9b5a44b,"reason=FailedScheduling count=None msg=0/6 nodes are available: 1 c_wall violated: 1 conflicting context pair(s) with node memory, 5 node(s) had untolerated taint(s). no new claims to deallocate, preemption: 0/6 nodes are available: 1 No preemption victims found for incoming pod, 5 Preemption is not helpful for scheduling."
0.2322,Event,ADDED,eval-sanitize-1-r3-139-fqmb9.18d4a2c9d402c954,"reason=FailedScheduling count=None msg=0/6 nodes are available: 1 c_wall violated: 1 conflicting context pair(s) with node memory, 5 node(s) had untolerated taint(s). no new claims to deallocate, preemption: 0/6 nodes are available: 1 No preemption victims found for incoming pod, 5 Preemption is not helpful for scheduling."
0.2325,Event,ADDED,eval-sanitize-1-r3-139-fqmb9.18d4a2ca742ad84a,"reason=FailedScheduling count=None msg=0/6 nodes are available: 1 c_wall violated: 1 conflicting context pair(s) with node memory, 5 node(s) had untolerated taint(s). no new claims to deallocate, preemption: 0/6 nodes are available: 1 No preemption victims found for incoming pod, 5 Preemption is not helpful for scheduling."
0.2327,Event,ADDED,eval-sanitize-1-r3-139-fqmb9.18d4a2ca7f40d4f6,"reason=FailedScheduling count=None msg=0/6 nodes are available: 1 c_wall violated: 2 conflicting context pair(s) with node memory, 5 node(s) had untolerated taint(s). no new claims to deallocate, preemption: 0/6 nodes are available: 1 No preemption victims found for incoming pod, 5 Preemption is not helpful for scheduling."
0.2329,Event,ADDED,eval-sanitize-1-r3-139-fqmb9.18d4a2ca8419c785,"reason=FailedScheduling count=None msg=0/6 nodes are available: 1 c_wall violated: 2 conflicting context pair(s) with node memory, 5 node(s) had untolerated taint(s). no new claims to deallocate, preemption: 0/6 nodes are available: 1 No preemption victims found for incoming pod, 5 Preemption is not helpful for scheduling."
0.2332,Event,ADDED,eval-sanitize-1-r3-139-fqmb9.18d4a2caec49afb0,reason=Scheduled count=None msg=Successfully assigned compute/eval-sanitize-1-r3-139-fqmb9 to kind-worker4
0.2334,Event,ADDED,eval-sanitize-1-r3-139-fqmb9.18d4a2cb0598ad14,"reason=Pulled count=1 msg=Container image ""busybox:musl"" already present on machine"
0.2336,Event,ADDED,eval-sanitize-1-r3-139-fqmb9.18d4a2cb079f5c67,reason=Created count=1 msg=Created container: task
0.2341,Event,ADDED,eval-sanitize-1-r3-139-fqmb9.18d4a2cb0be48a3d,reason=Started count=1 msg=Started container task
0.2343,Event,ADDED,eval-sanitize-1-r3-139.18d4a2c85a449470,reason=SuccessfulCreate count=1 msg=Created pod: eval-sanitize-1-r3-139-fqmb9
0.2345,Event,ADDED,eval-sanitize-1-r3-139.18d4a2d06ec1c23c,reason=Completed count=1 msg=Job completed
0.2346,Event,ADDED,eval-sanitize-1-r3-140-7ngv2.18d4a2c8958f32ba,"reason=FailedScheduling count=None msg=0/6 nodes are available: 6 node(s) had untolerated taint(s). no new claims to deallocate, preemption: 0/6 nodes are available: 6 Preemption is not helpful for scheduling."
0.2351,Event,ADDED,eval-sanitize-1-r3-140-7ngv2.18d4a2c9279092dc,"reason=FailedScheduling count=None msg=0/6 nodes are available: 1 c_wall violated: 3 conflicting context pair(s) with node memory, 5 node(s) had untolerated taint(s). no new claims to deallocate, preemption: 0/6 nodes are available: 1 No preemption victims found for incoming pod, 5 Preemption is not helpful for scheduling."
0.2353,Event,ADDED,eval-sanitize-1-r3-140-7ngv2.18d4a2c930100225,"reason=FailedScheduling count=None msg=0/6 nodes are available: 1 c_wall violated: 3 conflicting context pair(s) with node memory, 5 node(s) had untolerated taint(s). no new claims to deallocate, preemption: 0/6 nodes are available: 1 No preemption victims found for incoming pod, 5 Preemption is not helpful for scheduling."
0.2354,Event,ADDED,eval-sanitize-1-r3-140-7ngv2.18d4a2c9ca3d3317,"reason=FailedScheduling count=None msg=0/6 nodes are available: 1 c_wall violated: 1 conflicting context pair(s) with node memory, 5 node(s) had untolerated taint(s). no new claims to deallocate, preemption: 0/6 nodes are available: 1 No preemption victims found for incoming pod, 5 Preemption is not helpful for scheduling."
0.2357,Event,ADDED,eval-sanitize-1-r3-140-7ngv2.18d4a2c9d42c2ce0,"reason=FailedScheduling count=None msg=0/6 nodes are available: 1 c_wall violated: 1 conflicting context pair(s) with node memory, 5 node(s) had untolerated taint(s). no new claims to deallocate, preemption: 0/6 nodes are available: 1 No preemption victims found for incoming pod, 5 Preemption is not helpful for scheduling."
0.2358,Event,ADDED,eval-sanitize-1-r3-140-7ngv2.18d4a2ca750dbdcd,reason=Scheduled count=None msg=Successfully assigned compute/eval-sanitize-1-r3-140-7ngv2 to kind-worker3
0.236,Event,ADDED,eval-sanitize-1-r3-140-7ngv2.18d4a2ca91322b1a,"reason=Pulled count=1 msg=Container image ""busybox:musl"" already present on machine"
0.2362,Event,ADDED,eval-sanitize-1-r3-140-7ngv2.18d4a2ca9623d113,reason=Created count=1 msg=Created container: task
0.2364,Event,ADDED,eval-sanitize-1-r3-140-7ngv2.18d4a2ca98dd1041,reason=Started count=1 msg=Started container task
0.2365,Event,ADDED,eval-sanitize-1-r3-140.18d4a2c89582b184,reason=SuccessfulCreate count=1 msg=Created pod: eval-sanitize-1-r3-140-7ngv2
0.2367,Event,ADDED,eval-sanitize-1-r3-140.18d4a2d0320451d9,reason=Completed count=1 msg=Job completed
0.2368,Event,ADDED,eval-sanitize-1-r3-141-mx5nn.18d4a2c8d17c3cd5,"reason=FailedScheduling count=None msg=0/6 nodes are available: 6 node(s) had untolerated taint(s). no new claims to deallocate, preemption: 0/6 nodes are available: 6 Preemption is not helpful for scheduling."
0.237,Event,ADDED,eval-sanitize-1-r3-141-mx5nn.18d4a2c92aa2ebe3,reason=Scheduled count=None msg=Successfully assigned compute/eval-sanitize-1-r3-141-mx5nn to kind-worker
0.2372,Event,ADDED,eval-sanitize-1-r3-141-mx5nn.18d4a2c945987fca,"reason=Pulled count=1 msg=Container image ""busybox:musl"" already present on machine"
0.2373,Event,ADDED,eval-sanitize-1-r3-141-mx5nn.18d4a2c94718474c,reason=Created count=1 msg=Created container: task
0.2375,Event,ADDED,eval-sanitize-1-r3-141-mx5nn.18d4a2c94a7044ac,reason=Started count=1 msg=Started container task
0.2377,Event,ADDED,eval-sanitize-1-r3-141.18d4a2c8d16e021e,reason=SuccessfulCreate count=1 msg=Created pod: eval-sanitize-1-r3-141-mx5nn
0.2378,Event,ADDED,eval-sanitize-1-r3-141.18d4a2ce67bd72e3,reason=Completed count=1 msg=Job completed
0.238,Event,ADDED,eval-sanitize-1-r3-142-k9jpk.18d4a2c90ceaa7a9,"reason=FailedScheduling count=None msg=0/6 nodes are available: 6 node(s) had untolerated taint(s). no new claims to deallocate, preemption: 0/6 nodes are available: 6 Preemption is not helpful for scheduling."
0.2381,Event,ADDED,eval-sanitize-1-r3-142-k9jpk.18d4a2c92ad0c53d,reason=Scheduled count=None msg=Successfully assigned compute/eval-sanitize-1-r3-142-k9jpk to kind-worker
0.2383,Event,ADDED,eval-sanitize-1-r3-142-k9jpk.18d4a2c9451775c4,"reason=Pulled count=1 msg=Container image ""busybox:musl"" already present on machine"
0.2385,Event,ADDED,eval-sanitize-1-r3-142-k9jpk.18d4a2c94671012d,reason=Created count=1 msg=Created container: task
0.2386,Event,ADDED,eval-sanitize-1-r3-142-k9jpk.18d4a2c949f6b6be,reason=Started count=1 msg=Started container task
0.2388,Event,ADDED,eval-sanitize-1-r3-142.18d4a2c90ce21dd6,reason=SuccessfulCreate count=1 msg=Created pod: eval-sanitize-1-r3-142-k9jpk
0.239,Event,ADDED,eval-sanitize-1-r3-142.18d4a2ce6a384a80,reason=Completed count=1 msg=Job completed
0.2391,Event,ADDED,eval-sanitize-1-r3-143-4v5dp.18d4a2c948b176a4,"reason=FailedScheduling count=None msg=0/6 nodes are available: 1 c_wall violated: 1 conflicting context pair(s) with node memory, 5 node(s) had untolerated taint(s). no new claims to deallocate, preemption: 0/6 nodes are available: 1 No preemption victims found for incoming pod, 5 Preemption is not helpful for scheduling."
0.2393,Event,ADDED,eval-sanitize-1-r3-143-4v5dp.18d4a2c9496d6747,"reason=FailedScheduling count=None msg=0/6 nodes are available: 1 c_wall violated: 1 conflicting context pair(s) with node memory, 5 node(s) had untolerated taint(s). no new claims to deallocate, preemption: 0/6 nodes are available: 1 No preemption victims found for incoming pod, 5 Preemption is not helpful for scheduling."
0.2395,Event,ADDED,eval-sanitize-1-r3-143-4v5dp.18d4a2c9cf6174ac,reason=Scheduled count=None msg=Successfully assigned compute/eval-sanitize-1-r3-143-4v5dp to kind-worker5
0.2396,Event,ADDED,eval-sanitize-1-r3-143-4v5dp.18d4a2c9e89a5f07,"reason=Pulled count=1 msg=Container image ""busybox:musl"" already present on machine"
0.2398,Event,ADDED,eval-sanitize-1-r3-143-4v5dp.18d4a2c9e9ee0bd7,reason=Created count=1 msg=Created container: task
0.24,Event,ADDED,eval-sanitize-1-r3-143-4v5dp.18d4a2c9ee11d3a5,reason=Started count=1 msg=Started container task
0.2401,Event,ADDED,eval-sanitize-1-r3-143.18d4a2c948603f45,reason=SuccessfulCreate count=1 msg=Created pod: eval-sanitize-1-r3-143-4v5dp
0.2403,Event,ADDED,eval-sanitize-1-r3-143.18d4a2cf8ac00e2d,reason=Completed count=1 msg=Job completed
0.2404,Event,ADDED,eval-sanitize-1-r3-144-pzzkq.18d4a2c983a21f46,"reason=FailedScheduling count=None msg=0/6 nodes are available: 6 node(s) had untolerated taint(s). no new claims to deallocate, preemption: 0/6 nodes are available: 6 Preemption is not helpful for scheduling."
0.2406,Event,ADDED,eval-sanitize-1-r3-144-pzzkq.18d4a2c9cf54e27c,"reason=FailedScheduling count=None msg=0/6 nodes are available: 1 c_wall violated: 1 conflicting context pair(s) with node memory, 5 node(s) had untolerated taint(s). no new claims to deallocate, preemption: 0/6 nodes are available: 1 No preemption victims found for incoming pod, 5 Preemption is not helpful for scheduling."
0.2408,Event,ADDED,eval-sanitize-1-r3-144-pzzkq.18d4a2c9d559b64e,"reason=FailedScheduling count=None msg=0/6 nodes are available: 1 c_wall violated: 1 conflicting context pair(s) with node memory, 5 node(s) had untolerated taint(s). no new claims to deallocate, preemption: 0/6 nodes are available: 1 No preemption victims found for incoming pod, 5 Preemption is not helpful for scheduling."
0.2409,Event,ADDED,eval-sanitize-1-r3-144-pzzkq.18d4a2ca75b85883,reason=Scheduled count=None msg=Successfully assigned compute/eval-sanitize-1-r3-144-pzzkq to kind-worker3
0.2411,Event,ADDED,eval-sanitize-1-r3-144-pzzkq.18d4a2ca9330f3f7,"reason=Pulled count=1 msg=Container image ""busybox:musl"" already present on machine"
0.2412,Event,ADDED,eval-sanitize-1-r3-144-pzzkq.18d4a2ca98d48bd2,reason=Created count=1 msg=Created container: task
0.2415,Event,ADDED,eval-sanitize-1-r3-144-pzzkq.18d4a2ca9c7ca952,reason=Started count=1 msg=Started container task
0.2417,Event,ADDED,eval-sanitize-1-r3-144.18d4a2c9839a159a,reason=SuccessfulCreate count=1 msg=Created pod: eval-sanitize-1-r3-144-pzzkq
0.2419,Event,ADDED,eval-sanitize-1-r3-144.18d4a2cff846f429,reason=Completed count=1 msg=Job completed
0.242,Event,ADDED,eval-sanitize-1-r3-145-t97kj.18d4a2c9c01b1881,"reason=FailedScheduling count=None msg=0/6 nodes are available: 6 node(s) had untolerated taint(s). no new claims to deallocate, preemption: 0/6 nodes are available: 6 Preemption is not helpful for scheduling."
0.2422,Event,ADDED,eval-sanitize-1-r3-145-t97kj.18d4a2c9d04b07ae,reason=Scheduled count=None msg=Successfully assigned compute/eval-sanitize-1-r3-145-t97kj to kind-worker5
0.2424,Event,ADDED,eval-sanitize-1-r3-145-t97kj.18d4a2c9e9f200e9,"reason=Pulled count=1 msg=Container image ""busybox:musl"" already present on machine"
0.2438,Event,ADDED,eval-sanitize-1-r3-145-t97kj.18d4a2c9eb1eecc8,reason=Created count=1 msg=Created container: task
0.244,Event,ADDED,eval-sanitize-1-r3-145-t97kj.18d4a2c9ee716b6f,reason=Started count=1 msg=Started container task
0.2441,Event,ADDED,eval-sanitize-1-r3-145.18d4a2c9c01052b8,reason=SuccessfulCreate count=1 msg=Created pod: eval-sanitize-1-r3-145-t97kj
0.2443,Event,ADDED,eval-sanitize-1-r3-145.18d4a2cf4f413ae8,reason=Completed count=1 msg=Job completed
0.2444,Event,ADDED,eval-sanitize-1-r3-146-ntxjb.18d4a2c9fb452b4f,"reason=FailedScheduling count=None msg=0/6 nodes are available: 1 c_wall violated: 2 conflicting context pair(s) with node memory, 5 node(s) had untolerated taint(s). no new claims to deallocate, preemption: 0/6 nodes are available: 1 No preemption victims found for incoming pod, 5 Preemption is not helpful for scheduling."
0.2446,Event,ADDED,eval-sanitize-1-r3-146-ntxjb.18d4a2c9fbbcad91,"reason=FailedScheduling count=None msg=0/6 nodes are available: 1 c_wall violated: 2 conflicting context pair(s) with node memory, 5 node(s) had untolerated taint(s). no new claims to deallocate, preemption: 0/6 nodes are available: 1 No preemption victims found for incoming pod, 5 Preemption is not helpful for scheduling."
0.2448,Event,ADDED,eval-sanitize-1-r3-146-ntxjb.18d4a2ca7e7370b5,reason=Scheduled count=None msg=Successfully assigned compute/eval-sanitize-1-r3-146-ntxjb to kind-worker3
0.2449,Event,ADDED,eval-sanitize-1-r3-146-ntxjb.18d4a2ca9bb73d17,"reason=Pulled count=1 msg=Container image ""busybox:musl"" already present on machine"
0.2454,Event,ADDED,eval-sanitize-1-r3-146-ntxjb.18d4a2ca9d60e189,reason=Created count=1 msg=Created container: task
0.2455,Event,ADDED,eval-sanitize-1-r3-146-ntxjb.18d4a2caa16a4c0e,reason=Started count=1 msg=Started container task
0.2457,Event,ADDED,eval-sanitize-1-r3-146.18d4a2c9fb057afc,reason=SuccessfulCreate count=1 msg=Created pod: eval-sanitize-1-r3-146-ntxjb
0.2459,Event,ADDED,eval-sanitize-1-r3-146.18d4a2cff6be9d5a,reason=Completed count=1 msg=Job completed
0.2462,Event,ADDED,eval-sanitize-1-r3-147-vfbn4.18d4a2ca3672af63,"reason=FailedScheduling count=None msg=0/6 nodes are available: 6 node(s) had untolerated taint(s). no new claims to deallocate, preemption: 0/6 nodes are available: 6 Preemption is not helpful for scheduling."
0.2463,Event,ADDED,eval-sanitize-1-r3-147-vfbn4.18d4a2ca7ebfd828,reason=Scheduled count=None msg=Successfully assigned compute/eval-sanitize-1-r3-147-vfbn4 to kind-worker3
0.2465,Event,ADDED,eval-sanitize-1-r3-147-vfbn4.18d4a2ca9cb439a9,"reason=Pulled count=1 msg=Container image ""busybox:musl"" already present on machine"
0.2468,Event,ADDED,eval-sanitize-1-r3-147-vfbn4.18d4a2ca9e7a0937,reason=Created count=1 msg=Created container: task
0.2469,Event,ADDED,eval-sanitize-1-r3-147-vfbn4.18d4a2caa21e21ea,reason=Started count=1 msg=Started container task
0.2471,Event,ADDED,eval-sanitize-1-r3-147.18d4a2ca366920de,reason=SuccessfulCreate count=1 msg=Created pod: eval-sanitize-1-r3-147-vfbn4
0.2473,Event,ADDED,eval-sanitize-1-r3-147.18d4a2d032037b92,reason=Completed count=1 msg=Job completed
0.2476,Event,ADDED,eval-sanitize-1-r3-148-g68t5.18d4a2ca72cf63c5,"reason=FailedScheduling count=None msg=0/6 nodes are available: 6 node(s) had untolerated taint(s). no new claims to deallocate, preemption: 0/6 nodes are available: 6 Preemption is not helpful for scheduling."
0.2478,Event,ADDED,eval-sanitize-1-r3-148-g68t5.18d4a2ca7e643868,"reason=FailedScheduling count=None msg=0/6 nodes are available: 1 c_wall violated: 2 conflicting context pair(s) with node memory, 5 node(s) had untolerated taint(s). no new claims to deallocate, preemption: 0/6 nodes are available: 1 No preemption victims found for incoming pod, 5 Preemption is not helpful for scheduling."
0.248,Event,ADDED,eval-sanitize-1-r3-148-g68t5.18d4a2ca83d0f958,"reason=FailedScheduling count=None msg=0/6 nodes are available: 1 c_wall violated: 2 conflicting context pair(s) with node memory, 5 node(s) had untolerated taint(s). no new claims to deallocate, preemption: 0/6 nodes are available: 1 No preemption victims found for incoming pod, 5 Preemption is not helpful for scheduling."
0.2482,Event,ADDED,eval-sanitize-1-r3-148-g68t5.18d4a2caec66c485,"reason=FailedScheduling count=None msg=0/6 nodes are available: 1 c_wall violated: 2 conflicting context pair(s) with node memory, 5 node(s) had untolerated taint(s). no new claims to deallocate, preemption: 0/6 nodes are available: 1 No preemption victims found for incoming pod, 5 Preemption is not helpful for scheduling."
0.2484,Event,ADDED,eval-sanitize-1-r3-148-g68t5.18d4a2caed989d2a,"reason=FailedScheduling count=None msg=0/6 nodes are available: 1 c_wall violated: 2 conflicting context pair(s) with node memory, 5 node(s) had untolerated taint(s). no new claims to deallocate, preemption: 0/6 nodes are available: 1 No preemption victims found for incoming pod, 5 Preemption is not helpful for scheduling."
0.2486,Event,ADDED,eval-sanitize-1-r3-148-g68t5.18d4a2cb06ac0119,reason=Scheduled count=None msg=Successfully assigned compute/eval-sanitize-1-r3-148-g68t5 to kind-worker2
0.2489,Event,ADDED,eval-sanitize-1-r3-148-g68t5.18d4a2cb20d49eb6,"reason=Pulled count=1 msg=Container image ""busybox:musl"" already present on machine"
0.2491,Event,ADDED,eval-sanitize-1-r3-148-g68t5.18d4a2cb21f32467,reason=Created count=1 msg=Created container: task
0.2493,Event,ADDED,eval-sanitize-1-r3-148-g68t5.18d4a2cb2713a8a7,reason=Started count=1 msg=Started container task
0.2494,Event,ADDED,eval-sanitize-1-r3-148.18d4a2ca72bf0e4f,reason=SuccessfulCreate count=1 msg=Created pod: eval-sanitize-1-r3-148-g68t5
0.2497,Event,ADDED,eval-sanitize-1-r3-148.18d4a2d08cdac023,reason=Completed count=1 msg=Job completed
0.2498,Event,ADDED,eval-sanitize-1-r3-149-7s9v2.18d4a2caae2ae9d7,"reason=FailedScheduling count=None msg=0/6 nodes are available: 1 c_wall violated: 3 conflicting context pair(s) with node memory, 5 node(s) had untolerated taint(s). no new claims to deallocate, preemption: 0/6 nodes are available: 1 No preemption victims found for incoming pod, 5 Preemption is not helpful for scheduling."
0.25,Event,ADDED,eval-sanitize-1-r3-149-7s9v2.18d4a2caaebe5686,"reason=FailedScheduling count=None msg=0/6 nodes are available: 1 c_wall violated: 3 conflicting context pair(s) with node memory, 5 node(s) had untolerated taint(s). no new claims to deallocate, preemption: 0/6 nodes are available: 1 No preemption victims found for incoming pod, 5 Preemption is not helpful for scheduling."
0.2502,Event,ADDED,eval-sanitize-1-r3-149-7s9v2.18d4a2caec823e62,reason=Scheduled count=None msg=Successfully assigned compute/eval-sanitize-1-r3-149-7s9v2 to kind-worker4
0.2503,Event,ADDED,eval-sanitize-1-r3-149-7s9v2.18d4a2cb05d922ae,"reason=Pulled count=1 msg=Container image ""busybox:musl"" already present on machine"
0.2505,Event,ADDED,eval-sanitize-1-r3-149-7s9v2.18d4a2cb080d56ad,reason=Created count=1 msg=Created container: task
0.2507,Event,ADDED,eval-sanitize-1-r3-149-7s9v2.18d4a2cb0c0a67ff,reason=Started count=1 msg=Started container task
0.2508,Event,ADDED,eval-sanitize-1-r3-149.18d4a2caaddb654a,reason=SuccessfulCreate count=1 msg=Created pod: eval-sanitize-1-r3-149-7s9v2
0.251,Event,ADDED,eval-sanitize-1-r3-149.18d4a2d033e49063,reason=Completed count=1 msg=Job completed
0.2512,Event,ADDED,eval-sanitize-1-r3-150-kv5l5.18d4a2caea42911a,"reason=FailedScheduling count=None msg=0/6 nodes are available: 6 node(s) had untolerated taint(s). no new claims to deallocate, preemption: 0/6 nodes are available: 6 Preemption is not helpful for scheduling."
0.2513,Event,ADDED,eval-sanitize-1-r3-150-kv5l5.18d4a2caeceeba48,"reason=FailedScheduling count=None msg=0/6 nodes are available: 1 c_wall violated: 2 conflicting context pair(s) with node memory, 5 node(s) had untolerated taint(s). no new claims to deallocate, preemption: 0/6 nodes are available: 1 No preemption victims found for incoming pod, 5 Preemption is not helpful for scheduling."
0.2515,Event,ADDED,eval-sanitize-1-r3-150-kv5l5.18d4a2caedc3ef71,"reason=FailedScheduling count=None msg=0/6 nodes are available: 1 c_wall violated: 2 conflicting context pair(s) with node memory, 5 node(s) had untolerated taint(s). no new claims to deallocate, preemption: 0/6 nodes are available: 1 No preemption victims found for incoming pod, 5 Preemption is not helpful for scheduling."
0.2517,Event,ADDED,eval-sanitize-1-r3-150-kv5l5.18d4a2cb09de85f2,"reason=FailedScheduling count=None msg=0/6 nodes are available: 1 c_wall violated: 1 conflicting context pair(s) with node memory, 1 c_wall violated: 2 conflicting context pair(s) with node memory, 4 node(s) had untolerated taint(s). no new claims to deallocate, preemption: 0/6 nodes are available: 2 No preemption victims found for incoming pod, 4 Preemption is not helpful for scheduling."
0.2519,Event,ADDED,eval-sanitize-1-r3-150-kv5l5.18d4a2cb2dcc6b27,"reason=FailedScheduling count=None msg=0/6 nodes are available: 1 c_wall violated: 1 conflicting context pair(s) with node memory, 5 node(s) had untolerated taint(s). no new claims to deallocate, preemption: 0/6 nodes are available: 1 No preemption victims found for incoming pod, 5 Preemption is not helpful for scheduling."
0.252,Event,ADDED,eval-sanitize-1-r3-150-kv5l5.18d4a2d02910a061,reason=Scheduled count=None msg=Successfully assigned compute/eval-sanitize-1-r3-150-kv5l5 to kind-worker
0.2522,Event,ADDED,eval-sanitize-1-r3-150-kv5l5.18d4a2d043b08db4,"reason=Pulled count=1 msg=Container image ""busybox:musl"" already present on machine"
0.2524,Event,ADDED,eval-sanitize-1-r3-150-kv5l5.18d4a2d046c73557,reason=Created count=1 msg=Created container: task
0.2525,Event,ADDED,eval-sanitize-1-r3-150-kv5l5.18d4a2d04a7b6d2a,reason=Started count=1 msg=Started container task
0.2527,Event,ADDED,eval-sanitize-1-r3-150.18d4a2caea37102d,reason=SuccessfulCreate count=1 msg=Created pod: eval-sanitize-1-r3-150-kv5l5
0.2529,Event,ADDED,eval-sanitize-1-r3-150.18d4a2d6873cb063,reason=Completed count=1 msg=Job completed
0.253,Event,ADDED,eval-sanitize-1-r3-151-4slzv.18d4a2cb256c6b19,reason=Scheduled count=None msg=Successfully assigned compute/eval-sanitize-1-r3-151-4slzv to kind-worker4
0.2532,Event,ADDED,eval-sanitize-1-r3-151-4slzv.18d4a2cb405462f2,"reason=Pulled count=1 msg=Container image ""busybox:musl"" already present on machine"
0.2533,Event,ADDED,eval-sanitize-1-r3-151-4slzv.18d4a2cb416e5a2a,reason=Created count=1 msg=Created container: task
0.2535,Event,ADDED,eval-sanitize-1-r3-151-4slzv.18d4a2cb438c223a,reason=Started count=1 msg=Started container task
0.2537,Event,ADDED,eval-sanitize-1-r3-151.18d4a2cb24c6f0a0,reason=SuccessfulCreate count=1 msg=Created pod: eval-sanitize-1-r3-151-4slzv
0.2538,Event,ADDED,eval-sanitize-1-r3-151.18d4a2d0d216c75f,reason=Completed count=1 msg=Job completed
0.254,Event,ADDED,eval-sanitize-1-r3-152-ktls5.18d4a2cb60ce9029,"reason=FailedScheduling count=None msg=0/6 nodes are available: 6 node(s) had untolerated taint(s). no new claims to deallocate, preemption: 0/6 nodes are available: 6 Preemption is not helpful for scheduling."
0.2541,Event,ADDED,eval-sanitize-1-r3-152-ktls5.18d4a2d029b672c8,reason=Scheduled count=None msg=Successfully assigned compute/eval-sanitize-1-r3-152-ktls5 to kind-worker
0.2543,Event,ADDED,eval-sanitize-1-r3-152-ktls5.18d4a2d043cff1a6,"reason=Pulled count=1 msg=Container image ""busybox:musl"" already present on machine"
0.2546,Event,ADDED,eval-sanitize-1-r3-152-ktls5.18d4a2d047198c9c,reason=Created count=1 msg=Created container: task
0.2547,Event,ADDED,eval-sanitize-1-r3-152-ktls5.18d4a2d04ad0c8c4,reason=Started count=1 msg=Started container task
0.255,Event,ADDED,eval-sanitize-1-r3-152.18d4a2cb60bd9aea,reason=SuccessfulCreate count=1 msg=Created pod: eval-sanitize-1-r3-152-ktls5
0.2551,Event,ADDED,eval-sanitize-1-r3-152.18d4a2d6909212ee,reason=Completed count=1 msg=Job completed
0.2553,Event,ADDED,eval-sanitize-1-r3-153-ljqsr.18d4a2cb9c87d983,"reason=FailedScheduling count=None msg=0/6 nodes are available: 6 node(s) had untolerated taint(s). no new claims to deallocate, preemption: 0/6 nodes are available: 6 Preemption is not helpful for scheduling."
0.2554,Event,ADDED,eval-sanitize-1-r3-153-ljqsr.18d4a2d029929091,"reason=FailedScheduling count=None msg=0/6 nodes are available: 1 c_wall violated: 1 conflicting context pair(s) with node memory, 5 node(s) had untolerated taint(s). no new claims to deallocate, preemption: 0/6 nodes are available: 1 No preemption victims found for incoming pod, 5 Preemption is not helpful for scheduling."
0.2556,Event,ADDED,eval-sanitize-1-r3-153-ljqsr.18d4a2d0646dbb91,"reason=FailedScheduling count=None msg=0/6 nodes are available: 1 c_wall violated: 1 conflicting context pair(s) with node memory, 1 c_wall violated: 2 conflicting context pair(s) with node memory, 1 c_wall violated: 3 conflicting context pair(s) with node memory, 3 node(s) had untolerated taint(s). no new claims to deallocate, preemption: 0/6 nodes are available: 3 No preemption victims found for incoming pod, 3 Preemption is not helpful for scheduling."
0.2558,Event,ADDED,eval-sanitize-1-r3-153-ljqsr.18d4a2d07645bd41,"reason=FailedScheduling count=None msg=0/6 nodes are available: 1 c_wall violated: 2 conflicting context pair(s) with node memory, 5 node(s) had untolerated taint(s). no new claims to deallocate, preemption: 0/6 nodes are available: 1 No preemption victims found for incoming pod, 5 Preemption is not helpful for scheduling."
0.256,Event,ADDED,eval-sanitize-1-r3-153-ljqsr.18d4a2d07b0bca59,"reason=FailedScheduling count=None msg=0/6 nodes are available: 1 c_wall violated: 2 conflicting context pair(s) with node memory, 5 node(s) had untolerated taint(s). no new claims to deallocate, preemption: 0/6 nodes are available: 1 No preemption victims found for incoming pod, 5 Preemption is not helpful for scheduling."
0.2561,Event,ADDED,eval-sanitize-1-r3-153-ljqsr.18d4a2d117f758d2,"reason=FailedScheduling count=None msg=0/6 nodes are available: 1 c_wall violated: 1 conflicting context pair(s) with node memory, 5 node(s) had untolerated taint(s). no new claims to deallocate, preemption: 0/6 nodes are available: 1 No preemption victims found for incoming pod, 5 Preemption is not helpful for scheduling."
0.2563,Event,ADDED,eval-sanitize-1-r3-153-ljqsr.18d4a2d11d171f3a,"reason=FailedScheduling count=None msg=0/6 nodes are available: 1 c_wall violated: 1 conflicting context pair(s) with node memory, 5 node(s) had untolerated taint(s). no new claims to deallocate, preemption: 0/6 nodes are available: 1 No preemption victims found for incoming pod, 5 Preemption is not helpful for scheduling."
0.2565,Event,ADDED,eval-sanitize-1-r3-153-ljqsr.18d4a2d158601d27,"reason=FailedScheduling count=None msg=0/6 nodes are available: 1 c_wall violated: 1 conflicting context pair(s) with node memory, 1 c_wall violated: 2 conflicting context pair(s) with node memory, 4 node(s) had untolerated taint(s). no new claims to deallocate, preemption: 0/6 nodes are available: 2 No preemption victims found for incoming pod, 4 Preemption is not helpful for scheduling."
0.2566,Event,ADDED,eval-sanitize-1-r3-153-ljqsr.18d4a2d15d95a04c,"reason=FailedScheduling count=None msg=0/6 nodes are available: 1 c_wall violated: 1 conflicting context pair(s) with node memory, 1 c_wall violated: 2 conflicting context pair(s) with node memory, 4 node(s) had untolerated taint(s). no new claims to deallocate, preemption: 0/6 nodes are available: 2 No preemption victims found for incoming pod, 4 Preemption is not helpful for scheduling."
0.2568,Event,ADDED,eval-sanitize-1-r3-153-ljqsr.18d4a2d1768596ff,"reason=FailedScheduling count=None msg=0/6 nodes are available: 1 c_wall violated: 2 conflicting context pair(s) with node memory, 5 node(s) had untolerated taint(s). no new claims to deallocate, preemption: 0/6 nodes are available: 1 No preemption victims found for incoming pod, 5 Preemption is not helpful for scheduling."
0.257,Event,ADDED,eval-sanitize-1-r3-153-ljqsr.18d4a2d5aca71959,reason=Scheduled count=None msg=Successfully assigned compute/eval-sanitize-1-r3-153-ljqsr to kind-worker
0.2572,Event,ADDED,eval-sanitize-1-r3-153-ljqsr.18d4a2d5c9f12169,"reason=Pulled count=1 msg=Container image ""busybox:musl"" already present on machine"
0.2573,Event,ADDED,eval-sanitize-1-r3-153-ljqsr.18d4a2d5cc94da55,reason=Created count=1 msg=Created container: task
0.2575,Event,ADDED,eval-sanitize-1-r3-153-ljqsr.18d4a2d5cee5147a,reason=Started count=1 msg=Started container task
0.2577,Event,ADDED,eval-sanitize-1-r3-153.18d4a2cb9c7c4965,reason=SuccessfulCreate count=1 msg=Created pod: eval-sanitize-1-r3-153-ljqsr
0.2578,Event,ADDED,eval-sanitize-1-r3-153.18d4a2db61c4642b,reason=Completed count=1 msg=Job completed
0.258,Event,ADDED,eval-sanitize-1-r3-154-c6lk6.18d4a2cbd7aa65d5,"reason=FailedScheduling count=None msg=0/6 nodes are available: 6 node(s) had untolerated taint(s). no new claims to deallocate, preemption: 0/6 nodes are available: 6 Preemption is not helpful for scheduling."
0.2581,Event,ADDED,eval-sanitize-1-r3-154-c6lk6.18d4a2d02a74b4fd,"reason=FailedScheduling count=None msg=0/6 nodes are available: 1 c_wall violated: 1 conflicting context pair(s) with node memory, 5 node(s) had untolerated taint(s). no new claims to deallocate, preemption: 0/6 nodes are available: 1 No preemption victims found for incoming pod, 5 Preemption is not helpful for scheduling."
0.2583,Event,ADDED,eval-sanitize-1-r3-154-c6lk6.18d4a2d06a4ef01a,"reason=FailedScheduling count=None msg=0/6 nodes are available: 1 c_wall violated: 1 conflicting context pair(s) with node memory, 1 c_wall violated: 2 conflicting context pair(s) with node memory, 1 c_wall violated: 3 conflicting context pair(s) with node memory, 3 node(s) had untolerated taint(s). no new claims to deallocate, preemption: 0/6 nodes are available: 3 No preemption victims found for incoming pod, 3 Preemption is not helpful for scheduling."
0.2584,Event,ADDED,eval-sanitize-1-r3-154-c6lk6.18d4a2d076fa66b8,"reason=FailedScheduling count=None msg=0/6 nodes are available: 1 c_wall violated: 2 conflicting context pair(s) with node memory, 5 node(s) had untolerated taint(s). no new claims to deallocate, preemption: 0/6 nodes are available: 1 No preemption victims found for incoming pod, 5 Preemption is not helpful for scheduling."
0.2586,Event,ADDED,eval-sanitize-1-r3-154-c6lk6.18d4a2d07bf3ba4f,"reason=FailedScheduling count=None msg=0/6 nodes are available: 1 c_wall violated: 2 conflicting context pair(s) with node memory, 5 node(s) had untolerated taint(s). no new claims to deallocate, preemption: 0/6 nodes are available: 1 No preemption victims found for incoming pod, 5 Preemption is not helpful for scheduling."
0.2588,Event,ADDED,eval-sanitize-1-r3-154-c6lk6.18d4a2d11769f954,"reason=FailedScheduling count=None msg=0/6 nodes are available: 1 c_wall violated: 1 conflicting context pair(s) with node memory, 5 node(s) had untolerated taint(s). no new claims to deallocate, preemption: 0/6 nodes are available: 1 No preemption victims found for incoming pod, 5 Preemption is not helpful for scheduling."
0.2589,Event,ADDED,eval-sanitize-1-r3-154-c6lk6.18d4a2d11ce36979,"reason=FailedScheduling count=None msg=0/6 nodes are available: 1 c_wall violated: 1 conflicting context pair(s) with node memory, 5 node(s) had untolerated taint(s). no new claims to deallocate, preemption: 0/6 nodes are available: 1 No preemption victims found for incoming pod, 5 Preemption is not helpful for scheduling."
0.2591,Event,ADDED,eval-sanitize-1-r3-154-c6lk6.18d4a2d15913be1b,"reason=FailedScheduling count=None msg=0/6 nodes are available: 1 c_wall violated: 1 conflicting context pair(s) with node memory, 1 c_wall violated: 2 conflicting context pair(s) with node memory, 4 node(s) had untolerated taint(s). no new claims to deallocate, preemption: 0/6 nodes are available: 2 No preemption victims found for incoming pod, 4 Preemption is not helpful for scheduling."
0.2593,Event,ADDED,eval-sanitize-1-r3-154-c6lk6.18d4a2d176b47b26,"reason=FailedScheduling count=None msg=0/6 nodes are available: 1 c_wall violated: 2 conflicting context pair(s) with node memory, 5 node(s) had untolerated taint(s). no new claims to deallocate, preemption: 0/6 nodes are available: 1 No preemption victims found for incoming pod, 5 Preemption is not helpful for scheduling."
0.2595,Event,ADDED,eval-sanitize-1-r3-154-c6lk6.18d4a2d5b0b7cd92,reason=Scheduled count=None msg=Successfully assigned compute/eval-sanitize-1-r3-154-c6lk6 to kind-worker
0.2596,Event,ADDED,eval-sanitize-1-r3-154-c6lk6.18d4a2d5c7b9e9af,"reason=Pulled count=1 msg=Container image ""busybox:musl"" already present on machine"
0.2598,Event,ADDED,eval-sanitize-1-r3-154-c6lk6.18d4a2d5c965f501,reason=Created count=1 msg=Created container: task
0.26,Event,ADDED,eval-sanitize-1-r3-154-c6lk6.18d4a2d5cc990ab4,reason=Started count=1 msg=Started container task
0.2601,Event,ADDED,eval-sanitize-1-r3-154.18d4a2cbd7a0543b,reason=SuccessfulCreate count=1 msg=Created pod: eval-sanitize-1-r3-154-c6lk6
0.2603,Event,ADDED,eval-sanitize-1-r3-154.18d4a2db61cb6856,reason=Completed count=1 msg=Job completed
0.2605,Event,ADDED,eval-sanitize-1-r3-155-q444d.18d4a2cc13e66fcc,"reason=FailedScheduling count=None msg=0/6 nodes are available: 6 node(s) had untolerated taint(s). no new claims to deallocate, preemption: 0/6 nodes are available: 6 Preemption is not helpful for scheduling."
0.2606,Event,ADDED,eval-sanitize-1-r3-155-q444d.18d4a2d02c643d7a,reason=Scheduled count=None msg=Successfully assigned compute/eval-sanitize-1-r3-155-q444d to kind-worker
0.2608,Event,ADDED,eval-sanitize-1-r3-155-q444d.18d4a2d049d22b26,"reason=Pulled count=1 msg=Container image ""busybox:musl"" already present on machine"
0.261,Event,ADDED,eval-sanitize-1-r3-155-q444d.18d4a2d04d21c61e,reason=Created count=1 msg=Created container: task
0.2611,Event,ADDED,eval-sanitize-1-r3-155-q444d.18d4a2d0529f9766,reason=Started count=1 msg=Started container task
0.2613,Event,ADDED,eval-sanitize-1-r3-155.18d4a2cc13d7bd9b,reason=SuccessfulCreate count=1 msg=Created pod: eval-sanitize-1-r3-155-q444d
0.2616,Event,ADDED,eval-sanitize-1-r3-155.18d4a2d588f5c775,reason=Completed count=1 msg=Job completed
0.2617,Event,ADDED,eval-sanitize-1-r3-156-ndfv6.18d4a2cc4f826843,"reason=FailedScheduling count=None msg=0/6 nodes are available: 6 node(s) had untolerated taint(s). no new claims to deallocate, preemption: 0/6 nodes are available: 6 Preemption is not helpful for scheduling."
0.2619,Event,ADDED,eval-sanitize-1-r3-156-ndfv6.18d4a2d02c4b22d6,"reason=FailedScheduling count=None msg=0/6 nodes are available: 1 c_wall violated: 1 conflicting context pair(s) with node memory, 5 node(s) had untolerated taint(s). no new claims to deallocate, preemption: 0/6 nodes are available: 1 No preemption victims found for incoming pod, 5 Preemption is not helpful for scheduling."
0.2621,Event,ADDED,eval-sanitize-1-r3-156-ndfv6.18d4a2d070d5c54d,reason=Scheduled count=None msg=Successfully assigned compute/eval-sanitize-1-r3-156-ndfv6 to kind-worker5
0.2623,Event,ADDED,eval-sanitize-1-r3-156-ndfv6.18d4a2d08bc7d0aa,"reason=Pulled count=1 msg=Container image ""busybox:musl"" already present on machine"
0.2624,Event,ADDED,eval-sanitize-1-r3-156-ndfv6.18d4a2d08d5da773,reason=Created count=1 msg=Created container: task
0.2626,Event,ADDED,eval-sanitize-1-r3-156-ndfv6.18d4a2d08fce263f,reason=Started count=1 msg=Started container task
0.2628,Event,ADDED,eval-sanitize-1-r3-156.18d4a2cc4f788c40,reason=SuccessfulCreate count=1 msg=Created pod: eval-sanitize-1-r3-156-ndfv6
0.2629,Event,ADDED,eval-sanitize-1-r3-156.18d4a2d75eeeae22,reason=Completed count=1 msg=Job completed
0.2631,Event,ADDED,eval-sanitize-1-r3-157-k7ff5.18d4a2ccc4138d73,"reason=FailedScheduling count=None msg=0/6 nodes are available: 6 node(s) had untolerated taint(s). no new claims to deallocate, preemption: 0/6 nodes are available: 6 Preemption is not helpful for scheduling."
0.2632,Event,ADDED,eval-sanitize-1-r3-157-k7ff5.18d4a2d02eceefcf,reason=Scheduled count=None msg=Successfully assigned compute/eval-sanitize-1-r3-157-k7ff5 to kind-worker
0.2634,Event,ADDED,eval-sanitize-1-r3-157-k7ff5.18d4a2d04b537222,"reason=Pulled count=1 msg=Container image ""busybox:musl"" already present on machine"
0.2636,Event,ADDED,eval-sanitize-1-r3-157-k7ff5.18d4a2d04fa47e43,reason=Created count=1 msg=Created container: task
0.2637,Event,ADDED,eval-sanitize-1-r3-157-k7ff5.18d4a2d0529f9774,reason=Started count=1 msg=Started container task
0.2639,Event,ADDED,eval-sanitize-1-r3-157.18d4a2ccc4049fa4,reason=SuccessfulCreate count=1 msg=Created pod: eval-sanitize-1-r3-157-k7ff5
0.2641,Event,ADDED,eval-sanitize-1-r3-157.18d4a2d589443996,reason=Completed count=1 msg=Job completed
0.2642,Event,ADDED,eval-sanitize-1-r3-158-xpp5m.18d4a2ccc74d8d0d,"reason=FailedScheduling count=None msg=0/6 nodes are available: 6 node(s) had untolerated taint(s). no new claims to deallocate, preemption: 0/6 nodes are available: 6 Preemption is not helpful for scheduling."
0.2644,Event,ADDED,eval-sanitize-1-r3-158-xpp5m.18d4a2d0303067f6,reason=Scheduled count=None msg=Successfully assigned compute/eval-sanitize-1-r3-158-xpp5m to kind-worker5
0.2646,Event,ADDED,eval-sanitize-1-r3-158-xpp5m.18d4a2d04b721963,"reason=Pulled count=1 msg=Container image ""busybox:musl"" already present on machine"
0.2647,Event,ADDED,eval-sanitize-1-r3-158-xpp5m.18d4a2d04e554cc6,reason=Created count=1 msg=Created container: task
0.2649,Event,ADDED,eval-sanitize-1-r3-158-xpp5m.18d4a2d052035dd0,reason=Started count=1 msg=Started container task
0.2651,Event,ADDED,eval-sanitize-1-r3-158.18d4a2ccc7437f01,reason=SuccessfulCreate count=1 msg=Created pod: eval-sanitize-1-r3-158-xpp5m
0.2652,Event,ADDED,eval-sanitize-1-r3-158.18d4a2d594044155,reason=Completed count=1 msg=Job completed
0.2654,Event,ADDED,eval-sanitize-1-r3-159-d46hg.18d4a2cd01d87051,"reason=FailedScheduling count=None msg=0/6 nodes are available: 6 node(s) had untolerated taint(s). no new claims to deallocate, preemption: 0/6 nodes are available: 6 Preemption is not helpful for scheduling."
0.2655,Event,ADDED,eval-sanitize-1-r3-159-d46hg.18d4a2d032774cdb,reason=Scheduled count=None msg=Successfully assigned compute/eval-sanitize-1-r3-159-d46hg to kind-worker5
0.2657,Event,ADDED,eval-sanitize-1-r3-159-d46hg.18d4a2d053af7767,"reason=Pulled count=1 msg=Container image ""busybox:musl"" already present on machine"
0.2659,Event,ADDED,eval-sanitize-1-r3-159-d46hg.18d4a2d055358789,reason=Created count=1 msg=Created container: task
0.266,Event,ADDED,eval-sanitize-1-r3-159-d46hg.18d4a2d05843e20a,reason=Started count=1 msg=Started container task
0.2662,Event,ADDED,eval-sanitize-1-r3-159.18d4a2cd01cdee19,reason=SuccessfulCreate count=1 msg=Created pod: eval-sanitize-1-r3-159-d46hg
0.2664,Event,ADDED,eval-sanitize-1-r3-159.18d4a2d6e2d8294e,reason=Completed count=1 msg=Job completed
0.2665,Event,ADDED,eval-sanitize-1-r3-160-lfszb.18d4a2cd3d5bf7e1,"reason=FailedScheduling count=None msg=0/6 nodes are available: 6 node(s) had untolerated taint(s). no new claims to deallocate, preemption: 0/6 nodes are available: 6 Preemption is not helpful for scheduling."
0.2666,Event,ADDED,eval-sanitize-1-r3-160-lfszb.18d4a2d037fb6b9b,reason=Scheduled count=None msg=Successfully assigned compute/eval-sanitize-1-r3-160-lfszb to kind-worker5
0.2668,Event,ADDED,eval-sanitize-1-r3-160-lfszb.18d4a2d0554b9dc1,"reason=Pulled count=1 msg=Container image ""busybox:musl"" already present on machine"
0.267,Event,ADDED,eval-sanitize-1-r3-160-lfszb.18d4a2d056cb0f20,reason=Created count=1 msg=Created container: task
0.2672,Event,ADDED,eval-sanitize-1-r3-160-lfszb.18d4a2d059f86b92,reason=Started count=1 msg=Started container task
0.2673,Event,ADDED,eval-sanitize-1-r3-160.18d4a2cd3d4bd555,reason=SuccessfulCreate count=1 msg=Created pod: eval-sanitize-1-r3-160-lfszb
0.2675,Event,ADDED,eval-sanitize-1-r3-160.18d4a2d6c5f9845d,reason=Completed count=1 msg=Job completed
0.2676,Event,ADDED,eval-sanitize-1-r3-161-s62rx.18d4a2cd798c38a1,"reason=FailedScheduling count=None msg=0/6 nodes are available: 6 node(s) had untolerated taint(s). no new claims to deallocate, preemption: 0/6 nodes are available: 6 Preemption is not helpful for scheduling."
0.2678,Event,ADDED,eval-sanitize-1-r3-161-s62rx.18d4a2d0384b8bd0,reason=Scheduled count=None msg=Successfully assigned compute/eval-sanitize-1-r3-161-s62rx to kind-worker
0.2679,Event,ADDED,eval-sanitize-1-r3-161-s62rx.18d4a2d05809f7d0,"reason=Pulled count=1 msg=Container image ""busybox:musl"" already present on machine"
0.2681,Event,ADDED,eval-sanitize-1-r3-161-s62rx.18d4a2d05ae09960,reason=Created count=1 msg=Created container: task
0.2683,Event,ADDED,eval-sanitize-1-r3-161-s62rx.18d4a2d05fc95319,reason=Started count=1 msg=Started container task
0.2684,Event,ADDED,eval-sanitize-1-r3-161.18d4a2cd797d32fe,reason=SuccessfulCreate count=1 msg=Created pod: eval-sanitize-1-r3-161-s62rx
0.2686,Event,ADDED,eval-sanitize-1-r3-161.18d4a2d7414ce91d,reason=Completed count=1 msg=Job completed
0.2689,Event,ADDED,eval-sanitize-1-r3-162-m667w.18d4a2cdb51c4162,"reason=FailedScheduling count=None msg=0/6 nodes are available: 6 node(s) had untolerated taint(s). no new claims to deallocate, preemption: 0/6 nodes are available: 6 Preemption is not helpful for scheduling."
0.2691,Event,ADDED,eval-sanitize-1-r3-162-m667w.18d4a2d03abec3b7,reason=Scheduled count=None msg=Successfully assigned compute/eval-sanitize-1-r3-162-m667w to kind-worker5
0.2693,Event,ADDED,eval-sanitize-1-r3-162-m667w.18d4a2d056c53735,"reason=Pulled count=1 msg=Container image ""busybox:musl"" already present on machine"
0.2696,Event,ADDED,eval-sanitize-1-r3-162-m667w.18d4a2d058c62ab7,reason=Created count=1 msg=Created container: task
0.2698,Event,ADDED,eval-sanitize-1-r3-162-m667w.18d4a2d05f951eaf,reason=Started count=1 msg=Started container task
0.2699,Event,ADDED,eval-sanitize-1-r3-162.18d4a2cdb50870f9,reason=SuccessfulCreate count=1 msg=Created pod: eval-sanitize-1-r3-162-m667w
0.2701,Event,ADDED,eval-sanitize-1-r3-162.18d4a2d6e08a1249,reason=Completed count=1 msg=Job completed
0.2704,Event,ADDED,eval-sanitize-1-r3-163-7jfc5.18d4a2cdf0aa5807,"reason=FailedScheduling count=None msg=0/6 nodes are available: 6 node(s) had untolerated taint(s). no new claims to deallocate, preemption: 0/6 nodes are available: 6 Preemption is not helpful for scheduling."
0.2707,Event,ADDED,eval-sanitize-1-r3-163-7jfc5.18d4a2d03b1d62db,reason=Scheduled count=None msg=Successfully assigned compute/eval-sanitize-1-r3-163-7jfc5 to kind-worker
0.2708,Event,ADDED,eval-sanitize-1-r3-163-7jfc5.18d4a2d05889a0fc,"reason=Pulled count=1 msg=Container image ""busybox:musl"" already present on machine"
0.271,Event,ADDED,eval-sanitize-1-r3-163-7jfc5.18d4a2d05c8e5db3,reason=Created count=1 msg=Created container: task
0.2713,Event,ADDED,eval-sanitize-1-r3-163-7jfc5.18d4a2d05f239f84,reason=Started count=1 msg=Started container task
0.2715,Event,ADDED,eval-sanitize-1-r3-163.18d4a2cdf08ccbfc,reason=SuccessfulCreate count=1 msg=Created pod: eval-sanitize-1-r3-163-7jfc5
0.2717,Event,ADDED,eval-sanitize-1-r3-163.18d4a2d58919117f,reason=Completed count=1 msg=Job completed
0.272,Event,ADDED,eval-sanitize-1-r3-164-dhd5k.18d4a2ce2cb7cc6f,"reason=FailedScheduling count=None msg=0/6 nodes are available: 6 node(s) had untolerated taint(s). no new claims to deallocate, preemption: 0/6 nodes are available: 6 Preemption is not helpful for scheduling."
0.2721,Event,ADDED,eval-sanitize-1-r3-164-dhd5k.18d4a2d03cb32cad,reason=Scheduled count=None msg=Successfully assigned compute/eval-sanitize-1-r3-164-dhd5k to kind-worker
0.2723,Event,ADDED,eval-sanitize-1-r3-164-dhd5k.18d4a2d05855a8d0,"reason=Pulled count=1 msg=Container image ""busybox:musl"" already present on machine"
0.2725,Event,ADDED,eval-sanitize-1-r3-164-dhd5k.18d4a2d05c21954e,reason=Created count=1 msg=Created container: task
0.2727,Event,ADDED,eval-sanitize-1-r3-164-dhd5k.18d4a2d05ea419e5,reason=Started count=1 msg=Started container task
0.2729,Event,ADDED,eval-sanitize-1-r3-164.18d4a2ce2c9e8f2a,reason=SuccessfulCreate count=1 msg=Created pod: eval-sanitize-1-r3-164-dhd5k
0.273,Event,ADDED,eval-sanitize-1-r3-164.18d4a2d67feb8461,reason=Completed count=1 msg=Job completed
0.2733,Event,ADDED,eval-sanitize-1-r3-165-gh9dj.18d4a2ce67f3292b,"reason=FailedScheduling count=None msg=0/6 nodes are available: 6 node(s) had untolerated taint(s). no new claims to deallocate, preemption: 0/6 nodes are available: 6 Preemption is not helpful for scheduling."
0.2734,Event,ADDED,eval-sanitize-1-r3-165-gh9dj.18d4a2d043fa031c,"reason=FailedScheduling count=None msg=0/6 nodes are available: 2 c_wall violated: 1 conflicting context pair(s) with node memory, 4 node(s) had untolerated taint(s). no new claims to deallocate, preemption: 0/6 nodes are available: 2 No preemption victims found for incoming pod, 4 Preemption is not helpful for scheduling."
0.2736,Event,ADDED,eval-sanitize-1-r3-165-gh9dj.18d4a2d0767721f8,reason=Scheduled count=None msg=Successfully assigned compute/eval-sanitize-1-r3-165-gh9dj to kind-worker2
0.2737,Event,ADDED,eval-sanitize-1-r3-165-gh9dj.18d4a2d08f021d23,"reason=Pulled count=1 msg=Container image ""busybox:musl"" already present on machine"
0.2739,Event,ADDED,eval-sanitize-1-r3-165-gh9dj.18d4a2d09061b12e,reason=Created count=1 msg=Created container: task
0.2741,Event,ADDED,eval-sanitize-1-r3-165-gh9dj.18d4a2d094d956f1,reason=Started count=1 msg=Started container task
0.2742,Event,ADDED,eval-sanitize-1-r3-165.18d4a2ce67e45d87,reason=SuccessfulCreate count=1 msg=Created pod: eval-sanitize-1-r3-165-gh9dj
0.2744,Event,ADDED,eval-sanitize-1-r3-165.18d4a2d76b050e0d,reason=Completed count=1 msg=Job completed
0.2749,Event,ADDED,eval-sanitize-1-r3-166-9zdtn.18d4a2cea30d226a,"reason=FailedScheduling count=None msg=0/6 nodes are available: 6 node(s) had untolerated taint(s). no new claims to deallocate, preemption: 0/6 nodes are available: 6 Preemption is not helpful for scheduling."
0.2751,Event,ADDED,eval-sanitize-1-r3-166-9zdtn.18d4a2d045f1f98a,reason=Scheduled count=None msg=Successfully assigned compute/eval-sanitize-1-r3-166-9zdtn to kind-worker
0.2752,Event,ADDED,eval-sanitize-1-r3-166-9zdtn.18d4a2d0645010ec,"reason=Pulled count=1 msg=Container image ""busybox:musl"" already present on machine"
0.2755,Event,ADDED,eval-sanitize-1-r3-166-9zdtn.18d4a2d066c33348,reason=Created count=1 msg=Created container: task
0.2756,Event,ADDED,eval-sanitize-1-r3-166-9zdtn.18d4a2d06ae52d9d,reason=Started count=1 msg=Started container task
0.2758,Event,ADDED,eval-sanitize-1-r3-166.18d4a2cea2fe7440,reason=SuccessfulCreate count=1 msg=Created pod: eval-sanitize-1-r3-166-9zdtn
0.276,Event,ADDED,eval-sanitize-1-r3-166.18d4a2d7303f0e9a,reason=Completed count=1 msg=Job completed
0.2761,Event,ADDED,eval-sanitize-1-r3-167-k4s2d.18d4a2cededa3c41,"reason=FailedScheduling count=None msg=0/6 nodes are available: 6 node(s) had untolerated taint(s). no new claims to deallocate, preemption: 0/6 nodes are available: 6 Preemption is not helpful for scheduling."
0.2763,Event,ADDED,eval-sanitize-1-r3-167-k4s2d.18d4a2d04a8ee4c2,reason=Scheduled count=None msg=Successfully assigned compute/eval-sanitize-1-r3-167-k4s2d to kind-worker
0.2765,Event,ADDED,eval-sanitize-1-r3-167-k4s2d.18d4a2d0657782f4,"reason=Pulled count=1 msg=Container image ""busybox:musl"" already present on machine"
0.2766,Event,ADDED,eval-sanitize-1-r3-167-k4s2d.18d4a2d0673f12f0,reason=Created count=1 msg=Created container: task
0.2768,Event,ADDED,eval-sanitize-1-r3-167-k4s2d.18d4a2d06ae52d93,reason=Started count=1 msg=Started container task
0.277,Event,ADDED,eval-sanitize-1-r3-167.18d4a2cedecac611,reason=SuccessfulCreate count=1 msg=Created pod: eval-sanitize-1-r3-167-k4s2d
0.2771,Event,ADDED,eval-sanitize-1-r3-167.18d4a2d7414ce90e,reason=Completed count=1 msg=Job completed
0.2773,Event,ADDED,eval-sanitize-1-r3-168-7b62k.18d4a2cf1aa9d903,"reason=FailedScheduling count=None msg=0/6 nodes are available: 6 node(s) had untolerated taint(s). no new claims to deallocate, preemption: 0/6 nodes are available: 6 Preemption is not helpful for scheduling."
0.2775,Event,ADDED,eval-sanitize-1-r3-168-7b62k.18d4a2d04df74cfc,reason=Scheduled count=None msg=Successfully assigned compute/eval-sanitize-1-r3-168-7b62k to kind-worker2
0.2776,Event,ADDED,eval-sanitize-1-r3-168-7b62k.18d4a2d069b50bd0,"reason=Pulled count=1 msg=Container image ""busybox:musl"" already present on machine"
0.2778,Event,ADDED,eval-sanitize-1-r3-168-7b62k.18d4a2d06bdb48e8,reason=Created count=1 msg=Created container: task
0.278,Event,ADDED,eval-sanitize-1-r3-168-7b62k.18d4a2d06f15a223,reason=Started count=1 msg=Started container task
0.2781,Event,ADDED,eval-sanitize-1-r3-168.18d4a2cf1a9a57e3,reason=SuccessfulCreate count=1 msg=Created pod: eval-sanitize-1-r3-168-7b62k
0.2783,Event,ADDED,eval-sanitize-1-r3-168.18d4a2d709821e65,reason=Completed count=1 msg=Job completed
0.2785,Event,ADDED,eval-sanitize-1-r3-169-8gzqj.18d4a2cf684da73a,"reason=FailedScheduling count=None msg=0/6 nodes are available: 6 node(s) had untolerated taint(s). no new claims to deallocate, preemption: 0/6 nodes are available: 6 Preemption is not helpful for scheduling."
0.2786,Event,ADDED,eval-sanitize-1-r3-169-8gzqj.18d4a2d04fdb5576,reason=Scheduled count=None msg=Successfully assigned compute/eval-sanitize-1-r3-169-8gzqj to kind-worker
0.2788,Event,ADDED,eval-sanitize-1-r3-169-8gzqj.18d4a2d069fc7f7c,"reason=Pulled count=1 msg=Container image ""busybox:musl"" already present on machine"
0.2789,Event,ADDED,eval-sanitize-1-r3-169-8gzqj.18d4a2d06c36a861,reason=Created count=1 msg=Created container: task
0.2792,Event,ADDED,eval-sanitize-1-r3-169-8gzqj.18d4a2d06f1536ae,reason=Started count=1 msg=Started container task
0.2794,Event,ADDED,eval-sanitize-1-r3-169.18d4a2cf683e4aeb,reason=SuccessfulCreate count=1 msg=Created pod: eval-sanitize-1-r3-169-8gzqj
0.2796,Event,ADDED,eval-sanitize-1-r3-169.18d4a2d74e949ebe,reason=Completed count=1 msg=Job completed
0.2797,Event,ADDED,eval-sanitize-1-r3-170-fdl4r.18d4a2cf918a31b8,"reason=FailedScheduling count=None msg=0/6 nodes are available: 6 node(s) had untolerated taint(s). no new claims to deallocate, preemption: 0/6 nodes are available: 6 Preemption is not helpful for scheduling."
0.28,Event,ADDED,eval-sanitize-1-r3-170-fdl4r.18d4a2d053e7b2f0,reason=Scheduled count=None msg=Successfully assigned compute/eval-sanitize-1-r3-170-fdl4r to kind-worker5
0.2801,Event,ADDED,eval-sanitize-1-r3-170-fdl4r.18d4a2d06ea79def,"reason=Pulled count=1 msg=Container image ""busybox:musl"" already present on machine"
0.2803,Event,ADDED,eval-sanitize-1-r3-170-fdl4r.18d4a2d071c03cf1,reason=Created count=1 msg=Created container: task
0.2805,Event,ADDED,eval-sanitize-1-r3-170-fdl4r.18d4a2d074cc460c,reason=Started count=1 msg=Started container task
0.2807,Event,ADDED,eval-sanitize-1-r3-170.18d4a2cf917ddaa1,reason=SuccessfulCreate count=1 msg=Created pod: eval-sanitize-1-r3-170-fdl4r
0.2808,Event,ADDED,eval-sanitize-1-r3-170.18d4a2d75165284a,reason=Completed count=1 msg=Job completed
0.281,Event,ADDED,eval-sanitize-1-r3-171-mhjwj.18d4a2cfcd2dee2b,"reason=FailedScheduling count=None msg=0/6 nodes are available: 6 node(s) had untolerated taint(s). no new claims to deallocate, preemption: 0/6 nodes are available: 6 Preemption is not helpful for scheduling."
0.2811,Event,ADDED,eval-sanitize-1-r3-171-mhjwj.18d4a2d059da9d46,reason=Scheduled count=None msg=Successfully assigned compute/eval-sanitize-1-r3-171-mhjwj to kind-worker
0.2813,Event,ADDED,eval-sanitize-1-r3-171-mhjwj.18d4a2d07549de06,"reason=Pulled count=1 msg=Container image ""busybox:musl"" already present on machine"
0.2815,Event,ADDED,eval-sanitize-1-r3-171-mhjwj.18d4a2d0772fad45,reason=Created count=1 msg=Created container: task
0.2816,Event,ADDED,eval-sanitize-1-r3-171-mhjwj.18d4a2d079e1f07b,reason=Started count=1 msg=Started container task
0.2818,Event,ADDED,eval-sanitize-1-r3-171.18d4a2cfcd1fc25a,reason=SuccessfulCreate count=1 msg=Created pod: eval-sanitize-1-r3-171-mhjwj
0.282,Event,ADDED,eval-sanitize-1-r3-171.18d4a2d73025c880,reason=Completed count=1 msg=Job completed
0.2821,Event,ADDED,eval-sanitize-1-r3-172-w2kmh.18d4a2d0093fb927,"reason=FailedScheduling count=None msg=0/6 nodes are available: 6 node(s) had untolerated taint(s). no new claims to deallocate, preemption: 0/6 nodes are available: 6 Preemption is not helpful for scheduling."
0.2823,Event,ADDED,eval-sanitize-1-r3-172-w2kmh.18d4a2d05f512787,reason=Scheduled count=None msg=Successfully assigned compute/eval-sanitize-1-r3-172-w2kmh to kind-worker2
0.2825,Event,ADDED,eval-sanitize-1-r3-172-w2kmh.18d4a2d0796ef6bd,"reason=Pulled count=1 msg=Container image ""busybox:musl"" already present on machine"
0.2827,Event,ADDED,eval-sanitize-1-r3-172-w2kmh.18d4a2d07ae633d0,reason=Created count=1 msg=Created container: task
0.2829,Event,ADDED,eval-sanitize-1-r3-172-w2kmh.18d4a2d080442e39,reason=Started count=1 msg=Started container task
0.283,Event,ADDED,eval-sanitize-1-r3-172.18d4a2d0092f0322,reason=SuccessfulCreate count=1 msg=Created pod: eval-sanitize-1-r3-172-w2kmh
0.2832,Event,ADDED,eval-sanitize-1-r3-172.18d4a2d73021f4d9,reason=Completed count=1 msg=Job completed
0.2834,Event,ADDED,eval-sanitize-1-r3-173-tssrq.18d4a2d058186ab1,reason=Scheduled count=None msg=Successfully assigned compute/eval-sanitize-1-r3-173-tssrq to kind-worker2
0.2835,Event,ADDED,eval-sanitize-1-r3-173-tssrq.18d4a2d072916d46,"reason=Pulled count=1 msg=Container image ""busybox:musl"" already present on machine"
0.2837,Event,ADDED,eval-sanitize-1-r3-173-tssrq.18d4a2d074a280dd,reason=Created count=1 msg=Created container: task
0.2839,Event,ADDED,eval-sanitize-1-r3-173-tssrq.18d4a2d077c75050,reason=Started count=1 msg=Started container task
0.284,Event,ADDED,eval-sanitize-1-r3-173.18d4a2d045a2ced4,reason=SuccessfulCreate count=1 msg=Created pod: eval-sanitize-1-r3-173-tssrq
0.2842,Event,ADDED,eval-sanitize-1-r3-173.18d4a2d718652123,reason=Completed count=1 msg=Job completed
0.2843,Event,ADDED,eval-sanitize-1-r3-174-7b279.18d4a2d08062760f,"reason=FailedScheduling count=None msg=0/6 nodes are available: 1 c_wall violated: 1 conflicting context pair(s) with node memory, 5 node(s) had untolerated taint(s). no new claims to deallocate, preemption: 0/6 nodes are available: 1 No preemption victims found for incoming pod, 5 Preemption is not helpful for scheduling."
0.2849,Event,ADDED,eval-sanitize-1-r3-174-7b279.18d4a2d0810ba334,"reason=FailedScheduling count=None msg=0/6 nodes are available: 1 c_wall violated: 1 conflicting context pair(s) with node memory, 5 node(s) had untolerated taint(s). no new claims to deallocate, preemption: 0/6 nodes are available: 1 No preemption victims found for incoming pod, 5 Preemption is not helpful for scheduling."
0.2852,Event,ADDED,eval-sanitize-1-r3-174-7b279.18d4a2d11777fd42,reason=Scheduled count=None msg=Successfully assigned compute/eval-sanitize-1-r3-174-7b279 to kind-worker3
0.2853,Event,ADDED,eval-sanitize-1-r3-174-7b279.18d4a2d130d26109,"reason=Pulled count=1 msg=Container image ""busybox:musl"" already present on machine"
0.2861,Event,ADDED,eval-sanitize-1-r3-174-7b279.18d4a2d1325820d1,reason=Created count=1 msg=Created container: task
0.2862,Event,ADDED,eval-sanitize-1-r3-174-7b279.18d4a2d1350265ee,reason=Started count=1 msg=Started container task
0.2864,Event,ADDED,eval-sanitize-1-r3-174.18d4a2d08008f446,reason=SuccessfulCreate count=1 msg=Created pod: eval-sanitize-1-r3-174-7b279
0.2866,Event,ADDED,eval-sanitize-1-r3-174.18d4a2d783acb4f0,reason=Completed count=1 msg=Job completed
0.2871,Event,ADDED,eval-sanitize-1-r3-175-qlsm9.18d4a2d0bb8c15f0,"reason=FailedScheduling count=None msg=0/6 nodes are available: 6 node(s) had untolerated taint(s). no new claims to deallocate, preemption: 0/6 nodes are available: 6 Preemption is not helpful for scheduling."
0.2873,Event,ADDED,eval-sanitize-1-r3-175-qlsm9.18d4a2d118da303f,reason=Scheduled count=None msg=Successfully assigned compute/eval-sanitize-1-r3-175-qlsm9 to kind-worker3
0.2875,Event,ADDED,eval-sanitize-1-r3-175-qlsm9.18d4a2d131e09a7f,"reason=Pulled count=1 msg=Container image ""busybox:musl"" already present on machine"
0.2878,Event,ADDED,eval-sanitize-1-r3-175-qlsm9.18d4a2d133532d48,reason=Created count=1 msg=Created container: task
0.288,Event,ADDED,eval-sanitize-1-r3-175-qlsm9.18d4a2d135dae7b7,reason=Started count=1 msg=Started container task
0.2882,Event,ADDED,eval-sanitize-1-r3-175.18d4a2d0bb798df1,reason=SuccessfulCreate count=1 msg=Created pod: eval-sanitize-1-r3-175-qlsm9
0.2884,Event,ADDED,eval-sanitize-1-r3-175.18d4a2d7899cea88,reason=Completed count=1 msg=Job completed
0.2887,Event,ADDED,eval-sanitize-1-r3-176-s5tc6.18d4a2d0f72cc0ce,"reason=FailedScheduling count=None msg=0/6 nodes are available: 6 node(s) had untolerated taint(s). no new claims to deallocate, preemption: 0/6 nodes are available: 6 Preemption is not helpful for scheduling."
0.2888,Event,ADDED,eval-sanitize-1-r3-176-s5tc6.18d4a2d118ca63bb,"reason=FailedScheduling count=None msg=0/6 nodes are available: 1 c_wall violated: 1 conflicting context pair(s) with node memory, 5 node(s) had untolerated taint(s). no new claims to deallocate, preemption: 0/6 nodes are available: 1 No preemption victims found for incoming pod, 5 Preemption is not helpful for scheduling."
0.289,Event,ADDED,eval-sanitize-1-r3-176-s5tc6.18d4a2d11d441205,"reason=FailedScheduling count=None msg=0/6 nodes are available: 1 c_wall violated: 1 conflicting context pair(s) with node memory, 5 node(s) had untolerated taint(s). no new claims to deallocate, preemption: 0/6 nodes are available: 1 No preemption victims found for incoming pod, 5 Preemption is not helpful for scheduling."
0.2893,Event,ADDED,eval-sanitize-1-r3-176-s5tc6.18d4a2d153403d16,reason=Scheduled count=None msg=Successfully assigned compute/eval-sanitize-1-r3-176-s5tc6 to kind-worker4
0.2895,Event,ADDED,eval-sanitize-1-r3-176-s5tc6.18d4a2d16f390718,"reason=Pulled count=1 msg=Container image ""busybox:musl"" already present on machine"
0.2897,Event,ADDED,eval-sanitize-1-r3-176-s5tc6.18d4a2d171a7ff34,reason=Created count=1 msg=Created container: task
0.2899,Event,ADDED,eval-sanitize-1-r3-176-s5tc6.18d4a2d175f1d028,reason=Started count=1 msg=Started container task
0.2902,Event,ADDED,eval-sanitize-1-r3-176.18d4a2d0f71dc2c2,reason=SuccessfulCreate count=1 msg=Created pod: eval-sanitize-1-r3-176-s5tc6
0.2904,Event,ADDED,eval-sanitize-1-r3-176.18d4a2d7a6e1ce45,reason=Completed count=1 msg=Job completed
0.2905,Event,ADDED,eval-sanitize-1-r3-177-q5v8t.18d4a2d1335d7e1e,"reason=FailedScheduling count=None msg=0/6 nodes are available: 1 c_wall violated: 1 conflicting context pair(s) with node memory, 5 node(s) had untolerated taint(s). no new claims to deallocate, preemption: 0/6 nodes are available: 1 No preemption victims found for incoming pod, 5 Preemption is not helpful for scheduling."
0.2908,Event,ADDED,eval-sanitize-1-r3-177-q5v8t.18d4a2d134160633,"reason=FailedScheduling count=None msg=0/6 nodes are available: 1 c_wall violated: 1 conflicting context pair(s) with node memory, 5 node(s) had untolerated taint(s). no new claims to deallocate, preemption: 0/6 nodes are available: 1 No preemption victims found for incoming pod, 5 Preemption is not helpful for scheduling."
0.2909,Event,ADDED,eval-sanitize-1-r3-177-q5v8t.18d4a2d1522dad67,reason=Scheduled count=None msg=Successfully assigned compute/eval-sanitize-1-r3-177-q5v8t to kind-worker4
0.2911,Event,ADDED,eval-sanitize-1-r3-177-q5v8t.18d4a2d16efb8550,"reason=Pulled count=1 msg=Container image ""busybox:musl"" already present on machine"
0.2913,Event,ADDED,eval-sanitize-1-r3-177-q5v8t.18d4a2d17126a588,reason=Created count=1 msg=Created container: task
0.2915,Event,ADDED,eval-sanitize-1-r3-177-q5v8t.18d4a2d1758b407e,reason=Started count=1 msg=Started container task
0.2916,Event,ADDED,eval-sanitize-1-r3-177.18d4a2d133059bc0,reason=SuccessfulCreate count=1 msg=Created pod: eval-sanitize-1-r3-177-q5v8t
0.2918,Event,ADDED,eval-sanitize-1-r3-177.18d4a2d7a70f254b,reason=Completed count=1 msg=Job completed
0.292,Event,ADDED,eval-sanitize-1-r3-178-mx4pw.18d4a2d1706ce3a3,reason=Scheduled count=None msg=Successfully assigned compute/eval-sanitize-1-r3-178-mx4pw to kind-worker3
0.2922,Event,ADDED,eval-sanitize-1-r3-178-mx4pw.18d4a2d189cf92bc,"reason=Pulled count=1 msg=Container image ""busybox:musl"" already present on machine"
0.2924,Event,ADDED,eval-sanitize-1-r3-178-mx4pw.18d4a2d18b03b19b,reason=Created count=1 msg=Created container: task
0.2926,Event,ADDED,eval-sanitize-1-r3-178-mx4pw.18d4a2d18d5d3ae6,reason=Started count=1 msg=Started container task
0.2928,Event,ADDED,eval-sanitize-1-r3-178.18d4a2d16f5c473b,reason=SuccessfulCreate count=1 msg=Created pod: eval-sanitize-1-r3-178-mx4pw
0.293,Event,ADDED,eval-sanitize-1-r3-178.18d4a2d7aab5a432,reason=Completed count=1 msg=Job completed
0.2931,Event,ADDED,eval-sanitize-1-r3-179-f6r5x.18d4a2d1a9c80e4d,"reason=FailedScheduling count=None msg=0/6 nodes are available: 6 node(s) had untolerated taint(s). no new claims to deallocate, preemption: 0/6 nodes are available: 6 Preemption is not helpful for scheduling."
0.2933,Event,ADDED,eval-sanitize-1-r3-179-f6r5x.18d4a2d5b0b73d7a,reason=Scheduled count=None msg=Successfully assigned compute/eval-sanitize-1-r3-179-f6r5x to kind-worker
0.2936,Event,ADDED,eval-sanitize-1-r3-179-f6r5x.18d4a2d5c7db8472,"reason=Pulled count=1 msg=Container image ""busybox:musl"" already present on machine"
0.2938,Event,ADDED,eval-sanitize-1-r3-179-f6r5x.18d4a2d5c9d0e685,reason=Created count=1 msg=Created container: task
0.294,Event,ADDED,eval-sanitize-1-r3-179-f6r5x.18d4a2d5cc9a5d8f,reason=Started count=1 msg=Started container task
0.2944,Event,ADDED,eval-sanitize-1-r3-179.18d4a2d1a9bb43ba,reason=SuccessfulCreate count=1 msg=Created pod: eval-sanitize-1-r3-179-f6r5x
0.2946,Event,ADDED,eval-sanitize-1-r3-179.18d4a2dbbd5bd513,reason=Completed count=1 msg=Job completed
0.2947,Event,ADDED,eval-sanitize-1-r3-180-6xmbf.18d4a2d1e5fe077a,"reason=FailedScheduling count=None msg=0/6 nodes are available: 6 node(s) had untolerated taint(s). no new claims to deallocate, preemption: 0/6 nodes are available: 6 Preemption is not helpful for scheduling."
0.2949,Event,ADDED,eval-sanitize-1-r3-180-6xmbf.18d4a2d5b0bc2223,"reason=FailedScheduling count=None msg=0/6 nodes are available: 1 c_wall violated: 1 conflicting context pair(s) with node memory, 5 node(s) had untolerated taint(s). no new claims to deallocate, preemption: 0/6 nodes are available: 1 No preemption victims found for incoming pod, 5 Preemption is not helpful for scheduling."
0.2951,Event,ADDED,eval-sanitize-1-r3-180-6xmbf.18d4a2d5c4f04661,"reason=FailedScheduling count=None msg=0/6 nodes are available: 1 c_wall violated: 2 conflicting context pair(s) with node memory, 5 node(s) had untolerated taint(s). no new claims to deallocate, preemption: 0/6 nodes are available: 1 No preemption victims found for incoming pod, 5 Preemption is not helpful for scheduling."
0.2953,Event,ADDED,eval-sanitize-1-r3-180-6xmbf.18d4a2d5d11acbc6,"reason=FailedScheduling count=None msg=0/6 nodes are available: 1 c_wall violated: 2 conflicting context pair(s) with node memory, 5 node(s) had untolerated taint(s). no new claims to deallocate, preemption: 0/6 nodes are available: 1 No preemption victims found for incoming pod, 5 Preemption is not helpful for scheduling."
0.2954,Event,ADDED,eval-sanitize-1-r3-180-6xmbf.18d4a2d5f4c194dc,reason=Scheduled count=None msg=Successfully assigned compute/eval-sanitize-1-r3-180-6xmbf to kind-worker5
0.2956,Event,ADDED,eval-sanitize-1-r3-180-6xmbf.18d4a2d60faef492,"reason=Pulled count=1 msg=Container image ""busybox:musl"" already present on machine"
0.2957,Event,ADDED,eval-sanitize-1-r3-180-6xmbf.18d4a2d6116d9846,reason=Created count=1 msg=Created container: task
0.2959,Event,ADDED,eval-sanitize-1-r3-180-6xmbf.18d4a2d61573fe44,reason=Started count=1 msg=Started container task
0.2961,Event,ADDED,eval-sanitize-1-r3-180.18d4a2d1e5f0a2bb,reason=SuccessfulCreate count=1 msg=Created pod: eval-sanitize-1-r3-180-6xmbf
0.2962,Event,ADDED,eval-sanitize-1-r3-180.18d4a2dc07a087f6,reason=Completed count=1 msg=Job completed
0.2964,Event,ADDED,eval-sanitize-1-r3-181-pzm87.18d4a2d22129c226,"reason=FailedScheduling count=None msg=0/6 nodes are available: 6 node(s) had untolerated taint(s). no new claims to deallocate, preemption: 0/6 nodes are available: 6 Preemption is not helpful for scheduling."
0.2965,Event,ADDED,eval-sanitize-1-r3-181-pzm87.18d4a2d5b6a79d02,reason=Scheduled count=None msg=Successfully assigned compute/eval-sanitize-1-r3-181-pzm87 to kind-worker
0.297,Event,ADDED,eval-sanitize-1-r3-181-pzm87.18d4a2d5cb922fc3,"reason=Pulled count=1 msg=Container image ""busybox:musl"" already present on machine"
0.2972,Event,ADDED,eval-sanitize-1-r3-181-pzm87.18d4a2d5cdeb4bea,reason=Created count=1 msg=Created container: task
0.2974,Event,ADDED,eval-sanitize-1-r3-181-pzm87.18d4a2d5d3f060e7,reason=Started count=1 msg=Started container task
0.2976,Event,ADDED,eval-sanitize-1-r3-181.18d4a2d2211f5d5f,reason=SuccessfulCreate count=1 msg=Created pod: eval-sanitize-1-r3-181-pzm87
0.2979,Event,ADDED,eval-sanitize-1-r3-181.18d4a2db27dfa5e8,reason=Completed count=1 msg=Job completed
0.2981,Event,ADDED,eval-sanitize-1-r3-182-5hgjf.18d4a2d25dd2f0b3,"reason=FailedScheduling count=None msg=0/6 nodes are available: 6 node(s) had untolerated taint(s). no new claims to deallocate, preemption: 0/6 nodes are available: 6 Preemption is not helpful for scheduling."
0.2982,Event,ADDED,eval-sanitize-1-r3-182-5hgjf.18d4a2d5b6acad02,"reason=FailedScheduling count=None msg=0/6 nodes are available: 1 c_wall violated: 2 conflicting context pair(s) with node memory, 5 node(s) had untolerated taint(s). no new claims to deallocate, preemption: 0/6 nodes are available: 1 No preemption victims found for incoming pod, 5 Preemption is not helpful for scheduling."
0.2985,Event,ADDED,eval-sanitize-1-r3-182-5hgjf.18d4a2d5c5930e66,"reason=FailedScheduling count=None msg=0/6 nodes are available: 1 c_wall violated: 2 conflicting context pair(s) with node memory, 5 node(s) had untolerated taint(s). no new claims to deallocate, preemption: 0/6 nodes are available: 1 No preemption victims found for incoming pod, 5 Preemption is not helpful for scheduling."
0.2987,Event,ADDED,eval-sanitize-1-r3-182-5hgjf.18d4a2d60c053da7,reason=Scheduled count=None msg=Successfully assigned compute/eval-sanitize-1-r3-182-5hgjf to kind-worker2
0.2989,Event,ADDED,eval-sanitize-1-r3-182-5hgjf.18d4a2d629d2de1d,"reason=Pulled count=1 msg=Container image ""busybox:musl"" already present on machine"
0.2992,Event,ADDED,eval-sanitize-1-r3-182-5hgjf.18d4a2d62b8e11f0,reason=Created count=1 msg=Created container: task
0.2994,Event,ADDED,eval-sanitize-1-r3-182-5hgjf.18d4a2d630a7a88e,reason=Started count=1 msg=Started container task
0.2996,Event,ADDED,eval-sanitize-1-r3-182.18d4a2d25dc8ff3d,reason=SuccessfulCreate count=1 msg=Created pod: eval-sanitize-1-r3-182-5hgjf
0.2997,Event,ADDED,eval-sanitize-1-r3-182.18d4a2dc2a906c30,reason=Completed count=1 msg=Job completed
0.3,Event,ADDED,eval-sanitize-1-r3-183-q4qv2.18d4a2d29893a25a,"reason=FailedScheduling count=None msg=0/6 nodes are available: 6 node(s) had untolerated taint(s). no new claims to deallocate, preemption: 0/6 nodes are available: 6 Preemption is not helpful for scheduling."
0.3001,Event,ADDED,eval-sanitize-1-r3-183-q4qv2.18d4a2d5b7986528,reason=Scheduled count=None msg=Successfully assigned compute/eval-sanitize-1-r3-183-q4qv2 to kind-worker
0.3003,Event,ADDED,eval-sanitize-1-r3-183-q4qv2.18d4a2d5db7b87ab,"reason=Pulled count=1 msg=Container image ""busybox:musl"" already present on machine"
0.3004,Event,ADDED,eval-sanitize-1-r3-183-q4qv2.18d4a2d5de3871f3,reason=Created count=1 msg=Created container: task
0.3006,Event,ADDED,eval-sanitize-1-r3-183-q4qv2.18d4a2d5e7937add,reason=Started count=1 msg=Started container task
0.3008,Event,ADDED,eval-sanitize-1-r3-183.18d4a2d2988bad70,reason=SuccessfulCreate count=1 msg=Created pod: eval-sanitize-1-r3-183-q4qv2
0.301,Event,ADDED,eval-sanitize-1-r3-183.18d4a2db61c2f5bf,reason=Completed count=1 msg=Job completed
0.3011,Event,ADDED,eval-sanitize-1-r3-184-zzt7g.18d4a2d2d43dda08,"reason=FailedScheduling count=None msg=0/6 nodes are available: 6 node(s) had untolerated taint(s). no new claims to deallocate, preemption: 0/6 nodes are available: 6 Preemption is not helpful for scheduling."
0.3013,Event,ADDED,eval-sanitize-1-r3-184-zzt7g.18d4a2d5b7841b45,"reason=FailedScheduling count=None msg=0/6 nodes are available: 1 c_wall violated: 2 conflicting context pair(s) with node memory, 5 node(s) had untolerated taint(s). no new claims to deallocate, preemption: 0/6 nodes are available: 1 No preemption victims found for incoming pod, 5 Preemption is not helpful for scheduling."
0.3015,Event,ADDED,eval-sanitize-1-r3-184-zzt7g.18d4a2d5c8c4f28f,"reason=FailedScheduling count=None msg=0/6 nodes are available: 1 c_wall violated: 2 conflicting context pair(s) with node memory, 5 node(s) had untolerated taint(s). no new claims to deallocate, preemption: 0/6 nodes are available: 1 No preemption victims found for incoming pod, 5 Preemption is not helpful for scheduling."
0.3017,Event,ADDED,eval-sanitize-1-r3-184-zzt7g.18d4a2d60cd9fad3,reason=Scheduled count=None msg=Successfully assigned compute/eval-sanitize-1-r3-184-zzt7g to kind-worker2
0.3019,Event,ADDED,eval-sanitize-1-r3-184-zzt7g.18d4a2d62a094470,"reason=Pulled count=1 msg=Container image ""busybox:musl"" already present on machine"
0.3021,Event,ADDED,eval-sanitize-1-r3-184-zzt7g.18d4a2d62bebbf71,reason=Created count=1 msg=Created container: task
0.3023,Event,ADDED,eval-sanitize-1-r3-184-zzt7g.18d4a2d630a79d93,reason=Started count=1 msg=Started container task
0.3026,Event,ADDED,eval-sanitize-1-r3-184.18d4a2d2d4343f33,reason=SuccessfulCreate count=1 msg=Created pod: eval-sanitize-1-r3-184-zzt7g
0.3028,Event,ADDED,eval-sanitize-1-r3-184.18d4a2dc24a04550,reason=Completed count=1 msg=Job completed
0.3029,Event,ADDED,eval-sanitize-1-r3-185-n6ncr.18d4a2d30fa1cc74,"reason=FailedScheduling count=None msg=0/6 nodes are available: 6 node(s) had untolerated taint(s). no new claims to deallocate, preemption: 0/6 nodes are available: 6 Preemption is not helpful for scheduling."
0.3031,Event,ADDED,eval-sanitize-1-r3-185-n6ncr.18d4a2d5b8a4e88b,reason=Scheduled count=None msg=Successfully assigned compute/eval-sanitize-1-r3-185-n6ncr to kind-worker
0.3034,Event,ADDED,eval-sanitize-1-r3-185-n6ncr.18d4a2d5dba5646c,"reason=Pulled count=1 msg=Container image ""busybox:musl"" already present on machine"
0.3038,Event,ADDED,eval-sanitize-1-r3-185-n6ncr.18d4a2d5dfa7e642,reason=Created count=1 msg=Created container: task
0.3039,Event,ADDED,eval-sanitize-1-r3-185-n6ncr.18d4a2d5e8957e57,reason=Started count=1 msg=Started container task
0.3042,Event,ADDED,eval-sanitize-1-r3-185.18d4a2d30f9750aa,reason=SuccessfulCreate count=1 msg=Created pod: eval-sanitize-1-r3-185-n6ncr
0.3043,Event,ADDED,eval-sanitize-1-r3-185.18d4a2db26797d78,reason=Completed count=1 msg=Job completed
0.3045,Event,ADDED,eval-sanitize-1-r3-186-m4kdh.18d4a2d34c7187d0,"reason=FailedScheduling count=None msg=0/6 nodes are available: 6 node(s) had untolerated taint(s). no new claims to deallocate, preemption: 0/6 nodes are available: 6 Preemption is not helpful for scheduling."
0.3046,Event,ADDED,eval-sanitize-1-r3-186-m4kdh.18d4a2d5b86956e4,"reason=FailedScheduling count=None msg=0/6 nodes are available: 1 c_wall violated: 2 conflicting context pair(s) with node memory, 5 node(s) had untolerated taint(s). no new claims to deallocate, preemption: 0/6 nodes are available: 1 No preemption victims found for incoming pod, 5 Preemption is not helpful for scheduling."
0.3048,Event,ADDED,eval-sanitize-1-r3-186-m4kdh.18d4a2d5c8f95ac4,"reason=FailedScheduling count=None msg=0/6 nodes are available: 1 c_wall violated: 2 conflicting context pair(s) with node memory, 5 node(s) had untolerated taint(s). no new claims to deallocate, preemption: 0/6 nodes are available: 1 No preemption victims found for incoming pod, 5 Preemption is not helpful for scheduling."
0.305,Event,ADDED,eval-sanitize-1-r3-186-m4kdh.18d4a2d60ced5d7b,"reason=FailedScheduling count=None msg=0/6 nodes are available: 2 c_wall violated: 1 conflicting context pair(s) with node memory, 4 node(s) had untolerated taint(s). no new claims to deallocate, preemption: 0/6 nodes are available: 2 No preemption victims found for incoming pod, 4 Preemption is not helpful for scheduling."
0.3052,Event,ADDED,eval-sanitize-1-r3-186-m4kdh.18d4a2d6188f535b,"reason=FailedScheduling count=None msg=0/6 nodes are available: 2 c_wall violated: 1 conflicting context pair(s) with node memory, 4 node(s) had untolerated taint(s). no new claims to deallocate, preemption: 0/6 nodes are available: 2 No preemption victims found for incoming pod, 4 Preemption is not helpful for scheduling."
0.3054,Event,ADDED,eval-sanitize-1-r3-186-m4kdh.18d4a2d631c29b3f,"reason=FailedScheduling count=None msg=0/6 nodes are available: 1 c_wall violated: 1 conflicting context pair(s) with node memory, 5 node(s) had untolerated taint(s). no new claims to deallocate, preemption: 0/6 nodes are available: 1 No preemption victims found for incoming pod, 5 Preemption is not helpful for scheduling."
0.3055,Event,ADDED,eval-sanitize-1-r3-186-m4kdh.18d4a2d6952e3e2d,reason=Scheduled count=None msg=Successfully assigned compute/eval-sanitize-1-r3-186-m4kdh to kind-worker4
0.3057,Event,ADDED,eval-sanitize-1-r3-186-m4kdh.18d4a2d6b08623e9,"reason=Pulled count=1 msg=Container image ""busybox:musl"" already present on machine"
0.3059,Event,ADDED,eval-sanitize-1-r3-186-m4kdh.18d4a2d6b2f91adb,reason=Created count=1 msg=Created container: task
0.3061,Event,ADDED,eval-sanitize-1-r3-186-m4kdh.18d4a2d6b6e7fcb9,reason=Started count=1 msg=Started container task
0.3063,Event,ADDED,eval-sanitize-1-r3-186.18d4a2d34c6884d8,reason=SuccessfulCreate count=1 msg=Created pod: eval-sanitize-1-r3-186-m4kdh
0.3065,Event,ADDED,eval-sanitize-1-r3-186.18d4a2dc963d26b2,reason=Completed count=1 msg=Job completed
0.3067,Event,ADDED,eval-sanitize-1-r3-187-7wx4g.18d4a2d386b7c89d,"reason=FailedScheduling count=None msg=0/6 nodes are available: 6 node(s) had untolerated taint(s). no new claims to deallocate, preemption: 0/6 nodes are available: 6 Preemption is not helpful for scheduling."
0.3068,Event,ADDED,eval-sanitize-1-r3-187-7wx4g.18d4a2d5b91c00fe,"reason=FailedScheduling count=None msg=0/6 nodes are available: 1 c_wall violated: 2 conflicting context pair(s) with node memory, 5 node(s) had untolerated taint(s). no new claims to deallocate, preemption: 0/6 nodes are available: 1 No preemption victims found for incoming pod, 5 Preemption is not helpful for scheduling."
0.307,Event,ADDED,eval-sanitize-1-r3-187-7wx4g.18d4a2d5c9254a56,"reason=FailedScheduling count=None msg=0/6 nodes are available: 1 c_wall violated: 2 conflicting context pair(s) with node memory, 5 node(s) had untolerated taint(s). no new claims to deallocate, preemption: 0/6 nodes are available: 1 No preemption victims found for incoming pod, 5 Preemption is not helpful for scheduling."
0.3076,Event,ADDED,eval-sanitize-1-r3-187-7wx4g.18d4a2d612297708,reason=Scheduled count=None msg=Successfully assigned compute/eval-sanitize-1-r3-187-7wx4g to kind-worker2
0.3078,Event,ADDED,eval-sanitize-1-r3-187-7wx4g.18d4a2d62ccc0fb9,"reason=Pulled count=1 msg=Container image ""busybox:musl"" already present on machine"
0.308,Event,ADDED,eval-sanitize-1-r3-187-7wx4g.18d4a2d630fd8487,reason=Created count=1 msg=Created container: task
0.3082,Event,ADDED,eval-sanitize-1-r3-187-7wx4g.18d4a2d6399ae7b0,reason=Started count=1 msg=Started container task
0.3084,Event,ADDED,eval-sanitize-1-r3-187.18d4a2d386a8f271,reason=SuccessfulCreate count=1 msg=Created pod: eval-sanitize-1-r3-187-7wx4g
0.3086,Event,ADDED,eval-sanitize-1-r3-187.18d4a2dc308390ae,reason=Completed count=1 msg=Job completed
0.3087,Event,ADDED,eval-sanitize-1-r3-188-vsk5w.18d4a2d3c25cd262,"reason=FailedScheduling count=None msg=0/6 nodes are available: 6 node(s) had untolerated taint(s). no new claims to deallocate, preemption: 0/6 nodes are available: 6 Preemption is not helpful for scheduling."
0.3091,Event,ADDED,eval-sanitize-1-r3-188-vsk5w.18d4a2d5bce99a1c,"reason=FailedScheduling count=None msg=0/6 nodes are available: 1 c_wall violated: 2 conflicting context pair(s) with node memory, 5 node(s) had untolerated taint(s). no new claims to deallocate, preemption: 0/6 nodes are available: 1 No preemption victims found for incoming pod, 5 Preemption is not helpful for scheduling."
0.3093,Event,ADDED,eval-sanitize-1-r3-188-vsk5w.18d4a2d5ca0f48bb,"reason=FailedScheduling count=None msg=0/6 nodes are available: 1 c_wall violated: 2 conflicting context pair(s) with node memory, 5 node(s) had untolerated taint(s). no new claims to deallocate, preemption: 0/6 nodes are available: 1 No preemption victims found for incoming pod, 5 Preemption is not helpful for scheduling."
0.3094,Event,ADDED,eval-sanitize-1-r3-188-vsk5w.18d4a2d5fbb6f583,reason=Scheduled count=None msg=Successfully assigned compute/eval-sanitize-1-r3-188-vsk5w to kind-worker2
0.3097,Event,ADDED,eval-sanitize-1-r3-188-vsk5w.18d4a2d615db72ba,"reason=Pulled count=1 msg=Container image ""busybox:musl"" already present on machine"
0.3099,Event,ADDED,eval-sanitize-1-r3-188-vsk5w.18d4a2d61774d682,reason=Created count=1 msg=Created container: task
0.31,Event,ADDED,eval-sanitize-1-r3-188-vsk5w.18d4a2d61b02c9ae,reason=Started count=1 msg=Started container task
0.3102,Event,ADDED,eval-sanitize-1-r3-188.18d4a2d3c250df24,reason=SuccessfulCreate count=1 msg=Created pod: eval-sanitize-1-r3-188-vsk5w
0.3104,Event,ADDED,eval-sanitize-1-r3-188.18d4a2dbe5fa6c84,reason=Completed count=1 msg=Job completed
0.3105,Event,ADDED,eval-sanitize-1-r3-189-n7jr6.18d4a2d4016433de,"reason=FailedScheduling count=None msg=0/6 nodes are available: 6 node(s) had untolerated taint(s). no new claims to deallocate, preemption: 0/6 nodes are available: 6 Preemption is not helpful for scheduling."
0.3107,Event,ADDED,eval-sanitize-1-r3-189-n7jr6.18d4a2d5bd7ef19b,"reason=FailedScheduling count=None msg=0/6 nodes are available: 1 c_wall violated: 2 conflicting context pair(s) with node memory, 5 node(s) had untolerated taint(s). no new claims to deallocate, preemption: 0/6 nodes are available: 1 No preemption victims found for incoming pod, 5 Preemption is not helpful for scheduling."
0.3109,Event,ADDED,eval-sanitize-1-r3-189-n7jr6.18d4a2d5caf1e6a7,"reason=FailedScheduling count=None msg=0/6 nodes are available: 1 c_wall violated: 2 conflicting context pair(s) with node memory, 5 node(s) had untolerated taint(s). no new claims to deallocate, preemption: 0/6 nodes are available: 1 No preemption victims found for incoming pod, 5 Preemption is not helpful for scheduling."
0.311,Event,ADDED,eval-sanitize-1-r3-189-n7jr6.18d4a2d603b20e1f,reason=Scheduled count=None msg=Successfully assigned compute/eval-sanitize-1-r3-189-n7jr6 to kind-worker2
0.3112,Event,ADDED,eval-sanitize-1-r3-189-n7jr6.18d4a2d61c39dee8,"reason=Pulled count=1 msg=Container image ""busybox:musl"" already present on machine"
0.3114,Event,ADDED,eval-sanitize-1-r3-189-n7jr6.18d4a2d61d5b513f,reason=Created count=1 msg=Created container: task
0.3115,Event,ADDED,eval-sanitize-1-r3-189-n7jr6.18d4a2d62370fa1e,reason=Started count=1 msg=Started container task
0.3117,Event,ADDED,eval-sanitize-1-r3-189.18d4a2d40157d3c0,reason=SuccessfulCreate count=1 msg=Created pod: eval-sanitize-1-r3-189-n7jr6
0.3119,Event,ADDED,eval-sanitize-1-r3-189.18d4a2dbf0841fd7,reason=Completed count=1 msg=Job completed
0.312,Event,ADDED,eval-sanitize-1-r3-190-rj7wt.18d4a2d4399ad1fa,"reason=FailedScheduling count=None msg=0/6 nodes are available: 6 node(s) had untolerated taint(s). no new claims to deallocate, preemption: 0/6 nodes are available: 6 Preemption is not helpful for scheduling."
0.3122,Event,ADDED,eval-sanitize-1-r3-190-rj7wt.18d4a2d5be29dfba,"reason=FailedScheduling count=None msg=0/6 nodes are available: 1 c_wall violated: 2 conflicting context pair(s) with node memory, 5 node(s) had untolerated taint(s). no new claims to deallocate, preemption: 0/6 nodes are available: 1 No preemption victims found for incoming pod, 5 Preemption is not helpful for scheduling."
0.3124,Event,ADDED,eval-sanitize-1-r3-190-rj7wt.18d4a2d5cb3cd533,"reason=FailedScheduling count=None msg=0/6 nodes are available: 1 c_wall violated: 2 conflicting context pair(s) with node memory, 5 node(s) had untolerated taint(s). no new claims to deallocate, preemption: 0/6 nodes are available: 1 No preemption victims found for incoming pod, 5 Preemption is not helpful for scheduling."
0.3125,Event,ADDED,eval-sanitize-1-r3-190-rj7wt.18d4a2d5e8ab68a8,reason=Scheduled count=None msg=Successfully assigned compute/eval-sanitize-1-r3-190-rj7wt to kind-worker5
0.3128,Event,ADDED,eval-sanitize-1-r3-190-rj7wt.18d4a2d6037b1d5e,"reason=Pulled count=1 msg=Container image ""busybox:musl"" already present on machine"
0.3129,Event,ADDED,eval-sanitize-1-r3-190-rj7wt.18d4a2d605cdc2ce,reason=Created count=1 msg=Created container: task
0.3131,Event,ADDED,eval-sanitize-1-r3-190-rj7wt.18d4a2d60a2b7b8e,reason=Started count=1 msg=Started container task
0.3133,Event,ADDED,eval-sanitize-1-r3-190.18d4a2d4398ca4e6,reason=SuccessfulCreate count=1 msg=Created pod: eval-sanitize-1-r3-190-rj7wt
0.3134,Event,ADDED,eval-sanitize-1-r3-190.18d4a2dc0ccb0392,reason=Completed count=1 msg=Job completed
0.3136,Event,ADDED,eval-sanitize-1-r3-191-z9bm2.18d4a2d4751a713b,"reason=FailedScheduling count=None msg=0/6 nodes are available: 6 node(s) had untolerated taint(s). no new claims to deallocate, preemption: 0/6 nodes are available: 6 Preemption is not helpful for scheduling."
0.3137,Event,ADDED,eval-sanitize-1-r3-191-z9bm2.18d4a2d5c0b01cfb,reason=Scheduled count=None msg=Successfully assigned compute/eval-sanitize-1-r3-191-z9bm2 to kind-worker
0.3139,Event,ADDED,eval-sanitize-1-r3-191-z9bm2.18d4a2d5dbdb577c,"reason=Pulled count=1 msg=Container image ""busybox:musl"" already present on machine"
0.3141,Event,ADDED,eval-sanitize-1-r3-191-z9bm2.18d4a2d5df7fc57b,reason=Created count=1 msg=Created container: task
0.3142,Event,ADDED,eval-sanitize-1-r3-191-z9bm2.18d4a2d5e895fdd1,reason=Started count=1 msg=Started container task
0.3144,Event,ADDED,eval-sanitize-1-r3-191.18d4a2d4751166a2,reason=SuccessfulCreate count=1 msg=Created pod: eval-sanitize-1-r3-191-z9bm2
0.3146,Event,ADDED,eval-sanitize-1-r3-191.18d4a2db2677a317,reason=Completed count=1 msg=Job completed
0.3147,Event,ADDED,eval-sanitize-1-r3-192-mcr49.18d4a2d4b0b48c7a,"reason=FailedScheduling count=None msg=0/6 nodes are available: 6 node(s) had untolerated taint(s). no new claims to deallocate, preemption: 0/6 nodes are available: 6 Preemption is not helpful for scheduling."
0.3149,Event,ADDED,eval-sanitize-1-r3-192-mcr49.18d4a2d5beebd799,"reason=FailedScheduling count=None msg=0/6 nodes are available: 1 c_wall violated: 1 conflicting context pair(s) with node memory, 5 node(s) had untolerated taint(s). no new claims to deallocate, preemption: 0/6 nodes are available: 1 No preemption victims found for incoming pod, 5 Preemption is not helpful for scheduling."
0.3151,Event,ADDED,eval-sanitize-1-r3-192-mcr49.18d4a2d5cb9c2133,"reason=FailedScheduling count=None msg=0/6 nodes are available: 1 c_wall violated: 1 conflicting context pair(s) with node memory, 5 node(s) had untolerated taint(s). no new claims to deallocate, preemption: 0/6 nodes are available: 1 No preemption victims found for incoming pod, 5 Preemption is not helpful for scheduling."
0.3152,Event,ADDED,eval-sanitize-1-r3-192-mcr49.18d4a2d605c70957,"reason=FailedScheduling count=None msg=0/6 nodes are available: 1 c_wall violated: 2 conflicting context pair(s) with node memory, 2 c_wall violated: 1 conflicting context pair(s) with node memory, 3 node(s) had untolerated taint(s). no new claims to deallocate, preemption: 0/6 nodes are available: 3 No preemption victims found for incoming pod, 3 Preemption is not helpful for scheduling."
0.3153,Event,ADDED,eval-sanitize-1-r3-192-mcr49.18d4a2d612c518bd,"reason=FailedScheduling count=None msg=0/6 nodes are available: 1 c_wall violated: 1 conflicting context pair(s) with node memory, 1 c_wall violated: 2 conflicting context pair(s) with node memory, 4 node(s) had untolerated taint(s). no new claims to deallocate, preemption: 0/6 nodes are available: 2 No preemption victims found for incoming pod, 4 Preemption is not helpful for scheduling."
0.3155,Event,ADDED,eval-sanitize-1-r3-192-mcr49.18d4a2d618e5fad2,"reason=FailedScheduling count=None msg=0/6 nodes are available: 1 c_wall violated: 1 conflicting context pair(s) with node memory, 1 c_wall violated: 2 conflicting context pair(s) with node memory, 4 node(s) had untolerated taint(s). no new claims to deallocate, preemption: 0/6 nodes are available: 2 No preemption victims found for incoming pod, 4 Preemption is not helpful for scheduling."
0.3157,Event,ADDED,eval-sanitize-1-r3-192-mcr49.18d4a2d631f82d96,"reason=FailedScheduling count=None msg=0/6 nodes are available: 1 c_wall violated: 1 conflicting context pair(s) with node memory, 5 node(s) had untolerated taint(s). no new claims to deallocate, preemption: 0/6 nodes are available: 1 No preemption victims found for incoming pod, 5 Preemption is not helpful for scheduling."
0.3159,Event,ADDED,eval-sanitize-1-r3-192-mcr49.18d4a2d69552acf9,"reason=FailedScheduling count=None msg=0/6 nodes are available: 1 c_wall violated: 1 conflicting context pair(s) with node memory, 5 node(s) had untolerated taint(s). no new claims to deallocate, preemption: 0/6 nodes are available: 1 No preemption victims found for incoming pod, 5 Preemption is not helpful for scheduling."
0.316,Event,ADDED,eval-sanitize-1-r3-192-mcr49.18d4a2d69a9c690a,"reason=FailedScheduling count=None msg=0/6 nodes are available: 1 c_wall violated: 1 conflicting context pair(s) with node memory, 5 node(s) had untolerated taint(s). no new claims to deallocate, preemption: 0/6 nodes are available: 1 No preemption victims found for incoming pod, 5 Preemption is not helpful for scheduling."
0.3162,Event,ADDED,eval-sanitize-1-r3-192-mcr49.18d4a2d6d000420c,reason=Scheduled count=None msg=Successfully assigned compute/eval-sanitize-1-r3-192-mcr49 to kind-worker3
0.3164,Event,ADDED,eval-sanitize-1-r3-192-mcr49.18d4a2d6eefd0162,"reason=Pulled count=1 msg=Container image ""busybox:musl"" already present on machine"
0.3165,Event,ADDED,eval-sanitize-1-r3-192-mcr49.18d4a2d6f0600e37,reason=Created count=1 msg=Created container: task
0.3167,Event,ADDED,eval-sanitize-1-r3-192-mcr49.18d4a2d6f4d15b7b,reason=Started count=1 msg=Started container task
0.3169,Event,ADDED,eval-sanitize-1-r3-192.18d4a2d4b0aab1bb,reason=SuccessfulCreate count=1 msg=Created pod: eval-sanitize-1-r3-192-mcr49
0.3173,Event,ADDED,eval-sanitize-1-r3-192.18d4a2dc87f16e44,reason=Completed count=1 msg=Job completed
0.3176,Event,ADDED,eval-sanitize-1-r3-193-8mkw2.18d4a2d4efe839c3,"reason=FailedScheduling count=None msg=0/6 nodes are available: 6 node(s) had untolerated taint(s). no new claims to deallocate, preemption: 0/6 nodes are available: 6 Preemption is not helpful for scheduling."
0.3179,Event,ADDED,eval-sanitize-1-r3-193-8mkw2.18d4a2d5c300d6fd,reason=Scheduled count=None msg=Successfully assigned compute/eval-sanitize-1-r3-193-8mkw2 to kind-worker
0.3182,Event,ADDED,eval-sanitize-1-r3-193-8mkw2.18d4a2d5e9275c76,"reason=Pulled count=1 msg=Container image ""busybox:musl"" already present on machine"
0.3185,Event,ADDED,eval-sanitize-1-r3-193-8mkw2.18d4a2d5eab4113b,reason=Created count=1 msg=Created container: task
0.3187,Event,ADDED,eval-sanitize-1-r3-193-8mkw2.18d4a2d5eea948a9,reason=Started count=1 msg=Started container task
0.3189,Event,ADDED,eval-sanitize-1-r3-193.18d4a2d4efdda1d2,reason=SuccessfulCreate count=1 msg=Created pod: eval-sanitize-1-r3-193-8mkw2
0.319,Event,ADDED,eval-sanitize-1-r3-193.18d4a2dbb3671f80,reason=Completed count=1 msg=Job completed
0.3193,Event,ADDED,eval-sanitize-1-r3-194-vs9p9.18d4a2d527f5c400,"reason=FailedScheduling count=None msg=0/6 nodes are available: 6 node(s) had untolerated taint(s). no new claims to deallocate, preemption: 0/6 nodes are available: 6 Preemption is not helpful for scheduling."
0.3195,Event,ADDED,eval-sanitize-1-r3-194-vs9p9.18d4a2d5c2e0cc8b,"reason=FailedScheduling count=None msg=0/6 nodes are available: 1 c_wall violated: 2 conflicting context pair(s) with node memory, 5 node(s) had untolerated taint(s). no new claims to deallocate, preemption: 0/6 nodes are available: 1 No preemption victims found for incoming pod, 5 Preemption is not helpful for scheduling."
0.3197,Event,ADDED,eval-sanitize-1-r3-194-vs9p9.18d4a2d5cfdc9794,"reason=FailedScheduling count=None msg=0/6 nodes are available: 1 c_wall violated: 2 conflicting context pair(s) with node memory, 5 node(s) had untolerated taint(s). no new claims to deallocate, preemption: 0/6 nodes are available: 1 No preemption victims found for incoming pod, 5 Preemption is not helpful for scheduling."
0.3199,Event,ADDED,eval-sanitize-1-r3-194-vs9p9.18d4a2d5ee78dae0,reason=Scheduled count=None msg=Successfully assigned compute/eval-sanitize-1-r3-194-vs9p9 to kind-worker5
0.3201,Event,ADDED,eval-sanitize-1-r3-194-vs9p9.18d4a2d60ba14d1e,"reason=Pulled count=1 msg=Container image ""busybox:musl"" already present on machine"
0.3203,Event,ADDED,eval-sanitize-1-r3-194-vs9p9.18d4a2d60d6c4b27,reason=Created count=1 msg=Created container: task
0.3205,Event,ADDED,eval-sanitize-1-r3-194-vs9p9.18d4a2d60ffe976c,reason=Started count=1 msg=Started container task
0.3206,Event,ADDED,eval-sanitize-1-r3-194.18d4a2d527ebf9f3,reason=SuccessfulCreate count=1 msg=Created pod: eval-sanitize-1-r3-194-vs9p9
0.3208,Event,ADDED,eval-sanitize-1-r3-194.18d4a2dc00e4e0fe,reason=Completed count=1 msg=Job completed
0.321,Event,ADDED,eval-sanitize-1-r3-195-9dx9m.18d4a2d563d13785,"reason=FailedScheduling count=None msg=0/6 nodes are available: 6 node(s) had untolerated taint(s). no new claims to deallocate, preemption: 0/6 nodes are available: 6 Preemption is not helpful for scheduling."
0.3211,Event,ADDED,eval-sanitize-1-r3-195-9dx9m.18d4a2d5c38c5b42,"reason=FailedScheduling count=None msg=0/6 nodes are available: 1 c_wall violated: 2 conflicting context pair(s) with node memory, 5 node(s) had untolerated taint(s). no new claims to deallocate, preemption: 0/6 nodes are available: 1 No preemption victims found for incoming pod, 5 Preemption is not helpful for scheduling."
0.3214,Event,ADDED,eval-sanitize-1-r3-195-9dx9m.18d4a2d5d0120413,"reason=FailedScheduling count=None msg=0/6 nodes are available: 1 c_wall violated: 2 conflicting context pair(s) with node memory, 5 node(s) had untolerated taint(s). no new claims to deallocate, preemption: 0/6 nodes are available: 1 No preemption victims found for incoming pod, 5 Preemption is not helpful for scheduling."
0.3216,Event,ADDED,eval-sanitize-1-r3-195-9dx9m.18d4a2d5f2442e87,reason=Scheduled count=None msg=Successfully assigned compute/eval-sanitize-1-r3-195-9dx9m to kind-worker5
0.3219,Event,ADDED,eval-sanitize-1-r3-195-9dx9m.18d4a2d60bc973dc,"reason=Pulled count=1 msg=Container image ""busybox:musl"" already present on machine"
0.3221,Event,ADDED,eval-sanitize-1-r3-195-9dx9m.18d4a2d60db90758,reason=Created count=1 msg=Created container: task
0.3223,Event,ADDED,eval-sanitize-1-r3-195-9dx9m.18d4a2d61077be5e,reason=Started count=1 msg=Started container task
0.3224,Event,ADDED,eval-sanitize-1-r3-195.18d4a2d563c4af53,reason=SuccessfulCreate count=1 msg=Created pod: eval-sanitize-1-r3-195-9dx9m
0.3226,Event,ADDED,eval-sanitize-1-r3-195.18d4a2dbfae3f3c1,reason=Completed count=1 msg=Job completed
0.3228,Event,ADDED,eval-sanitize-1-r3-196-s7qb9.18d4a2d5aa147096,"reason=FailedScheduling count=None msg=0/6 nodes are available: 6 node(s) had untolerated taint(s). no new claims to deallocate, preemption: 0/6 nodes are available: 6 Preemption is not helpful for scheduling."
0.3229,Event,ADDED,eval-sanitize-1-r3-196-s7qb9.18d4a2d5c428d787,"reason=FailedScheduling count=None msg=0/6 nodes are available: 1 c_wall violated: 1 conflicting context pair(s) with node memory, 5 node(s) had untolerated taint(s). no new claims to deallocate, preemption: 0/6 nodes are available: 1 No preemption victims found for incoming pod, 5 Preemption is not helpful for scheduling."
0.3232,Event,ADDED,eval-sanitize-1-r3-196-s7qb9.18d4a2d5d04ce90a,"reason=FailedScheduling count=None msg=0/6 nodes are available: 1 c_wall violated: 1 conflicting context pair(s) with node memory, 5 node(s) had untolerated taint(s). no new claims to deallocate, preemption: 0/6 nodes are available: 1 No preemption victims found for incoming pod, 5 Preemption is not helpful for scheduling."
0.3233,Event,ADDED,eval-sanitize-1-r3-196-s7qb9.18d4a2d606c304d7,"reason=FailedScheduling count=None msg=0/6 nodes are available: 2 c_wall violated: 1 conflicting context pair(s) with node memory, 4 node(s) had untolerated taint(s). no new claims to deallocate, preemption: 0/6 nodes are available: 2 No preemption victims found for incoming pod, 4 Preemption is not helpful for scheduling."
0.3235,Event,ADDED,eval-sanitize-1-r3-196-s7qb9.18d4a2d63225c74c,"reason=FailedScheduling count=None msg=0/6 nodes are available: 1 c_wall violated: 1 conflicting context pair(s) with node memory, 5 node(s) had untolerated taint(s). no new claims to deallocate, preemption: 0/6 nodes are available: 1 No preemption victims found for incoming pod, 5 Preemption is not helpful for scheduling."
0.3237,Event,ADDED,eval-sanitize-1-r3-196-s7qb9.18d4a2d699698723,"reason=FailedScheduling count=None msg=0/6 nodes are available: 1 c_wall violated: 1 conflicting context pair(s) with node memory, 5 node(s) had untolerated taint(s). no new claims to deallocate, preemption: 0/6 nodes are available: 1 No preemption victims found for incoming pod, 5 Preemption is not helpful for scheduling."
0.3239,Event,ADDED,eval-sanitize-1-r3-196-s7qb9.18d4a2d69ad7c4bb,"reason=FailedScheduling count=None msg=0/6 nodes are available: 1 c_wall violated: 1 conflicting context pair(s) with node memory, 5 node(s) had untolerated taint(s). no new claims to deallocate, preemption: 0/6 nodes are available: 1 No preemption victims found for incoming pod, 5 Preemption is not helpful for scheduling."
0.324,Event,ADDED,eval-sanitize-1-r3-196-s7qb9.18d4a2d6d1c57bcf,"reason=FailedScheduling count=None msg=0/6 nodes are available: 2 c_wall violated: 1 conflicting context pair(s) with node memory, 4 node(s) had untolerated taint(s). no new claims to deallocate, preemption: 0/6 nodes are available: 2 No preemption victims found for incoming pod, 4 Preemption is not helpful for scheduling."
0.3242,Event,ADDED,eval-sanitize-1-r3-196-s7qb9.18d4a2d6e4a32a88,"reason=FailedScheduling count=None msg=0/6 nodes are available: 1 c_wall violated: 1 conflicting context pair(s) with node memory, 5 node(s) had untolerated taint(s). no new claims to deallocate, preemption: 0/6 nodes are available: 1 No preemption victims found for incoming pod, 5 Preemption is not helpful for scheduling."
0.3244,Event,ADDED,eval-sanitize-1-r3-196-s7qb9.18d4a2dc19ce6b7d,reason=Scheduled count=None msg=Successfully assigned compute/eval-sanitize-1-r3-196-s7qb9 to kind-worker5
0.3245,Event,ADDED,eval-sanitize-1-r3-196-s7qb9.18d4a2dc384fd58d,"reason=Pulled count=1 msg=Container image ""busybox:musl"" already present on machine"
0.3247,Event,ADDED,eval-sanitize-1-r3-196-s7qb9.18d4a2dc39b203b9,reason=Created count=1 msg=Created container: task
0.3249,Event,ADDED,eval-sanitize-1-r3-196-s7qb9.18d4a2dc4792a0f4,reason=Started count=1 msg=Started container task
0.325,Event,ADDED,eval-sanitize-1-r3-196.18d4a2d5aa08b7fd,reason=SuccessfulCreate count=1 msg=Created pod: eval-sanitize-1-r3-196-s7qb9
0.3255,Event,ADDED,eval-sanitize-1-r3-196.18d4a2e1b7400024,reason=Completed count=1 msg=Job completed
0.3261,Event,ADDED,eval-sanitize-1-r3-197-9dzlf.18d4a2d639f03873,"reason=FailedScheduling count=None msg=0/6 nodes are available: 1 c_wall violated: 1 conflicting context pair(s) with node memory, 5 node(s) had untolerated taint(s). no new claims to deallocate, preemption: 0/6 nodes are available: 1 No preemption victims found for incoming pod, 5 Preemption is not helpful for scheduling."
0.3263,Event,ADDED,eval-sanitize-1-r3-197-9dzlf.18d4a2d63bbd3bc1,"reason=FailedScheduling count=None msg=0/6 nodes are available: 1 c_wall violated: 1 conflicting context pair(s) with node memory, 5 node(s) had untolerated taint(s). no new claims to deallocate, preemption: 0/6 nodes are available: 1 No preemption victims found for incoming pod, 5 Preemption is not helpful for scheduling."
0.3265,Event,ADDED,eval-sanitize-1-r3-197-9dzlf.18d4a2d6974b2d26,reason=Scheduled count=None msg=Successfully assigned compute/eval-sanitize-1-r3-197-9dzlf to kind-worker4
0.3269,Event,ADDED,eval-sanitize-1-r3-197-9dzlf.18d4a2d6b178a995,"reason=Pulled count=1 msg=Container image ""busybox:musl"" already present on machine"
0.3271,Event,ADDED,eval-sanitize-1-r3-197-9dzlf.18d4a2d6b36835a1,reason=Created count=1 msg=Created container: task
0.3273,Event,ADDED,eval-sanitize-1-r3-197-9dzlf.18d4a2d6b72ee589,reason=Started count=1 msg=Started container task
0.3274,Event,ADDED,eval-sanitize-1-r3-197.18d4a2d639ab355c,reason=SuccessfulCreate count=1 msg=Created pod: eval-sanitize-1-r3-197-9dzlf
0.3276,Event,ADDED,eval-sanitize-1-r3-197.18d4a2dc5543e103,reason=Completed count=1 msg=Job completed
0.3278,Event,ADDED,eval-sanitize-1-r3-198-dv5m9.18d4a2d68744eba6,"reason=FailedScheduling count=None msg=0/6 nodes are available: 6 node(s) had untolerated taint(s). no new claims to deallocate, preemption: 0/6 nodes are available: 6 Preemption is not helpful for scheduling."
0.328,Event,ADDED,eval-sanitize-1-r3-198-dv5m9.18d4a2d69a0e8c47,"reason=FailedScheduling count=None msg=0/6 nodes are available: 1 c_wall violated: 1 conflicting context pair(s) with node memory, 5 node(s) had untolerated taint(s). no new claims to deallocate, preemption: 0/6 nodes are available: 1 No preemption victims found for incoming pod, 5 Preemption is not helpful for scheduling."
0.3282,Event,ADDED,eval-sanitize-1-r3-198-dv5m9.18d4a2d69b194e12,"reason=FailedScheduling count=None msg=0/6 nodes are available: 1 c_wall violated: 1 conflicting context pair(s) with node memory, 5 node(s) had untolerated taint(s). no new claims to deallocate, preemption: 0/6 nodes are available: 1 No preemption victims found for incoming pod, 5 Preemption is not helpful for scheduling."
0.3284,Event,ADDED,eval-sanitize-1-r3-198-dv5m9.18d4a2d6d5fd72a4,"reason=FailedScheduling count=None msg=0/6 nodes are available: 2 c_wall violated: 1 conflicting context pair(s) with node memory, 4 node(s) had untolerated taint(s). no new claims to deallocate, preemption: 0/6 nodes are available: 2 No preemption victims found for incoming pod, 4 Preemption is not helpful for scheduling."
0.3286,Event,ADDED,eval-sanitize-1-r3-198-dv5m9.18d4a2d6e424db43,"reason=FailedScheduling count=None msg=0/6 nodes are available: 1 c_wall violated: 2 conflicting context pair(s) with node memory, 5 node(s) had untolerated taint(s). no new claims to deallocate, preemption: 0/6 nodes are available: 1 No preemption victims found for incoming pod, 5 Preemption is not helpful for scheduling."
0.3289,Event,ADDED,eval-sanitize-1-r3-198-dv5m9.18d4a2d6e4d297d4,"reason=FailedScheduling count=None msg=0/6 nodes are available: 1 c_wall violated: 2 conflicting context pair(s) with node memory, 5 node(s) had untolerated taint(s). no new claims to deallocate, preemption: 0/6 nodes are available: 1 No preemption victims found for incoming pod, 5 Preemption is not helpful for scheduling."
0.3291,Event,ADDED,eval-sanitize-1-r3-198-dv5m9.18d4a2dc1a06c695,"reason=FailedScheduling count=None msg=0/6 nodes are available: 1 c_wall violated: 1 conflicting context pair(s) with node memory, 5 node(s) had untolerated taint(s). no new claims to deallocate, preemption: 0/6 nodes are available: 1 No preemption victims found for incoming pod, 5 Preemption is not helpful for scheduling."
0.3292,Event,ADDED,eval-sanitize-1-r3-198-dv5m9.18d4a2dc1aeae80e,"reason=FailedScheduling count=None msg=0/6 nodes are available: 1 c_wall violated: 1 conflicting context pair(s) with node memory, 5 node(s) had untolerated taint(s). no new claims to deallocate, preemption: 0/6 nodes are available: 1 No preemption victims found for incoming pod, 5 Preemption is not helpful for scheduling."
0.3295,Event,ADDED,eval-sanitize-1-r3-198-dv5m9.18d4a2dc2443b943,reason=Scheduled count=None msg=Successfully assigned compute/eval-sanitize-1-r3-198-dv5m9 to kind-worker2
0.3297,Event,ADDED,eval-sanitize-1-r3-198-dv5m9.18d4a2dc47812450,"reason=Pulled count=1 msg=Container image ""busybox:musl"" already present on machine"
0.3299,Event,ADDED,eval-sanitize-1-r3-198-dv5m9.18d4a2dc48c044a4,reason=Created count=1 msg=Created container: task
0.3303,Event,ADDED,eval-sanitize-1-r3-198-dv5m9.18d4a2dc4d997f14,reason=Started count=1 msg=Started container task
0.3305,Event,ADDED,eval-sanitize-1-r3-198.18d4a2d6873702f7,reason=SuccessfulCreate count=1 msg=Created pod: eval-sanitize-1-r3-198-dv5m9
0.3306,Event,ADDED,eval-sanitize-1-r3-198.18d4a2e1d6d58f28,reason=Completed count=1 msg=Job completed
0.3308,Event,ADDED,eval-sanitize-1-r3-199-67525.18d4a2d6e129eda1,reason=Scheduled count=None msg=Successfully assigned compute/eval-sanitize-1-r3-199-67525 to kind-worker3
0.3311,Event,ADDED,eval-sanitize-1-r3-199-67525.18d4a2d6fa1d9d02,"reason=Pulled count=1 msg=Container image ""busybox:musl"" already present on machine"
0.3312,Event,ADDED,eval-sanitize-1-r3-199-67525.18d4a2d6fb66f161,reason=Created count=1 msg=Created container: task
0.3314,Event,ADDED,eval-sanitize-1-r3-199-67525.18d4a2d704ad2143,reason=Started count=1 msg=Started container task
0.3316,Event,ADDED,eval-sanitize-1-r3-199.18d4a2d6e0711b7d,reason=SuccessfulCreate count=1 msg=Created pod: eval-sanitize-1-r3-199-67525
0.3318,Event,ADDED,eval-sanitize-1-r3-199.18d4a2dc87cbb6bf,reason=Completed count=1 msg=Job completed
0.332,Event,ADDED,eval-sanitize-1-r4-000-mqg7v.18d4a2eca4386633,reason=Scheduled count=None msg=Successfully assigned compute/eval-sanitize-1-r4-000-mqg7v to kind-worker3
0.3321,Event,ADDED,eval-sanitize-1-r4-000-mqg7v.18d4a2ecc0d16a6e,"reason=Pulled count=1 msg=Container image ""busybox:musl"" already present on machine"
0.3323,Event,ADDED,eval-sanitize-1-r4-000-mqg7v.18d4a2ecc1f40829,reason=Created count=1 msg=Created container: task
0.3328,Event,ADDED,eval-sanitize-1-r4-000-mqg7v.18d4a2ecc76f95f6,reason=Started count=1 msg=Started container task
0.333,Event,ADDED,eval-sanitize-1-r4-000.18d4a2eca31de774,reason=SuccessfulCreate count=1 msg=Created pod: eval-sanitize-1-r4-000-mqg7v
0.3331,Event,ADDED,eval-sanitize-1-r4-000.18d4a2f2365d8353,reason=Completed count=1 msg=Job completed
0.3334,Event,ADDED,eval-sanitize-1-r4-001-c7wnw.18d4a2ecdfe5224c,reason=Scheduled count=None msg=Successfully assigned compute/eval-sanitize-1-r4-001-c7wnw to kind-worker
0.3336,Event,ADDED,eval-sanitize-1-r4-001-c7wnw.18d4a2ecf98fccbc,"reason=Pulled count=1 msg=Container image ""busybox:musl"" already present on machine"
0.3338,Event,ADDED,eval-sanitize-1-r4-001-c7wnw.18d4a2ecfab66d02,reason=Created count=1 msg=Created container: task
0.3339,Event,ADDED,eval-sanitize-1-r4-001-c7wnw.18d4a2ecfede6d81,reason=Started count=1 msg=Started container task
0.3342,Event,ADDED,eval-sanitize-1-r4-001.18d4a2ecdd2bdd65,reason=SuccessfulCreate count=1 msg=Created pod: eval-sanitize-1-r4-001-c7wnw
0.3343,Event,ADDED,eval-sanitize-1-r4-001.18d4a2f28227ad79,reason=Completed count=1 msg=Job completed
0.3345,Event,ADDED,eval-sanitize-1-r4-002-zt7zf.18d4a2ed19555a23,reason=Scheduled count=None msg=Successfully assigned compute/eval-sanitize-1-r4-002-zt7zf to kind-worker5
0.3347,Event,ADDED,eval-sanitize-1-r4-002-zt7zf.18d4a2ed35de1f31,"reason=Pulled count=1 msg=Container image ""busybox:musl"" already present on machine"
0.3349,Event,ADDED,eval-sanitize-1-r4-002-zt7zf.18d4a2ed36f15303,reason=Created count=1 msg=Created container: task
0.3351,Event,ADDED,eval-sanitize-1-r4-002-zt7zf.18d4a2ed3c12aafc,reason=Started count=1 msg=Started container task
0.3352,Event,ADDED,eval-sanitize-1-r4-002.18d4a2ed18987219,reason=SuccessfulCreate count=1 msg=Created pod: eval-sanitize-1-r4-002-zt7zf
0.3357,Event,ADDED,eval-sanitize-1-r4-002.18d4a2f2bf1d1776,reason=Completed count=1 msg=Job completed
0.3359,Event,ADDED,eval-sanitize-1-r4-003-qkshd.18d4a2ed54a83258,reason=Scheduled count=None msg=Successfully assigned compute/eval-sanitize-1-r4-003-qkshd to kind-worker2
0.336,Event,ADDED,eval-sanitize-1-r4-003-qkshd.18d4a2ed7082617d,"reason=Pulled count=1 msg=Container image ""busybox:musl"" already present on machine"
0.3362,Event,ADDED,eval-sanitize-1-r4-003-qkshd.18d4a2ed71a50cc2,reason=Created count=1 msg=Created container: task
0.3364,Event,ADDED,eval-sanitize-1-r4-003-qkshd.18d4a2ed7899c6ea,reason=Started count=1 msg=Started container task
0.3365,Event,ADDED,eval-sanitize-1-r4-003.18d4a2ed5418e19f,reason=SuccessfulCreate count=1 msg=Created pod: eval-sanitize-1-r4-003-qkshd
0.3367,Event,ADDED,eval-sanitize-1-r4-003.18d4a2f3226977ba,reason=Completed count=1 msg=Job completed
0.3369,Event,ADDED,eval-sanitize-1-r4-004-tsn2c.18d4a2ed95744328,reason=Scheduled count=None msg=Successfully assigned compute/eval-sanitize-1-r4-004-tsn2c to kind-worker4
0.337,Event,ADDED,eval-sanitize-1-r4-004-tsn2c.18d4a2edb0991abc,"reason=Pulled count=1 msg=Container image ""busybox:musl"" already present on machine"
0.3372,Event,ADDED,eval-sanitize-1-r4-004-tsn2c.18d4a2edb1aa9148,reason=Created count=1 msg=Created container: task
0.3373,Event,ADDED,eval-sanitize-1-r4-004-tsn2c.18d4a2edb65a651d,reason=Started count=1 msg=Started container task
0.3375,Event,ADDED,eval-sanitize-1-r4-004.18d4a2ed95110d17,reason=SuccessfulCreate count=1 msg=Created pod: eval-sanitize-1-r4-004-tsn2c
0.3377,Event,ADDED,eval-sanitize-1-r4-004.18d4a2f3228e611f,reason=Completed count=1 msg=Job completed
0.3378,Event,ADDED,eval-sanitize-1-r4-005-9msdv.18d4a2edcf222fa8,"reason=FailedScheduling count=None msg=0/6 nodes are available: 6 node(s) had untolerated taint(s). no new claims to deallocate, preemption: 0/6 nodes are available: 6 Preemption is not helpful for scheduling."
0.338,Event,ADDED,eval-sanitize-1-r4-005-9msdv.18d4a2f1cb310da8,reason=Scheduled count=None msg=Successfully assigned compute/eval-sanitize-1-r4-005-9msdv to kind-worker3
0.3381,Event,ADDED,eval-sanitize-1-r4-005-9msdv.18d4a2f1e4e45ff0,"reason=Pulled count=1 msg=Container image ""busybox:musl"" already present on machine"
0.3383,Event,ADDED,eval-sanitize-1-r4-005-9msdv.18d4a2f1e6c5a9d7,reason=Created count=1 msg=Created container: task
0.3385,Event,ADDED,eval-sanitize-1-r4-005-9msdv.18d4a2f1ef2b0fe9,reason=Started count=1 msg=Started container task
0.3386,Event,ADDED,eval-sanitize-1-r4-005.18d4a2edcf164ef0,reason=SuccessfulCreate count=1 msg=Created pod: eval-sanitize-1-r4-005-9msdv
0.3388,Event,ADDED,eval-sanitize-1-r4-005.18d4a2f7510fbd09,reason=Completed count=1 msg=Job completed
0.339,Event,ADDED,eval-sanitize-1-r4-006-dxb7p.18d4a2ee07a0897e,"reason=FailedScheduling count=None msg=0/6 nodes are available: 6 node(s) had untolerated taint(s). no new claims to deallocate, preemption: 0/6 nodes are available: 6 Preemption is not helpful for scheduling."
0.3391,Event,ADDED,eval-sanitize-1-r4-006-dxb7p.18d4a2f1cb42ad4f,"reason=FailedScheduling count=None msg=0/6 nodes are available: 1 c_wall violated: 1 conflicting context pair(s) with node memory, 5 node(s) had untolerated taint(s). no new claims to deallocate, preemption: 0/6 nodes are available: 1 No preemption victims found for incoming pod, 5 Preemption is not helpful for scheduling."
0.3393,Event,ADDED,eval-sanitize-1-r4-006-dxb7p.18d4a2f1e133432c,"reason=FailedScheduling count=None msg=0/6 nodes are available: 1 c_wall violated: 3 conflicting context pair(s) with node memory, 5 node(s) had untolerated taint(s). no new claims to deallocate, preemption: 0/6 nodes are available: 1 No preemption victims found for incoming pod, 5 Preemption is not helpful for scheduling."
0.3395,Event,ADDED,eval-sanitize-1-r4-006-dxb7p.18d4a2f1eb5e1882,"reason=FailedScheduling count=None msg=0/6 nodes are available: 1 c_wall violated: 3 conflicting context pair(s) with node memory, 5 node(s) had untolerated taint(s). no new claims to deallocate, preemption: 0/6 nodes are available: 1 No preemption victims found for incoming pod, 5 Preemption is not helpful for scheduling."
0.3396,Event,ADDED,eval-sanitize-1-r4-006-dxb7p.18d4a2f2538f04db,reason=Scheduled count=None msg=Successfully assigned compute/eval-sanitize-1-r4-006-dxb7p to kind-worker
0.3402,Event,ADDED,eval-sanitize-1-r4-006-dxb7p.18d4a2f26a7d8845,"reason=Pulled count=1 msg=Container image ""busybox:musl"" already present on machine"
0.3404,Event,ADDED,eval-sanitize-1-r4-006-dxb7p.18d4a2f26c9ea009,reason=Created count=1 msg=Created container: task
0.3406,Event,ADDED,eval-sanitize-1-r4-006-dxb7p.18d4a2f275f9aa9a,reason=Started count=1 msg=Started container task
0.3408,Event,ADDED,eval-sanitize-1-r4-006.18d4a2ee0795cec0,reason=SuccessfulCreate count=1 msg=Created pod: eval-sanitize-1-r4-006-dxb7p
0.3411,Event,ADDED,eval-sanitize-1-r4-006.18d4a2f88f1736c9,reason=Completed count=1 msg=Job completed
0.3413,Event,ADDED,eval-sanitize-1-r4-007-twdvc.18d4a2ee42848ce9,"reason=FailedScheduling count=None msg=0/6 nodes are available: 6 node(s) had untolerated taint(s). no new claims to deallocate, preemption: 0/6 nodes are available: 6 Preemption is not helpful for scheduling."
0.3414,Event,ADDED,eval-sanitize-1-r4-007-twdvc.18d4a2f1cbe083a8,"reason=FailedScheduling count=None msg=0/6 nodes are available: 1 c_wall violated: 1 conflicting context pair(s) with node memory, 5 node(s) had untolerated taint(s). no new claims to deallocate, preemption: 0/6 nodes are available: 1 No preemption victims found for incoming pod, 5 Preemption is not helpful for scheduling."
0.342,Event,ADDED,eval-sanitize-1-r4-007-twdvc.18d4a2f1e1ac90a2,"reason=FailedScheduling count=None msg=0/6 nodes are available: 1 c_wall violated: 1 conflicting context pair(s) with node memory, 5 node(s) had untolerated taint(s). no new claims to deallocate, preemption: 0/6 nodes are available: 1 No preemption victims found for incoming pod, 5 Preemption is not helpful for scheduling."
0.3422,Event,ADDED,eval-sanitize-1-r4-007-twdvc.18d4a2f2597d5179,"reason=FailedScheduling count=None msg=0/6 nodes are available: 1 c_wall violated: 1 conflicting context pair(s) with node memory, 5 node(s) had untolerated taint(s). no new claims to deallocate, preemption: 0/6 nodes are available: 1 No preemption victims found for incoming pod, 5 Preemption is not helpful for scheduling."
0.3424,Event,ADDED,eval-sanitize-1-r4-007-twdvc.18d4a2f25c256873,"reason=FailedScheduling count=None msg=0/6 nodes are available: 1 c_wall violated: 1 conflicting context pair(s) with node memory, 5 node(s) had untolerated taint(s). no new claims to deallocate, preemption: 0/6 nodes are available: 1 No preemption victims found for incoming pod, 5 Preemption is not helpful for scheduling."
0.3427,Event,ADDED,eval-sanitize-1-r4-007-twdvc.18d4a2f2815bd8e1,reason=Scheduled count=None msg=Successfully assigned compute/eval-sanitize-1-r4-007-twdvc to kind-worker5
0.3429,Event,ADDED,eval-sanitize-1-r4-007-twdvc.18d4a2f2a394c0a3,"reason=Pulled count=1 msg=Container image ""busybox:musl"" already present on machine"
0.343,Event,ADDED,eval-sanitize-1-r4-007-twdvc.18d4a2f2a562b451,reason=Created count=1 msg=Created container: task
0.3432,Event,ADDED,eval-sanitize-1-r4-007-twdvc.18d4a2f2aa073d21,reason=Started count=1 msg=Started container task
0.3435,Event,ADDED,eval-sanitize-1-r4-007.18d4a2ee42764a92,reason=SuccessfulCreate count=1 msg=Created pod: eval-sanitize-1-r4-007-twdvc
0.3437,Event,ADDED,eval-sanitize-1-r4-007.18d4a2f926e10f98,reason=Completed count=1 msg=Job completed
0.3438,Event,ADDED,eval-sanitize-1-r4-008-cft9w.18d4a2ee7fe7241e,"reason=FailedScheduling count=None msg=0/6 nodes are available: 6 node(s) had untolerated taint(s). no new claims to deallocate, preemption: 0/6 nodes are available: 6 Preemption is not helpful for scheduling."
0.3441,Event,ADDED,eval-sanitize-1-r4-008-cft9w.18d4a2f1cc7e3431,"reason=FailedScheduling count=None msg=0/6 nodes are available: 1 c_wall violated: 1 conflicting context pair(s) with node memory, 5 node(s) had untolerated taint(s). no new claims to deallocate, preemption: 0/6 nodes are available: 1 No preemption victims found for incoming pod, 5 Preemption is not helpful for scheduling."
0.3442,Event,ADDED,eval-sanitize-1-r4-008-cft9w.18d4a2f1e253084f,"reason=FailedScheduling count=None msg=0/6 nodes are available: 1 c_wall violated: 3 conflicting context pair(s) with node memory, 5 node(s) had untolerated taint(s). no new claims to deallocate, preemption: 0/6 nodes are available: 1 No preemption victims found for incoming pod, 5 Preemption is not helpful for scheduling."
0.3444,Event,ADDED,eval-sanitize-1-r4-008-cft9w.18d4a2f1eb8b6909,"reason=FailedScheduling count=None msg=0/6 nodes are available: 1 c_wall violated: 3 conflicting context pair(s) with node memory, 5 node(s) had untolerated taint(s). no new claims to deallocate, preemption: 0/6 nodes are available: 1 No preemption victims found for incoming pod, 5 Preemption is not helpful for scheduling."
0.3448,Event,ADDED,eval-sanitize-1-r4-008-cft9w.18d4a2f250bea61d,"reason=FailedScheduling count=None msg=0/6 nodes are available: 1 c_wall violated: 1 conflicting context pair(s) with node memory, 5 node(s) had untolerated taint(s). no new claims to deallocate, preemption: 0/6 nodes are available: 1 No preemption victims found for incoming pod, 5 Preemption is not helpful for scheduling."
0.345,Event,ADDED,eval-sanitize-1-r4-008-cft9w.18d4a2f25aec1d50,"reason=FailedScheduling count=None msg=0/6 nodes are available: 1 c_wall violated: 1 conflicting context pair(s) with node memory, 5 node(s) had untolerated taint(s). no new claims to deallocate, preemption: 0/6 nodes are available: 1 No preemption victims found for incoming pod, 5 Preemption is not helpful for scheduling."
0.3453,Event,ADDED,eval-sanitize-1-r4-008-cft9w.18d4a2f2882bc907,"reason=FailedScheduling count=None msg=0/6 nodes are available: 1 c_wall violated: 1 conflicting context pair(s) with node memory, 1 c_wall violated: 2 conflicting context pair(s) with node memory, 4 node(s) had untolerated taint(s). no new claims to deallocate, preemption: 0/6 nodes are available: 2 No preemption victims found for incoming pod, 4 Preemption is not helpful for scheduling."
0.3455,Event,ADDED,eval-sanitize-1-r4-008-cft9w.18d4a2f28cf97cb1,"reason=FailedScheduling count=None msg=0/6 nodes are available: 1 c_wall violated: 2 conflicting context pair(s) with node memory, 5 node(s) had untolerated taint(s). no new claims to deallocate, preemption: 0/6 nodes are available: 1 No preemption victims found for incoming pod, 5 Preemption is not helpful for scheduling."
0.3457,Event,ADDED,eval-sanitize-1-r4-008-cft9w.18d4a2f29196a5f1,"reason=FailedScheduling count=None msg=0/6 nodes are available: 1 c_wall violated: 2 conflicting context pair(s) with node memory, 5 node(s) had untolerated taint(s). no new claims to deallocate, preemption: 0/6 nodes are available: 1 No preemption victims found for incoming pod, 5 Preemption is not helpful for scheduling."
0.3458,Event,ADDED,eval-sanitize-1-r4-008-cft9w.18d4a2f2bad9d9a2,reason=Scheduled count=None msg=Successfully assigned compute/eval-sanitize-1-r4-008-cft9w to kind-worker2
0.346,Event,ADDED,eval-sanitize-1-r4-008-cft9w.18d4a2f2d80a4927,"reason=Pulled count=1 msg=Container image ""busybox:musl"" already present on machine"
0.3462,Event,ADDED,eval-sanitize-1-r4-008-cft9w.18d4a2f2dabbdf15,reason=Created count=1 msg=Created container: task
0.3464,Event,ADDED,eval-sanitize-1-r4-008-cft9w.18d4a2f2e2f18e9c,reason=Started count=1 msg=Started container task
0.3466,Event,ADDED,eval-sanitize-1-r4-008.18d4a2ee7fdde9b5,reason=SuccessfulCreate count=1 msg=Created pod: eval-sanitize-1-r4-008-cft9w
0.3468,Event,ADDED,eval-sanitize-1-r4-008.18d4a2f93e0f6dce,reason=Completed count=1 msg=Job completed
0.347,Event,ADDED,eval-sanitize-1-r4-009-vvlvr.18d4a2eeba2104b9,"reason=FailedScheduling count=None msg=0/6 nodes are available: 6 node(s) had untolerated taint(s). no new claims to deallocate, preemption: 0/6 nodes are available: 6 Preemption is not helpful for scheduling."
0.3471,Event,ADDED,eval-sanitize-1-r4-009-vvlvr.18d4a2f1cd0011ac,"reason=FailedScheduling count=None msg=0/6 nodes are available: 1 c_wall violated: 1 conflicting context pair(s) with node memory, 5 node(s) had untolerated taint(s). no new claims to deallocate, preemption: 0/6 nodes are available: 1 No preemption victims found for incoming pod, 5 Preemption is not helpful for scheduling."
0.3473,Event,ADDED,eval-sanitize-1-r4-009-vvlvr.18d4a2f1e3032817,"reason=FailedScheduling count=None msg=0/6 nodes are available: 1 c_wall violated: 3 conflicting context pair(s) with node memory, 5 node(s) had untolerated taint(s). no new claims to deallocate, preemption: 0/6 nodes are available: 1 No preemption victims found for incoming pod, 5 Preemption is not helpful for scheduling."
0.3475,Event,ADDED,eval-sanitize-1-r4-009-vvlvr.18d4a2f1ebb5bc21,"reason=FailedScheduling count=None msg=0/6 nodes are available: 1 c_wall violated: 3 conflicting context pair(s) with node memory, 5 node(s) had untolerated taint(s). no new claims to deallocate, preemption: 0/6 nodes are available: 1 No preemption victims found for incoming pod, 5 Preemption is not helpful for scheduling."
0.3477,Event,ADDED,eval-sanitize-1-r4-009-vvlvr.18d4a2f25903cd1b,reason=Scheduled count=None msg=Successfully assigned compute/eval-sanitize-1-r4-009-vvlvr to kind-worker
0.3478,Event,ADDED,eval-sanitize-1-r4-009-vvlvr.18d4a2f27cf9deab,"reason=Pulled count=1 msg=Container image ""busybox:musl"" already present on machine"
0.348,Event,ADDED,eval-sanitize-1-r4-009-vvlvr.18d4a2f27f88cf7f,reason=Created count=1 msg=Created container: task
0.3482,Event,ADDED,eval-sanitize-1-r4-009-vvlvr.18d4a2f288fc65c3,reason=Started count=1 msg=Started container task
0.3484,Event,ADDED,eval-sanitize-1-r4-009.18d4a2eeba15edf1,reason=SuccessfulCreate count=1 msg=Created pod: eval-sanitize-1-r4-009-vvlvr
0.3487,Event,ADDED,eval-sanitize-1-r4-009.18d4a2f91772ca33,reason=Completed count=1 msg=Job completed
0.3488,Event,ADDED,eval-sanitize-1-r4-010-pd9hn.18d4a2eef51ef5ec,"reason=FailedScheduling count=None msg=0/6 nodes are available: 6 node(s) had untolerated taint(s). no new claims to deallocate, preemption: 0/6 nodes are available: 6 Preemption is not helpful for scheduling."
0.349,Event,ADDED,eval-sanitize-1-r4-010-pd9hn.18d4a2f1cd8cfea7,"reason=FailedScheduling count=None msg=0/6 nodes are available: 1 c_wall violated: 1 conflicting context pair(s) with node memory, 5 node(s) had untolerated taint(s). no new claims to deallocate, preemption: 0/6 nodes are available: 1 No preemption victims found for incoming pod, 5 Preemption is not helpful for scheduling."
0.3493,Event,ADDED,eval-sanitize-1-r4-010-pd9hn.18d4a2f1e3a4905f,"reason=FailedScheduling count=None msg=0/6 nodes are available: 1 c_wall violated: 3 conflicting context pair(s) with node memory, 5 node(s) had untolerated taint(s). no new claims to deallocate, preemption: 0/6 nodes are available: 1 No preemption victims found for incoming pod, 5 Preemption is not helpful for scheduling."
0.3495,Event,ADDED,eval-sanitize-1-r4-010-pd9hn.18d4a2f1f0ac7a30,"reason=FailedScheduling count=None msg=0/6 nodes are available: 1 c_wall violated: 3 conflicting context pair(s) with node memory, 5 node(s) had untolerated taint(s). no new claims to deallocate, preemption: 0/6 nodes are available: 1 No preemption victims found for incoming pod, 5 Preemption is not helpful for scheduling."
0.3497,Event,ADDED,eval-sanitize-1-r4-010-pd9hn.18d4a2f253f9079e,"reason=FailedScheduling count=None msg=0/6 nodes are available: 1 c_wall violated: 1 conflicting context pair(s) with node memory, 5 node(s) had untolerated taint(s). no new claims to deallocate, preemption: 0/6 nodes are available: 1 No preemption victims found for incoming pod, 5 Preemption is not helpful for scheduling."
0.3499,Event,ADDED,eval-sanitize-1-r4-010-pd9hn.18d4a2f25bfcd30a,"reason=FailedScheduling count=None msg=0/6 nodes are available: 1 c_wall violated: 1 conflicting context pair(s) with node memory, 5 node(s) had untolerated taint(s). no new claims to deallocate, preemption: 0/6 nodes are available: 1 No preemption victims found for incoming pod, 5 Preemption is not helpful for scheduling."
0.3501,Event,ADDED,eval-sanitize-1-r4-010-pd9hn.18d4a2f28bb03915,"reason=FailedScheduling count=None msg=0/6 nodes are available: 1 c_wall violated: 1 conflicting context pair(s) with node memory, 1 c_wall violated: 2 conflicting context pair(s) with node memory, 4 node(s) had untolerated taint(s). no new claims to deallocate, preemption: 0/6 nodes are available: 2 No preemption victims found for incoming pod, 4 Preemption is not helpful for scheduling."
0.3502,Event,ADDED,eval-sanitize-1-r4-010-pd9hn.18d4a2f28d7ef7d7,"reason=FailedScheduling count=None msg=0/6 nodes are available: 1 c_wall violated: 2 conflicting context pair(s) with node memory, 5 node(s) had untolerated taint(s). no new claims to deallocate, preemption: 0/6 nodes are available: 1 No preemption victims found for incoming pod, 5 Preemption is not helpful for scheduling."
0.3504,Event,ADDED,eval-sanitize-1-r4-010-pd9hn.18d4a2f291d0b57f,"reason=FailedScheduling count=None msg=0/6 nodes are available: 1 c_wall violated: 2 conflicting context pair(s) with node memory, 5 node(s) had untolerated taint(s). no new claims to deallocate, preemption: 0/6 nodes are available: 1 No preemption victims found for incoming pod, 5 Preemption is not helpful for scheduling."
0.3506,Event,ADDED,eval-sanitize-1-r4-010-pd9hn.18d4a2f2ba5785cc,reason=Scheduled count=None msg=Successfully assigned compute/eval-sanitize-1-r4-010-pd9hn to kind-worker2
0.3507,Event,ADDED,eval-sanitize-1-r4-010-pd9hn.18d4a2f2d7f65ccf,"reason=Pulled count=1 msg=Container image ""busybox:musl"" already present on machine"
0.3509,Event,ADDED,eval-sanitize-1-r4-010-pd9hn.18d4a2f2d9c9c7da,reason=Created count=1 msg=Created container: task
0.3515,Event,ADDED,eval-sanitize-1-r4-010-pd9hn.18d4a2f2e2f1da2a,reason=Started count=1 msg=Started container task
0.3517,Event,ADDED,eval-sanitize-1-r4-010.18d4a2eef5144e84,reason=SuccessfulCreate count=1 msg=Created pod: eval-sanitize-1-r4-010-pd9hn
0.3518,Event,ADDED,eval-sanitize-1-r4-010.18d4a2f94625dc4d,reason=Completed count=1 msg=Job completed
0.3521,Event,ADDED,eval-sanitize-1-r4-011-jljh7.18d4a2ef36623bb0,"reason=FailedScheduling count=None msg=0/6 nodes are available: 6 node(s) had untolerated taint(s). no new claims to deallocate, preemption: 0/6 nodes are available: 6 Preemption is not helpful for scheduling."
0.3522,Event,ADDED,eval-sanitize-1-r4-011-jljh7.18d4a2f1d0a5c7e3,"reason=FailedScheduling count=None msg=0/6 nodes are available: 1 c_wall violated: 1 conflicting context pair(s) with node memory, 5 node(s) had untolerated taint(s). no new claims to deallocate, preemption: 0/6 nodes are available: 1 No preemption victims found for incoming pod, 5 Preemption is not helpful for scheduling."
0.3524,Event,ADDED,eval-sanitize-1-r4-011-jljh7.18d4a2f1e4bc9d5c,"reason=FailedScheduling count=None msg=0/6 nodes are available: 1 c_wall violated: 2 conflicting context pair(s) with node memory, 5 node(s) had untolerated taint(s). no new claims to deallocate, preemption: 0/6 nodes are available: 1 No preemption victims found for incoming pod, 5 Preemption is not helpful for scheduling."
0.3526,Event,ADDED,eval-sanitize-1-r4-011-jljh7.18d4a2f1f0e3de20,"reason=FailedScheduling count=None msg=0/6 nodes are available: 1 c_wall violated: 2 conflicting context pair(s) with node memory, 5 node(s) had untolerated taint(s). no new claims to deallocate, preemption: 0/6 nodes are available: 1 No preemption victims found for incoming pod, 5 Preemption is not helpful for scheduling."
0.3527,Event,ADDED,eval-sanitize-1-r4-011-jljh7.18d4a2f259b1748b,reason=Scheduled count=None msg=Successfully assigned compute/eval-sanitize-1-r4-011-jljh7 to kind-worker
0.3529,Event,ADDED,eval-sanitize-1-r4-011-jljh7.18d4a2f27e572434,"reason=Pulled count=1 msg=Container image ""busybox:musl"" already present on machine"
0.3531,Event,ADDED,eval-sanitize-1-r4-011-jljh7.18d4a2f28074220c,reason=Created count=1 msg=Created container: task
0.3532,Event,ADDED,eval-sanitize-1-r4-011-jljh7.18d4a2f28999780a,reason=Started count=1 msg=Started container task
0.3534,Event,ADDED,eval-sanitize-1-r4-011.18d4a2ef365b2ff8,reason=SuccessfulCreate count=1 msg=Created pod: eval-sanitize-1-r4-011-jljh7
0.3536,Event,ADDED,eval-sanitize-1-r4-011.18d4a2f921c46e6f,reason=Completed count=1 msg=Job completed
0.3537,Event,ADDED,eval-sanitize-1-r4-012-nhb97.18d4a2ef6ebf890b,"reason=FailedScheduling count=None msg=0/6 nodes are available: 6 node(s) had untolerated taint(s). no new claims to deallocate, preemption: 0/6 nodes are available: 6 Preemption is not helpful for scheduling."
0.3539,Event,ADDED,eval-sanitize-1-r4-012-nhb97.18d4a2f1d189757f,reason=Scheduled count=None msg=Successfully assigned compute/eval-sanitize-1-r4-012-nhb97 to kind-worker3
0.354,Event,ADDED,eval-sanitize-1-r4-012-nhb97.18d4a2f1ef2ec703,"reason=Pulled count=1 msg=Container image ""busybox:musl"" already present on machine"
0.3542,Event,ADDED,eval-sanitize-1-r4-012-nhb97.18d4a2f1f1be8378,reason=Created count=1 msg=Created container: task
0.3544,Event,ADDED,eval-sanitize-1-r4-012-nhb97.18d4a2f1fa145b52,reason=Started count=1 msg=Started container task
0.3546,Event,ADDED,eval-sanitize-1-r4-012.18d4a2ef6eb49ce2,reason=SuccessfulCreate count=1 msg=Created pod: eval-sanitize-1-r4-012-nhb97
0.3547,Event,ADDED,eval-sanitize-1-r4-012.18d4a2f78d1e2535,reason=Completed count=1 msg=Job completed
0.3549,Event,ADDED,eval-sanitize-1-r4-013-pjt2d.18d4a2efa81f3144,"reason=FailedScheduling count=None msg=0/6 nodes are available: 6 node(s) had untolerated taint(s). no new claims to deallocate, preemption: 0/6 nodes are available: 6 Preemption is not helpful for scheduling."
0.355,Event,ADDED,eval-sanitize-1-r4-013-pjt2d.18d4a2f1d16386f9,"reason=FailedScheduling count=None msg=0/6 nodes are available: 1 c_wall violated: 2 conflicting context pair(s) with node memory, 5 node(s) had untolerated taint(s). no new claims to deallocate, preemption: 0/6 nodes are available: 1 No preemption victims found for incoming pod, 5 Preemption is not helpful for scheduling."
0.3552,Event,ADDED,eval-sanitize-1-r4-013-pjt2d.18d4a2f1e59bb7db,"reason=FailedScheduling count=None msg=0/6 nodes are available: 1 c_wall violated: 2 conflicting context pair(s) with node memory, 5 node(s) had untolerated taint(s). no new claims to deallocate, preemption: 0/6 nodes are available: 1 No preemption victims found for incoming pod, 5 Preemption is not helpful for scheduling."
0.3554,Event,ADDED,eval-sanitize-1-r4-013-pjt2d.18d4a2f24ad98585,reason=Scheduled count=None msg=Successfully assigned compute/eval-sanitize-1-r4-013-pjt2d to kind-worker
0.3555,Event,ADDED,eval-sanitize-1-r4-013-pjt2d.18d4a2f2671c1748,"reason=Pulled count=1 msg=Container image ""busybox:musl"" already present on machine"
0.3557,Event,ADDED,eval-sanitize-1-r4-013-pjt2d.18d4a2f268977f33,reason=Created count=1 msg=Created container: task
0.3559,Event,ADDED,eval-sanitize-1-r4-013-pjt2d.18d4a2f26b092487,reason=Started count=1 msg=Started container task
0.356,Event,ADDED,eval-sanitize-1-r4-013.18d4a2efa8142260,reason=SuccessfulCreate count=1 msg=Created pod: eval-sanitize-1-r4-013-pjt2d
0.3566,Event,ADDED,eval-sanitize-1-r4-013.18d4a2f888464d68,reason=Completed count=1 msg=Job completed
0.3568,Event,ADDED,eval-sanitize-1-r4-014-fv5nz.18d4a2efe395d6dd,"reason=FailedScheduling count=None msg=0/6 nodes are available: 6 node(s) had untolerated taint(s). no new claims to deallocate, preemption: 0/6 nodes are available: 6 Preemption is not helpful for scheduling."
0.3569,Event,ADDED,eval-sanitize-1-r4-014-fv5nz.18d4a2f1d1e7da01,"reason=FailedScheduling count=None msg=0/6 nodes are available: 1 c_wall violated: 2 conflicting context pair(s) with node memory, 5 node(s) had untolerated taint(s). no new claims to deallocate, preemption: 0/6 nodes are available: 1 No preemption victims found for incoming pod, 5 Preemption is not helpful for scheduling."
0.3572,Event,ADDED,eval-sanitize-1-r4-014-fv5nz.18d4a2f1e6670873,"reason=FailedScheduling count=None msg=0/6 nodes are available: 1 c_wall violated: 2 conflicting context pair(s) with node memory, 5 node(s) had untolerated taint(s). no new claims to deallocate, preemption: 0/6 nodes are available: 1 No preemption victims found for incoming pod, 5 Preemption is not helpful for scheduling."
0.3573,Event,ADDED,eval-sanitize-1-r4-014-fv5nz.18d4a2f24b51f336,reason=Scheduled count=None msg=Successfully assigned compute/eval-sanitize-1-r4-014-fv5nz to kind-worker
0.3575,Event,ADDED,eval-sanitize-1-r4-014-fv5nz.18d4a2f2690386d9,"reason=Pulled count=1 msg=Container image ""busybox:musl"" already present on machine"
0.3577,Event,ADDED,eval-sanitize-1-r4-014-fv5nz.18d4a2f26bda7993,reason=Created count=1 msg=Created container: task
0.3581,Event,ADDED,eval-sanitize-1-r4-014-fv5nz.18d4a2f275fc082e,reason=Started count=1 msg=Started container task
0.3583,Event,ADDED,eval-sanitize-1-r4-014.18d4a2efe3879511,reason=SuccessfulCreate count=1 msg=Created pod: eval-sanitize-1-r4-014-fv5nz
0.3585,Event,ADDED,eval-sanitize-1-r4-014.18d4a2f870611581,reason=Completed count=1 msg=Job completed
0.3587,Event,ADDED,eval-sanitize-1-r4-015-z76gx.18d4a2f01f1e76c4,"reason=FailedScheduling count=None msg=0/6 nodes are available: 6 node(s) had untolerated taint(s). no new claims to deallocate, preemption: 0/6 nodes are available: 6 Preemption is not helpful for scheduling."
0.3588,Event,ADDED,eval-sanitize-1-r4-015-z76gx.18d4a2f1d29861bc,"reason=FailedScheduling count=None msg=0/6 nodes are available: 1 c_wall violated: 2 conflicting context pair(s) with node memory, 5 node(s) had untolerated taint(s). no new claims to deallocate, preemption: 0/6 nodes are available: 1 No preemption victims found for incoming pod, 5 Preemption is not helpful for scheduling."
0.359,Event,ADDED,eval-sanitize-1-r4-015-z76gx.18d4a2f1e6a2c75f,"reason=FailedScheduling count=None msg=0/6 nodes are available: 1 c_wall violated: 2 conflicting context pair(s) with node memory, 5 node(s) had untolerated taint(s). no new claims to deallocate, preemption: 0/6 nodes are available: 1 No preemption victims found for incoming pod, 5 Preemption is not helpful for scheduling."
0.3591,Event,ADDED,eval-sanitize-1-r4-015-z76gx.18d4a2f24d9c84d9,reason=Scheduled count=None msg=Successfully assigned compute/eval-sanitize-1-r4-015-z76gx to kind-worker
0.3593,Event,ADDED,eval-sanitize-1-r4-015-z76gx.18d4a2f268e173ff,"reason=Pulled count=1 msg=Container image ""busybox:musl"" already present on machine"
0.3594,Event,ADDED,eval-sanitize-1-r4-015-z76gx.18d4a2f26b4eb9ce,reason=Created count=1 msg=Created container: task
0.3596,Event,ADDED,eval-sanitize-1-r4-015-z76gx.18d4a2f275f921ce,reason=Started count=1 msg=Started container task
0.3598,Event,ADDED,eval-sanitize-1-r4-015.18d4a2f01f133fd4,reason=SuccessfulCreate count=1 msg=Created pod: eval-sanitize-1-r4-015-z76gx
0.3599,Event,ADDED,eval-sanitize-1-r4-015.18d4a2f7d8bc164c,reason=Completed count=1 msg=Job completed
0.3601,Event,ADDED,eval-sanitize-1-r4-016-qbzsg.18d4a2f05aa8547b,"reason=FailedScheduling count=None msg=0/6 nodes are available: 6 node(s) had untolerated taint(s). no new claims to deallocate, preemption: 0/6 nodes are available: 6 Preemption is not helpful for scheduling."
0.3602,Event,ADDED,eval-sanitize-1-r4-016-qbzsg.18d4a2f1dbff8e95,reason=Scheduled count=None msg=Successfully assigned compute/eval-sanitize-1-r4-016-qbzsg to kind-worker3
0.3604,Event,ADDED,eval-sanitize-1-r4-016-qbzsg.18d4a2f1fa1c8d66,"reason=Pulled count=1 msg=Container image ""busybox:musl"" already present on machine"
0.3606,Event,ADDED,eval-sanitize-1-r4-016-qbzsg.18d4a2f1fbf31390,reason=Created count=1 msg=Created container: task
0.3607,Event,ADDED,eval-sanitize-1-r4-016-qbzsg.18d4a2f2088fe490,reason=Started count=1 msg=Started container task
0.3609,Event,ADDED,eval-sanitize-1-r4-016.18d4a2f05aa02b8e,reason=SuccessfulCreate count=1 msg=Created pod: eval-sanitize-1-r4-016-qbzsg
0.3611,Event,ADDED,eval-sanitize-1-r4-016.18d4a2f78d07f157,reason=Completed count=1 msg=Job completed
0.3612,Event,ADDED,eval-sanitize-1-r4-017-zhktm.18d4a2f09651bb0e,"reason=FailedScheduling count=None msg=0/6 nodes are available: 6 node(s) had untolerated taint(s). no new claims to deallocate, preemption: 0/6 nodes are available: 6 Preemption is not helpful for scheduling."
0.3614,Event,ADDED,eval-sanitize-1-r4-017-zhktm.18d4a2f1d6c99e0f,"reason=FailedScheduling count=None msg=0/6 nodes are available: 1 c_wall violated: 1 conflicting context pair(s) with node memory, 5 node(s) had untolerated taint(s). no new claims to deallocate, preemption: 0/6 nodes are available: 1 No preemption victims found for incoming pod, 5 Preemption is not helpful for scheduling."
0.3616,Event,ADDED,eval-sanitize-1-r4-017-zhktm.18d4a2f1e6d6fca5,"reason=FailedScheduling count=None msg=0/6 nodes are available: 1 c_wall violated: 1 conflicting context pair(s) with node memory, 5 node(s) had untolerated taint(s). no new claims to deallocate, preemption: 0/6 nodes are available: 1 No preemption victims found for incoming pod, 5 Preemption is not helpful for scheduling."
0.3618,Event,ADDED,eval-sanitize-1-r4-017-zhktm.18d4a2f24d9e1c53,"reason=FailedScheduling count=None msg=0/6 nodes are available: 1 c_wall violated: 1 conflicting context pair(s) with node memory, 5 node(s) had untolerated taint(s). no new claims to deallocate, preemption: 0/6 nodes are available: 1 No preemption victims found for incoming pod, 5 Preemption is not helpful for scheduling."
0.3619,Event,ADDED,eval-sanitize-1-r4-017-zhktm.18d4a2f25a51f697,"reason=FailedScheduling count=None msg=0/6 nodes are available: 1 c_wall violated: 1 conflicting context pair(s) with node memory, 5 node(s) had untolerated taint(s). no new claims to deallocate, preemption: 0/6 nodes are available: 1 No preemption victims found for incoming pod, 5 Preemption is not helpful for scheduling."
0.3622,Event,ADDED,eval-sanitize-1-r4-017-zhktm.18d4a2f2850a8b30,reason=Scheduled count=None msg=Successfully assigned compute/eval-sanitize-1-r4-017-zhktm to kind-worker5
0.3624,Event,ADDED,eval-sanitize-1-r4-017-zhktm.18d4a2f2ac9eba99,"reason=Pulled count=1 msg=Container image ""busybox:musl"" already present on machine"
0.3626,Event,ADDED,eval-sanitize-1-r4-017-zhktm.18d4a2f2ade4ead7,reason=Created count=1 msg=Created container: task
0.3628,Event,ADDED,eval-sanitize-1-r4-017-zhktm.18d4a2f2b20a9a8a,reason=Started count=1 msg=Started container task
0.363,Event,ADDED,eval-sanitize-1-r4-017.18d4a2f096419508,reason=SuccessfulCreate count=1 msg=Created pod: eval-sanitize-1-r4-017-zhktm
0.3632,Event,ADDED,eval-sanitize-1-r4-017.18d4a2f92339aef3,reason=Completed count=1 msg=Job completed
0.3633,Event,ADDED,eval-sanitize-1-r4-018-2x78q.18d4a2f0d2139035,"reason=FailedScheduling count=None msg=0/6 nodes are available: 6 node(s) had untolerated taint(s). no new claims to deallocate, preemption: 0/6 nodes are available: 6 Preemption is not helpful for scheduling."
0.3635,Event,ADDED,eval-sanitize-1-r4-018-2x78q.18d4a2f1dccd1f9e,reason=Scheduled count=None msg=Successfully assigned compute/eval-sanitize-1-r4-018-2x78q to kind-worker3
0.3637,Event,ADDED,eval-sanitize-1-r4-018-2x78q.18d4a2f1fa1d0fb2,"reason=Pulled count=1 msg=Container image ""busybox:musl"" already present on machine"
0.3638,Event,ADDED,eval-sanitize-1-r4-018-2x78q.18d4a2f1fc4bef49,reason=Created count=1 msg=Created container: task
0.364,Event,ADDED,eval-sanitize-1-r4-018-2x78q.18d4a2f2088ea370,reason=Started count=1 msg=Started container task
0.3642,Event,ADDED,eval-sanitize-1-r4-018.18d4a2f0d206ce3c,reason=SuccessfulCreate count=1 msg=Created pod: eval-sanitize-1-r4-018-2x78q
0.3643,Event,ADDED,eval-sanitize-1-r4-018.18d4a2f78cf70442,reason=Completed count=1 msg=Job completed
0.3645,Event,ADDED,eval-sanitize-1-r4-019-zmn7z.18d4a2f10e7903eb,"reason=FailedScheduling count=None msg=0/6 nodes are available: 6 node(s) had untolerated taint(s). no new claims to deallocate, preemption: 0/6 nodes are available: 6 Preemption is not helpful for scheduling."
0.3647,Event,ADDED,eval-sanitize-1-r4-019-zmn7z.18d4a2f1dc94a5be,"reason=FailedScheduling count=None msg=0/6 nodes are available: 1 c_wall violated: 1 conflicting context pair(s) with node memory, 5 node(s) had untolerated taint(s). no new claims to deallocate, preemption: 0/6 nodes are available: 1 No preemption victims found for incoming pod, 5 Preemption is not helpful for scheduling."
0.3649,Event,ADDED,eval-sanitize-1-r4-019-zmn7z.18d4a2f1e9a14230,"reason=FailedScheduling count=None msg=0/6 nodes are available: 1 c_wall violated: 1 conflicting context pair(s) with node memory, 5 node(s) had untolerated taint(s). no new claims to deallocate, preemption: 0/6 nodes are available: 1 No preemption victims found for incoming pod, 5 Preemption is not helpful for scheduling."
0.365,Event,ADDED,eval-sanitize-1-r4-019-zmn7z.18d4a2f24e584049,"reason=FailedScheduling count=None msg=0/6 nodes are available: 1 c_wall violated: 1 conflicting context pair(s) with node memory, 5 node(s) had untolerated taint(s). no new claims to deallocate, preemption: 0/6 nodes are available: 1 No preemption victims found for incoming pod, 5 Preemption is not helpful for scheduling."
0.3656,Event,ADDED,eval-sanitize-1-r4-019-zmn7z.18d4a2f25a7b6243,"reason=FailedScheduling count=None msg=0/6 nodes are available: 1 c_wall violated: 1 conflicting context pair(s) with node memory, 5 node(s) had untolerated taint(s). no new claims to deallocate, preemption: 0/6 nodes are available: 1 No preemption victims found for incoming pod, 5 Preemption is not helpful for scheduling."
0.3657,Event,ADDED,eval-sanitize-1-r4-019-zmn7z.18d4a2f27674d016,reason=Scheduled count=None msg=Successfully assigned compute/eval-sanitize-1-r4-019-zmn7z to kind-worker5
0.3659,Event,ADDED,eval-sanitize-1-r4-019-zmn7z.18d4a2f28fec48f5,"reason=Pulled count=1 msg=Container image ""busybox:musl"" already present on machine"
0.3661,Event,ADDED,eval-sanitize-1-r4-019-zmn7z.18d4a2f2917ce607,reason=Created count=1 msg=Created container: task
0.3663,Event,ADDED,eval-sanitize-1-r4-019-zmn7z.18d4a2f294bb6aa4,reason=Started count=1 msg=Started container task
0.3665,Event,ADDED,eval-sanitize-1-r4-019.18d4a2f10e702019,reason=SuccessfulCreate count=1 msg=Created pod: eval-sanitize-1-r4-019-zmn7z
0.3666,Event,ADDED,eval-sanitize-1-r4-019.18d4a2f92e86d9cc,reason=Completed count=1 msg=Job completed
0.3668,Event,ADDED,eval-sanitize-1-r4-020-rthjw.18d4a2f1494a01b4,"reason=FailedScheduling count=None msg=0/6 nodes are available: 6 node(s) had untolerated taint(s). no new claims to deallocate, preemption: 0/6 nodes are available: 6 Preemption is not helpful for scheduling."
0.3669,Event,ADDED,eval-sanitize-1-r4-020-rthjw.18d4a2f1dd4486c2,"reason=FailedScheduling count=None msg=0/6 nodes are available: 1 c_wall violated: 3 conflicting context pair(s) with node memory, 5 node(s) had untolerated taint(s). no new claims to deallocate, preemption: 0/6 nodes are available: 1 No preemption victims found for incoming pod, 5 Preemption is not helpful for scheduling."
0.3671,Event,ADDED,eval-sanitize-1-r4-020-rthjw.18d4a2f1eac9715a,"reason=FailedScheduling count=None msg=0/6 nodes are available: 1 c_wall violated: 3 conflicting context pair(s) with node memory, 5 node(s) had untolerated taint(s). no new claims to deallocate, preemption: 0/6 nodes are available: 1 No preemption victims found for incoming pod, 5 Preemption is not helpful for scheduling."
0.3673,Event,ADDED,eval-sanitize-1-r4-020-rthjw.18d4a2f24f2bd289,reason=Scheduled count=None msg=Successfully assigned compute/eval-sanitize-1-r4-020-rthjw to kind-worker
0.3675,Event,ADDED,eval-sanitize-1-r4-020-rthjw.18d4a2f268a83e55,"reason=Pulled count=1 msg=Container image ""busybox:musl"" already present on machine"
0.3676,Event,ADDED,eval-sanitize-1-r4-020-rthjw.18d4a2f26a79cef1,reason=Created count=1 msg=Created container: task
0.3678,Event,ADDED,eval-sanitize-1-r4-020-rthjw.18d4a2f275f921a8,reason=Started count=1 msg=Started container task
0.368,Event,ADDED,eval-sanitize-1-r4-020.18d4a2f1493d764c,reason=SuccessfulCreate count=1 msg=Created pod: eval-sanitize-1-r4-020-rthjw
0.3681,Event,ADDED,eval-sanitize-1-r4-020.18d4a2f87cc418ac,reason=Completed count=1 msg=Job completed
0.3683,Event,ADDED,eval-sanitize-1-r4-021-m8qwz.18d4a2f18598190f,"reason=FailedScheduling count=None msg=0/6 nodes are available: 6 node(s) had untolerated taint(s). no new claims to deallocate, preemption: 0/6 nodes are available: 6 Preemption is not helpful for scheduling."
0.3684,Event,ADDED,eval-sanitize-1-r4-021-m8qwz.18d4a2f1dde91a1d,"reason=FailedScheduling count=None msg=0/6 nodes are available: 1 c_wall violated: 1 conflicting context pair(s) with node memory, 5 node(s) had untolerated taint(s). no new claims to deallocate, preemption: 0/6 nodes are available: 1 No preemption victims found for incoming pod, 5 Preemption is not helpful for scheduling."
0.3686,Event,ADDED,eval-sanitize-1-r4-021-m8qwz.18d4a2f1eaff39e7,"reason=FailedScheduling count=None msg=0/6 nodes are available: 1 c_wall violated: 1 conflicting context pair(s) with node memory, 5 node(s) had untolerated taint(s). no new claims to deallocate, preemption: 0/6 nodes are available: 1 No preemption victims found for incoming pod, 5 Preemption is not helpful for scheduling."
0.3688,Event,ADDED,eval-sanitize-1-r4-021-m8qwz.18d4a2f24efea931,"reason=FailedScheduling count=None msg=0/6 nodes are available: 1 c_wall violated: 1 conflicting context pair(s) with node memory, 5 node(s) had untolerated taint(s). no new claims to deallocate, preemption: 0/6 nodes are available: 1 No preemption victims found for incoming pod, 5 Preemption is not helpful for scheduling."
0.369,Event,ADDED,eval-sanitize-1-r4-021-m8qwz.18d4a2f25aa41076,"reason=FailedScheduling count=None msg=0/6 nodes are available: 1 c_wall violated: 1 conflicting context pair(s) with node memory, 5 node(s) had untolerated taint(s). no new claims to deallocate, preemption: 0/6 nodes are available: 1 No preemption victims found for incoming pod, 5 Preemption is not helpful for scheduling."
0.3691,Event,ADDED,eval-sanitize-1-r4-021-m8qwz.18d4a2f2772a2f97,reason=Scheduled count=None msg=Successfully assigned compute/eval-sanitize-1-r4-021-m8qwz to kind-worker5
0.3693,Event,ADDED,eval-sanitize-1-r4-021-m8qwz.18d4a2f290db2dff,"reason=Pulled count=1 msg=Container image ""busybox:musl"" already present on machine"
0.3694,Event,ADDED,eval-sanitize-1-r4-021-m8qwz.18d4a2f29279c834,reason=Created count=1 msg=Created container: task
0.3696,Event,ADDED,eval-sanitize-1-r4-021-m8qwz.18d4a2f2955b5751,reason=Started count=1 msg=Started container task
0.3699,Event,ADDED,eval-sanitize-1-r4-021.18d4a2f1858cff3c,reason=SuccessfulCreate count=1 msg=Created pod: eval-sanitize-1-r4-021-m8qwz
0.3701,Event,ADDED,eval-sanitize-1-r4-021.18d4a2f9322e243f,reason=Completed count=1 msg=Job completed
0.3704,Event,ADDED,eval-sanitize-1-r4-022-rshz9.18d4a2f1c042d690,"reason=FailedScheduling count=None msg=0/6 nodes are available: 6 node(s) had untolerated taint(s). no new claims to deallocate, preemption: 0/6 nodes are available: 6 Preemption is not helpful for scheduling."
0.3706,Event,ADDED,eval-sanitize-1-r4-022-rshz9.18d4a2f1e0a6ec6b,"reason=FailedScheduling count=None msg=0/6 nodes are available: 1 c_wall violated: 3 conflicting context pair(s) with node memory, 5 node(s) had untolerated taint(s). no new claims to deallocate, preemption: 0/6 nodes are available: 1 No preemption victims found for incoming pod, 5 Preemption is not helpful for scheduling."
0.3708,Event,ADDED,eval-sanitize-1-r4-022-rshz9.18d4a2f1eb2edb53,"reason=FailedScheduling count=None msg=0/6 nodes are available: 1 c_wall violated: 3 conflicting context pair(s) with node memory, 5 node(s) had untolerated taint(s). no new claims to deallocate, preemption: 0/6 nodes are available: 1 No preemption victims found for incoming pod, 5 Preemption is not helpful for scheduling."
0.3711,Event,ADDED,eval-sanitize-1-r4-022-rshz9.18d4a2f250089fc2,"reason=FailedScheduling count=None msg=0/6 nodes are available: 1 c_wall violated: 1 conflicting context pair(s) with node memory, 5 node(s) had untolerated taint(s). no new claims to deallocate, preemption: 0/6 nodes are available: 1 No preemption victims found for incoming pod, 5 Preemption is not helpful for scheduling."
0.3713,Event,ADDED,eval-sanitize-1-r4-022-rshz9.18d4a2f25ac7c5f5,"reason=FailedScheduling count=None msg=0/6 nodes are available: 1 c_wall violated: 1 conflicting context pair(s) with node memory, 5 node(s) had untolerated taint(s). no new claims to deallocate, preemption: 0/6 nodes are available: 1 No preemption victims found for incoming pod, 5 Preemption is not helpful for scheduling."
0.3714,Event,ADDED,eval-sanitize-1-r4-022-rshz9.18d4a2f287564106,"reason=FailedScheduling count=None msg=0/6 nodes are available: 1 c_wall violated: 1 conflicting context pair(s) with node memory, 1 c_wall violated: 2 conflicting context pair(s) with node memory, 4 node(s) had untolerated taint(s). no new claims to deallocate, preemption: 0/6 nodes are available: 2 No preemption victims found for incoming pod, 4 Preemption is not helpful for scheduling."
0.3717,Event,ADDED,eval-sanitize-1-r4-022-rshz9.18d4a2f28c61c06b,"reason=FailedScheduling count=None msg=0/6 nodes are available: 1 c_wall violated: 2 conflicting context pair(s) with node memory, 5 node(s) had untolerated taint(s). no new claims to deallocate, preemption: 0/6 nodes are available: 1 No preemption victims found for incoming pod, 5 Preemption is not helpful for scheduling."
0.3719,Event,ADDED,eval-sanitize-1-r4-022-rshz9.18d4a2f28df631c6,"reason=FailedScheduling count=None msg=0/6 nodes are available: 1 c_wall violated: 2 conflicting context pair(s) with node memory, 5 node(s) had untolerated taint(s). no new claims to deallocate, preemption: 0/6 nodes are available: 1 No preemption victims found for incoming pod, 5 Preemption is not helpful for scheduling."
0.372,Event,ADDED,eval-sanitize-1-r4-022-rshz9.18d4a2f2ba988742,reason=Scheduled count=None msg=Successfully assigned compute/eval-sanitize-1-r4-022-rshz9 to kind-worker2
0.3723,Event,ADDED,eval-sanitize-1-r4-022-rshz9.18d4a2f2d82d31eb,"reason=Pulled count=1 msg=Container image ""busybox:musl"" already present on machine"
0.3727,Event,ADDED,eval-sanitize-1-r4-022-rshz9.18d4a2f2daa0890d,reason=Created count=1 msg=Created container: task
0.3729,Event,ADDED,eval-sanitize-1-r4-022-rshz9.18d4a2f2e2f18e4c,reason=Started count=1 msg=Started container task
0.373,Event,ADDED,eval-sanitize-1-r4-022.18d4a2f1c0319247,reason=SuccessfulCreate count=1 msg=Created pod: eval-sanitize-1-r4-022-rshz9
0.3732,Event,ADDED,eval-sanitize-1-r4-022.18d4a2f9462e281a,reason=Completed count=1 msg=Job completed
0.3735,Event,ADDED,eval-sanitize-1-r4-023-cm26t.18d4a2f1fd30bc9d,reason=Scheduled count=None msg=Successfully assigned compute/eval-sanitize-1-r4-023-cm26t to kind-worker3
0.3737,Event,ADDED,eval-sanitize-1-r4-023-cm26t.18d4a2f21fda4e38,"reason=Pulled count=1 msg=Container image ""busybox:musl"" already present on machine"
0.3739,Event,ADDED,eval-sanitize-1-r4-023-cm26t.18d4a2f22152adb3,reason=Created count=1 msg=Created container: task
0.3742,Event,ADDED,eval-sanitize-1-r4-023-cm26t.18d4a2f22bb1583e,reason=Started count=1 msg=Started container task
0.3744,Event,ADDED,eval-sanitize-1-r4-023.18d4a2f1fc66a7f4,reason=SuccessfulCreate count=1 msg=Created pod: eval-sanitize-1-r4-023-cm26t
0.3746,Event,ADDED,eval-sanitize-1-r4-023.18d4a2f78cf0139c,reason=Completed count=1 msg=Job completed
0.3748,Event,ADDED,eval-sanitize-1-r4-024-r8zjn.18d4a2f2377e3799,"reason=FailedScheduling count=None msg=0/6 nodes are available: 6 node(s) had untolerated taint(s). no new claims to deallocate, preemption: 0/6 nodes are available: 6 Preemption is not helpful for scheduling."
0.3751,Event,ADDED,eval-sanitize-1-r4-024-r8zjn.18d4a2f25fd98123,reason=Scheduled count=None msg=Successfully assigned compute/eval-sanitize-1-r4-024-r8zjn to kind-worker
0.3753,Event,ADDED,eval-sanitize-1-r4-024-r8zjn.18d4a2f27e12f6b0,"reason=Pulled count=1 msg=Container image ""busybox:musl"" already present on machine"
0.3755,Event,ADDED,eval-sanitize-1-r4-024-r8zjn.18d4a2f2800be969,reason=Created count=1 msg=Created container: task
0.3759,Event,ADDED,eval-sanitize-1-r4-024-r8zjn.18d4a2f2865b88cd,reason=Started count=1 msg=Started container task
0.376,Event,ADDED,eval-sanitize-1-r4-024.18d4a2f237711a5b,reason=SuccessfulCreate count=1 msg=Created pod: eval-sanitize-1-r4-024-r8zjn
0.3762,Event,ADDED,eval-sanitize-1-r4-024.18d4a2f91a5bcda5,reason=Completed count=1 msg=Job completed
0.3764,Event,ADDED,eval-sanitize-1-r4-025-mzlz4.18d4a2f27cd964d2,reason=Scheduled count=None msg=Successfully assigned compute/eval-sanitize-1-r4-025-mzlz4 to kind-worker5
0.3767,Event,ADDED,eval-sanitize-1-r4-025-mzlz4.18d4a2f295e467bd,"reason=Pulled count=1 msg=Container image ""busybox:musl"" already present on machine"
0.377,Event,ADDED,eval-sanitize-1-r4-025-mzlz4.18d4a2f2972aa4e8,reason=Created count=1 msg=Created container: task
0.3773,Event,ADDED,eval-sanitize-1-r4-025-mzlz4.18d4a2f2a38f9a15,reason=Started count=1 msg=Started container task
0.3779,Event,ADDED,eval-sanitize-1-r4-025.18d4a2f279f30f12,reason=SuccessfulCreate count=1 msg=Created pod: eval-sanitize-1-r4-025-mzlz4
0.3782,Event,ADDED,eval-sanitize-1-r4-025.18d4a2f95393ecbd,reason=Completed count=1 msg=Job completed
0.3783,Event,ADDED,eval-sanitize-1-r4-026-hmdrf.18d4a2f2aefdc80d,"reason=FailedScheduling count=None msg=0/6 nodes are available: 1 c_wall violated: 2 conflicting context pair(s) with node memory, 5 node(s) had untolerated taint(s). no new claims to deallocate, preemption: 0/6 nodes are available: 1 No preemption victims found for incoming pod, 5 Preemption is not helpful for scheduling."
0.3785,Event,ADDED,eval-sanitize-1-r4-026-hmdrf.18d4a2f2b0004ac1,"reason=FailedScheduling count=None msg=0/6 nodes are available: 1 c_wall violated: 2 conflicting context pair(s) with node memory, 5 node(s) had untolerated taint(s). no new claims to deallocate, preemption: 0/6 nodes are available: 1 No preemption victims found for incoming pod, 5 Preemption is not helpful for scheduling."
0.3789,Event,ADDED,eval-sanitize-1-r4-026-hmdrf.18d4a2f2bba8b620,reason=Scheduled count=None msg=Successfully assigned compute/eval-sanitize-1-r4-026-hmdrf to kind-worker2
0.3791,Event,ADDED,eval-sanitize-1-r4-026-hmdrf.18d4a2f2d8577c9d,"reason=Pulled count=1 msg=Container image ""busybox:musl"" already present on machine"
0.3793,Event,ADDED,eval-sanitize-1-r4-026-hmdrf.18d4a2f2db0ea94a,reason=Created count=1 msg=Created container: task
0.3796,Event,ADDED,eval-sanitize-1-r4-026-hmdrf.18d4a2f2e2f43e90,reason=Started count=1 msg=Started container task
0.3798,Event,ADDED,eval-sanitize-1-r4-026.18d4a2f2aeb3be34,reason=SuccessfulCreate count=1 msg=Created pod: eval-sanitize-1-r4-026-hmdrf
0.38,Event,ADDED,eval-sanitize-1-r4-026.18d4a2f93c2c0b8e,reason=Completed count=1 msg=Job completed
0.3802,Event,ADDED,eval-sanitize-1-r4-027-rl8l8.18d4a2f2efd113a2,reason=Scheduled count=None msg=Successfully assigned compute/eval-sanitize-1-r4-027-rl8l8 to kind-worker4
0.3805,Event,ADDED,eval-sanitize-1-r4-027-rl8l8.18d4a2f30e8a739c,"reason=Pulled count=1 msg=Container image ""busybox:musl"" already present on machine"
0.3806,Event,ADDED,eval-sanitize-1-r4-027-rl8l8.18d4a2f30fa78d84,reason=Created count=1 msg=Created container: task
0.3808,Event,ADDED,eval-sanitize-1-r4-027-rl8l8.18d4a2f3181f309c,reason=Started count=1 msg=Started container task
0.381,Event,ADDED,eval-sanitize-1-r4-027.18d4a2f2eed4bbb6,reason=SuccessfulCreate count=1 msg=Created pod: eval-sanitize-1-r4-027-rl8l8
0.3813,Event,ADDED,eval-sanitize-1-r4-027.18d4a2f953aed580,reason=Completed count=1 msg=Job completed
0.3815,Event,ADDED,eval-sanitize-1-r4-028-4vwxq.18d4a2f325b61813,"reason=FailedScheduling count=None msg=0/6 nodes are available: 6 node(s) had untolerated taint(s). no new claims to deallocate, preemption: 0/6 nodes are available: 6 Preemption is not helpful for scheduling."
0.3816,Event,ADDED,eval-sanitize-1-r4-028-4vwxq.18d4a2f7601e211b,reason=Scheduled count=None msg=Successfully assigned compute/eval-sanitize-1-r4-028-4vwxq to kind-worker3
0.3819,Event,ADDED,eval-sanitize-1-r4-028-4vwxq.18d4a2f779b728e3,"reason=Pulled count=1 msg=Container image ""busybox:musl"" already present on machine"
0.3821,Event,ADDED,eval-sanitize-1-r4-028-4vwxq.18d4a2f77bc27744,reason=Created count=1 msg=Created container: task
0.3823,Event,ADDED,eval-sanitize-1-r4-028-4vwxq.18d4a2f77dcf5ffc,reason=Started count=1 msg=Started container task
0.3825,Event,ADDED,eval-sanitize-1-r4-028.18d4a2f325aaae92,reason=SuccessfulCreate count=1 msg=Created pod: eval-sanitize-1-r4-028-4vwxq
0.3827,Event,ADDED,eval-sanitize-1-r4-028.18d4a2fcb3100bf9,reason=Completed count=1 msg=Job completed
0.383,Event,ADDED,eval-sanitize-1-r4-029-vgjxl.18d4a2f3614ccb8a,"reason=FailedScheduling count=None msg=0/6 nodes are available: 6 node(s) had untolerated taint(s). no new claims to deallocate, preemption: 0/6 nodes are available: 6 Preemption is not helpful for scheduling."
0.3831,Event,ADDED,eval-sanitize-1-r4-029-vgjxl.18d4a2f76058432d,"reason=FailedScheduling count=None msg=0/6 nodes are available: 1 c_wall violated: 1 conflicting context pair(s) with node memory, 5 node(s) had untolerated taint(s). no new claims to deallocate, preemption: 0/6 nodes are available: 1 No preemption victims found for incoming pod, 5 Preemption is not helpful for scheduling."
0.3833,Event,ADDED,eval-sanitize-1-r4-029-vgjxl.18d4a2f771850eb1,"reason=FailedScheduling count=None msg=0/6 nodes are available: 1 c_wall violated: 3 conflicting context pair(s) with node memory, 5 node(s) had untolerated taint(s). no new claims to deallocate, preemption: 0/6 nodes are available: 1 No preemption victims found for incoming pod, 5 Preemption is not helpful for scheduling."
0.3835,Event,ADDED,eval-sanitize-1-r4-029-vgjxl.18d4a2f77b8cbcb4,"reason=FailedScheduling count=None msg=0/6 nodes are available: 1 c_wall violated: 3 conflicting context pair(s) with node memory, 5 node(s) had untolerated taint(s). no new claims to deallocate, preemption: 0/6 nodes are available: 1 No preemption victims found for incoming pod, 5 Preemption is not helpful for scheduling."
0.3836,Event,ADDED,eval-sanitize-1-r4-029-vgjxl.18d4a2f7c982c2c9,"reason=FailedScheduling count=None msg=0/6 nodes are available: 1 c_wall violated: 1 conflicting context pair(s) with node memory, 5 node(s) had untolerated taint(s). no new claims to deallocate, preemption: 0/6 nodes are available: 1 No preemption victims found for incoming pod, 5 Preemption is not helpful for scheduling."
0.3838,Event,ADDED,eval-sanitize-1-r4-029-vgjxl.18d4a2f7d723750a,"reason=FailedScheduling count=None msg=0/6 nodes are available: 1 c_wall violated: 1 conflicting context pair(s) with node memory, 5 node(s) had untolerated taint(s). no new claims to deallocate, preemption: 0/6 nodes are available: 1 No preemption victims found for incoming pod, 5 Preemption is not helpful for scheduling."
0.384,Event,ADDED,eval-sanitize-1-r4-029-vgjxl.18d4a2f7ec5f3524,"reason=FailedScheduling count=None msg=0/6 nodes are available: 2 c_wall violated: 1 conflicting context pair(s) with node memory, 4 node(s) had untolerated taint(s). no new claims to deallocate, preemption: 0/6 nodes are available: 2 No preemption victims found for incoming pod, 4 Preemption is not helpful for scheduling."
0.3843,Event,ADDED,eval-sanitize-1-r4-029-vgjxl.18d4a2f815aa527a,"reason=FailedScheduling count=None msg=0/6 nodes are available: 1 c_wall violated: 1 conflicting context pair(s) with node memory, 5 node(s) had untolerated taint(s). no new claims to deallocate, preemption: 0/6 nodes are available: 1 No preemption victims found for incoming pod, 5 Preemption is not helpful for scheduling."
0.3845,Event,ADDED,eval-sanitize-1-r4-029-vgjxl.18d4a2f835f740e3,reason=Scheduled count=None msg=Successfully assigned compute/eval-sanitize-1-r4-029-vgjxl to kind-worker2
0.3846,Event,ADDED,eval-sanitize-1-r4-029-vgjxl.18d4a2f84f123802,"reason=Pulled count=1 msg=Container image ""busybox:musl"" already present on machine"
0.3849,Event,ADDED,eval-sanitize-1-r4-029-vgjxl.18d4a2f850814038,reason=Created count=1 msg=Created container: task
0.3851,Event,ADDED,eval-sanitize-1-r4-029-vgjxl.18d4a2f85376034d,reason=Started count=1 msg=Started container task
0.3853,Event,ADDED,eval-sanitize-1-r4-029.18d4a2f36140c12b,reason=SuccessfulCreate count=1 msg=Created pod: eval-sanitize-1-r4-029-vgjxl
0.3855,Event,ADDED,eval-sanitize-1-r4-029.18d4a2fe89b0f77d,reason=Completed count=1 msg=Job completed
0.3858,Event,ADDED,eval-sanitize-1-r4-030-4h977.18d4a2f39d07baa3,"reason=FailedScheduling count=None msg=0/6 nodes are available: 6 node(s) had untolerated taint(s). no new claims to deallocate, preemption: 0/6 nodes are available: 6 Preemption is not helpful for scheduling."
0.386,Event,ADDED,eval-sanitize-1-r4-030-4h977.18d4a2f761968257,reason=Scheduled count=None msg=Successfully assigned compute/eval-sanitize-1-r4-030-4h977 to kind-worker3
0.3861,Event,ADDED,eval-sanitize-1-r4-030-4h977.18d4a2f77ad1f256,"reason=Pulled count=1 msg=Container image ""busybox:musl"" already present on machine"
0.3864,Event,ADDED,eval-sanitize-1-r4-030-4h977.18d4a2f77d8e6b5c,reason=Created count=1 msg=Created container: task
0.3865,Event,ADDED,eval-sanitize-1-r4-030-4h977.18d4a2f7800f603e,reason=Started count=1 msg=Started container task
0.3867,Event,ADDED,eval-sanitize-1-r4-030.18d4a2f39cfbdc91,reason=SuccessfulCreate count=1 msg=Created pod: eval-sanitize-1-r4-030-4h977
0.3869,Event,ADDED,eval-sanitize-1-r4-030.18d4a2fcefe7c54f,reason=Completed count=1 msg=Job completed
0.3871,Event,ADDED,eval-sanitize-1-r4-031-wjvth.18d4a2f3d8c2defa,"reason=FailedScheduling count=None msg=0/6 nodes are available: 6 node(s) had untolerated taint(s). no new claims to deallocate, preemption: 0/6 nodes are available: 6 Preemption is not helpful for scheduling."
0.3872,Event,ADDED,eval-sanitize-1-r4-031-wjvth.18d4a2f761bf4267,reason=Scheduled count=None msg=Successfully assigned compute/eval-sanitize-1-r4-031-wjvth to kind-worker3
0.3874,Event,ADDED,eval-sanitize-1-r4-031-wjvth.18d4a2f77ae89d1b,"reason=Pulled count=1 msg=Container image ""busybox:musl"" already present on machine"
0.3875,Event,ADDED,eval-sanitize-1-r4-031-wjvth.18d4a2f77d596c65,reason=Created count=1 msg=Created container: task
0.3877,Event,ADDED,eval-sanitize-1-r4-031-wjvth.18d4a2f77fb81926,reason=Started count=1 msg=Started container task
0.3879,Event,ADDED,eval-sanitize-1-r4-031.18d4a2f3d8b94bc0,reason=SuccessfulCreate count=1 msg=Created pod: eval-sanitize-1-r4-031-wjvth
0.3881,Event,ADDED,eval-sanitize-1-r4-031.18d4a2fcb33a32f4,reason=Completed count=1 msg=Job completed
0.3882,Event,ADDED,eval-sanitize-1-r4-032-wz7q7.18d4a2f4142552c1,"reason=FailedScheduling count=None msg=0/6 nodes are available: 6 node(s) had untolerated taint(s). no new claims to deallocate, preemption: 0/6 nodes are available: 6 Preemption is not helpful for scheduling."
0.3884,Event,ADDED,eval-sanitize-1-r4-032-wz7q7.18d4a2f761a2fc09,"reason=FailedScheduling count=None msg=0/6 nodes are available: 1 c_wall violated: 3 conflicting context pair(s) with node memory, 5 node(s) had untolerated taint(s). no new claims to deallocate, preemption: 0/6 nodes are available: 1 No preemption victims found for incoming pod, 5 Preemption is not helpful for scheduling."
0.3885,Event,ADDED,eval-sanitize-1-r4-032-wz7q7.18d4a2f77200e690,"reason=FailedScheduling count=None msg=0/6 nodes are available: 1 c_wall violated: 3 conflicting context pair(s) with node memory, 5 node(s) had untolerated taint(s). no new claims to deallocate, preemption: 0/6 nodes are available: 1 No preemption victims found for incoming pod, 5 Preemption is not helpful for scheduling."
0.3887,Event,ADDED,eval-sanitize-1-r4-032-wz7q7.18d4a2f7ca331747,"reason=FailedScheduling count=None msg=0/6 nodes are available: 1 c_wall violated: 1 conflicting context pair(s) with node memory, 5 node(s) had untolerated taint(s). no new claims to deallocate, preemption: 0/6 nodes are available: 1 No preemption victims found for incoming pod, 5 Preemption is not helpful for scheduling."
0.3889,Event,ADDED,eval-sanitize-1-r4-032-wz7q7.18d4a2f7d75395be,"reason=FailedScheduling count=None msg=0/6 nodes are available: 1 c_wall violated: 1 conflicting context pair(s) with node memory, 5 node(s) had untolerated taint(s). no new claims to deallocate, preemption: 0/6 nodes are available: 1 No preemption victims found for incoming pod, 5 Preemption is not helpful for scheduling."
0.3891,Event,ADDED,eval-sanitize-1-r4-032-wz7q7.18d4a2f7eccecaa8,"reason=FailedScheduling count=None msg=0/6 nodes are available: 2 c_wall violated: 1 conflicting context pair(s) with node memory, 4 node(s) had untolerated taint(s). no new claims to deallocate, preemption: 0/6 nodes are available: 2 No preemption victims found for incoming pod, 4 Preemption is not helpful for scheduling."
0.3893,Event,ADDED,eval-sanitize-1-r4-032-wz7q7.18d4a2f815d823be,"reason=FailedScheduling count=None msg=0/6 nodes are available: 1 c_wall violated: 1 conflicting context pair(s) with node memory, 5 node(s) had untolerated taint(s). no new claims to deallocate, preemption: 0/6 nodes are available: 1 No preemption victims found for incoming pod, 5 Preemption is not helpful for scheduling."
0.3894,Event,ADDED,eval-sanitize-1-r4-032-wz7q7.18d4a2f834b17a05,reason=Scheduled count=None msg=Successfully assigned compute/eval-sanitize-1-r4-032-wz7q7 to kind-worker2
0.3896,Event,ADDED,eval-sanitize-1-r4-032-wz7q7.18d4a2f84ddc01f5,"reason=Pulled count=1 msg=Container image ""busybox:musl"" already present on machine"
0.3898,Event,ADDED,eval-sanitize-1-r4-032-wz7q7.18d4a2f84f797e4b,reason=Created count=1 msg=Created container: task
0.3899,Event,ADDED,eval-sanitize-1-r4-032-wz7q7.18d4a2f852c72275,reason=Started count=1 msg=Started container task
0.3901,Event,ADDED,eval-sanitize-1-r4-032.18d4a2f4141dec97,reason=SuccessfulCreate count=1 msg=Created pod: eval-sanitize-1-r4-032-wz7q7
0.3902,Event,ADDED,eval-sanitize-1-r4-032.18d4a2fe7ac73a4b,reason=Completed count=1 msg=Job completed
0.3904,Event,ADDED,eval-sanitize-1-r4-033-9zttk.18d4a2f44fd7148d,"reason=FailedScheduling count=None msg=0/6 nodes are available: 6 node(s) had untolerated taint(s). no new claims to deallocate, preemption: 0/6 nodes are available: 6 Preemption is not helpful for scheduling."
0.3905,Event,ADDED,eval-sanitize-1-r4-033-9zttk.18d4a2f76565f9bb,reason=Scheduled count=None msg=Successfully assigned compute/eval-sanitize-1-r4-033-9zttk to kind-worker3
0.3907,Event,ADDED,eval-sanitize-1-r4-033-9zttk.18d4a2f77cea04a1,"reason=Pulled count=1 msg=Container image ""busybox:musl"" already present on machine"
0.3909,Event,ADDED,eval-sanitize-1-r4-033-9zttk.18d4a2f77eef1ce7,reason=Created count=1 msg=Created container: task
0.391,Event,ADDED,eval-sanitize-1-r4-033-9zttk.18d4a2f7816b51d4,reason=Started count=1 msg=Started container task
0.3913,Event,ADDED,eval-sanitize-1-r4-033.18d4a2f44fcadabf,reason=SuccessfulCreate count=1 msg=Created pod: eval-sanitize-1-r4-033-9zttk
0.3915,Event,ADDED,eval-sanitize-1-r4-033.18d4a2fcb336b4cf,reason=Completed count=1 msg=Job completed
0.3916,Event,ADDED,eval-sanitize-1-r4-034-zsgnd.18d4a2f48b6fd217,"reason=FailedScheduling count=None msg=0/6 nodes are available: 6 node(s) had untolerated taint(s). no new claims to deallocate, preemption: 0/6 nodes are available: 6 Preemption is not helpful for scheduling."
0.3917,Event,ADDED,eval-sanitize-1-r4-034-zsgnd.18d4a2f76521b017,"reason=FailedScheduling count=None msg=0/6 nodes are available: 1 c_wall violated: 3 conflicting context pair(s) with node memory, 5 node(s) had untolerated taint(s). no new claims to deallocate, preemption: 0/6 nodes are available: 1 No preemption victims found for incoming pod, 5 Preemption is not helpful for scheduling."
0.3919,Event,ADDED,eval-sanitize-1-r4-034-zsgnd.18d4a2f772beee49,"reason=FailedScheduling count=None msg=0/6 nodes are available: 1 c_wall violated: 3 conflicting context pair(s) with node memory, 5 node(s) had untolerated taint(s). no new claims to deallocate, preemption: 0/6 nodes are available: 1 No preemption victims found for incoming pod, 5 Preemption is not helpful for scheduling."
0.3922,Event,ADDED,eval-sanitize-1-r4-034-zsgnd.18d4a2f7cacb9595,"reason=FailedScheduling count=None msg=0/6 nodes are available: 1 c_wall violated: 1 conflicting context pair(s) with node memory, 5 node(s) had untolerated taint(s). no new claims to deallocate, preemption: 0/6 nodes are available: 1 No preemption victims found for incoming pod, 5 Preemption is not helpful for scheduling."
0.3924,Event,ADDED,eval-sanitize-1-r4-034-zsgnd.18d4a2f7d77d906d,"reason=FailedScheduling count=None msg=0/6 nodes are available: 1 c_wall violated: 1 conflicting context pair(s) with node memory, 5 node(s) had untolerated taint(s). no new claims to deallocate, preemption: 0/6 nodes are available: 1 No preemption victims found for incoming pod, 5 Preemption is not helpful for scheduling."
0.3926,Event,ADDED,eval-sanitize-1-r4-034-zsgnd.18d4a2f7ed2a9e83,"reason=FailedScheduling count=None msg=0/6 nodes are available: 2 c_wall violated: 1 conflicting context pair(s) with node memory, 4 node(s) had untolerated taint(s). no new claims to deallocate, preemption: 0/6 nodes are available: 2 No preemption victims found for incoming pod, 4 Preemption is not helpful for scheduling."
0.393,Event,ADDED,eval-sanitize-1-r4-034-zsgnd.18d4a2f8154d7c16,"reason=FailedScheduling count=None msg=0/6 nodes are available: 1 c_wall violated: 1 conflicting context pair(s) with node memory, 5 node(s) had untolerated taint(s). no new claims to deallocate, preemption: 0/6 nodes are available: 1 No preemption victims found for incoming pod, 5 Preemption is not helpful for scheduling."
0.3931,Event,ADDED,eval-sanitize-1-r4-034-zsgnd.18d4a2f8351f7778,reason=Scheduled count=None msg=Successfully assigned compute/eval-sanitize-1-r4-034-zsgnd to kind-worker2
0.3933,Event,ADDED,eval-sanitize-1-r4-034-zsgnd.18d4a2f84e39cc71,"reason=Pulled count=1 msg=Container image ""busybox:musl"" already present on machine"
0.3935,Event,ADDED,eval-sanitize-1-r4-034-zsgnd.18d4a2f84fee1c5f,reason=Created count=1 msg=Created container: task
0.394,Event,ADDED,eval-sanitize-1-r4-034-zsgnd.18d4a2f85375c8be,reason=Started count=1 msg=Started container task
0.3942,Event,ADDED,eval-sanitize-1-r4-034.18d4a2f48b648d54,reason=SuccessfulCreate count=1 msg=Created pod: eval-sanitize-1-r4-034-zsgnd
0.3943,Event,ADDED,eval-sanitize-1-r4-034.18d4a2fe86bf9d83,reason=Completed count=1 msg=Job completed
0.3949,Event,ADDED,eval-sanitize-1-r4-035-wtsrl.18d4a2f4c75561e0,"reason=FailedScheduling count=None msg=0/6 nodes are available: 6 node(s) had untolerated taint(s). no new claims to deallocate, preemption: 0/6 nodes are available: 6 Preemption is not helpful for scheduling."
0.3951,Event,ADDED,eval-sanitize-1-r4-035-wtsrl.18d4a2f765be1acd,"reason=FailedScheduling count=None msg=0/6 nodes are available: 1 c_wall violated: 2 conflicting context pair(s) with node memory, 5 node(s) had untolerated taint(s). no new claims to deallocate, preemption: 0/6 nodes are available: 1 No preemption victims found for incoming pod, 5 Preemption is not helpful for scheduling."
0.3954,Event,ADDED,eval-sanitize-1-r4-035-wtsrl.18d4a2f772e7c52a,"reason=FailedScheduling count=None msg=0/6 nodes are available: 1 c_wall violated: 2 conflicting context pair(s) with node memory, 5 node(s) had untolerated taint(s). no new claims to deallocate, preemption: 0/6 nodes are available: 1 No preemption victims found for incoming pod, 5 Preemption is not helpful for scheduling."
0.3957,Event,ADDED,eval-sanitize-1-r4-035-wtsrl.18d4a2f7cc894e8e,reason=Scheduled count=None msg=Successfully assigned compute/eval-sanitize-1-r4-035-wtsrl to kind-worker5
0.3959,Event,ADDED,eval-sanitize-1-r4-035-wtsrl.18d4a2f7e677a995,"reason=Pulled count=1 msg=Container image ""busybox:musl"" already present on machine"
0.3961,Event,ADDED,eval-sanitize-1-r4-035-wtsrl.18d4a2f7e807518d,reason=Created count=1 msg=Created container: task
0.3962,Event,ADDED,eval-sanitize-1-r4-035-wtsrl.18d4a2f7ec1a65e8,reason=Started count=1 msg=Started container task
0.3965,Event,ADDED,eval-sanitize-1-r4-035.18d4a2f4c74b74c6,reason=SuccessfulCreate count=1 msg=Created pod: eval-sanitize-1-r4-035-wtsrl
0.3967,Event,ADDED,eval-sanitize-1-r4-035.18d4a2fe20f4f0e8,reason=Completed count=1 msg=Job completed
0.3969,Event,ADDED,eval-sanitize-1-r4-036-xx6nz.18d4a2f5058c94cd,"reason=FailedScheduling count=None msg=0/6 nodes are available: 6 node(s) had untolerated taint(s). no new claims to deallocate, preemption: 0/6 nodes are available: 6 Preemption is not helpful for scheduling."
0.397,Event,ADDED,eval-sanitize-1-r4-036-xx6nz.18d4a2f7671a1a90,reason=Scheduled count=None msg=Successfully assigned compute/eval-sanitize-1-r4-036-xx6nz to kind-worker3
0.3973,Event,ADDED,eval-sanitize-1-r4-036-xx6nz.18d4a2f780d74da5,"reason=Pulled count=1 msg=Container image ""busybox:musl"" already present on machine"
0.3975,Event,ADDED,eval-sanitize-1-r4-036-xx6nz.18d4a2f782531c7d,reason=Created count=1 msg=Created container: task
0.3977,Event,ADDED,eval-sanitize-1-r4-036-xx6nz.18d4a2f78c5772c8,reason=Started count=1 msg=Started container task
0.398,Event,ADDED,eval-sanitize-1-r4-036.18d4a2f50580aa52,reason=SuccessfulCreate count=1 msg=Created pod: eval-sanitize-1-r4-036-xx6nz
0.3982,Event,ADDED,eval-sanitize-1-r4-036.18d4a2fcb38907ec,reason=Completed count=1 msg=Job completed
0.3983,Event,ADDED,eval-sanitize-1-r4-037-cxlld.18d4a2f53f2515de,"reason=FailedScheduling count=None msg=0/6 nodes are available: 6 node(s) had untolerated taint(s). no new claims to deallocate, preemption: 0/6 nodes are available: 6 Preemption is not helpful for scheduling."
0.3985,Event,ADDED,eval-sanitize-1-r4-037-cxlld.18d4a2f766ff5afd,"reason=FailedScheduling count=None msg=0/6 nodes are available: 1 c_wall violated: 2 conflicting context pair(s) with node memory, 5 node(s) had untolerated taint(s). no new claims to deallocate, preemption: 0/6 nodes are available: 1 No preemption victims found for incoming pod, 5 Preemption is not helpful for scheduling."
0.3988,Event,ADDED,eval-sanitize-1-r4-037-cxlld.18d4a2f7741537ed,"reason=FailedScheduling count=None msg=0/6 nodes are available: 1 c_wall violated: 2 conflicting context pair(s) with node memory, 5 node(s) had untolerated taint(s). no new claims to deallocate, preemption: 0/6 nodes are available: 1 No preemption victims found for incoming pod, 5 Preemption is not helpful for scheduling."
0.399,Event,ADDED,eval-sanitize-1-r4-037-cxlld.18d4a2f7cc6fda81,"reason=FailedScheduling count=None msg=0/6 nodes are available: 1 c_wall violated: 2 conflicting context pair(s) with node memory, 5 node(s) had untolerated taint(s). no new claims to deallocate, preemption: 0/6 nodes are available: 1 No preemption victims found for incoming pod, 5 Preemption is not helpful for scheduling."
0.3993,Event,ADDED,eval-sanitize-1-r4-037-cxlld.18d4a2f7d7af0cb9,"reason=FailedScheduling count=None msg=0/6 nodes are available: 1 c_wall violated: 2 conflicting context pair(s) with node memory, 5 node(s) had untolerated taint(s). no new claims to deallocate, preemption: 0/6 nodes are available: 1 No preemption victims found for incoming pod, 5 Preemption is not helpful for scheduling."
0.3995,Event,ADDED,eval-sanitize-1-r4-037-cxlld.18d4a2f7e1bd48b4,reason=Scheduled count=None msg=Successfully assigned compute/eval-sanitize-1-r4-037-cxlld to kind-worker
0.3997,Event,ADDED,eval-sanitize-1-r4-037-cxlld.18d4a2f7f93f9f82,"reason=Pulled count=1 msg=Container image ""busybox:musl"" already present on machine"
0.3999,Event,ADDED,eval-sanitize-1-r4-037-cxlld.18d4a2f7fa5f35ff,reason=Created count=1 msg=Created container: task
0.4002,Event,ADDED,eval-sanitize-1-r4-037-cxlld.18d4a2f7fd366886,reason=Started count=1 msg=Started container task
0.4004,Event,ADDED,eval-sanitize-1-r4-037.18d4a2f53f19b477,reason=SuccessfulCreate count=1 msg=Created pod: eval-sanitize-1-r4-037-cxlld
0.4006,Event,ADDED,eval-sanitize-1-r4-037.18d4a2fdfdadae5e,reason=Completed count=1 msg=Job completed
0.4008,Event,ADDED,eval-sanitize-1-r4-038-lgppx.18d4a2f580f65b0e,"reason=FailedScheduling count=None msg=0/6 nodes are available: 6 node(s) had untolerated taint(s). no new claims to deallocate, preemption: 0/6 nodes are available: 6 Preemption is not helpful for scheduling."
0.401,Event,ADDED,eval-sanitize-1-r4-038-lgppx.18d4a2f767b9615e,"reason=FailedScheduling count=None msg=0/6 nodes are available: 1 c_wall violated: 2 conflicting context pair(s) with node memory, 5 node(s) had untolerated taint(s). no new claims to deallocate, preemption: 0/6 nodes are available: 1 No preemption victims found for incoming pod, 5 Preemption is not helpful for scheduling."
0.4012,Event,ADDED,eval-sanitize-1-r4-038-lgppx.18d4a2f7754a1cad,"reason=FailedScheduling count=None msg=0/6 nodes are available: 1 c_wall violated: 2 conflicting context pair(s) with node memory, 5 node(s) had untolerated taint(s). no new claims to deallocate, preemption: 0/6 nodes are available: 1 No preemption victims found for incoming pod, 5 Preemption is not helpful for scheduling."
0.4014,Event,ADDED,eval-sanitize-1-r4-038-lgppx.18d4a2f7ceaeeb44,"reason=FailedScheduling count=None msg=0/6 nodes are available: 1 c_wall violated: 1 conflicting context pair(s) with node memory, 5 node(s) had untolerated taint(s). no new claims to deallocate, preemption: 0/6 nodes are available: 1 No preemption victims found for incoming pod, 5 Preemption is not helpful for scheduling."
0.4017,Event,ADDED,eval-sanitize-1-r4-038-lgppx.18d4a2f7d813e49c,"reason=FailedScheduling count=None msg=0/6 nodes are available: 1 c_wall violated: 1 conflicting context pair(s) with node memory, 5 node(s) had untolerated taint(s). no new claims to deallocate, preemption: 0/6 nodes are available: 1 No preemption victims found for incoming pod, 5 Preemption is not helpful for scheduling."
0.4018,Event,ADDED,eval-sanitize-1-r4-038-lgppx.18d4a2f7e403e94b,reason=Scheduled count=None msg=Successfully assigned compute/eval-sanitize-1-r4-038-lgppx to kind-worker
0.402,Event,ADDED,eval-sanitize-1-r4-038-lgppx.18d4a2f7fd108cd7,"reason=Pulled count=1 msg=Container image ""busybox:musl"" already present on machine"
0.4024,Event,ADDED,eval-sanitize-1-r4-038-lgppx.18d4a2f7fe92ed8c,reason=Created count=1 msg=Created container: task
0.4025,Event,ADDED,eval-sanitize-1-r4-038-lgppx.18d4a2f8023a908a,reason=Started count=1 msg=Started container task
0.4027,Event,ADDED,eval-sanitize-1-r4-038.18d4a2f580ead300,reason=SuccessfulCreate count=1 msg=Created pod: eval-sanitize-1-r4-038-lgppx
0.4029,Event,ADDED,eval-sanitize-1-r4-038.18d4a2fd7a9dbdb2,reason=Completed count=1 msg=Job completed
0.4032,Event,ADDED,eval-sanitize-1-r4-039-x9mkv.18d4a2f5b5eaa92b,"reason=FailedScheduling count=None msg=0/6 nodes are available: 6 node(s) had untolerated taint(s). no new claims to deallocate, preemption: 0/6 nodes are available: 6 Preemption is not helpful for scheduling."
0.4033,Event,ADDED,eval-sanitize-1-r4-039-x9mkv.18d4a2f76876628b,"reason=FailedScheduling count=None msg=0/6 nodes are available: 1 c_wall violated: 2 conflicting context pair(s) with node memory, 5 node(s) had untolerated taint(s). no new claims to deallocate, preemption: 0/6 nodes are available: 1 No preemption victims found for incoming pod, 5 Preemption is not helpful for scheduling."
0.4036,Event,ADDED,eval-sanitize-1-r4-039-x9mkv.18d4a2f77582021f,"reason=FailedScheduling count=None msg=0/6 nodes are available: 1 c_wall violated: 2 conflicting context pair(s) with node memory, 5 node(s) had untolerated taint(s). no new claims to deallocate, preemption: 0/6 nodes are available: 1 No preemption victims found for incoming pod, 5 Preemption is not helpful for scheduling."
0.4039,Event,ADDED,eval-sanitize-1-r4-039-x9mkv.18d4a2f7d03933c0,reason=Scheduled count=None msg=Successfully assigned compute/eval-sanitize-1-r4-039-x9mkv to kind-worker5
0.4041,Event,ADDED,eval-sanitize-1-r4-039-x9mkv.18d4a2f7ec5a45d2,"reason=Pulled count=1 msg=Container image ""busybox:musl"" already present on machine"
0.4043,Event,ADDED,eval-sanitize-1-r4-039-x9mkv.18d4a2f7edb70c7a,reason=Created count=1 msg=Created container: task
0.4044,Event,ADDED,eval-sanitize-1-r4-039-x9mkv.18d4a2f7f141d036,reason=Started count=1 msg=Started container task
0.4048,Event,ADDED,eval-sanitize-1-r4-039.18d4a2f5b5dd52b4,reason=SuccessfulCreate count=1 msg=Created pod: eval-sanitize-1-r4-039-x9mkv
0.405,Event,ADDED,eval-sanitize-1-r4-039.18d4a2fd415fdd78,reason=Completed count=1 msg=Job completed
0.4051,Event,ADDED,eval-sanitize-1-r4-040-twvmh.18d4a2f5f13fbd68,"reason=FailedScheduling count=None msg=0/6 nodes are available: 6 node(s) had untolerated taint(s). no new claims to deallocate, preemption: 0/6 nodes are available: 6 Preemption is not helpful for scheduling."
0.4054,Event,ADDED,eval-sanitize-1-r4-040-twvmh.18d4a2f76b688a92,reason=Scheduled count=None msg=Successfully assigned compute/eval-sanitize-1-r4-040-twvmh to kind-worker3
0.4056,Event,ADDED,eval-sanitize-1-r4-040-twvmh.18d4a2f78c631eae,"reason=Pulled count=1 msg=Container image ""busybox:musl"" already present on machine"
0.4058,Event,ADDED,eval-sanitize-1-r4-040-twvmh.18d4a2f78e1cd141,reason=Created count=1 msg=Created container: task
0.406,Event,ADDED,eval-sanitize-1-r4-040-twvmh.18d4a2f7928266d0,reason=Started count=1 msg=Started container task
0.4064,Event,ADDED,eval-sanitize-1-r4-040.18d4a2f5f135f594,reason=SuccessfulCreate count=1 msg=Created pod: eval-sanitize-1-r4-040-twvmh
0.4066,Event,ADDED,eval-sanitize-1-r4-040.18d4a2fcf096aae9,reason=Completed count=1 msg=Job completed
0.4067,Event,ADDED,eval-sanitize-1-r4-041-6zj8w.18d4a2f62cc45b05,"reason=FailedScheduling count=None msg=0/6 nodes are available: 6 node(s) had untolerated taint(s). no new claims to deallocate, preemption: 0/6 nodes are available: 6 Preemption is not helpful for scheduling."
0.4069,Event,ADDED,eval-sanitize-1-r4-041-6zj8w.18d4a2f76b4920b1,"reason=FailedScheduling count=None msg=0/6 nodes are available: 1 c_wall violated: 2 conflicting context pair(s) with node memory, 5 node(s) had untolerated taint(s). no new claims to deallocate, preemption: 0/6 nodes are available: 1 No preemption victims found for incoming pod, 5 Preemption is not helpful for scheduling."
0.4071,Event,ADDED,eval-sanitize-1-r4-041-6zj8w.18d4a2f775bd59a2,"reason=FailedScheduling count=None msg=0/6 nodes are available: 1 c_wall violated: 2 conflicting context pair(s) with node memory, 5 node(s) had untolerated taint(s). no new claims to deallocate, preemption: 0/6 nodes are available: 1 No preemption victims found for incoming pod, 5 Preemption is not helpful for scheduling."
0.4073,Event,ADDED,eval-sanitize-1-r4-041-6zj8w.18d4a2f7d03c3be0,"reason=FailedScheduling count=None msg=0/6 nodes are available: 1 c_wall violated: 1 conflicting context pair(s) with node memory, 5 node(s) had untolerated taint(s). no new claims to deallocate, preemption: 0/6 nodes are available: 1 No preemption victims found for incoming pod, 5 Preemption is not helpful for scheduling."
0.4074,Event,ADDED,eval-sanitize-1-r4-041-6zj8w.18d4a2f7da9612d1,"reason=FailedScheduling count=None msg=0/6 nodes are available: 1 c_wall violated: 1 conflicting context pair(s) with node memory, 5 node(s) had untolerated taint(s). no new claims to deallocate, preemption: 0/6 nodes are available: 1 No preemption victims found for incoming pod, 5 Preemption is not helpful for scheduling."
0.4116,Event,ADDED,eval-sanitize-1-r4-041-6zj8w.18d4a2f7e9091649,reason=Scheduled count=None msg=Successfully assigned compute/eval-sanitize-1-r4-041-6zj8w to kind-worker
0.4118,Event,ADDED,eval-sanitize-1-r4-041-6zj8w.18d4a2f8024a43d5,"reason=Pulled count=1 msg=Container image ""busybox:musl"" already present on machine"
0.4119,Event,ADDED,eval-sanitize-1-r4-041-6zj8w.18d4a2f803a25bfb,reason=Created count=1 msg=Created container: task
0.4123,Event,ADDED,eval-sanitize-1-r4-041-6zj8w.18d4a2f80b49b4c1,reason=Started count=1 msg=Started container task
0.4124,Event,ADDED,eval-sanitize-1-r4-041.18d4a2f62cb65eeb,reason=SuccessfulCreate count=1 msg=Created pod: eval-sanitize-1-r4-041-6zj8w
0.4126,Event,ADDED,eval-sanitize-1-r4-041.18d4a2fe009eeb11,reason=Completed count=1 msg=Job completed
0.4128,Event,ADDED,eval-sanitize-1-r4-042-bfmd5.18d4a2f668960719,"reason=FailedScheduling count=None msg=0/6 nodes are available: 6 node(s) had untolerated taint(s). no new claims to deallocate, preemption: 0/6 nodes are available: 6 Preemption is not helpful for scheduling."
0.4131,Event,ADDED,eval-sanitize-1-r4-042-bfmd5.18d4a2f76c0083d3,"reason=FailedScheduling count=None msg=0/6 nodes are available: 1 c_wall violated: 4 conflicting context pair(s) with node memory, 5 node(s) had untolerated taint(s). no new claims to deallocate, preemption: 0/6 nodes are available: 1 No preemption victims found for incoming pod, 5 Preemption is not helpful for scheduling."
0.4133,Event,ADDED,eval-sanitize-1-r4-042-bfmd5.18d4a2f775fa67d8,"reason=FailedScheduling count=None msg=0/6 nodes are available: 1 c_wall violated: 4 conflicting context pair(s) with node memory, 5 node(s) had untolerated taint(s). no new claims to deallocate, preemption: 0/6 nodes are available: 1 No preemption victims found for incoming pod, 5 Preemption is not helpful for scheduling."
0.4135,Event,ADDED,eval-sanitize-1-r4-042-bfmd5.18d4a2f7d299fe77,reason=Scheduled count=None msg=Successfully assigned compute/eval-sanitize-1-r4-042-bfmd5 to kind-worker5
0.4137,Event,ADDED,eval-sanitize-1-r4-042-bfmd5.18d4a2f7f0d41ff4,"reason=Pulled count=1 msg=Container image ""busybox:musl"" already present on machine"
0.4139,Event,ADDED,eval-sanitize-1-r4-042-bfmd5.18d4a2f7f2237cf2,reason=Created count=1 msg=Created container: task
0.4141,Event,ADDED,eval-sanitize-1-r4-042-bfmd5.18d4a2f7f44e9b03,reason=Started count=1 msg=Started container task
0.4143,Event,ADDED,eval-sanitize-1-r4-042.18d4a2f6688a6dfe,reason=SuccessfulCreate count=1 msg=Created pod: eval-sanitize-1-r4-042-bfmd5
0.4146,Event,ADDED,eval-sanitize-1-r4-042.18d4a2fd41072ba0,reason=Completed count=1 msg=Job completed
0.4147,Event,ADDED,eval-sanitize-1-r4-043-lmg9h.18d4a2f6a3f062b5,"reason=FailedScheduling count=None msg=0/6 nodes are available: 6 node(s) had untolerated taint(s). no new claims to deallocate, preemption: 0/6 nodes are available: 6 Preemption is not helpful for scheduling."
0.4149,Event,ADDED,eval-sanitize-1-r4-043-lmg9h.18d4a2f76ccb6b0c,"reason=FailedScheduling count=None msg=0/6 nodes are available: 1 c_wall violated: 2 conflicting context pair(s) with node memory, 5 node(s) had untolerated taint(s). no new claims to deallocate, preemption: 0/6 nodes are available: 1 No preemption victims found for incoming pod, 5 Preemption is not helpful for scheduling."
0.4152,Event,ADDED,eval-sanitize-1-r4-043-lmg9h.18d4a2f7762cd306,"reason=FailedScheduling count=None msg=0/6 nodes are available: 1 c_wall violated: 2 conflicting context pair(s) with node memory, 5 node(s) had untolerated taint(s). no new claims to deallocate, preemption: 0/6 nodes are available: 1 No preemption victims found for incoming pod, 5 Preemption is not helpful for scheduling."
0.4153,Event,ADDED,eval-sanitize-1-r4-043-lmg9h.18d4a2f7d2c61acf,reason=Scheduled count=None msg=Successfully assigned compute/eval-sanitize-1-r4-043-lmg9h to kind-worker5
0.4155,Event,ADDED,eval-sanitize-1-r4-043-lmg9h.18d4a2f7f193e0a6,"reason=Pulled count=1 msg=Container image ""busybox:musl"" already present on machine"
0.4157,Event,ADDED,eval-sanitize-1-r4-043-lmg9h.18d4a2f7f2fed111,reason=Created count=1 msg=Created container: task
0.4158,Event,ADDED,eval-sanitize-1-r4-043-lmg9h.18d4a2f7f508bf88,reason=Started count=1 msg=Started container task
0.416,Event,ADDED,eval-sanitize-1-r4-043.18d4a2f6a3e38b68,reason=SuccessfulCreate count=1 msg=Created pod: eval-sanitize-1-r4-043-lmg9h
0.4162,Event,ADDED,eval-sanitize-1-r4-043.18d4a2fe1865b76e,reason=Completed count=1 msg=Job completed
0.4163,Event,ADDED,eval-sanitize-1-r4-044-t8hxw.18d4a2f6df71fc82,"reason=FailedScheduling count=None msg=0/6 nodes are available: 6 node(s) had untolerated taint(s). no new claims to deallocate, preemption: 0/6 nodes are available: 6 Preemption is not helpful for scheduling."
0.4165,Event,ADDED,eval-sanitize-1-r4-044-t8hxw.18d4a2f76d40e362,"reason=FailedScheduling count=None msg=0/6 nodes are available: 1 c_wall violated: 2 conflicting context pair(s) with node memory, 5 node(s) had untolerated taint(s). no new claims to deallocate, preemption: 0/6 nodes are available: 1 No preemption victims found for incoming pod, 5 Preemption is not helpful for scheduling."
0.4166,Event,ADDED,eval-sanitize-1-r4-044-t8hxw.18d4a2f776d3e51b,"reason=FailedScheduling count=None msg=0/6 nodes are available: 1 c_wall violated: 2 conflicting context pair(s) with node memory, 5 node(s) had untolerated taint(s). no new claims to deallocate, preemption: 0/6 nodes are available: 1 No preemption victims found for incoming pod, 5 Preemption is not helpful for scheduling."
0.4168,Event,ADDED,eval-sanitize-1-r4-044-t8hxw.18d4a2f7d488667c,"reason=FailedScheduling count=None msg=0/6 nodes are available: 1 c_wall violated: 2 conflicting context pair(s) with node memory, 5 node(s) had untolerated taint(s). no new claims to deallocate, preemption: 0/6 nodes are available: 1 No preemption victims found for incoming pod, 5 Preemption is not helpful for scheduling."
0.417,Event,ADDED,eval-sanitize-1-r4-044-t8hxw.18d4a2f7db0dc76f,reason=Scheduled count=None msg=Successfully assigned compute/eval-sanitize-1-r4-044-t8hxw to kind-worker
0.4171,Event,ADDED,eval-sanitize-1-r4-044-t8hxw.18d4a2f7f3884f23,"reason=Pulled count=1 msg=Container image ""busybox:musl"" already present on machine"
0.4174,Event,ADDED,eval-sanitize-1-r4-044-t8hxw.18d4a2f7f4d46ec2,reason=Created count=1 msg=Created container: task
0.4177,Event,ADDED,eval-sanitize-1-r4-044-t8hxw.18d4a2f7f7620181,reason=Started count=1 msg=Started container task
0.4179,Event,ADDED,eval-sanitize-1-r4-044.18d4a2f6df65e19b,reason=SuccessfulCreate count=1 msg=Created pod: eval-sanitize-1-r4-044-t8hxw
0.4181,Event,ADDED,eval-sanitize-1-r4-044.18d4a2fe13b0338f,reason=Completed count=1 msg=Job completed
0.4184,Event,ADDED,eval-sanitize-1-r4-045-fz8hv.18d4a2f71e67798b,"reason=FailedScheduling count=None msg=0/6 nodes are available: 6 node(s) had untolerated taint(s). no new claims to deallocate, preemption: 0/6 nodes are available: 6 Preemption is not helpful for scheduling."
0.4185,Event,ADDED,eval-sanitize-1-r4-045-fz8hv.18d4a2f76f3bb3fd,"reason=FailedScheduling count=None msg=0/6 nodes are available: 1 c_wall violated: 2 conflicting context pair(s) with node memory, 5 node(s) had untolerated taint(s). no new claims to deallocate, preemption: 0/6 nodes are available: 1 No preemption victims found for incoming pod, 5 Preemption is not helpful for scheduling."
0.4187,Event,ADDED,eval-sanitize-1-r4-045-fz8hv.18d4a2f77b1cd788,"reason=FailedScheduling count=None msg=0/6 nodes are available: 1 c_wall violated: 2 conflicting context pair(s) with node memory, 5 node(s) had untolerated taint(s). no new claims to deallocate, preemption: 0/6 nodes are available: 1 No preemption victims found for incoming pod, 5 Preemption is not helpful for scheduling."
0.4192,Event,ADDED,eval-sanitize-1-r4-045-fz8hv.18d4a2f7c95bf481,reason=Scheduled count=None msg=Successfully assigned compute/eval-sanitize-1-r4-045-fz8hv to kind-worker5
0.4194,Event,ADDED,eval-sanitize-1-r4-045-fz8hv.18d4a2f7e4d12653,"reason=Pulled count=1 msg=Container image ""busybox:musl"" already present on machine"
0.4196,Event,ADDED,eval-sanitize-1-r4-045-fz8hv.18d4a2f7e6736c9a,reason=Created count=1 msg=Created container: task
0.4198,Event,ADDED,eval-sanitize-1-r4-045-fz8hv.18d4a2f7eb631f5d,reason=Started count=1 msg=Started container task
0.4202,Event,ADDED,eval-sanitize-1-r4-045.18d4a2f71e5cb15e,reason=SuccessfulCreate count=1 msg=Created pod: eval-sanitize-1-r4-045-fz8hv
0.4204,Event,ADDED,eval-sanitize-1-r4-045.18d4a2fe1b8d41f2,reason=Completed count=1 msg=Job completed
0.4206,Event,ADDED,eval-sanitize-1-r4-046-b4rwf.18d4a2f756a31ede,"reason=FailedScheduling count=None msg=0/6 nodes are available: 6 node(s) had untolerated taint(s). no new claims to deallocate, preemption: 0/6 nodes are available: 6 Preemption is not helpful for scheduling."
