t_recv,kind,type,name,detail
0.0234,Node,ADDED,kind-control-plane,taints=1
0.0255,Node,ADDED,kind-worker,taints=0
0.0265,Node,ADDED,kind-worker2,taints=0
0.0282,Node,ADDED,kind-worker3,taints=0
0.0294,Node,ADDED,kind-worker4,taints=0
0.0306,Node,ADDED,kind-worker5,taints=0
0.0515,TaskRequest,ADDED,eval-conflicts-rho040-r6-000,phase=None job=None
0.0555,TaskRequest,MODIFIED,eval-conflicts-rho040-r6-000,phase=Pending job=None
0.0619,Event,ADDED,eval-conflicts-rho020-r0-000-ktmb9.18d4677df479e92b,reason=Scheduled count=None msg=Successfully assigned compute/eval-conflicts-rho020-r0-000-ktmb9 to kind-worker5
0.0623,Event,ADDED,eval-conflicts-rho020-r0-000-ktmb9.18d4677e12a61816,"reason=Pulled count=1 msg=Container image ""busybox:musl"" already present on machine"
0.0625,Event,ADDED,eval-conflicts-rho020-r0-000-ktmb9.18d4677e145884e7,reason=Created count=1 msg=Created container: task
0.0627,Event,ADDED,eval-conflicts-rho020-r0-000-ktmb9.18d4677e1795b922,reason=Started count=1 msg=Started container task
0.0629,Event,ADDED,eval-conflicts-rho020-r0-000.18d4677df365239b,reason=SuccessfulCreate count=1 msg=Created pod: eval-conflicts-rho020-r0-000-ktmb9
0.0633,Event,ADDED,eval-conflicts-rho020-r0-000.18d467813a6634ea,reason=Completed count=1 msg=Job completed
0.0634,Event,ADDED,eval-conflicts-rho020-r0-001-ndskb.18d4677e2f2b327b,reason=Scheduled count=None msg=Successfully assigned compute/eval-conflicts-rho020-r0-001-ndskb to kind-worker2
0.0636,Event,ADDED,eval-conflicts-rho020-r0-001-ndskb.18d4677e4d7deaf7,"reason=Pulled count=1 msg=Container image ""busybox:musl"" already present on machine"
0.0644,Event,ADDED,eval-conflicts-rho020-r0-001-ndskb.18d4677e4ea5a7fe,reason=Created count=1 msg=Created container: task
0.0648,Event,ADDED,eval-conflicts-rho020-r0-001-ndskb.18d4677e53332f8e,reason=Started count=1 msg=Started container task
0.0653,Event,ADDED,eval-conflicts-rho020-r0-001.18d4677e2e13df84,reason=SuccessfulCreate count=1 msg=Created pod: eval-conflicts-rho020-r0-001-ndskb
0.0657,Event,ADDED,eval-conflicts-rho020-r0-001.18d467816938258d,reason=Completed count=1 msg=Job completed
0.0662,Event,ADDED,eval-conflicts-rho020-r0-002-2xhq7.18d4677e6a502114,reason=Scheduled count=None msg=Successfully assigned compute/eval-conflicts-rho020-r0-002-2xhq7 to kind-worker5
0.0666,Event,ADDED,eval-conflicts-rho020-r0-002-2xhq7.18d4677e82f68d9d,"reason=Pulled count=1 msg=Container image ""busybox:musl"" already present on machine"
0.0668,Event,ADDED,eval-conflicts-rho020-r0-002-2xhq7.18d4677e84220d5b,reason=Created count=1 msg=Created container: task
0.067,Event,ADDED,eval-conflicts-rho020-r0-002-2xhq7.18d4677e862ef2c5,reason=Started count=1 msg=Started container task
0.0674,Event,ADDED,eval-conflicts-rho020-r0-002.18d4677e69463362,reason=SuccessfulCreate count=1 msg=Created pod: eval-conflicts-rho020-r0-002-2xhq7
0.0677,Event,ADDED,eval-conflicts-rho020-r0-002.18d46781b1ceb28e,reason=Completed count=1 msg=Job completed
0.0679,Event,ADDED,eval-conflicts-rho020-r0-003-4k7pc.18d4677ea65825cd,reason=Scheduled count=None msg=Successfully assigned compute/eval-conflicts-rho020-r0-003-4k7pc to kind-worker
0.0682,Event,ADDED,eval-conflicts-rho020-r0-003-4k7pc.18d4677ebe8cd782,"reason=Pulled count=1 msg=Container image ""busybox:musl"" already present on machine"
0.0684,Event,ADDED,eval-conflicts-rho020-r0-003-4k7pc.18d4677ebffb0129,reason=Created count=1 msg=Created container: task
0.0686,Event,ADDED,eval-conflicts-rho020-r0-003-4k7pc.18d4677ec20a8e1c,reason=Started count=1 msg=Started container task
0.0688,Event,ADDED,eval-conflicts-rho020-r0-003.18d4677ea553d63b,reason=SuccessfulCreate count=1 msg=Created pod: eval-conflicts-rho020-r0-003-4k7pc
0.0692,Event,ADDED,eval-conflicts-rho020-r0-003.18d46781e591ab13,reason=Completed count=1 msg=Job completed
0.0694,Event,ADDED,eval-conflicts-rho020-r0-004-wds79.18d4677ee0c3c401,reason=Scheduled count=None msg=Successfully assigned compute/eval-conflicts-rho020-r0-004-wds79 to kind-worker
0.0696,Event,ADDED,eval-conflicts-rho020-r0-004-wds79.18d4677efad7bc80,"reason=Pulled count=1 msg=Container image ""busybox:musl"" already present on machine"
0.0697,Event,ADDED,eval-conflicts-rho020-r0-004-wds79.18d4677efc042a85,reason=Created count=1 msg=Created container: task
0.0701,Event,ADDED,eval-conflicts-rho020-r0-004-wds79.18d4677efe0ef6d8,reason=Started count=1 msg=Started container task
0.0703,Event,ADDED,eval-conflicts-rho020-r0-004.18d4677edf9c4f3c,reason=SuccessfulCreate count=1 msg=Created pod: eval-conflicts-rho020-r0-004-wds79
0.0705,Event,ADDED,eval-conflicts-rho020-r0-004.18d46782214420ec,reason=Completed count=1 msg=Job completed
0.0708,Event,ADDED,eval-conflicts-rho020-r0-005-rkx9b.18d4677f1d0d3061,reason=Scheduled count=None msg=Successfully assigned compute/eval-conflicts-rho020-r0-005-rkx9b to kind-worker2
0.071,Event,ADDED,eval-conflicts-rho020-r0-005-rkx9b.18d4677f36cb6d8e,"reason=Pulled count=1 msg=Container image ""busybox:musl"" already present on machine"
0.0712,Event,ADDED,eval-conflicts-rho020-r0-005-rkx9b.18d4677f37f86312,reason=Created count=1 msg=Created container: task
0.0713,Event,ADDED,eval-conflicts-rho020-r0-005-rkx9b.18d4677f3b140765,reason=Started count=1 msg=Started container task
0.0717,Event,ADDED,eval-conflicts-rho020-r0-005.18d4677f1bc594cc,reason=SuccessfulCreate count=1 msg=Created pod: eval-conflicts-rho020-r0-005-rkx9b
0.0719,Event,ADDED,eval-conflicts-rho020-r0-005.18d467825823ae56,reason=Completed count=1 msg=Job completed
0.072,Event,ADDED,eval-conflicts-rho020-r0-006-wz8wq.18d4677f587f758e,reason=Scheduled count=None msg=Successfully assigned compute/eval-conflicts-rho020-r0-006-wz8wq to kind-worker4
0.0722,Event,ADDED,eval-conflicts-rho020-r0-006-wz8wq.18d4677f71757fbd,"reason=Pulled count=1 msg=Container image ""busybox:musl"" already present on machine"
0.0725,Event,ADDED,eval-conflicts-rho020-r0-006-wz8wq.18d4677f728bac33,reason=Created count=1 msg=Created container: task
0.0728,Event,ADDED,eval-conflicts-rho020-r0-006-wz8wq.18d4677f7636b23f,reason=Started count=1 msg=Started container task
0.073,Event,ADDED,eval-conflicts-rho020-r0-006.18d4677f57546068,reason=SuccessfulCreate count=1 msg=Created pod: eval-conflicts-rho020-r0-006-wz8wq
0.0736,Event,ADDED,eval-conflicts-rho020-r0-006.18d46782a696d36c,reason=Completed count=1 msg=Job completed
0.0738,Event,ADDED,eval-conflicts-rho020-r0-007-4h55j.18d4677f937fd4a9,reason=Scheduled count=None msg=Successfully assigned compute/eval-conflicts-rho020-r0-007-4h55j to kind-worker3
0.074,Event,ADDED,eval-conflicts-rho020-r0-007-4h55j.18d4677fac352c0b,"reason=Pulled count=1 msg=Container image ""busybox:musl"" already present on machine"
0.0743,Event,ADDED,eval-conflicts-rho020-r0-007-4h55j.18d4677fad3bef47,reason=Created count=1 msg=Created container: task
0.0746,Event,ADDED,eval-conflicts-rho020-r0-007-4h55j.18d4677faf195392,reason=Started count=1 msg=Started container task
0.0748,Event,ADDED,eval-conflicts-rho020-r0-007.18d4677f92ecf379,reason=SuccessfulCreate count=1 msg=Created pod: eval-conflicts-rho020-r0-007-4h55j
0.0749,Event,ADDED,eval-conflicts-rho020-r0-007.18d46782f03ee197,reason=Completed count=1 msg=Job completed
0.0755,Job,ADDED,eval-conflicts-rho040-r6-000,
0.0758,Event,ADDED,eval-conflicts-rho020-r0-008-qndfq.18d4677fceef9a49,reason=Scheduled count=None msg=Successfully assigned compute/eval-conflicts-rho020-r0-008-qndfq to kind-worker3
0.076,Event,ADDED,eval-conflicts-rho020-r0-008-qndfq.18d4677fe8035067,"reason=Pulled count=1 msg=Container image ""busybox:musl"" already present on machine"
0.0762,Event,ADDED,eval-conflicts-rho020-r0-008-qndfq.18d4677fe9169a5c,reason=Created count=1 msg=Created container: task
0.0764,Event,ADDED,eval-conflicts-rho020-r0-008-qndfq.18d4677feb10bfa7,reason=Started count=1 msg=Started container task
0.0768,Event,ADDED,eval-conflicts-rho020-r0-008.18d4677fce46e424,reason=SuccessfulCreate count=1 msg=Created pod: eval-conflicts-rho020-r0-008-qndfq
0.077,Event,ADDED,eval-conflicts-rho020-r0-008.18d467832c264621,reason=Completed count=1 msg=Job completed
0.0771,Event,ADDED,eval-conflicts-rho020-r0-009-zxncj.18d467800a9fb5f9,"reason=FailedScheduling count=None msg=0/6 nodes are available: 1 c_wall violated: 1 conflicting context pair(s) with node memory, 5 node(s) had untolerated taint(s). no new claims to deallocate, preemption: 0/6 nodes are available: 1 No preemption victims found for incoming pod, 5 Preemption is not helpful for scheduling."
0.0775,Event,ADDED,eval-conflicts-rho020-r0-009-zxncj.18d467800b432771,"reason=FailedScheduling count=None msg=0/6 nodes are available: 1 c_wall violated: 1 conflicting context pair(s) with node memory, 5 node(s) had untolerated taint(s). no new claims to deallocate, preemption: 0/6 nodes are available: 1 No preemption victims found for incoming pod, 5 Preemption is not helpful for scheduling."
0.0777,Event,ADDED,eval-conflicts-rho020-r0-009-zxncj.18d46781c3e952bf,reason=Scheduled count=None msg=Successfully assigned compute/eval-conflicts-rho020-r0-009-zxncj to kind-worker
0.0781,Event,ADDED,eval-conflicts-rho020-r0-009-zxncj.18d46781dd5e06d8,"reason=Pulled count=1 msg=Container image ""busybox:musl"" already present on machine"
0.0783,Event,ADDED,eval-conflicts-rho020-r0-009-zxncj.18d46781dee189c6,reason=Created count=1 msg=Created container: task
0.0787,Event,ADDED,eval-conflicts-rho020-r0-009-zxncj.18d46781e6f55e29,reason=Started count=1 msg=Started container task
0.0789,Event,ADDED,eval-conflicts-rho020-r0-009.18d467800a5b0570,reason=SuccessfulCreate count=1 msg=Created pod: eval-conflicts-rho020-r0-009-zxncj
0.0792,Event,ADDED,eval-conflicts-rho020-r0-009.18d46784f252aad4,reason=Completed count=1 msg=Job completed
0.0793,TaskRequest,MODIFIED,eval-conflicts-rho040-r6-000,phase=Scheduled job=None
0.0796,Event,ADDED,eval-conflicts-rho020-r0-010-ffhc2.18d467804617ed0b,"reason=FailedScheduling count=None msg=0/6 nodes are available: 1 c_wall violated: 1 conflicting context pair(s) with node memory, 5 node(s) had untolerated taint(s). no new claims to deallocate, preemption: 0/6 nodes are available: 1 No preemption victims found for incoming pod, 5 Preemption is not helpful for scheduling."
0.0799,Event,ADDED,eval-conflicts-rho020-r0-010-ffhc2.18d4678046a0b30f,"reason=FailedScheduling count=None msg=0/6 nodes are available: 1 c_wall violated: 1 conflicting context pair(s) with node memory, 5 node(s) had untolerated taint(s). no new claims to deallocate, preemption: 0/6 nodes are available: 1 No preemption victims found for incoming pod, 5 Preemption is not helpful for scheduling."
0.08,Event,ADDED,eval-conflicts-rho020-r0-010-ffhc2.18d46781c3d04e49,"reason=FailedScheduling count=None msg=0/6 nodes are available: 1 c_wall violated: 1 conflicting context pair(s) with node memory, 5 node(s) had untolerated taint(s). no new claims to deallocate, preemption: 0/6 nodes are available: 1 No preemption victims found for incoming pod, 5 Preemption is not helpful for scheduling."
0.0803,Event,ADDED,eval-conflicts-rho020-r0-010-ffhc2.18d46781c544228f,"reason=FailedScheduling count=None msg=0/6 nodes are available: 1 c_wall violated: 1 conflicting context pair(s) with node memory, 5 node(s) had untolerated taint(s). no new claims to deallocate, preemption: 0/6 nodes are available: 1 No preemption victims found for incoming pod, 5 Preemption is not helpful for scheduling."
0.0805,Event,ADDED,eval-conflicts-rho020-r0-010-ffhc2.18d46782387c5ba3,reason=Scheduled count=None msg=Successfully assigned compute/eval-conflicts-rho020-r0-010-ffhc2 to kind-worker5
0.0806,Event,ADDED,eval-conflicts-rho020-r0-010-ffhc2.18d467824de2b1d5,"reason=Pulled count=1 msg=Container image ""busybox:musl"" already present on machine"
0.0808,Event,ADDED,eval-conflicts-rho020-r0-010-ffhc2.18d467824f3bf78c,reason=Created count=1 msg=Created container: task
0.0811,Event,ADDED,eval-conflicts-rho020-r0-010-ffhc2.18d4678253523def,reason=Started count=1 msg=Started container task
0.0816,Event,ADDED,eval-conflicts-rho020-r0-010.18d4678045c9a350,reason=SuccessfulCreate count=1 msg=Created pod: eval-conflicts-rho020-r0-010-ffhc2
0.0819,Event,ADDED,eval-conflicts-rho020-r0-010.18d4678532ebb830,reason=Completed count=1 msg=Job completed
0.0826,Event,ADDED,eval-conflicts-rho020-r0-011-zr7jb.18d46780818c131b,"reason=FailedScheduling count=None msg=0/6 nodes are available: 1 c_wall violated: 1 conflicting context pair(s) with node memory, 5 node(s) had untolerated taint(s). no new claims to deallocate, preemption: 0/6 nodes are available: 1 No preemption victims found for incoming pod, 5 Preemption is not helpful for scheduling."
0.083,Event,ADDED,eval-conflicts-rho020-r0-011-zr7jb.18d46780821d636f,"reason=FailedScheduling count=None msg=0/6 nodes are available: 1 c_wall violated: 1 conflicting context pair(s) with node memory, 5 node(s) had untolerated taint(s). no new claims to deallocate, preemption: 0/6 nodes are available: 1 No preemption victims found for incoming pod, 5 Preemption is not helpful for scheduling."
0.0832,Event,ADDED,eval-conflicts-rho020-r0-011-zr7jb.18d46781c4c1f5ef,reason=Scheduled count=None msg=Successfully assigned compute/eval-conflicts-rho020-r0-011-zr7jb to kind-worker
0.0836,Event,ADDED,eval-conflicts-rho020-r0-011-zr7jb.18d46781de5d5ecb,"reason=Pulled count=1 msg=Container image ""busybox:musl"" already present on machine"
0.0838,Event,ADDED,eval-conflicts-rho020-r0-011-zr7jb.18d46781e0257c15,reason=Created count=1 msg=Created container: task
0.084,Event,ADDED,eval-conflicts-rho020-r0-011-zr7jb.18d46781e30573ac,reason=Started count=1 msg=Started container task
0.0842,Event,ADDED,eval-conflicts-rho020-r0-011.18d46780814e46fc,reason=SuccessfulCreate count=1 msg=Created pod: eval-conflicts-rho020-r0-011-zr7jb
0.0849,Pod,ADDED,eval-conflicts-rho040-r6-000-62xmt,phase=Pending node=None
0.0853,Event,ADDED,eval-conflicts-rho020-r0-011.18d467852ce0d855,reason=Completed count=1 msg=Job completed
0.0855,Event,ADDED,eval-conflicts-rho020-r0-012-xjx5d.18d46780bd8f4962,reason=Scheduled count=None msg=Successfully assigned compute/eval-conflicts-rho020-r0-012-xjx5d to kind-worker3
0.0857,Event,ADDED,eval-conflicts-rho020-r0-012-xjx5d.18d46780d6d5a409,"reason=Pulled count=1 msg=Container image ""busybox:musl"" already present on machine"
0.0858,Event,ADDED,eval-conflicts-rho020-r0-012-xjx5d.18d46780d7fb2525,reason=Created count=1 msg=Created container: task
0.0862,Event,ADDED,eval-conflicts-rho020-r0-012-xjx5d.18d46780da244268,reason=Started count=1 msg=Started container task
0.0864,Event,ADDED,eval-conflicts-rho020-r0-012.18d46780bd079552,reason=SuccessfulCreate count=1 msg=Created pod: eval-conflicts-rho020-r0-012-xjx5d
0.0866,Event,ADDED,eval-conflicts-rho020-r0-012.18d467841bdc13ad,reason=Completed count=1 msg=Job completed
0.0869,Event,ADDED,eval-conflicts-rho020-r0-013-fkznw.18d46780f8a3e38d,reason=Scheduled count=None msg=Successfully assigned compute/eval-conflicts-rho020-r0-013-fkznw to kind-worker3
0.0871,Event,ADDED,eval-conflicts-rho020-r0-013-fkznw.18d46781120ae587,"reason=Pulled count=1 msg=Container image ""busybox:musl"" already present on machine"
0.0873,Event,ADDED,eval-conflicts-rho020-r0-013-fkznw.18d46781132683e4,reason=Created count=1 msg=Created container: task
0.0875,Event,ADDED,eval-conflicts-rho020-r0-013-fkznw.18d4678117ebf3a1,reason=Started count=1 msg=Started container task
0.0878,Event,ADDED,eval-conflicts-rho020-r0-013.18d46780f81d63dc,reason=SuccessfulCreate count=1 msg=Created pod: eval-conflicts-rho020-r0-013-fkznw
0.088,Event,ADDED,eval-conflicts-rho020-r0-013.18d4678457afd53e,reason=Completed count=1 msg=Job completed
0.0883,Event,ADDED,eval-conflicts-rho020-r0-014-7j25q.18d4678134b91386,reason=Scheduled count=None msg=Successfully assigned compute/eval-conflicts-rho020-r0-014-7j25q to kind-worker3
0.0885,Event,ADDED,eval-conflicts-rho020-r0-014-7j25q.18d467814f1da493,"reason=Pulled count=1 msg=Container image ""busybox:musl"" already present on machine"
0.0889,Event,ADDED,eval-conflicts-rho020-r0-014-7j25q.18d46781503e0fd2,reason=Created count=1 msg=Created container: task
0.089,Event,ADDED,eval-conflicts-rho020-r0-014-7j25q.18d46781523f20e8,reason=Started count=1 msg=Started container task
0.0892,Event,ADDED,eval-conflicts-rho020-r0-014.18d4678134192679,reason=SuccessfulCreate count=1 msg=Created pod: eval-conflicts-rho020-r0-014-7j25q
0.0894,Event,ADDED,eval-conflicts-rho020-r0-014.18d4678493171321,reason=Completed count=1 msg=Job completed
0.0898,Event,ADDED,eval-conflicts-rho020-r0-015-8jmzp.18d46781700cde5f,"reason=FailedScheduling count=None msg=0/6 nodes are available: 1 c_wall violated: 1 conflicting context pair(s) with node memory, 5 node(s) had untolerated taint(s). no new claims to deallocate, preemption: 0/6 nodes are available: 1 No preemption victims found for incoming pod, 5 Preemption is not helpful for scheduling."
0.09,Event,ADDED,eval-conflicts-rho020-r0-015-8jmzp.18d46781710dc5ff,"reason=FailedScheduling count=None msg=0/6 nodes are available: 1 c_wall violated: 1 conflicting context pair(s) with node memory, 5 node(s) had untolerated taint(s). no new claims to deallocate, preemption: 0/6 nodes are available: 1 No preemption victims found for incoming pod, 5 Preemption is not helpful for scheduling."
0.0904,Event,ADDED,eval-conflicts-rho020-r0-015-8jmzp.18d46781c4de5f1a,reason=Scheduled count=None msg=Successfully assigned compute/eval-conflicts-rho020-r0-015-8jmzp to kind-worker
0.0906,Event,ADDED,eval-conflicts-rho020-r0-015-8jmzp.18d46781de426ec3,"reason=Pulled count=1 msg=Container image ""busybox:musl"" already present on machine"
0.0907,Event,ADDED,eval-conflicts-rho020-r0-015-8jmzp.18d46781dfd56990,reason=Created count=1 msg=Created container: task
0.0909,Event,ADDED,eval-conflicts-rho020-r0-015-8jmzp.18d46781e301dc65,reason=Started count=1 msg=Started container task
0.0918,Job,MODIFIED,eval-conflicts-rho040-r6-000,
0.0921,Event,ADDED,eval-conflicts-rho020-r0-015.18d467816fcfe0f6,reason=SuccessfulCreate count=1 msg=Created pod: eval-conflicts-rho020-r0-015-8jmzp
0.0923,Event,ADDED,eval-conflicts-rho020-r0-015.18d46784f0e7a985,reason=Completed count=1 msg=Job completed
0.0925,Event,ADDED,eval-conflicts-rho020-r0-016-lqmf8.18d46781ab551664,"reason=FailedScheduling count=None msg=0/6 nodes are available: 6 node(s) had untolerated taint(s). no new claims to deallocate, preemption: 0/6 nodes are available: 6 Preemption is not helpful for scheduling."
0.0928,Event,ADDED,eval-conflicts-rho020-r0-016-lqmf8.18d46781c4afeeef,"reason=FailedScheduling count=None msg=0/6 nodes are available: 1 c_wall violated: 1 conflicting context pair(s) with node memory, 5 node(s) had untolerated taint(s). no new claims to deallocate, preemption: 0/6 nodes are available: 1 No preemption victims found for incoming pod, 5 Preemption is not helpful for scheduling."
0.093,Event,ADDED,eval-conflicts-rho020-r0-016-lqmf8.18d46781c57804e1,"reason=FailedScheduling count=None msg=0/6 nodes are available: 1 c_wall violated: 1 conflicting context pair(s) with node memory, 5 node(s) had untolerated taint(s). no new claims to deallocate, preemption: 0/6 nodes are available: 1 No preemption victims found for incoming pod, 5 Preemption is not helpful for scheduling."
0.0932,Event,ADDED,eval-conflicts-rho020-r0-016-lqmf8.18d4678238cdd8f4,reason=Scheduled count=None msg=Successfully assigned compute/eval-conflicts-rho020-r0-016-lqmf8 to kind-worker5
0.0934,Event,ADDED,eval-conflicts-rho020-r0-016-lqmf8.18d467825449455c,"reason=Pulled count=1 msg=Container image ""busybox:musl"" already present on machine"
0.0937,Event,ADDED,eval-conflicts-rho020-r0-016-lqmf8.18d46782555be1e2,reason=Created count=1 msg=Created container: task
0.0939,Event,ADDED,eval-conflicts-rho020-r0-016-lqmf8.18d4678258fac059,reason=Started count=1 msg=Started container task
0.0941,Event,ADDED,eval-conflicts-rho020-r0-016.18d46781ab4f6cc5,reason=SuccessfulCreate count=1 msg=Created pod: eval-conflicts-rho020-r0-016-lqmf8
0.0942,TaskRequest,MODIFIED,eval-conflicts-rho040-r6-000,phase=Scheduled job=None
0.0946,Event,ADDED,eval-conflicts-rho020-r0-016.18d4678533c7f5e2,reason=Completed count=1 msg=Job completed
0.0947,Event,ADDED,eval-conflicts-rho020-r0-017-d87dk.18d46781e79636c0,reason=Scheduled count=None msg=Successfully assigned compute/eval-conflicts-rho020-r0-017-d87dk to kind-worker
0.0949,Event,ADDED,eval-conflicts-rho020-r0-017-d87dk.18d4678200d18614,"reason=Pulled count=1 msg=Container image ""busybox:musl"" already present on machine"
0.0951,Event,ADDED,eval-conflicts-rho020-r0-017-d87dk.18d4678201f89794,reason=Created count=1 msg=Created container: task
0.0957,Event,ADDED,eval-conflicts-rho020-r0-017-d87dk.18d4678203ff288a,reason=Started count=1 msg=Started container task
0.0962,Event,ADDED,eval-conflicts-rho020-r0-017.18d46781e70dffeb,reason=SuccessfulCreate count=1 msg=Created pod: eval-conflicts-rho020-r0-017-d87dk
0.0964,Event,ADDED,eval-conflicts-rho020-r0-017.18d467852c33682d,reason=Completed count=1 msg=Job completed
0.0966,Event,ADDED,eval-conflicts-rho020-r0-018-wjgg6.18d46782230fe948,reason=Scheduled count=None msg=Successfully assigned compute/eval-conflicts-rho020-r0-018-wjgg6 to kind-worker
0.0969,Event,ADDED,eval-conflicts-rho020-r0-018-wjgg6.18d467823da6822b,"reason=Pulled count=1 msg=Container image ""busybox:musl"" already present on machine"
0.0971,Event,ADDED,eval-conflicts-rho020-r0-018-wjgg6.18d467823ec44021,reason=Created count=1 msg=Created container: task
0.0973,Event,ADDED,eval-conflicts-rho020-r0-018-wjgg6.18d4678240c4cf36,reason=Started count=1 msg=Started container task
0.098,Pod,MODIFIED,eval-conflicts-rho040-r6-000-62xmt,phase=Pending node=kind-worker2
0.0984,Event,ADDED,eval-conflicts-rho020-r0-018.18d4678222812151,reason=SuccessfulCreate count=1 msg=Created pod: eval-conflicts-rho020-r0-018-wjgg6
0.0986,Event,ADDED,eval-conflicts-rho020-r0-018.18d467852d0a668c,reason=Completed count=1 msg=Job completed
0.0988,Event,ADDED,eval-conflicts-rho020-r0-019-wb9vv.18d467825e5b856f,"reason=FailedScheduling count=None msg=0/6 nodes are available: 2 c_wall violated: 1 conflicting context pair(s) with node memory, 4 node(s) had untolerated taint(s). no new claims to deallocate, preemption: 0/6 nodes are available: 2 No preemption victims found for incoming pod, 4 Preemption is not helpful for scheduling."
0.0993,Event,ADDED,eval-conflicts-rho020-r0-019-wb9vv.18d467825f0e7cdd,"reason=FailedScheduling count=None msg=0/6 nodes are available: 2 c_wall violated: 1 conflicting context pair(s) with node memory, 4 node(s) had untolerated taint(s). no new claims to deallocate, preemption: 0/6 nodes are available: 2 No preemption victims found for incoming pod, 4 Preemption is not helpful for scheduling."
0.0997,Event,ADDED,eval-conflicts-rho020-r0-019-wb9vv.18d46783132af16f,"reason=FailedScheduling count=None msg=0/6 nodes are available: 1 c_wall violated: 1 conflicting context pair(s) with node memory, 1 c_wall violated: 2 conflicting context pair(s) with node memory, 4 node(s) had untolerated taint(s). no new claims to deallocate, preemption: 0/6 nodes are available: 2 No preemption victims found for incoming pod, 4 Preemption is not helpful for scheduling."
0.1001,Event,ADDED,eval-conflicts-rho020-r0-019-wb9vv.18d467841fd893ad,"reason=FailedScheduling count=None msg=0/6 nodes are available: 1 c_wall violated: 2 conflicting context pair(s) with node memory, 5 node(s) had untolerated taint(s). no new claims to deallocate, preemption: 0/6 nodes are available: 1 No preemption victims found for incoming pod, 5 Preemption is not helpful for scheduling."
0.1007,Event,ADDED,eval-conflicts-rho020-r0-019-wb9vv.18d467843caa8792,reason=Scheduled count=None msg=Successfully assigned compute/eval-conflicts-rho020-r0-019-wb9vv to kind-worker4
0.1012,Event,ADDED,eval-conflicts-rho020-r0-019-wb9vv.18d46784569afcdd,"reason=Pulled count=1 msg=Container image ""busybox:musl"" already present on machine"
0.1015,Event,ADDED,eval-conflicts-rho020-r0-019-wb9vv.18d46784588c75da,reason=Created count=1 msg=Created container: task
0.1019,Event,ADDED,eval-conflicts-rho020-r0-019-wb9vv.18d467845c47385c,reason=Started count=1 msg=Started container task
0.1024,Event,ADDED,eval-conflicts-rho020-r0-019.18d467825de63a80,reason=SuccessfulCreate count=1 msg=Created pod: eval-conflicts-rho020-r0-019-wb9vv
0.1027,Event,ADDED,eval-conflicts-rho020-r0-019.18d467878e8e0a25,reason=Completed count=1 msg=Job completed
0.103,Event,ADDED,eval-conflicts-rho020-r0-020-4cppg.18d467829a842425,reason=Scheduled count=None msg=Successfully assigned compute/eval-conflicts-rho020-r0-020-4cppg to kind-worker5
0.1034,Event,ADDED,eval-conflicts-rho020-r0-020-4cppg.18d46782b3bf6071,"reason=Pulled count=1 msg=Container image ""busybox:musl"" already present on machine"
0.1038,Event,ADDED,eval-conflicts-rho020-r0-020-4cppg.18d46782b529650b,reason=Created count=1 msg=Created container: task
0.1041,Event,ADDED,eval-conflicts-rho020-r0-020-4cppg.18d46782b90ef460,reason=Started count=1 msg=Started container task
0.1043,Event,ADDED,eval-conflicts-rho020-r0-020.18d4678299af8ce5,reason=SuccessfulCreate count=1 msg=Created pod: eval-conflicts-rho020-r0-020-4cppg
0.1049,Event,ADDED,eval-conflicts-rho020-r0-020.18d46785e7c05013,reason=Completed count=1 msg=Job completed
0.1053,Event,ADDED,eval-conflicts-rho020-r0-021-f572g.18d46782d64fab06,reason=Scheduled count=None msg=Successfully assigned compute/eval-conflicts-rho020-r0-021-f572g to kind-worker5
0.1058,Event,ADDED,eval-conflicts-rho020-r0-021-f572g.18d46782efabf437,"reason=Pulled count=1 msg=Container image ""busybox:musl"" already present on machine"
0.1061,Event,ADDED,eval-conflicts-rho020-r0-021-f572g.18d46782f1117544,reason=Created count=1 msg=Created container: task
0.1072,Event,ADDED,eval-conflicts-rho020-r0-021-f572g.18d46782f44886cf,reason=Started count=1 msg=Started container task
0.1076,Event,ADDED,eval-conflicts-rho020-r0-021.18d46782d51c664d,reason=SuccessfulCreate count=1 msg=Created pod: eval-conflicts-rho020-r0-021-f572g
0.108,Event,ADDED,eval-conflicts-rho020-r0-021.18d4678623872364,reason=Completed count=1 msg=Job completed
0.1086,Event,ADDED,eval-conflicts-rho020-r0-022-mcvjk.18d46783117373e5,reason=Scheduled count=None msg=Successfully assigned compute/eval-conflicts-rho020-r0-022-mcvjk to kind-worker5
0.1089,Event,ADDED,eval-conflicts-rho020-r0-022-mcvjk.18d467832c9191b8,"reason=Pulled count=1 msg=Container image ""busybox:musl"" already present on machine"
0.1093,Event,ADDED,eval-conflicts-rho020-r0-022-mcvjk.18d467832ded4c2e,reason=Created count=1 msg=Created container: task
0.1095,Event,ADDED,eval-conflicts-rho020-r0-022-mcvjk.18d4678333edeaab,reason=Started count=1 msg=Started container task
0.1101,Event,ADDED,eval-conflicts-rho020-r0-022.18d46783108eb6bb,reason=SuccessfulCreate count=1 msg=Created pod: eval-conflicts-rho020-r0-022-mcvjk
0.1104,Event,ADDED,eval-conflicts-rho020-r0-022.18d467865fed67d9,reason=Completed count=1 msg=Job completed
0.1106,Event,ADDED,eval-conflicts-rho020-r0-023-rts7d.18d467834ce0fa62,"reason=FailedScheduling count=None msg=0/6 nodes are available: 1 c_wall violated: 1 conflicting context pair(s) with node memory, 1 c_wall violated: 2 conflicting context pair(s) with node memory, 4 node(s) had untolerated taint(s). no new claims to deallocate, preemption: 0/6 nodes are available: 2 No preemption victims found for incoming pod, 4 Preemption is not helpful for scheduling."
0.1132,Pod,MODIFIED,eval-conflicts-rho040-r6-000-62xmt,phase=Pending node=kind-worker2
0.1137,Event,ADDED,eval-conflicts-rho020-r0-023-rts7d.18d467834dbf6df4,"reason=FailedScheduling count=None msg=0/6 nodes are available: 1 c_wall violated: 1 conflicting context pair(s) with node memory, 1 c_wall violated: 2 conflicting context pair(s) with node memory, 4 node(s) had untolerated taint(s). no new claims to deallocate, preemption: 0/6 nodes are available: 2 No preemption victims found for incoming pod, 4 Preemption is not helpful for scheduling."
0.114,Event,ADDED,eval-conflicts-rho020-r0-023-rts7d.18d46784200331d8,"reason=FailedScheduling count=None msg=0/6 nodes are available: 1 c_wall violated: 2 conflicting context pair(s) with node memory, 5 node(s) had untolerated taint(s). no new claims to deallocate, preemption: 0/6 nodes are available: 1 No preemption victims found for incoming pod, 5 Preemption is not helpful for scheduling."
0.1143,Event,ADDED,eval-conflicts-rho020-r0-023-rts7d.18d467843ceab57e,reason=Scheduled count=None msg=Successfully assigned compute/eval-conflicts-rho020-r0-023-rts7d to kind-worker4
0.1148,Event,ADDED,eval-conflicts-rho020-r0-023-rts7d.18d4678457340cb9,"reason=Pulled count=1 msg=Container image ""busybox:musl"" already present on machine"
0.1152,Event,ADDED,eval-conflicts-rho020-r0-023-rts7d.18d46784592b95f6,reason=Created count=1 msg=Created container: task
0.1155,Event,ADDED,eval-conflicts-rho020-r0-023-rts7d.18d4678460eb750e,reason=Started count=1 msg=Started container task
0.1158,Event,ADDED,eval-conflicts-rho020-r0-023.18d467834c647a43,reason=SuccessfulCreate count=1 msg=Created pod: eval-conflicts-rho020-r0-023-rts7d
0.1163,Event,ADDED,eval-conflicts-rho020-r0-023.18d467878e8f2941,reason=Completed count=1 msg=Job completed
0.1166,Event,ADDED,eval-conflicts-rho020-r0-024-6fk82.18d46783891fd016,"reason=FailedScheduling count=None msg=0/6 nodes are available: 1 c_wall violated: 1 conflicting context pair(s) with node memory, 1 c_wall violated: 2 conflicting context pair(s) with node memory, 4 node(s) had untolerated taint(s). no new claims to deallocate, preemption: 0/6 nodes are available: 2 No preemption victims found for incoming pod, 4 Preemption is not helpful for scheduling."
0.1169,Event,ADDED,eval-conflicts-rho020-r0-024-6fk82.18d4678389cd5f22,"reason=FailedScheduling count=None msg=0/6 nodes are available: 1 c_wall violated: 1 conflicting context pair(s) with node memory, 1 c_wall violated: 2 conflicting context pair(s) with node memory, 4 node(s) had untolerated taint(s). no new claims to deallocate, preemption: 0/6 nodes are available: 2 No preemption victims found for incoming pod, 4 Preemption is not helpful for scheduling."
0.1176,Event,ADDED,eval-conflicts-rho020-r0-024-6fk82.18d467841faa5aed,"reason=FailedScheduling count=None msg=0/6 nodes are available: 1 c_wall violated: 2 conflicting context pair(s) with node memory, 5 node(s) had untolerated taint(s). no new claims to deallocate, preemption: 0/6 nodes are available: 1 No preemption victims found for incoming pod, 5 Preemption is not helpful for scheduling."
0.118,Event,ADDED,eval-conflicts-rho020-r0-024-6fk82.18d4678442c3b4c3,reason=Scheduled count=None msg=Successfully assigned compute/eval-conflicts-rho020-r0-024-6fk82 to kind-worker4
0.1184,Event,ADDED,eval-conflicts-rho020-r0-024-6fk82.18d467845e9d62a7,"reason=Pulled count=1 msg=Container image ""busybox:musl"" already present on machine"
0.119,Event,ADDED,eval-conflicts-rho020-r0-024-6fk82.18d467845fd428ea,reason=Created count=1 msg=Created container: task
0.1193,Event,ADDED,eval-conflicts-rho020-r0-024-6fk82.18d46784621143a7,reason=Started count=1 msg=Started container task
0.1195,Event,ADDED,eval-conflicts-rho020-r0-024.18d4678388a8318f,reason=SuccessfulCreate count=1 msg=Created pod: eval-conflicts-rho020-r0-024-6fk82
0.1198,Event,ADDED,eval-conflicts-rho020-r0-024.18d467878e683954,reason=Completed count=1 msg=Job completed
0.1203,Event,ADDED,eval-conflicts-rho020-r0-025-jnppp.18d46783c442975f,reason=Scheduled count=None msg=Successfully assigned compute/eval-conflicts-rho020-r0-025-jnppp to kind-worker
0.1205,Event,ADDED,eval-conflicts-rho020-r0-025-jnppp.18d46783ddbe4a36,"reason=Pulled count=1 msg=Container image ""busybox:musl"" already present on machine"
0.1207,Event,ADDED,eval-conflicts-rho020-r0-025-jnppp.18d46783df15149e,reason=Created count=1 msg=Created container: task
0.1209,Event,ADDED,eval-conflicts-rho020-r0-025-jnppp.18d46783e79a5db5,reason=Started count=1 msg=Started container task
0.1213,Event,ADDED,eval-conflicts-rho020-r0-025.18d46783c3916916,reason=SuccessfulCreate count=1 msg=Created pod: eval-conflicts-rho020-r0-025-jnppp
0.1215,Event,ADDED,eval-conflicts-rho020-r0-025.18d467870c3791a8,reason=Completed count=1 msg=Job completed
0.1217,Event,ADDED,eval-conflicts-rho020-r0-026-8psns.18d467840015dc6b,reason=Scheduled count=None msg=Successfully assigned compute/eval-conflicts-rho020-r0-026-8psns to kind-worker
0.1219,Event,ADDED,eval-conflicts-rho020-r0-026-8psns.18d467841a1876ad,"reason=Pulled count=1 msg=Container image ""busybox:musl"" already present on machine"
0.1221,Event,ADDED,eval-conflicts-rho020-r0-026-8psns.18d467841bc0039c,reason=Created count=1 msg=Created container: task
0.1223,Event,ADDED,eval-conflicts-rho020-r0-026-8psns.18d46784213d5988,reason=Started count=1 msg=Started container task
0.1225,Event,ADDED,eval-conflicts-rho020-r0-026.18d46783ff5b1c27,reason=SuccessfulCreate count=1 msg=Created pod: eval-conflicts-rho020-r0-026-8psns
0.1227,Event,ADDED,eval-conflicts-rho020-r0-026.18d46787484d4320,reason=Completed count=1 msg=Job completed
0.1228,Event,ADDED,eval-conflicts-rho020-r0-027-h6pl5.18d467843aede448,"reason=FailedScheduling count=None msg=0/6 nodes are available: 1 c_wall violated: 1 conflicting context pair(s) with node memory, 5 node(s) had untolerated taint(s). no new claims to deallocate, preemption: 0/6 nodes are available: 1 No preemption victims found for incoming pod, 5 Preemption is not helpful for scheduling."
0.1232,Event,ADDED,eval-conflicts-rho020-r0-027-h6pl5.18d467843b9dfcd2,"reason=FailedScheduling count=None msg=0/6 nodes are available: 1 c_wall violated: 1 conflicting context pair(s) with node memory, 5 node(s) had untolerated taint(s). no new claims to deallocate, preemption: 0/6 nodes are available: 1 No preemption victims found for incoming pod, 5 Preemption is not helpful for scheduling."
0.1237,Event,ADDED,eval-conflicts-rho020-r0-027-h6pl5.18d4678442baa4f8,"reason=FailedScheduling count=None msg=0/6 nodes are available: 2 c_wall violated: 1 conflicting context pair(s) with node memory, 4 node(s) had untolerated taint(s). no new claims to deallocate, preemption: 0/6 nodes are available: 2 No preemption victims found for incoming pod, 4 Preemption is not helpful for scheduling."
0.1239,Event,ADDED,eval-conflicts-rho020-r0-027-h6pl5.18d4678448f024fd,reason=Scheduled count=None msg=Successfully assigned compute/eval-conflicts-rho020-r0-027-h6pl5 to kind-worker2
0.1241,Event,ADDED,eval-conflicts-rho020-r0-027-h6pl5.18d4678461fe1fc5,"reason=Pulled count=1 msg=Container image ""busybox:musl"" already present on machine"
0.1246,Event,ADDED,eval-conflicts-rho020-r0-027-h6pl5.18d467846336f8a6,reason=Created count=1 msg=Created container: task
0.1248,Event,ADDED,eval-conflicts-rho020-r0-027-h6pl5.18d4678465a0a3fa,reason=Started count=1 msg=Started container task
0.125,Event,ADDED,eval-conflicts-rho020-r0-027.18d467843aad6b2c,reason=SuccessfulCreate count=1 msg=Created pod: eval-conflicts-rho020-r0-027-h6pl5
0.1253,Event,ADDED,eval-conflicts-rho020-r0-027.18d467877a571b3e,reason=Completed count=1 msg=Job completed
0.1256,Event,ADDED,eval-conflicts-rho020-r0-028-2bsts.18d46784787cafc9,reason=Scheduled count=None msg=Successfully assigned compute/eval-conflicts-rho020-r0-028-2bsts to kind-worker5
0.1258,Event,ADDED,eval-conflicts-rho020-r0-028-2bsts.18d467849117f901,"reason=Pulled count=1 msg=Container image ""busybox:musl"" already present on machine"
0.126,Event,ADDED,eval-conflicts-rho020-r0-028-2bsts.18d467849238834e,reason=Created count=1 msg=Created container: task
0.1262,Event,ADDED,eval-conflicts-rho020-r0-028-2bsts.18d467849454b50d,reason=Started count=1 msg=Started container task
0.1277,Node,MODIFIED,kind-worker2,taints=0
0.1283,Event,ADDED,eval-conflicts-rho020-r0-028.18d4678476ae5df4,reason=SuccessfulCreate count=1 msg=Created pod: eval-conflicts-rho020-r0-028-2bsts
0.1287,Event,ADDED,eval-conflicts-rho020-r0-028.18d46787c5cdba45,reason=Completed count=1 msg=Job completed
0.129,Event,ADDED,eval-conflicts-rho020-r0-029-wx5ws.18d46784b266adea,reason=Scheduled count=None msg=Successfully assigned compute/eval-conflicts-rho020-r0-029-wx5ws to kind-worker4
0.1295,Event,ADDED,eval-conflicts-rho020-r0-029-wx5ws.18d46784cb803750,"reason=Pulled count=1 msg=Container image ""busybox:musl"" already present on machine"
0.1297,Event,ADDED,eval-conflicts-rho020-r0-029-wx5ws.18d46784cc9e58e6,reason=Created count=1 msg=Created container: task
0.1299,Event,ADDED,eval-conflicts-rho020-r0-029-wx5ws.18d46784ce85f097,reason=Started count=1 msg=Started container task
0.13,Event,ADDED,eval-conflicts-rho020-r0-029.18d46784b1d01d40,reason=SuccessfulCreate count=1 msg=Created pod: eval-conflicts-rho020-r0-029-wx5ws
0.1304,Event,ADDED,eval-conflicts-rho020-r0-029.18d4678806326fcd,reason=Completed count=1 msg=Job completed
0.1306,Event,ADDED,eval-conflicts-rho020-r0-030-9tszl.18d46784ee787be8,reason=Scheduled count=None msg=Successfully assigned compute/eval-conflicts-rho020-r0-030-9tszl to kind-worker2
0.1308,Event,ADDED,eval-conflicts-rho020-r0-030-9tszl.18d4678507cf58cd,"reason=Pulled count=1 msg=Container image ""busybox:musl"" already present on machine"
0.1311,Event,ADDED,eval-conflicts-rho020-r0-030-9tszl.18d4678508d80f55,reason=Created count=1 msg=Created container: task
0.1313,Event,ADDED,eval-conflicts-rho020-r0-030-9tszl.18d467850f086535,reason=Started count=1 msg=Started container task
0.1315,Event,ADDED,eval-conflicts-rho020-r0-030.18d46784edb647e6,reason=SuccessfulCreate count=1 msg=Created pod: eval-conflicts-rho020-r0-030-9tszl
0.1317,Event,ADDED,eval-conflicts-rho020-r0-030.18d467882e6caf56,reason=Completed count=1 msg=Job completed
0.132,Event,ADDED,eval-conflicts-rho020-r0-031-dh7tc.18d467852a5abc9f,"reason=FailedScheduling count=None msg=0/6 nodes are available: 2 c_wall violated: 1 conflicting context pair(s) with node memory, 4 node(s) had untolerated taint(s). no new claims to deallocate, preemption: 0/6 nodes are available: 2 No preemption victims found for incoming pod, 4 Preemption is not helpful for scheduling."
0.1323,Event,ADDED,eval-conflicts-rho020-r0-031-dh7tc.18d467852afb9a3d,"reason=FailedScheduling count=None msg=0/6 nodes are available: 2 c_wall violated: 1 conflicting context pair(s) with node memory, 4 node(s) had untolerated taint(s). no new claims to deallocate, preemption: 0/6 nodes are available: 2 No preemption victims found for incoming pod, 4 Preemption is not helpful for scheduling."
0.1325,Event,ADDED,eval-conflicts-rho020-r0-031-dh7tc.18d467866d27f98d,reason=Scheduled count=None msg=Successfully assigned compute/eval-conflicts-rho020-r0-031-dh7tc to kind-worker3
0.1328,Event,ADDED,eval-conflicts-rho020-r0-031-dh7tc.18d4678686a89663,"reason=Pulled count=1 msg=Container image ""busybox:musl"" already present on machine"
0.133,Event,ADDED,eval-conflicts-rho020-r0-031-dh7tc.18d4678687bf94c1,reason=Created count=1 msg=Created container: task
0.1332,Event,ADDED,eval-conflicts-rho020-r0-031-dh7tc.18d4678689992158,reason=Started count=1 msg=Started container task
0.1333,Event,ADDED,eval-conflicts-rho020-r0-031.18d4678529e95b84,reason=SuccessfulCreate count=1 msg=Created pod: eval-conflicts-rho020-r0-031-dh7tc
0.1337,Event,ADDED,eval-conflicts-rho020-r0-031.18d46789b5e7423b,reason=Completed count=1 msg=Job completed
0.1339,Event,ADDED,eval-conflicts-rho020-r0-032-jl6pc.18d46785657aaa6d,reason=Scheduled count=None msg=Successfully assigned compute/eval-conflicts-rho020-r0-032-jl6pc to kind-worker2
0.134,Event,ADDED,eval-conflicts-rho020-r0-032-jl6pc.18d467858128b5c0,"reason=Pulled count=1 msg=Container image ""busybox:musl"" already present on machine"
0.1344,Event,ADDED,eval-conflicts-rho020-r0-032-jl6pc.18d467858239d124,reason=Created count=1 msg=Created container: task
0.1346,Event,ADDED,eval-conflicts-rho020-r0-032-jl6pc.18d467858a95ada2,reason=Started count=1 msg=Started container task
0.1349,Event,ADDED,eval-conflicts-rho020-r0-032.18d4678564bd185f,reason=SuccessfulCreate count=1 msg=Created pod: eval-conflicts-rho020-r0-032-jl6pc
0.1353,Event,ADDED,eval-conflicts-rho020-r0-032.18d46788a5562990,reason=Completed count=1 msg=Job completed
0.1357,Event,ADDED,eval-conflicts-rho020-r0-033-p69lz.18d46785a13465c6,reason=Scheduled count=None msg=Successfully assigned compute/eval-conflicts-rho020-r0-033-p69lz to kind-worker2
0.1359,Event,ADDED,eval-conflicts-rho020-r0-033-p69lz.18d46785ba10ece5,"reason=Pulled count=1 msg=Container image ""busybox:musl"" already present on machine"
0.136,Event,ADDED,eval-conflicts-rho020-r0-033-p69lz.18d46785bb2d822d,reason=Created count=1 msg=Created container: task
0.1363,Event,ADDED,eval-conflicts-rho020-r0-033-p69lz.18d46785c0a77584,reason=Started count=1 msg=Started container task
0.1366,Event,ADDED,eval-conflicts-rho020-r0-033.18d46785a070a051,reason=SuccessfulCreate count=1 msg=Created pod: eval-conflicts-rho020-r0-033-p69lz
0.1367,Event,ADDED,eval-conflicts-rho020-r0-033.18d46788e1486561,reason=Completed count=1 msg=Job completed
0.1369,Event,ADDED,eval-conflicts-rho020-r0-034-4lcrn.18d46785dd43ebf7,reason=Scheduled count=None msg=Successfully assigned compute/eval-conflicts-rho020-r0-034-4lcrn to kind-worker2
0.1371,Event,ADDED,eval-conflicts-rho020-r0-034-4lcrn.18d46785f6997600,"reason=Pulled count=1 msg=Container image ""busybox:musl"" already present on machine"
0.1373,Event,ADDED,eval-conflicts-rho020-r0-034-4lcrn.18d46785f7b4289f,reason=Created count=1 msg=Created container: task
0.1374,Event,ADDED,eval-conflicts-rho020-r0-034-4lcrn.18d46785fa98b367,reason=Started count=1 msg=Started container task
0.1376,Event,ADDED,eval-conflicts-rho020-r0-034.18d46785dc88a45f,reason=SuccessfulCreate count=1 msg=Created pod: eval-conflicts-rho020-r0-034-4lcrn
0.1378,Event,ADDED,eval-conflicts-rho020-r0-034.18d467891d988f30,reason=Completed count=1 msg=Job completed
0.1379,Event,ADDED,eval-conflicts-rho020-r0-035-krgjj.18d4678618cd394f,reason=Scheduled count=None msg=Successfully assigned compute/eval-conflicts-rho020-r0-035-krgjj to kind-worker2
0.1381,Event,ADDED,eval-conflicts-rho020-r0-035-krgjj.18d4678630e5f7b6,"reason=Pulled count=1 msg=Container image ""busybox:musl"" already present on machine"
0.1383,Event,ADDED,eval-conflicts-rho020-r0-035-krgjj.18d4678632076155,reason=Created count=1 msg=Created container: task
0.1384,Event,ADDED,eval-conflicts-rho020-r0-035-krgjj.18d4678633e4c4fe,reason=Started count=1 msg=Started container task
0.1386,Event,ADDED,eval-conflicts-rho020-r0-035.18d46786178f63cb,reason=SuccessfulCreate count=1 msg=Created pod: eval-conflicts-rho020-r0-035-krgjj
0.1388,Event,ADDED,eval-conflicts-rho020-r0-035.18d46789590bb25d,reason=Completed count=1 msg=Job completed
0.1391,Event,ADDED,eval-conflicts-rho020-r0-036-dkp5l.18d4678653b522a2,reason=Scheduled count=None msg=Successfully assigned compute/eval-conflicts-rho020-r0-036-dkp5l to kind-worker4
0.1393,Event,ADDED,eval-conflicts-rho020-r0-036-dkp5l.18d467866cbefb7e,"reason=Pulled count=1 msg=Container image ""busybox:musl"" already present on machine"
0.1395,Event,ADDED,eval-conflicts-rho020-r0-036-dkp5l.18d467866e1425a4,reason=Created count=1 msg=Created container: task
0.1396,Event,ADDED,eval-conflicts-rho020-r0-036-dkp5l.18d46786702b64a1,reason=Started count=1 msg=Started container task
0.1399,Event,ADDED,eval-conflicts-rho020-r0-036.18d4678652fc6e6f,reason=SuccessfulCreate count=1 msg=Created pod: eval-conflicts-rho020-r0-036-dkp5l
0.1401,Event,ADDED,eval-conflicts-rho020-r0-036.18d46789a79db4a2,reason=Completed count=1 msg=Job completed
0.1403,Event,ADDED,eval-conflicts-rho020-r0-037-cjbnk.18d467868fc1b3d5,reason=Scheduled count=None msg=Successfully assigned compute/eval-conflicts-rho020-r0-037-cjbnk to kind-worker3
0.1405,Event,ADDED,eval-conflicts-rho020-r0-037-cjbnk.18d46786a8d837fb,"reason=Pulled count=1 msg=Container image ""busybox:musl"" already present on machine"
0.1407,Event,ADDED,eval-conflicts-rho020-r0-037-cjbnk.18d46786a9e2b82e,reason=Created count=1 msg=Created container: task
0.1409,Event,ADDED,eval-conflicts-rho020-r0-037-cjbnk.18d46786abdbaf14,reason=Started count=1 msg=Started container task
0.1411,Event,ADDED,eval-conflicts-rho020-r0-037.18d467868e9cb0bc,reason=SuccessfulCreate count=1 msg=Created pod: eval-conflicts-rho020-r0-037-cjbnk
0.1413,Event,ADDED,eval-conflicts-rho020-r0-037.18d46789f2b3830a,reason=Completed count=1 msg=Job completed
0.1414,Event,ADDED,eval-conflicts-rho020-r0-038-rf2lq.18d46786cab8325f,reason=Scheduled count=None msg=Successfully assigned compute/eval-conflicts-rho020-r0-038-rf2lq to kind-worker3
0.1416,Event,ADDED,eval-conflicts-rho020-r0-038-rf2lq.18d46786e42b14b4,"reason=Pulled count=1 msg=Container image ""busybox:musl"" already present on machine"
0.1419,Event,ADDED,eval-conflicts-rho020-r0-038-rf2lq.18d46786e534d87d,reason=Created count=1 msg=Created container: task
0.1422,Event,ADDED,eval-conflicts-rho020-r0-038-rf2lq.18d46786e9cb9466,reason=Started count=1 msg=Started container task
0.1424,Event,ADDED,eval-conflicts-rho020-r0-038.18d46786ca34171c,reason=SuccessfulCreate count=1 msg=Created pod: eval-conflicts-rho020-r0-038-rf2lq
0.1427,Event,ADDED,eval-conflicts-rho020-r0-038.18d4678a2e819ba6,reason=Completed count=1 msg=Job completed
0.1433,Event,ADDED,eval-conflicts-rho020-r0-039-zbn6l.18d4678706716d6d,reason=Scheduled count=None msg=Successfully assigned compute/eval-conflicts-rho020-r0-039-zbn6l to kind-worker3
0.1436,Event,ADDED,eval-conflicts-rho020-r0-039-zbn6l.18d467872008f4bd,"reason=Pulled count=1 msg=Container image ""busybox:musl"" already present on machine"
0.144,Event,ADDED,eval-conflicts-rho020-r0-039-zbn6l.18d46787211e8285,reason=Created count=1 msg=Created container: task
0.1444,Event,ADDED,eval-conflicts-rho020-r0-039-zbn6l.18d46787233f93ad,reason=Started count=1 msg=Started container task
0.1447,Event,ADDED,eval-conflicts-rho020-r0-039.18d4678705e5e5a4,reason=SuccessfulCreate count=1 msg=Created pod: eval-conflicts-rho020-r0-039-zbn6l
0.1449,Event,ADDED,eval-conflicts-rho020-r0-039.18d4678a2d9a1afc,reason=Completed count=1 msg=Job completed
0.1451,Event,ADDED,eval-conflicts-rho020-r0-040-57xfx.18d4678742632be2,reason=Scheduled count=None msg=Successfully assigned compute/eval-conflicts-rho020-r0-040-57xfx to kind-worker3
0.1453,Event,ADDED,eval-conflicts-rho020-r0-040-57xfx.18d467875c2ca4b1,"reason=Pulled count=1 msg=Container image ""busybox:musl"" already present on machine"
0.1456,Event,ADDED,eval-conflicts-rho020-r0-040-57xfx.18d467875d3ebe43,reason=Created count=1 msg=Created container: task
0.1458,Event,ADDED,eval-conflicts-rho020-r0-040-57xfx.18d467875f4efb94,reason=Started count=1 msg=Started container task
0.146,Event,ADDED,eval-conflicts-rho020-r0-040.18d46787416d1349,reason=SuccessfulCreate count=1 msg=Created pod: eval-conflicts-rho020-r0-040-57xfx
0.1462,Event,ADDED,eval-conflicts-rho020-r0-040.18d4678a69b17b18,reason=Completed count=1 msg=Job completed
0.1464,Event,ADDED,eval-conflicts-rho020-r0-041-cx5wf.18d46787821312be,reason=Scheduled count=None msg=Successfully assigned compute/eval-conflicts-rho020-r0-041-cx5wf to kind-worker3
0.1466,Event,ADDED,eval-conflicts-rho020-r0-041-cx5wf.18d467879ad3a384,"reason=Pulled count=1 msg=Container image ""busybox:musl"" already present on machine"
0.1467,Event,ADDED,eval-conflicts-rho020-r0-041-cx5wf.18d467879be60fd3,reason=Created count=1 msg=Created container: task
0.1469,Event,ADDED,eval-conflicts-rho020-r0-041-cx5wf.18d467879dd6fe2d,reason=Started count=1 msg=Started container task
0.1472,Event,ADDED,eval-conflicts-rho020-r0-041.18d467877d2cc0a3,reason=SuccessfulCreate count=1 msg=Created pod: eval-conflicts-rho020-r0-041-cx5wf
0.1474,Event,ADDED,eval-conflicts-rho020-r0-041.18d4678ae15b58f3,reason=Completed count=1 msg=Job completed
0.1476,Event,ADDED,eval-conflicts-rho020-r0-042-mv8sp.18d46787babac865,reason=Scheduled count=None msg=Successfully assigned compute/eval-conflicts-rho020-r0-042-mv8sp to kind-worker3
0.1491,Node,MODIFIED,kind-worker2,taints=0
0.1493,Event,ADDED,eval-conflicts-rho020-r0-042-mv8sp.18d46787d4506a15,"reason=Pulled count=1 msg=Container image ""busybox:musl"" already present on machine"
0.1495,Event,ADDED,eval-conflicts-rho020-r0-042-mv8sp.18d46787d568f222,reason=Created count=1 msg=Created container: task
0.1497,Event,ADDED,eval-conflicts-rho020-r0-042-mv8sp.18d46787d9d71a02,reason=Started count=1 msg=Started container task
0.1501,Event,ADDED,eval-conflicts-rho020-r0-042.18d46787ba016404,reason=SuccessfulCreate count=1 msg=Created pod: eval-conflicts-rho020-r0-042-mv8sp
0.1503,Event,ADDED,eval-conflicts-rho020-r0-042.18d4678ae1bb7fa5,reason=Completed count=1 msg=Job completed
0.1504,Event,ADDED,eval-conflicts-rho020-r0-043-cqj42.18d46787f4a9cdde,"reason=FailedScheduling count=None msg=0/6 nodes are available: 1 c_wall violated: 2 conflicting context pair(s) with node memory, 5 node(s) had untolerated taint(s). no new claims to deallocate, preemption: 0/6 nodes are available: 1 No preemption victims found for incoming pod, 5 Preemption is not helpful for scheduling."
0.1507,Event,ADDED,eval-conflicts-rho020-r0-043-cqj42.18d46787f535f213,"reason=FailedScheduling count=None msg=0/6 nodes are available: 1 c_wall violated: 2 conflicting context pair(s) with node memory, 5 node(s) had untolerated taint(s). no new claims to deallocate, preemption: 0/6 nodes are available: 1 No preemption victims found for incoming pod, 5 Preemption is not helpful for scheduling."
0.1509,Event,ADDED,eval-conflicts-rho020-r0-043-cqj42.18d46789026084e7,reason=Scheduled count=None msg=Successfully assigned compute/eval-conflicts-rho020-r0-043-cqj42 to kind-worker
0.1511,Event,ADDED,eval-conflicts-rho020-r0-043-cqj42.18d467891b878214,"reason=Pulled count=1 msg=Container image ""busybox:musl"" already present on machine"
0.1512,Event,ADDED,eval-conflicts-rho020-r0-043-cqj42.18d467891d5ee7e2,reason=Created count=1 msg=Created container: task
0.1514,Event,ADDED,eval-conflicts-rho020-r0-043-cqj42.18d4678921f45420,reason=Started count=1 msg=Started container task
0.1516,Event,ADDED,eval-conflicts-rho020-r0-043.18d46787f4683e34,reason=SuccessfulCreate count=1 msg=Created pod: eval-conflicts-rho020-r0-043-cqj42
0.1518,Event,ADDED,eval-conflicts-rho020-r0-043.18d4678c2f2d2c1a,reason=Completed count=1 msg=Job completed
0.1519,Event,ADDED,eval-conflicts-rho020-r0-044-vdcql.18d46788310139e8,reason=Scheduled count=None msg=Successfully assigned compute/eval-conflicts-rho020-r0-044-vdcql to kind-worker3
0.1521,Event,ADDED,eval-conflicts-rho020-r0-044-vdcql.18d467884a20eb83,"reason=Pulled count=1 msg=Container image ""busybox:musl"" already present on machine"
0.1525,Event,ADDED,eval-conflicts-rho020-r0-044-vdcql.18d467884b37c189,reason=Created count=1 msg=Created container: task
0.1527,Event,ADDED,eval-conflicts-rho020-r0-044-vdcql.18d467884d48a713,reason=Started count=1 msg=Started container task
0.153,Event,ADDED,eval-conflicts-rho020-r0-044.18d467883065a5d8,reason=SuccessfulCreate count=1 msg=Created pod: eval-conflicts-rho020-r0-044-vdcql
0.1531,Event,ADDED,eval-conflicts-rho020-r0-044.18d4678b596da52c,reason=Completed count=1 msg=Job completed
0.1534,Event,ADDED,eval-conflicts-rho020-r0-045-5xzj4.18d467886c739a04,reason=Scheduled count=None msg=Successfully assigned compute/eval-conflicts-rho020-r0-045-5xzj4 to kind-worker3
0.1536,Event,ADDED,eval-conflicts-rho020-r0-045-5xzj4.18d4678885cbc09c,"reason=Pulled count=1 msg=Container image ""busybox:musl"" already present on machine"
0.1538,Event,ADDED,eval-conflicts-rho020-r0-045-5xzj4.18d4678886f34586,reason=Created count=1 msg=Created container: task
0.154,Event,ADDED,eval-conflicts-rho020-r0-045-5xzj4.18d4678889093a4b,reason=Started count=1 msg=Started container task
0.1541,Event,ADDED,eval-conflicts-rho020-r0-045.18d467886bd957b9,reason=SuccessfulCreate count=1 msg=Created pod: eval-conflicts-rho020-r0-045-5xzj4
0.1543,Event,ADDED,eval-conflicts-rho020-r0-045.18d4678b95580b17,reason=Completed count=1 msg=Job completed
0.1545,Event,ADDED,eval-conflicts-rho020-r0-046-v5hnp.18d46788a82e2e03,reason=Scheduled count=None msg=Successfully assigned compute/eval-conflicts-rho020-r0-046-v5hnp to kind-worker3
0.1547,Event,ADDED,eval-conflicts-rho020-r0-046-v5hnp.18d46788c150bb5c,"reason=Pulled count=1 msg=Container image ""busybox:musl"" already present on machine"
0.1548,Event,ADDED,eval-conflicts-rho020-r0-046-v5hnp.18d46788c268338d,reason=Created count=1 msg=Created container: task
0.155,Event,ADDED,eval-conflicts-rho020-r0-046-v5hnp.18d46788c44e6ce8,reason=Started count=1 msg=Started container task
0.1552,Event,ADDED,eval-conflicts-rho020-r0-046.18d46788a79b6fc0,reason=SuccessfulCreate count=1 msg=Created pod: eval-conflicts-rho020-r0-046-v5hnp
0.1553,Event,ADDED,eval-conflicts-rho020-r0-046.18d4678bd1138dff,reason=Completed count=1 msg=Job completed
0.1555,Event,ADDED,eval-conflicts-rho020-r0-047-7jnp8.18d46788e2f0889e,"reason=FailedScheduling count=None msg=0/6 nodes are available: 6 node(s) had untolerated taint(s). no new claims to deallocate, preemption: 0/6 nodes are available: 6 Preemption is not helpful for scheduling."
0.1556,Event,ADDED,eval-conflicts-rho020-r0-047-7jnp8.18d4678902963806,reason=Scheduled count=None msg=Successfully assigned compute/eval-conflicts-rho020-r0-047-7jnp8 to kind-worker
0.1558,Event,ADDED,eval-conflicts-rho020-r0-047-7jnp8.18d467891b6ddab2,"reason=Pulled count=1 msg=Container image ""busybox:musl"" already present on machine"
0.156,Event,ADDED,eval-conflicts-rho020-r0-047-7jnp8.18d467891cf0a4a9,reason=Created count=1 msg=Created container: task
0.1564,Event,ADDED,eval-conflicts-rho020-r0-047-7jnp8.18d4678921bcdba9,reason=Started count=1 msg=Started container task
0.1566,Event,ADDED,eval-conflicts-rho020-r0-047.18d46788e2e8bf83,reason=SuccessfulCreate count=1 msg=Created pod: eval-conflicts-rho020-r0-047-7jnp8
0.1568,Event,ADDED,eval-conflicts-rho020-r0-047.18d4678c2ed40707,reason=Completed count=1 msg=Job completed
0.1569,Event,ADDED,eval-conflicts-rho020-r0-048-djs5p.18d467891feb9ad9,reason=Scheduled count=None msg=Successfully assigned compute/eval-conflicts-rho020-r0-048-djs5p to kind-worker2
0.1572,Event,ADDED,eval-conflicts-rho020-r0-048-djs5p.18d4678939a6afae,"reason=Pulled count=1 msg=Container image ""busybox:musl"" already present on machine"
0.1574,Event,ADDED,eval-conflicts-rho020-r0-048-djs5p.18d467893abd959b,reason=Created count=1 msg=Created container: task
0.1575,Event,ADDED,eval-conflicts-rho020-r0-048-djs5p.18d467893cb29dba,reason=Started count=1 msg=Started container task
0.1577,Event,ADDED,eval-conflicts-rho020-r0-048.18d467891ee90ef0,reason=SuccessfulCreate count=1 msg=Created pod: eval-conflicts-rho020-r0-048-djs5p
0.1579,Event,ADDED,eval-conflicts-rho020-r0-048.18d4678c276d603e,reason=Completed count=1 msg=Job completed
0.158,Event,ADDED,eval-conflicts-rho020-r0-049-9qxwk.18d467895ae7e1dd,reason=Scheduled count=None msg=Successfully assigned compute/eval-conflicts-rho020-r0-049-9qxwk to kind-worker5
0.1582,Event,ADDED,eval-conflicts-rho020-r0-049-9qxwk.18d46789736eef78,"reason=Pulled count=1 msg=Container image ""busybox:musl"" already present on machine"
0.1584,Event,ADDED,eval-conflicts-rho020-r0-049-9qxwk.18d4678974783258,reason=Created count=1 msg=Created container: task
0.1586,Event,ADDED,eval-conflicts-rho020-r0-049-9qxwk.18d4678976728adc,reason=Started count=1 msg=Started container task
0.1587,Event,ADDED,eval-conflicts-rho020-r0-049.18d4678959e735b4,reason=SuccessfulCreate count=1 msg=Created pod: eval-conflicts-rho020-r0-049-9qxwk
0.1589,Event,ADDED,eval-conflicts-rho020-r0-049.18d4678cab0ffb37,reason=Completed count=1 msg=Job completed
0.159,Event,ADDED,eval-conflicts-rho020-r0-050-qjjv6.18d4678996deeb44,reason=Scheduled count=None msg=Successfully assigned compute/eval-conflicts-rho020-r0-050-qjjv6 to kind-worker2
0.1592,Event,ADDED,eval-conflicts-rho020-r0-050-qjjv6.18d46789af68231a,"reason=Pulled count=1 msg=Container image ""busybox:musl"" already present on machine"
0.1594,Event,ADDED,eval-conflicts-rho020-r0-050-qjjv6.18d46789b077c2f1,reason=Created count=1 msg=Created container: task
0.1596,Event,ADDED,eval-conflicts-rho020-r0-050-qjjv6.18d46789b412314b,reason=Started count=1 msg=Started container task
0.1597,Event,ADDED,eval-conflicts-rho020-r0-050.18d4678995ec907d,reason=SuccessfulCreate count=1 msg=Created pod: eval-conflicts-rho020-r0-050-qjjv6
0.1599,Event,ADDED,eval-conflicts-rho020-r0-050.18d4678cd98b65d7,reason=Completed count=1 msg=Job completed
0.16,Event,ADDED,eval-conflicts-rho020-r0-051-96665.18d46789d2353ee1,reason=Scheduled count=None msg=Successfully assigned compute/eval-conflicts-rho020-r0-051-96665 to kind-worker5
0.1603,Event,ADDED,eval-conflicts-rho020-r0-051-96665.18d46789ebd9730e,"reason=Pulled count=1 msg=Container image ""busybox:musl"" already present on machine"
0.1605,Event,ADDED,eval-conflicts-rho020-r0-051-96665.18d46789ed4598cc,reason=Created count=1 msg=Created container: task
0.1607,Event,ADDED,eval-conflicts-rho020-r0-051-96665.18d46789ef6e633a,reason=Started count=1 msg=Started container task
0.1608,Event,ADDED,eval-conflicts-rho020-r0-051.18d46789d140d4f7,reason=SuccessfulCreate count=1 msg=Created pod: eval-conflicts-rho020-r0-051-96665
0.1614,Event,ADDED,eval-conflicts-rho020-r0-051.18d4678ce78dcf5b,reason=Completed count=1 msg=Job completed
0.1616,Event,ADDED,eval-conflicts-rho020-r0-052-8hdgh.18d4678a0e2a9793,reason=Scheduled count=None msg=Successfully assigned compute/eval-conflicts-rho020-r0-052-8hdgh to kind-worker5
0.1617,Event,ADDED,eval-conflicts-rho020-r0-052-8hdgh.18d4678a27b2af0c,"reason=Pulled count=1 msg=Container image ""busybox:musl"" already present on machine"
0.162,Event,ADDED,eval-conflicts-rho020-r0-052-8hdgh.18d4678a28cf5aec,reason=Created count=1 msg=Created container: task
0.1621,Event,ADDED,eval-conflicts-rho020-r0-052-8hdgh.18d4678a2add5255,reason=Started count=1 msg=Started container task
0.1623,Event,ADDED,eval-conflicts-rho020-r0-052.18d4678a0cf2de26,reason=SuccessfulCreate count=1 msg=Created pod: eval-conflicts-rho020-r0-052-8hdgh
0.1625,Event,ADDED,eval-conflicts-rho020-r0-052.18d4678d5ffcacf4,reason=Completed count=1 msg=Job completed
0.1626,Event,ADDED,eval-conflicts-rho020-r0-053-ckm5b.18d4678a49eba011,reason=Scheduled count=None msg=Successfully assigned compute/eval-conflicts-rho020-r0-053-ckm5b to kind-worker
0.1628,Event,ADDED,eval-conflicts-rho020-r0-053-ckm5b.18d4678a63312ff4,"reason=Pulled count=1 msg=Container image ""busybox:musl"" already present on machine"
0.163,Event,ADDED,eval-conflicts-rho020-r0-053-ckm5b.18d4678a6440bf44,reason=Created count=1 msg=Created container: task
0.1631,Event,ADDED,eval-conflicts-rho020-r0-053-ckm5b.18d4678a68d301e4,reason=Started count=1 msg=Started container task
0.1633,Event,ADDED,eval-conflicts-rho020-r0-053.18d4678a487f3cf7,reason=SuccessfulCreate count=1 msg=Created pod: eval-conflicts-rho020-r0-053-ckm5b
0.1635,Event,ADDED,eval-conflicts-rho020-r0-053.18d4678d969def59,reason=Completed count=1 msg=Job completed
0.1636,Event,ADDED,eval-conflicts-rho020-r0-054-pv672.18d4678a854ddebf,reason=Scheduled count=None msg=Successfully assigned compute/eval-conflicts-rho020-r0-054-pv672 to kind-worker
0.1638,Event,ADDED,eval-conflicts-rho020-r0-054-pv672.18d4678a9e272e67,"reason=Pulled count=1 msg=Container image ""busybox:musl"" already present on machine"
0.164,Event,ADDED,eval-conflicts-rho020-r0-054-pv672.18d4678a9f3d70b9,reason=Created count=1 msg=Created container: task
0.1642,Event,ADDED,eval-conflicts-rho020-r0-054-pv672.18d4678aa391c199,reason=Started count=1 msg=Started container task
0.1644,Event,ADDED,eval-conflicts-rho020-r0-054.18d4678a840ae4f4,reason=SuccessfulCreate count=1 msg=Created pod: eval-conflicts-rho020-r0-054-pv672
0.1647,Event,ADDED,eval-conflicts-rho020-r0-054.18d4678dd24fe48e,reason=Completed count=1 msg=Job completed
0.1649,Event,ADDED,eval-conflicts-rho020-r0-055-77wnl.18d4678ac116e61d,reason=Scheduled count=None msg=Successfully assigned compute/eval-conflicts-rho020-r0-055-77wnl to kind-worker2
0.165,Event,ADDED,eval-conflicts-rho020-r0-055-77wnl.18d4678adb811005,"reason=Pulled count=1 msg=Container image ""busybox:musl"" already present on machine"
0.1652,Event,ADDED,eval-conflicts-rho020-r0-055-77wnl.18d4678adc914125,reason=Created count=1 msg=Created container: task
0.1654,Event,ADDED,eval-conflicts-rho020-r0-055-77wnl.18d4678aded13e06,reason=Started count=1 msg=Started container task
0.1656,Event,ADDED,eval-conflicts-rho020-r0-055.18d4678abfc0ffd3,reason=SuccessfulCreate count=1 msg=Created pod: eval-conflicts-rho020-r0-055-77wnl
0.1657,Event,ADDED,eval-conflicts-rho020-r0-055.18d4678e0511c74b,reason=Completed count=1 msg=Job completed
0.1659,Event,ADDED,eval-conflicts-rho020-r0-056-zttq2.18d4678afca00e43,reason=Scheduled count=None msg=Successfully assigned compute/eval-conflicts-rho020-r0-056-zttq2 to kind-worker2
0.1661,Event,ADDED,eval-conflicts-rho020-r0-056-zttq2.18d4678b152ab7ae,"reason=Pulled count=1 msg=Container image ""busybox:musl"" already present on machine"
0.1662,Event,ADDED,eval-conflicts-rho020-r0-056-zttq2.18d4678b1639ca5f,reason=Created count=1 msg=Created container: task
0.1664,Event,ADDED,eval-conflicts-rho020-r0-056-zttq2.18d4678b18471e7f,reason=Started count=1 msg=Started container task
0.1666,Event,ADDED,eval-conflicts-rho020-r0-056.18d4678afb801d69,reason=SuccessfulCreate count=1 msg=Created pod: eval-conflicts-rho020-r0-056-zttq2
0.1667,Event,ADDED,eval-conflicts-rho020-r0-056.18d4678e4101f2a0,reason=Completed count=1 msg=Job completed
0.1669,Event,ADDED,eval-conflicts-rho020-r0-057-r22dv.18d4678b3801a5b9,reason=Scheduled count=None msg=Successfully assigned compute/eval-conflicts-rho020-r0-057-r22dv to kind-worker5
0.1671,Event,ADDED,eval-conflicts-rho020-r0-057-r22dv.18d4678b51a9695c,"reason=Pulled count=1 msg=Container image ""busybox:musl"" already present on machine"
0.1673,Event,ADDED,eval-conflicts-rho020-r0-057-r22dv.18d4678b52c72301,reason=Created count=1 msg=Created container: task
0.1675,Event,ADDED,eval-conflicts-rho020-r0-057-r22dv.18d4678b54dab1b8,reason=Started count=1 msg=Started container task
0.1676,Event,ADDED,eval-conflicts-rho020-r0-057.18d4678b370a6209,reason=SuccessfulCreate count=1 msg=Created pod: eval-conflicts-rho020-r0-057-r22dv
0.1678,Event,ADDED,eval-conflicts-rho020-r0-057.18d4678e8968ebae,reason=Completed count=1 msg=Job completed
0.168,Event,ADDED,eval-conflicts-rho020-r0-058-7nvjn.18d4678b73206206,reason=Scheduled count=None msg=Successfully assigned compute/eval-conflicts-rho020-r0-058-7nvjn to kind-worker2
0.1681,Event,ADDED,eval-conflicts-rho020-r0-058-7nvjn.18d4678b8c614ab7,"reason=Pulled count=1 msg=Container image ""busybox:musl"" already present on machine"
0.1683,Event,ADDED,eval-conflicts-rho020-r0-058-7nvjn.18d4678b8d6375fe,reason=Created count=1 msg=Created container: task
0.1685,Event,ADDED,eval-conflicts-rho020-r0-058-7nvjn.18d4678b8f5ce894,reason=Started count=1 msg=Started container task
0.1686,Event,ADDED,eval-conflicts-rho020-r0-058.18d4678b726dced6,reason=SuccessfulCreate count=1 msg=Created pod: eval-conflicts-rho020-r0-058-7nvjn
0.1688,Event,ADDED,eval-conflicts-rho020-r0-058.18d4678eb8192a7e,reason=Completed count=1 msg=Job completed
0.169,Event,ADDED,eval-conflicts-rho020-r0-059-rd6fx.18d4678bae8defb6,reason=Scheduled count=None msg=Successfully assigned compute/eval-conflicts-rho020-r0-059-rd6fx to kind-worker4
0.1691,Event,ADDED,eval-conflicts-rho020-r0-059-rd6fx.18d4678bc64a762f,"reason=Pulled count=1 msg=Container image ""busybox:musl"" already present on machine"
0.1693,Event,ADDED,eval-conflicts-rho020-r0-059-rd6fx.18d4678bc75de491,reason=Created count=1 msg=Created container: task
0.1694,Event,ADDED,eval-conflicts-rho020-r0-059-rd6fx.18d4678bc94eaf5a,reason=Started count=1 msg=Started container task
0.1696,Event,ADDED,eval-conflicts-rho020-r0-059.18d4678bae483368,reason=SuccessfulCreate count=1 msg=Created pod: eval-conflicts-rho020-r0-059-rd6fx
0.1698,Event,ADDED,eval-conflicts-rho020-r0-059.18d4678f05b96272,reason=Completed count=1 msg=Job completed
0.1699,Event,ADDED,eval-conflicts-rho020-r0-060-jp5tb.18d4678beb927745,reason=Scheduled count=None msg=Successfully assigned compute/eval-conflicts-rho020-r0-060-jp5tb to kind-worker4
0.1701,Event,ADDED,eval-conflicts-rho020-r0-060-jp5tb.18d4678c059c6758,"reason=Pulled count=1 msg=Container image ""busybox:musl"" already present on machine"
0.1703,Event,ADDED,eval-conflicts-rho020-r0-060-jp5tb.18d4678c06c9072f,reason=Created count=1 msg=Created container: task
0.1704,Event,ADDED,eval-conflicts-rho020-r0-060-jp5tb.18d4678c08dd2be9,reason=Started count=1 msg=Started container task
0.1706,Event,ADDED,eval-conflicts-rho020-r0-060.18d4678beae675a6,reason=SuccessfulCreate count=1 msg=Created pod: eval-conflicts-rho020-r0-060-jp5tb
0.1708,Event,ADDED,eval-conflicts-rho020-r0-060.18d4678f41cedd42,reason=Completed count=1 msg=Job completed
0.1709,Event,ADDED,eval-conflicts-rho020-r0-061-4s2j8.18d4678c28b2fe3d,reason=Scheduled count=None msg=Successfully assigned compute/eval-conflicts-rho020-r0-061-4s2j8 to kind-worker4
0.1711,Event,ADDED,eval-conflicts-rho020-r0-061-4s2j8.18d4678c41b5de44,"reason=Pulled count=1 msg=Container image ""busybox:musl"" already present on machine"
0.1713,Event,ADDED,eval-conflicts-rho020-r0-061-4s2j8.18d4678c4310c394,reason=Created count=1 msg=Created container: task
0.1714,Event,ADDED,eval-conflicts-rho020-r0-061-4s2j8.18d4678c4cfbdfd3,reason=Started count=1 msg=Started container task
0.1716,Event,ADDED,eval-conflicts-rho020-r0-061.18d4678c27f7444f,reason=SuccessfulCreate count=1 msg=Created pod: eval-conflicts-rho020-r0-061-4s2j8
0.1718,Event,ADDED,eval-conflicts-rho020-r0-061.18d4678f7d45243c,reason=Completed count=1 msg=Job completed
0.172,Event,ADDED,eval-conflicts-rho020-r0-062-87q6z.18d4678c61acdabd,"reason=FailedScheduling count=None msg=0/6 nodes are available: 1 c_wall violated: 1 conflicting context pair(s) with node memory, 5 node(s) had untolerated taint(s). no new claims to deallocate, preemption: 0/6 nodes are available: 1 No preemption victims found for incoming pod, 5 Preemption is not helpful for scheduling."
0.1722,Event,ADDED,eval-conflicts-rho020-r0-062-87q6z.18d4678c626e34ec,"reason=FailedScheduling count=None msg=0/6 nodes are available: 1 c_wall violated: 1 conflicting context pair(s) with node memory, 5 node(s) had untolerated taint(s). no new claims to deallocate, preemption: 0/6 nodes are available: 1 No preemption victims found for incoming pod, 5 Preemption is not helpful for scheduling."
0.1724,Event,ADDED,eval-conflicts-rho020-r0-062-87q6z.18d4678d91ee1baa,"reason=FailedScheduling count=None msg=0/6 nodes are available: 2 c_wall violated: 1 conflicting context pair(s) with node memory, 4 node(s) had untolerated taint(s). no new claims to deallocate, preemption: 0/6 nodes are available: 2 No preemption victims found for incoming pod, 4 Preemption is not helpful for scheduling."
0.1726,Event,ADDED,eval-conflicts-rho020-r0-062-87q6z.18d4678dc8caae6a,"reason=FailedScheduling count=None msg=0/6 nodes are available: 1 c_wall violated: 1 conflicting context pair(s) with node memory, 1 c_wall violated: 2 conflicting context pair(s) with node memory, 4 node(s) had untolerated taint(s). no new claims to deallocate, preemption: 0/6 nodes are available: 2 No preemption victims found for incoming pod, 4 Preemption is not helpful for scheduling."
0.1727,Event,ADDED,eval-conflicts-rho020-r0-062-87q6z.18d4678dd99b5624,reason=Scheduled count=None msg=Successfully assigned compute/eval-conflicts-rho020-r0-062-87q6z to kind-worker
0.1729,Event,ADDED,eval-conflicts-rho020-r0-062-87q6z.18d4678df2f50025,"reason=Pulled count=1 msg=Container image ""busybox:musl"" already present on machine"
0.1731,Event,ADDED,eval-conflicts-rho020-r0-062-87q6z.18d4678df400715a,reason=Created count=1 msg=Created container: task
0.1732,Event,ADDED,eval-conflicts-rho020-r0-062-87q6z.18d4678df62f5e2c,reason=Started count=1 msg=Started container task
0.1734,Event,ADDED,eval-conflicts-rho020-r0-062.18d4678c6166fe4c,reason=SuccessfulCreate count=1 msg=Created pod: eval-conflicts-rho020-r0-062-87q6z
0.1736,Event,ADDED,eval-conflicts-rho020-r0-062.18d4679117cfa506,reason=Completed count=1 msg=Job completed
0.1737,Event,ADDED,eval-conflicts-rho020-r0-063-7l4ld.18d4678c9d0d83cd,"reason=FailedScheduling count=None msg=0/6 nodes are available: 1 c_wall violated: 1 conflicting context pair(s) with node memory, 5 node(s) had untolerated taint(s). no new claims to deallocate, preemption: 0/6 nodes are available: 1 No preemption victims found for incoming pod, 5 Preemption is not helpful for scheduling."
0.1739,Event,ADDED,eval-conflicts-rho020-r0-063-7l4ld.18d4678c9dece81e,"reason=FailedScheduling count=None msg=0/6 nodes are available: 1 c_wall violated: 1 conflicting context pair(s) with node memory, 5 node(s) had untolerated taint(s). no new claims to deallocate, preemption: 0/6 nodes are available: 1 No preemption victims found for incoming pod, 5 Preemption is not helpful for scheduling."
0.1741,Event,ADDED,eval-conflicts-rho020-r0-063-7l4ld.18d4678d8bfab924,reason=Scheduled count=None msg=Successfully assigned compute/eval-conflicts-rho020-r0-063-7l4ld to kind-worker3
0.1743,Event,ADDED,eval-conflicts-rho020-r0-063-7l4ld.18d4678da5e7f1a5,"reason=Pulled count=1 msg=Container image ""busybox:musl"" already present on machine"
0.1744,Event,ADDED,eval-conflicts-rho020-r0-063-7l4ld.18d4678da7935b4d,reason=Created count=1 msg=Created container: task
0.1746,Event,ADDED,eval-conflicts-rho020-r0-063-7l4ld.18d4678dabb184c3,reason=Started count=1 msg=Started container task
0.1747,Event,ADDED,eval-conflicts-rho020-r0-063.18d4678c9cc633d9,reason=SuccessfulCreate count=1 msg=Created pod: eval-conflicts-rho020-r0-063-7l4ld
0.1749,Event,ADDED,eval-conflicts-rho020-r0-063.18d46790b8256c51,reason=Completed count=1 msg=Job completed
0.1751,Event,ADDED,eval-conflicts-rho020-r0-064-lzc88.18d4678cd9d7583c,reason=Scheduled count=None msg=Successfully assigned compute/eval-conflicts-rho020-r0-064-lzc88 to kind-worker4
0.1752,Event,ADDED,eval-conflicts-rho020-r0-064-lzc88.18d4678cf2fdfd89,"reason=Pulled count=1 msg=Container image ""busybox:musl"" already present on machine"
0.1754,Event,ADDED,eval-conflicts-rho020-r0-064-lzc88.18d4678cf41e5f0e,reason=Created count=1 msg=Created container: task
0.1756,Event,ADDED,eval-conflicts-rho020-r0-064-lzc88.18d4678cf984a459,reason=Started count=1 msg=Started container task
0.1757,Event,ADDED,eval-conflicts-rho020-r0-064.18d4678cd913275a,reason=SuccessfulCreate count=1 msg=Created pod: eval-conflicts-rho020-r0-064-lzc88
0.1759,Event,ADDED,eval-conflicts-rho020-r0-064.18d467903112533c,reason=Completed count=1 msg=Job completed
0.1761,Event,ADDED,eval-conflicts-rho020-r0-065-mnt2l.18d4678d1457a857,reason=Scheduled count=None msg=Successfully assigned compute/eval-conflicts-rho020-r0-065-mnt2l to kind-worker4
0.1762,Event,ADDED,eval-conflicts-rho020-r0-065-mnt2l.18d4678d2d9b237c,"reason=Pulled count=1 msg=Container image ""busybox:musl"" already present on machine"
0.1764,Event,ADDED,eval-conflicts-rho020-r0-065-mnt2l.18d4678d2eb9c49d,reason=Created count=1 msg=Created container: task
0.1766,Event,ADDED,eval-conflicts-rho020-r0-065-mnt2l.18d4678d32e602da,reason=Started count=1 msg=Started container task
0.1768,Event,ADDED,eval-conflicts-rho020-r0-065.18d4678d13c6f70f,reason=SuccessfulCreate count=1 msg=Created pod: eval-conflicts-rho020-r0-065-mnt2l
0.177,Event,ADDED,eval-conflicts-rho020-r0-065.18d467906d132b10,reason=Completed count=1 msg=Job completed
0.1771,Event,ADDED,eval-conflicts-rho020-r0-066-sz9xv.18d4678d501f7fae,"reason=FailedScheduling count=None msg=0/6 nodes are available: 1 c_wall violated: 1 conflicting context pair(s) with node memory, 5 node(s) had untolerated taint(s). no new claims to deallocate, preemption: 0/6 nodes are available: 1 No preemption victims found for incoming pod, 5 Preemption is not helpful for scheduling."
0.1775,Event,ADDED,eval-conflicts-rho020-r0-066-sz9xv.18d4678d510258a8,"reason=FailedScheduling count=None msg=0/6 nodes are available: 1 c_wall violated: 1 conflicting context pair(s) with node memory, 5 node(s) had untolerated taint(s). no new claims to deallocate, preemption: 0/6 nodes are available: 1 No preemption victims found for incoming pod, 5 Preemption is not helpful for scheduling."
0.1776,Event,ADDED,eval-conflicts-rho020-r0-066-sz9xv.18d4678d8d8bd966,reason=Scheduled count=None msg=Successfully assigned compute/eval-conflicts-rho020-r0-066-sz9xv to kind-worker3
0.1778,Event,ADDED,eval-conflicts-rho020-r0-066-sz9xv.18d4678da6d755e9,"reason=Pulled count=1 msg=Container image ""busybox:musl"" already present on machine"
0.1781,Event,ADDED,eval-conflicts-rho020-r0-066-sz9xv.18d4678da8437752,reason=Created count=1 msg=Created container: task
0.1783,Event,ADDED,eval-conflicts-rho020-r0-066-sz9xv.18d4678dae6b5a89,reason=Started count=1 msg=Started container task
0.1785,Event,ADDED,eval-conflicts-rho020-r0-066.18d4678d4fdfdc53,reason=SuccessfulCreate count=1 msg=Created pod: eval-conflicts-rho020-r0-066-sz9xv
0.1787,Event,ADDED,eval-conflicts-rho020-r0-066.18d46790f4e45e59,reason=Completed count=1 msg=Job completed
0.1789,Event,ADDED,eval-conflicts-rho020-r0-067-w8p7x.18d4678d8b64b7b2,reason=Scheduled count=None msg=Successfully assigned compute/eval-conflicts-rho020-r0-067-w8p7x to kind-worker4
0.1791,Event,ADDED,eval-conflicts-rho020-r0-067-w8p7x.18d4678da5e57534,"reason=Pulled count=1 msg=Container image ""busybox:musl"" already present on machine"
0.1793,Event,ADDED,eval-conflicts-rho020-r0-067-w8p7x.18d4678da76f3c2b,reason=Created count=1 msg=Created container: task
0.1794,Event,ADDED,eval-conflicts-rho020-r0-067-w8p7x.18d4678dab9bf38a,reason=Started count=1 msg=Started container task
0.1796,Event,ADDED,eval-conflicts-rho020-r0-067.18d4678d8ae1af28,reason=SuccessfulCreate count=1 msg=Created pod: eval-conflicts-rho020-r0-067-w8p7x
0.1798,Event,ADDED,eval-conflicts-rho020-r0-067.18d46790e4fa9e27,reason=Completed count=1 msg=Job completed
0.18,Event,ADDED,eval-conflicts-rho020-r0-068-56h4z.18d4678dc757b64f,reason=Scheduled count=None msg=Successfully assigned compute/eval-conflicts-rho020-r0-068-56h4z to kind-worker4
0.1803,Event,ADDED,eval-conflicts-rho020-r0-068-56h4z.18d4678de16105bb,"reason=Pulled count=1 msg=Container image ""busybox:musl"" already present on machine"
0.1805,Event,ADDED,eval-conflicts-rho020-r0-068-56h4z.18d4678de276dffc,reason=Created count=1 msg=Created container: task
0.1807,Event,ADDED,eval-conflicts-rho020-r0-068-56h4z.18d4678de4df63d4,reason=Started count=1 msg=Started container task
0.1808,Event,ADDED,eval-conflicts-rho020-r0-068.18d4678dc69ef3c2,reason=SuccessfulCreate count=1 msg=Created pod: eval-conflicts-rho020-r0-068-56h4z
0.1811,Event,ADDED,eval-conflicts-rho020-r0-068.18d46791211f11ca,reason=Completed count=1 msg=Job completed
0.1813,Event,ADDED,eval-conflicts-rho020-r0-069-vms9g.18d4678e02c28054,reason=Scheduled count=None msg=Successfully assigned compute/eval-conflicts-rho020-r0-069-vms9g to kind-worker3
0.1815,Event,ADDED,eval-conflicts-rho020-r0-069-vms9g.18d4678e1b9517e8,"reason=Pulled count=1 msg=Container image ""busybox:musl"" already present on machine"
0.1817,Event,ADDED,eval-conflicts-rho020-r0-069-vms9g.18d4678e1cae4da7,reason=Created count=1 msg=Created container: task
0.182,Event,ADDED,eval-conflicts-rho020-r0-069-vms9g.18d4678e1f0d35d3,reason=Started count=1 msg=Started container task
0.1822,Event,ADDED,eval-conflicts-rho020-r0-069.18d4678e0217875e,reason=SuccessfulCreate count=1 msg=Created pod: eval-conflicts-rho020-r0-069-vms9g
0.1824,Event,ADDED,eval-conflicts-rho020-r0-069.18d4679130b1be60,reason=Completed count=1 msg=Job completed
0.1826,Event,ADDED,eval-conflicts-rho020-r0-070-fp55s.18d4678e3f688906,reason=Scheduled count=None msg=Successfully assigned compute/eval-conflicts-rho020-r0-070-fp55s to kind-worker
0.1827,Event,ADDED,eval-conflicts-rho020-r0-070-fp55s.18d4678e58d8aca7,"reason=Pulled count=1 msg=Container image ""busybox:musl"" already present on machine"
0.1829,Event,ADDED,eval-conflicts-rho020-r0-070-fp55s.18d4678e59e772d7,reason=Created count=1 msg=Created container: task
0.1831,Event,ADDED,eval-conflicts-rho020-r0-070-fp55s.18d4678e5cf5646f,reason=Started count=1 msg=Started container task
0.1833,Event,ADDED,eval-conflicts-rho020-r0-070.18d4678e3e2982fd,reason=SuccessfulCreate count=1 msg=Created pod: eval-conflicts-rho020-r0-070-fp55s
0.1834,Event,ADDED,eval-conflicts-rho020-r0-070.18d467918fb7c144,reason=Completed count=1 msg=Job completed
0.1836,Event,ADDED,eval-conflicts-rho020-r0-071-cz2w5.18d4678e7a2d497c,reason=Scheduled count=None msg=Successfully assigned compute/eval-conflicts-rho020-r0-071-cz2w5 to kind-worker
0.1838,Event,ADDED,eval-conflicts-rho020-r0-071-cz2w5.18d4678e93d576a7,"reason=Pulled count=1 msg=Container image ""busybox:musl"" already present on machine"
0.1839,Event,ADDED,eval-conflicts-rho020-r0-071-cz2w5.18d4678e94e1db90,reason=Created count=1 msg=Created container: task
0.1842,Event,ADDED,eval-conflicts-rho020-r0-071-cz2w5.18d4678e96d338e1,reason=Started count=1 msg=Started container task
0.1844,Event,ADDED,eval-conflicts-rho020-r0-071.18d4678e7975446f,reason=SuccessfulCreate count=1 msg=Created pod: eval-conflicts-rho020-r0-071-cz2w5
0.1847,Event,ADDED,eval-conflicts-rho020-r0-071.18d46791cad94b3f,reason=Completed count=1 msg=Job completed
0.1849,Event,ADDED,eval-conflicts-rho020-r0-072-hl5tc.18d4678eb5c21f7b,reason=Scheduled count=None msg=Successfully assigned compute/eval-conflicts-rho020-r0-072-hl5tc to kind-worker
0.1851,Event,ADDED,eval-conflicts-rho020-r0-072-hl5tc.18d4678ecfd7d3b6,"reason=Pulled count=1 msg=Container image ""busybox:musl"" already present on machine"
0.1852,Event,ADDED,eval-conflicts-rho020-r0-072-hl5tc.18d4678ed0e16084,reason=Created count=1 msg=Created container: task
0.1854,Event,ADDED,eval-conflicts-rho020-r0-072-hl5tc.18d4678ed50b7204,reason=Started count=1 msg=Started container task
0.1856,Event,ADDED,eval-conflicts-rho020-r0-072.18d4678eb4f415ce,reason=SuccessfulCreate count=1 msg=Created pod: eval-conflicts-rho020-r0-072-hl5tc
0.1858,Event,ADDED,eval-conflicts-rho020-r0-072.18d467920716008a,reason=Completed count=1 msg=Job completed
0.1859,Event,ADDED,eval-conflicts-rho020-r0-073-4nwfv.18d4678ef0eede3e,"reason=FailedScheduling count=None msg=0/6 nodes are available: 2 c_wall violated: 1 conflicting context pair(s) with node memory, 4 node(s) had untolerated taint(s). no new claims to deallocate, preemption: 0/6 nodes are available: 2 No preemption victims found for incoming pod, 4 Preemption is not helpful for scheduling."
0.1861,Event,ADDED,eval-conflicts-rho020-r0-073-4nwfv.18d4678ef1c0e6b9,"reason=FailedScheduling count=None msg=0/6 nodes are available: 2 c_wall violated: 1 conflicting context pair(s) with node memory, 4 node(s) had untolerated taint(s). no new claims to deallocate, preemption: 0/6 nodes are available: 2 No preemption victims found for incoming pod, 4 Preemption is not helpful for scheduling."
0.1863,Event,ADDED,eval-conflicts-rho020-r0-073-4nwfv.18d4678fe1eddb47,"reason=FailedScheduling count=None msg=0/6 nodes are available: 1 c_wall violated: 1 conflicting context pair(s) with node memory, 5 node(s) had untolerated taint(s). no new claims to deallocate, preemption: 0/6 nodes are available: 1 No preemption victims found for incoming pod, 5 Preemption is not helpful for scheduling."
0.1865,Event,ADDED,eval-conflicts-rho020-r0-073-4nwfv.18d467904619ffc1,reason=Scheduled count=None msg=Successfully assigned compute/eval-conflicts-rho020-r0-073-4nwfv to kind-worker2
0.1867,Event,ADDED,eval-conflicts-rho020-r0-073-4nwfv.18d467905f17cece,"reason=Pulled count=1 msg=Container image ""busybox:musl"" already present on machine"
0.1868,Event,ADDED,eval-conflicts-rho020-r0-073-4nwfv.18d4679060b42477,reason=Created count=1 msg=Created container: task
0.187,Event,ADDED,eval-conflicts-rho020-r0-073-4nwfv.18d46790650d5806,reason=Started count=1 msg=Started container task
0.1872,Event,ADDED,eval-conflicts-rho020-r0-073.18d4678ef084e4b1,reason=SuccessfulCreate count=1 msg=Created pod: eval-conflicts-rho020-r0-073-4nwfv
0.1873,Event,ADDED,eval-conflicts-rho020-r0-073.18d467939fcdf8fa,reason=Completed count=1 msg=Job completed
0.1875,Event,ADDED,eval-conflicts-rho020-r0-074-4t5bt.18d4678f2ce0209a,reason=Scheduled count=None msg=Successfully assigned compute/eval-conflicts-rho020-r0-074-4t5bt to kind-worker
0.1877,Event,ADDED,eval-conflicts-rho020-r0-074-4t5bt.18d4678f4784fb85,"reason=Pulled count=1 msg=Container image ""busybox:musl"" already present on machine"
0.1879,Event,ADDED,eval-conflicts-rho020-r0-074-4t5bt.18d4678f48ad2691,reason=Created count=1 msg=Created container: task
0.1881,Event,ADDED,eval-conflicts-rho020-r0-074-4t5bt.18d4678f4d0e7edc,reason=Started count=1 msg=Started container task
0.1883,Event,ADDED,eval-conflicts-rho020-r0-074.18d4678f2c352df0,reason=SuccessfulCreate count=1 msg=Created pod: eval-conflicts-rho020-r0-074-4t5bt
0.1885,Event,ADDED,eval-conflicts-rho020-r0-074.18d467927ed86655,reason=Completed count=1 msg=Job completed
0.1886,Event,ADDED,eval-conflicts-rho020-r0-075-n8mt4.18d4678f687506e7,reason=Scheduled count=None msg=Successfully assigned compute/eval-conflicts-rho020-r0-075-n8mt4 to kind-worker
0.1888,Event,ADDED,eval-conflicts-rho020-r0-075-n8mt4.18d4678f812d738e,"reason=Pulled count=1 msg=Container image ""busybox:musl"" already present on machine"
0.1891,Event,ADDED,eval-conflicts-rho020-r0-075-n8mt4.18d4678f82343946,reason=Created count=1 msg=Created container: task
0.1892,Event,ADDED,eval-conflicts-rho020-r0-075-n8mt4.18d4678f84301df0,reason=Started count=1 msg=Started container task
0.1894,Event,ADDED,eval-conflicts-rho020-r0-075.18d4678f67b9add3,reason=SuccessfulCreate count=1 msg=Created pod: eval-conflicts-rho020-r0-075-n8mt4
0.1896,Event,ADDED,eval-conflicts-rho020-r0-075.18d46792ba01bcf8,reason=Completed count=1 msg=Job completed
0.1899,Event,ADDED,eval-conflicts-rho020-r0-076-9jl9x.18d4678fa45c849f,reason=Scheduled count=None msg=Successfully assigned compute/eval-conflicts-rho020-r0-076-9jl9x to kind-worker
0.1901,Event,ADDED,eval-conflicts-rho020-r0-076-9jl9x.18d4678fc03dc862,"reason=Pulled count=1 msg=Container image ""busybox:musl"" already present on machine"
0.1903,Event,ADDED,eval-conflicts-rho020-r0-076-9jl9x.18d4678fc18c70ae,reason=Created count=1 msg=Created container: task
0.1905,Event,ADDED,eval-conflicts-rho020-r0-076-9jl9x.18d4678fc5e0a97c,reason=Started count=1 msg=Started container task
0.1907,Event,ADDED,eval-conflicts-rho020-r0-076.18d4678fa390f99e,reason=SuccessfulCreate count=1 msg=Created pod: eval-conflicts-rho020-r0-076-9jl9x
0.1909,Event,ADDED,eval-conflicts-rho020-r0-076.18d46792f5a3f6c7,reason=Completed count=1 msg=Job completed
0.191,Event,ADDED,eval-conflicts-rho020-r0-077-zrlqs.18d4678fdf9a3739,"reason=FailedScheduling count=None msg=0/6 nodes are available: 2 c_wall violated: 1 conflicting context pair(s) with node memory, 4 node(s) had untolerated taint(s). no new claims to deallocate, preemption: 0/6 nodes are available: 2 No preemption victims found for incoming pod, 4 Preemption is not helpful for scheduling."
0.1912,Event,ADDED,eval-conflicts-rho020-r0-077-zrlqs.18d4678fe065b3cb,"reason=FailedScheduling count=None msg=0/6 nodes are available: 2 c_wall violated: 1 conflicting context pair(s) with node memory, 4 node(s) had untolerated taint(s). no new claims to deallocate, preemption: 0/6 nodes are available: 2 No preemption victims found for incoming pod, 4 Preemption is not helpful for scheduling."
0.1914,Event,ADDED,eval-conflicts-rho020-r0-077-zrlqs.18d4678fe21d6958,"reason=FailedScheduling count=None msg=0/6 nodes are available: 1 c_wall violated: 1 conflicting context pair(s) with node memory, 5 node(s) had untolerated taint(s). no new claims to deallocate, preemption: 0/6 nodes are available: 1 No preemption victims found for incoming pod, 5 Preemption is not helpful for scheduling."
0.1916,Event,ADDED,eval-conflicts-rho020-r0-077-zrlqs.18d4679045d80d50,reason=Scheduled count=None msg=Successfully assigned compute/eval-conflicts-rho020-r0-077-zrlqs to kind-worker2
0.1918,Event,ADDED,eval-conflicts-rho020-r0-077-zrlqs.18d467905ef2ba56,"reason=Pulled count=1 msg=Container image ""busybox:musl"" already present on machine"
0.192,Event,ADDED,eval-conflicts-rho020-r0-077-zrlqs.18d46790605a4232,reason=Created count=1 msg=Created container: task
0.1922,Event,ADDED,eval-conflicts-rho020-r0-077-zrlqs.18d46790650d57f2,reason=Started count=1 msg=Started container task
0.1923,Event,ADDED,eval-conflicts-rho020-r0-077.18d4678fdf1ef74e,reason=SuccessfulCreate count=1 msg=Created pod: eval-conflicts-rho020-r0-077-zrlqs
0.1925,Event,ADDED,eval-conflicts-rho020-r0-077.18d467939f6f7f4e,reason=Completed count=1 msg=Job completed
0.1927,Event,ADDED,eval-conflicts-rho020-r0-078-zbbjd.18d467901b5a6cef,reason=Scheduled count=None msg=Successfully assigned compute/eval-conflicts-rho020-r0-078-zbbjd to kind-worker
0.1928,Event,ADDED,eval-conflicts-rho020-r0-078-zbbjd.18d4679034de777f,"reason=Pulled count=1 msg=Container image ""busybox:musl"" already present on machine"
0.193,Event,ADDED,eval-conflicts-rho020-r0-078-zbbjd.18d46790360d5088,reason=Created count=1 msg=Created container: task
0.1932,Event,ADDED,eval-conflicts-rho020-r0-078-zbbjd.18d467903aead8c3,reason=Started count=1 msg=Started container task
0.1933,Event,ADDED,eval-conflicts-rho020-r0-078.18d467901ad59b68,reason=SuccessfulCreate count=1 msg=Created pod: eval-conflicts-rho020-r0-078-zbbjd
0.1935,Event,ADDED,eval-conflicts-rho020-r0-078.18d467936d7c947e,reason=Completed count=1 msg=Job completed
0.1936,Event,ADDED,eval-conflicts-rho020-r0-079-bjmxc.18d4679056ff2f51,reason=Scheduled count=None msg=Successfully assigned compute/eval-conflicts-rho020-r0-079-bjmxc to kind-worker2
0.1938,Event,ADDED,eval-conflicts-rho020-r0-079-bjmxc.18d4679074b2ac76,"reason=Pulled count=1 msg=Container image ""busybox:musl"" already present on machine"
0.194,Event,ADDED,eval-conflicts-rho020-r0-079-bjmxc.18d4679075c630ea,reason=Created count=1 msg=Created container: task
0.1942,Event,ADDED,eval-conflicts-rho020-r0-079-bjmxc.18d4679079bdb981,reason=Started count=1 msg=Started container task
0.1943,Event,ADDED,eval-conflicts-rho020-r0-079.18d467905671e394,reason=SuccessfulCreate count=1 msg=Created pod: eval-conflicts-rho020-r0-079-bjmxc
0.1945,Event,ADDED,eval-conflicts-rho020-r0-079.18d467939f47012d,reason=Completed count=1 msg=Job completed
0.1946,Event,ADDED,eval-conflicts-rho020-r0-080-d5j9k.18d4679092a7391f,reason=Scheduled count=None msg=Successfully assigned compute/eval-conflicts-rho020-r0-080-d5j9k to kind-worker5
0.1948,Event,ADDED,eval-conflicts-rho020-r0-080-d5j9k.18d46790ae062caf,"reason=Pulled count=1 msg=Container image ""busybox:musl"" already present on machine"
0.195,Event,ADDED,eval-conflicts-rho020-r0-080-d5j9k.18d46790af1d9479,reason=Created count=1 msg=Created container: task
0.1951,Event,ADDED,eval-conflicts-rho020-r0-080-d5j9k.18d46790b35a9792,reason=Started count=1 msg=Started container task
0.1953,Event,ADDED,eval-conflicts-rho020-r0-080.18d4679092268a8f,reason=SuccessfulCreate count=1 msg=Created pod: eval-conflicts-rho020-r0-080-d5j9k
0.1955,Event,ADDED,eval-conflicts-rho020-r0-080.18d46793e7c31b67,reason=Completed count=1 msg=Job completed
0.1956,Event,ADDED,eval-conflicts-rho020-r0-081-swqks.18d46790cf1bd0e0,reason=Scheduled count=None msg=Successfully assigned compute/eval-conflicts-rho020-r0-081-swqks to kind-worker5
0.1958,Event,ADDED,eval-conflicts-rho020-r0-081-swqks.18d46790e9da5c64,"reason=Pulled count=1 msg=Container image ""busybox:musl"" already present on machine"
0.1959,Event,ADDED,eval-conflicts-rho020-r0-081-swqks.18d46790eadeb056,reason=Created count=1 msg=Created container: task
0.1961,Event,ADDED,eval-conflicts-rho020-r0-081-swqks.18d46790ecd4331c,reason=Started count=1 msg=Started container task
0.1963,Event,ADDED,eval-conflicts-rho020-r0-081.18d46790ce85d552,reason=SuccessfulCreate count=1 msg=Created pod: eval-conflicts-rho020-r0-081-swqks
0.1965,Event,ADDED,eval-conflicts-rho020-r0-081.18d46794239d72ad,reason=Completed count=1 msg=Job completed
0.1967,Event,ADDED,eval-conflicts-rho020-r0-082-vjr68.18d4679109e9ccb0,"reason=FailedScheduling count=None msg=0/6 nodes are available: 2 c_wall violated: 1 conflicting context pair(s) with node memory, 4 node(s) had untolerated taint(s). no new claims to deallocate, preemption: 0/6 nodes are available: 2 No preemption victims found for incoming pod, 4 Preemption is not helpful for scheduling."
0.1968,Event,ADDED,eval-conflicts-rho020-r0-082-vjr68.18d467910aa21047,"reason=FailedScheduling count=None msg=0/6 nodes are available: 2 c_wall violated: 1 conflicting context pair(s) with node memory, 4 node(s) had untolerated taint(s). no new claims to deallocate, preemption: 0/6 nodes are available: 2 No preemption victims found for incoming pod, 4 Preemption is not helpful for scheduling."
0.1973,Event,ADDED,eval-conflicts-rho020-r0-082-vjr68.18d46791823e2933,"reason=FailedScheduling count=None msg=0/6 nodes are available: 1 c_wall violated: 1 conflicting context pair(s) with node memory, 1 c_wall violated: 2 conflicting context pair(s) with node memory, 4 node(s) had untolerated taint(s). no new claims to deallocate, preemption: 0/6 nodes are available: 2 No preemption victims found for incoming pod, 4 Preemption is not helpful for scheduling."
0.1975,Event,ADDED,eval-conflicts-rho020-r0-082-vjr68.18d4679258aae977,reason=Scheduled count=None msg=Successfully assigned compute/eval-conflicts-rho020-r0-082-vjr68 to kind-worker3
0.1976,Event,ADDED,eval-conflicts-rho020-r0-082-vjr68.18d46792713d1215,"reason=Pulled count=1 msg=Container image ""busybox:musl"" already present on machine"
0.1981,Event,ADDED,eval-conflicts-rho020-r0-082-vjr68.18d4679272584186,reason=Created count=1 msg=Created container: task
0.1983,Event,ADDED,eval-conflicts-rho020-r0-082-vjr68.18d467927730256d,reason=Started count=1 msg=Started container task
0.1984,Event,ADDED,eval-conflicts-rho020-r0-082.18d4679109808840,reason=SuccessfulCreate count=1 msg=Created pod: eval-conflicts-rho020-r0-082-vjr68
0.1986,Event,ADDED,eval-conflicts-rho020-r0-082.18d467959ef8016e,reason=Completed count=1 msg=Job completed
0.199,Event,ADDED,eval-conflicts-rho020-r0-083-nj5r7.18d46791455f5d76,reason=Scheduled count=None msg=Successfully assigned compute/eval-conflicts-rho020-r0-083-nj5r7 to kind-worker2
0.1992,Event,ADDED,eval-conflicts-rho020-r0-083-nj5r7.18d467915fbff555,"reason=Pulled count=1 msg=Container image ""busybox:musl"" already present on machine"
0.1993,Event,ADDED,eval-conflicts-rho020-r0-083-nj5r7.18d4679160f6ae48,reason=Created count=1 msg=Created container: task
0.1995,Event,ADDED,eval-conflicts-rho020-r0-083-nj5r7.18d46791633a8f31,reason=Started count=1 msg=Started container task
0.1997,Event,ADDED,eval-conflicts-rho020-r0-083.18d4679144aac7fe,reason=SuccessfulCreate count=1 msg=Created pod: eval-conflicts-rho020-r0-083-nj5r7
0.1999,Event,ADDED,eval-conflicts-rho020-r0-083.18d46794905414e3,reason=Completed count=1 msg=Job completed
0.2,Event,ADDED,eval-conflicts-rho020-r0-084-xwskm.18d4679181118348,reason=Scheduled count=None msg=Successfully assigned compute/eval-conflicts-rho020-r0-084-xwskm to kind-worker5
0.2003,Event,ADDED,eval-conflicts-rho020-r0-084-xwskm.18d467919ac0f3ac,"reason=Pulled count=1 msg=Container image ""busybox:musl"" already present on machine"
0.2005,Event,ADDED,eval-conflicts-rho020-r0-084-xwskm.18d467919bd3fd70,reason=Created count=1 msg=Created container: task
0.2007,Event,ADDED,eval-conflicts-rho020-r0-084-xwskm.18d467919df7a293,reason=Started count=1 msg=Started container task
0.2009,Event,ADDED,eval-conflicts-rho020-r0-084.18d467918059c578,reason=SuccessfulCreate count=1 msg=Created pod: eval-conflicts-rho020-r0-084-xwskm
0.201,Event,ADDED,eval-conflicts-rho020-r0-084.18d46794d6cdcb37,reason=Completed count=1 msg=Job completed
0.2012,Event,ADDED,eval-conflicts-rho020-r0-085-bc8wb.18d46791bc81a627,reason=Scheduled count=None msg=Successfully assigned compute/eval-conflicts-rho020-r0-085-bc8wb to kind-worker2
0.2013,Event,ADDED,eval-conflicts-rho020-r0-085-bc8wb.18d46791d71ffd81,"reason=Pulled count=1 msg=Container image ""busybox:musl"" already present on machine"
0.2015,Event,ADDED,eval-conflicts-rho020-r0-085-bc8wb.18d46791d866c337,reason=Created count=1 msg=Created container: task
0.2017,Event,ADDED,eval-conflicts-rho020-r0-085-bc8wb.18d46791ddf8f448,reason=Started count=1 msg=Started container task
0.2018,Event,ADDED,eval-conflicts-rho020-r0-085.18d46791bbd9478d,reason=SuccessfulCreate count=1 msg=Created pod: eval-conflicts-rho020-r0-085-bc8wb
0.202,Event,ADDED,eval-conflicts-rho020-r0-085.18d46795061cd960,reason=Completed count=1 msg=Job completed
0.2021,Event,ADDED,eval-conflicts-rho020-r0-086-9t9fh.18d46791f922d5a6,reason=Scheduled count=None msg=Successfully assigned compute/eval-conflicts-rho020-r0-086-9t9fh to kind-worker5
0.2023,Event,ADDED,eval-conflicts-rho020-r0-086-9t9fh.18d46792141d7312,"reason=Pulled count=1 msg=Container image ""busybox:musl"" already present on machine"
0.2025,Event,ADDED,eval-conflicts-rho020-r0-086-9t9fh.18d4679215669c79,reason=Created count=1 msg=Created container: task
0.2026,Event,ADDED,eval-conflicts-rho020-r0-086-9t9fh.18d4679219ad291f,reason=Started count=1 msg=Started container task
0.2028,Event,ADDED,eval-conflicts-rho020-r0-086.18d46791f7e277cc,reason=SuccessfulCreate count=1 msg=Created pod: eval-conflicts-rho020-r0-086-9t9fh
0.203,Event,ADDED,eval-conflicts-rho020-r0-086.18d467954e62b2b8,reason=Completed count=1 msg=Job completed
0.2031,Event,ADDED,eval-conflicts-rho020-r0-087-ms59s.18d4679233ff8be7,reason=Scheduled count=None msg=Successfully assigned compute/eval-conflicts-rho020-r0-087-ms59s to kind-worker5
0.2033,Event,ADDED,eval-conflicts-rho020-r0-087-ms59s.18d467924c730ad5,"reason=Pulled count=1 msg=Container image ""busybox:musl"" already present on machine"
0.2034,Event,ADDED,eval-conflicts-rho020-r0-087-ms59s.18d467924d82d0d5,reason=Created count=1 msg=Created container: task
0.2036,Event,ADDED,eval-conflicts-rho020-r0-087-ms59s.18d467924f8bfbde,reason=Started count=1 msg=Started container task
0.2038,Event,ADDED,eval-conflicts-rho020-r0-087.18d4679233137513,reason=SuccessfulCreate count=1 msg=Created pod: eval-conflicts-rho020-r0-087-ms59s
0.2039,Event,ADDED,eval-conflicts-rho020-r0-087.18d467958a30dd00,reason=Completed count=1 msg=Job completed
0.2041,Event,ADDED,eval-conflicts-rho020-r0-088-g2mg9.18d467926f8665c4,reason=Scheduled count=None msg=Successfully assigned compute/eval-conflicts-rho020-r0-088-g2mg9 to kind-worker2
0.2043,Event,ADDED,eval-conflicts-rho020-r0-088-g2mg9.18d4679288d24ff9,"reason=Pulled count=1 msg=Container image ""busybox:musl"" already present on machine"
0.2044,Event,ADDED,eval-conflicts-rho020-r0-088-g2mg9.18d4679289efdae7,reason=Created count=1 msg=Created container: task
0.2046,Event,ADDED,eval-conflicts-rho020-r0-088-g2mg9.18d467928bdc9ff6,reason=Started count=1 msg=Started container task
0.2048,Event,ADDED,eval-conflicts-rho020-r0-088.18d467926ea6073e,reason=SuccessfulCreate count=1 msg=Created pod: eval-conflicts-rho020-r0-088-g2mg9
0.2049,Event,ADDED,eval-conflicts-rho020-r0-088.18d46795b9be1fbc,reason=Completed count=1 msg=Job completed
0.2051,Event,ADDED,eval-conflicts-rho020-r0-089-mlmwd.18d46792aabb1c84,reason=Scheduled count=None msg=Successfully assigned compute/eval-conflicts-rho020-r0-089-mlmwd to kind-worker3
0.2052,Event,ADDED,eval-conflicts-rho020-r0-089-mlmwd.18d46792c3a0e034,"reason=Pulled count=1 msg=Container image ""busybox:musl"" already present on machine"
0.2054,Event,ADDED,eval-conflicts-rho020-r0-089-mlmwd.18d46792c4bc9b13,reason=Created count=1 msg=Created container: task
0.2056,Event,ADDED,eval-conflicts-rho020-r0-089-mlmwd.18d46792c6e43df9,reason=Started count=1 msg=Started container task
0.2057,Event,ADDED,eval-conflicts-rho020-r0-089.18d46792aa0bc2ff,reason=SuccessfulCreate count=1 msg=Created pod: eval-conflicts-rho020-r0-089-mlmwd
0.2059,Event,ADDED,eval-conflicts-rho020-r0-089.18d46795db259bc4,reason=Completed count=1 msg=Job completed
0.206,Event,ADDED,eval-conflicts-rho020-r0-090-ms5qj.18d46792e670579d,reason=Scheduled count=None msg=Successfully assigned compute/eval-conflicts-rho020-r0-090-ms5qj to kind-worker4
0.2062,Event,ADDED,eval-conflicts-rho020-r0-090-ms5qj.18d46792ffcf1cad,"reason=Pulled count=1 msg=Container image ""busybox:musl"" already present on machine"
0.2064,Event,ADDED,eval-conflicts-rho020-r0-090-ms5qj.18d4679300d78134,reason=Created count=1 msg=Created container: task
0.2066,Event,ADDED,eval-conflicts-rho020-r0-090-ms5qj.18d4679302c77050,reason=Started count=1 msg=Started container task
0.2067,Event,ADDED,eval-conflicts-rho020-r0-090.18d46792e5ca6113,reason=SuccessfulCreate count=1 msg=Created pod: eval-conflicts-rho020-r0-090-ms5qj
0.2069,Event,ADDED,eval-conflicts-rho020-r0-090.18d4679642e9ac6f,reason=Completed count=1 msg=Job completed
0.2093,Event,ADDED,eval-conflicts-rho020-r0-091-fqbts.18d4679321fc2517,reason=Scheduled count=None msg=Successfully assigned compute/eval-conflicts-rho020-r0-091-fqbts to kind-worker3
0.2095,Event,ADDED,eval-conflicts-rho020-r0-091-fqbts.18d467933b43f29d,"reason=Pulled count=1 msg=Container image ""busybox:musl"" already present on machine"
0.2098,Event,ADDED,eval-conflicts-rho020-r0-091-fqbts.18d467933c53a8e8,reason=Created count=1 msg=Created container: task
0.2099,Event,ADDED,eval-conflicts-rho020-r0-091-fqbts.18d467933e5e5abe,reason=Started count=1 msg=Started container task
0.2101,Event,ADDED,eval-conflicts-rho020-r0-091.18d46793215f0a9f,reason=SuccessfulCreate count=1 msg=Created pod: eval-conflicts-rho020-r0-091-fqbts
0.2103,Event,ADDED,eval-conflicts-rho020-r0-091.18d46796526f5d11,reason=Completed count=1 msg=Job completed
0.2104,Event,ADDED,eval-conflicts-rho020-r0-092-cmrjr.18d467935e4120cf,reason=Scheduled count=None msg=Successfully assigned compute/eval-conflicts-rho020-r0-092-cmrjr to kind-worker4
0.2106,Event,ADDED,eval-conflicts-rho020-r0-092-cmrjr.18d4679376badbb9,"reason=Pulled count=1 msg=Container image ""busybox:musl"" already present on machine"
0.2107,Event,ADDED,eval-conflicts-rho020-r0-092-cmrjr.18d4679377cc923d,reason=Created count=1 msg=Created container: task
0.2109,Event,ADDED,eval-conflicts-rho020-r0-092-cmrjr.18d4679379dad1d4,reason=Started count=1 msg=Started container task
0.2111,Event,ADDED,eval-conflicts-rho020-r0-092.18d467935d73f350,reason=SuccessfulCreate count=1 msg=Created pod: eval-conflicts-rho020-r0-092-cmrjr
0.2112,Event,ADDED,eval-conflicts-rho020-r0-092.18d46796bb093d37,reason=Completed count=1 msg=Job completed
0.2114,Event,ADDED,eval-conflicts-rho020-r0-093-f7hvr.18d467939a5864c2,"reason=FailedScheduling count=None msg=0/6 nodes are available: 2 c_wall violated: 1 conflicting context pair(s) with node memory, 4 node(s) had untolerated taint(s). no new claims to deallocate, preemption: 0/6 nodes are available: 2 No preemption victims found for incoming pod, 4 Preemption is not helpful for scheduling."
0.2116,Event,ADDED,eval-conflicts-rho020-r0-093-f7hvr.18d467939b1ca207,"reason=FailedScheduling count=None msg=0/6 nodes are available: 2 c_wall violated: 1 conflicting context pair(s) with node memory, 4 node(s) had untolerated taint(s). no new claims to deallocate, preemption: 0/6 nodes are available: 2 No preemption victims found for incoming pod, 4 Preemption is not helpful for scheduling."
0.2118,Event,ADDED,eval-conflicts-rho020-r0-093-f7hvr.18d46794af36b70f,"reason=FailedScheduling count=None msg=0/6 nodes are available: 1 c_wall violated: 1 conflicting context pair(s) with node memory, 5 node(s) had untolerated taint(s). no new claims to deallocate, preemption: 0/6 nodes are available: 1 No preemption victims found for incoming pod, 5 Preemption is not helpful for scheduling."
0.2119,Event,ADDED,eval-conflicts-rho020-r0-093-f7hvr.18d46794f9669edb,reason=Scheduled count=None msg=Successfully assigned compute/eval-conflicts-rho020-r0-093-f7hvr to kind-worker
0.2121,Event,ADDED,eval-conflicts-rho020-r0-093-f7hvr.18d467951294e44a,"reason=Pulled count=1 msg=Container image ""busybox:musl"" already present on machine"
0.2123,Event,ADDED,eval-conflicts-rho020-r0-093-f7hvr.18d467951436104d,reason=Created count=1 msg=Created container: task
0.2124,Event,ADDED,eval-conflicts-rho020-r0-093-f7hvr.18d4679518c9185f,reason=Started count=1 msg=Started container task
0.2126,Event,ADDED,eval-conflicts-rho020-r0-093.18d4679399e8f14a,reason=SuccessfulCreate count=1 msg=Created pod: eval-conflicts-rho020-r0-093-f7hvr
0.2128,Event,ADDED,eval-conflicts-rho020-r0-093.18d4679855e2d788,reason=Completed count=1 msg=Job completed
0.2129,Event,ADDED,eval-conflicts-rho020-r0-094-gstkm.18d46793d523bce1,"reason=FailedScheduling count=None msg=0/6 nodes are available: 2 c_wall violated: 1 conflicting context pair(s) with node memory, 4 node(s) had untolerated taint(s). no new claims to deallocate, preemption: 0/6 nodes are available: 2 No preemption victims found for incoming pod, 4 Preemption is not helpful for scheduling."
0.2131,Event,ADDED,eval-conflicts-rho020-r0-094-gstkm.18d46793d5d16615,"reason=FailedScheduling count=None msg=0/6 nodes are available: 2 c_wall violated: 1 conflicting context pair(s) with node memory, 4 node(s) had untolerated taint(s). no new claims to deallocate, preemption: 0/6 nodes are available: 2 No preemption victims found for incoming pod, 4 Preemption is not helpful for scheduling."
0.2133,Event,ADDED,eval-conflicts-rho020-r0-094-gstkm.18d46794aee483ae,"reason=FailedScheduling count=None msg=0/6 nodes are available: 1 c_wall violated: 1 conflicting context pair(s) with node memory, 5 node(s) had untolerated taint(s). no new claims to deallocate, preemption: 0/6 nodes are available: 1 No preemption victims found for incoming pod, 5 Preemption is not helpful for scheduling."
0.2134,Event,ADDED,eval-conflicts-rho020-r0-094-gstkm.18d46794fa1b4b3a,reason=Scheduled count=None msg=Successfully assigned compute/eval-conflicts-rho020-r0-094-gstkm to kind-worker
0.2136,Event,ADDED,eval-conflicts-rho020-r0-094-gstkm.18d4679518cd01bb,"reason=Pulled count=1 msg=Container image ""busybox:musl"" already present on machine"
0.2138,Event,ADDED,eval-conflicts-rho020-r0-094-gstkm.18d467951a8173d5,reason=Created count=1 msg=Created container: task
0.2139,Event,ADDED,eval-conflicts-rho020-r0-094-gstkm.18d4679522ae3f93,reason=Started count=1 msg=Started container task
0.2141,Event,ADDED,eval-conflicts-rho020-r0-094.18d46793d4b63c69,reason=SuccessfulCreate count=1 msg=Created pod: eval-conflicts-rho020-r0-094-gstkm
0.2143,Event,ADDED,eval-conflicts-rho020-r0-094.18d4679854ed385a,reason=Completed count=1 msg=Job completed
0.2144,Event,ADDED,eval-conflicts-rho020-r0-095-7hh7k.18d4679410cb7236,"reason=FailedScheduling count=None msg=0/6 nodes are available: 2 c_wall violated: 1 conflicting context pair(s) with node memory, 4 node(s) had untolerated taint(s). no new claims to deallocate, preemption: 0/6 nodes are available: 2 No preemption victims found for incoming pod, 4 Preemption is not helpful for scheduling."
0.2146,Event,ADDED,eval-conflicts-rho020-r0-095-7hh7k.18d46794117c014d,"reason=FailedScheduling count=None msg=0/6 nodes are available: 2 c_wall violated: 1 conflicting context pair(s) with node memory, 4 node(s) had untolerated taint(s). no new claims to deallocate, preemption: 0/6 nodes are available: 2 No preemption victims found for incoming pod, 4 Preemption is not helpful for scheduling."
0.2148,Event,ADDED,eval-conflicts-rho020-r0-095-7hh7k.18d46794af0b34cd,"reason=FailedScheduling count=None msg=0/6 nodes are available: 1 c_wall violated: 1 conflicting context pair(s) with node memory, 5 node(s) had untolerated taint(s). no new claims to deallocate, preemption: 0/6 nodes are available: 1 No preemption victims found for incoming pod, 5 Preemption is not helpful for scheduling."
0.215,Event,ADDED,eval-conflicts-rho020-r0-095-7hh7k.18d46794fa46d784,reason=Scheduled count=None msg=Successfully assigned compute/eval-conflicts-rho020-r0-095-7hh7k to kind-worker
0.2151,Event,ADDED,eval-conflicts-rho020-r0-095-7hh7k.18d4679518da5764,"reason=Pulled count=1 msg=Container image ""busybox:musl"" already present on machine"
0.2153,Event,ADDED,eval-conflicts-rho020-r0-095-7hh7k.18d467951b3d0fe9,reason=Created count=1 msg=Created container: task
0.2155,Event,ADDED,eval-conflicts-rho020-r0-095-7hh7k.18d467951f7c2735,reason=Started count=1 msg=Started container task
0.2156,Event,ADDED,eval-conflicts-rho020-r0-095.18d467941057cadd,reason=SuccessfulCreate count=1 msg=Created pod: eval-conflicts-rho020-r0-095-7hh7k
0.2158,Event,ADDED,eval-conflicts-rho020-r0-095.18d4679854ef53f8,reason=Completed count=1 msg=Job completed
0.2159,Event,ADDED,eval-conflicts-rho020-r0-096-jnrhm.18d467944c9a0877,reason=Scheduled count=None msg=Successfully assigned compute/eval-conflicts-rho020-r0-096-jnrhm to kind-worker3
0.2161,Event,ADDED,eval-conflicts-rho020-r0-096-jnrhm.18d4679466083dc3,"reason=Pulled count=1 msg=Container image ""busybox:musl"" already present on machine"
0.2163,Event,ADDED,eval-conflicts-rho020-r0-096-jnrhm.18d467946715cdc8,reason=Created count=1 msg=Created container: task
0.2165,Event,ADDED,eval-conflicts-rho020-r0-096-jnrhm.18d4679468fca044,reason=Started count=1 msg=Started container task
0.2167,Event,ADDED,eval-conflicts-rho020-r0-096.18d467944be2dabe,reason=SuccessfulCreate count=1 msg=Created pod: eval-conflicts-rho020-r0-096-jnrhm
0.2169,Event,ADDED,eval-conflicts-rho020-r0-096.18d467977d8e65d1,reason=Completed count=1 msg=Job completed
0.217,Event,ADDED,eval-conflicts-rho020-r0-097-z6nsd.18d46794883e786d,reason=Scheduled count=None msg=Successfully assigned compute/eval-conflicts-rho020-r0-097-z6nsd to kind-worker4
0.2172,Event,ADDED,eval-conflicts-rho020-r0-097-z6nsd.18d46794a25af158,"reason=Pulled count=1 msg=Container image ""busybox:musl"" already present on machine"
0.2174,Event,ADDED,eval-conflicts-rho020-r0-097-z6nsd.18d46794a3781444,reason=Created count=1 msg=Created container: task
0.2175,Event,ADDED,eval-conflicts-rho020-r0-097-z6nsd.18d46794ac8468b6,reason=Started count=1 msg=Started container task
0.2177,Event,ADDED,eval-conflicts-rho020-r0-097.18d467948719c6b3,reason=SuccessfulCreate count=1 msg=Created pod: eval-conflicts-rho020-r0-097-z6nsd
0.2179,Event,ADDED,eval-conflicts-rho020-r0-097.18d46797eaaef804,reason=Completed count=1 msg=Job completed
0.218,Event,ADDED,eval-conflicts-rho020-r0-098-rxrfn.18d46794c2fb3fe1,reason=Scheduled count=None msg=Successfully assigned compute/eval-conflicts-rho020-r0-098-rxrfn to kind-worker4
0.2182,Event,ADDED,eval-conflicts-rho020-r0-098-rxrfn.18d46794dbb634ac,"reason=Pulled count=1 msg=Container image ""busybox:musl"" already present on machine"
0.2183,Event,ADDED,eval-conflicts-rho020-r0-098-rxrfn.18d46794dccb6077,reason=Created count=1 msg=Created container: task
0.2185,Event,ADDED,eval-conflicts-rho020-r0-098-rxrfn.18d46794df3a4493,reason=Started count=1 msg=Started container task
0.2187,Event,ADDED,eval-conflicts-rho020-r0-098.18d46794c278f30e,reason=SuccessfulCreate count=1 msg=Created pod: eval-conflicts-rho020-r0-098-rxrfn
0.2188,Event,ADDED,eval-conflicts-rho020-r0-098.18d4679826d1d326,reason=Completed count=1 msg=Job completed
0.219,Event,ADDED,eval-conflicts-rho020-r0-099-q54dz.18d46794ff4bfc94,reason=Scheduled count=None msg=Successfully assigned compute/eval-conflicts-rho020-r0-099-q54dz to kind-worker
0.2194,Event,ADDED,eval-conflicts-rho020-r0-099-q54dz.18d46795192d1505,"reason=Pulled count=1 msg=Container image ""busybox:musl"" already present on machine"
0.22,Event,ADDED,eval-conflicts-rho020-r0-099-q54dz.18d467951b707581,reason=Created count=1 msg=Created container: task
0.2203,Event,ADDED,eval-conflicts-rho020-r0-099-q54dz.18d467951f7b4de3,reason=Started count=1 msg=Started container task
0.2204,Event,ADDED,eval-conflicts-rho020-r0-099.18d46794fe0dbf8b,reason=SuccessfulCreate count=1 msg=Created pod: eval-conflicts-rho020-r0-099-q54dz
0.2208,Event,ADDED,eval-conflicts-rho020-r0-099.18d4679855101985,reason=Completed count=1 msg=Job completed
0.221,Event,ADDED,eval-conflicts-rho020-r1-000-2db75.18d4679d81e5ea43,reason=Scheduled count=None msg=Successfully assigned compute/eval-conflicts-rho020-r1-000-2db75 to kind-worker5
0.2212,Event,ADDED,eval-conflicts-rho020-r1-000-2db75.18d4679d9b86ae32,"reason=Pulled count=1 msg=Container image ""busybox:musl"" already present on machine"
0.2215,Event,ADDED,eval-conflicts-rho020-r1-000-2db75.18d4679d9cbe330c,reason=Created count=1 msg=Created container: task
0.2217,Event,ADDED,eval-conflicts-rho020-r1-000-2db75.18d4679d9ee52d53,reason=Started count=1 msg=Started container task
0.222,Event,ADDED,eval-conflicts-rho020-r1-000.18d4679d80dad958,reason=SuccessfulCreate count=1 msg=Created pod: eval-conflicts-rho020-r1-000-2db75
0.2222,Event,ADDED,eval-conflicts-rho020-r1-000.18d467a0c27d801c,reason=Completed count=1 msg=Job completed
0.2226,Event,ADDED,eval-conflicts-rho020-r1-001-fpwsm.18d4679dbd1a59bb,reason=Scheduled count=None msg=Successfully assigned compute/eval-conflicts-rho020-r1-001-fpwsm to kind-worker5
0.2228,Event,ADDED,eval-conflicts-rho020-r1-001-fpwsm.18d4679dd6b7c32f,"reason=Pulled count=1 msg=Container image ""busybox:musl"" already present on machine"
0.223,Event,ADDED,eval-conflicts-rho020-r1-001-fpwsm.18d4679dd7e079c0,reason=Created count=1 msg=Created container: task
0.2232,Event,ADDED,eval-conflicts-rho020-r1-001-fpwsm.18d4679dd9e3c40f,reason=Started count=1 msg=Started container task
0.2236,Event,ADDED,eval-conflicts-rho020-r1-001.18d4679dbc068b88,reason=SuccessfulCreate count=1 msg=Created pod: eval-conflicts-rho020-r1-001-fpwsm
0.2238,Event,ADDED,eval-conflicts-rho020-r1-001.18d467a0fe4f7280,reason=Completed count=1 msg=Job completed
0.2239,Event,ADDED,eval-conflicts-rho020-r1-002-xkpgb.18d4679df732997b,reason=Scheduled count=None msg=Successfully assigned compute/eval-conflicts-rho020-r1-002-xkpgb to kind-worker2
0.2242,Event,ADDED,eval-conflicts-rho020-r1-002-xkpgb.18d4679e10220e1b,"reason=Pulled count=1 msg=Container image ""busybox:musl"" already present on machine"
0.2243,Event,ADDED,eval-conflicts-rho020-r1-002-xkpgb.18d4679e113b307d,reason=Created count=1 msg=Created container: task
0.2245,Event,ADDED,eval-conflicts-rho020-r1-002-xkpgb.18d4679e15ef3360,reason=Started count=1 msg=Started container task
0.2247,Event,ADDED,eval-conflicts-rho020-r1-002.18d4679df67b77e0,reason=SuccessfulCreate count=1 msg=Created pod: eval-conflicts-rho020-r1-002-xkpgb
0.2249,Event,ADDED,eval-conflicts-rho020-r1-002.18d467a12a435f29,reason=Completed count=1 msg=Job completed
0.225,Event,ADDED,eval-conflicts-rho020-r1-003-5x2l8.18d4679e33a72944,reason=Scheduled count=None msg=Successfully assigned compute/eval-conflicts-rho020-r1-003-5x2l8 to kind-worker
0.2252,Event,ADDED,eval-conflicts-rho020-r1-003-5x2l8.18d4679e4d355a18,"reason=Pulled count=1 msg=Container image ""busybox:musl"" already present on machine"
0.2254,Event,ADDED,eval-conflicts-rho020-r1-003-5x2l8.18d4679e4e4bc344,reason=Created count=1 msg=Created container: task
0.2255,Event,ADDED,eval-conflicts-rho020-r1-003-5x2l8.18d4679e5043ad82,reason=Started count=1 msg=Started container task
0.2257,Event,ADDED,eval-conflicts-rho020-r1-003.18d4679e32a05d3e,reason=SuccessfulCreate count=1 msg=Created pod: eval-conflicts-rho020-r1-003-5x2l8
0.226,Event,ADDED,eval-conflicts-rho020-r1-003.18d467a1716ee5a0,reason=Completed count=1 msg=Job completed
0.2263,Event,ADDED,eval-conflicts-rho020-r1-004-b8lrq.18d4679e6fde35cd,reason=Scheduled count=None msg=Successfully assigned compute/eval-conflicts-rho020-r1-004-b8lrq to kind-worker
0.2265,Event,ADDED,eval-conflicts-rho020-r1-004-b8lrq.18d4679e8814f91a,"reason=Pulled count=1 msg=Container image ""busybox:musl"" already present on machine"
0.2267,Event,ADDED,eval-conflicts-rho020-r1-004-b8lrq.18d4679e89276098,reason=Created count=1 msg=Created container: task
0.2269,Event,ADDED,eval-conflicts-rho020-r1-004-b8lrq.18d4679e8b411604,reason=Started count=1 msg=Started container task
0.2272,Event,ADDED,eval-conflicts-rho020-r1-004.18d4679e6ea80a30,reason=SuccessfulCreate count=1 msg=Created pod: eval-conflicts-rho020-r1-004-b8lrq
0.2274,Event,ADDED,eval-conflicts-rho020-r1-004.18d467a1ad28be28,reason=Completed count=1 msg=Job completed
0.2276,Event,ADDED,eval-conflicts-rho020-r1-005-nrjz7.18d4679eaa2812de,reason=Scheduled count=None msg=Successfully assigned compute/eval-conflicts-rho020-r1-005-nrjz7 to kind-worker4
0.2279,Event,ADDED,eval-conflicts-rho020-r1-005-nrjz7.18d4679ec32881c3,"reason=Pulled count=1 msg=Container image ""busybox:musl"" already present on machine"
0.2281,Event,ADDED,eval-conflicts-rho020-r1-005-nrjz7.18d4679ec42daeea,reason=Created count=1 msg=Created container: task
0.2284,Event,ADDED,eval-conflicts-rho020-r1-005-nrjz7.18d4679ec61653f3,reason=Started count=1 msg=Started container task
0.2286,Event,ADDED,eval-conflicts-rho020-r1-005.18d4679ea995f9a5,reason=SuccessfulCreate count=1 msg=Created pod: eval-conflicts-rho020-r1-005-nrjz7
0.229,Event,ADDED,eval-conflicts-rho020-r1-005.18d467a1b301dd14,reason=Completed count=1 msg=Job completed
0.2291,Event,ADDED,eval-conflicts-rho020-r1-006-dlnd9.18d4679ee5e84082,reason=Scheduled count=None msg=Successfully assigned compute/eval-conflicts-rho020-r1-006-dlnd9 to kind-worker4
0.2293,Event,ADDED,eval-conflicts-rho020-r1-006-dlnd9.18d4679eff02097d,"reason=Pulled count=1 msg=Container image ""busybox:musl"" already present on machine"
0.2295,Event,ADDED,eval-conflicts-rho020-r1-006-dlnd9.18d4679f00991508,reason=Created count=1 msg=Created container: task
0.2299,Event,ADDED,eval-conflicts-rho020-r1-006-dlnd9.18d4679f0567dfca,reason=Started count=1 msg=Started container task
0.2301,Event,ADDED,eval-conflicts-rho020-r1-006.18d4679ee5332d44,reason=SuccessfulCreate count=1 msg=Created pod: eval-conflicts-rho020-r1-006-dlnd9
0.2304,Event,ADDED,eval-conflicts-rho020-r1-006.18d467a22a80218c,reason=Completed count=1 msg=Job completed
0.2307,Event,ADDED,eval-conflicts-rho020-r1-007-5d9ck.18d4679f21e422d7,reason=Scheduled count=None msg=Successfully assigned compute/eval-conflicts-rho020-r1-007-5d9ck to kind-worker4
0.2309,Event,ADDED,eval-conflicts-rho020-r1-007-5d9ck.18d4679f3b673edc,"reason=Pulled count=1 msg=Container image ""busybox:musl"" already present on machine"
0.231,Event,ADDED,eval-conflicts-rho020-r1-007-5d9ck.18d4679f3c754066,reason=Created count=1 msg=Created container: task
0.2312,Event,ADDED,eval-conflicts-rho020-r1-007-5d9ck.18d4679f3ff4e7ea,reason=Started count=1 msg=Started container task
0.2314,Event,ADDED,eval-conflicts-rho020-r1-007.18d4679f21052a32,reason=SuccessfulCreate count=1 msg=Created pod: eval-conflicts-rho020-r1-007-5d9ck
0.2316,Event,ADDED,eval-conflicts-rho020-r1-007.18d467a2662d475f,reason=Completed count=1 msg=Job completed
0.2317,Event,ADDED,eval-conflicts-rho020-r1-008-5svl6.18d4679f5e067de7,reason=Scheduled count=None msg=Successfully assigned compute/eval-conflicts-rho020-r1-008-5svl6 to kind-worker4
0.2319,Event,ADDED,eval-conflicts-rho020-r1-008-5svl6.18d4679f76aea3f1,"reason=Pulled count=1 msg=Container image ""busybox:musl"" already present on machine"
0.2321,Event,ADDED,eval-conflicts-rho020-r1-008-5svl6.18d4679f77c54084,reason=Created count=1 msg=Created container: task
0.2323,Event,ADDED,eval-conflicts-rho020-r1-008-5svl6.18d4679f7b93fcf2,reason=Started count=1 msg=Started container task
0.2324,Event,ADDED,eval-conflicts-rho020-r1-008.18d4679f5d3f1297,reason=SuccessfulCreate count=1 msg=Created pod: eval-conflicts-rho020-r1-008-5svl6
0.2327,Event,ADDED,eval-conflicts-rho020-r1-008.18d467a2a1f91cfe,reason=Completed count=1 msg=Job completed
0.2329,Event,ADDED,eval-conflicts-rho020-r1-009-wbrrg.18d4679f9886cf75,reason=Scheduled count=None msg=Successfully assigned compute/eval-conflicts-rho020-r1-009-wbrrg to kind-worker3
0.2331,Event,ADDED,eval-conflicts-rho020-r1-009-wbrrg.18d4679fb18d18c1,"reason=Pulled count=1 msg=Container image ""busybox:musl"" already present on machine"
0.2334,Event,ADDED,eval-conflicts-rho020-r1-009-wbrrg.18d4679fb2c1ff3f,reason=Created count=1 msg=Created container: task
0.2339,Event,ADDED,eval-conflicts-rho020-r1-009-wbrrg.18d4679fb4bf51d3,reason=Started count=1 msg=Started container task
0.2341,Event,ADDED,eval-conflicts-rho020-r1-009.18d4679f97e90885,reason=SuccessfulCreate count=1 msg=Created pod: eval-conflicts-rho020-r1-009-wbrrg
0.2343,Event,ADDED,eval-conflicts-rho020-r1-009.18d467a2ef2afd73,reason=Completed count=1 msg=Job completed
0.2347,Event,ADDED,eval-conflicts-rho020-r1-010-8s2ck.18d4679fd49ac79a,reason=Scheduled count=None msg=Successfully assigned compute/eval-conflicts-rho020-r1-010-8s2ck to kind-worker3
0.2349,Event,ADDED,eval-conflicts-rho020-r1-010-8s2ck.18d4679feda238e8,"reason=Pulled count=1 msg=Container image ""busybox:musl"" already present on machine"
0.235,Event,ADDED,eval-conflicts-rho020-r1-010-8s2ck.18d4679feebcb864,reason=Created count=1 msg=Created container: task
0.2352,Event,ADDED,eval-conflicts-rho020-r1-010-8s2ck.18d4679ff0c0f999,reason=Started count=1 msg=Started container task
0.2356,Event,ADDED,eval-conflicts-rho020-r1-010.18d4679fd39152b2,reason=SuccessfulCreate count=1 msg=Created pod: eval-conflicts-rho020-r1-010-8s2ck
0.2358,Event,ADDED,eval-conflicts-rho020-r1-010.18d467a329c3e59d,reason=Completed count=1 msg=Job completed
0.236,Event,ADDED,eval-conflicts-rho020-r1-011-9dqq6.18d467a00ff18b75,reason=Scheduled count=None msg=Successfully assigned compute/eval-conflicts-rho020-r1-011-9dqq6 to kind-worker4
0.2362,Event,ADDED,eval-conflicts-rho020-r1-011-9dqq6.18d467a02ba58181,"reason=Pulled count=1 msg=Container image ""busybox:musl"" already present on machine"
0.2364,Event,ADDED,eval-conflicts-rho020-r1-011-9dqq6.18d467a02cd389bb,reason=Created count=1 msg=Created container: task
0.2366,Event,ADDED,eval-conflicts-rho020-r1-011-9dqq6.18d467a030fe94b8,reason=Started count=1 msg=Started container task
0.2368,Event,ADDED,eval-conflicts-rho020-r1-011.18d467a00f1e883a,reason=SuccessfulCreate count=1 msg=Created pod: eval-conflicts-rho020-r1-011-9dqq6
0.237,Event,ADDED,eval-conflicts-rho020-r1-011.18d467a357a1addf,reason=Completed count=1 msg=Job completed
0.2371,Event,ADDED,eval-conflicts-rho020-r1-012-kfszv.18d467a04d580229,reason=Scheduled count=None msg=Successfully assigned compute/eval-conflicts-rho020-r1-012-kfszv to kind-worker3
0.2373,Event,ADDED,eval-conflicts-rho020-r1-012-kfszv.18d467a06769bf93,"reason=Pulled count=1 msg=Container image ""busybox:musl"" already present on machine"
0.2375,Event,ADDED,eval-conflicts-rho020-r1-012-kfszv.18d467a06881d280,reason=Created count=1 msg=Created container: task
0.2377,Event,ADDED,eval-conflicts-rho020-r1-012-kfszv.18d467a06db3d2e5,reason=Started count=1 msg=Started container task
0.2378,Event,ADDED,eval-conflicts-rho020-r1-012.18d467a04ca44fde,reason=SuccessfulCreate count=1 msg=Created pod: eval-conflicts-rho020-r1-012-kfszv
0.238,Event,ADDED,eval-conflicts-rho020-r1-012.18d467a3a45d1413,reason=Completed count=1 msg=Job completed
0.2381,Event,ADDED,eval-conflicts-rho020-r1-013-hxf64.18d467a088885741,"reason=FailedScheduling count=None msg=0/6 nodes are available: 1 c_wall violated: 1 conflicting context pair(s) with node memory, 5 node(s) had untolerated taint(s). no new claims to deallocate, preemption: 0/6 nodes are available: 1 No preemption victims found for incoming pod, 5 Preemption is not helpful for scheduling."
0.2383,Event,ADDED,eval-conflicts-rho020-r1-013-hxf64.18d467a0890ea9ea,"reason=FailedScheduling count=None msg=0/6 nodes are available: 1 c_wall violated: 1 conflicting context pair(s) with node memory, 5 node(s) had untolerated taint(s). no new claims to deallocate, preemption: 0/6 nodes are available: 1 No preemption victims found for incoming pod, 5 Preemption is not helpful for scheduling."
0.2385,Event,ADDED,eval-conflicts-rho020-r1-013-hxf64.18d467a0ea981ae2,reason=Scheduled count=None msg=Successfully assigned compute/eval-conflicts-rho020-r1-013-hxf64 to kind-worker2
0.2387,Event,ADDED,eval-conflicts-rho020-r1-013-hxf64.18d467a1047d6d6a,"reason=Pulled count=1 msg=Container image ""busybox:musl"" already present on machine"
0.2388,Event,ADDED,eval-conflicts-rho020-r1-013-hxf64.18d467a10593475a,reason=Created count=1 msg=Created container: task
0.239,Event,ADDED,eval-conflicts-rho020-r1-013-hxf64.18d467a1076e73d9,reason=Started count=1 msg=Started container task
0.2392,Event,ADDED,eval-conflicts-rho020-r1-013.18d467a0884bc76a,reason=SuccessfulCreate count=1 msg=Created pod: eval-conflicts-rho020-r1-013-hxf64
0.2393,Event,ADDED,eval-conflicts-rho020-r1-013.18d467a438299cbc,reason=Completed count=1 msg=Job completed
0.2395,Event,ADDED,eval-conflicts-rho020-r1-014-bp9sj.18d467a0c24b0fb9,"reason=FailedScheduling count=None msg=0/6 nodes are available: 1 c_wall violated: 2 conflicting context pair(s) with node memory, 5 node(s) had untolerated taint(s). no new claims to deallocate, preemption: 0/6 nodes are available: 1 No preemption victims found for incoming pod, 5 Preemption is not helpful for scheduling."
0.2397,Event,ADDED,eval-conflicts-rho020-r1-014-bp9sj.18d467a0c3013201,"reason=FailedScheduling count=None msg=0/6 nodes are available: 1 c_wall violated: 2 conflicting context pair(s) with node memory, 5 node(s) had untolerated taint(s). no new claims to deallocate, preemption: 0/6 nodes are available: 1 No preemption victims found for incoming pod, 5 Preemption is not helpful for scheduling."
0.2399,Event,ADDED,eval-conflicts-rho020-r1-014-bp9sj.18d467a0ebdb5483,"reason=FailedScheduling count=None msg=0/6 nodes are available: 1 c_wall violated: 1 conflicting context pair(s) with node memory, 1 c_wall violated: 2 conflicting context pair(s) with node memory, 4 node(s) had untolerated taint(s). no new claims to deallocate, preemption: 0/6 nodes are available: 2 No preemption victims found for incoming pod, 4 Preemption is not helpful for scheduling."
0.2402,Event,ADDED,eval-conflicts-rho020-r1-014-bp9sj.18d467a0fc52a047,"reason=FailedScheduling count=None msg=0/6 nodes are available: 1 c_wall violated: 1 conflicting context pair(s) with node memory, 5 node(s) had untolerated taint(s). no new claims to deallocate, preemption: 0/6 nodes are available: 1 No preemption victims found for incoming pod, 5 Preemption is not helpful for scheduling."
0.2404,Event,ADDED,eval-conflicts-rho020-r1-014-bp9sj.18d467a1094ad03c,reason=Scheduled count=None msg=Successfully assigned compute/eval-conflicts-rho020-r1-014-bp9sj to kind-worker5
0.2406,Event,ADDED,eval-conflicts-rho020-r1-014-bp9sj.18d467a122e92fa5,"reason=Pulled count=1 msg=Container image ""busybox:musl"" already present on machine"
0.2408,Event,ADDED,eval-conflicts-rho020-r1-014-bp9sj.18d467a123fd90e9,reason=Created count=1 msg=Created container: task
0.241,Event,ADDED,eval-conflicts-rho020-r1-014-bp9sj.18d467a129d54d91,reason=Started count=1 msg=Started container task
0.2412,Event,ADDED,eval-conflicts-rho020-r1-014.18d467a0c20a750a,reason=SuccessfulCreate count=1 msg=Created pod: eval-conflicts-rho020-r1-014-bp9sj
0.2413,Event,ADDED,eval-conflicts-rho020-r1-014.18d467a442f367db,reason=Completed count=1 msg=Job completed
0.2415,Event,ADDED,eval-conflicts-rho020-r1-015-kwk7h.18d467a0fd737c72,"reason=FailedScheduling count=None msg=0/6 nodes are available: 1 c_wall violated: 1 conflicting context pair(s) with node memory, 5 node(s) had untolerated taint(s). no new claims to deallocate, preemption: 0/6 nodes are available: 1 No preemption victims found for incoming pod, 5 Preemption is not helpful for scheduling."
0.2417,Event,ADDED,eval-conflicts-rho020-r1-015-kwk7h.18d467a0fe01a0b1,"reason=FailedScheduling count=None msg=0/6 nodes are available: 1 c_wall violated: 1 conflicting context pair(s) with node memory, 5 node(s) had untolerated taint(s). no new claims to deallocate, preemption: 0/6 nodes are available: 1 No preemption victims found for incoming pod, 5 Preemption is not helpful for scheduling."
0.2419,Event,ADDED,eval-conflicts-rho020-r1-015-kwk7h.18d467a10e72110c,"reason=FailedScheduling count=None msg=0/6 nodes are available: 2 c_wall violated: 1 conflicting context pair(s) with node memory, 4 node(s) had untolerated taint(s). no new claims to deallocate, preemption: 0/6 nodes are available: 2 No preemption victims found for incoming pod, 4 Preemption is not helpful for scheduling."
0.242,Event,ADDED,eval-conflicts-rho020-r1-015-kwk7h.18d467a32dcd01d9,reason=Scheduled count=None msg=Successfully assigned compute/eval-conflicts-rho020-r1-015-kwk7h to kind-worker
0.2422,Event,ADDED,eval-conflicts-rho020-r1-015-kwk7h.18d467a3484364cd,"reason=Pulled count=1 msg=Container image ""busybox:musl"" already present on machine"
0.2424,Event,ADDED,eval-conflicts-rho020-r1-015-kwk7h.18d467a349670e4f,reason=Created count=1 msg=Created container: task
0.2425,Event,ADDED,eval-conflicts-rho020-r1-015-kwk7h.18d467a34b60d84f,reason=Started count=1 msg=Started container task
0.2427,Event,ADDED,eval-conflicts-rho020-r1-015.18d467a0fd37c38b,reason=SuccessfulCreate count=1 msg=Created pod: eval-conflicts-rho020-r1-015-kwk7h
0.2429,Event,ADDED,eval-conflicts-rho020-r1-015.18d467a61ea445a2,reason=Completed count=1 msg=Job completed
0.243,Event,ADDED,eval-conflicts-rho020-r1-016-d2nc6.18d467a13a11a2e5,reason=Scheduled count=None msg=Successfully assigned compute/eval-conflicts-rho020-r1-016-d2nc6 to kind-worker5
0.2432,Event,ADDED,eval-conflicts-rho020-r1-016-d2nc6.18d467a156c95fa6,"reason=Pulled count=1 msg=Container image ""busybox:musl"" already present on machine"
0.2433,Event,ADDED,eval-conflicts-rho020-r1-016-d2nc6.18d467a1582bdae7,reason=Created count=1 msg=Created container: task
0.2435,Event,ADDED,eval-conflicts-rho020-r1-016-d2nc6.18d467a15ba933d0,reason=Started count=1 msg=Started container task
0.2438,Event,ADDED,eval-conflicts-rho020-r1-016.18d467a138d7f265,reason=SuccessfulCreate count=1 msg=Created pod: eval-conflicts-rho020-r1-016-d2nc6
0.2439,Event,ADDED,eval-conflicts-rho020-r1-016.18d467a47eba5d44,reason=Completed count=1 msg=Job completed
0.2441,Event,ADDED,eval-conflicts-rho020-r1-017-6dh4z.18d467a17afa2a11,reason=Scheduled count=None msg=Successfully assigned compute/eval-conflicts-rho020-r1-017-6dh4z to kind-worker2
0.2443,Event,ADDED,eval-conflicts-rho020-r1-017-6dh4z.18d467a194a837a9,"reason=Pulled count=1 msg=Container image ""busybox:musl"" already present on machine"
0.2445,Event,ADDED,eval-conflicts-rho020-r1-017-6dh4z.18d467a19663a043,reason=Created count=1 msg=Created container: task
0.2446,Event,ADDED,eval-conflicts-rho020-r1-017-6dh4z.18d467a19ab1bc67,reason=Started count=1 msg=Started container task
0.2448,Event,ADDED,eval-conflicts-rho020-r1-017.18d467a17524f366,reason=SuccessfulCreate count=1 msg=Created pod: eval-conflicts-rho020-r1-017-6dh4z
0.245,Event,ADDED,eval-conflicts-rho020-r1-017.18d467a4aae83f15,reason=Completed count=1 msg=Job completed
0.2451,Event,ADDED,eval-conflicts-rho020-r1-018-mvzjx.18d467a1b0f61f1f,reason=Scheduled count=None msg=Successfully assigned compute/eval-conflicts-rho020-r1-018-mvzjx to kind-worker5
0.2453,Event,ADDED,eval-conflicts-rho020-r1-018-mvzjx.18d467a1cdce51d8,"reason=Pulled count=1 msg=Container image ""busybox:musl"" already present on machine"
0.2455,Event,ADDED,eval-conflicts-rho020-r1-018-mvzjx.18d467a1cf1b6dfc,reason=Created count=1 msg=Created container: task
0.2456,Event,ADDED,eval-conflicts-rho020-r1-018-mvzjx.18d467a1d4fec5a8,reason=Started count=1 msg=Started container task
0.2458,Event,ADDED,eval-conflicts-rho020-r1-018.18d467a1b03ef420,reason=SuccessfulCreate count=1 msg=Created pod: eval-conflicts-rho020-r1-018-mvzjx
0.246,Event,ADDED,eval-conflicts-rho020-r1-018.18d467a4b73241ba,reason=Completed count=1 msg=Job completed
0.2462,Event,ADDED,eval-conflicts-rho020-r1-019-bql7q.18d467a1ed5d35e4,reason=Scheduled count=None msg=Successfully assigned compute/eval-conflicts-rho020-r1-019-bql7q to kind-worker5
0.2464,Event,ADDED,eval-conflicts-rho020-r1-019-bql7q.18d467a207e7f05d,"reason=Pulled count=1 msg=Container image ""busybox:musl"" already present on machine"
0.2465,Event,ADDED,eval-conflicts-rho020-r1-019-bql7q.18d467a20903b2e1,reason=Created count=1 msg=Created container: task
0.2467,Event,ADDED,eval-conflicts-rho020-r1-019-bql7q.18d467a211a00713,reason=Started count=1 msg=Started container task
0.2469,Event,ADDED,eval-conflicts-rho020-r1-019.18d467a1ec821a3d,reason=SuccessfulCreate count=1 msg=Created pod: eval-conflicts-rho020-r1-019-bql7q
0.247,Event,ADDED,eval-conflicts-rho020-r1-019.18d467a4f4563862,reason=Completed count=1 msg=Job completed
0.2472,Event,ADDED,eval-conflicts-rho020-r1-020-6rw8j.18d467a229bf16ed,reason=Scheduled count=None msg=Successfully assigned compute/eval-conflicts-rho020-r1-020-6rw8j to kind-worker5
0.2474,Event,ADDED,eval-conflicts-rho020-r1-020-6rw8j.18d467a24403b89a,"reason=Pulled count=1 msg=Container image ""busybox:musl"" already present on machine"
0.2475,Event,ADDED,eval-conflicts-rho020-r1-020-6rw8j.18d467a245130e20,reason=Created count=1 msg=Created container: task
0.2477,Event,ADDED,eval-conflicts-rho020-r1-020-6rw8j.18d467a24cb4c37f,reason=Started count=1 msg=Started container task
0.2479,Event,ADDED,eval-conflicts-rho020-r1-020.18d467a22900ab3b,reason=SuccessfulCreate count=1 msg=Created pod: eval-conflicts-rho020-r1-020-6rw8j
0.248,Event,ADDED,eval-conflicts-rho020-r1-020.18d467a56bc89956,reason=Completed count=1 msg=Job completed
0.2483,Event,ADDED,eval-conflicts-rho020-r1-021-f9vs7.18d467a263d9b80f,reason=Scheduled count=None msg=Successfully assigned compute/eval-conflicts-rho020-r1-021-f9vs7 to kind-worker2
0.2486,Event,ADDED,eval-conflicts-rho020-r1-021-f9vs7.18d467a27e2cbc89,"reason=Pulled count=1 msg=Container image ""busybox:musl"" already present on machine"
0.2487,Event,ADDED,eval-conflicts-rho020-r1-021-f9vs7.18d467a27f422be4,reason=Created count=1 msg=Created container: task
0.2491,Event,ADDED,eval-conflicts-rho020-r1-021-f9vs7.18d467a28506fa76,reason=Started count=1 msg=Started container task
0.2493,Event,ADDED,eval-conflicts-rho020-r1-021.18d467a263455ee3,reason=SuccessfulCreate count=1 msg=Created pod: eval-conflicts-rho020-r1-021-f9vs7
0.2494,Event,ADDED,eval-conflicts-rho020-r1-021.18d467a59fbf6321,reason=Completed count=1 msg=Job completed
0.2497,Event,ADDED,eval-conflicts-rho020-r1-022-6s9xx.18d467a29fb904de,reason=Scheduled count=None msg=Successfully assigned compute/eval-conflicts-rho020-r1-022-6s9xx to kind-worker2
0.2498,Event,ADDED,eval-conflicts-rho020-r1-022-6s9xx.18d467a2bbfedfca,"reason=Pulled count=1 msg=Container image ""busybox:musl"" already present on machine"
0.25,Event,ADDED,eval-conflicts-rho020-r1-022-6s9xx.18d467a2bd214818,reason=Created count=1 msg=Created container: task
0.2502,Event,ADDED,eval-conflicts-rho020-r1-022-6s9xx.18d467a2c7ae7e71,reason=Started count=1 msg=Started container task
0.2503,Event,ADDED,eval-conflicts-rho020-r1-022.18d467a29ed925c3,reason=SuccessfulCreate count=1 msg=Created pod: eval-conflicts-rho020-r1-022-6s9xx
0.2505,Event,ADDED,eval-conflicts-rho020-r1-022.18d467a5d4b48bba,reason=Completed count=1 msg=Job completed
0.2507,Event,ADDED,eval-conflicts-rho020-r1-023-2dxvz.18d467a2db1cb942,"reason=FailedScheduling count=None msg=0/6 nodes are available: 2 c_wall violated: 1 conflicting context pair(s) with node memory, 4 node(s) had untolerated taint(s). no new claims to deallocate, preemption: 0/6 nodes are available: 2 No preemption victims found for incoming pod, 4 Preemption is not helpful for scheduling."
0.2509,Event,ADDED,eval-conflicts-rho020-r1-023-2dxvz.18d467a2dbc8940c,"reason=FailedScheduling count=None msg=0/6 nodes are available: 2 c_wall violated: 1 conflicting context pair(s) with node memory, 4 node(s) had untolerated taint(s). no new claims to deallocate, preemption: 0/6 nodes are available: 2 No preemption victims found for incoming pod, 4 Preemption is not helpful for scheduling."
0.251,Event,ADDED,eval-conflicts-rho020-r1-023-2dxvz.18d467a332fc8c6b,reason=Scheduled count=None msg=Successfully assigned compute/eval-conflicts-rho020-r1-023-2dxvz to kind-worker
0.2512,Event,ADDED,eval-conflicts-rho020-r1-023-2dxvz.18d467a34a9523b2,"reason=Pulled count=1 msg=Container image ""busybox:musl"" already present on machine"
0.2513,Event,ADDED,eval-conflicts-rho020-r1-023-2dxvz.18d467a34bbb25af,reason=Created count=1 msg=Created container: task
0.2515,Event,ADDED,eval-conflicts-rho020-r1-023-2dxvz.18d467a3509e6c0e,reason=Started count=1 msg=Started container task
0.2517,Event,ADDED,eval-conflicts-rho020-r1-023.18d467a2daa577b1,reason=SuccessfulCreate count=1 msg=Created pod: eval-conflicts-rho020-r1-023-2dxvz
0.2518,Event,ADDED,eval-conflicts-rho020-r1-023.18d467a65acc42c9,reason=Completed count=1 msg=Job completed
0.252,Event,ADDED,eval-conflicts-rho020-r1-024-vvxmp.18d467a3171e17c4,reason=Scheduled count=None msg=Successfully assigned compute/eval-conflicts-rho020-r1-024-vvxmp to kind-worker2
0.2522,Event,ADDED,eval-conflicts-rho020-r1-024-vvxmp.18d467a33284dc62,"reason=Pulled count=1 msg=Container image ""busybox:musl"" already present on machine"
0.2523,Event,ADDED,eval-conflicts-rho020-r1-024-vvxmp.18d467a333ccb70e,reason=Created count=1 msg=Created container: task
0.2525,Event,ADDED,eval-conflicts-rho020-r1-024-vvxmp.18d467a33791b9ff,reason=Started count=1 msg=Started container task
0.2527,Event,ADDED,eval-conflicts-rho020-r1-024.18d467a31629d7fc,reason=SuccessfulCreate count=1 msg=Created pod: eval-conflicts-rho020-r1-024-vvxmp
0.2528,Event,ADDED,eval-conflicts-rho020-r1-024.18d467a64c9272ea,reason=Completed count=1 msg=Job completed
0.253,Event,ADDED,eval-conflicts-rho020-r1-025-9g9q7.18d467a3525f0dec,reason=Scheduled count=None msg=Successfully assigned compute/eval-conflicts-rho020-r1-025-9g9q7 to kind-worker
0.2531,Event,ADDED,eval-conflicts-rho020-r1-025-9g9q7.18d467a370fd9432,"reason=Pulled count=1 msg=Container image ""busybox:musl"" already present on machine"
0.2533,Event,ADDED,eval-conflicts-rho020-r1-025-9g9q7.18d467a372165eff,reason=Created count=1 msg=Created container: task
0.2535,Event,ADDED,eval-conflicts-rho020-r1-025-9g9q7.18d467a378f45a09,reason=Started count=1 msg=Started container task
0.2536,Event,ADDED,eval-conflicts-rho020-r1-025.18d467a3516c2b04,reason=SuccessfulCreate count=1 msg=Created pod: eval-conflicts-rho020-r1-025-9g9q7
0.2539,Event,ADDED,eval-conflicts-rho020-r1-025.18d467a65a948e7c,reason=Completed count=1 msg=Job completed
0.254,Event,ADDED,eval-conflicts-rho020-r1-026-dr2t9.18d467a38d81577e,reason=Scheduled count=None msg=Successfully assigned compute/eval-conflicts-rho020-r1-026-dr2t9 to kind-worker4
0.2542,Event,ADDED,eval-conflicts-rho020-r1-026-dr2t9.18d467a3ab37a0e7,"reason=Pulled count=1 msg=Container image ""busybox:musl"" already present on machine"
0.2544,Event,ADDED,eval-conflicts-rho020-r1-026-dr2t9.18d467a3ac617482,reason=Created count=1 msg=Created container: task
0.2547,Event,ADDED,eval-conflicts-rho020-r1-026-dr2t9.18d467a3b6fb74ac,reason=Started count=1 msg=Started container task
0.2549,Event,ADDED,eval-conflicts-rho020-r1-026.18d467a38cc83749,reason=SuccessfulCreate count=1 msg=Created pod: eval-conflicts-rho020-r1-026-dr2t9
0.2551,Event,ADDED,eval-conflicts-rho020-r1-026.18d467a6d7b0017a,reason=Completed count=1 msg=Job completed
0.2553,Event,ADDED,eval-conflicts-rho020-r1-027-4ln55.18d467a3ccdf2a8a,reason=Scheduled count=None msg=Successfully assigned compute/eval-conflicts-rho020-r1-027-4ln55 to kind-worker
0.2557,Event,ADDED,eval-conflicts-rho020-r1-027-4ln55.18d467a3e7c0c1ef,"reason=Pulled count=1 msg=Container image ""busybox:musl"" already present on machine"
0.2559,Event,ADDED,eval-conflicts-rho020-r1-027-4ln55.18d467a3e8d8e532,reason=Created count=1 msg=Created container: task
0.256,Event,ADDED,eval-conflicts-rho020-r1-027-4ln55.18d467a3ee94b5be,reason=Started count=1 msg=Started container task
0.2564,Event,ADDED,eval-conflicts-rho020-r1-027.18d467a3cc2072f1,reason=SuccessfulCreate count=1 msg=Created pod: eval-conflicts-rho020-r1-027-4ln55
0.2566,Event,ADDED,eval-conflicts-rho020-r1-027.18d467a70cabe4e3,reason=Completed count=1 msg=Job completed
0.2568,Event,ADDED,eval-conflicts-rho020-r1-028-5n7vn.18d467a4055ba333,reason=Scheduled count=None msg=Successfully assigned compute/eval-conflicts-rho020-r1-028-5n7vn to kind-worker4
0.2569,Event,ADDED,eval-conflicts-rho020-r1-028-5n7vn.18d467a41f4ce301,"reason=Pulled count=1 msg=Container image ""busybox:musl"" already present on machine"
0.2573,Event,ADDED,eval-conflicts-rho020-r1-028-5n7vn.18d467a420579c46,reason=Created count=1 msg=Created container: task
0.2574,Event,ADDED,eval-conflicts-rho020-r1-028-5n7vn.18d467a4222a0a7a,reason=Started count=1 msg=Started container task
0.2576,Event,ADDED,eval-conflicts-rho020-r1-028.18d467a4048ef26b,reason=SuccessfulCreate count=1 msg=Created pod: eval-conflicts-rho020-r1-028-5n7vn
0.258,Event,ADDED,eval-conflicts-rho020-r1-028.18d467a7518a3d08,reason=Completed count=1 msg=Job completed
0.2582,Event,ADDED,eval-conflicts-rho020-r1-029-5qdnz.18d467a440b6c931,reason=Scheduled count=None msg=Successfully assigned compute/eval-conflicts-rho020-r1-029-5qdnz to kind-worker
0.2584,Event,ADDED,eval-conflicts-rho020-r1-029-5qdnz.18d467a459949b3c,"reason=Pulled count=1 msg=Container image ""busybox:musl"" already present on machine"
0.2586,Event,ADDED,eval-conflicts-rho020-r1-029-5qdnz.18d467a45aa962a8,reason=Created count=1 msg=Created container: task
0.2588,Event,ADDED,eval-conflicts-rho020-r1-029-5qdnz.18d467a45ef3dbc2,reason=Started count=1 msg=Started container task
0.259,Event,ADDED,eval-conflicts-rho020-r1-029.18d467a43fb6e438,reason=SuccessfulCreate count=1 msg=Created pod: eval-conflicts-rho020-r1-029-5qdnz
0.2591,Event,ADDED,eval-conflicts-rho020-r1-029.18d467a746185993,reason=Completed count=1 msg=Job completed
0.2593,Event,ADDED,eval-conflicts-rho020-r1-030-fbkpq.18d467a47ca1f173,reason=Scheduled count=None msg=Successfully assigned compute/eval-conflicts-rho020-r1-030-fbkpq to kind-worker4
0.2595,Event,ADDED,eval-conflicts-rho020-r1-030-fbkpq.18d467a4982cfc06,"reason=Pulled count=1 msg=Container image ""busybox:musl"" already present on machine"
0.2596,Event,ADDED,eval-conflicts-rho020-r1-030-fbkpq.18d467a4994644cf,reason=Created count=1 msg=Created container: task
0.2598,Event,ADDED,eval-conflicts-rho020-r1-030-fbkpq.18d467a49dd8be9d,reason=Started count=1 msg=Started container task
0.26,Event,ADDED,eval-conflicts-rho020-r1-030.18d467a47bc70904,reason=SuccessfulCreate count=1 msg=Created pod: eval-conflicts-rho020-r1-030-fbkpq
0.2602,Event,ADDED,eval-conflicts-rho020-r1-030.18d467a7c870d957,reason=Completed count=1 msg=Job completed
0.2603,Event,ADDED,eval-conflicts-rho020-r1-031-gfbx9.18d467a4b8aceda5,reason=Scheduled count=None msg=Successfully assigned compute/eval-conflicts-rho020-r1-031-gfbx9 to kind-worker
0.2606,Event,ADDED,eval-conflicts-rho020-r1-031-gfbx9.18d467a4d2f8088e,"reason=Pulled count=1 msg=Container image ""busybox:musl"" already present on machine"
0.2608,Event,ADDED,eval-conflicts-rho020-r1-031-gfbx9.18d467a4d403eb64,reason=Created count=1 msg=Created container: task
0.261,Event,ADDED,eval-conflicts-rho020-r1-031-gfbx9.18d467a4d83b4ea3,reason=Started count=1 msg=Started container task
0.2612,Event,ADDED,eval-conflicts-rho020-r1-031.18d467a4b7ce21a7,reason=SuccessfulCreate count=1 msg=Created pod: eval-conflicts-rho020-r1-031-gfbx9
0.2613,Event,ADDED,eval-conflicts-rho020-r1-031.18d467a7bd8c4365,reason=Completed count=1 msg=Job completed
0.2615,Event,ADDED,eval-conflicts-rho020-r1-032-n8mnk.18d467a4f6236958,reason=Scheduled count=None msg=Successfully assigned compute/eval-conflicts-rho020-r1-032-n8mnk to kind-worker4
0.2617,Event,ADDED,eval-conflicts-rho020-r1-032-n8mnk.18d467a50e66af4a,"reason=Pulled count=1 msg=Container image ""busybox:musl"" already present on machine"
0.2619,Event,ADDED,eval-conflicts-rho020-r1-032-n8mnk.18d467a50f7f9690,reason=Created count=1 msg=Created container: task
0.2624,Event,ADDED,eval-conflicts-rho020-r1-032-n8mnk.18d467a5145728ca,reason=Started count=1 msg=Started container task
0.2625,Event,ADDED,eval-conflicts-rho020-r1-032.18d467a4f50708c3,reason=SuccessfulCreate count=1 msg=Created pod: eval-conflicts-rho020-r1-032-n8mnk
0.2627,Event,ADDED,eval-conflicts-rho020-r1-032.18d467a84049d099,reason=Completed count=1 msg=Job completed
0.2628,Event,ADDED,eval-conflicts-rho020-r1-033-xdpvh.18d467a52f3f1e05,reason=Scheduled count=None msg=Successfully assigned compute/eval-conflicts-rho020-r1-033-xdpvh to kind-worker3
0.2631,Event,ADDED,eval-conflicts-rho020-r1-033-xdpvh.18d467a54c12a6b0,"reason=Pulled count=1 msg=Container image ""busybox:musl"" already present on machine"
0.2633,Event,ADDED,eval-conflicts-rho020-r1-033-xdpvh.18d467a54d3f2692,reason=Created count=1 msg=Created container: task
0.2634,Event,ADDED,eval-conflicts-rho020-r1-033-xdpvh.18d467a55213d7a9,reason=Started count=1 msg=Started container task
0.2636,Event,ADDED,eval-conflicts-rho020-r1-033.18d467a52e5e7df0,reason=SuccessfulCreate count=1 msg=Created pod: eval-conflicts-rho020-r1-033-xdpvh
0.2638,Event,ADDED,eval-conflicts-rho020-r1-033.18d467a888635991,reason=Completed count=1 msg=Job completed
0.2639,Event,ADDED,eval-conflicts-rho020-r1-034-kjgm2.18d467a56a82805d,"reason=FailedScheduling count=None msg=0/6 nodes are available: 1 c_wall violated: 2 conflicting context pair(s) with node memory, 2 c_wall violated: 1 conflicting context pair(s) with node memory, 3 node(s) had untolerated taint(s). no new claims to deallocate, preemption: 0/6 nodes are available: 3 No preemption victims found for incoming pod, 3 Preemption is not helpful for scheduling."
0.2641,Event,ADDED,eval-conflicts-rho020-r1-034-kjgm2.18d467a56fc75cd3,"reason=FailedScheduling count=None msg=0/6 nodes are available: 1 c_wall violated: 2 conflicting context pair(s) with node memory, 2 c_wall violated: 1 conflicting context pair(s) with node memory, 3 node(s) had untolerated taint(s). no new claims to deallocate, preemption: 0/6 nodes are available: 3 No preemption victims found for incoming pod, 3 Preemption is not helpful for scheduling."
0.2643,Event,ADDED,eval-conflicts-rho020-r1-034-kjgm2.18d467a581797ccb,"reason=FailedScheduling count=None msg=0/6 nodes are available: 2 c_wall violated: 1 conflicting context pair(s) with node memory, 4 node(s) had untolerated taint(s). no new claims to deallocate, preemption: 0/6 nodes are available: 2 No preemption victims found for incoming pod, 4 Preemption is not helpful for scheduling."
0.2645,Event,ADDED,eval-conflicts-rho020-r1-034-kjgm2.18d467a5b6cdefe9,"reason=FailedScheduling count=None msg=0/6 nodes are available: 1 c_wall violated: 1 conflicting context pair(s) with node memory, 5 node(s) had untolerated taint(s). no new claims to deallocate, preemption: 0/6 nodes are available: 1 No preemption victims found for incoming pod, 5 Preemption is not helpful for scheduling."
0.2647,Event,ADDED,eval-conflicts-rho020-r1-034-kjgm2.18d467a5cb7f8095,reason=Scheduled count=None msg=Successfully assigned compute/eval-conflicts-rho020-r1-034-kjgm2 to kind-worker5
0.2648,Event,ADDED,eval-conflicts-rho020-r1-034-kjgm2.18d467a5e7724c79,"reason=Pulled count=1 msg=Container image ""busybox:musl"" already present on machine"
0.265,Event,ADDED,eval-conflicts-rho020-r1-034-kjgm2.18d467a5e8ae43f6,reason=Created count=1 msg=Created container: task
0.2652,Event,ADDED,eval-conflicts-rho020-r1-034-kjgm2.18d467a5eda0f150,reason=Started count=1 msg=Started container task
0.2656,Event,ADDED,eval-conflicts-rho020-r1-034.18d467a569c9dd32,reason=SuccessfulCreate count=1 msg=Created pod: eval-conflicts-rho020-r1-034-kjgm2
0.2657,Event,ADDED,eval-conflicts-rho020-r1-034.18d467a9264152cc,reason=Completed count=1 msg=Job completed
0.2659,Event,ADDED,eval-conflicts-rho020-r1-035-2q557.18d467a5a6f06ce9,reason=Scheduled count=None msg=Successfully assigned compute/eval-conflicts-rho020-r1-035-2q557 to kind-worker3
0.2661,Event,ADDED,eval-conflicts-rho020-r1-035-2q557.18d467a5c0594e57,"reason=Pulled count=1 msg=Container image ""busybox:musl"" already present on machine"
0.2663,Event,ADDED,eval-conflicts-rho020-r1-035-2q557.18d467a5c17dcf7f,reason=Created count=1 msg=Created container: task
0.2664,Event,ADDED,eval-conflicts-rho020-r1-035-2q557.18d467a5c3792f56,reason=Started count=1 msg=Started container task
0.2666,Event,ADDED,eval-conflicts-rho020-r1-035.18d467a5a6144c9d,reason=SuccessfulCreate count=1 msg=Created pod: eval-conflicts-rho020-r1-035-2q557
0.2668,Event,ADDED,eval-conflicts-rho020-r1-035.18d467a9004e371f,reason=Completed count=1 msg=Job completed
0.2669,Event,ADDED,eval-conflicts-rho020-r1-036-xbmbp.18d467a5e36096e2,reason=Scheduled count=None msg=Successfully assigned compute/eval-conflicts-rho020-r1-036-xbmbp to kind-worker5
0.2671,Event,ADDED,eval-conflicts-rho020-r1-036-xbmbp.18d467a5fcc59d18,"reason=Pulled count=1 msg=Container image ""busybox:musl"" already present on machine"
0.2673,Event,ADDED,eval-conflicts-rho020-r1-036-xbmbp.18d467a5fde3d339,reason=Created count=1 msg=Created container: task
0.2675,Event,ADDED,eval-conflicts-rho020-r1-036-xbmbp.18d467a5ffecdd18,reason=Started count=1 msg=Started container task
0.2676,Event,ADDED,eval-conflicts-rho020-r1-036.18d467a5e2c15329,reason=SuccessfulCreate count=1 msg=Created pod: eval-conflicts-rho020-r1-036-xbmbp
0.2678,Event,ADDED,eval-conflicts-rho020-r1-036.18d467a8eb9b7e1a,reason=Completed count=1 msg=Job completed
0.2679,Event,ADDED,eval-conflicts-rho020-r1-037-xmtzx.18d467a620597e19,reason=Scheduled count=None msg=Successfully assigned compute/eval-conflicts-rho020-r1-037-xmtzx to kind-worker5
0.2681,Event,ADDED,eval-conflicts-rho020-r1-037-xmtzx.18d467a6398276ef,"reason=Pulled count=1 msg=Container image ""busybox:musl"" already present on machine"
0.2683,Event,ADDED,eval-conflicts-rho020-r1-037-xmtzx.18d467a63aaae1cd,reason=Created count=1 msg=Created container: task
0.2684,Event,ADDED,eval-conflicts-rho020-r1-037-xmtzx.18d467a6401b91ee,reason=Started count=1 msg=Started container task
0.2686,Event,ADDED,eval-conflicts-rho020-r1-037.18d467a61f66e3e2,reason=SuccessfulCreate count=1 msg=Created pod: eval-conflicts-rho020-r1-037-xmtzx
0.2688,Event,ADDED,eval-conflicts-rho020-r1-037.18d467a927046479,reason=Completed count=1 msg=Job completed
0.2689,Event,ADDED,eval-conflicts-rho020-r1-038-x949z.18d467a65b7a5546,reason=Scheduled count=None msg=Successfully assigned compute/eval-conflicts-rho020-r1-038-x949z to kind-worker5
0.2691,Event,ADDED,eval-conflicts-rho020-r1-038-x949z.18d467a674ee4f8c,"reason=Pulled count=1 msg=Container image ""busybox:musl"" already present on machine"
0.2693,Event,ADDED,eval-conflicts-rho020-r1-038-x949z.18d467a67606c490,reason=Created count=1 msg=Created container: task
0.2694,Event,ADDED,eval-conflicts-rho020-r1-038-x949z.18d467a67d4d57ca,reason=Started count=1 msg=Started container task
0.2696,Event,ADDED,eval-conflicts-rho020-r1-038.18d467a65a6d0c9a,reason=SuccessfulCreate count=1 msg=Created pod: eval-conflicts-rho020-r1-038-x949z
0.2698,Event,ADDED,eval-conflicts-rho020-r1-038.18d467a962f66bab,reason=Completed count=1 msg=Job completed
0.27,Event,ADDED,eval-conflicts-rho020-r1-039-qxgcc.18d467a69728c262,reason=Scheduled count=None msg=Successfully assigned compute/eval-conflicts-rho020-r1-039-qxgcc to kind-worker5
0.2701,Event,ADDED,eval-conflicts-rho020-r1-039-qxgcc.18d467a6b041166d,"reason=Pulled count=1 msg=Container image ""busybox:musl"" already present on machine"
0.2703,Event,ADDED,eval-conflicts-rho020-r1-039-qxgcc.18d467a6b16b04db,reason=Created count=1 msg=Created container: task
0.2705,Event,ADDED,eval-conflicts-rho020-r1-039-qxgcc.18d467a6ba0b0c23,reason=Started count=1 msg=Started container task
0.2706,Event,ADDED,eval-conflicts-rho020-r1-039.18d467a69626c913,reason=SuccessfulCreate count=1 msg=Created pod: eval-conflicts-rho020-r1-039-qxgcc
0.2708,Event,ADDED,eval-conflicts-rho020-r1-039.18d467a99e9d127c,reason=Completed count=1 msg=Job completed
0.2709,Event,ADDED,eval-conflicts-rho020-r1-040-d2zcv.18d467a6d0358e52,reason=Scheduled count=None msg=Successfully assigned compute/eval-conflicts-rho020-r1-040-d2zcv to kind-worker5
0.2712,Event,ADDED,eval-conflicts-rho020-r1-040-d2zcv.18d467a6e88265e8,"reason=Pulled count=1 msg=Container image ""busybox:musl"" already present on machine"
0.2714,Event,ADDED,eval-conflicts-rho020-r1-040-d2zcv.18d467a6e998fac2,reason=Created count=1 msg=Created container: task
0.2717,Event,ADDED,eval-conflicts-rho020-r1-040-d2zcv.18d467a6eb89ac8c,reason=Started count=1 msg=Started container task
0.2719,Event,ADDED,eval-conflicts-rho020-r1-040.18d467a6cf5392d2,reason=SuccessfulCreate count=1 msg=Created pod: eval-conflicts-rho020-r1-040-d2zcv
0.2721,Event,ADDED,eval-conflicts-rho020-r1-040.18d467aa16059ed5,reason=Completed count=1 msg=Job completed
0.2723,Event,ADDED,eval-conflicts-rho020-r1-041-swtwk.18d467a70beeabce,reason=Scheduled count=None msg=Successfully assigned compute/eval-conflicts-rho020-r1-041-swtwk to kind-worker3
0.2724,Event,ADDED,eval-conflicts-rho020-r1-041-swtwk.18d467a725fe979d,"reason=Pulled count=1 msg=Container image ""busybox:musl"" already present on machine"
0.2726,Event,ADDED,eval-conflicts-rho020-r1-041-swtwk.18d467a727028feb,reason=Created count=1 msg=Created container: task
0.2728,Event,ADDED,eval-conflicts-rho020-r1-041-swtwk.18d467a728e26311,reason=Started count=1 msg=Started container task
0.2729,Event,ADDED,eval-conflicts-rho020-r1-041.18d467a70b4ef7ac,reason=SuccessfulCreate count=1 msg=Created pod: eval-conflicts-rho020-r1-041-swtwk
0.2731,Event,ADDED,eval-conflicts-rho020-r1-041.18d467aa64d16298,reason=Completed count=1 msg=Job completed
0.2733,Event,ADDED,eval-conflicts-rho020-r1-042-tl9g2.18d467a747816e6e,reason=Scheduled count=None msg=Successfully assigned compute/eval-conflicts-rho020-r1-042-tl9g2 to kind-worker5
0.2735,Event,ADDED,eval-conflicts-rho020-r1-042-tl9g2.18d467a764284793,"reason=Pulled count=1 msg=Container image ""busybox:musl"" already present on machine"
0.2737,Event,ADDED,eval-conflicts-rho020-r1-042-tl9g2.18d467a766b35580,reason=Created count=1 msg=Created container: task
0.2738,Event,ADDED,eval-conflicts-rho020-r1-042-tl9g2.18d467a76fb5db42,reason=Started count=1 msg=Started container task
0.274,Event,ADDED,eval-conflicts-rho020-r1-042.18d467a746a7635d,reason=SuccessfulCreate count=1 msg=Created pod: eval-conflicts-rho020-r1-042-tl9g2
0.2742,Event,ADDED,eval-conflicts-rho020-r1-042.18d467aa8d95f4f9,reason=Completed count=1 msg=Job completed
0.2743,Event,ADDED,eval-conflicts-rho020-r1-043-lmg9t.18d467a7837d1276,reason=Scheduled count=None msg=Successfully assigned compute/eval-conflicts-rho020-r1-043-lmg9t to kind-worker3
0.2745,Event,ADDED,eval-conflicts-rho020-r1-043-lmg9t.18d467a79f83810a,"reason=Pulled count=1 msg=Container image ""busybox:musl"" already present on machine"
0.2747,Event,ADDED,eval-conflicts-rho020-r1-043-lmg9t.18d467a7a0957c9e,reason=Created count=1 msg=Created container: task
0.2748,Event,ADDED,eval-conflicts-rho020-r1-043-lmg9t.18d467a7a5cd9afe,reason=Started count=1 msg=Started container task
0.2751,Event,ADDED,eval-conflicts-rho020-r1-043.18d467a782ac80a7,reason=SuccessfulCreate count=1 msg=Created pod: eval-conflicts-rho020-r1-043-lmg9t
0.2752,Event,ADDED,eval-conflicts-rho020-r1-043.18d467aadca3e332,reason=Completed count=1 msg=Job completed
0.2754,Event,ADDED,eval-conflicts-rho020-r1-044-2m5jb.18d467a7be75db86,"reason=FailedScheduling count=None msg=0/6 nodes are available: 1 c_wall violated: 1 conflicting context pair(s) with node memory, 5 node(s) had untolerated taint(s). no new claims to deallocate, preemption: 0/6 nodes are available: 1 No preemption victims found for incoming pod, 5 Preemption is not helpful for scheduling."
0.2756,Event,ADDED,eval-conflicts-rho020-r1-044-2m5jb.18d467a7bf1b2c8e,"reason=FailedScheduling count=None msg=0/6 nodes are available: 1 c_wall violated: 1 conflicting context pair(s) with node memory, 5 node(s) had untolerated taint(s). no new claims to deallocate, preemption: 0/6 nodes are available: 1 No preemption victims found for incoming pod, 5 Preemption is not helpful for scheduling."
0.2759,Event,ADDED,eval-conflicts-rho020-r1-044-2m5jb.18d467a7db9f990a,reason=Scheduled count=None msg=Successfully assigned compute/eval-conflicts-rho020-r1-044-2m5jb to kind-worker
0.2761,Event,ADDED,eval-conflicts-rho020-r1-044-2m5jb.18d467a7f58596df,"reason=Pulled count=1 msg=Container image ""busybox:musl"" already present on machine"
0.2763,Event,ADDED,eval-conflicts-rho020-r1-044-2m5jb.18d467a7f694c146,reason=Created count=1 msg=Created container: task
0.2766,Event,ADDED,eval-conflicts-rho020-r1-044-2m5jb.18d467a7f8814986,reason=Started count=1 msg=Started container task
0.2768,Event,ADDED,eval-conflicts-rho020-r1-044.18d467a7be2d7eae,reason=SuccessfulCreate count=1 msg=Created pod: eval-conflicts-rho020-r1-044-2m5jb
0.2769,Event,ADDED,eval-conflicts-rho020-r1-044.18d467ab0264dc08,reason=Completed count=1 msg=Job completed
0.2772,Event,ADDED,eval-conflicts-rho020-r1-045-6fz5d.18d467a7fa22d0f1,reason=Scheduled count=None msg=Successfully assigned compute/eval-conflicts-rho020-r1-045-6fz5d to kind-worker
0.2775,Event,ADDED,eval-conflicts-rho020-r1-045-6fz5d.18d467a81690a33f,"reason=Pulled count=1 msg=Container image ""busybox:musl"" already present on machine"
0.2777,Event,ADDED,eval-conflicts-rho020-r1-045-6fz5d.18d467a817cd839c,reason=Created count=1 msg=Created container: task
0.2779,Event,ADDED,eval-conflicts-rho020-r1-045-6fz5d.18d467a81efa7241,reason=Started count=1 msg=Started container task
0.2782,Event,ADDED,eval-conflicts-rho020-r1-045.18d467a7f946c1f9,reason=SuccessfulCreate count=1 msg=Created pod: eval-conflicts-rho020-r1-045-6fz5d
0.2784,Event,ADDED,eval-conflicts-rho020-r1-045.18d467ab03112d02,reason=Completed count=1 msg=Job completed
0.2785,Event,ADDED,eval-conflicts-rho020-r1-046-52lj5.18d467a83627c22e,reason=Scheduled count=None msg=Successfully assigned compute/eval-conflicts-rho020-r1-046-52lj5 to kind-worker2
0.2787,Event,ADDED,eval-conflicts-rho020-r1-046-52lj5.18d467a851ce7b8f,"reason=Pulled count=1 msg=Container image ""busybox:musl"" already present on machine"
0.2792,Event,ADDED,eval-conflicts-rho020-r1-046-52lj5.18d467a852e906f9,reason=Created count=1 msg=Created container: task
0.2794,Event,ADDED,eval-conflicts-rho020-r1-046-52lj5.18d467a8558c2b9c,reason=Started count=1 msg=Started container task
0.2795,Event,ADDED,eval-conflicts-rho020-r1-046.18d467a83569ba1f,reason=SuccessfulCreate count=1 msg=Created pod: eval-conflicts-rho020-r1-046-52lj5
0.2797,Event,ADDED,eval-conflicts-rho020-r1-046.18d467ab6dee18e8,reason=Completed count=1 msg=Job completed
0.2799,Event,ADDED,eval-conflicts-rho020-r1-047-62dvq.18d467a871bf3ea7,reason=Scheduled count=None msg=Successfully assigned compute/eval-conflicts-rho020-r1-047-62dvq to kind-worker2
0.2801,Event,ADDED,eval-conflicts-rho020-r1-047-62dvq.18d467a88b3000dc,"reason=Pulled count=1 msg=Container image ""busybox:musl"" already present on machine"
0.2802,Event,ADDED,eval-conflicts-rho020-r1-047-62dvq.18d467a88c59075d,reason=Created count=1 msg=Created container: task
0.2804,Event,ADDED,eval-conflicts-rho020-r1-047-62dvq.18d467a8908608c9,reason=Started count=1 msg=Started container task
0.2806,Event,ADDED,eval-conflicts-rho020-r1-047.18d467a870c593d0,reason=SuccessfulCreate count=1 msg=Created pod: eval-conflicts-rho020-r1-047-62dvq
0.2807,Event,ADDED,eval-conflicts-rho020-r1-047.18d467aba9de48dc,reason=Completed count=1 msg=Job completed
0.2809,Event,ADDED,eval-conflicts-rho020-r1-048-hf4qq.18d467a8ada3c7c2,reason=Scheduled count=None msg=Successfully assigned compute/eval-conflicts-rho020-r1-048-hf4qq to kind-worker2
0.2811,Event,ADDED,eval-conflicts-rho020-r1-048-hf4qq.18d467a8c6bc5191,"reason=Pulled count=1 msg=Container image ""busybox:musl"" already present on machine"
0.2812,Event,ADDED,eval-conflicts-rho020-r1-048-hf4qq.18d467a8c7ca78b6,reason=Created count=1 msg=Created container: task
0.2814,Event,ADDED,eval-conflicts-rho020-r1-048-hf4qq.18d467a8cc226fae,reason=Started count=1 msg=Started container task
0.2816,Event,ADDED,eval-conflicts-rho020-r1-048.18d467a8ac7f8dbd,reason=SuccessfulCreate count=1 msg=Created pod: eval-conflicts-rho020-r1-048-hf4qq
0.2817,Event,ADDED,eval-conflicts-rho020-r1-048.18d467abe5ba54ee,reason=Completed count=1 msg=Job completed
0.2819,Event,ADDED,eval-conflicts-rho020-r1-049-74tp2.18d467a8e8da338b,reason=Scheduled count=None msg=Successfully assigned compute/eval-conflicts-rho020-r1-049-74tp2 to kind-worker
0.282,Event,ADDED,eval-conflicts-rho020-r1-049-74tp2.18d467a90234b04e,"reason=Pulled count=1 msg=Container image ""busybox:musl"" already present on machine"
0.2822,Event,ADDED,eval-conflicts-rho020-r1-049-74tp2.18d467a903623996,reason=Created count=1 msg=Created container: task
0.2824,Event,ADDED,eval-conflicts-rho020-r1-049-74tp2.18d467a90578454d,reason=Started count=1 msg=Started container task
0.2825,Event,ADDED,eval-conflicts-rho020-r1-049.18d467a8e7db6d2c,reason=SuccessfulCreate count=1 msg=Created pod: eval-conflicts-rho020-r1-049-74tp2
0.2827,Event,ADDED,eval-conflicts-rho020-r1-049.18d467ac2cd1e606,reason=Completed count=1 msg=Job completed
0.2829,Event,ADDED,eval-conflicts-rho020-r1-050-45dxr.18d467a924c62117,reason=Scheduled count=None msg=Successfully assigned compute/eval-conflicts-rho020-r1-050-45dxr to kind-worker4
0.283,Event,ADDED,eval-conflicts-rho020-r1-050-45dxr.18d467a93daf8054,"reason=Pulled count=1 msg=Container image ""busybox:musl"" already present on machine"
0.2832,Event,ADDED,eval-conflicts-rho020-r1-050-45dxr.18d467a93f8fa395,reason=Created count=1 msg=Created container: task
0.2834,Event,ADDED,eval-conflicts-rho020-r1-050-45dxr.18d467a945a20216,reason=Started count=1 msg=Started container task
0.2835,Event,ADDED,eval-conflicts-rho020-r1-050.18d467a923eb606a,reason=SuccessfulCreate count=1 msg=Created pod: eval-conflicts-rho020-r1-050-45dxr
0.2837,Event,ADDED,eval-conflicts-rho020-r1-050.18d467ac703827e4,reason=Completed count=1 msg=Job completed
0.2838,Event,ADDED,eval-conflicts-rho020-r1-051-jsw2l.18d467a99cb421bc,reason=Scheduled count=None msg=Successfully assigned compute/eval-conflicts-rho020-r1-051-jsw2l to kind-worker
0.2846,Event,ADDED,eval-conflicts-rho020-r1-051-jsw2l.18d467a9b5c14865,"reason=Pulled count=1 msg=Container image ""busybox:musl"" already present on machine"
0.2849,Event,ADDED,eval-conflicts-rho020-r1-051-jsw2l.18d467a9b7055c61,reason=Created count=1 msg=Created container: task
0.2851,Event,ADDED,eval-conflicts-rho020-r1-051-jsw2l.18d467a9b9204641,reason=Started count=1 msg=Started container task
0.2853,Event,ADDED,eval-conflicts-rho020-r1-051.18d467a99b417c25,reason=SuccessfulCreate count=1 msg=Created pod: eval-conflicts-rho020-r1-051-jsw2l
0.2857,Event,ADDED,eval-conflicts-rho020-r1-051.18d467aca4edb3fd,reason=Completed count=1 msg=Job completed
0.2858,Event,ADDED,eval-conflicts-rho020-r1-052-x5kgn.18d467a9a103af48,reason=Scheduled count=None msg=Successfully assigned compute/eval-conflicts-rho020-r1-052-x5kgn to kind-worker
0.286,Event,ADDED,eval-conflicts-rho020-r1-052-x5kgn.18d467a9b80f46c6,"reason=Pulled count=1 msg=Container image ""busybox:musl"" already present on machine"
0.2863,Event,ADDED,eval-conflicts-rho020-r1-052-x5kgn.18d467a9b94d1180,reason=Created count=1 msg=Created container: task
0.2865,Event,ADDED,eval-conflicts-rho020-r1-052-x5kgn.18d467a9bba29f1a,reason=Started count=1 msg=Started container task
0.2867,Event,ADDED,eval-conflicts-rho020-r1-052.18d467a99d139647,reason=SuccessfulCreate count=1 msg=Created pod: eval-conflicts-rho020-r1-052-x5kgn
0.2868,Event,ADDED,eval-conflicts-rho020-r1-052.18d467ace02802b5,reason=Completed count=1 msg=Job completed
0.2872,Event,ADDED,eval-conflicts-rho020-r1-053-t9zxn.18d467a9d7487541,reason=Scheduled count=None msg=Successfully assigned compute/eval-conflicts-rho020-r1-053-t9zxn to kind-worker4
0.2874,Event,ADDED,eval-conflicts-rho020-r1-053-t9zxn.18d467a9f4c6c2ee,"reason=Pulled count=1 msg=Container image ""busybox:musl"" already present on machine"
0.2876,Event,ADDED,eval-conflicts-rho020-r1-053-t9zxn.18d467a9f5f1c5f0,reason=Created count=1 msg=Created container: task
0.2878,Event,ADDED,eval-conflicts-rho020-r1-053-t9zxn.18d467a9faa757f9,reason=Started count=1 msg=Started container task
0.2881,Event,ADDED,eval-conflicts-rho020-r1-053.18d467a9d627ae04,reason=SuccessfulCreate count=1 msg=Created pod: eval-conflicts-rho020-r1-053-t9zxn
0.2883,Event,ADDED,eval-conflicts-rho020-r1-053.18d467ad2419b02c,reason=Completed count=1 msg=Job completed
0.2885,Event,ADDED,eval-conflicts-rho020-r1-054-cfgzn.18d467aa139dd9db,reason=Scheduled count=None msg=Successfully assigned compute/eval-conflicts-rho020-r1-054-cfgzn to kind-worker4
0.2887,Event,ADDED,eval-conflicts-rho020-r1-054-cfgzn.18d467aa2ceeb8cf,"reason=Pulled count=1 msg=Container image ""busybox:musl"" already present on machine"
0.289,Event,ADDED,eval-conflicts-rho020-r1-054-cfgzn.18d467aa2e0b06b8,reason=Created count=1 msg=Created container: task
0.2892,Event,ADDED,eval-conflicts-rho020-r1-054-cfgzn.18d467aa300c70ac,reason=Started count=1 msg=Started container task
0.2893,Event,ADDED,eval-conflicts-rho020-r1-054.18d467aa127de47f,reason=SuccessfulCreate count=1 msg=Created pod: eval-conflicts-rho020-r1-054-cfgzn
0.2897,Event,ADDED,eval-conflicts-rho020-r1-054.18d467ad5ff2a13a,reason=Completed count=1 msg=Job completed
0.2898,Event,ADDED,eval-conflicts-rho020-r1-055-rkmvb.18d467aa4ed19a2d,reason=Scheduled count=None msg=Successfully assigned compute/eval-conflicts-rho020-r1-055-rkmvb to kind-worker2
0.29,Event,ADDED,eval-conflicts-rho020-r1-055-rkmvb.18d467aa6d55f90c,"reason=Pulled count=1 msg=Container image ""busybox:musl"" already present on machine"
0.2903,Event,ADDED,eval-conflicts-rho020-r1-055-rkmvb.18d467aa6e729945,reason=Created count=1 msg=Created container: task
0.2905,Event,ADDED,eval-conflicts-rho020-r1-055-rkmvb.18d467aa73481294,reason=Started count=1 msg=Started container task
0.2908,Event,ADDED,eval-conflicts-rho020-r1-055.18d467aa4debeab9,reason=SuccessfulCreate count=1 msg=Created pod: eval-conflicts-rho020-r1-055-rkmvb
0.2911,Event,ADDED,eval-conflicts-rho020-r1-055.18d467ad891b255f,reason=Completed count=1 msg=Job completed
0.2914,Event,ADDED,eval-conflicts-rho020-r1-056-t2wf4.18d467aa89c78480,reason=Scheduled count=None msg=Successfully assigned compute/eval-conflicts-rho020-r1-056-t2wf4 to kind-worker5
0.2916,Event,ADDED,eval-conflicts-rho020-r1-056-t2wf4.18d467aaa3131247,"reason=Pulled count=1 msg=Container image ""busybox:musl"" already present on machine"
0.292,Event,ADDED,eval-conflicts-rho020-r1-056-t2wf4.18d467aaa42f5fa3,reason=Created count=1 msg=Created container: task
0.2922,Event,ADDED,eval-conflicts-rho020-r1-056-t2wf4.18d467aaa62e4cc9,reason=Started count=1 msg=Started container task
0.2925,Event,ADDED,eval-conflicts-rho020-r1-056.18d467aa895dadf6,reason=SuccessfulCreate count=1 msg=Created pod: eval-conflicts-rho020-r1-056-t2wf4
0.2927,Event,ADDED,eval-conflicts-rho020-r1-056.18d467add425bda7,reason=Completed count=1 msg=Job completed
0.2928,Event,ADDED,eval-conflicts-rho020-r1-057-b4c2s.18d467aac602ad5c,reason=Scheduled count=None msg=Successfully assigned compute/eval-conflicts-rho020-r1-057-b4c2s to kind-worker5
0.2931,Event,ADDED,eval-conflicts-rho020-r1-057-b4c2s.18d467aadf415284,"reason=Pulled count=1 msg=Container image ""busybox:musl"" already present on machine"
0.2932,Event,ADDED,eval-conflicts-rho020-r1-057-b4c2s.18d467aae055ce2d,reason=Created count=1 msg=Created container: task
0.2934,Event,ADDED,eval-conflicts-rho020-r1-057-b4c2s.18d467aae267954c,reason=Started count=1 msg=Started container task
0.2936,Event,ADDED,eval-conflicts-rho020-r1-057.18d467aac52e8a60,reason=SuccessfulCreate count=1 msg=Created pod: eval-conflicts-rho020-r1-057-b4c2s
0.2939,Event,ADDED,eval-conflicts-rho020-r1-057.18d467ae0eda76d1,reason=Completed count=1 msg=Job completed
0.2941,Event,ADDED,eval-conflicts-rho020-r1-058-2mxbv.18d467ab0185bcf3,reason=Scheduled count=None msg=Successfully assigned compute/eval-conflicts-rho020-r1-058-2mxbv to kind-worker5
0.2942,Event,ADDED,eval-conflicts-rho020-r1-058-2mxbv.18d467ab1c3fb5d3,"reason=Pulled count=1 msg=Container image ""busybox:musl"" already present on machine"
0.2944,Event,ADDED,eval-conflicts-rho020-r1-058-2mxbv.18d467ab1d579db1,reason=Created count=1 msg=Created container: task
0.2948,Event,ADDED,eval-conflicts-rho020-r1-058-2mxbv.18d467ab21a46501,reason=Started count=1 msg=Started container task
0.2949,Event,ADDED,eval-conflicts-rho020-r1-058.18d467ab011ec3a8,reason=SuccessfulCreate count=1 msg=Created pod: eval-conflicts-rho020-r1-058-2mxbv
0.2951,Event,ADDED,eval-conflicts-rho020-r1-058.18d467ae0f86d73d,reason=Completed count=1 msg=Job completed
0.2955,Event,ADDED,eval-conflicts-rho020-r1-059-bmlsq.18d467ab3d0aaa5e,reason=Scheduled count=None msg=Successfully assigned compute/eval-conflicts-rho020-r1-059-bmlsq to kind-worker5
0.2957,Event,ADDED,eval-conflicts-rho020-r1-059-bmlsq.18d467ab55a4dc85,"reason=Pulled count=1 msg=Container image ""busybox:musl"" already present on machine"
0.2959,Event,ADDED,eval-conflicts-rho020-r1-059-bmlsq.18d467ab56ab54e9,reason=Created count=1 msg=Created container: task
0.296,Event,ADDED,eval-conflicts-rho020-r1-059-bmlsq.18d467ab58d5a3ea,reason=Started count=1 msg=Started container task
0.2964,Event,ADDED,eval-conflicts-rho020-r1-059.18d467ab3c829da7,reason=SuccessfulCreate count=1 msg=Created pod: eval-conflicts-rho020-r1-059-bmlsq
0.2966,Event,ADDED,eval-conflicts-rho020-r1-059.18d467ae86d774dd,reason=Completed count=1 msg=Job completed
0.2968,Event,ADDED,eval-conflicts-rho020-r1-060-cfgwk.18d467ab785781a2,reason=Scheduled count=None msg=Successfully assigned compute/eval-conflicts-rho020-r1-060-cfgwk to kind-worker5
0.2969,Event,ADDED,eval-conflicts-rho020-r1-060-cfgwk.18d467ab936dacad,"reason=Pulled count=1 msg=Container image ""busybox:musl"" already present on machine"
0.2973,Event,ADDED,eval-conflicts-rho020-r1-060-cfgwk.18d467ab948f1e44,reason=Created count=1 msg=Created container: task
0.2975,Event,ADDED,eval-conflicts-rho020-r1-060-cfgwk.18d467ab97eac996,reason=Started count=1 msg=Started container task
0.2976,Event,ADDED,eval-conflicts-rho020-r1-060.18d467ab77be9d04,reason=SuccessfulCreate count=1 msg=Created pod: eval-conflicts-rho020-r1-060-cfgwk
0.2979,Event,ADDED,eval-conflicts-rho020-r1-060.18d467aec2cd39f3,reason=Completed count=1 msg=Job completed
0.2981,Event,ADDED,eval-conflicts-rho020-r1-061-fj29z.18d467abb3d121d8,reason=Scheduled count=None msg=Successfully assigned compute/eval-conflicts-rho020-r1-061-fj29z to kind-worker5
0.2984,Event,ADDED,eval-conflicts-rho020-r1-061-fj29z.18d467abccd99db6,"reason=Pulled count=1 msg=Container image ""busybox:musl"" already present on machine"
0.2986,Event,ADDED,eval-conflicts-rho020-r1-061-fj29z.18d467abcdf547a5,reason=Created count=1 msg=Created container: task
0.2987,Event,ADDED,eval-conflicts-rho020-r1-061-fj29z.18d467abcff45ccd,reason=Started count=1 msg=Started container task
0.2989,Event,ADDED,eval-conflicts-rho020-r1-061.18d467abb341e6e5,reason=SuccessfulCreate count=1 msg=Created pod: eval-conflicts-rho020-r1-061-fj29z
0.2992,Event,ADDED,eval-conflicts-rho020-r1-061.18d467aefed59fa4,reason=Completed count=1 msg=Job completed
0.2993,Event,ADDED,eval-conflicts-rho020-r1-062-qtsbv.18d467abef7f9caf,reason=Scheduled count=None msg=Successfully assigned compute/eval-conflicts-rho020-r1-062-qtsbv to kind-worker5
0.2995,Event,ADDED,eval-conflicts-rho020-r1-062-qtsbv.18d467ac08c37f2a,"reason=Pulled count=1 msg=Container image ""busybox:musl"" already present on machine"
0.3,Event,ADDED,eval-conflicts-rho020-r1-062-qtsbv.18d467ac09ce1515,reason=Created count=1 msg=Created container: task
0.3001,Event,ADDED,eval-conflicts-rho020-r1-062-qtsbv.18d467ac0ba79a29,reason=Started count=1 msg=Started container task
0.3003,Event,ADDED,eval-conflicts-rho020-r1-062.18d467abeefb5da6,reason=SuccessfulCreate count=1 msg=Created pod: eval-conflicts-rho020-r1-062-qtsbv
0.3005,Event,ADDED,eval-conflicts-rho020-r1-062.18d467af3ae21131,reason=Completed count=1 msg=Job completed
0.3008,Event,ADDED,eval-conflicts-rho020-r1-063-vrqfq.18d467ac2b494bb1,reason=Scheduled count=None msg=Successfully assigned compute/eval-conflicts-rho020-r1-063-vrqfq to kind-worker5
0.301,Event,ADDED,eval-conflicts-rho020-r1-063-vrqfq.18d467ac44be04ab,"reason=Pulled count=1 msg=Container image ""busybox:musl"" already present on machine"
0.3011,Event,ADDED,eval-conflicts-rho020-r1-063-vrqfq.18d467ac45db9efa,reason=Created count=1 msg=Created container: task
0.3014,Event,ADDED,eval-conflicts-rho020-r1-063-vrqfq.18d467ac4a88731c,reason=Started count=1 msg=Started container task
0.3016,Event,ADDED,eval-conflicts-rho020-r1-063.18d467ac2aa43864,reason=SuccessfulCreate count=1 msg=Created pod: eval-conflicts-rho020-r1-063-vrqfq
0.3018,Event,ADDED,eval-conflicts-rho020-r1-063.18d467af761db4a7,reason=Completed count=1 msg=Job completed
0.302,Event,ADDED,eval-conflicts-rho020-r1-064-ctkmw.18d467ac673269f3,reason=Scheduled count=None msg=Successfully assigned compute/eval-conflicts-rho020-r1-064-ctkmw to kind-worker3
0.3023,Event,ADDED,eval-conflicts-rho020-r1-064-ctkmw.18d467ac803f0b6f,"reason=Pulled count=1 msg=Container image ""busybox:musl"" already present on machine"
0.3024,Event,ADDED,eval-conflicts-rho020-r1-064-ctkmw.18d467ac814af0d0,reason=Created count=1 msg=Created container: task
0.3026,Event,ADDED,eval-conflicts-rho020-r1-064-ctkmw.18d467ac837e9407,reason=Started count=1 msg=Started container task
0.3028,Event,ADDED,eval-conflicts-rho020-r1-064.18d467ac6626fe3d,reason=SuccessfulCreate count=1 msg=Created pod: eval-conflicts-rho020-r1-064-ctkmw
0.303,Event,ADDED,eval-conflicts-rho020-r1-064.18d467afc4d53b2a,reason=Completed count=1 msg=Job completed
0.3032,Event,ADDED,eval-conflicts-rho020-r1-065-v9ctv.18d467aca29966b2,reason=Scheduled count=None msg=Successfully assigned compute/eval-conflicts-rho020-r1-065-v9ctv to kind-worker
0.3033,Event,ADDED,eval-conflicts-rho020-r1-065-v9ctv.18d467acbb2f2c29,"reason=Pulled count=1 msg=Container image ""busybox:musl"" already present on machine"
0.3035,Event,ADDED,eval-conflicts-rho020-r1-065-v9ctv.18d467acbcf0ccdc,reason=Created count=1 msg=Created container: task
0.3037,Event,ADDED,eval-conflicts-rho020-r1-065-v9ctv.18d467acbf225a8d,reason=Started count=1 msg=Started container task
0.3038,Event,ADDED,eval-conflicts-rho020-r1-065.18d467aca180b50e,reason=SuccessfulCreate count=1 msg=Created pod: eval-conflicts-rho020-r1-065-v9ctv
0.304,Event,ADDED,eval-conflicts-rho020-r1-065.18d467afead8a6dd,reason=Completed count=1 msg=Job completed
0.3042,Event,ADDED,eval-conflicts-rho020-r1-066-8qdxt.18d467acdea03775,reason=Scheduled count=None msg=Successfully assigned compute/eval-conflicts-rho020-r1-066-8qdxt to kind-worker
0.3043,Event,ADDED,eval-conflicts-rho020-r1-066-8qdxt.18d467acf7da18ce,"reason=Pulled count=1 msg=Container image ""busybox:musl"" already present on machine"
0.3045,Event,ADDED,eval-conflicts-rho020-r1-066-8qdxt.18d467acf8fa65e9,reason=Created count=1 msg=Created container: task
0.3048,Event,ADDED,eval-conflicts-rho020-r1-066-8qdxt.18d467acfb16c93e,reason=Started count=1 msg=Started container task
0.3051,Event,ADDED,eval-conflicts-rho020-r1-066.18d467acdda967ed,reason=SuccessfulCreate count=1 msg=Created pod: eval-conflicts-rho020-r1-066-8qdxt
0.3053,Event,ADDED,eval-conflicts-rho020-r1-066.18d467b026ae7440,reason=Completed count=1 msg=Job completed
0.3054,Event,ADDED,eval-conflicts-rho020-r1-067-99hd6.18d467ad1ab5ea92,reason=Scheduled count=None msg=Successfully assigned compute/eval-conflicts-rho020-r1-067-99hd6 to kind-worker
0.3057,Event,ADDED,eval-conflicts-rho020-r1-067-99hd6.18d467ad34a51429,"reason=Pulled count=1 msg=Container image ""busybox:musl"" already present on machine"
0.3059,Event,ADDED,eval-conflicts-rho020-r1-067-99hd6.18d467ad35d69621,reason=Created count=1 msg=Created container: task
0.3061,Event,ADDED,eval-conflicts-rho020-r1-067-99hd6.18d467ad39c78e3a,reason=Started count=1 msg=Started container task
0.3063,Event,ADDED,eval-conflicts-rho020-r1-067.18d467ad19d9a7f8,reason=SuccessfulCreate count=1 msg=Created pod: eval-conflicts-rho020-r1-067-99hd6
0.3065,Event,ADDED,eval-conflicts-rho020-r1-067.18d467b06201c81b,reason=Completed count=1 msg=Job completed
0.3066,Event,ADDED,eval-conflicts-rho020-r1-068-lhdfq.18d467ad55cc3162,reason=Scheduled count=None msg=Successfully assigned compute/eval-conflicts-rho020-r1-068-lhdfq to kind-worker
0.3068,Event,ADDED,eval-conflicts-rho020-r1-068-lhdfq.18d467ad6f8653b3,"reason=Pulled count=1 msg=Container image ""busybox:musl"" already present on machine"
0.3071,Event,ADDED,eval-conflicts-rho020-r1-068-lhdfq.18d467ad70c0e29a,reason=Created count=1 msg=Created container: task
0.3073,Event,ADDED,eval-conflicts-rho020-r1-068-lhdfq.18d467ad74d28362,reason=Started count=1 msg=Started container task
0.3074,Event,ADDED,eval-conflicts-rho020-r1-068.18d467ad54e20a22,reason=SuccessfulCreate count=1 msg=Created pod: eval-conflicts-rho020-r1-068-lhdfq
0.3076,Event,ADDED,eval-conflicts-rho020-r1-068.18d467b09e39dad2,reason=Completed count=1 msg=Job completed
0.3078,Event,ADDED,eval-conflicts-rho020-r1-069-z2mq8.18d467ad91c126c9,"reason=FailedScheduling count=None msg=0/6 nodes are available: 2 c_wall violated: 1 conflicting context pair(s) with node memory, 4 node(s) had untolerated taint(s). no new claims to deallocate, preemption: 0/6 nodes are available: 2 No preemption victims found for incoming pod, 4 Preemption is not helpful for scheduling."
0.308,Event,ADDED,eval-conflicts-rho020-r1-069-z2mq8.18d467ad92671870,"reason=FailedScheduling count=None msg=0/6 nodes are available: 2 c_wall violated: 1 conflicting context pair(s) with node memory, 4 node(s) had untolerated taint(s). no new claims to deallocate, preemption: 0/6 nodes are available: 2 No preemption victims found for incoming pod, 4 Preemption is not helpful for scheduling."
0.3082,Event,ADDED,eval-conflicts-rho020-r1-069-z2mq8.18d467adce089bdf,"reason=FailedScheduling count=None msg=0/6 nodes are available: 1 c_wall violated: 1 conflicting context pair(s) with node memory, 1 c_wall violated: 2 conflicting context pair(s) with node memory, 4 node(s) had untolerated taint(s). no new claims to deallocate, preemption: 0/6 nodes are available: 2 No preemption victims found for incoming pod, 4 Preemption is not helpful for scheduling."
0.3085,Event,ADDED,eval-conflicts-rho020-r1-069-z2mq8.18d467ae95b65150,"reason=FailedScheduling count=None msg=0/6 nodes are available: 1 c_wall violated: 1 conflicting context pair(s) with node memory, 5 node(s) had untolerated taint(s). no new claims to deallocate, preemption: 0/6 nodes are available: 1 No preemption victims found for incoming pod, 5 Preemption is not helpful for scheduling."
0.3087,Event,ADDED,eval-conflicts-rho020-r1-069-z2mq8.18d467af1338d0bf,reason=Scheduled count=None msg=Successfully assigned compute/eval-conflicts-rho020-r1-069-z2mq8 to kind-worker2
0.3088,Event,ADDED,eval-conflicts-rho020-r1-069-z2mq8.18d467af2cca0818,"reason=Pulled count=1 msg=Container image ""busybox:musl"" already present on machine"
0.3091,Event,ADDED,eval-conflicts-rho020-r1-069-z2mq8.18d467af2e29acb3,reason=Created count=1 msg=Created container: task
0.3093,Event,ADDED,eval-conflicts-rho020-r1-069-z2mq8.18d467af303f37e0,reason=Started count=1 msg=Started container task
0.3094,Event,ADDED,eval-conflicts-rho020-r1-069.18d467ad91581fe5,reason=SuccessfulCreate count=1 msg=Created pod: eval-conflicts-rho020-r1-069-z2mq8
0.3096,Event,ADDED,eval-conflicts-rho020-r1-069.18d467b26ea7a358,reason=Completed count=1 msg=Job completed
0.3097,Event,ADDED,eval-conflicts-rho020-r1-070-wk685.18d467adcc96649a,reason=Scheduled count=None msg=Successfully assigned compute/eval-conflicts-rho020-r1-070-wk685 to kind-worker3
0.3099,Event,ADDED,eval-conflicts-rho020-r1-070-wk685.18d467ade587df11,"reason=Pulled count=1 msg=Container image ""busybox:musl"" already present on machine"
0.3101,Event,ADDED,eval-conflicts-rho020-r1-070-wk685.18d467ade6a4fd34,reason=Created count=1 msg=Created container: task
0.3103,Event,ADDED,eval-conflicts-rho020-r1-070-wk685.18d467ade89bc440,reason=Started count=1 msg=Started container task
0.3104,Event,ADDED,eval-conflicts-rho020-r1-070.18d467adcbf9dcf7,reason=SuccessfulCreate count=1 msg=Created pod: eval-conflicts-rho020-r1-070-wk685
0.3106,Event,ADDED,eval-conflicts-rho020-r1-070.18d467b12a85db4a,reason=Completed count=1 msg=Job completed
0.3107,Event,ADDED,eval-conflicts-rho020-r1-071-bztnn.18d467ae084139e8,reason=Scheduled count=None msg=Successfully assigned compute/eval-conflicts-rho020-r1-071-bztnn to kind-worker3
0.3109,Event,ADDED,eval-conflicts-rho020-r1-071-bztnn.18d467ae20ce1b00,"reason=Pulled count=1 msg=Container image ""busybox:musl"" already present on machine"
0.3116,Event,ADDED,eval-conflicts-rho020-r1-071-bztnn.18d467ae21f06c91,reason=Created count=1 msg=Created container: task
0.3119,Event,ADDED,eval-conflicts-rho020-r1-071-bztnn.18d467ae2682c63c,reason=Started count=1 msg=Started container task
0.3121,Event,ADDED,eval-conflicts-rho020-r1-071.18d467ae078d6e8b,reason=SuccessfulCreate count=1 msg=Created pod: eval-conflicts-rho020-r1-071-bztnn
0.3123,Event,ADDED,eval-conflicts-rho020-r1-071.18d467b16622214d,reason=Completed count=1 msg=Job completed
0.3128,Event,ADDED,eval-conflicts-rho020-r1-072-ffspt.18d467ae43cd7a75,reason=Scheduled count=None msg=Successfully assigned compute/eval-conflicts-rho020-r1-072-ffspt to kind-worker3
0.313,Event,ADDED,eval-conflicts-rho020-r1-072-ffspt.18d467ae5d931c10,"reason=Pulled count=1 msg=Container image ""busybox:musl"" already present on machine"
0.3132,Event,ADDED,eval-conflicts-rho020-r1-072-ffspt.18d467ae5eb6ada5,reason=Created count=1 msg=Created container: task
0.3135,Event,ADDED,eval-conflicts-rho020-r1-072-ffspt.18d467ae68b26380,reason=Started count=1 msg=Started container task
0.3138,Event,ADDED,eval-conflicts-rho020-r1-072.18d467ae431a59f7,reason=SuccessfulCreate count=1 msg=Created pod: eval-conflicts-rho020-r1-072-ffspt
0.314,Event,ADDED,eval-conflicts-rho020-r1-072.18d467b1a13f35c6,reason=Completed count=1 msg=Job completed
0.3141,Event,ADDED,eval-conflicts-rho020-r1-073-vb7sf.18d467ae80bc2839,reason=Scheduled count=None msg=Successfully assigned compute/eval-conflicts-rho020-r1-073-vb7sf to kind-worker
0.3144,Event,ADDED,eval-conflicts-rho020-r1-073-vb7sf.18d467ae9962bc87,"reason=Pulled count=1 msg=Container image ""busybox:musl"" already present on machine"
0.3146,Event,ADDED,eval-conflicts-rho020-r1-073-vb7sf.18d467ae9ab551f4,reason=Created count=1 msg=Created container: task
0.3148,Event,ADDED,eval-conflicts-rho020-r1-073-vb7sf.18d467ae9caa68b3,reason=Started count=1 msg=Started container task
0.315,Event,ADDED,eval-conflicts-rho020-r1-073.18d467ae7f82f2b6,reason=SuccessfulCreate count=1 msg=Created pod: eval-conflicts-rho020-r1-073-vb7sf
0.3153,Event,ADDED,eval-conflicts-rho020-r1-073.18d467b1c836e039,reason=Completed count=1 msg=Job completed
0.3154,Event,ADDED,eval-conflicts-rho020-r1-074-hp58n.18d467aebab77489,reason=Scheduled count=None msg=Successfully assigned compute/eval-conflicts-rho020-r1-074-hp58n to kind-worker
0.3156,Event,ADDED,eval-conflicts-rho020-r1-074-hp58n.18d467aed39c7380,"reason=Pulled count=1 msg=Container image ""busybox:musl"" already present on machine"
0.3159,Event,ADDED,eval-conflicts-rho020-r1-074-hp58n.18d467aed4a5dc30,reason=Created count=1 msg=Created container: task
0.3161,Event,ADDED,eval-conflicts-rho020-r1-074-hp58n.18d467aed67fe9f7,reason=Started count=1 msg=Started container task
0.3163,Event,ADDED,eval-conflicts-rho020-r1-074.18d467aeba32a30b,reason=SuccessfulCreate count=1 msg=Created pod: eval-conflicts-rho020-r1-074-hp58n
0.3164,Event,ADDED,eval-conflicts-rho020-r1-074.18d467b203f79084,reason=Completed count=1 msg=Job completed
0.3168,Event,ADDED,eval-conflicts-rho020-r1-075-8bm2l.18d467aef593ca75,"reason=FailedScheduling count=None msg=0/6 nodes are available: 6 node(s) had untolerated taint(s). no new claims to deallocate, preemption: 0/6 nodes are available: 6 Preemption is not helpful for scheduling."
0.317,Event,ADDED,eval-conflicts-rho020-r1-075-8bm2l.18d467af136ab41a,reason=Scheduled count=None msg=Successfully assigned compute/eval-conflicts-rho020-r1-075-8bm2l to kind-worker2
0.3172,Event,ADDED,eval-conflicts-rho020-r1-075-8bm2l.18d467af2cdf311c,"reason=Pulled count=1 msg=Container image ""busybox:musl"" already present on machine"
0.3173,Event,ADDED,eval-conflicts-rho020-r1-075-8bm2l.18d467af2e76fb34,reason=Created count=1 msg=Created container: task
0.3176,Event,ADDED,eval-conflicts-rho020-r1-075-8bm2l.18d467af307e9e33,reason=Started count=1 msg=Started container task
0.3177,Event,ADDED,eval-conflicts-rho020-r1-075.18d467aef587a3b9,reason=SuccessfulCreate count=1 msg=Created pod: eval-conflicts-rho020-r1-075-8bm2l
0.3179,Event,ADDED,eval-conflicts-rho020-r1-075.18d467b26e7e05f8,reason=Completed count=1 msg=Job completed
0.3181,Event,ADDED,eval-conflicts-rho020-r1-076-2xxgk.18d467af31a16f21,reason=Scheduled count=None msg=Successfully assigned compute/eval-conflicts-rho020-r1-076-2xxgk to kind-worker4
0.3183,Event,ADDED,eval-conflicts-rho020-r1-076-2xxgk.18d467af4bc37bc8,"reason=Pulled count=1 msg=Container image ""busybox:musl"" already present on machine"
0.3185,Event,ADDED,eval-conflicts-rho020-r1-076-2xxgk.18d467af4cef1ffb,reason=Created count=1 msg=Created container: task
0.3186,Event,ADDED,eval-conflicts-rho020-r1-076-2xxgk.18d467af50625391,reason=Started count=1 msg=Started container task
0.3189,Event,ADDED,eval-conflicts-rho020-r1-076.18d467af3126cd0f,reason=SuccessfulCreate count=1 msg=Created pod: eval-conflicts-rho020-r1-076-2xxgk
0.319,Event,ADDED,eval-conflicts-rho020-r1-076.18d467b281d5999d,reason=Completed count=1 msg=Job completed
0.3192,Event,ADDED,eval-conflicts-rho020-r1-077-msx6f.18d467af6e31e6fb,reason=Scheduled count=None msg=Successfully assigned compute/eval-conflicts-rho020-r1-077-msx6f to kind-worker5
0.3193,Event,ADDED,eval-conflicts-rho020-r1-077-msx6f.18d467af883d53df,"reason=Pulled count=1 msg=Container image ""busybox:musl"" already present on machine"
0.3195,Event,ADDED,eval-conflicts-rho020-r1-077-msx6f.18d467af89801a30,reason=Created count=1 msg=Created container: task
0.3197,Event,ADDED,eval-conflicts-rho020-r1-077-msx6f.18d467af8db5e7e1,reason=Started count=1 msg=Started container task
0.3198,Event,ADDED,eval-conflicts-rho020-r1-077.18d467af6d2e9125,reason=SuccessfulCreate count=1 msg=Created pod: eval-conflicts-rho020-r1-077-msx6f
0.3202,Event,ADDED,eval-conflicts-rho020-r1-077.18d467b2bb3976d4,reason=Completed count=1 msg=Job completed
0.3203,Event,ADDED,eval-conflicts-rho020-r1-078-qlcvl.18d467afaa325687,reason=Scheduled count=None msg=Successfully assigned compute/eval-conflicts-rho020-r1-078-qlcvl to kind-worker5
0.3205,Event,ADDED,eval-conflicts-rho020-r1-078-qlcvl.18d467afc47728b9,"reason=Pulled count=1 msg=Container image ""busybox:musl"" already present on machine"
0.3207,Event,ADDED,eval-conflicts-rho020-r1-078-qlcvl.18d467afc5c8513c,reason=Created count=1 msg=Created container: task
0.321,Event,ADDED,eval-conflicts-rho020-r1-078-qlcvl.18d467afc9e09705,reason=Started count=1 msg=Started container task
0.3212,Event,ADDED,eval-conflicts-rho020-r1-078.18d467afa8e5ae76,reason=SuccessfulCreate count=1 msg=Created pod: eval-conflicts-rho020-r1-078-qlcvl
0.3214,Event,ADDED,eval-conflicts-rho020-r1-078.18d467b2f727d123,reason=Completed count=1 msg=Job completed
0.3217,Event,ADDED,eval-conflicts-rho020-r1-079-wnjmx.18d467afe569fa1a,reason=Scheduled count=None msg=Successfully assigned compute/eval-conflicts-rho020-r1-079-wnjmx to kind-worker5
0.3218,Event,ADDED,eval-conflicts-rho020-r1-079-wnjmx.18d467affdf6e572,"reason=Pulled count=1 msg=Container image ""busybox:musl"" already present on machine"
0.3221,Event,ADDED,eval-conflicts-rho020-r1-079-wnjmx.18d467afff12924f,reason=Created count=1 msg=Created container: task
0.3223,Event,ADDED,eval-conflicts-rho020-r1-079-wnjmx.18d467b00105663a,reason=Started count=1 msg=Started container task
0.3226,Event,ADDED,eval-conflicts-rho020-r1-079.18d467afe3f7c254,reason=SuccessfulCreate count=1 msg=Created pod: eval-conflicts-rho020-r1-079-wnjmx
0.3228,Event,ADDED,eval-conflicts-rho020-r1-079.18d467b333b42fb5,reason=Completed count=1 msg=Job completed
0.3229,Event,ADDED,eval-conflicts-rho020-r1-080-qfncq.18d467b020ca5633,reason=Scheduled count=None msg=Successfully assigned compute/eval-conflicts-rho020-r1-080-qfncq to kind-worker2
0.3231,Event,ADDED,eval-conflicts-rho020-r1-080-qfncq.18d467b03ae029c5,"reason=Pulled count=1 msg=Container image ""busybox:musl"" already present on machine"
0.3234,Event,ADDED,eval-conflicts-rho020-r1-080-qfncq.18d467b03bf4d4d3,reason=Created count=1 msg=Created container: task
0.3236,Event,ADDED,eval-conflicts-rho020-r1-080-qfncq.18d467b03dee0cdf,reason=Started count=1 msg=Started container task
0.3237,Event,ADDED,eval-conflicts-rho020-r1-080.18d467b01f8b28ce,reason=SuccessfulCreate count=1 msg=Created pod: eval-conflicts-rho020-r1-080-qfncq
0.3239,Event,ADDED,eval-conflicts-rho020-r1-080.18d467b35dee75ea,reason=Completed count=1 msg=Job completed
0.3241,Event,ADDED,eval-conflicts-rho020-r1-081-5zsgr.18d467b05ca02760,reason=Scheduled count=None msg=Successfully assigned compute/eval-conflicts-rho020-r1-081-5zsgr to kind-worker5
0.3242,Event,ADDED,eval-conflicts-rho020-r1-081-5zsgr.18d467b0761644d7,"reason=Pulled count=1 msg=Container image ""busybox:musl"" already present on machine"
0.3246,Event,ADDED,eval-conflicts-rho020-r1-081-5zsgr.18d467b07728e89c,reason=Created count=1 msg=Created container: task
0.3248,Event,ADDED,eval-conflicts-rho020-r1-081-5zsgr.18d467b0797acd74,reason=Started count=1 msg=Started container task
0.3249,Event,ADDED,eval-conflicts-rho020-r1-081.18d467b05b85ccda,reason=SuccessfulCreate count=1 msg=Created pod: eval-conflicts-rho020-r1-081-5zsgr
0.3251,Event,ADDED,eval-conflicts-rho020-r1-081.18d467b3aae00cab,reason=Completed count=1 msg=Job completed
0.3253,Event,ADDED,eval-conflicts-rho020-r1-082-kw79d.18d467b099471d1e,reason=Scheduled count=None msg=Successfully assigned compute/eval-conflicts-rho020-r1-082-kw79d to kind-worker4
0.3254,Event,ADDED,eval-conflicts-rho020-r1-082-kw79d.18d467b0b207b926,"reason=Pulled count=1 msg=Container image ""busybox:musl"" already present on machine"
0.3256,Event,ADDED,eval-conflicts-rho020-r1-082-kw79d.18d467b0b344fd0e,reason=Created count=1 msg=Created container: task
0.3258,Event,ADDED,eval-conflicts-rho020-r1-082-kw79d.18d467b0b666ff8f,reason=Started count=1 msg=Started container task
0.3259,Event,ADDED,eval-conflicts-rho020-r1-082.18d467b0984e9af9,reason=SuccessfulCreate count=1 msg=Created pod: eval-conflicts-rho020-r1-082-kw79d
0.3261,Event,ADDED,eval-conflicts-rho020-r1-082.18d467b3e81a796d,reason=Completed count=1 msg=Job completed
0.3264,Event,ADDED,eval-conflicts-rho020-r1-083-6lp5h.18d467b0d3851829,reason=Scheduled count=None msg=Successfully assigned compute/eval-conflicts-rho020-r1-083-6lp5h to kind-worker2
0.3265,Event,ADDED,eval-conflicts-rho020-r1-083-6lp5h.18d467b0ed0c1b6a,"reason=Pulled count=1 msg=Container image ""busybox:musl"" already present on machine"
0.3268,Event,ADDED,eval-conflicts-rho020-r1-083-6lp5h.18d467b0ee7b9063,reason=Created count=1 msg=Created container: task
0.327,Event,ADDED,eval-conflicts-rho020-r1-083-6lp5h.18d467b0f26f4b08,reason=Started count=1 msg=Started container task
0.3271,Event,ADDED,eval-conflicts-rho020-r1-083.18d467b0d26eb1d8,reason=SuccessfulCreate count=1 msg=Created pod: eval-conflicts-rho020-r1-083-6lp5h
0.3273,Event,ADDED,eval-conflicts-rho020-r1-083.18d467b410f4d05e,reason=Completed count=1 msg=Job completed
0.3275,Event,ADDED,eval-conflicts-rho020-r1-084-fzdhn.18d467b10ef5db33,"reason=FailedScheduling count=None msg=0/6 nodes are available: 3 c_wall violated: 1 conflicting context pair(s) with node memory, 3 node(s) had untolerated taint(s). no new claims to deallocate, preemption: 0/6 nodes are available: 3 No preemption victims found for incoming pod, 3 Preemption is not helpful for scheduling."
0.3277,Event,ADDED,eval-conflicts-rho020-r1-084-fzdhn.18d467b113b14efa,"reason=FailedScheduling count=None msg=0/6 nodes are available: 3 c_wall violated: 1 conflicting context pair(s) with node memory, 3 node(s) had untolerated taint(s). no new claims to deallocate, preemption: 0/6 nodes are available: 3 No preemption victims found for incoming pod, 3 Preemption is not helpful for scheduling."
0.3279,Event,ADDED,eval-conflicts-rho020-r1-084-fzdhn.18d467b16ccda504,"reason=FailedScheduling count=None msg=0/6 nodes are available: 2 c_wall violated: 1 conflicting context pair(s) with node memory, 4 node(s) had untolerated taint(s). no new claims to deallocate, preemption: 0/6 nodes are available: 2 No preemption victims found for incoming pod, 4 Preemption is not helpful for scheduling."
0.328,Event,ADDED,eval-conflicts-rho020-r1-084-fzdhn.18d467b18bad6300,"reason=FailedScheduling count=None msg=0/6 nodes are available: 1 c_wall violated: 1 conflicting context pair(s) with node memory, 5 node(s) had untolerated taint(s). no new claims to deallocate, preemption: 0/6 nodes are available: 1 No preemption victims found for incoming pod, 5 Preemption is not helpful for scheduling."
0.3282,Event,ADDED,eval-conflicts-rho020-r1-084-fzdhn.18d467b35b0d78c4,reason=Scheduled count=None msg=Successfully assigned compute/eval-conflicts-rho020-r1-084-fzdhn to kind-worker3
0.3284,Event,ADDED,eval-conflicts-rho020-r1-084-fzdhn.18d467b37511b975,"reason=Pulled count=1 msg=Container image ""busybox:musl"" already present on machine"
0.3286,Event,ADDED,eval-conflicts-rho020-r1-084-fzdhn.18d467b377e92532,reason=Created count=1 msg=Created container: task
0.3287,Event,ADDED,eval-conflicts-rho020-r1-084-fzdhn.18d467b37bc3914d,reason=Started count=1 msg=Started container task
0.3289,Event,ADDED,eval-conflicts-rho020-r1-084.18d467b10e32d7af,reason=SuccessfulCreate count=1 msg=Created pod: eval-conflicts-rho020-r1-084-fzdhn
0.3291,Event,ADDED,eval-conflicts-rho020-r1-084.18d467b689473afc,reason=Completed count=1 msg=Job completed
0.3292,Event,ADDED,eval-conflicts-rho020-r1-085-x67xq.18d467b14ad04992,reason=Scheduled count=None msg=Successfully assigned compute/eval-conflicts-rho020-r1-085-x67xq to kind-worker2
0.3294,Event,ADDED,eval-conflicts-rho020-r1-085-x67xq.18d467b16424dc7f,"reason=Pulled count=1 msg=Container image ""busybox:musl"" already present on machine"
0.3295,Event,ADDED,eval-conflicts-rho020-r1-085-x67xq.18d467b165410b0c,reason=Created count=1 msg=Created container: task
0.3297,Event,ADDED,eval-conflicts-rho020-r1-085-x67xq.18d467b168e00205,reason=Started count=1 msg=Started container task
0.3299,Event,ADDED,eval-conflicts-rho020-r1-085.18d467b149b847c0,reason=SuccessfulCreate count=1 msg=Created pod: eval-conflicts-rho020-r1-085-x67xq
0.33,Event,ADDED,eval-conflicts-rho020-r1-085.18d467b488ff069e,reason=Completed count=1 msg=Job completed
0.3302,Event,ADDED,eval-conflicts-rho020-r1-086-8p7ff.18d467b18637596f,reason=Scheduled count=None msg=Successfully assigned compute/eval-conflicts-rho020-r1-086-8p7ff to kind-worker4
0.3304,Event,ADDED,eval-conflicts-rho020-r1-086-8p7ff.18d467b19ee3ee88,"reason=Pulled count=1 msg=Container image ""busybox:musl"" already present on machine"
0.3305,Event,ADDED,eval-conflicts-rho020-r1-086-8p7ff.18d467b19fea5808,reason=Created count=1 msg=Created container: task
0.3307,Event,ADDED,eval-conflicts-rho020-r1-086-8p7ff.18d467b1a21c8e50,reason=Started count=1 msg=Started container task
0.3309,Event,ADDED,eval-conflicts-rho020-r1-086.18d467b185280e61,reason=SuccessfulCreate count=1 msg=Created pod: eval-conflicts-rho020-r1-086-8p7ff
0.331,Event,ADDED,eval-conflicts-rho020-r1-086.18d467b4d724f8c1,reason=Completed count=1 msg=Job completed
0.3312,Event,ADDED,eval-conflicts-rho020-r1-087-htw7n.18d467b1c0b7ad85,"reason=FailedScheduling count=None msg=0/6 nodes are available: 6 node(s) had untolerated taint(s). no new claims to deallocate, preemption: 0/6 nodes are available: 6 Preemption is not helpful for scheduling."
0.3313,Event,ADDED,eval-conflicts-rho020-r1-087-htw7n.18d467b35b96fe3d,reason=Scheduled count=None msg=Successfully assigned compute/eval-conflicts-rho020-r1-087-htw7n to kind-worker3
0.3315,Event,ADDED,eval-conflicts-rho020-r1-087-htw7n.18d467b375bb971c,"reason=Pulled count=1 msg=Container image ""busybox:musl"" already present on machine"
0.3317,Event,ADDED,eval-conflicts-rho020-r1-087-htw7n.18d467b3796f85c7,reason=Created count=1 msg=Created container: task
0.3319,Event,ADDED,eval-conflicts-rho020-r1-087-htw7n.18d467b37c79cee4,reason=Started count=1 msg=Started container task
0.3321,Event,ADDED,eval-conflicts-rho020-r1-087.18d467b1c0afb7fa,reason=SuccessfulCreate count=1 msg=Created pod: eval-conflicts-rho020-r1-087-htw7n
0.3322,Event,ADDED,eval-conflicts-rho020-r1-087.18d467b6890b14c4,reason=Completed count=1 msg=Job completed
0.3324,Event,ADDED,eval-conflicts-rho020-r1-088-br5xx.18d467b1fc82cb92,"reason=FailedScheduling count=None msg=0/6 nodes are available: 6 node(s) had untolerated taint(s). no new claims to deallocate, preemption: 0/6 nodes are available: 6 Preemption is not helpful for scheduling."
0.3325,Event,ADDED,eval-conflicts-rho020-r1-088-br5xx.18d467b35bf5bd43,reason=Scheduled count=None msg=Successfully assigned compute/eval-conflicts-rho020-r1-088-br5xx to kind-worker3
0.3327,Event,ADDED,eval-conflicts-rho020-r1-088-br5xx.18d467b375d771a2,"reason=Pulled count=1 msg=Container image ""busybox:musl"" already present on machine"
0.3329,Event,ADDED,eval-conflicts-rho020-r1-088-br5xx.18d467b379948be8,reason=Created count=1 msg=Created container: task
0.333,Event,ADDED,eval-conflicts-rho020-r1-088-br5xx.18d467b37c77ac51,reason=Started count=1 msg=Started container task
0.3335,Event,ADDED,eval-conflicts-rho020-r1-088.18d467b1fc74940b,reason=SuccessfulCreate count=1 msg=Created pod: eval-conflicts-rho020-r1-088-br5xx
0.3337,Event,ADDED,eval-conflicts-rho020-r1-088.18d467b689ab2ccf,reason=Completed count=1 msg=Job completed
0.334,Event,ADDED,eval-conflicts-rho020-r1-089-p6p5w.18d467b2380db67f,"reason=FailedScheduling count=None msg=0/6 nodes are available: 6 node(s) had untolerated taint(s). no new claims to deallocate, preemption: 0/6 nodes are available: 6 Preemption is not helpful for scheduling."
0.3343,Event,ADDED,eval-conflicts-rho020-r1-089-p6p5w.18d467b35bae81e7,"reason=FailedScheduling count=None msg=0/6 nodes are available: 1 c_wall violated: 2 conflicting context pair(s) with node memory, 5 node(s) had untolerated taint(s). no new claims to deallocate, preemption: 0/6 nodes are available: 1 No preemption victims found for incoming pod, 5 Preemption is not helpful for scheduling."
0.335,Event,ADDED,eval-conflicts-rho020-r1-089-p6p5w.18d467b361630ae7,"reason=FailedScheduling count=None msg=0/6 nodes are available: 1 c_wall violated: 2 conflicting context pair(s) with node memory, 5 node(s) had untolerated taint(s). no new claims to deallocate, preemption: 0/6 nodes are available: 1 No preemption victims found for incoming pod, 5 Preemption is not helpful for scheduling."
0.3353,Event,ADDED,eval-conflicts-rho020-r1-089-p6p5w.18d467b3baabc939,reason=Scheduled count=None msg=Successfully assigned compute/eval-conflicts-rho020-r1-089-p6p5w to kind-worker
0.3356,Event,ADDED,eval-conflicts-rho020-r1-089-p6p5w.18d467b3d490760c,"reason=Pulled count=1 msg=Container image ""busybox:musl"" already present on machine"
0.3359,Event,ADDED,eval-conflicts-rho020-r1-089-p6p5w.18d467b3d6357db6,reason=Created count=1 msg=Created container: task
0.3361,Event,ADDED,eval-conflicts-rho020-r1-089-p6p5w.18d467b3d98bc283,reason=Started count=1 msg=Started container task
0.3363,Event,ADDED,eval-conflicts-rho020-r1-089.18d467b23801e1e5,reason=SuccessfulCreate count=1 msg=Created pod: eval-conflicts-rho020-r1-089-p6p5w
0.3365,Event,ADDED,eval-conflicts-rho020-r1-089.18d467b6ec104fd3,reason=Completed count=1 msg=Job completed
0.3368,Event,ADDED,eval-conflicts-rho020-r1-090-d6z4j.18d467b2739bc33a,"reason=FailedScheduling count=None msg=0/6 nodes are available: 6 node(s) had untolerated taint(s). no new claims to deallocate, preemption: 0/6 nodes are available: 6 Preemption is not helpful for scheduling."
0.337,Event,ADDED,eval-conflicts-rho020-r1-090-d6z4j.18d467b35c51af2f,"reason=FailedScheduling count=None msg=0/6 nodes are available: 1 c_wall violated: 2 conflicting context pair(s) with node memory, 5 node(s) had untolerated taint(s). no new claims to deallocate, preemption: 0/6 nodes are available: 1 No preemption victims found for incoming pod, 5 Preemption is not helpful for scheduling."
0.3372,Event,ADDED,eval-conflicts-rho020-r1-090-d6z4j.18d467b36194d1aa,"reason=FailedScheduling count=None msg=0/6 nodes are available: 1 c_wall violated: 2 conflicting context pair(s) with node memory, 5 node(s) had untolerated taint(s). no new claims to deallocate, preemption: 0/6 nodes are available: 1 No preemption victims found for incoming pod, 5 Preemption is not helpful for scheduling."
0.3374,Event,ADDED,eval-conflicts-rho020-r1-090-d6z4j.18d467b3ba098690,reason=Scheduled count=None msg=Successfully assigned compute/eval-conflicts-rho020-r1-090-d6z4j to kind-worker
0.3375,Event,ADDED,eval-conflicts-rho020-r1-090-d6z4j.18d467b3d376101f,"reason=Pulled count=1 msg=Container image ""busybox:musl"" already present on machine"
0.3378,Event,ADDED,eval-conflicts-rho020-r1-090-d6z4j.18d467b3d55bceb5,reason=Created count=1 msg=Created container: task
0.3383,Event,ADDED,eval-conflicts-rho020-r1-090-d6z4j.18d467b3d8c148d6,reason=Started count=1 msg=Started container task
0.3386,Event,ADDED,eval-conflicts-rho020-r1-090.18d467b27394eaa5,reason=SuccessfulCreate count=1 msg=Created pod: eval-conflicts-rho020-r1-090-d6z4j
0.3389,Event,ADDED,eval-conflicts-rho020-r1-090.18d467b6ec564235,reason=Completed count=1 msg=Job completed
0.3391,Event,ADDED,eval-conflicts-rho020-r1-091-gccvp.18d467b2b00b0151,"reason=FailedScheduling count=None msg=0/6 nodes are available: 6 node(s) had untolerated taint(s). no new claims to deallocate, preemption: 0/6 nodes are available: 6 Preemption is not helpful for scheduling."
0.3395,Event,ADDED,eval-conflicts-rho020-r1-091-gccvp.18d467b35eb61757,reason=Scheduled count=None msg=Successfully assigned compute/eval-conflicts-rho020-r1-091-gccvp to kind-worker3
0.3397,Event,ADDED,eval-conflicts-rho020-r1-091-gccvp.18d467b378c17995,"reason=Pulled count=1 msg=Container image ""busybox:musl"" already present on machine"
0.3399,Event,ADDED,eval-conflicts-rho020-r1-091-gccvp.18d467b37a53f23b,reason=Created count=1 msg=Created container: task
0.3401,Event,ADDED,eval-conflicts-rho020-r1-091-gccvp.18d467b37dc61e1a,reason=Started count=1 msg=Started container task
0.3403,Event,ADDED,eval-conflicts-rho020-r1-091.18d467b2b0062d45,reason=SuccessfulCreate count=1 msg=Created pod: eval-conflicts-rho020-r1-091-gccvp
0.3404,Event,ADDED,eval-conflicts-rho020-r1-091.18d467b6c63cd8ca,reason=Completed count=1 msg=Job completed
0.3406,Event,ADDED,eval-conflicts-rho020-r1-092-wksgh.18d467b2eb6fca6a,"reason=FailedScheduling count=None msg=0/6 nodes are available: 6 node(s) had untolerated taint(s). no new claims to deallocate, preemption: 0/6 nodes are available: 6 Preemption is not helpful for scheduling."
0.3408,Event,ADDED,eval-conflicts-rho020-r1-092-wksgh.18d467b361511f49,reason=Scheduled count=None msg=Successfully assigned compute/eval-conflicts-rho020-r1-092-wksgh to kind-worker3
0.3409,Event,ADDED,eval-conflicts-rho020-r1-092-wksgh.18d467b37de9c561,"reason=Pulled count=1 msg=Container image ""busybox:musl"" already present on machine"
0.3411,Event,ADDED,eval-conflicts-rho020-r1-092-wksgh.18d467b37fcdccf2,reason=Created count=1 msg=Created container: task
0.3413,Event,ADDED,eval-conflicts-rho020-r1-092-wksgh.18d467b384313ec2,reason=Started count=1 msg=Started container task
0.3414,Event,ADDED,eval-conflicts-rho020-r1-092.18d467b2eb6998d8,reason=SuccessfulCreate count=1 msg=Created pod: eval-conflicts-rho020-r1-092-wksgh
0.3416,Event,ADDED,eval-conflicts-rho020-r1-092.18d467b6c5b450a5,reason=Completed count=1 msg=Job completed
0.3418,Event,ADDED,eval-conflicts-rho020-r1-093-rwkwt.18d467b3270590ab,"reason=FailedScheduling count=None msg=0/6 nodes are available: 6 node(s) had untolerated taint(s). no new claims to deallocate, preemption: 0/6 nodes are available: 6 Preemption is not helpful for scheduling."
0.3419,Event,ADDED,eval-conflicts-rho020-r1-093-rwkwt.18d467b36188805d,reason=Scheduled count=None msg=Successfully assigned compute/eval-conflicts-rho020-r1-093-rwkwt to kind-worker3
0.3421,Event,ADDED,eval-conflicts-rho020-r1-093-rwkwt.18d467b37dca22b7,"reason=Pulled count=1 msg=Container image ""busybox:musl"" already present on machine"
0.3423,Event,ADDED,eval-conflicts-rho020-r1-093-rwkwt.18d467b37f5b53ea,reason=Created count=1 msg=Created container: task
0.3424,Event,ADDED,eval-conflicts-rho020-r1-093-rwkwt.18d467b383fb28bd,reason=Started count=1 msg=Started container task
0.3426,Event,ADDED,eval-conflicts-rho020-r1-093.18d467b326fa33f2,reason=SuccessfulCreate count=1 msg=Created pod: eval-conflicts-rho020-r1-093-rwkwt
0.3428,Event,ADDED,eval-conflicts-rho020-r1-093.18d467b6c4ef4f13,reason=Completed count=1 msg=Job completed
0.3429,Event,ADDED,eval-conflicts-rho020-r1-094-vr42b.18d467b3670eb4d6,"reason=FailedScheduling count=None msg=0/6 nodes are available: 1 c_wall violated: 2 conflicting context pair(s) with node memory, 5 node(s) had untolerated taint(s). no new claims to deallocate, preemption: 0/6 nodes are available: 1 No preemption victims found for incoming pod, 5 Preemption is not helpful for scheduling."
0.3432,Event,ADDED,eval-conflicts-rho020-r1-094-vr42b.18d467b36a92b4de,"reason=FailedScheduling count=None msg=0/6 nodes are available: 1 c_wall violated: 2 conflicting context pair(s) with node memory, 5 node(s) had untolerated taint(s). no new claims to deallocate, preemption: 0/6 nodes are available: 1 No preemption victims found for incoming pod, 5 Preemption is not helpful for scheduling."
0.3434,Event,ADDED,eval-conflicts-rho020-r1-094-vr42b.18d467b3bb6595be,reason=Scheduled count=None msg=Successfully assigned compute/eval-conflicts-rho020-r1-094-vr42b to kind-worker
0.3437,Event,ADDED,eval-conflicts-rho020-r1-094-vr42b.18d467b3d4becde2,"reason=Pulled count=1 msg=Container image ""busybox:musl"" already present on machine"
0.3439,Event,ADDED,eval-conflicts-rho020-r1-094-vr42b.18d467b3d6895375,reason=Created count=1 msg=Created container: task
0.3443,Event,ADDED,eval-conflicts-rho020-r1-094-vr42b.18d467b3d9895f63,reason=Started count=1 msg=Started container task
0.3445,Event,ADDED,eval-conflicts-rho020-r1-094.18d467b362631c06,reason=SuccessfulCreate count=1 msg=Created pod: eval-conflicts-rho020-r1-094-vr42b
0.3447,Event,ADDED,eval-conflicts-rho020-r1-094.18d467b7282ea44e,reason=Completed count=1 msg=Job completed
0.3449,Event,ADDED,eval-conflicts-rho020-r1-095-gfvdp.18d467b39e77108f,reason=Scheduled count=None msg=Successfully assigned compute/eval-conflicts-rho020-r1-095-gfvdp to kind-worker3
0.3451,Event,ADDED,eval-conflicts-rho020-r1-095-gfvdp.18d467b3b8a4d2e4,"reason=Pulled count=1 msg=Container image ""busybox:musl"" already present on machine"
0.3453,Event,ADDED,eval-conflicts-rho020-r1-095-gfvdp.18d467b3b9ceeb43,reason=Created count=1 msg=Created container: task
0.3454,Event,ADDED,eval-conflicts-rho020-r1-095-gfvdp.18d467b3bd3311e7,reason=Started count=1 msg=Started container task
0.346,Event,ADDED,eval-conflicts-rho020-r1-095.18d467b39ddaca3d,reason=SuccessfulCreate count=1 msg=Created pod: eval-conflicts-rho020-r1-095-gfvdp
0.3464,Event,ADDED,eval-conflicts-rho020-r1-095.18d467b701007982,reason=Completed count=1 msg=Job completed
0.3467,Event,ADDED,eval-conflicts-rho020-r1-096-9cqfh.18d467b3daed1d02,reason=Scheduled count=None msg=Successfully assigned compute/eval-conflicts-rho020-r1-096-9cqfh to kind-worker
0.3474,Event,ADDED,eval-conflicts-rho020-r1-096-9cqfh.18d467b3f494f8d0,"reason=Pulled count=1 msg=Container image ""busybox:musl"" already present on machine"
0.3475,Event,ADDED,eval-conflicts-rho020-r1-096-9cqfh.18d467b3f5a32582,reason=Created count=1 msg=Created container: task
0.3477,Event,ADDED,eval-conflicts-rho020-r1-096-9cqfh.18d467b3f9937b43,reason=Started count=1 msg=Started container task
0.3479,Event,ADDED,eval-conflicts-rho020-r1-096.18d467b3d9af2dc5,reason=SuccessfulCreate count=1 msg=Created pod: eval-conflicts-rho020-r1-096-9cqfh
0.3481,Event,ADDED,eval-conflicts-rho020-r1-096.18d467b72858eb5d,reason=Completed count=1 msg=Job completed
0.3483,Event,ADDED,eval-conflicts-rho020-r1-097-pzznq.18d467b415e1d738,reason=Scheduled count=None msg=Successfully assigned compute/eval-conflicts-rho020-r1-097-pzznq to kind-worker5
0.3484,Event,ADDED,eval-conflicts-rho020-r1-097-pzznq.18d467b42f66de5a,"reason=Pulled count=1 msg=Container image ""busybox:musl"" already present on machine"
0.3486,Event,ADDED,eval-conflicts-rho020-r1-097-pzznq.18d467b4307cba1a,reason=Created count=1 msg=Created container: task
0.3488,Event,ADDED,eval-conflicts-rho020-r1-097-pzznq.18d467b43277c4ab,reason=Started count=1 msg=Started container task
0.3489,Event,ADDED,eval-conflicts-rho020-r1-097.18d467b414cdfcb7,reason=SuccessfulCreate count=1 msg=Created pod: eval-conflicts-rho020-r1-097-pzznq
0.3491,Event,ADDED,eval-conflicts-rho020-r1-097.18d467b72bede5ce,reason=Completed count=1 msg=Job completed
0.3493,Event,ADDED,eval-conflicts-rho020-r1-098-89x9m.18d467b451bb8eff,reason=Scheduled count=None msg=Successfully assigned compute/eval-conflicts-rho020-r1-098-89x9m to kind-worker5
0.3494,Event,ADDED,eval-conflicts-rho020-r1-098-89x9m.18d467b46b14863a,"reason=Pulled count=1 msg=Container image ""busybox:musl"" already present on machine"
0.3496,Event,ADDED,eval-conflicts-rho020-r1-098-89x9m.18d467b46c3dd979,reason=Created count=1 msg=Created container: task
0.3498,Event,ADDED,eval-conflicts-rho020-r1-098-89x9m.18d467b46ffd3df5,reason=Started count=1 msg=Started container task
0.3499,Event,ADDED,eval-conflicts-rho020-r1-098.18d467b450980c57,reason=SuccessfulCreate count=1 msg=Created pod: eval-conflicts-rho020-r1-098-89x9m
0.3501,Event,ADDED,eval-conflicts-rho020-r1-098.18d467b7a3785f32,reason=Completed count=1 msg=Job completed
0.3502,Event,ADDED,eval-conflicts-rho020-r1-099-5pvws.18d467b48d252912,reason=Scheduled count=None msg=Successfully assigned compute/eval-conflicts-rho020-r1-099-5pvws to kind-worker5
0.3504,Event,ADDED,eval-conflicts-rho020-r1-099-5pvws.18d467b4a63ef820,"reason=Pulled count=1 msg=Container image ""busybox:musl"" already present on machine"
0.3506,Event,ADDED,eval-conflicts-rho020-r1-099-5pvws.18d467b4a753b1b5,reason=Created count=1 msg=Created container: task
0.3507,Event,ADDED,eval-conflicts-rho020-r1-099-5pvws.18d467b4a93ecc8c,reason=Started count=1 msg=Started container task
0.3509,Event,ADDED,eval-conflicts-rho020-r1-099.18d467b48c0bb568,reason=SuccessfulCreate count=1 msg=Created pod: eval-conflicts-rho020-r1-099-5pvws
0.3511,Event,ADDED,eval-conflicts-rho020-r1-099.18d467b7df9031cc,reason=Completed count=1 msg=Job completed
0.3512,Event,ADDED,eval-conflicts-rho020-r2-000-mmvw9.18d467bd116bd9dd,reason=Scheduled count=None msg=Successfully assigned compute/eval-conflicts-rho020-r2-000-mmvw9 to kind-worker5
0.3514,Event,ADDED,eval-conflicts-rho020-r2-000-mmvw9.18d467bd2bbe296b,"reason=Pulled count=1 msg=Container image ""busybox:musl"" already present on machine"
0.3516,Event,ADDED,eval-conflicts-rho020-r2-000-mmvw9.18d467bd2ced4df6,reason=Created count=1 msg=Created container: task
0.3517,Event,ADDED,eval-conflicts-rho020-r2-000-mmvw9.18d467bd30689216,reason=Started count=1 msg=Started container task
0.3519,Event,ADDED,eval-conflicts-rho020-r2-000.18d467bd10522f12,reason=SuccessfulCreate count=1 msg=Created pod: eval-conflicts-rho020-r2-000-mmvw9
0.3521,Event,ADDED,eval-conflicts-rho020-r2-000.18d467c0477b5812,reason=Completed count=1 msg=Job completed
0.3522,Event,ADDED,eval-conflicts-rho020-r2-001-tmc96.18d467bd4c862ca9,reason=Scheduled count=None msg=Successfully assigned compute/eval-conflicts-rho020-r2-001-tmc96 to kind-worker
0.3524,Event,ADDED,eval-conflicts-rho020-r2-001-tmc96.18d467bd66d1efb2,"reason=Pulled count=1 msg=Container image ""busybox:musl"" already present on machine"
0.3526,Event,ADDED,eval-conflicts-rho020-r2-001-tmc96.18d467bd68579919,reason=Created count=1 msg=Created container: task
0.3528,Event,ADDED,eval-conflicts-rho020-r2-001-tmc96.18d467bd6cc410f5,reason=Started count=1 msg=Started container task
0.3529,Event,ADDED,eval-conflicts-rho020-r2-001.18d467bd4bc3de03,reason=SuccessfulCreate count=1 msg=Created pod: eval-conflicts-rho020-r2-001-tmc96
0.3531,Event,ADDED,eval-conflicts-rho020-r2-001.18d467c07de17cb3,reason=Completed count=1 msg=Job completed
0.3532,Event,ADDED,eval-conflicts-rho020-r2-002-hm22d.18d467bd891d63ae,reason=Scheduled count=None msg=Successfully assigned compute/eval-conflicts-rho020-r2-002-hm22d to kind-worker
0.3534,Event,ADDED,eval-conflicts-rho020-r2-002-hm22d.18d467bda43bb8cb,"reason=Pulled count=1 msg=Container image ""busybox:musl"" already present on machine"
0.3536,Event,ADDED,eval-conflicts-rho020-r2-002-hm22d.18d467bda58cd20a,reason=Created count=1 msg=Created container: task
0.3539,Event,ADDED,eval-conflicts-rho020-r2-002-hm22d.18d467bdaa31bcc3,reason=Started count=1 msg=Started container task
0.3541,Event,ADDED,eval-conflicts-rho020-r2-002.18d467bd8853ac90,reason=SuccessfulCreate count=1 msg=Created pod: eval-conflicts-rho020-r2-002-hm22d
0.3543,Event,ADDED,eval-conflicts-rho020-r2-002.18d467c0b9b5d5f7,reason=Completed count=1 msg=Job completed
0.3545,Event,ADDED,eval-conflicts-rho020-r2-003-gg4lk.18d467bdc30cbc21,reason=Scheduled count=None msg=Successfully assigned compute/eval-conflicts-rho020-r2-003-gg4lk to kind-worker2
0.3547,Event,ADDED,eval-conflicts-rho020-r2-003-gg4lk.18d467bddc7534de,"reason=Pulled count=1 msg=Container image ""busybox:musl"" already present on machine"
0.3588,Event,ADDED,eval-conflicts-rho020-r2-003-gg4lk.18d467bddd867d35,reason=Created count=1 msg=Created container: task
0.359,Event,ADDED,eval-conflicts-rho020-r2-003-gg4lk.18d467bde24d7faf,reason=Started count=1 msg=Started container task
0.3592,Event,ADDED,eval-conflicts-rho020-r2-003.18d467bdc246b6e2,reason=SuccessfulCreate count=1 msg=Created pod: eval-conflicts-rho020-r2-003-gg4lk
0.3594,Event,ADDED,eval-conflicts-rho020-r2-003.18d467c123706024,reason=Completed count=1 msg=Job completed
0.3595,Event,ADDED,eval-conflicts-rho020-r2-004-4bjg4.18d467bdfe731b66,reason=Scheduled count=None msg=Successfully assigned compute/eval-conflicts-rho020-r2-004-4bjg4 to kind-worker2
0.3597,Event,ADDED,eval-conflicts-rho020-r2-004-4bjg4.18d467be19cc2653,"reason=Pulled count=1 msg=Container image ""busybox:musl"" already present on machine"
0.3599,Event,ADDED,eval-conflicts-rho020-r2-004-4bjg4.18d467be1b2748d7,reason=Created count=1 msg=Created container: task
0.36,Event,ADDED,eval-conflicts-rho020-r2-004-4bjg4.18d467be208ffec0,reason=Started count=1 msg=Started container task
0.3602,Event,ADDED,eval-conflicts-rho020-r2-004.18d467bdfd6bb699,reason=SuccessfulCreate count=1 msg=Created pod: eval-conflicts-rho020-r2-004-4bjg4
0.3604,Event,ADDED,eval-conflicts-rho020-r2-004.18d467c15f2fa6b5,reason=Completed count=1 msg=Job completed
0.3605,Event,ADDED,eval-conflicts-rho020-r2-005-wnt2m.18d467be3b562364,reason=Scheduled count=None msg=Successfully assigned compute/eval-conflicts-rho020-r2-005-wnt2m to kind-worker4
0.3607,Event,ADDED,eval-conflicts-rho020-r2-005-wnt2m.18d467be576850d0,"reason=Pulled count=1 msg=Container image ""busybox:musl"" already present on machine"
0.3609,Event,ADDED,eval-conflicts-rho020-r2-005-wnt2m.18d467be58773559,reason=Created count=1 msg=Created container: task
0.361,Event,ADDED,eval-conflicts-rho020-r2-005-wnt2m.18d467be5d937107,reason=Started count=1 msg=Started container task
0.3612,Event,ADDED,eval-conflicts-rho020-r2-005.18d467be3a14456e,reason=SuccessfulCreate count=1 msg=Created pod: eval-conflicts-rho020-r2-005-wnt2m
0.3613,Event,ADDED,eval-conflicts-rho020-r2-005.18d467c17151cb02,reason=Completed count=1 msg=Job completed
0.3618,Event,ADDED,eval-conflicts-rho020-r2-006-ghtqx.18d467be76e6d5ab,reason=Scheduled count=None msg=Successfully assigned compute/eval-conflicts-rho020-r2-006-ghtqx to kind-worker
0.362,Event,ADDED,eval-conflicts-rho020-r2-006-ghtqx.18d467be912e307e,"reason=Pulled count=1 msg=Container image ""busybox:musl"" already present on machine"
0.3622,Event,ADDED,eval-conflicts-rho020-r2-006-ghtqx.18d467be923bee88,reason=Created count=1 msg=Created container: task
0.3623,Event,ADDED,eval-conflicts-rho020-r2-006-ghtqx.18d467be943a12d5,reason=Started count=1 msg=Started container task
0.3625,Event,ADDED,eval-conflicts-rho020-r2-006.18d467be75152e32,reason=SuccessfulCreate count=1 msg=Created pod: eval-conflicts-rho020-r2-006-ghtqx
0.3627,Event,ADDED,eval-conflicts-rho020-r2-006.18d467c1a9424c22,reason=Completed count=1 msg=Job completed
0.3628,Event,ADDED,eval-conflicts-rho020-r2-007-hrzlr.18d467beb2265f49,reason=Scheduled count=None msg=Successfully assigned compute/eval-conflicts-rho020-r2-007-hrzlr to kind-worker2
0.363,Event,ADDED,eval-conflicts-rho020-r2-007-hrzlr.18d467becb90752c,"reason=Pulled count=1 msg=Container image ""busybox:musl"" already present on machine"
0.3633,Event,ADDED,eval-conflicts-rho020-r2-007-hrzlr.18d467beccad1006,reason=Created count=1 msg=Created container: task
0.3635,Event,ADDED,eval-conflicts-rho020-r2-007-hrzlr.18d467bece9cb7ba,reason=Started count=1 msg=Started container task
0.3637,Event,ADDED,eval-conflicts-rho020-r2-007.18d467beb1165400,reason=SuccessfulCreate count=1 msg=Created pod: eval-conflicts-rho020-r2-007-hrzlr
0.3639,Event,ADDED,eval-conflicts-rho020-r2-007.18d467c2121cbe0f,reason=Completed count=1 msg=Job completed
0.3641,Event,ADDED,eval-conflicts-rho020-r2-008-k59g5.18d467beed0bdad9,reason=Scheduled count=None msg=Successfully assigned compute/eval-conflicts-rho020-r2-008-k59g5 to kind-worker3
0.3642,Event,ADDED,eval-conflicts-rho020-r2-008-k59g5.18d467bf05bee8f8,"reason=Pulled count=1 msg=Container image ""busybox:musl"" already present on machine"
0.3645,Event,ADDED,eval-conflicts-rho020-r2-008-k59g5.18d467bf06e14f81,reason=Created count=1 msg=Created container: task
0.3647,Event,ADDED,eval-conflicts-rho020-r2-008-k59g5.18d467bf0aee759e,reason=Started count=1 msg=Started container task
0.3649,Event,ADDED,eval-conflicts-rho020-r2-008.18d467beec27c4db,reason=SuccessfulCreate count=1 msg=Created pod: eval-conflicts-rho020-r2-008-k59g5
0.365,Event,ADDED,eval-conflicts-rho020-r2-008.18d467c234d95f93,reason=Completed count=1 msg=Job completed
0.3653,Event,ADDED,eval-conflicts-rho020-r2-009-96hgd.18d467bf2869c7f2,reason=Scheduled count=None msg=Successfully assigned compute/eval-conflicts-rho020-r2-009-96hgd to kind-worker
0.3656,Event,ADDED,eval-conflicts-rho020-r2-009-96hgd.18d467bf406f8a9c,"reason=Pulled count=1 msg=Container image ""busybox:musl"" already present on machine"
0.3657,Event,ADDED,eval-conflicts-rho020-r2-009-96hgd.18d467bf418ca175,reason=Created count=1 msg=Created container: task
0.3661,Event,ADDED,eval-conflicts-rho020-r2-009-96hgd.18d467bf43b00d1c,reason=Started count=1 msg=Started container task
0.3662,Event,ADDED,eval-conflicts-rho020-r2-009.18d467bf275dd210,reason=SuccessfulCreate count=1 msg=Created pod: eval-conflicts-rho020-r2-009-96hgd
0.3664,Event,ADDED,eval-conflicts-rho020-r2-009.18d467c25b9693b5,reason=Completed count=1 msg=Job completed
0.3666,Event,ADDED,eval-conflicts-rho020-r2-010-ztp9s.18d467bf63de2e13,"reason=FailedScheduling count=None msg=0/6 nodes are available: 1 c_wall violated: 2 conflicting context pair(s) with node memory, 2 c_wall violated: 1 conflicting context pair(s) with node memory, 3 node(s) had untolerated taint(s). no new claims to deallocate, preemption: 0/6 nodes are available: 3 No preemption victims found for incoming pod, 3 Preemption is not helpful for scheduling."
0.3668,Event,ADDED,eval-conflicts-rho020-r2-010-ztp9s.18d467bf65533725,"reason=FailedScheduling count=None msg=0/6 nodes are available: 1 c_wall violated: 2 conflicting context pair(s) with node memory, 2 c_wall violated: 1 conflicting context pair(s) with node memory, 3 node(s) had untolerated taint(s). no new claims to deallocate, preemption: 0/6 nodes are available: 3 No preemption victims found for incoming pod, 3 Preemption is not helpful for scheduling."
0.367,Event,ADDED,eval-conflicts-rho020-r2-010-ztp9s.18d467bf790685fc,"reason=FailedScheduling count=None msg=0/6 nodes are available: 2 c_wall violated: 1 conflicting context pair(s) with node memory, 4 node(s) had untolerated taint(s). no new claims to deallocate, preemption: 0/6 nodes are available: 2 No preemption victims found for incoming pod, 4 Preemption is not helpful for scheduling."
0.3672,Event,ADDED,eval-conflicts-rho020-r2-010-ztp9s.18d467bf84f31a1d,"reason=FailedScheduling count=None msg=0/6 nodes are available: 1 c_wall violated: 1 conflicting context pair(s) with node memory, 5 node(s) had untolerated taint(s). no new claims to deallocate, preemption: 0/6 nodes are available: 1 No preemption victims found for incoming pod, 5 Preemption is not helpful for scheduling."
0.3674,Event,ADDED,eval-conflicts-rho020-r2-010-ztp9s.18d467c1e8332b4d,reason=Scheduled count=None msg=Successfully assigned compute/eval-conflicts-rho020-r2-010-ztp9s to kind-worker2
0.3675,Event,ADDED,eval-conflicts-rho020-r2-010-ztp9s.18d467c205148ab4,"reason=Pulled count=1 msg=Container image ""busybox:musl"" already present on machine"
0.3677,Event,ADDED,eval-conflicts-rho020-r2-010-ztp9s.18d467c207ab1511,reason=Created count=1 msg=Created container: task
0.368,Event,ADDED,eval-conflicts-rho020-r2-010-ztp9s.18d467c20b968f05,reason=Started count=1 msg=Started container task
0.3682,Event,ADDED,eval-conflicts-rho020-r2-010.18d467bf632185b7,reason=SuccessfulCreate count=1 msg=Created pod: eval-conflicts-rho020-r2-010-ztp9s
0.3684,Event,ADDED,eval-conflicts-rho020-r2-010.18d467c5a9e9c086,reason=Completed count=1 msg=Job completed
0.3685,Event,ADDED,eval-conflicts-rho020-r2-011-h5xc7.18d467bf9f190a6b,"reason=FailedScheduling count=None msg=0/6 nodes are available: 6 node(s) had untolerated taint(s). no new claims to deallocate, preemption: 0/6 nodes are available: 6 Preemption is not helpful for scheduling."
0.3687,Event,ADDED,eval-conflicts-rho020-r2-011-h5xc7.18d467c1e8ddfce4,reason=Scheduled count=None msg=Successfully assigned compute/eval-conflicts-rho020-r2-011-h5xc7 to kind-worker2
0.3689,Event,ADDED,eval-conflicts-rho020-r2-011-h5xc7.18d467c2063605a2,"reason=Pulled count=1 msg=Container image ""busybox:musl"" already present on machine"
0.3691,Event,ADDED,eval-conflicts-rho020-r2-011-h5xc7.18d467c20af08ecd,reason=Created count=1 msg=Created container: task
0.3693,Event,ADDED,eval-conflicts-rho020-r2-011-h5xc7.18d467c20f389ce3,reason=Started count=1 msg=Started container task
0.3694,Event,ADDED,eval-conflicts-rho020-r2-011.18d467bf9f099d87,reason=SuccessfulCreate count=1 msg=Created pod: eval-conflicts-rho020-r2-011-h5xc7
0.3696,Event,ADDED,eval-conflicts-rho020-r2-011.18d467c5b5e17720,reason=Completed count=1 msg=Job completed
0.3697,Event,ADDED,eval-conflicts-rho020-r2-012-46hbl.18d467bfdaaf8fad,"reason=FailedScheduling count=None msg=0/6 nodes are available: 6 node(s) had untolerated taint(s). no new claims to deallocate, preemption: 0/6 nodes are available: 6 Preemption is not helpful for scheduling."
0.3699,Event,ADDED,eval-conflicts-rho020-r2-012-46hbl.18d467c1e93ac026,reason=Scheduled count=None msg=Successfully assigned compute/eval-conflicts-rho020-r2-012-46hbl to kind-worker2
0.37,Event,ADDED,eval-conflicts-rho020-r2-012-46hbl.18d467c207b4f4d9,"reason=Pulled count=1 msg=Container image ""busybox:musl"" already present on machine"
0.3702,Event,ADDED,eval-conflicts-rho020-r2-012-46hbl.18d467c20b3ed92a,reason=Created count=1 msg=Created container: task
0.3705,Event,ADDED,eval-conflicts-rho020-r2-012-46hbl.18d467c20f300176,reason=Started count=1 msg=Started container task
0.3707,Event,ADDED,eval-conflicts-rho020-r2-012.18d467bfdaa3fc1f,reason=SuccessfulCreate count=1 msg=Created pod: eval-conflicts-rho020-r2-012-46hbl
0.371,Event,ADDED,eval-conflicts-rho020-r2-012.18d467c5acdd36c2,reason=Completed count=1 msg=Job completed
0.3711,Event,ADDED,eval-conflicts-rho020-r2-013-mr9jp.18d467c015f9185f,"reason=FailedScheduling count=None msg=0/6 nodes are available: 6 node(s) had untolerated taint(s). no new claims to deallocate, preemption: 0/6 nodes are available: 6 Preemption is not helpful for scheduling."
0.3714,Event,ADDED,eval-conflicts-rho020-r2-013-mr9jp.18d467c1e9723ecd,reason=Scheduled count=None msg=Successfully assigned compute/eval-conflicts-rho020-r2-013-mr9jp to kind-worker2
0.3716,Event,ADDED,eval-conflicts-rho020-r2-013-mr9jp.18d467c20741cb7f,"reason=Pulled count=1 msg=Container image ""busybox:musl"" already present on machine"
0.3718,Event,ADDED,eval-conflicts-rho020-r2-013-mr9jp.18d467c20b1904cf,reason=Created count=1 msg=Created container: task
0.3721,Event,ADDED,eval-conflicts-rho020-r2-013-mr9jp.18d467c20f391b3f,reason=Started count=1 msg=Started container task
0.3723,Event,ADDED,eval-conflicts-rho020-r2-013.18d467c015f14275,reason=SuccessfulCreate count=1 msg=Created pod: eval-conflicts-rho020-r2-013-mr9jp
0.3724,Event,ADDED,eval-conflicts-rho020-r2-013.18d467c5b0170516,reason=Completed count=1 msg=Job completed
0.3726,Event,ADDED,eval-conflicts-rho020-r2-014-2ld8c.18d467c052cc226e,"reason=FailedScheduling count=None msg=0/6 nodes are available: 6 node(s) had untolerated taint(s). no new claims to deallocate, preemption: 0/6 nodes are available: 6 Preemption is not helpful for scheduling."
0.3731,Event,ADDED,eval-conflicts-rho020-r2-014-2ld8c.18d467c1e92bfe5c,"reason=FailedScheduling count=None msg=0/6 nodes are available: 1 c_wall violated: 1 conflicting context pair(s) with node memory, 5 node(s) had untolerated taint(s). no new claims to deallocate, preemption: 0/6 nodes are available: 1 No preemption victims found for incoming pod, 5 Preemption is not helpful for scheduling."
0.3733,Event,ADDED,eval-conflicts-rho020-r2-014-2ld8c.18d467c1fd326109,"reason=FailedScheduling count=None msg=0/6 nodes are available: 1 c_wall violated: 1 conflicting context pair(s) with node memory, 5 node(s) had untolerated taint(s). no new claims to deallocate, preemption: 0/6 nodes are available: 1 No preemption victims found for incoming pod, 5 Preemption is not helpful for scheduling."
0.3734,Event,ADDED,eval-conflicts-rho020-r2-014-2ld8c.18d467c203d3de23,reason=Scheduled count=None msg=Successfully assigned compute/eval-conflicts-rho020-r2-014-2ld8c to kind-worker4
0.3738,Event,ADDED,eval-conflicts-rho020-r2-014-2ld8c.18d467c21d45f05a,"reason=Pulled count=1 msg=Container image ""busybox:musl"" already present on machine"
0.374,Event,ADDED,eval-conflicts-rho020-r2-014-2ld8c.18d467c21ecc0452,reason=Created count=1 msg=Created container: task
0.3742,Event,ADDED,eval-conflicts-rho020-r2-014-2ld8c.18d467c2265ae0de,reason=Started count=1 msg=Started container task
0.3744,Event,ADDED,eval-conflicts-rho020-r2-014.18d467c052be51ce,reason=SuccessfulCreate count=1 msg=Created pod: eval-conflicts-rho020-r2-014-2ld8c
0.3747,Event,ADDED,eval-conflicts-rho020-r2-014.18d467c5c4de67a2,reason=Completed count=1 msg=Job completed
0.3749,Event,ADDED,eval-conflicts-rho020-r2-015-smlzz.18d467c08de67eeb,"reason=FailedScheduling count=None msg=0/6 nodes are available: 6 node(s) had untolerated taint(s). no new claims to deallocate, preemption: 0/6 nodes are available: 6 Preemption is not helpful for scheduling."
0.375,Event,ADDED,eval-conflicts-rho020-r2-015-smlzz.18d467c1f1bd19c5,reason=Scheduled count=None msg=Successfully assigned compute/eval-conflicts-rho020-r2-015-smlzz to kind-worker2
0.3754,Event,ADDED,eval-conflicts-rho020-r2-015-smlzz.18d467c20d4965df,"reason=Pulled count=1 msg=Container image ""busybox:musl"" already present on machine"
0.3756,Event,ADDED,eval-conflicts-rho020-r2-015-smlzz.18d467c210304cd9,reason=Created count=1 msg=Created container: task
0.3758,Event,ADDED,eval-conflicts-rho020-r2-015-smlzz.18d467c214b3c5ca,reason=Started count=1 msg=Started container task
0.376,Event,ADDED,eval-conflicts-rho020-r2-015.18d467c08dcec014,reason=SuccessfulCreate count=1 msg=Created pod: eval-conflicts-rho020-r2-015-smlzz
0.3763,Event,ADDED,eval-conflicts-rho020-r2-015.18d467c557846041,reason=Completed count=1 msg=Job completed
0.3765,Event,ADDED,eval-conflicts-rho020-r2-016-62rf9.18d467c0c956b6e6,"reason=FailedScheduling count=None msg=0/6 nodes are available: 6 node(s) had untolerated taint(s). no new claims to deallocate, preemption: 0/6 nodes are available: 6 Preemption is not helpful for scheduling."
0.3767,Event,ADDED,eval-conflicts-rho020-r2-016-62rf9.18d467c1f18d4d94,"reason=FailedScheduling count=None msg=0/6 nodes are available: 1 c_wall violated: 1 conflicting context pair(s) with node memory, 5 node(s) had untolerated taint(s). no new claims to deallocate, preemption: 0/6 nodes are available: 1 No preemption victims found for incoming pod, 5 Preemption is not helpful for scheduling."
0.377,Event,ADDED,eval-conflicts-rho020-r2-016-62rf9.18d467c1fd8ff540,"reason=FailedScheduling count=None msg=0/6 nodes are available: 1 c_wall violated: 1 conflicting context pair(s) with node memory, 5 node(s) had untolerated taint(s). no new claims to deallocate, preemption: 0/6 nodes are available: 1 No preemption victims found for incoming pod, 5 Preemption is not helpful for scheduling."
0.3771,Event,ADDED,eval-conflicts-rho020-r2-016-62rf9.18d467c204675bb9,reason=Scheduled count=None msg=Successfully assigned compute/eval-conflicts-rho020-r2-016-62rf9 to kind-worker4
0.3773,Event,ADDED,eval-conflicts-rho020-r2-016-62rf9.18d467c21da8e456,"reason=Pulled count=1 msg=Container image ""busybox:musl"" already present on machine"
0.3775,Event,ADDED,eval-conflicts-rho020-r2-016-62rf9.18d467c21f2b5f73,reason=Created count=1 msg=Created container: task
0.3777,Event,ADDED,eval-conflicts-rho020-r2-016-62rf9.18d467c228e28982,reason=Started count=1 msg=Started container task
0.3779,Event,ADDED,eval-conflicts-rho020-r2-016.18d467c0c94a722f,reason=SuccessfulCreate count=1 msg=Created pod: eval-conflicts-rho020-r2-016-62rf9
0.3781,Event,ADDED,eval-conflicts-rho020-r2-016.18d467c5c7d4aed5,reason=Completed count=1 msg=Job completed
0.3782,Event,ADDED,eval-conflicts-rho020-r2-017-ggzkg.18d467c104cd4495,"reason=FailedScheduling count=None msg=0/6 nodes are available: 6 node(s) had untolerated taint(s). no new claims to deallocate, preemption: 0/6 nodes are available: 6 Preemption is not helpful for scheduling."
0.3784,Event,ADDED,eval-conflicts-rho020-r2-017-ggzkg.18d467c1f737816a,reason=Scheduled count=None msg=Successfully assigned compute/eval-conflicts-rho020-r2-017-ggzkg to kind-worker2
0.3785,Event,ADDED,eval-conflicts-rho020-r2-017-ggzkg.18d467c2101177ad,"reason=Pulled count=1 msg=Container image ""busybox:musl"" already present on machine"
0.3787,Event,ADDED,eval-conflicts-rho020-r2-017-ggzkg.18d467c212996187,reason=Created count=1 msg=Created container: task
0.3789,Event,ADDED,eval-conflicts-rho020-r2-017-ggzkg.18d467c2162581f5,reason=Started count=1 msg=Started container task
0.379,Event,ADDED,eval-conflicts-rho020-r2-017.18d467c104c4d53d,reason=SuccessfulCreate count=1 msg=Created pod: eval-conflicts-rho020-r2-017-ggzkg
0.3792,Event,ADDED,eval-conflicts-rho020-r2-017.18d467c51eb8f865,reason=Completed count=1 msg=Job completed
0.3794,Event,ADDED,eval-conflicts-rho020-r2-018-n9m5x.18d467c140865f39,"reason=FailedScheduling count=None msg=0/6 nodes are available: 6 node(s) had untolerated taint(s). no new claims to deallocate, preemption: 0/6 nodes are available: 6 Preemption is not helpful for scheduling."
0.3797,Event,ADDED,eval-conflicts-rho020-r2-018-n9m5x.18d467c1f7db3643,reason=Scheduled count=None msg=Successfully assigned compute/eval-conflicts-rho020-r2-018-n9m5x to kind-worker2
0.3799,Event,ADDED,eval-conflicts-rho020-r2-018-n9m5x.18d467c214481fa5,"reason=Pulled count=1 msg=Container image ""busybox:musl"" already present on machine"
0.38,Event,ADDED,eval-conflicts-rho020-r2-018-n9m5x.18d467c2162005f9,reason=Created count=1 msg=Created container: task
0.3803,Event,ADDED,eval-conflicts-rho020-r2-018-n9m5x.18d467c218b20f00,reason=Started count=1 msg=Started container task
0.3805,Event,ADDED,eval-conflicts-rho020-r2-018.18d467c1407ca45f,reason=SuccessfulCreate count=1 msg=Created pod: eval-conflicts-rho020-r2-018-n9m5x
0.3807,Event,ADDED,eval-conflicts-rho020-r2-018.18d467c51e31c25e,reason=Completed count=1 msg=Job completed
0.3808,Event,ADDED,eval-conflicts-rho020-r2-019-g5lbh.18d467c17b920f4b,"reason=FailedScheduling count=None msg=0/6 nodes are available: 6 node(s) had untolerated taint(s). no new claims to deallocate, preemption: 0/6 nodes are available: 6 Preemption is not helpful for scheduling."
0.3811,Event,ADDED,eval-conflicts-rho020-r2-019-g5lbh.18d467c1f7888b9a,"reason=FailedScheduling count=None msg=0/6 nodes are available: 1 c_wall violated: 1 conflicting context pair(s) with node memory, 5 node(s) had untolerated taint(s). no new claims to deallocate, preemption: 0/6 nodes are available: 1 No preemption victims found for incoming pod, 5 Preemption is not helpful for scheduling."
0.3813,Event,ADDED,eval-conflicts-rho020-r2-019-g5lbh.18d467c20329a94e,reason=Scheduled count=None msg=Successfully assigned compute/eval-conflicts-rho020-r2-019-g5lbh to kind-worker4
0.3815,Event,ADDED,eval-conflicts-rho020-r2-019-g5lbh.18d467c217d7104e,"reason=Pulled count=1 msg=Container image ""busybox:musl"" already present on machine"
0.3818,Event,ADDED,eval-conflicts-rho020-r2-019-g5lbh.18d467c21a324de2,reason=Created count=1 msg=Created container: task
0.382,Event,ADDED,eval-conflicts-rho020-r2-019-g5lbh.18d467c21d44b2aa,reason=Started count=1 msg=Started container task
0.3822,Event,ADDED,eval-conflicts-rho020-r2-019.18d467c17b861cf2,reason=SuccessfulCreate count=1 msg=Created pod: eval-conflicts-rho020-r2-019-g5lbh
0.3824,Event,ADDED,eval-conflicts-rho020-r2-019.18d467c5d6b7137f,reason=Completed count=1 msg=Job completed
0.3828,Event,ADDED,eval-conflicts-rho020-r2-020-5xf9b.18d467c1b74dac39,"reason=FailedScheduling count=None msg=0/6 nodes are available: 6 node(s) had untolerated taint(s). no new claims to deallocate, preemption: 0/6 nodes are available: 6 Preemption is not helpful for scheduling."
0.3829,Event,ADDED,eval-conflicts-rho020-r2-020-5xf9b.18d467c1fd2c57ac,reason=Scheduled count=None msg=Successfully assigned compute/eval-conflicts-rho020-r2-020-5xf9b to kind-worker2
0.3831,Event,ADDED,eval-conflicts-rho020-r2-020-5xf9b.18d467c215ba87f0,"reason=Pulled count=1 msg=Container image ""busybox:musl"" already present on machine"
0.3833,Event,ADDED,eval-conflicts-rho020-r2-020-5xf9b.18d467c2179dfad3,reason=Created count=1 msg=Created container: task
0.3835,Event,ADDED,eval-conflicts-rho020-r2-020-5xf9b.18d467c21a18b159,reason=Started count=1 msg=Started container task
0.3837,Event,ADDED,eval-conflicts-rho020-r2-020.18d467c1b7448d35,reason=SuccessfulCreate count=1 msg=Created pod: eval-conflicts-rho020-r2-020-5xf9b
0.3838,Event,ADDED,eval-conflicts-rho020-r2-020.18d467c51f216091,reason=Completed count=1 msg=Job completed
0.384,Event,ADDED,eval-conflicts-rho020-r2-021-xvclq.18d467c1f8c126bd,reason=Scheduled count=None msg=Successfully assigned compute/eval-conflicts-rho020-r2-021-xvclq to kind-worker2
0.3843,Event,ADDED,eval-conflicts-rho020-r2-021-xvclq.18d467c21628c111,"reason=Pulled count=1 msg=Container image ""busybox:musl"" already present on machine"
0.3844,Event,ADDED,eval-conflicts-rho020-r2-021-xvclq.18d467c21829ae9c,reason=Created count=1 msg=Created container: task
0.3846,Event,ADDED,eval-conflicts-rho020-r2-021-xvclq.18d467c21ab440be,reason=Started count=1 msg=Started container task
0.3852,Event,ADDED,eval-conflicts-rho020-r2-021.18d467c1f36d4ba6,reason=SuccessfulCreate count=1 msg=Created pod: eval-conflicts-rho020-r2-021-xvclq
0.3853,Event,ADDED,eval-conflicts-rho020-r2-021.18d467c5b300f92b,reason=Completed count=1 msg=Job completed
0.3855,Event,ADDED,eval-conflicts-rho020-r2-022-m877t.18d467c22fc2b6b6,reason=Scheduled count=None msg=Successfully assigned compute/eval-conflicts-rho020-r2-022-m877t to kind-worker5
0.3857,Event,ADDED,eval-conflicts-rho020-r2-022-m877t.18d467c24a1d53bd,"reason=Pulled count=1 msg=Container image ""busybox:musl"" already present on machine"
0.3858,Event,ADDED,eval-conflicts-rho020-r2-022-m877t.18d467c24b2e262d,reason=Created count=1 msg=Created container: task
0.386,Event,ADDED,eval-conflicts-rho020-r2-022-m877t.18d467c24f188e7b,reason=Started count=1 msg=Started container task
0.3861,Event,ADDED,eval-conflicts-rho020-r2-022.18d467c22e778f5b,reason=SuccessfulCreate count=1 msg=Created pod: eval-conflicts-rho020-r2-022-m877t
0.3863,Event,ADDED,eval-conflicts-rho020-r2-022.18d467c5e28ef22f,reason=Completed count=1 msg=Job completed
0.3865,Event,ADDED,eval-conflicts-rho020-r2-023-tb9s9.18d467c26dc2d747,reason=Scheduled count=None msg=Successfully assigned compute/eval-conflicts-rho020-r2-023-tb9s9 to kind-worker5
0.3866,Event,ADDED,eval-conflicts-rho020-r2-023-tb9s9.18d467c286c16cff,"reason=Pulled count=1 msg=Container image ""busybox:musl"" already present on machine"
0.3869,Event,ADDED,eval-conflicts-rho020-r2-023-tb9s9.18d467c287dbd0e6,reason=Created count=1 msg=Created container: task
0.3871,Event,ADDED,eval-conflicts-rho020-r2-023-tb9s9.18d467c28bb9fa40,reason=Started count=1 msg=Started container task
0.3873,Event,ADDED,eval-conflicts-rho020-r2-023.18d467c26cb8140f,reason=SuccessfulCreate count=1 msg=Created pod: eval-conflicts-rho020-r2-023-tb9s9
0.3874,Event,ADDED,eval-conflicts-rho020-r2-023.18d467c6184a6d9b,reason=Completed count=1 msg=Job completed
0.3876,Event,ADDED,eval-conflicts-rho020-r2-024-q5ktl.18d467c2a69a04b6,reason=Scheduled count=None msg=Successfully assigned compute/eval-conflicts-rho020-r2-024-q5ktl to kind-worker5
0.3878,Event,ADDED,eval-conflicts-rho020-r2-024-q5ktl.18d467c2c0a6a686,"reason=Pulled count=1 msg=Container image ""busybox:musl"" already present on machine"
0.388,Event,ADDED,eval-conflicts-rho020-r2-024-q5ktl.18d467c2c1c41c3f,reason=Created count=1 msg=Created container: task
0.3881,Event,ADDED,eval-conflicts-rho020-r2-024-q5ktl.18d467c2c3dc537c,reason=Started count=1 msg=Started container task
0.3883,Event,ADDED,eval-conflicts-rho020-r2-024.18d467c2a57879a2,reason=SuccessfulCreate count=1 msg=Created pod: eval-conflicts-rho020-r2-024-q5ktl
0.3885,Event,ADDED,eval-conflicts-rho020-r2-024.18d467c63f928b0d,reason=Completed count=1 msg=Job completed
0.3886,Event,ADDED,eval-conflicts-rho020-r2-025-ckvdh.18d467c2e40c9644,reason=Scheduled count=None msg=Successfully assigned compute/eval-conflicts-rho020-r2-025-ckvdh to kind-worker5
0.3888,Event,ADDED,eval-conflicts-rho020-r2-025-ckvdh.18d467c2fc803cf1,"reason=Pulled count=1 msg=Container image ""busybox:musl"" already present on machine"
0.389,Event,ADDED,eval-conflicts-rho020-r2-025-ckvdh.18d467c2fda14b1d,reason=Created count=1 msg=Created container: task
0.3891,Event,ADDED,eval-conflicts-rho020-r2-025-ckvdh.18d467c2ff8312b4,reason=Started count=1 msg=Started container task
0.3893,Event,ADDED,eval-conflicts-rho020-r2-025.18d467c2e2bf6449,reason=SuccessfulCreate count=1 msg=Created pod: eval-conflicts-rho020-r2-025-ckvdh
0.3895,Event,ADDED,eval-conflicts-rho020-r2-025.18d467c639082142,reason=Completed count=1 msg=Job completed
0.3896,Event,ADDED,eval-conflicts-rho020-r2-026-jmj9k.18d467c31e73eb7f,reason=Scheduled count=None msg=Successfully assigned compute/eval-conflicts-rho020-r2-026-jmj9k to kind-worker4
0.3898,Event,ADDED,eval-conflicts-rho020-r2-026-jmj9k.18d467c33806d7f0,"reason=Pulled count=1 msg=Container image ""busybox:musl"" already present on machine"
0.39,Event,ADDED,eval-conflicts-rho020-r2-026-jmj9k.18d467c3391ff837,reason=Created count=1 msg=Created container: task
0.3901,Event,ADDED,eval-conflicts-rho020-r2-026-jmj9k.18d467c33d3af2e8,reason=Started count=1 msg=Started container task
0.3903,Event,ADDED,eval-conflicts-rho020-r2-026.18d467c31d2629e9,reason=SuccessfulCreate count=1 msg=Created pod: eval-conflicts-rho020-r2-026-jmj9k
0.3905,Event,ADDED,eval-conflicts-rho020-r2-026.18d467c65d817f95,reason=Completed count=1 msg=Job completed
0.3906,Event,ADDED,eval-conflicts-rho020-r2-027-n4l5r.18d467c35a00e5c3,reason=Scheduled count=None msg=Successfully assigned compute/eval-conflicts-rho020-r2-027-n4l5r to kind-worker5
0.3908,Event,ADDED,eval-conflicts-rho020-r2-027-n4l5r.18d467c374866c0c,"reason=Pulled count=1 msg=Container image ""busybox:musl"" already present on machine"
0.391,Event,ADDED,eval-conflicts-rho020-r2-027-n4l5r.18d467c3759e93d0,reason=Created count=1 msg=Created container: task
0.3911,Event,ADDED,eval-conflicts-rho020-r2-027-n4l5r.18d467c37780c580,reason=Started count=1 msg=Started container task
0.3913,Event,ADDED,eval-conflicts-rho020-r2-027.18d467c358d4e4c2,reason=SuccessfulCreate count=1 msg=Created pod: eval-conflicts-rho020-r2-027-n4l5r
0.3915,Event,ADDED,eval-conflicts-rho020-r2-027.18d467c696549b5b,reason=Completed count=1 msg=Job completed
0.3917,Event,ADDED,eval-conflicts-rho020-r2-028-rsrhb.18d467c3957a5bab,reason=Scheduled count=None msg=Successfully assigned compute/eval-conflicts-rho020-r2-028-rsrhb to kind-worker4
0.392,Event,ADDED,eval-conflicts-rho020-r2-028-rsrhb.18d467c3aedaba21,"reason=Pulled count=1 msg=Container image ""busybox:musl"" already present on machine"
0.3923,Event,ADDED,eval-conflicts-rho020-r2-028-rsrhb.18d467c3aff7ca56,reason=Created count=1 msg=Created container: task
0.3925,Event,ADDED,eval-conflicts-rho020-r2-028-rsrhb.18d467c3b38e08fd,reason=Started count=1 msg=Started container task
0.3927,Event,ADDED,eval-conflicts-rho020-r2-028.18d467c3948d5256,reason=SuccessfulCreate count=1 msg=Created pod: eval-conflicts-rho020-r2-028-rsrhb
0.3934,Event,ADDED,eval-conflicts-rho020-r2-028.18d467c6ceaa9ae7,reason=Completed count=1 msg=Job completed
0.3937,Event,ADDED,eval-conflicts-rho020-r2-029-ssd9f.18d467c3d077a650,reason=Scheduled count=None msg=Successfully assigned compute/eval-conflicts-rho020-r2-029-ssd9f to kind-worker5
0.3941,Event,ADDED,eval-conflicts-rho020-r2-029-ssd9f.18d467c3e9b7aa6b,"reason=Pulled count=1 msg=Container image ""busybox:musl"" already present on machine"
0.3943,Event,ADDED,eval-conflicts-rho020-r2-029-ssd9f.18d467c3eac3b023,reason=Created count=1 msg=Created container: task
0.3947,Event,ADDED,eval-conflicts-rho020-r2-029-ssd9f.18d467c3ecf2664f,reason=Started count=1 msg=Started container task
0.395,Event,ADDED,eval-conflicts-rho020-r2-029.18d467c3cf7c15ea,reason=SuccessfulCreate count=1 msg=Created pod: eval-conflicts-rho020-r2-029-ssd9f
0.3952,Event,ADDED,eval-conflicts-rho020-r2-029.18d467c70c4da9ac,reason=Completed count=1 msg=Job completed
0.3956,Event,ADDED,eval-conflicts-rho020-r2-030-7pzqd.18d467c40cb41ca3,reason=Scheduled count=None msg=Successfully assigned compute/eval-conflicts-rho020-r2-030-7pzqd to kind-worker5
0.396,Event,ADDED,eval-conflicts-rho020-r2-030-7pzqd.18d467c4264f8325,"reason=Pulled count=1 msg=Container image ""busybox:musl"" already present on machine"
0.3963,Event,ADDED,eval-conflicts-rho020-r2-030-7pzqd.18d467c4277e9526,reason=Created count=1 msg=Created container: task
0.3966,Event,ADDED,eval-conflicts-rho020-r2-030-7pzqd.18d467c429b8678b,reason=Started count=1 msg=Started container task
0.397,Event,ADDED,eval-conflicts-rho020-r2-030.18d467c40b469384,reason=SuccessfulCreate count=1 msg=Created pod: eval-conflicts-rho020-r2-030-7pzqd
0.3972,Event,ADDED,eval-conflicts-rho020-r2-030.18d467c747ce60d4,reason=Completed count=1 msg=Job completed
0.3974,Event,ADDED,eval-conflicts-rho020-r2-031-fvjzp.18d467c4480b528b,reason=Scheduled count=None msg=Successfully assigned compute/eval-conflicts-rho020-r2-031-fvjzp to kind-worker
0.3975,Event,ADDED,eval-conflicts-rho020-r2-031-fvjzp.18d467c46dee7bbe,"reason=Pulled count=1 msg=Container image ""busybox:musl"" already present on machine"
0.3984,Event,ADDED,eval-conflicts-rho020-r2-031-fvjzp.18d467c46f340750,reason=Created count=1 msg=Created container: task
0.3988,Event,ADDED,eval-conflicts-rho020-r2-031-fvjzp.18d467c474d66b2d,reason=Started count=1 msg=Started container task
0.3992,Event,ADDED,eval-conflicts-rho020-r2-031.18d467c447244f18,reason=SuccessfulCreate count=1 msg=Created pod: eval-conflicts-rho020-r2-031-fvjzp
0.3996,Event,ADDED,eval-conflicts-rho020-r2-031.18d467c7b9d48621,reason=Completed count=1 msg=Job completed
0.3998,Event,ADDED,eval-conflicts-rho020-r2-032-hdv89.18d467c48390035c,reason=Scheduled count=None msg=Successfully assigned compute/eval-conflicts-rho020-r2-032-hdv89 to kind-worker
0.4,Event,ADDED,eval-conflicts-rho020-r2-032-hdv89.18d467c49e224061,"reason=Pulled count=1 msg=Container image ""busybox:musl"" already present on machine"
0.4001,Event,ADDED,eval-conflicts-rho020-r2-032-hdv89.18d467c49fb019db,reason=Created count=1 msg=Created container: task
0.4005,Event,ADDED,eval-conflicts-rho020-r2-032-hdv89.18d467c4a9874724,reason=Started count=1 msg=Started container task
0.4007,Event,ADDED,eval-conflicts-rho020-r2-032.18d467c48276b6dc,reason=SuccessfulCreate count=1 msg=Created pod: eval-conflicts-rho020-r2-032-hdv89
0.4009,Event,ADDED,eval-conflicts-rho020-r2-032.18d467c7ba32f841,reason=Completed count=1 msg=Job completed
0.401,Event,ADDED,eval-conflicts-rho020-r2-033-c8g7v.18d467c4beef675d,reason=Scheduled count=None msg=Successfully assigned compute/eval-conflicts-rho020-r2-033-c8g7v to kind-worker
0.4014,Event,ADDED,eval-conflicts-rho020-r2-033-c8g7v.18d467c4d9002e1f,"reason=Pulled count=1 msg=Container image ""busybox:musl"" already present on machine"
0.4016,Event,ADDED,eval-conflicts-rho020-r2-033-c8g7v.18d467c4da1ebc99,reason=Created count=1 msg=Created container: task
0.4018,Event,ADDED,eval-conflicts-rho020-r2-033-c8g7v.18d467c4dc4ead84,reason=Started count=1 msg=Started container task
0.4022,Event,ADDED,eval-conflicts-rho020-r2-033.18d467c4be11fbdb,reason=SuccessfulCreate count=1 msg=Created pod: eval-conflicts-rho020-r2-033-c8g7v
0.4024,Event,ADDED,eval-conflicts-rho020-r2-033.18d467c7f5beb185,reason=Completed count=1 msg=Job completed
0.4026,Event,ADDED,eval-conflicts-rho020-r2-034-9vkfz.18d467c4fa8017e2,reason=Scheduled count=None msg=Successfully assigned compute/eval-conflicts-rho020-r2-034-9vkfz to kind-worker3
0.4028,Event,ADDED,eval-conflicts-rho020-r2-034-9vkfz.18d467c513ddc056,"reason=Pulled count=1 msg=Container image ""busybox:musl"" already present on machine"
0.4031,Event,ADDED,eval-conflicts-rho020-r2-034-9vkfz.18d467c5150fbc1d,reason=Created count=1 msg=Created container: task
0.4033,Event,ADDED,eval-conflicts-rho020-r2-034-9vkfz.18d467c51e0730ce,reason=Started count=1 msg=Started container task
0.4035,Event,ADDED,eval-conflicts-rho020-r2-034.18d467c4f9da4ca9,reason=SuccessfulCreate count=1 msg=Created pod: eval-conflicts-rho020-r2-034-9vkfz
0.4038,Event,ADDED,eval-conflicts-rho020-r2-034.18d467c8469bd0c9,reason=Completed count=1 msg=Job completed
0.404,Event,ADDED,eval-conflicts-rho020-r2-035-v2pfm.18d467c545773386,reason=Scheduled count=None msg=Successfully assigned compute/eval-conflicts-rho020-r2-035-v2pfm to kind-worker3
0.4043,Event,ADDED,eval-conflicts-rho020-r2-035-v2pfm.18d467c55e64f320,"reason=Pulled count=1 msg=Container image ""busybox:musl"" already present on machine"
0.4045,Event,ADDED,eval-conflicts-rho020-r2-035-v2pfm.18d467c55f8f659a,reason=Created count=1 msg=Created container: task
0.4048,Event,ADDED,eval-conflicts-rho020-r2-035-v2pfm.18d467c561b902c6,reason=Started count=1 msg=Started container task
0.405,Event,ADDED,eval-conflicts-rho020-r2-035.18d467c544e1fa85,reason=SuccessfulCreate count=1 msg=Created pod: eval-conflicts-rho020-r2-035-v2pfm
0.4052,Event,ADDED,eval-conflicts-rho020-r2-035.18d467c8829dd27e,reason=Completed count=1 msg=Job completed
0.4054,Event,ADDED,eval-conflicts-rho020-r2-036-h99mr.18d467c592d4533d,"reason=FailedScheduling count=None msg=0/6 nodes are available: 2 c_wall violated: 1 conflicting context pair(s) with node memory, 4 node(s) had untolerated taint(s). no new claims to deallocate, preemption: 0/6 nodes are available: 2 No preemption victims found for incoming pod, 4 Preemption is not helpful for scheduling."
0.4056,Event,ADDED,eval-conflicts-rho020-r2-036-h99mr.18d467c5936cbda7,"reason=FailedScheduling count=None msg=0/6 nodes are available: 2 c_wall violated: 1 conflicting context pair(s) with node memory, 4 node(s) had untolerated taint(s). no new claims to deallocate, preemption: 0/6 nodes are available: 2 No preemption victims found for incoming pod, 4 Preemption is not helpful for scheduling."
0.4058,Event,ADDED,eval-conflicts-rho020-r2-036-h99mr.18d467c627bf33cb,"reason=FailedScheduling count=None msg=0/6 nodes are available: 1 c_wall violated: 2 conflicting context pair(s) with node memory, 5 node(s) had untolerated taint(s). no new claims to deallocate, preemption: 0/6 nodes are available: 1 No preemption victims found for incoming pod, 5 Preemption is not helpful for scheduling."
0.406,Event,ADDED,eval-conflicts-rho020-r2-036-h99mr.18d467c62ad3156f,"reason=FailedScheduling count=None msg=0/6 nodes are available: 1 c_wall violated: 2 conflicting context pair(s) with node memory, 5 node(s) had untolerated taint(s). no new claims to deallocate, preemption: 0/6 nodes are available: 1 No preemption victims found for incoming pod, 5 Preemption is not helpful for scheduling."
0.4061,Event,ADDED,eval-conflicts-rho020-r2-036-h99mr.18d467c6a1f7dce4,reason=Scheduled count=None msg=Successfully assigned compute/eval-conflicts-rho020-r2-036-h99mr to kind-worker2
0.4063,Event,ADDED,eval-conflicts-rho020-r2-036-h99mr.18d467c6bb8e4370,"reason=Pulled count=1 msg=Container image ""busybox:musl"" already present on machine"
0.4065,Event,ADDED,eval-conflicts-rho020-r2-036-h99mr.18d467c6bce7e35f,reason=Created count=1 msg=Created container: task
0.4066,Event,ADDED,eval-conflicts-rho020-r2-036-h99mr.18d467c6bf00856b,reason=Started count=1 msg=Started container task
0.4068,Event,ADDED,eval-conflicts-rho020-r2-036.18d467c59273c74b,reason=SuccessfulCreate count=1 msg=Created pod: eval-conflicts-rho020-r2-036-h99mr
0.407,Event,ADDED,eval-conflicts-rho020-r2-036.18d467ca04035686,reason=Completed count=1 msg=Job completed
0.4071,Event,ADDED,eval-conflicts-rho020-r2-037-5q2q7.18d467c5bf86e113,reason=Scheduled count=None msg=Successfully assigned compute/eval-conflicts-rho020-r2-037-5q2q7 to kind-worker3
0.4073,Event,ADDED,eval-conflicts-rho020-r2-037-5q2q7.18d467c5d9a1041a,"reason=Pulled count=1 msg=Container image ""busybox:musl"" already present on machine"
0.4075,Event,ADDED,eval-conflicts-rho020-r2-037-5q2q7.18d467c5dacf825d,reason=Created count=1 msg=Created container: task
0.4076,Event,ADDED,eval-conflicts-rho020-r2-037-5q2q7.18d467c5dcebeda1,reason=Started count=1 msg=Started container task
0.4078,Event,ADDED,eval-conflicts-rho020-r2-037.18d467c5bee3102c,reason=SuccessfulCreate count=1 msg=Created pod: eval-conflicts-rho020-r2-037-5q2q7
0.408,Event,ADDED,eval-conflicts-rho020-r2-037.18d467c8facfd2b8,reason=Completed count=1 msg=Job completed
0.4082,Event,ADDED,eval-conflicts-rho020-r2-038-dbtlx.18d467c5f54c36ac,reason=Scheduled count=None msg=Successfully assigned compute/eval-conflicts-rho020-r2-038-dbtlx to kind-worker3
0.4085,Event,ADDED,eval-conflicts-rho020-r2-038-dbtlx.18d467c60f6f0046,"reason=Pulled count=1 msg=Container image ""busybox:musl"" already present on machine"
0.4089,Event,ADDED,eval-conflicts-rho020-r2-038-dbtlx.18d467c610a49af3,reason=Created count=1 msg=Created container: task
0.4091,Event,ADDED,eval-conflicts-rho020-r2-038-dbtlx.18d467c614dc7155,reason=Started count=1 msg=Started container task
0.4093,Event,ADDED,eval-conflicts-rho020-r2-038.18d467c5f4a9017b,reason=SuccessfulCreate count=1 msg=Created pod: eval-conflicts-rho020-r2-038-dbtlx
0.4096,Event,ADDED,eval-conflicts-rho020-r2-038.18d467c936d1152c,reason=Completed count=1 msg=Job completed
0.4099,Event,ADDED,eval-conflicts-rho020-r2-039-m9tw9.18d467c627ddf708,reason=Scheduled count=None msg=Successfully assigned compute/eval-conflicts-rho020-r2-039-m9tw9 to kind-worker
0.4101,Event,ADDED,eval-conflicts-rho020-r2-039-m9tw9.18d467c641926805,"reason=Pulled count=1 msg=Container image ""busybox:musl"" already present on machine"
0.4103,Event,ADDED,eval-conflicts-rho020-r2-039-m9tw9.18d467c642d43b6d,reason=Created count=1 msg=Created container: task
0.4108,Event,ADDED,eval-conflicts-rho020-r2-039-m9tw9.18d467c647fa7cdf,reason=Started count=1 msg=Started container task
0.411,Event,ADDED,eval-conflicts-rho020-r2-039.18d467c62733f9ac,reason=SuccessfulCreate count=1 msg=Created pod: eval-conflicts-rho020-r2-039-m9tw9
0.4112,Event,ADDED,eval-conflicts-rho020-r2-039.18d467c95c7e99e6,reason=Completed count=1 msg=Job completed
0.4113,Event,ADDED,eval-conflicts-rho020-r2-040-vrwj7.18d467c6602be840,reason=Scheduled count=None msg=Successfully assigned compute/eval-conflicts-rho020-r2-040-vrwj7 to kind-worker
0.4116,Event,ADDED,eval-conflicts-rho020-r2-040-vrwj7.18d467c679843565,"reason=Pulled count=1 msg=Container image ""busybox:musl"" already present on machine"
0.4118,Event,ADDED,eval-conflicts-rho020-r2-040-vrwj7.18d467c67a8a4d0e,reason=Created count=1 msg=Created container: task
0.412,Event,ADDED,eval-conflicts-rho020-r2-040-vrwj7.18d467c67dc1217d,reason=Started count=1 msg=Started container task
0.4123,Event,ADDED,eval-conflicts-rho020-r2-040.18d467c65f761d80,reason=SuccessfulCreate count=1 msg=Created pod: eval-conflicts-rho020-r2-040-vrwj7
0.4125,Event,ADDED,eval-conflicts-rho020-r2-040.18d467c997fd1b18,reason=Completed count=1 msg=Job completed
0.4127,Event,ADDED,eval-conflicts-rho020-r2-041-92fc7.18d467c69ae4c041,"reason=FailedScheduling count=None msg=0/6 nodes are available: 6 node(s) had untolerated taint(s). no new claims to deallocate, preemption: 0/6 nodes are available: 6 Preemption is not helpful for scheduling."
0.4128,Event,ADDED,eval-conflicts-rho020-r2-041-92fc7.18d467c6a220eea0,reason=Scheduled count=None msg=Successfully assigned compute/eval-conflicts-rho020-r2-041-92fc7 to kind-worker2
0.4131,Event,ADDED,eval-conflicts-rho020-r2-041-92fc7.18d467c6bba1ea3c,"reason=Pulled count=1 msg=Container image ""busybox:musl"" already present on machine"
0.4133,Event,ADDED,eval-conflicts-rho020-r2-041-92fc7.18d467c6bd3c7686,reason=Created count=1 msg=Created container: task
0.4134,Event,ADDED,eval-conflicts-rho020-r2-041-92fc7.18d467c6bf3cbb79,reason=Started count=1 msg=Started container task
0.4136,Event,ADDED,eval-conflicts-rho020-r2-041.18d467c69ad91ddb,reason=SuccessfulCreate count=1 msg=Created pod: eval-conflicts-rho020-r2-041-92fc7
0.4138,Event,ADDED,eval-conflicts-rho020-r2-041.18d467ca03c19278,reason=Completed count=1 msg=Job completed
0.4139,Event,ADDED,eval-conflicts-rho020-r2-042-qhtqj.18d467c6d79fb175,reason=Scheduled count=None msg=Successfully assigned compute/eval-conflicts-rho020-r2-042-qhtqj to kind-worker2
0.4141,Event,ADDED,eval-conflicts-rho020-r2-042-qhtqj.18d467c6f0c40125,"reason=Pulled count=1 msg=Container image ""busybox:musl"" already present on machine"
0.4143,Event,ADDED,eval-conflicts-rho020-r2-042-qhtqj.18d467c6f1d73c42,reason=Created count=1 msg=Created container: task
0.4144,Event,ADDED,eval-conflicts-rho020-r2-042-qhtqj.18d467c6f59ea94c,reason=Started count=1 msg=Started container task
0.4146,Event,ADDED,eval-conflicts-rho020-r2-042.18d467c6d6839a22,reason=SuccessfulCreate count=1 msg=Created pod: eval-conflicts-rho020-r2-042-qhtqj
0.4149,Event,ADDED,eval-conflicts-rho020-r2-042.18d467ca03e2cca6,reason=Completed count=1 msg=Job completed
0.4152,Event,ADDED,eval-conflicts-rho020-r2-043-f69x9.18d467c7130bc185,reason=Scheduled count=None msg=Successfully assigned compute/eval-conflicts-rho020-r2-043-f69x9 to kind-worker5
0.4154,Event,ADDED,eval-conflicts-rho020-r2-043-f69x9.18d467c72b699973,"reason=Pulled count=1 msg=Container image ""busybox:musl"" already present on machine"
0.4155,Event,ADDED,eval-conflicts-rho020-r2-043-f69x9.18d467c72c807dd4,reason=Created count=1 msg=Created container: task
0.4159,Event,ADDED,eval-conflicts-rho020-r2-043-f69x9.18d467c72e80740e,reason=Started count=1 msg=Started container task
0.4161,Event,ADDED,eval-conflicts-rho020-r2-043.18d467c71230f129,reason=SuccessfulCreate count=1 msg=Created pod: eval-conflicts-rho020-r2-043-f69x9
0.4163,Event,ADDED,eval-conflicts-rho020-r2-043.18d467ca50fa2cd6,reason=Completed count=1 msg=Job completed
0.4165,Event,ADDED,eval-conflicts-rho020-r2-044-tch7k.18d467c74e6fd081,reason=Scheduled count=None msg=Successfully assigned compute/eval-conflicts-rho020-r2-044-tch7k to kind-worker5
0.4168,Event,ADDED,eval-conflicts-rho020-r2-044-tch7k.18d467c7676e8348,"reason=Pulled count=1 msg=Container image ""busybox:musl"" already present on machine"
0.417,Event,ADDED,eval-conflicts-rho020-r2-044-tch7k.18d467c768801c9f,reason=Created count=1 msg=Created container: task
0.4171,Event,ADDED,eval-conflicts-rho020-r2-044-tch7k.18d467c76c36b0a1,reason=Started count=1 msg=Started container task
0.4174,Event,ADDED,eval-conflicts-rho020-r2-044.18d467c74d989322,reason=SuccessfulCreate count=1 msg=Created pod: eval-conflicts-rho020-r2-044-tch7k
0.4175,Event,ADDED,eval-conflicts-rho020-r2-044.18d467ca8d19257b,reason=Completed count=1 msg=Job completed
0.4177,Event,ADDED,eval-conflicts-rho020-r2-045-bj8kx.18d467c78a3d259f,reason=Scheduled count=None msg=Successfully assigned compute/eval-conflicts-rho020-r2-045-bj8kx to kind-worker5
0.4179,Event,ADDED,eval-conflicts-rho020-r2-045-bj8kx.18d467c7a333a5b4,"reason=Pulled count=1 msg=Container image ""busybox:musl"" already present on machine"
0.418,Event,ADDED,eval-conflicts-rho020-r2-045-bj8kx.18d467c7a46373e5,reason=Created count=1 msg=Created container: task
0.4182,Event,ADDED,eval-conflicts-rho020-r2-045-bj8kx.18d467c7a7bbb97b,reason=Started count=1 msg=Started container task
0.4184,Event,ADDED,eval-conflicts-rho020-r2-045.18d467c78944cf2d,reason=SuccessfulCreate count=1 msg=Created pod: eval-conflicts-rho020-r2-045-bj8kx
0.4185,Event,ADDED,eval-conflicts-rho020-r2-045.18d467cac8bdbee3,reason=Completed count=1 msg=Job completed
0.4187,Event,ADDED,eval-conflicts-rho020-r2-046-nnbnv.18d467c7c5942255,reason=Scheduled count=None msg=Successfully assigned compute/eval-conflicts-rho020-r2-046-nnbnv to kind-worker5
0.4189,Event,ADDED,eval-conflicts-rho020-r2-046-nnbnv.18d467c7de491294,"reason=Pulled count=1 msg=Container image ""busybox:musl"" already present on machine"
0.419,Event,ADDED,eval-conflicts-rho020-r2-046-nnbnv.18d467c7df678289,reason=Created count=1 msg=Created container: task
0.4192,Event,ADDED,eval-conflicts-rho020-r2-046-nnbnv.18d467c7e1728797,reason=Started count=1 msg=Started container task
0.4194,Event,ADDED,eval-conflicts-rho020-r2-046.18d467c7c4c5e8f4,reason=SuccessfulCreate count=1 msg=Created pod: eval-conflicts-rho020-r2-046-nnbnv
0.4196,Event,ADDED,eval-conflicts-rho020-r2-046.18d467cb05257010,reason=Completed count=1 msg=Job completed
0.4197,Event,ADDED,eval-conflicts-rho020-r2-047-zbngq.18d467c8016805eb,reason=Scheduled count=None msg=Successfully assigned compute/eval-conflicts-rho020-r2-047-zbngq to kind-worker4
0.4199,Event,ADDED,eval-conflicts-rho020-r2-047-zbngq.18d467c81b3112a5,"reason=Pulled count=1 msg=Container image ""busybox:musl"" already present on machine"
0.42,Event,ADDED,eval-conflicts-rho020-r2-047-zbngq.18d467c81ca51da3,reason=Created count=1 msg=Created container: task
0.4204,Event,ADDED,eval-conflicts-rho020-r2-047-zbngq.18d467c81ea42d10,reason=Started count=1 msg=Started container task
0.4206,Event,ADDED,eval-conflicts-rho020-r2-047.18d467c8008a46a3,reason=SuccessfulCreate count=1 msg=Created pod: eval-conflicts-rho020-r2-047-zbngq
0.4208,Event,ADDED,eval-conflicts-rho020-r2-047.18d467cb3f0cf343,reason=Completed count=1 msg=Job completed
0.421,Event,ADDED,eval-conflicts-rho020-r2-048-hfqpv.18d467c83dcf58a4,reason=Scheduled count=None msg=Successfully assigned compute/eval-conflicts-rho020-r2-048-hfqpv to kind-worker4
0.4211,Event,ADDED,eval-conflicts-rho020-r2-048-hfqpv.18d467c8597fddf7,"reason=Pulled count=1 msg=Container image ""busybox:musl"" already present on machine"
0.4213,Event,ADDED,eval-conflicts-rho020-r2-048-hfqpv.18d467c85aac29e0,reason=Created count=1 msg=Created container: task
0.4215,Event,ADDED,eval-conflicts-rho020-r2-048-hfqpv.18d467c8603d8855,reason=Started count=1 msg=Started container task
0.4217,Event,ADDED,eval-conflicts-rho020-r2-048.18d467c83c8e2048,reason=SuccessfulCreate count=1 msg=Created pod: eval-conflicts-rho020-r2-048-hfqpv
0.4218,Event,ADDED,eval-conflicts-rho020-r2-048.18d467cb7ad92db5,reason=Completed count=1 msg=Job completed
0.4224,Event,ADDED,eval-conflicts-rho020-r2-049-gbk47.18d467c87a00ec6d,reason=Scheduled count=None msg=Successfully assigned compute/eval-conflicts-rho020-r2-049-gbk47 to kind-worker2
0.4227,Event,ADDED,eval-conflicts-rho020-r2-049-gbk47.18d467c893e89417,"reason=Pulled count=1 msg=Container image ""busybox:musl"" already present on machine"
0.4229,Event,ADDED,eval-conflicts-rho020-r2-049-gbk47.18d467c894f528e7,reason=Created count=1 msg=Created container: task
0.4231,Event,ADDED,eval-conflicts-rho020-r2-049-gbk47.18d467c89719b264,reason=Started count=1 msg=Started container task
0.4233,Event,ADDED,eval-conflicts-rho020-r2-049.18d467c87911a633,reason=SuccessfulCreate count=1 msg=Created pod: eval-conflicts-rho020-r2-049-gbk47
0.4235,Event,ADDED,eval-conflicts-rho020-r2-049.18d467cba642a5f4,reason=Completed count=1 msg=Job completed
0.4236,Event,ADDED,eval-conflicts-rho020-r2-050-lgj5l.18d467c8b4f99976,reason=Scheduled count=None msg=Successfully assigned compute/eval-conflicts-rho020-r2-050-lgj5l to kind-worker4
0.4238,Event,ADDED,eval-conflicts-rho020-r2-050-lgj5l.18d467c8cdec9988,"reason=Pulled count=1 msg=Container image ""busybox:musl"" already present on machine"
0.424,Event,ADDED,eval-conflicts-rho020-r2-050-lgj5l.18d467c8cf066c95,reason=Created count=1 msg=Created container: task
0.4243,Event,ADDED,eval-conflicts-rho020-r2-050-lgj5l.18d467c8d0fb65f2,reason=Started count=1 msg=Started container task
0.4245,Event,ADDED,eval-conflicts-rho020-r2-050.18d467c8b3bd412c,reason=SuccessfulCreate count=1 msg=Created pod: eval-conflicts-rho020-r2-050-lgj5l
0.4248,Event,ADDED,eval-conflicts-rho020-r2-050.18d467cbf2366b2e,reason=Completed count=1 msg=Job completed
0.4249,Event,ADDED,eval-conflicts-rho020-r2-051-ckjbf.18d467c8f03358b4,reason=Scheduled count=None msg=Successfully assigned compute/eval-conflicts-rho020-r2-051-ckjbf to kind-worker2
0.4252,Event,ADDED,eval-conflicts-rho020-r2-051-ckjbf.18d467c90a825043,"reason=Pulled count=1 msg=Container image ""busybox:musl"" already present on machine"
0.4254,Event,ADDED,eval-conflicts-rho020-r2-051-ckjbf.18d467c90b909229,reason=Created count=1 msg=Created container: task
0.4256,Event,ADDED,eval-conflicts-rho020-r2-051-ckjbf.18d467c90da89d0e,reason=Started count=1 msg=Started container task
0.4259,Event,ADDED,eval-conflicts-rho020-r2-051.18d467c8ef07a078,reason=SuccessfulCreate count=1 msg=Created pod: eval-conflicts-rho020-r2-051-ckjbf
0.4261,Event,ADDED,eval-conflicts-rho020-r2-051.18d467cc1dfebfa4,reason=Completed count=1 msg=Job completed
0.4262,Event,ADDED,eval-conflicts-rho020-r2-052-g95pw.18d467c92b00fb0f,reason=Scheduled count=None msg=Successfully assigned compute/eval-conflicts-rho020-r2-052-g95pw to kind-worker5
0.4264,Event,ADDED,eval-conflicts-rho020-r2-052-g95pw.18d467c94365ffe2,"reason=Pulled count=1 msg=Container image ""busybox:musl"" already present on machine"
0.4267,Event,ADDED,eval-conflicts-rho020-r2-052-g95pw.18d467c9447bc57d,reason=Created count=1 msg=Created container: task
0.427,Event,ADDED,eval-conflicts-rho020-r2-052-g95pw.18d467c946600b4e,reason=Started count=1 msg=Started container task
0.4273,Event,ADDED,eval-conflicts-rho020-r2-052.18d467c92a8b2a43,reason=SuccessfulCreate count=1 msg=Created pod: eval-conflicts-rho020-r2-052-g95pw
0.4276,Event,ADDED,eval-conflicts-rho020-r2-052.18d467cc6ba5988e,reason=Completed count=1 msg=Job completed
0.4277,Event,ADDED,eval-conflicts-rho020-r2-053-f42ch.18d467c9661d2a34,"reason=FailedScheduling count=None msg=0/6 nodes are available: 6 node(s) had untolerated taint(s). no new claims to deallocate, preemption: 0/6 nodes are available: 6 Preemption is not helpful for scheduling."
0.4279,Event,ADDED,eval-conflicts-rho020-r2-053-f42ch.18d467caeb86c91f,reason=Scheduled count=None msg=Successfully assigned compute/eval-conflicts-rho020-r2-053-f42ch to kind-worker3
0.4281,Event,ADDED,eval-conflicts-rho020-r2-053-f42ch.18d467cb07adc609,"reason=Pulled count=1 msg=Container image ""busybox:musl"" already present on machine"
0.4284,Event,ADDED,eval-conflicts-rho020-r2-053-f42ch.18d467cb09427e7d,reason=Created count=1 msg=Created container: task
0.4286,Event,ADDED,eval-conflicts-rho020-r2-053-f42ch.18d467cb0d39e5ed,reason=Started count=1 msg=Started container task
0.4287,Event,ADDED,eval-conflicts-rho020-r2-053.18d467c966131ee5,reason=SuccessfulCreate count=1 msg=Created pod: eval-conflicts-rho020-r2-053-f42ch
0.4289,Event,ADDED,eval-conflicts-rho020-r2-053.18d467ce593f0d24,reason=Completed count=1 msg=Job completed
0.4292,Event,ADDED,eval-conflicts-rho020-r2-054-xr4pr.18d467c9a1bfc7d4,"reason=FailedScheduling count=None msg=0/6 nodes are available: 6 node(s) had untolerated taint(s). no new claims to deallocate, preemption: 0/6 nodes are available: 6 Preemption is not helpful for scheduling."
0.4294,Event,ADDED,eval-conflicts-rho020-r2-054-xr4pr.18d467caec3edb40,reason=Scheduled count=None msg=Successfully assigned compute/eval-conflicts-rho020-r2-054-xr4pr to kind-worker3
0.4296,Event,ADDED,eval-conflicts-rho020-r2-054-xr4pr.18d467cb09eac6f7,"reason=Pulled count=1 msg=Container image ""busybox:musl"" already present on machine"
0.4298,Event,ADDED,eval-conflicts-rho020-r2-054-xr4pr.18d467cb0c7ff02a,reason=Created count=1 msg=Created container: task
0.43,Event,ADDED,eval-conflicts-rho020-r2-054-xr4pr.18d467cb0f0808ee,reason=Started count=1 msg=Started container task
0.4302,Event,ADDED,eval-conflicts-rho020-r2-054.18d467c9a1b36450,reason=SuccessfulCreate count=1 msg=Created pod: eval-conflicts-rho020-r2-054-xr4pr
0.4304,Event,ADDED,eval-conflicts-rho020-r2-054.18d467ce59a9215e,reason=Completed count=1 msg=Job completed
0.4306,Event,ADDED,eval-conflicts-rho020-r2-055-m4flf.18d467c9dd61b6b6,"reason=FailedScheduling count=None msg=0/6 nodes are available: 6 node(s) had untolerated taint(s). no new claims to deallocate, preemption: 0/6 nodes are available: 6 Preemption is not helpful for scheduling."
0.4307,Event,ADDED,eval-conflicts-rho020-r2-055-m4flf.18d467caec6dfcf8,reason=Scheduled count=None msg=Successfully assigned compute/eval-conflicts-rho020-r2-055-m4flf to kind-worker3
0.4309,Event,ADDED,eval-conflicts-rho020-r2-055-m4flf.18d467cb09e1d9dc,"reason=Pulled count=1 msg=Container image ""busybox:musl"" already present on machine"
0.4311,Event,ADDED,eval-conflicts-rho020-r2-055-m4flf.18d467cb0c1aaa59,reason=Created count=1 msg=Created container: task
0.4313,Event,ADDED,eval-conflicts-rho020-r2-055-m4flf.18d467cb0e5b686b,reason=Started count=1 msg=Started container task
0.4315,Event,ADDED,eval-conflicts-rho020-r2-055.18d467c9dd50ee83,reason=SuccessfulCreate count=1 msg=Created pod: eval-conflicts-rho020-r2-055-m4flf
0.4317,Event,ADDED,eval-conflicts-rho020-r2-055.18d467ce5a216259,reason=Completed count=1 msg=Job completed
0.4318,Event,ADDED,eval-conflicts-rho020-r2-056-pb6st.18d467ca18fe5626,"reason=FailedScheduling count=None msg=0/6 nodes are available: 6 node(s) had untolerated taint(s). no new claims to deallocate, preemption: 0/6 nodes are available: 6 Preemption is not helpful for scheduling."
0.432,Event,ADDED,eval-conflicts-rho020-r2-056-pb6st.18d467caeca38173,reason=Scheduled count=None msg=Successfully assigned compute/eval-conflicts-rho020-r2-056-pb6st to kind-worker3
0.4322,Event,ADDED,eval-conflicts-rho020-r2-056-pb6st.18d467cb0a27443f,"reason=Pulled count=1 msg=Container image ""busybox:musl"" already present on machine"
0.4324,Event,ADDED,eval-conflicts-rho020-r2-056-pb6st.18d467cb0d4bf92e,reason=Created count=1 msg=Created container: task
0.4326,Event,ADDED,eval-conflicts-rho020-r2-056-pb6st.18d467cb0fbffb34,reason=Started count=1 msg=Started container task
0.4329,Event,ADDED,eval-conflicts-rho020-r2-056.18d467ca18f4f466,reason=SuccessfulCreate count=1 msg=Created pod: eval-conflicts-rho020-r2-056-pb6st
0.4333,Event,ADDED,eval-conflicts-rho020-r2-056.18d467ce5896d72f,reason=Completed count=1 msg=Job completed
0.4336,Event,ADDED,eval-conflicts-rho020-r2-057-k8cb5.18d467ca575e0d64,"reason=FailedScheduling count=None msg=0/6 nodes are available: 6 node(s) had untolerated taint(s). no new claims to deallocate, preemption: 0/6 nodes are available: 6 Preemption is not helpful for scheduling."
0.4339,Event,ADDED,eval-conflicts-rho020-r2-057-k8cb5.18d467caec6ed115,"reason=FailedScheduling count=None msg=0/6 nodes are available: 1 c_wall violated: 1 conflicting context pair(s) with node memory, 5 node(s) had untolerated taint(s). no new claims to deallocate, preemption: 0/6 nodes are available: 1 No preemption victims found for incoming pod, 5 Preemption is not helpful for scheduling."
0.4342,Event,ADDED,eval-conflicts-rho020-r2-057-k8cb5.18d467caf221a20c,"reason=FailedScheduling count=None msg=0/6 nodes are available: 1 c_wall violated: 1 conflicting context pair(s) with node memory, 5 node(s) had untolerated taint(s). no new claims to deallocate, preemption: 0/6 nodes are available: 1 No preemption victims found for incoming pod, 5 Preemption is not helpful for scheduling."
0.4346,Event,ADDED,eval-conflicts-rho020-r2-057-k8cb5.18d467cb4aa425a9,"reason=FailedScheduling count=None msg=0/6 nodes are available: 1 c_wall violated: 2 conflicting context pair(s) with node memory, 5 node(s) had untolerated taint(s). no new claims to deallocate, preemption: 0/6 nodes are available: 1 No preemption victims found for incoming pod, 5 Preemption is not helpful for scheduling."
0.4347,Event,ADDED,eval-conflicts-rho020-r2-057-k8cb5.18d467cb50f9647f,reason=Scheduled count=None msg=Successfully assigned compute/eval-conflicts-rho020-r2-057-k8cb5 to kind-worker
0.4349,Event,ADDED,eval-conflicts-rho020-r2-057-k8cb5.18d467cb6a2f69b4,"reason=Pulled count=1 msg=Container image ""busybox:musl"" already present on machine"
0.4351,Event,ADDED,eval-conflicts-rho020-r2-057-k8cb5.18d467cb6bde884a,reason=Created count=1 msg=Created container: task
0.4355,Event,ADDED,eval-conflicts-rho020-r2-057-k8cb5.18d467cb7098399c,reason=Started count=1 msg=Started container task
0.4357,Event,ADDED,eval-conflicts-rho020-r2-057.18d467ca5755ad87,reason=SuccessfulCreate count=1 msg=Created pod: eval-conflicts-rho020-r2-057-k8cb5
0.4359,Event,ADDED,eval-conflicts-rho020-r2-057.18d467ce7f309736,reason=Completed count=1 msg=Job completed
0.4363,Event,ADDED,eval-conflicts-rho020-r2-058-67wdw.18d467ca905fcc35,"reason=FailedScheduling count=None msg=0/6 nodes are available: 6 node(s) had untolerated taint(s). no new claims to deallocate, preemption: 0/6 nodes are available: 6 Preemption is not helpful for scheduling."
0.4364,Event,ADDED,eval-conflicts-rho020-r2-058-67wdw.18d467caedc18f3c,reason=Scheduled count=None msg=Successfully assigned compute/eval-conflicts-rho020-r2-058-67wdw to kind-worker3
0.4366,Event,ADDED,eval-conflicts-rho020-r2-058-67wdw.18d467cb0a3daf8b,"reason=Pulled count=1 msg=Container image ""busybox:musl"" already present on machine"
0.4368,Event,ADDED,eval-conflicts-rho020-r2-058-67wdw.18d467cb0d336adc,reason=Created count=1 msg=Created container: task
0.4371,Event,ADDED,eval-conflicts-rho020-r2-058-67wdw.18d467cb0fc19705,reason=Started count=1 msg=Started container task
0.4373,Event,ADDED,eval-conflicts-rho020-r2-058.18d467ca904e6677,reason=SuccessfulCreate count=1 msg=Created pod: eval-conflicts-rho020-r2-058-67wdw
0.4375,Event,ADDED,eval-conflicts-rho020-r2-058.18d467ce58c11ce8,reason=Completed count=1 msg=Job completed
0.4377,Event,ADDED,eval-conflicts-rho020-r2-059-kxnsz.18d467caccbb5cd4,"reason=FailedScheduling count=None msg=0/6 nodes are available: 6 node(s) had untolerated taint(s). no new claims to deallocate, preemption: 0/6 nodes are available: 6 Preemption is not helpful for scheduling."
0.4379,Event,ADDED,eval-conflicts-rho020-r2-059-kxnsz.18d467caf157c436,"reason=FailedScheduling count=None msg=0/6 nodes are available: 1 c_wall violated: 1 conflicting context pair(s) with node memory, 5 node(s) had untolerated taint(s). no new claims to deallocate, preemption: 0/6 nodes are available: 1 No preemption victims found for incoming pod, 5 Preemption is not helpful for scheduling."
0.4381,Event,ADDED,eval-conflicts-rho020-r2-059-kxnsz.18d467caf2515a5e,"reason=FailedScheduling count=None msg=0/6 nodes are available: 1 c_wall violated: 1 conflicting context pair(s) with node memory, 5 node(s) had untolerated taint(s). no new claims to deallocate, preemption: 0/6 nodes are available: 1 No preemption victims found for incoming pod, 5 Preemption is not helpful for scheduling."
0.4383,Event,ADDED,eval-conflicts-rho020-r2-059-kxnsz.18d467cb4ba05188,reason=Scheduled count=None msg=Successfully assigned compute/eval-conflicts-rho020-r2-059-kxnsz to kind-worker
0.4384,Event,ADDED,eval-conflicts-rho020-r2-059-kxnsz.18d467cb6ae40bf5,"reason=Pulled count=1 msg=Container image ""busybox:musl"" already present on machine"
0.4386,Event,ADDED,eval-conflicts-rho020-r2-059-kxnsz.18d467cb6c7b5584,reason=Created count=1 msg=Created container: task
0.4388,Event,ADDED,eval-conflicts-rho020-r2-059-kxnsz.18d467cb7098397d,reason=Started count=1 msg=Started container task
0.439,Event,ADDED,eval-conflicts-rho020-r2-059.18d467caccb1ea2a,reason=SuccessfulCreate count=1 msg=Created pod: eval-conflicts-rho020-r2-059-kxnsz
0.4391,Event,ADDED,eval-conflicts-rho020-r2-059.18d467ce802a21a0,reason=Completed count=1 msg=Job completed
0.4393,Event,ADDED,eval-conflicts-rho020-r2-060-vrpvg.18d467cb07ef76d5,"reason=FailedScheduling count=None msg=0/6 nodes are available: 1 c_wall violated: 1 conflicting context pair(s) with node memory, 5 node(s) had untolerated taint(s). no new claims to deallocate, preemption: 0/6 nodes are available: 1 No preemption victims found for incoming pod, 5 Preemption is not helpful for scheduling."
0.4395,Event,ADDED,eval-conflicts-rho020-r2-060-vrpvg.18d467cb08a972f7,"reason=FailedScheduling count=None msg=0/6 nodes are available: 1 c_wall violated: 1 conflicting context pair(s) with node memory, 5 node(s) had untolerated taint(s). no new claims to deallocate, preemption: 0/6 nodes are available: 1 No preemption victims found for incoming pod, 5 Preemption is not helpful for scheduling."
0.4396,Event,ADDED,eval-conflicts-rho020-r2-060-vrpvg.18d467cb4b30c1b0,reason=Scheduled count=None msg=Successfully assigned compute/eval-conflicts-rho020-r2-060-vrpvg to kind-worker
0.4398,Event,ADDED,eval-conflicts-rho020-r2-060-vrpvg.18d467cb6657bb87,"reason=Pulled count=1 msg=Container image ""busybox:musl"" already present on machine"
0.4401,Event,ADDED,eval-conflicts-rho020-r2-060-vrpvg.18d467cb6792055b,reason=Created count=1 msg=Created container: task
0.4404,Event,ADDED,eval-conflicts-rho020-r2-060-vrpvg.18d467cb6a7017c3,reason=Started count=1 msg=Started container task
0.4405,Event,ADDED,eval-conflicts-rho020-r2-060.18d467cb07a1ccbf,reason=SuccessfulCreate count=1 msg=Created pod: eval-conflicts-rho020-r2-060-vrpvg
0.4407,Event,ADDED,eval-conflicts-rho020-r2-060.18d467ce7f4f908d,reason=Completed count=1 msg=Job completed
0.4409,Event,ADDED,eval-conflicts-rho020-r2-061-l5zdp.18d467cb45f9f700,reason=Scheduled count=None msg=Successfully assigned compute/eval-conflicts-rho020-r2-061-l5zdp to kind-worker3
0.4411,Event,ADDED,eval-conflicts-rho020-r2-061-l5zdp.18d467cb5fcbf616,"reason=Pulled count=1 msg=Container image ""busybox:musl"" already present on machine"
0.4413,Event,ADDED,eval-conflicts-rho020-r2-061-l5zdp.18d467cb61650934,reason=Created count=1 msg=Created container: task
0.4415,Event,ADDED,eval-conflicts-rho020-r2-061-l5zdp.18d467cb664ac2ec,reason=Started count=1 msg=Started container task
0.4416,Event,ADDED,eval-conflicts-rho020-r2-061.18d467cb45668279,reason=SuccessfulCreate count=1 msg=Created pod: eval-conflicts-rho020-r2-061-l5zdp
0.4418,Event,ADDED,eval-conflicts-rho020-r2-061.18d467ce94a04063,reason=Completed count=1 msg=Job completed
0.4419,Event,ADDED,eval-conflicts-rho020-r2-062-t6tbk.18d467cb805f6e8a,reason=Scheduled count=None msg=Successfully assigned compute/eval-conflicts-rho020-r2-062-t6tbk to kind-worker
0.4421,Event,ADDED,eval-conflicts-rho020-r2-062-t6tbk.18d467cb99c66d23,"reason=Pulled count=1 msg=Container image ""busybox:musl"" already present on machine"
0.4423,Event,ADDED,eval-conflicts-rho020-r2-062-t6tbk.18d467cb9ad5059b,reason=Created count=1 msg=Created container: task
0.4425,Event,ADDED,eval-conflicts-rho020-r2-062-t6tbk.18d467cb9cddbb21,reason=Started count=1 msg=Started container task
0.4427,Event,ADDED,eval-conflicts-rho020-r2-062.18d467cb7f7ecef1,reason=SuccessfulCreate count=1 msg=Created pod: eval-conflicts-rho020-r2-062-t6tbk
0.4431,Event,ADDED,eval-conflicts-rho020-r2-062.18d467cebb1f2b6d,reason=Completed count=1 msg=Job completed
0.4432,Event,ADDED,eval-conflicts-rho020-r2-063-nx4fg.18d467cbbaf79c1c,reason=Scheduled count=None msg=Successfully assigned compute/eval-conflicts-rho020-r2-063-nx4fg to kind-worker3
0.4434,Event,ADDED,eval-conflicts-rho020-r2-063-nx4fg.18d467cbd66ee0fe,"reason=Pulled count=1 msg=Container image ""busybox:musl"" already present on machine"
0.4436,Event,ADDED,eval-conflicts-rho020-r2-063-nx4fg.18d467cbd792894a,reason=Created count=1 msg=Created container: task
0.4439,Event,ADDED,eval-conflicts-rho020-r2-063-nx4fg.18d467cbd9a1c501,reason=Started count=1 msg=Started container task
0.4441,Event,ADDED,eval-conflicts-rho020-r2-063.18d467cbba4ed2cb,reason=SuccessfulCreate count=1 msg=Created pod: eval-conflicts-rho020-r2-063-nx4fg
0.4443,Event,ADDED,eval-conflicts-rho020-r2-063.18d467cf0cb8d6ac,reason=Completed count=1 msg=Job completed
0.4444,Event,ADDED,eval-conflicts-rho020-r2-064-s8lpj.18d467cbf68e52aa,reason=Scheduled count=None msg=Successfully assigned compute/eval-conflicts-rho020-r2-064-s8lpj to kind-worker3
0.4448,Event,ADDED,eval-conflicts-rho020-r2-064-s8lpj.18d467cc0fbcb5d1,"reason=Pulled count=1 msg=Container image ""busybox:musl"" already present on machine"
0.4451,Event,ADDED,eval-conflicts-rho020-r2-064-s8lpj.18d467cc10e9dd6f,reason=Created count=1 msg=Created container: task
0.4453,Event,ADDED,eval-conflicts-rho020-r2-064-s8lpj.18d467cc1422de5b,reason=Started count=1 msg=Started container task
0.4455,Event,ADDED,eval-conflicts-rho020-r2-064.18d467cbf5e14f14,reason=SuccessfulCreate count=1 msg=Created pod: eval-conflicts-rho020-r2-064-s8lpj
0.4457,Event,ADDED,eval-conflicts-rho020-r2-064.18d467cf488e865e,reason=Completed count=1 msg=Job completed
0.4459,Event,ADDED,eval-conflicts-rho020-r2-065-nlrhd.18d467cc31c7b354,reason=Scheduled count=None msg=Successfully assigned compute/eval-conflicts-rho020-r2-065-nlrhd to kind-worker
0.4461,Event,ADDED,eval-conflicts-rho020-r2-065-nlrhd.18d467cc4b4ed470,"reason=Pulled count=1 msg=Container image ""busybox:musl"" already present on machine"
0.4463,Event,ADDED,eval-conflicts-rho020-r2-065-nlrhd.18d467cc4c699f6e,reason=Created count=1 msg=Created container: task
0.4465,Event,ADDED,eval-conflicts-rho020-r2-065-nlrhd.18d467cc4f57a0f1,reason=Started count=1 msg=Started container task
0.4467,Event,ADDED,eval-conflicts-rho020-r2-065.18d467cc310e60a4,reason=SuccessfulCreate count=1 msg=Created pod: eval-conflicts-rho020-r2-065-nlrhd
0.4468,Event,ADDED,eval-conflicts-rho020-r2-065.18d467cf731f66d8,reason=Completed count=1 msg=Job completed
0.447,Event,ADDED,eval-conflicts-rho020-r2-066-pqd2w.18d467cc6db83658,reason=Scheduled count=None msg=Successfully assigned compute/eval-conflicts-rho020-r2-066-pqd2w to kind-worker
0.4473,Event,ADDED,eval-conflicts-rho020-r2-066-pqd2w.18d467cc86eba125,"reason=Pulled count=1 msg=Container image ""busybox:musl"" already present on machine"
0.4475,Event,ADDED,eval-conflicts-rho020-r2-066-pqd2w.18d467cc87f60383,reason=Created count=1 msg=Created container: task
0.4477,Event,ADDED,eval-conflicts-rho020-r2-066-pqd2w.18d467cc89dd1049,reason=Started count=1 msg=Started container task
0.4479,Event,ADDED,eval-conflicts-rho020-r2-066.18d467cc6d0c9392,reason=SuccessfulCreate count=1 msg=Created pod: eval-conflicts-rho020-r2-066-pqd2w
0.4481,Event,ADDED,eval-conflicts-rho020-r2-066.18d467cfae320333,reason=Completed count=1 msg=Job completed
0.4482,Event,ADDED,eval-conflicts-rho020-r2-067-q2c8d.18d467cca919f031,reason=Scheduled count=None msg=Successfully assigned compute/eval-conflicts-rho020-r2-067-q2c8d to kind-worker
0.4485,Event,ADDED,eval-conflicts-rho020-r2-067-q2c8d.18d467ccc3383afd,"reason=Pulled count=1 msg=Container image ""busybox:musl"" already present on machine"
0.4486,Event,ADDED,eval-conflicts-rho020-r2-067-q2c8d.18d467ccc4654ee4,reason=Created count=1 msg=Created container: task
0.4488,Event,ADDED,eval-conflicts-rho020-r2-067-q2c8d.18d467ccc657e63b,reason=Started count=1 msg=Started container task
0.449,Event,ADDED,eval-conflicts-rho020-r2-067.18d467cca86d6e13,reason=SuccessfulCreate count=1 msg=Created pod: eval-conflicts-rho020-r2-067-q2c8d
0.4491,Event,ADDED,eval-conflicts-rho020-r2-067.18d467cfe685ee92,reason=Completed count=1 msg=Job completed
0.4493,Event,ADDED,eval-conflicts-rho020-r2-068-qjwvp.18d467cce4f5cee8,reason=Scheduled count=None msg=Successfully assigned compute/eval-conflicts-rho020-r2-068-qjwvp to kind-worker
0.4495,Event,ADDED,eval-conflicts-rho020-r2-068-qjwvp.18d467ccfdbf552a,"reason=Pulled count=1 msg=Container image ""busybox:musl"" already present on machine"
0.4496,Event,ADDED,eval-conflicts-rho020-r2-068-qjwvp.18d467ccfed482c9,reason=Created count=1 msg=Created container: task
0.4498,Event,ADDED,eval-conflicts-rho020-r2-068-qjwvp.18d467cd00cc2fb5,reason=Started count=1 msg=Started container task
0.45,Event,ADDED,eval-conflicts-rho020-r2-068.18d467cce4309e2d,reason=SuccessfulCreate count=1 msg=Created pod: eval-conflicts-rho020-r2-068-qjwvp
0.4501,Event,ADDED,eval-conflicts-rho020-r2-068.18d467d0225fb68f,reason=Completed count=1 msg=Job completed
0.4503,Event,ADDED,eval-conflicts-rho020-r2-069-p6wzm.18d467cd20aaff7f,reason=Scheduled count=None msg=Successfully assigned compute/eval-conflicts-rho020-r2-069-p6wzm to kind-worker3
0.4505,Event,ADDED,eval-conflicts-rho020-r2-069-p6wzm.18d467cd397bd26a,"reason=Pulled count=1 msg=Container image ""busybox:musl"" already present on machine"
0.4506,Event,ADDED,eval-conflicts-rho020-r2-069-p6wzm.18d467cd3aa62b19,reason=Created count=1 msg=Created container: task
0.4508,Event,ADDED,eval-conflicts-rho020-r2-069-p6wzm.18d467cd3cd51221,reason=Started count=1 msg=Started container task
0.451,Event,ADDED,eval-conflicts-rho020-r2-069.18d467cd1fdca981,reason=SuccessfulCreate count=1 msg=Created pod: eval-conflicts-rho020-r2-069-p6wzm
0.4511,Event,ADDED,eval-conflicts-rho020-r2-069.18d467d075765998,reason=Completed count=1 msg=Job completed
0.4513,Event,ADDED,eval-conflicts-rho020-r2-070-5vwvr.18d467cd5b936f71,"reason=FailedScheduling count=None msg=0/6 nodes are available: 1 c_wall violated: 1 conflicting context pair(s) with node memory, 5 node(s) had untolerated taint(s). no new claims to deallocate, preemption: 0/6 nodes are available: 1 No preemption victims found for incoming pod, 5 Preemption is not helpful for scheduling."
0.4515,Event,ADDED,eval-conflicts-rho020-r2-070-5vwvr.18d467cd5c39b938,"reason=FailedScheduling count=None msg=0/6 nodes are available: 1 c_wall violated: 1 conflicting context pair(s) with node memory, 5 node(s) had untolerated taint(s). no new claims to deallocate, preemption: 0/6 nodes are available: 1 No preemption victims found for incoming pod, 5 Preemption is not helpful for scheduling."
0.4516,Event,ADDED,eval-conflicts-rho020-r2-070-5vwvr.18d467cdb6b4d476,reason=Scheduled count=None msg=Successfully assigned compute/eval-conflicts-rho020-r2-070-5vwvr to kind-worker2
0.4518,Event,ADDED,eval-conflicts-rho020-r2-070-5vwvr.18d467cdcff39c20,"reason=Pulled count=1 msg=Container image ""busybox:musl"" already present on machine"
0.452,Event,ADDED,eval-conflicts-rho020-r2-070-5vwvr.18d467cdd1799bda,reason=Created count=1 msg=Created container: task
0.4521,Event,ADDED,eval-conflicts-rho020-r2-070-5vwvr.18d467cdd3dda7e7,reason=Started count=1 msg=Started container task
0.4523,Event,ADDED,eval-conflicts-rho020-r2-070.18d467cd5b51dc24,reason=SuccessfulCreate count=1 msg=Created pod: eval-conflicts-rho020-r2-070-5vwvr
0.4525,Event,ADDED,eval-conflicts-rho020-r2-070.18d467d10ac6a587,reason=Completed count=1 msg=Job completed
0.4526,Event,ADDED,eval-conflicts-rho020-r2-071-wbvlm.18d467cd974a3bbc,"reason=FailedScheduling count=None msg=0/6 nodes are available: 1 c_wall violated: 1 conflicting context pair(s) with node memory, 5 node(s) had untolerated taint(s). no new claims to deallocate, preemption: 0/6 nodes are available: 1 No preemption victims found for incoming pod, 5 Preemption is not helpful for scheduling."
0.4528,Event,ADDED,eval-conflicts-rho020-r2-071-wbvlm.18d467cd97e8c825,"reason=FailedScheduling count=None msg=0/6 nodes are available: 1 c_wall violated: 1 conflicting context pair(s) with node memory, 5 node(s) had untolerated taint(s). no new claims to deallocate, preemption: 0/6 nodes are available: 1 No preemption victims found for incoming pod, 5 Preemption is not helpful for scheduling."
0.453,Event,ADDED,eval-conflicts-rho020-r2-071-wbvlm.18d467cdb6e2dbcd,reason=Scheduled count=None msg=Successfully assigned compute/eval-conflicts-rho020-r2-071-wbvlm to kind-worker2
0.4531,Event,ADDED,eval-conflicts-rho020-r2-071-wbvlm.18d467cdd00bc521,"reason=Pulled count=1 msg=Container image ""busybox:musl"" already present on machine"
0.4533,Event,ADDED,eval-conflicts-rho020-r2-071-wbvlm.18d467cdd1d4fd52,reason=Created count=1 msg=Created container: task
0.4534,Event,ADDED,eval-conflicts-rho020-r2-071-wbvlm.18d467cdd4349248,reason=Started count=1 msg=Started container task
0.4537,Event,ADDED,eval-conflicts-rho020-r2-071.18d467cd97046aac,reason=SuccessfulCreate count=1 msg=Created pod: eval-conflicts-rho020-r2-071-wbvlm
0.4539,Event,ADDED,eval-conflicts-rho020-r2-071.18d467d10ae44c1e,reason=Completed count=1 msg=Job completed
0.4541,Event,ADDED,eval-conflicts-rho020-r2-072-l9r92.18d467cdd3cdc7ff,reason=Scheduled count=None msg=Successfully assigned compute/eval-conflicts-rho020-r2-072-l9r92 to kind-worker4
0.4543,Event,ADDED,eval-conflicts-rho020-r2-072-l9r92.18d467cded23ec35,"reason=Pulled count=1 msg=Container image ""busybox:musl"" already present on machine"
0.4546,Event,ADDED,eval-conflicts-rho020-r2-072-l9r92.18d467cdee592e92,reason=Created count=1 msg=Created container: task
0.4548,Event,ADDED,eval-conflicts-rho020-r2-072-l9r92.18d467cdf06d37ea,reason=Started count=1 msg=Started container task
0.455,Event,ADDED,eval-conflicts-rho020-r2-072.18d467cdd270ab52,reason=SuccessfulCreate count=1 msg=Created pod: eval-conflicts-rho020-r2-072-l9r92
0.4552,Event,ADDED,eval-conflicts-rho020-r2-072.18d467d0da2f279c,reason=Completed count=1 msg=Job completed
0.4554,Event,ADDED,eval-conflicts-rho020-r2-073-5g77c.18d467ce0f92fd98,reason=Scheduled count=None msg=Successfully assigned compute/eval-conflicts-rho020-r2-073-5g77c to kind-worker5
0.4555,Event,ADDED,eval-conflicts-rho020-r2-073-5g77c.18d467ce29027b6c,"reason=Pulled count=1 msg=Container image ""busybox:musl"" already present on machine"
0.4557,Event,ADDED,eval-conflicts-rho020-r2-073-5g77c.18d467ce2a1c63cc,reason=Created count=1 msg=Created container: task
0.456,Event,ADDED,eval-conflicts-rho020-r2-073-5g77c.18d467ce2d6bdd27,reason=Started count=1 msg=Started container task
0.4562,Event,ADDED,eval-conflicts-rho020-r2-073.18d467ce0ebbc4f5,reason=SuccessfulCreate count=1 msg=Created pod: eval-conflicts-rho020-r2-073-5g77c
0.4563,Event,ADDED,eval-conflicts-rho020-r2-073.18d467d11707bef9,reason=Completed count=1 msg=Job completed
0.4565,Event,ADDED,eval-conflicts-rho020-r2-074-wjp2h.18d467ce4bb032ed,reason=Scheduled count=None msg=Successfully assigned compute/eval-conflicts-rho020-r2-074-wjp2h to kind-worker5
0.4571,Event,ADDED,eval-conflicts-rho020-r2-074-wjp2h.18d467ce649af52a,"reason=Pulled count=1 msg=Container image ""busybox:musl"" already present on machine"
0.4573,Event,ADDED,eval-conflicts-rho020-r2-074-wjp2h.18d467ce659f074d,reason=Created count=1 msg=Created container: task
0.4574,Event,ADDED,eval-conflicts-rho020-r2-074-wjp2h.18d467ce67e64498,reason=Started count=1 msg=Started container task
0.4576,Event,ADDED,eval-conflicts-rho020-r2-074.18d467ce4a993ba9,reason=SuccessfulCreate count=1 msg=Created pod: eval-conflicts-rho020-r2-074-wjp2h
0.458,Event,ADDED,eval-conflicts-rho020-r2-074.18d467d18eb67534,reason=Completed count=1 msg=Job completed
0.4582,Event,ADDED,eval-conflicts-rho020-r2-075-86cv7.18d467ce87b12882,reason=Scheduled count=None msg=Successfully assigned compute/eval-conflicts-rho020-r2-075-86cv7 to kind-worker5
0.4583,Event,ADDED,eval-conflicts-rho020-r2-075-86cv7.18d467cea18c7de5,"reason=Pulled count=1 msg=Container image ""busybox:musl"" already present on machine"
0.4586,Event,ADDED,eval-conflicts-rho020-r2-075-86cv7.18d467cea29d9868,reason=Created count=1 msg=Created container: task
0.4588,Event,ADDED,eval-conflicts-rho020-r2-075-86cv7.18d467cea9a8bfd9,reason=Started count=1 msg=Started container task
0.4589,Event,ADDED,eval-conflicts-rho020-r2-075.18d467ce869b0fa6,reason=SuccessfulCreate count=1 msg=Created pod: eval-conflicts-rho020-r2-075-86cv7
0.4591,Event,ADDED,eval-conflicts-rho020-r2-075.18d467d18ed3c983,reason=Completed count=1 msg=Job completed
0.4593,Event,ADDED,eval-conflicts-rho020-r2-076-lhfrt.18d467cec2cc2b00,reason=Scheduled count=None msg=Successfully assigned compute/eval-conflicts-rho020-r2-076-lhfrt to kind-worker5
0.4595,Event,ADDED,eval-conflicts-rho020-r2-076-lhfrt.18d467cede688d1b,"reason=Pulled count=1 msg=Container image ""busybox:musl"" already present on machine"
0.4596,Event,ADDED,eval-conflicts-rho020-r2-076-lhfrt.18d467cedfbf0698,reason=Created count=1 msg=Created container: task
0.4598,Event,ADDED,eval-conflicts-rho020-r2-076-lhfrt.18d467cee53ef777,reason=Started count=1 msg=Started container task
0.46,Event,ADDED,eval-conflicts-rho020-r2-076.18d467cec18b5c01,reason=SuccessfulCreate count=1 msg=Created pod: eval-conflicts-rho020-r2-076-lhfrt
0.4601,Event,ADDED,eval-conflicts-rho020-r2-076.18d467d2066ab50a,reason=Completed count=1 msg=Job completed
0.4603,Event,ADDED,eval-conflicts-rho020-r2-077-mgcfp.18d467cefe53c94d,reason=Scheduled count=None msg=Successfully assigned compute/eval-conflicts-rho020-r2-077-mgcfp to kind-worker2
0.4605,Event,ADDED,eval-conflicts-rho020-r2-077-mgcfp.18d467cf185c9dbc,"reason=Pulled count=1 msg=Container image ""busybox:musl"" already present on machine"
0.4606,Event,ADDED,eval-conflicts-rho020-r2-077-mgcfp.18d467cf19810908,reason=Created count=1 msg=Created container: task
0.4608,Event,ADDED,eval-conflicts-rho020-r2-077-mgcfp.18d467cf1ddca2fe,reason=Started count=1 msg=Started container task
0.461,Event,ADDED,eval-conflicts-rho020-r2-077.18d467cefd34b6aa,reason=SuccessfulCreate count=1 msg=Created pod: eval-conflicts-rho020-r2-077-mgcfp
0.4611,Event,ADDED,eval-conflicts-rho020-r2-077.18d467d22fa48d03,reason=Completed count=1 msg=Job completed
0.4613,Event,ADDED,eval-conflicts-rho020-r2-078-bc56l.18d467cf39beb8dd,reason=Scheduled count=None msg=Successfully assigned compute/eval-conflicts-rho020-r2-078-bc56l to kind-worker5
0.4615,Event,ADDED,eval-conflicts-rho020-r2-078-bc56l.18d467cf53e7eddc,"reason=Pulled count=1 msg=Container image ""busybox:musl"" already present on machine"
0.4616,Event,ADDED,eval-conflicts-rho020-r2-078-bc56l.18d467cf5501cb85,reason=Created count=1 msg=Created container: task
0.4618,Event,ADDED,eval-conflicts-rho020-r2-078-bc56l.18d467cf5a82d45b,reason=Started count=1 msg=Started container task
0.462,Event,ADDED,eval-conflicts-rho020-r2-078.18d467cf38d559c1,reason=SuccessfulCreate count=1 msg=Created pod: eval-conflicts-rho020-r2-078-bc56l
0.4621,Event,ADDED,eval-conflicts-rho020-r2-078.18d467d27e70a759,reason=Completed count=1 msg=Job completed
0.4623,Event,ADDED,eval-conflicts-rho020-r2-079-9n2fw.18d467cf75605970,reason=Scheduled count=None msg=Successfully assigned compute/eval-conflicts-rho020-r2-079-9n2fw to kind-worker5
0.4624,Event,ADDED,eval-conflicts-rho020-r2-079-9n2fw.18d467cf900b93cc,"reason=Pulled count=1 msg=Container image ""busybox:musl"" already present on machine"
0.4626,Event,ADDED,eval-conflicts-rho020-r2-079-9n2fw.18d467cf913e2976,reason=Created count=1 msg=Created container: task
0.4628,Event,ADDED,eval-conflicts-rho020-r2-079-9n2fw.18d467cf984f30a8,reason=Started count=1 msg=Started container task
0.463,Event,ADDED,eval-conflicts-rho020-r2-079.18d467cf7456e664,reason=SuccessfulCreate count=1 msg=Created pod: eval-conflicts-rho020-r2-079-9n2fw
0.4633,Event,ADDED,eval-conflicts-rho020-r2-079.18d467d2ba0ae547,reason=Completed count=1 msg=Job completed
0.4634,Event,ADDED,eval-conflicts-rho020-r2-080-fsv5n.18d467cfb103bcdd,reason=Scheduled count=None msg=Successfully assigned compute/eval-conflicts-rho020-r2-080-fsv5n to kind-worker2
0.4637,Event,ADDED,eval-conflicts-rho020-r2-080-fsv5n.18d467cfca5e5005,"reason=Pulled count=1 msg=Container image ""busybox:musl"" already present on machine"
0.4639,Event,ADDED,eval-conflicts-rho020-r2-080-fsv5n.18d467cfcb757f1a,reason=Created count=1 msg=Created container: task
0.464,Event,ADDED,eval-conflicts-rho020-r2-080-fsv5n.18d467cfcf9928ec,reason=Started count=1 msg=Started container task
0.4642,Event,ADDED,eval-conflicts-rho020-r2-080.18d467cfafe025db,reason=SuccessfulCreate count=1 msg=Created pod: eval-conflicts-rho020-r2-080-fsv5n
0.4644,Event,ADDED,eval-conflicts-rho020-r2-080.18d467d2e3e9dd12,reason=Completed count=1 msg=Job completed
0.4646,Event,ADDED,eval-conflicts-rho020-r2-081-sgbfr.18d467cfeee088fa,reason=Scheduled count=None msg=Successfully assigned compute/eval-conflicts-rho020-r2-081-sgbfr to kind-worker4
0.4648,Event,ADDED,eval-conflicts-rho020-r2-081-sgbfr.18d467d0088fdc40,"reason=Pulled count=1 msg=Container image ""busybox:musl"" already present on machine"
0.465,Event,ADDED,eval-conflicts-rho020-r2-081-sgbfr.18d467d009d51786,reason=Created count=1 msg=Created container: task
0.4651,Event,ADDED,eval-conflicts-rho020-r2-081-sgbfr.18d467d0105d4dee,reason=Started count=1 msg=Started container task
0.4653,Event,ADDED,eval-conflicts-rho020-r2-081.18d467cfeda8b0ea,reason=SuccessfulCreate count=1 msg=Created pod: eval-conflicts-rho020-r2-081-sgbfr
0.4655,Event,ADDED,eval-conflicts-rho020-r2-081.18d467d2f16e10a9,reason=Completed count=1 msg=Job completed
0.4656,Event,ADDED,eval-conflicts-rho020-r2-082-2twbv.18d467d027fd7b61,reason=Scheduled count=None msg=Successfully assigned compute/eval-conflicts-rho020-r2-082-2twbv to kind-worker
0.4658,Event,ADDED,eval-conflicts-rho020-r2-082-2twbv.18d467d0402f776f,"reason=Pulled count=1 msg=Container image ""busybox:musl"" already present on machine"
0.466,Event,ADDED,eval-conflicts-rho020-r2-082-2twbv.18d467d041622209,reason=Created count=1 msg=Created container: task
0.4661,Event,ADDED,eval-conflicts-rho020-r2-082-2twbv.18d467d0456727ab,reason=Started count=1 msg=Started container task
0.4663,Event,ADDED,eval-conflicts-rho020-r2-082.18d467d02753726a,reason=SuccessfulCreate count=1 msg=Created pod: eval-conflicts-rho020-r2-082-2twbv
0.4665,Event,ADDED,eval-conflicts-rho020-r2-082.18d467d3677d05b9,reason=Completed count=1 msg=Job completed
0.4666,Event,ADDED,eval-conflicts-rho020-r2-083-tzfmf.18d467d0650cab25,reason=Scheduled count=None msg=Successfully assigned compute/eval-conflicts-rho020-r2-083-tzfmf to kind-worker
0.4668,Event,ADDED,eval-conflicts-rho020-r2-083-tzfmf.18d467d0803a3d47,"reason=Pulled count=1 msg=Container image ""busybox:musl"" already present on machine"
0.4669,Event,ADDED,eval-conflicts-rho020-r2-083-tzfmf.18d467d0814e11b1,reason=Created count=1 msg=Created container: task
0.4671,Event,ADDED,eval-conflicts-rho020-r2-083-tzfmf.18d467d08bce2f3a,reason=Started count=1 msg=Started container task
0.4673,Event,ADDED,eval-conflicts-rho020-r2-083.18d467d0648c4787,reason=SuccessfulCreate count=1 msg=Created pod: eval-conflicts-rho020-r2-083-tzfmf
0.4675,Event,ADDED,eval-conflicts-rho020-r2-083.18d467d3a384a069,reason=Completed count=1 msg=Job completed
0.4677,Event,ADDED,eval-conflicts-rho020-r2-084-92wkp.18d467d09ef75175,"reason=FailedScheduling count=None msg=0/6 nodes are available: 1 c_wall violated: 1 conflicting context pair(s) with node memory, 5 node(s) had untolerated taint(s). no new claims to deallocate, preemption: 0/6 nodes are available: 1 No preemption victims found for incoming pod, 5 Preemption is not helpful for scheduling."
0.4679,Event,ADDED,eval-conflicts-rho020-r2-084-92wkp.18d467d09f894275,"reason=FailedScheduling count=None msg=0/6 nodes are available: 1 c_wall violated: 1 conflicting context pair(s) with node memory, 5 node(s) had untolerated taint(s). no new claims to deallocate, preemption: 0/6 nodes are available: 1 No preemption victims found for incoming pod, 5 Preemption is not helpful for scheduling."
0.468,Event,ADDED,eval-conflicts-rho020-r2-084-92wkp.18d467d2128e2621,reason=Scheduled count=None msg=Successfully assigned compute/eval-conflicts-rho020-r2-084-92wkp to kind-worker3
0.4682,Event,ADDED,eval-conflicts-rho020-r2-084-92wkp.18d467d22d8f3d3a,"reason=Pulled count=1 msg=Container image ""busybox:musl"" already present on machine"
0.4684,Event,ADDED,eval-conflicts-rho020-r2-084-92wkp.18d467d230006616,reason=Created count=1 msg=Created container: task
0.4685,Event,ADDED,eval-conflicts-rho020-r2-084-92wkp.18d467d238d04170,reason=Started count=1 msg=Started container task
0.4687,Event,ADDED,eval-conflicts-rho020-r2-084.18d467d09ead1f5e,reason=SuccessfulCreate count=1 msg=Created pod: eval-conflicts-rho020-r2-084-92wkp
0.4689,Event,ADDED,eval-conflicts-rho020-r2-084.18d467d55b7598f7,reason=Completed count=1 msg=Job completed
0.469,Event,ADDED,eval-conflicts-rho020-r2-085-ltxqb.18d467d0da2cb5bd,reason=Scheduled count=None msg=Successfully assigned compute/eval-conflicts-rho020-r2-085-ltxqb to kind-worker
0.4692,Event,ADDED,eval-conflicts-rho020-r2-085-ltxqb.18d467d0f37de52b,"reason=Pulled count=1 msg=Container image ""busybox:musl"" already present on machine"
0.4693,Event,ADDED,eval-conflicts-rho020-r2-085-ltxqb.18d467d0f4ab74cb,reason=Created count=1 msg=Created container: task
0.4695,Event,ADDED,eval-conflicts-rho020-r2-085-ltxqb.18d467d0f8ea26db,reason=Started count=1 msg=Started container task
0.4697,Event,ADDED,eval-conflicts-rho020-r2-085.18d467d0d9806447,reason=SuccessfulCreate count=1 msg=Created pod: eval-conflicts-rho020-r2-085-ltxqb
0.4698,Event,ADDED,eval-conflicts-rho020-r2-085.18d467d41ad70f38,reason=Completed count=1 msg=Job completed
0.47,Event,ADDED,eval-conflicts-rho020-r2-086-xzdz9.18d467d11726e323,"reason=FailedScheduling count=None msg=0/6 nodes are available: 1 c_wall violated: 1 conflicting context pair(s) with node memory, 5 node(s) had untolerated taint(s). no new claims to deallocate, preemption: 0/6 nodes are available: 1 No preemption victims found for incoming pod, 5 Preemption is not helpful for scheduling."
0.4702,Event,ADDED,eval-conflicts-rho020-r2-086-xzdz9.18d467d117c64a92,"reason=FailedScheduling count=None msg=0/6 nodes are available: 1 c_wall violated: 1 conflicting context pair(s) with node memory, 5 node(s) had untolerated taint(s). no new claims to deallocate, preemption: 0/6 nodes are available: 1 No preemption victims found for incoming pod, 5 Preemption is not helpful for scheduling."
0.4703,Event,ADDED,eval-conflicts-rho020-r2-086-xzdz9.18d467d21210af6b,reason=Scheduled count=None msg=Successfully assigned compute/eval-conflicts-rho020-r2-086-xzdz9 to kind-worker3
0.4705,Event,ADDED,eval-conflicts-rho020-r2-086-xzdz9.18d467d22d725d25,"reason=Pulled count=1 msg=Container image ""busybox:musl"" already present on machine"
0.4707,Event,ADDED,eval-conflicts-rho020-r2-086-xzdz9.18d467d22f7f357e,reason=Created count=1 msg=Created container: task
0.4708,Event,ADDED,eval-conflicts-rho020-r2-086-xzdz9.18d467d238d04166,reason=Started count=1 msg=Started container task
0.471,Event,ADDED,eval-conflicts-rho020-r2-086.18d467d116db7efe,reason=SuccessfulCreate count=1 msg=Created pod: eval-conflicts-rho020-r2-086-xzdz9
0.4711,Event,ADDED,eval-conflicts-rho020-r2-086.18d467d55b7bc08c,reason=Completed count=1 msg=Job completed
0.4713,Event,ADDED,eval-conflicts-rho020-r2-087-4hn8w.18d467d151447615,reason=Scheduled count=None msg=Successfully assigned compute/eval-conflicts-rho020-r2-087-4hn8w to kind-worker
0.4715,Event,ADDED,eval-conflicts-rho020-r2-087-4hn8w.18d467d169a7d497,"reason=Pulled count=1 msg=Container image ""busybox:musl"" already present on machine"
0.4717,Event,ADDED,eval-conflicts-rho020-r2-087-4hn8w.18d467d16abd77c7,reason=Created count=1 msg=Created container: task
0.4719,Event,ADDED,eval-conflicts-rho020-r2-087-4hn8w.18d467d16ee8830f,reason=Started count=1 msg=Started container task
0.472,Event,ADDED,eval-conflicts-rho020-r2-087.18d467d150ca5092,reason=SuccessfulCreate count=1 msg=Created pod: eval-conflicts-rho020-r2-087-4hn8w
0.4722,Event,ADDED,eval-conflicts-rho020-r2-087.18d467d492a9dc3a,reason=Completed count=1 msg=Job completed
0.4724,Event,ADDED,eval-conflicts-rho020-r2-088-b6s7f.18d467d18ce0afcb,reason=Scheduled count=None msg=Successfully assigned compute/eval-conflicts-rho020-r2-088-b6s7f to kind-worker
0.4725,Event,ADDED,eval-conflicts-rho020-r2-088-b6s7f.18d467d1a6c2b41a,"reason=Pulled count=1 msg=Container image ""busybox:musl"" already present on machine"
0.4727,Event,ADDED,eval-conflicts-rho020-r2-088-b6s7f.18d467d1aa1cecb7,reason=Created count=1 msg=Created container: task
0.4729,Event,ADDED,eval-conflicts-rho020-r2-088-b6s7f.18d467d1ae85e80b,reason=Started count=1 msg=Started container task
0.473,Event,ADDED,eval-conflicts-rho020-r2-088.18d467d18c3faf8f,reason=SuccessfulCreate count=1 msg=Created pod: eval-conflicts-rho020-r2-088-b6s7f
0.4732,Event,ADDED,eval-conflicts-rho020-r2-088.18d467d4ce4a9fc4,reason=Completed count=1 msg=Job completed
0.4733,Event,ADDED,eval-conflicts-rho020-r2-089-5bfkr.18d467d1c8ce8c15,reason=Scheduled count=None msg=Successfully assigned compute/eval-conflicts-rho020-r2-089-5bfkr to kind-worker
0.4735,Event,ADDED,eval-conflicts-rho020-r2-089-5bfkr.18d467d1e21e807d,"reason=Pulled count=1 msg=Container image ""busybox:musl"" already present on machine"
0.4738,Event,ADDED,eval-conflicts-rho020-r2-089-5bfkr.18d467d1e3338e34,reason=Created count=1 msg=Created container: task
0.4741,Event,ADDED,eval-conflicts-rho020-r2-089-5bfkr.18d467d1e523091d,reason=Started count=1 msg=Started container task
0.4744,Event,ADDED,eval-conflicts-rho020-r2-089.18d467d1c82e2b8f,reason=SuccessfulCreate count=1 msg=Created pod: eval-conflicts-rho020-r2-089-5bfkr
0.4746,Event,ADDED,eval-conflicts-rho020-r2-089.18d467d50a44bbf0,reason=Completed count=1 msg=Job completed
0.4748,Event,ADDED,eval-conflicts-rho020-r2-090-w8495.18d467d20573a031,"reason=FailedScheduling count=None msg=0/6 nodes are available: 1 c_wall violated: 1 conflicting context pair(s) with node memory, 5 node(s) had untolerated taint(s). no new claims to deallocate, preemption: 0/6 nodes are available: 1 No preemption victims found for incoming pod, 5 Preemption is not helpful for scheduling."
0.4754,Event,ADDED,eval-conflicts-rho020-r2-090-w8495.18d467d20691efb1,"reason=FailedScheduling count=None msg=0/6 nodes are available: 1 c_wall violated: 1 conflicting context pair(s) with node memory, 5 node(s) had untolerated taint(s). no new claims to deallocate, preemption: 0/6 nodes are available: 1 No preemption victims found for incoming pod, 5 Preemption is not helpful for scheduling."
0.4757,Event,ADDED,eval-conflicts-rho020-r2-090-w8495.18d467d211969c27,reason=Scheduled count=None msg=Successfully assigned compute/eval-conflicts-rho020-r2-090-w8495 to kind-worker3
0.476,Event,ADDED,eval-conflicts-rho020-r2-090-w8495.18d467d22d0e7046,"reason=Pulled count=1 msg=Container image ""busybox:musl"" already present on machine"
0.4762,Event,ADDED,eval-conflicts-rho020-r2-090-w8495.18d467d22efaf907,reason=Created count=1 msg=Created container: task
0.4765,Event,ADDED,eval-conflicts-rho020-r2-090-w8495.18d467d235c814ef,reason=Started count=1 msg=Started container task
0.4767,Event,ADDED,eval-conflicts-rho020-r2-090.18d467d2052e8360,reason=SuccessfulCreate count=1 msg=Created pod: eval-conflicts-rho020-r2-090-w8495
0.4768,Event,ADDED,eval-conflicts-rho020-r2-090.18d467d55b7c0caf,reason=Completed count=1 msg=Job completed
0.477,Event,ADDED,eval-conflicts-rho020-r2-091-q66c2.18d467d23fb6451f,reason=Scheduled count=None msg=Successfully assigned compute/eval-conflicts-rho020-r2-091-q66c2 to kind-worker
0.4772,Event,ADDED,eval-conflicts-rho020-r2-091-q66c2.18d467d25899ce0f,"reason=Pulled count=1 msg=Container image ""busybox:musl"" already present on machine"
0.4773,Event,ADDED,eval-conflicts-rho020-r2-091-q66c2.18d467d259c3fa28,reason=Created count=1 msg=Created container: task
0.4775,Event,ADDED,eval-conflicts-rho020-r2-091-q66c2.18d467d25e1c6ef5,reason=Started count=1 msg=Started container task
0.4779,Event,ADDED,eval-conflicts-rho020-r2-091.18d467d23ef7483d,reason=SuccessfulCreate count=1 msg=Created pod: eval-conflicts-rho020-r2-091-q66c2
0.478,Event,ADDED,eval-conflicts-rho020-r2-091.18d467d582488eb6,reason=Completed count=1 msg=Job completed
0.4782,Event,ADDED,eval-conflicts-rho020-r2-092-bkrgv.18d467d27caddcc2,reason=Scheduled count=None msg=Successfully assigned compute/eval-conflicts-rho020-r2-092-bkrgv to kind-worker3
0.4785,Event,ADDED,eval-conflicts-rho020-r2-092-bkrgv.18d467d296283016,"reason=Pulled count=1 msg=Container image ""busybox:musl"" already present on machine"
0.4787,Event,ADDED,eval-conflicts-rho020-r2-092-bkrgv.18d467d2976b0b1c,reason=Created count=1 msg=Created container: task
0.4789,Event,ADDED,eval-conflicts-rho020-r2-092-bkrgv.18d467d2997bc777,reason=Started count=1 msg=Started container task
0.479,Event,ADDED,eval-conflicts-rho020-r2-092.18d467d27c13ca12,reason=SuccessfulCreate count=1 msg=Created pod: eval-conflicts-rho020-r2-092-bkrgv
0.4794,Event,ADDED,eval-conflicts-rho020-r2-092.18d467d5d37aadb3,reason=Completed count=1 msg=Job completed
0.4796,Event,ADDED,eval-conflicts-rho020-r2-093-ph9lx.18d467d2b71d5f1e,reason=Scheduled count=None msg=Successfully assigned compute/eval-conflicts-rho020-r2-093-ph9lx to kind-worker5
0.4798,Event,ADDED,eval-conflicts-rho020-r2-093-ph9lx.18d467d2cfff4e67,"reason=Pulled count=1 msg=Container image ""busybox:musl"" already present on machine"
0.4799,Event,ADDED,eval-conflicts-rho020-r2-093-ph9lx.18d467d2d12abc80,reason=Created count=1 msg=Created container: task
0.4802,Event,ADDED,eval-conflicts-rho020-r2-093-ph9lx.18d467d2d3258ff8,reason=Started count=1 msg=Started container task
0.4804,Event,ADDED,eval-conflicts-rho020-r2-093.18d467d2b68d703c,reason=SuccessfulCreate count=1 msg=Created pod: eval-conflicts-rho020-r2-093-ph9lx
0.4806,Event,ADDED,eval-conflicts-rho020-r2-093.18d467d60004ae8b,reason=Completed count=1 msg=Job completed
0.4808,Event,ADDED,eval-conflicts-rho020-r2-094-j529b.18d467d2f2b2be4f,reason=Scheduled count=None msg=Successfully assigned compute/eval-conflicts-rho020-r2-094-j529b to kind-worker5
0.481,Event,ADDED,eval-conflicts-rho020-r2-094-j529b.18d467d30cf315ee,"reason=Pulled count=1 msg=Container image ""busybox:musl"" already present on machine"
0.4812,Event,ADDED,eval-conflicts-rho020-r2-094-j529b.18d467d30e35b7a4,reason=Created count=1 msg=Created container: task
0.4813,Event,ADDED,eval-conflicts-rho020-r2-094-j529b.18d467d311caf5fc,reason=Started count=1 msg=Started container task
0.4815,Event,ADDED,eval-conflicts-rho020-r2-094.18d467d2f1fb1c00,reason=SuccessfulCreate count=1 msg=Created pod: eval-conflicts-rho020-r2-094-j529b
0.4817,Event,ADDED,eval-conflicts-rho020-r2-094.18d467d63bfec5db,reason=Completed count=1 msg=Job completed
0.4819,Event,ADDED,eval-conflicts-rho020-r2-095-7x5zm.18d467d32fd7ad30,reason=Scheduled count=None msg=Successfully assigned compute/eval-conflicts-rho020-r2-095-7x5zm to kind-worker5
0.4821,Event,ADDED,eval-conflicts-rho020-r2-095-7x5zm.18d467d34a6e2e61,"reason=Pulled count=1 msg=Container image ""busybox:musl"" already present on machine"
0.4823,Event,ADDED,eval-conflicts-rho020-r2-095-7x5zm.18d467d34bf084a8,reason=Created count=1 msg=Created container: task
0.4824,Event,ADDED,eval-conflicts-rho020-r2-095-7x5zm.18d467d3527e508c,reason=Started count=1 msg=Started container task
0.4826,Event,ADDED,eval-conflicts-rho020-r2-095.18d467d32e8a5fb3,reason=SuccessfulCreate count=1 msg=Created pod: eval-conflicts-rho020-r2-095-7x5zm
0.4828,Event,ADDED,eval-conflicts-rho020-r2-095.18d467d6770a3893,reason=Completed count=1 msg=Job completed
0.4829,Event,ADDED,eval-conflicts-rho020-r2-096-v4kxw.18d467d36a91b55b,reason=Scheduled count=None msg=Successfully assigned compute/eval-conflicts-rho020-r2-096-v4kxw to kind-worker5
0.4831,Event,ADDED,eval-conflicts-rho020-r2-096-v4kxw.18d467d383bc322c,"reason=Pulled count=1 msg=Container image ""busybox:musl"" already present on machine"
0.4832,Event,ADDED,eval-conflicts-rho020-r2-096-v4kxw.18d467d384c8bf66,reason=Created count=1 msg=Created container: task
0.4834,Event,ADDED,eval-conflicts-rho020-r2-096-v4kxw.18d467d386e0234b,reason=Started count=1 msg=Started container task
0.4836,Event,ADDED,eval-conflicts-rho020-r2-096.18d467d369a35c85,reason=SuccessfulCreate count=1 msg=Created pod: eval-conflicts-rho020-r2-096-v4kxw
0.4837,Event,ADDED,eval-conflicts-rho020-r2-096.18d467d6b3139724,reason=Completed count=1 msg=Job completed
0.4839,Event,ADDED,eval-conflicts-rho020-r2-097-dc64t.18d467d3a57d0590,reason=Scheduled count=None msg=Successfully assigned compute/eval-conflicts-rho020-r2-097-dc64t to kind-worker5
0.4841,Event,ADDED,eval-conflicts-rho020-r2-097-dc64t.18d467d3bf22d42e,"reason=Pulled count=1 msg=Container image ""busybox:musl"" already present on machine"
0.4842,Event,ADDED,eval-conflicts-rho020-r2-097-dc64t.18d467d3c0319891,reason=Created count=1 msg=Created container: task
0.4845,Event,ADDED,eval-conflicts-rho020-r2-097-dc64t.18d467d3c2503810,reason=Started count=1 msg=Started container task
0.4848,Event,ADDED,eval-conflicts-rho020-r2-097.18d467d3a4b9156b,reason=SuccessfulCreate count=1 msg=Created pod: eval-conflicts-rho020-r2-097-dc64t
0.485,Event,ADDED,eval-conflicts-rho020-r2-097.18d467d6eefb70ae,reason=Completed count=1 msg=Job completed
0.4851,Event,ADDED,eval-conflicts-rho020-r2-098-rl5cj.18d467d3e1945c3a,"reason=FailedScheduling count=None msg=0/6 nodes are available: 1 c_wall violated: 2 conflicting context pair(s) with node memory, 1 c_wall violated: 3 conflicting context pair(s) with node memory, 4 node(s) had untolerated taint(s). no new claims to deallocate, preemption: 0/6 nodes are available: 2 No preemption victims found for incoming pod, 4 Preemption is not helpful for scheduling."
0.4853,Event,ADDED,eval-conflicts-rho020-r2-098-rl5cj.18d467d3e2313e62,"reason=FailedScheduling count=None msg=0/6 nodes are available: 1 c_wall violated: 2 conflicting context pair(s) with node memory, 1 c_wall violated: 3 conflicting context pair(s) with node memory, 4 node(s) had untolerated taint(s). no new claims to deallocate, preemption: 0/6 nodes are available: 2 No preemption victims found for incoming pod, 4 Preemption is not helpful for scheduling."
0.4855,Event,ADDED,eval-conflicts-rho020-r2-098-rl5cj.18d467d467c8bc26,"reason=FailedScheduling count=None msg=0/6 nodes are available: 1 c_wall violated: 3 conflicting context pair(s) with node memory, 5 node(s) had untolerated taint(s). no new claims to deallocate, preemption: 0/6 nodes are available: 1 No preemption victims found for incoming pod, 5 Preemption is not helpful for scheduling."
0.4857,Event,ADDED,eval-conflicts-rho020-r2-098-rl5cj.18d467d4dcba7228,reason=Scheduled count=None msg=Successfully assigned compute/eval-conflicts-rho020-r2-098-rl5cj to kind-worker2
0.4859,Event,ADDED,eval-conflicts-rho020-r2-098-rl5cj.18d467d4f6e478a9,"reason=Pulled count=1 msg=Container image ""busybox:musl"" already present on machine"
0.486,Event,ADDED,eval-conflicts-rho020-r2-098-rl5cj.18d467d4f8fdac6d,reason=Created count=1 msg=Created container: task
0.4862,Event,ADDED,eval-conflicts-rho020-r2-098-rl5cj.18d467d4fd38f41b,reason=Started count=1 msg=Started container task
0.4865,Event,ADDED,eval-conflicts-rho020-r2-098.18d467d3e11aa16f,reason=SuccessfulCreate count=1 msg=Created pod: eval-conflicts-rho020-r2-098-rl5cj
0.4868,Event,ADDED,eval-conflicts-rho020-r2-098.18d467d841d05e87,reason=Completed count=1 msg=Job completed
0.487,Event,ADDED,eval-conflicts-rho020-r2-099-kxkkt.18d467d41dbec9f4,"reason=FailedScheduling count=None msg=0/6 nodes are available: 2 c_wall violated: 1 conflicting context pair(s) with node memory, 4 node(s) had untolerated taint(s). no new claims to deallocate, preemption: 0/6 nodes are available: 2 No preemption victims found for incoming pod, 4 Preemption is not helpful for scheduling."
0.4872,Event,ADDED,eval-conflicts-rho020-r2-099-kxkkt.18d467d41e9a5056,"reason=FailedScheduling count=None msg=0/6 nodes are available: 2 c_wall violated: 1 conflicting context pair(s) with node memory, 4 node(s) had untolerated taint(s). no new claims to deallocate, preemption: 0/6 nodes are available: 2 No preemption victims found for incoming pod, 4 Preemption is not helpful for scheduling."
0.4876,Event,ADDED,eval-conflicts-rho020-r2-099-kxkkt.18d467d467f6e9b2,"reason=FailedScheduling count=None msg=0/6 nodes are available: 1 c_wall violated: 1 conflicting context pair(s) with node memory, 5 node(s) had untolerated taint(s). no new claims to deallocate, preemption: 0/6 nodes are available: 1 No preemption victims found for incoming pod, 5 Preemption is not helpful for scheduling."
0.4878,Event,ADDED,eval-conflicts-rho020-r2-099-kxkkt.18d467d4dceed253,reason=Scheduled count=None msg=Successfully assigned compute/eval-conflicts-rho020-r2-099-kxkkt to kind-worker2
0.488,Event,ADDED,eval-conflicts-rho020-r2-099-kxkkt.18d467d4f6ca125b,"reason=Pulled count=1 msg=Container image ""busybox:musl"" already present on machine"
0.4882,Event,ADDED,eval-conflicts-rho020-r2-099-kxkkt.18d467d4f8a85c1a,reason=Created count=1 msg=Created container: task
0.4885,Event,ADDED,eval-conflicts-rho020-r2-099-kxkkt.18d467d4fd023419,reason=Started count=1 msg=Started container task
0.4887,Event,ADDED,eval-conflicts-rho020-r2-099.18d467d41d498199,reason=SuccessfulCreate count=1 msg=Created pod: eval-conflicts-rho020-r2-099-kxkkt
0.4889,Event,ADDED,eval-conflicts-rho020-r2-099.18d467d84191f992,reason=Completed count=1 msg=Job completed
0.4894,Event,ADDED,eval-conflicts-rho020-r3-000-kpsmv.18d467dda0697789,reason=Scheduled count=None msg=Successfully assigned compute/eval-conflicts-rho020-r3-000-kpsmv to kind-worker5
0.4896,Event,ADDED,eval-conflicts-rho020-r3-000-kpsmv.18d467ddba375e3c,"reason=Pulled count=1 msg=Container image ""busybox:musl"" already present on machine"
0.4899,Event,ADDED,eval-conflicts-rho020-r3-000-kpsmv.18d467ddbb4305ec,reason=Created count=1 msg=Created container: task
0.49,Event,ADDED,eval-conflicts-rho020-r3-000-kpsmv.18d467ddbd39f9f2,reason=Started count=1 msg=Started container task
0.4904,Event,ADDED,eval-conflicts-rho020-r3-000.18d467dd9f856912,reason=SuccessfulCreate count=1 msg=Created pod: eval-conflicts-rho020-r3-000-kpsmv
0.4906,Event,ADDED,eval-conflicts-rho020-r3-000.18d467e0f7c68a21,reason=Completed count=1 msg=Job completed
0.4908,Event,ADDED,eval-conflicts-rho020-r3-001-25cjb.18d467ddda527929,reason=Scheduled count=None msg=Successfully assigned compute/eval-conflicts-rho020-r3-001-25cjb to kind-worker5
0.4912,Event,ADDED,eval-conflicts-rho020-r3-001-25cjb.18d467ddf448b7bd,"reason=Pulled count=1 msg=Container image ""busybox:musl"" already present on machine"
0.4914,Event,ADDED,eval-conflicts-rho020-r3-001-25cjb.18d467ddf554df99,reason=Created count=1 msg=Created container: task
0.4917,Event,ADDED,eval-conflicts-rho020-r3-001-25cjb.18d467ddf95163de,reason=Started count=1 msg=Started container task
0.4918,Event,ADDED,eval-conflicts-rho020-r3-001.18d467ddd94f9e26,reason=SuccessfulCreate count=1 msg=Created pod: eval-conflicts-rho020-r3-001-25cjb
0.4921,Event,ADDED,eval-conflicts-rho020-r3-001.18d467e133d597f6,reason=Completed count=1 msg=Job completed
0.4924,Event,ADDED,eval-conflicts-rho020-r3-002-w6rcb.18d467de15e4e951,reason=Scheduled count=None msg=Successfully assigned compute/eval-conflicts-rho020-r3-002-w6rcb to kind-worker
0.4926,Event,ADDED,eval-conflicts-rho020-r3-002-w6rcb.18d467de2fd700b1,"reason=Pulled count=1 msg=Container image ""busybox:musl"" already present on machine"
0.4928,Event,ADDED,eval-conflicts-rho020-r3-002-w6rcb.18d467de30f1f55e,reason=Created count=1 msg=Created container: task
0.4931,Event,ADDED,eval-conflicts-rho020-r3-002-w6rcb.18d467de32ea7450,reason=Started count=1 msg=Started container task
0.4933,Event,ADDED,eval-conflicts-rho020-r3-002.18d467de14dbc0e9,reason=SuccessfulCreate count=1 msg=Created pod: eval-conflicts-rho020-r3-002-w6rcb
0.4935,Event,ADDED,eval-conflicts-rho020-r3-002.18d467e1688b40da,reason=Completed count=1 msg=Job completed
0.4938,Event,ADDED,eval-conflicts-rho020-r3-003-7jw46.18d467de51d8516d,reason=Scheduled count=None msg=Successfully assigned compute/eval-conflicts-rho020-r3-003-7jw46 to kind-worker2
0.494,Event,ADDED,eval-conflicts-rho020-r3-003-7jw46.18d467de69dad5bc,"reason=Pulled count=1 msg=Container image ""busybox:musl"" already present on machine"
0.4942,Event,ADDED,eval-conflicts-rho020-r3-003-7jw46.18d467de6af952b2,reason=Created count=1 msg=Created container: task
0.4943,Event,ADDED,eval-conflicts-rho020-r3-003-7jw46.18d467de6cf2b9ce,reason=Started count=1 msg=Started container task
0.4947,Event,ADDED,eval-conflicts-rho020-r3-003.18d467de5114d393,reason=SuccessfulCreate count=1 msg=Created pod: eval-conflicts-rho020-r3-003-7jw46
0.4949,Event,ADDED,eval-conflicts-rho020-r3-003.18d467e197c0f735,reason=Completed count=1 msg=Job completed
0.4951,Event,ADDED,eval-conflicts-rho020-r3-004-j5cgg.18d467de8cf85287,reason=Scheduled count=None msg=Successfully assigned compute/eval-conflicts-rho020-r3-004-j5cgg to kind-worker2
0.4953,Event,ADDED,eval-conflicts-rho020-r3-004-j5cgg.18d467dea71f8c92,"reason=Pulled count=1 msg=Container image ""busybox:musl"" already present on machine"
0.4958,Event,ADDED,eval-conflicts-rho020-r3-004-j5cgg.18d467dea8249c68,reason=Created count=1 msg=Created container: task
0.496,Event,ADDED,eval-conflicts-rho020-r3-004-j5cgg.18d467deaa489fd8,reason=Started count=1 msg=Started container task
0.5001,Event,ADDED,eval-conflicts-rho020-r3-004.18d467de8c310960,reason=SuccessfulCreate count=1 msg=Created pod: eval-conflicts-rho020-r3-004-j5cgg
0.5004,Event,ADDED,eval-conflicts-rho020-r3-004.18d467e198784318,reason=Completed count=1 msg=Job completed
0.5006,Event,ADDED,eval-conflicts-rho020-r3-005-rml6v.18d467dec8e5325f,reason=Scheduled count=None msg=Successfully assigned compute/eval-conflicts-rho020-r3-005-rml6v to kind-worker2
0.5008,Event,ADDED,eval-conflicts-rho020-r3-005-rml6v.18d467dee2024b99,"reason=Pulled count=1 msg=Container image ""busybox:musl"" already present on machine"
0.5009,Event,ADDED,eval-conflicts-rho020-r3-005-rml6v.18d467dee30cf00d,reason=Created count=1 msg=Created container: task
0.5013,Event,ADDED,eval-conflicts-rho020-r3-005-rml6v.18d467dee50a7342,reason=Started count=1 msg=Started container task
0.5015,Event,ADDED,eval-conflicts-rho020-r3-005.18d467dec81a5362,reason=SuccessfulCreate count=1 msg=Created pod: eval-conflicts-rho020-r3-005-rml6v
0.5017,Event,ADDED,eval-conflicts-rho020-r3-005.18d467e20fd56059,reason=Completed count=1 msg=Job completed
0.5019,Event,ADDED,eval-conflicts-rho020-r3-006-qwmjc.18d467df03f5ed0b,reason=Scheduled count=None msg=Successfully assigned compute/eval-conflicts-rho020-r3-006-qwmjc to kind-worker4
0.5023,Event,ADDED,eval-conflicts-rho020-r3-006-qwmjc.18d467df1d909c37,"reason=Pulled count=1 msg=Container image ""busybox:musl"" already present on machine"
0.5025,Event,ADDED,eval-conflicts-rho020-r3-006-qwmjc.18d467df1eaf8198,reason=Created count=1 msg=Created container: task
0.5026,Event,ADDED,eval-conflicts-rho020-r3-006-qwmjc.18d467df20b6a044,reason=Started count=1 msg=Started container task
0.503,Event,ADDED,eval-conflicts-rho020-r3-006.18d467df034c78bf,reason=SuccessfulCreate count=1 msg=Created pod: eval-conflicts-rho020-r3-006-qwmjc
0.5032,Event,ADDED,eval-conflicts-rho020-r3-006.18d467e257263293,reason=Completed count=1 msg=Job completed
0.5033,Event,ADDED,eval-conflicts-rho020-r3-007-7tw65.18d467df3fe649b4,reason=Scheduled count=None msg=Successfully assigned compute/eval-conflicts-rho020-r3-007-7tw65 to kind-worker4
0.5035,Event,ADDED,eval-conflicts-rho020-r3-007-7tw65.18d467df59d45310,"reason=Pulled count=1 msg=Container image ""busybox:musl"" already present on machine"
0.5037,Event,ADDED,eval-conflicts-rho020-r3-007-7tw65.18d467df5b026837,reason=Created count=1 msg=Created container: task
0.5039,Event,ADDED,eval-conflicts-rho020-r3-007-7tw65.18d467df5ec74a9d,reason=Started count=1 msg=Started container task
0.504,Event,ADDED,eval-conflicts-rho020-r3-007.18d467df3ed74de4,reason=SuccessfulCreate count=1 msg=Created pod: eval-conflicts-rho020-r3-007-7tw65
0.5043,Event,ADDED,eval-conflicts-rho020-r3-007.18d467e2931b8666,reason=Completed count=1 msg=Job completed
0.5045,Event,ADDED,eval-conflicts-rho020-r3-008-h5khj.18d467df7bffd217,reason=Scheduled count=None msg=Successfully assigned compute/eval-conflicts-rho020-r3-008-h5khj to kind-worker2
0.5047,Event,ADDED,eval-conflicts-rho020-r3-008-h5khj.18d467df94fddb15,"reason=Pulled count=1 msg=Container image ""busybox:musl"" already present on machine"
0.5048,Event,ADDED,eval-conflicts-rho020-r3-008-h5khj.18d467df965071f9,reason=Created count=1 msg=Created container: task
0.5051,Event,ADDED,eval-conflicts-rho020-r3-008-h5khj.18d467df986ab79b,reason=Started count=1 msg=Started container task
0.5053,Event,ADDED,eval-conflicts-rho020-r3-008.18d467df7ac94d3c,reason=SuccessfulCreate count=1 msg=Created pod: eval-conflicts-rho020-r3-008-h5khj
0.5055,Event,ADDED,eval-conflicts-rho020-r3-008.18d467e2c2ac0de7,reason=Completed count=1 msg=Job completed
0.5057,Event,ADDED,eval-conflicts-rho020-r3-009-dqfjd.18d467dfb6fa5cb4,reason=Scheduled count=None msg=Successfully assigned compute/eval-conflicts-rho020-r3-009-dqfjd to kind-worker4
0.506,Event,ADDED,eval-conflicts-rho020-r3-009-dqfjd.18d467dfd07f2fbb,"reason=Pulled count=1 msg=Container image ""busybox:musl"" already present on machine"
0.5062,Event,ADDED,eval-conflicts-rho020-r3-009-dqfjd.18d467dfd18dd955,reason=Created count=1 msg=Created container: task
0.5063,Event,ADDED,eval-conflicts-rho020-r3-009-dqfjd.18d467dfd638a2ed,reason=Started count=1 msg=Started container task
0.5066,Event,ADDED,eval-conflicts-rho020-r3-009.18d467dfb6279b11,reason=SuccessfulCreate count=1 msg=Created pod: eval-conflicts-rho020-r3-009-dqfjd
0.5068,Event,ADDED,eval-conflicts-rho020-r3-009.18d467e30a72ecb3,reason=Completed count=1 msg=Job completed
0.507,Event,ADDED,eval-conflicts-rho020-r3-010-t5kmg.18d467dff234ce25,reason=Scheduled count=None msg=Successfully assigned compute/eval-conflicts-rho020-r3-010-t5kmg to kind-worker2
0.5071,Event,ADDED,eval-conflicts-rho020-r3-010-t5kmg.18d467e00b38e88b,"reason=Pulled count=1 msg=Container image ""busybox:musl"" already present on machine"
0.5073,Event,ADDED,eval-conflicts-rho020-r3-010-t5kmg.18d467e00c70df1e,reason=Created count=1 msg=Created container: task
0.5075,Event,ADDED,eval-conflicts-rho020-r3-010-t5kmg.18d467e010c78dae,reason=Started count=1 msg=Started container task
0.5076,Event,ADDED,eval-conflicts-rho020-r3-010.18d467dff165dea4,reason=SuccessfulCreate count=1 msg=Created pod: eval-conflicts-rho020-r3-010-t5kmg
0.5078,Event,ADDED,eval-conflicts-rho020-r3-010.18d467e33a8947e0,reason=Completed count=1 msg=Job completed
0.5081,Event,ADDED,eval-conflicts-rho020-r3-011-4qfj6.18d467e02e3647c5,reason=Scheduled count=None msg=Successfully assigned compute/eval-conflicts-rho020-r3-011-4qfj6 to kind-worker3
0.5084,Event,ADDED,eval-conflicts-rho020-r3-011-4qfj6.18d467e047f4997a,"reason=Pulled count=1 msg=Container image ""busybox:musl"" already present on machine"
0.5085,Event,ADDED,eval-conflicts-rho020-r3-011-4qfj6.18d467e04918c944,reason=Created count=1 msg=Created container: task
0.5088,Event,ADDED,eval-conflicts-rho020-r3-011-4qfj6.18d467e04d6fd730,reason=Started count=1 msg=Started container task
0.509,Event,ADDED,eval-conflicts-rho020-r3-011.18d467e02d74a05b,reason=SuccessfulCreate count=1 msg=Created pod: eval-conflicts-rho020-r3-011-4qfj6
0.5091,Event,ADDED,eval-conflicts-rho020-r3-011.18d467e396e77b80,reason=Completed count=1 msg=Job completed
0.5093,Event,ADDED,eval-conflicts-rho020-r3-012-sf9qv.18d467e06b6f10c4,reason=Scheduled count=None msg=Successfully assigned compute/eval-conflicts-rho020-r3-012-sf9qv to kind-worker2
0.5095,Event,ADDED,eval-conflicts-rho020-r3-012-sf9qv.18d467e08575e8a4,"reason=Pulled count=1 msg=Container image ""busybox:musl"" already present on machine"
0.5096,Event,ADDED,eval-conflicts-rho020-r3-012-sf9qv.18d467e086a03572,reason=Created count=1 msg=Created container: task
0.5098,Event,ADDED,eval-conflicts-rho020-r3-012-sf9qv.18d467e08fb6e50b,reason=Started count=1 msg=Started container task
0.51,Event,ADDED,eval-conflicts-rho020-r3-012.18d467e06a487b09,reason=SuccessfulCreate count=1 msg=Created pod: eval-conflicts-rho020-r3-012-sf9qv
0.5101,Event,ADDED,eval-conflicts-rho020-r3-012.18d467e3b257118f,reason=Completed count=1 msg=Job completed
0.5103,Event,ADDED,eval-conflicts-rho020-r3-013-hxkhf.18d467e0a5cd7ce8,reason=Scheduled count=None msg=Successfully assigned compute/eval-conflicts-rho020-r3-013-hxkhf to kind-worker3
0.5105,Event,ADDED,eval-conflicts-rho020-r3-013-hxkhf.18d467e0c8920e42,"reason=Pulled count=1 msg=Container image ""busybox:musl"" already present on machine"
0.5106,Event,ADDED,eval-conflicts-rho020-r3-013-hxkhf.18d467e0c9beb46e,reason=Created count=1 msg=Created container: task
0.5108,Event,ADDED,eval-conflicts-rho020-r3-013-hxkhf.18d467e0cdd22a41,reason=Started count=1 msg=Started container task
0.511,Event,ADDED,eval-conflicts-rho020-r3-013.18d467e0a52e7185,reason=SuccessfulCreate count=1 msg=Created pod: eval-conflicts-rho020-r3-013-hxkhf
0.5111,Event,ADDED,eval-conflicts-rho020-r3-013.18d467e40edd09f9,reason=Completed count=1 msg=Job completed
0.5113,Event,ADDED,eval-conflicts-rho020-r3-014-5gfzk.18d467e0e08b8657,"reason=FailedScheduling count=None msg=0/6 nodes are available: 1 c_wall violated: 1 conflicting context pair(s) with node memory, 5 node(s) had untolerated taint(s). no new claims to deallocate, preemption: 0/6 nodes are available: 1 No preemption victims found for incoming pod, 5 Preemption is not helpful for scheduling."
0.5115,Event,ADDED,eval-conflicts-rho020-r3-014-5gfzk.18d467e0e1182774,"reason=FailedScheduling count=None msg=0/6 nodes are available: 1 c_wall violated: 1 conflicting context pair(s) with node memory, 5 node(s) had untolerated taint(s). no new claims to deallocate, preemption: 0/6 nodes are available: 1 No preemption victims found for incoming pod, 5 Preemption is not helpful for scheduling."
0.5117,Event,ADDED,eval-conflicts-rho020-r3-014-5gfzk.18d467e2e58c22e8,reason=Scheduled count=None msg=Successfully assigned compute/eval-conflicts-rho020-r3-014-5gfzk to kind-worker
0.5119,Event,ADDED,eval-conflicts-rho020-r3-014-5gfzk.18d467e3036693aa,"reason=Pulled count=1 msg=Container image ""busybox:musl"" already present on machine"
0.5121,Event,ADDED,eval-conflicts-rho020-r3-014-5gfzk.18d467e3055472a8,reason=Created count=1 msg=Created container: task
0.5124,Event,ADDED,eval-conflicts-rho020-r3-014-5gfzk.18d467e3097c2f8a,reason=Started count=1 msg=Started container task
0.5127,Event,ADDED,eval-conflicts-rho020-r3-014.18d467e0e04a16b1,reason=SuccessfulCreate count=1 msg=Created pod: eval-conflicts-rho020-r3-014-5gfzk
0.5128,Event,ADDED,eval-conflicts-rho020-r3-014.18d467e6504896f5,reason=Completed count=1 msg=Job completed
0.513,Event,ADDED,eval-conflicts-rho020-r3-015-qr8g9.18d467e11c8d5dce,reason=Scheduled count=None msg=Successfully assigned compute/eval-conflicts-rho020-r3-015-qr8g9 to kind-worker3
0.5132,Event,ADDED,eval-conflicts-rho020-r3-015-qr8g9.18d467e135f7b083,"reason=Pulled count=1 msg=Container image ""busybox:musl"" already present on machine"
0.5135,Event,ADDED,eval-conflicts-rho020-r3-015-qr8g9.18d467e1374a47c3,reason=Created count=1 msg=Created container: task
0.5137,Event,ADDED,eval-conflicts-rho020-r3-015-qr8g9.18d467e13b924aa3,reason=Started count=1 msg=Started container task
0.5138,Event,ADDED,eval-conflicts-rho020-r3-015.18d467e11c02cd79,reason=SuccessfulCreate count=1 msg=Created pod: eval-conflicts-rho020-r3-015-qr8g9
0.514,Event,ADDED,eval-conflicts-rho020-r3-015.18d467e44a839f7b,reason=Completed count=1 msg=Job completed
0.5142,Event,ADDED,eval-conflicts-rho020-r3-016-4zm2p.18d467e1582b71ec,reason=Scheduled count=None msg=Successfully assigned compute/eval-conflicts-rho020-r3-016-4zm2p to kind-worker3
0.5144,Event,ADDED,eval-conflicts-rho020-r3-016-4zm2p.18d467e170efd8f5,"reason=Pulled count=1 msg=Container image ""busybox:musl"" already present on machine"
0.5146,Event,ADDED,eval-conflicts-rho020-r3-016-4zm2p.18d467e17209eadb,reason=Created count=1 msg=Created container: task
0.5148,Event,ADDED,eval-conflicts-rho020-r3-016-4zm2p.18d467e1740b4bf1,reason=Started count=1 msg=Started container task
0.5149,Event,ADDED,eval-conflicts-rho020-r3-016.18d467e15798a8d0,reason=SuccessfulCreate count=1 msg=Created pod: eval-conflicts-rho020-r3-016-4zm2p
0.5151,Event,ADDED,eval-conflicts-rho020-r3-016.18d467e486a04f84,reason=Completed count=1 msg=Job completed
0.5152,Event,ADDED,eval-conflicts-rho020-r3-017-7zr9f.18d467e193a50a9b,reason=Scheduled count=None msg=Successfully assigned compute/eval-conflicts-rho020-r3-017-7zr9f to kind-worker3
0.5154,Event,ADDED,eval-conflicts-rho020-r3-017-7zr9f.18d467e1ac2d44e0,"reason=Pulled count=1 msg=Container image ""busybox:musl"" already present on machine"
0.5156,Event,ADDED,eval-conflicts-rho020-r3-017-7zr9f.18d467e1ad4df2e3,reason=Created count=1 msg=Created container: task
0.5158,Event,ADDED,eval-conflicts-rho020-r3-017-7zr9f.18d467e1af5bdd4e,reason=Started count=1 msg=Started container task
0.5161,Event,ADDED,eval-conflicts-rho020-r3-017.18d467e193047624,reason=SuccessfulCreate count=1 msg=Created pod: eval-conflicts-rho020-r3-017-7zr9f
0.5164,Event,ADDED,eval-conflicts-rho020-r3-017.18d467e4c222dd5e,reason=Completed count=1 msg=Job completed
0.5165,Event,ADDED,eval-conflicts-rho020-r3-018-qrmwr.18d467e1cec8fcc1,"reason=FailedScheduling count=None msg=0/6 nodes are available: 1 c_wall violated: 1 conflicting context pair(s) with node memory, 5 node(s) had untolerated taint(s). no new claims to deallocate, preemption: 0/6 nodes are available: 1 No preemption victims found for incoming pod, 5 Preemption is not helpful for scheduling."
0.5167,Event,ADDED,eval-conflicts-rho020-r3-018-qrmwr.18d467e1cf78c362,"reason=FailedScheduling count=None msg=0/6 nodes are available: 1 c_wall violated: 1 conflicting context pair(s) with node memory, 5 node(s) had untolerated taint(s). no new claims to deallocate, preemption: 0/6 nodes are available: 1 No preemption victims found for incoming pod, 5 Preemption is not helpful for scheduling."
0.5171,Event,ADDED,eval-conflicts-rho020-r3-018-qrmwr.18d467e2e561342a,reason=Scheduled count=None msg=Successfully assigned compute/eval-conflicts-rho020-r3-018-qrmwr to kind-worker
0.5173,Event,ADDED,eval-conflicts-rho020-r3-018-qrmwr.18d467e30303b67c,"reason=Pulled count=1 msg=Container image ""busybox:musl"" already present on machine"
0.5175,Event,ADDED,eval-conflicts-rho020-r3-018-qrmwr.18d467e304f808a2,reason=Created count=1 msg=Created container: task
0.5178,Event,ADDED,eval-conflicts-rho020-r3-018-qrmwr.18d467e3091d77a2,reason=Started count=1 msg=Started container task
0.518,Event,ADDED,eval-conflicts-rho020-r3-018.18d467e1ce88711c,reason=SuccessfulCreate count=1 msg=Created pod: eval-conflicts-rho020-r3-018-qrmwr
0.5182,Event,ADDED,eval-conflicts-rho020-r3-018.18d467e650eaaecb,reason=Completed count=1 msg=Job completed
0.5183,Event,ADDED,eval-conflicts-rho020-r3-019-wlsqs.18d467e20af9ab0f,reason=Scheduled count=None msg=Successfully assigned compute/eval-conflicts-rho020-r3-019-wlsqs to kind-worker3
0.5188,Event,ADDED,eval-conflicts-rho020-r3-019-wlsqs.18d467e2252321da,"reason=Pulled count=1 msg=Container image ""busybox:musl"" already present on machine"
0.519,Event,ADDED,eval-conflicts-rho020-r3-019-wlsqs.18d467e226401237,reason=Created count=1 msg=Created container: task
0.5192,Event,ADDED,eval-conflicts-rho020-r3-019-wlsqs.18d467e228667ec9,reason=Started count=1 msg=Started container task
0.5194,Event,ADDED,eval-conflicts-rho020-r3-019.18d467e20a6fa43a,reason=SuccessfulCreate count=1 msg=Created pod: eval-conflicts-rho020-r3-019-wlsqs
0.5197,Event,ADDED,eval-conflicts-rho020-r3-019.18d467e53a263988,reason=Completed count=1 msg=Job completed
0.5199,Event,ADDED,eval-conflicts-rho020-r3-020-nljcn.18d467e246d25389,reason=Scheduled count=None msg=Successfully assigned compute/eval-conflicts-rho020-r3-020-nljcn to kind-worker3
0.5201,Event,ADDED,eval-conflicts-rho020-r3-020-nljcn.18d467e260864fad,"reason=Pulled count=1 msg=Container image ""busybox:musl"" already present on machine"
0.5204,Event,ADDED,eval-conflicts-rho020-r3-020-nljcn.18d467e261a83d87,reason=Created count=1 msg=Created container: task
0.5206,Event,ADDED,eval-conflicts-rho020-r3-020-nljcn.18d467e2638ef17e,reason=Started count=1 msg=Started container task
0.5208,Event,ADDED,eval-conflicts-rho020-r3-020.18d467e24625dd2e,reason=SuccessfulCreate count=1 msg=Created pod: eval-conflicts-rho020-r3-020-nljcn
0.521,Event,ADDED,eval-conflicts-rho020-r3-020.18d467e57607c96d,reason=Completed count=1 msg=Job completed
0.5213,Event,ADDED,eval-conflicts-rho020-r3-021-4dk4b.18d467e2818c42b4,"reason=FailedScheduling count=None msg=0/6 nodes are available: 6 node(s) had untolerated taint(s). no new claims to deallocate, preemption: 0/6 nodes are available: 6 Preemption is not helpful for scheduling."
0.5215,Event,ADDED,eval-conflicts-rho020-r3-021-4dk4b.18d467e2e5763e2f,"reason=FailedScheduling count=None msg=0/6 nodes are available: 1 c_wall violated: 1 conflicting context pair(s) with node memory, 5 node(s) had untolerated taint(s). no new claims to deallocate, preemption: 0/6 nodes are available: 1 No preemption victims found for incoming pod, 5 Preemption is not helpful for scheduling."
0.5217,Event,ADDED,eval-conflicts-rho020-r3-021-4dk4b.18d467e2e6996938,"reason=FailedScheduling count=None msg=0/6 nodes are available: 1 c_wall violated: 2 conflicting context pair(s) with node memory, 5 node(s) had untolerated taint(s). no new claims to deallocate, preemption: 0/6 nodes are available: 1 No preemption victims found for incoming pod, 5 Preemption is not helpful for scheduling."
0.522,Event,ADDED,eval-conflicts-rho020-r3-021-4dk4b.18d467e2e8b4ed03,"reason=FailedScheduling count=None msg=0/6 nodes are available: 1 c_wall violated: 2 conflicting context pair(s) with node memory, 5 node(s) had untolerated taint(s). no new claims to deallocate, preemption: 0/6 nodes are available: 1 No preemption victims found for incoming pod, 5 Preemption is not helpful for scheduling."
0.5222,Event,ADDED,eval-conflicts-rho020-r3-021-4dk4b.18d467e2fd461db8,reason=Scheduled count=None msg=Successfully assigned compute/eval-conflicts-rho020-r3-021-4dk4b to kind-worker4
0.5224,Event,ADDED,eval-conflicts-rho020-r3-021-4dk4b.18d467e3150db369,"reason=Pulled count=1 msg=Container image ""busybox:musl"" already present on machine"
0.5226,Event,ADDED,eval-conflicts-rho020-r3-021-4dk4b.18d467e316374ab9,reason=Created count=1 msg=Created container: task
0.5228,Event,ADDED,eval-conflicts-rho020-r3-021-4dk4b.18d467e319ea8518,reason=Started count=1 msg=Started container task
0.523,Event,ADDED,eval-conflicts-rho020-r3-021.18d467e2818286b3,reason=SuccessfulCreate count=1 msg=Created pod: eval-conflicts-rho020-r3-021-4dk4b
0.5231,Event,ADDED,eval-conflicts-rho020-r3-021.18d467e64fa2b7cf,reason=Completed count=1 msg=Job completed
0.5234,Event,ADDED,eval-conflicts-rho020-r3-022-jv5d6.18d467e2be3c9fc2,"reason=FailedScheduling count=None msg=0/6 nodes are available: 6 node(s) had untolerated taint(s). no new claims to deallocate, preemption: 0/6 nodes are available: 6 Preemption is not helpful for scheduling."
0.5236,Event,ADDED,eval-conflicts-rho020-r3-022-jv5d6.18d467e2e6baf186,reason=Scheduled count=None msg=Successfully assigned compute/eval-conflicts-rho020-r3-022-jv5d6 to kind-worker
0.5239,Event,ADDED,eval-conflicts-rho020-r3-022-jv5d6.18d467e303886451,"reason=Pulled count=1 msg=Container image ""busybox:musl"" already present on machine"
0.5243,Event,ADDED,eval-conflicts-rho020-r3-022-jv5d6.18d467e3058b60b1,reason=Created count=1 msg=Created container: task
0.5245,Event,ADDED,eval-conflicts-rho020-r3-022-jv5d6.18d467e309aa94e0,reason=Started count=1 msg=Started container task
0.5246,Event,ADDED,eval-conflicts-rho020-r3-022.18d467e2be327b2d,reason=SuccessfulCreate count=1 msg=Created pod: eval-conflicts-rho020-r3-022-jv5d6
0.5248,Event,ADDED,eval-conflicts-rho020-r3-022.18d467e64fd9b95a,reason=Completed count=1 msg=Job completed
0.5251,Event,ADDED,eval-conflicts-rho020-r3-023-2nb7k.18d467e2f973f2bb,reason=Scheduled count=None msg=Successfully assigned compute/eval-conflicts-rho020-r3-023-2nb7k to kind-worker
0.5253,Event,ADDED,eval-conflicts-rho020-r3-023-2nb7k.18d467e314439044,"reason=Pulled count=1 msg=Container image ""busybox:musl"" already present on machine"
0.5255,Event,ADDED,eval-conflicts-rho020-r3-023-2nb7k.18d467e3158339f2,reason=Created count=1 msg=Created container: task
0.5256,Event,ADDED,eval-conflicts-rho020-r3-023-2nb7k.18d467e3199de298,reason=Started count=1 msg=Started container task
0.5259,Event,ADDED,eval-conflicts-rho020-r3-023.18d467e2f8eda8ec,reason=SuccessfulCreate count=1 msg=Created pod: eval-conflicts-rho020-r3-023-2nb7k
0.526,Event,ADDED,eval-conflicts-rho020-r3-023.18d467e650e87055,reason=Completed count=1 msg=Job completed
0.5262,Event,ADDED,eval-conflicts-rho020-r3-024-9vf5c.18d467e334baf739,reason=Scheduled count=None msg=Successfully assigned compute/eval-conflicts-rho020-r3-024-9vf5c to kind-worker5
0.5264,Event,ADDED,eval-conflicts-rho020-r3-024-9vf5c.18d467e34e1cdf5c,"reason=Pulled count=1 msg=Container image ""busybox:musl"" already present on machine"
0.5266,Event,ADDED,eval-conflicts-rho020-r3-024-9vf5c.18d467e34f2943fa,reason=Created count=1 msg=Created container: task
0.5267,Event,ADDED,eval-conflicts-rho020-r3-024-9vf5c.18d467e351069bc1,reason=Started count=1 msg=Started container task
0.5269,Event,ADDED,eval-conflicts-rho020-r3-024.18d467e333ef7d17,reason=SuccessfulCreate count=1 msg=Created pod: eval-conflicts-rho020-r3-024-9vf5c
0.5271,Event,ADDED,eval-conflicts-rho020-r3-024.18d467e657689af6,reason=Completed count=1 msg=Job completed
0.5272,Event,ADDED,eval-conflicts-rho020-r3-025-tqx5b.18d467e371446dda,reason=Scheduled count=None msg=Successfully assigned compute/eval-conflicts-rho020-r3-025-tqx5b to kind-worker5
0.5274,Event,ADDED,eval-conflicts-rho020-r3-025-tqx5b.18d467e389ee5865,"reason=Pulled count=1 msg=Container image ""busybox:musl"" already present on machine"
0.5277,Event,ADDED,eval-conflicts-rho020-r3-025-tqx5b.18d467e38af87b6e,reason=Created count=1 msg=Created container: task
0.528,Event,ADDED,eval-conflicts-rho020-r3-025-tqx5b.18d467e38cff6adf,reason=Started count=1 msg=Started container task
0.5283,Event,ADDED,eval-conflicts-rho020-r3-025.18d467e36fecced2,reason=SuccessfulCreate count=1 msg=Created pod: eval-conflicts-rho020-r3-025-tqx5b
0.5285,Event,ADDED,eval-conflicts-rho020-r3-025.18d467e6ce4ffba5,reason=Completed count=1 msg=Job completed
0.5288,Event,ADDED,eval-conflicts-rho020-r3-026-k9ktx.18d467e3ac8ba522,reason=Scheduled count=None msg=Successfully assigned compute/eval-conflicts-rho020-r3-026-k9ktx to kind-worker4
0.529,Event,ADDED,eval-conflicts-rho020-r3-026-k9ktx.18d467e3c76c56e1,"reason=Pulled count=1 msg=Container image ""busybox:musl"" already present on machine"
0.5291,Event,ADDED,eval-conflicts-rho020-r3-026-k9ktx.18d467e3c8e0cf22,reason=Created count=1 msg=Created container: task
0.5293,Event,ADDED,eval-conflicts-rho020-r3-026-k9ktx.18d467e3cec8bd2d,reason=Started count=1 msg=Started container task
0.5297,Event,ADDED,eval-conflicts-rho020-r3-026.18d467e3ab7bfc9d,reason=SuccessfulCreate count=1 msg=Created pod: eval-conflicts-rho020-r3-026-k9ktx
0.5299,Event,ADDED,eval-conflicts-rho020-r3-026.18d467e702a5a31c,reason=Completed count=1 msg=Job completed
0.5301,Event,ADDED,eval-conflicts-rho020-r3-027-b4psj.18d467e3e8efde7e,reason=Scheduled count=None msg=Successfully assigned compute/eval-conflicts-rho020-r3-027-b4psj to kind-worker4
0.5305,Event,ADDED,eval-conflicts-rho020-r3-027-b4psj.18d467e401f849a2,"reason=Pulled count=1 msg=Container image ""busybox:musl"" already present on machine"
0.5307,Event,ADDED,eval-conflicts-rho020-r3-027-b4psj.18d467e403218026,reason=Created count=1 msg=Created container: task
0.5309,Event,ADDED,eval-conflicts-rho020-r3-027-b4psj.18d467e405114d86,reason=Started count=1 msg=Started container task
0.5311,Event,ADDED,eval-conflicts-rho020-r3-027.18d467e3e7f0ce6b,reason=SuccessfulCreate count=1 msg=Created pod: eval-conflicts-rho020-r3-027-b4psj
0.5314,Event,ADDED,eval-conflicts-rho020-r3-027.18d467e73eb934c5,reason=Completed count=1 msg=Job completed
0.5316,Event,ADDED,eval-conflicts-rho020-r3-028-dwhnc.18d467e423b7f047,reason=Scheduled count=None msg=Successfully assigned compute/eval-conflicts-rho020-r3-028-dwhnc to kind-worker5
0.5318,Event,ADDED,eval-conflicts-rho020-r3-028-dwhnc.18d467e43cda6184,"reason=Pulled count=1 msg=Container image ""busybox:musl"" already present on machine"
0.5319,Event,ADDED,eval-conflicts-rho020-r3-028-dwhnc.18d467e43df4d9a5,reason=Created count=1 msg=Created container: task
0.5323,Event,ADDED,eval-conflicts-rho020-r3-028-dwhnc.18d467e44001881d,reason=Started count=1 msg=Started container task
0.5326,Event,ADDED,eval-conflicts-rho020-r3-028.18d467e422905963,reason=SuccessfulCreate count=1 msg=Created pod: eval-conflicts-rho020-r3-028-dwhnc
0.533,Event,ADDED,eval-conflicts-rho020-r3-028.18d467e78202f8ee,reason=Completed count=1 msg=Job completed
0.5339,Event,ADDED,eval-conflicts-rho020-r3-029-br7qz.18d467e45fb50164,reason=Scheduled count=None msg=Successfully assigned compute/eval-conflicts-rho020-r3-029-br7qz to kind-worker5
0.5341,Event,ADDED,eval-conflicts-rho020-r3-029-br7qz.18d467e479f9a83c,"reason=Pulled count=1 msg=Container image ""busybox:musl"" already present on machine"
0.5343,Event,ADDED,eval-conflicts-rho020-r3-029-br7qz.18d467e47b145038,reason=Created count=1 msg=Created container: task
0.5345,Event,ADDED,eval-conflicts-rho020-r3-029-br7qz.18d467e47d4acfd0,reason=Started count=1 msg=Started container task
0.5348,Event,ADDED,eval-conflicts-rho020-r3-029.18d467e45e666cc3,reason=SuccessfulCreate count=1 msg=Created pod: eval-conflicts-rho020-r3-029-br7qz
0.535,Event,ADDED,eval-conflicts-rho020-r3-029.18d467e7be1971e1,reason=Completed count=1 msg=Job completed
0.5352,Event,ADDED,eval-conflicts-rho020-r3-030-k54gl.18d467e49b1ef029,reason=Scheduled count=None msg=Successfully assigned compute/eval-conflicts-rho020-r3-030-k54gl to kind-worker
0.5354,Event,ADDED,eval-conflicts-rho020-r3-030-k54gl.18d467e4b3ed4252,"reason=Pulled count=1 msg=Container image ""busybox:musl"" already present on machine"
0.5357,Event,ADDED,eval-conflicts-rho020-r3-030-k54gl.18d467e4b5096e15,reason=Created count=1 msg=Created container: task
0.5359,Event,ADDED,eval-conflicts-rho020-r3-030-k54gl.18d467e4b704fc58,reason=Started count=1 msg=Started container task
0.5361,Event,ADDED,eval-conflicts-rho020-r3-030.18d467e49a0ab723,reason=SuccessfulCreate count=1 msg=Created pod: eval-conflicts-rho020-r3-030-k54gl
0.5363,Event,ADDED,eval-conflicts-rho020-r3-030.18d467e7f40c644c,reason=Completed count=1 msg=Job completed
0.5365,Event,ADDED,eval-conflicts-rho020-r3-031-qb76b.18d467e4d6fb0fb8,reason=Scheduled count=None msg=Successfully assigned compute/eval-conflicts-rho020-r3-031-qb76b to kind-worker5
0.5366,Event,ADDED,eval-conflicts-rho020-r3-031-qb76b.18d467e4ef63fdac,"reason=Pulled count=1 msg=Container image ""busybox:musl"" already present on machine"
0.5368,Event,ADDED,eval-conflicts-rho020-r3-031-qb76b.18d467e4f06b798c,reason=Created count=1 msg=Created container: task
0.537,Event,ADDED,eval-conflicts-rho020-r3-031-qb76b.18d467e4f250700f,reason=Started count=1 msg=Started container task
0.5372,Event,ADDED,eval-conflicts-rho020-r3-031.18d467e4d58732f2,reason=SuccessfulCreate count=1 msg=Created pod: eval-conflicts-rho020-r3-031-qb76b
0.5373,Event,ADDED,eval-conflicts-rho020-r3-031.18d467e83600174a,reason=Completed count=1 msg=Job completed
0.5375,Event,ADDED,eval-conflicts-rho020-r3-032-l5wz8.18d467e511f8c17c,reason=Scheduled count=None msg=Successfully assigned compute/eval-conflicts-rho020-r3-032-l5wz8 to kind-worker
0.5377,Event,ADDED,eval-conflicts-rho020-r3-032-l5wz8.18d467e52b54c714,"reason=Pulled count=1 msg=Container image ""busybox:musl"" already present on machine"
0.5379,Event,ADDED,eval-conflicts-rho020-r3-032-l5wz8.18d467e52c829290,reason=Created count=1 msg=Created container: task
0.538,Event,ADDED,eval-conflicts-rho020-r3-032-l5wz8.18d467e5306aec53,reason=Started count=1 msg=Started container task
0.5382,Event,ADDED,eval-conflicts-rho020-r3-032.18d467e5110bd987,reason=SuccessfulCreate count=1 msg=Created pod: eval-conflicts-rho020-r3-032-l5wz8
0.5384,Event,ADDED,eval-conflicts-rho020-r3-032.18d467e86a1e432d,reason=Completed count=1 msg=Job completed
0.5387,Event,ADDED,eval-conflicts-rho020-r3-033-c7nl2.18d467e54d86b91c,reason=Scheduled count=None msg=Successfully assigned compute/eval-conflicts-rho020-r3-033-c7nl2 to kind-worker5
0.5389,Event,ADDED,eval-conflicts-rho020-r3-033-c7nl2.18d467e565d91116,"reason=Pulled count=1 msg=Container image ""busybox:musl"" already present on machine"
0.5391,Event,ADDED,eval-conflicts-rho020-r3-033-c7nl2.18d467e566f3798b,reason=Created count=1 msg=Created container: task
0.5393,Event,ADDED,eval-conflicts-rho020-r3-033-c7nl2.18d467e568faad78,reason=Started count=1 msg=Started container task
0.5395,Event,ADDED,eval-conflicts-rho020-r3-033.18d467e54c91f22f,reason=SuccessfulCreate count=1 msg=Created pod: eval-conflicts-rho020-r3-033-c7nl2
0.5396,Event,ADDED,eval-conflicts-rho020-r3-033.18d467e8add1733b,reason=Completed count=1 msg=Job completed
0.5398,Event,ADDED,eval-conflicts-rho020-r3-034-x5mvb.18d467e588be5855,reason=Scheduled count=None msg=Successfully assigned compute/eval-conflicts-rho020-r3-034-x5mvb to kind-worker2
0.54,Event,ADDED,eval-conflicts-rho020-r3-034-x5mvb.18d467e5a273bbb9,"reason=Pulled count=1 msg=Container image ""busybox:musl"" already present on machine"
0.5402,Event,ADDED,eval-conflicts-rho020-r3-034-x5mvb.18d467e5a38104d6,reason=Created count=1 msg=Created container: task
0.5404,Event,ADDED,eval-conflicts-rho020-r3-034-x5mvb.18d467e5a5881a19,reason=Started count=1 msg=Started container task
0.5406,Event,ADDED,eval-conflicts-rho020-r3-034.18d467e588510642,reason=SuccessfulCreate count=1 msg=Created pod: eval-conflicts-rho020-r3-034-x5mvb
0.5408,Event,ADDED,eval-conflicts-rho020-r3-034.18d467e8d534a180,reason=Completed count=1 msg=Job completed
0.541,Event,ADDED,eval-conflicts-rho020-r3-035-mbz8v.18d467e5c4761be2,reason=Scheduled count=None msg=Successfully assigned compute/eval-conflicts-rho020-r3-035-mbz8v to kind-worker2
0.5412,Event,ADDED,eval-conflicts-rho020-r3-035-mbz8v.18d467e5df052716,"reason=Pulled count=1 msg=Container image ""busybox:musl"" already present on machine"
0.5414,Event,ADDED,eval-conflicts-rho020-r3-035-mbz8v.18d467e5e01ae313,reason=Created count=1 msg=Created container: task
0.5415,Event,ADDED,eval-conflicts-rho020-r3-035-mbz8v.18d467e5e719fce6,reason=Started count=1 msg=Started container task
0.5417,Event,ADDED,eval-conflicts-rho020-r3-035.18d467e5c3cf462c,reason=SuccessfulCreate count=1 msg=Created pod: eval-conflicts-rho020-r3-035-mbz8v
0.5419,Event,ADDED,eval-conflicts-rho020-r3-035.18d467e9114e8a31,reason=Completed count=1 msg=Job completed
0.542,Event,ADDED,eval-conflicts-rho020-r3-036-dkn9d.18d467e5fffb2ecd,reason=Scheduled count=None msg=Successfully assigned compute/eval-conflicts-rho020-r3-036-dkn9d to kind-worker2
0.5424,Event,ADDED,eval-conflicts-rho020-r3-036-dkn9d.18d467e61a581024,"reason=Pulled count=1 msg=Container image ""busybox:musl"" already present on machine"
0.5426,Event,ADDED,eval-conflicts-rho020-r3-036-dkn9d.18d467e61ba6b850,reason=Created count=1 msg=Created container: task
0.5427,Event,ADDED,eval-conflicts-rho020-r3-036-dkn9d.18d467e61f58a53d,reason=Started count=1 msg=Started container task
0.5433,Event,ADDED,eval-conflicts-rho020-r3-036.18d467e5ff583425,reason=SuccessfulCreate count=1 msg=Created pod: eval-conflicts-rho020-r3-036-dkn9d
0.5435,Event,ADDED,eval-conflicts-rho020-r3-036.18d467e94cbcbc9e,reason=Completed count=1 msg=Job completed
0.5436,Event,ADDED,eval-conflicts-rho020-r3-037-gq6qx.18d467e63ba06ca3,reason=Scheduled count=None msg=Successfully assigned compute/eval-conflicts-rho020-r3-037-gq6qx to kind-worker2
0.5442,Event,ADDED,eval-conflicts-rho020-r3-037-gq6qx.18d467e655348301,"reason=Pulled count=1 msg=Container image ""busybox:musl"" already present on machine"
0.5444,Event,ADDED,eval-conflicts-rho020-r3-037-gq6qx.18d467e6567e6237,reason=Created count=1 msg=Created container: task
0.5446,Event,ADDED,eval-conflicts-rho020-r3-037-gq6qx.18d467e65f3e0906,reason=Started count=1 msg=Started container task
0.5448,Event,ADDED,eval-conflicts-rho020-r3-037.18d467e63b15eee7,reason=SuccessfulCreate count=1 msg=Created pod: eval-conflicts-rho020-r3-037-gq6qx
0.5451,Event,ADDED,eval-conflicts-rho020-r3-037.18d467e988d945c6,reason=Completed count=1 msg=Job completed
0.5452,Event,ADDED,eval-conflicts-rho020-r3-038-lcpdq.18d467e6778f6aa6,"reason=FailedScheduling count=None msg=0/6 nodes are available: 1 c_wall violated: 1 conflicting context pair(s) with node memory, 5 node(s) had untolerated taint(s). no new claims to deallocate, preemption: 0/6 nodes are available: 1 No preemption victims found for incoming pod, 5 Preemption is not helpful for scheduling."
0.5454,Event,ADDED,eval-conflicts-rho020-r3-038-lcpdq.18d467e6781c3f21,"reason=FailedScheduling count=None msg=0/6 nodes are available: 1 c_wall violated: 1 conflicting context pair(s) with node memory, 5 node(s) had untolerated taint(s). no new claims to deallocate, preemption: 0/6 nodes are available: 1 No preemption victims found for incoming pod, 5 Preemption is not helpful for scheduling."
0.5458,Event,ADDED,eval-conflicts-rho020-r3-038-lcpdq.18d467e73d444a29,"reason=FailedScheduling count=None msg=0/6 nodes are available: 2 c_wall violated: 1 conflicting context pair(s) with node memory, 4 node(s) had untolerated taint(s). no new claims to deallocate, preemption: 0/6 nodes are available: 2 No preemption victims found for incoming pod, 4 Preemption is not helpful for scheduling."
0.5459,Event,ADDED,eval-conflicts-rho020-r3-038-lcpdq.18d467e7b9064dd8,reason=Scheduled count=None msg=Successfully assigned compute/eval-conflicts-rho020-r3-038-lcpdq to kind-worker4
0.5461,Event,ADDED,eval-conflicts-rho020-r3-038-lcpdq.18d467e7d3f498c1,"reason=Pulled count=1 msg=Container image ""busybox:musl"" already present on machine"
0.5463,Event,ADDED,eval-conflicts-rho020-r3-038-lcpdq.18d467e7d594b2d8,reason=Created count=1 msg=Created container: task
0.5465,Event,ADDED,eval-conflicts-rho020-r3-038-lcpdq.18d467e7d9dce228,reason=Started count=1 msg=Started container task
0.5467,Event,ADDED,eval-conflicts-rho020-r3-038.18d467e6774e5f5f,reason=SuccessfulCreate count=1 msg=Created pod: eval-conflicts-rho020-r3-038-lcpdq
0.5468,Event,ADDED,eval-conflicts-rho020-r3-038.18d467eafbac87ae,reason=Completed count=1 msg=Job completed
0.547,Event,ADDED,eval-conflicts-rho020-r3-039-wcggr.18d467e6b33df476,"reason=FailedScheduling count=None msg=0/6 nodes are available: 1 c_wall violated: 1 conflicting context pair(s) with node memory, 5 node(s) had untolerated taint(s). no new claims to deallocate, preemption: 0/6 nodes are available: 1 No preemption victims found for incoming pod, 5 Preemption is not helpful for scheduling."
0.5472,Event,ADDED,eval-conflicts-rho020-r3-039-wcggr.18d467e6b3d2203d,"reason=FailedScheduling count=None msg=0/6 nodes are available: 1 c_wall violated: 1 conflicting context pair(s) with node memory, 5 node(s) had untolerated taint(s). no new claims to deallocate, preemption: 0/6 nodes are available: 1 No preemption victims found for incoming pod, 5 Preemption is not helpful for scheduling."
0.5473,Event,ADDED,eval-conflicts-rho020-r3-039-wcggr.18d467e7387ac6bd,reason=Scheduled count=None msg=Successfully assigned compute/eval-conflicts-rho020-r3-039-wcggr to kind-worker3
0.5475,Event,ADDED,eval-conflicts-rho020-r3-039-wcggr.18d467e751fc0796,"reason=Pulled count=1 msg=Container image ""busybox:musl"" already present on machine"
0.5477,Event,ADDED,eval-conflicts-rho020-r3-039-wcggr.18d467e7536b3cee,reason=Created count=1 msg=Created container: task
0.5478,Event,ADDED,eval-conflicts-rho020-r3-039-wcggr.18d467e7585f2e2b,reason=Started count=1 msg=Started container task
0.5481,Event,ADDED,eval-conflicts-rho020-r3-039.18d467e6b2fb68a3,reason=SuccessfulCreate count=1 msg=Created pod: eval-conflicts-rho020-r3-039-wcggr
0.5484,Event,ADDED,eval-conflicts-rho020-r3-039.18d467ea99ee2d8a,reason=Completed count=1 msg=Job completed
0.5486,Event,ADDED,eval-conflicts-rho020-r3-040-nrwrq.18d467e6ee902392,reason=Scheduled count=None msg=Successfully assigned compute/eval-conflicts-rho020-r3-040-nrwrq to kind-worker2
0.5488,Event,ADDED,eval-conflicts-rho020-r3-040-nrwrq.18d467e7076675c1,"reason=Pulled count=1 msg=Container image ""busybox:musl"" already present on machine"
0.549,Event,ADDED,eval-conflicts-rho020-r3-040-nrwrq.18d467e7087205ad,reason=Created count=1 msg=Created container: task
0.5491,Event,ADDED,eval-conflicts-rho020-r3-040-nrwrq.18d467e70a9360d8,reason=Started count=1 msg=Started container task
0.5493,Event,ADDED,eval-conflicts-rho020-r3-040.18d467e6ee119b74,reason=SuccessfulCreate count=1 msg=Created pod: eval-conflicts-rho020-r3-040-nrwrq
0.5495,Event,ADDED,eval-conflicts-rho020-r3-040.18d467ea3d200185,reason=Completed count=1 msg=Job completed
0.5497,Event,ADDED,eval-conflicts-rho020-r3-041-lmqgg.18d467e72a5da484,"reason=FailedScheduling count=None msg=0/6 nodes are available: 1 c_wall violated: 1 conflicting context pair(s) with node memory, 5 node(s) had untolerated taint(s). no new claims to deallocate, preemption: 0/6 nodes are available: 1 No preemption victims found for incoming pod, 5 Preemption is not helpful for scheduling."
0.5499,Event,ADDED,eval-conflicts-rho020-r3-041-lmqgg.18d467e72aee7dde,"reason=FailedScheduling count=None msg=0/6 nodes are available: 1 c_wall violated: 1 conflicting context pair(s) with node memory, 5 node(s) had untolerated taint(s). no new claims to deallocate, preemption: 0/6 nodes are available: 1 No preemption victims found for incoming pod, 5 Preemption is not helpful for scheduling."
0.55,Event,ADDED,eval-conflicts-rho020-r3-041-lmqgg.18d467e738a57cb6,reason=Scheduled count=None msg=Successfully assigned compute/eval-conflicts-rho020-r3-041-lmqgg to kind-worker3
0.5502,Event,ADDED,eval-conflicts-rho020-r3-041-lmqgg.18d467e752304de7,"reason=Pulled count=1 msg=Container image ""busybox:musl"" already present on machine"
0.5504,Event,ADDED,eval-conflicts-rho020-r3-041-lmqgg.18d467e7539ffba5,reason=Created count=1 msg=Created container: task
0.5505,Event,ADDED,eval-conflicts-rho020-r3-041-lmqgg.18d467e7585bcb2f,reason=Started count=1 msg=Started container task
0.5507,Event,ADDED,eval-conflicts-rho020-r3-041.18d467e72a18a30d,reason=SuccessfulCreate count=1 msg=Created pod: eval-conflicts-rho020-r3-041-lmqgg
0.5509,Event,ADDED,eval-conflicts-rho020-r3-041.18d467ea99d43a34,reason=Completed count=1 msg=Job completed
0.551,Event,ADDED,eval-conflicts-rho020-r3-042-xbczh.18d467e765e6ea64,"reason=FailedScheduling count=None msg=0/6 nodes are available: 2 c_wall violated: 1 conflicting context pair(s) with node memory, 4 node(s) had untolerated taint(s). no new claims to deallocate, preemption: 0/6 nodes are available: 2 No preemption victims found for incoming pod, 4 Preemption is not helpful for scheduling."
0.5512,Event,ADDED,eval-conflicts-rho020-r3-042-xbczh.18d467e766a11d13,"reason=FailedScheduling count=None msg=0/6 nodes are available: 2 c_wall violated: 1 conflicting context pair(s) with node memory, 4 node(s) had untolerated taint(s). no new claims to deallocate, preemption: 0/6 nodes are available: 2 No preemption victims found for incoming pod, 4 Preemption is not helpful for scheduling."
0.5514,Event,ADDED,eval-conflicts-rho020-r3-042-xbczh.18d467e7b2f7e5de,reason=Scheduled count=None msg=Successfully assigned compute/eval-conflicts-rho020-r3-042-xbczh to kind-worker4
0.5515,Event,ADDED,eval-conflicts-rho020-r3-042-xbczh.18d467e7cca1300c,"reason=Pulled count=1 msg=Container image ""busybox:musl"" already present on machine"
0.5517,Event,ADDED,eval-conflicts-rho020-r3-042-xbczh.18d467e7cf3b6544,reason=Created count=1 msg=Created container: task
0.5519,Event,ADDED,eval-conflicts-rho020-r3-042-xbczh.18d467e7d3616224,reason=Started count=1 msg=Started container task
0.552,Event,ADDED,eval-conflicts-rho020-r3-042.18d467e765794011,reason=SuccessfulCreate count=1 msg=Created pod: eval-conflicts-rho020-r3-042-xbczh
0.5524,Event,ADDED,eval-conflicts-rho020-r3-042.18d467eafabe0c4d,reason=Completed count=1 msg=Job completed
0.5525,Event,ADDED,eval-conflicts-rho020-r3-043-d5br4.18d467e7a127392f,"reason=FailedScheduling count=None msg=0/6 nodes are available: 2 c_wall violated: 1 conflicting context pair(s) with node memory, 4 node(s) had untolerated taint(s). no new claims to deallocate, preemption: 0/6 nodes are available: 2 No preemption victims found for incoming pod, 4 Preemption is not helpful for scheduling."
0.5528,Event,ADDED,eval-conflicts-rho020-r3-043-d5br4.18d467e7a1dfd410,"reason=FailedScheduling count=None msg=0/6 nodes are available: 2 c_wall violated: 1 conflicting context pair(s) with node memory, 4 node(s) had untolerated taint(s). no new claims to deallocate, preemption: 0/6 nodes are available: 2 No preemption victims found for incoming pod, 4 Preemption is not helpful for scheduling."
0.553,Event,ADDED,eval-conflicts-rho020-r3-043-d5br4.18d467e7b88f984a,reason=Scheduled count=None msg=Successfully assigned compute/eval-conflicts-rho020-r3-043-d5br4 to kind-worker4
0.5531,Event,ADDED,eval-conflicts-rho020-r3-043-d5br4.18d467e7d3770043,"reason=Pulled count=1 msg=Container image ""busybox:musl"" already present on machine"
0.5533,Event,ADDED,eval-conflicts-rho020-r3-043-d5br4.18d467e7d537f282,reason=Created count=1 msg=Created container: task
0.5535,Event,ADDED,eval-conflicts-rho020-r3-043-d5br4.18d467e7d9dce23c,reason=Started count=1 msg=Started container task
0.5536,Event,ADDED,eval-conflicts-rho020-r3-043.18d467e7a0cbe9a5,reason=SuccessfulCreate count=1 msg=Created pod: eval-conflicts-rho020-r3-043-d5br4
0.5538,Event,ADDED,eval-conflicts-rho020-r3-043.18d467eafae320c0,reason=Completed count=1 msg=Job completed
0.5547,Event,ADDED,eval-conflicts-rho020-r3-044-pgb5t.18d467e7dda5c600,reason=Scheduled count=None msg=Successfully assigned compute/eval-conflicts-rho020-r3-044-pgb5t to kind-worker4
0.555,Event,ADDED,eval-conflicts-rho020-r3-044-pgb5t.18d467e7f7260cce,"reason=Pulled count=1 msg=Container image ""busybox:musl"" already present on machine"
0.5552,Event,ADDED,eval-conflicts-rho020-r3-044-pgb5t.18d467e7f8730fad,reason=Created count=1 msg=Created container: task
0.5554,Event,ADDED,eval-conflicts-rho020-r3-044-pgb5t.18d467e7fc124ddb,reason=Started count=1 msg=Started container task
0.5557,Event,ADDED,eval-conflicts-rho020-r3-044.18d467e7dc6828c4,reason=SuccessfulCreate count=1 msg=Created pod: eval-conflicts-rho020-r3-044-pgb5t
0.5559,Event,ADDED,eval-conflicts-rho020-r3-044.18d467eb36ceefab,reason=Completed count=1 msg=Job completed
0.5561,Event,ADDED,eval-conflicts-rho020-r3-045-pd5f7.18d467e81888c994,reason=Scheduled count=None msg=Successfully assigned compute/eval-conflicts-rho020-r3-045-pd5f7 to kind-worker3
0.5564,Event,ADDED,eval-conflicts-rho020-r3-045-pd5f7.18d467e832074cd0,"reason=Pulled count=1 msg=Container image ""busybox:musl"" already present on machine"
0.5565,Event,ADDED,eval-conflicts-rho020-r3-045-pd5f7.18d467e83314cf40,reason=Created count=1 msg=Created container: task
0.5567,Event,ADDED,eval-conflicts-rho020-r3-045-pd5f7.18d467e83513b395,reason=Started count=1 msg=Started container task
0.5569,Event,ADDED,eval-conflicts-rho020-r3-045.18d467e817c53154,reason=SuccessfulCreate count=1 msg=Created pod: eval-conflicts-rho020-r3-045-pd5f7
0.5571,Event,ADDED,eval-conflicts-rho020-r3-045.18d467eb4c35f169,reason=Completed count=1 msg=Job completed
0.5573,Event,ADDED,eval-conflicts-rho020-r3-046-6txrg.18d467e85400adcf,"reason=FailedScheduling count=None msg=0/6 nodes are available: 2 c_wall violated: 1 conflicting context pair(s) with node memory, 4 node(s) had untolerated taint(s). no new claims to deallocate, preemption: 0/6 nodes are available: 2 No preemption victims found for incoming pod, 4 Preemption is not helpful for scheduling."
0.5575,Event,ADDED,eval-conflicts-rho020-r3-046-6txrg.18d467e854b5f539,"reason=FailedScheduling count=None msg=0/6 nodes are available: 2 c_wall violated: 1 conflicting context pair(s) with node memory, 4 node(s) had untolerated taint(s). no new claims to deallocate, preemption: 0/6 nodes are available: 2 No preemption victims found for incoming pod, 4 Preemption is not helpful for scheduling."
0.5577,Event,ADDED,eval-conflicts-rho020-r3-046-6txrg.18d467e890ffe474,"reason=FailedScheduling count=None msg=0/6 nodes are available: 1 c_wall violated: 1 conflicting context pair(s) with node memory, 1 c_wall violated: 2 conflicting context pair(s) with node memory, 4 node(s) had untolerated taint(s). no new claims to deallocate, preemption: 0/6 nodes are available: 2 No preemption victims found for incoming pod, 4 Preemption is not helpful for scheduling."
0.5579,Event,ADDED,eval-conflicts-rho020-r3-046-6txrg.18d467e98f39a38d,"reason=FailedScheduling count=None msg=0/6 nodes are available: 1 c_wall violated: 2 conflicting context pair(s) with node memory, 5 node(s) had untolerated taint(s). no new claims to deallocate, preemption: 0/6 nodes are available: 1 No preemption victims found for incoming pod, 5 Preemption is not helpful for scheduling."
0.558,Event,ADDED,eval-conflicts-rho020-r3-046-6txrg.18d467e9fb69ce20,reason=Scheduled count=None msg=Successfully assigned compute/eval-conflicts-rho020-r3-046-6txrg to kind-worker
0.5583,Event,ADDED,eval-conflicts-rho020-r3-046-6txrg.18d467ea14997ca6,"reason=Pulled count=1 msg=Container image ""busybox:musl"" already present on machine"
0.5585,Event,ADDED,eval-conflicts-rho020-r3-046-6txrg.18d467ea1614e7f1,reason=Created count=1 msg=Created container: task
0.5587,Event,ADDED,eval-conflicts-rho020-r3-046-6txrg.18d467ea19d73f32,reason=Started count=1 msg=Started container task
0.5589,Event,ADDED,eval-conflicts-rho020-r3-046.18d467e8538c2600,reason=SuccessfulCreate count=1 msg=Created pod: eval-conflicts-rho020-r3-046-6txrg
0.5591,Event,ADDED,eval-conflicts-rho020-r3-046.18d467ed52372b33,reason=Completed count=1 msg=Job completed
0.5593,Event,ADDED,eval-conflicts-rho020-r3-047-js28g.18d467e88fedf99d,reason=Scheduled count=None msg=Successfully assigned compute/eval-conflicts-rho020-r3-047-js28g to kind-worker4
0.5594,Event,ADDED,eval-conflicts-rho020-r3-047-js28g.18d467e8a927ba51,"reason=Pulled count=1 msg=Container image ""busybox:musl"" already present on machine"
0.5596,Event,ADDED,eval-conflicts-rho020-r3-047-js28g.18d467e8aa39d6ca,reason=Created count=1 msg=Created container: task
0.5598,Event,ADDED,eval-conflicts-rho020-r3-047-js28g.18d467e8af2e048d,reason=Started count=1 msg=Started container task
0.56,Event,ADDED,eval-conflicts-rho020-r3-047.18d467e88f0aa4ee,reason=SuccessfulCreate count=1 msg=Created pod: eval-conflicts-rho020-r3-047-js28g
0.5602,Event,ADDED,eval-conflicts-rho020-r3-047.18d467ebeace3951,reason=Completed count=1 msg=Job completed
0.5606,Event,ADDED,eval-conflicts-rho020-r3-048-rqzkl.18d467e8cb5d4b27,reason=Scheduled count=None msg=Successfully assigned compute/eval-conflicts-rho020-r3-048-rqzkl to kind-worker3
0.5608,Event,ADDED,eval-conflicts-rho020-r3-048-rqzkl.18d467e8e48c6daf,"reason=Pulled count=1 msg=Container image ""busybox:musl"" already present on machine"
0.561,Event,ADDED,eval-conflicts-rho020-r3-048-rqzkl.18d467e8e5a8cd89,reason=Created count=1 msg=Created container: task
0.5613,Event,ADDED,eval-conflicts-rho020-r3-048-rqzkl.18d467e8e7827b99,reason=Started count=1 msg=Started container task
0.5615,Event,ADDED,eval-conflicts-rho020-r3-048.18d467e8cab8fe70,reason=SuccessfulCreate count=1 msg=Created pod: eval-conflicts-rho020-r3-048-rqzkl
0.5617,Event,ADDED,eval-conflicts-rho020-r3-048.18d467ebff6609cd,reason=Completed count=1 msg=Job completed
0.5619,Event,ADDED,eval-conflicts-rho020-r3-049-2cm5b.18d467e907458358,reason=Scheduled count=None msg=Successfully assigned compute/eval-conflicts-rho020-r3-049-2cm5b to kind-worker4
0.5622,Event,ADDED,eval-conflicts-rho020-r3-049-2cm5b.18d467e920c22fc0,"reason=Pulled count=1 msg=Container image ""busybox:musl"" already present on machine"
0.5624,Event,ADDED,eval-conflicts-rho020-r3-049-2cm5b.18d467e921d4dd54,reason=Created count=1 msg=Created container: task
0.5625,Event,ADDED,eval-conflicts-rho020-r3-049-2cm5b.18d467e923d4a98b,reason=Started count=1 msg=Started container task
0.5627,Event,ADDED,eval-conflicts-rho020-r3-049.18d467e9064c0383,reason=SuccessfulCreate count=1 msg=Created pod: eval-conflicts-rho020-r3-049-2cm5b
0.563,Event,ADDED,eval-conflicts-rho020-r3-049.18d467ec64578210,reason=Completed count=1 msg=Job completed
0.5632,Event,ADDED,eval-conflicts-rho020-r3-050-9wqm2.18d467e9439ac14a,reason=Scheduled count=None msg=Successfully assigned compute/eval-conflicts-rho020-r3-050-9wqm2 to kind-worker3
0.5634,Event,ADDED,eval-conflicts-rho020-r3-050-9wqm2.18d467e95e1b0465,"reason=Pulled count=1 msg=Container image ""busybox:musl"" already present on machine"
0.5637,Event,ADDED,eval-conflicts-rho020-r3-050-9wqm2.18d467e95f351291,reason=Created count=1 msg=Created container: task
0.5639,Event,ADDED,eval-conflicts-rho020-r3-050-9wqm2.18d467e961246e91,reason=Started count=1 msg=Started container task
0.5642,Event,ADDED,eval-conflicts-rho020-r3-050.18d467e942cdcaed,reason=SuccessfulCreate count=1 msg=Created pod: eval-conflicts-rho020-r3-050-9wqm2
0.5644,Event,ADDED,eval-conflicts-rho020-r3-050.18d467ec76e90e06,reason=Completed count=1 msg=Job completed
0.5646,Event,ADDED,eval-conflicts-rho020-r3-051-868bl.18d467e97deb8956,"reason=FailedScheduling count=None msg=0/6 nodes are available: 1 c_wall violated: 1 conflicting context pair(s) with node memory, 1 c_wall violated: 2 conflicting context pair(s) with node memory, 4 node(s) had untolerated taint(s). no new claims to deallocate, preemption: 0/6 nodes are available: 2 No preemption victims found for incoming pod, 4 Preemption is not helpful for scheduling."
0.5648,Event,ADDED,eval-conflicts-rho020-r3-051-868bl.18d467e983cad312,"reason=FailedScheduling count=None msg=0/6 nodes are available: 1 c_wall violated: 1 conflicting context pair(s) with node memory, 1 c_wall violated: 2 conflicting context pair(s) with node memory, 4 node(s) had untolerated taint(s). no new claims to deallocate, preemption: 0/6 nodes are available: 2 No preemption victims found for incoming pod, 4 Preemption is not helpful for scheduling."
0.565,Event,ADDED,eval-conflicts-rho020-r3-051-868bl.18d467e98f6086d5,"reason=FailedScheduling count=None msg=0/6 nodes are available: 1 c_wall violated: 2 conflicting context pair(s) with node memory, 5 node(s) had untolerated taint(s). no new claims to deallocate, preemption: 0/6 nodes are available: 1 No preemption victims found for incoming pod, 5 Preemption is not helpful for scheduling."
0.5652,Event,ADDED,eval-conflicts-rho020-r3-051-868bl.18d467e9fb132825,reason=Scheduled count=None msg=Successfully assigned compute/eval-conflicts-rho020-r3-051-868bl to kind-worker
0.5653,Event,ADDED,eval-conflicts-rho020-r3-051-868bl.18d467ea14b03dca,"reason=Pulled count=1 msg=Container image ""busybox:musl"" already present on machine"
0.5655,Event,ADDED,eval-conflicts-rho020-r3-051-868bl.18d467ea16488398,reason=Created count=1 msg=Created container: task
0.5659,Event,ADDED,eval-conflicts-rho020-r3-051-868bl.18d467ea19d73f46,reason=Started count=1 msg=Started container task
0.5661,Event,ADDED,eval-conflicts-rho020-r3-051.18d467e97d6fdeff,reason=SuccessfulCreate count=1 msg=Created pod: eval-conflicts-rho020-r3-051-868bl
0.5663,Event,ADDED,eval-conflicts-rho020-r3-051.18d467ed517b2671,reason=Completed count=1 msg=Job completed
0.5664,Event,ADDED,eval-conflicts-rho020-r3-052-snjd9.18d467e9ba224ded,reason=Scheduled count=None msg=Successfully assigned compute/eval-conflicts-rho020-r3-052-snjd9 to kind-worker4
0.5667,Event,ADDED,eval-conflicts-rho020-r3-052-snjd9.18d467e9d45ba690,"reason=Pulled count=1 msg=Container image ""busybox:musl"" already present on machine"
0.5669,Event,ADDED,eval-conflicts-rho020-r3-052-snjd9.18d467e9d57977ed,reason=Created count=1 msg=Created container: task
0.5671,Event,ADDED,eval-conflicts-rho020-r3-052-snjd9.18d467e9d7a0cd4c,reason=Started count=1 msg=Started container task
0.5674,Event,ADDED,eval-conflicts-rho020-r3-052.18d467e9b983ace2,reason=SuccessfulCreate count=1 msg=Created pod: eval-conflicts-rho020-r3-052-snjd9
0.5676,Event,ADDED,eval-conflicts-rho020-r3-052.18d467ed1ede6c80,reason=Completed count=1 msg=Job completed
0.5677,Event,ADDED,eval-conflicts-rho020-r3-053-d8z78.18d467e9f5833e59,reason=Scheduled count=None msg=Successfully assigned compute/eval-conflicts-rho020-r3-053-d8z78 to kind-worker4
0.5679,Event,ADDED,eval-conflicts-rho020-r3-053-d8z78.18d467ea0e74d0b7,"reason=Pulled count=1 msg=Container image ""busybox:musl"" already present on machine"
0.5681,Event,ADDED,eval-conflicts-rho020-r3-053-d8z78.18d467ea0fbf1e7f,reason=Created count=1 msg=Created container: task
0.5683,Event,ADDED,eval-conflicts-rho020-r3-053-d8z78.18d467ea13a16316,reason=Started count=1 msg=Started container task
0.5685,Event,ADDED,eval-conflicts-rho020-r3-053.18d467e9f4eb55d8,reason=SuccessfulCreate count=1 msg=Created pod: eval-conflicts-rho020-r3-053-d8z78
0.5686,Event,ADDED,eval-conflicts-rho020-r3-053.18d467ed5155b202,reason=Completed count=1 msg=Job completed
0.5688,Event,ADDED,eval-conflicts-rho020-r3-054-wwlv5.18d467ea3164a8fa,reason=Scheduled count=None msg=Successfully assigned compute/eval-conflicts-rho020-r3-054-wwlv5 to kind-worker2
0.569,Event,ADDED,eval-conflicts-rho020-r3-054-wwlv5.18d467ea4a316940,"reason=Pulled count=1 msg=Container image ""busybox:musl"" already present on machine"
0.5691,Event,ADDED,eval-conflicts-rho020-r3-054-wwlv5.18d467ea4b359c51,reason=Created count=1 msg=Created container: task
0.5694,Event,ADDED,eval-conflicts-rho020-r3-054-wwlv5.18d467ea4d8c0aad,reason=Started count=1 msg=Started container task
0.5696,Event,ADDED,eval-conflicts-rho020-r3-054.18d467ea308b42f5,reason=SuccessfulCreate count=1 msg=Created pod: eval-conflicts-rho020-r3-054-wwlv5
0.5698,Event,ADDED,eval-conflicts-rho020-r3-054.18d467ed8cd8a9e0,reason=Completed count=1 msg=Job completed
0.5699,Event,ADDED,eval-conflicts-rho020-r3-055-lvrx4.18d467ea6cd1fc1f,reason=Scheduled count=None msg=Successfully assigned compute/eval-conflicts-rho020-r3-055-lvrx4 to kind-worker5
0.5701,Event,ADDED,eval-conflicts-rho020-r3-055-lvrx4.18d467ea89f5ec95,"reason=Pulled count=1 msg=Container image ""busybox:musl"" already present on machine"
0.5703,Event,ADDED,eval-conflicts-rho020-r3-055-lvrx4.18d467ea8b500ea5,reason=Created count=1 msg=Created container: task
0.5705,Event,ADDED,eval-conflicts-rho020-r3-055-lvrx4.18d467ea901b6c80,reason=Started count=1 msg=Started container task
0.5706,Event,ADDED,eval-conflicts-rho020-r3-055.18d467ea6bf65eba,reason=SuccessfulCreate count=1 msg=Created pod: eval-conflicts-rho020-r3-055-lvrx4
0.5708,Event,ADDED,eval-conflicts-rho020-r3-055.18d467edd8eda033,reason=Completed count=1 msg=Job completed
0.571,Event,ADDED,eval-conflicts-rho020-r3-056-mwjwg.18d467eaa8f7a90e,reason=Scheduled count=None msg=Successfully assigned compute/eval-conflicts-rho020-r3-056-mwjwg to kind-worker5
0.5711,Event,ADDED,eval-conflicts-rho020-r3-056-mwjwg.18d467eac6ff33c6,"reason=Pulled count=1 msg=Container image ""busybox:musl"" already present on machine"
0.5713,Event,ADDED,eval-conflicts-rho020-r3-056-mwjwg.18d467eac81d144a,reason=Created count=1 msg=Created container: task
0.5715,Event,ADDED,eval-conflicts-rho020-r3-056-mwjwg.18d467eacbd0021b,reason=Started count=1 msg=Started container task
0.5716,Event,ADDED,eval-conflicts-rho020-r3-056.18d467eaa7c24d35,reason=SuccessfulCreate count=1 msg=Created pod: eval-conflicts-rho020-r3-056-mwjwg
0.5718,Event,ADDED,eval-conflicts-rho020-r3-056.18d467ee12768c4e,reason=Completed count=1 msg=Job completed
0.572,Event,ADDED,eval-conflicts-rho020-r3-057-bx4ck.18d467eae410060e,reason=Scheduled count=None msg=Successfully assigned compute/eval-conflicts-rho020-r3-057-bx4ck to kind-worker5
0.5722,Event,ADDED,eval-conflicts-rho020-r3-057-bx4ck.18d467eafd254e0f,"reason=Pulled count=1 msg=Container image ""busybox:musl"" already present on machine"
0.5724,Event,ADDED,eval-conflicts-rho020-r3-057-bx4ck.18d467eafe272043,reason=Created count=1 msg=Created container: task
0.5726,Event,ADDED,eval-conflicts-rho020-r3-057-bx4ck.18d467eb02f9c7c9,reason=Started count=1 msg=Started container task
0.5729,Event,ADDED,eval-conflicts-rho020-r3-057.18d467eae30758fe,reason=SuccessfulCreate count=1 msg=Created pod: eval-conflicts-rho020-r3-057-bx4ck
0.5731,Event,ADDED,eval-conflicts-rho020-r3-057.18d467ee4f7fb32d,reason=Completed count=1 msg=Job completed
0.5733,Event,ADDED,eval-conflicts-rho020-r3-058-25xxg.18d467eb1f48f9f8,"reason=FailedScheduling count=None msg=0/6 nodes are available: 3 c_wall violated: 1 conflicting context pair(s) with node memory, 3 node(s) had untolerated taint(s). no new claims to deallocate, preemption: 0/6 nodes are available: 3 No preemption victims found for incoming pod, 3 Preemption is not helpful for scheduling."
0.5737,Event,ADDED,eval-conflicts-rho020-r3-058-25xxg.18d467eb245c938c,"reason=FailedScheduling count=None msg=0/6 nodes are available: 3 c_wall violated: 1 conflicting context pair(s) with node memory, 3 node(s) had untolerated taint(s). no new claims to deallocate, preemption: 0/6 nodes are available: 3 No preemption victims found for incoming pod, 3 Preemption is not helpful for scheduling."
0.5739,Event,ADDED,eval-conflicts-rho020-r3-058-25xxg.18d467ec6029f88b,"reason=FailedScheduling count=None msg=0/6 nodes are available: 2 c_wall violated: 1 conflicting context pair(s) with node memory, 4 node(s) had untolerated taint(s). no new claims to deallocate, preemption: 0/6 nodes are available: 2 No preemption victims found for incoming pod, 4 Preemption is not helpful for scheduling."
0.5741,Event,ADDED,eval-conflicts-rho020-r3-058-25xxg.18d467ec777a3f71,"reason=FailedScheduling count=None msg=0/6 nodes are available: 1 c_wall violated: 1 conflicting context pair(s) with node memory, 5 node(s) had untolerated taint(s). no new claims to deallocate, preemption: 0/6 nodes are available: 1 No preemption victims found for incoming pod, 5 Preemption is not helpful for scheduling."
0.5744,Event,ADDED,eval-conflicts-rho020-r3-058-25xxg.18d467ee50a3e43e,reason=Scheduled count=None msg=Successfully assigned compute/eval-conflicts-rho020-r3-058-25xxg to kind-worker3
0.5746,Event,ADDED,eval-conflicts-rho020-r3-058-25xxg.18d467ee6bce8dfc,"reason=Pulled count=1 msg=Container image ""busybox:musl"" already present on machine"
0.5748,Event,ADDED,eval-conflicts-rho020-r3-058-25xxg.18d467ee6e452350,reason=Created count=1 msg=Created container: task
0.575,Event,ADDED,eval-conflicts-rho020-r3-058-25xxg.18d467ee70ead863,reason=Started count=1 msg=Started container task
0.5752,Event,ADDED,eval-conflicts-rho020-r3-058.18d467eb1e9e28c3,reason=SuccessfulCreate count=1 msg=Created pod: eval-conflicts-rho020-r3-058-25xxg
0.5754,Event,ADDED,eval-conflicts-rho020-r3-058.18d467f19b65a2d9,reason=Completed count=1 msg=Job completed
0.5755,Event,ADDED,eval-conflicts-rho020-r3-059-f6s8m.18d467eb5bbca16f,reason=Scheduled count=None msg=Successfully assigned compute/eval-conflicts-rho020-r3-059-f6s8m to kind-worker2
0.5757,Event,ADDED,eval-conflicts-rho020-r3-059-f6s8m.18d467eb74319817,"reason=Pulled count=1 msg=Container image ""busybox:musl"" already present on machine"
0.5759,Event,ADDED,eval-conflicts-rho020-r3-059-f6s8m.18d467eb754c6a9b,reason=Created count=1 msg=Created container: task
0.5762,Event,ADDED,eval-conflicts-rho020-r3-059-f6s8m.18d467eb7764da34,reason=Started count=1 msg=Started container task
0.5764,Event,ADDED,eval-conflicts-rho020-r3-059.18d467eb5a7bf11f,reason=SuccessfulCreate count=1 msg=Created pod: eval-conflicts-rho020-r3-059-f6s8m
0.5767,Event,ADDED,eval-conflicts-rho020-r3-059.18d467eeb265cb47,reason=Completed count=1 msg=Job completed
0.5769,Event,ADDED,eval-conflicts-rho020-r3-060-5dj7c.18d467eb96df46b2,"reason=FailedScheduling count=None msg=0/6 nodes are available: 1 c_wall violated: 2 conflicting context pair(s) with node memory, 2 c_wall violated: 1 conflicting context pair(s) with node memory, 3 node(s) had untolerated taint(s). no new claims to deallocate, preemption: 0/6 nodes are available: 3 No preemption victims found for incoming pod, 3 Preemption is not helpful for scheduling."
0.5771,Event,ADDED,eval-conflicts-rho020-r3-060-5dj7c.18d467eb9b8e91dd,"reason=FailedScheduling count=None msg=0/6 nodes are available: 1 c_wall violated: 2 conflicting context pair(s) with node memory, 2 c_wall violated: 1 conflicting context pair(s) with node memory, 3 node(s) had untolerated taint(s). no new claims to deallocate, preemption: 0/6 nodes are available: 3 No preemption victims found for incoming pod, 3 Preemption is not helpful for scheduling."
0.5777,Event,ADDED,eval-conflicts-rho020-r3-060-5dj7c.18d467ec60c67b62,"reason=FailedScheduling count=None msg=0/6 nodes are available: 1 c_wall violated: 1 conflicting context pair(s) with node memory, 1 c_wall violated: 2 conflicting context pair(s) with node memory, 4 node(s) had untolerated taint(s). no new claims to deallocate, preemption: 0/6 nodes are available: 2 No preemption victims found for incoming pod, 4 Preemption is not helpful for scheduling."
0.5779,Event,ADDED,eval-conflicts-rho020-r3-060-5dj7c.18d467ec77d2d14f,"reason=FailedScheduling count=None msg=0/6 nodes are available: 1 c_wall violated: 2 conflicting context pair(s) with node memory, 5 node(s) had untolerated taint(s). no new claims to deallocate, preemption: 0/6 nodes are available: 1 No preemption victims found for incoming pod, 5 Preemption is not helpful for scheduling."
0.5783,Event,ADDED,eval-conflicts-rho020-r3-060-5dj7c.18d467ee50e896ea,"reason=FailedScheduling count=None msg=0/6 nodes are available: 1 c_wall violated: 1 conflicting context pair(s) with node memory, 5 node(s) had untolerated taint(s). no new claims to deallocate, preemption: 0/6 nodes are available: 1 No preemption victims found for incoming pod, 5 Preemption is not helpful for scheduling."
0.5786,Event,ADDED,eval-conflicts-rho020-r3-060-5dj7c.18d467ee5897eca5,"reason=FailedScheduling count=None msg=0/6 nodes are available: 1 c_wall violated: 1 conflicting context pair(s) with node memory, 5 node(s) had untolerated taint(s). no new claims to deallocate, preemption: 0/6 nodes are available: 1 No preemption victims found for incoming pod, 5 Preemption is not helpful for scheduling."
0.5788,Event,ADDED,eval-conflicts-rho020-r3-060-5dj7c.18d467ee689bbae7,"reason=FailedScheduling count=None msg=0/6 nodes are available: 1 c_wall violated: 2 conflicting context pair(s) with node memory, 5 node(s) had untolerated taint(s). no new claims to deallocate, preemption: 0/6 nodes are available: 1 No preemption victims found for incoming pod, 5 Preemption is not helpful for scheduling."
0.5791,Event,ADDED,eval-conflicts-rho020-r3-060-5dj7c.18d467eecb2ec3e0,"reason=FailedScheduling count=None msg=0/6 nodes are available: 1 c_wall violated: 1 conflicting context pair(s) with node memory, 1 c_wall violated: 2 conflicting context pair(s) with node memory, 4 node(s) had untolerated taint(s). no new claims to deallocate, preemption: 0/6 nodes are available: 2 No preemption victims found for incoming pod, 4 Preemption is not helpful for scheduling."
0.5792,Event,ADDED,eval-conflicts-rho020-r3-060-5dj7c.18d467eed87d955b,reason=Scheduled count=None msg=Successfully assigned compute/eval-conflicts-rho020-r3-060-5dj7c to kind-worker4
0.5794,Event,ADDED,eval-conflicts-rho020-r3-060-5dj7c.18d467eef40867db,"reason=Pulled count=1 msg=Container image ""busybox:musl"" already present on machine"
0.5795,Event,ADDED,eval-conflicts-rho020-r3-060-5dj7c.18d467eef5fdc1b1,reason=Created count=1 msg=Created container: task
0.5798,Event,ADDED,eval-conflicts-rho020-r3-060-5dj7c.18d467eefb1e3974,reason=Started count=1 msg=Started container task
0.5799,Event,ADDED,eval-conflicts-rho020-r3-060.18d467eb962c3db8,reason=SuccessfulCreate count=1 msg=Created pod: eval-conflicts-rho020-r3-060-5dj7c
0.5802,Event,ADDED,eval-conflicts-rho020-r3-060.18d467f2382c9bbc,reason=Completed count=1 msg=Job completed
0.5805,Event,ADDED,eval-conflicts-rho020-r3-061-bkfdn.18d467ebd28e9a77,reason=Scheduled count=None msg=Successfully assigned compute/eval-conflicts-rho020-r3-061-bkfdn to kind-worker2
0.5807,Event,ADDED,eval-conflicts-rho020-r3-061-bkfdn.18d467ebebed9704,"reason=Pulled count=1 msg=Container image ""busybox:musl"" already present on machine"
0.581,Event,ADDED,eval-conflicts-rho020-r3-061-bkfdn.18d467ebed173063,reason=Created count=1 msg=Created container: task
0.5812,Event,ADDED,eval-conflicts-rho020-r3-061-bkfdn.18d467ebf0e3e357,reason=Started count=1 msg=Started container task
0.5814,Event,ADDED,eval-conflicts-rho020-r3-061.18d467ebd166c94d,reason=SuccessfulCreate count=1 msg=Created pod: eval-conflicts-rho020-r3-061-bkfdn
0.5815,Event,ADDED,eval-conflicts-rho020-r3-061.18d467ef26e1451b,reason=Completed count=1 msg=Job completed
0.5817,Event,ADDED,eval-conflicts-rho020-r3-062-bp7vw.18d467ec0e49b27f,"reason=FailedScheduling count=None msg=0/6 nodes are available: 1 c_wall violated: 2 conflicting context pair(s) with node memory, 2 c_wall violated: 1 conflicting context pair(s) with node memory, 3 node(s) had untolerated taint(s). no new claims to deallocate, preemption: 0/6 nodes are available: 3 No preemption victims found for incoming pod, 3 Preemption is not helpful for scheduling."
0.582,Event,ADDED,eval-conflicts-rho020-r3-062-bp7vw.18d467ec12cf2569,"reason=FailedScheduling count=None msg=0/6 nodes are available: 1 c_wall violated: 2 conflicting context pair(s) with node memory, 2 c_wall violated: 1 conflicting context pair(s) with node memory, 3 node(s) had untolerated taint(s). no new claims to deallocate, preemption: 0/6 nodes are available: 3 No preemption victims found for incoming pod, 3 Preemption is not helpful for scheduling."
0.5821,Event,ADDED,eval-conflicts-rho020-r3-062-bp7vw.18d467ec607e53ff,"reason=FailedScheduling count=None msg=0/6 nodes are available: 1 c_wall violated: 1 conflicting context pair(s) with node memory, 1 c_wall violated: 2 conflicting context pair(s) with node memory, 4 node(s) had untolerated taint(s). no new claims to deallocate, preemption: 0/6 nodes are available: 2 No preemption victims found for incoming pod, 4 Preemption is not helpful for scheduling."
0.5823,Event,ADDED,eval-conflicts-rho020-r3-062-bp7vw.18d467ec77aab4a3,"reason=FailedScheduling count=None msg=0/6 nodes are available: 1 c_wall violated: 2 conflicting context pair(s) with node memory, 5 node(s) had untolerated taint(s). no new claims to deallocate, preemption: 0/6 nodes are available: 1 No preemption victims found for incoming pod, 5 Preemption is not helpful for scheduling."
0.5825,Event,ADDED,eval-conflicts-rho020-r3-062-bp7vw.18d467ee5112a503,reason=Scheduled count=None msg=Successfully assigned compute/eval-conflicts-rho020-r3-062-bp7vw to kind-worker3
0.5827,Event,ADDED,eval-conflicts-rho020-r3-062-bp7vw.18d467ee6ce6f53a,"reason=Pulled count=1 msg=Container image ""busybox:musl"" already present on machine"
0.5829,Event,ADDED,eval-conflicts-rho020-r3-062-bp7vw.18d467ee7044d478,reason=Created count=1 msg=Created container: task
0.583,Event,ADDED,eval-conflicts-rho020-r3-062-bp7vw.18d467ee74e93b73,reason=Started count=1 msg=Started container task
0.5833,Event,ADDED,eval-conflicts-rho020-r3-062.18d467ec0d728d35,reason=SuccessfulCreate count=1 msg=Created pod: eval-conflicts-rho020-r3-062-bp7vw
0.5835,Event,ADDED,eval-conflicts-rho020-r3-062.18d467f19b83832b,reason=Completed count=1 msg=Job completed
0.5837,Event,ADDED,eval-conflicts-rho020-r3-063-l68p2.18d467ec4a124217,reason=Scheduled count=None msg=Successfully assigned compute/eval-conflicts-rho020-r3-063-l68p2 to kind-worker5
0.584,Event,ADDED,eval-conflicts-rho020-r3-063-l68p2.18d467ec63f168c7,"reason=Pulled count=1 msg=Container image ""busybox:musl"" already present on machine"
0.5842,Event,ADDED,eval-conflicts-rho020-r3-063-l68p2.18d467ec6547af8c,reason=Created count=1 msg=Created container: task
0.5845,Event,ADDED,eval-conflicts-rho020-r3-063-l68p2.18d467ec6a1aec69,reason=Started count=1 msg=Started container task
0.5847,Event,ADDED,eval-conflicts-rho020-r3-063.18d467ec48f67af7,reason=SuccessfulCreate count=1 msg=Created pod: eval-conflicts-rho020-r3-063-l68p2
0.5849,Event,ADDED,eval-conflicts-rho020-r3-063.18d467efaf79affb,reason=Completed count=1 msg=Job completed
0.5851,Event,ADDED,eval-conflicts-rho020-r3-064-zc68g.18d467ec8483c959,"reason=FailedScheduling count=None msg=0/6 nodes are available: 1 c_wall violated: 2 conflicting context pair(s) with node memory, 5 node(s) had untolerated taint(s). no new claims to deallocate, preemption: 0/6 nodes are available: 1 No preemption victims found for incoming pod, 5 Preemption is not helpful for scheduling."
0.5853,Event,ADDED,eval-conflicts-rho020-r3-064-zc68g.18d467ec84fd9791,"reason=FailedScheduling count=None msg=0/6 nodes are available: 1 c_wall violated: 2 conflicting context pair(s) with node memory, 5 node(s) had untolerated taint(s). no new claims to deallocate, preemption: 0/6 nodes are available: 1 No preemption victims found for incoming pod, 5 Preemption is not helpful for scheduling."
0.5855,Event,ADDED,eval-conflicts-rho020-r3-064-zc68g.18d467ee5208878d,reason=Scheduled count=None msg=Successfully assigned compute/eval-conflicts-rho020-r3-064-zc68g to kind-worker3
0.5856,Event,ADDED,eval-conflicts-rho020-r3-064-zc68g.18d467ee6d9b7a8a,"reason=Pulled count=1 msg=Container image ""busybox:musl"" already present on machine"
0.5858,Event,ADDED,eval-conflicts-rho020-r3-064-zc68g.18d467ee713a5af6,reason=Created count=1 msg=Created container: task
0.586,Event,ADDED,eval-conflicts-rho020-r3-064-zc68g.18d467ee7405c236,reason=Started count=1 msg=Started container task
0.5861,Event,ADDED,eval-conflicts-rho020-r3-064.18d467ec84476d67,reason=SuccessfulCreate count=1 msg=Created pod: eval-conflicts-rho020-r3-064-zc68g
0.5863,Event,ADDED,eval-conflicts-rho020-r3-064.18d467f19a93cd45,reason=Completed count=1 msg=Job completed
0.5865,Event,ADDED,eval-conflicts-rho020-r3-065-qflvf.18d467ecc3d1e25a,"reason=FailedScheduling count=None msg=0/6 nodes are available: 6 node(s) had untolerated taint(s). no new claims to deallocate, preemption: 0/6 nodes are available: 6 Preemption is not helpful for scheduling."
0.5866,Event,ADDED,eval-conflicts-rho020-r3-065-qflvf.18d467ee522cfe7c,reason=Scheduled count=None msg=Successfully assigned compute/eval-conflicts-rho020-r3-065-qflvf to kind-worker3
0.5868,Event,ADDED,eval-conflicts-rho020-r3-065-qflvf.18d467ee6dceecde,"reason=Pulled count=1 msg=Container image ""busybox:musl"" already present on machine"
0.587,Event,ADDED,eval-conflicts-rho020-r3-065-qflvf.18d467ee7183dd1f,reason=Created count=1 msg=Created container: task
0.5871,Event,ADDED,eval-conflicts-rho020-r3-065-qflvf.18d467ee74963f1d,reason=Started count=1 msg=Started container task
0.5873,Event,ADDED,eval-conflicts-rho020-r3-065.18d467ecc3c56493,reason=SuccessfulCreate count=1 msg=Created pod: eval-conflicts-rho020-r3-065-qflvf
0.5875,Event,ADDED,eval-conflicts-rho020-r3-065.18d467f19b1cd3d5,reason=Completed count=1 msg=Job completed
0.5876,Event,ADDED,eval-conflicts-rho020-r3-066-z4tfq.18d467ecfbc46261,"reason=FailedScheduling count=None msg=0/6 nodes are available: 6 node(s) had untolerated taint(s). no new claims to deallocate, preemption: 0/6 nodes are available: 6 Preemption is not helpful for scheduling."
0.5878,Event,ADDED,eval-conflicts-rho020-r3-066-z4tfq.18d467ee526aa366,reason=Scheduled count=None msg=Successfully assigned compute/eval-conflicts-rho020-r3-066-z4tfq to kind-worker3
0.5881,Event,ADDED,eval-conflicts-rho020-r3-066-z4tfq.18d467ee6db4f42a,"reason=Pulled count=1 msg=Container image ""busybox:musl"" already present on machine"
0.5883,Event,ADDED,eval-conflicts-rho020-r3-066-z4tfq.18d467ee710a0cc4,reason=Created count=1 msg=Created container: task
0.5885,Event,ADDED,eval-conflicts-rho020-r3-066-z4tfq.18d467ee73835e86,reason=Started count=1 msg=Started container task
0.5891,Event,ADDED,eval-conflicts-rho020-r3-066.18d467ecfbb60da3,reason=SuccessfulCreate count=1 msg=Created pod: eval-conflicts-rho020-r3-066-z4tfq
0.5895,Event,ADDED,eval-conflicts-rho020-r3-066.18d467f19a6916dc,reason=Completed count=1 msg=Job completed
0.5896,Event,ADDED,eval-conflicts-rho020-r3-067-gblfv.18d467ed3e1fcfd5,"reason=FailedScheduling count=None msg=0/6 nodes are available: 6 node(s) had untolerated taint(s). no new claims to deallocate, preemption: 0/6 nodes are available: 6 Preemption is not helpful for scheduling."
0.5899,Event,ADDED,eval-conflicts-rho020-r3-067-gblfv.18d467ee56e771b4,reason=Scheduled count=None msg=Successfully assigned compute/eval-conflicts-rho020-r3-067-gblfv to kind-worker3
0.5901,Event,ADDED,eval-conflicts-rho020-r3-067-gblfv.18d467ee6fdb204d,"reason=Pulled count=1 msg=Container image ""busybox:musl"" already present on machine"
0.5906,Event,ADDED,eval-conflicts-rho020-r3-067-gblfv.18d467ee72badc0d,reason=Created count=1 msg=Created container: task
0.5909,Event,ADDED,eval-conflicts-rho020-r3-067-gblfv.18d467ee759592c0,reason=Started count=1 msg=Started container task
0.5913,Event,ADDED,eval-conflicts-rho020-r3-067.18d467ed3e15a9f2,reason=SuccessfulCreate count=1 msg=Created pod: eval-conflicts-rho020-r3-067-gblfv
0.5915,Event,ADDED,eval-conflicts-rho020-r3-067.18d467f19a44b392,reason=Completed count=1 msg=Job completed
0.5916,Event,ADDED,eval-conflicts-rho020-r3-068-vt4x7.18d467ed73a9d2db,"reason=FailedScheduling count=None msg=0/6 nodes are available: 6 node(s) had untolerated taint(s). no new claims to deallocate, preemption: 0/6 nodes are available: 6 Preemption is not helpful for scheduling."
0.5918,Event,ADDED,eval-conflicts-rho020-r3-068-vt4x7.18d467ee5705498a,reason=Scheduled count=None msg=Successfully assigned compute/eval-conflicts-rho020-r3-068-vt4x7 to kind-worker3
0.5925,Event,ADDED,eval-conflicts-rho020-r3-068-vt4x7.18d467ee70f25592,"reason=Pulled count=1 msg=Container image ""busybox:musl"" already present on machine"
0.5928,Event,ADDED,eval-conflicts-rho020-r3-068-vt4x7.18d467ee72d92253,reason=Created count=1 msg=Created container: task
0.593,Event,ADDED,eval-conflicts-rho020-r3-068-vt4x7.18d467ee75956c56,reason=Started count=1 msg=Started container task
0.5933,Event,ADDED,eval-conflicts-rho020-r3-068.18d467ed73a09e5f,reason=SuccessfulCreate count=1 msg=Created pod: eval-conflicts-rho020-r3-068-vt4x7
0.5934,Event,ADDED,eval-conflicts-rho020-r3-068.18d467f19a685068,reason=Completed count=1 msg=Job completed
0.5936,Event,ADDED,eval-conflicts-rho020-r3-069-8fclc.18d467edae6f639a,"reason=FailedScheduling count=None msg=0/6 nodes are available: 6 node(s) had untolerated taint(s). no new claims to deallocate, preemption: 0/6 nodes are available: 6 Preemption is not helpful for scheduling."
0.5937,Event,ADDED,eval-conflicts-rho020-r3-069-8fclc.18d467ee56de30cd,"reason=FailedScheduling count=None msg=0/6 nodes are available: 1 c_wall violated: 2 conflicting context pair(s) with node memory, 5 node(s) had untolerated taint(s). no new claims to deallocate, preemption: 0/6 nodes are available: 1 No preemption victims found for incoming pod, 5 Preemption is not helpful for scheduling."
0.5939,Event,ADDED,eval-conflicts-rho020-r3-069-8fclc.18d467ee5a97000f,"reason=FailedScheduling count=None msg=0/6 nodes are available: 1 c_wall violated: 2 conflicting context pair(s) with node memory, 5 node(s) had untolerated taint(s). no new claims to deallocate, preemption: 0/6 nodes are available: 1 No preemption victims found for incoming pod, 5 Preemption is not helpful for scheduling."
0.5941,Event,ADDED,eval-conflicts-rho020-r3-069-8fclc.18d467eec5b254ff,reason=Scheduled count=None msg=Successfully assigned compute/eval-conflicts-rho020-r3-069-8fclc to kind-worker
0.5943,Event,ADDED,eval-conflicts-rho020-r3-069-8fclc.18d467eef2c92c34,"reason=Pulled count=1 msg=Container image ""busybox:musl"" already present on machine"
0.5948,Event,ADDED,eval-conflicts-rho020-r3-069-8fclc.18d467eef4c8e681,reason=Created count=1 msg=Created container: task
0.5953,Event,ADDED,eval-conflicts-rho020-r3-069-8fclc.18d467eefadc74ef,reason=Started count=1 msg=Started container task
0.5956,Event,ADDED,eval-conflicts-rho020-r3-069.18d467edae6633a5,reason=SuccessfulCreate count=1 msg=Created pod: eval-conflicts-rho020-r3-069-8fclc
0.5959,Event,ADDED,eval-conflicts-rho020-r3-069.18d467f2796a39f0,reason=Completed count=1 msg=Job completed
0.5963,Event,ADDED,eval-conflicts-rho020-r3-070-bv9dl.18d467edea055e6a,"reason=FailedScheduling count=None msg=0/6 nodes are available: 6 node(s) had untolerated taint(s). no new claims to deallocate, preemption: 0/6 nodes are available: 6 Preemption is not helpful for scheduling."
0.5965,Event,ADDED,eval-conflicts-rho020-r3-070-bv9dl.18d467ee57680834,"reason=FailedScheduling count=None msg=0/6 nodes are available: 1 c_wall violated: 1 conflicting context pair(s) with node memory, 5 node(s) had untolerated taint(s). no new claims to deallocate, preemption: 0/6 nodes are available: 1 No preemption victims found for incoming pod, 5 Preemption is not helpful for scheduling."
0.5967,Event,ADDED,eval-conflicts-rho020-r3-070-bv9dl.18d467ee5c74bbe9,"reason=FailedScheduling count=None msg=0/6 nodes are available: 1 c_wall violated: 1 conflicting context pair(s) with node memory, 5 node(s) had untolerated taint(s). no new claims to deallocate, preemption: 0/6 nodes are available: 1 No preemption victims found for incoming pod, 5 Preemption is not helpful for scheduling."
0.5972,Event,ADDED,eval-conflicts-rho020-r3-070-bv9dl.18d467ee650e28cd,"reason=FailedScheduling count=None msg=0/6 nodes are available: 1 c_wall violated: 2 conflicting context pair(s) with node memory, 5 node(s) had untolerated taint(s). no new claims to deallocate, preemption: 0/6 nodes are available: 1 No preemption victims found for incoming pod, 5 Preemption is not helpful for scheduling."
0.5974,Event,ADDED,eval-conflicts-rho020-r3-070-bv9dl.18d467eecbd7df1b,"reason=FailedScheduling count=None msg=0/6 nodes are available: 1 c_wall violated: 1 conflicting context pair(s) with node memory, 1 c_wall violated: 2 conflicting context pair(s) with node memory, 4 node(s) had untolerated taint(s). no new claims to deallocate, preemption: 0/6 nodes are available: 2 No preemption victims found for incoming pod, 4 Preemption is not helpful for scheduling."
0.5975,Event,ADDED,eval-conflicts-rho020-r3-070-bv9dl.18d467eed7607ac3,reason=Scheduled count=None msg=Successfully assigned compute/eval-conflicts-rho020-r3-070-bv9dl to kind-worker4
0.5978,Event,ADDED,eval-conflicts-rho020-r3-070-bv9dl.18d467eef4298ca8,"reason=Pulled count=1 msg=Container image ""busybox:musl"" already present on machine"
0.598,Event,ADDED,eval-conflicts-rho020-r3-070-bv9dl.18d467eef637cec0,reason=Created count=1 msg=Created container: task
0.5981,Event,ADDED,eval-conflicts-rho020-r3-070-bv9dl.18d467eefb1e3988,reason=Started count=1 msg=Started container task
0.5983,Event,ADDED,eval-conflicts-rho020-r3-070.18d467ede9f9e9b4,reason=SuccessfulCreate count=1 msg=Created pod: eval-conflicts-rho020-r3-070-bv9dl
0.5985,Event,ADDED,eval-conflicts-rho020-r3-070.18d467f238073a02,reason=Completed count=1 msg=Job completed
0.5986,Event,ADDED,eval-conflicts-rho020-r3-071-r2bjc.18d467ee25bd6b6e,"reason=FailedScheduling count=None msg=0/6 nodes are available: 6 node(s) had untolerated taint(s). no new claims to deallocate, preemption: 0/6 nodes are available: 6 Preemption is not helpful for scheduling."
0.5989,Event,ADDED,eval-conflicts-rho020-r3-071-r2bjc.18d467ee57f5c4a0,"reason=FailedScheduling count=None msg=0/6 nodes are available: 1 c_wall violated: 2 conflicting context pair(s) with node memory, 5 node(s) had untolerated taint(s). no new claims to deallocate, preemption: 0/6 nodes are available: 1 No preemption victims found for incoming pod, 5 Preemption is not helpful for scheduling."
0.5993,Event,ADDED,eval-conflicts-rho020-r3-071-r2bjc.18d467ee5caaa3b3,"reason=FailedScheduling count=None msg=0/6 nodes are available: 1 c_wall violated: 2 conflicting context pair(s) with node memory, 5 node(s) had untolerated taint(s). no new claims to deallocate, preemption: 0/6 nodes are available: 1 No preemption victims found for incoming pod, 5 Preemption is not helpful for scheduling."
0.5994,Event,ADDED,eval-conflicts-rho020-r3-071-r2bjc.18d467eec0712f7a,reason=Scheduled count=None msg=Successfully assigned compute/eval-conflicts-rho020-r3-071-r2bjc to kind-worker
0.5996,Event,ADDED,eval-conflicts-rho020-r3-071-r2bjc.18d467eeda46c84f,"reason=Pulled count=1 msg=Container image ""busybox:musl"" already present on machine"
0.6002,Event,ADDED,eval-conflicts-rho020-r3-071-r2bjc.18d467eedbe159f5,reason=Created count=1 msg=Created container: task
0.6005,Event,ADDED,eval-conflicts-rho020-r3-071-r2bjc.18d467eee07b1259,reason=Started count=1 msg=Started container task
0.6007,Event,ADDED,eval-conflicts-rho020-r3-071.18d467ee25b0bf08,reason=SuccessfulCreate count=1 msg=Created pod: eval-conflicts-rho020-r3-071-r2bjc
0.6008,Event,ADDED,eval-conflicts-rho020-r3-071.18d467f242c3751f,reason=Completed count=1 msg=Job completed
0.6012,Event,ADDED,eval-conflicts-rho020-r3-072-s42f2.18d467ee6319342d,reason=Scheduled count=None msg=Successfully assigned compute/eval-conflicts-rho020-r3-072-s42f2 to kind-worker3
0.6014,Event,ADDED,eval-conflicts-rho020-r3-072-s42f2.18d467ee7f98aff3,"reason=Pulled count=1 msg=Container image ""busybox:musl"" already present on machine"
0.6016,Event,ADDED,eval-conflicts-rho020-r3-072-s42f2.18d467ee80e15be4,reason=Created count=1 msg=Created container: task
0.602,Event,ADDED,eval-conflicts-rho020-r3-072-s42f2.18d467ee8aef2a8e,reason=Started count=1 msg=Started container task
0.6022,Event,ADDED,eval-conflicts-rho020-r3-072.18d467ee6280eb99,reason=SuccessfulCreate count=1 msg=Created pod: eval-conflicts-rho020-r3-072-s42f2
0.6023,Event,ADDED,eval-conflicts-rho020-r3-072.18d467f16078bc44,reason=Completed count=1 msg=Job completed
0.6025,Event,ADDED,eval-conflicts-rho020-r3-073-hnwzl.18d467ee9f4ea38b,"reason=FailedScheduling count=None msg=0/6 nodes are available: 1 c_wall violated: 2 conflicting context pair(s) with node memory, 5 node(s) had untolerated taint(s). no new claims to deallocate, preemption: 0/6 nodes are available: 1 No preemption victims found for incoming pod, 5 Preemption is not helpful for scheduling."
0.6029,Event,ADDED,eval-conflicts-rho020-r3-073-hnwzl.18d467ee9fd3e0fe,"reason=FailedScheduling count=None msg=0/6 nodes are available: 1 c_wall violated: 2 conflicting context pair(s) with node memory, 5 node(s) had untolerated taint(s). no new claims to deallocate, preemption: 0/6 nodes are available: 1 No preemption victims found for incoming pod, 5 Preemption is not helpful for scheduling."
0.6031,Event,ADDED,eval-conflicts-rho020-r3-073-hnwzl.18d467eec6eaca9a,reason=Scheduled count=None msg=Successfully assigned compute/eval-conflicts-rho020-r3-073-hnwzl to kind-worker
0.6033,Event,ADDED,eval-conflicts-rho020-r3-073-hnwzl.18d467eee0fa5508,"reason=Pulled count=1 msg=Container image ""busybox:musl"" already present on machine"
0.6044,Event,ADDED,eval-conflicts-rho020-r3-073-hnwzl.18d467eee2163eea,reason=Created count=1 msg=Created container: task
0.6046,Event,ADDED,eval-conflicts-rho020-r3-073-hnwzl.18d467eee5e72ab8,reason=Started count=1 msg=Started container task
0.6048,Event,ADDED,eval-conflicts-rho020-r3-073.18d467ee9f0f69b9,reason=SuccessfulCreate count=1 msg=Created pod: eval-conflicts-rho020-r3-073-hnwzl
0.6049,Event,ADDED,eval-conflicts-rho020-r3-073.18d467f2402ddddb,reason=Completed count=1 msg=Job completed
0.6053,Event,ADDED,eval-conflicts-rho020-r3-074-5cl75.18d467eedeee63ff,reason=Scheduled count=None msg=Successfully assigned compute/eval-conflicts-rho020-r3-074-5cl75 to kind-worker
0.6055,Event,ADDED,eval-conflicts-rho020-r3-074-5cl75.18d467eefbd39da1,"reason=Pulled count=1 msg=Container image ""busybox:musl"" already present on machine"
0.6057,Event,ADDED,eval-conflicts-rho020-r3-074-5cl75.18d467eefd406904,reason=Created count=1 msg=Created container: task
0.606,Event,ADDED,eval-conflicts-rho020-r3-074-5cl75.18d467ef03b62cc6,reason=Started count=1 msg=Started container task
0.6062,Event,ADDED,eval-conflicts-rho020-r3-074.18d467eeda4551f6,reason=SuccessfulCreate count=1 msg=Created pod: eval-conflicts-rho020-r3-074-5cl75
0.6064,Event,ADDED,eval-conflicts-rho020-r3-074.18d467f2886f52a8,reason=Completed count=1 msg=Job completed
0.6065,Event,ADDED,eval-conflicts-rho020-r3-075-gc8lx.18d467ef15b8a921,reason=Scheduled count=None msg=Successfully assigned compute/eval-conflicts-rho020-r3-075-gc8lx to kind-worker2
0.6069,Event,ADDED,eval-conflicts-rho020-r3-075-gc8lx.18d467ef2efaa57d,"reason=Pulled count=1 msg=Container image ""busybox:musl"" already present on machine"
0.607,Event,ADDED,eval-conflicts-rho020-r3-075-gc8lx.18d467ef3035ecc9,reason=Created count=1 msg=Created container: task
0.6072,Event,ADDED,eval-conflicts-rho020-r3-075-gc8lx.18d467ef351a413b,reason=Started count=1 msg=Started container task
0.6075,Event,ADDED,eval-conflicts-rho020-r3-075.18d467ef14898131,reason=SuccessfulCreate count=1 msg=Created pod: eval-conflicts-rho020-r3-075-gc8lx
0.6077,Event,ADDED,eval-conflicts-rho020-r3-075.18d467f2696c7045,reason=Completed count=1 msg=Job completed
0.6079,Event,ADDED,eval-conflicts-rho020-r3-076-7g9wn.18d467ef510c0679,reason=Scheduled count=None msg=Successfully assigned compute/eval-conflicts-rho020-r3-076-7g9wn to kind-worker2
0.6082,Event,ADDED,eval-conflicts-rho020-r3-076-7g9wn.18d467ef6a9cf8f9,"reason=Pulled count=1 msg=Container image ""busybox:musl"" already present on machine"
0.6085,Event,ADDED,eval-conflicts-rho020-r3-076-7g9wn.18d467ef6bf2d994,reason=Created count=1 msg=Created container: task
