t_recv,kind,type,name,detail
0.0192,Node,ADDED,kind-control-plane,taints=1
0.0216,Event,ADDED,eval-sanitize-5-r1-011-4cvxp.18d3d3d7eccf09d3,"reason=FailedScheduling count=None msg=0/6 nodes are available: 1 c_wall violated: 1 conflicting context pair(s) with node memory, 5 node(s) had untolerated taint(s). no new claims to deallocate, preemption: 0/6 nodes are available: 1 No preemption victims found for incoming pod, 5 Preemption is not helpful for scheduling."
0.0228,Node,ADDED,kind-worker,taints=0
0.0231,Event,ADDED,eval-sanitize-5-r1-014-8x522.18d3d3d7ed0515d2,"reason=FailedScheduling count=None msg=0/6 nodes are available: 1 c_wall violated: 2 conflicting context pair(s) with node memory, 5 node(s) had untolerated taint(s). no new claims to deallocate, preemption: 0/6 nodes are available: 1 No preemption victims found for incoming pod, 5 Preemption is not helpful for scheduling."
0.0233,Event,ADDED,eval-sanitize-5-r1-016-ql8wf.18d3d3d7ed3d5ebf,"reason=FailedScheduling count=None msg=0/6 nodes are available: 1 c_wall violated: 1 conflicting context pair(s) with node memory, 5 node(s) had untolerated taint(s). no new claims to deallocate, preemption: 0/6 nodes are available: 1 No preemption victims found for incoming pod, 5 Preemption is not helpful for scheduling."
0.0235,Event,ADDED,eval-sanitize-5-r1-026-psh7v.18d3d3d9e058761c,"reason=FailedScheduling count=None msg=0/6 nodes are available: 1 c_wall violated: 1 conflicting context pair(s) with node memory, 5 node(s) had untolerated taint(s). no new claims to deallocate, preemption: 0/6 nodes are available: 1 No preemption victims found for incoming pod, 5 Preemption is not helpful for scheduling."
0.0239,Event,ADDED,eval-sanitize-5-r1-026-psh7v.18d3d3da586e6650,"reason=FailedScheduling count=None msg=0/6 nodes are available: 1 c_wall violated: 2 conflicting context pair(s) with node memory, 5 node(s) had untolerated taint(s). no new claims to deallocate, preemption: 0/6 nodes are available: 1 No preemption victims found for incoming pod, 5 Preemption is not helpful for scheduling."
0.024,Event,ADDED,eval-sanitize-5-r1-029-9dgzs.18d3d3da934fcb7c,"reason=FailedScheduling count=None msg=0/6 nodes are available: 1 c_wall violated: 2 conflicting context pair(s) with node memory, 5 node(s) had untolerated taint(s). no new claims to deallocate, preemption: 0/6 nodes are available: 1 No preemption victims found for incoming pod, 5 Preemption is not helpful for scheduling."
0.0242,Event,ADDED,eval-sanitize-5-r1-030-7hjwr.18d3d3db7a6ae75f,"reason=FailedScheduling count=None msg=0/6 nodes are available: 1 c_wall violated: 1 conflicting context pair(s) with node memory, 5 node(s) had untolerated taint(s). no new claims to deallocate, preemption: 0/6 nodes are available: 1 No preemption victims found for incoming pod, 5 Preemption is not helpful for scheduling."
0.0253,Node,ADDED,kind-worker2,taints=0
0.0257,Event,ADDED,eval-sanitize-5-r1-030-7hjwr.18d3d3dc1d8a7b40,"reason=FailedScheduling count=None msg=0/6 nodes are available: 2 c_wall violated: 1 conflicting context pair(s) with node memory, 4 node(s) had untolerated taint(s). no new claims to deallocate, preemption: 0/6 nodes are available: 2 No preemption victims found for incoming pod, 4 Preemption is not helpful for scheduling."
0.026,Event,ADDED,eval-sanitize-5-r1-030-7hjwr.18d3d3dcaad50abb,"reason=FailedScheduling count=None msg=0/6 nodes are available: 1 c_wall violated: 1 conflicting context pair(s) with node memory, 5 node(s) had untolerated taint(s). no new claims to deallocate, preemption: 0/6 nodes are available: 1 No preemption victims found for incoming pod, 5 Preemption is not helpful for scheduling."
0.0264,Event,ADDED,eval-sanitize-5-r1-031-vp575.18d3d3db7ba99046,"reason=FailedScheduling count=None msg=0/6 nodes are available: 1 c_wall violated: 2 conflicting context pair(s) with node memory, 5 node(s) had untolerated taint(s). no new claims to deallocate, preemption: 0/6 nodes are available: 1 No preemption victims found for incoming pod, 5 Preemption is not helpful for scheduling."
0.0266,Event,ADDED,eval-sanitize-5-r1-031-vp575.18d3d3db7fd1f119,"reason=FailedScheduling count=None msg=0/6 nodes are available: 1 c_wall violated: 2 conflicting context pair(s) with node memory, 5 node(s) had untolerated taint(s). no new claims to deallocate, preemption: 0/6 nodes are available: 1 No preemption victims found for incoming pod, 5 Preemption is not helpful for scheduling."
0.0268,Event,ADDED,eval-sanitize-5-r1-033-qwngz.18d3d3db819cace9,"reason=FailedScheduling count=None msg=0/6 nodes are available: 1 c_wall violated: 2 conflicting context pair(s) with node memory, 5 node(s) had untolerated taint(s). no new claims to deallocate, preemption: 0/6 nodes are available: 1 No preemption victims found for incoming pod, 5 Preemption is not helpful for scheduling."
0.028,Node,ADDED,kind-worker3,taints=0
0.0283,Event,ADDED,eval-sanitize-5-r1-034-sjxpc.18d3d3dbbe3cbdbf,"reason=FailedScheduling count=None msg=0/6 nodes are available: 1 c_wall violated: 2 conflicting context pair(s) with node memory, 5 node(s) had untolerated taint(s). no new claims to deallocate, preemption: 0/6 nodes are available: 1 No preemption victims found for incoming pod, 5 Preemption is not helpful for scheduling."
0.0285,Event,ADDED,eval-sanitize-5-r1-036-779qg.18d3d3dc359b781e,"reason=FailedScheduling count=None msg=0/6 nodes are available: 2 c_wall violated: 1 conflicting context pair(s) with node memory, 4 node(s) had untolerated taint(s). no new claims to deallocate, preemption: 0/6 nodes are available: 2 No preemption victims found for incoming pod, 4 Preemption is not helpful for scheduling."
0.0287,Event,ADDED,eval-sanitize-5-r1-036-779qg.18d3d3dcaba1b7f5,"reason=FailedScheduling count=None msg=0/6 nodes are available: 1 c_wall violated: 1 conflicting context pair(s) with node memory, 5 node(s) had untolerated taint(s). no new claims to deallocate, preemption: 0/6 nodes are available: 1 No preemption victims found for incoming pod, 5 Preemption is not helpful for scheduling."
0.0293,Event,ADDED,eval-sanitize-5-r1-037-f2njp.18d3d3dc7061cc87,"reason=FailedScheduling count=None msg=0/6 nodes are available: 2 c_wall violated: 1 conflicting context pair(s) with node memory, 4 node(s) had untolerated taint(s). no new claims to deallocate, preemption: 0/6 nodes are available: 2 No preemption victims found for incoming pod, 4 Preemption is not helpful for scheduling."
0.0295,Event,ADDED,eval-sanitize-5-r1-037-f2njp.18d3d3dcabd07580,"reason=FailedScheduling count=None msg=0/6 nodes are available: 1 c_wall violated: 1 conflicting context pair(s) with node memory, 5 node(s) had untolerated taint(s). no new claims to deallocate, preemption: 0/6 nodes are available: 1 No preemption victims found for incoming pod, 5 Preemption is not helpful for scheduling."
0.0297,Event,ADDED,eval-sanitize-5-r1-037-f2njp.18d3d3dd0d437091,"reason=FailedScheduling count=None msg=0/6 nodes are available: 2 c_wall violated: 1 conflicting context pair(s) with node memory, 4 node(s) had untolerated taint(s). no new claims to deallocate, preemption: 0/6 nodes are available: 2 No preemption victims found for incoming pod, 4 Preemption is not helpful for scheduling."
0.0308,Node,ADDED,kind-worker4,taints=0
0.0311,Event,ADDED,eval-sanitize-5-r1-038-w86qq.18d3d3dcaca8589c,"reason=FailedScheduling count=None msg=0/6 nodes are available: 1 c_wall violated: 1 conflicting context pair(s) with node memory, 5 node(s) had untolerated taint(s). no new claims to deallocate, preemption: 0/6 nodes are available: 1 No preemption victims found for incoming pod, 5 Preemption is not helpful for scheduling."
0.0313,Event,ADDED,eval-sanitize-5-r1-041-m6ft9.18d3d3dd5e7c2260,"reason=FailedScheduling count=None msg=0/6 nodes are available: 2 c_wall violated: 1 conflicting context pair(s) with node memory, 4 node(s) had untolerated taint(s). no new claims to deallocate, preemption: 0/6 nodes are available: 2 No preemption victims found for incoming pod, 4 Preemption is not helpful for scheduling."
0.0315,Event,ADDED,eval-sanitize-5-r1-043-5jmf7.18d3d3ddd61457ac,"reason=FailedScheduling count=None msg=0/6 nodes are available: 2 c_wall violated: 1 conflicting context pair(s) with node memory, 4 node(s) had untolerated taint(s). no new claims to deallocate, preemption: 0/6 nodes are available: 2 No preemption victims found for incoming pod, 4 Preemption is not helpful for scheduling."
0.0317,Event,ADDED,eval-sanitize-5-r1-044-5m8mg.18d3d3de1867ba4e,"reason=FailedScheduling count=None msg=0/6 nodes are available: 1 c_wall violated: 1 conflicting context pair(s) with node memory, 1 c_wall violated: 2 conflicting context pair(s) with node memory, 4 node(s) had untolerated taint(s). no new claims to deallocate, preemption: 0/6 nodes are available: 2 No preemption victims found for incoming pod, 4 Preemption is not helpful for scheduling."
0.0319,Event,ADDED,eval-sanitize-5-r1-044-5m8mg.18d3d3de42440367,"reason=FailedScheduling count=None msg=0/6 nodes are available: 2 c_wall violated: 1 conflicting context pair(s) with node memory, 4 node(s) had untolerated taint(s). no new claims to deallocate, preemption: 0/6 nodes are available: 2 No preemption victims found for incoming pod, 4 Preemption is not helpful for scheduling."
0.0321,Event,ADDED,eval-sanitize-5-r1-044-5m8mg.18d3d3de43836989,"reason=FailedScheduling count=None msg=0/6 nodes are available: 2 c_wall violated: 1 conflicting context pair(s) with node memory, 4 node(s) had untolerated taint(s). no new claims to deallocate, preemption: 0/6 nodes are available: 2 No preemption victims found for incoming pod, 4 Preemption is not helpful for scheduling."
0.0323,Event,ADDED,eval-sanitize-5-r1-044-5m8mg.18d3d3de548de89a,"reason=FailedScheduling count=None msg=0/6 nodes are available: 1 c_wall violated: 1 conflicting context pair(s) with node memory, 5 node(s) had untolerated taint(s). no new claims to deallocate, preemption: 0/6 nodes are available: 1 No preemption victims found for incoming pod, 5 Preemption is not helpful for scheduling."
0.0324,Event,ADDED,eval-sanitize-5-r1-044-5m8mg.18d3d3dec5c2247f,"reason=FailedScheduling count=None msg=0/6 nodes are available: 1 c_wall violated: 2 conflicting context pair(s) with node memory, 5 node(s) had untolerated taint(s). no new claims to deallocate, preemption: 0/6 nodes are available: 1 No preemption victims found for incoming pod, 5 Preemption is not helpful for scheduling."
0.0337,Node,ADDED,kind-worker5,taints=0
0.034,Event,ADDED,eval-sanitize-5-r1-044-5m8mg.18d3d3df139e4330,"reason=FailedScheduling count=None msg=0/6 nodes are available: 1 c_wall violated: 1 conflicting context pair(s) with node memory, 1 c_wall violated: 2 conflicting context pair(s) with node memory, 4 node(s) had untolerated taint(s). no new claims to deallocate, preemption: 0/6 nodes are available: 2 No preemption victims found for incoming pod, 4 Preemption is not helpful for scheduling."
0.0342,Event,ADDED,eval-sanitize-5-r1-044-5m8mg.18d3d3df7c405c7e,"reason=FailedScheduling count=None msg=0/6 nodes are available: 1 c_wall violated: 1 conflicting context pair(s) with node memory, 5 node(s) had untolerated taint(s). no new claims to deallocate, preemption: 0/6 nodes are available: 1 No preemption victims found for incoming pod, 5 Preemption is not helpful for scheduling."
0.0344,Event,ADDED,eval-sanitize-5-r1-044-5m8mg.18d3d3dfb33b8fb1,"reason=FailedScheduling count=None msg=0/6 nodes are available: 1 c_wall violated: 2 conflicting context pair(s) with node memory, 5 node(s) had untolerated taint(s). no new claims to deallocate, preemption: 0/6 nodes are available: 1 No preemption victims found for incoming pod, 5 Preemption is not helpful for scheduling."
0.0348,Event,ADDED,eval-sanitize-5-r1-045-bpmp6.18d3d3de4ee1b7c1,"reason=FailedScheduling count=None msg=0/6 nodes are available: 2 c_wall violated: 1 conflicting context pair(s) with node memory, 4 node(s) had untolerated taint(s). no new claims to deallocate, preemption: 0/6 nodes are available: 2 No preemption victims found for incoming pod, 4 Preemption is not helpful for scheduling."
0.035,Event,ADDED,eval-sanitize-5-r1-045-bpmp6.18d3d3de54b6f922,"reason=FailedScheduling count=None msg=0/6 nodes are available: 1 c_wall violated: 1 conflicting context pair(s) with node memory, 5 node(s) had untolerated taint(s). no new claims to deallocate, preemption: 0/6 nodes are available: 1 No preemption victims found for incoming pod, 5 Preemption is not helpful for scheduling."
0.0352,Event,ADDED,eval-sanitize-5-r1-045-bpmp6.18d3d3dec8fe2b34,"reason=FailedScheduling count=None msg=0/6 nodes are available: 1 c_wall violated: 2 conflicting context pair(s) with node memory, 5 node(s) had untolerated taint(s). no new claims to deallocate, preemption: 0/6 nodes are available: 1 No preemption victims found for incoming pod, 5 Preemption is not helpful for scheduling."
0.0355,Event,ADDED,eval-sanitize-5-r1-045-bpmp6.18d3d3df187c3a44,"reason=FailedScheduling count=None msg=0/6 nodes are available: 1 c_wall violated: 1 conflicting context pair(s) with node memory, 1 c_wall violated: 2 conflicting context pair(s) with node memory, 4 node(s) had untolerated taint(s). no new claims to deallocate, preemption: 0/6 nodes are available: 2 No preemption victims found for incoming pod, 4 Preemption is not helpful for scheduling."
0.0357,Event,ADDED,eval-sanitize-5-r1-045-bpmp6.18d3d3df7c709b5e,"reason=FailedScheduling count=None msg=0/6 nodes are available: 1 c_wall violated: 1 conflicting context pair(s) with node memory, 5 node(s) had untolerated taint(s). no new claims to deallocate, preemption: 0/6 nodes are available: 1 No preemption victims found for incoming pod, 5 Preemption is not helpful for scheduling."
0.036,TaskRequest,ADDED,eval-sanitize-5-r3-000,phase=None job=None
0.0363,Event,ADDED,eval-sanitize-5-r1-045-bpmp6.18d3d3dfb36e280b,"reason=FailedScheduling count=None msg=0/6 nodes are available: 1 c_wall violated: 2 conflicting context pair(s) with node memory, 5 node(s) had untolerated taint(s). no new claims to deallocate, preemption: 0/6 nodes are available: 1 No preemption victims found for incoming pod, 5 Preemption is not helpful for scheduling."
0.0365,Event,ADDED,eval-sanitize-5-r1-046-7nrqt.18d3d3de888c4e53,"reason=FailedScheduling count=None msg=0/6 nodes are available: 1 c_wall violated: 1 conflicting context pair(s) with node memory, 5 node(s) had untolerated taint(s). no new claims to deallocate, preemption: 0/6 nodes are available: 1 No preemption victims found for incoming pod, 5 Preemption is not helpful for scheduling."
0.0367,Event,ADDED,eval-sanitize-5-r1-048-7mtx6.18d3d3deffadaa2b,"reason=FailedScheduling count=None msg=0/6 nodes are available: 1 c_wall violated: 2 conflicting context pair(s) with node memory, 5 node(s) had untolerated taint(s). no new claims to deallocate, preemption: 0/6 nodes are available: 1 No preemption victims found for incoming pod, 5 Preemption is not helpful for scheduling."
0.037,Event,ADDED,eval-sanitize-5-r1-054-jzsg6.18d3d3e0b85dfe2b,"reason=FailedScheduling count=None msg=0/6 nodes are available: 1 c_wall violated: 2 conflicting context pair(s) with node memory, 5 node(s) had untolerated taint(s). no new claims to deallocate, preemption: 0/6 nodes are available: 1 No preemption victims found for incoming pod, 5 Preemption is not helpful for scheduling."
0.0372,Event,ADDED,eval-sanitize-5-r1-063-g82fq.18d3d3e27e1ac4e6,"reason=FailedScheduling count=None msg=0/6 nodes are available: 1 c_wall violated: 1 conflicting context pair(s) with node memory, 5 node(s) had untolerated taint(s). no new claims to deallocate, preemption: 0/6 nodes are available: 1 No preemption victims found for incoming pod, 5 Preemption is not helpful for scheduling."
0.0374,Event,ADDED,eval-sanitize-5-r1-063-g82fq.18d3d3e2f62abe5d,"reason=FailedScheduling count=None msg=0/6 nodes are available: 1 c_wall violated: 2 conflicting context pair(s) with node memory, 5 node(s) had untolerated taint(s). no new claims to deallocate, preemption: 0/6 nodes are available: 1 No preemption victims found for incoming pod, 5 Preemption is not helpful for scheduling."
0.0377,Event,ADDED,eval-sanitize-5-r1-064-4cqk5.18d3d3e2b929b514,"reason=FailedScheduling count=None msg=0/6 nodes are available: 1 c_wall violated: 1 conflicting context pair(s) with node memory, 5 node(s) had untolerated taint(s). no new claims to deallocate, preemption: 0/6 nodes are available: 1 No preemption victims found for incoming pod, 5 Preemption is not helpful for scheduling."
0.0379,Event,ADDED,eval-sanitize-5-r1-066-bblxb.18d3d3e3ea4e297c,"reason=FailedScheduling count=None msg=0/6 nodes are available: 1 c_wall violated: 3 conflicting context pair(s) with node memory, 5 node(s) had untolerated taint(s). no new claims to deallocate, preemption: 0/6 nodes are available: 1 No preemption victims found for incoming pod, 5 Preemption is not helpful for scheduling."
0.0381,Event,ADDED,eval-sanitize-5-r1-067-msll8.18d3d3e3ea7900c5,"reason=FailedScheduling count=None msg=0/6 nodes are available: 1 c_wall violated: 2 conflicting context pair(s) with node memory, 5 node(s) had untolerated taint(s). no new claims to deallocate, preemption: 0/6 nodes are available: 1 No preemption victims found for incoming pod, 5 Preemption is not helpful for scheduling."
0.0384,Event,ADDED,eval-sanitize-5-r1-070-9w8fw.18d3d3e41f0bee3c,"reason=FailedScheduling count=None msg=0/6 nodes are available: 1 c_wall violated: 1 conflicting context pair(s) with node memory, 5 node(s) had untolerated taint(s). no new claims to deallocate, preemption: 0/6 nodes are available: 1 No preemption victims found for incoming pod, 5 Preemption is not helpful for scheduling."
0.0386,Event,ADDED,eval-sanitize-5-r1-072-pk7p4.18d3d3e496109a5b,"reason=FailedScheduling count=None msg=0/6 nodes are available: 2 c_wall violated: 2 conflicting context pair(s) with node memory, 4 node(s) had untolerated taint(s). no new claims to deallocate, preemption: 0/6 nodes are available: 2 No preemption victims found for incoming pod, 4 Preemption is not helpful for scheduling."
0.0388,Event,ADDED,eval-sanitize-5-r1-075-89cdl.18d3d3e54a9b5e97,"reason=FailedScheduling count=None msg=0/6 nodes are available: 2 c_wall violated: 1 conflicting context pair(s) with node memory, 4 node(s) had untolerated taint(s). no new claims to deallocate, preemption: 0/6 nodes are available: 2 No preemption victims found for incoming pod, 4 Preemption is not helpful for scheduling."
0.0392,Event,ADDED,eval-sanitize-5-r1-075-89cdl.18d3d3e5827ab1d7,"reason=FailedScheduling count=None msg=0/6 nodes are available: 1 c_wall violated: 1 conflicting context pair(s) with node memory, 5 node(s) had untolerated taint(s). no new claims to deallocate, preemption: 0/6 nodes are available: 1 No preemption victims found for incoming pod, 5 Preemption is not helpful for scheduling."
0.0394,Event,ADDED,eval-sanitize-5-r1-075-89cdl.18d3d3e5e1181c47,"reason=FailedScheduling count=None msg=0/6 nodes are available: 1 c_wall violated: 1 conflicting context pair(s) with node memory, 5 node(s) had untolerated taint(s). no new claims to deallocate, preemption: 0/6 nodes are available: 1 No preemption victims found for incoming pod, 5 Preemption is not helpful for scheduling."
0.0395,Event,ADDED,eval-sanitize-5-r1-075-89cdl.18d3d3e67485c365,"reason=FailedScheduling count=None msg=0/6 nodes are available: 1 c_wall violated: 2 conflicting context pair(s) with node memory, 5 node(s) had untolerated taint(s). no new claims to deallocate, preemption: 0/6 nodes are available: 1 No preemption victims found for incoming pod, 5 Preemption is not helpful for scheduling."
0.0399,Event,ADDED,eval-sanitize-5-r1-076-l92hp.18d3d3e5850724ab,"reason=FailedScheduling count=None msg=0/6 nodes are available: 1 c_wall violated: 1 conflicting context pair(s) with node memory, 5 node(s) had untolerated taint(s). no new claims to deallocate, preemption: 0/6 nodes are available: 1 No preemption victims found for incoming pod, 5 Preemption is not helpful for scheduling."
0.0401,Event,ADDED,eval-sanitize-5-r1-077-vcqz4.18d3d3e5c044ecb0,"reason=FailedScheduling count=None msg=0/6 nodes are available: 1 c_wall violated: 1 conflicting context pair(s) with node memory, 5 node(s) had untolerated taint(s). no new claims to deallocate, preemption: 0/6 nodes are available: 1 No preemption victims found for incoming pod, 5 Preemption is not helpful for scheduling."
0.0404,Event,ADDED,eval-sanitize-5-r1-078-l7vbp.18d3d3e5fc7ca2da,"reason=FailedScheduling count=None msg=0/6 nodes are available: 1 c_wall violated: 1 conflicting context pair(s) with node memory, 5 node(s) had untolerated taint(s). no new claims to deallocate, preemption: 0/6 nodes are available: 1 No preemption victims found for incoming pod, 5 Preemption is not helpful for scheduling."
0.0405,Event,ADDED,eval-sanitize-5-r1-078-l7vbp.18d3d3e674532dfc,"reason=FailedScheduling count=None msg=0/6 nodes are available: 1 c_wall violated: 2 conflicting context pair(s) with node memory, 5 node(s) had untolerated taint(s). no new claims to deallocate, preemption: 0/6 nodes are available: 1 No preemption victims found for incoming pod, 5 Preemption is not helpful for scheduling."
0.0407,Event,ADDED,eval-sanitize-5-r1-081-bwbks.18d3d3e6af031e36,"reason=FailedScheduling count=None msg=0/6 nodes are available: 1 c_wall violated: 4 conflicting context pair(s) with node memory, 5 node(s) had untolerated taint(s). no new claims to deallocate, preemption: 0/6 nodes are available: 1 No preemption victims found for incoming pod, 5 Preemption is not helpful for scheduling."
0.0411,Event,ADDED,eval-sanitize-5-r1-082-gt58r.18d3d3e6ea30d6dd,"reason=FailedScheduling count=None msg=0/6 nodes are available: 1 c_wall violated: 1 conflicting context pair(s) with node memory, 1 c_wall violated: 3 conflicting context pair(s) with node memory, 4 node(s) had untolerated taint(s). no new claims to deallocate, preemption: 0/6 nodes are available: 2 No preemption victims found for incoming pod, 4 Preemption is not helpful for scheduling."
0.0413,Event,ADDED,eval-sanitize-5-r1-082-gt58r.18d3d3e71cc9cb8d,"reason=FailedScheduling count=None msg=0/6 nodes are available: 1 c_wall violated: 1 conflicting context pair(s) with node memory, 5 node(s) had untolerated taint(s). no new claims to deallocate, preemption: 0/6 nodes are available: 1 No preemption victims found for incoming pod, 5 Preemption is not helpful for scheduling."
0.0415,Event,ADDED,eval-sanitize-5-r1-083-nl2zs.18d3d3e72586f396,"reason=FailedScheduling count=None msg=0/6 nodes are available: 1 c_wall violated: 2 conflicting context pair(s) with node memory, 5 node(s) had untolerated taint(s). no new claims to deallocate, preemption: 0/6 nodes are available: 1 No preemption victims found for incoming pod, 5 Preemption is not helpful for scheduling."
0.0418,Event,ADDED,eval-sanitize-5-r1-083-nl2zs.18d3d3e855f895dc,"reason=FailedScheduling count=None msg=0/6 nodes are available: 1 c_wall violated: 1 conflicting context pair(s) with node memory, 5 node(s) had untolerated taint(s). no new claims to deallocate, preemption: 0/6 nodes are available: 1 No preemption victims found for incoming pod, 5 Preemption is not helpful for scheduling."
0.042,Event,ADDED,eval-sanitize-5-r1-084-qssxt.18d3d3e76279fffd,"reason=FailedScheduling count=None msg=0/6 nodes are available: 1 c_wall violated: 1 conflicting context pair(s) with node memory, 5 node(s) had untolerated taint(s). no new claims to deallocate, preemption: 0/6 nodes are available: 1 No preemption victims found for incoming pod, 5 Preemption is not helpful for scheduling."
0.0422,Event,ADDED,eval-sanitize-5-r1-085-hqp2x.18d3d3e79d270f80,"reason=FailedScheduling count=None msg=0/6 nodes are available: 1 c_wall violated: 1 conflicting context pair(s) with node memory, 5 node(s) had untolerated taint(s). no new claims to deallocate, preemption: 0/6 nodes are available: 1 No preemption victims found for incoming pod, 5 Preemption is not helpful for scheduling."
0.0425,Event,ADDED,eval-sanitize-5-r1-085-hqp2x.18d3d3e85a10954c,"reason=FailedScheduling count=None msg=0/6 nodes are available: 1 c_wall violated: 2 conflicting context pair(s) with node memory, 5 node(s) had untolerated taint(s). no new claims to deallocate, preemption: 0/6 nodes are available: 1 No preemption victims found for incoming pod, 5 Preemption is not helpful for scheduling."
0.0427,Event,ADDED,eval-sanitize-5-r1-086-zg49q.18d3d3e7d97cebac,"reason=FailedScheduling count=None msg=0/6 nodes are available: 1 c_wall violated: 1 conflicting context pair(s) with node memory, 5 node(s) had untolerated taint(s). no new claims to deallocate, preemption: 0/6 nodes are available: 1 No preemption victims found for incoming pod, 5 Preemption is not helpful for scheduling."
0.0429,Event,ADDED,eval-sanitize-5-r1-086-zg49q.18d3d3e85ac9b01a,"reason=FailedScheduling count=None msg=0/6 nodes are available: 1 c_wall violated: 2 conflicting context pair(s) with node memory, 5 node(s) had untolerated taint(s). no new claims to deallocate, preemption: 0/6 nodes are available: 1 No preemption victims found for incoming pod, 5 Preemption is not helpful for scheduling."
0.0432,Event,ADDED,eval-sanitize-5-r1-086-zg49q.18d3d3e8cf0cd35c,"reason=FailedScheduling count=None msg=0/6 nodes are available: 2 c_wall violated: 2 conflicting context pair(s) with node memory, 4 node(s) had untolerated taint(s). no new claims to deallocate, preemption: 0/6 nodes are available: 2 No preemption victims found for incoming pod, 4 Preemption is not helpful for scheduling."
0.0433,Event,ADDED,eval-sanitize-5-r1-087-4rjqj.18d3d3e859c2e345,"reason=FailedScheduling count=None msg=0/6 nodes are available: 1 c_wall violated: 1 conflicting context pair(s) with node memory, 5 node(s) had untolerated taint(s). no new claims to deallocate, preemption: 0/6 nodes are available: 1 No preemption victims found for incoming pod, 5 Preemption is not helpful for scheduling."
0.0437,Event,ADDED,eval-sanitize-5-r1-089-z85qm.18d3d3e88b82bf7d,"reason=FailedScheduling count=None msg=0/6 nodes are available: 1 c_wall violated: 1 conflicting context pair(s) with node memory, 5 node(s) had untolerated taint(s). no new claims to deallocate, preemption: 0/6 nodes are available: 1 No preemption victims found for incoming pod, 5 Preemption is not helpful for scheduling."
0.0439,Event,ADDED,eval-sanitize-5-r1-089-z85qm.18d3d3e8cf55dfb1,"reason=FailedScheduling count=None msg=0/6 nodes are available: 1 c_wall violated: 1 conflicting context pair(s) with node memory, 1 c_wall violated: 2 conflicting context pair(s) with node memory, 4 node(s) had untolerated taint(s). no new claims to deallocate, preemption: 0/6 nodes are available: 2 No preemption victims found for incoming pod, 4 Preemption is not helpful for scheduling."
0.0441,Event,ADDED,eval-sanitize-5-r1-089-z85qm.18d3d3e93fd23a4b,"reason=FailedScheduling count=None msg=0/6 nodes are available: 1 c_wall violated: 2 conflicting context pair(s) with node memory, 2 c_wall violated: 1 conflicting context pair(s) with node memory, 3 node(s) had untolerated taint(s). no new claims to deallocate, preemption: 0/6 nodes are available: 3 No preemption victims found for incoming pod, 3 Preemption is not helpful for scheduling."
0.0442,TaskRequest,MODIFIED,eval-sanitize-5-r3-000,phase=Pending job=None
0.0444,Event,ADDED,eval-sanitize-5-r1-089-z85qm.18d3d3e985d23b1b,"reason=FailedScheduling count=None msg=0/6 nodes are available: 1 c_wall violated: 1 conflicting context pair(s) with node memory, 1 c_wall violated: 2 conflicting context pair(s) with node memory, 4 node(s) had untolerated taint(s). no new claims to deallocate, preemption: 0/6 nodes are available: 2 No preemption victims found for incoming pod, 4 Preemption is not helpful for scheduling."
0.0446,Event,ADDED,eval-sanitize-5-r1-096-lnqcz.18d3d3ea2ce106b8,"reason=FailedScheduling count=None msg=0/6 nodes are available: 2 c_wall violated: 1 conflicting context pair(s) with node memory, 4 node(s) had untolerated taint(s). no new claims to deallocate, preemption: 0/6 nodes are available: 2 No preemption victims found for incoming pod, 4 Preemption is not helpful for scheduling."
0.0448,Event,ADDED,eval-sanitize-5-r1-096-lnqcz.18d3d3ea61186260,"reason=FailedScheduling count=None msg=0/6 nodes are available: 1 c_wall violated: 1 conflicting context pair(s) with node memory, 5 node(s) had untolerated taint(s). no new claims to deallocate, preemption: 0/6 nodes are available: 1 No preemption victims found for incoming pod, 5 Preemption is not helpful for scheduling."
0.0452,Event,ADDED,eval-sanitize-5-r1-097-st9pk.18d3d3ea680cbdde,"reason=FailedScheduling count=None msg=0/6 nodes are available: 1 c_wall violated: 1 conflicting context pair(s) with node memory, 5 node(s) had untolerated taint(s). no new claims to deallocate, preemption: 0/6 nodes are available: 1 No preemption victims found for incoming pod, 5 Preemption is not helpful for scheduling."
0.0455,Event,ADDED,eval-sanitize-5-r1-097-st9pk.18d3d3ea83516413,"reason=FailedScheduling count=None msg=0/6 nodes are available: 2 c_wall violated: 1 conflicting context pair(s) with node memory, 4 node(s) had untolerated taint(s). no new claims to deallocate, preemption: 0/6 nodes are available: 2 No preemption victims found for incoming pod, 4 Preemption is not helpful for scheduling."
0.0456,Event,ADDED,eval-sanitize-5-r1-097-st9pk.18d3d3eac5cb7f1c,"reason=FailedScheduling count=None msg=0/6 nodes are available: 1 c_wall violated: 1 conflicting context pair(s) with node memory, 5 node(s) had untolerated taint(s). no new claims to deallocate, preemption: 0/6 nodes are available: 1 No preemption victims found for incoming pod, 5 Preemption is not helpful for scheduling."
0.0458,Event,ADDED,eval-sanitize-5-r1-099-jc44k.18d3d3eadf7939d6,"reason=FailedScheduling count=None msg=0/6 nodes are available: 1 c_wall violated: 1 conflicting context pair(s) with node memory, 5 node(s) had untolerated taint(s). no new claims to deallocate, preemption: 0/6 nodes are available: 1 No preemption victims found for incoming pod, 5 Preemption is not helpful for scheduling."
0.0618,Job,ADDED,eval-sanitize-5-r3-000,
0.0685,TaskRequest,MODIFIED,eval-sanitize-5-r3-000,phase=Scheduled job=None
0.0738,Pod,ADDED,eval-sanitize-5-r3-000-2jwwc,phase=Pending node=None
0.0759,Job,MODIFIED,eval-sanitize-5-r3-000,
0.079,TaskRequest,MODIFIED,eval-sanitize-5-r3-000,phase=Scheduled job=None
0.0806,Event,ADDED,eval-sanitize-5-r3-000.18d3d463b10db58a,reason=SuccessfulCreate count=1 msg=Created pod: eval-sanitize-5-r3-000-2jwwc
0.0883,Pod,MODIFIED,eval-sanitize-5-r3-000-2jwwc,phase=Pending node=kind-worker2
0.0918,Event,ADDED,eval-sanitize-5-r3-000-2jwwc.18d3d463b1ea2104,reason=Scheduled count=None msg=Successfully assigned compute/eval-sanitize-5-r3-000-2jwwc to kind-worker2
0.1008,Node,MODIFIED,kind-worker2,taints=0
0.102,Pod,MODIFIED,eval-sanitize-5-r3-000-2jwwc,phase=Pending node=kind-worker2
0.1137,Node,MODIFIED,kind-worker2,taints=0
0.2269,Node,MODIFIED,kind-worker2,taints=1
0.2398,Node,MODIFIED,kind-worker2,taints=1
0.5441,Event,ADDED,eval-sanitize-5-r3-000-2jwwc.18d3d463ccdd814b,"reason=Pulled count=1 msg=Container image ""busybox:musl"" already present on machine"
0.5618,Event,ADDED,eval-sanitize-5-r3-000-2jwwc.18d3d463cdf49a40,reason=Created count=1 msg=Created container: task
0.6239,Event,ADDED,eval-sanitize-5-r3-000-2jwwc.18d3d463d1a061b7,reason=Started count=1 msg=Started container task
0.8233,Pod,MODIFIED,eval-sanitize-5-r3-000-2jwwc,phase=Running node=kind-worker2
1.0236,TaskRequest,ADDED,eval-sanitize-5-r3-001,phase=None job=None
1.0283,TaskRequest,MODIFIED,eval-sanitize-5-r3-001,phase=Pending job=None
1.0438,Job,ADDED,eval-sanitize-5-r3-001,
1.0477,TaskRequest,MODIFIED,eval-sanitize-5-r3-001,phase=Scheduled job=None
1.0508,Pod,ADDED,eval-sanitize-5-r3-001-kbq6c,phase=Pending node=None
1.0529,Job,MODIFIED,eval-sanitize-5-r3-001,
1.0579,Event,ADDED,eval-sanitize-5-r3-001.18d3d463eb50c00d,reason=SuccessfulCreate count=1 msg=Created pod: eval-sanitize-5-r3-001-kbq6c
1.058,TaskRequest,MODIFIED,eval-sanitize-5-r3-001,phase=Scheduled job=None
1.0595,Pod,MODIFIED,eval-sanitize-5-r3-001-kbq6c,phase=Pending node=kind-worker
1.0645,Event,ADDED,eval-sanitize-5-r3-001-kbq6c.18d3d463ebd1dee3,reason=Scheduled count=None msg=Successfully assigned compute/eval-sanitize-5-r3-001-kbq6c to kind-worker
1.0692,Node,MODIFIED,kind-worker,taints=0
1.0713,Pod,MODIFIED,eval-sanitize-5-r3-001-kbq6c,phase=Pending node=kind-worker
1.0795,Node,MODIFIED,kind-worker,taints=0
1.0803,Job,MODIFIED,eval-sanitize-5-r3-000,
1.0895,Job,MODIFIED,eval-sanitize-5-r3-000,
1.4919,Event,ADDED,eval-sanitize-5-r3-001-kbq6c.18d3d464055c026c,"reason=Pulled count=1 msg=Container image ""busybox:musl"" already present on machine"
1.51,Event,ADDED,eval-sanitize-5-r3-001-kbq6c.18d3d464066de005,reason=Created count=1 msg=Created container: task
1.5421,Event,ADDED,eval-sanitize-5-r3-001-kbq6c.18d3d464085c960c,reason=Started count=1 msg=Started container task
1.6713,Node,MODIFIED,kind-worker,taints=1
1.6837,Node,MODIFIED,kind-worker,taints=1
2.0137,TaskRequest,ADDED,eval-sanitize-5-r3-002,phase=None job=None
2.0186,TaskRequest,MODIFIED,eval-sanitize-5-r3-002,phase=Pending job=None
2.0335,Job,ADDED,eval-sanitize-5-r3-002,
2.04,TaskRequest,MODIFIED,eval-sanitize-5-r3-002,phase=Scheduled job=None
2.041,Pod,ADDED,eval-sanitize-5-r3-002-lxfh7,phase=Pending node=None
2.0433,Job,MODIFIED,eval-sanitize-5-r3-002,
2.0458,Event,ADDED,eval-sanitize-5-r3-002.18d3d4642651beac,reason=SuccessfulCreate count=1 msg=Created pod: eval-sanitize-5-r3-002-lxfh7
2.0468,TaskRequest,MODIFIED,eval-sanitize-5-r3-002,phase=Scheduled job=None
2.05,Pod,MODIFIED,eval-sanitize-5-r3-002-lxfh7,phase=Pending node=kind-worker4
2.0565,Event,ADDED,eval-sanitize-5-r3-002-lxfh7.18d3d46426db6c9b,reason=Scheduled count=None msg=Successfully assigned compute/eval-sanitize-5-r3-002-lxfh7 to kind-worker4
2.059,Job,MODIFIED,eval-sanitize-5-r3-001,
2.0623,Node,MODIFIED,kind-worker4,taints=0
2.0646,Pod,MODIFIED,eval-sanitize-5-r3-002-lxfh7,phase=Pending node=kind-worker4
2.0693,Job,MODIFIED,eval-sanitize-5-r3-001,
2.0727,Node,MODIFIED,kind-worker4,taints=0
2.4056,Pod,MODIFIED,eval-sanitize-5-r3-001-kbq6c,phase=Running node=kind-worker
2.4797,Event,ADDED,eval-sanitize-5-r3-002-lxfh7.18d3d4644036fc70,"reason=Pulled count=1 msg=Container image ""busybox:musl"" already present on machine"
2.4989,Event,ADDED,eval-sanitize-5-r3-002-lxfh7.18d3d464415ed76c,reason=Created count=1 msg=Created container: task
2.5378,Event,ADDED,eval-sanitize-5-r3-002-lxfh7.18d3d46443997964,reason=Started count=1 msg=Started container task
2.7555,Pod,MODIFIED,eval-sanitize-5-r3-002-lxfh7,phase=Running node=kind-worker4
3.014,TaskRequest,ADDED,eval-sanitize-5-r3-003,phase=None job=None
3.0181,TaskRequest,MODIFIED,eval-sanitize-5-r3-003,phase=Pending job=None
3.0358,Job,ADDED,eval-sanitize-5-r3-003,
3.0431,Pod,ADDED,eval-sanitize-5-r3-003-9sqzh,phase=Pending node=None
3.0432,TaskRequest,MODIFIED,eval-sanitize-5-r3-003,phase=Scheduled job=None
3.0462,Job,MODIFIED,eval-sanitize-5-r3-002,
3.047,Job,MODIFIED,eval-sanitize-5-r3-003,
3.0483,Event,ADDED,eval-sanitize-5-r3-003.18d3d464620ae9c7,reason=SuccessfulCreate count=1 msg=Created pod: eval-sanitize-5-r3-003-9sqzh
3.0503,TaskRequest,MODIFIED,eval-sanitize-5-r3-003,phase=Scheduled job=None
3.0561,Job,MODIFIED,eval-sanitize-5-r3-002,
3.0591,Pod,MODIFIED,eval-sanitize-5-r3-003-9sqzh,phase=Pending node=kind-worker5
3.0646,Job,MODIFIED,eval-sanitize-5-r3-001,
3.065,Event,ADDED,eval-sanitize-5-r3-003-9sqzh.18d3d46463011098,reason=Scheduled count=None msg=Successfully assigned compute/eval-sanitize-5-r3-003-9sqzh to kind-worker5
3.0692,Node,MODIFIED,kind-worker5,taints=0
3.0712,Pod,MODIFIED,eval-sanitize-5-r3-003-9sqzh,phase=Pending node=kind-worker5
3.077,Job,MODIFIED,eval-sanitize-5-r3-001,
3.0817,Node,MODIFIED,kind-worker5,taints=0
3.4978,Event,ADDED,eval-sanitize-5-r3-003-9sqzh.18d3d4647cc55c65,"reason=Pulled count=1 msg=Container image ""busybox:musl"" already present on machine"
3.5154,Event,ADDED,eval-sanitize-5-r3-003-9sqzh.18d3d4647df7e5c6,reason=Created count=1 msg=Created container: task
3.5743,Event,ADDED,eval-sanitize-5-r3-003-9sqzh.18d3d4648182974f,reason=Started count=1 msg=Started container task
3.7706,Pod,MODIFIED,eval-sanitize-5-r3-003-9sqzh,phase=Running node=kind-worker5
4.0137,TaskRequest,ADDED,eval-sanitize-5-r3-004,phase=None job=None
4.0191,TaskRequest,MODIFIED,eval-sanitize-5-r3-004,phase=Pending job=None
4.0347,Job,ADDED,eval-sanitize-5-r3-004,
4.0411,TaskRequest,MODIFIED,eval-sanitize-5-r3-004,phase=Scheduled job=None
4.0443,Job,MODIFIED,eval-sanitize-5-r3-004,
4.0455,Pod,ADDED,eval-sanitize-5-r3-004-th9rv,phase=Pending node=None
4.048,Job,MODIFIED,eval-sanitize-5-r3-003,
4.0483,Event,ADDED,eval-sanitize-5-r3-004.18d3d4649dbce72e,reason=SuccessfulCreate count=1 msg=Created pod: eval-sanitize-5-r3-004-th9rv
4.0578,Job,MODIFIED,eval-sanitize-5-r3-003,
4.058,TaskRequest,MODIFIED,eval-sanitize-5-r3-004,phase=Scheduled job=None
4.0652,Pod,MODIFIED,eval-sanitize-5-r3-004-th9rv,phase=Pending node=kind-worker4
4.0695,Event,ADDED,eval-sanitize-5-r3-004-th9rv.18d3d4649efde220,reason=Scheduled count=None msg=Successfully assigned compute/eval-sanitize-5-r3-004-th9rv to kind-worker4
4.0765,Node,MODIFIED,kind-worker4,taints=0
4.0796,Pod,MODIFIED,eval-sanitize-5-r3-004-th9rv,phase=Pending node=kind-worker4
4.0876,Node,MODIFIED,kind-worker4,taints=0
4.5041,Event,ADDED,eval-sanitize-5-r3-004-th9rv.18d3d464b8e93239,"reason=Pulled count=1 msg=Container image ""busybox:musl"" already present on machine"
4.5234,Event,ADDED,eval-sanitize-5-r3-004-th9rv.18d3d464ba0fde3f,reason=Created count=1 msg=Created container: task
4.5936,Event,ADDED,eval-sanitize-5-r3-004-th9rv.18d3d464be3009f0,reason=Started count=1 msg=Started container task
4.7579,Pod,MODIFIED,eval-sanitize-5-r3-004-th9rv,phase=Running node=kind-worker4
5.008,TaskRequest,ADDED,eval-sanitize-5-r3-005,phase=None job=None
5.015,TaskRequest,MODIFIED,eval-sanitize-5-r3-005,phase=Pending job=None
5.0302,Job,ADDED,eval-sanitize-5-r3-005,
5.0362,TaskRequest,MODIFIED,eval-sanitize-5-r3-005,phase=Scheduled job=None
5.0397,Pod,ADDED,eval-sanitize-5-r3-005-cqc9r,phase=Pending node=None
5.0417,Job,MODIFIED,eval-sanitize-5-r3-005,
5.0442,Event,ADDED,eval-sanitize-5-r3-005.18d3d464d911d6e2,reason=SuccessfulCreate count=1 msg=Created pod: eval-sanitize-5-r3-005-cqc9r
5.0444,TaskRequest,MODIFIED,eval-sanitize-5-r3-005,phase=Scheduled job=None
5.0486,Job,MODIFIED,eval-sanitize-5-r3-004,
5.0534,Pod,MODIFIED,eval-sanitize-5-r3-005-cqc9r,phase=Pending node=kind-worker3
5.0592,Job,MODIFIED,eval-sanitize-5-r3-004,
5.0596,Event,ADDED,eval-sanitize-5-r3-005-cqc9r.18d3d464d9e2bc57,reason=Scheduled count=None msg=Successfully assigned compute/eval-sanitize-5-r3-005-cqc9r to kind-worker3
5.064,Node,MODIFIED,kind-worker3,taints=0
5.0662,Pod,MODIFIED,eval-sanitize-5-r3-005-cqc9r,phase=Pending node=kind-worker3
5.0751,Node,MODIFIED,kind-worker3,taints=0
5.235,Node,MODIFIED,kind-worker5,taints=1
5.2371,Node,MODIFIED,kind-worker4,taints=1
5.2768,Node,MODIFIED,kind-worker5,taints=1
5.3778,Node,MODIFIED,kind-worker4,taints=1
5.4818,Event,ADDED,eval-sanitize-5-r3-005-cqc9r.18d3d464f322673b,"reason=Pulled count=1 msg=Container image ""busybox:musl"" already present on machine"
5.506,Event,ADDED,eval-sanitize-5-r3-005-cqc9r.18d3d464f478b4b0,reason=Created count=1 msg=Created container: task
5.54,Event,ADDED,eval-sanitize-5-r3-005-cqc9r.18d3d464f6a835da,reason=Started count=1 msg=Started container task
5.7587,Pod,MODIFIED,eval-sanitize-5-r3-005-cqc9r,phase=Running node=kind-worker3
6.0154,TaskRequest,ADDED,eval-sanitize-5-r3-006,phase=None job=None
6.0196,TaskRequest,MODIFIED,eval-sanitize-5-r3-006,phase=Pending job=None
6.0355,Job,ADDED,eval-sanitize-5-r3-006,
6.0416,Pod,ADDED,eval-sanitize-5-r3-006-wjlsd,phase=Pending node=None
6.0427,TaskRequest,MODIFIED,eval-sanitize-5-r3-006,phase=Scheduled job=None
6.0464,Job,MODIFIED,eval-sanitize-5-r3-006,
6.0475,Job,MODIFIED,eval-sanitize-5-r3-005,
6.0505,Event,ADDED,eval-sanitize-5-r3-006.18d3d46514c8a1ad,reason=SuccessfulCreate count=1 msg=Created pod: eval-sanitize-5-r3-006-wjlsd
6.0524,Pod,MODIFIED,eval-sanitize-5-r3-006-wjlsd,phase=Pending node=kind-worker3
6.0528,TaskRequest,MODIFIED,eval-sanitize-5-r3-006,phase=Scheduled job=None
6.0596,Job,MODIFIED,eval-sanitize-5-r3-005,
6.06,Event,ADDED,eval-sanitize-5-r3-006-wjlsd.18d3d4651570f66d,reason=Scheduled count=None msg=Successfully assigned compute/eval-sanitize-5-r3-006-wjlsd to kind-worker3
6.0644,Node,MODIFIED,kind-worker3,taints=0
6.066,Pod,MODIFIED,eval-sanitize-5-r3-006-wjlsd,phase=Pending node=kind-worker3
6.0754,Node,MODIFIED,kind-worker3,taints=0
6.4953,Event,ADDED,eval-sanitize-5-r3-006-wjlsd.18d3d4652f9a764e,"reason=Pulled count=1 msg=Container image ""busybox:musl"" already present on machine"
6.5141,Event,ADDED,eval-sanitize-5-r3-006-wjlsd.18d3d46530b2dd7b,reason=Created count=1 msg=Created container: task
6.5492,Event,ADDED,eval-sanitize-5-r3-006-wjlsd.18d3d46532c1f659,reason=Started count=1 msg=Started container task
6.7626,Pod,MODIFIED,eval-sanitize-5-r3-006-wjlsd,phase=Running node=kind-worker3
7.0137,TaskRequest,ADDED,eval-sanitize-5-r3-007,phase=None job=None
7.0178,TaskRequest,MODIFIED,eval-sanitize-5-r3-007,phase=Pending job=None
7.0356,Job,ADDED,eval-sanitize-5-r3-007,
7.0394,TaskRequest,MODIFIED,eval-sanitize-5-r3-007,phase=Scheduled job=None
7.0427,Pod,ADDED,eval-sanitize-5-r3-007-4m9hq,phase=Pending node=None
7.0463,Job,MODIFIED,eval-sanitize-5-r3-007,
7.048,Event,ADDED,eval-sanitize-5-r3-007.18d3d465507851ce,reason=SuccessfulCreate count=1 msg=Created pod: eval-sanitize-5-r3-007-4m9hq
7.0488,Job,MODIFIED,eval-sanitize-5-r3-006,
7.049,TaskRequest,MODIFIED,eval-sanitize-5-r3-007,phase=Scheduled job=None
7.0521,Pod,MODIFIED,eval-sanitize-5-r3-007-4m9hq,phase=Pending node=None
7.0525,Event,ADDED,eval-sanitize-5-r3-007-4m9hq.18d3d46550bce1ce,"reason=FailedScheduling count=None msg=0/6 nodes are available: 1 c_wall violated: 2 conflicting context pair(s) with node memory, 5 node(s) had untolerated taint(s). no new claims to deallocate, preemption: 0/6 nodes are available: 1 No preemption victims found for incoming pod, 5 Preemption is not helpful for scheduling."
7.06,Job,MODIFIED,eval-sanitize-5-r3-006,
7.0603,Event,ADDED,eval-sanitize-5-r3-007-4m9hq.18d3d4655142e856,"reason=FailedScheduling count=None msg=0/6 nodes are available: 1 c_wall violated: 2 conflicting context pair(s) with node memory, 5 node(s) had untolerated taint(s). no new claims to deallocate, preemption: 0/6 nodes are available: 1 No preemption victims found for incoming pod, 5 Preemption is not helpful for scheduling."
8.0129,TaskRequest,ADDED,eval-sanitize-5-r3-008,phase=None job=None
8.0167,TaskRequest,MODIFIED,eval-sanitize-5-r3-008,phase=Pending job=None
8.0334,Job,ADDED,eval-sanitize-5-r3-008,
8.038,TaskRequest,MODIFIED,eval-sanitize-5-r3-008,phase=Scheduled job=None
8.0411,Pod,ADDED,eval-sanitize-5-r3-008-l6qpn,phase=Pending node=None
8.0434,Job,MODIFIED,eval-sanitize-5-r3-008,
8.0482,Event,ADDED,eval-sanitize-5-r3-008.18d3d4658bfe781d,reason=SuccessfulCreate count=1 msg=Created pod: eval-sanitize-5-r3-008-l6qpn
8.0484,TaskRequest,MODIFIED,eval-sanitize-5-r3-008,phase=Scheduled job=None
8.0492,Job,MODIFIED,eval-sanitize-5-r3-007,
8.0514,Pod,MODIFIED,eval-sanitize-5-r3-008-l6qpn,phase=Pending node=None
8.0518,Event,ADDED,eval-sanitize-5-r3-008-l6qpn.18d3d4658c453200,"reason=FailedScheduling count=None msg=0/6 nodes are available: 1 c_wall violated: 2 conflicting context pair(s) with node memory, 5 node(s) had untolerated taint(s). no new claims to deallocate, preemption: 0/6 nodes are available: 1 No preemption victims found for incoming pod, 5 Preemption is not helpful for scheduling."
8.0611,Job,MODIFIED,eval-sanitize-5-r3-007,
8.0621,Event,ADDED,eval-sanitize-5-r3-008-l6qpn.18d3d4658cd85016,"reason=FailedScheduling count=None msg=0/6 nodes are available: 1 c_wall violated: 2 conflicting context pair(s) with node memory, 5 node(s) had untolerated taint(s). no new claims to deallocate, preemption: 0/6 nodes are available: 1 No preemption victims found for incoming pod, 5 Preemption is not helpful for scheduling."
9.0052,Node,MODIFIED,kind-worker3,taints=1
9.0116,Pod,MODIFIED,eval-sanitize-5-r3-007-4m9hq,phase=Pending node=None
9.0123,Event,MODIFIED,eval-sanitize-5-r3-007-4m9hq.18d3d4655142e856,"reason=FailedScheduling count=None msg=0/6 nodes are available: 1 c_wall violated: 2 conflicting context pair(s) with node memory, 5 node(s) had untolerated taint(s). no new claims to deallocate, preemption: 0/6 nodes are available: 1 No preemption victims found for incoming pod, 5 Preemption is not helpful for scheduling."
9.0125,TaskRequest,ADDED,eval-sanitize-5-r3-009,phase=None job=None
9.0174,Pod,MODIFIED,eval-sanitize-5-r3-008-l6qpn,phase=Pending node=None
9.0196,Event,MODIFIED,eval-sanitize-5-r3-008-l6qpn.18d3d4658cd85016,"reason=FailedScheduling count=None msg=0/6 nodes are available: 1 c_wall violated: 2 conflicting context pair(s) with node memory, 5 node(s) had untolerated taint(s). no new claims to deallocate, preemption: 0/6 nodes are available: 1 No preemption victims found for incoming pod, 5 Preemption is not helpful for scheduling."
9.0197,TaskRequest,MODIFIED,eval-sanitize-5-r3-009,phase=Pending job=None
9.0212,Node,MODIFIED,kind-worker3,taints=1
9.0358,Job,ADDED,eval-sanitize-5-r3-009,
9.0437,Pod,ADDED,eval-sanitize-5-r3-009-m59w9,phase=Pending node=None
9.0461,Job,MODIFIED,eval-sanitize-5-r3-009,
9.0462,TaskRequest,MODIFIED,eval-sanitize-5-r3-009,phase=Scheduled job=None
9.0483,Job,MODIFIED,eval-sanitize-5-r3-008,
9.0506,Event,ADDED,eval-sanitize-5-r3-009-m59w9.18d3d465c7c67454,"reason=FailedScheduling count=None msg=0/6 nodes are available: 6 node(s) had untolerated taint(s). no new claims to deallocate, preemption: 0/6 nodes are available: 6 Preemption is not helpful for scheduling."
9.0508,Event,ADDED,eval-sanitize-5-r3-009.18d3d465c7c568a7,reason=SuccessfulCreate count=1 msg=Created pod: eval-sanitize-5-r3-009-m59w9
9.0519,Pod,MODIFIED,eval-sanitize-5-r3-009-m59w9,phase=Pending node=None
9.0531,TaskRequest,MODIFIED,eval-sanitize-5-r3-009,phase=Scheduled job=None
9.0578,Job,MODIFIED,eval-sanitize-5-r3-008,
10.0122,TaskRequest,ADDED,eval-sanitize-5-r3-010,phase=None job=None
10.0188,TaskRequest,MODIFIED,eval-sanitize-5-r3-010,phase=Pending job=None
10.0332,Job,ADDED,eval-sanitize-5-r3-010,
10.0401,Pod,ADDED,eval-sanitize-5-r3-010-bppgt,phase=Pending node=None
10.0412,TaskRequest,MODIFIED,eval-sanitize-5-r3-010,phase=Scheduled job=None
10.0443,Job,MODIFIED,eval-sanitize-5-r3-010,
10.0462,Event,ADDED,eval-sanitize-5-r3-010.18d3d46603226b3a,reason=SuccessfulCreate count=1 msg=Created pod: eval-sanitize-5-r3-010-bppgt
10.0464,Event,ADDED,eval-sanitize-5-r3-010-bppgt.18d3d466032e0625,"reason=FailedScheduling count=None msg=0/6 nodes are available: 6 node(s) had untolerated taint(s). no new claims to deallocate, preemption: 0/6 nodes are available: 6 Preemption is not helpful for scheduling."
10.0475,Pod,MODIFIED,eval-sanitize-5-r3-010-bppgt,phase=Pending node=None
10.0484,Job,MODIFIED,eval-sanitize-5-r3-009,
10.0499,TaskRequest,MODIFIED,eval-sanitize-5-r3-010,phase=Scheduled job=None
10.0571,Job,MODIFIED,eval-sanitize-5-r3-009,
10.8428,Pod,MODIFIED,eval-sanitize-5-r3-000-2jwwc,phase=Running node=kind-worker2
11.0098,TaskRequest,ADDED,eval-sanitize-5-r3-011,phase=None job=None
11.0137,TaskRequest,MODIFIED,eval-sanitize-5-r3-011,phase=Pending job=None
11.03,Job,ADDED,eval-sanitize-5-r3-011,
11.0373,Pod,ADDED,eval-sanitize-5-r3-011-kmvsv,phase=Pending node=None
11.0392,TaskRequest,MODIFIED,eval-sanitize-5-r3-011,phase=Scheduled job=None
11.04,Job,MODIFIED,eval-sanitize-5-r3-011,
11.0455,Pod,MODIFIED,eval-sanitize-5-r3-011-kmvsv,phase=Pending node=None
11.0463,Job,MODIFIED,eval-sanitize-5-r3-010,
11.0467,Event,ADDED,eval-sanitize-5-r3-011.18d3d4663e941131,reason=SuccessfulCreate count=1 msg=Created pod: eval-sanitize-5-r3-011-kmvsv
11.0469,Event,ADDED,eval-sanitize-5-r3-011-kmvsv.18d3d4663e9fac9c,"reason=FailedScheduling count=None msg=0/6 nodes are available: 6 node(s) had untolerated taint(s). no new claims to deallocate, preemption: 0/6 nodes are available: 6 Preemption is not helpful for scheduling."
11.0472,TaskRequest,MODIFIED,eval-sanitize-5-r3-011,phase=Scheduled job=None
11.0545,Job,MODIFIED,eval-sanitize-5-r3-010,
11.853,Job,MODIFIED,eval-sanitize-5-r3-000,
11.8635,Job,MODIFIED,eval-sanitize-5-r3-000,
11.9381,Pod,MODIFIED,eval-sanitize-5-r3-000-2jwwc,phase=Succeeded node=kind-worker2
12.0081,TaskRequest,ADDED,eval-sanitize-5-r3-012,phase=None job=None
12.0119,TaskRequest,MODIFIED,eval-sanitize-5-r3-012,phase=Pending job=None
12.0288,Job,ADDED,eval-sanitize-5-r3-012,
12.0354,Pod,ADDED,eval-sanitize-5-r3-012-64j5t,phase=Pending node=None
12.0356,TaskRequest,MODIFIED,eval-sanitize-5-r3-012,phase=Scheduled job=None
12.0386,Job,MODIFIED,eval-sanitize-5-r3-012,
12.0429,Event,ADDED,eval-sanitize-5-r3-012.18d3d4667a167ff5,reason=SuccessfulCreate count=1 msg=Created pod: eval-sanitize-5-r3-012-64j5t
12.0433,Event,ADDED,eval-sanitize-5-r3-012-64j5t.18d3d4667a225cc7,"reason=FailedScheduling count=None msg=0/6 nodes are available: 6 node(s) had untolerated taint(s). no new claims to deallocate, preemption: 0/6 nodes are available: 6 Preemption is not helpful for scheduling."
12.0441,Job,MODIFIED,eval-sanitize-5-r3-011,
12.045,Pod,MODIFIED,eval-sanitize-5-r3-012-64j5t,phase=Pending node=None
12.0452,TaskRequest,MODIFIED,eval-sanitize-5-r3-012,phase=Scheduled job=None
12.0559,Job,MODIFIED,eval-sanitize-5-r3-011,
12.4254,Pod,MODIFIED,eval-sanitize-5-r3-001-kbq6c,phase=Running node=kind-worker
12.7716,Pod,MODIFIED,eval-sanitize-5-r3-002-lxfh7,phase=Running node=kind-worker4
12.8725,Job,MODIFIED,eval-sanitize-5-r3-000,
12.8808,Pod,MODIFIED,eval-sanitize-5-r3-000-2jwwc,phase=Succeeded node=kind-worker2
12.8823,Job,MODIFIED,eval-sanitize-5-r3-000,
13.0087,TaskRequest,ADDED,eval-sanitize-5-r3-013,phase=None job=None
13.014,TaskRequest,MODIFIED,eval-sanitize-5-r3-013,phase=Pending job=None
13.0284,Job,ADDED,eval-sanitize-5-r3-013,
13.0359,Pod,ADDED,eval-sanitize-5-r3-013-lk4lx,phase=Pending node=None
13.036,TaskRequest,MODIFIED,eval-sanitize-5-r3-013,phase=Scheduled job=None
13.0388,Job,MODIFIED,eval-sanitize-5-r3-013,
13.0409,Event,ADDED,eval-sanitize-5-r3-013.18d3d466b5b01048,reason=SuccessfulCreate count=1 msg=Created pod: eval-sanitize-5-r3-013-lk4lx
13.042,Job,MODIFIED,eval-sanitize-5-r3-012,
13.043,Pod,MODIFIED,eval-sanitize-5-r3-013-lk4lx,phase=Pending node=None
13.0434,Event,ADDED,eval-sanitize-5-r3-013-lk4lx.18d3d466b5ba0804,"reason=FailedScheduling count=None msg=0/6 nodes are available: 6 node(s) had untolerated taint(s). no new claims to deallocate, preemption: 0/6 nodes are available: 6 Preemption is not helpful for scheduling."
13.0439,TaskRequest,MODIFIED,eval-sanitize-5-r3-013,phase=Scheduled job=None
13.05,Job,MODIFIED,eval-sanitize-5-r3-012,
13.4313,Job,MODIFIED,eval-sanitize-5-r3-001,
13.4424,Job,MODIFIED,eval-sanitize-5-r3-001,
13.521,Pod,MODIFIED,eval-sanitize-5-r3-001-kbq6c,phase=Succeeded node=kind-worker
13.7796,Job,MODIFIED,eval-sanitize-5-r3-002,
13.7886,Pod,MODIFIED,eval-sanitize-5-r3-003-9sqzh,phase=Running node=kind-worker5
13.7896,Job,MODIFIED,eval-sanitize-5-r3-002,
13.8785,Job,MODIFIED,eval-sanitize-5-r3-000,
13.8814,Pod,MODIFIED,eval-sanitize-5-r3-002-lxfh7,phase=Succeeded node=kind-worker4
13.8829,Job,MODIFIED,eval-sanitize-5-r3-000,
13.8872,Event,ADDED,eval-sanitize-5-r3-000.18d3d466e838b9f1,reason=Completed count=1 msg=Job completed
13.8962,Job,MODIFIED,eval-sanitize-5-r3-000,
13.9016,TaskRequest,MODIFIED,eval-sanitize-5-r3-000,phase=Complete job=None
13.9104,Job,MODIFIED,eval-sanitize-5-r3-000,
14.0108,TaskRequest,ADDED,eval-sanitize-5-r3-014,phase=None job=None
14.0145,TaskRequest,MODIFIED,eval-sanitize-5-r3-014,phase=Pending job=None
14.0304,Job,ADDED,eval-sanitize-5-r3-014,
14.038,Pod,ADDED,eval-sanitize-5-r3-014-blrpd,phase=Pending node=None
14.0381,TaskRequest,MODIFIED,eval-sanitize-5-r3-014,phase=Scheduled job=None
14.0406,Job,MODIFIED,eval-sanitize-5-r3-014,
14.0426,Event,ADDED,eval-sanitize-5-r3-014.18d3d466f1676676,reason=SuccessfulCreate count=1 msg=Created pod: eval-sanitize-5-r3-014-blrpd
14.0438,Pod,MODIFIED,eval-sanitize-5-r3-014-blrpd,phase=Pending node=None
14.0446,Job,MODIFIED,eval-sanitize-5-r3-013,
14.045,Event,ADDED,eval-sanitize-5-r3-014-blrpd.18d3d466f16f671b,"reason=FailedScheduling count=None msg=0/6 nodes are available: 6 node(s) had untolerated taint(s). no new claims to deallocate, preemption: 0/6 nodes are available: 6 Preemption is not helpful for scheduling."
14.0453,TaskRequest,MODIFIED,eval-sanitize-5-r3-014,phase=Scheduled job=None
14.0525,Job,MODIFIED,eval-sanitize-5-r3-013,
14.443,Job,MODIFIED,eval-sanitize-5-r3-001,
14.4518,Pod,MODIFIED,eval-sanitize-5-r3-001-kbq6c,phase=Succeeded node=kind-worker
14.4534,Job,MODIFIED,eval-sanitize-5-r3-001,
14.7809,Pod,MODIFIED,eval-sanitize-5-r3-004-th9rv,phase=Running node=kind-worker4
14.7852,Job,MODIFIED,eval-sanitize-5-r3-002,
14.7933,Job,MODIFIED,eval-sanitize-5-r3-003,
14.7957,Job,MODIFIED,eval-sanitize-5-r3-002,
14.7973,Pod,MODIFIED,eval-sanitize-5-r3-002-lxfh7,phase=Succeeded node=kind-worker4
14.804,Job,MODIFIED,eval-sanitize-5-r3-003,
14.9488,Pod,MODIFIED,eval-sanitize-5-r3-003-9sqzh,phase=Succeeded node=kind-worker5
15.0095,TaskRequest,ADDED,eval-sanitize-5-r3-015,phase=None job=None
15.0131,TaskRequest,MODIFIED,eval-sanitize-5-r3-015,phase=Pending job=None
15.0301,Job,ADDED,eval-sanitize-5-r3-015,
15.0359,Pod,ADDED,eval-sanitize-5-r3-015-x7rh2,phase=Pending node=None
15.0377,TaskRequest,MODIFIED,eval-sanitize-5-r3-015,phase=Scheduled job=None
15.0407,Job,MODIFIED,eval-sanitize-5-r3-015,
15.0428,Event,ADDED,eval-sanitize-5-r3-015.18d3d4672cd02572,reason=SuccessfulCreate count=1 msg=Created pod: eval-sanitize-5-r3-015-x7rh2
15.0431,Event,ADDED,eval-sanitize-5-r3-015-x7rh2.18d3d4672cda56b6,"reason=FailedScheduling count=None msg=0/6 nodes are available: 6 node(s) had untolerated taint(s). no new claims to deallocate, preemption: 0/6 nodes are available: 6 Preemption is not helpful for scheduling."
15.044,Job,MODIFIED,eval-sanitize-5-r3-014,
15.045,Pod,MODIFIED,eval-sanitize-5-r3-015-x7rh2,phase=Pending node=None
15.046,TaskRequest,MODIFIED,eval-sanitize-5-r3-015,phase=Scheduled job=None
15.0526,Job,MODIFIED,eval-sanitize-5-r3-014,
15.4484,Job,MODIFIED,eval-sanitize-5-r3-001,
15.4533,Job,MODIFIED,eval-sanitize-5-r3-001,
15.458,Event,ADDED,eval-sanitize-5-r3-001.18d3d46745af58be,reason=Completed count=1 msg=Job completed
15.465,Job,MODIFIED,eval-sanitize-5-r3-001,
15.4701,TaskRequest,MODIFIED,eval-sanitize-5-r3-001,phase=Complete job=None
15.4825,Job,MODIFIED,eval-sanitize-5-r3-001,
15.5632,Node,MODIFIED,kind-worker5,taints=1
15.5795,Node,MODIFIED,kind-worker5,taints=1
15.5874,Node,MODIFIED,kind-worker5,taints=0
15.593,Pod,MODIFIED,eval-sanitize-5-r3-007-4m9hq,phase=Pending node=kind-worker5
15.5979,Event,ADDED,eval-sanitize-5-r3-007-4m9hq.18d3d4674dffebaa,reason=Scheduled count=None msg=Successfully assigned compute/eval-sanitize-5-r3-007-4m9hq to kind-worker5
15.6028,Pod,MODIFIED,eval-sanitize-5-r3-008-l6qpn,phase=Pending node=kind-worker5
15.6054,Pod,MODIFIED,eval-sanitize-5-r3-007-4m9hq,phase=Pending node=kind-worker5
15.6067,Node,MODIFIED,kind-worker5,taints=0
15.6093,Pod,MODIFIED,eval-sanitize-5-r3-009-m59w9,phase=Pending node=kind-worker5
15.6119,Event,ADDED,eval-sanitize-5-r3-008-l6qpn.18d3d4674e91ea24,reason=Scheduled count=None msg=Successfully assigned compute/eval-sanitize-5-r3-008-l6qpn to kind-worker5
15.6128,Pod,MODIFIED,eval-sanitize-5-r3-010-bppgt,phase=Pending node=kind-worker5
15.6136,Pod,MODIFIED,eval-sanitize-5-r3-011-kmvsv,phase=Pending node=kind-worker5
15.6178,Pod,MODIFIED,eval-sanitize-5-r3-008-l6qpn,phase=Pending node=kind-worker5
15.6188,Pod,MODIFIED,eval-sanitize-5-r3-012-64j5t,phase=Pending node=None
15.6203,Event,ADDED,eval-sanitize-5-r3-009-m59w9.18d3d4674efacde6,reason=Scheduled count=None msg=Successfully assigned compute/eval-sanitize-5-r3-009-m59w9 to kind-worker5
15.6205,Event,ADDED,eval-sanitize-5-r3-012-64j5t.18d3d4674f00260c,"reason=FailedScheduling count=None msg=0/6 nodes are available: 1 c_wall violated: 3 conflicting context pair(s) with node memory, 5 node(s) had untolerated taint(s). no new claims to deallocate, preemption: 0/6 nodes are available: 1 No preemption victims found for incoming pod, 5 Preemption is not helpful for scheduling."
15.6208,Event,ADDED,eval-sanitize-5-r3-011-kmvsv.18d3d4674f2a0507,reason=Scheduled count=None msg=Successfully assigned compute/eval-sanitize-5-r3-011-kmvsv to kind-worker5
15.621,Event,ADDED,eval-sanitize-5-r3-010-bppgt.18d3d4674f2b9514,reason=Scheduled count=None msg=Successfully assigned compute/eval-sanitize-5-r3-010-bppgt to kind-worker5
15.6265,Node,MODIFIED,kind-worker5,taints=0
15.6287,Pod,MODIFIED,eval-sanitize-5-r3-009-m59w9,phase=Pending node=kind-worker5
15.6302,Pod,MODIFIED,eval-sanitize-5-r3-013-lk4lx,phase=Pending node=kind-worker5
15.6317,Event,ADDED,eval-sanitize-5-r3-013-lk4lx.18d3d467501a6b5c,reason=Scheduled count=None msg=Successfully assigned compute/eval-sanitize-5-r3-013-lk4lx to kind-worker5
15.6363,Pod,MODIFIED,eval-sanitize-5-r3-010-bppgt,phase=Pending node=kind-worker5
15.6422,Pod,MODIFIED,eval-sanitize-5-r3-011-kmvsv,phase=Pending node=kind-worker5
15.6478,Pod,MODIFIED,eval-sanitize-5-r3-013-lk4lx,phase=Pending node=kind-worker5
15.7082,Pod,MODIFIED,eval-sanitize-5-r3-014-blrpd,phase=Pending node=None
15.7093,Event,ADDED,eval-sanitize-5-r3-014-blrpd.18d3d46754831316,"reason=FailedScheduling count=None msg=0/6 nodes are available: 1 c_wall violated: 3 conflicting context pair(s) with node memory, 5 node(s) had untolerated taint(s). no new claims to deallocate, preemption: 0/6 nodes are available: 1 No preemption victims found for incoming pod, 5 Preemption is not helpful for scheduling."
15.7108,Node,MODIFIED,kind-worker5,taints=0
15.7182,Pod,MODIFIED,eval-sanitize-5-r3-015-x7rh2,phase=Pending node=kind-worker5
15.7186,Event,ADDED,eval-sanitize-5-r3-012-64j5t.18d3d46755462c22,"reason=FailedScheduling count=None msg=0/6 nodes are available: 1 c_wall violated: 3 conflicting context pair(s) with node memory, 5 node(s) had untolerated taint(s). no new claims to deallocate, preemption: 0/6 nodes are available: 1 No preemption victims found for incoming pod, 5 Preemption is not helpful for scheduling."
15.7209,Event,ADDED,eval-sanitize-5-r3-014-blrpd.18d3d467556ede3d,"reason=FailedScheduling count=None msg=0/6 nodes are available: 1 c_wall violated: 3 conflicting context pair(s) with node memory, 5 node(s) had untolerated taint(s). no new claims to deallocate, preemption: 0/6 nodes are available: 1 No preemption victims found for incoming pod, 5 Preemption is not helpful for scheduling."
15.7223,Event,ADDED,eval-sanitize-5-r3-015-x7rh2.18d3d46755736dad,reason=Scheduled count=None msg=Successfully assigned compute/eval-sanitize-5-r3-015-x7rh2 to kind-worker5
15.7269,Event,MODIFIED,eval-sanitize-5-r3-012-64j5t.18d3d46755462c22,"reason=FailedScheduling count=None msg=0/6 nodes are available: 1 c_wall violated: 3 conflicting context pair(s) with node memory, 5 node(s) had untolerated taint(s). no new claims to deallocate, preemption: 0/6 nodes are available: 1 No preemption victims found for incoming pod, 5 Preemption is not helpful for scheduling."
15.7304,Pod,MODIFIED,eval-sanitize-5-r3-015-x7rh2,phase=Pending node=kind-worker5
15.7308,Event,MODIFIED,eval-sanitize-5-r3-014-blrpd.18d3d467556ede3d,"reason=FailedScheduling count=None msg=0/6 nodes are available: 1 c_wall violated: 3 conflicting context pair(s) with node memory, 5 node(s) had untolerated taint(s). no new claims to deallocate, preemption: 0/6 nodes are available: 1 No preemption victims found for incoming pod, 5 Preemption is not helpful for scheduling."
15.7752,Node,MODIFIED,kind-worker2,taints=1
15.7788,Pod,MODIFIED,eval-sanitize-5-r3-005-cqc9r,phase=Running node=kind-worker3
15.78,Node,MODIFIED,kind-worker5,taints=0
15.7864,Job,MODIFIED,eval-sanitize-5-r3-004,
15.7908,Job,MODIFIED,eval-sanitize-5-r3-002,
15.7966,Job,MODIFIED,eval-sanitize-5-r3-002,
15.8002,Job,MODIFIED,eval-sanitize-5-r3-004,
15.8016,Event,ADDED,eval-sanitize-5-r3-002.18d3d4675a245eec,reason=Completed count=1 msg=Job completed
15.8026,Job,MODIFIED,eval-sanitize-5-r3-003,
15.8095,Job,MODIFIED,eval-sanitize-5-r3-002,
15.8131,Pod,MODIFIED,eval-sanitize-5-r3-003-9sqzh,phase=Succeeded node=kind-worker5
15.8144,Job,MODIFIED,eval-sanitize-5-r3-003,
15.8146,TaskRequest,MODIFIED,eval-sanitize-5-r3-002,phase=Complete job=None
15.8242,Job,MODIFIED,eval-sanitize-5-r3-002,
15.8692,Node,MODIFIED,kind-worker2,taints=1
15.8713,Node,MODIFIED,kind-worker5,taints=0
15.8747,Pod,MODIFIED,eval-sanitize-5-r3-004-th9rv,phase=Succeeded node=kind-worker4
15.879,Node,MODIFIED,kind-worker2,taints=0
15.8925,Node,MODIFIED,kind-worker2,taints=0
15.9084,Pod,MODIFIED,eval-sanitize-5-r3-012-64j5t,phase=Pending node=kind-worker2
15.9122,Event,ADDED,eval-sanitize-5-r3-012-64j5t.18d3d46760cab156,reason=Scheduled count=None msg=Successfully assigned compute/eval-sanitize-5-r3-012-64j5t to kind-worker2
15.9192,Node,MODIFIED,kind-worker2,taints=0
15.9272,Pod,MODIFIED,eval-sanitize-5-r3-012-64j5t,phase=Pending node=kind-worker2
15.9318,Pod,MODIFIED,eval-sanitize-5-r3-014-blrpd,phase=Pending node=kind-worker2
15.9363,Event,ADDED,eval-sanitize-5-r3-014-blrpd.18d3d467623752eb,reason=Scheduled count=None msg=Successfully assigned compute/eval-sanitize-5-r3-014-blrpd to kind-worker2
15.947,Pod,MODIFIED,eval-sanitize-5-r3-014-blrpd,phase=Pending node=kind-worker2
15.9633,Node,MODIFIED,kind-worker2,taints=0
16.0207,TaskRequest,ADDED,eval-sanitize-5-r3-016,phase=None job=None
16.0281,TaskRequest,MODIFIED,eval-sanitize-5-r3-016,phase=Pending job=None
16.0429,Job,MODIFIED,eval-sanitize-5-r3-015,
16.0486,Job,ADDED,eval-sanitize-5-r3-016,
16.0545,TaskRequest,MODIFIED,eval-sanitize-5-r3-016,phase=Scheduled job=None
16.0588,Pod,ADDED,eval-sanitize-5-r3-016-5jw6h,phase=Pending node=None
16.0619,Job,MODIFIED,eval-sanitize-5-r3-016,
16.0706,Event,ADDED,eval-sanitize-5-r3-016.18d3d46769c159ee,reason=SuccessfulCreate count=1 msg=Created pod: eval-sanitize-5-r3-016-5jw6h
16.0708,TaskRequest,MODIFIED,eval-sanitize-5-r3-016,phase=Scheduled job=None
16.0712,Event,ADDED,eval-sanitize-5-r3-007-4m9hq.18d3d46769e29b6c,"reason=Pulled count=1 msg=Container image ""busybox:musl"" already present on machine"
16.0781,Job,MODIFIED,eval-sanitize-5-r3-015,
16.085,Pod,MODIFIED,eval-sanitize-5-r3-016-5jw6h,phase=Pending node=kind-worker2
16.0901,Event,ADDED,eval-sanitize-5-r3-016-5jw6h.18d3d4676b4fdf40,reason=Scheduled count=None msg=Successfully assigned compute/eval-sanitize-5-r3-016-5jw6h to kind-worker2
16.1,Node,MODIFIED,kind-worker2,taints=0
16.1006,Event,ADDED,eval-sanitize-5-r3-007-4m9hq.18d3d4676bb9aed0,reason=Created count=1 msg=Created container: task
16.1022,Pod,MODIFIED,eval-sanitize-5-r3-016-5jw6h,phase=Pending node=kind-worker2
16.1071,Event,ADDED,eval-sanitize-5-r3-009-m59w9.18d3d4676bd2dd0b,"reason=Pulled count=1 msg=Container image ""busybox:musl"" already present on machine"
16.1146,Node,MODIFIED,kind-worker2,taints=0
16.115,Event,ADDED,eval-sanitize-5-r3-011-kmvsv.18d3d4676c05b65a,"reason=Pulled count=1 msg=Container image ""busybox:musl"" already present on machine"
16.1222,Event,ADDED,eval-sanitize-5-r3-008-l6qpn.18d3d4676c4f6d61,"reason=Pulled count=1 msg=Container image ""busybox:musl"" already present on machine"
16.1268,Event,ADDED,eval-sanitize-5-r3-010-bppgt.18d3d4676c675974,"reason=Pulled count=1 msg=Container image ""busybox:musl"" already present on machine"
16.1317,Event,ADDED,eval-sanitize-5-r3-013-lk4lx.18d3d4676d0c76ca,"reason=Pulled count=1 msg=Container image ""busybox:musl"" already present on machine"
16.1355,Event,ADDED,eval-sanitize-5-r3-007-4m9hq.18d3d4676e17bfb5,reason=Started count=1 msg=Started container task
16.1424,Event,ADDED,eval-sanitize-5-r3-009-m59w9.18d3d4676e5869c6,reason=Created count=1 msg=Created container: task
16.1465,Event,ADDED,eval-sanitize-5-r3-011-kmvsv.18d3d4676e9ecc6c,reason=Created count=1 msg=Created container: task
16.1505,Event,ADDED,eval-sanitize-5-r3-015-x7rh2.18d3d4676e9fb357,"reason=Pulled count=1 msg=Container image ""busybox:musl"" already present on machine"
16.1611,Event,ADDED,eval-sanitize-5-r3-008-l6qpn.18d3d4676fb44ad7,reason=Created count=1 msg=Created container: task
16.174,Event,ADDED,eval-sanitize-5-r3-010-bppgt.18d3d467704808f9,reason=Created count=1 msg=Created container: task
16.1809,Event,ADDED,eval-sanitize-5-r3-013-lk4lx.18d3d467708e5e71,reason=Created count=1 msg=Created container: task
16.1853,Event,ADDED,eval-sanitize-5-r3-015-x7rh2.18d3d46770edb540,reason=Created count=1 msg=Created container: task
16.2108,Event,ADDED,eval-sanitize-5-r3-011-kmvsv.18d3d467729b682e,reason=Started count=1 msg=Started container task
16.2156,Event,ADDED,eval-sanitize-5-r3-009-m59w9.18d3d467729f45c9,reason=Started count=1 msg=Started container task
16.2345,Event,ADDED,eval-sanitize-5-r3-010-bppgt.18d3d46773ec128d,reason=Started count=1 msg=Started container task
16.2382,Event,ADDED,eval-sanitize-5-r3-008-l6qpn.18d3d46773ee5acc,reason=Started count=1 msg=Started container task
16.2419,Event,ADDED,eval-sanitize-5-r3-015-x7rh2.18d3d46773ee6e72,reason=Started count=1 msg=Started container task
16.2455,Event,ADDED,eval-sanitize-5-r3-013-lk4lx.18d3d46773ef09e9,reason=Started count=1 msg=Started container task
16.3472,Event,ADDED,eval-sanitize-5-r3-012-64j5t.18d3d4677a8d6d34,"reason=Pulled count=1 msg=Container image ""busybox:musl"" already present on machine"
16.3551,Event,ADDED,eval-sanitize-5-r3-014-blrpd.18d3d4677b360d3b,"reason=Pulled count=1 msg=Container image ""busybox:musl"" already present on machine"
16.3675,Event,ADDED,eval-sanitize-5-r3-012-64j5t.18d3d4677c013c78,reason=Created count=1 msg=Created container: task
16.378,Event,ADDED,eval-sanitize-5-r3-014-blrpd.18d3d4677c9a020c,reason=Created count=1 msg=Created container: task
16.4049,Event,ADDED,eval-sanitize-5-r3-012-64j5t.18d3d4677e0ac225,reason=Started count=1 msg=Started container task
16.412,Event,ADDED,eval-sanitize-5-r3-014-blrpd.18d3d4677ea2783f,reason=Started count=1 msg=Started container task
16.5117,Event,ADDED,eval-sanitize-5-r3-016-5jw6h.18d3d467848511dd,"reason=Pulled count=1 msg=Container image ""busybox:musl"" already present on machine"
16.5288,Event,ADDED,eval-sanitize-5-r3-016-5jw6h.18d3d4678599e9da,reason=Created count=1 msg=Created container: task
16.5679,Event,ADDED,eval-sanitize-5-r3-016-5jw6h.18d3d46787e3652e,reason=Started count=1 msg=Started container task
16.7852,Pod,MODIFIED,eval-sanitize-5-r3-006-wjlsd,phase=Running node=kind-worker3
16.7867,Job,MODIFIED,eval-sanitize-5-r3-005,
16.7923,Job,MODIFIED,eval-sanitize-5-r3-004,
16.7989,Pod,MODIFIED,eval-sanitize-5-r3-009-m59w9,phase=Running node=kind-worker5
16.8027,Job,MODIFIED,eval-sanitize-5-r3-005,
16.8047,Job,MODIFIED,eval-sanitize-5-r3-004,
16.8061,Pod,MODIFIED,eval-sanitize-5-r3-004-th9rv,phase=Succeeded node=kind-worker4
16.8076,Job,MODIFIED,eval-sanitize-5-r3-003,
16.8115,Pod,MODIFIED,eval-sanitize-5-r3-015-x7rh2,phase=Running node=kind-worker5
16.8134,Job,MODIFIED,eval-sanitize-5-r3-003,
16.8199,Event,ADDED,eval-sanitize-5-r3-003.18d3d46796c49864,reason=Completed count=1 msg=Job completed
16.8213,Pod,MODIFIED,eval-sanitize-5-r3-008-l6qpn,phase=Running node=kind-worker5
16.8247,Job,MODIFIED,eval-sanitize-5-r3-003,
16.8283,Pod,MODIFIED,eval-sanitize-5-r3-010-bppgt,phase=Running node=kind-worker5
16.8309,TaskRequest,MODIFIED,eval-sanitize-5-r3-003,phase=Complete job=None
16.8371,Pod,MODIFIED,eval-sanitize-5-r3-007-4m9hq,phase=Running node=kind-worker5
16.84,Job,MODIFIED,eval-sanitize-5-r3-003,
16.843,Pod,MODIFIED,eval-sanitize-5-r3-013-lk4lx,phase=Running node=kind-worker5
16.8502,Pod,MODIFIED,eval-sanitize-5-r3-011-kmvsv,phase=Running node=kind-worker5
16.8543,Pod,MODIFIED,eval-sanitize-5-r3-016-5jw6h,phase=Running node=kind-worker2
16.8613,Pod,MODIFIED,eval-sanitize-5-r3-012-64j5t,phase=Running node=kind-worker2
16.8673,Pod,MODIFIED,eval-sanitize-5-r3-014-blrpd,phase=Running node=kind-worker2
16.8693,Pod,MODIFIED,eval-sanitize-5-r3-005-cqc9r,phase=Succeeded node=kind-worker3
17.0196,Node,MODIFIED,kind-worker,taints=1
17.0216,TaskRequest,ADDED,eval-sanitize-5-r3-017,phase=None job=None
17.0249,TaskRequest,MODIFIED,eval-sanitize-5-r3-017,phase=Pending job=None
17.0404,Job,ADDED,eval-sanitize-5-r3-017,
17.0464,Pod,ADDED,eval-sanitize-5-r3-017-hs5c9,phase=Pending node=None
17.0478,TaskRequest,MODIFIED,eval-sanitize-5-r3-017,phase=Scheduled job=None
17.0486,Job,MODIFIED,eval-sanitize-5-r3-017,
17.0494,Job,MODIFIED,eval-sanitize-5-r3-015,
17.0507,Event,ADDED,eval-sanitize-5-r3-017.18d3d467a4a66b53,reason=SuccessfulCreate count=1 msg=Created pod: eval-sanitize-5-r3-017-hs5c9
17.0591,Pod,MODIFIED,eval-sanitize-5-r3-017-hs5c9,phase=Pending node=kind-worker5
17.0604,TaskRequest,MODIFIED,eval-sanitize-5-r3-017,phase=Scheduled job=None
17.0612,Job,MODIFIED,eval-sanitize-5-r3-015,
17.0666,Node,MODIFIED,kind-worker,taints=0
17.067,Event,ADDED,eval-sanitize-5-r3-017-hs5c9.18d3d467a5608705,reason=Scheduled count=None msg=Successfully assigned compute/eval-sanitize-5-r3-017-hs5c9 to kind-worker5
17.0678,Job,MODIFIED,eval-sanitize-5-r3-016,
17.0708,Pod,MODIFIED,eval-sanitize-5-r3-017-hs5c9,phase=Pending node=kind-worker5
17.0738,Node,MODIFIED,kind-worker,taints=0
17.0766,Job,MODIFIED,eval-sanitize-5-r3-016,
17.0836,Node,MODIFIED,kind-worker,taints=0
17.4837,Event,ADDED,eval-sanitize-5-r3-017-hs5c9.18d3d467be753ff8,"reason=Pulled count=1 msg=Container image ""busybox:musl"" already present on machine"
17.5015,Event,ADDED,eval-sanitize-5-r3-017-hs5c9.18d3d467bf90099b,reason=Created count=1 msg=Created container: task
17.5351,Event,ADDED,eval-sanitize-5-r3-017-hs5c9.18d3d467c18c8953,reason=Started count=1 msg=Started container task
17.7921,Job,MODIFIED,eval-sanitize-5-r3-006,
17.7941,Job,MODIFIED,eval-sanitize-5-r3-005,
17.7966,Job,MODIFIED,eval-sanitize-5-r3-004,
17.8029,Job,MODIFIED,eval-sanitize-5-r3-004,
17.8057,Job,MODIFIED,eval-sanitize-5-r3-006,
17.8078,Pod,MODIFIED,eval-sanitize-5-r3-005-cqc9r,phase=Succeeded node=kind-worker3
17.8084,Event,ADDED,eval-sanitize-5-r3-004.18d3d467d1bd364a,reason=Completed count=1 msg=Job completed
17.8092,Job,MODIFIED,eval-sanitize-5-r3-009,
17.8104,Pod,MODIFIED,eval-sanitize-5-r3-017-hs5c9,phase=Running node=kind-worker5
17.8115,Job,MODIFIED,eval-sanitize-5-r3-005,
17.8148,Job,MODIFIED,eval-sanitize-5-r3-004,
17.8173,Job,MODIFIED,eval-sanitize-5-r3-009,
17.8196,TaskRequest,MODIFIED,eval-sanitize-5-r3-004,phase=Complete job=None
17.8252,Job,MODIFIED,eval-sanitize-5-r3-008,
17.8283,Job,MODIFIED,eval-sanitize-5-r3-004,
17.8324,Job,MODIFIED,eval-sanitize-5-r3-010,
17.8342,Job,MODIFIED,eval-sanitize-5-r3-008,
17.8414,Job,MODIFIED,eval-sanitize-5-r3-007,
17.8467,Job,MODIFIED,eval-sanitize-5-r3-013,
17.8536,Job,MODIFIED,eval-sanitize-5-r3-011,
17.8661,Job,MODIFIED,eval-sanitize-5-r3-012,
17.868,Job,MODIFIED,eval-sanitize-5-r3-010,
17.8706,Job,MODIFIED,eval-sanitize-5-r3-007,
17.8712,Job,MODIFIED,eval-sanitize-5-r3-013,
17.8725,Job,MODIFIED,eval-sanitize-5-r3-014,
17.8732,Job,MODIFIED,eval-sanitize-5-r3-011,
17.8756,Job,MODIFIED,eval-sanitize-5-r3-012,
17.9281,Job,MODIFIED,eval-sanitize-5-r3-014,
17.9336,Pod,MODIFIED,eval-sanitize-5-r3-006-wjlsd,phase=Succeeded node=kind-worker3
18.0269,TaskRequest,ADDED,eval-sanitize-5-r3-018,phase=None job=None
18.0308,TaskRequest,MODIFIED,eval-sanitize-5-r3-018,phase=Pending job=None
18.0461,Job,ADDED,eval-sanitize-5-r3-018,
18.0514,Job,MODIFIED,eval-sanitize-5-r3-017,
18.053,TaskRequest,MODIFIED,eval-sanitize-5-r3-018,phase=Scheduled job=None
18.054,Pod,ADDED,eval-sanitize-5-r3-018-pndjq,phase=Pending node=None
18.0554,Job,MODIFIED,eval-sanitize-5-r3-018,
18.0581,Event,ADDED,eval-sanitize-5-r3-018.18d3d467e0b23c51,reason=SuccessfulCreate count=1 msg=Created pod: eval-sanitize-5-r3-018-pndjq
18.0614,TaskRequest,MODIFIED,eval-sanitize-5-r3-018,phase=Scheduled job=None
18.064,Job,MODIFIED,eval-sanitize-5-r3-017,
18.066,Pod,MODIFIED,eval-sanitize-5-r3-018-pndjq,phase=Pending node=kind-worker
18.0695,Event,ADDED,eval-sanitize-5-r3-018-pndjq.18d3d467e16c0f8b,reason=Scheduled count=None msg=Successfully assigned compute/eval-sanitize-5-r3-018-pndjq to kind-worker
18.076,Node,MODIFIED,kind-worker,taints=0
18.078,Pod,MODIFIED,eval-sanitize-5-r3-018-pndjq,phase=Pending node=kind-worker
18.086,Node,MODIFIED,kind-worker,taints=0
18.4905,Event,ADDED,eval-sanitize-5-r3-018-pndjq.18d3d467fa760a49,"reason=Pulled count=1 msg=Container image ""busybox:musl"" already present on machine"
18.5106,Event,ADDED,eval-sanitize-5-r3-018-pndjq.18d3d467fb9452a1,reason=Created count=1 msg=Created container: task
18.5683,Event,ADDED,eval-sanitize-5-r3-018-pndjq.18d3d467ff1caf9b,reason=Started count=1 msg=Started container task
18.8031,Job,MODIFIED,eval-sanitize-5-r3-006,
18.8048,Job,MODIFIED,eval-sanitize-5-r3-005,
18.8097,Job,MODIFIED,eval-sanitize-5-r3-005,
18.8127,Pod,MODIFIED,eval-sanitize-5-r3-006-wjlsd,phase=Succeeded node=kind-worker3
18.8141,Job,MODIFIED,eval-sanitize-5-r3-006,
18.8153,Event,ADDED,eval-sanitize-5-r3-005.18d3d4680dc26095,reason=Completed count=1 msg=Job completed
18.8221,Job,MODIFIED,eval-sanitize-5-r3-005,
18.828,TaskRequest,MODIFIED,eval-sanitize-5-r3-005,phase=Complete job=None
18.8374,Job,MODIFIED,eval-sanitize-5-r3-005,
19.0092,TaskRequest,ADDED,eval-sanitize-5-r3-019,phase=None job=None
19.0131,TaskRequest,MODIFIED,eval-sanitize-5-r3-019,phase=Pending job=None
19.0293,Job,ADDED,eval-sanitize-5-r3-019,
19.0334,TaskRequest,MODIFIED,eval-sanitize-5-r3-019,phase=Scheduled job=None
19.0367,Pod,ADDED,eval-sanitize-5-r3-019-dq89j,phase=Pending node=None
19.0394,Job,MODIFIED,eval-sanitize-5-r3-019,
19.0432,Event,ADDED,eval-sanitize-5-r3-019.18d3d4681b42f4dc,reason=SuccessfulCreate count=1 msg=Created pod: eval-sanitize-5-r3-019-dq89j
19.0434,TaskRequest,MODIFIED,eval-sanitize-5-r3-019,phase=Scheduled job=None
19.0527,Pod,MODIFIED,eval-sanitize-5-r3-019-dq89j,phase=Pending node=kind-worker2
19.0577,Event,ADDED,eval-sanitize-5-r3-019-dq89j.18d3d4681c3df8d1,reason=Scheduled count=None msg=Successfully assigned compute/eval-sanitize-5-r3-019-dq89j to kind-worker2
19.0621,Job,MODIFIED,eval-sanitize-5-r3-018,
19.0645,Pod,MODIFIED,eval-sanitize-5-r3-019-dq89j,phase=Pending node=kind-worker2
19.0723,Job,MODIFIED,eval-sanitize-5-r3-018,
19.1956,Node,MODIFIED,kind-worker3,taints=1
19.2685,Node,MODIFIED,kind-worker3,taints=1
19.2748,Node,MODIFIED,kind-worker3,taints=0
19.2867,Node,MODIFIED,kind-worker3,taints=0
19.4406,Pod,MODIFIED,eval-sanitize-5-r3-018-pndjq,phase=Running node=kind-worker
19.475,Event,ADDED,eval-sanitize-5-r3-019-dq89j.18d3d46835267b00,"reason=Pulled count=1 msg=Container image ""busybox:musl"" already present on machine"
19.4933,Event,ADDED,eval-sanitize-5-r3-019-dq89j.18d3d468364a19f3,reason=Created count=1 msg=Created container: task
19.5266,Event,ADDED,eval-sanitize-5-r3-019-dq89j.18d3d468383f0d04,reason=Started count=1 msg=Started container task
19.8139,Job,MODIFIED,eval-sanitize-5-r3-006,
19.8194,Job,MODIFIED,eval-sanitize-5-r3-006,
19.8238,Event,ADDED,eval-sanitize-5-r3-006.18d3d46849ed350c,reason=Completed count=1 msg=Job completed
19.8307,Job,MODIFIED,eval-sanitize-5-r3-006,
19.835,TaskRequest,MODIFIED,eval-sanitize-5-r3-006,phase=Complete job=None
19.8444,Job,MODIFIED,eval-sanitize-5-r3-006,
19.8629,Pod,MODIFIED,eval-sanitize-5-r3-019-dq89j,phase=Running node=kind-worker2
20.0084,TaskRequest,ADDED,eval-sanitize-5-r3-020,phase=None job=None
20.0123,TaskRequest,MODIFIED,eval-sanitize-5-r3-020,phase=Pending job=None
20.0284,Job,ADDED,eval-sanitize-5-r3-020,
20.0336,TaskRequest,MODIFIED,eval-sanitize-5-r3-020,phase=Scheduled job=None
20.0369,Pod,ADDED,eval-sanitize-5-r3-020-m7rv7,phase=Pending node=None
20.039,Job,MODIFIED,eval-sanitize-5-r3-020,
20.0411,Job,MODIFIED,eval-sanitize-5-r3-019,
20.0425,Event,ADDED,eval-sanitize-5-r3-020.18d3d46856dcf7ef,reason=SuccessfulCreate count=1 msg=Created pod: eval-sanitize-5-r3-020-m7rv7
20.0427,TaskRequest,MODIFIED,eval-sanitize-5-r3-020,phase=Scheduled job=None
20.0512,Job,MODIFIED,eval-sanitize-5-r3-019,
20.0574,Pod,MODIFIED,eval-sanitize-5-r3-020-m7rv7,phase=Pending node=kind-worker
20.0613,Event,ADDED,eval-sanitize-5-r3-020-m7rv7.18d3d468581c9acd,reason=Scheduled count=None msg=Successfully assigned compute/eval-sanitize-5-r3-020-m7rv7 to kind-worker
20.0676,Pod,MODIFIED,eval-sanitize-5-r3-020-m7rv7,phase=Pending node=kind-worker
20.0698,Job,MODIFIED,eval-sanitize-5-r3-018,
20.0793,Job,MODIFIED,eval-sanitize-5-r3-018,
20.4953,Event,ADDED,eval-sanitize-5-r3-020-m7rv7.18d3d46871d4970c,"reason=Pulled count=1 msg=Container image ""busybox:musl"" already present on machine"
20.5125,Event,ADDED,eval-sanitize-5-r3-020-m7rv7.18d3d46872fdb5ae,reason=Created count=1 msg=Created container: task
20.5851,Event,ADDED,eval-sanitize-5-r3-020-m7rv7.18d3d468775639ea,reason=Started count=1 msg=Started container task
20.7058,Node,MODIFIED,kind-worker4,taints=1
20.7199,Node,MODIFIED,kind-worker4,taints=1
20.761,Node,MODIFIED,kind-worker4,taints=0
20.7748,Node,MODIFIED,kind-worker4,taints=0
20.7785,Node,MODIFIED,kind-worker5,taints=1
20.962,Node,MODIFIED,kind-worker5,taints=1
20.9755,Node,MODIFIED,kind-worker2,taints=1
20.9882,Node,MODIFIED,kind-worker2,taints=1
21.0135,TaskRequest,ADDED,eval-sanitize-5-r3-021,phase=None job=None
21.0172,TaskRequest,MODIFIED,eval-sanitize-5-r3-021,phase=Pending job=None
21.0327,Job,ADDED,eval-sanitize-5-r3-021,
21.0374,TaskRequest,MODIFIED,eval-sanitize-5-r3-021,phase=Scheduled job=None
21.0411,Pod,ADDED,eval-sanitize-5-r3-021-gbb9r,phase=Pending node=None
21.0432,Job,MODIFIED,eval-sanitize-5-r3-020,
21.0441,Job,MODIFIED,eval-sanitize-5-r3-021,
21.0477,Event,ADDED,eval-sanitize-5-r3-021.18d3d46892bb78bd,reason=SuccessfulCreate count=1 msg=Created pod: eval-sanitize-5-r3-021-gbb9r
21.0478,TaskRequest,MODIFIED,eval-sanitize-5-r3-021,phase=Scheduled job=None
21.0527,Pod,MODIFIED,eval-sanitize-5-r3-021-gbb9r,phase=Pending node=kind-worker4
21.0549,Job,MODIFIED,eval-sanitize-5-r3-020,
21.0566,Event,ADDED,eval-sanitize-5-r3-021-gbb9r.18d3d46893728254,reason=Scheduled count=None msg=Successfully assigned compute/eval-sanitize-5-r3-021-gbb9r to kind-worker4
21.0632,Node,MODIFIED,kind-worker4,taints=0
21.0652,Pod,MODIFIED,eval-sanitize-5-r3-021-gbb9r,phase=Pending node=kind-worker4
21.1641,Node,MODIFIED,kind-worker4,taints=0
21.4436,Pod,MODIFIED,eval-sanitize-5-r3-020-m7rv7,phase=Running node=kind-worker
21.4821,Event,ADDED,eval-sanitize-5-r3-021-gbb9r.18d3d468acc2e01f,"reason=Pulled count=1 msg=Container image ""busybox:musl"" already present on machine"
21.5018,Event,ADDED,eval-sanitize-5-r3-021-gbb9r.18d3d468adf725ea,reason=Created count=1 msg=Created container: task
21.5333,Event,ADDED,eval-sanitize-5-r3-021-gbb9r.18d3d468afe017b2,reason=Started count=1 msg=Started container task
21.7961,Pod,MODIFIED,eval-sanitize-5-r3-021-gbb9r,phase=Running node=kind-worker4
22.0184,TaskRequest,ADDED,eval-sanitize-5-r3-022,phase=None job=None
22.0225,TaskRequest,MODIFIED,eval-sanitize-5-r3-022,phase=Pending job=None
22.0387,Job,ADDED,eval-sanitize-5-r3-022,
22.0424,TaskRequest,MODIFIED,eval-sanitize-5-r3-022,phase=Scheduled job=None
22.0471,Pod,ADDED,eval-sanitize-5-r3-022-62z7n,phase=Pending node=None
22.0502,Job,MODIFIED,eval-sanitize-5-r3-021,
22.0512,Job,MODIFIED,eval-sanitize-5-r3-022,
22.0513,TaskRequest,MODIFIED,eval-sanitize-5-r3-022,phase=Scheduled job=None
22.0526,Job,MODIFIED,eval-sanitize-5-r3-020,
22.0531,Event,ADDED,eval-sanitize-5-r3-022.18d3d468ceb3597e,reason=SuccessfulCreate count=1 msg=Created pod: eval-sanitize-5-r3-022-62z7n
22.0602,Pod,MODIFIED,eval-sanitize-5-r3-022-62z7n,phase=Pending node=kind-worker3
22.0626,Job,MODIFIED,eval-sanitize-5-r3-021,
22.0675,Job,MODIFIED,eval-sanitize-5-r3-020,
22.0678,Event,ADDED,eval-sanitize-5-r3-022-62z7n.18d3d468cf7d26d7,reason=Scheduled count=None msg=Successfully assigned compute/eval-sanitize-5-r3-022-62z7n to kind-worker3
22.0717,Node,MODIFIED,kind-worker3,taints=0
22.0738,Pod,MODIFIED,eval-sanitize-5-r3-022-62z7n,phase=Pending node=kind-worker3
22.0819,Node,MODIFIED,kind-worker3,taints=0
22.0866,Node,MODIFIED,kind-worker,taints=1
22.0992,Node,MODIFIED,kind-worker,taints=1
22.4918,Event,ADDED,eval-sanitize-5-r3-022-62z7n.18d3d468e8f5bfa1,"reason=Pulled count=1 msg=Container image ""busybox:musl"" already present on machine"
22.5108,Event,ADDED,eval-sanitize-5-r3-022-62z7n.18d3d468ea1d3046,reason=Created count=1 msg=Created container: task
22.5878,Event,ADDED,eval-sanitize-5-r3-022-62z7n.18d3d468eeaf4ce4,reason=Started count=1 msg=Started container task
22.7992,Pod,MODIFIED,eval-sanitize-5-r3-022-62z7n,phase=Running node=kind-worker3
23.0085,TaskRequest,ADDED,eval-sanitize-5-r3-023,phase=None job=None
23.012,TaskRequest,MODIFIED,eval-sanitize-5-r3-023,phase=Pending job=None
23.0295,Job,ADDED,eval-sanitize-5-r3-023,
23.034,TaskRequest,MODIFIED,eval-sanitize-5-r3-023,phase=Scheduled job=None
23.039,Pod,ADDED,eval-sanitize-5-r3-023-rzr46,phase=Pending node=None
23.0423,Job,MODIFIED,eval-sanitize-5-r3-023,
23.044,Event,ADDED,eval-sanitize-5-r3-023.18d3d46909d8064e,reason=SuccessfulCreate count=1 msg=Created pod: eval-sanitize-5-r3-023-rzr46
23.0442,TaskRequest,MODIFIED,eval-sanitize-5-r3-023,phase=Scheduled job=None
23.0514,Pod,MODIFIED,eval-sanitize-5-r3-023-rzr46,phase=Pending node=None
23.0537,Event,ADDED,eval-sanitize-5-r3-023-rzr46.18d3d4690a4451c9,"reason=FailedScheduling count=None msg=0/6 nodes are available: 2 c_wall violated: 1 conflicting context pair(s) with node memory, 4 node(s) had untolerated taint(s). no new claims to deallocate, preemption: 0/6 nodes are available: 2 No preemption victims found for incoming pod, 4 Preemption is not helpful for scheduling."
23.0546,Job,MODIFIED,eval-sanitize-5-r3-022,
23.0612,Event,ADDED,eval-sanitize-5-r3-023-rzr46.18d3d4690af3f3ab,"reason=FailedScheduling count=None msg=0/6 nodes are available: 2 c_wall violated: 1 conflicting context pair(s) with node memory, 4 node(s) had untolerated taint(s). no new claims to deallocate, preemption: 0/6 nodes are available: 2 No preemption victims found for incoming pod, 4 Preemption is not helpful for scheduling."
23.0641,Job,MODIFIED,eval-sanitize-5-r3-022,
24.0123,TaskRequest,ADDED,eval-sanitize-5-r3-024,phase=None job=None
24.0176,TaskRequest,MODIFIED,eval-sanitize-5-r3-024,phase=Pending job=None
24.0321,Job,ADDED,eval-sanitize-5-r3-024,
24.0367,TaskRequest,MODIFIED,eval-sanitize-5-r3-024,phase=Scheduled job=None
24.0406,Pod,ADDED,eval-sanitize-5-r3-024-c56sv,phase=Pending node=None
24.042,Job,MODIFIED,eval-sanitize-5-r3-024,
24.0442,Job,MODIFIED,eval-sanitize-5-r3-023,
24.0461,Event,ADDED,eval-sanitize-5-r3-024.18d3d46945860da4,reason=SuccessfulCreate count=1 msg=Created pod: eval-sanitize-5-r3-024-c56sv
24.0463,TaskRequest,MODIFIED,eval-sanitize-5-r3-024,phase=Scheduled job=None
24.0513,Pod,MODIFIED,eval-sanitize-5-r3-024-c56sv,phase=Pending node=kind-worker3
24.055,Job,MODIFIED,eval-sanitize-5-r3-023,
24.0553,Event,ADDED,eval-sanitize-5-r3-024-c56sv.18d3d4694630c8e5,reason=Scheduled count=None msg=Successfully assigned compute/eval-sanitize-5-r3-024-c56sv to kind-worker3
24.0656,Node,MODIFIED,kind-worker3,taints=0
24.067,Pod,MODIFIED,eval-sanitize-5-r3-024-c56sv,phase=Pending node=kind-worker3
24.0675,Event,MODIFIED,eval-sanitize-5-r3-023-rzr46.18d3d4690af3f3ab,"reason=FailedScheduling count=None msg=0/6 nodes are available: 2 c_wall violated: 1 conflicting context pair(s) with node memory, 4 node(s) had untolerated taint(s). no new claims to deallocate, preemption: 0/6 nodes are available: 2 No preemption victims found for incoming pod, 4 Preemption is not helpful for scheduling."
24.0767,Node,MODIFIED,kind-worker3,taints=0
24.2962,Node,MODIFIED,kind-worker3,taints=1
24.3157,Pod,MODIFIED,eval-sanitize-5-r3-023-rzr46,phase=Pending node=None
24.3197,Node,MODIFIED,kind-worker3,taints=1
24.3239,Event,ADDED,eval-sanitize-5-r3-023-rzr46.18d3d4695630c0ab,"reason=FailedScheduling count=None msg=0/6 nodes are available: 1 c_wall violated: 1 conflicting context pair(s) with node memory, 5 node(s) had untolerated taint(s). no new claims to deallocate, preemption: 0/6 nodes are available: 1 No preemption victims found for incoming pod, 5 Preemption is not helpful for scheduling."
24.3273,Event,MODIFIED,eval-sanitize-5-r3-023-rzr46.18d3d4695630c0ab,"reason=FailedScheduling count=None msg=0/6 nodes are available: 1 c_wall violated: 1 conflicting context pair(s) with node memory, 5 node(s) had untolerated taint(s). no new claims to deallocate, preemption: 0/6 nodes are available: 1 No preemption victims found for incoming pod, 5 Preemption is not helpful for scheduling."
24.4923,Event,ADDED,eval-sanitize-5-r3-024-c56sv.18d3d46960351154,"reason=Pulled count=1 msg=Container image ""busybox:musl"" already present on machine"
24.5129,Event,ADDED,eval-sanitize-5-r3-024-c56sv.18d3d469615f88b6,reason=Created count=1 msg=Created container: task
24.5469,Event,ADDED,eval-sanitize-5-r3-024-c56sv.18d3d469637e7423,reason=Started count=1 msg=Started container task
24.8058,Pod,MODIFIED,eval-sanitize-5-r3-024-c56sv,phase=Running node=kind-worker3
25.0105,TaskRequest,ADDED,eval-sanitize-5-r3-025,phase=None job=None
25.0142,TaskRequest,MODIFIED,eval-sanitize-5-r3-025,phase=Pending job=None
25.031,Job,ADDED,eval-sanitize-5-r3-025,
25.0348,TaskRequest,MODIFIED,eval-sanitize-5-r3-025,phase=Scheduled job=None
25.0384,Pod,ADDED,eval-sanitize-5-r3-025-v6v64,phase=Pending node=None
25.0403,Job,MODIFIED,eval-sanitize-5-r3-025,
25.0429,Event,ADDED,eval-sanitize-5-r3-025.18d3d4698107243f,reason=SuccessfulCreate count=1 msg=Created pod: eval-sanitize-5-r3-025-v6v64
25.0432,TaskRequest,MODIFIED,eval-sanitize-5-r3-025,phase=Scheduled job=None
25.0467,Job,MODIFIED,eval-sanitize-5-r3-024,
25.0488,Event,ADDED,eval-sanitize-5-r3-025-v6v64.18d3d4698144a988,"reason=FailedScheduling count=None msg=0/6 nodes are available: 1 c_wall violated: 1 conflicting context pair(s) with node memory, 5 node(s) had untolerated taint(s). no new claims to deallocate, preemption: 0/6 nodes are available: 1 No preemption victims found for incoming pod, 5 Preemption is not helpful for scheduling."
25.0504,Pod,MODIFIED,eval-sanitize-5-r3-025-v6v64,phase=Pending node=None
25.0564,Job,MODIFIED,eval-sanitize-5-r3-024,
25.0594,Event,ADDED,eval-sanitize-5-r3-025-v6v64.18d3d46981fa2aa5,"reason=FailedScheduling count=None msg=0/6 nodes are available: 1 c_wall violated: 1 conflicting context pair(s) with node memory, 5 node(s) had untolerated taint(s). no new claims to deallocate, preemption: 0/6 nodes are available: 1 No preemption victims found for incoming pod, 5 Preemption is not helpful for scheduling."
25.7842,Node,MODIFIED,kind-worker4,taints=1
25.7893,Pod,MODIFIED,eval-sanitize-5-r3-023-rzr46,phase=Pending node=None
25.7943,Pod,MODIFIED,eval-sanitize-5-r3-025-v6v64,phase=Pending node=None
25.7948,Event,MODIFIED,eval-sanitize-5-r3-025-v6v64.18d3d46981fa2aa5,"reason=FailedScheduling count=None msg=0/6 nodes are available: 1 c_wall violated: 1 conflicting context pair(s) with node memory, 5 node(s) had untolerated taint(s). no new claims to deallocate, preemption: 0/6 nodes are available: 1 No preemption victims found for incoming pod, 5 Preemption is not helpful for scheduling."
25.798,Node,MODIFIED,kind-worker4,taints=1
26.0082,TaskRequest,ADDED,eval-sanitize-5-r3-026,phase=None job=None
26.0115,TaskRequest,MODIFIED,eval-sanitize-5-r3-026,phase=Pending job=None
26.0265,Job,ADDED,eval-sanitize-5-r3-026,
26.0333,Pod,ADDED,eval-sanitize-5-r3-026-hghxc,phase=Pending node=None
26.0335,TaskRequest,MODIFIED,eval-sanitize-5-r3-026,phase=Scheduled job=None
26.0363,Job,MODIFIED,eval-sanitize-5-r3-026,
26.0392,Pod,MODIFIED,eval-sanitize-5-r3-026-hghxc,phase=Pending node=None
26.0403,Event,ADDED,eval-sanitize-5-r3-026.18d3d469bc4f7de8,reason=SuccessfulCreate count=1 msg=Created pod: eval-sanitize-5-r3-026-hghxc
26.0405,Event,ADDED,eval-sanitize-5-r3-026-hghxc.18d3d469bc5d3bde,"reason=FailedScheduling count=None msg=0/6 nodes are available: 6 node(s) had untolerated taint(s). no new claims to deallocate, preemption: 0/6 nodes are available: 6 Preemption is not helpful for scheduling."
26.0421,TaskRequest,MODIFIED,eval-sanitize-5-r3-026,phase=Scheduled job=None
26.0429,Job,MODIFIED,eval-sanitize-5-r3-025,
26.0526,Job,MODIFIED,eval-sanitize-5-r3-025,
26.8298,Pod,MODIFIED,eval-sanitize-5-r3-011-kmvsv,phase=Running node=kind-worker5
26.8366,Pod,MODIFIED,eval-sanitize-5-r3-007-4m9hq,phase=Running node=kind-worker5
26.8428,Pod,MODIFIED,eval-sanitize-5-r3-013-lk4lx,phase=Running node=kind-worker5
26.8486,Pod,MODIFIED,eval-sanitize-5-r3-015-x7rh2,phase=Running node=kind-worker5
26.8548,Pod,MODIFIED,eval-sanitize-5-r3-008-l6qpn,phase=Running node=kind-worker5
26.861,Pod,MODIFIED,eval-sanitize-5-r3-009-m59w9,phase=Running node=kind-worker5
26.8676,Pod,MODIFIED,eval-sanitize-5-r3-010-bppgt,phase=Running node=kind-worker5
26.8762,Pod,MODIFIED,eval-sanitize-5-r3-014-blrpd,phase=Running node=kind-worker2
26.8818,Pod,MODIFIED,eval-sanitize-5-r3-016-5jw6h,phase=Running node=kind-worker2
26.888,Pod,MODIFIED,eval-sanitize-5-r3-012-64j5t,phase=Running node=kind-worker2
27.0082,TaskRequest,ADDED,eval-sanitize-5-r3-027,phase=None job=None
27.0119,TaskRequest,MODIFIED,eval-sanitize-5-r3-027,phase=Pending job=None
27.028,Job,ADDED,eval-sanitize-5-r3-027,
27.0358,Pod,ADDED,eval-sanitize-5-r3-027-9ft5d,phase=Pending node=None
27.0391,Job,MODIFIED,eval-sanitize-5-r3-027,
27.0392,TaskRequest,MODIFIED,eval-sanitize-5-r3-027,phase=Scheduled job=None
27.0403,Job,MODIFIED,eval-sanitize-5-r3-026,
27.0406,Event,ADDED,eval-sanitize-5-r3-027.18d3d469f81682db,reason=SuccessfulCreate count=1 msg=Created pod: eval-sanitize-5-r3-027-9ft5d
27.0423,Event,ADDED,eval-sanitize-5-r3-027-9ft5d.18d3d469f824991d,"reason=FailedScheduling count=None msg=0/6 nodes are available: 6 node(s) had untolerated taint(s). no new claims to deallocate, preemption: 0/6 nodes are available: 6 Preemption is not helpful for scheduling."
27.0434,Pod,MODIFIED,eval-sanitize-5-r3-027-9ft5d,phase=Pending node=None
27.0454,TaskRequest,MODIFIED,eval-sanitize-5-r3-027,phase=Scheduled job=None
27.0515,Job,MODIFIED,eval-sanitize-5-r3-026,
27.8383,Job,MODIFIED,eval-sanitize-5-r3-011,
27.842,Pod,MODIFIED,eval-sanitize-5-r3-017-hs5c9,phase=Running node=kind-worker5
27.844,Job,MODIFIED,eval-sanitize-5-r3-007,
27.8483,Job,MODIFIED,eval-sanitize-5-r3-013,
27.8528,Job,MODIFIED,eval-sanitize-5-r3-011,
27.8536,Job,MODIFIED,eval-sanitize-5-r3-015,
27.8561,Job,MODIFIED,eval-sanitize-5-r3-007,
27.858,Job,MODIFIED,eval-sanitize-5-r3-013,
27.861,Job,MODIFIED,eval-sanitize-5-r3-008,
27.8641,Job,MODIFIED,eval-sanitize-5-r3-015,
27.8659,Job,MODIFIED,eval-sanitize-5-r3-009,
27.8703,Job,MODIFIED,eval-sanitize-5-r3-008,
27.8746,Job,MODIFIED,eval-sanitize-5-r3-010,
27.8786,Job,MODIFIED,eval-sanitize-5-r3-009,
27.8825,Job,MODIFIED,eval-sanitize-5-r3-014,
27.8865,Job,MODIFIED,eval-sanitize-5-r3-016,
27.8919,Job,MODIFIED,eval-sanitize-5-r3-012,
27.9271,Job,MODIFIED,eval-sanitize-5-r3-010,
27.9293,Job,MODIFIED,eval-sanitize-5-r3-014,
27.9317,Job,MODIFIED,eval-sanitize-5-r3-016,
27.9327,Job,MODIFIED,eval-sanitize-5-r3-012,
27.9914,Pod,MODIFIED,eval-sanitize-5-r3-009-m59w9,phase=Succeeded node=kind-worker5
28.0065,TaskRequest,ADDED,eval-sanitize-5-r3-028,phase=None job=None
28.0101,TaskRequest,MODIFIED,eval-sanitize-5-r3-028,phase=Pending job=None
28.0254,Job,ADDED,eval-sanitize-5-r3-028,
28.0347,Pod,ADDED,eval-sanitize-5-r3-028-6xmxg,phase=Pending node=None
28.0349,TaskRequest,MODIFIED,eval-sanitize-5-r3-028,phase=Scheduled job=None
28.0419,Job,MODIFIED,eval-sanitize-5-r3-028,
28.0454,Event,ADDED,eval-sanitize-5-r3-028-6xmxg.18d3d46a33aee3d5,"reason=FailedScheduling count=None msg=0/6 nodes are available: 6 node(s) had untolerated taint(s). no new claims to deallocate, preemption: 0/6 nodes are available: 6 Preemption is not helpful for scheduling."
28.0463,Job,MODIFIED,eval-sanitize-5-r3-027,
28.0474,Pod,MODIFIED,eval-sanitize-5-r3-028-6xmxg,phase=Pending node=None
28.0477,Event,ADDED,eval-sanitize-5-r3-028.18d3d46a33a69a9b,reason=SuccessfulCreate count=1 msg=Created pod: eval-sanitize-5-r3-028-6xmxg
28.0478,TaskRequest,MODIFIED,eval-sanitize-5-r3-028,phase=Scheduled job=None
28.0602,Job,MODIFIED,eval-sanitize-5-r3-027,
28.0616,Pod,MODIFIED,eval-sanitize-5-r3-010-bppgt,phase=Succeeded node=kind-worker5
28.0687,Pod,MODIFIED,eval-sanitize-5-r3-007-4m9hq,phase=Succeeded node=kind-worker5
28.0749,Pod,MODIFIED,eval-sanitize-5-r3-013-lk4lx,phase=Succeeded node=kind-worker5
28.0809,Pod,MODIFIED,eval-sanitize-5-r3-011-kmvsv,phase=Succeeded node=kind-worker5
28.0869,Pod,MODIFIED,eval-sanitize-5-r3-015-x7rh2,phase=Succeeded node=kind-worker5
28.0924,Pod,MODIFIED,eval-sanitize-5-r3-008-l6qpn,phase=Succeeded node=kind-worker5
28.1318,Pod,MODIFIED,eval-sanitize-5-r3-014-blrpd,phase=Succeeded node=kind-worker2
28.1376,Pod,MODIFIED,eval-sanitize-5-r3-016-5jw6h,phase=Succeeded node=kind-worker2
28.1646,Pod,MODIFIED,eval-sanitize-5-r3-012-64j5t,phase=Succeeded node=kind-worker2
28.8463,Job,MODIFIED,eval-sanitize-5-r3-011,
28.8483,Job,MODIFIED,eval-sanitize-5-r3-017,
28.8506,Job,MODIFIED,eval-sanitize-5-r3-007,
28.8539,Job,MODIFIED,eval-sanitize-5-r3-013,
28.8572,Job,MODIFIED,eval-sanitize-5-r3-011,
28.8589,Pod,MODIFIED,eval-sanitize-5-r3-011-kmvsv,phase=Succeeded node=kind-worker5
28.8602,Job,MODIFIED,eval-sanitize-5-r3-017,
28.8611,Job,MODIFIED,eval-sanitize-5-r3-015,
28.8648,Pod,MODIFIED,eval-sanitize-5-r3-007-4m9hq,phase=Succeeded node=kind-worker5
28.8658,Job,MODIFIED,eval-sanitize-5-r3-007,
28.8675,Pod,MODIFIED,eval-sanitize-5-r3-013-lk4lx,phase=Succeeded node=kind-worker5
28.8684,Job,MODIFIED,eval-sanitize-5-r3-013,
28.8753,Job,MODIFIED,eval-sanitize-5-r3-008,
28.8767,Job,MODIFIED,eval-sanitize-5-r3-015,
28.8791,Pod,MODIFIED,eval-sanitize-5-r3-015-x7rh2,phase=Succeeded node=kind-worker5
28.8804,Job,MODIFIED,eval-sanitize-5-r3-009,
28.8815,Job,MODIFIED,eval-sanitize-5-r3-010,
28.8868,Pod,MODIFIED,eval-sanitize-5-r3-008-l6qpn,phase=Succeeded node=kind-worker5
28.889,Job,MODIFIED,eval-sanitize-5-r3-014,
28.8909,Pod,MODIFIED,eval-sanitize-5-r3-009-m59w9,phase=Succeeded node=kind-worker5
28.8919,Job,MODIFIED,eval-sanitize-5-r3-008,
28.8936,Pod,MODIFIED,eval-sanitize-5-r3-010-bppgt,phase=Succeeded node=kind-worker5
28.8944,Job,MODIFIED,eval-sanitize-5-r3-009,
28.8952,Job,MODIFIED,eval-sanitize-5-r3-016,
28.8966,Job,MODIFIED,eval-sanitize-5-r3-010,
28.898,Pod,MODIFIED,eval-sanitize-5-r3-014-blrpd,phase=Succeeded node=kind-worker2
28.8984,Event,ADDED,eval-sanitize-5-r3-010.18d3d46a66d6b368,reason=Completed count=1 msg=Job completed
28.8992,Job,MODIFIED,eval-sanitize-5-r3-012,
28.9012,Job,MODIFIED,eval-sanitize-5-r3-014,
28.9026,Pod,MODIFIED,eval-sanitize-5-r3-016-5jw6h,phase=Succeeded node=kind-worker2
28.9055,Job,MODIFIED,eval-sanitize-5-r3-016,
28.9082,Pod,MODIFIED,eval-sanitize-5-r3-012-64j5t,phase=Succeeded node=kind-worker2
28.9248,Job,MODIFIED,eval-sanitize-5-r3-010,
28.9429,Event,ADDED,eval-sanitize-5-r3-014.18d3d46a675236ca,reason=Completed count=1 msg=Job completed
28.9617,TaskRequest,MODIFIED,eval-sanitize-5-r3-010,phase=Complete job=None
28.9675,Job,MODIFIED,eval-sanitize-5-r3-014,
28.97,Job,MODIFIED,eval-sanitize-5-r3-016,
28.9711,Job,MODIFIED,eval-sanitize-5-r3-012,
28.972,Job,MODIFIED,eval-sanitize-5-r3-010,
28.9726,TaskRequest,MODIFIED,eval-sanitize-5-r3-014,phase=Complete job=None
29.0124,TaskRequest,ADDED,eval-sanitize-5-r3-029,phase=None job=None
29.019,TaskRequest,MODIFIED,eval-sanitize-5-r3-016,phase=Complete job=None
29.0253,Job,MODIFIED,eval-sanitize-5-r3-014,
29.0254,TaskRequest,MODIFIED,eval-sanitize-5-r3-029,phase=Pending job=None
29.028,Job,MODIFIED,eval-sanitize-5-r3-016,
29.0427,Event,ADDED,eval-sanitize-5-r3-016.18d3d46a67916cc5,reason=Completed count=1 msg=Job completed
29.0467,Pod,MODIFIED,eval-sanitize-5-r3-017-hs5c9,phase=Succeeded node=kind-worker5
29.0732,Job,ADDED,eval-sanitize-5-r3-029,
29.0796,TaskRequest,MODIFIED,eval-sanitize-5-r3-029,phase=Scheduled job=None
29.082,Job,MODIFIED,eval-sanitize-5-r3-029,
29.0874,TaskRequest,MODIFIED,eval-sanitize-5-r3-029,phase=Scheduled job=None
29.0932,Job,MODIFIED,eval-sanitize-5-r3-028,
29.1019,Job,MODIFIED,eval-sanitize-5-r3-028,
29.1448,Pod,ADDED,eval-sanitize-5-r3-029-j9fgd,phase=Pending node=None
29.1505,Pod,MODIFIED,eval-sanitize-5-r3-029-j9fgd,phase=Pending node=None
29.1509,Event,ADDED,eval-sanitize-5-r3-029-j9fgd.18d3d46a75db2b54,"reason=FailedScheduling count=None msg=0/6 nodes are available: 6 node(s) had untolerated taint(s). no new claims to deallocate, preemption: 0/6 nodes are available: 6 Preemption is not helpful for scheduling."
29.2463,Event,ADDED,eval-sanitize-5-r3-029.18d3d46a75d10da2,reason=SuccessfulCreate count=1 msg=Created pod: eval-sanitize-5-r3-029-j9fgd
29.457,Pod,MODIFIED,eval-sanitize-5-r3-018-pndjq,phase=Running node=kind-worker
29.8541,Job,MODIFIED,eval-sanitize-5-r3-011,
29.856,Job,MODIFIED,eval-sanitize-5-r3-017,
29.8574,Job,MODIFIED,eval-sanitize-5-r3-007,
29.8586,Job,MODIFIED,eval-sanitize-5-r3-011,
29.8604,Job,MODIFIED,eval-sanitize-5-r3-013,
29.8637,Job,MODIFIED,eval-sanitize-5-r3-007,
29.8657,Event,ADDED,eval-sanitize-5-r3-011.18d3d46aa0596d79,reason=Completed count=1 msg=Job completed
29.8667,Job,MODIFIED,eval-sanitize-5-r3-013,
29.8682,Pod,MODIFIED,eval-sanitize-5-r3-017-hs5c9,phase=Succeeded node=kind-worker5
29.8691,Job,MODIFIED,eval-sanitize-5-r3-015,
29.8702,Job,MODIFIED,eval-sanitize-5-r3-017,
29.8715,Job,MODIFIED,eval-sanitize-5-r3-015,
29.874,Job,MODIFIED,eval-sanitize-5-r3-011,
29.879,Job,MODIFIED,eval-sanitize-5-r3-007,
29.8811,Job,MODIFIED,eval-sanitize-5-r3-013,
29.8813,TaskRequest,MODIFIED,eval-sanitize-5-r3-011,phase=Complete job=None
29.8834,Job,MODIFIED,eval-sanitize-5-r3-015,
29.8919,Pod,MODIFIED,eval-sanitize-5-r3-019-dq89j,phase=Running node=kind-worker2
29.8925,Event,ADDED,eval-sanitize-5-r3-007.18d3d46aa0aa91ab,reason=Completed count=1 msg=Job completed
29.9478,Job,MODIFIED,eval-sanitize-5-r3-008,
29.9591,TaskRequest,MODIFIED,eval-sanitize-5-r3-007,phase=Complete job=None
29.9651,TaskRequest,MODIFIED,eval-sanitize-5-r3-013,phase=Complete job=None
29.9717,Job,MODIFIED,eval-sanitize-5-r3-011,
29.973,TaskRequest,MODIFIED,eval-sanitize-5-r3-015,phase=Complete job=None
29.974,Job,MODIFIED,eval-sanitize-5-r3-007,
29.9757,Job,MODIFIED,eval-sanitize-5-r3-013,
29.9846,Job,MODIFIED,eval-sanitize-5-r3-015,
29.9865,Job,MODIFIED,eval-sanitize-5-r3-008,
29.993,Job,MODIFIED,eval-sanitize-5-r3-009,
30.0073,TaskRequest,ADDED,eval-sanitize-5-r3-030,phase=None job=None
30.0215,TaskRequest,MODIFIED,eval-sanitize-5-r3-030,phase=Pending job=None
30.0428,Event,ADDED,eval-sanitize-5-r3-013.18d3d46aa0d436f1,reason=Completed count=1 msg=Job completed
30.072,Job,MODIFIED,eval-sanitize-5-r3-009,
30.0732,Job,ADDED,eval-sanitize-5-r3-030,
30.0777,TaskRequest,MODIFIED,eval-sanitize-5-r3-030,phase=Scheduled job=None
30.0824,Job,MODIFIED,eval-sanitize-5-r3-030,
30.0838,TaskRequest,MODIFIED,eval-sanitize-5-r3-030,phase=Scheduled job=None
30.0931,Job,MODIFIED,eval-sanitize-5-r3-012,
30.1012,Job,MODIFIED,eval-sanitize-5-r3-012,
30.2446,Event,ADDED,eval-sanitize-5-r3-015.18d3d46aa124dfd0,reason=Completed count=1 msg=Job completed
30.2994,Pod,ADDED,eval-sanitize-5-r3-030-9m4cf,phase=Pending node=None
30.3047,Pod,MODIFIED,eval-sanitize-5-r3-030-9m4cf,phase=Pending node=None
30.305,Event,ADDED,eval-sanitize-5-r3-030-9m4cf.18d3d46abaad74b1,"reason=FailedScheduling count=None msg=0/6 nodes are available: 6 node(s) had untolerated taint(s). no new claims to deallocate, preemption: 0/6 nodes are available: 6 Preemption is not helpful for scheduling."
30.3454,Job,MODIFIED,eval-sanitize-5-r3-029,
30.3548,Job,MODIFIED,eval-sanitize-5-r3-029,
30.4939,Event,ADDED,eval-sanitize-5-r3-030.18d3d46abaa304f7,reason=SuccessfulCreate count=1 msg=Created pod: eval-sanitize-5-r3-030-9m4cf
30.5449,Job,MODIFIED,eval-sanitize-5-r3-018,
30.5559,Job,MODIFIED,eval-sanitize-5-r3-018,
30.6364,Pod,MODIFIED,eval-sanitize-5-r3-018-pndjq,phase=Succeeded node=kind-worker
30.8681,Job,MODIFIED,eval-sanitize-5-r3-017,
30.8729,Job,MODIFIED,eval-sanitize-5-r3-017,
30.8789,Event,ADDED,eval-sanitize-5-r3-017.18d3d46adcd3135d,reason=Completed count=1 msg=Job completed
30.8841,Job,MODIFIED,eval-sanitize-5-r3-017,
30.8898,TaskRequest,MODIFIED,eval-sanitize-5-r3-017,phase=Complete job=None
30.898,Job,MODIFIED,eval-sanitize-5-r3-019,
30.8998,Job,MODIFIED,eval-sanitize-5-r3-017,
30.907,Job,MODIFIED,eval-sanitize-5-r3-019,
30.9535,Job,MODIFIED,eval-sanitize-5-r3-008,
30.9567,Event,ADDED,eval-sanitize-5-r3-008.18d3d46ae19ec322,reason=Completed count=1 msg=Job completed
30.9585,TaskRequest,MODIFIED,eval-sanitize-5-r3-008,phase=Complete job=None
30.9682,Job,MODIFIED,eval-sanitize-5-r3-008,
30.9917,Pod,MODIFIED,eval-sanitize-5-r3-019-dq89j,phase=Succeeded node=kind-worker2
30.9983,Job,MODIFIED,eval-sanitize-5-r3-009,
31.0029,Event,ADDED,eval-sanitize-5-r3-009.18d3d46ae44b5695,reason=Completed count=1 msg=Job completed
31.0031,TaskRequest,MODIFIED,eval-sanitize-5-r3-009,phase=Complete job=None
31.0063,TaskRequest,ADDED,eval-sanitize-5-r3-031,phase=None job=None
31.0095,TaskRequest,MODIFIED,eval-sanitize-5-r3-031,phase=Pending job=None
31.0126,Job,MODIFIED,eval-sanitize-5-r3-009,
31.0249,Job,ADDED,eval-sanitize-5-r3-031,
31.0289,TaskRequest,MODIFIED,eval-sanitize-5-r3-031,phase=Scheduled job=None
31.0316,Pod,ADDED,eval-sanitize-5-r3-031-brmm4,phase=Pending node=None
31.0341,Job,MODIFIED,eval-sanitize-5-r3-031,
31.0365,Pod,MODIFIED,eval-sanitize-5-r3-031-brmm4,phase=Pending node=None
31.0377,Event,ADDED,eval-sanitize-5-r3-031-brmm4.18d3d46ae6560258,"reason=FailedScheduling count=None msg=0/6 nodes are available: 6 node(s) had untolerated taint(s). no new claims to deallocate, preemption: 0/6 nodes are available: 6 Preemption is not helpful for scheduling."
31.0378,TaskRequest,MODIFIED,eval-sanitize-5-r3-031,phase=Scheduled job=None
31.094,Event,ADDED,eval-sanitize-5-r3-031.18d3d46ae650bd5f,reason=SuccessfulCreate count=1 msg=Created pod: eval-sanitize-5-r3-031-brmm4
31.1462,Job,MODIFIED,eval-sanitize-5-r3-030,
31.1561,Job,MODIFIED,eval-sanitize-5-r3-030,
31.1656,Node,MODIFIED,kind-worker5,taints=1
31.1781,Node,MODIFIED,kind-worker5,taints=1
31.187,Node,MODIFIED,kind-worker5,taints=0
31.1937,Pod,MODIFIED,eval-sanitize-5-r3-023-rzr46,phase=Pending node=kind-worker5
31.1949,Job,MODIFIED,eval-sanitize-5-r3-012,
31.1972,Event,ADDED,eval-sanitize-5-r3-023-rzr46.18d3d46aefe6909a,reason=Scheduled count=None msg=Successfully assigned compute/eval-sanitize-5-r3-023-rzr46 to kind-worker5
31.2004,TaskRequest,MODIFIED,eval-sanitize-5-r3-012,phase=Complete job=None
31.2034,Event,ADDED,eval-sanitize-5-r3-025-v6v64.18d3d46af01e00fb,"reason=FailedScheduling count=None msg=0/6 nodes are available: 1 c_wall violated: 1 conflicting context pair(s) with node memory, 5 node(s) had untolerated taint(s). no new claims to deallocate, preemption: 0/6 nodes are available: 1 No preemption victims found for incoming pod, 5 Preemption is not helpful for scheduling."
31.2046,Pod,MODIFIED,eval-sanitize-5-r3-025-v6v64,phase=Pending node=None
31.206,Node,MODIFIED,kind-worker5,taints=0
31.2074,Pod,MODIFIED,eval-sanitize-5-r3-023-rzr46,phase=Pending node=kind-worker5
31.2118,Job,MODIFIED,eval-sanitize-5-r3-012,
31.2131,Event,ADDED,eval-sanitize-5-r3-026-hghxc.18d3d46af0c86bdc,"reason=FailedScheduling count=None msg=0/6 nodes are available: 1 c_wall violated: 1 conflicting context pair(s) with node memory, 5 node(s) had untolerated taint(s). no new claims to deallocate, preemption: 0/6 nodes are available: 1 No preemption victims found for incoming pod, 5 Preemption is not helpful for scheduling."
31.2141,Pod,MODIFIED,eval-sanitize-5-r3-026-hghxc,phase=Pending node=None
31.223,Pod,MODIFIED,eval-sanitize-5-r3-027-9ft5d,phase=Pending node=kind-worker5
31.2257,Pod,MODIFIED,eval-sanitize-5-r3-028-6xmxg,phase=Pending node=kind-worker5
31.2299,Pod,MODIFIED,eval-sanitize-5-r3-029-j9fgd,phase=Pending node=None
31.2325,Event,ADDED,eval-sanitize-5-r3-027-9ft5d.18d3d46af1aeac41,reason=Scheduled count=None msg=Successfully assigned compute/eval-sanitize-5-r3-027-9ft5d to kind-worker5
31.2326,Event,ADDED,eval-sanitize-5-r3-029-j9fgd.18d3d46af1bcea3e,"reason=FailedScheduling count=None msg=0/6 nodes are available: 1 c_wall violated: 1 conflicting context pair(s) with node memory, 5 node(s) had untolerated taint(s). no new claims to deallocate, preemption: 0/6 nodes are available: 1 No preemption victims found for incoming pod, 5 Preemption is not helpful for scheduling."
31.2328,Event,ADDED,eval-sanitize-5-r3-028-6xmxg.18d3d46af1da7c4a,reason=Scheduled count=None msg=Successfully assigned compute/eval-sanitize-5-r3-028-6xmxg to kind-worker5
31.2396,Pod,MODIFIED,eval-sanitize-5-r3-027-9ft5d,phase=Pending node=kind-worker5
31.242,Event,ADDED,eval-sanitize-5-r3-012.18d3d46af002eee0,reason=Completed count=1 msg=Job completed
31.2478,Event,ADDED,eval-sanitize-5-r3-030-9m4cf.18d3d46af2cc1295,"reason=FailedScheduling count=None msg=0/6 nodes are available: 1 c_wall violated: 2 conflicting context pair(s) with node memory, 5 node(s) had untolerated taint(s). no new claims to deallocate, preemption: 0/6 nodes are available: 1 No preemption victims found for incoming pod, 5 Preemption is not helpful for scheduling."
31.2493,Pod,MODIFIED,eval-sanitize-5-r3-028-6xmxg,phase=Pending node=kind-worker5
31.2506,Node,MODIFIED,kind-worker5,taints=0
31.2516,Pod,MODIFIED,eval-sanitize-5-r3-030-9m4cf,phase=Pending node=None
31.2615,Pod,MODIFIED,eval-sanitize-5-r3-031-brmm4,phase=Pending node=None
31.2619,Event,ADDED,eval-sanitize-5-r3-031-brmm4.18d3d46af39d049c,"reason=FailedScheduling count=None msg=0/6 nodes are available: 1 c_wall violated: 2 conflicting context pair(s) with node memory, 5 node(s) had untolerated taint(s). no new claims to deallocate, preemption: 0/6 nodes are available: 1 No preemption victims found for incoming pod, 5 Preemption is not helpful for scheduling."
31.2698,Event,ADDED,eval-sanitize-5-r3-025-v6v64.18d3d46af43277a0,"reason=FailedScheduling count=None msg=0/6 nodes are available: 1 c_wall violated: 1 conflicting context pair(s) with node memory, 5 node(s) had untolerated taint(s). no new claims to deallocate, preemption: 0/6 nodes are available: 1 No preemption victims found for incoming pod, 5 Preemption is not helpful for scheduling."
31.3044,Event,ADDED,eval-sanitize-5-r3-026-hghxc.18d3d46af462604a,"reason=FailedScheduling count=None msg=0/6 nodes are available: 1 c_wall violated: 1 conflicting context pair(s) with node memory, 5 node(s) had untolerated taint(s). no new claims to deallocate, preemption: 0/6 nodes are available: 1 No preemption victims found for incoming pod, 5 Preemption is not helpful for scheduling."
31.3064,Event,ADDED,eval-sanitize-5-r3-029-j9fgd.18d3d46af67d7eb9,"reason=FailedScheduling count=None msg=0/6 nodes are available: 1 c_wall violated: 1 conflicting context pair(s) with node memory, 5 node(s) had untolerated taint(s). no new claims to deallocate, preemption: 0/6 nodes are available: 1 No preemption victims found for incoming pod, 5 Preemption is not helpful for scheduling."
31.3256,Event,ADDED,eval-sanitize-5-r3-030-9m4cf.18d3d46af787c74c,"reason=FailedScheduling count=None msg=0/6 nodes are available: 1 c_wall violated: 2 conflicting context pair(s) with node memory, 5 node(s) had untolerated taint(s). no new claims to deallocate, preemption: 0/6 nodes are available: 1 No preemption victims found for incoming pod, 5 Preemption is not helpful for scheduling."
31.3262,Event,ADDED,eval-sanitize-5-r3-031-brmm4.18d3d46af7af55f0,"reason=FailedScheduling count=None msg=0/6 nodes are available: 1 c_wall violated: 2 conflicting context pair(s) with node memory, 5 node(s) had untolerated taint(s). no new claims to deallocate, preemption: 0/6 nodes are available: 1 No preemption victims found for incoming pod, 5 Preemption is not helpful for scheduling."
31.3724,Node,MODIFIED,kind-worker5,taints=0
31.3741,Node,MODIFIED,kind-worker2,taints=1
31.3819,Event,MODIFIED,eval-sanitize-5-r3-025-v6v64.18d3d46af43277a0,"reason=FailedScheduling count=None msg=0/6 nodes are available: 1 c_wall violated: 1 conflicting context pair(s) with node memory, 5 node(s) had untolerated taint(s). no new claims to deallocate, preemption: 0/6 nodes are available: 1 No preemption victims found for incoming pod, 5 Preemption is not helpful for scheduling."
31.3856,Event,MODIFIED,eval-sanitize-5-r3-026-hghxc.18d3d46af462604a,"reason=FailedScheduling count=None msg=0/6 nodes are available: 1 c_wall violated: 1 conflicting context pair(s) with node memory, 5 node(s) had untolerated taint(s). no new claims to deallocate, preemption: 0/6 nodes are available: 1 No preemption victims found for incoming pod, 5 Preemption is not helpful for scheduling."
31.39,Event,MODIFIED,eval-sanitize-5-r3-029-j9fgd.18d3d46af67d7eb9,"reason=FailedScheduling count=None msg=0/6 nodes are available: 1 c_wall violated: 1 conflicting context pair(s) with node memory, 5 node(s) had untolerated taint(s). no new claims to deallocate, preemption: 0/6 nodes are available: 1 No preemption victims found for incoming pod, 5 Preemption is not helpful for scheduling."
31.3933,Event,MODIFIED,eval-sanitize-5-r3-030-9m4cf.18d3d46af787c74c,"reason=FailedScheduling count=None msg=0/6 nodes are available: 1 c_wall violated: 2 conflicting context pair(s) with node memory, 5 node(s) had untolerated taint(s). no new claims to deallocate, preemption: 0/6 nodes are available: 1 No preemption victims found for incoming pod, 5 Preemption is not helpful for scheduling."
31.3939,Event,MODIFIED,eval-sanitize-5-r3-031-brmm4.18d3d46af7af55f0,"reason=FailedScheduling count=None msg=0/6 nodes are available: 1 c_wall violated: 2 conflicting context pair(s) with node memory, 5 node(s) had untolerated taint(s). no new claims to deallocate, preemption: 0/6 nodes are available: 1 No preemption victims found for incoming pod, 5 Preemption is not helpful for scheduling."
31.4631,Pod,MODIFIED,eval-sanitize-5-r3-020-m7rv7,phase=Running node=kind-worker
31.4644,Node,MODIFIED,kind-worker2,taints=0
31.4658,Node,MODIFIED,kind-worker5,taints=0
31.4723,Node,MODIFIED,kind-worker2,taints=0
31.4748,Pod,MODIFIED,eval-sanitize-5-r3-029-j9fgd,phase=Pending node=kind-worker2
31.4804,Event,ADDED,eval-sanitize-5-r3-029-j9fgd.18d3d46b00a785be,reason=Scheduled count=None msg=Successfully assigned compute/eval-sanitize-5-r3-029-j9fgd to kind-worker2
31.4836,Pod,MODIFIED,eval-sanitize-5-r3-030-9m4cf,phase=Pending node=kind-worker2
31.486,Node,MODIFIED,kind-worker2,taints=0
31.4912,Pod,MODIFIED,eval-sanitize-5-r3-029-j9fgd,phase=Pending node=kind-worker2
31.4916,Event,ADDED,eval-sanitize-5-r3-030-9m4cf.18d3d46b01418fb9,reason=Scheduled count=None msg=Successfully assigned compute/eval-sanitize-5-r3-030-9m4cf to kind-worker2
31.4943,Node,MODIFIED,kind-worker2,taints=0
31.4995,Pod,MODIFIED,eval-sanitize-5-r3-030-9m4cf,phase=Pending node=kind-worker2
31.5042,Node,MODIFIED,kind-worker2,taints=0
31.5444,Pod,MODIFIED,eval-sanitize-5-r3-031-brmm4,phase=Pending node=None
31.5545,Job,MODIFIED,eval-sanitize-5-r3-018,
31.5647,Pod,MODIFIED,eval-sanitize-5-r3-018-pndjq,phase=Succeeded node=kind-worker
31.5657,Job,MODIFIED,eval-sanitize-5-r3-018,
31.5665,Pod,MODIFIED,eval-sanitize-5-r3-025-v6v64,phase=Pending node=None
31.5769,Pod,MODIFIED,eval-sanitize-5-r3-026-hghxc,phase=Pending node=kind-worker2
31.5814,Event,ADDED,eval-sanitize-5-r3-026-hghxc.18d3d46b06c070a6,reason=Scheduled count=None msg=Successfully assigned compute/eval-sanitize-5-r3-026-hghxc to kind-worker2
31.5894,Node,MODIFIED,kind-worker2,taints=0
31.5926,Pod,MODIFIED,eval-sanitize-5-r3-026-hghxc,phase=Pending node=kind-worker2
31.6012,Node,MODIFIED,kind-worker2,taints=0
31.6503,Event,ADDED,eval-sanitize-5-r3-027-9ft5d.18d3d46b0ae1802e,"reason=Pulled count=1 msg=Container image ""busybox:musl"" already present on machine"
31.6546,Event,ADDED,eval-sanitize-5-r3-023-rzr46.18d3d46b0af3339c,"reason=Pulled count=1 msg=Container image ""busybox:musl"" already present on machine"
31.6613,Event,ADDED,eval-sanitize-5-r3-031-brmm4.18d3d46b0b6977e4,"reason=FailedScheduling count=None msg=0/6 nodes are available: 1 c_wall violated: 1 conflicting context pair(s) with node memory, 1 c_wall violated: 2 conflicting context pair(s) with node memory, 4 node(s) had untolerated taint(s). no new claims to deallocate, preemption: 0/6 nodes are available: 2 No preemption victims found for incoming pod, 4 Preemption is not helpful for scheduling."
31.6624,Event,ADDED,eval-sanitize-5-r3-028-6xmxg.18d3d46b0b5087af,"reason=Pulled count=1 msg=Container image ""busybox:musl"" already present on machine"
31.6668,Event,ADDED,eval-sanitize-5-r3-025-v6v64.18d3d46b0bbcc07d,"reason=FailedScheduling count=None msg=0/6 nodes are available: 2 c_wall violated: 1 conflicting context pair(s) with node memory, 4 node(s) had untolerated taint(s). no new claims to deallocate, preemption: 0/6 nodes are available: 2 No preemption victims found for incoming pod, 4 Preemption is not helpful for scheduling."
31.6733,Event,MODIFIED,eval-sanitize-5-r3-031-brmm4.18d3d46b0b6977e4,"reason=FailedScheduling count=None msg=0/6 nodes are available: 1 c_wall violated: 1 conflicting context pair(s) with node memory, 1 c_wall violated: 2 conflicting context pair(s) with node memory, 4 node(s) had untolerated taint(s). no new claims to deallocate, preemption: 0/6 nodes are available: 2 No preemption victims found for incoming pod, 4 Preemption is not helpful for scheduling."
31.6848,Event,ADDED,eval-sanitize-5-r3-027-9ft5d.18d3d46b0cf67194,reason=Created count=1 msg=Created container: task
31.69,Event,ADDED,eval-sanitize-5-r3-023-rzr46.18d3d46b0d53ac99,reason=Created count=1 msg=Created container: task
31.6946,Event,ADDED,eval-sanitize-5-r3-028-6xmxg.18d3d46b0d8909d8,reason=Created count=1 msg=Created container: task
31.758,Event,ADDED,eval-sanitize-5-r3-027-9ft5d.18d3d46b114dee0c,reason=Started count=1 msg=Started container task
31.7629,Event,ADDED,eval-sanitize-5-r3-023-rzr46.18d3d46b114dedf8,reason=Started count=1 msg=Started container task
31.7667,Event,ADDED,eval-sanitize-5-r3-028-6xmxg.18d3d46b11948cd7,reason=Started count=1 msg=Started container task
31.8144,Pod,MODIFIED,eval-sanitize-5-r3-021-gbb9r,phase=Running node=kind-worker4
31.826,Event,MODIFIED,eval-sanitize-5-r3-025-v6v64.18d3d46b0bbcc07d,"reason=FailedScheduling count=None msg=0/6 nodes are available: 2 c_wall violated: 1 conflicting context pair(s) with node memory, 4 node(s) had untolerated taint(s). no new claims to deallocate, preemption: 0/6 nodes are available: 2 No preemption victims found for incoming pod, 4 Preemption is not helpful for scheduling."
31.8608,Pod,MODIFIED,eval-sanitize-5-r3-028-6xmxg,phase=Running node=kind-worker5
31.868,Pod,MODIFIED,eval-sanitize-5-r3-027-9ft5d,phase=Running node=kind-worker5
31.8756,Pod,MODIFIED,eval-sanitize-5-r3-023-rzr46,phase=Running node=kind-worker5
31.9003,Event,ADDED,eval-sanitize-5-r3-029-j9fgd.18d3d46b19cad2c4,"reason=Pulled count=1 msg=Container image ""busybox:musl"" already present on machine"
31.9051,Job,MODIFIED,eval-sanitize-5-r3-019,
31.9106,Event,ADDED,eval-sanitize-5-r3-030-9m4cf.18d3d46b1a69ecf3,"reason=Pulled count=1 msg=Container image ""busybox:musl"" already present on machine"
31.9151,Pod,MODIFIED,eval-sanitize-5-r3-019-dq89j,phase=Succeeded node=kind-worker2
31.9169,Job,MODIFIED,eval-sanitize-5-r3-019,
31.9354,Event,ADDED,eval-sanitize-5-r3-029-j9fgd.18d3d46b1be88057,reason=Created count=1 msg=Created container: task
31.9479,Event,ADDED,eval-sanitize-5-r3-030-9m4cf.18d3d46b1c97af50,reason=Created count=1 msg=Created container: task
32.0073,TaskRequest,ADDED,eval-sanitize-5-r3-032,phase=None job=None
32.0104,Event,ADDED,eval-sanitize-5-r3-029-j9fgd.18d3d46b2068f357,reason=Started count=1 msg=Started container task
32.0114,TaskRequest,MODIFIED,eval-sanitize-5-r3-032,phase=Pending job=None
32.0229,Event,ADDED,eval-sanitize-5-r3-030-9m4cf.18d3d46b2106618e,reason=Started count=1 msg=Started container task
32.026,Job,ADDED,eval-sanitize-5-r3-032,
32.0285,Event,ADDED,eval-sanitize-5-r3-026-hghxc.18d3d46b2159ebe2,"reason=Pulled count=1 msg=Container image ""busybox:musl"" already present on machine"
32.0306,Pod,ADDED,eval-sanitize-5-r3-032-wdxmb,phase=Pending node=None
32.0326,TaskRequest,MODIFIED,eval-sanitize-5-r3-032,phase=Scheduled job=None
32.0364,Job,MODIFIED,eval-sanitize-5-r3-032,
32.0393,Event,ADDED,eval-sanitize-5-r3-032.18d3d46b21db7b91,reason=SuccessfulCreate count=1 msg=Created pod: eval-sanitize-5-r3-032-wdxmb
32.0403,Job,MODIFIED,eval-sanitize-5-r3-031,
32.0439,Pod,MODIFIED,eval-sanitize-5-r3-032-wdxmb,phase=Pending node=kind-worker2
32.0441,TaskRequest,MODIFIED,eval-sanitize-5-r3-032,phase=Scheduled job=None
32.0498,Event,ADDED,eval-sanitize-5-r3-032-wdxmb.18d3d46b229e91ea,reason=Scheduled count=None msg=Successfully assigned compute/eval-sanitize-5-r3-032-wdxmb to kind-worker2
32.0529,Event,ADDED,eval-sanitize-5-r3-026-hghxc.18d3d46b22cac1ee,reason=Created count=1 msg=Created container: task
32.0539,Job,MODIFIED,eval-sanitize-5-r3-031,
32.0562,Pod,MODIFIED,eval-sanitize-5-r3-032-wdxmb,phase=Pending node=kind-worker2
32.1172,Event,ADDED,eval-sanitize-5-r3-026-hghxc.18d3d46b26ad9c3d,reason=Started count=1 msg=Started container task
32.1984,Job,MODIFIED,eval-sanitize-5-r3-023,
32.2074,Job,MODIFIED,eval-sanitize-5-r3-023,
32.2273,Job,MODIFIED,eval-sanitize-5-r3-027,
32.2301,Job,MODIFIED,eval-sanitize-5-r3-028,
32.2361,Job,MODIFIED,eval-sanitize-5-r3-027,
32.2382,Job,MODIFIED,eval-sanitize-5-r3-028,
32.4644,Event,ADDED,eval-sanitize-5-r3-032-wdxmb.18d3d46b3b6b52ff,"reason=Pulled count=1 msg=Container image ""busybox:musl"" already present on machine"
32.4677,Job,MODIFIED,eval-sanitize-5-r3-020,
32.4796,Job,MODIFIED,eval-sanitize-5-r3-020,
32.488,Event,ADDED,eval-sanitize-5-r3-032-wdxmb.18d3d46b3cd8b7e4,reason=Created count=1 msg=Created container: task
32.5596,Job,MODIFIED,eval-sanitize-5-r3-018,
32.5599,Event,ADDED,eval-sanitize-5-r3-032-wdxmb.18d3d46b412823e4,reason=Started count=1 msg=Started container task
32.5636,Job,MODIFIED,eval-sanitize-5-r3-018,
32.5679,Event,ADDED,eval-sanitize-5-r3-018.18d3d46b419cf95b,reason=Completed count=1 msg=Job completed
32.5737,Job,MODIFIED,eval-sanitize-5-r3-018,
32.5779,TaskRequest,MODIFIED,eval-sanitize-5-r3-018,phase=Complete job=None
32.5876,Job,MODIFIED,eval-sanitize-5-r3-018,
32.593,Pod,MODIFIED,eval-sanitize-5-r3-020-m7rv7,phase=Succeeded node=kind-worker
32.8214,Pod,MODIFIED,eval-sanitize-5-r3-022-62z7n,phase=Running node=kind-worker3
32.8228,Job,MODIFIED,eval-sanitize-5-r3-021,
32.8328,Job,MODIFIED,eval-sanitize-5-r3-021,
32.9024,Pod,MODIFIED,eval-sanitize-5-r3-032-wdxmb,phase=Running node=kind-worker2
32.9079,Pod,MODIFIED,eval-sanitize-5-r3-021-gbb9r,phase=Succeeded node=kind-worker4
32.9097,Pod,MODIFIED,eval-sanitize-5-r3-030-9m4cf,phase=Running node=kind-worker2
32.9111,Job,MODIFIED,eval-sanitize-5-r3-019,
32.9153,Job,MODIFIED,eval-sanitize-5-r3-019,
32.9184,Pod,MODIFIED,eval-sanitize-5-r3-029-j9fgd,phase=Running node=kind-worker2
32.9204,Event,ADDED,eval-sanitize-5-r3-019.18d3d46b569372a8,reason=Completed count=1 msg=Job completed
32.9272,Pod,MODIFIED,eval-sanitize-5-r3-026-hghxc,phase=Running node=kind-worker2
32.9282,Job,MODIFIED,eval-sanitize-5-r3-019,
32.933,TaskRequest,MODIFIED,eval-sanitize-5-r3-019,phase=Complete job=None
32.9427,Job,MODIFIED,eval-sanitize-5-r3-019,
33.0067,TaskRequest,ADDED,eval-sanitize-5-r3-033,phase=None job=None
33.0102,TaskRequest,MODIFIED,eval-sanitize-5-r3-033,phase=Pending job=None
33.0252,Job,ADDED,eval-sanitize-5-r3-033,
33.0317,Pod,ADDED,eval-sanitize-5-r3-033-zg9jg,phase=Pending node=None
33.0319,TaskRequest,MODIFIED,eval-sanitize-5-r3-033,phase=Scheduled job=None
33.0344,Job,MODIFIED,eval-sanitize-5-r3-033,
33.0362,Event,ADDED,eval-sanitize-5-r3-033.18d3d46b5d7f44ad,reason=SuccessfulCreate count=1 msg=Created pod: eval-sanitize-5-r3-033-zg9jg
33.0371,Job,MODIFIED,eval-sanitize-5-r3-032,
33.0387,TaskRequest,MODIFIED,eval-sanitize-5-r3-033,phase=Scheduled job=None
33.0533,Pod,MODIFIED,eval-sanitize-5-r3-033-zg9jg,phase=Pending node=kind-worker2
33.0555,Job,MODIFIED,eval-sanitize-5-r3-032,
33.0588,Event,ADDED,eval-sanitize-5-r3-033-zg9jg.18d3d46b5ec85d93,reason=Scheduled count=None msg=Successfully assigned compute/eval-sanitize-5-r3-033-zg9jg to kind-worker2
33.0652,Pod,MODIFIED,eval-sanitize-5-r3-033-zg9jg,phase=Pending node=kind-worker2
33.4762,Job,MODIFIED,eval-sanitize-5-r3-020,
33.4866,Pod,MODIFIED,eval-sanitize-5-r3-020-m7rv7,phase=Succeeded node=kind-worker
33.489,Event,ADDED,eval-sanitize-5-r3-033-zg9jg.18d3d46b7863d992,"reason=Pulled count=1 msg=Container image ""busybox:musl"" already present on machine"
33.4901,Job,MODIFIED,eval-sanitize-5-r3-020,
33.5077,Event,ADDED,eval-sanitize-5-r3-033-zg9jg.18d3d46b79a6c912,reason=Created count=1 msg=Created container: task
33.5784,Event,ADDED,eval-sanitize-5-r3-033-zg9jg.18d3d46b7dd703dd,reason=Started count=1 msg=Started container task
33.8279,Job,MODIFIED,eval-sanitize-5-r3-022,
33.8305,Job,MODIFIED,eval-sanitize-5-r3-021,
33.8402,Pod,MODIFIED,eval-sanitize-5-r3-021-gbb9r,phase=Succeeded node=kind-worker4
33.8412,Job,MODIFIED,eval-sanitize-5-r3-022,
33.8422,Job,MODIFIED,eval-sanitize-5-r3-021,
33.909,Pod,MODIFIED,eval-sanitize-5-r3-033-zg9jg,phase=Running node=kind-worker2
33.9156,Job,MODIFIED,eval-sanitize-5-r3-030,
33.9236,Job,MODIFIED,eval-sanitize-5-r3-029,
33.9254,Job,MODIFIED,eval-sanitize-5-r3-030,
33.9295,Job,MODIFIED,eval-sanitize-5-r3-026,
33.9328,Job,MODIFIED,eval-sanitize-5-r3-029,
33.9389,Job,MODIFIED,eval-sanitize-5-r3-026,
33.9634,Pod,MODIFIED,eval-sanitize-5-r3-022-62z7n,phase=Succeeded node=kind-worker3
34.0083,TaskRequest,ADDED,eval-sanitize-5-r3-034,phase=None job=None
34.0136,TaskRequest,MODIFIED,eval-sanitize-5-r3-034,phase=Pending job=None
34.0287,Job,ADDED,eval-sanitize-5-r3-034,
34.0349,TaskRequest,MODIFIED,eval-sanitize-5-r3-034,phase=Scheduled job=None
34.0378,Job,MODIFIED,eval-sanitize-5-r3-033,
34.039,Pod,ADDED,eval-sanitize-5-r3-034-tqzsg,phase=Pending node=None
34.0398,Job,MODIFIED,eval-sanitize-5-r3-034,
34.0435,Event,ADDED,eval-sanitize-5-r3-034.18d3d46b9974f79d,reason=SuccessfulCreate count=1 msg=Created pod: eval-sanitize-5-r3-034-tqzsg
34.0436,TaskRequest,MODIFIED,eval-sanitize-5-r3-034,phase=Scheduled job=None
34.0467,Job,MODIFIED,eval-sanitize-5-r3-033,
34.0492,Pod,MODIFIED,eval-sanitize-5-r3-034-tqzsg,phase=Pending node=kind-worker5
34.0528,Event,ADDED,eval-sanitize-5-r3-034-tqzsg.18d3d46b9a28c742,reason=Scheduled count=None msg=Successfully assigned compute/eval-sanitize-5-r3-034-tqzsg to kind-worker5
34.0593,Pod,MODIFIED,eval-sanitize-5-r3-034-tqzsg,phase=Pending node=kind-worker5
34.4844,Job,MODIFIED,eval-sanitize-5-r3-020,
34.4899,Job,MODIFIED,eval-sanitize-5-r3-020,
34.4902,Event,ADDED,eval-sanitize-5-r3-034-tqzsg.18d3d46bb42b21c4,"reason=Pulled count=1 msg=Container image ""busybox:musl"" already present on machine"
34.4943,Event,ADDED,eval-sanitize-5-r3-020.18d3d46bb46e7eab,reason=Completed count=1 msg=Job completed
34.5011,Job,MODIFIED,eval-sanitize-5-r3-020,
34.5088,TaskRequest,MODIFIED,eval-sanitize-5-r3-020,phase=Complete job=None
34.5118,Event,ADDED,eval-sanitize-5-r3-034-tqzsg.18d3d46bb57f271f,reason=Created count=1 msg=Created container: task
34.5193,Job,MODIFIED,eval-sanitize-5-r3-020,
34.5724,Event,ADDED,eval-sanitize-5-r3-034-tqzsg.18d3d46bb91b48bd,reason=Started count=1 msg=Started container task
34.8267,Pod,MODIFIED,eval-sanitize-5-r3-024-c56sv,phase=Running node=kind-worker3
34.8338,Job,MODIFIED,eval-sanitize-5-r3-022,
34.8357,Job,MODIFIED,eval-sanitize-5-r3-021,
34.8415,Job,MODIFIED,eval-sanitize-5-r3-021,
34.8443,Pod,MODIFIED,eval-sanitize-5-r3-022-62z7n,phase=Succeeded node=kind-worker3
34.8458,Job,MODIFIED,eval-sanitize-5-r3-022,
34.8462,Event,ADDED,eval-sanitize-5-r3-021.18d3d46bc9629fc4,reason=Completed count=1 msg=Job completed
34.852,Job,MODIFIED,eval-sanitize-5-r3-021,
34.8563,TaskRequest,MODIFIED,eval-sanitize-5-r3-021,phase=Complete job=None
34.8663,Job,MODIFIED,eval-sanitize-5-r3-021,
34.8686,Pod,MODIFIED,eval-sanitize-5-r3-034-tqzsg,phase=Running node=kind-worker5
35.0087,TaskRequest,ADDED,eval-sanitize-5-r3-035,phase=None job=None
35.0132,TaskRequest,MODIFIED,eval-sanitize-5-r3-035,phase=Pending job=None
35.0283,Job,ADDED,eval-sanitize-5-r3-035,
35.0358,Pod,ADDED,eval-sanitize-5-r3-035-9gzvj,phase=Pending node=None
35.0359,TaskRequest,MODIFIED,eval-sanitize-5-r3-035,phase=Scheduled job=None
35.0389,Job,MODIFIED,eval-sanitize-5-r3-035,
35.0414,Event,ADDED,eval-sanitize-5-r3-035.18d3d46bd4f3652f,reason=SuccessfulCreate count=1 msg=Created pod: eval-sanitize-5-r3-035-9gzvj
35.0424,Job,MODIFIED,eval-sanitize-5-r3-034,
35.0425,TaskRequest,MODIFIED,eval-sanitize-5-r3-035,phase=Scheduled job=None
35.0491,Pod,MODIFIED,eval-sanitize-5-r3-035-9gzvj,phase=Pending node=None
35.0496,Event,ADDED,eval-sanitize-5-r3-035-9gzvj.18d3d46bd55bbdb3,"reason=FailedScheduling count=None msg=0/6 nodes are available: 2 c_wall violated: 1 conflicting context pair(s) with node memory, 4 node(s) had untolerated taint(s). no new claims to deallocate, preemption: 0/6 nodes are available: 2 No preemption victims found for incoming pod, 4 Preemption is not helpful for scheduling."
35.0526,Job,MODIFIED,eval-sanitize-5-r3-034,
35.0584,Event,ADDED,eval-sanitize-5-r3-035-9gzvj.18d3d46bd61e8579,"reason=FailedScheduling count=None msg=0/6 nodes are available: 2 c_wall violated: 1 conflicting context pair(s) with node memory, 4 node(s) had untolerated taint(s). no new claims to deallocate, preemption: 0/6 nodes are available: 2 No preemption victims found for incoming pod, 4 Preemption is not helpful for scheduling."
35.8334,Job,MODIFIED,eval-sanitize-5-r3-024,
35.8418,Job,MODIFIED,eval-sanitize-5-r3-022,
35.8445,Job,MODIFIED,eval-sanitize-5-r3-024,
35.8468,Job,MODIFIED,eval-sanitize-5-r3-022,
35.851,Event,ADDED,eval-sanitize-5-r3-022.18d3d46c054da596,reason=Completed count=1 msg=Job completed
35.8636,Job,MODIFIED,eval-sanitize-5-r3-022,
35.8679,TaskRequest,MODIFIED,eval-sanitize-5-r3-022,phase=Complete job=None
35.8797,Job,MODIFIED,eval-sanitize-5-r3-022,
35.9291,Pod,MODIFIED,eval-sanitize-5-r3-024-c56sv,phase=Succeeded node=kind-worker3
35.951,Event,MODIFIED,eval-sanitize-5-r3-035-9gzvj.18d3d46bd61e8579,"reason=FailedScheduling count=None msg=0/6 nodes are available: 2 c_wall violated: 1 conflicting context pair(s) with node memory, 4 node(s) had untolerated taint(s). no new claims to deallocate, preemption: 0/6 nodes are available: 2 No preemption victims found for incoming pod, 4 Preemption is not helpful for scheduling."
36.0083,TaskRequest,ADDED,eval-sanitize-5-r3-036,phase=None job=None
36.0132,TaskRequest,MODIFIED,eval-sanitize-5-r3-036,phase=Pending job=None
36.0282,Job,ADDED,eval-sanitize-5-r3-036,
36.0361,TaskRequest,MODIFIED,eval-sanitize-5-r3-036,phase=Scheduled job=None
36.0395,Job,MODIFIED,eval-sanitize-5-r3-036,
36.0402,Pod,ADDED,eval-sanitize-5-r3-036-8zwkc,phase=Pending node=None
36.042,Job,MODIFIED,eval-sanitize-5-r3-035,
36.0428,Event,ADDED,eval-sanitize-5-r3-036.18d3d46c10c98b5e,reason=SuccessfulCreate count=1 msg=Created pod: eval-sanitize-5-r3-036-8zwkc
36.046,TaskRequest,MODIFIED,eval-sanitize-5-r3-036,phase=Scheduled job=None
36.0504,Job,MODIFIED,eval-sanitize-5-r3-035,
36.0603,Node,MODIFIED,kind-worker4,taints=1
36.0735,Node,MODIFIED,kind-worker4,taints=0
36.091,Node,MODIFIED,kind-worker4,taints=0
36.1012,Node,MODIFIED,kind-worker4,taints=0
36.163,Pod,MODIFIED,eval-sanitize-5-r3-036-8zwkc,phase=Pending node=kind-worker5
36.1675,Event,ADDED,eval-sanitize-5-r3-036-8zwkc.18d3d46c1825fb67,reason=Scheduled count=None msg=Successfully assigned compute/eval-sanitize-5-r3-036-8zwkc to kind-worker5
36.1738,Pod,MODIFIED,eval-sanitize-5-r3-036-8zwkc,phase=Pending node=kind-worker5
36.2308,Pod,MODIFIED,eval-sanitize-5-r3-025-v6v64,phase=Pending node=kind-worker4
36.2343,Pod,MODIFIED,eval-sanitize-5-r3-031-brmm4,phase=Pending node=None
36.2347,Event,ADDED,eval-sanitize-5-r3-025-v6v64.18d3d46c1c303285,reason=Scheduled count=None msg=Successfully assigned compute/eval-sanitize-5-r3-025-v6v64 to kind-worker4
36.242,Pod,MODIFIED,eval-sanitize-5-r3-025-v6v64,phase=Pending node=kind-worker4
36.2447,Node,MODIFIED,kind-worker4,taints=0
36.2548,Node,MODIFIED,kind-worker4,taints=0
36.272,Node,MODIFIED,kind-worker5,taints=1
36.2856,Node,MODIFIED,kind-worker5,taints=1
36.3332,Pod,MODIFIED,eval-sanitize-5-r3-035-9gzvj,phase=Pending node=kind-worker4
36.3357,Event,ADDED,eval-sanitize-5-r3-031-brmm4.18d3d46c21f5badd,"reason=FailedScheduling count=None msg=0/6 nodes are available: 2 c_wall violated: 1 conflicting context pair(s) with node memory, 4 node(s) had untolerated taint(s). no new claims to deallocate, preemption: 0/6 nodes are available: 2 No preemption victims found for incoming pod, 4 Preemption is not helpful for scheduling."
36.3367,Pod,MODIFIED,eval-sanitize-5-r3-031-brmm4,phase=Pending node=None
36.337,Event,ADDED,eval-sanitize-5-r3-035-9gzvj.18d3d46c224a50ba,reason=Scheduled count=None msg=Successfully assigned compute/eval-sanitize-5-r3-035-9gzvj to kind-worker4
36.3451,Pod,MODIFIED,eval-sanitize-5-r3-035-9gzvj,phase=Pending node=kind-worker4
36.3575,Event,ADDED,eval-sanitize-5-r3-031-brmm4.18d3d46c238a7042,"reason=FailedScheduling count=None msg=0/6 nodes are available: 2 c_wall violated: 1 conflicting context pair(s) with node memory, 4 node(s) had untolerated taint(s). no new claims to deallocate, preemption: 0/6 nodes are available: 2 No preemption victims found for incoming pod, 4 Preemption is not helpful for scheduling."
36.4284,Event,MODIFIED,eval-sanitize-5-r3-031-brmm4.18d3d46c238a7042,"reason=FailedScheduling count=None msg=0/6 nodes are available: 2 c_wall violated: 1 conflicting context pair(s) with node memory, 4 node(s) had untolerated taint(s). no new claims to deallocate, preemption: 0/6 nodes are available: 2 No preemption victims found for incoming pod, 4 Preemption is not helpful for scheduling."
36.5743,Node,MODIFIED,kind-worker2,taints=1
36.585,Pod,MODIFIED,eval-sanitize-5-r3-031-brmm4,phase=Pending node=None
36.5883,Node,MODIFIED,kind-worker2,taints=1
36.5947,Event,ADDED,eval-sanitize-5-r3-031-brmm4.18d3d46c31876237,"reason=FailedScheduling count=None msg=0/6 nodes are available: 1 c_wall violated: 1 conflicting context pair(s) with node memory, 5 node(s) had untolerated taint(s). no new claims to deallocate, preemption: 0/6 nodes are available: 1 No preemption victims found for incoming pod, 5 Preemption is not helpful for scheduling."
36.5983,Event,ADDED,eval-sanitize-5-r3-036-8zwkc.18d3d46c31e1924e,"reason=Pulled count=1 msg=Container image ""busybox:musl"" already present on machine"
36.6196,Event,ADDED,eval-sanitize-5-r3-036-8zwkc.18d3d46c33160a52,reason=Created count=1 msg=Created container: task
36.6803,Event,ADDED,eval-sanitize-5-r3-025-v6v64.18d3d46c3679022f,"reason=Pulled count=1 msg=Container image ""busybox:musl"" already present on machine"
36.6816,Event,ADDED,eval-sanitize-5-r3-036-8zwkc.18d3d46c36ca9252,reason=Started count=1 msg=Started container task
36.7017,Event,ADDED,eval-sanitize-5-r3-025-v6v64.18d3d46c38085efc,reason=Created count=1 msg=Created container: task
36.7358,Event,ADDED,eval-sanitize-5-r3-025-v6v64.18d3d46c3a0f2375,reason=Started count=1 msg=Started container task
36.7415,Event,ADDED,eval-sanitize-5-r3-035-9gzvj.18d3d46c3a1bd3f4,"reason=Pulled count=1 msg=Container image ""busybox:musl"" already present on machine"
36.7554,Event,ADDED,eval-sanitize-5-r3-035-9gzvj.18d3d46c3b3b3a61,reason=Created count=1 msg=Created container: task
36.8263,Pod,MODIFIED,eval-sanitize-5-r3-025-v6v64,phase=Running node=kind-worker4
36.8393,Job,MODIFIED,eval-sanitize-5-r3-024,
36.8458,Event,ADDED,eval-sanitize-5-r3-035-9gzvj.18d3d46c4098c0e1,reason=Started count=1 msg=Started container task
36.8489,Job,MODIFIED,eval-sanitize-5-r3-024,
36.8502,Pod,MODIFIED,eval-sanitize-5-r3-024-c56sv,phase=Succeeded node=kind-worker3
36.8768,Pod,MODIFIED,eval-sanitize-5-r3-036-8zwkc,phase=Running node=kind-worker5
37.0209,TaskRequest,ADDED,eval-sanitize-5-r3-037,phase=None job=None
37.024,TaskRequest,MODIFIED,eval-sanitize-5-r3-037,phase=Pending job=None
37.0405,Job,ADDED,eval-sanitize-5-r3-037,
37.0454,Job,MODIFIED,eval-sanitize-5-r3-036,
37.0466,TaskRequest,MODIFIED,eval-sanitize-5-r3-037,phase=Scheduled job=None
37.0477,Pod,ADDED,eval-sanitize-5-r3-037-gnpkz,phase=Pending node=None
37.0497,Job,MODIFIED,eval-sanitize-5-r3-037,
37.0521,Event,ADDED,eval-sanitize-5-r3-037.18d3d46c4ce015ec,reason=SuccessfulCreate count=1 msg=Created pod: eval-sanitize-5-r3-037-gnpkz
37.0547,TaskRequest,MODIFIED,eval-sanitize-5-r3-037,phase=Scheduled job=None
37.058,Job,MODIFIED,eval-sanitize-5-r3-036,
37.059,Pod,MODIFIED,eval-sanitize-5-r3-037-gnpkz,phase=Pending node=kind-worker4
37.0621,Event,ADDED,eval-sanitize-5-r3-037-gnpkz.18d3d46c4d7cb0dc,reason=Scheduled count=None msg=Successfully assigned compute/eval-sanitize-5-r3-037-gnpkz to kind-worker4
37.0674,Pod,MODIFIED,eval-sanitize-5-r3-031-brmm4,phase=Pending node=None
37.0704,Pod,MODIFIED,eval-sanitize-5-r3-037-gnpkz,phase=Pending node=kind-worker4
37.0721,Node,MODIFIED,kind-worker4,taints=0
37.0758,Event,ADDED,eval-sanitize-5-r3-031-brmm4.18d3d46c4e544a41,"reason=FailedScheduling count=None msg=0/6 nodes are available: 1 c_wall violated: 2 conflicting context pair(s) with node memory, 5 node(s) had untolerated taint(s). no new claims to deallocate, preemption: 0/6 nodes are available: 1 No preemption victims found for incoming pod, 5 Preemption is not helpful for scheduling."
37.0808,Node,MODIFIED,kind-worker4,taints=0
37.0811,Event,MODIFIED,eval-sanitize-5-r3-031-brmm4.18d3d46c4e544a41,"reason=FailedScheduling count=None msg=0/6 nodes are available: 1 c_wall violated: 2 conflicting context pair(s) with node memory, 5 node(s) had untolerated taint(s). no new claims to deallocate, preemption: 0/6 nodes are available: 1 No preemption victims found for incoming pod, 5 Preemption is not helpful for scheduling."
37.2435,Job,MODIFIED,eval-sanitize-5-r3-025,
37.2518,Job,MODIFIED,eval-sanitize-5-r3-025,
37.355,Node,MODIFIED,kind-worker,taints=1
37.3674,Node,MODIFIED,kind-worker,taints=1
37.3768,Node,MODIFIED,kind-worker,taints=0
37.3841,Pod,MODIFIED,eval-sanitize-5-r3-031-brmm4,phase=Pending node=kind-worker
37.3919,Node,MODIFIED,kind-worker,taints=0
37.3936,Event,ADDED,eval-sanitize-5-r3-031-brmm4.18d3d46c60ecd9e3,reason=Scheduled count=None msg=Successfully assigned compute/eval-sanitize-5-r3-031-brmm4 to kind-worker
37.3979,Pod,MODIFIED,eval-sanitize-5-r3-031-brmm4,phase=Pending node=kind-worker
37.4199,Node,MODIFIED,kind-worker,taints=0
37.4573,Node,MODIFIED,kind-worker,taints=0
37.4829,Event,ADDED,eval-sanitize-5-r3-037-gnpkz.18d3d46c6692d5ff,"reason=Pulled count=1 msg=Container image ""busybox:musl"" already present on machine"
37.5038,Event,ADDED,eval-sanitize-5-r3-037-gnpkz.18d3d46c67b9eddb,reason=Created count=1 msg=Created container: task
37.5757,Event,ADDED,eval-sanitize-5-r3-037-gnpkz.18d3d46c6c2417cd,reason=Started count=1 msg=Started container task
37.8014,Event,ADDED,eval-sanitize-5-r3-031-brmm4.18d3d46c7992adb4,"reason=Pulled count=1 msg=Container image ""busybox:musl"" already present on machine"
37.8236,Event,ADDED,eval-sanitize-5-r3-031-brmm4.18d3d46c7ae17534,reason=Created count=1 msg=Created container: task
37.8303,Pod,MODIFIED,eval-sanitize-5-r3-035-9gzvj,phase=Running node=kind-worker4
37.8367,Pod,MODIFIED,eval-sanitize-5-r3-037-gnpkz,phase=Running node=kind-worker4
37.8455,Job,MODIFIED,eval-sanitize-5-r3-024,
37.85,Job,MODIFIED,eval-sanitize-5-r3-024,
37.856,Event,ADDED,eval-sanitize-5-r3-024.18d3d46c7cba06f8,reason=Completed count=1 msg=Job completed
37.8576,Event,ADDED,eval-sanitize-5-r3-031-brmm4.18d3d46c7ce98ef4,reason=Started count=1 msg=Started container task
37.8615,Job,MODIFIED,eval-sanitize-5-r3-024,
37.8665,TaskRequest,MODIFIED,eval-sanitize-5-r3-024,phase=Complete job=None
37.8755,Job,MODIFIED,eval-sanitize-5-r3-024,
38.027,TaskRequest,ADDED,eval-sanitize-5-r3-038,phase=None job=None
38.0321,TaskRequest,MODIFIED,eval-sanitize-5-r3-038,phase=Pending job=None
38.0462,Job,ADDED,eval-sanitize-5-r3-038,
38.0508,TaskRequest,MODIFIED,eval-sanitize-5-r3-038,phase=Scheduled job=None
38.0545,Job,MODIFIED,eval-sanitize-5-r3-037,
38.0556,Pod,ADDED,eval-sanitize-5-r3-038-szrth,phase=Pending node=None
38.0568,Job,MODIFIED,eval-sanitize-5-r3-038,
38.0588,Event,ADDED,eval-sanitize-5-r3-038.18d3d46c88e3756f,reason=SuccessfulCreate count=1 msg=Created pod: eval-sanitize-5-r3-038-szrth
38.0589,TaskRequest,MODIFIED,eval-sanitize-5-r3-038,phase=Scheduled job=None
38.0635,Job,MODIFIED,eval-sanitize-5-r3-037,
38.0666,Pod,MODIFIED,eval-sanitize-5-r3-038-szrth,phase=Pending node=kind-worker
38.0701,Event,ADDED,eval-sanitize-5-r3-038-szrth.18d3d46c899f6cb8,reason=Scheduled count=None msg=Successfully assigned compute/eval-sanitize-5-r3-038-szrth to kind-worker
38.0764,Node,MODIFIED,kind-worker,taints=0
38.0785,Pod,MODIFIED,eval-sanitize-5-r3-038-szrth,phase=Pending node=kind-worker
38.0882,Node,MODIFIED,kind-worker,taints=0
38.4861,Pod,MODIFIED,eval-sanitize-5-r3-031-brmm4,phase=Running node=kind-worker
38.4893,Event,ADDED,eval-sanitize-5-r3-038-szrth.18d3d46ca2935bb9,"reason=Pulled count=1 msg=Container image ""busybox:musl"" already present on machine"
38.5077,Event,ADDED,eval-sanitize-5-r3-038-szrth.18d3d46ca3b09d6b,reason=Created count=1 msg=Created container: task
38.5576,Event,ADDED,eval-sanitize-5-r3-038-szrth.18d3d46ca68869ac,reason=Started count=1 msg=Started container task
38.8469,Job,MODIFIED,eval-sanitize-5-r3-035,
38.8568,Job,MODIFIED,eval-sanitize-5-r3-035,
39.0142,TaskRequest,ADDED,eval-sanitize-5-r3-039,phase=None job=None
39.018,TaskRequest,MODIFIED,eval-sanitize-5-r3-039,phase=Pending job=None
39.0339,Job,ADDED,eval-sanitize-5-r3-039,
39.0394,Pod,ADDED,eval-sanitize-5-r3-039-l8s8w,phase=Pending node=None
39.0415,TaskRequest,MODIFIED,eval-sanitize-5-r3-039,phase=Scheduled job=None
39.0446,Job,MODIFIED,eval-sanitize-5-r3-039,
39.0464,Event,ADDED,eval-sanitize-5-r3-039.18d3d46cc39624f2,reason=SuccessfulCreate count=1 msg=Created pod: eval-sanitize-5-r3-039-l8s8w
39.0507,Pod,MODIFIED,eval-sanitize-5-r3-039-l8s8w,phase=Pending node=kind-worker
39.0509,TaskRequest,MODIFIED,eval-sanitize-5-r3-039,phase=Scheduled job=None
39.0536,Job,MODIFIED,eval-sanitize-5-r3-039,
39.054,Event,ADDED,eval-sanitize-5-r3-039-l8s8w.18d3d46cc447f737,reason=Scheduled count=None msg=Successfully assigned compute/eval-sanitize-5-r3-039-l8s8w to kind-worker
39.0596,Job,MODIFIED,eval-sanitize-5-r3-038,
39.0635,Job,MODIFIED,eval-sanitize-5-r3-039,
39.0665,Pod,MODIFIED,eval-sanitize-5-r3-039-l8s8w,phase=Pending node=kind-worker
39.0685,Job,MODIFIED,eval-sanitize-5-r3-038,
39.4867,Pod,MODIFIED,eval-sanitize-5-r3-038-szrth,phase=Running node=kind-worker
39.4904,Job,MODIFIED,eval-sanitize-5-r3-031,
39.5015,Job,MODIFIED,eval-sanitize-5-r3-031,
39.5019,Event,ADDED,eval-sanitize-5-r3-039-l8s8w.18d3d46cdeedf99d,"reason=Pulled count=1 msg=Container image ""busybox:musl"" already present on machine"
39.5255,Event,ADDED,eval-sanitize-5-r3-039-l8s8w.18d3d46ce044ded0,reason=Created count=1 msg=Created container: task
39.5577,Event,ADDED,eval-sanitize-5-r3-039-l8s8w.18d3d46ce244c55f,reason=Started count=1 msg=Started container task
39.5639,Node,MODIFIED,kind-worker3,taints=1
39.576,Node,MODIFIED,kind-worker3,taints=1
39.5838,Node,MODIFIED,kind-worker3,taints=0
39.5954,Node,MODIFIED,kind-worker3,taints=0
40.0198,TaskRequest,ADDED,eval-sanitize-5-r3-040,phase=None job=None
40.0235,TaskRequest,MODIFIED,eval-sanitize-5-r3-040,phase=Pending job=None
40.0402,Job,ADDED,eval-sanitize-5-r3-040,
40.0467,Pod,ADDED,eval-sanitize-5-r3-040-znsfm,phase=Pending node=None
40.0481,TaskRequest,MODIFIED,eval-sanitize-5-r3-040,phase=Scheduled job=None
40.0489,Job,MODIFIED,eval-sanitize-5-r3-040,
40.0514,Event,ADDED,eval-sanitize-5-r3-040.18d3d46cffa982fd,reason=SuccessfulCreate count=1 msg=Created pod: eval-sanitize-5-r3-040-znsfm
40.0576,TaskRequest,MODIFIED,eval-sanitize-5-r3-040,phase=Scheduled job=None
40.0661,Job,MODIFIED,eval-sanitize-5-r3-038,
40.0693,Pod,MODIFIED,eval-sanitize-5-r3-040-znsfm,phase=Pending node=kind-worker3
40.0734,Event,ADDED,eval-sanitize-5-r3-040-znsfm.18d3d46d00fc693d,reason=Scheduled count=None msg=Successfully assigned compute/eval-sanitize-5-r3-040-znsfm to kind-worker3
40.0764,Job,MODIFIED,eval-sanitize-5-r3-038,
40.0804,Node,MODIFIED,kind-worker3,taints=0
40.0827,Pod,MODIFIED,eval-sanitize-5-r3-040-znsfm,phase=Pending node=kind-worker3
40.091,Node,MODIFIED,kind-worker3,taints=0
40.4842,Pod,MODIFIED,eval-sanitize-5-r3-039-l8s8w,phase=Running node=kind-worker
40.5109,Event,ADDED,eval-sanitize-5-r3-040-znsfm.18d3d46d1af1880a,"reason=Pulled count=1 msg=Container image ""busybox:musl"" already present on machine"
40.5299,Event,ADDED,eval-sanitize-5-r3-040-znsfm.18d3d46d1c35c696,reason=Created count=1 msg=Created container: task
40.6209,Event,ADDED,eval-sanitize-5-r3-040-znsfm.18d3d46d21a24611,reason=Started count=1 msg=Started container task
40.8446,Pod,MODIFIED,eval-sanitize-5-r3-040-znsfm,phase=Running node=kind-worker3
41.02,TaskRequest,ADDED,eval-sanitize-5-r3-041,phase=None job=None
41.0239,TaskRequest,MODIFIED,eval-sanitize-5-r3-041,phase=Pending job=None
41.0404,Job,ADDED,eval-sanitize-5-r3-041,
41.0453,TaskRequest,MODIFIED,eval-sanitize-5-r3-041,phase=Scheduled job=None
41.0493,Pod,ADDED,eval-sanitize-5-r3-041-tmt29,phase=Pending node=None
41.0515,Job,MODIFIED,eval-sanitize-5-r3-041,
41.0542,Job,MODIFIED,eval-sanitize-5-r3-040,
41.0552,Event,ADDED,eval-sanitize-5-r3-041.18d3d46d3b658026,reason=SuccessfulCreate count=1 msg=Created pod: eval-sanitize-5-r3-041-tmt29
41.0554,TaskRequest,MODIFIED,eval-sanitize-5-r3-041,phase=Scheduled job=None
41.0638,Job,MODIFIED,eval-sanitize-5-r3-040,
41.0694,Pod,MODIFIED,eval-sanitize-5-r3-041-tmt29,phase=Pending node=kind-worker4
41.0734,Event,ADDED,eval-sanitize-5-r3-041-tmt29.18d3d46d3ca36c60,reason=Scheduled count=None msg=Successfully assigned compute/eval-sanitize-5-r3-041-tmt29 to kind-worker4
41.0797,Pod,MODIFIED,eval-sanitize-5-r3-041-tmt29,phase=Pending node=kind-worker4
41.0826,Node,MODIFIED,kind-worker4,taints=0
41.0937,Node,MODIFIED,kind-worker4,taints=1
41.1039,Node,MODIFIED,kind-worker4,taints=1
41.1741,Node,MODIFIED,kind-worker4,taints=1
41.4939,Job,MODIFIED,eval-sanitize-5-r3-039,
41.504,Job,MODIFIED,eval-sanitize-5-r3-039,
41.5187,Event,ADDED,eval-sanitize-5-r3-041-tmt29.18d3d46d5711387a,"reason=Pulled count=1 msg=Container image ""busybox:musl"" already present on machine"
41.5347,Event,ADDED,eval-sanitize-5-r3-041-tmt29.18d3d46d5827d42a,reason=Created count=1 msg=Created container: task
41.6185,Event,ADDED,eval-sanitize-5-r3-041-tmt29.18d3d46d5d18263f,reason=Started count=1 msg=Started container task
41.8401,Pod,MODIFIED,eval-sanitize-5-r3-041-tmt29,phase=Running node=kind-worker4
41.8854,Pod,MODIFIED,eval-sanitize-5-r3-028-6xmxg,phase=Running node=kind-worker5
41.8913,Pod,MODIFIED,eval-sanitize-5-r3-027-9ft5d,phase=Running node=kind-worker5
41.8973,Pod,MODIFIED,eval-sanitize-5-r3-023-rzr46,phase=Running node=kind-worker5
42.0244,TaskRequest,ADDED,eval-sanitize-5-r3-042,phase=None job=None
42.0296,TaskRequest,MODIFIED,eval-sanitize-5-r3-042,phase=Pending job=None
42.0474,Job,ADDED,eval-sanitize-5-r3-042,
42.0516,TaskRequest,MODIFIED,eval-sanitize-5-r3-042,phase=Scheduled job=None
42.0544,Job,MODIFIED,eval-sanitize-5-r3-041,
42.0568,Pod,ADDED,eval-sanitize-5-r3-042-cf2pb,phase=Pending node=None
42.0601,Job,MODIFIED,eval-sanitize-5-r3-042,
42.0619,Event,ADDED,eval-sanitize-5-r3-042.18d3d46d77747eec,reason=SuccessfulCreate count=1 msg=Created pod: eval-sanitize-5-r3-042-cf2pb
42.062,TaskRequest,MODIFIED,eval-sanitize-5-r3-042,phase=Scheduled job=None
42.0643,Job,MODIFIED,eval-sanitize-5-r3-041,
42.0683,Pod,MODIFIED,eval-sanitize-5-r3-042-cf2pb,phase=Pending node=kind-worker3
42.0721,Event,ADDED,eval-sanitize-5-r3-042-cf2pb.18d3d46d782d168f,reason=Scheduled count=None msg=Successfully assigned compute/eval-sanitize-5-r3-042-cf2pb to kind-worker3
42.0779,Pod,MODIFIED,eval-sanitize-5-r3-042-cf2pb,phase=Pending node=kind-worker3
42.0811,Node,MODIFIED,kind-worker3,taints=0
42.0922,Node,MODIFIED,kind-worker3,taints=0
42.3984,Node,MODIFIED,kind-worker,taints=1
42.4132,Node,MODIFIED,kind-worker,taints=1
42.5049,Event,ADDED,eval-sanitize-5-r3-042-cf2pb.18d3d46d91ecb39b,"reason=Pulled count=1 msg=Container image ""busybox:musl"" already present on machine"
42.5235,Event,ADDED,eval-sanitize-5-r3-042-cf2pb.18d3d46d930f8626,reason=Created count=1 msg=Created container: task
42.573,Event,ADDED,eval-sanitize-5-r3-042-cf2pb.18d3d46d95ed064a,reason=Started count=1 msg=Started container task
42.8458,Pod,MODIFIED,eval-sanitize-5-r3-042-cf2pb,phase=Running node=kind-worker3
42.8933,Job,MODIFIED,eval-sanitize-5-r3-028,
42.8958,Job,MODIFIED,eval-sanitize-5-r3-027,
42.9016,Job,MODIFIED,eval-sanitize-5-r3-023,
42.9043,Job,MODIFIED,eval-sanitize-5-r3-028,
42.9084,Job,MODIFIED,eval-sanitize-5-r3-027,
42.9124,Job,MODIFIED,eval-sanitize-5-r3-023,
42.9241,Pod,MODIFIED,eval-sanitize-5-r3-032-wdxmb,phase=Running node=kind-worker2
42.9305,Pod,MODIFIED,eval-sanitize-5-r3-030-9m4cf,phase=Running node=kind-worker2
42.937,Pod,MODIFIED,eval-sanitize-5-r3-029-j9fgd,phase=Running node=kind-worker2
42.9438,Pod,MODIFIED,eval-sanitize-5-r3-026-hghxc,phase=Running node=kind-worker2
43.0043,Pod,MODIFIED,eval-sanitize-5-r3-023-rzr46,phase=Succeeded node=kind-worker5
43.0138,TaskRequest,ADDED,eval-sanitize-5-r3-043,phase=None job=None
43.0176,TaskRequest,MODIFIED,eval-sanitize-5-r3-043,phase=Pending job=None
43.0264,Pod,MODIFIED,eval-sanitize-5-r3-028-6xmxg,phase=Succeeded node=kind-worker5
43.0324,Job,ADDED,eval-sanitize-5-r3-043,
43.0392,Pod,ADDED,eval-sanitize-5-r3-043-2mzj6,phase=Pending node=None
43.0393,TaskRequest,MODIFIED,eval-sanitize-5-r3-043,phase=Scheduled job=None
43.0461,Job,MODIFIED,eval-sanitize-5-r3-043,
43.0467,Event,ADDED,eval-sanitize-5-r3-043.18d3d46db2013d1a,reason=SuccessfulCreate count=1 msg=Created pod: eval-sanitize-5-r3-043-2mzj6
43.0513,Pod,MODIFIED,eval-sanitize-5-r3-043-2mzj6,phase=Pending node=None
43.0526,Event,ADDED,eval-sanitize-5-r3-043-2mzj6.18d3d46db2485dec,"reason=FailedScheduling count=None msg=0/6 nodes are available: 1 c_wall violated: 1 conflicting context pair(s) with node memory, 5 node(s) had untolerated taint(s). no new claims to deallocate, preemption: 0/6 nodes are available: 1 No preemption victims found for incoming pod, 5 Preemption is not helpful for scheduling."
43.0527,TaskRequest,MODIFIED,eval-sanitize-5-r3-043,phase=Scheduled job=None
43.0618,Job,MODIFIED,eval-sanitize-5-r3-042,
43.063,Event,ADDED,eval-sanitize-5-r3-043-2mzj6.18d3d46db303f0b0,"reason=FailedScheduling count=None msg=0/6 nodes are available: 1 c_wall violated: 1 conflicting context pair(s) with node memory, 5 node(s) had untolerated taint(s). no new claims to deallocate, preemption: 0/6 nodes are available: 1 No preemption victims found for incoming pod, 5 Preemption is not helpful for scheduling."
43.0729,Job,MODIFIED,eval-sanitize-5-r3-042,
43.0857,Pod,MODIFIED,eval-sanitize-5-r3-027-9ft5d,phase=Succeeded node=kind-worker5
43.0951,Event,MODIFIED,eval-sanitize-5-r3-043-2mzj6.18d3d46db303f0b0,"reason=FailedScheduling count=None msg=0/6 nodes are available: 1 c_wall violated: 1 conflicting context pair(s) with node memory, 5 node(s) had untolerated taint(s). no new claims to deallocate, preemption: 0/6 nodes are available: 1 No preemption victims found for incoming pod, 5 Preemption is not helpful for scheduling."
43.9029,Job,MODIFIED,eval-sanitize-5-r3-028,
43.9055,Job,MODIFIED,eval-sanitize-5-r3-027,
43.9092,Job,MODIFIED,eval-sanitize-5-r3-023,
43.9123,Pod,MODIFIED,eval-sanitize-5-r3-028-6xmxg,phase=Succeeded node=kind-worker5
43.9143,Job,MODIFIED,eval-sanitize-5-r3-028,
43.9159,Pod,MODIFIED,eval-sanitize-5-r3-027-9ft5d,phase=Succeeded node=kind-worker5
43.917,Job,MODIFIED,eval-sanitize-5-r3-027,
43.9198,Pod,MODIFIED,eval-sanitize-5-r3-023-rzr46,phase=Succeeded node=kind-worker5
43.9208,Job,MODIFIED,eval-sanitize-5-r3-023,
43.9292,Job,MODIFIED,eval-sanitize-5-r3-032,
43.9323,Pod,MODIFIED,eval-sanitize-5-r3-033-zg9jg,phase=Running node=kind-worker2
43.935,Job,MODIFIED,eval-sanitize-5-r3-030,
43.9393,Job,MODIFIED,eval-sanitize-5-r3-032,
43.9413,Job,MODIFIED,eval-sanitize-5-r3-029,
43.945,Job,MODIFIED,eval-sanitize-5-r3-030,
43.9472,Job,MODIFIED,eval-sanitize-5-r3-026,
43.9496,Job,MODIFIED,eval-sanitize-5-r3-029,
43.9552,Job,MODIFIED,eval-sanitize-5-r3-026,
44.0143,TaskRequest,ADDED,eval-sanitize-5-r3-044,phase=None job=None
44.0194,TaskRequest,MODIFIED,eval-sanitize-5-r3-044,phase=Pending job=None
44.0361,Job,ADDED,eval-sanitize-5-r3-044,
44.042,Pod,ADDED,eval-sanitize-5-r3-044-97sfv,phase=Pending node=None
44.0437,TaskRequest,MODIFIED,eval-sanitize-5-r3-044,phase=Scheduled job=None
44.0475,Job,MODIFIED,eval-sanitize-5-r3-043,
44.0485,Event,ADDED,eval-sanitize-5-r3-044.18d3d46dedca8553,reason=SuccessfulCreate count=1 msg=Created pod: eval-sanitize-5-r3-044-97sfv
44.0493,Job,MODIFIED,eval-sanitize-5-r3-044,
44.0521,Pod,MODIFIED,eval-sanitize-5-r3-044-97sfv,phase=Pending node=None
44.0545,Event,ADDED,eval-sanitize-5-r3-044-97sfv.18d3d46dee20d254,"reason=FailedScheduling count=None msg=0/6 nodes are available: 1 c_wall violated: 2 conflicting context pair(s) with node memory, 5 node(s) had untolerated taint(s). no new claims to deallocate, preemption: 0/6 nodes are available: 1 No preemption victims found for incoming pod, 5 Preemption is not helpful for scheduling."
44.0546,TaskRequest,MODIFIED,eval-sanitize-5-r3-044,phase=Scheduled job=None
44.0581,Job,MODIFIED,eval-sanitize-5-r3-044,
44.0589,Job,MODIFIED,eval-sanitize-5-r3-043,
44.0642,Event,ADDED,eval-sanitize-5-r3-044-97sfv.18d3d46deeb02aaf,"reason=FailedScheduling count=None msg=0/6 nodes are available: 1 c_wall violated: 2 conflicting context pair(s) with node memory, 5 node(s) had untolerated taint(s). no new claims to deallocate, preemption: 0/6 nodes are available: 1 No preemption victims found for incoming pod, 5 Preemption is not helpful for scheduling."
44.0674,Job,MODIFIED,eval-sanitize-5-r3-044,
44.1838,Pod,MODIFIED,eval-sanitize-5-r3-026-hghxc,phase=Succeeded node=kind-worker2
44.1965,Event,MODIFIED,eval-sanitize-5-r3-044-97sfv.18d3d46deeb02aaf,"reason=FailedScheduling count=None msg=0/6 nodes are available: 1 c_wall violated: 2 conflicting context pair(s) with node memory, 5 node(s) had untolerated taint(s). no new claims to deallocate, preemption: 0/6 nodes are available: 1 No preemption victims found for incoming pod, 5 Preemption is not helpful for scheduling."
44.2356,Pod,MODIFIED,eval-sanitize-5-r3-030-9m4cf,phase=Succeeded node=kind-worker2
44.2431,Pod,MODIFIED,eval-sanitize-5-r3-032-wdxmb,phase=Succeeded node=kind-worker2
44.2717,Pod,MODIFIED,eval-sanitize-5-r3-029-j9fgd,phase=Succeeded node=kind-worker2
44.6052,Node,MODIFIED,kind-worker3,taints=1
44.6129,Pod,MODIFIED,eval-sanitize-5-r3-043-2mzj6,phase=Pending node=None
44.6248,Pod,MODIFIED,eval-sanitize-5-r3-044-97sfv,phase=Pending node=None
44.6284,Node,MODIFIED,kind-worker3,taints=1
44.9021,Pod,MODIFIED,eval-sanitize-5-r3-034-tqzsg,phase=Running node=kind-worker5
44.9076,Job,MODIFIED,eval-sanitize-5-r3-028,
44.9102,Job,MODIFIED,eval-sanitize-5-r3-027,
44.9125,Job,MODIFIED,eval-sanitize-5-r3-028,
44.9152,Job,MODIFIED,eval-sanitize-5-r3-023,
44.9161,Job,MODIFIED,eval-sanitize-5-r3-027,
44.9185,Event,ADDED,eval-sanitize-5-r3-028.18d3d46e21a08b3f,reason=Completed count=1 msg=Job completed
44.9198,Job,MODIFIED,eval-sanitize-5-r3-023,
44.9235,Job,MODIFIED,eval-sanitize-5-r3-028,
44.9249,Event,ADDED,eval-sanitize-5-r3-027.18d3d46e21c73f2b,reason=Completed count=1 msg=Job completed
44.926,Job,MODIFIED,eval-sanitize-5-r3-027,
44.928,TaskRequest,MODIFIED,eval-sanitize-5-r3-028,phase=Complete job=None
44.9287,Event,ADDED,eval-sanitize-5-r3-023.18d3d46e22025af5,reason=Completed count=1 msg=Job completed
44.9327,Job,MODIFIED,eval-sanitize-5-r3-023,
44.9356,Job,MODIFIED,eval-sanitize-5-r3-032,
44.9379,Job,MODIFIED,eval-sanitize-5-r3-033,
44.9401,Job,MODIFIED,eval-sanitize-5-r3-030,
44.9461,Pod,MODIFIED,eval-sanitize-5-r3-032-wdxmb,phase=Succeeded node=kind-worker2
44.9477,Job,MODIFIED,eval-sanitize-5-r3-029,
44.9505,Pod,MODIFIED,eval-sanitize-5-r3-030-9m4cf,phase=Succeeded node=kind-worker2
44.9523,Job,MODIFIED,eval-sanitize-5-r3-032,
44.9541,Job,MODIFIED,eval-sanitize-5-r3-026,
44.9598,Pod,MODIFIED,eval-sanitize-5-r3-029-j9fgd,phase=Succeeded node=kind-worker2
44.9608,Job,MODIFIED,eval-sanitize-5-r3-030,
44.9612,Event,ADDED,eval-sanitize-5-r3-032.18d3d46e23fb6a80,reason=Completed count=1 msg=Job completed
44.9642,Pod,MODIFIED,eval-sanitize-5-r3-026-hghxc,phase=Succeeded node=kind-worker2
44.9656,Job,MODIFIED,eval-sanitize-5-r3-029,
44.9667,Event,ADDED,eval-sanitize-5-r3-030.18d3d46e245b1203,reason=Completed count=1 msg=Job completed
44.9695,Job,MODIFIED,eval-sanitize-5-r3-026,
44.9707,Event,ADDED,eval-sanitize-5-r3-029.18d3d46e24ca171b,reason=Completed count=1 msg=Job completed
44.9755,Event,ADDED,eval-sanitize-5-r3-026.18d3d46e25042429,reason=Completed count=1 msg=Job completed
45.0064,TaskRequest,ADDED,eval-sanitize-5-r3-045,phase=None job=None
45.0368,TaskRequest,MODIFIED,eval-sanitize-5-r3-027,phase=Complete job=None
45.0662,Job,MODIFIED,eval-sanitize-5-r3-028,
45.1236,TaskRequest,MODIFIED,eval-sanitize-5-r3-023,phase=Complete job=None
45.1283,Job,MODIFIED,eval-sanitize-5-r3-027,
45.135,Job,MODIFIED,eval-sanitize-5-r3-023,
45.1386,Job,MODIFIED,eval-sanitize-5-r3-032,
45.1409,Pod,MODIFIED,eval-sanitize-5-r3-033-zg9jg,phase=Succeeded node=kind-worker2
45.1419,Job,MODIFIED,eval-sanitize-5-r3-033,
45.1429,Job,MODIFIED,eval-sanitize-5-r3-030,
45.1439,Job,MODIFIED,eval-sanitize-5-r3-026,
45.157,TaskRequest,MODIFIED,eval-sanitize-5-r3-045,phase=Pending job=None
45.2265,Job,MODIFIED,eval-sanitize-5-r3-029,
45.2276,Job,ADDED,eval-sanitize-5-r3-045,
45.2328,Pod,ADDED,eval-sanitize-5-r3-045-9klvn,phase=Pending node=None
45.2348,TaskRequest,MODIFIED,eval-sanitize-5-r3-045,phase=Scheduled job=None
45.2375,Job,MODIFIED,eval-sanitize-5-r3-045,
45.2391,Event,ADDED,eval-sanitize-5-r3-045.18d3d46e34b8f0bc,reason=SuccessfulCreate count=1 msg=Created pod: eval-sanitize-5-r3-045-9klvn
45.2393,Event,ADDED,eval-sanitize-5-r3-045-9klvn.18d3d46e34c523f9,"reason=FailedScheduling count=None msg=0/6 nodes are available: 6 node(s) had untolerated taint(s). no new claims to deallocate, preemption: 0/6 nodes are available: 6 Preemption is not helpful for scheduling."
45.2401,Pod,MODIFIED,eval-sanitize-5-r3-045-9klvn,phase=Pending node=None
45.2596,TaskRequest,MODIFIED,eval-sanitize-5-r3-032,phase=Complete job=None
45.2612,TaskRequest,MODIFIED,eval-sanitize-5-r3-045,phase=Scheduled job=None
45.2644,TaskRequest,MODIFIED,eval-sanitize-5-r3-030,phase=Complete job=None
45.2688,Job,MODIFIED,eval-sanitize-5-r3-032,
45.2701,TaskRequest,MODIFIED,eval-sanitize-5-r3-026,phase=Complete job=None
45.2731,TaskRequest,MODIFIED,eval-sanitize-5-r3-029,phase=Complete job=None
45.3229,Job,MODIFIED,eval-sanitize-5-r3-030,
45.3248,Job,MODIFIED,eval-sanitize-5-r3-026,
45.3257,Job,MODIFIED,eval-sanitize-5-r3-029,
45.9086,Job,MODIFIED,eval-sanitize-5-r3-034,
45.9202,Job,MODIFIED,eval-sanitize-5-r3-034,
45.9436,Job,MODIFIED,eval-sanitize-5-r3-033,
45.9518,Pod,MODIFIED,eval-sanitize-5-r3-033-zg9jg,phase=Succeeded node=kind-worker2
45.9529,Job,MODIFIED,eval-sanitize-5-r3-033,
45.9726,Pod,MODIFIED,eval-sanitize-5-r3-034-tqzsg,phase=Succeeded node=kind-worker5
46.0077,TaskRequest,ADDED,eval-sanitize-5-r3-046,phase=None job=None
46.0112,TaskRequest,MODIFIED,eval-sanitize-5-r3-046,phase=Pending job=None
46.0258,Job,ADDED,eval-sanitize-5-r3-046,
46.0291,TaskRequest,MODIFIED,eval-sanitize-5-r3-046,phase=Scheduled job=None
46.0325,Pod,ADDED,eval-sanitize-5-r3-046-bg7dm,phase=Pending node=None
46.0351,Job,MODIFIED,eval-sanitize-5-r3-046,
46.0367,TaskRequest,MODIFIED,eval-sanitize-5-r3-046,phase=Scheduled job=None
46.0376,Pod,MODIFIED,eval-sanitize-5-r3-046-bg7dm,phase=Pending node=None
46.0386,Event,ADDED,eval-sanitize-5-r3-046.18d3d46e645fb1bc,reason=SuccessfulCreate count=1 msg=Created pod: eval-sanitize-5-r3-046-bg7dm
46.0387,Event,ADDED,eval-sanitize-5-r3-046-bg7dm.18d3d46e646b5542,"reason=FailedScheduling count=None msg=0/6 nodes are available: 6 node(s) had untolerated taint(s). no new claims to deallocate, preemption: 0/6 nodes are available: 6 Preemption is not helpful for scheduling."
46.2397,Job,MODIFIED,eval-sanitize-5-r3-045,
46.2483,Job,MODIFIED,eval-sanitize-5-r3-045,
46.8519,Pod,MODIFIED,eval-sanitize-5-r3-025-v6v64,phase=Running node=kind-worker4
46.9056,Pod,MODIFIED,eval-sanitize-5-r3-036-8zwkc,phase=Running node=kind-worker5
46.9132,Job,MODIFIED,eval-sanitize-5-r3-034,
46.9206,Pod,MODIFIED,eval-sanitize-5-r3-034-tqzsg,phase=Succeeded node=kind-worker5
46.9221,Job,MODIFIED,eval-sanitize-5-r3-034,
46.9481,Job,MODIFIED,eval-sanitize-5-r3-033,
46.952,Job,MODIFIED,eval-sanitize-5-r3-033,
46.957,Event,ADDED,eval-sanitize-5-r3-033.18d3d46e9b31aca8,reason=Completed count=1 msg=Job completed
46.9637,Job,MODIFIED,eval-sanitize-5-r3-033,
46.9673,Node,MODIFIED,kind-worker2,taints=1
46.9675,TaskRequest,MODIFIED,eval-sanitize-5-r3-033,phase=Complete job=None
46.9777,Job,MODIFIED,eval-sanitize-5-r3-033,
46.9802,Node,MODIFIED,kind-worker2,taints=1
46.9889,Node,MODIFIED,kind-worker2,taints=0
46.9935,Pod,MODIFIED,eval-sanitize-5-r3-043-2mzj6,phase=Pending node=kind-worker2
46.9959,Pod,MODIFIED,eval-sanitize-5-r3-044-97sfv,phase=Pending node=kind-worker2
46.9994,Event,ADDED,eval-sanitize-5-r3-043-2mzj6.18d3d46e9da5ace9,reason=Scheduled count=None msg=Successfully assigned compute/eval-sanitize-5-r3-043-2mzj6 to kind-worker2
47.0037,Event,ADDED,eval-sanitize-5-r3-044-97sfv.18d3d46e9dcc42cd,reason=Scheduled count=None msg=Successfully assigned compute/eval-sanitize-5-r3-044-97sfv to kind-worker2
47.0049,Pod,MODIFIED,eval-sanitize-5-r3-045-9klvn,phase=Pending node=kind-worker2
47.0069,Event,ADDED,eval-sanitize-5-r3-046-bg7dm.18d3d46e9dedfbdc,"reason=FailedScheduling count=None msg=0/6 nodes are available: 1 c_wall violated: 1 conflicting context pair(s) with node memory, 5 node(s) had untolerated taint(s). no new claims to deallocate, preemption: 0/6 nodes are available: 1 No preemption victims found for incoming pod, 5 Preemption is not helpful for scheduling."
47.0079,Pod,MODIFIED,eval-sanitize-5-r3-046-bg7dm,phase=Pending node=None
47.0093,Node,MODIFIED,kind-worker2,taints=0
47.0105,TaskRequest,ADDED,eval-sanitize-5-r3-047,phase=None job=None
47.0128,Pod,MODIFIED,eval-sanitize-5-r3-043-2mzj6,phase=Pending node=kind-worker2
47.0135,Event,ADDED,eval-sanitize-5-r3-045-9klvn.18d3d46e9e5254ad,reason=Scheduled count=None msg=Successfully assigned compute/eval-sanitize-5-r3-045-9klvn to kind-worker2
47.0153,TaskRequest,MODIFIED,eval-sanitize-5-r3-047,phase=Pending job=None
47.0173,Event,ADDED,eval-sanitize-5-r3-046-bg7dm.18d3d46e9ec13855,"reason=FailedScheduling count=None msg=0/6 nodes are available: 1 c_wall violated: 1 conflicting context pair(s) with node memory, 5 node(s) had untolerated taint(s). no new claims to deallocate, preemption: 0/6 nodes are available: 1 No preemption victims found for incoming pod, 5 Preemption is not helpful for scheduling."
47.0207,Pod,MODIFIED,eval-sanitize-5-r3-044-97sfv,phase=Pending node=kind-worker2
47.0237,Event,MODIFIED,eval-sanitize-5-r3-046-bg7dm.18d3d46e9ec13855,"reason=FailedScheduling count=None msg=0/6 nodes are available: 1 c_wall violated: 1 conflicting context pair(s) with node memory, 5 node(s) had untolerated taint(s). no new claims to deallocate, preemption: 0/6 nodes are available: 1 No preemption victims found for incoming pod, 5 Preemption is not helpful for scheduling."
47.0273,Pod,MODIFIED,eval-sanitize-5-r3-045-9klvn,phase=Pending node=kind-worker2
47.0315,Job,ADDED,eval-sanitize-5-r3-047,
47.0368,Job,MODIFIED,eval-sanitize-5-r3-046,
47.0383,TaskRequest,MODIFIED,eval-sanitize-5-r3-047,phase=Scheduled job=None
47.0394,Pod,ADDED,eval-sanitize-5-r3-047-nb5vw,phase=Pending node=None
47.0405,Job,MODIFIED,eval-sanitize-5-r3-047,
47.0467,Event,ADDED,eval-sanitize-5-r3-047.18d3d46ea060af53,reason=SuccessfulCreate count=1 msg=Created pod: eval-sanitize-5-r3-047-nb5vw
47.0482,Node,MODIFIED,kind-worker2,taints=0
47.0487,TaskRequest,MODIFIED,eval-sanitize-5-r3-047,phase=Scheduled job=None
47.0495,Job,MODIFIED,eval-sanitize-5-r3-046,
47.0605,Node,MODIFIED,kind-worker2,taints=0
47.0621,Pod,MODIFIED,eval-sanitize-5-r3-047-nb5vw,phase=Pending node=None
47.0625,Event,ADDED,eval-sanitize-5-r3-047-nb5vw.18d3d46ea1728052,"reason=FailedScheduling count=None msg=0/6 nodes are available: 1 c_wall violated: 1 conflicting context pair(s) with node memory, 5 node(s) had untolerated taint(s). no new claims to deallocate, preemption: 0/6 nodes are available: 1 No preemption victims found for incoming pod, 5 Preemption is not helpful for scheduling."
47.0715,Node,MODIFIED,kind-worker2,taints=0
47.105,Event,ADDED,eval-sanitize-5-r3-047-nb5vw.18d3d46ea4016692,"reason=FailedScheduling count=None msg=0/6 nodes are available: 1 c_wall violated: 1 conflicting context pair(s) with node memory, 5 node(s) had untolerated taint(s). no new claims to deallocate, preemption: 0/6 nodes are available: 1 No preemption victims found for incoming pod, 5 Preemption is not helpful for scheduling."
47.1107,Event,MODIFIED,eval-sanitize-5-r3-047-nb5vw.18d3d46ea4016692,"reason=FailedScheduling count=None msg=0/6 nodes are available: 1 c_wall violated: 1 conflicting context pair(s) with node memory, 5 node(s) had untolerated taint(s). no new claims to deallocate, preemption: 0/6 nodes are available: 1 No preemption victims found for incoming pod, 5 Preemption is not helpful for scheduling."
47.4232,Event,ADDED,eval-sanitize-5-r3-043-2mzj6.18d3d46eb6e88535,"reason=Pulled count=1 msg=Container image ""busybox:musl"" already present on machine"
47.4329,Event,ADDED,eval-sanitize-5-r3-044-97sfv.18d3d46eb7952957,"reason=Pulled count=1 msg=Container image ""busybox:musl"" already present on machine"
47.4371,Event,ADDED,eval-sanitize-5-r3-045-9klvn.18d3d46eb7d0f1c4,"reason=Pulled count=1 msg=Container image ""busybox:musl"" already present on machine"
47.4492,Event,ADDED,eval-sanitize-5-r3-043-2mzj6.18d3d46eb886e92d,reason=Created count=1 msg=Created container: task
47.4651,Event,ADDED,eval-sanitize-5-r3-044-97sfv.18d3d46eb989fa87,reason=Created count=1 msg=Created container: task
47.4698,Event,ADDED,eval-sanitize-5-r3-045-9klvn.18d3d46eb9e1d962,reason=Created count=1 msg=Created container: task
47.5404,Event,ADDED,eval-sanitize-5-r3-043-2mzj6.18d3d46ebdf9c816,reason=Started count=1 msg=Started container task
47.5511,Event,ADDED,eval-sanitize-5-r3-044-97sfv.18d3d46ebe99949c,reason=Started count=1 msg=Started container task
47.5571,Event,ADDED,eval-sanitize-5-r3-045-9klvn.18d3d46ebe999b6c,reason=Started count=1 msg=Started container task
47.8558,Pod,MODIFIED,eval-sanitize-5-r3-035-9gzvj,phase=Running node=kind-worker4
47.8571,Job,MODIFIED,eval-sanitize-5-r3-025,
47.8652,Pod,MODIFIED,eval-sanitize-5-r3-037-gnpkz,phase=Running node=kind-worker4
47.8669,Job,MODIFIED,eval-sanitize-5-r3-025,
47.9123,Job,MODIFIED,eval-sanitize-5-r3-036,
47.9177,Job,MODIFIED,eval-sanitize-5-r3-034,
47.9224,Job,MODIFIED,eval-sanitize-5-r3-036,
47.9243,Job,MODIFIED,eval-sanitize-5-r3-034,
47.9272,Event,ADDED,eval-sanitize-5-r3-034.18d3d46ed5257188,reason=Completed count=1 msg=Job completed
47.9348,Job,MODIFIED,eval-sanitize-5-r3-034,
47.9389,TaskRequest,MODIFIED,eval-sanitize-5-r3-034,phase=Complete job=None
47.9493,Job,MODIFIED,eval-sanitize-5-r3-034,
47.9517,Pod,MODIFIED,eval-sanitize-5-r3-043-2mzj6,phase=Running node=kind-worker2
47.9585,Pod,MODIFIED,eval-sanitize-5-r3-044-97sfv,phase=Running node=kind-worker2
47.9676,Pod,MODIFIED,eval-sanitize-5-r3-045-9klvn,phase=Running node=kind-worker2
47.9997,Job,MODIFIED,eval-sanitize-5-r3-043,
48.0015,Job,MODIFIED,eval-sanitize-5-r3-044,
48.0085,TaskRequest,ADDED,eval-sanitize-5-r3-048,phase=None job=None
48.0111,Job,MODIFIED,eval-sanitize-5-r3-043,
48.012,Job,MODIFIED,eval-sanitize-5-r3-044,
48.0147,Pod,MODIFIED,eval-sanitize-5-r3-025-v6v64,phase=Succeeded node=kind-worker4
48.0148,TaskRequest,MODIFIED,eval-sanitize-5-r3-048,phase=Pending job=None
48.0291,Job,ADDED,eval-sanitize-5-r3-048,
48.0335,TaskRequest,MODIFIED,eval-sanitize-5-r3-048,phase=Scheduled job=None
48.0366,Pod,ADDED,eval-sanitize-5-r3-048-tc9lm,phase=Pending node=None
48.0391,Job,MODIFIED,eval-sanitize-5-r3-048,
48.0412,Event,ADDED,eval-sanitize-5-r3-048.18d3d46edbd6bb05,reason=SuccessfulCreate count=1 msg=Created pod: eval-sanitize-5-r3-048-tc9lm
48.0414,TaskRequest,MODIFIED,eval-sanitize-5-r3-048,phase=Scheduled job=None
48.0439,Job,MODIFIED,eval-sanitize-5-r3-047,
48.0549,Job,MODIFIED,eval-sanitize-5-r3-047,
48.0605,Pod,MODIFIED,eval-sanitize-5-r3-048-tc9lm,phase=Pending node=None
48.0608,Event,ADDED,eval-sanitize-5-r3-048-tc9lm.18d3d46edcf751f3,"reason=FailedScheduling count=None msg=0/6 nodes are available: 1 c_wall violated: 1 conflicting context pair(s) with node memory, 5 node(s) had untolerated taint(s). no new claims to deallocate, preemption: 0/6 nodes are available: 1 No preemption victims found for incoming pod, 5 Preemption is not helpful for scheduling."
48.069,Event,ADDED,eval-sanitize-5-r3-048-tc9lm.18d3d46edd73f520,"reason=FailedScheduling count=None msg=0/6 nodes are available: 1 c_wall violated: 1 conflicting context pair(s) with node memory, 5 node(s) had untolerated taint(s). no new claims to deallocate, preemption: 0/6 nodes are available: 1 No preemption victims found for incoming pod, 5 Preemption is not helpful for scheduling."
48.1079,Pod,MODIFIED,eval-sanitize-5-r3-036-8zwkc,phase=Succeeded node=kind-worker5
48.1203,Event,MODIFIED,eval-sanitize-5-r3-048-tc9lm.18d3d46edd73f520,"reason=FailedScheduling count=None msg=0/6 nodes are available: 1 c_wall violated: 1 conflicting context pair(s) with node memory, 5 node(s) had untolerated taint(s). no new claims to deallocate, preemption: 0/6 nodes are available: 1 No preemption victims found for incoming pod, 5 Preemption is not helpful for scheduling."
48.5043,Pod,MODIFIED,eval-sanitize-5-r3-031-brmm4,phase=Running node=kind-worker
48.8634,Job,MODIFIED,eval-sanitize-5-r3-035,
48.8653,Job,MODIFIED,eval-sanitize-5-r3-025,
48.8703,Job,MODIFIED,eval-sanitize-5-r3-037,
48.8727,Job,MODIFIED,eval-sanitize-5-r3-035,
48.8778,Job,MODIFIED,eval-sanitize-5-r3-025,
48.8793,Pod,MODIFIED,eval-sanitize-5-r3-025-v6v64,phase=Succeeded node=kind-worker4
48.8814,Job,MODIFIED,eval-sanitize-5-r3-037,
48.9149,Event,MODIFIED,eval-sanitize-5-r3-031-brmm4.18d3d46c31876237,"reason=FailedScheduling count=None msg=0/6 nodes are available: 1 c_wall violated: 1 conflicting context pair(s) with node memory, 5 node(s) had untolerated taint(s). no new claims to deallocate, preemption: 0/6 nodes are available: 1 No preemption victims found for incoming pod, 5 Preemption is not helpful for scheduling."
48.918,Job,MODIFIED,eval-sanitize-5-r3-036,
48.926,Pod,MODIFIED,eval-sanitize-5-r3-036-8zwkc,phase=Succeeded node=kind-worker5
48.9272,Job,MODIFIED,eval-sanitize-5-r3-036,
48.9751,Job,MODIFIED,eval-sanitize-5-r3-045,
48.9843,Job,MODIFIED,eval-sanitize-5-r3-045,
49.0228,TaskRequest,ADDED,eval-sanitize-5-r3-049,phase=None job=None
49.0264,TaskRequest,MODIFIED,eval-sanitize-5-r3-049,phase=Pending job=None
49.042,Job,ADDED,eval-sanitize-5-r3-049,
49.0429,Job,MODIFIED,eval-sanitize-5-r3-048,
49.0479,TaskRequest,MODIFIED,eval-sanitize-5-r3-049,phase=Scheduled job=None
49.0497,Pod,ADDED,eval-sanitize-5-r3-049-t2ff5,phase=Pending node=None
49.052,Job,MODIFIED,eval-sanitize-5-r3-049,
49.0545,Event,ADDED,eval-sanitize-5-r3-049.18d3d46f1838f8d6,reason=SuccessfulCreate count=1 msg=Created pod: eval-sanitize-5-r3-049-t2ff5
49.0556,TaskRequest,MODIFIED,eval-sanitize-5-r3-049,phase=Scheduled job=None
49.0587,Job,MODIFIED,eval-sanitize-5-r3-048,
49.0603,Event,ADDED,eval-sanitize-5-r3-049-t2ff5.18d3d46f187c1767,"reason=FailedScheduling count=None msg=0/6 nodes are available: 1 c_wall violated: 2 conflicting context pair(s) with node memory, 5 node(s) had untolerated taint(s). no new claims to deallocate, preemption: 0/6 nodes are available: 1 No preemption victims found for incoming pod, 5 Preemption is not helpful for scheduling."
49.0613,Pod,MODIFIED,eval-sanitize-5-r3-049-t2ff5,phase=Pending node=None
49.068,Event,ADDED,eval-sanitize-5-r3-049-t2ff5.18d3d46f19190570,"reason=FailedScheduling count=None msg=0/6 nodes are available: 1 c_wall violated: 2 conflicting context pair(s) with node memory, 5 node(s) had untolerated taint(s). no new claims to deallocate, preemption: 0/6 nodes are available: 1 No preemption victims found for incoming pod, 5 Preemption is not helpful for scheduling."
49.127,Pod,MODIFIED,eval-sanitize-5-r3-035-9gzvj,phase=Succeeded node=kind-worker4
49.1441,Event,MODIFIED,eval-sanitize-5-r3-049-t2ff5.18d3d46f19190570,"reason=FailedScheduling count=None msg=0/6 nodes are available: 1 c_wall violated: 2 conflicting context pair(s) with node memory, 5 node(s) had untolerated taint(s). no new claims to deallocate, preemption: 0/6 nodes are available: 1 No preemption victims found for incoming pod, 5 Preemption is not helpful for scheduling."
49.165,Pod,MODIFIED,eval-sanitize-5-r3-037-gnpkz,phase=Succeeded node=kind-worker4
49.506,Pod,MODIFIED,eval-sanitize-5-r3-038-szrth,phase=Running node=kind-worker
49.5092,Job,MODIFIED,eval-sanitize-5-r3-031,
49.5204,Job,MODIFIED,eval-sanitize-5-r3-031,
49.6099,Pod,MODIFIED,eval-sanitize-5-r3-031-brmm4,phase=Succeeded node=kind-worker
49.8708,Job,MODIFIED,eval-sanitize-5-r3-035,
49.8728,Job,MODIFIED,eval-sanitize-5-r3-025,
49.8761,Job,MODIFIED,eval-sanitize-5-r3-037,
49.8787,Job,MODIFIED,eval-sanitize-5-r3-025,
49.8814,Pod,MODIFIED,eval-sanitize-5-r3-035-9gzvj,phase=Succeeded node=kind-worker4
49.8821,Job,MODIFIED,eval-sanitize-5-r3-035,
49.8839,Event,ADDED,eval-sanitize-5-r3-025.18d3d46f49a5db84,reason=Completed count=1 msg=Job completed
49.8852,Pod,MODIFIED,eval-sanitize-5-r3-037-gnpkz,phase=Succeeded node=kind-worker4
49.8865,Job,MODIFIED,eval-sanitize-5-r3-037,
49.8884,Job,MODIFIED,eval-sanitize-5-r3-025,
49.8934,TaskRequest,MODIFIED,eval-sanitize-5-r3-025,phase=Complete job=None
49.9022,Job,MODIFIED,eval-sanitize-5-r3-025,
49.9261,Job,MODIFIED,eval-sanitize-5-r3-036,
49.9297,Job,MODIFIED,eval-sanitize-5-r3-036,
49.933,Event,ADDED,eval-sanitize-5-r3-036.18d3d46f4cabb94f,reason=Completed count=1 msg=Job completed
49.942,Job,MODIFIED,eval-sanitize-5-r3-036,
49.9469,TaskRequest,MODIFIED,eval-sanitize-5-r3-036,phase=Complete job=None
49.9562,Job,MODIFIED,eval-sanitize-5-r3-036,
50.0069,TaskRequest,ADDED,eval-sanitize-5-r3-050,phase=None job=None
50.0134,TaskRequest,MODIFIED,eval-sanitize-5-r3-050,phase=Pending job=None
50.0266,Job,ADDED,eval-sanitize-5-r3-050,
50.0333,Pod,ADDED,eval-sanitize-5-r3-050-l6mlt,phase=Pending node=None
50.0343,TaskRequest,MODIFIED,eval-sanitize-5-r3-050,phase=Scheduled job=None
50.0371,Job,MODIFIED,eval-sanitize-5-r3-050,
50.0391,Event,ADDED,eval-sanitize-5-r3-050.18d3d46f52d8ea3c,reason=SuccessfulCreate count=1 msg=Created pod: eval-sanitize-5-r3-050-l6mlt
50.042,Pod,MODIFIED,eval-sanitize-5-r3-050-l6mlt,phase=Pending node=None
50.0432,Event,ADDED,eval-sanitize-5-r3-050-l6mlt.18d3d46f53120ce1,"reason=FailedScheduling count=None msg=0/6 nodes are available: 1 c_wall violated: 1 conflicting context pair(s) with node memory, 5 node(s) had untolerated taint(s). no new claims to deallocate, preemption: 0/6 nodes are available: 1 No preemption victims found for incoming pod, 5 Preemption is not helpful for scheduling."
50.0433,TaskRequest,MODIFIED,eval-sanitize-5-r3-050,phase=Scheduled job=None
50.0493,Event,ADDED,eval-sanitize-5-r3-050-l6mlt.18d3d46f539aeff4,"reason=FailedScheduling count=None msg=0/6 nodes are available: 1 c_wall violated: 1 conflicting context pair(s) with node memory, 5 node(s) had untolerated taint(s). no new claims to deallocate, preemption: 0/6 nodes are available: 1 No preemption victims found for incoming pod, 5 Preemption is not helpful for scheduling."
50.0544,Job,MODIFIED,eval-sanitize-5-r3-049,
50.0631,Job,MODIFIED,eval-sanitize-5-r3-049,
50.5141,Pod,MODIFIED,eval-sanitize-5-r3-039-l8s8w,phase=Running node=kind-worker
50.5155,Job,MODIFIED,eval-sanitize-5-r3-038,
50.5164,Job,MODIFIED,eval-sanitize-5-r3-031,
50.5275,Pod,MODIFIED,eval-sanitize-5-r3-031-brmm4,phase=Succeeded node=kind-worker
50.5326,Job,MODIFIED,eval-sanitize-5-r3-038,
50.5337,Job,MODIFIED,eval-sanitize-5-r3-031,
50.5379,Event,MODIFIED,eval-sanitize-5-r3-050-l6mlt.18d3d46f539aeff4,"reason=FailedScheduling count=None msg=0/6 nodes are available: 1 c_wall violated: 1 conflicting context pair(s) with node memory, 5 node(s) had untolerated taint(s). no new claims to deallocate, preemption: 0/6 nodes are available: 1 No preemption victims found for incoming pod, 5 Preemption is not helpful for scheduling."
50.6076,Pod,MODIFIED,eval-sanitize-5-r3-038-szrth,phase=Succeeded node=kind-worker
50.8608,Pod,MODIFIED,eval-sanitize-5-r3-040-znsfm,phase=Running node=kind-worker3
50.8774,Job,MODIFIED,eval-sanitize-5-r3-035,
50.8826,Job,MODIFIED,eval-sanitize-5-r3-037,
50.8852,Job,MODIFIED,eval-sanitize-5-r3-035,
50.8873,Job,MODIFIED,eval-sanitize-5-r3-037,
50.8881,Event,ADDED,eval-sanitize-5-r3-035.18d3d46f85a00f21,reason=Completed count=1 msg=Job completed
50.893,Event,ADDED,eval-sanitize-5-r3-037.18d3d46f85c3c284,reason=Completed count=1 msg=Job completed
50.894,Job,MODIFIED,eval-sanitize-5-r3-035,
50.8979,Job,MODIFIED,eval-sanitize-5-r3-037,
50.898,TaskRequest,MODIFIED,eval-sanitize-5-r3-035,phase=Complete job=None
50.9042,TaskRequest,MODIFIED,eval-sanitize-5-r3-037,phase=Complete job=None
50.9095,Job,MODIFIED,eval-sanitize-5-r3-035,
50.9135,Job,MODIFIED,eval-sanitize-5-r3-037,
51.0084,TaskRequest,ADDED,eval-sanitize-5-r3-051,phase=None job=None
51.0118,TaskRequest,MODIFIED,eval-sanitize-5-r3-051,phase=Pending job=None
51.027,Job,ADDED,eval-sanitize-5-r3-051,
51.0348,Pod,ADDED,eval-sanitize-5-r3-051-dsht7,phase=Pending node=None
51.0417,TaskRequest,MODIFIED,eval-sanitize-5-r3-051,phase=Scheduled job=None
51.0428,Job,MODIFIED,eval-sanitize-5-r3-051,
51.0452,Event,ADDED,eval-sanitize-5-r3-051.18d3d46f8e8a8cac,reason=SuccessfulCreate count=1 msg=Created pod: eval-sanitize-5-r3-051-dsht7
51.0457,Event,ADDED,eval-sanitize-5-r3-051-dsht7.18d3d46f8eca1aef,"reason=FailedScheduling count=None msg=0/6 nodes are available: 1 c_wall violated: 2 conflicting context pair(s) with node memory, 5 node(s) had untolerated taint(s). no new claims to deallocate, preemption: 0/6 nodes are available: 1 No preemption victims found for incoming pod, 5 Preemption is not helpful for scheduling."
51.0468,Pod,MODIFIED,eval-sanitize-5-r3-051-dsht7,phase=Pending node=None
51.0476,Job,MODIFIED,eval-sanitize-5-r3-050,
51.0506,TaskRequest,MODIFIED,eval-sanitize-5-r3-051,phase=Scheduled job=None
51.0547,Job,MODIFIED,eval-sanitize-5-r3-050,
51.055,Event,ADDED,eval-sanitize-5-r3-051-dsht7.18d3d46f8f771701,"reason=FailedScheduling count=None msg=0/6 nodes are available: 1 c_wall violated: 2 conflicting context pair(s) with node memory, 5 node(s) had untolerated taint(s). no new claims to deallocate, preemption: 0/6 nodes are available: 1 No preemption victims found for incoming pod, 5 Preemption is not helpful for scheduling."
51.5204,Job,MODIFIED,eval-sanitize-5-r3-039,
51.5228,Job,MODIFIED,eval-sanitize-5-r3-038,
51.5239,Job,MODIFIED,eval-sanitize-5-r3-031,
51.5293,Job,MODIFIED,eval-sanitize-5-r3-031,
51.533,Job,MODIFIED,eval-sanitize-5-r3-039,
51.5346,Pod,MODIFIED,eval-sanitize-5-r3-038-szrth,phase=Succeeded node=kind-worker
51.535,Event,ADDED,eval-sanitize-5-r3-031.18d3d46fac041af2,reason=Completed count=1 msg=Job completed
51.5359,Job,MODIFIED,eval-sanitize-5-r3-038,
51.5412,Job,MODIFIED,eval-sanitize-5-r3-031,
51.5462,TaskRequest,MODIFIED,eval-sanitize-5-r3-031,phase=Complete job=None
51.5554,Job,MODIFIED,eval-sanitize-5-r3-031,
51.6852,Pod,MODIFIED,eval-sanitize-5-r3-039-l8s8w,phase=Succeeded node=kind-worker
51.7092,Event,MODIFIED,eval-sanitize-5-r3-051-dsht7.18d3d46f8f771701,"reason=FailedScheduling count=None msg=0/6 nodes are available: 1 c_wall violated: 2 conflicting context pair(s) with node memory, 5 node(s) had untolerated taint(s). no new claims to deallocate, preemption: 0/6 nodes are available: 1 No preemption victims found for incoming pod, 5 Preemption is not helpful for scheduling."
51.7712,Node,MODIFIED,kind-worker5,taints=1
51.7854,Node,MODIFIED,kind-worker5,taints=0
51.7943,Node,MODIFIED,kind-worker5,taints=0
51.7968,Pod,MODIFIED,eval-sanitize-5-r3-051-dsht7,phase=Pending node=kind-worker5
51.8087,Event,ADDED,eval-sanitize-5-r3-051-dsht7.18d3d46fbbe3bad8,reason=Scheduled count=None msg=Successfully assigned compute/eval-sanitize-5-r3-051-dsht7 to kind-worker5
51.8103,Pod,MODIFIED,eval-sanitize-5-r3-046-bg7dm,phase=Pending node=kind-worker5
51.817,Pod,MODIFIED,eval-sanitize-5-r3-051-dsht7,phase=Pending node=kind-worker5
51.8173,Event,ADDED,eval-sanitize-5-r3-046-bg7dm.18d3d46fbca83680,reason=Scheduled count=None msg=Successfully assigned compute/eval-sanitize-5-r3-046-bg7dm to kind-worker5
51.8189,Node,MODIFIED,kind-worker5,taints=0
51.8218,Pod,MODIFIED,eval-sanitize-5-r3-046-bg7dm,phase=Pending node=kind-worker5
51.8596,Node,MODIFIED,kind-worker5,taints=0
51.8606,Pod,MODIFIED,eval-sanitize-5-r3-047-nb5vw,phase=Pending node=None
51.8658,Job,MODIFIED,eval-sanitize-5-r3-040,
51.8693,Pod,MODIFIED,eval-sanitize-5-r3-041-tmt29,phase=Running node=kind-worker4
51.872,Node,MODIFIED,kind-worker5,taints=0
51.873,Pod,MODIFIED,eval-sanitize-5-r3-048-tc9lm,phase=Pending node=None
51.8766,Job,MODIFIED,eval-sanitize-5-r3-040,
51.8836,Node,MODIFIED,kind-worker5,taints=0
51.9602,Pod,MODIFIED,eval-sanitize-5-r3-049-t2ff5,phase=Pending node=kind-worker5
51.9623,Pod,MODIFIED,eval-sanitize-5-r3-050-l6mlt,phase=Pending node=None
51.9632,Event,ADDED,eval-sanitize-5-r3-049-t2ff5.18d3d46fc5ad04b5,reason=Scheduled count=None msg=Successfully assigned compute/eval-sanitize-5-r3-049-t2ff5 to kind-worker5
51.9713,Node,MODIFIED,kind-worker5,taints=0
51.9737,Pod,MODIFIED,eval-sanitize-5-r3-049-t2ff5,phase=Pending node=kind-worker5
51.974,Event,ADDED,eval-sanitize-5-r3-047-nb5vw.18d3d46fc6260487,"reason=FailedScheduling count=None msg=0/6 nodes are available: 2 c_wall violated: 1 conflicting context pair(s) with node memory, 4 node(s) had untolerated taint(s). no new claims to deallocate, preemption: 0/6 nodes are available: 2 No preemption victims found for incoming pod, 4 Preemption is not helpful for scheduling."
51.979,Pod,MODIFIED,eval-sanitize-5-r3-048-tc9lm,phase=Pending node=None
51.9816,Event,ADDED,eval-sanitize-5-r3-048-tc9lm.18d3d46fc68a7f6d,"reason=FailedScheduling count=None msg=0/6 nodes are available: 1 c_wall violated: 1 conflicting context pair(s) with node memory, 1 c_wall violated: 2 conflicting context pair(s) with node memory, 4 node(s) had untolerated taint(s). no new claims to deallocate, preemption: 0/6 nodes are available: 2 No preemption victims found for incoming pod, 4 Preemption is not helpful for scheduling."
51.9832,Node,MODIFIED,kind-worker5,taints=0
52.005,Pod,MODIFIED,eval-sanitize-5-r3-040-znsfm,phase=Succeeded node=kind-worker3
52.0067,TaskRequest,ADDED,eval-sanitize-5-r3-052,phase=None job=None
52.0123,TaskRequest,MODIFIED,eval-sanitize-5-r3-052,phase=Pending job=None
52.0259,Job,ADDED,eval-sanitize-5-r3-052,
52.0323,Pod,ADDED,eval-sanitize-5-r3-052-gndzv,phase=Pending node=None
52.0325,TaskRequest,MODIFIED,eval-sanitize-5-r3-052,phase=Scheduled job=None
52.0356,Job,MODIFIED,eval-sanitize-5-r3-052,
52.0371,Event,ADDED,eval-sanitize-5-r3-052.18d3d46fca029cca,reason=SuccessfulCreate count=1 msg=Created pod: eval-sanitize-5-r3-052-gndzv
52.0397,Job,MODIFIED,eval-sanitize-5-r3-051,
52.0399,TaskRequest,MODIFIED,eval-sanitize-5-r3-052,phase=Scheduled job=None
52.0494,Job,MODIFIED,eval-sanitize-5-r3-051,
52.0617,Event,ADDED,eval-sanitize-5-r3-050-l6mlt.18d3d46fcb5d7648,"reason=FailedScheduling count=None msg=0/6 nodes are available: 1 c_wall violated: 1 conflicting context pair(s) with node memory, 1 c_wall violated: 2 conflicting context pair(s) with node memory, 4 node(s) had untolerated taint(s). no new claims to deallocate, preemption: 0/6 nodes are available: 2 No preemption victims found for incoming pod, 4 Preemption is not helpful for scheduling."
52.0662,Node,MODIFIED,kind-worker2,taints=1
52.0679,Pod,MODIFIED,eval-sanitize-5-r3-052-gndzv,phase=Pending node=kind-worker5
52.0713,Event,ADDED,eval-sanitize-5-r3-052-gndzv.18d3d46fcc1b5f2e,reason=Scheduled count=None msg=Successfully assigned compute/eval-sanitize-5-r3-052-gndzv to kind-worker5
52.0722,Event,MODIFIED,eval-sanitize-5-r3-047-nb5vw.18d3d46fc6260487,"reason=FailedScheduling count=None msg=0/6 nodes are available: 2 c_wall violated: 1 conflicting context pair(s) with node memory, 4 node(s) had untolerated taint(s). no new claims to deallocate, preemption: 0/6 nodes are available: 2 No preemption victims found for incoming pod, 4 Preemption is not helpful for scheduling."
52.078,Pod,MODIFIED,eval-sanitize-5-r3-052-gndzv,phase=Pending node=kind-worker5
52.0803,Node,MODIFIED,kind-worker2,taints=1
52.1583,Pod,MODIFIED,eval-sanitize-5-r3-048-tc9lm,phase=Pending node=None
52.1588,Event,ADDED,eval-sanitize-5-r3-048-tc9lm.18d3d46fd1204f76,"reason=FailedScheduling count=None msg=0/6 nodes are available: 1 c_wall violated: 2 conflicting context pair(s) with node memory, 5 node(s) had untolerated taint(s). no new claims to deallocate, preemption: 0/6 nodes are available: 1 No preemption victims found for incoming pod, 5 Preemption is not helpful for scheduling."
52.1682,Pod,MODIFIED,eval-sanitize-5-r3-050-l6mlt,phase=Pending node=None
52.1714,Event,MODIFIED,eval-sanitize-5-r3-050-l6mlt.18d3d46fcb5d7648,"reason=FailedScheduling count=None msg=0/6 nodes are available: 1 c_wall violated: 1 conflicting context pair(s) with node memory, 1 c_wall violated: 2 conflicting context pair(s) with node memory, 4 node(s) had untolerated taint(s). no new claims to deallocate, preemption: 0/6 nodes are available: 2 No preemption victims found for incoming pod, 4 Preemption is not helpful for scheduling."
52.1771,Pod,MODIFIED,eval-sanitize-5-r3-047-nb5vw,phase=Pending node=None
52.1841,Event,ADDED,eval-sanitize-5-r3-048-tc9lm.18d3d46fd2d58a3b,"reason=FailedScheduling count=None msg=0/6 nodes are available: 1 c_wall violated: 2 conflicting context pair(s) with node memory, 5 node(s) had untolerated taint(s). no new claims to deallocate, preemption: 0/6 nodes are available: 1 No preemption victims found for incoming pod, 5 Preemption is not helpful for scheduling."
52.1862,Event,ADDED,eval-sanitize-5-r3-050-l6mlt.18d3d46fd2ff004d,"reason=FailedScheduling count=None msg=0/6 nodes are available: 1 c_wall violated: 2 conflicting context pair(s) with node memory, 5 node(s) had untolerated taint(s). no new claims to deallocate, preemption: 0/6 nodes are available: 1 No preemption victims found for incoming pod, 5 Preemption is not helpful for scheduling."
52.1886,Event,ADDED,eval-sanitize-5-r3-047-nb5vw.18d3d46fd32c6cc1,"reason=FailedScheduling count=None msg=0/6 nodes are available: 1 c_wall violated: 1 conflicting context pair(s) with node memory, 5 node(s) had untolerated taint(s). no new claims to deallocate, preemption: 0/6 nodes are available: 1 No preemption victims found for incoming pod, 5 Preemption is not helpful for scheduling."
52.2401,Event,ADDED,eval-sanitize-5-r3-046-bg7dm.18d3d46fd5f318aa,"reason=Pulled count=1 msg=Container image ""busybox:musl"" already present on machine"
52.2441,Event,ADDED,eval-sanitize-5-r3-051-dsht7.18d3d46fd64c20bc,"reason=Pulled count=1 msg=Container image ""busybox:musl"" already present on machine"
52.2614,Event,ADDED,eval-sanitize-5-r3-046-bg7dm.18d3d46fd76cfd05,reason=Created count=1 msg=Created container: task
52.268,Event,ADDED,eval-sanitize-5-r3-051-dsht7.18d3d46fd7bcc076,reason=Created count=1 msg=Created container: task
52.3452,Event,ADDED,eval-sanitize-5-r3-046-bg7dm.18d3d46fdc4ff9cc,reason=Started count=1 msg=Started container task
52.3491,Event,ADDED,eval-sanitize-5-r3-051-dsht7.18d3d46fdc82230a,reason=Started count=1 msg=Started container task
52.3897,Event,ADDED,eval-sanitize-5-r3-049-t2ff5.18d3d46fdf0e8447,"reason=Pulled count=1 msg=Container image ""busybox:musl"" already present on machine"
52.4162,Event,ADDED,eval-sanitize-5-r3-049-t2ff5.18d3d46fe02ca732,reason=Created count=1 msg=Created container: task
52.4463,Event,ADDED,eval-sanitize-5-r3-049-t2ff5.18d3d46fe25e7629,reason=Started count=1 msg=Started container task
52.4691,Event,ADDED,eval-sanitize-5-r3-052-gndzv.18d3d46fe3cd9847,"reason=Pulled count=1 msg=Container image ""busybox:musl"" already present on machine"
52.4863,Event,ADDED,eval-sanitize-5-r3-052-gndzv.18d3d46fe4debbc8,reason=Created count=1 msg=Created container: task
52.5268,Job,MODIFIED,eval-sanitize-5-r3-039,
52.5288,Job,MODIFIED,eval-sanitize-5-r3-038,
52.5343,Job,MODIFIED,eval-sanitize-5-r3-038,
52.5369,Pod,MODIFIED,eval-sanitize-5-r3-039-l8s8w,phase=Succeeded node=kind-worker
52.5382,Job,MODIFIED,eval-sanitize-5-r3-039,
52.5386,Event,ADDED,eval-sanitize-5-r3-038.18d3d46fe7ea8e76,reason=Completed count=1 msg=Job completed
52.5443,Job,MODIFIED,eval-sanitize-5-r3-038,
52.5489,TaskRequest,MODIFIED,eval-sanitize-5-r3-038,phase=Complete job=None
52.5503,Event,ADDED,eval-sanitize-5-r3-052-gndzv.18d3d46fe8b471c4,reason=Started count=1 msg=Started container task
52.5575,Job,MODIFIED,eval-sanitize-5-r3-038,
52.7602,Node,MODIFIED,kind-worker,taints=1
52.7685,Event,MODIFIED,eval-sanitize-5-r3-048-tc9lm.18d3d46fd2d58a3b,"reason=FailedScheduling count=None msg=0/6 nodes are available: 1 c_wall violated: 2 conflicting context pair(s) with node memory, 5 node(s) had untolerated taint(s). no new claims to deallocate, preemption: 0/6 nodes are available: 1 No preemption victims found for incoming pod, 5 Preemption is not helpful for scheduling."
52.7732,Node,MODIFIED,kind-worker,taints=0
52.7742,Event,MODIFIED,eval-sanitize-5-r3-050-l6mlt.18d3d46fd2ff004d,"reason=FailedScheduling count=None msg=0/6 nodes are available: 1 c_wall violated: 2 conflicting context pair(s) with node memory, 5 node(s) had untolerated taint(s). no new claims to deallocate, preemption: 0/6 nodes are available: 1 No preemption victims found for incoming pod, 5 Preemption is not helpful for scheduling."
52.7751,Event,MODIFIED,eval-sanitize-5-r3-047-nb5vw.18d3d46fd32c6cc1,"reason=FailedScheduling count=None msg=0/6 nodes are available: 1 c_wall violated: 1 conflicting context pair(s) with node memory, 5 node(s) had untolerated taint(s). no new claims to deallocate, preemption: 0/6 nodes are available: 1 No preemption victims found for incoming pod, 5 Preemption is not helpful for scheduling."
52.7818,Pod,MODIFIED,eval-sanitize-5-r3-048-tc9lm,phase=Pending node=kind-worker
52.7841,Node,MODIFIED,kind-worker,taints=0
52.7874,Pod,MODIFIED,eval-sanitize-5-r3-050-l6mlt,phase=Pending node=kind-worker
52.7878,Event,ADDED,eval-sanitize-5-r3-048-tc9lm.18d3d46ff6a732d1,reason=Scheduled count=None msg=Successfully assigned compute/eval-sanitize-5-r3-048-tc9lm to kind-worker
52.7925,Pod,MODIFIED,eval-sanitize-5-r3-047-nb5vw,phase=Pending node=None
52.7945,Event,ADDED,eval-sanitize-5-r3-050-l6mlt.18d3d46ff6ff5941,reason=Scheduled count=None msg=Successfully assigned compute/eval-sanitize-5-r3-050-l6mlt to kind-worker
52.7959,Pod,MODIFIED,eval-sanitize-5-r3-048-tc9lm,phase=Pending node=kind-worker
52.7979,Node,MODIFIED,kind-worker,taints=0
52.802,Pod,MODIFIED,eval-sanitize-5-r3-050-l6mlt,phase=Pending node=kind-worker
52.8092,Node,MODIFIED,kind-worker,taints=0
52.8185,Node,MODIFIED,kind-worker,taints=0
52.8648,Pod,MODIFIED,eval-sanitize-5-r3-042-cf2pb,phase=Running node=kind-worker3
52.8713,Job,MODIFIED,eval-sanitize-5-r3-040,
52.8717,Event,ADDED,eval-sanitize-5-r3-047-nb5vw.18d3d46ffbbce394,"reason=FailedScheduling count=None msg=0/6 nodes are available: 2 c_wall violated: 1 conflicting context pair(s) with node memory, 4 node(s) had untolerated taint(s). no new claims to deallocate, preemption: 0/6 nodes are available: 2 No preemption victims found for incoming pod, 4 Preemption is not helpful for scheduling."
52.8743,Job,MODIFIED,eval-sanitize-5-r3-041,
52.8798,Pod,MODIFIED,eval-sanitize-5-r3-040-znsfm,phase=Succeeded node=kind-worker3
52.8837,Job,MODIFIED,eval-sanitize-5-r3-040,
52.8846,Job,MODIFIED,eval-sanitize-5-r3-041,
52.9224,Pod,MODIFIED,eval-sanitize-5-r3-052-gndzv,phase=Running node=kind-worker5
52.9286,Pod,MODIFIED,eval-sanitize-5-r3-046-bg7dm,phase=Running node=kind-worker5
52.935,Pod,MODIFIED,eval-sanitize-5-r3-049-t2ff5,phase=Running node=kind-worker5
52.9414,Pod,MODIFIED,eval-sanitize-5-r3-051-dsht7,phase=Running node=kind-worker5
52.9586,Event,MODIFIED,eval-sanitize-5-r3-047-nb5vw.18d3d46ffbbce394,"reason=FailedScheduling count=None msg=0/6 nodes are available: 2 c_wall violated: 1 conflicting context pair(s) with node memory, 4 node(s) had untolerated taint(s). no new claims to deallocate, preemption: 0/6 nodes are available: 2 No preemption victims found for incoming pod, 4 Preemption is not helpful for scheduling."
52.9647,Job,MODIFIED,eval-sanitize-5-r3-049,
52.9738,Job,MODIFIED,eval-sanitize-5-r3-049,
53.0069,TaskRequest,ADDED,eval-sanitize-5-r3-053,phase=None job=None
53.012,TaskRequest,MODIFIED,eval-sanitize-5-r3-053,phase=Pending job=None
53.0259,Pod,MODIFIED,eval-sanitize-5-r3-041-tmt29,phase=Succeeded node=kind-worker4
53.0274,Job,ADDED,eval-sanitize-5-r3-053,
53.0323,Pod,ADDED,eval-sanitize-5-r3-053-dbxqm,phase=Pending node=None
53.0334,TaskRequest,MODIFIED,eval-sanitize-5-r3-053,phase=Scheduled job=None
53.0364,Job,MODIFIED,eval-sanitize-5-r3-053,
53.0378,Event,ADDED,eval-sanitize-5-r3-053.18d3d470059dbc66,reason=SuccessfulCreate count=1 msg=Created pod: eval-sanitize-5-r3-053-dbxqm
53.0387,Job,MODIFIED,eval-sanitize-5-r3-052,
53.0423,TaskRequest,MODIFIED,eval-sanitize-5-r3-053,phase=Scheduled job=None
53.0461,Job,MODIFIED,eval-sanitize-5-r3-051,
53.0469,Job,MODIFIED,eval-sanitize-5-r3-053,
53.0476,Job,MODIFIED,eval-sanitize-5-r3-052,
53.0571,Job,MODIFIED,eval-sanitize-5-r3-051,
53.0594,Job,MODIFIED,eval-sanitize-5-r3-053,
53.0604,Pod,MODIFIED,eval-sanitize-5-r3-053-dbxqm,phase=Pending node=kind-worker5
53.0656,Event,ADDED,eval-sanitize-5-r3-053-dbxqm.18d3d470073e2e7f,reason=Scheduled count=None msg=Successfully assigned compute/eval-sanitize-5-r3-053-dbxqm to kind-worker5
53.0722,Pod,MODIFIED,eval-sanitize-5-r3-053-dbxqm,phase=Pending node=kind-worker5
53.2216,Event,ADDED,eval-sanitize-5-r3-048-tc9lm.18d3d47010a691f2,"reason=Pulled count=1 msg=Container image ""busybox:musl"" already present on machine"
53.2261,Event,ADDED,eval-sanitize-5-r3-050-l6mlt.18d3d47010c00dea,"reason=Pulled count=1 msg=Container image ""busybox:musl"" already present on machine"
53.2469,Event,ADDED,eval-sanitize-5-r3-048-tc9lm.18d3d47011ff1301,reason=Created count=1 msg=Created container: task
53.2514,Event,ADDED,eval-sanitize-5-r3-050-l6mlt.18d3d47012596f99,reason=Created count=1 msg=Created container: task
53.278,Event,ADDED,eval-sanitize-5-r3-048-tc9lm.18d3d47014031910,reason=Started count=1 msg=Started container task
53.2813,Event,ADDED,eval-sanitize-5-r3-050-l6mlt.18d3d4701449f105,reason=Started count=1 msg=Started container task
53.4829,Event,ADDED,eval-sanitize-5-r3-053-dbxqm.18d3d4702023c882,"reason=Pulled count=1 msg=Container image ""busybox:musl"" already present on machine"
53.4996,Event,ADDED,eval-sanitize-5-r3-053-dbxqm.18d3d470213f936f,reason=Created count=1 msg=Created container: task
53.5181,Pod,MODIFIED,eval-sanitize-5-r3-050-l6mlt,phase=Running node=kind-worker
53.5252,Pod,MODIFIED,eval-sanitize-5-r3-048-tc9lm,phase=Running node=kind-worker
53.5387,Job,MODIFIED,eval-sanitize-5-r3-039,
53.5406,Event,ADDED,eval-sanitize-5-r3-053-dbxqm.18d3d47023b3f2bc,reason=Started count=1 msg=Started container task
53.5438,Job,MODIFIED,eval-sanitize-5-r3-039,
53.5473,Event,ADDED,eval-sanitize-5-r3-039.18d3d470241a32e2,reason=Completed count=1 msg=Job completed
53.5533,Job,MODIFIED,eval-sanitize-5-r3-039,
53.5571,TaskRequest,MODIFIED,eval-sanitize-5-r3-039,phase=Complete job=None
53.5663,Job,MODIFIED,eval-sanitize-5-r3-039,
53.8761,Job,MODIFIED,eval-sanitize-5-r3-042,
53.8797,Job,MODIFIED,eval-sanitize-5-r3-040,
53.8842,Job,MODIFIED,eval-sanitize-5-r3-041,
53.8871,Job,MODIFIED,eval-sanitize-5-r3-040,
53.8878,Job,MODIFIED,eval-sanitize-5-r3-042,
53.8911,Event,ADDED,eval-sanitize-5-r3-040.18d3d470388d1359,reason=Completed count=1 msg=Job completed
53.8942,Job,MODIFIED,eval-sanitize-5-r3-041,
53.8956,Pod,MODIFIED,eval-sanitize-5-r3-041-tmt29,phase=Succeeded node=kind-worker4
53.8968,Job,MODIFIED,eval-sanitize-5-r3-040,
53.9009,TaskRequest,MODIFIED,eval-sanitize-5-r3-040,phase=Complete job=None
53.9099,Job,MODIFIED,eval-sanitize-5-r3-040,
53.9254,Pod,MODIFIED,eval-sanitize-5-r3-053-dbxqm,phase=Running node=kind-worker5
53.9333,Job,MODIFIED,eval-sanitize-5-r3-046,
53.9424,Job,MODIFIED,eval-sanitize-5-r3-046,
53.9527,Pod,MODIFIED,eval-sanitize-5-r3-042-cf2pb,phase=Succeeded node=kind-worker3
54.018,TaskRequest,ADDED,eval-sanitize-5-r3-054,phase=None job=None
54.0218,TaskRequest,MODIFIED,eval-sanitize-5-r3-054,phase=Pending job=None
54.0372,Job,ADDED,eval-sanitize-5-r3-054,
54.0407,Job,MODIFIED,eval-sanitize-5-r3-053,
54.0431,Pod,ADDED,eval-sanitize-5-r3-054-tfvvd,phase=Pending node=None
54.0442,TaskRequest,MODIFIED,eval-sanitize-5-r3-054,phase=Scheduled job=None
54.0469,Job,MODIFIED,eval-sanitize-5-r3-054,
54.0485,Event,ADDED,eval-sanitize-5-r3-054.18d3d47041dfdf9a,reason=SuccessfulCreate count=1 msg=Created pod: eval-sanitize-5-r3-054-tfvvd
54.0505,TaskRequest,MODIFIED,eval-sanitize-5-r3-054,phase=Scheduled job=None
54.0534,Job,MODIFIED,eval-sanitize-5-r3-053,
54.0545,Event,ADDED,eval-sanitize-5-r3-054-tfvvd.18d3d470424a1be2,"reason=FailedScheduling count=None msg=0/6 nodes are available: 2 c_wall violated: 1 conflicting context pair(s) with node memory, 4 node(s) had untolerated taint(s). no new claims to deallocate, preemption: 0/6 nodes are available: 2 No preemption victims found for incoming pod, 4 Preemption is not helpful for scheduling."
54.0558,Pod,MODIFIED,eval-sanitize-5-r3-054-tfvvd,phase=Pending node=None
54.0656,Event,ADDED,eval-sanitize-5-r3-054-tfvvd.18d3d47042f89496,"reason=FailedScheduling count=None msg=0/6 nodes are available: 2 c_wall violated: 1 conflicting context pair(s) with node memory, 4 node(s) had untolerated taint(s). no new claims to deallocate, preemption: 0/6 nodes are available: 2 No preemption victims found for incoming pod, 4 Preemption is not helpful for scheduling."
54.5297,Job,MODIFIED,eval-sanitize-5-r3-050,
54.5318,Job,MODIFIED,eval-sanitize-5-r3-048,
54.5399,Job,MODIFIED,eval-sanitize-5-r3-050,
54.5415,Job,MODIFIED,eval-sanitize-5-r3-048,
54.8706,Node,MODIFIED,kind-worker3,taints=1
54.8819,Job,MODIFIED,eval-sanitize-5-r3-042,
54.8863,Node,MODIFIED,kind-worker3,taints=0
54.8919,Job,MODIFIED,eval-sanitize-5-r3-041,
54.8933,Pod,MODIFIED,eval-sanitize-5-r3-042-cf2pb,phase=Succeeded node=kind-worker3
54.8942,Event,MODIFIED,eval-sanitize-5-r3-054-tfvvd.18d3d47042f89496,"reason=FailedScheduling count=None msg=0/6 nodes are available: 2 c_wall violated: 1 conflicting context pair(s) with node memory, 4 node(s) had untolerated taint(s). no new claims to deallocate, preemption: 0/6 nodes are available: 2 No preemption victims found for incoming pod, 4 Preemption is not helpful for scheduling."
54.8952,Job,MODIFIED,eval-sanitize-5-r3-042,
54.8979,Job,MODIFIED,eval-sanitize-5-r3-041,
54.8993,Node,MODIFIED,kind-worker3,taints=0
54.9017,Event,ADDED,eval-sanitize-5-r3-041.18d3d47074ce6c41,reason=Completed count=1 msg=Job completed
54.9083,Job,MODIFIED,eval-sanitize-5-r3-041,
54.9121,TaskRequest,MODIFIED,eval-sanitize-5-r3-041,phase=Complete job=None
54.9216,Job,MODIFIED,eval-sanitize-5-r3-041,
54.9648,Pod,MODIFIED,eval-sanitize-5-r3-047-nb5vw,phase=Pending node=kind-worker3
54.9668,Node,MODIFIED,kind-worker3,taints=0
54.9707,Pod,MODIFIED,eval-sanitize-5-r3-054-tfvvd,phase=Pending node=kind-worker3
54.9714,Event,ADDED,eval-sanitize-5-r3-047-nb5vw.18d3d47078c85ba6,reason=Scheduled count=None msg=Successfully assigned compute/eval-sanitize-5-r3-047-nb5vw to kind-worker3
54.9762,Event,ADDED,eval-sanitize-5-r3-054-tfvvd.18d3d470791ce30a,reason=Scheduled count=None msg=Successfully assigned compute/eval-sanitize-5-r3-054-tfvvd to kind-worker3
54.9874,Pod,MODIFIED,eval-sanitize-5-r3-047-nb5vw,phase=Pending node=kind-worker3
54.989,Node,MODIFIED,kind-worker3,taints=0
54.993,Pod,MODIFIED,eval-sanitize-5-r3-054-tfvvd,phase=Pending node=kind-worker3
54.997,Node,MODIFIED,kind-worker3,taints=0
55.006,TaskRequest,ADDED,eval-sanitize-5-r3-055,phase=None job=None
55.0104,TaskRequest,MODIFIED,eval-sanitize-5-r3-055,phase=Pending job=None
55.0254,Job,ADDED,eval-sanitize-5-r3-055,
55.0305,Pod,ADDED,eval-sanitize-5-r3-055-n28zx,phase=Pending node=None
55.0318,TaskRequest,MODIFIED,eval-sanitize-5-r3-055,phase=Scheduled job=None
55.0347,Job,MODIFIED,eval-sanitize-5-r3-055,
55.035,Event,ADDED,eval-sanitize-5-r3-055.18d3d4707cb602f3,reason=SuccessfulCreate count=1 msg=Created pod: eval-sanitize-5-r3-055-n28zx
55.0409,TaskRequest,MODIFIED,eval-sanitize-5-r3-055,phase=Scheduled job=None
55.048,Job,MODIFIED,eval-sanitize-5-r3-054,
55.0574,Job,MODIFIED,eval-sanitize-5-r3-054,
55.0622,Pod,MODIFIED,eval-sanitize-5-r3-055-n28zx,phase=Pending node=kind-worker3
55.0676,Event,ADDED,eval-sanitize-5-r3-055-n28zx.18d3d4707e9737ce,reason=Scheduled count=None msg=Successfully assigned compute/eval-sanitize-5-r3-055-n28zx to kind-worker3
55.072,Node,MODIFIED,kind-worker3,taints=0
55.0741,Pod,MODIFIED,eval-sanitize-5-r3-055-n28zx,phase=Pending node=kind-worker3
55.082,Node,MODIFIED,kind-worker3,taints=0
55.3987,Event,ADDED,eval-sanitize-5-r3-047-nb5vw.18d3d4709269b6b8,"reason=Pulled count=1 msg=Container image ""busybox:musl"" already present on machine"
55.4229,Event,ADDED,eval-sanitize-5-r3-047-nb5vw.18d3d47093d2ad99,reason=Created count=1 msg=Created container: task
55.5037,Event,ADDED,eval-sanitize-5-r3-047-nb5vw.18d3d470989a1e76,reason=Started count=1 msg=Started container task
55.5119,Event,ADDED,eval-sanitize-5-r3-055-n28zx.18d3d47099303ad9,"reason=Pulled count=1 msg=Container image ""busybox:musl"" already present on machine"
55.5293,Event,ADDED,eval-sanitize-5-r3-055-n28zx.18d3d4709a3d2a5b,reason=Created count=1 msg=Created container: task
55.607,Event,ADDED,eval-sanitize-5-r3-055-n28zx.18d3d4709ec3ad31,reason=Started count=1 msg=Started container task
55.7116,Event,ADDED,eval-sanitize-5-r3-054-tfvvd.18d3d470a513747b,"reason=Pulled count=1 msg=Container image ""busybox:musl"" already present on machine"
55.7285,Event,ADDED,eval-sanitize-5-r3-054-tfvvd.18d3d470a61e4d45,reason=Created count=1 msg=Created container: task
55.7585,Event,ADDED,eval-sanitize-5-r3-054-tfvvd.18d3d470a7e29fb2,reason=Started count=1 msg=Started container task
55.8818,Pod,MODIFIED,eval-sanitize-5-r3-055-n28zx,phase=Running node=kind-worker3
55.8865,Job,MODIFIED,eval-sanitize-5-r3-042,
55.8886,Pod,MODIFIED,eval-sanitize-5-r3-047-nb5vw,phase=Running node=kind-worker3
55.8906,Job,MODIFIED,eval-sanitize-5-r3-042,
55.8956,Pod,MODIFIED,eval-sanitize-5-r3-054-tfvvd,phase=Running node=kind-worker3
55.8964,Event,ADDED,eval-sanitize-5-r3-042.18d3d470afff0418,reason=Completed count=1 msg=Job completed
55.9029,Job,MODIFIED,eval-sanitize-5-r3-042,
55.9079,TaskRequest,MODIFIED,eval-sanitize-5-r3-042,phase=Complete job=None
55.916,Job,MODIFIED,eval-sanitize-5-r3-042,
55.9859,Job,MODIFIED,eval-sanitize-5-r3-047,
55.9946,Job,MODIFIED,eval-sanitize-5-r3-047,
56.0058,TaskRequest,ADDED,eval-sanitize-5-r3-056,phase=None job=None
56.0089,TaskRequest,MODIFIED,eval-sanitize-5-r3-056,phase=Pending job=None
56.0232,Job,ADDED,eval-sanitize-5-r3-056,
56.0293,Pod,ADDED,eval-sanitize-5-r3-056-p8v5t,phase=Pending node=None
56.0295,TaskRequest,MODIFIED,eval-sanitize-5-r3-056,phase=Scheduled job=None
56.0319,Job,MODIFIED,eval-sanitize-5-r3-056,
56.0354,Event,ADDED,eval-sanitize-5-r3-056.18d3d470b841453e,reason=SuccessfulCreate count=1 msg=Created pod: eval-sanitize-5-r3-056-p8v5t
56.0362,Job,MODIFIED,eval-sanitize-5-r3-055,
56.0363,TaskRequest,MODIFIED,eval-sanitize-5-r3-056,phase=Scheduled job=None
56.0457,Pod,MODIFIED,eval-sanitize-5-r3-056-p8v5t,phase=Pending node=kind-worker
56.0475,Job,MODIFIED,eval-sanitize-5-r3-055,
56.0502,Event,ADDED,eval-sanitize-5-r3-056-p8v5t.18d3d470b9330cd4,reason=Scheduled count=None msg=Successfully assigned compute/eval-sanitize-5-r3-056-p8v5t to kind-worker
56.0529,Job,MODIFIED,eval-sanitize-5-r3-054,
56.0576,Node,MODIFIED,kind-worker,taints=0
56.0591,Pod,MODIFIED,eval-sanitize-5-r3-056-p8v5t,phase=Pending node=kind-worker
56.0651,Job,MODIFIED,eval-sanitize-5-r3-054,
56.0686,Node,MODIFIED,kind-worker,taints=0
56.4679,Node,MODIFIED,kind-worker4,taints=1
56.4821,Node,MODIFIED,kind-worker4,taints=0
56.493,Node,MODIFIED,kind-worker4,taints=0
56.5665,Node,MODIFIED,kind-worker4,taints=0
56.5702,Event,ADDED,eval-sanitize-5-r3-056-p8v5t.18d3d470d8476786,"reason=Pulled count=1 msg=Container image ""busybox:musl"" already present on machine"
56.5892,Event,ADDED,eval-sanitize-5-r3-056-p8v5t.18d3d470d959653b,reason=Created count=1 msg=Created container: task
56.6574,Event,ADDED,eval-sanitize-5-r3-056-p8v5t.18d3d470dd790bf5,reason=Started count=1 msg=Started container task
56.881,Node,MODIFIED,kind-worker5,taints=1
56.893,Node,MODIFIED,kind-worker5,taints=1
57.0071,TaskRequest,ADDED,eval-sanitize-5-r3-057,phase=None job=None
57.0107,TaskRequest,MODIFIED,eval-sanitize-5-r3-057,phase=Pending job=None
57.0251,Job,ADDED,eval-sanitize-5-r3-057,
57.0284,TaskRequest,MODIFIED,eval-sanitize-5-r3-057,phase=Scheduled job=None
57.0313,Pod,ADDED,eval-sanitize-5-r3-057-bccxp,phase=Pending node=None
57.0337,Job,MODIFIED,eval-sanitize-5-r3-056,
57.0355,Job,MODIFIED,eval-sanitize-5-r3-057,
57.0376,Event,ADDED,eval-sanitize-5-r3-057.18d3d470f4004837,reason=SuccessfulCreate count=1 msg=Created pod: eval-sanitize-5-r3-057-bccxp
57.0378,TaskRequest,MODIFIED,eval-sanitize-5-r3-057,phase=Scheduled job=None
57.0422,Job,MODIFIED,eval-sanitize-5-r3-056,
57.0445,Pod,MODIFIED,eval-sanitize-5-r3-057-bccxp,phase=Pending node=kind-worker4
57.0477,Event,ADDED,eval-sanitize-5-r3-057-bccxp.18d3d470f4c3df5d,reason=Scheduled count=None msg=Successfully assigned compute/eval-sanitize-5-r3-057-bccxp to kind-worker4
57.0534,Pod,MODIFIED,eval-sanitize-5-r3-057-bccxp,phase=Pending node=kind-worker4
57.0556,Node,MODIFIED,kind-worker4,taints=0
57.0652,Node,MODIFIED,kind-worker4,taints=0
57.4691,Event,ADDED,eval-sanitize-5-r3-057-bccxp.18d3d4710dc8ecba,"reason=Pulled count=1 msg=Container image ""busybox:musl"" already present on machine"
57.4856,Event,ADDED,eval-sanitize-5-r3-057-bccxp.18d3d4710ed6ac2f,reason=Created count=1 msg=Created container: task
57.5351,Pod,MODIFIED,eval-sanitize-5-r3-056-p8v5t,phase=Running node=kind-worker
57.5607,Event,ADDED,eval-sanitize-5-r3-057-bccxp.18d3d471134b4623,reason=Started count=1 msg=Started container task
57.7995,Node,MODIFIED,kind-worker,taints=1
57.8115,Node,MODIFIED,kind-worker,taints=1
57.8823,Pod,MODIFIED,eval-sanitize-5-r3-057-bccxp,phase=Running node=kind-worker4
57.9779,Pod,MODIFIED,eval-sanitize-5-r3-045-9klvn,phase=Running node=kind-worker2
57.984,Pod,MODIFIED,eval-sanitize-5-r3-044-97sfv,phase=Running node=kind-worker2
57.9903,Pod,MODIFIED,eval-sanitize-5-r3-043-2mzj6,phase=Running node=kind-worker2
58.0064,TaskRequest,ADDED,eval-sanitize-5-r3-058,phase=None job=None
58.0111,TaskRequest,MODIFIED,eval-sanitize-5-r3-058,phase=Pending job=None
58.024,Job,ADDED,eval-sanitize-5-r3-058,
58.029,TaskRequest,MODIFIED,eval-sanitize-5-r3-058,phase=Scheduled job=None
58.0309,Pod,ADDED,eval-sanitize-5-r3-058-nvqm9,phase=Pending node=None
58.0328,Job,MODIFIED,eval-sanitize-5-r3-058,
58.0351,Event,ADDED,eval-sanitize-5-r3-058.18d3d4712f904f0a,reason=SuccessfulCreate count=1 msg=Created pod: eval-sanitize-5-r3-058-nvqm9
58.0376,Job,MODIFIED,eval-sanitize-5-r3-057,
58.0398,Job,MODIFIED,eval-sanitize-5-r3-056,
58.0399,TaskRequest,MODIFIED,eval-sanitize-5-r3-058,phase=Scheduled job=None
58.0425,Pod,MODIFIED,eval-sanitize-5-r3-058-nvqm9,phase=Pending node=None
58.0428,Event,ADDED,eval-sanitize-5-r3-058-nvqm9.18d3d4712ff51c48,"reason=FailedScheduling count=None msg=0/6 nodes are available: 2 c_wall violated: 1 conflicting context pair(s) with node memory, 4 node(s) had untolerated taint(s). no new claims to deallocate, preemption: 0/6 nodes are available: 2 No preemption victims found for incoming pod, 4 Preemption is not helpful for scheduling."
58.0474,Job,MODIFIED,eval-sanitize-5-r3-057,
58.0501,Job,MODIFIED,eval-sanitize-5-r3-056,
58.0508,Event,ADDED,eval-sanitize-5-r3-058-nvqm9.18d3d47130958a00,"reason=FailedScheduling count=None msg=0/6 nodes are available: 2 c_wall violated: 1 conflicting context pair(s) with node memory, 4 node(s) had untolerated taint(s). no new claims to deallocate, preemption: 0/6 nodes are available: 2 No preemption victims found for incoming pod, 4 Preemption is not helpful for scheduling."
58.9914,Job,MODIFIED,eval-sanitize-5-r3-045,
58.9932,Job,MODIFIED,eval-sanitize-5-r3-044,
58.9997,Job,MODIFIED,eval-sanitize-5-r3-043,
59.0025,Job,MODIFIED,eval-sanitize-5-r3-045,
59.0046,Job,MODIFIED,eval-sanitize-5-r3-044,
59.0077,TaskRequest,ADDED,eval-sanitize-5-r3-059,phase=None job=None
59.0106,Job,MODIFIED,eval-sanitize-5-r3-043,
59.0112,TaskRequest,MODIFIED,eval-sanitize-5-r3-059,phase=Pending job=None
59.0272,Job,ADDED,eval-sanitize-5-r3-059,
59.0328,Pod,ADDED,eval-sanitize-5-r3-059-4hqs6,phase=Pending node=None
59.034,TaskRequest,MODIFIED,eval-sanitize-5-r3-059,phase=Scheduled job=None
59.0378,Event,ADDED,eval-sanitize-5-r3-059.18d3d4716b447e73,reason=SuccessfulCreate count=1 msg=Created pod: eval-sanitize-5-r3-059-4hqs6
59.0389,Job,MODIFIED,eval-sanitize-5-r3-058,
59.0401,Job,MODIFIED,eval-sanitize-5-r3-059,
59.0427,TaskRequest,MODIFIED,eval-sanitize-5-r3-059,phase=Scheduled job=None
59.0458,Pod,MODIFIED,eval-sanitize-5-r3-059-4hqs6,phase=Pending node=None
59.0463,Event,ADDED,eval-sanitize-5-r3-059-4hqs6.18d3d4716bc1434d,"reason=FailedScheduling count=None msg=0/6 nodes are available: 2 c_wall violated: 1 conflicting context pair(s) with node memory, 4 node(s) had untolerated taint(s). no new claims to deallocate, preemption: 0/6 nodes are available: 2 No preemption victims found for incoming pod, 4 Preemption is not helpful for scheduling."
59.0555,Event,ADDED,eval-sanitize-5-r3-059-4hqs6.18d3d4716c6b433a,"reason=FailedScheduling count=None msg=0/6 nodes are available: 2 c_wall violated: 1 conflicting context pair(s) with node memory, 4 node(s) had untolerated taint(s). no new claims to deallocate, preemption: 0/6 nodes are available: 2 No preemption victims found for incoming pod, 4 Preemption is not helpful for scheduling."
59.0655,Job,MODIFIED,eval-sanitize-5-r3-058,
59.1363,Pod,MODIFIED,eval-sanitize-5-r3-044-97sfv,phase=Succeeded node=kind-worker2
59.147,Event,MODIFIED,eval-sanitize-5-r3-058-nvqm9.18d3d47130958a00,"reason=FailedScheduling count=None msg=0/6 nodes are available: 2 c_wall violated: 1 conflicting context pair(s) with node memory, 4 node(s) had untolerated taint(s). no new claims to deallocate, preemption: 0/6 nodes are available: 2 No preemption victims found for incoming pod, 4 Preemption is not helpful for scheduling."
59.1531,Event,MODIFIED,eval-sanitize-5-r3-059-4hqs6.18d3d4716c6b433a,"reason=FailedScheduling count=None msg=0/6 nodes are available: 2 c_wall violated: 1 conflicting context pair(s) with node memory, 4 node(s) had untolerated taint(s). no new claims to deallocate, preemption: 0/6 nodes are available: 2 No preemption victims found for incoming pod, 4 Preemption is not helpful for scheduling."
59.1781,Pod,MODIFIED,eval-sanitize-5-r3-043-2mzj6,phase=Succeeded node=kind-worker2
59.1848,Pod,MODIFIED,eval-sanitize-5-r3-045-9klvn,phase=Succeeded node=kind-worker2
59.9133,Node,MODIFIED,kind-worker3,taints=1
59.9218,Pod,MODIFIED,eval-sanitize-5-r3-058-nvqm9,phase=Pending node=None
59.9266,Node,MODIFIED,kind-worker3,taints=1
59.9302,Pod,MODIFIED,eval-sanitize-5-r3-059-4hqs6,phase=Pending node=None
59.9386,Event,ADDED,eval-sanitize-5-r3-058-nvqm9.18d3d471a10224c4,"reason=FailedScheduling count=None msg=0/6 nodes are available: 1 c_wall violated: 1 conflicting context pair(s) with node memory, 5 node(s) had untolerated taint(s). no new claims to deallocate, preemption: 0/6 nodes are available: 1 No preemption victims found for incoming pod, 5 Preemption is not helpful for scheduling."
59.9411,Event,ADDED,eval-sanitize-5-r3-059-4hqs6.18d3d471a1300290,"reason=FailedScheduling count=None msg=0/6 nodes are available: 1 c_wall violated: 1 conflicting context pair(s) with node memory, 5 node(s) had untolerated taint(s). no new claims to deallocate, preemption: 0/6 nodes are available: 1 No preemption victims found for incoming pod, 5 Preemption is not helpful for scheduling."
60.0021,Job,MODIFIED,eval-sanitize-5-r3-045,
60.0042,Job,MODIFIED,eval-sanitize-5-r3-044,
60.0053,Job,MODIFIED,eval-sanitize-5-r3-043,
60.0074,TaskRequest,ADDED,eval-sanitize-5-r3-060,phase=None job=None
60.011,Pod,MODIFIED,eval-sanitize-5-r3-045-9klvn,phase=Succeeded node=kind-worker2
60.0138,Pod,MODIFIED,eval-sanitize-5-r3-043-2mzj6,phase=Succeeded node=kind-worker2
60.0146,Job,MODIFIED,eval-sanitize-5-r3-045,
60.0193,Pod,MODIFIED,eval-sanitize-5-r3-044-97sfv,phase=Succeeded node=kind-worker2
60.0203,TaskRequest,ADDED,eval-sanitize-5-r3-000,phase=Complete job=None
60.0207,TaskRequest,ADDED,eval-sanitize-5-r3-001,phase=Complete job=None
60.0208,TaskRequest,ADDED,eval-sanitize-5-r3-002,phase=Complete job=None
60.0222,Node,ADDED,kind-control-plane,taints=1
60.0224,TaskRequest,ADDED,eval-sanitize-5-r3-003,phase=Complete job=None
60.0224,TaskRequest,ADDED,eval-sanitize-5-r3-004,phase=Complete job=None
60.0225,TaskRequest,ADDED,eval-sanitize-5-r3-005,phase=Complete job=None
60.0233,TaskRequest,ADDED,eval-sanitize-5-r3-006,phase=Complete job=None
60.0234,TaskRequest,ADDED,eval-sanitize-5-r3-007,phase=Complete job=None
60.0236,TaskRequest,ADDED,eval-sanitize-5-r3-008,phase=Complete job=None
60.025,Job,ADDED,eval-sanitize-5-r3-000,
60.0252,TaskRequest,ADDED,eval-sanitize-5-r3-009,phase=Complete job=None
60.0253,TaskRequest,ADDED,eval-sanitize-5-r3-010,phase=Complete job=None
60.0267,Pod,ADDED,eval-sanitize-5-r3-000-2jwwc,phase=Succeeded node=kind-worker2
60.0269,TaskRequest,ADDED,eval-sanitize-5-r3-011,phase=Complete job=None
60.027,TaskRequest,ADDED,eval-sanitize-5-r3-012,phase=Complete job=None
60.0271,TaskRequest,ADDED,eval-sanitize-5-r3-013,phase=Complete job=None
60.0275,Event,ADDED,eval-sanitize-5-r1-011-4cvxp.18d3d3d7eccf09d3,"reason=FailedScheduling count=None msg=0/6 nodes are available: 1 c_wall violated: 1 conflicting context pair(s) with node memory, 5 node(s) had untolerated taint(s). no new claims to deallocate, preemption: 0/6 nodes are available: 1 No preemption victims found for incoming pod, 5 Preemption is not helpful for scheduling."
60.0291,Node,ADDED,kind-worker,taints=1
60.03,Job,ADDED,eval-sanitize-5-r3-001,
60.0301,TaskRequest,ADDED,eval-sanitize-5-r3-014,phase=Complete job=None
60.0301,TaskRequest,ADDED,eval-sanitize-5-r3-015,phase=Complete job=None
60.0302,TaskRequest,ADDED,eval-sanitize-5-r3-016,phase=Complete job=None
60.0305,Event,ADDED,eval-sanitize-5-r1-014-8x522.18d3d3d7ed0515d2,"reason=FailedScheduling count=None msg=0/6 nodes are available: 1 c_wall violated: 2 conflicting context pair(s) with node memory, 5 node(s) had untolerated taint(s). no new claims to deallocate, preemption: 0/6 nodes are available: 1 No preemption victims found for incoming pod, 5 Preemption is not helpful for scheduling."
60.0307,Event,ADDED,eval-sanitize-5-r1-016-ql8wf.18d3d3d7ed3d5ebf,"reason=FailedScheduling count=None msg=0/6 nodes are available: 1 c_wall violated: 1 conflicting context pair(s) with node memory, 5 node(s) had untolerated taint(s). no new claims to deallocate, preemption: 0/6 nodes are available: 1 No preemption victims found for incoming pod, 5 Preemption is not helpful for scheduling."
60.0309,Event,ADDED,eval-sanitize-5-r1-026-psh7v.18d3d3d9e058761c,"reason=FailedScheduling count=None msg=0/6 nodes are available: 1 c_wall violated: 1 conflicting context pair(s) with node memory, 5 node(s) had untolerated taint(s). no new claims to deallocate, preemption: 0/6 nodes are available: 1 No preemption victims found for incoming pod, 5 Preemption is not helpful for scheduling."
60.0322,Pod,ADDED,eval-sanitize-5-r3-001-kbq6c,phase=Succeeded node=kind-worker
60.033,Job,ADDED,eval-sanitize-5-r3-002,
60.0331,TaskRequest,ADDED,eval-sanitize-5-r3-017,phase=Complete job=None
60.0331,TaskRequest,ADDED,eval-sanitize-5-r3-018,phase=Complete job=None
60.0334,Event,ADDED,eval-sanitize-5-r1-026-psh7v.18d3d3da586e6650,"reason=FailedScheduling count=None msg=0/6 nodes are available: 1 c_wall violated: 2 conflicting context pair(s) with node memory, 5 node(s) had untolerated taint(s). no new claims to deallocate, preemption: 0/6 nodes are available: 1 No preemption victims found for incoming pod, 5 Preemption is not helpful for scheduling."
60.0337,Event,ADDED,eval-sanitize-5-r1-029-9dgzs.18d3d3da934fcb7c,"reason=FailedScheduling count=None msg=0/6 nodes are available: 1 c_wall violated: 2 conflicting context pair(s) with node memory, 5 node(s) had untolerated taint(s). no new claims to deallocate, preemption: 0/6 nodes are available: 1 No preemption victims found for incoming pod, 5 Preemption is not helpful for scheduling."
60.0338,Event,ADDED,eval-sanitize-5-r1-030-7hjwr.18d3d3db7a6ae75f,"reason=FailedScheduling count=None msg=0/6 nodes are available: 1 c_wall violated: 1 conflicting context pair(s) with node memory, 5 node(s) had untolerated taint(s). no new claims to deallocate, preemption: 0/6 nodes are available: 1 No preemption victims found for incoming pod, 5 Preemption is not helpful for scheduling."
60.035,Node,ADDED,kind-worker2,taints=1
60.0366,Pod,ADDED,eval-sanitize-5-r3-002-lxfh7,phase=Succeeded node=kind-worker4
60.0368,TaskRequest,ADDED,eval-sanitize-5-r3-019,phase=Complete job=None
60.0368,TaskRequest,ADDED,eval-sanitize-5-r3-020,phase=Complete job=None
60.0368,TaskRequest,ADDED,eval-sanitize-5-r3-021,phase=Complete job=None
60.0372,Event,ADDED,eval-sanitize-5-r1-030-7hjwr.18d3d3dc1d8a7b40,"reason=FailedScheduling count=None msg=0/6 nodes are available: 2 c_wall violated: 1 conflicting context pair(s) with node memory, 4 node(s) had untolerated taint(s). no new claims to deallocate, preemption: 0/6 nodes are available: 2 No preemption victims found for incoming pod, 4 Preemption is not helpful for scheduling."
60.0374,Event,ADDED,eval-sanitize-5-r1-030-7hjwr.18d3d3dcaad50abb,"reason=FailedScheduling count=None msg=0/6 nodes are available: 1 c_wall violated: 1 conflicting context pair(s) with node memory, 5 node(s) had untolerated taint(s). no new claims to deallocate, preemption: 0/6 nodes are available: 1 No preemption victims found for incoming pod, 5 Preemption is not helpful for scheduling."
60.0377,Event,ADDED,eval-sanitize-5-r1-031-vp575.18d3d3db7ba99046,"reason=FailedScheduling count=None msg=0/6 nodes are available: 1 c_wall violated: 2 conflicting context pair(s) with node memory, 5 node(s) had untolerated taint(s). no new claims to deallocate, preemption: 0/6 nodes are available: 1 No preemption victims found for incoming pod, 5 Preemption is not helpful for scheduling."
60.0379,Event,ADDED,eval-sanitize-5-r1-031-vp575.18d3d3db7fd1f119,"reason=FailedScheduling count=None msg=0/6 nodes are available: 1 c_wall violated: 2 conflicting context pair(s) with node memory, 5 node(s) had untolerated taint(s). no new claims to deallocate, preemption: 0/6 nodes are available: 1 No preemption victims found for incoming pod, 5 Preemption is not helpful for scheduling."
60.0381,Event,ADDED,eval-sanitize-5-r1-033-qwngz.18d3d3db819cace9,"reason=FailedScheduling count=None msg=0/6 nodes are available: 1 c_wall violated: 2 conflicting context pair(s) with node memory, 5 node(s) had untolerated taint(s). no new claims to deallocate, preemption: 0/6 nodes are available: 1 No preemption victims found for incoming pod, 5 Preemption is not helpful for scheduling."
60.039,Job,ADDED,eval-sanitize-5-r3-003,
60.0391,TaskRequest,ADDED,eval-sanitize-5-r3-022,phase=Complete job=None
60.0392,TaskRequest,ADDED,eval-sanitize-5-r3-023,phase=Complete job=None
60.0392,TaskRequest,ADDED,eval-sanitize-5-r3-024,phase=Complete job=None
60.0393,TaskRequest,ADDED,eval-sanitize-5-r3-025,phase=Complete job=None
60.0393,TaskRequest,ADDED,eval-sanitize-5-r3-026,phase=Complete job=None
60.0397,Event,ADDED,eval-sanitize-5-r1-034-sjxpc.18d3d3dbbe3cbdbf,"reason=FailedScheduling count=None msg=0/6 nodes are available: 1 c_wall violated: 2 conflicting context pair(s) with node memory, 5 node(s) had untolerated taint(s). no new claims to deallocate, preemption: 0/6 nodes are available: 1 No preemption victims found for incoming pod, 5 Preemption is not helpful for scheduling."
60.0399,Event,ADDED,eval-sanitize-5-r1-036-779qg.18d3d3dc359b781e,"reason=FailedScheduling count=None msg=0/6 nodes are available: 2 c_wall violated: 1 conflicting context pair(s) with node memory, 4 node(s) had untolerated taint(s). no new claims to deallocate, preemption: 0/6 nodes are available: 2 No preemption victims found for incoming pod, 4 Preemption is not helpful for scheduling."
60.0401,Event,ADDED,eval-sanitize-5-r1-036-779qg.18d3d3dcaba1b7f5,"reason=FailedScheduling count=None msg=0/6 nodes are available: 1 c_wall violated: 1 conflicting context pair(s) with node memory, 5 node(s) had untolerated taint(s). no new claims to deallocate, preemption: 0/6 nodes are available: 1 No preemption victims found for incoming pod, 5 Preemption is not helpful for scheduling."
60.041,Job,ADDED,eval-sanitize-5-r3-004,
60.0423,Node,ADDED,kind-worker3,taints=1
60.0435,Pod,ADDED,eval-sanitize-5-r3-003-9sqzh,phase=Succeeded node=kind-worker5
60.0436,TaskRequest,ADDED,eval-sanitize-5-r3-027,phase=Complete job=None
60.0437,TaskRequest,ADDED,eval-sanitize-5-r3-028,phase=Complete job=None
60.0437,TaskRequest,ADDED,eval-sanitize-5-r3-029,phase=Complete job=None
60.0441,Event,ADDED,eval-sanitize-5-r1-037-f2njp.18d3d3dc7061cc87,"reason=FailedScheduling count=None msg=0/6 nodes are available: 2 c_wall violated: 1 conflicting context pair(s) with node memory, 4 node(s) had untolerated taint(s). no new claims to deallocate, preemption: 0/6 nodes are available: 2 No preemption victims found for incoming pod, 4 Preemption is not helpful for scheduling."
60.0443,Event,ADDED,eval-sanitize-5-r1-037-f2njp.18d3d3dcabd07580,"reason=FailedScheduling count=None msg=0/6 nodes are available: 1 c_wall violated: 1 conflicting context pair(s) with node memory, 5 node(s) had untolerated taint(s). no new claims to deallocate, preemption: 0/6 nodes are available: 1 No preemption victims found for incoming pod, 5 Preemption is not helpful for scheduling."
60.0445,Event,ADDED,eval-sanitize-5-r1-037-f2njp.18d3d3dd0d437091,"reason=FailedScheduling count=None msg=0/6 nodes are available: 2 c_wall violated: 1 conflicting context pair(s) with node memory, 4 node(s) had untolerated taint(s). no new claims to deallocate, preemption: 0/6 nodes are available: 2 No preemption victims found for incoming pod, 4 Preemption is not helpful for scheduling."
60.0449,Event,ADDED,eval-sanitize-5-r1-038-w86qq.18d3d3dcaca8589c,"reason=FailedScheduling count=None msg=0/6 nodes are available: 1 c_wall violated: 1 conflicting context pair(s) with node memory, 5 node(s) had untolerated taint(s). no new claims to deallocate, preemption: 0/6 nodes are available: 1 No preemption victims found for incoming pod, 5 Preemption is not helpful for scheduling."
60.0455,Event,ADDED,eval-sanitize-5-r1-041-m6ft9.18d3d3dd5e7c2260,"reason=FailedScheduling count=None msg=0/6 nodes are available: 2 c_wall violated: 1 conflicting context pair(s) with node memory, 4 node(s) had untolerated taint(s). no new claims to deallocate, preemption: 0/6 nodes are available: 2 No preemption victims found for incoming pod, 4 Preemption is not helpful for scheduling."
60.0457,Event,ADDED,eval-sanitize-5-r1-043-5jmf7.18d3d3ddd61457ac,"reason=FailedScheduling count=None msg=0/6 nodes are available: 2 c_wall violated: 1 conflicting context pair(s) with node memory, 4 node(s) had untolerated taint(s). no new claims to deallocate, preemption: 0/6 nodes are available: 2 No preemption victims found for incoming pod, 4 Preemption is not helpful for scheduling."
60.0469,Node,ADDED,kind-worker4,taints=0
60.0474,Event,ADDED,eval-sanitize-5-r1-044-5m8mg.18d3d3de1867ba4e,"reason=FailedScheduling count=None msg=0/6 nodes are available: 1 c_wall violated: 1 conflicting context pair(s) with node memory, 1 c_wall violated: 2 conflicting context pair(s) with node memory, 4 node(s) had untolerated taint(s). no new claims to deallocate, preemption: 0/6 nodes are available: 2 No preemption victims found for incoming pod, 4 Preemption is not helpful for scheduling."
60.0476,Event,ADDED,eval-sanitize-5-r1-044-5m8mg.18d3d3de42440367,"reason=FailedScheduling count=None msg=0/6 nodes are available: 2 c_wall violated: 1 conflicting context pair(s) with node memory, 4 node(s) had untolerated taint(s). no new claims to deallocate, preemption: 0/6 nodes are available: 2 No preemption victims found for incoming pod, 4 Preemption is not helpful for scheduling."
60.0487,Pod,ADDED,eval-sanitize-5-r3-004-th9rv,phase=Succeeded node=kind-worker4
60.0488,TaskRequest,ADDED,eval-sanitize-5-r3-030,phase=Complete job=None
60.0489,TaskRequest,ADDED,eval-sanitize-5-r3-031,phase=Complete job=None
60.0504,Node,ADDED,kind-worker5,taints=1
60.0513,Job,ADDED,eval-sanitize-5-r3-005,
60.0519,Job,ADDED,eval-sanitize-5-r3-006,
60.052,TaskRequest,ADDED,eval-sanitize-5-r3-032,phase=Complete job=None
60.0521,TaskRequest,ADDED,eval-sanitize-5-r3-033,phase=Complete job=None
60.0521,TaskRequest,ADDED,eval-sanitize-5-r3-034,phase=Complete job=None
60.0525,Event,ADDED,eval-sanitize-5-r1-044-5m8mg.18d3d3de43836989,"reason=FailedScheduling count=None msg=0/6 nodes are available: 2 c_wall violated: 1 conflicting context pair(s) with node memory, 4 node(s) had untolerated taint(s). no new claims to deallocate, preemption: 0/6 nodes are available: 2 No preemption victims found for incoming pod, 4 Preemption is not helpful for scheduling."
60.0527,Event,ADDED,eval-sanitize-5-r1-044-5m8mg.18d3d3de548de89a,"reason=FailedScheduling count=None msg=0/6 nodes are available: 1 c_wall violated: 1 conflicting context pair(s) with node memory, 5 node(s) had untolerated taint(s). no new claims to deallocate, preemption: 0/6 nodes are available: 1 No preemption victims found for incoming pod, 5 Preemption is not helpful for scheduling."
60.0529,Event,ADDED,eval-sanitize-5-r1-044-5m8mg.18d3d3dec5c2247f,"reason=FailedScheduling count=None msg=0/6 nodes are available: 1 c_wall violated: 2 conflicting context pair(s) with node memory, 5 node(s) had untolerated taint(s). no new claims to deallocate, preemption: 0/6 nodes are available: 1 No preemption victims found for incoming pod, 5 Preemption is not helpful for scheduling."
60.0537,Job,ADDED,eval-sanitize-5-r3-007,
60.0539,TaskRequest,ADDED,eval-sanitize-5-r3-035,phase=Complete job=None
60.054,TaskRequest,ADDED,eval-sanitize-5-r3-036,phase=Complete job=None
60.054,TaskRequest,ADDED,eval-sanitize-5-r3-037,phase=Complete job=None
60.0548,Event,ADDED,eval-sanitize-5-r1-044-5m8mg.18d3d3df139e4330,"reason=FailedScheduling count=None msg=0/6 nodes are available: 1 c_wall violated: 1 conflicting context pair(s) with node memory, 1 c_wall violated: 2 conflicting context pair(s) with node memory, 4 node(s) had untolerated taint(s). no new claims to deallocate, preemption: 0/6 nodes are available: 2 No preemption victims found for incoming pod, 4 Preemption is not helpful for scheduling."
60.0551,Event,ADDED,eval-sanitize-5-r1-044-5m8mg.18d3d3df7c405c7e,"reason=FailedScheduling count=None msg=0/6 nodes are available: 1 c_wall violated: 1 conflicting context pair(s) with node memory, 5 node(s) had untolerated taint(s). no new claims to deallocate, preemption: 0/6 nodes are available: 1 No preemption victims found for incoming pod, 5 Preemption is not helpful for scheduling."
60.0552,Event,ADDED,eval-sanitize-5-r1-044-5m8mg.18d3d3dfb33b8fb1,"reason=FailedScheduling count=None msg=0/6 nodes are available: 1 c_wall violated: 2 conflicting context pair(s) with node memory, 5 node(s) had untolerated taint(s). no new claims to deallocate, preemption: 0/6 nodes are available: 1 No preemption victims found for incoming pod, 5 Preemption is not helpful for scheduling."
60.0562,Job,ADDED,eval-sanitize-5-r3-008,
60.057,Job,ADDED,eval-sanitize-5-r3-009,
60.0581,Job,ADDED,eval-sanitize-5-r3-010,
60.0588,Event,ADDED,eval-sanitize-5-r1-045-bpmp6.18d3d3de4ee1b7c1,"reason=FailedScheduling count=None msg=0/6 nodes are available: 2 c_wall violated: 1 conflicting context pair(s) with node memory, 4 node(s) had untolerated taint(s). no new claims to deallocate, preemption: 0/6 nodes are available: 2 No preemption victims found for incoming pod, 4 Preemption is not helpful for scheduling."
60.059,Event,ADDED,eval-sanitize-5-r1-045-bpmp6.18d3d3de54b6f922,"reason=FailedScheduling count=None msg=0/6 nodes are available: 1 c_wall violated: 1 conflicting context pair(s) with node memory, 5 node(s) had untolerated taint(s). no new claims to deallocate, preemption: 0/6 nodes are available: 1 No preemption victims found for incoming pod, 5 Preemption is not helpful for scheduling."
60.0592,Event,ADDED,eval-sanitize-5-r1-045-bpmp6.18d3d3dec8fe2b34,"reason=FailedScheduling count=None msg=0/6 nodes are available: 1 c_wall violated: 2 conflicting context pair(s) with node memory, 5 node(s) had untolerated taint(s). no new claims to deallocate, preemption: 0/6 nodes are available: 1 No preemption victims found for incoming pod, 5 Preemption is not helpful for scheduling."
60.0594,TaskRequest,ADDED,eval-sanitize-5-r3-038,phase=Complete job=None
60.0594,TaskRequest,ADDED,eval-sanitize-5-r3-039,phase=Complete job=None
60.0602,Event,ADDED,eval-sanitize-5-r1-045-bpmp6.18d3d3df187c3a44,"reason=FailedScheduling count=None msg=0/6 nodes are available: 1 c_wall violated: 1 conflicting context pair(s) with node memory, 1 c_wall violated: 2 conflicting context pair(s) with node memory, 4 node(s) had untolerated taint(s). no new claims to deallocate, preemption: 0/6 nodes are available: 2 No preemption victims found for incoming pod, 4 Preemption is not helpful for scheduling."
60.0604,Event,ADDED,eval-sanitize-5-r1-045-bpmp6.18d3d3df7c709b5e,"reason=FailedScheduling count=None msg=0/6 nodes are available: 1 c_wall violated: 1 conflicting context pair(s) with node memory, 5 node(s) had untolerated taint(s). no new claims to deallocate, preemption: 0/6 nodes are available: 1 No preemption victims found for incoming pod, 5 Preemption is not helpful for scheduling."
60.0617,Pod,ADDED,eval-sanitize-5-r3-005-cqc9r,phase=Succeeded node=kind-worker3
60.0618,TaskRequest,ADDED,eval-sanitize-5-r3-040,phase=Complete job=None
60.0618,TaskRequest,ADDED,eval-sanitize-5-r3-041,phase=Complete job=None
60.0618,TaskRequest,ADDED,eval-sanitize-5-r3-042,phase=Complete job=None
60.0627,Job,ADDED,eval-sanitize-5-r3-011,
60.0635,Event,ADDED,eval-sanitize-5-r1-045-bpmp6.18d3d3dfb36e280b,"reason=FailedScheduling count=None msg=0/6 nodes are available: 1 c_wall violated: 2 conflicting context pair(s) with node memory, 5 node(s) had untolerated taint(s). no new claims to deallocate, preemption: 0/6 nodes are available: 1 No preemption victims found for incoming pod, 5 Preemption is not helpful for scheduling."
60.0637,Event,ADDED,eval-sanitize-5-r1-046-7nrqt.18d3d3de888c4e53,"reason=FailedScheduling count=None msg=0/6 nodes are available: 1 c_wall violated: 1 conflicting context pair(s) with node memory, 5 node(s) had untolerated taint(s). no new claims to deallocate, preemption: 0/6 nodes are available: 1 No preemption victims found for incoming pod, 5 Preemption is not helpful for scheduling."
60.0639,Event,ADDED,eval-sanitize-5-r1-048-7mtx6.18d3d3deffadaa2b,"reason=FailedScheduling count=None msg=0/6 nodes are available: 1 c_wall violated: 2 conflicting context pair(s) with node memory, 5 node(s) had untolerated taint(s). no new claims to deallocate, preemption: 0/6 nodes are available: 1 No preemption victims found for incoming pod, 5 Preemption is not helpful for scheduling."
60.0651,Pod,ADDED,eval-sanitize-5-r3-006-wjlsd,phase=Succeeded node=kind-worker3
60.0652,TaskRequest,ADDED,eval-sanitize-5-r3-043,phase=Scheduled job=None
60.0652,TaskRequest,ADDED,eval-sanitize-5-r3-044,phase=Scheduled job=None
60.0661,Job,ADDED,eval-sanitize-5-r3-012,
60.0665,Event,ADDED,eval-sanitize-5-r1-054-jzsg6.18d3d3e0b85dfe2b,"reason=FailedScheduling count=None msg=0/6 nodes are available: 1 c_wall violated: 2 conflicting context pair(s) with node memory, 5 node(s) had untolerated taint(s). no new claims to deallocate, preemption: 0/6 nodes are available: 1 No preemption victims found for incoming pod, 5 Preemption is not helpful for scheduling."
60.0668,Event,ADDED,eval-sanitize-5-r1-063-g82fq.18d3d3e27e1ac4e6,"reason=FailedScheduling count=None msg=0/6 nodes are available: 1 c_wall violated: 1 conflicting context pair(s) with node memory, 5 node(s) had untolerated taint(s). no new claims to deallocate, preemption: 0/6 nodes are available: 1 No preemption victims found for incoming pod, 5 Preemption is not helpful for scheduling."
60.0669,Event,ADDED,eval-sanitize-5-r1-063-g82fq.18d3d3e2f62abe5d,"reason=FailedScheduling count=None msg=0/6 nodes are available: 1 c_wall violated: 2 conflicting context pair(s) with node memory, 5 node(s) had untolerated taint(s). no new claims to deallocate, preemption: 0/6 nodes are available: 1 No preemption victims found for incoming pod, 5 Preemption is not helpful for scheduling."
60.067,TaskRequest,ADDED,eval-sanitize-5-r3-045,phase=Scheduled job=None
60.0671,TaskRequest,ADDED,eval-sanitize-5-r3-046,phase=Scheduled job=None
60.0673,TaskRequest,ADDED,eval-sanitize-5-r3-047,phase=Scheduled job=None
60.0685,Pod,ADDED,eval-sanitize-5-r3-007-4m9hq,phase=Succeeded node=kind-worker5
60.0688,Event,ADDED,eval-sanitize-5-r1-064-4cqk5.18d3d3e2b929b514,"reason=FailedScheduling count=None msg=0/6 nodes are available: 1 c_wall violated: 1 conflicting context pair(s) with node memory, 5 node(s) had untolerated taint(s). no new claims to deallocate, preemption: 0/6 nodes are available: 1 No preemption victims found for incoming pod, 5 Preemption is not helpful for scheduling."
60.069,Event,ADDED,eval-sanitize-5-r1-066-bblxb.18d3d3e3ea4e297c,"reason=FailedScheduling count=None msg=0/6 nodes are available: 1 c_wall violated: 3 conflicting context pair(s) with node memory, 5 node(s) had untolerated taint(s). no new claims to deallocate, preemption: 0/6 nodes are available: 1 No preemption victims found for incoming pod, 5 Preemption is not helpful for scheduling."
60.0692,Event,ADDED,eval-sanitize-5-r1-067-msll8.18d3d3e3ea7900c5,"reason=FailedScheduling count=None msg=0/6 nodes are available: 1 c_wall violated: 2 conflicting context pair(s) with node memory, 5 node(s) had untolerated taint(s). no new claims to deallocate, preemption: 0/6 nodes are available: 1 No preemption victims found for incoming pod, 5 Preemption is not helpful for scheduling."
60.0693,TaskRequest,ADDED,eval-sanitize-5-r3-048,phase=Scheduled job=None
60.0693,TaskRequest,ADDED,eval-sanitize-5-r3-049,phase=Scheduled job=None
60.0693,TaskRequest,ADDED,eval-sanitize-5-r3-050,phase=Scheduled job=None
60.0702,Job,ADDED,eval-sanitize-5-r3-013,
60.0714,Pod,ADDED,eval-sanitize-5-r3-008-l6qpn,phase=Succeeded node=kind-worker5
60.0718,Event,ADDED,eval-sanitize-5-r1-070-9w8fw.18d3d3e41f0bee3c,"reason=FailedScheduling count=None msg=0/6 nodes are available: 1 c_wall violated: 1 conflicting context pair(s) with node memory, 5 node(s) had untolerated taint(s). no new claims to deallocate, preemption: 0/6 nodes are available: 1 No preemption victims found for incoming pod, 5 Preemption is not helpful for scheduling."
60.072,Event,ADDED,eval-sanitize-5-r1-072-pk7p4.18d3d3e496109a5b,"reason=FailedScheduling count=None msg=0/6 nodes are available: 2 c_wall violated: 2 conflicting context pair(s) with node memory, 4 node(s) had untolerated taint(s). no new claims to deallocate, preemption: 0/6 nodes are available: 2 No preemption victims found for incoming pod, 4 Preemption is not helpful for scheduling."
60.0722,Event,ADDED,eval-sanitize-5-r1-075-89cdl.18d3d3e54a9b5e97,"reason=FailedScheduling count=None msg=0/6 nodes are available: 2 c_wall violated: 1 conflicting context pair(s) with node memory, 4 node(s) had untolerated taint(s). no new claims to deallocate, preemption: 0/6 nodes are available: 2 No preemption victims found for incoming pod, 4 Preemption is not helpful for scheduling."
60.0723,TaskRequest,ADDED,eval-sanitize-5-r3-051,phase=Scheduled job=None
60.0724,TaskRequest,ADDED,eval-sanitize-5-r3-052,phase=Scheduled job=None
60.0724,TaskRequest,ADDED,eval-sanitize-5-r3-053,phase=Scheduled job=None
60.0732,Job,ADDED,eval-sanitize-5-r3-014,
60.0735,Event,ADDED,eval-sanitize-5-r1-075-89cdl.18d3d3e5827ab1d7,"reason=FailedScheduling count=None msg=0/6 nodes are available: 1 c_wall violated: 1 conflicting context pair(s) with node memory, 5 node(s) had untolerated taint(s). no new claims to deallocate, preemption: 0/6 nodes are available: 1 No preemption victims found for incoming pod, 5 Preemption is not helpful for scheduling."
60.0737,Event,ADDED,eval-sanitize-5-r1-075-89cdl.18d3d3e5e1181c47,"reason=FailedScheduling count=None msg=0/6 nodes are available: 1 c_wall violated: 1 conflicting context pair(s) with node memory, 5 node(s) had untolerated taint(s). no new claims to deallocate, preemption: 0/6 nodes are available: 1 No preemption victims found for incoming pod, 5 Preemption is not helpful for scheduling."
60.0739,Event,ADDED,eval-sanitize-5-r1-075-89cdl.18d3d3e67485c365,"reason=FailedScheduling count=None msg=0/6 nodes are available: 1 c_wall violated: 2 conflicting context pair(s) with node memory, 5 node(s) had untolerated taint(s). no new claims to deallocate, preemption: 0/6 nodes are available: 1 No preemption victims found for incoming pod, 5 Preemption is not helpful for scheduling."
60.074,TaskRequest,ADDED,eval-sanitize-5-r3-054,phase=Scheduled job=None
60.074,TaskRequest,ADDED,eval-sanitize-5-r3-055,phase=Scheduled job=None
60.0755,Pod,ADDED,eval-sanitize-5-r3-009-m59w9,phase=Succeeded node=kind-worker5
60.0758,Event,ADDED,eval-sanitize-5-r1-076-l92hp.18d3d3e5850724ab,"reason=FailedScheduling count=None msg=0/6 nodes are available: 1 c_wall violated: 1 conflicting context pair(s) with node memory, 5 node(s) had untolerated taint(s). no new claims to deallocate, preemption: 0/6 nodes are available: 1 No preemption victims found for incoming pod, 5 Preemption is not helpful for scheduling."
60.076,Event,ADDED,eval-sanitize-5-r1-077-vcqz4.18d3d3e5c044ecb0,"reason=FailedScheduling count=None msg=0/6 nodes are available: 1 c_wall violated: 1 conflicting context pair(s) with node memory, 5 node(s) had untolerated taint(s). no new claims to deallocate, preemption: 0/6 nodes are available: 1 No preemption victims found for incoming pod, 5 Preemption is not helpful for scheduling."
60.0767,Job,ADDED,eval-sanitize-5-r3-015,
60.0768,TaskRequest,ADDED,eval-sanitize-5-r3-056,phase=Scheduled job=None
60.0769,TaskRequest,ADDED,eval-sanitize-5-r3-057,phase=Scheduled job=None
60.0769,TaskRequest,ADDED,eval-sanitize-5-r3-058,phase=Scheduled job=None
60.0776,Event,ADDED,eval-sanitize-5-r1-078-l7vbp.18d3d3e5fc7ca2da,"reason=FailedScheduling count=None msg=0/6 nodes are available: 1 c_wall violated: 1 conflicting context pair(s) with node memory, 5 node(s) had untolerated taint(s). no new claims to deallocate, preemption: 0/6 nodes are available: 1 No preemption victims found for incoming pod, 5 Preemption is not helpful for scheduling."
60.0779,Event,ADDED,eval-sanitize-5-r1-078-l7vbp.18d3d3e674532dfc,"reason=FailedScheduling count=None msg=0/6 nodes are available: 1 c_wall violated: 2 conflicting context pair(s) with node memory, 5 node(s) had untolerated taint(s). no new claims to deallocate, preemption: 0/6 nodes are available: 1 No preemption victims found for incoming pod, 5 Preemption is not helpful for scheduling."
60.0782,Event,ADDED,eval-sanitize-5-r1-081-bwbks.18d3d3e6af031e36,"reason=FailedScheduling count=None msg=0/6 nodes are available: 1 c_wall violated: 4 conflicting context pair(s) with node memory, 5 node(s) had untolerated taint(s). no new claims to deallocate, preemption: 0/6 nodes are available: 1 No preemption victims found for incoming pod, 5 Preemption is not helpful for scheduling."
60.0783,TaskRequest,ADDED,eval-sanitize-5-r3-059,phase=Scheduled job=None
60.0783,TaskRequest,ADDED,eval-sanitize-5-r3-060,phase=Pending job=None
60.0794,Pod,ADDED,eval-sanitize-5-r3-010-bppgt,phase=Succeeded node=kind-worker5
60.0802,Job,ADDED,eval-sanitize-5-r3-016,
60.0806,Event,ADDED,eval-sanitize-5-r1-082-gt58r.18d3d3e6ea30d6dd,"reason=FailedScheduling count=None msg=0/6 nodes are available: 1 c_wall violated: 1 conflicting context pair(s) with node memory, 1 c_wall violated: 3 conflicting context pair(s) with node memory, 4 node(s) had untolerated taint(s). no new claims to deallocate, preemption: 0/6 nodes are available: 2 No preemption victims found for incoming pod, 4 Preemption is not helpful for scheduling."
60.0808,Event,ADDED,eval-sanitize-5-r1-082-gt58r.18d3d3e71cc9cb8d,"reason=FailedScheduling count=None msg=0/6 nodes are available: 1 c_wall violated: 1 conflicting context pair(s) with node memory, 5 node(s) had untolerated taint(s). no new claims to deallocate, preemption: 0/6 nodes are available: 1 No preemption victims found for incoming pod, 5 Preemption is not helpful for scheduling."
60.081,Event,ADDED,eval-sanitize-5-r1-083-nl2zs.18d3d3e72586f396,"reason=FailedScheduling count=None msg=0/6 nodes are available: 1 c_wall violated: 2 conflicting context pair(s) with node memory, 5 node(s) had untolerated taint(s). no new claims to deallocate, preemption: 0/6 nodes are available: 1 No preemption victims found for incoming pod, 5 Preemption is not helpful for scheduling."
60.081,TaskRequest,MODIFIED,eval-sanitize-5-r3-060,phase=Scheduled job=None
60.0822,Job,ADDED,eval-sanitize-5-r3-017,
60.0824,Event,ADDED,eval-sanitize-5-r1-083-nl2zs.18d3d3e855f895dc,"reason=FailedScheduling count=None msg=0/6 nodes are available: 1 c_wall violated: 1 conflicting context pair(s) with node memory, 5 node(s) had untolerated taint(s). no new claims to deallocate, preemption: 0/6 nodes are available: 1 No preemption victims found for incoming pod, 5 Preemption is not helpful for scheduling."
60.0827,Event,ADDED,eval-sanitize-5-r1-084-qssxt.18d3d3e76279fffd,"reason=FailedScheduling count=None msg=0/6 nodes are available: 1 c_wall violated: 1 conflicting context pair(s) with node memory, 5 node(s) had untolerated taint(s). no new claims to deallocate, preemption: 0/6 nodes are available: 1 No preemption victims found for incoming pod, 5 Preemption is not helpful for scheduling."
60.0828,Event,ADDED,eval-sanitize-5-r1-085-hqp2x.18d3d3e79d270f80,"reason=FailedScheduling count=None msg=0/6 nodes are available: 1 c_wall violated: 1 conflicting context pair(s) with node memory, 5 node(s) had untolerated taint(s). no new claims to deallocate, preemption: 0/6 nodes are available: 1 No preemption victims found for incoming pod, 5 Preemption is not helpful for scheduling."
60.0829,TaskRequest,MODIFIED,eval-sanitize-5-r3-060,phase=Scheduled job=None
60.0839,Pod,ADDED,eval-sanitize-5-r3-011-kmvsv,phase=Succeeded node=kind-worker5
60.0846,Job,ADDED,eval-sanitize-5-r3-018,
60.0853,Job,ADDED,eval-sanitize-5-r3-019,
60.086,Job,ADDED,eval-sanitize-5-r3-020,
60.0866,Event,ADDED,eval-sanitize-5-r1-085-hqp2x.18d3d3e85a10954c,"reason=FailedScheduling count=None msg=0/6 nodes are available: 1 c_wall violated: 2 conflicting context pair(s) with node memory, 5 node(s) had untolerated taint(s). no new claims to deallocate, preemption: 0/6 nodes are available: 1 No preemption victims found for incoming pod, 5 Preemption is not helpful for scheduling."
60.087,Event,ADDED,eval-sanitize-5-r1-086-zg49q.18d3d3e7d97cebac,"reason=FailedScheduling count=None msg=0/6 nodes are available: 1 c_wall violated: 1 conflicting context pair(s) with node memory, 5 node(s) had untolerated taint(s). no new claims to deallocate, preemption: 0/6 nodes are available: 1 No preemption victims found for incoming pod, 5 Preemption is not helpful for scheduling."
60.0872,Event,ADDED,eval-sanitize-5-r1-086-zg49q.18d3d3e85ac9b01a,"reason=FailedScheduling count=None msg=0/6 nodes are available: 1 c_wall violated: 2 conflicting context pair(s) with node memory, 5 node(s) had untolerated taint(s). no new claims to deallocate, preemption: 0/6 nodes are available: 1 No preemption victims found for incoming pod, 5 Preemption is not helpful for scheduling."
60.0885,Pod,ADDED,eval-sanitize-5-r3-012-64j5t,phase=Succeeded node=kind-worker2
60.0892,Event,ADDED,eval-sanitize-5-r1-086-zg49q.18d3d3e8cf0cd35c,"reason=FailedScheduling count=None msg=0/6 nodes are available: 2 c_wall violated: 2 conflicting context pair(s) with node memory, 4 node(s) had untolerated taint(s). no new claims to deallocate, preemption: 0/6 nodes are available: 2 No preemption victims found for incoming pod, 4 Preemption is not helpful for scheduling."
60.0894,Event,ADDED,eval-sanitize-5-r1-087-4rjqj.18d3d3e859c2e345,"reason=FailedScheduling count=None msg=0/6 nodes are available: 1 c_wall violated: 1 conflicting context pair(s) with node memory, 5 node(s) had untolerated taint(s). no new claims to deallocate, preemption: 0/6 nodes are available: 1 No preemption victims found for incoming pod, 5 Preemption is not helpful for scheduling."
60.0896,Event,ADDED,eval-sanitize-5-r1-089-z85qm.18d3d3e88b82bf7d,"reason=FailedScheduling count=None msg=0/6 nodes are available: 1 c_wall violated: 1 conflicting context pair(s) with node memory, 5 node(s) had untolerated taint(s). no new claims to deallocate, preemption: 0/6 nodes are available: 1 No preemption victims found for incoming pod, 5 Preemption is not helpful for scheduling."
60.0898,Event,ADDED,eval-sanitize-5-r1-089-z85qm.18d3d3e8cf55dfb1,"reason=FailedScheduling count=None msg=0/6 nodes are available: 1 c_wall violated: 1 conflicting context pair(s) with node memory, 1 c_wall violated: 2 conflicting context pair(s) with node memory, 4 node(s) had untolerated taint(s). no new claims to deallocate, preemption: 0/6 nodes are available: 2 No preemption victims found for incoming pod, 4 Preemption is not helpful for scheduling."
60.09,Event,ADDED,eval-sanitize-5-r1-089-z85qm.18d3d3e93fd23a4b,"reason=FailedScheduling count=None msg=0/6 nodes are available: 1 c_wall violated: 2 conflicting context pair(s) with node memory, 2 c_wall violated: 1 conflicting context pair(s) with node memory, 3 node(s) had untolerated taint(s). no new claims to deallocate, preemption: 0/6 nodes are available: 3 No preemption victims found for incoming pod, 3 Preemption is not helpful for scheduling."
60.0908,Job,ADDED,eval-sanitize-5-r3-021,
60.0918,Pod,ADDED,eval-sanitize-5-r3-013-lk4lx,phase=Succeeded node=kind-worker5
60.0921,Event,ADDED,eval-sanitize-5-r1-089-z85qm.18d3d3e985d23b1b,"reason=FailedScheduling count=None msg=0/6 nodes are available: 1 c_wall violated: 1 conflicting context pair(s) with node memory, 1 c_wall violated: 2 conflicting context pair(s) with node memory, 4 node(s) had untolerated taint(s). no new claims to deallocate, preemption: 0/6 nodes are available: 2 No preemption victims found for incoming pod, 4 Preemption is not helpful for scheduling."
60.0923,Event,ADDED,eval-sanitize-5-r1-096-lnqcz.18d3d3ea2ce106b8,"reason=FailedScheduling count=None msg=0/6 nodes are available: 2 c_wall violated: 1 conflicting context pair(s) with node memory, 4 node(s) had untolerated taint(s). no new claims to deallocate, preemption: 0/6 nodes are available: 2 No preemption victims found for incoming pod, 4 Preemption is not helpful for scheduling."
60.0925,Event,ADDED,eval-sanitize-5-r1-096-lnqcz.18d3d3ea61186260,"reason=FailedScheduling count=None msg=0/6 nodes are available: 1 c_wall violated: 1 conflicting context pair(s) with node memory, 5 node(s) had untolerated taint(s). no new claims to deallocate, preemption: 0/6 nodes are available: 1 No preemption victims found for incoming pod, 5 Preemption is not helpful for scheduling."
60.0932,Job,ADDED,eval-sanitize-5-r3-022,
60.0942,Pod,ADDED,eval-sanitize-5-r3-014-blrpd,phase=Succeeded node=kind-worker2
60.0945,Event,ADDED,eval-sanitize-5-r1-097-st9pk.18d3d3ea680cbdde,"reason=FailedScheduling count=None msg=0/6 nodes are available: 1 c_wall violated: 1 conflicting context pair(s) with node memory, 5 node(s) had untolerated taint(s). no new claims to deallocate, preemption: 0/6 nodes are available: 1 No preemption victims found for incoming pod, 5 Preemption is not helpful for scheduling."
60.0947,Event,ADDED,eval-sanitize-5-r1-097-st9pk.18d3d3ea83516413,"reason=FailedScheduling count=None msg=0/6 nodes are available: 2 c_wall violated: 1 conflicting context pair(s) with node memory, 4 node(s) had untolerated taint(s). no new claims to deallocate, preemption: 0/6 nodes are available: 2 No preemption victims found for incoming pod, 4 Preemption is not helpful for scheduling."
60.0949,Event,ADDED,eval-sanitize-5-r1-097-st9pk.18d3d3eac5cb7f1c,"reason=FailedScheduling count=None msg=0/6 nodes are available: 1 c_wall violated: 1 conflicting context pair(s) with node memory, 5 node(s) had untolerated taint(s). no new claims to deallocate, preemption: 0/6 nodes are available: 1 No preemption victims found for incoming pod, 5 Preemption is not helpful for scheduling."
60.0957,Job,ADDED,eval-sanitize-5-r3-023,
60.0963,Job,ADDED,eval-sanitize-5-r3-024,
60.0966,Event,ADDED,eval-sanitize-5-r1-099-jc44k.18d3d3eadf7939d6,"reason=FailedScheduling count=None msg=0/6 nodes are available: 1 c_wall violated: 1 conflicting context pair(s) with node memory, 5 node(s) had untolerated taint(s). no new claims to deallocate, preemption: 0/6 nodes are available: 1 No preemption victims found for incoming pod, 5 Preemption is not helpful for scheduling."
60.0968,Event,ADDED,eval-sanitize-5-r3-000-2jwwc.18d3d463b1ea2104,reason=Scheduled count=None msg=Successfully assigned compute/eval-sanitize-5-r3-000-2jwwc to kind-worker2
60.0969,Event,ADDED,eval-sanitize-5-r3-000-2jwwc.18d3d463ccdd814b,"reason=Pulled count=1 msg=Container image ""busybox:musl"" already present on machine"
60.0976,Job,ADDED,eval-sanitize-5-r3-025,
60.0985,Job,ADDED,eval-sanitize-5-r3-026,
60.099,Event,ADDED,eval-sanitize-5-r3-000-2jwwc.18d3d463cdf49a40,reason=Created count=1 msg=Created container: task
60.0991,Event,ADDED,eval-sanitize-5-r3-000-2jwwc.18d3d463d1a061b7,reason=Started count=1 msg=Started container task
60.0993,Event,ADDED,eval-sanitize-5-r3-000.18d3d463b10db58a,reason=SuccessfulCreate count=1 msg=Created pod: eval-sanitize-5-r3-000-2jwwc
60.0995,Event,ADDED,eval-sanitize-5-r3-000.18d3d466e838b9f1,reason=Completed count=1 msg=Job completed
60.1002,Job,ADDED,eval-sanitize-5-r3-027,
60.1013,Pod,ADDED,eval-sanitize-5-r3-015-x7rh2,phase=Succeeded node=kind-worker5
60.1016,Event,ADDED,eval-sanitize-5-r3-001-kbq6c.18d3d463ebd1dee3,reason=Scheduled count=None msg=Successfully assigned compute/eval-sanitize-5-r3-001-kbq6c to kind-worker
60.1018,Event,ADDED,eval-sanitize-5-r3-001-kbq6c.18d3d464055c026c,"reason=Pulled count=1 msg=Container image ""busybox:musl"" already present on machine"
60.1019,Event,ADDED,eval-sanitize-5-r3-001-kbq6c.18d3d464066de005,reason=Created count=1 msg=Created container: task
60.1027,Job,ADDED,eval-sanitize-5-r3-028,
60.1038,Pod,ADDED,eval-sanitize-5-r3-016-5jw6h,phase=Succeeded node=kind-worker2
60.1041,Event,ADDED,eval-sanitize-5-r3-001-kbq6c.18d3d464085c960c,reason=Started count=1 msg=Started container task
60.1043,Event,ADDED,eval-sanitize-5-r3-001.18d3d463eb50c00d,reason=SuccessfulCreate count=1 msg=Created pod: eval-sanitize-5-r3-001-kbq6c
60.1045,Event,ADDED,eval-sanitize-5-r3-001.18d3d46745af58be,reason=Completed count=1 msg=Job completed
60.1046,Event,ADDED,eval-sanitize-5-r3-002-lxfh7.18d3d46426db6c9b,reason=Scheduled count=None msg=Successfully assigned compute/eval-sanitize-5-r3-002-lxfh7 to kind-worker4
60.105,Event,ADDED,eval-sanitize-5-r3-002-lxfh7.18d3d4644036fc70,"reason=Pulled count=1 msg=Container image ""busybox:musl"" already present on machine"
60.1051,Event,ADDED,eval-sanitize-5-r3-002-lxfh7.18d3d464415ed76c,reason=Created count=1 msg=Created container: task
60.1053,Event,ADDED,eval-sanitize-5-r3-002-lxfh7.18d3d46443997964,reason=Started count=1 msg=Started container task
60.1055,Event,ADDED,eval-sanitize-5-r3-002.18d3d4642651beac,reason=SuccessfulCreate count=1 msg=Created pod: eval-sanitize-5-r3-002-lxfh7
60.1063,Job,ADDED,eval-sanitize-5-r3-029,
60.1073,Pod,ADDED,eval-sanitize-5-r3-017-hs5c9,phase=Succeeded node=kind-worker5
60.1076,Event,ADDED,eval-sanitize-5-r3-002.18d3d4675a245eec,reason=Completed count=1 msg=Job completed
60.1077,Event,ADDED,eval-sanitize-5-r3-003-9sqzh.18d3d46463011098,reason=Scheduled count=None msg=Successfully assigned compute/eval-sanitize-5-r3-003-9sqzh to kind-worker5
60.1079,Event,ADDED,eval-sanitize-5-r3-003-9sqzh.18d3d4647cc55c65,"reason=Pulled count=1 msg=Container image ""busybox:musl"" already present on machine"
60.1081,Event,ADDED,eval-sanitize-5-r3-003-9sqzh.18d3d4647df7e5c6,reason=Created count=1 msg=Created container: task
60.1083,Event,ADDED,eval-sanitize-5-r3-003-9sqzh.18d3d4648182974f,reason=Started count=1 msg=Started container task
60.1084,Event,ADDED,eval-sanitize-5-r3-003.18d3d464620ae9c7,reason=SuccessfulCreate count=1 msg=Created pod: eval-sanitize-5-r3-003-9sqzh
60.1086,Event,ADDED,eval-sanitize-5-r3-003.18d3d46796c49864,reason=Completed count=1 msg=Job completed
60.1088,Event,ADDED,eval-sanitize-5-r3-004-th9rv.18d3d4649efde220,reason=Scheduled count=None msg=Successfully assigned compute/eval-sanitize-5-r3-004-th9rv to kind-worker4
60.1089,Event,ADDED,eval-sanitize-5-r3-004-th9rv.18d3d464b8e93239,"reason=Pulled count=1 msg=Container image ""busybox:musl"" already present on machine"
60.1091,Event,ADDED,eval-sanitize-5-r3-004-th9rv.18d3d464ba0fde3f,reason=Created count=1 msg=Created container: task
60.1093,Event,ADDED,eval-sanitize-5-r3-004-th9rv.18d3d464be3009f0,reason=Started count=1 msg=Started container task
60.11,Job,ADDED,eval-sanitize-5-r3-030,
60.111,Pod,ADDED,eval-sanitize-5-r3-018-pndjq,phase=Succeeded node=kind-worker
60.1112,Event,ADDED,eval-sanitize-5-r3-004.18d3d4649dbce72e,reason=SuccessfulCreate count=1 msg=Created pod: eval-sanitize-5-r3-004-th9rv
60.1114,Event,ADDED,eval-sanitize-5-r3-004.18d3d467d1bd364a,reason=Completed count=1 msg=Job completed
60.1116,Event,ADDED,eval-sanitize-5-r3-005-cqc9r.18d3d464d9e2bc57,reason=Scheduled count=None msg=Successfully assigned compute/eval-sanitize-5-r3-005-cqc9r to kind-worker3
60.1134,Job,ADDED,eval-sanitize-5-r3-031,
60.1141,Job,ADDED,eval-sanitize-5-r3-032,
60.1144,Event,ADDED,eval-sanitize-5-r3-005-cqc9r.18d3d464f322673b,"reason=Pulled count=1 msg=Container image ""busybox:musl"" already present on machine"
60.1146,Event,ADDED,eval-sanitize-5-r3-005-cqc9r.18d3d464f478b4b0,reason=Created count=1 msg=Created container: task
60.1148,Event,ADDED,eval-sanitize-5-r3-005-cqc9r.18d3d464f6a835da,reason=Started count=1 msg=Started container task
60.1149,Event,ADDED,eval-sanitize-5-r3-005.18d3d464d911d6e2,reason=SuccessfulCreate count=1 msg=Created pod: eval-sanitize-5-r3-005-cqc9r
60.116,Pod,ADDED,eval-sanitize-5-r3-019-dq89j,phase=Succeeded node=kind-worker2
60.1171,Job,ADDED,eval-sanitize-5-r3-033,
60.1177,Job,ADDED,eval-sanitize-5-r3-034,
60.1184,Pod,ADDED,eval-sanitize-5-r3-020-m7rv7,phase=Succeeded node=kind-worker
60.1187,Event,ADDED,eval-sanitize-5-r3-005.18d3d4680dc26095,reason=Completed count=1 msg=Job completed
60.1189,Event,ADDED,eval-sanitize-5-r3-006-wjlsd.18d3d4651570f66d,reason=Scheduled count=None msg=Successfully assigned compute/eval-sanitize-5-r3-006-wjlsd to kind-worker3
60.1191,Event,ADDED,eval-sanitize-5-r3-006-wjlsd.18d3d4652f9a764e,"reason=Pulled count=1 msg=Container image ""busybox:musl"" already present on machine"
60.1192,Event,ADDED,eval-sanitize-5-r3-006-wjlsd.18d3d46530b2dd7b,reason=Created count=1 msg=Created container: task
60.12,Job,ADDED,eval-sanitize-5-r3-035,
60.1206,Job,ADDED,eval-sanitize-5-r3-036,
60.1213,Job,ADDED,eval-sanitize-5-r3-037,
60.1216,Event,ADDED,eval-sanitize-5-r3-006-wjlsd.18d3d46532c1f659,reason=Started count=1 msg=Started container task
60.1218,Event,ADDED,eval-sanitize-5-r3-006.18d3d46514c8a1ad,reason=SuccessfulCreate count=1 msg=Created pod: eval-sanitize-5-r3-006-wjlsd
60.1219,Event,ADDED,eval-sanitize-5-r3-006.18d3d46849ed350c,reason=Completed count=1 msg=Job completed
60.123,Pod,ADDED,eval-sanitize-5-r3-021-gbb9r,phase=Succeeded node=kind-worker4
60.1237,Job,ADDED,eval-sanitize-5-r3-038,
60.124,Event,ADDED,eval-sanitize-5-r3-007-4m9hq.18d3d46550bce1ce,"reason=FailedScheduling count=None msg=0/6 nodes are available: 1 c_wall violated: 2 conflicting context pair(s) with node memory, 5 node(s) had untolerated taint(s). no new claims to deallocate, preemption: 0/6 nodes are available: 1 No preemption victims found for incoming pod, 5 Preemption is not helpful for scheduling."
60.1242,Event,ADDED,eval-sanitize-5-r3-007-4m9hq.18d3d4655142e856,"reason=FailedScheduling count=None msg=0/6 nodes are available: 1 c_wall violated: 2 conflicting context pair(s) with node memory, 5 node(s) had untolerated taint(s). no new claims to deallocate, preemption: 0/6 nodes are available: 1 No preemption victims found for incoming pod, 5 Preemption is not helpful for scheduling."
60.1244,Event,ADDED,eval-sanitize-5-r3-007-4m9hq.18d3d4674dffebaa,reason=Scheduled count=None msg=Successfully assigned compute/eval-sanitize-5-r3-007-4m9hq to kind-worker5
60.1246,Event,ADDED,eval-sanitize-5-r3-007-4m9hq.18d3d46769e29b6c,"reason=Pulled count=1 msg=Container image ""busybox:musl"" already present on machine"
60.1261,Event,ADDED,eval-sanitize-5-r3-007-4m9hq.18d3d4676bb9aed0,reason=Created count=1 msg=Created container: task
60.1263,Event,ADDED,eval-sanitize-5-r3-007-4m9hq.18d3d4676e17bfb5,reason=Started count=1 msg=Started container task
60.1265,Event,ADDED,eval-sanitize-5-r3-007.18d3d465507851ce,reason=SuccessfulCreate count=1 msg=Created pod: eval-sanitize-5-r3-007-4m9hq
60.1271,Pod,ADDED,eval-sanitize-5-r3-022-62z7n,phase=Succeeded node=kind-worker3
60.1275,Event,ADDED,eval-sanitize-5-r3-007.18d3d46aa0aa91ab,reason=Completed count=1 msg=Job completed
60.1277,Event,ADDED,eval-sanitize-5-r3-008-l6qpn.18d3d4658c453200,"reason=FailedScheduling count=None msg=0/6 nodes are available: 1 c_wall violated: 2 conflicting context pair(s) with node memory, 5 node(s) had untolerated taint(s). no new claims to deallocate, preemption: 0/6 nodes are available: 1 No preemption victims found for incoming pod, 5 Preemption is not helpful for scheduling."
60.1279,Event,ADDED,eval-sanitize-5-r3-008-l6qpn.18d3d4658cd85016,"reason=FailedScheduling count=None msg=0/6 nodes are available: 1 c_wall violated: 2 conflicting context pair(s) with node memory, 5 node(s) had untolerated taint(s). no new claims to deallocate, preemption: 0/6 nodes are available: 1 No preemption victims found for incoming pod, 5 Preemption is not helpful for scheduling."
60.1287,Job,ADDED,eval-sanitize-5-r3-039,
60.129,Event,ADDED,eval-sanitize-5-r3-008-l6qpn.18d3d4674e91ea24,reason=Scheduled count=None msg=Successfully assigned compute/eval-sanitize-5-r3-008-l6qpn to kind-worker5
60.1291,Event,ADDED,eval-sanitize-5-r3-008-l6qpn.18d3d4676c4f6d61,"reason=Pulled count=1 msg=Container image ""busybox:musl"" already present on machine"
60.1293,Event,ADDED,eval-sanitize-5-r3-008-l6qpn.18d3d4676fb44ad7,reason=Created count=1 msg=Created container: task
60.1295,Event,ADDED,eval-sanitize-5-r3-008-l6qpn.18d3d46773ee5acc,reason=Started count=1 msg=Started container task
60.1304,Job,ADDED,eval-sanitize-5-r3-040,
60.1316,Pod,ADDED,eval-sanitize-5-r3-023-rzr46,phase=Succeeded node=kind-worker5
60.1319,Event,ADDED,eval-sanitize-5-r3-008.18d3d4658bfe781d,reason=SuccessfulCreate count=1 msg=Created pod: eval-sanitize-5-r3-008-l6qpn
60.1321,Event,ADDED,eval-sanitize-5-r3-008.18d3d46ae19ec322,reason=Completed count=1 msg=Job completed
60.1323,Event,ADDED,eval-sanitize-5-r3-009-m59w9.18d3d465c7c67454,"reason=FailedScheduling count=None msg=0/6 nodes are available: 6 node(s) had untolerated taint(s). no new claims to deallocate, preemption: 0/6 nodes are available: 6 Preemption is not helpful for scheduling."
60.1324,Event,ADDED,eval-sanitize-5-r3-009-m59w9.18d3d4674efacde6,reason=Scheduled count=None msg=Successfully assigned compute/eval-sanitize-5-r3-009-m59w9 to kind-worker5
60.1336,Pod,ADDED,eval-sanitize-5-r3-024-c56sv,phase=Succeeded node=kind-worker3
60.134,Event,ADDED,eval-sanitize-5-r3-009-m59w9.18d3d4676bd2dd0b,"reason=Pulled count=1 msg=Container image ""busybox:musl"" already present on machine"
60.1342,Event,ADDED,eval-sanitize-5-r3-009-m59w9.18d3d4676e5869c6,reason=Created count=1 msg=Created container: task
60.1344,Event,ADDED,eval-sanitize-5-r3-009-m59w9.18d3d467729f45c9,reason=Started count=1 msg=Started container task
60.1352,Job,ADDED,eval-sanitize-5-r3-041,
60.1369,Event,ADDED,eval-sanitize-5-r3-009.18d3d465c7c568a7,reason=SuccessfulCreate count=1 msg=Created pod: eval-sanitize-5-r3-009-m59w9
60.1372,Event,ADDED,eval-sanitize-5-r3-009.18d3d46ae44b5695,reason=Completed count=1 msg=Job completed
60.1374,Event,ADDED,eval-sanitize-5-r3-010-bppgt.18d3d466032e0625,"reason=FailedScheduling count=None msg=0/6 nodes are available: 6 node(s) had untolerated taint(s). no new claims to deallocate, preemption: 0/6 nodes are available: 6 Preemption is not helpful for scheduling."
60.1375,Event,ADDED,eval-sanitize-5-r3-010-bppgt.18d3d4674f2b9514,reason=Scheduled count=None msg=Successfully assigned compute/eval-sanitize-5-r3-010-bppgt to kind-worker5
60.1383,Job,ADDED,eval-sanitize-5-r3-042,
60.1394,Pod,ADDED,eval-sanitize-5-r3-025-v6v64,phase=Succeeded node=kind-worker4
60.1397,Event,ADDED,eval-sanitize-5-r3-010-bppgt.18d3d4676c675974,"reason=Pulled count=1 msg=Container image ""busybox:musl"" already present on machine"
60.1398,Event,ADDED,eval-sanitize-5-r3-010-bppgt.18d3d467704808f9,reason=Created count=1 msg=Created container: task
60.14,Event,ADDED,eval-sanitize-5-r3-010-bppgt.18d3d46773ec128d,reason=Started count=1 msg=Started container task
60.1402,Event,ADDED,eval-sanitize-5-r3-010.18d3d46603226b3a,reason=SuccessfulCreate count=1 msg=Created pod: eval-sanitize-5-r3-010-bppgt
60.1413,Pod,ADDED,eval-sanitize-5-r3-026-hghxc,phase=Succeeded node=kind-worker2
60.1416,Event,ADDED,eval-sanitize-5-r3-010.18d3d46a66d6b368,reason=Completed count=1 msg=Job completed
60.1419,Event,ADDED,eval-sanitize-5-r3-011-kmvsv.18d3d4663e9fac9c,"reason=FailedScheduling count=None msg=0/6 nodes are available: 6 node(s) had untolerated taint(s). no new claims to deallocate, preemption: 0/6 nodes are available: 6 Preemption is not helpful for scheduling."
60.142,Event,ADDED,eval-sanitize-5-r3-011-kmvsv.18d3d4674f2a0507,reason=Scheduled count=None msg=Successfully assigned compute/eval-sanitize-5-r3-011-kmvsv to kind-worker5
60.1422,Event,ADDED,eval-sanitize-5-r3-011-kmvsv.18d3d4676c05b65a,"reason=Pulled count=1 msg=Container image ""busybox:musl"" already present on machine"
60.1424,Event,ADDED,eval-sanitize-5-r3-011-kmvsv.18d3d4676e9ecc6c,reason=Created count=1 msg=Created container: task
60.1426,Event,ADDED,eval-sanitize-5-r3-011-kmvsv.18d3d467729b682e,reason=Started count=1 msg=Started container task
60.1428,Event,ADDED,eval-sanitize-5-r3-011.18d3d4663e941131,reason=SuccessfulCreate count=1 msg=Created pod: eval-sanitize-5-r3-011-kmvsv
60.143,Event,ADDED,eval-sanitize-5-r3-011.18d3d46aa0596d79,reason=Completed count=1 msg=Job completed
60.1432,Event,ADDED,eval-sanitize-5-r3-012-64j5t.18d3d4667a225cc7,"reason=FailedScheduling count=None msg=0/6 nodes are available: 6 node(s) had untolerated taint(s). no new claims to deallocate, preemption: 0/6 nodes are available: 6 Preemption is not helpful for scheduling."
60.1434,Event,ADDED,eval-sanitize-5-r3-012-64j5t.18d3d4674f00260c,"reason=FailedScheduling count=None msg=0/6 nodes are available: 1 c_wall violated: 3 conflicting context pair(s) with node memory, 5 node(s) had untolerated taint(s). no new claims to deallocate, preemption: 0/6 nodes are available: 1 No preemption victims found for incoming pod, 5 Preemption is not helpful for scheduling."
60.1443,Job,ADDED,eval-sanitize-5-r3-043,
60.1447,Event,ADDED,eval-sanitize-5-r3-012-64j5t.18d3d46755462c22,"reason=FailedScheduling count=None msg=0/6 nodes are available: 1 c_wall violated: 3 conflicting context pair(s) with node memory, 5 node(s) had untolerated taint(s). no new claims to deallocate, preemption: 0/6 nodes are available: 1 No preemption victims found for incoming pod, 5 Preemption is not helpful for scheduling."
60.1449,Event,ADDED,eval-sanitize-5-r3-012-64j5t.18d3d46760cab156,reason=Scheduled count=None msg=Successfully assigned compute/eval-sanitize-5-r3-012-64j5t to kind-worker2
60.1451,Event,ADDED,eval-sanitize-5-r3-012-64j5t.18d3d4677a8d6d34,"reason=Pulled count=1 msg=Container image ""busybox:musl"" already present on machine"
60.1453,Event,ADDED,eval-sanitize-5-r3-012-64j5t.18d3d4677c013c78,reason=Created count=1 msg=Created container: task
60.1455,Event,ADDED,eval-sanitize-5-r3-012-64j5t.18d3d4677e0ac225,reason=Started count=1 msg=Started container task
60.1456,Event,ADDED,eval-sanitize-5-r3-012.18d3d4667a167ff5,reason=SuccessfulCreate count=1 msg=Created pod: eval-sanitize-5-r3-012-64j5t
60.1458,Event,ADDED,eval-sanitize-5-r3-012.18d3d46af002eee0,reason=Completed count=1 msg=Job completed
60.146,Event,ADDED,eval-sanitize-5-r3-013-lk4lx.18d3d466b5ba0804,"reason=FailedScheduling count=None msg=0/6 nodes are available: 6 node(s) had untolerated taint(s). no new claims to deallocate, preemption: 0/6 nodes are available: 6 Preemption is not helpful for scheduling."
60.1462,Event,ADDED,eval-sanitize-5-r3-013-lk4lx.18d3d467501a6b5c,reason=Scheduled count=None msg=Successfully assigned compute/eval-sanitize-5-r3-013-lk4lx to kind-worker5
60.1464,Event,ADDED,eval-sanitize-5-r3-013-lk4lx.18d3d4676d0c76ca,"reason=Pulled count=1 msg=Container image ""busybox:musl"" already present on machine"
60.1466,Event,ADDED,eval-sanitize-5-r3-013-lk4lx.18d3d467708e5e71,reason=Created count=1 msg=Created container: task
60.1477,Pod,ADDED,eval-sanitize-5-r3-027-9ft5d,phase=Succeeded node=kind-worker5
60.1484,Job,ADDED,eval-sanitize-5-r3-044,
60.1487,Event,ADDED,eval-sanitize-5-r3-013-lk4lx.18d3d46773ef09e9,reason=Started count=1 msg=Started container task
60.1488,Event,ADDED,eval-sanitize-5-r3-013.18d3d466b5b01048,reason=SuccessfulCreate count=1 msg=Created pod: eval-sanitize-5-r3-013-lk4lx
60.149,Event,ADDED,eval-sanitize-5-r3-013.18d3d46aa0d436f1,reason=Completed count=1 msg=Job completed
60.1501,Pod,ADDED,eval-sanitize-5-r3-028-6xmxg,phase=Succeeded node=kind-worker5
60.1504,Event,ADDED,eval-sanitize-5-r3-014-blrpd.18d3d466f16f671b,"reason=FailedScheduling count=None msg=0/6 nodes are available: 6 node(s) had untolerated taint(s). no new claims to deallocate, preemption: 0/6 nodes are available: 6 Preemption is not helpful for scheduling."
60.1505,Event,ADDED,eval-sanitize-5-r3-014-blrpd.18d3d46754831316,"reason=FailedScheduling count=None msg=0/6 nodes are available: 1 c_wall violated: 3 conflicting context pair(s) with node memory, 5 node(s) had untolerated taint(s). no new claims to deallocate, preemption: 0/6 nodes are available: 1 No preemption victims found for incoming pod, 5 Preemption is not helpful for scheduling."
60.1507,Event,ADDED,eval-sanitize-5-r3-014-blrpd.18d3d467556ede3d,"reason=FailedScheduling count=None msg=0/6 nodes are available: 1 c_wall violated: 3 conflicting context pair(s) with node memory, 5 node(s) had untolerated taint(s). no new claims to deallocate, preemption: 0/6 nodes are available: 1 No preemption victims found for incoming pod, 5 Preemption is not helpful for scheduling."
60.1509,Event,ADDED,eval-sanitize-5-r3-014-blrpd.18d3d467623752eb,reason=Scheduled count=None msg=Successfully assigned compute/eval-sanitize-5-r3-014-blrpd to kind-worker2
60.1515,Job,ADDED,eval-sanitize-5-r3-045,
60.1521,Job,ADDED,eval-sanitize-5-r3-046,
60.1526,Job,ADDED,eval-sanitize-5-r3-047,
60.1532,Job,ADDED,eval-sanitize-5-r3-048,
60.1543,Pod,ADDED,eval-sanitize-5-r3-029-j9fgd,phase=Succeeded node=kind-worker2
60.1546,Event,ADDED,eval-sanitize-5-r3-014-blrpd.18d3d4677b360d3b,"reason=Pulled count=1 msg=Container image ""busybox:musl"" already present on machine"
60.1548,Event,ADDED,eval-sanitize-5-r3-014-blrpd.18d3d4677c9a020c,reason=Created count=1 msg=Created container: task
60.1549,Event,ADDED,eval-sanitize-5-r3-014-blrpd.18d3d4677ea2783f,reason=Started count=1 msg=Started container task
60.1561,Pod,ADDED,eval-sanitize-5-r3-030-9m4cf,phase=Succeeded node=kind-worker2
60.157,Pod,ADDED,eval-sanitize-5-r3-031-brmm4,phase=Succeeded node=kind-worker
60.1576,Event,ADDED,eval-sanitize-5-r3-014.18d3d466f1676676,reason=SuccessfulCreate count=1 msg=Created pod: eval-sanitize-5-r3-014-blrpd
60.1579,Event,ADDED,eval-sanitize-5-r3-014.18d3d46a675236ca,reason=Completed count=1 msg=Job completed
60.1581,Event,ADDED,eval-sanitize-5-r3-015-x7rh2.18d3d4672cda56b6,"reason=FailedScheduling count=None msg=0/6 nodes are available: 6 node(s) had untolerated taint(s). no new claims to deallocate, preemption: 0/6 nodes are available: 6 Preemption is not helpful for scheduling."
60.1582,Event,ADDED,eval-sanitize-5-r3-015-x7rh2.18d3d46755736dad,reason=Scheduled count=None msg=Successfully assigned compute/eval-sanitize-5-r3-015-x7rh2 to kind-worker5
60.1589,Job,ADDED,eval-sanitize-5-r3-049,
60.16,Pod,ADDED,eval-sanitize-5-r3-032-wdxmb,phase=Succeeded node=kind-worker2
60.1603,Event,ADDED,eval-sanitize-5-r3-015-x7rh2.18d3d4676e9fb357,"reason=Pulled count=1 msg=Container image ""busybox:musl"" already present on machine"
60.1605,Event,ADDED,eval-sanitize-5-r3-015-x7rh2.18d3d46770edb540,reason=Created count=1 msg=Created container: task
60.1607,Event,ADDED,eval-sanitize-5-r3-015-x7rh2.18d3d46773ee6e72,reason=Started count=1 msg=Started container task
60.1608,Event,ADDED,eval-sanitize-5-r3-015.18d3d4672cd02572,reason=SuccessfulCreate count=1 msg=Created pod: eval-sanitize-5-r3-015-x7rh2
60.1615,Job,ADDED,eval-sanitize-5-r3-050,
60.1617,Event,ADDED,eval-sanitize-5-r3-015.18d3d46aa124dfd0,reason=Completed count=1 msg=Job completed
60.1619,Event,ADDED,eval-sanitize-5-r3-016-5jw6h.18d3d4676b4fdf40,reason=Scheduled count=None msg=Successfully assigned compute/eval-sanitize-5-r3-016-5jw6h to kind-worker2
60.1621,Event,ADDED,eval-sanitize-5-r3-016-5jw6h.18d3d467848511dd,"reason=Pulled count=1 msg=Container image ""busybox:musl"" already present on machine"
60.1627,Job,ADDED,eval-sanitize-5-r3-051,
60.1629,Event,ADDED,eval-sanitize-5-r3-016-5jw6h.18d3d4678599e9da,reason=Created count=1 msg=Created container: task
60.1631,Event,ADDED,eval-sanitize-5-r3-016-5jw6h.18d3d46787e3652e,reason=Started count=1 msg=Started container task
60.1633,Event,ADDED,eval-sanitize-5-r3-016.18d3d46769c159ee,reason=SuccessfulCreate count=1 msg=Created pod: eval-sanitize-5-r3-016-5jw6h
60.1635,Event,ADDED,eval-sanitize-5-r3-016.18d3d46a67916cc5,reason=Completed count=1 msg=Job completed
60.1645,Pod,ADDED,eval-sanitize-5-r3-033-zg9jg,phase=Succeeded node=kind-worker2
60.1651,Job,ADDED,eval-sanitize-5-r3-052,
60.1653,Event,ADDED,eval-sanitize-5-r3-017-hs5c9.18d3d467a5608705,reason=Scheduled count=None msg=Successfully assigned compute/eval-sanitize-5-r3-017-hs5c9 to kind-worker5
60.1655,Event,ADDED,eval-sanitize-5-r3-017-hs5c9.18d3d467be753ff8,"reason=Pulled count=1 msg=Container image ""busybox:musl"" already present on machine"
60.1657,Event,ADDED,eval-sanitize-5-r3-017-hs5c9.18d3d467bf90099b,reason=Created count=1 msg=Created container: task
60.1659,Event,ADDED,eval-sanitize-5-r3-017-hs5c9.18d3d467c18c8953,reason=Started count=1 msg=Started container task
60.1669,Pod,ADDED,eval-sanitize-5-r3-034-tqzsg,phase=Succeeded node=kind-worker5
60.1672,Event,ADDED,eval-sanitize-5-r3-017.18d3d467a4a66b53,reason=SuccessfulCreate count=1 msg=Created pod: eval-sanitize-5-r3-017-hs5c9
60.1674,Event,ADDED,eval-sanitize-5-r3-017.18d3d46adcd3135d,reason=Completed count=1 msg=Job completed
60.1676,Event,ADDED,eval-sanitize-5-r3-018-pndjq.18d3d467e16c0f8b,reason=Scheduled count=None msg=Successfully assigned compute/eval-sanitize-5-r3-018-pndjq to kind-worker
60.1683,Job,ADDED,eval-sanitize-5-r3-053,
60.1686,Event,ADDED,eval-sanitize-5-r3-018-pndjq.18d3d467fa760a49,"reason=Pulled count=1 msg=Container image ""busybox:musl"" already present on machine"
60.1687,Event,ADDED,eval-sanitize-5-r3-018-pndjq.18d3d467fb9452a1,reason=Created count=1 msg=Created container: task
60.1689,Event,ADDED,eval-sanitize-5-r3-018-pndjq.18d3d467ff1caf9b,reason=Started count=1 msg=Started container task
60.1691,Event,ADDED,eval-sanitize-5-r3-018.18d3d467e0b23c51,reason=SuccessfulCreate count=1 msg=Created pod: eval-sanitize-5-r3-018-pndjq
60.1693,Event,ADDED,eval-sanitize-5-r3-018.18d3d46b419cf95b,reason=Completed count=1 msg=Job completed
60.1694,Event,ADDED,eval-sanitize-5-r3-019-dq89j.18d3d4681c3df8d1,reason=Scheduled count=None msg=Successfully assigned compute/eval-sanitize-5-r3-019-dq89j to kind-worker2
60.1696,Event,ADDED,eval-sanitize-5-r3-019-dq89j.18d3d46835267b00,"reason=Pulled count=1 msg=Container image ""busybox:musl"" already present on machine"
60.1698,Event,ADDED,eval-sanitize-5-r3-019-dq89j.18d3d468364a19f3,reason=Created count=1 msg=Created container: task
60.1703,Job,ADDED,eval-sanitize-5-r3-054,
60.1714,Pod,ADDED,eval-sanitize-5-r3-035-9gzvj,phase=Succeeded node=kind-worker4
60.1717,Event,ADDED,eval-sanitize-5-r3-019-dq89j.18d3d468383f0d04,reason=Started count=1 msg=Started container task
60.1719,Event,ADDED,eval-sanitize-5-r3-019.18d3d4681b42f4dc,reason=SuccessfulCreate count=1 msg=Created pod: eval-sanitize-5-r3-019-dq89j
60.1721,Event,ADDED,eval-sanitize-5-r3-019.18d3d46b569372a8,reason=Completed count=1 msg=Job completed
60.1732,Pod,ADDED,eval-sanitize-5-r3-036-8zwkc,phase=Succeeded node=kind-worker5
60.1734,Event,ADDED,eval-sanitize-5-r3-020-m7rv7.18d3d468581c9acd,reason=Scheduled count=None msg=Successfully assigned compute/eval-sanitize-5-r3-020-m7rv7 to kind-worker
60.1736,Event,ADDED,eval-sanitize-5-r3-020-m7rv7.18d3d46871d4970c,"reason=Pulled count=1 msg=Container image ""busybox:musl"" already present on machine"
60.1738,Event,ADDED,eval-sanitize-5-r3-020-m7rv7.18d3d46872fdb5ae,reason=Created count=1 msg=Created container: task
60.174,Event,ADDED,eval-sanitize-5-r3-020-m7rv7.18d3d468775639ea,reason=Started count=1 msg=Started container task
60.1746,Job,ADDED,eval-sanitize-5-r3-055,
60.175,Event,ADDED,eval-sanitize-5-r3-020.18d3d46856dcf7ef,reason=SuccessfulCreate count=1 msg=Created pod: eval-sanitize-5-r3-020-m7rv7
60.1751,Event,ADDED,eval-sanitize-5-r3-020.18d3d46bb46e7eab,reason=Completed count=1 msg=Job completed
60.1753,Event,ADDED,eval-sanitize-5-r3-021-gbb9r.18d3d46893728254,reason=Scheduled count=None msg=Successfully assigned compute/eval-sanitize-5-r3-021-gbb9r to kind-worker4
60.1755,Event,ADDED,eval-sanitize-5-r3-021-gbb9r.18d3d468acc2e01f,"reason=Pulled count=1 msg=Container image ""busybox:musl"" already present on machine"
60.1762,Job,ADDED,eval-sanitize-5-r3-056,
60.1772,Pod,ADDED,eval-sanitize-5-r3-037-gnpkz,phase=Succeeded node=kind-worker4
60.1775,Event,ADDED,eval-sanitize-5-r3-021-gbb9r.18d3d468adf725ea,reason=Created count=1 msg=Created container: task
60.1777,Event,ADDED,eval-sanitize-5-r3-021-gbb9r.18d3d468afe017b2,reason=Started count=1 msg=Started container task
60.1778,Event,ADDED,eval-sanitize-5-r3-021.18d3d46892bb78bd,reason=SuccessfulCreate count=1 msg=Created pod: eval-sanitize-5-r3-021-gbb9r
60.1794,Pod,ADDED,eval-sanitize-5-r3-038-szrth,phase=Succeeded node=kind-worker
60.1796,Event,ADDED,eval-sanitize-5-r3-021.18d3d46bc9629fc4,reason=Completed count=1 msg=Job completed
60.1798,Event,ADDED,eval-sanitize-5-r3-022-62z7n.18d3d468cf7d26d7,reason=Scheduled count=None msg=Successfully assigned compute/eval-sanitize-5-r3-022-62z7n to kind-worker3
60.18,Event,ADDED,eval-sanitize-5-r3-022-62z7n.18d3d468e8f5bfa1,"reason=Pulled count=1 msg=Container image ""busybox:musl"" already present on machine"
60.1802,Event,ADDED,eval-sanitize-5-r3-022-62z7n.18d3d468ea1d3046,reason=Created count=1 msg=Created container: task
60.1807,Job,ADDED,eval-sanitize-5-r3-057,
60.1821,Pod,ADDED,eval-sanitize-5-r3-039-l8s8w,phase=Succeeded node=kind-worker
60.183,Pod,ADDED,eval-sanitize-5-r3-040-znsfm,phase=Succeeded node=kind-worker3
60.1836,Job,ADDED,eval-sanitize-5-r3-058,
60.1839,Event,ADDED,eval-sanitize-5-r3-022-62z7n.18d3d468eeaf4ce4,reason=Started count=1 msg=Started container task
60.1841,Event,ADDED,eval-sanitize-5-r3-022.18d3d468ceb3597e,reason=SuccessfulCreate count=1 msg=Created pod: eval-sanitize-5-r3-022-62z7n
60.1843,Event,ADDED,eval-sanitize-5-r3-022.18d3d46c054da596,reason=Completed count=1 msg=Job completed
60.1853,Pod,ADDED,eval-sanitize-5-r3-041-tmt29,phase=Succeeded node=kind-worker4
60.1856,Event,ADDED,eval-sanitize-5-r3-023-rzr46.18d3d4690a4451c9,"reason=FailedScheduling count=None msg=0/6 nodes are available: 2 c_wall violated: 1 conflicting context pair(s) with node memory, 4 node(s) had untolerated taint(s). no new claims to deallocate, preemption: 0/6 nodes are available: 2 No preemption victims found for incoming pod, 4 Preemption is not helpful for scheduling."
60.1858,Event,ADDED,eval-sanitize-5-r3-023-rzr46.18d3d4690af3f3ab,"reason=FailedScheduling count=None msg=0/6 nodes are available: 2 c_wall violated: 1 conflicting context pair(s) with node memory, 4 node(s) had untolerated taint(s). no new claims to deallocate, preemption: 0/6 nodes are available: 2 No preemption victims found for incoming pod, 4 Preemption is not helpful for scheduling."
60.1861,Event,ADDED,eval-sanitize-5-r3-023-rzr46.18d3d4695630c0ab,"reason=FailedScheduling count=None msg=0/6 nodes are available: 1 c_wall violated: 1 conflicting context pair(s) with node memory, 5 node(s) had untolerated taint(s). no new claims to deallocate, preemption: 0/6 nodes are available: 1 No preemption victims found for incoming pod, 5 Preemption is not helpful for scheduling."
60.1862,Event,ADDED,eval-sanitize-5-r3-023-rzr46.18d3d46aefe6909a,reason=Scheduled count=None msg=Successfully assigned compute/eval-sanitize-5-r3-023-rzr46 to kind-worker5
60.1875,Pod,ADDED,eval-sanitize-5-r3-042-cf2pb,phase=Succeeded node=kind-worker3
60.188,Job,ADDED,eval-sanitize-5-r3-059,
60.1883,Event,ADDED,eval-sanitize-5-r3-023-rzr46.18d3d46b0af3339c,"reason=Pulled count=1 msg=Container image ""busybox:musl"" already present on machine"
60.1885,Event,ADDED,eval-sanitize-5-r3-023-rzr46.18d3d46b0d53ac99,reason=Created count=1 msg=Created container: task
60.189,Job,ADDED,eval-sanitize-5-r3-060,
60.1891,Event,ADDED,eval-sanitize-5-r3-023-rzr46.18d3d46b114dedf8,reason=Started count=1 msg=Started container task
60.1894,Event,ADDED,eval-sanitize-5-r3-023.18d3d46909d8064e,reason=SuccessfulCreate count=1 msg=Created pod: eval-sanitize-5-r3-023-rzr46
60.1896,Event,ADDED,eval-sanitize-5-r3-023.18d3d46e22025af5,reason=Completed count=1 msg=Job completed
60.1898,Event,ADDED,eval-sanitize-5-r3-024-c56sv.18d3d4694630c8e5,reason=Scheduled count=None msg=Successfully assigned compute/eval-sanitize-5-r3-024-c56sv to kind-worker3
60.1899,Event,ADDED,eval-sanitize-5-r3-024-c56sv.18d3d46960351154,"reason=Pulled count=1 msg=Container image ""busybox:musl"" already present on machine"
60.191,Pod,ADDED,eval-sanitize-5-r3-043-2mzj6,phase=Succeeded node=kind-worker2
60.1915,Job,MODIFIED,eval-sanitize-5-r3-059,
60.1926,Pod,ADDED,eval-sanitize-5-r3-044-97sfv,phase=Succeeded node=kind-worker2
60.1937,Pod,ADDED,eval-sanitize-5-r3-045-9klvn,phase=Succeeded node=kind-worker2
60.1946,Pod,ADDED,eval-sanitize-5-r3-046-bg7dm,phase=Running node=kind-worker5
60.1951,Job,MODIFIED,eval-sanitize-5-r3-060,
60.1961,Pod,ADDED,eval-sanitize-5-r3-047-nb5vw,phase=Running node=kind-worker3
60.1971,Pod,ADDED,eval-sanitize-5-r3-048-tc9lm,phase=Running node=kind-worker
60.1981,Pod,ADDED,eval-sanitize-5-r3-049-t2ff5,phase=Running node=kind-worker5
60.199,Pod,ADDED,eval-sanitize-5-r3-050-l6mlt,phase=Running node=kind-worker
60.1999,Pod,ADDED,eval-sanitize-5-r3-051-dsht7,phase=Running node=kind-worker5
60.2007,Pod,ADDED,eval-sanitize-5-r3-052-gndzv,phase=Running node=kind-worker5
60.2017,Pod,ADDED,eval-sanitize-5-r3-053-dbxqm,phase=Running node=kind-worker5
60.205,Pod,ADDED,eval-sanitize-5-r3-054-tfvvd,phase=Running node=kind-worker3
60.2053,Event,ADDED,eval-sanitize-5-r3-024-c56sv.18d3d469615f88b6,reason=Created count=1 msg=Created container: task
60.2055,Event,ADDED,eval-sanitize-5-r3-024-c56sv.18d3d469637e7423,reason=Started count=1 msg=Started container task
60.2056,Event,ADDED,eval-sanitize-5-r3-024.18d3d46945860da4,reason=SuccessfulCreate count=1 msg=Created pod: eval-sanitize-5-r3-024-c56sv
60.2058,Event,ADDED,eval-sanitize-5-r3-024.18d3d46c7cba06f8,reason=Completed count=1 msg=Job completed
60.2064,Job,MODIFIED,eval-sanitize-5-r3-059,
60.2067,Event,ADDED,eval-sanitize-5-r3-025-v6v64.18d3d4698144a988,"reason=FailedScheduling count=None msg=0/6 nodes are available: 1 c_wall violated: 1 conflicting context pair(s) with node memory, 5 node(s) had untolerated taint(s). no new claims to deallocate, preemption: 0/6 nodes are available: 1 No preemption victims found for incoming pod, 5 Preemption is not helpful for scheduling."
60.2069,Event,ADDED,eval-sanitize-5-r3-025-v6v64.18d3d46981fa2aa5,"reason=FailedScheduling count=None msg=0/6 nodes are available: 1 c_wall violated: 1 conflicting context pair(s) with node memory, 5 node(s) had untolerated taint(s). no new claims to deallocate, preemption: 0/6 nodes are available: 1 No preemption victims found for incoming pod, 5 Preemption is not helpful for scheduling."
60.2071,Event,ADDED,eval-sanitize-5-r3-025-v6v64.18d3d46af01e00fb,"reason=FailedScheduling count=None msg=0/6 nodes are available: 1 c_wall violated: 1 conflicting context pair(s) with node memory, 5 node(s) had untolerated taint(s). no new claims to deallocate, preemption: 0/6 nodes are available: 1 No preemption victims found for incoming pod, 5 Preemption is not helpful for scheduling."
60.2081,Pod,ADDED,eval-sanitize-5-r3-055-n28zx,phase=Running node=kind-worker3
60.2084,Event,ADDED,eval-sanitize-5-r3-025-v6v64.18d3d46af43277a0,"reason=FailedScheduling count=None msg=0/6 nodes are available: 1 c_wall violated: 1 conflicting context pair(s) with node memory, 5 node(s) had untolerated taint(s). no new claims to deallocate, preemption: 0/6 nodes are available: 1 No preemption victims found for incoming pod, 5 Preemption is not helpful for scheduling."
60.2086,Event,ADDED,eval-sanitize-5-r3-025-v6v64.18d3d46b0bbcc07d,"reason=FailedScheduling count=None msg=0/6 nodes are available: 2 c_wall violated: 1 conflicting context pair(s) with node memory, 4 node(s) had untolerated taint(s). no new claims to deallocate, preemption: 0/6 nodes are available: 2 No preemption victims found for incoming pod, 4 Preemption is not helpful for scheduling."
60.2088,Event,ADDED,eval-sanitize-5-r3-025-v6v64.18d3d46c1c303285,reason=Scheduled count=None msg=Successfully assigned compute/eval-sanitize-5-r3-025-v6v64 to kind-worker4
60.2098,Pod,ADDED,eval-sanitize-5-r3-056-p8v5t,phase=Running node=kind-worker
60.2101,Event,ADDED,eval-sanitize-5-r3-025-v6v64.18d3d46c3679022f,"reason=Pulled count=1 msg=Container image ""busybox:musl"" already present on machine"
60.2103,Event,ADDED,eval-sanitize-5-r3-025-v6v64.18d3d46c38085efc,reason=Created count=1 msg=Created container: task
60.2105,Event,ADDED,eval-sanitize-5-r3-025-v6v64.18d3d46c3a0f2375,reason=Started count=1 msg=Started container task
60.2108,Event,ADDED,eval-sanitize-5-r3-025.18d3d4698107243f,reason=SuccessfulCreate count=1 msg=Created pod: eval-sanitize-5-r3-025-v6v64
60.211,Event,ADDED,eval-sanitize-5-r3-025.18d3d46f49a5db84,reason=Completed count=1 msg=Job completed
60.2112,Event,ADDED,eval-sanitize-5-r3-026-hghxc.18d3d469bc5d3bde,"reason=FailedScheduling count=None msg=0/6 nodes are available: 6 node(s) had untolerated taint(s). no new claims to deallocate, preemption: 0/6 nodes are available: 6 Preemption is not helpful for scheduling."
60.2113,Event,ADDED,eval-sanitize-5-r3-026-hghxc.18d3d46af0c86bdc,"reason=FailedScheduling count=None msg=0/6 nodes are available: 1 c_wall violated: 1 conflicting context pair(s) with node memory, 5 node(s) had untolerated taint(s). no new claims to deallocate, preemption: 0/6 nodes are available: 1 No preemption victims found for incoming pod, 5 Preemption is not helpful for scheduling."
60.2123,Pod,ADDED,eval-sanitize-5-r3-057-bccxp,phase=Running node=kind-worker4
60.2126,Event,ADDED,eval-sanitize-5-r3-026-hghxc.18d3d46af462604a,"reason=FailedScheduling count=None msg=0/6 nodes are available: 1 c_wall violated: 1 conflicting context pair(s) with node memory, 5 node(s) had untolerated taint(s). no new claims to deallocate, preemption: 0/6 nodes are available: 1 No preemption victims found for incoming pod, 5 Preemption is not helpful for scheduling."
60.2128,Event,ADDED,eval-sanitize-5-r3-026-hghxc.18d3d46b06c070a6,reason=Scheduled count=None msg=Successfully assigned compute/eval-sanitize-5-r3-026-hghxc to kind-worker2
60.2129,Event,ADDED,eval-sanitize-5-r3-026-hghxc.18d3d46b2159ebe2,"reason=Pulled count=1 msg=Container image ""busybox:musl"" already present on machine"
60.2136,Pod,ADDED,eval-sanitize-5-r3-058-nvqm9,phase=Pending node=None
60.2139,Event,ADDED,eval-sanitize-5-r3-026-hghxc.18d3d46b22cac1ee,reason=Created count=1 msg=Created container: task
60.2141,Event,ADDED,eval-sanitize-5-r3-026-hghxc.18d3d46b26ad9c3d,reason=Started count=1 msg=Started container task
60.2143,Event,ADDED,eval-sanitize-5-r3-026.18d3d469bc4f7de8,reason=SuccessfulCreate count=1 msg=Created pod: eval-sanitize-5-r3-026-hghxc
60.2144,Event,ADDED,eval-sanitize-5-r3-026.18d3d46e25042429,reason=Completed count=1 msg=Job completed
60.2152,Pod,ADDED,eval-sanitize-5-r3-059-4hqs6,phase=Pending node=None
60.2155,Event,ADDED,eval-sanitize-5-r3-027-9ft5d.18d3d469f824991d,"reason=FailedScheduling count=None msg=0/6 nodes are available: 6 node(s) had untolerated taint(s). no new claims to deallocate, preemption: 0/6 nodes are available: 6 Preemption is not helpful for scheduling."
60.2156,Event,ADDED,eval-sanitize-5-r3-027-9ft5d.18d3d46af1aeac41,reason=Scheduled count=None msg=Successfully assigned compute/eval-sanitize-5-r3-027-9ft5d to kind-worker5
60.2158,Event,ADDED,eval-sanitize-5-r3-027-9ft5d.18d3d46b0ae1802e,"reason=Pulled count=1 msg=Container image ""busybox:musl"" already present on machine"
60.2161,Event,ADDED,eval-sanitize-5-r3-027-9ft5d.18d3d46b0cf67194,reason=Created count=1 msg=Created container: task
60.2163,Event,ADDED,eval-sanitize-5-r3-027-9ft5d.18d3d46b114dee0c,reason=Started count=1 msg=Started container task
60.2165,Event,ADDED,eval-sanitize-5-r3-027.18d3d469f81682db,reason=SuccessfulCreate count=1 msg=Created pod: eval-sanitize-5-r3-027-9ft5d
60.2166,Event,ADDED,eval-sanitize-5-r3-027.18d3d46e21c73f2b,reason=Completed count=1 msg=Job completed
60.2168,Event,ADDED,eval-sanitize-5-r3-028-6xmxg.18d3d46a33aee3d5,"reason=FailedScheduling count=None msg=0/6 nodes are available: 6 node(s) had untolerated taint(s). no new claims to deallocate, preemption: 0/6 nodes are available: 6 Preemption is not helpful for scheduling."
60.217,Event,ADDED,eval-sanitize-5-r3-028-6xmxg.18d3d46af1da7c4a,reason=Scheduled count=None msg=Successfully assigned compute/eval-sanitize-5-r3-028-6xmxg to kind-worker5
60.2172,Event,ADDED,eval-sanitize-5-r3-028-6xmxg.18d3d46b0b5087af,"reason=Pulled count=1 msg=Container image ""busybox:musl"" already present on machine"
60.2173,Event,ADDED,eval-sanitize-5-r3-028-6xmxg.18d3d46b0d8909d8,reason=Created count=1 msg=Created container: task
60.2176,Event,ADDED,eval-sanitize-5-r3-028-6xmxg.18d3d46b11948cd7,reason=Started count=1 msg=Started container task
60.2178,Event,ADDED,eval-sanitize-5-r3-028.18d3d46a33a69a9b,reason=SuccessfulCreate count=1 msg=Created pod: eval-sanitize-5-r3-028-6xmxg
60.218,Event,ADDED,eval-sanitize-5-r3-028.18d3d46e21a08b3f,reason=Completed count=1 msg=Job completed
60.2186,Pod,ADDED,eval-sanitize-5-r3-060-jqm27,phase=Pending node=None
60.2189,Event,ADDED,eval-sanitize-5-r3-029-j9fgd.18d3d46a75db2b54,"reason=FailedScheduling count=None msg=0/6 nodes are available: 6 node(s) had untolerated taint(s). no new claims to deallocate, preemption: 0/6 nodes are available: 6 Preemption is not helpful for scheduling."
60.219,Event,ADDED,eval-sanitize-5-r3-029-j9fgd.18d3d46af1bcea3e,"reason=FailedScheduling count=None msg=0/6 nodes are available: 1 c_wall violated: 1 conflicting context pair(s) with node memory, 5 node(s) had untolerated taint(s). no new claims to deallocate, preemption: 0/6 nodes are available: 1 No preemption victims found for incoming pod, 5 Preemption is not helpful for scheduling."
60.2192,Event,ADDED,eval-sanitize-5-r3-029-j9fgd.18d3d46af67d7eb9,"reason=FailedScheduling count=None msg=0/6 nodes are available: 1 c_wall violated: 1 conflicting context pair(s) with node memory, 5 node(s) had untolerated taint(s). no new claims to deallocate, preemption: 0/6 nodes are available: 1 No preemption victims found for incoming pod, 5 Preemption is not helpful for scheduling."
60.2195,Event,ADDED,eval-sanitize-5-r3-029-j9fgd.18d3d46b00a785be,reason=Scheduled count=None msg=Successfully assigned compute/eval-sanitize-5-r3-029-j9fgd to kind-worker2
60.2197,Event,ADDED,eval-sanitize-5-r3-029-j9fgd.18d3d46b19cad2c4,"reason=Pulled count=1 msg=Container image ""busybox:musl"" already present on machine"
60.2198,Event,ADDED,eval-sanitize-5-r3-029-j9fgd.18d3d46b1be88057,reason=Created count=1 msg=Created container: task
60.2201,Event,ADDED,eval-sanitize-5-r3-029-j9fgd.18d3d46b2068f357,reason=Started count=1 msg=Started container task
60.2211,Pod,MODIFIED,eval-sanitize-5-r3-060-jqm27,phase=Pending node=None
60.2216,Event,ADDED,eval-sanitize-5-r3-029.18d3d46a75d10da2,reason=SuccessfulCreate count=1 msg=Created pod: eval-sanitize-5-r3-029-j9fgd
60.2217,Event,ADDED,eval-sanitize-5-r3-029.18d3d46e24ca171b,reason=Completed count=1 msg=Job completed
60.2219,Event,ADDED,eval-sanitize-5-r3-030-9m4cf.18d3d46abaad74b1,"reason=FailedScheduling count=None msg=0/6 nodes are available: 6 node(s) had untolerated taint(s). no new claims to deallocate, preemption: 0/6 nodes are available: 6 Preemption is not helpful for scheduling."
60.2221,Event,ADDED,eval-sanitize-5-r3-030-9m4cf.18d3d46af2cc1295,"reason=FailedScheduling count=None msg=0/6 nodes are available: 1 c_wall violated: 2 conflicting context pair(s) with node memory, 5 node(s) had untolerated taint(s). no new claims to deallocate, preemption: 0/6 nodes are available: 1 No preemption victims found for incoming pod, 5 Preemption is not helpful for scheduling."
60.2223,Event,ADDED,eval-sanitize-5-r3-030-9m4cf.18d3d46af787c74c,"reason=FailedScheduling count=None msg=0/6 nodes are available: 1 c_wall violated: 2 conflicting context pair(s) with node memory, 5 node(s) had untolerated taint(s). no new claims to deallocate, preemption: 0/6 nodes are available: 1 No preemption victims found for incoming pod, 5 Preemption is not helpful for scheduling."
60.2225,Event,ADDED,eval-sanitize-5-r3-030-9m4cf.18d3d46b01418fb9,reason=Scheduled count=None msg=Successfully assigned compute/eval-sanitize-5-r3-030-9m4cf to kind-worker2
60.2226,Event,ADDED,eval-sanitize-5-r3-030-9m4cf.18d3d46b1a69ecf3,"reason=Pulled count=1 msg=Container image ""busybox:musl"" already present on machine"
60.2228,Event,ADDED,eval-sanitize-5-r3-030-9m4cf.18d3d46b1c97af50,reason=Created count=1 msg=Created container: task
60.223,Event,ADDED,eval-sanitize-5-r3-030-9m4cf.18d3d46b2106618e,reason=Started count=1 msg=Started container task
60.2231,Event,ADDED,eval-sanitize-5-r3-030.18d3d46abaa304f7,reason=SuccessfulCreate count=1 msg=Created pod: eval-sanitize-5-r3-030-9m4cf
60.2233,Event,ADDED,eval-sanitize-5-r3-030.18d3d46e245b1203,reason=Completed count=1 msg=Job completed
60.2235,Event,ADDED,eval-sanitize-5-r3-031-brmm4.18d3d46ae6560258,"reason=FailedScheduling count=None msg=0/6 nodes are available: 6 node(s) had untolerated taint(s). no new claims to deallocate, preemption: 0/6 nodes are available: 6 Preemption is not helpful for scheduling."
60.2236,Event,ADDED,eval-sanitize-5-r3-031-brmm4.18d3d46af39d049c,"reason=FailedScheduling count=None msg=0/6 nodes are available: 1 c_wall violated: 2 conflicting context pair(s) with node memory, 5 node(s) had untolerated taint(s). no new claims to deallocate, preemption: 0/6 nodes are available: 1 No preemption victims found for incoming pod, 5 Preemption is not helpful for scheduling."
60.2238,Event,ADDED,eval-sanitize-5-r3-031-brmm4.18d3d46af7af55f0,"reason=FailedScheduling count=None msg=0/6 nodes are available: 1 c_wall violated: 2 conflicting context pair(s) with node memory, 5 node(s) had untolerated taint(s). no new claims to deallocate, preemption: 0/6 nodes are available: 1 No preemption victims found for incoming pod, 5 Preemption is not helpful for scheduling."
60.224,Event,ADDED,eval-sanitize-5-r3-031-brmm4.18d3d46b0b6977e4,"reason=FailedScheduling count=None msg=0/6 nodes are available: 1 c_wall violated: 1 conflicting context pair(s) with node memory, 1 c_wall violated: 2 conflicting context pair(s) with node memory, 4 node(s) had untolerated taint(s). no new claims to deallocate, preemption: 0/6 nodes are available: 2 No preemption victims found for incoming pod, 4 Preemption is not helpful for scheduling."
60.2242,Event,ADDED,eval-sanitize-5-r3-031-brmm4.18d3d46c21f5badd,"reason=FailedScheduling count=None msg=0/6 nodes are available: 2 c_wall violated: 1 conflicting context pair(s) with node memory, 4 node(s) had untolerated taint(s). no new claims to deallocate, preemption: 0/6 nodes are available: 2 No preemption victims found for incoming pod, 4 Preemption is not helpful for scheduling."
60.2243,Event,ADDED,eval-sanitize-5-r3-031-brmm4.18d3d46c238a7042,"reason=FailedScheduling count=None msg=0/6 nodes are available: 2 c_wall violated: 1 conflicting context pair(s) with node memory, 4 node(s) had untolerated taint(s). no new claims to deallocate, preemption: 0/6 nodes are available: 2 No preemption victims found for incoming pod, 4 Preemption is not helpful for scheduling."
60.2245,Event,ADDED,eval-sanitize-5-r3-031-brmm4.18d3d46c31876237,"reason=FailedScheduling count=None msg=0/6 nodes are available: 1 c_wall violated: 1 conflicting context pair(s) with node memory, 5 node(s) had untolerated taint(s). no new claims to deallocate, preemption: 0/6 nodes are available: 1 No preemption victims found for incoming pod, 5 Preemption is not helpful for scheduling."
60.2247,Event,ADDED,eval-sanitize-5-r3-031-brmm4.18d3d46c4e544a41,"reason=FailedScheduling count=None msg=0/6 nodes are available: 1 c_wall violated: 2 conflicting context pair(s) with node memory, 5 node(s) had untolerated taint(s). no new claims to deallocate, preemption: 0/6 nodes are available: 1 No preemption victims found for incoming pod, 5 Preemption is not helpful for scheduling."
60.2249,Event,ADDED,eval-sanitize-5-r3-031-brmm4.18d3d46c60ecd9e3,reason=Scheduled count=None msg=Successfully assigned compute/eval-sanitize-5-r3-031-brmm4 to kind-worker
60.225,Event,ADDED,eval-sanitize-5-r3-031-brmm4.18d3d46c7992adb4,"reason=Pulled count=1 msg=Container image ""busybox:musl"" already present on machine"
60.2252,Event,ADDED,eval-sanitize-5-r3-031-brmm4.18d3d46c7ae17534,reason=Created count=1 msg=Created container: task
60.2254,Event,ADDED,eval-sanitize-5-r3-031-brmm4.18d3d46c7ce98ef4,reason=Started count=1 msg=Started container task
60.2265,Event,ADDED,eval-sanitize-5-r3-031.18d3d46ae650bd5f,reason=SuccessfulCreate count=1 msg=Created pod: eval-sanitize-5-r3-031-brmm4
60.2266,Event,ADDED,eval-sanitize-5-r3-031.18d3d46fac041af2,reason=Completed count=1 msg=Job completed
60.2268,Event,ADDED,eval-sanitize-5-r3-032-wdxmb.18d3d46b229e91ea,reason=Scheduled count=None msg=Successfully assigned compute/eval-sanitize-5-r3-032-wdxmb to kind-worker2
60.227,Event,ADDED,eval-sanitize-5-r3-032-wdxmb.18d3d46b3b6b52ff,"reason=Pulled count=1 msg=Container image ""busybox:musl"" already present on machine"
60.2272,Event,ADDED,eval-sanitize-5-r3-032-wdxmb.18d3d46b3cd8b7e4,reason=Created count=1 msg=Created container: task
60.2274,Event,ADDED,eval-sanitize-5-r3-032-wdxmb.18d3d46b412823e4,reason=Started count=1 msg=Started container task
60.2275,Event,ADDED,eval-sanitize-5-r3-032.18d3d46b21db7b91,reason=SuccessfulCreate count=1 msg=Created pod: eval-sanitize-5-r3-032-wdxmb
60.2277,Event,ADDED,eval-sanitize-5-r3-032.18d3d46e23fb6a80,reason=Completed count=1 msg=Job completed
60.2279,Event,ADDED,eval-sanitize-5-r3-033-zg9jg.18d3d46b5ec85d93,reason=Scheduled count=None msg=Successfully assigned compute/eval-sanitize-5-r3-033-zg9jg to kind-worker2
60.228,Event,ADDED,eval-sanitize-5-r3-033-zg9jg.18d3d46b7863d992,"reason=Pulled count=1 msg=Container image ""busybox:musl"" already present on machine"
60.2282,Event,ADDED,eval-sanitize-5-r3-033-zg9jg.18d3d46b79a6c912,reason=Created count=1 msg=Created container: task
60.2284,Event,ADDED,eval-sanitize-5-r3-033-zg9jg.18d3d46b7dd703dd,reason=Started count=1 msg=Started container task
60.2285,Event,ADDED,eval-sanitize-5-r3-033.18d3d46b5d7f44ad,reason=SuccessfulCreate count=1 msg=Created pod: eval-sanitize-5-r3-033-zg9jg
60.2287,Event,ADDED,eval-sanitize-5-r3-033.18d3d46e9b31aca8,reason=Completed count=1 msg=Job completed
60.2288,Event,ADDED,eval-sanitize-5-r3-034-tqzsg.18d3d46b9a28c742,reason=Scheduled count=None msg=Successfully assigned compute/eval-sanitize-5-r3-034-tqzsg to kind-worker5
60.229,Event,ADDED,eval-sanitize-5-r3-034-tqzsg.18d3d46bb42b21c4,"reason=Pulled count=1 msg=Container image ""busybox:musl"" already present on machine"
60.2292,Event,ADDED,eval-sanitize-5-r3-034-tqzsg.18d3d46bb57f271f,reason=Created count=1 msg=Created container: task
60.2293,Event,ADDED,eval-sanitize-5-r3-034-tqzsg.18d3d46bb91b48bd,reason=Started count=1 msg=Started container task
60.2295,Event,ADDED,eval-sanitize-5-r3-034.18d3d46b9974f79d,reason=SuccessfulCreate count=1 msg=Created pod: eval-sanitize-5-r3-034-tqzsg
60.2297,Event,ADDED,eval-sanitize-5-r3-034.18d3d46ed5257188,reason=Completed count=1 msg=Job completed
60.2298,Event,ADDED,eval-sanitize-5-r3-035-9gzvj.18d3d46bd55bbdb3,"reason=FailedScheduling count=None msg=0/6 nodes are available: 2 c_wall violated: 1 conflicting context pair(s) with node memory, 4 node(s) had untolerated taint(s). no new claims to deallocate, preemption: 0/6 nodes are available: 2 No preemption victims found for incoming pod, 4 Preemption is not helpful for scheduling."
60.23,Event,ADDED,eval-sanitize-5-r3-035-9gzvj.18d3d46bd61e8579,"reason=FailedScheduling count=None msg=0/6 nodes are available: 2 c_wall violated: 1 conflicting context pair(s) with node memory, 4 node(s) had untolerated taint(s). no new claims to deallocate, preemption: 0/6 nodes are available: 2 No preemption victims found for incoming pod, 4 Preemption is not helpful for scheduling."
60.2302,Event,ADDED,eval-sanitize-5-r3-035-9gzvj.18d3d46c224a50ba,reason=Scheduled count=None msg=Successfully assigned compute/eval-sanitize-5-r3-035-9gzvj to kind-worker4
60.2303,Event,ADDED,eval-sanitize-5-r3-035-9gzvj.18d3d46c3a1bd3f4,"reason=Pulled count=1 msg=Container image ""busybox:musl"" already present on machine"
60.2305,Event,ADDED,eval-sanitize-5-r3-035-9gzvj.18d3d46c3b3b3a61,reason=Created count=1 msg=Created container: task
60.2307,Event,ADDED,eval-sanitize-5-r3-035-9gzvj.18d3d46c4098c0e1,reason=Started count=1 msg=Started container task
60.2308,Event,ADDED,eval-sanitize-5-r3-035.18d3d46bd4f3652f,reason=SuccessfulCreate count=1 msg=Created pod: eval-sanitize-5-r3-035-9gzvj
60.231,Event,ADDED,eval-sanitize-5-r3-035.18d3d46f85a00f21,reason=Completed count=1 msg=Job completed
60.2311,Event,ADDED,eval-sanitize-5-r3-036-8zwkc.18d3d46c1825fb67,reason=Scheduled count=None msg=Successfully assigned compute/eval-sanitize-5-r3-036-8zwkc to kind-worker5
60.2313,Event,ADDED,eval-sanitize-5-r3-036-8zwkc.18d3d46c31e1924e,"reason=Pulled count=1 msg=Container image ""busybox:musl"" already present on machine"
60.2315,Event,ADDED,eval-sanitize-5-r3-036-8zwkc.18d3d46c33160a52,reason=Created count=1 msg=Created container: task
60.2316,Event,ADDED,eval-sanitize-5-r3-036-8zwkc.18d3d46c36ca9252,reason=Started count=1 msg=Started container task
60.2318,Event,ADDED,eval-sanitize-5-r3-036.18d3d46c10c98b5e,reason=SuccessfulCreate count=1 msg=Created pod: eval-sanitize-5-r3-036-8zwkc
60.232,Event,ADDED,eval-sanitize-5-r3-036.18d3d46f4cabb94f,reason=Completed count=1 msg=Job completed
60.2321,Event,ADDED,eval-sanitize-5-r3-037-gnpkz.18d3d46c4d7cb0dc,reason=Scheduled count=None msg=Successfully assigned compute/eval-sanitize-5-r3-037-gnpkz to kind-worker4
60.2323,Event,ADDED,eval-sanitize-5-r3-037-gnpkz.18d3d46c6692d5ff,"reason=Pulled count=1 msg=Container image ""busybox:musl"" already present on machine"
60.2324,Event,ADDED,eval-sanitize-5-r3-037-gnpkz.18d3d46c67b9eddb,reason=Created count=1 msg=Created container: task
60.2326,Event,ADDED,eval-sanitize-5-r3-037-gnpkz.18d3d46c6c2417cd,reason=Started count=1 msg=Started container task
60.2328,Event,ADDED,eval-sanitize-5-r3-037.18d3d46c4ce015ec,reason=SuccessfulCreate count=1 msg=Created pod: eval-sanitize-5-r3-037-gnpkz
60.2329,Event,ADDED,eval-sanitize-5-r3-037.18d3d46f85c3c284,reason=Completed count=1 msg=Job completed
60.2331,Event,ADDED,eval-sanitize-5-r3-038-szrth.18d3d46c899f6cb8,reason=Scheduled count=None msg=Successfully assigned compute/eval-sanitize-5-r3-038-szrth to kind-worker
60.2332,Event,ADDED,eval-sanitize-5-r3-038-szrth.18d3d46ca2935bb9,"reason=Pulled count=1 msg=Container image ""busybox:musl"" already present on machine"
60.2337,Event,ADDED,eval-sanitize-5-r3-038-szrth.18d3d46ca3b09d6b,reason=Created count=1 msg=Created container: task
60.2339,Event,ADDED,eval-sanitize-5-r3-038-szrth.18d3d46ca68869ac,reason=Started count=1 msg=Started container task
60.234,Event,ADDED,eval-sanitize-5-r3-038.18d3d46c88e3756f,reason=SuccessfulCreate count=1 msg=Created pod: eval-sanitize-5-r3-038-szrth
60.2342,Event,ADDED,eval-sanitize-5-r3-038.18d3d46fe7ea8e76,reason=Completed count=1 msg=Job completed
60.2343,Event,ADDED,eval-sanitize-5-r3-039-l8s8w.18d3d46cc447f737,reason=Scheduled count=None msg=Successfully assigned compute/eval-sanitize-5-r3-039-l8s8w to kind-worker
60.2345,Event,ADDED,eval-sanitize-5-r3-039-l8s8w.18d3d46cdeedf99d,"reason=Pulled count=1 msg=Container image ""busybox:musl"" already present on machine"
60.2347,Event,ADDED,eval-sanitize-5-r3-039-l8s8w.18d3d46ce044ded0,reason=Created count=1 msg=Created container: task
60.2348,Event,ADDED,eval-sanitize-5-r3-039-l8s8w.18d3d46ce244c55f,reason=Started count=1 msg=Started container task
60.235,Event,ADDED,eval-sanitize-5-r3-039.18d3d46cc39624f2,reason=SuccessfulCreate count=1 msg=Created pod: eval-sanitize-5-r3-039-l8s8w
60.2352,Event,ADDED,eval-sanitize-5-r3-039.18d3d470241a32e2,reason=Completed count=1 msg=Job completed
60.2353,Event,ADDED,eval-sanitize-5-r3-040-znsfm.18d3d46d00fc693d,reason=Scheduled count=None msg=Successfully assigned compute/eval-sanitize-5-r3-040-znsfm to kind-worker3
60.2355,Event,ADDED,eval-sanitize-5-r3-040-znsfm.18d3d46d1af1880a,"reason=Pulled count=1 msg=Container image ""busybox:musl"" already present on machine"
60.2357,Event,ADDED,eval-sanitize-5-r3-040-znsfm.18d3d46d1c35c696,reason=Created count=1 msg=Created container: task
60.2358,Event,ADDED,eval-sanitize-5-r3-040-znsfm.18d3d46d21a24611,reason=Started count=1 msg=Started container task
60.236,Event,ADDED,eval-sanitize-5-r3-040.18d3d46cffa982fd,reason=SuccessfulCreate count=1 msg=Created pod: eval-sanitize-5-r3-040-znsfm
60.2362,Event,ADDED,eval-sanitize-5-r3-040.18d3d470388d1359,reason=Completed count=1 msg=Job completed
60.2368,Event,ADDED,eval-sanitize-5-r3-041-tmt29.18d3d46d3ca36c60,reason=Scheduled count=None msg=Successfully assigned compute/eval-sanitize-5-r3-041-tmt29 to kind-worker4
60.237,Event,ADDED,eval-sanitize-5-r3-041-tmt29.18d3d46d5711387a,"reason=Pulled count=1 msg=Container image ""busybox:musl"" already present on machine"
60.2372,Event,ADDED,eval-sanitize-5-r3-041-tmt29.18d3d46d5827d42a,reason=Created count=1 msg=Created container: task
60.2373,Event,ADDED,eval-sanitize-5-r3-041-tmt29.18d3d46d5d18263f,reason=Started count=1 msg=Started container task
60.2377,Event,ADDED,eval-sanitize-5-r3-041.18d3d46d3b658026,reason=SuccessfulCreate count=1 msg=Created pod: eval-sanitize-5-r3-041-tmt29
60.2378,Event,ADDED,eval-sanitize-5-r3-041.18d3d47074ce6c41,reason=Completed count=1 msg=Job completed
60.238,Event,ADDED,eval-sanitize-5-r3-042-cf2pb.18d3d46d782d168f,reason=Scheduled count=None msg=Successfully assigned compute/eval-sanitize-5-r3-042-cf2pb to kind-worker3
60.2382,Event,ADDED,eval-sanitize-5-r3-042-cf2pb.18d3d46d91ecb39b,"reason=Pulled count=1 msg=Container image ""busybox:musl"" already present on machine"
60.2385,Event,ADDED,eval-sanitize-5-r3-042-cf2pb.18d3d46d930f8626,reason=Created count=1 msg=Created container: task
60.2387,Event,ADDED,eval-sanitize-5-r3-042-cf2pb.18d3d46d95ed064a,reason=Started count=1 msg=Started container task
60.2389,Event,ADDED,eval-sanitize-5-r3-042.18d3d46d77747eec,reason=SuccessfulCreate count=1 msg=Created pod: eval-sanitize-5-r3-042-cf2pb
60.2391,Event,ADDED,eval-sanitize-5-r3-042.18d3d470afff0418,reason=Completed count=1 msg=Job completed
60.2393,Event,ADDED,eval-sanitize-5-r3-043-2mzj6.18d3d46db2485dec,"reason=FailedScheduling count=None msg=0/6 nodes are available: 1 c_wall violated: 1 conflicting context pair(s) with node memory, 5 node(s) had untolerated taint(s). no new claims to deallocate, preemption: 0/6 nodes are available: 1 No preemption victims found for incoming pod, 5 Preemption is not helpful for scheduling."
60.2395,Event,ADDED,eval-sanitize-5-r3-043-2mzj6.18d3d46db303f0b0,"reason=FailedScheduling count=None msg=0/6 nodes are available: 1 c_wall violated: 1 conflicting context pair(s) with node memory, 5 node(s) had untolerated taint(s). no new claims to deallocate, preemption: 0/6 nodes are available: 1 No preemption victims found for incoming pod, 5 Preemption is not helpful for scheduling."
60.2396,Event,ADDED,eval-sanitize-5-r3-043-2mzj6.18d3d46e9da5ace9,reason=Scheduled count=None msg=Successfully assigned compute/eval-sanitize-5-r3-043-2mzj6 to kind-worker2
60.2398,Event,ADDED,eval-sanitize-5-r3-043-2mzj6.18d3d46eb6e88535,"reason=Pulled count=1 msg=Container image ""busybox:musl"" already present on machine"
60.2399,Event,ADDED,eval-sanitize-5-r3-043-2mzj6.18d3d46eb886e92d,reason=Created count=1 msg=Created container: task
60.2401,Event,ADDED,eval-sanitize-5-r3-043-2mzj6.18d3d46ebdf9c816,reason=Started count=1 msg=Started container task
60.2403,Event,ADDED,eval-sanitize-5-r3-043.18d3d46db2013d1a,reason=SuccessfulCreate count=1 msg=Created pod: eval-sanitize-5-r3-043-2mzj6
60.2404,Event,ADDED,eval-sanitize-5-r3-044-97sfv.18d3d46dee20d254,"reason=FailedScheduling count=None msg=0/6 nodes are available: 1 c_wall violated: 2 conflicting context pair(s) with node memory, 5 node(s) had untolerated taint(s). no new claims to deallocate, preemption: 0/6 nodes are available: 1 No preemption victims found for incoming pod, 5 Preemption is not helpful for scheduling."
60.2406,Event,ADDED,eval-sanitize-5-r3-044-97sfv.18d3d46deeb02aaf,"reason=FailedScheduling count=None msg=0/6 nodes are available: 1 c_wall violated: 2 conflicting context pair(s) with node memory, 5 node(s) had untolerated taint(s). no new claims to deallocate, preemption: 0/6 nodes are available: 1 No preemption victims found for incoming pod, 5 Preemption is not helpful for scheduling."
60.2408,Event,ADDED,eval-sanitize-5-r3-044-97sfv.18d3d46e9dcc42cd,reason=Scheduled count=None msg=Successfully assigned compute/eval-sanitize-5-r3-044-97sfv to kind-worker2
60.241,Event,ADDED,eval-sanitize-5-r3-044-97sfv.18d3d46eb7952957,"reason=Pulled count=1 msg=Container image ""busybox:musl"" already present on machine"
60.2412,Event,ADDED,eval-sanitize-5-r3-044-97sfv.18d3d46eb989fa87,reason=Created count=1 msg=Created container: task
60.2414,Event,ADDED,eval-sanitize-5-r3-044-97sfv.18d3d46ebe99949c,reason=Started count=1 msg=Started container task
60.2416,Event,ADDED,eval-sanitize-5-r3-044.18d3d46dedca8553,reason=SuccessfulCreate count=1 msg=Created pod: eval-sanitize-5-r3-044-97sfv
60.2418,Event,ADDED,eval-sanitize-5-r3-045-9klvn.18d3d46e34c523f9,"reason=FailedScheduling count=None msg=0/6 nodes are available: 6 node(s) had untolerated taint(s). no new claims to deallocate, preemption: 0/6 nodes are available: 6 Preemption is not helpful for scheduling."
60.2419,Event,ADDED,eval-sanitize-5-r3-045-9klvn.18d3d46e9e5254ad,reason=Scheduled count=None msg=Successfully assigned compute/eval-sanitize-5-r3-045-9klvn to kind-worker2
60.2421,Event,ADDED,eval-sanitize-5-r3-045-9klvn.18d3d46eb7d0f1c4,"reason=Pulled count=1 msg=Container image ""busybox:musl"" already present on machine"
60.2423,Event,ADDED,eval-sanitize-5-r3-045-9klvn.18d3d46eb9e1d962,reason=Created count=1 msg=Created container: task
60.2424,Event,ADDED,eval-sanitize-5-r3-045-9klvn.18d3d46ebe999b6c,reason=Started count=1 msg=Started container task
60.2426,Event,ADDED,eval-sanitize-5-r3-045.18d3d46e34b8f0bc,reason=SuccessfulCreate count=1 msg=Created pod: eval-sanitize-5-r3-045-9klvn
60.2428,Event,ADDED,eval-sanitize-5-r3-046-bg7dm.18d3d46e646b5542,"reason=FailedScheduling count=None msg=0/6 nodes are available: 6 node(s) had untolerated taint(s). no new claims to deallocate, preemption: 0/6 nodes are available: 6 Preemption is not helpful for scheduling."
60.2429,Event,ADDED,eval-sanitize-5-r3-046-bg7dm.18d3d46e9dedfbdc,"reason=FailedScheduling count=None msg=0/6 nodes are available: 1 c_wall violated: 1 conflicting context pair(s) with node memory, 5 node(s) had untolerated taint(s). no new claims to deallocate, preemption: 0/6 nodes are available: 1 No preemption victims found for incoming pod, 5 Preemption is not helpful for scheduling."
60.2431,Event,ADDED,eval-sanitize-5-r3-046-bg7dm.18d3d46e9ec13855,"reason=FailedScheduling count=None msg=0/6 nodes are available: 1 c_wall violated: 1 conflicting context pair(s) with node memory, 5 node(s) had untolerated taint(s). no new claims to deallocate, preemption: 0/6 nodes are available: 1 No preemption victims found for incoming pod, 5 Preemption is not helpful for scheduling."
60.2433,Event,ADDED,eval-sanitize-5-r3-046-bg7dm.18d3d46fbca83680,reason=Scheduled count=None msg=Successfully assigned compute/eval-sanitize-5-r3-046-bg7dm to kind-worker5
60.2434,Event,ADDED,eval-sanitize-5-r3-046-bg7dm.18d3d46fd5f318aa,"reason=Pulled count=1 msg=Container image ""busybox:musl"" already present on machine"
60.2436,Event,ADDED,eval-sanitize-5-r3-046-bg7dm.18d3d46fd76cfd05,reason=Created count=1 msg=Created container: task
60.2438,Event,ADDED,eval-sanitize-5-r3-046-bg7dm.18d3d46fdc4ff9cc,reason=Started count=1 msg=Started container task
60.244,Event,ADDED,eval-sanitize-5-r3-046.18d3d46e645fb1bc,reason=SuccessfulCreate count=1 msg=Created pod: eval-sanitize-5-r3-046-bg7dm
60.2441,Event,ADDED,eval-sanitize-5-r3-047-nb5vw.18d3d46ea1728052,"reason=FailedScheduling count=None msg=0/6 nodes are available: 1 c_wall violated: 1 conflicting context pair(s) with node memory, 5 node(s) had untolerated taint(s). no new claims to deallocate, preemption: 0/6 nodes are available: 1 No preemption victims found for incoming pod, 5 Preemption is not helpful for scheduling."
60.2443,Event,ADDED,eval-sanitize-5-r3-047-nb5vw.18d3d46ea4016692,"reason=FailedScheduling count=None msg=0/6 nodes are available: 1 c_wall violated: 1 conflicting context pair(s) with node memory, 5 node(s) had untolerated taint(s). no new claims to deallocate, preemption: 0/6 nodes are available: 1 No preemption victims found for incoming pod, 5 Preemption is not helpful for scheduling."
60.2445,Event,ADDED,eval-sanitize-5-r3-047-nb5vw.18d3d46fc6260487,"reason=FailedScheduling count=None msg=0/6 nodes are available: 2 c_wall violated: 1 conflicting context pair(s) with node memory, 4 node(s) had untolerated taint(s). no new claims to deallocate, preemption: 0/6 nodes are available: 2 No preemption victims found for incoming pod, 4 Preemption is not helpful for scheduling."
60.2447,Event,ADDED,eval-sanitize-5-r3-047-nb5vw.18d3d46fd32c6cc1,"reason=FailedScheduling count=None msg=0/6 nodes are available: 1 c_wall violated: 1 conflicting context pair(s) with node memory, 5 node(s) had untolerated taint(s). no new claims to deallocate, preemption: 0/6 nodes are available: 1 No preemption victims found for incoming pod, 5 Preemption is not helpful for scheduling."
60.2449,Event,ADDED,eval-sanitize-5-r3-047-nb5vw.18d3d46ffbbce394,"reason=FailedScheduling count=None msg=0/6 nodes are available: 2 c_wall violated: 1 conflicting context pair(s) with node memory, 4 node(s) had untolerated taint(s). no new claims to deallocate, preemption: 0/6 nodes are available: 2 No preemption victims found for incoming pod, 4 Preemption is not helpful for scheduling."
60.2452,Event,ADDED,eval-sanitize-5-r3-047-nb5vw.18d3d47078c85ba6,reason=Scheduled count=None msg=Successfully assigned compute/eval-sanitize-5-r3-047-nb5vw to kind-worker3
60.2454,Event,ADDED,eval-sanitize-5-r3-047-nb5vw.18d3d4709269b6b8,"reason=Pulled count=1 msg=Container image ""busybox:musl"" already present on machine"
60.2456,Event,ADDED,eval-sanitize-5-r3-047-nb5vw.18d3d47093d2ad99,reason=Created count=1 msg=Created container: task
60.2459,Event,ADDED,eval-sanitize-5-r3-047-nb5vw.18d3d470989a1e76,reason=Started count=1 msg=Started container task
60.2461,Event,ADDED,eval-sanitize-5-r3-047.18d3d46ea060af53,reason=SuccessfulCreate count=1 msg=Created pod: eval-sanitize-5-r3-047-nb5vw
60.2463,Event,ADDED,eval-sanitize-5-r3-048-tc9lm.18d3d46edcf751f3,"reason=FailedScheduling count=None msg=0/6 nodes are available: 1 c_wall violated: 1 conflicting context pair(s) with node memory, 5 node(s) had untolerated taint(s). no new claims to deallocate, preemption: 0/6 nodes are available: 1 No preemption victims found for incoming pod, 5 Preemption is not helpful for scheduling."
60.2466,Event,ADDED,eval-sanitize-5-r3-048-tc9lm.18d3d46edd73f520,"reason=FailedScheduling count=None msg=0/6 nodes are available: 1 c_wall violated: 1 conflicting context pair(s) with node memory, 5 node(s) had untolerated taint(s). no new claims to deallocate, preemption: 0/6 nodes are available: 1 No preemption victims found for incoming pod, 5 Preemption is not helpful for scheduling."
60.2467,Event,ADDED,eval-sanitize-5-r3-048-tc9lm.18d3d46fc68a7f6d,"reason=FailedScheduling count=None msg=0/6 nodes are available: 1 c_wall violated: 1 conflicting context pair(s) with node memory, 1 c_wall violated: 2 conflicting context pair(s) with node memory, 4 node(s) had untolerated taint(s). no new claims to deallocate, preemption: 0/6 nodes are available: 2 No preemption victims found for incoming pod, 4 Preemption is not helpful for scheduling."
60.2469,Event,ADDED,eval-sanitize-5-r3-048-tc9lm.18d3d46fd1204f76,"reason=FailedScheduling count=None msg=0/6 nodes are available: 1 c_wall violated: 2 conflicting context pair(s) with node memory, 5 node(s) had untolerated taint(s). no new claims to deallocate, preemption: 0/6 nodes are available: 1 No preemption victims found for incoming pod, 5 Preemption is not helpful for scheduling."
60.2471,Event,ADDED,eval-sanitize-5-r3-048-tc9lm.18d3d46fd2d58a3b,"reason=FailedScheduling count=None msg=0/6 nodes are available: 1 c_wall violated: 2 conflicting context pair(s) with node memory, 5 node(s) had untolerated taint(s). no new claims to deallocate, preemption: 0/6 nodes are available: 1 No preemption victims found for incoming pod, 5 Preemption is not helpful for scheduling."
60.2472,Event,ADDED,eval-sanitize-5-r3-048-tc9lm.18d3d46ff6a732d1,reason=Scheduled count=None msg=Successfully assigned compute/eval-sanitize-5-r3-048-tc9lm to kind-worker
60.2474,Event,ADDED,eval-sanitize-5-r3-048-tc9lm.18d3d47010a691f2,"reason=Pulled count=1 msg=Container image ""busybox:musl"" already present on machine"
60.2475,Event,ADDED,eval-sanitize-5-r3-048-tc9lm.18d3d47011ff1301,reason=Created count=1 msg=Created container: task
60.2477,Event,ADDED,eval-sanitize-5-r3-048-tc9lm.18d3d47014031910,reason=Started count=1 msg=Started container task
60.2479,Event,ADDED,eval-sanitize-5-r3-048.18d3d46edbd6bb05,reason=SuccessfulCreate count=1 msg=Created pod: eval-sanitize-5-r3-048-tc9lm
60.248,Event,ADDED,eval-sanitize-5-r3-049-t2ff5.18d3d46f187c1767,"reason=FailedScheduling count=None msg=0/6 nodes are available: 1 c_wall violated: 2 conflicting context pair(s) with node memory, 5 node(s) had untolerated taint(s). no new claims to deallocate, preemption: 0/6 nodes are available: 1 No preemption victims found for incoming pod, 5 Preemption is not helpful for scheduling."
60.2482,Event,ADDED,eval-sanitize-5-r3-049-t2ff5.18d3d46f19190570,"reason=FailedScheduling count=None msg=0/6 nodes are available: 1 c_wall violated: 2 conflicting context pair(s) with node memory, 5 node(s) had untolerated taint(s). no new claims to deallocate, preemption: 0/6 nodes are available: 1 No preemption victims found for incoming pod, 5 Preemption is not helpful for scheduling."
60.2484,Event,ADDED,eval-sanitize-5-r3-049-t2ff5.18d3d46fc5ad04b5,reason=Scheduled count=None msg=Successfully assigned compute/eval-sanitize-5-r3-049-t2ff5 to kind-worker5
60.2485,Event,ADDED,eval-sanitize-5-r3-049-t2ff5.18d3d46fdf0e8447,"reason=Pulled count=1 msg=Container image ""busybox:musl"" already present on machine"
60.2487,Event,ADDED,eval-sanitize-5-r3-049-t2ff5.18d3d46fe02ca732,reason=Created count=1 msg=Created container: task
60.2489,Event,ADDED,eval-sanitize-5-r3-049-t2ff5.18d3d46fe25e7629,reason=Started count=1 msg=Started container task
60.249,Event,ADDED,eval-sanitize-5-r3-049.18d3d46f1838f8d6,reason=SuccessfulCreate count=1 msg=Created pod: eval-sanitize-5-r3-049-t2ff5
60.2492,Event,ADDED,eval-sanitize-5-r3-050-l6mlt.18d3d46f53120ce1,"reason=FailedScheduling count=None msg=0/6 nodes are available: 1 c_wall violated: 1 conflicting context pair(s) with node memory, 5 node(s) had untolerated taint(s). no new claims to deallocate, preemption: 0/6 nodes are available: 1 No preemption victims found for incoming pod, 5 Preemption is not helpful for scheduling."
60.2495,Event,ADDED,eval-sanitize-5-r3-050-l6mlt.18d3d46f539aeff4,"reason=FailedScheduling count=None msg=0/6 nodes are available: 1 c_wall violated: 1 conflicting context pair(s) with node memory, 5 node(s) had untolerated taint(s). no new claims to deallocate, preemption: 0/6 nodes are available: 1 No preemption victims found for incoming pod, 5 Preemption is not helpful for scheduling."
60.2497,Event,ADDED,eval-sanitize-5-r3-050-l6mlt.18d3d46fcb5d7648,"reason=FailedScheduling count=None msg=0/6 nodes are available: 1 c_wall violated: 1 conflicting context pair(s) with node memory, 1 c_wall violated: 2 conflicting context pair(s) with node memory, 4 node(s) had untolerated taint(s). no new claims to deallocate, preemption: 0/6 nodes are available: 2 No preemption victims found for incoming pod, 4 Preemption is not helpful for scheduling."
60.2499,Event,ADDED,eval-sanitize-5-r3-050-l6mlt.18d3d46fd2ff004d,"reason=FailedScheduling count=None msg=0/6 nodes are available: 1 c_wall violated: 2 conflicting context pair(s) with node memory, 5 node(s) had untolerated taint(s). no new claims to deallocate, preemption: 0/6 nodes are available: 1 No preemption victims found for incoming pod, 5 Preemption is not helpful for scheduling."
60.2501,Event,ADDED,eval-sanitize-5-r3-050-l6mlt.18d3d46ff6ff5941,reason=Scheduled count=None msg=Successfully assigned compute/eval-sanitize-5-r3-050-l6mlt to kind-worker
60.2502,Event,ADDED,eval-sanitize-5-r3-050-l6mlt.18d3d47010c00dea,"reason=Pulled count=1 msg=Container image ""busybox:musl"" already present on machine"
60.2504,Event,ADDED,eval-sanitize-5-r3-050-l6mlt.18d3d47012596f99,reason=Created count=1 msg=Created container: task
60.2506,Event,ADDED,eval-sanitize-5-r3-050-l6mlt.18d3d4701449f105,reason=Started count=1 msg=Started container task
60.2507,Event,ADDED,eval-sanitize-5-r3-050.18d3d46f52d8ea3c,reason=SuccessfulCreate count=1 msg=Created pod: eval-sanitize-5-r3-050-l6mlt
60.2509,Event,ADDED,eval-sanitize-5-r3-051-dsht7.18d3d46f8eca1aef,"reason=FailedScheduling count=None msg=0/6 nodes are available: 1 c_wall violated: 2 conflicting context pair(s) with node memory, 5 node(s) had untolerated taint(s). no new claims to deallocate, preemption: 0/6 nodes are available: 1 No preemption victims found for incoming pod, 5 Preemption is not helpful for scheduling."
60.2511,Event,ADDED,eval-sanitize-5-r3-051-dsht7.18d3d46f8f771701,"reason=FailedScheduling count=None msg=0/6 nodes are available: 1 c_wall violated: 2 conflicting context pair(s) with node memory, 5 node(s) had untolerated taint(s). no new claims to deallocate, preemption: 0/6 nodes are available: 1 No preemption victims found for incoming pod, 5 Preemption is not helpful for scheduling."
60.2512,Event,ADDED,eval-sanitize-5-r3-051-dsht7.18d3d46fbbe3bad8,reason=Scheduled count=None msg=Successfully assigned compute/eval-sanitize-5-r3-051-dsht7 to kind-worker5
60.2514,Event,ADDED,eval-sanitize-5-r3-051-dsht7.18d3d46fd64c20bc,"reason=Pulled count=1 msg=Container image ""busybox:musl"" already present on machine"
60.2516,Event,ADDED,eval-sanitize-5-r3-051-dsht7.18d3d46fd7bcc076,reason=Created count=1 msg=Created container: task
60.2517,Event,ADDED,eval-sanitize-5-r3-051-dsht7.18d3d46fdc82230a,reason=Started count=1 msg=Started container task
60.2519,Event,ADDED,eval-sanitize-5-r3-051.18d3d46f8e8a8cac,reason=SuccessfulCreate count=1 msg=Created pod: eval-sanitize-5-r3-051-dsht7
60.252,Event,ADDED,eval-sanitize-5-r3-052-gndzv.18d3d46fcc1b5f2e,reason=Scheduled count=None msg=Successfully assigned compute/eval-sanitize-5-r3-052-gndzv to kind-worker5
60.2522,Event,ADDED,eval-sanitize-5-r3-052-gndzv.18d3d46fe3cd9847,"reason=Pulled count=1 msg=Container image ""busybox:musl"" already present on machine"
60.2524,Event,ADDED,eval-sanitize-5-r3-052-gndzv.18d3d46fe4debbc8,reason=Created count=1 msg=Created container: task
60.2525,Event,ADDED,eval-sanitize-5-r3-052-gndzv.18d3d46fe8b471c4,reason=Started count=1 msg=Started container task
60.2527,Event,ADDED,eval-sanitize-5-r3-052.18d3d46fca029cca,reason=SuccessfulCreate count=1 msg=Created pod: eval-sanitize-5-r3-052-gndzv
60.2528,Event,ADDED,eval-sanitize-5-r3-053-dbxqm.18d3d470073e2e7f,reason=Scheduled count=None msg=Successfully assigned compute/eval-sanitize-5-r3-053-dbxqm to kind-worker5
60.253,Event,ADDED,eval-sanitize-5-r3-053-dbxqm.18d3d4702023c882,"reason=Pulled count=1 msg=Container image ""busybox:musl"" already present on machine"
60.2532,Event,ADDED,eval-sanitize-5-r3-053-dbxqm.18d3d470213f936f,reason=Created count=1 msg=Created container: task
60.2533,Event,ADDED,eval-sanitize-5-r3-053-dbxqm.18d3d47023b3f2bc,reason=Started count=1 msg=Started container task
60.2535,Event,ADDED,eval-sanitize-5-r3-053.18d3d470059dbc66,reason=SuccessfulCreate count=1 msg=Created pod: eval-sanitize-5-r3-053-dbxqm
60.2537,Event,ADDED,eval-sanitize-5-r3-054-tfvvd.18d3d470424a1be2,"reason=FailedScheduling count=None msg=0/6 nodes are available: 2 c_wall violated: 1 conflicting context pair(s) with node memory, 4 node(s) had untolerated taint(s). no new claims to deallocate, preemption: 0/6 nodes are available: 2 No preemption victims found for incoming pod, 4 Preemption is not helpful for scheduling."
60.2539,Event,ADDED,eval-sanitize-5-r3-054-tfvvd.18d3d47042f89496,"reason=FailedScheduling count=None msg=0/6 nodes are available: 2 c_wall violated: 1 conflicting context pair(s) with node memory, 4 node(s) had untolerated taint(s). no new claims to deallocate, preemption: 0/6 nodes are available: 2 No preemption victims found for incoming pod, 4 Preemption is not helpful for scheduling."
60.254,Event,ADDED,eval-sanitize-5-r3-054-tfvvd.18d3d470791ce30a,reason=Scheduled count=None msg=Successfully assigned compute/eval-sanitize-5-r3-054-tfvvd to kind-worker3
60.2542,Event,ADDED,eval-sanitize-5-r3-054-tfvvd.18d3d470a513747b,"reason=Pulled count=1 msg=Container image ""busybox:musl"" already present on machine"
60.2543,Event,ADDED,eval-sanitize-5-r3-054-tfvvd.18d3d470a61e4d45,reason=Created count=1 msg=Created container: task
60.2545,Event,ADDED,eval-sanitize-5-r3-054-tfvvd.18d3d470a7e29fb2,reason=Started count=1 msg=Started container task
60.2547,Event,ADDED,eval-sanitize-5-r3-054.18d3d47041dfdf9a,reason=SuccessfulCreate count=1 msg=Created pod: eval-sanitize-5-r3-054-tfvvd
60.2548,Event,ADDED,eval-sanitize-5-r3-055-n28zx.18d3d4707e9737ce,reason=Scheduled count=None msg=Successfully assigned compute/eval-sanitize-5-r3-055-n28zx to kind-worker3
60.255,Event,ADDED,eval-sanitize-5-r3-055-n28zx.18d3d47099303ad9,"reason=Pulled count=1 msg=Container image ""busybox:musl"" already present on machine"
60.2551,Event,ADDED,eval-sanitize-5-r3-055-n28zx.18d3d4709a3d2a5b,reason=Created count=1 msg=Created container: task
60.2553,Event,ADDED,eval-sanitize-5-r3-055-n28zx.18d3d4709ec3ad31,reason=Started count=1 msg=Started container task
60.2555,Event,ADDED,eval-sanitize-5-r3-055.18d3d4707cb602f3,reason=SuccessfulCreate count=1 msg=Created pod: eval-sanitize-5-r3-055-n28zx
60.2556,Event,ADDED,eval-sanitize-5-r3-056-p8v5t.18d3d470b9330cd4,reason=Scheduled count=None msg=Successfully assigned compute/eval-sanitize-5-r3-056-p8v5t to kind-worker
60.2559,Event,ADDED,eval-sanitize-5-r3-056-p8v5t.18d3d470d8476786,"reason=Pulled count=1 msg=Container image ""busybox:musl"" already present on machine"
60.256,Event,ADDED,eval-sanitize-5-r3-056-p8v5t.18d3d470d959653b,reason=Created count=1 msg=Created container: task
60.2562,Event,ADDED,eval-sanitize-5-r3-056-p8v5t.18d3d470dd790bf5,reason=Started count=1 msg=Started container task
60.2564,Event,ADDED,eval-sanitize-5-r3-056.18d3d470b841453e,reason=SuccessfulCreate count=1 msg=Created pod: eval-sanitize-5-r3-056-p8v5t
60.2565,Event,ADDED,eval-sanitize-5-r3-057-bccxp.18d3d470f4c3df5d,reason=Scheduled count=None msg=Successfully assigned compute/eval-sanitize-5-r3-057-bccxp to kind-worker4
60.2567,Event,ADDED,eval-sanitize-5-r3-057-bccxp.18d3d4710dc8ecba,"reason=Pulled count=1 msg=Container image ""busybox:musl"" already present on machine"
60.2569,Event,ADDED,eval-sanitize-5-r3-057-bccxp.18d3d4710ed6ac2f,reason=Created count=1 msg=Created container: task
60.2571,Event,ADDED,eval-sanitize-5-r3-057-bccxp.18d3d471134b4623,reason=Started count=1 msg=Started container task
60.2573,Event,ADDED,eval-sanitize-5-r3-057.18d3d470f4004837,reason=SuccessfulCreate count=1 msg=Created pod: eval-sanitize-5-r3-057-bccxp
60.2575,Event,ADDED,eval-sanitize-5-r3-058-nvqm9.18d3d4712ff51c48,"reason=FailedScheduling count=None msg=0/6 nodes are available: 2 c_wall violated: 1 conflicting context pair(s) with node memory, 4 node(s) had untolerated taint(s). no new claims to deallocate, preemption: 0/6 nodes are available: 2 No preemption victims found for incoming pod, 4 Preemption is not helpful for scheduling."
60.2577,Event,ADDED,eval-sanitize-5-r3-058-nvqm9.18d3d47130958a00,"reason=FailedScheduling count=None msg=0/6 nodes are available: 2 c_wall violated: 1 conflicting context pair(s) with node memory, 4 node(s) had untolerated taint(s). no new claims to deallocate, preemption: 0/6 nodes are available: 2 No preemption victims found for incoming pod, 4 Preemption is not helpful for scheduling."
60.2578,Event,ADDED,eval-sanitize-5-r3-058-nvqm9.18d3d471a10224c4,"reason=FailedScheduling count=None msg=0/6 nodes are available: 1 c_wall violated: 1 conflicting context pair(s) with node memory, 5 node(s) had untolerated taint(s). no new claims to deallocate, preemption: 0/6 nodes are available: 1 No preemption victims found for incoming pod, 5 Preemption is not helpful for scheduling."
60.258,Event,ADDED,eval-sanitize-5-r3-058.18d3d4712f904f0a,reason=SuccessfulCreate count=1 msg=Created pod: eval-sanitize-5-r3-058-nvqm9
60.2581,Event,ADDED,eval-sanitize-5-r3-059-4hqs6.18d3d4716bc1434d,"reason=FailedScheduling count=None msg=0/6 nodes are available: 2 c_wall violated: 1 conflicting context pair(s) with node memory, 4 node(s) had untolerated taint(s). no new claims to deallocate, preemption: 0/6 nodes are available: 2 No preemption victims found for incoming pod, 4 Preemption is not helpful for scheduling."
60.2583,Event,ADDED,eval-sanitize-5-r3-059-4hqs6.18d3d4716c6b433a,"reason=FailedScheduling count=None msg=0/6 nodes are available: 2 c_wall violated: 1 conflicting context pair(s) with node memory, 4 node(s) had untolerated taint(s). no new claims to deallocate, preemption: 0/6 nodes are available: 2 No preemption victims found for incoming pod, 4 Preemption is not helpful for scheduling."
60.2585,Event,ADDED,eval-sanitize-5-r3-059-4hqs6.18d3d471a1300290,"reason=FailedScheduling count=None msg=0/6 nodes are available: 1 c_wall violated: 1 conflicting context pair(s) with node memory, 5 node(s) had untolerated taint(s). no new claims to deallocate, preemption: 0/6 nodes are available: 1 No preemption victims found for incoming pod, 5 Preemption is not helpful for scheduling."
60.2586,Event,ADDED,eval-sanitize-5-r3-059.18d3d4716b447e73,reason=SuccessfulCreate count=1 msg=Created pod: eval-sanitize-5-r3-059-4hqs6
60.259,Event,ADDED,eval-sanitize-5-r3-060.18d3d471a72c6e68,reason=SuccessfulCreate count=1 msg=Created pod: eval-sanitize-5-r3-060-jqm27
60.2591,Event,ADDED,eval-sanitize-5-r3-060-jqm27.18d3d471a76d73f1,"reason=FailedScheduling count=None msg=0/6 nodes are available: 1 c_wall violated: 1 conflicting context pair(s) with node memory, 5 node(s) had untolerated taint(s). no new claims to deallocate, preemption: 0/6 nodes are available: 1 No preemption victims found for incoming pod, 5 Preemption is not helpful for scheduling."
60.2593,Event,ADDED,eval-sanitize-5-r3-060-jqm27.18d3d471a7e3d793,"reason=FailedScheduling count=None msg=0/6 nodes are available: 1 c_wall violated: 1 conflicting context pair(s) with node memory, 5 node(s) had untolerated taint(s). no new claims to deallocate, preemption: 0/6 nodes are available: 1 No preemption victims found for incoming pod, 5 Preemption is not helpful for scheduling."
61.0131,Job,MODIFIED,eval-sanitize-5-r3-045,
61.0147,Job,MODIFIED,eval-sanitize-5-r3-044,
61.015,TaskRequest,ADDED,eval-sanitize-5-r3-061,phase=None job=None
61.0159,Job,MODIFIED,eval-sanitize-5-r3-043,
61.0174,Job,MODIFIED,eval-sanitize-5-r3-045,
61.0199,Job,MODIFIED,eval-sanitize-5-r3-043,
61.0208,Job,MODIFIED,eval-sanitize-5-r3-044,
61.022,TaskRequest,MODIFIED,eval-sanitize-5-r3-061,phase=Pending job=None
61.0249,Event,ADDED,eval-sanitize-5-r3-045.18d3d471e198974e,reason=Completed count=1 msg=Job completed
61.0275,Job,MODIFIED,eval-sanitize-5-r3-044,
61.0288,Job,MODIFIED,eval-sanitize-5-r3-043,
61.0298,Job,MODIFIED,eval-sanitize-5-r3-045,
61.0302,Event,ADDED,eval-sanitize-5-r3-043.18d3d471e1babf50,reason=Completed count=1 msg=Job completed
61.0332,Event,ADDED,eval-sanitize-5-r3-044.18d3d471e1bb7c3b,reason=Completed count=1 msg=Job completed
61.0409,Job,ADDED,eval-sanitize-5-r3-061,
61.0425,Job,MODIFIED,eval-sanitize-5-r3-060,
61.046,TaskRequest,MODIFIED,eval-sanitize-5-r3-061,phase=Scheduled job=None
61.0488,Pod,ADDED,eval-sanitize-5-r3-061-jsgbk,phase=Pending node=None
61.0504,Job,MODIFIED,eval-sanitize-5-r3-061,
61.0521,TaskRequest,MODIFIED,eval-sanitize-5-r3-044,phase=Complete job=None
61.0528,Event,ADDED,eval-sanitize-5-r3-061.18d3d471e378da86,reason=SuccessfulCreate count=1 msg=Created pod: eval-sanitize-5-r3-061-jsgbk
61.0573,Pod,MODIFIED,eval-sanitize-5-r3-061-jsgbk,phase=Pending node=None
61.0577,Event,ADDED,eval-sanitize-5-r3-061-jsgbk.18d3d471e3b3d3a1,"reason=FailedScheduling count=None msg=0/6 nodes are available: 1 c_wall violated: 1 conflicting context pair(s) with node memory, 5 node(s) had untolerated taint(s). no new claims to deallocate, preemption: 0/6 nodes are available: 1 No preemption victims found for incoming pod, 5 Preemption is not helpful for scheduling."
61.0618,TaskRequest,MODIFIED,eval-sanitize-5-r3-061,phase=Scheduled job=None
61.0635,Event,ADDED,eval-sanitize-5-r3-061-jsgbk.18d3d471e42cd82d,"reason=FailedScheduling count=None msg=0/6 nodes are available: 1 c_wall violated: 1 conflicting context pair(s) with node memory, 5 node(s) had untolerated taint(s). no new claims to deallocate, preemption: 0/6 nodes are available: 1 No preemption victims found for incoming pod, 5 Preemption is not helpful for scheduling."
61.1193,TaskRequest,MODIFIED,eval-sanitize-5-r3-043,phase=Complete job=None
61.1225,Job,MODIFIED,eval-sanitize-5-r3-044,
61.1245,TaskRequest,MODIFIED,eval-sanitize-5-r3-045,phase=Complete job=None
61.1291,Job,MODIFIED,eval-sanitize-5-r3-043,
61.1335,Job,MODIFIED,eval-sanitize-5-r3-045,
61.1352,Job,MODIFIED,eval-sanitize-5-r3-060,
61.5031,Node,MODIFIED,kind-worker4,taints=1
61.5083,Pod,MODIFIED,eval-sanitize-5-r3-058-nvqm9,phase=Pending node=None
61.5088,Event,MODIFIED,eval-sanitize-5-r3-058-nvqm9.18d3d471a10224c4,"reason=FailedScheduling count=None msg=0/6 nodes are available: 1 c_wall violated: 1 conflicting context pair(s) with node memory, 5 node(s) had untolerated taint(s). no new claims to deallocate, preemption: 0/6 nodes are available: 1 No preemption victims found for incoming pod, 5 Preemption is not helpful for scheduling."
61.5135,Pod,MODIFIED,eval-sanitize-5-r3-059-4hqs6,phase=Pending node=None
61.5161,Event,MODIFIED,eval-sanitize-5-r3-059-4hqs6.18d3d471a1300290,"reason=FailedScheduling count=None msg=0/6 nodes are available: 1 c_wall violated: 1 conflicting context pair(s) with node memory, 5 node(s) had untolerated taint(s). no new claims to deallocate, preemption: 0/6 nodes are available: 1 No preemption victims found for incoming pod, 5 Preemption is not helpful for scheduling."
61.5205,Node,MODIFIED,kind-worker4,taints=1
61.5215,Pod,MODIFIED,eval-sanitize-5-r3-060-jqm27,phase=Pending node=None
61.522,Event,MODIFIED,eval-sanitize-5-r3-060-jqm27.18d3d471a7e3d793,"reason=FailedScheduling count=None msg=0/6 nodes are available: 1 c_wall violated: 1 conflicting context pair(s) with node memory, 5 node(s) had untolerated taint(s). no new claims to deallocate, preemption: 0/6 nodes are available: 1 No preemption victims found for incoming pod, 5 Preemption is not helpful for scheduling."
61.5263,Pod,MODIFIED,eval-sanitize-5-r3-061-jsgbk,phase=Pending node=None
61.5267,Event,MODIFIED,eval-sanitize-5-r3-061-jsgbk.18d3d471e42cd82d,"reason=FailedScheduling count=None msg=0/6 nodes are available: 1 c_wall violated: 1 conflicting context pair(s) with node memory, 5 node(s) had untolerated taint(s). no new claims to deallocate, preemption: 0/6 nodes are available: 1 No preemption victims found for incoming pod, 5 Preemption is not helpful for scheduling."
62.0129,TaskRequest,ADDED,eval-sanitize-5-r3-062,phase=None job=None
62.0176,TaskRequest,MODIFIED,eval-sanitize-5-r3-062,phase=Pending job=None
62.0313,Job,ADDED,eval-sanitize-5-r3-062,
62.0379,Pod,ADDED,eval-sanitize-5-r3-062-lrf47,phase=Pending node=None
62.038,TaskRequest,MODIFIED,eval-sanitize-5-r3-062,phase=Scheduled job=None
62.0421,Job,MODIFIED,eval-sanitize-5-r3-062,
62.0526,Event,ADDED,eval-sanitize-5-r3-062.18d3d4721e672420,reason=SuccessfulCreate count=1 msg=Created pod: eval-sanitize-5-r3-062-lrf47
62.0532,Event,ADDED,eval-sanitize-5-r3-062-lrf47.18d3d4721e732142,"reason=FailedScheduling count=None msg=0/6 nodes are available: 6 node(s) had untolerated taint(s). no new claims to deallocate, preemption: 0/6 nodes are available: 6 Preemption is not helpful for scheduling."
62.0541,Pod,MODIFIED,eval-sanitize-5-r3-062-lrf47,phase=Pending node=None
62.055,TaskRequest,MODIFIED,eval-sanitize-5-r3-062,phase=Scheduled job=None
62.058,Job,MODIFIED,eval-sanitize-5-r3-061,
62.0672,Job,MODIFIED,eval-sanitize-5-r3-061,
62.4679,Node,MODIFIED,kind-worker2,taints=1
62.4805,Node,MODIFIED,kind-worker2,taints=0
62.4846,Pod,MODIFIED,eval-sanitize-5-r3-058-nvqm9,phase=Pending node=kind-worker2
62.4912,Node,MODIFIED,kind-worker2,taints=0
62.4916,Event,ADDED,eval-sanitize-5-r3-058-nvqm9.18d3d4723908ed64,reason=Scheduled count=None msg=Successfully assigned compute/eval-sanitize-5-r3-058-nvqm9 to kind-worker2
62.4918,Event,ADDED,eval-sanitize-5-r3-059-4hqs6.18d3d472390fda84,"reason=FailedScheduling count=None msg=0/6 nodes are available: 1 c_wall violated: 1 conflicting context pair(s) with node memory, 5 node(s) had untolerated taint(s). no new claims to deallocate, preemption: 0/6 nodes are available: 1 No preemption victims found for incoming pod, 5 Preemption is not helpful for scheduling."
62.4928,Pod,MODIFIED,eval-sanitize-5-r3-059-4hqs6,phase=Pending node=None
62.5054,Pod,MODIFIED,eval-sanitize-5-r3-058-nvqm9,phase=Pending node=kind-worker2
62.5081,Pod,MODIFIED,eval-sanitize-5-r3-060-jqm27,phase=Pending node=None
62.5084,Event,ADDED,eval-sanitize-5-r3-060-jqm27.18d3d47239b97310,"reason=FailedScheduling count=None msg=0/6 nodes are available: 1 c_wall violated: 1 conflicting context pair(s) with node memory, 5 node(s) had untolerated taint(s). no new claims to deallocate, preemption: 0/6 nodes are available: 1 No preemption victims found for incoming pod, 5 Preemption is not helpful for scheduling."
62.5097,Node,MODIFIED,kind-worker2,taints=0
62.5576,Pod,MODIFIED,eval-sanitize-5-r3-061-jsgbk,phase=Pending node=None
62.5583,Event,ADDED,eval-sanitize-5-r3-061-jsgbk.18d3d4723c3de401,"reason=FailedScheduling count=None msg=0/6 nodes are available: 1 c_wall violated: 1 conflicting context pair(s) with node memory, 5 node(s) had untolerated taint(s). no new claims to deallocate, preemption: 0/6 nodes are available: 1 No preemption victims found for incoming pod, 5 Preemption is not helpful for scheduling."
62.5598,Node,MODIFIED,kind-worker2,taints=0
62.5666,Pod,MODIFIED,eval-sanitize-5-r3-062-lrf47,phase=Pending node=kind-worker2
62.5718,Node,MODIFIED,kind-worker2,taints=0
62.5791,Pod,MODIFIED,eval-sanitize-5-r3-062-lrf47,phase=Pending node=kind-worker2
62.608,Pod,MODIFIED,eval-sanitize-5-r3-059-4hqs6,phase=Pending node=None
62.6088,Event,ADDED,eval-sanitize-5-r3-062-lrf47.18d3d4723fe5abcf,reason=Scheduled count=None msg=Successfully assigned compute/eval-sanitize-5-r3-062-lrf47 to kind-worker2
62.6089,Event,ADDED,eval-sanitize-5-r3-059-4hqs6.18d3d4723dc0553c,"reason=FailedScheduling count=None msg=0/6 nodes are available: 1 c_wall violated: 2 conflicting context pair(s) with node memory, 5 node(s) had untolerated taint(s). no new claims to deallocate, preemption: 0/6 nodes are available: 1 No preemption victims found for incoming pod, 5 Preemption is not helpful for scheduling."
62.6126,Node,MODIFIED,kind-worker2,taints=0
62.6172,Pod,MODIFIED,eval-sanitize-5-r3-060-jqm27,phase=Pending node=None
62.6185,Event,ADDED,eval-sanitize-5-r3-060-jqm27.18d3d47240a1234b,"reason=FailedScheduling count=None msg=0/6 nodes are available: 1 c_wall violated: 2 conflicting context pair(s) with node memory, 5 node(s) had untolerated taint(s). no new claims to deallocate, preemption: 0/6 nodes are available: 1 No preemption victims found for incoming pod, 5 Preemption is not helpful for scheduling."
62.6223,Node,MODIFIED,kind-worker2,taints=0
62.6247,Pod,MODIFIED,eval-sanitize-5-r3-061-jsgbk,phase=Pending node=None
62.6252,Event,ADDED,eval-sanitize-5-r3-061-jsgbk.18d3d47241248bf7,"reason=FailedScheduling count=None msg=0/6 nodes are available: 1 c_wall violated: 2 conflicting context pair(s) with node memory, 5 node(s) had untolerated taint(s). no new claims to deallocate, preemption: 0/6 nodes are available: 1 No preemption victims found for incoming pod, 5 Preemption is not helpful for scheduling."
62.6324,Event,ADDED,eval-sanitize-5-r3-059-4hqs6.18d3d4724199449f,"reason=FailedScheduling count=None msg=0/6 nodes are available: 1 c_wall violated: 2 conflicting context pair(s) with node memory, 5 node(s) had untolerated taint(s). no new claims to deallocate, preemption: 0/6 nodes are available: 1 No preemption victims found for incoming pod, 5 Preemption is not helpful for scheduling."
62.6338,Event,ADDED,eval-sanitize-5-r3-060-jqm27.18d3d47241bebd68,"reason=FailedScheduling count=None msg=0/6 nodes are available: 1 c_wall violated: 2 conflicting context pair(s) with node memory, 5 node(s) had untolerated taint(s). no new claims to deallocate, preemption: 0/6 nodes are available: 1 No preemption victims found for incoming pod, 5 Preemption is not helpful for scheduling."
62.6357,Event,ADDED,eval-sanitize-5-r3-061-jsgbk.18d3d47241e4b0a3,"reason=FailedScheduling count=None msg=0/6 nodes are available: 1 c_wall violated: 2 conflicting context pair(s) with node memory, 5 node(s) had untolerated taint(s). no new claims to deallocate, preemption: 0/6 nodes are available: 1 No preemption victims found for incoming pod, 5 Preemption is not helpful for scheduling."
62.8992,Event,ADDED,eval-sanitize-5-r3-058-nvqm9.18d3d4725166b6ed,"reason=Pulled count=1 msg=Container image ""busybox:musl"" already present on machine"
62.9207,Event,ADDED,eval-sanitize-5-r3-058-nvqm9.18d3d47252cbc981,reason=Created count=1 msg=Created container: task
62.9501,Pod,MODIFIED,eval-sanitize-5-r3-051-dsht7,phase=Running node=kind-worker5
62.9613,Pod,MODIFIED,eval-sanitize-5-r3-049-t2ff5,phase=Running node=kind-worker5
62.9623,Event,ADDED,eval-sanitize-5-r3-058-nvqm9.18d3d47254dd1dae,reason=Started count=1 msg=Started container task
62.9638,Event,MODIFIED,eval-sanitize-5-r3-059-4hqs6.18d3d4724199449f,"reason=FailedScheduling count=None msg=0/6 nodes are available: 1 c_wall violated: 2 conflicting context pair(s) with node memory, 5 node(s) had untolerated taint(s). no new claims to deallocate, preemption: 0/6 nodes are available: 1 No preemption victims found for incoming pod, 5 Preemption is not helpful for scheduling."
62.9663,Event,MODIFIED,eval-sanitize-5-r3-060-jqm27.18d3d47241bebd68,"reason=FailedScheduling count=None msg=0/6 nodes are available: 1 c_wall violated: 2 conflicting context pair(s) with node memory, 5 node(s) had untolerated taint(s). no new claims to deallocate, preemption: 0/6 nodes are available: 1 No preemption victims found for incoming pod, 5 Preemption is not helpful for scheduling."
62.9684,Event,MODIFIED,eval-sanitize-5-r3-061-jsgbk.18d3d47241e4b0a3,"reason=FailedScheduling count=None msg=0/6 nodes are available: 1 c_wall violated: 2 conflicting context pair(s) with node memory, 5 node(s) had untolerated taint(s). no new claims to deallocate, preemption: 0/6 nodes are available: 1 No preemption victims found for incoming pod, 5 Preemption is not helpful for scheduling."
62.9735,Pod,MODIFIED,eval-sanitize-5-r3-052-gndzv,phase=Running node=kind-worker5
62.9738,Event,ADDED,eval-sanitize-5-r3-062-lrf47.18d3d47255bcea3a,"reason=Pulled count=1 msg=Container image ""busybox:musl"" already present on machine"
62.9822,Pod,MODIFIED,eval-sanitize-5-r3-046-bg7dm,phase=Running node=kind-worker5
62.9899,Pod,MODIFIED,eval-sanitize-5-r3-058-nvqm9,phase=Running node=kind-worker2
62.9924,Event,ADDED,eval-sanitize-5-r3-062-lrf47.18d3d4725707e687,reason=Created count=1 msg=Created container: task
63.0064,TaskRequest,ADDED,eval-sanitize-5-r3-063,phase=None job=None
63.0099,TaskRequest,MODIFIED,eval-sanitize-5-r3-063,phase=Pending job=None
63.0248,Job,ADDED,eval-sanitize-5-r3-063,
63.0312,Pod,ADDED,eval-sanitize-5-r3-063-rcwj5,phase=Pending node=None
63.0313,TaskRequest,MODIFIED,eval-sanitize-5-r3-063,phase=Scheduled job=None
63.0339,Job,MODIFIED,eval-sanitize-5-r3-063,
63.0362,Event,ADDED,eval-sanitize-5-r3-063.18d3d47259a175bd,reason=SuccessfulCreate count=1 msg=Created pod: eval-sanitize-5-r3-063-rcwj5
63.0386,TaskRequest,MODIFIED,eval-sanitize-5-r3-063,phase=Scheduled job=None
63.0418,Job,MODIFIED,eval-sanitize-5-r3-062,
63.0506,Job,MODIFIED,eval-sanitize-5-r3-062,
63.0621,Pod,MODIFIED,eval-sanitize-5-r3-063-rcwj5,phase=Pending node=None
63.0629,Event,ADDED,eval-sanitize-5-r3-063-rcwj5.18d3d4725b176f74,"reason=FailedScheduling count=None msg=0/6 nodes are available: 1 c_wall violated: 2 conflicting context pair(s) with node memory, 5 node(s) had untolerated taint(s). no new claims to deallocate, preemption: 0/6 nodes are available: 1 No preemption victims found for incoming pod, 5 Preemption is not helpful for scheduling."
63.064,Event,ADDED,eval-sanitize-5-r3-062-lrf47.18d3d4725b5fd952,reason=Started count=1 msg=Started container task
63.0763,Event,ADDED,eval-sanitize-5-r3-063-rcwj5.18d3d4725c1b72bf,"reason=FailedScheduling count=None msg=0/6 nodes are available: 1 c_wall violated: 2 conflicting context pair(s) with node memory, 5 node(s) had untolerated taint(s). no new claims to deallocate, preemption: 0/6 nodes are available: 1 No preemption victims found for incoming pod, 5 Preemption is not helpful for scheduling."
63.5418,Pod,MODIFIED,eval-sanitize-5-r3-048-tc9lm,phase=Running node=kind-worker
63.5484,Pod,MODIFIED,eval-sanitize-5-r3-050-l6mlt,phase=Running node=kind-worker
63.5595,Event,MODIFIED,eval-sanitize-5-r3-063-rcwj5.18d3d4725c1b72bf,"reason=FailedScheduling count=None msg=0/6 nodes are available: 1 c_wall violated: 2 conflicting context pair(s) with node memory, 5 node(s) had untolerated taint(s). no new claims to deallocate, preemption: 0/6 nodes are available: 1 No preemption victims found for incoming pod, 5 Preemption is not helpful for scheduling."
63.9566,Pod,MODIFIED,eval-sanitize-5-r3-053-dbxqm,phase=Running node=kind-worker5
63.96,Job,MODIFIED,eval-sanitize-5-r3-051,
63.9659,Job,MODIFIED,eval-sanitize-5-r3-049,
63.9704,Job,MODIFIED,eval-sanitize-5-r3-051,
63.9754,Job,MODIFIED,eval-sanitize-5-r3-049,
63.9781,Job,MODIFIED,eval-sanitize-5-r3-052,
63.9871,Job,MODIFIED,eval-sanitize-5-r3-046,
63.9889,Job,MODIFIED,eval-sanitize-5-r3-052,
63.9947,Pod,MODIFIED,eval-sanitize-5-r3-062-lrf47,phase=Running node=kind-worker2
63.9959,Job,MODIFIED,eval-sanitize-5-r3-058,
63.998,Job,MODIFIED,eval-sanitize-5-r3-046,
64.0052,Job,MODIFIED,eval-sanitize-5-r3-058,
64.0067,TaskRequest,ADDED,eval-sanitize-5-r3-064,phase=None job=None
64.0102,TaskRequest,MODIFIED,eval-sanitize-5-r3-064,phase=Pending job=None
64.0265,Job,ADDED,eval-sanitize-5-r3-064,
64.0326,Pod,ADDED,eval-sanitize-5-r3-064-mcszm,phase=Pending node=None
64.0372,Job,MODIFIED,eval-sanitize-5-r3-063,
64.0381,Event,ADDED,eval-sanitize-5-r3-064.18d3d472955221b6,reason=SuccessfulCreate count=1 msg=Created pod: eval-sanitize-5-r3-064-mcszm
64.0389,Job,MODIFIED,eval-sanitize-5-r3-064,
64.0461,Job,MODIFIED,eval-sanitize-5-r3-062,
64.0593,Pod,MODIFIED,eval-sanitize-5-r3-064-mcszm,phase=Pending node=None
64.0604,Event,ADDED,eval-sanitize-5-r3-064-mcszm.18d3d472969bd633,"reason=FailedScheduling count=None msg=0/6 nodes are available: 1 c_wall violated: 1 conflicting context pair(s) with node memory, 5 node(s) had untolerated taint(s). no new claims to deallocate, preemption: 0/6 nodes are available: 1 No preemption victims found for incoming pod, 5 Preemption is not helpful for scheduling."
64.0605,TaskRequest,MODIFIED,eval-sanitize-5-r3-064,phase=Scheduled job=None
64.0648,Job,MODIFIED,eval-sanitize-5-r3-064,
64.0714,TaskRequest,MODIFIED,eval-sanitize-5-r3-064,phase=Scheduled job=None
64.0736,Event,ADDED,eval-sanitize-5-r3-064-mcszm.18d3d472975c58e5,"reason=FailedScheduling count=None msg=0/6 nodes are available: 1 c_wall violated: 1 conflicting context pair(s) with node memory, 5 node(s) had untolerated taint(s). no new claims to deallocate, preemption: 0/6 nodes are available: 1 No preemption victims found for incoming pod, 5 Preemption is not helpful for scheduling."
64.0745,Job,MODIFIED,eval-sanitize-5-r3-062,
64.0756,Job,MODIFIED,eval-sanitize-5-r3-063,
64.0775,Job,MODIFIED,eval-sanitize-5-r3-064,
64.1487,Pod,MODIFIED,eval-sanitize-5-r3-049-t2ff5,phase=Succeeded node=kind-worker5
64.1683,Event,MODIFIED,eval-sanitize-5-r3-064-mcszm.18d3d472975c58e5,"reason=FailedScheduling count=None msg=0/6 nodes are available: 1 c_wall violated: 1 conflicting context pair(s) with node memory, 5 node(s) had untolerated taint(s). no new claims to deallocate, preemption: 0/6 nodes are available: 1 No preemption victims found for incoming pod, 5 Preemption is not helpful for scheduling."
64.1913,Pod,MODIFIED,eval-sanitize-5-r3-052-gndzv,phase=Succeeded node=kind-worker5
64.1982,Pod,MODIFIED,eval-sanitize-5-r3-046-bg7dm,phase=Succeeded node=kind-worker5
64.2043,Pod,MODIFIED,eval-sanitize-5-r3-051-dsht7,phase=Succeeded node=kind-worker5
64.553,Job,MODIFIED,eval-sanitize-5-r3-048,
64.5561,Job,MODIFIED,eval-sanitize-5-r3-050,
64.5646,Job,MODIFIED,eval-sanitize-5-r3-048,
64.5665,Job,MODIFIED,eval-sanitize-5-r3-050,
64.6355,Pod,MODIFIED,eval-sanitize-5-r3-048-tc9lm,phase=Succeeded node=kind-worker
64.6865,Pod,MODIFIED,eval-sanitize-5-r3-050-l6mlt,phase=Succeeded node=kind-worker
64.9696,Job,MODIFIED,eval-sanitize-5-r3-053,
64.9748,Job,MODIFIED,eval-sanitize-5-r3-051,
64.9757,Job,MODIFIED,eval-sanitize-5-r3-049,
64.9804,Job,MODIFIED,eval-sanitize-5-r3-053,
64.9831,Pod,MODIFIED,eval-sanitize-5-r3-051-dsht7,phase=Succeeded node=kind-worker5
64.9848,Job,MODIFIED,eval-sanitize-5-r3-052,
64.9864,Pod,MODIFIED,eval-sanitize-5-r3-049-t2ff5,phase=Succeeded node=kind-worker5
64.9878,Job,MODIFIED,eval-sanitize-5-r3-051,
64.9887,Job,MODIFIED,eval-sanitize-5-r3-049,
64.9954,Job,MODIFIED,eval-sanitize-5-r3-046,
64.997,Pod,MODIFIED,eval-sanitize-5-r3-052-gndzv,phase=Succeeded node=kind-worker5
64.9978,Job,MODIFIED,eval-sanitize-5-r3-052,
65.0051,Pod,MODIFIED,eval-sanitize-5-r3-046-bg7dm,phase=Succeeded node=kind-worker5
65.0061,Job,MODIFIED,eval-sanitize-5-r3-046,
65.0217,TaskRequest,ADDED,eval-sanitize-5-r3-065,phase=None job=None
65.0253,TaskRequest,MODIFIED,eval-sanitize-5-r3-065,phase=Pending job=None
65.041,Job,ADDED,eval-sanitize-5-r3-065,
65.0475,Pod,ADDED,eval-sanitize-5-r3-065-sqkkl,phase=Pending node=None
65.0504,Job,MODIFIED,eval-sanitize-5-r3-065,
65.0528,Event,ADDED,eval-sanitize-5-r3-065.18d3d472d1ca53af,reason=SuccessfulCreate count=1 msg=Created pod: eval-sanitize-5-r3-065-sqkkl
65.0562,Pod,MODIFIED,eval-sanitize-5-r3-065-sqkkl,phase=Pending node=None
65.0576,Event,ADDED,eval-sanitize-5-r3-065-sqkkl.18d3d472d21263c8,"reason=FailedScheduling count=None msg=0/6 nodes are available: 1 c_wall violated: 1 conflicting context pair(s) with node memory, 5 node(s) had untolerated taint(s). no new claims to deallocate, preemption: 0/6 nodes are available: 1 No preemption victims found for incoming pod, 5 Preemption is not helpful for scheduling."
65.0577,TaskRequest,MODIFIED,eval-sanitize-5-r3-065,phase=Scheduled job=None
65.0627,Event,ADDED,eval-sanitize-5-r3-065-sqkkl.18d3d472d28b85de,"reason=FailedScheduling count=None msg=0/6 nodes are available: 1 c_wall violated: 1 conflicting context pair(s) with node memory, 5 node(s) had untolerated taint(s). no new claims to deallocate, preemption: 0/6 nodes are available: 1 No preemption victims found for incoming pod, 5 Preemption is not helpful for scheduling."
65.0653,TaskRequest,MODIFIED,eval-sanitize-5-r3-065,phase=Scheduled job=None
65.1046,Pod,MODIFIED,eval-sanitize-5-r3-053-dbxqm,phase=Succeeded node=kind-worker5
65.1313,Event,MODIFIED,eval-sanitize-5-r3-065-sqkkl.18d3d472d28b85de,"reason=FailedScheduling count=None msg=0/6 nodes are available: 1 c_wall violated: 1 conflicting context pair(s) with node memory, 5 node(s) had untolerated taint(s). no new claims to deallocate, preemption: 0/6 nodes are available: 1 No preemption victims found for incoming pod, 5 Preemption is not helpful for scheduling."
65.574,Job,MODIFIED,eval-sanitize-5-r3-048,
65.5763,Job,MODIFIED,eval-sanitize-5-r3-050,
65.5842,Pod,MODIFIED,eval-sanitize-5-r3-048-tc9lm,phase=Succeeded node=kind-worker
65.5859,Pod,MODIFIED,eval-sanitize-5-r3-050-l6mlt,phase=Succeeded node=kind-worker
65.5867,Job,MODIFIED,eval-sanitize-5-r3-048,
65.5876,Job,MODIFIED,eval-sanitize-5-r3-050,
65.9081,Pod,MODIFIED,eval-sanitize-5-r3-055-n28zx,phase=Running node=kind-worker3
65.9158,Pod,MODIFIED,eval-sanitize-5-r3-047-nb5vw,phase=Running node=kind-worker3
65.9228,Pod,MODIFIED,eval-sanitize-5-r3-054-tfvvd,phase=Running node=kind-worker3
65.9845,Job,MODIFIED,eval-sanitize-5-r3-053,
65.9864,Job,MODIFIED,eval-sanitize-5-r3-049,
65.9876,Job,MODIFIED,eval-sanitize-5-r3-051,
65.9895,Job,MODIFIED,eval-sanitize-5-r3-052,
65.992,Job,MODIFIED,eval-sanitize-5-r3-049,
65.9936,Job,MODIFIED,eval-sanitize-5-r3-051,
65.9951,Pod,MODIFIED,eval-sanitize-5-r3-053-dbxqm,phase=Succeeded node=kind-worker5
65.9961,Job,MODIFIED,eval-sanitize-5-r3-052,
65.997,Job,MODIFIED,eval-sanitize-5-r3-053,
65.9974,Event,ADDED,eval-sanitize-5-r3-051.18d3d4730a1aee39,reason=Completed count=1 msg=Job completed
66.0002,Job,MODIFIED,eval-sanitize-5-r3-051,
66.0013,Job,MODIFIED,eval-sanitize-5-r3-046,
66.0062,Event,ADDED,eval-sanitize-5-r3-049.18d3d4730a1c3f2c,reason=Completed count=1 msg=Job completed
66.0063,TaskRequest,MODIFIED,eval-sanitize-5-r3-051,phase=Complete job=None
66.0073,Job,MODIFIED,eval-sanitize-5-r3-049,
66.0077,TaskRequest,ADDED,eval-sanitize-5-r3-066,phase=None job=None
66.0085,Job,MODIFIED,eval-sanitize-5-r3-046,
66.0092,Job,MODIFIED,eval-sanitize-5-r3-052,
66.0095,Event,ADDED,eval-sanitize-5-r3-052.18d3d4730a60a687,reason=Completed count=1 msg=Job completed
66.0137,Event,ADDED,eval-sanitize-5-r3-046.18d3d4730b0178f9,reason=Completed count=1 msg=Job completed
66.0584,Job,MODIFIED,eval-sanitize-5-r3-065,
66.0586,TaskRequest,MODIFIED,eval-sanitize-5-r3-049,phase=Complete job=None
66.0631,Job,MODIFIED,eval-sanitize-5-r3-051,
66.0642,TaskRequest,MODIFIED,eval-sanitize-5-r3-052,phase=Complete job=None
66.0651,Job,MODIFIED,eval-sanitize-5-r3-046,
66.0688,Job,MODIFIED,eval-sanitize-5-r3-049,
66.0698,TaskRequest,MODIFIED,eval-sanitize-5-r3-066,phase=Pending job=None
66.0748,Job,MODIFIED,eval-sanitize-5-r3-052,
66.0851,Job,ADDED,eval-sanitize-5-r3-066,
66.0909,Pod,ADDED,eval-sanitize-5-r3-066-tcxw9,phase=Pending node=None
66.0929,Job,MODIFIED,eval-sanitize-5-r3-066,
66.0956,Event,ADDED,eval-sanitize-5-r3-066.18d3d47310010266,reason=SuccessfulCreate count=1 msg=Created pod: eval-sanitize-5-r3-066-tcxw9
66.0996,Pod,MODIFIED,eval-sanitize-5-r3-066-tcxw9,phase=Pending node=None
66.1,Event,ADDED,eval-sanitize-5-r3-066-tcxw9.18d3d47310419fc8,"reason=FailedScheduling count=None msg=0/6 nodes are available: 1 c_wall violated: 2 conflicting context pair(s) with node memory, 5 node(s) had untolerated taint(s). no new claims to deallocate, preemption: 0/6 nodes are available: 1 No preemption victims found for incoming pod, 5 Preemption is not helpful for scheduling."
66.1088,Event,ADDED,eval-sanitize-5-r3-066-tcxw9.18d3d47310bcad31,"reason=FailedScheduling count=None msg=0/6 nodes are available: 1 c_wall violated: 2 conflicting context pair(s) with node memory, 5 node(s) had untolerated taint(s). no new claims to deallocate, preemption: 0/6 nodes are available: 1 No preemption victims found for incoming pod, 5 Preemption is not helpful for scheduling."
66.1593,TaskRequest,MODIFIED,eval-sanitize-5-r3-066,phase=Scheduled job=None
66.1627,TaskRequest,MODIFIED,eval-sanitize-5-r3-046,phase=Complete job=None
66.1675,TaskRequest,MODIFIED,eval-sanitize-5-r3-066,phase=Scheduled job=None
66.1703,Job,MODIFIED,eval-sanitize-5-r3-065,
66.1723,Job,MODIFIED,eval-sanitize-5-r3-046,
66.5858,Job,MODIFIED,eval-sanitize-5-r3-048,
66.5871,Job,MODIFIED,eval-sanitize-5-r3-050,
66.5899,Job,MODIFIED,eval-sanitize-5-r3-048,
66.5918,Job,MODIFIED,eval-sanitize-5-r3-050,
66.5928,Event,ADDED,eval-sanitize-5-r3-048.18d3d4732dbf4981,reason=Completed count=1 msg=Job completed
66.5977,Event,ADDED,eval-sanitize-5-r3-050.18d3d4732de127ab,reason=Completed count=1 msg=Job completed
66.6015,Job,MODIFIED,eval-sanitize-5-r3-048,
66.6034,Job,MODIFIED,eval-sanitize-5-r3-050,
66.6063,TaskRequest,MODIFIED,eval-sanitize-5-r3-048,phase=Complete job=None
66.611,TaskRequest,MODIFIED,eval-sanitize-5-r3-050,phase=Complete job=None
66.6158,Job,MODIFIED,eval-sanitize-5-r3-048,
66.6192,Job,MODIFIED,eval-sanitize-5-r3-050,
66.9237,Job,MODIFIED,eval-sanitize-5-r3-055,
66.9258,Job,MODIFIED,eval-sanitize-5-r3-047,
66.9289,Job,MODIFIED,eval-sanitize-5-r3-054,
66.9348,Job,MODIFIED,eval-sanitize-5-r3-055,
66.9383,Job,MODIFIED,eval-sanitize-5-r3-047,
66.942,Job,MODIFIED,eval-sanitize-5-r3-054,
66.9926,Job,MODIFIED,eval-sanitize-5-r3-053,
66.997,Job,MODIFIED,eval-sanitize-5-r3-053,
67.0007,Pod,MODIFIED,eval-sanitize-5-r3-055-n28zx,phase=Succeeded node=kind-worker3
67.0022,Event,ADDED,eval-sanitize-5-r3-053.18d3d4734604f9b9,reason=Completed count=1 msg=Job completed
67.0076,TaskRequest,ADDED,eval-sanitize-5-r3-067,phase=None job=None
67.0117,Job,MODIFIED,eval-sanitize-5-r3-053,
67.0118,TaskRequest,MODIFIED,eval-sanitize-5-r3-067,phase=Pending job=None
67.0258,Event,MODIFIED,eval-sanitize-5-r3-066-tcxw9.18d3d47310bcad31,"reason=FailedScheduling count=None msg=0/6 nodes are available: 1 c_wall violated: 2 conflicting context pair(s) with node memory, 5 node(s) had untolerated taint(s). no new claims to deallocate, preemption: 0/6 nodes are available: 1 No preemption victims found for incoming pod, 5 Preemption is not helpful for scheduling."
67.0303,Job,ADDED,eval-sanitize-5-r3-067,
67.0365,Pod,MODIFIED,eval-sanitize-5-r3-047-nb5vw,phase=Succeeded node=kind-worker3
67.0392,TaskRequest,MODIFIED,eval-sanitize-5-r3-067,phase=Scheduled job=None
67.0405,Pod,ADDED,eval-sanitize-5-r3-067-nj69x,phase=Pending node=None
67.0413,Job,MODIFIED,eval-sanitize-5-r3-067,
67.0456,Pod,MODIFIED,eval-sanitize-5-r3-054-tfvvd,phase=Succeeded node=kind-worker3
67.0461,Event,ADDED,eval-sanitize-5-r3-067.18d3d47348947573,reason=SuccessfulCreate count=1 msg=Created pod: eval-sanitize-5-r3-067-nj69x
67.0462,TaskRequest,MODIFIED,eval-sanitize-5-r3-053,phase=Complete job=None
67.0475,TaskRequest,MODIFIED,eval-sanitize-5-r3-067,phase=Scheduled job=None
67.0551,Job,MODIFIED,eval-sanitize-5-r3-053,
67.0603,Pod,MODIFIED,eval-sanitize-5-r3-067-nj69x,phase=Pending node=None
67.0607,Event,ADDED,eval-sanitize-5-r3-067-nj69x.18d3d4734987599c,"reason=FailedScheduling count=None msg=0/6 nodes are available: 1 c_wall violated: 1 conflicting context pair(s) with node memory, 5 node(s) had untolerated taint(s). no new claims to deallocate, preemption: 0/6 nodes are available: 1 No preemption victims found for incoming pod, 5 Preemption is not helpful for scheduling."
67.1042,Job,MODIFIED,eval-sanitize-5-r3-066,
67.113,Job,MODIFIED,eval-sanitize-5-r3-066,
67.1595,Event,ADDED,eval-sanitize-5-r3-067-nj69x.18d3d4734f76ac0c,"reason=FailedScheduling count=None msg=0/6 nodes are available: 1 c_wall violated: 1 conflicting context pair(s) with node memory, 5 node(s) had untolerated taint(s). no new claims to deallocate, preemption: 0/6 nodes are available: 1 No preemption victims found for incoming pod, 5 Preemption is not helpful for scheduling."
67.2753,Node,MODIFIED,kind-worker5,taints=1
67.2996,Event,MODIFIED,eval-sanitize-5-r3-067-nj69x.18d3d4734f76ac0c,"reason=FailedScheduling count=None msg=0/6 nodes are available: 1 c_wall violated: 1 conflicting context pair(s) with node memory, 5 node(s) had untolerated taint(s). no new claims to deallocate, preemption: 0/6 nodes are available: 1 No preemption victims found for incoming pod, 5 Preemption is not helpful for scheduling."
67.3692,Node,MODIFIED,kind-worker5,taints=0
67.3765,Pod,MODIFIED,eval-sanitize-5-r3-060-jqm27,phase=Pending node=kind-worker5
67.3796,Node,MODIFIED,kind-worker5,taints=0
67.38,Event,ADDED,eval-sanitize-5-r3-060-jqm27.18d3d4735c9adaad,reason=Scheduled count=None msg=Successfully assigned compute/eval-sanitize-5-r3-060-jqm27 to kind-worker5
67.3853,Pod,MODIFIED,eval-sanitize-5-r3-061-jsgbk,phase=Pending node=kind-worker5
67.3878,Pod,MODIFIED,eval-sanitize-5-r3-060-jqm27,phase=Pending node=kind-worker5
67.3918,Node,MODIFIED,kind-worker5,taints=0
67.3929,Event,ADDED,eval-sanitize-5-r3-061-jsgbk.18d3d4735d24dd83,reason=Scheduled count=None msg=Successfully assigned compute/eval-sanitize-5-r3-061-jsgbk to kind-worker5
67.3941,Pod,MODIFIED,eval-sanitize-5-r3-059-4hqs6,phase=Pending node=kind-worker5
67.3999,Pod,MODIFIED,eval-sanitize-5-r3-061-jsgbk,phase=Pending node=kind-worker5
67.4003,Event,ADDED,eval-sanitize-5-r3-059-4hqs6.18d3d4735da3ade3,reason=Scheduled count=None msg=Successfully assigned compute/eval-sanitize-5-r3-059-4hqs6 to kind-worker5
67.4037,Node,MODIFIED,kind-worker5,taints=0
67.4088,Pod,MODIFIED,eval-sanitize-5-r3-059-4hqs6,phase=Pending node=kind-worker5
67.4132,Node,MODIFIED,kind-worker5,taints=0
67.4679,Pod,MODIFIED,eval-sanitize-5-r3-064-mcszm,phase=Pending node=None
67.4774,Pod,MODIFIED,eval-sanitize-5-r3-066-tcxw9,phase=Pending node=None
67.4873,Pod,MODIFIED,eval-sanitize-5-r3-065-sqkkl,phase=Pending node=kind-worker5
67.4908,Event,ADDED,eval-sanitize-5-r3-065-sqkkl.18d3d473633c6dd7,reason=Scheduled count=None msg=Successfully assigned compute/eval-sanitize-5-r3-065-sqkkl to kind-worker5
67.4985,Node,MODIFIED,kind-worker5,taints=0
67.4998,Pod,MODIFIED,eval-sanitize-5-r3-065-sqkkl,phase=Pending node=kind-worker5
67.5079,Node,MODIFIED,kind-worker5,taints=0
67.5622,Pod,MODIFIED,eval-sanitize-5-r3-056-p8v5t,phase=Running node=kind-worker
67.5635,Pod,MODIFIED,eval-sanitize-5-r3-063-rcwj5,phase=Pending node=None
67.578,Node,MODIFIED,kind-worker2,taints=1
67.5789,Pod,MODIFIED,eval-sanitize-5-r3-067-nj69x,phase=Pending node=kind-worker5
67.5805,Event,ADDED,eval-sanitize-5-r3-064-mcszm.18d3d4736878b094,"reason=FailedScheduling count=None msg=0/6 nodes are available: 2 c_wall violated: 1 conflicting context pair(s) with node memory, 4 node(s) had untolerated taint(s). no new claims to deallocate, preemption: 0/6 nodes are available: 2 No preemption victims found for incoming pod, 4 Preemption is not helpful for scheduling."
67.5813,Event,ADDED,eval-sanitize-5-r3-067-nj69x.18d3d47368a5ebb7,reason=Scheduled count=None msg=Successfully assigned compute/eval-sanitize-5-r3-067-nj69x to kind-worker5
67.5901,Pod,MODIFIED,eval-sanitize-5-r3-067-nj69x,phase=Pending node=kind-worker5
67.5918,Node,MODIFIED,kind-worker2,taints=1
67.661,Event,ADDED,eval-sanitize-5-r3-066-tcxw9.18d3d4736d089da1,"reason=FailedScheduling count=None msg=0/6 nodes are available: 1 c_wall violated: 1 conflicting context pair(s) with node memory, 1 c_wall violated: 2 conflicting context pair(s) with node memory, 4 node(s) had untolerated taint(s). no new claims to deallocate, preemption: 0/6 nodes are available: 2 No preemption victims found for incoming pod, 4 Preemption is not helpful for scheduling."
67.6634,Event,ADDED,eval-sanitize-5-r3-063-rcwj5.18d3d4736d385c2e,"reason=FailedScheduling count=None msg=0/6 nodes are available: 1 c_wall violated: 1 conflicting context pair(s) with node memory, 5 node(s) had untolerated taint(s). no new claims to deallocate, preemption: 0/6 nodes are available: 1 No preemption victims found for incoming pod, 5 Preemption is not helpful for scheduling."
67.6644,Pod,MODIFIED,eval-sanitize-5-r3-063-rcwj5,phase=Pending node=None
67.6718,Pod,MODIFIED,eval-sanitize-5-r3-064-mcszm,phase=Pending node=None
67.6722,Event,MODIFIED,eval-sanitize-5-r3-064-mcszm.18d3d4736878b094,"reason=FailedScheduling count=None msg=0/6 nodes are available: 2 c_wall violated: 1 conflicting context pair(s) with node memory, 4 node(s) had untolerated taint(s). no new claims to deallocate, preemption: 0/6 nodes are available: 2 No preemption victims found for incoming pod, 4 Preemption is not helpful for scheduling."
67.6795,Pod,MODIFIED,eval-sanitize-5-r3-066-tcxw9,phase=Pending node=None
67.6798,Event,MODIFIED,eval-sanitize-5-r3-066-tcxw9.18d3d4736d089da1,"reason=FailedScheduling count=None msg=0/6 nodes are available: 1 c_wall violated: 1 conflicting context pair(s) with node memory, 1 c_wall violated: 2 conflicting context pair(s) with node memory, 4 node(s) had untolerated taint(s). no new claims to deallocate, preemption: 0/6 nodes are available: 2 No preemption victims found for incoming pod, 4 Preemption is not helpful for scheduling."
67.6852,Event,ADDED,eval-sanitize-5-r3-063-rcwj5.18d3d4736ede2515,"reason=FailedScheduling count=None msg=0/6 nodes are available: 1 c_wall violated: 1 conflicting context pair(s) with node memory, 5 node(s) had untolerated taint(s). no new claims to deallocate, preemption: 0/6 nodes are available: 1 No preemption victims found for incoming pod, 5 Preemption is not helpful for scheduling."
67.6894,Event,ADDED,eval-sanitize-5-r3-064-mcszm.18d3d4736f04fb70,"reason=FailedScheduling count=None msg=0/6 nodes are available: 1 c_wall violated: 1 conflicting context pair(s) with node memory, 5 node(s) had untolerated taint(s). no new claims to deallocate, preemption: 0/6 nodes are available: 1 No preemption victims found for incoming pod, 5 Preemption is not helpful for scheduling."
67.6906,Event,ADDED,eval-sanitize-5-r3-066-tcxw9.18d3d4736f2eb345,"reason=FailedScheduling count=None msg=0/6 nodes are available: 1 c_wall violated: 1 conflicting context pair(s) with node memory, 5 node(s) had untolerated taint(s). no new claims to deallocate, preemption: 0/6 nodes are available: 1 No preemption victims found for incoming pod, 5 Preemption is not helpful for scheduling."
67.8144,Event,ADDED,eval-sanitize-5-r3-060-jqm27.18d3d4737675a24a,"reason=Pulled count=1 msg=Container image ""busybox:musl"" already present on machine"
67.8249,Event,ADDED,eval-sanitize-5-r3-061-jsgbk.18d3d47376ffa1f4,"reason=Pulled count=1 msg=Container image ""busybox:musl"" already present on machine"
67.8302,Event,ADDED,eval-sanitize-5-r3-059-4hqs6.18d3d4737765d6a1,"reason=Pulled count=1 msg=Container image ""busybox:musl"" already present on machine"
67.8546,Event,ADDED,eval-sanitize-5-r3-060-jqm27.18d3d47378e51fd7,reason=Created count=1 msg=Created container: task
67.8651,Event,ADDED,eval-sanitize-5-r3-061-jsgbk.18d3d4737988861e,reason=Created count=1 msg=Created container: task
67.8719,Event,ADDED,eval-sanitize-5-r3-059-4hqs6.18d3d47379febef6,reason=Created count=1 msg=Created container: task
67.9026,Pod,MODIFIED,eval-sanitize-5-r3-057-bccxp,phase=Running node=kind-worker4
67.9119,Event,MODIFIED,eval-sanitize-5-r3-063-rcwj5.18d3d4736ede2515,"reason=FailedScheduling count=None msg=0/6 nodes are available: 1 c_wall violated: 1 conflicting context pair(s) with node memory, 5 node(s) had untolerated taint(s). no new claims to deallocate, preemption: 0/6 nodes are available: 1 No preemption victims found for incoming pod, 5 Preemption is not helpful for scheduling."
67.9156,Event,MODIFIED,eval-sanitize-5-r3-064-mcszm.18d3d4736f04fb70,"reason=FailedScheduling count=None msg=0/6 nodes are available: 1 c_wall violated: 1 conflicting context pair(s) with node memory, 5 node(s) had untolerated taint(s). no new claims to deallocate, preemption: 0/6 nodes are available: 1 No preemption victims found for incoming pod, 5 Preemption is not helpful for scheduling."
67.9196,Event,MODIFIED,eval-sanitize-5-r3-066-tcxw9.18d3d4736f2eb345,"reason=FailedScheduling count=None msg=0/6 nodes are available: 1 c_wall violated: 1 conflicting context pair(s) with node memory, 5 node(s) had untolerated taint(s). no new claims to deallocate, preemption: 0/6 nodes are available: 1 No preemption victims found for incoming pod, 5 Preemption is not helpful for scheduling."
67.9291,Job,MODIFIED,eval-sanitize-5-r3-055,
67.9312,Job,MODIFIED,eval-sanitize-5-r3-047,
67.9343,Job,MODIFIED,eval-sanitize-5-r3-054,
67.9394,Pod,MODIFIED,eval-sanitize-5-r3-055-n28zx,phase=Succeeded node=kind-worker3
67.941,Job,MODIFIED,eval-sanitize-5-r3-055,
67.9442,Pod,MODIFIED,eval-sanitize-5-r3-047-nb5vw,phase=Succeeded node=kind-worker3
67.9457,Pod,MODIFIED,eval-sanitize-5-r3-054-tfvvd,phase=Succeeded node=kind-worker3
67.9478,Job,MODIFIED,eval-sanitize-5-r3-047,
67.9487,Job,MODIFIED,eval-sanitize-5-r3-054,
67.969,Event,ADDED,eval-sanitize-5-r3-060-jqm27.18d3d4737fbbe497,reason=Started count=1 msg=Started container task
67.985,Event,ADDED,eval-sanitize-5-r3-067-nj69x.18d3d4738088be4b,"reason=Pulled count=1 msg=Container image ""busybox:musl"" already present on machine"
68.0004,Event,ADDED,eval-sanitize-5-r3-067-nj69x.18d3d47381a44970,reason=Created count=1 msg=Created container: task
68.0085,TaskRequest,ADDED,eval-sanitize-5-r3-068,phase=None job=None
68.0126,TaskRequest,MODIFIED,eval-sanitize-5-r3-068,phase=Pending job=None
68.0195,Event,ADDED,eval-sanitize-5-r3-059-4hqs6.18d3d47382af8644,reason=Started count=1 msg=Started container task
68.0234,Event,ADDED,eval-sanitize-5-r3-061-jsgbk.18d3d47382b019c8,reason=Started count=1 msg=Started container task
68.0277,Job,ADDED,eval-sanitize-5-r3-068,
68.0337,Pod,ADDED,eval-sanitize-5-r3-068-x42j8,phase=Pending node=None
68.0344,TaskRequest,MODIFIED,eval-sanitize-5-r3-068,phase=Scheduled job=None
68.0375,Job,MODIFIED,eval-sanitize-5-r3-068,
68.0392,Event,ADDED,eval-sanitize-5-r3-068.18d3d47383c57fb1,reason=SuccessfulCreate count=1 msg=Created pod: eval-sanitize-5-r3-068-x42j8
68.0433,Pod,MODIFIED,eval-sanitize-5-r3-068-x42j8,phase=Pending node=kind-worker5
68.0447,TaskRequest,MODIFIED,eval-sanitize-5-r3-068,phase=Scheduled job=None
68.0456,Job,MODIFIED,eval-sanitize-5-r3-067,
68.0461,Event,ADDED,eval-sanitize-5-r3-065-sqkkl.18d3d4738453377f,"reason=Pulled count=1 msg=Container image ""busybox:musl"" already present on machine"
68.0467,Event,ADDED,eval-sanitize-5-r3-068-x42j8.18d3d473845de7b7,reason=Scheduled count=None msg=Successfully assigned compute/eval-sanitize-5-r3-068-x42j8 to kind-worker5
68.0576,Pod,MODIFIED,eval-sanitize-5-r3-068-x42j8,phase=Pending node=kind-worker5
68.0616,Job,MODIFIED,eval-sanitize-5-r3-067,
68.063,Event,ADDED,eval-sanitize-5-r3-067-nj69x.18d3d473855be62a,reason=Started count=1 msg=Started container task
68.0688,Event,ADDED,eval-sanitize-5-r3-065-sqkkl.18d3d47385b47a0c,reason=Created count=1 msg=Created container: task
68.1523,Event,ADDED,eval-sanitize-5-r3-065-sqkkl.18d3d4738aa729fd,reason=Started count=1 msg=Started container task
68.4779,Event,ADDED,eval-sanitize-5-r3-068-x42j8.18d3d4739e0f748a,"reason=Pulled count=1 msg=Container image ""busybox:musl"" already present on machine"
68.496,Event,ADDED,eval-sanitize-5-r3-068-x42j8.18d3d4739f1bf89b,reason=Created count=1 msg=Created container: task
68.528,Event,ADDED,eval-sanitize-5-r3-068-x42j8.18d3d473a10d85fe,reason=Started count=1 msg=Started container task
68.5673,Job,MODIFIED,eval-sanitize-5-r3-056,
68.5765,Job,MODIFIED,eval-sanitize-5-r3-056,
68.6285,Pod,MODIFIED,eval-sanitize-5-r3-056-p8v5t,phase=Succeeded node=kind-worker
68.9233,Job,MODIFIED,eval-sanitize-5-r3-057,
68.9331,Job,MODIFIED,eval-sanitize-5-r3-057,
68.9349,Job,MODIFIED,eval-sanitize-5-r3-055,
68.937,Job,MODIFIED,eval-sanitize-5-r3-047,
68.9404,Job,MODIFIED,eval-sanitize-5-r3-054,
68.9426,Job,MODIFIED,eval-sanitize-5-r3-055,
68.9436,Job,MODIFIED,eval-sanitize-5-r3-047,
68.9463,Job,MODIFIED,eval-sanitize-5-r3-054,
68.9472,Event,ADDED,eval-sanitize-5-r3-047.18d3d473b9fb82d8,reason=Completed count=1 msg=Job completed
68.9503,Job,MODIFIED,eval-sanitize-5-r3-055,
68.9523,Job,MODIFIED,eval-sanitize-5-r3-047,
68.9528,Event,ADDED,eval-sanitize-5-r3-055.18d3d473b9ff95a8,reason=Completed count=1 msg=Job completed
68.9552,TaskRequest,MODIFIED,eval-sanitize-5-r3-055,phase=Complete job=None
68.9572,Event,ADDED,eval-sanitize-5-r3-054.18d3d473ba3ac0f5,reason=Completed count=1 msg=Job completed
68.9582,Job,MODIFIED,eval-sanitize-5-r3-054,
68.961,TaskRequest,MODIFIED,eval-sanitize-5-r3-047,phase=Complete job=None
68.9655,Job,MODIFIED,eval-sanitize-5-r3-055,
68.9665,TaskRequest,MODIFIED,eval-sanitize-5-r3-054,phase=Complete job=None
68.9705,Job,MODIFIED,eval-sanitize-5-r3-047,
68.9752,Pod,MODIFIED,eval-sanitize-5-r3-059-4hqs6,phase=Running node=kind-worker5
68.9817,Pod,MODIFIED,eval-sanitize-5-r3-061-jsgbk,phase=Running node=kind-worker5
68.9889,Pod,MODIFIED,eval-sanitize-5-r3-067-nj69x,phase=Running node=kind-worker5
68.9906,Pod,MODIFIED,eval-sanitize-5-r3-057-bccxp,phase=Succeeded node=kind-worker4
68.9954,Pod,MODIFIED,eval-sanitize-5-r3-068-x42j8,phase=Running node=kind-worker5
69.0017,Pod,MODIFIED,eval-sanitize-5-r3-060-jqm27,phase=Running node=kind-worker5
69.0078,Pod,MODIFIED,eval-sanitize-5-r3-065-sqkkl,phase=Running node=kind-worker5
69.0244,Job,MODIFIED,eval-sanitize-5-r3-054,
69.0372,Job,MODIFIED,eval-sanitize-5-r3-068,
69.0445,Job,MODIFIED,eval-sanitize-5-r3-068,
69.0496,Job,MODIFIED,eval-sanitize-5-r3-067,
69.0557,TaskRequest,ADDED,eval-sanitize-5-r3-069,phase=None job=None
69.0585,Job,MODIFIED,eval-sanitize-5-r3-067,
69.0592,TaskRequest,MODIFIED,eval-sanitize-5-r3-069,phase=Pending job=None
69.0741,Job,ADDED,eval-sanitize-5-r3-069,
69.08,Pod,ADDED,eval-sanitize-5-r3-069-h9nl9,phase=Pending node=None
69.0802,TaskRequest,MODIFIED,eval-sanitize-5-r3-069,phase=Scheduled job=None
69.0827,Job,MODIFIED,eval-sanitize-5-r3-069,
69.0855,Event,ADDED,eval-sanitize-5-r3-069.18d3d473c22e88f4,reason=SuccessfulCreate count=1 msg=Created pod: eval-sanitize-5-r3-069-h9nl9
69.0876,Pod,MODIFIED,eval-sanitize-5-r3-069-h9nl9,phase=Pending node=kind-worker5
69.0942,Event,ADDED,eval-sanitize-5-r3-069-h9nl9.18d3d473c29c8522,reason=Scheduled count=None msg=Successfully assigned compute/eval-sanitize-5-r3-069-h9nl9 to kind-worker5
69.0995,Node,MODIFIED,kind-worker5,taints=0
69.1011,Pod,MODIFIED,eval-sanitize-5-r3-069-h9nl9,phase=Pending node=kind-worker5
69.11,Node,MODIFIED,kind-worker5,taints=0
69.1733,TaskRequest,MODIFIED,eval-sanitize-5-r3-069,phase=Scheduled job=None
69.5255,Event,ADDED,eval-sanitize-5-r3-069-h9nl9.18d3d473dc83e0d3,"reason=Pulled count=1 msg=Container image ""busybox:musl"" already present on machine"
69.5464,Event,ADDED,eval-sanitize-5-r3-069-h9nl9.18d3d473ddc46b52,reason=Created count=1 msg=Created container: task
69.5748,Job,MODIFIED,eval-sanitize-5-r3-056,
69.5788,Event,ADDED,eval-sanitize-5-r3-069-h9nl9.18d3d473dfb57d66,reason=Started count=1 msg=Started container task
69.5826,Pod,MODIFIED,eval-sanitize-5-r3-056-p8v5t,phase=Succeeded node=kind-worker
69.5839,Job,MODIFIED,eval-sanitize-5-r3-056,
69.9308,Job,MODIFIED,eval-sanitize-5-r3-057,
69.9393,Pod,MODIFIED,eval-sanitize-5-r3-057-bccxp,phase=Succeeded node=kind-worker4
69.9407,Job,MODIFIED,eval-sanitize-5-r3-057,
69.9801,Job,MODIFIED,eval-sanitize-5-r3-059,
69.9864,Pod,MODIFIED,eval-sanitize-5-r3-069-h9nl9,phase=Running node=kind-worker5
69.9876,Job,MODIFIED,eval-sanitize-5-r3-061,
69.9899,Job,MODIFIED,eval-sanitize-5-r3-059,
69.997,Job,MODIFIED,eval-sanitize-5-r3-061,
70.0057,Job,MODIFIED,eval-sanitize-5-r3-060,
70.0059,TaskRequest,ADDED,eval-sanitize-5-r3-070,phase=None job=None
70.0116,Job,MODIFIED,eval-sanitize-5-r3-065,
70.013,TaskRequest,MODIFIED,eval-sanitize-5-r3-070,phase=Pending job=None
70.0156,Job,MODIFIED,eval-sanitize-5-r3-060,
70.0278,Job,ADDED,eval-sanitize-5-r3-070,
70.0316,TaskRequest,MODIFIED,eval-sanitize-5-r3-070,phase=Scheduled job=None
70.0347,Pod,ADDED,eval-sanitize-5-r3-070-h5cjp,phase=Pending node=None
70.0363,Job,MODIFIED,eval-sanitize-5-r3-070,
70.0401,Event,ADDED,eval-sanitize-5-r3-070.18d3d473fb15cbd3,reason=SuccessfulCreate count=1 msg=Created pod: eval-sanitize-5-r3-070-h5cjp
70.0402,TaskRequest,MODIFIED,eval-sanitize-5-r3-070,phase=Scheduled job=None
70.0426,Job,MODIFIED,eval-sanitize-5-r3-065,
70.0453,Pod,MODIFIED,eval-sanitize-5-r3-070-h5cjp,phase=Pending node=kind-worker5
70.0507,Event,ADDED,eval-sanitize-5-r3-070-h5cjp.18d3d473fbb0f922,reason=Scheduled count=None msg=Successfully assigned compute/eval-sanitize-5-r3-070-h5cjp to kind-worker5
70.0584,Pod,MODIFIED,eval-sanitize-5-r3-070-h5cjp,phase=Pending node=kind-worker5
70.0867,Job,MODIFIED,eval-sanitize-5-r3-069,
70.095,Job,MODIFIED,eval-sanitize-5-r3-069,
70.2738,Node,MODIFIED,kind-worker3,taints=1
70.2946,Node,MODIFIED,kind-worker3,taints=0
70.3041,Pod,MODIFIED,eval-sanitize-5-r3-064-mcszm,phase=Pending node=kind-worker3
70.3068,Node,MODIFIED,kind-worker3,taints=0
70.3102,Pod,MODIFIED,eval-sanitize-5-r3-066-tcxw9,phase=Pending node=kind-worker3
70.3108,Event,ADDED,eval-sanitize-5-r3-064-mcszm.18d3d4740b1a817e,reason=Scheduled count=None msg=Successfully assigned compute/eval-sanitize-5-r3-064-mcszm to kind-worker3
70.3175,Pod,MODIFIED,eval-sanitize-5-r3-064-mcszm,phase=Pending node=kind-worker3
70.318,Event,ADDED,eval-sanitize-5-r3-066-tcxw9.18d3d4740b778d20,reason=Scheduled count=None msg=Successfully assigned compute/eval-sanitize-5-r3-066-tcxw9 to kind-worker3
70.3215,Node,MODIFIED,kind-worker3,taints=0
70.3236,Pod,MODIFIED,eval-sanitize-5-r3-066-tcxw9,phase=Pending node=kind-worker3
70.3312,Node,MODIFIED,kind-worker3,taints=0
70.3635,Node,MODIFIED,kind-worker3,taints=0
70.3647,Pod,MODIFIED,eval-sanitize-5-r3-063-rcwj5,phase=Pending node=kind-worker3
70.3672,Event,ADDED,eval-sanitize-5-r3-063-rcwj5.18d3d4740eb072a4,reason=Scheduled count=None msg=Successfully assigned compute/eval-sanitize-5-r3-063-rcwj5 to kind-worker3
70.3741,Pod,MODIFIED,eval-sanitize-5-r3-063-rcwj5,phase=Pending node=kind-worker3
70.3765,Node,MODIFIED,kind-worker3,taints=0
70.3843,Node,MODIFIED,kind-worker3,taints=0
70.3949,Node,MODIFIED,kind-worker3,taints=0
70.4791,Event,ADDED,eval-sanitize-5-r3-070-h5cjp.18d3d474154100a6,"reason=Pulled count=1 msg=Container image ""busybox:musl"" already present on machine"
70.4957,Event,ADDED,eval-sanitize-5-r3-070-h5cjp.18d3d47416632457,reason=Created count=1 msg=Created container: task
70.5439,Event,ADDED,eval-sanitize-5-r3-070-h5cjp.18d3d4741937d181,reason=Started count=1 msg=Started container task
70.5795,Job,MODIFIED,eval-sanitize-5-r3-056,
70.5833,Job,MODIFIED,eval-sanitize-5-r3-056,
70.5888,Event,ADDED,eval-sanitize-5-r3-056.18d3d4741bcb1998,reason=Completed count=1 msg=Job completed
70.5936,Job,MODIFIED,eval-sanitize-5-r3-056,
70.5992,TaskRequest,MODIFIED,eval-sanitize-5-r3-056,phase=Complete job=None
70.6081,Job,MODIFIED,eval-sanitize-5-r3-056,
70.7378,Event,ADDED,eval-sanitize-5-r3-064-mcszm.18d3d47424b877ad,"reason=Pulled count=1 msg=Container image ""busybox:musl"" already present on machine"
70.7432,Event,ADDED,eval-sanitize-5-r3-066-tcxw9.18d3d47424d810b5,"reason=Pulled count=1 msg=Container image ""busybox:musl"" already present on machine"
70.7639,Event,ADDED,eval-sanitize-5-r3-066-tcxw9.18d3d4742648e360,reason=Created count=1 msg=Created container: task
70.769,Event,ADDED,eval-sanitize-5-r3-064-mcszm.18d3d47426a04c87,reason=Created count=1 msg=Created container: task
70.8086,Event,ADDED,eval-sanitize-5-r3-063-rcwj5.18d3d47428f28104,"reason=Pulled count=1 msg=Container image ""busybox:musl"" already present on machine"
70.8171,Event,ADDED,eval-sanitize-5-r3-066-tcxw9.18d3d47429838c7c,reason=Started count=1 msg=Started container task
70.8223,Event,ADDED,eval-sanitize-5-r3-064-mcszm.18d3d47429846181,reason=Started count=1 msg=Started container task
70.8276,Event,ADDED,eval-sanitize-5-r3-063-rcwj5.18d3d4742a2da5d4,reason=Created count=1 msg=Created container: task
70.9083,Event,ADDED,eval-sanitize-5-r3-063-rcwj5.18d3d4742ee92f75,reason=Started count=1 msg=Started container task
70.9144,Pod,MODIFIED,eval-sanitize-5-r3-063-rcwj5,phase=Running node=kind-worker3
70.9202,Pod,MODIFIED,eval-sanitize-5-r3-064-mcszm,phase=Running node=kind-worker3
70.9263,Pod,MODIFIED,eval-sanitize-5-r3-066-tcxw9,phase=Running node=kind-worker3
70.9346,Job,MODIFIED,eval-sanitize-5-r3-057,
70.9385,Job,MODIFIED,eval-sanitize-5-r3-057,
70.9414,Event,ADDED,eval-sanitize-5-r3-057.18d3d47430fb50aa,reason=Completed count=1 msg=Job completed
70.9499,Job,MODIFIED,eval-sanitize-5-r3-057,
70.954,TaskRequest,MODIFIED,eval-sanitize-5-r3-057,phase=Complete job=None
70.9626,Job,MODIFIED,eval-sanitize-5-r3-057,
70.9887,Pod,MODIFIED,eval-sanitize-5-r3-070-h5cjp,phase=Running node=kind-worker5
71.0068,TaskRequest,ADDED,eval-sanitize-5-r3-071,phase=None job=None
71.0113,TaskRequest,MODIFIED,eval-sanitize-5-r3-071,phase=Pending job=None
71.0248,Job,ADDED,eval-sanitize-5-r3-071,
71.0312,Pod,ADDED,eval-sanitize-5-r3-071-xbnq2,phase=Pending node=None
71.0314,TaskRequest,MODIFIED,eval-sanitize-5-r3-071,phase=Scheduled job=None
71.0342,Job,MODIFIED,eval-sanitize-5-r3-071,
71.0354,Event,ADDED,eval-sanitize-5-r3-071.18d3d474367811f9,reason=SuccessfulCreate count=1 msg=Created pod: eval-sanitize-5-r3-071-xbnq2
71.0373,TaskRequest,MODIFIED,eval-sanitize-5-r3-071,phase=Scheduled job=None
71.0399,Job,MODIFIED,eval-sanitize-5-r3-070,
71.0427,Pod,MODIFIED,eval-sanitize-5-r3-071-xbnq2,phase=Pending node=kind-worker3
71.0461,Event,ADDED,eval-sanitize-5-r3-071-xbnq2.18d3d474372d948e,reason=Scheduled count=None msg=Successfully assigned compute/eval-sanitize-5-r3-071-xbnq2 to kind-worker3
71.0486,Job,MODIFIED,eval-sanitize-5-r3-070,
71.0538,Pod,MODIFIED,eval-sanitize-5-r3-071-xbnq2,phase=Pending node=kind-worker3
71.315,Job,MODIFIED,eval-sanitize-5-r3-064,
71.3165,Job,MODIFIED,eval-sanitize-5-r3-066,
71.3236,Job,MODIFIED,eval-sanitize-5-r3-064,
71.3252,Job,MODIFIED,eval-sanitize-5-r3-066,
71.3686,Job,MODIFIED,eval-sanitize-5-r3-063,
71.3785,Job,MODIFIED,eval-sanitize-5-r3-063,
71.4708,Event,ADDED,eval-sanitize-5-r3-071-xbnq2.18d3d4745073622b,"reason=Pulled count=1 msg=Container image ""busybox:musl"" already present on machine"
71.4905,Event,ADDED,eval-sanitize-5-r3-071-xbnq2.18d3d474518fc430,reason=Created count=1 msg=Created container: task
71.5455,Event,ADDED,eval-sanitize-5-r3-071-xbnq2.18d3d47454ee7951,reason=Started count=1 msg=Started container task
71.7663,Node,MODIFIED,kind-worker4,taints=1
71.7785,Node,MODIFIED,kind-worker4,taints=0
71.7867,Node,MODIFIED,kind-worker4,taints=0
71.7965,Node,MODIFIED,kind-worker4,taints=0
71.9273,Pod,MODIFIED,eval-sanitize-5-r3-071-xbnq2,phase=Running node=kind-worker3
72.0131,TaskRequest,ADDED,eval-sanitize-5-r3-072,phase=None job=None
72.018,TaskRequest,MODIFIED,eval-sanitize-5-r3-072,phase=Pending job=None
72.0327,Job,ADDED,eval-sanitize-5-r3-072,
72.0369,Job,MODIFIED,eval-sanitize-5-r3-071,
72.039,Pod,ADDED,eval-sanitize-5-r3-072-2sstz,phase=Pending node=None
72.0402,TaskRequest,MODIFIED,eval-sanitize-5-r3-072,phase=Scheduled job=None
72.0409,Job,MODIFIED,eval-sanitize-5-r3-072,
72.0434,Event,ADDED,eval-sanitize-5-r3-072.18d3d4747292f649,reason=SuccessfulCreate count=1 msg=Created pod: eval-sanitize-5-r3-072-2sstz
72.0499,TaskRequest,MODIFIED,eval-sanitize-5-r3-072,phase=Scheduled job=None
72.0531,Job,MODIFIED,eval-sanitize-5-r3-071,
72.0594,Pod,MODIFIED,eval-sanitize-5-r3-072-2sstz,phase=Pending node=kind-worker4
72.0627,Event,ADDED,eval-sanitize-5-r3-072-2sstz.18d3d47473c4df96,reason=Scheduled count=None msg=Successfully assigned compute/eval-sanitize-5-r3-072-2sstz to kind-worker4
72.0683,Pod,MODIFIED,eval-sanitize-5-r3-072-2sstz,phase=Pending node=kind-worker4
72.0705,Node,MODIFIED,kind-worker4,taints=0
72.0799,Node,MODIFIED,kind-worker4,taints=0
72.3871,Node,MODIFIED,kind-worker5,taints=1
72.4007,Node,MODIFIED,kind-worker5,taints=1
72.4888,Event,ADDED,eval-sanitize-5-r3-072-2sstz.18d3d4748d1f20ef,"reason=Pulled count=1 msg=Container image ""busybox:musl"" already present on machine"
72.5063,Event,ADDED,eval-sanitize-5-r3-072-2sstz.18d3d4748e32aaad,reason=Created count=1 msg=Created container: task
72.5413,Event,ADDED,eval-sanitize-5-r3-072-2sstz.18d3d474902515d1,reason=Started count=1 msg=Started container task
72.9187,Pod,MODIFIED,eval-sanitize-5-r3-072-2sstz,phase=Running node=kind-worker4
73.008,TaskRequest,ADDED,eval-sanitize-5-r3-073,phase=None job=None
73.0129,TaskRequest,MODIFIED,eval-sanitize-5-r3-073,phase=Pending job=None
73.0143,Pod,MODIFIED,eval-sanitize-5-r3-058-nvqm9,phase=Running node=kind-worker2
73.0276,Job,ADDED,eval-sanitize-5-r3-073,
73.0341,Pod,ADDED,eval-sanitize-5-r3-073-fbnx9,phase=Pending node=None
73.0353,TaskRequest,MODIFIED,eval-sanitize-5-r3-073,phase=Scheduled job=None
73.0362,Job,MODIFIED,eval-sanitize-5-r3-073,
73.0383,Event,ADDED,eval-sanitize-5-r3-073.18d3d474ade2c286,reason=SuccessfulCreate count=1 msg=Created pod: eval-sanitize-5-r3-073-fbnx9
73.0441,Job,MODIFIED,eval-sanitize-5-r3-072,
73.0443,TaskRequest,MODIFIED,eval-sanitize-5-r3-073,phase=Scheduled job=None
73.0472,Pod,MODIFIED,eval-sanitize-5-r3-073-fbnx9,phase=Pending node=kind-worker4
73.052,Event,ADDED,eval-sanitize-5-r3-073-fbnx9.18d3d474aea59f0b,reason=Scheduled count=None msg=Successfully assigned compute/eval-sanitize-5-r3-073-fbnx9 to kind-worker4
73.0543,Job,MODIFIED,eval-sanitize-5-r3-072,
73.0574,Node,MODIFIED,kind-worker4,taints=0
73.0599,Pod,MODIFIED,eval-sanitize-5-r3-073-fbnx9,phase=Pending node=kind-worker4
73.0678,Node,MODIFIED,kind-worker4,taints=0
73.2688,Node,MODIFIED,kind-worker,taints=1
73.2826,Node,MODIFIED,kind-worker,taints=0
73.2904,Node,MODIFIED,kind-worker,taints=0
73.2998,Node,MODIFIED,kind-worker,taints=0
73.4568,Event,ADDED,eval-sanitize-5-r3-073-fbnx9.18d3d474c6d4fed3,"reason=Pulled count=1 msg=Container image ""busybox:musl"" already present on machine"
73.4753,Event,ADDED,eval-sanitize-5-r3-073-fbnx9.18d3d474c7f0b9b1,reason=Created count=1 msg=Created container: task
73.54,Event,ADDED,eval-sanitize-5-r3-073-fbnx9.18d3d474cbd3f2d1,reason=Started count=1 msg=Started container task
73.9208,Pod,MODIFIED,eval-sanitize-5-r3-073-fbnx9,phase=Running node=kind-worker4
74.0211,TaskRequest,ADDED,eval-sanitize-5-r3-074,phase=None job=None
74.026,Job,MODIFIED,eval-sanitize-5-r3-058,
74.0273,TaskRequest,MODIFIED,eval-sanitize-5-r3-074,phase=Pending job=None
74.0287,Pod,MODIFIED,eval-sanitize-5-r3-062-lrf47,phase=Running node=kind-worker2
74.0393,Job,MODIFIED,eval-sanitize-5-r3-073,
74.0421,Job,ADDED,eval-sanitize-5-r3-074,
74.0465,TaskRequest,MODIFIED,eval-sanitize-5-r3-074,phase=Scheduled job=None
74.0538,Pod,ADDED,eval-sanitize-5-r3-074-mp9lq,phase=Pending node=None
74.0568,Job,MODIFIED,eval-sanitize-5-r3-074,
74.0585,Event,ADDED,eval-sanitize-5-r3-074.18d3d474ea99e92a,reason=SuccessfulCreate count=1 msg=Created pod: eval-sanitize-5-r3-074-mp9lq
74.0586,TaskRequest,MODIFIED,eval-sanitize-5-r3-074,phase=Scheduled job=None
74.0594,Job,MODIFIED,eval-sanitize-5-r3-058,
74.0601,Job,MODIFIED,eval-sanitize-5-r3-073,
74.0645,Pod,MODIFIED,eval-sanitize-5-r3-074-mp9lq,phase=Pending node=kind-worker
74.0714,Event,ADDED,eval-sanitize-5-r3-074-mp9lq.18d3d474eb4b8b6f,reason=Scheduled count=None msg=Successfully assigned compute/eval-sanitize-5-r3-074-mp9lq to kind-worker
74.0749,Node,MODIFIED,kind-worker,taints=0
74.0772,Pod,MODIFIED,eval-sanitize-5-r3-074-mp9lq,phase=Pending node=kind-worker
74.086,Node,MODIFIED,kind-worker,taints=0
74.1385,Pod,MODIFIED,eval-sanitize-5-r3-058-nvqm9,phase=Succeeded node=kind-worker2
74.5181,Event,ADDED,eval-sanitize-5-r3-074-mp9lq.18d3d47505fe8374,"reason=Pulled count=1 msg=Container image ""busybox:musl"" already present on machine"
74.5363,Event,ADDED,eval-sanitize-5-r3-074-mp9lq.18d3d475071c83a9,reason=Created count=1 msg=Created container: task
74.5971,Event,ADDED,eval-sanitize-5-r3-074-mp9lq.18d3d4750abc2ba1,reason=Started count=1 msg=Started container task
75.011,TaskRequest,ADDED,eval-sanitize-5-r3-075,phase=None job=None
75.0171,TaskRequest,MODIFIED,eval-sanitize-5-r3-075,phase=Pending job=None
75.0322,Job,MODIFIED,eval-sanitize-5-r3-058,
75.0375,Job,MODIFIED,eval-sanitize-5-r3-062,
75.0385,Job,ADDED,eval-sanitize-5-r3-075,
75.0429,Pod,MODIFIED,eval-sanitize-5-r3-058-nvqm9,phase=Succeeded node=kind-worker2
75.0439,Pod,ADDED,eval-sanitize-5-r3-075-8qnkc,phase=Pending node=None
75.0454,TaskRequest,MODIFIED,eval-sanitize-5-r3-075,phase=Scheduled job=None
75.0488,Job,MODIFIED,eval-sanitize-5-r3-058,
75.0495,Job,MODIFIED,eval-sanitize-5-r3-075,
75.0499,Event,ADDED,eval-sanitize-5-r3-075.18d3d47525994a14,reason=SuccessfulCreate count=1 msg=Created pod: eval-sanitize-5-r3-075-8qnkc
75.0551,TaskRequest,MODIFIED,eval-sanitize-5-r3-075,phase=Scheduled job=None
75.0575,Event,ADDED,eval-sanitize-5-r3-058.18d3d47525e6c687,reason=Completed count=1 msg=Job completed
75.0586,Job,MODIFIED,eval-sanitize-5-r3-058,
75.0596,Job,MODIFIED,eval-sanitize-5-r3-075,
75.0603,Job,MODIFIED,eval-sanitize-5-r3-062,
75.0618,Job,MODIFIED,eval-sanitize-5-r3-074,
75.0628,Pod,MODIFIED,eval-sanitize-5-r3-075-8qnkc,phase=Pending node=kind-worker
75.066,Event,ADDED,eval-sanitize-5-r3-075-8qnkc.18d3d47526b4022f,reason=Scheduled count=None msg=Successfully assigned compute/eval-sanitize-5-r3-075-8qnkc to kind-worker
75.072,Pod,MODIFIED,eval-sanitize-5-r3-075-8qnkc,phase=Pending node=kind-worker
75.115,TaskRequest,MODIFIED,eval-sanitize-5-r3-058,phase=Complete job=None
75.1257,Job,MODIFIED,eval-sanitize-5-r3-058,
75.1271,Job,MODIFIED,eval-sanitize-5-r3-075,
75.1279,Job,MODIFIED,eval-sanitize-5-r3-074,
75.1866,Pod,MODIFIED,eval-sanitize-5-r3-062-lrf47,phase=Succeeded node=kind-worker2
75.3162,Node,MODIFIED,kind-worker3,taints=1
75.3291,Node,MODIFIED,kind-worker3,taints=1
75.4836,Event,ADDED,eval-sanitize-5-r3-075-8qnkc.18d3d4753f8dc657,"reason=Pulled count=1 msg=Container image ""busybox:musl"" already present on machine"
75.5075,Event,ADDED,eval-sanitize-5-r3-075-8qnkc.18d3d475409d4355,reason=Created count=1 msg=Created container: task
75.534,Event,ADDED,eval-sanitize-5-r3-075-8qnkc.18d3d475429595aa,reason=Started count=1 msg=Started container task
75.5733,Pod,MODIFIED,eval-sanitize-5-r3-075-8qnkc,phase=Running node=kind-worker
75.5796,Pod,MODIFIED,eval-sanitize-5-r3-074-mp9lq,phase=Running node=kind-worker
76.0213,TaskRequest,ADDED,eval-sanitize-5-r3-076,phase=None job=None
76.0255,TaskRequest,MODIFIED,eval-sanitize-5-r3-076,phase=Pending job=None
76.0416,Job,ADDED,eval-sanitize-5-r3-076,
76.0436,Job,MODIFIED,eval-sanitize-5-r3-062,
76.0479,Pod,ADDED,eval-sanitize-5-r3-076-xqtjs,phase=Pending node=None
76.0492,TaskRequest,MODIFIED,eval-sanitize-5-r3-076,phase=Scheduled job=None
76.0501,Job,MODIFIED,eval-sanitize-5-r3-075,
76.0538,Pod,MODIFIED,eval-sanitize-5-r3-062-lrf47,phase=Succeeded node=kind-worker2
76.0543,Event,ADDED,eval-sanitize-5-r3-076.18d3d47561721a9a,reason=SuccessfulCreate count=1 msg=Created pod: eval-sanitize-5-r3-076-xqtjs
76.055,Job,MODIFIED,eval-sanitize-5-r3-076,
76.0575,Job,MODIFIED,eval-sanitize-5-r3-062,
76.0606,Pod,MODIFIED,eval-sanitize-5-r3-076-xqtjs,phase=Pending node=None
76.0632,Job,MODIFIED,eval-sanitize-5-r3-075,
76.0647,Event,ADDED,eval-sanitize-5-r3-062.18d3d47562060112,reason=Completed count=1 msg=Job completed
76.0656,Job,MODIFIED,eval-sanitize-5-r3-074,
76.0673,Event,ADDED,eval-sanitize-5-r3-076-xqtjs.18d3d47561e64373,"reason=FailedScheduling count=None msg=0/6 nodes are available: 2 c_wall violated: 1 conflicting context pair(s) with node memory, 4 node(s) had untolerated taint(s). no new claims to deallocate, preemption: 0/6 nodes are available: 2 No preemption victims found for incoming pod, 4 Preemption is not helpful for scheduling."
76.0701,Job,MODIFIED,eval-sanitize-5-r3-062,
76.0704,Event,ADDED,eval-sanitize-5-r3-076-xqtjs.18d3d4756298bcd6,"reason=FailedScheduling count=None msg=0/6 nodes are available: 2 c_wall violated: 1 conflicting context pair(s) with node memory, 4 node(s) had untolerated taint(s). no new claims to deallocate, preemption: 0/6 nodes are available: 2 No preemption victims found for incoming pod, 4 Preemption is not helpful for scheduling."
76.0736,Job,MODIFIED,eval-sanitize-5-r3-074,
76.0738,TaskRequest,MODIFIED,eval-sanitize-5-r3-062,phase=Complete job=None
76.1233,Job,MODIFIED,eval-sanitize-5-r3-062,
76.1234,TaskRequest,MODIFIED,eval-sanitize-5-r3-076,phase=Scheduled job=None
76.7979,Node,MODIFIED,kind-worker4,taints=1
76.8074,Pod,MODIFIED,eval-sanitize-5-r3-076-xqtjs,phase=Pending node=None
76.8079,Event,MODIFIED,eval-sanitize-5-r3-076-xqtjs.18d3d4756298bcd6,"reason=FailedScheduling count=None msg=0/6 nodes are available: 2 c_wall violated: 1 conflicting context pair(s) with node memory, 4 node(s) had untolerated taint(s). no new claims to deallocate, preemption: 0/6 nodes are available: 2 No preemption victims found for incoming pod, 4 Preemption is not helpful for scheduling."
76.8114,Node,MODIFIED,kind-worker4,taints=1
76.8151,Event,ADDED,eval-sanitize-5-r3-076-xqtjs.18d3d4758ef4a11f,"reason=FailedScheduling count=None msg=0/6 nodes are available: 1 c_wall violated: 1 conflicting context pair(s) with node memory, 5 node(s) had untolerated taint(s). no new claims to deallocate, preemption: 0/6 nodes are available: 1 No preemption victims found for incoming pod, 5 Preemption is not helpful for scheduling."
76.8425,Event,MODIFIED,eval-sanitize-5-r3-076-xqtjs.18d3d4758ef4a11f,"reason=FailedScheduling count=None msg=0/6 nodes are available: 1 c_wall violated: 1 conflicting context pair(s) with node memory, 5 node(s) had untolerated taint(s). no new claims to deallocate, preemption: 0/6 nodes are available: 1 No preemption victims found for incoming pod, 5 Preemption is not helpful for scheduling."
77.0129,TaskRequest,ADDED,eval-sanitize-5-r3-077,phase=None job=None
77.0181,TaskRequest,MODIFIED,eval-sanitize-5-r3-077,phase=Pending job=None
77.0329,Job,ADDED,eval-sanitize-5-r3-077,
77.0394,Pod,ADDED,eval-sanitize-5-r3-077-98g9s,phase=Pending node=None
77.0415,TaskRequest,MODIFIED,eval-sanitize-5-r3-077,phase=Scheduled job=None
77.0423,Job,MODIFIED,eval-sanitize-5-r3-077,
77.0442,Event,ADDED,eval-sanitize-5-r3-077.18d3d4759c906946,reason=SuccessfulCreate count=1 msg=Created pod: eval-sanitize-5-r3-077-98g9s
77.0491,Pod,MODIFIED,eval-sanitize-5-r3-077-98g9s,phase=Pending node=kind-worker
77.0499,TaskRequest,MODIFIED,eval-sanitize-5-r3-077,phase=Scheduled job=None
77.0549,Job,MODIFIED,eval-sanitize-5-r3-076,
77.0553,Event,ADDED,eval-sanitize-5-r3-077-98g9s.18d3d4759d1da832,reason=Scheduled count=None msg=Successfully assigned compute/eval-sanitize-5-r3-077-98g9s to kind-worker
77.0594,Node,MODIFIED,kind-worker,taints=0
77.0621,Pod,MODIFIED,eval-sanitize-5-r3-077-98g9s,phase=Pending node=kind-worker
77.0633,Job,MODIFIED,eval-sanitize-5-r3-076,
77.0701,Node,MODIFIED,kind-worker,taints=0
77.4679,Event,ADDED,eval-sanitize-5-r3-077-98g9s.18d3d475b5d42244,"reason=Pulled count=1 msg=Container image ""busybox:musl"" already present on machine"
77.4868,Event,ADDED,eval-sanitize-5-r3-077-98g9s.18d3d475b6fcbf00,reason=Created count=1 msg=Created container: task
77.5244,Event,ADDED,eval-sanitize-5-r3-077-98g9s.18d3d475b93489a6,reason=Started count=1 msg=Started container task
77.584,Pod,MODIFIED,eval-sanitize-5-r3-077-98g9s,phase=Running node=kind-worker
78.0059,Pod,MODIFIED,eval-sanitize-5-r3-060-jqm27,phase=Running node=kind-worker5
78.0069,TaskRequest,ADDED,eval-sanitize-5-r3-078,phase=None job=None
78.0121,TaskRequest,MODIFIED,eval-sanitize-5-r3-078,phase=Pending job=None
78.0263,Job,ADDED,eval-sanitize-5-r3-078,
78.0335,Pod,ADDED,eval-sanitize-5-r3-078-rcqhb,phase=Pending node=None
78.0337,TaskRequest,MODIFIED,eval-sanitize-5-r3-078,phase=Scheduled job=None
78.0359,Job,MODIFIED,eval-sanitize-5-r3-078,
78.0392,Event,ADDED,eval-sanitize-5-r3-078.18d3d475d7c6c17b,reason=SuccessfulCreate count=1 msg=Created pod: eval-sanitize-5-r3-078-rcqhb
78.0413,Event,ADDED,eval-sanitize-5-r3-078-rcqhb.18d3d475d801d2dd,"reason=FailedScheduling count=None msg=0/6 nodes are available: 1 c_wall violated: 1 conflicting context pair(s) with node memory, 5 node(s) had untolerated taint(s). no new claims to deallocate, preemption: 0/6 nodes are available: 1 No preemption victims found for incoming pod, 5 Preemption is not helpful for scheduling."
78.0415,TaskRequest,MODIFIED,eval-sanitize-5-r3-078,phase=Scheduled job=None
78.0425,Pod,MODIFIED,eval-sanitize-5-r3-078-rcqhb,phase=Pending node=None
78.0438,Job,MODIFIED,eval-sanitize-5-r3-077,
78.0499,Event,ADDED,eval-sanitize-5-r3-078-rcqhb.18d3d475d8918bf1,"reason=FailedScheduling count=None msg=0/6 nodes are available: 1 c_wall violated: 1 conflicting context pair(s) with node memory, 5 node(s) had untolerated taint(s). no new claims to deallocate, preemption: 0/6 nodes are available: 1 No preemption victims found for incoming pod, 5 Preemption is not helpful for scheduling."
78.0525,Job,MODIFIED,eval-sanitize-5-r3-077,
78.0723,Node,MODIFIED,kind-worker2,taints=1
78.0841,Event,MODIFIED,eval-sanitize-5-r3-078-rcqhb.18d3d475d8918bf1,"reason=FailedScheduling count=None msg=0/6 nodes are available: 1 c_wall violated: 1 conflicting context pair(s) with node memory, 5 node(s) had untolerated taint(s). no new claims to deallocate, preemption: 0/6 nodes are available: 1 No preemption victims found for incoming pod, 5 Preemption is not helpful for scheduling."
78.1588,Node,MODIFIED,kind-worker2,taints=0
78.1683,Node,MODIFIED,kind-worker2,taints=0
78.1696,Pod,MODIFIED,eval-sanitize-5-r3-076-xqtjs,phase=Pending node=kind-worker2
78.1739,Pod,MODIFIED,eval-sanitize-5-r3-078-rcqhb,phase=Pending node=kind-worker2
78.1744,Event,ADDED,eval-sanitize-5-r3-076-xqtjs.18d3d475dfe8d72e,reason=Scheduled count=None msg=Successfully assigned compute/eval-sanitize-5-r3-076-xqtjs to kind-worker2
78.1819,Node,MODIFIED,kind-worker2,taints=0
78.184,Event,ADDED,eval-sanitize-5-r3-078-rcqhb.18d3d475e0262bac,reason=Scheduled count=None msg=Successfully assigned compute/eval-sanitize-5-r3-078-rcqhb to kind-worker2
78.1894,Pod,MODIFIED,eval-sanitize-5-r3-076-xqtjs,phase=Pending node=kind-worker2
78.1953,Pod,MODIFIED,eval-sanitize-5-r3-078-rcqhb,phase=Pending node=kind-worker2
78.2075,Node,MODIFIED,kind-worker2,taints=0
78.2169,Node,MODIFIED,kind-worker2,taints=0
78.3014,Node,MODIFIED,kind-worker,taints=1
78.3129,Node,MODIFIED,kind-worker,taints=1
78.6993,Event,ADDED,eval-sanitize-5-r3-078-rcqhb.18d3d475ff3ae334,"reason=Pulled count=1 msg=Container image ""busybox:musl"" already present on machine"
78.7038,Event,ADDED,eval-sanitize-5-r3-076-xqtjs.18d3d475ff597a3e,"reason=Pulled count=1 msg=Container image ""busybox:musl"" already present on machine"
78.7222,Event,ADDED,eval-sanitize-5-r3-078-rcqhb.18d3d476008c3c8d,reason=Created count=1 msg=Created container: task
78.7261,Event,ADDED,eval-sanitize-5-r3-076-xqtjs.18d3d47600e432c8,reason=Created count=1 msg=Created container: task
78.7835,Event,ADDED,eval-sanitize-5-r3-078-rcqhb.18d3d476044387bd,reason=Started count=1 msg=Started container task
78.7871,Event,ADDED,eval-sanitize-5-r3-076-xqtjs.18d3d47604868d92,reason=Started count=1 msg=Started container task
79.0092,Pod,MODIFIED,eval-sanitize-5-r3-059-4hqs6,phase=Running node=kind-worker5
79.0104,Job,MODIFIED,eval-sanitize-5-r3-060,
79.0128,TaskRequest,ADDED,eval-sanitize-5-r3-079,phase=None job=None
79.0164,Pod,MODIFIED,eval-sanitize-5-r3-061-jsgbk,phase=Running node=kind-worker5
79.0165,TaskRequest,MODIFIED,eval-sanitize-5-r3-079,phase=Pending job=None
79.0217,Job,MODIFIED,eval-sanitize-5-r3-060,
79.0257,Pod,MODIFIED,eval-sanitize-5-r3-065-sqkkl,phase=Running node=kind-worker5
79.0346,Pod,MODIFIED,eval-sanitize-5-r3-067-nj69x,phase=Running node=kind-worker5
79.0371,Job,ADDED,eval-sanitize-5-r3-079,
79.0386,Pod,MODIFIED,eval-sanitize-5-r3-076-xqtjs,phase=Running node=kind-worker2
79.0395,Job,MODIFIED,eval-sanitize-5-r3-078,
79.0428,Pod,MODIFIED,eval-sanitize-5-r3-068-x42j8,phase=Running node=kind-worker5
79.0458,Pod,ADDED,eval-sanitize-5-r3-079-xc8jq,phase=Pending node=None
79.0459,TaskRequest,MODIFIED,eval-sanitize-5-r3-079,phase=Scheduled job=None
79.0471,Pod,MODIFIED,eval-sanitize-5-r3-078-rcqhb,phase=Running node=kind-worker2
79.0485,Job,MODIFIED,eval-sanitize-5-r3-079,
79.05,Event,ADDED,eval-sanitize-5-r3-079.18d3d47614148674,reason=SuccessfulCreate count=1 msg=Created pod: eval-sanitize-5-r3-079-xc8jq
79.0537,Pod,MODIFIED,eval-sanitize-5-r3-079-xc8jq,phase=Pending node=None
79.0546,Event,ADDED,eval-sanitize-5-r3-079-xc8jq.18d3d476145985e7,"reason=FailedScheduling count=None msg=0/6 nodes are available: 1 c_wall violated: 1 conflicting context pair(s) with node memory, 5 node(s) had untolerated taint(s). no new claims to deallocate, preemption: 0/6 nodes are available: 1 No preemption victims found for incoming pod, 5 Preemption is not helpful for scheduling."
79.0547,TaskRequest,MODIFIED,eval-sanitize-5-r3-079,phase=Scheduled job=None
79.0572,Job,MODIFIED,eval-sanitize-5-r3-078,
79.0601,Event,ADDED,eval-sanitize-5-r3-079-xc8jq.18d3d47614d6320c,"reason=FailedScheduling count=None msg=0/6 nodes are available: 1 c_wall violated: 1 conflicting context pair(s) with node memory, 5 node(s) had untolerated taint(s). no new claims to deallocate, preemption: 0/6 nodes are available: 1 No preemption victims found for incoming pod, 5 Preemption is not helpful for scheduling."
79.1259,Pod,MODIFIED,eval-sanitize-5-r3-060-jqm27,phase=Succeeded node=kind-worker5
79.1337,Event,MODIFIED,eval-sanitize-5-r3-079-xc8jq.18d3d47614d6320c,"reason=FailedScheduling count=None msg=0/6 nodes are available: 1 c_wall violated: 1 conflicting context pair(s) with node memory, 5 node(s) had untolerated taint(s). no new claims to deallocate, preemption: 0/6 nodes are available: 1 No preemption victims found for incoming pod, 5 Preemption is not helpful for scheduling."
79.1761,Job,MODIFIED,eval-sanitize-5-r3-076,
79.1847,Job,MODIFIED,eval-sanitize-5-r3-076,
80.0089,TaskRequest,ADDED,eval-sanitize-5-r3-080,phase=None job=None
80.0162,Job,MODIFIED,eval-sanitize-5-r3-059,
80.018,TaskRequest,MODIFIED,eval-sanitize-5-r3-080,phase=Pending job=None
80.0201,Job,MODIFIED,eval-sanitize-5-r3-060,
80.0243,Job,MODIFIED,eval-sanitize-5-r3-061,
80.0276,Pod,MODIFIED,eval-sanitize-5-r3-069-h9nl9,phase=Running node=kind-worker5
80.0336,Pod,MODIFIED,eval-sanitize-5-r3-060-jqm27,phase=Succeeded node=kind-worker5
80.0347,Job,MODIFIED,eval-sanitize-5-r3-065,
80.037,Job,MODIFIED,eval-sanitize-5-r3-060,
80.039,Job,ADDED,eval-sanitize-5-r3-080,
80.0422,Job,MODIFIED,eval-sanitize-5-r3-067,
80.0436,Event,ADDED,eval-sanitize-5-r3-060.18d3d4764f39d947,reason=Completed count=1 msg=Job completed
80.0453,Job,MODIFIED,eval-sanitize-5-r3-078,
80.0463,Pod,ADDED,eval-sanitize-5-r3-080-2s9ct,phase=Pending node=None
80.0521,Job,MODIFIED,eval-sanitize-5-r3-068,
80.0536,Event,ADDED,eval-sanitize-5-r3-080.18d3d4764fbf2ee6,reason=SuccessfulCreate count=1 msg=Created pod: eval-sanitize-5-r3-080-2s9ct
80.0545,Job,MODIFIED,eval-sanitize-5-r3-080,
80.0552,Job,MODIFIED,eval-sanitize-5-r3-079,
80.0591,Pod,MODIFIED,eval-sanitize-5-r3-080-2s9ct,phase=Pending node=None
80.0602,Event,ADDED,eval-sanitize-5-r3-080-2s9ct.18d3d47650098dd5,"reason=FailedScheduling count=None msg=0/6 nodes are available: 1 c_wall violated: 1 conflicting context pair(s) with node memory, 5 node(s) had untolerated taint(s). no new claims to deallocate, preemption: 0/6 nodes are available: 1 No preemption victims found for incoming pod, 5 Preemption is not helpful for scheduling."
80.0604,TaskRequest,MODIFIED,eval-sanitize-5-r3-080,phase=Scheduled job=None
