t_recv,kind,type,name,detail
0.0229,Node,ADDED,kind-control-plane,taints=1
0.0248,Node,ADDED,kind-worker,taints=0
0.0263,Node,ADDED,kind-worker2,taints=0
0.0277,Node,ADDED,kind-worker3,taints=0
0.0291,Node,ADDED,kind-worker4,taints=0
0.0304,Node,ADDED,kind-worker5,taints=0
0.0468,TaskRequest,ADDED,eval-conflicts-rho070-r2-000,phase=None job=None
0.0506,TaskRequest,MODIFIED,eval-conflicts-rho070-r2-000,phase=Pending job=None
0.0643,Event,ADDED,eval-conflicts-rho020-r0-000-nk7lx.18d53ec2f9c031a6,reason=Scheduled count=None msg=Successfully assigned compute/eval-conflicts-rho020-r0-000-nk7lx to kind-worker2
0.0649,Event,ADDED,eval-conflicts-rho020-r0-000-nk7lx.18d53ec319222533,"reason=Pulled count=1 msg=Container image ""busybox:musl"" already present on machine"
0.0651,Event,ADDED,eval-conflicts-rho020-r0-000-nk7lx.18d53ec31aaf5d5c,reason=Created count=1 msg=Created container: task
0.0654,Event,ADDED,eval-conflicts-rho020-r0-000-nk7lx.18d53ec32143bd08,reason=Started count=1 msg=Started container task
0.0656,Event,ADDED,eval-conflicts-rho020-r0-000.18d53ec2f8c7b0fd,reason=SuccessfulCreate count=1 msg=Created pod: eval-conflicts-rho020-r0-000-nk7lx
0.066,Event,ADDED,eval-conflicts-rho020-r0-000.18d53ec880ad1688,reason=Completed count=1 msg=Job completed
0.0662,Event,ADDED,eval-conflicts-rho020-r0-001-ztv6z.18d53ec3330674d4,reason=Scheduled count=None msg=Successfully assigned compute/eval-conflicts-rho020-r0-001-ztv6z to kind-worker3
0.0665,Event,ADDED,eval-conflicts-rho020-r0-001-ztv6z.18d53ec3506bf6b0,"reason=Pulled count=1 msg=Container image ""busybox:musl"" already present on machine"
0.0672,Event,ADDED,eval-conflicts-rho020-r0-001-ztv6z.18d53ec35179dcf5,reason=Created count=1 msg=Created container: task
0.0675,Event,ADDED,eval-conflicts-rho020-r0-001-ztv6z.18d53ec353658a0b,reason=Started count=1 msg=Started container task
0.0677,Event,ADDED,eval-conflicts-rho020-r0-001.18d53ec331ea6e38,reason=SuccessfulCreate count=1 msg=Created pod: eval-conflicts-rho020-r0-001-ztv6z
0.0678,Event,ADDED,eval-conflicts-rho020-r0-001.18d53ec8b949feb2,reason=Completed count=1 msg=Job completed
0.0682,Event,ADDED,eval-conflicts-rho020-r0-002-7mwfg.18d53ec36e026383,reason=Scheduled count=None msg=Successfully assigned compute/eval-conflicts-rho020-r0-002-7mwfg to kind-worker3
0.0686,Event,ADDED,eval-conflicts-rho020-r0-002-7mwfg.18d53ec388b85a98,"reason=Pulled count=1 msg=Container image ""busybox:musl"" already present on machine"
0.0689,Event,ADDED,eval-conflicts-rho020-r0-002-7mwfg.18d53ec38a07f8d1,reason=Created count=1 msg=Created container: task
0.0691,Event,ADDED,eval-conflicts-rho020-r0-002-7mwfg.18d53ec391f9a6be,reason=Started count=1 msg=Started container task
0.0694,Event,ADDED,eval-conflicts-rho020-r0-002.18d53ec36d07af08,reason=SuccessfulCreate count=1 msg=Created pod: eval-conflicts-rho020-r0-002-7mwfg
0.0696,Event,ADDED,eval-conflicts-rho020-r0-002.18d53ec8f5b3080b,reason=Completed count=1 msg=Job completed
0.0698,Event,ADDED,eval-conflicts-rho020-r0-003-ghpsv.18d53ec3a7ba037f,reason=Scheduled count=None msg=Successfully assigned compute/eval-conflicts-rho020-r0-003-ghpsv to kind-worker2
0.0705,Job,ADDED,eval-conflicts-rho070-r2-000,
0.0708,Event,ADDED,eval-conflicts-rho020-r0-003-ghpsv.18d53ec3c52ad917,"reason=Pulled count=1 msg=Container image ""busybox:musl"" already present on machine"
0.0711,Event,ADDED,eval-conflicts-rho020-r0-003-ghpsv.18d53ec3c64bc499,reason=Created count=1 msg=Created container: task
0.0713,Event,ADDED,eval-conflicts-rho020-r0-003-ghpsv.18d53ec3cafd93e3,reason=Started count=1 msg=Started container task
0.0715,Event,ADDED,eval-conflicts-rho020-r0-003.18d53ec3a6d4f335,reason=SuccessfulCreate count=1 msg=Created pod: eval-conflicts-rho020-r0-003-ghpsv
0.0718,Event,ADDED,eval-conflicts-rho020-r0-003.18d53ec933a8acc3,reason=Completed count=1 msg=Job completed
0.072,Event,ADDED,eval-conflicts-rho020-r0-004-7594m.18d53ec3e769d2d1,reason=Scheduled count=None msg=Successfully assigned compute/eval-conflicts-rho020-r0-004-7594m to kind-worker4
0.0722,Event,ADDED,eval-conflicts-rho020-r0-004-7594m.18d53ec4065cd7f5,"reason=Pulled count=1 msg=Container image ""busybox:musl"" already present on machine"
0.0724,Event,ADDED,eval-conflicts-rho020-r0-004-7594m.18d53ec40796202c,reason=Created count=1 msg=Created container: task
0.0729,Event,ADDED,eval-conflicts-rho020-r0-004-7594m.18d53ec409f64e77,reason=Started count=1 msg=Started container task
0.0732,Event,ADDED,eval-conflicts-rho020-r0-004.18d53ec3e693a297,reason=SuccessfulCreate count=1 msg=Created pod: eval-conflicts-rho020-r0-004-7594m
0.0734,Event,ADDED,eval-conflicts-rho020-r0-004.18d53ec9a628073c,reason=Completed count=1 msg=Job completed
0.074,Event,ADDED,eval-conflicts-rho020-r0-005-2x666.18d53ec41fd7b386,reason=Scheduled count=None msg=Successfully assigned compute/eval-conflicts-rho020-r0-005-2x666 to kind-worker4
0.0742,Event,ADDED,eval-conflicts-rho020-r0-005-2x666.18d53ec439b0243e,"reason=Pulled count=1 msg=Container image ""busybox:musl"" already present on machine"
0.0744,Event,ADDED,eval-conflicts-rho020-r0-005-2x666.18d53ec43ae24e30,reason=Created count=1 msg=Created container: task
0.0745,Event,ADDED,eval-conflicts-rho020-r0-005-2x666.18d53ec4420b7c97,reason=Started count=1 msg=Started container task
0.0747,TaskRequest,MODIFIED,eval-conflicts-rho070-r2-000,phase=Scheduled job=None
0.075,Event,ADDED,eval-conflicts-rho020-r0-005.18d53ec41ea82b05,reason=SuccessfulCreate count=1 msg=Created pod: eval-conflicts-rho020-r0-005-2x666
0.0752,Event,ADDED,eval-conflicts-rho020-r0-005.18d53ec9a64ac32c,reason=Completed count=1 msg=Job completed
0.0754,Event,ADDED,eval-conflicts-rho020-r0-006-5h2m7.18d53ec45ad67018,reason=Scheduled count=None msg=Successfully assigned compute/eval-conflicts-rho020-r0-006-5h2m7 to kind-worker3
0.0756,Event,ADDED,eval-conflicts-rho020-r0-006-5h2m7.18d53ec477842228,"reason=Pulled count=1 msg=Container image ""busybox:musl"" already present on machine"
0.0759,Event,ADDED,eval-conflicts-rho020-r0-006-5h2m7.18d53ec478c4c147,reason=Created count=1 msg=Created container: task
0.0762,Event,ADDED,eval-conflicts-rho020-r0-006-5h2m7.18d53ec47e152f2b,reason=Started count=1 msg=Started container task
0.0763,Event,ADDED,eval-conflicts-rho020-r0-006.18d53ec459ad34a4,reason=SuccessfulCreate count=1 msg=Created pod: eval-conflicts-rho020-r0-006-5h2m7
0.0769,Event,ADDED,eval-conflicts-rho020-r0-006.18d53ec9e22e8ef0,reason=Completed count=1 msg=Job completed
0.0774,Event,ADDED,eval-conflicts-rho020-r0-007-pf64c.18d53ec4967d3be6,reason=Scheduled count=None msg=Successfully assigned compute/eval-conflicts-rho020-r0-007-pf64c to kind-worker5
0.0779,Event,ADDED,eval-conflicts-rho020-r0-007-pf64c.18d53ec4af929b0d,"reason=Pulled count=1 msg=Container image ""busybox:musl"" already present on machine"
0.0784,Event,ADDED,eval-conflicts-rho020-r0-007-pf64c.18d53ec4b0a1cdcd,reason=Created count=1 msg=Created container: task
0.0792,Event,ADDED,eval-conflicts-rho020-r0-007-pf64c.18d53ec4b27b204e,reason=Started count=1 msg=Started container task
0.0796,Event,ADDED,eval-conflicts-rho020-r0-007.18d53ec495371d37,reason=SuccessfulCreate count=1 msg=Created pod: eval-conflicts-rho020-r0-007-pf64c
0.0801,Event,ADDED,eval-conflicts-rho020-r0-007.18d53eca4f298745,reason=Completed count=1 msg=Job completed
0.0806,Event,ADDED,eval-conflicts-rho020-r0-008-c6z28.18d53ec4d1e44399,reason=Scheduled count=None msg=Successfully assigned compute/eval-conflicts-rho020-r0-008-c6z28 to kind-worker2
0.0808,Event,ADDED,eval-conflicts-rho020-r0-008-c6z28.18d53ec4eb9cfbc7,"reason=Pulled count=1 msg=Container image ""busybox:musl"" already present on machine"
0.081,Event,ADDED,eval-conflicts-rho020-r0-008-c6z28.18d53ec4ecd19151,reason=Created count=1 msg=Created container: task
0.0813,Event,ADDED,eval-conflicts-rho020-r0-008-c6z28.18d53ec4f0c96acd,reason=Started count=1 msg=Started container task
0.0822,Pod,ADDED,eval-conflicts-rho070-r2-000-bc5z5,phase=Pending node=None
0.0827,Event,ADDED,eval-conflicts-rho020-r0-008.18d53ec4d0aef2e3,reason=SuccessfulCreate count=1 msg=Created pod: eval-conflicts-rho020-r0-008-c6z28
0.0829,Event,ADDED,eval-conflicts-rho020-r0-008.18d53eca630bfa3c,reason=Completed count=1 msg=Job completed
0.0831,Event,ADDED,eval-conflicts-rho020-r0-009-24pl6.18d53ec5116bcfa8,reason=Scheduled count=None msg=Successfully assigned compute/eval-conflicts-rho020-r0-009-24pl6 to kind-worker3
0.0833,Event,ADDED,eval-conflicts-rho020-r0-009-24pl6.18d53ec52bbdcb2c,"reason=Pulled count=1 msg=Container image ""busybox:musl"" already present on machine"
0.0836,Event,ADDED,eval-conflicts-rho020-r0-009-24pl6.18d53ec52cccbe53,reason=Created count=1 msg=Created container: task
0.0838,Event,ADDED,eval-conflicts-rho020-r0-009-24pl6.18d53ec52ee7d214,reason=Started count=1 msg=Started container task
0.084,Event,ADDED,eval-conflicts-rho020-r0-009.18d53ec50c59b15d,reason=SuccessfulCreate count=1 msg=Created pod: eval-conflicts-rho020-r0-009-24pl6
0.0848,Job,MODIFIED,eval-conflicts-rho070-r2-000,
0.0851,Event,ADDED,eval-conflicts-rho020-r0-009.18d53eca94bd4d64,reason=Completed count=1 msg=Job completed
0.0853,Event,ADDED,eval-conflicts-rho020-r0-010-l62xn.18d53ec548e7ef93,reason=Scheduled count=None msg=Successfully assigned compute/eval-conflicts-rho020-r0-010-l62xn to kind-worker4
0.0855,Event,ADDED,eval-conflicts-rho020-r0-010-l62xn.18d53ec562192884,"reason=Pulled count=1 msg=Container image ""busybox:musl"" already present on machine"
0.0857,Event,ADDED,eval-conflicts-rho020-r0-010-l62xn.18d53ec56316ffa3,reason=Created count=1 msg=Created container: task
0.086,Event,ADDED,eval-conflicts-rho020-r0-010-l62xn.18d53ec5698d4bcf,reason=Started count=1 msg=Started container task
0.0862,Event,ADDED,eval-conflicts-rho020-r0-010.18d53ec547a3d923,reason=SuccessfulCreate count=1 msg=Created pod: eval-conflicts-rho020-r0-010-l62xn
0.0864,Event,ADDED,eval-conflicts-rho020-r0-010.18d53ecacef6ace9,reason=Completed count=1 msg=Job completed
0.0865,Event,ADDED,eval-conflicts-rho020-r0-011-lrcth.18d53ec584a24fcd,reason=Scheduled count=None msg=Successfully assigned compute/eval-conflicts-rho020-r0-011-lrcth to kind-worker3
0.0869,Event,ADDED,eval-conflicts-rho020-r0-011-lrcth.18d53ec5a051c324,"reason=Pulled count=1 msg=Container image ""busybox:musl"" already present on machine"
0.0871,Event,ADDED,eval-conflicts-rho020-r0-011-lrcth.18d53ec5a17e6a7f,reason=Created count=1 msg=Created container: task
0.0873,Event,ADDED,eval-conflicts-rho020-r0-011-lrcth.18d53ec5a5f90207,reason=Started count=1 msg=Started container task
0.0878,Event,ADDED,eval-conflicts-rho020-r0-011.18d53ec583474b5e,reason=SuccessfulCreate count=1 msg=Created pod: eval-conflicts-rho020-r0-011-lrcth
0.0881,Event,ADDED,eval-conflicts-rho020-r0-011.18d53ecb0c8adaf0,reason=Completed count=1 msg=Job completed
0.0883,Event,ADDED,eval-conflicts-rho020-r0-012-7gns6.18d53ec5c64f6ca4,reason=Scheduled count=None msg=Successfully assigned compute/eval-conflicts-rho020-r0-012-7gns6 to kind-worker
0.0885,Event,ADDED,eval-conflicts-rho020-r0-012-7gns6.18d53ec5e221c760,"reason=Pulled count=1 msg=Container image ""busybox:musl"" already present on machine"
0.0888,Event,ADDED,eval-conflicts-rho020-r0-012-7gns6.18d53ec5e335a8f7,reason=Created count=1 msg=Created container: task
0.089,Event,ADDED,eval-conflicts-rho020-r0-012-7gns6.18d53ec5ea0a8c0c,reason=Started count=1 msg=Started container task
0.0892,Event,ADDED,eval-conflicts-rho020-r0-012.18d53ec5bfd1b0ef,reason=SuccessfulCreate count=1 msg=Created pod: eval-conflicts-rho020-r0-012-7gns6
0.0894,Event,ADDED,eval-conflicts-rho020-r0-012.18d53ecb6e641f9f,reason=Completed count=1 msg=Job completed
0.0896,Event,ADDED,eval-conflicts-rho020-r0-013-7qlqh.18d53ec5fb8ba802,reason=Scheduled count=None msg=Successfully assigned compute/eval-conflicts-rho020-r0-013-7qlqh to kind-worker2
0.0898,Event,ADDED,eval-conflicts-rho020-r0-013-7qlqh.18d53ec6152ffdee,"reason=Pulled count=1 msg=Container image ""busybox:musl"" already present on machine"
0.0899,Event,ADDED,eval-conflicts-rho020-r0-013-7qlqh.18d53ec61647f4f6,reason=Created count=1 msg=Created container: task
0.0902,Event,ADDED,eval-conflicts-rho020-r0-013-7qlqh.18d53ec61841438e,reason=Started count=1 msg=Started container task
0.0904,Event,ADDED,eval-conflicts-rho020-r0-013.18d53ec5fa314fd0,reason=SuccessfulCreate count=1 msg=Created pod: eval-conflicts-rho020-r0-013-7qlqh
0.0905,Event,ADDED,eval-conflicts-rho020-r0-013.18d53ecb8951fb26,reason=Completed count=1 msg=Job completed
0.0907,Event,ADDED,eval-conflicts-rho020-r0-014-tps2z.18d53ec637530228,reason=Scheduled count=None msg=Successfully assigned compute/eval-conflicts-rho020-r0-014-tps2z to kind-worker2
0.091,Event,ADDED,eval-conflicts-rho020-r0-014-tps2z.18d53ec64f6f024f,"reason=Pulled count=1 msg=Container image ""busybox:musl"" already present on machine"
0.0912,Event,ADDED,eval-conflicts-rho020-r0-014-tps2z.18d53ec650779827,reason=Created count=1 msg=Created container: task
0.0914,Event,ADDED,eval-conflicts-rho020-r0-014-tps2z.18d53ec6525e2db8,reason=Started count=1 msg=Started container task
0.0918,Event,ADDED,eval-conflicts-rho020-r0-014.18d53ec635fce4ff,reason=SuccessfulCreate count=1 msg=Created pod: eval-conflicts-rho020-r0-014-tps2z
0.0922,Event,ADDED,eval-conflicts-rho020-r0-014.18d53ecbc53f5db6,reason=Completed count=1 msg=Job completed
0.0925,Event,ADDED,eval-conflicts-rho020-r0-015-xpq9h.18d53ec6767dff92,reason=Scheduled count=None msg=Successfully assigned compute/eval-conflicts-rho020-r0-015-xpq9h to kind-worker5
0.0927,Event,ADDED,eval-conflicts-rho020-r0-015-xpq9h.18d53ec68fab3f6d,"reason=Pulled count=1 msg=Container image ""busybox:musl"" already present on machine"
0.0931,Event,ADDED,eval-conflicts-rho020-r0-015-xpq9h.18d53ec690be129d,reason=Created count=1 msg=Created container: task
0.0933,Event,ADDED,eval-conflicts-rho020-r0-015-xpq9h.18d53ec694b7d01c,reason=Started count=1 msg=Started container task
0.0935,Event,ADDED,eval-conflicts-rho020-r0-015.18d53ec671ff41c9,reason=SuccessfulCreate count=1 msg=Created pod: eval-conflicts-rho020-r0-015-xpq9h
0.0937,Event,ADDED,eval-conflicts-rho020-r0-015.18d53ecc29e0fc53,reason=Completed count=1 msg=Job completed
0.0946,Job,MODIFIED,eval-conflicts-rho070-r2-000,
0.0951,Event,ADDED,eval-conflicts-rho020-r0-016-wqtj4.18d53ec6b29b27a1,reason=Scheduled count=None msg=Successfully assigned compute/eval-conflicts-rho020-r0-016-wqtj4 to kind-worker
0.0953,Event,ADDED,eval-conflicts-rho020-r0-016-wqtj4.18d53ec6cc3bc1e6,"reason=Pulled count=1 msg=Container image ""busybox:musl"" already present on machine"
0.0955,Event,ADDED,eval-conflicts-rho020-r0-016-wqtj4.18d53ec6cd73fa6a,reason=Created count=1 msg=Created container: task
0.0959,Event,ADDED,eval-conflicts-rho020-r0-016-wqtj4.18d53ec6d426e281,reason=Started count=1 msg=Started container task
0.0961,Event,ADDED,eval-conflicts-rho020-r0-016.18d53ec6ae16d5a8,reason=SuccessfulCreate count=1 msg=Created pod: eval-conflicts-rho020-r0-016-wqtj4
0.0962,Event,ADDED,eval-conflicts-rho020-r0-016.18d53ecc5ad521c9,reason=Completed count=1 msg=Job completed
0.0964,Event,ADDED,eval-conflicts-rho020-r0-017-87fqr.18d53ec6ec9b1fb2,reason=Scheduled count=None msg=Successfully assigned compute/eval-conflicts-rho020-r0-017-87fqr to kind-worker4
0.0967,Event,ADDED,eval-conflicts-rho020-r0-017-87fqr.18d53ec706aa1197,"reason=Pulled count=1 msg=Container image ""busybox:musl"" already present on machine"
0.097,Event,ADDED,eval-conflicts-rho020-r0-017-87fqr.18d53ec707c33a31,reason=Created count=1 msg=Created container: task
0.0977,Event,ADDED,eval-conflicts-rho020-r0-017-87fqr.18d53ec70b3ef780,reason=Started count=1 msg=Started container task
0.0987,Pod,MODIFIED,eval-conflicts-rho070-r2-000-bc5z5,phase=Pending node=kind-worker2
0.0993,Event,ADDED,eval-conflicts-rho020-r0-017.18d53ec6eb80b018,reason=SuccessfulCreate count=1 msg=Created pod: eval-conflicts-rho020-r0-017-87fqr
0.0995,Event,ADDED,eval-conflicts-rho020-r0-017.18d53ecc7146467e,reason=Completed count=1 msg=Job completed
0.0997,Event,ADDED,eval-conflicts-rho020-r0-018-75bn6.18d53ec72540e97a,reason=Scheduled count=None msg=Successfully assigned compute/eval-conflicts-rho020-r0-018-75bn6 to kind-worker
0.0999,Event,ADDED,eval-conflicts-rho020-r0-018-75bn6.18d53ec73f80e0af,"reason=Pulled count=1 msg=Container image ""busybox:musl"" already present on machine"
0.1005,Event,ADDED,eval-conflicts-rho020-r0-018-75bn6.18d53ec7409a4892,reason=Created count=1 msg=Created container: task
0.1008,Event,ADDED,eval-conflicts-rho020-r0-018-75bn6.18d53ec745271d9d,reason=Started count=1 msg=Started container task
0.1013,Event,ADDED,eval-conflicts-rho020-r0-018.18d53ec7244f96e3,reason=SuccessfulCreate count=1 msg=Created pod: eval-conflicts-rho020-r0-018-75bn6
0.1016,Event,ADDED,eval-conflicts-rho020-r0-018.18d53eccd203fb44,reason=Completed count=1 msg=Job completed
0.102,Event,ADDED,eval-conflicts-rho020-r0-019-467sv.18d53ec76174990b,reason=Scheduled count=None msg=Successfully assigned compute/eval-conflicts-rho020-r0-019-467sv to kind-worker5
0.1022,Event,ADDED,eval-conflicts-rho020-r0-019-467sv.18d53ec77a322153,"reason=Pulled count=1 msg=Container image ""busybox:musl"" already present on machine"
0.1024,Event,ADDED,eval-conflicts-rho020-r0-019-467sv.18d53ec77b44310a,reason=Created count=1 msg=Created container: task
0.1027,Event,ADDED,eval-conflicts-rho020-r0-019-467sv.18d53ec780bd41e3,reason=Started count=1 msg=Started container task
0.1029,Event,ADDED,eval-conflicts-rho020-r0-019.18d53ec760488d4d,reason=SuccessfulCreate count=1 msg=Created pod: eval-conflicts-rho020-r0-019-467sv
0.1031,Event,ADDED,eval-conflicts-rho020-r0-019.18d53ecd1852f36b,reason=Completed count=1 msg=Job completed
0.1033,Event,ADDED,eval-conflicts-rho020-r0-020-ntwgc.18d53ec79ce81fcc,reason=Scheduled count=None msg=Successfully assigned compute/eval-conflicts-rho020-r0-020-ntwgc to kind-worker5
0.1037,Event,ADDED,eval-conflicts-rho020-r0-020-ntwgc.18d53ec7b801c993,"reason=Pulled count=1 msg=Container image ""busybox:musl"" already present on machine"
0.1039,Event,ADDED,eval-conflicts-rho020-r0-020-ntwgc.18d53ec7b94dbf7e,reason=Created count=1 msg=Created container: task
0.1041,Event,ADDED,eval-conflicts-rho020-r0-020-ntwgc.18d53ec7bd16ffd1,reason=Started count=1 msg=Started container task
0.1043,Event,ADDED,eval-conflicts-rho020-r0-020.18d53ec79ba74b42,reason=SuccessfulCreate count=1 msg=Created pod: eval-conflicts-rho020-r0-020-ntwgc
0.1048,Event,ADDED,eval-conflicts-rho020-r0-020.18d53ecd54590ced,reason=Completed count=1 msg=Job completed
0.105,Event,ADDED,eval-conflicts-rho020-r0-021-wvx4w.18d53ec7d9ec73e1,reason=Scheduled count=None msg=Successfully assigned compute/eval-conflicts-rho020-r0-021-wvx4w to kind-worker4
0.1052,Event,ADDED,eval-conflicts-rho020-r0-021-wvx4w.18d53ec7f5d05f8d,"reason=Pulled count=1 msg=Container image ""busybox:musl"" already present on machine"
0.1054,TaskRequest,MODIFIED,eval-conflicts-rho070-r2-000,phase=Scheduled job=None
0.1058,Event,ADDED,eval-conflicts-rho020-r0-021-wvx4w.18d53ec7f7239f2c,reason=Created count=1 msg=Created container: task
0.106,Event,ADDED,eval-conflicts-rho020-r0-021-wvx4w.18d53ec7fd65fc67,reason=Started count=1 msg=Started container task
0.1062,Event,ADDED,eval-conflicts-rho020-r0-021.18d53ec7d8b716e7,reason=SuccessfulCreate count=1 msg=Created pod: eval-conflicts-rho020-r0-021-wvx4w
0.1063,Event,ADDED,eval-conflicts-rho020-r0-021.18d53ecd60639727,reason=Completed count=1 msg=Job completed
0.1077,Job,MODIFIED,eval-conflicts-rho070-r2-000,
0.108,Event,ADDED,eval-conflicts-rho020-r0-022-vgs8h.18d53ec81428581f,reason=Scheduled count=None msg=Successfully assigned compute/eval-conflicts-rho020-r0-022-vgs8h to kind-worker
0.1083,Event,ADDED,eval-conflicts-rho020-r0-022-vgs8h.18d53ec8301451db,"reason=Pulled count=1 msg=Container image ""busybox:musl"" already present on machine"
0.1085,Event,ADDED,eval-conflicts-rho020-r0-022-vgs8h.18d53ec83169c07b,reason=Created count=1 msg=Created container: task
0.1089,Event,ADDED,eval-conflicts-rho020-r0-022-vgs8h.18d53ec835308f26,reason=Started count=1 msg=Started container task
0.109,Event,ADDED,eval-conflicts-rho020-r0-022.18d53ec813348d81,reason=SuccessfulCreate count=1 msg=Created pod: eval-conflicts-rho020-r0-022-vgs8h
0.1092,Event,ADDED,eval-conflicts-rho020-r0-022.18d53ecdc19e1aab,reason=Completed count=1 msg=Job completed
0.1094,Event,ADDED,eval-conflicts-rho020-r0-023-x6znr.18d53ec84f3242e5,reason=Scheduled count=None msg=Successfully assigned compute/eval-conflicts-rho020-r0-023-x6znr to kind-worker
0.1112,Node,MODIFIED,kind-worker2,taints=0
0.1116,Event,ADDED,eval-conflicts-rho020-r0-023-x6znr.18d53ec868904c5b,"reason=Pulled count=1 msg=Container image ""busybox:musl"" already present on machine"
0.1118,Event,ADDED,eval-conflicts-rho020-r0-023-x6znr.18d53ec86999b5c0,reason=Created count=1 msg=Created container: task
0.112,Event,ADDED,eval-conflicts-rho020-r0-023-x6znr.18d53ec86c079466,reason=Started count=1 msg=Started container task
0.1121,Event,ADDED,eval-conflicts-rho020-r0-023.18d53ec84e590a95,reason=SuccessfulCreate count=1 msg=Created pod: eval-conflicts-rho020-r0-023-x6znr
0.1125,Event,ADDED,eval-conflicts-rho020-r0-023.18d53ecdfd80a0b3,reason=Completed count=1 msg=Job completed
0.1127,Event,ADDED,eval-conflicts-rho020-r0-024-jw4mk.18d53ec88b7ca800,reason=Scheduled count=None msg=Successfully assigned compute/eval-conflicts-rho020-r0-024-jw4mk to kind-worker
0.1129,Event,ADDED,eval-conflicts-rho020-r0-024-jw4mk.18d53ec8a570d764,"reason=Pulled count=1 msg=Container image ""busybox:musl"" already present on machine"
0.1131,Event,ADDED,eval-conflicts-rho020-r0-024-jw4mk.18d53ec8a692723b,reason=Created count=1 msg=Created container: task
0.1132,Event,ADDED,eval-conflicts-rho020-r0-024-jw4mk.18d53ec8abaeaa4a,reason=Started count=1 msg=Started container task
0.1134,Event,ADDED,eval-conflicts-rho020-r0-024.18d53ec88ad2f60c,reason=SuccessfulCreate count=1 msg=Created pod: eval-conflicts-rho020-r0-024-jw4mk
0.1136,Event,ADDED,eval-conflicts-rho020-r0-024.18d53ece38f0a72d,reason=Completed count=1 msg=Job completed
0.1138,Event,ADDED,eval-conflicts-rho020-r0-025-cr896.18d53ec8c652af52,reason=Scheduled count=None msg=Successfully assigned compute/eval-conflicts-rho020-r0-025-cr896 to kind-worker
0.1139,Event,ADDED,eval-conflicts-rho020-r0-025-cr896.18d53ec8df91ad74,"reason=Pulled count=1 msg=Container image ""busybox:musl"" already present on machine"
0.1141,Event,ADDED,eval-conflicts-rho020-r0-025-cr896.18d53ec8e0c419ee,reason=Created count=1 msg=Created container: task
0.1143,Event,ADDED,eval-conflicts-rho020-r0-025-cr896.18d53ec8e32659fb,reason=Started count=1 msg=Started container task
0.1145,Event,ADDED,eval-conflicts-rho020-r0-025.18d53ec8c5c4586f,reason=SuccessfulCreate count=1 msg=Created pod: eval-conflicts-rho020-r0-025-cr896
0.1147,Event,ADDED,eval-conflicts-rho020-r0-025.18d53ece74d71b37,reason=Completed count=1 msg=Job completed
0.1148,Event,ADDED,eval-conflicts-rho020-r0-026-jvszx.18d53ec902b25ccb,reason=Scheduled count=None msg=Successfully assigned compute/eval-conflicts-rho020-r0-026-jvszx to kind-worker
0.115,Event,ADDED,eval-conflicts-rho020-r0-026-jvszx.18d53ec91dda58af,"reason=Pulled count=1 msg=Container image ""busybox:musl"" already present on machine"
0.1152,Event,ADDED,eval-conflicts-rho020-r0-026-jvszx.18d53ec91efac3d1,reason=Created count=1 msg=Created container: task
0.1153,Event,ADDED,eval-conflicts-rho020-r0-026-jvszx.18d53ec923fde8c3,reason=Started count=1 msg=Started container task
0.1155,Event,ADDED,eval-conflicts-rho020-r0-026.18d53ec9022c83d6,reason=SuccessfulCreate count=1 msg=Created pod: eval-conflicts-rho020-r0-026-jvszx
0.1157,Event,ADDED,eval-conflicts-rho020-r0-026.18d53eceb0cf451b,reason=Completed count=1 msg=Job completed
0.1158,Event,ADDED,eval-conflicts-rho020-r0-027-bwsz2.18d53ec93e46fc91,reason=Scheduled count=None msg=Successfully assigned compute/eval-conflicts-rho020-r0-027-bwsz2 to kind-worker
0.1161,Event,ADDED,eval-conflicts-rho020-r0-027-bwsz2.18d53ec959bea0f9,"reason=Pulled count=1 msg=Container image ""busybox:musl"" already present on machine"
0.1174,Pod,MODIFIED,eval-conflicts-rho070-r2-000-bc5z5,phase=Pending node=kind-worker2
0.1179,Event,ADDED,eval-conflicts-rho020-r0-027-bwsz2.18d53ec95ad0cfa3,reason=Created count=1 msg=Created container: task
0.1181,Event,ADDED,eval-conflicts-rho020-r0-027-bwsz2.18d53ec96370e4a9,reason=Started count=1 msg=Started container task
0.1183,Event,ADDED,eval-conflicts-rho020-r0-027.18d53ec93daa0f9b,reason=SuccessfulCreate count=1 msg=Created pod: eval-conflicts-rho020-r0-027-bwsz2
0.1185,Event,ADDED,eval-conflicts-rho020-r0-027.18d53eceeccc389c,reason=Completed count=1 msg=Job completed
0.1188,Event,ADDED,eval-conflicts-rho020-r0-028-mg59f.18d53ec979da30e5,"reason=FailedScheduling count=None msg=0/6 nodes are available: 6 node(s) had untolerated taint(s). no new claims to deallocate, preemption: 0/6 nodes are available: 6 Preemption is not helpful for scheduling."
0.119,Event,ADDED,eval-conflicts-rho020-r0-028-mg59f.18d53ecaad8e6699,reason=Scheduled count=None msg=Successfully assigned compute/eval-conflicts-rho020-r0-028-mg59f to kind-worker3
0.1192,Event,ADDED,eval-conflicts-rho020-r0-028-mg59f.18d53ecaccdbc910,"reason=Pulled count=1 msg=Container image ""busybox:musl"" already present on machine"
0.1193,Event,ADDED,eval-conflicts-rho020-r0-028-mg59f.18d53ecaceda0137,reason=Created count=1 msg=Created container: task
0.1196,Event,ADDED,eval-conflicts-rho020-r0-028-mg59f.18d53ecad277ae3d,reason=Started count=1 msg=Started container task
0.1198,Event,ADDED,eval-conflicts-rho020-r0-028.18d53ec979c9e020,reason=SuccessfulCreate count=1 msg=Created pod: eval-conflicts-rho020-r0-028-mg59f
0.1199,Event,ADDED,eval-conflicts-rho020-r0-028.18d53ed06d255b0c,reason=Completed count=1 msg=Job completed
0.1202,Event,ADDED,eval-conflicts-rho020-r0-029-fc6x5.18d53ec9b4623a90,"reason=FailedScheduling count=None msg=0/6 nodes are available: 6 node(s) had untolerated taint(s). no new claims to deallocate, preemption: 0/6 nodes are available: 6 Preemption is not helpful for scheduling."
0.1204,Event,ADDED,eval-conflicts-rho020-r0-029-fc6x5.18d53ecaae4db409,reason=Scheduled count=None msg=Successfully assigned compute/eval-conflicts-rho020-r0-029-fc6x5 to kind-worker3
0.1207,Event,ADDED,eval-conflicts-rho020-r0-029-fc6x5.18d53ecacd78af15,"reason=Pulled count=1 msg=Container image ""busybox:musl"" already present on machine"
0.1209,Event,ADDED,eval-conflicts-rho020-r0-029-fc6x5.18d53ecacf351d5d,reason=Created count=1 msg=Created container: task
0.1212,Event,ADDED,eval-conflicts-rho020-r0-029-fc6x5.18d53ecad277ade8,reason=Started count=1 msg=Started container task
0.1214,Event,ADDED,eval-conflicts-rho020-r0-029.18d53ec9b45650ce,reason=SuccessfulCreate count=1 msg=Created pod: eval-conflicts-rho020-r0-029-fc6x5
0.1216,Event,ADDED,eval-conflicts-rho020-r0-029.18d53ed06d00a256,reason=Completed count=1 msg=Job completed
0.1222,Event,ADDED,eval-conflicts-rho020-r0-030-bmhxs.18d53ec9efa1d0fc,"reason=FailedScheduling count=None msg=0/6 nodes are available: 6 node(s) had untolerated taint(s). no new claims to deallocate, preemption: 0/6 nodes are available: 6 Preemption is not helpful for scheduling."
0.1224,Event,ADDED,eval-conflicts-rho020-r0-030-bmhxs.18d53ecaae6fe6a7,reason=Scheduled count=None msg=Successfully assigned compute/eval-conflicts-rho020-r0-030-bmhxs to kind-worker3
0.1226,Event,ADDED,eval-conflicts-rho020-r0-030-bmhxs.18d53ecada1f9e4b,"reason=Pulled count=1 msg=Container image ""busybox:musl"" already present on machine"
0.1228,Event,ADDED,eval-conflicts-rho020-r0-030-bmhxs.18d53ecadb24bac1,reason=Created count=1 msg=Created container: task
0.1232,Event,ADDED,eval-conflicts-rho020-r0-030-bmhxs.18d53ecaded8ea49,reason=Started count=1 msg=Started container task
0.1234,Event,ADDED,eval-conflicts-rho020-r0-030.18d53ec9ef91d3b1,reason=SuccessfulCreate count=1 msg=Created pod: eval-conflicts-rho020-r0-030-bmhxs
0.1236,Event,ADDED,eval-conflicts-rho020-r0-030.18d53ed06e6270a0,reason=Completed count=1 msg=Job completed
0.1237,Event,ADDED,eval-conflicts-rho020-r0-031-6szqg.18d53eca2b38b962,"reason=FailedScheduling count=None msg=0/6 nodes are available: 6 node(s) had untolerated taint(s). no new claims to deallocate, preemption: 0/6 nodes are available: 6 Preemption is not helpful for scheduling."
0.1241,Event,ADDED,eval-conflicts-rho020-r0-031-6szqg.18d53ecab0043f1a,"reason=FailedScheduling count=None msg=0/6 nodes are available: 1 c_wall violated: 2 conflicting context pair(s) with node memory, 5 node(s) had untolerated taint(s). no new claims to deallocate, preemption: 0/6 nodes are available: 1 No preemption victims found for incoming pod, 5 Preemption is not helpful for scheduling."
0.1243,Event,ADDED,eval-conflicts-rho020-r0-031-6szqg.18d53ecab5c688a1,"reason=FailedScheduling count=None msg=0/6 nodes are available: 1 c_wall violated: 2 conflicting context pair(s) with node memory, 5 node(s) had untolerated taint(s). no new claims to deallocate, preemption: 0/6 nodes are available: 1 No preemption victims found for incoming pod, 5 Preemption is not helpful for scheduling."
0.1245,Event,ADDED,eval-conflicts-rho020-r0-031-6szqg.18d53ecb99855f36,reason=Scheduled count=None msg=Successfully assigned compute/eval-conflicts-rho020-r0-031-6szqg to kind-worker2
0.1258,Node,MODIFIED,kind-worker2,taints=0
0.1261,Event,ADDED,eval-conflicts-rho020-r0-031-6szqg.18d53ecbb0eac182,"reason=Pulled count=1 msg=Container image ""busybox:musl"" already present on machine"
0.1263,Event,ADDED,eval-conflicts-rho020-r0-031-6szqg.18d53ecbb2938da2,reason=Created count=1 msg=Created container: task
0.1264,Event,ADDED,eval-conflicts-rho020-r0-031-6szqg.18d53ecbbaa5db4f,reason=Started count=1 msg=Started container task
0.1267,Event,ADDED,eval-conflicts-rho020-r0-031.18d53eca2b2bb038,reason=SuccessfulCreate count=1 msg=Created pod: eval-conflicts-rho020-r0-031-6szqg
0.1269,Event,ADDED,eval-conflicts-rho020-r0-031.18d53ed123b24f35,reason=Completed count=1 msg=Job completed
0.1271,Event,ADDED,eval-conflicts-rho020-r0-032-tlbkx.18d53eca66983984,"reason=FailedScheduling count=None msg=0/6 nodes are available: 6 node(s) had untolerated taint(s). no new claims to deallocate, preemption: 0/6 nodes are available: 6 Preemption is not helpful for scheduling."
0.1273,Event,ADDED,eval-conflicts-rho020-r0-032-tlbkx.18d53ecab0d059e4,reason=Scheduled count=None msg=Successfully assigned compute/eval-conflicts-rho020-r0-032-tlbkx to kind-worker3
0.1275,Event,ADDED,eval-conflicts-rho020-r0-032-tlbkx.18d53ecacbea91b1,"reason=Pulled count=1 msg=Container image ""busybox:musl"" already present on machine"
0.1277,Event,ADDED,eval-conflicts-rho020-r0-032-tlbkx.18d53ecacde32bee,reason=Created count=1 msg=Created container: task
0.1279,Event,ADDED,eval-conflicts-rho020-r0-032-tlbkx.18d53ecad204a0de,reason=Started count=1 msg=Started container task
0.1281,Event,ADDED,eval-conflicts-rho020-r0-032.18d53eca668b5b49,reason=SuccessfulCreate count=1 msg=Created pod: eval-conflicts-rho020-r0-032-tlbkx
0.1282,Event,ADDED,eval-conflicts-rho020-r0-032.18d53ed06dec7939,reason=Completed count=1 msg=Job completed
0.1284,Event,ADDED,eval-conflicts-rho020-r0-033-2x4h9.18d53ecaa2b17c76,"reason=FailedScheduling count=None msg=0/6 nodes are available: 6 node(s) had untolerated taint(s). no new claims to deallocate, preemption: 0/6 nodes are available: 6 Preemption is not helpful for scheduling."
0.1286,Event,ADDED,eval-conflicts-rho020-r0-033-2x4h9.18d53ecab0fc3f64,reason=Scheduled count=None msg=Successfully assigned compute/eval-conflicts-rho020-r0-033-2x4h9 to kind-worker3
0.1287,Event,ADDED,eval-conflicts-rho020-r0-033-2x4h9.18d53ecacbd681a5,"reason=Pulled count=1 msg=Container image ""busybox:musl"" already present on machine"
0.1289,Event,ADDED,eval-conflicts-rho020-r0-033-2x4h9.18d53ecacd7586a5,reason=Created count=1 msg=Created container: task
0.1291,Event,ADDED,eval-conflicts-rho020-r0-033-2x4h9.18d53ecad175c767,reason=Started count=1 msg=Started container task
0.1292,Event,ADDED,eval-conflicts-rho020-r0-033.18d53ecaa2a1d4b0,reason=SuccessfulCreate count=1 msg=Created pod: eval-conflicts-rho020-r0-033-2x4h9
0.1295,Event,ADDED,eval-conflicts-rho020-r0-033.18d53ed06d69e94c,reason=Completed count=1 msg=Job completed
0.1296,Event,ADDED,eval-conflicts-rho020-r0-034-xnnpf.18d53ecae0ad827b,"reason=FailedScheduling count=None msg=0/6 nodes are available: 1 c_wall violated: 1 conflicting context pair(s) with node memory, 5 node(s) had untolerated taint(s). no new claims to deallocate, preemption: 0/6 nodes are available: 1 No preemption victims found for incoming pod, 5 Preemption is not helpful for scheduling."
0.1298,Event,ADDED,eval-conflicts-rho020-r0-034-xnnpf.18d53ecae12b39d5,"reason=FailedScheduling count=None msg=0/6 nodes are available: 1 c_wall violated: 1 conflicting context pair(s) with node memory, 5 node(s) had untolerated taint(s). no new claims to deallocate, preemption: 0/6 nodes are available: 1 No preemption victims found for incoming pod, 5 Preemption is not helpful for scheduling."
0.13,Event,ADDED,eval-conflicts-rho020-r0-034-xnnpf.18d53ecb9c36f6e9,reason=Scheduled count=None msg=Successfully assigned compute/eval-conflicts-rho020-r0-034-xnnpf to kind-worker2
0.1301,Event,ADDED,eval-conflicts-rho020-r0-034-xnnpf.18d53ecbbaa97b80,"reason=Pulled count=1 msg=Container image ""busybox:musl"" already present on machine"
0.1303,Event,ADDED,eval-conflicts-rho020-r0-034-xnnpf.18d53ecbbc454cdf,reason=Created count=1 msg=Created container: task
0.1305,Event,ADDED,eval-conflicts-rho020-r0-034-xnnpf.18d53ecbc0699c17,reason=Started count=1 msg=Started container task
0.1307,Event,ADDED,eval-conflicts-rho020-r0-034.18d53ecae06bb3bc,reason=SuccessfulCreate count=1 msg=Created pod: eval-conflicts-rho020-r0-034-xnnpf
0.1309,Event,ADDED,eval-conflicts-rho020-r0-034.18d53ed12499f3dc,reason=Completed count=1 msg=Job completed
0.1311,Event,ADDED,eval-conflicts-rho020-r0-035-xfwqw.18d53ecb19e2f6f3,"reason=FailedScheduling count=None msg=0/6 nodes are available: 1 c_wall violated: 1 conflicting context pair(s) with node memory, 5 node(s) had untolerated taint(s). no new claims to deallocate, preemption: 0/6 nodes are available: 1 No preemption victims found for incoming pod, 5 Preemption is not helpful for scheduling."
0.1314,Event,ADDED,eval-conflicts-rho020-r0-035-xfwqw.18d53ecb1a56ece8,"reason=FailedScheduling count=None msg=0/6 nodes are available: 1 c_wall violated: 1 conflicting context pair(s) with node memory, 5 node(s) had untolerated taint(s). no new claims to deallocate, preemption: 0/6 nodes are available: 1 No preemption victims found for incoming pod, 5 Preemption is not helpful for scheduling."
0.1316,Event,ADDED,eval-conflicts-rho020-r0-035-xfwqw.18d53ecb9c982608,reason=Scheduled count=None msg=Successfully assigned compute/eval-conflicts-rho020-r0-035-xfwqw to kind-worker2
0.1317,Event,ADDED,eval-conflicts-rho020-r0-035-xfwqw.18d53ecbbb128f14,"reason=Pulled count=1 msg=Container image ""busybox:musl"" already present on machine"
0.1319,Event,ADDED,eval-conflicts-rho020-r0-035-xfwqw.18d53ecbbc849f8e,reason=Created count=1 msg=Created container: task
0.1321,Event,ADDED,eval-conflicts-rho020-r0-035-xfwqw.18d53ecbc0699c18,reason=Started count=1 msg=Started container task
0.1322,Event,ADDED,eval-conflicts-rho020-r0-035.18d53ecb19a416b4,reason=SuccessfulCreate count=1 msg=Created pod: eval-conflicts-rho020-r0-035-xfwqw
0.1324,Event,ADDED,eval-conflicts-rho020-r0-035.18d53ed123d259fb,reason=Completed count=1 msg=Job completed
0.1326,Event,ADDED,eval-conflicts-rho020-r0-036-8rhg4.18d53ecb55b3883a,reason=Scheduled count=None msg=Successfully assigned compute/eval-conflicts-rho020-r0-036-8rhg4 to kind-worker3
0.1327,Event,ADDED,eval-conflicts-rho020-r0-036-8rhg4.18d53ecb705ef2c3,"reason=Pulled count=1 msg=Container image ""busybox:musl"" already present on machine"
0.1329,Event,ADDED,eval-conflicts-rho020-r0-036-8rhg4.18d53ecb71716c27,reason=Created count=1 msg=Created container: task
0.1331,Event,ADDED,eval-conflicts-rho020-r0-036-8rhg4.18d53ecb753c8352,reason=Started count=1 msg=Started container task
0.1332,Event,ADDED,eval-conflicts-rho020-r0-036.18d53ecb552d3857,reason=SuccessfulCreate count=1 msg=Created pod: eval-conflicts-rho020-r0-036-8rhg4
0.1334,Event,ADDED,eval-conflicts-rho020-r0-036.18d53ed0e5d63cb2,reason=Completed count=1 msg=Job completed
0.1335,Event,ADDED,eval-conflicts-rho020-r0-037-sjfwx.18d53ecb91c70974,reason=Scheduled count=None msg=Successfully assigned compute/eval-conflicts-rho020-r0-037-sjfwx to kind-worker3
0.1337,Event,ADDED,eval-conflicts-rho020-r0-037-sjfwx.18d53ecbab58d639,"reason=Pulled count=1 msg=Container image ""busybox:musl"" already present on machine"
0.1339,Event,ADDED,eval-conflicts-rho020-r0-037-sjfwx.18d53ecbaca00a5f,reason=Created count=1 msg=Created container: task
0.1341,Event,ADDED,eval-conflicts-rho020-r0-037-sjfwx.18d53ecbaeb03d5e,reason=Started count=1 msg=Started container task
0.1343,Event,ADDED,eval-conflicts-rho020-r0-037.18d53ecb91308078,reason=SuccessfulCreate count=1 msg=Created pod: eval-conflicts-rho020-r0-037-sjfwx
0.1346,Event,ADDED,eval-conflicts-rho020-r0-037.18d53ed121fb21d9,reason=Completed count=1 msg=Job completed
0.1347,Event,ADDED,eval-conflicts-rho020-r0-038-jl5vt.18d53ecbcd4c988e,reason=Scheduled count=None msg=Successfully assigned compute/eval-conflicts-rho020-r0-038-jl5vt to kind-worker2
0.1349,Event,ADDED,eval-conflicts-rho020-r0-038-jl5vt.18d53ecbebc1fd06,"reason=Pulled count=1 msg=Container image ""busybox:musl"" already present on machine"
0.1353,Event,ADDED,eval-conflicts-rho020-r0-038-jl5vt.18d53ecbecfc87d6,reason=Created count=1 msg=Created container: task
0.1354,Event,ADDED,eval-conflicts-rho020-r0-038-jl5vt.18d53ecbf7857e2b,reason=Started count=1 msg=Started container task
0.1356,Event,ADDED,eval-conflicts-rho020-r0-038.18d53ecbcc9e1a74,reason=SuccessfulCreate count=1 msg=Created pod: eval-conflicts-rho020-r0-038-jl5vt
0.1358,Event,ADDED,eval-conflicts-rho020-r0-038.18d53ed15ff3de8b,reason=Completed count=1 msg=Job completed
0.1361,Event,ADDED,eval-conflicts-rho020-r0-039-mw5dn.18d53ecc08cd46e5,reason=Scheduled count=None msg=Successfully assigned compute/eval-conflicts-rho020-r0-039-mw5dn to kind-worker3
0.1363,Event,ADDED,eval-conflicts-rho020-r0-039-mw5dn.18d53ecc25331496,"reason=Pulled count=1 msg=Container image ""busybox:musl"" already present on machine"
0.1365,Event,ADDED,eval-conflicts-rho020-r0-039-mw5dn.18d53ecc26451250,reason=Created count=1 msg=Created container: task
0.1368,Event,ADDED,eval-conflicts-rho020-r0-039-mw5dn.18d53ecc299bdd42,reason=Started count=1 msg=Started container task
0.137,Event,ADDED,eval-conflicts-rho020-r0-039.18d53ecc081360b7,reason=SuccessfulCreate count=1 msg=Created pod: eval-conflicts-rho020-r0-039-mw5dn
0.1372,Event,ADDED,eval-conflicts-rho020-r0-039.18d53ed1997610d9,reason=Completed count=1 msg=Job completed
0.1374,Event,ADDED,eval-conflicts-rho020-r0-040-tm4p8.18d53ecc44e18cef,reason=Scheduled count=None msg=Successfully assigned compute/eval-conflicts-rho020-r0-040-tm4p8 to kind-worker3
0.1377,Event,ADDED,eval-conflicts-rho020-r0-040-tm4p8.18d53ecc63dd981b,"reason=Pulled count=1 msg=Container image ""busybox:musl"" already present on machine"
0.1379,Event,ADDED,eval-conflicts-rho020-r0-040-tm4p8.18d53ecc651777fc,reason=Created count=1 msg=Created container: task
0.138,Event,ADDED,eval-conflicts-rho020-r0-040-tm4p8.18d53ecc68f6c8a8,reason=Started count=1 msg=Started container task
0.1382,Event,ADDED,eval-conflicts-rho020-r0-040.18d53ecc441bc8ee,reason=SuccessfulCreate count=1 msg=Created pod: eval-conflicts-rho020-r0-040-tm4p8
0.1385,Event,ADDED,eval-conflicts-rho020-r0-040.18d53ed1d45d8329,reason=Completed count=1 msg=Job completed
0.1387,Event,ADDED,eval-conflicts-rho020-r0-041-sdkvs.18d53ecc7fd6b29b,reason=Scheduled count=None msg=Successfully assigned compute/eval-conflicts-rho020-r0-041-sdkvs to kind-worker2
0.1389,Event,ADDED,eval-conflicts-rho020-r0-041-sdkvs.18d53ecc9aac52b6,"reason=Pulled count=1 msg=Container image ""busybox:musl"" already present on machine"
0.1391,Event,ADDED,eval-conflicts-rho020-r0-041-sdkvs.18d53ecc9bba3522,reason=Created count=1 msg=Created container: task
0.1393,Event,ADDED,eval-conflicts-rho020-r0-041-sdkvs.18d53ecc9f87d146,reason=Started count=1 msg=Started container task
0.1394,Event,ADDED,eval-conflicts-rho020-r0-041.18d53ecc7f346014,reason=SuccessfulCreate count=1 msg=Created pod: eval-conflicts-rho020-r0-041-sdkvs
0.1396,Event,ADDED,eval-conflicts-rho020-r0-041.18d53ed213674522,reason=Completed count=1 msg=Job completed
0.1398,Event,ADDED,eval-conflicts-rho020-r0-042-4b8rw.18d53eccbb623464,reason=Scheduled count=None msg=Successfully assigned compute/eval-conflicts-rho020-r0-042-4b8rw to kind-worker3
0.1399,Event,ADDED,eval-conflicts-rho020-r0-042-4b8rw.18d53eccd4c112c9,"reason=Pulled count=1 msg=Container image ""busybox:musl"" already present on machine"
0.1401,Event,ADDED,eval-conflicts-rho020-r0-042-4b8rw.18d53eccd5d0e51a,reason=Created count=1 msg=Created container: task
0.1403,Event,ADDED,eval-conflicts-rho020-r0-042-4b8rw.18d53eccd7c1ce35,reason=Started count=1 msg=Started container task
0.1405,Event,ADDED,eval-conflicts-rho020-r0-042.18d53eccbab619d9,reason=SuccessfulCreate count=1 msg=Created pod: eval-conflicts-rho020-r0-042-4b8rw
0.1407,Event,ADDED,eval-conflicts-rho020-r0-042.18d53ed2534a2388,reason=Completed count=1 msg=Job completed
0.1409,Event,ADDED,eval-conflicts-rho020-r0-043-x8kh4.18d53eccf712b311,reason=Scheduled count=None msg=Successfully assigned compute/eval-conflicts-rho020-r0-043-x8kh4 to kind-worker2
0.141,Event,ADDED,eval-conflicts-rho020-r0-043-x8kh4.18d53ecd0f650c35,"reason=Pulled count=1 msg=Container image ""busybox:musl"" already present on machine"
0.1412,Event,ADDED,eval-conflicts-rho020-r0-043-x8kh4.18d53ecd107e177a,reason=Created count=1 msg=Created container: task
0.1414,Event,ADDED,eval-conflicts-rho020-r0-043-x8kh4.18d53ecd14f08ba1,reason=Started count=1 msg=Started container task
0.1415,Event,ADDED,eval-conflicts-rho020-r0-043.18d53eccf65e2ed3,reason=SuccessfulCreate count=1 msg=Created pod: eval-conflicts-rho020-r0-043-x8kh4
0.1417,Event,ADDED,eval-conflicts-rho020-r0-043.18d53ed28f0a726a,reason=Completed count=1 msg=Job completed
0.1419,Event,ADDED,eval-conflicts-rho020-r0-044-pfmjq.18d53ecd3292e2d8,reason=Scheduled count=None msg=Successfully assigned compute/eval-conflicts-rho020-r0-044-pfmjq to kind-worker3
0.142,Event,ADDED,eval-conflicts-rho020-r0-044-pfmjq.18d53ecd4bd78fd0,"reason=Pulled count=1 msg=Container image ""busybox:musl"" already present on machine"
0.1425,Event,ADDED,eval-conflicts-rho020-r0-044-pfmjq.18d53ecd4cef2ecf,reason=Created count=1 msg=Created container: task
0.143,Event,ADDED,eval-conflicts-rho020-r0-044-pfmjq.18d53ecd4f311e2e,reason=Started count=1 msg=Started container task
0.1434,Event,ADDED,eval-conflicts-rho020-r0-044.18d53ecd31f6752f,reason=SuccessfulCreate count=1 msg=Created pod: eval-conflicts-rho020-r0-044-pfmjq
0.1436,Event,ADDED,eval-conflicts-rho020-r0-044.18d53ed28f956b97,reason=Completed count=1 msg=Job completed
0.1439,Event,ADDED,eval-conflicts-rho020-r0-045-ht7g2.18d53ecd6f61d042,reason=Scheduled count=None msg=Successfully assigned compute/eval-conflicts-rho020-r0-045-ht7g2 to kind-worker5
0.1441,Event,ADDED,eval-conflicts-rho020-r0-045-ht7g2.18d53ecd90f58c5c,"reason=Pulled count=1 msg=Container image ""busybox:musl"" already present on machine"
0.1443,Event,ADDED,eval-conflicts-rho020-r0-045-ht7g2.18d53ecd9205de7d,reason=Created count=1 msg=Created container: task
0.1445,Event,ADDED,eval-conflicts-rho020-r0-045-ht7g2.18d53ecd95ad6b8f,reason=Started count=1 msg=Started container task
0.1454,Event,ADDED,eval-conflicts-rho020-r0-045.18d53ecd6e371428,reason=SuccessfulCreate count=1 msg=Created pod: eval-conflicts-rho020-r0-045-ht7g2
0.1459,Event,ADDED,eval-conflicts-rho020-r0-045.18d53ed3345d9332,reason=Completed count=1 msg=Job completed
0.1463,Event,ADDED,eval-conflicts-rho020-r0-046-zsfnt.18d53ecdaa0e6114,reason=Scheduled count=None msg=Successfully assigned compute/eval-conflicts-rho020-r0-046-zsfnt to kind-worker5
0.1468,Event,ADDED,eval-conflicts-rho020-r0-046-zsfnt.18d53ecdc2d8269d,"reason=Pulled count=1 msg=Container image ""busybox:musl"" already present on machine"
0.1473,Event,ADDED,eval-conflicts-rho020-r0-046-zsfnt.18d53ecdc40b36a9,reason=Created count=1 msg=Created container: task
0.1478,Event,ADDED,eval-conflicts-rho020-r0-046-zsfnt.18d53ecdc8c06b91,reason=Started count=1 msg=Started container task
0.1482,Event,ADDED,eval-conflicts-rho020-r0-046.18d53ecda91ecf44,reason=SuccessfulCreate count=1 msg=Created pod: eval-conflicts-rho020-r0-046-zsfnt
0.1485,Event,ADDED,eval-conflicts-rho020-r0-046.18d53ed3701b6cc7,reason=Completed count=1 msg=Job completed
0.1487,Event,ADDED,eval-conflicts-rho020-r0-047-8jpfs.18d53ecde6013b82,reason=Scheduled count=None msg=Successfully assigned compute/eval-conflicts-rho020-r0-047-8jpfs to kind-worker2
0.1489,Event,ADDED,eval-conflicts-rho020-r0-047-8jpfs.18d53ece051129d4,"reason=Pulled count=1 msg=Container image ""busybox:musl"" already present on machine"
0.1491,Event,ADDED,eval-conflicts-rho020-r0-047-8jpfs.18d53ece062e0ebc,reason=Created count=1 msg=Created container: task
0.1496,Event,ADDED,eval-conflicts-rho020-r0-047-8jpfs.18d53ece0aff0bdb,reason=Started count=1 msg=Started container task
0.1498,Event,ADDED,eval-conflicts-rho020-r0-047.18d53ecde4d6295b,reason=SuccessfulCreate count=1 msg=Created pod: eval-conflicts-rho020-r0-047-8jpfs
0.1499,Event,ADDED,eval-conflicts-rho020-r0-047.18d53ed3457e4aab,reason=Completed count=1 msg=Job completed
0.1501,Event,ADDED,eval-conflicts-rho020-r0-048-p2274.18d53ece218646f6,reason=Scheduled count=None msg=Successfully assigned compute/eval-conflicts-rho020-r0-048-p2274 to kind-worker3
0.1503,Event,ADDED,eval-conflicts-rho020-r0-048-p2274.18d53ece3f945e04,"reason=Pulled count=1 msg=Container image ""busybox:musl"" already present on machine"
0.1505,Event,ADDED,eval-conflicts-rho020-r0-048-p2274.18d53ece40b91cd2,reason=Created count=1 msg=Created container: task
0.1508,Event,ADDED,eval-conflicts-rho020-r0-048-p2274.18d53ece44c63208,reason=Started count=1 msg=Started container task
0.1512,Event,ADDED,eval-conflicts-rho020-r0-048.18d53ece2071d209,reason=SuccessfulCreate count=1 msg=Created pod: eval-conflicts-rho020-r0-048-p2274
0.1514,Event,ADDED,eval-conflicts-rho020-r0-048.18d53ed3bdc3f2eb,reason=Completed count=1 msg=Job completed
0.1516,Event,ADDED,eval-conflicts-rho020-r0-049-rbhhm.18d53ece5d078eb2,reason=Scheduled count=None msg=Successfully assigned compute/eval-conflicts-rho020-r0-049-rbhhm to kind-worker5
0.1519,Event,ADDED,eval-conflicts-rho020-r0-049-rbhhm.18d53ece765134a4,"reason=Pulled count=1 msg=Container image ""busybox:musl"" already present on machine"
0.1522,Event,ADDED,eval-conflicts-rho020-r0-049-rbhhm.18d53ece777d6e59,reason=Created count=1 msg=Created container: task
0.1523,Event,ADDED,eval-conflicts-rho020-r0-049-rbhhm.18d53ece79bf2058,reason=Started count=1 msg=Started container task
0.1525,Event,ADDED,eval-conflicts-rho020-r0-049.18d53ece5c14e45d,reason=SuccessfulCreate count=1 msg=Created pod: eval-conflicts-rho020-r0-049-rbhhm
0.1533,Event,ADDED,eval-conflicts-rho020-r0-049.18d53ed42057c483,reason=Completed count=1 msg=Job completed
0.1535,Event,ADDED,eval-conflicts-rho020-r0-050-jbfnr.18d53ece98f2ff10,reason=Scheduled count=None msg=Successfully assigned compute/eval-conflicts-rho020-r0-050-jbfnr to kind-worker2
0.1537,Event,ADDED,eval-conflicts-rho020-r0-050-jbfnr.18d53eceb2625fab,"reason=Pulled count=1 msg=Container image ""busybox:musl"" already present on machine"
0.1538,Event,ADDED,eval-conflicts-rho020-r0-050-jbfnr.18d53eceb3781995,reason=Created count=1 msg=Created container: task
0.1541,Event,ADDED,eval-conflicts-rho020-r0-050-jbfnr.18d53eceb900a12e,reason=Started count=1 msg=Started container task
0.1542,Event,ADDED,eval-conflicts-rho020-r0-050.18d53ece97ef6f43,reason=SuccessfulCreate count=1 msg=Created pod: eval-conflicts-rho020-r0-050-jbfnr
0.1544,Event,ADDED,eval-conflicts-rho020-r0-050.18d53ed3f5de4196,reason=Completed count=1 msg=Job completed
0.1546,Event,ADDED,eval-conflicts-rho020-r0-051-zdcdk.18d53eced495ef27,reason=Scheduled count=None msg=Successfully assigned compute/eval-conflicts-rho020-r0-051-zdcdk to kind-worker5
0.1548,Event,ADDED,eval-conflicts-rho020-r0-051-zdcdk.18d53eceed38b4f1,"reason=Pulled count=1 msg=Container image ""busybox:musl"" already present on machine"
0.1549,Event,ADDED,eval-conflicts-rho020-r0-051-zdcdk.18d53eceee72f06e,reason=Created count=1 msg=Created container: task
0.1551,Event,ADDED,eval-conflicts-rho020-r0-051-zdcdk.18d53ecef07efcfb,reason=Started count=1 msg=Started container task
0.1553,Event,ADDED,eval-conflicts-rho020-r0-051.18d53eced351d778,reason=SuccessfulCreate count=1 msg=Created pod: eval-conflicts-rho020-r0-051-zdcdk
0.1554,Event,ADDED,eval-conflicts-rho020-r0-051.18d53ed420ebe376,reason=Completed count=1 msg=Job completed
0.1556,Event,ADDED,eval-conflicts-rho020-r0-052-jr28w.18d53ecf102ecf61,reason=Scheduled count=None msg=Successfully assigned compute/eval-conflicts-rho020-r0-052-jr28w to kind-worker5
0.1558,Event,ADDED,eval-conflicts-rho020-r0-052-jr28w.18d53ecf28afed7b,"reason=Pulled count=1 msg=Container image ""busybox:musl"" already present on machine"
0.1562,Event,ADDED,eval-conflicts-rho020-r0-052-jr28w.18d53ecf29d2e726,reason=Created count=1 msg=Created container: task
0.1563,Event,ADDED,eval-conflicts-rho020-r0-052-jr28w.18d53ecf2bde4c1f,reason=Started count=1 msg=Started container task
0.1565,Event,ADDED,eval-conflicts-rho020-r0-052.18d53ecf0ef4fcee,reason=SuccessfulCreate count=1 msg=Created pod: eval-conflicts-rho020-r0-052-jr28w
0.1568,Event,ADDED,eval-conflicts-rho020-r0-052.18d53ed49e493862,reason=Completed count=1 msg=Job completed
0.157,Event,ADDED,eval-conflicts-rho020-r0-053-vw9tr.18d53ecf4c014e48,reason=Scheduled count=None msg=Successfully assigned compute/eval-conflicts-rho020-r0-053-vw9tr to kind-worker5
0.1572,Event,ADDED,eval-conflicts-rho020-r0-053-vw9tr.18d53ecf644f9f31,"reason=Pulled count=1 msg=Container image ""busybox:musl"" already present on machine"
0.1573,Event,ADDED,eval-conflicts-rho020-r0-053-vw9tr.18d53ecf65578b45,reason=Created count=1 msg=Created container: task
0.1576,Event,ADDED,eval-conflicts-rho020-r0-053-vw9tr.18d53ecf67732dfe,reason=Started count=1 msg=Started container task
0.1577,Event,ADDED,eval-conflicts-rho020-r0-053.18d53ecf4a9b8d79,reason=SuccessfulCreate count=1 msg=Created pod: eval-conflicts-rho020-r0-053-vw9tr
0.1579,Event,ADDED,eval-conflicts-rho020-r0-053.18d53ed4da12b51d,reason=Completed count=1 msg=Job completed
0.1581,Event,ADDED,eval-conflicts-rho020-r0-054-28xn9.18d53ecf86b6621b,reason=Scheduled count=None msg=Successfully assigned compute/eval-conflicts-rho020-r0-054-28xn9 to kind-worker5
0.1586,Event,ADDED,eval-conflicts-rho020-r0-054-28xn9.18d53ecfa0b11a8f,"reason=Pulled count=1 msg=Container image ""busybox:musl"" already present on machine"
0.1588,Event,ADDED,eval-conflicts-rho020-r0-054-28xn9.18d53ecfa24dce1b,reason=Created count=1 msg=Created container: task
0.159,Event,ADDED,eval-conflicts-rho020-r0-054-28xn9.18d53ecfa7154387,reason=Started count=1 msg=Started container task
0.1592,Event,ADDED,eval-conflicts-rho020-r0-054.18d53ecf8611077c,reason=SuccessfulCreate count=1 msg=Created pod: eval-conflicts-rho020-r0-054-28xn9
0.1594,Event,ADDED,eval-conflicts-rho020-r0-054.18d53ed554433722,reason=Completed count=1 msg=Job completed
0.1595,Event,ADDED,eval-conflicts-rho020-r0-055-tcpx2.18d53ecfc260c06d,"reason=FailedScheduling count=None msg=0/6 nodes are available: 2 c_wall violated: 1 conflicting context pair(s) with node memory, 4 node(s) had untolerated taint(s). no new claims to deallocate, preemption: 0/6 nodes are available: 2 No preemption victims found for incoming pod, 4 Preemption is not helpful for scheduling."
0.1598,Event,ADDED,eval-conflicts-rho020-r0-055-tcpx2.18d53ecfc31848f2,"reason=FailedScheduling count=None msg=0/6 nodes are available: 2 c_wall violated: 1 conflicting context pair(s) with node memory, 4 node(s) had untolerated taint(s). no new claims to deallocate, preemption: 0/6 nodes are available: 2 No preemption victims found for incoming pod, 4 Preemption is not helpful for scheduling."
0.16,Event,ADDED,eval-conflicts-rho020-r0-055-tcpx2.18d53ed0441cecbc,"reason=FailedScheduling count=None msg=0/6 nodes are available: 1 c_wall violated: 1 conflicting context pair(s) with node memory, 5 node(s) had untolerated taint(s). no new claims to deallocate, preemption: 0/6 nodes are available: 1 No preemption victims found for incoming pod, 5 Preemption is not helpful for scheduling."
0.1601,Event,ADDED,eval-conflicts-rho020-r0-055-tcpx2.18d53ed1af9f4ac0,"reason=FailedScheduling count=None msg=0/6 nodes are available: 2 c_wall violated: 1 conflicting context pair(s) with node memory, 4 node(s) had untolerated taint(s). no new claims to deallocate, preemption: 0/6 nodes are available: 2 No preemption victims found for incoming pod, 4 Preemption is not helpful for scheduling."
0.1603,Event,ADDED,eval-conflicts-rho020-r0-055-tcpx2.18d53ed1fc625459,"reason=FailedScheduling count=None msg=0/6 nodes are available: 1 c_wall violated: 1 conflicting context pair(s) with node memory, 5 node(s) had untolerated taint(s). no new claims to deallocate, preemption: 0/6 nodes are available: 1 No preemption victims found for incoming pod, 5 Preemption is not helpful for scheduling."
0.1605,Event,ADDED,eval-conflicts-rho020-r0-055-tcpx2.18d53ed2c1e73f69,reason=Scheduled count=None msg=Successfully assigned compute/eval-conflicts-rho020-r0-055-tcpx2 to kind-worker
0.1608,Event,ADDED,eval-conflicts-rho020-r0-055-tcpx2.18d53ed2e69b6183,"reason=Pulled count=1 msg=Container image ""busybox:musl"" already present on machine"
0.1609,Event,ADDED,eval-conflicts-rho020-r0-055-tcpx2.18d53ed2e9955bdd,reason=Created count=1 msg=Created container: task
0.1612,Event,ADDED,eval-conflicts-rho020-r0-055-tcpx2.18d53ed2f1859150,reason=Started count=1 msg=Started container task
0.1614,Event,ADDED,eval-conflicts-rho020-r0-055.18d53ecfc1ead18c,reason=SuccessfulCreate count=1 msg=Created pod: eval-conflicts-rho020-r0-055-tcpx2
0.1615,Event,ADDED,eval-conflicts-rho020-r0-055.18d53ed8967828cd,reason=Completed count=1 msg=Job completed
0.1618,Event,ADDED,eval-conflicts-rho020-r0-056-fr88w.18d53ecffea78682,"reason=FailedScheduling count=None msg=0/6 nodes are available: 2 c_wall violated: 1 conflicting context pair(s) with node memory, 4 node(s) had untolerated taint(s). no new claims to deallocate, preemption: 0/6 nodes are available: 2 No preemption victims found for incoming pod, 4 Preemption is not helpful for scheduling."
0.162,Event,ADDED,eval-conflicts-rho020-r0-056-fr88w.18d53ecfff776af1,"reason=FailedScheduling count=None msg=0/6 nodes are available: 2 c_wall violated: 1 conflicting context pair(s) with node memory, 4 node(s) had untolerated taint(s). no new claims to deallocate, preemption: 0/6 nodes are available: 2 No preemption victims found for incoming pod, 4 Preemption is not helpful for scheduling."
0.1622,Event,ADDED,eval-conflicts-rho020-r0-056-fr88w.18d53ed044444475,"reason=FailedScheduling count=None msg=0/6 nodes are available: 1 c_wall violated: 1 conflicting context pair(s) with node memory, 5 node(s) had untolerated taint(s). no new claims to deallocate, preemption: 0/6 nodes are available: 1 No preemption victims found for incoming pod, 5 Preemption is not helpful for scheduling."
0.1626,Event,ADDED,eval-conflicts-rho020-r0-056-fr88w.18d53ed1afe990c9,"reason=FailedScheduling count=None msg=0/6 nodes are available: 2 c_wall violated: 1 conflicting context pair(s) with node memory, 4 node(s) had untolerated taint(s). no new claims to deallocate, preemption: 0/6 nodes are available: 2 No preemption victims found for incoming pod, 4 Preemption is not helpful for scheduling."
0.1629,Event,ADDED,eval-conflicts-rho020-r0-056-fr88w.18d53ed1fc91c398,"reason=FailedScheduling count=None msg=0/6 nodes are available: 1 c_wall violated: 1 conflicting context pair(s) with node memory, 5 node(s) had untolerated taint(s). no new claims to deallocate, preemption: 0/6 nodes are available: 1 No preemption victims found for incoming pod, 5 Preemption is not helpful for scheduling."
0.163,Event,ADDED,eval-conflicts-rho020-r0-056-fr88w.18d53ed2c24444c7,reason=Scheduled count=None msg=Successfully assigned compute/eval-conflicts-rho020-r0-056-fr88w to kind-worker
0.1633,Event,ADDED,eval-conflicts-rho020-r0-056-fr88w.18d53ed2e6c11cde,"reason=Pulled count=1 msg=Container image ""busybox:musl"" already present on machine"
0.1635,Event,ADDED,eval-conflicts-rho020-r0-056-fr88w.18d53ed2e9d97d95,reason=Created count=1 msg=Created container: task
0.1637,Event,ADDED,eval-conflicts-rho020-r0-056-fr88w.18d53ed2f182e950,reason=Started count=1 msg=Started container task
0.1639,Event,ADDED,eval-conflicts-rho020-r0-056.18d53ecffe3f0bc3,reason=SuccessfulCreate count=1 msg=Created pod: eval-conflicts-rho020-r0-056-fr88w
0.1641,Event,ADDED,eval-conflicts-rho020-r0-056.18d53ed896a41457,reason=Completed count=1 msg=Job completed
0.1642,Event,ADDED,eval-conflicts-rho020-r0-057-rw46r.18d53ed03a8bc05d,reason=Scheduled count=None msg=Successfully assigned compute/eval-conflicts-rho020-r0-057-rw46r to kind-worker5
0.1644,Event,ADDED,eval-conflicts-rho020-r0-057-rw46r.18d53ed05339217e,"reason=Pulled count=1 msg=Container image ""busybox:musl"" already present on machine"
0.1647,Event,ADDED,eval-conflicts-rho020-r0-057-rw46r.18d53ed0544a80bb,reason=Created count=1 msg=Created container: task
0.1649,Event,ADDED,eval-conflicts-rho020-r0-057-rw46r.18d53ed056f1c05c,reason=Started count=1 msg=Started container task
0.1651,Event,ADDED,eval-conflicts-rho020-r0-057.18d53ed039b73651,reason=SuccessfulCreate count=1 msg=Created pod: eval-conflicts-rho020-r0-057-rw46r
0.1652,Event,ADDED,eval-conflicts-rho020-r0-057.18d53ed5cac0f3c2,reason=Completed count=1 msg=Job completed
0.1654,Event,ADDED,eval-conflicts-rho020-r0-058-8hszd.18d53ed0796c5235,"reason=FailedScheduling count=None msg=0/6 nodes are available: 1 c_wall violated: 1 conflicting context pair(s) with node memory, 5 node(s) had untolerated taint(s). no new claims to deallocate, preemption: 0/6 nodes are available: 1 No preemption victims found for incoming pod, 5 Preemption is not helpful for scheduling."
0.1656,Event,ADDED,eval-conflicts-rho020-r0-058-8hszd.18d53ed079eaca18,"reason=FailedScheduling count=None msg=0/6 nodes are available: 1 c_wall violated: 1 conflicting context pair(s) with node memory, 5 node(s) had untolerated taint(s). no new claims to deallocate, preemption: 0/6 nodes are available: 1 No preemption victims found for incoming pod, 5 Preemption is not helpful for scheduling."
0.1658,Event,ADDED,eval-conflicts-rho020-r0-058-8hszd.18d53ed1a5e09bbc,reason=Scheduled count=None msg=Successfully assigned compute/eval-conflicts-rho020-r0-058-8hszd to kind-worker4
0.166,Event,ADDED,eval-conflicts-rho020-r0-058-8hszd.18d53ed1c49a5521,"reason=Pulled count=1 msg=Container image ""busybox:musl"" already present on machine"
0.1661,Event,ADDED,eval-conflicts-rho020-r0-058-8hszd.18d53ed1c5df12ab,reason=Created count=1 msg=Created container: task
0.1666,Event,ADDED,eval-conflicts-rho020-r0-058-8hszd.18d53ed1ca8ccfc6,reason=Started count=1 msg=Started container task
0.1667,Event,ADDED,eval-conflicts-rho020-r0-058.18d53ed07931bc06,reason=SuccessfulCreate count=1 msg=Created pod: eval-conflicts-rho020-r0-058-8hszd
0.1669,Event,ADDED,eval-conflicts-rho020-r0-058.18d53ed6fe1f4bf7,reason=Completed count=1 msg=Job completed
0.1671,Event,ADDED,eval-conflicts-rho020-r0-059-b2x49.18d53ed0b21c889a,reason=Scheduled count=None msg=Successfully assigned compute/eval-conflicts-rho020-r0-059-b2x49 to kind-worker5
0.1672,Event,ADDED,eval-conflicts-rho020-r0-059-b2x49.18d53ed0cf912d67,"reason=Pulled count=1 msg=Container image ""busybox:musl"" already present on machine"
0.1674,Event,ADDED,eval-conflicts-rho020-r0-059-b2x49.18d53ed0d0a85843,reason=Created count=1 msg=Created container: task
0.1676,Event,ADDED,eval-conflicts-rho020-r0-059-b2x49.18d53ed0d664dce8,reason=Started count=1 msg=Started container task
0.1677,Event,ADDED,eval-conflicts-rho020-r0-059.18d53ed0b165d4a5,reason=SuccessfulCreate count=1 msg=Created pod: eval-conflicts-rho020-r0-059-b2x49
0.1679,Event,ADDED,eval-conflicts-rho020-r0-059.18d53ed63c9e1a17,reason=Completed count=1 msg=Job completed
0.1681,Event,ADDED,eval-conflicts-rho020-r0-060-l2mvv.18d53ed0ee4e52c4,reason=Scheduled count=None msg=Successfully assigned compute/eval-conflicts-rho020-r0-060-l2mvv to kind-worker5
0.1682,Event,ADDED,eval-conflicts-rho020-r0-060-l2mvv.18d53ed1094969f5,"reason=Pulled count=1 msg=Container image ""busybox:musl"" already present on machine"
0.1684,Event,ADDED,eval-conflicts-rho020-r0-060-l2mvv.18d53ed10a647ba8,reason=Created count=1 msg=Created container: task
0.1686,Event,ADDED,eval-conflicts-rho020-r0-060-l2mvv.18d53ed10f0e0991,reason=Started count=1 msg=Started container task
0.1689,Event,ADDED,eval-conflicts-rho020-r0-060.18d53ed0edbe3b0a,reason=SuccessfulCreate count=1 msg=Created pod: eval-conflicts-rho020-r0-060-l2mvv
0.1691,Event,ADDED,eval-conflicts-rho020-r0-060.18d53ed6b6e0e7cd,reason=Completed count=1 msg=Job completed
0.1693,Event,ADDED,eval-conflicts-rho020-r0-061-v5hwc.18d53ed130463793,reason=Scheduled count=None msg=Successfully assigned compute/eval-conflicts-rho020-r0-061-v5hwc to kind-worker5
0.1699,Event,ADDED,eval-conflicts-rho020-r0-061-v5hwc.18d53ed1495edaee,"reason=Pulled count=1 msg=Container image ""busybox:musl"" already present on machine"
0.1701,Event,ADDED,eval-conflicts-rho020-r0-061-v5hwc.18d53ed14a762f76,reason=Created count=1 msg=Created container: task
0.1703,Event,ADDED,eval-conflicts-rho020-r0-061-v5hwc.18d53ed14f90ba65,reason=Started count=1 msg=Started container task
0.1705,Event,ADDED,eval-conflicts-rho020-r0-061.18d53ed12f8ccf0e,reason=SuccessfulCreate count=1 msg=Created pod: eval-conflicts-rho020-r0-061-v5hwc
0.1708,Event,ADDED,eval-conflicts-rho020-r0-061.18d53ed6f28c2b82,reason=Completed count=1 msg=Job completed
0.171,Event,ADDED,eval-conflicts-rho020-r0-062-4gj9b.18d53ed164da4d78,"reason=FailedScheduling count=None msg=0/6 nodes are available: 1 c_wall violated: 2 conflicting context pair(s) with node memory, 5 node(s) had untolerated taint(s). no new claims to deallocate, preemption: 0/6 nodes are available: 1 No preemption victims found for incoming pod, 5 Preemption is not helpful for scheduling."
0.1712,Event,ADDED,eval-conflicts-rho020-r0-062-4gj9b.18d53ed16571c2ae,"reason=FailedScheduling count=None msg=0/6 nodes are available: 1 c_wall violated: 2 conflicting context pair(s) with node memory, 5 node(s) had untolerated taint(s). no new claims to deallocate, preemption: 0/6 nodes are available: 1 No preemption victims found for incoming pod, 5 Preemption is not helpful for scheduling."
0.1715,Event,ADDED,eval-conflicts-rho020-r0-062-4gj9b.18d53ed1aae67522,reason=Scheduled count=None msg=Successfully assigned compute/eval-conflicts-rho020-r0-062-4gj9b to kind-worker4
0.1717,Event,ADDED,eval-conflicts-rho020-r0-062-4gj9b.18d53ed1ca90f725,"reason=Pulled count=1 msg=Container image ""busybox:musl"" already present on machine"
0.1718,Event,ADDED,eval-conflicts-rho020-r0-062-4gj9b.18d53ed1cc3a1a7a,reason=Created count=1 msg=Created container: task
0.172,Event,ADDED,eval-conflicts-rho020-r0-062-4gj9b.18d53ed1d2ca0cf2,reason=Started count=1 msg=Started container task
0.1723,Event,ADDED,eval-conflicts-rho020-r0-062.18d53ed163127e94,reason=SuccessfulCreate count=1 msg=Created pod: eval-conflicts-rho020-r0-062-4gj9b
0.1728,Event,ADDED,eval-conflicts-rho020-r0-062.18d53ed7700afb73,reason=Completed count=1 msg=Job completed
0.1729,Event,ADDED,eval-conflicts-rho020-r0-063-pzxxx.18d53ed19f3527d6,"reason=FailedScheduling count=None msg=0/6 nodes are available: 1 c_wall violated: 1 conflicting context pair(s) with node memory, 5 node(s) had untolerated taint(s). no new claims to deallocate, preemption: 0/6 nodes are available: 1 No preemption victims found for incoming pod, 5 Preemption is not helpful for scheduling."
0.1733,Event,ADDED,eval-conflicts-rho020-r0-063-pzxxx.18d53ed19fb8bf9f,"reason=FailedScheduling count=None msg=0/6 nodes are available: 1 c_wall violated: 1 conflicting context pair(s) with node memory, 5 node(s) had untolerated taint(s). no new claims to deallocate, preemption: 0/6 nodes are available: 1 No preemption victims found for incoming pod, 5 Preemption is not helpful for scheduling."
0.1735,Event,ADDED,eval-conflicts-rho020-r0-063-pzxxx.18d53ed1b0d28f46,reason=Scheduled count=None msg=Successfully assigned compute/eval-conflicts-rho020-r0-063-pzxxx to kind-worker4
0.1737,Event,ADDED,eval-conflicts-rho020-r0-063-pzxxx.18d53ed1cb104c8e,"reason=Pulled count=1 msg=Container image ""busybox:musl"" already present on machine"
0.174,Event,ADDED,eval-conflicts-rho020-r0-063-pzxxx.18d53ed1ccc29f36,reason=Created count=1 msg=Created container: task
0.1741,Event,ADDED,eval-conflicts-rho020-r0-063-pzxxx.18d53ed1d2c98463,reason=Started count=1 msg=Started container task
0.1743,Event,ADDED,eval-conflicts-rho020-r0-063.18d53ed19ef1a2c9,reason=SuccessfulCreate count=1 msg=Created pod: eval-conflicts-rho020-r0-063-pzxxx
0.1745,Event,ADDED,eval-conflicts-rho020-r0-063.18d53ed7700ae204,reason=Completed count=1 msg=Job completed
0.1748,Event,ADDED,eval-conflicts-rho020-r0-064-rdcqs.18d53ed1df5c5db0,reason=Scheduled count=None msg=Successfully assigned compute/eval-conflicts-rho020-r0-064-rdcqs to kind-worker5
0.175,Event,ADDED,eval-conflicts-rho020-r0-064-rdcqs.18d53ed1fa1fe8bc,"reason=Pulled count=1 msg=Container image ""busybox:musl"" already present on machine"
0.1752,Event,ADDED,eval-conflicts-rho020-r0-064-rdcqs.18d53ed1fc5c423e,reason=Created count=1 msg=Created container: task
0.1753,Event,ADDED,eval-conflicts-rho020-r0-064-rdcqs.18d53ed201c7ce72,reason=Started count=1 msg=Started container task
0.1755,Event,ADDED,eval-conflicts-rho020-r0-064.18d53ed1de5c6ecd,reason=SuccessfulCreate count=1 msg=Created pod: eval-conflicts-rho020-r0-064-rdcqs
0.1757,Event,ADDED,eval-conflicts-rho020-r0-064.18d53ed7b1117702,reason=Completed count=1 msg=Job completed
0.1759,Event,ADDED,eval-conflicts-rho020-r0-065-7vgfr.18d53ed21629d523,"reason=FailedScheduling count=None msg=0/6 nodes are available: 1 c_wall violated: 1 conflicting context pair(s) with node memory, 5 node(s) had untolerated taint(s). no new claims to deallocate, preemption: 0/6 nodes are available: 1 No preemption victims found for incoming pod, 5 Preemption is not helpful for scheduling."
0.1761,Event,ADDED,eval-conflicts-rho020-r0-065-7vgfr.18d53ed216ee7ab2,"reason=FailedScheduling count=None msg=0/6 nodes are available: 1 c_wall violated: 1 conflicting context pair(s) with node memory, 5 node(s) had untolerated taint(s). no new claims to deallocate, preemption: 0/6 nodes are available: 1 No preemption victims found for incoming pod, 5 Preemption is not helpful for scheduling."
0.1762,Event,ADDED,eval-conflicts-rho020-r0-065-7vgfr.18d53ed2c2d43a8e,reason=Scheduled count=None msg=Successfully assigned compute/eval-conflicts-rho020-r0-065-7vgfr to kind-worker
0.1764,Event,ADDED,eval-conflicts-rho020-r0-065-7vgfr.18d53ed2e6ecc55e,"reason=Pulled count=1 msg=Container image ""busybox:musl"" already present on machine"
0.1767,Event,ADDED,eval-conflicts-rho020-r0-065-7vgfr.18d53ed2e9f45d1d,reason=Created count=1 msg=Created container: task
0.1769,Event,ADDED,eval-conflicts-rho020-r0-065-7vgfr.18d53ed2f18353e6,reason=Started count=1 msg=Started container task
0.177,Event,ADDED,eval-conflicts-rho020-r0-065.18d53ed215e4593f,reason=SuccessfulCreate count=1 msg=Created pod: eval-conflicts-rho020-r0-065-7vgfr
0.1773,Event,ADDED,eval-conflicts-rho020-r0-065.18d53ed896a37464,reason=Completed count=1 msg=Job completed
0.1776,Event,ADDED,eval-conflicts-rho020-r0-066-k8vzz.18d53ed2551d8985,"reason=FailedScheduling count=None msg=0/6 nodes are available: 1 c_wall violated: 1 conflicting context pair(s) with node memory, 5 node(s) had untolerated taint(s). no new claims to deallocate, preemption: 0/6 nodes are available: 1 No preemption victims found for incoming pod, 5 Preemption is not helpful for scheduling."
0.1778,Event,ADDED,eval-conflicts-rho020-r0-066-k8vzz.18d53ed255af5e1c,"reason=FailedScheduling count=None msg=0/6 nodes are available: 1 c_wall violated: 1 conflicting context pair(s) with node memory, 5 node(s) had untolerated taint(s). no new claims to deallocate, preemption: 0/6 nodes are available: 1 No preemption victims found for incoming pod, 5 Preemption is not helpful for scheduling."
0.1779,Event,ADDED,eval-conflicts-rho020-r0-066-k8vzz.18d53ed2ca491e0f,reason=Scheduled count=None msg=Successfully assigned compute/eval-conflicts-rho020-r0-066-k8vzz to kind-worker
0.1781,Event,ADDED,eval-conflicts-rho020-r0-066-k8vzz.18d53ed2f1875bba,"reason=Pulled count=1 msg=Container image ""busybox:musl"" already present on machine"
0.1783,Event,ADDED,eval-conflicts-rho020-r0-066-k8vzz.18d53ed2f336365c,reason=Created count=1 msg=Created container: task
0.1785,Event,ADDED,eval-conflicts-rho020-r0-066-k8vzz.18d53ed2fab3e59b,reason=Started count=1 msg=Started container task
0.1786,Event,ADDED,eval-conflicts-rho020-r0-066.18d53ed254d81746,reason=SuccessfulCreate count=1 msg=Created pod: eval-conflicts-rho020-r0-066-k8vzz
0.1788,Event,ADDED,eval-conflicts-rho020-r0-066.18d53ed896a28889,reason=Completed count=1 msg=Job completed
0.1789,Event,ADDED,eval-conflicts-rho020-r0-067-t5qbj.18d53ed2909584f5,reason=Scheduled count=None msg=Successfully assigned compute/eval-conflicts-rho020-r0-067-t5qbj to kind-worker4
0.1791,Event,ADDED,eval-conflicts-rho020-r0-067-t5qbj.18d53ed2af4903de,"reason=Pulled count=1 msg=Container image ""busybox:musl"" already present on machine"
0.1793,Event,ADDED,eval-conflicts-rho020-r0-067-t5qbj.18d53ed2b08c49d9,reason=Created count=1 msg=Created container: task
0.1795,Event,ADDED,eval-conflicts-rho020-r0-067-t5qbj.18d53ed2b8fb0d03,reason=Started count=1 msg=Started container task
0.1796,Event,ADDED,eval-conflicts-rho020-r0-067.18d53ed28ffe2641,reason=SuccessfulCreate count=1 msg=Created pod: eval-conflicts-rho020-r0-067-t5qbj
0.1798,Event,ADDED,eval-conflicts-rho020-r0-067.18d53ed82d0fee07,reason=Completed count=1 msg=Job completed
0.1801,Event,ADDED,eval-conflicts-rho020-r0-068-hdclg.18d53ed2cce2feac,reason=Scheduled count=None msg=Successfully assigned compute/eval-conflicts-rho020-r0-068-hdclg to kind-worker4
0.1802,Event,ADDED,eval-conflicts-rho020-r0-068-hdclg.18d53ed2f153aa8c,"reason=Pulled count=1 msg=Container image ""busybox:musl"" already present on machine"
0.1804,Event,ADDED,eval-conflicts-rho020-r0-068-hdclg.18d53ed2f31fd7ac,reason=Created count=1 msg=Created container: task
0.1806,Event,ADDED,eval-conflicts-rho020-r0-068-hdclg.18d53ed2fab00497,reason=Started count=1 msg=Started container task
0.1808,Event,ADDED,eval-conflicts-rho020-r0-068.18d53ed2cbc517cf,reason=SuccessfulCreate count=1 msg=Created pod: eval-conflicts-rho020-r0-068-hdclg
0.1809,Event,ADDED,eval-conflicts-rho020-r0-068.18d53ed899199106,reason=Completed count=1 msg=Job completed
0.1811,Event,ADDED,eval-conflicts-rho020-r0-069-x67vn.18d53ed30886b223,reason=Scheduled count=None msg=Successfully assigned compute/eval-conflicts-rho020-r0-069-x67vn to kind-worker
0.1815,Event,ADDED,eval-conflicts-rho020-r0-069-x67vn.18d53ed333cfd796,"reason=Pulled count=1 msg=Container image ""busybox:musl"" already present on machine"
0.1817,Event,ADDED,eval-conflicts-rho020-r0-069-x67vn.18d53ed3354151c6,reason=Created count=1 msg=Created container: task
0.1819,Event,ADDED,eval-conflicts-rho020-r0-069-x67vn.18d53ed344aa3903,reason=Started count=1 msg=Started container task
0.1821,Event,ADDED,eval-conflicts-rho020-r0-069.18d53ed3079b9bc3,reason=SuccessfulCreate count=1 msg=Created pod: eval-conflicts-rho020-r0-069-x67vn
0.1824,Event,ADDED,eval-conflicts-rho020-r0-069.18d53ed8bdfaa647,reason=Completed count=1 msg=Job completed
0.1825,Event,ADDED,eval-conflicts-rho020-r0-070-fx47n.18d53ed34746f5c5,reason=Scheduled count=None msg=Successfully assigned compute/eval-conflicts-rho020-r0-070-fx47n to kind-worker4
0.1827,Event,ADDED,eval-conflicts-rho020-r0-070-fx47n.18d53ed36b2953fa,"reason=Pulled count=1 msg=Container image ""busybox:musl"" already present on machine"
0.1829,Event,ADDED,eval-conflicts-rho020-r0-070-fx47n.18d53ed36c407b7b,reason=Created count=1 msg=Created container: task
0.1832,Event,ADDED,eval-conflicts-rho020-r0-070-fx47n.18d53ed36e3248c8,reason=Started count=1 msg=Started container task
0.1834,Event,ADDED,eval-conflicts-rho020-r0-070.18d53ed3465d0ea9,reason=SuccessfulCreate count=1 msg=Created pod: eval-conflicts-rho020-r0-070-fx47n
0.1835,Event,ADDED,eval-conflicts-rho020-r0-070.18d53ed89945831f,reason=Completed count=1 msg=Job completed
0.1839,Event,ADDED,eval-conflicts-rho020-r0-071-kp96t.18d53ed37bfc9298,"reason=FailedScheduling count=None msg=0/6 nodes are available: 1 c_wall violated: 1 conflicting context pair(s) with node memory, 1 c_wall violated: 2 conflicting context pair(s) with node memory, 4 node(s) had untolerated taint(s). no new claims to deallocate, preemption: 0/6 nodes are available: 2 No preemption victims found for incoming pod, 4 Preemption is not helpful for scheduling."
0.1841,Event,ADDED,eval-conflicts-rho020-r0-071-kp96t.18d53ed37c9a7d7e,"reason=FailedScheduling count=None msg=0/6 nodes are available: 1 c_wall violated: 1 conflicting context pair(s) with node memory, 1 c_wall violated: 2 conflicting context pair(s) with node memory, 4 node(s) had untolerated taint(s). no new claims to deallocate, preemption: 0/6 nodes are available: 2 No preemption victims found for incoming pod, 4 Preemption is not helpful for scheduling."
0.1842,Event,ADDED,eval-conflicts-rho020-r0-071-kp96t.18d53ed4157e22a5,reason=Scheduled count=None msg=Successfully assigned compute/eval-conflicts-rho020-r0-071-kp96t to kind-worker3
0.1848,Event,ADDED,eval-conflicts-rho020-r0-071-kp96t.18d53ed432447422,"reason=Pulled count=1 msg=Container image ""busybox:musl"" already present on machine"
0.1849,Event,ADDED,eval-conflicts-rho020-r0-071-kp96t.18d53ed43402139d,reason=Created count=1 msg=Created container: task
0.1851,Event,ADDED,eval-conflicts-rho020-r0-071-kp96t.18d53ed43e4067d6,reason=Started count=1 msg=Started container task
0.1853,Event,ADDED,eval-conflicts-rho020-r0-071.18d53ed37b963d92,reason=SuccessfulCreate count=1 msg=Created pod: eval-conflicts-rho020-r0-071-kp96t
0.1855,Event,ADDED,eval-conflicts-rho020-r0-071.18d53ed9ca1dc5a2,reason=Completed count=1 msg=Job completed
0.1857,Event,ADDED,eval-conflicts-rho020-r0-072-825vc.18d53ed3bbae23d8,reason=Scheduled count=None msg=Successfully assigned compute/eval-conflicts-rho020-r0-072-825vc to kind-worker4
0.1858,Event,ADDED,eval-conflicts-rho020-r0-072-825vc.18d53ed3df5b6317,"reason=Pulled count=1 msg=Container image ""busybox:musl"" already present on machine"
0.186,Event,ADDED,eval-conflicts-rho020-r0-072-825vc.18d53ed3e0aadb64,reason=Created count=1 msg=Created container: task
0.1863,Event,ADDED,eval-conflicts-rho020-r0-072-825vc.18d53ed3ea225faf,reason=Started count=1 msg=Started container task
0.1865,Event,ADDED,eval-conflicts-rho020-r0-072.18d53ed3bb05eea5,reason=SuccessfulCreate count=1 msg=Created pod: eval-conflicts-rho020-r0-072-825vc
0.1866,Event,ADDED,eval-conflicts-rho020-r0-072.18d53ed98d2d83c5,reason=Completed count=1 msg=Job completed
0.1869,Event,ADDED,eval-conflicts-rho020-r0-073-gqgh4.18d53ed3f66f5e97,reason=Scheduled count=None msg=Successfully assigned compute/eval-conflicts-rho020-r0-073-gqgh4 to kind-worker
0.1871,Event,ADDED,eval-conflicts-rho020-r0-073-gqgh4.18d53ed412e7afbb,"reason=Pulled count=1 msg=Container image ""busybox:musl"" already present on machine"
0.1873,Event,ADDED,eval-conflicts-rho020-r0-073-gqgh4.18d53ed41418ade9,reason=Created count=1 msg=Created container: task
0.1875,Event,ADDED,eval-conflicts-rho020-r0-073-gqgh4.18d53ed4163ea3a3,reason=Started count=1 msg=Started container task
0.1877,Event,ADDED,eval-conflicts-rho020-r0-073.18d53ed3f5ba5274,reason=SuccessfulCreate count=1 msg=Created pod: eval-conflicts-rho020-r0-073-gqgh4
0.1879,Event,ADDED,eval-conflicts-rho020-r0-073.18d53ed9b8198845,reason=Completed count=1 msg=Job completed
0.188,Event,ADDED,eval-conflicts-rho020-r0-074-d87bq.18d53ed43524b833,reason=Scheduled count=None msg=Successfully assigned compute/eval-conflicts-rho020-r0-074-d87bq to kind-worker3
0.1882,Event,ADDED,eval-conflicts-rho020-r0-074-d87bq.18d53ed4539b124a,"reason=Pulled count=1 msg=Container image ""busybox:musl"" already present on machine"
0.1884,Event,ADDED,eval-conflicts-rho020-r0-074-d87bq.18d53ed454c0575c,reason=Created count=1 msg=Created container: task
0.1885,Event,ADDED,eval-conflicts-rho020-r0-074-d87bq.18d53ed45e7f7bd4,reason=Started count=1 msg=Started container task
0.1887,Event,ADDED,eval-conflicts-rho020-r0-074.18d53ed4341a46c6,reason=SuccessfulCreate count=1 msg=Created pod: eval-conflicts-rho020-r0-074-d87bq
0.1889,Event,ADDED,eval-conflicts-rho020-r0-074.18d53ed9c960bb94,reason=Completed count=1 msg=Job completed
0.189,Event,ADDED,eval-conflicts-rho020-r0-075-29wch.18d53ed4736cf056,reason=Scheduled count=None msg=Successfully assigned compute/eval-conflicts-rho020-r0-075-29wch to kind-worker4
0.1892,Event,ADDED,eval-conflicts-rho020-r0-075-29wch.18d53ed49264a29e,"reason=Pulled count=1 msg=Container image ""busybox:musl"" already present on machine"
0.1894,Event,ADDED,eval-conflicts-rho020-r0-075-29wch.18d53ed49380f005,reason=Created count=1 msg=Created container: task
0.1896,Event,ADDED,eval-conflicts-rho020-r0-075-29wch.18d53ed49dcbcb84,reason=Started count=1 msg=Started container task
0.1897,Event,ADDED,eval-conflicts-rho020-r0-075.18d53ed472066b14,reason=SuccessfulCreate count=1 msg=Created pod: eval-conflicts-rho020-r0-075-29wch
0.1899,Event,ADDED,eval-conflicts-rho020-r0-075.18d53ed9c8be6a91,reason=Completed count=1 msg=Job completed
0.19,Event,ADDED,eval-conflicts-rho020-r0-076-p5wrc.18d53ed4a87fc2ae,reason=Scheduled count=None msg=Successfully assigned compute/eval-conflicts-rho020-r0-076-p5wrc to kind-worker3
0.1902,Event,ADDED,eval-conflicts-rho020-r0-076-p5wrc.18d53ed4ca674b97,"reason=Pulled count=1 msg=Container image ""busybox:musl"" already present on machine"
0.1904,Event,ADDED,eval-conflicts-rho020-r0-076-p5wrc.18d53ed4cb95dc8e,reason=Created count=1 msg=Created container: task
0.1905,Event,ADDED,eval-conflicts-rho020-r0-076-p5wrc.18d53ed4d49caee8,reason=Started count=1 msg=Started container task
0.1908,Event,ADDED,eval-conflicts-rho020-r0-076.18d53ed4a757021d,reason=SuccessfulCreate count=1 msg=Created pod: eval-conflicts-rho020-r0-076-p5wrc
0.191,Event,ADDED,eval-conflicts-rho020-r0-076.18d53eda049d063a,reason=Completed count=1 msg=Job completed
0.1913,Event,ADDED,eval-conflicts-rho020-r0-077-q4s9r.18d53ed4e714a916,reason=Scheduled count=None msg=Successfully assigned compute/eval-conflicts-rho020-r0-077-q4s9r to kind-worker3
0.1916,Event,ADDED,eval-conflicts-rho020-r0-077-q4s9r.18d53ed5075af422,"reason=Pulled count=1 msg=Container image ""busybox:musl"" already present on machine"
0.1918,Event,ADDED,eval-conflicts-rho020-r0-077-q4s9r.18d53ed508724730,reason=Created count=1 msg=Created container: task
0.1919,Event,ADDED,eval-conflicts-rho020-r0-077-q4s9r.18d53ed5128b00bd,reason=Started count=1 msg=Started container task
0.1921,Event,ADDED,eval-conflicts-rho020-r0-077.18d53ed4e5fc42cd,reason=SuccessfulCreate count=1 msg=Created pod: eval-conflicts-rho020-r0-077-q4s9r
0.1924,Event,ADDED,eval-conflicts-rho020-r0-077.18d53eda406b8714,reason=Completed count=1 msg=Job completed
0.1926,Event,ADDED,eval-conflicts-rho020-r0-078-4jk75.18d53ed522256695,reason=Scheduled count=None msg=Successfully assigned compute/eval-conflicts-rho020-r0-078-4jk75 to kind-worker2
0.1927,Event,ADDED,eval-conflicts-rho020-r0-078-4jk75.18d53ed54104dfca,"reason=Pulled count=1 msg=Container image ""busybox:musl"" already present on machine"
0.1929,Event,ADDED,eval-conflicts-rho020-r0-078-4jk75.18d53ed5421c74e8,reason=Created count=1 msg=Created container: task
0.1931,Event,ADDED,eval-conflicts-rho020-r0-078-4jk75.18d53ed54be60614,reason=Started count=1 msg=Started container task
0.1933,Event,ADDED,eval-conflicts-rho020-r0-078.18d53ed520f137db,reason=SuccessfulCreate count=1 msg=Created pod: eval-conflicts-rho020-r0-078-4jk75
0.1934,Event,ADDED,eval-conflicts-rho020-r0-078.18d53edab7fc77c9,reason=Completed count=1 msg=Job completed
0.1936,Event,ADDED,eval-conflicts-rho020-r0-079-dxtsk.18d53ed559d70f19,reason=Scheduled count=None msg=Successfully assigned compute/eval-conflicts-rho020-r0-079-dxtsk to kind-worker2
0.1938,Event,ADDED,eval-conflicts-rho020-r0-079-dxtsk.18d53ed57eb99551,"reason=Pulled count=1 msg=Container image ""busybox:musl"" already present on machine"
0.1939,Event,ADDED,eval-conflicts-rho020-r0-079-dxtsk.18d53ed57fe2439c,reason=Created count=1 msg=Created container: task
0.1941,Event,ADDED,eval-conflicts-rho020-r0-079-dxtsk.18d53ed587f18e79,reason=Started count=1 msg=Started container task
0.1943,Event,ADDED,eval-conflicts-rho020-r0-079.18d53ed55878a414,reason=SuccessfulCreate count=1 msg=Created pod: eval-conflicts-rho020-r0-079-dxtsk
0.1945,Event,ADDED,eval-conflicts-rho020-r0-079.18d53edaf3f1eb9b,reason=Completed count=1 msg=Job completed
0.1946,Event,ADDED,eval-conflicts-rho020-r0-080-ks878.18d53ed595736d4e,reason=Scheduled count=None msg=Successfully assigned compute/eval-conflicts-rho020-r0-080-ks878 to kind-worker2
0.1948,Event,ADDED,eval-conflicts-rho020-r0-080-ks878.18d53ed5bb55ec4e,"reason=Pulled count=1 msg=Container image ""busybox:musl"" already present on machine"
0.195,Event,ADDED,eval-conflicts-rho020-r0-080-ks878.18d53ed5bc8c5648,reason=Created count=1 msg=Created container: task
0.1952,Event,ADDED,eval-conflicts-rho020-r0-080-ks878.18d53ed5ca75b74f,reason=Started count=1 msg=Started container task
0.1954,Event,ADDED,eval-conflicts-rho020-r0-080.18d53ed5940c98cd,reason=SuccessfulCreate count=1 msg=Created pod: eval-conflicts-rho020-r0-080-ks878
0.1958,Event,ADDED,eval-conflicts-rho020-r0-080.18d53edaf49f9401,reason=Completed count=1 msg=Job completed
0.196,Event,ADDED,eval-conflicts-rho020-r0-081-m5mvk.18d53ed5d4a66a03,reason=Scheduled count=None msg=Successfully assigned compute/eval-conflicts-rho020-r0-081-m5mvk to kind-worker2
0.1963,Event,ADDED,eval-conflicts-rho020-r0-081-m5mvk.18d53ed5f474f524,"reason=Pulled count=1 msg=Container image ""busybox:musl"" already present on machine"
0.1965,Event,ADDED,eval-conflicts-rho020-r0-081-m5mvk.18d53ed5f580a635,reason=Created count=1 msg=Created container: task
0.1967,Event,ADDED,eval-conflicts-rho020-r0-081-m5mvk.18d53ed5fbe2fa63,reason=Started count=1 msg=Started container task
0.1969,Event,ADDED,eval-conflicts-rho020-r0-081.18d53ed5d3477545,reason=SuccessfulCreate count=1 msg=Created pod: eval-conflicts-rho020-r0-081-m5mvk
0.1973,Event,ADDED,eval-conflicts-rho020-r0-081.18d53edb76585366,reason=Completed count=1 msg=Job completed
0.1975,Event,ADDED,eval-conflicts-rho020-r0-082-t86qn.18d53ed60c326d31,reason=Scheduled count=None msg=Successfully assigned compute/eval-conflicts-rho020-r0-082-t86qn to kind-worker2
0.1977,Event,ADDED,eval-conflicts-rho020-r0-082-t86qn.18d53ed62acfb975,"reason=Pulled count=1 msg=Container image ""busybox:musl"" already present on machine"
0.1981,Event,ADDED,eval-conflicts-rho020-r0-082-t86qn.18d53ed62bd6e92b,reason=Created count=1 msg=Created container: task
0.1983,Event,ADDED,eval-conflicts-rho020-r0-082-t86qn.18d53ed632a3d0be,reason=Started count=1 msg=Started container task
0.1984,Event,ADDED,eval-conflicts-rho020-r0-082.18d53ed60adf5a40,reason=SuccessfulCreate count=1 msg=Created pod: eval-conflicts-rho020-r0-082-t86qn
0.1986,Event,ADDED,eval-conflicts-rho020-r0-082.18d53edbb7205f54,reason=Completed count=1 msg=Job completed
0.1988,Event,ADDED,eval-conflicts-rho020-r0-083-z6jfp.18d53ed64ab2762a,reason=Scheduled count=None msg=Successfully assigned compute/eval-conflicts-rho020-r0-083-z6jfp to kind-worker
0.199,Event,ADDED,eval-conflicts-rho020-r0-083-z6jfp.18d53ed6770e932d,"reason=Pulled count=1 msg=Container image ""busybox:musl"" already present on machine"
0.1992,Event,ADDED,eval-conflicts-rho020-r0-083-z6jfp.18d53ed678808a64,reason=Created count=1 msg=Created container: task
0.1995,Event,ADDED,eval-conflicts-rho020-r0-083-z6jfp.18d53ed6823d8c41,reason=Started count=1 msg=Started container task
0.1997,Event,ADDED,eval-conflicts-rho020-r0-083.18d53ed6498044d2,reason=SuccessfulCreate count=1 msg=Created pod: eval-conflicts-rho020-r0-083-z6jfp
0.1999,Event,ADDED,eval-conflicts-rho020-r0-083.18d53edc0920f69f,reason=Completed count=1 msg=Job completed
0.2001,Event,ADDED,eval-conflicts-rho020-r0-084-nt2rs.18d53ed6854b0b68,reason=Scheduled count=None msg=Successfully assigned compute/eval-conflicts-rho020-r0-084-nt2rs to kind-worker3
0.2003,Event,ADDED,eval-conflicts-rho020-r0-084-nt2rs.18d53ed6c22d6a21,"reason=Pulled count=1 msg=Container image ""busybox:musl"" already present on machine"
0.2005,Event,ADDED,eval-conflicts-rho020-r0-084-nt2rs.18d53ed6c37e14fb,reason=Created count=1 msg=Created container: task
0.2007,Event,ADDED,eval-conflicts-rho020-r0-084-nt2rs.18d53ed6c80f7c66,reason=Started count=1 msg=Started container task
0.2009,Event,ADDED,eval-conflicts-rho020-r0-084.18d53ed684386124,reason=SuccessfulCreate count=1 msg=Created pod: eval-conflicts-rho020-r0-084-nt2rs
0.2012,Event,ADDED,eval-conflicts-rho020-r0-084.18d53edc66933697,reason=Completed count=1 msg=Job completed
0.2013,Event,ADDED,eval-conflicts-rho020-r0-085-p96ws.18d53ed6c423a79c,reason=Scheduled count=None msg=Successfully assigned compute/eval-conflicts-rho020-r0-085-p96ws to kind-worker3
0.2015,Event,ADDED,eval-conflicts-rho020-r0-085-p96ws.18d53ed6e30c748e,"reason=Pulled count=1 msg=Container image ""busybox:musl"" already present on machine"
0.2019,Event,ADDED,eval-conflicts-rho020-r0-085-p96ws.18d53ed6e4244ada,reason=Created count=1 msg=Created container: task
0.2021,Event,ADDED,eval-conflicts-rho020-r0-085-p96ws.18d53ed6ea4227bc,reason=Started count=1 msg=Started container task
0.2023,Event,ADDED,eval-conflicts-rho020-r0-085.18d53ed6c2ee3a25,reason=SuccessfulCreate count=1 msg=Created pod: eval-conflicts-rho020-r0-085-p96ws
0.2024,Event,ADDED,eval-conflicts-rho020-r0-085.18d53edc66b2ae53,reason=Completed count=1 msg=Job completed
0.2028,Event,ADDED,eval-conflicts-rho020-r0-086-j9tlt.18d53ed705295252,reason=Scheduled count=None msg=Successfully assigned compute/eval-conflicts-rho020-r0-086-j9tlt to kind-worker2
0.2032,Event,ADDED,eval-conflicts-rho020-r0-086-j9tlt.18d53ed72336c0a4,"reason=Pulled count=1 msg=Container image ""busybox:musl"" already present on machine"
0.2033,Event,ADDED,eval-conflicts-rho020-r0-086-j9tlt.18d53ed724936ff5,reason=Created count=1 msg=Created container: task
0.2036,Event,ADDED,eval-conflicts-rho020-r0-086-j9tlt.18d53ed72e8fcc55,reason=Started count=1 msg=Started container task
0.2039,Event,ADDED,eval-conflicts-rho020-r0-086.18d53ed6fd87885d,reason=SuccessfulCreate count=1 msg=Created pod: eval-conflicts-rho020-r0-086-j9tlt
0.2042,Event,ADDED,eval-conflicts-rho020-r0-086.18d53edca4de2590,reason=Completed count=1 msg=Job completed
0.2044,Event,ADDED,eval-conflicts-rho020-r0-087-qxpdz.18d53ed739798523,reason=Scheduled count=None msg=Successfully assigned compute/eval-conflicts-rho020-r0-087-qxpdz to kind-worker3
0.2047,Event,ADDED,eval-conflicts-rho020-r0-087-qxpdz.18d53ed757359c33,"reason=Pulled count=1 msg=Container image ""busybox:musl"" already present on machine"
0.2048,Event,ADDED,eval-conflicts-rho020-r0-087-qxpdz.18d53ed7584649fd,reason=Created count=1 msg=Created container: task
0.205,Event,ADDED,eval-conflicts-rho020-r0-087-qxpdz.18d53ed76341b1d2,reason=Started count=1 msg=Started container task
0.2052,Event,ADDED,eval-conflicts-rho020-r0-087.18d53ed73848a02f,reason=SuccessfulCreate count=1 msg=Created pod: eval-conflicts-rho020-r0-087-qxpdz
0.2055,Event,ADDED,eval-conflicts-rho020-r0-087.18d53edc95d531fa,reason=Completed count=1 msg=Job completed
0.2057,Event,ADDED,eval-conflicts-rho020-r0-088-lxcjz.18d53ed771dcf64e,"reason=FailedScheduling count=None msg=0/6 nodes are available: 1 c_wall violated: 1 conflicting context pair(s) with node memory, 1 c_wall violated: 2 conflicting context pair(s) with node memory, 4 node(s) had untolerated taint(s). no new claims to deallocate, preemption: 0/6 nodes are available: 2 No preemption victims found for incoming pod, 4 Preemption is not helpful for scheduling."
0.2059,Event,ADDED,eval-conflicts-rho020-r0-088-lxcjz.18d53ed7728db722,"reason=FailedScheduling count=None msg=0/6 nodes are available: 1 c_wall violated: 1 conflicting context pair(s) with node memory, 1 c_wall violated: 2 conflicting context pair(s) with node memory, 4 node(s) had untolerated taint(s). no new claims to deallocate, preemption: 0/6 nodes are available: 2 No preemption victims found for incoming pod, 4 Preemption is not helpful for scheduling."
0.2061,Event,ADDED,eval-conflicts-rho020-r0-088-lxcjz.18d53ed8c01172b3,"reason=FailedScheduling count=None msg=0/6 nodes are available: 1 c_wall violated: 1 conflicting context pair(s) with node memory, 5 node(s) had untolerated taint(s). no new claims to deallocate, preemption: 0/6 nodes are available: 1 No preemption victims found for incoming pod, 5 Preemption is not helpful for scheduling."
0.2062,Event,ADDED,eval-conflicts-rho020-r0-088-lxcjz.18d53edb13f13ec2,reason=Scheduled count=None msg=Successfully assigned compute/eval-conflicts-rho020-r0-088-lxcjz to kind-worker4
0.2064,Event,ADDED,eval-conflicts-rho020-r0-088-lxcjz.18d53edb3939d464,"reason=Pulled count=1 msg=Container image ""busybox:musl"" already present on machine"
0.2066,Event,ADDED,eval-conflicts-rho020-r0-088-lxcjz.18d53edb440094fb,reason=Created count=1 msg=Created container: task
0.2068,Event,ADDED,eval-conflicts-rho020-r0-088-lxcjz.18d53edb48e0d7fb,reason=Started count=1 msg=Started container task
0.2069,Event,ADDED,eval-conflicts-rho020-r0-088.18d53ed771711050,reason=SuccessfulCreate count=1 msg=Created pod: eval-conflicts-rho020-r0-088-lxcjz
0.2071,Event,ADDED,eval-conflicts-rho020-r0-088.18d53ee120d1dba5,reason=Completed count=1 msg=Job completed
0.2073,Event,ADDED,eval-conflicts-rho020-r0-089-p45ln.18d53ed7b375fa7f,"reason=FailedScheduling count=None msg=0/6 nodes are available: 1 c_wall violated: 1 conflicting context pair(s) with node memory, 1 c_wall violated: 2 conflicting context pair(s) with node memory, 4 node(s) had untolerated taint(s). no new claims to deallocate, preemption: 0/6 nodes are available: 2 No preemption victims found for incoming pod, 4 Preemption is not helpful for scheduling."
0.2075,Event,ADDED,eval-conflicts-rho020-r0-089-p45ln.18d53ed7b7030d26,"reason=FailedScheduling count=None msg=0/6 nodes are available: 1 c_wall violated: 1 conflicting context pair(s) with node memory, 1 c_wall violated: 2 conflicting context pair(s) with node memory, 4 node(s) had untolerated taint(s). no new claims to deallocate, preemption: 0/6 nodes are available: 2 No preemption victims found for incoming pod, 4 Preemption is not helpful for scheduling."
0.2077,Event,ADDED,eval-conflicts-rho020-r0-089-p45ln.18d53ed8c03c2546,"reason=FailedScheduling count=None msg=0/6 nodes are available: 1 c_wall violated: 1 conflicting context pair(s) with node memory, 5 node(s) had untolerated taint(s). no new claims to deallocate, preemption: 0/6 nodes are available: 1 No preemption victims found for incoming pod, 5 Preemption is not helpful for scheduling."
0.2078,Event,ADDED,eval-conflicts-rho020-r0-089-p45ln.18d53edb0e8ebfdf,reason=Scheduled count=None msg=Successfully assigned compute/eval-conflicts-rho020-r0-089-p45ln to kind-worker4
0.208,Event,ADDED,eval-conflicts-rho020-r0-089-p45ln.18d53edb2aecba95,"reason=Pulled count=1 msg=Container image ""busybox:musl"" already present on machine"
0.2082,Event,ADDED,eval-conflicts-rho020-r0-089-p45ln.18d53edb2d7c0407,reason=Created count=1 msg=Created container: task
0.2083,Event,ADDED,eval-conflicts-rho020-r0-089-p45ln.18d53edb38b6584b,reason=Started count=1 msg=Started container task
0.2085,Event,ADDED,eval-conflicts-rho020-r0-089.18d53ed7b2f5f40b,reason=SuccessfulCreate count=1 msg=Created pod: eval-conflicts-rho020-r0-089-p45ln
0.2087,Event,ADDED,eval-conflicts-rho020-r0-089.18d53ee0c940d8a0,reason=Completed count=1 msg=Job completed
0.2088,Event,ADDED,eval-conflicts-rho020-r0-090-p7nl6.18d53ed7eae1bf0d,reason=Scheduled count=None msg=Successfully assigned compute/eval-conflicts-rho020-r0-090-p7nl6 to kind-worker3
0.209,Event,ADDED,eval-conflicts-rho020-r0-090-p7nl6.18d53ed80791f330,"reason=Pulled count=1 msg=Container image ""busybox:musl"" already present on machine"
0.2092,Event,ADDED,eval-conflicts-rho020-r0-090-p7nl6.18d53ed808dc9f67,reason=Created count=1 msg=Created container: task
0.2093,Event,ADDED,eval-conflicts-rho020-r0-090-p7nl6.18d53ed81388637a,reason=Started count=1 msg=Started container task
0.2095,Event,ADDED,eval-conflicts-rho020-r0-090.18d53ed7e8c58494,reason=SuccessfulCreate count=1 msg=Created pod: eval-conflicts-rho020-r0-090-p7nl6
0.2097,Event,ADDED,eval-conflicts-rho020-r0-090.18d53edd46380f27,reason=Completed count=1 msg=Job completed
0.2098,Event,ADDED,eval-conflicts-rho020-r0-091-zdlzb.18d53ed83b40c918,reason=Scheduled count=None msg=Successfully assigned compute/eval-conflicts-rho020-r0-091-zdlzb to kind-worker3
0.21,Event,ADDED,eval-conflicts-rho020-r0-091-zdlzb.18d53ed85c85540c,"reason=Pulled count=1 msg=Container image ""busybox:musl"" already present on machine"
0.2102,Event,ADDED,eval-conflicts-rho020-r0-091-zdlzb.18d53ed85ded42f9,reason=Created count=1 msg=Created container: task
0.2103,Event,ADDED,eval-conflicts-rho020-r0-091-zdlzb.18d53ed862baa93c,reason=Started count=1 msg=Started container task
0.2105,Event,ADDED,eval-conflicts-rho020-r0-091.18d53ed82e2d4558,reason=SuccessfulCreate count=1 msg=Created pod: eval-conflicts-rho020-r0-091-zdlzb
0.2106,Event,ADDED,eval-conflicts-rho020-r0-091.18d53eddf976e7f3,reason=Completed count=1 msg=Job completed
0.2108,Event,ADDED,eval-conflicts-rho020-r0-092-s5vdf.18d53ed862298da8,reason=Scheduled count=None msg=Successfully assigned compute/eval-conflicts-rho020-r0-092-s5vdf to kind-worker2
0.211,Event,ADDED,eval-conflicts-rho020-r0-092-s5vdf.18d53ed880d365f0,"reason=Pulled count=1 msg=Container image ""busybox:musl"" already present on machine"
0.2111,Event,ADDED,eval-conflicts-rho020-r0-092-s5vdf.18d53ed882565361,reason=Created count=1 msg=Created container: task
0.2113,Event,ADDED,eval-conflicts-rho020-r0-092-s5vdf.18d53ed8898aad06,reason=Started count=1 msg=Started container task
0.2115,Event,ADDED,eval-conflicts-rho020-r0-092.18d53ed85fd2b379,reason=SuccessfulCreate count=1 msg=Created pod: eval-conflicts-rho020-r0-092-s5vdf
0.2117,Event,ADDED,eval-conflicts-rho020-r0-092.18d53eddfb9b2920,reason=Completed count=1 msg=Job completed
0.2119,Event,ADDED,eval-conflicts-rho020-r0-093-nqqh9.18d53ed8ab517096,reason=Scheduled count=None msg=Successfully assigned compute/eval-conflicts-rho020-r0-093-nqqh9 to kind-worker3
0.212,Event,ADDED,eval-conflicts-rho020-r0-093-nqqh9.18d53ed8e1c46e92,"reason=Pulled count=1 msg=Container image ""busybox:musl"" already present on machine"
0.2123,Event,ADDED,eval-conflicts-rho020-r0-093-nqqh9.18d53ed8e32677b3,reason=Created count=1 msg=Created container: task
0.2126,Event,ADDED,eval-conflicts-rho020-r0-093-nqqh9.18d53ed8ee2b2b72,reason=Started count=1 msg=Started container task
0.2128,Event,ADDED,eval-conflicts-rho020-r0-093.18d53ed8aa803076,reason=SuccessfulCreate count=1 msg=Created pod: eval-conflicts-rho020-r0-093-nqqh9
0.2132,Event,ADDED,eval-conflicts-rho020-r0-093.18d53ede710f4f64,reason=Completed count=1 msg=Job completed
0.2133,Event,ADDED,eval-conflicts-rho020-r0-094-7zlr9.18d53ed8d790c988,"reason=FailedScheduling count=None msg=0/6 nodes are available: 1 c_wall violated: 1 conflicting context pair(s) with node memory, 5 node(s) had untolerated taint(s). no new claims to deallocate, preemption: 0/6 nodes are available: 1 No preemption victims found for incoming pod, 5 Preemption is not helpful for scheduling."
0.2135,Event,ADDED,eval-conflicts-rho020-r0-094-7zlr9.18d53ed8d831ed2f,"reason=FailedScheduling count=None msg=0/6 nodes are available: 1 c_wall violated: 1 conflicting context pair(s) with node memory, 5 node(s) had untolerated taint(s). no new claims to deallocate, preemption: 0/6 nodes are available: 1 No preemption victims found for incoming pod, 5 Preemption is not helpful for scheduling."
0.2138,Event,ADDED,eval-conflicts-rho020-r0-094-7zlr9.18d53edb0fcc8e15,reason=Scheduled count=None msg=Successfully assigned compute/eval-conflicts-rho020-r0-094-7zlr9 to kind-worker4
0.214,Event,ADDED,eval-conflicts-rho020-r0-094-7zlr9.18d53edb3749b24f,"reason=Pulled count=1 msg=Container image ""busybox:musl"" already present on machine"
0.2142,Event,ADDED,eval-conflicts-rho020-r0-094-7zlr9.18d53edb3cef0f2c,reason=Created count=1 msg=Created container: task
0.2145,Event,ADDED,eval-conflicts-rho020-r0-094-7zlr9.18d53edb43886c15,reason=Started count=1 msg=Started container task
0.2147,Event,ADDED,eval-conflicts-rho020-r0-094.18d53ed8d7512738,reason=SuccessfulCreate count=1 msg=Created pod: eval-conflicts-rho020-r0-094-7zlr9
0.2149,Event,ADDED,eval-conflicts-rho020-r0-094.18d53ee0c9b1251e,reason=Completed count=1 msg=Job completed
0.215,Event,ADDED,eval-conflicts-rho020-r0-095-sqmml.18d53ed91aa9398d,"reason=FailedScheduling count=None msg=0/6 nodes are available: 1 c_wall violated: 1 conflicting context pair(s) with node memory, 5 node(s) had untolerated taint(s). no new claims to deallocate, preemption: 0/6 nodes are available: 1 No preemption victims found for incoming pod, 5 Preemption is not helpful for scheduling."
0.2156,Event,ADDED,eval-conflicts-rho020-r0-095-sqmml.18d53ed926cfbd1a,"reason=FailedScheduling count=None msg=0/6 nodes are available: 1 c_wall violated: 1 conflicting context pair(s) with node memory, 5 node(s) had untolerated taint(s). no new claims to deallocate, preemption: 0/6 nodes are available: 1 No preemption victims found for incoming pod, 5 Preemption is not helpful for scheduling."
0.2158,Event,ADDED,eval-conflicts-rho020-r0-095-sqmml.18d53edb0f2fdff6,reason=Scheduled count=None msg=Successfully assigned compute/eval-conflicts-rho020-r0-095-sqmml to kind-worker4
0.216,Event,ADDED,eval-conflicts-rho020-r0-095-sqmml.18d53edb37ab0f66,"reason=Pulled count=1 msg=Container image ""busybox:musl"" already present on machine"
0.2163,Event,ADDED,eval-conflicts-rho020-r0-095-sqmml.18d53edb3d504a41,reason=Created count=1 msg=Created container: task
0.2165,Event,ADDED,eval-conflicts-rho020-r0-095-sqmml.18d53edb4383db52,reason=Started count=1 msg=Started container task
0.2167,Event,ADDED,eval-conflicts-rho020-r0-095.18d53ed9169e61bb,reason=SuccessfulCreate count=1 msg=Created pod: eval-conflicts-rho020-r0-095-sqmml
0.2169,Event,ADDED,eval-conflicts-rho020-r0-095.18d53ee0c9534588,reason=Completed count=1 msg=Job completed
0.2173,Event,ADDED,eval-conflicts-rho020-r0-096-vdfw5.18d53ed94f2023a3,"reason=FailedScheduling count=None msg=0/6 nodes are available: 1 c_wall violated: 2 conflicting context pair(s) with node memory, 5 node(s) had untolerated taint(s). no new claims to deallocate, preemption: 0/6 nodes are available: 1 No preemption victims found for incoming pod, 5 Preemption is not helpful for scheduling."
0.2175,Event,ADDED,eval-conflicts-rho020-r0-096-vdfw5.18d53ed94fb2ac6c,"reason=FailedScheduling count=None msg=0/6 nodes are available: 1 c_wall violated: 2 conflicting context pair(s) with node memory, 5 node(s) had untolerated taint(s). no new claims to deallocate, preemption: 0/6 nodes are available: 1 No preemption victims found for incoming pod, 5 Preemption is not helpful for scheduling."
0.2176,Event,ADDED,eval-conflicts-rho020-r0-096-vdfw5.18d53edb0fa65b70,reason=Scheduled count=None msg=Successfully assigned compute/eval-conflicts-rho020-r0-096-vdfw5 to kind-worker4
0.2178,Event,ADDED,eval-conflicts-rho020-r0-096-vdfw5.18d53edb37d68e43,"reason=Pulled count=1 msg=Container image ""busybox:musl"" already present on machine"
0.218,Event,ADDED,eval-conflicts-rho020-r0-096-vdfw5.18d53edb3dcae098,reason=Created count=1 msg=Created container: task
0.2182,Event,ADDED,eval-conflicts-rho020-r0-096-vdfw5.18d53edb43846d8f,reason=Started count=1 msg=Started container task
0.2183,Event,ADDED,eval-conflicts-rho020-r0-096.18d53ed94eece142,reason=SuccessfulCreate count=1 msg=Created pod: eval-conflicts-rho020-r0-096-vdfw5
0.2185,Event,ADDED,eval-conflicts-rho020-r0-096.18d53ee090a112c4,reason=Completed count=1 msg=Job completed
0.2187,Event,ADDED,eval-conflicts-rho020-r0-097-tzb86.18d53ed98a025b04,"reason=FailedScheduling count=None msg=0/6 nodes are available: 1 c_wall violated: 1 conflicting context pair(s) with node memory, 5 node(s) had untolerated taint(s). no new claims to deallocate, preemption: 0/6 nodes are available: 1 No preemption victims found for incoming pod, 5 Preemption is not helpful for scheduling."
0.2189,Event,ADDED,eval-conflicts-rho020-r0-097-tzb86.18d53ed98ddbbf40,"reason=FailedScheduling count=None msg=0/6 nodes are available: 1 c_wall violated: 1 conflicting context pair(s) with node memory, 5 node(s) had untolerated taint(s). no new claims to deallocate, preemption: 0/6 nodes are available: 1 No preemption victims found for incoming pod, 5 Preemption is not helpful for scheduling."
0.219,Event,ADDED,eval-conflicts-rho020-r0-097-tzb86.18d53edb144b0780,reason=Scheduled count=None msg=Successfully assigned compute/eval-conflicts-rho020-r0-097-tzb86 to kind-worker4
0.2192,Event,ADDED,eval-conflicts-rho020-r0-097-tzb86.18d53edb3810461d,"reason=Pulled count=1 msg=Container image ""busybox:musl"" already present on machine"
0.2194,Event,ADDED,eval-conflicts-rho020-r0-097-tzb86.18d53edb43df11a8,reason=Created count=1 msg=Created container: task
0.2195,Event,ADDED,eval-conflicts-rho020-r0-097-tzb86.18d53edb48e0c35a,reason=Started count=1 msg=Started container task
0.2197,Event,ADDED,eval-conflicts-rho020-r0-097.18d53ed989c3f2ed,reason=SuccessfulCreate count=1 msg=Created pod: eval-conflicts-rho020-r0-097-tzb86
0.2199,Event,ADDED,eval-conflicts-rho020-r0-097.18d53ee090c01286,reason=Completed count=1 msg=Job completed
0.22,Event,ADDED,eval-conflicts-rho020-r0-098-q6cfl.18d53ed9c96c6b93,"reason=FailedScheduling count=None msg=0/6 nodes are available: 6 node(s) had untolerated taint(s). no new claims to deallocate, preemption: 0/6 nodes are available: 6 Preemption is not helpful for scheduling."
0.2202,Event,ADDED,eval-conflicts-rho020-r0-098-q6cfl.18d53edb14eeb5a2,reason=Scheduled count=None msg=Successfully assigned compute/eval-conflicts-rho020-r0-098-q6cfl to kind-worker4
0.2203,Event,ADDED,eval-conflicts-rho020-r0-098-q6cfl.18d53edb384bc7a6,"reason=Pulled count=1 msg=Container image ""busybox:musl"" already present on machine"
0.2205,Event,ADDED,eval-conflicts-rho020-r0-098-q6cfl.18d53edb43df3c29,reason=Created count=1 msg=Created container: task
0.2207,Event,ADDED,eval-conflicts-rho020-r0-098-q6cfl.18d53edb48e12234,reason=Started count=1 msg=Started container task
0.2209,Event,ADDED,eval-conflicts-rho020-r0-098.18d53ed9c95efd0a,reason=SuccessfulCreate count=1 msg=Created pod: eval-conflicts-rho020-r0-098-q6cfl
0.221,Event,ADDED,eval-conflicts-rho020-r0-098.18d53ee123b41cea,reason=Completed count=1 msg=Job completed
0.2212,Event,ADDED,eval-conflicts-rho020-r0-099-zk7x8.18d53eda0462334a,"reason=FailedScheduling count=None msg=0/6 nodes are available: 6 node(s) had untolerated taint(s). no new claims to deallocate, preemption: 0/6 nodes are available: 6 Preemption is not helpful for scheduling."
0.2213,Event,ADDED,eval-conflicts-rho020-r0-099-zk7x8.18d53edb14865da3,"reason=FailedScheduling count=None msg=0/6 nodes are available: 1 c_wall violated: 1 conflicting context pair(s) with node memory, 5 node(s) had untolerated taint(s). no new claims to deallocate, preemption: 0/6 nodes are available: 1 No preemption victims found for incoming pod, 5 Preemption is not helpful for scheduling."
0.2215,Event,ADDED,eval-conflicts-rho020-r0-099-zk7x8.18d53edb20a84c5e,"reason=FailedScheduling count=None msg=0/6 nodes are available: 1 c_wall violated: 1 conflicting context pair(s) with node memory, 5 node(s) had untolerated taint(s). no new claims to deallocate, preemption: 0/6 nodes are available: 1 No preemption victims found for incoming pod, 5 Preemption is not helpful for scheduling."
0.2217,Event,ADDED,eval-conflicts-rho020-r0-099-zk7x8.18d53edb6d05f6bf,reason=Scheduled count=None msg=Successfully assigned compute/eval-conflicts-rho020-r0-099-zk7x8 to kind-worker5
0.2218,Event,ADDED,eval-conflicts-rho020-r0-099-zk7x8.18d53edb918a778b,"reason=Pulled count=1 msg=Container image ""busybox:musl"" already present on machine"
0.222,Event,ADDED,eval-conflicts-rho020-r0-099-zk7x8.18d53edb93e10128,reason=Created count=1 msg=Created container: task
0.2222,Event,ADDED,eval-conflicts-rho020-r0-099-zk7x8.18d53edb9dab6d5b,reason=Started count=1 msg=Started container task
0.2223,Event,ADDED,eval-conflicts-rho020-r0-099.18d53eda0455a90d,reason=SuccessfulCreate count=1 msg=Created pod: eval-conflicts-rho020-r0-099-zk7x8
0.2225,Event,ADDED,eval-conflicts-rho020-r0-099.18d53ee198147d10,reason=Completed count=1 msg=Job completed
0.2227,Event,ADDED,eval-conflicts-rho020-r0-100-c2chv.18d53eda3e683e3a,"reason=FailedScheduling count=None msg=0/6 nodes are available: 6 node(s) had untolerated taint(s). no new claims to deallocate, preemption: 0/6 nodes are available: 6 Preemption is not helpful for scheduling."
0.2228,Event,ADDED,eval-conflicts-rho020-r0-100-c2chv.18d53edb155eebf1,"reason=FailedScheduling count=None msg=0/6 nodes are available: 1 c_wall violated: 1 conflicting context pair(s) with node memory, 5 node(s) had untolerated taint(s). no new claims to deallocate, preemption: 0/6 nodes are available: 1 No preemption victims found for incoming pod, 5 Preemption is not helpful for scheduling."
0.223,Event,ADDED,eval-conflicts-rho020-r0-100-c2chv.18d53edb20dc2cd2,"reason=FailedScheduling count=None msg=0/6 nodes are available: 1 c_wall violated: 1 conflicting context pair(s) with node memory, 5 node(s) had untolerated taint(s). no new claims to deallocate, preemption: 0/6 nodes are available: 1 No preemption victims found for incoming pod, 5 Preemption is not helpful for scheduling."
0.2232,Event,ADDED,eval-conflicts-rho020-r0-100-c2chv.18d53edb75acba71,reason=Scheduled count=None msg=Successfully assigned compute/eval-conflicts-rho020-r0-100-c2chv to kind-worker5
0.2233,Event,ADDED,eval-conflicts-rho020-r0-100-c2chv.18d53edb9db0e144,"reason=Pulled count=1 msg=Container image ""busybox:musl"" already present on machine"
0.2235,Event,ADDED,eval-conflicts-rho020-r0-100-c2chv.18d53edb9ee3dd16,reason=Created count=1 msg=Created container: task
0.2237,Event,ADDED,eval-conflicts-rho020-r0-100-c2chv.18d53edba3b11c70,reason=Started count=1 msg=Started container task
0.2238,Event,ADDED,eval-conflicts-rho020-r0-100.18d53eda3e5f3e2a,reason=SuccessfulCreate count=1 msg=Created pod: eval-conflicts-rho020-r0-100-c2chv
0.2267,Event,ADDED,eval-conflicts-rho020-r0-100.18d53ee17437e27b,reason=Completed count=1 msg=Job completed
0.2271,Event,ADDED,eval-conflicts-rho020-r0-101-7slrd.18d53eda78aab45b,"reason=FailedScheduling count=None msg=0/6 nodes are available: 6 node(s) had untolerated taint(s). no new claims to deallocate, preemption: 0/6 nodes are available: 6 Preemption is not helpful for scheduling."
0.2273,Event,ADDED,eval-conflicts-rho020-r0-101-7slrd.18d53edb17290895,"reason=FailedScheduling count=None msg=0/6 nodes are available: 1 c_wall violated: 1 conflicting context pair(s) with node memory, 5 node(s) had untolerated taint(s). no new claims to deallocate, preemption: 0/6 nodes are available: 1 No preemption victims found for incoming pod, 5 Preemption is not helpful for scheduling."
0.2275,Event,ADDED,eval-conflicts-rho020-r0-101-7slrd.18d53edb211654d2,"reason=FailedScheduling count=None msg=0/6 nodes are available: 1 c_wall violated: 1 conflicting context pair(s) with node memory, 5 node(s) had untolerated taint(s). no new claims to deallocate, preemption: 0/6 nodes are available: 1 No preemption victims found for incoming pod, 5 Preemption is not helpful for scheduling."
0.2278,Event,ADDED,eval-conflicts-rho020-r0-101-7slrd.18d53edb66d98a49,reason=Scheduled count=None msg=Successfully assigned compute/eval-conflicts-rho020-r0-101-7slrd to kind-worker5
0.228,Event,ADDED,eval-conflicts-rho020-r0-101-7slrd.18d53edb83c22b92,"reason=Pulled count=1 msg=Container image ""busybox:musl"" already present on machine"
0.2282,Event,ADDED,eval-conflicts-rho020-r0-101-7slrd.18d53edb866e2bfb,reason=Created count=1 msg=Created container: task
0.2284,Event,ADDED,eval-conflicts-rho020-r0-101-7slrd.18d53edb918a3e96,reason=Started count=1 msg=Started container task
0.229,Event,ADDED,eval-conflicts-rho020-r0-101.18d53eda789fc69f,reason=SuccessfulCreate count=1 msg=Created pod: eval-conflicts-rho020-r0-101-7slrd
0.2292,Event,ADDED,eval-conflicts-rho020-r0-101.18d53ee141a720aa,reason=Completed count=1 msg=Job completed
0.2294,Event,ADDED,eval-conflicts-rho020-r0-102-tmbrq.18d53edab407633b,"reason=FailedScheduling count=None msg=0/6 nodes are available: 6 node(s) had untolerated taint(s). no new claims to deallocate, preemption: 0/6 nodes are available: 6 Preemption is not helpful for scheduling."
0.2297,Event,ADDED,eval-conflicts-rho020-r0-102-tmbrq.18d53edb1a239d07,"reason=FailedScheduling count=None msg=0/6 nodes are available: 1 c_wall violated: 1 conflicting context pair(s) with node memory, 5 node(s) had untolerated taint(s). no new claims to deallocate, preemption: 0/6 nodes are available: 1 No preemption victims found for incoming pod, 5 Preemption is not helpful for scheduling."
0.2298,Event,ADDED,eval-conflicts-rho020-r0-102-tmbrq.18d53edb214b0ff9,"reason=FailedScheduling count=None msg=0/6 nodes are available: 1 c_wall violated: 2 conflicting context pair(s) with node memory, 5 node(s) had untolerated taint(s). no new claims to deallocate, preemption: 0/6 nodes are available: 1 No preemption victims found for incoming pod, 5 Preemption is not helpful for scheduling."
0.23,Event,ADDED,eval-conflicts-rho020-r0-102-tmbrq.18d53edb2643beac,"reason=FailedScheduling count=None msg=0/6 nodes are available: 1 c_wall violated: 2 conflicting context pair(s) with node memory, 5 node(s) had untolerated taint(s). no new claims to deallocate, preemption: 0/6 nodes are available: 1 No preemption victims found for incoming pod, 5 Preemption is not helpful for scheduling."
0.2302,Event,ADDED,eval-conflicts-rho020-r0-102-tmbrq.18d53edb6b2f11e0,reason=Scheduled count=None msg=Successfully assigned compute/eval-conflicts-rho020-r0-102-tmbrq to kind-worker5
0.2304,Event,ADDED,eval-conflicts-rho020-r0-102-tmbrq.18d53edb9196a066,"reason=Pulled count=1 msg=Container image ""busybox:musl"" already present on machine"
0.2305,Event,ADDED,eval-conflicts-rho020-r0-102-tmbrq.18d53edb946e6d4d,reason=Created count=1 msg=Created container: task
0.2307,Event,ADDED,eval-conflicts-rho020-r0-102-tmbrq.18d53edb9da7a608,reason=Started count=1 msg=Started container task
0.2309,Event,ADDED,eval-conflicts-rho020-r0-102.18d53edab3fe0c35,reason=SuccessfulCreate count=1 msg=Created pod: eval-conflicts-rho020-r0-102-tmbrq
0.2311,Event,ADDED,eval-conflicts-rho020-r0-102.18d53ee183f40038,reason=Completed count=1 msg=Job completed
0.2313,Event,ADDED,eval-conflicts-rho020-r0-103-hbvx9.18d53edaf4aebd60,"reason=FailedScheduling count=None msg=0/6 nodes are available: 6 node(s) had untolerated taint(s). no new claims to deallocate, preemption: 0/6 nodes are available: 6 Preemption is not helpful for scheduling."
0.2316,Event,ADDED,eval-conflicts-rho020-r0-103-hbvx9.18d53edb20e39653,reason=Scheduled count=None msg=Successfully assigned compute/eval-conflicts-rho020-r0-103-hbvx9 to kind-worker4
0.2318,Event,ADDED,eval-conflicts-rho020-r0-103-hbvx9.18d53edb4965c8c4,"reason=Pulled count=1 msg=Container image ""busybox:musl"" already present on machine"
0.232,Event,ADDED,eval-conflicts-rho020-r0-103-hbvx9.18d53edb4aa54cdd,reason=Created count=1 msg=Created container: task
0.2322,Event,ADDED,eval-conflicts-rho020-r0-103-hbvx9.18d53edb4cfeea66,reason=Started count=1 msg=Started container task
0.2326,Event,ADDED,eval-conflicts-rho020-r0-103.18d53edaf4a46661,reason=SuccessfulCreate count=1 msg=Created pod: eval-conflicts-rho020-r0-103-hbvx9
0.2329,Event,ADDED,eval-conflicts-rho020-r0-103.18d53ee0910730be,reason=Completed count=1 msg=Job completed
0.2331,Event,ADDED,eval-conflicts-rho020-r0-104-fms7j.18d53edb2bf7d031,reason=Scheduled count=None msg=Successfully assigned compute/eval-conflicts-rho020-r0-104-fms7j to kind-worker4
0.2333,Event,ADDED,eval-conflicts-rho020-r0-104-fms7j.18d53edb4af19708,"reason=Pulled count=1 msg=Container image ""busybox:musl"" already present on machine"
0.2338,Event,ADDED,eval-conflicts-rho020-r0-104-fms7j.18d53edb4c258c24,reason=Created count=1 msg=Created container: task
0.234,Event,ADDED,eval-conflicts-rho020-r0-104-fms7j.18d53edb4e6b3161,reason=Started count=1 msg=Started container task
0.2342,Event,ADDED,eval-conflicts-rho020-r0-104.18d53edb2b2c8512,reason=SuccessfulCreate count=1 msg=Created pod: eval-conflicts-rho020-r0-104-fms7j
0.2345,Event,ADDED,eval-conflicts-rho020-r0-104.18d53ee126b88164,reason=Completed count=1 msg=Job completed
0.2347,Event,ADDED,eval-conflicts-rho020-r0-105-8h5qp.18d53edb6b8bc9ec,reason=Scheduled count=None msg=Successfully assigned compute/eval-conflicts-rho020-r0-105-8h5qp to kind-worker5
0.2349,Event,ADDED,eval-conflicts-rho020-r0-105-8h5qp.18d53edb91bcaf31,"reason=Pulled count=1 msg=Container image ""busybox:musl"" already present on machine"
0.235,Event,ADDED,eval-conflicts-rho020-r0-105-8h5qp.18d53edb94a8cc44,reason=Created count=1 msg=Created container: task
0.2353,Event,ADDED,eval-conflicts-rho020-r0-105-8h5qp.18d53edb9dab5285,reason=Started count=1 msg=Started container task
0.2354,Event,ADDED,eval-conflicts-rho020-r0-105.18d53edb676594d1,reason=SuccessfulCreate count=1 msg=Created pod: eval-conflicts-rho020-r0-105-8h5qp
0.2356,Event,ADDED,eval-conflicts-rho020-r0-105.18d53ee18982c13b,reason=Completed count=1 msg=Job completed
0.2357,Event,ADDED,eval-conflicts-rho020-r0-106-w7wkr.18d53edba2546bce,reason=Scheduled count=None msg=Successfully assigned compute/eval-conflicts-rho020-r0-106-w7wkr to kind-worker5
0.2359,Event,ADDED,eval-conflicts-rho020-r0-106-w7wkr.18d53edbcec33b41,"reason=Pulled count=1 msg=Container image ""busybox:musl"" already present on machine"
0.2361,Event,ADDED,eval-conflicts-rho020-r0-106-w7wkr.18d53edbd0073ba7,reason=Created count=1 msg=Created container: task
0.2363,Event,ADDED,eval-conflicts-rho020-r0-106-w7wkr.18d53edbd83b56bc,reason=Started count=1 msg=Started container task
0.2364,Event,ADDED,eval-conflicts-rho020-r0-106.18d53edba18aff5e,reason=SuccessfulCreate count=1 msg=Created pod: eval-conflicts-rho020-r0-106-w7wkr
0.2366,Event,ADDED,eval-conflicts-rho020-r0-106.18d53ee1beb4ac7a,reason=Completed count=1 msg=Job completed
0.2368,Event,ADDED,eval-conflicts-rho020-r0-107-4zdsv.18d53edbeab1bc7c,reason=Scheduled count=None msg=Successfully assigned compute/eval-conflicts-rho020-r0-107-4zdsv to kind-worker4
0.2369,Event,ADDED,eval-conflicts-rho020-r0-107-4zdsv.18d53edc08b39baf,"reason=Pulled count=1 msg=Container image ""busybox:musl"" already present on machine"
0.2371,Event,ADDED,eval-conflicts-rho020-r0-107-4zdsv.18d53edc0a160f46,reason=Created count=1 msg=Created container: task
0.2373,Event,ADDED,eval-conflicts-rho020-r0-107-4zdsv.18d53edc14ee6649,reason=Started count=1 msg=Started container task
0.2375,Event,ADDED,eval-conflicts-rho020-r0-107.18d53edbe9c7f44a,reason=SuccessfulCreate count=1 msg=Created pod: eval-conflicts-rho020-r0-107-4zdsv
0.2376,Event,ADDED,eval-conflicts-rho020-r0-107.18d53ee1e6a857f6,reason=Completed count=1 msg=Job completed
0.2378,Event,ADDED,eval-conflicts-rho020-r0-108-tsjxd.18d53edc1a027f47,reason=Scheduled count=None msg=Successfully assigned compute/eval-conflicts-rho020-r0-108-tsjxd to kind-worker4
0.238,Event,ADDED,eval-conflicts-rho020-r0-108-tsjxd.18d53edc39062d43,"reason=Pulled count=1 msg=Container image ""busybox:musl"" already present on machine"
0.2381,Event,ADDED,eval-conflicts-rho020-r0-108-tsjxd.18d53edc3a1d00e1,reason=Created count=1 msg=Created container: task
0.2383,Event,ADDED,eval-conflicts-rho020-r0-108-tsjxd.18d53edc403b811b,reason=Started count=1 msg=Started container task
0.2385,Event,ADDED,eval-conflicts-rho020-r0-108.18d53edc1952d2de,reason=SuccessfulCreate count=1 msg=Created pod: eval-conflicts-rho020-r0-108-tsjxd
0.2386,Event,ADDED,eval-conflicts-rho020-r0-108.18d53ee1ce3af9d5,reason=Completed count=1 msg=Job completed
0.2388,Event,ADDED,eval-conflicts-rho020-r0-109-fjqbq.18d53edc55ae615e,reason=Scheduled count=None msg=Successfully assigned compute/eval-conflicts-rho020-r0-109-fjqbq to kind-worker
0.2389,Event,ADDED,eval-conflicts-rho020-r0-109-fjqbq.18d53edc715164ea,"reason=Pulled count=1 msg=Container image ""busybox:musl"" already present on machine"
0.2391,Event,ADDED,eval-conflicts-rho020-r0-109-fjqbq.18d53edc731b9e5c,reason=Created count=1 msg=Created container: task
0.2393,Event,ADDED,eval-conflicts-rho020-r0-109-fjqbq.18d53edc7b2eab8e,reason=Started count=1 msg=Started container task
0.2394,Event,ADDED,eval-conflicts-rho020-r0-109.18d53edc546e4295,reason=SuccessfulCreate count=1 msg=Created pod: eval-conflicts-rho020-r0-109-fjqbq
0.2396,Event,ADDED,eval-conflicts-rho020-r0-109.18d53ee21a15f9ae,reason=Completed count=1 msg=Job completed
0.2398,Event,ADDED,eval-conflicts-rho020-r0-110-fk7wn.18d53edc96f28370,reason=Scheduled count=None msg=Successfully assigned compute/eval-conflicts-rho020-r0-110-fk7wn to kind-worker
0.2399,Event,ADDED,eval-conflicts-rho020-r0-110-fk7wn.18d53edcbaea69a1,"reason=Pulled count=1 msg=Container image ""busybox:musl"" already present on machine"
0.2404,Event,ADDED,eval-conflicts-rho020-r0-110-fk7wn.18d53edcbc02a57e,reason=Created count=1 msg=Created container: task
0.2407,Event,ADDED,eval-conflicts-rho020-r0-110-fk7wn.18d53edcc3b3e529,reason=Started count=1 msg=Started container task
0.2409,Event,ADDED,eval-conflicts-rho020-r0-110.18d53edc95bc6e89,reason=SuccessfulCreate count=1 msg=Created pod: eval-conflicts-rho020-r0-110-fk7wn
0.2411,Event,ADDED,eval-conflicts-rho020-r0-110.18d53ee24e80930a,reason=Completed count=1 msg=Job completed
0.2413,Event,ADDED,eval-conflicts-rho020-r0-111-flsjx.18d53edccdd7500a,reason=Scheduled count=None msg=Successfully assigned compute/eval-conflicts-rho020-r0-111-flsjx to kind-worker
0.2415,Event,ADDED,eval-conflicts-rho020-r0-111-flsjx.18d53edcefc0cd72,"reason=Pulled count=1 msg=Container image ""busybox:musl"" already present on machine"
0.2417,Event,ADDED,eval-conflicts-rho020-r0-111-flsjx.18d53edcf10c3459,reason=Created count=1 msg=Created container: task
0.2418,Event,ADDED,eval-conflicts-rho020-r0-111-flsjx.18d53edcfc7c6e50,reason=Started count=1 msg=Started container task
0.242,Event,ADDED,eval-conflicts-rho020-r0-111.18d53edccc9bfbef,reason=SuccessfulCreate count=1 msg=Created pod: eval-conflicts-rho020-r0-111-flsjx
0.2422,Event,ADDED,eval-conflicts-rho020-r0-111.18d53ee28a0bdcc6,reason=Completed count=1 msg=Job completed
0.2423,Event,ADDED,eval-conflicts-rho020-r0-112-psxzx.18d53edd0e80e0d8,reason=Scheduled count=None msg=Successfully assigned compute/eval-conflicts-rho020-r0-112-psxzx to kind-worker
0.2425,Event,ADDED,eval-conflicts-rho020-r0-112-psxzx.18d53edd25b46151,"reason=Pulled count=1 msg=Container image ""busybox:musl"" already present on machine"
0.2427,Event,ADDED,eval-conflicts-rho020-r0-112-psxzx.18d53edd26ca234f,reason=Created count=1 msg=Created container: task
0.2428,Event,ADDED,eval-conflicts-rho020-r0-112-psxzx.18d53edd31c9d227,reason=Started count=1 msg=Started container task
0.243,Event,ADDED,eval-conflicts-rho020-r0-112.18d53edd0abe109a,reason=SuccessfulCreate count=1 msg=Created pod: eval-conflicts-rho020-r0-112-psxzx
0.2432,Event,ADDED,eval-conflicts-rho020-r0-112.18d53ee2c5d71ff9,reason=Completed count=1 msg=Job completed
0.2433,Event,ADDED,eval-conflicts-rho020-r0-113-k25mb.18d53edd46b9409b,reason=Scheduled count=None msg=Successfully assigned compute/eval-conflicts-rho020-r0-113-k25mb to kind-worker
0.2435,Event,ADDED,eval-conflicts-rho020-r0-113-k25mb.18d53edd63c9e468,"reason=Pulled count=1 msg=Container image ""busybox:musl"" already present on machine"
0.2437,Event,ADDED,eval-conflicts-rho020-r0-113-k25mb.18d53edd69ca5685,reason=Created count=1 msg=Created container: task
0.2439,Event,ADDED,eval-conflicts-rho020-r0-113-k25mb.18d53edd74546a74,reason=Started count=1 msg=Started container task
0.2441,Event,ADDED,eval-conflicts-rho020-r0-113.18d53edd45824b11,reason=SuccessfulCreate count=1 msg=Created pod: eval-conflicts-rho020-r0-113-k25mb
0.2442,Event,ADDED,eval-conflicts-rho020-r0-113.18d53ee30143d28e,reason=Completed count=1 msg=Job completed
0.2444,Event,ADDED,eval-conflicts-rho020-r0-114-f7xm6.18d53edd82cc6f47,reason=Scheduled count=None msg=Successfully assigned compute/eval-conflicts-rho020-r0-114-f7xm6 to kind-worker5
0.2447,Event,ADDED,eval-conflicts-rho020-r0-114-f7xm6.18d53edda19a3b75,"reason=Pulled count=1 msg=Container image ""busybox:musl"" already present on machine"
0.2449,Event,ADDED,eval-conflicts-rho020-r0-114-f7xm6.18d53edda2c353dc,reason=Created count=1 msg=Created container: task
0.2453,Event,ADDED,eval-conflicts-rho020-r0-114-f7xm6.18d53eddabb14616,reason=Started count=1 msg=Started container task
0.2455,Event,ADDED,eval-conflicts-rho020-r0-114.18d53edd81b1d944,reason=SuccessfulCreate count=1 msg=Created pod: eval-conflicts-rho020-r0-114-f7xm6
0.2457,Event,ADDED,eval-conflicts-rho020-r0-114.18d53ee30da080bf,reason=Completed count=1 msg=Job completed
0.2458,Event,ADDED,eval-conflicts-rho020-r0-115-xn6rf.18d53eddbb39c35a,reason=Scheduled count=None msg=Successfully assigned compute/eval-conflicts-rho020-r0-115-xn6rf to kind-worker5
0.2462,Event,ADDED,eval-conflicts-rho020-r0-115-xn6rf.18d53eddda31e85a,"reason=Pulled count=1 msg=Container image ""busybox:musl"" already present on machine"
0.2465,Event,ADDED,eval-conflicts-rho020-r0-115-xn6rf.18d53edddb5393e4,reason=Created count=1 msg=Created container: task
0.2466,Event,ADDED,eval-conflicts-rho020-r0-115-xn6rf.18d53edddfc1e963,reason=Started count=1 msg=Started container task
0.2468,Event,ADDED,eval-conflicts-rho020-r0-115.18d53eddba561ff7,reason=SuccessfulCreate count=1 msg=Created pod: eval-conflicts-rho020-r0-115-xn6rf
0.2473,Event,ADDED,eval-conflicts-rho020-r0-115.18d53ee349808698,reason=Completed count=1 msg=Job completed
0.2475,Event,ADDED,eval-conflicts-rho020-r0-116-fp98b.18d53eddfa449994,reason=Scheduled count=None msg=Successfully assigned compute/eval-conflicts-rho020-r0-116-fp98b to kind-worker5
0.2477,Event,ADDED,eval-conflicts-rho020-r0-116-fp98b.18d53ede16e83d43,"reason=Pulled count=1 msg=Container image ""busybox:musl"" already present on machine"
0.2479,Event,ADDED,eval-conflicts-rho020-r0-116-fp98b.18d53ede1818b37d,reason=Created count=1 msg=Created container: task
0.2481,Event,ADDED,eval-conflicts-rho020-r0-116-fp98b.18d53ede21db3c49,reason=Started count=1 msg=Started container task
0.2482,Event,ADDED,eval-conflicts-rho020-r0-116.18d53eddf8b13981,reason=SuccessfulCreate count=1 msg=Created pod: eval-conflicts-rho020-r0-116-fp98b
0.2484,Event,ADDED,eval-conflicts-rho020-r0-116.18d53ee38540458c,reason=Completed count=1 msg=Job completed
0.2486,Event,ADDED,eval-conflicts-rho020-r0-117-4d849.18d53ede321bee72,reason=Scheduled count=None msg=Successfully assigned compute/eval-conflicts-rho020-r0-117-4d849 to kind-worker5
0.2488,Event,ADDED,eval-conflicts-rho020-r0-117-4d849.18d53ede52251475,"reason=Pulled count=1 msg=Container image ""busybox:musl"" already present on machine"
0.2489,Event,ADDED,eval-conflicts-rho020-r0-117-4d849.18d53ede53475503,reason=Created count=1 msg=Created container: task
0.2493,Event,ADDED,eval-conflicts-rho020-r0-117-4d849.18d53ede5e217527,reason=Started count=1 msg=Started container task
0.2494,Event,ADDED,eval-conflicts-rho020-r0-117.18d53ede31269b07,reason=SuccessfulCreate count=1 msg=Created pod: eval-conflicts-rho020-r0-117-4d849
0.2496,Event,ADDED,eval-conflicts-rho020-r0-117.18d53ee3c4056b74,reason=Completed count=1 msg=Job completed
0.2498,Event,ADDED,eval-conflicts-rho020-r0-118-xc794.18d53ede70958c2a,reason=Scheduled count=None msg=Successfully assigned compute/eval-conflicts-rho020-r0-118-xc794 to kind-worker2
0.2502,Event,ADDED,eval-conflicts-rho020-r0-118-xc794.18d53ede94cb401a,"reason=Pulled count=1 msg=Container image ""busybox:musl"" already present on machine"
0.2504,Event,ADDED,eval-conflicts-rho020-r0-118-xc794.18d53ede95fea28b,reason=Created count=1 msg=Created container: task
0.2505,Event,ADDED,eval-conflicts-rho020-r0-118-xc794.18d53ede9ee1c655,reason=Started count=1 msg=Started container task
0.2507,Event,ADDED,eval-conflicts-rho020-r0-118.18d53ede6f6614aa,reason=SuccessfulCreate count=1 msg=Created pod: eval-conflicts-rho020-r0-118-xc794
0.251,Event,ADDED,eval-conflicts-rho020-r0-118.18d53ee410988e05,reason=Completed count=1 msg=Job completed
0.2511,Event,ADDED,eval-conflicts-rho020-r0-119-5d2zr.18d53edeb7c4d3a0,reason=Scheduled count=None msg=Successfully assigned compute/eval-conflicts-rho020-r0-119-5d2zr to kind-worker2
0.2513,Event,ADDED,eval-conflicts-rho020-r0-119-5d2zr.18d53eded4fd0ab4,"reason=Pulled count=1 msg=Container image ""busybox:musl"" already present on machine"
0.2517,Event,ADDED,eval-conflicts-rho020-r0-119-5d2zr.18d53eded6108b30,reason=Created count=1 msg=Created container: task
0.2519,Event,ADDED,eval-conflicts-rho020-r0-119-5d2zr.18d53ededad104e8,reason=Started count=1 msg=Started container task
0.252,Event,ADDED,eval-conflicts-rho020-r0-119.18d53edeacdf0e25,reason=SuccessfulCreate count=1 msg=Created pod: eval-conflicts-rho020-r0-119-5d2zr
0.2522,Event,ADDED,eval-conflicts-rho020-r0-119.18d53ee44c51294e,reason=Completed count=1 msg=Job completed
0.2525,Event,ADDED,eval-conflicts-rho020-r0-120-z5n8l.18d53edee6788a0f,reason=Scheduled count=None msg=Successfully assigned compute/eval-conflicts-rho020-r0-120-z5n8l to kind-worker2
0.2527,Event,ADDED,eval-conflicts-rho020-r0-120-z5n8l.18d53edeff89eb04,"reason=Pulled count=1 msg=Container image ""busybox:musl"" already present on machine"
0.2529,Event,ADDED,eval-conflicts-rho020-r0-120-z5n8l.18d53edf009fa466,reason=Created count=1 msg=Created container: task
0.2531,Event,ADDED,eval-conflicts-rho020-r0-120-z5n8l.18d53edf02a2fa92,reason=Started count=1 msg=Started container task
0.2535,Event,ADDED,eval-conflicts-rho020-r0-120.18d53edee4f0f329,reason=SuccessfulCreate count=1 msg=Created pod: eval-conflicts-rho020-r0-120-z5n8l
0.2537,Event,ADDED,eval-conflicts-rho020-r0-120.18d53ee487f23c2a,reason=Completed count=1 msg=Job completed
0.2538,Event,ADDED,eval-conflicts-rho020-r0-121-5k88z.18d53edf24271e8b,reason=Scheduled count=None msg=Successfully assigned compute/eval-conflicts-rho020-r0-121-5k88z to kind-worker2
0.2543,Event,ADDED,eval-conflicts-rho020-r0-121-5k88z.18d53edf3ef7a45d,"reason=Pulled count=1 msg=Container image ""busybox:musl"" already present on machine"
0.2545,Event,ADDED,eval-conflicts-rho020-r0-121-5k88z.18d53edf4006ef78,reason=Created count=1 msg=Created container: task
0.2547,Event,ADDED,eval-conflicts-rho020-r0-121-5k88z.18d53edf472d64c6,reason=Started count=1 msg=Started container task
0.2549,Event,ADDED,eval-conflicts-rho020-r0-121.18d53edf22b8c549,reason=SuccessfulCreate count=1 msg=Created pod: eval-conflicts-rho020-r0-121-5k88z
0.2552,Event,ADDED,eval-conflicts-rho020-r0-121.18d53ee4c56319b9,reason=Completed count=1 msg=Job completed
0.2553,Event,ADDED,eval-conflicts-rho020-r0-122-kp5np.18d53edf601cf5ff,reason=Scheduled count=None msg=Successfully assigned compute/eval-conflicts-rho020-r0-122-kp5np to kind-worker5
0.2555,Event,ADDED,eval-conflicts-rho020-r0-122-kp5np.18d53edf79a8925b,"reason=Pulled count=1 msg=Container image ""busybox:musl"" already present on machine"
0.2559,Event,ADDED,eval-conflicts-rho020-r0-122-kp5np.18d53edf7abff73b,reason=Created count=1 msg=Created container: task
0.2561,Event,ADDED,eval-conflicts-rho020-r0-122-kp5np.18d53edf7cd32657,reason=Started count=1 msg=Started container task
0.2562,Event,ADDED,eval-conflicts-rho020-r0-122.18d53edf5c56a935,reason=SuccessfulCreate count=1 msg=Created pod: eval-conflicts-rho020-r0-122-kp5np
0.2564,Event,ADDED,eval-conflicts-rho020-r0-122.18d53ee4eb7d4e97,reason=Completed count=1 msg=Job completed
0.2567,Event,ADDED,eval-conflicts-rho020-r0-123-6qp7x.18d53edf9d76bf76,reason=Scheduled count=None msg=Successfully assigned compute/eval-conflicts-rho020-r0-123-6qp7x to kind-worker5
0.2569,Event,ADDED,eval-conflicts-rho020-r0-123-6qp7x.18d53edfb9709953,"reason=Pulled count=1 msg=Container image ""busybox:musl"" already present on machine"
0.2571,Event,ADDED,eval-conflicts-rho020-r0-123-6qp7x.18d53edfbad8c091,reason=Created count=1 msg=Created container: task
0.2573,Event,ADDED,eval-conflicts-rho020-r0-123-6qp7x.18d53edfbec6f00f,reason=Started count=1 msg=Started container task
0.2575,Event,ADDED,eval-conflicts-rho020-r0-123.18d53edf9c3d2130,reason=SuccessfulCreate count=1 msg=Created pod: eval-conflicts-rho020-r0-123-6qp7x
0.2577,Event,ADDED,eval-conflicts-rho020-r0-123.18d53ee5273b429a,reason=Completed count=1 msg=Job completed
0.2578,Event,ADDED,eval-conflicts-rho020-r0-124-qfd7z.18d53edfd95aa040,reason=Scheduled count=None msg=Successfully assigned compute/eval-conflicts-rho020-r0-124-qfd7z to kind-worker2
0.2582,Event,ADDED,eval-conflicts-rho020-r0-124-qfd7z.18d53edff87cdcad,"reason=Pulled count=1 msg=Container image ""busybox:musl"" already present on machine"
0.2587,Event,ADDED,eval-conflicts-rho020-r0-124-qfd7z.18d53edff99b005a,reason=Created count=1 msg=Created container: task
0.2592,Event,ADDED,eval-conflicts-rho020-r0-124-qfd7z.18d53edffe9da3db,reason=Started count=1 msg=Started container task
0.2593,Event,ADDED,eval-conflicts-rho020-r0-124.18d53edfd8200154,reason=SuccessfulCreate count=1 msg=Created pod: eval-conflicts-rho020-r0-124-qfd7z
0.2597,Event,ADDED,eval-conflicts-rho020-r0-124.18d53ee57c8932de,reason=Completed count=1 msg=Job completed
0.2598,Event,ADDED,eval-conflicts-rho020-r0-125-wqjwd.18d53ee00fb69af6,reason=Scheduled count=None msg=Successfully assigned compute/eval-conflicts-rho020-r0-125-wqjwd to kind-worker5
0.26,Event,ADDED,eval-conflicts-rho020-r0-125-wqjwd.18d53ee02ad6e73a,"reason=Pulled count=1 msg=Container image ""busybox:musl"" already present on machine"
0.2602,Event,ADDED,eval-conflicts-rho020-r0-125-wqjwd.18d53ee02bfe2123,reason=Created count=1 msg=Created container: task
0.2605,Event,ADDED,eval-conflicts-rho020-r0-125-wqjwd.18d53ee031ec880b,reason=Started count=1 msg=Started container task
0.2607,Event,ADDED,eval-conflicts-rho020-r0-125.18d53ee00eb06c80,reason=SuccessfulCreate count=1 msg=Created pod: eval-conflicts-rho020-r0-125-wqjwd
0.2609,Event,ADDED,eval-conflicts-rho020-r0-125.18d53ee5a4e046b7,reason=Completed count=1 msg=Job completed
0.2612,Event,ADDED,eval-conflicts-rho020-r0-126-g9zxq.18d53ee04a376605,"reason=FailedScheduling count=None msg=0/6 nodes are available: 2 c_wall violated: 2 conflicting context pair(s) with node memory, 4 node(s) had untolerated taint(s). no new claims to deallocate, preemption: 0/6 nodes are available: 2 No preemption victims found for incoming pod, 4 Preemption is not helpful for scheduling."
0.2614,Event,ADDED,eval-conflicts-rho020-r0-126-g9zxq.18d53ee04ae60101,"reason=FailedScheduling count=None msg=0/6 nodes are available: 2 c_wall violated: 2 conflicting context pair(s) with node memory, 4 node(s) had untolerated taint(s). no new claims to deallocate, preemption: 0/6 nodes are available: 2 No preemption victims found for incoming pod, 4 Preemption is not helpful for scheduling."
0.2616,Event,ADDED,eval-conflicts-rho020-r0-126-g9zxq.18d53ee0dd559c64,"reason=FailedScheduling count=None msg=0/6 nodes are available: 1 c_wall violated: 2 conflicting context pair(s) with node memory, 5 node(s) had untolerated taint(s). no new claims to deallocate, preemption: 0/6 nodes are available: 1 No preemption victims found for incoming pod, 5 Preemption is not helpful for scheduling."
0.2619,Event,ADDED,eval-conflicts-rho020-r0-126-g9zxq.18d53ee22c85a645,reason=Scheduled count=None msg=Successfully assigned compute/eval-conflicts-rho020-r0-126-g9zxq to kind-worker3
0.2621,Event,ADDED,eval-conflicts-rho020-r0-126-g9zxq.18d53ee245dd6415,"reason=Pulled count=1 msg=Container image ""busybox:musl"" already present on machine"
0.2623,Event,ADDED,eval-conflicts-rho020-r0-126-g9zxq.18d53ee2478218a6,reason=Created count=1 msg=Created container: task
0.2625,Event,ADDED,eval-conflicts-rho020-r0-126-g9zxq.18d53ee24c758360,reason=Started count=1 msg=Started container task
0.2628,Event,ADDED,eval-conflicts-rho020-r0-126.18d53ee049c5791d,reason=SuccessfulCreate count=1 msg=Created pod: eval-conflicts-rho020-r0-126-g9zxq
0.263,Event,ADDED,eval-conflicts-rho020-r0-126.18d53ee7c86657c2,reason=Completed count=1 msg=Job completed
0.2631,Event,ADDED,eval-conflicts-rho020-r0-127-zwpx4.18d53ee088e7eb8f,reason=Scheduled count=None msg=Successfully assigned compute/eval-conflicts-rho020-r0-127-zwpx4 to kind-worker2
0.2634,Event,ADDED,eval-conflicts-rho020-r0-127-zwpx4.18d53ee0a584822f,"reason=Pulled count=1 msg=Container image ""busybox:musl"" already present on machine"
0.2636,Event,ADDED,eval-conflicts-rho020-r0-127-zwpx4.18d53ee0a6ce1106,reason=Created count=1 msg=Created container: task
0.2637,Event,ADDED,eval-conflicts-rho020-r0-127-zwpx4.18d53ee0ad452dcc,reason=Started count=1 msg=Started container task
0.2639,Event,ADDED,eval-conflicts-rho020-r0-127.18d53ee088034557,reason=SuccessfulCreate count=1 msg=Created pod: eval-conflicts-rho020-r0-127-zwpx4
0.2641,Event,ADDED,eval-conflicts-rho020-r0-127.18d53ee62d3b8754,reason=Completed count=1 msg=Job completed
0.2642,Event,ADDED,eval-conflicts-rho020-r0-128-562kr.18d53ee0c76faa4e,reason=Scheduled count=None msg=Successfully assigned compute/eval-conflicts-rho020-r0-128-562kr to kind-worker2
0.2644,Event,ADDED,eval-conflicts-rho020-r0-128-562kr.18d53ee0e174bc74,"reason=Pulled count=1 msg=Container image ""busybox:musl"" already present on machine"
0.2646,Event,ADDED,eval-conflicts-rho020-r0-128-562kr.18d53ee0e2be2b1b,reason=Created count=1 msg=Created container: task
0.2647,Event,ADDED,eval-conflicts-rho020-r0-128-562kr.18d53ee0e7c27f23,reason=Started count=1 msg=Started container task
0.2649,Event,ADDED,eval-conflicts-rho020-r0-128.18d53ee0c3907852,reason=SuccessfulCreate count=1 msg=Created pod: eval-conflicts-rho020-r0-128-562kr
0.2651,Event,ADDED,eval-conflicts-rho020-r0-128.18d53ee669a05112,reason=Completed count=1 msg=Job completed
0.2653,Event,ADDED,eval-conflicts-rho020-r0-129-hl649.18d53ee10d38b7f1,reason=Scheduled count=None msg=Successfully assigned compute/eval-conflicts-rho020-r0-129-hl649 to kind-worker2
0.2655,Event,ADDED,eval-conflicts-rho020-r0-129-hl649.18d53ee12592baee,"reason=Pulled count=1 msg=Container image ""busybox:musl"" already present on machine"
0.2657,Event,ADDED,eval-conflicts-rho020-r0-129-hl649.18d53ee1269b82a2,reason=Created count=1 msg=Created container: task
0.2658,Event,ADDED,eval-conflicts-rho020-r0-129-hl649.18d53ee128c6e655,reason=Started count=1 msg=Started container task
0.2662,Event,ADDED,eval-conflicts-rho020-r0-129.18d53ee10cb967fd,reason=SuccessfulCreate count=1 msg=Created pod: eval-conflicts-rho020-r0-129-hl649
0.2666,Event,ADDED,eval-conflicts-rho020-r0-129.18d53ee6a1d4f0a8,reason=Completed count=1 msg=Job completed
0.2669,Event,ADDED,eval-conflicts-rho020-r0-130-w5tkr.18d53ee150f311f9,reason=Scheduled count=None msg=Successfully assigned compute/eval-conflicts-rho020-r0-130-w5tkr to kind-worker2
0.2673,Event,ADDED,eval-conflicts-rho020-r0-130-w5tkr.18d53ee16a08da7d,"reason=Pulled count=1 msg=Container image ""busybox:musl"" already present on machine"
0.2675,Event,ADDED,eval-conflicts-rho020-r0-130-w5tkr.18d53ee16b1c793b,reason=Created count=1 msg=Created container: task
0.2677,Event,ADDED,eval-conflicts-rho020-r0-130-w5tkr.18d53ee173c66a27,reason=Started count=1 msg=Started container task
0.2678,Event,ADDED,eval-conflicts-rho020-r0-130.18d53ee1507243ec,reason=SuccessfulCreate count=1 msg=Created pod: eval-conflicts-rho020-r0-130-w5tkr
0.2681,Event,ADDED,eval-conflicts-rho020-r0-130.18d53ee6ddc3618b,reason=Completed count=1 msg=Job completed
0.2682,Event,ADDED,eval-conflicts-rho020-r0-131-zpt8r.18d53ee1805c34b6,"reason=FailedScheduling count=None msg=0/6 nodes are available: 1 c_wall violated: 1 conflicting context pair(s) with node memory, 5 node(s) had untolerated taint(s). no new claims to deallocate, preemption: 0/6 nodes are available: 1 No preemption victims found for incoming pod, 5 Preemption is not helpful for scheduling."
0.2684,Event,ADDED,eval-conflicts-rho020-r0-131-zpt8r.18d53ee180ec0532,"reason=FailedScheduling count=None msg=0/6 nodes are available: 1 c_wall violated: 1 conflicting context pair(s) with node memory, 5 node(s) had untolerated taint(s). no new claims to deallocate, preemption: 0/6 nodes are available: 1 No preemption victims found for incoming pod, 5 Preemption is not helpful for scheduling."
0.2686,Event,ADDED,eval-conflicts-rho020-r0-131-zpt8r.18d53ee237a77fa7,reason=Scheduled count=None msg=Successfully assigned compute/eval-conflicts-rho020-r0-131-zpt8r to kind-worker3
0.2688,Event,ADDED,eval-conflicts-rho020-r0-131-zpt8r.18d53ee25551b610,"reason=Pulled count=1 msg=Container image ""busybox:musl"" already present on machine"
0.2689,Event,ADDED,eval-conflicts-rho020-r0-131-zpt8r.18d53ee256e2bb79,reason=Created count=1 msg=Created container: task
0.2691,Event,ADDED,eval-conflicts-rho020-r0-131-zpt8r.18d53ee25bd5f518,reason=Started count=1 msg=Started container task
0.2693,Event,ADDED,eval-conflicts-rho020-r0-131.18d53ee18023f3e0,reason=SuccessfulCreate count=1 msg=Created pod: eval-conflicts-rho020-r0-131-zpt8r
0.2694,Event,ADDED,eval-conflicts-rho020-r0-131.18d53ee7c8b6d17a,reason=Completed count=1 msg=Job completed
0.2696,Event,ADDED,eval-conflicts-rho020-r0-132-2dp4b.18d53ee1b00da19a,"reason=FailedScheduling count=None msg=0/6 nodes are available: 1 c_wall violated: 1 conflicting context pair(s) with node memory, 5 node(s) had untolerated taint(s). no new claims to deallocate, preemption: 0/6 nodes are available: 1 No preemption victims found for incoming pod, 5 Preemption is not helpful for scheduling."
0.2699,Event,ADDED,eval-conflicts-rho020-r0-132-2dp4b.18d53ee1b080f023,"reason=FailedScheduling count=None msg=0/6 nodes are available: 1 c_wall violated: 1 conflicting context pair(s) with node memory, 5 node(s) had untolerated taint(s). no new claims to deallocate, preemption: 0/6 nodes are available: 1 No preemption victims found for incoming pod, 5 Preemption is not helpful for scheduling."
0.2701,Event,ADDED,eval-conflicts-rho020-r0-132-2dp4b.18d53ee22b793a8d,reason=Scheduled count=None msg=Successfully assigned compute/eval-conflicts-rho020-r0-132-2dp4b to kind-worker3
0.2703,Event,ADDED,eval-conflicts-rho020-r0-132-2dp4b.18d53ee244e09f5a,"reason=Pulled count=1 msg=Container image ""busybox:musl"" already present on machine"
0.2706,Event,ADDED,eval-conflicts-rho020-r0-132-2dp4b.18d53ee2465100c1,reason=Created count=1 msg=Created container: task
0.2709,Event,ADDED,eval-conflicts-rho020-r0-132-2dp4b.18d53ee24b627df0,reason=Started count=1 msg=Started container task
0.2711,Event,ADDED,eval-conflicts-rho020-r0-132.18d53ee1afd008de,reason=SuccessfulCreate count=1 msg=Created pod: eval-conflicts-rho020-r0-132-2dp4b
0.2712,Event,ADDED,eval-conflicts-rho020-r0-132.18d53ee7c93f88b2,reason=Completed count=1 msg=Job completed
0.2715,Event,ADDED,eval-conflicts-rho020-r0-133-mbd2v.18d53ee1eb3a75a1,reason=Scheduled count=None msg=Successfully assigned compute/eval-conflicts-rho020-r0-133-mbd2v to kind-worker2
0.2717,Event,ADDED,eval-conflicts-rho020-r0-133-mbd2v.18d53ee207d77760,"reason=Pulled count=1 msg=Container image ""busybox:musl"" already present on machine"
0.2719,Event,ADDED,eval-conflicts-rho020-r0-133-mbd2v.18d53ee208f875d6,reason=Created count=1 msg=Created container: task
0.2721,Event,ADDED,eval-conflicts-rho020-r0-133-mbd2v.18d53ee211e421ce,reason=Started count=1 msg=Started container task
0.2723,Event,ADDED,eval-conflicts-rho020-r0-133.18d53ee1eab1106d,reason=SuccessfulCreate count=1 msg=Created pod: eval-conflicts-rho020-r0-133-mbd2v
0.2724,Event,ADDED,eval-conflicts-rho020-r0-133.18d53ee7909a0d51,reason=Completed count=1 msg=Job completed
0.2726,Event,ADDED,eval-conflicts-rho020-r0-134-882l6.18d53ee227110d85,"reason=FailedScheduling count=None msg=0/6 nodes are available: 1 c_wall violated: 2 conflicting context pair(s) with node memory, 5 node(s) had untolerated taint(s). no new claims to deallocate, preemption: 0/6 nodes are available: 1 No preemption victims found for incoming pod, 5 Preemption is not helpful for scheduling."
0.2728,Event,ADDED,eval-conflicts-rho020-r0-134-882l6.18d53ee22c07cd25,reason=Scheduled count=None msg=Successfully assigned compute/eval-conflicts-rho020-r0-134-882l6 to kind-worker3
0.2729,Event,ADDED,eval-conflicts-rho020-r0-134-882l6.18d53ee2459a4367,"reason=Pulled count=1 msg=Container image ""busybox:musl"" already present on machine"
0.2731,Event,ADDED,eval-conflicts-rho020-r0-134-882l6.18d53ee2474e38ac,reason=Created count=1 msg=Created container: task
0.2733,Event,ADDED,eval-conflicts-rho020-r0-134-882l6.18d53ee24c745099,reason=Started count=1 msg=Started container task
0.2735,Event,ADDED,eval-conflicts-rho020-r0-134.18d53ee226b87fbe,reason=SuccessfulCreate count=1 msg=Created pod: eval-conflicts-rho020-r0-134-882l6
0.2737,Event,ADDED,eval-conflicts-rho020-r0-134.18d53ee7c89c21eb,reason=Completed count=1 msg=Job completed
0.2739,Event,ADDED,eval-conflicts-rho020-r0-135-lgh8r.18d53ee263c86038,reason=Scheduled count=None msg=Successfully assigned compute/eval-conflicts-rho020-r0-135-lgh8r to kind-worker2
0.2742,Event,ADDED,eval-conflicts-rho020-r0-135-lgh8r.18d53ee27e357427,"reason=Pulled count=1 msg=Container image ""busybox:musl"" already present on machine"
0.2744,Event,ADDED,eval-conflicts-rho020-r0-135-lgh8r.18d53ee27f51d2e8,reason=Created count=1 msg=Created container: task
0.2746,Event,ADDED,eval-conflicts-rho020-r0-135-lgh8r.18d53ee2815a4db2,reason=Started count=1 msg=Started container task
0.2747,Event,ADDED,eval-conflicts-rho020-r0-135.18d53ee263087b72,reason=SuccessfulCreate count=1 msg=Created pod: eval-conflicts-rho020-r0-135-lgh8r
0.275,Event,ADDED,eval-conflicts-rho020-r0-135.18d53ee7cc2e6368,reason=Completed count=1 msg=Job completed
0.2752,Event,ADDED,eval-conflicts-rho020-r0-136-jl6q9.18d53ee2a06e25b7,reason=Scheduled count=None msg=Successfully assigned compute/eval-conflicts-rho020-r0-136-jl6q9 to kind-worker3
0.2754,Event,ADDED,eval-conflicts-rho020-r0-136-jl6q9.18d53ee2ba64223c,"reason=Pulled count=1 msg=Container image ""busybox:musl"" already present on machine"
0.2755,Event,ADDED,eval-conflicts-rho020-r0-136-jl6q9.18d53ee2bb8a4dc4,reason=Created count=1 msg=Created container: task
0.2758,Event,ADDED,eval-conflicts-rho020-r0-136-jl6q9.18d53ee2bfe76740,reason=Started count=1 msg=Started container task
0.276,Event,ADDED,eval-conflicts-rho020-r0-136.18d53ee29f87856f,reason=SuccessfulCreate count=1 msg=Created pod: eval-conflicts-rho020-r0-136-jl6q9
0.2761,Event,ADDED,eval-conflicts-rho020-r0-136.18d53ee84036a18c,reason=Completed count=1 msg=Job completed
0.2766,Event,ADDED,eval-conflicts-rho020-r0-137-g776f.18d53ee2da7ef80f,reason=Scheduled count=None msg=Successfully assigned compute/eval-conflicts-rho020-r0-137-g776f to kind-worker2
0.2768,Event,ADDED,eval-conflicts-rho020-r0-137-g776f.18d53ee2f52a57d5,"reason=Pulled count=1 msg=Container image ""busybox:musl"" already present on machine"
0.2769,Event,ADDED,eval-conflicts-rho020-r0-137-g776f.18d53ee2f651371f,reason=Created count=1 msg=Created container: task
0.2771,Event,ADDED,eval-conflicts-rho020-r0-137-g776f.18d53ee2fd986416,reason=Started count=1 msg=Started container task
0.2774,Event,ADDED,eval-conflicts-rho020-r0-137.18d53ee2d9e21acd,reason=SuccessfulCreate count=1 msg=Created pod: eval-conflicts-rho020-r0-137-g776f
0.2776,Event,ADDED,eval-conflicts-rho020-r0-137.18d53ee88368c599,reason=Completed count=1 msg=Job completed
0.2777,Event,ADDED,eval-conflicts-rho020-r0-138-l5qfb.18d53ee31589fa74,"reason=FailedScheduling count=None msg=0/6 nodes are available: 1 c_wall violated: 1 conflicting context pair(s) with node memory, 5 node(s) had untolerated taint(s). no new claims to deallocate, preemption: 0/6 nodes are available: 1 No preemption victims found for incoming pod, 5 Preemption is not helpful for scheduling."
0.2781,Event,ADDED,eval-conflicts-rho020-r0-138-l5qfb.18d53ee316245d8d,"reason=FailedScheduling count=None msg=0/6 nodes are available: 1 c_wall violated: 1 conflicting context pair(s) with node memory, 5 node(s) had untolerated taint(s). no new claims to deallocate, preemption: 0/6 nodes are available: 1 No preemption victims found for incoming pod, 5 Preemption is not helpful for scheduling."
0.2783,Event,ADDED,eval-conflicts-rho020-r0-138-l5qfb.18d53ee479daf3e0,reason=Scheduled count=None msg=Successfully assigned compute/eval-conflicts-rho020-r0-138-l5qfb to kind-worker4
0.2785,Event,ADDED,eval-conflicts-rho020-r0-138-l5qfb.18d53ee494384536,"reason=Pulled count=1 msg=Container image ""busybox:musl"" already present on machine"
0.2787,Event,ADDED,eval-conflicts-rho020-r0-138-l5qfb.18d53ee4964533f2,reason=Created count=1 msg=Created container: task
0.279,Event,ADDED,eval-conflicts-rho020-r0-138-l5qfb.18d53ee49aa4270c,reason=Started count=1 msg=Started container task
0.2792,Event,ADDED,eval-conflicts-rho020-r0-138.18d53ee315436aee,reason=SuccessfulCreate count=1 msg=Created pod: eval-conflicts-rho020-r0-138-l5qfb
0.2793,Event,ADDED,eval-conflicts-rho020-r0-138.18d53eea30813af2,reason=Completed count=1 msg=Job completed
0.2796,Event,ADDED,eval-conflicts-rho020-r0-139-lbqbs.18d53ee353647c98,reason=Scheduled count=None msg=Successfully assigned compute/eval-conflicts-rho020-r0-139-lbqbs to kind-worker3
0.2798,Event,ADDED,eval-conflicts-rho020-r0-139-lbqbs.18d53ee36ec3ed53,"reason=Pulled count=1 msg=Container image ""busybox:musl"" already present on machine"
0.28,Event,ADDED,eval-conflicts-rho020-r0-139-lbqbs.18d53ee36fe55bbf,reason=Created count=1 msg=Created container: task
0.2802,Event,ADDED,eval-conflicts-rho020-r0-139-lbqbs.18d53ee373c1e09a,reason=Started count=1 msg=Started container task
0.2808,Event,ADDED,eval-conflicts-rho020-r0-139.18d53ee352b4e22f,reason=SuccessfulCreate count=1 msg=Created pod: eval-conflicts-rho020-r0-139-lbqbs
0.2811,Event,ADDED,eval-conflicts-rho020-r0-139.18d53ee8f3db753c,reason=Completed count=1 msg=Job completed
0.2813,Event,ADDED,eval-conflicts-rho020-r0-140-khlfz.18d53ee38dad65eb,"reason=FailedScheduling count=None msg=0/6 nodes are available: 1 c_wall violated: 2 conflicting context pair(s) with node memory, 5 node(s) had untolerated taint(s). no new claims to deallocate, preemption: 0/6 nodes are available: 1 No preemption victims found for incoming pod, 5 Preemption is not helpful for scheduling."
0.2817,Event,ADDED,eval-conflicts-rho020-r0-140-khlfz.18d53ee38e540e21,"reason=FailedScheduling count=None msg=0/6 nodes are available: 1 c_wall violated: 2 conflicting context pair(s) with node memory, 5 node(s) had untolerated taint(s). no new claims to deallocate, preemption: 0/6 nodes are available: 1 No preemption victims found for incoming pod, 5 Preemption is not helpful for scheduling."
0.2819,Event,ADDED,eval-conflicts-rho020-r0-140-khlfz.18d53ee4802bbece,"reason=FailedScheduling count=None msg=0/6 nodes are available: 1 c_wall violated: 1 conflicting context pair(s) with node memory, 1 c_wall violated: 2 conflicting context pair(s) with node memory, 4 node(s) had untolerated taint(s). no new claims to deallocate, preemption: 0/6 nodes are available: 2 No preemption victims found for incoming pod, 4 Preemption is not helpful for scheduling."
0.282,Event,ADDED,eval-conflicts-rho020-r0-140-khlfz.18d53ee5a751ce2a,reason=Scheduled count=None msg=Successfully assigned compute/eval-conflicts-rho020-r0-140-khlfz to kind-worker
0.2824,Event,ADDED,eval-conflicts-rho020-r0-140-khlfz.18d53ee5c5816865,"reason=Pulled count=1 msg=Container image ""busybox:musl"" already present on machine"
0.2825,Event,ADDED,eval-conflicts-rho020-r0-140-khlfz.18d53ee5c7e4a839,reason=Created count=1 msg=Created container: task
0.2827,Event,ADDED,eval-conflicts-rho020-r0-140-khlfz.18d53ee5cb710801,reason=Started count=1 msg=Started container task
0.2829,Event,ADDED,eval-conflicts-rho020-r0-140.18d53ee38d622052,reason=SuccessfulCreate count=1 msg=Created pod: eval-conflicts-rho020-r0-140-khlfz
0.2831,Event,ADDED,eval-conflicts-rho020-r0-140.18d53eeb6613615c,reason=Completed count=1 msg=Job completed
0.2833,Event,ADDED,eval-conflicts-rho020-r0-141-tpqwz.18d53ee3c7eaed03,"reason=FailedScheduling count=None msg=0/6 nodes are available: 1 c_wall violated: 1 conflicting context pair(s) with node memory, 5 node(s) had untolerated taint(s). no new claims to deallocate, preemption: 0/6 nodes are available: 1 No preemption victims found for incoming pod, 5 Preemption is not helpful for scheduling."
0.2835,Event,ADDED,eval-conflicts-rho020-r0-141-tpqwz.18d53ee3c87545ba,"reason=FailedScheduling count=None msg=0/6 nodes are available: 1 c_wall violated: 1 conflicting context pair(s) with node memory, 5 node(s) had untolerated taint(s). no new claims to deallocate, preemption: 0/6 nodes are available: 1 No preemption victims found for incoming pod, 5 Preemption is not helpful for scheduling."
0.2839,Event,ADDED,eval-conflicts-rho020-r0-141-tpqwz.18d53ee47fa605af,reason=Scheduled count=None msg=Successfully assigned compute/eval-conflicts-rho020-r0-141-tpqwz to kind-worker4
0.2841,Event,ADDED,eval-conflicts-rho020-r0-141-tpqwz.18d53ee49b3a66e8,"reason=Pulled count=1 msg=Container image ""busybox:musl"" already present on machine"
0.2842,Event,ADDED,eval-conflicts-rho020-r0-141-tpqwz.18d53ee49c49e7b9,reason=Created count=1 msg=Created container: task
0.2844,Event,ADDED,eval-conflicts-rho020-r0-141-tpqwz.18d53ee4a1a76cb6,reason=Started count=1 msg=Started container task
0.2847,Event,ADDED,eval-conflicts-rho020-r0-141.18d53ee3c79fc376,reason=SuccessfulCreate count=1 msg=Created pod: eval-conflicts-rho020-r0-141-tpqwz
0.2849,Event,ADDED,eval-conflicts-rho020-r0-141.18d53eea30582441,reason=Completed count=1 msg=Job completed
0.285,Event,ADDED,eval-conflicts-rho020-r0-142-8rh9p.18d53ee404d65b79,"reason=FailedScheduling count=None msg=0/6 nodes are available: 1 c_wall violated: 1 conflicting context pair(s) with node memory, 5 node(s) had untolerated taint(s). no new claims to deallocate, preemption: 0/6 nodes are available: 1 No preemption victims found for incoming pod, 5 Preemption is not helpful for scheduling."
0.2853,Event,ADDED,eval-conflicts-rho020-r0-142-8rh9p.18d53ee4056d137c,"reason=FailedScheduling count=None msg=0/6 nodes are available: 1 c_wall violated: 1 conflicting context pair(s) with node memory, 5 node(s) had untolerated taint(s). no new claims to deallocate, preemption: 0/6 nodes are available: 1 No preemption victims found for incoming pod, 5 Preemption is not helpful for scheduling."
0.2854,Event,ADDED,eval-conflicts-rho020-r0-142-8rh9p.18d53ee479aeb9a5,reason=Scheduled count=None msg=Successfully assigned compute/eval-conflicts-rho020-r0-142-8rh9p to kind-worker4
0.2856,Event,ADDED,eval-conflicts-rho020-r0-142-8rh9p.18d53ee49423b4b8,"reason=Pulled count=1 msg=Container image ""busybox:musl"" already present on machine"
0.2858,Event,ADDED,eval-conflicts-rho020-r0-142-8rh9p.18d53ee495c5e3b9,reason=Created count=1 msg=Created container: task
0.2861,Event,ADDED,eval-conflicts-rho020-r0-142-8rh9p.18d53ee49a244d0b,reason=Started count=1 msg=Started container task
0.2863,Event,ADDED,eval-conflicts-rho020-r0-142.18d53ee4048fc11e,reason=SuccessfulCreate count=1 msg=Created pod: eval-conflicts-rho020-r0-142-8rh9p
0.2864,Event,ADDED,eval-conflicts-rho020-r0-142.18d53ee9ee079b93,reason=Completed count=1 msg=Job completed
0.2867,Event,ADDED,eval-conflicts-rho020-r0-143-nx74g.18d53ee43fda0997,reason=Scheduled count=None msg=Successfully assigned compute/eval-conflicts-rho020-r0-143-nx74g to kind-worker3
0.2869,Event,ADDED,eval-conflicts-rho020-r0-143-nx74g.18d53ee4598e0750,"reason=Pulled count=1 msg=Container image ""busybox:musl"" already present on machine"
0.2871,Event,ADDED,eval-conflicts-rho020-r0-143-nx74g.18d53ee45a9d8f99,reason=Created count=1 msg=Created container: task
0.2873,Event,ADDED,eval-conflicts-rho020-r0-143-nx74g.18d53ee45cc80eb8,reason=Started count=1 msg=Started container task
0.2877,Event,ADDED,eval-conflicts-rho020-r0-143.18d53ee43f5324d6,reason=SuccessfulCreate count=1 msg=Created pod: eval-conflicts-rho020-r0-143-nx74g
0.2879,Event,ADDED,eval-conflicts-rho020-r0-143.18d53ee9ed79e25b,reason=Completed count=1 msg=Job completed
0.288,Event,ADDED,eval-conflicts-rho020-r0-144-m6z95.18d53ee47f721ecd,"reason=FailedScheduling count=None msg=0/6 nodes are available: 1 c_wall violated: 1 conflicting context pair(s) with node memory, 1 c_wall violated: 2 conflicting context pair(s) with node memory, 4 node(s) had untolerated taint(s). no new claims to deallocate, preemption: 0/6 nodes are available: 2 No preemption victims found for incoming pod, 4 Preemption is not helpful for scheduling."
0.2883,Event,ADDED,eval-conflicts-rho020-r0-144-m6z95.18d53ee48506e66c,"reason=FailedScheduling count=None msg=0/6 nodes are available: 1 c_wall violated: 1 conflicting context pair(s) with node memory, 1 c_wall violated: 2 conflicting context pair(s) with node memory, 4 node(s) had untolerated taint(s). no new claims to deallocate, preemption: 0/6 nodes are available: 2 No preemption victims found for incoming pod, 4 Preemption is not helpful for scheduling."
0.2884,Event,ADDED,eval-conflicts-rho020-r0-144-m6z95.18d53ee5adc0317a,reason=Scheduled count=None msg=Successfully assigned compute/eval-conflicts-rho020-r0-144-m6z95 to kind-worker
0.2886,Event,ADDED,eval-conflicts-rho020-r0-144-m6z95.18d53ee5cba30034,"reason=Pulled count=1 msg=Container image ""busybox:musl"" already present on machine"
0.289,Event,ADDED,eval-conflicts-rho020-r0-144-m6z95.18d53ee5cccb11a6,reason=Created count=1 msg=Created container: task
0.2891,Event,ADDED,eval-conflicts-rho020-r0-144-m6z95.18d53ee5d17893dc,reason=Started count=1 msg=Started container task
0.2893,Event,ADDED,eval-conflicts-rho020-r0-144.18d53ee47b5f1fe3,reason=SuccessfulCreate count=1 msg=Created pod: eval-conflicts-rho020-r0-144-m6z95
0.2895,Event,ADDED,eval-conflicts-rho020-r0-144.18d53eeb6687c103,reason=Completed count=1 msg=Job completed
0.2899,Event,ADDED,eval-conflicts-rho020-r0-145-qdx7m.18d53ee4b65d3c9f,"reason=FailedScheduling count=None msg=0/6 nodes are available: 1 c_wall violated: 1 conflicting context pair(s) with node memory, 1 c_wall violated: 2 conflicting context pair(s) with node memory, 4 node(s) had untolerated taint(s). no new claims to deallocate, preemption: 0/6 nodes are available: 2 No preemption victims found for incoming pod, 4 Preemption is not helpful for scheduling."
0.2901,Event,ADDED,eval-conflicts-rho020-r0-145-qdx7m.18d53ee4b882643d,"reason=FailedScheduling count=None msg=0/6 nodes are available: 1 c_wall violated: 1 conflicting context pair(s) with node memory, 1 c_wall violated: 2 conflicting context pair(s) with node memory, 4 node(s) had untolerated taint(s). no new claims to deallocate, preemption: 0/6 nodes are available: 2 No preemption victims found for incoming pod, 4 Preemption is not helpful for scheduling."
0.2902,Event,ADDED,eval-conflicts-rho020-r0-145-qdx7m.18d53ee5a46fcd67,reason=Scheduled count=None msg=Successfully assigned compute/eval-conflicts-rho020-r0-145-qdx7m to kind-worker
0.2904,Event,ADDED,eval-conflicts-rho020-r0-145-qdx7m.18d53ee5c5653026,"reason=Pulled count=1 msg=Container image ""busybox:musl"" already present on machine"
0.2906,Event,ADDED,eval-conflicts-rho020-r0-145-qdx7m.18d53ee5c7530f57,reason=Created count=1 msg=Created container: task
0.2908,Event,ADDED,eval-conflicts-rho020-r0-145-qdx7m.18d53ee5cb741e5f,reason=Started count=1 msg=Started container task
0.291,Event,ADDED,eval-conflicts-rho020-r0-145.18d53ee4b5f7fc62,reason=SuccessfulCreate count=1 msg=Created pod: eval-conflicts-rho020-r0-145-qdx7m
0.2913,Event,ADDED,eval-conflicts-rho020-r0-145.18d53eeb65f3aba8,reason=Completed count=1 msg=Job completed
0.2918,Event,ADDED,eval-conflicts-rho020-r0-146-lzdrf.18d53ee4f703b311,reason=Scheduled count=None msg=Successfully assigned compute/eval-conflicts-rho020-r0-146-lzdrf to kind-worker4
0.2919,Event,ADDED,eval-conflicts-rho020-r0-146-lzdrf.18d53ee51388ddb5,"reason=Pulled count=1 msg=Container image ""busybox:musl"" already present on machine"
0.2923,Event,ADDED,eval-conflicts-rho020-r0-146-lzdrf.18d53ee514af6f73,reason=Created count=1 msg=Created container: task
0.2925,Event,ADDED,eval-conflicts-rho020-r0-146-lzdrf.18d53ee51b30a938,reason=Started count=1 msg=Started container task
0.2927,Event,ADDED,eval-conflicts-rho020-r0-146.18d53ee4f5c7ff01,reason=SuccessfulCreate count=1 msg=Created pod: eval-conflicts-rho020-r0-146-lzdrf
0.2928,Event,ADDED,eval-conflicts-rho020-r0-146.18d53eea998a6032,reason=Completed count=1 msg=Job completed
0.2931,Event,ADDED,eval-conflicts-rho020-r0-147-lg9hb.18d53ee53a4a559b,reason=Scheduled count=None msg=Successfully assigned compute/eval-conflicts-rho020-r0-147-lg9hb to kind-worker3
0.2933,Event,ADDED,eval-conflicts-rho020-r0-147-lg9hb.18d53ee55d3b8bf5,"reason=Pulled count=1 msg=Container image ""busybox:musl"" already present on machine"
0.2935,Event,ADDED,eval-conflicts-rho020-r0-147-lg9hb.18d53ee55e6c586c,reason=Created count=1 msg=Created container: task
0.2936,Event,ADDED,eval-conflicts-rho020-r0-147-lg9hb.18d53ee5671d3fb5,reason=Started count=1 msg=Started container task
0.294,Event,ADDED,eval-conflicts-rho020-r0-147.18d53ee53139b9c4,reason=SuccessfulCreate count=1 msg=Created pod: eval-conflicts-rho020-r0-147-lg9hb
0.2946,Event,ADDED,eval-conflicts-rho020-r0-147.18d53eead5a68988,reason=Completed count=1 msg=Job completed
0.2948,Event,ADDED,eval-conflicts-rho020-r0-148-vdqmd.18d53ee56a2c9e78,reason=Scheduled count=None msg=Successfully assigned compute/eval-conflicts-rho020-r0-148-vdqmd to kind-worker4
0.2954,Event,ADDED,eval-conflicts-rho020-r0-148-vdqmd.18d53ee58528659e,"reason=Pulled count=1 msg=Container image ""busybox:musl"" already present on machine"
0.2958,Event,ADDED,eval-conflicts-rho020-r0-148-vdqmd.18d53ee5864c29fc,reason=Created count=1 msg=Created container: task
0.2961,Event,ADDED,eval-conflicts-rho020-r0-148-vdqmd.18d53ee58a6b5dba,reason=Started count=1 msg=Started container task
0.2963,Event,ADDED,eval-conflicts-rho020-r0-148.18d53ee5694fea46,reason=SuccessfulCreate count=1 msg=Created pod: eval-conflicts-rho020-r0-148-vdqmd
0.2966,Event,ADDED,eval-conflicts-rho020-r0-148.18d53eeb13fe23b6,reason=Completed count=1 msg=Job completed
0.2968,Event,ADDED,eval-conflicts-rho020-r0-149-b9gbz.18d53ee5a83bdfe9,reason=Scheduled count=None msg=Successfully assigned compute/eval-conflicts-rho020-r0-149-b9gbz to kind-worker4
0.297,Event,ADDED,eval-conflicts-rho020-r0-149-b9gbz.18d53ee5c56dd3a3,"reason=Pulled count=1 msg=Container image ""busybox:musl"" already present on machine"
0.2972,Event,ADDED,eval-conflicts-rho020-r0-149-b9gbz.18d53ee5c7294649,reason=Created count=1 msg=Created container: task
0.2974,Event,ADDED,eval-conflicts-rho020-r0-149-b9gbz.18d53ee5cb533624,reason=Started count=1 msg=Started container task
0.2976,Event,ADDED,eval-conflicts-rho020-r0-149.18d53ee5a65cb950,reason=SuccessfulCreate count=1 msg=Created pod: eval-conflicts-rho020-r0-149-b9gbz
0.2977,Event,ADDED,eval-conflicts-rho020-r0-149.18d53eeb52dc3109,reason=Completed count=1 msg=Job completed
0.2979,Event,ADDED,eval-conflicts-rho020-r0-150-pmntd.18d53ee5e10acee2,reason=Scheduled count=None msg=Successfully assigned compute/eval-conflicts-rho020-r0-150-pmntd to kind-worker
0.2981,Event,ADDED,eval-conflicts-rho020-r0-150-pmntd.18d53ee5fa9b5b34,"reason=Pulled count=1 msg=Container image ""busybox:musl"" already present on machine"
0.2982,Event,ADDED,eval-conflicts-rho020-r0-150-pmntd.18d53ee5fbd50d50,reason=Created count=1 msg=Created container: task
0.2984,Event,ADDED,eval-conflicts-rho020-r0-150-pmntd.18d53ee5fde6d9bc,reason=Started count=1 msg=Started container task
0.2986,Event,ADDED,eval-conflicts-rho020-r0-150.18d53ee5e02ba7d0,reason=SuccessfulCreate count=1 msg=Created pod: eval-conflicts-rho020-r0-150-pmntd
0.2987,Event,ADDED,eval-conflicts-rho020-r0-150.18d53eeb66f8044f,reason=Completed count=1 msg=Job completed
0.2989,Event,ADDED,eval-conflicts-rho020-r0-151-5kxth.18d53ee61c9e5fb0,reason=Scheduled count=None msg=Successfully assigned compute/eval-conflicts-rho020-r0-151-5kxth to kind-worker4
0.2991,Event,ADDED,eval-conflicts-rho020-r0-151-5kxth.18d53ee635b066d2,"reason=Pulled count=1 msg=Container image ""busybox:musl"" already present on machine"
0.2992,Event,ADDED,eval-conflicts-rho020-r0-151-5kxth.18d53ee636d5a927,reason=Created count=1 msg=Created container: task
0.2994,Event,ADDED,eval-conflicts-rho020-r0-151-5kxth.18d53ee6394298f2,reason=Started count=1 msg=Started container task
0.2996,Event,ADDED,eval-conflicts-rho020-r0-151.18d53ee61bc456af,reason=SuccessfulCreate count=1 msg=Created pod: eval-conflicts-rho020-r0-151-5kxth
0.2997,Event,ADDED,eval-conflicts-rho020-r0-151.18d53eebcc266c5e,reason=Completed count=1 msg=Job completed
0.2999,Event,ADDED,eval-conflicts-rho020-r0-152-flr65.18d53ee6589cdf7a,reason=Scheduled count=None msg=Successfully assigned compute/eval-conflicts-rho020-r0-152-flr65 to kind-worker
0.3,Event,ADDED,eval-conflicts-rho020-r0-152-flr65.18d53ee671bdf55d,"reason=Pulled count=1 msg=Container image ""busybox:musl"" already present on machine"
0.3002,Event,ADDED,eval-conflicts-rho020-r0-152-flr65.18d53ee672d61617,reason=Created count=1 msg=Created container: task
0.3004,Event,ADDED,eval-conflicts-rho020-r0-152-flr65.18d53ee6751cdf99,reason=Started count=1 msg=Started container task
0.3005,Event,ADDED,eval-conflicts-rho020-r0-152.18d53ee657829d8b,reason=SuccessfulCreate count=1 msg=Created pod: eval-conflicts-rho020-r0-152-flr65
0.3007,Event,ADDED,eval-conflicts-rho020-r0-152.18d53eebde74ce69,reason=Completed count=1 msg=Job completed
0.3009,Event,ADDED,eval-conflicts-rho020-r0-153-77zpx.18d53ee69589c070,reason=Scheduled count=None msg=Successfully assigned compute/eval-conflicts-rho020-r0-153-77zpx to kind-worker4
0.301,Event,ADDED,eval-conflicts-rho020-r0-153-77zpx.18d53ee6b0b4418d,"reason=Pulled count=1 msg=Container image ""busybox:musl"" already present on machine"
0.3012,Event,ADDED,eval-conflicts-rho020-r0-153-77zpx.18d53ee6b1c57efd,reason=Created count=1 msg=Created container: task
0.3014,Event,ADDED,eval-conflicts-rho020-r0-153-77zpx.18d53ee6b6371655,reason=Started count=1 msg=Started container task
0.3016,Event,ADDED,eval-conflicts-rho020-r0-153.18d53ee69420dd29,reason=SuccessfulCreate count=1 msg=Created pod: eval-conflicts-rho020-r0-153-77zpx
0.3018,Event,ADDED,eval-conflicts-rho020-r0-153.18d53eec41ea2316,reason=Completed count=1 msg=Job completed
0.3019,Event,ADDED,eval-conflicts-rho020-r0-154-jj8p6.18d53ee6d0bdbedf,reason=Scheduled count=None msg=Successfully assigned compute/eval-conflicts-rho020-r0-154-jj8p6 to kind-worker3
0.3022,Event,ADDED,eval-conflicts-rho020-r0-154-jj8p6.18d53ee6ea91a00a,"reason=Pulled count=1 msg=Container image ""busybox:musl"" already present on machine"
0.3025,Event,ADDED,eval-conflicts-rho020-r0-154-jj8p6.18d53ee6eba89f0e,reason=Created count=1 msg=Created container: task
0.3027,Event,ADDED,eval-conflicts-rho020-r0-154-jj8p6.18d53ee6f09b9cb4,reason=Started count=1 msg=Started container task
0.3028,Event,ADDED,eval-conflicts-rho020-r0-154.18d53ee6cfb3404f,reason=SuccessfulCreate count=1 msg=Created pod: eval-conflicts-rho020-r0-154-jj8p6
0.3031,Event,ADDED,eval-conflicts-rho020-r0-154.18d53eec756e8f7d,reason=Completed count=1 msg=Job completed
0.3032,Event,ADDED,eval-conflicts-rho020-r0-155-8wtkh.18d53ee70ba1af30,reason=Scheduled count=None msg=Successfully assigned compute/eval-conflicts-rho020-r0-155-8wtkh to kind-worker4
0.3034,Event,ADDED,eval-conflicts-rho020-r0-155-8wtkh.18d53ee724a7bf4c,"reason=Pulled count=1 msg=Container image ""busybox:musl"" already present on machine"
0.3036,Event,ADDED,eval-conflicts-rho020-r0-155-8wtkh.18d53ee725dc5876,reason=Created count=1 msg=Created container: task
0.3037,Event,ADDED,eval-conflicts-rho020-r0-155-8wtkh.18d53ee7281ef928,reason=Started count=1 msg=Started container task
0.3039,Event,ADDED,eval-conflicts-rho020-r0-155.18d53ee70af7f744,reason=SuccessfulCreate count=1 msg=Created pod: eval-conflicts-rho020-r0-155-8wtkh
0.3041,Event,ADDED,eval-conflicts-rho020-r0-155.18d53eecb4c5a24d,reason=Completed count=1 msg=Job completed
0.3042,Event,ADDED,eval-conflicts-rho020-r0-156-l64rm.18d53ee7468d2ca0,reason=Scheduled count=None msg=Successfully assigned compute/eval-conflicts-rho020-r0-156-l64rm to kind-worker4
0.3044,Event,ADDED,eval-conflicts-rho020-r0-156-l64rm.18d53ee760249fe3,"reason=Pulled count=1 msg=Container image ""busybox:musl"" already present on machine"
0.3046,Event,ADDED,eval-conflicts-rho020-r0-156-l64rm.18d53ee761608082,reason=Created count=1 msg=Created container: task
0.3047,Event,ADDED,eval-conflicts-rho020-r0-156-l64rm.18d53ee7639b414b,reason=Started count=1 msg=Started container task
0.3049,Event,ADDED,eval-conflicts-rho020-r0-156.18d53ee745cf6cc9,reason=SuccessfulCreate count=1 msg=Created pod: eval-conflicts-rho020-r0-156-l64rm
0.3051,Event,ADDED,eval-conflicts-rho020-r0-156.18d53eecf1333ff1,reason=Completed count=1 msg=Job completed
0.3052,Event,ADDED,eval-conflicts-rho020-r0-157-7blxx.18d53ee7827714a4,reason=Scheduled count=None msg=Successfully assigned compute/eval-conflicts-rho020-r0-157-7blxx to kind-worker
0.3054,Event,ADDED,eval-conflicts-rho020-r0-157-7blxx.18d53ee79c9fd943,"reason=Pulled count=1 msg=Container image ""busybox:musl"" already present on machine"
0.3056,Event,ADDED,eval-conflicts-rho020-r0-157-7blxx.18d53ee79dc2a5c2,reason=Created count=1 msg=Created container: task
0.3057,Event,ADDED,eval-conflicts-rho020-r0-157-7blxx.18d53ee7a0bf8022,reason=Started count=1 msg=Started container task
0.3059,Event,ADDED,eval-conflicts-rho020-r0-157.18d53ee781b95774,reason=SuccessfulCreate count=1 msg=Created pod: eval-conflicts-rho020-r0-157-7blxx
0.3061,Event,ADDED,eval-conflicts-rho020-r0-157.18d53eed0e448b00,reason=Completed count=1 msg=Job completed
0.3062,Event,ADDED,eval-conflicts-rho020-r0-158-g6gzd.18d53ee7bd953228,"reason=FailedScheduling count=None msg=0/6 nodes are available: 2 c_wall violated: 1 conflicting context pair(s) with node memory, 4 node(s) had untolerated taint(s). no new claims to deallocate, preemption: 0/6 nodes are available: 2 No preemption victims found for incoming pod, 4 Preemption is not helpful for scheduling."
0.3064,Event,ADDED,eval-conflicts-rho020-r0-158-g6gzd.18d53ee7be7480af,"reason=FailedScheduling count=None msg=0/6 nodes are available: 2 c_wall violated: 1 conflicting context pair(s) with node memory, 4 node(s) had untolerated taint(s). no new claims to deallocate, preemption: 0/6 nodes are available: 2 No preemption victims found for incoming pod, 4 Preemption is not helpful for scheduling."
0.3066,Event,ADDED,eval-conflicts-rho020-r0-158-g6gzd.18d53ee925fe2c85,"reason=FailedScheduling count=None msg=0/6 nodes are available: 1 c_wall violated: 1 conflicting context pair(s) with node memory, 5 node(s) had untolerated taint(s). no new claims to deallocate, preemption: 0/6 nodes are available: 1 No preemption victims found for incoming pod, 5 Preemption is not helpful for scheduling."
0.3068,Event,ADDED,eval-conflicts-rho020-r0-158-g6gzd.18d53ee9892ec510,reason=Scheduled count=None msg=Successfully assigned compute/eval-conflicts-rho020-r0-158-g6gzd to kind-worker5
0.307,Event,ADDED,eval-conflicts-rho020-r0-158-g6gzd.18d53ee9a12fcf0f,"reason=Pulled count=1 msg=Container image ""busybox:musl"" already present on machine"
0.3072,Event,ADDED,eval-conflicts-rho020-r0-158-g6gzd.18d53ee9a2f539e9,reason=Created count=1 msg=Created container: task
0.3074,Event,ADDED,eval-conflicts-rho020-r0-158-g6gzd.18d53ee9ab146d78,reason=Started count=1 msg=Started container task
0.3077,Event,ADDED,eval-conflicts-rho020-r0-158.18d53ee7bd185902,reason=SuccessfulCreate count=1 msg=Created pod: eval-conflicts-rho020-r0-158-g6gzd
0.3078,Event,ADDED,eval-conflicts-rho020-r0-158.18d53eeefd49d0d8,reason=Completed count=1 msg=Job completed
0.308,Event,ADDED,eval-conflicts-rho020-r0-159-zvbvl.18d53ee7f9277a6b,"reason=FailedScheduling count=None msg=0/6 nodes are available: 2 c_wall violated: 1 conflicting context pair(s) with node memory, 4 node(s) had untolerated taint(s). no new claims to deallocate, preemption: 0/6 nodes are available: 2 No preemption victims found for incoming pod, 4 Preemption is not helpful for scheduling."
0.3082,Event,ADDED,eval-conflicts-rho020-r0-159-zvbvl.18d53ee7f9e6163d,"reason=FailedScheduling count=None msg=0/6 nodes are available: 2 c_wall violated: 1 conflicting context pair(s) with node memory, 4 node(s) had untolerated taint(s). no new claims to deallocate, preemption: 0/6 nodes are available: 2 No preemption victims found for incoming pod, 4 Preemption is not helpful for scheduling."
0.3084,Event,ADDED,eval-conflicts-rho020-r0-159-zvbvl.18d53ee92724191d,"reason=FailedScheduling count=None msg=0/6 nodes are available: 1 c_wall violated: 1 conflicting context pair(s) with node memory, 5 node(s) had untolerated taint(s). no new claims to deallocate, preemption: 0/6 nodes are available: 1 No preemption victims found for incoming pod, 5 Preemption is not helpful for scheduling."
0.3085,Event,ADDED,eval-conflicts-rho020-r0-159-zvbvl.18d53ee983a77a27,reason=Scheduled count=None msg=Successfully assigned compute/eval-conflicts-rho020-r0-159-zvbvl to kind-worker5
0.3087,Event,ADDED,eval-conflicts-rho020-r0-159-zvbvl.18d53ee99ea71515,"reason=Pulled count=1 msg=Container image ""busybox:musl"" already present on machine"
0.3089,Event,ADDED,eval-conflicts-rho020-r0-159-zvbvl.18d53ee9a0200adf,reason=Created count=1 msg=Created container: task
0.309,Event,ADDED,eval-conflicts-rho020-r0-159-zvbvl.18d53ee9a27698c9,reason=Started count=1 msg=Started container task
0.3092,Event,ADDED,eval-conflicts-rho020-r0-159.18d53ee7f8bbdd7a,reason=SuccessfulCreate count=1 msg=Created pod: eval-conflicts-rho020-r0-159-zvbvl
0.3094,Event,ADDED,eval-conflicts-rho020-r0-159.18d53eef42acb0f7,reason=Completed count=1 msg=Job completed
0.3095,Event,ADDED,eval-conflicts-rho020-r0-160-85gzp.18d53ee83500f1ac,reason=Scheduled count=None msg=Successfully assigned compute/eval-conflicts-rho020-r0-160-85gzp to kind-worker4
0.3097,Event,ADDED,eval-conflicts-rho020-r0-160-85gzp.18d53ee850d9ed6a,"reason=Pulled count=1 msg=Container image ""busybox:musl"" already present on machine"
0.3099,Event,ADDED,eval-conflicts-rho020-r0-160-85gzp.18d53ee851f09273,reason=Created count=1 msg=Created container: task
0.3101,Event,ADDED,eval-conflicts-rho020-r0-160-85gzp.18d53ee855e1918c,reason=Started count=1 msg=Started container task
0.3103,Event,ADDED,eval-conflicts-rho020-r0-160.18d53ee8344f9856,reason=SuccessfulCreate count=1 msg=Created pod: eval-conflicts-rho020-r0-160-85gzp
0.3104,Event,ADDED,eval-conflicts-rho020-r0-160.18d53eede2d5d964,reason=Completed count=1 msg=Job completed
0.3106,Event,ADDED,eval-conflicts-rho020-r0-161-j5fqr.18d53ee871ba9896,reason=Scheduled count=None msg=Successfully assigned compute/eval-conflicts-rho020-r0-161-j5fqr to kind-worker
0.3108,Event,ADDED,eval-conflicts-rho020-r0-161-j5fqr.18d53ee88ac94a2b,"reason=Pulled count=1 msg=Container image ""busybox:musl"" already present on machine"
0.3109,Event,ADDED,eval-conflicts-rho020-r0-161-j5fqr.18d53ee88bdc3840,reason=Created count=1 msg=Created container: task
0.3111,Event,ADDED,eval-conflicts-rho020-r0-161-j5fqr.18d53ee88dfb2c36,reason=Started count=1 msg=Started container task
0.3113,Event,ADDED,eval-conflicts-rho020-r0-161.18d53ee8707db9f9,reason=SuccessfulCreate count=1 msg=Created pod: eval-conflicts-rho020-r0-161-j5fqr
0.3115,Event,ADDED,eval-conflicts-rho020-r0-161.18d53eedfeec9fe5,reason=Completed count=1 msg=Job completed
0.3117,Event,ADDED,eval-conflicts-rho020-r0-162-gn5d4.18d53ee8ac7495f3,"reason=FailedScheduling count=None msg=0/6 nodes are available: 2 c_wall violated: 1 conflicting context pair(s) with node memory, 4 node(s) had untolerated taint(s). no new claims to deallocate, preemption: 0/6 nodes are available: 2 No preemption victims found for incoming pod, 4 Preemption is not helpful for scheduling."
0.3118,Event,ADDED,eval-conflicts-rho020-r0-162-gn5d4.18d53ee8ad417c32,"reason=FailedScheduling count=None msg=0/6 nodes are available: 2 c_wall violated: 1 conflicting context pair(s) with node memory, 4 node(s) had untolerated taint(s). no new claims to deallocate, preemption: 0/6 nodes are available: 2 No preemption victims found for incoming pod, 4 Preemption is not helpful for scheduling."
0.3122,Event,ADDED,eval-conflicts-rho020-r0-162-gn5d4.18d53ee925cd644c,"reason=FailedScheduling count=None msg=0/6 nodes are available: 1 c_wall violated: 1 conflicting context pair(s) with node memory, 5 node(s) had untolerated taint(s). no new claims to deallocate, preemption: 0/6 nodes are available: 1 No preemption victims found for incoming pod, 5 Preemption is not helpful for scheduling."
0.3124,Event,ADDED,eval-conflicts-rho020-r0-162-gn5d4.18d53ee9870d616a,reason=Scheduled count=None msg=Successfully assigned compute/eval-conflicts-rho020-r0-162-gn5d4 to kind-worker5
0.3125,Event,ADDED,eval-conflicts-rho020-r0-162-gn5d4.18d53ee9a1131394,"reason=Pulled count=1 msg=Container image ""busybox:musl"" already present on machine"
0.3129,Event,ADDED,eval-conflicts-rho020-r0-162-gn5d4.18d53ee9a2da0ffc,reason=Created count=1 msg=Created container: task
0.313,Event,ADDED,eval-conflicts-rho020-r0-162-gn5d4.18d53ee9ab167cf4,reason=Started count=1 msg=Started container task
0.3132,Event,ADDED,eval-conflicts-rho020-r0-162.18d53ee8ac0fd8c1,reason=SuccessfulCreate count=1 msg=Created pod: eval-conflicts-rho020-r0-162-gn5d4
0.3134,Event,ADDED,eval-conflicts-rho020-r0-162.18d53eef42aaba6e,reason=Completed count=1 msg=Job completed
0.3136,Event,ADDED,eval-conflicts-rho020-r0-163-qh4mc.18d53ee8e994e1b7,reason=Scheduled count=None msg=Successfully assigned compute/eval-conflicts-rho020-r0-163-qh4mc to kind-worker4
0.3138,Event,ADDED,eval-conflicts-rho020-r0-163-qh4mc.18d53ee905de98ff,"reason=Pulled count=1 msg=Container image ""busybox:musl"" already present on machine"
0.3139,Event,ADDED,eval-conflicts-rho020-r0-163-qh4mc.18d53ee90737cce1,reason=Created count=1 msg=Created container: task
0.3141,Event,ADDED,eval-conflicts-rho020-r0-163-qh4mc.18d53ee90bcb97f6,reason=Started count=1 msg=Started container task
0.3143,Event,ADDED,eval-conflicts-rho020-r0-163.18d53ee8e8dbc6aa,reason=SuccessfulCreate count=1 msg=Created pod: eval-conflicts-rho020-r0-163-qh4mc
0.3145,Event,ADDED,eval-conflicts-rho020-r0-163.18d53eee9a1d33d5,reason=Completed count=1 msg=Job completed
0.3146,Event,ADDED,eval-conflicts-rho020-r0-164-wplhn.18d53ee924d961a1,"reason=FailedScheduling count=None msg=0/6 nodes are available: 1 c_wall violated: 1 conflicting context pair(s) with node memory, 5 node(s) had untolerated taint(s). no new claims to deallocate, preemption: 0/6 nodes are available: 1 No preemption victims found for incoming pod, 5 Preemption is not helpful for scheduling."
0.3148,Event,ADDED,eval-conflicts-rho020-r0-164-wplhn.18d53ee92629abae,"reason=FailedScheduling count=None msg=0/6 nodes are available: 1 c_wall violated: 1 conflicting context pair(s) with node memory, 5 node(s) had untolerated taint(s). no new claims to deallocate, preemption: 0/6 nodes are available: 1 No preemption victims found for incoming pod, 5 Preemption is not helpful for scheduling."
0.315,Event,ADDED,eval-conflicts-rho020-r0-164-wplhn.18d53ee993b60a4b,"reason=FailedScheduling count=None msg=0/6 nodes are available: 2 c_wall violated: 1 conflicting context pair(s) with node memory, 4 node(s) had untolerated taint(s). no new claims to deallocate, preemption: 0/6 nodes are available: 2 No preemption victims found for incoming pod, 4 Preemption is not helpful for scheduling."
0.3152,Event,ADDED,eval-conflicts-rho020-r0-164-wplhn.18d53eea484a3500,"reason=FailedScheduling count=None msg=0/6 nodes are available: 1 c_wall violated: 1 conflicting context pair(s) with node memory, 5 node(s) had untolerated taint(s). no new claims to deallocate, preemption: 0/6 nodes are available: 1 No preemption victims found for incoming pod, 5 Preemption is not helpful for scheduling."
0.3153,Event,ADDED,eval-conflicts-rho020-r0-164-wplhn.18d53eec88e938e3,reason=Scheduled count=None msg=Successfully assigned compute/eval-conflicts-rho020-r0-164-wplhn to kind-worker2
0.3155,Event,ADDED,eval-conflicts-rho020-r0-164-wplhn.18d53eecbde122d2,"reason=Pulled count=1 msg=Container image ""busybox:musl"" already present on machine"
0.3157,Event,ADDED,eval-conflicts-rho020-r0-164-wplhn.18d53eecc0878233,reason=Created count=1 msg=Created container: task
0.3158,Event,ADDED,eval-conflicts-rho020-r0-164-wplhn.18d53eecc6c6c346,reason=Started count=1 msg=Started container task
0.316,Event,ADDED,eval-conflicts-rho020-r0-164.18d53ee92409ed09,reason=SuccessfulCreate count=1 msg=Created pod: eval-conflicts-rho020-r0-164-wplhn
0.3161,Event,ADDED,eval-conflicts-rho020-r0-164.18d53ef21ad1643a,reason=Completed count=1 msg=Job completed
0.3163,Event,ADDED,eval-conflicts-rho020-r0-165-jwgns.18d53ee95f88d33c,"reason=FailedScheduling count=None msg=0/6 nodes are available: 1 c_wall violated: 1 conflicting context pair(s) with node memory, 5 node(s) had untolerated taint(s). no new claims to deallocate, preemption: 0/6 nodes are available: 1 No preemption victims found for incoming pod, 5 Preemption is not helpful for scheduling."
0.3165,Event,ADDED,eval-conflicts-rho020-r0-165-jwgns.18d53ee960031547,"reason=FailedScheduling count=None msg=0/6 nodes are available: 1 c_wall violated: 1 conflicting context pair(s) with node memory, 5 node(s) had untolerated taint(s). no new claims to deallocate, preemption: 0/6 nodes are available: 1 No preemption victims found for incoming pod, 5 Preemption is not helpful for scheduling."
0.3167,Event,ADDED,eval-conflicts-rho020-r0-165-jwgns.18d53ee983d0884a,reason=Scheduled count=None msg=Successfully assigned compute/eval-conflicts-rho020-r0-165-jwgns to kind-worker5
0.3168,Event,ADDED,eval-conflicts-rho020-r0-165-jwgns.18d53ee99e2dea74,"reason=Pulled count=1 msg=Container image ""busybox:musl"" already present on machine"
0.317,Event,ADDED,eval-conflicts-rho020-r0-165-jwgns.18d53ee99fca4d1b,reason=Created count=1 msg=Created container: task
0.3172,Event,ADDED,eval-conflicts-rho020-r0-165-jwgns.18d53ee9a2214c14,reason=Started count=1 msg=Started container task
0.3173,Event,ADDED,eval-conflicts-rho020-r0-165.18d53ee95f452d82,reason=SuccessfulCreate count=1 msg=Created pod: eval-conflicts-rho020-r0-165-jwgns
0.3176,Event,ADDED,eval-conflicts-rho020-r0-165.18d53eef42e37b92,reason=Completed count=1 msg=Job completed
0.3177,Event,ADDED,eval-conflicts-rho020-r0-166-w85s7.18d53ee99b08b7eb,reason=Scheduled count=None msg=Successfully assigned compute/eval-conflicts-rho020-r0-166-w85s7 to kind-worker5
0.3179,Event,ADDED,eval-conflicts-rho020-r0-166-w85s7.18d53ee9bbe8d4f6,"reason=Pulled count=1 msg=Container image ""busybox:musl"" already present on machine"
0.318,Event,ADDED,eval-conflicts-rho020-r0-166-w85s7.18d53ee9bcffa741,reason=Created count=1 msg=Created container: task
0.3182,Event,ADDED,eval-conflicts-rho020-r0-166-w85s7.18d53ee9c3febe60,reason=Started count=1 msg=Started container task
0.3184,Event,ADDED,eval-conflicts-rho020-r0-166.18d53ee99a64e20f,reason=SuccessfulCreate count=1 msg=Created pod: eval-conflicts-rho020-r0-166-w85s7
0.3186,Event,ADDED,eval-conflicts-rho020-r0-166.18d53eef42ad2a9d,reason=Completed count=1 msg=Job completed
0.3188,Event,ADDED,eval-conflicts-rho020-r0-167-fkh6m.18d53ee9e4715cf6,reason=Scheduled count=None msg=Successfully assigned compute/eval-conflicts-rho020-r0-167-fkh6m to kind-worker5
0.319,Event,ADDED,eval-conflicts-rho020-r0-167-fkh6m.18d53eea06fa0ca7,"reason=Pulled count=1 msg=Container image ""busybox:musl"" already present on machine"
0.3191,Event,ADDED,eval-conflicts-rho020-r0-167-fkh6m.18d53eea0813a58a,reason=Created count=1 msg=Created container: task
0.3193,Event,ADDED,eval-conflicts-rho020-r0-167-fkh6m.18d53eea13326139,reason=Started count=1 msg=Started container task
0.3195,Event,ADDED,eval-conflicts-rho020-r0-167.18d53ee9d92e6869,reason=SuccessfulCreate count=1 msg=Created pod: eval-conflicts-rho020-r0-167-fkh6m
0.3196,Event,ADDED,eval-conflicts-rho020-r0-167.18d53eef82635bb0,reason=Completed count=1 msg=Job completed
0.3198,Event,ADDED,eval-conflicts-rho020-r0-168-q4ndq.18d53eea15e9929c,reason=Scheduled count=None msg=Successfully assigned compute/eval-conflicts-rho020-r0-168-q4ndq to kind-worker5
0.3199,Event,ADDED,eval-conflicts-rho020-r0-168-q4ndq.18d53eea3a5791e0,"reason=Pulled count=1 msg=Container image ""busybox:musl"" already present on machine"
0.3201,Event,ADDED,eval-conflicts-rho020-r0-168-q4ndq.18d53eea3b5de7ae,reason=Created count=1 msg=Created container: task
0.3203,Event,ADDED,eval-conflicts-rho020-r0-168-q4ndq.18d53eea40b61b5a,reason=Started count=1 msg=Started container task
0.3204,Event,ADDED,eval-conflicts-rho020-r0-168.18d53eea14fdba39,reason=SuccessfulCreate count=1 msg=Created pod: eval-conflicts-rho020-r0-168-q4ndq
0.3206,Event,ADDED,eval-conflicts-rho020-r0-168.18d53eefc3989167,reason=Completed count=1 msg=Job completed
0.3208,Event,ADDED,eval-conflicts-rho020-r0-169-dfgp7.18d53eea4dcd0cbb,"reason=FailedScheduling count=None msg=0/6 nodes are available: 1 c_wall violated: 2 conflicting context pair(s) with node memory, 5 node(s) had untolerated taint(s). no new claims to deallocate, preemption: 0/6 nodes are available: 1 No preemption victims found for incoming pod, 5 Preemption is not helpful for scheduling."
0.3209,Event,ADDED,eval-conflicts-rho020-r0-169-dfgp7.18d53eea4e435fbd,"reason=FailedScheduling count=None msg=0/6 nodes are available: 1 c_wall violated: 2 conflicting context pair(s) with node memory, 5 node(s) had untolerated taint(s). no new claims to deallocate, preemption: 0/6 nodes are available: 1 No preemption victims found for incoming pod, 5 Preemption is not helpful for scheduling."
0.3214,Event,ADDED,eval-conflicts-rho020-r0-169-dfgp7.18d53eec8e0792ee,"reason=FailedScheduling count=None msg=0/6 nodes are available: 1 c_wall violated: 1 conflicting context pair(s) with node memory, 1 c_wall violated: 2 conflicting context pair(s) with node memory, 4 node(s) had untolerated taint(s). no new claims to deallocate, preemption: 0/6 nodes are available: 2 No preemption victims found for incoming pod, 4 Preemption is not helpful for scheduling."
0.3216,Event,ADDED,eval-conflicts-rho020-r0-169-dfgp7.18d53eee30859f2f,"reason=FailedScheduling count=None msg=0/6 nodes are available: 1 c_wall violated: 1 conflicting context pair(s) with node memory, 5 node(s) had untolerated taint(s). no new claims to deallocate, preemption: 0/6 nodes are available: 1 No preemption victims found for incoming pod, 5 Preemption is not helpful for scheduling."
0.3217,Event,ADDED,eval-conflicts-rho020-r0-169-dfgp7.18d53eef0dcf6db5,reason=Scheduled count=None msg=Successfully assigned compute/eval-conflicts-rho020-r0-169-dfgp7 to kind-worker
0.3219,Event,ADDED,eval-conflicts-rho020-r0-169-dfgp7.18d53eef2810dbba,"reason=Pulled count=1 msg=Container image ""busybox:musl"" already present on machine"
0.3221,Event,ADDED,eval-conflicts-rho020-r0-169-dfgp7.18d53eef29ff782c,reason=Created count=1 msg=Created container: task
0.3223,Event,ADDED,eval-conflicts-rho020-r0-169-dfgp7.18d53eef3307ae61,reason=Started count=1 msg=Started container task
0.3225,Event,ADDED,eval-conflicts-rho020-r0-169.18d53eea4d92932c,reason=SuccessfulCreate count=1 msg=Created pod: eval-conflicts-rho020-r0-169-dfgp7
0.3228,Event,ADDED,eval-conflicts-rho020-r0-169.18d53ef4c3a4bbef,reason=Completed count=1 msg=Job completed
0.3229,Event,ADDED,eval-conflicts-rho020-r0-170-kshcb.18d53eea88e28e03,reason=Scheduled count=None msg=Successfully assigned compute/eval-conflicts-rho020-r0-170-kshcb to kind-worker5
0.3231,Event,ADDED,eval-conflicts-rho020-r0-170-kshcb.18d53eeaa1b3bb78,"reason=Pulled count=1 msg=Container image ""busybox:musl"" already present on machine"
0.3233,Event,ADDED,eval-conflicts-rho020-r0-170-kshcb.18d53eeaa2d511af,reason=Created count=1 msg=Created container: task
0.3236,Event,ADDED,eval-conflicts-rho020-r0-170-kshcb.18d53eeaa5229647,reason=Started count=1 msg=Started container task
0.3238,Event,ADDED,eval-conflicts-rho020-r0-170.18d53eea8866b33b,reason=SuccessfulCreate count=1 msg=Created pod: eval-conflicts-rho020-r0-170-kshcb
0.3239,Event,ADDED,eval-conflicts-rho020-r0-170.18d53ef028d609ba,reason=Completed count=1 msg=Job completed
0.3242,Event,ADDED,eval-conflicts-rho020-r0-171-96fjh.18d53eeac43da50e,"reason=FailedScheduling count=None msg=0/6 nodes are available: 1 c_wall violated: 1 conflicting context pair(s) with node memory, 5 node(s) had untolerated taint(s). no new claims to deallocate, preemption: 0/6 nodes are available: 1 No preemption victims found for incoming pod, 5 Preemption is not helpful for scheduling."
0.3244,Event,ADDED,eval-conflicts-rho020-r0-171-96fjh.18d53eeac4d05759,"reason=FailedScheduling count=None msg=0/6 nodes are available: 1 c_wall violated: 1 conflicting context pair(s) with node memory, 5 node(s) had untolerated taint(s). no new claims to deallocate, preemption: 0/6 nodes are available: 1 No preemption victims found for incoming pod, 5 Preemption is not helpful for scheduling."
0.3245,Event,ADDED,eval-conflicts-rho020-r0-171-96fjh.18d53eec82a8b7ec,reason=Scheduled count=None msg=Successfully assigned compute/eval-conflicts-rho020-r0-171-96fjh to kind-worker2
0.3247,Event,ADDED,eval-conflicts-rho020-r0-171-96fjh.18d53eeca226e2c6,"reason=Pulled count=1 msg=Container image ""busybox:musl"" already present on machine"
0.3248,Event,ADDED,eval-conflicts-rho020-r0-171-96fjh.18d53eeca447bcf3,reason=Created count=1 msg=Created container: task
0.325,Event,ADDED,eval-conflicts-rho020-r0-171-96fjh.18d53eeca7e7c848,reason=Started count=1 msg=Started container task
0.3252,Event,ADDED,eval-conflicts-rho020-r0-171.18d53eeac401c9f1,reason=SuccessfulCreate count=1 msg=Created pod: eval-conflicts-rho020-r0-171-96fjh
0.3253,Event,ADDED,eval-conflicts-rho020-r0-171.18d53ef1dc39c683,reason=Completed count=1 msg=Job completed
0.3255,Event,ADDED,eval-conflicts-rho020-r0-172-ld5cs.18d53eeb01d8cf5d,"reason=FailedScheduling count=None msg=0/6 nodes are available: 1 c_wall violated: 1 conflicting context pair(s) with node memory, 5 node(s) had untolerated taint(s). no new claims to deallocate, preemption: 0/6 nodes are available: 1 No preemption victims found for incoming pod, 5 Preemption is not helpful for scheduling."
0.3257,Event,ADDED,eval-conflicts-rho020-r0-172-ld5cs.18d53eeb025ba5d8,"reason=FailedScheduling count=None msg=0/6 nodes are available: 1 c_wall violated: 1 conflicting context pair(s) with node memory, 5 node(s) had untolerated taint(s). no new claims to deallocate, preemption: 0/6 nodes are available: 1 No preemption victims found for incoming pod, 5 Preemption is not helpful for scheduling."
0.3258,Event,ADDED,eval-conflicts-rho020-r0-172-ld5cs.18d53eec891ca19e,reason=Scheduled count=None msg=Successfully assigned compute/eval-conflicts-rho020-r0-172-ld5cs to kind-worker2
0.326,Event,ADDED,eval-conflicts-rho020-r0-172-ld5cs.18d53eecbe3a3a3c,"reason=Pulled count=1 msg=Container image ""busybox:musl"" already present on machine"
0.3262,Event,ADDED,eval-conflicts-rho020-r0-172-ld5cs.18d53eecc0ff210a,reason=Created count=1 msg=Created container: task
0.3263,Event,ADDED,eval-conflicts-rho020-r0-172-ld5cs.18d53eecc6c3470f,reason=Started count=1 msg=Started container task
0.3265,Event,ADDED,eval-conflicts-rho020-r0-172.18d53eeb006ab33d,reason=SuccessfulCreate count=1 msg=Created pod: eval-conflicts-rho020-r0-172-ld5cs
0.3267,Event,ADDED,eval-conflicts-rho020-r0-172.18d53ef21ad7b5e0,reason=Completed count=1 msg=Job completed
0.3268,Event,ADDED,eval-conflicts-rho020-r0-173-82nlc.18d53eeb3e7eeace,reason=Scheduled count=None msg=Successfully assigned compute/eval-conflicts-rho020-r0-173-82nlc to kind-worker5
0.327,Event,ADDED,eval-conflicts-rho020-r0-173-82nlc.18d53eeb58a4e759,"reason=Pulled count=1 msg=Container image ""busybox:musl"" already present on machine"
0.3272,Event,ADDED,eval-conflicts-rho020-r0-173-82nlc.18d53eeb59c1e663,reason=Created count=1 msg=Created container: task
0.3273,Event,ADDED,eval-conflicts-rho020-r0-173-82nlc.18d53eeb5f03460a,reason=Started count=1 msg=Started container task
0.3275,Event,ADDED,eval-conflicts-rho020-r0-173.18d53eeb3df466dd,reason=SuccessfulCreate count=1 msg=Created pod: eval-conflicts-rho020-r0-173-82nlc
0.3276,Event,ADDED,eval-conflicts-rho020-r0-173.18d53ef0e582d619,reason=Completed count=1 msg=Job completed
0.3278,Event,ADDED,eval-conflicts-rho020-r0-174-bcdgt.18d53eeb7a61d464,"reason=FailedScheduling count=None msg=0/6 nodes are available: 1 c_wall violated: 1 conflicting context pair(s) with node memory, 5 node(s) had untolerated taint(s). no new claims to deallocate, preemption: 0/6 nodes are available: 1 No preemption victims found for incoming pod, 5 Preemption is not helpful for scheduling."
0.328,Event,ADDED,eval-conflicts-rho020-r0-174-bcdgt.18d53eeb7b7c8d01,"reason=FailedScheduling count=None msg=0/6 nodes are available: 1 c_wall violated: 1 conflicting context pair(s) with node memory, 5 node(s) had untolerated taint(s). no new claims to deallocate, preemption: 0/6 nodes are available: 1 No preemption victims found for incoming pod, 5 Preemption is not helpful for scheduling."
0.3281,Event,ADDED,eval-conflicts-rho020-r0-174-bcdgt.18d53eec89835f63,reason=Scheduled count=None msg=Successfully assigned compute/eval-conflicts-rho020-r0-174-bcdgt to kind-worker2
0.3284,Event,ADDED,eval-conflicts-rho020-r0-174-bcdgt.18d53eecbe00e7cd,"reason=Pulled count=1 msg=Container image ""busybox:musl"" already present on machine"
0.3286,Event,ADDED,eval-conflicts-rho020-r0-174-bcdgt.18d53eecc0a769f3,reason=Created count=1 msg=Created container: task
0.3287,Event,ADDED,eval-conflicts-rho020-r0-174-bcdgt.18d53eecc6c44d75,reason=Started count=1 msg=Started container task
0.3289,Event,ADDED,eval-conflicts-rho020-r0-174.18d53eeb7a1d4e7c,reason=SuccessfulCreate count=1 msg=Created pod: eval-conflicts-rho020-r0-174-bcdgt
0.329,Event,ADDED,eval-conflicts-rho020-r0-174.18d53ef21aabba94,reason=Completed count=1 msg=Job completed
0.3292,Event,ADDED,eval-conflicts-rho020-r0-175-hhntt.18d53eebb39a7e6e,"reason=FailedScheduling count=None msg=0/6 nodes are available: 1 c_wall violated: 2 conflicting context pair(s) with node memory, 5 node(s) had untolerated taint(s). no new claims to deallocate, preemption: 0/6 nodes are available: 1 No preemption victims found for incoming pod, 5 Preemption is not helpful for scheduling."
0.3294,Event,ADDED,eval-conflicts-rho020-r0-175-hhntt.18d53eebb4595f82,"reason=FailedScheduling count=None msg=0/6 nodes are available: 1 c_wall violated: 2 conflicting context pair(s) with node memory, 5 node(s) had untolerated taint(s). no new claims to deallocate, preemption: 0/6 nodes are available: 1 No preemption victims found for incoming pod, 5 Preemption is not helpful for scheduling."
0.3295,Event,ADDED,eval-conflicts-rho020-r0-175-hhntt.18d53eec8dfbee33,reason=Scheduled count=None msg=Successfully assigned compute/eval-conflicts-rho020-r0-175-hhntt to kind-worker2
0.3297,Event,ADDED,eval-conflicts-rho020-r0-175-hhntt.18d53eecafb3bde5,"reason=Pulled count=1 msg=Container image ""busybox:musl"" already present on machine"
0.3299,Event,ADDED,eval-conflicts-rho020-r0-175-hhntt.18d53eecb1ce3677,reason=Created count=1 msg=Created container: task
0.33,Event,ADDED,eval-conflicts-rho020-r0-175-hhntt.18d53eecbdd34764,reason=Started count=1 msg=Started container task
0.3302,Event,ADDED,eval-conflicts-rho020-r0-175.18d53eebb356af36,reason=SuccessfulCreate count=1 msg=Created pod: eval-conflicts-rho020-r0-175-hhntt
0.3304,Event,ADDED,eval-conflicts-rho020-r0-175.18d53ef2613a623b,reason=Completed count=1 msg=Job completed
0.3305,Event,ADDED,eval-conflicts-rho020-r0-176-2kn8b.18d53eebee83247a,"reason=FailedScheduling count=None msg=0/6 nodes are available: 1 c_wall violated: 1 conflicting context pair(s) with node memory, 5 node(s) had untolerated taint(s). no new claims to deallocate, preemption: 0/6 nodes are available: 1 No preemption victims found for incoming pod, 5 Preemption is not helpful for scheduling."
0.3307,Event,ADDED,eval-conflicts-rho020-r0-176-2kn8b.18d53eebef05933f,"reason=FailedScheduling count=None msg=0/6 nodes are available: 1 c_wall violated: 1 conflicting context pair(s) with node memory, 5 node(s) had untolerated taint(s). no new claims to deallocate, preemption: 0/6 nodes are available: 1 No preemption victims found for incoming pod, 5 Preemption is not helpful for scheduling."
0.3308,Event,ADDED,eval-conflicts-rho020-r0-176-2kn8b.18d53eec7ecffef6,reason=Scheduled count=None msg=Successfully assigned compute/eval-conflicts-rho020-r0-176-2kn8b to kind-worker2
0.331,Event,ADDED,eval-conflicts-rho020-r0-176-2kn8b.18d53eec9c3b8cd7,"reason=Pulled count=1 msg=Container image ""busybox:musl"" already present on machine"
0.3314,Event,ADDED,eval-conflicts-rho020-r0-176-2kn8b.18d53eec9e2a0be7,reason=Created count=1 msg=Created container: task
0.3316,Event,ADDED,eval-conflicts-rho020-r0-176-2kn8b.18d53eeca1e49907,reason=Started count=1 msg=Started container task
0.3318,Event,ADDED,eval-conflicts-rho020-r0-176.18d53eebee408c0e,reason=SuccessfulCreate count=1 msg=Created pod: eval-conflicts-rho020-r0-176-2kn8b
0.3321,Event,ADDED,eval-conflicts-rho020-r0-176.18d53ef1dbd72000,reason=Completed count=1 msg=Job completed
0.3322,Event,ADDED,eval-conflicts-rho020-r0-177-fbvml.18d53eec2a88de54,"reason=FailedScheduling count=None msg=0/6 nodes are available: 1 c_wall violated: 2 conflicting context pair(s) with node memory, 5 node(s) had untolerated taint(s). no new claims to deallocate, preemption: 0/6 nodes are available: 1 No preemption victims found for incoming pod, 5 Preemption is not helpful for scheduling."
0.3324,Event,ADDED,eval-conflicts-rho020-r0-177-fbvml.18d53eec2b15de7e,"reason=FailedScheduling count=None msg=0/6 nodes are available: 1 c_wall violated: 2 conflicting context pair(s) with node memory, 5 node(s) had untolerated taint(s). no new claims to deallocate, preemption: 0/6 nodes are available: 1 No preemption victims found for incoming pod, 5 Preemption is not helpful for scheduling."
0.3328,Event,ADDED,eval-conflicts-rho020-r0-177-fbvml.18d53eec8dc057e9,"reason=FailedScheduling count=None msg=0/6 nodes are available: 1 c_wall violated: 1 conflicting context pair(s) with node memory, 1 c_wall violated: 2 conflicting context pair(s) with node memory, 4 node(s) had untolerated taint(s). no new claims to deallocate, preemption: 0/6 nodes are available: 2 No preemption victims found for incoming pod, 4 Preemption is not helpful for scheduling."
0.3329,Event,ADDED,eval-conflicts-rho020-r0-177-fbvml.18d53eee30b6df4c,"reason=FailedScheduling count=None msg=0/6 nodes are available: 1 c_wall violated: 1 conflicting context pair(s) with node memory, 5 node(s) had untolerated taint(s). no new claims to deallocate, preemption: 0/6 nodes are available: 1 No preemption victims found for incoming pod, 5 Preemption is not helpful for scheduling."
0.3331,Event,ADDED,eval-conflicts-rho020-r0-177-fbvml.18d53eef0eb862ab,reason=Scheduled count=None msg=Successfully assigned compute/eval-conflicts-rho020-r0-177-fbvml to kind-worker
0.3334,Event,ADDED,eval-conflicts-rho020-r0-177-fbvml.18d53eef282b5ba6,"reason=Pulled count=1 msg=Container image ""busybox:musl"" already present on machine"
0.3336,Event,ADDED,eval-conflicts-rho020-r0-177-fbvml.18d53eef2a4751aa,reason=Created count=1 msg=Created container: task
0.3338,Event,ADDED,eval-conflicts-rho020-r0-177-fbvml.18d53eef3306e375,reason=Started count=1 msg=Started container task
0.3339,Event,ADDED,eval-conflicts-rho020-r0-177.18d53eec2a400e82,reason=SuccessfulCreate count=1 msg=Created pod: eval-conflicts-rho020-r0-177-fbvml
0.3342,Event,ADDED,eval-conflicts-rho020-r0-177.18d53ef4c3c9e600,reason=Completed count=1 msg=Job completed
0.3343,Event,ADDED,eval-conflicts-rho020-r0-178-s2vrr.18d53eec6604f3b0,"reason=FailedScheduling count=None msg=0/6 nodes are available: 1 c_wall violated: 1 conflicting context pair(s) with node memory, 5 node(s) had untolerated taint(s). no new claims to deallocate, preemption: 0/6 nodes are available: 1 No preemption victims found for incoming pod, 5 Preemption is not helpful for scheduling."
0.3345,Event,ADDED,eval-conflicts-rho020-r0-178-s2vrr.18d53eec66a36ed9,"reason=FailedScheduling count=None msg=0/6 nodes are available: 1 c_wall violated: 1 conflicting context pair(s) with node memory, 5 node(s) had untolerated taint(s). no new claims to deallocate, preemption: 0/6 nodes are available: 1 No preemption victims found for incoming pod, 5 Preemption is not helpful for scheduling."
0.3346,Event,ADDED,eval-conflicts-rho020-r0-178-s2vrr.18d53eec82576345,reason=Scheduled count=None msg=Successfully assigned compute/eval-conflicts-rho020-r0-178-s2vrr to kind-worker2
0.3348,Event,ADDED,eval-conflicts-rho020-r0-178-s2vrr.18d53eeca1e93351,"reason=Pulled count=1 msg=Container image ""busybox:musl"" already present on machine"
0.335,Event,ADDED,eval-conflicts-rho020-r0-178-s2vrr.18d53eeca3af2022,reason=Created count=1 msg=Created container: task
0.3351,Event,ADDED,eval-conflicts-rho020-r0-178-s2vrr.18d53eeca7e7bcae,reason=Started count=1 msg=Started container task
0.3353,Event,ADDED,eval-conflicts-rho020-r0-178.18d53eec65c5423b,reason=SuccessfulCreate count=1 msg=Created pod: eval-conflicts-rho020-r0-178-s2vrr
0.3355,Event,ADDED,eval-conflicts-rho020-r0-178.18d53ef1dbfd47fd,reason=Completed count=1 msg=Job completed
0.3356,Event,ADDED,eval-conflicts-rho020-r0-179-s5gj7.18d53eeca23a41e1,reason=Scheduled count=None msg=Successfully assigned compute/eval-conflicts-rho020-r0-179-s5gj7 to kind-worker2
0.3358,Event,ADDED,eval-conflicts-rho020-r0-179-s5gj7.18d53eecc6cc8d34,"reason=Pulled count=1 msg=Container image ""busybox:musl"" already present on machine"
0.3359,Event,ADDED,eval-conflicts-rho020-r0-179-s5gj7.18d53eecc7f384e0,reason=Created count=1 msg=Created container: task
0.3361,Event,ADDED,eval-conflicts-rho020-r0-179-s5gj7.18d53eeccd56468c,reason=Started count=1 msg=Started container task
0.3363,Event,ADDED,eval-conflicts-rho020-r0-179.18d53eeca12bb034,reason=SuccessfulCreate count=1 msg=Created pod: eval-conflicts-rho020-r0-179-s5gj7
0.3364,Event,ADDED,eval-conflicts-rho020-r0-179.18d53ef261180ece,reason=Completed count=1 msg=Job completed
0.3366,Event,ADDED,eval-conflicts-rho020-r0-180-cmqz7.18d53eece2c2029b,reason=Scheduled count=None msg=Successfully assigned compute/eval-conflicts-rho020-r0-180-cmqz7 to kind-worker2
0.3368,Event,ADDED,eval-conflicts-rho020-r0-180-cmqz7.18d53eed02f8c499,"reason=Pulled count=1 msg=Container image ""busybox:musl"" already present on machine"
0.3369,Event,ADDED,eval-conflicts-rho020-r0-180-cmqz7.18d53eed043cd84a,reason=Created count=1 msg=Created container: task
0.3371,Event,ADDED,eval-conflicts-rho020-r0-180-cmqz7.18d53eed0dfea6bf,reason=Started count=1 msg=Started container task
0.3373,Event,ADDED,eval-conflicts-rho020-r0-180.18d53eece1feefcb,reason=SuccessfulCreate count=1 msg=Created pod: eval-conflicts-rho020-r0-180-cmqz7
0.3374,Event,ADDED,eval-conflicts-rho020-r0-180.18d53ef26184b4ab,reason=Completed count=1 msg=Job completed
0.3376,Event,ADDED,eval-conflicts-rho020-r0-181-mrd7z.18d53eed1eb58925,reason=Scheduled count=None msg=Successfully assigned compute/eval-conflicts-rho020-r0-181-mrd7z to kind-worker2
0.3377,Event,ADDED,eval-conflicts-rho020-r0-181-mrd7z.18d53eed4438f725,"reason=Pulled count=1 msg=Container image ""busybox:musl"" already present on machine"
0.338,Event,ADDED,eval-conflicts-rho020-r0-181-mrd7z.18d53eed45686cc1,reason=Created count=1 msg=Created container: task
0.3381,Event,ADDED,eval-conflicts-rho020-r0-181-mrd7z.18d53eed4a2f3ceb,reason=Started count=1 msg=Started container task
0.3383,Event,ADDED,eval-conflicts-rho020-r0-181.18d53eed1de97784,reason=SuccessfulCreate count=1 msg=Created pod: eval-conflicts-rho020-r0-181-mrd7z
0.3385,Event,ADDED,eval-conflicts-rho020-r0-181.18d53ef2d95fa5fc,reason=Completed count=1 msg=Job completed
0.3386,Event,ADDED,eval-conflicts-rho020-r0-182-jbqql.18d53eed54675e74,reason=Scheduled count=None msg=Successfully assigned compute/eval-conflicts-rho020-r0-182-jbqql to kind-worker2
0.3388,Event,ADDED,eval-conflicts-rho020-r0-182-jbqql.18d53eed704d215b,"reason=Pulled count=1 msg=Container image ""busybox:musl"" already present on machine"
0.339,Event,ADDED,eval-conflicts-rho020-r0-182-jbqql.18d53eed718032b3,reason=Created count=1 msg=Created container: task
0.3391,Event,ADDED,eval-conflicts-rho020-r0-182-jbqql.18d53eed75e9a92e,reason=Started count=1 msg=Started container task
0.3393,Event,ADDED,eval-conflicts-rho020-r0-182.18d53eed53bfef7e,reason=SuccessfulCreate count=1 msg=Created pod: eval-conflicts-rho020-r0-182-jbqql
0.3395,Event,ADDED,eval-conflicts-rho020-r0-182.18d53ef315eb8697,reason=Completed count=1 msg=Job completed
0.3396,Event,ADDED,eval-conflicts-rho020-r0-183-fpd7t.18d53eed903bdcdb,reason=Scheduled count=None msg=Successfully assigned compute/eval-conflicts-rho020-r0-183-fpd7t to kind-worker5
0.3398,Event,ADDED,eval-conflicts-rho020-r0-183-fpd7t.18d53eedae86ab4d,"reason=Pulled count=1 msg=Container image ""busybox:musl"" already present on machine"
0.3399,Event,ADDED,eval-conflicts-rho020-r0-183-fpd7t.18d53eedafa5d299,reason=Created count=1 msg=Created container: task
0.3401,Event,ADDED,eval-conflicts-rho020-r0-183-fpd7t.18d53eedb3096fe3,reason=Started count=1 msg=Started container task
0.3403,Event,ADDED,eval-conflicts-rho020-r0-183.18d53eed8f7fa1f7,reason=SuccessfulCreate count=1 msg=Created pod: eval-conflicts-rho020-r0-183-fpd7t
0.3404,Event,ADDED,eval-conflicts-rho020-r0-183.18d53ef346d733f8,reason=Completed count=1 msg=Job completed
0.3407,Event,ADDED,eval-conflicts-rho020-r0-184-7gd9l.18d53eedce982c35,reason=Scheduled count=None msg=Successfully assigned compute/eval-conflicts-rho020-r0-184-7gd9l to kind-worker2
0.3409,Event,ADDED,eval-conflicts-rho020-r0-184-7gd9l.18d53eeded298e2a,"reason=Pulled count=1 msg=Container image ""busybox:musl"" already present on machine"
0.3411,Event,ADDED,eval-conflicts-rho020-r0-184-7gd9l.18d53eedee6cf4ed,reason=Created count=1 msg=Created container: task
0.3412,Event,ADDED,eval-conflicts-rho020-r0-184-7gd9l.18d53eedf39342cd,reason=Started count=1 msg=Started container task
0.3416,Event,ADDED,eval-conflicts-rho020-r0-184.18d53eedcdee1be2,reason=SuccessfulCreate count=1 msg=Created pod: eval-conflicts-rho020-r0-184-7gd9l
0.3418,Event,ADDED,eval-conflicts-rho020-r0-184.18d53ef3879e5db0,reason=Completed count=1 msg=Job completed
0.3419,Event,ADDED,eval-conflicts-rho020-r0-185-hpvpx.18d53eee091dada4,reason=Scheduled count=None msg=Successfully assigned compute/eval-conflicts-rho020-r0-185-hpvpx to kind-worker5
0.3421,Event,ADDED,eval-conflicts-rho020-r0-185-hpvpx.18d53eee27d6386e,"reason=Pulled count=1 msg=Container image ""busybox:musl"" already present on machine"
0.3423,Event,ADDED,eval-conflicts-rho020-r0-185-hpvpx.18d53eee2937f0d3,reason=Created count=1 msg=Created container: task
0.3425,Event,ADDED,eval-conflicts-rho020-r0-185-hpvpx.18d53eee2efb1083,reason=Started count=1 msg=Started container task
0.3427,Event,ADDED,eval-conflicts-rho020-r0-185.18d53eee087c8329,reason=SuccessfulCreate count=1 msg=Created pod: eval-conflicts-rho020-r0-185-hpvpx
0.343,Event,ADDED,eval-conflicts-rho020-r0-185.18d53ef3acacb00f,reason=Completed count=1 msg=Job completed
0.3431,Event,ADDED,eval-conflicts-rho020-r0-186-hbxrd.18d53eee489b2c5c,reason=Scheduled count=None msg=Successfully assigned compute/eval-conflicts-rho020-r0-186-hbxrd to kind-worker2
0.3433,Event,ADDED,eval-conflicts-rho020-r0-186-hbxrd.18d53eee64f40356,"reason=Pulled count=1 msg=Container image ""busybox:musl"" already present on machine"
0.3435,Event,ADDED,eval-conflicts-rho020-r0-186-hbxrd.18d53eee661d5ddc,reason=Created count=1 msg=Created container: task
0.3438,Event,ADDED,eval-conflicts-rho020-r0-186-hbxrd.18d53eee7027d86b,reason=Started count=1 msg=Started container task
0.344,Event,ADDED,eval-conflicts-rho020-r0-186.18d53eee480ad015,reason=SuccessfulCreate count=1 msg=Created pod: eval-conflicts-rho020-r0-186-hbxrd
0.3441,Event,ADDED,eval-conflicts-rho020-r0-186.18d53ef404e67f37,reason=Completed count=1 msg=Job completed
0.3443,Event,ADDED,eval-conflicts-rho020-r0-187-whq24.18d53eee81320dd6,"reason=FailedScheduling count=None msg=0/6 nodes are available: 1 c_wall violated: 1 conflicting context pair(s) with node memory, 5 node(s) had untolerated taint(s). no new claims to deallocate, preemption: 0/6 nodes are available: 1 No preemption victims found for incoming pod, 5 Preemption is not helpful for scheduling."
0.3445,Event,ADDED,eval-conflicts-rho020-r0-187-whq24.18d53eee81bf9656,"reason=FailedScheduling count=None msg=0/6 nodes are available: 1 c_wall violated: 1 conflicting context pair(s) with node memory, 5 node(s) had untolerated taint(s). no new claims to deallocate, preemption: 0/6 nodes are available: 1 No preemption victims found for incoming pod, 5 Preemption is not helpful for scheduling."
0.3447,Event,ADDED,eval-conflicts-rho020-r0-187-whq24.18d53eef18311b13,"reason=FailedScheduling count=None msg=0/6 nodes are available: 2 c_wall violated: 1 conflicting context pair(s) with node memory, 4 node(s) had untolerated taint(s). no new claims to deallocate, preemption: 0/6 nodes are available: 2 No preemption victims found for incoming pod, 4 Preemption is not helpful for scheduling."
0.3449,Event,ADDED,eval-conflicts-rho020-r0-187-whq24.18d53ef03fe8d71d,reason=Scheduled count=None msg=Successfully assigned compute/eval-conflicts-rho020-r0-187-whq24 to kind-worker3
0.345,Event,ADDED,eval-conflicts-rho020-r0-187-whq24.18d53ef05d5789eb,"reason=Pulled count=1 msg=Container image ""busybox:musl"" already present on machine"
0.3452,Event,ADDED,eval-conflicts-rho020-r0-187-whq24.18d53ef05f05d0c4,reason=Created count=1 msg=Created container: task
0.3454,Event,ADDED,eval-conflicts-rho020-r0-187-whq24.18d53ef0637b0e25,reason=Started count=1 msg=Started container task
0.3455,Event,ADDED,eval-conflicts-rho020-r0-187.18d53eee80effbc2,reason=SuccessfulCreate count=1 msg=Created pod: eval-conflicts-rho020-r0-187-whq24
0.3457,Event,ADDED,eval-conflicts-rho020-r0-187.18d53ef5d750716f,reason=Completed count=1 msg=Job completed
0.3459,Event,ADDED,eval-conflicts-rho020-r0-188-52flf.18d53eeeb99fbc57,"reason=FailedScheduling count=None msg=0/6 nodes are available: 1 c_wall violated: 2 conflicting context pair(s) with node memory, 5 node(s) had untolerated taint(s). no new claims to deallocate, preemption: 0/6 nodes are available: 1 No preemption victims found for incoming pod, 5 Preemption is not helpful for scheduling."
0.3461,Event,ADDED,eval-conflicts-rho020-r0-188-52flf.18d53eeeba1fcd2e,"reason=FailedScheduling count=None msg=0/6 nodes are available: 1 c_wall violated: 2 conflicting context pair(s) with node memory, 5 node(s) had untolerated taint(s). no new claims to deallocate, preemption: 0/6 nodes are available: 1 No preemption victims found for incoming pod, 5 Preemption is not helpful for scheduling."
0.3462,Event,ADDED,eval-conflicts-rho020-r0-188-52flf.18d53eef1746fb3b,reason=Scheduled count=None msg=Successfully assigned compute/eval-conflicts-rho020-r0-188-52flf to kind-worker
0.3464,Event,ADDED,eval-conflicts-rho020-r0-188-52flf.18d53eef420d3991,"reason=Pulled count=1 msg=Container image ""busybox:musl"" already present on machine"
0.3466,Event,ADDED,eval-conflicts-rho020-r0-188-52flf.18d53eef43bbff11,reason=Created count=1 msg=Created container: task
0.3468,Event,ADDED,eval-conflicts-rho020-r0-188-52flf.18d53eef4838fef6,reason=Started count=1 msg=Started container task
0.347,Event,ADDED,eval-conflicts-rho020-r0-188.18d53eeeb953519b,reason=SuccessfulCreate count=1 msg=Created pod: eval-conflicts-rho020-r0-188-52flf
0.3472,Event,ADDED,eval-conflicts-rho020-r0-188.18d53ef4c3ca0fab,reason=Completed count=1 msg=Job completed
0.3473,Event,ADDED,eval-conflicts-rho020-r0-189-n2t42.18d53eeef5d27d7b,"reason=FailedScheduling count=None msg=0/6 nodes are available: 1 c_wall violated: 1 conflicting context pair(s) with node memory, 5 node(s) had untolerated taint(s). no new claims to deallocate, preemption: 0/6 nodes are available: 1 No preemption victims found for incoming pod, 5 Preemption is not helpful for scheduling."
0.3475,Event,ADDED,eval-conflicts-rho020-r0-189-n2t42.18d53eeef63bc500,"reason=FailedScheduling count=None msg=0/6 nodes are available: 1 c_wall violated: 1 conflicting context pair(s) with node memory, 5 node(s) had untolerated taint(s). no new claims to deallocate, preemption: 0/6 nodes are available: 1 No preemption victims found for incoming pod, 5 Preemption is not helpful for scheduling."
0.3477,Event,ADDED,eval-conflicts-rho020-r0-189-n2t42.18d53eef17c79a7f,"reason=FailedScheduling count=None msg=0/6 nodes are available: 2 c_wall violated: 1 conflicting context pair(s) with node memory, 4 node(s) had untolerated taint(s). no new claims to deallocate, preemption: 0/6 nodes are available: 2 No preemption victims found for incoming pod, 4 Preemption is not helpful for scheduling."
0.3478,Event,ADDED,eval-conflicts-rho020-r0-189-n2t42.18d53ef0417e25de,reason=Scheduled count=None msg=Successfully assigned compute/eval-conflicts-rho020-r0-189-n2t42 to kind-worker3
0.348,Event,ADDED,eval-conflicts-rho020-r0-189-n2t42.18d53ef05db47c0a,"reason=Pulled count=1 msg=Container image ""busybox:musl"" already present on machine"
0.3482,Event,ADDED,eval-conflicts-rho020-r0-189-n2t42.18d53ef05f3a26be,reason=Created count=1 msg=Created container: task
0.3483,Event,ADDED,eval-conflicts-rho020-r0-189-n2t42.18d53ef063a6f6bc,reason=Started count=1 msg=Started container task
0.3485,Event,ADDED,eval-conflicts-rho020-r0-189.18d53eeef5914ce0,reason=SuccessfulCreate count=1 msg=Created pod: eval-conflicts-rho020-r0-189-n2t42
0.3487,Event,ADDED,eval-conflicts-rho020-r0-189.18d53ef5d72f02eb,reason=Completed count=1 msg=Job completed
0.3488,Event,ADDED,eval-conflicts-rho020-r0-190-c5nfd.18d53eef35556aa7,reason=Scheduled count=None msg=Successfully assigned compute/eval-conflicts-rho020-r0-190-c5nfd to kind-worker
0.3491,Event,ADDED,eval-conflicts-rho020-r0-190-c5nfd.18d53eef539f750a,"reason=Pulled count=1 msg=Container image ""busybox:musl"" already present on machine"
0.3493,Event,ADDED,eval-conflicts-rho020-r0-190-c5nfd.18d53eef54c4270b,reason=Created count=1 msg=Created container: task
0.3495,Event,ADDED,eval-conflicts-rho020-r0-190-c5nfd.18d53eef5ddbe41d,reason=Started count=1 msg=Started container task
0.3497,Event,ADDED,eval-conflicts-rho020-r0-190.18d53eef34ac0c34,reason=SuccessfulCreate count=1 msg=Created pod: eval-conflicts-rho020-r0-190-c5nfd
0.3499,Event,ADDED,eval-conflicts-rho020-r0-190.18d53ef4c3a62bd4,reason=Completed count=1 msg=Job completed
0.3501,Event,ADDED,eval-conflicts-rho020-r0-191-qxwq6.18d53eef73fa3e71,reason=Scheduled count=None msg=Successfully assigned compute/eval-conflicts-rho020-r0-191-qxwq6 to kind-worker2
0.3503,Event,ADDED,eval-conflicts-rho020-r0-191-qxwq6.18d53eef9655ebd9,"reason=Pulled count=1 msg=Container image ""busybox:musl"" already present on machine"
0.3504,Event,ADDED,eval-conflicts-rho020-r0-191-qxwq6.18d53eef97ec2236,reason=Created count=1 msg=Created container: task
0.3506,Event,ADDED,eval-conflicts-rho020-r0-191-qxwq6.18d53eef9eff1355,reason=Started count=1 msg=Started container task
0.3508,Event,ADDED,eval-conflicts-rho020-r0-191.18d53eef732d93a8,reason=SuccessfulCreate count=1 msg=Created pod: eval-conflicts-rho020-r0-191-qxwq6
0.3509,Event,ADDED,eval-conflicts-rho020-r0-191.18d53ef51dd6608a,reason=Completed count=1 msg=Job completed
0.3516,Event,ADDED,eval-conflicts-rho020-r0-192-9v79h.18d53eefacd76365,reason=Scheduled count=None msg=Successfully assigned compute/eval-conflicts-rho020-r0-192-9v79h to kind-worker2
0.3518,Event,ADDED,eval-conflicts-rho020-r0-192-9v79h.18d53eefcebf7ef0,"reason=Pulled count=1 msg=Container image ""busybox:musl"" already present on machine"
0.352,Event,ADDED,eval-conflicts-rho020-r0-192-9v79h.18d53eefcfd88529,reason=Created count=1 msg=Created container: task
0.3522,Event,ADDED,eval-conflicts-rho020-r0-192-9v79h.18d53eefd8848d06,reason=Started count=1 msg=Started container task
0.3525,Event,ADDED,eval-conflicts-rho020-r0-192.18d53eefac1514a3,reason=SuccessfulCreate count=1 msg=Created pod: eval-conflicts-rho020-r0-192-9v79h
0.3527,Event,ADDED,eval-conflicts-rho020-r0-192.18d53ef559eeab1f,reason=Completed count=1 msg=Job completed
0.3528,Event,ADDED,eval-conflicts-rho020-r0-193-vzpz9.18d53eefe67e4003,reason=Scheduled count=None msg=Successfully assigned compute/eval-conflicts-rho020-r0-193-vzpz9 to kind-worker2
0.353,Event,ADDED,eval-conflicts-rho020-r0-193-vzpz9.18d53ef0022748ee,"reason=Pulled count=1 msg=Container image ""busybox:musl"" already present on machine"
0.3533,Event,ADDED,eval-conflicts-rho020-r0-193-vzpz9.18d53ef00337cb82,reason=Created count=1 msg=Created container: task
0.3535,Event,ADDED,eval-conflicts-rho020-r0-193-vzpz9.18d53ef00dbe437a,reason=Started count=1 msg=Started container task
0.3537,Event,ADDED,eval-conflicts-rho020-r0-193.18d53eefe5d142d0,reason=SuccessfulCreate count=1 msg=Created pod: eval-conflicts-rho020-r0-193-vzpz9
0.354,Event,ADDED,eval-conflicts-rho020-r0-193.18d53ef599669150,reason=Completed count=1 msg=Job completed
0.3542,Event,ADDED,eval-conflicts-rho020-r0-194-9rzp5.18d53ef026a79929,reason=Scheduled count=None msg=Successfully assigned compute/eval-conflicts-rho020-r0-194-9rzp5 to kind-worker2
0.3543,Event,ADDED,eval-conflicts-rho020-r0-194-9rzp5.18d53ef040ce0644,"reason=Pulled count=1 msg=Container image ""busybox:musl"" already present on machine"
0.3545,Event,ADDED,eval-conflicts-rho020-r0-194-9rzp5.18d53ef042360176,reason=Created count=1 msg=Created container: task
0.3548,Event,ADDED,eval-conflicts-rho020-r0-194-9rzp5.18d53ef04ebcba6a,reason=Started count=1 msg=Started container task
0.355,Event,ADDED,eval-conflicts-rho020-r0-194.18d53ef025cc387f,reason=SuccessfulCreate count=1 msg=Created pod: eval-conflicts-rho020-r0-194-9rzp5
0.3551,Event,ADDED,eval-conflicts-rho020-r0-194.18d53ef5d74ff377,reason=Completed count=1 msg=Job completed
0.3553,Event,ADDED,eval-conflicts-rho020-r0-195-ggwl6.18d53ef05c16ef80,reason=Scheduled count=None msg=Successfully assigned compute/eval-conflicts-rho020-r0-195-ggwl6 to kind-worker3
0.3555,Event,ADDED,eval-conflicts-rho020-r0-195-ggwl6.18d53ef092121fa6,"reason=Pulled count=1 msg=Container image ""busybox:musl"" already present on machine"
0.3557,Event,ADDED,eval-conflicts-rho020-r0-195-ggwl6.18d53ef093269816,reason=Created count=1 msg=Created container: task
0.3559,Event,ADDED,eval-conflicts-rho020-r0-195-ggwl6.18d53ef0982a241c,reason=Started count=1 msg=Started container task
0.3561,Event,ADDED,eval-conflicts-rho020-r0-195.18d53ef05a9c635f,reason=SuccessfulCreate count=1 msg=Created pod: eval-conflicts-rho020-r0-195-ggwl6
0.3562,Event,ADDED,eval-conflicts-rho020-r0-195.18d53ef609c4aa4c,reason=Completed count=1 msg=Job completed
0.3564,Event,ADDED,eval-conflicts-rho020-r0-196-gpv9k.18d53ef096e24663,reason=Scheduled count=None msg=Successfully assigned compute/eval-conflicts-rho020-r0-196-gpv9k to kind-worker
0.3566,Event,ADDED,eval-conflicts-rho020-r0-196-gpv9k.18d53ef0b6636fe6,"reason=Pulled count=1 msg=Container image ""busybox:musl"" already present on machine"
0.3567,Event,ADDED,eval-conflicts-rho020-r0-196-gpv9k.18d53ef0b7ffdc6a,reason=Created count=1 msg=Created container: task
0.3569,Event,ADDED,eval-conflicts-rho020-r0-196-gpv9k.18d53ef0c5e8fbfb,reason=Started count=1 msg=Started container task
0.3571,Event,ADDED,eval-conflicts-rho020-r0-196.18d53ef095ee4e39,reason=SuccessfulCreate count=1 msg=Created pod: eval-conflicts-rho020-r0-196-gpv9k
0.3572,Event,ADDED,eval-conflicts-rho020-r0-196.18d53ef62fb72699,reason=Completed count=1 msg=Job completed
0.3574,Event,ADDED,eval-conflicts-rho020-r0-197-4r8qc.18d53ef0d28e9c12,reason=Scheduled count=None msg=Successfully assigned compute/eval-conflicts-rho020-r0-197-4r8qc to kind-worker3
0.3576,Event,ADDED,eval-conflicts-rho020-r0-197-4r8qc.18d53ef0edc8460a,"reason=Pulled count=1 msg=Container image ""busybox:musl"" already present on machine"
0.3577,Event,ADDED,eval-conflicts-rho020-r0-197-4r8qc.18d53ef0eede245d,reason=Created count=1 msg=Created container: task
0.3579,Event,ADDED,eval-conflicts-rho020-r0-197-4r8qc.18d53ef0f91ec103,reason=Started count=1 msg=Started container task
0.3581,Event,ADDED,eval-conflicts-rho020-r0-197.18d53ef0d1719fa3,reason=SuccessfulCreate count=1 msg=Created pod: eval-conflicts-rho020-r0-197-4r8qc
0.3582,Event,ADDED,eval-conflicts-rho020-r0-197.18d53ef692086d5c,reason=Completed count=1 msg=Job completed
0.3584,Event,ADDED,eval-conflicts-rho020-r0-198-7sfjd.18d53ef1125b7933,reason=Scheduled count=None msg=Successfully assigned compute/eval-conflicts-rho020-r0-198-7sfjd to kind-worker3
0.3585,Event,ADDED,eval-conflicts-rho020-r0-198-7sfjd.18d53ef13dd3ba93,"reason=Pulled count=1 msg=Container image ""busybox:musl"" already present on machine"
0.3587,Event,ADDED,eval-conflicts-rho020-r0-198-7sfjd.18d53ef13ef46124,reason=Created count=1 msg=Created container: task
0.3589,Event,ADDED,eval-conflicts-rho020-r0-198-7sfjd.18d53ef14e8116f9,reason=Started count=1 msg=Started container task
0.359,Event,ADDED,eval-conflicts-rho020-r0-198.18d53ef1113a65e2,reason=SuccessfulCreate count=1 msg=Created pod: eval-conflicts-rho020-r0-198-7sfjd
0.3592,Event,ADDED,eval-conflicts-rho020-r0-198.18d53ef6bdce1375,reason=Completed count=1 msg=Job completed
0.3593,Event,ADDED,eval-conflicts-rho020-r0-199-xc989.18d53ef150ee1bc9,reason=Scheduled count=None msg=Successfully assigned compute/eval-conflicts-rho020-r0-199-xc989 to kind-worker
0.3595,Event,ADDED,eval-conflicts-rho020-r0-199-xc989.18d53ef16fbca463,"reason=Pulled count=1 msg=Container image ""busybox:musl"" already present on machine"
0.3597,Event,ADDED,eval-conflicts-rho020-r0-199-xc989.18d53ef170edab0d,reason=Created count=1 msg=Created container: task
0.3598,Event,ADDED,eval-conflicts-rho020-r0-199-xc989.18d53ef179a2ec02,reason=Started count=1 msg=Started container task
0.36,Event,ADDED,eval-conflicts-rho020-r0-199.18d53ef150132690,reason=SuccessfulCreate count=1 msg=Created pod: eval-conflicts-rho020-r0-199-xc989
0.3602,Event,ADDED,eval-conflicts-rho020-r0-199.18d53ef717d59f1e,reason=Completed count=1 msg=Job completed
0.3604,Event,ADDED,eval-conflicts-rho020-r1-000-h4kbw.18d53f00df9a6b14,reason=Scheduled count=None msg=Successfully assigned compute/eval-conflicts-rho020-r1-000-h4kbw to kind-worker2
0.3606,Event,ADDED,eval-conflicts-rho020-r1-000-h4kbw.18d53f00fa4b5fd7,"reason=Pulled count=1 msg=Container image ""busybox:musl"" already present on machine"
0.3608,Event,ADDED,eval-conflicts-rho020-r1-000-h4kbw.18d53f00fb7205ce,reason=Created count=1 msg=Created container: task
0.3609,Event,ADDED,eval-conflicts-rho020-r1-000-h4kbw.18d53f00ff588b44,reason=Started count=1 msg=Started container task
0.3611,Event,ADDED,eval-conflicts-rho020-r1-000.18d53f00debdc3be,reason=SuccessfulCreate count=1 msg=Created pod: eval-conflicts-rho020-r1-000-h4kbw
0.3613,Event,ADDED,eval-conflicts-rho020-r1-000.18d53f066329d34e,reason=Completed count=1 msg=Job completed
0.3614,Event,ADDED,eval-conflicts-rho020-r1-001-4w2dr.18d53f0119eb37cb,reason=Scheduled count=None msg=Successfully assigned compute/eval-conflicts-rho020-r1-001-4w2dr to kind-worker2
0.3616,Event,ADDED,eval-conflicts-rho020-r1-001-4w2dr.18d53f0134ba3047,"reason=Pulled count=1 msg=Container image ""busybox:musl"" already present on machine"
0.3618,Event,ADDED,eval-conflicts-rho020-r1-001-4w2dr.18d53f0135dfef49,reason=Created count=1 msg=Created container: task
0.3619,Event,ADDED,eval-conflicts-rho020-r1-001-4w2dr.18d53f013b04222e,reason=Started count=1 msg=Started container task
0.3624,Event,ADDED,eval-conflicts-rho020-r1-001.18d53f0118de5902,reason=SuccessfulCreate count=1 msg=Created pod: eval-conflicts-rho020-r1-001-4w2dr
0.3627,Event,ADDED,eval-conflicts-rho020-r1-001.18d53f069f5c6466,reason=Completed count=1 msg=Job completed
0.3628,Event,ADDED,eval-conflicts-rho020-r1-002-w9gdl.18d53f015444063d,reason=Scheduled count=None msg=Successfully assigned compute/eval-conflicts-rho020-r1-002-w9gdl to kind-worker3
0.363,Event,ADDED,eval-conflicts-rho020-r1-002-w9gdl.18d53f016db94856,"reason=Pulled count=1 msg=Container image ""busybox:musl"" already present on machine"
0.3633,Event,ADDED,eval-conflicts-rho020-r1-002-w9gdl.18d53f016ecbf15b,reason=Created count=1 msg=Created container: task
0.3635,Event,ADDED,eval-conflicts-rho020-r1-002-w9gdl.18d53f01724402dd,reason=Started count=1 msg=Started container task
0.3637,Event,ADDED,eval-conflicts-rho020-r1-002.18d53f015380dc56,reason=SuccessfulCreate count=1 msg=Created pod: eval-conflicts-rho020-r1-002-w9gdl
0.3638,Event,ADDED,eval-conflicts-rho020-r1-002.18d53f070de17f9d,reason=Completed count=1 msg=Job completed
0.3641,Event,ADDED,eval-conflicts-rho020-r1-003-b5j8g.18d53f018fd9ffd4,reason=Scheduled count=None msg=Successfully assigned compute/eval-conflicts-rho020-r1-003-b5j8g to kind-worker4
0.3643,Event,ADDED,eval-conflicts-rho020-r1-003-b5j8g.18d53f01ac80a371,"reason=Pulled count=1 msg=Container image ""busybox:musl"" already present on machine"
0.3645,Event,ADDED,eval-conflicts-rho020-r1-003-b5j8g.18d53f01adb0930d,reason=Created count=1 msg=Created container: task
0.3648,Event,ADDED,eval-conflicts-rho020-r1-003-b5j8g.18d53f01b144d58d,reason=Started count=1 msg=Started container task
0.365,Event,ADDED,eval-conflicts-rho020-r1-003.18d53f018ed94f72,reason=SuccessfulCreate count=1 msg=Created pod: eval-conflicts-rho020-r1-003-b5j8g
0.3652,Event,ADDED,eval-conflicts-rho020-r1-003.18d53f0713134a3b,reason=Completed count=1 msg=Job completed
0.3654,Event,ADDED,eval-conflicts-rho020-r1-004-nvxmb.18d53f01cbf620d0,reason=Scheduled count=None msg=Successfully assigned compute/eval-conflicts-rho020-r1-004-nvxmb to kind-worker5
0.3657,Event,ADDED,eval-conflicts-rho020-r1-004-nvxmb.18d53f01e4ec8267,"reason=Pulled count=1 msg=Container image ""busybox:musl"" already present on machine"
0.3659,Event,ADDED,eval-conflicts-rho020-r1-004-nvxmb.18d53f01e5f890b8,reason=Created count=1 msg=Created container: task
0.366,Event,ADDED,eval-conflicts-rho020-r1-004-nvxmb.18d53f01eae8db60,reason=Started count=1 msg=Started container task
0.3664,Event,ADDED,eval-conflicts-rho020-r1-004.18d53f01ca276d14,reason=SuccessfulCreate count=1 msg=Created pod: eval-conflicts-rho020-r1-004-nvxmb
0.3666,Event,ADDED,eval-conflicts-rho020-r1-004.18d53f077f3451df,reason=Completed count=1 msg=Job completed
0.3667,Event,ADDED,eval-conflicts-rho020-r1-005-kdn6t.18d53f020927d17a,reason=Scheduled count=None msg=Successfully assigned compute/eval-conflicts-rho020-r1-005-kdn6t to kind-worker4
0.3669,Event,ADDED,eval-conflicts-rho020-r1-005-kdn6t.18d53f02232a86e2,"reason=Pulled count=1 msg=Container image ""busybox:musl"" already present on machine"
0.3672,Event,ADDED,eval-conflicts-rho020-r1-005-kdn6t.18d53f02248d1a6b,reason=Created count=1 msg=Created container: task
0.3674,Event,ADDED,eval-conflicts-rho020-r1-005-kdn6t.18d53f022833a895,reason=Started count=1 msg=Started container task
0.3676,Event,ADDED,eval-conflicts-rho020-r1-005.18d53f02079eff2e,reason=SuccessfulCreate count=1 msg=Created pod: eval-conflicts-rho020-r1-005-kdn6t
0.3677,Event,ADDED,eval-conflicts-rho020-r1-005.18d53f07c723bcdb,reason=Completed count=1 msg=Job completed
0.368,Event,ADDED,eval-conflicts-rho020-r1-006-45w4m.18d53f024227871b,reason=Scheduled count=None msg=Successfully assigned compute/eval-conflicts-rho020-r1-006-45w4m to kind-worker
0.3682,Event,ADDED,eval-conflicts-rho020-r1-006-45w4m.18d53f025b5f1a7a,"reason=Pulled count=1 msg=Container image ""busybox:musl"" already present on machine"
0.3684,Event,ADDED,eval-conflicts-rho020-r1-006-45w4m.18d53f025c7e43c8,reason=Created count=1 msg=Created container: task
0.3686,Event,ADDED,eval-conflicts-rho020-r1-006-45w4m.18d53f0262213f1a,reason=Started count=1 msg=Started container task
0.3688,Event,ADDED,eval-conflicts-rho020-r1-006.18d53f0240cdbea4,reason=SuccessfulCreate count=1 msg=Created pod: eval-conflicts-rho020-r1-006-45w4m
0.369,Event,ADDED,eval-conflicts-rho020-r1-006.18d53f07e22a7760,reason=Completed count=1 msg=Job completed
0.3691,Event,ADDED,eval-conflicts-rho020-r1-007-8kh6l.18d53f02826f49ee,reason=Scheduled count=None msg=Successfully assigned compute/eval-conflicts-rho020-r1-007-8kh6l to kind-worker2
0.3693,Event,ADDED,eval-conflicts-rho020-r1-007-8kh6l.18d53f029c798f3d,"reason=Pulled count=1 msg=Container image ""busybox:musl"" already present on machine"
0.3695,Event,ADDED,eval-conflicts-rho020-r1-007-8kh6l.18d53f029d8c0600,reason=Created count=1 msg=Created container: task
0.3696,Event,ADDED,eval-conflicts-rho020-r1-007-8kh6l.18d53f02a2b9e981,reason=Started count=1 msg=Started container task
0.3698,Event,ADDED,eval-conflicts-rho020-r1-007.18d53f027d7745e9,reason=SuccessfulCreate count=1 msg=Created pod: eval-conflicts-rho020-r1-007-8kh6l
0.37,Event,ADDED,eval-conflicts-rho020-r1-007.18d53f080404055c,reason=Completed count=1 msg=Job completed
0.3701,Event,ADDED,eval-conflicts-rho020-r1-008-p9mk9.18d53f02bfafbca9,reason=Scheduled count=None msg=Successfully assigned compute/eval-conflicts-rho020-r1-008-p9mk9 to kind-worker3
0.3703,Event,ADDED,eval-conflicts-rho020-r1-008-p9mk9.18d53f02d95a2762,"reason=Pulled count=1 msg=Container image ""busybox:musl"" already present on machine"
0.3705,Event,ADDED,eval-conflicts-rho020-r1-008-p9mk9.18d53f02da82ceb3,reason=Created count=1 msg=Created container: task
0.3706,Event,ADDED,eval-conflicts-rho020-r1-008-p9mk9.18d53f02dce1f0d8,reason=Started count=1 msg=Started container task
0.3708,Event,ADDED,eval-conflicts-rho020-r1-008.18d53f02b926d2d3,reason=SuccessfulCreate count=1 msg=Created pod: eval-conflicts-rho020-r1-008-p9mk9
0.371,Event,ADDED,eval-conflicts-rho020-r1-008.18d53f08742487a1,reason=Completed count=1 msg=Job completed
0.3711,Event,ADDED,eval-conflicts-rho020-r1-009-zcjm5.18d53f02f54cc64d,reason=Scheduled count=None msg=Successfully assigned compute/eval-conflicts-rho020-r1-009-zcjm5 to kind-worker2
0.3713,Event,ADDED,eval-conflicts-rho020-r1-009-zcjm5.18d53f03102b8b52,"reason=Pulled count=1 msg=Container image ""busybox:musl"" already present on machine"
0.3714,Event,ADDED,eval-conflicts-rho020-r1-009-zcjm5.18d53f03114f95b2,reason=Created count=1 msg=Created container: task
0.3717,Event,ADDED,eval-conflicts-rho020-r1-009-zcjm5.18d53f03180a2a53,reason=Started count=1 msg=Started container task
0.3719,Event,ADDED,eval-conflicts-rho020-r1-009.18d53f02f3e06704,reason=SuccessfulCreate count=1 msg=Created pod: eval-conflicts-rho020-r1-009-zcjm5
0.3721,Event,ADDED,eval-conflicts-rho020-r1-009.18d53f087c791f7f,reason=Completed count=1 msg=Job completed
0.3722,Event,ADDED,eval-conflicts-rho020-r1-010-wmp2r.18d53f0331305c13,reason=Scheduled count=None msg=Successfully assigned compute/eval-conflicts-rho020-r1-010-wmp2r to kind-worker2
0.3727,Event,ADDED,eval-conflicts-rho020-r1-010-wmp2r.18d53f034a6e1315,"reason=Pulled count=1 msg=Container image ""busybox:musl"" already present on machine"
0.377,Event,ADDED,eval-conflicts-rho020-r1-010-wmp2r.18d53f034b9efbfd,reason=Created count=1 msg=Created container: task
0.3772,Event,ADDED,eval-conflicts-rho020-r1-010-wmp2r.18d53f0350b4869d,reason=Started count=1 msg=Started container task
0.3773,Event,ADDED,eval-conflicts-rho020-r1-010.18d53f032fe03217,reason=SuccessfulCreate count=1 msg=Created pod: eval-conflicts-rho020-r1-010-wmp2r
0.3775,Event,ADDED,eval-conflicts-rho020-r1-010.18d53f08b893eb02,reason=Completed count=1 msg=Job completed
0.3777,Event,ADDED,eval-conflicts-rho020-r1-011-nqflb.18d53f036d1dec63,reason=Scheduled count=None msg=Successfully assigned compute/eval-conflicts-rho020-r1-011-nqflb to kind-worker4
0.3779,Event,ADDED,eval-conflicts-rho020-r1-011-nqflb.18d53f0388390a03,"reason=Pulled count=1 msg=Container image ""busybox:musl"" already present on machine"
0.3781,Event,ADDED,eval-conflicts-rho020-r1-011-nqflb.18d53f038956f23d,reason=Created count=1 msg=Created container: task
0.3783,Event,ADDED,eval-conflicts-rho020-r1-011-nqflb.18d53f038d7f68c7,reason=Started count=1 msg=Started container task
0.3785,Event,ADDED,eval-conflicts-rho020-r1-011.18d53f036b944eee,reason=SuccessfulCreate count=1 msg=Created pod: eval-conflicts-rho020-r1-011-nqflb
0.3786,Event,ADDED,eval-conflicts-rho020-r1-011.18d53f08f1a5548b,reason=Completed count=1 msg=Job completed
0.3789,Event,ADDED,eval-conflicts-rho020-r1-012-kzcb4.18d53f03a82ea29a,reason=Scheduled count=None msg=Successfully assigned compute/eval-conflicts-rho020-r1-012-kzcb4 to kind-worker
0.379,Event,ADDED,eval-conflicts-rho020-r1-012-kzcb4.18d53f03c342794b,"reason=Pulled count=1 msg=Container image ""busybox:musl"" already present on machine"
0.3792,Event,ADDED,eval-conflicts-rho020-r1-012-kzcb4.18d53f03c469e234,reason=Created count=1 msg=Created container: task
0.3794,Event,ADDED,eval-conflicts-rho020-r1-012-kzcb4.18d53f03c93a4759,reason=Started count=1 msg=Started container task
0.3796,Event,ADDED,eval-conflicts-rho020-r1-012.18d53f03a6b447d3,reason=SuccessfulCreate count=1 msg=Created pod: eval-conflicts-rho020-r1-012-kzcb4
0.3797,Event,ADDED,eval-conflicts-rho020-r1-012.18d53f094a7dc11f,reason=Completed count=1 msg=Job completed
0.3799,Event,ADDED,eval-conflicts-rho020-r1-013-d4b9c.18d53f03e64c9e4a,reason=Scheduled count=None msg=Successfully assigned compute/eval-conflicts-rho020-r1-013-d4b9c to kind-worker4
0.38,Event,ADDED,eval-conflicts-rho020-r1-013-d4b9c.18d53f0402c329e4,"reason=Pulled count=1 msg=Container image ""busybox:musl"" already present on machine"
0.3802,Event,ADDED,eval-conflicts-rho020-r1-013-d4b9c.18d53f0403dc4281,reason=Created count=1 msg=Created container: task
0.3804,Event,ADDED,eval-conflicts-rho020-r1-013-d4b9c.18d53f040934f811,reason=Started count=1 msg=Started container task
0.3805,Event,ADDED,eval-conflicts-rho020-r1-013.18d53f03e4e2f882,reason=SuccessfulCreate count=1 msg=Created pod: eval-conflicts-rho020-r1-013-d4b9c
0.3808,Event,ADDED,eval-conflicts-rho020-r1-013.18d53f09696e4501,reason=Completed count=1 msg=Job completed
0.381,Event,ADDED,eval-conflicts-rho020-r1-014-2hv6v.18d53f041f80d0ee,reason=Scheduled count=None msg=Successfully assigned compute/eval-conflicts-rho020-r1-014-2hv6v to kind-worker5
0.3812,Event,ADDED,eval-conflicts-rho020-r1-014-2hv6v.18d53f04394504b6,"reason=Pulled count=1 msg=Container image ""busybox:musl"" already present on machine"
0.3814,Event,ADDED,eval-conflicts-rho020-r1-014-2hv6v.18d53f043aa018be,reason=Created count=1 msg=Created container: task
0.3816,Event,ADDED,eval-conflicts-rho020-r1-014-2hv6v.18d53f043ca97a5a,reason=Started count=1 msg=Started container task
0.3818,Event,ADDED,eval-conflicts-rho020-r1-014.18d53f041e639f34,reason=SuccessfulCreate count=1 msg=Created pod: eval-conflicts-rho020-r1-014-2hv6v
0.382,Event,ADDED,eval-conflicts-rho020-r1-014.18d53f09d3811bb6,reason=Completed count=1 msg=Job completed
0.3822,Event,ADDED,eval-conflicts-rho020-r1-015-qdvhq.18d53f045b6c0c36,reason=Scheduled count=None msg=Successfully assigned compute/eval-conflicts-rho020-r1-015-qdvhq to kind-worker5
0.3823,Event,ADDED,eval-conflicts-rho020-r1-015-qdvhq.18d53f0474bd67b7,"reason=Pulled count=1 msg=Container image ""busybox:musl"" already present on machine"
0.3825,Event,ADDED,eval-conflicts-rho020-r1-015-qdvhq.18d53f0475bfbb15,reason=Created count=1 msg=Created container: task
0.3827,Event,ADDED,eval-conflicts-rho020-r1-015-qdvhq.18d53f0477a9fd9c,reason=Started count=1 msg=Started container task
0.3829,Event,ADDED,eval-conflicts-rho020-r1-015.18d53f045a42f28b,reason=SuccessfulCreate count=1 msg=Created pod: eval-conflicts-rho020-r1-015-qdvhq
0.3831,Event,ADDED,eval-conflicts-rho020-r1-015.18d53f0a123d1e12,reason=Completed count=1 msg=Job completed
0.3832,Event,ADDED,eval-conflicts-rho020-r1-016-bztnq.18d53f04968ce151,reason=Scheduled count=None msg=Successfully assigned compute/eval-conflicts-rho020-r1-016-bztnq to kind-worker
0.3834,Event,ADDED,eval-conflicts-rho020-r1-016-bztnq.18d53f04afc64652,"reason=Pulled count=1 msg=Container image ""busybox:musl"" already present on machine"
0.3835,Event,ADDED,eval-conflicts-rho020-r1-016-bztnq.18d53f04b0f9924e,reason=Created count=1 msg=Created container: task
0.3837,Event,ADDED,eval-conflicts-rho020-r1-016-bztnq.18d53f04b440fc9f,reason=Started count=1 msg=Started container task
0.3839,Event,ADDED,eval-conflicts-rho020-r1-016.18d53f04953ad3ce,reason=SuccessfulCreate count=1 msg=Created pod: eval-conflicts-rho020-r1-016-bztnq
0.3841,Event,ADDED,eval-conflicts-rho020-r1-016.18d53f0a4401ce3c,reason=Completed count=1 msg=Job completed
0.3842,Event,ADDED,eval-conflicts-rho020-r1-017-899ph.18d53f04d212e320,reason=Scheduled count=None msg=Successfully assigned compute/eval-conflicts-rho020-r1-017-899ph to kind-worker4
0.3844,Event,ADDED,eval-conflicts-rho020-r1-017-899ph.18d53f04ec829cd3,"reason=Pulled count=1 msg=Container image ""busybox:musl"" already present on machine"
0.3846,Event,ADDED,eval-conflicts-rho020-r1-017-899ph.18d53f04ed92b9a8,reason=Created count=1 msg=Created container: task
0.3847,Event,ADDED,eval-conflicts-rho020-r1-017-899ph.18d53f04f25efb79,reason=Started count=1 msg=Started container task
0.3849,Event,ADDED,eval-conflicts-rho020-r1-017.18d53f04d0dcd534,reason=SuccessfulCreate count=1 msg=Created pod: eval-conflicts-rho020-r1-017-899ph
0.3851,Event,ADDED,eval-conflicts-rho020-r1-017.18d53f0a5af61571,reason=Completed count=1 msg=Job completed
0.3852,Event,ADDED,eval-conflicts-rho020-r1-018-27nt9.18d53f050d50336d,"reason=FailedScheduling count=None msg=0/6 nodes are available: 1 c_wall violated: 2 conflicting context pair(s) with node memory, 2 c_wall violated: 1 conflicting context pair(s) with node memory, 3 node(s) had untolerated taint(s). no new claims to deallocate, preemption: 0/6 nodes are available: 3 No preemption victims found for incoming pod, 3 Preemption is not helpful for scheduling."
0.3854,Event,ADDED,eval-conflicts-rho020-r1-018-27nt9.18d53f05118c949b,"reason=FailedScheduling count=None msg=0/6 nodes are available: 1 c_wall violated: 2 conflicting context pair(s) with node memory, 2 c_wall violated: 1 conflicting context pair(s) with node memory, 3 node(s) had untolerated taint(s). no new claims to deallocate, preemption: 0/6 nodes are available: 3 No preemption victims found for incoming pod, 3 Preemption is not helpful for scheduling."
0.3856,Event,ADDED,eval-conflicts-rho020-r1-018-27nt9.18d53f053d28bd47,"reason=FailedScheduling count=None msg=0/6 nodes are available: 2 c_wall violated: 1 conflicting context pair(s) with node memory, 4 node(s) had untolerated taint(s). no new claims to deallocate, preemption: 0/6 nodes are available: 2 No preemption victims found for incoming pod, 4 Preemption is not helpful for scheduling."
0.3859,Event,ADDED,eval-conflicts-rho020-r1-018-27nt9.18d53f0588a22ad9,"reason=FailedScheduling count=None msg=0/6 nodes are available: 1 c_wall violated: 1 conflicting context pair(s) with node memory, 1 c_wall violated: 2 conflicting context pair(s) with node memory, 4 node(s) had untolerated taint(s). no new claims to deallocate, preemption: 0/6 nodes are available: 2 No preemption victims found for incoming pod, 4 Preemption is not helpful for scheduling."
0.386,Event,ADDED,eval-conflicts-rho020-r1-018-27nt9.18d53f058fd415a8,"reason=FailedScheduling count=None msg=0/6 nodes are available: 1 c_wall violated: 1 conflicting context pair(s) with node memory, 5 node(s) had untolerated taint(s). no new claims to deallocate, preemption: 0/6 nodes are available: 1 No preemption victims found for incoming pod, 5 Preemption is not helpful for scheduling."
0.3862,Event,ADDED,eval-conflicts-rho020-r1-018-27nt9.18d53f089ebd613e,reason=Scheduled count=None msg=Successfully assigned compute/eval-conflicts-rho020-r1-018-27nt9 to kind-worker2
0.3864,Event,ADDED,eval-conflicts-rho020-r1-018-27nt9.18d53f08b9db55c0,"reason=Pulled count=1 msg=Container image ""busybox:musl"" already present on machine"
0.3865,Event,ADDED,eval-conflicts-rho020-r1-018-27nt9.18d53f08bc9e7f33,reason=Created count=1 msg=Created container: task
0.3867,Event,ADDED,eval-conflicts-rho020-r1-018-27nt9.18d53f08bf92acbb,reason=Started count=1 msg=Started container task
0.3869,Event,ADDED,eval-conflicts-rho020-r1-018.18d53f050c98fe35,reason=SuccessfulCreate count=1 msg=Created pod: eval-conflicts-rho020-r1-018-27nt9
0.387,Event,ADDED,eval-conflicts-rho020-r1-018.18d53f0e56e4f38a,reason=Completed count=1 msg=Job completed
0.3872,Event,ADDED,eval-conflicts-rho020-r1-019-dpthr.18d53f054932dcfd,reason=Scheduled count=None msg=Successfully assigned compute/eval-conflicts-rho020-r1-019-dpthr to kind-worker5
0.3873,Event,ADDED,eval-conflicts-rho020-r1-019-dpthr.18d53f0564a77e57,"reason=Pulled count=1 msg=Container image ""busybox:musl"" already present on machine"
0.3875,Event,ADDED,eval-conflicts-rho020-r1-019-dpthr.18d53f05661d24c2,reason=Created count=1 msg=Created container: task
0.3877,Event,ADDED,eval-conflicts-rho020-r1-019-dpthr.18d53f05698e67cc,reason=Started count=1 msg=Started container task
0.3878,Event,ADDED,eval-conflicts-rho020-r1-019.18d53f05485f0445,reason=SuccessfulCreate count=1 msg=Created pod: eval-conflicts-rho020-r1-019-dpthr
0.388,Event,ADDED,eval-conflicts-rho020-r1-019.18d53f0aff5f7b44,reason=Completed count=1 msg=Job completed
0.3885,Event,ADDED,eval-conflicts-rho020-r1-020-ff2jv.18d53f05851769bf,reason=Scheduled count=None msg=Successfully assigned compute/eval-conflicts-rho020-r1-020-ff2jv to kind-worker5
0.3887,Event,ADDED,eval-conflicts-rho020-r1-020-ff2jv.18d53f059f120c12,"reason=Pulled count=1 msg=Container image ""busybox:musl"" already present on machine"
0.3889,Event,ADDED,eval-conflicts-rho020-r1-020-ff2jv.18d53f05a030af89,reason=Created count=1 msg=Created container: task
0.3891,Event,ADDED,eval-conflicts-rho020-r1-020-ff2jv.18d53f05a49e6939,reason=Started count=1 msg=Started container task
0.3893,Event,ADDED,eval-conflicts-rho020-r1-020.18d53f05843679ab,reason=SuccessfulCreate count=1 msg=Created pod: eval-conflicts-rho020-r1-020-ff2jv
0.3895,Event,ADDED,eval-conflicts-rho020-r1-020.18d53f0b3c14ee64,reason=Completed count=1 msg=Job completed
0.3896,Event,ADDED,eval-conflicts-rho020-r1-021-z685d.18d53f05c17dd23e,reason=Scheduled count=None msg=Successfully assigned compute/eval-conflicts-rho020-r1-021-z685d to kind-worker
0.39,Event,ADDED,eval-conflicts-rho020-r1-021-z685d.18d53f05dba7e57a,"reason=Pulled count=1 msg=Container image ""busybox:musl"" already present on machine"
0.3902,Event,ADDED,eval-conflicts-rho020-r1-021-z685d.18d53f05dcb7ddab,reason=Created count=1 msg=Created container: task
0.3904,Event,ADDED,eval-conflicts-rho020-r1-021-z685d.18d53f05dea086e6,reason=Started count=1 msg=Started container task
0.3905,Event,ADDED,eval-conflicts-rho020-r1-021.18d53f05c0e9ba60,reason=SuccessfulCreate count=1 msg=Created pod: eval-conflicts-rho020-r1-021-z685d
0.3907,Event,ADDED,eval-conflicts-rho020-r1-021.18d53f0b63a116f3,reason=Completed count=1 msg=Job completed
0.3909,Event,ADDED,eval-conflicts-rho020-r1-022-g6qf4.18d53f05fb0b32af,reason=Scheduled count=None msg=Successfully assigned compute/eval-conflicts-rho020-r1-022-g6qf4 to kind-worker
0.391,Event,ADDED,eval-conflicts-rho020-r1-022-g6qf4.18d53f061694b163,"reason=Pulled count=1 msg=Container image ""busybox:musl"" already present on machine"
0.3912,Event,ADDED,eval-conflicts-rho020-r1-022-g6qf4.18d53f0617ae5ac0,reason=Created count=1 msg=Created container: task
0.3914,Event,ADDED,eval-conflicts-rho020-r1-022-g6qf4.18d53f061d75a82d,reason=Started count=1 msg=Started container task
0.3916,Event,ADDED,eval-conflicts-rho020-r1-022.18d53f05fa8d43f6,reason=SuccessfulCreate count=1 msg=Created pod: eval-conflicts-rho020-r1-022-g6qf4
0.3917,Event,ADDED,eval-conflicts-rho020-r1-022.18d53f0b9e0cd408,reason=Completed count=1 msg=Job completed
0.3919,Event,ADDED,eval-conflicts-rho020-r1-023-n5lv2.18d53f0636d11f06,reason=Scheduled count=None msg=Successfully assigned compute/eval-conflicts-rho020-r1-023-n5lv2 to kind-worker
0.3921,Event,ADDED,eval-conflicts-rho020-r1-023-n5lv2.18d53f0650957947,"reason=Pulled count=1 msg=Container image ""busybox:musl"" already present on machine"
0.3922,Event,ADDED,eval-conflicts-rho020-r1-023-n5lv2.18d53f0651b09059,reason=Created count=1 msg=Created container: task
0.3924,Event,ADDED,eval-conflicts-rho020-r1-023-n5lv2.18d53f065467d5c8,reason=Started count=1 msg=Started container task
0.3926,Event,ADDED,eval-conflicts-rho020-r1-023.18d53f0636502c43,reason=SuccessfulCreate count=1 msg=Created pod: eval-conflicts-rho020-r1-023-n5lv2
0.3927,Event,ADDED,eval-conflicts-rho020-r1-023.18d53f0bda26e313,reason=Completed count=1 msg=Job completed
0.3929,Event,ADDED,eval-conflicts-rho020-r1-024-txqzn.18d53f0672bf5911,"reason=FailedScheduling count=None msg=0/6 nodes are available: 6 node(s) had untolerated taint(s). no new claims to deallocate, preemption: 0/6 nodes are available: 6 Preemption is not helpful for scheduling."
0.393,Event,ADDED,eval-conflicts-rho020-r1-024-txqzn.18d53f08a3f6f979,reason=Scheduled count=None msg=Successfully assigned compute/eval-conflicts-rho020-r1-024-txqzn to kind-worker2
0.3932,Event,ADDED,eval-conflicts-rho020-r1-024-txqzn.18d53f08ba82738e,"reason=Pulled count=1 msg=Container image ""busybox:musl"" already present on machine"
0.3933,Event,ADDED,eval-conflicts-rho020-r1-024-txqzn.18d53f08bd669f4c,reason=Created count=1 msg=Created container: task
0.3935,Event,ADDED,eval-conflicts-rho020-r1-024-txqzn.18d53f08c061bebb,reason=Started count=1 msg=Started container task
0.3937,Event,ADDED,eval-conflicts-rho020-r1-024.18d53f0672b83049,reason=SuccessfulCreate count=1 msg=Created pod: eval-conflicts-rho020-r1-024-txqzn
0.3939,Event,ADDED,eval-conflicts-rho020-r1-024.18d53f0e1a2fc5b6,reason=Completed count=1 msg=Job completed
0.394,Event,ADDED,eval-conflicts-rho020-r1-025-qqng4.18d53f06adbd2204,"reason=FailedScheduling count=None msg=0/6 nodes are available: 6 node(s) had untolerated taint(s). no new claims to deallocate, preemption: 0/6 nodes are available: 6 Preemption is not helpful for scheduling."
0.3942,Event,ADDED,eval-conflicts-rho020-r1-025-qqng4.18d53f08a3f87287,reason=Scheduled count=None msg=Successfully assigned compute/eval-conflicts-rho020-r1-025-qqng4 to kind-worker2
0.3943,Event,ADDED,eval-conflicts-rho020-r1-025-qqng4.18d53f08baa32f3d,"reason=Pulled count=1 msg=Container image ""busybox:musl"" already present on machine"
0.3945,Event,ADDED,eval-conflicts-rho020-r1-025-qqng4.18d53f08bdef6519,reason=Created count=1 msg=Created container: task
0.3946,Event,ADDED,eval-conflicts-rho020-r1-025-qqng4.18d53f08c0d4e420,reason=Started count=1 msg=Started container task
0.3948,Event,ADDED,eval-conflicts-rho020-r1-025.18d53f06adb073d5,reason=SuccessfulCreate count=1 msg=Created pod: eval-conflicts-rho020-r1-025-qqng4
0.395,Event,ADDED,eval-conflicts-rho020-r1-025.18d53f0e563e3d3d,reason=Completed count=1 msg=Job completed
0.3951,Event,ADDED,eval-conflicts-rho020-r1-026-wlr6h.18d53f06e9094eb6,"reason=FailedScheduling count=None msg=0/6 nodes are available: 6 node(s) had untolerated taint(s). no new claims to deallocate, preemption: 0/6 nodes are available: 6 Preemption is not helpful for scheduling."
0.3953,Event,ADDED,eval-conflicts-rho020-r1-026-wlr6h.18d53f08a458b8d5,reason=Scheduled count=None msg=Successfully assigned compute/eval-conflicts-rho020-r1-026-wlr6h to kind-worker2
0.3954,Event,ADDED,eval-conflicts-rho020-r1-026-wlr6h.18d53f08bf09a1f5,"reason=Pulled count=1 msg=Container image ""busybox:musl"" already present on machine"
0.396,Event,ADDED,eval-conflicts-rho020-r1-026-wlr6h.18d53f08c0cd39e7,reason=Created count=1 msg=Created container: task
0.3962,Event,ADDED,eval-conflicts-rho020-r1-026-wlr6h.18d53f08c33841bf,reason=Started count=1 msg=Started container task
0.3966,Event,ADDED,eval-conflicts-rho020-r1-026.18d53f06e8fffaee,reason=SuccessfulCreate count=1 msg=Created pod: eval-conflicts-rho020-r1-026-wlr6h
0.3968,Event,ADDED,eval-conflicts-rho020-r1-026.18d53f0e19ce0a8c,reason=Completed count=1 msg=Job completed
0.397,Event,ADDED,eval-conflicts-rho020-r1-027-mt2ll.18d53f07251c251e,"reason=FailedScheduling count=None msg=0/6 nodes are available: 6 node(s) had untolerated taint(s). no new claims to deallocate, preemption: 0/6 nodes are available: 6 Preemption is not helpful for scheduling."
0.3971,Event,ADDED,eval-conflicts-rho020-r1-027-mt2ll.18d53f08a48084a6,reason=Scheduled count=None msg=Successfully assigned compute/eval-conflicts-rho020-r1-027-mt2ll to kind-worker2
0.3974,Event,ADDED,eval-conflicts-rho020-r1-027-mt2ll.18d53f08c0d54160,"reason=Pulled count=1 msg=Container image ""busybox:musl"" already present on machine"
0.3975,Event,ADDED,eval-conflicts-rho020-r1-027-mt2ll.18d53f08c260a85d,reason=Created count=1 msg=Created container: task
0.3977,Event,ADDED,eval-conflicts-rho020-r1-027-mt2ll.18d53f08c71f9837,reason=Started count=1 msg=Started container task
0.3979,Event,ADDED,eval-conflicts-rho020-r1-027.18d53f0725101cd8,reason=SuccessfulCreate count=1 msg=Created pod: eval-conflicts-rho020-r1-027-mt2ll
0.398,Event,ADDED,eval-conflicts-rho020-r1-027.18d53f0e19efca3f,reason=Completed count=1 msg=Job completed
0.3982,Event,ADDED,eval-conflicts-rho020-r1-028-nln9v.18d53f07605baf22,"reason=FailedScheduling count=None msg=0/6 nodes are available: 6 node(s) had untolerated taint(s). no new claims to deallocate, preemption: 0/6 nodes are available: 6 Preemption is not helpful for scheduling."
0.3983,Event,ADDED,eval-conflicts-rho020-r1-028-nln9v.18d53f08a45e83fb,"reason=FailedScheduling count=None msg=0/6 nodes are available: 1 c_wall violated: 1 conflicting context pair(s) with node memory, 5 node(s) had untolerated taint(s). no new claims to deallocate, preemption: 0/6 nodes are available: 1 No preemption victims found for incoming pod, 5 Preemption is not helpful for scheduling."
0.3986,Event,ADDED,eval-conflicts-rho020-r1-028-nln9v.18d53f08ab67c4bb,"reason=FailedScheduling count=None msg=0/6 nodes are available: 1 c_wall violated: 1 conflicting context pair(s) with node memory, 5 node(s) had untolerated taint(s). no new claims to deallocate, preemption: 0/6 nodes are available: 1 No preemption victims found for incoming pod, 5 Preemption is not helpful for scheduling."
0.3988,Event,ADDED,eval-conflicts-rho020-r1-028-nln9v.18d53f0c50c361a3,reason=Scheduled count=None msg=Successfully assigned compute/eval-conflicts-rho020-r1-028-nln9v to kind-worker3
0.3989,Event,ADDED,eval-conflicts-rho020-r1-028-nln9v.18d53f0c6b50308b,"reason=Pulled count=1 msg=Container image ""busybox:musl"" already present on machine"
0.3992,Event,ADDED,eval-conflicts-rho020-r1-028-nln9v.18d53f0c6e3313aa,reason=Created count=1 msg=Created container: task
0.3993,Event,ADDED,eval-conflicts-rho020-r1-028-nln9v.18d53f0c71c74c81,reason=Started count=1 msg=Started container task
0.3995,Event,ADDED,eval-conflicts-rho020-r1-028.18d53f07604ecb8e,reason=SuccessfulCreate count=1 msg=Created pod: eval-conflicts-rho020-r1-028-nln9v
0.3997,Event,ADDED,eval-conflicts-rho020-r1-028.18d53f120d476bdf,reason=Completed count=1 msg=Job completed
0.3998,Event,ADDED,eval-conflicts-rho020-r1-029-csz2w.18d53f079c19ba16,"reason=FailedScheduling count=None msg=0/6 nodes are available: 6 node(s) had untolerated taint(s). no new claims to deallocate, preemption: 0/6 nodes are available: 6 Preemption is not helpful for scheduling."
0.4,Event,ADDED,eval-conflicts-rho020-r1-029-csz2w.18d53f08a5a521e7,reason=Scheduled count=None msg=Successfully assigned compute/eval-conflicts-rho020-r1-029-csz2w to kind-worker2
0.4003,Event,ADDED,eval-conflicts-rho020-r1-029-csz2w.18d53f08c0ea4c1a,"reason=Pulled count=1 msg=Container image ""busybox:musl"" already present on machine"
0.4008,Event,ADDED,eval-conflicts-rho020-r1-029-csz2w.18d53f08c29c564b,reason=Created count=1 msg=Created container: task
0.4011,Event,ADDED,eval-conflicts-rho020-r1-029-csz2w.18d53f08c755fdc1,reason=Started count=1 msg=Started container task
0.4014,Event,ADDED,eval-conflicts-rho020-r1-029.18d53f079c0ddfc6,reason=SuccessfulCreate count=1 msg=Created pod: eval-conflicts-rho020-r1-029-csz2w
0.4016,Event,ADDED,eval-conflicts-rho020-r1-029.18d53f0e56e42543,reason=Completed count=1 msg=Job completed
0.4019,Event,ADDED,eval-conflicts-rho020-r1-030-phgrg.18d53f07d79afb04,"reason=FailedScheduling count=None msg=0/6 nodes are available: 6 node(s) had untolerated taint(s). no new claims to deallocate, preemption: 0/6 nodes are available: 6 Preemption is not helpful for scheduling."
0.4021,Event,ADDED,eval-conflicts-rho020-r1-030-phgrg.18d53f08a5665816,"reason=FailedScheduling count=None msg=0/6 nodes are available: 1 c_wall violated: 1 conflicting context pair(s) with node memory, 5 node(s) had untolerated taint(s). no new claims to deallocate, preemption: 0/6 nodes are available: 1 No preemption victims found for incoming pod, 5 Preemption is not helpful for scheduling."
0.4023,Event,ADDED,eval-conflicts-rho020-r1-030-phgrg.18d53f08ab966070,"reason=FailedScheduling count=None msg=0/6 nodes are available: 1 c_wall violated: 1 conflicting context pair(s) with node memory, 5 node(s) had untolerated taint(s). no new claims to deallocate, preemption: 0/6 nodes are available: 1 No preemption victims found for incoming pod, 5 Preemption is not helpful for scheduling."
0.4027,Event,ADDED,eval-conflicts-rho020-r1-030-phgrg.18d53f0c53ab5277,reason=Scheduled count=None msg=Successfully assigned compute/eval-conflicts-rho020-r1-030-phgrg to kind-worker3
0.4029,Event,ADDED,eval-conflicts-rho020-r1-030-phgrg.18d53f0c6e9baa30,"reason=Pulled count=1 msg=Container image ""busybox:musl"" already present on machine"
0.4031,Event,ADDED,eval-conflicts-rho020-r1-030-phgrg.18d53f0c7319ddc1,reason=Created count=1 msg=Created container: task
0.4035,Event,ADDED,eval-conflicts-rho020-r1-030-phgrg.18d53f0c79472759,reason=Started count=1 msg=Started container task
0.4037,Event,ADDED,eval-conflicts-rho020-r1-030.18d53f07d7902847,reason=SuccessfulCreate count=1 msg=Created pod: eval-conflicts-rho020-r1-030-phgrg
0.4039,Event,ADDED,eval-conflicts-rho020-r1-030.18d53f1255daea50,reason=Completed count=1 msg=Job completed
0.404,Event,ADDED,eval-conflicts-rho020-r1-031-gss2q.18d53f08132463b6,"reason=FailedScheduling count=None msg=0/6 nodes are available: 6 node(s) had untolerated taint(s). no new claims to deallocate, preemption: 0/6 nodes are available: 6 Preemption is not helpful for scheduling."
0.4043,Event,ADDED,eval-conflicts-rho020-r1-031-gss2q.18d53f08aa6cfe42,reason=Scheduled count=None msg=Successfully assigned compute/eval-conflicts-rho020-r1-031-gss2q to kind-worker2
0.4045,Event,ADDED,eval-conflicts-rho020-r1-031-gss2q.18d53f08c304e0a6,"reason=Pulled count=1 msg=Container image ""busybox:musl"" already present on machine"
0.4047,Event,ADDED,eval-conflicts-rho020-r1-031-gss2q.18d53f08c439133d,reason=Created count=1 msg=Created container: task
0.4049,Event,ADDED,eval-conflicts-rho020-r1-031-gss2q.18d53f08c7b1fed8,reason=Started count=1 msg=Started container task
0.4053,Event,ADDED,eval-conflicts-rho020-r1-031.18d53f08131dec8a,reason=SuccessfulCreate count=1 msg=Created pod: eval-conflicts-rho020-r1-031-gss2q
0.4055,Event,ADDED,eval-conflicts-rho020-r1-031.18d53f0e56e2dbc8,reason=Completed count=1 msg=Job completed
0.4057,Event,ADDED,eval-conflicts-rho020-r1-032-5bh6x.18d53f084ee2f467,"reason=FailedScheduling count=None msg=0/6 nodes are available: 6 node(s) had untolerated taint(s). no new claims to deallocate, preemption: 0/6 nodes are available: 6 Preemption is not helpful for scheduling."
0.406,Event,ADDED,eval-conflicts-rho020-r1-032-5bh6x.18d53f08aa2e048d,"reason=FailedScheduling count=None msg=0/6 nodes are available: 1 c_wall violated: 1 conflicting context pair(s) with node memory, 5 node(s) had untolerated taint(s). no new claims to deallocate, preemption: 0/6 nodes are available: 1 No preemption victims found for incoming pod, 5 Preemption is not helpful for scheduling."
0.4062,Event,ADDED,eval-conflicts-rho020-r1-032-5bh6x.18d53f08afe62c78,"reason=FailedScheduling count=None msg=0/6 nodes are available: 1 c_wall violated: 1 conflicting context pair(s) with node memory, 5 node(s) had untolerated taint(s). no new claims to deallocate, preemption: 0/6 nodes are available: 1 No preemption victims found for incoming pod, 5 Preemption is not helpful for scheduling."
0.4064,Event,ADDED,eval-conflicts-rho020-r1-032-5bh6x.18d53f0c63e5654f,"reason=FailedScheduling count=None msg=0/6 nodes are available: 2 c_wall violated: 1 conflicting context pair(s) with node memory, 4 node(s) had untolerated taint(s). no new claims to deallocate, preemption: 0/6 nodes are available: 2 No preemption victims found for incoming pod, 4 Preemption is not helpful for scheduling."
0.4068,Event,ADDED,eval-conflicts-rho020-r1-032-5bh6x.18d53f0c855286e6,"reason=FailedScheduling count=None msg=0/6 nodes are available: 1 c_wall violated: 1 conflicting context pair(s) with node memory, 1 c_wall violated: 2 conflicting context pair(s) with node memory, 4 node(s) had untolerated taint(s). no new claims to deallocate, preemption: 0/6 nodes are available: 2 No preemption victims found for incoming pod, 4 Preemption is not helpful for scheduling."
0.407,Event,ADDED,eval-conflicts-rho020-r1-032-5bh6x.18d53f0d4909f18a,"reason=FailedScheduling count=None msg=0/6 nodes are available: 1 c_wall violated: 2 conflicting context pair(s) with node memory, 5 node(s) had untolerated taint(s). no new claims to deallocate, preemption: 0/6 nodes are available: 1 No preemption victims found for incoming pod, 5 Preemption is not helpful for scheduling."
0.4071,Event,ADDED,eval-conflicts-rho020-r1-032-5bh6x.18d53f0ea34e6685,reason=Scheduled count=None msg=Successfully assigned compute/eval-conflicts-rho020-r1-032-5bh6x to kind-worker4
0.4074,Event,ADDED,eval-conflicts-rho020-r1-032-5bh6x.18d53f0ec2f4795a,"reason=Pulled count=1 msg=Container image ""busybox:musl"" already present on machine"
0.4076,Event,ADDED,eval-conflicts-rho020-r1-032-5bh6x.18d53f0ec6ad544f,reason=Created count=1 msg=Created container: task
0.4078,Event,ADDED,eval-conflicts-rho020-r1-032-5bh6x.18d53f0ecaa51e64,reason=Started count=1 msg=Started container task
0.408,Event,ADDED,eval-conflicts-rho020-r1-032.18d53f084ed5dddb,reason=SuccessfulCreate count=1 msg=Created pod: eval-conflicts-rho020-r1-032-5bh6x
0.4083,Event,ADDED,eval-conflicts-rho020-r1-032.18d53f146412d073,reason=Completed count=1 msg=Job completed
0.4084,Event,ADDED,eval-conflicts-rho020-r1-033-cszxq.18d53f088aeee499,"reason=FailedScheduling count=None msg=0/6 nodes are available: 6 node(s) had untolerated taint(s). no new claims to deallocate, preemption: 0/6 nodes are available: 6 Preemption is not helpful for scheduling."
0.4086,Event,ADDED,eval-conflicts-rho020-r1-033-cszxq.18d53f08aad573dd,"reason=FailedScheduling count=None msg=0/6 nodes are available: 1 c_wall violated: 1 conflicting context pair(s) with node memory, 5 node(s) had untolerated taint(s). no new claims to deallocate, preemption: 0/6 nodes are available: 1 No preemption victims found for incoming pod, 5 Preemption is not helpful for scheduling."
0.4088,Event,ADDED,eval-conflicts-rho020-r1-033-cszxq.18d53f08b01fe4ac,"reason=FailedScheduling count=None msg=0/6 nodes are available: 1 c_wall violated: 1 conflicting context pair(s) with node memory, 5 node(s) had untolerated taint(s). no new claims to deallocate, preemption: 0/6 nodes are available: 1 No preemption victims found for incoming pod, 5 Preemption is not helpful for scheduling."
0.409,Event,ADDED,eval-conflicts-rho020-r1-033-cszxq.18d53f0c6516a865,"reason=FailedScheduling count=None msg=0/6 nodes are available: 2 c_wall violated: 1 conflicting context pair(s) with node memory, 4 node(s) had untolerated taint(s). no new claims to deallocate, preemption: 0/6 nodes are available: 2 No preemption victims found for incoming pod, 4 Preemption is not helpful for scheduling."
0.4092,Event,ADDED,eval-conflicts-rho020-r1-033-cszxq.18d53f0c85a59ed1,"reason=FailedScheduling count=None msg=0/6 nodes are available: 1 c_wall violated: 1 conflicting context pair(s) with node memory, 1 c_wall violated: 2 conflicting context pair(s) with node memory, 4 node(s) had untolerated taint(s). no new claims to deallocate, preemption: 0/6 nodes are available: 2 No preemption victims found for incoming pod, 4 Preemption is not helpful for scheduling."
0.4094,Event,ADDED,eval-conflicts-rho020-r1-033-cszxq.18d53f0d493a6f17,"reason=FailedScheduling count=None msg=0/6 nodes are available: 1 c_wall violated: 2 conflicting context pair(s) with node memory, 5 node(s) had untolerated taint(s). no new claims to deallocate, preemption: 0/6 nodes are available: 1 No preemption victims found for incoming pod, 5 Preemption is not helpful for scheduling."
0.4095,Event,ADDED,eval-conflicts-rho020-r1-033-cszxq.18d53f0ea735f477,reason=Scheduled count=None msg=Successfully assigned compute/eval-conflicts-rho020-r1-033-cszxq to kind-worker4
0.4097,Event,ADDED,eval-conflicts-rho020-r1-033-cszxq.18d53f0ec2930ed0,"reason=Pulled count=1 msg=Container image ""busybox:musl"" already present on machine"
0.4099,Event,ADDED,eval-conflicts-rho020-r1-033-cszxq.18d53f0ec5e04002,reason=Created count=1 msg=Created container: task
0.4102,Event,ADDED,eval-conflicts-rho020-r1-033-cszxq.18d53f0ecaa02955,reason=Started count=1 msg=Started container task
0.4105,Event,ADDED,eval-conflicts-rho020-r1-033.18d53f088aed595b,reason=SuccessfulCreate count=1 msg=Created pod: eval-conflicts-rho020-r1-033-cszxq
0.4108,Event,ADDED,eval-conflicts-rho020-r1-033.18d53f1428191c33,reason=Completed count=1 msg=Job completed
0.4109,Event,ADDED,eval-conflicts-rho020-r1-034-826ff.18d53f08c61fc60a,"reason=FailedScheduling count=None msg=0/6 nodes are available: 1 c_wall violated: 1 conflicting context pair(s) with node memory, 5 node(s) had untolerated taint(s). no new claims to deallocate, preemption: 0/6 nodes are available: 1 No preemption victims found for incoming pod, 5 Preemption is not helpful for scheduling."
0.4112,Event,ADDED,eval-conflicts-rho020-r1-034-826ff.18d53f08c6bc0d5f,"reason=FailedScheduling count=None msg=0/6 nodes are available: 1 c_wall violated: 1 conflicting context pair(s) with node memory, 5 node(s) had untolerated taint(s). no new claims to deallocate, preemption: 0/6 nodes are available: 1 No preemption victims found for incoming pod, 5 Preemption is not helpful for scheduling."
0.4114,Event,ADDED,eval-conflicts-rho020-r1-034-826ff.18d53f0c5a34f4ee,reason=Scheduled count=None msg=Successfully assigned compute/eval-conflicts-rho020-r1-034-826ff to kind-worker3
0.4115,Event,ADDED,eval-conflicts-rho020-r1-034-826ff.18d53f0c7a1f45bd,"reason=Pulled count=1 msg=Container image ""busybox:musl"" already present on machine"
0.4117,Event,ADDED,eval-conflicts-rho020-r1-034-826ff.18d53f0c7c87308d,reason=Created count=1 msg=Created container: task
0.4119,Event,ADDED,eval-conflicts-rho020-r1-034-826ff.18d53f0c803ca24c,reason=Started count=1 msg=Started container task
0.4121,Event,ADDED,eval-conflicts-rho020-r1-034.18d53f08c5cee40c,reason=SuccessfulCreate count=1 msg=Created pod: eval-conflicts-rho020-r1-034-826ff
0.4122,Event,ADDED,eval-conflicts-rho020-r1-034.18d53f120cf0a79f,reason=Completed count=1 msg=Job completed
0.4124,Event,ADDED,eval-conflicts-rho020-r1-035-bn49h.18d53f09029bdce9,reason=Scheduled count=None msg=Successfully assigned compute/eval-conflicts-rho020-r1-035-bn49h to kind-worker2
0.4126,Event,ADDED,eval-conflicts-rho020-r1-035-bn49h.18d53f091d1fbe43,"reason=Pulled count=1 msg=Container image ""busybox:musl"" already present on machine"
0.4127,Event,ADDED,eval-conflicts-rho020-r1-035-bn49h.18d53f091e3a86f1,reason=Created count=1 msg=Created container: task
0.4129,Event,ADDED,eval-conflicts-rho020-r1-035-bn49h.18d53f092055fd7c,reason=Started count=1 msg=Started container task
0.4131,Event,ADDED,eval-conflicts-rho020-r1-035.18d53f0901de5684,reason=SuccessfulCreate count=1 msg=Created pod: eval-conflicts-rho020-r1-035-bn49h
0.4132,Event,ADDED,eval-conflicts-rho020-r1-035.18d53f0e9220ea2b,reason=Completed count=1 msg=Job completed
0.4134,Event,ADDED,eval-conflicts-rho020-r1-036-648gw.18d53f093da8db42,reason=Scheduled count=None msg=Successfully assigned compute/eval-conflicts-rho020-r1-036-648gw to kind-worker2
0.4136,Event,ADDED,eval-conflicts-rho020-r1-036-648gw.18d53f0957657c2e,"reason=Pulled count=1 msg=Container image ""busybox:musl"" already present on machine"
0.4137,Event,ADDED,eval-conflicts-rho020-r1-036-648gw.18d53f09588c7996,reason=Created count=1 msg=Created container: task
0.4139,Event,ADDED,eval-conflicts-rho020-r1-036-648gw.18d53f095ccdbfbd,reason=Started count=1 msg=Started container task
0.4141,Event,ADDED,eval-conflicts-rho020-r1-036.18d53f093d277fb9,reason=SuccessfulCreate count=1 msg=Created pod: eval-conflicts-rho020-r1-036-648gw
0.4142,Event,ADDED,eval-conflicts-rho020-r1-036.18d53f0ecd7d4f7b,reason=Completed count=1 msg=Job completed
0.4144,Event,ADDED,eval-conflicts-rho020-r1-037-7gph8.18d53f097c9d84e8,reason=Scheduled count=None msg=Successfully assigned compute/eval-conflicts-rho020-r1-037-7gph8 to kind-worker2
0.4145,Event,ADDED,eval-conflicts-rho020-r1-037-7gph8.18d53f09971b38b1,"reason=Pulled count=1 msg=Container image ""busybox:musl"" already present on machine"
0.4147,Event,ADDED,eval-conflicts-rho020-r1-037-7gph8.18d53f099876dce4,reason=Created count=1 msg=Created container: task
0.4149,Event,ADDED,eval-conflicts-rho020-r1-037-7gph8.18d53f099cb9c451,reason=Started count=1 msg=Started container task
0.415,Event,ADDED,eval-conflicts-rho020-r1-037.18d53f097c1118a3,reason=SuccessfulCreate count=1 msg=Created pod: eval-conflicts-rho020-r1-037-7gph8
0.4152,Event,ADDED,eval-conflicts-rho020-r1-037.18d53f0f10e4ca44,reason=Completed count=1 msg=Job completed
0.4154,Event,ADDED,eval-conflicts-rho020-r1-038-w462t.18d53f09b75c2b22,reason=Scheduled count=None msg=Successfully assigned compute/eval-conflicts-rho020-r1-038-w462t to kind-worker2
0.4155,Event,ADDED,eval-conflicts-rho020-r1-038-w462t.18d53f09d1a27575,"reason=Pulled count=1 msg=Container image ""busybox:musl"" already present on machine"
0.4157,Event,ADDED,eval-conflicts-rho020-r1-038-w462t.18d53f09d2c88442,reason=Created count=1 msg=Created container: task
0.4159,Event,ADDED,eval-conflicts-rho020-r1-038-w462t.18d53f09dafbc31d,reason=Started count=1 msg=Started container task
0.4163,Event,ADDED,eval-conflicts-rho020-r1-038.18d53f09b6d9f206,reason=SuccessfulCreate count=1 msg=Created pod: eval-conflicts-rho020-r1-038-w462t
0.4165,Event,ADDED,eval-conflicts-rho020-r1-038.18d53f0f448292c3,reason=Completed count=1 msg=Job completed
0.4167,Event,ADDED,eval-conflicts-rho020-r1-039-sm4xq.18d53f09f0292863,"reason=FailedScheduling count=None msg=0/6 nodes are available: 1 c_wall violated: 1 conflicting context pair(s) with node memory, 5 node(s) had untolerated taint(s). no new claims to deallocate, preemption: 0/6 nodes are available: 1 No preemption victims found for incoming pod, 5 Preemption is not helpful for scheduling."
0.4171,Event,ADDED,eval-conflicts-rho020-r1-039-sm4xq.18d53f09f0c0fb87,"reason=FailedScheduling count=None msg=0/6 nodes are available: 1 c_wall violated: 1 conflicting context pair(s) with node memory, 5 node(s) had untolerated taint(s). no new claims to deallocate, preemption: 0/6 nodes are available: 1 No preemption victims found for incoming pod, 5 Preemption is not helpful for scheduling."
0.4173,Event,ADDED,eval-conflicts-rho020-r1-039-sm4xq.18d53f0c592a574c,reason=Scheduled count=None msg=Successfully assigned compute/eval-conflicts-rho020-r1-039-sm4xq to kind-worker3
0.4174,Event,ADDED,eval-conflicts-rho020-r1-039-sm4xq.18d53f0c794e7c9c,"reason=Pulled count=1 msg=Container image ""busybox:musl"" already present on machine"
0.4176,Event,ADDED,eval-conflicts-rho020-r1-039-sm4xq.18d53f0c7b21d13e,reason=Created count=1 msg=Created container: task
0.4179,Event,ADDED,eval-conflicts-rho020-r1-039-sm4xq.18d53f0c7f5e7a24,reason=Started count=1 msg=Started container task
0.4181,Event,ADDED,eval-conflicts-rho020-r1-039.18d53f09efe8cd1c,reason=SuccessfulCreate count=1 msg=Created pod: eval-conflicts-rho020-r1-039-sm4xq
0.4183,Event,ADDED,eval-conflicts-rho020-r1-039.18d53f11d44631de,reason=Completed count=1 msg=Job completed
0.4188,Event,ADDED,eval-conflicts-rho020-r1-040-95jqh.18d53f0a2ef8f7ac,"reason=FailedScheduling count=None msg=0/6 nodes are available: 1 c_wall violated: 1 conflicting context pair(s) with node memory, 5 node(s) had untolerated taint(s). no new claims to deallocate, preemption: 0/6 nodes are available: 1 No preemption victims found for incoming pod, 5 Preemption is not helpful for scheduling."
0.419,Event,ADDED,eval-conflicts-rho020-r1-040-95jqh.18d53f0a2f8ad11e,"reason=FailedScheduling count=None msg=0/6 nodes are available: 1 c_wall violated: 1 conflicting context pair(s) with node memory, 5 node(s) had untolerated taint(s). no new claims to deallocate, preemption: 0/6 nodes are available: 1 No preemption victims found for incoming pod, 5 Preemption is not helpful for scheduling."
0.4192,Event,ADDED,eval-conflicts-rho020-r1-040-95jqh.18d53f0c59dc3867,reason=Scheduled count=None msg=Successfully assigned compute/eval-conflicts-rho020-r1-040-95jqh to kind-worker3
0.4195,Event,ADDED,eval-conflicts-rho020-r1-040-95jqh.18d53f0c7a5f3061,"reason=Pulled count=1 msg=Container image ""busybox:musl"" already present on machine"
0.4197,Event,ADDED,eval-conflicts-rho020-r1-040-95jqh.18d53f0c7cc61def,reason=Created count=1 msg=Created container: task
0.4199,Event,ADDED,eval-conflicts-rho020-r1-040-95jqh.18d53f0c804030df,reason=Started count=1 msg=Started container task
0.42,Event,ADDED,eval-conflicts-rho020-r1-040.18d53f0a2ebbf0b7,reason=SuccessfulCreate count=1 msg=Created pod: eval-conflicts-rho020-r1-040-95jqh
0.4209,Event,ADDED,eval-conflicts-rho020-r1-040.18d53f11d41b767f,reason=Completed count=1 msg=Job completed
0.4213,Event,ADDED,eval-conflicts-rho020-r1-041-8c5n8.18d53f0a7434da47,reason=Scheduled count=None msg=Successfully assigned compute/eval-conflicts-rho020-r1-041-8c5n8 to kind-worker2
0.4215,Event,ADDED,eval-conflicts-rho020-r1-041-8c5n8.18d53f0a962040e5,"reason=Pulled count=1 msg=Container image ""busybox:musl"" already present on machine"
0.4217,Event,ADDED,eval-conflicts-rho020-r1-041-8c5n8.18d53f0a97703a20,reason=Created count=1 msg=Created container: task
0.422,Event,ADDED,eval-conflicts-rho020-r1-041-8c5n8.18d53f0a9d031b71,reason=Started count=1 msg=Started container task
0.4222,Event,ADDED,eval-conflicts-rho020-r1-041.18d53f0a73b02296,reason=SuccessfulCreate count=1 msg=Created pod: eval-conflicts-rho020-r1-041-8c5n8
0.4224,Event,ADDED,eval-conflicts-rho020-r1-041.18d53f10331c7cf5,reason=Completed count=1 msg=Job completed
0.4227,Event,ADDED,eval-conflicts-rho020-r1-042-lmc4f.18d53f0aa7265c2f,"reason=FailedScheduling count=None msg=0/6 nodes are available: 1 c_wall violated: 1 conflicting context pair(s) with node memory, 5 node(s) had untolerated taint(s). no new claims to deallocate, preemption: 0/6 nodes are available: 1 No preemption victims found for incoming pod, 5 Preemption is not helpful for scheduling."
0.4228,Event,ADDED,eval-conflicts-rho020-r1-042-lmc4f.18d53f0aa7a8cb4b,"reason=FailedScheduling count=None msg=0/6 nodes are available: 1 c_wall violated: 1 conflicting context pair(s) with node memory, 5 node(s) had untolerated taint(s). no new claims to deallocate, preemption: 0/6 nodes are available: 1 No preemption victims found for incoming pod, 5 Preemption is not helpful for scheduling."
0.423,Event,ADDED,eval-conflicts-rho020-r1-042-lmc4f.18d53f0c50e606ef,reason=Scheduled count=None msg=Successfully assigned compute/eval-conflicts-rho020-r1-042-lmc4f to kind-worker3
0.4234,Event,ADDED,eval-conflicts-rho020-r1-042-lmc4f.18d53f0c6bdc68e2,"reason=Pulled count=1 msg=Container image ""busybox:musl"" already present on machine"
0.4236,Event,ADDED,eval-conflicts-rho020-r1-042-lmc4f.18d53f0c706120ff,reason=Created count=1 msg=Created container: task
0.4237,Event,ADDED,eval-conflicts-rho020-r1-042-lmc4f.18d53f0c72b20f1b,reason=Started count=1 msg=Started container task
0.4239,Event,ADDED,eval-conflicts-rho020-r1-042.18d53f0aa6e8f7a6,reason=SuccessfulCreate count=1 msg=Created pod: eval-conflicts-rho020-r1-042-lmc4f
0.4242,Event,ADDED,eval-conflicts-rho020-r1-042.18d53f11d47df488,reason=Completed count=1 msg=Job completed
0.4244,Event,ADDED,eval-conflicts-rho020-r1-043-2mg2p.18d53f0ae16d8378,"reason=FailedScheduling count=None msg=0/6 nodes are available: 1 c_wall violated: 1 conflicting context pair(s) with node memory, 5 node(s) had untolerated taint(s). no new claims to deallocate, preemption: 0/6 nodes are available: 1 No preemption victims found for incoming pod, 5 Preemption is not helpful for scheduling."
0.4247,Event,ADDED,eval-conflicts-rho020-r1-043-2mg2p.18d53f0ae1f89f26,"reason=FailedScheduling count=None msg=0/6 nodes are available: 1 c_wall violated: 1 conflicting context pair(s) with node memory, 5 node(s) had untolerated taint(s). no new claims to deallocate, preemption: 0/6 nodes are available: 1 No preemption victims found for incoming pod, 5 Preemption is not helpful for scheduling."
0.4251,Event,ADDED,eval-conflicts-rho020-r1-043-2mg2p.18d53f0c53413df1,reason=Scheduled count=None msg=Successfully assigned compute/eval-conflicts-rho020-r1-043-2mg2p to kind-worker3
0.4252,Event,ADDED,eval-conflicts-rho020-r1-043-2mg2p.18d53f0c6efe6dd3,"reason=Pulled count=1 msg=Container image ""busybox:musl"" already present on machine"
0.4254,Event,ADDED,eval-conflicts-rho020-r1-043-2mg2p.18d53f0c73651b7a,reason=Created count=1 msg=Created container: task
0.4256,Event,ADDED,eval-conflicts-rho020-r1-043-2mg2p.18d53f0c79e81dd5,reason=Started count=1 msg=Started container task
0.4259,Event,ADDED,eval-conflicts-rho020-r1-043.18d53f0ae127f9c8,reason=SuccessfulCreate count=1 msg=Created pod: eval-conflicts-rho020-r1-043-2mg2p
0.4261,Event,ADDED,eval-conflicts-rho020-r1-043.18d53f11d443af70,reason=Completed count=1 msg=Job completed
0.4263,Event,ADDED,eval-conflicts-rho020-r1-044-frf82.18d53f0b1c3f1519,reason=Scheduled count=None msg=Successfully assigned compute/eval-conflicts-rho020-r1-044-frf82 to kind-worker2
0.4268,Event,ADDED,eval-conflicts-rho020-r1-044-frf82.18d53f0b3badd887,"reason=Pulled count=1 msg=Container image ""busybox:musl"" already present on machine"
0.427,Event,ADDED,eval-conflicts-rho020-r1-044-frf82.18d53f0b3cf58b29,reason=Created count=1 msg=Created container: task
0.4272,Event,ADDED,eval-conflicts-rho020-r1-044-frf82.18d53f0b4700f96b,reason=Started count=1 msg=Started container task
0.4274,Event,ADDED,eval-conflicts-rho020-r1-044.18d53f0b1bc216dd,reason=SuccessfulCreate count=1 msg=Created pod: eval-conflicts-rho020-r1-044-frf82
0.4277,Event,ADDED,eval-conflicts-rho020-r1-044.18d53f10af438fd3,reason=Completed count=1 msg=Job completed
0.4279,Event,ADDED,eval-conflicts-rho020-r1-045-4hx5b.18d53f0b5c3bd8bd,reason=Scheduled count=None msg=Successfully assigned compute/eval-conflicts-rho020-r1-045-4hx5b to kind-worker2
0.4281,Event,ADDED,eval-conflicts-rho020-r1-045-4hx5b.18d53f0b7c243852,"reason=Pulled count=1 msg=Container image ""busybox:musl"" already present on machine"
0.4283,Event,ADDED,eval-conflicts-rho020-r1-045-4hx5b.18d53f0b7d3ea508,reason=Created count=1 msg=Created container: task
0.4286,Event,ADDED,eval-conflicts-rho020-r1-045-4hx5b.18d53f0b8343470a,reason=Started count=1 msg=Started container task
0.4288,Event,ADDED,eval-conflicts-rho020-r1-045.18d53f0b5bb9245d,reason=SuccessfulCreate count=1 msg=Created pod: eval-conflicts-rho020-r1-045-4hx5b
0.429,Event,ADDED,eval-conflicts-rho020-r1-045.18d53f10eb1fb34c,reason=Completed count=1 msg=Job completed
0.4293,Event,ADDED,eval-conflicts-rho020-r1-046-qrk76.18d53f0b94be862f,reason=Scheduled count=None msg=Successfully assigned compute/eval-conflicts-rho020-r1-046-qrk76 to kind-worker2
0.4295,Event,ADDED,eval-conflicts-rho020-r1-046-qrk76.18d53f0bc08c06b1,"reason=Pulled count=1 msg=Container image ""busybox:musl"" already present on machine"
0.4297,Event,ADDED,eval-conflicts-rho020-r1-046-qrk76.18d53f0bc1b03509,reason=Created count=1 msg=Created container: task
0.4299,Event,ADDED,eval-conflicts-rho020-r1-046-qrk76.18d53f0bc3b6d1cb,reason=Started count=1 msg=Started container task
0.4302,Event,ADDED,eval-conflicts-rho020-r1-046.18d53f0b944ccabd,reason=SuccessfulCreate count=1 msg=Created pod: eval-conflicts-rho020-r1-046-qrk76
0.4304,Event,ADDED,eval-conflicts-rho020-r1-046.18d53f1161404e7a,reason=Completed count=1 msg=Job completed
0.4307,Event,ADDED,eval-conflicts-rho020-r1-047-8rgqp.18d53f0bcdca544f,"reason=FailedScheduling count=None msg=0/6 nodes are available: 1 c_wall violated: 1 conflicting context pair(s) with node memory, 5 node(s) had untolerated taint(s). no new claims to deallocate, preemption: 0/6 nodes are available: 1 No preemption victims found for incoming pod, 5 Preemption is not helpful for scheduling."
0.4311,Event,ADDED,eval-conflicts-rho020-r1-047-8rgqp.18d53f0bce429f94,"reason=FailedScheduling count=None msg=0/6 nodes are available: 1 c_wall violated: 1 conflicting context pair(s) with node memory, 5 node(s) had untolerated taint(s). no new claims to deallocate, preemption: 0/6 nodes are available: 1 No preemption victims found for incoming pod, 5 Preemption is not helpful for scheduling."
0.4313,Event,ADDED,eval-conflicts-rho020-r1-047-8rgqp.18d53f0c597fb3bc,reason=Scheduled count=None msg=Successfully assigned compute/eval-conflicts-rho020-r1-047-8rgqp to kind-worker3
0.4315,Event,ADDED,eval-conflicts-rho020-r1-047-8rgqp.18d53f0c79539945,"reason=Pulled count=1 msg=Container image ""busybox:musl"" already present on machine"
0.4316,Event,ADDED,eval-conflicts-rho020-r1-047-8rgqp.18d53f0c7be84e91,reason=Created count=1 msg=Created container: task
0.432,Event,ADDED,eval-conflicts-rho020-r1-047-8rgqp.18d53f0c803b1a1f,reason=Started count=1 msg=Started container task
0.4322,Event,ADDED,eval-conflicts-rho020-r1-047.18d53f0bcd8e9c66,reason=SuccessfulCreate count=1 msg=Created pod: eval-conflicts-rho020-r1-047-8rgqp
0.4324,Event,ADDED,eval-conflicts-rho020-r1-047.18d53f11d3dc0e82,reason=Completed count=1 msg=Job completed
0.4327,Event,ADDED,eval-conflicts-rho020-r1-048-htjh2.18d53f0c093bf6ed,reason=Scheduled count=None msg=Successfully assigned compute/eval-conflicts-rho020-r1-048-htjh2 to kind-worker2
0.4329,Event,ADDED,eval-conflicts-rho020-r1-048-htjh2.18d53f0c2275b82f,"reason=Pulled count=1 msg=Container image ""busybox:musl"" already present on machine"
0.433,Event,ADDED,eval-conflicts-rho020-r1-048-htjh2.18d53f0c23939cdf,reason=Created count=1 msg=Created container: task
0.4332,Event,ADDED,eval-conflicts-rho020-r1-048-htjh2.18d53f0c287f9e5c,reason=Started count=1 msg=Started container task
0.4335,Event,ADDED,eval-conflicts-rho020-r1-048.18d53f0c08b585b2,reason=SuccessfulCreate count=1 msg=Created pod: eval-conflicts-rho020-r1-048-htjh2
0.4336,Event,ADDED,eval-conflicts-rho020-r1-048.18d53f11a0315844,reason=Completed count=1 msg=Job completed
0.4338,Event,ADDED,eval-conflicts-rho020-r1-049-mdgf6.18d53f0c47869d05,"reason=FailedScheduling count=None msg=0/6 nodes are available: 1 c_wall violated: 1 conflicting context pair(s) with node memory, 5 node(s) had untolerated taint(s). no new claims to deallocate, preemption: 0/6 nodes are available: 1 No preemption victims found for incoming pod, 5 Preemption is not helpful for scheduling."
0.4339,Event,ADDED,eval-conflicts-rho020-r1-049-mdgf6.18d53f0c50ea75cf,reason=Scheduled count=None msg=Successfully assigned compute/eval-conflicts-rho020-r1-049-mdgf6 to kind-worker3
0.4341,Event,ADDED,eval-conflicts-rho020-r1-049-mdgf6.18d53f0c6ba84116,"reason=Pulled count=1 msg=Container image ""busybox:musl"" already present on machine"
0.4343,Event,ADDED,eval-conflicts-rho020-r1-049-mdgf6.18d53f0c6fbb6c3a,reason=Created count=1 msg=Created container: task
0.4345,Event,ADDED,eval-conflicts-rho020-r1-049-mdgf6.18d53f0c726007a3,reason=Started count=1 msg=Started container task
0.4346,Event,ADDED,eval-conflicts-rho020-r1-049.18d53f0c473e3218,reason=SuccessfulCreate count=1 msg=Created pod: eval-conflicts-rho020-r1-049-mdgf6
0.4348,Event,ADDED,eval-conflicts-rho020-r1-049.18d53f120d476c13,reason=Completed count=1 msg=Job completed
0.435,Event,ADDED,eval-conflicts-rho020-r1-050-cnqwp.18d53f0c81219611,reason=Scheduled count=None msg=Successfully assigned compute/eval-conflicts-rho020-r1-050-cnqwp to kind-worker3
0.4351,Event,ADDED,eval-conflicts-rho020-r1-050-cnqwp.18d53f0c9b4bc5dd,"reason=Pulled count=1 msg=Container image ""busybox:musl"" already present on machine"
0.4354,Event,ADDED,eval-conflicts-rho020-r1-050-cnqwp.18d53f0c9c60416a,reason=Created count=1 msg=Created container: task
0.4356,Event,ADDED,eval-conflicts-rho020-r1-050-cnqwp.18d53f0ca216a572,reason=Started count=1 msg=Started container task
0.4357,Event,ADDED,eval-conflicts-rho020-r1-050.18d53f0c7ffd71f6,reason=SuccessfulCreate count=1 msg=Created pod: eval-conflicts-rho020-r1-050-cnqwp
0.4359,Event,ADDED,eval-conflicts-rho020-r1-050.18d53f120d479843,reason=Completed count=1 msg=Job completed
0.4361,Event,ADDED,eval-conflicts-rho020-r1-051-tpbb2.18d53f0cc21f48ab,reason=Scheduled count=None msg=Successfully assigned compute/eval-conflicts-rho020-r1-051-tpbb2 to kind-worker3
0.4363,Event,ADDED,eval-conflicts-rho020-r1-051-tpbb2.18d53f0cdbb23868,"reason=Pulled count=1 msg=Container image ""busybox:musl"" already present on machine"
0.4364,Event,ADDED,eval-conflicts-rho020-r1-051-tpbb2.18d53f0cdcbddb2e,reason=Created count=1 msg=Created container: task
0.4367,Event,ADDED,eval-conflicts-rho020-r1-051-tpbb2.18d53f0ce2f485be,reason=Started count=1 msg=Started container task
0.4369,Event,ADDED,eval-conflicts-rho020-r1-051.18d53f0cbafb2844,reason=SuccessfulCreate count=1 msg=Created pod: eval-conflicts-rho020-r1-051-tpbb2
0.4371,Event,ADDED,eval-conflicts-rho020-r1-051.18d53f124b924274,reason=Completed count=1 msg=Job completed
0.4374,Event,ADDED,eval-conflicts-rho020-r1-052-jcblr.18d53f0cf8374cf0,reason=Scheduled count=None msg=Successfully assigned compute/eval-conflicts-rho020-r1-052-jcblr to kind-worker2
0.4376,Event,ADDED,eval-conflicts-rho020-r1-052-jcblr.18d53f0d1691f676,"reason=Pulled count=1 msg=Container image ""busybox:musl"" already present on machine"
0.4378,Event,ADDED,eval-conflicts-rho020-r1-052-jcblr.18d53f0d17b276ad,reason=Created count=1 msg=Created container: task
0.4379,Event,ADDED,eval-conflicts-rho020-r1-052-jcblr.18d53f0d1b7323f4,reason=Started count=1 msg=Started container task
0.4382,Event,ADDED,eval-conflicts-rho020-r1-052.18d53f0cf77fab9a,reason=SuccessfulCreate count=1 msg=Created pod: eval-conflicts-rho020-r1-052-jcblr
0.4385,Event,ADDED,eval-conflicts-rho020-r1-052.18d53f1256be043f,reason=Completed count=1 msg=Job completed
0.4387,Event,ADDED,eval-conflicts-rho020-r1-053-49qz2.18d53f0d3351ee0f,reason=Scheduled count=None msg=Successfully assigned compute/eval-conflicts-rho020-r1-053-49qz2 to kind-worker2
0.4388,Event,ADDED,eval-conflicts-rho020-r1-053-49qz2.18d53f0d4d555df0,"reason=Pulled count=1 msg=Container image ""busybox:musl"" already present on machine"
0.4392,Event,ADDED,eval-conflicts-rho020-r1-053-49qz2.18d53f0d4e826a37,reason=Created count=1 msg=Created container: task
0.4394,Event,ADDED,eval-conflicts-rho020-r1-053-49qz2.18d53f0d508437a5,reason=Started count=1 msg=Started container task
0.4396,Event,ADDED,eval-conflicts-rho020-r1-053.18d53f0d329f47cd,reason=SuccessfulCreate count=1 msg=Created pod: eval-conflicts-rho020-r1-053-49qz2
0.4399,Event,ADDED,eval-conflicts-rho020-r1-053.18d53f12ceffe336,reason=Completed count=1 msg=Job completed
0.4401,Event,ADDED,eval-conflicts-rho020-r1-054-mmm96.18d53f0d6e13c311,"reason=FailedScheduling count=None msg=0/6 nodes are available: 1 c_wall violated: 1 conflicting context pair(s) with node memory, 5 node(s) had untolerated taint(s). no new claims to deallocate, preemption: 0/6 nodes are available: 1 No preemption victims found for incoming pod, 5 Preemption is not helpful for scheduling."
0.4403,Event,ADDED,eval-conflicts-rho020-r1-054-mmm96.18d53f0d6eba0d35,"reason=FailedScheduling count=None msg=0/6 nodes are available: 1 c_wall violated: 1 conflicting context pair(s) with node memory, 5 node(s) had untolerated taint(s). no new claims to deallocate, preemption: 0/6 nodes are available: 1 No preemption victims found for incoming pod, 5 Preemption is not helpful for scheduling."
0.4404,Event,ADDED,eval-conflicts-rho020-r1-054-mmm96.18d53f0ea1159480,reason=Scheduled count=None msg=Successfully assigned compute/eval-conflicts-rho020-r1-054-mmm96 to kind-worker4
0.4408,Event,ADDED,eval-conflicts-rho020-r1-054-mmm96.18d53f0ec2ad5e5a,"reason=Pulled count=1 msg=Container image ""busybox:musl"" already present on machine"
0.441,Event,ADDED,eval-conflicts-rho020-r1-054-mmm96.18d53f0ec56c236b,reason=Created count=1 msg=Created container: task
0.4412,Event,ADDED,eval-conflicts-rho020-r1-054-mmm96.18d53f0ec9758ddb,reason=Started count=1 msg=Started container task
0.4415,Event,ADDED,eval-conflicts-rho020-r1-054.18d53f0d6dd244e6,reason=SuccessfulCreate count=1 msg=Created pod: eval-conflicts-rho020-r1-054-mmm96
0.4417,Event,ADDED,eval-conflicts-rho020-r1-054.18d53f14283b99b3,reason=Completed count=1 msg=Job completed
0.4419,Event,ADDED,eval-conflicts-rho020-r1-055-vshzj.18d53f0daad94729,"reason=FailedScheduling count=None msg=0/6 nodes are available: 1 c_wall violated: 1 conflicting context pair(s) with node memory, 5 node(s) had untolerated taint(s). no new claims to deallocate, preemption: 0/6 nodes are available: 1 No preemption victims found for incoming pod, 5 Preemption is not helpful for scheduling."
0.4422,Event,ADDED,eval-conflicts-rho020-r1-055-vshzj.18d53f0dab5eaeea,"reason=FailedScheduling count=None msg=0/6 nodes are available: 1 c_wall violated: 1 conflicting context pair(s) with node memory, 5 node(s) had untolerated taint(s). no new claims to deallocate, preemption: 0/6 nodes are available: 1 No preemption victims found for incoming pod, 5 Preemption is not helpful for scheduling."
0.4424,Event,ADDED,eval-conflicts-rho020-r1-055-vshzj.18d53f0ea1a47227,reason=Scheduled count=None msg=Successfully assigned compute/eval-conflicts-rho020-r1-055-vshzj to kind-worker4
0.4426,Event,ADDED,eval-conflicts-rho020-r1-055-vshzj.18d53f0ec31bb316,"reason=Pulled count=1 msg=Container image ""busybox:musl"" already present on machine"
0.4427,Event,ADDED,eval-conflicts-rho020-r1-055-vshzj.18d53f0ec676baff,reason=Created count=1 msg=Created container: task
0.4429,Event,ADDED,eval-conflicts-rho020-r1-055-vshzj.18d53f0ecaa153cb,reason=Started count=1 msg=Started container task
0.4431,Event,ADDED,eval-conflicts-rho020-r1-055.18d53f0daa9b4588,reason=SuccessfulCreate count=1 msg=Created pod: eval-conflicts-rho020-r1-055-vshzj
0.4433,Event,ADDED,eval-conflicts-rho020-r1-055.18d53f1462a21113,reason=Completed count=1 msg=Job completed
0.4434,Event,ADDED,eval-conflicts-rho020-r1-056-rqswk.18d53f0de6ed8962,reason=Scheduled count=None msg=Successfully assigned compute/eval-conflicts-rho020-r1-056-rqswk to kind-worker3
0.4436,Event,ADDED,eval-conflicts-rho020-r1-056-rqswk.18d53f0e01d0641c,"reason=Pulled count=1 msg=Container image ""busybox:musl"" already present on machine"
0.4438,Event,ADDED,eval-conflicts-rho020-r1-056-rqswk.18d53f0e02ddece3,reason=Created count=1 msg=Created container: task
0.4439,Event,ADDED,eval-conflicts-rho020-r1-056-rqswk.18d53f0e07457727,reason=Started count=1 msg=Started container task
0.4441,Event,ADDED,eval-conflicts-rho020-r1-056.18d53f0de64bd3a2,reason=SuccessfulCreate count=1 msg=Created pod: eval-conflicts-rho020-r1-056-rqswk
0.4443,Event,ADDED,eval-conflicts-rho020-r1-056.18d53f13ac8af077,reason=Completed count=1 msg=Job completed
0.4444,Event,ADDED,eval-conflicts-rho020-r1-057-ff8rh.18d53f0e25a94b3b,"reason=FailedScheduling count=None msg=0/6 nodes are available: 1 c_wall violated: 2 conflicting context pair(s) with node memory, 5 node(s) had untolerated taint(s). no new claims to deallocate, preemption: 0/6 nodes are available: 1 No preemption victims found for incoming pod, 5 Preemption is not helpful for scheduling."
0.4447,Event,ADDED,eval-conflicts-rho020-r1-057-ff8rh.18d53f0e2691773e,"reason=FailedScheduling count=None msg=0/6 nodes are available: 1 c_wall violated: 2 conflicting context pair(s) with node memory, 5 node(s) had untolerated taint(s). no new claims to deallocate, preemption: 0/6 nodes are available: 1 No preemption victims found for incoming pod, 5 Preemption is not helpful for scheduling."
0.4448,Event,ADDED,eval-conflicts-rho020-r1-057-ff8rh.18d53f0ea7e772da,reason=Scheduled count=None msg=Successfully assigned compute/eval-conflicts-rho020-r1-057-ff8rh to kind-worker4
0.445,Event,ADDED,eval-conflicts-rho020-r1-057-ff8rh.18d53f0ec2cba84e,"reason=Pulled count=1 msg=Container image ""busybox:musl"" already present on machine"
0.4452,Event,ADDED,eval-conflicts-rho020-r1-057-ff8rh.18d53f0ec676bb13,reason=Created count=1 msg=Created container: task
0.4455,Event,ADDED,eval-conflicts-rho020-r1-057-ff8rh.18d53f0ecaa06971,reason=Started count=1 msg=Started container task
0.4457,Event,ADDED,eval-conflicts-rho020-r1-057.18d53f0e2565111e,reason=SuccessfulCreate count=1 msg=Created pod: eval-conflicts-rho020-r1-057-ff8rh
0.446,Event,ADDED,eval-conflicts-rho020-r1-057.18d53f146262030c,reason=Completed count=1 msg=Job completed
0.4463,Event,ADDED,eval-conflicts-rho020-r1-058-7r24k.18d53f0e6066b175,"reason=FailedScheduling count=None msg=0/6 nodes are available: 1 c_wall violated: 1 conflicting context pair(s) with node memory, 5 node(s) had untolerated taint(s). no new claims to deallocate, preemption: 0/6 nodes are available: 1 No preemption victims found for incoming pod, 5 Preemption is not helpful for scheduling."
0.4465,Event,ADDED,eval-conflicts-rho020-r1-058-7r24k.18d53f0e60df7405,"reason=FailedScheduling count=None msg=0/6 nodes are available: 1 c_wall violated: 1 conflicting context pair(s) with node memory, 5 node(s) had untolerated taint(s). no new claims to deallocate, preemption: 0/6 nodes are available: 1 No preemption victims found for incoming pod, 5 Preemption is not helpful for scheduling."
0.4468,Event,ADDED,eval-conflicts-rho020-r1-058-7r24k.18d53f0e9bf1bd48,reason=Scheduled count=None msg=Successfully assigned compute/eval-conflicts-rho020-r1-058-7r24k to kind-worker4
0.447,Event,ADDED,eval-conflicts-rho020-r1-058-7r24k.18d53f0eb5fb5dea,"reason=Pulled count=1 msg=Container image ""busybox:musl"" already present on machine"
0.4474,Event,ADDED,eval-conflicts-rho020-r1-058-7r24k.18d53f0eb8af6d08,reason=Created count=1 msg=Created container: task
0.4476,Event,ADDED,eval-conflicts-rho020-r1-058-7r24k.18d53f0ebcbd477e,reason=Started count=1 msg=Started container task
0.4479,Event,ADDED,eval-conflicts-rho020-r1-058.18d53f0e6027cae5,reason=SuccessfulCreate count=1 msg=Created pod: eval-conflicts-rho020-r1-058-7r24k
0.4484,Event,ADDED,eval-conflicts-rho020-r1-058.18d53f1462a0428b,reason=Completed count=1 msg=Job completed
0.4486,Event,ADDED,eval-conflicts-rho020-r1-059-wxt9g.18d53f0e9bb8038d,reason=Scheduled count=None msg=Successfully assigned compute/eval-conflicts-rho020-r1-059-wxt9g to kind-worker3
0.4488,Event,ADDED,eval-conflicts-rho020-r1-059-wxt9g.18d53f0eb5dea63e,"reason=Pulled count=1 msg=Container image ""busybox:musl"" already present on machine"
0.449,Event,ADDED,eval-conflicts-rho020-r1-059-wxt9g.18d53f0eb76855c8,reason=Created count=1 msg=Created container: task
0.4493,Event,ADDED,eval-conflicts-rho020-r1-059-wxt9g.18d53f0ebc4a3873,reason=Started count=1 msg=Started container task
0.4495,Event,ADDED,eval-conflicts-rho020-r1-059.18d53f0e9b0e9c36,reason=SuccessfulCreate count=1 msg=Created pod: eval-conflicts-rho020-r1-059-wxt9g
0.4497,Event,ADDED,eval-conflicts-rho020-r1-059.18d53f142687f1db,reason=Completed count=1 msg=Job completed
0.4499,Event,ADDED,eval-conflicts-rho020-r1-060-v6qd8.18d53f0ed962e531,reason=Scheduled count=None msg=Successfully assigned compute/eval-conflicts-rho020-r1-060-v6qd8 to kind-worker4
0.4501,Event,ADDED,eval-conflicts-rho020-r1-060-v6qd8.18d53f0ef3b16f4f,"reason=Pulled count=1 msg=Container image ""busybox:musl"" already present on machine"
0.4503,Event,ADDED,eval-conflicts-rho020-r1-060-v6qd8.18d53f0ef4d2459d,reason=Created count=1 msg=Created container: task
0.4505,Event,ADDED,eval-conflicts-rho020-r1-060-v6qd8.18d53f0efba4f550,reason=Started count=1 msg=Started container task
0.4508,Event,ADDED,eval-conflicts-rho020-r1-060.18d53f0ed8a68a2d,reason=SuccessfulCreate count=1 msg=Created pod: eval-conflicts-rho020-r1-060-v6qd8
0.451,Event,ADDED,eval-conflicts-rho020-r1-060.18d53f1462812003,reason=Completed count=1 msg=Job completed
0.4511,Event,ADDED,eval-conflicts-rho020-r1-061-767pq.18d53f0f139745a8,reason=Scheduled count=None msg=Successfully assigned compute/eval-conflicts-rho020-r1-061-767pq to kind-worker5
0.4513,Event,ADDED,eval-conflicts-rho020-r1-061-767pq.18d53f0f2dd81c1e,"reason=Pulled count=1 msg=Container image ""busybox:musl"" already present on machine"
0.4516,Event,ADDED,eval-conflicts-rho020-r1-061-767pq.18d53f0f2eee4c9e,reason=Created count=1 msg=Created container: task
0.4517,Event,ADDED,eval-conflicts-rho020-r1-061-767pq.18d53f0f30f05a1f,reason=Started count=1 msg=Started container task
0.4519,Event,ADDED,eval-conflicts-rho020-r1-061.18d53f0f12804b36,reason=SuccessfulCreate count=1 msg=Created pod: eval-conflicts-rho020-r1-061-767pq
0.4522,Event,ADDED,eval-conflicts-rho020-r1-061.18d53f14cee04bb0,reason=Completed count=1 msg=Job completed
0.4524,Event,ADDED,eval-conflicts-rho020-r1-062-m7cd2.18d53f0f4c656144,reason=Scheduled count=None msg=Successfully assigned compute/eval-conflicts-rho020-r1-062-m7cd2 to kind-worker5
0.4527,Event,ADDED,eval-conflicts-rho020-r1-062-m7cd2.18d53f0f678fa2a8,"reason=Pulled count=1 msg=Container image ""busybox:musl"" already present on machine"
0.4529,Event,ADDED,eval-conflicts-rho020-r1-062-m7cd2.18d53f0f68a0f1db,reason=Created count=1 msg=Created container: task
0.4531,Event,ADDED,eval-conflicts-rho020-r1-062-m7cd2.18d53f0f6cc4ee83,reason=Started count=1 msg=Started container task
0.4533,Event,ADDED,eval-conflicts-rho020-r1-062.18d53f0f4b40b036,reason=SuccessfulCreate count=1 msg=Created pod: eval-conflicts-rho020-r1-062-m7cd2
0.4535,Event,ADDED,eval-conflicts-rho020-r1-062.18d53f150ad697ec,reason=Completed count=1 msg=Job completed
0.4536,Event,ADDED,eval-conflicts-rho020-r1-063-kklbp.18d53f0f88693ac4,reason=Scheduled count=None msg=Successfully assigned compute/eval-conflicts-rho020-r1-063-kklbp to kind-worker5
0.4538,Event,ADDED,eval-conflicts-rho020-r1-063-kklbp.18d53f0fa135ed77,"reason=Pulled count=1 msg=Container image ""busybox:musl"" already present on machine"
0.454,Event,ADDED,eval-conflicts-rho020-r1-063-kklbp.18d53f0fa24789ef,reason=Created count=1 msg=Created container: task
0.4541,Event,ADDED,eval-conflicts-rho020-r1-063-kklbp.18d53f0fa475c8f9,reason=Started count=1 msg=Started container task
0.4543,Event,ADDED,eval-conflicts-rho020-r1-063.18d53f0f8754ced9,reason=SuccessfulCreate count=1 msg=Created pod: eval-conflicts-rho020-r1-063-kklbp
0.4545,Event,ADDED,eval-conflicts-rho020-r1-063.18d53f150aba8021,reason=Completed count=1 msg=Job completed
0.4546,Event,ADDED,eval-conflicts-rho020-r1-064-rdlgz.18d53f0fc4eaa966,reason=Scheduled count=None msg=Successfully assigned compute/eval-conflicts-rho020-r1-064-rdlgz to kind-worker4
0.4548,Event,ADDED,eval-conflicts-rho020-r1-064-rdlgz.18d53f0fe0d62f76,"reason=Pulled count=1 msg=Container image ""busybox:musl"" already present on machine"
0.455,Event,ADDED,eval-conflicts-rho020-r1-064-rdlgz.18d53f0fe1f8d7e9,reason=Created count=1 msg=Created container: task
0.4551,Event,ADDED,eval-conflicts-rho020-r1-064-rdlgz.18d53f0fe639188a,reason=Started count=1 msg=Started container task
0.4553,Event,ADDED,eval-conflicts-rho020-r1-064.18d53f0fc3e60ac2,reason=SuccessfulCreate count=1 msg=Created pod: eval-conflicts-rho020-r1-064-rdlgz
0.4555,Event,ADDED,eval-conflicts-rho020-r1-064.18d53f1551114f2a,reason=Completed count=1 msg=Job completed
0.4556,Event,ADDED,eval-conflicts-rho020-r1-065-ccwgr.18d53f0ffee190fa,reason=Scheduled count=None msg=Successfully assigned compute/eval-conflicts-rho020-r1-065-ccwgr to kind-worker
0.4558,Event,ADDED,eval-conflicts-rho020-r1-065-ccwgr.18d53f1018ad2c3e,"reason=Pulled count=1 msg=Container image ""busybox:musl"" already present on machine"
0.456,Event,ADDED,eval-conflicts-rho020-r1-065-ccwgr.18d53f1019c8d4af,reason=Created count=1 msg=Created container: task
0.4561,Event,ADDED,eval-conflicts-rho020-r1-065-ccwgr.18d53f101bf5f8dc,reason=Started count=1 msg=Started container task
0.4563,Event,ADDED,eval-conflicts-rho020-r1-065.18d53f0ffdaea769,reason=SuccessfulCreate count=1 msg=Created pod: eval-conflicts-rho020-r1-065-ccwgr
0.4565,Event,ADDED,eval-conflicts-rho020-r1-065.18d53f15a98c621f,reason=Completed count=1 msg=Job completed
0.4567,Event,ADDED,eval-conflicts-rho020-r1-066-lf8zk.18d53f103b5ab149,reason=Scheduled count=None msg=Successfully assigned compute/eval-conflicts-rho020-r1-066-lf8zk to kind-worker
0.457,Event,ADDED,eval-conflicts-rho020-r1-066-lf8zk.18d53f1054a2d018,"reason=Pulled count=1 msg=Container image ""busybox:musl"" already present on machine"
0.4572,Event,ADDED,eval-conflicts-rho020-r1-066-lf8zk.18d53f1055b06f1e,reason=Created count=1 msg=Created container: task
0.4574,Event,ADDED,eval-conflicts-rho020-r1-066-lf8zk.18d53f105a8e5945,reason=Started count=1 msg=Started container task
0.4577,Event,ADDED,eval-conflicts-rho020-r1-066.18d53f1039f1e735,reason=SuccessfulCreate count=1 msg=Created pod: eval-conflicts-rho020-r1-066-lf8zk
0.4578,Event,ADDED,eval-conflicts-rho020-r1-066.18d53f15e57be1e4,reason=Completed count=1 msg=Job completed
0.458,Event,ADDED,eval-conflicts-rho020-r1-067-78d8k.18d53f107a54d8c4,reason=Scheduled count=None msg=Successfully assigned compute/eval-conflicts-rho020-r1-067-78d8k to kind-worker5
0.4582,Event,ADDED,eval-conflicts-rho020-r1-067-78d8k.18d53f109631dae7,"reason=Pulled count=1 msg=Container image ""busybox:musl"" already present on machine"
0.4584,Event,ADDED,eval-conflicts-rho020-r1-067-78d8k.18d53f10974af595,reason=Created count=1 msg=Created container: task
0.4586,Event,ADDED,eval-conflicts-rho020-r1-067-78d8k.18d53f109e446cf2,reason=Started count=1 msg=Started container task
0.4588,Event,ADDED,eval-conflicts-rho020-r1-067.18d53f1078e1425d,reason=SuccessfulCreate count=1 msg=Created pod: eval-conflicts-rho020-r1-067-78d8k
0.4589,Event,ADDED,eval-conflicts-rho020-r1-067.18d53f1636dfb962,reason=Completed count=1 msg=Job completed
0.4596,Event,ADDED,eval-conflicts-rho020-r1-068-56hrn.18d53f10b2448adf,reason=Scheduled count=None msg=Successfully assigned compute/eval-conflicts-rho020-r1-068-56hrn to kind-worker5
0.4598,Event,ADDED,eval-conflicts-rho020-r1-068-56hrn.18d53f10d0d6f721,"reason=Pulled count=1 msg=Container image ""busybox:musl"" already present on machine"
0.46,Event,ADDED,eval-conflicts-rho020-r1-068-56hrn.18d53f10d241205a,reason=Created count=1 msg=Created container: task
0.4604,Event,ADDED,eval-conflicts-rho020-r1-068-56hrn.18d53f10d5d8de65,reason=Started count=1 msg=Started container task
0.4605,Event,ADDED,eval-conflicts-rho020-r1-068.18d53f10b0cceae7,reason=SuccessfulCreate count=1 msg=Created pod: eval-conflicts-rho020-r1-068-56hrn
0.4607,Event,ADDED,eval-conflicts-rho020-r1-068.18d53f1672a69b9b,reason=Completed count=1 msg=Job completed
0.4609,Event,ADDED,eval-conflicts-rho020-r1-069-65bwv.18d53f10ed882918,reason=Scheduled count=None msg=Successfully assigned compute/eval-conflicts-rho020-r1-069-65bwv to kind-worker
0.4613,Event,ADDED,eval-conflicts-rho020-r1-069-65bwv.18d53f110af4cb6d,"reason=Pulled count=1 msg=Container image ""busybox:musl"" already present on machine"
0.4615,Event,ADDED,eval-conflicts-rho020-r1-069-65bwv.18d53f110c049d84,reason=Created count=1 msg=Created container: task
0.4616,Event,ADDED,eval-conflicts-rho020-r1-069-65bwv.18d53f1110b44bce,reason=Started count=1 msg=Started container task
0.4618,Event,ADDED,eval-conflicts-rho020-r1-069.18d53f10ec224ce9,reason=SuccessfulCreate count=1 msg=Created pod: eval-conflicts-rho020-r1-069-65bwv
0.4621,Event,ADDED,eval-conflicts-rho020-r1-069.18d53f169a6654a6,reason=Completed count=1 msg=Job completed
0.4625,Event,ADDED,eval-conflicts-rho020-r1-070-ggstl.18d53f1128f1ca93,reason=Scheduled count=None msg=Successfully assigned compute/eval-conflicts-rho020-r1-070-ggstl to kind-worker
0.4628,Event,ADDED,eval-conflicts-rho020-r1-070-ggstl.18d53f114a9c8362,"reason=Pulled count=1 msg=Container image ""busybox:musl"" already present on machine"
0.4631,Event,ADDED,eval-conflicts-rho020-r1-070-ggstl.18d53f114bad3840,reason=Created count=1 msg=Created container: task
0.4633,Event,ADDED,eval-conflicts-rho020-r1-070-ggstl.18d53f11571bfcca,reason=Started count=1 msg=Started container task
0.4635,Event,ADDED,eval-conflicts-rho020-r1-070.18d53f1127860ab3,reason=SuccessfulCreate count=1 msg=Created pod: eval-conflicts-rho020-r1-070-ggstl
0.4636,Event,ADDED,eval-conflicts-rho020-r1-070.18d53f16d66423f6,reason=Completed count=1 msg=Job completed
0.4639,Event,ADDED,eval-conflicts-rho020-r1-071-s8rvh.18d53f1164eb570a,reason=Scheduled count=None msg=Successfully assigned compute/eval-conflicts-rho020-r1-071-s8rvh to kind-worker4
0.464,Event,ADDED,eval-conflicts-rho020-r1-071-s8rvh.18d53f1197257d82,"reason=Pulled count=1 msg=Container image ""busybox:musl"" already present on machine"
0.4642,Event,ADDED,eval-conflicts-rho020-r1-071-s8rvh.18d53f1198810cdb,reason=Created count=1 msg=Created container: task
0.4646,Event,ADDED,eval-conflicts-rho020-r1-071-s8rvh.18d53f119ffc82bf,reason=Started count=1 msg=Started container task
0.4648,Event,ADDED,eval-conflicts-rho020-r1-071.18d53f116416481f,reason=SuccessfulCreate count=1 msg=Created pod: eval-conflicts-rho020-r1-071-s8rvh
0.465,Event,ADDED,eval-conflicts-rho020-r1-071.18d53f173058db65,reason=Completed count=1 msg=Job completed
0.4651,Event,ADDED,eval-conflicts-rho020-r1-072-b7fr9.18d53f11a9832a3b,reason=Scheduled count=None msg=Successfully assigned compute/eval-conflicts-rho020-r1-072-b7fr9 to kind-worker
0.4655,Event,ADDED,eval-conflicts-rho020-r1-072-b7fr9.18d53f11c4a313a0,"reason=Pulled count=1 msg=Container image ""busybox:musl"" already present on machine"
0.4656,Event,ADDED,eval-conflicts-rho020-r1-072-b7fr9.18d53f11c625f9f4,reason=Created count=1 msg=Created container: task
0.4658,Event,ADDED,eval-conflicts-rho020-r1-072-b7fr9.18d53f11cfd05b00,reason=Started count=1 msg=Started container task
0.466,Event,ADDED,eval-conflicts-rho020-r1-072.18d53f11a837c420,reason=SuccessfulCreate count=1 msg=Created pod: eval-conflicts-rho020-r1-072-b7fr9
0.4662,Event,ADDED,eval-conflicts-rho020-r1-072.18d53f1749c0e0fd,reason=Completed count=1 msg=Job completed
0.4663,Event,ADDED,eval-conflicts-rho020-r1-073-9tpd2.18d53f11e63ed6f0,reason=Scheduled count=None msg=Successfully assigned compute/eval-conflicts-rho020-r1-073-9tpd2 to kind-worker
0.4667,Event,ADDED,eval-conflicts-rho020-r1-073-9tpd2.18d53f12081d1269,"reason=Pulled count=1 msg=Container image ""busybox:musl"" already present on machine"
0.4669,Event,ADDED,eval-conflicts-rho020-r1-073-9tpd2.18d53f1209460085,reason=Created count=1 msg=Created container: task
0.467,Event,ADDED,eval-conflicts-rho020-r1-073-9tpd2.18d53f120d30fd79,reason=Started count=1 msg=Started container task
0.4672,Event,ADDED,eval-conflicts-rho020-r1-073.18d53f11e5109be2,reason=SuccessfulCreate count=1 msg=Created pod: eval-conflicts-rho020-r1-073-9tpd2
0.4674,Event,ADDED,eval-conflicts-rho020-r1-073.18d53f1785db261c,reason=Completed count=1 msg=Job completed
0.4675,Event,ADDED,eval-conflicts-rho020-r1-074-hp4qz.18d53f122311b98f,reason=Scheduled count=None msg=Successfully assigned compute/eval-conflicts-rho020-r1-074-hp4qz to kind-worker5
0.4677,Event,ADDED,eval-conflicts-rho020-r1-074-hp4qz.18d53f12400cf661,"reason=Pulled count=1 msg=Container image ""busybox:musl"" already present on machine"
0.4679,Event,ADDED,eval-conflicts-rho020-r1-074-hp4qz.18d53f12411147b7,reason=Created count=1 msg=Created container: task
0.468,Event,ADDED,eval-conflicts-rho020-r1-074-hp4qz.18d53f124b50e766,reason=Started count=1 msg=Started container task
0.4682,Event,ADDED,eval-conflicts-rho020-r1-074.18d53f12220e7602,reason=SuccessfulCreate count=1 msg=Created pod: eval-conflicts-rho020-r1-074-hp4qz
0.4684,Event,ADDED,eval-conflicts-rho020-r1-074.18d53f17ddf8c828,reason=Completed count=1 msg=Job completed
0.4685,Event,ADDED,eval-conflicts-rho020-r1-075-8rhrx.18d53f125877ad01,reason=Scheduled count=None msg=Successfully assigned compute/eval-conflicts-rho020-r1-075-8rhrx to kind-worker5
0.4687,Event,ADDED,eval-conflicts-rho020-r1-075-8rhrx.18d53f127f289d5e,"reason=Pulled count=1 msg=Container image ""busybox:musl"" already present on machine"
0.4689,Event,ADDED,eval-conflicts-rho020-r1-075-8rhrx.18d53f12803bb94a,reason=Created count=1 msg=Created container: task
0.4692,Event,ADDED,eval-conflicts-rho020-r1-075-8rhrx.18d53f1284a7df36,reason=Started count=1 msg=Started container task
0.4694,Event,ADDED,eval-conflicts-rho020-r1-075.18d53f12577b3b0d,reason=SuccessfulCreate count=1 msg=Created pod: eval-conflicts-rho020-r1-075-8rhrx
0.4696,Event,ADDED,eval-conflicts-rho020-r1-075.18d53f181966e8c1,reason=Completed count=1 msg=Job completed
0.4698,Event,ADDED,eval-conflicts-rho020-r1-076-4xjdt.18d53f128ff43b94,reason=Scheduled count=None msg=Successfully assigned compute/eval-conflicts-rho020-r1-076-4xjdt to kind-worker
0.47,Event,ADDED,eval-conflicts-rho020-r1-076-4xjdt.18d53f12bb40dbae,"reason=Pulled count=1 msg=Container image ""busybox:musl"" already present on machine"
0.4705,Event,ADDED,eval-conflicts-rho020-r1-076-4xjdt.18d53f12bc6f6e22,reason=Created count=1 msg=Created container: task
0.4707,Event,ADDED,eval-conflicts-rho020-r1-076-4xjdt.18d53f12c23681e7,reason=Started count=1 msg=Started container task
0.4709,Event,ADDED,eval-conflicts-rho020-r1-076.18d53f128ec0ce91,reason=SuccessfulCreate count=1 msg=Created pod: eval-conflicts-rho020-r1-076-4xjdt
0.471,Event,ADDED,eval-conflicts-rho020-r1-076.18d53f183d6dc750,reason=Completed count=1 msg=Job completed
0.4713,Event,ADDED,eval-conflicts-rho020-r1-077-2895n.18d53f12c9fa3c1f,reason=Scheduled count=None msg=Successfully assigned compute/eval-conflicts-rho020-r1-077-2895n to kind-worker5
0.4714,Event,ADDED,eval-conflicts-rho020-r1-077-2895n.18d53f12e346ff2a,"reason=Pulled count=1 msg=Container image ""busybox:musl"" already present on machine"
0.4716,Event,ADDED,eval-conflicts-rho020-r1-077-2895n.18d53f12e4537800,reason=Created count=1 msg=Created container: task
0.4718,Event,ADDED,eval-conflicts-rho020-r1-077-2895n.18d53f12ede3ae4d,reason=Started count=1 msg=Started container task
0.472,Event,ADDED,eval-conflicts-rho020-r1-077.18d53f12c9202c21,reason=SuccessfulCreate count=1 msg=Created pod: eval-conflicts-rho020-r1-077-2895n
0.4722,Event,ADDED,eval-conflicts-rho020-r1-077.18d53f1857fd903e,reason=Completed count=1 msg=Job completed
0.4723,Event,ADDED,eval-conflicts-rho020-r1-078-xcddd.18d53f13080a0add,reason=Scheduled count=None msg=Successfully assigned compute/eval-conflicts-rho020-r1-078-xcddd to kind-worker5
0.4726,Event,ADDED,eval-conflicts-rho020-r1-078-xcddd.18d53f13280fd6b8,"reason=Pulled count=1 msg=Container image ""busybox:musl"" already present on machine"
0.4728,Event,ADDED,eval-conflicts-rho020-r1-078-xcddd.18d53f1329230474,reason=Created count=1 msg=Created container: task
0.4729,Event,ADDED,eval-conflicts-rho020-r1-078-xcddd.18d53f1331585bf9,reason=Started count=1 msg=Started container task
0.4731,Event,ADDED,eval-conflicts-rho020-r1-078.18d53f130712dfa0,reason=SuccessfulCreate count=1 msg=Created pod: eval-conflicts-rho020-r1-078-xcddd
0.4734,Event,ADDED,eval-conflicts-rho020-r1-078.18d53f18c799334b,reason=Completed count=1 msg=Job completed
0.4735,Event,ADDED,eval-conflicts-rho020-r1-079-jn6wj.18d53f134736625c,reason=Scheduled count=None msg=Successfully assigned compute/eval-conflicts-rho020-r1-079-jn6wj to kind-worker5
0.4737,Event,ADDED,eval-conflicts-rho020-r1-079-jn6wj.18d53f1366d49fbf,"reason=Pulled count=1 msg=Container image ""busybox:musl"" already present on machine"
0.4738,Event,ADDED,eval-conflicts-rho020-r1-079-jn6wj.18d53f1368322523,reason=Created count=1 msg=Created container: task
0.474,Event,ADDED,eval-conflicts-rho020-r1-079-jn6wj.18d53f137061ecc3,reason=Started count=1 msg=Started container task
0.4742,Event,ADDED,eval-conflicts-rho020-r1-079.18d53f1346692c1e,reason=SuccessfulCreate count=1 msg=Created pod: eval-conflicts-rho020-r1-079-jn6wj
0.4744,Event,ADDED,eval-conflicts-rho020-r1-079.18d53f1909a668b5,reason=Completed count=1 msg=Job completed
0.4745,Event,ADDED,eval-conflicts-rho020-r1-080-67dkd.18d53f1385775fbc,reason=Scheduled count=None msg=Successfully assigned compute/eval-conflicts-rho020-r1-080-67dkd to kind-worker5
0.4747,Event,ADDED,eval-conflicts-rho020-r1-080-67dkd.18d53f13a074b16a,"reason=Pulled count=1 msg=Container image ""busybox:musl"" already present on machine"
0.4749,Event,ADDED,eval-conflicts-rho020-r1-080-67dkd.18d53f13a1923260,reason=Created count=1 msg=Created container: task
0.475,Event,ADDED,eval-conflicts-rho020-r1-080-67dkd.18d53f13a3ac7618,reason=Started count=1 msg=Started container task
0.4752,Event,ADDED,eval-conflicts-rho020-r1-080.18d53f1384bd4ebc,reason=SuccessfulCreate count=1 msg=Created pod: eval-conflicts-rho020-r1-080-67dkd
0.4754,Event,ADDED,eval-conflicts-rho020-r1-080.18d53f194dc2f8e8,reason=Completed count=1 msg=Job completed
0.4755,Event,ADDED,eval-conflicts-rho020-r1-081-wmgbk.18d53f13b9d1ecb6,"reason=FailedScheduling count=None msg=0/6 nodes are available: 1 c_wall violated: 1 conflicting context pair(s) with node memory, 5 node(s) had untolerated taint(s). no new claims to deallocate, preemption: 0/6 nodes are available: 1 No preemption victims found for incoming pod, 5 Preemption is not helpful for scheduling."
0.4758,Event,ADDED,eval-conflicts-rho020-r1-081-wmgbk.18d53f13baf6536d,"reason=FailedScheduling count=None msg=0/6 nodes are available: 1 c_wall violated: 1 conflicting context pair(s) with node memory, 5 node(s) had untolerated taint(s). no new claims to deallocate, preemption: 0/6 nodes are available: 1 No preemption victims found for incoming pod, 5 Preemption is not helpful for scheduling."
0.4759,Event,ADDED,eval-conflicts-rho020-r1-081-wmgbk.18d53f15ac13983b,reason=Scheduled count=None msg=Successfully assigned compute/eval-conflicts-rho020-r1-081-wmgbk to kind-worker3
0.4761,Event,ADDED,eval-conflicts-rho020-r1-081-wmgbk.18d53f15c8c68fcf,"reason=Pulled count=1 msg=Container image ""busybox:musl"" already present on machine"
0.4762,Event,ADDED,eval-conflicts-rho020-r1-081-wmgbk.18d53f15caf10c0a,reason=Created count=1 msg=Created container: task
0.4767,Event,ADDED,eval-conflicts-rho020-r1-081-wmgbk.18d53f15cd1e546d,reason=Started count=1 msg=Started container task
0.4769,Event,ADDED,eval-conflicts-rho020-r1-081.18d53f13b98febc3,reason=SuccessfulCreate count=1 msg=Created pod: eval-conflicts-rho020-r1-081-wmgbk
0.477,Event,ADDED,eval-conflicts-rho020-r1-081.18d53f1b2b4bdd8c,reason=Completed count=1 msg=Job completed
0.4773,Event,ADDED,eval-conflicts-rho020-r1-082-r2xjn.18d53f13fcb45dfb,"reason=FailedScheduling count=None msg=0/6 nodes are available: 1 c_wall violated: 1 conflicting context pair(s) with node memory, 5 node(s) had untolerated taint(s). no new claims to deallocate, preemption: 0/6 nodes are available: 1 No preemption victims found for incoming pod, 5 Preemption is not helpful for scheduling."
0.4774,Event,ADDED,eval-conflicts-rho020-r1-082-r2xjn.18d53f13fd635318,"reason=FailedScheduling count=None msg=0/6 nodes are available: 1 c_wall violated: 1 conflicting context pair(s) with node memory, 5 node(s) had untolerated taint(s). no new claims to deallocate, preemption: 0/6 nodes are available: 1 No preemption victims found for incoming pod, 5 Preemption is not helpful for scheduling."
0.4776,Event,ADDED,eval-conflicts-rho020-r1-082-r2xjn.18d53f15ab9ce6d4,reason=Scheduled count=None msg=Successfully assigned compute/eval-conflicts-rho020-r1-082-r2xjn to kind-worker3
0.4778,Event,ADDED,eval-conflicts-rho020-r1-082-r2xjn.18d53f15ca608097,"reason=Pulled count=1 msg=Container image ""busybox:musl"" already present on machine"
0.478,Event,ADDED,eval-conflicts-rho020-r1-082-r2xjn.18d53f15cd949719,reason=Created count=1 msg=Created container: task
0.4782,Event,ADDED,eval-conflicts-rho020-r1-082-r2xjn.18d53f15d040d2fb,reason=Started count=1 msg=Started container task
0.4784,Event,ADDED,eval-conflicts-rho020-r1-082.18d53f13fc6a8bcc,reason=SuccessfulCreate count=1 msg=Created pod: eval-conflicts-rho020-r1-082-r2xjn
0.4787,Event,ADDED,eval-conflicts-rho020-r1-082.18d53f1b2b6918af,reason=Completed count=1 msg=Job completed
0.4788,Event,ADDED,eval-conflicts-rho020-r1-083-snkdc.18d53f143468010c,"reason=FailedScheduling count=None msg=0/6 nodes are available: 1 c_wall violated: 1 conflicting context pair(s) with node memory, 5 node(s) had untolerated taint(s). no new claims to deallocate, preemption: 0/6 nodes are available: 1 No preemption victims found for incoming pod, 5 Preemption is not helpful for scheduling."
0.479,Event,ADDED,eval-conflicts-rho020-r1-083-snkdc.18d53f1434e56fe5,"reason=FailedScheduling count=None msg=0/6 nodes are available: 1 c_wall violated: 1 conflicting context pair(s) with node memory, 5 node(s) had untolerated taint(s). no new claims to deallocate, preemption: 0/6 nodes are available: 1 No preemption victims found for incoming pod, 5 Preemption is not helpful for scheduling."
0.4792,Event,ADDED,eval-conflicts-rho020-r1-083-snkdc.18d53f15aaede697,reason=Scheduled count=None msg=Successfully assigned compute/eval-conflicts-rho020-r1-083-snkdc to kind-worker3
0.4793,Event,ADDED,eval-conflicts-rho020-r1-083-snkdc.18d53f15c800ab0b,"reason=Pulled count=1 msg=Container image ""busybox:musl"" already present on machine"
0.4795,Event,ADDED,eval-conflicts-rho020-r1-083-snkdc.18d53f15c9ef455a,reason=Created count=1 msg=Created container: task
0.4797,Event,ADDED,eval-conflicts-rho020-r1-083-snkdc.18d53f15cc3b24a0,reason=Started count=1 msg=Started container task
0.4798,Event,ADDED,eval-conflicts-rho020-r1-083.18d53f1434220cbd,reason=SuccessfulCreate count=1 msg=Created pod: eval-conflicts-rho020-r1-083-snkdc
0.48,Event,ADDED,eval-conflicts-rho020-r1-083.18d53f1b2b6973b5,reason=Completed count=1 msg=Job completed
0.4801,Event,ADDED,eval-conflicts-rho020-r1-084-2gvts.18d53f146e9ea8b4,"reason=FailedScheduling count=None msg=0/6 nodes are available: 1 c_wall violated: 1 conflicting context pair(s) with node memory, 5 node(s) had untolerated taint(s). no new claims to deallocate, preemption: 0/6 nodes are available: 1 No preemption victims found for incoming pod, 5 Preemption is not helpful for scheduling."
0.4803,Event,ADDED,eval-conflicts-rho020-r1-084-2gvts.18d53f146f164ee2,"reason=FailedScheduling count=None msg=0/6 nodes are available: 1 c_wall violated: 1 conflicting context pair(s) with node memory, 5 node(s) had untolerated taint(s). no new claims to deallocate, preemption: 0/6 nodes are available: 1 No preemption victims found for incoming pod, 5 Preemption is not helpful for scheduling."
0.4805,Event,ADDED,eval-conflicts-rho020-r1-084-2gvts.18d53f15ac3599f7,reason=Scheduled count=None msg=Successfully assigned compute/eval-conflicts-rho020-r1-084-2gvts to kind-worker3
0.4808,Event,ADDED,eval-conflicts-rho020-r1-084-2gvts.18d53f15ca8775df,"reason=Pulled count=1 msg=Container image ""busybox:musl"" already present on machine"
0.481,Event,ADDED,eval-conflicts-rho020-r1-084-2gvts.18d53f15ced82efe,reason=Created count=1 msg=Created container: task
0.4812,Event,ADDED,eval-conflicts-rho020-r1-084-2gvts.18d53f15d1983acb,reason=Started count=1 msg=Started container task
0.4815,Event,ADDED,eval-conflicts-rho020-r1-084.18d53f146e63a1e9,reason=SuccessfulCreate count=1 msg=Created pod: eval-conflicts-rho020-r1-084-2gvts
0.4816,Event,ADDED,eval-conflicts-rho020-r1-084.18d53f1b2a372527,reason=Completed count=1 msg=Job completed
0.4819,Event,ADDED,eval-conflicts-rho020-r1-085-vcp64.18d53f14a6201525,"reason=FailedScheduling count=None msg=0/6 nodes are available: 6 node(s) had untolerated taint(s). no new claims to deallocate, preemption: 0/6 nodes are available: 6 Preemption is not helpful for scheduling."
0.4821,Event,ADDED,eval-conflicts-rho020-r1-085-vcp64.18d53f15ada67f59,reason=Scheduled count=None msg=Successfully assigned compute/eval-conflicts-rho020-r1-085-vcp64 to kind-worker3
0.4823,Event,ADDED,eval-conflicts-rho020-r1-085-vcp64.18d53f15c9ef066c,"reason=Pulled count=1 msg=Container image ""busybox:musl"" already present on machine"
0.4825,Event,ADDED,eval-conflicts-rho020-r1-085-vcp64.18d53f15cdb80163,reason=Created count=1 msg=Created container: task
0.4827,Event,ADDED,eval-conflicts-rho020-r1-085-vcp64.18d53f15d040d2dd,reason=Started count=1 msg=Started container task
0.4829,Event,ADDED,eval-conflicts-rho020-r1-085.18d53f14a61451d2,reason=SuccessfulCreate count=1 msg=Created pod: eval-conflicts-rho020-r1-085-vcp64
0.4831,Event,ADDED,eval-conflicts-rho020-r1-085.18d53f1b2a3abba8,reason=Completed count=1 msg=Job completed
0.4834,Event,ADDED,eval-conflicts-rho020-r1-086-ks4px.18d53f14e38942aa,"reason=FailedScheduling count=None msg=0/6 nodes are available: 6 node(s) had untolerated taint(s). no new claims to deallocate, preemption: 0/6 nodes are available: 6 Preemption is not helpful for scheduling."
0.4835,Event,ADDED,eval-conflicts-rho020-r1-086-ks4px.18d53f15ada73c95,reason=Scheduled count=None msg=Successfully assigned compute/eval-conflicts-rho020-r1-086-ks4px to kind-worker3
0.4837,Event,ADDED,eval-conflicts-rho020-r1-086-ks4px.18d53f15ca12d810,"reason=Pulled count=1 msg=Container image ""busybox:musl"" already present on machine"
0.4839,Event,ADDED,eval-conflicts-rho020-r1-086-ks4px.18d53f15cce09407,reason=Created count=1 msg=Created container: task
0.4842,Event,ADDED,eval-conflicts-rho020-r1-086-ks4px.18d53f15cf1c137d,reason=Started count=1 msg=Started container task
0.4844,Event,ADDED,eval-conflicts-rho020-r1-086.18d53f14e37dd076,reason=SuccessfulCreate count=1 msg=Created pod: eval-conflicts-rho020-r1-086-ks4px
0.4846,Event,ADDED,eval-conflicts-rho020-r1-086.18d53f1b6600f35d,reason=Completed count=1 msg=Job completed
0.4849,Event,ADDED,eval-conflicts-rho020-r1-087-bhrvf.18d53f151cf6c703,"reason=FailedScheduling count=None msg=0/6 nodes are available: 6 node(s) had untolerated taint(s). no new claims to deallocate, preemption: 0/6 nodes are available: 6 Preemption is not helpful for scheduling."
0.4851,Event,ADDED,eval-conflicts-rho020-r1-087-bhrvf.18d53f15b13f9499,reason=Scheduled count=None msg=Successfully assigned compute/eval-conflicts-rho020-r1-087-bhrvf to kind-worker3
0.4853,Event,ADDED,eval-conflicts-rho020-r1-087-bhrvf.18d53f15cc67e827,"reason=Pulled count=1 msg=Container image ""busybox:musl"" already present on machine"
0.4854,Event,ADDED,eval-conflicts-rho020-r1-087-bhrvf.18d53f15cf4d1705,reason=Created count=1 msg=Created container: task
0.4857,Event,ADDED,eval-conflicts-rho020-r1-087-bhrvf.18d53f15d23f5ca3,reason=Started count=1 msg=Started container task
0.4858,Event,ADDED,eval-conflicts-rho020-r1-087.18d53f151cecf551,reason=SuccessfulCreate count=1 msg=Created pod: eval-conflicts-rho020-r1-087-bhrvf
0.486,Event,ADDED,eval-conflicts-rho020-r1-087.18d53f1b2a372516,reason=Completed count=1 msg=Job completed
0.4862,Event,ADDED,eval-conflicts-rho020-r1-088-4ngfn.18d53f155a254599,"reason=FailedScheduling count=None msg=0/6 nodes are available: 6 node(s) had untolerated taint(s). no new claims to deallocate, preemption: 0/6 nodes are available: 6 Preemption is not helpful for scheduling."
0.4866,Event,ADDED,eval-conflicts-rho020-r1-088-4ngfn.18d53f15b1273080,"reason=FailedScheduling count=None msg=0/6 nodes are available: 1 c_wall violated: 2 conflicting context pair(s) with node memory, 5 node(s) had untolerated taint(s). no new claims to deallocate, preemption: 0/6 nodes are available: 1 No preemption victims found for incoming pod, 5 Preemption is not helpful for scheduling."
0.4868,Event,ADDED,eval-conflicts-rho020-r1-088-4ngfn.18d53f15b1d24ccc,"reason=FailedScheduling count=None msg=0/6 nodes are available: 1 c_wall violated: 2 conflicting context pair(s) with node memory, 5 node(s) had untolerated taint(s). no new claims to deallocate, preemption: 0/6 nodes are available: 1 No preemption victims found for incoming pod, 5 Preemption is not helpful for scheduling."
0.4869,Event,ADDED,eval-conflicts-rho020-r1-088-4ngfn.18d53f16b3557230,reason=Scheduled count=None msg=Successfully assigned compute/eval-conflicts-rho020-r1-088-4ngfn to kind-worker2
0.4872,Event,ADDED,eval-conflicts-rho020-r1-088-4ngfn.18d53f16cc4569e6,"reason=Pulled count=1 msg=Container image ""busybox:musl"" already present on machine"
0.4873,Event,ADDED,eval-conflicts-rho020-r1-088-4ngfn.18d53f16cd703fdf,reason=Created count=1 msg=Created container: task
0.4875,Event,ADDED,eval-conflicts-rho020-r1-088-4ngfn.18d53f16cf9caf91,reason=Started count=1 msg=Started container task
0.4877,Event,ADDED,eval-conflicts-rho020-r1-088.18d53f155a185d03,reason=SuccessfulCreate count=1 msg=Created pod: eval-conflicts-rho020-r1-088-4ngfn
0.4878,Event,ADDED,eval-conflicts-rho020-r1-088.18d53f1c658de6a5,reason=Completed count=1 msg=Job completed
0.488,Event,ADDED,eval-conflicts-rho020-r1-089-xh5k7.18d53f1595944b97,"reason=FailedScheduling count=None msg=0/6 nodes are available: 6 node(s) had untolerated taint(s). no new claims to deallocate, preemption: 0/6 nodes are available: 6 Preemption is not helpful for scheduling."
0.4881,Event,ADDED,eval-conflicts-rho020-r1-089-xh5k7.18d53f15b20a7136,reason=Scheduled count=None msg=Successfully assigned compute/eval-conflicts-rho020-r1-089-xh5k7 to kind-worker3
0.4883,Event,ADDED,eval-conflicts-rho020-r1-089-xh5k7.18d53f15cc491a28,"reason=Pulled count=1 msg=Container image ""busybox:musl"" already present on machine"
0.4885,Event,ADDED,eval-conflicts-rho020-r1-089-xh5k7.18d53f15cf821521,reason=Created count=1 msg=Created container: task
0.4887,Event,ADDED,eval-conflicts-rho020-r1-089-xh5k7.18d53f15d23b69b4,reason=Started count=1 msg=Started container task
0.489,Event,ADDED,eval-conflicts-rho020-r1-089.18d53f15958be355,reason=SuccessfulCreate count=1 msg=Created pod: eval-conflicts-rho020-r1-089-xh5k7
0.4891,Event,ADDED,eval-conflicts-rho020-r1-089.18d53f1b65ca92a2,reason=Completed count=1 msg=Job completed
0.4893,Event,ADDED,eval-conflicts-rho020-r1-090-czqmx.18d53f15d10293c0,"reason=FailedScheduling count=None msg=0/6 nodes are available: 1 c_wall violated: 1 conflicting context pair(s) with node memory, 5 node(s) had untolerated taint(s). no new claims to deallocate, preemption: 0/6 nodes are available: 1 No preemption victims found for incoming pod, 5 Preemption is not helpful for scheduling."
0.4895,Event,ADDED,eval-conflicts-rho020-r1-090-czqmx.18d53f15d19d8d82,"reason=FailedScheduling count=None msg=0/6 nodes are available: 1 c_wall violated: 1 conflicting context pair(s) with node memory, 5 node(s) had untolerated taint(s). no new claims to deallocate, preemption: 0/6 nodes are available: 1 No preemption victims found for incoming pod, 5 Preemption is not helpful for scheduling."
0.4897,Event,ADDED,eval-conflicts-rho020-r1-090-czqmx.18d53f16b558407c,reason=Scheduled count=None msg=Successfully assigned compute/eval-conflicts-rho020-r1-090-czqmx to kind-worker2
0.4898,Event,ADDED,eval-conflicts-rho020-r1-090-czqmx.18d53f16ce516137,"reason=Pulled count=1 msg=Container image ""busybox:musl"" already present on machine"
0.49,Event,ADDED,eval-conflicts-rho020-r1-090-czqmx.18d53f16cfc280ea,reason=Created count=1 msg=Created container: task
0.4902,Event,ADDED,eval-conflicts-rho020-r1-090-czqmx.18d53f16d232ff0c,reason=Started count=1 msg=Started container task
0.4903,Event,ADDED,eval-conflicts-rho020-r1-090.18d53f15d0b72a34,reason=SuccessfulCreate count=1 msg=Created pod: eval-conflicts-rho020-r1-090-czqmx
0.4905,Event,ADDED,eval-conflicts-rho020-r1-090.18d53f1c65ae90e8,reason=Completed count=1 msg=Job completed
0.4907,Event,ADDED,eval-conflicts-rho020-r1-091-xp7mz.18d53f160bc149e5,reason=Scheduled count=None msg=Successfully assigned compute/eval-conflicts-rho020-r1-091-xp7mz to kind-worker3
0.4908,Event,ADDED,eval-conflicts-rho020-r1-091-xp7mz.18d53f1627e1ff7c,"reason=Pulled count=1 msg=Container image ""busybox:musl"" already present on machine"
0.491,Event,ADDED,eval-conflicts-rho020-r1-091-xp7mz.18d53f162915a8af,reason=Created count=1 msg=Created container: task
0.4912,Event,ADDED,eval-conflicts-rho020-r1-091-xp7mz.18d53f162dda2c50,reason=Started count=1 msg=Started container task
0.4913,Event,ADDED,eval-conflicts-rho020-r1-091.18d53f160b3c4e14,reason=SuccessfulCreate count=1 msg=Created pod: eval-conflicts-rho020-r1-091-xp7mz
0.4915,Event,ADDED,eval-conflicts-rho020-r1-091.18d53f1b67801e54,reason=Completed count=1 msg=Job completed
0.4916,Event,ADDED,eval-conflicts-rho020-r1-092-r6cvr.18d53f1647812841,"reason=FailedScheduling count=None msg=0/6 nodes are available: 1 c_wall violated: 1 conflicting context pair(s) with node memory, 5 node(s) had untolerated taint(s). no new claims to deallocate, preemption: 0/6 nodes are available: 1 No preemption victims found for incoming pod, 5 Preemption is not helpful for scheduling."
0.4918,Event,ADDED,eval-conflicts-rho020-r1-092-r6cvr.18d53f16485b7140,"reason=FailedScheduling count=None msg=0/6 nodes are available: 1 c_wall violated: 1 conflicting context pair(s) with node memory, 5 node(s) had untolerated taint(s). no new claims to deallocate, preemption: 0/6 nodes are available: 1 No preemption victims found for incoming pod, 5 Preemption is not helpful for scheduling."
0.492,Event,ADDED,eval-conflicts-rho020-r1-092-r6cvr.18d53f16bb0d7be9,"reason=FailedScheduling count=None msg=0/6 nodes are available: 2 c_wall violated: 1 conflicting context pair(s) with node memory, 4 node(s) had untolerated taint(s). no new claims to deallocate, preemption: 0/6 nodes are available: 2 No preemption victims found for incoming pod, 4 Preemption is not helpful for scheduling."
0.4922,Event,ADDED,eval-conflicts-rho020-r1-092-r6cvr.18d53f18043b7b9d,reason=Scheduled count=None msg=Successfully assigned compute/eval-conflicts-rho020-r1-092-r6cvr to kind-worker4
0.4923,Event,ADDED,eval-conflicts-rho020-r1-092-r6cvr.18d53f181f06b752,"reason=Pulled count=1 msg=Container image ""busybox:musl"" already present on machine"
0.4926,Event,ADDED,eval-conflicts-rho020-r1-092-r6cvr.18d53f18202d66c1,reason=Created count=1 msg=Created container: task
0.4927,Event,ADDED,eval-conflicts-rho020-r1-092-r6cvr.18d53f18254f1a04,reason=Started count=1 msg=Started container task
0.4929,Event,ADDED,eval-conflicts-rho020-r1-092.18d53f16473fadea,reason=SuccessfulCreate count=1 msg=Created pod: eval-conflicts-rho020-r1-092-r6cvr
0.493,Event,ADDED,eval-conflicts-rho020-r1-092.18d53f1d8088def5,reason=Completed count=1 msg=Job completed
0.4936,Event,ADDED,eval-conflicts-rho020-r1-093-t9dkr.18d53f1684ae9f35,"reason=FailedScheduling count=None msg=0/6 nodes are available: 1 c_wall violated: 1 conflicting context pair(s) with node memory, 5 node(s) had untolerated taint(s). no new claims to deallocate, preemption: 0/6 nodes are available: 1 No preemption victims found for incoming pod, 5 Preemption is not helpful for scheduling."
0.4938,Event,ADDED,eval-conflicts-rho020-r1-093-t9dkr.18d53f1685437f9c,"reason=FailedScheduling count=None msg=0/6 nodes are available: 1 c_wall violated: 1 conflicting context pair(s) with node memory, 5 node(s) had untolerated taint(s). no new claims to deallocate, preemption: 0/6 nodes are available: 1 No preemption victims found for incoming pod, 5 Preemption is not helpful for scheduling."
0.4939,Event,ADDED,eval-conflicts-rho020-r1-093-t9dkr.18d53f16b7b1a58a,reason=Scheduled count=None msg=Successfully assigned compute/eval-conflicts-rho020-r1-093-t9dkr to kind-worker2
0.4941,Event,ADDED,eval-conflicts-rho020-r1-093-t9dkr.18d53f16cf2460ba,"reason=Pulled count=1 msg=Container image ""busybox:musl"" already present on machine"
0.4943,Event,ADDED,eval-conflicts-rho020-r1-093-t9dkr.18d53f16d09466e2,reason=Created count=1 msg=Created container: task
0.4945,Event,ADDED,eval-conflicts-rho020-r1-093-t9dkr.18d53f16d5c58ef5,reason=Started count=1 msg=Started container task
0.4948,Event,ADDED,eval-conflicts-rho020-r1-093.18d53f168474b693,reason=SuccessfulCreate count=1 msg=Created pod: eval-conflicts-rho020-r1-093-t9dkr
0.495,Event,ADDED,eval-conflicts-rho020-r1-093.18d53f1c278b53c5,reason=Completed count=1 msg=Job completed
0.4951,Event,ADDED,eval-conflicts-rho020-r1-094-f4tmq.18d53f16c168aa26,reason=Scheduled count=None msg=Successfully assigned compute/eval-conflicts-rho020-r1-094-f4tmq to kind-worker2
0.4953,Event,ADDED,eval-conflicts-rho020-r1-094-f4tmq.18d53f16da823cfd,"reason=Pulled count=1 msg=Container image ""busybox:musl"" already present on machine"
0.4955,Event,ADDED,eval-conflicts-rho020-r1-094-f4tmq.18d53f16db8f5404,reason=Created count=1 msg=Created container: task
0.4957,Event,ADDED,eval-conflicts-rho020-r1-094-f4tmq.18d53f16dd9d34b4,reason=Started count=1 msg=Started container task
0.4958,Event,ADDED,eval-conflicts-rho020-r1-094.18d53f16bfd982e0,reason=SuccessfulCreate count=1 msg=Created pod: eval-conflicts-rho020-r1-094-f4tmq
0.496,Event,ADDED,eval-conflicts-rho020-r1-094.18d53f1c65adaf3a,reason=Completed count=1 msg=Job completed
0.4962,Event,ADDED,eval-conflicts-rho020-r1-095-xk4df.18d53f16ff167f09,reason=Scheduled count=None msg=Successfully assigned compute/eval-conflicts-rho020-r1-095-xk4df to kind-worker3
0.4963,Event,ADDED,eval-conflicts-rho020-r1-095-xk4df.18d53f1718ecaa83,"reason=Pulled count=1 msg=Container image ""busybox:musl"" already present on machine"
0.4965,Event,ADDED,eval-conflicts-rho020-r1-095-xk4df.18d53f171a08598b,reason=Created count=1 msg=Created container: task
0.4967,Event,ADDED,eval-conflicts-rho020-r1-095-xk4df.18d53f171f18015f,reason=Started count=1 msg=Started container task
0.4968,Event,ADDED,eval-conflicts-rho020-r1-095.18d53f16f9e920f5,reason=SuccessfulCreate count=1 msg=Created pod: eval-conflicts-rho020-r1-095-xk4df
0.497,Event,ADDED,eval-conflicts-rho020-r1-095.18d53f1c8e92b50f,reason=Completed count=1 msg=Job completed
0.4972,Event,ADDED,eval-conflicts-rho020-r1-096-qng56.18d53f1735b9e69e,"reason=FailedScheduling count=None msg=0/6 nodes are available: 2 c_wall violated: 1 conflicting context pair(s) with node memory, 4 node(s) had untolerated taint(s). no new claims to deallocate, preemption: 0/6 nodes are available: 2 No preemption victims found for incoming pod, 4 Preemption is not helpful for scheduling."
0.4973,Event,ADDED,eval-conflicts-rho020-r1-096-qng56.18d53f17366ba210,"reason=FailedScheduling count=None msg=0/6 nodes are available: 2 c_wall violated: 1 conflicting context pair(s) with node memory, 4 node(s) had untolerated taint(s). no new claims to deallocate, preemption: 0/6 nodes are available: 2 No preemption victims found for incoming pod, 4 Preemption is not helpful for scheduling."
0.4975,Event,ADDED,eval-conflicts-rho020-r1-096-qng56.18d53f17fd72a051,reason=Scheduled count=None msg=Successfully assigned compute/eval-conflicts-rho020-r1-096-qng56 to kind-worker4
0.4977,Event,ADDED,eval-conflicts-rho020-r1-096-qng56.18d53f181b7f5f3d,"reason=Pulled count=1 msg=Container image ""busybox:musl"" already present on machine"
0.498,Event,ADDED,eval-conflicts-rho020-r1-096-qng56.18d53f181cab1273,reason=Created count=1 msg=Created container: task
0.4982,Event,ADDED,eval-conflicts-rho020-r1-096-qng56.18d53f181efd6943,reason=Started count=1 msg=Started container task
0.4984,Event,ADDED,eval-conflicts-rho020-r1-096.18d53f1735413d5c,reason=SuccessfulCreate count=1 msg=Created pod: eval-conflicts-rho020-r1-096-qng56
0.4986,Event,ADDED,eval-conflicts-rho020-r1-096.18d53f1d7fc276a4,reason=Completed count=1 msg=Job completed
0.4988,Event,ADDED,eval-conflicts-rho020-r1-097-pgvl9.18d53f177590c506,reason=Scheduled count=None msg=Successfully assigned compute/eval-conflicts-rho020-r1-097-pgvl9 to kind-worker2
0.499,Event,ADDED,eval-conflicts-rho020-r1-097-pgvl9.18d53f178feb8cd3,"reason=Pulled count=1 msg=Container image ""busybox:musl"" already present on machine"
0.4992,Event,ADDED,eval-conflicts-rho020-r1-097-pgvl9.18d53f17912b4b72,reason=Created count=1 msg=Created container: task
0.4995,Event,ADDED,eval-conflicts-rho020-r1-097-pgvl9.18d53f17a10057c4,reason=Started count=1 msg=Started container task
0.4997,Event,ADDED,eval-conflicts-rho020-r1-097.18d53f1774d3cc0d,reason=SuccessfulCreate count=1 msg=Created pod: eval-conflicts-rho020-r1-097-pgvl9
0.4999,Event,ADDED,eval-conflicts-rho020-r1-097.18d53f1d16708461,reason=Completed count=1 msg=Job completed
0.5,Event,ADDED,eval-conflicts-rho020-r1-098-snjb4.18d53f17b95c326a,reason=Scheduled count=None msg=Successfully assigned compute/eval-conflicts-rho020-r1-098-snjb4 to kind-worker2
0.5003,Event,ADDED,eval-conflicts-rho020-r1-098-snjb4.18d53f17dca91f02,"reason=Pulled count=1 msg=Container image ""busybox:musl"" already present on machine"
0.5005,Event,ADDED,eval-conflicts-rho020-r1-098-snjb4.18d53f17deab7167,reason=Created count=1 msg=Created container: task
0.5007,Event,ADDED,eval-conflicts-rho020-r1-098-snjb4.18d53f17e7b23760,reason=Started count=1 msg=Started container task
0.5009,Event,ADDED,eval-conflicts-rho020-r1-098.18d53f17acfbd805,reason=SuccessfulCreate count=1 msg=Created pod: eval-conflicts-rho020-r1-098-snjb4
0.5013,Event,ADDED,eval-conflicts-rho020-r1-098.18d53f1d528eee69,reason=Completed count=1 msg=Job completed
0.5015,Event,ADDED,eval-conflicts-rho020-r1-099-6w924.18d53f17f1e5d7d8,reason=Scheduled count=None msg=Successfully assigned compute/eval-conflicts-rho020-r1-099-6w924 to kind-worker2
0.5016,Event,ADDED,eval-conflicts-rho020-r1-099-6w924.18d53f180b0ca62f,"reason=Pulled count=1 msg=Container image ""busybox:musl"" already present on machine"
0.502,Event,ADDED,eval-conflicts-rho020-r1-099-6w924.18d53f180c3c1c6a,reason=Created count=1 msg=Created container: task
0.5021,Event,ADDED,eval-conflicts-rho020-r1-099-6w924.18d53f1811ec0df3,reason=Started count=1 msg=Started container task
0.5023,Event,ADDED,eval-conflicts-rho020-r1-099.18d53f17e9943c27,reason=SuccessfulCreate count=1 msg=Created pod: eval-conflicts-rho020-r1-099-6w924
0.5025,Event,ADDED,eval-conflicts-rho020-r1-099.18d53f1d509cf797,reason=Completed count=1 msg=Job completed
0.5027,Event,ADDED,eval-conflicts-rho020-r1-100-slcjn.18d53f1829563bf6,reason=Scheduled count=None msg=Successfully assigned compute/eval-conflicts-rho020-r1-100-slcjn to kind-worker3
0.5029,Event,ADDED,eval-conflicts-rho020-r1-100-slcjn.18d53f18466bd434,"reason=Pulled count=1 msg=Container image ""busybox:musl"" already present on machine"
0.5031,Event,ADDED,eval-conflicts-rho020-r1-100-slcjn.18d53f1847cb9442,reason=Created count=1 msg=Created container: task
0.5032,Event,ADDED,eval-conflicts-rho020-r1-100-slcjn.18d53f184e073f56,reason=Started count=1 msg=Started container task
0.5034,Event,ADDED,eval-conflicts-rho020-r1-100.18d53f18270b3078,reason=SuccessfulCreate count=1 msg=Created pod: eval-conflicts-rho020-r1-100-slcjn
0.5036,Event,ADDED,eval-conflicts-rho020-r1-100.18d53f1d7ec47a12,reason=Completed count=1 msg=Job completed
0.5037,Event,ADDED,eval-conflicts-rho020-r1-101-vnwzz.18d53f1860f84b49,reason=Scheduled count=None msg=Successfully assigned compute/eval-conflicts-rho020-r1-101-vnwzz to kind-worker4
0.5041,Event,ADDED,eval-conflicts-rho020-r1-101-vnwzz.18d53f187aec8728,"reason=Pulled count=1 msg=Container image ""busybox:musl"" already present on machine"
0.5044,Event,ADDED,eval-conflicts-rho020-r1-101-vnwzz.18d53f187c18586e,reason=Created count=1 msg=Created container: task
0.5048,Event,ADDED,eval-conflicts-rho020-r1-101-vnwzz.18d53f1884218acf,reason=Started count=1 msg=Started container task
0.5051,Event,ADDED,eval-conflicts-rho020-r1-101.18d53f185fbcbe6d,reason=SuccessfulCreate count=1 msg=Created pod: eval-conflicts-rho020-r1-101-vnwzz
0.5054,Event,ADDED,eval-conflicts-rho020-r1-101.18d53f1dbbfdedba,reason=Completed count=1 msg=Job completed
0.5056,Event,ADDED,eval-conflicts-rho020-r1-102-6xlt2.18d53f189c82bb54,reason=Scheduled count=None msg=Successfully assigned compute/eval-conflicts-rho020-r1-102-6xlt2 to kind-worker4
0.5057,Event,ADDED,eval-conflicts-rho020-r1-102-6xlt2.18d53f18b77ff33e,"reason=Pulled count=1 msg=Container image ""busybox:musl"" already present on machine"
0.5061,Event,ADDED,eval-conflicts-rho020-r1-102-6xlt2.18d53f18b8dd61cd,reason=Created count=1 msg=Created container: task
0.5062,Event,ADDED,eval-conflicts-rho020-r1-102-6xlt2.18d53f18bf7e516f,reason=Started count=1 msg=Started container task
0.5064,Event,ADDED,eval-conflicts-rho020-r1-102.18d53f189b4228a6,reason=SuccessfulCreate count=1 msg=Created pod: eval-conflicts-rho020-r1-102-6xlt2
0.5066,Event,ADDED,eval-conflicts-rho020-r1-102.18d53f1df893cd1c,reason=Completed count=1 msg=Job completed
0.5068,Event,ADDED,eval-conflicts-rho020-r1-103-sk6sl.18d53f18dc1a409f,reason=Scheduled count=None msg=Successfully assigned compute/eval-conflicts-rho020-r1-103-sk6sl to kind-worker4
0.507,Event,ADDED,eval-conflicts-rho020-r1-103-sk6sl.18d53f18fa0aca26,"reason=Pulled count=1 msg=Container image ""busybox:musl"" already present on machine"
0.5072,Event,ADDED,eval-conflicts-rho020-r1-103-sk6sl.18d53f18fb2ef385,reason=Created count=1 msg=Created container: task
0.5073,Event,ADDED,eval-conflicts-rho020-r1-103-sk6sl.18d53f18ffaad04e,reason=Started count=1 msg=Started container task
0.5075,Event,ADDED,eval-conflicts-rho020-r1-103.18d53f18db1c43e0,reason=SuccessfulCreate count=1 msg=Created pod: eval-conflicts-rho020-r1-103-sk6sl
0.5077,Event,ADDED,eval-conflicts-rho020-r1-103.18d53f1e70022629,reason=Completed count=1 msg=Job completed
0.5078,Event,ADDED,eval-conflicts-rho020-r1-104-cs8t2.18d53f191658ca71,reason=Scheduled count=None msg=Successfully assigned compute/eval-conflicts-rho020-r1-104-cs8t2 to kind-worker4
0.508,Event,ADDED,eval-conflicts-rho020-r1-104-cs8t2.18d53f19355c3ce8,"reason=Pulled count=1 msg=Container image ""busybox:musl"" already present on machine"
0.5082,Event,ADDED,eval-conflicts-rho020-r1-104-cs8t2.18d53f19369444ed,reason=Created count=1 msg=Created container: task
0.5083,Event,ADDED,eval-conflicts-rho020-r1-104-cs8t2.18d53f193a657f71,reason=Started count=1 msg=Started container task
0.5085,Event,ADDED,eval-conflicts-rho020-r1-104.18d53f191540bec8,reason=SuccessfulCreate count=1 msg=Created pod: eval-conflicts-rho020-r1-104-cs8t2
0.5088,Event,ADDED,eval-conflicts-rho020-r1-104.18d53f1e706937bb,reason=Completed count=1 msg=Job completed
0.509,Event,ADDED,eval-conflicts-rho020-r1-105-f5fmf.18d53f1950b04487,reason=Scheduled count=None msg=Successfully assigned compute/eval-conflicts-rho020-r1-105-f5fmf to kind-worker
0.5092,Event,ADDED,eval-conflicts-rho020-r1-105-f5fmf.18d53f1975291d2f,"reason=Pulled count=1 msg=Container image ""busybox:musl"" already present on machine"
0.5094,Event,ADDED,eval-conflicts-rho020-r1-105-f5fmf.18d53f1976540808,reason=Created count=1 msg=Created container: task
0.5096,Event,ADDED,eval-conflicts-rho020-r1-105-f5fmf.18d53f19807fd024,reason=Started count=1 msg=Started container task
0.5098,Event,ADDED,eval-conflicts-rho020-r1-105.18d53f194f9d77a7,reason=SuccessfulCreate count=1 msg=Created pod: eval-conflicts-rho020-r1-105-f5fmf
0.51,Event,ADDED,eval-conflicts-rho020-r1-105.18d53f1f04d37276,reason=Completed count=1 msg=Job completed
0.5103,Event,ADDED,eval-conflicts-rho020-r1-106-sp5fr.18d53f198acb61b7,reason=Scheduled count=None msg=Successfully assigned compute/eval-conflicts-rho020-r1-106-sp5fr to kind-worker
0.5104,Event,ADDED,eval-conflicts-rho020-r1-106-sp5fr.18d53f19a97e1017,"reason=Pulled count=1 msg=Container image ""busybox:musl"" already present on machine"
0.5106,Event,ADDED,eval-conflicts-rho020-r1-106-sp5fr.18d53f19aa90c79b,reason=Created count=1 msg=Created container: task
0.5108,Event,ADDED,eval-conflicts-rho020-r1-106-sp5fr.18d53f19ae86444b,reason=Started count=1 msg=Started container task
0.511,Event,ADDED,eval-conflicts-rho020-r1-106.18d53f19896d1120,reason=SuccessfulCreate count=1 msg=Created pod: eval-conflicts-rho020-r1-106-sp5fr
0.5112,Event,ADDED,eval-conflicts-rho020-r1-106.18d53f1f49f34a4d,reason=Completed count=1 msg=Job completed
0.5113,Event,ADDED,eval-conflicts-rho020-r1-107-ns7qs.18d53f19c6b0503f,reason=Scheduled count=None msg=Successfully assigned compute/eval-conflicts-rho020-r1-107-ns7qs to kind-worker
0.5115,Event,ADDED,eval-conflicts-rho020-r1-107-ns7qs.18d53f19e2a4dd2e,"reason=Pulled count=1 msg=Container image ""busybox:musl"" already present on machine"
0.5117,Event,ADDED,eval-conflicts-rho020-r1-107-ns7qs.18d53f19e3c24176,reason=Created count=1 msg=Created container: task
0.512,Event,ADDED,eval-conflicts-rho020-r1-107-ns7qs.18d53f19ebe04996,reason=Started count=1 msg=Started container task
0.5121,Event,ADDED,eval-conflicts-rho020-r1-107.18d53f19c549d95f,reason=SuccessfulCreate count=1 msg=Created pod: eval-conflicts-rho020-r1-107-ns7qs
0.5123,Event,ADDED,eval-conflicts-rho020-r1-107.18d53f1f8af8f950,reason=Completed count=1 msg=Job completed
0.5125,Event,ADDED,eval-conflicts-rho020-r1-108-nmj4s.18d53f1a05501d68,reason=Scheduled count=None msg=Successfully assigned compute/eval-conflicts-rho020-r1-108-nmj4s to kind-worker
0.5128,Event,ADDED,eval-conflicts-rho020-r1-108-nmj4s.18d53f1a38e94d55,"reason=Pulled count=1 msg=Container image ""busybox:musl"" already present on machine"
0.5131,Event,ADDED,eval-conflicts-rho020-r1-108-nmj4s.18d53f1a3a06bb3c,reason=Created count=1 msg=Created container: task
0.5132,Event,ADDED,eval-conflicts-rho020-r1-108-nmj4s.18d53f1a3e47a3bb,reason=Started count=1 msg=Started container task
0.5134,Event,ADDED,eval-conflicts-rho020-r1-108.18d53f1a03d6deef,reason=SuccessfulCreate count=1 msg=Created pod: eval-conflicts-rho020-r1-108-nmj4s
0.5136,Event,ADDED,eval-conflicts-rho020-r1-108.18d53f1fb186f8ad,reason=Completed count=1 msg=Job completed
0.5137,Event,ADDED,eval-conflicts-rho020-r1-109-thm2q.18d53f1a417cbd46,reason=Scheduled count=None msg=Successfully assigned compute/eval-conflicts-rho020-r1-109-thm2q to kind-worker2
0.5139,Event,ADDED,eval-conflicts-rho020-r1-109-thm2q.18d53f1a60579e5e,"reason=Pulled count=1 msg=Container image ""busybox:musl"" already present on machine"
0.5141,Event,ADDED,eval-conflicts-rho020-r1-109-thm2q.18d53f1a61737159,reason=Created count=1 msg=Created container: task
0.5142,Event,ADDED,eval-conflicts-rho020-r1-109-thm2q.18d53f1a696a4325,reason=Started count=1 msg=Started container task
0.5144,Event,ADDED,eval-conflicts-rho020-r1-109.18d53f1a3cf3f105,reason=SuccessfulCreate count=1 msg=Created pod: eval-conflicts-rho020-r1-109-thm2q
0.5146,Event,ADDED,eval-conflicts-rho020-r1-109.18d53f1fdf0a226d,reason=Completed count=1 msg=Job completed
0.5147,Event,ADDED,eval-conflicts-rho020-r1-110-w7xgl.18d53f1a7e24699e,reason=Scheduled count=None msg=Successfully assigned compute/eval-conflicts-rho020-r1-110-w7xgl to kind-worker4
0.5149,Event,ADDED,eval-conflicts-rho020-r1-110-w7xgl.18d53f1a97810fc7,"reason=Pulled count=1 msg=Container image ""busybox:musl"" already present on machine"
0.5151,Event,ADDED,eval-conflicts-rho020-r1-110-w7xgl.18d53f1a988e6142,reason=Created count=1 msg=Created container: task
0.5152,Event,ADDED,eval-conflicts-rho020-r1-110-w7xgl.18d53f1a9a7ad11c,reason=Started count=1 msg=Started container task
0.5155,Event,ADDED,eval-conflicts-rho020-r1-110.18d53f1a7cd34103,reason=SuccessfulCreate count=1 msg=Created pod: eval-conflicts-rho020-r1-110-w7xgl
0.5158,Event,ADDED,eval-conflicts-rho020-r1-110.18d53f1fd6668e9d,reason=Completed count=1 msg=Job completed
0.5159,Event,ADDED,eval-conflicts-rho020-r1-111-k9s2w.18d53f1ab448edd6,reason=Scheduled count=None msg=Successfully assigned compute/eval-conflicts-rho020-r1-111-k9s2w to kind-worker2
0.5161,Event,ADDED,eval-conflicts-rho020-r1-111-k9s2w.18d53f1ace24a52d,"reason=Pulled count=1 msg=Container image ""busybox:musl"" already present on machine"
0.5163,Event,ADDED,eval-conflicts-rho020-r1-111-k9s2w.18d53f1acf5438f9,reason=Created count=1 msg=Created container: task
0.5165,Event,ADDED,eval-conflicts-rho020-r1-111-k9s2w.18d53f1ad53bf749,reason=Started count=1 msg=Started container task
0.5169,Event,ADDED,eval-conflicts-rho020-r1-111.18d53f1ab35d6d9b,reason=SuccessfulCreate count=1 msg=Created pod: eval-conflicts-rho020-r1-111-k9s2w
0.517,Event,ADDED,eval-conflicts-rho020-r1-111.18d53f2059233146,reason=Completed count=1 msg=Job completed
0.5173,Event,ADDED,eval-conflicts-rho020-r1-112-cnrtz.18d53f1af5aa5559,reason=Scheduled count=None msg=Successfully assigned compute/eval-conflicts-rho020-r1-112-cnrtz to kind-worker2
0.5175,Event,ADDED,eval-conflicts-rho020-r1-112-cnrtz.18d53f1b16d7b347,"reason=Pulled count=1 msg=Container image ""busybox:musl"" already present on machine"
0.5178,Event,ADDED,eval-conflicts-rho020-r1-112-cnrtz.18d53f1b17edc69d,reason=Created count=1 msg=Created container: task
0.5179,Event,ADDED,eval-conflicts-rho020-r1-112-cnrtz.18d53f1b1f9fa1fe,reason=Started count=1 msg=Started container task
0.5181,Event,ADDED,eval-conflicts-rho020-r1-112.18d53f1af4aee669,reason=SuccessfulCreate count=1 msg=Created pod: eval-conflicts-rho020-r1-112-cnrtz
0.5183,Event,ADDED,eval-conflicts-rho020-r1-112.18d53f20912bc578,reason=Completed count=1 msg=Job completed
0.5184,Event,ADDED,eval-conflicts-rho020-r1-113-vv8st.18d53f1b2fe548c9,reason=Scheduled count=None msg=Successfully assigned compute/eval-conflicts-rho020-r1-113-vv8st to kind-worker2
0.5186,Event,ADDED,eval-conflicts-rho020-r1-113-vv8st.18d53f1b654aecb5,"reason=Pulled count=1 msg=Container image ""busybox:musl"" already present on machine"
0.5188,Event,ADDED,eval-conflicts-rho020-r1-113-vv8st.18d53f1b66b7a9df,reason=Created count=1 msg=Created container: task
0.519,Event,ADDED,eval-conflicts-rho020-r1-113-vv8st.18d53f1b6a6f98b2,reason=Started count=1 msg=Started container task
0.5191,Event,ADDED,eval-conflicts-rho020-r1-113.18d53f1b2f089149,reason=SuccessfulCreate count=1 msg=Created pod: eval-conflicts-rho020-r1-113-vv8st
0.5193,Event,ADDED,eval-conflicts-rho020-r1-113.18d53f20cd36b9ad,reason=Completed count=1 msg=Job completed
0.5195,Event,ADDED,eval-conflicts-rho020-r1-114-xnj2p.18d53f1b67ba3dec,"reason=FailedScheduling count=None msg=0/6 nodes are available: 1 c_wall violated: 1 conflicting context pair(s) with node memory, 1 c_wall violated: 2 conflicting context pair(s) with node memory, 4 node(s) had untolerated taint(s). no new claims to deallocate, preemption: 0/6 nodes are available: 2 No preemption victims found for incoming pod, 4 Preemption is not helpful for scheduling."
0.5197,Event,ADDED,eval-conflicts-rho020-r1-114-xnj2p.18d53f1b6888bd0d,"reason=FailedScheduling count=None msg=0/6 nodes are available: 1 c_wall violated: 1 conflicting context pair(s) with node memory, 1 c_wall violated: 2 conflicting context pair(s) with node memory, 4 node(s) had untolerated taint(s). no new claims to deallocate, preemption: 0/6 nodes are available: 2 No preemption victims found for incoming pod, 4 Preemption is not helpful for scheduling."
0.5198,Event,ADDED,eval-conflicts-rho020-r1-114-xnj2p.18d53f1caad94512,"reason=FailedScheduling count=None msg=0/6 nodes are available: 1 c_wall violated: 1 conflicting context pair(s) with node memory, 5 node(s) had untolerated taint(s). no new claims to deallocate, preemption: 0/6 nodes are available: 1 No preemption victims found for incoming pod, 5 Preemption is not helpful for scheduling."
0.52,Event,ADDED,eval-conflicts-rho020-r1-114-xnj2p.18d53f1d1e339445,"reason=FailedScheduling count=None msg=0/6 nodes are available: 2 c_wall violated: 1 conflicting context pair(s) with node memory, 4 node(s) had untolerated taint(s). no new claims to deallocate, preemption: 0/6 nodes are available: 2 No preemption victims found for incoming pod, 4 Preemption is not helpful for scheduling."
0.5202,Event,ADDED,eval-conflicts-rho020-r1-114-xnj2p.18d53f1de45b8005,"reason=FailedScheduling count=None msg=0/6 nodes are available: 1 c_wall violated: 1 conflicting context pair(s) with node memory, 5 node(s) had untolerated taint(s). no new claims to deallocate, preemption: 0/6 nodes are available: 1 No preemption victims found for incoming pod, 5 Preemption is not helpful for scheduling."
0.5204,Event,ADDED,eval-conflicts-rho020-r1-114-xnj2p.18d53f1f1de4f8ee,reason=Scheduled count=None msg=Successfully assigned compute/eval-conflicts-rho020-r1-114-xnj2p to kind-worker3
0.5207,Event,ADDED,eval-conflicts-rho020-r1-114-xnj2p.18d53f1f493caafb,"reason=Pulled count=1 msg=Container image ""busybox:musl"" already present on machine"
0.5209,Event,ADDED,eval-conflicts-rho020-r1-114-xnj2p.18d53f1f4e90e268,reason=Created count=1 msg=Created container: task
0.5211,Event,ADDED,eval-conflicts-rho020-r1-114-xnj2p.18d53f1f529fd42a,reason=Started count=1 msg=Started container task
0.5212,Event,ADDED,eval-conflicts-rho020-r1-114.18d53f1b6739516f,reason=SuccessfulCreate count=1 msg=Created pod: eval-conflicts-rho020-r1-114-xnj2p
0.5214,Event,ADDED,eval-conflicts-rho020-r1-114.18d53f24bc2d4ae1,reason=Completed count=1 msg=Job completed
0.5216,Event,ADDED,eval-conflicts-rho020-r1-115-l64sx.18d53f1ba8625010,reason=Scheduled count=None msg=Successfully assigned compute/eval-conflicts-rho020-r1-115-l64sx to kind-worker
0.5218,Event,ADDED,eval-conflicts-rho020-r1-115-l64sx.18d53f1bc6af4d93,"reason=Pulled count=1 msg=Container image ""busybox:musl"" already present on machine"
0.5219,Event,ADDED,eval-conflicts-rho020-r1-115-l64sx.18d53f1bc7dd76cd,reason=Created count=1 msg=Created container: task
0.5222,Event,ADDED,eval-conflicts-rho020-r1-115-l64sx.18d53f1bcfba02fc,reason=Started count=1 msg=Started container task
0.5224,Event,ADDED,eval-conflicts-rho020-r1-115.18d53f1ba7aafc49,reason=SuccessfulCreate count=1 msg=Created pod: eval-conflicts-rho020-r1-115-l64sx
0.5226,Event,ADDED,eval-conflicts-rho020-r1-115.18d53f215e082b44,reason=Completed count=1 msg=Job completed
0.5227,Event,ADDED,eval-conflicts-rho020-r1-116-tqxrb.18d53f1bdf0a59ae,reason=Scheduled count=None msg=Successfully assigned compute/eval-conflicts-rho020-r1-116-tqxrb to kind-worker4
0.523,Event,ADDED,eval-conflicts-rho020-r1-116-tqxrb.18d53f1bfa5976e9,"reason=Pulled count=1 msg=Container image ""busybox:musl"" already present on machine"
0.5232,Event,ADDED,eval-conflicts-rho020-r1-116-tqxrb.18d53f1bfb751308,reason=Created count=1 msg=Created container: task
0.5234,Event,ADDED,eval-conflicts-rho020-r1-116-tqxrb.18d53f1c02bc6eaf,reason=Started count=1 msg=Started container task
0.5236,Event,ADDED,eval-conflicts-rho020-r1-116.18d53f1bdde9ba82,reason=SuccessfulCreate count=1 msg=Created pod: eval-conflicts-rho020-r1-116-tqxrb
0.5238,Event,ADDED,eval-conflicts-rho020-r1-116.18d53f214002e053,reason=Completed count=1 msg=Job completed
0.524,Event,ADDED,eval-conflicts-rho020-r1-117-8rzzj.18d53f1c1a664ad1,"reason=FailedScheduling count=None msg=0/6 nodes are available: 1 c_wall violated: 1 conflicting context pair(s) with node memory, 1 c_wall violated: 2 conflicting context pair(s) with node memory, 4 node(s) had untolerated taint(s). no new claims to deallocate, preemption: 0/6 nodes are available: 2 No preemption victims found for incoming pod, 4 Preemption is not helpful for scheduling."
0.5242,Event,ADDED,eval-conflicts-rho020-r1-117-8rzzj.18d53f1c1e013467,"reason=FailedScheduling count=None msg=0/6 nodes are available: 1 c_wall violated: 1 conflicting context pair(s) with node memory, 1 c_wall violated: 2 conflicting context pair(s) with node memory, 4 node(s) had untolerated taint(s). no new claims to deallocate, preemption: 0/6 nodes are available: 2 No preemption victims found for incoming pod, 4 Preemption is not helpful for scheduling."
0.5244,Event,ADDED,eval-conflicts-rho020-r1-117-8rzzj.18d53f1cacf26fbf,"reason=FailedScheduling count=None msg=0/6 nodes are available: 1 c_wall violated: 1 conflicting context pair(s) with node memory, 5 node(s) had untolerated taint(s). no new claims to deallocate, preemption: 0/6 nodes are available: 1 No preemption victims found for incoming pod, 5 Preemption is not helpful for scheduling."
0.5246,Event,ADDED,eval-conflicts-rho020-r1-117-8rzzj.18d53f1d12d1c2fd,reason=Scheduled count=None msg=Successfully assigned compute/eval-conflicts-rho020-r1-117-8rzzj to kind-worker5
0.525,Event,ADDED,eval-conflicts-rho020-r1-117-8rzzj.18d53f1d35f66589,"reason=Pulled count=1 msg=Container image ""busybox:musl"" already present on machine"
0.5251,Event,ADDED,eval-conflicts-rho020-r1-117-8rzzj.18d53f1d38498c29,reason=Created count=1 msg=Created container: task
0.5253,Event,ADDED,eval-conflicts-rho020-r1-117-8rzzj.18d53f1d41f1d47f,reason=Started count=1 msg=Started container task
0.5255,Event,ADDED,eval-conflicts-rho020-r1-117.18d53f1c19fa73d5,reason=SuccessfulCreate count=1 msg=Created pod: eval-conflicts-rho020-r1-117-8rzzj
0.5258,Event,ADDED,eval-conflicts-rho020-r1-117.18d53f22d9b80e8b,reason=Completed count=1 msg=Job completed
0.5259,Event,ADDED,eval-conflicts-rho020-r1-118-h99vr.18d53f1c552f6961,reason=Scheduled count=None msg=Successfully assigned compute/eval-conflicts-rho020-r1-118-h99vr to kind-worker4
0.5261,Event,ADDED,eval-conflicts-rho020-r1-118-h99vr.18d53f1c7087ccae,"reason=Pulled count=1 msg=Container image ""busybox:musl"" already present on machine"
0.5263,Event,ADDED,eval-conflicts-rho020-r1-118-h99vr.18d53f1c7193e22e,reason=Created count=1 msg=Created container: task
0.5267,Event,ADDED,eval-conflicts-rho020-r1-118-h99vr.18d53f1c78b4f012,reason=Started count=1 msg=Started container task
0.5269,Event,ADDED,eval-conflicts-rho020-r1-118.18d53f1c5486e400,reason=SuccessfulCreate count=1 msg=Created pod: eval-conflicts-rho020-r1-118-h99vr
0.527,Event,ADDED,eval-conflicts-rho020-r1-118.18d53f21c06cfac0,reason=Completed count=1 msg=Job completed
0.5273,Event,ADDED,eval-conflicts-rho020-r1-119-9dpqh.18d53f1c911b68f3,reason=Scheduled count=None msg=Successfully assigned compute/eval-conflicts-rho020-r1-119-9dpqh to kind-worker4
0.5276,Event,ADDED,eval-conflicts-rho020-r1-119-9dpqh.18d53f1cb2ae2037,"reason=Pulled count=1 msg=Container image ""busybox:musl"" already present on machine"
0.5277,Event,ADDED,eval-conflicts-rho020-r1-119-9dpqh.18d53f1cb3d49870,reason=Created count=1 msg=Created container: task
0.5279,Event,ADDED,eval-conflicts-rho020-r1-119-9dpqh.18d53f1cbd938b36,reason=Started count=1 msg=Started container task
0.5282,Event,ADDED,eval-conflicts-rho020-r1-119.18d53f1c9071539d,reason=SuccessfulCreate count=1 msg=Created pod: eval-conflicts-rho020-r1-119-9dpqh
0.5284,Event,ADDED,eval-conflicts-rho020-r1-119.18d53f21f3c0848f,reason=Completed count=1 msg=Job completed
0.5286,Event,ADDED,eval-conflicts-rho020-r1-120-dmmrg.18d53f1ccc928bb3,"reason=FailedScheduling count=None msg=0/6 nodes are available: 1 c_wall violated: 2 conflicting context pair(s) with node memory, 5 node(s) had untolerated taint(s). no new claims to deallocate, preemption: 0/6 nodes are available: 1 No preemption victims found for incoming pod, 5 Preemption is not helpful for scheduling."
0.529,Event,ADDED,eval-conflicts-rho020-r1-120-dmmrg.18d53f1ccd2fe2d0,"reason=FailedScheduling count=None msg=0/6 nodes are available: 1 c_wall violated: 2 conflicting context pair(s) with node memory, 5 node(s) had untolerated taint(s). no new claims to deallocate, preemption: 0/6 nodes are available: 1 No preemption victims found for incoming pod, 5 Preemption is not helpful for scheduling."
0.5292,Event,ADDED,eval-conflicts-rho020-r1-120-dmmrg.18d53f1d13b6462e,reason=Scheduled count=None msg=Successfully assigned compute/eval-conflicts-rho020-r1-120-dmmrg to kind-worker5
0.5293,Event,ADDED,eval-conflicts-rho020-r1-120-dmmrg.18d53f1d36381790,"reason=Pulled count=1 msg=Container image ""busybox:musl"" already present on machine"
0.5295,Event,ADDED,eval-conflicts-rho020-r1-120-dmmrg.18d53f1d3872e9f6,reason=Created count=1 msg=Created container: task
0.5298,Event,ADDED,eval-conflicts-rho020-r1-120-dmmrg.18d53f1d41f14443,reason=Started count=1 msg=Started container task
0.53,Event,ADDED,eval-conflicts-rho020-r1-120.18d53f1ccc48bc40,reason=SuccessfulCreate count=1 msg=Created pod: eval-conflicts-rho020-r1-120-dmmrg
0.5302,Event,ADDED,eval-conflicts-rho020-r1-120.18d53f22d9b60520,reason=Completed count=1 msg=Job completed
0.5304,Event,ADDED,eval-conflicts-rho020-r1-121-vlxns.18d53f1d08a53b43,"reason=FailedScheduling count=None msg=0/6 nodes are available: 1 c_wall violated: 1 conflicting context pair(s) with node memory, 5 node(s) had untolerated taint(s). no new claims to deallocate, preemption: 0/6 nodes are available: 1 No preemption victims found for incoming pod, 5 Preemption is not helpful for scheduling."
0.5306,Event,ADDED,eval-conflicts-rho020-r1-121-vlxns.18d53f1d0c7858c7,"reason=FailedScheduling count=None msg=0/6 nodes are available: 1 c_wall violated: 1 conflicting context pair(s) with node memory, 5 node(s) had untolerated taint(s). no new claims to deallocate, preemption: 0/6 nodes are available: 1 No preemption victims found for incoming pod, 5 Preemption is not helpful for scheduling."
0.5308,Event,ADDED,eval-conflicts-rho020-r1-121-vlxns.18d53f1d134780f0,reason=Scheduled count=None msg=Successfully assigned compute/eval-conflicts-rho020-r1-121-vlxns to kind-worker5
0.5309,Event,ADDED,eval-conflicts-rho020-r1-121-vlxns.18d53f1d361f7e68,"reason=Pulled count=1 msg=Container image ""busybox:musl"" already present on machine"
0.5311,Event,ADDED,eval-conflicts-rho020-r1-121-vlxns.18d53f1d381d8c86,reason=Created count=1 msg=Created container: task
0.5313,Event,ADDED,eval-conflicts-rho020-r1-121-vlxns.18d53f1d41f0de2a,reason=Started count=1 msg=Started container task
0.5315,Event,ADDED,eval-conflicts-rho020-r1-121.18d53f1d0859bf52,reason=SuccessfulCreate count=1 msg=Created pod: eval-conflicts-rho020-r1-121-vlxns
0.5317,Event,ADDED,eval-conflicts-rho020-r1-121.18d53f22d9b9a8b5,reason=Completed count=1 msg=Job completed
0.5318,Event,ADDED,eval-conflicts-rho020-r1-122-kdzj8.18d53f1d5438d653,reason=Scheduled count=None msg=Successfully assigned compute/eval-conflicts-rho020-r1-122-kdzj8 to kind-worker5
0.5359,Event,ADDED,eval-conflicts-rho020-r1-122-kdzj8.18d53f1d72abfa71,"reason=Pulled count=1 msg=Container image ""busybox:musl"" already present on machine"
0.5361,Event,ADDED,eval-conflicts-rho020-r1-122-kdzj8.18d53f1d73ff9d6e,reason=Created count=1 msg=Created container: task
0.5363,Event,ADDED,eval-conflicts-rho020-r1-122-kdzj8.18d53f1d7d7d2b15,reason=Started count=1 msg=Started container task
0.5365,Event,ADDED,eval-conflicts-rho020-r1-122.18d53f1d515d2c50,reason=SuccessfulCreate count=1 msg=Created pod: eval-conflicts-rho020-r1-122-kdzj8
0.5367,Event,ADDED,eval-conflicts-rho020-r1-122.18d53f22da486e63,reason=Completed count=1 msg=Job completed
0.537,Event,ADDED,eval-conflicts-rho020-r1-123-knlcg.18d53f1d802e1c81,reason=Scheduled count=None msg=Successfully assigned compute/eval-conflicts-rho020-r1-123-knlcg to kind-worker5
0.5372,Event,ADDED,eval-conflicts-rho020-r1-123-knlcg.18d53f1dbaab6767,"reason=Pulled count=1 msg=Container image ""busybox:musl"" already present on machine"
0.5374,Event,ADDED,eval-conflicts-rho020-r1-123-knlcg.18d53f1dbc22f27b,reason=Created count=1 msg=Created container: task
0.5375,Event,ADDED,eval-conflicts-rho020-r1-123-knlcg.18d53f1dc05e2a5a,reason=Started count=1 msg=Started container task
0.5378,Event,ADDED,eval-conflicts-rho020-r1-123.18d53f1d7f2c0841,reason=SuccessfulCreate count=1 msg=Created pod: eval-conflicts-rho020-r1-123-knlcg
0.5379,Event,ADDED,eval-conflicts-rho020-r1-123.18d53f2315e17c3d,reason=Completed count=1 msg=Job completed
0.5381,Event,ADDED,eval-conflicts-rho020-r1-124-7gtpw.18d53f1dbd527b7e,"reason=FailedScheduling count=None msg=0/6 nodes are available: 2 c_wall violated: 1 conflicting context pair(s) with node memory, 4 node(s) had untolerated taint(s). no new claims to deallocate, preemption: 0/6 nodes are available: 2 No preemption victims found for incoming pod, 4 Preemption is not helpful for scheduling."
0.5383,Event,ADDED,eval-conflicts-rho020-r1-124-7gtpw.18d53f1dbf433d12,"reason=FailedScheduling count=None msg=0/6 nodes are available: 2 c_wall violated: 1 conflicting context pair(s) with node memory, 4 node(s) had untolerated taint(s). no new claims to deallocate, preemption: 0/6 nodes are available: 2 No preemption victims found for incoming pod, 4 Preemption is not helpful for scheduling."
0.5385,Event,ADDED,eval-conflicts-rho020-r1-124-7gtpw.18d53f1de48b3046,"reason=FailedScheduling count=None msg=0/6 nodes are available: 1 c_wall violated: 1 conflicting context pair(s) with node memory, 5 node(s) had untolerated taint(s). no new claims to deallocate, preemption: 0/6 nodes are available: 1 No preemption victims found for incoming pod, 5 Preemption is not helpful for scheduling."
0.5386,Event,ADDED,eval-conflicts-rho020-r1-124-7gtpw.18d53f1f1de6a7ba,reason=Scheduled count=None msg=Successfully assigned compute/eval-conflicts-rho020-r1-124-7gtpw to kind-worker3
0.5388,Event,ADDED,eval-conflicts-rho020-r1-124-7gtpw.18d53f1f498997ae,"reason=Pulled count=1 msg=Container image ""busybox:musl"" already present on machine"
0.539,Event,ADDED,eval-conflicts-rho020-r1-124-7gtpw.18d53f1f4f2f48a6,reason=Created count=1 msg=Created container: task
0.5391,Event,ADDED,eval-conflicts-rho020-r1-124-7gtpw.18d53f1f5323663c,reason=Started count=1 msg=Started container task
0.5393,Event,ADDED,eval-conflicts-rho020-r1-124.18d53f1dbce90bf8,reason=SuccessfulCreate count=1 msg=Created pod: eval-conflicts-rho020-r1-124-7gtpw
0.5395,Event,ADDED,eval-conflicts-rho020-r1-124.18d53f24f849ac17,reason=Completed count=1 msg=Job completed
0.5396,Event,ADDED,eval-conflicts-rho020-r1-125-dw85n.18d53f1df981a60d,"reason=FailedScheduling count=None msg=0/6 nodes are available: 1 c_wall violated: 1 conflicting context pair(s) with node memory, 5 node(s) had untolerated taint(s). no new claims to deallocate, preemption: 0/6 nodes are available: 1 No preemption victims found for incoming pod, 5 Preemption is not helpful for scheduling."
0.5398,Event,ADDED,eval-conflicts-rho020-r1-125-dw85n.18d53f1dfa02b06b,"reason=FailedScheduling count=None msg=0/6 nodes are available: 1 c_wall violated: 1 conflicting context pair(s) with node memory, 5 node(s) had untolerated taint(s). no new claims to deallocate, preemption: 0/6 nodes are available: 1 No preemption victims found for incoming pod, 5 Preemption is not helpful for scheduling."
0.54,Event,ADDED,eval-conflicts-rho020-r1-125-dw85n.18d53f1f1df2e318,reason=Scheduled count=None msg=Successfully assigned compute/eval-conflicts-rho020-r1-125-dw85n to kind-worker3
0.5401,Event,ADDED,eval-conflicts-rho020-r1-125-dw85n.18d53f1f496121f2,"reason=Pulled count=1 msg=Container image ""busybox:musl"" already present on machine"
0.5403,Event,ADDED,eval-conflicts-rho020-r1-125-dw85n.18d53f1f4eed8695,reason=Created count=1 msg=Created container: task
0.5405,Event,ADDED,eval-conflicts-rho020-r1-125-dw85n.18d53f1f539b3606,reason=Started count=1 msg=Started container task
0.5408,Event,ADDED,eval-conflicts-rho020-r1-125.18d53f1df9451265,reason=SuccessfulCreate count=1 msg=Created pod: eval-conflicts-rho020-r1-125-dw85n
0.541,Event,ADDED,eval-conflicts-rho020-r1-125.18d53f24bcb0628f,reason=Completed count=1 msg=Job completed
0.5411,Event,ADDED,eval-conflicts-rho020-r1-126-bz6nl.18d53f1e32e8eaca,"reason=FailedScheduling count=None msg=0/6 nodes are available: 1 c_wall violated: 1 conflicting context pair(s) with node memory, 5 node(s) had untolerated taint(s). no new claims to deallocate, preemption: 0/6 nodes are available: 1 No preemption victims found for incoming pod, 5 Preemption is not helpful for scheduling."
0.5415,Event,ADDED,eval-conflicts-rho020-r1-126-bz6nl.18d53f1e33867335,"reason=FailedScheduling count=None msg=0/6 nodes are available: 1 c_wall violated: 1 conflicting context pair(s) with node memory, 5 node(s) had untolerated taint(s). no new claims to deallocate, preemption: 0/6 nodes are available: 1 No preemption victims found for incoming pod, 5 Preemption is not helpful for scheduling."
0.5416,Event,ADDED,eval-conflicts-rho020-r1-126-bz6nl.18d53f1f1df0b098,reason=Scheduled count=None msg=Successfully assigned compute/eval-conflicts-rho020-r1-126-bz6nl to kind-worker3
0.5418,Event,ADDED,eval-conflicts-rho020-r1-126-bz6nl.18d53f1f490e45f7,"reason=Pulled count=1 msg=Container image ""busybox:musl"" already present on machine"
0.542,Event,ADDED,eval-conflicts-rho020-r1-126-bz6nl.18d53f1f4e30c7b7,reason=Created count=1 msg=Created container: task
0.5421,Event,ADDED,eval-conflicts-rho020-r1-126-bz6nl.18d53f1f52a31e9b,reason=Started count=1 msg=Started container task
0.5423,Event,ADDED,eval-conflicts-rho020-r1-126.18d53f1e329a7663,reason=SuccessfulCreate count=1 msg=Created pod: eval-conflicts-rho020-r1-126-bz6nl
0.5425,Event,ADDED,eval-conflicts-rho020-r1-126.18d53f24bcf931be,reason=Completed count=1 msg=Job completed
0.5428,Event,ADDED,eval-conflicts-rho020-r1-127-qncrb.18d53f1e71728043,"reason=FailedScheduling count=None msg=0/6 nodes are available: 1 c_wall violated: 1 conflicting context pair(s) with node memory, 5 node(s) had untolerated taint(s). no new claims to deallocate, preemption: 0/6 nodes are available: 1 No preemption victims found for incoming pod, 5 Preemption is not helpful for scheduling."
0.543,Event,ADDED,eval-conflicts-rho020-r1-127-qncrb.18d53f1e721ab30b,"reason=FailedScheduling count=None msg=0/6 nodes are available: 1 c_wall violated: 1 conflicting context pair(s) with node memory, 5 node(s) had untolerated taint(s). no new claims to deallocate, preemption: 0/6 nodes are available: 1 No preemption victims found for incoming pod, 5 Preemption is not helpful for scheduling."
0.5431,Event,ADDED,eval-conflicts-rho020-r1-127-qncrb.18d53f1f1dc1c351,reason=Scheduled count=None msg=Successfully assigned compute/eval-conflicts-rho020-r1-127-qncrb to kind-worker3
0.5434,Event,ADDED,eval-conflicts-rho020-r1-127-qncrb.18d53f1f48b9f2b8,"reason=Pulled count=1 msg=Container image ""busybox:musl"" already present on machine"
0.5435,Event,ADDED,eval-conflicts-rho020-r1-127-qncrb.18d53f1f4c8b28c5,reason=Created count=1 msg=Created container: task
0.5437,Event,ADDED,eval-conflicts-rho020-r1-127-qncrb.18d53f1f513f97fe,reason=Started count=1 msg=Started container task
0.5439,Event,ADDED,eval-conflicts-rho020-r1-127.18d53f1e711f6af8,reason=SuccessfulCreate count=1 msg=Created pod: eval-conflicts-rho020-r1-127-qncrb
0.5442,Event,ADDED,eval-conflicts-rho020-r1-127.18d53f24ba86e1b8,reason=Completed count=1 msg=Job completed
0.5443,Event,ADDED,eval-conflicts-rho020-r1-128-ft9sz.18d53f1eaafc4076,"reason=FailedScheduling count=None msg=0/6 nodes are available: 1 c_wall violated: 1 conflicting context pair(s) with node memory, 5 node(s) had untolerated taint(s). no new claims to deallocate, preemption: 0/6 nodes are available: 1 No preemption victims found for incoming pod, 5 Preemption is not helpful for scheduling."
0.5446,Event,ADDED,eval-conflicts-rho020-r1-128-ft9sz.18d53f1eab9855b5,"reason=FailedScheduling count=None msg=0/6 nodes are available: 1 c_wall violated: 1 conflicting context pair(s) with node memory, 5 node(s) had untolerated taint(s). no new claims to deallocate, preemption: 0/6 nodes are available: 1 No preemption victims found for incoming pod, 5 Preemption is not helpful for scheduling."
0.5449,Event,ADDED,eval-conflicts-rho020-r1-128-ft9sz.18d53f1f1de83be0,reason=Scheduled count=None msg=Successfully assigned compute/eval-conflicts-rho020-r1-128-ft9sz to kind-worker3
0.5451,Event,ADDED,eval-conflicts-rho020-r1-128-ft9sz.18d53f1f48e063bc,"reason=Pulled count=1 msg=Container image ""busybox:musl"" already present on machine"
0.5453,Event,ADDED,eval-conflicts-rho020-r1-128-ft9sz.18d53f1f4de560b1,reason=Created count=1 msg=Created container: task
0.5454,Event,ADDED,eval-conflicts-rho020-r1-128-ft9sz.18d53f1f52a39ba6,reason=Started count=1 msg=Started container task
0.5457,Event,ADDED,eval-conflicts-rho020-r1-128.18d53f1eaac4b3d3,reason=SuccessfulCreate count=1 msg=Created pod: eval-conflicts-rho020-r1-128-ft9sz
0.5459,Event,ADDED,eval-conflicts-rho020-r1-128.18d53f24f8689e88,reason=Completed count=1 msg=Job completed
0.5462,Event,ADDED,eval-conflicts-rho020-r1-129-h42fk.18d53f1ee771aa8c,reason=Scheduled count=None msg=Successfully assigned compute/eval-conflicts-rho020-r1-129-h42fk to kind-worker5
0.5465,Event,ADDED,eval-conflicts-rho020-r1-129-h42fk.18d53f1f0595b75b,"reason=Pulled count=1 msg=Container image ""busybox:musl"" already present on machine"
0.5467,Event,ADDED,eval-conflicts-rho020-r1-129-h42fk.18d53f1f073308c1,reason=Created count=1 msg=Created container: task
0.5469,Event,ADDED,eval-conflicts-rho020-r1-129-h42fk.18d53f1f11a17199,reason=Started count=1 msg=Started container task
0.547,Event,ADDED,eval-conflicts-rho020-r1-129.18d53f1ee6df4ec5,reason=SuccessfulCreate count=1 msg=Created pod: eval-conflicts-rho020-r1-129-h42fk
0.5475,Event,ADDED,eval-conflicts-rho020-r1-129.18d53f24404b0049,reason=Completed count=1 msg=Job completed
0.5479,Event,ADDED,eval-conflicts-rho020-r1-130-nmkpr.18d53f1f236cb747,reason=Scheduled count=None msg=Successfully assigned compute/eval-conflicts-rho020-r1-130-nmkpr to kind-worker3
0.5483,Event,ADDED,eval-conflicts-rho020-r1-130-nmkpr.18d53f1f53b66582,"reason=Pulled count=1 msg=Container image ""busybox:musl"" already present on machine"
0.5487,Event,ADDED,eval-conflicts-rho020-r1-130-nmkpr.18d53f1f54f43a95,reason=Created count=1 msg=Created container: task
0.549,Event,ADDED,eval-conflicts-rho020-r1-130-nmkpr.18d53f1f59302e1b,reason=Started count=1 msg=Started container task
0.5492,Event,ADDED,eval-conflicts-rho020-r1-130.18d53f1f211e3355,reason=SuccessfulCreate count=1 msg=Created pod: eval-conflicts-rho020-r1-130-nmkpr
0.5494,Event,ADDED,eval-conflicts-rho020-r1-130.18d53f24bc941590,reason=Completed count=1 msg=Job completed
0.5498,Event,ADDED,eval-conflicts-rho020-r1-131-jqx8r.18d53f1f5e31e176,"reason=FailedScheduling count=None msg=0/6 nodes are available: 2 c_wall violated: 1 conflicting context pair(s) with node memory, 4 node(s) had untolerated taint(s). no new claims to deallocate, preemption: 0/6 nodes are available: 2 No preemption victims found for incoming pod, 4 Preemption is not helpful for scheduling."
0.55,Event,ADDED,eval-conflicts-rho020-r1-131-jqx8r.18d53f1f5ed58c83,"reason=FailedScheduling count=None msg=0/6 nodes are available: 2 c_wall violated: 1 conflicting context pair(s) with node memory, 4 node(s) had untolerated taint(s). no new claims to deallocate, preemption: 0/6 nodes are available: 2 No preemption victims found for incoming pod, 4 Preemption is not helpful for scheduling."
0.5502,Event,ADDED,eval-conflicts-rho020-r1-131-jqx8r.18d53f21c6321f72,"reason=FailedScheduling count=None msg=0/6 nodes are available: 1 c_wall violated: 1 conflicting context pair(s) with node memory, 5 node(s) had untolerated taint(s). no new claims to deallocate, preemption: 0/6 nodes are available: 1 No preemption victims found for incoming pod, 5 Preemption is not helpful for scheduling."
0.5505,Event,ADDED,eval-conflicts-rho020-r1-131-jqx8r.18d53f22a141712e,reason=Scheduled count=None msg=Successfully assigned compute/eval-conflicts-rho020-r1-131-jqx8r to kind-worker
0.5507,Event,ADDED,eval-conflicts-rho020-r1-131-jqx8r.18d53f22bcf50408,"reason=Pulled count=1 msg=Container image ""busybox:musl"" already present on machine"
0.5509,Event,ADDED,eval-conflicts-rho020-r1-131-jqx8r.18d53f22bf6a02f0,reason=Created count=1 msg=Created container: task
0.551,Event,ADDED,eval-conflicts-rho020-r1-131-jqx8r.18d53f22c58f416b,reason=Started count=1 msg=Started container task
0.5515,Event,ADDED,eval-conflicts-rho020-r1-131.18d53f1f5dcc6bfc,reason=SuccessfulCreate count=1 msg=Created pod: eval-conflicts-rho020-r1-131-jqx8r
0.5517,Event,ADDED,eval-conflicts-rho020-r1-131.18d53f285ecc368e,reason=Completed count=1 msg=Job completed
0.5519,Event,ADDED,eval-conflicts-rho020-r1-132-lwgxj.18d53f1f984b4b6f,reason=Scheduled count=None msg=Successfully assigned compute/eval-conflicts-rho020-r1-132-lwgxj to kind-worker5
0.5522,Event,ADDED,eval-conflicts-rho020-r1-132-lwgxj.18d53f1fb9ff8f1a,"reason=Pulled count=1 msg=Container image ""busybox:musl"" already present on machine"
0.5524,Event,ADDED,eval-conflicts-rho020-r1-132-lwgxj.18d53f1fbb1a26ef,reason=Created count=1 msg=Created container: task
0.5527,Event,ADDED,eval-conflicts-rho020-r1-132-lwgxj.18d53f1fca037a01,reason=Started count=1 msg=Started container task
0.5529,Event,ADDED,eval-conflicts-rho020-r1-132.18d53f1f9771c52d,reason=SuccessfulCreate count=1 msg=Created pod: eval-conflicts-rho020-r1-132-lwgxj
0.5533,Event,ADDED,eval-conflicts-rho020-r1-132.18d53f24f264a497,reason=Completed count=1 msg=Job completed
0.5535,Event,ADDED,eval-conflicts-rho020-r1-133-cm9dh.18d53f1fd818be47,reason=Scheduled count=None msg=Successfully assigned compute/eval-conflicts-rho020-r1-133-cm9dh to kind-worker3
0.5537,Event,ADDED,eval-conflicts-rho020-r1-133-cm9dh.18d53f20019196fb,"reason=Pulled count=1 msg=Container image ""busybox:musl"" already present on machine"
0.5538,Event,ADDED,eval-conflicts-rho020-r1-133-cm9dh.18d53f2002bae5cd,reason=Created count=1 msg=Created container: task
0.5542,Event,ADDED,eval-conflicts-rho020-r1-133-cm9dh.18d53f200ccfa9f6,reason=Started count=1 msg=Started container task
0.5544,Event,ADDED,eval-conflicts-rho020-r1-133.18d53f1fd7362c4d,reason=SuccessfulCreate count=1 msg=Created pod: eval-conflicts-rho020-r1-133-cm9dh
0.5546,Event,ADDED,eval-conflicts-rho020-r1-133.18d53f25703ca52d,reason=Completed count=1 msg=Job completed
0.555,Event,ADDED,eval-conflicts-rho020-r1-134-ctmpf.18d53f20137cab08,"reason=FailedScheduling count=None msg=0/6 nodes are available: 1 c_wall violated: 1 conflicting context pair(s) with node memory, 1 c_wall violated: 2 conflicting context pair(s) with node memory, 4 node(s) had untolerated taint(s). no new claims to deallocate, preemption: 0/6 nodes are available: 2 No preemption victims found for incoming pod, 4 Preemption is not helpful for scheduling."
0.5552,Event,ADDED,eval-conflicts-rho020-r1-134-ctmpf.18d53f2014516399,"reason=FailedScheduling count=None msg=0/6 nodes are available: 1 c_wall violated: 1 conflicting context pair(s) with node memory, 1 c_wall violated: 2 conflicting context pair(s) with node memory, 4 node(s) had untolerated taint(s). no new claims to deallocate, preemption: 0/6 nodes are available: 2 No preemption victims found for incoming pod, 4 Preemption is not helpful for scheduling."
0.5554,Event,ADDED,eval-conflicts-rho020-r1-134-ctmpf.18d53f21c66aaf7e,"reason=FailedScheduling count=None msg=0/6 nodes are available: 1 c_wall violated: 2 conflicting context pair(s) with node memory, 5 node(s) had untolerated taint(s). no new claims to deallocate, preemption: 0/6 nodes are available: 1 No preemption victims found for incoming pod, 5 Preemption is not helpful for scheduling."
0.5557,Event,ADDED,eval-conflicts-rho020-r1-134-ctmpf.18d53f22a33a289a,reason=Scheduled count=None msg=Successfully assigned compute/eval-conflicts-rho020-r1-134-ctmpf to kind-worker
0.5559,Event,ADDED,eval-conflicts-rho020-r1-134-ctmpf.18d53f22cf3b5954,"reason=Pulled count=1 msg=Container image ""busybox:musl"" already present on machine"
0.5561,Event,ADDED,eval-conflicts-rho020-r1-134-ctmpf.18d53f22d06582ea,reason=Created count=1 msg=Created container: task
0.5563,Event,ADDED,eval-conflicts-rho020-r1-134-ctmpf.18d53f22d9336bc4,reason=Started count=1 msg=Started container task
0.5567,Event,ADDED,eval-conflicts-rho020-r1-134.18d53f200f8e3b29,reason=SuccessfulCreate count=1 msg=Created pod: eval-conflicts-rho020-r1-134-ctmpf
0.5569,Event,ADDED,eval-conflicts-rho020-r1-134.18d53f285eb16688,reason=Completed count=1 msg=Job completed
0.5571,Event,ADDED,eval-conflicts-rho020-r1-135-qz7wh.18d53f204b32eaa8,reason=Scheduled count=None msg=Successfully assigned compute/eval-conflicts-rho020-r1-135-qz7wh to kind-worker3
0.5574,Event,ADDED,eval-conflicts-rho020-r1-135-qz7wh.18d53f206ee2c7b7,"reason=Pulled count=1 msg=Container image ""busybox:musl"" already present on machine"
0.5576,Event,ADDED,eval-conflicts-rho020-r1-135-qz7wh.18d53f206fec02dd,reason=Created count=1 msg=Created container: task
0.5578,Event,ADDED,eval-conflicts-rho020-r1-135-qz7wh.18d53f207be5e8d7,reason=Started count=1 msg=Started container task
0.558,Event,ADDED,eval-conflicts-rho020-r1-135.18d53f204a7763b3,reason=SuccessfulCreate count=1 msg=Created pod: eval-conflicts-rho020-r1-135-qz7wh
0.5583,Event,ADDED,eval-conflicts-rho020-r1-135.18d53f25ebc39f05,reason=Completed count=1 msg=Job completed
0.5585,Event,ADDED,eval-conflicts-rho020-r1-136-sprsb.18d53f208af48027,reason=Scheduled count=None msg=Successfully assigned compute/eval-conflicts-rho020-r1-136-sprsb to kind-worker5
0.5586,Event,ADDED,eval-conflicts-rho020-r1-136-sprsb.18d53f20a863f07d,"reason=Pulled count=1 msg=Container image ""busybox:musl"" already present on machine"
0.5589,Event,ADDED,eval-conflicts-rho020-r1-136-sprsb.18d53f20a978f149,reason=Created count=1 msg=Created container: task
0.5591,Event,ADDED,eval-conflicts-rho020-r1-136-sprsb.18d53f20b0b264c8,reason=Started count=1 msg=Started container task
0.5592,Event,ADDED,eval-conflicts-rho020-r1-136.18d53f208a122fcb,reason=SuccessfulCreate count=1 msg=Created pod: eval-conflicts-rho020-r1-136-sprsb
0.5594,Event,ADDED,eval-conflicts-rho020-r1-136.18d53f25e05e4c0b,reason=Completed count=1 msg=Job completed
0.5596,Event,ADDED,eval-conflicts-rho020-r1-137-rqfw2.18d53f20c5b4c938,reason=Scheduled count=None msg=Successfully assigned compute/eval-conflicts-rho020-r1-137-rqfw2 to kind-worker3
0.5597,Event,ADDED,eval-conflicts-rho020-r1-137-rqfw2.18d53f20e49f43dc,"reason=Pulled count=1 msg=Container image ""busybox:musl"" already present on machine"
0.5599,Event,ADDED,eval-conflicts-rho020-r1-137-rqfw2.18d53f20e5ca5233,reason=Created count=1 msg=Created container: task
0.5601,Event,ADDED,eval-conflicts-rho020-r1-137-rqfw2.18d53f20ed7b91cc,reason=Started count=1 msg=Started container task
0.5602,Event,ADDED,eval-conflicts-rho020-r1-137.18d53f20c4e4eb34,reason=SuccessfulCreate count=1 msg=Created pod: eval-conflicts-rho020-r1-137-rqfw2
0.5604,Event,ADDED,eval-conflicts-rho020-r1-137.18d53f2669bf6b9b,reason=Completed count=1 msg=Job completed
0.5609,Event,ADDED,eval-conflicts-rho020-r1-138-97t89.18d53f20fe07a2d4,reason=Scheduled count=None msg=Successfully assigned compute/eval-conflicts-rho020-r1-138-97t89 to kind-worker3
0.5612,Event,ADDED,eval-conflicts-rho020-r1-138-97t89.18d53f2121ba9105,"reason=Pulled count=1 msg=Container image ""busybox:musl"" already present on machine"
0.5614,Event,ADDED,eval-conflicts-rho020-r1-138-97t89.18d53f2123144f03,reason=Created count=1 msg=Created container: task
0.5616,Event,ADDED,eval-conflicts-rho020-r1-138-97t89.18d53f212bec7aca,reason=Started count=1 msg=Started container task
0.5618,Event,ADDED,eval-conflicts-rho020-r1-138.18d53f20fcf864c4,reason=SuccessfulCreate count=1 msg=Created pod: eval-conflicts-rho020-r1-138-97t89
0.5622,Event,ADDED,eval-conflicts-rho020-r1-138.18d53f269eb17930,reason=Completed count=1 msg=Job completed
0.5624,Event,ADDED,eval-conflicts-rho020-r1-139-mlrvj.18d53f214413fc5f,reason=Scheduled count=None msg=Successfully assigned compute/eval-conflicts-rho020-r1-139-mlrvj to kind-worker5
0.5626,Event,ADDED,eval-conflicts-rho020-r1-139-mlrvj.18d53f2162b2394f,"reason=Pulled count=1 msg=Container image ""busybox:musl"" already present on machine"
0.5627,Event,ADDED,eval-conflicts-rho020-r1-139-mlrvj.18d53f21646707a2,reason=Created count=1 msg=Created container: task
0.563,Event,ADDED,eval-conflicts-rho020-r1-139-mlrvj.18d53f216e294871,reason=Started count=1 msg=Started container task
0.5631,Event,ADDED,eval-conflicts-rho020-r1-139.18d53f214083fdf6,reason=SuccessfulCreate count=1 msg=Created pod: eval-conflicts-rho020-r1-139-mlrvj
0.5633,Event,ADDED,eval-conflicts-rho020-r1-139.18d53f26d16f01ad,reason=Completed count=1 msg=Job completed
0.5635,Event,ADDED,eval-conflicts-rho020-r1-140-g297l.18d53f21751911bb,reason=Scheduled count=None msg=Successfully assigned compute/eval-conflicts-rho020-r1-140-g297l to kind-worker5
0.5637,Event,ADDED,eval-conflicts-rho020-r1-140-g297l.18d53f21947db0e4,"reason=Pulled count=1 msg=Container image ""busybox:musl"" already present on machine"
0.5639,Event,ADDED,eval-conflicts-rho020-r1-140-g297l.18d53f2195aa1a4f,reason=Created count=1 msg=Created container: task
0.564,Event,ADDED,eval-conflicts-rho020-r1-140-g297l.18d53f219c7684c2,reason=Started count=1 msg=Started container task
0.5642,Event,ADDED,eval-conflicts-rho020-r1-140.18d53f2174473ba6,reason=SuccessfulCreate count=1 msg=Created pod: eval-conflicts-rho020-r1-140-g297l
0.5644,Event,ADDED,eval-conflicts-rho020-r1-140.18d53f26d1529b4b,reason=Completed count=1 msg=Job completed
0.5646,Event,ADDED,eval-conflicts-rho020-r1-141-vr8vz.18d53f21b43d98f4,reason=Scheduled count=None msg=Successfully assigned compute/eval-conflicts-rho020-r1-141-vr8vz to kind-worker3
0.5648,Event,ADDED,eval-conflicts-rho020-r1-141-vr8vz.18d53f21d60ea972,"reason=Pulled count=1 msg=Container image ""busybox:musl"" already present on machine"
0.565,Event,ADDED,eval-conflicts-rho020-r1-141-vr8vz.18d53f21d72d8deb,reason=Created count=1 msg=Created container: task
0.5652,Event,ADDED,eval-conflicts-rho020-r1-141-vr8vz.18d53f21e5173aa8,reason=Started count=1 msg=Started container task
0.5654,Event,ADDED,eval-conflicts-rho020-r1-141.18d53f21b375cf39,reason=SuccessfulCreate count=1 msg=Created pod: eval-conflicts-rho020-r1-141-vr8vz
0.5655,Event,ADDED,eval-conflicts-rho020-r1-141.18d53f275387a7cb,reason=Completed count=1 msg=Job completed
0.5657,Event,ADDED,eval-conflicts-rho020-r1-142-wjnkt.18d53f21f5238da1,reason=Scheduled count=None msg=Successfully assigned compute/eval-conflicts-rho020-r1-142-wjnkt to kind-worker3
0.5659,Event,ADDED,eval-conflicts-rho020-r1-142-wjnkt.18d53f221873fec5,"reason=Pulled count=1 msg=Container image ""busybox:musl"" already present on machine"
0.566,Event,ADDED,eval-conflicts-rho020-r1-142-wjnkt.18d53f2219849e8b,reason=Created count=1 msg=Created container: task
0.5662,Event,ADDED,eval-conflicts-rho020-r1-142-wjnkt.18d53f221ff98793,reason=Started count=1 msg=Started container task
0.5664,Event,ADDED,eval-conflicts-rho020-r1-142.18d53f21f494a116,reason=SuccessfulCreate count=1 msg=Created pod: eval-conflicts-rho020-r1-142-wjnkt
0.5665,Event,ADDED,eval-conflicts-rho020-r1-142.18d53f2793b7fbb9,reason=Completed count=1 msg=Job completed
0.5668,Event,ADDED,eval-conflicts-rho020-r1-143-fblkl.18d53f222a837844,"reason=FailedScheduling count=None msg=0/6 nodes are available: 1 c_wall violated: 1 conflicting context pair(s) with node memory, 5 node(s) had untolerated taint(s). no new claims to deallocate, preemption: 0/6 nodes are available: 1 No preemption victims found for incoming pod, 5 Preemption is not helpful for scheduling."
0.5671,Event,ADDED,eval-conflicts-rho020-r1-143-fblkl.18d53f222afbb16e,"reason=FailedScheduling count=None msg=0/6 nodes are available: 1 c_wall violated: 1 conflicting context pair(s) with node memory, 5 node(s) had untolerated taint(s). no new claims to deallocate, preemption: 0/6 nodes are available: 1 No preemption victims found for incoming pod, 5 Preemption is not helpful for scheduling."
0.5673,Event,ADDED,eval-conflicts-rho020-r1-143-fblkl.18d53f229f5df0d0,reason=Scheduled count=None msg=Successfully assigned compute/eval-conflicts-rho020-r1-143-fblkl to kind-worker
0.5674,Event,ADDED,eval-conflicts-rho020-r1-143-fblkl.18d53f22bcd643d6,"reason=Pulled count=1 msg=Container image ""busybox:musl"" already present on machine"
0.568,Event,ADDED,eval-conflicts-rho020-r1-143-fblkl.18d53f22bf812ddf,reason=Created count=1 msg=Created container: task
0.5682,Event,ADDED,eval-conflicts-rho020-r1-143-fblkl.18d53f22cf366a8d,reason=Started count=1 msg=Started container task
0.5684,Event,ADDED,eval-conflicts-rho020-r1-143.18d53f222a4a2586,reason=SuccessfulCreate count=1 msg=Created pod: eval-conflicts-rho020-r1-143-fblkl
0.5686,Event,ADDED,eval-conflicts-rho020-r1-143.18d53f285eed21e1,reason=Completed count=1 msg=Job completed
0.5687,Event,ADDED,eval-conflicts-rho020-r1-144-fmdc9.18d53f226306dd3f,reason=Scheduled count=None msg=Successfully assigned compute/eval-conflicts-rho020-r1-144-fmdc9 to kind-worker3
0.5689,Event,ADDED,eval-conflicts-rho020-r1-144-fmdc9.18d53f227fe31826,"reason=Pulled count=1 msg=Container image ""busybox:musl"" already present on machine"
0.5691,Event,ADDED,eval-conflicts-rho020-r1-144-fmdc9.18d53f2280f804ee,reason=Created count=1 msg=Created container: task
0.5693,Event,ADDED,eval-conflicts-rho020-r1-144-fmdc9.18d53f2289ca0faf,reason=Started count=1 msg=Started container task
0.5694,Event,ADDED,eval-conflicts-rho020-r1-144.18d53f2262607d41,reason=SuccessfulCreate count=1 msg=Created pod: eval-conflicts-rho020-r1-144-fmdc9
0.5696,Event,ADDED,eval-conflicts-rho020-r1-144.18d53f28199cca08,reason=Completed count=1 msg=Job completed
0.5697,Event,ADDED,eval-conflicts-rho020-r1-145-6rrrj.18d53f229ef8bba5,reason=Scheduled count=None msg=Successfully assigned compute/eval-conflicts-rho020-r1-145-6rrrj to kind-worker3
0.5699,Event,ADDED,eval-conflicts-rho020-r1-145-6rrrj.18d53f22bcd3d4f0,"reason=Pulled count=1 msg=Container image ""busybox:musl"" already present on machine"
0.5701,Event,ADDED,eval-conflicts-rho020-r1-145-6rrrj.18d53f22be790c94,reason=Created count=1 msg=Created container: task
0.5703,Event,ADDED,eval-conflicts-rho020-r1-145-6rrrj.18d53f22c3fe16d6,reason=Started count=1 msg=Started container task
0.5707,Event,ADDED,eval-conflicts-rho020-r1-145.18d53f229e0d5282,reason=SuccessfulCreate count=1 msg=Created pod: eval-conflicts-rho020-r1-145-6rrrj
0.5709,Event,ADDED,eval-conflicts-rho020-r1-145.18d53f284dbfb7c3,reason=Completed count=1 msg=Job completed
0.571,Event,ADDED,eval-conflicts-rho020-r1-146-s5sjt.18d53f22dbef3252,reason=Scheduled count=None msg=Successfully assigned compute/eval-conflicts-rho020-r1-146-s5sjt to kind-worker
0.5712,Event,ADDED,eval-conflicts-rho020-r1-146-s5sjt.18d53f22fb64ffc9,"reason=Pulled count=1 msg=Container image ""busybox:musl"" already present on machine"
0.5716,Event,ADDED,eval-conflicts-rho020-r1-146-s5sjt.18d53f22fc97dc14,reason=Created count=1 msg=Created container: task
0.572,Event,ADDED,eval-conflicts-rho020-r1-146-s5sjt.18d53f23053d658d,reason=Started count=1 msg=Started container task
0.5722,Event,ADDED,eval-conflicts-rho020-r1-146.18d53f22db618bd6,reason=SuccessfulCreate count=1 msg=Created pod: eval-conflicts-rho020-r1-146-s5sjt
0.5727,Event,ADDED,eval-conflicts-rho020-r1-146.18d53f2894b5b80b,reason=Completed count=1 msg=Job completed
0.5729,Event,ADDED,eval-conflicts-rho020-r1-147-tv8dc.18d53f2316d8d550,reason=Scheduled count=None msg=Successfully assigned compute/eval-conflicts-rho020-r1-147-tv8dc to kind-worker3
0.5731,Event,ADDED,eval-conflicts-rho020-r1-147-tv8dc.18d53f233359744f,"reason=Pulled count=1 msg=Container image ""busybox:musl"" already present on machine"
0.5732,Event,ADDED,eval-conflicts-rho020-r1-147-tv8dc.18d53f233475fb90,reason=Created count=1 msg=Created container: task
0.5736,Event,ADDED,eval-conflicts-rho020-r1-147-tv8dc.18d53f2336e130de,reason=Started count=1 msg=Started container task
0.5738,Event,ADDED,eval-conflicts-rho020-r1-147.18d53f231618e9d7,reason=SuccessfulCreate count=1 msg=Created pod: eval-conflicts-rho020-r1-147-tv8dc
0.574,Event,ADDED,eval-conflicts-rho020-r1-147.18d53f288ba1c45b,reason=Completed count=1 msg=Job completed
0.5741,Event,ADDED,eval-conflicts-rho020-r1-148-vstdg.18d53f23552cee13,reason=Scheduled count=None msg=Successfully assigned compute/eval-conflicts-rho020-r1-148-vstdg to kind-worker
0.5743,Event,ADDED,eval-conflicts-rho020-r1-148-vstdg.18d53f2379cfd357,"reason=Pulled count=1 msg=Container image ""busybox:musl"" already present on machine"
0.5745,Event,ADDED,eval-conflicts-rho020-r1-148-vstdg.18d53f237b0adac7,reason=Created count=1 msg=Created container: task
0.5747,Event,ADDED,eval-conflicts-rho020-r1-148-vstdg.18d53f23829611c8,reason=Started count=1 msg=Started container task
0.5748,Event,ADDED,eval-conflicts-rho020-r1-148.18d53f23546c680c,reason=SuccessfulCreate count=1 msg=Created pod: eval-conflicts-rho020-r1-148-vstdg
0.575,Event,ADDED,eval-conflicts-rho020-r1-148.18d53f290d143440,reason=Completed count=1 msg=Job completed
0.5752,Event,ADDED,eval-conflicts-rho020-r1-149-sscgl.18d53f239232ce23,reason=Scheduled count=None msg=Successfully assigned compute/eval-conflicts-rho020-r1-149-sscgl to kind-worker3
0.5754,Event,ADDED,eval-conflicts-rho020-r1-149-sscgl.18d53f23b2c52364,"reason=Pulled count=1 msg=Container image ""busybox:musl"" already present on machine"
0.5757,Event,ADDED,eval-conflicts-rho020-r1-149-sscgl.18d53f23b3e2d7cc,reason=Created count=1 msg=Created container: task
0.5759,Event,ADDED,eval-conflicts-rho020-r1-149-sscgl.18d53f23c4b78dd3,reason=Started count=1 msg=Started container task
0.5761,Event,ADDED,eval-conflicts-rho020-r1-149.18d53f239173972c,reason=SuccessfulCreate count=1 msg=Created pod: eval-conflicts-rho020-r1-149-sscgl
0.5765,Event,ADDED,eval-conflicts-rho020-r1-149.18d53f292c58acca,reason=Completed count=1 msg=Job completed
0.5767,Event,ADDED,eval-conflicts-rho020-r1-150-4xd9l.18d53f23c808ed4f,"reason=FailedScheduling count=None msg=0/6 nodes are available: 1 c_wall violated: 1 conflicting context pair(s) with node memory, 5 node(s) had untolerated taint(s). no new claims to deallocate, preemption: 0/6 nodes are available: 1 No preemption victims found for incoming pod, 5 Preemption is not helpful for scheduling."
0.5769,Event,ADDED,eval-conflicts-rho020-r1-150-4xd9l.18d53f23c8899a9e,"reason=FailedScheduling count=None msg=0/6 nodes are available: 1 c_wall violated: 1 conflicting context pair(s) with node memory, 5 node(s) had untolerated taint(s). no new claims to deallocate, preemption: 0/6 nodes are available: 1 No preemption victims found for incoming pod, 5 Preemption is not helpful for scheduling."
0.5771,Event,ADDED,eval-conflicts-rho020-r1-150-4xd9l.18d53f24c565da24,reason=Scheduled count=None msg=Successfully assigned compute/eval-conflicts-rho020-r1-150-4xd9l to kind-worker2
0.5774,Event,ADDED,eval-conflicts-rho020-r1-150-4xd9l.18d53f24e29c2c25,"reason=Pulled count=1 msg=Container image ""busybox:musl"" already present on machine"
0.5776,Event,ADDED,eval-conflicts-rho020-r1-150-4xd9l.18d53f24e4032fea,reason=Created count=1 msg=Created container: task
0.5778,Event,ADDED,eval-conflicts-rho020-r1-150-4xd9l.18d53f24ea3750d8,reason=Started count=1 msg=Started container task
0.5781,Event,ADDED,eval-conflicts-rho020-r1-150.18d53f23c7c4f08d,reason=SuccessfulCreate count=1 msg=Created pod: eval-conflicts-rho020-r1-150-4xd9l
0.5784,Event,ADDED,eval-conflicts-rho020-r1-150.18d53f2a6873a92d,reason=Completed count=1 msg=Job completed
0.5786,Event,ADDED,eval-conflicts-rho020-r1-151-qvfb6.18d53f2405e8c8f5,reason=Scheduled count=None msg=Successfully assigned compute/eval-conflicts-rho020-r1-151-qvfb6 to kind-worker
0.5788,Event,ADDED,eval-conflicts-rho020-r1-151-qvfb6.18d53f243e7ffde5,"reason=Pulled count=1 msg=Container image ""busybox:musl"" already present on machine"
0.579,Event,ADDED,eval-conflicts-rho020-r1-151-qvfb6.18d53f243fcb384c,reason=Created count=1 msg=Created container: task
0.5792,Event,ADDED,eval-conflicts-rho020-r1-151-qvfb6.18d53f244cbf9b72,reason=Started count=1 msg=Started container task
0.5794,Event,ADDED,eval-conflicts-rho020-r1-151.18d53f240555c550,reason=SuccessfulCreate count=1 msg=Created pod: eval-conflicts-rho020-r1-151-qvfb6
0.5796,Event,ADDED,eval-conflicts-rho020-r1-151.18d53f29cb444ebd,reason=Completed count=1 msg=Job completed
0.5798,Event,ADDED,eval-conflicts-rho020-r1-152-sndwd.18d53f2440ccae21,reason=Scheduled count=None msg=Successfully assigned compute/eval-conflicts-rho020-r1-152-sndwd to kind-worker
0.58,Event,ADDED,eval-conflicts-rho020-r1-152-sndwd.18d53f245de1d197,"reason=Pulled count=1 msg=Container image ""busybox:musl"" already present on machine"
0.5802,Event,ADDED,eval-conflicts-rho020-r1-152-sndwd.18d53f245f000d82,reason=Created count=1 msg=Created container: task
0.5806,Event,ADDED,eval-conflicts-rho020-r1-152-sndwd.18d53f246113083d,reason=Started count=1 msg=Started container task
0.5808,Event,ADDED,eval-conflicts-rho020-r1-152.18d53f244025d53e,reason=SuccessfulCreate count=1 msg=Created pod: eval-conflicts-rho020-r1-152-sndwd
0.581,Event,ADDED,eval-conflicts-rho020-r1-152.18d53f2a0273cef5,reason=Completed count=1 msg=Job completed
0.5811,Event,ADDED,eval-conflicts-rho020-r1-153-r26sx.18d53f247bccc276,"reason=FailedScheduling count=None msg=0/6 nodes are available: 1 c_wall violated: 1 conflicting context pair(s) with node memory, 5 node(s) had untolerated taint(s). no new claims to deallocate, preemption: 0/6 nodes are available: 1 No preemption victims found for incoming pod, 5 Preemption is not helpful for scheduling."
0.5814,Event,ADDED,eval-conflicts-rho020-r1-153-r26sx.18d53f247c479bed,"reason=FailedScheduling count=None msg=0/6 nodes are available: 1 c_wall violated: 1 conflicting context pair(s) with node memory, 5 node(s) had untolerated taint(s). no new claims to deallocate, preemption: 0/6 nodes are available: 1 No preemption victims found for incoming pod, 5 Preemption is not helpful for scheduling."
0.5816,Event,ADDED,eval-conflicts-rho020-r1-153-r26sx.18d53f24c600a573,reason=Scheduled count=None msg=Successfully assigned compute/eval-conflicts-rho020-r1-153-r26sx to kind-worker2
0.5818,Event,ADDED,eval-conflicts-rho020-r1-153-r26sx.18d53f24e2b6c2d7,"reason=Pulled count=1 msg=Container image ""busybox:musl"" already present on machine"
0.5821,Event,ADDED,eval-conflicts-rho020-r1-153-r26sx.18d53f24e43b3597,reason=Created count=1 msg=Created container: task
0.5823,Event,ADDED,eval-conflicts-rho020-r1-153-r26sx.18d53f24ea3750d8,reason=Started count=1 msg=Started container task
0.5825,Event,ADDED,eval-conflicts-rho020-r1-153.18d53f247b8d3a9f,reason=SuccessfulCreate count=1 msg=Created pod: eval-conflicts-rho020-r1-153-r26sx
0.5828,Event,ADDED,eval-conflicts-rho020-r1-153.18d53f2a68b2cc3f,reason=Completed count=1 msg=Job completed
0.583,Event,ADDED,eval-conflicts-rho020-r1-154-sj7kp.18d53f24b7b7da06,reason=Scheduled count=None msg=Successfully assigned compute/eval-conflicts-rho020-r1-154-sj7kp to kind-worker
0.5831,Event,ADDED,eval-conflicts-rho020-r1-154-sj7kp.18d53f24d17982e0,"reason=Pulled count=1 msg=Container image ""busybox:musl"" already present on machine"
0.5833,Event,ADDED,eval-conflicts-rho020-r1-154-sj7kp.18d53f24d27e8534,reason=Created count=1 msg=Created container: task
0.5836,Event,ADDED,eval-conflicts-rho020-r1-154-sj7kp.18d53f24d627c15c,reason=Started count=1 msg=Started container task
0.5838,Event,ADDED,eval-conflicts-rho020-r1-154.18d53f24b70a19fd,reason=SuccessfulCreate count=1 msg=Created pod: eval-conflicts-rho020-r1-154-sj7kp
0.584,Event,ADDED,eval-conflicts-rho020-r1-154.18d53f2a84eedd6a,reason=Completed count=1 msg=Job completed
0.5841,Event,ADDED,eval-conflicts-rho020-r1-155-bs7ln.18d53f24f31770fc,reason=Scheduled count=None msg=Successfully assigned compute/eval-conflicts-rho020-r1-155-bs7ln to kind-worker2
0.5844,Event,ADDED,eval-conflicts-rho020-r1-155-bs7ln.18d53f251089d9d1,"reason=Pulled count=1 msg=Container image ""busybox:musl"" already present on machine"
0.5847,Event,ADDED,eval-conflicts-rho020-r1-155-bs7ln.18d53f2511a91849,reason=Created count=1 msg=Created container: task
0.5849,Event,ADDED,eval-conflicts-rho020-r1-155-bs7ln.18d53f2515f6f190,reason=Started count=1 msg=Started container task
0.5852,Event,ADDED,eval-conflicts-rho020-r1-155.18d53f24f1dac944,reason=SuccessfulCreate count=1 msg=Created pod: eval-conflicts-rho020-r1-155-bs7ln
0.5854,Event,ADDED,eval-conflicts-rho020-r1-155.18d53f2aa7d31869,reason=Completed count=1 msg=Job completed
0.5855,Event,ADDED,eval-conflicts-rho020-r1-156-28srv.18d53f2531f28101,reason=Scheduled count=None msg=Successfully assigned compute/eval-conflicts-rho020-r1-156-28srv to kind-worker
0.5857,Event,ADDED,eval-conflicts-rho020-r1-156-28srv.18d53f255df8f201,"reason=Pulled count=1 msg=Container image ""busybox:musl"" already present on machine"
0.586,Event,ADDED,eval-conflicts-rho020-r1-156-28srv.18d53f255f2d9744,reason=Created count=1 msg=Created container: task
0.5862,Event,ADDED,eval-conflicts-rho020-r1-156-28srv.18d53f2566e4597d,reason=Started count=1 msg=Started container task
0.5863,Event,ADDED,eval-conflicts-rho020-r1-156.18d53f2531437285,reason=SuccessfulCreate count=1 msg=Created pod: eval-conflicts-rho020-r1-156-28srv
0.5865,Event,ADDED,eval-conflicts-rho020-r1-156.18d53f2af2903c3f,reason=Completed count=1 msg=Job completed
0.5867,Event,ADDED,eval-conflicts-rho020-r1-157-jt2fj.18d53f2569ca5c87,"reason=FailedScheduling count=None msg=0/6 nodes are available: 1 c_wall violated: 1 conflicting context pair(s) with node memory, 1 c_wall violated: 2 conflicting context pair(s) with node memory, 4 node(s) had untolerated taint(s). no new claims to deallocate, preemption: 0/6 nodes are available: 2 No preemption victims found for incoming pod, 4 Preemption is not helpful for scheduling."
0.5869,Event,ADDED,eval-conflicts-rho020-r1-157-jt2fj.18d53f256a64c711,"reason=FailedScheduling count=None msg=0/6 nodes are available: 1 c_wall violated: 1 conflicting context pair(s) with node memory, 1 c_wall violated: 2 conflicting context pair(s) with node memory, 4 node(s) had untolerated taint(s). no new claims to deallocate, preemption: 0/6 nodes are available: 2 No preemption victims found for incoming pod, 4 Preemption is not helpful for scheduling."
0.5871,Event,ADDED,eval-conflicts-rho020-r1-157-jt2fj.18d53f261c4a9546,reason=Scheduled count=None msg=Successfully assigned compute/eval-conflicts-rho020-r1-157-jt2fj to kind-worker4
0.5873,Event,ADDED,eval-conflicts-rho020-r1-157-jt2fj.18d53f26358322bf,"reason=Pulled count=1 msg=Container image ""busybox:musl"" already present on machine"
0.5875,Event,ADDED,eval-conflicts-rho020-r1-157-jt2fj.18d53f26373b9d5e,reason=Created count=1 msg=Created container: task
0.5876,Event,ADDED,eval-conflicts-rho020-r1-157-jt2fj.18d53f263a583f82,reason=Started count=1 msg=Started container task
0.5878,Event,ADDED,eval-conflicts-rho020-r1-157.18d53f256958c72f,reason=SuccessfulCreate count=1 msg=Created pod: eval-conflicts-rho020-r1-157-jt2fj
0.588,Event,ADDED,eval-conflicts-rho020-r1-157.18d53f2bc45474c0,reason=Completed count=1 msg=Job completed
0.5881,Event,ADDED,eval-conflicts-rho020-r1-158-plwdv.18d53f25a64385da,reason=Scheduled count=None msg=Successfully assigned compute/eval-conflicts-rho020-r1-158-plwdv to kind-worker
0.5883,Event,ADDED,eval-conflicts-rho020-r1-158-plwdv.18d53f25c155a52c,"reason=Pulled count=1 msg=Container image ""busybox:musl"" already present on machine"
0.5885,Event,ADDED,eval-conflicts-rho020-r1-158-plwdv.18d53f25c27ee7fd,reason=Created count=1 msg=Created container: task
0.5887,Event,ADDED,eval-conflicts-rho020-r1-158-plwdv.18d53f25cc7d3b55,reason=Started count=1 msg=Started container task
0.5889,Event,ADDED,eval-conflicts-rho020-r1-158.18d53f25a54f535d,reason=SuccessfulCreate count=1 msg=Created pod: eval-conflicts-rho020-r1-158-plwdv
0.5891,Event,ADDED,eval-conflicts-rho020-r1-158.18d53f2b634ffb24,reason=Completed count=1 msg=Job completed
0.5894,Event,ADDED,eval-conflicts-rho020-r1-159-q9glq.18d53f25e14abab2,"reason=FailedScheduling count=None msg=0/6 nodes are available: 1 c_wall violated: 1 conflicting context pair(s) with node memory, 1 c_wall violated: 2 conflicting context pair(s) with node memory, 4 node(s) had untolerated taint(s). no new claims to deallocate, preemption: 0/6 nodes are available: 2 No preemption victims found for incoming pod, 4 Preemption is not helpful for scheduling."
0.5896,Event,ADDED,eval-conflicts-rho020-r1-159-q9glq.18d53f25e21023a3,"reason=FailedScheduling count=None msg=0/6 nodes are available: 1 c_wall violated: 1 conflicting context pair(s) with node memory, 1 c_wall violated: 2 conflicting context pair(s) with node memory, 4 node(s) had untolerated taint(s). no new claims to deallocate, preemption: 0/6 nodes are available: 2 No preemption victims found for incoming pod, 4 Preemption is not helpful for scheduling."
0.5897,Event,ADDED,eval-conflicts-rho020-r1-159-q9glq.18d53f261c69c07e,reason=Scheduled count=None msg=Successfully assigned compute/eval-conflicts-rho020-r1-159-q9glq to kind-worker4
0.5901,Event,ADDED,eval-conflicts-rho020-r1-159-q9glq.18d53f2636058d2b,"reason=Pulled count=1 msg=Container image ""busybox:musl"" already present on machine"
0.5903,Event,ADDED,eval-conflicts-rho020-r1-159-q9glq.18d53f26377eecc9,reason=Created count=1 msg=Created container: task
0.5905,Event,ADDED,eval-conflicts-rho020-r1-159-q9glq.18d53f263a583f51,reason=Started count=1 msg=Started container task
0.5908,Event,ADDED,eval-conflicts-rho020-r1-159.18d53f25e0ce5a52,reason=SuccessfulCreate count=1 msg=Created pod: eval-conflicts-rho020-r1-159-q9glq
0.5909,Event,ADDED,eval-conflicts-rho020-r1-159.18d53f2bc4349105,reason=Completed count=1 msg=Job completed
0.5911,Event,ADDED,eval-conflicts-rho020-r1-160-xrs75.18d53f261fef0b61,reason=Scheduled count=None msg=Successfully assigned compute/eval-conflicts-rho020-r1-160-xrs75 to kind-worker4
0.5912,Event,ADDED,eval-conflicts-rho020-r1-160-xrs75.18d53f2639dc8173,"reason=Pulled count=1 msg=Container image ""busybox:musl"" already present on machine"
0.5914,Event,ADDED,eval-conflicts-rho020-r1-160-xrs75.18d53f263b2a04d5,reason=Created count=1 msg=Created container: task
0.5917,Event,ADDED,eval-conflicts-rho020-r1-160-xrs75.18d53f2641aaf86d,reason=Started count=1 msg=Started container task
0.5919,Event,ADDED,eval-conflicts-rho020-r1-160.18d53f261e60e20f,reason=SuccessfulCreate count=1 msg=Created pod: eval-conflicts-rho020-r1-160-xrs75
0.592,Event,ADDED,eval-conflicts-rho020-r1-160.18d53f2bc450cd29,reason=Completed count=1 msg=Job completed
0.5922,Event,ADDED,eval-conflicts-rho020-r1-161-zrm58.18d53f265a179c18,reason=Scheduled count=None msg=Successfully assigned compute/eval-conflicts-rho020-r1-161-zrm58 to kind-worker2
0.5924,Event,ADDED,eval-conflicts-rho020-r1-161-zrm58.18d53f26737f15ef,"reason=Pulled count=1 msg=Container image ""busybox:musl"" already present on machine"
0.5926,Event,ADDED,eval-conflicts-rho020-r1-161-zrm58.18d53f2674ade251,reason=Created count=1 msg=Created container: task
0.5929,Event,ADDED,eval-conflicts-rho020-r1-161-zrm58.18d53f2678d18e37,reason=Started count=1 msg=Started container task
