t_recv,kind,type,name,detail
0.0943,TaskRequest,ADDED,eval-sanitize-20-r3-000,phase=None job=None
0.0951,Event,ADDED,eval-sanitize-20-r1-012-m6skw.18d41aa0e5463ab7,"reason=FailedScheduling count=None msg=0/6 nodes are available: 1 node(s) had untolerated taint(s), 2 c_wall violated: 2 conflicting context pair(s) with node memory, 3 c_wall violated: 1 conflicting context pair(s) with node memory. no new claims to deallocate, preemption: 0/6 nodes are available: 1 Preemption is not helpful for scheduling, 5 No preemption victims found for incoming pod."
0.0989,Node,ADDED,kind-control-plane,taints=1
0.0993,Event,ADDED,eval-sanitize-20-r1-012-m6skw.18d41aa167dc56a0,"reason=FailedScheduling count=None msg=0/6 nodes are available: 1 c_wall violated: 2 conflicting context pair(s) with node memory, 2 node(s) had untolerated taint(s), 3 c_wall violated: 1 conflicting context pair(s) with node memory. no new claims to deallocate, preemption: 0/6 nodes are available: 2 Preemption is not helpful for scheduling, 4 No preemption victims found for incoming pod."
0.0995,Event,ADDED,eval-sanitize-20-r1-012-m6skw.18d41aa197e5e65e,"reason=FailedScheduling count=None msg=0/6 nodes are available: 1 c_wall violated: 2 conflicting context pair(s) with node memory, 2 c_wall violated: 1 conflicting context pair(s) with node memory, 3 node(s) had untolerated taint(s). no new claims to deallocate, preemption: 0/6 nodes are available: 3 No preemption victims found for incoming pod, 3 Preemption is not helpful for scheduling."
0.0997,Event,ADDED,eval-sanitize-20-r1-012-m6skw.18d41aa1b3948e66,"reason=FailedScheduling count=None msg=0/6 nodes are available: 2 c_wall violated: 1 conflicting context pair(s) with node memory, 4 node(s) had untolerated taint(s). no new claims to deallocate, preemption: 0/6 nodes are available: 2 No preemption victims found for incoming pod, 4 Preemption is not helpful for scheduling."
0.1001,Event,ADDED,eval-sanitize-20-r1-012-m6skw.18d41aa200c7d429,"reason=FailedScheduling count=None msg=0/6 nodes are available: 1 c_wall violated: 1 conflicting context pair(s) with node memory, 5 node(s) had untolerated taint(s). no new claims to deallocate, preemption: 0/6 nodes are available: 1 No preemption victims found for incoming pod, 5 Preemption is not helpful for scheduling."
0.1003,Event,ADDED,eval-sanitize-20-r1-016-rhx4s.18d41aa1ca08d5b7,"reason=FailedScheduling count=None msg=0/6 nodes are available: 2 c_wall violated: 1 conflicting context pair(s) with node memory, 4 node(s) had untolerated taint(s). no new claims to deallocate, preemption: 0/6 nodes are available: 2 No preemption victims found for incoming pod, 4 Preemption is not helpful for scheduling."
0.1007,Event,ADDED,eval-sanitize-20-r1-016-rhx4s.18d41aa200eb824c,"reason=FailedScheduling count=None msg=0/6 nodes are available: 1 c_wall violated: 1 conflicting context pair(s) with node memory, 5 node(s) had untolerated taint(s). no new claims to deallocate, preemption: 0/6 nodes are available: 1 No preemption victims found for incoming pod, 5 Preemption is not helpful for scheduling."
0.1009,Event,ADDED,eval-sanitize-20-r1-019-dl74d.18d41aa624594873,"reason=FailedScheduling count=None msg=0/6 nodes are available: 1 c_wall violated: 2 conflicting context pair(s) with node memory, 5 node(s) had untolerated taint(s). no new claims to deallocate, preemption: 0/6 nodes are available: 1 No preemption victims found for incoming pod, 5 Preemption is not helpful for scheduling."
0.1011,Event,ADDED,eval-sanitize-20-r1-021-77dzv.18d41aa6298ecc45,"reason=FailedScheduling count=None msg=0/6 nodes are available: 1 c_wall violated: 2 conflicting context pair(s) with node memory, 5 node(s) had untolerated taint(s). no new claims to deallocate, preemption: 0/6 nodes are available: 1 No preemption victims found for incoming pod, 5 Preemption is not helpful for scheduling."
0.1024,Node,ADDED,kind-worker,taints=0
0.1027,Event,ADDED,eval-sanitize-20-r1-021-77dzv.18d41aa657834e4d,"reason=FailedScheduling count=None msg=0/6 nodes are available: 2 c_wall violated: 2 conflicting context pair(s) with node memory, 4 node(s) had untolerated taint(s). no new claims to deallocate, preemption: 0/6 nodes are available: 2 No preemption victims found for incoming pod, 4 Preemption is not helpful for scheduling."
0.1029,Event,ADDED,eval-sanitize-20-r1-021-77dzv.18d41aa693430262,"reason=FailedScheduling count=None msg=0/6 nodes are available: 1 c_wall violated: 1 conflicting context pair(s) with node memory, 2 c_wall violated: 2 conflicting context pair(s) with node memory, 3 node(s) had untolerated taint(s). no new claims to deallocate, preemption: 0/6 nodes are available: 3 No preemption victims found for incoming pod, 3 Preemption is not helpful for scheduling."
0.1031,Event,ADDED,eval-sanitize-20-r1-022-qr2sk.18d41aa629c0853a,"reason=FailedScheduling count=None msg=0/6 nodes are available: 1 c_wall violated: 2 conflicting context pair(s) with node memory, 5 node(s) had untolerated taint(s). no new claims to deallocate, preemption: 0/6 nodes are available: 1 No preemption victims found for incoming pod, 5 Preemption is not helpful for scheduling."
0.1032,TaskRequest,MODIFIED,eval-sanitize-20-r3-000,phase=Pending job=None
0.1035,Event,ADDED,eval-sanitize-20-r1-023-lhw8g.18d41aa629f759a2,"reason=FailedScheduling count=None msg=0/6 nodes are available: 1 c_wall violated: 1 conflicting context pair(s) with node memory, 5 node(s) had untolerated taint(s). no new claims to deallocate, preemption: 0/6 nodes are available: 1 No preemption victims found for incoming pod, 5 Preemption is not helpful for scheduling."
0.1037,Event,ADDED,eval-sanitize-20-r1-024-jjnk6.18d41aa62a2b7de3,"reason=FailedScheduling count=None msg=0/6 nodes are available: 1 c_wall violated: 2 conflicting context pair(s) with node memory, 5 node(s) had untolerated taint(s). no new claims to deallocate, preemption: 0/6 nodes are available: 1 No preemption victims found for incoming pod, 5 Preemption is not helpful for scheduling."
0.1039,Event,ADDED,eval-sanitize-20-r1-032-v889x.18d41aa62ae9127b,"reason=FailedScheduling count=None msg=0/6 nodes are available: 1 c_wall violated: 2 conflicting context pair(s) with node memory, 5 node(s) had untolerated taint(s). no new claims to deallocate, preemption: 0/6 nodes are available: 1 No preemption victims found for incoming pod, 5 Preemption is not helpful for scheduling."
0.105,Node,ADDED,kind-worker2,taints=0
0.1054,Event,ADDED,eval-sanitize-20-r1-034-48s2k.18d41aa62b1431af,"reason=FailedScheduling count=None msg=0/6 nodes are available: 1 c_wall violated: 2 conflicting context pair(s) with node memory, 5 node(s) had untolerated taint(s). no new claims to deallocate, preemption: 0/6 nodes are available: 1 No preemption victims found for incoming pod, 5 Preemption is not helpful for scheduling."
0.1056,Event,ADDED,eval-sanitize-20-r1-034-48s2k.18d41aa6635bba0d,"reason=FailedScheduling count=None msg=0/6 nodes are available: 2 c_wall violated: 2 conflicting context pair(s) with node memory, 4 node(s) had untolerated taint(s). no new claims to deallocate, preemption: 0/6 nodes are available: 2 No preemption victims found for incoming pod, 4 Preemption is not helpful for scheduling."
0.1058,Event,ADDED,eval-sanitize-20-r1-034-48s2k.18d41aa68dbd71c5,"reason=FailedScheduling count=None msg=0/6 nodes are available: 1 c_wall violated: 1 conflicting context pair(s) with node memory, 2 c_wall violated: 2 conflicting context pair(s) with node memory, 3 node(s) had untolerated taint(s). no new claims to deallocate, preemption: 0/6 nodes are available: 3 No preemption victims found for incoming pod, 3 Preemption is not helpful for scheduling."
0.1061,Event,ADDED,eval-sanitize-20-r1-035-sj97h.18d41aa637b15ea1,"reason=FailedScheduling count=None msg=0/6 nodes are available: 1 c_wall violated: 2 conflicting context pair(s) with node memory, 5 node(s) had untolerated taint(s). no new claims to deallocate, preemption: 0/6 nodes are available: 1 No preemption victims found for incoming pod, 5 Preemption is not helpful for scheduling."
0.1063,Event,ADDED,eval-sanitize-20-r1-035-sj97h.18d41aa65348362d,"reason=FailedScheduling count=None msg=0/6 nodes are available: 2 c_wall violated: 2 conflicting context pair(s) with node memory, 4 node(s) had untolerated taint(s). no new claims to deallocate, preemption: 0/6 nodes are available: 2 No preemption victims found for incoming pod, 4 Preemption is not helpful for scheduling."
0.1074,Node,ADDED,kind-worker3,taints=0
0.1078,Event,ADDED,eval-sanitize-20-r1-036-qpnd7.18d41aa6882ce074,"reason=FailedScheduling count=None msg=0/6 nodes are available: 1 c_wall violated: 1 conflicting context pair(s) with node memory, 2 c_wall violated: 2 conflicting context pair(s) with node memory, 3 node(s) had untolerated taint(s). no new claims to deallocate, preemption: 0/6 nodes are available: 3 No preemption victims found for incoming pod, 3 Preemption is not helpful for scheduling."
0.108,Event,ADDED,eval-sanitize-20-r1-055-bzm98.18d41aab0b863768,"reason=FailedScheduling count=None msg=0/6 nodes are available: 3 c_wall violated: 1 conflicting context pair(s) with node memory, 3 node(s) had untolerated taint(s). no new claims to deallocate, preemption: 0/6 nodes are available: 3 No preemption victims found for incoming pod, 3 Preemption is not helpful for scheduling."
0.1082,Event,ADDED,eval-sanitize-20-r1-055-bzm98.18d41aab1138d594,"reason=FailedScheduling count=None msg=0/6 nodes are available: 2 c_wall violated: 1 conflicting context pair(s) with node memory, 4 node(s) had untolerated taint(s). no new claims to deallocate, preemption: 0/6 nodes are available: 2 No preemption victims found for incoming pod, 4 Preemption is not helpful for scheduling."
0.1085,Event,ADDED,eval-sanitize-20-r1-055-bzm98.18d41aab609283a9,"reason=FailedScheduling count=None msg=0/6 nodes are available: 1 c_wall violated: 1 conflicting context pair(s) with node memory, 5 node(s) had untolerated taint(s). no new claims to deallocate, preemption: 0/6 nodes are available: 1 No preemption victims found for incoming pod, 5 Preemption is not helpful for scheduling."
0.1087,Event,ADDED,eval-sanitize-20-r1-056-sqhx4.18d41aab2a9edaa1,"reason=FailedScheduling count=None msg=0/6 nodes are available: 2 c_wall violated: 1 conflicting context pair(s) with node memory, 4 node(s) had untolerated taint(s). no new claims to deallocate, preemption: 0/6 nodes are available: 2 No preemption victims found for incoming pod, 4 Preemption is not helpful for scheduling."
0.1089,Event,ADDED,eval-sanitize-20-r1-056-sqhx4.18d41aab606b2c56,"reason=FailedScheduling count=None msg=0/6 nodes are available: 1 c_wall violated: 1 conflicting context pair(s) with node memory, 5 node(s) had untolerated taint(s). no new claims to deallocate, preemption: 0/6 nodes are available: 1 No preemption victims found for incoming pod, 5 Preemption is not helpful for scheduling."
0.1091,Event,ADDED,eval-sanitize-20-r1-059-vz4jf.18d41aaf95e3cb25,"reason=FailedScheduling count=None msg=0/6 nodes are available: 1 c_wall violated: 2 conflicting context pair(s) with node memory, 5 node(s) had untolerated taint(s). no new claims to deallocate, preemption: 0/6 nodes are available: 1 No preemption victims found for incoming pod, 5 Preemption is not helpful for scheduling."
0.1094,Event,ADDED,eval-sanitize-20-r1-061-sjpk6.18d41aaf96151266,"reason=FailedScheduling count=None msg=0/6 nodes are available: 1 c_wall violated: 2 conflicting context pair(s) with node memory, 5 node(s) had untolerated taint(s). no new claims to deallocate, preemption: 0/6 nodes are available: 1 No preemption victims found for incoming pod, 5 Preemption is not helpful for scheduling."
0.1096,Event,ADDED,eval-sanitize-20-r1-062-j6dn5.18d41aaf964b0a8b,"reason=FailedScheduling count=None msg=0/6 nodes are available: 1 c_wall violated: 2 conflicting context pair(s) with node memory, 5 node(s) had untolerated taint(s). no new claims to deallocate, preemption: 0/6 nodes are available: 1 No preemption victims found for incoming pod, 5 Preemption is not helpful for scheduling."
0.1098,Event,ADDED,eval-sanitize-20-r1-069-dxq4t.18d41aaf90cc68df,"reason=FailedScheduling count=None msg=0/6 nodes are available: 1 c_wall violated: 2 conflicting context pair(s) with node memory, 5 node(s) had untolerated taint(s). no new claims to deallocate, preemption: 0/6 nodes are available: 1 No preemption victims found for incoming pod, 5 Preemption is not helpful for scheduling."
0.11,Event,ADDED,eval-sanitize-20-r1-070-c8j2t.18d41aaf9104acd4,"reason=FailedScheduling count=None msg=0/6 nodes are available: 1 c_wall violated: 2 conflicting context pair(s) with node memory, 5 node(s) had untolerated taint(s). no new claims to deallocate, preemption: 0/6 nodes are available: 1 No preemption victims found for incoming pod, 5 Preemption is not helpful for scheduling."
0.1101,Event,ADDED,eval-sanitize-20-r1-071-b576n.18d41aaf91415639,"reason=FailedScheduling count=None msg=0/6 nodes are available: 1 c_wall violated: 2 conflicting context pair(s) with node memory, 5 node(s) had untolerated taint(s). no new claims to deallocate, preemption: 0/6 nodes are available: 1 No preemption victims found for incoming pod, 5 Preemption is not helpful for scheduling."
0.1113,Node,ADDED,kind-worker4,taints=0
0.1116,Event,ADDED,eval-sanitize-20-r1-072-q7qwt.18d41aaf93bbadfc,"reason=FailedScheduling count=None msg=0/6 nodes are available: 1 c_wall violated: 2 conflicting context pair(s) with node memory, 5 node(s) had untolerated taint(s). no new claims to deallocate, preemption: 0/6 nodes are available: 1 No preemption victims found for incoming pod, 5 Preemption is not helpful for scheduling."
0.1118,Event,ADDED,eval-sanitize-20-r1-074-4hsdp.18d41aaf95a16ace,"reason=FailedScheduling count=None msg=0/6 nodes are available: 1 c_wall violated: 2 conflicting context pair(s) with node memory, 5 node(s) had untolerated taint(s). no new claims to deallocate, preemption: 0/6 nodes are available: 1 No preemption victims found for incoming pod, 5 Preemption is not helpful for scheduling."
0.112,Event,ADDED,eval-sanitize-20-r1-096-52wjb.18d41ab48f9a3bfd,"reason=FailedScheduling count=None msg=0/6 nodes are available: 1 c_wall violated: 1 conflicting context pair(s) with node memory, 1 c_wall violated: 2 conflicting context pair(s) with node memory, 4 node(s) had untolerated taint(s). no new claims to deallocate, preemption: 0/6 nodes are available: 2 No preemption victims found for incoming pod, 4 Preemption is not helpful for scheduling."
0.1122,Event,ADDED,eval-sanitize-20-r1-096-52wjb.18d41ab4bda99bd1,"reason=FailedScheduling count=None msg=0/6 nodes are available: 1 c_wall violated: 2 conflicting context pair(s) with node memory, 5 node(s) had untolerated taint(s). no new claims to deallocate, preemption: 0/6 nodes are available: 1 No preemption victims found for incoming pod, 5 Preemption is not helpful for scheduling."
0.1124,Event,ADDED,eval-sanitize-20-r1-097-2bqqh.18d41ab4c56ac95c,"reason=FailedScheduling count=None msg=0/6 nodes are available: 1 c_wall violated: 2 conflicting context pair(s) with node memory, 5 node(s) had untolerated taint(s). no new claims to deallocate, preemption: 0/6 nodes are available: 1 No preemption victims found for incoming pod, 5 Preemption is not helpful for scheduling."
0.1127,Event,ADDED,eval-sanitize-20-r1-098-k4zs9.18d41ab8fbf63205,"reason=FailedScheduling count=None msg=0/6 nodes are available: 1 c_wall violated: 1 conflicting context pair(s) with node memory, 5 node(s) had untolerated taint(s). no new claims to deallocate, preemption: 0/6 nodes are available: 1 No preemption victims found for incoming pod, 5 Preemption is not helpful for scheduling."
0.1129,Event,ADDED,eval-sanitize-20-r1-099-2ss89.18d41ab8fc2d610c,"reason=FailedScheduling count=None msg=0/6 nodes are available: 1 c_wall violated: 1 conflicting context pair(s) with node memory, 5 node(s) had untolerated taint(s). no new claims to deallocate, preemption: 0/6 nodes are available: 1 No preemption victims found for incoming pod, 5 Preemption is not helpful for scheduling."
0.1141,Node,ADDED,kind-worker5,taints=0
0.1196,Job,ADDED,eval-sanitize-20-r3-000,
0.1246,TaskRequest,MODIFIED,eval-sanitize-20-r3-000,phase=Scheduled job=None
0.1313,Job,MODIFIED,eval-sanitize-20-r3-000,
0.1334,Pod,ADDED,eval-sanitize-20-r3-000-2x82f,phase=Pending node=None
0.1479,Pod,MODIFIED,eval-sanitize-20-r3-000-2x82f,phase=Pending node=kind-worker
0.1496,TaskRequest,MODIFIED,eval-sanitize-20-r3-000,phase=Scheduled job=None
0.1582,Node,MODIFIED,kind-worker,taints=0
0.1598,Pod,MODIFIED,eval-sanitize-20-r3-000-2x82f,phase=Pending node=kind-worker
0.1712,Node,MODIFIED,kind-worker,taints=0
0.1751,Event,ADDED,eval-sanitize-20-r3-000.18d41b278939adfb,reason=SuccessfulCreate count=1 msg=Created pod: eval-sanitize-20-r3-000-2x82f
0.1753,Event,ADDED,eval-sanitize-20-r3-000-2x82f.18d41b278a0eda09,reason=Scheduled count=None msg=Successfully assigned compute/eval-sanitize-20-r3-000-2x82f to kind-worker
0.6804,Event,ADDED,eval-sanitize-20-r3-000-2x82f.18d41b27a996433d,"reason=Pulled count=1 msg=Container image ""busybox:musl"" already present on machine"
0.6976,Event,ADDED,eval-sanitize-20-r3-000-2x82f.18d41b27aaa3e317,reason=Created count=1 msg=Created container: task
0.8403,Event,ADDED,eval-sanitize-20-r3-000-2x82f.18d41b27b30fe368,reason=Started count=1 msg=Started container task
1.0779,TaskRequest,ADDED,eval-sanitize-20-r3-001,phase=None job=None
1.0816,TaskRequest,MODIFIED,eval-sanitize-20-r3-001,phase=Pending job=None
1.0989,Job,ADDED,eval-sanitize-20-r3-001,
1.1055,Pod,ADDED,eval-sanitize-20-r3-001-zqtnq,phase=Pending node=None
1.1068,TaskRequest,MODIFIED,eval-sanitize-20-r3-001,phase=Scheduled job=None
1.1078,Job,MODIFIED,eval-sanitize-20-r3-001,
1.1105,Event,ADDED,eval-sanitize-20-r3-001.18d41b27c32573bd,reason=SuccessfulCreate count=1 msg=Created pod: eval-sanitize-20-r3-001-zqtnq
1.116,TaskRequest,MODIFIED,eval-sanitize-20-r3-001,phase=Scheduled job=None
1.1239,Pod,MODIFIED,eval-sanitize-20-r3-001-zqtnq,phase=Pending node=kind-worker5
1.1273,Event,ADDED,eval-sanitize-20-r3-001-zqtnq.18d41b27c43caf51,reason=Scheduled count=None msg=Successfully assigned compute/eval-sanitize-20-r3-001-zqtnq to kind-worker5
1.1336,Pod,MODIFIED,eval-sanitize-20-r3-001-zqtnq,phase=Pending node=kind-worker5
1.1361,Node,MODIFIED,kind-worker5,taints=0
1.1394,Job,MODIFIED,eval-sanitize-20-r3-000,
1.1463,Node,MODIFIED,kind-worker5,taints=0
1.148,Job,MODIFIED,eval-sanitize-20-r3-000,
1.6287,Pod,MODIFIED,eval-sanitize-20-r3-000-2x82f,phase=Running node=kind-worker
1.6446,Event,ADDED,eval-sanitize-20-r3-001-zqtnq.18d41b27e3090476,"reason=Pulled count=1 msg=Container image ""busybox:musl"" already present on machine"
1.6644,Event,ADDED,eval-sanitize-20-r3-001-zqtnq.18d41b27e43a4e20,reason=Created count=1 msg=Created container: task
1.8067,Event,ADDED,eval-sanitize-20-r3-001-zqtnq.18d41b27ecb4fb17,reason=Started count=1 msg=Started container task
2.0142,TaskRequest,ADDED,eval-sanitize-20-r3-002,phase=None job=None
2.0187,TaskRequest,MODIFIED,eval-sanitize-20-r3-002,phase=Pending job=None
2.0356,Pod,MODIFIED,eval-sanitize-20-r3-001-zqtnq,phase=Running node=kind-worker5
2.037,Job,ADDED,eval-sanitize-20-r3-002,
2.0438,Pod,ADDED,eval-sanitize-20-r3-002-6p6k5,phase=Pending node=None
2.0441,TaskRequest,MODIFIED,eval-sanitize-20-r3-002,phase=Scheduled job=None
2.048,Job,MODIFIED,eval-sanitize-20-r3-002,
2.0501,Event,ADDED,eval-sanitize-20-r3-002.18d41b27fb187275,reason=SuccessfulCreate count=1 msg=Created pod: eval-sanitize-20-r3-002-6p6k5
2.0524,TaskRequest,MODIFIED,eval-sanitize-20-r3-002,phase=Scheduled job=None
2.0617,Pod,MODIFIED,eval-sanitize-20-r3-002-6p6k5,phase=Pending node=kind-worker3
2.0681,Event,ADDED,eval-sanitize-20-r3-002-6p6k5.18d41b27fc26080d,reason=Scheduled count=None msg=Successfully assigned compute/eval-sanitize-20-r3-002-6p6k5 to kind-worker3
2.0724,Node,MODIFIED,kind-worker3,taints=0
2.0768,Pod,MODIFIED,eval-sanitize-20-r3-002-6p6k5,phase=Pending node=kind-worker3
2.0837,Node,MODIFIED,kind-worker3,taints=0
2.2185,Job,MODIFIED,eval-sanitize-20-r3-001,
2.2207,Job,MODIFIED,eval-sanitize-20-r3-000,
2.23,Job,MODIFIED,eval-sanitize-20-r3-001,
2.232,Job,MODIFIED,eval-sanitize-20-r3-000,
2.5551,Event,ADDED,eval-sanitize-20-r3-002-6p6k5.18d41b281941afaf,"reason=Pulled count=1 msg=Container image ""busybox:musl"" already present on machine"
2.5738,Event,ADDED,eval-sanitize-20-r3-002-6p6k5.18d41b281a6b48f4,reason=Created count=1 msg=Created container: task
2.7165,Event,ADDED,eval-sanitize-20-r3-002-6p6k5.18d41b2822e24bd0,reason=Started count=1 msg=Started container task
3.0329,TaskRequest,ADDED,eval-sanitize-20-r3-003,phase=None job=None
3.0366,TaskRequest,MODIFIED,eval-sanitize-20-r3-003,phase=Pending job=None
3.0499,Job,MODIFIED,eval-sanitize-20-r3-002,
3.0516,Job,ADDED,eval-sanitize-20-r3-003,
3.0583,Pod,ADDED,eval-sanitize-20-r3-003-wh2ts,phase=Pending node=None
3.0587,TaskRequest,MODIFIED,eval-sanitize-20-r3-003,phase=Scheduled job=None
3.0613,Job,MODIFIED,eval-sanitize-20-r3-003,
3.0646,Event,ADDED,eval-sanitize-20-r3-003.18d41b28378ebe87,reason=SuccessfulCreate count=1 msg=Created pod: eval-sanitize-20-r3-003-wh2ts
3.0665,TaskRequest,MODIFIED,eval-sanitize-20-r3-003,phase=Scheduled job=None
3.0726,Job,MODIFIED,eval-sanitize-20-r3-002,
3.0801,Pod,MODIFIED,eval-sanitize-20-r3-003-wh2ts,phase=Pending node=kind-worker3
3.0857,Event,ADDED,eval-sanitize-20-r3-003-wh2ts.18d41b2838d8db15,reason=Scheduled count=None msg=Successfully assigned compute/eval-sanitize-20-r3-003-wh2ts to kind-worker3
3.0901,Node,MODIFIED,kind-worker3,taints=0
3.0922,Pod,MODIFIED,eval-sanitize-20-r3-003-wh2ts,phase=Pending node=kind-worker3
3.1006,Node,MODIFIED,kind-worker3,taints=0
3.5643,Pod,MODIFIED,eval-sanitize-20-r3-002-6p6k5,phase=Running node=kind-worker3
3.567,Event,ADDED,eval-sanitize-20-r3-003-wh2ts.18d41b2855a42442,"reason=Pulled count=1 msg=Container image ""busybox:musl"" already present on machine"
3.5858,Event,ADDED,eval-sanitize-20-r3-003-wh2ts.18d41b2856ccfee5,reason=Created count=1 msg=Created container: task
3.6455,Event,ADDED,eval-sanitize-20-r3-003-wh2ts.18d41b285a52daaf,reason=Started count=1 msg=Started container task
4.0144,TaskRequest,ADDED,eval-sanitize-20-r3-004,phase=None job=None
4.0186,TaskRequest,MODIFIED,eval-sanitize-20-r3-004,phase=Pending job=None
4.0347,Job,ADDED,eval-sanitize-20-r3-004,
4.0413,Pod,ADDED,eval-sanitize-20-r3-004-2jl8f,phase=Pending node=None
4.0437,Job,MODIFIED,eval-sanitize-20-r3-004,
4.0439,TaskRequest,MODIFIED,eval-sanitize-20-r3-004,phase=Scheduled job=None
4.0478,Event,ADDED,eval-sanitize-20-r3-004.18d41b287226be70,reason=SuccessfulCreate count=1 msg=Created pod: eval-sanitize-20-r3-004-2jl8f
4.0519,TaskRequest,MODIFIED,eval-sanitize-20-r3-004,phase=Scheduled job=None
4.0546,Job,MODIFIED,eval-sanitize-20-r3-002,
4.0624,Pod,MODIFIED,eval-sanitize-20-r3-004-2jl8f,phase=Pending node=kind-worker2
4.0644,Job,MODIFIED,eval-sanitize-20-r3-003,
4.0653,Job,MODIFIED,eval-sanitize-20-r3-002,
4.0672,Event,ADDED,eval-sanitize-20-r3-004-2jl8f.18d41b28735f4aad,reason=Scheduled count=None msg=Successfully assigned compute/eval-sanitize-20-r3-004-2jl8f to kind-worker2
4.0735,Node,MODIFIED,kind-worker2,taints=0
4.0758,Pod,MODIFIED,eval-sanitize-20-r3-004-2jl8f,phase=Pending node=kind-worker2
4.0765,Job,MODIFIED,eval-sanitize-20-r3-003,
4.0834,Node,MODIFIED,kind-worker2,taints=0
4.4597,Pod,MODIFIED,eval-sanitize-20-r3-003-wh2ts,phase=Running node=kind-worker3
4.5974,Event,ADDED,eval-sanitize-20-r3-004-2jl8f.18d41b289309d108,"reason=Pulled count=1 msg=Container image ""busybox:musl"" already present on machine"
4.6157,Event,ADDED,eval-sanitize-20-r3-004-2jl8f.18d41b28942b58ad,reason=Created count=1 msg=Created container: task
4.7881,Event,ADDED,eval-sanitize-20-r3-004-2jl8f.18d41b289b75781a,reason=Started count=1 msg=Started container task
4.9929,Pod,MODIFIED,eval-sanitize-20-r3-004-2jl8f,phase=Running node=kind-worker2
5.0079,TaskRequest,ADDED,eval-sanitize-20-r3-005,phase=None job=None
5.0116,TaskRequest,MODIFIED,eval-sanitize-20-r3-005,phase=Pending job=None
5.0278,Job,ADDED,eval-sanitize-20-r3-005,
5.0342,Pod,ADDED,eval-sanitize-20-r3-005-6gx5c,phase=Pending node=None
5.0343,TaskRequest,MODIFIED,eval-sanitize-20-r3-005,phase=Scheduled job=None
5.037,Job,MODIFIED,eval-sanitize-20-r3-005,
5.0399,Event,ADDED,eval-sanitize-20-r3-005.18d41b28ad53a49e,reason=SuccessfulCreate count=1 msg=Created pod: eval-sanitize-20-r3-005-6gx5c
5.0422,TaskRequest,MODIFIED,eval-sanitize-20-r3-005,phase=Scheduled job=None
5.0467,Job,MODIFIED,eval-sanitize-20-r3-004,
5.0554,Job,MODIFIED,eval-sanitize-20-r3-004,
5.0573,Pod,MODIFIED,eval-sanitize-20-r3-005-6gx5c,phase=Pending node=kind-worker3
5.0619,Event,ADDED,eval-sanitize-20-r3-005-6gx5c.18d41b28aeb705db,reason=Scheduled count=None msg=Successfully assigned compute/eval-sanitize-20-r3-005-6gx5c to kind-worker3
5.0677,Pod,MODIFIED,eval-sanitize-20-r3-005-6gx5c,phase=Pending node=kind-worker3
5.0697,Job,MODIFIED,eval-sanitize-20-r3-003,
5.0785,Job,MODIFIED,eval-sanitize-20-r3-003,
5.4805,Event,ADDED,eval-sanitize-20-r3-005-6gx5c.18d41b28c7ac3fcb,"reason=Pulled count=1 msg=Container image ""busybox:musl"" already present on machine"
5.4993,Event,ADDED,eval-sanitize-20-r3-005-6gx5c.18d41b28c8cac173,reason=Created count=1 msg=Created container: task
5.6396,Event,ADDED,eval-sanitize-20-r3-005-6gx5c.18d41b28d122ba92,reason=Started count=1 msg=Started container task
6.0324,TaskRequest,ADDED,eval-sanitize-20-r3-006,phase=None job=None
6.0365,TaskRequest,MODIFIED,eval-sanitize-20-r3-006,phase=Pending job=None
6.0412,Job,MODIFIED,eval-sanitize-20-r3-005,
6.0512,Job,ADDED,eval-sanitize-20-r3-006,
6.0576,Pod,ADDED,eval-sanitize-20-r3-006-wc75b,phase=Pending node=None
6.0577,TaskRequest,MODIFIED,eval-sanitize-20-r3-006,phase=Scheduled job=None
6.0604,Job,MODIFIED,eval-sanitize-20-r3-006,
6.0629,Event,ADDED,eval-sanitize-20-r3-006.18d41b28ea513325,reason=SuccessfulCreate count=1 msg=Created pod: eval-sanitize-20-r3-006-wc75b
6.0643,TaskRequest,MODIFIED,eval-sanitize-20-r3-006,phase=Scheduled job=None
6.0674,Job,MODIFIED,eval-sanitize-20-r3-005,
6.0801,Pod,MODIFIED,eval-sanitize-20-r3-006-wc75b,phase=Pending node=kind-worker4
6.0844,Event,ADDED,eval-sanitize-20-r3-006-wc75b.18d41b28eba9c443,reason=Scheduled count=None msg=Successfully assigned compute/eval-sanitize-20-r3-006-wc75b to kind-worker4
6.0893,Node,MODIFIED,kind-worker4,taints=0
6.0909,Pod,MODIFIED,eval-sanitize-20-r3-006-wc75b,phase=Pending node=kind-worker4
6.0989,Node,MODIFIED,kind-worker4,taints=0
6.5009,Pod,MODIFIED,eval-sanitize-20-r3-005-6gx5c,phase=Running node=kind-worker3
6.5987,Event,ADDED,eval-sanitize-20-r3-006-wc75b.18d41b290a424bf7,"reason=Pulled count=1 msg=Container image ""busybox:musl"" already present on machine"
6.6141,Event,ADDED,eval-sanitize-20-r3-006-wc75b.18d41b290b4d4255,reason=Created count=1 msg=Created container: task
6.7535,Event,ADDED,eval-sanitize-20-r3-006-wc75b.18d41b291399ef66,reason=Started count=1 msg=Started container task
6.8907,Pod,MODIFIED,eval-sanitize-20-r3-006-wc75b,phase=Running node=kind-worker4
7.0893,TaskRequest,ADDED,eval-sanitize-20-r3-007,phase=None job=None
7.0923,Job,MODIFIED,eval-sanitize-20-r3-005,
7.0931,Job,MODIFIED,eval-sanitize-20-r3-006,
7.0932,TaskRequest,MODIFIED,eval-sanitize-20-r3-007,phase=Pending job=None
7.1072,Job,ADDED,eval-sanitize-20-r3-007,
7.1135,Pod,ADDED,eval-sanitize-20-r3-007-rbhj9,phase=Pending node=None
7.116,Job,MODIFIED,eval-sanitize-20-r3-007,
7.1161,TaskRequest,MODIFIED,eval-sanitize-20-r3-007,phase=Scheduled job=None
7.1184,Event,ADDED,eval-sanitize-20-r3-007.18d41b292947651c,reason=SuccessfulCreate count=1 msg=Created pod: eval-sanitize-20-r3-007-rbhj9
7.1236,TaskRequest,MODIFIED,eval-sanitize-20-r3-007,phase=Scheduled job=None
7.1267,Job,MODIFIED,eval-sanitize-20-r3-005,
7.1288,Job,MODIFIED,eval-sanitize-20-r3-006,
7.2974,Node,MODIFIED,kind-worker,taints=1
7.2988,Pod,MODIFIED,eval-sanitize-20-r3-007-rbhj9,phase=Pending node=kind-worker2
7.3033,Event,ADDED,eval-sanitize-20-r3-007-rbhj9.18d41b293454b1cf,reason=Scheduled count=None msg=Successfully assigned compute/eval-sanitize-20-r3-007-rbhj9 to kind-worker2
7.3098,Pod,MODIFIED,eval-sanitize-20-r3-007-rbhj9,phase=Pending node=kind-worker2
7.312,Node,MODIFIED,kind-worker,taints=1
7.6352,Node,MODIFIED,kind-worker4,taints=1
7.6584,Node,MODIFIED,kind-worker4,taints=1
7.8446,Event,ADDED,eval-sanitize-20-r3-007-rbhj9.18d41b29547f6e75,"reason=Pulled count=1 msg=Container image ""busybox:musl"" already present on machine"
7.8623,Event,ADDED,eval-sanitize-20-r3-007-rbhj9.18d41b2955a13bf7,reason=Created count=1 msg=Created container: task
7.9406,Event,ADDED,eval-sanitize-20-r3-007-rbhj9.18d41b295a52ebee,reason=Started count=1 msg=Started container task
8.0202,TaskRequest,ADDED,eval-sanitize-20-r3-008,phase=None job=None
8.1343,TaskRequest,MODIFIED,eval-sanitize-20-r3-008,phase=Pending job=None
8.1354,Job,MODIFIED,eval-sanitize-20-r3-007,
8.1494,Node,MODIFIED,kind-worker3,taints=1
8.1505,Job,ADDED,eval-sanitize-20-r3-008,
8.1555,Pod,ADDED,eval-sanitize-20-r3-008-zmb8h,phase=Pending node=None
8.1565,TaskRequest,MODIFIED,eval-sanitize-20-r3-008,phase=Scheduled job=None
8.1593,Job,MODIFIED,eval-sanitize-20-r3-008,
8.1613,Event,ADDED,eval-sanitize-20-r3-008.18d41b29675e2066,reason=SuccessfulCreate count=1 msg=Created pod: eval-sanitize-20-r3-008-zmb8h
8.163,Node,MODIFIED,kind-worker3,taints=1
8.1644,TaskRequest,MODIFIED,eval-sanitize-20-r3-008,phase=Scheduled job=None
8.1673,Job,MODIFIED,eval-sanitize-20-r3-007,
8.1682,Pod,MODIFIED,eval-sanitize-20-r3-008-zmb8h,phase=Pending node=kind-worker5
8.1724,Event,ADDED,eval-sanitize-20-r3-008-zmb8h.18d41b2968226b95,reason=Scheduled count=None msg=Successfully assigned compute/eval-sanitize-20-r3-008-zmb8h to kind-worker5
8.1778,Node,MODIFIED,kind-worker5,taints=0
8.1796,Pod,MODIFIED,eval-sanitize-20-r3-008-zmb8h,phase=Pending node=kind-worker5
8.23,Node,MODIFIED,kind-worker5,taints=0
8.5922,Node,MODIFIED,kind-worker2,taints=1
8.7219,Node,MODIFIED,kind-worker2,taints=1
8.7223,Event,ADDED,eval-sanitize-20-r3-008-zmb8h.18d41b2988ee2e45,"reason=Pulled count=1 msg=Container image ""busybox:musl"" already present on machine"
8.7447,Event,ADDED,eval-sanitize-20-r3-008-zmb8h.18d41b298a1b690c,reason=Created count=1 msg=Created container: task
8.9165,Event,ADDED,eval-sanitize-20-r3-008-zmb8h.18d41b2994851f33,reason=Started count=1 msg=Started container task
8.9199,Pod,MODIFIED,eval-sanitize-20-r3-007-rbhj9,phase=Running node=kind-worker2
9.0156,TaskRequest,ADDED,eval-sanitize-20-r3-009,phase=None job=None
9.0206,TaskRequest,MODIFIED,eval-sanitize-20-r3-009,phase=Pending job=None
9.03,Node,MODIFIED,kind-worker5,taints=1
9.0366,Job,ADDED,eval-sanitize-20-r3-009,
9.0428,Node,MODIFIED,kind-worker5,taints=1
9.0438,TaskRequest,MODIFIED,eval-sanitize-20-r3-009,phase=Scheduled job=None
9.0451,Pod,ADDED,eval-sanitize-20-r3-009-b98dg,phase=Pending node=None
9.0477,Job,MODIFIED,eval-sanitize-20-r3-009,
9.0513,Pod,MODIFIED,eval-sanitize-20-r3-008-zmb8h,phase=Running node=kind-worker5
9.0516,Event,ADDED,eval-sanitize-20-r3-009.18d41b299c5d6f53,reason=SuccessfulCreate count=1 msg=Created pod: eval-sanitize-20-r3-009-b98dg
9.0518,Event,ADDED,eval-sanitize-20-r3-009-b98dg.18d41b299c68fd9f,"reason=FailedScheduling count=None msg=0/6 nodes are available: 6 node(s) had untolerated taint(s). no new claims to deallocate, preemption: 0/6 nodes are available: 6 Preemption is not helpful for scheduling."
9.0526,Pod,MODIFIED,eval-sanitize-20-r3-009-b98dg,phase=Pending node=None
9.0646,TaskRequest,MODIFIED,eval-sanitize-20-r3-009,phase=Scheduled job=None
9.2197,Job,MODIFIED,eval-sanitize-20-r3-007,
9.223,Job,MODIFIED,eval-sanitize-20-r3-008,
9.229,Job,MODIFIED,eval-sanitize-20-r3-007,
9.2309,Job,MODIFIED,eval-sanitize-20-r3-008,
10.0083,TaskRequest,ADDED,eval-sanitize-20-r3-010,phase=None job=None
10.0134,TaskRequest,MODIFIED,eval-sanitize-20-r3-010,phase=Pending job=None
10.0278,Job,ADDED,eval-sanitize-20-r3-010,
10.034,Pod,ADDED,eval-sanitize-20-r3-010-85ngc,phase=Pending node=None
10.0342,TaskRequest,MODIFIED,eval-sanitize-20-r3-010,phase=Scheduled job=None
10.038,Job,MODIFIED,eval-sanitize-20-r3-010,
10.0404,Event,ADDED,eval-sanitize-20-r3-010.18d41b29d75fedea,reason=SuccessfulCreate count=1 msg=Created pod: eval-sanitize-20-r3-010-85ngc
10.0419,Pod,MODIFIED,eval-sanitize-20-r3-010-85ngc,phase=Pending node=None
10.0423,Event,ADDED,eval-sanitize-20-r3-010-85ngc.18d41b29d76a05b2,"reason=FailedScheduling count=None msg=0/6 nodes are available: 6 node(s) had untolerated taint(s). no new claims to deallocate, preemption: 0/6 nodes are available: 6 Preemption is not helpful for scheduling."
10.0424,TaskRequest,MODIFIED,eval-sanitize-20-r3-010,phase=Scheduled job=None
10.0498,Job,MODIFIED,eval-sanitize-20-r3-009,
10.0582,Job,MODIFIED,eval-sanitize-20-r3-009,
11.0089,TaskRequest,ADDED,eval-sanitize-20-r3-011,phase=None job=None
11.0135,TaskRequest,MODIFIED,eval-sanitize-20-r3-011,phase=Pending job=None
11.0311,Job,ADDED,eval-sanitize-20-r3-011,
11.0358,TaskRequest,MODIFIED,eval-sanitize-20-r3-011,phase=Scheduled job=None
11.0392,Job,MODIFIED,eval-sanitize-20-r3-010,
11.0403,Pod,ADDED,eval-sanitize-20-r3-011-7pmrj,phase=Pending node=None
11.0412,Job,MODIFIED,eval-sanitize-20-r3-011,
11.0456,Event,ADDED,eval-sanitize-20-r3-011.18d41b2a134b4949,reason=SuccessfulCreate count=1 msg=Created pod: eval-sanitize-20-r3-011-7pmrj
11.0458,TaskRequest,MODIFIED,eval-sanitize-20-r3-011,phase=Scheduled job=None
11.0468,Pod,MODIFIED,eval-sanitize-20-r3-011-7pmrj,phase=Pending node=None
11.0471,Event,ADDED,eval-sanitize-20-r3-011-7pmrj.18d41b2a13566a3c,"reason=FailedScheduling count=None msg=0/6 nodes are available: 6 node(s) had untolerated taint(s). no new claims to deallocate, preemption: 0/6 nodes are available: 6 Preemption is not helpful for scheduling."
11.0492,Job,MODIFIED,eval-sanitize-20-r3-010,
11.6511,Pod,MODIFIED,eval-sanitize-20-r3-000-2x82f,phase=Running node=kind-worker
12.0133,TaskRequest,ADDED,eval-sanitize-20-r3-012,phase=None job=None
12.0168,TaskRequest,MODIFIED,eval-sanitize-20-r3-012,phase=Pending job=None
12.0326,Job,ADDED,eval-sanitize-20-r3-012,
12.0377,TaskRequest,MODIFIED,eval-sanitize-20-r3-012,phase=Scheduled job=None
12.0393,Pod,ADDED,eval-sanitize-20-r3-012-cqb84,phase=Pending node=None
12.042,Job,MODIFIED,eval-sanitize-20-r3-012,
12.044,Job,MODIFIED,eval-sanitize-20-r3-011,
12.0458,Event,ADDED,eval-sanitize-20-r3-012.18d41b2a4ee6e6fb,reason=SuccessfulCreate count=1 msg=Created pod: eval-sanitize-20-r3-012-cqb84
12.046,Event,ADDED,eval-sanitize-20-r3-012-cqb84.18d41b2a4ef56607,"reason=FailedScheduling count=None msg=0/6 nodes are available: 6 node(s) had untolerated taint(s). no new claims to deallocate, preemption: 0/6 nodes are available: 6 Preemption is not helpful for scheduling."
12.0469,Pod,MODIFIED,eval-sanitize-20-r3-012-cqb84,phase=Pending node=None
12.047,TaskRequest,MODIFIED,eval-sanitize-20-r3-012,phase=Scheduled job=None
12.0558,Pod,MODIFIED,eval-sanitize-20-r3-001-zqtnq,phase=Running node=kind-worker5
12.0567,Job,MODIFIED,eval-sanitize-20-r3-011,
12.6558,Job,MODIFIED,eval-sanitize-20-r3-000,
12.666,Job,MODIFIED,eval-sanitize-20-r3-000,
12.863,Pod,MODIFIED,eval-sanitize-20-r3-000-2x82f,phase=Succeeded node=kind-worker
13.0127,TaskRequest,ADDED,eval-sanitize-20-r3-013,phase=None job=None
13.0181,TaskRequest,MODIFIED,eval-sanitize-20-r3-013,phase=Pending job=None
13.0337,Job,ADDED,eval-sanitize-20-r3-013,
13.0388,Pod,ADDED,eval-sanitize-20-r3-013-98nmn,phase=Pending node=None
13.0407,TaskRequest,MODIFIED,eval-sanitize-20-r3-013,phase=Scheduled job=None
13.0437,Job,MODIFIED,eval-sanitize-20-r3-013,
13.0445,Pod,MODIFIED,eval-sanitize-20-r3-013-98nmn,phase=Pending node=None
13.0451,Event,ADDED,eval-sanitize-20-r3-013.18d41b2a8a7afebc,reason=SuccessfulCreate count=1 msg=Created pod: eval-sanitize-20-r3-013-98nmn
13.0453,Event,ADDED,eval-sanitize-20-r3-013-98nmn.18d41b2a8a817a8c,"reason=FailedScheduling count=None msg=0/6 nodes are available: 6 node(s) had untolerated taint(s). no new claims to deallocate, preemption: 0/6 nodes are available: 6 Preemption is not helpful for scheduling."
13.0461,Job,MODIFIED,eval-sanitize-20-r3-012,
13.0489,TaskRequest,MODIFIED,eval-sanitize-20-r3-013,phase=Scheduled job=None
13.0525,Job,MODIFIED,eval-sanitize-20-r3-013,
13.0558,Job,MODIFIED,eval-sanitize-20-r3-012,
13.0599,Job,MODIFIED,eval-sanitize-20-r3-001,
13.0623,Job,MODIFIED,eval-sanitize-20-r3-013,
13.0684,Job,MODIFIED,eval-sanitize-20-r3-001,
13.2604,Pod,MODIFIED,eval-sanitize-20-r3-001-zqtnq,phase=Succeeded node=kind-worker5
13.4777,Pod,MODIFIED,eval-sanitize-20-r3-002-6p6k5,phase=Running node=kind-worker3
13.6622,Job,MODIFIED,eval-sanitize-20-r3-000,
13.6706,Pod,MODIFIED,eval-sanitize-20-r3-000-2x82f,phase=Succeeded node=kind-worker
13.6734,Job,MODIFIED,eval-sanitize-20-r3-000,
14.0088,TaskRequest,ADDED,eval-sanitize-20-r3-014,phase=None job=None
14.0141,TaskRequest,MODIFIED,eval-sanitize-20-r3-014,phase=Pending job=None
14.0299,Job,ADDED,eval-sanitize-20-r3-014,
14.0369,Pod,ADDED,eval-sanitize-20-r3-014-7fzzg,phase=Pending node=None
14.037,TaskRequest,MODIFIED,eval-sanitize-20-r3-014,phase=Scheduled job=None
14.0401,Job,MODIFIED,eval-sanitize-20-r3-014,
14.0423,Event,ADDED,eval-sanitize-20-r3-014.18d41b2ac5f02032,reason=SuccessfulCreate count=1 msg=Created pod: eval-sanitize-20-r3-014-7fzzg
14.0427,Event,ADDED,eval-sanitize-20-r3-014-7fzzg.18d41b2ac5fc793c,"reason=FailedScheduling count=None msg=0/6 nodes are available: 6 node(s) had untolerated taint(s). no new claims to deallocate, preemption: 0/6 nodes are available: 6 Preemption is not helpful for scheduling."
14.0436,Pod,MODIFIED,eval-sanitize-20-r3-014-7fzzg,phase=Pending node=None
14.0438,TaskRequest,MODIFIED,eval-sanitize-20-r3-014,phase=Scheduled job=None
14.0652,Job,MODIFIED,eval-sanitize-20-r3-001,
14.0735,Pod,MODIFIED,eval-sanitize-20-r3-001-zqtnq,phase=Succeeded node=kind-worker5
14.075,Job,MODIFIED,eval-sanitize-20-r3-001,
14.4815,Pod,MODIFIED,eval-sanitize-20-r3-003-wh2ts,phase=Running node=kind-worker3
14.4823,Job,MODIFIED,eval-sanitize-20-r3-002,
14.4934,Job,MODIFIED,eval-sanitize-20-r3-002,
14.5921,Pod,MODIFIED,eval-sanitize-20-r3-002-6p6k5,phase=Succeeded node=kind-worker3
14.67,Job,MODIFIED,eval-sanitize-20-r3-000,
14.6739,Job,MODIFIED,eval-sanitize-20-r3-000,
14.6771,Event,ADDED,eval-sanitize-20-r3-000.18d41b2aebef39c5,reason=Completed count=1 msg=Job completed
14.6868,Job,MODIFIED,eval-sanitize-20-r3-000,
14.6927,TaskRequest,MODIFIED,eval-sanitize-20-r3-000,phase=Complete job=None
14.7037,Job,MODIFIED,eval-sanitize-20-r3-000,
14.9192,Pod,MODIFIED,eval-sanitize-20-r3-004-2jl8f,phase=Running node=kind-worker2
15.0131,TaskRequest,ADDED,eval-sanitize-20-r3-015,phase=None job=None
15.018,TaskRequest,MODIFIED,eval-sanitize-20-r3-015,phase=Pending job=None
15.0323,Job,ADDED,eval-sanitize-20-r3-015,
15.0364,TaskRequest,MODIFIED,eval-sanitize-20-r3-015,phase=Scheduled job=None
15.0395,Pod,ADDED,eval-sanitize-20-r3-015-7nhgg,phase=Pending node=None
15.0418,Job,MODIFIED,eval-sanitize-20-r3-015,
15.0425,Job,MODIFIED,eval-sanitize-20-r3-014,
15.0457,Event,ADDED,eval-sanitize-20-r3-015.18d41b2b01bab8ad,reason=SuccessfulCreate count=1 msg=Created pod: eval-sanitize-20-r3-015-7nhgg
15.046,Event,ADDED,eval-sanitize-20-r3-015-7nhgg.18d41b2b01c5e6d1,"reason=FailedScheduling count=None msg=0/6 nodes are available: 6 node(s) had untolerated taint(s). no new claims to deallocate, preemption: 0/6 nodes are available: 6 Preemption is not helpful for scheduling."
15.0461,TaskRequest,MODIFIED,eval-sanitize-20-r3-015,phase=Scheduled job=None
15.0469,Pod,MODIFIED,eval-sanitize-20-r3-015-7nhgg,phase=Pending node=None
15.0539,Job,MODIFIED,eval-sanitize-20-r3-014,
15.0699,Job,MODIFIED,eval-sanitize-20-r3-001,
15.0745,Job,MODIFIED,eval-sanitize-20-r3-001,
15.0778,Event,ADDED,eval-sanitize-20-r3-001.18d41b2b03caf3b2,reason=Completed count=1 msg=Job completed
15.0836,Job,MODIFIED,eval-sanitize-20-r3-001,
15.0884,TaskRequest,MODIFIED,eval-sanitize-20-r3-001,phase=Complete job=None
15.0968,Job,MODIFIED,eval-sanitize-20-r3-001,
15.4908,Job,MODIFIED,eval-sanitize-20-r3-003,
15.4926,Job,MODIFIED,eval-sanitize-20-r3-002,
15.5018,Job,MODIFIED,eval-sanitize-20-r3-003,
15.5046,Pod,MODIFIED,eval-sanitize-20-r3-002-6p6k5,phase=Succeeded node=kind-worker3
15.5055,Job,MODIFIED,eval-sanitize-20-r3-002,
15.5633,Pod,MODIFIED,eval-sanitize-20-r3-003-wh2ts,phase=Succeeded node=kind-worker3
15.9264,Job,MODIFIED,eval-sanitize-20-r3-004,
15.9362,Job,MODIFIED,eval-sanitize-20-r3-004,
15.9939,Pod,MODIFIED,eval-sanitize-20-r3-004-2jl8f,phase=Succeeded node=kind-worker2
16.0069,TaskRequest,ADDED,eval-sanitize-20-r3-016,phase=None job=None
16.0106,TaskRequest,MODIFIED,eval-sanitize-20-r3-016,phase=Pending job=None
16.0267,Job,ADDED,eval-sanitize-20-r3-016,
16.0306,TaskRequest,MODIFIED,eval-sanitize-20-r3-016,phase=Scheduled job=None
16.0336,Pod,ADDED,eval-sanitize-20-r3-016-wg4b2,phase=Pending node=None
16.0362,Job,MODIFIED,eval-sanitize-20-r3-016,
16.0397,TaskRequest,MODIFIED,eval-sanitize-20-r3-016,phase=Scheduled job=None
16.0405,Event,ADDED,eval-sanitize-20-r3-016.18d41b2b3cfc5e95,reason=SuccessfulCreate count=1 msg=Created pod: eval-sanitize-20-r3-016-wg4b2
16.0408,Event,ADDED,eval-sanitize-20-r3-016-wg4b2.18d41b2b3d065eec,"reason=FailedScheduling count=None msg=0/6 nodes are available: 6 node(s) had untolerated taint(s). no new claims to deallocate, preemption: 0/6 nodes are available: 6 Preemption is not helpful for scheduling."
16.0417,Pod,MODIFIED,eval-sanitize-20-r3-016-wg4b2,phase=Pending node=None
16.0446,Job,MODIFIED,eval-sanitize-20-r3-015,
16.0543,Job,MODIFIED,eval-sanitize-20-r3-015,
16.4868,Pod,MODIFIED,eval-sanitize-20-r3-005-6gx5c,phase=Running node=kind-worker3
16.4963,Job,MODIFIED,eval-sanitize-20-r3-003,
16.5002,Job,MODIFIED,eval-sanitize-20-r3-002,
16.5052,Pod,MODIFIED,eval-sanitize-20-r3-003-wh2ts,phase=Succeeded node=kind-worker3
16.5071,Job,MODIFIED,eval-sanitize-20-r3-002,
16.5079,Job,MODIFIED,eval-sanitize-20-r3-003,
16.5111,Event,ADDED,eval-sanitize-20-r3-002.18d41b2b5934b058,reason=Completed count=1 msg=Job completed
16.5151,Job,MODIFIED,eval-sanitize-20-r3-002,
16.5199,TaskRequest,MODIFIED,eval-sanitize-20-r3-002,phase=Complete job=None
16.5294,Job,MODIFIED,eval-sanitize-20-r3-002,
16.9089,Pod,MODIFIED,eval-sanitize-20-r3-006-wc75b,phase=Running node=kind-worker4
16.9339,Job,MODIFIED,eval-sanitize-20-r3-004,
16.9431,Pod,MODIFIED,eval-sanitize-20-r3-004-2jl8f,phase=Succeeded node=kind-worker2
16.9443,Job,MODIFIED,eval-sanitize-20-r3-004,
17.0083,TaskRequest,ADDED,eval-sanitize-20-r3-017,phase=None job=None
17.0125,TaskRequest,MODIFIED,eval-sanitize-20-r3-017,phase=Pending job=None
17.0283,Job,ADDED,eval-sanitize-20-r3-017,
17.035,Pod,ADDED,eval-sanitize-20-r3-017-zwmxm,phase=Pending node=None
17.0352,TaskRequest,MODIFIED,eval-sanitize-20-r3-017,phase=Scheduled job=None
17.0384,Job,MODIFIED,eval-sanitize-20-r3-017,
17.0414,Event,ADDED,eval-sanitize-20-r3-017.18d41b2b78ace366,reason=SuccessfulCreate count=1 msg=Created pod: eval-sanitize-20-r3-017-zwmxm
17.0424,Pod,MODIFIED,eval-sanitize-20-r3-017-zwmxm,phase=Pending node=None
17.0431,Job,MODIFIED,eval-sanitize-20-r3-016,
17.0434,TaskRequest,MODIFIED,eval-sanitize-20-r3-017,phase=Scheduled job=None
17.0448,Event,ADDED,eval-sanitize-20-r3-017-zwmxm.18d41b2b78b471cd,"reason=FailedScheduling count=None msg=0/6 nodes are available: 6 node(s) had untolerated taint(s). no new claims to deallocate, preemption: 0/6 nodes are available: 6 Preemption is not helpful for scheduling."
17.0507,Job,MODIFIED,eval-sanitize-20-r3-016,
17.4925,Job,MODIFIED,eval-sanitize-20-r3-005,
17.5014,Job,MODIFIED,eval-sanitize-20-r3-003,
17.5066,Job,MODIFIED,eval-sanitize-20-r3-005,
17.5093,Job,MODIFIED,eval-sanitize-20-r3-003,
17.5127,Event,ADDED,eval-sanitize-20-r3-003.18d41b2b94a99696,reason=Completed count=1 msg=Job completed
17.5197,Job,MODIFIED,eval-sanitize-20-r3-003,
17.5262,TaskRequest,MODIFIED,eval-sanitize-20-r3-003,phase=Complete job=None
17.5363,Job,MODIFIED,eval-sanitize-20-r3-003,
17.5951,Pod,MODIFIED,eval-sanitize-20-r3-005-6gx5c,phase=Succeeded node=kind-worker3
17.9162,Job,MODIFIED,eval-sanitize-20-r3-006,
17.9276,Job,MODIFIED,eval-sanitize-20-r3-006,
17.9398,Job,MODIFIED,eval-sanitize-20-r3-004,
17.9443,Job,MODIFIED,eval-sanitize-20-r3-004,
17.9493,Event,ADDED,eval-sanitize-20-r3-004.18d41b2bae9853f9,reason=Completed count=1 msg=Job completed
17.9557,Job,MODIFIED,eval-sanitize-20-r3-004,
17.9605,TaskRequest,MODIFIED,eval-sanitize-20-r3-004,phase=Complete job=None
17.9701,Job,MODIFIED,eval-sanitize-20-r3-004,
18.0068,TaskRequest,ADDED,eval-sanitize-20-r3-018,phase=None job=None
18.0107,TaskRequest,MODIFIED,eval-sanitize-20-r3-018,phase=Pending job=None
18.0266,Job,ADDED,eval-sanitize-20-r3-018,
18.0311,TaskRequest,MODIFIED,eval-sanitize-20-r3-018,phase=Scheduled job=None
18.0342,Pod,ADDED,eval-sanitize-20-r3-018-mnx7g,phase=Pending node=None
18.036,Job,MODIFIED,eval-sanitize-20-r3-018,
18.0393,Pod,MODIFIED,eval-sanitize-20-r3-006-wc75b,phase=Succeeded node=kind-worker4
18.0409,Event,ADDED,eval-sanitize-20-r3-018.18d41b2bb3f05856,reason=SuccessfulCreate count=1 msg=Created pod: eval-sanitize-20-r3-018-mnx7g
18.0412,Event,ADDED,eval-sanitize-20-r3-018-mnx7g.18d41b2bb3fd7b27,"reason=FailedScheduling count=None msg=0/6 nodes are available: 6 node(s) had untolerated taint(s). no new claims to deallocate, preemption: 0/6 nodes are available: 6 Preemption is not helpful for scheduling."
18.0413,TaskRequest,MODIFIED,eval-sanitize-20-r3-018,phase=Scheduled job=None
18.0423,Pod,MODIFIED,eval-sanitize-20-r3-018-mnx7g,phase=Pending node=None
18.0431,Job,MODIFIED,eval-sanitize-20-r3-017,
18.0515,Job,MODIFIED,eval-sanitize-20-r3-017,
18.4977,Job,MODIFIED,eval-sanitize-20-r3-005,
18.5067,Pod,MODIFIED,eval-sanitize-20-r3-005-6gx5c,phase=Succeeded node=kind-worker3
18.5086,Job,MODIFIED,eval-sanitize-20-r3-005,
18.9225,Job,MODIFIED,eval-sanitize-20-r3-006,
18.9279,Pod,MODIFIED,eval-sanitize-20-r3-007-rbhj9,phase=Running node=kind-worker2
18.9311,Pod,MODIFIED,eval-sanitize-20-r3-006-wc75b,phase=Succeeded node=kind-worker4
18.9324,Job,MODIFIED,eval-sanitize-20-r3-006,
19.0089,TaskRequest,ADDED,eval-sanitize-20-r3-019,phase=None job=None
19.0127,TaskRequest,MODIFIED,eval-sanitize-20-r3-019,phase=Pending job=None
19.0283,Job,ADDED,eval-sanitize-20-r3-019,
19.0335,Pod,ADDED,eval-sanitize-20-r3-019-jntlw,phase=Pending node=None
19.0349,TaskRequest,MODIFIED,eval-sanitize-20-r3-019,phase=Scheduled job=None
19.0367,Job,MODIFIED,eval-sanitize-20-r3-019,
19.0393,Job,MODIFIED,eval-sanitize-20-r3-018,
19.041,Event,ADDED,eval-sanitize-20-r3-019.18d41b2bef876ae9,reason=SuccessfulCreate count=1 msg=Created pod: eval-sanitize-20-r3-019-jntlw
19.0413,Event,ADDED,eval-sanitize-20-r3-019-jntlw.18d41b2bef95c3aa,"reason=FailedScheduling count=None msg=0/6 nodes are available: 6 node(s) had untolerated taint(s). no new claims to deallocate, preemption: 0/6 nodes are available: 6 Preemption is not helpful for scheduling."
19.0424,Pod,MODIFIED,eval-sanitize-20-r3-019-jntlw,phase=Pending node=None
19.0443,TaskRequest,MODIFIED,eval-sanitize-20-r3-019,phase=Scheduled job=None
19.0465,Job,MODIFIED,eval-sanitize-20-r3-019,
19.0486,Job,MODIFIED,eval-sanitize-20-r3-018,
19.0555,Job,MODIFIED,eval-sanitize-20-r3-019,
19.073,Pod,MODIFIED,eval-sanitize-20-r3-008-zmb8h,phase=Running node=kind-worker5
19.3059,Node,MODIFIED,kind-worker4,taints=1
19.5047,Job,MODIFIED,eval-sanitize-20-r3-005,
19.5091,Job,MODIFIED,eval-sanitize-20-r3-005,
19.5153,Event,ADDED,eval-sanitize-20-r3-005.18d41b2c0bdc769e,reason=Completed count=1 msg=Job completed
19.5199,Job,MODIFIED,eval-sanitize-20-r3-005,
19.5258,TaskRequest,MODIFIED,eval-sanitize-20-r3-005,phase=Complete job=None
19.5357,Job,MODIFIED,eval-sanitize-20-r3-005,
19.9297,Job,MODIFIED,eval-sanitize-20-r3-006,
19.9333,Job,MODIFIED,eval-sanitize-20-r3-007,
19.9355,Job,MODIFIED,eval-sanitize-20-r3-006,
19.9401,Event,ADDED,eval-sanitize-20-r3-006.18d41b2c2544367c,reason=Completed count=1 msg=Job completed
19.9428,Job,MODIFIED,eval-sanitize-20-r3-007,
19.9481,Job,MODIFIED,eval-sanitize-20-r3-006,
19.9541,TaskRequest,MODIFIED,eval-sanitize-20-r3-006,phase=Complete job=None
19.9651,Job,MODIFIED,eval-sanitize-20-r3-006,
20.0082,TaskRequest,ADDED,eval-sanitize-20-r3-020,phase=None job=None
20.0136,TaskRequest,MODIFIED,eval-sanitize-20-r3-020,phase=Pending job=None
20.0235,Pod,MODIFIED,eval-sanitize-20-r3-007-rbhj9,phase=Succeeded node=kind-worker2
20.0302,Job,ADDED,eval-sanitize-20-r3-020,
20.0357,Pod,ADDED,eval-sanitize-20-r3-020-z7jzd,phase=Pending node=None
20.0373,TaskRequest,MODIFIED,eval-sanitize-20-r3-020,phase=Scheduled job=None
20.0399,Job,MODIFIED,eval-sanitize-20-r3-020,
20.0418,Event,ADDED,eval-sanitize-20-r3-020.18d41b2c2b3dbbb5,reason=SuccessfulCreate count=1 msg=Created pod: eval-sanitize-20-r3-020-z7jzd
20.0421,Event,ADDED,eval-sanitize-20-r3-020-z7jzd.18d41b2c2b42e844,"reason=FailedScheduling count=None msg=0/6 nodes are available: 6 node(s) had untolerated taint(s). no new claims to deallocate, preemption: 0/6 nodes are available: 6 Preemption is not helpful for scheduling."
20.0433,Pod,MODIFIED,eval-sanitize-20-r3-020-z7jzd,phase=Pending node=None
20.0454,TaskRequest,MODIFIED,eval-sanitize-20-r3-020,phase=Scheduled job=None
20.078,Job,MODIFIED,eval-sanitize-20-r3-008,
20.0874,Job,MODIFIED,eval-sanitize-20-r3-008,
20.2556,Pod,MODIFIED,eval-sanitize-20-r3-008-zmb8h,phase=Succeeded node=kind-worker5
20.9401,Job,MODIFIED,eval-sanitize-20-r3-007,
20.9499,Pod,MODIFIED,eval-sanitize-20-r3-007-rbhj9,phase=Succeeded node=kind-worker2
20.9512,Job,MODIFIED,eval-sanitize-20-r3-007,
21.0219,TaskRequest,ADDED,eval-sanitize-20-r3-021,phase=None job=None
21.0262,TaskRequest,MODIFIED,eval-sanitize-20-r3-021,phase=Pending job=None
21.0414,Job,MODIFIED,eval-sanitize-20-r3-020,
21.043,Job,ADDED,eval-sanitize-20-r3-021,
21.0478,TaskRequest,MODIFIED,eval-sanitize-20-r3-021,phase=Scheduled job=None
21.051,Pod,ADDED,eval-sanitize-20-r3-021-xmp2g,phase=Pending node=None
21.0538,Job,MODIFIED,eval-sanitize-20-r3-021,
21.0578,Event,ADDED,eval-sanitize-20-r3-021.18d41b2c67c25a3f,reason=SuccessfulCreate count=1 msg=Created pod: eval-sanitize-20-r3-021-xmp2g
21.0582,Event,ADDED,eval-sanitize-20-r3-021-xmp2g.18d41b2c67cdbf55,"reason=FailedScheduling count=None msg=0/6 nodes are available: 6 node(s) had untolerated taint(s). no new claims to deallocate, preemption: 0/6 nodes are available: 6 Preemption is not helpful for scheduling."
21.0591,Pod,MODIFIED,eval-sanitize-20-r3-021-xmp2g,phase=Pending node=None
21.0592,TaskRequest,MODIFIED,eval-sanitize-20-r3-021,phase=Scheduled job=None
21.0601,Job,MODIFIED,eval-sanitize-20-r3-020,
21.0846,Job,MODIFIED,eval-sanitize-20-r3-008,
21.0928,Pod,MODIFIED,eval-sanitize-20-r3-008-zmb8h,phase=Succeeded node=kind-worker5
21.0942,Job,MODIFIED,eval-sanitize-20-r3-008,
21.9461,Job,MODIFIED,eval-sanitize-20-r3-007,
21.9507,Job,MODIFIED,eval-sanitize-20-r3-007,
21.9533,Event,ADDED,eval-sanitize-20-r3-007.18d41b2c9d6227ae,reason=Completed count=1 msg=Job completed
21.9628,Job,MODIFIED,eval-sanitize-20-r3-007,
21.9667,TaskRequest,MODIFIED,eval-sanitize-20-r3-007,phase=Complete job=None
21.9753,Job,MODIFIED,eval-sanitize-20-r3-007,
22.0078,TaskRequest,ADDED,eval-sanitize-20-r3-022,phase=None job=None
22.0118,TaskRequest,MODIFIED,eval-sanitize-20-r3-022,phase=Pending job=None
22.0277,Job,ADDED,eval-sanitize-20-r3-022,
22.0341,Pod,ADDED,eval-sanitize-20-r3-022-22zpt,phase=Pending node=None
22.036,Job,MODIFIED,eval-sanitize-20-r3-022,
22.0361,TaskRequest,MODIFIED,eval-sanitize-20-r3-022,phase=Scheduled job=None
22.0394,Event,ADDED,eval-sanitize-20-r3-022.18d41b2ca25a0a03,reason=SuccessfulCreate count=1 msg=Created pod: eval-sanitize-20-r3-022-22zpt
22.0396,Event,ADDED,eval-sanitize-20-r3-022-22zpt.18d41b2ca26925a5,"reason=FailedScheduling count=None msg=0/6 nodes are available: 6 node(s) had untolerated taint(s). no new claims to deallocate, preemption: 0/6 nodes are available: 6 Preemption is not helpful for scheduling."
22.0406,Pod,MODIFIED,eval-sanitize-20-r3-022-22zpt,phase=Pending node=None
22.0439,TaskRequest,MODIFIED,eval-sanitize-20-r3-022,phase=Scheduled job=None
22.0546,Job,MODIFIED,eval-sanitize-20-r3-021,
22.0631,Job,MODIFIED,eval-sanitize-20-r3-021,
22.0903,Job,MODIFIED,eval-sanitize-20-r3-008,
22.0944,Job,MODIFIED,eval-sanitize-20-r3-008,
22.099,Event,ADDED,eval-sanitize-20-r3-008.18d41b2ca5f58365,reason=Completed count=1 msg=Job completed
22.1061,Job,MODIFIED,eval-sanitize-20-r3-008,
22.1105,TaskRequest,MODIFIED,eval-sanitize-20-r3-008,phase=Complete job=None
22.1192,Job,MODIFIED,eval-sanitize-20-r3-008,
23.0091,TaskRequest,ADDED,eval-sanitize-20-r3-023,phase=None job=None
23.0126,TaskRequest,MODIFIED,eval-sanitize-20-r3-023,phase=Pending job=None
23.0283,Job,ADDED,eval-sanitize-20-r3-023,
23.0342,TaskRequest,MODIFIED,eval-sanitize-20-r3-023,phase=Scheduled job=None
23.0375,Job,MODIFIED,eval-sanitize-20-r3-023,
23.0387,Pod,ADDED,eval-sanitize-20-r3-023-l94v5,phase=Pending node=None
23.0396,Job,MODIFIED,eval-sanitize-20-r3-022,
23.0431,Pod,MODIFIED,eval-sanitize-20-r3-023-l94v5,phase=Pending node=None
23.0438,Event,ADDED,eval-sanitize-20-r3-023.18d41b2cde2b76f3,reason=SuccessfulCreate count=1 msg=Created pod: eval-sanitize-20-r3-023-l94v5
23.044,Event,ADDED,eval-sanitize-20-r3-023-l94v5.18d41b2cde32856a,"reason=FailedScheduling count=None msg=0/6 nodes are available: 6 node(s) had untolerated taint(s). no new claims to deallocate, preemption: 0/6 nodes are available: 6 Preemption is not helpful for scheduling."
23.0441,TaskRequest,MODIFIED,eval-sanitize-20-r3-023,phase=Scheduled job=None
23.0484,Job,MODIFIED,eval-sanitize-20-r3-022,
24.0085,TaskRequest,ADDED,eval-sanitize-20-r3-024,phase=None job=None
24.0121,TaskRequest,MODIFIED,eval-sanitize-20-r3-024,phase=Pending job=None
24.0296,Job,ADDED,eval-sanitize-20-r3-024,
24.0341,TaskRequest,MODIFIED,eval-sanitize-20-r3-024,phase=Scheduled job=None
24.0372,Pod,ADDED,eval-sanitize-20-r3-024-7v9kq,phase=Pending node=None
24.04,Job,MODIFIED,eval-sanitize-20-r3-024,
24.0446,Event,ADDED,eval-sanitize-20-r3-024.18d41b2d19bd4b46,reason=SuccessfulCreate count=1 msg=Created pod: eval-sanitize-20-r3-024-7v9kq
24.0449,Event,ADDED,eval-sanitize-20-r3-024-7v9kq.18d41b2d19cabb5c,"reason=FailedScheduling count=None msg=0/6 nodes are available: 6 node(s) had untolerated taint(s). no new claims to deallocate, preemption: 0/6 nodes are available: 6 Preemption is not helpful for scheduling."
24.0459,Job,MODIFIED,eval-sanitize-20-r3-023,
24.0461,TaskRequest,MODIFIED,eval-sanitize-20-r3-024,phase=Scheduled job=None
24.047,Pod,MODIFIED,eval-sanitize-20-r3-024-7v9kq,phase=Pending node=None
24.0547,Job,MODIFIED,eval-sanitize-20-r3-023,
25.0443,Job,MODIFIED,eval-sanitize-20-r3-024,
25.0532,Job,MODIFIED,eval-sanitize-20-r3-024,
25.0698,TaskRequest,ADDED,eval-sanitize-20-r3-025,phase=None job=None
25.0749,TaskRequest,MODIFIED,eval-sanitize-20-r3-025,phase=Pending job=None
25.089,Job,ADDED,eval-sanitize-20-r3-025,
25.0952,Pod,ADDED,eval-sanitize-20-r3-025-928bl,phase=Pending node=None
25.0968,TaskRequest,MODIFIED,eval-sanitize-20-r3-025,phase=Scheduled job=None
25.0996,Job,MODIFIED,eval-sanitize-20-r3-025,
25.103,Event,ADDED,eval-sanitize-20-r3-025.18d41b2d58d7042b,reason=SuccessfulCreate count=1 msg=Created pod: eval-sanitize-20-r3-025-928bl
25.1039,Pod,MODIFIED,eval-sanitize-20-r3-025-928bl,phase=Pending node=None
25.1042,Event,ADDED,eval-sanitize-20-r3-025-928bl.18d41b2d58ed9685,"reason=FailedScheduling count=None msg=0/6 nodes are available: 6 node(s) had untolerated taint(s). no new claims to deallocate, preemption: 0/6 nodes are available: 6 Preemption is not helpful for scheduling."
25.1044,TaskRequest,MODIFIED,eval-sanitize-20-r3-025,phase=Scheduled job=None
26.0087,TaskRequest,ADDED,eval-sanitize-20-r3-026,phase=None job=None
26.012,TaskRequest,MODIFIED,eval-sanitize-20-r3-026,phase=Pending job=None
26.027,Job,ADDED,eval-sanitize-20-r3-026,
26.0312,TaskRequest,MODIFIED,eval-sanitize-20-r3-026,phase=Scheduled job=None
26.0342,Pod,ADDED,eval-sanitize-20-r3-026-4255x,phase=Pending node=None
26.0359,Job,MODIFIED,eval-sanitize-20-r3-026,
26.0409,Pod,MODIFIED,eval-sanitize-20-r3-026-4255x,phase=Pending node=None
26.0413,Event,ADDED,eval-sanitize-20-r3-026.18d41b2d90cc1d7f,reason=SuccessfulCreate count=1 msg=Created pod: eval-sanitize-20-r3-026-4255x
26.0415,Event,ADDED,eval-sanitize-20-r3-026-4255x.18d41b2d90d6ecaf,"reason=FailedScheduling count=None msg=0/6 nodes are available: 6 node(s) had untolerated taint(s). no new claims to deallocate, preemption: 0/6 nodes are available: 6 Preemption is not helpful for scheduling."
26.0513,TaskRequest,MODIFIED,eval-sanitize-20-r3-026,phase=Scheduled job=None
26.1026,Job,MODIFIED,eval-sanitize-20-r3-025,
26.1111,Job,MODIFIED,eval-sanitize-20-r3-025,
27.0082,TaskRequest,ADDED,eval-sanitize-20-r3-027,phase=None job=None
27.0123,TaskRequest,MODIFIED,eval-sanitize-20-r3-027,phase=Pending job=None
27.0268,Job,ADDED,eval-sanitize-20-r3-027,
27.0333,Pod,ADDED,eval-sanitize-20-r3-027-p6tjp,phase=Pending node=None
27.0343,TaskRequest,MODIFIED,eval-sanitize-20-r3-027,phase=Scheduled job=None
27.0351,Job,MODIFIED,eval-sanitize-20-r3-027,
27.0392,Pod,MODIFIED,eval-sanitize-20-r3-027-p6tjp,phase=Pending node=None
27.0402,Event,ADDED,eval-sanitize-20-r3-027.18d41b2dcc560852,reason=SuccessfulCreate count=1 msg=Created pod: eval-sanitize-20-r3-027-p6tjp
27.0404,Event,ADDED,eval-sanitize-20-r3-027-p6tjp.18d41b2dcc6050fc,"reason=FailedScheduling count=None msg=0/6 nodes are available: 6 node(s) had untolerated taint(s). no new claims to deallocate, preemption: 0/6 nodes are available: 6 Preemption is not helpful for scheduling."
27.041,Job,MODIFIED,eval-sanitize-20-r3-026,
27.0466,TaskRequest,MODIFIED,eval-sanitize-20-r3-027,phase=Scheduled job=None
27.0498,Job,MODIFIED,eval-sanitize-20-r3-026,
27.4689,Node,MODIFIED,kind-worker,taints=1
27.4847,Node,MODIFIED,kind-worker,taints=0
27.4911,Pod,MODIFIED,eval-sanitize-20-r3-009-b98dg,phase=Pending node=kind-worker
27.4943,Node,MODIFIED,kind-worker,taints=0
27.4976,Event,ADDED,eval-sanitize-20-r3-009-b98dg.18d41b2de7a54ad6,reason=Scheduled count=None msg=Successfully assigned compute/eval-sanitize-20-r3-009-b98dg to kind-worker
27.5002,Pod,MODIFIED,eval-sanitize-20-r3-010-85ngc,phase=Pending node=None
27.5022,Event,ADDED,eval-sanitize-20-r3-010-85ngc.18d41b2de7db4a7e,"reason=FailedScheduling count=None msg=0/6 nodes are available: 1 c_wall violated: 1 conflicting context pair(s) with node memory, 5 node(s) had untolerated taint(s). no new claims to deallocate, preemption: 0/6 nodes are available: 1 No preemption victims found for incoming pod, 5 Preemption is not helpful for scheduling."
27.5056,Node,MODIFIED,kind-worker,taints=0
27.5081,Pod,MODIFIED,eval-sanitize-20-r3-009-b98dg,phase=Pending node=kind-worker
27.5097,Pod,MODIFIED,eval-sanitize-20-r3-011-7pmrj,phase=Pending node=kind-worker
27.5125,Pod,MODIFIED,eval-sanitize-20-r3-012-cqb84,phase=Pending node=None
27.5152,Event,ADDED,eval-sanitize-20-r3-012-cqb84.18d41b2de899a569,"reason=FailedScheduling count=None msg=0/6 nodes are available: 1 c_wall violated: 1 conflicting context pair(s) with node memory, 5 node(s) had untolerated taint(s). no new claims to deallocate, preemption: 0/6 nodes are available: 1 No preemption victims found for incoming pod, 5 Preemption is not helpful for scheduling."
27.5159,Event,ADDED,eval-sanitize-20-r3-011-7pmrj.18d41b2de8bcbf26,reason=Scheduled count=None msg=Successfully assigned compute/eval-sanitize-20-r3-011-7pmrj to kind-worker
27.5202,Node,MODIFIED,kind-worker,taints=0
27.522,Pod,MODIFIED,eval-sanitize-20-r3-011-7pmrj,phase=Pending node=kind-worker
27.5542,Pod,MODIFIED,eval-sanitize-20-r3-013-98nmn,phase=Pending node=kind-worker
27.5561,Event,ADDED,eval-sanitize-20-r3-014-7fzzg.18d41b2deb314304,"reason=FailedScheduling count=None msg=0/6 nodes are available: 1 c_wall violated: 2 conflicting context pair(s) with node memory, 5 node(s) had untolerated taint(s). no new claims to deallocate, preemption: 0/6 nodes are available: 1 No preemption victims found for incoming pod, 5 Preemption is not helpful for scheduling."
27.5572,Pod,MODIFIED,eval-sanitize-20-r3-014-7fzzg,phase=Pending node=None
27.5578,Event,ADDED,eval-sanitize-20-r3-013-98nmn.18d41b2deb652ba2,reason=Scheduled count=None msg=Successfully assigned compute/eval-sanitize-20-r3-013-98nmn to kind-worker
27.5644,Node,MODIFIED,kind-worker,taints=0
27.5664,Pod,MODIFIED,eval-sanitize-20-r3-013-98nmn,phase=Pending node=kind-worker
27.5936,Node,MODIFIED,kind-worker,taints=0
27.6019,Event,ADDED,eval-sanitize-20-r3-015-7nhgg.18d41b2dedc9c788,"reason=FailedScheduling count=None msg=0/6 nodes are available: 1 c_wall violated: 2 conflicting context pair(s) with node memory, 5 node(s) had untolerated taint(s). no new claims to deallocate, preemption: 0/6 nodes are available: 1 No preemption victims found for incoming pod, 5 Preemption is not helpful for scheduling."
27.6035,Pod,MODIFIED,eval-sanitize-20-r3-015-7nhgg,phase=Pending node=None
27.605,Node,MODIFIED,kind-worker,taints=0
27.6113,Pod,MODIFIED,eval-sanitize-20-r3-016-wg4b2,phase=Pending node=None
27.6116,Event,ADDED,eval-sanitize-20-r3-016-wg4b2.18d41b2dee86b4b5,"reason=FailedScheduling count=None msg=0/6 nodes are available: 1 c_wall violated: 2 conflicting context pair(s) with node memory, 5 node(s) had untolerated taint(s). no new claims to deallocate, preemption: 0/6 nodes are available: 1 No preemption victims found for incoming pod, 5 Preemption is not helpful for scheduling."
27.6197,Node,MODIFIED,kind-worker,taints=0
27.6213,Pod,MODIFIED,eval-sanitize-20-r3-017-zwmxm,phase=Pending node=kind-worker
27.6229,Event,ADDED,eval-sanitize-20-r3-018-mnx7g.18d41b2def2e3b7b,"reason=FailedScheduling count=None msg=0/6 nodes are available: 1 c_wall violated: 2 conflicting context pair(s) with node memory, 5 node(s) had untolerated taint(s). no new claims to deallocate, preemption: 0/6 nodes are available: 1 No preemption victims found for incoming pod, 5 Preemption is not helpful for scheduling."
27.6242,Pod,MODIFIED,eval-sanitize-20-r3-018-mnx7g,phase=Pending node=None
27.6246,Event,ADDED,eval-sanitize-20-r3-017-zwmxm.18d41b2def65325b,reason=Scheduled count=None msg=Successfully assigned compute/eval-sanitize-20-r3-017-zwmxm to kind-worker
27.6304,Node,MODIFIED,kind-worker,taints=0
27.6325,Pod,MODIFIED,eval-sanitize-20-r3-017-zwmxm,phase=Pending node=kind-worker
27.6331,Event,ADDED,eval-sanitize-20-r3-019-jntlw.18d41b2defc45a29,"reason=FailedScheduling count=None msg=0/6 nodes are available: 1 c_wall violated: 1 conflicting context pair(s) with node memory, 5 node(s) had untolerated taint(s). no new claims to deallocate, preemption: 0/6 nodes are available: 1 No preemption victims found for incoming pod, 5 Preemption is not helpful for scheduling."
27.6339,Pod,MODIFIED,eval-sanitize-20-r3-019-jntlw,phase=Pending node=None
27.6525,Pod,MODIFIED,eval-sanitize-20-r3-020-z7jzd,phase=Pending node=kind-worker
27.6552,Pod,MODIFIED,eval-sanitize-20-r3-021-xmp2g,phase=Pending node=None
27.6555,Event,ADDED,eval-sanitize-20-r3-021-xmp2g.18d41b2df12582e1,"reason=FailedScheduling count=None msg=0/6 nodes are available: 1 c_wall violated: 3 conflicting context pair(s) with node memory, 5 node(s) had untolerated taint(s). no new claims to deallocate, preemption: 0/6 nodes are available: 1 No preemption victims found for incoming pod, 5 Preemption is not helpful for scheduling."
27.6579,Event,ADDED,eval-sanitize-20-r3-020-z7jzd.18d41b2df1414e4e,reason=Scheduled count=None msg=Successfully assigned compute/eval-sanitize-20-r3-020-z7jzd to kind-worker
27.6637,Pod,MODIFIED,eval-sanitize-20-r3-020-z7jzd,phase=Pending node=kind-worker
27.6971,Pod,MODIFIED,eval-sanitize-20-r3-022-22zpt,phase=Pending node=kind-worker
27.6989,Pod,MODIFIED,eval-sanitize-20-r3-023-l94v5,phase=Pending node=None
27.6991,Event,ADDED,eval-sanitize-20-r3-023-l94v5.18d41b2df3bfddbe,"reason=FailedScheduling count=None msg=0/6 nodes are available: 1 c_wall violated: 2 conflicting context pair(s) with node memory, 5 node(s) had untolerated taint(s). no new claims to deallocate, preemption: 0/6 nodes are available: 1 No preemption victims found for incoming pod, 5 Preemption is not helpful for scheduling."
27.7006,Event,ADDED,eval-sanitize-20-r3-022-22zpt.18d41b2df3ed05f7,reason=Scheduled count=None msg=Successfully assigned compute/eval-sanitize-20-r3-022-22zpt to kind-worker
27.7078,Pod,MODIFIED,eval-sanitize-20-r3-022-22zpt,phase=Pending node=kind-worker
27.7094,Pod,MODIFIED,eval-sanitize-20-r3-024-7v9kq,phase=Pending node=kind-worker
27.7182,Event,ADDED,eval-sanitize-20-r3-024-7v9kq.18d41b2df4a9398a,reason=Scheduled count=None msg=Successfully assigned compute/eval-sanitize-20-r3-024-7v9kq to kind-worker
27.724,Pod,MODIFIED,eval-sanitize-20-r3-024-7v9kq,phase=Pending node=kind-worker
27.7523,Node,MODIFIED,kind-worker4,taints=1
27.753,Event,ADDED,eval-sanitize-20-r3-025-928bl.18d41b2df6ede65d,"reason=FailedScheduling count=None msg=0/6 nodes are available: 1 c_wall violated: 2 conflicting context pair(s) with node memory, 5 node(s) had untolerated taint(s). no new claims to deallocate, preemption: 0/6 nodes are available: 1 No preemption victims found for incoming pod, 5 Preemption is not helpful for scheduling."
27.7542,Pod,MODIFIED,eval-sanitize-20-r3-025-928bl,phase=Pending node=None
27.7623,Pod,MODIFIED,eval-sanitize-20-r3-026-4255x,phase=Pending node=None
27.7626,Event,ADDED,eval-sanitize-20-r3-026-4255x.18d41b2df7827851,"reason=FailedScheduling count=None msg=0/6 nodes are available: 1 c_wall violated: 3 conflicting context pair(s) with node memory, 5 node(s) had untolerated taint(s). no new claims to deallocate, preemption: 0/6 nodes are available: 1 No preemption victims found for incoming pod, 5 Preemption is not helpful for scheduling."
27.7695,Pod,MODIFIED,eval-sanitize-20-r3-027-p6tjp,phase=Pending node=None
27.7698,Event,ADDED,eval-sanitize-20-r3-027-p6tjp.18d41b2df7fae7d4,"reason=FailedScheduling count=None msg=0/6 nodes are available: 1 c_wall violated: 3 conflicting context pair(s) with node memory, 5 node(s) had untolerated taint(s). no new claims to deallocate, preemption: 0/6 nodes are available: 1 No preemption victims found for incoming pod, 5 Preemption is not helpful for scheduling."
27.7994,Pod,MODIFIED,eval-sanitize-20-r3-010-85ngc,phase=Pending node=None
27.8006,Event,ADDED,eval-sanitize-20-r3-010-85ngc.18d41b2df9aff3b3,"reason=FailedScheduling count=None msg=0/6 nodes are available: 1 c_wall violated: 3 conflicting context pair(s) with node memory, 5 node(s) had untolerated taint(s). no new claims to deallocate, preemption: 0/6 nodes are available: 1 No preemption victims found for incoming pod, 5 Preemption is not helpful for scheduling."
27.8099,Pod,MODIFIED,eval-sanitize-20-r3-012-cqb84,phase=Pending node=None
27.8103,Event,ADDED,eval-sanitize-20-r3-012-cqb84.18d41b2dfa35c78f,"reason=FailedScheduling count=None msg=0/6 nodes are available: 1 c_wall violated: 2 conflicting context pair(s) with node memory, 5 node(s) had untolerated taint(s). no new claims to deallocate, preemption: 0/6 nodes are available: 1 No preemption victims found for incoming pod, 5 Preemption is not helpful for scheduling."
27.8171,Event,ADDED,eval-sanitize-20-r3-014-7fzzg.18d41b2dfad2abba,"reason=FailedScheduling count=None msg=0/6 nodes are available: 1 c_wall violated: 2 conflicting context pair(s) with node memory, 5 node(s) had untolerated taint(s). no new claims to deallocate, preemption: 0/6 nodes are available: 1 No preemption victims found for incoming pod, 5 Preemption is not helpful for scheduling."
27.8218,Node,MODIFIED,kind-worker4,taints=1
27.8242,Event,ADDED,eval-sanitize-20-r3-015-7nhgg.18d41b2dfb086cb8,"reason=FailedScheduling count=None msg=0/6 nodes are available: 1 c_wall violated: 2 conflicting context pair(s) with node memory, 5 node(s) had untolerated taint(s). no new claims to deallocate, preemption: 0/6 nodes are available: 1 No preemption victims found for incoming pod, 5 Preemption is not helpful for scheduling."
27.8266,Event,ADDED,eval-sanitize-20-r3-016-wg4b2.18d41b2dfb434164,"reason=FailedScheduling count=None msg=0/6 nodes are available: 1 c_wall violated: 2 conflicting context pair(s) with node memory, 5 node(s) had untolerated taint(s). no new claims to deallocate, preemption: 0/6 nodes are available: 1 No preemption victims found for incoming pod, 5 Preemption is not helpful for scheduling."
27.8334,Node,MODIFIED,kind-worker4,taints=0
27.8478,Node,MODIFIED,kind-worker4,taints=0
27.8577,Event,ADDED,eval-sanitize-20-r3-018-mnx7g.18d41b2dfd1766ee,"reason=FailedScheduling count=None msg=0/6 nodes are available: 1 c_wall violated: 2 conflicting context pair(s) with node memory, 5 node(s) had untolerated taint(s). no new claims to deallocate, preemption: 0/6 nodes are available: 1 No preemption victims found for incoming pod, 5 Preemption is not helpful for scheduling."
27.861,Pod,MODIFIED,eval-sanitize-20-r3-019-jntlw,phase=Pending node=kind-worker4
27.8652,Event,ADDED,eval-sanitize-20-r3-019-jntlw.18d41b2dfdaafbc4,reason=Scheduled count=None msg=Successfully assigned compute/eval-sanitize-20-r3-019-jntlw to kind-worker4
27.872,Node,MODIFIED,kind-worker4,taints=0
27.874,Pod,MODIFIED,eval-sanitize-20-r3-019-jntlw,phase=Pending node=kind-worker4
27.8821,Node,MODIFIED,kind-worker4,taints=0
27.912,Event,ADDED,eval-sanitize-20-r3-021-xmp2g.18d41b2dffec6199,"reason=FailedScheduling count=None msg=0/6 nodes are available: 1 c_wall violated: 1 conflicting context pair(s) with node memory, 1 c_wall violated: 3 conflicting context pair(s) with node memory, 4 node(s) had untolerated taint(s). no new claims to deallocate, preemption: 0/6 nodes are available: 2 No preemption victims found for incoming pod, 4 Preemption is not helpful for scheduling."
27.9135,Pod,MODIFIED,eval-sanitize-20-r3-021-xmp2g,phase=Pending node=None
27.9272,Event,ADDED,eval-sanitize-20-r3-009-b98dg.18d41b2e0160e32b,"reason=Pulled count=1 msg=Container image ""busybox:musl"" already present on machine"
27.9404,Event,ADDED,eval-sanitize-20-r3-011-7pmrj.18d41b2e02178802,"reason=Pulled count=1 msg=Container image ""busybox:musl"" already present on machine"
27.957,Pod,MODIFIED,eval-sanitize-20-r3-023-l94v5,phase=Pending node=None
27.9579,Event,ADDED,eval-sanitize-20-r3-023-l94v5.18d41b2e030b7bc9,"reason=FailedScheduling count=None msg=0/6 nodes are available: 1 c_wall violated: 1 conflicting context pair(s) with node memory, 1 c_wall violated: 2 conflicting context pair(s) with node memory, 4 node(s) had untolerated taint(s). no new claims to deallocate, preemption: 0/6 nodes are available: 2 No preemption victims found for incoming pod, 4 Preemption is not helpful for scheduling."
27.9581,Event,ADDED,eval-sanitize-20-r3-009-b98dg.18d41b2e032dcd78,reason=Created count=1 msg=Created container: task
27.9679,Event,ADDED,eval-sanitize-20-r3-011-7pmrj.18d41b2e03d00615,reason=Created count=1 msg=Created container: task
28.0032,Pod,MODIFIED,eval-sanitize-20-r3-025-928bl,phase=Pending node=None
28.0037,Event,ADDED,eval-sanitize-20-r3-025-928bl.18d41b2e05a80982,"reason=FailedScheduling count=None msg=0/6 nodes are available: 1 c_wall violated: 1 conflicting context pair(s) with node memory, 1 c_wall violated: 2 conflicting context pair(s) with node memory, 4 node(s) had untolerated taint(s). no new claims to deallocate, preemption: 0/6 nodes are available: 2 No preemption victims found for incoming pod, 4 Preemption is not helpful for scheduling."
28.0116,Event,ADDED,eval-sanitize-20-r3-013-98nmn.18d41b2e062874de,"reason=Pulled count=1 msg=Container image ""busybox:musl"" already present on machine"
28.0117,TaskRequest,ADDED,eval-sanitize-20-r3-028,phase=None job=None
28.0173,Pod,MODIFIED,eval-sanitize-20-r3-026-4255x,phase=Pending node=kind-worker4
28.0175,TaskRequest,MODIFIED,eval-sanitize-20-r3-028,phase=Pending job=None
28.0178,Event,ADDED,eval-sanitize-20-r3-009-b98dg.18d41b2e069b2e8e,reason=Started count=1 msg=Started container task
28.0219,Event,ADDED,eval-sanitize-20-r3-026-4255x.18d41b2e07006236,reason=Scheduled count=None msg=Successfully assigned compute/eval-sanitize-20-r3-026-4255x to kind-worker4
28.0274,Event,ADDED,eval-sanitize-20-r3-011-7pmrj.18d41b2e069d8107,reason=Started count=1 msg=Started container task
28.0311,Event,ADDED,eval-sanitize-20-r3-027-p6tjp.18d41b2e073a5064,"reason=FailedScheduling count=None msg=0/6 nodes are available: 1 c_wall violated: 1 conflicting context pair(s) with node memory, 1 c_wall violated: 3 conflicting context pair(s) with node memory, 4 node(s) had untolerated taint(s). no new claims to deallocate, preemption: 0/6 nodes are available: 2 No preemption victims found for incoming pod, 4 Preemption is not helpful for scheduling."
28.0321,Pod,MODIFIED,eval-sanitize-20-r3-027-p6tjp,phase=Pending node=None
28.0333,Pod,MODIFIED,eval-sanitize-20-r3-026-4255x,phase=Pending node=kind-worker4
28.0347,Node,MODIFIED,kind-worker4,taints=0
28.0418,Job,ADDED,eval-sanitize-20-r3-028,
28.0428,Job,MODIFIED,eval-sanitize-20-r3-027,
28.0456,Node,MODIFIED,kind-worker4,taints=0
28.0463,Event,ADDED,eval-sanitize-20-r3-013-98nmn.18d41b2e08634189,reason=Created count=1 msg=Created container: task
28.0505,Pod,ADDED,eval-sanitize-20-r3-028-cc6vw,phase=Pending node=None
28.0507,TaskRequest,MODIFIED,eval-sanitize-20-r3-028,phase=Scheduled job=None
28.0535,Job,MODIFIED,eval-sanitize-20-r3-028,
28.0563,Event,ADDED,eval-sanitize-20-r3-028.18d41b2e08ea876d,reason=SuccessfulCreate count=1 msg=Created pod: eval-sanitize-20-r3-028-cc6vw
28.06,TaskRequest,MODIFIED,eval-sanitize-20-r3-028,phase=Scheduled job=None
28.0629,Job,MODIFIED,eval-sanitize-20-r3-027,
28.089,Event,ADDED,eval-sanitize-20-r3-017-zwmxm.18d41b2e0af52b6b,"reason=Pulled count=1 msg=Container image ""busybox:musl"" already present on machine"
28.0967,Pod,MODIFIED,eval-sanitize-20-r3-010-85ngc,phase=Pending node=kind-worker4
28.0972,Event,ADDED,eval-sanitize-20-r3-013-98nmn.18d41b2e0b49b86a,reason=Started count=1 msg=Started container task
28.1028,Event,ADDED,eval-sanitize-20-r3-010-85ngc.18d41b2e0bad37d7,reason=Scheduled count=None msg=Successfully assigned compute/eval-sanitize-20-r3-010-85ngc to kind-worker4
28.104,Event,ADDED,eval-sanitize-20-r3-020-z7jzd.18d41b2e0b824370,"reason=Pulled count=1 msg=Container image ""busybox:musl"" already present on machine"
28.1105,Pod,MODIFIED,eval-sanitize-20-r3-010-85ngc,phase=Pending node=kind-worker4
28.1205,Event,ADDED,eval-sanitize-20-r3-017-zwmxm.18d41b2e0cd5eb60,reason=Created count=1 msg=Created container: task
28.1255,Pod,MODIFIED,eval-sanitize-20-r3-028-cc6vw,phase=Pending node=kind-worker
28.1274,Event,ADDED,eval-sanitize-20-r3-020-z7jzd.18d41b2e0d4f5c64,reason=Created count=1 msg=Created container: task
28.131,Event,ADDED,eval-sanitize-20-r3-028-cc6vw.18d41b2e0d6fe694,reason=Scheduled count=None msg=Successfully assigned compute/eval-sanitize-20-r3-028-cc6vw to kind-worker
28.1329,Pod,MODIFIED,eval-sanitize-20-r3-012-cqb84,phase=Pending node=kind-worker4
28.1388,Pod,MODIFIED,eval-sanitize-20-r3-028-cc6vw,phase=Pending node=kind-worker
28.1392,Event,ADDED,eval-sanitize-20-r3-012-cqb84.18d41b2e0de23ae7,reason=Scheduled count=None msg=Successfully assigned compute/eval-sanitize-20-r3-012-cqb84 to kind-worker4
28.144,Node,MODIFIED,kind-worker4,taints=0
28.146,Pod,MODIFIED,eval-sanitize-20-r3-012-cqb84,phase=Pending node=kind-worker4
28.1551,Node,MODIFIED,kind-worker4,taints=0
28.181,Event,ADDED,eval-sanitize-20-r3-024-7v9kq.18d41b2e1060d778,"reason=Pulled count=1 msg=Container image ""busybox:musl"" already present on machine"
28.1915,Event,ADDED,eval-sanitize-20-r3-020-z7jzd.18d41b2e11222145,reason=Started count=1 msg=Started container task
28.1978,Pod,MODIFIED,eval-sanitize-20-r3-014-7fzzg,phase=Pending node=None
28.1981,Event,ADDED,eval-sanitize-20-r3-017-zwmxm.18d41b2e1122a3fe,reason=Started count=1 msg=Started container task
28.1985,Event,MODIFIED,eval-sanitize-20-r3-014-7fzzg.18d41b2dfad2abba,"reason=FailedScheduling count=None msg=0/6 nodes are available: 1 c_wall violated: 2 conflicting context pair(s) with node memory, 5 node(s) had untolerated taint(s). no new claims to deallocate, preemption: 0/6 nodes are available: 1 No preemption victims found for incoming pod, 5 Preemption is not helpful for scheduling."
28.2043,Event,ADDED,eval-sanitize-20-r3-022-22zpt.18d41b2e11250c47,"reason=Pulled count=1 msg=Container image ""busybox:musl"" already present on machine"
28.2092,Event,ADDED,eval-sanitize-20-r3-024-7v9kq.18d41b2e11f05d94,reason=Created count=1 msg=Created container: task
28.2164,Event,ADDED,eval-sanitize-20-r3-022-22zpt.18d41b2e12aca068,reason=Created count=1 msg=Created container: task
28.2274,Pod,MODIFIED,eval-sanitize-20-r3-015-7nhgg,phase=Pending node=None
28.2277,Event,MODIFIED,eval-sanitize-20-r3-015-7nhgg.18d41b2dfb086cb8,"reason=FailedScheduling count=None msg=0/6 nodes are available: 1 c_wall violated: 2 conflicting context pair(s) with node memory, 5 node(s) had untolerated taint(s). no new claims to deallocate, preemption: 0/6 nodes are available: 1 No preemption victims found for incoming pod, 5 Preemption is not helpful for scheduling."
28.26,Node,MODIFIED,kind-worker3,taints=1
28.2707,Event,ADDED,eval-sanitize-20-r3-024-7v9kq.18d41b2e15dd30e5,reason=Started count=1 msg=Started container task
28.2761,Event,ADDED,eval-sanitize-20-r3-022-22zpt.18d41b2e1611b713,reason=Started count=1 msg=Started container task
28.2916,Pod,MODIFIED,eval-sanitize-20-r3-016-wg4b2,phase=Pending node=kind-worker4
28.2967,Event,ADDED,eval-sanitize-20-r3-016-wg4b2.18d41b2e1750fb35,reason=Scheduled count=None msg=Successfully assigned compute/eval-sanitize-20-r3-016-wg4b2 to kind-worker4
28.2997,Pod,MODIFIED,eval-sanitize-20-r3-018-mnx7g,phase=Pending node=None
28.3003,Event,MODIFIED,eval-sanitize-20-r3-018-mnx7g.18d41b2dfd1766ee,"reason=FailedScheduling count=None msg=0/6 nodes are available: 1 c_wall violated: 2 conflicting context pair(s) with node memory, 5 node(s) had untolerated taint(s). no new claims to deallocate, preemption: 0/6 nodes are available: 1 No preemption victims found for incoming pod, 5 Preemption is not helpful for scheduling."
28.305,Pod,MODIFIED,eval-sanitize-20-r3-016-wg4b2,phase=Pending node=kind-worker4
28.3222,Node,MODIFIED,kind-worker3,taints=1
28.3271,Event,ADDED,eval-sanitize-20-r3-019-jntlw.18d41b2e18fb6ef3,"reason=Pulled count=1 msg=Container image ""busybox:musl"" already present on machine"
28.3305,Pod,MODIFIED,eval-sanitize-20-r3-021-xmp2g,phase=Pending node=None
28.3307,Event,ADDED,eval-sanitize-20-r3-021-xmp2g.18d41b2e1953acf8,"reason=FailedScheduling count=None msg=0/6 nodes are available: 1 c_wall violated: 2 conflicting context pair(s) with node memory, 1 c_wall violated: 3 conflicting context pair(s) with node memory, 4 node(s) had untolerated taint(s). no new claims to deallocate, preemption: 0/6 nodes are available: 2 No preemption victims found for incoming pod, 4 Preemption is not helpful for scheduling."
28.3362,Node,MODIFIED,kind-worker3,taints=0
28.3446,Event,ADDED,eval-sanitize-20-r3-019-jntlw.18d41b2e1a51fbca,reason=Created count=1 msg=Created container: task
28.3484,Node,MODIFIED,kind-worker3,taints=0
28.3964,Event,ADDED,eval-sanitize-20-r3-023-l94v5.18d41b2e1d437fe6,"reason=FailedScheduling count=None msg=0/6 nodes are available: 1 c_wall violated: 1 conflicting context pair(s) with node memory, 1 c_wall violated: 2 conflicting context pair(s) with node memory, 4 node(s) had untolerated taint(s). no new claims to deallocate, preemption: 0/6 nodes are available: 2 No preemption victims found for incoming pod, 4 Preemption is not helpful for scheduling."
28.414,Event,ADDED,eval-sanitize-20-r3-019-jntlw.18d41b2e1e5f3a3f,reason=Started count=1 msg=Started container task
28.4259,Pod,MODIFIED,eval-sanitize-20-r3-025-928bl,phase=Pending node=kind-worker3
28.4305,Event,ADDED,eval-sanitize-20-r3-025-928bl.18d41b2e1f55e911,reason=Scheduled count=None msg=Successfully assigned compute/eval-sanitize-20-r3-025-928bl to kind-worker3
28.4356,Node,MODIFIED,kind-worker3,taints=0
28.4373,Pod,MODIFIED,eval-sanitize-20-r3-025-928bl,phase=Pending node=kind-worker3
28.4469,Node,MODIFIED,kind-worker3,taints=0
28.4968,Event,ADDED,eval-sanitize-20-r3-026-4255x.18d41b2e231ed7dc,"reason=Pulled count=1 msg=Container image ""busybox:musl"" already present on machine"
28.499,Pod,MODIFIED,eval-sanitize-20-r3-027-p6tjp,phase=Pending node=kind-worker3
28.5047,Event,ADDED,eval-sanitize-20-r3-027-p6tjp.18d41b2e23a7d9e0,reason=Scheduled count=None msg=Successfully assigned compute/eval-sanitize-20-r3-027-p6tjp to kind-worker3
28.5123,Node,MODIFIED,kind-worker3,taints=0
28.5144,Pod,MODIFIED,eval-sanitize-20-r3-027-p6tjp,phase=Pending node=kind-worker3
28.5251,Node,MODIFIED,kind-worker3,taints=0
28.5266,Event,ADDED,eval-sanitize-20-r3-026-4255x.18d41b2e25076682,reason=Created count=1 msg=Created container: task
28.5285,Event,ADDED,eval-sanitize-20-r3-014-7fzzg.18d41b2e252e52e1,"reason=FailedScheduling count=None msg=0/6 nodes are available: 1 c_wall violated: 2 conflicting context pair(s) with node memory, 2 c_wall violated: 1 conflicting context pair(s) with node memory, 3 node(s) had untolerated taint(s). no new claims to deallocate, preemption: 0/6 nodes are available: 3 No preemption victims found for incoming pod, 3 Preemption is not helpful for scheduling."
28.5296,Pod,MODIFIED,eval-sanitize-20-r3-014-7fzzg,phase=Pending node=None
28.579,Event,ADDED,eval-sanitize-20-r3-010-85ngc.18d41b2e28346732,"reason=Pulled count=1 msg=Container image ""busybox:musl"" already present on machine"
28.5804,Event,ADDED,eval-sanitize-20-r3-028-cc6vw.18d41b2e2839c410,"reason=Pulled count=1 msg=Container image ""busybox:musl"" already present on machine"
28.5886,Event,ADDED,eval-sanitize-20-r3-026-4255x.18d41b2e28befde3,reason=Started count=1 msg=Started container task
28.5957,Event,ADDED,eval-sanitize-20-r3-012-cqb84.18d41b2e28bf319c,"reason=Pulled count=1 msg=Container image ""busybox:musl"" already present on machine"
28.6115,Event,ADDED,eval-sanitize-20-r3-010-85ngc.18d41b2e2a361843,reason=Created count=1 msg=Created container: task
28.6137,Event,ADDED,eval-sanitize-20-r3-028-cc6vw.18d41b2e2a579d93,reason=Created count=1 msg=Created container: task
28.6229,Event,ADDED,eval-sanitize-20-r3-012-cqb84.18d41b2e2addc084,reason=Created count=1 msg=Created container: task
28.6265,Pod,MODIFIED,eval-sanitize-20-r3-015-7nhgg,phase=Pending node=kind-worker3
28.6306,Event,ADDED,eval-sanitize-20-r3-015-7nhgg.18d41b2e2b472875,reason=Scheduled count=None msg=Successfully assigned compute/eval-sanitize-20-r3-015-7nhgg to kind-worker3
28.6385,Node,MODIFIED,kind-worker3,taints=0
28.6399,Pod,MODIFIED,eval-sanitize-20-r3-015-7nhgg,phase=Pending node=kind-worker3
28.6498,Node,MODIFIED,kind-worker3,taints=0
28.6824,Pod,MODIFIED,eval-sanitize-20-r3-024-7v9kq,phase=Running node=kind-worker
28.686,Event,ADDED,eval-sanitize-20-r3-010-85ngc.18d41b2e2e4ab9c7,reason=Started count=1 msg=Started container task
28.6867,Event,ADDED,eval-sanitize-20-r3-028-cc6vw.18d41b2e2e63e981,reason=Started count=1 msg=Started container task
28.6938,Pod,MODIFIED,eval-sanitize-20-r3-009-b98dg,phase=Running node=kind-worker
28.6941,Event,ADDED,eval-sanitize-20-r3-012-cqb84.18d41b2e2ebeb52d,reason=Started count=1 msg=Started container task
28.6967,Pod,MODIFIED,eval-sanitize-20-r3-018-mnx7g,phase=Pending node=None
28.698,Event,ADDED,eval-sanitize-20-r3-018-mnx7g.18d41b2e2f319fbb,"reason=FailedScheduling count=None msg=0/6 nodes are available: 1 c_wall violated: 2 conflicting context pair(s) with node memory, 2 c_wall violated: 1 conflicting context pair(s) with node memory, 3 node(s) had untolerated taint(s). no new claims to deallocate, preemption: 0/6 nodes are available: 3 No preemption victims found for incoming pod, 3 Preemption is not helpful for scheduling."
28.7017,Pod,MODIFIED,eval-sanitize-20-r3-011-7pmrj,phase=Running node=kind-worker
28.7089,Pod,MODIFIED,eval-sanitize-20-r3-022-22zpt,phase=Running node=kind-worker
28.7146,Pod,MODIFIED,eval-sanitize-20-r3-013-98nmn,phase=Running node=kind-worker
28.7164,Job,MODIFIED,eval-sanitize-20-r3-024,
28.723,Pod,MODIFIED,eval-sanitize-20-r3-017-zwmxm,phase=Running node=kind-worker
28.7265,Job,MODIFIED,eval-sanitize-20-r3-024,
28.7295,Pod,MODIFIED,eval-sanitize-20-r3-020-z7jzd,phase=Running node=kind-worker
28.7298,Event,ADDED,eval-sanitize-20-r3-016-wg4b2.18d41b2e313f4a6d,"reason=Pulled count=1 msg=Container image ""busybox:musl"" already present on machine"
28.749,Event,ADDED,eval-sanitize-20-r3-016-wg4b2.18d41b2e3264c697,reason=Created count=1 msg=Created container: task
28.7986,Pod,MODIFIED,eval-sanitize-20-r3-021-xmp2g,phase=Pending node=kind-worker3
28.8024,Event,ADDED,eval-sanitize-20-r3-021-xmp2g.18d41b2e358b41b2,reason=Scheduled count=None msg=Successfully assigned compute/eval-sanitize-20-r3-021-xmp2g to kind-worker3
28.8094,Pod,MODIFIED,eval-sanitize-20-r3-021-xmp2g,phase=Pending node=kind-worker3
28.8227,Event,ADDED,eval-sanitize-20-r3-016-wg4b2.18d41b2e3690f58a,reason=Started count=1 msg=Started container task
28.829,Pod,MODIFIED,eval-sanitize-20-r3-023-l94v5,phase=Pending node=None
28.8318,Event,MODIFIED,eval-sanitize-20-r3-023-l94v5.18d41b2e1d437fe6,"reason=FailedScheduling count=None msg=0/6 nodes are available: 1 c_wall violated: 1 conflicting context pair(s) with node memory, 1 c_wall violated: 2 conflicting context pair(s) with node memory, 4 node(s) had untolerated taint(s). no new claims to deallocate, preemption: 0/6 nodes are available: 2 No preemption victims found for incoming pod, 4 Preemption is not helpful for scheduling."
28.8639,Node,MODIFIED,kind-worker2,taints=1
28.8781,Node,MODIFIED,kind-worker2,taints=0
28.8916,Node,MODIFIED,kind-worker2,taints=0
28.9039,Node,MODIFIED,kind-worker2,taints=0
28.9069,Event,ADDED,eval-sanitize-20-r3-025-928bl.18d41b2e3bb829cc,"reason=Pulled count=1 msg=Container image ""busybox:musl"" already present on machine"
28.9243,Event,ADDED,eval-sanitize-20-r3-027-p6tjp.18d41b2e3cc0d3f5,"reason=Pulled count=1 msg=Container image ""busybox:musl"" already present on machine"
28.9277,Event,ADDED,eval-sanitize-20-r3-014-7fzzg.18d41b2e3cfe0636,"reason=FailedScheduling count=None msg=0/6 nodes are available: 1 c_wall violated: 2 conflicting context pair(s) with node memory, 2 c_wall violated: 1 conflicting context pair(s) with node memory, 3 node(s) had untolerated taint(s). no new claims to deallocate, preemption: 0/6 nodes are available: 3 No preemption victims found for incoming pod, 3 Preemption is not helpful for scheduling."
28.9327,Pod,MODIFIED,eval-sanitize-20-r3-010-85ngc,phase=Running node=kind-worker4
28.9343,Event,ADDED,eval-sanitize-20-r3-025-928bl.18d41b2e3d46b20f,reason=Created count=1 msg=Created container: task
28.9411,Pod,MODIFIED,eval-sanitize-20-r3-026-4255x,phase=Running node=kind-worker4
28.9484,Pod,MODIFIED,eval-sanitize-20-r3-019-jntlw,phase=Running node=kind-worker4
28.9491,Event,ADDED,eval-sanitize-20-r3-027-p6tjp.18d41b2e3e58b738,reason=Created count=1 msg=Created container: task
28.954,Pod,MODIFIED,eval-sanitize-20-r3-016-wg4b2,phase=Running node=kind-worker4
28.9605,Pod,MODIFIED,eval-sanitize-20-r3-012-cqb84,phase=Running node=kind-worker4
28.9945,Event,ADDED,eval-sanitize-20-r3-025-928bl.18d41b2e40fd5436,reason=Started count=1 msg=Started container task
29.0,Pod,MODIFIED,eval-sanitize-20-r3-018-mnx7g,phase=Pending node=kind-worker2
29.0003,Event,ADDED,eval-sanitize-20-r3-027-p6tjp.18d41b2e413a516a,reason=Started count=1 msg=Started container task
29.0031,Event,ADDED,eval-sanitize-20-r3-018-mnx7g.18d41b2e418e05ef,reason=Scheduled count=None msg=Successfully assigned compute/eval-sanitize-20-r3-018-mnx7g to kind-worker2
29.0104,Pod,MODIFIED,eval-sanitize-20-r3-018-mnx7g,phase=Pending node=kind-worker2
29.0126,Node,MODIFIED,kind-worker2,taints=0
29.0234,Node,MODIFIED,kind-worker2,taints=0
29.0381,Event,ADDED,eval-sanitize-20-r3-015-7nhgg.18d41b2e43a1e0a1,"reason=Pulled count=1 msg=Container image ""busybox:musl"" already present on machine"
29.0548,Job,MODIFIED,eval-sanitize-20-r3-028,
29.0575,Event,ADDED,eval-sanitize-20-r3-015-7nhgg.18d41b2e44bdfb91,reason=Created count=1 msg=Created container: task
29.0637,Job,MODIFIED,eval-sanitize-20-r3-028,
29.0955,TaskRequest,ADDED,eval-sanitize-20-r3-029,phase=None job=None
29.1013,Pod,MODIFIED,eval-sanitize-20-r3-023-l94v5,phase=Pending node=kind-worker2
29.1014,TaskRequest,MODIFIED,eval-sanitize-20-r3-029,phase=Pending job=None
29.1068,Event,ADDED,eval-sanitize-20-r3-023-l94v5.18d41b2e4798fa8a,reason=Scheduled count=None msg=Successfully assigned compute/eval-sanitize-20-r3-023-l94v5 to kind-worker2
29.1142,Pod,MODIFIED,eval-sanitize-20-r3-023-l94v5,phase=Pending node=kind-worker2
29.1193,Job,ADDED,eval-sanitize-20-r3-029,
29.1257,Pod,ADDED,eval-sanitize-20-r3-029-mpn7t,phase=Pending node=None
29.1268,Event,ADDED,eval-sanitize-20-r3-015-7nhgg.18d41b2e48d6892b,reason=Started count=1 msg=Started container task
29.1269,TaskRequest,MODIFIED,eval-sanitize-20-r3-029,phase=Scheduled job=None
29.1295,Job,MODIFIED,eval-sanitize-20-r3-029,
29.1311,Event,ADDED,eval-sanitize-20-r3-029.18d41b2e4910574d,reason=SuccessfulCreate count=1 msg=Created pod: eval-sanitize-20-r3-029-mpn7t
29.1354,TaskRequest,MODIFIED,eval-sanitize-20-r3-029,phase=Scheduled job=None
29.1391,Job,MODIFIED,eval-sanitize-20-r3-029,
29.1479,Job,MODIFIED,eval-sanitize-20-r3-029,
29.2196,Event,ADDED,eval-sanitize-20-r3-021-xmp2g.18d41b2e4e674db3,"reason=Pulled count=1 msg=Container image ""busybox:musl"" already present on machine"
29.2273,Node,MODIFIED,kind-worker5,taints=1
29.2283,Pod,MODIFIED,eval-sanitize-20-r3-014-7fzzg,phase=Pending node=kind-worker2
29.2323,Event,ADDED,eval-sanitize-20-r3-014-7fzzg.18d41b2e4f17a2ef,reason=Scheduled count=None msg=Successfully assigned compute/eval-sanitize-20-r3-014-7fzzg to kind-worker2
29.2389,Pod,MODIFIED,eval-sanitize-20-r3-014-7fzzg,phase=Pending node=kind-worker2
29.2423,Node,MODIFIED,kind-worker5,taints=1
29.2435,Event,ADDED,eval-sanitize-20-r3-021-xmp2g.18d41b2e4fe34033,reason=Created count=1 msg=Created container: task
29.2507,Node,MODIFIED,kind-worker5,taints=0
29.2779,Event,ADDED,eval-sanitize-20-r3-021-xmp2g.18d41b2e51e6d2c5,reason=Started count=1 msg=Started container task
29.3087,Pod,MODIFIED,eval-sanitize-20-r3-029-mpn7t,phase=Pending node=kind-worker3
29.3116,Event,ADDED,eval-sanitize-20-r3-029-mpn7t.18d41b2e53ee4e11,reason=Scheduled count=None msg=Successfully assigned compute/eval-sanitize-20-r3-029-mpn7t to kind-worker3
29.3184,Pod,MODIFIED,eval-sanitize-20-r3-029-mpn7t,phase=Pending node=kind-worker3
29.3218,Node,MODIFIED,kind-worker5,taints=0
29.4288,Event,ADDED,eval-sanitize-20-r3-018-mnx7g.18d41b2e5add787a,"reason=Pulled count=1 msg=Container image ""busybox:musl"" already present on machine"
29.449,Event,ADDED,eval-sanitize-20-r3-018-mnx7g.18d41b2e5c157145,reason=Created count=1 msg=Created container: task
29.5171,Pod,MODIFIED,eval-sanitize-20-r3-021-xmp2g,phase=Running node=kind-worker3
29.5196,Event,ADDED,eval-sanitize-20-r3-018-mnx7g.18d41b2e603c9e46,reason=Started count=1 msg=Started container task
29.5235,Pod,MODIFIED,eval-sanitize-20-r3-015-7nhgg,phase=Running node=kind-worker3
29.5259,Event,ADDED,eval-sanitize-20-r3-023-l94v5.18d41b2e60bd12cd,"reason=Pulled count=1 msg=Container image ""busybox:musl"" already present on machine"
29.5308,Pod,MODIFIED,eval-sanitize-20-r3-025-928bl,phase=Running node=kind-worker3
29.5381,Pod,MODIFIED,eval-sanitize-20-r3-027-p6tjp,phase=Running node=kind-worker3
29.549,Event,ADDED,eval-sanitize-20-r3-023-l94v5.18d41b2e62028348,reason=Created count=1 msg=Created container: task
29.6035,Event,ADDED,eval-sanitize-20-r3-023-l94v5.18d41b2e654805a4,reason=Started count=1 msg=Started container task
29.633,Job,MODIFIED,eval-sanitize-20-r3-015,
29.6398,Event,ADDED,eval-sanitize-20-r3-014-7fzzg.18d41b2e675f5609,"reason=Pulled count=1 msg=Container image ""busybox:musl"" already present on machine"
29.6435,Job,MODIFIED,eval-sanitize-20-r3-015,
29.6656,Event,ADDED,eval-sanitize-20-r3-014-7fzzg.18d41b2e68e56314,reason=Created count=1 msg=Created container: task
29.6984,Pod,MODIFIED,eval-sanitize-20-r3-028-cc6vw,phase=Running node=kind-worker
29.6994,Job,MODIFIED,eval-sanitize-20-r3-009,
29.7069,Job,MODIFIED,eval-sanitize-20-r3-011,
29.7093,Job,MODIFIED,eval-sanitize-20-r3-009,
29.7137,Job,MODIFIED,eval-sanitize-20-r3-022,
29.7166,Job,MODIFIED,eval-sanitize-20-r3-011,
29.7195,Job,MODIFIED,eval-sanitize-20-r3-013,
29.7228,Job,MODIFIED,eval-sanitize-20-r3-022,
29.7268,Job,MODIFIED,eval-sanitize-20-r3-017,
29.729,Job,MODIFIED,eval-sanitize-20-r3-013,
29.7338,Job,MODIFIED,eval-sanitize-20-r3-020,
29.7378,Job,MODIFIED,eval-sanitize-20-r3-017,
29.7397,Event,ADDED,eval-sanitize-20-r3-014-7fzzg.18d41b2e6d76877f,reason=Started count=1 msg=Started container task
29.7437,Job,MODIFIED,eval-sanitize-20-r3-020,
29.744,Event,ADDED,eval-sanitize-20-r3-029-mpn7t.18d41b2e6db26ed6,"reason=Pulled count=1 msg=Container image ""busybox:musl"" already present on machine"
29.7639,Event,ADDED,eval-sanitize-20-r3-029-mpn7t.18d41b2e6ed8ae86,reason=Created count=1 msg=Created container: task
29.8047,Job,MODIFIED,eval-sanitize-20-r3-021,
29.8144,Job,MODIFIED,eval-sanitize-20-r3-021,
29.8313,Event,ADDED,eval-sanitize-20-r3-029-mpn7t.18d41b2e72d54c0a,reason=Started count=1 msg=Started container task
29.9391,Job,MODIFIED,eval-sanitize-20-r3-010,
29.946,Pod,MODIFIED,eval-sanitize-20-r3-023-l94v5,phase=Running node=kind-worker2
29.9469,Job,MODIFIED,eval-sanitize-20-r3-026,
29.949,Job,MODIFIED,eval-sanitize-20-r3-010,
29.9518,Pod,MODIFIED,eval-sanitize-20-r3-018-mnx7g,phase=Running node=kind-worker2
29.9531,Job,MODIFIED,eval-sanitize-20-r3-019,
29.9558,Job,MODIFIED,eval-sanitize-20-r3-026,
29.9584,Pod,MODIFIED,eval-sanitize-20-r3-014-7fzzg,phase=Running node=kind-worker2
29.9595,Job,MODIFIED,eval-sanitize-20-r3-016,
29.9617,Job,MODIFIED,eval-sanitize-20-r3-019,
29.9646,Job,MODIFIED,eval-sanitize-20-r3-012,
29.9678,Job,MODIFIED,eval-sanitize-20-r3-016,
29.9751,Job,MODIFIED,eval-sanitize-20-r3-012,
30.0125,TaskRequest,ADDED,eval-sanitize-20-r3-030,phase=None job=None
30.0162,TaskRequest,MODIFIED,eval-sanitize-20-r3-030,phase=Pending job=None
30.0313,Job,ADDED,eval-sanitize-20-r3-030,
30.0379,Pod,ADDED,eval-sanitize-20-r3-030-tqczp,phase=Pending node=None
30.0381,TaskRequest,MODIFIED,eval-sanitize-20-r3-030,phase=Scheduled job=None
30.0408,Job,MODIFIED,eval-sanitize-20-r3-030,
30.0432,Event,ADDED,eval-sanitize-20-r3-030.18d41b2e7f7131f9,reason=SuccessfulCreate count=1 msg=Created pod: eval-sanitize-20-r3-030-tqczp
30.0442,TaskRequest,MODIFIED,eval-sanitize-20-r3-030,phase=Scheduled job=None
30.0594,Job,MODIFIED,eval-sanitize-20-r3-028,
30.0621,Pod,MODIFIED,eval-sanitize-20-r3-030-tqczp,phase=Pending node=kind-worker5
30.0653,Event,ADDED,eval-sanitize-20-r3-030-tqczp.18d41b2e80dd12bd,reason=Scheduled count=None msg=Successfully assigned compute/eval-sanitize-20-r3-030-tqczp to kind-worker5
30.0692,Job,MODIFIED,eval-sanitize-20-r3-028,
30.0718,Node,MODIFIED,kind-worker5,taints=0
30.0738,Pod,MODIFIED,eval-sanitize-20-r3-030-tqczp,phase=Pending node=kind-worker5
30.082,Node,MODIFIED,kind-worker5,taints=0
30.2332,Job,MODIFIED,eval-sanitize-20-r3-014,
30.242,Job,MODIFIED,eval-sanitize-20-r3-014,
30.4908,Event,ADDED,eval-sanitize-20-r3-030-tqczp.18d41b2e9a1f7034,"reason=Pulled count=1 msg=Container image ""busybox:musl"" already present on machine"
30.5073,Event,ADDED,eval-sanitize-20-r3-030-tqczp.18d41b2e9b3cde86,reason=Created count=1 msg=Created container: task
30.5213,Pod,MODIFIED,eval-sanitize-20-r3-029-mpn7t,phase=Running node=kind-worker3
30.5356,Job,MODIFIED,eval-sanitize-20-r3-025,
30.5422,Job,MODIFIED,eval-sanitize-20-r3-027,
30.5425,Event,ADDED,eval-sanitize-20-r3-030-tqczp.18d41b2e9d3f489f,reason=Started count=1 msg=Started container task
30.5446,Job,MODIFIED,eval-sanitize-20-r3-025,
30.5506,Job,MODIFIED,eval-sanitize-20-r3-027,
30.9522,Job,MODIFIED,eval-sanitize-20-r3-023,
30.9562,Job,MODIFIED,eval-sanitize-20-r3-018,
30.9616,Job,MODIFIED,eval-sanitize-20-r3-023,
30.9655,Job,MODIFIED,eval-sanitize-20-r3-018,
31.0084,TaskRequest,ADDED,eval-sanitize-20-r3-031,phase=None job=None
31.0138,TaskRequest,MODIFIED,eval-sanitize-20-r3-031,phase=Pending job=None
31.0309,Job,ADDED,eval-sanitize-20-r3-031,
31.0349,TaskRequest,MODIFIED,eval-sanitize-20-r3-031,phase=Scheduled job=None
31.0385,Pod,ADDED,eval-sanitize-20-r3-031-92b5r,phase=Pending node=None
31.0403,Job,MODIFIED,eval-sanitize-20-r3-031,
31.0441,Event,ADDED,eval-sanitize-20-r3-031.18d41b2ebb149c62,reason=SuccessfulCreate count=1 msg=Created pod: eval-sanitize-20-r3-031-92b5r
31.0442,TaskRequest,MODIFIED,eval-sanitize-20-r3-031,phase=Scheduled job=None
31.045,Job,MODIFIED,eval-sanitize-20-r3-030,
31.0553,Job,MODIFIED,eval-sanitize-20-r3-030,
31.0999,Pod,MODIFIED,eval-sanitize-20-r3-030-tqczp,phase=Running node=kind-worker5
31.1291,Pod,MODIFIED,eval-sanitize-20-r3-031-92b5r,phase=Pending node=kind-worker3
31.1327,Event,ADDED,eval-sanitize-20-r3-031-92b5r.18d41b2ec07c7ff9,reason=Scheduled count=None msg=Successfully assigned compute/eval-sanitize-20-r3-031-92b5r to kind-worker3
31.1388,Pod,MODIFIED,eval-sanitize-20-r3-031-92b5r,phase=Pending node=kind-worker3
31.5314,Job,MODIFIED,eval-sanitize-20-r3-029,
31.5419,Job,MODIFIED,eval-sanitize-20-r3-029,
31.5598,Event,ADDED,eval-sanitize-20-r3-031-92b5r.18d41b2ed9e1a7a5,"reason=Pulled count=1 msg=Container image ""busybox:musl"" already present on machine"
31.5789,Event,ADDED,eval-sanitize-20-r3-031-92b5r.18d41b2edb11d287,reason=Created count=1 msg=Created container: task
31.6135,Event,ADDED,eval-sanitize-20-r3-031-92b5r.18d41b2edd12266c,reason=Started count=1 msg=Started container task
32.0084,TaskRequest,ADDED,eval-sanitize-20-r3-032,phase=None job=None
32.0118,TaskRequest,MODIFIED,eval-sanitize-20-r3-032,phase=Pending job=None
32.0276,Job,ADDED,eval-sanitize-20-r3-032,
32.0328,TaskRequest,MODIFIED,eval-sanitize-20-r3-032,phase=Scheduled job=None
32.0358,Pod,ADDED,eval-sanitize-20-r3-032-cr99x,phase=Pending node=None
32.0384,Job,MODIFIED,eval-sanitize-20-r3-032,
32.042,Event,ADDED,eval-sanitize-20-r3-032.18d41b2ef6889d0e,reason=SuccessfulCreate count=1 msg=Created pod: eval-sanitize-20-r3-032-cr99x
32.0421,TaskRequest,MODIFIED,eval-sanitize-20-r3-032,phase=Scheduled job=None
32.0444,Job,MODIFIED,eval-sanitize-20-r3-031,
32.0499,Job,MODIFIED,eval-sanitize-20-r3-030,
32.0554,Job,MODIFIED,eval-sanitize-20-r3-031,
32.0593,Job,MODIFIED,eval-sanitize-20-r3-030,
32.1304,Pod,MODIFIED,eval-sanitize-20-r3-032-cr99x,phase=Pending node=kind-worker5
32.1338,Event,ADDED,eval-sanitize-20-r3-032-cr99x.18d41b2efc2c87b8,reason=Scheduled count=None msg=Successfully assigned compute/eval-sanitize-20-r3-032-cr99x to kind-worker5
32.1399,Pod,MODIFIED,eval-sanitize-20-r3-032-cr99x,phase=Pending node=kind-worker5
32.5289,Pod,MODIFIED,eval-sanitize-20-r3-031-92b5r,phase=Running node=kind-worker3
32.5662,Event,ADDED,eval-sanitize-20-r3-032-cr99x.18d41b2f15c181ae,"reason=Pulled count=1 msg=Container image ""busybox:musl"" already present on machine"
32.5833,Event,ADDED,eval-sanitize-20-r3-032-cr99x.18d41b2f16f0a4d5,reason=Created count=1 msg=Created container: task
32.6387,Event,ADDED,eval-sanitize-20-r3-032-cr99x.18d41b2f1a2a913e,reason=Started count=1 msg=Started container task
33.0229,TaskRequest,ADDED,eval-sanitize-20-r3-033,phase=None job=None
33.0263,TaskRequest,MODIFIED,eval-sanitize-20-r3-033,phase=Pending job=None
33.0409,Job,MODIFIED,eval-sanitize-20-r3-032,
33.0427,Job,ADDED,eval-sanitize-20-r3-033,
33.0471,TaskRequest,MODIFIED,eval-sanitize-20-r3-033,phase=Scheduled job=None
33.05,Job,MODIFIED,eval-sanitize-20-r3-031,
33.0513,Pod,ADDED,eval-sanitize-20-r3-033-mpfrc,phase=Pending node=None
33.0524,Job,MODIFIED,eval-sanitize-20-r3-033,
33.0543,Event,ADDED,eval-sanitize-20-r3-033.18d41b2f32f80217,reason=SuccessfulCreate count=1 msg=Created pod: eval-sanitize-20-r3-033-mpfrc
33.055,TaskRequest,MODIFIED,eval-sanitize-20-r3-033,phase=Scheduled job=None
33.0579,Job,MODIFIED,eval-sanitize-20-r3-032,
33.0612,Job,MODIFIED,eval-sanitize-20-r3-031,
33.1046,Pod,MODIFIED,eval-sanitize-20-r3-032-cr99x,phase=Running node=kind-worker5
33.1308,Pod,MODIFIED,eval-sanitize-20-r3-033-mpfrc,phase=Pending node=kind-worker2
33.1343,Event,ADDED,eval-sanitize-20-r3-033-mpfrc.18d41b2f37ccbcd3,reason=Scheduled count=None msg=Successfully assigned compute/eval-sanitize-20-r3-033-mpfrc to kind-worker2
33.1401,Pod,MODIFIED,eval-sanitize-20-r3-033-mpfrc,phase=Pending node=kind-worker2
33.1426,Node,MODIFIED,kind-worker2,taints=0
33.1525,Node,MODIFIED,kind-worker2,taints=0
33.5435,Event,ADDED,eval-sanitize-20-r3-033-mpfrc.18d41b2f5028d2c5,"reason=Pulled count=1 msg=Container image ""busybox:musl"" already present on machine"
33.5618,Event,ADDED,eval-sanitize-20-r3-033-mpfrc.18d41b2f5140e3e5,reason=Created count=1 msg=Created container: task
33.5946,Event,ADDED,eval-sanitize-20-r3-033-mpfrc.18d41b2f533a1818,reason=Started count=1 msg=Started container task
33.9604,Pod,MODIFIED,eval-sanitize-20-r3-033-mpfrc,phase=Running node=kind-worker2
34.0136,TaskRequest,ADDED,eval-sanitize-20-r3-034,phase=None job=None
34.0183,TaskRequest,MODIFIED,eval-sanitize-20-r3-034,phase=Pending job=None
34.0351,Job,ADDED,eval-sanitize-20-r3-034,
34.0438,Pod,ADDED,eval-sanitize-20-r3-034-bjfdr,phase=Pending node=None
34.0439,TaskRequest,MODIFIED,eval-sanitize-20-r3-034,phase=Scheduled job=None
34.0464,Job,MODIFIED,eval-sanitize-20-r3-034,
34.049,Job,MODIFIED,eval-sanitize-20-r3-032,
34.0494,Event,ADDED,eval-sanitize-20-r3-034.18d41b2f6e2ad810,reason=SuccessfulCreate count=1 msg=Created pod: eval-sanitize-20-r3-034-bjfdr
34.0509,TaskRequest,MODIFIED,eval-sanitize-20-r3-034,phase=Scheduled job=None
34.0549,Job,MODIFIED,eval-sanitize-20-r3-033,
34.0584,Job,MODIFIED,eval-sanitize-20-r3-032,
34.0627,Job,MODIFIED,eval-sanitize-20-r3-033,
34.1299,Pod,MODIFIED,eval-sanitize-20-r3-034-bjfdr,phase=Pending node=kind-worker5
34.1335,Event,ADDED,eval-sanitize-20-r3-034-bjfdr.18d41b2f735724ed,reason=Scheduled count=None msg=Successfully assigned compute/eval-sanitize-20-r3-034-bjfdr to kind-worker5
34.1393,Pod,MODIFIED,eval-sanitize-20-r3-034-bjfdr,phase=Pending node=kind-worker5
34.1418,Node,MODIFIED,kind-worker5,taints=0
34.1516,Node,MODIFIED,kind-worker5,taints=0
34.583,Event,ADDED,eval-sanitize-20-r3-034-bjfdr.18d41b2f8e02963d,"reason=Pulled count=1 msg=Container image ""busybox:musl"" already present on machine"
34.602,Event,ADDED,eval-sanitize-20-r3-034-bjfdr.18d41b2f8f37f84d,reason=Created count=1 msg=Created container: task
34.6416,Event,ADDED,eval-sanitize-20-r3-034-bjfdr.18d41b2f919bae27,reason=Started count=1 msg=Started container task
35.0078,TaskRequest,ADDED,eval-sanitize-20-r3-035,phase=None job=None
35.0133,TaskRequest,MODIFIED,eval-sanitize-20-r3-035,phase=Pending job=None
35.0272,Job,ADDED,eval-sanitize-20-r3-035,
35.0338,Pod,ADDED,eval-sanitize-20-r3-035-p99z2,phase=Pending node=None
35.0351,TaskRequest,MODIFIED,eval-sanitize-20-r3-035,phase=Scheduled job=None
35.0357,Job,MODIFIED,eval-sanitize-20-r3-035,
35.0385,Event,ADDED,eval-sanitize-20-r3-035.18d41b2fa939b417,reason=SuccessfulCreate count=1 msg=Created pod: eval-sanitize-20-r3-035-p99z2
35.0428,TaskRequest,MODIFIED,eval-sanitize-20-r3-035,phase=Scheduled job=None
35.0476,Job,MODIFIED,eval-sanitize-20-r3-034,
35.0571,Job,MODIFIED,eval-sanitize-20-r3-034,
35.1084,Pod,MODIFIED,eval-sanitize-20-r3-034-bjfdr,phase=Running node=kind-worker5
35.129,Pod,MODIFIED,eval-sanitize-20-r3-035-p99z2,phase=Pending node=kind-worker3
35.1327,Event,ADDED,eval-sanitize-20-r3-035-p99z2.18d41b2faee1cf2f,reason=Scheduled count=None msg=Successfully assigned compute/eval-sanitize-20-r3-035-p99z2 to kind-worker3
35.1402,Pod,MODIFIED,eval-sanitize-20-r3-035-p99z2,phase=Pending node=kind-worker3
35.5558,Event,ADDED,eval-sanitize-20-r3-035-p99z2.18d41b2fc801529a,"reason=Pulled count=1 msg=Container image ""busybox:musl"" already present on machine"
35.5736,Event,ADDED,eval-sanitize-20-r3-035-p99z2.18d41b2fc9252a02,reason=Created count=1 msg=Created container: task
35.6096,Event,ADDED,eval-sanitize-20-r3-035-p99z2.18d41b2fcb4ecfd1,reason=Started count=1 msg=Started container task
36.0095,TaskRequest,ADDED,eval-sanitize-20-r3-036,phase=None job=None
36.0135,TaskRequest,MODIFIED,eval-sanitize-20-r3-036,phase=Pending job=None
36.0304,Job,ADDED,eval-sanitize-20-r3-036,
36.0363,Pod,ADDED,eval-sanitize-20-r3-036-slccs,phase=Pending node=None
36.0375,TaskRequest,MODIFIED,eval-sanitize-20-r3-036,phase=Scheduled job=None
36.0404,Job,MODIFIED,eval-sanitize-20-r3-035,
36.0417,Event,ADDED,eval-sanitize-20-r3-036.18d41b2fe4f75829,reason=SuccessfulCreate count=1 msg=Created pod: eval-sanitize-20-r3-036-slccs
36.0423,Job,MODIFIED,eval-sanitize-20-r3-036,
36.0465,TaskRequest,MODIFIED,eval-sanitize-20-r3-036,phase=Scheduled job=None
36.0492,Job,MODIFIED,eval-sanitize-20-r3-035,
36.0527,Job,MODIFIED,eval-sanitize-20-r3-034,
36.0616,Job,MODIFIED,eval-sanitize-20-r3-034,
36.1278,Pod,MODIFIED,eval-sanitize-20-r3-036-slccs,phase=Pending node=kind-worker2
36.1312,Event,ADDED,eval-sanitize-20-r3-036-slccs.18d41b2fea7194f1,reason=Scheduled count=None msg=Successfully assigned compute/eval-sanitize-20-r3-036-slccs to kind-worker2
36.1379,Node,MODIFIED,kind-worker2,taints=0
36.1392,Pod,MODIFIED,eval-sanitize-20-r3-036-slccs,phase=Pending node=kind-worker2
36.1593,Node,MODIFIED,kind-worker2,taints=0
36.5364,Pod,MODIFIED,eval-sanitize-20-r3-035-p99z2,phase=Running node=kind-worker3
36.5467,Event,ADDED,eval-sanitize-20-r3-036-slccs.18d41b30032d734c,"reason=Pulled count=1 msg=Container image ""busybox:musl"" already present on machine"
36.5644,Event,ADDED,eval-sanitize-20-r3-036-slccs.18d41b300440e402,reason=Created count=1 msg=Created container: task
36.6215,Event,ADDED,eval-sanitize-20-r3-036-slccs.18d41b3007967a1d,reason=Started count=1 msg=Started container task
36.9653,Pod,MODIFIED,eval-sanitize-20-r3-036-slccs,phase=Running node=kind-worker2
37.0087,TaskRequest,ADDED,eval-sanitize-20-r3-037,phase=None job=None
37.0123,TaskRequest,MODIFIED,eval-sanitize-20-r3-037,phase=Pending job=None
37.0301,Job,ADDED,eval-sanitize-20-r3-037,
37.0348,TaskRequest,MODIFIED,eval-sanitize-20-r3-037,phase=Scheduled job=None
37.0379,Pod,ADDED,eval-sanitize-20-r3-037-b44z7,phase=Pending node=None
37.0406,Job,MODIFIED,eval-sanitize-20-r3-037,
37.0431,Job,MODIFIED,eval-sanitize-20-r3-036,
37.0447,Event,ADDED,eval-sanitize-20-r3-037.18d41b3020b330b7,reason=SuccessfulCreate count=1 msg=Created pod: eval-sanitize-20-r3-037-b44z7
37.0448,TaskRequest,MODIFIED,eval-sanitize-20-r3-037,phase=Scheduled job=None
37.0456,Job,MODIFIED,eval-sanitize-20-r3-035,
37.0526,Job,MODIFIED,eval-sanitize-20-r3-036,
37.0553,Job,MODIFIED,eval-sanitize-20-r3-035,
37.1339,Pod,MODIFIED,eval-sanitize-20-r3-037-b44z7,phase=Pending node=kind-worker5
37.1349,Event,ADDED,eval-sanitize-20-r3-037-b44z7.18d41b302640f9d8,reason=Scheduled count=None msg=Successfully assigned compute/eval-sanitize-20-r3-037-b44z7 to kind-worker5
37.1423,Node,MODIFIED,kind-worker5,taints=0
37.1444,Pod,MODIFIED,eval-sanitize-20-r3-037-b44z7,phase=Pending node=kind-worker5
37.1529,Node,MODIFIED,kind-worker5,taints=0
37.5695,Event,ADDED,eval-sanitize-20-r3-037-b44z7.18d41b30401699d5,"reason=Pulled count=1 msg=Container image ""busybox:musl"" already present on machine"
37.5908,Event,ADDED,eval-sanitize-20-r3-037-b44z7.18d41b3041588ce2,reason=Created count=1 msg=Created container: task
37.6607,Event,ADDED,eval-sanitize-20-r3-037-b44z7.18d41b304591bcf3,reason=Started count=1 msg=Started container task
38.0098,TaskRequest,ADDED,eval-sanitize-20-r3-038,phase=None job=None
38.0156,TaskRequest,MODIFIED,eval-sanitize-20-r3-038,phase=Pending job=None
38.0423,Job,ADDED,eval-sanitize-20-r3-038,
38.0472,Job,MODIFIED,eval-sanitize-20-r3-037,
38.0492,Pod,ADDED,eval-sanitize-20-r3-038-hxklj,phase=Pending node=None
38.0515,TaskRequest,MODIFIED,eval-sanitize-20-r3-038,phase=Scheduled job=None
38.0542,Job,MODIFIED,eval-sanitize-20-r3-038,
38.0546,Event,ADDED,eval-sanitize-20-r3-038.18d41b305cfa9784,reason=SuccessfulCreate count=1 msg=Created pod: eval-sanitize-20-r3-038-hxklj
38.06,TaskRequest,MODIFIED,eval-sanitize-20-r3-038,phase=Scheduled job=None
38.0629,Job,MODIFIED,eval-sanitize-20-r3-037,
38.1154,Pod,MODIFIED,eval-sanitize-20-r3-037-b44z7,phase=Running node=kind-worker5
38.1245,Pod,MODIFIED,eval-sanitize-20-r3-038-hxklj,phase=Pending node=kind-worker3
38.128,Event,ADDED,eval-sanitize-20-r3-038-hxklj.18d41b306178a203,reason=Scheduled count=None msg=Successfully assigned compute/eval-sanitize-20-r3-038-hxklj to kind-worker3
38.1338,Pod,MODIFIED,eval-sanitize-20-r3-038-hxklj,phase=Pending node=kind-worker3
38.5616,Event,ADDED,eval-sanitize-20-r3-038-hxklj.18d41b307b4a43b6,"reason=Pulled count=1 msg=Container image ""busybox:musl"" already present on machine"
38.5795,Event,ADDED,eval-sanitize-20-r3-038-hxklj.18d41b307c5409e1,reason=Created count=1 msg=Created container: task
38.6112,Event,ADDED,eval-sanitize-20-r3-038-hxklj.18d41b307e419b5d,reason=Started count=1 msg=Started container task
38.7144,Pod,MODIFIED,eval-sanitize-20-r3-020-z7jzd,phase=Running node=kind-worker
38.7215,Pod,MODIFIED,eval-sanitize-20-r3-011-7pmrj,phase=Running node=kind-worker
38.7279,Pod,MODIFIED,eval-sanitize-20-r3-028-cc6vw,phase=Running node=kind-worker
38.7341,Pod,MODIFIED,eval-sanitize-20-r3-017-zwmxm,phase=Running node=kind-worker
38.7404,Pod,MODIFIED,eval-sanitize-20-r3-024-7v9kq,phase=Running node=kind-worker
38.7466,Pod,MODIFIED,eval-sanitize-20-r3-013-98nmn,phase=Running node=kind-worker
38.7537,Pod,MODIFIED,eval-sanitize-20-r3-022-22zpt,phase=Running node=kind-worker
38.7592,Pod,MODIFIED,eval-sanitize-20-r3-009-b98dg,phase=Running node=kind-worker
38.9692,Pod,MODIFIED,eval-sanitize-20-r3-026-4255x,phase=Running node=kind-worker4
38.9753,Pod,MODIFIED,eval-sanitize-20-r3-010-85ngc,phase=Running node=kind-worker4
38.9807,Pod,MODIFIED,eval-sanitize-20-r3-019-jntlw,phase=Running node=kind-worker4
38.9865,Pod,MODIFIED,eval-sanitize-20-r3-016-wg4b2,phase=Running node=kind-worker4
38.9923,Pod,MODIFIED,eval-sanitize-20-r3-012-cqb84,phase=Running node=kind-worker4
39.0074,TaskRequest,ADDED,eval-sanitize-20-r3-039,phase=None job=None
39.0111,TaskRequest,MODIFIED,eval-sanitize-20-r3-039,phase=Pending job=None
39.0261,Job,ADDED,eval-sanitize-20-r3-039,
39.0321,Pod,ADDED,eval-sanitize-20-r3-039-6gdd4,phase=Pending node=None
39.0322,TaskRequest,MODIFIED,eval-sanitize-20-r3-039,phase=Scheduled job=None
39.0361,Job,MODIFIED,eval-sanitize-20-r3-039,
39.0377,Event,ADDED,eval-sanitize-20-r3-039.18d41b3097938461,reason=SuccessfulCreate count=1 msg=Created pod: eval-sanitize-20-r3-039-6gdd4
39.0398,TaskRequest,MODIFIED,eval-sanitize-20-r3-039,phase=Scheduled job=None
39.0527,Job,MODIFIED,eval-sanitize-20-r3-037,
39.0551,Job,MODIFIED,eval-sanitize-20-r3-038,
39.0623,Job,MODIFIED,eval-sanitize-20-r3-037,
39.0639,Job,MODIFIED,eval-sanitize-20-r3-038,
39.1245,Pod,MODIFIED,eval-sanitize-20-r3-039-6gdd4,phase=Pending node=kind-worker
39.1287,Event,ADDED,eval-sanitize-20-r3-039-6gdd4.18d41b309d071355,reason=Scheduled count=None msg=Successfully assigned compute/eval-sanitize-20-r3-039-6gdd4 to kind-worker
39.1348,Pod,MODIFIED,eval-sanitize-20-r3-039-6gdd4,phase=Pending node=kind-worker
39.5543,Pod,MODIFIED,eval-sanitize-20-r3-021-xmp2g,phase=Running node=kind-worker3
39.562,Pod,MODIFIED,eval-sanitize-20-r3-027-p6tjp,phase=Running node=kind-worker3
39.5694,Pod,MODIFIED,eval-sanitize-20-r3-038-hxklj,phase=Running node=kind-worker3
39.5702,Event,ADDED,eval-sanitize-20-r3-039-6gdd4.18d41b30b733acd5,"reason=Pulled count=1 msg=Container image ""busybox:musl"" already present on machine"
39.5777,Pod,MODIFIED,eval-sanitize-20-r3-015-7nhgg,phase=Running node=kind-worker3
39.5862,Pod,MODIFIED,eval-sanitize-20-r3-025-928bl,phase=Running node=kind-worker3
39.5887,Event,ADDED,eval-sanitize-20-r3-039-6gdd4.18d41b30b887d30d,reason=Created count=1 msg=Created container: task
39.7203,Job,MODIFIED,eval-sanitize-20-r3-020,
39.7223,Event,ADDED,eval-sanitize-20-r3-039-6gdd4.18d41b30c071592e,reason=Started count=1 msg=Started container task
39.7313,Job,MODIFIED,eval-sanitize-20-r3-011,
39.7347,Job,MODIFIED,eval-sanitize-20-r3-020,
39.7372,Job,MODIFIED,eval-sanitize-20-r3-028,
39.7402,Job,MODIFIED,eval-sanitize-20-r3-017,
39.7427,Job,MODIFIED,eval-sanitize-20-r3-011,
39.7448,Job,MODIFIED,eval-sanitize-20-r3-024,
39.7473,Job,MODIFIED,eval-sanitize-20-r3-028,
39.7496,Job,MODIFIED,eval-sanitize-20-r3-017,
39.7516,Job,MODIFIED,eval-sanitize-20-r3-013,
39.7537,Job,MODIFIED,eval-sanitize-20-r3-024,
39.7567,Job,MODIFIED,eval-sanitize-20-r3-022,
39.763,Job,MODIFIED,eval-sanitize-20-r3-009,
39.8153,Job,MODIFIED,eval-sanitize-20-r3-013,
39.8171,Job,MODIFIED,eval-sanitize-20-r3-022,
39.8178,Job,MODIFIED,eval-sanitize-20-r3-009,
39.974,Pod,MODIFIED,eval-sanitize-20-r3-018-mnx7g,phase=Running node=kind-worker2
39.9748,Job,MODIFIED,eval-sanitize-20-r3-026,
39.979,Job,MODIFIED,eval-sanitize-20-r3-010,
39.9831,Pod,MODIFIED,eval-sanitize-20-r3-014-7fzzg,phase=Running node=kind-worker2
39.9865,Job,MODIFIED,eval-sanitize-20-r3-026,
39.9915,Job,MODIFIED,eval-sanitize-20-r3-019,
39.9945,Job,MODIFIED,eval-sanitize-20-r3-010,
39.9976,Pod,MODIFIED,eval-sanitize-20-r3-023-l94v5,phase=Running node=kind-worker2
39.9987,Job,MODIFIED,eval-sanitize-20-r3-016,
40.0006,Job,MODIFIED,eval-sanitize-20-r3-012,
40.007,Job,MODIFIED,eval-sanitize-20-r3-019,
40.0104,Job,MODIFIED,eval-sanitize-20-r3-016,
40.0139,Job,MODIFIED,eval-sanitize-20-r3-012,
40.0141,TaskRequest,ADDED,eval-sanitize-20-r3-040,phase=None job=None
40.0186,Pod,MODIFIED,eval-sanitize-20-r3-020-z7jzd,phase=Succeeded node=kind-worker
40.0271,Pod,MODIFIED,eval-sanitize-20-r3-011-7pmrj,phase=Succeeded node=kind-worker
40.0343,Pod,MODIFIED,eval-sanitize-20-r3-017-zwmxm,phase=Succeeded node=kind-worker
40.0378,Job,MODIFIED,eval-sanitize-20-r3-039,
40.0417,Pod,MODIFIED,eval-sanitize-20-r3-022-22zpt,phase=Succeeded node=kind-worker
40.0477,Pod,MODIFIED,eval-sanitize-20-r3-013-98nmn,phase=Succeeded node=kind-worker
40.0535,Pod,MODIFIED,eval-sanitize-20-r3-009-b98dg,phase=Succeeded node=kind-worker
40.0592,Pod,MODIFIED,eval-sanitize-20-r3-028-cc6vw,phase=Succeeded node=kind-worker
40.0605,Job,MODIFIED,eval-sanitize-20-r3-038,
40.0668,Pod,MODIFIED,eval-sanitize-20-r3-024-7v9kq,phase=Succeeded node=kind-worker
40.077,TaskRequest,MODIFIED,eval-sanitize-20-r3-040,phase=Pending job=None
40.082,Job,MODIFIED,eval-sanitize-20-r3-039,
40.0839,Job,MODIFIED,eval-sanitize-20-r3-038,
40.1447,Pod,MODIFIED,eval-sanitize-20-r3-016-wg4b2,phase=Succeeded node=kind-worker4
40.151,Pod,MODIFIED,eval-sanitize-20-r3-026-4255x,phase=Succeeded node=kind-worker4
40.1571,Pod,MODIFIED,eval-sanitize-20-r3-010-85ngc,phase=Succeeded node=kind-worker4
40.1629,Pod,MODIFIED,eval-sanitize-20-r3-019-jntlw,phase=Succeeded node=kind-worker4
40.1692,Pod,MODIFIED,eval-sanitize-20-r3-012-cqb84,phase=Succeeded node=kind-worker4
40.2821,Job,ADDED,eval-sanitize-20-r3-040,
40.2889,Pod,ADDED,eval-sanitize-20-r3-040-p6zwl,phase=Pending node=None
40.29,TaskRequest,MODIFIED,eval-sanitize-20-r3-040,phase=Scheduled job=None
40.2908,Job,MODIFIED,eval-sanitize-20-r3-040,
40.2934,Event,ADDED,eval-sanitize-20-r3-040.18d41b30e2738d1b,reason=SuccessfulCreate count=1 msg=Created pod: eval-sanitize-20-r3-040-p6zwl
40.2993,TaskRequest,MODIFIED,eval-sanitize-20-r3-040,phase=Scheduled job=None
40.4008,Pod,MODIFIED,eval-sanitize-20-r3-040-p6zwl,phase=Pending node=kind-worker2
40.4046,Event,ADDED,eval-sanitize-20-r3-040-p6zwl.18d41b30e91f86e7,reason=Scheduled count=None msg=Successfully assigned compute/eval-sanitize-20-r3-040-p6zwl to kind-worker2
40.4109,Pod,MODIFIED,eval-sanitize-20-r3-040-p6zwl,phase=Pending node=kind-worker2
40.5606,Pod,MODIFIED,eval-sanitize-20-r3-029-mpn7t,phase=Running node=kind-worker3
40.5638,Job,MODIFIED,eval-sanitize-20-r3-021,
40.567,Job,MODIFIED,eval-sanitize-20-r3-027,
40.5734,Job,MODIFIED,eval-sanitize-20-r3-021,
40.5756,Job,MODIFIED,eval-sanitize-20-r3-027,
40.5813,Job,MODIFIED,eval-sanitize-20-r3-015,
40.5893,Job,MODIFIED,eval-sanitize-20-r3-015,
40.5911,Job,MODIFIED,eval-sanitize-20-r3-025,
40.5992,Job,MODIFIED,eval-sanitize-20-r3-025,
40.7266,Job,MODIFIED,eval-sanitize-20-r3-020,
40.7364,Pod,MODIFIED,eval-sanitize-20-r3-020-z7jzd,phase=Succeeded node=kind-worker
40.7379,Job,MODIFIED,eval-sanitize-20-r3-011,
40.7393,Pod,MODIFIED,eval-sanitize-20-r3-025-928bl,phase=Succeeded node=kind-worker3
40.7407,Job,MODIFIED,eval-sanitize-20-r3-020,
40.7438,Job,MODIFIED,eval-sanitize-20-r3-028,
40.7469,Pod,MODIFIED,eval-sanitize-20-r3-011-7pmrj,phase=Succeeded node=kind-worker
40.7494,Pod,MODIFIED,eval-sanitize-20-r3-039-6gdd4,phase=Running node=kind-worker
40.7502,Job,MODIFIED,eval-sanitize-20-r3-017,
40.7513,Job,MODIFIED,eval-sanitize-20-r3-011,
40.7525,Job,MODIFIED,eval-sanitize-20-r3-024,
40.7542,Job,MODIFIED,eval-sanitize-20-r3-028,
40.7555,Pod,MODIFIED,eval-sanitize-20-r3-028-cc6vw,phase=Succeeded node=kind-worker
40.7569,Job,MODIFIED,eval-sanitize-20-r3-013,
40.7669,Pod,MODIFIED,eval-sanitize-20-r3-017-zwmxm,phase=Succeeded node=kind-worker
40.7679,Job,MODIFIED,eval-sanitize-20-r3-017,
40.7693,Pod,MODIFIED,eval-sanitize-20-r3-024-7v9kq,phase=Succeeded node=kind-worker
40.7705,Job,MODIFIED,eval-sanitize-20-r3-022,
40.772,Job,MODIFIED,eval-sanitize-20-r3-024,
40.774,Pod,MODIFIED,eval-sanitize-20-r3-013-98nmn,phase=Succeeded node=kind-worker
40.7747,Job,MODIFIED,eval-sanitize-20-r3-013,
40.7774,Job,MODIFIED,eval-sanitize-20-r3-009,
40.7813,Job,MODIFIED,eval-sanitize-20-r3-022,
40.7828,Pod,MODIFIED,eval-sanitize-20-r3-022-22zpt,phase=Succeeded node=kind-worker
40.7846,Pod,MODIFIED,eval-sanitize-20-r3-027-p6tjp,phase=Succeeded node=kind-worker3
40.7867,Pod,MODIFIED,eval-sanitize-20-r3-009-b98dg,phase=Succeeded node=kind-worker
40.7905,Job,MODIFIED,eval-sanitize-20-r3-009,
40.7931,Pod,MODIFIED,eval-sanitize-20-r3-015-7nhgg,phase=Succeeded node=kind-worker3
40.7938,Event,ADDED,eval-sanitize-20-r3-009.18d41b3100633b90,reason=Completed count=1 msg=Job completed
40.7997,Pod,MODIFIED,eval-sanitize-20-r3-021-xmp2g,phase=Succeeded node=kind-worker3
40.8124,Job,MODIFIED,eval-sanitize-20-r3-009,
40.8163,TaskRequest,MODIFIED,eval-sanitize-20-r3-009,phase=Complete job=None
40.8268,Job,MODIFIED,eval-sanitize-20-r3-009,
40.8302,Event,ADDED,eval-sanitize-20-r3-040-p6zwl.18d41b31028b02e1,"reason=Pulled count=1 msg=Container image ""busybox:musl"" already present on machine"
40.8495,Event,ADDED,eval-sanitize-20-r3-040-p6zwl.18d41b3103acce6b,reason=Created count=1 msg=Created container: task
40.929,Event,ADDED,eval-sanitize-20-r3-040-p6zwl.18d41b31085766f8,reason=Started count=1 msg=Started container task
40.9795,Job,MODIFIED,eval-sanitize-20-r3-018,
40.9824,Job,MODIFIED,eval-sanitize-20-r3-026,
40.9847,Pod,MODIFIED,eval-sanitize-20-r3-040-p6zwl,phase=Running node=kind-worker2
40.9862,Job,MODIFIED,eval-sanitize-20-r3-010,
40.9878,Job,MODIFIED,eval-sanitize-20-r3-014,
40.9902,Job,MODIFIED,eval-sanitize-20-r3-018,
40.9916,Pod,MODIFIED,eval-sanitize-20-r3-026-4255x,phase=Succeeded node=kind-worker4
40.9929,Job,MODIFIED,eval-sanitize-20-r3-026,
40.9951,Pod,MODIFIED,eval-sanitize-20-r3-010-85ngc,phase=Succeeded node=kind-worker4
40.9971,Job,MODIFIED,eval-sanitize-20-r3-010,
40.9978,Job,MODIFIED,eval-sanitize-20-r3-019,
40.9988,Job,MODIFIED,eval-sanitize-20-r3-014,
41.008,Job,MODIFIED,eval-sanitize-20-r3-019,
41.0084,TaskRequest,ADDED,eval-sanitize-20-r3-041,phase=None job=None
41.0115,TaskRequest,MODIFIED,eval-sanitize-20-r3-041,phase=Pending job=None
41.0807,Job,MODIFIED,eval-sanitize-20-r3-016,
41.0816,Job,ADDED,eval-sanitize-20-r3-041,
41.0881,TaskRequest,MODIFIED,eval-sanitize-20-r3-041,phase=Scheduled job=None
41.0916,Job,MODIFIED,eval-sanitize-20-r3-041,
41.0956,TaskRequest,MODIFIED,eval-sanitize-20-r3-041,phase=Scheduled job=None
41.1001,Job,MODIFIED,eval-sanitize-20-r3-016,
41.1188,Job,MODIFIED,eval-sanitize-20-r3-023,
41.1219,Pod,MODIFIED,eval-sanitize-20-r3-030-tqczp,phase=Running node=kind-worker5
41.1275,Job,MODIFIED,eval-sanitize-20-r3-023,
41.1428,Pod,MODIFIED,eval-sanitize-20-r3-014-7fzzg,phase=Succeeded node=kind-worker2
41.1726,Pod,MODIFIED,eval-sanitize-20-r3-019-jntlw,phase=Succeeded node=kind-worker4
41.1845,Pod,MODIFIED,eval-sanitize-20-r3-018-mnx7g,phase=Succeeded node=kind-worker2
41.1905,Pod,MODIFIED,eval-sanitize-20-r3-023-l94v5,phase=Succeeded node=kind-worker2
41.2205,Job,MODIFIED,eval-sanitize-20-r3-012,
41.2331,Job,MODIFIED,eval-sanitize-20-r3-012,
41.2773,Job,MODIFIED,eval-sanitize-20-r3-039,
41.2867,Job,MODIFIED,eval-sanitize-20-r3-039,
41.3326,Pod,MODIFIED,eval-sanitize-20-r3-016-wg4b2,phase=Succeeded node=kind-worker4
41.382,Pod,ADDED,eval-sanitize-20-r3-041-pdkzt,phase=Pending node=None
41.4079,Pod,MODIFIED,eval-sanitize-20-r3-041-pdkzt,phase=Pending node=kind-worker2
41.4116,Event,ADDED,eval-sanitize-20-r3-041-pdkzt.18d41b3125293325,reason=Scheduled count=None msg=Successfully assigned compute/eval-sanitize-20-r3-041-pdkzt to kind-worker2
41.4181,Pod,MODIFIED,eval-sanitize-20-r3-041-pdkzt,phase=Pending node=kind-worker2
41.4791,Pod,MODIFIED,eval-sanitize-20-r3-012-cqb84,phase=Succeeded node=kind-worker4
41.5338,Job,MODIFIED,eval-sanitize-20-r3-040,
41.5429,Job,MODIFIED,eval-sanitize-20-r3-040,
41.6199,Job,MODIFIED,eval-sanitize-20-r3-041,
41.6296,Job,MODIFIED,eval-sanitize-20-r3-041,
41.6688,Event,ADDED,eval-sanitize-20-r3-041.18d41b3123a7cb70,reason=SuccessfulCreate count=1 msg=Created pod: eval-sanitize-20-r3-041-pdkzt
41.6966,Pod,MODIFIED,eval-sanitize-20-r3-029-mpn7t,phase=Succeeded node=kind-worker3
41.7694,Job,MODIFIED,eval-sanitize-20-r3-029,
41.7782,Job,MODIFIED,eval-sanitize-20-r3-029,
41.8197,Job,MODIFIED,eval-sanitize-20-r3-021,
41.8307,Job,MODIFIED,eval-sanitize-20-r3-021,
41.831,Event,ADDED,eval-sanitize-20-r3-041-pdkzt.18d41b313e1e2863,"reason=Pulled count=1 msg=Container image ""busybox:musl"" already present on machine"
41.849,Event,ADDED,eval-sanitize-20-r3-041-pdkzt.18d41b313f2f7628,reason=Created count=1 msg=Created container: task
41.8692,Job,MODIFIED,eval-sanitize-20-r3-027,
41.8789,Job,MODIFIED,eval-sanitize-20-r3-027,
41.9025,Event,ADDED,eval-sanitize-20-r3-041-pdkzt.18d41b31425efd6e,reason=Started count=1 msg=Started container task
41.9192,Job,MODIFIED,eval-sanitize-20-r3-015,
41.9284,Job,MODIFIED,eval-sanitize-20-r3-015,
41.9743,Job,MODIFIED,eval-sanitize-20-r3-025,
41.9831,Pod,MODIFIED,eval-sanitize-20-r3-041-pdkzt,phase=Running node=kind-worker2
41.9841,Job,MODIFIED,eval-sanitize-20-r3-025,
42.0113,TaskRequest,ADDED,eval-sanitize-20-r3-042,phase=None job=None
42.0147,TaskRequest,MODIFIED,eval-sanitize-20-r3-042,phase=Pending job=None
42.0183,Job,MODIFIED,eval-sanitize-20-r3-020,
42.03,Job,ADDED,eval-sanitize-20-r3-042,
42.0353,TaskRequest,MODIFIED,eval-sanitize-20-r3-042,phase=Scheduled job=None
42.038,Job,MODIFIED,eval-sanitize-20-r3-042,
42.042,TaskRequest,MODIFIED,eval-sanitize-20-r3-042,phase=Scheduled job=None
42.0455,Job,MODIFIED,eval-sanitize-20-r3-020,
42.0771,Pod,MODIFIED,eval-sanitize-20-r3-021-xmp2g,phase=Succeeded node=kind-worker3
42.1244,Pod,MODIFIED,eval-sanitize-20-r3-027-p6tjp,phase=Succeeded node=kind-worker3
42.1752,Pod,MODIFIED,eval-sanitize-20-r3-015-7nhgg,phase=Succeeded node=kind-worker3
42.209,Pod,MODIFIED,eval-sanitize-20-r3-030-tqczp,phase=Succeeded node=kind-worker5
42.2227,Pod,MODIFIED,eval-sanitize-20-r3-025-928bl,phase=Succeeded node=kind-worker3
42.5216,Job,MODIFIED,eval-sanitize-20-r3-011,
42.53,Job,MODIFIED,eval-sanitize-20-r3-011,
42.5644,Pod,MODIFIED,eval-sanitize-20-r3-031-92b5r,phase=Running node=kind-worker3
42.5693,Job,MODIFIED,eval-sanitize-20-r3-028,
42.5781,Job,MODIFIED,eval-sanitize-20-r3-028,
42.6198,Job,MODIFIED,eval-sanitize-20-r3-017,
42.6292,Job,MODIFIED,eval-sanitize-20-r3-017,
42.6702,Job,MODIFIED,eval-sanitize-20-r3-024,
42.6784,Job,MODIFIED,eval-sanitize-20-r3-024,
42.7192,Job,MODIFIED,eval-sanitize-20-r3-013,
42.7283,Job,MODIFIED,eval-sanitize-20-r3-013,
43.0134,TaskRequest,ADDED,eval-sanitize-20-r3-043,phase=None job=None
43.0192,Job,MODIFIED,eval-sanitize-20-r3-022,
43.0193,TaskRequest,MODIFIED,eval-sanitize-20-r3-043,phase=Pending job=None
43.0352,Job,ADDED,eval-sanitize-20-r3-043,
43.0398,TaskRequest,MODIFIED,eval-sanitize-20-r3-043,phase=Scheduled job=None
43.0449,Job,MODIFIED,eval-sanitize-20-r3-043,
43.0471,TaskRequest,MODIFIED,eval-sanitize-20-r3-043,phase=Scheduled job=None
43.0499,Job,MODIFIED,eval-sanitize-20-r3-022,
43.0687,Job,MODIFIED,eval-sanitize-20-r3-018,
43.0768,Job,MODIFIED,eval-sanitize-20-r3-018,
43.1242,Job,MODIFIED,eval-sanitize-20-r3-026,
43.1297,Pod,MODIFIED,eval-sanitize-20-r3-032-cr99x,phase=Running node=kind-worker5
43.1332,Job,MODIFIED,eval-sanitize-20-r3-026,
43.184,Job,MODIFIED,eval-sanitize-20-r3-010,
43.1936,Job,MODIFIED,eval-sanitize-20-r3-010,
43.2203,Job,MODIFIED,eval-sanitize-20-r3-014,
43.2311,Job,MODIFIED,eval-sanitize-20-r3-014,
43.33,Pod,MODIFIED,eval-sanitize-20-r3-018-mnx7g,phase=Succeeded node=kind-worker2
43.4816,Pod,MODIFIED,eval-sanitize-20-r3-014-7fzzg,phase=Succeeded node=kind-worker2
43.5275,Job,MODIFIED,eval-sanitize-20-r3-019,
43.5365,Job,MODIFIED,eval-sanitize-20-r3-019,
43.6273,Pod,ADDED,eval-sanitize-20-r3-042-p8bkn,phase=Pending node=None
43.6701,Job,MODIFIED,eval-sanitize-20-r3-016,
43.6786,Job,MODIFIED,eval-sanitize-20-r3-016,
43.7323,Pod,MODIFIED,eval-sanitize-20-r3-042-p8bkn,phase=Pending node=kind-worker3
43.7357,Event,ADDED,eval-sanitize-20-r3-042-p8bkn.18d41b31afbce0f4,reason=Scheduled count=None msg=Successfully assigned compute/eval-sanitize-20-r3-042-p8bkn to kind-worker3
43.7416,Pod,MODIFIED,eval-sanitize-20-r3-042-p8bkn,phase=Pending node=kind-worker3
43.7718,Pod,MODIFIED,eval-sanitize-20-r3-031-92b5r,phase=Succeeded node=kind-worker3
43.8273,Job,MODIFIED,eval-sanitize-20-r3-041,
43.8357,Job,MODIFIED,eval-sanitize-20-r3-041,
43.8689,Job,MODIFIED,eval-sanitize-20-r3-042,
43.8776,Job,MODIFIED,eval-sanitize-20-r3-042,
43.9291,Event,ADDED,eval-sanitize-20-r3-042.18d41b31a978682d,reason=SuccessfulCreate count=1 msg=Created pod: eval-sanitize-20-r3-042-p8bkn
43.9897,Pod,MODIFIED,eval-sanitize-20-r3-033-mpfrc,phase=Running node=kind-worker2
44.0071,TaskRequest,ADDED,eval-sanitize-20-r3-044,phase=None job=None
44.0123,TaskRequest,MODIFIED,eval-sanitize-20-r3-044,phase=Pending job=None
44.0187,Job,MODIFIED,eval-sanitize-20-r3-023,
44.0275,Job,ADDED,eval-sanitize-20-r3-044,
44.0317,TaskRequest,MODIFIED,eval-sanitize-20-r3-044,phase=Scheduled job=None
44.0362,Job,MODIFIED,eval-sanitize-20-r3-044,
44.0396,TaskRequest,MODIFIED,eval-sanitize-20-r3-044,phase=Scheduled job=None
44.0423,Job,MODIFIED,eval-sanitize-20-r3-023,
44.0701,Job,MODIFIED,eval-sanitize-20-r3-030,
44.0795,Job,MODIFIED,eval-sanitize-20-r3-030,
44.1286,Job,MODIFIED,eval-sanitize-20-r3-012,
44.1435,Job,MODIFIED,eval-sanitize-20-r3-012,
44.161,Event,ADDED,eval-sanitize-20-r3-042-p8bkn.18d41b31c8fde0d5,"reason=Pulled count=1 msg=Container image ""busybox:musl"" already present on machine"
44.1701,Job,MODIFIED,eval-sanitize-20-r3-029,
44.1805,Job,MODIFIED,eval-sanitize-20-r3-029,
44.1819,Event,ADDED,eval-sanitize-20-r3-042-p8bkn.18d41b31ca487d67,reason=Created count=1 msg=Created container: task
44.2273,Job,MODIFIED,eval-sanitize-20-r3-021,
44.2305,Event,ADDED,eval-sanitize-20-r3-042-p8bkn.18d41b31cd3b8dc2,reason=Started count=1 msg=Started container task
44.2354,Job,MODIFIED,eval-sanitize-20-r3-021,
44.247,Pod,MODIFIED,eval-sanitize-20-r3-032-cr99x,phase=Succeeded node=kind-worker5
44.2738,Pod,MODIFIED,eval-sanitize-20-r3-023-l94v5,phase=Succeeded node=kind-worker2
44.3278,Pod,MODIFIED,eval-sanitize-20-r3-030-tqczp,phase=Succeeded node=kind-worker5
44.4329,Pod,MODIFIED,eval-sanitize-20-r3-029-mpn7t,phase=Succeeded node=kind-worker3
44.5804,Pod,MODIFIED,eval-sanitize-20-r3-042-p8bkn,phase=Running node=kind-worker3
44.6187,Job,MODIFIED,eval-sanitize-20-r3-027,
44.6285,Job,MODIFIED,eval-sanitize-20-r3-027,
44.7196,Job,MODIFIED,eval-sanitize-20-r3-015,
44.7286,Job,MODIFIED,eval-sanitize-20-r3-015,
44.7764,Job,MODIFIED,eval-sanitize-20-r3-025,
44.785,Job,MODIFIED,eval-sanitize-20-r3-025,
44.8283,Job,MODIFIED,eval-sanitize-20-r3-020,
44.8318,TaskRequest,MODIFIED,eval-sanitize-20-r3-020,phase=Complete job=None
44.8412,Job,MODIFIED,eval-sanitize-20-r3-020,
44.9209,Pod,ADDED,eval-sanitize-20-r3-043-zkwvs,phase=Pending node=None
44.9431,Pod,MODIFIED,eval-sanitize-20-r3-043-zkwvs,phase=Pending node=kind-worker3
44.9482,Event,ADDED,eval-sanitize-20-r3-043-zkwvs.18d41b31f7e632f3,reason=Scheduled count=None msg=Successfully assigned compute/eval-sanitize-20-r3-043-zkwvs to kind-worker3
44.9546,Pod,MODIFIED,eval-sanitize-20-r3-043-zkwvs,phase=Pending node=kind-worker3
45.0078,TaskRequest,ADDED,eval-sanitize-20-r3-045,phase=None job=None
45.0118,TaskRequest,MODIFIED,eval-sanitize-20-r3-045,phase=Pending job=None
45.0272,Job,ADDED,eval-sanitize-20-r3-045,
45.0326,TaskRequest,MODIFIED,eval-sanitize-20-r3-045,phase=Scheduled job=None
45.0359,Job,MODIFIED,eval-sanitize-20-r3-045,
45.0387,TaskRequest,MODIFIED,eval-sanitize-20-r3-045,phase=Scheduled job=None
45.073,Job,MODIFIED,eval-sanitize-20-r3-011,
45.0771,TaskRequest,MODIFIED,eval-sanitize-20-r3-011,phase=Complete job=None
45.0837,Pod,MODIFIED,eval-sanitize-20-r3-033-mpfrc,phase=Succeeded node=kind-worker2
45.086,Job,MODIFIED,eval-sanitize-20-r3-011,
45.1357,Event,ADDED,eval-sanitize-20-r3-020.18d41b31f10f6334,reason=Completed count=1 msg=Job completed
45.1415,Pod,MODIFIED,eval-sanitize-20-r3-034-bjfdr,phase=Running node=kind-worker5
45.1704,Job,MODIFIED,eval-sanitize-20-r3-031,
45.1789,Job,MODIFIED,eval-sanitize-20-r3-031,
45.2276,Job,MODIFIED,eval-sanitize-20-r3-043,
45.2384,Job,MODIFIED,eval-sanitize-20-r3-043,
45.2699,Job,MODIFIED,eval-sanitize-20-r3-028,
45.275,TaskRequest,MODIFIED,eval-sanitize-20-r3-028,phase=Complete job=None
45.2852,Job,MODIFIED,eval-sanitize-20-r3-028,
45.3325,Job,MODIFIED,eval-sanitize-20-r3-017,
45.3364,TaskRequest,MODIFIED,eval-sanitize-20-r3-017,phase=Complete job=None
45.3457,Event,ADDED,eval-sanitize-20-r3-043-zkwvs.18d41b320f99d2a9,"reason=Pulled count=1 msg=Container image ""busybox:musl"" already present on machine"
45.3492,Job,MODIFIED,eval-sanitize-20-r3-017,
45.3648,Event,ADDED,eval-sanitize-20-r3-043-zkwvs.18d41b3210cc2165,reason=Created count=1 msg=Created container: task
45.3694,Job,MODIFIED,eval-sanitize-20-r3-024,
45.3733,TaskRequest,MODIFIED,eval-sanitize-20-r3-024,phase=Complete job=None
45.384,Job,MODIFIED,eval-sanitize-20-r3-024,
45.3997,Event,ADDED,eval-sanitize-20-r3-043-zkwvs.18d41b3212e45754,reason=Started count=1 msg=Started container task
45.4183,Event,ADDED,eval-sanitize-20-r3-043.18d41b31f694fa72,reason=SuccessfulCreate count=1 msg=Created pod: eval-sanitize-20-r3-043-zkwvs
45.4887,Pod,MODIFIED,eval-sanitize-20-r3-031-92b5r,phase=Succeeded node=kind-worker3
45.5338,Job,MODIFIED,eval-sanitize-20-r3-013,
45.5372,TaskRequest,MODIFIED,eval-sanitize-20-r3-013,phase=Complete job=None
45.5482,Job,MODIFIED,eval-sanitize-20-r3-013,
45.5759,Job,MODIFIED,eval-sanitize-20-r3-022,
45.5811,Pod,MODIFIED,eval-sanitize-20-r3-043-zkwvs,phase=Running node=kind-worker3
45.5813,TaskRequest,MODIFIED,eval-sanitize-20-r3-022,phase=Complete job=None
45.5893,Job,MODIFIED,eval-sanitize-20-r3-022,
45.6343,Pod,ADDED,eval-sanitize-20-r3-044-s9w22,phase=Pending node=None
45.6567,Pod,MODIFIED,eval-sanitize-20-r3-044-s9w22,phase=Pending node=kind-worker
45.6603,Event,ADDED,eval-sanitize-20-r3-044-s9w22.18d41b3222705818,reason=Scheduled count=None msg=Successfully assigned compute/eval-sanitize-20-r3-044-s9w22 to kind-worker
45.6662,Pod,MODIFIED,eval-sanitize-20-r3-044-s9w22,phase=Pending node=kind-worker
45.6684,Job,MODIFIED,eval-sanitize-20-r3-018,
45.6782,Job,MODIFIED,eval-sanitize-20-r3-018,
45.7176,Event,ADDED,eval-sanitize-20-r3-011.18d41b31ffa70178,reason=Completed count=1 msg=Job completed
45.8298,Job,MODIFIED,eval-sanitize-20-r3-026,
45.834,TaskRequest,MODIFIED,eval-sanitize-20-r3-026,phase=Complete job=None
45.8436,Job,MODIFIED,eval-sanitize-20-r3-026,
45.869,Job,MODIFIED,eval-sanitize-20-r3-032,
45.8778,Job,MODIFIED,eval-sanitize-20-r3-032,
45.9251,Job,MODIFIED,eval-sanitize-20-r3-044,
45.9342,Job,MODIFIED,eval-sanitize-20-r3-044,
46.0074,TaskRequest,ADDED,eval-sanitize-20-r3-046,phase=None job=None
46.0127,TaskRequest,MODIFIED,eval-sanitize-20-r3-046,phase=Pending job=None
46.0181,Event,ADDED,eval-sanitize-20-r3-028.18d41b320b61da0b,reason=Completed count=1 msg=Job completed
46.0374,Job,ADDED,eval-sanitize-20-r3-046,
46.0423,TaskRequest,MODIFIED,eval-sanitize-20-r3-046,phase=Scheduled job=None
46.0476,Job,MODIFIED,eval-sanitize-20-r3-046,
46.0521,TaskRequest,MODIFIED,eval-sanitize-20-r3-046,phase=Scheduled job=None
46.0705,Job,MODIFIED,eval-sanitize-20-r3-010,
46.0743,Event,ADDED,eval-sanitize-20-r3-044-s9w22.18d41b323b186c6d,"reason=Pulled count=1 msg=Container image ""busybox:musl"" already present on machine"
46.0771,TaskRequest,MODIFIED,eval-sanitize-20-r3-010,phase=Complete job=None
46.0876,Job,MODIFIED,eval-sanitize-20-r3-010,
46.0972,Event,ADDED,eval-sanitize-20-r3-044-s9w22.18d41b323c58c3c5,reason=Created count=1 msg=Created container: task
46.1193,Job,MODIFIED,eval-sanitize-20-r3-014,
46.1294,Job,MODIFIED,eval-sanitize-20-r3-014,
46.1332,Event,ADDED,eval-sanitize-20-r3-044-s9w22.18d41b323ea44ebd,reason=Started count=1 msg=Started container task
46.1732,Pod,MODIFIED,eval-sanitize-20-r3-032-cr99x,phase=Succeeded node=kind-worker5
46.2274,Job,MODIFIED,eval-sanitize-20-r3-019,
46.2316,TaskRequest,MODIFIED,eval-sanitize-20-r3-019,phase=Complete job=None
46.2426,Job,MODIFIED,eval-sanitize-20-r3-019,
46.2521,Pod,MODIFIED,eval-sanitize-20-r3-034-bjfdr,phase=Succeeded node=kind-worker5
46.269,Job,MODIFIED,eval-sanitize-20-r3-042,
46.2778,Job,MODIFIED,eval-sanitize-20-r3-042,
46.3281,Event,ADDED,eval-sanitize-20-r3-017.18d41b320f2149e4,reason=Completed count=1 msg=Job completed
46.3789,Job,MODIFIED,eval-sanitize-20-r3-016,
46.3837,TaskRequest,MODIFIED,eval-sanitize-20-r3-016,phase=Complete job=None
46.3929,Job,MODIFIED,eval-sanitize-20-r3-016,
46.5337,Job,MODIFIED,eval-sanitize-20-r3-033,
46.5429,Job,MODIFIED,eval-sanitize-20-r3-033,
46.5712,Job,MODIFIED,eval-sanitize-20-r3-023,
46.5767,Pod,MODIFIED,eval-sanitize-20-r3-035-p99z2,phase=Running node=kind-worker3
46.5807,Job,MODIFIED,eval-sanitize-20-r3-023,
46.6327,Event,ADDED,eval-sanitize-20-r3-024.18d41b3211516fa5,reason=Completed count=1 msg=Job completed
46.6836,Pod,ADDED,eval-sanitize-20-r3-045-r687p,phase=Pending node=None
46.7056,Pod,MODIFIED,eval-sanitize-20-r3-045-r687p,phase=Pending node=kind-worker2
46.7088,Event,ADDED,eval-sanitize-20-r3-045-r687p.18d41b3260f25a3f,reason=Scheduled count=None msg=Successfully assigned compute/eval-sanitize-20-r3-045-r687p to kind-worker2
46.7153,Pod,MODIFIED,eval-sanitize-20-r3-045-r687p,phase=Pending node=kind-worker2
46.7192,Job,MODIFIED,eval-sanitize-20-r3-030,
46.7282,Job,MODIFIED,eval-sanitize-20-r3-030,
46.7567,Pod,MODIFIED,eval-sanitize-20-r3-044-s9w22,phase=Running node=kind-worker
46.7687,Job,MODIFIED,eval-sanitize-20-r3-012,
46.773,TaskRequest,MODIFIED,eval-sanitize-20-r3-012,phase=Complete job=None
46.7819,Job,MODIFIED,eval-sanitize-20-r3-012,
46.8246,Pod,MODIFIED,eval-sanitize-20-r3-033-mpfrc,phase=Succeeded node=kind-worker2
46.9179,Event,ADDED,eval-sanitize-20-r3-013.18d41b321b2546cf,reason=Completed count=1 msg=Job completed
46.9761,Job,MODIFIED,eval-sanitize-20-r3-045,
46.9845,Job,MODIFIED,eval-sanitize-20-r3-045,
46.9958,Pod,MODIFIED,eval-sanitize-20-r3-036-slccs,phase=Running node=kind-worker2
47.0076,TaskRequest,ADDED,eval-sanitize-20-r3-047,phase=None job=None
47.0111,TaskRequest,MODIFIED,eval-sanitize-20-r3-047,phase=Pending job=None
47.0262,Job,ADDED,eval-sanitize-20-r3-047,
47.0305,TaskRequest,MODIFIED,eval-sanitize-20-r3-047,phase=Scheduled job=None
47.0356,Job,MODIFIED,eval-sanitize-20-r3-047,
47.0379,TaskRequest,MODIFIED,eval-sanitize-20-r3-047,phase=Scheduled job=None
47.0686,Job,MODIFIED,eval-sanitize-20-r3-029,
47.0773,Job,MODIFIED,eval-sanitize-20-r3-029,
47.1534,Event,ADDED,eval-sanitize-20-r3-045-r687p.18d41b327b6d56bc,"reason=Pulled count=1 msg=Container image ""busybox:musl"" already present on machine"
47.1698,Job,MODIFIED,eval-sanitize-20-r3-021,
47.1729,Event,ADDED,eval-sanitize-20-r3-045-r687p.18d41b327c7c69e0,reason=Created count=1 msg=Created container: task
47.1735,TaskRequest,MODIFIED,eval-sanitize-20-r3-021,phase=Complete job=None
47.185,Job,MODIFIED,eval-sanitize-20-r3-021,
47.2182,Event,ADDED,eval-sanitize-20-r3-022.18d41b321da1bac0,reason=Completed count=1 msg=Job completed
47.2403,Event,ADDED,eval-sanitize-20-r3-045-r687p.18d41b328099fe1d,reason=Started count=1 msg=Started container task
47.2705,Job,MODIFIED,eval-sanitize-20-r3-027,
47.2739,TaskRequest,MODIFIED,eval-sanitize-20-r3-027,phase=Complete job=None
47.2836,Job,MODIFIED,eval-sanitize-20-r3-027,
47.3307,Job,MODIFIED,eval-sanitize-20-r3-015,
47.3355,TaskRequest,MODIFIED,eval-sanitize-20-r3-015,phase=Complete job=None
47.3447,Job,MODIFIED,eval-sanitize-20-r3-015,
47.4263,Job,MODIFIED,eval-sanitize-20-r3-025,
47.4319,TaskRequest,MODIFIED,eval-sanitize-20-r3-025,phase=Complete job=None
47.4385,Job,MODIFIED,eval-sanitize-20-r3-025,
47.4833,Job,MODIFIED,eval-sanitize-20-r3-043,
47.4922,Job,MODIFIED,eval-sanitize-20-r3-043,
47.5066,Node,MODIFIED,kind-worker,taints=1
47.5238,Node,MODIFIED,kind-worker,taints=1
47.5241,Event,ADDED,eval-sanitize-20-r3-044.18d41b32211a6677,reason=SuccessfulCreate count=1 msg=Created pod: eval-sanitize-20-r3-044-s9w22
47.5821,Pod,ADDED,eval-sanitize-20-r3-046-vwfpx,phase=Pending node=None
47.6049,Pod,MODIFIED,eval-sanitize-20-r3-046-vwfpx,phase=Pending node=kind-worker5
47.6085,Event,ADDED,eval-sanitize-20-r3-046-vwfpx.18d41b3296aad35f,reason=Scheduled count=None msg=Successfully assigned compute/eval-sanitize-20-r3-046-vwfpx to kind-worker5
47.6156,Pod,MODIFIED,eval-sanitize-20-r3-046-vwfpx,phase=Pending node=kind-worker5
47.6188,Job,MODIFIED,eval-sanitize-20-r3-034,
47.6288,Job,MODIFIED,eval-sanitize-20-r3-034,
47.6892,Job,MODIFIED,eval-sanitize-20-r3-031,
47.6983,Pod,MODIFIED,eval-sanitize-20-r3-035-p99z2,phase=Succeeded node=kind-worker3
47.6995,Job,MODIFIED,eval-sanitize-20-r3-031,
47.7181,Job,MODIFIED,eval-sanitize-20-r3-044,
47.726,Job,MODIFIED,eval-sanitize-20-r3-044,
47.7694,Job,MODIFIED,eval-sanitize-20-r3-018,
47.7739,TaskRequest,MODIFIED,eval-sanitize-20-r3-018,phase=Complete job=None
47.7828,Job,MODIFIED,eval-sanitize-20-r3-018,
47.8298,Event,ADDED,eval-sanitize-20-r3-026.18d41b322cc18c2a,reason=Completed count=1 msg=Job completed
47.854,Node,MODIFIED,kind-worker4,taints=1
47.8672,Node,MODIFIED,kind-worker4,taints=1
47.8691,Job,MODIFIED,eval-sanitize-20-r3-046,
47.8776,Job,MODIFIED,eval-sanitize-20-r3-046,
47.9257,Pod,MODIFIED,eval-sanitize-20-r3-034-bjfdr,phase=Succeeded node=kind-worker5
47.9686,Node,MODIFIED,kind-worker4,taints=1
47.9806,Node,MODIFIED,kind-worker4,taints=1
47.9889,Node,MODIFIED,kind-worker4,taints=0
47.9992,Pod,MODIFIED,eval-sanitize-20-r3-045-r687p,phase=Running node=kind-worker2
48.0075,TaskRequest,ADDED,eval-sanitize-20-r3-048,phase=None job=None
48.0106,TaskRequest,MODIFIED,eval-sanitize-20-r3-048,phase=Pending job=None
48.0181,Job,MODIFIED,eval-sanitize-20-r3-032,
48.0255,Job,ADDED,eval-sanitize-20-r3-048,
48.0293,TaskRequest,MODIFIED,eval-sanitize-20-r3-048,phase=Scheduled job=None
48.0348,Job,MODIFIED,eval-sanitize-20-r3-048,
48.0368,TaskRequest,MODIFIED,eval-sanitize-20-r3-048,phase=Scheduled job=None
48.0397,Job,MODIFIED,eval-sanitize-20-r3-032,
48.0634,Event,ADDED,eval-sanitize-20-r3-046-vwfpx.18d41b32b1c8f04a,"reason=Pulled count=1 msg=Container image ""busybox:musl"" already present on machine"
48.0673,Node,MODIFIED,kind-worker4,taints=0
48.0692,Pod,ADDED,eval-sanitize-20-r3-047-zd5js,phase=Pending node=None
48.0845,Event,ADDED,eval-sanitize-20-r3-046-vwfpx.18d41b32b2ee7d1f,reason=Created count=1 msg=Created container: task
48.0861,Pod,MODIFIED,eval-sanitize-20-r3-047-zd5js,phase=Pending node=kind-worker4
48.0915,Event,ADDED,eval-sanitize-20-r3-047-zd5js.18d41b32b361b42d,reason=Scheduled count=None msg=Successfully assigned compute/eval-sanitize-20-r3-047-zd5js to kind-worker4
48.0958,Node,MODIFIED,kind-worker4,taints=0
48.0984,Pod,MODIFIED,eval-sanitize-20-r3-047-zd5js,phase=Pending node=kind-worker4
48.1063,Node,MODIFIED,kind-worker4,taints=0
48.1179,Event,ADDED,eval-sanitize-20-r3-010.18d41b323b182bde,reason=Completed count=1 msg=Job completed
48.1391,Pod,MODIFIED,eval-sanitize-20-r3-036-slccs,phase=Succeeded node=kind-worker2
48.1439,Pod,MODIFIED,eval-sanitize-20-r3-037-b44z7,phase=Running node=kind-worker5
48.1531,Event,ADDED,eval-sanitize-20-r3-046-vwfpx.18d41b32b72bc922,reason=Started count=1 msg=Started container task
48.1686,Job,MODIFIED,eval-sanitize-20-r3-014,
48.1722,TaskRequest,MODIFIED,eval-sanitize-20-r3-014,phase=Complete job=None
48.1812,Job,MODIFIED,eval-sanitize-20-r3-014,
48.2687,Job,MODIFIED,eval-sanitize-20-r3-033,
48.278,Job,MODIFIED,eval-sanitize-20-r3-033,
48.3602,Node,MODIFIED,kind-worker3,taints=1
48.3686,Job,MODIFIED,eval-sanitize-20-r3-047,
48.3718,Node,MODIFIED,kind-worker3,taints=1
48.3768,Job,MODIFIED,eval-sanitize-20-r3-047,
48.4219,Event,ADDED,eval-sanitize-20-r3-019.18d41b324473edca,reason=Completed count=1 msg=Job completed
48.4709,Job,MODIFIED,eval-sanitize-20-r3-023,
48.4757,TaskRequest,MODIFIED,eval-sanitize-20-r3-023,phase=Complete job=None
48.4852,Job,MODIFIED,eval-sanitize-20-r3-023,
48.538,Job,MODIFIED,eval-sanitize-20-r3-035,
48.5488,Job,MODIFIED,eval-sanitize-20-r3-035,
48.5534,Event,ADDED,eval-sanitize-20-r3-047-zd5js.18d41b32cef2d630,"reason=Pulled count=1 msg=Container image ""busybox:musl"" already present on machine"
48.5737,Event,ADDED,eval-sanitize-20-r3-047-zd5js.18d41b32d03b24c8,reason=Created count=1 msg=Created container: task
48.6245,Job,MODIFIED,eval-sanitize-20-r3-045,
48.6329,Job,MODIFIED,eval-sanitize-20-r3-045,
48.6695,Job,MODIFIED,eval-sanitize-20-r3-030,
48.6728,TaskRequest,MODIFIED,eval-sanitize-20-r3-030,phase=Complete job=None
48.682,Job,MODIFIED,eval-sanitize-20-r3-030,
48.7289,Event,ADDED,eval-sanitize-20-r3-016.18d41b324d80a30d,reason=Completed count=1 msg=Job completed
48.7344,Event,ADDED,eval-sanitize-20-r3-047-zd5js.18d41b32d9d8dc3b,reason=Started count=1 msg=Started container task
48.7823,Job,MODIFIED,eval-sanitize-20-r3-036,
48.7911,Job,MODIFIED,eval-sanitize-20-r3-036,
48.8232,Pod,MODIFIED,eval-sanitize-20-r3-035-p99z2,phase=Succeeded node=kind-worker3
48.8761,Pod,ADDED,eval-sanitize-20-r3-048-vzkh2,phase=Pending node=None
48.8965,Node,MODIFIED,kind-worker2,taints=1
48.9015,Pod,MODIFIED,eval-sanitize-20-r3-048-vzkh2,phase=Pending node=kind-worker4
48.9048,Event,ADDED,eval-sanitize-20-r3-048-vzkh2.18d41b32e3f705a1,reason=Scheduled count=None msg=Successfully assigned compute/eval-sanitize-20-r3-048-vzkh2 to kind-worker4
48.9096,Node,MODIFIED,kind-worker2,taints=1
48.9118,Pod,MODIFIED,eval-sanitize-20-r3-048-vzkh2,phase=Pending node=kind-worker4
48.9131,Node,MODIFIED,kind-worker4,taints=0
48.9184,Job,MODIFIED,eval-sanitize-20-r3-029,
48.923,TaskRequest,MODIFIED,eval-sanitize-20-r3-029,phase=Complete job=None
48.9316,Job,MODIFIED,eval-sanitize-20-r3-029,
48.9725,Job,MODIFIED,eval-sanitize-20-r3-034,
48.9784,Node,MODIFIED,kind-worker4,taints=0
48.9814,Job,MODIFIED,eval-sanitize-20-r3-034,
48.9867,Pod,MODIFIED,eval-sanitize-20-r3-047-zd5js,phase=Running node=kind-worker4
49.0123,TaskRequest,ADDED,eval-sanitize-20-r3-049,phase=None job=None
49.017,TaskRequest,MODIFIED,eval-sanitize-20-r3-049,phase=Pending job=None
49.0179,Event,ADDED,eval-sanitize-20-r3-045.18d41b325fa88529,reason=SuccessfulCreate count=1 msg=Created pod: eval-sanitize-20-r3-045-r687p
49.033,Job,ADDED,eval-sanitize-20-r3-049,
49.0371,TaskRequest,MODIFIED,eval-sanitize-20-r3-049,phase=Scheduled job=None
49.0407,Job,MODIFIED,eval-sanitize-20-r3-049,
49.0438,TaskRequest,MODIFIED,eval-sanitize-20-r3-049,phase=Scheduled job=None
49.0741,Pod,MODIFIED,eval-sanitize-20-r3-036-slccs,phase=Succeeded node=kind-worker2
49.1521,Pod,MODIFIED,eval-sanitize-20-r3-046-vwfpx,phase=Running node=kind-worker5
49.1687,Job,MODIFIED,eval-sanitize-20-r3-048,
49.1772,Job,MODIFIED,eval-sanitize-20-r3-048,
49.2191,Job,MODIFIED,eval-sanitize-20-r3-031,
49.2246,TaskRequest,MODIFIED,eval-sanitize-20-r3-031,phase=Complete job=None
49.2353,Job,MODIFIED,eval-sanitize-20-r3-031,
49.2599,Pod,MODIFIED,eval-sanitize-20-r3-037-b44z7,phase=Succeeded node=kind-worker5
49.3173,Event,ADDED,eval-sanitize-20-r3-012.18d41b3264ba5ea3,reason=Completed count=1 msg=Job completed
49.3318,Node,MODIFIED,kind-worker5,taints=1
49.3347,Event,ADDED,eval-sanitize-20-r3-048-vzkh2.18d41b32fd9545be,"reason=Pulled count=1 msg=Container image ""busybox:musl"" already present on machine"
49.3453,Node,MODIFIED,kind-worker5,taints=1
49.3537,Event,ADDED,eval-sanitize-20-r3-048-vzkh2.18d41b32feb934b1,reason=Created count=1 msg=Created container: task
49.4034,Event,ADDED,eval-sanitize-20-r3-048-vzkh2.18d41b33019f2680,reason=Started count=1 msg=Started container task
49.4193,Job,MODIFIED,eval-sanitize-20-r3-032,
49.4229,TaskRequest,MODIFIED,eval-sanitize-20-r3-032,phase=Complete job=None
49.433,Job,MODIFIED,eval-sanitize-20-r3-032,
49.4778,Pod,ADDED,eval-sanitize-20-r3-049-fxkt7,phase=Pending node=None
49.4859,Pod,MODIFIED,eval-sanitize-20-r3-049-fxkt7,phase=Pending node=None
49.4863,Event,ADDED,eval-sanitize-20-r3-049-fxkt7.18d41b33068b012b,"reason=FailedScheduling count=None msg=0/6 nodes are available: 1 c_wall violated: 2 conflicting context pair(s) with node memory, 5 node(s) had untolerated taint(s). no new claims to deallocate, preemption: 0/6 nodes are available: 1 No preemption victims found for incoming pod, 5 Preemption is not helpful for scheduling."
49.4917,Event,ADDED,eval-sanitize-20-r3-049-fxkt7.18d41b3306fdbb6a,"reason=FailedScheduling count=None msg=0/6 nodes are available: 1 c_wall violated: 2 conflicting context pair(s) with node memory, 5 node(s) had untolerated taint(s). no new claims to deallocate, preemption: 0/6 nodes are available: 1 No preemption victims found for incoming pod, 5 Preemption is not helpful for scheduling."
49.5176,Job,MODIFIED,eval-sanitize-20-r3-047,
49.526,Job,MODIFIED,eval-sanitize-20-r3-047,
49.5697,Job,MODIFIED,eval-sanitize-20-r3-035,
49.5789,Job,MODIFIED,eval-sanitize-20-r3-035,
49.5854,Pod,MODIFIED,eval-sanitize-20-r3-038-hxklj,phase=Running node=kind-worker3
49.5928,Event,MODIFIED,eval-sanitize-20-r3-049-fxkt7.18d41b3306fdbb6a,"reason=FailedScheduling count=None msg=0/6 nodes are available: 1 c_wall violated: 2 conflicting context pair(s) with node memory, 5 node(s) had untolerated taint(s). no new claims to deallocate, preemption: 0/6 nodes are available: 1 No preemption victims found for incoming pod, 5 Preemption is not helpful for scheduling."
49.6184,Event,ADDED,eval-sanitize-20-r3-021.18d41b327c9c2ac9,reason=Completed count=1 msg=Job completed
49.675,Job,MODIFIED,eval-sanitize-20-r3-037,
49.6857,Job,MODIFIED,eval-sanitize-20-r3-037,
49.7193,Job,MODIFIED,eval-sanitize-20-r3-033,
49.7225,TaskRequest,MODIFIED,eval-sanitize-20-r3-033,phase=Complete job=None
49.7325,Job,MODIFIED,eval-sanitize-20-r3-033,
49.764,Pod,MODIFIED,eval-sanitize-20-r3-039-6gdd4,phase=Running node=kind-worker
49.7686,Job,MODIFIED,eval-sanitize-20-r3-049,
49.778,Job,MODIFIED,eval-sanitize-20-r3-049,
49.824,Job,MODIFIED,eval-sanitize-20-r3-036,
49.8334,Job,MODIFIED,eval-sanitize-20-r3-036,
49.9264,Event,ADDED,eval-sanitize-20-r3-027.18d41b32829c5c36,reason=Completed count=1 msg=Job completed
49.9857,Pod,MODIFIED,eval-sanitize-20-r3-037-b44z7,phase=Succeeded node=kind-worker5
49.9915,Pod,MODIFIED,eval-sanitize-20-r3-048-vzkh2,phase=Running node=kind-worker4
50.0069,TaskRequest,ADDED,eval-sanitize-20-r3-050,phase=None job=None
50.0102,TaskRequest,MODIFIED,eval-sanitize-20-r3-050,phase=Pending job=None
50.0256,Job,ADDED,eval-sanitize-20-r3-050,
50.0296,TaskRequest,MODIFIED,eval-sanitize-20-r3-050,phase=Scheduled job=None
50.0337,Job,MODIFIED,eval-sanitize-20-r3-050,
50.0366,TaskRequest,MODIFIED,eval-sanitize-20-r3-050,phase=Scheduled job=None
50.0821,Job,MODIFIED,eval-sanitize-20-r3-035,
50.0864,TaskRequest,MODIFIED,eval-sanitize-20-r3-035,phase=Complete job=None
50.0953,Job,MODIFIED,eval-sanitize-20-r3-035,
50.1232,Event,ADDED,eval-sanitize-20-r3-015.18d41b32863c3b4b,reason=Completed count=1 msg=Job completed
50.1788,Job,MODIFIED,eval-sanitize-20-r3-034,
50.1826,TaskRequest,MODIFIED,eval-sanitize-20-r3-034,phase=Complete job=None
50.1915,Job,MODIFIED,eval-sanitize-20-r3-034,
50.2725,Pod,ADDED,eval-sanitize-20-r3-050-lzwr9,phase=Pending node=None
50.2808,Pod,MODIFIED,eval-sanitize-20-r3-050-lzwr9,phase=Pending node=None
50.2811,Event,ADDED,eval-sanitize-20-r3-050-lzwr9.18d41b3335ece8e6,"reason=FailedScheduling count=None msg=0/6 nodes are available: 1 c_wall violated: 1 conflicting context pair(s) with node memory, 5 node(s) had untolerated taint(s). no new claims to deallocate, preemption: 0/6 nodes are available: 1 No preemption victims found for incoming pod, 5 Preemption is not helpful for scheduling."
50.2868,Event,ADDED,eval-sanitize-20-r3-050-lzwr9.18d41b33366025d0,"reason=FailedScheduling count=None msg=0/6 nodes are available: 1 c_wall violated: 1 conflicting context pair(s) with node memory, 5 node(s) had untolerated taint(s). no new claims to deallocate, preemption: 0/6 nodes are available: 1 No preemption victims found for incoming pod, 5 Preemption is not helpful for scheduling."
50.3319,Event,ADDED,eval-sanitize-20-r3-025.18d41b328beb7c34,reason=Completed count=1 msg=Job completed
50.3687,Job,MODIFIED,eval-sanitize-20-r3-046,
50.3775,Job,MODIFIED,eval-sanitize-20-r3-046,
50.4278,Job,MODIFIED,eval-sanitize-20-r3-048,
50.4366,Job,MODIFIED,eval-sanitize-20-r3-048,
50.4682,Job,MODIFIED,eval-sanitize-20-r3-037,
50.4768,Job,MODIFIED,eval-sanitize-20-r3-037,
50.5677,Event,ADDED,eval-sanitize-20-r3-046.18d41b32955a32c9,reason=SuccessfulCreate count=1 msg=Created pod: eval-sanitize-20-r3-046-vwfpx
50.6215,Job,MODIFIED,eval-sanitize-20-r3-036,
50.6255,TaskRequest,MODIFIED,eval-sanitize-20-r3-036,phase=Complete job=None
50.6364,Job,MODIFIED,eval-sanitize-20-r3-036,
50.7252,Event,ADDED,eval-sanitize-20-r3-018.18d41b32a07fd605,reason=Completed count=1 msg=Job completed
50.7346,Pod,MODIFIED,eval-sanitize-20-r3-038-hxklj,phase=Succeeded node=kind-worker3
50.7471,Event,MODIFIED,eval-sanitize-20-r3-050-lzwr9.18d41b33366025d0,"reason=FailedScheduling count=None msg=0/6 nodes are available: 1 c_wall violated: 1 conflicting context pair(s) with node memory, 5 node(s) had untolerated taint(s). no new claims to deallocate, preemption: 0/6 nodes are available: 1 No preemption victims found for incoming pod, 5 Preemption is not helpful for scheduling."
50.7689,Job,MODIFIED,eval-sanitize-20-r3-038,
50.779,Job,MODIFIED,eval-sanitize-20-r3-038,
50.8235,Event,ADDED,eval-sanitize-20-r3-047.18d41b32b2608e7d,reason=SuccessfulCreate count=1 msg=Created pod: eval-sanitize-20-r3-047-zd5js
50.8736,Job,MODIFIED,eval-sanitize-20-r3-039,
50.8818,Pod,MODIFIED,eval-sanitize-20-r3-039-6gdd4,phase=Succeeded node=kind-worker
50.8833,Job,MODIFIED,eval-sanitize-20-r3-039,
50.928,Event,ADDED,eval-sanitize-20-r3-014.18d41b32b84d0947,reason=Completed count=1 msg=Job completed
50.9712,Event,ADDED,eval-sanitize-20-r3-023.18d41b32ca4e92fb,reason=Completed count=1 msg=Job completed
51.0236,Pod,MODIFIED,eval-sanitize-20-r3-040-p6zwl,phase=Running node=kind-worker2
51.0239,Event,ADDED,eval-sanitize-20-r3-030.18d41b32d62527df,reason=Completed count=1 msg=Job completed
51.024,TaskRequest,ADDED,eval-sanitize-20-r3-051,phase=None job=None
51.0286,TaskRequest,MODIFIED,eval-sanitize-20-r3-051,phase=Pending job=None
51.0457,Job,ADDED,eval-sanitize-20-r3-051,
51.0501,TaskRequest,MODIFIED,eval-sanitize-20-r3-051,phase=Scheduled job=None
51.0545,Job,MODIFIED,eval-sanitize-20-r3-051,
51.0578,TaskRequest,MODIFIED,eval-sanitize-20-r3-051,phase=Scheduled job=None
51.0671,Event,ADDED,eval-sanitize-20-r3-048.18d41b32e279599a,reason=SuccessfulCreate count=1 msg=Created pod: eval-sanitize-20-r3-048-vzkh2
51.1295,Job,MODIFIED,eval-sanitize-20-r3-050,
51.1387,Job,MODIFIED,eval-sanitize-20-r3-050,
51.1852,Pod,ADDED,eval-sanitize-20-r3-051-xgx9f,phase=Pending node=None
51.1948,Pod,MODIFIED,eval-sanitize-20-r3-051-xgx9f,phase=Pending node=None
51.1951,Event,ADDED,eval-sanitize-20-r3-051-xgx9f.18d41b336c5e38d4,"reason=FailedScheduling count=None msg=0/6 nodes are available: 1 c_wall violated: 2 conflicting context pair(s) with node memory, 5 node(s) had untolerated taint(s). no new claims to deallocate, preemption: 0/6 nodes are available: 1 No preemption victims found for incoming pod, 5 Preemption is not helpful for scheduling."
51.2024,Event,ADDED,eval-sanitize-20-r3-051-xgx9f.18d41b336ce1c91e,"reason=FailedScheduling count=None msg=0/6 nodes are available: 1 c_wall violated: 2 conflicting context pair(s) with node memory, 5 node(s) had untolerated taint(s). no new claims to deallocate, preemption: 0/6 nodes are available: 1 No preemption victims found for incoming pod, 5 Preemption is not helpful for scheduling."
51.2173,Event,ADDED,eval-sanitize-20-r3-029.18d41b32e4fc5ad5,reason=Completed count=1 msg=Job completed
51.3204,Event,ADDED,eval-sanitize-20-r3-031.18d41b32f6edc3da,reason=Completed count=1 msg=Job completed
51.3784,Event,ADDED,eval-sanitize-20-r3-032.18d41b3302d7cd1f,reason=Completed count=1 msg=Job completed
51.4202,Event,ADDED,eval-sanitize-20-r3-049.18d41b330655eab2,reason=SuccessfulCreate count=1 msg=Created pod: eval-sanitize-20-r3-049-fxkt7
51.4739,Event,ADDED,eval-sanitize-20-r3-033.18d41b3314bac7d1,reason=Completed count=1 msg=Job completed
51.5188,Job,MODIFIED,eval-sanitize-20-r3-037,
51.5228,TaskRequest,MODIFIED,eval-sanitize-20-r3-037,phase=Complete job=None
51.5332,Job,MODIFIED,eval-sanitize-20-r3-037,
51.5679,Event,ADDED,eval-sanitize-20-r3-035.18d41b332a5a58d7,reason=Completed count=1 msg=Job completed
51.6176,Event,ADDED,eval-sanitize-20-r3-034.18d41b33301eb2d3,reason=Completed count=1 msg=Job completed
51.6768,Event,ADDED,eval-sanitize-20-r3-050.18d41b3335b460e7,reason=SuccessfulCreate count=1 msg=Created pod: eval-sanitize-20-r3-050-lzwr9
51.7285,Event,ADDED,eval-sanitize-20-r3-036.18d41b334a7eb528,reason=Completed count=1 msg=Job completed
51.7739,Event,ADDED,eval-sanitize-20-r3-051.18d41b336c1c25f6,reason=SuccessfulCreate count=1 msg=Created pod: eval-sanitize-20-r3-051-xgx9f
51.8277,Job,MODIFIED,eval-sanitize-20-r3-038,
51.8379,Job,MODIFIED,eval-sanitize-20-r3-038,
51.8779,Event,ADDED,eval-sanitize-20-r3-037.18d41b337ffee0c1,reason=Completed count=1 msg=Job completed
51.929,Pod,MODIFIED,eval-sanitize-20-r3-038-hxklj,phase=Succeeded node=kind-worker3
51.9763,Job,MODIFIED,eval-sanitize-20-r3-039,
51.9861,Job,MODIFIED,eval-sanitize-20-r3-039,
52.0085,TaskRequest,ADDED,eval-sanitize-20-r3-052,phase=None job=None
52.0125,Pod,MODIFIED,eval-sanitize-20-r3-041-pdkzt,phase=Running node=kind-worker2
52.0126,TaskRequest,MODIFIED,eval-sanitize-20-r3-052,phase=Pending job=None
52.0267,Event,MODIFIED,eval-sanitize-20-r3-051-xgx9f.18d41b336ce1c91e,"reason=FailedScheduling count=None msg=0/6 nodes are available: 1 c_wall violated: 2 conflicting context pair(s) with node memory, 5 node(s) had untolerated taint(s). no new claims to deallocate, preemption: 0/6 nodes are available: 1 No preemption victims found for incoming pod, 5 Preemption is not helpful for scheduling."
52.0305,Job,ADDED,eval-sanitize-20-r3-052,
52.0353,TaskRequest,MODIFIED,eval-sanitize-20-r3-052,phase=Scheduled job=None
52.0406,Job,MODIFIED,eval-sanitize-20-r3-052,
52.0422,TaskRequest,MODIFIED,eval-sanitize-20-r3-052,phase=Scheduled job=None
52.0748,Pod,MODIFIED,eval-sanitize-20-r3-039-6gdd4,phase=Succeeded node=kind-worker
52.1222,Job,MODIFIED,eval-sanitize-20-r3-040,
52.1273,Pod,MODIFIED,eval-sanitize-20-r3-040-p6zwl,phase=Succeeded node=kind-worker2
52.131,Job,MODIFIED,eval-sanitize-20-r3-040,
52.1831,Pod,ADDED,eval-sanitize-20-r3-052-j6284,phase=Pending node=None
52.1915,Pod,MODIFIED,eval-sanitize-20-r3-052-j6284,phase=Pending node=None
52.1918,Event,ADDED,eval-sanitize-20-r3-052-j6284.18d41b33a7cfdfd6,"reason=FailedScheduling count=None msg=0/6 nodes are available: 1 c_wall violated: 1 conflicting context pair(s) with node memory, 5 node(s) had untolerated taint(s). no new claims to deallocate, preemption: 0/6 nodes are available: 1 No preemption victims found for incoming pod, 5 Preemption is not helpful for scheduling."
52.1987,Event,ADDED,eval-sanitize-20-r3-052-j6284.18d41b33a84654c1,"reason=FailedScheduling count=None msg=0/6 nodes are available: 1 c_wall violated: 1 conflicting context pair(s) with node memory, 5 node(s) had untolerated taint(s). no new claims to deallocate, preemption: 0/6 nodes are available: 1 No preemption victims found for incoming pod, 5 Preemption is not helpful for scheduling."
52.2181,Job,MODIFIED,eval-sanitize-20-r3-051,
52.2267,Job,MODIFIED,eval-sanitize-20-r3-051,
52.3723,Event,ADDED,eval-sanitize-20-r3-052.18d41b33a79947de,reason=SuccessfulCreate count=1 msg=Created pod: eval-sanitize-20-r3-052-j6284
52.8376,Job,MODIFIED,eval-sanitize-20-r3-038,
52.842,Job,MODIFIED,eval-sanitize-20-r3-038,
52.8473,Event,ADDED,eval-sanitize-20-r3-038.18d41b33cee09cc2,reason=Completed count=1 msg=Job completed
52.8537,Job,MODIFIED,eval-sanitize-20-r3-038,
52.8574,TaskRequest,MODIFIED,eval-sanitize-20-r3-038,phase=Complete job=None
52.866,Job,MODIFIED,eval-sanitize-20-r3-038,
52.9864,Job,MODIFIED,eval-sanitize-20-r3-039,
52.9917,Job,MODIFIED,eval-sanitize-20-r3-039,
52.996,Event,ADDED,eval-sanitize-20-r3-039.18d41b33d7d389a5,reason=Completed count=1 msg=Job completed
53.0022,Job,MODIFIED,eval-sanitize-20-r3-039,
53.007,TaskRequest,ADDED,eval-sanitize-20-r3-053,phase=None job=None
53.0083,TaskRequest,MODIFIED,eval-sanitize-20-r3-039,phase=Complete job=None
53.0138,TaskRequest,MODIFIED,eval-sanitize-20-r3-053,phase=Pending job=None
53.0176,Job,MODIFIED,eval-sanitize-20-r3-041,
53.0199,Job,MODIFIED,eval-sanitize-20-r3-039,
53.0303,Job,ADDED,eval-sanitize-20-r3-053,
53.0377,Pod,ADDED,eval-sanitize-20-r3-053-ltx59,phase=Pending node=None
53.0396,Job,MODIFIED,eval-sanitize-20-r3-053,
53.0468,Event,ADDED,eval-sanitize-20-r3-053.18d41b33da8c0e8b,reason=SuccessfulCreate count=1 msg=Created pod: eval-sanitize-20-r3-053-ltx59
53.0476,Job,MODIFIED,eval-sanitize-20-r3-052,
53.0486,Event,ADDED,eval-sanitize-20-r3-053-ltx59.18d41b33dad03ac9,"reason=FailedScheduling count=None msg=0/6 nodes are available: 1 c_wall violated: 1 conflicting context pair(s) with node memory, 5 node(s) had untolerated taint(s). no new claims to deallocate, preemption: 0/6 nodes are available: 1 No preemption victims found for incoming pod, 5 Preemption is not helpful for scheduling."
53.0499,Pod,MODIFIED,eval-sanitize-20-r3-053-ltx59,phase=Pending node=None
53.0595,Event,ADDED,eval-sanitize-20-r3-053-ltx59.18d41b33db7f26c5,"reason=FailedScheduling count=None msg=0/6 nodes are available: 1 c_wall violated: 1 conflicting context pair(s) with node memory, 5 node(s) had untolerated taint(s). no new claims to deallocate, preemption: 0/6 nodes are available: 1 No preemption victims found for incoming pod, 5 Preemption is not helpful for scheduling."
53.0712,TaskRequest,MODIFIED,eval-sanitize-20-r3-053,phase=Scheduled job=None
53.079,TaskRequest,MODIFIED,eval-sanitize-20-r3-053,phase=Scheduled job=None
53.0821,Job,MODIFIED,eval-sanitize-20-r3-041,
53.0841,Job,MODIFIED,eval-sanitize-20-r3-052,
53.1071,Pod,MODIFIED,eval-sanitize-20-r3-041-pdkzt,phase=Succeeded node=kind-worker2
53.1245,Event,MODIFIED,eval-sanitize-20-r3-052-j6284.18d41b33a84654c1,"reason=FailedScheduling count=None msg=0/6 nodes are available: 1 c_wall violated: 1 conflicting context pair(s) with node memory, 5 node(s) had untolerated taint(s). no new claims to deallocate, preemption: 0/6 nodes are available: 1 No preemption victims found for incoming pod, 5 Preemption is not helpful for scheduling."
53.1272,Job,MODIFIED,eval-sanitize-20-r3-040,
53.1275,Event,MODIFIED,eval-sanitize-20-r3-053-ltx59.18d41b33db7f26c5,"reason=FailedScheduling count=None msg=0/6 nodes are available: 1 c_wall violated: 1 conflicting context pair(s) with node memory, 5 node(s) had untolerated taint(s). no new claims to deallocate, preemption: 0/6 nodes are available: 1 No preemption victims found for incoming pod, 5 Preemption is not helpful for scheduling."
53.1354,Pod,MODIFIED,eval-sanitize-20-r3-040-p6zwl,phase=Succeeded node=kind-worker2
53.1368,Job,MODIFIED,eval-sanitize-20-r3-040,
54.0083,TaskRequest,ADDED,eval-sanitize-20-r3-054,phase=None job=None
54.0124,TaskRequest,MODIFIED,eval-sanitize-20-r3-054,phase=Pending job=None
54.0239,Job,MODIFIED,eval-sanitize-20-r3-041,
54.0273,Job,ADDED,eval-sanitize-20-r3-054,
54.0316,Pod,MODIFIED,eval-sanitize-20-r3-041-pdkzt,phase=Succeeded node=kind-worker2
54.0326,Pod,ADDED,eval-sanitize-20-r3-054-hfq7n,phase=Pending node=None
54.0348,TaskRequest,MODIFIED,eval-sanitize-20-r3-054,phase=Scheduled job=None
54.0381,Job,MODIFIED,eval-sanitize-20-r3-054,
54.0385,Event,ADDED,eval-sanitize-20-r3-054.18d41b3415d9fada,reason=SuccessfulCreate count=1 msg=Created pod: eval-sanitize-20-r3-054-hfq7n
54.04,Job,MODIFIED,eval-sanitize-20-r3-041,
54.0417,Pod,MODIFIED,eval-sanitize-20-r3-054-hfq7n,phase=Pending node=None
54.0431,Event,ADDED,eval-sanitize-20-r3-054-hfq7n.18d41b3416156ea0,"reason=FailedScheduling count=None msg=0/6 nodes are available: 1 c_wall violated: 2 conflicting context pair(s) with node memory, 5 node(s) had untolerated taint(s). no new claims to deallocate, preemption: 0/6 nodes are available: 1 No preemption victims found for incoming pod, 5 Preemption is not helpful for scheduling."
54.0438,Job,MODIFIED,eval-sanitize-20-r3-053,
54.0458,Event,ADDED,eval-sanitize-20-r3-041.18d41b34162e061b,reason=Completed count=1 msg=Job completed
54.0459,TaskRequest,MODIFIED,eval-sanitize-20-r3-054,phase=Scheduled job=None
54.0468,Job,MODIFIED,eval-sanitize-20-r3-041,
54.0493,Event,ADDED,eval-sanitize-20-r3-054-hfq7n.18d41b34169f03f7,"reason=FailedScheduling count=None msg=0/6 nodes are available: 1 c_wall violated: 2 conflicting context pair(s) with node memory, 5 node(s) had untolerated taint(s). no new claims to deallocate, preemption: 0/6 nodes are available: 1 No preemption victims found for incoming pod, 5 Preemption is not helpful for scheduling."
54.0531,Job,MODIFIED,eval-sanitize-20-r3-053,
54.0535,TaskRequest,MODIFIED,eval-sanitize-20-r3-041,phase=Complete job=None
54.1152,Job,MODIFIED,eval-sanitize-20-r3-041,
54.1326,Job,MODIFIED,eval-sanitize-20-r3-040,
54.1372,Job,MODIFIED,eval-sanitize-20-r3-040,
54.1426,Event,ADDED,eval-sanitize-20-r3-040.18d41b341c0d2c17,reason=Completed count=1 msg=Job completed
54.1489,Job,MODIFIED,eval-sanitize-20-r3-040,
54.1534,TaskRequest,MODIFIED,eval-sanitize-20-r3-040,phase=Complete job=None
54.1627,Job,MODIFIED,eval-sanitize-20-r3-040,
54.6071,Pod,MODIFIED,eval-sanitize-20-r3-042-p8bkn,phase=Running node=kind-worker3
54.6311,Event,MODIFIED,eval-sanitize-20-r3-054-hfq7n.18d41b34169f03f7,"reason=FailedScheduling count=None msg=0/6 nodes are available: 1 c_wall violated: 2 conflicting context pair(s) with node memory, 5 node(s) had untolerated taint(s). no new claims to deallocate, preemption: 0/6 nodes are available: 1 No preemption victims found for incoming pod, 5 Preemption is not helpful for scheduling."
55.0106,TaskRequest,ADDED,eval-sanitize-20-r3-055,phase=None job=None
55.0144,TaskRequest,MODIFIED,eval-sanitize-20-r3-055,phase=Pending job=None
55.0306,Job,ADDED,eval-sanitize-20-r3-055,
55.0344,TaskRequest,MODIFIED,eval-sanitize-20-r3-055,phase=Scheduled job=None
55.0372,Pod,ADDED,eval-sanitize-20-r3-055-88wc4,phase=Pending node=None
55.0393,Job,MODIFIED,eval-sanitize-20-r3-054,
55.0401,Job,MODIFIED,eval-sanitize-20-r3-055,
55.0431,TaskRequest,MODIFIED,eval-sanitize-20-r3-055,phase=Scheduled job=None
55.0435,Event,ADDED,eval-sanitize-20-r3-055.18d41b3451bbd950,reason=SuccessfulCreate count=1 msg=Created pod: eval-sanitize-20-r3-055-88wc4
55.0461,Pod,MODIFIED,eval-sanitize-20-r3-055-88wc4,phase=Pending node=kind-worker4
55.049,Job,MODIFIED,eval-sanitize-20-r3-054,
55.0497,Event,ADDED,eval-sanitize-20-r3-055-88wc4.18d41b34523efb63,reason=Scheduled count=None msg=Successfully assigned compute/eval-sanitize-20-r3-055-88wc4 to kind-worker4
55.0583,Node,MODIFIED,kind-worker4,taints=0
55.0602,Pod,MODIFIED,eval-sanitize-20-r3-055-88wc4,phase=Pending node=kind-worker4
55.0618,Pod,MODIFIED,eval-sanitize-20-r3-051-xgx9f,phase=Pending node=None
55.0688,Node,MODIFIED,kind-worker4,taints=0
55.1262,Pod,MODIFIED,eval-sanitize-20-r3-054-hfq7n,phase=Pending node=None
55.157,Event,ADDED,eval-sanitize-20-r3-051-xgx9f.18d41b345888010e,"reason=FailedScheduling count=None msg=0/6 nodes are available: 1 c_wall violated: 3 conflicting context pair(s) with node memory, 5 node(s) had untolerated taint(s). no new claims to deallocate, preemption: 0/6 nodes are available: 1 No preemption victims found for incoming pod, 5 Preemption is not helpful for scheduling."
55.1629,Event,ADDED,eval-sanitize-20-r3-054-hfq7n.18d41b3459019124,"reason=FailedScheduling count=None msg=0/6 nodes are available: 1 c_wall violated: 3 conflicting context pair(s) with node memory, 5 node(s) had untolerated taint(s). no new claims to deallocate, preemption: 0/6 nodes are available: 1 No preemption victims found for incoming pod, 5 Preemption is not helpful for scheduling."
55.5035,Event,ADDED,eval-sanitize-20-r3-055-88wc4.18d41b346d421572,"reason=Pulled count=1 msg=Container image ""busybox:musl"" already present on machine"
55.5202,Event,ADDED,eval-sanitize-20-r3-055-88wc4.18d41b346e5112bd,reason=Created count=1 msg=Created container: task
55.5965,Event,ADDED,eval-sanitize-20-r3-055-88wc4.18d41b3472d19512,reason=Started count=1 msg=Started container task
55.6029,Pod,MODIFIED,eval-sanitize-20-r3-043-zkwvs,phase=Running node=kind-worker3
55.6113,Job,MODIFIED,eval-sanitize-20-r3-042,
55.6173,Event,MODIFIED,eval-sanitize-20-r3-051-xgx9f.18d41b345888010e,"reason=FailedScheduling count=None msg=0/6 nodes are available: 1 c_wall violated: 3 conflicting context pair(s) with node memory, 5 node(s) had untolerated taint(s). no new claims to deallocate, preemption: 0/6 nodes are available: 1 No preemption victims found for incoming pod, 5 Preemption is not helpful for scheduling."
55.6232,Job,MODIFIED,eval-sanitize-20-r3-042,
55.6268,Event,MODIFIED,eval-sanitize-20-r3-054-hfq7n.18d41b3459019124,"reason=FailedScheduling count=None msg=0/6 nodes are available: 1 c_wall violated: 3 conflicting context pair(s) with node memory, 5 node(s) had untolerated taint(s). no new claims to deallocate, preemption: 0/6 nodes are available: 1 No preemption victims found for incoming pod, 5 Preemption is not helpful for scheduling."
55.7687,Pod,MODIFIED,eval-sanitize-20-r3-042-p8bkn,phase=Succeeded node=kind-worker3
56.0021,Pod,MODIFIED,eval-sanitize-20-r3-055-88wc4,phase=Running node=kind-worker4
56.008,TaskRequest,ADDED,eval-sanitize-20-r3-056,phase=None job=None
56.0117,TaskRequest,MODIFIED,eval-sanitize-20-r3-056,phase=Pending job=None
56.0268,Job,ADDED,eval-sanitize-20-r3-056,
56.034,TaskRequest,MODIFIED,eval-sanitize-20-r3-056,phase=Scheduled job=None
56.0354,Pod,ADDED,eval-sanitize-20-r3-056-bmfg2,phase=Pending node=None
56.0365,Job,MODIFIED,eval-sanitize-20-r3-056,
56.0393,Event,ADDED,eval-sanitize-20-r3-056.18d41b348d30abbf,reason=SuccessfulCreate count=1 msg=Created pod: eval-sanitize-20-r3-056-bmfg2
56.0419,Job,MODIFIED,eval-sanitize-20-r3-055,
56.0441,Pod,MODIFIED,eval-sanitize-20-r3-056-bmfg2,phase=Pending node=None
56.0444,Event,ADDED,eval-sanitize-20-r3-056-bmfg2.18d41b348d74c38e,"reason=FailedScheduling count=None msg=0/6 nodes are available: 1 c_wall violated: 3 conflicting context pair(s) with node memory, 5 node(s) had untolerated taint(s). no new claims to deallocate, preemption: 0/6 nodes are available: 1 No preemption victims found for incoming pod, 5 Preemption is not helpful for scheduling."
56.0446,TaskRequest,MODIFIED,eval-sanitize-20-r3-056,phase=Scheduled job=None
56.0511,Job,MODIFIED,eval-sanitize-20-r3-055,
56.0911,Event,ADDED,eval-sanitize-20-r3-056-bmfg2.18d41b349045f0d4,"reason=FailedScheduling count=None msg=0/6 nodes are available: 1 c_wall violated: 3 conflicting context pair(s) with node memory, 5 node(s) had untolerated taint(s). no new claims to deallocate, preemption: 0/6 nodes are available: 1 No preemption victims found for incoming pod, 5 Preemption is not helpful for scheduling."
56.6121,Job,MODIFIED,eval-sanitize-20-r3-043,
56.6164,Job,MODIFIED,eval-sanitize-20-r3-042,
56.6221,Job,MODIFIED,eval-sanitize-20-r3-043,
56.6247,Pod,MODIFIED,eval-sanitize-20-r3-042-p8bkn,phase=Succeeded node=kind-worker3
56.6263,Job,MODIFIED,eval-sanitize-20-r3-042,
56.6773,Pod,MODIFIED,eval-sanitize-20-r3-043-zkwvs,phase=Succeeded node=kind-worker3
56.7092,Event,MODIFIED,eval-sanitize-20-r3-056-bmfg2.18d41b349045f0d4,"reason=FailedScheduling count=None msg=0/6 nodes are available: 1 c_wall violated: 3 conflicting context pair(s) with node memory, 5 node(s) had untolerated taint(s). no new claims to deallocate, preemption: 0/6 nodes are available: 1 No preemption victims found for incoming pod, 5 Preemption is not helpful for scheduling."
56.7774,Pod,MODIFIED,eval-sanitize-20-r3-044-s9w22,phase=Running node=kind-worker
57.0078,TaskRequest,ADDED,eval-sanitize-20-r3-057,phase=None job=None
57.0146,TaskRequest,MODIFIED,eval-sanitize-20-r3-057,phase=Pending job=None
57.0288,Job,ADDED,eval-sanitize-20-r3-057,
57.0353,Pod,ADDED,eval-sanitize-20-r3-057-kjtnf,phase=Pending node=None
57.0354,TaskRequest,MODIFIED,eval-sanitize-20-r3-057,phase=Scheduled job=None
57.0381,Job,MODIFIED,eval-sanitize-20-r3-057,
57.0403,Job,MODIFIED,eval-sanitize-20-r3-056,
57.0406,Event,ADDED,eval-sanitize-20-r3-057.18d41b34c8ccf8da,reason=SuccessfulCreate count=1 msg=Created pod: eval-sanitize-20-r3-057-kjtnf
57.0438,Pod,MODIFIED,eval-sanitize-20-r3-057-kjtnf,phase=Pending node=None
57.0452,Event,ADDED,eval-sanitize-20-r3-057-kjtnf.18d41b34c90c651c,"reason=FailedScheduling count=None msg=0/6 nodes are available: 1 c_wall violated: 2 conflicting context pair(s) with node memory, 5 node(s) had untolerated taint(s). no new claims to deallocate, preemption: 0/6 nodes are available: 1 No preemption victims found for incoming pod, 5 Preemption is not helpful for scheduling."
57.0453,TaskRequest,MODIFIED,eval-sanitize-20-r3-057,phase=Scheduled job=None
57.0494,Job,MODIFIED,eval-sanitize-20-r3-056,
57.0498,Event,ADDED,eval-sanitize-20-r3-057-kjtnf.18d41b34c987ef74,"reason=FailedScheduling count=None msg=0/6 nodes are available: 1 c_wall violated: 2 conflicting context pair(s) with node memory, 5 node(s) had untolerated taint(s). no new claims to deallocate, preemption: 0/6 nodes are available: 1 No preemption victims found for incoming pod, 5 Preemption is not helpful for scheduling."
57.6239,Job,MODIFIED,eval-sanitize-20-r3-043,
57.6256,Job,MODIFIED,eval-sanitize-20-r3-042,
57.6308,Job,MODIFIED,eval-sanitize-20-r3-042,
57.6337,Pod,MODIFIED,eval-sanitize-20-r3-043-zkwvs,phase=Succeeded node=kind-worker3
57.6352,Job,MODIFIED,eval-sanitize-20-r3-043,
57.6365,Event,ADDED,eval-sanitize-20-r3-042.18d41b34ec52836f,reason=Completed count=1 msg=Job completed
57.6413,Job,MODIFIED,eval-sanitize-20-r3-042,
57.647,TaskRequest,MODIFIED,eval-sanitize-20-r3-042,phase=Complete job=None
57.6563,Job,MODIFIED,eval-sanitize-20-r3-042,
57.7848,Job,MODIFIED,eval-sanitize-20-r3-044,
57.7952,Job,MODIFIED,eval-sanitize-20-r3-044,
57.9359,Pod,MODIFIED,eval-sanitize-20-r3-044-s9w22,phase=Succeeded node=kind-worker
57.9645,Event,MODIFIED,eval-sanitize-20-r3-057-kjtnf.18d41b34c987ef74,"reason=FailedScheduling count=None msg=0/6 nodes are available: 1 c_wall violated: 2 conflicting context pair(s) with node memory, 5 node(s) had untolerated taint(s). no new claims to deallocate, preemption: 0/6 nodes are available: 1 No preemption victims found for incoming pod, 5 Preemption is not helpful for scheduling."
58.0068,TaskRequest,ADDED,eval-sanitize-20-r3-058,phase=None job=None
58.0106,TaskRequest,MODIFIED,eval-sanitize-20-r3-058,phase=Pending job=None
58.027,Job,ADDED,eval-sanitize-20-r3-058,
58.031,Pod,MODIFIED,eval-sanitize-20-r3-045-r687p,phase=Running node=kind-worker2
58.034,Pod,ADDED,eval-sanitize-20-r3-058-vjdj6,phase=Pending node=None
58.0353,TaskRequest,MODIFIED,eval-sanitize-20-r3-058,phase=Scheduled job=None
58.0361,Job,MODIFIED,eval-sanitize-20-r3-058,
58.04,Event,ADDED,eval-sanitize-20-r3-058.18d41b35045a62a9,reason=SuccessfulCreate count=1 msg=Created pod: eval-sanitize-20-r3-058-vjdj6
58.0418,Job,MODIFIED,eval-sanitize-20-r3-057,
58.0437,Pod,MODIFIED,eval-sanitize-20-r3-058-vjdj6,phase=Pending node=kind-worker4
58.0444,TaskRequest,MODIFIED,eval-sanitize-20-r3-058,phase=Scheduled job=None
58.048,Event,ADDED,eval-sanitize-20-r3-058-vjdj6.18d41b3504e9c9e3,reason=Scheduled count=None msg=Successfully assigned compute/eval-sanitize-20-r3-058-vjdj6 to kind-worker4
58.0528,Job,MODIFIED,eval-sanitize-20-r3-057,
58.0556,Pod,MODIFIED,eval-sanitize-20-r3-058-vjdj6,phase=Pending node=kind-worker4
58.4835,Event,ADDED,eval-sanitize-20-r3-058-vjdj6.18d41b351edb2b7d,"reason=Pulled count=1 msg=Container image ""busybox:musl"" already present on machine"
58.5034,Event,ADDED,eval-sanitize-20-r3-058-vjdj6.18d41b3520053856,reason=Created count=1 msg=Created container: task
58.5384,Event,ADDED,eval-sanitize-20-r3-058-vjdj6.18d41b35222da186,reason=Started count=1 msg=Started container task
58.63,Job,MODIFIED,eval-sanitize-20-r3-043,
58.6345,Job,MODIFIED,eval-sanitize-20-r3-043,
58.6393,Event,ADDED,eval-sanitize-20-r3-043.18d41b35282378da,reason=Completed count=1 msg=Job completed
58.6467,Job,MODIFIED,eval-sanitize-20-r3-043,
58.6503,TaskRequest,MODIFIED,eval-sanitize-20-r3-043,phase=Complete job=None
58.6603,Job,MODIFIED,eval-sanitize-20-r3-043,
58.7927,Job,MODIFIED,eval-sanitize-20-r3-044,
58.8023,Pod,MODIFIED,eval-sanitize-20-r3-044-s9w22,phase=Succeeded node=kind-worker
58.8031,Job,MODIFIED,eval-sanitize-20-r3-044,
59.0097,Pod,MODIFIED,eval-sanitize-20-r3-058-vjdj6,phase=Running node=kind-worker4
59.0101,TaskRequest,ADDED,eval-sanitize-20-r3-059,phase=None job=None
59.0166,Pod,MODIFIED,eval-sanitize-20-r3-047-zd5js,phase=Running node=kind-worker4
59.0168,TaskRequest,MODIFIED,eval-sanitize-20-r3-059,phase=Pending job=None
59.0318,Job,ADDED,eval-sanitize-20-r3-059,
59.0362,Job,MODIFIED,eval-sanitize-20-r3-045,
59.0385,Pod,ADDED,eval-sanitize-20-r3-059-xwnbs,phase=Pending node=None
59.0398,TaskRequest,MODIFIED,eval-sanitize-20-r3-059,phase=Scheduled job=None
59.0406,Job,MODIFIED,eval-sanitize-20-r3-058,
59.043,Job,MODIFIED,eval-sanitize-20-r3-059,
59.0446,Event,ADDED,eval-sanitize-20-r3-059.18d41b35403a82f3,reason=SuccessfulCreate count=1 msg=Created pod: eval-sanitize-20-r3-059-xwnbs
59.049,TaskRequest,MODIFIED,eval-sanitize-20-r3-059,phase=Scheduled job=None
59.0526,Job,MODIFIED,eval-sanitize-20-r3-045,
59.0542,Job,MODIFIED,eval-sanitize-20-r3-058,
59.1236,Pod,MODIFIED,eval-sanitize-20-r3-045-r687p,phase=Succeeded node=kind-worker2
59.1254,Pod,MODIFIED,eval-sanitize-20-r3-059-xwnbs,phase=Pending node=kind-worker4
59.1288,Event,ADDED,eval-sanitize-20-r3-059-xwnbs.18d41b354564511d,reason=Scheduled count=None msg=Successfully assigned compute/eval-sanitize-20-r3-059-xwnbs to kind-worker4
59.1353,Pod,MODIFIED,eval-sanitize-20-r3-059-xwnbs,phase=Pending node=kind-worker4
59.1714,Pod,MODIFIED,eval-sanitize-20-r3-046-vwfpx,phase=Running node=kind-worker5
59.5516,Event,ADDED,eval-sanitize-20-r3-059-xwnbs.18d41b355e8bfd4a,"reason=Pulled count=1 msg=Container image ""busybox:musl"" already present on machine"
59.5686,Event,ADDED,eval-sanitize-20-r3-059-xwnbs.18d41b355f99e26d,reason=Created count=1 msg=Created container: task
59.6244,Event,ADDED,eval-sanitize-20-r3-059-xwnbs.18d41b3562da1b0d,reason=Started count=1 msg=Started container task
59.7999,Job,MODIFIED,eval-sanitize-20-r3-044,
59.8041,Job,MODIFIED,eval-sanitize-20-r3-044,
59.807,Event,ADDED,eval-sanitize-20-r3-044.18d41b356ddf3f75,reason=Completed count=1 msg=Job completed
59.8155,Job,MODIFIED,eval-sanitize-20-r3-044,
59.8194,TaskRequest,MODIFIED,eval-sanitize-20-r3-044,phase=Complete job=None
59.83,Job,MODIFIED,eval-sanitize-20-r3-044,
60.0084,TaskRequest,ADDED,eval-sanitize-20-r3-060,phase=None job=None
60.0166,Pod,ADDED,eval-sanitize-20-r3-000-2x82f,phase=Succeeded node=kind-worker
60.0198,Pod,ADDED,eval-sanitize-20-r3-001-zqtnq,phase=Succeeded node=kind-worker5
60.0219,Pod,ADDED,eval-sanitize-20-r3-002-6p6k5,phase=Succeeded node=kind-worker3
60.0234,Event,ADDED,eval-sanitize-20-r1-012-m6skw.18d41aa0e5463ab7,"reason=FailedScheduling count=None msg=0/6 nodes are available: 1 node(s) had untolerated taint(s), 2 c_wall violated: 2 conflicting context pair(s) with node memory, 3 c_wall violated: 1 conflicting context pair(s) with node memory. no new claims to deallocate, preemption: 0/6 nodes are available: 1 Preemption is not helpful for scheduling, 5 No preemption victims found for incoming pod."
60.0261,Pod,ADDED,eval-sanitize-20-r3-003-wh2ts,phase=Succeeded node=kind-worker3
60.0263,TaskRequest,ADDED,eval-sanitize-20-r3-000,phase=Complete job=None
60.0266,Event,ADDED,eval-sanitize-20-r1-012-m6skw.18d41aa167dc56a0,"reason=FailedScheduling count=None msg=0/6 nodes are available: 1 c_wall violated: 2 conflicting context pair(s) with node memory, 2 node(s) had untolerated taint(s), 3 c_wall violated: 1 conflicting context pair(s) with node memory. no new claims to deallocate, preemption: 0/6 nodes are available: 2 Preemption is not helpful for scheduling, 4 No preemption victims found for incoming pod."
60.0271,Event,ADDED,eval-sanitize-20-r1-012-m6skw.18d41aa197e5e65e,"reason=FailedScheduling count=None msg=0/6 nodes are available: 1 c_wall violated: 2 conflicting context pair(s) with node memory, 2 c_wall violated: 1 conflicting context pair(s) with node memory, 3 node(s) had untolerated taint(s). no new claims to deallocate, preemption: 0/6 nodes are available: 3 No preemption victims found for incoming pod, 3 Preemption is not helpful for scheduling."
60.0276,Event,ADDED,eval-sanitize-20-r1-012-m6skw.18d41aa1b3948e66,"reason=FailedScheduling count=None msg=0/6 nodes are available: 2 c_wall violated: 1 conflicting context pair(s) with node memory, 4 node(s) had untolerated taint(s). no new claims to deallocate, preemption: 0/6 nodes are available: 2 No preemption victims found for incoming pod, 4 Preemption is not helpful for scheduling."
60.0293,Job,ADDED,eval-sanitize-20-r3-000,
60.0307,Node,ADDED,kind-control-plane,taints=1
60.0322,Pod,ADDED,eval-sanitize-20-r3-004-2jl8f,phase=Succeeded node=kind-worker2
60.0323,TaskRequest,ADDED,eval-sanitize-20-r3-001,phase=Complete job=None
60.0323,TaskRequest,ADDED,eval-sanitize-20-r3-002,phase=Complete job=None
60.0326,Event,ADDED,eval-sanitize-20-r1-012-m6skw.18d41aa200c7d429,"reason=FailedScheduling count=None msg=0/6 nodes are available: 1 c_wall violated: 1 conflicting context pair(s) with node memory, 5 node(s) had untolerated taint(s). no new claims to deallocate, preemption: 0/6 nodes are available: 1 No preemption victims found for incoming pod, 5 Preemption is not helpful for scheduling."
60.0329,Event,ADDED,eval-sanitize-20-r1-016-rhx4s.18d41aa1ca08d5b7,"reason=FailedScheduling count=None msg=0/6 nodes are available: 2 c_wall violated: 1 conflicting context pair(s) with node memory, 4 node(s) had untolerated taint(s). no new claims to deallocate, preemption: 0/6 nodes are available: 2 No preemption victims found for incoming pod, 4 Preemption is not helpful for scheduling."
60.0331,TaskRequest,ADDED,eval-sanitize-20-r3-003,phase=Complete job=None
60.0331,TaskRequest,ADDED,eval-sanitize-20-r3-004,phase=Complete job=None
60.0331,TaskRequest,ADDED,eval-sanitize-20-r3-005,phase=Complete job=None
60.0332,TaskRequest,ADDED,eval-sanitize-20-r3-006,phase=Complete job=None
60.0332,TaskRequest,ADDED,eval-sanitize-20-r3-007,phase=Complete job=None
60.0333,TaskRequest,ADDED,eval-sanitize-20-r3-008,phase=Complete job=None
60.0336,Event,ADDED,eval-sanitize-20-r1-016-rhx4s.18d41aa200eb824c,"reason=FailedScheduling count=None msg=0/6 nodes are available: 1 c_wall violated: 1 conflicting context pair(s) with node memory, 5 node(s) had untolerated taint(s). no new claims to deallocate, preemption: 0/6 nodes are available: 1 No preemption victims found for incoming pod, 5 Preemption is not helpful for scheduling."
60.0338,Event,ADDED,eval-sanitize-20-r1-019-dl74d.18d41aa624594873,"reason=FailedScheduling count=None msg=0/6 nodes are available: 1 c_wall violated: 2 conflicting context pair(s) with node memory, 5 node(s) had untolerated taint(s). no new claims to deallocate, preemption: 0/6 nodes are available: 1 No preemption victims found for incoming pod, 5 Preemption is not helpful for scheduling."
60.0341,Event,ADDED,eval-sanitize-20-r1-021-77dzv.18d41aa6298ecc45,"reason=FailedScheduling count=None msg=0/6 nodes are available: 1 c_wall violated: 2 conflicting context pair(s) with node memory, 5 node(s) had untolerated taint(s). no new claims to deallocate, preemption: 0/6 nodes are available: 1 No preemption victims found for incoming pod, 5 Preemption is not helpful for scheduling."
60.0352,Pod,ADDED,eval-sanitize-20-r3-005-6gx5c,phase=Succeeded node=kind-worker3
60.036,Job,ADDED,eval-sanitize-20-r3-001,
60.0368,Job,ADDED,eval-sanitize-20-r3-002,
60.0369,TaskRequest,ADDED,eval-sanitize-20-r3-009,phase=Complete job=None
60.0369,TaskRequest,ADDED,eval-sanitize-20-r3-010,phase=Complete job=None
60.0372,Event,ADDED,eval-sanitize-20-r1-021-77dzv.18d41aa657834e4d,"reason=FailedScheduling count=None msg=0/6 nodes are available: 2 c_wall violated: 2 conflicting context pair(s) with node memory, 4 node(s) had untolerated taint(s). no new claims to deallocate, preemption: 0/6 nodes are available: 2 No preemption victims found for incoming pod, 4 Preemption is not helpful for scheduling."
60.0375,Event,ADDED,eval-sanitize-20-r1-021-77dzv.18d41aa693430262,"reason=FailedScheduling count=None msg=0/6 nodes are available: 1 c_wall violated: 1 conflicting context pair(s) with node memory, 2 c_wall violated: 2 conflicting context pair(s) with node memory, 3 node(s) had untolerated taint(s). no new claims to deallocate, preemption: 0/6 nodes are available: 3 No preemption victims found for incoming pod, 3 Preemption is not helpful for scheduling."
60.0377,Event,ADDED,eval-sanitize-20-r1-022-qr2sk.18d41aa629c0853a,"reason=FailedScheduling count=None msg=0/6 nodes are available: 1 c_wall violated: 2 conflicting context pair(s) with node memory, 5 node(s) had untolerated taint(s). no new claims to deallocate, preemption: 0/6 nodes are available: 1 No preemption victims found for incoming pod, 5 Preemption is not helpful for scheduling."
60.0389,Pod,ADDED,eval-sanitize-20-r3-006-wc75b,phase=Succeeded node=kind-worker4
60.0393,Event,ADDED,eval-sanitize-20-r1-023-lhw8g.18d41aa629f759a2,"reason=FailedScheduling count=None msg=0/6 nodes are available: 1 c_wall violated: 1 conflicting context pair(s) with node memory, 5 node(s) had untolerated taint(s). no new claims to deallocate, preemption: 0/6 nodes are available: 1 No preemption victims found for incoming pod, 5 Preemption is not helpful for scheduling."
60.0395,Event,ADDED,eval-sanitize-20-r1-024-jjnk6.18d41aa62a2b7de3,"reason=FailedScheduling count=None msg=0/6 nodes are available: 1 c_wall violated: 2 conflicting context pair(s) with node memory, 5 node(s) had untolerated taint(s). no new claims to deallocate, preemption: 0/6 nodes are available: 1 No preemption victims found for incoming pod, 5 Preemption is not helpful for scheduling."
60.0397,Event,ADDED,eval-sanitize-20-r1-032-v889x.18d41aa62ae9127b,"reason=FailedScheduling count=None msg=0/6 nodes are available: 1 c_wall violated: 2 conflicting context pair(s) with node memory, 5 node(s) had untolerated taint(s). no new claims to deallocate, preemption: 0/6 nodes are available: 1 No preemption victims found for incoming pod, 5 Preemption is not helpful for scheduling."
60.041,Node,ADDED,kind-worker,taints=1
60.0411,TaskRequest,ADDED,eval-sanitize-20-r3-011,phase=Complete job=None
60.0411,TaskRequest,ADDED,eval-sanitize-20-r3-012,phase=Complete job=None
60.0412,TaskRequest,ADDED,eval-sanitize-20-r3-013,phase=Complete job=None
60.0422,Pod,ADDED,eval-sanitize-20-r3-007-rbhj9,phase=Succeeded node=kind-worker2
60.0436,Job,ADDED,eval-sanitize-20-r3-003,
60.0442,Event,ADDED,eval-sanitize-20-r1-034-48s2k.18d41aa62b1431af,"reason=FailedScheduling count=None msg=0/6 nodes are available: 1 c_wall violated: 2 conflicting context pair(s) with node memory, 5 node(s) had untolerated taint(s). no new claims to deallocate, preemption: 0/6 nodes are available: 1 No preemption victims found for incoming pod, 5 Preemption is not helpful for scheduling."
60.0445,Event,ADDED,eval-sanitize-20-r1-034-48s2k.18d41aa6635bba0d,"reason=FailedScheduling count=None msg=0/6 nodes are available: 2 c_wall violated: 2 conflicting context pair(s) with node memory, 4 node(s) had untolerated taint(s). no new claims to deallocate, preemption: 0/6 nodes are available: 2 No preemption victims found for incoming pod, 4 Preemption is not helpful for scheduling."
60.0448,Event,ADDED,eval-sanitize-20-r1-034-48s2k.18d41aa68dbd71c5,"reason=FailedScheduling count=None msg=0/6 nodes are available: 1 c_wall violated: 1 conflicting context pair(s) with node memory, 2 c_wall violated: 2 conflicting context pair(s) with node memory, 3 node(s) had untolerated taint(s). no new claims to deallocate, preemption: 0/6 nodes are available: 3 No preemption victims found for incoming pod, 3 Preemption is not helpful for scheduling."
60.0463,Pod,ADDED,eval-sanitize-20-r3-008-zmb8h,phase=Succeeded node=kind-worker5
60.0471,Job,ADDED,eval-sanitize-20-r3-004,
60.0473,Event,ADDED,eval-sanitize-20-r1-035-sj97h.18d41aa637b15ea1,"reason=FailedScheduling count=None msg=0/6 nodes are available: 1 c_wall violated: 2 conflicting context pair(s) with node memory, 5 node(s) had untolerated taint(s). no new claims to deallocate, preemption: 0/6 nodes are available: 1 No preemption victims found for incoming pod, 5 Preemption is not helpful for scheduling."
60.0476,Event,ADDED,eval-sanitize-20-r1-035-sj97h.18d41aa65348362d,"reason=FailedScheduling count=None msg=0/6 nodes are available: 2 c_wall violated: 2 conflicting context pair(s) with node memory, 4 node(s) had untolerated taint(s). no new claims to deallocate, preemption: 0/6 nodes are available: 2 No preemption victims found for incoming pod, 4 Preemption is not helpful for scheduling."
60.0489,Node,ADDED,kind-worker2,taints=1
60.049,TaskRequest,ADDED,eval-sanitize-20-r3-014,phase=Complete job=None
60.049,TaskRequest,ADDED,eval-sanitize-20-r3-015,phase=Complete job=None
60.0491,TaskRequest,ADDED,eval-sanitize-20-r3-016,phase=Complete job=None
60.0496,Event,ADDED,eval-sanitize-20-r1-036-qpnd7.18d41aa6882ce074,"reason=FailedScheduling count=None msg=0/6 nodes are available: 1 c_wall violated: 1 conflicting context pair(s) with node memory, 2 c_wall violated: 2 conflicting context pair(s) with node memory, 3 node(s) had untolerated taint(s). no new claims to deallocate, preemption: 0/6 nodes are available: 3 No preemption victims found for incoming pod, 3 Preemption is not helpful for scheduling."
60.0498,Event,ADDED,eval-sanitize-20-r1-055-bzm98.18d41aab0b863768,"reason=FailedScheduling count=None msg=0/6 nodes are available: 3 c_wall violated: 1 conflicting context pair(s) with node memory, 3 node(s) had untolerated taint(s). no new claims to deallocate, preemption: 0/6 nodes are available: 3 No preemption victims found for incoming pod, 3 Preemption is not helpful for scheduling."
60.05,Event,ADDED,eval-sanitize-20-r1-055-bzm98.18d41aab1138d594,"reason=FailedScheduling count=None msg=0/6 nodes are available: 2 c_wall violated: 1 conflicting context pair(s) with node memory, 4 node(s) had untolerated taint(s). no new claims to deallocate, preemption: 0/6 nodes are available: 2 No preemption victims found for incoming pod, 4 Preemption is not helpful for scheduling."
60.0505,Event,ADDED,eval-sanitize-20-r1-055-bzm98.18d41aab609283a9,"reason=FailedScheduling count=None msg=0/6 nodes are available: 1 c_wall violated: 1 conflicting context pair(s) with node memory, 5 node(s) had untolerated taint(s). no new claims to deallocate, preemption: 0/6 nodes are available: 1 No preemption victims found for incoming pod, 5 Preemption is not helpful for scheduling."
60.0508,Event,ADDED,eval-sanitize-20-r1-056-sqhx4.18d41aab2a9edaa1,"reason=FailedScheduling count=None msg=0/6 nodes are available: 2 c_wall violated: 1 conflicting context pair(s) with node memory, 4 node(s) had untolerated taint(s). no new claims to deallocate, preemption: 0/6 nodes are available: 2 No preemption victims found for incoming pod, 4 Preemption is not helpful for scheduling."
60.051,Event,ADDED,eval-sanitize-20-r1-056-sqhx4.18d41aab606b2c56,"reason=FailedScheduling count=None msg=0/6 nodes are available: 1 c_wall violated: 1 conflicting context pair(s) with node memory, 5 node(s) had untolerated taint(s). no new claims to deallocate, preemption: 0/6 nodes are available: 1 No preemption victims found for incoming pod, 5 Preemption is not helpful for scheduling."
60.0511,TaskRequest,ADDED,eval-sanitize-20-r3-017,phase=Complete job=None
60.0511,TaskRequest,ADDED,eval-sanitize-20-r3-018,phase=Complete job=None
60.0514,TaskRequest,ADDED,eval-sanitize-20-r3-019,phase=Complete job=None
60.0514,TaskRequest,ADDED,eval-sanitize-20-r3-020,phase=Complete job=None
60.0514,TaskRequest,ADDED,eval-sanitize-20-r3-021,phase=Complete job=None
60.0527,Pod,ADDED,eval-sanitize-20-r3-009-b98dg,phase=Succeeded node=kind-worker
60.0537,Job,ADDED,eval-sanitize-20-r3-005,
60.0546,Event,ADDED,eval-sanitize-20-r1-059-vz4jf.18d41aaf95e3cb25,"reason=FailedScheduling count=None msg=0/6 nodes are available: 1 c_wall violated: 2 conflicting context pair(s) with node memory, 5 node(s) had untolerated taint(s). no new claims to deallocate, preemption: 0/6 nodes are available: 1 No preemption victims found for incoming pod, 5 Preemption is not helpful for scheduling."
60.0549,Event,ADDED,eval-sanitize-20-r1-061-sjpk6.18d41aaf96151266,"reason=FailedScheduling count=None msg=0/6 nodes are available: 1 c_wall violated: 2 conflicting context pair(s) with node memory, 5 node(s) had untolerated taint(s). no new claims to deallocate, preemption: 0/6 nodes are available: 1 No preemption victims found for incoming pod, 5 Preemption is not helpful for scheduling."
60.0551,Event,ADDED,eval-sanitize-20-r1-062-j6dn5.18d41aaf964b0a8b,"reason=FailedScheduling count=None msg=0/6 nodes are available: 1 c_wall violated: 2 conflicting context pair(s) with node memory, 5 node(s) had untolerated taint(s). no new claims to deallocate, preemption: 0/6 nodes are available: 1 No preemption victims found for incoming pod, 5 Preemption is not helpful for scheduling."
60.0552,TaskRequest,ADDED,eval-sanitize-20-r3-022,phase=Complete job=None
60.0553,TaskRequest,ADDED,eval-sanitize-20-r3-023,phase=Complete job=None
60.057,Pod,ADDED,eval-sanitize-20-r3-010-85ngc,phase=Succeeded node=kind-worker4
60.0577,Job,ADDED,eval-sanitize-20-r3-006,
60.0589,Node,ADDED,kind-worker3,taints=1
60.0596,Event,ADDED,eval-sanitize-20-r1-069-dxq4t.18d41aaf90cc68df,"reason=FailedScheduling count=None msg=0/6 nodes are available: 1 c_wall violated: 2 conflicting context pair(s) with node memory, 5 node(s) had untolerated taint(s). no new claims to deallocate, preemption: 0/6 nodes are available: 1 No preemption victims found for incoming pod, 5 Preemption is not helpful for scheduling."
60.0598,Event,ADDED,eval-sanitize-20-r1-070-c8j2t.18d41aaf9104acd4,"reason=FailedScheduling count=None msg=0/6 nodes are available: 1 c_wall violated: 2 conflicting context pair(s) with node memory, 5 node(s) had untolerated taint(s). no new claims to deallocate, preemption: 0/6 nodes are available: 1 No preemption victims found for incoming pod, 5 Preemption is not helpful for scheduling."
60.0601,Event,ADDED,eval-sanitize-20-r1-071-b576n.18d41aaf91415639,"reason=FailedScheduling count=None msg=0/6 nodes are available: 1 c_wall violated: 2 conflicting context pair(s) with node memory, 5 node(s) had untolerated taint(s). no new claims to deallocate, preemption: 0/6 nodes are available: 1 No preemption victims found for incoming pod, 5 Preemption is not helpful for scheduling."
60.0602,TaskRequest,ADDED,eval-sanitize-20-r3-024,phase=Complete job=None
60.0602,TaskRequest,ADDED,eval-sanitize-20-r3-025,phase=Complete job=None
60.0602,TaskRequest,ADDED,eval-sanitize-20-r3-026,phase=Complete job=None
60.0615,Pod,ADDED,eval-sanitize-20-r3-011-7pmrj,phase=Succeeded node=kind-worker
60.0625,Job,ADDED,eval-sanitize-20-r3-007,
60.0643,Pod,ADDED,eval-sanitize-20-r3-012-cqb84,phase=Succeeded node=kind-worker4
60.0645,TaskRequest,ADDED,eval-sanitize-20-r3-027,phase=Complete job=None
60.0645,TaskRequest,ADDED,eval-sanitize-20-r3-028,phase=Complete job=None
60.0646,TaskRequest,ADDED,eval-sanitize-20-r3-029,phase=Complete job=None
60.0654,Job,ADDED,eval-sanitize-20-r3-008,
60.0656,Event,ADDED,eval-sanitize-20-r1-072-q7qwt.18d41aaf93bbadfc,"reason=FailedScheduling count=None msg=0/6 nodes are available: 1 c_wall violated: 2 conflicting context pair(s) with node memory, 5 node(s) had untolerated taint(s). no new claims to deallocate, preemption: 0/6 nodes are available: 1 No preemption victims found for incoming pod, 5 Preemption is not helpful for scheduling."
60.0658,Event,ADDED,eval-sanitize-20-r1-074-4hsdp.18d41aaf95a16ace,"reason=FailedScheduling count=None msg=0/6 nodes are available: 1 c_wall violated: 2 conflicting context pair(s) with node memory, 5 node(s) had untolerated taint(s). no new claims to deallocate, preemption: 0/6 nodes are available: 1 No preemption victims found for incoming pod, 5 Preemption is not helpful for scheduling."
60.0674,Node,ADDED,kind-worker4,taints=0
60.0686,Pod,ADDED,eval-sanitize-20-r3-013-98nmn,phase=Succeeded node=kind-worker
60.0687,TaskRequest,ADDED,eval-sanitize-20-r3-030,phase=Complete job=None
60.0687,TaskRequest,ADDED,eval-sanitize-20-r3-031,phase=Complete job=None
60.0692,TaskRequest,ADDED,eval-sanitize-20-r3-032,phase=Complete job=None
60.0692,TaskRequest,ADDED,eval-sanitize-20-r3-033,phase=Complete job=None
60.0692,TaskRequest,ADDED,eval-sanitize-20-r3-034,phase=Complete job=None
60.0699,Job,ADDED,eval-sanitize-20-r3-009,
60.0702,Event,ADDED,eval-sanitize-20-r1-096-52wjb.18d41ab48f9a3bfd,"reason=FailedScheduling count=None msg=0/6 nodes are available: 1 c_wall violated: 1 conflicting context pair(s) with node memory, 1 c_wall violated: 2 conflicting context pair(s) with node memory, 4 node(s) had untolerated taint(s). no new claims to deallocate, preemption: 0/6 nodes are available: 2 No preemption victims found for incoming pod, 4 Preemption is not helpful for scheduling."
60.0704,Event,ADDED,eval-sanitize-20-r1-096-52wjb.18d41ab4bda99bd1,"reason=FailedScheduling count=None msg=0/6 nodes are available: 1 c_wall violated: 2 conflicting context pair(s) with node memory, 5 node(s) had untolerated taint(s). no new claims to deallocate, preemption: 0/6 nodes are available: 1 No preemption victims found for incoming pod, 5 Preemption is not helpful for scheduling."
60.0706,Event,ADDED,eval-sanitize-20-r1-097-2bqqh.18d41ab4c56ac95c,"reason=FailedScheduling count=None msg=0/6 nodes are available: 1 c_wall violated: 2 conflicting context pair(s) with node memory, 5 node(s) had untolerated taint(s). no new claims to deallocate, preemption: 0/6 nodes are available: 1 No preemption victims found for incoming pod, 5 Preemption is not helpful for scheduling."
60.0708,Event,ADDED,eval-sanitize-20-r1-098-k4zs9.18d41ab8fbf63205,"reason=FailedScheduling count=None msg=0/6 nodes are available: 1 c_wall violated: 1 conflicting context pair(s) with node memory, 5 node(s) had untolerated taint(s). no new claims to deallocate, preemption: 0/6 nodes are available: 1 No preemption victims found for incoming pod, 5 Preemption is not helpful for scheduling."
60.071,Event,ADDED,eval-sanitize-20-r1-099-2ss89.18d41ab8fc2d610c,"reason=FailedScheduling count=None msg=0/6 nodes are available: 1 c_wall violated: 1 conflicting context pair(s) with node memory, 5 node(s) had untolerated taint(s). no new claims to deallocate, preemption: 0/6 nodes are available: 1 No preemption victims found for incoming pod, 5 Preemption is not helpful for scheduling."
60.0711,Event,ADDED,eval-sanitize-20-r3-000-2x82f.18d41b278a0eda09,reason=Scheduled count=None msg=Successfully assigned compute/eval-sanitize-20-r3-000-2x82f to kind-worker
60.0723,Node,ADDED,kind-worker5,taints=1
60.0724,TaskRequest,ADDED,eval-sanitize-20-r3-035,phase=Complete job=None
60.0724,TaskRequest,ADDED,eval-sanitize-20-r3-036,phase=Complete job=None
60.0731,Job,ADDED,eval-sanitize-20-r3-010,
60.0738,Event,ADDED,eval-sanitize-20-r3-000-2x82f.18d41b27a996433d,"reason=Pulled count=1 msg=Container image ""busybox:musl"" already present on machine"
60.074,Event,ADDED,eval-sanitize-20-r3-000-2x82f.18d41b27aaa3e317,reason=Created count=1 msg=Created container: task
60.0742,Event,ADDED,eval-sanitize-20-r3-000-2x82f.18d41b27b30fe368,reason=Started count=1 msg=Started container task
60.0743,Event,ADDED,eval-sanitize-20-r3-000.18d41b278939adfb,reason=SuccessfulCreate count=1 msg=Created pod: eval-sanitize-20-r3-000-2x82f
60.0755,Pod,ADDED,eval-sanitize-20-r3-014-7fzzg,phase=Succeeded node=kind-worker2
60.0756,TaskRequest,ADDED,eval-sanitize-20-r3-037,phase=Complete job=None
60.0756,TaskRequest,ADDED,eval-sanitize-20-r3-038,phase=Complete job=None
60.0757,TaskRequest,ADDED,eval-sanitize-20-r3-039,phase=Complete job=None
60.0763,Job,ADDED,eval-sanitize-20-r3-011,
60.0766,Event,ADDED,eval-sanitize-20-r3-000.18d41b2aebef39c5,reason=Completed count=1 msg=Job completed
60.0768,Event,ADDED,eval-sanitize-20-r3-001-zqtnq.18d41b27c43caf51,reason=Scheduled count=None msg=Successfully assigned compute/eval-sanitize-20-r3-001-zqtnq to kind-worker5
60.077,Event,ADDED,eval-sanitize-20-r3-001-zqtnq.18d41b27e3090476,"reason=Pulled count=1 msg=Container image ""busybox:musl"" already present on machine"
60.0772,Event,ADDED,eval-sanitize-20-r3-001-zqtnq.18d41b27e43a4e20,reason=Created count=1 msg=Created container: task
60.0779,Job,ADDED,eval-sanitize-20-r3-012,
60.078,TaskRequest,ADDED,eval-sanitize-20-r3-040,phase=Complete job=None
60.078,TaskRequest,ADDED,eval-sanitize-20-r3-041,phase=Complete job=None
60.078,TaskRequest,ADDED,eval-sanitize-20-r3-042,phase=Complete job=None
60.0796,Job,ADDED,eval-sanitize-20-r3-013,
60.0796,TaskRequest,ADDED,eval-sanitize-20-r3-043,phase=Complete job=None
60.0797,TaskRequest,ADDED,eval-sanitize-20-r3-044,phase=Complete job=None
60.0799,Event,ADDED,eval-sanitize-20-r3-001-zqtnq.18d41b27ecb4fb17,reason=Started count=1 msg=Started container task
60.0801,Event,ADDED,eval-sanitize-20-r3-001.18d41b27c32573bd,reason=SuccessfulCreate count=1 msg=Created pod: eval-sanitize-20-r3-001-zqtnq
60.0803,Event,ADDED,eval-sanitize-20-r3-001.18d41b2b03caf3b2,reason=Completed count=1 msg=Job completed
60.0815,Pod,ADDED,eval-sanitize-20-r3-015-7nhgg,phase=Succeeded node=kind-worker3
60.0825,Job,ADDED,eval-sanitize-20-r3-014,
60.0826,TaskRequest,ADDED,eval-sanitize-20-r3-045,phase=Scheduled job=None
60.0826,TaskRequest,ADDED,eval-sanitize-20-r3-046,phase=Scheduled job=None
60.0826,TaskRequest,ADDED,eval-sanitize-20-r3-047,phase=Scheduled job=None
60.0829,Event,ADDED,eval-sanitize-20-r3-002-6p6k5.18d41b27fc26080d,reason=Scheduled count=None msg=Successfully assigned compute/eval-sanitize-20-r3-002-6p6k5 to kind-worker3
60.0831,Event,ADDED,eval-sanitize-20-r3-002-6p6k5.18d41b281941afaf,"reason=Pulled count=1 msg=Container image ""busybox:musl"" already present on machine"
60.0833,Event,ADDED,eval-sanitize-20-r3-002-6p6k5.18d41b281a6b48f4,reason=Created count=1 msg=Created container: task
60.0835,Event,ADDED,eval-sanitize-20-r3-002-6p6k5.18d41b2822e24bd0,reason=Started count=1 msg=Started container task
60.0846,Pod,ADDED,eval-sanitize-20-r3-016-wg4b2,phase=Succeeded node=kind-worker4
60.0851,TaskRequest,ADDED,eval-sanitize-20-r3-048,phase=Scheduled job=None
60.0852,TaskRequest,ADDED,eval-sanitize-20-r3-049,phase=Scheduled job=None
60.0852,TaskRequest,ADDED,eval-sanitize-20-r3-050,phase=Scheduled job=None
60.0856,Event,ADDED,eval-sanitize-20-r3-002.18d41b27fb187275,reason=SuccessfulCreate count=1 msg=Created pod: eval-sanitize-20-r3-002-6p6k5
60.0858,Event,ADDED,eval-sanitize-20-r3-002.18d41b2b5934b058,reason=Completed count=1 msg=Job completed
60.086,Event,ADDED,eval-sanitize-20-r3-003-wh2ts.18d41b2838d8db15,reason=Scheduled count=None msg=Successfully assigned compute/eval-sanitize-20-r3-003-wh2ts to kind-worker3
60.0862,Event,ADDED,eval-sanitize-20-r3-003-wh2ts.18d41b2855a42442,"reason=Pulled count=1 msg=Container image ""busybox:musl"" already present on machine"
60.087,Job,ADDED,eval-sanitize-20-r3-015,
60.0881,Pod,ADDED,eval-sanitize-20-r3-017-zwmxm,phase=Succeeded node=kind-worker
60.0881,TaskRequest,ADDED,eval-sanitize-20-r3-051,phase=Scheduled job=None
60.0882,TaskRequest,ADDED,eval-sanitize-20-r3-052,phase=Scheduled job=None
60.0883,TaskRequest,ADDED,eval-sanitize-20-r3-053,phase=Scheduled job=None
60.0883,TaskRequest,ADDED,eval-sanitize-20-r3-054,phase=Scheduled job=None
60.0883,TaskRequest,ADDED,eval-sanitize-20-r3-055,phase=Scheduled job=None
60.0884,TaskRequest,ADDED,eval-sanitize-20-r3-056,phase=Scheduled job=None
60.0884,TaskRequest,ADDED,eval-sanitize-20-r3-057,phase=Scheduled job=None
60.0884,TaskRequest,ADDED,eval-sanitize-20-r3-058,phase=Scheduled job=None
60.0893,Job,ADDED,eval-sanitize-20-r3-016,
60.0904,Pod,ADDED,eval-sanitize-20-r3-018-mnx7g,phase=Succeeded node=kind-worker2
60.0906,Event,ADDED,eval-sanitize-20-r3-003-wh2ts.18d41b2856ccfee5,reason=Created count=1 msg=Created container: task
60.0908,Event,ADDED,eval-sanitize-20-r3-003-wh2ts.18d41b285a52daaf,reason=Started count=1 msg=Started container task
60.091,Event,ADDED,eval-sanitize-20-r3-003.18d41b28378ebe87,reason=SuccessfulCreate count=1 msg=Created pod: eval-sanitize-20-r3-003-wh2ts
60.0912,Event,ADDED,eval-sanitize-20-r3-003.18d41b2b94a99696,reason=Completed count=1 msg=Job completed
60.0914,Event,ADDED,eval-sanitize-20-r3-004-2jl8f.18d41b28735f4aad,reason=Scheduled count=None msg=Successfully assigned compute/eval-sanitize-20-r3-004-2jl8f to kind-worker2
60.0916,Event,ADDED,eval-sanitize-20-r3-004-2jl8f.18d41b289309d108,"reason=Pulled count=1 msg=Container image ""busybox:musl"" already present on machine"
60.092,Event,ADDED,eval-sanitize-20-r3-004-2jl8f.18d41b28942b58ad,reason=Created count=1 msg=Created container: task
60.0921,TaskRequest,ADDED,eval-sanitize-20-r3-059,phase=Scheduled job=None
60.0921,TaskRequest,ADDED,eval-sanitize-20-r3-060,phase=Pending job=None
60.0924,TaskRequest,MODIFIED,eval-sanitize-20-r3-060,phase=Scheduled job=None
60.0925,TaskRequest,MODIFIED,eval-sanitize-20-r3-060,phase=Scheduled job=None
60.0928,Event,ADDED,eval-sanitize-20-r3-004-2jl8f.18d41b289b75781a,reason=Started count=1 msg=Started container task
60.093,Event,ADDED,eval-sanitize-20-r3-004.18d41b287226be70,reason=SuccessfulCreate count=1 msg=Created pod: eval-sanitize-20-r3-004-2jl8f
60.0932,Event,ADDED,eval-sanitize-20-r3-004.18d41b2bae9853f9,reason=Completed count=1 msg=Job completed
60.0934,Event,ADDED,eval-sanitize-20-r3-005-6gx5c.18d41b28aeb705db,reason=Scheduled count=None msg=Successfully assigned compute/eval-sanitize-20-r3-005-6gx5c to kind-worker3
60.0942,Job,ADDED,eval-sanitize-20-r3-017,
60.0953,Job,ADDED,eval-sanitize-20-r3-018,
60.0965,Pod,ADDED,eval-sanitize-20-r3-019-jntlw,phase=Succeeded node=kind-worker4
60.0967,Event,ADDED,eval-sanitize-20-r3-005-6gx5c.18d41b28c7ac3fcb,"reason=Pulled count=1 msg=Container image ""busybox:musl"" already present on machine"
60.0969,Event,ADDED,eval-sanitize-20-r3-005-6gx5c.18d41b28c8cac173,reason=Created count=1 msg=Created container: task
60.0971,Event,ADDED,eval-sanitize-20-r3-005-6gx5c.18d41b28d122ba92,reason=Started count=1 msg=Started container task
60.0973,Event,ADDED,eval-sanitize-20-r3-005.18d41b28ad53a49e,reason=SuccessfulCreate count=1 msg=Created pod: eval-sanitize-20-r3-005-6gx5c
60.0976,Event,ADDED,eval-sanitize-20-r3-005.18d41b2c0bdc769e,reason=Completed count=1 msg=Job completed
60.0978,Event,ADDED,eval-sanitize-20-r3-006-wc75b.18d41b28eba9c443,reason=Scheduled count=None msg=Successfully assigned compute/eval-sanitize-20-r3-006-wc75b to kind-worker4
60.098,Event,ADDED,eval-sanitize-20-r3-006-wc75b.18d41b290a424bf7,"reason=Pulled count=1 msg=Container image ""busybox:musl"" already present on machine"
60.0996,Pod,ADDED,eval-sanitize-20-r3-020-z7jzd,phase=Succeeded node=kind-worker
60.1009,Job,ADDED,eval-sanitize-20-r3-019,
60.1021,Pod,ADDED,eval-sanitize-20-r3-021-xmp2g,phase=Succeeded node=kind-worker3
60.1024,Event,ADDED,eval-sanitize-20-r3-006-wc75b.18d41b290b4d4255,reason=Created count=1 msg=Created container: task
60.1026,Event,ADDED,eval-sanitize-20-r3-006-wc75b.18d41b291399ef66,reason=Started count=1 msg=Started container task
60.1028,Event,ADDED,eval-sanitize-20-r3-006.18d41b28ea513325,reason=SuccessfulCreate count=1 msg=Created pod: eval-sanitize-20-r3-006-wc75b
60.103,Event,ADDED,eval-sanitize-20-r3-006.18d41b2c2544367c,reason=Completed count=1 msg=Job completed
60.1038,Job,ADDED,eval-sanitize-20-r3-020,
60.1053,Pod,ADDED,eval-sanitize-20-r3-022-22zpt,phase=Succeeded node=kind-worker
60.1055,Event,ADDED,eval-sanitize-20-r3-007-rbhj9.18d41b293454b1cf,reason=Scheduled count=None msg=Successfully assigned compute/eval-sanitize-20-r3-007-rbhj9 to kind-worker2
60.1058,Event,ADDED,eval-sanitize-20-r3-007-rbhj9.18d41b29547f6e75,"reason=Pulled count=1 msg=Container image ""busybox:musl"" already present on machine"
60.106,Event,ADDED,eval-sanitize-20-r3-007-rbhj9.18d41b2955a13bf7,reason=Created count=1 msg=Created container: task
60.1069,Job,ADDED,eval-sanitize-20-r3-021,
60.1082,Pod,ADDED,eval-sanitize-20-r3-023-l94v5,phase=Succeeded node=kind-worker2
60.1085,Event,ADDED,eval-sanitize-20-r3-007-rbhj9.18d41b295a52ebee,reason=Started count=1 msg=Started container task
60.1087,Event,ADDED,eval-sanitize-20-r3-007.18d41b292947651c,reason=SuccessfulCreate count=1 msg=Created pod: eval-sanitize-20-r3-007-rbhj9
60.1089,Event,ADDED,eval-sanitize-20-r3-007.18d41b2c9d6227ae,reason=Completed count=1 msg=Job completed
60.1091,Event,ADDED,eval-sanitize-20-r3-008-zmb8h.18d41b2968226b95,reason=Scheduled count=None msg=Successfully assigned compute/eval-sanitize-20-r3-008-zmb8h to kind-worker5
60.1099,Job,ADDED,eval-sanitize-20-r3-022,
60.1112,Pod,ADDED,eval-sanitize-20-r3-024-7v9kq,phase=Succeeded node=kind-worker
60.1115,Event,ADDED,eval-sanitize-20-r3-008-zmb8h.18d41b2988ee2e45,"reason=Pulled count=1 msg=Container image ""busybox:musl"" already present on machine"
60.1117,Event,ADDED,eval-sanitize-20-r3-008-zmb8h.18d41b298a1b690c,reason=Created count=1 msg=Created container: task
60.1119,Event,ADDED,eval-sanitize-20-r3-008-zmb8h.18d41b2994851f33,reason=Started count=1 msg=Started container task
60.1121,Event,ADDED,eval-sanitize-20-r3-008.18d41b29675e2066,reason=SuccessfulCreate count=1 msg=Created pod: eval-sanitize-20-r3-008-zmb8h
60.1123,TaskRequest,MODIFIED,eval-sanitize-20-r3-045,phase=Complete job=None
60.1134,Job,ADDED,eval-sanitize-20-r3-023,
60.1138,Event,ADDED,eval-sanitize-20-r3-008.18d41b2ca5f58365,reason=Completed count=1 msg=Job completed
60.114,Event,ADDED,eval-sanitize-20-r3-009-b98dg.18d41b299c68fd9f,"reason=FailedScheduling count=None msg=0/6 nodes are available: 6 node(s) had untolerated taint(s). no new claims to deallocate, preemption: 0/6 nodes are available: 6 Preemption is not helpful for scheduling."
60.1142,Event,ADDED,eval-sanitize-20-r3-009-b98dg.18d41b2de7a54ad6,reason=Scheduled count=None msg=Successfully assigned compute/eval-sanitize-20-r3-009-b98dg to kind-worker
60.1154,Pod,ADDED,eval-sanitize-20-r3-025-928bl,phase=Succeeded node=kind-worker3
60.1165,Job,ADDED,eval-sanitize-20-r3-024,
60.1168,Event,ADDED,eval-sanitize-20-r3-009-b98dg.18d41b2e0160e32b,"reason=Pulled count=1 msg=Container image ""busybox:musl"" already present on machine"
60.1171,Event,ADDED,eval-sanitize-20-r3-009-b98dg.18d41b2e032dcd78,reason=Created count=1 msg=Created container: task
60.1172,Event,ADDED,eval-sanitize-20-r3-009-b98dg.18d41b2e069b2e8e,reason=Started count=1 msg=Started container task
60.1174,Event,ADDED,eval-sanitize-20-r3-009.18d41b299c5d6f53,reason=SuccessfulCreate count=1 msg=Created pod: eval-sanitize-20-r3-009-b98dg
60.1204,Pod,ADDED,eval-sanitize-20-r3-026-4255x,phase=Succeeded node=kind-worker4
60.1207,Event,ADDED,eval-sanitize-20-r3-009.18d41b3100633b90,reason=Completed count=1 msg=Job completed
60.1209,Event,ADDED,eval-sanitize-20-r3-010-85ngc.18d41b29d76a05b2,"reason=FailedScheduling count=None msg=0/6 nodes are available: 6 node(s) had untolerated taint(s). no new claims to deallocate, preemption: 0/6 nodes are available: 6 Preemption is not helpful for scheduling."
60.1211,Event,ADDED,eval-sanitize-20-r3-010-85ngc.18d41b2de7db4a7e,"reason=FailedScheduling count=None msg=0/6 nodes are available: 1 c_wall violated: 1 conflicting context pair(s) with node memory, 5 node(s) had untolerated taint(s). no new claims to deallocate, preemption: 0/6 nodes are available: 1 No preemption victims found for incoming pod, 5 Preemption is not helpful for scheduling."
60.1215,Event,ADDED,eval-sanitize-20-r3-010-85ngc.18d41b2df9aff3b3,"reason=FailedScheduling count=None msg=0/6 nodes are available: 1 c_wall violated: 3 conflicting context pair(s) with node memory, 5 node(s) had untolerated taint(s). no new claims to deallocate, preemption: 0/6 nodes are available: 1 No preemption victims found for incoming pod, 5 Preemption is not helpful for scheduling."
60.1217,Event,ADDED,eval-sanitize-20-r3-010-85ngc.18d41b2e0bad37d7,reason=Scheduled count=None msg=Successfully assigned compute/eval-sanitize-20-r3-010-85ngc to kind-worker4
60.1219,Event,ADDED,eval-sanitize-20-r3-010-85ngc.18d41b2e28346732,"reason=Pulled count=1 msg=Container image ""busybox:musl"" already present on machine"
60.1221,Event,ADDED,eval-sanitize-20-r3-010-85ngc.18d41b2e2a361843,reason=Created count=1 msg=Created container: task
60.1232,Job,ADDED,eval-sanitize-20-r3-025,
60.1246,Pod,ADDED,eval-sanitize-20-r3-027-p6tjp,phase=Succeeded node=kind-worker3
60.1249,Event,ADDED,eval-sanitize-20-r3-010-85ngc.18d41b2e2e4ab9c7,reason=Started count=1 msg=Started container task
60.1251,Event,ADDED,eval-sanitize-20-r3-010.18d41b29d75fedea,reason=SuccessfulCreate count=1 msg=Created pod: eval-sanitize-20-r3-010-85ngc
60.1254,Event,ADDED,eval-sanitize-20-r3-010.18d41b323b182bde,reason=Completed count=1 msg=Job completed
60.1264,Job,ADDED,eval-sanitize-20-r3-026,
60.1275,Pod,ADDED,eval-sanitize-20-r3-028-cc6vw,phase=Succeeded node=kind-worker
60.1278,Event,ADDED,eval-sanitize-20-r3-011-7pmrj.18d41b2a13566a3c,"reason=FailedScheduling count=None msg=0/6 nodes are available: 6 node(s) had untolerated taint(s). no new claims to deallocate, preemption: 0/6 nodes are available: 6 Preemption is not helpful for scheduling."
60.1279,Event,ADDED,eval-sanitize-20-r3-011-7pmrj.18d41b2de8bcbf26,reason=Scheduled count=None msg=Successfully assigned compute/eval-sanitize-20-r3-011-7pmrj to kind-worker
60.1282,Event,ADDED,eval-sanitize-20-r3-011-7pmrj.18d41b2e02178802,"reason=Pulled count=1 msg=Container image ""busybox:musl"" already present on machine"
60.1284,Event,ADDED,eval-sanitize-20-r3-011-7pmrj.18d41b2e03d00615,reason=Created count=1 msg=Created container: task
60.1287,Event,ADDED,eval-sanitize-20-r3-011-7pmrj.18d41b2e069d8107,reason=Started count=1 msg=Started container task
60.1289,Event,ADDED,eval-sanitize-20-r3-011.18d41b2a134b4949,reason=SuccessfulCreate count=1 msg=Created pod: eval-sanitize-20-r3-011-7pmrj
60.129,Event,ADDED,eval-sanitize-20-r3-011.18d41b31ffa70178,reason=Completed count=1 msg=Job completed
60.1293,Event,ADDED,eval-sanitize-20-r3-012-cqb84.18d41b2a4ef56607,"reason=FailedScheduling count=None msg=0/6 nodes are available: 6 node(s) had untolerated taint(s). no new claims to deallocate, preemption: 0/6 nodes are available: 6 Preemption is not helpful for scheduling."
60.1301,Job,ADDED,eval-sanitize-20-r3-027,
60.1309,Job,ADDED,eval-sanitize-20-r3-028,
60.1312,Event,ADDED,eval-sanitize-20-r3-012-cqb84.18d41b2de899a569,"reason=FailedScheduling count=None msg=0/6 nodes are available: 1 c_wall violated: 1 conflicting context pair(s) with node memory, 5 node(s) had untolerated taint(s). no new claims to deallocate, preemption: 0/6 nodes are available: 1 No preemption victims found for incoming pod, 5 Preemption is not helpful for scheduling."
60.1314,Event,ADDED,eval-sanitize-20-r3-012-cqb84.18d41b2dfa35c78f,"reason=FailedScheduling count=None msg=0/6 nodes are available: 1 c_wall violated: 2 conflicting context pair(s) with node memory, 5 node(s) had untolerated taint(s). no new claims to deallocate, preemption: 0/6 nodes are available: 1 No preemption victims found for incoming pod, 5 Preemption is not helpful for scheduling."
60.1315,Event,ADDED,eval-sanitize-20-r3-012-cqb84.18d41b2e0de23ae7,reason=Scheduled count=None msg=Successfully assigned compute/eval-sanitize-20-r3-012-cqb84 to kind-worker4
60.1326,Pod,ADDED,eval-sanitize-20-r3-029-mpn7t,phase=Succeeded node=kind-worker3
60.1337,Pod,ADDED,eval-sanitize-20-r3-030-tqczp,phase=Succeeded node=kind-worker5
60.134,Event,ADDED,eval-sanitize-20-r3-012-cqb84.18d41b2e28bf319c,"reason=Pulled count=1 msg=Container image ""busybox:musl"" already present on machine"
60.1342,Event,ADDED,eval-sanitize-20-r3-012-cqb84.18d41b2e2addc084,reason=Created count=1 msg=Created container: task
60.1344,Event,ADDED,eval-sanitize-20-r3-012-cqb84.18d41b2e2ebeb52d,reason=Started count=1 msg=Started container task
60.1352,Job,ADDED,eval-sanitize-20-r3-029,
60.1359,Job,ADDED,eval-sanitize-20-r3-030,
60.1371,Pod,ADDED,eval-sanitize-20-r3-031-92b5r,phase=Succeeded node=kind-worker3
60.1374,Event,ADDED,eval-sanitize-20-r3-012.18d41b2a4ee6e6fb,reason=SuccessfulCreate count=1 msg=Created pod: eval-sanitize-20-r3-012-cqb84
60.1376,Event,ADDED,eval-sanitize-20-r3-012.18d41b3264ba5ea3,reason=Completed count=1 msg=Job completed
60.1378,Event,ADDED,eval-sanitize-20-r3-013-98nmn.18d41b2a8a817a8c,"reason=FailedScheduling count=None msg=0/6 nodes are available: 6 node(s) had untolerated taint(s). no new claims to deallocate, preemption: 0/6 nodes are available: 6 Preemption is not helpful for scheduling."
60.138,Event,ADDED,eval-sanitize-20-r3-013-98nmn.18d41b2deb652ba2,reason=Scheduled count=None msg=Successfully assigned compute/eval-sanitize-20-r3-013-98nmn to kind-worker
60.1382,Event,ADDED,eval-sanitize-20-r3-013-98nmn.18d41b2e062874de,"reason=Pulled count=1 msg=Container image ""busybox:musl"" already present on machine"
60.1384,Event,ADDED,eval-sanitize-20-r3-013-98nmn.18d41b2e08634189,reason=Created count=1 msg=Created container: task
60.1386,Event,ADDED,eval-sanitize-20-r3-013-98nmn.18d41b2e0b49b86a,reason=Started count=1 msg=Started container task
60.1388,Event,ADDED,eval-sanitize-20-r3-013.18d41b2a8a7afebc,reason=SuccessfulCreate count=1 msg=Created pod: eval-sanitize-20-r3-013-98nmn
60.1399,Pod,ADDED,eval-sanitize-20-r3-032-cr99x,phase=Succeeded node=kind-worker5
60.1407,Job,ADDED,eval-sanitize-20-r3-031,
60.141,Event,ADDED,eval-sanitize-20-r3-013.18d41b321b2546cf,reason=Completed count=1 msg=Job completed
60.1413,Event,ADDED,eval-sanitize-20-r3-014-7fzzg.18d41b2ac5fc793c,"reason=FailedScheduling count=None msg=0/6 nodes are available: 6 node(s) had untolerated taint(s). no new claims to deallocate, preemption: 0/6 nodes are available: 6 Preemption is not helpful for scheduling."
60.1414,Event,ADDED,eval-sanitize-20-r3-014-7fzzg.18d41b2deb314304,"reason=FailedScheduling count=None msg=0/6 nodes are available: 1 c_wall violated: 2 conflicting context pair(s) with node memory, 5 node(s) had untolerated taint(s). no new claims to deallocate, preemption: 0/6 nodes are available: 1 No preemption victims found for incoming pod, 5 Preemption is not helpful for scheduling."
60.1417,Event,ADDED,eval-sanitize-20-r3-014-7fzzg.18d41b2dfad2abba,"reason=FailedScheduling count=None msg=0/6 nodes are available: 1 c_wall violated: 2 conflicting context pair(s) with node memory, 5 node(s) had untolerated taint(s). no new claims to deallocate, preemption: 0/6 nodes are available: 1 No preemption victims found for incoming pod, 5 Preemption is not helpful for scheduling."
60.1419,Event,ADDED,eval-sanitize-20-r3-014-7fzzg.18d41b2e252e52e1,"reason=FailedScheduling count=None msg=0/6 nodes are available: 1 c_wall violated: 2 conflicting context pair(s) with node memory, 2 c_wall violated: 1 conflicting context pair(s) with node memory, 3 node(s) had untolerated taint(s). no new claims to deallocate, preemption: 0/6 nodes are available: 3 No preemption victims found for incoming pod, 3 Preemption is not helpful for scheduling."
60.1421,Event,ADDED,eval-sanitize-20-r3-014-7fzzg.18d41b2e3cfe0636,"reason=FailedScheduling count=None msg=0/6 nodes are available: 1 c_wall violated: 2 conflicting context pair(s) with node memory, 2 c_wall violated: 1 conflicting context pair(s) with node memory, 3 node(s) had untolerated taint(s). no new claims to deallocate, preemption: 0/6 nodes are available: 3 No preemption victims found for incoming pod, 3 Preemption is not helpful for scheduling."
60.1432,Pod,ADDED,eval-sanitize-20-r3-033-mpfrc,phase=Succeeded node=kind-worker2
60.1439,Job,ADDED,eval-sanitize-20-r3-032,
60.1442,Event,ADDED,eval-sanitize-20-r3-014-7fzzg.18d41b2e4f17a2ef,reason=Scheduled count=None msg=Successfully assigned compute/eval-sanitize-20-r3-014-7fzzg to kind-worker2
60.1444,Event,ADDED,eval-sanitize-20-r3-014-7fzzg.18d41b2e675f5609,"reason=Pulled count=1 msg=Container image ""busybox:musl"" already present on machine"
60.1446,Event,ADDED,eval-sanitize-20-r3-014-7fzzg.18d41b2e68e56314,reason=Created count=1 msg=Created container: task
60.1448,Event,ADDED,eval-sanitize-20-r3-014-7fzzg.18d41b2e6d76877f,reason=Started count=1 msg=Started container task
60.1454,Event,ADDED,eval-sanitize-20-r3-014.18d41b2ac5f02032,reason=SuccessfulCreate count=1 msg=Created pod: eval-sanitize-20-r3-014-7fzzg
60.1457,Event,ADDED,eval-sanitize-20-r3-014.18d41b32b84d0947,reason=Completed count=1 msg=Job completed
60.1459,Event,ADDED,eval-sanitize-20-r3-015-7nhgg.18d41b2b01c5e6d1,"reason=FailedScheduling count=None msg=0/6 nodes are available: 6 node(s) had untolerated taint(s). no new claims to deallocate, preemption: 0/6 nodes are available: 6 Preemption is not helpful for scheduling."
60.1474,Pod,ADDED,eval-sanitize-20-r3-034-bjfdr,phase=Succeeded node=kind-worker5
60.1485,Job,ADDED,eval-sanitize-20-r3-033,
60.1488,Event,ADDED,eval-sanitize-20-r3-015-7nhgg.18d41b2dedc9c788,"reason=FailedScheduling count=None msg=0/6 nodes are available: 1 c_wall violated: 2 conflicting context pair(s) with node memory, 5 node(s) had untolerated taint(s). no new claims to deallocate, preemption: 0/6 nodes are available: 1 No preemption victims found for incoming pod, 5 Preemption is not helpful for scheduling."
60.1491,Event,ADDED,eval-sanitize-20-r3-015-7nhgg.18d41b2dfb086cb8,"reason=FailedScheduling count=None msg=0/6 nodes are available: 1 c_wall violated: 2 conflicting context pair(s) with node memory, 5 node(s) had untolerated taint(s). no new claims to deallocate, preemption: 0/6 nodes are available: 1 No preemption victims found for incoming pod, 5 Preemption is not helpful for scheduling."
60.1493,Event,ADDED,eval-sanitize-20-r3-015-7nhgg.18d41b2e2b472875,reason=Scheduled count=None msg=Successfully assigned compute/eval-sanitize-20-r3-015-7nhgg to kind-worker3
60.1502,Job,ADDED,eval-sanitize-20-r3-034,
60.1507,Event,ADDED,eval-sanitize-20-r3-015-7nhgg.18d41b2e43a1e0a1,"reason=Pulled count=1 msg=Container image ""busybox:musl"" already present on machine"
60.1511,Event,ADDED,eval-sanitize-20-r3-015-7nhgg.18d41b2e44bdfb91,reason=Created count=1 msg=Created container: task
60.1515,Event,ADDED,eval-sanitize-20-r3-015-7nhgg.18d41b2e48d6892b,reason=Started count=1 msg=Started container task
60.1517,Event,ADDED,eval-sanitize-20-r3-015.18d41b2b01bab8ad,reason=SuccessfulCreate count=1 msg=Created pod: eval-sanitize-20-r3-015-7nhgg
60.1528,Pod,ADDED,eval-sanitize-20-r3-035-p99z2,phase=Succeeded node=kind-worker3
60.1531,Event,ADDED,eval-sanitize-20-r3-015.18d41b32863c3b4b,reason=Completed count=1 msg=Job completed
60.1533,Event,ADDED,eval-sanitize-20-r3-016-wg4b2.18d41b2b3d065eec,"reason=FailedScheduling count=None msg=0/6 nodes are available: 6 node(s) had untolerated taint(s). no new claims to deallocate, preemption: 0/6 nodes are available: 6 Preemption is not helpful for scheduling."
60.1534,Event,ADDED,eval-sanitize-20-r3-016-wg4b2.18d41b2dee86b4b5,"reason=FailedScheduling count=None msg=0/6 nodes are available: 1 c_wall violated: 2 conflicting context pair(s) with node memory, 5 node(s) had untolerated taint(s). no new claims to deallocate, preemption: 0/6 nodes are available: 1 No preemption victims found for incoming pod, 5 Preemption is not helpful for scheduling."
60.1542,Job,ADDED,eval-sanitize-20-r3-035,
60.1555,Pod,ADDED,eval-sanitize-20-r3-036-slccs,phase=Succeeded node=kind-worker2
60.1558,Event,ADDED,eval-sanitize-20-r3-016-wg4b2.18d41b2dfb434164,"reason=FailedScheduling count=None msg=0/6 nodes are available: 1 c_wall violated: 2 conflicting context pair(s) with node memory, 5 node(s) had untolerated taint(s). no new claims to deallocate, preemption: 0/6 nodes are available: 1 No preemption victims found for incoming pod, 5 Preemption is not helpful for scheduling."
60.156,Event,ADDED,eval-sanitize-20-r3-016-wg4b2.18d41b2e1750fb35,reason=Scheduled count=None msg=Successfully assigned compute/eval-sanitize-20-r3-016-wg4b2 to kind-worker4
60.1562,Event,ADDED,eval-sanitize-20-r3-016-wg4b2.18d41b2e313f4a6d,"reason=Pulled count=1 msg=Container image ""busybox:musl"" already present on machine"
60.1564,Event,ADDED,eval-sanitize-20-r3-016-wg4b2.18d41b2e3264c697,reason=Created count=1 msg=Created container: task
60.1572,Job,ADDED,eval-sanitize-20-r3-036,
60.1575,Event,ADDED,eval-sanitize-20-r3-016-wg4b2.18d41b2e3690f58a,reason=Started count=1 msg=Started container task
60.1579,Event,ADDED,eval-sanitize-20-r3-016.18d41b2b3cfc5e95,reason=SuccessfulCreate count=1 msg=Created pod: eval-sanitize-20-r3-016-wg4b2
60.1584,Event,ADDED,eval-sanitize-20-r3-016.18d41b324d80a30d,reason=Completed count=1 msg=Job completed
60.1595,Pod,ADDED,eval-sanitize-20-r3-037-b44z7,phase=Succeeded node=kind-worker5
60.1608,Job,ADDED,eval-sanitize-20-r3-037,
60.1613,Event,ADDED,eval-sanitize-20-r3-017-zwmxm.18d41b2b78b471cd,"reason=FailedScheduling count=None msg=0/6 nodes are available: 6 node(s) had untolerated taint(s). no new claims to deallocate, preemption: 0/6 nodes are available: 6 Preemption is not helpful for scheduling."
60.1615,Event,ADDED,eval-sanitize-20-r3-017-zwmxm.18d41b2def65325b,reason=Scheduled count=None msg=Successfully assigned compute/eval-sanitize-20-r3-017-zwmxm to kind-worker
60.1617,Event,ADDED,eval-sanitize-20-r3-017-zwmxm.18d41b2e0af52b6b,"reason=Pulled count=1 msg=Container image ""busybox:musl"" already present on machine"
60.1619,Event,ADDED,eval-sanitize-20-r3-017-zwmxm.18d41b2e0cd5eb60,reason=Created count=1 msg=Created container: task
60.1633,Pod,ADDED,eval-sanitize-20-r3-038-hxklj,phase=Succeeded node=kind-worker3
60.1645,Job,ADDED,eval-sanitize-20-r3-038,
60.1648,Event,ADDED,eval-sanitize-20-r3-017-zwmxm.18d41b2e1122a3fe,reason=Started count=1 msg=Started container task
60.1651,Event,ADDED,eval-sanitize-20-r3-017.18d41b2b78ace366,reason=SuccessfulCreate count=1 msg=Created pod: eval-sanitize-20-r3-017-zwmxm
60.1653,Event,ADDED,eval-sanitize-20-r3-017.18d41b320f2149e4,reason=Completed count=1 msg=Job completed
60.1654,Event,ADDED,eval-sanitize-20-r3-018-mnx7g.18d41b2bb3fd7b27,"reason=FailedScheduling count=None msg=0/6 nodes are available: 6 node(s) had untolerated taint(s). no new claims to deallocate, preemption: 0/6 nodes are available: 6 Preemption is not helpful for scheduling."
60.1671,Pod,ADDED,eval-sanitize-20-r3-039-6gdd4,phase=Succeeded node=kind-worker
60.1679,Job,ADDED,eval-sanitize-20-r3-039,
60.1682,Event,ADDED,eval-sanitize-20-r3-018-mnx7g.18d41b2def2e3b7b,"reason=FailedScheduling count=None msg=0/6 nodes are available: 1 c_wall violated: 2 conflicting context pair(s) with node memory, 5 node(s) had untolerated taint(s). no new claims to deallocate, preemption: 0/6 nodes are available: 1 No preemption victims found for incoming pod, 5 Preemption is not helpful for scheduling."
60.1684,Event,ADDED,eval-sanitize-20-r3-018-mnx7g.18d41b2dfd1766ee,"reason=FailedScheduling count=None msg=0/6 nodes are available: 1 c_wall violated: 2 conflicting context pair(s) with node memory, 5 node(s) had untolerated taint(s). no new claims to deallocate, preemption: 0/6 nodes are available: 1 No preemption victims found for incoming pod, 5 Preemption is not helpful for scheduling."
60.1686,Event,ADDED,eval-sanitize-20-r3-018-mnx7g.18d41b2e2f319fbb,"reason=FailedScheduling count=None msg=0/6 nodes are available: 1 c_wall violated: 2 conflicting context pair(s) with node memory, 2 c_wall violated: 1 conflicting context pair(s) with node memory, 3 node(s) had untolerated taint(s). no new claims to deallocate, preemption: 0/6 nodes are available: 3 No preemption victims found for incoming pod, 3 Preemption is not helpful for scheduling."
60.1697,Pod,ADDED,eval-sanitize-20-r3-040-p6zwl,phase=Succeeded node=kind-worker2
60.1705,Job,ADDED,eval-sanitize-20-r3-040,
60.1708,Event,ADDED,eval-sanitize-20-r3-018-mnx7g.18d41b2e418e05ef,reason=Scheduled count=None msg=Successfully assigned compute/eval-sanitize-20-r3-018-mnx7g to kind-worker2
60.1711,Event,ADDED,eval-sanitize-20-r3-018-mnx7g.18d41b2e5add787a,"reason=Pulled count=1 msg=Container image ""busybox:musl"" already present on machine"
60.1713,Event,ADDED,eval-sanitize-20-r3-018-mnx7g.18d41b2e5c157145,reason=Created count=1 msg=Created container: task
60.1717,Event,ADDED,eval-sanitize-20-r3-018-mnx7g.18d41b2e603c9e46,reason=Started count=1 msg=Started container task
60.1719,Event,ADDED,eval-sanitize-20-r3-018.18d41b2bb3f05856,reason=SuccessfulCreate count=1 msg=Created pod: eval-sanitize-20-r3-018-mnx7g
60.1722,Event,ADDED,eval-sanitize-20-r3-018.18d41b32a07fd605,reason=Completed count=1 msg=Job completed
60.1723,Event,ADDED,eval-sanitize-20-r3-019-jntlw.18d41b2bef95c3aa,"reason=FailedScheduling count=None msg=0/6 nodes are available: 6 node(s) had untolerated taint(s). no new claims to deallocate, preemption: 0/6 nodes are available: 6 Preemption is not helpful for scheduling."
60.1725,Event,ADDED,eval-sanitize-20-r3-019-jntlw.18d41b2defc45a29,"reason=FailedScheduling count=None msg=0/6 nodes are available: 1 c_wall violated: 1 conflicting context pair(s) with node memory, 5 node(s) had untolerated taint(s). no new claims to deallocate, preemption: 0/6 nodes are available: 1 No preemption victims found for incoming pod, 5 Preemption is not helpful for scheduling."
60.1727,Event,ADDED,eval-sanitize-20-r3-019-jntlw.18d41b2dfdaafbc4,reason=Scheduled count=None msg=Successfully assigned compute/eval-sanitize-20-r3-019-jntlw to kind-worker4
60.1729,Event,ADDED,eval-sanitize-20-r3-019-jntlw.18d41b2e18fb6ef3,"reason=Pulled count=1 msg=Container image ""busybox:musl"" already present on machine"
60.1743,Pod,ADDED,eval-sanitize-20-r3-041-pdkzt,phase=Succeeded node=kind-worker2
60.1752,Job,ADDED,eval-sanitize-20-r3-041,
60.1755,Event,ADDED,eval-sanitize-20-r3-019-jntlw.18d41b2e1a51fbca,reason=Created count=1 msg=Created container: task
60.1757,Event,ADDED,eval-sanitize-20-r3-019-jntlw.18d41b2e1e5f3a3f,reason=Started count=1 msg=Started container task
60.1759,Event,ADDED,eval-sanitize-20-r3-019.18d41b2bef876ae9,reason=SuccessfulCreate count=1 msg=Created pod: eval-sanitize-20-r3-019-jntlw
60.1762,Event,ADDED,eval-sanitize-20-r3-019.18d41b324473edca,reason=Completed count=1 msg=Job completed
60.1773,Pod,ADDED,eval-sanitize-20-r3-042-p8bkn,phase=Succeeded node=kind-worker3
60.1781,Job,ADDED,eval-sanitize-20-r3-042,
60.1784,Event,ADDED,eval-sanitize-20-r3-020-z7jzd.18d41b2c2b42e844,"reason=FailedScheduling count=None msg=0/6 nodes are available: 6 node(s) had untolerated taint(s). no new claims to deallocate, preemption: 0/6 nodes are available: 6 Preemption is not helpful for scheduling."
60.1786,Event,ADDED,eval-sanitize-20-r3-020-z7jzd.18d41b2df1414e4e,reason=Scheduled count=None msg=Successfully assigned compute/eval-sanitize-20-r3-020-z7jzd to kind-worker
60.1788,Event,ADDED,eval-sanitize-20-r3-020-z7jzd.18d41b2e0b824370,"reason=Pulled count=1 msg=Container image ""busybox:musl"" already present on machine"
60.1795,Event,ADDED,eval-sanitize-20-r3-020-z7jzd.18d41b2e0d4f5c64,reason=Created count=1 msg=Created container: task
60.1797,Event,ADDED,eval-sanitize-20-r3-020-z7jzd.18d41b2e11222145,reason=Started count=1 msg=Started container task
60.18,Event,ADDED,eval-sanitize-20-r3-020.18d41b2c2b3dbbb5,reason=SuccessfulCreate count=1 msg=Created pod: eval-sanitize-20-r3-020-z7jzd
60.1801,Event,ADDED,eval-sanitize-20-r3-020.18d41b31f10f6334,reason=Completed count=1 msg=Job completed
60.1814,Pod,ADDED,eval-sanitize-20-r3-043-zkwvs,phase=Succeeded node=kind-worker3
60.1825,Pod,ADDED,eval-sanitize-20-r3-044-s9w22,phase=Succeeded node=kind-worker
60.1828,Event,ADDED,eval-sanitize-20-r3-021-xmp2g.18d41b2c67cdbf55,"reason=FailedScheduling count=None msg=0/6 nodes are available: 6 node(s) had untolerated taint(s). no new claims to deallocate, preemption: 0/6 nodes are available: 6 Preemption is not helpful for scheduling."
60.183,Event,ADDED,eval-sanitize-20-r3-021-xmp2g.18d41b2df12582e1,"reason=FailedScheduling count=None msg=0/6 nodes are available: 1 c_wall violated: 3 conflicting context pair(s) with node memory, 5 node(s) had untolerated taint(s). no new claims to deallocate, preemption: 0/6 nodes are available: 1 No preemption victims found for incoming pod, 5 Preemption is not helpful for scheduling."
60.1832,Event,ADDED,eval-sanitize-20-r3-021-xmp2g.18d41b2dffec6199,"reason=FailedScheduling count=None msg=0/6 nodes are available: 1 c_wall violated: 1 conflicting context pair(s) with node memory, 1 c_wall violated: 3 conflicting context pair(s) with node memory, 4 node(s) had untolerated taint(s). no new claims to deallocate, preemption: 0/6 nodes are available: 2 No preemption victims found for incoming pod, 4 Preemption is not helpful for scheduling."
60.184,Job,ADDED,eval-sanitize-20-r3-043,
60.185,Job,ADDED,eval-sanitize-20-r3-044,
60.1853,Event,ADDED,eval-sanitize-20-r3-021-xmp2g.18d41b2e1953acf8,"reason=FailedScheduling count=None msg=0/6 nodes are available: 1 c_wall violated: 2 conflicting context pair(s) with node memory, 1 c_wall violated: 3 conflicting context pair(s) with node memory, 4 node(s) had untolerated taint(s). no new claims to deallocate, preemption: 0/6 nodes are available: 2 No preemption victims found for incoming pod, 4 Preemption is not helpful for scheduling."
60.1856,Event,ADDED,eval-sanitize-20-r3-021-xmp2g.18d41b2e358b41b2,reason=Scheduled count=None msg=Successfully assigned compute/eval-sanitize-20-r3-021-xmp2g to kind-worker3
60.1859,Event,ADDED,eval-sanitize-20-r3-021-xmp2g.18d41b2e4e674db3,"reason=Pulled count=1 msg=Container image ""busybox:musl"" already present on machine"
60.1863,Event,ADDED,eval-sanitize-20-r3-021-xmp2g.18d41b2e4fe34033,reason=Created count=1 msg=Created container: task
60.1876,Pod,ADDED,eval-sanitize-20-r3-045-r687p,phase=Succeeded node=kind-worker2
60.1881,Event,ADDED,eval-sanitize-20-r3-021-xmp2g.18d41b2e51e6d2c5,reason=Started count=1 msg=Started container task
60.1883,Event,ADDED,eval-sanitize-20-r3-021.18d41b2c67c25a3f,reason=SuccessfulCreate count=1 msg=Created pod: eval-sanitize-20-r3-021-xmp2g
60.1885,Event,ADDED,eval-sanitize-20-r3-021.18d41b327c9c2ac9,reason=Completed count=1 msg=Job completed
60.1896,Pod,ADDED,eval-sanitize-20-r3-046-vwfpx,phase=Running node=kind-worker5
60.1904,Job,ADDED,eval-sanitize-20-r3-045,
60.1907,Event,ADDED,eval-sanitize-20-r3-022-22zpt.18d41b2ca26925a5,"reason=FailedScheduling count=None msg=0/6 nodes are available: 6 node(s) had untolerated taint(s). no new claims to deallocate, preemption: 0/6 nodes are available: 6 Preemption is not helpful for scheduling."
60.1908,Event,ADDED,eval-sanitize-20-r3-022-22zpt.18d41b2df3ed05f7,reason=Scheduled count=None msg=Successfully assigned compute/eval-sanitize-20-r3-022-22zpt to kind-worker
60.1911,Event,ADDED,eval-sanitize-20-r3-022-22zpt.18d41b2e11250c47,"reason=Pulled count=1 msg=Container image ""busybox:musl"" already present on machine"
60.1913,Event,ADDED,eval-sanitize-20-r3-022-22zpt.18d41b2e12aca068,reason=Created count=1 msg=Created container: task
60.1925,Pod,ADDED,eval-sanitize-20-r3-047-zd5js,phase=Running node=kind-worker4
60.1931,Job,ADDED,eval-sanitize-20-r3-046,
60.1933,Event,ADDED,eval-sanitize-20-r3-022-22zpt.18d41b2e1611b713,reason=Started count=1 msg=Started container task
60.1935,Event,ADDED,eval-sanitize-20-r3-022.18d41b2ca25a0a03,reason=SuccessfulCreate count=1 msg=Created pod: eval-sanitize-20-r3-022-22zpt
60.1937,Event,ADDED,eval-sanitize-20-r3-022.18d41b321da1bac0,reason=Completed count=1 msg=Job completed
60.1939,Event,ADDED,eval-sanitize-20-r3-023-l94v5.18d41b2cde32856a,"reason=FailedScheduling count=None msg=0/6 nodes are available: 6 node(s) had untolerated taint(s). no new claims to deallocate, preemption: 0/6 nodes are available: 6 Preemption is not helpful for scheduling."
60.195,Pod,ADDED,eval-sanitize-20-r3-048-vzkh2,phase=Running node=kind-worker4
60.1958,Pod,ADDED,eval-sanitize-20-r3-049-fxkt7,phase=Pending node=None
60.1964,Job,ADDED,eval-sanitize-20-r3-047,
60.1967,Event,ADDED,eval-sanitize-20-r3-023-l94v5.18d41b2df3bfddbe,"reason=FailedScheduling count=None msg=0/6 nodes are available: 1 c_wall violated: 2 conflicting context pair(s) with node memory, 5 node(s) had untolerated taint(s). no new claims to deallocate, preemption: 0/6 nodes are available: 1 No preemption victims found for incoming pod, 5 Preemption is not helpful for scheduling."
60.1969,Event,ADDED,eval-sanitize-20-r3-023-l94v5.18d41b2e030b7bc9,"reason=FailedScheduling count=None msg=0/6 nodes are available: 1 c_wall violated: 1 conflicting context pair(s) with node memory, 1 c_wall violated: 2 conflicting context pair(s) with node memory, 4 node(s) had untolerated taint(s). no new claims to deallocate, preemption: 0/6 nodes are available: 2 No preemption victims found for incoming pod, 4 Preemption is not helpful for scheduling."
60.1973,Event,ADDED,eval-sanitize-20-r3-023-l94v5.18d41b2e1d437fe6,"reason=FailedScheduling count=None msg=0/6 nodes are available: 1 c_wall violated: 1 conflicting context pair(s) with node memory, 1 c_wall violated: 2 conflicting context pair(s) with node memory, 4 node(s) had untolerated taint(s). no new claims to deallocate, preemption: 0/6 nodes are available: 2 No preemption victims found for incoming pod, 4 Preemption is not helpful for scheduling."
60.1974,Event,ADDED,eval-sanitize-20-r3-023-l94v5.18d41b2e4798fa8a,reason=Scheduled count=None msg=Successfully assigned compute/eval-sanitize-20-r3-023-l94v5 to kind-worker2
60.1976,Event,ADDED,eval-sanitize-20-r3-023-l94v5.18d41b2e60bd12cd,"reason=Pulled count=1 msg=Container image ""busybox:musl"" already present on machine"
60.1978,Event,ADDED,eval-sanitize-20-r3-023-l94v5.18d41b2e62028348,reason=Created count=1 msg=Created container: task
60.1985,Job,ADDED,eval-sanitize-20-r3-048,
60.1993,Pod,ADDED,eval-sanitize-20-r3-050-lzwr9,phase=Pending node=None
60.1995,Event,ADDED,eval-sanitize-20-r3-023-l94v5.18d41b2e654805a4,reason=Started count=1 msg=Started container task
60.1998,Event,ADDED,eval-sanitize-20-r3-023.18d41b2cde2b76f3,reason=SuccessfulCreate count=1 msg=Created pod: eval-sanitize-20-r3-023-l94v5
60.2,Event,ADDED,eval-sanitize-20-r3-023.18d41b32ca4e92fb,reason=Completed count=1 msg=Job completed
60.2002,Event,ADDED,eval-sanitize-20-r3-024-7v9kq.18d41b2d19cabb5c,"reason=FailedScheduling count=None msg=0/6 nodes are available: 6 node(s) had untolerated taint(s). no new claims to deallocate, preemption: 0/6 nodes are available: 6 Preemption is not helpful for scheduling."
60.2004,Event,ADDED,eval-sanitize-20-r3-024-7v9kq.18d41b2df4a9398a,reason=Scheduled count=None msg=Successfully assigned compute/eval-sanitize-20-r3-024-7v9kq to kind-worker
60.2006,Event,ADDED,eval-sanitize-20-r3-024-7v9kq.18d41b2e1060d778,"reason=Pulled count=1 msg=Container image ""busybox:musl"" already present on machine"
60.2008,Event,ADDED,eval-sanitize-20-r3-024-7v9kq.18d41b2e11f05d94,reason=Created count=1 msg=Created container: task
60.2015,Pod,ADDED,eval-sanitize-20-r3-051-xgx9f,phase=Pending node=None
60.2026,Job,ADDED,eval-sanitize-20-r3-049,
60.203,Event,ADDED,eval-sanitize-20-r3-024-7v9kq.18d41b2e15dd30e5,reason=Started count=1 msg=Started container task
60.2032,Event,ADDED,eval-sanitize-20-r3-024.18d41b2d19bd4b46,reason=SuccessfulCreate count=1 msg=Created pod: eval-sanitize-20-r3-024-7v9kq
60.2034,Event,ADDED,eval-sanitize-20-r3-024.18d41b3211516fa5,reason=Completed count=1 msg=Job completed
60.2036,Event,ADDED,eval-sanitize-20-r3-025-928bl.18d41b2d58ed9685,"reason=FailedScheduling count=None msg=0/6 nodes are available: 6 node(s) had untolerated taint(s). no new claims to deallocate, preemption: 0/6 nodes are available: 6 Preemption is not helpful for scheduling."
60.2043,Pod,ADDED,eval-sanitize-20-r3-052-j6284,phase=Pending node=None
60.2049,Job,ADDED,eval-sanitize-20-r3-050,
60.2054,Event,ADDED,eval-sanitize-20-r3-025-928bl.18d41b2df6ede65d,"reason=FailedScheduling count=None msg=0/6 nodes are available: 1 c_wall violated: 2 conflicting context pair(s) with node memory, 5 node(s) had untolerated taint(s). no new claims to deallocate, preemption: 0/6 nodes are available: 1 No preemption victims found for incoming pod, 5 Preemption is not helpful for scheduling."
60.2056,Event,ADDED,eval-sanitize-20-r3-025-928bl.18d41b2e05a80982,"reason=FailedScheduling count=None msg=0/6 nodes are available: 1 c_wall violated: 1 conflicting context pair(s) with node memory, 1 c_wall violated: 2 conflicting context pair(s) with node memory, 4 node(s) had untolerated taint(s). no new claims to deallocate, preemption: 0/6 nodes are available: 2 No preemption victims found for incoming pod, 4 Preemption is not helpful for scheduling."
60.2058,Event,ADDED,eval-sanitize-20-r3-025-928bl.18d41b2e1f55e911,reason=Scheduled count=None msg=Successfully assigned compute/eval-sanitize-20-r3-025-928bl to kind-worker3
60.2066,Pod,ADDED,eval-sanitize-20-r3-053-ltx59,phase=Pending node=None
60.2074,Pod,ADDED,eval-sanitize-20-r3-054-hfq7n,phase=Pending node=None
60.2077,Event,ADDED,eval-sanitize-20-r3-025-928bl.18d41b2e3bb829cc,"reason=Pulled count=1 msg=Container image ""busybox:musl"" already present on machine"
60.208,Event,ADDED,eval-sanitize-20-r3-025-928bl.18d41b2e3d46b20f,reason=Created count=1 msg=Created container: task
60.2082,Event,ADDED,eval-sanitize-20-r3-025-928bl.18d41b2e40fd5436,reason=Started count=1 msg=Started container task
60.2084,Event,ADDED,eval-sanitize-20-r3-025.18d41b2d58d7042b,reason=SuccessfulCreate count=1 msg=Created pod: eval-sanitize-20-r3-025-928bl
60.2091,Job,ADDED,eval-sanitize-20-r3-051,
60.2095,Event,ADDED,eval-sanitize-20-r3-025.18d41b328beb7c34,reason=Completed count=1 msg=Job completed
60.2097,Event,ADDED,eval-sanitize-20-r3-026-4255x.18d41b2d90d6ecaf,"reason=FailedScheduling count=None msg=0/6 nodes are available: 6 node(s) had untolerated taint(s). no new claims to deallocate, preemption: 0/6 nodes are available: 6 Preemption is not helpful for scheduling."
60.2098,Event,ADDED,eval-sanitize-20-r3-026-4255x.18d41b2df7827851,"reason=FailedScheduling count=None msg=0/6 nodes are available: 1 c_wall violated: 3 conflicting context pair(s) with node memory, 5 node(s) had untolerated taint(s). no new claims to deallocate, preemption: 0/6 nodes are available: 1 No preemption victims found for incoming pod, 5 Preemption is not helpful for scheduling."
60.2106,Job,ADDED,eval-sanitize-20-r3-052,
60.2116,Pod,ADDED,eval-sanitize-20-r3-055-88wc4,phase=Running node=kind-worker4
60.2119,Event,ADDED,eval-sanitize-20-r3-026-4255x.18d41b2e07006236,reason=Scheduled count=None msg=Successfully assigned compute/eval-sanitize-20-r3-026-4255x to kind-worker4
60.2121,Event,ADDED,eval-sanitize-20-r3-026-4255x.18d41b2e231ed7dc,"reason=Pulled count=1 msg=Container image ""busybox:musl"" already present on machine"
60.2123,Event,ADDED,eval-sanitize-20-r3-026-4255x.18d41b2e25076682,reason=Created count=1 msg=Created container: task
60.2125,Event,ADDED,eval-sanitize-20-r3-026-4255x.18d41b2e28befde3,reason=Started count=1 msg=Started container task
60.2133,Job,ADDED,eval-sanitize-20-r3-053,
60.2141,Pod,ADDED,eval-sanitize-20-r3-056-bmfg2,phase=Pending node=None
60.2144,Event,ADDED,eval-sanitize-20-r3-026.18d41b2d90cc1d7f,reason=SuccessfulCreate count=1 msg=Created pod: eval-sanitize-20-r3-026-4255x
60.2146,Event,ADDED,eval-sanitize-20-r3-026.18d41b322cc18c2a,reason=Completed count=1 msg=Job completed
60.2147,Event,ADDED,eval-sanitize-20-r3-027-p6tjp.18d41b2dcc6050fc,"reason=FailedScheduling count=None msg=0/6 nodes are available: 6 node(s) had untolerated taint(s). no new claims to deallocate, preemption: 0/6 nodes are available: 6 Preemption is not helpful for scheduling."
60.2154,Job,ADDED,eval-sanitize-20-r3-054,
60.2163,Pod,ADDED,eval-sanitize-20-r3-057-kjtnf,phase=Pending node=None
60.2165,Event,ADDED,eval-sanitize-20-r3-027-p6tjp.18d41b2df7fae7d4,"reason=FailedScheduling count=None msg=0/6 nodes are available: 1 c_wall violated: 3 conflicting context pair(s) with node memory, 5 node(s) had untolerated taint(s). no new claims to deallocate, preemption: 0/6 nodes are available: 1 No preemption victims found for incoming pod, 5 Preemption is not helpful for scheduling."
60.2167,Event,ADDED,eval-sanitize-20-r3-027-p6tjp.18d41b2e073a5064,"reason=FailedScheduling count=None msg=0/6 nodes are available: 1 c_wall violated: 1 conflicting context pair(s) with node memory, 1 c_wall violated: 3 conflicting context pair(s) with node memory, 4 node(s) had untolerated taint(s). no new claims to deallocate, preemption: 0/6 nodes are available: 2 No preemption victims found for incoming pod, 4 Preemption is not helpful for scheduling."
60.2169,Event,ADDED,eval-sanitize-20-r3-027-p6tjp.18d41b2e23a7d9e0,reason=Scheduled count=None msg=Successfully assigned compute/eval-sanitize-20-r3-027-p6tjp to kind-worker3
60.2171,Event,ADDED,eval-sanitize-20-r3-027-p6tjp.18d41b2e3cc0d3f5,"reason=Pulled count=1 msg=Container image ""busybox:musl"" already present on machine"
60.2174,Event,ADDED,eval-sanitize-20-r3-027-p6tjp.18d41b2e3e58b738,reason=Created count=1 msg=Created container: task
60.2177,Event,ADDED,eval-sanitize-20-r3-027-p6tjp.18d41b2e413a516a,reason=Started count=1 msg=Started container task
60.2187,Job,ADDED,eval-sanitize-20-r3-055,
60.2189,Event,ADDED,eval-sanitize-20-r3-027.18d41b2dcc560852,reason=SuccessfulCreate count=1 msg=Created pod: eval-sanitize-20-r3-027-p6tjp
60.2202,Pod,ADDED,eval-sanitize-20-r3-058-vjdj6,phase=Running node=kind-worker4
60.221,Job,ADDED,eval-sanitize-20-r3-056,
60.2213,Event,ADDED,eval-sanitize-20-r3-027.18d41b32829c5c36,reason=Completed count=1 msg=Job completed
60.2214,Event,ADDED,eval-sanitize-20-r3-028-cc6vw.18d41b2e0d6fe694,reason=Scheduled count=None msg=Successfully assigned compute/eval-sanitize-20-r3-028-cc6vw to kind-worker
60.2216,Event,ADDED,eval-sanitize-20-r3-028-cc6vw.18d41b2e2839c410,"reason=Pulled count=1 msg=Container image ""busybox:musl"" already present on machine"
60.2218,Event,ADDED,eval-sanitize-20-r3-028-cc6vw.18d41b2e2a579d93,reason=Created count=1 msg=Created container: task
60.2232,Pod,ADDED,eval-sanitize-20-r3-059-xwnbs,phase=Running node=kind-worker4
60.2235,Event,ADDED,eval-sanitize-20-r3-028-cc6vw.18d41b2e2e63e981,reason=Started count=1 msg=Started container task
60.2237,Event,ADDED,eval-sanitize-20-r3-028.18d41b2e08ea876d,reason=SuccessfulCreate count=1 msg=Created pod: eval-sanitize-20-r3-028-cc6vw
60.224,Event,ADDED,eval-sanitize-20-r3-028.18d41b320b61da0b,reason=Completed count=1 msg=Job completed
60.2242,Event,ADDED,eval-sanitize-20-r3-029-mpn7t.18d41b2e53ee4e11,reason=Scheduled count=None msg=Successfully assigned compute/eval-sanitize-20-r3-029-mpn7t to kind-worker3
60.2278,Job,ADDED,eval-sanitize-20-r3-057,
60.2282,Event,ADDED,eval-sanitize-20-r3-029-mpn7t.18d41b2e6db26ed6,"reason=Pulled count=1 msg=Container image ""busybox:musl"" already present on machine"
60.2285,Event,ADDED,eval-sanitize-20-r3-029-mpn7t.18d41b2e6ed8ae86,reason=Created count=1 msg=Created container: task
60.2288,Event,ADDED,eval-sanitize-20-r3-029-mpn7t.18d41b2e72d54c0a,reason=Started count=1 msg=Started container task
60.2305,Pod,MODIFIED,eval-sanitize-20-r3-048-vzkh2,phase=Running node=kind-worker4
60.2312,Job,ADDED,eval-sanitize-20-r3-058,
60.2316,Event,ADDED,eval-sanitize-20-r3-029.18d41b2e4910574d,reason=SuccessfulCreate count=1 msg=Created pod: eval-sanitize-20-r3-029-mpn7t
60.232,Event,ADDED,eval-sanitize-20-r3-029.18d41b32e4fc5ad5,reason=Completed count=1 msg=Job completed
60.2324,Event,ADDED,eval-sanitize-20-r3-030-tqczp.18d41b2e80dd12bd,reason=Scheduled count=None msg=Successfully assigned compute/eval-sanitize-20-r3-030-tqczp to kind-worker5
60.2327,Event,ADDED,eval-sanitize-20-r3-030-tqczp.18d41b2e9a1f7034,"reason=Pulled count=1 msg=Container image ""busybox:musl"" already present on machine"
60.2331,Event,ADDED,eval-sanitize-20-r3-030-tqczp.18d41b2e9b3cde86,reason=Created count=1 msg=Created container: task
60.2334,Event,ADDED,eval-sanitize-20-r3-030-tqczp.18d41b2e9d3f489f,reason=Started count=1 msg=Started container task
60.2336,Event,ADDED,eval-sanitize-20-r3-030.18d41b2e7f7131f9,reason=SuccessfulCreate count=1 msg=Created pod: eval-sanitize-20-r3-030-tqczp
60.2338,Event,ADDED,eval-sanitize-20-r3-030.18d41b32d62527df,reason=Completed count=1 msg=Job completed
60.2347,Pod,ADDED,eval-sanitize-20-r3-060-898td,phase=Pending node=None
60.235,Event,ADDED,eval-sanitize-20-r3-031-92b5r.18d41b2ec07c7ff9,reason=Scheduled count=None msg=Successfully assigned compute/eval-sanitize-20-r3-031-92b5r to kind-worker3
60.2352,Event,ADDED,eval-sanitize-20-r3-031-92b5r.18d41b2ed9e1a7a5,"reason=Pulled count=1 msg=Container image ""busybox:musl"" already present on machine"
60.2355,Event,ADDED,eval-sanitize-20-r3-031-92b5r.18d41b2edb11d287,reason=Created count=1 msg=Created container: task
60.2362,Job,ADDED,eval-sanitize-20-r3-059,
60.2367,Event,ADDED,eval-sanitize-20-r3-031-92b5r.18d41b2edd12266c,reason=Started count=1 msg=Started container task
60.237,Event,ADDED,eval-sanitize-20-r3-031.18d41b2ebb149c62,reason=SuccessfulCreate count=1 msg=Created pod: eval-sanitize-20-r3-031-92b5r
60.2373,Event,ADDED,eval-sanitize-20-r3-031.18d41b32f6edc3da,reason=Completed count=1 msg=Job completed
60.2375,Event,ADDED,eval-sanitize-20-r3-032-cr99x.18d41b2efc2c87b8,reason=Scheduled count=None msg=Successfully assigned compute/eval-sanitize-20-r3-032-cr99x to kind-worker5
60.2383,Job,MODIFIED,eval-sanitize-20-r3-047,
60.2397,Pod,MODIFIED,eval-sanitize-20-r3-045-r687p,phase=Succeeded node=kind-worker2
60.24,Event,ADDED,eval-sanitize-20-r3-032-cr99x.18d41b2f15c181ae,"reason=Pulled count=1 msg=Container image ""busybox:musl"" already present on machine"
60.2402,Event,ADDED,eval-sanitize-20-r3-032-cr99x.18d41b2f16f0a4d5,reason=Created count=1 msg=Created container: task
60.2404,Event,ADDED,eval-sanitize-20-r3-032-cr99x.18d41b2f1a2a913e,reason=Started count=1 msg=Started container task
60.2406,Event,ADDED,eval-sanitize-20-r3-032.18d41b2ef6889d0e,reason=SuccessfulCreate count=1 msg=Created pod: eval-sanitize-20-r3-032-cr99x
60.2411,Job,ADDED,eval-sanitize-20-r3-060,
60.2415,Event,ADDED,eval-sanitize-20-r3-032.18d41b3302d7cd1f,reason=Completed count=1 msg=Job completed
60.2417,Event,ADDED,eval-sanitize-20-r3-033-mpfrc.18d41b2f37ccbcd3,reason=Scheduled count=None msg=Successfully assigned compute/eval-sanitize-20-r3-033-mpfrc to kind-worker2
60.242,Event,ADDED,eval-sanitize-20-r3-033-mpfrc.18d41b2f5028d2c5,"reason=Pulled count=1 msg=Container image ""busybox:musl"" already present on machine"
60.2428,Pod,MODIFIED,eval-sanitize-20-r3-060-898td,phase=Pending node=None
60.2432,Event,ADDED,eval-sanitize-20-r3-033-mpfrc.18d41b2f5140e3e5,reason=Created count=1 msg=Created container: task
60.2435,Event,ADDED,eval-sanitize-20-r3-033-mpfrc.18d41b2f533a1818,reason=Started count=1 msg=Started container task
60.2437,Event,ADDED,eval-sanitize-20-r3-033.18d41b2f32f80217,reason=SuccessfulCreate count=1 msg=Created pod: eval-sanitize-20-r3-033-mpfrc
60.244,Event,ADDED,eval-sanitize-20-r3-033.18d41b3314bac7d1,reason=Completed count=1 msg=Job completed
60.2447,Job,MODIFIED,eval-sanitize-20-r3-045,
60.245,Event,ADDED,eval-sanitize-20-r3-034-bjfdr.18d41b2f735724ed,reason=Scheduled count=None msg=Successfully assigned compute/eval-sanitize-20-r3-034-bjfdr to kind-worker5
60.2452,Event,ADDED,eval-sanitize-20-r3-034-bjfdr.18d41b2f8e02963d,"reason=Pulled count=1 msg=Container image ""busybox:musl"" already present on machine"
60.2454,Event,ADDED,eval-sanitize-20-r3-034-bjfdr.18d41b2f8f37f84d,reason=Created count=1 msg=Created container: task
60.2456,Event,ADDED,eval-sanitize-20-r3-034-bjfdr.18d41b2f919bae27,reason=Started count=1 msg=Started container task
60.2459,Event,ADDED,eval-sanitize-20-r3-034.18d41b2f6e2ad810,reason=SuccessfulCreate count=1 msg=Created pod: eval-sanitize-20-r3-034-bjfdr
60.2461,Event,ADDED,eval-sanitize-20-r3-034.18d41b33301eb2d3,reason=Completed count=1 msg=Job completed
60.2462,Event,ADDED,eval-sanitize-20-r3-035-p99z2.18d41b2faee1cf2f,reason=Scheduled count=None msg=Successfully assigned compute/eval-sanitize-20-r3-035-p99z2 to kind-worker3
60.2474,Pod,MODIFIED,eval-sanitize-20-r3-047-zd5js,phase=Succeeded node=kind-worker4
60.2481,Job,MODIFIED,eval-sanitize-20-r3-059,
60.2484,Event,ADDED,eval-sanitize-20-r3-035-p99z2.18d41b2fc801529a,"reason=Pulled count=1 msg=Container image ""busybox:musl"" already present on machine"
60.2486,Event,ADDED,eval-sanitize-20-r3-035-p99z2.18d41b2fc9252a02,reason=Created count=1 msg=Created container: task
60.2488,Event,ADDED,eval-sanitize-20-r3-035-p99z2.18d41b2fcb4ecfd1,reason=Started count=1 msg=Started container task
60.249,Event,ADDED,eval-sanitize-20-r3-035.18d41b2fa939b417,reason=SuccessfulCreate count=1 msg=Created pod: eval-sanitize-20-r3-035-p99z2
60.2493,Event,ADDED,eval-sanitize-20-r3-035.18d41b332a5a58d7,reason=Completed count=1 msg=Job completed
60.2495,Event,ADDED,eval-sanitize-20-r3-036-slccs.18d41b2fea7194f1,reason=Scheduled count=None msg=Successfully assigned compute/eval-sanitize-20-r3-036-slccs to kind-worker2
60.2506,Job,MODIFIED,eval-sanitize-20-r3-060,
60.2508,Event,ADDED,eval-sanitize-20-r3-036-slccs.18d41b30032d734c,"reason=Pulled count=1 msg=Container image ""busybox:musl"" already present on machine"
60.2511,Event,ADDED,eval-sanitize-20-r3-036-slccs.18d41b300440e402,reason=Created count=1 msg=Created container: task
60.2513,Event,ADDED,eval-sanitize-20-r3-036-slccs.18d41b3007967a1d,reason=Started count=1 msg=Started container task
60.2516,Event,ADDED,eval-sanitize-20-r3-036.18d41b2fe4f75829,reason=SuccessfulCreate count=1 msg=Created pod: eval-sanitize-20-r3-036-slccs
60.2517,Event,ADDED,eval-sanitize-20-r3-036.18d41b334a7eb528,reason=Completed count=1 msg=Job completed
60.2526,Job,MODIFIED,eval-sanitize-20-r3-045,
60.2529,Event,ADDED,eval-sanitize-20-r3-037-b44z7.18d41b302640f9d8,reason=Scheduled count=None msg=Successfully assigned compute/eval-sanitize-20-r3-037-b44z7 to kind-worker5
60.2531,Event,ADDED,eval-sanitize-20-r3-037-b44z7.18d41b30401699d5,"reason=Pulled count=1 msg=Container image ""busybox:musl"" already present on machine"
60.2533,Event,ADDED,eval-sanitize-20-r3-037-b44z7.18d41b3041588ce2,reason=Created count=1 msg=Created container: task
60.2535,Event,ADDED,eval-sanitize-20-r3-037-b44z7.18d41b304591bcf3,reason=Started count=1 msg=Started container task
60.254,Event,ADDED,eval-sanitize-20-r3-037.18d41b3020b330b7,reason=SuccessfulCreate count=1 msg=Created pod: eval-sanitize-20-r3-037-b44z7
60.2542,Event,ADDED,eval-sanitize-20-r3-037.18d41b337ffee0c1,reason=Completed count=1 msg=Job completed
60.2544,Event,ADDED,eval-sanitize-20-r3-038-hxklj.18d41b306178a203,reason=Scheduled count=None msg=Successfully assigned compute/eval-sanitize-20-r3-038-hxklj to kind-worker3
60.2546,Event,ADDED,eval-sanitize-20-r3-038-hxklj.18d41b307b4a43b6,"reason=Pulled count=1 msg=Container image ""busybox:musl"" already present on machine"
60.2552,Job,MODIFIED,eval-sanitize-20-r3-047,
60.2555,Event,ADDED,eval-sanitize-20-r3-038-hxklj.18d41b307c5409e1,reason=Created count=1 msg=Created container: task
60.2557,Event,ADDED,eval-sanitize-20-r3-038-hxklj.18d41b307e419b5d,reason=Started count=1 msg=Started container task
60.2559,Event,ADDED,eval-sanitize-20-r3-038.18d41b305cfa9784,reason=SuccessfulCreate count=1 msg=Created pod: eval-sanitize-20-r3-038-hxklj
60.2561,Event,ADDED,eval-sanitize-20-r3-038.18d41b33cee09cc2,reason=Completed count=1 msg=Job completed
60.2563,Event,ADDED,eval-sanitize-20-r3-039-6gdd4.18d41b309d071355,reason=Scheduled count=None msg=Successfully assigned compute/eval-sanitize-20-r3-039-6gdd4 to kind-worker
60.2565,Event,ADDED,eval-sanitize-20-r3-039-6gdd4.18d41b30b733acd5,"reason=Pulled count=1 msg=Container image ""busybox:musl"" already present on machine"
60.2567,Event,ADDED,eval-sanitize-20-r3-039-6gdd4.18d41b30b887d30d,reason=Created count=1 msg=Created container: task
60.2575,Job,MODIFIED,eval-sanitize-20-r3-045,
60.2577,Event,ADDED,eval-sanitize-20-r3-039-6gdd4.18d41b30c071592e,reason=Started count=1 msg=Started container task
60.2579,Event,ADDED,eval-sanitize-20-r3-039.18d41b3097938461,reason=SuccessfulCreate count=1 msg=Created pod: eval-sanitize-20-r3-039-6gdd4
60.2581,Event,ADDED,eval-sanitize-20-r3-039.18d41b33d7d389a5,reason=Completed count=1 msg=Job completed
60.2583,Event,ADDED,eval-sanitize-20-r3-040-p6zwl.18d41b30e91f86e7,reason=Scheduled count=None msg=Successfully assigned compute/eval-sanitize-20-r3-040-p6zwl to kind-worker2
60.2586,Event,ADDED,eval-sanitize-20-r3-040-p6zwl.18d41b31028b02e1,"reason=Pulled count=1 msg=Container image ""busybox:musl"" already present on machine"
60.2588,Event,ADDED,eval-sanitize-20-r3-040-p6zwl.18d41b3103acce6b,reason=Created count=1 msg=Created container: task
60.259,Event,ADDED,eval-sanitize-20-r3-040-p6zwl.18d41b31085766f8,reason=Started count=1 msg=Started container task
60.2596,Job,MODIFIED,eval-sanitize-20-r3-059,
60.2599,Event,ADDED,eval-sanitize-20-r3-040.18d41b30e2738d1b,reason=SuccessfulCreate count=1 msg=Created pod: eval-sanitize-20-r3-040-p6zwl
60.2601,Event,ADDED,eval-sanitize-20-r3-040.18d41b341c0d2c17,reason=Completed count=1 msg=Job completed
60.2603,Event,ADDED,eval-sanitize-20-r3-041-pdkzt.18d41b3125293325,reason=Scheduled count=None msg=Successfully assigned compute/eval-sanitize-20-r3-041-pdkzt to kind-worker2
60.2605,Event,ADDED,eval-sanitize-20-r3-041-pdkzt.18d41b313e1e2863,"reason=Pulled count=1 msg=Container image ""busybox:musl"" already present on machine"
60.2613,Job,MODIFIED,eval-sanitize-20-r3-045,
60.2615,Event,ADDED,eval-sanitize-20-r3-041-pdkzt.18d41b313f2f7628,reason=Created count=1 msg=Created container: task
60.2617,Event,ADDED,eval-sanitize-20-r3-041-pdkzt.18d41b31425efd6e,reason=Started count=1 msg=Started container task
60.2621,Event,ADDED,eval-sanitize-20-r3-041.18d41b3123a7cb70,reason=SuccessfulCreate count=1 msg=Created pod: eval-sanitize-20-r3-041-pdkzt
60.2623,Event,ADDED,eval-sanitize-20-r3-041.18d41b34162e061b,reason=Completed count=1 msg=Job completed
60.2632,Job,MODIFIED,eval-sanitize-20-r3-046,
60.2635,Event,ADDED,eval-sanitize-20-r3-042-p8bkn.18d41b31afbce0f4,reason=Scheduled count=None msg=Successfully assigned compute/eval-sanitize-20-r3-042-p8bkn to kind-worker3
60.2637,Event,ADDED,eval-sanitize-20-r3-042-p8bkn.18d41b31c8fde0d5,"reason=Pulled count=1 msg=Container image ""busybox:musl"" already present on machine"
60.2638,Event,ADDED,eval-sanitize-20-r3-042-p8bkn.18d41b31ca487d67,reason=Created count=1 msg=Created container: task
60.2651,Job,MODIFIED,eval-sanitize-20-r3-046,
60.2653,Event,ADDED,eval-sanitize-20-r3-042-p8bkn.18d41b31cd3b8dc2,reason=Started count=1 msg=Started container task
60.2656,Event,ADDED,eval-sanitize-20-r3-042.18d41b31a978682d,reason=SuccessfulCreate count=1 msg=Created pod: eval-sanitize-20-r3-042-p8bkn
60.2658,Event,ADDED,eval-sanitize-20-r3-042.18d41b34ec52836f,reason=Completed count=1 msg=Job completed
60.2659,Event,ADDED,eval-sanitize-20-r3-043-zkwvs.18d41b31f7e632f3,reason=Scheduled count=None msg=Successfully assigned compute/eval-sanitize-20-r3-043-zkwvs to kind-worker3
60.2662,Event,ADDED,eval-sanitize-20-r3-043-zkwvs.18d41b320f99d2a9,"reason=Pulled count=1 msg=Container image ""busybox:musl"" already present on machine"
60.2664,Event,ADDED,eval-sanitize-20-r3-043-zkwvs.18d41b3210cc2165,reason=Created count=1 msg=Created container: task
60.2666,Event,ADDED,eval-sanitize-20-r3-043-zkwvs.18d41b3212e45754,reason=Started count=1 msg=Started container task
60.2668,Event,ADDED,eval-sanitize-20-r3-043.18d41b31f694fa72,reason=SuccessfulCreate count=1 msg=Created pod: eval-sanitize-20-r3-043-zkwvs
60.2671,Event,ADDED,eval-sanitize-20-r3-043.18d41b35282378da,reason=Completed count=1 msg=Job completed
60.2673,Event,ADDED,eval-sanitize-20-r3-044-s9w22.18d41b3222705818,reason=Scheduled count=None msg=Successfully assigned compute/eval-sanitize-20-r3-044-s9w22 to kind-worker
60.2675,Event,ADDED,eval-sanitize-20-r3-044-s9w22.18d41b323b186c6d,"reason=Pulled count=1 msg=Container image ""busybox:musl"" already present on machine"
60.268,Event,ADDED,eval-sanitize-20-r3-044-s9w22.18d41b323c58c3c5,reason=Created count=1 msg=Created container: task
60.2684,Event,ADDED,eval-sanitize-20-r3-044-s9w22.18d41b323ea44ebd,reason=Started count=1 msg=Started container task
60.2686,Event,ADDED,eval-sanitize-20-r3-044.18d41b32211a6677,reason=SuccessfulCreate count=1 msg=Created pod: eval-sanitize-20-r3-044-s9w22
60.2688,Event,ADDED,eval-sanitize-20-r3-044.18d41b356ddf3f75,reason=Completed count=1 msg=Job completed
60.2691,Event,ADDED,eval-sanitize-20-r3-045-r687p.18d41b3260f25a3f,reason=Scheduled count=None msg=Successfully assigned compute/eval-sanitize-20-r3-045-r687p to kind-worker2
60.2693,Event,ADDED,eval-sanitize-20-r3-045-r687p.18d41b327b6d56bc,"reason=Pulled count=1 msg=Container image ""busybox:musl"" already present on machine"
60.2695,Event,ADDED,eval-sanitize-20-r3-045-r687p.18d41b327c7c69e0,reason=Created count=1 msg=Created container: task
60.2698,Event,ADDED,eval-sanitize-20-r3-045-r687p.18d41b328099fe1d,reason=Started count=1 msg=Started container task
60.27,Event,ADDED,eval-sanitize-20-r3-045.18d41b325fa88529,reason=SuccessfulCreate count=1 msg=Created pod: eval-sanitize-20-r3-045-r687p
60.2702,Event,ADDED,eval-sanitize-20-r3-046-vwfpx.18d41b3296aad35f,reason=Scheduled count=None msg=Successfully assigned compute/eval-sanitize-20-r3-046-vwfpx to kind-worker5
60.2704,Event,ADDED,eval-sanitize-20-r3-046-vwfpx.18d41b32b1c8f04a,"reason=Pulled count=1 msg=Container image ""busybox:musl"" already present on machine"
60.2706,Event,ADDED,eval-sanitize-20-r3-046-vwfpx.18d41b32b2ee7d1f,reason=Created count=1 msg=Created container: task
60.2708,Event,ADDED,eval-sanitize-20-r3-046-vwfpx.18d41b32b72bc922,reason=Started count=1 msg=Started container task
60.271,Event,ADDED,eval-sanitize-20-r3-046.18d41b32955a32c9,reason=SuccessfulCreate count=1 msg=Created pod: eval-sanitize-20-r3-046-vwfpx
60.2712,Event,ADDED,eval-sanitize-20-r3-047-zd5js.18d41b32b361b42d,reason=Scheduled count=None msg=Successfully assigned compute/eval-sanitize-20-r3-047-zd5js to kind-worker4
60.2716,Event,ADDED,eval-sanitize-20-r3-047-zd5js.18d41b32cef2d630,"reason=Pulled count=1 msg=Container image ""busybox:musl"" already present on machine"
60.2718,Event,ADDED,eval-sanitize-20-r3-047-zd5js.18d41b32d03b24c8,reason=Created count=1 msg=Created container: task
60.272,Event,ADDED,eval-sanitize-20-r3-047-zd5js.18d41b32d9d8dc3b,reason=Started count=1 msg=Started container task
60.2723,Event,ADDED,eval-sanitize-20-r3-047.18d41b32b2608e7d,reason=SuccessfulCreate count=1 msg=Created pod: eval-sanitize-20-r3-047-zd5js
60.2725,Event,ADDED,eval-sanitize-20-r3-048-vzkh2.18d41b32e3f705a1,reason=Scheduled count=None msg=Successfully assigned compute/eval-sanitize-20-r3-048-vzkh2 to kind-worker4
60.2727,Event,ADDED,eval-sanitize-20-r3-048-vzkh2.18d41b32fd9545be,"reason=Pulled count=1 msg=Container image ""busybox:musl"" already present on machine"
60.2729,Event,ADDED,eval-sanitize-20-r3-048-vzkh2.18d41b32feb934b1,reason=Created count=1 msg=Created container: task
60.2732,Event,ADDED,eval-sanitize-20-r3-048-vzkh2.18d41b33019f2680,reason=Started count=1 msg=Started container task
60.2734,Event,ADDED,eval-sanitize-20-r3-048.18d41b32e279599a,reason=SuccessfulCreate count=1 msg=Created pod: eval-sanitize-20-r3-048-vzkh2
60.2735,Event,ADDED,eval-sanitize-20-r3-049-fxkt7.18d41b33068b012b,"reason=FailedScheduling count=None msg=0/6 nodes are available: 1 c_wall violated: 2 conflicting context pair(s) with node memory, 5 node(s) had untolerated taint(s). no new claims to deallocate, preemption: 0/6 nodes are available: 1 No preemption victims found for incoming pod, 5 Preemption is not helpful for scheduling."
60.2739,Event,ADDED,eval-sanitize-20-r3-049-fxkt7.18d41b3306fdbb6a,"reason=FailedScheduling count=None msg=0/6 nodes are available: 1 c_wall violated: 2 conflicting context pair(s) with node memory, 5 node(s) had untolerated taint(s). no new claims to deallocate, preemption: 0/6 nodes are available: 1 No preemption victims found for incoming pod, 5 Preemption is not helpful for scheduling."
60.2741,Event,ADDED,eval-sanitize-20-r3-049.18d41b330655eab2,reason=SuccessfulCreate count=1 msg=Created pod: eval-sanitize-20-r3-049-fxkt7
60.2742,Event,ADDED,eval-sanitize-20-r3-050-lzwr9.18d41b3335ece8e6,"reason=FailedScheduling count=None msg=0/6 nodes are available: 1 c_wall violated: 1 conflicting context pair(s) with node memory, 5 node(s) had untolerated taint(s). no new claims to deallocate, preemption: 0/6 nodes are available: 1 No preemption victims found for incoming pod, 5 Preemption is not helpful for scheduling."
60.2746,Event,ADDED,eval-sanitize-20-r3-050-lzwr9.18d41b33366025d0,"reason=FailedScheduling count=None msg=0/6 nodes are available: 1 c_wall violated: 1 conflicting context pair(s) with node memory, 5 node(s) had untolerated taint(s). no new claims to deallocate, preemption: 0/6 nodes are available: 1 No preemption victims found for incoming pod, 5 Preemption is not helpful for scheduling."
60.2748,Event,ADDED,eval-sanitize-20-r3-050.18d41b3335b460e7,reason=SuccessfulCreate count=1 msg=Created pod: eval-sanitize-20-r3-050-lzwr9
60.275,Event,ADDED,eval-sanitize-20-r3-051-xgx9f.18d41b336c5e38d4,"reason=FailedScheduling count=None msg=0/6 nodes are available: 1 c_wall violated: 2 conflicting context pair(s) with node memory, 5 node(s) had untolerated taint(s). no new claims to deallocate, preemption: 0/6 nodes are available: 1 No preemption victims found for incoming pod, 5 Preemption is not helpful for scheduling."
60.2751,Event,ADDED,eval-sanitize-20-r3-051-xgx9f.18d41b336ce1c91e,"reason=FailedScheduling count=None msg=0/6 nodes are available: 1 c_wall violated: 2 conflicting context pair(s) with node memory, 5 node(s) had untolerated taint(s). no new claims to deallocate, preemption: 0/6 nodes are available: 1 No preemption victims found for incoming pod, 5 Preemption is not helpful for scheduling."
60.2755,Event,ADDED,eval-sanitize-20-r3-051-xgx9f.18d41b345888010e,"reason=FailedScheduling count=None msg=0/6 nodes are available: 1 c_wall violated: 3 conflicting context pair(s) with node memory, 5 node(s) had untolerated taint(s). no new claims to deallocate, preemption: 0/6 nodes are available: 1 No preemption victims found for incoming pod, 5 Preemption is not helpful for scheduling."
60.2757,Event,ADDED,eval-sanitize-20-r3-051.18d41b336c1c25f6,reason=SuccessfulCreate count=1 msg=Created pod: eval-sanitize-20-r3-051-xgx9f
60.2758,Event,ADDED,eval-sanitize-20-r3-052-j6284.18d41b33a7cfdfd6,"reason=FailedScheduling count=None msg=0/6 nodes are available: 1 c_wall violated: 1 conflicting context pair(s) with node memory, 5 node(s) had untolerated taint(s). no new claims to deallocate, preemption: 0/6 nodes are available: 1 No preemption victims found for incoming pod, 5 Preemption is not helpful for scheduling."
60.2762,Event,ADDED,eval-sanitize-20-r3-052-j6284.18d41b33a84654c1,"reason=FailedScheduling count=None msg=0/6 nodes are available: 1 c_wall violated: 1 conflicting context pair(s) with node memory, 5 node(s) had untolerated taint(s). no new claims to deallocate, preemption: 0/6 nodes are available: 1 No preemption victims found for incoming pod, 5 Preemption is not helpful for scheduling."
60.2764,Event,ADDED,eval-sanitize-20-r3-052.18d41b33a79947de,reason=SuccessfulCreate count=1 msg=Created pod: eval-sanitize-20-r3-052-j6284
60.2766,Event,ADDED,eval-sanitize-20-r3-053-ltx59.18d41b33dad03ac9,"reason=FailedScheduling count=None msg=0/6 nodes are available: 1 c_wall violated: 1 conflicting context pair(s) with node memory, 5 node(s) had untolerated taint(s). no new claims to deallocate, preemption: 0/6 nodes are available: 1 No preemption victims found for incoming pod, 5 Preemption is not helpful for scheduling."
60.2769,Event,ADDED,eval-sanitize-20-r3-053-ltx59.18d41b33db7f26c5,"reason=FailedScheduling count=None msg=0/6 nodes are available: 1 c_wall violated: 1 conflicting context pair(s) with node memory, 5 node(s) had untolerated taint(s). no new claims to deallocate, preemption: 0/6 nodes are available: 1 No preemption victims found for incoming pod, 5 Preemption is not helpful for scheduling."
60.2771,Event,ADDED,eval-sanitize-20-r3-053.18d41b33da8c0e8b,reason=SuccessfulCreate count=1 msg=Created pod: eval-sanitize-20-r3-053-ltx59
60.2773,Event,ADDED,eval-sanitize-20-r3-054-hfq7n.18d41b3416156ea0,"reason=FailedScheduling count=None msg=0/6 nodes are available: 1 c_wall violated: 2 conflicting context pair(s) with node memory, 5 node(s) had untolerated taint(s). no new claims to deallocate, preemption: 0/6 nodes are available: 1 No preemption victims found for incoming pod, 5 Preemption is not helpful for scheduling."
60.278,Event,ADDED,eval-sanitize-20-r3-054-hfq7n.18d41b34169f03f7,"reason=FailedScheduling count=None msg=0/6 nodes are available: 1 c_wall violated: 2 conflicting context pair(s) with node memory, 5 node(s) had untolerated taint(s). no new claims to deallocate, preemption: 0/6 nodes are available: 1 No preemption victims found for incoming pod, 5 Preemption is not helpful for scheduling."
60.2784,Event,ADDED,eval-sanitize-20-r3-054-hfq7n.18d41b3459019124,"reason=FailedScheduling count=None msg=0/6 nodes are available: 1 c_wall violated: 3 conflicting context pair(s) with node memory, 5 node(s) had untolerated taint(s). no new claims to deallocate, preemption: 0/6 nodes are available: 1 No preemption victims found for incoming pod, 5 Preemption is not helpful for scheduling."
60.2787,Event,ADDED,eval-sanitize-20-r3-054.18d41b3415d9fada,reason=SuccessfulCreate count=1 msg=Created pod: eval-sanitize-20-r3-054-hfq7n
60.279,Event,ADDED,eval-sanitize-20-r3-055-88wc4.18d41b34523efb63,reason=Scheduled count=None msg=Successfully assigned compute/eval-sanitize-20-r3-055-88wc4 to kind-worker4
60.2792,Event,ADDED,eval-sanitize-20-r3-055-88wc4.18d41b346d421572,"reason=Pulled count=1 msg=Container image ""busybox:musl"" already present on machine"
60.2794,Event,ADDED,eval-sanitize-20-r3-055-88wc4.18d41b346e5112bd,reason=Created count=1 msg=Created container: task
60.2795,Event,ADDED,eval-sanitize-20-r3-055-88wc4.18d41b3472d19512,reason=Started count=1 msg=Started container task
60.2798,Event,ADDED,eval-sanitize-20-r3-055.18d41b3451bbd950,reason=SuccessfulCreate count=1 msg=Created pod: eval-sanitize-20-r3-055-88wc4
60.28,Event,ADDED,eval-sanitize-20-r3-056-bmfg2.18d41b348d74c38e,"reason=FailedScheduling count=None msg=0/6 nodes are available: 1 c_wall violated: 3 conflicting context pair(s) with node memory, 5 node(s) had untolerated taint(s). no new claims to deallocate, preemption: 0/6 nodes are available: 1 No preemption victims found for incoming pod, 5 Preemption is not helpful for scheduling."
60.2802,Event,ADDED,eval-sanitize-20-r3-056-bmfg2.18d41b349045f0d4,"reason=FailedScheduling count=None msg=0/6 nodes are available: 1 c_wall violated: 3 conflicting context pair(s) with node memory, 5 node(s) had untolerated taint(s). no new claims to deallocate, preemption: 0/6 nodes are available: 1 No preemption victims found for incoming pod, 5 Preemption is not helpful for scheduling."
60.2805,Event,ADDED,eval-sanitize-20-r3-056.18d41b348d30abbf,reason=SuccessfulCreate count=1 msg=Created pod: eval-sanitize-20-r3-056-bmfg2
60.2807,Event,ADDED,eval-sanitize-20-r3-057-kjtnf.18d41b34c90c651c,"reason=FailedScheduling count=None msg=0/6 nodes are available: 1 c_wall violated: 2 conflicting context pair(s) with node memory, 5 node(s) had untolerated taint(s). no new claims to deallocate, preemption: 0/6 nodes are available: 1 No preemption victims found for incoming pod, 5 Preemption is not helpful for scheduling."
60.2809,Event,ADDED,eval-sanitize-20-r3-057-kjtnf.18d41b34c987ef74,"reason=FailedScheduling count=None msg=0/6 nodes are available: 1 c_wall violated: 2 conflicting context pair(s) with node memory, 5 node(s) had untolerated taint(s). no new claims to deallocate, preemption: 0/6 nodes are available: 1 No preemption victims found for incoming pod, 5 Preemption is not helpful for scheduling."
60.2813,Event,ADDED,eval-sanitize-20-r3-057.18d41b34c8ccf8da,reason=SuccessfulCreate count=1 msg=Created pod: eval-sanitize-20-r3-057-kjtnf
60.2815,Event,ADDED,eval-sanitize-20-r3-058-vjdj6.18d41b3504e9c9e3,reason=Scheduled count=None msg=Successfully assigned compute/eval-sanitize-20-r3-058-vjdj6 to kind-worker4
60.2817,Event,ADDED,eval-sanitize-20-r3-058-vjdj6.18d41b351edb2b7d,"reason=Pulled count=1 msg=Container image ""busybox:musl"" already present on machine"
60.2819,Event,ADDED,eval-sanitize-20-r3-058-vjdj6.18d41b3520053856,reason=Created count=1 msg=Created container: task
60.2823,Event,ADDED,eval-sanitize-20-r3-058-vjdj6.18d41b35222da186,reason=Started count=1 msg=Started container task
60.2825,Event,ADDED,eval-sanitize-20-r3-058.18d41b35045a62a9,reason=SuccessfulCreate count=1 msg=Created pod: eval-sanitize-20-r3-058-vjdj6
60.2827,Event,ADDED,eval-sanitize-20-r3-059-xwnbs.18d41b354564511d,reason=Scheduled count=None msg=Successfully assigned compute/eval-sanitize-20-r3-059-xwnbs to kind-worker4
60.2831,Event,ADDED,eval-sanitize-20-r3-059-xwnbs.18d41b355e8bfd4a,"reason=Pulled count=1 msg=Container image ""busybox:musl"" already present on machine"
60.2833,Event,ADDED,eval-sanitize-20-r3-059-xwnbs.18d41b355f99e26d,reason=Created count=1 msg=Created container: task
60.2835,Event,ADDED,eval-sanitize-20-r3-059-xwnbs.18d41b3562da1b0d,reason=Started count=1 msg=Started container task
60.2837,Event,ADDED,eval-sanitize-20-r3-059.18d41b35403a82f3,reason=SuccessfulCreate count=1 msg=Created pod: eval-sanitize-20-r3-059-xwnbs
60.284,Event,ADDED,eval-sanitize-20-r3-060.18d41b357c2d455b,reason=SuccessfulCreate count=1 msg=Created pod: eval-sanitize-20-r3-060-898td
60.2842,Event,ADDED,eval-sanitize-20-r3-045.18d41b357cf6d92f,reason=Completed count=1 msg=Job completed
60.2844,Event,ADDED,eval-sanitize-20-r3-060-898td.18d41b357f5019c9,"reason=FailedScheduling count=None msg=0/6 nodes are available: 1 c_wall violated: 1 conflicting context pair(s) with node memory, 5 node(s) had untolerated taint(s). no new claims to deallocate, preemption: 0/6 nodes are available: 1 No preemption victims found for incoming pod, 5 Preemption is not helpful for scheduling."
60.2846,Event,ADDED,eval-sanitize-20-r3-060-898td.18d41b358494f8f2,"reason=FailedScheduling count=None msg=0/6 nodes are available: 1 c_wall violated: 1 conflicting context pair(s) with node memory, 5 node(s) had untolerated taint(s). no new claims to deallocate, preemption: 0/6 nodes are available: 1 No preemption victims found for incoming pod, 5 Preemption is not helpful for scheduling."
60.3087,Pod,MODIFIED,eval-sanitize-20-r3-046-vwfpx,phase=Succeeded node=kind-worker5
60.3238,Event,MODIFIED,eval-sanitize-20-r3-060-898td.18d41b358494f8f2,"reason=FailedScheduling count=None msg=0/6 nodes are available: 1 c_wall violated: 1 conflicting context pair(s) with node memory, 5 node(s) had untolerated taint(s). no new claims to deallocate, preemption: 0/6 nodes are available: 1 No preemption victims found for incoming pod, 5 Preemption is not helpful for scheduling."
61.0088,TaskRequest,ADDED,eval-sanitize-20-r3-061,phase=None job=None
61.0144,TaskRequest,MODIFIED,eval-sanitize-20-r3-061,phase=Pending job=None
61.0295,Job,ADDED,eval-sanitize-20-r3-061,
61.0337,Job,MODIFIED,eval-sanitize-20-r3-047,
61.0363,Job,MODIFIED,eval-sanitize-20-r3-048,
61.0378,TaskRequest,MODIFIED,eval-sanitize-20-r3-061,phase=Scheduled job=None
61.0392,Pod,ADDED,eval-sanitize-20-r3-061-5wthb,phase=Pending node=None
61.0426,Job,MODIFIED,eval-sanitize-20-r3-061,
61.0463,Pod,MODIFIED,eval-sanitize-20-r3-047-zd5js,phase=Succeeded node=kind-worker4
61.0464,TaskRequest,MODIFIED,eval-sanitize-20-r3-061,phase=Scheduled job=None
61.0478,Event,ADDED,eval-sanitize-20-r3-061.18d41b35b7730435,reason=SuccessfulCreate count=1 msg=Created pod: eval-sanitize-20-r3-061-5wthb
61.0488,Pod,MODIFIED,eval-sanitize-20-r3-061-5wthb,phase=Pending node=None
61.0496,Event,ADDED,eval-sanitize-20-r3-061-5wthb.18d41b35b7b9787a,"reason=FailedScheduling count=None msg=0/6 nodes are available: 1 c_wall violated: 2 conflicting context pair(s) with node memory, 5 node(s) had untolerated taint(s). no new claims to deallocate, preemption: 0/6 nodes are available: 1 No preemption victims found for incoming pod, 5 Preemption is not helpful for scheduling."
61.0504,Job,MODIFIED,eval-sanitize-20-r3-047,
61.0511,Job,MODIFIED,eval-sanitize-20-r3-048,
61.0517,Job,MODIFIED,eval-sanitize-20-r3-060,
61.0569,Event,ADDED,eval-sanitize-20-r3-061-5wthb.18d41b35b8463c68,"reason=FailedScheduling count=None msg=0/6 nodes are available: 1 c_wall violated: 2 conflicting context pair(s) with node memory, 5 node(s) had untolerated taint(s). no new claims to deallocate, preemption: 0/6 nodes are available: 1 No preemption victims found for incoming pod, 5 Preemption is not helpful for scheduling."
61.0608,Job,MODIFIED,eval-sanitize-20-r3-060,
61.1409,Pod,MODIFIED,eval-sanitize-20-r3-048-vzkh2,phase=Succeeded node=kind-worker4
61.1689,Event,MODIFIED,eval-sanitize-20-r3-061-5wthb.18d41b35b8463c68,"reason=FailedScheduling count=None msg=0/6 nodes are available: 1 c_wall violated: 2 conflicting context pair(s) with node memory, 5 node(s) had untolerated taint(s). no new claims to deallocate, preemption: 0/6 nodes are available: 1 No preemption victims found for incoming pod, 5 Preemption is not helpful for scheduling."
61.181,Job,MODIFIED,eval-sanitize-20-r3-046,
61.1891,Pod,MODIFIED,eval-sanitize-20-r3-046-vwfpx,phase=Succeeded node=kind-worker5
61.1901,Job,MODIFIED,eval-sanitize-20-r3-046,
62.0104,TaskRequest,ADDED,eval-sanitize-20-r3-062,phase=None job=None
62.0151,TaskRequest,MODIFIED,eval-sanitize-20-r3-062,phase=Pending job=None
62.0326,Job,ADDED,eval-sanitize-20-r3-062,
62.0512,Job,MODIFIED,eval-sanitize-20-r3-047,
62.0529,TaskRequest,MODIFIED,eval-sanitize-20-r3-062,phase=Scheduled job=None
62.054,Pod,ADDED,eval-sanitize-20-r3-062-jfhcb,phase=Pending node=None
62.055,Job,MODIFIED,eval-sanitize-20-r3-048,
62.0557,Job,MODIFIED,eval-sanitize-20-r3-062,
62.0564,Job,MODIFIED,eval-sanitize-20-r3-061,
62.0572,Job,MODIFIED,eval-sanitize-20-r3-047,
62.0581,Event,ADDED,eval-sanitize-20-r3-062.18d41b35f3f621bb,reason=SuccessfulCreate count=1 msg=Created pod: eval-sanitize-20-r3-062-jfhcb
62.0637,Pod,MODIFIED,eval-sanitize-20-r3-048-vzkh2,phase=Succeeded node=kind-worker4
62.0649,Event,ADDED,eval-sanitize-20-r3-047.18d41b35f426daed,reason=Completed count=1 msg=Job completed
62.0657,Pod,MODIFIED,eval-sanitize-20-r3-062-jfhcb,phase=Pending node=kind-worker4
62.0674,Job,MODIFIED,eval-sanitize-20-r3-047,
62.0675,TaskRequest,MODIFIED,eval-sanitize-20-r3-062,phase=Scheduled job=None
62.0711,Job,MODIFIED,eval-sanitize-20-r3-048,
62.0714,Event,ADDED,eval-sanitize-20-r3-062-jfhcb.18d41b35f4a6a272,reason=Scheduled count=None msg=Successfully assigned compute/eval-sanitize-20-r3-062-jfhcb to kind-worker4
62.0798,Event,ADDED,eval-sanitize-20-r3-048.18d41b35f50280f7,reason=Completed count=1 msg=Job completed
62.0814,Pod,MODIFIED,eval-sanitize-20-r3-062-jfhcb,phase=Pending node=kind-worker4
62.0825,Job,MODIFIED,eval-sanitize-20-r3-048,
62.1097,Job,MODIFIED,eval-sanitize-20-r3-061,
62.111,TaskRequest,MODIFIED,eval-sanitize-20-r3-048,phase=Complete job=None
62.1156,TaskRequest,MODIFIED,eval-sanitize-20-r3-047,phase=Complete job=None
62.1224,Job,MODIFIED,eval-sanitize-20-r3-048,
62.1259,Job,MODIFIED,eval-sanitize-20-r3-047,
62.1873,Job,MODIFIED,eval-sanitize-20-r3-046,
62.1934,Job,MODIFIED,eval-sanitize-20-r3-046,
62.1979,Event,ADDED,eval-sanitize-20-r3-046.18d41b35fc4075bd,reason=Completed count=1 msg=Job completed
62.2084,Job,MODIFIED,eval-sanitize-20-r3-046,
62.2139,TaskRequest,MODIFIED,eval-sanitize-20-r3-046,phase=Complete job=None
62.2255,Job,MODIFIED,eval-sanitize-20-r3-046,
62.5005,Event,ADDED,eval-sanitize-20-r3-062-jfhcb.18d41b360e4cac3e,"reason=Pulled count=1 msg=Container image ""busybox:musl"" already present on machine"
62.5193,Event,ADDED,eval-sanitize-20-r3-062-jfhcb.18d41b360f671685,reason=Created count=1 msg=Created container: task
62.5575,Event,ADDED,eval-sanitize-20-r3-062-jfhcb.18d41b3611b1139d,reason=Started count=1 msg=Started container task
63.0102,TaskRequest,ADDED,eval-sanitize-20-r3-063,phase=None job=None
63.0144,TaskRequest,MODIFIED,eval-sanitize-20-r3-063,phase=Pending job=None
63.0238,Pod,MODIFIED,eval-sanitize-20-r3-062-jfhcb,phase=Running node=kind-worker4
63.0311,Job,ADDED,eval-sanitize-20-r3-063,
63.0379,Pod,ADDED,eval-sanitize-20-r3-063-pt5lj,phase=Pending node=None
63.0397,Job,MODIFIED,eval-sanitize-20-r3-063,
63.0398,TaskRequest,MODIFIED,eval-sanitize-20-r3-063,phase=Scheduled job=None
63.0423,Event,ADDED,eval-sanitize-20-r3-063.18d41b362ea06866,reason=SuccessfulCreate count=1 msg=Created pod: eval-sanitize-20-r3-063-pt5lj
63.0469,Pod,MODIFIED,eval-sanitize-20-r3-063-pt5lj,phase=Pending node=kind-worker4
63.0474,TaskRequest,MODIFIED,eval-sanitize-20-r3-063,phase=Scheduled job=None
63.0513,Event,ADDED,eval-sanitize-20-r3-063-pt5lj.18d41b362f1e9355,reason=Scheduled count=None msg=Successfully assigned compute/eval-sanitize-20-r3-063-pt5lj to kind-worker4
63.0568,Pod,MODIFIED,eval-sanitize-20-r3-063-pt5lj,phase=Pending node=kind-worker4
63.0582,Job,MODIFIED,eval-sanitize-20-r3-062,
63.0663,Job,MODIFIED,eval-sanitize-20-r3-062,
63.4862,Event,ADDED,eval-sanitize-20-r3-063-pt5lj.18d41b364917789f,"reason=Pulled count=1 msg=Container image ""busybox:musl"" already present on machine"
63.5035,Event,ADDED,eval-sanitize-20-r3-063-pt5lj.18d41b364a29efd7,reason=Created count=1 msg=Created container: task
63.5366,Event,ADDED,eval-sanitize-20-r3-063-pt5lj.18d41b364c085354,reason=Started count=1 msg=Started container task
64.0079,TaskRequest,ADDED,eval-sanitize-20-r3-064,phase=None job=None
64.0116,TaskRequest,MODIFIED,eval-sanitize-20-r3-064,phase=Pending job=None
64.0276,Job,ADDED,eval-sanitize-20-r3-064,
64.0312,Pod,MODIFIED,eval-sanitize-20-r3-063-pt5lj,phase=Running node=kind-worker4
64.0352,Pod,ADDED,eval-sanitize-20-r3-064-fzdfm,phase=Pending node=None
64.0353,TaskRequest,MODIFIED,eval-sanitize-20-r3-064,phase=Scheduled job=None
64.0382,Job,MODIFIED,eval-sanitize-20-r3-064,
64.0409,Event,ADDED,eval-sanitize-20-r3-064.18d41b366a0c0236,reason=SuccessfulCreate count=1 msg=Created pod: eval-sanitize-20-r3-064-fzdfm
64.0443,Job,MODIFIED,eval-sanitize-20-r3-063,
64.0462,TaskRequest,MODIFIED,eval-sanitize-20-r3-064,phase=Scheduled job=None
64.0472,Pod,MODIFIED,eval-sanitize-20-r3-064-fzdfm,phase=Pending node=kind-worker4
64.0507,Event,ADDED,eval-sanitize-20-r3-064-fzdfm.18d41b366abfeab5,reason=Scheduled count=None msg=Successfully assigned compute/eval-sanitize-20-r3-064-fzdfm to kind-worker4
64.0546,Job,MODIFIED,eval-sanitize-20-r3-063,
64.057,Pod,MODIFIED,eval-sanitize-20-r3-064-fzdfm,phase=Pending node=kind-worker4
64.4774,Event,ADDED,eval-sanitize-20-r3-064-fzdfm.18d41b368430d43d,"reason=Pulled count=1 msg=Container image ""busybox:musl"" already present on machine"
64.4952,Event,ADDED,eval-sanitize-20-r3-064-fzdfm.18d41b3685404b11,reason=Created count=1 msg=Created container: task
64.5329,Event,ADDED,eval-sanitize-20-r3-064-fzdfm.18d41b36876fccaf,reason=Started count=1 msg=Started container task
65.0088,TaskRequest,ADDED,eval-sanitize-20-r3-065,phase=None job=None
65.0123,TaskRequest,MODIFIED,eval-sanitize-20-r3-065,phase=Pending job=None
65.0281,Job,ADDED,eval-sanitize-20-r3-065,
65.0311,Pod,MODIFIED,eval-sanitize-20-r3-064-fzdfm,phase=Running node=kind-worker4
65.0342,Pod,ADDED,eval-sanitize-20-r3-065-hkfwq,phase=Pending node=None
65.0345,TaskRequest,MODIFIED,eval-sanitize-20-r3-065,phase=Scheduled job=None
65.0392,Job,MODIFIED,eval-sanitize-20-r3-065,
65.0418,Event,ADDED,eval-sanitize-20-r3-065.18d41b36a5a00bee,reason=SuccessfulCreate count=1 msg=Created pod: eval-sanitize-20-r3-065-hkfwq
65.0428,Job,MODIFIED,eval-sanitize-20-r3-064,
65.0449,Pod,MODIFIED,eval-sanitize-20-r3-065-hkfwq,phase=Pending node=kind-worker4
65.045,TaskRequest,MODIFIED,eval-sanitize-20-r3-065,phase=Scheduled job=None
65.049,Event,ADDED,eval-sanitize-20-r3-065-hkfwq.18d41b36a63dc5dd,reason=Scheduled count=None msg=Successfully assigned compute/eval-sanitize-20-r3-065-hkfwq to kind-worker4
65.0529,Job,MODIFIED,eval-sanitize-20-r3-064,
65.0575,Pod,MODIFIED,eval-sanitize-20-r3-065-hkfwq,phase=Pending node=kind-worker4
65.4644,Event,ADDED,eval-sanitize-20-r3-065-hkfwq.18d41b36beff951b,"reason=Pulled count=1 msg=Container image ""busybox:musl"" already present on machine"
65.4816,Event,ADDED,eval-sanitize-20-r3-065-hkfwq.18d41b36c0114a95,reason=Created count=1 msg=Created container: task
65.5178,Event,ADDED,eval-sanitize-20-r3-065-hkfwq.18d41b36c224ab86,reason=Started count=1 msg=Started container task
66.0084,TaskRequest,ADDED,eval-sanitize-20-r3-066,phase=None job=None
66.012,TaskRequest,MODIFIED,eval-sanitize-20-r3-066,phase=Pending job=None
66.0305,Job,ADDED,eval-sanitize-20-r3-066,
66.036,Pod,MODIFIED,eval-sanitize-20-r3-055-88wc4,phase=Running node=kind-worker4
66.037,TaskRequest,MODIFIED,eval-sanitize-20-r3-066,phase=Scheduled job=None
66.0378,Pod,ADDED,eval-sanitize-20-r3-066-mxntj,phase=Pending node=None
66.0406,Job,MODIFIED,eval-sanitize-20-r3-065,
66.0422,Job,MODIFIED,eval-sanitize-20-r3-066,
66.0447,Event,ADDED,eval-sanitize-20-r3-066.18d41b36e1707a30,reason=SuccessfulCreate count=1 msg=Created pod: eval-sanitize-20-r3-066-mxntj
66.0461,Pod,MODIFIED,eval-sanitize-20-r3-065-hkfwq,phase=Running node=kind-worker4
66.0467,TaskRequest,MODIFIED,eval-sanitize-20-r3-066,phase=Scheduled job=None
66.0491,Event,ADDED,eval-sanitize-20-r3-066-mxntj.18d41b36e1cd8c37,"reason=FailedScheduling count=None msg=0/6 nodes are available: 1 c_wall violated: 1 conflicting context pair(s) with node memory, 5 node(s) had untolerated taint(s). no new claims to deallocate, preemption: 0/6 nodes are available: 1 No preemption victims found for incoming pod, 5 Preemption is not helpful for scheduling."
66.0499,Pod,MODIFIED,eval-sanitize-20-r3-066-mxntj,phase=Pending node=None
66.0505,Job,MODIFIED,eval-sanitize-20-r3-065,
66.1314,Event,ADDED,eval-sanitize-20-r3-066-mxntj.18d41b36e6b5a1e6,"reason=FailedScheduling count=None msg=0/6 nodes are available: 1 c_wall violated: 1 conflicting context pair(s) with node memory, 5 node(s) had untolerated taint(s). no new claims to deallocate, preemption: 0/6 nodes are available: 1 No preemption victims found for incoming pod, 5 Preemption is not helpful for scheduling."
67.0225,TaskRequest,ADDED,eval-sanitize-20-r3-067,phase=None job=None
67.0265,TaskRequest,MODIFIED,eval-sanitize-20-r3-067,phase=Pending job=None
67.0448,Job,MODIFIED,eval-sanitize-20-r3-055,
67.0465,Job,MODIFIED,eval-sanitize-20-r3-066,
67.0472,Job,ADDED,eval-sanitize-20-r3-067,
67.0483,Job,MODIFIED,eval-sanitize-20-r3-065,
67.0538,Pod,ADDED,eval-sanitize-20-r3-067-5kf4n,phase=Pending node=None
67.0544,TaskRequest,MODIFIED,eval-sanitize-20-r3-067,phase=Scheduled job=None
67.0582,Job,MODIFIED,eval-sanitize-20-r3-067,
67.0608,Event,ADDED,eval-sanitize-20-r3-067.18d41b371e003100,reason=SuccessfulCreate count=1 msg=Created pod: eval-sanitize-20-r3-067-5kf4n
67.0654,Pod,MODIFIED,eval-sanitize-20-r3-067-5kf4n,phase=Pending node=kind-worker4
67.0668,TaskRequest,MODIFIED,eval-sanitize-20-r3-067,phase=Scheduled job=None
67.0679,Job,MODIFIED,eval-sanitize-20-r3-055,
67.072,Job,MODIFIED,eval-sanitize-20-r3-066,
67.0723,Event,ADDED,eval-sanitize-20-r3-067-5kf4n.18d41b371eaf9fca,reason=Scheduled count=None msg=Successfully assigned compute/eval-sanitize-20-r3-067-5kf4n to kind-worker4
67.0734,Job,MODIFIED,eval-sanitize-20-r3-065,
67.0778,Pod,MODIFIED,eval-sanitize-20-r3-067-5kf4n,phase=Pending node=kind-worker4
67.1424,Event,MODIFIED,eval-sanitize-20-r3-066-mxntj.18d41b36e6b5a1e6,"reason=FailedScheduling count=None msg=0/6 nodes are available: 1 c_wall violated: 1 conflicting context pair(s) with node memory, 5 node(s) had untolerated taint(s). no new claims to deallocate, preemption: 0/6 nodes are available: 1 No preemption victims found for incoming pod, 5 Preemption is not helpful for scheduling."
67.1858,Pod,MODIFIED,eval-sanitize-20-r3-055-88wc4,phase=Succeeded node=kind-worker4
67.5026,Event,ADDED,eval-sanitize-20-r3-067-5kf4n.18d41b37387bdb3f,"reason=Pulled count=1 msg=Container image ""busybox:musl"" already present on machine"
67.5208,Event,ADDED,eval-sanitize-20-r3-067-5kf4n.18d41b3739936409,reason=Created count=1 msg=Created container: task
67.5578,Event,ADDED,eval-sanitize-20-r3-067-5kf4n.18d41b373bba5cc3,reason=Started count=1 msg=Started container task
67.967,Node,MODIFIED,kind-worker,taints=1
67.9804,Node,MODIFIED,kind-worker,taints=0
67.9897,Node,MODIFIED,kind-worker,taints=0
67.991,Pod,MODIFIED,eval-sanitize-20-r3-049-fxkt7,phase=Pending node=kind-worker
67.9986,Pod,MODIFIED,eval-sanitize-20-r3-050-lzwr9,phase=Pending node=None
67.9989,Event,ADDED,eval-sanitize-20-r3-049-fxkt7.18d41b3755da4c95,reason=Scheduled count=None msg=Successfully assigned compute/eval-sanitize-20-r3-049-fxkt7 to kind-worker
68.0023,Node,MODIFIED,kind-worker,taints=0
68.0046,Pod,MODIFIED,eval-sanitize-20-r3-049-fxkt7,phase=Pending node=kind-worker
68.0241,Node,MODIFIED,kind-worker,taints=0
68.0242,TaskRequest,ADDED,eval-sanitize-20-r3-068,phase=None job=None
68.0283,Pod,MODIFIED,eval-sanitize-20-r3-051-xgx9f,phase=Pending node=kind-worker
68.0284,TaskRequest,MODIFIED,eval-sanitize-20-r3-068,phase=Pending job=None
68.0317,Event,ADDED,eval-sanitize-20-r3-051-xgx9f.18d41b375815b257,reason=Scheduled count=None msg=Successfully assigned compute/eval-sanitize-20-r3-051-xgx9f to kind-worker
68.0382,Node,MODIFIED,kind-worker,taints=0
68.0409,Pod,MODIFIED,eval-sanitize-20-r3-051-xgx9f,phase=Pending node=kind-worker
68.0457,Pod,MODIFIED,eval-sanitize-20-r3-067-5kf4n,phase=Running node=kind-worker4
68.0467,Job,ADDED,eval-sanitize-20-r3-068,
68.049,Job,MODIFIED,eval-sanitize-20-r3-055,
68.0515,Pod,ADDED,eval-sanitize-20-r3-068-rcxxr,phase=Pending node=None
68.0539,TaskRequest,MODIFIED,eval-sanitize-20-r3-068,phase=Scheduled job=None
68.0574,Job,MODIFIED,eval-sanitize-20-r3-068,
68.0592,Pod,MODIFIED,eval-sanitize-20-r3-055-88wc4,phase=Succeeded node=kind-worker4
68.0595,Event,ADDED,eval-sanitize-20-r3-068.18d41b37597a8435,reason=SuccessfulCreate count=1 msg=Created pod: eval-sanitize-20-r3-068-rcxxr
68.061,Job,MODIFIED,eval-sanitize-20-r3-067,
68.062,Job,MODIFIED,eval-sanitize-20-r3-055,
68.0651,Node,MODIFIED,kind-worker,taints=0
68.0664,TaskRequest,MODIFIED,eval-sanitize-20-r3-068,phase=Scheduled job=None
68.0675,Job,MODIFIED,eval-sanitize-20-r3-068,
68.0686,Event,ADDED,eval-sanitize-20-r3-055.18d41b375a1aa031,reason=Completed count=1 msg=Job completed
68.0693,Job,MODIFIED,eval-sanitize-20-r3-067,
68.0732,Job,MODIFIED,eval-sanitize-20-r3-055,
68.0776,Node,MODIFIED,kind-worker4,taints=1
68.0792,Node,MODIFIED,kind-worker,taints=0
68.0888,Pod,MODIFIED,eval-sanitize-20-r3-066-mxntj,phase=Pending node=None
68.0967,Pod,MODIFIED,eval-sanitize-20-r3-068-rcxxr,phase=Pending node=None
68.1009,Event,ADDED,eval-sanitize-20-r3-068-rcxxr.18d41b375be4934d,"reason=FailedScheduling count=None msg=0/6 nodes are available: 1 c_wall violated: 1 conflicting context pair(s) with node memory, 5 node(s) had untolerated taint(s). no new claims to deallocate, preemption: 0/6 nodes are available: 1 No preemption victims found for incoming pod, 5 Preemption is not helpful for scheduling."
68.1065,TaskRequest,MODIFIED,eval-sanitize-20-r3-055,phase=Complete job=None
68.1109,Job,MODIFIED,eval-sanitize-20-r3-068,
68.1152,Job,MODIFIED,eval-sanitize-20-r3-055,
68.1254,Pod,MODIFIED,eval-sanitize-20-r3-053-ltx59,phase=Pending node=None
68.133,Pod,MODIFIED,eval-sanitize-20-r3-054-hfq7n,phase=Pending node=kind-worker
68.1363,Pod,MODIFIED,eval-sanitize-20-r3-056-bmfg2,phase=Pending node=kind-worker
68.1367,Event,ADDED,eval-sanitize-20-r3-054-hfq7n.18d41b375e561209,reason=Scheduled count=None msg=Successfully assigned compute/eval-sanitize-20-r3-054-hfq7n to kind-worker
68.1404,Pod,MODIFIED,eval-sanitize-20-r3-057-kjtnf,phase=Pending node=kind-worker
68.1408,Event,ADDED,eval-sanitize-20-r3-056-bmfg2.18d41b375e808cb1,reason=Scheduled count=None msg=Successfully assigned compute/eval-sanitize-20-r3-056-bmfg2 to kind-worker
68.1432,Event,ADDED,eval-sanitize-20-r3-057-kjtnf.18d41b375ec1ac81,reason=Scheduled count=None msg=Successfully assigned compute/eval-sanitize-20-r3-057-kjtnf to kind-worker
68.1469,Pod,MODIFIED,eval-sanitize-20-r3-054-hfq7n,phase=Pending node=kind-worker
68.153,Pod,MODIFIED,eval-sanitize-20-r3-057-kjtnf,phase=Pending node=kind-worker
68.1551,Node,MODIFIED,kind-worker,taints=0
68.1593,Pod,MODIFIED,eval-sanitize-20-r3-056-bmfg2,phase=Pending node=kind-worker
68.1617,Node,MODIFIED,kind-worker4,taints=1
68.1977,Pod,MODIFIED,eval-sanitize-20-r3-060-898td,phase=Pending node=None
68.2555,Pod,MODIFIED,eval-sanitize-20-r3-061-5wthb,phase=Pending node=kind-worker
68.2597,Event,ADDED,eval-sanitize-20-r3-050-lzwr9.18d41b3765668b64,"reason=FailedScheduling count=None msg=0/6 nodes are available: 1 c_wall violated: 2 conflicting context pair(s) with node memory, 5 node(s) had untolerated taint(s). no new claims to deallocate, preemption: 0/6 nodes are available: 1 No preemption victims found for incoming pod, 5 Preemption is not helpful for scheduling."
68.2607,Pod,MODIFIED,eval-sanitize-20-r3-050-lzwr9,phase=Pending node=None
68.261,Event,ADDED,eval-sanitize-20-r3-061-5wthb.18d41b3765a1ae5f,reason=Scheduled count=None msg=Successfully assigned compute/eval-sanitize-20-r3-061-5wthb to kind-worker
68.2688,Pod,MODIFIED,eval-sanitize-20-r3-061-5wthb,phase=Pending node=kind-worker
68.2781,Node,MODIFIED,kind-worker,taints=0
68.2974,Pod,MODIFIED,eval-sanitize-20-r3-066-mxntj,phase=Pending node=None
68.2977,Event,ADDED,eval-sanitize-20-r3-066-mxntj.18d41b3767d58331,"reason=FailedScheduling count=None msg=0/6 nodes are available: 1 c_wall violated: 2 conflicting context pair(s) with node memory, 5 node(s) had untolerated taint(s). no new claims to deallocate, preemption: 0/6 nodes are available: 1 No preemption victims found for incoming pod, 5 Preemption is not helpful for scheduling."
68.3064,Event,ADDED,eval-sanitize-20-r3-068-rcxxr.18d41b37685d6485,"reason=FailedScheduling count=None msg=0/6 nodes are available: 1 c_wall violated: 1 conflicting context pair(s) with node memory, 5 node(s) had untolerated taint(s). no new claims to deallocate, preemption: 0/6 nodes are available: 1 No preemption victims found for incoming pod, 5 Preemption is not helpful for scheduling."
68.3096,Pod,MODIFIED,eval-sanitize-20-r3-052-j6284,phase=Pending node=None
68.3177,Pod,MODIFIED,eval-sanitize-20-r3-053-ltx59,phase=Pending node=None
68.318,Event,ADDED,eval-sanitize-20-r3-053-ltx59.18d41b3769085a3b,"reason=FailedScheduling count=None msg=0/6 nodes are available: 1 c_wall violated: 3 conflicting context pair(s) with node memory, 5 node(s) had untolerated taint(s). no new claims to deallocate, preemption: 0/6 nodes are available: 1 No preemption victims found for incoming pod, 5 Preemption is not helpful for scheduling."
68.3261,Event,ADDED,eval-sanitize-20-r3-060-898td.18d41b376983db2b,"reason=FailedScheduling count=None msg=0/6 nodes are available: 1 c_wall violated: 3 conflicting context pair(s) with node memory, 5 node(s) had untolerated taint(s). no new claims to deallocate, preemption: 0/6 nodes are available: 1 No preemption victims found for incoming pod, 5 Preemption is not helpful for scheduling."
68.3274,Event,ADDED,eval-sanitize-20-r3-050-lzwr9.18d41b3769b00717,"reason=FailedScheduling count=None msg=0/6 nodes are available: 1 c_wall violated: 2 conflicting context pair(s) with node memory, 5 node(s) had untolerated taint(s). no new claims to deallocate, preemption: 0/6 nodes are available: 1 No preemption victims found for incoming pod, 5 Preemption is not helpful for scheduling."
68.3294,Event,ADDED,eval-sanitize-20-r3-066-mxntj.18d41b3769d9b1aa,"reason=FailedScheduling count=None msg=0/6 nodes are available: 1 c_wall violated: 2 conflicting context pair(s) with node memory, 5 node(s) had untolerated taint(s). no new claims to deallocate, preemption: 0/6 nodes are available: 1 No preemption victims found for incoming pod, 5 Preemption is not helpful for scheduling."
68.3512,Event,ADDED,eval-sanitize-20-r3-052-j6284.18d41b376b010872,"reason=FailedScheduling count=None msg=0/6 nodes are available: 1 c_wall violated: 2 conflicting context pair(s) with node memory, 5 node(s) had untolerated taint(s). no new claims to deallocate, preemption: 0/6 nodes are available: 1 No preemption victims found for incoming pod, 5 Preemption is not helpful for scheduling."
68.391,Event,ADDED,eval-sanitize-20-r3-053-ltx59.18d41b376d71b6aa,"reason=FailedScheduling count=None msg=0/6 nodes are available: 1 c_wall violated: 3 conflicting context pair(s) with node memory, 5 node(s) had untolerated taint(s). no new claims to deallocate, preemption: 0/6 nodes are available: 1 No preemption victims found for incoming pod, 5 Preemption is not helpful for scheduling."
68.4189,Event,ADDED,eval-sanitize-20-r3-049-fxkt7.18d41b376f188bb7,"reason=Pulled count=1 msg=Container image ""busybox:musl"" already present on machine"
68.4372,Event,ADDED,eval-sanitize-20-r3-049-fxkt7.18d41b37703a4ecf,reason=Created count=1 msg=Created container: task
68.4548,Event,ADDED,eval-sanitize-20-r3-051-xgx9f.18d41b3771202aca,"reason=Pulled count=1 msg=Container image ""busybox:musl"" already present on machine"
68.4721,Event,ADDED,eval-sanitize-20-r3-049-fxkt7.18d41b37724029bd,reason=Started count=1 msg=Started container task
68.489,Event,ADDED,eval-sanitize-20-r3-051-xgx9f.18d41b37734f8b16,reason=Created count=1 msg=Created container: task
68.5234,Event,ADDED,eval-sanitize-20-r3-051-xgx9f.18d41b3775512317,reason=Started count=1 msg=Started container task
68.5784,Node,MODIFIED,kind-worker3,taints=1
68.5787,Event,ADDED,eval-sanitize-20-r3-056-bmfg2.18d41b3778995483,"reason=Pulled count=1 msg=Container image ""busybox:musl"" already present on machine"
68.5848,Event,ADDED,eval-sanitize-20-r3-054-hfq7n.18d41b3778df368a,"reason=Pulled count=1 msg=Container image ""busybox:musl"" already present on machine"
68.589,Event,MODIFIED,eval-sanitize-20-r3-068-rcxxr.18d41b37685d6485,"reason=FailedScheduling count=None msg=0/6 nodes are available: 1 c_wall violated: 1 conflicting context pair(s) with node memory, 5 node(s) had untolerated taint(s). no new claims to deallocate, preemption: 0/6 nodes are available: 1 No preemption victims found for incoming pod, 5 Preemption is not helpful for scheduling."
68.5907,Event,MODIFIED,eval-sanitize-20-r3-060-898td.18d41b376983db2b,"reason=FailedScheduling count=None msg=0/6 nodes are available: 1 c_wall violated: 3 conflicting context pair(s) with node memory, 5 node(s) had untolerated taint(s). no new claims to deallocate, preemption: 0/6 nodes are available: 1 No preemption victims found for incoming pod, 5 Preemption is not helpful for scheduling."
68.5947,Event,MODIFIED,eval-sanitize-20-r3-050-lzwr9.18d41b3769b00717,"reason=FailedScheduling count=None msg=0/6 nodes are available: 1 c_wall violated: 2 conflicting context pair(s) with node memory, 5 node(s) had untolerated taint(s). no new claims to deallocate, preemption: 0/6 nodes are available: 1 No preemption victims found for incoming pod, 5 Preemption is not helpful for scheduling."
68.5974,Event,MODIFIED,eval-sanitize-20-r3-066-mxntj.18d41b3769d9b1aa,"reason=FailedScheduling count=None msg=0/6 nodes are available: 1 c_wall violated: 2 conflicting context pair(s) with node memory, 5 node(s) had untolerated taint(s). no new claims to deallocate, preemption: 0/6 nodes are available: 1 No preemption victims found for incoming pod, 5 Preemption is not helpful for scheduling."
68.6006,Event,MODIFIED,eval-sanitize-20-r3-052-j6284.18d41b376b010872,"reason=FailedScheduling count=None msg=0/6 nodes are available: 1 c_wall violated: 2 conflicting context pair(s) with node memory, 5 node(s) had untolerated taint(s). no new claims to deallocate, preemption: 0/6 nodes are available: 1 No preemption victims found for incoming pod, 5 Preemption is not helpful for scheduling."
68.6022,Event,MODIFIED,eval-sanitize-20-r3-053-ltx59.18d41b376d71b6aa,"reason=FailedScheduling count=None msg=0/6 nodes are available: 1 c_wall violated: 3 conflicting context pair(s) with node memory, 5 node(s) had untolerated taint(s). no new claims to deallocate, preemption: 0/6 nodes are available: 1 No preemption victims found for incoming pod, 5 Preemption is not helpful for scheduling."
68.6185,Event,ADDED,eval-sanitize-20-r3-056-bmfg2.18d41b377a661642,reason=Created count=1 msg=Created container: task
68.625,Event,ADDED,eval-sanitize-20-r3-054-hfq7n.18d41b377b6a3eaa,reason=Created count=1 msg=Created container: task
68.6445,Event,ADDED,eval-sanitize-20-r3-056-bmfg2.18d41b377c8aeb19,reason=Started count=1 msg=Started container task
68.6568,Event,ADDED,eval-sanitize-20-r3-057-kjtnf.18d41b377d53630f,"reason=Pulled count=1 msg=Container image ""busybox:musl"" already present on machine"
68.6625,Event,ADDED,eval-sanitize-20-r3-054-hfq7n.18d41b377d90ea77,reason=Started count=1 msg=Started container task
68.6673,Node,MODIFIED,kind-worker3,taints=0
68.6787,Node,MODIFIED,kind-worker3,taints=0
68.682,Pod,MODIFIED,eval-sanitize-20-r3-068-rcxxr,phase=Pending node=kind-worker3
68.6835,Event,ADDED,eval-sanitize-20-r3-061-5wthb.18d41b377ee04072,"reason=Pulled count=1 msg=Container image ""busybox:musl"" already present on machine"
68.6862,Event,ADDED,eval-sanitize-20-r3-068-rcxxr.18d41b377f0865e7,reason=Scheduled count=None msg=Successfully assigned compute/eval-sanitize-20-r3-068-rcxxr to kind-worker3
68.6907,Node,MODIFIED,kind-worker3,taints=0
68.6926,Event,ADDED,eval-sanitize-20-r3-057-kjtnf.18d41b377ee79070,reason=Created count=1 msg=Created container: task
68.6939,Pod,MODIFIED,eval-sanitize-20-r3-060-898td,phase=Pending node=None
68.6966,Pod,MODIFIED,eval-sanitize-20-r3-068-rcxxr,phase=Pending node=kind-worker3
68.7046,Pod,MODIFIED,eval-sanitize-20-r3-050-lzwr9,phase=Pending node=None
68.705,Event,ADDED,eval-sanitize-20-r3-061-5wthb.18d41b3780396b99,reason=Created count=1 msg=Created container: task
68.7167,Node,MODIFIED,kind-worker3,taints=0
68.7249,Pod,MODIFIED,eval-sanitize-20-r3-066-mxntj,phase=Pending node=None
68.7275,Node,MODIFIED,kind-worker3,taints=0
68.7812,Event,ADDED,eval-sanitize-20-r3-057-kjtnf.18d41b3784b6714e,reason=Started count=1 msg=Started container task
68.7846,Event,ADDED,eval-sanitize-20-r3-061-5wthb.18d41b3784b8bf95,reason=Started count=1 msg=Started container task
68.7923,Pod,MODIFIED,eval-sanitize-20-r3-052-j6284,phase=Pending node=None
68.8019,Pod,MODIFIED,eval-sanitize-20-r3-056-bmfg2,phase=Running node=kind-worker
68.8038,Pod,MODIFIED,eval-sanitize-20-r3-053-ltx59,phase=Pending node=None
68.8091,Pod,MODIFIED,eval-sanitize-20-r3-061-5wthb,phase=Running node=kind-worker
68.8146,Pod,MODIFIED,eval-sanitize-20-r3-049-fxkt7,phase=Running node=kind-worker
68.821,Pod,MODIFIED,eval-sanitize-20-r3-057-kjtnf,phase=Running node=kind-worker
68.8251,Event,ADDED,eval-sanitize-20-r3-060-898td.18d41b378752b423,"reason=FailedScheduling count=None msg=0/6 nodes are available: 1 c_wall violated: 1 conflicting context pair(s) with node memory, 1 c_wall violated: 3 conflicting context pair(s) with node memory, 4 node(s) had untolerated taint(s). no new claims to deallocate, preemption: 0/6 nodes are available: 2 No preemption victims found for incoming pod, 4 Preemption is not helpful for scheduling."
68.8279,Pod,MODIFIED,eval-sanitize-20-r3-054-hfq7n,phase=Running node=kind-worker
68.8343,Pod,MODIFIED,eval-sanitize-20-r3-051-xgx9f,phase=Running node=kind-worker
68.8974,Event,ADDED,eval-sanitize-20-r3-050-lzwr9.18d41b378b3ee835,"reason=FailedScheduling count=None msg=0/6 nodes are available: 1 c_wall violated: 1 conflicting context pair(s) with node memory, 1 c_wall violated: 2 conflicting context pair(s) with node memory, 4 node(s) had untolerated taint(s). no new claims to deallocate, preemption: 0/6 nodes are available: 2 No preemption victims found for incoming pod, 4 Preemption is not helpful for scheduling."
68.9,Event,ADDED,eval-sanitize-20-r3-066-mxntj.18d41b378b911b81,"reason=FailedScheduling count=None msg=0/6 nodes are available: 1 c_wall violated: 1 conflicting context pair(s) with node memory, 1 c_wall violated: 2 conflicting context pair(s) with node memory, 4 node(s) had untolerated taint(s). no new claims to deallocate, preemption: 0/6 nodes are available: 2 No preemption victims found for incoming pod, 4 Preemption is not helpful for scheduling."
68.9219,Event,ADDED,eval-sanitize-20-r3-052-j6284.18d41b378d117250,"reason=FailedScheduling count=None msg=0/6 nodes are available: 1 c_wall violated: 1 conflicting context pair(s) with node memory, 1 c_wall violated: 2 conflicting context pair(s) with node memory, 4 node(s) had untolerated taint(s). no new claims to deallocate, preemption: 0/6 nodes are available: 2 No preemption victims found for incoming pod, 4 Preemption is not helpful for scheduling."
68.9262,Event,ADDED,eval-sanitize-20-r3-053-ltx59.18d41b378d649f8b,"reason=FailedScheduling count=None msg=0/6 nodes are available: 1 c_wall violated: 1 conflicting context pair(s) with node memory, 1 c_wall violated: 3 conflicting context pair(s) with node memory, 4 node(s) had untolerated taint(s). no new claims to deallocate, preemption: 0/6 nodes are available: 2 No preemption victims found for incoming pod, 4 Preemption is not helpful for scheduling."
69.0008,Event,MODIFIED,eval-sanitize-20-r3-060-898td.18d41b378752b423,"reason=FailedScheduling count=None msg=0/6 nodes are available: 1 c_wall violated: 1 conflicting context pair(s) with node memory, 1 c_wall violated: 3 conflicting context pair(s) with node memory, 4 node(s) had untolerated taint(s). no new claims to deallocate, preemption: 0/6 nodes are available: 2 No preemption victims found for incoming pod, 4 Preemption is not helpful for scheduling."
69.004,Job,MODIFIED,eval-sanitize-20-r3-049,
69.0044,Event,MODIFIED,eval-sanitize-20-r3-050-lzwr9.18d41b378b3ee835,"reason=FailedScheduling count=None msg=0/6 nodes are available: 1 c_wall violated: 1 conflicting context pair(s) with node memory, 1 c_wall violated: 2 conflicting context pair(s) with node memory, 4 node(s) had untolerated taint(s). no new claims to deallocate, preemption: 0/6 nodes are available: 2 No preemption victims found for incoming pod, 4 Preemption is not helpful for scheduling."
69.0066,TaskRequest,ADDED,eval-sanitize-20-r3-069,phase=None job=None
69.0115,TaskRequest,MODIFIED,eval-sanitize-20-r3-069,phase=Pending job=None
69.0144,Job,MODIFIED,eval-sanitize-20-r3-049,
69.0278,Job,ADDED,eval-sanitize-20-r3-069,
69.034,Job,MODIFIED,eval-sanitize-20-r3-051,
69.0365,TaskRequest,MODIFIED,eval-sanitize-20-r3-069,phase=Scheduled job=None
69.0374,Pod,ADDED,eval-sanitize-20-r3-069-75x4s,phase=Pending node=None
69.0398,Job,MODIFIED,eval-sanitize-20-r3-069,
69.0426,Event,ADDED,eval-sanitize-20-r3-069.18d41b37943af564,reason=SuccessfulCreate count=1 msg=Created pod: eval-sanitize-20-r3-069-75x4s
69.0464,TaskRequest,MODIFIED,eval-sanitize-20-r3-069,phase=Scheduled job=None
69.0495,Job,MODIFIED,eval-sanitize-20-r3-051,
69.0508,Pod,MODIFIED,eval-sanitize-20-r3-058-vjdj6,phase=Running node=kind-worker4
69.0585,Pod,MODIFIED,eval-sanitize-20-r3-069-75x4s,phase=Pending node=kind-worker3
69.062,Event,ADDED,eval-sanitize-20-r3-069-75x4s.18d41b3795823be1,reason=Scheduled count=None msg=Successfully assigned compute/eval-sanitize-20-r3-069-75x4s to kind-worker3
69.0684,Pod,MODIFIED,eval-sanitize-20-r3-069-75x4s,phase=Pending node=kind-worker3
69.0707,Node,MODIFIED,kind-worker3,taints=0
69.1002,Pod,MODIFIED,eval-sanitize-20-r3-066-mxntj,phase=Pending node=None
69.1011,Event,MODIFIED,eval-sanitize-20-r3-066-mxntj.18d41b378b911b81,"reason=FailedScheduling count=None msg=0/6 nodes are available: 1 c_wall violated: 1 conflicting context pair(s) with node memory, 1 c_wall violated: 2 conflicting context pair(s) with node memory, 4 node(s) had untolerated taint(s). no new claims to deallocate, preemption: 0/6 nodes are available: 2 No preemption victims found for incoming pod, 4 Preemption is not helpful for scheduling."
69.1121,Pod,MODIFIED,eval-sanitize-20-r3-052-j6284,phase=Pending node=None
69.1124,Event,MODIFIED,eval-sanitize-20-r3-052-j6284.18d41b378d117250,"reason=FailedScheduling count=None msg=0/6 nodes are available: 1 c_wall violated: 1 conflicting context pair(s) with node memory, 1 c_wall violated: 2 conflicting context pair(s) with node memory, 4 node(s) had untolerated taint(s). no new claims to deallocate, preemption: 0/6 nodes are available: 2 No preemption victims found for incoming pod, 4 Preemption is not helpful for scheduling."
69.1297,Node,MODIFIED,kind-worker2,taints=1
69.131,Event,ADDED,eval-sanitize-20-r3-068-rcxxr.18d41b37994e91e2,"reason=Pulled count=1 msg=Container image ""busybox:musl"" already present on machine"
69.1325,Node,MODIFIED,kind-worker3,taints=0
69.1385,Job,MODIFIED,eval-sanitize-20-r3-054,
69.1422,Job,MODIFIED,eval-sanitize-20-r3-056,
69.1454,Job,MODIFIED,eval-sanitize-20-r3-057,
69.1485,Job,MODIFIED,eval-sanitize-20-r3-054,
69.1493,Event,ADDED,eval-sanitize-20-r3-068-rcxxr.18d41b379aafc12c,reason=Created count=1 msg=Created container: task
69.1541,Job,MODIFIED,eval-sanitize-20-r3-056,
69.1559,Job,MODIFIED,eval-sanitize-20-r3-057,
69.1939,Pod,MODIFIED,eval-sanitize-20-r3-053-ltx59,phase=Pending node=None
69.1942,Event,MODIFIED,eval-sanitize-20-r3-053-ltx59.18d41b378d649f8b,"reason=FailedScheduling count=None msg=0/6 nodes are available: 1 c_wall violated: 1 conflicting context pair(s) with node memory, 1 c_wall violated: 3 conflicting context pair(s) with node memory, 4 node(s) had untolerated taint(s). no new claims to deallocate, preemption: 0/6 nodes are available: 2 No preemption victims found for incoming pod, 4 Preemption is not helpful for scheduling."
69.2045,Pod,MODIFIED,eval-sanitize-20-r3-060-898td,phase=Pending node=None
69.2195,Node,MODIFIED,kind-worker2,taints=0
69.2224,Event,ADDED,eval-sanitize-20-r3-068-rcxxr.18d41b379ef7aad3,reason=Started count=1 msg=Started container task
69.2235,Pod,MODIFIED,eval-sanitize-20-r3-050-lzwr9,phase=Pending node=None
69.228,Node,MODIFIED,kind-worker2,taints=0
69.2398,Node,MODIFIED,kind-worker2,taints=0
69.2606,Job,MODIFIED,eval-sanitize-20-r3-061,
69.2682,Job,MODIFIED,eval-sanitize-20-r3-061,
69.2894,Pod,MODIFIED,eval-sanitize-20-r3-066-mxntj,phase=Pending node=kind-worker2
69.2929,Event,ADDED,eval-sanitize-20-r3-066-mxntj.18d41b37a33ed809,reason=Scheduled count=None msg=Successfully assigned compute/eval-sanitize-20-r3-066-mxntj to kind-worker2
69.2998,Node,MODIFIED,kind-worker2,taints=0
69.3024,Pod,MODIFIED,eval-sanitize-20-r3-066-mxntj,phase=Pending node=kind-worker2
69.3101,Node,MODIFIED,kind-worker2,taints=0
69.3227,Pod,MODIFIED,eval-sanitize-20-r3-052-j6284,phase=Pending node=kind-worker2
69.3314,Pod,MODIFIED,eval-sanitize-20-r3-052-j6284,phase=Pending node=kind-worker2
69.3493,Event,ADDED,eval-sanitize-20-r3-052-j6284.18d41b37a69e5b73,reason=Scheduled count=None msg=Successfully assigned compute/eval-sanitize-20-r3-052-j6284 to kind-worker2
69.3989,Pod,MODIFIED,eval-sanitize-20-r3-053-ltx59,phase=Pending node=kind-worker2
69.4036,Event,ADDED,eval-sanitize-20-r3-053-ltx59.18d41b37a9c99e59,reason=Scheduled count=None msg=Successfully assigned compute/eval-sanitize-20-r3-053-ltx59 to kind-worker2
69.4129,Node,MODIFIED,kind-worker2,taints=0
69.4141,Pod,MODIFIED,eval-sanitize-20-r3-053-ltx59,phase=Pending node=kind-worker2
69.4237,Node,MODIFIED,kind-worker2,taints=0
69.4275,Pod,MODIFIED,eval-sanitize-20-r3-060-898td,phase=Pending node=kind-worker2
69.432,Event,ADDED,eval-sanitize-20-r3-060-898td.18d41b37ab776bf3,reason=Scheduled count=None msg=Successfully assigned compute/eval-sanitize-20-r3-060-898td to kind-worker2
69.4391,Pod,MODIFIED,eval-sanitize-20-r3-060-898td,phase=Pending node=kind-worker2
69.5082,Pod,MODIFIED,eval-sanitize-20-r3-050-lzwr9,phase=Pending node=kind-worker2
69.5118,Event,ADDED,eval-sanitize-20-r3-050-lzwr9.18d41b37b049a878,reason=Scheduled count=None msg=Successfully assigned compute/eval-sanitize-20-r3-050-lzwr9 to kind-worker2
69.52,Pod,MODIFIED,eval-sanitize-20-r3-050-lzwr9,phase=Pending node=kind-worker2
69.5322,Node,MODIFIED,kind-worker5,taints=1
69.5348,Event,ADDED,eval-sanitize-20-r3-069-75x4s.18d41b37b196671a,"reason=Pulled count=1 msg=Container image ""busybox:musl"" already present on machine"
69.5485,Node,MODIFIED,kind-worker5,taints=1
69.5559,Event,ADDED,eval-sanitize-20-r3-069-75x4s.18d41b37b2d2ab95,reason=Created count=1 msg=Created container: task
69.6188,Node,MODIFIED,kind-worker5,taints=0
69.6338,Node,MODIFIED,kind-worker5,taints=0
69.6409,Pod,MODIFIED,eval-sanitize-20-r3-068-rcxxr,phase=Running node=kind-worker3
69.6412,Event,ADDED,eval-sanitize-20-r3-069-75x4s.18d41b37b7e5acd5,reason=Started count=1 msg=Started container task
69.7416,Event,ADDED,eval-sanitize-20-r3-066-mxntj.18d41b37bdd1cd0d,"reason=Pulled count=1 msg=Container image ""busybox:musl"" already present on machine"
69.757,Event,ADDED,eval-sanitize-20-r3-052-j6284.18d41b37bee035dc,"reason=Pulled count=1 msg=Container image ""busybox:musl"" already present on machine"
69.7737,Event,ADDED,eval-sanitize-20-r3-066-mxntj.18d41b37bfe0efb4,reason=Created count=1 msg=Created container: task
69.7937,Event,ADDED,eval-sanitize-20-r3-052-j6284.18d41b37c101df6b,reason=Created count=1 msg=Created container: task
69.8528,Event,ADDED,eval-sanitize-20-r3-066-mxntj.18d41b37c4938f28,reason=Started count=1 msg=Started container task
69.8631,Event,ADDED,eval-sanitize-20-r3-052-j6284.18d41b37c52afe08,reason=Started count=1 msg=Started container task
69.8688,Event,ADDED,eval-sanitize-20-r3-053-ltx59.18d41b37c574bc17,"reason=Pulled count=1 msg=Container image ""busybox:musl"" already present on machine"
69.8744,Event,ADDED,eval-sanitize-20-r3-060-898td.18d41b37c5e5697e,"reason=Pulled count=1 msg=Container image ""busybox:musl"" already present on machine"
69.8929,Event,ADDED,eval-sanitize-20-r3-053-ltx59.18d41b37c6fbafc7,reason=Created count=1 msg=Created container: task
69.8994,Event,ADDED,eval-sanitize-20-r3-060-898td.18d41b37c75cdb3b,reason=Created count=1 msg=Created container: task
69.9067,Event,ADDED,eval-sanitize-20-r3-050-lzwr9.18d41b37c7ced985,"reason=Pulled count=1 msg=Container image ""busybox:musl"" already present on machine"
69.9311,Event,ADDED,eval-sanitize-20-r3-053-ltx59.18d41b37c91652d3,reason=Started count=1 msg=Started container task
69.9352,Event,ADDED,eval-sanitize-20-r3-050-lzwr9.18d41b37c916ad7e,reason=Created count=1 msg=Created container: task
69.9392,Event,ADDED,eval-sanitize-20-r3-060-898td.18d41b37c9719f45,reason=Started count=1 msg=Started container task
69.9742,Event,ADDED,eval-sanitize-20-r3-050-lzwr9.18d41b37cbd8f0ff,reason=Started count=1 msg=Started container task
70.0192,TaskRequest,ADDED,eval-sanitize-20-r3-070,phase=None job=None
70.0229,TaskRequest,MODIFIED,eval-sanitize-20-r3-070,phase=Pending job=None
70.0378,Job,ADDED,eval-sanitize-20-r3-070,
70.0421,Job,MODIFIED,eval-sanitize-20-r3-069,
70.0443,Pod,ADDED,eval-sanitize-20-r3-070-b2qnt,phase=Pending node=None
70.0456,TaskRequest,MODIFIED,eval-sanitize-20-r3-070,phase=Scheduled job=None
70.0462,Job,MODIFIED,eval-sanitize-20-r3-070,
70.0488,Event,ADDED,eval-sanitize-20-r3-070.18d41b37d03ebac4,reason=SuccessfulCreate count=1 msg=Created pod: eval-sanitize-20-r3-070-b2qnt
70.0566,Pod,MODIFIED,eval-sanitize-20-r3-059-xwnbs,phase=Running node=kind-worker4
70.0567,TaskRequest,MODIFIED,eval-sanitize-20-r3-070,phase=Scheduled job=None
70.0575,Job,MODIFIED,eval-sanitize-20-r3-058,
70.0595,Job,MODIFIED,eval-sanitize-20-r3-069,
70.0626,Pod,MODIFIED,eval-sanitize-20-r3-053-ltx59,phase=Running node=kind-worker2
70.0673,Pod,MODIFIED,eval-sanitize-20-r3-070-b2qnt,phase=Pending node=kind-worker5
70.0695,Job,MODIFIED,eval-sanitize-20-r3-058,
70.0755,Pod,MODIFIED,eval-sanitize-20-r3-052-j6284,phase=Running node=kind-worker2
70.0768,Event,ADDED,eval-sanitize-20-r3-070-b2qnt.18d41b37d19e08b5,reason=Scheduled count=None msg=Successfully assigned compute/eval-sanitize-20-r3-070-b2qnt to kind-worker5
70.0814,Node,MODIFIED,kind-worker5,taints=0
70.0828,Pod,MODIFIED,eval-sanitize-20-r3-070-b2qnt,phase=Pending node=kind-worker5
70.0857,Pod,MODIFIED,eval-sanitize-20-r3-060-898td,phase=Running node=kind-worker2
70.0921,Node,MODIFIED,kind-worker5,taints=0
70.094,Pod,MODIFIED,eval-sanitize-20-r3-050-lzwr9,phase=Running node=kind-worker2
70.101,Pod,MODIFIED,eval-sanitize-20-r3-066-mxntj,phase=Running node=kind-worker2
70.1043,Job,MODIFIED,eval-sanitize-20-r3-066,
70.1127,Job,MODIFIED,eval-sanitize-20-r3-066,
70.1525,Pod,MODIFIED,eval-sanitize-20-r3-058-vjdj6,phase=Succeeded node=kind-worker4
70.2128,Job,MODIFIED,eval-sanitize-20-r3-053,
70.2149,Job,MODIFIED,eval-sanitize-20-r3-060,
70.2216,Job,MODIFIED,eval-sanitize-20-r3-053,
70.2234,Job,MODIFIED,eval-sanitize-20-r3-060,
70.2275,Job,MODIFIED,eval-sanitize-20-r3-050,
70.2354,Job,MODIFIED,eval-sanitize-20-r3-050,
70.3415,Job,MODIFIED,eval-sanitize-20-r3-052,
70.3496,Job,MODIFIED,eval-sanitize-20-r3-052,
70.5245,Event,ADDED,eval-sanitize-20-r3-070-b2qnt.18d41b37ec95a72d,"reason=Pulled count=1 msg=Container image ""busybox:musl"" already present on machine"
70.5419,Event,ADDED,eval-sanitize-20-r3-070-b2qnt.18d41b37edb49131,reason=Created count=1 msg=Created container: task
70.5766,Event,ADDED,eval-sanitize-20-r3-070-b2qnt.18d41b37efa296f9,reason=Started count=1 msg=Started container task
70.6472,Pod,MODIFIED,eval-sanitize-20-r3-069-75x4s,phase=Running node=kind-worker3
70.6488,Job,MODIFIED,eval-sanitize-20-r3-068,
70.6574,Job,MODIFIED,eval-sanitize-20-r3-068,
71.0165,TaskRequest,ADDED,eval-sanitize-20-r3-071,phase=None job=None
71.0203,TaskRequest,MODIFIED,eval-sanitize-20-r3-071,phase=Pending job=None
71.0364,Job,ADDED,eval-sanitize-20-r3-071,
71.043,Pod,ADDED,eval-sanitize-20-r3-071-ngvkv,phase=Pending node=None
71.0451,TaskRequest,MODIFIED,eval-sanitize-20-r3-071,phase=Scheduled job=None
71.046,Job,MODIFIED,eval-sanitize-20-r3-071,
71.0483,Job,MODIFIED,eval-sanitize-20-r3-069,
71.0496,Event,ADDED,eval-sanitize-20-r3-071.18d41b380bc5f937,reason=SuccessfulCreate count=1 msg=Created pod: eval-sanitize-20-r3-071-ngvkv
71.0505,Job,MODIFIED,eval-sanitize-20-r3-070,
71.0542,TaskRequest,MODIFIED,eval-sanitize-20-r3-071,phase=Scheduled job=None
71.0587,Job,MODIFIED,eval-sanitize-20-r3-069,
71.0621,Job,MODIFIED,eval-sanitize-20-r3-070,
71.0628,Job,MODIFIED,eval-sanitize-20-r3-059,
71.064,Job,MODIFIED,eval-sanitize-20-r3-058,
71.0701,Pod,MODIFIED,eval-sanitize-20-r3-071-ngvkv,phase=Pending node=kind-worker3
71.0736,Pod,MODIFIED,eval-sanitize-20-r3-058-vjdj6,phase=Succeeded node=kind-worker4
71.074,Event,ADDED,eval-sanitize-20-r3-071-ngvkv.18d41b380d6423fd,reason=Scheduled count=None msg=Successfully assigned compute/eval-sanitize-20-r3-071-ngvkv to kind-worker3
71.0789,Job,MODIFIED,eval-sanitize-20-r3-058,
71.0841,Pod,MODIFIED,eval-sanitize-20-r3-071-ngvkv,phase=Pending node=kind-worker3
71.0845,Event,ADDED,eval-sanitize-20-r3-058.18d41b380de876fa,reason=Completed count=1 msg=Job completed
71.117,Job,MODIFIED,eval-sanitize-20-r3-059,
71.119,Job,MODIFIED,eval-sanitize-20-r3-058,
71.1228,TaskRequest,MODIFIED,eval-sanitize-20-r3-058,phase=Complete job=None
71.1325,Job,MODIFIED,eval-sanitize-20-r3-058,
71.1876,Pod,MODIFIED,eval-sanitize-20-r3-059-xwnbs,phase=Succeeded node=kind-worker4
71.1937,Pod,MODIFIED,eval-sanitize-20-r3-070-b2qnt,phase=Running node=kind-worker5
71.5038,Event,ADDED,eval-sanitize-20-r3-071-ngvkv.18d41b3826e7e30e,"reason=Pulled count=1 msg=Container image ""busybox:musl"" already present on machine"
71.5202,Event,ADDED,eval-sanitize-20-r3-071-ngvkv.18d41b3827fd606b,reason=Created count=1 msg=Created container: task
71.5596,Event,ADDED,eval-sanitize-20-r3-071-ngvkv.18d41b382a549689,reason=Started count=1 msg=Started container task
71.6436,Pod,MODIFIED,eval-sanitize-20-r3-071-ngvkv,phase=Running node=kind-worker3
72.0292,TaskRequest,ADDED,eval-sanitize-20-r3-072,phase=None job=None
72.034,TaskRequest,MODIFIED,eval-sanitize-20-r3-072,phase=Pending job=None
72.049,Job,MODIFIED,eval-sanitize-20-r3-071,
72.052,Job,ADDED,eval-sanitize-20-r3-072,
72.0579,TaskRequest,MODIFIED,eval-sanitize-20-r3-072,phase=Scheduled job=None
72.0588,Job,MODIFIED,eval-sanitize-20-r3-070,
72.0613,Pod,ADDED,eval-sanitize-20-r3-072-cst2r,phase=Pending node=None
72.0641,Job,MODIFIED,eval-sanitize-20-r3-072,
72.0684,Event,ADDED,eval-sanitize-20-r3-072.18d41b384871a65b,reason=SuccessfulCreate count=1 msg=Created pod: eval-sanitize-20-r3-072-cst2r
72.0699,Job,MODIFIED,eval-sanitize-20-r3-059,
72.0716,Job,MODIFIED,eval-sanitize-20-r3-071,
72.0724,Job,MODIFIED,eval-sanitize-20-r3-070,
72.0791,Pod,MODIFIED,eval-sanitize-20-r3-059-xwnbs,phase=Succeeded node=kind-worker4
72.0834,Job,MODIFIED,eval-sanitize-20-r3-059,
72.0867,Event,ADDED,eval-sanitize-20-r3-059.18d41b3849cbca0d,reason=Completed count=1 msg=Job completed
72.1182,Job,MODIFIED,eval-sanitize-20-r3-059,
72.125,Pod,MODIFIED,eval-sanitize-20-r3-072-cst2r,phase=Pending node=None
72.1263,Event,ADDED,eval-sanitize-20-r3-072-cst2r.18d41b384bea4d1d,"reason=FailedScheduling count=None msg=0/6 nodes are available: 1 c_wall violated: 2 conflicting context pair(s) with node memory, 2 node(s) had untolerated taint(s), 3 c_wall violated: 1 conflicting context pair(s) with node memory. no new claims to deallocate, preemption: 0/6 nodes are available: 2 Preemption is not helpful for scheduling, 4 No preemption victims found for incoming pod."
72.1268,TaskRequest,MODIFIED,eval-sanitize-20-r3-059,phase=Complete job=None
72.1268,TaskRequest,MODIFIED,eval-sanitize-20-r3-072,phase=Scheduled job=None
72.1383,Job,MODIFIED,eval-sanitize-20-r3-059,
72.2292,Event,ADDED,eval-sanitize-20-r3-072-cst2r.18d41b3851e66a2c,"reason=FailedScheduling count=None msg=0/6 nodes are available: 1 c_wall violated: 2 conflicting context pair(s) with node memory, 2 node(s) had untolerated taint(s), 3 c_wall violated: 1 conflicting context pair(s) with node memory. no new claims to deallocate, preemption: 0/6 nodes are available: 2 Preemption is not helpful for scheduling, 4 No preemption victims found for incoming pod."
73.0079,TaskRequest,ADDED,eval-sanitize-20-r3-073,phase=None job=None
73.0116,TaskRequest,MODIFIED,eval-sanitize-20-r3-073,phase=Pending job=None
73.0281,Job,ADDED,eval-sanitize-20-r3-073,
73.0323,TaskRequest,MODIFIED,eval-sanitize-20-r3-073,phase=Scheduled job=None
73.0358,Pod,ADDED,eval-sanitize-20-r3-073-srpdw,phase=Pending node=None
73.0377,Job,MODIFIED,eval-sanitize-20-r3-073,
73.0418,Event,ADDED,eval-sanitize-20-r3-073.18d41b388291875e,reason=SuccessfulCreate count=1 msg=Created pod: eval-sanitize-20-r3-073-srpdw
73.0419,TaskRequest,MODIFIED,eval-sanitize-20-r3-073,phase=Scheduled job=None
73.0602,Pod,MODIFIED,eval-sanitize-20-r3-073-srpdw,phase=Pending node=kind-worker3
73.0683,Job,MODIFIED,eval-sanitize-20-r3-072,
73.0686,Event,ADDED,eval-sanitize-20-r3-073-srpdw.18d41b3884027350,reason=Scheduled count=None msg=Successfully assigned compute/eval-sanitize-20-r3-073-srpdw to kind-worker3
73.0698,Pod,MODIFIED,eval-sanitize-20-r3-062-jfhcb,phase=Running node=kind-worker4
73.0711,Pod,MODIFIED,eval-sanitize-20-r3-073-srpdw,phase=Pending node=kind-worker3
73.0765,Job,MODIFIED,eval-sanitize-20-r3-072,
73.1578,Event,MODIFIED,eval-sanitize-20-r3-072-cst2r.18d41b3851e66a2c,"reason=FailedScheduling count=None msg=0/6 nodes are available: 1 c_wall violated: 2 conflicting context pair(s) with node memory, 2 node(s) had untolerated taint(s), 3 c_wall violated: 1 conflicting context pair(s) with node memory. no new claims to deallocate, preemption: 0/6 nodes are available: 2 Preemption is not helpful for scheduling, 4 No preemption victims found for incoming pod."
73.4868,Event,ADDED,eval-sanitize-20-r3-073-srpdw.18d41b389d159b48,"reason=Pulled count=1 msg=Container image ""busybox:musl"" already present on machine"
73.5068,Event,ADDED,eval-sanitize-20-r3-073-srpdw.18d41b389e4db676,reason=Created count=1 msg=Created container: task
73.5839,Event,ADDED,eval-sanitize-20-r3-073-srpdw.18d41b38a2fefd0a,reason=Started count=1 msg=Started container task
73.6594,Pod,MODIFIED,eval-sanitize-20-r3-073-srpdw,phase=Running node=kind-worker3
74.0085,TaskRequest,ADDED,eval-sanitize-20-r3-074,phase=None job=None
74.0123,TaskRequest,MODIFIED,eval-sanitize-20-r3-074,phase=Pending job=None
74.0285,Job,ADDED,eval-sanitize-20-r3-074,
74.0357,Pod,ADDED,eval-sanitize-20-r3-074-4q6rc,phase=Pending node=None
74.0379,Job,MODIFIED,eval-sanitize-20-r3-074,
74.038,TaskRequest,MODIFIED,eval-sanitize-20-r3-074,phase=Scheduled job=None
74.0429,Event,ADDED,eval-sanitize-20-r3-074.18d41b38be283c56,reason=SuccessfulCreate count=1 msg=Created pod: eval-sanitize-20-r3-074-4q6rc
74.0437,Job,MODIFIED,eval-sanitize-20-r3-073,
74.0459,TaskRequest,MODIFIED,eval-sanitize-20-r3-074,phase=Scheduled job=None
74.0523,Job,MODIFIED,eval-sanitize-20-r3-073,
74.0575,Pod,MODIFIED,eval-sanitize-20-r3-074-4q6rc,phase=Pending node=None
74.0583,Event,ADDED,eval-sanitize-20-r3-074-4q6rc.18d41b38bf2ee581,"reason=FailedScheduling count=None msg=0/6 nodes are available: 1 c_wall violated: 2 conflicting context pair(s) with node memory, 2 node(s) had untolerated taint(s), 3 c_wall violated: 1 conflicting context pair(s) with node memory. no new claims to deallocate, preemption: 0/6 nodes are available: 2 Preemption is not helpful for scheduling, 4 No preemption victims found for incoming pod."
74.0708,Pod,MODIFIED,eval-sanitize-20-r3-063-pt5lj,phase=Running node=kind-worker4
74.0738,Job,MODIFIED,eval-sanitize-20-r3-062,
74.0834,Job,MODIFIED,eval-sanitize-20-r3-062,
74.1294,Event,ADDED,eval-sanitize-20-r3-074-4q6rc.18d41b38c36701df,"reason=FailedScheduling count=None msg=0/6 nodes are available: 1 c_wall violated: 2 conflicting context pair(s) with node memory, 2 node(s) had untolerated taint(s), 3 c_wall violated: 1 conflicting context pair(s) with node memory. no new claims to deallocate, preemption: 0/6 nodes are available: 2 Preemption is not helpful for scheduling, 4 No preemption victims found for incoming pod."
74.192,Pod,MODIFIED,eval-sanitize-20-r3-062-jfhcb,phase=Succeeded node=kind-worker4
74.3261,Event,MODIFIED,eval-sanitize-20-r3-074-4q6rc.18d41b38c36701df,"reason=FailedScheduling count=None msg=0/6 nodes are available: 1 c_wall violated: 2 conflicting context pair(s) with node memory, 2 node(s) had untolerated taint(s), 3 c_wall violated: 1 conflicting context pair(s) with node memory. no new claims to deallocate, preemption: 0/6 nodes are available: 2 Preemption is not helpful for scheduling, 4 No preemption victims found for incoming pod."
75.0103,TaskRequest,ADDED,eval-sanitize-20-r3-075,phase=None job=None
75.0138,TaskRequest,MODIFIED,eval-sanitize-20-r3-075,phase=Pending job=None
75.0298,Job,ADDED,eval-sanitize-20-r3-075,
75.0346,TaskRequest,MODIFIED,eval-sanitize-20-r3-075,phase=Scheduled job=None
75.0401,Pod,ADDED,eval-sanitize-20-r3-075-n85xt,phase=Pending node=None
75.0441,Job,MODIFIED,eval-sanitize-20-r3-075,
75.045,Job,MODIFIED,eval-sanitize-20-r3-074,
75.0453,Event,ADDED,eval-sanitize-20-r3-075.18d41b38f9f75709,reason=SuccessfulCreate count=1 msg=Created pod: eval-sanitize-20-r3-075-n85xt
75.0466,TaskRequest,MODIFIED,eval-sanitize-20-r3-075,phase=Scheduled job=None
75.0536,Job,MODIFIED,eval-sanitize-20-r3-074,
75.0622,Pod,MODIFIED,eval-sanitize-20-r3-075-n85xt,phase=Pending node=kind-worker5
75.0751,Event,ADDED,eval-sanitize-20-r3-075-n85xt.18d41b38fb4b1b8d,reason=Scheduled count=None msg=Successfully assigned compute/eval-sanitize-20-r3-075-n85xt to kind-worker5
75.0785,Job,MODIFIED,eval-sanitize-20-r3-063,
75.0814,Job,MODIFIED,eval-sanitize-20-r3-062,
75.0829,Node,MODIFIED,kind-worker5,taints=0
75.0865,Pod,MODIFIED,eval-sanitize-20-r3-075-n85xt,phase=Pending node=kind-worker5
75.0881,Pod,MODIFIED,eval-sanitize-20-r3-064-fzdfm,phase=Running node=kind-worker4
75.0909,Pod,MODIFIED,eval-sanitize-20-r3-062-jfhcb,phase=Succeeded node=kind-worker4
75.0933,Job,MODIFIED,eval-sanitize-20-r3-063,
75.0945,Job,MODIFIED,eval-sanitize-20-r3-062,
75.0961,Node,MODIFIED,kind-worker5,taints=0
75.3017,Pod,MODIFIED,eval-sanitize-20-r3-063-pt5lj,phase=Succeeded node=kind-worker4
75.5015,Event,ADDED,eval-sanitize-20-r3-075-n85xt.18d41b3915481e9e,"reason=Pulled count=1 msg=Container image ""busybox:musl"" already present on machine"
75.52,Event,ADDED,eval-sanitize-20-r3-075-n85xt.18d41b391663871a,reason=Created count=1 msg=Created container: task
75.6187,Event,ADDED,eval-sanitize-20-r3-075-n85xt.18d41b391c39e04f,reason=Started count=1 msg=Started container task
76.0084,TaskRequest,ADDED,eval-sanitize-20-r3-076,phase=None job=None
76.0122,TaskRequest,MODIFIED,eval-sanitize-20-r3-076,phase=Pending job=None
76.0288,Job,ADDED,eval-sanitize-20-r3-076,
76.0356,Pod,ADDED,eval-sanitize-20-r3-076-jwx8r,phase=Pending node=None
76.0359,TaskRequest,MODIFIED,eval-sanitize-20-r3-076,phase=Scheduled job=None
76.0387,Job,MODIFIED,eval-sanitize-20-r3-076,
76.0431,Event,ADDED,eval-sanitize-20-r3-076.18d41b393562d43f,reason=SuccessfulCreate count=1 msg=Created pod: eval-sanitize-20-r3-076-jwx8r
76.0442,Job,MODIFIED,eval-sanitize-20-r3-075,
76.0444,TaskRequest,MODIFIED,eval-sanitize-20-r3-076,phase=Scheduled job=None
76.0545,Job,MODIFIED,eval-sanitize-20-r3-075,
76.0578,Pod,MODIFIED,eval-sanitize-20-r3-076-jwx8r,phase=Pending node=None
76.0581,Event,ADDED,eval-sanitize-20-r3-076-jwx8r.18d41b393664e5a3,"reason=FailedScheduling count=None msg=0/6 nodes are available: 1 c_wall violated: 2 conflicting context pair(s) with node memory, 2 node(s) had untolerated taint(s), 3 c_wall violated: 1 conflicting context pair(s) with node memory. no new claims to deallocate, preemption: 0/6 nodes are available: 2 Preemption is not helpful for scheduling, 4 No preemption victims found for incoming pod."
76.0855,Pod,MODIFIED,eval-sanitize-20-r3-065-hkfwq,phase=Running node=kind-worker4
76.0867,Job,MODIFIED,eval-sanitize-20-r3-063,
76.0875,Job,MODIFIED,eval-sanitize-20-r3-062,
76.0912,Job,MODIFIED,eval-sanitize-20-r3-062,
76.0933,Job,MODIFIED,eval-sanitize-20-r3-064,
76.0972,Pod,MODIFIED,eval-sanitize-20-r3-063-pt5lj,phase=Succeeded node=kind-worker4
76.0982,Event,ADDED,eval-sanitize-20-r3-062.18d41b3938b3bbd8,reason=Completed count=1 msg=Job completed
76.099,Job,MODIFIED,eval-sanitize-20-r3-063,
76.0999,Job,MODIFIED,eval-sanitize-20-r3-062,
76.1084,TaskRequest,MODIFIED,eval-sanitize-20-r3-062,phase=Complete job=None
76.1139,Job,MODIFIED,eval-sanitize-20-r3-064,
76.1173,Job,MODIFIED,eval-sanitize-20-r3-062,
76.1296,Event,ADDED,eval-sanitize-20-r3-076-jwx8r.18d41b393ab9c704,"reason=FailedScheduling count=None msg=0/6 nodes are available: 1 c_wall violated: 2 conflicting context pair(s) with node memory, 2 node(s) had untolerated taint(s), 3 c_wall violated: 1 conflicting context pair(s) with node memory. no new claims to deallocate, preemption: 0/6 nodes are available: 2 Preemption is not helpful for scheduling, 4 No preemption victims found for incoming pod."
76.1723,Pod,MODIFIED,eval-sanitize-20-r3-064-fzdfm,phase=Succeeded node=kind-worker4
76.2104,Pod,MODIFIED,eval-sanitize-20-r3-075-n85xt,phase=Running node=kind-worker5
76.4247,Event,MODIFIED,eval-sanitize-20-r3-076-jwx8r.18d41b393ab9c704,"reason=FailedScheduling count=None msg=0/6 nodes are available: 1 c_wall violated: 2 conflicting context pair(s) with node memory, 2 node(s) had untolerated taint(s), 3 c_wall violated: 1 conflicting context pair(s) with node memory. no new claims to deallocate, preemption: 0/6 nodes are available: 2 Preemption is not helpful for scheduling, 4 No preemption victims found for incoming pod."
77.0084,TaskRequest,ADDED,eval-sanitize-20-r3-077,phase=None job=None
77.0139,TaskRequest,MODIFIED,eval-sanitize-20-r3-077,phase=Pending job=None
77.0296,Job,ADDED,eval-sanitize-20-r3-077,
77.0354,TaskRequest,MODIFIED,eval-sanitize-20-r3-077,phase=Scheduled job=None
77.0385,Pod,ADDED,eval-sanitize-20-r3-077-fh6pf,phase=Pending node=None
77.0404,Job,MODIFIED,eval-sanitize-20-r3-077,
77.0428,Job,MODIFIED,eval-sanitize-20-r3-076,
77.0443,Event,ADDED,eval-sanitize-20-r3-077.18d41b3971269714,reason=SuccessfulCreate count=1 msg=Created pod: eval-sanitize-20-r3-077-fh6pf
77.0468,TaskRequest,MODIFIED,eval-sanitize-20-r3-077,phase=Scheduled job=None
77.0496,Job,MODIFIED,eval-sanitize-20-r3-075,
77.0518,Job,MODIFIED,eval-sanitize-20-r3-076,
77.0596,Job,MODIFIED,eval-sanitize-20-r3-075,
77.0643,Pod,MODIFIED,eval-sanitize-20-r3-077-fh6pf,phase=Pending node=kind-worker5
77.0698,Event,ADDED,eval-sanitize-20-r3-077-fh6pf.18d41b3972aeece9,reason=Scheduled count=None msg=Successfully assigned compute/eval-sanitize-20-r3-077-fh6pf to kind-worker5
77.077,Pod,MODIFIED,eval-sanitize-20-r3-077-fh6pf,phase=Pending node=kind-worker5
77.0921,Job,MODIFIED,eval-sanitize-20-r3-065,
77.0938,Job,MODIFIED,eval-sanitize-20-r3-063,
77.0982,Job,MODIFIED,eval-sanitize-20-r3-064,
77.1005,Job,MODIFIED,eval-sanitize-20-r3-063,
77.1026,Job,MODIFIED,eval-sanitize-20-r3-065,
77.1064,Event,ADDED,eval-sanitize-20-r3-063.18d41b3974de02b3,reason=Completed count=1 msg=Job completed
77.1115,Pod,MODIFIED,eval-sanitize-20-r3-064-fzdfm,phase=Succeeded node=kind-worker4
77.1131,Job,MODIFIED,eval-sanitize-20-r3-063,
77.1139,Job,MODIFIED,eval-sanitize-20-r3-064,
77.1197,TaskRequest,MODIFIED,eval-sanitize-20-r3-063,phase=Complete job=None
77.1296,Job,MODIFIED,eval-sanitize-20-r3-063,
77.239,Pod,MODIFIED,eval-sanitize-20-r3-065-hkfwq,phase=Succeeded node=kind-worker4
77.4935,Event,ADDED,eval-sanitize-20-r3-077-fh6pf.18d41b398bea1a74,"reason=Pulled count=1 msg=Container image ""busybox:musl"" already present on machine"
77.5113,Event,ADDED,eval-sanitize-20-r3-077-fh6pf.18d41b398d0ab118,reason=Created count=1 msg=Created container: task
77.5451,Event,ADDED,eval-sanitize-20-r3-077-fh6pf.18d41b398f00643d,reason=Started count=1 msg=Started container task
78.0084,TaskRequest,ADDED,eval-sanitize-20-r3-078,phase=None job=None
78.0137,TaskRequest,MODIFIED,eval-sanitize-20-r3-078,phase=Pending job=None
78.03,Job,ADDED,eval-sanitize-20-r3-078,
78.0356,Pod,ADDED,eval-sanitize-20-r3-078-qjcll,phase=Pending node=None
78.0375,TaskRequest,MODIFIED,eval-sanitize-20-r3-078,phase=Scheduled job=None
78.0405,Job,MODIFIED,eval-sanitize-20-r3-078,
78.0421,Event,ADDED,eval-sanitize-20-r3-078.18d41b39ac817f08,reason=SuccessfulCreate count=1 msg=Created pod: eval-sanitize-20-r3-078-qjcll
78.0448,Job,MODIFIED,eval-sanitize-20-r3-077,
78.0483,TaskRequest,MODIFIED,eval-sanitize-20-r3-078,phase=Scheduled job=None
78.0542,Job,MODIFIED,eval-sanitize-20-r3-077,
78.06,Pod,MODIFIED,eval-sanitize-20-r3-078-qjcll,phase=Pending node=kind-worker5
78.0638,Event,ADDED,eval-sanitize-20-r3-078-qjcll.18d41b39ade9e23f,reason=Scheduled count=None msg=Successfully assigned compute/eval-sanitize-20-r3-078-qjcll to kind-worker5
78.0699,Pod,MODIFIED,eval-sanitize-20-r3-078-qjcll,phase=Pending node=kind-worker5
78.0922,Pod,MODIFIED,eval-sanitize-20-r3-067-5kf4n,phase=Running node=kind-worker4
78.0982,Job,MODIFIED,eval-sanitize-20-r3-065,
78.103,Job,MODIFIED,eval-sanitize-20-r3-064,
78.1068,Pod,MODIFIED,eval-sanitize-20-r3-065-hkfwq,phase=Succeeded node=kind-worker4
78.1084,Job,MODIFIED,eval-sanitize-20-r3-065,
78.1094,Job,MODIFIED,eval-sanitize-20-r3-064,
78.1136,Event,ADDED,eval-sanitize-20-r3-064.18d41b39b0d81b2a,reason=Completed count=1 msg=Job completed
78.1187,Job,MODIFIED,eval-sanitize-20-r3-064,
78.123,TaskRequest,MODIFIED,eval-sanitize-20-r3-064,phase=Complete job=None
78.1331,Job,MODIFIED,eval-sanitize-20-r3-064,
78.2138,Pod,MODIFIED,eval-sanitize-20-r3-077-fh6pf,phase=Running node=kind-worker5
78.4821,Event,ADDED,eval-sanitize-20-r3-078-qjcll.18d41b39c6d73ac6,"reason=Pulled count=1 msg=Container image ""busybox:musl"" already present on machine"
78.5067,Event,ADDED,eval-sanitize-20-r3-078-qjcll.18d41b39c83ce2f4,reason=Created count=1 msg=Created container: task
78.651,Event,ADDED,eval-sanitize-20-r3-078-qjcll.18d41b39d0e9741d,reason=Started count=1 msg=Started container task
78.831,Pod,MODIFIED,eval-sanitize-20-r3-051-xgx9f,phase=Running node=kind-worker
78.8378,Pod,MODIFIED,eval-sanitize-20-r3-061-5wthb,phase=Running node=kind-worker
78.8448,Pod,MODIFIED,eval-sanitize-20-r3-049-fxkt7,phase=Running node=kind-worker
78.8521,Pod,MODIFIED,eval-sanitize-20-r3-057-kjtnf,phase=Running node=kind-worker
78.8583,Pod,MODIFIED,eval-sanitize-20-r3-054-hfq7n,phase=Running node=kind-worker
78.8642,Pod,MODIFIED,eval-sanitize-20-r3-056-bmfg2,phase=Running node=kind-worker
79.0295,TaskRequest,ADDED,eval-sanitize-20-r3-079,phase=None job=None
79.0339,TaskRequest,MODIFIED,eval-sanitize-20-r3-079,phase=Pending job=None
79.0415,Job,MODIFIED,eval-sanitize-20-r3-078,
79.0479,Job,ADDED,eval-sanitize-20-r3-079,
79.0502,Job,MODIFIED,eval-sanitize-20-r3-077,
79.0529,Pod,ADDED,eval-sanitize-20-r3-079-pkdp4,phase=Pending node=None
79.0548,TaskRequest,MODIFIED,eval-sanitize-20-r3-079,phase=Scheduled job=None
79.0575,Job,MODIFIED,eval-sanitize-20-r3-079,
79.0578,Event,ADDED,eval-sanitize-20-r3-079.18d41b39e922f857,reason=SuccessfulCreate count=1 msg=Created pod: eval-sanitize-20-r3-079-pkdp4
79.0629,TaskRequest,MODIFIED,eval-sanitize-20-r3-079,phase=Scheduled job=None
79.0657,Job,MODIFIED,eval-sanitize-20-r3-077,
79.0666,Job,MODIFIED,eval-sanitize-20-r3-078,
79.0971,Job,MODIFIED,eval-sanitize-20-r3-067,
79.1035,Job,MODIFIED,eval-sanitize-20-r3-065,
79.1063,Job,MODIFIED,eval-sanitize-20-r3-067,
79.1091,Job,MODIFIED,eval-sanitize-20-r3-065,
79.1152,Event,ADDED,eval-sanitize-20-r3-065.18d41b39ec7dd612,reason=Completed count=1 msg=Job completed
79.1207,Job,MODIFIED,eval-sanitize-20-r3-065,
79.1269,TaskRequest,MODIFIED,eval-sanitize-20-r3-065,phase=Complete job=None
79.1372,Job,MODIFIED,eval-sanitize-20-r3-065,
79.1822,Pod,MODIFIED,eval-sanitize-20-r3-067-5kf4n,phase=Succeeded node=kind-worker4
79.2131,Pod,MODIFIED,eval-sanitize-20-r3-078-qjcll,phase=Running node=kind-worker5
79.2349,Pod,MODIFIED,eval-sanitize-20-r3-079-pkdp4,phase=Pending node=kind-worker3
79.2419,Event,ADDED,eval-sanitize-20-r3-079-pkdp4.18d41b39f3f5efd2,reason=Scheduled count=None msg=Successfully assigned compute/eval-sanitize-20-r3-079-pkdp4 to kind-worker3
79.2482,Node,MODIFIED,kind-worker3,taints=0
79.2498,Pod,MODIFIED,eval-sanitize-20-r3-079-pkdp4,phase=Pending node=kind-worker3
79.2586,Node,MODIFIED,kind-worker3,taints=0
79.3296,Pod,MODIFIED,eval-sanitize-20-r3-074-4q6rc,phase=Pending node=None
79.4263,Pod,MODIFIED,eval-sanitize-20-r3-076-jwx8r,phase=Pending node=None
79.5233,Pod,MODIFIED,eval-sanitize-20-r3-072-cst2r,phase=Pending node=None
79.5424,Event,ADDED,eval-sanitize-20-r3-074-4q6rc.18d41b3a05f23982,"reason=FailedScheduling count=None msg=0/6 nodes are available: 2 c_wall violated: 1 conflicting context pair(s) with node memory, 2 c_wall violated: 2 conflicting context pair(s) with node memory, 2 node(s) had untolerated taint(s). no new claims to deallocate, preemption: 0/6 nodes are available: 2 Preemption is not helpful for scheduling, 4 No preemption victims found for incoming pod."
79.6313,Event,ADDED,eval-sanitize-20-r3-076-jwx8r.18d41b3a0b41c748,"reason=FailedScheduling count=None msg=0/6 nodes are available: 2 c_wall violated: 1 conflicting context pair(s) with node memory, 2 c_wall violated: 2 conflicting context pair(s) with node memory, 2 node(s) had untolerated taint(s). no new claims to deallocate, preemption: 0/6 nodes are available: 2 Preemption is not helpful for scheduling, 4 No preemption victims found for incoming pod."
79.6639,Pod,MODIFIED,eval-sanitize-20-r3-068-rcxxr,phase=Running node=kind-worker3
79.6643,Event,ADDED,eval-sanitize-20-r3-079-pkdp4.18d41b3a0d215d95,"reason=Pulled count=1 msg=Container image ""busybox:musl"" already present on machine"
79.6808,Event,ADDED,eval-sanitize-20-r3-079-pkdp4.18d41b3a0e406712,reason=Created count=1 msg=Created container: task
79.7287,Event,ADDED,eval-sanitize-20-r3-072-cst2r.18d41b3a1116d7dd,"reason=FailedScheduling count=None msg=0/6 nodes are available: 2 c_wall violated: 1 conflicting context pair(s) with node memory, 2 c_wall violated: 2 conflicting context pair(s) with node memory, 2 node(s) had untolerated taint(s). no new claims to deallocate, preemption: 0/6 nodes are available: 2 Preemption is not helpful for scheduling, 4 No preemption victims found for incoming pod."
79.7562,Event,ADDED,eval-sanitize-20-r3-079-pkdp4.18d41b3a12cabd99,reason=Started count=1 msg=Started container task
79.8247,Event,MODIFIED,eval-sanitize-20-r3-074-4q6rc.18d41b3a05f23982,"reason=FailedScheduling count=None msg=0/6 nodes are available: 2 c_wall violated: 1 conflicting context pair(s) with node memory, 2 c_wall violated: 2 conflicting context pair(s) with node memory, 2 node(s) had untolerated taint(s). no new claims to deallocate, preemption: 0/6 nodes are available: 2 Preemption is not helpful for scheduling, 4 No preemption victims found for incoming pod."
79.8364,Job,MODIFIED,eval-sanitize-20-r3-051,
79.8403,Event,MODIFIED,eval-sanitize-20-r3-076-jwx8r.18d41b3a0b41c748,"reason=FailedScheduling count=None msg=0/6 nodes are available: 2 c_wall violated: 1 conflicting context pair(s) with node memory, 2 c_wall violated: 2 conflicting context pair(s) with node memory, 2 node(s) had untolerated taint(s). no new claims to deallocate, preemption: 0/6 nodes are available: 2 Preemption is not helpful for scheduling, 4 No preemption victims found for incoming pod."
79.8441,Job,MODIFIED,eval-sanitize-20-r3-061,
79.8489,Job,MODIFIED,eval-sanitize-20-r3-051,
79.8516,Job,MODIFIED,eval-sanitize-20-r3-049,
79.8572,Job,MODIFIED,eval-sanitize-20-r3-061,
79.8592,Job,MODIFIED,eval-sanitize-20-r3-057,
79.8614,Job,MODIFIED,eval-sanitize-20-r3-049,
79.8648,Job,MODIFIED,eval-sanitize-20-r3-054,
79.869,Job,MODIFIED,eval-sanitize-20-r3-057,
79.8709,Job,MODIFIED,eval-sanitize-20-r3-056,
79.8734,Job,MODIFIED,eval-sanitize-20-r3-054,
79.8787,Job,MODIFIED,eval-sanitize-20-r3-056,
80.008,Pod,MODIFIED,eval-sanitize-20-r3-054-hfq7n,phase=Succeeded node=kind-worker
80.0081,TaskRequest,ADDED,eval-sanitize-20-r3-080,phase=None job=None
80.0112,TaskRequest,MODIFIED,eval-sanitize-20-r3-080,phase=Pending job=None
80.0212,Event,MODIFIED,eval-sanitize-20-r3-072-cst2r.18d41b3a1116d7dd,"reason=FailedScheduling count=None msg=0/6 nodes are available: 2 c_wall violated: 1 conflicting context pair(s) with node memory, 2 c_wall violated: 2 conflicting context pair(s) with node memory, 2 node(s) had untolerated taint(s). no new claims to deallocate, preemption: 0/6 nodes are available: 2 Preemption is not helpful for scheduling, 4 No preemption victims found for incoming pod."
80.0284,Job,ADDED,eval-sanitize-20-r3-080,
80.0372,Pod,ADDED,eval-sanitize-20-r3-080-grjrf,phase=Pending node=None
80.0402,Job,MODIFIED,eval-sanitize-20-r3-080,
80.0403,TaskRequest,MODIFIED,eval-sanitize-20-r3-080,phase=Scheduled job=None
80.0433,Event,ADDED,eval-sanitize-20-r3-080.18d41b3a23ca5a65,reason=SuccessfulCreate count=1 msg=Created pod: eval-sanitize-20-r3-080-grjrf
80.0473,Job,MODIFIED,eval-sanitize-20-r3-078,
80.0476,TaskRequest,MODIFIED,eval-sanitize-20-r3-080,phase=Scheduled job=None
80.0513,Pod,MODIFIED,eval-sanitize-20-r3-049-fxkt7,phase=Succeeded node=kind-worker
80.0586,Pod,MODIFIED,eval-sanitize-20-r3-057-kjtnf,phase=Succeeded node=kind-worker
80.0596,Job,MODIFIED,eval-sanitize-20-r3-078,
80.0603,Job,MODIFIED,eval-sanitize-20-r3-079,
80.065,Pod,MODIFIED,eval-sanitize-20-r3-056-bmfg2,phase=Succeeded node=kind-worker
80.071,Job,MODIFIED,eval-sanitize-20-r3-079,
80.0736,Pod,MODIFIED,eval-sanitize-20-r3-051-xgx9f,phase=Succeeded node=kind-worker
80.0817,Pod,MODIFIED,eval-sanitize-20-r3-061-5wthb,phase=Succeeded node=kind-worker
80.0926,Pod,MODIFIED,eval-sanitize-20-r3-053-ltx59,phase=Running node=kind-worker2
80.0986,Pod,MODIFIED,eval-sanitize-20-r3-052-j6284,phase=Running node=kind-worker2
80.1025,Job,MODIFIED,eval-sanitize-20-r3-067,
80.1053,Pod,MODIFIED,eval-sanitize-20-r3-060-898td,phase=Running node=kind-worker2
80.1105,Pod,MODIFIED,eval-sanitize-20-r3-067-5kf4n,phase=Succeeded node=kind-worker4
80.112,Job,MODIFIED,eval-sanitize-20-r3-067,
80.1361,Pod,MODIFIED,eval-sanitize-20-r3-080-grjrf,phase=Pending node=None
80.1365,Event,ADDED,eval-sanitize-20-r3-080-grjrf.18d41b3a295960fa,"reason=FailedScheduling count=None msg=0/6 nodes are available: 2 c_wall violated: 1 conflicting context pair(s) with node memory, 2 c_wall violated: 2 conflicting context pair(s) with node memory, 2 node(s) had untolerated taint(s). no new claims to deallocate, preemption: 0/6 nodes are available: 2 Preemption is not helpful for scheduling, 4 No preemption victims found for incoming pod."
80.5288,Event,ADDED,eval-sanitize-20-r3-080-grjrf.18d41b3a40897c3b,"reason=FailedScheduling count=None msg=0/6 nodes are available: 2 c_wall violated: 1 conflicting context pair(s) with node memory, 2 c_wall violated: 2 conflicting context pair(s) with node memory, 2 node(s) had untolerated taint(s). no new claims to deallocate, preemption: 0/6 nodes are available: 2 Preemption is not helpful for scheduling, 4 No preemption victims found for incoming pod."
80.6669,Pod,MODIFIED,eval-sanitize-20-r3-069-75x4s,phase=Running node=kind-worker3
80.6688,Job,MODIFIED,eval-sanitize-20-r3-068,
80.6746,Pod,MODIFIED,eval-sanitize-20-r3-079-pkdp4,phase=Running node=kind-worker3
80.6792,Job,MODIFIED,eval-sanitize-20-r3-068,
80.8022,Pod,MODIFIED,eval-sanitize-20-r3-068-rcxxr,phase=Succeeded node=kind-worker3
80.8443,Job,MODIFIED,eval-sanitize-20-r3-051,
80.8495,Job,MODIFIED,eval-sanitize-20-r3-061,
80.8543,Pod,MODIFIED,eval-sanitize-20-r3-051-xgx9f,phase=Succeeded node=kind-worker
80.8558,Job,MODIFIED,eval-sanitize-20-r3-051,
80.8578,Job,MODIFIED,eval-sanitize-20-r3-049,
80.8604,Job,MODIFIED,eval-sanitize-20-r3-061,
80.8617,Pod,MODIFIED,eval-sanitize-20-r3-061-5wthb,phase=Succeeded node=kind-worker
80.8649,Job,MODIFIED,eval-sanitize-20-r3-057,
80.8675,Pod,MODIFIED,eval-sanitize-20-r3-049-fxkt7,phase=Succeeded node=kind-worker
80.8702,Job,MODIFIED,eval-sanitize-20-r3-054,
80.8745,Job,MODIFIED,eval-sanitize-20-r3-049,
80.8778,Job,MODIFIED,eval-sanitize-20-r3-057,
80.8796,Pod,MODIFIED,eval-sanitize-20-r3-057-kjtnf,phase=Succeeded node=kind-worker
80.8804,Job,MODIFIED,eval-sanitize-20-r3-056,
80.8807,Event,ADDED,eval-sanitize-20-r3-049.18d41b3a55b60c62,reason=Completed count=1 msg=Job completed
80.8822,Pod,MODIFIED,eval-sanitize-20-r3-054-hfq7n,phase=Succeeded node=kind-worker
80.8831,Job,MODIFIED,eval-sanitize-20-r3-054,
80.8839,Job,MODIFIED,eval-sanitize-20-r3-049,
80.8888,Pod,MODIFIED,eval-sanitize-20-r3-056-bmfg2,phase=Succeeded node=kind-worker
80.8899,Job,MODIFIED,eval-sanitize-20-r3-056,
80.9082,TaskRequest,MODIFIED,eval-sanitize-20-r3-049,phase=Complete job=None
80.9178,Job,MODIFIED,eval-sanitize-20-r3-049,
80.9361,Event,MODIFIED,eval-sanitize-20-r3-080-grjrf.18d41b3a40897c3b,"reason=FailedScheduling count=None msg=0/6 nodes are available: 2 c_wall violated: 1 conflicting context pair(s) with node memory, 2 c_wall violated: 2 conflicting context pair(s) with node memory, 2 node(s) had untolerated taint(s). no new claims to deallocate, preemption: 0/6 nodes are available: 2 Preemption is not helpful for scheduling, 4 No preemption victims found for incoming pod."
81.0071,TaskRequest,ADDED,eval-sanitize-20-r3-081,phase=None job=None
81.0107,TaskRequest,MODIFIED,eval-sanitize-20-r3-081,phase=Pending job=None
81.027,Job,ADDED,eval-sanitize-20-r3-081,
81.0336,Pod,ADDED,eval-sanitize-20-r3-081-9q4t2,phase=Pending node=None
81.0337,TaskRequest,MODIFIED,eval-sanitize-20-r3-081,phase=Scheduled job=None
81.0363,Job,MODIFIED,eval-sanitize-20-r3-081,
81.0387,Event,ADDED,eval-sanitize-20-r3-081.18d41b3a5f30b90e,reason=SuccessfulCreate count=1 msg=Created pod: eval-sanitize-20-r3-081-9q4t2
81.0413,Job,MODIFIED,eval-sanitize-20-r3-080,
81.0415,TaskRequest,MODIFIED,eval-sanitize-20-r3-081,phase=Scheduled job=None
81.0501,Job,MODIFIED,eval-sanitize-20-r3-080,
81.0643,Job,MODIFIED,eval-sanitize-20-r3-079,
81.0726,Job,MODIFIED,eval-sanitize-20-r3-079,
81.1016,Job,MODIFIED,eval-sanitize-20-r3-053,
81.1059,Pod,MODIFIED,eval-sanitize-20-r3-066-mxntj,phase=Running node=kind-worker2
81.1067,Job,MODIFIED,eval-sanitize-20-r3-052,
81.1091,Job,MODIFIED,eval-sanitize-20-r3-067,
81.1108,Job,MODIFIED,eval-sanitize-20-r3-060,
81.1135,Job,MODIFIED,eval-sanitize-20-r3-067,
81.115,Pod,MODIFIED,eval-sanitize-20-r3-050-lzwr9,phase=Running node=kind-worker2
81.1169,Job,MODIFIED,eval-sanitize-20-r3-053,
81.1179,Job,MODIFIED,eval-sanitize-20-r3-052,
81.1204,Event,ADDED,eval-sanitize-20-r3-067.18d41b3a63f024ab,reason=Completed count=1 msg=Job completed
81.1257,Job,MODIFIED,eval-sanitize-20-r3-060,
81.1284,Job,MODIFIED,eval-sanitize-20-r3-067,
81.1334,TaskRequest,MODIFIED,eval-sanitize-20-r3-067,phase=Complete job=None
81.1438,Job,MODIFIED,eval-sanitize-20-r3-067,
81.2203,Pod,MODIFIED,eval-sanitize-20-r3-070-b2qnt,phase=Running node=kind-worker5
81.2342,Pod,MODIFIED,eval-sanitize-20-r3-081-9q4t2,phase=Pending node=kind-worker
81.239,Event,ADDED,eval-sanitize-20-r3-081-9q4t2.18d41b3a6b20b6de,reason=Scheduled count=None msg=Successfully assigned compute/eval-sanitize-20-r3-081-9q4t2 to kind-worker
81.2456,Pod,MODIFIED,eval-sanitize-20-r3-081-9q4t2,phase=Pending node=kind-worker
81.2552,Pod,MODIFIED,eval-sanitize-20-r3-052-j6284,phase=Succeeded node=kind-worker2
81.2994,Pod,MODIFIED,eval-sanitize-20-r3-053-ltx59,phase=Succeeded node=kind-worker2
81.3055,Pod,MODIFIED,eval-sanitize-20-r3-060-898td,phase=Succeeded node=kind-worker2
81.6501,Event,ADDED,eval-sanitize-20-r3-081-9q4t2.18d41b3a83b0b862,"reason=Pulled count=1 msg=Container image ""busybox:musl"" already present on machine"
81.6742,Pod,MODIFIED,eval-sanitize-20-r3-071-ngvkv,phase=Running node=kind-worker3
81.6745,Event,ADDED,eval-sanitize-20-r3-081-9q4t2.18d41b3a84df178e,reason=Created count=1 msg=Created container: task
81.6754,Job,MODIFIED,eval-sanitize-20-r3-069,
81.6779,Job,MODIFIED,eval-sanitize-20-r3-068,
81.6867,Job,MODIFIED,eval-sanitize-20-r3-069,
81.6895,Pod,MODIFIED,eval-sanitize-20-r3-068-rcxxr,phase=Succeeded node=kind-worker3
81.6929,Job,MODIFIED,eval-sanitize-20-r3-068,
81.7405,Event,ADDED,eval-sanitize-20-r3-081-9q4t2.18d41b3a8916da2f,reason=Started count=1 msg=Started container task
81.8212,Pod,MODIFIED,eval-sanitize-20-r3-069-75x4s,phase=Succeeded node=kind-worker3
81.8511,Job,MODIFIED,eval-sanitize-20-r3-051,
81.8543,Job,MODIFIED,eval-sanitize-20-r3-061,
81.8586,Pod,MODIFIED,eval-sanitize-20-r3-081-9q4t2,phase=Running node=kind-worker
81.8596,Job,MODIFIED,eval-sanitize-20-r3-051,
81.8609,Job,MODIFIED,eval-sanitize-20-r3-061,
81.8637,Event,ADDED,eval-sanitize-20-r3-051.18d41b3a90486add,reason=Completed count=1 msg=Job completed
81.8685,Job,MODIFIED,eval-sanitize-20-r3-051,
81.8701,Event,ADDED,eval-sanitize-20-r3-061.18d41b3a906e8d20,reason=Completed count=1 msg=Job completed
81.871,Job,MODIFIED,eval-sanitize-20-r3-057,
81.8728,Job,MODIFIED,eval-sanitize-20-r3-061,
81.8748,Job,MODIFIED,eval-sanitize-20-r3-054,
81.8769,Job,MODIFIED,eval-sanitize-20-r3-057,
81.877,TaskRequest,MODIFIED,eval-sanitize-20-r3-051,phase=Complete job=None
81.8789,Job,MODIFIED,eval-sanitize-20-r3-054,
81.8803,Event,ADDED,eval-sanitize-20-r3-057.18d41b3a91781c26,reason=Completed count=1 msg=Job completed
81.8831,Job,MODIFIED,eval-sanitize-20-r3-056,
81.8847,TaskRequest,MODIFIED,eval-sanitize-20-r3-061,phase=Complete job=None
81.8876,Event,ADDED,eval-sanitize-20-r3-054.18d41b3a91991094,reason=Completed count=1 msg=Job completed
81.8887,Job,MODIFIED,eval-sanitize-20-r3-051,
81.8912,Job,MODIFIED,eval-sanitize-20-r3-056,
81.8922,Job,MODIFIED,eval-sanitize-20-r3-057,
81.8949,Job,MODIFIED,eval-sanitize-20-r3-061,
81.8962,Event,ADDED,eval-sanitize-20-r3-056.18d41b3a925303d4,reason=Completed count=1 msg=Job completed
81.8971,Job,MODIFIED,eval-sanitize-20-r3-054,
81.9083,Job,MODIFIED,eval-sanitize-20-r3-056,
81.9761,TaskRequest,MODIFIED,eval-sanitize-20-r3-057,phase=Complete job=None
81.9802,TaskRequest,MODIFIED,eval-sanitize-20-r3-054,phase=Complete job=None
81.9853,TaskRequest,MODIFIED,eval-sanitize-20-r3-056,phase=Complete job=None
81.9884,Job,MODIFIED,eval-sanitize-20-r3-057,
81.99,Job,MODIFIED,eval-sanitize-20-r3-054,
81.9946,Job,MODIFIED,eval-sanitize-20-r3-056,
82.0077,TaskRequest,ADDED,eval-sanitize-20-r3-082,phase=None job=None
82.0113,TaskRequest,MODIFIED,eval-sanitize-20-r3-082,phase=Pending job=None
82.0397,Job,MODIFIED,eval-sanitize-20-r3-081,
82.0773,Job,ADDED,eval-sanitize-20-r3-082,
82.084,TaskRequest,MODIFIED,eval-sanitize-20-r3-082,phase=Scheduled job=None
82.0857,Pod,ADDED,eval-sanitize-20-r3-082-7mkd4,phase=Pending node=None
82.0895,Job,MODIFIED,eval-sanitize-20-r3-082,
82.0911,Event,ADDED,eval-sanitize-20-r3-082.18d41b3a9de910a6,reason=SuccessfulCreate count=1 msg=Created pod: eval-sanitize-20-r3-082-7mkd4
82.0945,Job,MODIFIED,eval-sanitize-20-r3-081,
82.1085,Job,MODIFIED,eval-sanitize-20-r3-053,
82.1126,Job,MODIFIED,eval-sanitize-20-r3-066,
82.1205,Job,MODIFIED,eval-sanitize-20-r3-053,
82.1234,Job,MODIFIED,eval-sanitize-20-r3-066,
82.1437,Job,MODIFIED,eval-sanitize-20-r3-052,
82.1766,Job,MODIFIED,eval-sanitize-20-r3-052,
82.1966,Pod,MODIFIED,eval-sanitize-20-r3-053-ltx59,phase=Succeeded node=kind-worker2
82.1987,Pod,MODIFIED,eval-sanitize-20-r3-066-mxntj,phase=Succeeded node=kind-worker2
82.2301,TaskRequest,MODIFIED,eval-sanitize-20-r3-082,phase=Scheduled job=None
82.2422,Job,MODIFIED,eval-sanitize-20-r3-060,
82.245,Pod,MODIFIED,eval-sanitize-20-r3-050-lzwr9,phase=Succeeded node=kind-worker2
82.2521,Job,MODIFIED,eval-sanitize-20-r3-060,
82.2926,Job,MODIFIED,eval-sanitize-20-r3-050,
82.3022,Job,MODIFIED,eval-sanitize-20-r3-050,
82.3304,Pod,MODIFIED,eval-sanitize-20-r3-082-7mkd4,phase=Pending node=kind-worker
82.3352,Event,ADDED,eval-sanitize-20-r3-082-7mkd4.18d41b3aac78b5be,reason=Scheduled count=None msg=Successfully assigned compute/eval-sanitize-20-r3-082-7mkd4 to kind-worker
82.3416,Pod,MODIFIED,eval-sanitize-20-r3-082-7mkd4,phase=Pending node=kind-worker
82.3461,Pod,MODIFIED,eval-sanitize-20-r3-052-j6284,phase=Succeeded node=kind-worker2
82.3584,Pod,MODIFIED,eval-sanitize-20-r3-070-b2qnt,phase=Succeeded node=kind-worker5
82.4426,Job,MODIFIED,eval-sanitize-20-r3-070,
82.4532,Job,MODIFIED,eval-sanitize-20-r3-070,
82.4972,Pod,MODIFIED,eval-sanitize-20-r3-060-898td,phase=Succeeded node=kind-worker2
82.6785,Job,MODIFIED,eval-sanitize-20-r3-071,
82.6917,Job,MODIFIED,eval-sanitize-20-r3-071,
82.6942,Job,MODIFIED,eval-sanitize-20-r3-069,
82.7038,Job,MODIFIED,eval-sanitize-20-r3-069,
82.7435,Job,MODIFIED,eval-sanitize-20-r3-068,
82.7522,Job,MODIFIED,eval-sanitize-20-r3-068,
82.8001,Pod,MODIFIED,eval-sanitize-20-r3-069-75x4s,phase=Succeeded node=kind-worker3
82.8337,Event,ADDED,eval-sanitize-20-r3-082-7mkd4.18d41b3aca3dadcc,"reason=Pulled count=1 msg=Container image ""busybox:musl"" already present on machine"
82.8521,Event,ADDED,eval-sanitize-20-r3-082-7mkd4.18d41b3acb5dbca1,reason=Created count=1 msg=Created container: task
82.9061,Pod,MODIFIED,eval-sanitize-20-r3-071-ngvkv,phase=Succeeded node=kind-worker3
82.9221,Event,ADDED,eval-sanitize-20-r3-082-7mkd4.18d41b3acf7f812b,reason=Started count=1 msg=Started container task
83.0085,TaskRequest,ADDED,eval-sanitize-20-r3-083,phase=None job=None
83.0121,TaskRequest,MODIFIED,eval-sanitize-20-r3-083,phase=Pending job=None
83.0284,Job,ADDED,eval-sanitize-20-r3-083,
83.0331,TaskRequest,MODIFIED,eval-sanitize-20-r3-083,phase=Scheduled job=None
83.0364,Pod,ADDED,eval-sanitize-20-r3-083-rwbk8,phase=Pending node=None
83.0388,Job,MODIFIED,eval-sanitize-20-r3-083,
83.0411,TaskRequest,MODIFIED,eval-sanitize-20-r3-083,phase=Scheduled job=None
83.0419,Event,ADDED,eval-sanitize-20-r3-083.18d41b3ad69350aa,reason=SuccessfulCreate count=1 msg=Created pod: eval-sanitize-20-r3-083-rwbk8
83.0926,Job,MODIFIED,eval-sanitize-20-r3-082,
83.1023,Job,MODIFIED,eval-sanitize-20-r3-082,
83.1435,Job,MODIFIED,eval-sanitize-20-r3-053,
83.153,Job,MODIFIED,eval-sanitize-20-r3-053,
83.1929,Job,MODIFIED,eval-sanitize-20-r3-066,
83.2028,Job,MODIFIED,eval-sanitize-20-r3-066,
83.2229,Pod,MODIFIED,eval-sanitize-20-r3-083-rwbk8,phase=Pending node=kind-worker2
83.2292,Event,ADDED,eval-sanitize-20-r3-083-rwbk8.18d41b3ae1acc893,reason=Scheduled count=None msg=Successfully assigned compute/eval-sanitize-20-r3-083-rwbk8 to kind-worker2
83.2348,Pod,MODIFIED,eval-sanitize-20-r3-083-rwbk8,phase=Pending node=kind-worker2
83.2932,Job,MODIFIED,eval-sanitize-20-r3-052,
83.3026,Job,MODIFIED,eval-sanitize-20-r3-052,
83.3483,Pod,MODIFIED,eval-sanitize-20-r3-066-mxntj,phase=Succeeded node=kind-worker2
83.3932,Job,MODIFIED,eval-sanitize-20-r3-060,
83.4036,Job,MODIFIED,eval-sanitize-20-r3-060,
83.444,Job,MODIFIED,eval-sanitize-20-r3-050,
83.4547,Job,MODIFIED,eval-sanitize-20-r3-050,
83.5949,Job,MODIFIED,eval-sanitize-20-r3-070,
83.6043,Job,MODIFIED,eval-sanitize-20-r3-070,
83.6958,Event,ADDED,eval-sanitize-20-r3-083-rwbk8.18d41b3afd81dd38,"reason=Pulled count=1 msg=Container image ""busybox:musl"" already present on machine"
83.6972,Pod,MODIFIED,eval-sanitize-20-r3-050-lzwr9,phase=Succeeded node=kind-worker2
83.713,Event,ADDED,eval-sanitize-20-r3-083-rwbk8.18d41b3afea2558b,reason=Created count=1 msg=Created container: task
83.7552,Pod,MODIFIED,eval-sanitize-20-r3-070-b2qnt,phase=Succeeded node=kind-worker5
83.7816,Event,ADDED,eval-sanitize-20-r3-083-rwbk8.18d41b3b02c0964b,reason=Started count=1 msg=Started container task
83.7924,Job,MODIFIED,eval-sanitize-20-r3-071,
83.8017,Job,MODIFIED,eval-sanitize-20-r3-071,
83.8426,Job,MODIFIED,eval-sanitize-20-r3-069,
83.8522,Job,MODIFIED,eval-sanitize-20-r3-069,
83.8608,Pod,MODIFIED,eval-sanitize-20-r3-082-7mkd4,phase=Running node=kind-worker
83.9434,Job,MODIFIED,eval-sanitize-20-r3-068,
83.9468,TaskRequest,MODIFIED,eval-sanitize-20-r3-068,phase=Complete job=None
83.9566,Job,MODIFIED,eval-sanitize-20-r3-068,
84.0087,TaskRequest,ADDED,eval-sanitize-20-r3-084,phase=None job=None
84.0126,TaskRequest,MODIFIED,eval-sanitize-20-r3-084,phase=Pending job=None
84.0292,Job,ADDED,eval-sanitize-20-r3-084,
84.0328,TaskRequest,MODIFIED,eval-sanitize-20-r3-084,phase=Scheduled job=None
84.0384,Job,MODIFIED,eval-sanitize-20-r3-084,
84.0394,TaskRequest,MODIFIED,eval-sanitize-20-r3-084,phase=Scheduled job=None
84.0445,Pod,MODIFIED,eval-sanitize-20-r3-071-ngvkv,phase=Succeeded node=kind-worker3
84.1165,Pod,MODIFIED,eval-sanitize-20-r3-083-rwbk8,phase=Running node=kind-worker2
84.1426,Event,ADDED,eval-sanitize-20-r3-068.18d41b3b0c9de641,reason=Completed count=1 msg=Job completed
84.1936,Pod,ADDED,eval-sanitize-20-r3-084-mrxnw,phase=Pending node=None
84.2369,Pod,MODIFIED,eval-sanitize-20-r3-084-mrxnw,phase=Pending node=kind-worker5
84.2427,Job,MODIFIED,eval-sanitize-20-r3-083,
84.2431,Event,ADDED,eval-sanitize-20-r3-084-mrxnw.18d41b3b1e1ac6af,reason=Scheduled count=None msg=Successfully assigned compute/eval-sanitize-20-r3-084-mrxnw to kind-worker5
84.248,Pod,MODIFIED,eval-sanitize-20-r3-084-mrxnw,phase=Pending node=kind-worker5
84.2529,Job,MODIFIED,eval-sanitize-20-r3-083,
84.3442,Job,MODIFIED,eval-sanitize-20-r3-082,
84.354,Job,MODIFIED,eval-sanitize-20-r3-082,
84.3944,Job,MODIFIED,eval-sanitize-20-r3-053,
84.3986,TaskRequest,MODIFIED,eval-sanitize-20-r3-053,phase=Complete job=None
84.4094,Job,MODIFIED,eval-sanitize-20-r3-053,
84.4924,Event,ADDED,eval-sanitize-20-r3-084.18d41b3b1b87404d,reason=SuccessfulCreate count=1 msg=Created pod: eval-sanitize-20-r3-084-mrxnw
84.5439,Job,MODIFIED,eval-sanitize-20-r3-066,
84.5551,Job,MODIFIED,eval-sanitize-20-r3-066,
84.5932,Job,MODIFIED,eval-sanitize-20-r3-052,
84.5978,TaskRequest,MODIFIED,eval-sanitize-20-r3-052,phase=Complete job=None
84.6076,Job,MODIFIED,eval-sanitize-20-r3-052,
84.6453,Job,MODIFIED,eval-sanitize-20-r3-060,
84.6492,TaskRequest,MODIFIED,eval-sanitize-20-r3-060,phase=Complete job=None
84.6602,Job,MODIFIED,eval-sanitize-20-r3-060,
84.664,Event,ADDED,eval-sanitize-20-r3-084-mrxnw.18d41b3b375dcd2d,"reason=Pulled count=1 msg=Container image ""busybox:musl"" already present on machine"
84.6827,Pod,MODIFIED,eval-sanitize-20-r3-073-srpdw,phase=Running node=kind-worker3
84.6835,Event,ADDED,eval-sanitize-20-r3-084-mrxnw.18d41b3b3882bf75,reason=Created count=1 msg=Created container: task
84.692,Job,MODIFIED,eval-sanitize-20-r3-050,
84.7014,Job,MODIFIED,eval-sanitize-20-r3-050,
84.7424,Event,ADDED,eval-sanitize-20-r3-053.18d41b3b2781f80d,reason=Completed count=1 msg=Job completed
84.7494,Event,ADDED,eval-sanitize-20-r3-084-mrxnw.18d41b3b3c69d3a4,reason=Started count=1 msg=Started container task
84.8445,Job,MODIFIED,eval-sanitize-20-r3-070,
84.8539,Job,MODIFIED,eval-sanitize-20-r3-070,
84.9427,Event,ADDED,eval-sanitize-20-r3-052.18d41b3b335a53ae,reason=Completed count=1 msg=Job completed
84.994,Job,MODIFIED,eval-sanitize-20-r3-071,
85.0045,Job,MODIFIED,eval-sanitize-20-r3-071,
85.0073,TaskRequest,ADDED,eval-sanitize-20-r3-085,phase=None job=None
85.0108,TaskRequest,MODIFIED,eval-sanitize-20-r3-085,phase=Pending job=None
85.0262,Job,ADDED,eval-sanitize-20-r3-085,
85.0303,TaskRequest,MODIFIED,eval-sanitize-20-r3-085,phase=Scheduled job=None
85.0347,Job,MODIFIED,eval-sanitize-20-r3-085,
85.0365,TaskRequest,MODIFIED,eval-sanitize-20-r3-085,phase=Scheduled job=None
85.041,Job,MODIFIED,eval-sanitize-20-r3-069,
85.044,TaskRequest,MODIFIED,eval-sanitize-20-r3-069,phase=Complete job=None
85.0623,Job,MODIFIED,eval-sanitize-20-r3-069,
85.1418,Event,ADDED,eval-sanitize-20-r3-060.18d41b3b36789c51,reason=Completed count=1 msg=Job completed
85.2339,Pod,MODIFIED,eval-sanitize-20-r3-084-mrxnw,phase=Running node=kind-worker5
85.2451,Pod,ADDED,eval-sanitize-20-r3-085-645dg,phase=Pending node=None
85.2935,Job,MODIFIED,eval-sanitize-20-r3-084,
85.3034,Job,MODIFIED,eval-sanitize-20-r3-084,
85.3383,Pod,MODIFIED,eval-sanitize-20-r3-085-645dg,phase=Pending node=kind-worker2
85.3453,Job,MODIFIED,eval-sanitize-20-r3-083,
85.3457,Event,ADDED,eval-sanitize-20-r3-085-645dg.18d41b3b5fc4ad5a,reason=Scheduled count=None msg=Successfully assigned compute/eval-sanitize-20-r3-085-645dg to kind-worker2
85.3506,Pod,MODIFIED,eval-sanitize-20-r3-085-645dg,phase=Pending node=kind-worker2
85.3548,Job,MODIFIED,eval-sanitize-20-r3-083,
85.394,Event,ADDED,eval-sanitize-20-r3-069.18d41b3b4e140604,reason=Completed count=1 msg=Job completed
85.4926,Event,ADDED,eval-sanitize-20-r3-085.18d41b3b5a3670d0,reason=SuccessfulCreate count=1 msg=Created pod: eval-sanitize-20-r3-085-645dg
85.5492,Job,MODIFIED,eval-sanitize-20-r3-066,
85.5539,TaskRequest,MODIFIED,eval-sanitize-20-r3-066,phase=Complete job=None
85.5646,Job,MODIFIED,eval-sanitize-20-r3-066,
85.5942,Event,ADDED,eval-sanitize-20-r3-066.18d41b3b6c55f713,reason=Completed count=1 msg=Job completed
85.6899,Job,MODIFIED,eval-sanitize-20-r3-073,
85.7001,Job,MODIFIED,eval-sanitize-20-r3-050,
85.7051,Job,MODIFIED,eval-sanitize-20-r3-073,
85.7053,TaskRequest,MODIFIED,eval-sanitize-20-r3-050,phase=Complete job=None
85.715,Job,MODIFIED,eval-sanitize-20-r3-050,
85.7421,Event,ADDED,eval-sanitize-20-r3-050.18d41b3b75587393,reason=Completed count=1 msg=Job completed
85.8316,Event,ADDED,eval-sanitize-20-r3-085-645dg.18d41b3b7ce0829f,"reason=Pulled count=1 msg=Container image ""busybox:musl"" already present on machine"
85.8529,Job,MODIFIED,eval-sanitize-20-r3-070,
85.8532,Event,ADDED,eval-sanitize-20-r3-085-645dg.18d41b3b7e1ed8a8,reason=Created count=1 msg=Created container: task
85.8588,Pod,MODIFIED,eval-sanitize-20-r3-073-srpdw,phase=Succeeded node=kind-worker3
85.8594,Event,ADDED,eval-sanitize-20-r3-070.18d41b3b7e6b688d,reason=Completed count=1 msg=Job completed
85.8596,TaskRequest,MODIFIED,eval-sanitize-20-r3-070,phase=Complete job=None
85.8704,Job,MODIFIED,eval-sanitize-20-r3-070,
85.9188,Event,ADDED,eval-sanitize-20-r3-085-645dg.18d41b3b8219b8d0,reason=Started count=1 msg=Started container task
86.0003,Job,MODIFIED,eval-sanitize-20-r3-071,
86.0039,Event,ADDED,eval-sanitize-20-r3-071.18d41b3b873d232f,reason=Completed count=1 msg=Job completed
86.006,TaskRequest,MODIFIED,eval-sanitize-20-r3-071,phase=Complete job=None
86.016,Job,MODIFIED,eval-sanitize-20-r3-071,
86.0346,TaskRequest,ADDED,eval-sanitize-20-r3-086,phase=None job=None
86.038,TaskRequest,MODIFIED,eval-sanitize-20-r3-086,phase=Pending job=None
86.0409,Job,MODIFIED,eval-sanitize-20-r3-085,
86.0561,Job,ADDED,eval-sanitize-20-r3-086,
86.0626,Pod,ADDED,eval-sanitize-20-r3-086-qf972,phase=Pending node=None
86.0645,TaskRequest,MODIFIED,eval-sanitize-20-r3-086,phase=Scheduled job=None
86.0654,Job,MODIFIED,eval-sanitize-20-r3-086,
86.0742,TaskRequest,MODIFIED,eval-sanitize-20-r3-086,phase=Scheduled job=None
86.0751,Job,MODIFIED,eval-sanitize-20-r3-085,
86.1208,Pod,MODIFIED,eval-sanitize-20-r3-085-645dg,phase=Running node=kind-worker2
86.1444,Event,ADDED,eval-sanitize-20-r3-086.18d41b3b8af57902,reason=SuccessfulCreate count=1 msg=Created pod: eval-sanitize-20-r3-086-qf972
86.2241,Pod,MODIFIED,eval-sanitize-20-r3-086-qf972,phase=Pending node=kind-worker
86.2281,Event,ADDED,eval-sanitize-20-r3-086-qf972.18d41b3b949067e6,reason=Scheduled count=None msg=Successfully assigned compute/eval-sanitize-20-r3-086-qf972 to kind-worker
86.2341,Pod,MODIFIED,eval-sanitize-20-r3-075-n85xt,phase=Running node=kind-worker5
86.2359,Pod,MODIFIED,eval-sanitize-20-r3-086-qf972,phase=Pending node=kind-worker
86.2373,Job,MODIFIED,eval-sanitize-20-r3-084,
86.2459,Job,MODIFIED,eval-sanitize-20-r3-084,
86.669,Event,ADDED,eval-sanitize-20-r3-086-qf972.18d41b3baedc461a,"reason=Pulled count=1 msg=Container image ""busybox:musl"" already present on machine"
86.686,Event,ADDED,eval-sanitize-20-r3-086-qf972.18d41b3bafeba9d6,reason=Created count=1 msg=Created container: task
86.6957,Job,MODIFIED,eval-sanitize-20-r3-073,
86.7048,Pod,MODIFIED,eval-sanitize-20-r3-073-srpdw,phase=Succeeded node=kind-worker3
86.7058,Job,MODIFIED,eval-sanitize-20-r3-073,
86.7193,Event,ADDED,eval-sanitize-20-r3-086-qf972.18d41b3bb1e0229c,reason=Started count=1 msg=Started container task
86.8692,Pod,MODIFIED,eval-sanitize-20-r3-086-qf972,phase=Running node=kind-worker
87.026,TaskRequest,ADDED,eval-sanitize-20-r3-087,phase=None job=None
87.0316,TaskRequest,MODIFIED,eval-sanitize-20-r3-087,phase=Pending job=None
87.046,Job,MODIFIED,eval-sanitize-20-r3-085,
87.0473,Job,ADDED,eval-sanitize-20-r3-087,
87.0533,Pod,ADDED,eval-sanitize-20-r3-087-qhxq2,phase=Pending node=None
87.0549,TaskRequest,MODIFIED,eval-sanitize-20-r3-087,phase=Scheduled job=None
87.0558,Job,MODIFIED,eval-sanitize-20-r3-087,
87.0576,Event,ADDED,eval-sanitize-20-r3-087.18d41b3bc6046666,reason=SuccessfulCreate count=1 msg=Created pod: eval-sanitize-20-r3-087-qhxq2
87.0636,TaskRequest,MODIFIED,eval-sanitize-20-r3-087,phase=Scheduled job=None
87.0663,Job,MODIFIED,eval-sanitize-20-r3-085,
87.068,Job,MODIFIED,eval-sanitize-20-r3-086,
87.0763,Job,MODIFIED,eval-sanitize-20-r3-086,
87.2265,Event,ADDED,eval-sanitize-20-r3-087-qhxq2.18d41b3bcfeb6fb5,"reason=FailedScheduling count=None msg=0/6 nodes are available: 2 c_wall violated: 1 conflicting context pair(s) with node memory, 2 c_wall violated: 2 conflicting context pair(s) with node memory, 2 node(s) had untolerated taint(s). no new claims to deallocate, preemption: 0/6 nodes are available: 2 Preemption is not helpful for scheduling, 4 No preemption victims found for incoming pod."
87.2276,Pod,MODIFIED,eval-sanitize-20-r3-087-qhxq2,phase=Pending node=None
87.2391,Job,MODIFIED,eval-sanitize-20-r3-075,
87.2485,Job,MODIFIED,eval-sanitize-20-r3-075,
87.3247,Pod,MODIFIED,eval-sanitize-20-r3-075-n85xt,phase=Succeeded node=kind-worker5
87.325,Event,ADDED,eval-sanitize-20-r3-087-qhxq2.18d41b3bd5d3f4d3,"reason=FailedScheduling count=None msg=0/6 nodes are available: 2 c_wall violated: 1 conflicting context pair(s) with node memory, 2 c_wall violated: 2 conflicting context pair(s) with node memory, 2 node(s) had untolerated taint(s). no new claims to deallocate, preemption: 0/6 nodes are available: 2 Preemption is not helpful for scheduling, 4 No preemption victims found for incoming pod."
87.7023,Job,MODIFIED,eval-sanitize-20-r3-073,
87.7066,Job,MODIFIED,eval-sanitize-20-r3-073,
87.711,Event,ADDED,eval-sanitize-20-r3-073.18d41b3becf62aa9,reason=Completed count=1 msg=Job completed
87.7176,Job,MODIFIED,eval-sanitize-20-r3-073,
87.7222,TaskRequest,MODIFIED,eval-sanitize-20-r3-073,phase=Complete job=None
87.7271,Event,MODIFIED,eval-sanitize-20-r3-087-qhxq2.18d41b3bd5d3f4d3,"reason=FailedScheduling count=None msg=0/6 nodes are available: 2 c_wall violated: 1 conflicting context pair(s) with node memory, 2 c_wall violated: 2 conflicting context pair(s) with node memory, 2 node(s) had untolerated taint(s). no new claims to deallocate, preemption: 0/6 nodes are available: 2 Preemption is not helpful for scheduling, 4 No preemption victims found for incoming pod."
87.7313,Job,MODIFIED,eval-sanitize-20-r3-073,
88.0028,Node,MODIFIED,kind-worker,taints=1
88.0166,Node,MODIFIED,kind-worker,taints=1
88.0167,TaskRequest,ADDED,eval-sanitize-20-r3-088,phase=None job=None
88.021,Pod,MODIFIED,eval-sanitize-20-r3-076-jwx8r,phase=Pending node=None
88.0211,TaskRequest,MODIFIED,eval-sanitize-20-r3-088,phase=Pending job=None
88.0364,Job,ADDED,eval-sanitize-20-r3-088,
88.0423,Pod,ADDED,eval-sanitize-20-r3-088-79qsw,phase=Pending node=None
88.0425,TaskRequest,MODIFIED,eval-sanitize-20-r3-088,phase=Scheduled job=None
88.045,Job,MODIFIED,eval-sanitize-20-r3-088,
88.0476,Event,ADDED,eval-sanitize-20-r3-088.18d41b3c00fb1fc2,reason=SuccessfulCreate count=1 msg=Created pod: eval-sanitize-20-r3-088-79qsw
88.0505,TaskRequest,MODIFIED,eval-sanitize-20-r3-088,phase=Scheduled job=None
88.0574,Job,MODIFIED,eval-sanitize-20-r3-087,
88.0655,Job,MODIFIED,eval-sanitize-20-r3-087,
88.0944,Pod,MODIFIED,eval-sanitize-20-r3-072-cst2r,phase=Pending node=None
88.1332,Pod,MODIFIED,eval-sanitize-20-r3-088-79qsw,phase=Pending node=kind-worker5
88.1383,Event,ADDED,eval-sanitize-20-r3-088-79qsw.18d41b3c065c18cc,reason=Scheduled count=None msg=Successfully assigned compute/eval-sanitize-20-r3-088-79qsw to kind-worker5
88.1436,Node,MODIFIED,kind-worker5,taints=0
88.1454,Pod,MODIFIED,eval-sanitize-20-r3-088-79qsw,phase=Pending node=kind-worker5
88.1991,Pod,MODIFIED,eval-sanitize-20-r3-074-4q6rc,phase=Pending node=None
88.222,Node,MODIFIED,kind-worker5,taints=0
88.2413,Pod,MODIFIED,eval-sanitize-20-r3-077-fh6pf,phase=Running node=kind-worker5
88.244,Job,MODIFIED,eval-sanitize-20-r3-075,
88.2518,Pod,MODIFIED,eval-sanitize-20-r3-075-n85xt,phase=Succeeded node=kind-worker5
88.2533,Job,MODIFIED,eval-sanitize-20-r3-075,
88.291,Pod,MODIFIED,eval-sanitize-20-r3-080-grjrf,phase=Pending node=None
88.3059,Pod,MODIFIED,eval-sanitize-20-r3-087-qhxq2,phase=Pending node=None
88.3936,Event,ADDED,eval-sanitize-20-r3-076-jwx8r.18d41b3c158be6ff,"reason=FailedScheduling count=None msg=0/6 nodes are available: 1 c_wall violated: 2 conflicting context pair(s) with node memory, 2 c_wall violated: 1 conflicting context pair(s) with node memory, 3 node(s) had untolerated taint(s). no new claims to deallocate, preemption: 0/6 nodes are available: 3 No preemption victims found for incoming pod, 3 Preemption is not helpful for scheduling."
88.4237,Pod,MODIFIED,eval-sanitize-20-r3-072-cst2r,phase=Pending node=None
88.4246,Event,ADDED,eval-sanitize-20-r3-072-cst2r.18d41b3c1759c2b7,"reason=FailedScheduling count=None msg=0/6 nodes are available: 1 c_wall violated: 1 conflicting context pair(s) with node memory, 2 c_wall violated: 2 conflicting context pair(s) with node memory, 3 node(s) had untolerated taint(s). no new claims to deallocate, preemption: 0/6 nodes are available: 3 No preemption victims found for incoming pod, 3 Preemption is not helpful for scheduling."
88.4746,Node,MODIFIED,kind-worker4,taints=1
88.4875,Node,MODIFIED,kind-worker4,taints=1
88.4938,Event,ADDED,eval-sanitize-20-r3-074-4q6rc.18d41b3c1b9b1ca9,"reason=FailedScheduling count=None msg=0/6 nodes are available: 1 c_wall violated: 1 conflicting context pair(s) with node memory, 2 c_wall violated: 2 conflicting context pair(s) with node memory, 3 node(s) had untolerated taint(s). no new claims to deallocate, preemption: 0/6 nodes are available: 3 No preemption victims found for incoming pod, 3 Preemption is not helpful for scheduling."
88.5318,Node,MODIFIED,kind-worker2,taints=0
88.5492,Event,ADDED,eval-sanitize-20-r3-088-79qsw.18d41b3c1ee14e9b,"reason=Pulled count=1 msg=Container image ""busybox:musl"" already present on machine"
88.5646,Node,MODIFIED,kind-worker4,taints=0
88.5658,Event,ADDED,eval-sanitize-20-r3-088-79qsw.18d41b3c1ff462bd,reason=Created count=1 msg=Created container: task
88.5771,Node,MODIFIED,kind-worker4,taints=0
88.588,Event,ADDED,eval-sanitize-20-r3-080-grjrf.18d41b3c213e3c3c,"reason=FailedScheduling count=None msg=0/6 nodes are available: 1 c_wall violated: 2 conflicting context pair(s) with node memory, 2 c_wall violated: 1 conflicting context pair(s) with node memory, 3 node(s) had untolerated taint(s). no new claims to deallocate, preemption: 0/6 nodes are available: 3 No preemption victims found for incoming pod, 3 Preemption is not helpful for scheduling."
88.5996,Pod,MODIFIED,eval-sanitize-20-r3-087-qhxq2,phase=Pending node=kind-worker4
88.6013,Event,ADDED,eval-sanitize-20-r3-088-79qsw.18d41b3c220f629c,reason=Started count=1 msg=Started container task
88.6048,Event,ADDED,eval-sanitize-20-r3-087-qhxq2.18d41b3c222a334d,reason=Scheduled count=None msg=Successfully assigned compute/eval-sanitize-20-r3-087-qhxq2 to kind-worker4
88.61,Node,MODIFIED,kind-worker4,taints=0
88.6117,Pod,MODIFIED,eval-sanitize-20-r3-087-qhxq2,phase=Pending node=kind-worker4
88.6207,Node,MODIFIED,kind-worker4,taints=0
88.6854,Node,MODIFIED,kind-worker3,taints=1
88.6963,Pod,MODIFIED,eval-sanitize-20-r3-076-jwx8r,phase=Pending node=kind-worker4
88.6988,Node,MODIFIED,kind-worker3,taints=1
88.7005,Event,ADDED,eval-sanitize-20-r3-076-jwx8r.18d41b3c27efafbd,reason=Scheduled count=None msg=Successfully assigned compute/eval-sanitize-20-r3-076-jwx8r to kind-worker4
88.7066,Pod,MODIFIED,eval-sanitize-20-r3-076-jwx8r,phase=Pending node=kind-worker4
88.7968,Pod,MODIFIED,eval-sanitize-20-r3-072-cst2r,phase=Pending node=kind-worker4
88.8002,Event,ADDED,eval-sanitize-20-r3-072-cst2r.18d41b3c2dea1766,reason=Scheduled count=None msg=Successfully assigned compute/eval-sanitize-20-r3-072-cst2r to kind-worker4
88.8066,Pod,MODIFIED,eval-sanitize-20-r3-072-cst2r,phase=Pending node=kind-worker4
88.8092,Node,MODIFIED,kind-worker4,taints=0
88.8259,Pod,MODIFIED,eval-sanitize-20-r3-074-4q6rc,phase=Pending node=kind-worker4
88.8295,Event,ADDED,eval-sanitize-20-r3-074-4q6rc.18d41b3c2fa64bc5,reason=Scheduled count=None msg=Successfully assigned compute/eval-sanitize-20-r3-074-4q6rc to kind-worker4
88.8353,Pod,MODIFIED,eval-sanitize-20-r3-074-4q6rc,phase=Pending node=kind-worker4
88.8707,Node,MODIFIED,kind-worker4,taints=0
88.9009,Pod,MODIFIED,eval-sanitize-20-r3-080-grjrf,phase=Pending node=kind-worker4
88.9051,Event,ADDED,eval-sanitize-20-r3-080-grjrf.18d41b3c34214700,reason=Scheduled count=None msg=Successfully assigned compute/eval-sanitize-20-r3-080-grjrf to kind-worker4
88.9133,Pod,MODIFIED,eval-sanitize-20-r3-080-grjrf,phase=Pending node=kind-worker4
89.0136,TaskRequest,ADDED,eval-sanitize-20-r3-089,phase=None job=None
89.0149,Event,ADDED,eval-sanitize-20-r3-087-qhxq2.18d41b3c3ab28e34,"reason=Pulled count=1 msg=Container image ""busybox:musl"" already present on machine"
89.0207,TaskRequest,MODIFIED,eval-sanitize-20-r3-089,phase=Pending job=None
89.0363,Job,ADDED,eval-sanitize-20-r3-089,
89.0405,Event,ADDED,eval-sanitize-20-r3-087-qhxq2.18d41b3c3c1b506f,reason=Created count=1 msg=Created container: task
89.0414,TaskRequest,MODIFIED,eval-sanitize-20-r3-089,phase=Scheduled job=None
89.045,Job,MODIFIED,eval-sanitize-20-r3-089,
89.0458,Pod,ADDED,eval-sanitize-20-r3-089-6c526,phase=Pending node=None
89.049,Job,MODIFIED,eval-sanitize-20-r3-088,
89.0493,Event,ADDED,eval-sanitize-20-r3-089.18d41b3c3cb89cd4,reason=SuccessfulCreate count=1 msg=Created pod: eval-sanitize-20-r3-089-6c526
89.058,Job,MODIFIED,eval-sanitize-20-r3-088,
89.0599,TaskRequest,MODIFIED,eval-sanitize-20-r3-089,phase=Scheduled job=None
89.0666,Pod,MODIFIED,eval-sanitize-20-r3-089-6c526,phase=Pending node=kind-worker5
89.0707,Event,ADDED,eval-sanitize-20-r3-089-6c526.18d41b3c3e06e9e5,reason=Scheduled count=None msg=Successfully assigned compute/eval-sanitize-20-r3-089-6c526 to kind-worker5
89.0775,Pod,MODIFIED,eval-sanitize-20-r3-089-6c526,phase=Pending node=kind-worker5
89.1001,Event,ADDED,eval-sanitize-20-r3-087-qhxq2.18d41b3c3fb5173b,reason=Started count=1 msg=Started container task
89.1169,Event,ADDED,eval-sanitize-20-r3-076-jwx8r.18d41b3c40bf354a,"reason=Pulled count=1 msg=Container image ""busybox:musl"" already present on machine"
89.1209,Pod,MODIFIED,eval-sanitize-20-r3-087-qhxq2,phase=Running node=kind-worker4
89.14,Event,ADDED,eval-sanitize-20-r3-076-jwx8r.18d41b3c421a15e8,reason=Created count=1 msg=Created container: task
89.2224,Event,ADDED,eval-sanitize-20-r3-076-jwx8r.18d41b3c46f143f4,reason=Started count=1 msg=Started container task
89.2438,Node,MODIFIED,kind-worker2,taints=1
89.2449,Event,ADDED,eval-sanitize-20-r3-072-cst2r.18d41b3c4805b121,"reason=Pulled count=1 msg=Container image ""busybox:musl"" already present on machine"
89.2492,Job,MODIFIED,eval-sanitize-20-r3-077,
89.2529,Job,MODIFIED,eval-sanitize-20-r3-075,
89.2543,Pod,MODIFIED,eval-sanitize-20-r3-078-qjcll,phase=Running node=kind-worker5
89.2584,Job,MODIFIED,eval-sanitize-20-r3-075,
89.2619,Job,MODIFIED,eval-sanitize-20-r3-077,
89.2642,Pod,MODIFIED,eval-sanitize-20-r3-088-79qsw,phase=Running node=kind-worker5
89.2659,Node,MODIFIED,kind-worker2,taints=1
89.2663,Event,ADDED,eval-sanitize-20-r3-075.18d41b3c4972d17c,reason=Completed count=1 msg=Job completed
89.2743,Job,MODIFIED,eval-sanitize-20-r3-075,
89.2753,Event,ADDED,eval-sanitize-20-r3-072-cst2r.18d41b3c4a39ae93,reason=Created count=1 msg=Created container: task
89.2793,TaskRequest,MODIFIED,eval-sanitize-20-r3-075,phase=Complete job=None
89.2802,Event,ADDED,eval-sanitize-20-r3-074-4q6rc.18d41b3c4a4094b0,"reason=Pulled count=1 msg=Container image ""busybox:musl"" already present on machine"
89.2892,Job,MODIFIED,eval-sanitize-20-r3-075,
89.2955,Event,ADDED,eval-sanitize-20-r3-074-4q6rc.18d41b3c4b7c0a5c,reason=Created count=1 msg=Created container: task
89.349,Event,ADDED,eval-sanitize-20-r3-072-cst2r.18d41b3c4e8f5cf1,reason=Started count=1 msg=Started container task
89.3554,Event,ADDED,eval-sanitize-20-r3-080-grjrf.18d41b3c4e927ead,"reason=Pulled count=1 msg=Container image ""busybox:musl"" already present on machine"
89.3598,Event,ADDED,eval-sanitize-20-r3-074-4q6rc.18d41b3c4eebb5f8,reason=Started count=1 msg=Started container task
89.3678,Event,ADDED,eval-sanitize-20-r3-080-grjrf.18d41b3c4fcd8149,reason=Created count=1 msg=Created container: task
89.3872,Pod,MODIFIED,eval-sanitize-20-r3-077-fh6pf,phase=Succeeded node=kind-worker5
89.4254,Event,ADDED,eval-sanitize-20-r3-080-grjrf.18d41b3c53187aa8,reason=Started count=1 msg=Started container task
89.5066,Event,ADDED,eval-sanitize-20-r3-089-6c526.18d41b3c57faa5fa,"reason=Pulled count=1 msg=Container image ""busybox:musl"" already present on machine"
89.5293,Event,ADDED,eval-sanitize-20-r3-089-6c526.18d41b3c59599aec,reason=Created count=1 msg=Created container: task
89.5636,Event,ADDED,eval-sanitize-20-r3-089-6c526.18d41b3c5b65d99e,reason=Started count=1 msg=Started container task
89.6376,Node,MODIFIED,kind-worker5,taints=1
89.7184,Node,MODIFIED,kind-worker5,taints=1
90.0142,TaskRequest,ADDED,eval-sanitize-20-r3-090,phase=None job=None
90.0185,TaskRequest,MODIFIED,eval-sanitize-20-r3-090,phase=Pending job=None
90.0332,Job,ADDED,eval-sanitize-20-r3-090,
90.0385,Pod,ADDED,eval-sanitize-20-r3-090-bzmnn,phase=Pending node=None
90.0397,TaskRequest,MODIFIED,eval-sanitize-20-r3-090,phase=Scheduled job=None
90.0427,Job,MODIFIED,eval-sanitize-20-r3-090,
90.0441,Event,ADDED,eval-sanitize-20-r3-090.18d41b3c77f3adee,reason=SuccessfulCreate count=1 msg=Created pod: eval-sanitize-20-r3-090-bzmnn
90.0475,Pod,MODIFIED,eval-sanitize-20-r3-090-bzmnn,phase=Pending node=None
90.0483,Event,ADDED,eval-sanitize-20-r3-090-bzmnn.18d41b3c783680a2,"reason=FailedScheduling count=None msg=0/6 nodes are available: 1 c_wall violated: 2 conflicting context pair(s) with node memory, 5 node(s) had untolerated taint(s). no new claims to deallocate, preemption: 0/6 nodes are available: 1 No preemption victims found for incoming pod, 5 Preemption is not helpful for scheduling."
90.0484,TaskRequest,MODIFIED,eval-sanitize-20-r3-090,phase=Scheduled job=None
90.0491,Job,MODIFIED,eval-sanitize-20-r3-089,
90.0549,Job,MODIFIED,eval-sanitize-20-r3-088,
90.0555,Event,ADDED,eval-sanitize-20-r3-090-bzmnn.18d41b3c78ae20af,"reason=FailedScheduling count=None msg=0/6 nodes are available: 1 c_wall violated: 2 conflicting context pair(s) with node memory, 5 node(s) had untolerated taint(s). no new claims to deallocate, preemption: 0/6 nodes are available: 1 No preemption victims found for incoming pod, 5 Preemption is not helpful for scheduling."
90.0589,Job,MODIFIED,eval-sanitize-20-r3-089,
90.0629,Job,MODIFIED,eval-sanitize-20-r3-088,
90.1256,Pod,MODIFIED,eval-sanitize-20-r3-080-grjrf,phase=Running node=kind-worker4
90.1271,Job,MODIFIED,eval-sanitize-20-r3-087,
90.1335,Pod,MODIFIED,eval-sanitize-20-r3-076-jwx8r,phase=Running node=kind-worker4
90.1362,Event,MODIFIED,eval-sanitize-20-r3-090-bzmnn.18d41b3c78ae20af,"reason=FailedScheduling count=None msg=0/6 nodes are available: 1 c_wall violated: 2 conflicting context pair(s) with node memory, 5 node(s) had untolerated taint(s). no new claims to deallocate, preemption: 0/6 nodes are available: 1 No preemption victims found for incoming pod, 5 Preemption is not helpful for scheduling."
90.1394,Job,MODIFIED,eval-sanitize-20-r3-087,
90.1406,Pod,MODIFIED,eval-sanitize-20-r3-072-cst2r,phase=Running node=kind-worker4
90.146,Pod,MODIFIED,eval-sanitize-20-r3-074-4q6rc,phase=Running node=kind-worker4
90.2518,Pod,MODIFIED,eval-sanitize-20-r3-089-6c526,phase=Running node=kind-worker5
90.2559,Job,MODIFIED,eval-sanitize-20-r3-077,
90.2574,Job,MODIFIED,eval-sanitize-20-r3-078,
90.2645,Pod,MODIFIED,eval-sanitize-20-r3-077-fh6pf,phase=Succeeded node=kind-worker5
90.266,Job,MODIFIED,eval-sanitize-20-r3-077,
90.2705,Job,MODIFIED,eval-sanitize-20-r3-078,
90.3789,Pod,MODIFIED,eval-sanitize-20-r3-078-qjcll,phase=Succeeded node=kind-worker5
90.6979,Pod,MODIFIED,eval-sanitize-20-r3-079-pkdp4,phase=Running node=kind-worker3
91.0087,TaskRequest,ADDED,eval-sanitize-20-r3-091,phase=None job=None
91.0141,TaskRequest,MODIFIED,eval-sanitize-20-r3-091,phase=Pending job=None
91.0287,Job,ADDED,eval-sanitize-20-r3-091,
91.0354,Pod,ADDED,eval-sanitize-20-r3-091-vcg5m,phase=Pending node=None
91.0372,Job,MODIFIED,eval-sanitize-20-r3-091,
91.0374,TaskRequest,MODIFIED,eval-sanitize-20-r3-091,phase=Scheduled job=None
91.0399,Event,ADDED,eval-sanitize-20-r3-091.18d41b3cb35ec99e,reason=SuccessfulCreate count=1 msg=Created pod: eval-sanitize-20-r3-091-vcg5m
91.0438,Job,MODIFIED,eval-sanitize-20-r3-090,
91.0468,Pod,MODIFIED,eval-sanitize-20-r3-091-vcg5m,phase=Pending node=kind-worker4
91.0473,TaskRequest,MODIFIED,eval-sanitize-20-r3-091,phase=Scheduled job=None
91.0529,Event,ADDED,eval-sanitize-20-r3-091-vcg5m.18d41b3cb40ec33c,reason=Scheduled count=None msg=Successfully assigned compute/eval-sanitize-20-r3-091-vcg5m to kind-worker4
91.0561,Job,MODIFIED,eval-sanitize-20-r3-090,
91.0568,Job,MODIFIED,eval-sanitize-20-r3-089,
91.059,Node,MODIFIED,kind-worker4,taints=0
91.061,Pod,MODIFIED,eval-sanitize-20-r3-091-vcg5m,phase=Pending node=kind-worker4
91.0677,Job,MODIFIED,eval-sanitize-20-r3-089,
91.0702,Node,MODIFIED,kind-worker4,taints=0
91.1319,Job,MODIFIED,eval-sanitize-20-r3-080,
91.138,Job,MODIFIED,eval-sanitize-20-r3-076,
91.1416,Job,MODIFIED,eval-sanitize-20-r3-080,
91.1456,Job,MODIFIED,eval-sanitize-20-r3-072,
91.1475,Job,MODIFIED,eval-sanitize-20-r3-076,
91.1503,Job,MODIFIED,eval-sanitize-20-r3-074,
91.1547,Job,MODIFIED,eval-sanitize-20-r3-072,
91.1588,Job,MODIFIED,eval-sanitize-20-r3-074,
91.2626,Job,MODIFIED,eval-sanitize-20-r3-077,
91.2644,Job,MODIFIED,eval-sanitize-20-r3-078,
91.2677,Job,MODIFIED,eval-sanitize-20-r3-077,
91.2736,Event,ADDED,eval-sanitize-20-r3-077.18d41b3cc1395072,reason=Completed count=1 msg=Job completed
91.2744,Job,MODIFIED,eval-sanitize-20-r3-078,
91.2757,Pod,MODIFIED,eval-sanitize-20-r3-078-qjcll,phase=Succeeded node=kind-worker5
91.2781,Job,MODIFIED,eval-sanitize-20-r3-077,
91.2838,TaskRequest,MODIFIED,eval-sanitize-20-r3-077,phase=Complete job=None
91.2936,Job,MODIFIED,eval-sanitize-20-r3-077,
91.4682,Event,ADDED,eval-sanitize-20-r3-091-vcg5m.18d41b3cccec520a,"reason=Pulled count=1 msg=Container image ""busybox:musl"" already present on machine"
91.4862,Event,ADDED,eval-sanitize-20-r3-091-vcg5m.18d41b3cce059bd4,reason=Created count=1 msg=Created container: task
91.5193,Event,ADDED,eval-sanitize-20-r3-091-vcg5m.18d41b3ccfff64a6,reason=Started count=1 msg=Started container task
91.7044,Job,MODIFIED,eval-sanitize-20-r3-079,
91.7146,Job,MODIFIED,eval-sanitize-20-r3-079,
91.7942,Pod,MODIFIED,eval-sanitize-20-r3-079-pkdp4,phase=Succeeded node=kind-worker3
91.881,Pod,MODIFIED,eval-sanitize-20-r3-081-9q4t2,phase=Running node=kind-worker
92.0124,TaskRequest,ADDED,eval-sanitize-20-r3-092,phase=None job=None
92.0162,TaskRequest,MODIFIED,eval-sanitize-20-r3-092,phase=Pending job=None
92.034,Job,ADDED,eval-sanitize-20-r3-092,
92.0405,Job,MODIFIED,eval-sanitize-20-r3-091,
92.0424,TaskRequest,MODIFIED,eval-sanitize-20-r3-092,phase=Scheduled job=None
92.0433,Pod,ADDED,eval-sanitize-20-r3-092-4rqfw,phase=Pending node=None
92.0452,Job,MODIFIED,eval-sanitize-20-r3-092,
92.0477,Event,ADDED,eval-sanitize-20-r3-092.18d41b3cef6ab238,reason=SuccessfulCreate count=1 msg=Created pod: eval-sanitize-20-r3-092-4rqfw
92.0495,TaskRequest,MODIFIED,eval-sanitize-20-r3-092,phase=Scheduled job=None
92.0529,Pod,MODIFIED,eval-sanitize-20-r3-092-4rqfw,phase=Pending node=None
92.0536,Job,MODIFIED,eval-sanitize-20-r3-091,
92.0539,Event,ADDED,eval-sanitize-20-r3-092-4rqfw.18d41b3cefb31edf,"reason=FailedScheduling count=None msg=0/6 nodes are available: 1 c_wall violated: 1 conflicting context pair(s) with node memory, 5 node(s) had untolerated taint(s). no new claims to deallocate, preemption: 0/6 nodes are available: 1 No preemption victims found for incoming pod, 5 Preemption is not helpful for scheduling."
92.0595,Event,ADDED,eval-sanitize-20-r3-092-4rqfw.18d41b3cf0373274,"reason=FailedScheduling count=None msg=0/6 nodes are available: 1 c_wall violated: 1 conflicting context pair(s) with node memory, 5 node(s) had untolerated taint(s). no new claims to deallocate, preemption: 0/6 nodes are available: 1 No preemption victims found for incoming pod, 5 Preemption is not helpful for scheduling."
92.1351,Pod,MODIFIED,eval-sanitize-20-r3-091-vcg5m,phase=Running node=kind-worker4
92.1477,Event,MODIFIED,eval-sanitize-20-r3-092-4rqfw.18d41b3cf0373274,"reason=FailedScheduling count=None msg=0/6 nodes are available: 1 c_wall violated: 1 conflicting context pair(s) with node memory, 5 node(s) had untolerated taint(s). no new claims to deallocate, preemption: 0/6 nodes are available: 1 No preemption victims found for incoming pod, 5 Preemption is not helpful for scheduling."
92.2724,Job,MODIFIED,eval-sanitize-20-r3-078,
92.2767,Job,MODIFIED,eval-sanitize-20-r3-078,
92.2797,Event,ADDED,eval-sanitize-20-r3-078.18d41b3cfd5dbe40,reason=Completed count=1 msg=Job completed
92.2891,Job,MODIFIED,eval-sanitize-20-r3-078,
92.2936,TaskRequest,MODIFIED,eval-sanitize-20-r3-078,phase=Complete job=None
92.3019,Job,MODIFIED,eval-sanitize-20-r3-078,
92.7137,Job,MODIFIED,eval-sanitize-20-r3-079,
92.7228,Pod,MODIFIED,eval-sanitize-20-r3-079-pkdp4,phase=Succeeded node=kind-worker3
92.7244,Job,MODIFIED,eval-sanitize-20-r3-079,
92.8871,Job,MODIFIED,eval-sanitize-20-r3-081,
92.9067,Job,MODIFIED,eval-sanitize-20-r3-081,
93.007,TaskRequest,ADDED,eval-sanitize-20-r3-093,phase=None job=None
93.0104,TaskRequest,MODIFIED,eval-sanitize-20-r3-093,phase=Pending job=None
93.0254,Job,ADDED,eval-sanitize-20-r3-093,
93.0308,Pod,ADDED,eval-sanitize-20-r3-093-cs68v,phase=Pending node=None
93.0341,TaskRequest,MODIFIED,eval-sanitize-20-r3-093,phase=Scheduled job=None
93.0368,Event,ADDED,eval-sanitize-20-r3-093.18d41b3d2a50e0c4,reason=SuccessfulCreate count=1 msg=Created pod: eval-sanitize-20-r3-093-cs68v
93.0378,Job,MODIFIED,eval-sanitize-20-r3-093,
93.0421,Pod,MODIFIED,eval-sanitize-20-r3-093-cs68v,phase=Pending node=kind-worker4
93.0456,Pod,MODIFIED,eval-sanitize-20-r3-081-9q4t2,phase=Succeeded node=kind-worker
93.0476,TaskRequest,MODIFIED,eval-sanitize-20-r3-093,phase=Scheduled job=None
93.0485,Job,MODIFIED,eval-sanitize-20-r3-093,
93.0493,Job,MODIFIED,eval-sanitize-20-r3-091,
93.0498,Event,ADDED,eval-sanitize-20-r3-093-cs68v.18d41b3d2af2d394,reason=Scheduled count=None msg=Successfully assigned compute/eval-sanitize-20-r3-093-cs68v to kind-worker4
93.0506,Job,MODIFIED,eval-sanitize-20-r3-092,
93.054,Pod,MODIFIED,eval-sanitize-20-r3-093-cs68v,phase=Pending node=kind-worker4
93.0616,Job,MODIFIED,eval-sanitize-20-r3-093,
93.0638,Job,MODIFIED,eval-sanitize-20-r3-091,
93.0644,Job,MODIFIED,eval-sanitize-20-r3-092,
93.4685,Event,ADDED,eval-sanitize-20-r3-093-cs68v.18d41b3d442db824,"reason=Pulled count=1 msg=Container image ""busybox:musl"" already present on machine"
93.4873,Event,ADDED,eval-sanitize-20-r3-093-cs68v.18d41b3d4539dc64,reason=Created count=1 msg=Created container: task
93.5669,Event,ADDED,eval-sanitize-20-r3-093-cs68v.18d41b3d4a069569,reason=Started count=1 msg=Started container task
93.721,Job,MODIFIED,eval-sanitize-20-r3-079,
93.7252,Job,MODIFIED,eval-sanitize-20-r3-079,
93.7282,Event,ADDED,eval-sanitize-20-r3-079.18d41b3d53af70f1,reason=Completed count=1 msg=Job completed
93.8198,Job,MODIFIED,eval-sanitize-20-r3-079,
93.8246,TaskRequest,MODIFIED,eval-sanitize-20-r3-079,phase=Complete job=None
93.8339,Job,MODIFIED,eval-sanitize-20-r3-079,
93.8882,Pod,MODIFIED,eval-sanitize-20-r3-082-7mkd4,phase=Running node=kind-worker
93.892,Job,MODIFIED,eval-sanitize-20-r3-081,
93.9008,Pod,MODIFIED,eval-sanitize-20-r3-081-9q4t2,phase=Succeeded node=kind-worker
93.9019,Job,MODIFIED,eval-sanitize-20-r3-081,
94.0081,TaskRequest,ADDED,eval-sanitize-20-r3-094,phase=None job=None
94.0116,TaskRequest,MODIFIED,eval-sanitize-20-r3-094,phase=Pending job=None
94.0278,Job,ADDED,eval-sanitize-20-r3-094,
94.0319,TaskRequest,MODIFIED,eval-sanitize-20-r3-094,phase=Scheduled job=None
94.0349,Pod,ADDED,eval-sanitize-20-r3-094-g88k7,phase=Pending node=None
94.0369,Job,MODIFIED,eval-sanitize-20-r3-094,
94.0429,TaskRequest,MODIFIED,eval-sanitize-20-r3-094,phase=Scheduled job=None
94.0434,Event,ADDED,eval-sanitize-20-r3-094.18d41b3d6632df89,reason=SuccessfulCreate count=1 msg=Created pod: eval-sanitize-20-r3-094-g88k7
94.0449,Pod,MODIFIED,eval-sanitize-20-r3-094-g88k7,phase=Pending node=None
94.0453,Event,ADDED,eval-sanitize-20-r3-094-g88k7.18d41b3d666a2039,"reason=FailedScheduling count=None msg=0/6 nodes are available: 1 c_wall violated: 1 conflicting context pair(s) with node memory, 5 node(s) had untolerated taint(s). no new claims to deallocate, preemption: 0/6 nodes are available: 1 No preemption victims found for incoming pod, 5 Preemption is not helpful for scheduling."
94.0535,Event,ADDED,eval-sanitize-20-r3-094-g88k7.18d41b3d670c273e,"reason=FailedScheduling count=None msg=0/6 nodes are available: 1 c_wall violated: 1 conflicting context pair(s) with node memory, 5 node(s) had untolerated taint(s). no new claims to deallocate, preemption: 0/6 nodes are available: 1 No preemption victims found for incoming pod, 5 Preemption is not helpful for scheduling."
94.1372,Pod,MODIFIED,eval-sanitize-20-r3-083-rwbk8,phase=Running node=kind-worker2
94.139,Pod,MODIFIED,eval-sanitize-20-r3-093-cs68v,phase=Running node=kind-worker4
94.1516,Event,MODIFIED,eval-sanitize-20-r3-094-g88k7.18d41b3d670c273e,"reason=FailedScheduling count=None msg=0/6 nodes are available: 1 c_wall violated: 1 conflicting context pair(s) with node memory, 5 node(s) had untolerated taint(s). no new claims to deallocate, preemption: 0/6 nodes are available: 1 No preemption victims found for incoming pod, 5 Preemption is not helpful for scheduling."
94.8953,Job,MODIFIED,eval-sanitize-20-r3-082,
94.8973,Job,MODIFIED,eval-sanitize-20-r3-081,
94.9022,Job,MODIFIED,eval-sanitize-20-r3-081,
94.9066,Job,MODIFIED,eval-sanitize-20-r3-082,
94.9088,Event,ADDED,eval-sanitize-20-r3-081.18d41b3d99dd0f17,reason=Completed count=1 msg=Job completed
94.9175,Job,MODIFIED,eval-sanitize-20-r3-081,
94.9231,TaskRequest,MODIFIED,eval-sanitize-20-r3-081,phase=Complete job=None
94.932,Job,MODIFIED,eval-sanitize-20-r3-081,
94.9881,Pod,MODIFIED,eval-sanitize-20-r3-082-7mkd4,phase=Succeeded node=kind-worker
95.012,TaskRequest,ADDED,eval-sanitize-20-r3-095,phase=None job=None
95.0171,TaskRequest,MODIFIED,eval-sanitize-20-r3-095,phase=Pending job=None
95.0309,Job,ADDED,eval-sanitize-20-r3-095,
95.0361,TaskRequest,MODIFIED,eval-sanitize-20-r3-095,phase=Scheduled job=None
95.0379,Pod,ADDED,eval-sanitize-20-r3-095-mj974,phase=Pending node=None
95.0412,Job,MODIFIED,eval-sanitize-20-r3-094,
95.042,Job,MODIFIED,eval-sanitize-20-r3-095,
95.0426,Event,ADDED,eval-sanitize-20-r3-095.18d41b3da1f12a7f,reason=SuccessfulCreate count=1 msg=Created pod: eval-sanitize-20-r3-095-mj974
95.0433,TaskRequest,MODIFIED,eval-sanitize-20-r3-095,phase=Scheduled job=None
95.0469,Pod,MODIFIED,eval-sanitize-20-r3-095-mj974,phase=Pending node=None
95.048,Event,ADDED,eval-sanitize-20-r3-095-mj974.18d41b3da23506a7,"reason=FailedScheduling count=None msg=0/6 nodes are available: 1 c_wall violated: 1 conflicting context pair(s) with node memory, 5 node(s) had untolerated taint(s). no new claims to deallocate, preemption: 0/6 nodes are available: 1 No preemption victims found for incoming pod, 5 Preemption is not helpful for scheduling."
95.0509,Job,MODIFIED,eval-sanitize-20-r3-094,
95.0532,Event,ADDED,eval-sanitize-20-r3-095-mj974.18d41b3da2b169cb,"reason=FailedScheduling count=None msg=0/6 nodes are available: 1 c_wall violated: 1 conflicting context pair(s) with node memory, 5 node(s) had untolerated taint(s). no new claims to deallocate, preemption: 0/6 nodes are available: 1 No preemption victims found for incoming pod, 5 Preemption is not helpful for scheduling."
95.1446,Job,MODIFIED,eval-sanitize-20-r3-083,
95.1461,Job,MODIFIED,eval-sanitize-20-r3-093,
95.1552,Job,MODIFIED,eval-sanitize-20-r3-083,
95.1575,Job,MODIFIED,eval-sanitize-20-r3-093,
95.2397,Pod,MODIFIED,eval-sanitize-20-r3-083-rwbk8,phase=Succeeded node=kind-worker2
95.2546,Event,MODIFIED,eval-sanitize-20-r3-095-mj974.18d41b3da2b169cb,"reason=FailedScheduling count=None msg=0/6 nodes are available: 1 c_wall violated: 1 conflicting context pair(s) with node memory, 5 node(s) had untolerated taint(s). no new claims to deallocate, preemption: 0/6 nodes are available: 1 No preemption victims found for incoming pod, 5 Preemption is not helpful for scheduling."
95.2627,Pod,MODIFIED,eval-sanitize-20-r3-084-mrxnw,phase=Running node=kind-worker5
95.9054,Job,MODIFIED,eval-sanitize-20-r3-082,
95.9141,Pod,MODIFIED,eval-sanitize-20-r3-082-7mkd4,phase=Succeeded node=kind-worker
95.916,Job,MODIFIED,eval-sanitize-20-r3-082,
96.0092,TaskRequest,ADDED,eval-sanitize-20-r3-096,phase=None job=None
96.0126,TaskRequest,MODIFIED,eval-sanitize-20-r3-096,phase=Pending job=None
96.029,Job,ADDED,eval-sanitize-20-r3-096,
96.0346,Pod,ADDED,eval-sanitize-20-r3-096-tm8xd,phase=Pending node=None
96.0355,TaskRequest,MODIFIED,eval-sanitize-20-r3-096,phase=Scheduled job=None
96.0381,Job,MODIFIED,eval-sanitize-20-r3-096,
96.0393,Event,ADDED,eval-sanitize-20-r3-096.18d41b3ddd579bd0,reason=SuccessfulCreate count=1 msg=Created pod: eval-sanitize-20-r3-096-tm8xd
96.0422,Job,MODIFIED,eval-sanitize-20-r3-095,
96.0437,TaskRequest,MODIFIED,eval-sanitize-20-r3-096,phase=Scheduled job=None
96.0451,Pod,MODIFIED,eval-sanitize-20-r3-096-tm8xd,phase=Pending node=kind-worker4
96.0486,Event,ADDED,eval-sanitize-20-r3-096-tm8xd.18d41b3dddefd1b1,reason=Scheduled count=None msg=Successfully assigned compute/eval-sanitize-20-r3-096-tm8xd to kind-worker4
96.052,Job,MODIFIED,eval-sanitize-20-r3-095,
96.0573,Pod,MODIFIED,eval-sanitize-20-r3-096-tm8xd,phase=Pending node=kind-worker4
96.1462,Pod,MODIFIED,eval-sanitize-20-r3-085-645dg,phase=Running node=kind-worker2
96.1498,Job,MODIFIED,eval-sanitize-20-r3-083,
96.1587,Pod,MODIFIED,eval-sanitize-20-r3-083-rwbk8,phase=Succeeded node=kind-worker2
96.1599,Job,MODIFIED,eval-sanitize-20-r3-083,
96.2697,Job,MODIFIED,eval-sanitize-20-r3-084,
96.2796,Job,MODIFIED,eval-sanitize-20-r3-084,
96.3601,Pod,MODIFIED,eval-sanitize-20-r3-084-mrxnw,phase=Succeeded node=kind-worker5
96.4624,Event,ADDED,eval-sanitize-20-r3-096-tm8xd.18d41b3df69a1130,"reason=Pulled count=1 msg=Container image ""busybox:musl"" already present on machine"
96.4796,Event,ADDED,eval-sanitize-20-r3-096-tm8xd.18d41b3df7acd761,reason=Created count=1 msg=Created container: task
96.5125,Event,ADDED,eval-sanitize-20-r3-096-tm8xd.18d41b3df990e387,reason=Started count=1 msg=Started container task
96.8971,Pod,MODIFIED,eval-sanitize-20-r3-086-qf972,phase=Running node=kind-worker
96.9111,Job,MODIFIED,eval-sanitize-20-r3-082,
96.9157,Job,MODIFIED,eval-sanitize-20-r3-082,
96.9187,Event,ADDED,eval-sanitize-20-r3-082.18d41b3e11e00e1a,reason=Completed count=1 msg=Job completed
96.9281,Job,MODIFIED,eval-sanitize-20-r3-082,
96.9321,TaskRequest,MODIFIED,eval-sanitize-20-r3-082,phase=Complete job=None
96.9414,Job,MODIFIED,eval-sanitize-20-r3-082,
97.0116,TaskRequest,ADDED,eval-sanitize-20-r3-097,phase=None job=None
97.0166,TaskRequest,MODIFIED,eval-sanitize-20-r3-097,phase=Pending job=None
97.0318,Job,ADDED,eval-sanitize-20-r3-097,
97.037,Pod,ADDED,eval-sanitize-20-r3-097-8f4hj,phase=Pending node=None
97.0383,TaskRequest,MODIFIED,eval-sanitize-20-r3-097,phase=Scheduled job=None
97.0417,Job,MODIFIED,eval-sanitize-20-r3-096,
97.0449,Event,ADDED,eval-sanitize-20-r3-097.18d41b3e191e558a,reason=SuccessfulCreate count=1 msg=Created pod: eval-sanitize-20-r3-097-8f4hj
97.0457,Job,MODIFIED,eval-sanitize-20-r3-097,
97.0472,Event,ADDED,eval-sanitize-20-r3-097-8f4hj.18d41b3e19617297,"reason=FailedScheduling count=None msg=0/6 nodes are available: 1 c_wall violated: 1 conflicting context pair(s) with node memory, 5 node(s) had untolerated taint(s). no new claims to deallocate, preemption: 0/6 nodes are available: 1 No preemption victims found for incoming pod, 5 Preemption is not helpful for scheduling."
97.0474,TaskRequest,MODIFIED,eval-sanitize-20-r3-097,phase=Scheduled job=None
97.0484,Pod,MODIFIED,eval-sanitize-20-r3-097-8f4hj,phase=Pending node=None
97.0495,Job,MODIFIED,eval-sanitize-20-r3-096,
97.0516,Job,MODIFIED,eval-sanitize-20-r3-097,
97.0547,Event,ADDED,eval-sanitize-20-r3-097-8f4hj.18d41b3e19fe374f,"reason=FailedScheduling count=None msg=0/6 nodes are available: 1 c_wall violated: 1 conflicting context pair(s) with node memory, 5 node(s) had untolerated taint(s). no new claims to deallocate, preemption: 0/6 nodes are available: 1 No preemption victims found for incoming pod, 5 Preemption is not helpful for scheduling."
97.0601,Job,MODIFIED,eval-sanitize-20-r3-097,
97.1497,Pod,MODIFIED,eval-sanitize-20-r3-096-tm8xd,phase=Running node=kind-worker4
97.1508,Job,MODIFIED,eval-sanitize-20-r3-085,
97.1548,Job,MODIFIED,eval-sanitize-20-r3-083,
97.1594,Job,MODIFIED,eval-sanitize-20-r3-083,
97.1617,Job,MODIFIED,eval-sanitize-20-r3-085,
97.1671,Event,ADDED,eval-sanitize-20-r3-083.18d41b3e2068b813,reason=Completed count=1 msg=Job completed
97.1724,Job,MODIFIED,eval-sanitize-20-r3-083,
97.1728,Event,MODIFIED,eval-sanitize-20-r3-097-8f4hj.18d41b3e19fe374f,"reason=FailedScheduling count=None msg=0/6 nodes are available: 1 c_wall violated: 1 conflicting context pair(s) with node memory, 5 node(s) had untolerated taint(s). no new claims to deallocate, preemption: 0/6 nodes are available: 1 No preemption victims found for incoming pod, 5 Preemption is not helpful for scheduling."
97.1786,TaskRequest,MODIFIED,eval-sanitize-20-r3-083,phase=Complete job=None
97.1881,Job,MODIFIED,eval-sanitize-20-r3-083,
97.2393,Pod,MODIFIED,eval-sanitize-20-r3-085-645dg,phase=Succeeded node=kind-worker2
97.2761,Job,MODIFIED,eval-sanitize-20-r3-084,
97.2845,Pod,MODIFIED,eval-sanitize-20-r3-084-mrxnw,phase=Succeeded node=kind-worker5
97.2856,Job,MODIFIED,eval-sanitize-20-r3-084,
97.9032,Job,MODIFIED,eval-sanitize-20-r3-086,
97.9138,Job,MODIFIED,eval-sanitize-20-r3-086,
98.0093,TaskRequest,ADDED,eval-sanitize-20-r3-098,phase=None job=None
98.0132,TaskRequest,MODIFIED,eval-sanitize-20-r3-098,phase=Pending job=None
98.0325,Job,ADDED,eval-sanitize-20-r3-098,
98.0339,Pod,MODIFIED,eval-sanitize-20-r3-086-qf972,phase=Succeeded node=kind-worker
98.0402,Pod,ADDED,eval-sanitize-20-r3-098-76b9t,phase=Pending node=None
98.0405,TaskRequest,MODIFIED,eval-sanitize-20-r3-098,phase=Scheduled job=None
98.0465,Job,MODIFIED,eval-sanitize-20-r3-098,
98.0476,Event,ADDED,eval-sanitize-20-r3-098.18d41b3e54e496f5,reason=SuccessfulCreate count=1 msg=Created pod: eval-sanitize-20-r3-098-76b9t
98.0484,Job,MODIFIED,eval-sanitize-20-r3-096,
98.0508,Pod,MODIFIED,eval-sanitize-20-r3-098-76b9t,phase=Pending node=None
98.0511,Event,ADDED,eval-sanitize-20-r3-098-76b9t.18d41b3e5537556a,"reason=FailedScheduling count=None msg=0/6 nodes are available: 1 c_wall violated: 1 conflicting context pair(s) with node memory, 5 node(s) had untolerated taint(s). no new claims to deallocate, preemption: 0/6 nodes are available: 1 No preemption victims found for incoming pod, 5 Preemption is not helpful for scheduling."
98.0512,TaskRequest,MODIFIED,eval-sanitize-20-r3-098,phase=Scheduled job=None
98.0554,Job,MODIFIED,eval-sanitize-20-r3-098,
98.0577,Job,MODIFIED,eval-sanitize-20-r3-096,
98.0654,Job,MODIFIED,eval-sanitize-20-r3-098,
