t_recv,kind,type,name,detail
0.0213,Node,ADDED,kind-control-plane,taints=1
0.0233,Node,ADDED,kind-worker,taints=0
0.0245,Node,ADDED,kind-worker2,taints=0
0.0256,Node,ADDED,kind-worker3,taints=0
0.027,Node,ADDED,kind-worker4,taints=0
0.0281,Node,ADDED,kind-worker5,taints=0
0.0372,TaskRequest,ADDED,eval-sanitize-10-r3-000,phase=None job=None
0.0423,TaskRequest,MODIFIED,eval-sanitize-10-r3-000,phase=Pending job=None
0.0581,Job,ADDED,eval-sanitize-10-r3-000,
0.0584,Event,ADDED,eval-image-prepull-65b6g.18d4e35acdf3e476,reason=Scheduled count=1 msg=Successfully assigned compute/eval-image-prepull-65b6g to kind-worker4
0.0589,Event,ADDED,eval-image-prepull-65b6g.18d4e35aed672d76,"reason=Pulling count=1 msg=Pulling image ""busybox:musl"""
0.0591,Event,ADDED,eval-image-prepull-65b6g.18d4e35b9167000d,"reason=Pulled count=1 msg=Successfully pulled image ""busybox:musl"" in 2.751s (2.751s including waiting). Image size: 895652 bytes."
0.0593,Event,ADDED,eval-image-prepull-65b6g.18d4e35b93055405,reason=Created count=1 msg=Created container: pause
0.0597,Event,ADDED,eval-image-prepull-65b6g.18d4e35b95017365,reason=Started count=1 msg=Started container pause
0.0605,Event,ADDED,eval-image-prepull-65b6g.18d4e35c2763564c,reason=Killing count=1 msg=Stopping container pause
0.0609,Event,ADDED,eval-image-prepull-kwmc6.18d4e35ace6ce42b,reason=Scheduled count=1 msg=Successfully assigned compute/eval-image-prepull-kwmc6 to kind-worker3
0.0613,Event,ADDED,eval-image-prepull-kwmc6.18d4e35aed5c6f99,"reason=Pulling count=1 msg=Pulling image ""busybox:musl"""
0.0619,Event,ADDED,eval-image-prepull-kwmc6.18d4e35ba2b44112,"reason=Pulled count=1 msg=Successfully pulled image ""busybox:musl"" in 3.042s (3.042s including waiting). Image size: 895652 bytes."
0.0622,Event,ADDED,eval-image-prepull-kwmc6.18d4e35ba3d92f8f,reason=Created count=1 msg=Created container: pause
0.0625,Event,ADDED,eval-image-prepull-kwmc6.18d4e35ba6a6bcc6,reason=Started count=1 msg=Started container pause
0.0628,Event,ADDED,eval-image-prepull-kwmc6.18d4e35c59a27d19,reason=Killing count=1 msg=Stopping container pause
0.0633,Event,ADDED,eval-image-prepull-pgs6x.18d4e35ace8fb9ed,reason=Scheduled count=1 msg=Successfully assigned compute/eval-image-prepull-pgs6x to kind-worker
0.0636,Event,ADDED,eval-image-prepull-pgs6x.18d4e35aed548225,"reason=Pulling count=1 msg=Pulling image ""busybox:musl"""
0.0639,Event,ADDED,eval-image-prepull-pgs6x.18d4e35ba03f5f31,"reason=Pulled count=1 msg=Successfully pulled image ""busybox:musl"" in 3.001s (3.001s including waiting). Image size: 895652 bytes."
0.064,Event,ADDED,eval-image-prepull-pgs6x.18d4e35ba1a6bdc9,reason=Created count=1 msg=Created container: pause
0.0644,TaskRequest,MODIFIED,eval-sanitize-10-r3-000,phase=Scheduled job=None
0.0647,Event,ADDED,eval-image-prepull-pgs6x.18d4e35ba659c36d,reason=Started count=1 msg=Started container pause
0.065,Event,ADDED,eval-image-prepull-pgs6x.18d4e35c2843c0a2,reason=Killing count=1 msg=Stopping container pause
0.0652,Event,ADDED,eval-image-prepull-rnd7x.18d4e35acefec1a1,reason=Scheduled count=1 msg=Successfully assigned compute/eval-image-prepull-rnd7x to kind-worker5
0.0655,Event,ADDED,eval-image-prepull-rnd7x.18d4e35aed3c5f49,"reason=Pulling count=1 msg=Pulling image ""busybox:musl"""
0.0657,Event,ADDED,eval-image-prepull-rnd7x.18d4e35b8d4c0b7b,"reason=Pulled count=1 msg=Successfully pulled image ""busybox:musl"" in 2.685s (2.685s including waiting). Image size: 895652 bytes."
0.0661,Event,ADDED,eval-image-prepull-rnd7x.18d4e35b8ed12826,reason=Created count=1 msg=Created container: pause
0.0666,Event,ADDED,eval-image-prepull-rnd7x.18d4e35b931fd41f,reason=Started count=1 msg=Started container pause
0.0672,Event,ADDED,eval-image-prepull-rnd7x.18d4e35c25f96533,reason=Killing count=1 msg=Stopping container pause
0.0676,Event,ADDED,eval-image-prepull-tgpld.18d4e35acf003d1a,reason=Scheduled count=1 msg=Successfully assigned compute/eval-image-prepull-tgpld to kind-worker2
0.0679,Event,ADDED,eval-image-prepull-tgpld.18d4e35aed33b0b3,"reason=Pulling count=1 msg=Pulling image ""busybox:musl"""
0.0684,Event,ADDED,eval-image-prepull-tgpld.18d4e35b901f668e,"reason=Pulled count=1 msg=Successfully pulled image ""busybox:musl"" in 2.733s (2.733s including waiting). Image size: 895652 bytes."
0.0686,Event,ADDED,eval-image-prepull-tgpld.18d4e35b91d753b1,reason=Created count=1 msg=Created container: pause
0.0689,Event,ADDED,eval-image-prepull-tgpld.18d4e35b93ee7f67,reason=Started count=1 msg=Started container pause
0.0691,Event,ADDED,eval-image-prepull-tgpld.18d4e35c25ed5bb5,reason=Killing count=1 msg=Stopping container pause
0.0695,Event,ADDED,eval-image-prepull.18d4e35acda4fbcc,reason=SuccessfulCreate count=1 msg=Created pod: eval-image-prepull-65b6g
0.0697,Event,ADDED,eval-image-prepull.18d4e35ace207db2,reason=SuccessfulCreate count=1 msg=Created pod: eval-image-prepull-kwmc6
0.0699,Event,ADDED,eval-image-prepull.18d4e35ace208118,reason=SuccessfulCreate count=1 msg=Created pod: eval-image-prepull-pgs6x
0.0703,Event,ADDED,eval-image-prepull.18d4e35ace915fc1,reason=SuccessfulCreate count=1 msg=Created pod: eval-image-prepull-rnd7x
0.0713,Pod,ADDED,eval-sanitize-10-r3-000-nnzw4,phase=Pending node=None
0.0718,Event,ADDED,eval-image-prepull.18d4e35ace9350c7,reason=SuccessfulCreate count=1 msg=Created pod: eval-image-prepull-tgpld
0.0721,Event,ADDED,eval-sanitize-10-r0-000-47slc.18d4e4a6258e0f44,reason=Scheduled count=None msg=Successfully assigned compute/eval-sanitize-10-r0-000-47slc to kind-worker5
0.0723,Event,ADDED,eval-sanitize-10-r0-000-47slc.18d4e4a640a1aa7a,"reason=Pulled count=1 msg=Container image ""busybox:musl"" already present on machine"
0.0726,Event,ADDED,eval-sanitize-10-r0-000-47slc.18d4e4a641c78cc1,reason=Created count=1 msg=Created container: task
0.0734,Job,MODIFIED,eval-sanitize-10-r3-000,
0.0737,Event,ADDED,eval-sanitize-10-r0-000-47slc.18d4e4a647aa6e5c,reason=Started count=1 msg=Started container task
0.0739,Event,ADDED,eval-sanitize-10-r0-000.18d4e4a61b902352,reason=SuccessfulCreate count=1 msg=Created pod: eval-sanitize-10-r0-000-47slc
0.0741,Event,ADDED,eval-sanitize-10-r0-000.18d4e4abbd3d8d96,reason=Completed count=1 msg=Job completed
0.0744,Event,ADDED,eval-sanitize-10-r0-001-rsj9h.18d4e4a6563cc4af,reason=Scheduled count=None msg=Successfully assigned compute/eval-sanitize-10-r0-001-rsj9h to kind-worker
0.0745,Event,ADDED,eval-sanitize-10-r0-001-rsj9h.18d4e4a66f50005c,"reason=Pulled count=1 msg=Container image ""busybox:musl"" already present on machine"
0.0747,Event,ADDED,eval-sanitize-10-r0-001-rsj9h.18d4e4a6706598f5,reason=Created count=1 msg=Created container: task
0.075,Event,ADDED,eval-sanitize-10-r0-001-rsj9h.18d4e4a6723d332a,reason=Started count=1 msg=Started container task
0.0756,Event,ADDED,eval-sanitize-10-r0-001.18d4e4a65529be48,reason=SuccessfulCreate count=1 msg=Created pod: eval-sanitize-10-r0-001-rsj9h
0.0759,Event,ADDED,eval-sanitize-10-r0-001.18d4e4ac050eb969,reason=Completed count=1 msg=Job completed
0.0761,Event,ADDED,eval-sanitize-10-r0-002-ljlrw.18d4e4a69238bca0,reason=Scheduled count=None msg=Successfully assigned compute/eval-sanitize-10-r0-002-ljlrw to kind-worker5
0.0763,Event,ADDED,eval-sanitize-10-r0-002-ljlrw.18d4e4a6ad4b9419,"reason=Pulled count=1 msg=Container image ""busybox:musl"" already present on machine"
0.0767,Event,ADDED,eval-sanitize-10-r0-002-ljlrw.18d4e4a6ae599fc7,reason=Created count=1 msg=Created container: task
0.077,Event,ADDED,eval-sanitize-10-r0-002-ljlrw.18d4e4a6b547d630,reason=Started count=1 msg=Started container task
0.0772,Event,ADDED,eval-sanitize-10-r0-002.18d4e4a6913d6125,reason=SuccessfulCreate count=1 msg=Created pod: eval-sanitize-10-r0-002-ljlrw
0.0775,Event,ADDED,eval-sanitize-10-r0-002.18d4e4ac35fcca27,reason=Completed count=1 msg=Job completed
0.0777,Event,ADDED,eval-sanitize-10-r0-003-rb7tr.18d4e4a6d20f24bd,reason=Scheduled count=None msg=Successfully assigned compute/eval-sanitize-10-r0-003-rb7tr to kind-worker2
0.0779,Event,ADDED,eval-sanitize-10-r0-003-rb7tr.18d4e4a6ebf8ec8b,"reason=Pulled count=1 msg=Container image ""busybox:musl"" already present on machine"
0.0781,Event,ADDED,eval-sanitize-10-r0-003-rb7tr.18d4e4a6ed1770a1,reason=Created count=1 msg=Created container: task
0.0785,Event,ADDED,eval-sanitize-10-r0-003-rb7tr.18d4e4a6ef1e035f,reason=Started count=1 msg=Started container task
0.0786,Event,ADDED,eval-sanitize-10-r0-003.18d4e4a6d12d0504,reason=SuccessfulCreate count=1 msg=Created pod: eval-sanitize-10-r0-003-rb7tr
0.0788,Event,ADDED,eval-sanitize-10-r0-003.18d4e4ac9685420f,reason=Completed count=1 msg=Job completed
0.079,Event,ADDED,eval-sanitize-10-r0-004-zzlg6.18d4e4a709384893,reason=Scheduled count=None msg=Successfully assigned compute/eval-sanitize-10-r0-004-zzlg6 to kind-worker4
0.0793,Event,ADDED,eval-sanitize-10-r0-004-zzlg6.18d4e4a724eba5cd,"reason=Pulled count=1 msg=Container image ""busybox:musl"" already present on machine"
0.0795,Event,ADDED,eval-sanitize-10-r0-004-zzlg6.18d4e4a72631931a,reason=Created count=1 msg=Created container: task
0.0797,Event,ADDED,eval-sanitize-10-r0-004-zzlg6.18d4e4a72a0d517e,reason=Started count=1 msg=Started container task
0.0802,Event,ADDED,eval-sanitize-10-r0-004.18d4e4a708136e56,reason=SuccessfulCreate count=1 msg=Created pod: eval-sanitize-10-r0-004-zzlg6
0.0805,Event,ADDED,eval-sanitize-10-r0-004.18d4e4acd3349d62,reason=Completed count=1 msg=Job completed
0.0807,Event,ADDED,eval-sanitize-10-r0-005-vg58w.18d4e4a7450c202e,reason=Scheduled count=None msg=Successfully assigned compute/eval-sanitize-10-r0-005-vg58w to kind-worker
0.081,Event,ADDED,eval-sanitize-10-r0-005-vg58w.18d4e4a760734f23,"reason=Pulled count=1 msg=Container image ""busybox:musl"" already present on machine"
0.0814,Event,ADDED,eval-sanitize-10-r0-005-vg58w.18d4e4a7619eda22,reason=Created count=1 msg=Created container: task
0.0816,Event,ADDED,eval-sanitize-10-r0-005-vg58w.18d4e4a76a610bdf,reason=Started count=1 msg=Started container task
0.0818,Event,ADDED,eval-sanitize-10-r0-005.18d4e4a743942a4f,reason=SuccessfulCreate count=1 msg=Created pod: eval-sanitize-10-r0-005-vg58w
0.0819,Event,ADDED,eval-sanitize-10-r0-005.18d4e4acfae369b6,reason=Completed count=1 msg=Job completed
0.0823,Event,ADDED,eval-sanitize-10-r0-006-rx9xb.18d4e4a78327ece1,reason=Scheduled count=None msg=Successfully assigned compute/eval-sanitize-10-r0-006-rx9xb to kind-worker4
0.0825,Event,ADDED,eval-sanitize-10-r0-006-rx9xb.18d4e4a7a4fecbe3,"reason=Pulled count=1 msg=Container image ""busybox:musl"" already present on machine"
0.0826,Event,ADDED,eval-sanitize-10-r0-006-rx9xb.18d4e4a7a61627a2,reason=Created count=1 msg=Created container: task
0.0832,Event,ADDED,eval-sanitize-10-r0-006-rx9xb.18d4e4a7abd102e8,reason=Started count=1 msg=Started container task
0.0834,Event,ADDED,eval-sanitize-10-r0-006.18d4e4a7823839ca,reason=SuccessfulCreate count=1 msg=Created pod: eval-sanitize-10-r0-006-rx9xb
0.0836,Event,ADDED,eval-sanitize-10-r0-006.18d4e4ad13ad7c69,reason=Completed count=1 msg=Job completed
0.0838,Event,ADDED,eval-sanitize-10-r0-007-s25l2.18d4e4a7bb09b66a,reason=Scheduled count=None msg=Successfully assigned compute/eval-sanitize-10-r0-007-s25l2 to kind-worker3
0.0842,Event,ADDED,eval-sanitize-10-r0-007-s25l2.18d4e4a7d62d557e,"reason=Pulled count=1 msg=Container image ""busybox:musl"" already present on machine"
0.0844,Event,ADDED,eval-sanitize-10-r0-007-s25l2.18d4e4a7d7477b72,reason=Created count=1 msg=Created container: task
0.0846,Event,ADDED,eval-sanitize-10-r0-007-s25l2.18d4e4a7da34ea26,reason=Started count=1 msg=Started container task
0.0847,Event,ADDED,eval-sanitize-10-r0-007.18d4e4a7baa5fee9,reason=SuccessfulCreate count=1 msg=Created pod: eval-sanitize-10-r0-007-s25l2
0.0851,Event,ADDED,eval-sanitize-10-r0-007.18d4e4ad5f173dbf,reason=Completed count=1 msg=Job completed
0.0853,Event,ADDED,eval-sanitize-10-r0-008-27nls.18d4e4a7f70c1395,"reason=FailedScheduling count=None msg=0/6 nodes are available: 1 c_wall violated: 1 conflicting context pair(s) with node memory, 5 node(s) had untolerated taint(s). no new claims to deallocate, preemption: 0/6 nodes are available: 1 No preemption victims found for incoming pod, 5 Preemption is not helpful for scheduling."
0.0855,Event,ADDED,eval-sanitize-10-r0-008-27nls.18d4e4a7f7c50564,"reason=FailedScheduling count=None msg=0/6 nodes are available: 1 c_wall violated: 1 conflicting context pair(s) with node memory, 5 node(s) had untolerated taint(s). no new claims to deallocate, preemption: 0/6 nodes are available: 1 No preemption victims found for incoming pod, 5 Preemption is not helpful for scheduling."
0.0865,Event,ADDED,eval-sanitize-10-r0-008-27nls.18d4e4a8706e2f2d,"reason=FailedScheduling count=None msg=0/6 nodes are available: 1 c_wall violated: 2 conflicting context pair(s) with node memory, 5 node(s) had untolerated taint(s). no new claims to deallocate, preemption: 0/6 nodes are available: 1 No preemption victims found for incoming pod, 5 Preemption is not helpful for scheduling."
0.0867,Event,ADDED,eval-sanitize-10-r0-008-27nls.18d4e4ac375abbba,reason=Scheduled count=None msg=Successfully assigned compute/eval-sanitize-10-r0-008-27nls to kind-worker2
0.0869,Event,ADDED,eval-sanitize-10-r0-008-27nls.18d4e4ac59394466,"reason=Pulled count=1 msg=Container image ""busybox:musl"" already present on machine"
0.0873,Event,ADDED,eval-sanitize-10-r0-008-27nls.18d4e4ac5a8caaae,reason=Created count=1 msg=Created container: task
0.0878,Event,ADDED,eval-sanitize-10-r0-008-27nls.18d4e4ac5e88e29f,reason=Started count=1 msg=Started container task
0.0883,Event,ADDED,eval-sanitize-10-r0-008.18d4e4a7f6c9bb2f,reason=SuccessfulCreate count=1 msg=Created pod: eval-sanitize-10-r0-008-27nls
0.0885,Event,ADDED,eval-sanitize-10-r0-008.18d4e4b1ec17fb2a,reason=Completed count=1 msg=Job completed
0.0895,Pod,MODIFIED,eval-sanitize-10-r3-000-nnzw4,phase=Pending node=kind-worker5
0.0898,Event,ADDED,eval-sanitize-10-r0-009-zrk9r.18d4e4a832deffde,"reason=FailedScheduling count=None msg=0/6 nodes are available: 1 c_wall violated: 1 conflicting context pair(s) with node memory, 5 node(s) had untolerated taint(s). no new claims to deallocate, preemption: 0/6 nodes are available: 1 No preemption victims found for incoming pod, 5 Preemption is not helpful for scheduling."
0.09,Event,ADDED,eval-sanitize-10-r0-009-zrk9r.18d4e4a8336d12c4,"reason=FailedScheduling count=None msg=0/6 nodes are available: 1 c_wall violated: 1 conflicting context pair(s) with node memory, 5 node(s) had untolerated taint(s). no new claims to deallocate, preemption: 0/6 nodes are available: 1 No preemption victims found for incoming pod, 5 Preemption is not helpful for scheduling."
0.0902,Event,ADDED,eval-sanitize-10-r0-009-zrk9r.18d4e4ac37910b2a,"reason=FailedScheduling count=None msg=0/6 nodes are available: 1 c_wall violated: 1 conflicting context pair(s) with node memory, 5 node(s) had untolerated taint(s). no new claims to deallocate, preemption: 0/6 nodes are available: 1 No preemption victims found for incoming pod, 5 Preemption is not helpful for scheduling."
0.0906,Event,ADDED,eval-sanitize-10-r0-009-zrk9r.18d4e4ac43d6615d,"reason=FailedScheduling count=None msg=0/6 nodes are available: 1 c_wall violated: 1 conflicting context pair(s) with node memory, 5 node(s) had untolerated taint(s). no new claims to deallocate, preemption: 0/6 nodes are available: 1 No preemption victims found for incoming pod, 5 Preemption is not helpful for scheduling."
0.0908,Event,ADDED,eval-sanitize-10-r0-009-zrk9r.18d4e4ac7d2a9ab8,reason=Scheduled count=None msg=Successfully assigned compute/eval-sanitize-10-r0-009-zrk9r to kind-worker5
0.0909,Event,ADDED,eval-sanitize-10-r0-009-zrk9r.18d4e4acad2d2148,"reason=Pulled count=1 msg=Container image ""busybox:musl"" already present on machine"
0.0913,Event,ADDED,eval-sanitize-10-r0-009-zrk9r.18d4e4acaee41652,reason=Created count=1 msg=Created container: task
0.0915,Event,ADDED,eval-sanitize-10-r0-009-zrk9r.18d4e4acb0c91892,reason=Started count=1 msg=Started container task
0.0919,Event,ADDED,eval-sanitize-10-r0-009.18d4e4a83296f134,reason=SuccessfulCreate count=1 msg=Created pod: eval-sanitize-10-r0-009-zrk9r
0.0921,Event,ADDED,eval-sanitize-10-r0-009.18d4e4b2c4e31f54,reason=Completed count=1 msg=Job completed
0.0923,TaskRequest,MODIFIED,eval-sanitize-10-r3-000,phase=Scheduled job=None
0.0926,Event,ADDED,eval-sanitize-10-r0-010-wqr8t.18d4e4a86f74b2a3,reason=Scheduled count=None msg=Successfully assigned compute/eval-sanitize-10-r0-010-wqr8t to kind-worker3
0.0929,Event,ADDED,eval-sanitize-10-r0-010-wqr8t.18d4e4a888ce8cdd,"reason=Pulled count=1 msg=Container image ""busybox:musl"" already present on machine"
0.0931,Event,ADDED,eval-sanitize-10-r0-010-wqr8t.18d4e4a889f6632c,reason=Created count=1 msg=Created container: task
0.0935,Event,ADDED,eval-sanitize-10-r0-010-wqr8t.18d4e4a88f936cc1,reason=Started count=1 msg=Started container task
0.0937,Event,ADDED,eval-sanitize-10-r0-010.18d4e4a86eefccfb,reason=SuccessfulCreate count=1 msg=Created pod: eval-sanitize-10-r0-010-wqr8t
0.0939,Event,ADDED,eval-sanitize-10-r0-010.18d4e4ae1e127d46,reason=Completed count=1 msg=Job completed
0.094,Event,ADDED,eval-sanitize-10-r0-011-q6442.18d4e4a8a9e1dcdb,reason=Scheduled count=None msg=Successfully assigned compute/eval-sanitize-10-r0-011-q6442 to kind-worker3
0.0944,Event,ADDED,eval-sanitize-10-r0-011-q6442.18d4e4a8c8445177,"reason=Pulled count=1 msg=Container image ""busybox:musl"" already present on machine"
0.0946,Event,ADDED,eval-sanitize-10-r0-011-q6442.18d4e4a8c962fb59,reason=Created count=1 msg=Created container: task
0.0948,Event,ADDED,eval-sanitize-10-r0-011-q6442.18d4e4a8cd5486bc,reason=Started count=1 msg=Started container task
0.0951,Event,ADDED,eval-sanitize-10-r0-011.18d4e4a8a94a2218,reason=SuccessfulCreate count=1 msg=Created pod: eval-sanitize-10-r0-011-q6442
0.0954,Event,ADDED,eval-sanitize-10-r0-011.18d4e4ae5c999b33,reason=Completed count=1 msg=Job completed
0.0955,Event,ADDED,eval-sanitize-10-r0-012-drlp2.18d4e4a8e7179e1a,"reason=FailedScheduling count=None msg=0/6 nodes are available: 1 c_wall violated: 1 conflicting context pair(s) with node memory, 5 node(s) had untolerated taint(s). no new claims to deallocate, preemption: 0/6 nodes are available: 1 No preemption victims found for incoming pod, 5 Preemption is not helpful for scheduling."
0.0958,Event,ADDED,eval-sanitize-10-r0-012-drlp2.18d4e4a8e7a95d1c,"reason=FailedScheduling count=None msg=0/6 nodes are available: 1 c_wall violated: 1 conflicting context pair(s) with node memory, 5 node(s) had untolerated taint(s). no new claims to deallocate, preemption: 0/6 nodes are available: 1 No preemption victims found for incoming pod, 5 Preemption is not helpful for scheduling."
0.0963,Event,ADDED,eval-sanitize-10-r0-012-drlp2.18d4e4ac38846570,reason=Scheduled count=None msg=Successfully assigned compute/eval-sanitize-10-r0-012-drlp2 to kind-worker2
0.0966,Event,ADDED,eval-sanitize-10-r0-012-drlp2.18d4e4ac61ec80c5,"reason=Pulled count=1 msg=Container image ""busybox:musl"" already present on machine"
0.0969,Event,ADDED,eval-sanitize-10-r0-012-drlp2.18d4e4ac63574101,reason=Created count=1 msg=Created container: task
0.0971,Event,ADDED,eval-sanitize-10-r0-012-drlp2.18d4e4ac6b0a186d,reason=Started count=1 msg=Started container task
0.0974,Event,ADDED,eval-sanitize-10-r0-012.18d4e4a8e6d025d3,reason=SuccessfulCreate count=1 msg=Created pod: eval-sanitize-10-r0-012-drlp2
0.0976,Event,ADDED,eval-sanitize-10-r0-012.18d4e4b1ed306510,reason=Completed count=1 msg=Job completed
0.0977,Event,ADDED,eval-sanitize-10-r0-013-b6m5m.18d4e4a924e82d67,reason=Scheduled count=None msg=Successfully assigned compute/eval-sanitize-10-r0-013-b6m5m to kind-worker3
0.0997,Node,MODIFIED,kind-worker5,taints=0
0.0999,Event,ADDED,eval-sanitize-10-r0-013-b6m5m.18d4e4a94aab797d,"reason=Pulled count=1 msg=Container image ""busybox:musl"" already present on machine"
0.1001,Event,ADDED,eval-sanitize-10-r0-013-b6m5m.18d4e4a94bcf9a85,reason=Created count=1 msg=Created container: task
0.1003,Event,ADDED,eval-sanitize-10-r0-013-b6m5m.18d4e4a9552417f0,reason=Started count=1 msg=Started container task
0.1004,Event,ADDED,eval-sanitize-10-r0-013.18d4e4a92466cad1,reason=SuccessfulCreate count=1 msg=Created pod: eval-sanitize-10-r0-013-b6m5m
0.1012,Event,ADDED,eval-sanitize-10-r0-013.18d4e4aeccd07951,reason=Completed count=1 msg=Job completed
0.1015,Event,ADDED,eval-sanitize-10-r0-014-c597g.18d4e4a964cf81de,"reason=FailedScheduling count=None msg=0/6 nodes are available: 1 c_wall violated: 1 conflicting context pair(s) with node memory, 5 node(s) had untolerated taint(s). no new claims to deallocate, preemption: 0/6 nodes are available: 1 No preemption victims found for incoming pod, 5 Preemption is not helpful for scheduling."
0.1017,Event,ADDED,eval-sanitize-10-r0-014-c597g.18d4e4a965e9f9dd,"reason=FailedScheduling count=None msg=0/6 nodes are available: 1 c_wall violated: 1 conflicting context pair(s) with node memory, 5 node(s) had untolerated taint(s). no new claims to deallocate, preemption: 0/6 nodes are available: 1 No preemption victims found for incoming pod, 5 Preemption is not helpful for scheduling."
0.102,Event,ADDED,eval-sanitize-10-r0-014-c597g.18d4e4ac38558634,"reason=FailedScheduling count=None msg=0/6 nodes are available: 1 c_wall violated: 1 conflicting context pair(s) with node memory, 5 node(s) had untolerated taint(s). no new claims to deallocate, preemption: 0/6 nodes are available: 1 No preemption victims found for incoming pod, 5 Preemption is not helpful for scheduling."
0.1022,Event,ADDED,eval-sanitize-10-r0-014-c597g.18d4e4ac4838c835,"reason=FailedScheduling count=None msg=0/6 nodes are available: 1 c_wall violated: 1 conflicting context pair(s) with node memory, 5 node(s) had untolerated taint(s). no new claims to deallocate, preemption: 0/6 nodes are available: 1 No preemption victims found for incoming pod, 5 Preemption is not helpful for scheduling."
0.1024,Event,ADDED,eval-sanitize-10-r0-014-c597g.18d4e4ac80d87dc8,reason=Scheduled count=None msg=Successfully assigned compute/eval-sanitize-10-r0-014-c597g to kind-worker5
0.1035,Pod,MODIFIED,eval-sanitize-10-r3-000-nnzw4,phase=Pending node=kind-worker5
0.1038,Event,ADDED,eval-sanitize-10-r0-014-c597g.18d4e4acae9f318e,"reason=Pulled count=1 msg=Container image ""busybox:musl"" already present on machine"
0.104,Event,ADDED,eval-sanitize-10-r0-014-c597g.18d4e4acb036a785,reason=Created count=1 msg=Created container: task
0.1042,Event,ADDED,eval-sanitize-10-r0-014-c597g.18d4e4acb22e18e2,reason=Started count=1 msg=Started container task
0.1043,Event,ADDED,eval-sanitize-10-r0-014.18d4e4a96486edef,reason=SuccessfulCreate count=1 msg=Created pod: eval-sanitize-10-r0-014-c597g
0.1046,Event,ADDED,eval-sanitize-10-r0-014.18d4e4b2b954268a,reason=Completed count=1 msg=Job completed
0.1047,Event,ADDED,eval-sanitize-10-r0-015-8787w.18d4e4a99a37a668,"reason=FailedScheduling count=None msg=0/6 nodes are available: 1 c_wall violated: 1 conflicting context pair(s) with node memory, 5 node(s) had untolerated taint(s). no new claims to deallocate, preemption: 0/6 nodes are available: 1 No preemption victims found for incoming pod, 5 Preemption is not helpful for scheduling."
0.105,Event,ADDED,eval-sanitize-10-r0-015-8787w.18d4e4a99aae2582,"reason=FailedScheduling count=None msg=0/6 nodes are available: 1 c_wall violated: 1 conflicting context pair(s) with node memory, 5 node(s) had untolerated taint(s). no new claims to deallocate, preemption: 0/6 nodes are available: 1 No preemption victims found for incoming pod, 5 Preemption is not helpful for scheduling."
0.1053,Event,ADDED,eval-sanitize-10-r0-015-8787w.18d4e4ac38d4e599,"reason=FailedScheduling count=None msg=0/6 nodes are available: 1 c_wall violated: 1 conflicting context pair(s) with node memory, 5 node(s) had untolerated taint(s). no new claims to deallocate, preemption: 0/6 nodes are available: 1 No preemption victims found for incoming pod, 5 Preemption is not helpful for scheduling."
0.1055,Event,ADDED,eval-sanitize-10-r0-015-8787w.18d4e4ac48664796,"reason=FailedScheduling count=None msg=0/6 nodes are available: 1 c_wall violated: 1 conflicting context pair(s) with node memory, 5 node(s) had untolerated taint(s). no new claims to deallocate, preemption: 0/6 nodes are available: 1 No preemption victims found for incoming pod, 5 Preemption is not helpful for scheduling."
0.1056,Event,ADDED,eval-sanitize-10-r0-015-8787w.18d4e4ac8125f343,reason=Scheduled count=None msg=Successfully assigned compute/eval-sanitize-10-r0-015-8787w to kind-worker5
0.1061,Event,ADDED,eval-sanitize-10-r0-015-8787w.18d4e4acaee976e5,"reason=Pulled count=1 msg=Container image ""busybox:musl"" already present on machine"
0.1063,Event,ADDED,eval-sanitize-10-r0-015-8787w.18d4e4acb0c5b436,reason=Created count=1 msg=Created container: task
0.1065,Event,ADDED,eval-sanitize-10-r0-015-8787w.18d4e4acb2bad772,reason=Started count=1 msg=Started container task
0.1066,Event,ADDED,eval-sanitize-10-r0-015.18d4e4a999f0afd2,reason=SuccessfulCreate count=1 msg=Created pod: eval-sanitize-10-r0-015-8787w
0.107,Event,ADDED,eval-sanitize-10-r0-015.18d4e4b2c221d4b7,reason=Completed count=1 msg=Job completed
0.1072,Event,ADDED,eval-sanitize-10-r0-016-nx566.18d4e4a9d5e83751,"reason=FailedScheduling count=None msg=0/6 nodes are available: 1 c_wall violated: 1 conflicting context pair(s) with node memory, 5 node(s) had untolerated taint(s). no new claims to deallocate, preemption: 0/6 nodes are available: 1 No preemption victims found for incoming pod, 5 Preemption is not helpful for scheduling."
0.1074,Event,ADDED,eval-sanitize-10-r0-016-nx566.18d4e4a9d6743042,"reason=FailedScheduling count=None msg=0/6 nodes are available: 1 c_wall violated: 1 conflicting context pair(s) with node memory, 5 node(s) had untolerated taint(s). no new claims to deallocate, preemption: 0/6 nodes are available: 1 No preemption victims found for incoming pod, 5 Preemption is not helpful for scheduling."
0.1077,Event,ADDED,eval-sanitize-10-r0-016-nx566.18d4e4ac3c0fbf56,"reason=FailedScheduling count=None msg=0/6 nodes are available: 1 c_wall violated: 1 conflicting context pair(s) with node memory, 5 node(s) had untolerated taint(s). no new claims to deallocate, preemption: 0/6 nodes are available: 1 No preemption victims found for incoming pod, 5 Preemption is not helpful for scheduling."
0.1079,Event,ADDED,eval-sanitize-10-r0-016-nx566.18d4e4ac48a2fc26,"reason=FailedScheduling count=None msg=0/6 nodes are available: 1 c_wall violated: 2 conflicting context pair(s) with node memory, 5 node(s) had untolerated taint(s). no new claims to deallocate, preemption: 0/6 nodes are available: 1 No preemption victims found for incoming pod, 5 Preemption is not helpful for scheduling."
0.1082,Event,ADDED,eval-sanitize-10-r0-016-nx566.18d4e4ac55b9adad,"reason=FailedScheduling count=None msg=0/6 nodes are available: 1 c_wall violated: 2 conflicting context pair(s) with node memory, 5 node(s) had untolerated taint(s). no new claims to deallocate, preemption: 0/6 nodes are available: 1 No preemption victims found for incoming pod, 5 Preemption is not helpful for scheduling."
0.1089,Event,ADDED,eval-sanitize-10-r0-016-nx566.18d4e4ac9bb20a0d,"reason=FailedScheduling count=None msg=0/6 nodes are available: 1 c_wall violated: 1 conflicting context pair(s) with node memory, 1 c_wall violated: 2 conflicting context pair(s) with node memory, 4 node(s) had untolerated taint(s). no new claims to deallocate, preemption: 0/6 nodes are available: 2 No preemption victims found for incoming pod, 4 Preemption is not helpful for scheduling."
0.1092,Event,ADDED,eval-sanitize-10-r0-016-nx566.18d4e4ae9fb4f4f1,"reason=FailedScheduling count=None msg=0/6 nodes are available: 1 c_wall violated: 1 conflicting context pair(s) with node memory, 5 node(s) had untolerated taint(s). no new claims to deallocate, preemption: 0/6 nodes are available: 1 No preemption victims found for incoming pod, 5 Preemption is not helpful for scheduling."
0.1094,Event,ADDED,eval-sanitize-10-r0-016-nx566.18d4e4aeb571af9e,"reason=FailedScheduling count=None msg=0/6 nodes are available: 2 c_wall violated: 1 conflicting context pair(s) with node memory, 4 node(s) had untolerated taint(s). no new claims to deallocate, preemption: 0/6 nodes are available: 2 No preemption victims found for incoming pod, 4 Preemption is not helpful for scheduling."
0.1096,Event,ADDED,eval-sanitize-10-r0-016-nx566.18d4e4aee1bae047,reason=Scheduled count=None msg=Successfully assigned compute/eval-sanitize-10-r0-016-nx566 to kind-worker4
0.1097,Event,ADDED,eval-sanitize-10-r0-016-nx566.18d4e4af009f1527,"reason=Pulled count=1 msg=Container image ""busybox:musl"" already present on machine"
0.1099,Event,ADDED,eval-sanitize-10-r0-016-nx566.18d4e4af01b9dd93,reason=Created count=1 msg=Created container: task
0.1101,Event,ADDED,eval-sanitize-10-r0-016-nx566.18d4e4af065a6a85,reason=Started count=1 msg=Started container task
0.1104,Event,ADDED,eval-sanitize-10-r0-016.18d4e4a9d5943d81,reason=SuccessfulCreate count=1 msg=Created pod: eval-sanitize-10-r0-016-nx566
0.1106,Event,ADDED,eval-sanitize-10-r0-016.18d4e4b47d12f962,reason=Completed count=1 msg=Job completed
0.1108,Event,ADDED,eval-sanitize-10-r0-017-h6qq9.18d4e4aa0f3ad696,"reason=FailedScheduling count=None msg=0/6 nodes are available: 6 node(s) had untolerated taint(s). no new claims to deallocate, preemption: 0/6 nodes are available: 6 Preemption is not helpful for scheduling."
0.1111,Event,ADDED,eval-sanitize-10-r0-017-h6qq9.18d4e4ac3d30c0e8,"reason=FailedScheduling count=None msg=0/6 nodes are available: 1 c_wall violated: 2 conflicting context pair(s) with node memory, 5 node(s) had untolerated taint(s). no new claims to deallocate, preemption: 0/6 nodes are available: 1 No preemption victims found for incoming pod, 5 Preemption is not helpful for scheduling."
0.1113,Event,ADDED,eval-sanitize-10-r0-017-h6qq9.18d4e4ac5036d08d,"reason=FailedScheduling count=None msg=0/6 nodes are available: 1 c_wall violated: 3 conflicting context pair(s) with node memory, 5 node(s) had untolerated taint(s). no new claims to deallocate, preemption: 0/6 nodes are available: 1 No preemption victims found for incoming pod, 5 Preemption is not helpful for scheduling."
0.1115,Event,ADDED,eval-sanitize-10-r0-017-h6qq9.18d4e4ac55f0d58f,"reason=FailedScheduling count=None msg=0/6 nodes are available: 1 c_wall violated: 3 conflicting context pair(s) with node memory, 5 node(s) had untolerated taint(s). no new claims to deallocate, preemption: 0/6 nodes are available: 1 No preemption victims found for incoming pod, 5 Preemption is not helpful for scheduling."
0.1127,Node,MODIFIED,kind-worker5,taints=0
0.113,Event,ADDED,eval-sanitize-10-r0-017-h6qq9.18d4e4ac9c783726,"reason=FailedScheduling count=None msg=0/6 nodes are available: 1 c_wall violated: 1 conflicting context pair(s) with node memory, 1 c_wall violated: 3 conflicting context pair(s) with node memory, 4 node(s) had untolerated taint(s). no new claims to deallocate, preemption: 0/6 nodes are available: 2 No preemption victims found for incoming pod, 4 Preemption is not helpful for scheduling."
0.1132,Event,ADDED,eval-sanitize-10-r0-017-h6qq9.18d4e4ad9cd23ed4,"reason=FailedScheduling count=None msg=0/6 nodes are available: 1 c_wall violated: 2 conflicting context pair(s) with node memory, 1 c_wall violated: 3 conflicting context pair(s) with node memory, 4 node(s) had untolerated taint(s). no new claims to deallocate, preemption: 0/6 nodes are available: 2 No preemption victims found for incoming pod, 4 Preemption is not helpful for scheduling."
0.1134,Event,ADDED,eval-sanitize-10-r0-017-h6qq9.18d4e4aea3198f37,"reason=FailedScheduling count=None msg=0/6 nodes are available: 1 c_wall violated: 2 conflicting context pair(s) with node memory, 5 node(s) had untolerated taint(s). no new claims to deallocate, preemption: 0/6 nodes are available: 1 No preemption victims found for incoming pod, 5 Preemption is not helpful for scheduling."
0.1138,Event,ADDED,eval-sanitize-10-r0-017-h6qq9.18d4e4aeaa6596ca,reason=Scheduled count=None msg=Successfully assigned compute/eval-sanitize-10-r0-017-h6qq9 to kind-worker
0.114,Event,ADDED,eval-sanitize-10-r0-017-h6qq9.18d4e4aecbf571bf,"reason=Pulled count=1 msg=Container image ""busybox:musl"" already present on machine"
0.1142,Event,ADDED,eval-sanitize-10-r0-017-h6qq9.18d4e4aece0cbdd3,reason=Created count=1 msg=Created container: task
0.1145,Event,ADDED,eval-sanitize-10-r0-017-h6qq9.18d4e4aed92229a3,reason=Started count=1 msg=Started container task
0.1147,Event,ADDED,eval-sanitize-10-r0-017.18d4e4aa0f310650,reason=SuccessfulCreate count=1 msg=Created pod: eval-sanitize-10-r0-017-h6qq9
0.1149,Event,ADDED,eval-sanitize-10-r0-017.18d4e4b462fa827b,reason=Completed count=1 msg=Job completed
0.1151,Event,ADDED,eval-sanitize-10-r0-018-r7lhj.18d4e4aa4a713172,"reason=FailedScheduling count=None msg=0/6 nodes are available: 6 node(s) had untolerated taint(s). no new claims to deallocate, preemption: 0/6 nodes are available: 6 Preemption is not helpful for scheduling."
0.1154,Event,ADDED,eval-sanitize-10-r0-018-r7lhj.18d4e4ac3d9b6415,"reason=FailedScheduling count=None msg=0/6 nodes are available: 1 c_wall violated: 2 conflicting context pair(s) with node memory, 5 node(s) had untolerated taint(s). no new claims to deallocate, preemption: 0/6 nodes are available: 1 No preemption victims found for incoming pod, 5 Preemption is not helpful for scheduling."
0.1155,Event,ADDED,eval-sanitize-10-r0-018-r7lhj.18d4e4ac5126a520,"reason=FailedScheduling count=None msg=0/6 nodes are available: 1 c_wall violated: 3 conflicting context pair(s) with node memory, 5 node(s) had untolerated taint(s). no new claims to deallocate, preemption: 0/6 nodes are available: 1 No preemption victims found for incoming pod, 5 Preemption is not helpful for scheduling."
0.1157,Event,ADDED,eval-sanitize-10-r0-018-r7lhj.18d4e4ac56250f8a,"reason=FailedScheduling count=None msg=0/6 nodes are available: 1 c_wall violated: 3 conflicting context pair(s) with node memory, 5 node(s) had untolerated taint(s). no new claims to deallocate, preemption: 0/6 nodes are available: 1 No preemption victims found for incoming pod, 5 Preemption is not helpful for scheduling."
0.1161,Event,ADDED,eval-sanitize-10-r0-018-r7lhj.18d4e4aca1a13be3,"reason=FailedScheduling count=None msg=0/6 nodes are available: 1 c_wall violated: 1 conflicting context pair(s) with node memory, 1 c_wall violated: 3 conflicting context pair(s) with node memory, 4 node(s) had untolerated taint(s). no new claims to deallocate, preemption: 0/6 nodes are available: 2 No preemption victims found for incoming pod, 4 Preemption is not helpful for scheduling."
0.1163,Event,ADDED,eval-sanitize-10-r0-018-r7lhj.18d4e4ad9d2d18f3,"reason=FailedScheduling count=None msg=0/6 nodes are available: 1 c_wall violated: 2 conflicting context pair(s) with node memory, 1 c_wall violated: 3 conflicting context pair(s) with node memory, 4 node(s) had untolerated taint(s). no new claims to deallocate, preemption: 0/6 nodes are available: 2 No preemption victims found for incoming pod, 4 Preemption is not helpful for scheduling."
0.1165,Event,ADDED,eval-sanitize-10-r0-018-r7lhj.18d4e4aea341b6a8,"reason=FailedScheduling count=None msg=0/6 nodes are available: 1 c_wall violated: 2 conflicting context pair(s) with node memory, 5 node(s) had untolerated taint(s). no new claims to deallocate, preemption: 0/6 nodes are available: 1 No preemption victims found for incoming pod, 5 Preemption is not helpful for scheduling."
0.1168,Event,ADDED,eval-sanitize-10-r0-018-r7lhj.18d4e4aeaab8a809,reason=Scheduled count=None msg=Successfully assigned compute/eval-sanitize-10-r0-018-r7lhj to kind-worker
0.1171,Event,ADDED,eval-sanitize-10-r0-018-r7lhj.18d4e4aecc0c5e50,"reason=Pulled count=1 msg=Container image ""busybox:musl"" already present on machine"
0.1172,Event,ADDED,eval-sanitize-10-r0-018-r7lhj.18d4e4aece9cc860,reason=Created count=1 msg=Created container: task
0.1175,Event,ADDED,eval-sanitize-10-r0-018-r7lhj.18d4e4aed921c36f,reason=Started count=1 msg=Started container task
0.1177,Event,ADDED,eval-sanitize-10-r0-018.18d4e4aa4a643817,reason=SuccessfulCreate count=1 msg=Created pod: eval-sanitize-10-r0-018-r7lhj
0.1179,Event,ADDED,eval-sanitize-10-r0-018.18d4e4b4626f6c97,reason=Completed count=1 msg=Job completed
0.118,Event,ADDED,eval-sanitize-10-r0-019-n68kp.18d4e4aa85b9d8d9,"reason=FailedScheduling count=None msg=0/6 nodes are available: 6 node(s) had untolerated taint(s). no new claims to deallocate, preemption: 0/6 nodes are available: 6 Preemption is not helpful for scheduling."
0.1183,Event,ADDED,eval-sanitize-10-r0-019-n68kp.18d4e4ac3e0a383e,"reason=FailedScheduling count=None msg=0/6 nodes are available: 1 c_wall violated: 1 conflicting context pair(s) with node memory, 5 node(s) had untolerated taint(s). no new claims to deallocate, preemption: 0/6 nodes are available: 1 No preemption victims found for incoming pod, 5 Preemption is not helpful for scheduling."
0.1187,Event,ADDED,eval-sanitize-10-r0-019-n68kp.18d4e4ac51aee196,"reason=FailedScheduling count=None msg=0/6 nodes are available: 1 c_wall violated: 1 conflicting context pair(s) with node memory, 5 node(s) had untolerated taint(s). no new claims to deallocate, preemption: 0/6 nodes are available: 1 No preemption victims found for incoming pod, 5 Preemption is not helpful for scheduling."
0.1188,Event,ADDED,eval-sanitize-10-r0-019-n68kp.18d4e4ac6d418bb0,reason=Scheduled count=None msg=Successfully assigned compute/eval-sanitize-10-r0-019-n68kp to kind-worker5
0.119,Event,ADDED,eval-sanitize-10-r0-019-n68kp.18d4e4aca38f4587,"reason=Pulled count=1 msg=Container image ""busybox:musl"" already present on machine"
0.1192,Event,ADDED,eval-sanitize-10-r0-019-n68kp.18d4e4aca7bc2a96,reason=Created count=1 msg=Created container: task
0.1193,Event,ADDED,eval-sanitize-10-r0-019-n68kp.18d4e4acabf9fbaf,reason=Started count=1 msg=Started container task
0.1195,Event,ADDED,eval-sanitize-10-r0-019.18d4e4aa85afdc04,reason=SuccessfulCreate count=1 msg=Created pod: eval-sanitize-10-r0-019-n68kp
0.12,Event,ADDED,eval-sanitize-10-r0-019.18d4e4b2a766a9bc,reason=Completed count=1 msg=Job completed
0.1201,Event,ADDED,eval-sanitize-10-r0-020-n6m72.18d4e4aac1913ba8,"reason=FailedScheduling count=None msg=0/6 nodes are available: 6 node(s) had untolerated taint(s). no new claims to deallocate, preemption: 0/6 nodes are available: 6 Preemption is not helpful for scheduling."
0.1203,Event,ADDED,eval-sanitize-10-r0-020-n6m72.18d4e4ac3ec0a57d,reason=Scheduled count=None msg=Successfully assigned compute/eval-sanitize-10-r0-020-n6m72 to kind-worker2
0.1205,Event,ADDED,eval-sanitize-10-r0-020-n6m72.18d4e4ac5b98e4fb,"reason=Pulled count=1 msg=Container image ""busybox:musl"" already present on machine"
0.1207,Event,ADDED,eval-sanitize-10-r0-020-n6m72.18d4e4ac5daacca1,reason=Created count=1 msg=Created container: task
0.1209,Event,ADDED,eval-sanitize-10-r0-020-n6m72.18d4e4ac5fc0541a,reason=Started count=1 msg=Started container task
0.121,Event,ADDED,eval-sanitize-10-r0-020.18d4e4aac18847f7,reason=SuccessfulCreate count=1 msg=Created pod: eval-sanitize-10-r0-020-n6m72
0.1213,Event,ADDED,eval-sanitize-10-r0-020.18d4e4b1ebe7cc04,reason=Completed count=1 msg=Job completed
0.1214,Event,ADDED,eval-sanitize-10-r0-021-vlvrj.18d4e4aafed712bc,"reason=FailedScheduling count=None msg=0/6 nodes are available: 6 node(s) had untolerated taint(s). no new claims to deallocate, preemption: 0/6 nodes are available: 6 Preemption is not helpful for scheduling."
0.1216,Event,ADDED,eval-sanitize-10-r0-021-vlvrj.18d4e4ac3e9c8b2f,"reason=FailedScheduling count=None msg=0/6 nodes are available: 1 c_wall violated: 1 conflicting context pair(s) with node memory, 5 node(s) had untolerated taint(s). no new claims to deallocate, preemption: 0/6 nodes are available: 1 No preemption victims found for incoming pod, 5 Preemption is not helpful for scheduling."
0.1218,Event,ADDED,eval-sanitize-10-r0-021-vlvrj.18d4e4ac51dacf9a,"reason=FailedScheduling count=None msg=0/6 nodes are available: 1 c_wall violated: 1 conflicting context pair(s) with node memory, 5 node(s) had untolerated taint(s). no new claims to deallocate, preemption: 0/6 nodes are available: 1 No preemption victims found for incoming pod, 5 Preemption is not helpful for scheduling."
0.1219,Event,ADDED,eval-sanitize-10-r0-021-vlvrj.18d4e4ac6dac8212,reason=Scheduled count=None msg=Successfully assigned compute/eval-sanitize-10-r0-021-vlvrj to kind-worker5
0.1221,Event,ADDED,eval-sanitize-10-r0-021-vlvrj.18d4e4aca3bd6184,"reason=Pulled count=1 msg=Container image ""busybox:musl"" already present on machine"
0.1222,Event,ADDED,eval-sanitize-10-r0-021-vlvrj.18d4e4aca84ff26b,reason=Created count=1 msg=Created container: task
0.1224,Event,ADDED,eval-sanitize-10-r0-021-vlvrj.18d4e4acac61bb5c,reason=Started count=1 msg=Started container task
0.1226,Event,ADDED,eval-sanitize-10-r0-021.18d4e4aafecd66a8,reason=SuccessfulCreate count=1 msg=Created pod: eval-sanitize-10-r0-021-vlvrj
0.1227,Event,ADDED,eval-sanitize-10-r0-021.18d4e4b2afad2435,reason=Completed count=1 msg=Job completed
0.1229,Event,ADDED,eval-sanitize-10-r0-022-jws8p.18d4e4ab3b615635,"reason=FailedScheduling count=None msg=0/6 nodes are available: 6 node(s) had untolerated taint(s). no new claims to deallocate, preemption: 0/6 nodes are available: 6 Preemption is not helpful for scheduling."
0.123,Event,ADDED,eval-sanitize-10-r0-022-jws8p.18d4e4ac3f169977,"reason=FailedScheduling count=None msg=0/6 nodes are available: 1 c_wall violated: 1 conflicting context pair(s) with node memory, 5 node(s) had untolerated taint(s). no new claims to deallocate, preemption: 0/6 nodes are available: 1 No preemption victims found for incoming pod, 5 Preemption is not helpful for scheduling."
0.1232,Event,ADDED,eval-sanitize-10-r0-022-jws8p.18d4e4ac52053936,"reason=FailedScheduling count=None msg=0/6 nodes are available: 1 c_wall violated: 1 conflicting context pair(s) with node memory, 5 node(s) had untolerated taint(s). no new claims to deallocate, preemption: 0/6 nodes are available: 1 No preemption victims found for incoming pod, 5 Preemption is not helpful for scheduling."
0.1234,Event,ADDED,eval-sanitize-10-r0-022-jws8p.18d4e4ac6e682e5f,reason=Scheduled count=None msg=Successfully assigned compute/eval-sanitize-10-r0-022-jws8p to kind-worker5
0.1235,Event,ADDED,eval-sanitize-10-r0-022-jws8p.18d4e4aca36e7218,"reason=Pulled count=1 msg=Container image ""busybox:musl"" already present on machine"
0.1237,Event,ADDED,eval-sanitize-10-r0-022-jws8p.18d4e4aca72c6601,reason=Created count=1 msg=Created container: task
0.1239,Event,ADDED,eval-sanitize-10-r0-022-jws8p.18d4e4acabc7c1bc,reason=Started count=1 msg=Started container task
0.124,Event,ADDED,eval-sanitize-10-r0-022.18d4e4ab3b575ac1,reason=SuccessfulCreate count=1 msg=Created pod: eval-sanitize-10-r0-022-jws8p
0.1242,Event,ADDED,eval-sanitize-10-r0-022.18d4e4b2b29aa77e,reason=Completed count=1 msg=Job completed
0.1243,Event,ADDED,eval-sanitize-10-r0-023-rxtzf.18d4e4ab76e3899a,"reason=FailedScheduling count=None msg=0/6 nodes are available: 6 node(s) had untolerated taint(s). no new claims to deallocate, preemption: 0/6 nodes are available: 6 Preemption is not helpful for scheduling."
0.1245,Event,ADDED,eval-sanitize-10-r0-023-rxtzf.18d4e4ac3ff6adbf,reason=Scheduled count=None msg=Successfully assigned compute/eval-sanitize-10-r0-023-rxtzf to kind-worker2
0.1247,Event,ADDED,eval-sanitize-10-r0-023-rxtzf.18d4e4ac5978cd58,"reason=Pulled count=1 msg=Container image ""busybox:musl"" already present on machine"
0.1249,Event,ADDED,eval-sanitize-10-r0-023-rxtzf.18d4e4ac5af065a9,reason=Created count=1 msg=Created container: task
0.1251,Event,ADDED,eval-sanitize-10-r0-023-rxtzf.18d4e4ac5ec5c8bf,reason=Started count=1 msg=Started container task
0.1253,Event,ADDED,eval-sanitize-10-r0-023.18d4e4ab76db2847,reason=SuccessfulCreate count=1 msg=Created pod: eval-sanitize-10-r0-023-rxtzf
0.1255,Event,ADDED,eval-sanitize-10-r0-023.18d4e4b1ecf19663,reason=Completed count=1 msg=Job completed
0.1256,Event,ADDED,eval-sanitize-10-r0-024-s65nc.18d4e4abb3a6a284,"reason=FailedScheduling count=None msg=0/6 nodes are available: 6 node(s) had untolerated taint(s). no new claims to deallocate, preemption: 0/6 nodes are available: 6 Preemption is not helpful for scheduling."
0.1258,Event,ADDED,eval-sanitize-10-r0-024-s65nc.18d4e4ac42389cbc,"reason=FailedScheduling count=None msg=0/6 nodes are available: 1 c_wall violated: 3 conflicting context pair(s) with node memory, 5 node(s) had untolerated taint(s). no new claims to deallocate, preemption: 0/6 nodes are available: 1 No preemption victims found for incoming pod, 5 Preemption is not helpful for scheduling."
0.1262,Event,ADDED,eval-sanitize-10-r0-024-s65nc.18d4e4ac523228af,"reason=FailedScheduling count=None msg=0/6 nodes are available: 1 c_wall violated: 3 conflicting context pair(s) with node memory, 5 node(s) had untolerated taint(s). no new claims to deallocate, preemption: 0/6 nodes are available: 1 No preemption victims found for incoming pod, 5 Preemption is not helpful for scheduling."
0.1264,Event,ADDED,eval-sanitize-10-r0-024-s65nc.18d4e4ac977120ce,"reason=FailedScheduling count=None msg=0/6 nodes are available: 1 c_wall violated: 1 conflicting context pair(s) with node memory, 1 c_wall violated: 3 conflicting context pair(s) with node memory, 4 node(s) had untolerated taint(s). no new claims to deallocate, preemption: 0/6 nodes are available: 2 No preemption victims found for incoming pod, 4 Preemption is not helpful for scheduling."
0.1266,Event,ADDED,eval-sanitize-10-r0-024-s65nc.18d4e4ad9d7dc006,"reason=FailedScheduling count=None msg=0/6 nodes are available: 1 c_wall violated: 2 conflicting context pair(s) with node memory, 1 c_wall violated: 3 conflicting context pair(s) with node memory, 4 node(s) had untolerated taint(s). no new claims to deallocate, preemption: 0/6 nodes are available: 2 No preemption victims found for incoming pod, 4 Preemption is not helpful for scheduling."
0.1268,Event,ADDED,eval-sanitize-10-r0-024-s65nc.18d4e4aea36fa687,"reason=FailedScheduling count=None msg=0/6 nodes are available: 1 c_wall violated: 2 conflicting context pair(s) with node memory, 5 node(s) had untolerated taint(s). no new claims to deallocate, preemption: 0/6 nodes are available: 1 No preemption victims found for incoming pod, 5 Preemption is not helpful for scheduling."
0.1269,Event,ADDED,eval-sanitize-10-r0-024-s65nc.18d4e4aeb1b1b2a6,reason=Scheduled count=None msg=Successfully assigned compute/eval-sanitize-10-r0-024-s65nc to kind-worker
0.1271,Event,ADDED,eval-sanitize-10-r0-024-s65nc.18d4e4aed943fe5d,"reason=Pulled count=1 msg=Container image ""busybox:musl"" already present on machine"
0.1276,Event,ADDED,eval-sanitize-10-r0-024-s65nc.18d4e4aedb14c576,reason=Created count=1 msg=Created container: task
0.1278,Event,ADDED,eval-sanitize-10-r0-024-s65nc.18d4e4aee19587b5,reason=Started count=1 msg=Started container task
0.1279,Event,ADDED,eval-sanitize-10-r0-024.18d4e4abb399eee9,reason=SuccessfulCreate count=1 msg=Created pod: eval-sanitize-10-r0-024-s65nc
0.1284,Event,ADDED,eval-sanitize-10-r0-024.18d4e4b4628c0208,reason=Completed count=1 msg=Job completed
0.1286,Event,ADDED,eval-sanitize-10-r0-025-bg96t.18d4e4abf3508450,"reason=FailedScheduling count=None msg=0/6 nodes are available: 6 node(s) had untolerated taint(s). no new claims to deallocate, preemption: 0/6 nodes are available: 6 Preemption is not helpful for scheduling."
0.1287,Event,ADDED,eval-sanitize-10-r0-025-bg96t.18d4e4ac43674a70,reason=Scheduled count=None msg=Successfully assigned compute/eval-sanitize-10-r0-025-bg96t to kind-worker2
0.1289,Event,ADDED,eval-sanitize-10-r0-025-bg96t.18d4e4ac5af07049,"reason=Pulled count=1 msg=Container image ""busybox:musl"" already present on machine"
0.1291,Event,ADDED,eval-sanitize-10-r0-025-bg96t.18d4e4ac5cb8929b,reason=Created count=1 msg=Created container: task
0.1293,Event,ADDED,eval-sanitize-10-r0-025-bg96t.18d4e4ac5f0d2fb7,reason=Started count=1 msg=Started container task
0.1295,Event,ADDED,eval-sanitize-10-r0-025.18d4e4abf342fb1c,reason=SuccessfulCreate count=1 msg=Created pod: eval-sanitize-10-r0-025-bg96t
0.1296,Event,ADDED,eval-sanitize-10-r0-025.18d4e4b1ecf2a1fe,reason=Completed count=1 msg=Job completed
0.1298,Event,ADDED,eval-sanitize-10-r0-026-bxcxr.18d4e4ac2a50f2b2,"reason=FailedScheduling count=None msg=0/6 nodes are available: 6 node(s) had untolerated taint(s). no new claims to deallocate, preemption: 0/6 nodes are available: 6 Preemption is not helpful for scheduling."
0.1299,Event,ADDED,eval-sanitize-10-r0-026-bxcxr.18d4e4ac434ed8f0,"reason=FailedScheduling count=None msg=0/6 nodes are available: 1 c_wall violated: 1 conflicting context pair(s) with node memory, 5 node(s) had untolerated taint(s). no new claims to deallocate, preemption: 0/6 nodes are available: 1 No preemption victims found for incoming pod, 5 Preemption is not helpful for scheduling."
0.1302,Event,ADDED,eval-sanitize-10-r0-026-bxcxr.18d4e4ac5506d34a,"reason=FailedScheduling count=None msg=0/6 nodes are available: 1 c_wall violated: 1 conflicting context pair(s) with node memory, 5 node(s) had untolerated taint(s). no new claims to deallocate, preemption: 0/6 nodes are available: 1 No preemption victims found for incoming pod, 5 Preemption is not helpful for scheduling."
0.1304,Event,ADDED,eval-sanitize-10-r0-026-bxcxr.18d4e4ac7ccb2515,reason=Scheduled count=None msg=Successfully assigned compute/eval-sanitize-10-r0-026-bxcxr to kind-worker5
0.1306,Event,ADDED,eval-sanitize-10-r0-026-bxcxr.18d4e4acad06689c,"reason=Pulled count=1 msg=Container image ""busybox:musl"" already present on machine"
0.1308,Event,ADDED,eval-sanitize-10-r0-026-bxcxr.18d4e4acae81730f,reason=Created count=1 msg=Created container: task
0.131,Event,ADDED,eval-sanitize-10-r0-026-bxcxr.18d4e4acb09be438,reason=Started count=1 msg=Started container task
0.1311,Event,ADDED,eval-sanitize-10-r0-026.18d4e4ac2a43d568,reason=SuccessfulCreate count=1 msg=Created pod: eval-sanitize-10-r0-026-bxcxr
0.1313,Event,ADDED,eval-sanitize-10-r0-026.18d4e4b2a12c8043,reason=Completed count=1 msg=Job completed
0.1314,Event,ADDED,eval-sanitize-10-r0-027-rzhzs.18d4e4ac6b41b501,reason=Scheduled count=None msg=Successfully assigned compute/eval-sanitize-10-r0-027-rzhzs to kind-worker2
0.1316,Event,ADDED,eval-sanitize-10-r0-027-rzhzs.18d4e4ac8f194918,"reason=Pulled count=1 msg=Container image ""busybox:musl"" already present on machine"
0.1318,Event,ADDED,eval-sanitize-10-r0-027-rzhzs.18d4e4ac977b3921,reason=Created count=1 msg=Created container: task
0.1319,Event,ADDED,eval-sanitize-10-r0-027-rzhzs.18d4e4aca37aa5c8,reason=Started count=1 msg=Started container task
0.1321,Event,ADDED,eval-sanitize-10-r0-027.18d4e4ac622af70a,reason=SuccessfulCreate count=1 msg=Created pod: eval-sanitize-10-r0-027-rzhzs
0.1323,Event,ADDED,eval-sanitize-10-r0-027.18d4e4b28ff004c2,reason=Completed count=1 msg=Job completed
0.1324,Event,ADDED,eval-sanitize-10-r0-028-rvzt7.18d4e4aca7099f26,reason=Scheduled count=None msg=Successfully assigned compute/eval-sanitize-10-r0-028-rvzt7 to kind-worker5
0.1326,Event,ADDED,eval-sanitize-10-r0-028-rvzt7.18d4e4acc95e1f87,"reason=Pulled count=1 msg=Container image ""busybox:musl"" already present on machine"
0.1328,Event,ADDED,eval-sanitize-10-r0-028-rvzt7.18d4e4acca7f817a,reason=Created count=1 msg=Created container: task
0.133,Event,ADDED,eval-sanitize-10-r0-028-rvzt7.18d4e4acd2ba0602,reason=Started count=1 msg=Started container task
0.1332,Event,ADDED,eval-sanitize-10-r0-028.18d4e4aca61c4093,reason=SuccessfulCreate count=1 msg=Created pod: eval-sanitize-10-r0-028-rvzt7
0.1334,Event,ADDED,eval-sanitize-10-r0-028.18d4e4b29e53c938,reason=Completed count=1 msg=Job completed
0.1336,Event,ADDED,eval-sanitize-10-r0-029-jr5n4.18d4e4ace0791ad1,reason=Scheduled count=None msg=Successfully assigned compute/eval-sanitize-10-r0-029-jr5n4 to kind-worker5
0.1338,Event,ADDED,eval-sanitize-10-r0-029-jr5n4.18d4e4ad04f07190,"reason=Pulled count=1 msg=Container image ""busybox:musl"" already present on machine"
0.1339,Event,ADDED,eval-sanitize-10-r0-029-jr5n4.18d4e4ad05faf37c,reason=Created count=1 msg=Created container: task
0.1341,Event,ADDED,eval-sanitize-10-r0-029-jr5n4.18d4e4ad0ae87dc8,reason=Started count=1 msg=Started container task
0.1344,Event,ADDED,eval-sanitize-10-r0-029.18d4e4acdfc1ab72,reason=SuccessfulCreate count=1 msg=Created pod: eval-sanitize-10-r0-029-jr5n4
0.1346,Event,ADDED,eval-sanitize-10-r0-029.18d4e4b2e844241e,reason=Completed count=1 msg=Job completed
0.1347,Event,ADDED,eval-sanitize-10-r0-030-mb9nj.18d4e4ad16344af9,reason=Scheduled count=None msg=Successfully assigned compute/eval-sanitize-10-r0-030-mb9nj to kind-worker2
0.1349,Event,ADDED,eval-sanitize-10-r0-030-mb9nj.18d4e4ad35648711,"reason=Pulled count=1 msg=Container image ""busybox:musl"" already present on machine"
0.1351,Event,ADDED,eval-sanitize-10-r0-030-mb9nj.18d4e4ad368e3d9e,reason=Created count=1 msg=Created container: task
0.1353,Event,ADDED,eval-sanitize-10-r0-030-mb9nj.18d4e4ad3f65f4ca,reason=Started count=1 msg=Started container task
0.1355,Event,ADDED,eval-sanitize-10-r0-030.18d4e4ad14fb16e1,reason=SuccessfulCreate count=1 msg=Created pod: eval-sanitize-10-r0-030-mb9nj
0.1356,Event,ADDED,eval-sanitize-10-r0-030.18d4e4b30f1a2836,reason=Completed count=1 msg=Job completed
0.1358,Event,ADDED,eval-sanitize-10-r0-031-zwcv2.18d4e4ad52693a0e,reason=Scheduled count=None msg=Successfully assigned compute/eval-sanitize-10-r0-031-zwcv2 to kind-worker5
0.136,Event,ADDED,eval-sanitize-10-r0-031-zwcv2.18d4e4ad6d4d285c,"reason=Pulled count=1 msg=Container image ""busybox:musl"" already present on machine"
0.1361,Event,ADDED,eval-sanitize-10-r0-031-zwcv2.18d4e4ad6e6bfdae,reason=Created count=1 msg=Created container: task
0.1363,Event,ADDED,eval-sanitize-10-r0-031-zwcv2.18d4e4ad7865d6d5,reason=Started count=1 msg=Started container task
0.1365,Event,ADDED,eval-sanitize-10-r0-031.18d4e4ad51b8368d,reason=SuccessfulCreate count=1 msg=Created pod: eval-sanitize-10-r0-031-zwcv2
0.1367,Event,ADDED,eval-sanitize-10-r0-031.18d4e4b35229a58d,reason=Completed count=1 msg=Job completed
0.137,Event,ADDED,eval-sanitize-10-r0-032-n7znt.18d4e4ad91cd9372,reason=Scheduled count=None msg=Successfully assigned compute/eval-sanitize-10-r0-032-n7znt to kind-worker5
0.1373,Event,ADDED,eval-sanitize-10-r0-032-n7znt.18d4e4adaebfa1b0,"reason=Pulled count=1 msg=Container image ""busybox:musl"" already present on machine"
0.1375,Event,ADDED,eval-sanitize-10-r0-032-n7znt.18d4e4adafdc89f1,reason=Created count=1 msg=Created container: task
0.1377,Event,ADDED,eval-sanitize-10-r0-032-n7znt.18d4e4adbb6ce9b4,reason=Started count=1 msg=Started container task
0.138,Event,ADDED,eval-sanitize-10-r0-032.18d4e4ad91261e5e,reason=SuccessfulCreate count=1 msg=Created pod: eval-sanitize-10-r0-032-n7znt
0.1382,Event,ADDED,eval-sanitize-10-r0-032.18d4e4b340bc9adc,reason=Completed count=1 msg=Job completed
0.1384,Event,ADDED,eval-sanitize-10-r0-033-nr6f2.18d4e4add2b7b4b1,"reason=FailedScheduling count=None msg=0/6 nodes are available: 2 c_wall violated: 1 conflicting context pair(s) with node memory, 4 node(s) had untolerated taint(s). no new claims to deallocate, preemption: 0/6 nodes are available: 2 No preemption victims found for incoming pod, 4 Preemption is not helpful for scheduling."
0.1387,Event,ADDED,eval-sanitize-10-r0-033-nr6f2.18d4e4add362d155,"reason=FailedScheduling count=None msg=0/6 nodes are available: 2 c_wall violated: 1 conflicting context pair(s) with node memory, 4 node(s) had untolerated taint(s). no new claims to deallocate, preemption: 0/6 nodes are available: 2 No preemption victims found for incoming pod, 4 Preemption is not helpful for scheduling."
0.1389,Event,ADDED,eval-sanitize-10-r0-033-nr6f2.18d4e4ae9f8a5452,"reason=FailedScheduling count=None msg=0/6 nodes are available: 1 c_wall violated: 1 conflicting context pair(s) with node memory, 5 node(s) had untolerated taint(s). no new claims to deallocate, preemption: 0/6 nodes are available: 1 No preemption victims found for incoming pod, 5 Preemption is not helpful for scheduling."
0.1391,Event,ADDED,eval-sanitize-10-r0-033-nr6f2.18d4e4aeb524729c,"reason=FailedScheduling count=None msg=0/6 nodes are available: 2 c_wall violated: 1 conflicting context pair(s) with node memory, 4 node(s) had untolerated taint(s). no new claims to deallocate, preemption: 0/6 nodes are available: 2 No preemption victims found for incoming pod, 4 Preemption is not helpful for scheduling."
0.1394,Event,ADDED,eval-sanitize-10-r0-033-nr6f2.18d4e4aed95c73fd,reason=Scheduled count=None msg=Successfully assigned compute/eval-sanitize-10-r0-033-nr6f2 to kind-worker3
0.1396,Event,ADDED,eval-sanitize-10-r0-033-nr6f2.18d4e4aef4dcf49b,"reason=Pulled count=1 msg=Container image ""busybox:musl"" already present on machine"
0.1398,Event,ADDED,eval-sanitize-10-r0-033-nr6f2.18d4e4aef6698364,reason=Created count=1 msg=Created container: task
0.14,Event,ADDED,eval-sanitize-10-r0-033-nr6f2.18d4e4af007750a2,reason=Started count=1 msg=Started container task
0.1403,Event,ADDED,eval-sanitize-10-r0-033.18d4e4add23eb379,reason=SuccessfulCreate count=1 msg=Created pod: eval-sanitize-10-r0-033-nr6f2
0.1405,Event,ADDED,eval-sanitize-10-r0-033.18d4e4b4607bfecd,reason=Completed count=1 msg=Job completed
0.1406,Event,ADDED,eval-sanitize-10-r0-034-mpr92.18d4e4ae07266608,reason=Scheduled count=None msg=Successfully assigned compute/eval-sanitize-10-r0-034-mpr92 to kind-worker5
0.1409,Event,ADDED,eval-sanitize-10-r0-034-mpr92.18d4e4ae27032008,"reason=Pulled count=1 msg=Container image ""busybox:musl"" already present on machine"
0.1412,Event,ADDED,eval-sanitize-10-r0-034-mpr92.18d4e4ae281dbdf4,reason=Created count=1 msg=Created container: task
0.1414,Event,ADDED,eval-sanitize-10-r0-034-mpr92.18d4e4ae2da20b83,reason=Started count=1 msg=Started container task
0.1416,Event,ADDED,eval-sanitize-10-r0-034.18d4e4ae0679c52d,reason=SuccessfulCreate count=1 msg=Created pod: eval-sanitize-10-r0-034-mpr92
0.142,Event,ADDED,eval-sanitize-10-r0-034.18d4e4b3ad383246,reason=Completed count=1 msg=Job completed
0.1421,Event,ADDED,eval-sanitize-10-r0-035-4jvhc.18d4e4ae4374eeb3,reason=Scheduled count=None msg=Successfully assigned compute/eval-sanitize-10-r0-035-4jvhc to kind-worker5
0.1423,Event,ADDED,eval-sanitize-10-r0-035-4jvhc.18d4e4ae6fbbf048,"reason=Pulled count=1 msg=Container image ""busybox:musl"" already present on machine"
0.1425,Event,ADDED,eval-sanitize-10-r0-035-4jvhc.18d4e4ae70e56ace,reason=Created count=1 msg=Created container: task
0.1428,Event,ADDED,eval-sanitize-10-r0-035-4jvhc.18d4e4ae79c6d8a5,reason=Started count=1 msg=Started container task
0.143,Event,ADDED,eval-sanitize-10-r0-035.18d4e4ae42bea8c2,reason=SuccessfulCreate count=1 msg=Created pod: eval-sanitize-10-r0-035-4jvhc
0.1432,Event,ADDED,eval-sanitize-10-r0-035.18d4e4b3e8dd5335,reason=Completed count=1 msg=Job completed
0.1433,Event,ADDED,eval-sanitize-10-r0-036-4jjzp.18d4e4ae7c19dc09,reason=Scheduled count=None msg=Successfully assigned compute/eval-sanitize-10-r0-036-4jjzp to kind-worker5
0.1435,Event,ADDED,eval-sanitize-10-r0-036-4jjzp.18d4e4ae9baf3ff7,"reason=Pulled count=1 msg=Container image ""busybox:musl"" already present on machine"
0.1437,Event,ADDED,eval-sanitize-10-r0-036-4jjzp.18d4e4ae9d0120fe,reason=Created count=1 msg=Created container: task
0.1439,Event,ADDED,eval-sanitize-10-r0-036-4jjzp.18d4e4aea0eb36e1,reason=Started count=1 msg=Started container task
0.1441,Event,ADDED,eval-sanitize-10-r0-036.18d4e4ae7b716edb,reason=SuccessfulCreate count=1 msg=Created pod: eval-sanitize-10-r0-036-4jjzp
0.1442,Event,ADDED,eval-sanitize-10-r0-036.18d4e4b4242064e1,reason=Completed count=1 msg=Job completed
0.1444,Event,ADDED,eval-sanitize-10-r0-037-qstm7.18d4e4aebc5b3392,reason=Scheduled count=None msg=Successfully assigned compute/eval-sanitize-10-r0-037-qstm7 to kind-worker
0.1445,Event,ADDED,eval-sanitize-10-r0-037-qstm7.18d4e4aee19b10d2,"reason=Pulled count=1 msg=Container image ""busybox:musl"" already present on machine"
0.1447,Event,ADDED,eval-sanitize-10-r0-037-qstm7.18d4e4aee2e6aa9a,reason=Created count=1 msg=Created container: task
0.1449,Event,ADDED,eval-sanitize-10-r0-037-qstm7.18d4e4aeeee90468,reason=Started count=1 msg=Started container task
0.145,Event,ADDED,eval-sanitize-10-r0-037.18d4e4aebbc2cbba,reason=SuccessfulCreate count=1 msg=Created pod: eval-sanitize-10-r0-037-qstm7
0.1452,Event,ADDED,eval-sanitize-10-r0-037.18d4e4b4635c59ff,reason=Completed count=1 msg=Job completed
0.1454,Event,ADDED,eval-sanitize-10-r0-038-bfmh6.18d4e4aef415b6b7,reason=Scheduled count=None msg=Successfully assigned compute/eval-sanitize-10-r0-038-bfmh6 to kind-worker4
0.1455,Event,ADDED,eval-sanitize-10-r0-038-bfmh6.18d4e4af0e2df9fb,"reason=Pulled count=1 msg=Container image ""busybox:musl"" already present on machine"
0.1457,Event,ADDED,eval-sanitize-10-r0-038-bfmh6.18d4e4af0f4526d8,reason=Created count=1 msg=Created container: task
0.1459,Event,ADDED,eval-sanitize-10-r0-038-bfmh6.18d4e4af180e9363,reason=Started count=1 msg=Started container task
0.146,Event,ADDED,eval-sanitize-10-r0-038.18d4e4aef2a8baef,reason=SuccessfulCreate count=1 msg=Created pod: eval-sanitize-10-r0-038-bfmh6
0.1462,Event,ADDED,eval-sanitize-10-r0-038.18d4e4b47cc1229a,reason=Completed count=1 msg=Job completed
0.1464,Event,ADDED,eval-sanitize-10-r0-039-85zxp.18d4e4af392e0b2e,reason=Scheduled count=None msg=Successfully assigned compute/eval-sanitize-10-r0-039-85zxp to kind-worker3
0.1465,Event,ADDED,eval-sanitize-10-r0-039-85zxp.18d4e4af55f6d436,"reason=Pulled count=1 msg=Container image ""busybox:musl"" already present on machine"
0.1467,Event,ADDED,eval-sanitize-10-r0-039-85zxp.18d4e4af57024f51,reason=Created count=1 msg=Created container: task
0.1469,Event,ADDED,eval-sanitize-10-r0-039-85zxp.18d4e4af617f7b01,reason=Started count=1 msg=Started container task
0.147,Event,ADDED,eval-sanitize-10-r0-039.18d4e4af383f3558,reason=SuccessfulCreate count=1 msg=Created pod: eval-sanitize-10-r0-039-85zxp
0.1472,Event,ADDED,eval-sanitize-10-r0-039.18d4e4b4d7fbd862,reason=Completed count=1 msg=Job completed
0.1474,Event,ADDED,eval-sanitize-10-r0-040-rhgm6.18d4e4af6a51cec7,reason=Scheduled count=None msg=Successfully assigned compute/eval-sanitize-10-r0-040-rhgm6 to kind-worker4
0.1475,Event,ADDED,eval-sanitize-10-r0-040-rhgm6.18d4e4af86d59521,"reason=Pulled count=1 msg=Container image ""busybox:musl"" already present on machine"
0.1477,Event,ADDED,eval-sanitize-10-r0-040-rhgm6.18d4e4af87f2ff60,reason=Created count=1 msg=Created container: task
0.1479,Event,ADDED,eval-sanitize-10-r0-040-rhgm6.18d4e4af8da6f5ff,reason=Started count=1 msg=Started container task
0.148,Event,ADDED,eval-sanitize-10-r0-040.18d4e4af69508a25,reason=SuccessfulCreate count=1 msg=Created pod: eval-sanitize-10-r0-040-rhgm6
0.1483,Event,ADDED,eval-sanitize-10-r0-040.18d4e4b4f134a829,reason=Completed count=1 msg=Job completed
0.1484,Event,ADDED,eval-sanitize-10-r0-041-x4ftk.18d4e4afaeda1ab2,reason=Scheduled count=None msg=Successfully assigned compute/eval-sanitize-10-r0-041-x4ftk to kind-worker3
0.1486,Event,ADDED,eval-sanitize-10-r0-041-x4ftk.18d4e4afcfe09fb8,"reason=Pulled count=1 msg=Container image ""busybox:musl"" already present on machine"
0.1489,Event,ADDED,eval-sanitize-10-r0-041-x4ftk.18d4e4afd1137315,reason=Created count=1 msg=Created container: task
0.1491,Event,ADDED,eval-sanitize-10-r0-041-x4ftk.18d4e4afd65d4613,reason=Started count=1 msg=Started container task
0.1493,Event,ADDED,eval-sanitize-10-r0-041.18d4e4afaddd6705,reason=SuccessfulCreate count=1 msg=Created pod: eval-sanitize-10-r0-041-x4ftk
0.1495,Event,ADDED,eval-sanitize-10-r0-041.18d4e4b5501c5c99,reason=Completed count=1 msg=Job completed
0.1496,Event,ADDED,eval-sanitize-10-r0-042-4ptxc.18d4e4afe47fb450,reason=Scheduled count=None msg=Successfully assigned compute/eval-sanitize-10-r0-042-4ptxc to kind-worker4
0.1498,Event,ADDED,eval-sanitize-10-r0-042-4ptxc.18d4e4affdb0bc00,"reason=Pulled count=1 msg=Container image ""busybox:musl"" already present on machine"
0.15,Event,ADDED,eval-sanitize-10-r0-042-4ptxc.18d4e4affec6ad24,reason=Created count=1 msg=Created container: task
0.1501,Event,ADDED,eval-sanitize-10-r0-042-4ptxc.18d4e4b0034b5198,reason=Started count=1 msg=Started container task
0.1503,Event,ADDED,eval-sanitize-10-r0-042.18d4e4afe35904f7,reason=SuccessfulCreate count=1 msg=Created pod: eval-sanitize-10-r0-042-4ptxc
0.1505,Event,ADDED,eval-sanitize-10-r0-042.18d4e4b56bd363e2,reason=Completed count=1 msg=Job completed
0.1506,Event,ADDED,eval-sanitize-10-r0-043-2mg2f.18d4e4b01d258f88,reason=Scheduled count=None msg=Successfully assigned compute/eval-sanitize-10-r0-043-2mg2f to kind-worker4
0.1508,Event,ADDED,eval-sanitize-10-r0-043-2mg2f.18d4e4b037428c76,"reason=Pulled count=1 msg=Container image ""busybox:musl"" already present on machine"
0.1509,Event,ADDED,eval-sanitize-10-r0-043-2mg2f.18d4e4b038751a85,reason=Created count=1 msg=Created container: task
0.1511,Event,ADDED,eval-sanitize-10-r0-043-2mg2f.18d4e4b03a84aa56,reason=Started count=1 msg=Started container task
0.1513,Event,ADDED,eval-sanitize-10-r0-043.18d4e4b01c1c65ff,reason=SuccessfulCreate count=1 msg=Created pod: eval-sanitize-10-r0-043-2mg2f
0.1514,Event,ADDED,eval-sanitize-10-r0-043.18d4e4b5a7a9f37d,reason=Completed count=1 msg=Job completed
0.1516,Event,ADDED,eval-sanitize-10-r0-044-47p8v.18d4e4b05914f386,reason=Scheduled count=None msg=Successfully assigned compute/eval-sanitize-10-r0-044-47p8v to kind-worker3
0.1517,Event,ADDED,eval-sanitize-10-r0-044-47p8v.18d4e4b0749fc6cf,"reason=Pulled count=1 msg=Container image ""busybox:musl"" already present on machine"
0.1519,Event,ADDED,eval-sanitize-10-r0-044-47p8v.18d4e4b075a4d710,reason=Created count=1 msg=Created container: task
0.1521,Event,ADDED,eval-sanitize-10-r0-044-47p8v.18d4e4b07935f548,reason=Started count=1 msg=Started container task
0.1523,Event,ADDED,eval-sanitize-10-r0-044.18d4e4b057ccc7ec,reason=SuccessfulCreate count=1 msg=Created pod: eval-sanitize-10-r0-044-47p8v
0.1525,Event,ADDED,eval-sanitize-10-r0-044.18d4e4b602f26992,reason=Completed count=1 msg=Job completed
0.1526,Event,ADDED,eval-sanitize-10-r0-045-wzd2r.18d4e4b094a40448,reason=Scheduled count=None msg=Successfully assigned compute/eval-sanitize-10-r0-045-wzd2r to kind-worker4
0.1528,Event,ADDED,eval-sanitize-10-r0-045-wzd2r.18d4e4b0b2b212e2,"reason=Pulled count=1 msg=Container image ""busybox:musl"" already present on machine"
0.153,Event,ADDED,eval-sanitize-10-r0-045-wzd2r.18d4e4b0b3ccd096,reason=Created count=1 msg=Created container: task
0.1531,Event,ADDED,eval-sanitize-10-r0-045-wzd2r.18d4e4b0bc38b1db,reason=Started count=1 msg=Started container task
0.1533,Event,ADDED,eval-sanitize-10-r0-045.18d4e4b09373ca68,reason=SuccessfulCreate count=1 msg=Created pod: eval-sanitize-10-r0-045-wzd2r
0.1535,Event,ADDED,eval-sanitize-10-r0-045.18d4e4b656c251f6,reason=Completed count=1 msg=Job completed
0.1536,Event,ADDED,eval-sanitize-10-r0-046-p2xfg.18d4e4b0d0a81368,"reason=FailedScheduling count=None msg=0/6 nodes are available: 3 c_wall violated: 2 conflicting context pair(s) with node memory, 3 node(s) had untolerated taint(s). no new claims to deallocate, preemption: 0/6 nodes are available: 3 No preemption victims found for incoming pod, 3 Preemption is not helpful for scheduling."
0.1538,Event,ADDED,eval-sanitize-10-r0-046-p2xfg.18d4e4b0d40d8d0b,"reason=FailedScheduling count=None msg=0/6 nodes are available: 3 c_wall violated: 2 conflicting context pair(s) with node memory, 3 node(s) had untolerated taint(s). no new claims to deallocate, preemption: 0/6 nodes are available: 3 No preemption victims found for incoming pod, 3 Preemption is not helpful for scheduling."
0.154,Event,ADDED,eval-sanitize-10-r0-046-p2xfg.18d4e4b1085007f4,"reason=FailedScheduling count=None msg=0/6 nodes are available: 2 c_wall violated: 2 conflicting context pair(s) with node memory, 4 node(s) had untolerated taint(s). no new claims to deallocate, preemption: 0/6 nodes are available: 2 No preemption victims found for incoming pod, 4 Preemption is not helpful for scheduling."
0.1542,Event,ADDED,eval-sanitize-10-r0-046-p2xfg.18d4e4b132fa6c79,"reason=FailedScheduling count=None msg=0/6 nodes are available: 1 c_wall violated: 2 conflicting context pair(s) with node memory, 5 node(s) had untolerated taint(s). no new claims to deallocate, preemption: 0/6 nodes are available: 1 No preemption victims found for incoming pod, 5 Preemption is not helpful for scheduling."
0.1543,Event,ADDED,eval-sanitize-10-r0-046-p2xfg.18d4e4b36ea54032,reason=Scheduled count=None msg=Successfully assigned compute/eval-sanitize-10-r0-046-p2xfg to kind-worker2
0.1545,Event,ADDED,eval-sanitize-10-r0-046-p2xfg.18d4e4b38c95aa2e,"reason=Pulled count=1 msg=Container image ""busybox:musl"" already present on machine"
0.1546,Event,ADDED,eval-sanitize-10-r0-046-p2xfg.18d4e4b38e525b35,reason=Created count=1 msg=Created container: task
0.1548,Event,ADDED,eval-sanitize-10-r0-046-p2xfg.18d4e4b39828973c,reason=Started count=1 msg=Started container task
0.155,Event,ADDED,eval-sanitize-10-r0-046.18d4e4b0cfdb5813,reason=SuccessfulCreate count=1 msg=Created pod: eval-sanitize-10-r0-046-p2xfg
0.1551,Event,ADDED,eval-sanitize-10-r0-046.18d4e4b92a33ce64,reason=Completed count=1 msg=Job completed
0.1553,Event,ADDED,eval-sanitize-10-r0-047-75x68.18d4e4b10b26b4d0,"reason=FailedScheduling count=None msg=0/6 nodes are available: 2 c_wall violated: 2 conflicting context pair(s) with node memory, 4 node(s) had untolerated taint(s). no new claims to deallocate, preemption: 0/6 nodes are available: 2 No preemption victims found for incoming pod, 4 Preemption is not helpful for scheduling."
0.1555,Event,ADDED,eval-sanitize-10-r0-047-75x68.18d4e4b10bd239ab,"reason=FailedScheduling count=None msg=0/6 nodes are available: 2 c_wall violated: 2 conflicting context pair(s) with node memory, 4 node(s) had untolerated taint(s). no new claims to deallocate, preemption: 0/6 nodes are available: 2 No preemption victims found for incoming pod, 4 Preemption is not helpful for scheduling."
0.1557,Event,ADDED,eval-sanitize-10-r0-047-75x68.18d4e4b133232ea2,"reason=FailedScheduling count=None msg=0/6 nodes are available: 1 c_wall violated: 2 conflicting context pair(s) with node memory, 5 node(s) had untolerated taint(s). no new claims to deallocate, preemption: 0/6 nodes are available: 1 No preemption victims found for incoming pod, 5 Preemption is not helpful for scheduling."
0.1559,Event,ADDED,eval-sanitize-10-r0-047-75x68.18d4e4b36e1b7988,reason=Scheduled count=None msg=Successfully assigned compute/eval-sanitize-10-r0-047-75x68 to kind-worker2
0.1561,Event,ADDED,eval-sanitize-10-r0-047-75x68.18d4e4b38f2ab0d9,"reason=Pulled count=1 msg=Container image ""busybox:musl"" already present on machine"
0.1562,Event,ADDED,eval-sanitize-10-r0-047-75x68.18d4e4b3910e8c5d,reason=Created count=1 msg=Created container: task
0.1564,Event,ADDED,eval-sanitize-10-r0-047-75x68.18d4e4b3988f5d7c,reason=Started count=1 msg=Started container task
0.1565,Event,ADDED,eval-sanitize-10-r0-047.18d4e4b10abf4cd3,reason=SuccessfulCreate count=1 msg=Created pod: eval-sanitize-10-r0-047-75x68
0.1567,Event,ADDED,eval-sanitize-10-r0-047.18d4e4b929a75a0b,reason=Completed count=1 msg=Job completed
0.1569,Event,ADDED,eval-sanitize-10-r0-048-hvrjd.18d4e4b146f74955,"reason=FailedScheduling count=None msg=0/6 nodes are available: 6 node(s) had untolerated taint(s). no new claims to deallocate, preemption: 0/6 nodes are available: 6 Preemption is not helpful for scheduling."
0.1571,Event,ADDED,eval-sanitize-10-r0-048-hvrjd.18d4e4b36e8fe1b4,"reason=FailedScheduling count=None msg=0/6 nodes are available: 1 c_wall violated: 1 conflicting context pair(s) with node memory, 5 node(s) had untolerated taint(s). no new claims to deallocate, preemption: 0/6 nodes are available: 1 No preemption victims found for incoming pod, 5 Preemption is not helpful for scheduling."
0.1573,Event,ADDED,eval-sanitize-10-r0-048-hvrjd.18d4e4b37a902969,"reason=FailedScheduling count=None msg=0/6 nodes are available: 1 c_wall violated: 1 conflicting context pair(s) with node memory, 5 node(s) had untolerated taint(s). no new claims to deallocate, preemption: 0/6 nodes are available: 1 No preemption victims found for incoming pod, 5 Preemption is not helpful for scheduling."
0.1574,Event,ADDED,eval-sanitize-10-r0-048-hvrjd.18d4e4b6062a6ef6,"reason=FailedScheduling count=None msg=0/6 nodes are available: 1 c_wall violated: 1 conflicting context pair(s) with node memory, 1 c_wall violated: 2 conflicting context pair(s) with node memory, 4 node(s) had untolerated taint(s). no new claims to deallocate, preemption: 0/6 nodes are available: 2 No preemption victims found for incoming pod, 4 Preemption is not helpful for scheduling."
0.1576,Event,ADDED,eval-sanitize-10-r0-048-hvrjd.18d4e4b622e2b749,"reason=FailedScheduling count=None msg=0/6 nodes are available: 1 c_wall violated: 2 conflicting context pair(s) with node memory, 2 c_wall violated: 1 conflicting context pair(s) with node memory, 3 node(s) had untolerated taint(s). no new claims to deallocate, preemption: 0/6 nodes are available: 3 No preemption victims found for incoming pod, 3 Preemption is not helpful for scheduling."
0.1577,Event,ADDED,eval-sanitize-10-r0-048-hvrjd.18d4e4b652ca4de5,"reason=FailedScheduling count=None msg=0/6 nodes are available: 1 c_wall violated: 2 conflicting context pair(s) with node memory, 2 node(s) had untolerated taint(s), 3 c_wall violated: 1 conflicting context pair(s) with node memory. no new claims to deallocate, preemption: 0/6 nodes are available: 2 Preemption is not helpful for scheduling, 4 No preemption victims found for incoming pod."
0.1579,Event,ADDED,eval-sanitize-10-r0-048-hvrjd.18d4e4b676e733e6,"reason=FailedScheduling count=None msg=0/6 nodes are available: 1 c_wall violated: 2 conflicting context pair(s) with node memory, 2 node(s) had untolerated taint(s), 3 c_wall violated: 1 conflicting context pair(s) with node memory. no new claims to deallocate, preemption: 0/6 nodes are available: 2 Preemption is not helpful for scheduling, 4 No preemption victims found for incoming pod."
0.158,Event,ADDED,eval-sanitize-10-r0-048-hvrjd.18d4e4b85e8b347f,"reason=FailedScheduling count=None msg=0/6 nodes are available: 1 c_wall violated: 1 conflicting context pair(s) with node memory, 2 c_wall violated: 2 conflicting context pair(s) with node memory, 3 node(s) had untolerated taint(s). no new claims to deallocate, preemption: 0/6 nodes are available: 3 No preemption victims found for incoming pod, 3 Preemption is not helpful for scheduling."
0.1582,Event,ADDED,eval-sanitize-10-r0-048-hvrjd.18d4e4b86b7c324b,"reason=FailedScheduling count=None msg=0/6 nodes are available: 1 c_wall violated: 1 conflicting context pair(s) with node memory, 1 c_wall violated: 2 conflicting context pair(s) with node memory, 4 node(s) had untolerated taint(s). no new claims to deallocate, preemption: 0/6 nodes are available: 2 No preemption victims found for incoming pod, 4 Preemption is not helpful for scheduling."
0.1583,Event,ADDED,eval-sanitize-10-r0-048-hvrjd.18d4e4b8778f0b9b,"reason=FailedScheduling count=None msg=0/6 nodes are available: 1 c_wall violated: 2 conflicting context pair(s) with node memory, 5 node(s) had untolerated taint(s). no new claims to deallocate, preemption: 0/6 nodes are available: 1 No preemption victims found for incoming pod, 5 Preemption is not helpful for scheduling."
0.1585,Event,ADDED,eval-sanitize-10-r0-048-hvrjd.18d4e4b87dfe5f0e,"reason=FailedScheduling count=None msg=0/6 nodes are available: 1 c_wall violated: 2 conflicting context pair(s) with node memory, 5 node(s) had untolerated taint(s). no new claims to deallocate, preemption: 0/6 nodes are available: 1 No preemption victims found for incoming pod, 5 Preemption is not helpful for scheduling."
0.1587,Event,ADDED,eval-sanitize-10-r0-048-hvrjd.18d4e4baa8702067,reason=Scheduled count=None msg=Successfully assigned compute/eval-sanitize-10-r0-048-hvrjd to kind-worker2
0.1588,Event,ADDED,eval-sanitize-10-r0-048-hvrjd.18d4e4bae8042a5b,"reason=Pulled count=1 msg=Container image ""busybox:musl"" already present on machine"
0.159,Event,ADDED,eval-sanitize-10-r0-048-hvrjd.18d4e4baeb6d0bb8,reason=Created count=1 msg=Created container: task
0.1592,Event,ADDED,eval-sanitize-10-r0-048-hvrjd.18d4e4baf48363e4,reason=Started count=1 msg=Started container task
0.1593,Event,ADDED,eval-sanitize-10-r0-048.18d4e4b146f00364,reason=SuccessfulCreate count=1 msg=Created pod: eval-sanitize-10-r0-048-hvrjd
0.1595,Event,ADDED,eval-sanitize-10-r0-048.18d4e4c02e5f4ef5,reason=Completed count=1 msg=Job completed
0.1597,Event,ADDED,eval-sanitize-10-r0-049-fd757.18d4e4b184bc1cf8,"reason=FailedScheduling count=None msg=0/6 nodes are available: 6 node(s) had untolerated taint(s). no new claims to deallocate, preemption: 0/6 nodes are available: 6 Preemption is not helpful for scheduling."
0.1598,Event,ADDED,eval-sanitize-10-r0-049-fd757.18d4e4b36f3cd9e0,"reason=FailedScheduling count=None msg=0/6 nodes are available: 1 c_wall violated: 1 conflicting context pair(s) with node memory, 5 node(s) had untolerated taint(s). no new claims to deallocate, preemption: 0/6 nodes are available: 1 No preemption victims found for incoming pod, 5 Preemption is not helpful for scheduling."
0.16,Event,ADDED,eval-sanitize-10-r0-049-fd757.18d4e4b37ab74c72,"reason=FailedScheduling count=None msg=0/6 nodes are available: 1 c_wall violated: 1 conflicting context pair(s) with node memory, 5 node(s) had untolerated taint(s). no new claims to deallocate, preemption: 0/6 nodes are available: 1 No preemption victims found for incoming pod, 5 Preemption is not helpful for scheduling."
0.1601,Event,ADDED,eval-sanitize-10-r0-049-fd757.18d4e4b60ac3f9f3,"reason=FailedScheduling count=None msg=0/6 nodes are available: 2 c_wall violated: 1 conflicting context pair(s) with node memory, 4 node(s) had untolerated taint(s). no new claims to deallocate, preemption: 0/6 nodes are available: 2 No preemption victims found for incoming pod, 4 Preemption is not helpful for scheduling."
0.1603,Event,ADDED,eval-sanitize-10-r0-049-fd757.18d4e4b629d6976f,reason=Scheduled count=None msg=Successfully assigned compute/eval-sanitize-10-r0-049-fd757 to kind-worker4
0.1604,Event,ADDED,eval-sanitize-10-r0-049-fd757.18d4e4b6475438ad,"reason=Pulled count=1 msg=Container image ""busybox:musl"" already present on machine"
0.1606,Event,ADDED,eval-sanitize-10-r0-049-fd757.18d4e4b6485eaa1f,reason=Created count=1 msg=Created container: task
0.1608,Event,ADDED,eval-sanitize-10-r0-049-fd757.18d4e4b64e62b6dc,reason=Started count=1 msg=Started container task
0.1609,Event,ADDED,eval-sanitize-10-r0-049.18d4e4b184b6b140,reason=SuccessfulCreate count=1 msg=Created pod: eval-sanitize-10-r0-049-fd757
0.1613,Event,ADDED,eval-sanitize-10-r0-049.18d4e4bbbbe46c59,reason=Completed count=1 msg=Job completed
0.1614,Event,ADDED,eval-sanitize-10-r0-050-csrlz.18d4e4b1be21c6f3,"reason=FailedScheduling count=None msg=0/6 nodes are available: 6 node(s) had untolerated taint(s). no new claims to deallocate, preemption: 0/6 nodes are available: 6 Preemption is not helpful for scheduling."
0.1616,Event,ADDED,eval-sanitize-10-r0-050-csrlz.18d4e4b37005aa9c,reason=Scheduled count=None msg=Successfully assigned compute/eval-sanitize-10-r0-050-csrlz to kind-worker2
0.1618,Event,ADDED,eval-sanitize-10-r0-050-csrlz.18d4e4b38d977549,"reason=Pulled count=1 msg=Container image ""busybox:musl"" already present on machine"
0.1621,Event,ADDED,eval-sanitize-10-r0-050-csrlz.18d4e4b3905a0350,reason=Created count=1 msg=Created container: task
0.1623,Event,ADDED,eval-sanitize-10-r0-050-csrlz.18d4e4b398907370,reason=Started count=1 msg=Started container task
0.1625,Event,ADDED,eval-sanitize-10-r0-050.18d4e4b1be1b721f,reason=SuccessfulCreate count=1 msg=Created pod: eval-sanitize-10-r0-050-csrlz
0.1627,Event,ADDED,eval-sanitize-10-r0-050.18d4e4b929a7b8be,reason=Completed count=1 msg=Job completed
0.1629,Event,ADDED,eval-sanitize-10-r0-051-z2b26.18d4e4b1f921d1f0,"reason=FailedScheduling count=None msg=0/6 nodes are available: 6 node(s) had untolerated taint(s). no new claims to deallocate, preemption: 0/6 nodes are available: 6 Preemption is not helpful for scheduling."
0.1631,Event,ADDED,eval-sanitize-10-r0-051-z2b26.18d4e4b37036b7be,reason=Scheduled count=None msg=Successfully assigned compute/eval-sanitize-10-r0-051-z2b26 to kind-worker2
0.1633,Event,ADDED,eval-sanitize-10-r0-051-z2b26.18d4e4b38ccebbcd,"reason=Pulled count=1 msg=Container image ""busybox:musl"" already present on machine"
0.1636,Event,ADDED,eval-sanitize-10-r0-051-z2b26.18d4e4b38f25b233,reason=Created count=1 msg=Created container: task
0.1638,Event,ADDED,eval-sanitize-10-r0-051-z2b26.18d4e4b398940aad,reason=Started count=1 msg=Started container task
0.1641,Event,ADDED,eval-sanitize-10-r0-051.18d4e4b1f918c46d,reason=SuccessfulCreate count=1 msg=Created pod: eval-sanitize-10-r0-051-z2b26
0.1642,Event,ADDED,eval-sanitize-10-r0-051.18d4e4b92946a08a,reason=Completed count=1 msg=Job completed
0.1644,Event,ADDED,eval-sanitize-10-r0-052-vbnc7.18d4e4b23e9f7877,"reason=FailedScheduling count=None msg=0/6 nodes are available: 6 node(s) had untolerated taint(s). no new claims to deallocate, preemption: 0/6 nodes are available: 6 Preemption is not helpful for scheduling."
0.1646,Event,ADDED,eval-sanitize-10-r0-052-vbnc7.18d4e4b3708ac217,reason=Scheduled count=None msg=Successfully assigned compute/eval-sanitize-10-r0-052-vbnc7 to kind-worker2
0.1648,Event,ADDED,eval-sanitize-10-r0-052-vbnc7.18d4e4b38d7d7910,"reason=Pulled count=1 msg=Container image ""busybox:musl"" already present on machine"
0.1649,Event,ADDED,eval-sanitize-10-r0-052-vbnc7.18d4e4b38fd5d4fd,reason=Created count=1 msg=Created container: task
0.1651,Event,ADDED,eval-sanitize-10-r0-052-vbnc7.18d4e4b3988eee35,reason=Started count=1 msg=Started container task
0.1653,Event,ADDED,eval-sanitize-10-r0-052.18d4e4b23e93b33e,reason=SuccessfulCreate count=1 msg=Created pod: eval-sanitize-10-r0-052-vbnc7
0.1654,Event,ADDED,eval-sanitize-10-r0-052.18d4e4b92a139fa0,reason=Completed count=1 msg=Job completed
0.1656,Event,ADDED,eval-sanitize-10-r0-053-6z5k9.18d4e4b289d5d551,"reason=FailedScheduling count=None msg=0/6 nodes are available: 6 node(s) had untolerated taint(s). no new claims to deallocate, preemption: 0/6 nodes are available: 6 Preemption is not helpful for scheduling."
0.1657,Event,ADDED,eval-sanitize-10-r0-053-6z5k9.18d4e4b37448b10c,"reason=FailedScheduling count=None msg=0/6 nodes are available: 1 c_wall violated: 1 conflicting context pair(s) with node memory, 5 node(s) had untolerated taint(s). no new claims to deallocate, preemption: 0/6 nodes are available: 1 No preemption victims found for incoming pod, 5 Preemption is not helpful for scheduling."
0.1659,Event,ADDED,eval-sanitize-10-r0-053-6z5k9.18d4e4b37ae33b73,"reason=FailedScheduling count=None msg=0/6 nodes are available: 1 c_wall violated: 1 conflicting context pair(s) with node memory, 5 node(s) had untolerated taint(s). no new claims to deallocate, preemption: 0/6 nodes are available: 1 No preemption victims found for incoming pod, 5 Preemption is not helpful for scheduling."
0.1661,Event,ADDED,eval-sanitize-10-r0-053-6z5k9.18d4e4b5f69540be,reason=Scheduled count=None msg=Successfully assigned compute/eval-sanitize-10-r0-053-6z5k9 to kind-worker
0.1663,Event,ADDED,eval-sanitize-10-r0-053-6z5k9.18d4e4b612be4a47,"reason=Pulled count=1 msg=Container image ""busybox:musl"" already present on machine"
0.1664,Event,ADDED,eval-sanitize-10-r0-053-6z5k9.18d4e4b614e035b0,reason=Created count=1 msg=Created container: task
0.1666,Event,ADDED,eval-sanitize-10-r0-053-6z5k9.18d4e4b6173d187f,reason=Started count=1 msg=Started container task
0.1668,Event,ADDED,eval-sanitize-10-r0-053.18d4e4b289cb5880,reason=SuccessfulCreate count=1 msg=Created pod: eval-sanitize-10-r0-053-6z5k9
0.1669,Event,ADDED,eval-sanitize-10-r0-053.18d4e4bb6845848d,reason=Completed count=1 msg=Job completed
0.1671,Event,ADDED,eval-sanitize-10-r0-054-4frvx.18d4e4b2bbb7ec76,"reason=FailedScheduling count=None msg=0/6 nodes are available: 6 node(s) had untolerated taint(s). no new claims to deallocate, preemption: 0/6 nodes are available: 6 Preemption is not helpful for scheduling."
0.1672,Event,ADDED,eval-sanitize-10-r0-054-4frvx.18d4e4b374bfceb8,"reason=FailedScheduling count=None msg=0/6 nodes are available: 1 c_wall violated: 2 conflicting context pair(s) with node memory, 5 node(s) had untolerated taint(s). no new claims to deallocate, preemption: 0/6 nodes are available: 1 No preemption victims found for incoming pod, 5 Preemption is not helpful for scheduling."
0.1674,Event,ADDED,eval-sanitize-10-r0-054-4frvx.18d4e4b37b0bc527,"reason=FailedScheduling count=None msg=0/6 nodes are available: 1 c_wall violated: 2 conflicting context pair(s) with node memory, 5 node(s) had untolerated taint(s). no new claims to deallocate, preemption: 0/6 nodes are available: 1 No preemption victims found for incoming pod, 5 Preemption is not helpful for scheduling."
0.1676,Event,ADDED,eval-sanitize-10-r0-054-4frvx.18d4e4b5f6b98813,reason=Scheduled count=None msg=Successfully assigned compute/eval-sanitize-10-r0-054-4frvx to kind-worker
0.1677,Event,ADDED,eval-sanitize-10-r0-054-4frvx.18d4e4b612e232b3,"reason=Pulled count=1 msg=Container image ""busybox:musl"" already present on machine"
0.1679,Event,ADDED,eval-sanitize-10-r0-054-4frvx.18d4e4b61529a48a,reason=Created count=1 msg=Created container: task
0.1681,Event,ADDED,eval-sanitize-10-r0-054-4frvx.18d4e4b6173dbd8b,reason=Started count=1 msg=Started container task
0.1682,Event,ADDED,eval-sanitize-10-r0-054.18d4e4b2bbac57ac,reason=SuccessfulCreate count=1 msg=Created pod: eval-sanitize-10-r0-054-4frvx
0.1684,Event,ADDED,eval-sanitize-10-r0-054.18d4e4bbeaaaabc9,reason=Completed count=1 msg=Job completed
0.1685,Event,ADDED,eval-sanitize-10-r0-055-vp7xw.18d4e4b2ef170f26,"reason=FailedScheduling count=None msg=0/6 nodes are available: 6 node(s) had untolerated taint(s). no new claims to deallocate, preemption: 0/6 nodes are available: 6 Preemption is not helpful for scheduling."
0.1687,Event,ADDED,eval-sanitize-10-r0-055-vp7xw.18d4e4b3752e7536,"reason=FailedScheduling count=None msg=0/6 nodes are available: 1 c_wall violated: 1 conflicting context pair(s) with node memory, 5 node(s) had untolerated taint(s). no new claims to deallocate, preemption: 0/6 nodes are available: 1 No preemption victims found for incoming pod, 5 Preemption is not helpful for scheduling."
0.1689,Event,ADDED,eval-sanitize-10-r0-055-vp7xw.18d4e4b37b3127a1,"reason=FailedScheduling count=None msg=0/6 nodes are available: 1 c_wall violated: 1 conflicting context pair(s) with node memory, 5 node(s) had untolerated taint(s). no new claims to deallocate, preemption: 0/6 nodes are available: 1 No preemption victims found for incoming pod, 5 Preemption is not helpful for scheduling."
0.169,Event,ADDED,eval-sanitize-10-r0-055-vp7xw.18d4e4b5f687ab5c,"reason=FailedScheduling count=None msg=0/6 nodes are available: 1 c_wall violated: 1 conflicting context pair(s) with node memory, 5 node(s) had untolerated taint(s). no new claims to deallocate, preemption: 0/6 nodes are available: 1 No preemption victims found for incoming pod, 5 Preemption is not helpful for scheduling."
0.1692,Event,ADDED,eval-sanitize-10-r0-055-vp7xw.18d4e4b610ca0a47,"reason=FailedScheduling count=None msg=0/6 nodes are available: 1 c_wall violated: 1 conflicting context pair(s) with node memory, 1 c_wall violated: 2 conflicting context pair(s) with node memory, 4 node(s) had untolerated taint(s). no new claims to deallocate, preemption: 0/6 nodes are available: 2 No preemption victims found for incoming pod, 4 Preemption is not helpful for scheduling."
0.1693,Event,ADDED,eval-sanitize-10-r0-055-vp7xw.18d4e4b64643bb7a,"reason=FailedScheduling count=None msg=0/6 nodes are available: 1 c_wall violated: 2 conflicting context pair(s) with node memory, 2 node(s) had untolerated taint(s), 3 c_wall violated: 1 conflicting context pair(s) with node memory. no new claims to deallocate, preemption: 0/6 nodes are available: 2 Preemption is not helpful for scheduling, 4 No preemption victims found for incoming pod."
0.1695,Event,ADDED,eval-sanitize-10-r0-055-vp7xw.18d4e4b664b16b89,"reason=FailedScheduling count=None msg=0/6 nodes are available: 1 c_wall violated: 2 conflicting context pair(s) with node memory, 2 node(s) had untolerated taint(s), 3 c_wall violated: 1 conflicting context pair(s) with node memory. no new claims to deallocate, preemption: 0/6 nodes are available: 2 Preemption is not helpful for scheduling, 4 No preemption victims found for incoming pod."
0.1697,Event,ADDED,eval-sanitize-10-r0-055-vp7xw.18d4e4b841291f39,"reason=FailedScheduling count=None msg=0/6 nodes are available: 2 c_wall violated: 1 conflicting context pair(s) with node memory, 2 c_wall violated: 2 conflicting context pair(s) with node memory, 2 node(s) had untolerated taint(s). no new claims to deallocate, preemption: 0/6 nodes are available: 2 Preemption is not helpful for scheduling, 4 No preemption victims found for incoming pod."
0.1699,Event,ADDED,eval-sanitize-10-r0-055-vp7xw.18d4e4b870d42154,"reason=FailedScheduling count=None msg=0/6 nodes are available: 1 c_wall violated: 1 conflicting context pair(s) with node memory, 1 c_wall violated: 2 conflicting context pair(s) with node memory, 4 node(s) had untolerated taint(s). no new claims to deallocate, preemption: 0/6 nodes are available: 2 No preemption victims found for incoming pod, 4 Preemption is not helpful for scheduling."
0.17,Event,ADDED,eval-sanitize-10-r0-055-vp7xw.18d4e4b8826c545f,"reason=FailedScheduling count=None msg=0/6 nodes are available: 1 c_wall violated: 2 conflicting context pair(s) with node memory, 5 node(s) had untolerated taint(s). no new claims to deallocate, preemption: 0/6 nodes are available: 1 No preemption victims found for incoming pod, 5 Preemption is not helpful for scheduling."
0.1702,Event,ADDED,eval-sanitize-10-r0-055-vp7xw.18d4e4bab149dca9,reason=Scheduled count=None msg=Successfully assigned compute/eval-sanitize-10-r0-055-vp7xw to kind-worker2
0.1704,Event,ADDED,eval-sanitize-10-r0-055-vp7xw.18d4e4bace7c0372,"reason=Pulled count=1 msg=Container image ""busybox:musl"" already present on machine"
0.1705,Event,ADDED,eval-sanitize-10-r0-055-vp7xw.18d4e4bad050025f,reason=Created count=1 msg=Created container: task
0.1707,Event,ADDED,eval-sanitize-10-r0-055-vp7xw.18d4e4bad28a2364,reason=Started count=1 msg=Started container task
0.1709,Event,ADDED,eval-sanitize-10-r0-055.18d4e4b2ef0bff0a,reason=SuccessfulCreate count=1 msg=Created pod: eval-sanitize-10-r0-055-vp7xw
0.1714,Event,ADDED,eval-sanitize-10-r0-055.18d4e4c068f84ec4,reason=Completed count=1 msg=Job completed
0.1716,Event,ADDED,eval-sanitize-10-r0-056-cbrgg.18d4e4b32326b3bb,"reason=FailedScheduling count=None msg=0/6 nodes are available: 6 node(s) had untolerated taint(s). no new claims to deallocate, preemption: 0/6 nodes are available: 6 Preemption is not helpful for scheduling."
0.1717,Event,ADDED,eval-sanitize-10-r0-056-cbrgg.18d4e4b376ae94b5,"reason=FailedScheduling count=None msg=0/6 nodes are available: 1 c_wall violated: 2 conflicting context pair(s) with node memory, 5 node(s) had untolerated taint(s). no new claims to deallocate, preemption: 0/6 nodes are available: 1 No preemption victims found for incoming pod, 5 Preemption is not helpful for scheduling."
0.172,Event,ADDED,eval-sanitize-10-r0-056-cbrgg.18d4e4b37b5aecb6,"reason=FailedScheduling count=None msg=0/6 nodes are available: 1 c_wall violated: 2 conflicting context pair(s) with node memory, 5 node(s) had untolerated taint(s). no new claims to deallocate, preemption: 0/6 nodes are available: 1 No preemption victims found for incoming pod, 5 Preemption is not helpful for scheduling."
0.1721,Event,ADDED,eval-sanitize-10-r0-056-cbrgg.18d4e4b5fa7a1172,"reason=FailedScheduling count=None msg=0/6 nodes are available: 1 c_wall violated: 1 conflicting context pair(s) with node memory, 5 node(s) had untolerated taint(s). no new claims to deallocate, preemption: 0/6 nodes are available: 1 No preemption victims found for incoming pod, 5 Preemption is not helpful for scheduling."
0.1723,Event,ADDED,eval-sanitize-10-r0-056-cbrgg.18d4e4b611dd43dc,reason=Scheduled count=None msg=Successfully assigned compute/eval-sanitize-10-r0-056-cbrgg to kind-worker3
0.1724,Event,ADDED,eval-sanitize-10-r0-056-cbrgg.18d4e4b62cd61ae3,"reason=Pulled count=1 msg=Container image ""busybox:musl"" already present on machine"
0.1726,Event,ADDED,eval-sanitize-10-r0-056-cbrgg.18d4e4b62e43544a,reason=Created count=1 msg=Created container: task
0.1728,Event,ADDED,eval-sanitize-10-r0-056-cbrgg.18d4e4b6307c3dbb,reason=Started count=1 msg=Started container task
0.1729,Event,ADDED,eval-sanitize-10-r0-056.18d4e4b3231746f3,reason=SuccessfulCreate count=1 msg=Created pod: eval-sanitize-10-r0-056-cbrgg
0.1731,Event,ADDED,eval-sanitize-10-r0-056.18d4e4bb6a9d4d7e,reason=Completed count=1 msg=Job completed
0.1732,Event,ADDED,eval-sanitize-10-r0-057-5xg2x.18d4e4b35fab1132,"reason=FailedScheduling count=None msg=0/6 nodes are available: 6 node(s) had untolerated taint(s). no new claims to deallocate, preemption: 0/6 nodes are available: 6 Preemption is not helpful for scheduling."
0.1734,Event,ADDED,eval-sanitize-10-r0-057-5xg2x.18d4e4b379f7b777,"reason=FailedScheduling count=None msg=0/6 nodes are available: 1 c_wall violated: 2 conflicting context pair(s) with node memory, 5 node(s) had untolerated taint(s). no new claims to deallocate, preemption: 0/6 nodes are available: 1 No preemption victims found for incoming pod, 5 Preemption is not helpful for scheduling."
0.1737,Event,ADDED,eval-sanitize-10-r0-057-5xg2x.18d4e4b37b8b55ff,"reason=FailedScheduling count=None msg=0/6 nodes are available: 1 c_wall violated: 2 conflicting context pair(s) with node memory, 5 node(s) had untolerated taint(s). no new claims to deallocate, preemption: 0/6 nodes are available: 1 No preemption victims found for incoming pod, 5 Preemption is not helpful for scheduling."
0.1738,Event,ADDED,eval-sanitize-10-r0-057-5xg2x.18d4e4b5fb0594c0,"reason=FailedScheduling count=None msg=0/6 nodes are available: 1 c_wall violated: 1 conflicting context pair(s) with node memory, 5 node(s) had untolerated taint(s). no new claims to deallocate, preemption: 0/6 nodes are available: 1 No preemption victims found for incoming pod, 5 Preemption is not helpful for scheduling."
0.174,Event,ADDED,eval-sanitize-10-r0-057-5xg2x.18d4e4b612c1a52f,reason=Scheduled count=None msg=Successfully assigned compute/eval-sanitize-10-r0-057-5xg2x to kind-worker3
0.1741,Event,ADDED,eval-sanitize-10-r0-057-5xg2x.18d4e4b62d2c1d1e,"reason=Pulled count=1 msg=Container image ""busybox:musl"" already present on machine"
0.1743,Event,ADDED,eval-sanitize-10-r0-057-5xg2x.18d4e4b62e9dd50f,reason=Created count=1 msg=Created container: task
0.1745,Event,ADDED,eval-sanitize-10-r0-057-5xg2x.18d4e4b630c78f00,reason=Started count=1 msg=Started container task
0.1746,Event,ADDED,eval-sanitize-10-r0-057.18d4e4b35fa0fb33,reason=SuccessfulCreate count=1 msg=Created pod: eval-sanitize-10-r0-057-5xg2x
0.1748,Event,ADDED,eval-sanitize-10-r0-057.18d4e4bb6874689b,reason=Completed count=1 msg=Job completed
0.1749,Event,ADDED,eval-sanitize-10-r0-058-lwnj8.18d4e4b39a85c329,"reason=FailedScheduling count=None msg=0/6 nodes are available: 1 c_wall violated: 1 conflicting context pair(s) with node memory, 5 node(s) had untolerated taint(s). no new claims to deallocate, preemption: 0/6 nodes are available: 1 No preemption victims found for incoming pod, 5 Preemption is not helpful for scheduling."
0.1751,Event,ADDED,eval-sanitize-10-r0-058-lwnj8.18d4e4b39b29af40,"reason=FailedScheduling count=None msg=0/6 nodes are available: 1 c_wall violated: 1 conflicting context pair(s) with node memory, 5 node(s) had untolerated taint(s). no new claims to deallocate, preemption: 0/6 nodes are available: 1 No preemption victims found for incoming pod, 5 Preemption is not helpful for scheduling."
0.1753,Event,ADDED,eval-sanitize-10-r0-058-lwnj8.18d4e4b605510c8e,"reason=FailedScheduling count=None msg=0/6 nodes are available: 1 c_wall violated: 1 conflicting context pair(s) with node memory, 1 c_wall violated: 2 conflicting context pair(s) with node memory, 4 node(s) had untolerated taint(s). no new claims to deallocate, preemption: 0/6 nodes are available: 2 No preemption victims found for incoming pod, 4 Preemption is not helpful for scheduling."
0.1754,Event,ADDED,eval-sanitize-10-r0-058-lwnj8.18d4e4b61d59d2a6,"reason=FailedScheduling count=None msg=0/6 nodes are available: 1 c_wall violated: 2 conflicting context pair(s) with node memory, 2 c_wall violated: 1 conflicting context pair(s) with node memory, 3 node(s) had untolerated taint(s). no new claims to deallocate, preemption: 0/6 nodes are available: 3 No preemption victims found for incoming pod, 3 Preemption is not helpful for scheduling."
0.1756,Event,ADDED,eval-sanitize-10-r0-058-lwnj8.18d4e4b64f45e0fb,"reason=FailedScheduling count=None msg=0/6 nodes are available: 1 c_wall violated: 2 conflicting context pair(s) with node memory, 2 node(s) had untolerated taint(s), 3 c_wall violated: 1 conflicting context pair(s) with node memory. no new claims to deallocate, preemption: 0/6 nodes are available: 2 Preemption is not helpful for scheduling, 4 No preemption victims found for incoming pod."
0.1757,Event,ADDED,eval-sanitize-10-r0-058-lwnj8.18d4e4b676181160,"reason=FailedScheduling count=None msg=0/6 nodes are available: 1 c_wall violated: 2 conflicting context pair(s) with node memory, 2 node(s) had untolerated taint(s), 3 c_wall violated: 1 conflicting context pair(s) with node memory. no new claims to deallocate, preemption: 0/6 nodes are available: 2 Preemption is not helpful for scheduling, 4 No preemption victims found for incoming pod."
0.1759,Event,ADDED,eval-sanitize-10-r0-058-lwnj8.18d4e4b85b3725cd,"reason=FailedScheduling count=None msg=0/6 nodes are available: 1 c_wall violated: 1 conflicting context pair(s) with node memory, 2 c_wall violated: 2 conflicting context pair(s) with node memory, 3 node(s) had untolerated taint(s). no new claims to deallocate, preemption: 0/6 nodes are available: 3 No preemption victims found for incoming pod, 3 Preemption is not helpful for scheduling."
0.176,Event,ADDED,eval-sanitize-10-r0-058-lwnj8.18d4e4b86ab19a5b,"reason=FailedScheduling count=None msg=0/6 nodes are available: 1 c_wall violated: 1 conflicting context pair(s) with node memory, 1 c_wall violated: 2 conflicting context pair(s) with node memory, 4 node(s) had untolerated taint(s). no new claims to deallocate, preemption: 0/6 nodes are available: 2 No preemption victims found for incoming pod, 4 Preemption is not helpful for scheduling."
0.1762,Event,ADDED,eval-sanitize-10-r0-058-lwnj8.18d4e4b877152602,"reason=FailedScheduling count=None msg=0/6 nodes are available: 1 c_wall violated: 2 conflicting context pair(s) with node memory, 5 node(s) had untolerated taint(s). no new claims to deallocate, preemption: 0/6 nodes are available: 1 No preemption victims found for incoming pod, 5 Preemption is not helpful for scheduling."
0.1764,Event,ADDED,eval-sanitize-10-r0-058-lwnj8.18d4e4b87dd4efb5,"reason=FailedScheduling count=None msg=0/6 nodes are available: 1 c_wall violated: 2 conflicting context pair(s) with node memory, 5 node(s) had untolerated taint(s). no new claims to deallocate, preemption: 0/6 nodes are available: 1 No preemption victims found for incoming pod, 5 Preemption is not helpful for scheduling."
0.1765,Event,ADDED,eval-sanitize-10-r0-058-lwnj8.18d4e4baa8246872,reason=Scheduled count=None msg=Successfully assigned compute/eval-sanitize-10-r0-058-lwnj8 to kind-worker2
0.1767,Event,ADDED,eval-sanitize-10-r0-058-lwnj8.18d4e4bad2927d79,"reason=Pulled count=1 msg=Container image ""busybox:musl"" already present on machine"
0.1768,Event,ADDED,eval-sanitize-10-r0-058-lwnj8.18d4e4bad53d22cb,reason=Created count=1 msg=Created container: task
0.177,Event,ADDED,eval-sanitize-10-r0-058-lwnj8.18d4e4bae7d7fefd,reason=Started count=1 msg=Started container task
0.1772,Event,ADDED,eval-sanitize-10-r0-058.18d4e4b39a49948f,reason=SuccessfulCreate count=1 msg=Created pod: eval-sanitize-10-r0-058-lwnj8
0.1773,Event,ADDED,eval-sanitize-10-r0-058.18d4e4c02e3a12c0,reason=Completed count=1 msg=Job completed
0.1775,Event,ADDED,eval-sanitize-10-r0-059-89wwh.18d4e4b3d63033d9,"reason=FailedScheduling count=None msg=0/6 nodes are available: 1 c_wall violated: 1 conflicting context pair(s) with node memory, 5 node(s) had untolerated taint(s). no new claims to deallocate, preemption: 0/6 nodes are available: 1 No preemption victims found for incoming pod, 5 Preemption is not helpful for scheduling."
0.1777,Event,ADDED,eval-sanitize-10-r0-059-89wwh.18d4e4b3d6b6880c,"reason=FailedScheduling count=None msg=0/6 nodes are available: 1 c_wall violated: 1 conflicting context pair(s) with node memory, 5 node(s) had untolerated taint(s). no new claims to deallocate, preemption: 0/6 nodes are available: 1 No preemption victims found for incoming pod, 5 Preemption is not helpful for scheduling."
0.1782,Event,ADDED,eval-sanitize-10-r0-059-89wwh.18d4e4b606b9cb2b,"reason=FailedScheduling count=None msg=0/6 nodes are available: 2 c_wall violated: 1 conflicting context pair(s) with node memory, 4 node(s) had untolerated taint(s). no new claims to deallocate, preemption: 0/6 nodes are available: 2 No preemption victims found for incoming pod, 4 Preemption is not helpful for scheduling."
0.1784,Event,ADDED,eval-sanitize-10-r0-059-89wwh.18d4e4b6269e835a,reason=Scheduled count=None msg=Successfully assigned compute/eval-sanitize-10-r0-059-89wwh to kind-worker4
0.1787,Event,ADDED,eval-sanitize-10-r0-059-89wwh.18d4e4b640b34cc3,"reason=Pulled count=1 msg=Container image ""busybox:musl"" already present on machine"
0.1789,Event,ADDED,eval-sanitize-10-r0-059-89wwh.18d4e4b64254d848,reason=Created count=1 msg=Created container: task
0.1791,Event,ADDED,eval-sanitize-10-r0-059-89wwh.18d4e4b646434e9e,reason=Started count=1 msg=Started container task
0.1792,Event,ADDED,eval-sanitize-10-r0-059.18d4e4b3d5e7b5a4,reason=SuccessfulCreate count=1 msg=Created pod: eval-sanitize-10-r0-059-89wwh
0.1795,Event,ADDED,eval-sanitize-10-r0-059.18d4e4bbf9e37849,reason=Completed count=1 msg=Job completed
0.1796,Event,ADDED,eval-sanitize-10-r0-060-m9mf5.18d4e4b412d7c26f,"reason=FailedScheduling count=None msg=0/6 nodes are available: 1 c_wall violated: 2 conflicting context pair(s) with node memory, 5 node(s) had untolerated taint(s). no new claims to deallocate, preemption: 0/6 nodes are available: 1 No preemption victims found for incoming pod, 5 Preemption is not helpful for scheduling."
0.1798,Event,ADDED,eval-sanitize-10-r0-060-m9mf5.18d4e4b413610bf7,"reason=FailedScheduling count=None msg=0/6 nodes are available: 1 c_wall violated: 2 conflicting context pair(s) with node memory, 5 node(s) had untolerated taint(s). no new claims to deallocate, preemption: 0/6 nodes are available: 1 No preemption victims found for incoming pod, 5 Preemption is not helpful for scheduling."
0.1803,Event,ADDED,eval-sanitize-10-r0-060-m9mf5.18d4e4b5fb81d9c3,"reason=FailedScheduling count=None msg=0/6 nodes are available: 1 c_wall violated: 2 conflicting context pair(s) with node memory, 5 node(s) had untolerated taint(s). no new claims to deallocate, preemption: 0/6 nodes are available: 1 No preemption victims found for incoming pod, 5 Preemption is not helpful for scheduling."
0.1804,Event,ADDED,eval-sanitize-10-r0-060-m9mf5.18d4e4b616d0e9a9,"reason=FailedScheduling count=None msg=0/6 nodes are available: 2 c_wall violated: 2 conflicting context pair(s) with node memory, 4 node(s) had untolerated taint(s). no new claims to deallocate, preemption: 0/6 nodes are available: 2 No preemption victims found for incoming pod, 4 Preemption is not helpful for scheduling."
0.1806,Event,ADDED,eval-sanitize-10-r0-060-m9mf5.18d4e4b64b622a87,"reason=FailedScheduling count=None msg=0/6 nodes are available: 2 c_wall violated: 1 conflicting context pair(s) with node memory, 2 c_wall violated: 2 conflicting context pair(s) with node memory, 2 node(s) had untolerated taint(s). no new claims to deallocate, preemption: 0/6 nodes are available: 2 Preemption is not helpful for scheduling, 4 No preemption victims found for incoming pod."
0.1809,Event,ADDED,eval-sanitize-10-r0-060-m9mf5.18d4e4b66a54b08f,"reason=FailedScheduling count=None msg=0/6 nodes are available: 2 c_wall violated: 1 conflicting context pair(s) with node memory, 2 c_wall violated: 2 conflicting context pair(s) with node memory, 2 node(s) had untolerated taint(s). no new claims to deallocate, preemption: 0/6 nodes are available: 2 Preemption is not helpful for scheduling, 4 No preemption victims found for incoming pod."
0.1811,Event,ADDED,eval-sanitize-10-r0-060-m9mf5.18d4e4b6d01cc1f4,"reason=FailedScheduling count=None msg=0/6 nodes are available: 1 c_wall violated: 1 conflicting context pair(s) with node memory, 2 node(s) had untolerated taint(s), 3 c_wall violated: 2 conflicting context pair(s) with node memory. no new claims to deallocate, preemption: 0/6 nodes are available: 2 Preemption is not helpful for scheduling, 4 No preemption victims found for incoming pod."
0.1813,Event,ADDED,eval-sanitize-10-r0-060-m9mf5.18d4e4b825cb25df,"reason=FailedScheduling count=None msg=0/6 nodes are available: 1 c_wall violated: 3 conflicting context pair(s) with node memory, 2 node(s) had untolerated taint(s), 3 c_wall violated: 2 conflicting context pair(s) with node memory. no new claims to deallocate, preemption: 0/6 nodes are available: 2 Preemption is not helpful for scheduling, 4 No preemption victims found for incoming pod."
0.1815,Event,ADDED,eval-sanitize-10-r0-060-m9mf5.18d4e4b85350c500,"reason=FailedScheduling count=None msg=0/6 nodes are available: 1 c_wall violated: 3 conflicting context pair(s) with node memory, 2 c_wall violated: 2 conflicting context pair(s) with node memory, 3 node(s) had untolerated taint(s). no new claims to deallocate, preemption: 0/6 nodes are available: 3 No preemption victims found for incoming pod, 3 Preemption is not helpful for scheduling."
0.1816,Event,ADDED,eval-sanitize-10-r0-060-m9mf5.18d4e4b866397ac1,"reason=FailedScheduling count=None msg=0/6 nodes are available: 1 c_wall violated: 2 conflicting context pair(s) with node memory, 1 c_wall violated: 3 conflicting context pair(s) with node memory, 4 node(s) had untolerated taint(s). no new claims to deallocate, preemption: 0/6 nodes are available: 2 No preemption victims found for incoming pod, 4 Preemption is not helpful for scheduling."
0.1818,Event,ADDED,eval-sanitize-10-r0-060-m9mf5.18d4e4b876a3959d,"reason=FailedScheduling count=None msg=0/6 nodes are available: 1 c_wall violated: 3 conflicting context pair(s) with node memory, 5 node(s) had untolerated taint(s). no new claims to deallocate, preemption: 0/6 nodes are available: 1 No preemption victims found for incoming pod, 5 Preemption is not helpful for scheduling."
0.182,Event,ADDED,eval-sanitize-10-r0-060-m9mf5.18d4e4b87d9e363b,"reason=FailedScheduling count=None msg=0/6 nodes are available: 1 c_wall violated: 3 conflicting context pair(s) with node memory, 5 node(s) had untolerated taint(s). no new claims to deallocate, preemption: 0/6 nodes are available: 1 No preemption victims found for incoming pod, 5 Preemption is not helpful for scheduling."
0.1821,Event,ADDED,eval-sanitize-10-r0-060-m9mf5.18d4e4baa654b2a7,"reason=FailedScheduling count=None msg=0/6 nodes are available: 1 c_wall violated: 1 conflicting context pair(s) with node memory, 5 node(s) had untolerated taint(s). no new claims to deallocate, preemption: 0/6 nodes are available: 1 No preemption victims found for incoming pod, 5 Preemption is not helpful for scheduling."
0.1823,Event,ADDED,eval-sanitize-10-r0-060-m9mf5.18d4e4babb3683b8,"reason=FailedScheduling count=None msg=0/6 nodes are available: 1 c_wall violated: 1 conflicting context pair(s) with node memory, 5 node(s) had untolerated taint(s). no new claims to deallocate, preemption: 0/6 nodes are available: 1 No preemption victims found for incoming pod, 5 Preemption is not helpful for scheduling."
0.1825,Event,ADDED,eval-sanitize-10-r0-060-m9mf5.18d4e4bd2f530d06,"reason=FailedScheduling count=None msg=0/6 nodes are available: 1 c_wall violated: 3 conflicting context pair(s) with node memory, 5 node(s) had untolerated taint(s). no new claims to deallocate, preemption: 0/6 nodes are available: 1 No preemption victims found for incoming pod, 5 Preemption is not helpful for scheduling."
0.1826,Event,ADDED,eval-sanitize-10-r0-060-m9mf5.18d4e4bd37260e58,reason=Scheduled count=None msg=Successfully assigned compute/eval-sanitize-10-r0-060-m9mf5 to kind-worker5
0.1828,Event,ADDED,eval-sanitize-10-r0-060-m9mf5.18d4e4bd522d14c4,"reason=Pulled count=1 msg=Container image ""busybox:musl"" already present on machine"
0.1829,Event,ADDED,eval-sanitize-10-r0-060-m9mf5.18d4e4bd5431b713,reason=Created count=1 msg=Created container: task
0.1831,Event,ADDED,eval-sanitize-10-r0-060-m9mf5.18d4e4bd56c6a1a4,reason=Started count=1 msg=Started container task
0.1833,Event,ADDED,eval-sanitize-10-r0-060.18d4e4b4129227f5,reason=SuccessfulCreate count=1 msg=Created pod: eval-sanitize-10-r0-060-m9mf5
0.1834,Event,ADDED,eval-sanitize-10-r0-060.18d4e4c394f8adcd,reason=Completed count=1 msg=Job completed
0.1836,Event,ADDED,eval-sanitize-10-r0-061-pz5b8.18d4e4b44e35f9e9,"reason=FailedScheduling count=None msg=0/6 nodes are available: 1 c_wall violated: 1 conflicting context pair(s) with node memory, 5 node(s) had untolerated taint(s). no new claims to deallocate, preemption: 0/6 nodes are available: 1 No preemption victims found for incoming pod, 5 Preemption is not helpful for scheduling."
0.1838,Event,ADDED,eval-sanitize-10-r0-061-pz5b8.18d4e4b44eb899b7,"reason=FailedScheduling count=None msg=0/6 nodes are available: 1 c_wall violated: 1 conflicting context pair(s) with node memory, 5 node(s) had untolerated taint(s). no new claims to deallocate, preemption: 0/6 nodes are available: 1 No preemption victims found for incoming pod, 5 Preemption is not helpful for scheduling."
0.1839,Event,ADDED,eval-sanitize-10-r0-061-pz5b8.18d4e4b5fc8ffbf8,reason=Scheduled count=None msg=Successfully assigned compute/eval-sanitize-10-r0-061-pz5b8 to kind-worker
0.1841,Event,ADDED,eval-sanitize-10-r0-061-pz5b8.18d4e4b616ade303,"reason=Pulled count=1 msg=Container image ""busybox:musl"" already present on machine"
0.1843,Event,ADDED,eval-sanitize-10-r0-061-pz5b8.18d4e4b61859f2ef,reason=Created count=1 msg=Created container: task
0.1844,Event,ADDED,eval-sanitize-10-r0-061-pz5b8.18d4e4b61abc2c01,reason=Started count=1 msg=Started container task
0.1846,Event,ADDED,eval-sanitize-10-r0-061.18d4e4b44df69bfd,reason=SuccessfulCreate count=1 msg=Created pod: eval-sanitize-10-r0-061-pz5b8
0.1848,Event,ADDED,eval-sanitize-10-r0-061.18d4e4bb697a00af,reason=Completed count=1 msg=Job completed
0.1849,Event,ADDED,eval-sanitize-10-r0-062-vb6rs.18d4e4b4891dfe02,"reason=FailedScheduling count=None msg=0/6 nodes are available: 1 c_wall violated: 1 conflicting context pair(s) with node memory, 5 node(s) had untolerated taint(s). no new claims to deallocate, preemption: 0/6 nodes are available: 1 No preemption victims found for incoming pod, 5 Preemption is not helpful for scheduling."
0.1851,Event,ADDED,eval-sanitize-10-r0-062-vb6rs.18d4e4b4899af74e,"reason=FailedScheduling count=None msg=0/6 nodes are available: 1 c_wall violated: 1 conflicting context pair(s) with node memory, 5 node(s) had untolerated taint(s). no new claims to deallocate, preemption: 0/6 nodes are available: 1 No preemption victims found for incoming pod, 5 Preemption is not helpful for scheduling."
0.1853,Event,ADDED,eval-sanitize-10-r0-062-vb6rs.18d4e4b600314fa5,reason=Scheduled count=None msg=Successfully assigned compute/eval-sanitize-10-r0-062-vb6rs to kind-worker3
0.1854,Event,ADDED,eval-sanitize-10-r0-062-vb6rs.18d4e4b6169aa511,"reason=Pulled count=1 msg=Container image ""busybox:musl"" already present on machine"
0.1858,Event,ADDED,eval-sanitize-10-r0-062-vb6rs.18d4e4b6182861b0,reason=Created count=1 msg=Created container: task
0.1859,Event,ADDED,eval-sanitize-10-r0-062-vb6rs.18d4e4b61abe7cda,reason=Started count=1 msg=Started container task
0.1861,Event,ADDED,eval-sanitize-10-r0-062.18d4e4b488e005eb,reason=SuccessfulCreate count=1 msg=Created pod: eval-sanitize-10-r0-062-vb6rs
0.1863,Event,ADDED,eval-sanitize-10-r0-062.18d4e4bba34b3c02,reason=Completed count=1 msg=Job completed
0.1864,Event,ADDED,eval-sanitize-10-r0-063-4tpzj.18d4e4b4c6a28c1c,"reason=FailedScheduling count=None msg=0/6 nodes are available: 1 c_wall violated: 1 conflicting context pair(s) with node memory, 5 node(s) had untolerated taint(s). no new claims to deallocate, preemption: 0/6 nodes are available: 1 No preemption victims found for incoming pod, 5 Preemption is not helpful for scheduling."
0.1866,Event,ADDED,eval-sanitize-10-r0-063-4tpzj.18d4e4b4c72463e6,"reason=FailedScheduling count=None msg=0/6 nodes are available: 1 c_wall violated: 1 conflicting context pair(s) with node memory, 5 node(s) had untolerated taint(s). no new claims to deallocate, preemption: 0/6 nodes are available: 1 No preemption victims found for incoming pod, 5 Preemption is not helpful for scheduling."
0.1867,Event,ADDED,eval-sanitize-10-r0-063-4tpzj.18d4e4b600f89d21,reason=Scheduled count=None msg=Successfully assigned compute/eval-sanitize-10-r0-063-4tpzj to kind-worker3
0.1869,Event,ADDED,eval-sanitize-10-r0-063-4tpzj.18d4e4b61a323a15,"reason=Pulled count=1 msg=Container image ""busybox:musl"" already present on machine"
0.1871,Event,ADDED,eval-sanitize-10-r0-063-4tpzj.18d4e4b61bbc2b35,reason=Created count=1 msg=Created container: task
0.1873,Event,ADDED,eval-sanitize-10-r0-063-4tpzj.18d4e4b620480c8e,reason=Started count=1 msg=Started container task
0.1875,Event,ADDED,eval-sanitize-10-r0-063.18d4e4b4c668fba9,reason=SuccessfulCreate count=1 msg=Created pod: eval-sanitize-10-r0-063-4tpzj
0.1876,Event,ADDED,eval-sanitize-10-r0-063.18d4e4bb68731421,reason=Completed count=1 msg=Job completed
0.1878,Event,ADDED,eval-sanitize-10-r0-064-l74zr.18d4e4b503ccff85,"reason=FailedScheduling count=None msg=0/6 nodes are available: 1 c_wall violated: 1 conflicting context pair(s) with node memory, 5 node(s) had untolerated taint(s). no new claims to deallocate, preemption: 0/6 nodes are available: 1 No preemption victims found for incoming pod, 5 Preemption is not helpful for scheduling."
0.188,Event,ADDED,eval-sanitize-10-r0-064-l74zr.18d4e4b50451d8df,"reason=FailedScheduling count=None msg=0/6 nodes are available: 1 c_wall violated: 1 conflicting context pair(s) with node memory, 5 node(s) had untolerated taint(s). no new claims to deallocate, preemption: 0/6 nodes are available: 1 No preemption victims found for incoming pod, 5 Preemption is not helpful for scheduling."
0.1881,Event,ADDED,eval-sanitize-10-r0-064-l74zr.18d4e4b600fbba1a,"reason=FailedScheduling count=None msg=0/6 nodes are available: 2 c_wall violated: 1 conflicting context pair(s) with node memory, 4 node(s) had untolerated taint(s). no new claims to deallocate, preemption: 0/6 nodes are available: 2 No preemption victims found for incoming pod, 4 Preemption is not helpful for scheduling."
0.1883,Event,ADDED,eval-sanitize-10-r0-064-l74zr.18d4e4b61827b5ab,reason=Scheduled count=None msg=Successfully assigned compute/eval-sanitize-10-r0-064-l74zr to kind-worker5
0.1884,Event,ADDED,eval-sanitize-10-r0-064-l74zr.18d4e4b62f96ee36,"reason=Pulled count=1 msg=Container image ""busybox:musl"" already present on machine"
0.1886,Event,ADDED,eval-sanitize-10-r0-064-l74zr.18d4e4b630de3d67,reason=Created count=1 msg=Created container: task
0.1888,Event,ADDED,eval-sanitize-10-r0-064-l74zr.18d4e4b632bb9e88,reason=Started count=1 msg=Started container task
0.1889,Event,ADDED,eval-sanitize-10-r0-064.18d4e4b5039162d3,reason=SuccessfulCreate count=1 msg=Created pod: eval-sanitize-10-r0-064-l74zr
0.1891,Event,ADDED,eval-sanitize-10-r0-064.18d4e4bb68766199,reason=Completed count=1 msg=Job completed
0.1892,Event,ADDED,eval-sanitize-10-r0-065-899wh.18d4e4b53f72c5ac,"reason=FailedScheduling count=None msg=0/6 nodes are available: 1 c_wall violated: 1 conflicting context pair(s) with node memory, 5 node(s) had untolerated taint(s). no new claims to deallocate, preemption: 0/6 nodes are available: 1 No preemption victims found for incoming pod, 5 Preemption is not helpful for scheduling."
0.1896,Event,ADDED,eval-sanitize-10-r0-065-899wh.18d4e4b540781133,"reason=FailedScheduling count=None msg=0/6 nodes are available: 1 c_wall violated: 1 conflicting context pair(s) with node memory, 5 node(s) had untolerated taint(s). no new claims to deallocate, preemption: 0/6 nodes are available: 1 No preemption victims found for incoming pod, 5 Preemption is not helpful for scheduling."
0.1897,Event,ADDED,eval-sanitize-10-r0-065-899wh.18d4e4b604b0ae5f,"reason=FailedScheduling count=None msg=0/6 nodes are available: 2 c_wall violated: 1 conflicting context pair(s) with node memory, 4 node(s) had untolerated taint(s). no new claims to deallocate, preemption: 0/6 nodes are available: 2 No preemption victims found for incoming pod, 4 Preemption is not helpful for scheduling."
0.1898,Event,ADDED,eval-sanitize-10-r0-065-899wh.18d4e4b61d03b53a,reason=Scheduled count=None msg=Successfully assigned compute/eval-sanitize-10-r0-065-899wh to kind-worker5
0.1901,Event,ADDED,eval-sanitize-10-r0-065-899wh.18d4e4b6386ef165,"reason=Pulled count=1 msg=Container image ""busybox:musl"" already present on machine"
0.1902,Event,ADDED,eval-sanitize-10-r0-065-899wh.18d4e4b639a71b04,reason=Created count=1 msg=Created container: task
0.1904,Event,ADDED,eval-sanitize-10-r0-065-899wh.18d4e4b640b03dcd,reason=Started count=1 msg=Started container task
0.1905,Event,ADDED,eval-sanitize-10-r0-065.18d4e4b53baac3b2,reason=SuccessfulCreate count=1 msg=Created pod: eval-sanitize-10-r0-065-899wh
0.1912,Event,ADDED,eval-sanitize-10-r0-065.18d4e4bbe1cf09ec,reason=Completed count=1 msg=Job completed
0.1916,Event,ADDED,eval-sanitize-10-r0-066-5bmgm.18d4e4b577e4c9d2,reason=Scheduled count=None msg=Successfully assigned compute/eval-sanitize-10-r0-066-5bmgm to kind-worker2
0.1918,Event,ADDED,eval-sanitize-10-r0-066-5bmgm.18d4e4b5916f5f6f,"reason=Pulled count=1 msg=Container image ""busybox:musl"" already present on machine"
0.1921,Event,ADDED,eval-sanitize-10-r0-066-5bmgm.18d4e4b592a3430b,reason=Created count=1 msg=Created container: task
0.1923,Event,ADDED,eval-sanitize-10-r0-066-5bmgm.18d4e4b594bd4496,reason=Started count=1 msg=Started container task
0.1924,Event,ADDED,eval-sanitize-10-r0-066.18d4e4b5775e4293,reason=SuccessfulCreate count=1 msg=Created pod: eval-sanitize-10-r0-066-5bmgm
0.1926,Event,ADDED,eval-sanitize-10-r0-066.18d4e4bb097a9864,reason=Completed count=1 msg=Job completed
0.1929,Event,ADDED,eval-sanitize-10-r0-067-qkntr.18d4e4b5b381bf94,"reason=FailedScheduling count=None msg=0/6 nodes are available: 1 c_wall violated: 1 conflicting context pair(s) with node memory, 5 node(s) had untolerated taint(s). no new claims to deallocate, preemption: 0/6 nodes are available: 1 No preemption victims found for incoming pod, 5 Preemption is not helpful for scheduling."
0.1931,Event,ADDED,eval-sanitize-10-r0-067-qkntr.18d4e4b5b73dd01f,"reason=FailedScheduling count=None msg=0/6 nodes are available: 1 c_wall violated: 1 conflicting context pair(s) with node memory, 5 node(s) had untolerated taint(s). no new claims to deallocate, preemption: 0/6 nodes are available: 1 No preemption victims found for incoming pod, 5 Preemption is not helpful for scheduling."
0.1934,Event,ADDED,eval-sanitize-10-r0-067-qkntr.18d4e4b60bcb50c7,"reason=FailedScheduling count=None msg=0/6 nodes are available: 1 c_wall violated: 1 conflicting context pair(s) with node memory, 1 c_wall violated: 2 conflicting context pair(s) with node memory, 4 node(s) had untolerated taint(s). no new claims to deallocate, preemption: 0/6 nodes are available: 2 No preemption victims found for incoming pod, 4 Preemption is not helpful for scheduling."
0.1936,Event,ADDED,eval-sanitize-10-r0-067-qkntr.18d4e4b634abed88,"reason=FailedScheduling count=None msg=0/6 nodes are available: 1 c_wall violated: 2 conflicting context pair(s) with node memory, 2 node(s) had untolerated taint(s), 3 c_wall violated: 1 conflicting context pair(s) with node memory. no new claims to deallocate, preemption: 0/6 nodes are available: 2 Preemption is not helpful for scheduling, 4 No preemption victims found for incoming pod."
0.1939,Event,ADDED,eval-sanitize-10-r0-067-qkntr.18d4e4b658d721b1,"reason=FailedScheduling count=None msg=0/6 nodes are available: 1 c_wall violated: 2 conflicting context pair(s) with node memory, 2 node(s) had untolerated taint(s), 3 c_wall violated: 1 conflicting context pair(s) with node memory. no new claims to deallocate, preemption: 0/6 nodes are available: 2 Preemption is not helpful for scheduling, 4 No preemption victims found for incoming pod."
0.194,Event,ADDED,eval-sanitize-10-r0-067-qkntr.18d4e4b85f14aa92,"reason=FailedScheduling count=None msg=0/6 nodes are available: 1 c_wall violated: 1 conflicting context pair(s) with node memory, 1 c_wall violated: 2 conflicting context pair(s) with node memory, 4 node(s) had untolerated taint(s). no new claims to deallocate, preemption: 0/6 nodes are available: 2 No preemption victims found for incoming pod, 4 Preemption is not helpful for scheduling."
0.1943,Event,ADDED,eval-sanitize-10-r0-067-qkntr.18d4e4b86c1b2dcf,"reason=FailedScheduling count=None msg=0/6 nodes are available: 1 c_wall violated: 1 conflicting context pair(s) with node memory, 1 c_wall violated: 2 conflicting context pair(s) with node memory, 4 node(s) had untolerated taint(s). no new claims to deallocate, preemption: 0/6 nodes are available: 2 No preemption victims found for incoming pod, 4 Preemption is not helpful for scheduling."
0.1945,Event,ADDED,eval-sanitize-10-r0-067-qkntr.18d4e4b87e277b98,"reason=FailedScheduling count=None msg=0/6 nodes are available: 1 c_wall violated: 2 conflicting context pair(s) with node memory, 5 node(s) had untolerated taint(s). no new claims to deallocate, preemption: 0/6 nodes are available: 1 No preemption victims found for incoming pod, 5 Preemption is not helpful for scheduling."
0.1946,Event,ADDED,eval-sanitize-10-r0-067-qkntr.18d4e4baa89df1a3,reason=Scheduled count=None msg=Successfully assigned compute/eval-sanitize-10-r0-067-qkntr to kind-worker2
0.1948,Event,ADDED,eval-sanitize-10-r0-067-qkntr.18d4e4bac1612037,"reason=Pulled count=1 msg=Container image ""busybox:musl"" already present on machine"
0.195,Event,ADDED,eval-sanitize-10-r0-067-qkntr.18d4e4bac2cb1570,reason=Created count=1 msg=Created container: task
0.1951,Event,ADDED,eval-sanitize-10-r0-067-qkntr.18d4e4bacb753ea1,reason=Started count=1 msg=Started container task
0.1953,Event,ADDED,eval-sanitize-10-r0-067.18d4e4b5b34015b5,reason=SuccessfulCreate count=1 msg=Created pod: eval-sanitize-10-r0-067-qkntr
0.1955,Event,ADDED,eval-sanitize-10-r0-067.18d4e4c02bfc143c,reason=Completed count=1 msg=Job completed
0.1956,Event,ADDED,eval-sanitize-10-r0-068-6mm72.18d4e4b5ee50d289,"reason=FailedScheduling count=None msg=0/6 nodes are available: 6 node(s) had untolerated taint(s). no new claims to deallocate, preemption: 0/6 nodes are available: 6 Preemption is not helpful for scheduling."
0.1958,Event,ADDED,eval-sanitize-10-r0-068-6mm72.18d4e4b60c6787e4,"reason=FailedScheduling count=None msg=0/6 nodes are available: 2 c_wall violated: 1 conflicting context pair(s) with node memory, 4 node(s) had untolerated taint(s). no new claims to deallocate, preemption: 0/6 nodes are available: 2 No preemption victims found for incoming pod, 4 Preemption is not helpful for scheduling."
0.1959,Event,ADDED,eval-sanitize-10-r0-068-6mm72.18d4e4b640d3a3e4,reason=Scheduled count=None msg=Successfully assigned compute/eval-sanitize-10-r0-068-6mm72 to kind-worker5
0.1961,Event,ADDED,eval-sanitize-10-r0-068-6mm72.18d4e4b658e0742f,"reason=Pulled count=1 msg=Container image ""busybox:musl"" already present on machine"
0.1963,Event,ADDED,eval-sanitize-10-r0-068-6mm72.18d4e4b65a26c607,reason=Created count=1 msg=Created container: task
0.1964,Event,ADDED,eval-sanitize-10-r0-068-6mm72.18d4e4b6607cb633,reason=Started count=1 msg=Started container task
0.1966,Event,ADDED,eval-sanitize-10-r0-068.18d4e4b5ee4a8e16,reason=SuccessfulCreate count=1 msg=Created pod: eval-sanitize-10-r0-068-6mm72
0.1968,Event,ADDED,eval-sanitize-10-r0-068.18d4e4bc26e95bcf,reason=Completed count=1 msg=Job completed
0.1969,Event,ADDED,eval-sanitize-10-r0-069-2xvrk.18d4e4b63a7b8369,"reason=FailedScheduling count=None msg=0/6 nodes are available: 1 c_wall violated: 2 conflicting context pair(s) with node memory, 2 node(s) had untolerated taint(s), 3 c_wall violated: 1 conflicting context pair(s) with node memory. no new claims to deallocate, preemption: 0/6 nodes are available: 2 Preemption is not helpful for scheduling, 4 No preemption victims found for incoming pod."
0.1971,Event,ADDED,eval-sanitize-10-r0-069-2xvrk.18d4e4b65e9cd643,"reason=FailedScheduling count=None msg=0/6 nodes are available: 1 c_wall violated: 2 conflicting context pair(s) with node memory, 2 node(s) had untolerated taint(s), 3 c_wall violated: 1 conflicting context pair(s) with node memory. no new claims to deallocate, preemption: 0/6 nodes are available: 2 Preemption is not helpful for scheduling, 4 No preemption victims found for incoming pod."
0.1973,Event,ADDED,eval-sanitize-10-r0-069-2xvrk.18d4e4b80b6a196a,"reason=FailedScheduling count=None msg=0/6 nodes are available: 2 c_wall violated: 1 conflicting context pair(s) with node memory, 2 c_wall violated: 2 conflicting context pair(s) with node memory, 2 node(s) had untolerated taint(s). no new claims to deallocate, preemption: 0/6 nodes are available: 2 Preemption is not helpful for scheduling, 4 No preemption victims found for incoming pod."
0.1975,Event,ADDED,eval-sanitize-10-r0-069-2xvrk.18d4e4b85fab0b12,"reason=FailedScheduling count=None msg=0/6 nodes are available: 1 c_wall violated: 1 conflicting context pair(s) with node memory, 1 c_wall violated: 3 conflicting context pair(s) with node memory, 4 node(s) had untolerated taint(s). no new claims to deallocate, preemption: 0/6 nodes are available: 2 No preemption victims found for incoming pod, 4 Preemption is not helpful for scheduling."
0.1976,Event,ADDED,eval-sanitize-10-r0-069-2xvrk.18d4e4b8707ad3c5,"reason=FailedScheduling count=None msg=0/6 nodes are available: 1 c_wall violated: 1 conflicting context pair(s) with node memory, 1 c_wall violated: 3 conflicting context pair(s) with node memory, 4 node(s) had untolerated taint(s). no new claims to deallocate, preemption: 0/6 nodes are available: 2 No preemption victims found for incoming pod, 4 Preemption is not helpful for scheduling."
0.1978,Event,ADDED,eval-sanitize-10-r0-069-2xvrk.18d4e4b87e4c5446,"reason=FailedScheduling count=None msg=0/6 nodes are available: 1 c_wall violated: 3 conflicting context pair(s) with node memory, 5 node(s) had untolerated taint(s). no new claims to deallocate, preemption: 0/6 nodes are available: 1 No preemption victims found for incoming pod, 5 Preemption is not helpful for scheduling."
0.198,Event,ADDED,eval-sanitize-10-r0-069-2xvrk.18d4e4baa88b71e3,"reason=FailedScheduling count=None msg=0/6 nodes are available: 1 c_wall violated: 1 conflicting context pair(s) with node memory, 5 node(s) had untolerated taint(s). no new claims to deallocate, preemption: 0/6 nodes are available: 1 No preemption victims found for incoming pod, 5 Preemption is not helpful for scheduling."
0.1982,Event,ADDED,eval-sanitize-10-r0-069-2xvrk.18d4e4babdbc6587,"reason=FailedScheduling count=None msg=0/6 nodes are available: 1 c_wall violated: 1 conflicting context pair(s) with node memory, 5 node(s) had untolerated taint(s). no new claims to deallocate, preemption: 0/6 nodes are available: 1 No preemption victims found for incoming pod, 5 Preemption is not helpful for scheduling."
0.1983,Event,ADDED,eval-sanitize-10-r0-069-2xvrk.18d4e4bd3060e675,reason=Scheduled count=None msg=Successfully assigned compute/eval-sanitize-10-r0-069-2xvrk to kind-worker
0.1985,Event,ADDED,eval-sanitize-10-r0-069-2xvrk.18d4e4bd4f4647fd,"reason=Pulled count=1 msg=Container image ""busybox:musl"" already present on machine"
0.1986,Event,ADDED,eval-sanitize-10-r0-069-2xvrk.18d4e4bd514bfb9c,reason=Created count=1 msg=Created container: task
0.1988,Event,ADDED,eval-sanitize-10-r0-069-2xvrk.18d4e4bd5370622c,reason=Started count=1 msg=Started container task
0.199,Event,ADDED,eval-sanitize-10-r0-069.18d4e4b62a315469,reason=SuccessfulCreate count=1 msg=Created pod: eval-sanitize-10-r0-069-2xvrk
0.1991,Event,ADDED,eval-sanitize-10-r0-069.18d4e4c3e2ae63cf,reason=Completed count=1 msg=Job completed
0.1993,Event,ADDED,eval-sanitize-10-r0-070-z82m5.18d4e4b670b90f9f,reason=Scheduled count=None msg=Successfully assigned compute/eval-sanitize-10-r0-070-z82m5 to kind-worker5
0.1996,Event,ADDED,eval-sanitize-10-r0-070-z82m5.18d4e4b68cbb47af,"reason=Pulled count=1 msg=Container image ""busybox:musl"" already present on machine"
0.1997,Event,ADDED,eval-sanitize-10-r0-070-z82m5.18d4e4b68de2f29b,reason=Created count=1 msg=Created container: task
0.2005,Event,ADDED,eval-sanitize-10-r0-070-z82m5.18d4e4b696591be5,reason=Started count=1 msg=Started container task
0.2008,Event,ADDED,eval-sanitize-10-r0-070.18d4e4b665942268,reason=SuccessfulCreate count=1 msg=Created pod: eval-sanitize-10-r0-070-z82m5
0.2011,Event,ADDED,eval-sanitize-10-r0-070.18d4e4bc167a29a6,reason=Completed count=1 msg=Job completed
0.2013,Event,ADDED,eval-sanitize-10-r0-071-qf6zq.18d4e4b6a72736ca,reason=Scheduled count=None msg=Successfully assigned compute/eval-sanitize-10-r0-071-qf6zq to kind-worker5
0.2016,Event,ADDED,eval-sanitize-10-r0-071-qf6zq.18d4e4b6c50a995a,"reason=Pulled count=1 msg=Container image ""busybox:musl"" already present on machine"
0.2018,Event,ADDED,eval-sanitize-10-r0-071-qf6zq.18d4e4b6c620e426,reason=Created count=1 msg=Created container: task
0.202,Event,ADDED,eval-sanitize-10-r0-071-qf6zq.18d4e4b6c8102cc9,reason=Started count=1 msg=Started container task
0.2023,Event,ADDED,eval-sanitize-10-r0-071.18d4e4b6a5c816fc,reason=SuccessfulCreate count=1 msg=Created pod: eval-sanitize-10-r0-071-qf6zq
0.2025,Event,ADDED,eval-sanitize-10-r0-071.18d4e4bc52e69278,reason=Completed count=1 msg=Job completed
0.2026,Event,ADDED,eval-sanitize-10-r0-072-fwmbb.18d4e4b6dec5ae0a,reason=Scheduled count=None msg=Successfully assigned compute/eval-sanitize-10-r0-072-fwmbb to kind-worker
0.2028,Event,ADDED,eval-sanitize-10-r0-072-fwmbb.18d4e4b6fd85be69,"reason=Pulled count=1 msg=Container image ""busybox:musl"" already present on machine"
0.203,Event,ADDED,eval-sanitize-10-r0-072-fwmbb.18d4e4b6fea9d756,reason=Created count=1 msg=Created container: task
0.2032,Event,ADDED,eval-sanitize-10-r0-072-fwmbb.18d4e4b70763b863,reason=Started count=1 msg=Started container task
0.2034,Event,ADDED,eval-sanitize-10-r0-072.18d4e4b6dd9460cd,reason=SuccessfulCreate count=1 msg=Created pod: eval-sanitize-10-r0-072-fwmbb
0.2035,Event,ADDED,eval-sanitize-10-r0-072.18d4e4bc9132f6fb,reason=Completed count=1 msg=Job completed
0.2037,Event,ADDED,eval-sanitize-10-r0-073-psfv2.18d4e4b71eace9df,"reason=FailedScheduling count=None msg=0/6 nodes are available: 1 c_wall violated: 1 conflicting context pair(s) with node memory, 2 node(s) had untolerated taint(s), 3 c_wall violated: 2 conflicting context pair(s) with node memory. no new claims to deallocate, preemption: 0/6 nodes are available: 2 Preemption is not helpful for scheduling, 4 No preemption victims found for incoming pod."
0.2039,Event,ADDED,eval-sanitize-10-r0-073-psfv2.18d4e4b7239daa1f,"reason=FailedScheduling count=None msg=0/6 nodes are available: 1 c_wall violated: 1 conflicting context pair(s) with node memory, 2 node(s) had untolerated taint(s), 3 c_wall violated: 2 conflicting context pair(s) with node memory. no new claims to deallocate, preemption: 0/6 nodes are available: 2 Preemption is not helpful for scheduling, 4 No preemption victims found for incoming pod."
0.204,Event,ADDED,eval-sanitize-10-r0-073-psfv2.18d4e4b81c250910,"reason=FailedScheduling count=None msg=0/6 nodes are available: 1 c_wall violated: 3 conflicting context pair(s) with node memory, 2 node(s) had untolerated taint(s), 3 c_wall violated: 2 conflicting context pair(s) with node memory. no new claims to deallocate, preemption: 0/6 nodes are available: 2 Preemption is not helpful for scheduling, 4 No preemption victims found for incoming pod."
0.2042,Event,ADDED,eval-sanitize-10-r0-073-psfv2.18d4e4b847030f5f,"reason=FailedScheduling count=None msg=0/6 nodes are available: 1 c_wall violated: 3 conflicting context pair(s) with node memory, 2 node(s) had untolerated taint(s), 3 c_wall violated: 2 conflicting context pair(s) with node memory. no new claims to deallocate, preemption: 0/6 nodes are available: 2 Preemption is not helpful for scheduling, 4 No preemption victims found for incoming pod."
0.2044,Event,ADDED,eval-sanitize-10-r0-073-psfv2.18d4e4b8712d4426,"reason=FailedScheduling count=None msg=0/6 nodes are available: 1 c_wall violated: 2 conflicting context pair(s) with node memory, 1 c_wall violated: 3 conflicting context pair(s) with node memory, 4 node(s) had untolerated taint(s). no new claims to deallocate, preemption: 0/6 nodes are available: 2 No preemption victims found for incoming pod, 4 Preemption is not helpful for scheduling."
0.2046,Event,ADDED,eval-sanitize-10-r0-073-psfv2.18d4e4b882c1445e,"reason=FailedScheduling count=None msg=0/6 nodes are available: 6 node(s) had untolerated taint(s). no new claims to deallocate, preemption: 0/6 nodes are available: 6 Preemption is not helpful for scheduling."
0.2047,Event,ADDED,eval-sanitize-10-r0-073-psfv2.18d4e4baa58ce58f,"reason=FailedScheduling count=None msg=0/6 nodes are available: 1 c_wall violated: 1 conflicting context pair(s) with node memory, 5 node(s) had untolerated taint(s). no new claims to deallocate, preemption: 0/6 nodes are available: 1 No preemption victims found for incoming pod, 5 Preemption is not helpful for scheduling."
0.2049,Event,ADDED,eval-sanitize-10-r0-073-psfv2.18d4e4babaf36323,"reason=FailedScheduling count=None msg=0/6 nodes are available: 1 c_wall violated: 1 conflicting context pair(s) with node memory, 5 node(s) had untolerated taint(s). no new claims to deallocate, preemption: 0/6 nodes are available: 1 No preemption victims found for incoming pod, 5 Preemption is not helpful for scheduling."
0.205,Event,ADDED,eval-sanitize-10-r0-073-psfv2.18d4e4bd2a74e2ac,"reason=FailedScheduling count=None msg=0/6 nodes are available: 1 c_wall violated: 3 conflicting context pair(s) with node memory, 5 node(s) had untolerated taint(s). no new claims to deallocate, preemption: 0/6 nodes are available: 1 No preemption victims found for incoming pod, 5 Preemption is not helpful for scheduling."
0.2052,Event,ADDED,eval-sanitize-10-r0-073-psfv2.18d4e4bd370ae743,reason=Scheduled count=None msg=Successfully assigned compute/eval-sanitize-10-r0-073-psfv2 to kind-worker5
0.2054,Event,ADDED,eval-sanitize-10-r0-073-psfv2.18d4e4bd520f25de,"reason=Pulled count=1 msg=Container image ""busybox:musl"" already present on machine"
0.2055,Event,ADDED,eval-sanitize-10-r0-073-psfv2.18d4e4bd549d9941,reason=Created count=1 msg=Created container: task
0.2057,Event,ADDED,eval-sanitize-10-r0-073-psfv2.18d4e4bd56c71c07,reason=Started count=1 msg=Started container task
0.2059,Event,ADDED,eval-sanitize-10-r0-073.18d4e4b71dbbea02,reason=SuccessfulCreate count=1 msg=Created pod: eval-sanitize-10-r0-073-psfv2
0.206,Event,ADDED,eval-sanitize-10-r0-073.18d4e4c3a6bd3744,reason=Completed count=1 msg=Job completed
0.2062,Event,ADDED,eval-sanitize-10-r0-074-r8rkz.18d4e4b75d99cfcb,"reason=FailedScheduling count=None msg=0/6 nodes are available: 1 c_wall violated: 2 conflicting context pair(s) with node memory, 2 node(s) had untolerated taint(s), 3 c_wall violated: 1 conflicting context pair(s) with node memory. no new claims to deallocate, preemption: 0/6 nodes are available: 2 Preemption is not helpful for scheduling, 4 No preemption victims found for incoming pod."
0.2064,Event,ADDED,eval-sanitize-10-r0-074-r8rkz.18d4e4b75ecec972,"reason=FailedScheduling count=None msg=0/6 nodes are available: 1 c_wall violated: 2 conflicting context pair(s) with node memory, 2 node(s) had untolerated taint(s), 3 c_wall violated: 1 conflicting context pair(s) with node memory. no new claims to deallocate, preemption: 0/6 nodes are available: 2 Preemption is not helpful for scheduling, 4 No preemption victims found for incoming pod."
0.2066,Event,ADDED,eval-sanitize-10-r0-074-r8rkz.18d4e4b852af7c22,"reason=FailedScheduling count=None msg=0/6 nodes are available: 2 c_wall violated: 1 conflicting context pair(s) with node memory, 2 c_wall violated: 2 conflicting context pair(s) with node memory, 2 node(s) had untolerated taint(s). no new claims to deallocate, preemption: 0/6 nodes are available: 2 Preemption is not helpful for scheduling, 4 No preemption victims found for incoming pod."
0.2067,Event,ADDED,eval-sanitize-10-r0-074-r8rkz.18d4e4b8767b98a9,"reason=FailedScheduling count=None msg=0/6 nodes are available: 1 c_wall violated: 1 conflicting context pair(s) with node memory, 1 c_wall violated: 2 conflicting context pair(s) with node memory, 4 node(s) had untolerated taint(s). no new claims to deallocate, preemption: 0/6 nodes are available: 2 No preemption victims found for incoming pod, 4 Preemption is not helpful for scheduling."
0.2069,Event,ADDED,eval-sanitize-10-r0-074-r8rkz.18d4e4b8831a57ca,"reason=FailedScheduling count=None msg=0/6 nodes are available: 6 node(s) had untolerated taint(s). no new claims to deallocate, preemption: 0/6 nodes are available: 6 Preemption is not helpful for scheduling."
0.207,Event,ADDED,eval-sanitize-10-r0-074-r8rkz.18d4e4baa65f814c,reason=Scheduled count=None msg=Successfully assigned compute/eval-sanitize-10-r0-074-r8rkz to kind-worker2
0.2072,Event,ADDED,eval-sanitize-10-r0-074-r8rkz.18d4e4bad1a379bd,"reason=Pulled count=1 msg=Container image ""busybox:musl"" already present on machine"
0.2074,Event,ADDED,eval-sanitize-10-r0-074-r8rkz.18d4e4bad57db872,reason=Created count=1 msg=Created container: task
0.2075,Event,ADDED,eval-sanitize-10-r0-074-r8rkz.18d4e4bae7db2a88,reason=Started count=1 msg=Started container task
0.2077,Event,ADDED,eval-sanitize-10-r0-074.18d4e4b754554782,reason=SuccessfulCreate count=1 msg=Created pod: eval-sanitize-10-r0-074-r8rkz
0.2079,Event,ADDED,eval-sanitize-10-r0-074.18d4e4c02d883c66,reason=Completed count=1 msg=Job completed
0.208,Event,ADDED,eval-sanitize-10-r0-075-524vq.18d4e4b79102a2ef,reason=Scheduled count=None msg=Successfully assigned compute/eval-sanitize-10-r0-075-524vq to kind-worker
0.2082,Event,ADDED,eval-sanitize-10-r0-075-524vq.18d4e4b7ae3429d5,"reason=Pulled count=1 msg=Container image ""busybox:musl"" already present on machine"
0.2083,Event,ADDED,eval-sanitize-10-r0-075-524vq.18d4e4b7af50f791,reason=Created count=1 msg=Created container: task
0.2086,Event,ADDED,eval-sanitize-10-r0-075-524vq.18d4e4b7b5ef886a,reason=Started count=1 msg=Started container task
0.2088,Event,ADDED,eval-sanitize-10-r0-075.18d4e4b78fb124b2,reason=SuccessfulCreate count=1 msg=Created pod: eval-sanitize-10-r0-075-524vq
0.2089,Event,ADDED,eval-sanitize-10-r0-075.18d4e4bd4a65741f,reason=Completed count=1 msg=Job completed
0.2091,Event,ADDED,eval-sanitize-10-r0-076-p9hkv.18d4e4b7d349bebd,reason=Scheduled count=None msg=Successfully assigned compute/eval-sanitize-10-r0-076-p9hkv to kind-worker4
0.2092,Event,ADDED,eval-sanitize-10-r0-076-p9hkv.18d4e4b7ed880138,"reason=Pulled count=1 msg=Container image ""busybox:musl"" already present on machine"
0.2094,Event,ADDED,eval-sanitize-10-r0-076-p9hkv.18d4e4b7ee9b7e55,reason=Created count=1 msg=Created container: task
0.2096,Event,ADDED,eval-sanitize-10-r0-076-p9hkv.18d4e4b7f5cfda69,reason=Started count=1 msg=Started container task
0.2097,Event,ADDED,eval-sanitize-10-r0-076.18d4e4b7cc166abe,reason=SuccessfulCreate count=1 msg=Created pod: eval-sanitize-10-r0-076-p9hkv
0.2099,Event,ADDED,eval-sanitize-10-r0-076.18d4e4bd64645cad,reason=Completed count=1 msg=Job completed
0.21,Event,ADDED,eval-sanitize-10-r0-077-f6ftp.18d4e4b811bc08ec,reason=Scheduled count=None msg=Successfully assigned compute/eval-sanitize-10-r0-077-f6ftp to kind-worker4
0.2102,Event,ADDED,eval-sanitize-10-r0-077-f6ftp.18d4e4b82b5656e5,"reason=Pulled count=1 msg=Container image ""busybox:musl"" already present on machine"
0.2104,Event,ADDED,eval-sanitize-10-r0-077-f6ftp.18d4e4b82c602714,reason=Created count=1 msg=Created container: task
0.2106,Event,ADDED,eval-sanitize-10-r0-077-f6ftp.18d4e4b8343fefef,reason=Started count=1 msg=Started container task
0.2108,Event,ADDED,eval-sanitize-10-r0-077.18d4e4b807331f35,reason=SuccessfulCreate count=1 msg=Created pod: eval-sanitize-10-r0-077-f6ftp
0.2109,Event,ADDED,eval-sanitize-10-r0-077.18d4e4bd96219ee2,reason=Completed count=1 msg=Job completed
0.2111,Event,ADDED,eval-sanitize-10-r0-078-w9zgj.18d4e4b84fd30661,reason=Scheduled count=None msg=Successfully assigned compute/eval-sanitize-10-r0-078-w9zgj to kind-worker3
0.2112,Event,ADDED,eval-sanitize-10-r0-078-w9zgj.18d4e4b869ad0b2e,"reason=Pulled count=1 msg=Container image ""busybox:musl"" already present on machine"
0.2114,Event,ADDED,eval-sanitize-10-r0-078-w9zgj.18d4e4b86ac92664,reason=Created count=1 msg=Created container: task
0.2116,Event,ADDED,eval-sanitize-10-r0-078-w9zgj.18d4e4b86f14b0fc,reason=Started count=1 msg=Started container task
0.2117,Event,ADDED,eval-sanitize-10-r0-078.18d4e4b846214ae8,reason=SuccessfulCreate count=1 msg=Created pod: eval-sanitize-10-r0-078-w9zgj
0.2119,Event,ADDED,eval-sanitize-10-r0-078.18d4e4bdf5a63a0b,reason=Completed count=1 msg=Job completed
0.2121,Event,ADDED,eval-sanitize-10-r0-079-qsbfv.18d4e4b88272b865,"reason=FailedScheduling count=None msg=0/6 nodes are available: 6 node(s) had untolerated taint(s). no new claims to deallocate, preemption: 0/6 nodes are available: 6 Preemption is not helpful for scheduling."
0.2122,Event,ADDED,eval-sanitize-10-r0-079-qsbfv.18d4e4baa540b5f5,reason=Scheduled count=None msg=Successfully assigned compute/eval-sanitize-10-r0-079-qsbfv to kind-worker2
0.2124,Event,ADDED,eval-sanitize-10-r0-079-qsbfv.18d4e4bac098806f,"reason=Pulled count=1 msg=Container image ""busybox:musl"" already present on machine"
0.2125,Event,ADDED,eval-sanitize-10-r0-079-qsbfv.18d4e4bac23a56e1,reason=Created count=1 msg=Created container: task
0.2127,Event,ADDED,eval-sanitize-10-r0-079-qsbfv.18d4e4bac5e50bc2,reason=Started count=1 msg=Started container task
0.2129,Event,ADDED,eval-sanitize-10-r0-079.18d4e4b87eb89f4c,reason=SuccessfulCreate count=1 msg=Created pod: eval-sanitize-10-r0-079-qsbfv
0.213,Event,ADDED,eval-sanitize-10-r0-079.18d4e4c02b43ccb5,reason=Completed count=1 msg=Job completed
0.2132,Event,ADDED,eval-sanitize-10-r0-080-fsspn.18d4e4b8ba518ecc,"reason=FailedScheduling count=None msg=0/6 nodes are available: 6 node(s) had untolerated taint(s). no new claims to deallocate, preemption: 0/6 nodes are available: 6 Preemption is not helpful for scheduling."
0.2133,Event,ADDED,eval-sanitize-10-r0-080-fsspn.18d4e4baac99316d,"reason=FailedScheduling count=None msg=0/6 nodes are available: 1 c_wall violated: 1 conflicting context pair(s) with node memory, 5 node(s) had untolerated taint(s). no new claims to deallocate, preemption: 0/6 nodes are available: 1 No preemption victims found for incoming pod, 5 Preemption is not helpful for scheduling."
0.2135,Event,ADDED,eval-sanitize-10-r0-080-fsspn.18d4e4babdeec8d0,"reason=FailedScheduling count=None msg=0/6 nodes are available: 1 c_wall violated: 1 conflicting context pair(s) with node memory, 5 node(s) had untolerated taint(s). no new claims to deallocate, preemption: 0/6 nodes are available: 1 No preemption victims found for incoming pod, 5 Preemption is not helpful for scheduling."
0.2136,Event,ADDED,eval-sanitize-10-r0-080-fsspn.18d4e4bd23988e87,"reason=FailedScheduling count=None msg=0/6 nodes are available: 1 c_wall violated: 1 conflicting context pair(s) with node memory, 5 node(s) had untolerated taint(s). no new claims to deallocate, preemption: 0/6 nodes are available: 1 No preemption victims found for incoming pod, 5 Preemption is not helpful for scheduling."
0.2138,Event,ADDED,eval-sanitize-10-r0-080-fsspn.18d4e4bd3082fac9,"reason=FailedScheduling count=None msg=0/6 nodes are available: 1 c_wall violated: 1 conflicting context pair(s) with node memory, 5 node(s) had untolerated taint(s). no new claims to deallocate, preemption: 0/6 nodes are available: 1 No preemption victims found for incoming pod, 5 Preemption is not helpful for scheduling."
0.2139,Event,ADDED,eval-sanitize-10-r0-080-fsspn.18d4e4bd3d8dc190,reason=Scheduled count=None msg=Successfully assigned compute/eval-sanitize-10-r0-080-fsspn to kind-worker5
0.2141,Event,ADDED,eval-sanitize-10-r0-080-fsspn.18d4e4bd57875ce9,"reason=Pulled count=1 msg=Container image ""busybox:musl"" already present on machine"
0.2143,Event,ADDED,eval-sanitize-10-r0-080-fsspn.18d4e4bd5910f95f,reason=Created count=1 msg=Created container: task
0.2144,Event,ADDED,eval-sanitize-10-r0-080-fsspn.18d4e4bd5d04ad00,reason=Started count=1 msg=Started container task
0.2146,Event,ADDED,eval-sanitize-10-r0-080.18d4e4b8ba470b3a,reason=SuccessfulCreate count=1 msg=Created pod: eval-sanitize-10-r0-080-fsspn
0.2148,Event,ADDED,eval-sanitize-10-r0-080.18d4e4c38d4c8b25,reason=Completed count=1 msg=Job completed
0.2149,Event,ADDED,eval-sanitize-10-r0-081-qmx2t.18d4e4b8f5444aed,"reason=FailedScheduling count=None msg=0/6 nodes are available: 6 node(s) had untolerated taint(s). no new claims to deallocate, preemption: 0/6 nodes are available: 6 Preemption is not helpful for scheduling."
0.2151,Event,ADDED,eval-sanitize-10-r0-081-qmx2t.18d4e4bab192f9ce,"reason=FailedScheduling count=None msg=0/6 nodes are available: 1 c_wall violated: 1 conflicting context pair(s) with node memory, 5 node(s) had untolerated taint(s). no new claims to deallocate, preemption: 0/6 nodes are available: 1 No preemption victims found for incoming pod, 5 Preemption is not helpful for scheduling."
0.2152,Event,ADDED,eval-sanitize-10-r0-081-qmx2t.18d4e4babe1cf5a0,"reason=FailedScheduling count=None msg=0/6 nodes are available: 1 c_wall violated: 1 conflicting context pair(s) with node memory, 5 node(s) had untolerated taint(s). no new claims to deallocate, preemption: 0/6 nodes are available: 1 No preemption victims found for incoming pod, 5 Preemption is not helpful for scheduling."
0.2169,Event,ADDED,eval-sanitize-10-r0-081-qmx2t.18d4e4bd244b2aa2,"reason=FailedScheduling count=None msg=0/6 nodes are available: 1 c_wall violated: 3 conflicting context pair(s) with node memory, 5 node(s) had untolerated taint(s). no new claims to deallocate, preemption: 0/6 nodes are available: 1 No preemption victims found for incoming pod, 5 Preemption is not helpful for scheduling."
0.2171,Event,ADDED,eval-sanitize-10-r0-081-qmx2t.18d4e4bd30af505c,"reason=FailedScheduling count=None msg=0/6 nodes are available: 1 c_wall violated: 3 conflicting context pair(s) with node memory, 5 node(s) had untolerated taint(s). no new claims to deallocate, preemption: 0/6 nodes are available: 1 No preemption victims found for incoming pod, 5 Preemption is not helpful for scheduling."
0.2172,Event,ADDED,eval-sanitize-10-r0-081-qmx2t.18d4e4bd4f2b7b63,reason=Scheduled count=None msg=Successfully assigned compute/eval-sanitize-10-r0-081-qmx2t to kind-worker4
0.2174,Event,ADDED,eval-sanitize-10-r0-081-qmx2t.18d4e4bd69b1108a,"reason=Pulled count=1 msg=Container image ""busybox:musl"" already present on machine"
0.2176,Event,ADDED,eval-sanitize-10-r0-081-qmx2t.18d4e4bd6b5d1572,reason=Created count=1 msg=Created container: task
0.2177,Event,ADDED,eval-sanitize-10-r0-081-qmx2t.18d4e4bd6f6aad47,reason=Started count=1 msg=Started container task
0.2179,Event,ADDED,eval-sanitize-10-r0-081.18d4e4b8f5321045,reason=SuccessfulCreate count=1 msg=Created pod: eval-sanitize-10-r0-081-qmx2t
0.2181,Event,ADDED,eval-sanitize-10-r0-081.18d4e4c3e847905d,reason=Completed count=1 msg=Job completed
0.2182,Event,ADDED,eval-sanitize-10-r0-082-w5cdn.18d4e4b93474a315,"reason=FailedScheduling count=None msg=0/6 nodes are available: 6 node(s) had untolerated taint(s). no new claims to deallocate, preemption: 0/6 nodes are available: 6 Preemption is not helpful for scheduling."
0.2184,Event,ADDED,eval-sanitize-10-r0-082-w5cdn.18d4e4bab22edb2f,"reason=FailedScheduling count=None msg=0/6 nodes are available: 1 c_wall violated: 2 conflicting context pair(s) with node memory, 5 node(s) had untolerated taint(s). no new claims to deallocate, preemption: 0/6 nodes are available: 1 No preemption victims found for incoming pod, 5 Preemption is not helpful for scheduling."
0.2186,Event,ADDED,eval-sanitize-10-r0-082-w5cdn.18d4e4babe7cbe92,"reason=FailedScheduling count=None msg=0/6 nodes are available: 1 c_wall violated: 2 conflicting context pair(s) with node memory, 5 node(s) had untolerated taint(s). no new claims to deallocate, preemption: 0/6 nodes are available: 1 No preemption victims found for incoming pod, 5 Preemption is not helpful for scheduling."
0.2187,Event,ADDED,eval-sanitize-10-r0-082-w5cdn.18d4e4bd251258dd,reason=Scheduled count=None msg=Successfully assigned compute/eval-sanitize-10-r0-082-w5cdn to kind-worker
0.2189,Event,ADDED,eval-sanitize-10-r0-082-w5cdn.18d4e4bd4172dd1b,"reason=Pulled count=1 msg=Container image ""busybox:musl"" already present on machine"
0.219,Event,ADDED,eval-sanitize-10-r0-082-w5cdn.18d4e4bd43058749,reason=Created count=1 msg=Created container: task
0.2192,Event,ADDED,eval-sanitize-10-r0-082-w5cdn.18d4e4bd453bb747,reason=Started count=1 msg=Started container task
0.2194,Event,ADDED,eval-sanitize-10-r0-082.18d4e4b93470d980,reason=SuccessfulCreate count=1 msg=Created pod: eval-sanitize-10-r0-082-w5cdn
0.2195,Event,ADDED,eval-sanitize-10-r0-082.18d4e4c3d29d858a,reason=Completed count=1 msg=Job completed
0.2197,Event,ADDED,eval-sanitize-10-r0-083-rqf2s.18d4e4b96d4ae620,"reason=FailedScheduling count=None msg=0/6 nodes are available: 6 node(s) had untolerated taint(s). no new claims to deallocate, preemption: 0/6 nodes are available: 6 Preemption is not helpful for scheduling."
0.2198,Event,ADDED,eval-sanitize-10-r0-083-rqf2s.18d4e4bab2a55438,"reason=FailedScheduling count=None msg=0/6 nodes are available: 1 c_wall violated: 1 conflicting context pair(s) with node memory, 5 node(s) had untolerated taint(s). no new claims to deallocate, preemption: 0/6 nodes are available: 1 No preemption victims found for incoming pod, 5 Preemption is not helpful for scheduling."
0.22,Event,ADDED,eval-sanitize-10-r0-083-rqf2s.18d4e4babea5e158,"reason=FailedScheduling count=None msg=0/6 nodes are available: 1 c_wall violated: 1 conflicting context pair(s) with node memory, 5 node(s) had untolerated taint(s). no new claims to deallocate, preemption: 0/6 nodes are available: 1 No preemption victims found for incoming pod, 5 Preemption is not helpful for scheduling."
0.2202,Event,ADDED,eval-sanitize-10-r0-083-rqf2s.18d4e4bd24fb8c68,"reason=FailedScheduling count=None msg=0/6 nodes are available: 1 c_wall violated: 3 conflicting context pair(s) with node memory, 5 node(s) had untolerated taint(s). no new claims to deallocate, preemption: 0/6 nodes are available: 1 No preemption victims found for incoming pod, 5 Preemption is not helpful for scheduling."
0.2203,Event,ADDED,eval-sanitize-10-r0-083-rqf2s.18d4e4bd30dc319b,"reason=FailedScheduling count=None msg=0/6 nodes are available: 1 c_wall violated: 3 conflicting context pair(s) with node memory, 5 node(s) had untolerated taint(s). no new claims to deallocate, preemption: 0/6 nodes are available: 1 No preemption victims found for incoming pod, 5 Preemption is not helpful for scheduling."
0.2205,Event,ADDED,eval-sanitize-10-r0-083-rqf2s.18d4e4bd42ce7442,reason=Scheduled count=None msg=Successfully assigned compute/eval-sanitize-10-r0-083-rqf2s to kind-worker5
0.2206,Event,ADDED,eval-sanitize-10-r0-083-rqf2s.18d4e4bd5c9f8454,"reason=Pulled count=1 msg=Container image ""busybox:musl"" already present on machine"
0.2209,Event,ADDED,eval-sanitize-10-r0-083-rqf2s.18d4e4bd5ebf95ba,reason=Created count=1 msg=Created container: task
0.221,Event,ADDED,eval-sanitize-10-r0-083-rqf2s.18d4e4bd638bbe52,reason=Started count=1 msg=Started container task
0.2212,Event,ADDED,eval-sanitize-10-r0-083.18d4e4b96d48585b,reason=SuccessfulCreate count=1 msg=Created pod: eval-sanitize-10-r0-083-rqf2s
0.2213,Event,ADDED,eval-sanitize-10-r0-083.18d4e4c3aa1b8db8,reason=Completed count=1 msg=Job completed
0.2215,Event,ADDED,eval-sanitize-10-r0-084-8qs94.18d4e4b9a92a45c2,"reason=FailedScheduling count=None msg=0/6 nodes are available: 6 node(s) had untolerated taint(s). no new claims to deallocate, preemption: 0/6 nodes are available: 6 Preemption is not helpful for scheduling."
0.2216,Event,ADDED,eval-sanitize-10-r0-084-8qs94.18d4e4bab40f06e3,"reason=FailedScheduling count=None msg=0/6 nodes are available: 1 c_wall violated: 1 conflicting context pair(s) with node memory, 5 node(s) had untolerated taint(s). no new claims to deallocate, preemption: 0/6 nodes are available: 1 No preemption victims found for incoming pod, 5 Preemption is not helpful for scheduling."
0.2218,Event,ADDED,eval-sanitize-10-r0-084-8qs94.18d4e4babecd40dc,"reason=FailedScheduling count=None msg=0/6 nodes are available: 1 c_wall violated: 1 conflicting context pair(s) with node memory, 5 node(s) had untolerated taint(s). no new claims to deallocate, preemption: 0/6 nodes are available: 1 No preemption victims found for incoming pod, 5 Preemption is not helpful for scheduling."
0.222,Event,ADDED,eval-sanitize-10-r0-084-8qs94.18d4e4bd257b0a68,"reason=FailedScheduling count=None msg=0/6 nodes are available: 1 c_wall violated: 1 conflicting context pair(s) with node memory, 5 node(s) had untolerated taint(s). no new claims to deallocate, preemption: 0/6 nodes are available: 1 No preemption victims found for incoming pod, 5 Preemption is not helpful for scheduling."
0.2221,Event,ADDED,eval-sanitize-10-r0-084-8qs94.18d4e4bd31088d35,"reason=FailedScheduling count=None msg=0/6 nodes are available: 1 c_wall violated: 1 conflicting context pair(s) with node memory, 5 node(s) had untolerated taint(s). no new claims to deallocate, preemption: 0/6 nodes are available: 1 No preemption victims found for incoming pod, 5 Preemption is not helpful for scheduling."
0.2223,Event,ADDED,eval-sanitize-10-r0-084-8qs94.18d4e4bd43050f9b,reason=Scheduled count=None msg=Successfully assigned compute/eval-sanitize-10-r0-084-8qs94 to kind-worker5
0.2224,Event,ADDED,eval-sanitize-10-r0-084-8qs94.18d4e4bd5d206fb1,"reason=Pulled count=1 msg=Container image ""busybox:musl"" already present on machine"
0.2226,Event,ADDED,eval-sanitize-10-r0-084-8qs94.18d4e4bd5f7e6545,reason=Created count=1 msg=Created container: task
0.2228,Event,ADDED,eval-sanitize-10-r0-084-8qs94.18d4e4bd64412720,reason=Started count=1 msg=Started container task
0.2229,Event,ADDED,eval-sanitize-10-r0-084.18d4e4b9a9228cc2,reason=SuccessfulCreate count=1 msg=Created pod: eval-sanitize-10-r0-084-8qs94
0.2231,Event,ADDED,eval-sanitize-10-r0-084.18d4e4c39ac8e69c,reason=Completed count=1 msg=Job completed
0.2232,Event,ADDED,eval-sanitize-10-r0-085-v59w7.18d4e4b9e43bffef,"reason=FailedScheduling count=None msg=0/6 nodes are available: 6 node(s) had untolerated taint(s). no new claims to deallocate, preemption: 0/6 nodes are available: 6 Preemption is not helpful for scheduling."
0.2234,Event,ADDED,eval-sanitize-10-r0-085-v59w7.18d4e4babaa4466d,reason=Scheduled count=None msg=Successfully assigned compute/eval-sanitize-10-r0-085-v59w7 to kind-worker2
0.2236,Event,ADDED,eval-sanitize-10-r0-085-v59w7.18d4e4bae7e23669,"reason=Pulled count=1 msg=Container image ""busybox:musl"" already present on machine"
0.2238,Event,ADDED,eval-sanitize-10-r0-085-v59w7.18d4e4bae9f7b256,reason=Created count=1 msg=Created container: task
0.224,Event,ADDED,eval-sanitize-10-r0-085-v59w7.18d4e4baf481edc7,reason=Started count=1 msg=Started container task
0.2241,Event,ADDED,eval-sanitize-10-r0-085.18d4e4b9e4313159,reason=SuccessfulCreate count=1 msg=Created pod: eval-sanitize-10-r0-085-v59w7
0.2243,Event,ADDED,eval-sanitize-10-r0-085.18d4e4c0678f833e,reason=Completed count=1 msg=Job completed
0.2244,Event,ADDED,eval-sanitize-10-r0-086-28ghz.18d4e4ba200bdf5f,"reason=FailedScheduling count=None msg=0/6 nodes are available: 6 node(s) had untolerated taint(s). no new claims to deallocate, preemption: 0/6 nodes are available: 6 Preemption is not helpful for scheduling."
0.2246,Event,ADDED,eval-sanitize-10-r0-086-28ghz.18d4e4babaa72c4b,reason=Scheduled count=None msg=Successfully assigned compute/eval-sanitize-10-r0-086-28ghz to kind-worker2
0.2247,Event,ADDED,eval-sanitize-10-r0-086-28ghz.18d4e4bae7df963c,"reason=Pulled count=1 msg=Container image ""busybox:musl"" already present on machine"
0.2249,Event,ADDED,eval-sanitize-10-r0-086-28ghz.18d4e4baeb030d37,reason=Created count=1 msg=Created container: task
0.2252,Event,ADDED,eval-sanitize-10-r0-086-28ghz.18d4e4baf481edbe,reason=Started count=1 msg=Started container task
0.2254,Event,ADDED,eval-sanitize-10-r0-086.18d4e4ba1fffd4ee,reason=SuccessfulCreate count=1 msg=Created pod: eval-sanitize-10-r0-086-28ghz
0.2256,Event,ADDED,eval-sanitize-10-r0-086.18d4e4c02d85f6c8,reason=Completed count=1 msg=Job completed
0.2257,Event,ADDED,eval-sanitize-10-r0-087-n9n4j.18d4e4ba5c204ecc,"reason=FailedScheduling count=None msg=0/6 nodes are available: 6 node(s) had untolerated taint(s). no new claims to deallocate, preemption: 0/6 nodes are available: 6 Preemption is not helpful for scheduling."
0.2259,Event,ADDED,eval-sanitize-10-r0-087-n9n4j.18d4e4babaaa9fdb,reason=Scheduled count=None msg=Successfully assigned compute/eval-sanitize-10-r0-087-n9n4j to kind-worker2
0.226,Event,ADDED,eval-sanitize-10-r0-087-n9n4j.18d4e4bae8312f39,"reason=Pulled count=1 msg=Container image ""busybox:musl"" already present on machine"
0.2267,Event,ADDED,eval-sanitize-10-r0-087-n9n4j.18d4e4baebb47750,reason=Created count=1 msg=Created container: task
0.2269,Event,ADDED,eval-sanitize-10-r0-087-n9n4j.18d4e4baf483c6b7,reason=Started count=1 msg=Started container task
0.2271,Event,ADDED,eval-sanitize-10-r0-087.18d4e4ba5c132d39,reason=SuccessfulCreate count=1 msg=Created pod: eval-sanitize-10-r0-087-n9n4j
0.2273,Event,ADDED,eval-sanitize-10-r0-087.18d4e4c0683c5327,reason=Completed count=1 msg=Job completed
0.2277,Event,ADDED,eval-sanitize-10-r0-088-cvlgp.18d4e4ba9bf30c0b,"reason=FailedScheduling count=None msg=0/6 nodes are available: 6 node(s) had untolerated taint(s). no new claims to deallocate, preemption: 0/6 nodes are available: 6 Preemption is not helpful for scheduling."
0.2279,Event,ADDED,eval-sanitize-10-r0-088-cvlgp.18d4e4bab84a4f84,"reason=FailedScheduling count=None msg=0/6 nodes are available: 1 c_wall violated: 1 conflicting context pair(s) with node memory, 5 node(s) had untolerated taint(s). no new claims to deallocate, preemption: 0/6 nodes are available: 1 No preemption victims found for incoming pod, 5 Preemption is not helpful for scheduling."
0.2281,Event,ADDED,eval-sanitize-10-r0-088-cvlgp.18d4e4babefafd59,"reason=FailedScheduling count=None msg=0/6 nodes are available: 1 c_wall violated: 1 conflicting context pair(s) with node memory, 5 node(s) had untolerated taint(s). no new claims to deallocate, preemption: 0/6 nodes are available: 1 No preemption victims found for incoming pod, 5 Preemption is not helpful for scheduling."
0.2283,Event,ADDED,eval-sanitize-10-r0-088-cvlgp.18d4e4bd299f14cd,"reason=FailedScheduling count=None msg=0/6 nodes are available: 1 c_wall violated: 1 conflicting context pair(s) with node memory, 5 node(s) had untolerated taint(s). no new claims to deallocate, preemption: 0/6 nodes are available: 1 No preemption victims found for incoming pod, 5 Preemption is not helpful for scheduling."
0.2285,Event,ADDED,eval-sanitize-10-r0-088-cvlgp.18d4e4bd357ef8f1,"reason=FailedScheduling count=None msg=0/6 nodes are available: 1 c_wall violated: 1 conflicting context pair(s) with node memory, 5 node(s) had untolerated taint(s). no new claims to deallocate, preemption: 0/6 nodes are available: 1 No preemption victims found for incoming pod, 5 Preemption is not helpful for scheduling."
0.2286,Event,ADDED,eval-sanitize-10-r0-088-cvlgp.18d4e4bd48fd143d,reason=Scheduled count=None msg=Successfully assigned compute/eval-sanitize-10-r0-088-cvlgp to kind-worker5
0.2289,Event,ADDED,eval-sanitize-10-r0-088-cvlgp.18d4e4bd6447ab92,"reason=Pulled count=1 msg=Container image ""busybox:musl"" already present on machine"
0.229,Event,ADDED,eval-sanitize-10-r0-088-cvlgp.18d4e4bd65c2447a,reason=Created count=1 msg=Created container: task
0.2292,Event,ADDED,eval-sanitize-10-r0-088-cvlgp.18d4e4bd699b38e1,reason=Started count=1 msg=Started container task
0.2294,Event,ADDED,eval-sanitize-10-r0-088.18d4e4ba9be8324a,reason=SuccessfulCreate count=1 msg=Created pod: eval-sanitize-10-r0-088-cvlgp
0.2298,Event,ADDED,eval-sanitize-10-r0-088.18d4e4c39a0c8647,reason=Completed count=1 msg=Job completed
0.2302,Event,ADDED,eval-sanitize-10-r0-089-jjh4f.18d4e4bad341362f,"reason=FailedScheduling count=None msg=0/6 nodes are available: 1 c_wall violated: 2 conflicting context pair(s) with node memory, 5 node(s) had untolerated taint(s). no new claims to deallocate, preemption: 0/6 nodes are available: 1 No preemption victims found for incoming pod, 5 Preemption is not helpful for scheduling."
0.2305,Event,ADDED,eval-sanitize-10-r0-089-jjh4f.18d4e4bad3f7729d,"reason=FailedScheduling count=None msg=0/6 nodes are available: 1 c_wall violated: 2 conflicting context pair(s) with node memory, 5 node(s) had untolerated taint(s). no new claims to deallocate, preemption: 0/6 nodes are available: 1 No preemption victims found for incoming pod, 5 Preemption is not helpful for scheduling."
0.2308,Event,ADDED,eval-sanitize-10-r0-089-jjh4f.18d4e4bd1d451046,reason=Scheduled count=None msg=Successfully assigned compute/eval-sanitize-10-r0-089-jjh4f to kind-worker
0.231,Event,ADDED,eval-sanitize-10-r0-089-jjh4f.18d4e4bd37d28ef0,"reason=Pulled count=1 msg=Container image ""busybox:musl"" already present on machine"
0.2312,Event,ADDED,eval-sanitize-10-r0-089-jjh4f.18d4e4bd39ec63d6,reason=Created count=1 msg=Created container: task
0.2315,Event,ADDED,eval-sanitize-10-r0-089-jjh4f.18d4e4bd4031e1da,reason=Started count=1 msg=Started container task
0.2317,Event,ADDED,eval-sanitize-10-r0-089.18d4e4bad30155a4,reason=SuccessfulCreate count=1 msg=Created pod: eval-sanitize-10-r0-089-jjh4f
0.2318,Event,ADDED,eval-sanitize-10-r0-089.18d4e4c3b8d73c92,reason=Completed count=1 msg=Job completed
0.232,Event,ADDED,eval-sanitize-10-r0-090-nrlvw.18d4e4bb0daeb96e,"reason=FailedScheduling count=None msg=0/6 nodes are available: 1 c_wall violated: 2 conflicting context pair(s) with node memory, 5 node(s) had untolerated taint(s). no new claims to deallocate, preemption: 0/6 nodes are available: 1 No preemption victims found for incoming pod, 5 Preemption is not helpful for scheduling."
0.2325,Event,ADDED,eval-sanitize-10-r0-090-nrlvw.18d4e4bb12bdec0e,"reason=FailedScheduling count=None msg=0/6 nodes are available: 1 c_wall violated: 2 conflicting context pair(s) with node memory, 5 node(s) had untolerated taint(s). no new claims to deallocate, preemption: 0/6 nodes are available: 1 No preemption victims found for incoming pod, 5 Preemption is not helpful for scheduling."
0.2327,Event,ADDED,eval-sanitize-10-r0-090-nrlvw.18d4e4bd2f564f53,reason=Scheduled count=None msg=Successfully assigned compute/eval-sanitize-10-r0-090-nrlvw to kind-worker
0.2329,Event,ADDED,eval-sanitize-10-r0-090-nrlvw.18d4e4bd430568c9,"reason=Pulled count=1 msg=Container image ""busybox:musl"" already present on machine"
0.2332,Event,ADDED,eval-sanitize-10-r0-090-nrlvw.18d4e4bd44b5a189,reason=Created count=1 msg=Created container: task
0.2333,Event,ADDED,eval-sanitize-10-r0-090-nrlvw.18d4e4bd4b828737,reason=Started count=1 msg=Started container task
0.2335,Event,ADDED,eval-sanitize-10-r0-090.18d4e4bb0d77cb3a,reason=SuccessfulCreate count=1 msg=Created pod: eval-sanitize-10-r0-090-nrlvw
0.2337,Event,ADDED,eval-sanitize-10-r0-090.18d4e4c3d39faea3,reason=Completed count=1 msg=Job completed
0.2339,Event,ADDED,eval-sanitize-10-r0-091-kc5hx.18d4e4bb49c982a3,reason=Scheduled count=None msg=Successfully assigned compute/eval-sanitize-10-r0-091-kc5hx to kind-worker2
0.2341,Event,ADDED,eval-sanitize-10-r0-091-kc5hx.18d4e4bb69d00424,"reason=Pulled count=1 msg=Container image ""busybox:musl"" already present on machine"
0.2343,Event,ADDED,eval-sanitize-10-r0-091-kc5hx.18d4e4bb6b29ceca,reason=Created count=1 msg=Created container: task
0.2344,Event,ADDED,eval-sanitize-10-r0-091-kc5hx.18d4e4bb70c33d3e,reason=Started count=1 msg=Started container task
0.2347,Event,ADDED,eval-sanitize-10-r0-091.18d4e4bb493a0988,reason=SuccessfulCreate count=1 msg=Created pod: eval-sanitize-10-r0-091-kc5hx
0.2349,Event,ADDED,eval-sanitize-10-r0-091.18d4e4c0e12ba03b,reason=Completed count=1 msg=Job completed
0.2351,Event,ADDED,eval-sanitize-10-r0-092-glghv.18d4e4bb8cb772b2,"reason=FailedScheduling count=None msg=0/6 nodes are available: 1 c_wall violated: 2 conflicting context pair(s) with node memory, 5 node(s) had untolerated taint(s). no new claims to deallocate, preemption: 0/6 nodes are available: 1 No preemption victims found for incoming pod, 5 Preemption is not helpful for scheduling."
0.2353,Event,ADDED,eval-sanitize-10-r0-092-glghv.18d4e4bb8d301ed4,"reason=FailedScheduling count=None msg=0/6 nodes are available: 1 c_wall violated: 2 conflicting context pair(s) with node memory, 5 node(s) had untolerated taint(s). no new claims to deallocate, preemption: 0/6 nodes are available: 1 No preemption victims found for incoming pod, 5 Preemption is not helpful for scheduling."
0.2354,Event,ADDED,eval-sanitize-10-r0-092-glghv.18d4e4bd1da23156,reason=Scheduled count=None msg=Successfully assigned compute/eval-sanitize-10-r0-092-glghv to kind-worker
0.2356,Event,ADDED,eval-sanitize-10-r0-092-glghv.18d4e4bd385fdec9,"reason=Pulled count=1 msg=Container image ""busybox:musl"" already present on machine"
0.2358,Event,ADDED,eval-sanitize-10-r0-092-glghv.18d4e4bd3b235f32,reason=Created count=1 msg=Created container: task
0.2359,Event,ADDED,eval-sanitize-10-r0-092-glghv.18d4e4bd40f89e1e,reason=Started count=1 msg=Started container task
0.2361,Event,ADDED,eval-sanitize-10-r0-092.18d4e4bb8c7d8e6b,reason=SuccessfulCreate count=1 msg=Created pod: eval-sanitize-10-r0-092-glghv
0.2363,Event,ADDED,eval-sanitize-10-r0-092.18d4e4c3a0c95bfd,reason=Completed count=1 msg=Job completed
0.2364,Event,ADDED,eval-sanitize-10-r0-093-g95zw.18d4e4bbc880d7f6,"reason=FailedScheduling count=None msg=0/6 nodes are available: 1 c_wall violated: 2 conflicting context pair(s) with node memory, 5 node(s) had untolerated taint(s). no new claims to deallocate, preemption: 0/6 nodes are available: 1 No preemption victims found for incoming pod, 5 Preemption is not helpful for scheduling."
0.2366,Event,ADDED,eval-sanitize-10-r0-093-g95zw.18d4e4bbc8ffff79,"reason=FailedScheduling count=None msg=0/6 nodes are available: 1 c_wall violated: 2 conflicting context pair(s) with node memory, 5 node(s) had untolerated taint(s). no new claims to deallocate, preemption: 0/6 nodes are available: 1 No preemption victims found for incoming pod, 5 Preemption is not helpful for scheduling."
0.2368,Event,ADDED,eval-sanitize-10-r0-093-g95zw.18d4e4bd1df5dcc9,reason=Scheduled count=None msg=Successfully assigned compute/eval-sanitize-10-r0-093-g95zw to kind-worker
0.237,Event,ADDED,eval-sanitize-10-r0-093-g95zw.18d4e4bd38f8eb51,"reason=Pulled count=1 msg=Container image ""busybox:musl"" already present on machine"
0.2371,Event,ADDED,eval-sanitize-10-r0-093-g95zw.18d4e4bd3c1e748e,reason=Created count=1 msg=Created container: task
0.2373,Event,ADDED,eval-sanitize-10-r0-093-g95zw.18d4e4bd40f7719f,reason=Started count=1 msg=Started container task
0.2375,Event,ADDED,eval-sanitize-10-r0-093.18d4e4bbc849bbc5,reason=SuccessfulCreate count=1 msg=Created pod: eval-sanitize-10-r0-093-g95zw
0.2376,Event,ADDED,eval-sanitize-10-r0-093.18d4e4c3caafb788,reason=Completed count=1 msg=Job completed
0.2378,Event,ADDED,eval-sanitize-10-r0-094-bgcfb.18d4e4bbfc5195c2,"reason=FailedScheduling count=None msg=0/6 nodes are available: 1 c_wall violated: 1 conflicting context pair(s) with node memory, 5 node(s) had untolerated taint(s). no new claims to deallocate, preemption: 0/6 nodes are available: 1 No preemption victims found for incoming pod, 5 Preemption is not helpful for scheduling."
0.238,Event,ADDED,eval-sanitize-10-r0-094-bgcfb.18d4e4bbfcc80b5a,"reason=FailedScheduling count=None msg=0/6 nodes are available: 1 c_wall violated: 1 conflicting context pair(s) with node memory, 5 node(s) had untolerated taint(s). no new claims to deallocate, preemption: 0/6 nodes are available: 1 No preemption victims found for incoming pod, 5 Preemption is not helpful for scheduling."
0.2381,Event,ADDED,eval-sanitize-10-r0-094-bgcfb.18d4e4bd1e1e1741,reason=Scheduled count=None msg=Successfully assigned compute/eval-sanitize-10-r0-094-bgcfb to kind-worker
0.2383,Event,ADDED,eval-sanitize-10-r0-094-bgcfb.18d4e4bd395f7054,"reason=Pulled count=1 msg=Container image ""busybox:musl"" already present on machine"
0.2385,Event,ADDED,eval-sanitize-10-r0-094-bgcfb.18d4e4bd3c23a938,reason=Created count=1 msg=Created container: task
0.2386,Event,ADDED,eval-sanitize-10-r0-094-bgcfb.18d4e4bd40f7718b,reason=Started count=1 msg=Started container task
0.2389,Event,ADDED,eval-sanitize-10-r0-094.18d4e4bbfc159954,reason=SuccessfulCreate count=1 msg=Created pod: eval-sanitize-10-r0-094-bgcfb
0.2391,Event,ADDED,eval-sanitize-10-r0-094.18d4e4c2a145b6bd,reason=Completed count=1 msg=Job completed
0.2392,Event,ADDED,eval-sanitize-10-r0-095-fshwj.18d4e4bc3cb3e826,"reason=FailedScheduling count=None msg=0/6 nodes are available: 1 c_wall violated: 1 conflicting context pair(s) with node memory, 5 node(s) had untolerated taint(s). no new claims to deallocate, preemption: 0/6 nodes are available: 1 No preemption victims found for incoming pod, 5 Preemption is not helpful for scheduling."
0.2396,Event,ADDED,eval-sanitize-10-r0-095-fshwj.18d4e4bc3d37ded4,"reason=FailedScheduling count=None msg=0/6 nodes are available: 1 c_wall violated: 1 conflicting context pair(s) with node memory, 5 node(s) had untolerated taint(s). no new claims to deallocate, preemption: 0/6 nodes are available: 1 No preemption victims found for incoming pod, 5 Preemption is not helpful for scheduling."
0.2397,Event,ADDED,eval-sanitize-10-r0-095-fshwj.18d4e4bd1dd0ccdb,"reason=FailedScheduling count=None msg=0/6 nodes are available: 1 c_wall violated: 1 conflicting context pair(s) with node memory, 5 node(s) had untolerated taint(s). no new claims to deallocate, preemption: 0/6 nodes are available: 1 No preemption victims found for incoming pod, 5 Preemption is not helpful for scheduling."
0.2399,Event,ADDED,eval-sanitize-10-r0-095-fshwj.18d4e4bd30216cfb,"reason=FailedScheduling count=None msg=0/6 nodes are available: 1 c_wall violated: 1 conflicting context pair(s) with node memory, 5 node(s) had untolerated taint(s). no new claims to deallocate, preemption: 0/6 nodes are available: 1 No preemption victims found for incoming pod, 5 Preemption is not helpful for scheduling."
0.2402,Event,ADDED,eval-sanitize-10-r0-095-fshwj.18d4e4bd491da245,reason=Scheduled count=None msg=Successfully assigned compute/eval-sanitize-10-r0-095-fshwj to kind-worker4
0.2404,Event,ADDED,eval-sanitize-10-r0-095-fshwj.18d4e4bd63b7ceed,"reason=Pulled count=1 msg=Container image ""busybox:musl"" already present on machine"
0.2405,Event,ADDED,eval-sanitize-10-r0-095-fshwj.18d4e4bd65daa2d4,reason=Created count=1 msg=Created container: task
0.2407,Event,ADDED,eval-sanitize-10-r0-095-fshwj.18d4e4bd69ff71b7,reason=Started count=1 msg=Started container task
0.241,Event,ADDED,eval-sanitize-10-r0-095.18d4e4bc3c7587bf,reason=SuccessfulCreate count=1 msg=Created pod: eval-sanitize-10-r0-095-fshwj
0.2412,Event,ADDED,eval-sanitize-10-r0-095.18d4e4c3e5ad1705,reason=Completed count=1 msg=Job completed
0.2414,Event,ADDED,eval-sanitize-10-r0-096-rxmfr.18d4e4bc748a8f75,reason=Scheduled count=None msg=Successfully assigned compute/eval-sanitize-10-r0-096-rxmfr to kind-worker2
0.2416,Event,ADDED,eval-sanitize-10-r0-096-rxmfr.18d4e4bc90b5e41a,"reason=Pulled count=1 msg=Container image ""busybox:musl"" already present on machine"
0.2419,Event,ADDED,eval-sanitize-10-r0-096-rxmfr.18d4e4bc921e4a67,reason=Created count=1 msg=Created container: task
0.2422,Event,ADDED,eval-sanitize-10-r0-096-rxmfr.18d4e4bc96be8072,reason=Started count=1 msg=Started container task
0.2424,Event,ADDED,eval-sanitize-10-r0-096.18d4e4bc73fd2944,reason=SuccessfulCreate count=1 msg=Created pod: eval-sanitize-10-r0-096-rxmfr
0.2426,Event,ADDED,eval-sanitize-10-r0-096.18d4e4c20b3e2cde,reason=Completed count=1 msg=Job completed
0.2428,Event,ADDED,eval-sanitize-10-r0-097-qq868.18d4e4bcb38444de,"reason=FailedScheduling count=None msg=0/6 nodes are available: 1 c_wall violated: 1 conflicting context pair(s) with node memory, 5 node(s) had untolerated taint(s). no new claims to deallocate, preemption: 0/6 nodes are available: 1 No preemption victims found for incoming pod, 5 Preemption is not helpful for scheduling."
0.243,Event,ADDED,eval-sanitize-10-r0-097-qq868.18d4e4bcb98db904,"reason=FailedScheduling count=None msg=0/6 nodes are available: 1 c_wall violated: 1 conflicting context pair(s) with node memory, 5 node(s) had untolerated taint(s). no new claims to deallocate, preemption: 0/6 nodes are available: 1 No preemption victims found for incoming pod, 5 Preemption is not helpful for scheduling."
0.2435,Event,ADDED,eval-sanitize-10-r0-097-qq868.18d4e4bd1e9a0b1c,"reason=FailedScheduling count=None msg=0/6 nodes are available: 1 c_wall violated: 1 conflicting context pair(s) with node memory, 5 node(s) had untolerated taint(s). no new claims to deallocate, preemption: 0/6 nodes are available: 1 No preemption victims found for incoming pod, 5 Preemption is not helpful for scheduling."
0.2437,Event,ADDED,eval-sanitize-10-r0-097-qq868.18d4e4bd304dc9a9,"reason=FailedScheduling count=None msg=0/6 nodes are available: 1 c_wall violated: 1 conflicting context pair(s) with node memory, 5 node(s) had untolerated taint(s). no new claims to deallocate, preemption: 0/6 nodes are available: 1 No preemption victims found for incoming pod, 5 Preemption is not helpful for scheduling."
0.2438,Event,ADDED,eval-sanitize-10-r0-097-qq868.18d4e4bd4dd6e912,reason=Scheduled count=None msg=Successfully assigned compute/eval-sanitize-10-r0-097-qq868 to kind-worker4
0.244,Event,ADDED,eval-sanitize-10-r0-097-qq868.18d4e4bd69876bf0,"reason=Pulled count=1 msg=Container image ""busybox:musl"" already present on machine"
0.2443,Event,ADDED,eval-sanitize-10-r0-097-qq868.18d4e4bd6b0d56af,reason=Created count=1 msg=Created container: task
0.2444,Event,ADDED,eval-sanitize-10-r0-097-qq868.18d4e4bd6f47d26f,reason=Started count=1 msg=Started container task
0.2446,Event,ADDED,eval-sanitize-10-r0-097.18d4e4bcb2eecce1,reason=SuccessfulCreate count=1 msg=Created pod: eval-sanitize-10-r0-097-qq868
0.2448,Event,ADDED,eval-sanitize-10-r0-097.18d4e4c3f4497414,reason=Completed count=1 msg=Job completed
0.245,Event,ADDED,eval-sanitize-10-r0-098-hc6cj.18d4e4bcee82bd22,reason=Scheduled count=None msg=Successfully assigned compute/eval-sanitize-10-r0-098-hc6cj to kind-worker2
0.2452,Event,ADDED,eval-sanitize-10-r0-098-hc6cj.18d4e4bd0ba8130b,"reason=Pulled count=1 msg=Container image ""busybox:musl"" already present on machine"
0.2453,Event,ADDED,eval-sanitize-10-r0-098-hc6cj.18d4e4bd0cd00915,reason=Created count=1 msg=Created container: task
0.2456,Event,ADDED,eval-sanitize-10-r0-098-hc6cj.18d4e4bd119436a7,reason=Started count=1 msg=Started container task
0.2458,Event,ADDED,eval-sanitize-10-r0-098.18d4e4bced3574a1,reason=SuccessfulCreate count=1 msg=Created pod: eval-sanitize-10-r0-098-hc6cj
0.246,Event,ADDED,eval-sanitize-10-r0-098.18d4e4c282c6d5f8,reason=Completed count=1 msg=Job completed
0.2462,Event,ADDED,eval-sanitize-10-r0-099-zkx55.18d4e4bd2a150dda,"reason=FailedScheduling count=None msg=0/6 nodes are available: 1 c_wall violated: 3 conflicting context pair(s) with node memory, 5 node(s) had untolerated taint(s). no new claims to deallocate, preemption: 0/6 nodes are available: 1 No preemption victims found for incoming pod, 5 Preemption is not helpful for scheduling."
0.2464,Event,ADDED,eval-sanitize-10-r0-099-zkx55.18d4e4bd360de201,reason=Scheduled count=None msg=Successfully assigned compute/eval-sanitize-10-r0-099-zkx55 to kind-worker5
0.2466,Event,ADDED,eval-sanitize-10-r0-099-zkx55.18d4e4bd50b2d1ba,"reason=Pulled count=1 msg=Container image ""busybox:musl"" already present on machine"
0.2467,Event,ADDED,eval-sanitize-10-r0-099-zkx55.18d4e4bd52c201a9,reason=Created count=1 msg=Created container: task
0.247,Event,ADDED,eval-sanitize-10-r0-099-zkx55.18d4e4bd54d07c37,reason=Started count=1 msg=Started container task
0.2471,Event,ADDED,eval-sanitize-10-r0-099.18d4e4bd26735b7d,reason=SuccessfulCreate count=1 msg=Created pod: eval-sanitize-10-r0-099-zkx55
0.2473,Event,ADDED,eval-sanitize-10-r0-099.18d4e4c384e12a4f,reason=Completed count=1 msg=Job completed
0.2475,Event,ADDED,eval-sanitize-10-r0-100-vngm2.18d4e4bd6329bb96,reason=Scheduled count=None msg=Successfully assigned compute/eval-sanitize-10-r0-100-vngm2 to kind-worker
0.2476,Event,ADDED,eval-sanitize-10-r0-100-vngm2.18d4e4bd7ceda2d9,"reason=Pulled count=1 msg=Container image ""busybox:musl"" already present on machine"
0.2478,Event,ADDED,eval-sanitize-10-r0-100-vngm2.18d4e4bd7e598330,reason=Created count=1 msg=Created container: task
0.248,Event,ADDED,eval-sanitize-10-r0-100-vngm2.18d4e4bd8393d1b2,reason=Started count=1 msg=Started container task
0.2481,Event,ADDED,eval-sanitize-10-r0-100.18d4e4bd61c7ac12,reason=SuccessfulCreate count=1 msg=Created pod: eval-sanitize-10-r0-100-vngm2
0.2483,Event,ADDED,eval-sanitize-10-r0-100.18d4e4c41506c376,reason=Completed count=1 msg=Job completed
0.2484,Event,ADDED,eval-sanitize-10-r0-101-4vzh4.18d4e4bda07915cc,reason=Scheduled count=None msg=Successfully assigned compute/eval-sanitize-10-r0-101-4vzh4 to kind-worker4
0.2486,Event,ADDED,eval-sanitize-10-r0-101-4vzh4.18d4e4bdb91cd9e4,"reason=Pulled count=1 msg=Container image ""busybox:musl"" already present on machine"
0.2488,Event,ADDED,eval-sanitize-10-r0-101-4vzh4.18d4e4bdba7fca94,reason=Created count=1 msg=Created container: task
0.2489,Event,ADDED,eval-sanitize-10-r0-101-4vzh4.18d4e4bdbc7ae6eb,reason=Started count=1 msg=Started container task
0.2491,Event,ADDED,eval-sanitize-10-r0-101.18d4e4bd9f86b4ae,reason=SuccessfulCreate count=1 msg=Created pod: eval-sanitize-10-r0-101-4vzh4
0.2493,Event,ADDED,eval-sanitize-10-r0-101.18d4e4c3df72d662,reason=Completed count=1 msg=Job completed
0.2494,Event,ADDED,eval-sanitize-10-r0-102-v62nv.18d4e4bddb905081,reason=Scheduled count=None msg=Successfully assigned compute/eval-sanitize-10-r0-102-v62nv to kind-worker5
0.2496,Event,ADDED,eval-sanitize-10-r0-102-v62nv.18d4e4bdf5724cf7,"reason=Pulled count=1 msg=Container image ""busybox:musl"" already present on machine"
0.2497,Event,ADDED,eval-sanitize-10-r0-102-v62nv.18d4e4bdf6b1d7e2,reason=Created count=1 msg=Created container: task
0.2499,Event,ADDED,eval-sanitize-10-r0-102-v62nv.18d4e4bdfde58766,reason=Started count=1 msg=Started container task
0.2501,Event,ADDED,eval-sanitize-10-r0-102.18d4e4bdda6d1f86,reason=SuccessfulCreate count=1 msg=Created pod: eval-sanitize-10-r0-102-v62nv
0.2502,Event,ADDED,eval-sanitize-10-r0-102.18d4e4c426f2aa67,reason=Completed count=1 msg=Job completed
0.2504,Event,ADDED,eval-sanitize-10-r0-103-9kw2x.18d4e4be18cc1164,reason=Scheduled count=None msg=Successfully assigned compute/eval-sanitize-10-r0-103-9kw2x to kind-worker
0.2506,Event,ADDED,eval-sanitize-10-r0-103-9kw2x.18d4e4be31505073,"reason=Pulled count=1 msg=Container image ""busybox:musl"" already present on machine"
0.2507,Event,ADDED,eval-sanitize-10-r0-103-9kw2x.18d4e4be328e0de0,reason=Created count=1 msg=Created container: task
0.2509,Event,ADDED,eval-sanitize-10-r0-103-9kw2x.18d4e4be3798c730,reason=Started count=1 msg=Started container task
0.251,Event,ADDED,eval-sanitize-10-r0-103.18d4e4be17dc9400,reason=SuccessfulCreate count=1 msg=Created pod: eval-sanitize-10-r0-103-9kw2x
0.2512,Event,ADDED,eval-sanitize-10-r0-103.18d4e4c43bea2655,reason=Completed count=1 msg=Job completed
0.2514,Event,ADDED,eval-sanitize-10-r0-104-n5kfl.18d4e4be519136d6,reason=Scheduled count=None msg=Successfully assigned compute/eval-sanitize-10-r0-104-n5kfl to kind-worker4
0.2515,Event,ADDED,eval-sanitize-10-r0-104-n5kfl.18d4e4be69cbd0f1,"reason=Pulled count=1 msg=Container image ""busybox:musl"" already present on machine"
0.2518,Event,ADDED,eval-sanitize-10-r0-104-n5kfl.18d4e4be6af74813,reason=Created count=1 msg=Created container: task
0.2519,Event,ADDED,eval-sanitize-10-r0-104-n5kfl.18d4e4be6d07b2d6,reason=Started count=1 msg=Started container task
0.2521,Event,ADDED,eval-sanitize-10-r0-104.18d4e4be509100b5,reason=SuccessfulCreate count=1 msg=Created pod: eval-sanitize-10-r0-104-n5kfl
0.2522,Event,ADDED,eval-sanitize-10-r0-104.18d4e4c423ef24e4,reason=Completed count=1 msg=Job completed
0.2524,Event,ADDED,eval-sanitize-10-r0-105-ttbxk.18d4e4be8d015b06,reason=Scheduled count=None msg=Successfully assigned compute/eval-sanitize-10-r0-105-ttbxk to kind-worker5
0.2526,Event,ADDED,eval-sanitize-10-r0-105-ttbxk.18d4e4bea76097cd,"reason=Pulled count=1 msg=Container image ""busybox:musl"" already present on machine"
0.2527,Event,ADDED,eval-sanitize-10-r0-105-ttbxk.18d4e4bea88586a0,reason=Created count=1 msg=Created container: task
0.2529,Event,ADDED,eval-sanitize-10-r0-105-ttbxk.18d4e4beae9fcc4f,reason=Started count=1 msg=Started container task
0.2531,Event,ADDED,eval-sanitize-10-r0-105.18d4e4be8bef7ef6,reason=SuccessfulCreate count=1 msg=Created pod: eval-sanitize-10-r0-105-ttbxk
0.2533,Event,ADDED,eval-sanitize-10-r0-105.18d4e4c45f97b093,reason=Completed count=1 msg=Job completed
0.2534,Event,ADDED,eval-sanitize-10-r0-106-lh888.18d4e4bec8772ad1,reason=Scheduled count=None msg=Successfully assigned compute/eval-sanitize-10-r0-106-lh888 to kind-worker5
0.2537,Event,ADDED,eval-sanitize-10-r0-106-lh888.18d4e4bee43c2cc4,"reason=Pulled count=1 msg=Container image ""busybox:musl"" already present on machine"
0.2539,Event,ADDED,eval-sanitize-10-r0-106-lh888.18d4e4bee56f045f,reason=Created count=1 msg=Created container: task
0.2541,Event,ADDED,eval-sanitize-10-r0-106-lh888.18d4e4bee9d8114b,reason=Started count=1 msg=Started container task
0.2542,Event,ADDED,eval-sanitize-10-r0-106.18d4e4bec77d4052,reason=SuccessfulCreate count=1 msg=Created pod: eval-sanitize-10-r0-106-lh888
0.2545,Event,ADDED,eval-sanitize-10-r0-106.18d4e4c4d3b54347,reason=Completed count=1 msg=Job completed
0.2546,Event,ADDED,eval-sanitize-10-r0-107-sj5bt.18d4e4bf04b9ff22,reason=Scheduled count=None msg=Successfully assigned compute/eval-sanitize-10-r0-107-sj5bt to kind-worker4
0.2548,Event,ADDED,eval-sanitize-10-r0-107-sj5bt.18d4e4bf200bcfea,"reason=Pulled count=1 msg=Container image ""busybox:musl"" already present on machine"
0.255,Event,ADDED,eval-sanitize-10-r0-107-sj5bt.18d4e4bf213b6310,reason=Created count=1 msg=Created container: task
0.2553,Event,ADDED,eval-sanitize-10-r0-107-sj5bt.18d4e4bf25ea7f8a,reason=Started count=1 msg=Started container task
0.2554,Event,ADDED,eval-sanitize-10-r0-107.18d4e4bf03bdae0b,reason=SuccessfulCreate count=1 msg=Created pod: eval-sanitize-10-r0-107-sj5bt
0.2556,Event,ADDED,eval-sanitize-10-r0-107.18d4e4c5024b434f,reason=Completed count=1 msg=Job completed
0.256,Event,ADDED,eval-sanitize-10-r0-108-lg5nz.18d4e4bf3f9d69b1,reason=Scheduled count=None msg=Successfully assigned compute/eval-sanitize-10-r0-108-lg5nz to kind-worker5
0.2561,Event,ADDED,eval-sanitize-10-r0-108-lg5nz.18d4e4bf5ecd73b6,"reason=Pulled count=1 msg=Container image ""busybox:musl"" already present on machine"
0.2563,Event,ADDED,eval-sanitize-10-r0-108-lg5nz.18d4e4bf5ffe26c5,reason=Created count=1 msg=Created container: task
0.2565,Event,ADDED,eval-sanitize-10-r0-108-lg5nz.18d4e4bf679c5f86,reason=Started count=1 msg=Started container task
0.2569,Event,ADDED,eval-sanitize-10-r0-108.18d4e4bf3e9355e2,reason=SuccessfulCreate count=1 msg=Created pod: eval-sanitize-10-r0-108-lg5nz
0.2572,Event,ADDED,eval-sanitize-10-r0-108.18d4e4c50ccf85f2,reason=Completed count=1 msg=Job completed
0.2574,Event,ADDED,eval-sanitize-10-r0-109-fwtjs.18d4e4bf7dbd896b,reason=Scheduled count=None msg=Successfully assigned compute/eval-sanitize-10-r0-109-fwtjs to kind-worker5
0.2576,Event,ADDED,eval-sanitize-10-r0-109-fwtjs.18d4e4bf9bd52b4e,"reason=Pulled count=1 msg=Container image ""busybox:musl"" already present on machine"
0.2579,Event,ADDED,eval-sanitize-10-r0-109-fwtjs.18d4e4bf9d26f333,reason=Created count=1 msg=Created container: task
0.2581,Event,ADDED,eval-sanitize-10-r0-109-fwtjs.18d4e4bfa2519fdc,reason=Started count=1 msg=Started container task
0.2582,Event,ADDED,eval-sanitize-10-r0-109.18d4e4bf7d0926ef,reason=SuccessfulCreate count=1 msg=Created pod: eval-sanitize-10-r0-109-fwtjs
0.2584,Event,ADDED,eval-sanitize-10-r0-109.18d4e4c50321ca1d,reason=Completed count=1 msg=Job completed
0.2586,Event,ADDED,eval-sanitize-10-r0-110-7zvwq.18d4e4bfb62c6a87,reason=Scheduled count=None msg=Successfully assigned compute/eval-sanitize-10-r0-110-7zvwq to kind-worker3
0.2588,Event,ADDED,eval-sanitize-10-r0-110-7zvwq.18d4e4bfd1d9bf3a,"reason=Pulled count=1 msg=Container image ""busybox:musl"" already present on machine"
0.2589,Event,ADDED,eval-sanitize-10-r0-110-7zvwq.18d4e4bfd2eb2fbb,reason=Created count=1 msg=Created container: task
0.2591,Event,ADDED,eval-sanitize-10-r0-110-7zvwq.18d4e4bfd79f4076,reason=Started count=1 msg=Started container task
0.2593,Event,ADDED,eval-sanitize-10-r0-110.18d4e4bfb5cc485a,reason=SuccessfulCreate count=1 msg=Created pod: eval-sanitize-10-r0-110-7zvwq
0.2596,Event,ADDED,eval-sanitize-10-r0-110.18d4e4c574758351,reason=Completed count=1 msg=Job completed
0.2598,Event,ADDED,eval-sanitize-10-r0-111-6dxxd.18d4e4bff490cdc4,reason=Scheduled count=None msg=Successfully assigned compute/eval-sanitize-10-r0-111-6dxxd to kind-worker3
0.2602,Event,ADDED,eval-sanitize-10-r0-111-6dxxd.18d4e4c00eb5164f,"reason=Pulled count=1 msg=Container image ""busybox:musl"" already present on machine"
0.2604,Event,ADDED,eval-sanitize-10-r0-111-6dxxd.18d4e4c00fd0244b,reason=Created count=1 msg=Created container: task
0.2606,Event,ADDED,eval-sanitize-10-r0-111-6dxxd.18d4e4c0119e5cd9,reason=Started count=1 msg=Started container task
0.261,Event,ADDED,eval-sanitize-10-r0-111.18d4e4bff4207d4a,reason=SuccessfulCreate count=1 msg=Created pod: eval-sanitize-10-r0-111-6dxxd
0.2612,Event,ADDED,eval-sanitize-10-r0-111.18d4e4c5b41215c9,reason=Completed count=1 msg=Job completed
0.2614,Event,ADDED,eval-sanitize-10-r0-112-j7txf.18d4e4c036bd9602,"reason=FailedScheduling count=None msg=0/6 nodes are available: 1 c_wall violated: 1 conflicting context pair(s) with node memory, 5 node(s) had untolerated taint(s). no new claims to deallocate, preemption: 0/6 nodes are available: 1 No preemption victims found for incoming pod, 5 Preemption is not helpful for scheduling."
0.2616,Event,ADDED,eval-sanitize-10-r0-112-j7txf.18d4e4c0374c2baa,"reason=FailedScheduling count=None msg=0/6 nodes are available: 1 c_wall violated: 1 conflicting context pair(s) with node memory, 5 node(s) had untolerated taint(s). no new claims to deallocate, preemption: 0/6 nodes are available: 1 No preemption victims found for incoming pod, 5 Preemption is not helpful for scheduling."
0.2619,Event,ADDED,eval-sanitize-10-r0-112-j7txf.18d4e4c15ca33ef0,"reason=FailedScheduling count=None msg=0/6 nodes are available: 1 c_wall violated: 2 conflicting context pair(s) with node memory, 5 node(s) had untolerated taint(s). no new claims to deallocate, preemption: 0/6 nodes are available: 1 No preemption victims found for incoming pod, 5 Preemption is not helpful for scheduling."
0.2621,Event,ADDED,eval-sanitize-10-r0-112-j7txf.18d4e4c41aec5f00,reason=Scheduled count=None msg=Successfully assigned compute/eval-sanitize-10-r0-112-j7txf to kind-worker2
0.2623,Event,ADDED,eval-sanitize-10-r0-112-j7txf.18d4e4c435f81c2a,"reason=Pulled count=1 msg=Container image ""busybox:musl"" already present on machine"
0.2627,Event,ADDED,eval-sanitize-10-r0-112-j7txf.18d4e4c438ea70e7,reason=Created count=1 msg=Created container: task
0.263,Event,ADDED,eval-sanitize-10-r0-112-j7txf.18d4e4c43c8d71ac,reason=Started count=1 msg=Started container task
0.2632,Event,ADDED,eval-sanitize-10-r0-112.18d4e4c036858797,reason=SuccessfulCreate count=1 msg=Created pod: eval-sanitize-10-r0-112-j7txf
0.2633,Event,ADDED,eval-sanitize-10-r0-112.18d4e4c98f03a120,reason=Completed count=1 msg=Job completed
0.2636,Event,ADDED,eval-sanitize-10-r0-113-jtkll.18d4e4c069218733,"reason=FailedScheduling count=None msg=0/6 nodes are available: 1 c_wall violated: 1 conflicting context pair(s) with node memory, 5 node(s) had untolerated taint(s). no new claims to deallocate, preemption: 0/6 nodes are available: 1 No preemption victims found for incoming pod, 5 Preemption is not helpful for scheduling."
0.2638,Event,ADDED,eval-sanitize-10-r0-113-jtkll.18d4e4c069a9314e,"reason=FailedScheduling count=None msg=0/6 nodes are available: 1 c_wall violated: 1 conflicting context pair(s) with node memory, 5 node(s) had untolerated taint(s). no new claims to deallocate, preemption: 0/6 nodes are available: 1 No preemption victims found for incoming pod, 5 Preemption is not helpful for scheduling."
0.264,Event,ADDED,eval-sanitize-10-r0-113-jtkll.18d4e4c15b26ee08,"reason=FailedScheduling count=None msg=0/6 nodes are available: 1 c_wall violated: 2 conflicting context pair(s) with node memory, 5 node(s) had untolerated taint(s). no new claims to deallocate, preemption: 0/6 nodes are available: 1 No preemption victims found for incoming pod, 5 Preemption is not helpful for scheduling."
0.2644,Event,ADDED,eval-sanitize-10-r0-113-jtkll.18d4e4c419bef2d8,reason=Scheduled count=None msg=Successfully assigned compute/eval-sanitize-10-r0-113-jtkll to kind-worker2
0.2645,Event,ADDED,eval-sanitize-10-r0-113-jtkll.18d4e4c4343ccae9,"reason=Pulled count=1 msg=Container image ""busybox:musl"" already present on machine"
0.2647,Event,ADDED,eval-sanitize-10-r0-113-jtkll.18d4e4c43725c204,reason=Created count=1 msg=Created container: task
0.2651,Event,ADDED,eval-sanitize-10-r0-113-jtkll.18d4e4c43bcc48b4,reason=Started count=1 msg=Started container task
0.2653,Event,ADDED,eval-sanitize-10-r0-113.18d4e4c068d9f06a,reason=SuccessfulCreate count=1 msg=Created pod: eval-sanitize-10-r0-113-jtkll
0.2654,Event,ADDED,eval-sanitize-10-r0-113.18d4e4c98ecb48a3,reason=Completed count=1 msg=Job completed
0.2656,Event,ADDED,eval-sanitize-10-r0-114-8gxvs.18d4e4c0a4af2200,"reason=FailedScheduling count=None msg=0/6 nodes are available: 1 c_wall violated: 1 conflicting context pair(s) with node memory, 5 node(s) had untolerated taint(s). no new claims to deallocate, preemption: 0/6 nodes are available: 1 No preemption victims found for incoming pod, 5 Preemption is not helpful for scheduling."
0.2661,Event,ADDED,eval-sanitize-10-r0-114-8gxvs.18d4e4c0a536d180,"reason=FailedScheduling count=None msg=0/6 nodes are available: 1 c_wall violated: 1 conflicting context pair(s) with node memory, 5 node(s) had untolerated taint(s). no new claims to deallocate, preemption: 0/6 nodes are available: 1 No preemption victims found for incoming pod, 5 Preemption is not helpful for scheduling."
0.2663,Event,ADDED,eval-sanitize-10-r0-114-8gxvs.18d4e4c15b50e255,"reason=FailedScheduling count=None msg=0/6 nodes are available: 1 c_wall violated: 2 conflicting context pair(s) with node memory, 5 node(s) had untolerated taint(s). no new claims to deallocate, preemption: 0/6 nodes are available: 1 No preemption victims found for incoming pod, 5 Preemption is not helpful for scheduling."
0.2664,Event,ADDED,eval-sanitize-10-r0-114-8gxvs.18d4e4c419f1cc8b,"reason=FailedScheduling count=None msg=0/6 nodes are available: 1 c_wall violated: 1 conflicting context pair(s) with node memory, 5 node(s) had untolerated taint(s). no new claims to deallocate, preemption: 0/6 nodes are available: 1 No preemption victims found for incoming pod, 5 Preemption is not helpful for scheduling."
0.2667,Event,ADDED,eval-sanitize-10-r0-114-8gxvs.18d4e4c426d3455b,"reason=FailedScheduling count=None msg=0/6 nodes are available: 1 c_wall violated: 3 conflicting context pair(s) with node memory, 5 node(s) had untolerated taint(s). no new claims to deallocate, preemption: 0/6 nodes are available: 1 No preemption victims found for incoming pod, 5 Preemption is not helpful for scheduling."
0.2669,Event,ADDED,eval-sanitize-10-r0-114-8gxvs.18d4e4c42cae64c6,"reason=FailedScheduling count=None msg=0/6 nodes are available: 1 c_wall violated: 3 conflicting context pair(s) with node memory, 5 node(s) had untolerated taint(s). no new claims to deallocate, preemption: 0/6 nodes are available: 1 No preemption victims found for incoming pod, 5 Preemption is not helpful for scheduling."
0.2671,Event,ADDED,eval-sanitize-10-r0-114-8gxvs.18d4e4c451561c32,reason=Scheduled count=None msg=Successfully assigned compute/eval-sanitize-10-r0-114-8gxvs to kind-worker
0.2674,Event,ADDED,eval-sanitize-10-r0-114-8gxvs.18d4e4c46b9ad3e6,"reason=Pulled count=1 msg=Container image ""busybox:musl"" already present on machine"
0.2676,Event,ADDED,eval-sanitize-10-r0-114-8gxvs.18d4e4c46dbd3778,reason=Created count=1 msg=Created container: task
0.2678,Event,ADDED,eval-sanitize-10-r0-114-8gxvs.18d4e4c472331eb0,reason=Started count=1 msg=Started container task
0.2681,Event,ADDED,eval-sanitize-10-r0-114.18d4e4c0a46afa7b,reason=SuccessfulCreate count=1 msg=Created pod: eval-sanitize-10-r0-114-8gxvs
0.2683,Event,ADDED,eval-sanitize-10-r0-114.18d4e4ca3c1a0934,reason=Completed count=1 msg=Job completed
0.2685,Event,ADDED,eval-sanitize-10-r0-115-pht9g.18d4e4c0e1454ff6,"reason=FailedScheduling count=None msg=0/6 nodes are available: 1 c_wall violated: 1 conflicting context pair(s) with node memory, 5 node(s) had untolerated taint(s). no new claims to deallocate, preemption: 0/6 nodes are available: 1 No preemption victims found for incoming pod, 5 Preemption is not helpful for scheduling."
0.2687,Event,ADDED,eval-sanitize-10-r0-115-pht9g.18d4e4c0e1cea41e,"reason=FailedScheduling count=None msg=0/6 nodes are available: 1 c_wall violated: 1 conflicting context pair(s) with node memory, 5 node(s) had untolerated taint(s). no new claims to deallocate, preemption: 0/6 nodes are available: 1 No preemption victims found for incoming pod, 5 Preemption is not helpful for scheduling."
0.269,Event,ADDED,eval-sanitize-10-r0-115-pht9g.18d4e4c15b72be52,"reason=FailedScheduling count=None msg=0/6 nodes are available: 1 c_wall violated: 2 conflicting context pair(s) with node memory, 5 node(s) had untolerated taint(s). no new claims to deallocate, preemption: 0/6 nodes are available: 1 No preemption victims found for incoming pod, 5 Preemption is not helpful for scheduling."
0.2692,Event,ADDED,eval-sanitize-10-r0-115-pht9g.18d4e4c41abcbb19,reason=Scheduled count=None msg=Successfully assigned compute/eval-sanitize-10-r0-115-pht9g to kind-worker2
0.2693,Event,ADDED,eval-sanitize-10-r0-115-pht9g.18d4e4c43613c27e,"reason=Pulled count=1 msg=Container image ""busybox:musl"" already present on machine"
0.2696,Event,ADDED,eval-sanitize-10-r0-115-pht9g.18d4e4c438c612cf,reason=Created count=1 msg=Created container: task
0.2697,Event,ADDED,eval-sanitize-10-r0-115-pht9g.18d4e4c43c9092b2,reason=Started count=1 msg=Started container task
0.2699,Event,ADDED,eval-sanitize-10-r0-115.18d4e4c0e103b0da,reason=SuccessfulCreate count=1 msg=Created pod: eval-sanitize-10-r0-115-pht9g
0.2701,Event,ADDED,eval-sanitize-10-r0-115.18d4e4c98ff2d97f,reason=Completed count=1 msg=Job completed
0.2702,Event,ADDED,eval-sanitize-10-r0-116-6t6mh.18d4e4c11bc75755,reason=Scheduled count=None msg=Successfully assigned compute/eval-sanitize-10-r0-116-6t6mh to kind-worker3
0.2704,Event,ADDED,eval-sanitize-10-r0-116-6t6mh.18d4e4c13537f0b0,"reason=Pulled count=1 msg=Container image ""busybox:musl"" already present on machine"
0.2706,Event,ADDED,eval-sanitize-10-r0-116-6t6mh.18d4e4c1364efaf9,reason=Created count=1 msg=Created container: task
0.2708,Event,ADDED,eval-sanitize-10-r0-116-6t6mh.18d4e4c138264242,reason=Started count=1 msg=Started container task
0.271,Event,ADDED,eval-sanitize-10-r0-116.18d4e4c11b46c48d,reason=SuccessfulCreate count=1 msg=Created pod: eval-sanitize-10-r0-116-6t6mh
0.2712,Event,ADDED,eval-sanitize-10-r0-116.18d4e4c6d5f365a0,reason=Completed count=1 msg=Job completed
0.2714,Event,ADDED,eval-sanitize-10-r0-117-2j7x2.18d4e4c157a0d6a6,reason=Scheduled count=None msg=Successfully assigned compute/eval-sanitize-10-r0-117-2j7x2 to kind-worker3
0.2718,Event,ADDED,eval-sanitize-10-r0-117-2j7x2.18d4e4c1712d7b0f,"reason=Pulled count=1 msg=Container image ""busybox:musl"" already present on machine"
0.272,Event,ADDED,eval-sanitize-10-r0-117-2j7x2.18d4e4c1726a39ab,reason=Created count=1 msg=Created container: task
0.2722,Event,ADDED,eval-sanitize-10-r0-117-2j7x2.18d4e4c1768677b3,reason=Started count=1 msg=Started container task
0.2723,Event,ADDED,eval-sanitize-10-r0-117.18d4e4c156eb7745,reason=SuccessfulCreate count=1 msg=Created pod: eval-sanitize-10-r0-117-2j7x2
0.2726,Event,ADDED,eval-sanitize-10-r0-117.18d4e4c712ad29d4,reason=Completed count=1 msg=Job completed
0.2729,Event,ADDED,eval-sanitize-10-r0-118-kb567.18d4e4c19394dbbb,reason=Scheduled count=None msg=Successfully assigned compute/eval-sanitize-10-r0-118-kb567 to kind-worker3
0.2731,Event,ADDED,eval-sanitize-10-r0-118-kb567.18d4e4c1ac21e6ce,"reason=Pulled count=1 msg=Container image ""busybox:musl"" already present on machine"
0.2735,Event,ADDED,eval-sanitize-10-r0-118-kb567.18d4e4c1ad48f6a3,reason=Created count=1 msg=Created container: task
0.2737,Event,ADDED,eval-sanitize-10-r0-118-kb567.18d4e4c1b14d46ec,reason=Started count=1 msg=Started container task
0.2739,Event,ADDED,eval-sanitize-10-r0-118.18d4e4c192e69822,reason=SuccessfulCreate count=1 msg=Created pod: eval-sanitize-10-r0-118-kb567
0.2741,Event,ADDED,eval-sanitize-10-r0-118.18d4e4c74f081668,reason=Completed count=1 msg=Job completed
0.2744,Event,ADDED,eval-sanitize-10-r0-119-944qx.18d4e4c1ce8dca0a,"reason=FailedScheduling count=None msg=0/6 nodes are available: 1 c_wall violated: 2 conflicting context pair(s) with node memory, 5 node(s) had untolerated taint(s). no new claims to deallocate, preemption: 0/6 nodes are available: 1 No preemption victims found for incoming pod, 5 Preemption is not helpful for scheduling."
0.2746,Event,ADDED,eval-sanitize-10-r0-119-944qx.18d4e4c1d0031e23,"reason=FailedScheduling count=None msg=0/6 nodes are available: 1 c_wall violated: 2 conflicting context pair(s) with node memory, 5 node(s) had untolerated taint(s). no new claims to deallocate, preemption: 0/6 nodes are available: 1 No preemption victims found for incoming pod, 5 Preemption is not helpful for scheduling."
0.2748,Event,ADDED,eval-sanitize-10-r0-119-944qx.18d4e4c41b6260f2,reason=Scheduled count=None msg=Successfully assigned compute/eval-sanitize-10-r0-119-944qx to kind-worker2
0.2754,Event,ADDED,eval-sanitize-10-r0-119-944qx.18d4e4c435dd9106,"reason=Pulled count=1 msg=Container image ""busybox:musl"" already present on machine"
0.2755,Event,ADDED,eval-sanitize-10-r0-119-944qx.18d4e4c4383c5f71,reason=Created count=1 msg=Created container: task
0.2757,Event,ADDED,eval-sanitize-10-r0-119-944qx.18d4e4c43c909a51,reason=Started count=1 msg=Started container task
0.2759,Event,ADDED,eval-sanitize-10-r0-119.18d4e4c1ce467c06,reason=SuccessfulCreate count=1 msg=Created pod: eval-sanitize-10-r0-119-944qx
0.2762,Event,ADDED,eval-sanitize-10-r0-119.18d4e4c98f253398,reason=Completed count=1 msg=Job completed
0.2764,Event,ADDED,eval-sanitize-10-r0-120-4flw4.18d4e4c20b49675b,"reason=FailedScheduling count=None msg=0/6 nodes are available: 6 node(s) had untolerated taint(s). no new claims to deallocate, preemption: 0/6 nodes are available: 6 Preemption is not helpful for scheduling."
0.2766,Event,ADDED,eval-sanitize-10-r0-120-4flw4.18d4e4c41b02727c,"reason=FailedScheduling count=None msg=0/6 nodes are available: 1 c_wall violated: 1 conflicting context pair(s) with node memory, 5 node(s) had untolerated taint(s). no new claims to deallocate, preemption: 0/6 nodes are available: 1 No preemption victims found for incoming pod, 5 Preemption is not helpful for scheduling."
0.2772,Event,ADDED,eval-sanitize-10-r0-120-4flw4.18d4e4c4275794b2,"reason=FailedScheduling count=None msg=0/6 nodes are available: 1 c_wall violated: 1 conflicting context pair(s) with node memory, 5 node(s) had untolerated taint(s). no new claims to deallocate, preemption: 0/6 nodes are available: 1 No preemption victims found for incoming pod, 5 Preemption is not helpful for scheduling."
0.2775,Event,ADDED,eval-sanitize-10-r0-120-4flw4.18d4e4c451a95bb0,reason=Scheduled count=None msg=Successfully assigned compute/eval-sanitize-10-r0-120-4flw4 to kind-worker
0.2777,Event,ADDED,eval-sanitize-10-r0-120-4flw4.18d4e4c46b829a2d,"reason=Pulled count=1 msg=Container image ""busybox:musl"" already present on machine"
0.2779,Event,ADDED,eval-sanitize-10-r0-120-4flw4.18d4e4c46d17f1d0,reason=Created count=1 msg=Created container: task
0.2781,Event,ADDED,eval-sanitize-10-r0-120-4flw4.18d4e4c47232fcb3,reason=Started count=1 msg=Started container task
0.2786,Event,ADDED,eval-sanitize-10-r0-120.18d4e4c20b3e2c85,reason=SuccessfulCreate count=1 msg=Created pod: eval-sanitize-10-r0-120-4flw4
0.2788,Event,ADDED,eval-sanitize-10-r0-120.18d4e4ca37ade3f4,reason=Completed count=1 msg=Job completed
0.279,Event,ADDED,eval-sanitize-10-r0-121-tq5vh.18d4e4c2458d8656,"reason=FailedScheduling count=None msg=0/6 nodes are available: 6 node(s) had untolerated taint(s). no new claims to deallocate, preemption: 0/6 nodes are available: 6 Preemption is not helpful for scheduling."
0.2791,Event,ADDED,eval-sanitize-10-r0-121-tq5vh.18d4e4c41c2ff5bb,"reason=FailedScheduling count=None msg=0/6 nodes are available: 1 c_wall violated: 3 conflicting context pair(s) with node memory, 5 node(s) had untolerated taint(s). no new claims to deallocate, preemption: 0/6 nodes are available: 1 No preemption victims found for incoming pod, 5 Preemption is not helpful for scheduling."
0.2794,Event,ADDED,eval-sanitize-10-r0-121-tq5vh.18d4e4c427c17dbb,"reason=FailedScheduling count=None msg=0/6 nodes are available: 1 c_wall violated: 3 conflicting context pair(s) with node memory, 5 node(s) had untolerated taint(s). no new claims to deallocate, preemption: 0/6 nodes are available: 1 No preemption victims found for incoming pod, 5 Preemption is not helpful for scheduling."
0.2796,Event,ADDED,eval-sanitize-10-r0-121-tq5vh.18d4e4c4585b639d,reason=Scheduled count=None msg=Successfully assigned compute/eval-sanitize-10-r0-121-tq5vh to kind-worker
0.2798,Event,ADDED,eval-sanitize-10-r0-121-tq5vh.18d4e4c4723c5a9c,"reason=Pulled count=1 msg=Container image ""busybox:musl"" already present on machine"
0.28,Event,ADDED,eval-sanitize-10-r0-121-tq5vh.18d4e4c4738ba6e9,reason=Created count=1 msg=Created container: task
0.2801,Event,ADDED,eval-sanitize-10-r0-121-tq5vh.18d4e4c4783d74e7,reason=Started count=1 msg=Started container task
0.2803,Event,ADDED,eval-sanitize-10-r0-121.18d4e4c2458acdf6,reason=SuccessfulCreate count=1 msg=Created pod: eval-sanitize-10-r0-121-tq5vh
0.2805,Event,ADDED,eval-sanitize-10-r0-121.18d4e4ca454f2587,reason=Completed count=1 msg=Job completed
0.2806,Event,ADDED,eval-sanitize-10-r0-122-ms9hc.18d4e4c281b7c456,"reason=FailedScheduling count=None msg=0/6 nodes are available: 6 node(s) had untolerated taint(s). no new claims to deallocate, preemption: 0/6 nodes are available: 6 Preemption is not helpful for scheduling."
0.2809,Event,ADDED,eval-sanitize-10-r0-122-ms9hc.18d4e4c42089f89f,reason=Scheduled count=None msg=Successfully assigned compute/eval-sanitize-10-r0-122-ms9hc to kind-worker2
0.2812,Event,ADDED,eval-sanitize-10-r0-122-ms9hc.18d4e4c43bd21c58,"reason=Pulled count=1 msg=Container image ""busybox:musl"" already present on machine"
0.2814,Event,ADDED,eval-sanitize-10-r0-122-ms9hc.18d4e4c43d1695f4,reason=Created count=1 msg=Created container: task
0.2816,Event,ADDED,eval-sanitize-10-r0-122-ms9hc.18d4e4c440ad240d,reason=Started count=1 msg=Started container task
0.2818,Event,ADDED,eval-sanitize-10-r0-122.18d4e4c281ae499d,reason=SuccessfulCreate count=1 msg=Created pod: eval-sanitize-10-r0-122-ms9hc
0.2819,Event,ADDED,eval-sanitize-10-r0-122.18d4e4c98e9965d9,reason=Completed count=1 msg=Job completed
0.2821,Event,ADDED,eval-sanitize-10-r0-123-mvqxl.18d4e4c2e83166ed,"reason=FailedScheduling count=None msg=0/6 nodes are available: 6 node(s) had untolerated taint(s). no new claims to deallocate, preemption: 0/6 nodes are available: 6 Preemption is not helpful for scheduling."
0.2823,Event,ADDED,eval-sanitize-10-r0-123-mvqxl.18d4e4c41fe0b5c6,"reason=FailedScheduling count=None msg=0/6 nodes are available: 1 c_wall violated: 2 conflicting context pair(s) with node memory, 5 node(s) had untolerated taint(s). no new claims to deallocate, preemption: 0/6 nodes are available: 1 No preemption victims found for incoming pod, 5 Preemption is not helpful for scheduling."
0.2825,Event,ADDED,eval-sanitize-10-r0-123-mvqxl.18d4e4c42b850e76,"reason=FailedScheduling count=None msg=0/6 nodes are available: 1 c_wall violated: 2 conflicting context pair(s) with node memory, 5 node(s) had untolerated taint(s). no new claims to deallocate, preemption: 0/6 nodes are available: 1 No preemption victims found for incoming pod, 5 Preemption is not helpful for scheduling."
0.2829,Event,ADDED,eval-sanitize-10-r0-123-mvqxl.18d4e4c4620afd11,"reason=FailedScheduling count=None msg=0/6 nodes are available: 1 c_wall violated: 1 conflicting context pair(s) with node memory, 1 c_wall violated: 2 conflicting context pair(s) with node memory, 4 node(s) had untolerated taint(s). no new claims to deallocate, preemption: 0/6 nodes are available: 2 No preemption victims found for incoming pod, 4 Preemption is not helpful for scheduling."
0.2831,Event,ADDED,eval-sanitize-10-r0-123-mvqxl.18d4e4c4749f317a,reason=Scheduled count=None msg=Successfully assigned compute/eval-sanitize-10-r0-123-mvqxl to kind-worker4
0.2833,Event,ADDED,eval-sanitize-10-r0-123-mvqxl.18d4e4c493e03453,"reason=Pulled count=1 msg=Container image ""busybox:musl"" already present on machine"
0.2835,Event,ADDED,eval-sanitize-10-r0-123-mvqxl.18d4e4c49617bb21,reason=Created count=1 msg=Created container: task
0.2837,Event,ADDED,eval-sanitize-10-r0-123-mvqxl.18d4e4c499eb9d3f,reason=Started count=1 msg=Started container task
0.2838,Event,ADDED,eval-sanitize-10-r0-123.18d4e4c2e82800b1,reason=SuccessfulCreate count=1 msg=Created pod: eval-sanitize-10-r0-123-mvqxl
0.284,Event,ADDED,eval-sanitize-10-r0-123.18d4e4ca9afa4980,reason=Completed count=1 msg=Job completed
0.2841,Event,ADDED,eval-sanitize-10-r0-124-px5s9.18d4e4c36053b323,"reason=FailedScheduling count=None msg=0/6 nodes are available: 6 node(s) had untolerated taint(s). no new claims to deallocate, preemption: 0/6 nodes are available: 6 Preemption is not helpful for scheduling."
0.2843,Event,ADDED,eval-sanitize-10-r0-124-px5s9.18d4e4c420fffb93,"reason=FailedScheduling count=None msg=0/6 nodes are available: 1 c_wall violated: 1 conflicting context pair(s) with node memory, 5 node(s) had untolerated taint(s). no new claims to deallocate, preemption: 0/6 nodes are available: 1 No preemption victims found for incoming pod, 5 Preemption is not helpful for scheduling."
0.2845,Event,ADDED,eval-sanitize-10-r0-124-px5s9.18d4e4c42bbe000f,"reason=FailedScheduling count=None msg=0/6 nodes are available: 1 c_wall violated: 1 conflicting context pair(s) with node memory, 5 node(s) had untolerated taint(s). no new claims to deallocate, preemption: 0/6 nodes are available: 1 No preemption victims found for incoming pod, 5 Preemption is not helpful for scheduling."
0.2847,Event,ADDED,eval-sanitize-10-r0-124-px5s9.18d4e4c462b3659c,"reason=FailedScheduling count=None msg=0/6 nodes are available: 1 c_wall violated: 1 conflicting context pair(s) with node memory, 1 c_wall violated: 2 conflicting context pair(s) with node memory, 4 node(s) had untolerated taint(s). no new claims to deallocate, preemption: 0/6 nodes are available: 2 No preemption victims found for incoming pod, 4 Preemption is not helpful for scheduling."
0.2848,Event,ADDED,eval-sanitize-10-r0-124-px5s9.18d4e4c478d960f3,reason=Scheduled count=None msg=Successfully assigned compute/eval-sanitize-10-r0-124-px5s9 to kind-worker4
0.285,Event,ADDED,eval-sanitize-10-r0-124-px5s9.18d4e4c494110228,"reason=Pulled count=1 msg=Container image ""busybox:musl"" already present on machine"
0.2852,Event,ADDED,eval-sanitize-10-r0-124-px5s9.18d4e4c49767ebbb,reason=Created count=1 msg=Created container: task
0.2853,Event,ADDED,eval-sanitize-10-r0-124-px5s9.18d4e4c49ad45e4d,reason=Started count=1 msg=Started container task
0.2855,Event,ADDED,eval-sanitize-10-r0-124.18d4e4c3604c3032,reason=SuccessfulCreate count=1 msg=Created pod: eval-sanitize-10-r0-124-px5s9
0.2857,Event,ADDED,eval-sanitize-10-r0-124.18d4e4ca9b98adb0,reason=Completed count=1 msg=Job completed
0.2858,Event,ADDED,eval-sanitize-10-r0-125-m586z.18d4e4c3803329d6,"reason=FailedScheduling count=None msg=0/6 nodes are available: 6 node(s) had untolerated taint(s). no new claims to deallocate, preemption: 0/6 nodes are available: 6 Preemption is not helpful for scheduling."
0.286,Event,ADDED,eval-sanitize-10-r0-125-m586z.18d4e4c42185f7aa,"reason=FailedScheduling count=None msg=0/6 nodes are available: 1 c_wall violated: 1 conflicting context pair(s) with node memory, 5 node(s) had untolerated taint(s). no new claims to deallocate, preemption: 0/6 nodes are available: 1 No preemption victims found for incoming pod, 5 Preemption is not helpful for scheduling."
0.2861,Event,ADDED,eval-sanitize-10-r0-125-m586z.18d4e4c42bed1388,"reason=FailedScheduling count=None msg=0/6 nodes are available: 1 c_wall violated: 1 conflicting context pair(s) with node memory, 5 node(s) had untolerated taint(s). no new claims to deallocate, preemption: 0/6 nodes are available: 1 No preemption victims found for incoming pod, 5 Preemption is not helpful for scheduling."
0.2863,Event,ADDED,eval-sanitize-10-r0-125-m586z.18d4e4c467fa5c17,"reason=FailedScheduling count=None msg=0/6 nodes are available: 1 c_wall violated: 1 conflicting context pair(s) with node memory, 1 c_wall violated: 2 conflicting context pair(s) with node memory, 4 node(s) had untolerated taint(s). no new claims to deallocate, preemption: 0/6 nodes are available: 2 No preemption victims found for incoming pod, 4 Preemption is not helpful for scheduling."
0.2865,Event,ADDED,eval-sanitize-10-r0-125-m586z.18d4e4c47ac651a3,reason=Scheduled count=None msg=Successfully assigned compute/eval-sanitize-10-r0-125-m586z to kind-worker4
0.2869,Event,ADDED,eval-sanitize-10-r0-125-m586z.18d4e4c4950a8bfb,"reason=Pulled count=1 msg=Container image ""busybox:musl"" already present on machine"
0.287,Event,ADDED,eval-sanitize-10-r0-125-m586z.18d4e4c497bf5235,reason=Created count=1 msg=Created container: task
0.2872,Event,ADDED,eval-sanitize-10-r0-125-m586z.18d4e4c49ad45e57,reason=Started count=1 msg=Started container task
0.2874,Event,ADDED,eval-sanitize-10-r0-125.18d4e4c3802a6932,reason=SuccessfulCreate count=1 msg=Created pod: eval-sanitize-10-r0-125-m586z
0.2876,Event,ADDED,eval-sanitize-10-r0-125.18d4e4caa4749cdb,reason=Completed count=1 msg=Job completed
0.2877,Event,ADDED,eval-sanitize-10-r0-126-x9vh2.18d4e4c3bda4b28f,"reason=FailedScheduling count=None msg=0/6 nodes are available: 6 node(s) had untolerated taint(s). no new claims to deallocate, preemption: 0/6 nodes are available: 6 Preemption is not helpful for scheduling."
0.2879,Event,ADDED,eval-sanitize-10-r0-126-x9vh2.18d4e4c425e6a0e8,reason=Scheduled count=None msg=Successfully assigned compute/eval-sanitize-10-r0-126-x9vh2 to kind-worker2
0.2881,Event,ADDED,eval-sanitize-10-r0-126-x9vh2.18d4e4c440b41619,"reason=Pulled count=1 msg=Container image ""busybox:musl"" already present on machine"
0.2882,Event,ADDED,eval-sanitize-10-r0-126-x9vh2.18d4e4c441fb25cf,reason=Created count=1 msg=Created container: task
0.2884,Event,ADDED,eval-sanitize-10-r0-126-x9vh2.18d4e4c44874fdf7,reason=Started count=1 msg=Started container task
0.2885,Event,ADDED,eval-sanitize-10-r0-126.18d4e4c3bd969ebc,reason=SuccessfulCreate count=1 msg=Created pod: eval-sanitize-10-r0-126-x9vh2
0.2887,Event,ADDED,eval-sanitize-10-r0-126.18d4e4c98f4b9876,reason=Completed count=1 msg=Job completed
0.2889,Event,ADDED,eval-sanitize-10-r0-127-slgjs.18d4e4c3f161a8a8,"reason=FailedScheduling count=None msg=0/6 nodes are available: 6 node(s) had untolerated taint(s). no new claims to deallocate, preemption: 0/6 nodes are available: 6 Preemption is not helpful for scheduling."
0.2891,Event,ADDED,eval-sanitize-10-r0-127-slgjs.18d4e4c425bf430e,"reason=FailedScheduling count=None msg=0/6 nodes are available: 1 c_wall violated: 3 conflicting context pair(s) with node memory, 5 node(s) had untolerated taint(s). no new claims to deallocate, preemption: 0/6 nodes are available: 1 No preemption victims found for incoming pod, 5 Preemption is not helpful for scheduling."
0.2893,Event,ADDED,eval-sanitize-10-r0-127-slgjs.18d4e4c42c5e56c1,"reason=FailedScheduling count=None msg=0/6 nodes are available: 1 c_wall violated: 3 conflicting context pair(s) with node memory, 5 node(s) had untolerated taint(s). no new claims to deallocate, preemption: 0/6 nodes are available: 1 No preemption victims found for incoming pod, 5 Preemption is not helpful for scheduling."
0.2894,Event,ADDED,eval-sanitize-10-r0-127-slgjs.18d4e4c44ea4d6f1,reason=Scheduled count=None msg=Successfully assigned compute/eval-sanitize-10-r0-127-slgjs to kind-worker
0.2896,Event,ADDED,eval-sanitize-10-r0-127-slgjs.18d4e4c4682666bb,"reason=Pulled count=1 msg=Container image ""busybox:musl"" already present on machine"
0.2898,Event,ADDED,eval-sanitize-10-r0-127-slgjs.18d4e4c469bbae2b,reason=Created count=1 msg=Created container: task
0.2899,Event,ADDED,eval-sanitize-10-r0-127-slgjs.18d4e4c46c15d31b,reason=Started count=1 msg=Started container task
0.2902,Event,ADDED,eval-sanitize-10-r0-127.18d4e4c3f158d987,reason=SuccessfulCreate count=1 msg=Created pod: eval-sanitize-10-r0-127-slgjs
0.2903,Event,ADDED,eval-sanitize-10-r0-127.18d4e4ca3f25717f,reason=Completed count=1 msg=Job completed
0.2905,Event,ADDED,eval-sanitize-10-r0-128-8g58q.18d4e4c406537af4,"reason=FailedScheduling count=None msg=0/6 nodes are available: 6 node(s) had untolerated taint(s). no new claims to deallocate, preemption: 0/6 nodes are available: 6 Preemption is not helpful for scheduling."
0.2906,Event,ADDED,eval-sanitize-10-r0-128-8g58q.18d4e4c4264edc4f,"reason=FailedScheduling count=None msg=0/6 nodes are available: 1 c_wall violated: 1 conflicting context pair(s) with node memory, 5 node(s) had untolerated taint(s). no new claims to deallocate, preemption: 0/6 nodes are available: 1 No preemption victims found for incoming pod, 5 Preemption is not helpful for scheduling."
0.2908,Event,ADDED,eval-sanitize-10-r0-128-8g58q.18d4e4c42c82ea90,"reason=FailedScheduling count=None msg=0/6 nodes are available: 1 c_wall violated: 1 conflicting context pair(s) with node memory, 5 node(s) had untolerated taint(s). no new claims to deallocate, preemption: 0/6 nodes are available: 1 No preemption victims found for incoming pod, 5 Preemption is not helpful for scheduling."
0.2909,Event,ADDED,eval-sanitize-10-r0-128-8g58q.18d4e4c45e06d4e7,"reason=FailedScheduling count=None msg=0/6 nodes are available: 1 c_wall violated: 1 conflicting context pair(s) with node memory, 1 c_wall violated: 2 conflicting context pair(s) with node memory, 4 node(s) had untolerated taint(s). no new claims to deallocate, preemption: 0/6 nodes are available: 2 No preemption victims found for incoming pod, 4 Preemption is not helpful for scheduling."
0.2911,Event,ADDED,eval-sanitize-10-r0-128-8g58q.18d4e4c46855b031,"reason=FailedScheduling count=None msg=0/6 nodes are available: 1 c_wall violated: 1 conflicting context pair(s) with node memory, 1 c_wall violated: 2 conflicting context pair(s) with node memory, 4 node(s) had untolerated taint(s). no new claims to deallocate, preemption: 0/6 nodes are available: 2 No preemption victims found for incoming pod, 4 Preemption is not helpful for scheduling."
0.2913,Event,ADDED,eval-sanitize-10-r0-128-8g58q.18d4e4c48075e0b4,reason=Scheduled count=None msg=Successfully assigned compute/eval-sanitize-10-r0-128-8g58q to kind-worker4
0.2914,Event,ADDED,eval-sanitize-10-r0-128-8g58q.18d4e4c49b3fa9b1,"reason=Pulled count=1 msg=Container image ""busybox:musl"" already present on machine"
0.2916,Event,ADDED,eval-sanitize-10-r0-128-8g58q.18d4e4c49c6fac71,reason=Created count=1 msg=Created container: task
0.2918,Event,ADDED,eval-sanitize-10-r0-128-8g58q.18d4e4c4a2126093,reason=Started count=1 msg=Started container task
0.2919,Event,ADDED,eval-sanitize-10-r0-128.18d4e4c4064a2664,reason=SuccessfulCreate count=1 msg=Created pod: eval-sanitize-10-r0-128-8g58q
0.2921,Event,ADDED,eval-sanitize-10-r0-128.18d4e4ca9b1af44e,reason=Completed count=1 msg=Job completed
0.2922,Event,ADDED,eval-sanitize-10-r0-129-4q72f.18d4e4c4342be444,reason=Scheduled count=None msg=Successfully assigned compute/eval-sanitize-10-r0-129-4q72f to kind-worker2
0.2924,Event,ADDED,eval-sanitize-10-r0-129-4q72f.18d4e4c452c8aea5,"reason=Pulled count=1 msg=Container image ""busybox:musl"" already present on machine"
0.2926,Event,ADDED,eval-sanitize-10-r0-129-4q72f.18d4e4c453f3ce32,reason=Created count=1 msg=Created container: task
0.2928,Event,ADDED,eval-sanitize-10-r0-129-4q72f.18d4e4c4585d55f1,reason=Started count=1 msg=Started container task
0.293,Event,ADDED,eval-sanitize-10-r0-129.18d4e4c43369e24a,reason=SuccessfulCreate count=1 msg=Created pod: eval-sanitize-10-r0-129-4q72f
0.2932,Event,ADDED,eval-sanitize-10-r0-129.18d4e4c98fd69090,reason=Completed count=1 msg=Job completed
0.2934,Event,ADDED,eval-sanitize-10-r0-130-jvdd6.18d4e4c46e837cec,reason=Scheduled count=None msg=Successfully assigned compute/eval-sanitize-10-r0-130-jvdd6 to kind-worker2
0.2935,Event,ADDED,eval-sanitize-10-r0-130-jvdd6.18d4e4c487f4a0da,"reason=Pulled count=1 msg=Container image ""busybox:musl"" already present on machine"
0.2937,Event,ADDED,eval-sanitize-10-r0-130-jvdd6.18d4e4c488fb8a4e,reason=Created count=1 msg=Created container: task
0.2939,Event,ADDED,eval-sanitize-10-r0-130-jvdd6.18d4e4c48de409f3,reason=Started count=1 msg=Started container task
0.294,Event,ADDED,eval-sanitize-10-r0-130.18d4e4c4689f95a1,reason=SuccessfulCreate count=1 msg=Created pod: eval-sanitize-10-r0-130-jvdd6
0.2942,Event,ADDED,eval-sanitize-10-r0-130.18d4e4ca78453be4,reason=Completed count=1 msg=Job completed
0.2944,Event,ADDED,eval-sanitize-10-r0-131-j9zw8.18d4e4c4a2d85430,reason=Scheduled count=None msg=Successfully assigned compute/eval-sanitize-10-r0-131-j9zw8 to kind-worker2
0.2946,Event,ADDED,eval-sanitize-10-r0-131-j9zw8.18d4e4c4c2ca0cfc,"reason=Pulled count=1 msg=Container image ""busybox:musl"" already present on machine"
0.2948,Event,ADDED,eval-sanitize-10-r0-131-j9zw8.18d4e4c4c43070a1,reason=Created count=1 msg=Created container: task
0.2949,Event,ADDED,eval-sanitize-10-r0-131-j9zw8.18d4e4c4c8e5262b,reason=Started count=1 msg=Started container task
0.2951,Event,ADDED,eval-sanitize-10-r0-131.18d4e4c4a1f6ef30,reason=SuccessfulCreate count=1 msg=Created pod: eval-sanitize-10-r0-131-j9zw8
0.2952,Event,ADDED,eval-sanitize-10-r0-131.18d4e4cab35fbd65,reason=Completed count=1 msg=Job completed
0.2954,Event,ADDED,eval-sanitize-10-r0-132-4tnxk.18d4e4c4dfc810ad,reason=Scheduled count=None msg=Successfully assigned compute/eval-sanitize-10-r0-132-4tnxk to kind-worker
0.2956,Event,ADDED,eval-sanitize-10-r0-132-4tnxk.18d4e4c4fb476539,"reason=Pulled count=1 msg=Container image ""busybox:musl"" already present on machine"
0.2957,Event,ADDED,eval-sanitize-10-r0-132-4tnxk.18d4e4c4fc7ff17b,reason=Created count=1 msg=Created container: task
0.2959,Event,ADDED,eval-sanitize-10-r0-132-4tnxk.18d4e4c502371e2c,reason=Started count=1 msg=Started container task
0.296,Event,ADDED,eval-sanitize-10-r0-132.18d4e4c4deeac914,reason=SuccessfulCreate count=1 msg=Created pod: eval-sanitize-10-r0-132-4tnxk
0.2962,Event,ADDED,eval-sanitize-10-r0-132.18d4e4caf54c1e92,reason=Completed count=1 msg=Job completed
0.2964,Event,ADDED,eval-sanitize-10-r0-133-2vr9b.18d4e4c51a72c5fc,"reason=FailedScheduling count=None msg=0/6 nodes are available: 1 c_wall violated: 1 conflicting context pair(s) with node memory, 1 c_wall violated: 2 conflicting context pair(s) with node memory, 1 c_wall violated: 4 conflicting context pair(s) with node memory, 3 node(s) had untolerated taint(s). no new claims to deallocate, preemption: 0/6 nodes are available: 3 No preemption victims found for incoming pod, 3 Preemption is not helpful for scheduling."
0.2966,Event,ADDED,eval-sanitize-10-r0-133-2vr9b.18d4e4c51b4f43ac,"reason=FailedScheduling count=None msg=0/6 nodes are available: 1 c_wall violated: 1 conflicting context pair(s) with node memory, 1 c_wall violated: 2 conflicting context pair(s) with node memory, 1 c_wall violated: 4 conflicting context pair(s) with node memory, 3 node(s) had untolerated taint(s). no new claims to deallocate, preemption: 0/6 nodes are available: 3 No preemption victims found for incoming pod, 3 Preemption is not helpful for scheduling."
0.2968,Event,ADDED,eval-sanitize-10-r0-133-2vr9b.18d4e4c673032082,"reason=FailedScheduling count=None msg=0/6 nodes are available: 1 c_wall violated: 1 conflicting context pair(s) with node memory, 1 c_wall violated: 2 conflicting context pair(s) with node memory, 4 node(s) had untolerated taint(s). no new claims to deallocate, preemption: 0/6 nodes are available: 2 No preemption victims found for incoming pod, 4 Preemption is not helpful for scheduling."
0.2969,Event,ADDED,eval-sanitize-10-r0-133-2vr9b.18d4e4c6a95ff46b,"reason=FailedScheduling count=None msg=0/6 nodes are available: 1 c_wall violated: 1 conflicting context pair(s) with node memory, 5 node(s) had untolerated taint(s). no new claims to deallocate, preemption: 0/6 nodes are available: 1 No preemption victims found for incoming pod, 5 Preemption is not helpful for scheduling."
0.2971,Event,ADDED,eval-sanitize-10-r0-133-2vr9b.18d4e4c6c5dd1171,reason=Scheduled count=None msg=Successfully assigned compute/eval-sanitize-10-r0-133-2vr9b to kind-worker5
0.2974,Event,ADDED,eval-sanitize-10-r0-133-2vr9b.18d4e4c6e45a57bb,"reason=Pulled count=1 msg=Container image ""busybox:musl"" already present on machine"
0.2976,Event,ADDED,eval-sanitize-10-r0-133-2vr9b.18d4e4c6e5d86881,reason=Created count=1 msg=Created container: task
0.2977,Event,ADDED,eval-sanitize-10-r0-133-2vr9b.18d4e4c6ee3d4fa3,reason=Started count=1 msg=Started container task
0.298,Event,ADDED,eval-sanitize-10-r0-133.18d4e4c519cca689,reason=SuccessfulCreate count=1 msg=Created pod: eval-sanitize-10-r0-133-2vr9b
0.2982,Event,ADDED,eval-sanitize-10-r0-133.18d4e4cc766f3e7d,reason=Completed count=1 msg=Job completed
0.2984,Event,ADDED,eval-sanitize-10-r0-134-zd27l.18d4e4c551835b14,reason=Scheduled count=None msg=Successfully assigned compute/eval-sanitize-10-r0-134-zd27l to kind-worker
0.2985,Event,ADDED,eval-sanitize-10-r0-134-zd27l.18d4e4c56c76c7df,"reason=Pulled count=1 msg=Container image ""busybox:musl"" already present on machine"
0.299,Event,ADDED,eval-sanitize-10-r0-134-zd27l.18d4e4c56db5f129,reason=Created count=1 msg=Created container: task
0.2992,Event,ADDED,eval-sanitize-10-r0-134-zd27l.18d4e4c573109430,reason=Started count=1 msg=Started container task
0.2993,Event,ADDED,eval-sanitize-10-r0-134.18d4e4c550759f9d,reason=SuccessfulCreate count=1 msg=Created pod: eval-sanitize-10-r0-134-zd27l
0.2995,Event,ADDED,eval-sanitize-10-r0-134.18d4e4cb22a90e23,reason=Completed count=1 msg=Job completed
0.2998,Event,ADDED,eval-sanitize-10-r0-135-kl5tz.18d4e4c58ace7e9f,reason=Scheduled count=None msg=Successfully assigned compute/eval-sanitize-10-r0-135-kl5tz to kind-worker2
0.2999,Event,ADDED,eval-sanitize-10-r0-135-kl5tz.18d4e4c5a7c5d841,"reason=Pulled count=1 msg=Container image ""busybox:musl"" already present on machine"
0.3001,Event,ADDED,eval-sanitize-10-r0-135-kl5tz.18d4e4c5a926d7ba,reason=Created count=1 msg=Created container: task
0.3004,Event,ADDED,eval-sanitize-10-r0-135-kl5tz.18d4e4c5ac7e034d,reason=Started count=1 msg=Started container task
0.3006,Event,ADDED,eval-sanitize-10-r0-135.18d4e4c589dcb2a8,reason=SuccessfulCreate count=1 msg=Created pod: eval-sanitize-10-r0-135-kl5tz
0.3008,Event,ADDED,eval-sanitize-10-r0-135.18d4e4cb31dbe624,reason=Completed count=1 msg=Job completed
0.3009,Event,ADDED,eval-sanitize-10-r0-136-qsjrx.18d4e4c5cfa6787b,reason=Scheduled count=None msg=Successfully assigned compute/eval-sanitize-10-r0-136-qsjrx to kind-worker2
0.3012,Event,ADDED,eval-sanitize-10-r0-136-qsjrx.18d4e4c5f3d8c01f,"reason=Pulled count=1 msg=Container image ""busybox:musl"" already present on machine"
0.3014,Event,ADDED,eval-sanitize-10-r0-136-qsjrx.18d4e4c5f4f6d7f8,reason=Created count=1 msg=Created container: task
0.3016,Event,ADDED,eval-sanitize-10-r0-136-qsjrx.18d4e4c5fa736aec,reason=Started count=1 msg=Started container task
0.3017,Event,ADDED,eval-sanitize-10-r0-136.18d4e4c5c7742914,reason=SuccessfulCreate count=1 msg=Created pod: eval-sanitize-10-r0-136-qsjrx
0.302,Event,ADDED,eval-sanitize-10-r0-136.18d4e4cb29ae4e2c,reason=Completed count=1 msg=Job completed
0.3022,Event,ADDED,eval-sanitize-10-r0-137-xxhpt.18d4e4c603b300ed,reason=Scheduled count=None msg=Successfully assigned compute/eval-sanitize-10-r0-137-xxhpt to kind-worker2
0.3024,Event,ADDED,eval-sanitize-10-r0-137-xxhpt.18d4e4c624d07c70,"reason=Pulled count=1 msg=Container image ""busybox:musl"" already present on machine"
0.3026,Event,ADDED,eval-sanitize-10-r0-137-xxhpt.18d4e4c625edcc08,reason=Created count=1 msg=Created container: task
0.3028,Event,ADDED,eval-sanitize-10-r0-137-xxhpt.18d4e4c62e53c915,reason=Started count=1 msg=Started container task
0.3029,Event,ADDED,eval-sanitize-10-r0-137.18d4e4c60295736a,reason=SuccessfulCreate count=1 msg=Created pod: eval-sanitize-10-r0-137-xxhpt
0.3031,Event,ADDED,eval-sanitize-10-r0-137.18d4e4cb9f4ab16e,reason=Completed count=1 msg=Job completed
0.3033,Event,ADDED,eval-sanitize-10-r0-138-9n4dp.18d4e4c63c4c88f8,reason=Scheduled count=None msg=Successfully assigned compute/eval-sanitize-10-r0-138-9n4dp to kind-worker2
0.3035,Event,ADDED,eval-sanitize-10-r0-138-9n4dp.18d4e4c6630be387,"reason=Pulled count=1 msg=Container image ""busybox:musl"" already present on machine"
0.3037,Event,ADDED,eval-sanitize-10-r0-138-9n4dp.18d4e4c66422ccf4,reason=Created count=1 msg=Created container: task
0.3038,Event,ADDED,eval-sanitize-10-r0-138-9n4dp.18d4e4c668970eb3,reason=Started count=1 msg=Started container task
0.3041,Event,ADDED,eval-sanitize-10-r0-138.18d4e4c63b3088d1,reason=SuccessfulCreate count=1 msg=Created pod: eval-sanitize-10-r0-138-9n4dp
0.3042,Event,ADDED,eval-sanitize-10-r0-138.18d4e4cbdb97e542,reason=Completed count=1 msg=Job completed
0.3044,Event,ADDED,eval-sanitize-10-r0-139-nd7h2.18d4e4c676ad0a92,reason=Scheduled count=None msg=Successfully assigned compute/eval-sanitize-10-r0-139-nd7h2 to kind-worker4
0.3046,Event,ADDED,eval-sanitize-10-r0-139-nd7h2.18d4e4c6967897f4,"reason=Pulled count=1 msg=Container image ""busybox:musl"" already present on machine"
0.3047,Event,ADDED,eval-sanitize-10-r0-139-nd7h2.18d4e4c6980532ae,reason=Created count=1 msg=Created container: task
0.3049,Event,ADDED,eval-sanitize-10-r0-139-nd7h2.18d4e4c69e239f48,reason=Started count=1 msg=Started container task
0.3051,Event,ADDED,eval-sanitize-10-r0-139.18d4e4c6760d6bf1,reason=SuccessfulCreate count=1 msg=Created pod: eval-sanitize-10-r0-139-nd7h2
0.3052,Event,ADDED,eval-sanitize-10-r0-139.18d4e4cc0da9fb42,reason=Completed count=1 msg=Job completed
0.3054,Event,ADDED,eval-sanitize-10-r0-140-zjp9x.18d4e4c6b6a35930,"reason=FailedScheduling count=None msg=0/6 nodes are available: 1 c_wall violated: 1 conflicting context pair(s) with node memory, 5 node(s) had untolerated taint(s). no new claims to deallocate, preemption: 0/6 nodes are available: 1 No preemption victims found for incoming pod, 5 Preemption is not helpful for scheduling."
0.3056,Event,ADDED,eval-sanitize-10-r0-140-zjp9x.18d4e4c6b71d6063,"reason=FailedScheduling count=None msg=0/6 nodes are available: 1 c_wall violated: 1 conflicting context pair(s) with node memory, 5 node(s) had untolerated taint(s). no new claims to deallocate, preemption: 0/6 nodes are available: 1 No preemption victims found for incoming pod, 5 Preemption is not helpful for scheduling."
0.3058,Event,ADDED,eval-sanitize-10-r0-140-zjp9x.18d4e4c6c62be434,reason=Scheduled count=None msg=Successfully assigned compute/eval-sanitize-10-r0-140-zjp9x to kind-worker5
0.306,Event,ADDED,eval-sanitize-10-r0-140-zjp9x.18d4e4c6e4792b7f,"reason=Pulled count=1 msg=Container image ""busybox:musl"" already present on machine"
0.3063,Event,ADDED,eval-sanitize-10-r0-140-zjp9x.18d4e4c6e60aada5,reason=Created count=1 msg=Created container: task
0.3064,Event,ADDED,eval-sanitize-10-r0-140-zjp9x.18d4e4c6ee3d115f,reason=Started count=1 msg=Started container task
0.3067,Event,ADDED,eval-sanitize-10-r0-140.18d4e4c6b6621180,reason=SuccessfulCreate count=1 msg=Created pod: eval-sanitize-10-r0-140-zjp9x
0.3068,Event,ADDED,eval-sanitize-10-r0-140.18d4e4cc7649a3d5,reason=Completed count=1 msg=Job completed
0.307,Event,ADDED,eval-sanitize-10-r0-141-hlg2l.18d4e4c6f09ba553,reason=Scheduled count=None msg=Successfully assigned compute/eval-sanitize-10-r0-141-hlg2l to kind-worker5
0.3071,Event,ADDED,eval-sanitize-10-r0-141-hlg2l.18d4e4c70d7872aa,"reason=Pulled count=1 msg=Container image ""busybox:musl"" already present on machine"
0.3074,Event,ADDED,eval-sanitize-10-r0-141-hlg2l.18d4e4c70ebefbb7,reason=Created count=1 msg=Created container: task
0.3075,Event,ADDED,eval-sanitize-10-r0-141-hlg2l.18d4e4c7122a2c08,reason=Started count=1 msg=Started container task
0.3077,Event,ADDED,eval-sanitize-10-r0-141.18d4e4c6f0163f4a,reason=SuccessfulCreate count=1 msg=Created pod: eval-sanitize-10-r0-141-hlg2l
0.3079,Event,ADDED,eval-sanitize-10-r0-141.18d4e4ccb7bdd5e9,reason=Completed count=1 msg=Job completed
0.308,Event,ADDED,eval-sanitize-10-r0-142-rz5nf.18d4e4c72c77f9a0,"reason=FailedScheduling count=None msg=0/6 nodes are available: 1 c_wall violated: 2 conflicting context pair(s) with node memory, 5 node(s) had untolerated taint(s). no new claims to deallocate, preemption: 0/6 nodes are available: 1 No preemption victims found for incoming pod, 5 Preemption is not helpful for scheduling."
0.3082,Event,ADDED,eval-sanitize-10-r0-142-rz5nf.18d4e4c72d19f16c,"reason=FailedScheduling count=None msg=0/6 nodes are available: 1 c_wall violated: 2 conflicting context pair(s) with node memory, 5 node(s) had untolerated taint(s). no new claims to deallocate, preemption: 0/6 nodes are available: 1 No preemption victims found for incoming pod, 5 Preemption is not helpful for scheduling."
0.3083,Event,ADDED,eval-sanitize-10-r0-142-rz5nf.18d4e4c929affcb0,"reason=FailedScheduling count=None msg=0/6 nodes are available: 1 c_wall violated: 1 conflicting context pair(s) with node memory, 5 node(s) had untolerated taint(s). no new claims to deallocate, preemption: 0/6 nodes are available: 1 No preemption victims found for incoming pod, 5 Preemption is not helpful for scheduling."
0.3085,Event,ADDED,eval-sanitize-10-r0-142-rz5nf.18d4e4c92fdbfe0a,"reason=FailedScheduling count=None msg=0/6 nodes are available: 1 c_wall violated: 1 conflicting context pair(s) with node memory, 5 node(s) had untolerated taint(s). no new claims to deallocate, preemption: 0/6 nodes are available: 1 No preemption victims found for incoming pod, 5 Preemption is not helpful for scheduling."
0.3087,Event,ADDED,eval-sanitize-10-r0-142-rz5nf.18d4e4cb8241d7df,reason=Scheduled count=None msg=Successfully assigned compute/eval-sanitize-10-r0-142-rz5nf to kind-worker
0.3088,Event,ADDED,eval-sanitize-10-r0-142-rz5nf.18d4e4cb9df024df,"reason=Pulled count=1 msg=Container image ""busybox:musl"" already present on machine"
0.309,Event,ADDED,eval-sanitize-10-r0-142-rz5nf.18d4e4cb9f9809ba,reason=Created count=1 msg=Created container: task
0.3092,Event,ADDED,eval-sanitize-10-r0-142-rz5nf.18d4e4cba3a98f23,reason=Started count=1 msg=Started container task
0.3093,Event,ADDED,eval-sanitize-10-r0-142.18d4e4c72c32c699,reason=SuccessfulCreate count=1 msg=Created pod: eval-sanitize-10-r0-142-rz5nf
0.3096,Event,ADDED,eval-sanitize-10-r0-142.18d4e4d11c369f13,reason=Completed count=1 msg=Job completed
0.3097,Event,ADDED,eval-sanitize-10-r0-143-l5t5t.18d4e4c7652b84f7,"reason=FailedScheduling count=None msg=0/6 nodes are available: 1 c_wall violated: 2 conflicting context pair(s) with node memory, 5 node(s) had untolerated taint(s). no new claims to deallocate, preemption: 0/6 nodes are available: 1 No preemption victims found for incoming pod, 5 Preemption is not helpful for scheduling."
0.3099,Event,ADDED,eval-sanitize-10-r0-143-l5t5t.18d4e4c765b1489f,"reason=FailedScheduling count=None msg=0/6 nodes are available: 1 c_wall violated: 2 conflicting context pair(s) with node memory, 5 node(s) had untolerated taint(s). no new claims to deallocate, preemption: 0/6 nodes are available: 1 No preemption victims found for incoming pod, 5 Preemption is not helpful for scheduling."
0.3101,Event,ADDED,eval-sanitize-10-r0-143-l5t5t.18d4e4c92f36efae,"reason=FailedScheduling count=None msg=0/6 nodes are available: 1 c_wall violated: 1 conflicting context pair(s) with node memory, 5 node(s) had untolerated taint(s). no new claims to deallocate, preemption: 0/6 nodes are available: 1 No preemption victims found for incoming pod, 5 Preemption is not helpful for scheduling."
0.3102,Event,ADDED,eval-sanitize-10-r0-143-l5t5t.18d4e4c93003d99c,"reason=FailedScheduling count=None msg=0/6 nodes are available: 1 c_wall violated: 1 conflicting context pair(s) with node memory, 5 node(s) had untolerated taint(s). no new claims to deallocate, preemption: 0/6 nodes are available: 1 No preemption victims found for incoming pod, 5 Preemption is not helpful for scheduling."
0.3104,Event,ADDED,eval-sanitize-10-r0-143-l5t5t.18d4e4cb7b8b53a4,reason=Scheduled count=None msg=Successfully assigned compute/eval-sanitize-10-r0-143-l5t5t to kind-worker
0.3106,Event,ADDED,eval-sanitize-10-r0-143-l5t5t.18d4e4cb96a4f040,"reason=Pulled count=1 msg=Container image ""busybox:musl"" already present on machine"
0.3107,Event,ADDED,eval-sanitize-10-r0-143-l5t5t.18d4e4cb98bdb7a5,reason=Created count=1 msg=Created container: task
0.3109,Event,ADDED,eval-sanitize-10-r0-143-l5t5t.18d4e4cba6c13f34,reason=Started count=1 msg=Started container task
0.3111,Event,ADDED,eval-sanitize-10-r0-143.18d4e4c764e33915,reason=SuccessfulCreate count=1 msg=Created pod: eval-sanitize-10-r0-143-l5t5t
0.3112,Event,ADDED,eval-sanitize-10-r0-143.18d4e4d11d415212,reason=Completed count=1 msg=Job completed
0.3114,Event,ADDED,eval-sanitize-10-r0-144-ct4nk.18d4e4c7a1fcac16,reason=Scheduled count=None msg=Successfully assigned compute/eval-sanitize-10-r0-144-ct4nk to kind-worker5
0.3115,Event,ADDED,eval-sanitize-10-r0-144-ct4nk.18d4e4c7bbf5819b,"reason=Pulled count=1 msg=Container image ""busybox:musl"" already present on machine"
0.3117,Event,ADDED,eval-sanitize-10-r0-144-ct4nk.18d4e4c7bd13dfa7,reason=Created count=1 msg=Created container: task
0.3119,Event,ADDED,eval-sanitize-10-r0-144-ct4nk.18d4e4c7c08d81f5,reason=Started count=1 msg=Started container task
0.312,Event,ADDED,eval-sanitize-10-r0-144.18d4e4c7a175c71b,reason=SuccessfulCreate count=1 msg=Created pod: eval-sanitize-10-r0-144-ct4nk
0.3122,Event,ADDED,eval-sanitize-10-r0-144.18d4e4cd22471f50,reason=Completed count=1 msg=Job completed
0.3123,Event,ADDED,eval-sanitize-10-r0-145-vtddj.18d4e4c7dc240b7c,"reason=FailedScheduling count=None msg=0/6 nodes are available: 1 c_wall violated: 2 conflicting context pair(s) with node memory, 5 node(s) had untolerated taint(s). no new claims to deallocate, preemption: 0/6 nodes are available: 1 No preemption victims found for incoming pod, 5 Preemption is not helpful for scheduling."
0.3125,Event,ADDED,eval-sanitize-10-r0-145-vtddj.18d4e4c7dcbb35ce,"reason=FailedScheduling count=None msg=0/6 nodes are available: 1 c_wall violated: 2 conflicting context pair(s) with node memory, 5 node(s) had untolerated taint(s). no new claims to deallocate, preemption: 0/6 nodes are available: 1 No preemption victims found for incoming pod, 5 Preemption is not helpful for scheduling."
0.3127,Event,ADDED,eval-sanitize-10-r0-145-vtddj.18d4e4c92598ce04,reason=Scheduled count=None msg=Successfully assigned compute/eval-sanitize-10-r0-145-vtddj to kind-worker3
0.3129,Event,ADDED,eval-sanitize-10-r0-145-vtddj.18d4e4c944559303,"reason=Pulled count=1 msg=Container image ""busybox:musl"" already present on machine"
0.3132,Event,ADDED,eval-sanitize-10-r0-145-vtddj.18d4e4c946971f3f,reason=Created count=1 msg=Created container: task
0.3133,Event,ADDED,eval-sanitize-10-r0-145-vtddj.18d4e4c954c3ee53,reason=Started count=1 msg=Started container task
0.3135,Event,ADDED,eval-sanitize-10-r0-145.18d4e4c7dbe0fec0,reason=SuccessfulCreate count=1 msg=Created pod: eval-sanitize-10-r0-145-vtddj
0.3137,Event,ADDED,eval-sanitize-10-r0-145.18d4e4cecb753fef,reason=Completed count=1 msg=Job completed
0.3139,Event,ADDED,eval-sanitize-10-r0-146-4w2vn.18d4e4c81838e597,"reason=FailedScheduling count=None msg=0/6 nodes are available: 1 c_wall violated: 1 conflicting context pair(s) with node memory, 5 node(s) had untolerated taint(s). no new claims to deallocate, preemption: 0/6 nodes are available: 1 No preemption victims found for incoming pod, 5 Preemption is not helpful for scheduling."
0.3141,Event,ADDED,eval-sanitize-10-r0-146-4w2vn.18d4e4c818ba8ac5,"reason=FailedScheduling count=None msg=0/6 nodes are available: 1 c_wall violated: 1 conflicting context pair(s) with node memory, 5 node(s) had untolerated taint(s). no new claims to deallocate, preemption: 0/6 nodes are available: 1 No preemption victims found for incoming pod, 5 Preemption is not helpful for scheduling."
0.3142,Event,ADDED,eval-sanitize-10-r0-146-4w2vn.18d4e4c926185cad,reason=Scheduled count=None msg=Successfully assigned compute/eval-sanitize-10-r0-146-4w2vn to kind-worker3
0.3144,Event,ADDED,eval-sanitize-10-r0-146-4w2vn.18d4e4c9447d00d1,"reason=Pulled count=1 msg=Container image ""busybox:musl"" already present on machine"
0.3146,Event,ADDED,eval-sanitize-10-r0-146-4w2vn.18d4e4c9478a2bb3,reason=Created count=1 msg=Created container: task
0.3148,Event,ADDED,eval-sanitize-10-r0-146-4w2vn.18d4e4c954c3d69c,reason=Started count=1 msg=Started container task
0.3149,Event,ADDED,eval-sanitize-10-r0-146.18d4e4c817f5a4fd,reason=SuccessfulCreate count=1 msg=Created pod: eval-sanitize-10-r0-146-4w2vn
0.3151,Event,ADDED,eval-sanitize-10-r0-146.18d4e4cecb964ca6,reason=Completed count=1 msg=Job completed
0.3152,Event,ADDED,eval-sanitize-10-r0-147-7kmjj.18d4e4c85413a151,reason=Scheduled count=None msg=Successfully assigned compute/eval-sanitize-10-r0-147-7kmjj to kind-worker5
0.3154,Event,ADDED,eval-sanitize-10-r0-147-7kmjj.18d4e4c86f33d4a7,"reason=Pulled count=1 msg=Container image ""busybox:musl"" already present on machine"
0.3156,Event,ADDED,eval-sanitize-10-r0-147-7kmjj.18d4e4c87050099b,reason=Created count=1 msg=Created container: task
0.3157,Event,ADDED,eval-sanitize-10-r0-147-7kmjj.18d4e4c8746c7970,reason=Started count=1 msg=Started container task
0.3159,Event,ADDED,eval-sanitize-10-r0-147.18d4e4c85380f0d1,reason=SuccessfulCreate count=1 msg=Created pod: eval-sanitize-10-r0-147-7kmjj
0.3161,Event,ADDED,eval-sanitize-10-r0-147.18d4e4cdd5065320,reason=Completed count=1 msg=Job completed
0.3162,Event,ADDED,eval-sanitize-10-r0-148-8hqrt.18d4e4c88f23bc25,"reason=FailedScheduling count=None msg=0/6 nodes are available: 1 c_wall violated: 2 conflicting context pair(s) with node memory, 5 node(s) had untolerated taint(s). no new claims to deallocate, preemption: 0/6 nodes are available: 1 No preemption victims found for incoming pod, 5 Preemption is not helpful for scheduling."
0.3164,Event,ADDED,eval-sanitize-10-r0-148-8hqrt.18d4e4c88fd18730,"reason=FailedScheduling count=None msg=0/6 nodes are available: 1 c_wall violated: 2 conflicting context pair(s) with node memory, 5 node(s) had untolerated taint(s). no new claims to deallocate, preemption: 0/6 nodes are available: 1 No preemption victims found for incoming pod, 5 Preemption is not helpful for scheduling."
0.3166,Event,ADDED,eval-sanitize-10-r0-148-8hqrt.18d4e4c92948ed55,reason=Scheduled count=None msg=Successfully assigned compute/eval-sanitize-10-r0-148-8hqrt to kind-worker3
0.3167,Event,ADDED,eval-sanitize-10-r0-148-8hqrt.18d4e4c944a5ae50,"reason=Pulled count=1 msg=Container image ""busybox:musl"" already present on machine"
0.3169,Event,ADDED,eval-sanitize-10-r0-148-8hqrt.18d4e4c947d27a73,reason=Created count=1 msg=Created container: task
0.3171,Event,ADDED,eval-sanitize-10-r0-148-8hqrt.18d4e4c954b5dc08,reason=Started count=1 msg=Started container task
0.3173,Event,ADDED,eval-sanitize-10-r0-148.18d4e4c88ee45150,reason=SuccessfulCreate count=1 msg=Created pod: eval-sanitize-10-r0-148-8hqrt
0.3175,Event,ADDED,eval-sanitize-10-r0-148.18d4e4cecb976a25,reason=Completed count=1 msg=Job completed
0.3176,Event,ADDED,eval-sanitize-10-r0-149-qtkdx.18d4e4c8cb1a93cd,"reason=FailedScheduling count=None msg=0/6 nodes are available: 1 c_wall violated: 1 conflicting context pair(s) with node memory, 5 node(s) had untolerated taint(s). no new claims to deallocate, preemption: 0/6 nodes are available: 1 No preemption victims found for incoming pod, 5 Preemption is not helpful for scheduling."
0.3178,Event,ADDED,eval-sanitize-10-r0-149-qtkdx.18d4e4c8cb8690b5,"reason=FailedScheduling count=None msg=0/6 nodes are available: 1 c_wall violated: 1 conflicting context pair(s) with node memory, 5 node(s) had untolerated taint(s). no new claims to deallocate, preemption: 0/6 nodes are available: 1 No preemption victims found for incoming pod, 5 Preemption is not helpful for scheduling."
0.3179,Event,ADDED,eval-sanitize-10-r0-149-qtkdx.18d4e4c9260a332f,"reason=FailedScheduling count=None msg=0/6 nodes are available: 1 c_wall violated: 1 conflicting context pair(s) with node memory, 5 node(s) had untolerated taint(s). no new claims to deallocate, preemption: 0/6 nodes are available: 1 No preemption victims found for incoming pod, 5 Preemption is not helpful for scheduling."
0.3181,Event,ADDED,eval-sanitize-10-r0-149-qtkdx.18d4e4c92fa8f229,"reason=FailedScheduling count=None msg=0/6 nodes are available: 1 c_wall violated: 1 conflicting context pair(s) with node memory, 5 node(s) had untolerated taint(s). no new claims to deallocate, preemption: 0/6 nodes are available: 1 No preemption victims found for incoming pod, 5 Preemption is not helpful for scheduling."
0.3183,Event,ADDED,eval-sanitize-10-r0-149-qtkdx.18d4e4cb881eb920,"reason=FailedScheduling count=None msg=0/6 nodes are available: 1 c_wall violated: 2 conflicting context pair(s) with node memory, 5 node(s) had untolerated taint(s). no new claims to deallocate, preemption: 0/6 nodes are available: 1 No preemption victims found for incoming pod, 5 Preemption is not helpful for scheduling."
0.3186,Event,ADDED,eval-sanitize-10-r0-149-qtkdx.18d4e4cb894a751c,"reason=FailedScheduling count=None msg=0/6 nodes are available: 1 c_wall violated: 2 conflicting context pair(s) with node memory, 5 node(s) had untolerated taint(s). no new claims to deallocate, preemption: 0/6 nodes are available: 1 No preemption victims found for incoming pod, 5 Preemption is not helpful for scheduling."
0.3188,Event,ADDED,eval-sanitize-10-r0-149-qtkdx.18d4e4cd96ba2aae,reason=Scheduled count=None msg=Successfully assigned compute/eval-sanitize-10-r0-149-qtkdx to kind-worker2
0.319,Event,ADDED,eval-sanitize-10-r0-149-qtkdx.18d4e4cdb1b71457,"reason=Pulled count=1 msg=Container image ""busybox:musl"" already present on machine"
0.3196,Event,ADDED,eval-sanitize-10-r0-149-qtkdx.18d4e4cdb35a1d0e,reason=Created count=1 msg=Created container: task
0.3198,Event,ADDED,eval-sanitize-10-r0-149-qtkdx.18d4e4cdb5570532,reason=Started count=1 msg=Started container task
0.32,Event,ADDED,eval-sanitize-10-r0-149.18d4e4c8cad706c8,reason=SuccessfulCreate count=1 msg=Created pod: eval-sanitize-10-r0-149-qtkdx
0.3202,Event,ADDED,eval-sanitize-10-r0-149.18d4e4d3aab97429,reason=Completed count=1 msg=Job completed
0.3206,Event,ADDED,eval-sanitize-10-r0-150-2jplz.18d4e4c9066968b3,"reason=FailedScheduling count=None msg=0/6 nodes are available: 1 c_wall violated: 2 conflicting context pair(s) with node memory, 5 node(s) had untolerated taint(s). no new claims to deallocate, preemption: 0/6 nodes are available: 1 No preemption victims found for incoming pod, 5 Preemption is not helpful for scheduling."
0.3208,Event,ADDED,eval-sanitize-10-r0-150-2jplz.18d4e4c907016a75,"reason=FailedScheduling count=None msg=0/6 nodes are available: 1 c_wall violated: 2 conflicting context pair(s) with node memory, 5 node(s) had untolerated taint(s). no new claims to deallocate, preemption: 0/6 nodes are available: 1 No preemption victims found for incoming pod, 5 Preemption is not helpful for scheduling."
0.3209,Event,ADDED,eval-sanitize-10-r0-150-2jplz.18d4e4c92d25dded,reason=Scheduled count=None msg=Successfully assigned compute/eval-sanitize-10-r0-150-2jplz to kind-worker3
0.3212,Event,ADDED,eval-sanitize-10-r0-150-2jplz.18d4e4c954b61dc0,"reason=Pulled count=1 msg=Container image ""busybox:musl"" already present on machine"
0.3214,Event,ADDED,eval-sanitize-10-r0-150-2jplz.18d4e4c9565f1558,reason=Created count=1 msg=Created container: task
0.3215,Event,ADDED,eval-sanitize-10-r0-150-2jplz.18d4e4c9620447b3,reason=Started count=1 msg=Started container task
0.3217,Event,ADDED,eval-sanitize-10-r0-150.18d4e4c9061e4e7a,reason=SuccessfulCreate count=1 msg=Created pod: eval-sanitize-10-r0-150-2jplz
0.3219,Event,ADDED,eval-sanitize-10-r0-150.18d4e4cecb4c01e9,reason=Completed count=1 msg=Job completed
0.322,Event,ADDED,eval-sanitize-10-r0-151-q2dpk.18d4e4c9462b0a77,"reason=FailedScheduling count=None msg=0/6 nodes are available: 1 c_wall violated: 1 conflicting context pair(s) with node memory, 5 node(s) had untolerated taint(s). no new claims to deallocate, preemption: 0/6 nodes are available: 1 No preemption victims found for incoming pod, 5 Preemption is not helpful for scheduling."
0.3222,Event,ADDED,eval-sanitize-10-r0-151-q2dpk.18d4e4c946f96bb6,"reason=FailedScheduling count=None msg=0/6 nodes are available: 1 c_wall violated: 1 conflicting context pair(s) with node memory, 5 node(s) had untolerated taint(s). no new claims to deallocate, preemption: 0/6 nodes are available: 1 No preemption victims found for incoming pod, 5 Preemption is not helpful for scheduling."
0.3224,Event,ADDED,eval-sanitize-10-r0-151-q2dpk.18d4e4cb833ea8bf,reason=Scheduled count=None msg=Successfully assigned compute/eval-sanitize-10-r0-151-q2dpk to kind-worker
0.3226,Event,ADDED,eval-sanitize-10-r0-151-q2dpk.18d4e4cb9e07d7ac,"reason=Pulled count=1 msg=Container image ""busybox:musl"" already present on machine"
0.3227,Event,ADDED,eval-sanitize-10-r0-151-q2dpk.18d4e4cba010f32f,reason=Created count=1 msg=Created container: task
0.3231,Event,ADDED,eval-sanitize-10-r0-151-q2dpk.18d4e4cba6c349c2,reason=Started count=1 msg=Started container task
0.3233,Event,ADDED,eval-sanitize-10-r0-151.18d4e4c945e99b46,reason=SuccessfulCreate count=1 msg=Created pod: eval-sanitize-10-r0-151-q2dpk
0.3234,Event,ADDED,eval-sanitize-10-r0-151.18d4e4d11cdbd603,reason=Completed count=1 msg=Job completed
0.3236,Event,ADDED,eval-sanitize-10-r0-152-tt4zb.18d4e4c991d5c407,"reason=FailedScheduling count=None msg=0/6 nodes are available: 1 c_wall violated: 1 conflicting context pair(s) with node memory, 5 node(s) had untolerated taint(s). no new claims to deallocate, preemption: 0/6 nodes are available: 1 No preemption victims found for incoming pod, 5 Preemption is not helpful for scheduling."
0.3238,Event,ADDED,eval-sanitize-10-r0-152-tt4zb.18d4e4c993b644ff,"reason=FailedScheduling count=None msg=0/6 nodes are available: 1 c_wall violated: 1 conflicting context pair(s) with node memory, 5 node(s) had untolerated taint(s). no new claims to deallocate, preemption: 0/6 nodes are available: 1 No preemption victims found for incoming pod, 5 Preemption is not helpful for scheduling."
0.324,Event,ADDED,eval-sanitize-10-r0-152-tt4zb.18d4e4cda07a8a51,"reason=FailedScheduling count=None msg=0/6 nodes are available: 2 c_wall violated: 1 conflicting context pair(s) with node memory, 4 node(s) had untolerated taint(s). no new claims to deallocate, preemption: 0/6 nodes are available: 2 No preemption victims found for incoming pod, 4 Preemption is not helpful for scheduling."
0.3242,Event,ADDED,eval-sanitize-10-r0-152-tt4zb.18d4e4cdd0d853de,"reason=FailedScheduling count=None msg=0/6 nodes are available: 1 c_wall violated: 1 conflicting context pair(s) with node memory, 5 node(s) had untolerated taint(s). no new claims to deallocate, preemption: 0/6 nodes are available: 1 No preemption victims found for incoming pod, 5 Preemption is not helpful for scheduling."
0.3243,Event,ADDED,eval-sanitize-10-r0-152-tt4zb.18d4e4cde9e57d6e,reason=Scheduled count=None msg=Successfully assigned compute/eval-sanitize-10-r0-152-tt4zb to kind-worker5
0.3245,Event,ADDED,eval-sanitize-10-r0-152-tt4zb.18d4e4ce0433a159,"reason=Pulled count=1 msg=Container image ""busybox:musl"" already present on machine"
0.3247,Event,ADDED,eval-sanitize-10-r0-152-tt4zb.18d4e4ce06ed1b01,reason=Created count=1 msg=Created container: task
0.3248,Event,ADDED,eval-sanitize-10-r0-152-tt4zb.18d4e4ce09793dc5,reason=Started count=1 msg=Started container task
0.325,Event,ADDED,eval-sanitize-10-r0-152.18d4e4c9919cf37a,reason=SuccessfulCreate count=1 msg=Created pod: eval-sanitize-10-r0-152-tt4zb
0.3253,Event,ADDED,eval-sanitize-10-r0-152.18d4e4d3b8537d93,reason=Completed count=1 msg=Job completed
0.3254,Event,ADDED,eval-sanitize-10-r0-153-2td89.18d4e4c9c8fd9efd,"reason=FailedScheduling count=None msg=0/6 nodes are available: 1 c_wall violated: 1 conflicting context pair(s) with node memory, 5 node(s) had untolerated taint(s). no new claims to deallocate, preemption: 0/6 nodes are available: 1 No preemption victims found for incoming pod, 5 Preemption is not helpful for scheduling."
0.3256,Event,ADDED,eval-sanitize-10-r0-153-2td89.18d4e4c9ca3936e0,"reason=FailedScheduling count=None msg=0/6 nodes are available: 1 c_wall violated: 1 conflicting context pair(s) with node memory, 5 node(s) had untolerated taint(s). no new claims to deallocate, preemption: 0/6 nodes are available: 1 No preemption victims found for incoming pod, 5 Preemption is not helpful for scheduling."
0.3258,Event,ADDED,eval-sanitize-10-r0-153-2td89.18d4e4cb88192a69,reason=Scheduled count=None msg=Successfully assigned compute/eval-sanitize-10-r0-153-2td89 to kind-worker
0.3259,Event,ADDED,eval-sanitize-10-r0-153-2td89.18d4e4cb9ffe6d59,"reason=Pulled count=1 msg=Container image ""busybox:musl"" already present on machine"
0.3262,Event,ADDED,eval-sanitize-10-r0-153-2td89.18d4e4cba1445a8d,reason=Created count=1 msg=Created container: task
0.3263,Event,ADDED,eval-sanitize-10-r0-153-2td89.18d4e4cba6c13f2b,reason=Started count=1 msg=Started container task
0.3265,Event,ADDED,eval-sanitize-10-r0-153.18d4e4c9c8182b72,reason=SuccessfulCreate count=1 msg=Created pod: eval-sanitize-10-r0-153-2td89
0.3267,Event,ADDED,eval-sanitize-10-r0-153.18d4e4d11ca4a707,reason=Completed count=1 msg=Job completed
0.3268,Event,ADDED,eval-sanitize-10-r0-154-59lsk.18d4e4c9fe4d5b82,reason=Scheduled count=None msg=Successfully assigned compute/eval-sanitize-10-r0-154-59lsk to kind-worker3
0.327,Event,ADDED,eval-sanitize-10-r0-154-59lsk.18d4e4ca1aa7a604,"reason=Pulled count=1 msg=Container image ""busybox:musl"" already present on machine"
0.3271,Event,ADDED,eval-sanitize-10-r0-154-59lsk.18d4e4ca1bd8b601,reason=Created count=1 msg=Created container: task
0.3273,Event,ADDED,eval-sanitize-10-r0-154-59lsk.18d4e4ca24acde86,reason=Started count=1 msg=Started container task
0.3275,Event,ADDED,eval-sanitize-10-r0-154.18d4e4c9fdd34ff1,reason=SuccessfulCreate count=1 msg=Created pod: eval-sanitize-10-r0-154-59lsk
0.3276,Event,ADDED,eval-sanitize-10-r0-154.18d4e4cfb5383930,reason=Completed count=1 msg=Job completed
0.3278,Event,ADDED,eval-sanitize-10-r0-155-c6bsd.18d4e4ca48a64470,reason=Scheduled count=None msg=Successfully assigned compute/eval-sanitize-10-r0-155-c6bsd to kind-worker3
0.328,Event,ADDED,eval-sanitize-10-r0-155-c6bsd.18d4e4ca6aac6fae,"reason=Pulled count=1 msg=Container image ""busybox:musl"" already present on machine"
0.3281,Event,ADDED,eval-sanitize-10-r0-155-c6bsd.18d4e4ca6c0896ed,reason=Created count=1 msg=Created container: task
0.3283,Event,ADDED,eval-sanitize-10-r0-155-c6bsd.18d4e4ca728d1bb4,reason=Started count=1 msg=Started container task
0.3284,Event,ADDED,eval-sanitize-10-r0-155.18d4e4ca4826fa08,reason=SuccessfulCreate count=1 msg=Created pod: eval-sanitize-10-r0-155-c6bsd
0.3286,Event,ADDED,eval-sanitize-10-r0-155.18d4e4cff207a961,reason=Completed count=1 msg=Job completed
0.3288,Event,ADDED,eval-sanitize-10-r0-156-5sqv4.18d4e4ca7b1eb3fe,"reason=FailedScheduling count=None msg=0/6 nodes are available: 1 c_wall violated: 1 conflicting context pair(s) with node memory, 5 node(s) had untolerated taint(s). no new claims to deallocate, preemption: 0/6 nodes are available: 1 No preemption victims found for incoming pod, 5 Preemption is not helpful for scheduling."
0.329,Event,ADDED,eval-sanitize-10-r0-156-5sqv4.18d4e4ca7b9f36a8,"reason=FailedScheduling count=None msg=0/6 nodes are available: 1 c_wall violated: 1 conflicting context pair(s) with node memory, 5 node(s) had untolerated taint(s). no new claims to deallocate, preemption: 0/6 nodes are available: 1 No preemption victims found for incoming pod, 5 Preemption is not helpful for scheduling."
0.3294,Event,ADDED,eval-sanitize-10-r0-156-5sqv4.18d4e4cb88a85d14,"reason=FailedScheduling count=None msg=0/6 nodes are available: 1 c_wall violated: 2 conflicting context pair(s) with node memory, 5 node(s) had untolerated taint(s). no new claims to deallocate, preemption: 0/6 nodes are available: 1 No preemption victims found for incoming pod, 5 Preemption is not helpful for scheduling."
0.3296,Event,ADDED,eval-sanitize-10-r0-156-5sqv4.18d4e4cb8cf5d540,"reason=FailedScheduling count=None msg=0/6 nodes are available: 1 c_wall violated: 2 conflicting context pair(s) with node memory, 5 node(s) had untolerated taint(s). no new claims to deallocate, preemption: 0/6 nodes are available: 1 No preemption victims found for incoming pod, 5 Preemption is not helpful for scheduling."
0.3297,Event,ADDED,eval-sanitize-10-r0-156-5sqv4.18d4e4cd94af020f,reason=Scheduled count=None msg=Successfully assigned compute/eval-sanitize-10-r0-156-5sqv4 to kind-worker2
0.3306,Event,ADDED,eval-sanitize-10-r0-156-5sqv4.18d4e4cdaf91b003,"reason=Pulled count=1 msg=Container image ""busybox:musl"" already present on machine"
0.3308,Event,ADDED,eval-sanitize-10-r0-156-5sqv4.18d4e4cdb1cf6e6f,reason=Created count=1 msg=Created container: task
0.331,Event,ADDED,eval-sanitize-10-r0-156-5sqv4.18d4e4cdb3f1a658,reason=Started count=1 msg=Started container task
0.3311,Event,ADDED,eval-sanitize-10-r0-156.18d4e4ca7ae1054f,reason=SuccessfulCreate count=1 msg=Created pod: eval-sanitize-10-r0-156-5sqv4
0.3314,Event,ADDED,eval-sanitize-10-r0-156.18d4e4d3adc0886f,reason=Completed count=1 msg=Job completed
0.3315,Event,ADDED,eval-sanitize-10-r0-157-v4946.18d4e4cab0e66062,reason=Scheduled count=None msg=Successfully assigned compute/eval-sanitize-10-r0-157-v4946 to kind-worker3
0.3317,Event,ADDED,eval-sanitize-10-r0-157-v4946.18d4e4cad1c51403,"reason=Pulled count=1 msg=Container image ""busybox:musl"" already present on machine"
0.3318,Event,ADDED,eval-sanitize-10-r0-157-v4946.18d4e4cad2f162cf,reason=Created count=1 msg=Created container: task
0.332,Event,ADDED,eval-sanitize-10-r0-157-v4946.18d4e4cadd9cc27c,reason=Started count=1 msg=Started container task
0.3322,Event,ADDED,eval-sanitize-10-r0-157.18d4e4caaf56b4d9,reason=SuccessfulCreate count=1 msg=Created pod: eval-sanitize-10-r0-157-v4946
0.3323,Event,ADDED,eval-sanitize-10-r0-157.18d4e4d06573915c,reason=Completed count=1 msg=Job completed
0.3325,Event,ADDED,eval-sanitize-10-r0-158-f9mtv.18d4e4cae622636c,"reason=FailedScheduling count=None msg=0/6 nodes are available: 1 c_wall violated: 3 conflicting context pair(s) with node memory, 5 node(s) had untolerated taint(s). no new claims to deallocate, preemption: 0/6 nodes are available: 1 No preemption victims found for incoming pod, 5 Preemption is not helpful for scheduling."
0.3326,Event,ADDED,eval-sanitize-10-r0-158-f9mtv.18d4e4cae6af203e,"reason=FailedScheduling count=None msg=0/6 nodes are available: 1 c_wall violated: 3 conflicting context pair(s) with node memory, 5 node(s) had untolerated taint(s). no new claims to deallocate, preemption: 0/6 nodes are available: 1 No preemption victims found for incoming pod, 5 Preemption is not helpful for scheduling."
0.3328,Event,ADDED,eval-sanitize-10-r0-158-f9mtv.18d4e4cb7ca71821,reason=Scheduled count=None msg=Successfully assigned compute/eval-sanitize-10-r0-158-f9mtv to kind-worker
0.333,Event,ADDED,eval-sanitize-10-r0-158-f9mtv.18d4e4cb99dd7405,"reason=Pulled count=1 msg=Container image ""busybox:musl"" already present on machine"
0.3331,Event,ADDED,eval-sanitize-10-r0-158-f9mtv.18d4e4cb9afac461,reason=Created count=1 msg=Created container: task
0.3333,Event,ADDED,eval-sanitize-10-r0-158-f9mtv.18d4e4cb9de12d82,reason=Started count=1 msg=Started container task
0.3335,Event,ADDED,eval-sanitize-10-r0-158.18d4e4cae5dec772,reason=SuccessfulCreate count=1 msg=Created pod: eval-sanitize-10-r0-158-f9mtv
0.3336,Event,ADDED,eval-sanitize-10-r0-158.18d4e4d11c6be593,reason=Completed count=1 msg=Job completed
0.3338,Event,ADDED,eval-sanitize-10-r0-159-29spj.18d4e4cb25091c03,reason=Scheduled count=None msg=Successfully assigned compute/eval-sanitize-10-r0-159-29spj to kind-worker3
0.3339,Event,ADDED,eval-sanitize-10-r0-159-29spj.18d4e4cb3e4ce782,"reason=Pulled count=1 msg=Container image ""busybox:musl"" already present on machine"
0.3341,Event,ADDED,eval-sanitize-10-r0-159-29spj.18d4e4cb3f7b8331,reason=Created count=1 msg=Created container: task
0.3343,Event,ADDED,eval-sanitize-10-r0-159-29spj.18d4e4cb43b4b90f,reason=Started count=1 msg=Started container task
0.3345,Event,ADDED,eval-sanitize-10-r0-159.18d4e4cb24838e15,reason=SuccessfulCreate count=1 msg=Created pod: eval-sanitize-10-r0-159-29spj
0.3347,Event,ADDED,eval-sanitize-10-r0-159.18d4e4d0a16b7c73,reason=Completed count=1 msg=Job completed
0.3349,Event,ADDED,eval-sanitize-10-r0-160-nv5cx.18d4e4cb5aae2dcb,reason=Scheduled count=None msg=Successfully assigned compute/eval-sanitize-10-r0-160-nv5cx to kind-worker3
0.335,Event,ADDED,eval-sanitize-10-r0-160-nv5cx.18d4e4cb759373b2,"reason=Pulled count=1 msg=Container image ""busybox:musl"" already present on machine"
0.3353,Event,ADDED,eval-sanitize-10-r0-160-nv5cx.18d4e4cb76ffbdb0,reason=Created count=1 msg=Created container: task
0.3354,Event,ADDED,eval-sanitize-10-r0-160-nv5cx.18d4e4cb7aa2fd72,reason=Started count=1 msg=Started container task
0.3358,Event,ADDED,eval-sanitize-10-r0-160.18d4e4cb5a343023,reason=SuccessfulCreate count=1 msg=Created pod: eval-sanitize-10-r0-160-nv5cx
0.336,Event,ADDED,eval-sanitize-10-r0-160.18d4e4d0dd406108,reason=Completed count=1 msg=Job completed
0.3361,Event,ADDED,eval-sanitize-10-r0-161-m59ts.18d4e4cb9768d6dc,"reason=FailedScheduling count=None msg=0/6 nodes are available: 1 c_wall violated: 3 conflicting context pair(s) with node memory, 5 node(s) had untolerated taint(s). no new claims to deallocate, preemption: 0/6 nodes are available: 1 No preemption victims found for incoming pod, 5 Preemption is not helpful for scheduling."
0.3364,Event,ADDED,eval-sanitize-10-r0-161-m59ts.18d4e4cb983ab6b5,"reason=FailedScheduling count=None msg=0/6 nodes are available: 1 c_wall violated: 3 conflicting context pair(s) with node memory, 5 node(s) had untolerated taint(s). no new claims to deallocate, preemption: 0/6 nodes are available: 1 No preemption victims found for incoming pod, 5 Preemption is not helpful for scheduling."
0.3365,Event,ADDED,eval-sanitize-10-r0-161-m59ts.18d4e4cd90aa61f4,reason=Scheduled count=None msg=Successfully assigned compute/eval-sanitize-10-r0-161-m59ts to kind-worker2
0.3367,Event,ADDED,eval-sanitize-10-r0-161-m59ts.18d4e4cdad4caf27,"reason=Pulled count=1 msg=Container image ""busybox:musl"" already present on machine"
0.3368,Event,ADDED,eval-sanitize-10-r0-161-m59ts.18d4e4cdb0a53796,reason=Created count=1 msg=Created container: task
0.337,Event,ADDED,eval-sanitize-10-r0-161-m59ts.18d4e4cdb3492afa,reason=Started count=1 msg=Started container task
0.3372,Event,ADDED,eval-sanitize-10-r0-161.18d4e4cb97252be8,reason=SuccessfulCreate count=1 msg=Created pod: eval-sanitize-10-r0-161-m59ts
0.3373,Event,ADDED,eval-sanitize-10-r0-161.18d4e4d31a55ccdd,reason=Completed count=1 msg=Job completed
0.3375,Event,ADDED,eval-sanitize-10-r0-162-wrs98.18d4e4cbd22ae94b,reason=Scheduled count=None msg=Successfully assigned compute/eval-sanitize-10-r0-162-wrs98 to kind-worker
0.3377,Event,ADDED,eval-sanitize-10-r0-162-wrs98.18d4e4cbeebfaef5,"reason=Pulled count=1 msg=Container image ""busybox:musl"" already present on machine"
0.3378,Event,ADDED,eval-sanitize-10-r0-162-wrs98.18d4e4cbefd248b0,reason=Created count=1 msg=Created container: task
0.338,Event,ADDED,eval-sanitize-10-r0-162-wrs98.18d4e4cbf1ad012e,reason=Started count=1 msg=Started container task
0.3382,Event,ADDED,eval-sanitize-10-r0-162.18d4e4cbd181c6ec,reason=SuccessfulCreate count=1 msg=Created pod: eval-sanitize-10-r0-162-wrs98
0.3383,Event,ADDED,eval-sanitize-10-r0-162.18d4e4d158d52562,reason=Completed count=1 msg=Job completed
0.3385,Event,ADDED,eval-sanitize-10-r0-163-9hk66.18d4e4cc0d6c9d31,"reason=FailedScheduling count=None msg=0/6 nodes are available: 1 c_wall violated: 3 conflicting context pair(s) with node memory, 5 node(s) had untolerated taint(s). no new claims to deallocate, preemption: 0/6 nodes are available: 1 No preemption victims found for incoming pod, 5 Preemption is not helpful for scheduling."
0.3387,Event,ADDED,eval-sanitize-10-r0-163-9hk66.18d4e4cc0e02d83f,"reason=FailedScheduling count=None msg=0/6 nodes are available: 1 c_wall violated: 3 conflicting context pair(s) with node memory, 5 node(s) had untolerated taint(s). no new claims to deallocate, preemption: 0/6 nodes are available: 1 No preemption victims found for incoming pod, 5 Preemption is not helpful for scheduling."
0.3389,Event,ADDED,eval-sanitize-10-r0-163-9hk66.18d4e4cda0c5d9a6,"reason=FailedScheduling count=None msg=0/6 nodes are available: 1 c_wall violated: 1 conflicting context pair(s) with node memory, 1 c_wall violated: 3 conflicting context pair(s) with node memory, 4 node(s) had untolerated taint(s). no new claims to deallocate, preemption: 0/6 nodes are available: 2 No preemption victims found for incoming pod, 4 Preemption is not helpful for scheduling."
0.339,Event,ADDED,eval-sanitize-10-r0-163-9hk66.18d4e4cdd105720d,"reason=FailedScheduling count=None msg=0/6 nodes are available: 1 c_wall violated: 1 conflicting context pair(s) with node memory, 5 node(s) had untolerated taint(s). no new claims to deallocate, preemption: 0/6 nodes are available: 1 No preemption victims found for incoming pod, 5 Preemption is not helpful for scheduling."
0.3392,Event,ADDED,eval-sanitize-10-r0-163-9hk66.18d4e4cdee322d86,reason=Scheduled count=None msg=Successfully assigned compute/eval-sanitize-10-r0-163-9hk66 to kind-worker5
0.3393,Event,ADDED,eval-sanitize-10-r0-163-9hk66.18d4e4ce0a0ae0c9,"reason=Pulled count=1 msg=Container image ""busybox:musl"" already present on machine"
0.3395,Event,ADDED,eval-sanitize-10-r0-163-9hk66.18d4e4ce0b815647,reason=Created count=1 msg=Created container: task
0.3397,Event,ADDED,eval-sanitize-10-r0-163-9hk66.18d4e4ce108b6ad1,reason=Started count=1 msg=Started container task
0.3399,Event,ADDED,eval-sanitize-10-r0-163.18d4e4cc0d2aa297,reason=SuccessfulCreate count=1 msg=Created pod: eval-sanitize-10-r0-163-9hk66
0.3402,Event,ADDED,eval-sanitize-10-r0-163.18d4e4d3f5762e7d,reason=Completed count=1 msg=Job completed
0.3404,Event,ADDED,eval-sanitize-10-r0-164-5sdz4.18d4e4cc4c0dab97,"reason=FailedScheduling count=None msg=0/6 nodes are available: 1 c_wall violated: 3 conflicting context pair(s) with node memory, 5 node(s) had untolerated taint(s). no new claims to deallocate, preemption: 0/6 nodes are available: 1 No preemption victims found for incoming pod, 5 Preemption is not helpful for scheduling."
0.341,Event,ADDED,eval-sanitize-10-r0-164-5sdz4.18d4e4cc4cdfe90a,"reason=FailedScheduling count=None msg=0/6 nodes are available: 1 c_wall violated: 3 conflicting context pair(s) with node memory, 5 node(s) had untolerated taint(s). no new claims to deallocate, preemption: 0/6 nodes are available: 1 No preemption victims found for incoming pod, 5 Preemption is not helpful for scheduling."
0.3413,Event,ADDED,eval-sanitize-10-r0-164-5sdz4.18d4e4cda532f014,"reason=FailedScheduling count=None msg=0/6 nodes are available: 1 c_wall violated: 1 conflicting context pair(s) with node memory, 1 c_wall violated: 3 conflicting context pair(s) with node memory, 4 node(s) had untolerated taint(s). no new claims to deallocate, preemption: 0/6 nodes are available: 2 No preemption victims found for incoming pod, 4 Preemption is not helpful for scheduling."
0.3415,Event,ADDED,eval-sanitize-10-r0-164-5sdz4.18d4e4cdd4f672f2,"reason=FailedScheduling count=None msg=0/6 nodes are available: 1 c_wall violated: 1 conflicting context pair(s) with node memory, 5 node(s) had untolerated taint(s). no new claims to deallocate, preemption: 0/6 nodes are available: 1 No preemption victims found for incoming pod, 5 Preemption is not helpful for scheduling."
0.3418,Event,ADDED,eval-sanitize-10-r0-164-5sdz4.18d4e4cde62a4ac9,reason=Scheduled count=None msg=Successfully assigned compute/eval-sanitize-10-r0-164-5sdz4 to kind-worker5
0.342,Event,ADDED,eval-sanitize-10-r0-164-5sdz4.18d4e4ce010c5322,"reason=Pulled count=1 msg=Container image ""busybox:musl"" already present on machine"
0.3422,Event,ADDED,eval-sanitize-10-r0-164-5sdz4.18d4e4ce02b73ba6,reason=Created count=1 msg=Created container: task
0.3423,Event,ADDED,eval-sanitize-10-r0-164-5sdz4.18d4e4ce07d8e4cf,reason=Started count=1 msg=Started container task
0.3426,Event,ADDED,eval-sanitize-10-r0-164.18d4e4cc4bceafa2,reason=SuccessfulCreate count=1 msg=Created pod: eval-sanitize-10-r0-164-5sdz4
0.3428,Event,ADDED,eval-sanitize-10-r0-164.18d4e4d338b4363d,reason=Completed count=1 msg=Job completed
0.343,Event,ADDED,eval-sanitize-10-r0-165-hgq4q.18d4e4cc8522445a,"reason=FailedScheduling count=None msg=0/6 nodes are available: 1 c_wall violated: 1 conflicting context pair(s) with node memory, 5 node(s) had untolerated taint(s). no new claims to deallocate, preemption: 0/6 nodes are available: 1 No preemption victims found for incoming pod, 5 Preemption is not helpful for scheduling."
0.3433,Event,ADDED,eval-sanitize-10-r0-165-hgq4q.18d4e4cc858a3593,"reason=FailedScheduling count=None msg=0/6 nodes are available: 1 c_wall violated: 1 conflicting context pair(s) with node memory, 5 node(s) had untolerated taint(s). no new claims to deallocate, preemption: 0/6 nodes are available: 1 No preemption victims found for incoming pod, 5 Preemption is not helpful for scheduling."
0.3435,Event,ADDED,eval-sanitize-10-r0-165-hgq4q.18d4e4cda63b4d80,"reason=FailedScheduling count=None msg=0/6 nodes are available: 2 c_wall violated: 1 conflicting context pair(s) with node memory, 4 node(s) had untolerated taint(s). no new claims to deallocate, preemption: 0/6 nodes are available: 2 No preemption victims found for incoming pod, 4 Preemption is not helpful for scheduling."
0.3437,Event,ADDED,eval-sanitize-10-r0-165-hgq4q.18d4e4cdd03c21f8,"reason=FailedScheduling count=None msg=0/6 nodes are available: 1 c_wall violated: 1 conflicting context pair(s) with node memory, 5 node(s) had untolerated taint(s). no new claims to deallocate, preemption: 0/6 nodes are available: 1 No preemption victims found for incoming pod, 5 Preemption is not helpful for scheduling."
0.344,Event,ADDED,eval-sanitize-10-r0-165-hgq4q.18d4e4cde688d988,reason=Scheduled count=None msg=Successfully assigned compute/eval-sanitize-10-r0-165-hgq4q to kind-worker5
0.3442,Event,ADDED,eval-sanitize-10-r0-165-hgq4q.18d4e4ce0127278b,"reason=Pulled count=1 msg=Container image ""busybox:musl"" already present on machine"
0.3443,Event,ADDED,eval-sanitize-10-r0-165-hgq4q.18d4e4ce036d647c,reason=Created count=1 msg=Created container: task
0.3445,Event,ADDED,eval-sanitize-10-r0-165-hgq4q.18d4e4ce09fa44d1,reason=Started count=1 msg=Started container task
0.3448,Event,ADDED,eval-sanitize-10-r0-165.18d4e4cc84e2721a,reason=SuccessfulCreate count=1 msg=Created pod: eval-sanitize-10-r0-165-hgq4q
0.345,Event,ADDED,eval-sanitize-10-r0-165.18d4e4d338b471db,reason=Completed count=1 msg=Job completed
0.3452,Event,ADDED,eval-sanitize-10-r0-166-5h8lj.18d4e4ccc5e58d5b,"reason=FailedScheduling count=None msg=0/6 nodes are available: 1 c_wall violated: 3 conflicting context pair(s) with node memory, 5 node(s) had untolerated taint(s). no new claims to deallocate, preemption: 0/6 nodes are available: 1 No preemption victims found for incoming pod, 5 Preemption is not helpful for scheduling."
0.3455,Event,ADDED,eval-sanitize-10-r0-166-5h8lj.18d4e4ccc65bc0dc,"reason=FailedScheduling count=None msg=0/6 nodes are available: 1 c_wall violated: 3 conflicting context pair(s) with node memory, 5 node(s) had untolerated taint(s). no new claims to deallocate, preemption: 0/6 nodes are available: 1 No preemption victims found for incoming pod, 5 Preemption is not helpful for scheduling."
0.3457,Event,ADDED,eval-sanitize-10-r0-166-5h8lj.18d4e4cd9bfbd97d,reason=Scheduled count=None msg=Successfully assigned compute/eval-sanitize-10-r0-166-5h8lj to kind-worker2
0.3459,Event,ADDED,eval-sanitize-10-r0-166-5h8lj.18d4e4cdb4ff7183,"reason=Pulled count=1 msg=Container image ""busybox:musl"" already present on machine"
0.346,Event,ADDED,eval-sanitize-10-r0-166-5h8lj.18d4e4cdb6190b7c,reason=Created count=1 msg=Created container: task
0.3463,Event,ADDED,eval-sanitize-10-r0-166-5h8lj.18d4e4cdb7e66bee,reason=Started count=1 msg=Started container task
0.3465,Event,ADDED,eval-sanitize-10-r0-166.18d4e4ccc595338d,reason=SuccessfulCreate count=1 msg=Created pod: eval-sanitize-10-r0-166-5h8lj
0.3467,Event,ADDED,eval-sanitize-10-r0-166.18d4e4d31a55cd2d,reason=Completed count=1 msg=Job completed
0.347,Event,ADDED,eval-sanitize-10-r0-167-f4l98.18d4e4ccfb7f39ee,"reason=FailedScheduling count=None msg=0/6 nodes are available: 1 c_wall violated: 3 conflicting context pair(s) with node memory, 5 node(s) had untolerated taint(s). no new claims to deallocate, preemption: 0/6 nodes are available: 1 No preemption victims found for incoming pod, 5 Preemption is not helpful for scheduling."
0.3472,Event,ADDED,eval-sanitize-10-r0-167-f4l98.18d4e4ccfbfc6664,"reason=FailedScheduling count=None msg=0/6 nodes are available: 1 c_wall violated: 3 conflicting context pair(s) with node memory, 5 node(s) had untolerated taint(s). no new claims to deallocate, preemption: 0/6 nodes are available: 1 No preemption victims found for incoming pod, 5 Preemption is not helpful for scheduling."
0.3474,Event,ADDED,eval-sanitize-10-r0-167-f4l98.18d4e4cd8f8b2215,reason=Scheduled count=None msg=Successfully assigned compute/eval-sanitize-10-r0-167-f4l98 to kind-worker2
0.3475,Event,ADDED,eval-sanitize-10-r0-167-f4l98.18d4e4cdaa0c1faf,"reason=Pulled count=1 msg=Container image ""busybox:musl"" already present on machine"
0.3479,Event,ADDED,eval-sanitize-10-r0-167-f4l98.18d4e4cdaef9f1b6,reason=Created count=1 msg=Created container: task
0.348,Event,ADDED,eval-sanitize-10-r0-167-f4l98.18d4e4cdb1aea034,reason=Started count=1 msg=Started container task
0.3482,Event,ADDED,eval-sanitize-10-r0-167.18d4e4ccfb39a0a4,reason=SuccessfulCreate count=1 msg=Created pod: eval-sanitize-10-r0-167-f4l98
0.3488,Event,ADDED,eval-sanitize-10-r0-167.18d4e4d31a960180,reason=Completed count=1 msg=Job completed
0.3489,Event,ADDED,eval-sanitize-10-r0-168-x98p7.18d4e4cd3724219f,"reason=FailedScheduling count=None msg=0/6 nodes are available: 1 c_wall violated: 3 conflicting context pair(s) with node memory, 5 node(s) had untolerated taint(s). no new claims to deallocate, preemption: 0/6 nodes are available: 1 No preemption victims found for incoming pod, 5 Preemption is not helpful for scheduling."
0.3491,Event,ADDED,eval-sanitize-10-r0-168-x98p7.18d4e4cd37b999ce,"reason=FailedScheduling count=None msg=0/6 nodes are available: 1 c_wall violated: 3 conflicting context pair(s) with node memory, 5 node(s) had untolerated taint(s). no new claims to deallocate, preemption: 0/6 nodes are available: 1 No preemption victims found for incoming pod, 5 Preemption is not helpful for scheduling."
0.3494,Event,ADDED,eval-sanitize-10-r0-168-x98p7.18d4e4cda02abf46,"reason=FailedScheduling count=None msg=0/6 nodes are available: 1 c_wall violated: 1 conflicting context pair(s) with node memory, 1 c_wall violated: 3 conflicting context pair(s) with node memory, 4 node(s) had untolerated taint(s). no new claims to deallocate, preemption: 0/6 nodes are available: 2 No preemption victims found for incoming pod, 4 Preemption is not helpful for scheduling."
0.3496,Event,ADDED,eval-sanitize-10-r0-168-x98p7.18d4e4cdd0691f75,"reason=FailedScheduling count=None msg=0/6 nodes are available: 1 c_wall violated: 1 conflicting context pair(s) with node memory, 5 node(s) had untolerated taint(s). no new claims to deallocate, preemption: 0/6 nodes are available: 1 No preemption victims found for incoming pod, 5 Preemption is not helpful for scheduling."
0.3497,Event,ADDED,eval-sanitize-10-r0-168-x98p7.18d4e4cde90f845c,reason=Scheduled count=None msg=Successfully assigned compute/eval-sanitize-10-r0-168-x98p7 to kind-worker5
0.3499,Event,ADDED,eval-sanitize-10-r0-168-x98p7.18d4e4ce01d88701,"reason=Pulled count=1 msg=Container image ""busybox:musl"" already present on machine"
0.3501,Event,ADDED,eval-sanitize-10-r0-168-x98p7.18d4e4ce04ef09c6,reason=Created count=1 msg=Created container: task
0.3503,Event,ADDED,eval-sanitize-10-r0-168-x98p7.18d4e4ce09f9dccf,reason=Started count=1 msg=Started container task
0.3504,Event,ADDED,eval-sanitize-10-r0-168.18d4e4cd36df0a0c,reason=SuccessfulCreate count=1 msg=Created pod: eval-sanitize-10-r0-168-x98p7
0.3506,Event,ADDED,eval-sanitize-10-r0-168.18d4e4d3c5ef1c9a,reason=Completed count=1 msg=Job completed
0.3508,Event,ADDED,eval-sanitize-10-r0-169-bm48v.18d4e4cd736c6ac8,"reason=FailedScheduling count=None msg=0/6 nodes are available: 1 c_wall violated: 3 conflicting context pair(s) with node memory, 5 node(s) had untolerated taint(s). no new claims to deallocate, preemption: 0/6 nodes are available: 1 No preemption victims found for incoming pod, 5 Preemption is not helpful for scheduling."
0.3509,Event,ADDED,eval-sanitize-10-r0-169-bm48v.18d4e4cd73e6439b,"reason=FailedScheduling count=None msg=0/6 nodes are available: 1 c_wall violated: 3 conflicting context pair(s) with node memory, 5 node(s) had untolerated taint(s). no new claims to deallocate, preemption: 0/6 nodes are available: 1 No preemption victims found for incoming pod, 5 Preemption is not helpful for scheduling."
0.3511,Event,ADDED,eval-sanitize-10-r0-169-bm48v.18d4e4cd90512b54,reason=Scheduled count=None msg=Successfully assigned compute/eval-sanitize-10-r0-169-bm48v to kind-worker2
0.3512,Event,ADDED,eval-sanitize-10-r0-169-bm48v.18d4e4cdab311714,"reason=Pulled count=1 msg=Container image ""busybox:musl"" already present on machine"
0.3514,Event,ADDED,eval-sanitize-10-r0-169-bm48v.18d4e4cdb07f9226,reason=Created count=1 msg=Created container: task
0.3515,Event,ADDED,eval-sanitize-10-r0-169-bm48v.18d4e4cdb3527e54,reason=Started count=1 msg=Started container task
0.3518,Event,ADDED,eval-sanitize-10-r0-169.18d4e4cd732fb995,reason=SuccessfulCreate count=1 msg=Created pod: eval-sanitize-10-r0-169-bm48v
0.352,Event,ADDED,eval-sanitize-10-r0-169.18d4e4d31b3c1167,reason=Completed count=1 msg=Job completed
0.3521,Event,ADDED,eval-sanitize-10-r0-170-tmb2g.18d4e4cdaffd1aff,"reason=FailedScheduling count=None msg=0/6 nodes are available: 1 c_wall violated: 1 conflicting context pair(s) with node memory, 1 c_wall violated: 3 conflicting context pair(s) with node memory, 4 node(s) had untolerated taint(s). no new claims to deallocate, preemption: 0/6 nodes are available: 2 No preemption victims found for incoming pod, 4 Preemption is not helpful for scheduling."
0.3523,Event,ADDED,eval-sanitize-10-r0-170-tmb2g.18d4e4cdb0d3d520,"reason=FailedScheduling count=None msg=0/6 nodes are available: 1 c_wall violated: 1 conflicting context pair(s) with node memory, 1 c_wall violated: 3 conflicting context pair(s) with node memory, 4 node(s) had untolerated taint(s). no new claims to deallocate, preemption: 0/6 nodes are available: 2 No preemption victims found for incoming pod, 4 Preemption is not helpful for scheduling."
0.3525,Event,ADDED,eval-sanitize-10-r0-170-tmb2g.18d4e4cdd0a99553,"reason=FailedScheduling count=None msg=0/6 nodes are available: 1 c_wall violated: 1 conflicting context pair(s) with node memory, 5 node(s) had untolerated taint(s). no new claims to deallocate, preemption: 0/6 nodes are available: 1 No preemption victims found for incoming pod, 5 Preemption is not helpful for scheduling."
0.3527,Event,ADDED,eval-sanitize-10-r0-170-tmb2g.18d4e4cde9589bc5,reason=Scheduled count=None msg=Successfully assigned compute/eval-sanitize-10-r0-170-tmb2g to kind-worker5
0.3529,Event,ADDED,eval-sanitize-10-r0-170-tmb2g.18d4e4ce040f464b,"reason=Pulled count=1 msg=Container image ""busybox:musl"" already present on machine"
0.353,Event,ADDED,eval-sanitize-10-r0-170-tmb2g.18d4e4ce06631ee4,reason=Created count=1 msg=Created container: task
0.3532,Event,ADDED,eval-sanitize-10-r0-170-tmb2g.18d4e4ce0911c690,reason=Started count=1 msg=Started container task
0.3534,Event,ADDED,eval-sanitize-10-r0-170.18d4e4cdaf86484f,reason=SuccessfulCreate count=1 msg=Created pod: eval-sanitize-10-r0-170-tmb2g
0.3535,Event,ADDED,eval-sanitize-10-r0-170.18d4e4d338c3cb43,reason=Completed count=1 msg=Job completed
0.3537,Event,ADDED,eval-sanitize-10-r0-171-fg6s8.18d4e4cdf093c6ba,reason=Scheduled count=None msg=Successfully assigned compute/eval-sanitize-10-r0-171-fg6s8 to kind-worker2
0.3539,Event,ADDED,eval-sanitize-10-r0-171-fg6s8.18d4e4ce0933c7ee,"reason=Pulled count=1 msg=Container image ""busybox:musl"" already present on machine"
0.354,Event,ADDED,eval-sanitize-10-r0-171-fg6s8.18d4e4ce0ad7bd6c,reason=Created count=1 msg=Created container: task
0.3542,Event,ADDED,eval-sanitize-10-r0-171-fg6s8.18d4e4ce108ec20f,reason=Started count=1 msg=Started container task
0.3545,Event,ADDED,eval-sanitize-10-r0-171.18d4e4cde98856e0,reason=SuccessfulCreate count=1 msg=Created pod: eval-sanitize-10-r0-171-fg6s8
0.3546,Event,ADDED,eval-sanitize-10-r0-171.18d4e4d3e651a0a5,reason=Completed count=1 msg=Job completed
0.3548,Event,ADDED,eval-sanitize-10-r0-172-db4r5.18d4e4ce25e3bf38,reason=Scheduled count=None msg=Successfully assigned compute/eval-sanitize-10-r0-172-db4r5 to kind-worker4
0.355,Event,ADDED,eval-sanitize-10-r0-172-db4r5.18d4e4ce420e8d3d,"reason=Pulled count=1 msg=Container image ""busybox:musl"" already present on machine"
0.3551,Event,ADDED,eval-sanitize-10-r0-172-db4r5.18d4e4ce433e39b6,reason=Created count=1 msg=Created container: task
0.3553,Event,ADDED,eval-sanitize-10-r0-172-db4r5.18d4e4ce45303aa3,reason=Started count=1 msg=Started container task
0.3555,Event,ADDED,eval-sanitize-10-r0-172.18d4e4ce2517e86d,reason=SuccessfulCreate count=1 msg=Created pod: eval-sanitize-10-r0-172-db4r5
0.3556,Event,ADDED,eval-sanitize-10-r0-172.18d4e4d412fc82e3,reason=Completed count=1 msg=Job completed
0.3558,Event,ADDED,eval-sanitize-10-r0-173-965h6.18d4e4ce6242d22d,reason=Scheduled count=None msg=Successfully assigned compute/eval-sanitize-10-r0-173-965h6 to kind-worker4
0.3559,Event,ADDED,eval-sanitize-10-r0-173-965h6.18d4e4ce7f013d64,"reason=Pulled count=1 msg=Container image ""busybox:musl"" already present on machine"
0.3561,Event,ADDED,eval-sanitize-10-r0-173-965h6.18d4e4ce804cd95f,reason=Created count=1 msg=Created container: task
0.3563,Event,ADDED,eval-sanitize-10-r0-173-965h6.18d4e4ce845b6bdf,reason=Started count=1 msg=Started container task
0.3564,Event,ADDED,eval-sanitize-10-r0-173.18d4e4ce60d0e438,reason=SuccessfulCreate count=1 msg=Created pod: eval-sanitize-10-r0-173-965h6
0.3566,Event,ADDED,eval-sanitize-10-r0-173.18d4e4d4110bb14b,reason=Completed count=1 msg=Job completed
0.3567,Event,ADDED,eval-sanitize-10-r0-174-rzbxj.18d4e4ce9e4a72dc,reason=Scheduled count=None msg=Successfully assigned compute/eval-sanitize-10-r0-174-rzbxj to kind-worker4
0.357,Event,ADDED,eval-sanitize-10-r0-174-rzbxj.18d4e4ceb9b8c78e,"reason=Pulled count=1 msg=Container image ""busybox:musl"" already present on machine"
0.3571,Event,ADDED,eval-sanitize-10-r0-174-rzbxj.18d4e4cebb1e015f,reason=Created count=1 msg=Created container: task
0.3573,Event,ADDED,eval-sanitize-10-r0-174-rzbxj.18d4e4cebe7bc841,reason=Started count=1 msg=Started container task
0.3575,Event,ADDED,eval-sanitize-10-r0-174.18d4e4ce9d1957a6,reason=SuccessfulCreate count=1 msg=Created pod: eval-sanitize-10-r0-174-rzbxj
0.3576,Event,ADDED,eval-sanitize-10-r0-174.18d4e4d441427ab5,reason=Completed count=1 msg=Job completed
0.3578,Event,ADDED,eval-sanitize-10-r0-175-wbh9v.18d4e4ced9318dc4,"reason=FailedScheduling count=None msg=0/6 nodes are available: 1 c_wall violated: 1 conflicting context pair(s) with node memory, 2 c_wall violated: 2 conflicting context pair(s) with node memory, 3 node(s) had untolerated taint(s). no new claims to deallocate, preemption: 0/6 nodes are available: 3 No preemption victims found for incoming pod, 3 Preemption is not helpful for scheduling."
0.358,Event,ADDED,eval-sanitize-10-r0-175-wbh9v.18d4e4cedce58c8f,"reason=FailedScheduling count=None msg=0/6 nodes are available: 1 c_wall violated: 1 conflicting context pair(s) with node memory, 2 c_wall violated: 2 conflicting context pair(s) with node memory, 3 node(s) had untolerated taint(s). no new claims to deallocate, preemption: 0/6 nodes are available: 3 No preemption victims found for incoming pod, 3 Preemption is not helpful for scheduling."
0.3582,Event,ADDED,eval-sanitize-10-r0-175-wbh9v.18d4e4cf1de16b1a,"reason=FailedScheduling count=None msg=0/6 nodes are available: 1 c_wall violated: 1 conflicting context pair(s) with node memory, 1 c_wall violated: 2 conflicting context pair(s) with node memory, 1 c_wall violated: 3 conflicting context pair(s) with node memory, 3 node(s) had untolerated taint(s). no new claims to deallocate, preemption: 0/6 nodes are available: 3 No preemption victims found for incoming pod, 3 Preemption is not helpful for scheduling."
0.3584,Event,ADDED,eval-sanitize-10-r0-175-wbh9v.18d4e4cfe69cd50d,"reason=FailedScheduling count=None msg=0/6 nodes are available: 1 c_wall violated: 2 conflicting context pair(s) with node memory, 1 c_wall violated: 3 conflicting context pair(s) with node memory, 4 node(s) had untolerated taint(s). no new claims to deallocate, preemption: 0/6 nodes are available: 2 No preemption victims found for incoming pod, 4 Preemption is not helpful for scheduling."
0.3586,Event,ADDED,eval-sanitize-10-r0-175-wbh9v.18d4e4d03b78eb9c,"reason=FailedScheduling count=None msg=0/6 nodes are available: 1 c_wall violated: 3 conflicting context pair(s) with node memory, 5 node(s) had untolerated taint(s). no new claims to deallocate, preemption: 0/6 nodes are available: 1 No preemption victims found for incoming pod, 5 Preemption is not helpful for scheduling."
0.3587,Event,ADDED,eval-sanitize-10-r0-175-wbh9v.18d4e4d2a4b37a89,reason=Scheduled count=None msg=Successfully assigned compute/eval-sanitize-10-r0-175-wbh9v to kind-worker
0.3589,Event,ADDED,eval-sanitize-10-r0-175-wbh9v.18d4e4d2bde95e6c,"reason=Pulled count=1 msg=Container image ""busybox:musl"" already present on machine"
0.3591,Event,ADDED,eval-sanitize-10-r0-175-wbh9v.18d4e4d2c0c64d61,reason=Created count=1 msg=Created container: task
0.3592,Event,ADDED,eval-sanitize-10-r0-175-wbh9v.18d4e4d2c5c9c1c5,reason=Started count=1 msg=Started container task
0.3594,Event,ADDED,eval-sanitize-10-r0-175.18d4e4ced86d9fda,reason=SuccessfulCreate count=1 msg=Created pod: eval-sanitize-10-r0-175-wbh9v
0.3596,Event,ADDED,eval-sanitize-10-r0-175.18d4e4d859b879d1,reason=Completed count=1 msg=Job completed
0.3597,Event,ADDED,eval-sanitize-10-r0-176-7s5qq.18d4e4cf15145549,reason=Scheduled count=None msg=Successfully assigned compute/eval-sanitize-10-r0-176-7s5qq to kind-worker4
0.3599,Event,ADDED,eval-sanitize-10-r0-176-7s5qq.18d4e4cf34786a60,"reason=Pulled count=1 msg=Container image ""busybox:musl"" already present on machine"
0.36,Event,ADDED,eval-sanitize-10-r0-176-7s5qq.18d4e4cf35b7f3c4,reason=Created count=1 msg=Created container: task
0.3602,Event,ADDED,eval-sanitize-10-r0-176-7s5qq.18d4e4cf37ff8148,reason=Started count=1 msg=Started container task
0.3604,Event,ADDED,eval-sanitize-10-r0-176.18d4e4cf13fe7274,reason=SuccessfulCreate count=1 msg=Created pod: eval-sanitize-10-r0-176-7s5qq
0.3605,Event,ADDED,eval-sanitize-10-r0-176.18d4e4d4b23e8afc,reason=Completed count=1 msg=Job completed
0.3607,Event,ADDED,eval-sanitize-10-r0-177-x6hfv.18d4e4cf589be91c,reason=Scheduled count=None msg=Successfully assigned compute/eval-sanitize-10-r0-177-x6hfv to kind-worker4
0.3608,Event,ADDED,eval-sanitize-10-r0-177-x6hfv.18d4e4cf7ed77ff7,"reason=Pulled count=1 msg=Container image ""busybox:musl"" already present on machine"
0.361,Event,ADDED,eval-sanitize-10-r0-177-x6hfv.18d4e4cf800c527b,reason=Created count=1 msg=Created container: task
0.3643,Event,ADDED,eval-sanitize-10-r0-177-x6hfv.18d4e4cf84ca7d3a,reason=Started count=1 msg=Started container task
0.3647,Event,ADDED,eval-sanitize-10-r0-177.18d4e4cf53927049,reason=SuccessfulCreate count=1 msg=Created pod: eval-sanitize-10-r0-177-x6hfv
0.3649,Event,ADDED,eval-sanitize-10-r0-177.18d4e4d4ee40cb4f,reason=Completed count=1 msg=Job completed
0.3651,Event,ADDED,eval-sanitize-10-r0-178-g72f5.18d4e4cf8c53a096,reason=Scheduled count=None msg=Successfully assigned compute/eval-sanitize-10-r0-178-g72f5 to kind-worker4
0.3652,Event,ADDED,eval-sanitize-10-r0-178-g72f5.18d4e4cfa6b9312e,"reason=Pulled count=1 msg=Container image ""busybox:musl"" already present on machine"
0.3656,Event,ADDED,eval-sanitize-10-r0-178-g72f5.18d4e4cfa7d6e9c3,reason=Created count=1 msg=Created container: task
0.3658,Event,ADDED,eval-sanitize-10-r0-178-g72f5.18d4e4cfac96e7a4,reason=Started count=1 msg=Started container task
0.366,Event,ADDED,eval-sanitize-10-r0-178.18d4e4cf8b5ec793,reason=SuccessfulCreate count=1 msg=Created pod: eval-sanitize-10-r0-178-g72f5
0.3662,Event,ADDED,eval-sanitize-10-r0-178.18d4e4d52a30edc3,reason=Completed count=1 msg=Job completed
0.3664,Event,ADDED,eval-sanitize-10-r0-179-lbp64.18d4e4cfc8174398,reason=Scheduled count=None msg=Successfully assigned compute/eval-sanitize-10-r0-179-lbp64 to kind-worker4
0.3665,Event,ADDED,eval-sanitize-10-r0-179-lbp64.18d4e4cfe22acce6,"reason=Pulled count=1 msg=Container image ""busybox:musl"" already present on machine"
0.3667,Event,ADDED,eval-sanitize-10-r0-179-lbp64.18d4e4cfe3439417,reason=Created count=1 msg=Created container: task
0.3669,Event,ADDED,eval-sanitize-10-r0-179-lbp64.18d4e4cfe54f4b3e,reason=Started count=1 msg=Started container task
0.367,Event,ADDED,eval-sanitize-10-r0-179.18d4e4cfc71a7bee,reason=SuccessfulCreate count=1 msg=Created pod: eval-sanitize-10-r0-179-lbp64
0.3672,Event,ADDED,eval-sanitize-10-r0-179.18d4e4d56633fdea,reason=Completed count=1 msg=Job completed
0.3674,Event,ADDED,eval-sanitize-10-r0-180-6h2lf.18d4e4d003ea7453,reason=Scheduled count=None msg=Successfully assigned compute/eval-sanitize-10-r0-180-6h2lf to kind-worker5
0.3675,Event,ADDED,eval-sanitize-10-r0-180-6h2lf.18d4e4d01e5fdf36,"reason=Pulled count=1 msg=Container image ""busybox:musl"" already present on machine"
0.3677,Event,ADDED,eval-sanitize-10-r0-180-6h2lf.18d4e4d01f721045,reason=Created count=1 msg=Created container: task
0.3679,Event,ADDED,eval-sanitize-10-r0-180-6h2lf.18d4e4d0217afade,reason=Started count=1 msg=Started container task
0.368,Event,ADDED,eval-sanitize-10-r0-180.18d4e4d0026047c6,reason=SuccessfulCreate count=1 msg=Created pod: eval-sanitize-10-r0-180-6h2lf
0.3682,Event,ADDED,eval-sanitize-10-r0-180.18d4e4d5924a2583,reason=Completed count=1 msg=Job completed
0.3683,Event,ADDED,eval-sanitize-10-r0-181-wdh4m.18d4e4d03e665259,reason=Scheduled count=None msg=Successfully assigned compute/eval-sanitize-10-r0-181-wdh4m to kind-worker4
0.3685,Event,ADDED,eval-sanitize-10-r0-181-wdh4m.18d4e4d05787adf4,"reason=Pulled count=1 msg=Container image ""busybox:musl"" already present on machine"
0.3687,Event,ADDED,eval-sanitize-10-r0-181-wdh4m.18d4e4d058ee22a3,reason=Created count=1 msg=Created container: task
0.3688,Event,ADDED,eval-sanitize-10-r0-181-wdh4m.18d4e4d05cef6766,reason=Started count=1 msg=Started container task
0.369,Event,ADDED,eval-sanitize-10-r0-181.18d4e4d03dc3eb9c,reason=SuccessfulCreate count=1 msg=Created pod: eval-sanitize-10-r0-181-wdh4m
0.3692,Event,ADDED,eval-sanitize-10-r0-181.18d4e4d5dc74d716,reason=Completed count=1 msg=Job completed
0.3693,Event,ADDED,eval-sanitize-10-r0-182-v6vt9.18d4e4d079ff7921,"reason=FailedScheduling count=None msg=0/6 nodes are available: 6 node(s) had untolerated taint(s). no new claims to deallocate, preemption: 0/6 nodes are available: 6 Preemption is not helpful for scheduling."
0.3695,Event,ADDED,eval-sanitize-10-r0-182-v6vt9.18d4e4d2a4f311ae,"reason=FailedScheduling count=None msg=0/6 nodes are available: 1 c_wall violated: 1 conflicting context pair(s) with node memory, 5 node(s) had untolerated taint(s). no new claims to deallocate, preemption: 0/6 nodes are available: 1 No preemption victims found for incoming pod, 5 Preemption is not helpful for scheduling."
0.3696,Event,ADDED,eval-sanitize-10-r0-182-v6vt9.18d4e4d2af3c6843,"reason=FailedScheduling count=None msg=0/6 nodes are available: 1 c_wall violated: 3 conflicting context pair(s) with node memory, 5 node(s) had untolerated taint(s). no new claims to deallocate, preemption: 0/6 nodes are available: 1 No preemption victims found for incoming pod, 5 Preemption is not helpful for scheduling."
0.3699,Event,ADDED,eval-sanitize-10-r0-182-v6vt9.18d4e4d2b7fd329a,"reason=FailedScheduling count=None msg=0/6 nodes are available: 1 c_wall violated: 3 conflicting context pair(s) with node memory, 5 node(s) had untolerated taint(s). no new claims to deallocate, preemption: 0/6 nodes are available: 1 No preemption victims found for incoming pod, 5 Preemption is not helpful for scheduling."
0.3701,Event,ADDED,eval-sanitize-10-r0-182-v6vt9.18d4e4d306b28e29,reason=Scheduled count=None msg=Successfully assigned compute/eval-sanitize-10-r0-182-v6vt9 to kind-worker3
0.3703,Event,ADDED,eval-sanitize-10-r0-182-v6vt9.18d4e4d31fd7d4ee,"reason=Pulled count=1 msg=Container image ""busybox:musl"" already present on machine"
0.3709,Event,ADDED,eval-sanitize-10-r0-182-v6vt9.18d4e4d321c426b3,reason=Created count=1 msg=Created container: task
0.3711,Event,ADDED,eval-sanitize-10-r0-182-v6vt9.18d4e4d32658e24f,reason=Started count=1 msg=Started container task
0.3713,Event,ADDED,eval-sanitize-10-r0-182.18d4e4d079f289de,reason=SuccessfulCreate count=1 msg=Created pod: eval-sanitize-10-r0-182-v6vt9
0.3715,Event,ADDED,eval-sanitize-10-r0-182.18d4e4d8948aee72,reason=Completed count=1 msg=Job completed
0.3718,Event,ADDED,eval-sanitize-10-r0-183-9c688.18d4e4d0b4cf6b68,"reason=FailedScheduling count=None msg=0/6 nodes are available: 6 node(s) had untolerated taint(s). no new claims to deallocate, preemption: 0/6 nodes are available: 6 Preemption is not helpful for scheduling."
0.372,Event,ADDED,eval-sanitize-10-r0-183-9c688.18d4e4d2a57e9fa1,"reason=FailedScheduling count=None msg=0/6 nodes are available: 1 c_wall violated: 1 conflicting context pair(s) with node memory, 5 node(s) had untolerated taint(s). no new claims to deallocate, preemption: 0/6 nodes are available: 1 No preemption victims found for incoming pod, 5 Preemption is not helpful for scheduling."
0.3722,Event,ADDED,eval-sanitize-10-r0-183-9c688.18d4e4d2b094a731,"reason=FailedScheduling count=None msg=0/6 nodes are available: 1 c_wall violated: 2 conflicting context pair(s) with node memory, 5 node(s) had untolerated taint(s). no new claims to deallocate, preemption: 0/6 nodes are available: 1 No preemption victims found for incoming pod, 5 Preemption is not helpful for scheduling."
0.3725,Event,ADDED,eval-sanitize-10-r0-183-9c688.18d4e4d2b9663732,"reason=FailedScheduling count=None msg=0/6 nodes are available: 1 c_wall violated: 2 conflicting context pair(s) with node memory, 5 node(s) had untolerated taint(s). no new claims to deallocate, preemption: 0/6 nodes are available: 1 No preemption victims found for incoming pod, 5 Preemption is not helpful for scheduling."
0.3727,Event,ADDED,eval-sanitize-10-r0-183-9c688.18d4e4d3140b36f7,"reason=FailedScheduling count=None msg=0/6 nodes are available: 1 c_wall violated: 2 conflicting context pair(s) with node memory, 1 c_wall violated: 3 conflicting context pair(s) with node memory, 4 node(s) had untolerated taint(s). no new claims to deallocate, preemption: 0/6 nodes are available: 2 No preemption victims found for incoming pod, 4 Preemption is not helpful for scheduling."
0.3729,Event,ADDED,eval-sanitize-10-r0-183-9c688.18d4e4d31e084556,"reason=FailedScheduling count=None msg=0/6 nodes are available: 1 c_wall violated: 2 conflicting context pair(s) with node memory, 1 c_wall violated: 3 conflicting context pair(s) with node memory, 4 node(s) had untolerated taint(s). no new claims to deallocate, preemption: 0/6 nodes are available: 2 No preemption victims found for incoming pod, 4 Preemption is not helpful for scheduling."
0.3731,Event,ADDED,eval-sanitize-10-r0-183-9c688.18d4e4d4a7c34140,reason=Scheduled count=None msg=Successfully assigned compute/eval-sanitize-10-r0-183-9c688 to kind-worker2
0.3733,Event,ADDED,eval-sanitize-10-r0-183-9c688.18d4e4d4c7c830bc,"reason=Pulled count=1 msg=Container image ""busybox:musl"" already present on machine"
0.3734,Event,ADDED,eval-sanitize-10-r0-183-9c688.18d4e4d4c9e43bc8,reason=Created count=1 msg=Created container: task
0.3736,Event,ADDED,eval-sanitize-10-r0-183-9c688.18d4e4d4d25b3542,reason=Started count=1 msg=Started container task
0.3738,Event,ADDED,eval-sanitize-10-r0-183.18d4e4d0b4c5012d,reason=SuccessfulCreate count=1 msg=Created pod: eval-sanitize-10-r0-183-9c688
0.3739,Event,ADDED,eval-sanitize-10-r0-183.18d4e4da56758ef5,reason=Completed count=1 msg=Job completed
0.3741,Event,ADDED,eval-sanitize-10-r0-184-58xv7.18d4e4d0f0e48da1,"reason=FailedScheduling count=None msg=0/6 nodes are available: 6 node(s) had untolerated taint(s). no new claims to deallocate, preemption: 0/6 nodes are available: 6 Preemption is not helpful for scheduling."
0.3742,Event,ADDED,eval-sanitize-10-r0-184-58xv7.18d4e4d2a6095fdf,"reason=FailedScheduling count=None msg=0/6 nodes are available: 1 c_wall violated: 1 conflicting context pair(s) with node memory, 5 node(s) had untolerated taint(s). no new claims to deallocate, preemption: 0/6 nodes are available: 1 No preemption victims found for incoming pod, 5 Preemption is not helpful for scheduling."
0.3744,Event,ADDED,eval-sanitize-10-r0-184-58xv7.18d4e4d2b4f07326,"reason=FailedScheduling count=None msg=0/6 nodes are available: 1 c_wall violated: 3 conflicting context pair(s) with node memory, 5 node(s) had untolerated taint(s). no new claims to deallocate, preemption: 0/6 nodes are available: 1 No preemption victims found for incoming pod, 5 Preemption is not helpful for scheduling."
0.3746,Event,ADDED,eval-sanitize-10-r0-184-58xv7.18d4e4d2b994bb97,"reason=FailedScheduling count=None msg=0/6 nodes are available: 1 c_wall violated: 3 conflicting context pair(s) with node memory, 5 node(s) had untolerated taint(s). no new claims to deallocate, preemption: 0/6 nodes are available: 1 No preemption victims found for incoming pod, 5 Preemption is not helpful for scheduling."
0.3747,Event,ADDED,eval-sanitize-10-r0-184-58xv7.18d4e4d307ddb54a,reason=Scheduled count=None msg=Successfully assigned compute/eval-sanitize-10-r0-184-58xv7 to kind-worker3
0.3749,Event,ADDED,eval-sanitize-10-r0-184-58xv7.18d4e4d320bb77f2,"reason=Pulled count=1 msg=Container image ""busybox:musl"" already present on machine"
0.3751,Event,ADDED,eval-sanitize-10-r0-184-58xv7.18d4e4d322c1f2ae,reason=Created count=1 msg=Created container: task
0.3752,Event,ADDED,eval-sanitize-10-r0-184-58xv7.18d4e4d326ccaf1a,reason=Started count=1 msg=Started container task
0.3755,Event,ADDED,eval-sanitize-10-r0-184.18d4e4d0f0d772aa,reason=SuccessfulCreate count=1 msg=Created pod: eval-sanitize-10-r0-184-58xv7
0.3757,Event,ADDED,eval-sanitize-10-r0-184.18d4e4d8948a1a6f,reason=Completed count=1 msg=Job completed
0.3758,Event,ADDED,eval-sanitize-10-r0-185-bxnrk.18d4e4d12caf5f2c,"reason=FailedScheduling count=None msg=0/6 nodes are available: 6 node(s) had untolerated taint(s). no new claims to deallocate, preemption: 0/6 nodes are available: 6 Preemption is not helpful for scheduling."
0.376,Event,ADDED,eval-sanitize-10-r0-185-bxnrk.18d4e4d2a69eaaf3,"reason=FailedScheduling count=None msg=0/6 nodes are available: 1 c_wall violated: 1 conflicting context pair(s) with node memory, 5 node(s) had untolerated taint(s). no new claims to deallocate, preemption: 0/6 nodes are available: 1 No preemption victims found for incoming pod, 5 Preemption is not helpful for scheduling."
0.3761,Event,ADDED,eval-sanitize-10-r0-185-bxnrk.18d4e4d2b612e5fe,"reason=FailedScheduling count=None msg=0/6 nodes are available: 1 c_wall violated: 2 conflicting context pair(s) with node memory, 5 node(s) had untolerated taint(s). no new claims to deallocate, preemption: 0/6 nodes are available: 1 No preemption victims found for incoming pod, 5 Preemption is not helpful for scheduling."
0.3764,Event,ADDED,eval-sanitize-10-r0-185-bxnrk.18d4e4d2bae2c909,"reason=FailedScheduling count=None msg=0/6 nodes are available: 1 c_wall violated: 2 conflicting context pair(s) with node memory, 5 node(s) had untolerated taint(s). no new claims to deallocate, preemption: 0/6 nodes are available: 1 No preemption victims found for incoming pod, 5 Preemption is not helpful for scheduling."
0.3767,Event,ADDED,eval-sanitize-10-r0-185-bxnrk.18d4e4d31820b137,"reason=FailedScheduling count=None msg=0/6 nodes are available: 2 c_wall violated: 2 conflicting context pair(s) with node memory, 4 node(s) had untolerated taint(s). no new claims to deallocate, preemption: 0/6 nodes are available: 2 No preemption victims found for incoming pod, 4 Preemption is not helpful for scheduling."
0.3769,Event,ADDED,eval-sanitize-10-r0-185-bxnrk.18d4e4d4a8a32bd5,reason=Scheduled count=None msg=Successfully assigned compute/eval-sanitize-10-r0-185-bxnrk to kind-worker2
0.3772,Event,ADDED,eval-sanitize-10-r0-185-bxnrk.18d4e4d4c7dc6f2c,"reason=Pulled count=1 msg=Container image ""busybox:musl"" already present on machine"
0.3774,Event,ADDED,eval-sanitize-10-r0-185-bxnrk.18d4e4d4ca16b0e7,reason=Created count=1 msg=Created container: task
0.3776,Event,ADDED,eval-sanitize-10-r0-185-bxnrk.18d4e4d4d25b4802,reason=Started count=1 msg=Started container task
0.3777,Event,ADDED,eval-sanitize-10-r0-185.18d4e4d12c9d41bc,reason=SuccessfulCreate count=1 msg=Created pod: eval-sanitize-10-r0-185-bxnrk
0.3779,Event,ADDED,eval-sanitize-10-r0-185.18d4e4da56e2f92e,reason=Completed count=1 msg=Job completed
0.3781,Event,ADDED,eval-sanitize-10-r0-186-zmrvh.18d4e4d168525ed4,"reason=FailedScheduling count=None msg=0/6 nodes are available: 6 node(s) had untolerated taint(s). no new claims to deallocate, preemption: 0/6 nodes are available: 6 Preemption is not helpful for scheduling."
0.3782,Event,ADDED,eval-sanitize-10-r0-186-zmrvh.18d4e4d2a97db324,"reason=FailedScheduling count=None msg=0/6 nodes are available: 1 c_wall violated: 1 conflicting context pair(s) with node memory, 5 node(s) had untolerated taint(s). no new claims to deallocate, preemption: 0/6 nodes are available: 1 No preemption victims found for incoming pod, 5 Preemption is not helpful for scheduling."
0.3786,Event,ADDED,eval-sanitize-10-r0-186-zmrvh.18d4e4d2b69216bc,"reason=FailedScheduling count=None msg=0/6 nodes are available: 1 c_wall violated: 3 conflicting context pair(s) with node memory, 5 node(s) had untolerated taint(s). no new claims to deallocate, preemption: 0/6 nodes are available: 1 No preemption victims found for incoming pod, 5 Preemption is not helpful for scheduling."
0.3788,Event,ADDED,eval-sanitize-10-r0-186-zmrvh.18d4e4d2bb1a6b65,"reason=FailedScheduling count=None msg=0/6 nodes are available: 1 c_wall violated: 3 conflicting context pair(s) with node memory, 5 node(s) had untolerated taint(s). no new claims to deallocate, preemption: 0/6 nodes are available: 1 No preemption victims found for incoming pod, 5 Preemption is not helpful for scheduling."
0.379,Event,ADDED,eval-sanitize-10-r0-186-zmrvh.18d4e4d312e1016d,reason=Scheduled count=None msg=Successfully assigned compute/eval-sanitize-10-r0-186-zmrvh to kind-worker3
0.3792,Event,ADDED,eval-sanitize-10-r0-186-zmrvh.18d4e4d32a197028,"reason=Pulled count=1 msg=Container image ""busybox:musl"" already present on machine"
0.3793,Event,ADDED,eval-sanitize-10-r0-186-zmrvh.18d4e4d32b7a7480,reason=Created count=1 msg=Created container: task
0.3795,Event,ADDED,eval-sanitize-10-r0-186-zmrvh.18d4e4d32d67a3cb,reason=Started count=1 msg=Started container task
0.3797,Event,ADDED,eval-sanitize-10-r0-186.18d4e4d168450fa7,reason=SuccessfulCreate count=1 msg=Created pod: eval-sanitize-10-r0-186-zmrvh
0.3798,Event,ADDED,eval-sanitize-10-r0-186.18d4e4d89435fdaa,reason=Completed count=1 msg=Job completed
0.38,Event,ADDED,eval-sanitize-10-r0-187-gwj6l.18d4e4d1a3afba41,"reason=FailedScheduling count=None msg=0/6 nodes are available: 6 node(s) had untolerated taint(s). no new claims to deallocate, preemption: 0/6 nodes are available: 6 Preemption is not helpful for scheduling."
0.3801,Event,ADDED,eval-sanitize-10-r0-187-gwj6l.18d4e4d2aa5fda50,reason=Scheduled count=None msg=Successfully assigned compute/eval-sanitize-10-r0-187-gwj6l to kind-worker
0.3803,Event,ADDED,eval-sanitize-10-r0-187-gwj6l.18d4e4d2c5d18148,"reason=Pulled count=1 msg=Container image ""busybox:musl"" already present on machine"
0.3805,Event,ADDED,eval-sanitize-10-r0-187-gwj6l.18d4e4d2c78dd8d1,reason=Created count=1 msg=Created container: task
0.3807,Event,ADDED,eval-sanitize-10-r0-187-gwj6l.18d4e4d2cb81b580,reason=Started count=1 msg=Started container task
0.3808,Event,ADDED,eval-sanitize-10-r0-187.18d4e4d1a3a770c1,reason=SuccessfulCreate count=1 msg=Created pod: eval-sanitize-10-r0-187-gwj6l
0.381,Event,ADDED,eval-sanitize-10-r0-187.18d4e4d85998d8d5,reason=Completed count=1 msg=Job completed
0.3812,Event,ADDED,eval-sanitize-10-r0-188-hlfkl.18d4e4d1df4f04d9,"reason=FailedScheduling count=None msg=0/6 nodes are available: 6 node(s) had untolerated taint(s). no new claims to deallocate, preemption: 0/6 nodes are available: 6 Preemption is not helpful for scheduling."
0.3813,Event,ADDED,eval-sanitize-10-r0-188-hlfkl.18d4e4d2aa4a7469,"reason=FailedScheduling count=None msg=0/6 nodes are available: 1 c_wall violated: 1 conflicting context pair(s) with node memory, 5 node(s) had untolerated taint(s). no new claims to deallocate, preemption: 0/6 nodes are available: 1 No preemption victims found for incoming pod, 5 Preemption is not helpful for scheduling."
0.3815,Event,ADDED,eval-sanitize-10-r0-188-hlfkl.18d4e4d2b70a66c7,"reason=FailedScheduling count=None msg=0/6 nodes are available: 1 c_wall violated: 2 conflicting context pair(s) with node memory, 5 node(s) had untolerated taint(s). no new claims to deallocate, preemption: 0/6 nodes are available: 1 No preemption victims found for incoming pod, 5 Preemption is not helpful for scheduling."
0.3816,Event,ADDED,eval-sanitize-10-r0-188-hlfkl.18d4e4d2bb528f23,"reason=FailedScheduling count=None msg=0/6 nodes are available: 1 c_wall violated: 2 conflicting context pair(s) with node memory, 5 node(s) had untolerated taint(s). no new claims to deallocate, preemption: 0/6 nodes are available: 1 No preemption victims found for incoming pod, 5 Preemption is not helpful for scheduling."
0.3818,Event,ADDED,eval-sanitize-10-r0-188-hlfkl.18d4e4d318db0237,"reason=FailedScheduling count=None msg=0/6 nodes are available: 1 c_wall violated: 2 conflicting context pair(s) with node memory, 1 c_wall violated: 3 conflicting context pair(s) with node memory, 4 node(s) had untolerated taint(s). no new claims to deallocate, preemption: 0/6 nodes are available: 2 No preemption victims found for incoming pod, 4 Preemption is not helpful for scheduling."
0.382,Event,ADDED,eval-sanitize-10-r0-188-hlfkl.18d4e4d4b1a37d17,reason=Scheduled count=None msg=Successfully assigned compute/eval-sanitize-10-r0-188-hlfkl to kind-worker2
0.3821,Event,ADDED,eval-sanitize-10-r0-188-hlfkl.18d4e4d4d1dd984d,"reason=Pulled count=1 msg=Container image ""busybox:musl"" already present on machine"
0.3823,Event,ADDED,eval-sanitize-10-r0-188-hlfkl.18d4e4d4d36cb3e3,reason=Created count=1 msg=Created container: task
0.3825,Event,ADDED,eval-sanitize-10-r0-188-hlfkl.18d4e4d4dc476389,reason=Started count=1 msg=Started container task
0.3826,Event,ADDED,eval-sanitize-10-r0-188.18d4e4d1df470d96,reason=SuccessfulCreate count=1 msg=Created pod: eval-sanitize-10-r0-188-hlfkl
0.3828,Event,ADDED,eval-sanitize-10-r0-188.18d4e4da57a7af13,reason=Completed count=1 msg=Job completed
0.3829,Event,ADDED,eval-sanitize-10-r0-189-vdz5x.18d4e4d21b01db8a,"reason=FailedScheduling count=None msg=0/6 nodes are available: 6 node(s) had untolerated taint(s). no new claims to deallocate, preemption: 0/6 nodes are available: 6 Preemption is not helpful for scheduling."
0.3831,Event,ADDED,eval-sanitize-10-r0-189-vdz5x.18d4e4d2ab5769dd,reason=Scheduled count=None msg=Successfully assigned compute/eval-sanitize-10-r0-189-vdz5x to kind-worker
0.3833,Event,ADDED,eval-sanitize-10-r0-189-vdz5x.18d4e4d2c5e6e955,"reason=Pulled count=1 msg=Container image ""busybox:musl"" already present on machine"
0.3834,Event,ADDED,eval-sanitize-10-r0-189-vdz5x.18d4e4d2c7ef441d,reason=Created count=1 msg=Created container: task
0.3836,Event,ADDED,eval-sanitize-10-r0-189-vdz5x.18d4e4d2cbae03d2,reason=Started count=1 msg=Started container task
0.3837,Event,ADDED,eval-sanitize-10-r0-189.18d4e4d21af50b1d,reason=SuccessfulCreate count=1 msg=Created pod: eval-sanitize-10-r0-189-vdz5x
0.3839,Event,ADDED,eval-sanitize-10-r0-189.18d4e4d863a1e6fd,reason=Completed count=1 msg=Job completed
0.384,Event,ADDED,eval-sanitize-10-r0-190-rsqpx.18d4e4d25686fa13,"reason=FailedScheduling count=None msg=0/6 nodes are available: 6 node(s) had untolerated taint(s). no new claims to deallocate, preemption: 0/6 nodes are available: 6 Preemption is not helpful for scheduling."
0.3842,Event,ADDED,eval-sanitize-10-r0-190-rsqpx.18d4e4d2aefcba45,reason=Scheduled count=None msg=Successfully assigned compute/eval-sanitize-10-r0-190-rsqpx to kind-worker
0.3844,Event,ADDED,eval-sanitize-10-r0-190-rsqpx.18d4e4d2c5ff5421,"reason=Pulled count=1 msg=Container image ""busybox:musl"" already present on machine"
0.3845,Event,ADDED,eval-sanitize-10-r0-190-rsqpx.18d4e4d2c82e458e,reason=Created count=1 msg=Created container: task
0.3847,Event,ADDED,eval-sanitize-10-r0-190-rsqpx.18d4e4d2cbe85c33,reason=Started count=1 msg=Started container task
0.3849,Event,ADDED,eval-sanitize-10-r0-190.18d4e4d2567ccf94,reason=SuccessfulCreate count=1 msg=Created pod: eval-sanitize-10-r0-190-rsqpx
0.3851,Event,ADDED,eval-sanitize-10-r0-190.18d4e4d863bf6735,reason=Completed count=1 msg=Job completed
0.3852,Event,ADDED,eval-sanitize-10-r0-191-jqnzd.18d4e4d2922b434b,"reason=FailedScheduling count=None msg=0/6 nodes are available: 6 node(s) had untolerated taint(s). no new claims to deallocate, preemption: 0/6 nodes are available: 6 Preemption is not helpful for scheduling."
0.3854,Event,ADDED,eval-sanitize-10-r0-191-jqnzd.18d4e4d2ab5e53ea,"reason=FailedScheduling count=None msg=0/6 nodes are available: 1 c_wall violated: 2 conflicting context pair(s) with node memory, 5 node(s) had untolerated taint(s). no new claims to deallocate, preemption: 0/6 nodes are available: 1 No preemption victims found for incoming pod, 5 Preemption is not helpful for scheduling."
0.3856,Event,ADDED,eval-sanitize-10-r0-191-jqnzd.18d4e4d2b7afed33,"reason=FailedScheduling count=None msg=0/6 nodes are available: 1 c_wall violated: 2 conflicting context pair(s) with node memory, 5 node(s) had untolerated taint(s). no new claims to deallocate, preemption: 0/6 nodes are available: 1 No preemption victims found for incoming pod, 5 Preemption is not helpful for scheduling."
0.3858,Event,ADDED,eval-sanitize-10-r0-191-jqnzd.18d4e4d31948e0dc,"reason=FailedScheduling count=None msg=0/6 nodes are available: 1 c_wall violated: 1 conflicting context pair(s) with node memory, 1 c_wall violated: 2 conflicting context pair(s) with node memory, 4 node(s) had untolerated taint(s). no new claims to deallocate, preemption: 0/6 nodes are available: 2 No preemption victims found for incoming pod, 4 Preemption is not helpful for scheduling."
0.386,Event,ADDED,eval-sanitize-10-r0-191-jqnzd.18d4e4d4bf01249f,"reason=FailedScheduling count=None msg=0/6 nodes are available: 1 c_wall violated: 2 conflicting context pair(s) with node memory, 2 c_wall violated: 1 conflicting context pair(s) with node memory, 3 node(s) had untolerated taint(s). no new claims to deallocate, preemption: 0/6 nodes are available: 3 No preemption victims found for incoming pod, 3 Preemption is not helpful for scheduling."
0.3862,Event,ADDED,eval-sanitize-10-r0-191-jqnzd.18d4e4d50cd53ff0,"reason=FailedScheduling count=None msg=0/6 nodes are available: 2 c_wall violated: 1 conflicting context pair(s) with node memory, 4 node(s) had untolerated taint(s). no new claims to deallocate, preemption: 0/6 nodes are available: 2 No preemption victims found for incoming pod, 4 Preemption is not helpful for scheduling."
0.3864,Event,ADDED,eval-sanitize-10-r0-191-jqnzd.18d4e4d530ab4a94,reason=Scheduled count=None msg=Successfully assigned compute/eval-sanitize-10-r0-191-jqnzd to kind-worker5
0.3865,Event,ADDED,eval-sanitize-10-r0-191-jqnzd.18d4e4d5492429f1,"reason=Pulled count=1 msg=Container image ""busybox:musl"" already present on machine"
0.3867,Event,ADDED,eval-sanitize-10-r0-191-jqnzd.18d4e4d54a28f4f9,reason=Created count=1 msg=Created container: task
0.3869,Event,ADDED,eval-sanitize-10-r0-191-jqnzd.18d4e4d54e9a0fae,reason=Started count=1 msg=Started container task
0.387,Event,ADDED,eval-sanitize-10-r0-191.18d4e4d292219d53,reason=SuccessfulCreate count=1 msg=Created pod: eval-sanitize-10-r0-191-jqnzd
0.3872,Event,ADDED,eval-sanitize-10-r0-191.18d4e4daae31d7c2,reason=Completed count=1 msg=Job completed
0.3874,Event,ADDED,eval-sanitize-10-r0-192-gfvzq.18d4e4d2ce90e4a5,"reason=FailedScheduling count=None msg=0/6 nodes are available: 1 c_wall violated: 2 conflicting context pair(s) with node memory, 5 node(s) had untolerated taint(s). no new claims to deallocate, preemption: 0/6 nodes are available: 1 No preemption victims found for incoming pod, 5 Preemption is not helpful for scheduling."
0.3875,Event,ADDED,eval-sanitize-10-r0-192-gfvzq.18d4e4d2cf121672,"reason=FailedScheduling count=None msg=0/6 nodes are available: 1 c_wall violated: 2 conflicting context pair(s) with node memory, 5 node(s) had untolerated taint(s). no new claims to deallocate, preemption: 0/6 nodes are available: 1 No preemption victims found for incoming pod, 5 Preemption is not helpful for scheduling."
0.3877,Event,ADDED,eval-sanitize-10-r0-192-gfvzq.18d4e4d30da59b04,reason=Scheduled count=None msg=Successfully assigned compute/eval-sanitize-10-r0-192-gfvzq to kind-worker3
0.3879,Event,ADDED,eval-sanitize-10-r0-192-gfvzq.18d4e4d327af8953,"reason=Pulled count=1 msg=Container image ""busybox:musl"" already present on machine"
0.3881,Event,ADDED,eval-sanitize-10-r0-192-gfvzq.18d4e4d3292969af,reason=Created count=1 msg=Created container: task
0.3882,Event,ADDED,eval-sanitize-10-r0-192-gfvzq.18d4e4d32b7d5116,reason=Started count=1 msg=Started container task
0.3884,Event,ADDED,eval-sanitize-10-r0-192.18d4e4d2ce52f82c,reason=SuccessfulCreate count=1 msg=Created pod: eval-sanitize-10-r0-192-gfvzq
0.3886,Event,ADDED,eval-sanitize-10-r0-192.18d4e4d8945d9ed4,reason=Completed count=1 msg=Job completed
0.3887,Event,ADDED,eval-sanitize-10-r0-193-4x9j5.18d4e4d30dccc053,reason=Scheduled count=None msg=Successfully assigned compute/eval-sanitize-10-r0-193-4x9j5 to kind-worker3
0.3889,Event,ADDED,eval-sanitize-10-r0-193-4x9j5.18d4e4d327c2a750,"reason=Pulled count=1 msg=Container image ""busybox:musl"" already present on machine"
0.3891,Event,ADDED,eval-sanitize-10-r0-193-4x9j5.18d4e4d329891277,reason=Created count=1 msg=Created container: task
0.3893,Event,ADDED,eval-sanitize-10-r0-193-4x9j5.18d4e4d32be1eb5d,reason=Started count=1 msg=Started container task
0.3894,Event,ADDED,eval-sanitize-10-r0-193.18d4e4d30921b77b,reason=SuccessfulCreate count=1 msg=Created pod: eval-sanitize-10-r0-193-4x9j5
0.3896,Event,ADDED,eval-sanitize-10-r0-193.18d4e4d89486d8ba,reason=Completed count=1 msg=Job completed
0.3897,Event,ADDED,eval-sanitize-10-r0-194-dw2zn.18d4e4d354cb92a6,"reason=FailedScheduling count=None msg=0/6 nodes are available: 2 c_wall violated: 2 conflicting context pair(s) with node memory, 4 node(s) had untolerated taint(s). no new claims to deallocate, preemption: 0/6 nodes are available: 2 No preemption victims found for incoming pod, 4 Preemption is not helpful for scheduling."
0.3899,Event,ADDED,eval-sanitize-10-r0-194-dw2zn.18d4e4d35a584a53,"reason=FailedScheduling count=None msg=0/6 nodes are available: 2 c_wall violated: 2 conflicting context pair(s) with node memory, 4 node(s) had untolerated taint(s). no new claims to deallocate, preemption: 0/6 nodes are available: 2 No preemption victims found for incoming pod, 4 Preemption is not helpful for scheduling."
0.39,Event,ADDED,eval-sanitize-10-r0-194-dw2zn.18d4e4d4b44a6445,reason=Scheduled count=None msg=Successfully assigned compute/eval-sanitize-10-r0-194-dw2zn to kind-worker2
0.3902,Event,ADDED,eval-sanitize-10-r0-194-dw2zn.18d4e4d4d297ffa5,"reason=Pulled count=1 msg=Container image ""busybox:musl"" already present on machine"
0.3904,Event,ADDED,eval-sanitize-10-r0-194-dw2zn.18d4e4d4d43a09fa,reason=Created count=1 msg=Created container: task
0.3905,Event,ADDED,eval-sanitize-10-r0-194-dw2zn.18d4e4d4dc46ac15,reason=Started count=1 msg=Started container task
0.3907,Event,ADDED,eval-sanitize-10-r0-194.18d4e4d351433ee0,reason=SuccessfulCreate count=1 msg=Created pod: eval-sanitize-10-r0-194-dw2zn
0.3909,Event,ADDED,eval-sanitize-10-r0-194.18d4e4da56968270,reason=Completed count=1 msg=Job completed
0.391,Event,ADDED,eval-sanitize-10-r0-195-cwg57.18d4e4d394805b59,"reason=FailedScheduling count=None msg=0/6 nodes are available: 2 c_wall violated: 2 conflicting context pair(s) with node memory, 4 node(s) had untolerated taint(s). no new claims to deallocate, preemption: 0/6 nodes are available: 2 No preemption victims found for incoming pod, 4 Preemption is not helpful for scheduling."
0.3912,Event,ADDED,eval-sanitize-10-r0-195-cwg57.18d4e4d3963914fe,"reason=FailedScheduling count=None msg=0/6 nodes are available: 2 c_wall violated: 2 conflicting context pair(s) with node memory, 4 node(s) had untolerated taint(s). no new claims to deallocate, preemption: 0/6 nodes are available: 2 No preemption victims found for incoming pod, 4 Preemption is not helpful for scheduling."
0.3914,Event,ADDED,eval-sanitize-10-r0-195-cwg57.18d4e4d4bfeb58f7,reason=Scheduled count=None msg=Successfully assigned compute/eval-sanitize-10-r0-195-cwg57 to kind-worker2
0.3915,Event,ADDED,eval-sanitize-10-r0-195-cwg57.18d4e4d4dc4cd540,"reason=Pulled count=1 msg=Container image ""busybox:musl"" already present on machine"
0.3917,Event,ADDED,eval-sanitize-10-r0-195-cwg57.18d4e4d4dd7fb22e,reason=Created count=1 msg=Created container: task
0.3918,Event,ADDED,eval-sanitize-10-r0-195-cwg57.18d4e4d4e16adb02,reason=Started count=1 msg=Started container task
0.392,Event,ADDED,eval-sanitize-10-r0-195.18d4e4d39419d72c,reason=SuccessfulCreate count=1 msg=Created pod: eval-sanitize-10-r0-195-cwg57
0.3922,Event,ADDED,eval-sanitize-10-r0-195.18d4e4da5747a2d7,reason=Completed count=1 msg=Job completed
0.3923,Event,ADDED,eval-sanitize-10-r0-196-dtxlj.18d4e4d3c2ed7087,reason=Scheduled count=None msg=Successfully assigned compute/eval-sanitize-10-r0-196-dtxlj to kind-worker
0.3925,Event,ADDED,eval-sanitize-10-r0-196-dtxlj.18d4e4d3db7fd56e,"reason=Pulled count=1 msg=Container image ""busybox:musl"" already present on machine"
0.3927,Event,ADDED,eval-sanitize-10-r0-196-dtxlj.18d4e4d3dc98a60a,reason=Created count=1 msg=Created container: task
0.3928,Event,ADDED,eval-sanitize-10-r0-196-dtxlj.18d4e4d3dea5983b,reason=Started count=1 msg=Started container task
0.393,Event,ADDED,eval-sanitize-10-r0-196.18d4e4d3c2584fa5,reason=SuccessfulCreate count=1 msg=Created pod: eval-sanitize-10-r0-196-dtxlj
0.3931,Event,ADDED,eval-sanitize-10-r0-196.18d4e4d948e8b766,reason=Completed count=1 msg=Job completed
0.3933,Event,ADDED,eval-sanitize-10-r0-197-qdgbc.18d4e4d3f87ee85c,reason=Scheduled count=None msg=Successfully assigned compute/eval-sanitize-10-r0-197-qdgbc to kind-worker3
0.3935,Event,ADDED,eval-sanitize-10-r0-197-qdgbc.18d4e4d411868ed4,"reason=Pulled count=1 msg=Container image ""busybox:musl"" already present on machine"
0.3937,Event,ADDED,eval-sanitize-10-r0-197-qdgbc.18d4e4d412baf9ed,reason=Created count=1 msg=Created container: task
0.3939,Event,ADDED,eval-sanitize-10-r0-197-qdgbc.18d4e4d414b1dd02,reason=Started count=1 msg=Started container task
0.3941,Event,ADDED,eval-sanitize-10-r0-197.18d4e4d3f7749815,reason=SuccessfulCreate count=1 msg=Created pod: eval-sanitize-10-r0-197-qdgbc
0.3942,Event,ADDED,eval-sanitize-10-r0-197.18d4e4d982c95a66,reason=Completed count=1 msg=Job completed
0.3944,Event,ADDED,eval-sanitize-10-r0-198-kgc2d.18d4e4d433bfd5e8,reason=Scheduled count=None msg=Successfully assigned compute/eval-sanitize-10-r0-198-kgc2d to kind-worker
0.3945,Event,ADDED,eval-sanitize-10-r0-198-kgc2d.18d4e4d44c7afd58,"reason=Pulled count=1 msg=Container image ""busybox:musl"" already present on machine"
0.3947,Event,ADDED,eval-sanitize-10-r0-198-kgc2d.18d4e4d44d8af20a,reason=Created count=1 msg=Created container: task
0.3948,Event,ADDED,eval-sanitize-10-r0-198-kgc2d.18d4e4d453bb0ac6,reason=Started count=1 msg=Started container task
0.395,Event,ADDED,eval-sanitize-10-r0-198.18d4e4d4332371b6,reason=SuccessfulCreate count=1 msg=Created pod: eval-sanitize-10-r0-198-kgc2d
0.3952,Event,ADDED,eval-sanitize-10-r0-198.18d4e4d984a4962b,reason=Completed count=1 msg=Job completed
0.3953,Event,ADDED,eval-sanitize-10-r0-199-dnxrm.18d4e4d46f83b80e,reason=Scheduled count=None msg=Successfully assigned compute/eval-sanitize-10-r0-199-dnxrm to kind-worker3
0.3955,Event,ADDED,eval-sanitize-10-r0-199-dnxrm.18d4e4d4891cb735,"reason=Pulled count=1 msg=Container image ""busybox:musl"" already present on machine"
0.3957,Event,ADDED,eval-sanitize-10-r0-199-dnxrm.18d4e4d48a24f81f,reason=Created count=1 msg=Created container: task
0.3958,Event,ADDED,eval-sanitize-10-r0-199-dnxrm.18d4e4d48f936c66,reason=Started count=1 msg=Started container task
0.396,Event,ADDED,eval-sanitize-10-r0-199.18d4e4d46ed28693,reason=SuccessfulCreate count=1 msg=Created pod: eval-sanitize-10-r0-199-dnxrm
0.3961,Event,ADDED,eval-sanitize-10-r0-199.18d4e4d9fa7687c9,reason=Completed count=1 msg=Job completed
0.3963,Event,ADDED,eval-sanitize-10-r1-000-bgl6m.18d4e4e4f1d8cc00,reason=Scheduled count=None msg=Successfully assigned compute/eval-sanitize-10-r1-000-bgl6m to kind-worker5
0.3965,Event,ADDED,eval-sanitize-10-r1-000-bgl6m.18d4e4e50aa1b559,"reason=Pulled count=1 msg=Container image ""busybox:musl"" already present on machine"
0.3967,Event,ADDED,eval-sanitize-10-r1-000-bgl6m.18d4e4e50bbb75e4,reason=Created count=1 msg=Created container: task
0.397,Event,ADDED,eval-sanitize-10-r1-000-bgl6m.18d4e4e50f16fd9b,reason=Started count=1 msg=Started container task
0.3972,Event,ADDED,eval-sanitize-10-r1-000.18d4e4e4f0fe0608,reason=SuccessfulCreate count=1 msg=Created pod: eval-sanitize-10-r1-000-bgl6m
0.3974,Event,ADDED,eval-sanitize-10-r1-000.18d4e4ea8cc490fa,reason=Completed count=1 msg=Job completed
0.3977,Event,ADDED,eval-sanitize-10-r1-001-j8hjl.18d4e4e52c758013,reason=Scheduled count=None msg=Successfully assigned compute/eval-sanitize-10-r1-001-j8hjl to kind-worker2
0.3978,Event,ADDED,eval-sanitize-10-r1-001-j8hjl.18d4e4e5459e9934,"reason=Pulled count=1 msg=Container image ""busybox:musl"" already present on machine"
0.398,Event,ADDED,eval-sanitize-10-r1-001-j8hjl.18d4e4e546e5edb1,reason=Created count=1 msg=Created container: task
0.3982,Event,ADDED,eval-sanitize-10-r1-001-j8hjl.18d4e4e54b4cbff8,reason=Started count=1 msg=Started container task
0.3986,Event,ADDED,eval-sanitize-10-r1-001.18d4e4e52b7ce528,reason=SuccessfulCreate count=1 msg=Created pod: eval-sanitize-10-r1-001-j8hjl
0.3987,Event,ADDED,eval-sanitize-10-r1-001.18d4e4eaab152353,reason=Completed count=1 msg=Job completed
0.3989,Event,ADDED,eval-sanitize-10-r1-002-p2r8l.18d4e4e567965944,reason=Scheduled count=None msg=Successfully assigned compute/eval-sanitize-10-r1-002-p2r8l to kind-worker4
0.3991,Event,ADDED,eval-sanitize-10-r1-002-p2r8l.18d4e4e581b99102,"reason=Pulled count=1 msg=Container image ""busybox:musl"" already present on machine"
0.3994,Event,ADDED,eval-sanitize-10-r1-002-p2r8l.18d4e4e582be8225,reason=Created count=1 msg=Created container: task
0.3996,Event,ADDED,eval-sanitize-10-r1-002-p2r8l.18d4e4e5848da56e,reason=Started count=1 msg=Started container task
0.3998,Event,ADDED,eval-sanitize-10-r1-002.18d4e4e5668535c1,reason=SuccessfulCreate count=1 msg=Created pod: eval-sanitize-10-r1-002-p2r8l
0.4001,Event,ADDED,eval-sanitize-10-r1-002.18d4e4eb16e3f795,reason=Completed count=1 msg=Job completed
0.4003,Event,ADDED,eval-sanitize-10-r1-003-pj66m.18d4e4e5a370fbf1,reason=Scheduled count=None msg=Successfully assigned compute/eval-sanitize-10-r1-003-pj66m to kind-worker
0.4005,Event,ADDED,eval-sanitize-10-r1-003-pj66m.18d4e4e5bcf6c026,"reason=Pulled count=1 msg=Container image ""busybox:musl"" already present on machine"
0.4007,Event,ADDED,eval-sanitize-10-r1-003-pj66m.18d4e4e5be0ccf2d,reason=Created count=1 msg=Created container: task
0.401,Event,ADDED,eval-sanitize-10-r1-003-pj66m.18d4e4e5c5b9459c,reason=Started count=1 msg=Started container task
0.4012,Event,ADDED,eval-sanitize-10-r1-003.18d4e4e5a28c52f5,reason=SuccessfulCreate count=1 msg=Created pod: eval-sanitize-10-r1-003-pj66m
0.4014,Event,ADDED,eval-sanitize-10-r1-003.18d4e4eb41fff486,reason=Completed count=1 msg=Job completed
0.4015,Event,ADDED,eval-sanitize-10-r1-004-gdm5v.18d4e4e5e12a3fe2,reason=Scheduled count=None msg=Successfully assigned compute/eval-sanitize-10-r1-004-gdm5v to kind-worker3
0.4019,Event,ADDED,eval-sanitize-10-r1-004-gdm5v.18d4e4e5fd44879c,"reason=Pulled count=1 msg=Container image ""busybox:musl"" already present on machine"
0.402,Event,ADDED,eval-sanitize-10-r1-004-gdm5v.18d4e4e5fe65acc1,reason=Created count=1 msg=Created container: task
0.4022,Event,ADDED,eval-sanitize-10-r1-004-gdm5v.18d4e4e605a636fc,reason=Started count=1 msg=Started container task
0.4025,Event,ADDED,eval-sanitize-10-r1-004.18d4e4e5e07a6836,reason=SuccessfulCreate count=1 msg=Created pod: eval-sanitize-10-r1-004-gdm5v
0.4027,Event,ADDED,eval-sanitize-10-r1-004.18d4e4eb77a7b4d3,reason=Completed count=1 msg=Job completed
0.4029,Event,ADDED,eval-sanitize-10-r1-005-zqm9z.18d4e4e61aa22225,reason=Scheduled count=None msg=Successfully assigned compute/eval-sanitize-10-r1-005-zqm9z to kind-worker3
0.403,Event,ADDED,eval-sanitize-10-r1-005-zqm9z.18d4e4e637e78714,"reason=Pulled count=1 msg=Container image ""busybox:musl"" already present on machine"
0.4033,Event,ADDED,eval-sanitize-10-r1-005-zqm9z.18d4e4e6391648c2,reason=Created count=1 msg=Created container: task
0.4034,Event,ADDED,eval-sanitize-10-r1-005-zqm9z.18d4e4e63fcb702e,reason=Started count=1 msg=Started container task
0.4037,Event,ADDED,eval-sanitize-10-r1-005.18d4e4e619a0c0bb,reason=SuccessfulCreate count=1 msg=Created pod: eval-sanitize-10-r1-005-zqm9z
0.4038,Event,ADDED,eval-sanitize-10-r1-005.18d4e4ebb3ac4f09,reason=Completed count=1 msg=Job completed
0.404,Event,ADDED,eval-sanitize-10-r1-006-zwshz.18d4e4e656086b78,reason=Scheduled count=None msg=Successfully assigned compute/eval-sanitize-10-r1-006-zwshz to kind-worker3
0.4042,Event,ADDED,eval-sanitize-10-r1-006-zwshz.18d4e4e67b8a7e1f,"reason=Pulled count=1 msg=Container image ""busybox:musl"" already present on machine"
0.4043,Event,ADDED,eval-sanitize-10-r1-006-zwshz.18d4e4e67cd4161e,reason=Created count=1 msg=Created container: task
0.4045,Event,ADDED,eval-sanitize-10-r1-006-zwshz.18d4e4e68aa12413,reason=Started count=1 msg=Started container task
0.4047,Event,ADDED,eval-sanitize-10-r1-006.18d4e4e655042406,reason=SuccessfulCreate count=1 msg=Created pod: eval-sanitize-10-r1-006-zwshz
0.4048,Event,ADDED,eval-sanitize-10-r1-006.18d4e4ebef8dda5c,reason=Completed count=1 msg=Job completed
0.405,Event,ADDED,eval-sanitize-10-r1-007-z69tb.18d4e4e696246011,reason=Scheduled count=None msg=Successfully assigned compute/eval-sanitize-10-r1-007-z69tb to kind-worker3
0.4055,Event,ADDED,eval-sanitize-10-r1-007-z69tb.18d4e4e6bdb80549,"reason=Pulled count=1 msg=Container image ""busybox:musl"" already present on machine"
0.4057,Event,ADDED,eval-sanitize-10-r1-007-z69tb.18d4e4e6bed504a5,reason=Created count=1 msg=Created container: task
0.4058,Event,ADDED,eval-sanitize-10-r1-007-z69tb.18d4e4e6c257f845,reason=Started count=1 msg=Started container task
0.406,Event,ADDED,eval-sanitize-10-r1-007.18d4e4e695158396,reason=SuccessfulCreate count=1 msg=Created pod: eval-sanitize-10-r1-007-z69tb
0.4063,Event,ADDED,eval-sanitize-10-r1-007.18d4e4ec2ba4a90a,reason=Completed count=1 msg=Job completed
0.4064,Event,ADDED,eval-sanitize-10-r1-008-cj5zw.18d4e4e6cd1af67b,reason=Scheduled count=None msg=Successfully assigned compute/eval-sanitize-10-r1-008-cj5zw to kind-worker3
0.4066,Event,ADDED,eval-sanitize-10-r1-008-cj5zw.18d4e4e6eff0d43c,"reason=Pulled count=1 msg=Container image ""busybox:musl"" already present on machine"
0.4069,Event,ADDED,eval-sanitize-10-r1-008-cj5zw.18d4e4e6f10d9057,reason=Created count=1 msg=Created container: task
0.4071,Event,ADDED,eval-sanitize-10-r1-008-cj5zw.18d4e4e6fe1bb9ee,reason=Started count=1 msg=Started container task
0.4073,Event,ADDED,eval-sanitize-10-r1-008.18d4e4e6cc14aff0,reason=SuccessfulCreate count=1 msg=Created pod: eval-sanitize-10-r1-008-cj5zw
0.4075,Event,ADDED,eval-sanitize-10-r1-008.18d4e4ec6a43ac30,reason=Completed count=1 msg=Job completed
0.4078,Event,ADDED,eval-sanitize-10-r1-009-knll7.18d4e4e7136d6633,reason=Scheduled count=None msg=Successfully assigned compute/eval-sanitize-10-r1-009-knll7 to kind-worker3
0.408,Event,ADDED,eval-sanitize-10-r1-009-knll7.18d4e4e72d92d4f0,"reason=Pulled count=1 msg=Container image ""busybox:musl"" already present on machine"
0.4081,Event,ADDED,eval-sanitize-10-r1-009-knll7.18d4e4e72ea5cad1,reason=Created count=1 msg=Created container: task
0.4083,Event,ADDED,eval-sanitize-10-r1-009-knll7.18d4e4e732cabb86,reason=Started count=1 msg=Started container task
0.4087,Event,ADDED,eval-sanitize-10-r1-009.18d4e4e71257b0e0,reason=SuccessfulCreate count=1 msg=Created pod: eval-sanitize-10-r1-009-knll7
0.409,Event,ADDED,eval-sanitize-10-r1-009.18d4e4ecab7f09df,reason=Completed count=1 msg=Job completed
0.4091,Event,ADDED,eval-sanitize-10-r1-010-lz228.18d4e4e74592810a,reason=Scheduled count=None msg=Successfully assigned compute/eval-sanitize-10-r1-010-lz228 to kind-worker
0.4094,Event,ADDED,eval-sanitize-10-r1-010-lz228.18d4e4e760b02b16,"reason=Pulled count=1 msg=Container image ""busybox:musl"" already present on machine"
0.4097,Event,ADDED,eval-sanitize-10-r1-010-lz228.18d4e4e761ea8e12,reason=Created count=1 msg=Created container: task
0.4099,Event,ADDED,eval-sanitize-10-r1-010-lz228.18d4e4e766cf4fbe,reason=Started count=1 msg=Started container task
0.41,Event,ADDED,eval-sanitize-10-r1-010.18d4e4e744846264,reason=SuccessfulCreate count=1 msg=Created pod: eval-sanitize-10-r1-010-lz228
0.4103,Event,ADDED,eval-sanitize-10-r1-010.18d4e4ece78d0058,reason=Completed count=1 msg=Job completed
0.4104,Event,ADDED,eval-sanitize-10-r1-011-xdc8x.18d4e4e78025ac59,"reason=FailedScheduling count=None msg=0/6 nodes are available: 1 c_wall violated: 1 conflicting context pair(s) with node memory, 1 c_wall violated: 2 conflicting context pair(s) with node memory, 4 node(s) had untolerated taint(s). no new claims to deallocate, preemption: 0/6 nodes are available: 2 No preemption victims found for incoming pod, 4 Preemption is not helpful for scheduling."
0.4106,Event,ADDED,eval-sanitize-10-r1-011-xdc8x.18d4e4e780d04df7,"reason=FailedScheduling count=None msg=0/6 nodes are available: 1 c_wall violated: 1 conflicting context pair(s) with node memory, 1 c_wall violated: 2 conflicting context pair(s) with node memory, 4 node(s) had untolerated taint(s). no new claims to deallocate, preemption: 0/6 nodes are available: 2 No preemption victims found for incoming pod, 4 Preemption is not helpful for scheduling."
0.4108,Event,ADDED,eval-sanitize-10-r1-011-xdc8x.18d4e4e7ce889156,"reason=FailedScheduling count=None msg=0/6 nodes are available: 1 c_wall violated: 1 conflicting context pair(s) with node memory, 5 node(s) had untolerated taint(s). no new claims to deallocate, preemption: 0/6 nodes are available: 1 No preemption victims found for incoming pod, 5 Preemption is not helpful for scheduling."
0.411,Event,ADDED,eval-sanitize-10-r1-011-xdc8x.18d4e4ea4083b148,reason=Scheduled count=None msg=Successfully assigned compute/eval-sanitize-10-r1-011-xdc8x to kind-worker5
0.4111,Event,ADDED,eval-sanitize-10-r1-011-xdc8x.18d4e4ea5dc51639,"reason=Pulled count=1 msg=Container image ""busybox:musl"" already present on machine"
0.4113,Event,ADDED,eval-sanitize-10-r1-011-xdc8x.18d4e4ea60488230,reason=Created count=1 msg=Created container: task
0.4115,Event,ADDED,eval-sanitize-10-r1-011-xdc8x.18d4e4ea64b1aaa7,reason=Started count=1 msg=Started container task
0.4117,Event,ADDED,eval-sanitize-10-r1-011.18d4e4e77fafbe66,reason=SuccessfulCreate count=1 msg=Created pod: eval-sanitize-10-r1-011-xdc8x
0.4118,Event,ADDED,eval-sanitize-10-r1-011.18d4e4eff170e136,reason=Completed count=1 msg=Job completed
0.412,Event,ADDED,eval-sanitize-10-r1-012-t64st.18d4e4e7bc4017e9,reason=Scheduled count=None msg=Successfully assigned compute/eval-sanitize-10-r1-012-t64st to kind-worker3
0.4121,Event,ADDED,eval-sanitize-10-r1-012-t64st.18d4e4e7d71537d7,"reason=Pulled count=1 msg=Container image ""busybox:musl"" already present on machine"
0.4123,Event,ADDED,eval-sanitize-10-r1-012-t64st.18d4e4e7d82acc73,reason=Created count=1 msg=Created container: task
0.4126,Event,ADDED,eval-sanitize-10-r1-012-t64st.18d4e4e7db943e96,reason=Started count=1 msg=Started container task
0.4129,Event,ADDED,eval-sanitize-10-r1-012.18d4e4e7bb634761,reason=SuccessfulCreate count=1 msg=Created pod: eval-sanitize-10-r1-012-t64st
0.4131,Event,ADDED,eval-sanitize-10-r1-012.18d4e4ed5a8632a8,reason=Completed count=1 msg=Job completed
0.4132,Event,ADDED,eval-sanitize-10-r1-013-gkqz2.18d4e4e7f6a13b9d,"reason=FailedScheduling count=None msg=0/6 nodes are available: 1 c_wall violated: 1 conflicting context pair(s) with node memory, 5 node(s) had untolerated taint(s). no new claims to deallocate, preemption: 0/6 nodes are available: 1 No preemption victims found for incoming pod, 5 Preemption is not helpful for scheduling."
0.4135,Event,ADDED,eval-sanitize-10-r1-013-gkqz2.18d4e4e7f76022d4,"reason=FailedScheduling count=None msg=0/6 nodes are available: 1 c_wall violated: 1 conflicting context pair(s) with node memory, 5 node(s) had untolerated taint(s). no new claims to deallocate, preemption: 0/6 nodes are available: 1 No preemption victims found for incoming pod, 5 Preemption is not helpful for scheduling."
0.4136,Event,ADDED,eval-sanitize-10-r1-013-gkqz2.18d4e4ea41150c88,reason=Scheduled count=None msg=Successfully assigned compute/eval-sanitize-10-r1-013-gkqz2 to kind-worker5
0.4138,Event,ADDED,eval-sanitize-10-r1-013-gkqz2.18d4e4ea5dd5eda8,"reason=Pulled count=1 msg=Container image ""busybox:musl"" already present on machine"
0.414,Event,ADDED,eval-sanitize-10-r1-013-gkqz2.18d4e4ea60095f07,reason=Created count=1 msg=Created container: task
0.4142,Event,ADDED,eval-sanitize-10-r1-013-gkqz2.18d4e4ea647daa5f,reason=Started count=1 msg=Started container task
0.4143,Event,ADDED,eval-sanitize-10-r1-013.18d4e4e7f655c6af,reason=SuccessfulCreate count=1 msg=Created pod: eval-sanitize-10-r1-013-gkqz2
0.4145,Event,ADDED,eval-sanitize-10-r1-013.18d4e4eff1aa4b61,reason=Completed count=1 msg=Job completed
0.4146,Event,ADDED,eval-sanitize-10-r1-014-mtc4p.18d4e4e831ce93f8,"reason=FailedScheduling count=None msg=0/6 nodes are available: 6 node(s) had untolerated taint(s). no new claims to deallocate, preemption: 0/6 nodes are available: 6 Preemption is not helpful for scheduling."
0.4148,Event,ADDED,eval-sanitize-10-r1-014-mtc4p.18d4e4ea4180be14,reason=Scheduled count=None msg=Successfully assigned compute/eval-sanitize-10-r1-014-mtc4p to kind-worker5
0.4149,Event,ADDED,eval-sanitize-10-r1-014-mtc4p.18d4e4ea5e063c30,"reason=Pulled count=1 msg=Container image ""busybox:musl"" already present on machine"
0.4152,Event,ADDED,eval-sanitize-10-r1-014-mtc4p.18d4e4ea60ba24ab,reason=Created count=1 msg=Created container: task
0.4155,Event,ADDED,eval-sanitize-10-r1-014-mtc4p.18d4e4ea64e8edc3,reason=Started count=1 msg=Started container task
0.4157,Event,ADDED,eval-sanitize-10-r1-014.18d4e4e831c64375,reason=SuccessfulCreate count=1 msg=Created pod: eval-sanitize-10-r1-014-mtc4p
0.4159,Event,ADDED,eval-sanitize-10-r1-014.18d4e4eff137a2aa,reason=Completed count=1 msg=Job completed
0.416,Event,ADDED,eval-sanitize-10-r1-015-2nwzb.18d4e4e86d7d6603,"reason=FailedScheduling count=None msg=0/6 nodes are available: 6 node(s) had untolerated taint(s). no new claims to deallocate, preemption: 0/6 nodes are available: 6 Preemption is not helpful for scheduling."
0.4163,Event,ADDED,eval-sanitize-10-r1-015-2nwzb.18d4e4ea41318de2,"reason=FailedScheduling count=None msg=0/6 nodes are available: 1 c_wall violated: 1 conflicting context pair(s) with node memory, 5 node(s) had untolerated taint(s). no new claims to deallocate, preemption: 0/6 nodes are available: 1 No preemption victims found for incoming pod, 5 Preemption is not helpful for scheduling."
0.4165,Event,ADDED,eval-sanitize-10-r1-015-2nwzb.18d4e4ea4c49f129,"reason=FailedScheduling count=None msg=0/6 nodes are available: 1 c_wall violated: 1 conflicting context pair(s) with node memory, 5 node(s) had untolerated taint(s). no new claims to deallocate, preemption: 0/6 nodes are available: 1 No preemption victims found for incoming pod, 5 Preemption is not helpful for scheduling."
0.4171,Event,ADDED,eval-sanitize-10-r1-015-2nwzb.18d4e4ec34bcd00b,"reason=FailedScheduling count=None msg=0/6 nodes are available: 2 c_wall violated: 1 conflicting context pair(s) with node memory, 4 node(s) had untolerated taint(s). no new claims to deallocate, preemption: 0/6 nodes are available: 2 No preemption victims found for incoming pod, 4 Preemption is not helpful for scheduling."
0.4173,Event,ADDED,eval-sanitize-10-r1-015-2nwzb.18d4e4ec9c10400a,reason=Scheduled count=None msg=Successfully assigned compute/eval-sanitize-10-r1-015-2nwzb to kind-worker
0.4174,Event,ADDED,eval-sanitize-10-r1-015-2nwzb.18d4e4ecb5abd44d,"reason=Pulled count=1 msg=Container image ""busybox:musl"" already present on machine"
0.4176,Event,ADDED,eval-sanitize-10-r1-015-2nwzb.18d4e4ecb78e0acf,reason=Created count=1 msg=Created container: task
0.4179,Event,ADDED,eval-sanitize-10-r1-015-2nwzb.18d4e4ecbd02d1d9,reason=Started count=1 msg=Started container task
0.4181,Event,ADDED,eval-sanitize-10-r1-015.18d4e4e86d6aef74,reason=SuccessfulCreate count=1 msg=Created pod: eval-sanitize-10-r1-015-2nwzb
0.4183,Event,ADDED,eval-sanitize-10-r1-015.18d4e4f20b31eee6,reason=Completed count=1 msg=Job completed
0.4184,Event,ADDED,eval-sanitize-10-r1-016-5zqhb.18d4e4e8a9c540a9,"reason=FailedScheduling count=None msg=0/6 nodes are available: 6 node(s) had untolerated taint(s). no new claims to deallocate, preemption: 0/6 nodes are available: 6 Preemption is not helpful for scheduling."
0.4187,Event,ADDED,eval-sanitize-10-r1-016-5zqhb.18d4e4ea41e2818f,"reason=FailedScheduling count=None msg=0/6 nodes are available: 1 c_wall violated: 1 conflicting context pair(s) with node memory, 5 node(s) had untolerated taint(s). no new claims to deallocate, preemption: 0/6 nodes are available: 1 No preemption victims found for incoming pod, 5 Preemption is not helpful for scheduling."
0.4189,Event,ADDED,eval-sanitize-10-r1-016-5zqhb.18d4e4ea50844091,"reason=FailedScheduling count=None msg=0/6 nodes are available: 1 c_wall violated: 1 conflicting context pair(s) with node memory, 5 node(s) had untolerated taint(s). no new claims to deallocate, preemption: 0/6 nodes are available: 1 No preemption victims found for incoming pod, 5 Preemption is not helpful for scheduling."
0.4191,Event,ADDED,eval-sanitize-10-r1-016-5zqhb.18d4e4ec35139bc0,"reason=FailedScheduling count=None msg=0/6 nodes are available: 2 c_wall violated: 1 conflicting context pair(s) with node memory, 4 node(s) had untolerated taint(s). no new claims to deallocate, preemption: 0/6 nodes are available: 2 No preemption victims found for incoming pod, 4 Preemption is not helpful for scheduling."
0.4194,Event,ADDED,eval-sanitize-10-r1-016-5zqhb.18d4e4ecc463fea8,reason=Scheduled count=None msg=Successfully assigned compute/eval-sanitize-10-r1-016-5zqhb to kind-worker4
0.4196,Event,ADDED,eval-sanitize-10-r1-016-5zqhb.18d4e4ece59d1063,"reason=Pulled count=1 msg=Container image ""busybox:musl"" already present on machine"
0.4198,Event,ADDED,eval-sanitize-10-r1-016-5zqhb.18d4e4ece74a2a27,reason=Created count=1 msg=Created container: task
0.42,Event,ADDED,eval-sanitize-10-r1-016-5zqhb.18d4e4ece980ff89,reason=Started count=1 msg=Started container task
0.4201,Event,ADDED,eval-sanitize-10-r1-016.18d4e4e8a9baec79,reason=SuccessfulCreate count=1 msg=Created pod: eval-sanitize-10-r1-016-5zqhb
0.4203,Event,ADDED,eval-sanitize-10-r1-016.18d4e4f2563927d1,reason=Completed count=1 msg=Job completed
0.4205,Event,ADDED,eval-sanitize-10-r1-017-chm5l.18d4e4e8e5463192,"reason=FailedScheduling count=None msg=0/6 nodes are available: 6 node(s) had untolerated taint(s). no new claims to deallocate, preemption: 0/6 nodes are available: 6 Preemption is not helpful for scheduling."
0.4206,Event,ADDED,eval-sanitize-10-r1-017-chm5l.18d4e4ea44a32b17,"reason=FailedScheduling count=None msg=0/6 nodes are available: 1 c_wall violated: 1 conflicting context pair(s) with node memory, 5 node(s) had untolerated taint(s). no new claims to deallocate, preemption: 0/6 nodes are available: 1 No preemption victims found for incoming pod, 5 Preemption is not helpful for scheduling."
0.4208,Event,ADDED,eval-sanitize-10-r1-017-chm5l.18d4e4ea50c8045f,"reason=FailedScheduling count=None msg=0/6 nodes are available: 1 c_wall violated: 1 conflicting context pair(s) with node memory, 5 node(s) had untolerated taint(s). no new claims to deallocate, preemption: 0/6 nodes are available: 1 No preemption victims found for incoming pod, 5 Preemption is not helpful for scheduling."
0.4212,Event,ADDED,eval-sanitize-10-r1-017-chm5l.18d4e4ea8b8f4c60,"reason=FailedScheduling count=None msg=0/6 nodes are available: 1 c_wall violated: 2 conflicting context pair(s) with node memory, 5 node(s) had untolerated taint(s). no new claims to deallocate, preemption: 0/6 nodes are available: 1 No preemption victims found for incoming pod, 5 Preemption is not helpful for scheduling."
0.4213,Event,ADDED,eval-sanitize-10-r1-017-chm5l.18d4e4ec38042d67,"reason=FailedScheduling count=None msg=0/6 nodes are available: 1 c_wall violated: 2 conflicting context pair(s) with node memory, 1 c_wall violated: 3 conflicting context pair(s) with node memory, 4 node(s) had untolerated taint(s). no new claims to deallocate, preemption: 0/6 nodes are available: 2 No preemption victims found for incoming pod, 4 Preemption is not helpful for scheduling."
0.4215,Event,ADDED,eval-sanitize-10-r1-017-chm5l.18d4e4ec444d35eb,"reason=FailedScheduling count=None msg=0/6 nodes are available: 1 c_wall violated: 2 conflicting context pair(s) with node memory, 1 c_wall violated: 3 conflicting context pair(s) with node memory, 4 node(s) had untolerated taint(s). no new claims to deallocate, preemption: 0/6 nodes are available: 2 No preemption victims found for incoming pod, 4 Preemption is not helpful for scheduling."
0.4217,Event,ADDED,eval-sanitize-10-r1-017-chm5l.18d4e4ec9d925834,reason=Scheduled count=None msg=Successfully assigned compute/eval-sanitize-10-r1-017-chm5l to kind-worker
0.4218,Event,ADDED,eval-sanitize-10-r1-017-chm5l.18d4e4ecb6212700,"reason=Pulled count=1 msg=Container image ""busybox:musl"" already present on machine"
0.422,Event,ADDED,eval-sanitize-10-r1-017-chm5l.18d4e4ecb82cb98c,reason=Created count=1 msg=Created container: task
0.4222,Event,ADDED,eval-sanitize-10-r1-017-chm5l.18d4e4ecbcfe30f9,reason=Started count=1 msg=Started container task
0.4223,Event,ADDED,eval-sanitize-10-r1-017.18d4e4e8e534de33,reason=SuccessfulCreate count=1 msg=Created pod: eval-sanitize-10-r1-017-chm5l
0.4225,Event,ADDED,eval-sanitize-10-r1-017.18d4e4f2468bbeb7,reason=Completed count=1 msg=Job completed
0.4227,Event,ADDED,eval-sanitize-10-r1-018-qgscl.18d4e4e92196a499,"reason=FailedScheduling count=None msg=0/6 nodes are available: 6 node(s) had untolerated taint(s). no new claims to deallocate, preemption: 0/6 nodes are available: 6 Preemption is not helpful for scheduling."
0.4228,Event,ADDED,eval-sanitize-10-r1-018-qgscl.18d4e4ea464b245f,"reason=FailedScheduling count=None msg=0/6 nodes are available: 1 c_wall violated: 1 conflicting context pair(s) with node memory, 5 node(s) had untolerated taint(s). no new claims to deallocate, preemption: 0/6 nodes are available: 1 No preemption victims found for incoming pod, 5 Preemption is not helpful for scheduling."
0.423,Event,ADDED,eval-sanitize-10-r1-018-qgscl.18d4e4ea50fb1a63,"reason=FailedScheduling count=None msg=0/6 nodes are available: 1 c_wall violated: 1 conflicting context pair(s) with node memory, 5 node(s) had untolerated taint(s). no new claims to deallocate, preemption: 0/6 nodes are available: 1 No preemption victims found for incoming pod, 5 Preemption is not helpful for scheduling."
0.4232,Event,ADDED,eval-sanitize-10-r1-018-qgscl.18d4e4ec38c040c8,"reason=FailedScheduling count=None msg=0/6 nodes are available: 2 c_wall violated: 1 conflicting context pair(s) with node memory, 4 node(s) had untolerated taint(s). no new claims to deallocate, preemption: 0/6 nodes are available: 2 No preemption victims found for incoming pod, 4 Preemption is not helpful for scheduling."
0.4233,Event,ADDED,eval-sanitize-10-r1-018-qgscl.18d4e4ec937eacaa,reason=Scheduled count=None msg=Successfully assigned compute/eval-sanitize-10-r1-018-qgscl to kind-worker
0.4235,Event,ADDED,eval-sanitize-10-r1-018-qgscl.18d4e4ecb338e844,"reason=Pulled count=1 msg=Container image ""busybox:musl"" already present on machine"
0.4236,Event,ADDED,eval-sanitize-10-r1-018-qgscl.18d4e4ecb4cd9879,reason=Created count=1 msg=Created container: task
0.4238,Event,ADDED,eval-sanitize-10-r1-018-qgscl.18d4e4ecb70eb737,reason=Started count=1 msg=Started container task
0.424,Event,ADDED,eval-sanitize-10-r1-018.18d4e4e921939491,reason=SuccessfulCreate count=1 msg=Created pod: eval-sanitize-10-r1-018-qgscl
0.4241,Event,ADDED,eval-sanitize-10-r1-018.18d4e4f246bf9791,reason=Completed count=1 msg=Job completed
0.4243,Event,ADDED,eval-sanitize-10-r1-019-2fpkp.18d4e4e95d24163b,"reason=FailedScheduling count=None msg=0/6 nodes are available: 6 node(s) had untolerated taint(s). no new claims to deallocate, preemption: 0/6 nodes are available: 6 Preemption is not helpful for scheduling."
0.4244,Event,ADDED,eval-sanitize-10-r1-019-2fpkp.18d4e4ea46c11d77,"reason=FailedScheduling count=None msg=0/6 nodes are available: 1 c_wall violated: 1 conflicting context pair(s) with node memory, 5 node(s) had untolerated taint(s). no new claims to deallocate, preemption: 0/6 nodes are available: 1 No preemption victims found for incoming pod, 5 Preemption is not helpful for scheduling."
0.4246,Event,ADDED,eval-sanitize-10-r1-019-2fpkp.18d4e4ea5125a81a,"reason=FailedScheduling count=None msg=0/6 nodes are available: 1 c_wall violated: 1 conflicting context pair(s) with node memory, 5 node(s) had untolerated taint(s). no new claims to deallocate, preemption: 0/6 nodes are available: 1 No preemption victims found for incoming pod, 5 Preemption is not helpful for scheduling."
0.4249,Event,ADDED,eval-sanitize-10-r1-019-2fpkp.18d4e4ea8fabb9d8,"reason=FailedScheduling count=None msg=0/6 nodes are available: 1 c_wall violated: 2 conflicting context pair(s) with node memory, 5 node(s) had untolerated taint(s). no new claims to deallocate, preemption: 0/6 nodes are available: 1 No preemption victims found for incoming pod, 5 Preemption is not helpful for scheduling."
0.4251,Event,ADDED,eval-sanitize-10-r1-019-2fpkp.18d4e4ec207ba70a,reason=Scheduled count=None msg=Successfully assigned compute/eval-sanitize-10-r1-019-2fpkp to kind-worker2
0.4253,Event,ADDED,eval-sanitize-10-r1-019-2fpkp.18d4e4ec3cefe07c,"reason=Pulled count=1 msg=Container image ""busybox:musl"" already present on machine"
0.4255,Event,ADDED,eval-sanitize-10-r1-019-2fpkp.18d4e4ec3e7519cd,reason=Created count=1 msg=Created container: task
0.4256,Event,ADDED,eval-sanitize-10-r1-019-2fpkp.18d4e4ec43dc05ff,reason=Started count=1 msg=Started container task
0.4258,Event,ADDED,eval-sanitize-10-r1-019.18d4e4e95d19cc93,reason=SuccessfulCreate count=1 msg=Created pod: eval-sanitize-10-r1-019-2fpkp
0.426,Event,ADDED,eval-sanitize-10-r1-019.18d4e4f1739011b2,reason=Completed count=1 msg=Job completed
0.4261,Event,ADDED,eval-sanitize-10-r1-020-ggn42.18d4e4e997a9c8fe,"reason=FailedScheduling count=None msg=0/6 nodes are available: 6 node(s) had untolerated taint(s). no new claims to deallocate, preemption: 0/6 nodes are available: 6 Preemption is not helpful for scheduling."
0.4263,Event,ADDED,eval-sanitize-10-r1-020-ggn42.18d4e4ea4a6ae732,"reason=FailedScheduling count=None msg=0/6 nodes are available: 1 c_wall violated: 1 conflicting context pair(s) with node memory, 5 node(s) had untolerated taint(s). no new claims to deallocate, preemption: 0/6 nodes are available: 1 No preemption victims found for incoming pod, 5 Preemption is not helpful for scheduling."
0.4265,Event,ADDED,eval-sanitize-10-r1-020-ggn42.18d4e4ea51566604,"reason=FailedScheduling count=None msg=0/6 nodes are available: 1 c_wall violated: 1 conflicting context pair(s) with node memory, 5 node(s) had untolerated taint(s). no new claims to deallocate, preemption: 0/6 nodes are available: 1 No preemption victims found for incoming pod, 5 Preemption is not helpful for scheduling."
0.4267,Event,ADDED,eval-sanitize-10-r1-020-ggn42.18d4e4ea907d49c6,"reason=FailedScheduling count=None msg=0/6 nodes are available: 1 c_wall violated: 2 conflicting context pair(s) with node memory, 5 node(s) had untolerated taint(s). no new claims to deallocate, preemption: 0/6 nodes are available: 1 No preemption victims found for incoming pod, 5 Preemption is not helpful for scheduling."
0.4268,Event,ADDED,eval-sanitize-10-r1-020-ggn42.18d4e4ec3e5bb12d,"reason=FailedScheduling count=None msg=0/6 nodes are available: 1 c_wall violated: 2 conflicting context pair(s) with node memory, 1 c_wall violated: 3 conflicting context pair(s) with node memory, 4 node(s) had untolerated taint(s). no new claims to deallocate, preemption: 0/6 nodes are available: 2 No preemption victims found for incoming pod, 4 Preemption is not helpful for scheduling."
0.4271,Event,ADDED,eval-sanitize-10-r1-020-ggn42.18d4e4ec49ce9212,"reason=FailedScheduling count=None msg=0/6 nodes are available: 1 c_wall violated: 2 conflicting context pair(s) with node memory, 1 c_wall violated: 3 conflicting context pair(s) with node memory, 4 node(s) had untolerated taint(s). no new claims to deallocate, preemption: 0/6 nodes are available: 2 No preemption victims found for incoming pod, 4 Preemption is not helpful for scheduling."
0.4272,Event,ADDED,eval-sanitize-10-r1-020-ggn42.18d4e4ec929c67bb,reason=Scheduled count=None msg=Successfully assigned compute/eval-sanitize-10-r1-020-ggn42 to kind-worker
0.4274,Event,ADDED,eval-sanitize-10-r1-020-ggn42.18d4e4ecb2c67ba2,"reason=Pulled count=1 msg=Container image ""busybox:musl"" already present on machine"
0.4276,Event,ADDED,eval-sanitize-10-r1-020-ggn42.18d4e4ecb491a6a5,reason=Created count=1 msg=Created container: task
0.4278,Event,ADDED,eval-sanitize-10-r1-020-ggn42.18d4e4ecb70eb74b,reason=Started count=1 msg=Started container task
0.4279,Event,ADDED,eval-sanitize-10-r1-020.18d4e4e9979d5945,reason=SuccessfulCreate count=1 msg=Created pod: eval-sanitize-10-r1-020-ggn42
0.4281,Event,ADDED,eval-sanitize-10-r1-020.18d4e4f24696c7f9,reason=Completed count=1 msg=Job completed
0.4283,Event,ADDED,eval-sanitize-10-r1-021-8fscp.18d4e4e9d2f7f465,"reason=FailedScheduling count=None msg=0/6 nodes are available: 6 node(s) had untolerated taint(s). no new claims to deallocate, preemption: 0/6 nodes are available: 6 Preemption is not helpful for scheduling."
0.4285,Event,ADDED,eval-sanitize-10-r1-021-8fscp.18d4e4ea4b3532b3,reason=Scheduled count=None msg=Successfully assigned compute/eval-sanitize-10-r1-021-8fscp to kind-worker5
0.4287,Event,ADDED,eval-sanitize-10-r1-021-8fscp.18d4e4ea658990ba,"reason=Pulled count=1 msg=Container image ""busybox:musl"" already present on machine"
0.4289,Event,ADDED,eval-sanitize-10-r1-021-8fscp.18d4e4ea66a98538,reason=Created count=1 msg=Created container: task
0.4292,Event,ADDED,eval-sanitize-10-r1-021-8fscp.18d4e4ea6b6fdbc2,reason=Started count=1 msg=Started container task
0.4293,Event,ADDED,eval-sanitize-10-r1-021.18d4e4e9d2ea118e,reason=SuccessfulCreate count=1 msg=Created pod: eval-sanitize-10-r1-021-8fscp
0.4295,Event,ADDED,eval-sanitize-10-r1-021.18d4e4eff1a8dbba,reason=Completed count=1 msg=Job completed
0.4297,Event,ADDED,eval-sanitize-10-r1-022-rs9ml.18d4e4ea0fce8929,"reason=FailedScheduling count=None msg=0/6 nodes are available: 6 node(s) had untolerated taint(s). no new claims to deallocate, preemption: 0/6 nodes are available: 6 Preemption is not helpful for scheduling."
0.4298,Event,ADDED,eval-sanitize-10-r1-022-rs9ml.18d4e4ea4ba4a0a4,"reason=FailedScheduling count=None msg=0/6 nodes are available: 1 c_wall violated: 1 conflicting context pair(s) with node memory, 5 node(s) had untolerated taint(s). no new claims to deallocate, preemption: 0/6 nodes are available: 1 No preemption victims found for incoming pod, 5 Preemption is not helpful for scheduling."
0.43,Event,ADDED,eval-sanitize-10-r1-022-rs9ml.18d4e4ea54f80a4a,"reason=FailedScheduling count=None msg=0/6 nodes are available: 1 c_wall violated: 1 conflicting context pair(s) with node memory, 5 node(s) had untolerated taint(s). no new claims to deallocate, preemption: 0/6 nodes are available: 1 No preemption victims found for incoming pod, 5 Preemption is not helpful for scheduling."
0.4302,Event,ADDED,eval-sanitize-10-r1-022-rs9ml.18d4e4ea90db4359,"reason=FailedScheduling count=None msg=0/6 nodes are available: 1 c_wall violated: 2 conflicting context pair(s) with node memory, 5 node(s) had untolerated taint(s). no new claims to deallocate, preemption: 0/6 nodes are available: 1 No preemption victims found for incoming pod, 5 Preemption is not helpful for scheduling."
0.4303,Event,ADDED,eval-sanitize-10-r1-022-rs9ml.18d4e4ec1480341d,reason=Scheduled count=None msg=Successfully assigned compute/eval-sanitize-10-r1-022-rs9ml to kind-worker2
0.4306,Event,ADDED,eval-sanitize-10-r1-022-rs9ml.18d4e4ec33e30d18,"reason=Pulled count=1 msg=Container image ""busybox:musl"" already present on machine"
0.4309,Event,ADDED,eval-sanitize-10-r1-022-rs9ml.18d4e4ec375ce022,reason=Created count=1 msg=Created container: task
0.431,Event,ADDED,eval-sanitize-10-r1-022-rs9ml.18d4e4ec3be23758,reason=Started count=1 msg=Started container task
0.4312,Event,ADDED,eval-sanitize-10-r1-022.18d4e4ea0fc24db7,reason=SuccessfulCreate count=1 msg=Created pod: eval-sanitize-10-r1-022-rs9ml
0.4314,Event,ADDED,eval-sanitize-10-r1-022.18d4e4f1738e5c33,reason=Completed count=1 msg=Job completed
0.4316,Event,ADDED,eval-sanitize-10-r1-023-nnsnz.18d4e4ea4b1d9f65,"reason=FailedScheduling count=None msg=0/6 nodes are available: 1 c_wall violated: 1 conflicting context pair(s) with node memory, 5 node(s) had untolerated taint(s). no new claims to deallocate, preemption: 0/6 nodes are available: 1 No preemption victims found for incoming pod, 5 Preemption is not helpful for scheduling."
0.4318,Event,ADDED,eval-sanitize-10-r1-023-nnsnz.18d4e4ea5182b2cb,"reason=FailedScheduling count=None msg=0/6 nodes are available: 1 c_wall violated: 1 conflicting context pair(s) with node memory, 5 node(s) had untolerated taint(s). no new claims to deallocate, preemption: 0/6 nodes are available: 1 No preemption victims found for incoming pod, 5 Preemption is not helpful for scheduling."
0.4319,Event,ADDED,eval-sanitize-10-r1-023-nnsnz.18d4e4ec3f3089c6,"reason=FailedScheduling count=None msg=0/6 nodes are available: 2 c_wall violated: 1 conflicting context pair(s) with node memory, 4 node(s) had untolerated taint(s). no new claims to deallocate, preemption: 0/6 nodes are available: 2 No preemption victims found for incoming pod, 4 Preemption is not helpful for scheduling."
0.4321,Event,ADDED,eval-sanitize-10-r1-023-nnsnz.18d4e4eca33cb578,"reason=FailedScheduling count=None msg=0/6 nodes are available: 2 c_wall violated: 1 conflicting context pair(s) with node memory, 4 node(s) had untolerated taint(s). no new claims to deallocate, preemption: 0/6 nodes are available: 2 No preemption victims found for incoming pod, 4 Preemption is not helpful for scheduling."
0.4323,Event,ADDED,eval-sanitize-10-r1-023-nnsnz.18d4e4eca911e40e,"reason=FailedScheduling count=None msg=0/6 nodes are available: 2 c_wall violated: 1 conflicting context pair(s) with node memory, 4 node(s) had untolerated taint(s). no new claims to deallocate, preemption: 0/6 nodes are available: 2 No preemption victims found for incoming pod, 4 Preemption is not helpful for scheduling."
0.4324,Event,ADDED,eval-sanitize-10-r1-023-nnsnz.18d4e4ecc447cbe8,reason=Scheduled count=None msg=Successfully assigned compute/eval-sanitize-10-r1-023-nnsnz to kind-worker4
0.4326,Event,ADDED,eval-sanitize-10-r1-023-nnsnz.18d4e4ece586b459,"reason=Pulled count=1 msg=Container image ""busybox:musl"" already present on machine"
0.4329,Event,ADDED,eval-sanitize-10-r1-023-nnsnz.18d4e4ece6dec621,reason=Created count=1 msg=Created container: task
0.4331,Event,ADDED,eval-sanitize-10-r1-023-nnsnz.18d4e4ece923981b,reason=Started count=1 msg=Started container task
0.4333,Event,ADDED,eval-sanitize-10-r1-023.18d4e4ea49b64f89,reason=SuccessfulCreate count=1 msg=Created pod: eval-sanitize-10-r1-023-nnsnz
0.4336,Event,ADDED,eval-sanitize-10-r1-023.18d4e4f25610a72f,reason=Completed count=1 msg=Job completed
0.4338,Event,ADDED,eval-sanitize-10-r1-024-wsc79.18d4e4ea8692fc2a,reason=Scheduled count=None msg=Successfully assigned compute/eval-sanitize-10-r1-024-wsc79 to kind-worker5
0.4339,Event,ADDED,eval-sanitize-10-r1-024-wsc79.18d4e4eaa04edeb1,"reason=Pulled count=1 msg=Container image ""busybox:musl"" already present on machine"
0.4343,Event,ADDED,eval-sanitize-10-r1-024-wsc79.18d4e4eaa18728ae,reason=Created count=1 msg=Created container: task
0.4345,Event,ADDED,eval-sanitize-10-r1-024-wsc79.18d4e4eaa52b16c2,reason=Started count=1 msg=Started container task
0.4346,Event,ADDED,eval-sanitize-10-r1-024.18d4e4ea8604b36b,reason=SuccessfulCreate count=1 msg=Created pod: eval-sanitize-10-r1-024-wsc79
0.4348,Event,ADDED,eval-sanitize-10-r1-024.18d4e4f02d5a0c32,reason=Completed count=1 msg=Job completed
0.4351,Event,ADDED,eval-sanitize-10-r1-025-p26bb.18d4e4eac25638f5,"reason=FailedScheduling count=None msg=0/6 nodes are available: 1 c_wall violated: 2 conflicting context pair(s) with node memory, 5 node(s) had untolerated taint(s). no new claims to deallocate, preemption: 0/6 nodes are available: 1 No preemption victims found for incoming pod, 5 Preemption is not helpful for scheduling."
0.4353,Event,ADDED,eval-sanitize-10-r1-025-p26bb.18d4e4eac2fc818c,"reason=FailedScheduling count=None msg=0/6 nodes are available: 1 c_wall violated: 2 conflicting context pair(s) with node memory, 5 node(s) had untolerated taint(s). no new claims to deallocate, preemption: 0/6 nodes are available: 1 No preemption victims found for incoming pod, 5 Preemption is not helpful for scheduling."
0.4354,Event,ADDED,eval-sanitize-10-r1-025-p26bb.18d4e4ec14d85b55,reason=Scheduled count=None msg=Successfully assigned compute/eval-sanitize-10-r1-025-p26bb to kind-worker2
0.4359,Event,ADDED,eval-sanitize-10-r1-025-p26bb.18d4e4ec340821a7,"reason=Pulled count=1 msg=Container image ""busybox:musl"" already present on machine"
0.4361,Event,ADDED,eval-sanitize-10-r1-025-p26bb.18d4e4ec3814ede3,reason=Created count=1 msg=Created container: task
0.4363,Event,ADDED,eval-sanitize-10-r1-025-p26bb.18d4e4ec3c10589b,reason=Started count=1 msg=Started container task
0.4364,Event,ADDED,eval-sanitize-10-r1-025.18d4e4eac214dded,reason=SuccessfulCreate count=1 msg=Created pod: eval-sanitize-10-r1-025-p26bb
0.4366,Event,ADDED,eval-sanitize-10-r1-025.18d4e4f17334db68,reason=Completed count=1 msg=Job completed
0.4369,Event,ADDED,eval-sanitize-10-r1-026-jsggz.18d4e4eafd453b3b,reason=Scheduled count=None msg=Successfully assigned compute/eval-sanitize-10-r1-026-jsggz to kind-worker5
0.4371,Event,ADDED,eval-sanitize-10-r1-026-jsggz.18d4e4eb16568396,"reason=Pulled count=1 msg=Container image ""busybox:musl"" already present on machine"
0.4372,Event,ADDED,eval-sanitize-10-r1-026-jsggz.18d4e4eb179eb3c4,reason=Created count=1 msg=Created container: task
0.4376,Event,ADDED,eval-sanitize-10-r1-026-jsggz.18d4e4eb1e0614a9,reason=Started count=1 msg=Started container task
0.4378,Event,ADDED,eval-sanitize-10-r1-026.18d4e4eafcbf3bab,reason=SuccessfulCreate count=1 msg=Created pod: eval-sanitize-10-r1-026-jsggz
0.4379,Event,ADDED,eval-sanitize-10-r1-026.18d4e4f09f01f78a,reason=Completed count=1 msg=Job completed
0.4382,Event,ADDED,eval-sanitize-10-r1-027-qtx4r.18d4e4eb38834840,"reason=FailedScheduling count=None msg=0/6 nodes are available: 1 c_wall violated: 2 conflicting context pair(s) with node memory, 5 node(s) had untolerated taint(s). no new claims to deallocate, preemption: 0/6 nodes are available: 1 No preemption victims found for incoming pod, 5 Preemption is not helpful for scheduling."
0.4384,Event,ADDED,eval-sanitize-10-r1-027-qtx4r.18d4e4eb39092c82,"reason=FailedScheduling count=None msg=0/6 nodes are available: 1 c_wall violated: 2 conflicting context pair(s) with node memory, 5 node(s) had untolerated taint(s). no new claims to deallocate, preemption: 0/6 nodes are available: 1 No preemption victims found for incoming pod, 5 Preemption is not helpful for scheduling."
0.4385,Event,ADDED,eval-sanitize-10-r1-027-qtx4r.18d4e4ec2029dbf1,reason=Scheduled count=None msg=Successfully assigned compute/eval-sanitize-10-r1-027-qtx4r to kind-worker2
0.4387,Event,ADDED,eval-sanitize-10-r1-027-qtx4r.18d4e4ec3d0235e0,"reason=Pulled count=1 msg=Container image ""busybox:musl"" already present on machine"
0.4389,Event,ADDED,eval-sanitize-10-r1-027-qtx4r.18d4e4ec3edf143e,reason=Created count=1 msg=Created container: task
0.439,Event,ADDED,eval-sanitize-10-r1-027-qtx4r.18d4e4ec43dc05ea,reason=Started count=1 msg=Started container task
0.4393,Event,ADDED,eval-sanitize-10-r1-027.18d4e4eb38434153,reason=SuccessfulCreate count=1 msg=Created pod: eval-sanitize-10-r1-027-qtx4r
0.4396,Event,ADDED,eval-sanitize-10-r1-027.18d4e4f173683d26,reason=Completed count=1 msg=Job completed
0.4398,Event,ADDED,eval-sanitize-10-r1-028-6j5f6.18d4e4eb755cc8f8,reason=Scheduled count=None msg=Successfully assigned compute/eval-sanitize-10-r1-028-6j5f6 to kind-worker5
0.44,Event,ADDED,eval-sanitize-10-r1-028-6j5f6.18d4e4eb920d7871,"reason=Pulled count=1 msg=Container image ""busybox:musl"" already present on machine"
0.4401,Event,ADDED,eval-sanitize-10-r1-028-6j5f6.18d4e4eb93186372,reason=Created count=1 msg=Created container: task
0.4404,Event,ADDED,eval-sanitize-10-r1-028-6j5f6.18d4e4eb99c8e113,reason=Started count=1 msg=Started container task
0.4405,Event,ADDED,eval-sanitize-10-r1-028.18d4e4eb74cbdc28,reason=SuccessfulCreate count=1 msg=Created pod: eval-sanitize-10-r1-028-6j5f6
0.4408,Event,ADDED,eval-sanitize-10-r1-028.18d4e4f115f16773,reason=Completed count=1 msg=Job completed
0.4409,Event,ADDED,eval-sanitize-10-r1-029-jflgr.18d4e4ebb0165105,reason=Scheduled count=None msg=Successfully assigned compute/eval-sanitize-10-r1-029-jflgr to kind-worker5
0.4412,Event,ADDED,eval-sanitize-10-r1-029-jflgr.18d4e4ebcee2f517,"reason=Pulled count=1 msg=Container image ""busybox:musl"" already present on machine"
0.4414,Event,ADDED,eval-sanitize-10-r1-029-jflgr.18d4e4ebd00af6ff,reason=Created count=1 msg=Created container: task
0.4415,Event,ADDED,eval-sanitize-10-r1-029-jflgr.18d4e4ebd4038206,reason=Started count=1 msg=Started container task
0.4418,Event,ADDED,eval-sanitize-10-r1-029.18d4e4ebaf7e44e1,reason=SuccessfulCreate count=1 msg=Created pod: eval-sanitize-10-r1-029-jflgr
0.4421,Event,ADDED,eval-sanitize-10-r1-029.18d4e4f151cd260a,reason=Completed count=1 msg=Job completed
0.4423,Event,ADDED,eval-sanitize-10-r1-030-jmhns.18d4e4ebec942221,"reason=FailedScheduling count=None msg=0/6 nodes are available: 1 c_wall violated: 3 conflicting context pair(s) with node memory, 5 node(s) had untolerated taint(s). no new claims to deallocate, preemption: 0/6 nodes are available: 1 No preemption victims found for incoming pod, 5 Preemption is not helpful for scheduling."
0.4427,Event,ADDED,eval-sanitize-10-r1-030-jmhns.18d4e4ebed2c0d57,"reason=FailedScheduling count=None msg=0/6 nodes are available: 1 c_wall violated: 3 conflicting context pair(s) with node memory, 5 node(s) had untolerated taint(s). no new claims to deallocate, preemption: 0/6 nodes are available: 1 No preemption victims found for incoming pod, 5 Preemption is not helpful for scheduling."
0.4428,Event,ADDED,eval-sanitize-10-r1-030-jmhns.18d4e4ec3d986af0,"reason=FailedScheduling count=None msg=0/6 nodes are available: 2 c_wall violated: 3 conflicting context pair(s) with node memory, 4 node(s) had untolerated taint(s). no new claims to deallocate, preemption: 0/6 nodes are available: 2 No preemption victims found for incoming pod, 4 Preemption is not helpful for scheduling."
0.443,Event,ADDED,eval-sanitize-10-r1-030-jmhns.18d4e4ec497f637d,"reason=FailedScheduling count=None msg=0/6 nodes are available: 2 c_wall violated: 3 conflicting context pair(s) with node memory, 4 node(s) had untolerated taint(s). no new claims to deallocate, preemption: 0/6 nodes are available: 2 No preemption victims found for incoming pod, 4 Preemption is not helpful for scheduling."
0.4435,Event,ADDED,eval-sanitize-10-r1-030-jmhns.18d4e4eca4361c27,"reason=FailedScheduling count=None msg=0/6 nodes are available: 1 c_wall violated: 1 conflicting context pair(s) with node memory, 1 c_wall violated: 3 conflicting context pair(s) with node memory, 4 node(s) had untolerated taint(s). no new claims to deallocate, preemption: 0/6 nodes are available: 2 No preemption victims found for incoming pod, 4 Preemption is not helpful for scheduling."
0.4437,Event,ADDED,eval-sanitize-10-r1-030-jmhns.18d4e4ecc85ec935,reason=Scheduled count=None msg=Successfully assigned compute/eval-sanitize-10-r1-030-jmhns to kind-worker4
0.4439,Event,ADDED,eval-sanitize-10-r1-030-jmhns.18d4e4ece7f141d7,"reason=Pulled count=1 msg=Container image ""busybox:musl"" already present on machine"
0.4441,Event,ADDED,eval-sanitize-10-r1-030-jmhns.18d4e4ece97d2120,reason=Created count=1 msg=Created container: task
0.4444,Event,ADDED,eval-sanitize-10-r1-030-jmhns.18d4e4eceb521d76,reason=Started count=1 msg=Started container task
0.4446,Event,ADDED,eval-sanitize-10-r1-030.18d4e4ebec560964,reason=SuccessfulCreate count=1 msg=Created pod: eval-sanitize-10-r1-030-jmhns
0.4449,Event,ADDED,eval-sanitize-10-r1-030.18d4e4f2563875a4,reason=Completed count=1 msg=Job completed
0.4451,Event,ADDED,eval-sanitize-10-r1-031-dtfk5.18d4e4ec356eb282,reason=Scheduled count=None msg=Successfully assigned compute/eval-sanitize-10-r1-031-dtfk5 to kind-worker2
0.4453,Event,ADDED,eval-sanitize-10-r1-031-dtfk5.18d4e4ec61957d00,"reason=Pulled count=1 msg=Container image ""busybox:musl"" already present on machine"
0.4455,Event,ADDED,eval-sanitize-10-r1-031-dtfk5.18d4e4ec62e85f8c,reason=Created count=1 msg=Created container: task
0.4457,Event,ADDED,eval-sanitize-10-r1-031-dtfk5.18d4e4ec69fa760b,reason=Started count=1 msg=Started container task
0.4459,Event,ADDED,eval-sanitize-10-r1-031.18d4e4ec28316f62,reason=SuccessfulCreate count=1 msg=Created pod: eval-sanitize-10-r1-031-dtfk5
0.446,Event,ADDED,eval-sanitize-10-r1-031.18d4e4f1ed934485,reason=Completed count=1 msg=Job completed
0.4462,Event,ADDED,eval-sanitize-10-r1-032-8cb7t.18d4e4ec6389b2eb,reason=Scheduled count=None msg=Successfully assigned compute/eval-sanitize-10-r1-032-8cb7t to kind-worker2
0.4464,Event,ADDED,eval-sanitize-10-r1-032-8cb7t.18d4e4ec81edc14e,"reason=Pulled count=1 msg=Container image ""busybox:musl"" already present on machine"
0.4465,Event,ADDED,eval-sanitize-10-r1-032-8cb7t.18d4e4ec8303a0cb,reason=Created count=1 msg=Created container: task
0.4467,Event,ADDED,eval-sanitize-10-r1-032-8cb7t.18d4e4ec86c30168,reason=Started count=1 msg=Started container task
0.447,Event,ADDED,eval-sanitize-10-r1-032.18d4e4ec62c7dad5,reason=SuccessfulCreate count=1 msg=Created pod: eval-sanitize-10-r1-032-8cb7t
0.4472,Event,ADDED,eval-sanitize-10-r1-032.18d4e4f229daa642,reason=Completed count=1 msg=Job completed
0.4475,Event,ADDED,eval-sanitize-10-r1-033-sd5hj.18d4e4eca335adec,reason=Scheduled count=None msg=Successfully assigned compute/eval-sanitize-10-r1-033-sd5hj to kind-worker
0.4477,Event,ADDED,eval-sanitize-10-r1-033-sd5hj.18d4e4ecbd03061e,"reason=Pulled count=1 msg=Container image ""busybox:musl"" already present on machine"
0.4478,Event,ADDED,eval-sanitize-10-r1-033-sd5hj.18d4e4ecbe3ec186,reason=Created count=1 msg=Created container: task
0.4481,Event,ADDED,eval-sanitize-10-r1-033-sd5hj.18d4e4ecc47d4d69,reason=Started count=1 msg=Started container task
0.4483,Event,ADDED,eval-sanitize-10-r1-033.18d4e4ec9de65f7e,reason=SuccessfulCreate count=1 msg=Created pod: eval-sanitize-10-r1-033-sd5hj
0.4485,Event,ADDED,eval-sanitize-10-r1-033.18d4e4f20b32b56d,reason=Completed count=1 msg=Job completed
0.4487,Event,ADDED,eval-sanitize-10-r1-034-cljvr.18d4e4ecda80de8e,"reason=FailedScheduling count=None msg=0/6 nodes are available: 1 c_wall violated: 3 conflicting context pair(s) with node memory, 2 c_wall violated: 1 conflicting context pair(s) with node memory, 3 node(s) had untolerated taint(s). no new claims to deallocate, preemption: 0/6 nodes are available: 3 No preemption victims found for incoming pod, 3 Preemption is not helpful for scheduling."
0.449,Event,ADDED,eval-sanitize-10-r1-034-cljvr.18d4e4ecdecb6f63,"reason=FailedScheduling count=None msg=0/6 nodes are available: 1 c_wall violated: 3 conflicting context pair(s) with node memory, 2 c_wall violated: 1 conflicting context pair(s) with node memory, 3 node(s) had untolerated taint(s). no new claims to deallocate, preemption: 0/6 nodes are available: 3 No preemption victims found for incoming pod, 3 Preemption is not helpful for scheduling."
0.4492,Event,ADDED,eval-sanitize-10-r1-034-cljvr.18d4e4ee690b37ab,"reason=FailedScheduling count=None msg=0/6 nodes are available: 2 c_wall violated: 1 conflicting context pair(s) with node memory, 4 node(s) had untolerated taint(s). no new claims to deallocate, preemption: 0/6 nodes are available: 2 No preemption victims found for incoming pod, 4 Preemption is not helpful for scheduling."
0.4495,Event,ADDED,eval-sanitize-10-r1-034-cljvr.18d4e4eee84fd4b2,"reason=FailedScheduling count=None msg=0/6 nodes are available: 1 c_wall violated: 1 conflicting context pair(s) with node memory, 5 node(s) had untolerated taint(s). no new claims to deallocate, preemption: 0/6 nodes are available: 1 No preemption victims found for incoming pod, 5 Preemption is not helpful for scheduling."
0.4497,Event,ADDED,eval-sanitize-10-r1-034-cljvr.18d4e4ef34daa81c,"reason=FailedScheduling count=None msg=0/6 nodes are available: 1 c_wall violated: 1 conflicting context pair(s) with node memory, 5 node(s) had untolerated taint(s). no new claims to deallocate, preemption: 0/6 nodes are available: 1 No preemption victims found for incoming pod, 5 Preemption is not helpful for scheduling."
0.4499,Event,ADDED,eval-sanitize-10-r1-034-cljvr.18d4e4ef3a2c4d2e,"reason=FailedScheduling count=None msg=0/6 nodes are available: 1 c_wall violated: 1 conflicting context pair(s) with node memory, 5 node(s) had untolerated taint(s). no new claims to deallocate, preemption: 0/6 nodes are available: 1 No preemption victims found for incoming pod, 5 Preemption is not helpful for scheduling."
0.4504,Event,ADDED,eval-sanitize-10-r1-034-cljvr.18d4e4efe4149fc2,"reason=FailedScheduling count=None msg=0/6 nodes are available: 1 c_wall violated: 2 conflicting context pair(s) with node memory, 5 node(s) had untolerated taint(s). no new claims to deallocate, preemption: 0/6 nodes are available: 1 No preemption victims found for incoming pod, 5 Preemption is not helpful for scheduling."
0.4506,Event,ADDED,eval-sanitize-10-r1-034-cljvr.18d4e4f16de2c179,"reason=FailedScheduling count=None msg=0/6 nodes are available: 2 c_wall violated: 2 conflicting context pair(s) with node memory, 4 node(s) had untolerated taint(s). no new claims to deallocate, preemption: 0/6 nodes are available: 2 No preemption victims found for incoming pod, 4 Preemption is not helpful for scheduling."
0.4507,Event,ADDED,eval-sanitize-10-r1-034-cljvr.18d4e4f193595ad2,"reason=FailedScheduling count=None msg=0/6 nodes are available: 1 c_wall violated: 2 conflicting context pair(s) with node memory, 5 node(s) had untolerated taint(s). no new claims to deallocate, preemption: 0/6 nodes are available: 1 No preemption victims found for incoming pod, 5 Preemption is not helpful for scheduling."
0.4511,Event,ADDED,eval-sanitize-10-r1-034-cljvr.18d4e4f33b6df02c,reason=Scheduled count=None msg=Successfully assigned compute/eval-sanitize-10-r1-034-cljvr to kind-worker2
0.4513,Event,ADDED,eval-sanitize-10-r1-034-cljvr.18d4e4f35484d087,"reason=Pulled count=1 msg=Container image ""busybox:musl"" already present on machine"
0.4517,Event,ADDED,eval-sanitize-10-r1-034-cljvr.18d4e4f3563445e5,reason=Created count=1 msg=Created container: task
0.4519,Event,ADDED,eval-sanitize-10-r1-034-cljvr.18d4e4f359c4ce8c,reason=Started count=1 msg=Started container task
0.4522,Event,ADDED,eval-sanitize-10-r1-034.18d4e4ecd9c7a3df,reason=SuccessfulCreate count=1 msg=Created pod: eval-sanitize-10-r1-034-cljvr
0.4524,Event,ADDED,eval-sanitize-10-r1-034.18d4e4f8efcab45c,reason=Completed count=1 msg=Job completed
0.4525,Event,ADDED,eval-sanitize-10-r1-035-pbdqp.18d4e4ed15c02bfe,"reason=FailedScheduling count=None msg=0/6 nodes are available: 3 c_wall violated: 1 conflicting context pair(s) with node memory, 3 node(s) had untolerated taint(s). no new claims to deallocate, preemption: 0/6 nodes are available: 3 No preemption victims found for incoming pod, 3 Preemption is not helpful for scheduling."
0.4529,Event,ADDED,eval-sanitize-10-r1-035-pbdqp.18d4e4ed1a37827b,"reason=FailedScheduling count=None msg=0/6 nodes are available: 3 c_wall violated: 1 conflicting context pair(s) with node memory, 3 node(s) had untolerated taint(s). no new claims to deallocate, preemption: 0/6 nodes are available: 3 No preemption victims found for incoming pod, 3 Preemption is not helpful for scheduling."
0.4531,Event,ADDED,eval-sanitize-10-r1-035-pbdqp.18d4e4ee6d461258,"reason=FailedScheduling count=None msg=0/6 nodes are available: 2 c_wall violated: 1 conflicting context pair(s) with node memory, 4 node(s) had untolerated taint(s). no new claims to deallocate, preemption: 0/6 nodes are available: 2 No preemption victims found for incoming pod, 4 Preemption is not helpful for scheduling."
0.4534,Event,ADDED,eval-sanitize-10-r1-035-pbdqp.18d4e4eeeaffc71c,"reason=FailedScheduling count=None msg=0/6 nodes are available: 1 c_wall violated: 1 conflicting context pair(s) with node memory, 5 node(s) had untolerated taint(s). no new claims to deallocate, preemption: 0/6 nodes are available: 1 No preemption victims found for incoming pod, 5 Preemption is not helpful for scheduling."
0.4537,Event,ADDED,eval-sanitize-10-r1-035-pbdqp.18d4e4ef3604f1a7,reason=Scheduled count=None msg=Successfully assigned compute/eval-sanitize-10-r1-035-pbdqp to kind-worker3
0.4539,Event,ADDED,eval-sanitize-10-r1-035-pbdqp.18d4e4ef5d909aaa,"reason=Pulled count=1 msg=Container image ""busybox:musl"" already present on machine"
0.4541,Event,ADDED,eval-sanitize-10-r1-035-pbdqp.18d4e4ef5f2516aa,reason=Created count=1 msg=Created container: task
0.4542,Event,ADDED,eval-sanitize-10-r1-035-pbdqp.18d4e4ef6b246099,reason=Started count=1 msg=Started container task
0.4545,Event,ADDED,eval-sanitize-10-r1-035.18d4e4ed151dd0ce,reason=SuccessfulCreate count=1 msg=Created pod: eval-sanitize-10-r1-035-pbdqp
0.4546,Event,ADDED,eval-sanitize-10-r1-035.18d4e4f4d7446b3f,reason=Completed count=1 msg=Job completed
0.4548,Event,ADDED,eval-sanitize-10-r1-036-6mj27.18d4e4ed52135a23,reason=Scheduled count=None msg=Successfully assigned compute/eval-sanitize-10-r1-036-6mj27 to kind-worker2
0.455,Event,ADDED,eval-sanitize-10-r1-036-6mj27.18d4e4ed803c33d6,"reason=Pulled count=1 msg=Container image ""busybox:musl"" already present on machine"
0.4552,Event,ADDED,eval-sanitize-10-r1-036-6mj27.18d4e4ed8155b989,reason=Created count=1 msg=Created container: task
0.4554,Event,ADDED,eval-sanitize-10-r1-036-6mj27.18d4e4ed84f31bcd,reason=Started count=1 msg=Started container task
0.4556,Event,ADDED,eval-sanitize-10-r1-036.18d4e4ed5107db4d,reason=SuccessfulCreate count=1 msg=Created pod: eval-sanitize-10-r1-036-6mj27
0.4559,Event,ADDED,eval-sanitize-10-r1-036.18d4e4f3131ebef5,reason=Completed count=1 msg=Job completed
0.4561,Event,ADDED,eval-sanitize-10-r1-037-dcttd.18d4e4ed8f39c923,reason=Scheduled count=None msg=Successfully assigned compute/eval-sanitize-10-r1-037-dcttd to kind-worker2
0.4563,Event,ADDED,eval-sanitize-10-r1-037-dcttd.18d4e4eda878dbc3,"reason=Pulled count=1 msg=Container image ""busybox:musl"" already present on machine"
0.4564,Event,ADDED,eval-sanitize-10-r1-037-dcttd.18d4e4eda997deeb,reason=Created count=1 msg=Created container: task
0.4568,Event,ADDED,eval-sanitize-10-r1-037-dcttd.18d4e4edab7ab4a7,reason=Started count=1 msg=Started container task
0.457,Event,ADDED,eval-sanitize-10-r1-037.18d4e4ed8e515c5b,reason=SuccessfulCreate count=1 msg=Created pod: eval-sanitize-10-r1-037-dcttd
0.4571,Event,ADDED,eval-sanitize-10-r1-037.18d4e4f312ffcd93,reason=Completed count=1 msg=Job completed
0.4573,Event,ADDED,eval-sanitize-10-r1-038-gwknd.18d4e4edc8d9abb6,reason=Scheduled count=None msg=Successfully assigned compute/eval-sanitize-10-r1-038-gwknd to kind-worker
0.4577,Event,ADDED,eval-sanitize-10-r1-038-gwknd.18d4e4ede3abdaa7,"reason=Pulled count=1 msg=Container image ""busybox:musl"" already present on machine"
0.4579,Event,ADDED,eval-sanitize-10-r1-038-gwknd.18d4e4ede4ce0923,reason=Created count=1 msg=Created container: task
0.4581,Event,ADDED,eval-sanitize-10-r1-038-gwknd.18d4e4ede9b5311b,reason=Started count=1 msg=Started container task
0.4584,Event,ADDED,eval-sanitize-10-r1-038.18d4e4edc7c7ff7d,reason=SuccessfulCreate count=1 msg=Created pod: eval-sanitize-10-r1-038-gwknd
0.4586,Event,ADDED,eval-sanitize-10-r1-038.18d4e4f36b5cd8be,reason=Completed count=1 msg=Job completed
0.4587,Event,ADDED,eval-sanitize-10-r1-039-vlwqt.18d4e4ee04dc5ad2,reason=Scheduled count=None msg=Successfully assigned compute/eval-sanitize-10-r1-039-vlwqt to kind-worker
0.4589,Event,ADDED,eval-sanitize-10-r1-039-vlwqt.18d4e4ee2089cc1a,"reason=Pulled count=1 msg=Container image ""busybox:musl"" already present on machine"
0.4591,Event,ADDED,eval-sanitize-10-r1-039-vlwqt.18d4e4ee21a664ec,reason=Created count=1 msg=Created container: task
0.4593,Event,ADDED,eval-sanitize-10-r1-039-vlwqt.18d4e4ee261efc0b,reason=Started count=1 msg=Started container task
0.4595,Event,ADDED,eval-sanitize-10-r1-039.18d4e4ee03e21bb0,reason=SuccessfulCreate count=1 msg=Created pod: eval-sanitize-10-r1-039-vlwqt
0.4596,Event,ADDED,eval-sanitize-10-r1-039.18d4e4f3a711e4e6,reason=Completed count=1 msg=Job completed
0.4598,Event,ADDED,eval-sanitize-10-r1-040-c77s4.18d4e4ee41573535,reason=Scheduled count=None msg=Successfully assigned compute/eval-sanitize-10-r1-040-c77s4 to kind-worker
0.46,Event,ADDED,eval-sanitize-10-r1-040-c77s4.18d4e4ee5bf10c19,"reason=Pulled count=1 msg=Container image ""busybox:musl"" already present on machine"
0.4602,Event,ADDED,eval-sanitize-10-r1-040-c77s4.18d4e4ee5d114ed2,reason=Created count=1 msg=Created container: task
0.4605,Event,ADDED,eval-sanitize-10-r1-040-c77s4.18d4e4ee63d8c7f4,reason=Started count=1 msg=Started container task
0.4607,Event,ADDED,eval-sanitize-10-r1-040.18d4e4ee3f9e26bc,reason=SuccessfulCreate count=1 msg=Created pod: eval-sanitize-10-r1-040-c77s4
0.4609,Event,ADDED,eval-sanitize-10-r1-040.18d4e4f3e31037c7,reason=Completed count=1 msg=Job completed
0.461,Event,ADDED,eval-sanitize-10-r1-041-kp2zl.18d4e4ee7b3e1b03,"reason=FailedScheduling count=None msg=0/6 nodes are available: 2 c_wall violated: 1 conflicting context pair(s) with node memory, 4 node(s) had untolerated taint(s). no new claims to deallocate, preemption: 0/6 nodes are available: 2 No preemption victims found for incoming pod, 4 Preemption is not helpful for scheduling."
0.4614,Event,ADDED,eval-sanitize-10-r1-041-kp2zl.18d4e4ee7c47e43f,"reason=FailedScheduling count=None msg=0/6 nodes are available: 2 c_wall violated: 1 conflicting context pair(s) with node memory, 4 node(s) had untolerated taint(s). no new claims to deallocate, preemption: 0/6 nodes are available: 2 No preemption victims found for incoming pod, 4 Preemption is not helpful for scheduling."
0.4616,Event,ADDED,eval-sanitize-10-r1-041-kp2zl.18d4e4eee827625e,"reason=FailedScheduling count=None msg=0/6 nodes are available: 1 c_wall violated: 1 conflicting context pair(s) with node memory, 5 node(s) had untolerated taint(s). no new claims to deallocate, preemption: 0/6 nodes are available: 1 No preemption victims found for incoming pod, 5 Preemption is not helpful for scheduling."
0.4617,Event,ADDED,eval-sanitize-10-r1-041-kp2zl.18d4e4ef34ea29dd,reason=Scheduled count=None msg=Successfully assigned compute/eval-sanitize-10-r1-041-kp2zl to kind-worker3
0.4619,Event,ADDED,eval-sanitize-10-r1-041-kp2zl.18d4e4ef5d74334e,"reason=Pulled count=1 msg=Container image ""busybox:musl"" already present on machine"
0.4621,Event,ADDED,eval-sanitize-10-r1-041-kp2zl.18d4e4ef5f01748c,reason=Created count=1 msg=Created container: task
0.4623,Event,ADDED,eval-sanitize-10-r1-041-kp2zl.18d4e4ef6b2460ae,reason=Started count=1 msg=Started container task
0.4629,Event,ADDED,eval-sanitize-10-r1-041.18d4e4ee7adbe303,reason=SuccessfulCreate count=1 msg=Created pod: eval-sanitize-10-r1-041-kp2zl
0.463,Event,ADDED,eval-sanitize-10-r1-041.18d4e4f4d745d255,reason=Completed count=1 msg=Job completed
0.4632,Event,ADDED,eval-sanitize-10-r1-042-lclsw.18d4e4eeb7560b10,reason=Scheduled count=None msg=Successfully assigned compute/eval-sanitize-10-r1-042-lclsw to kind-worker
0.4633,Event,ADDED,eval-sanitize-10-r1-042-lclsw.18d4e4eed3d674c9,"reason=Pulled count=1 msg=Container image ""busybox:musl"" already present on machine"
0.4636,Event,ADDED,eval-sanitize-10-r1-042-lclsw.18d4e4eed4f31e41,reason=Created count=1 msg=Created container: task
0.4637,Event,ADDED,eval-sanitize-10-r1-042-lclsw.18d4e4eeda71dc82,reason=Started count=1 msg=Started container task
0.4639,Event,ADDED,eval-sanitize-10-r1-042.18d4e4eeb6b7ff83,reason=SuccessfulCreate count=1 msg=Created pod: eval-sanitize-10-r1-042-lclsw
0.4641,Event,ADDED,eval-sanitize-10-r1-042.18d4e4f45a44735f,reason=Completed count=1 msg=Job completed
0.4642,Event,ADDED,eval-sanitize-10-r1-043-r2pv8.18d4e4eef433f65c,"reason=FailedScheduling count=None msg=0/6 nodes are available: 1 c_wall violated: 2 conflicting context pair(s) with node memory, 5 node(s) had untolerated taint(s). no new claims to deallocate, preemption: 0/6 nodes are available: 1 No preemption victims found for incoming pod, 5 Preemption is not helpful for scheduling."
0.4644,Event,ADDED,eval-sanitize-10-r1-043-r2pv8.18d4e4eef4d71f74,"reason=FailedScheduling count=None msg=0/6 nodes are available: 1 c_wall violated: 2 conflicting context pair(s) with node memory, 5 node(s) had untolerated taint(s). no new claims to deallocate, preemption: 0/6 nodes are available: 1 No preemption victims found for incoming pod, 5 Preemption is not helpful for scheduling."
0.4646,Event,ADDED,eval-sanitize-10-r1-043-r2pv8.18d4e4ef35ed26dd,"reason=FailedScheduling count=None msg=0/6 nodes are available: 1 c_wall violated: 1 conflicting context pair(s) with node memory, 5 node(s) had untolerated taint(s). no new claims to deallocate, preemption: 0/6 nodes are available: 1 No preemption victims found for incoming pod, 5 Preemption is not helpful for scheduling."
0.4648,Event,ADDED,eval-sanitize-10-r1-043-r2pv8.18d4e4ef3a51583a,"reason=FailedScheduling count=None msg=0/6 nodes are available: 1 c_wall violated: 1 conflicting context pair(s) with node memory, 5 node(s) had untolerated taint(s). no new claims to deallocate, preemption: 0/6 nodes are available: 1 No preemption victims found for incoming pod, 5 Preemption is not helpful for scheduling."
0.465,Event,ADDED,eval-sanitize-10-r1-043-r2pv8.18d4e4f02106403b,"reason=FailedScheduling count=None msg=0/6 nodes are available: 1 c_wall violated: 2 conflicting context pair(s) with node memory, 5 node(s) had untolerated taint(s). no new claims to deallocate, preemption: 0/6 nodes are available: 1 No preemption victims found for incoming pod, 5 Preemption is not helpful for scheduling."
0.4652,Event,ADDED,eval-sanitize-10-r1-043-r2pv8.18d4e4f16f43d8f9,"reason=FailedScheduling count=None msg=0/6 nodes are available: 2 c_wall violated: 2 conflicting context pair(s) with node memory, 4 node(s) had untolerated taint(s). no new claims to deallocate, preemption: 0/6 nodes are available: 2 No preemption victims found for incoming pod, 4 Preemption is not helpful for scheduling."
0.4658,Event,ADDED,eval-sanitize-10-r1-043-r2pv8.18d4e4f19301f772,"reason=FailedScheduling count=None msg=0/6 nodes are available: 1 c_wall violated: 2 conflicting context pair(s) with node memory, 5 node(s) had untolerated taint(s). no new claims to deallocate, preemption: 0/6 nodes are available: 1 No preemption victims found for incoming pod, 5 Preemption is not helpful for scheduling."
0.466,Event,ADDED,eval-sanitize-10-r1-043-r2pv8.18d4e4f347c5188a,"reason=FailedScheduling count=None msg=0/6 nodes are available: 2 c_wall violated: 2 conflicting context pair(s) with node memory, 4 node(s) had untolerated taint(s). no new claims to deallocate, preemption: 0/6 nodes are available: 2 No preemption victims found for incoming pod, 4 Preemption is not helpful for scheduling."
0.4664,Event,ADDED,eval-sanitize-10-r1-043-r2pv8.18d4e4f351db52c4,"reason=FailedScheduling count=None msg=0/6 nodes are available: 2 c_wall violated: 2 conflicting context pair(s) with node memory, 4 node(s) had untolerated taint(s). no new claims to deallocate, preemption: 0/6 nodes are available: 2 No preemption victims found for incoming pod, 4 Preemption is not helpful for scheduling."
0.4666,Event,ADDED,eval-sanitize-10-r1-043-r2pv8.18d4e4f3b88c6825,"reason=FailedScheduling count=None msg=0/6 nodes are available: 1 c_wall violated: 2 conflicting context pair(s) with node memory, 5 node(s) had untolerated taint(s). no new claims to deallocate, preemption: 0/6 nodes are available: 1 No preemption victims found for incoming pod, 5 Preemption is not helpful for scheduling."
0.4668,Event,ADDED,eval-sanitize-10-r1-043-r2pv8.18d4e4f3e0b30f65,reason=Scheduled count=None msg=Successfully assigned compute/eval-sanitize-10-r1-043-r2pv8 to kind-worker4
0.4669,Event,ADDED,eval-sanitize-10-r1-043-r2pv8.18d4e4f3ffdd2e9f,"reason=Pulled count=1 msg=Container image ""busybox:musl"" already present on machine"
0.4673,Event,ADDED,eval-sanitize-10-r1-043-r2pv8.18d4e4f4021ca6e5,reason=Created count=1 msg=Created container: task
0.4675,Event,ADDED,eval-sanitize-10-r1-043-r2pv8.18d4e4f40a50edfc,reason=Started count=1 msg=Started container task
0.4676,Event,ADDED,eval-sanitize-10-r1-043.18d4e4eef3f34e97,reason=SuccessfulCreate count=1 msg=Created pod: eval-sanitize-10-r1-043-r2pv8
0.4679,Event,ADDED,eval-sanitize-10-r1-043.18d4e4f9915ebecb,reason=Completed count=1 msg=Job completed
0.4681,Event,ADDED,eval-sanitize-10-r1-044-rk65p.18d4e4ef342857ad,"reason=FailedScheduling count=None msg=0/6 nodes are available: 6 node(s) had untolerated taint(s). no new claims to deallocate, preemption: 0/6 nodes are available: 6 Preemption is not helpful for scheduling."
0.4683,Event,ADDED,eval-sanitize-10-r1-044-rk65p.18d4e4ef365663c1,"reason=FailedScheduling count=None msg=0/6 nodes are available: 1 c_wall violated: 2 conflicting context pair(s) with node memory, 5 node(s) had untolerated taint(s). no new claims to deallocate, preemption: 0/6 nodes are available: 1 No preemption victims found for incoming pod, 5 Preemption is not helpful for scheduling."
0.4684,Event,ADDED,eval-sanitize-10-r1-044-rk65p.18d4e4ef3a7773e9,"reason=FailedScheduling count=None msg=0/6 nodes are available: 1 c_wall violated: 2 conflicting context pair(s) with node memory, 5 node(s) had untolerated taint(s). no new claims to deallocate, preemption: 0/6 nodes are available: 1 No preemption victims found for incoming pod, 5 Preemption is not helpful for scheduling."
0.4688,Event,ADDED,eval-sanitize-10-r1-044-rk65p.18d4e4efe59ff456,"reason=FailedScheduling count=None msg=0/6 nodes are available: 1 c_wall violated: 3 conflicting context pair(s) with node memory, 5 node(s) had untolerated taint(s). no new claims to deallocate, preemption: 0/6 nodes are available: 1 No preemption victims found for incoming pod, 5 Preemption is not helpful for scheduling."
0.469,Event,ADDED,eval-sanitize-10-r1-044-rk65p.18d4e4f0212a800f,"reason=FailedScheduling count=None msg=0/6 nodes are available: 1 c_wall violated: 4 conflicting context pair(s) with node memory, 5 node(s) had untolerated taint(s). no new claims to deallocate, preemption: 0/6 nodes are available: 1 No preemption victims found for incoming pod, 5 Preemption is not helpful for scheduling."
0.4691,Event,ADDED,eval-sanitize-10-r1-044-rk65p.18d4e4f169257473,reason=Scheduled count=None msg=Successfully assigned compute/eval-sanitize-10-r1-044-rk65p to kind-worker5
0.4694,Event,ADDED,eval-sanitize-10-r1-044-rk65p.18d4e4f18942ff11,"reason=Pulled count=1 msg=Container image ""busybox:musl"" already present on machine"
0.4696,Event,ADDED,eval-sanitize-10-r1-044-rk65p.18d4e4f18aea76b1,reason=Created count=1 msg=Created container: task
0.4697,Event,ADDED,eval-sanitize-10-r1-044-rk65p.18d4e4f18eeeecb1,reason=Started count=1 msg=Started container task
0.4701,Event,ADDED,eval-sanitize-10-r1-044.18d4e4ef34209fb2,reason=SuccessfulCreate count=1 msg=Created pod: eval-sanitize-10-r1-044-rk65p
0.4703,Event,ADDED,eval-sanitize-10-r1-044.18d4e4f729651894,reason=Completed count=1 msg=Job completed
0.4705,Event,ADDED,eval-sanitize-10-r1-045-9l9c2.18d4e4ef6ce38047,"reason=FailedScheduling count=None msg=0/6 nodes are available: 1 c_wall violated: 1 conflicting context pair(s) with node memory, 5 node(s) had untolerated taint(s). no new claims to deallocate, preemption: 0/6 nodes are available: 1 No preemption victims found for incoming pod, 5 Preemption is not helpful for scheduling."
0.4709,Event,ADDED,eval-sanitize-10-r1-045-9l9c2.18d4e4ef6d5da26c,"reason=FailedScheduling count=None msg=0/6 nodes are available: 1 c_wall violated: 1 conflicting context pair(s) with node memory, 5 node(s) had untolerated taint(s). no new claims to deallocate, preemption: 0/6 nodes are available: 1 No preemption victims found for incoming pod, 5 Preemption is not helpful for scheduling."
0.4711,Event,ADDED,eval-sanitize-10-r1-045-9l9c2.18d4e4efe553a631,"reason=FailedScheduling count=None msg=0/6 nodes are available: 1 c_wall violated: 2 conflicting context pair(s) with node memory, 5 node(s) had untolerated taint(s). no new claims to deallocate, preemption: 0/6 nodes are available: 1 No preemption victims found for incoming pod, 5 Preemption is not helpful for scheduling."
0.4713,Event,ADDED,eval-sanitize-10-r1-045-9l9c2.18d4e4f16efeca7a,"reason=FailedScheduling count=None msg=0/6 nodes are available: 2 c_wall violated: 2 conflicting context pair(s) with node memory, 4 node(s) had untolerated taint(s). no new claims to deallocate, preemption: 0/6 nodes are available: 2 No preemption victims found for incoming pod, 4 Preemption is not helpful for scheduling."
0.4717,Event,ADDED,eval-sanitize-10-r1-045-9l9c2.18d4e4f192d21b1e,"reason=FailedScheduling count=None msg=0/6 nodes are available: 1 c_wall violated: 2 conflicting context pair(s) with node memory, 5 node(s) had untolerated taint(s). no new claims to deallocate, preemption: 0/6 nodes are available: 1 No preemption victims found for incoming pod, 5 Preemption is not helpful for scheduling."
0.4719,Event,ADDED,eval-sanitize-10-r1-045-9l9c2.18d4e4f33761e4f3,reason=Scheduled count=None msg=Successfully assigned compute/eval-sanitize-10-r1-045-9l9c2 to kind-worker2
0.4724,Event,ADDED,eval-sanitize-10-r1-045-9l9c2.18d4e4f350d14fbb,"reason=Pulled count=1 msg=Container image ""busybox:musl"" already present on machine"
0.4725,Event,ADDED,eval-sanitize-10-r1-045-9l9c2.18d4e4f35254a553,reason=Created count=1 msg=Created container: task
0.4732,Event,ADDED,eval-sanitize-10-r1-045-9l9c2.18d4e4f3547e0102,reason=Started count=1 msg=Started container task
0.4734,Event,ADDED,eval-sanitize-10-r1-045.18d4e4ef6c9f7eee,reason=SuccessfulCreate count=1 msg=Created pod: eval-sanitize-10-r1-045-9l9c2
0.4736,Event,ADDED,eval-sanitize-10-r1-045.18d4e4f8f09491dd,reason=Completed count=1 msg=Job completed
0.4739,Event,ADDED,eval-sanitize-10-r1-046-4wxt2.18d4e4efa73564c9,"reason=FailedScheduling count=None msg=0/6 nodes are available: 1 c_wall violated: 2 conflicting context pair(s) with node memory, 5 node(s) had untolerated taint(s). no new claims to deallocate, preemption: 0/6 nodes are available: 1 No preemption victims found for incoming pod, 5 Preemption is not helpful for scheduling."
0.4741,Event,ADDED,eval-sanitize-10-r1-046-4wxt2.18d4e4efa7b6a8b8,"reason=FailedScheduling count=None msg=0/6 nodes are available: 1 c_wall violated: 2 conflicting context pair(s) with node memory, 5 node(s) had untolerated taint(s). no new claims to deallocate, preemption: 0/6 nodes are available: 1 No preemption victims found for incoming pod, 5 Preemption is not helpful for scheduling."
0.4743,Event,ADDED,eval-sanitize-10-r1-046-4wxt2.18d4e4efe6ba8065,"reason=FailedScheduling count=None msg=0/6 nodes are available: 1 c_wall violated: 3 conflicting context pair(s) with node memory, 5 node(s) had untolerated taint(s). no new claims to deallocate, preemption: 0/6 nodes are available: 1 No preemption victims found for incoming pod, 5 Preemption is not helpful for scheduling."
0.4746,Event,ADDED,eval-sanitize-10-r1-046-4wxt2.18d4e4f15d02f3ee,reason=Scheduled count=None msg=Successfully assigned compute/eval-sanitize-10-r1-046-4wxt2 to kind-worker5
0.4747,Event,ADDED,eval-sanitize-10-r1-046-4wxt2.18d4e4f17a118b59,"reason=Pulled count=1 msg=Container image ""busybox:musl"" already present on machine"
0.4749,Event,ADDED,eval-sanitize-10-r1-046-4wxt2.18d4e4f17bb8eab3,reason=Created count=1 msg=Created container: task
0.4751,Event,ADDED,eval-sanitize-10-r1-046-4wxt2.18d4e4f18403a78a,reason=Started count=1 msg=Started container task
0.4754,Event,ADDED,eval-sanitize-10-r1-046.18d4e4efa6f9d469,reason=SuccessfulCreate count=1 msg=Created pod: eval-sanitize-10-r1-046-4wxt2
0.4757,Event,ADDED,eval-sanitize-10-r1-046.18d4e4f6b1ca248c,reason=Completed count=1 msg=Job completed
0.4759,Event,ADDED,eval-sanitize-10-r1-047-t7sg2.18d4e4efe18f02a5,reason=Scheduled count=None msg=Successfully assigned compute/eval-sanitize-10-r1-047-t7sg2 to kind-worker3
0.4762,Event,ADDED,eval-sanitize-10-r1-047-t7sg2.18d4e4effb97b780,"reason=Pulled count=1 msg=Container image ""busybox:musl"" already present on machine"
0.477,Event,ADDED,eval-sanitize-10-r1-047-t7sg2.18d4e4effcabfab2,reason=Created count=1 msg=Created container: task
0.4772,Event,ADDED,eval-sanitize-10-r1-047-t7sg2.18d4e4effe734f44,reason=Started count=1 msg=Started container task
0.4774,Event,ADDED,eval-sanitize-10-r1-047.18d4e4efe10e2de4,reason=SuccessfulCreate count=1 msg=Created pod: eval-sanitize-10-r1-047-t7sg2
0.4777,Event,ADDED,eval-sanitize-10-r1-047.18d4e4f58dce7bd2,reason=Completed count=1 msg=Job completed
0.4779,Event,ADDED,eval-sanitize-10-r1-048-grhnr.18d4e4f01c569f6f,reason=Scheduled count=None msg=Successfully assigned compute/eval-sanitize-10-r1-048-grhnr to kind-worker3
0.4781,Event,ADDED,eval-sanitize-10-r1-048-grhnr.18d4e4f035987a00,"reason=Pulled count=1 msg=Container image ""busybox:musl"" already present on machine"
0.4783,Event,ADDED,eval-sanitize-10-r1-048-grhnr.18d4e4f036b135c3,reason=Created count=1 msg=Created container: task
0.4786,Event,ADDED,eval-sanitize-10-r1-048-grhnr.18d4e4f03be149a3,reason=Started count=1 msg=Started container task
0.4787,Event,ADDED,eval-sanitize-10-r1-048.18d4e4f01bd66ef7,reason=SuccessfulCreate count=1 msg=Created pod: eval-sanitize-10-r1-048-grhnr
0.4789,Event,ADDED,eval-sanitize-10-r1-048.18d4e4f5bdb43898,reason=Completed count=1 msg=Job completed
0.4791,Event,ADDED,eval-sanitize-10-r1-049-92nxk.18d4e4f057f22724,"reason=FailedScheduling count=None msg=0/6 nodes are available: 1 c_wall violated: 4 conflicting context pair(s) with node memory, 5 node(s) had untolerated taint(s). no new claims to deallocate, preemption: 0/6 nodes are available: 1 No preemption victims found for incoming pod, 5 Preemption is not helpful for scheduling."
0.4793,Event,ADDED,eval-sanitize-10-r1-049-92nxk.18d4e4f0586f5b83,"reason=FailedScheduling count=None msg=0/6 nodes are available: 1 c_wall violated: 4 conflicting context pair(s) with node memory, 5 node(s) had untolerated taint(s). no new claims to deallocate, preemption: 0/6 nodes are available: 1 No preemption victims found for incoming pod, 5 Preemption is not helpful for scheduling."
0.4795,Event,ADDED,eval-sanitize-10-r1-049-92nxk.18d4e4f1697bb8f5,reason=Scheduled count=None msg=Successfully assigned compute/eval-sanitize-10-r1-049-92nxk to kind-worker5
0.4797,Event,ADDED,eval-sanitize-10-r1-049-92nxk.18d4e4f189a27a89,"reason=Pulled count=1 msg=Container image ""busybox:musl"" already present on machine"
0.4798,Event,ADDED,eval-sanitize-10-r1-049-92nxk.18d4e4f18b63945a,reason=Created count=1 msg=Created container: task
0.48,Event,ADDED,eval-sanitize-10-r1-049-92nxk.18d4e4f18f2303ed,reason=Started count=1 msg=Started container task
0.4802,Event,ADDED,eval-sanitize-10-r1-049.18d4e4f057ac5052,reason=SuccessfulCreate count=1 msg=Created pod: eval-sanitize-10-r1-049-92nxk
0.4803,Event,ADDED,eval-sanitize-10-r1-049.18d4e4f728dfa9e1,reason=Completed count=1 msg=Job completed
0.4805,Event,ADDED,eval-sanitize-10-r1-050-m8j6f.18d4e4f093bd4c1f,"reason=FailedScheduling count=None msg=0/6 nodes are available: 1 c_wall violated: 4 conflicting context pair(s) with node memory, 5 node(s) had untolerated taint(s). no new claims to deallocate, preemption: 0/6 nodes are available: 1 No preemption victims found for incoming pod, 5 Preemption is not helpful for scheduling."
0.4807,Event,ADDED,eval-sanitize-10-r1-050-m8j6f.18d4e4f09448e11c,"reason=FailedScheduling count=None msg=0/6 nodes are available: 1 c_wall violated: 4 conflicting context pair(s) with node memory, 5 node(s) had untolerated taint(s). no new claims to deallocate, preemption: 0/6 nodes are available: 1 No preemption victims found for incoming pod, 5 Preemption is not helpful for scheduling."
0.4808,Event,ADDED,eval-sanitize-10-r1-050-m8j6f.18d4e4f15b15af02,reason=Scheduled count=None msg=Successfully assigned compute/eval-sanitize-10-r1-050-m8j6f to kind-worker5
0.4811,Event,ADDED,eval-sanitize-10-r1-050-m8j6f.18d4e4f179c8dd2a,"reason=Pulled count=1 msg=Container image ""busybox:musl"" already present on machine"
0.4813,Event,ADDED,eval-sanitize-10-r1-050-m8j6f.18d4e4f17bcfb675,reason=Created count=1 msg=Created container: task
0.4816,Event,ADDED,eval-sanitize-10-r1-050-m8j6f.18d4e4f18403c18f,reason=Started count=1 msg=Started container task
0.4817,Event,ADDED,eval-sanitize-10-r1-050.18d4e4f09379a746,reason=SuccessfulCreate count=1 msg=Created pod: eval-sanitize-10-r1-050-m8j6f
0.4819,Event,ADDED,eval-sanitize-10-r1-050.18d4e4f6ed25abf0,reason=Completed count=1 msg=Job completed
0.4822,Event,ADDED,eval-sanitize-10-r1-051-8jgsw.18d4e4f0cf497556,reason=Scheduled count=None msg=Successfully assigned compute/eval-sanitize-10-r1-051-8jgsw to kind-worker3
0.4824,Event,ADDED,eval-sanitize-10-r1-051-8jgsw.18d4e4f0eab97cf4,"reason=Pulled count=1 msg=Container image ""busybox:musl"" already present on machine"
