t_recv,kind,type,name,detail
0.017,Event,ADDED,eval-sanitize-2-r1-019-mhl65.18d3d0fc3c377bce,"reason=FailedScheduling count=None msg=0/6 nodes are available: 2 c_wall violated: 1 conflicting context pair(s) with node memory, 4 node(s) had untolerated taint(s). no new claims to deallocate, preemption: 0/6 nodes are available: 2 No preemption victims found for incoming pod, 4 Preemption is not helpful for scheduling."
0.0179,Event,ADDED,eval-sanitize-2-r1-019-mhl65.18d3d0fc41f2b0d0,"reason=FailedScheduling count=None msg=0/6 nodes are available: 1 c_wall violated: 1 conflicting context pair(s) with node memory, 5 node(s) had untolerated taint(s). no new claims to deallocate, preemption: 0/6 nodes are available: 1 No preemption victims found for incoming pod, 5 Preemption is not helpful for scheduling."
0.0181,Event,ADDED,eval-sanitize-2-r1-021-5zgd4.18d3d0fe181b1013,"reason=FailedScheduling count=None msg=0/6 nodes are available: 1 c_wall violated: 1 conflicting context pair(s) with node memory, 5 node(s) had untolerated taint(s). no new claims to deallocate, preemption: 0/6 nodes are available: 1 No preemption victims found for incoming pod, 5 Preemption is not helpful for scheduling."
0.0183,Event,ADDED,eval-sanitize-2-r1-022-j62jr.18d3d0fe1860fa77,"reason=FailedScheduling count=None msg=0/6 nodes are available: 1 c_wall violated: 1 conflicting context pair(s) with node memory, 5 node(s) had untolerated taint(s). no new claims to deallocate, preemption: 0/6 nodes are available: 1 No preemption victims found for incoming pod, 5 Preemption is not helpful for scheduling."
0.0185,Event,ADDED,eval-sanitize-2-r1-023-ghcb9.18d3d0fe192cbe0d,"reason=FailedScheduling count=None msg=0/6 nodes are available: 1 c_wall violated: 1 conflicting context pair(s) with node memory, 5 node(s) had untolerated taint(s). no new claims to deallocate, preemption: 0/6 nodes are available: 1 No preemption victims found for incoming pod, 5 Preemption is not helpful for scheduling."
0.0187,Event,ADDED,eval-sanitize-2-r1-023-ghcb9.18d3d0fecc8cbc7b,"reason=FailedScheduling count=None msg=0/6 nodes are available: 1 c_wall violated: 2 conflicting context pair(s) with node memory, 5 node(s) had untolerated taint(s). no new claims to deallocate, preemption: 0/6 nodes are available: 1 No preemption victims found for incoming pod, 5 Preemption is not helpful for scheduling."
0.0189,Event,ADDED,eval-sanitize-2-r1-025-dxjk5.18d3d0fe1e128c69,"reason=FailedScheduling count=None msg=0/6 nodes are available: 1 c_wall violated: 1 conflicting context pair(s) with node memory, 5 node(s) had untolerated taint(s). no new claims to deallocate, preemption: 0/6 nodes are available: 1 No preemption victims found for incoming pod, 5 Preemption is not helpful for scheduling."
0.0191,Event,ADDED,eval-sanitize-2-r1-028-m45rp.18d3d0fe54f879aa,"reason=FailedScheduling count=None msg=0/6 nodes are available: 1 c_wall violated: 1 conflicting context pair(s) with node memory, 5 node(s) had untolerated taint(s). no new claims to deallocate, preemption: 0/6 nodes are available: 1 No preemption victims found for incoming pod, 5 Preemption is not helpful for scheduling."
0.0193,Event,ADDED,eval-sanitize-2-r1-029-8h5ds.18d3d0feccc23789,"reason=FailedScheduling count=None msg=0/6 nodes are available: 1 c_wall violated: 2 conflicting context pair(s) with node memory, 5 node(s) had untolerated taint(s). no new claims to deallocate, preemption: 0/6 nodes are available: 1 No preemption victims found for incoming pod, 5 Preemption is not helpful for scheduling."
0.0216,Event,ADDED,eval-sanitize-2-r1-029-8h5ds.18d3d0ff07e8edce,"reason=FailedScheduling count=None msg=0/6 nodes are available: 1 c_wall violated: 3 conflicting context pair(s) with node memory, 5 node(s) had untolerated taint(s). no new claims to deallocate, preemption: 0/6 nodes are available: 1 No preemption victims found for incoming pod, 5 Preemption is not helpful for scheduling."
0.0218,Event,ADDED,eval-sanitize-2-r1-029-8h5ds.18d3d0ff2bfac2c0,"reason=FailedScheduling count=None msg=0/6 nodes are available: 1 c_wall violated: 1 conflicting context pair(s) with node memory, 1 c_wall violated: 3 conflicting context pair(s) with node memory, 4 node(s) had untolerated taint(s). no new claims to deallocate, preemption: 0/6 nodes are available: 2 No preemption victims found for incoming pod, 4 Preemption is not helpful for scheduling."
0.022,Event,ADDED,eval-sanitize-2-r1-030-qxfhr.18d3d0fed24a070e,"reason=FailedScheduling count=None msg=0/6 nodes are available: 1 c_wall violated: 2 conflicting context pair(s) with node memory, 5 node(s) had untolerated taint(s). no new claims to deallocate, preemption: 0/6 nodes are available: 1 No preemption victims found for incoming pod, 5 Preemption is not helpful for scheduling."
0.0223,Event,ADDED,eval-sanitize-2-r1-033-l5hlx.18d3d0ff7e9bcade,"reason=FailedScheduling count=None msg=0/6 nodes are available: 1 c_wall violated: 1 conflicting context pair(s) with node memory, 1 c_wall violated: 2 conflicting context pair(s) with node memory, 4 node(s) had untolerated taint(s). no new claims to deallocate, preemption: 0/6 nodes are available: 2 No preemption victims found for incoming pod, 4 Preemption is not helpful for scheduling."
0.0226,Event,ADDED,eval-sanitize-2-r1-035-zhx85.18d3d0fff5331675,"reason=FailedScheduling count=None msg=0/6 nodes are available: 1 c_wall violated: 2 conflicting context pair(s) with node memory, 5 node(s) had untolerated taint(s). no new claims to deallocate, preemption: 0/6 nodes are available: 1 No preemption victims found for incoming pod, 5 Preemption is not helpful for scheduling."
0.0227,Event,ADDED,eval-sanitize-2-r1-036-k6gqd.18d3d10143b6d5c6,"reason=FailedScheduling count=None msg=0/6 nodes are available: 1 c_wall violated: 1 conflicting context pair(s) with node memory, 5 node(s) had untolerated taint(s). no new claims to deallocate, preemption: 0/6 nodes are available: 1 No preemption victims found for incoming pod, 5 Preemption is not helpful for scheduling."
0.0239,Node,ADDED,kind-control-plane,taints=1
0.0242,Event,ADDED,eval-sanitize-2-r1-037-n4x7c.18d3d101447d35b7,"reason=FailedScheduling count=None msg=0/6 nodes are available: 1 c_wall violated: 1 conflicting context pair(s) with node memory, 5 node(s) had untolerated taint(s). no new claims to deallocate, preemption: 0/6 nodes are available: 1 No preemption victims found for incoming pod, 5 Preemption is not helpful for scheduling."
0.0245,Event,ADDED,eval-sanitize-2-r1-039-9hqwx.18d3d10148b55f1a,"reason=FailedScheduling count=None msg=0/6 nodes are available: 1 c_wall violated: 1 conflicting context pair(s) with node memory, 5 node(s) had untolerated taint(s). no new claims to deallocate, preemption: 0/6 nodes are available: 1 No preemption victims found for incoming pod, 5 Preemption is not helpful for scheduling."
0.0247,Event,ADDED,eval-sanitize-2-r1-043-mqs67.18d3d10256ee65da,"reason=FailedScheduling count=None msg=0/6 nodes are available: 1 c_wall violated: 2 conflicting context pair(s) with node memory, 5 node(s) had untolerated taint(s). no new claims to deallocate, preemption: 0/6 nodes are available: 1 No preemption victims found for incoming pod, 5 Preemption is not helpful for scheduling."
0.0251,Event,ADDED,eval-sanitize-2-r1-043-mqs67.18d3d10262225b14,"reason=FailedScheduling count=None msg=0/6 nodes are available: 1 c_wall violated: 1 conflicting context pair(s) with node memory, 1 c_wall violated: 2 conflicting context pair(s) with node memory, 4 node(s) had untolerated taint(s). no new claims to deallocate, preemption: 0/6 nodes are available: 2 No preemption victims found for incoming pod, 4 Preemption is not helpful for scheduling."
0.0253,Event,ADDED,eval-sanitize-2-r1-044-qmqs2.18d3d102571a6b79,"reason=FailedScheduling count=None msg=0/6 nodes are available: 1 c_wall violated: 1 conflicting context pair(s) with node memory, 5 node(s) had untolerated taint(s). no new claims to deallocate, preemption: 0/6 nodes are available: 1 No preemption victims found for incoming pod, 5 Preemption is not helpful for scheduling."
0.0256,Event,ADDED,eval-sanitize-2-r1-044-qmqs2.18d3d10262b13a21,"reason=FailedScheduling count=None msg=0/6 nodes are available: 2 c_wall violated: 1 conflicting context pair(s) with node memory, 4 node(s) had untolerated taint(s). no new claims to deallocate, preemption: 0/6 nodes are available: 2 No preemption victims found for incoming pod, 4 Preemption is not helpful for scheduling."
0.0258,Event,ADDED,eval-sanitize-2-r1-044-qmqs2.18d3d10278a71b6f,"reason=FailedScheduling count=None msg=0/6 nodes are available: 3 c_wall violated: 1 conflicting context pair(s) with node memory, 3 node(s) had untolerated taint(s). no new claims to deallocate, preemption: 0/6 nodes are available: 3 No preemption victims found for incoming pod, 3 Preemption is not helpful for scheduling."
0.026,Event,ADDED,eval-sanitize-2-r1-044-qmqs2.18d3d102cc1afcff,"reason=FailedScheduling count=None msg=0/6 nodes are available: 1 c_wall violated: 2 conflicting context pair(s) with node memory, 2 c_wall violated: 1 conflicting context pair(s) with node memory, 3 node(s) had untolerated taint(s). no new claims to deallocate, preemption: 0/6 nodes are available: 3 No preemption victims found for incoming pod, 3 Preemption is not helpful for scheduling."
0.0273,Node,ADDED,kind-worker,taints=0
0.0276,Event,ADDED,eval-sanitize-2-r1-044-qmqs2.18d3d102d9f01f92,"reason=FailedScheduling count=None msg=0/6 nodes are available: 1 c_wall violated: 2 conflicting context pair(s) with node memory, 5 node(s) had untolerated taint(s). no new claims to deallocate, preemption: 0/6 nodes are available: 1 No preemption victims found for incoming pod, 5 Preemption is not helpful for scheduling."
0.0278,Event,ADDED,eval-sanitize-2-r1-045-nh7bx.18d3d1025ae3855e,"reason=FailedScheduling count=None msg=0/6 nodes are available: 1 c_wall violated: 1 conflicting context pair(s) with node memory, 5 node(s) had untolerated taint(s). no new claims to deallocate, preemption: 0/6 nodes are available: 1 No preemption victims found for incoming pod, 5 Preemption is not helpful for scheduling."
0.028,Event,ADDED,eval-sanitize-2-r1-045-nh7bx.18d3d10266774b1d,"reason=FailedScheduling count=None msg=0/6 nodes are available: 2 c_wall violated: 1 conflicting context pair(s) with node memory, 4 node(s) had untolerated taint(s). no new claims to deallocate, preemption: 0/6 nodes are available: 2 No preemption victims found for incoming pod, 4 Preemption is not helpful for scheduling."
0.0284,Event,ADDED,eval-sanitize-2-r1-045-nh7bx.18d3d1027a937acb,"reason=FailedScheduling count=None msg=0/6 nodes are available: 3 c_wall violated: 1 conflicting context pair(s) with node memory, 3 node(s) had untolerated taint(s). no new claims to deallocate, preemption: 0/6 nodes are available: 3 No preemption victims found for incoming pod, 3 Preemption is not helpful for scheduling."
0.0286,Event,ADDED,eval-sanitize-2-r1-045-nh7bx.18d3d102cdbeb596,"reason=FailedScheduling count=None msg=0/6 nodes are available: 1 c_wall violated: 2 conflicting context pair(s) with node memory, 2 c_wall violated: 1 conflicting context pair(s) with node memory, 3 node(s) had untolerated taint(s). no new claims to deallocate, preemption: 0/6 nodes are available: 3 No preemption victims found for incoming pod, 3 Preemption is not helpful for scheduling."
0.0288,Event,ADDED,eval-sanitize-2-r1-045-nh7bx.18d3d102d9b6cded,"reason=FailedScheduling count=None msg=0/6 nodes are available: 1 c_wall violated: 2 conflicting context pair(s) with node memory, 5 node(s) had untolerated taint(s). no new claims to deallocate, preemption: 0/6 nodes are available: 1 No preemption victims found for incoming pod, 5 Preemption is not helpful for scheduling."
0.0306,Node,ADDED,kind-worker2,taints=0
0.0313,Event,ADDED,eval-sanitize-2-r1-049-4mlwq.18d3d10337b429ac,"reason=FailedScheduling count=None msg=0/6 nodes are available: 1 c_wall violated: 1 conflicting context pair(s) with node memory, 5 node(s) had untolerated taint(s). no new claims to deallocate, preemption: 0/6 nodes are available: 1 No preemption victims found for incoming pod, 5 Preemption is not helpful for scheduling."
0.0317,Event,ADDED,eval-sanitize-2-r1-055-pt5vj.18d3d104d2f03aa1,"reason=FailedScheduling count=None msg=0/6 nodes are available: 1 c_wall violated: 4 conflicting context pair(s) with node memory, 5 node(s) had untolerated taint(s). no new claims to deallocate, preemption: 0/6 nodes are available: 1 No preemption victims found for incoming pod, 5 Preemption is not helpful for scheduling."
0.032,Event,ADDED,eval-sanitize-2-r1-055-pt5vj.18d3d104da0ce76c,"reason=FailedScheduling count=None msg=0/6 nodes are available: 1 c_wall violated: 4 conflicting context pair(s) with node memory, 5 node(s) had untolerated taint(s). no new claims to deallocate, preemption: 0/6 nodes are available: 1 No preemption victims found for incoming pod, 5 Preemption is not helpful for scheduling."
0.0324,Event,ADDED,eval-sanitize-2-r1-056-mlt6x.18d3d104da443e57,"reason=FailedScheduling count=None msg=0/6 nodes are available: 1 c_wall violated: 4 conflicting context pair(s) with node memory, 5 node(s) had untolerated taint(s). no new claims to deallocate, preemption: 0/6 nodes are available: 1 No preemption victims found for incoming pod, 5 Preemption is not helpful for scheduling."
0.0326,Event,ADDED,eval-sanitize-2-r1-057-chpmz.18d3d10514b8bec5,"reason=FailedScheduling count=None msg=0/6 nodes are available: 1 c_wall violated: 1 conflicting context pair(s) with node memory, 5 node(s) had untolerated taint(s). no new claims to deallocate, preemption: 0/6 nodes are available: 1 No preemption victims found for incoming pod, 5 Preemption is not helpful for scheduling."
0.0337,Node,ADDED,kind-worker3,taints=0
0.0347,Node,ADDED,kind-worker4,taints=0
0.0351,TaskRequest,ADDED,eval-sanitize-2-r3-000,phase=None job=None
0.0354,Event,ADDED,eval-sanitize-2-r1-058-j6wzt.18d3d1057317bc4f,"reason=FailedScheduling count=None msg=0/6 nodes are available: 1 c_wall violated: 1 conflicting context pair(s) with node memory, 5 node(s) had untolerated taint(s). no new claims to deallocate, preemption: 0/6 nodes are available: 1 No preemption victims found for incoming pod, 5 Preemption is not helpful for scheduling."
0.0356,Event,ADDED,eval-sanitize-2-r1-062-82jrc.18d3d1063e6bd98a,"reason=FailedScheduling count=None msg=0/6 nodes are available: 1 c_wall violated: 1 conflicting context pair(s) with node memory, 5 node(s) had untolerated taint(s). no new claims to deallocate, preemption: 0/6 nodes are available: 1 No preemption victims found for incoming pod, 5 Preemption is not helpful for scheduling."
0.0358,Event,ADDED,eval-sanitize-2-r1-062-82jrc.18d3d1067bd11e8d,"reason=FailedScheduling count=None msg=0/6 nodes are available: 1 c_wall violated: 2 conflicting context pair(s) with node memory, 5 node(s) had untolerated taint(s). no new claims to deallocate, preemption: 0/6 nodes are available: 1 No preemption victims found for incoming pod, 5 Preemption is not helpful for scheduling."
0.0369,Node,ADDED,kind-worker5,taints=0
0.0372,Event,ADDED,eval-sanitize-2-r1-064-8xhvn.18d3d106b5be4626,"reason=FailedScheduling count=None msg=0/6 nodes are available: 1 c_wall violated: 1 conflicting context pair(s) with node memory, 5 node(s) had untolerated taint(s). no new claims to deallocate, preemption: 0/6 nodes are available: 1 No preemption victims found for incoming pod, 5 Preemption is not helpful for scheduling."
0.0374,Event,ADDED,eval-sanitize-2-r1-066-9hdg9.18d3d1080a849509,"reason=FailedScheduling count=None msg=0/6 nodes are available: 1 c_wall violated: 2 conflicting context pair(s) with node memory, 5 node(s) had untolerated taint(s). no new claims to deallocate, preemption: 0/6 nodes are available: 1 No preemption victims found for incoming pod, 5 Preemption is not helpful for scheduling."
0.0376,Event,ADDED,eval-sanitize-2-r1-067-bkrpl.18d3d1080add570a,"reason=FailedScheduling count=None msg=0/6 nodes are available: 1 c_wall violated: 2 conflicting context pair(s) with node memory, 5 node(s) had untolerated taint(s). no new claims to deallocate, preemption: 0/6 nodes are available: 1 No preemption victims found for incoming pod, 5 Preemption is not helpful for scheduling."
0.038,Event,ADDED,eval-sanitize-2-r1-070-bt2ks.18d3d1081b910e54,"reason=FailedScheduling count=None msg=0/6 nodes are available: 1 c_wall violated: 1 conflicting context pair(s) with node memory, 5 node(s) had untolerated taint(s). no new claims to deallocate, preemption: 0/6 nodes are available: 1 No preemption victims found for incoming pod, 5 Preemption is not helpful for scheduling."
0.0382,Event,ADDED,eval-sanitize-2-r1-072-6qfr9.18d3d10964faf0b4,"reason=FailedScheduling count=None msg=0/6 nodes are available: 1 c_wall violated: 2 conflicting context pair(s) with node memory, 5 node(s) had untolerated taint(s). no new claims to deallocate, preemption: 0/6 nodes are available: 1 No preemption victims found for incoming pod, 5 Preemption is not helpful for scheduling."
0.0384,Event,ADDED,eval-sanitize-2-r1-072-6qfr9.18d3d1099a7125a7,"reason=FailedScheduling count=None msg=0/6 nodes are available: 2 c_wall violated: 2 conflicting context pair(s) with node memory, 4 node(s) had untolerated taint(s). no new claims to deallocate, preemption: 0/6 nodes are available: 2 No preemption victims found for incoming pod, 4 Preemption is not helpful for scheduling."
0.0386,Event,ADDED,eval-sanitize-2-r1-072-6qfr9.18d3d109f20ce905,"reason=FailedScheduling count=None msg=0/6 nodes are available: 1 c_wall violated: 2 conflicting context pair(s) with node memory, 5 node(s) had untolerated taint(s). no new claims to deallocate, preemption: 0/6 nodes are available: 1 No preemption victims found for incoming pod, 5 Preemption is not helpful for scheduling."
0.0388,Event,ADDED,eval-sanitize-2-r1-073-twh2n.18d3d109652df503,"reason=FailedScheduling count=None msg=0/6 nodes are available: 1 c_wall violated: 2 conflicting context pair(s) with node memory, 5 node(s) had untolerated taint(s). no new claims to deallocate, preemption: 0/6 nodes are available: 1 No preemption victims found for incoming pod, 5 Preemption is not helpful for scheduling."
0.039,Event,ADDED,eval-sanitize-2-r1-075-88zts.18d3d10965573d35,"reason=FailedScheduling count=None msg=0/6 nodes are available: 1 c_wall violated: 1 conflicting context pair(s) with node memory, 5 node(s) had untolerated taint(s). no new claims to deallocate, preemption: 0/6 nodes are available: 1 No preemption victims found for incoming pod, 5 Preemption is not helpful for scheduling."
0.0394,Event,ADDED,eval-sanitize-2-r1-075-88zts.18d3d1099a29c03e,"reason=FailedScheduling count=None msg=0/6 nodes are available: 2 c_wall violated: 1 conflicting context pair(s) with node memory, 4 node(s) had untolerated taint(s). no new claims to deallocate, preemption: 0/6 nodes are available: 2 No preemption victims found for incoming pod, 4 Preemption is not helpful for scheduling."
0.0395,Event,ADDED,eval-sanitize-2-r1-075-88zts.18d3d109f1e557a6,"reason=FailedScheduling count=None msg=0/6 nodes are available: 1 c_wall violated: 1 conflicting context pair(s) with node memory, 5 node(s) had untolerated taint(s). no new claims to deallocate, preemption: 0/6 nodes are available: 1 No preemption victims found for incoming pod, 5 Preemption is not helpful for scheduling."
0.0397,Event,ADDED,eval-sanitize-2-r1-076-ttcm4.18d3d1098173edca,"reason=FailedScheduling count=None msg=0/6 nodes are available: 1 c_wall violated: 1 conflicting context pair(s) with node memory, 5 node(s) had untolerated taint(s). no new claims to deallocate, preemption: 0/6 nodes are available: 1 No preemption victims found for incoming pod, 5 Preemption is not helpful for scheduling."
0.0401,Event,ADDED,eval-sanitize-2-r1-078-wmv2z.18d3d109f8453d82,"reason=FailedScheduling count=None msg=0/6 nodes are available: 1 c_wall violated: 1 conflicting context pair(s) with node memory, 5 node(s) had untolerated taint(s). no new claims to deallocate, preemption: 0/6 nodes are available: 1 No preemption victims found for incoming pod, 5 Preemption is not helpful for scheduling."
0.0403,Event,ADDED,eval-sanitize-2-r1-080-wtxtp.18d3d10a7020ac48,"reason=FailedScheduling count=None msg=0/6 nodes are available: 2 c_wall violated: 1 conflicting context pair(s) with node memory, 4 node(s) had untolerated taint(s). no new claims to deallocate, preemption: 0/6 nodes are available: 2 No preemption victims found for incoming pod, 4 Preemption is not helpful for scheduling."
0.0406,Event,ADDED,eval-sanitize-2-r1-080-wtxtp.18d3d10aaa836f11,"reason=FailedScheduling count=None msg=0/6 nodes are available: 1 c_wall violated: 1 conflicting context pair(s) with node memory, 5 node(s) had untolerated taint(s). no new claims to deallocate, preemption: 0/6 nodes are available: 1 No preemption victims found for incoming pod, 5 Preemption is not helpful for scheduling."
0.0408,Event,ADDED,eval-sanitize-2-r1-080-wtxtp.18d3d10aacc1ed75,"reason=FailedScheduling count=None msg=0/6 nodes are available: 1 c_wall violated: 2 conflicting context pair(s) with node memory, 5 node(s) had untolerated taint(s). no new claims to deallocate, preemption: 0/6 nodes are available: 1 No preemption victims found for incoming pod, 5 Preemption is not helpful for scheduling."
0.041,Event,ADDED,eval-sanitize-2-r1-082-ncrsp.18d3d10b7b89cb61,"reason=FailedScheduling count=None msg=0/6 nodes are available: 1 c_wall violated: 1 conflicting context pair(s) with node memory, 5 node(s) had untolerated taint(s). no new claims to deallocate, preemption: 0/6 nodes are available: 1 No preemption victims found for incoming pod, 5 Preemption is not helpful for scheduling."
0.0413,Event,ADDED,eval-sanitize-2-r1-082-ncrsp.18d3d10b9b2b0152,"reason=FailedScheduling count=None msg=0/6 nodes are available: 1 c_wall violated: 2 conflicting context pair(s) with node memory, 5 node(s) had untolerated taint(s). no new claims to deallocate, preemption: 0/6 nodes are available: 1 No preemption victims found for incoming pod, 5 Preemption is not helpful for scheduling."
0.0415,Event,ADDED,eval-sanitize-2-r1-082-ncrsp.18d3d10c7e0047c0,"reason=FailedScheduling count=None msg=0/6 nodes are available: 1 c_wall violated: 1 conflicting context pair(s) with node memory, 5 node(s) had untolerated taint(s). no new claims to deallocate, preemption: 0/6 nodes are available: 1 No preemption victims found for incoming pod, 5 Preemption is not helpful for scheduling."
0.0418,Event,ADDED,eval-sanitize-2-r1-084-j2b28.18d3d10b7bb676e2,"reason=FailedScheduling count=None msg=0/6 nodes are available: 1 c_wall violated: 1 conflicting context pair(s) with node memory, 5 node(s) had untolerated taint(s). no new claims to deallocate, preemption: 0/6 nodes are available: 1 No preemption victims found for incoming pod, 5 Preemption is not helpful for scheduling."
0.0423,Event,ADDED,eval-sanitize-2-r1-084-j2b28.18d3d10b9af96271,"reason=FailedScheduling count=None msg=0/6 nodes are available: 1 c_wall violated: 2 conflicting context pair(s) with node memory, 5 node(s) had untolerated taint(s). no new claims to deallocate, preemption: 0/6 nodes are available: 1 No preemption victims found for incoming pod, 5 Preemption is not helpful for scheduling."
0.0426,Event,ADDED,eval-sanitize-2-r1-084-j2b28.18d3d10c7e312a7c,"reason=FailedScheduling count=None msg=0/6 nodes are available: 1 c_wall violated: 1 conflicting context pair(s) with node memory, 5 node(s) had untolerated taint(s). no new claims to deallocate, preemption: 0/6 nodes are available: 1 No preemption victims found for incoming pod, 5 Preemption is not helpful for scheduling."
0.0428,Event,ADDED,eval-sanitize-2-r1-086-484rj.18d3d10bd5dcc012,"reason=FailedScheduling count=None msg=0/6 nodes are available: 1 c_wall violated: 1 conflicting context pair(s) with node memory, 5 node(s) had untolerated taint(s). no new claims to deallocate, preemption: 0/6 nodes are available: 1 No preemption victims found for incoming pod, 5 Preemption is not helpful for scheduling."
0.0429,TaskRequest,MODIFIED,eval-sanitize-2-r3-000,phase=Pending job=None
0.0432,Event,ADDED,eval-sanitize-2-r1-087-88smk.18d3d10c7e5e956d,"reason=FailedScheduling count=None msg=0/6 nodes are available: 1 c_wall violated: 1 conflicting context pair(s) with node memory, 5 node(s) had untolerated taint(s). no new claims to deallocate, preemption: 0/6 nodes are available: 1 No preemption victims found for incoming pod, 5 Preemption is not helpful for scheduling."
0.0434,Event,ADDED,eval-sanitize-2-r1-087-88smk.18d3d10cd6a7a32c,"reason=FailedScheduling count=None msg=0/6 nodes are available: 2 c_wall violated: 1 conflicting context pair(s) with node memory, 4 node(s) had untolerated taint(s). no new claims to deallocate, preemption: 0/6 nodes are available: 2 No preemption victims found for incoming pod, 4 Preemption is not helpful for scheduling."
0.0436,Event,ADDED,eval-sanitize-2-r1-087-88smk.18d3d10cf8efedf2,"reason=FailedScheduling count=None msg=0/6 nodes are available: 1 c_wall violated: 1 conflicting context pair(s) with node memory, 5 node(s) had untolerated taint(s). no new claims to deallocate, preemption: 0/6 nodes are available: 1 No preemption victims found for incoming pod, 5 Preemption is not helpful for scheduling."
0.0439,Event,ADDED,eval-sanitize-2-r1-088-wtjq7.18d3d10c81801567,"reason=FailedScheduling count=None msg=0/6 nodes are available: 1 c_wall violated: 1 conflicting context pair(s) with node memory, 5 node(s) had untolerated taint(s). no new claims to deallocate, preemption: 0/6 nodes are available: 1 No preemption victims found for incoming pod, 5 Preemption is not helpful for scheduling."
0.0441,Event,ADDED,eval-sanitize-2-r1-089-fshln.18d3d10c881d057e,"reason=FailedScheduling count=None msg=0/6 nodes are available: 1 c_wall violated: 1 conflicting context pair(s) with node memory, 5 node(s) had untolerated taint(s). no new claims to deallocate, preemption: 0/6 nodes are available: 1 No preemption victims found for incoming pod, 5 Preemption is not helpful for scheduling."
0.0443,Event,ADDED,eval-sanitize-2-r1-089-fshln.18d3d10cd7010b5f,"reason=FailedScheduling count=None msg=0/6 nodes are available: 2 c_wall violated: 1 conflicting context pair(s) with node memory, 4 node(s) had untolerated taint(s). no new claims to deallocate, preemption: 0/6 nodes are available: 2 No preemption victims found for incoming pod, 4 Preemption is not helpful for scheduling."
0.0445,Event,ADDED,eval-sanitize-2-r1-089-fshln.18d3d10cf91bdad8,"reason=FailedScheduling count=None msg=0/6 nodes are available: 1 c_wall violated: 1 conflicting context pair(s) with node memory, 5 node(s) had untolerated taint(s). no new claims to deallocate, preemption: 0/6 nodes are available: 1 No preemption victims found for incoming pod, 5 Preemption is not helpful for scheduling."
0.0447,Event,ADDED,eval-sanitize-2-r1-089-fshln.18d3d10d75f47e4e,"reason=FailedScheduling count=None msg=0/6 nodes are available: 1 c_wall violated: 2 conflicting context pair(s) with node memory, 5 node(s) had untolerated taint(s). no new claims to deallocate, preemption: 0/6 nodes are available: 1 No preemption victims found for incoming pod, 5 Preemption is not helpful for scheduling."
0.0452,Event,ADDED,eval-sanitize-2-r1-090-972ws.18d3d10cc3aef0ac,"reason=FailedScheduling count=None msg=0/6 nodes are available: 1 c_wall violated: 1 conflicting context pair(s) with node memory, 5 node(s) had untolerated taint(s). no new claims to deallocate, preemption: 0/6 nodes are available: 1 No preemption victims found for incoming pod, 5 Preemption is not helpful for scheduling."
0.0454,Event,ADDED,eval-sanitize-2-r1-090-972ws.18d3d10cda9db9fb,"reason=FailedScheduling count=None msg=0/6 nodes are available: 2 c_wall violated: 1 conflicting context pair(s) with node memory, 4 node(s) had untolerated taint(s). no new claims to deallocate, preemption: 0/6 nodes are available: 2 No preemption victims found for incoming pod, 4 Preemption is not helpful for scheduling."
0.0457,Event,ADDED,eval-sanitize-2-r1-090-972ws.18d3d10cf94304c9,"reason=FailedScheduling count=None msg=0/6 nodes are available: 1 c_wall violated: 1 conflicting context pair(s) with node memory, 5 node(s) had untolerated taint(s). no new claims to deallocate, preemption: 0/6 nodes are available: 1 No preemption victims found for incoming pod, 5 Preemption is not helpful for scheduling."
0.046,Event,ADDED,eval-sanitize-2-r1-091-k8x2x.18d3d10cff16be0e,"reason=FailedScheduling count=None msg=0/6 nodes are available: 1 c_wall violated: 2 conflicting context pair(s) with node memory, 5 node(s) had untolerated taint(s). no new claims to deallocate, preemption: 0/6 nodes are available: 1 No preemption victims found for incoming pod, 5 Preemption is not helpful for scheduling."
0.0462,Event,ADDED,eval-sanitize-2-r1-093-xbsd6.18d3d10d77b9daac,"reason=FailedScheduling count=None msg=0/6 nodes are available: 1 c_wall violated: 3 conflicting context pair(s) with node memory, 5 node(s) had untolerated taint(s). no new claims to deallocate, preemption: 0/6 nodes are available: 1 No preemption victims found for incoming pod, 5 Preemption is not helpful for scheduling."
0.0464,Event,ADDED,eval-sanitize-2-r1-093-xbsd6.18d3d10e211f62c8,"reason=FailedScheduling count=None msg=0/6 nodes are available: 1 c_wall violated: 1 conflicting context pair(s) with node memory, 5 node(s) had untolerated taint(s). no new claims to deallocate, preemption: 0/6 nodes are available: 1 No preemption victims found for incoming pod, 5 Preemption is not helpful for scheduling."
0.0466,Event,ADDED,eval-sanitize-2-r1-093-xbsd6.18d3d10e2220e53c,"reason=FailedScheduling count=None msg=0/6 nodes are available: 1 c_wall violated: 1 conflicting context pair(s) with node memory, 5 node(s) had untolerated taint(s). no new claims to deallocate, preemption: 0/6 nodes are available: 1 No preemption victims found for incoming pod, 5 Preemption is not helpful for scheduling."
0.0468,Event,ADDED,eval-sanitize-2-r1-096-ht5nh.18d3d10e28e3c7a8,"reason=FailedScheduling count=None msg=0/6 nodes are available: 1 c_wall violated: 1 conflicting context pair(s) with node memory, 5 node(s) had untolerated taint(s). no new claims to deallocate, preemption: 0/6 nodes are available: 1 No preemption victims found for incoming pod, 5 Preemption is not helpful for scheduling."
0.047,Event,ADDED,eval-sanitize-2-r1-096-ht5nh.18d3d10eca5f1ff8,"reason=FailedScheduling count=None msg=0/6 nodes are available: 1 c_wall violated: 1 conflicting context pair(s) with node memory, 5 node(s) had untolerated taint(s). no new claims to deallocate, preemption: 0/6 nodes are available: 1 No preemption victims found for incoming pod, 5 Preemption is not helpful for scheduling."
0.0472,Event,ADDED,eval-sanitize-2-r1-097-pqgfw.18d3d10e652baa44,"reason=FailedScheduling count=None msg=0/6 nodes are available: 1 c_wall violated: 1 conflicting context pair(s) with node memory, 5 node(s) had untolerated taint(s). no new claims to deallocate, preemption: 0/6 nodes are available: 1 No preemption victims found for incoming pod, 5 Preemption is not helpful for scheduling."
0.0473,Event,ADDED,eval-sanitize-2-r1-099-m4nhq.18d3d10edbee227a,"reason=FailedScheduling count=None msg=0/6 nodes are available: 1 c_wall violated: 1 conflicting context pair(s) with node memory, 5 node(s) had untolerated taint(s). no new claims to deallocate, preemption: 0/6 nodes are available: 1 No preemption victims found for incoming pod, 5 Preemption is not helpful for scheduling."
0.0475,Event,ADDED,eval-sanitize-2-r1-099-m4nhq.18d3d10fc9a7713d,"reason=FailedScheduling count=None msg=0/6 nodes are available: 1 c_wall violated: 1 conflicting context pair(s) with node memory, 5 node(s) had untolerated taint(s). no new claims to deallocate, preemption: 0/6 nodes are available: 1 No preemption victims found for incoming pod, 5 Preemption is not helpful for scheduling."
0.0574,Job,ADDED,eval-sanitize-2-r3-000,
0.064,TaskRequest,MODIFIED,eval-sanitize-2-r3-000,phase=Scheduled job=None
0.0674,Pod,ADDED,eval-sanitize-2-r3-000-d2spv,phase=Pending node=None
0.0694,Job,MODIFIED,eval-sanitize-2-r3-000,
0.0731,TaskRequest,MODIFIED,eval-sanitize-2-r3-000,phase=Scheduled job=None
0.0755,Event,ADDED,eval-sanitize-2-r3-000.18d3d18774c6748a,reason=SuccessfulCreate count=1 msg=Created pod: eval-sanitize-2-r3-000-d2spv
0.0824,Pod,MODIFIED,eval-sanitize-2-r3-000-d2spv,phase=Pending node=kind-worker2
0.0871,Event,ADDED,eval-sanitize-2-r3-000-d2spv.18d3d187759d5541,reason=Scheduled count=None msg=Successfully assigned compute/eval-sanitize-2-r3-000-d2spv to kind-worker2
0.0915,Pod,MODIFIED,eval-sanitize-2-r3-000-d2spv,phase=Pending node=kind-worker2
0.0935,Node,MODIFIED,kind-worker2,taints=0
0.1054,Node,MODIFIED,kind-worker2,taints=0
0.34,Node,MODIFIED,kind-worker2,taints=1
0.352,Node,MODIFIED,kind-worker2,taints=1
0.5037,Event,ADDED,eval-sanitize-2-r3-000-d2spv.18d3d1878e88956d,"reason=Pulled count=1 msg=Container image ""busybox:musl"" already present on machine"
0.5212,Event,ADDED,eval-sanitize-2-r3-000-d2spv.18d3d1878f97c7f7,reason=Created count=1 msg=Created container: task
0.5904,Event,ADDED,eval-sanitize-2-r3-000-d2spv.18d3d18793b1d6be,reason=Started count=1 msg=Started container task
0.6473,Pod,MODIFIED,eval-sanitize-2-r3-000-d2spv,phase=Running node=kind-worker2
1.0198,TaskRequest,ADDED,eval-sanitize-2-r3-001,phase=None job=None
1.0234,TaskRequest,MODIFIED,eval-sanitize-2-r3-001,phase=Pending job=None
1.0378,Job,ADDED,eval-sanitize-2-r3-001,
1.0421,TaskRequest,MODIFIED,eval-sanitize-2-r3-001,phase=Scheduled job=None
1.0458,Pod,ADDED,eval-sanitize-2-r3-001-k9ccn,phase=Pending node=None
1.0472,Job,MODIFIED,eval-sanitize-2-r3-001,
1.0515,Event,ADDED,eval-sanitize-2-r3-001.18d3d187af18eb42,reason=SuccessfulCreate count=1 msg=Created pod: eval-sanitize-2-r3-001-k9ccn
1.0517,TaskRequest,MODIFIED,eval-sanitize-2-r3-001,phase=Scheduled job=None
1.0533,Pod,MODIFIED,eval-sanitize-2-r3-001-k9ccn,phase=Pending node=kind-worker
1.058,Event,ADDED,eval-sanitize-2-r3-001-k9ccn.18d3d187af8682db,reason=Scheduled count=None msg=Successfully assigned compute/eval-sanitize-2-r3-001-k9ccn to kind-worker
1.063,Node,MODIFIED,kind-worker,taints=0
1.0642,Pod,MODIFIED,eval-sanitize-2-r3-001-k9ccn,phase=Pending node=kind-worker
1.0723,Node,MODIFIED,kind-worker,taints=0
1.0734,Job,MODIFIED,eval-sanitize-2-r3-000,
1.0822,Job,MODIFIED,eval-sanitize-2-r3-000,
1.4821,Event,ADDED,eval-sanitize-2-r3-001-k9ccn.18d3d187c8ccdc85,"reason=Pulled count=1 msg=Container image ""busybox:musl"" already present on machine"
1.5013,Event,ADDED,eval-sanitize-2-r3-001-k9ccn.18d3d187c9ed94ff,reason=Created count=1 msg=Created container: task
1.5734,Event,ADDED,eval-sanitize-2-r3-001-k9ccn.18d3d187ce466455,reason=Started count=1 msg=Started container task
1.8669,Node,MODIFIED,kind-worker,taints=1
1.8794,Node,MODIFIED,kind-worker,taints=1
2.014,TaskRequest,ADDED,eval-sanitize-2-r3-002,phase=None job=None
2.0187,TaskRequest,MODIFIED,eval-sanitize-2-r3-002,phase=Pending job=None
2.0369,Job,ADDED,eval-sanitize-2-r3-002,
2.0438,Pod,ADDED,eval-sanitize-2-r3-002-bb2jg,phase=Pending node=None
2.0439,TaskRequest,MODIFIED,eval-sanitize-2-r3-002,phase=Scheduled job=None
2.0468,Job,MODIFIED,eval-sanitize-2-r3-002,
2.0504,Event,ADDED,eval-sanitize-2-r3-002.18d3d187ea8bd7a0,reason=SuccessfulCreate count=1 msg=Created pod: eval-sanitize-2-r3-002-bb2jg
2.0512,Job,MODIFIED,eval-sanitize-2-r3-001,
2.0526,TaskRequest,MODIFIED,eval-sanitize-2-r3-002,phase=Scheduled job=None
2.0536,Pod,MODIFIED,eval-sanitize-2-r3-002-bb2jg,phase=Pending node=kind-worker4
2.0569,Event,ADDED,eval-sanitize-2-r3-002-bb2jg.18d3d187eb2269ac,reason=Scheduled count=None msg=Successfully assigned compute/eval-sanitize-2-r3-002-bb2jg to kind-worker4
2.0609,Job,MODIFIED,eval-sanitize-2-r3-001,
2.0644,Node,MODIFIED,kind-worker4,taints=0
2.0664,Pod,MODIFIED,eval-sanitize-2-r3-002-bb2jg,phase=Pending node=kind-worker4
2.075,Node,MODIFIED,kind-worker4,taints=0
2.4412,Pod,MODIFIED,eval-sanitize-2-r3-001-k9ccn,phase=Running node=kind-worker
2.4623,Node,MODIFIED,kind-worker4,taints=1
2.4844,Event,ADDED,eval-sanitize-2-r3-002-bb2jg.18d3d188049156f4,"reason=Pulled count=1 msg=Container image ""busybox:musl"" already present on machine"
2.5038,Event,ADDED,eval-sanitize-2-r3-002-bb2jg.18d3d18805af25ca,reason=Created count=1 msg=Created container: task
2.5749,Event,ADDED,eval-sanitize-2-r3-002-bb2jg.18d3d18809fddf73,reason=Started count=1 msg=Started container task
2.6568,Node,MODIFIED,kind-worker4,taints=1
3.007,TaskRequest,ADDED,eval-sanitize-2-r3-003,phase=None job=None
3.0118,TaskRequest,MODIFIED,eval-sanitize-2-r3-003,phase=Pending job=None
3.0267,Job,ADDED,eval-sanitize-2-r3-003,
3.0324,TaskRequest,MODIFIED,eval-sanitize-2-r3-003,phase=Scheduled job=None
3.0343,Pod,ADDED,eval-sanitize-2-r3-003-fg2r7,phase=Pending node=None
3.0378,Job,MODIFIED,eval-sanitize-2-r3-003,
3.0396,Event,ADDED,eval-sanitize-2-r3-003.18d3d1882598e3c1,reason=SuccessfulCreate count=1 msg=Created pod: eval-sanitize-2-r3-003-fg2r7
3.0447,Pod,MODIFIED,eval-sanitize-2-r3-003-fg2r7,phase=Pending node=kind-worker5
3.0473,TaskRequest,MODIFIED,eval-sanitize-2-r3-003,phase=Scheduled job=None
3.0509,Job,MODIFIED,eval-sanitize-2-r3-002,
3.052,Event,ADDED,eval-sanitize-2-r3-003-fg2r7.18d3d1882632d39a,reason=Scheduled count=None msg=Successfully assigned compute/eval-sanitize-2-r3-003-fg2r7 to kind-worker5
3.0581,Pod,MODIFIED,eval-sanitize-2-r3-003-fg2r7,phase=Pending node=kind-worker5
3.0602,Node,MODIFIED,kind-worker5,taints=0
3.0613,Job,MODIFIED,eval-sanitize-2-r3-001,
3.0624,Job,MODIFIED,eval-sanitize-2-r3-002,
3.0696,Job,MODIFIED,eval-sanitize-2-r3-001,
3.0728,Node,MODIFIED,kind-worker5,taints=0
3.3731,Pod,MODIFIED,eval-sanitize-2-r3-002-bb2jg,phase=Running node=kind-worker4
3.4822,Event,ADDED,eval-sanitize-2-r3-003-fg2r7.18d3d1884003c0a5,"reason=Pulled count=1 msg=Container image ""busybox:musl"" already present on machine"
3.501,Event,ADDED,eval-sanitize-2-r3-003-fg2r7.18d3d188412bb976,reason=Created count=1 msg=Created container: task
3.5701,Event,ADDED,eval-sanitize-2-r3-003-fg2r7.18d3d188454e10e7,reason=Started count=1 msg=Started container task
4.0177,TaskRequest,ADDED,eval-sanitize-2-r3-004,phase=None job=None
4.0211,TaskRequest,MODIFIED,eval-sanitize-2-r3-004,phase=Pending job=None
4.0373,Job,ADDED,eval-sanitize-2-r3-004,
4.0396,Job,MODIFIED,eval-sanitize-2-r3-003,
4.0437,Pod,ADDED,eval-sanitize-2-r3-004-8tv8k,phase=Pending node=None
4.044,TaskRequest,MODIFIED,eval-sanitize-2-r3-004,phase=Scheduled job=None
4.047,Job,MODIFIED,eval-sanitize-2-r3-004,
4.0499,Event,ADDED,eval-sanitize-2-r3-004.18d3d18861cb7e76,reason=SuccessfulCreate count=1 msg=Created pod: eval-sanitize-2-r3-004-8tv8k
4.0523,TaskRequest,MODIFIED,eval-sanitize-2-r3-004,phase=Scheduled job=None
4.0557,Job,MODIFIED,eval-sanitize-2-r3-002,
4.058,Job,MODIFIED,eval-sanitize-2-r3-003,
4.059,Pod,MODIFIED,eval-sanitize-2-r3-004-8tv8k,phase=Pending node=kind-worker3
4.064,Event,ADDED,eval-sanitize-2-r3-004-8tv8k.18d3d18862b19beb,reason=Scheduled count=None msg=Successfully assigned compute/eval-sanitize-2-r3-004-8tv8k to kind-worker3
4.0665,Job,MODIFIED,eval-sanitize-2-r3-002,
4.0691,Node,MODIFIED,kind-worker3,taints=0
4.0712,Pod,MODIFIED,eval-sanitize-2-r3-004-8tv8k,phase=Pending node=kind-worker3
4.146,Node,MODIFIED,kind-worker3,taints=0
4.3309,Pod,MODIFIED,eval-sanitize-2-r3-003-fg2r7,phase=Running node=kind-worker5
4.4779,Node,MODIFIED,kind-worker3,taints=1
4.4799,Node,MODIFIED,kind-worker5,taints=1
4.502,Event,ADDED,eval-sanitize-2-r3-004-8tv8k.18d3d1887cb9a793,"reason=Pulled count=1 msg=Container image ""busybox:musl"" already present on machine"
4.5167,Event,ADDED,eval-sanitize-2-r3-004-8tv8k.18d3d1887dc820ba,reason=Created count=1 msg=Created container: task
4.5559,Node,MODIFIED,kind-worker3,taints=1
4.5805,Event,ADDED,eval-sanitize-2-r3-004-8tv8k.18d3d188818a4337,reason=Started count=1 msg=Started container task
4.6429,Node,MODIFIED,kind-worker5,taints=1
5.0078,TaskRequest,ADDED,eval-sanitize-2-r3-005,phase=None job=None
5.0111,TaskRequest,MODIFIED,eval-sanitize-2-r3-005,phase=Pending job=None
5.0264,Job,ADDED,eval-sanitize-2-r3-005,
5.0317,TaskRequest,MODIFIED,eval-sanitize-2-r3-005,phase=Scheduled job=None
5.0349,Job,MODIFIED,eval-sanitize-2-r3-005,
5.0358,Pod,ADDED,eval-sanitize-2-r3-005-mnkl6,phase=Pending node=None
5.0393,Pod,MODIFIED,eval-sanitize-2-r3-005-mnkl6,phase=Pending node=None
5.0427,Event,ADDED,eval-sanitize-2-r3-005.18d3d1889cdd2778,reason=SuccessfulCreate count=1 msg=Created pod: eval-sanitize-2-r3-005-mnkl6
5.0429,Event,ADDED,eval-sanitize-2-r3-005-mnkl6.18d3d1889ce75ae0,"reason=FailedScheduling count=None msg=0/6 nodes are available: 6 node(s) had untolerated taint(s). no new claims to deallocate, preemption: 0/6 nodes are available: 6 Preemption is not helpful for scheduling."
5.0429,TaskRequest,MODIFIED,eval-sanitize-2-r3-005,phase=Scheduled job=None
5.0449,Job,MODIFIED,eval-sanitize-2-r3-003,
5.0475,Job,MODIFIED,eval-sanitize-2-r3-004,
5.0536,Job,MODIFIED,eval-sanitize-2-r3-003,
5.0553,Job,MODIFIED,eval-sanitize-2-r3-004,
5.33,Pod,MODIFIED,eval-sanitize-2-r3-004-8tv8k,phase=Running node=kind-worker3
6.016,TaskRequest,ADDED,eval-sanitize-2-r3-006,phase=None job=None
6.02,TaskRequest,MODIFIED,eval-sanitize-2-r3-006,phase=Pending job=None
6.0359,Job,ADDED,eval-sanitize-2-r3-006,
6.0403,Job,MODIFIED,eval-sanitize-2-r3-005,
6.0433,Pod,ADDED,eval-sanitize-2-r3-006-m98bf,phase=Pending node=None
6.0434,TaskRequest,MODIFIED,eval-sanitize-2-r3-006,phase=Scheduled job=None
6.0464,Job,MODIFIED,eval-sanitize-2-r3-006,
6.0501,Pod,MODIFIED,eval-sanitize-2-r3-006-m98bf,phase=Pending node=None
6.0505,Event,ADDED,eval-sanitize-2-r3-006.18d3d188d8f0149a,reason=SuccessfulCreate count=1 msg=Created pod: eval-sanitize-2-r3-006-m98bf
6.0507,Event,ADDED,eval-sanitize-2-r3-006-m98bf.18d3d188d8fca8b6,"reason=FailedScheduling count=None msg=0/6 nodes are available: 6 node(s) had untolerated taint(s). no new claims to deallocate, preemption: 0/6 nodes are available: 6 Preemption is not helpful for scheduling."
6.0518,TaskRequest,MODIFIED,eval-sanitize-2-r3-006,phase=Scheduled job=None
6.0546,Job,MODIFIED,eval-sanitize-2-r3-004,
6.0553,Job,MODIFIED,eval-sanitize-2-r3-005,
6.0656,Job,MODIFIED,eval-sanitize-2-r3-004,
7.0178,TaskRequest,ADDED,eval-sanitize-2-r3-007,phase=None job=None
7.0216,TaskRequest,MODIFIED,eval-sanitize-2-r3-007,phase=Pending job=None
7.0374,Job,ADDED,eval-sanitize-2-r3-007,
7.0443,Pod,ADDED,eval-sanitize-2-r3-007-t9hwl,phase=Pending node=None
7.0444,TaskRequest,MODIFIED,eval-sanitize-2-r3-007,phase=Scheduled job=None
7.0475,Job,MODIFIED,eval-sanitize-2-r3-007,
7.05,Pod,MODIFIED,eval-sanitize-2-r3-007-t9hwl,phase=Pending node=None
7.0507,Job,MODIFIED,eval-sanitize-2-r3-006,
7.0512,Event,ADDED,eval-sanitize-2-r3-007.18d3d189149eb890,reason=SuccessfulCreate count=1 msg=Created pod: eval-sanitize-2-r3-007-t9hwl
7.0514,Event,ADDED,eval-sanitize-2-r3-007-t9hwl.18d3d18914ac490d,"reason=FailedScheduling count=None msg=0/6 nodes are available: 6 node(s) had untolerated taint(s). no new claims to deallocate, preemption: 0/6 nodes are available: 6 Preemption is not helpful for scheduling."
7.0587,Job,MODIFIED,eval-sanitize-2-r3-006,
7.0588,TaskRequest,MODIFIED,eval-sanitize-2-r3-007,phase=Scheduled job=None
8.0086,TaskRequest,ADDED,eval-sanitize-2-r3-008,phase=None job=None
8.012,TaskRequest,MODIFIED,eval-sanitize-2-r3-008,phase=Pending job=None
8.0277,Job,ADDED,eval-sanitize-2-r3-008,
8.0326,TaskRequest,MODIFIED,eval-sanitize-2-r3-008,phase=Scheduled job=None
8.0358,Pod,ADDED,eval-sanitize-2-r3-008-7vg7g,phase=Pending node=None
8.0376,Job,MODIFIED,eval-sanitize-2-r3-008,
8.0412,Pod,MODIFIED,eval-sanitize-2-r3-008-7vg7g,phase=Pending node=None
8.0429,Event,ADDED,eval-sanitize-2-r3-008.18d3d1894fb87914,reason=SuccessfulCreate count=1 msg=Created pod: eval-sanitize-2-r3-008-7vg7g
8.0432,Event,ADDED,eval-sanitize-2-r3-008-7vg7g.18d3d1894fc2f2ff,"reason=FailedScheduling count=None msg=0/6 nodes are available: 6 node(s) had untolerated taint(s). no new claims to deallocate, preemption: 0/6 nodes are available: 6 Preemption is not helpful for scheduling."
8.0433,TaskRequest,MODIFIED,eval-sanitize-2-r3-008,phase=Scheduled job=None
8.0486,Job,MODIFIED,eval-sanitize-2-r3-007,
8.0568,Job,MODIFIED,eval-sanitize-2-r3-007,
9.0082,TaskRequest,ADDED,eval-sanitize-2-r3-009,phase=None job=None
9.0128,TaskRequest,MODIFIED,eval-sanitize-2-r3-009,phase=Pending job=None
9.0274,Job,ADDED,eval-sanitize-2-r3-009,
9.0321,TaskRequest,MODIFIED,eval-sanitize-2-r3-009,phase=Scheduled job=None
9.0337,Pod,ADDED,eval-sanitize-2-r3-009-j7dq8,phase=Pending node=None
9.0372,Job,MODIFIED,eval-sanitize-2-r3-009,
9.0397,Event,ADDED,eval-sanitize-2-r3-009.18d3d1898b3b2333,reason=SuccessfulCreate count=1 msg=Created pod: eval-sanitize-2-r3-009-j7dq8
9.041,Pod,MODIFIED,eval-sanitize-2-r3-009-j7dq8,phase=Pending node=None
9.0414,Event,ADDED,eval-sanitize-2-r3-009-j7dq8.18d3d1898b42fa65,"reason=FailedScheduling count=None msg=0/6 nodes are available: 6 node(s) had untolerated taint(s). no new claims to deallocate, preemption: 0/6 nodes are available: 6 Preemption is not helpful for scheduling."
9.0422,Job,MODIFIED,eval-sanitize-2-r3-008,
9.0434,TaskRequest,MODIFIED,eval-sanitize-2-r3-009,phase=Scheduled job=None
9.0506,Job,MODIFIED,eval-sanitize-2-r3-008,
10.0066,TaskRequest,ADDED,eval-sanitize-2-r3-010,phase=None job=None
10.0117,TaskRequest,MODIFIED,eval-sanitize-2-r3-010,phase=Pending job=None
10.0258,Job,ADDED,eval-sanitize-2-r3-010,
10.0308,TaskRequest,MODIFIED,eval-sanitize-2-r3-010,phase=Scheduled job=None
10.0332,Pod,ADDED,eval-sanitize-2-r3-010-c57dg,phase=Pending node=None
10.0345,Job,MODIFIED,eval-sanitize-2-r3-010,
10.0392,TaskRequest,MODIFIED,eval-sanitize-2-r3-010,phase=Scheduled job=None
10.0397,Event,ADDED,eval-sanitize-2-r3-010.18d3d189c6a88fee,reason=SuccessfulCreate count=1 msg=Created pod: eval-sanitize-2-r3-010-c57dg
10.0399,Event,ADDED,eval-sanitize-2-r3-010-c57dg.18d3d189c6b231e2,"reason=FailedScheduling count=None msg=0/6 nodes are available: 6 node(s) had untolerated taint(s). no new claims to deallocate, preemption: 0/6 nodes are available: 6 Preemption is not helpful for scheduling."
10.0407,Job,MODIFIED,eval-sanitize-2-r3-009,
10.0415,Pod,MODIFIED,eval-sanitize-2-r3-010-c57dg,phase=Pending node=None
10.0499,Job,MODIFIED,eval-sanitize-2-r3-009,
10.668,Pod,MODIFIED,eval-sanitize-2-r3-000-d2spv,phase=Running node=kind-worker2
11.0221,TaskRequest,ADDED,eval-sanitize-2-r3-011,phase=None job=None
11.0258,TaskRequest,MODIFIED,eval-sanitize-2-r3-011,phase=Pending job=None
11.0377,Job,MODIFIED,eval-sanitize-2-r3-010,
11.04,Job,ADDED,eval-sanitize-2-r3-011,
11.0456,Pod,ADDED,eval-sanitize-2-r3-011-vt6dt,phase=Pending node=None
11.0471,TaskRequest,MODIFIED,eval-sanitize-2-r3-011,phase=Scheduled job=None
11.0481,Job,MODIFIED,eval-sanitize-2-r3-011,
11.0514,Event,ADDED,eval-sanitize-2-r3-011.18d3d18a030ae6a5,reason=SuccessfulCreate count=1 msg=Created pod: eval-sanitize-2-r3-011-vt6dt
11.0516,Event,ADDED,eval-sanitize-2-r3-011-vt6dt.18d3d18a03191bc7,"reason=FailedScheduling count=None msg=0/6 nodes are available: 6 node(s) had untolerated taint(s). no new claims to deallocate, preemption: 0/6 nodes are available: 6 Preemption is not helpful for scheduling."
11.0525,Pod,MODIFIED,eval-sanitize-2-r3-011-vt6dt,phase=Pending node=None
11.0567,TaskRequest,MODIFIED,eval-sanitize-2-r3-011,phase=Scheduled job=None
11.058,Job,MODIFIED,eval-sanitize-2-r3-010,
11.6747,Job,MODIFIED,eval-sanitize-2-r3-000,
11.6858,Job,MODIFIED,eval-sanitize-2-r3-000,
11.7735,Pod,MODIFIED,eval-sanitize-2-r3-000-d2spv,phase=Succeeded node=kind-worker2
12.0098,TaskRequest,ADDED,eval-sanitize-2-r3-012,phase=None job=None
12.0137,TaskRequest,MODIFIED,eval-sanitize-2-r3-012,phase=Pending job=None
12.0205,Node,MODIFIED,kind-worker2,taints=1
12.0286,Job,ADDED,eval-sanitize-2-r3-012,
12.0347,TaskRequest,MODIFIED,eval-sanitize-2-r3-012,phase=Scheduled job=None
12.0382,Pod,ADDED,eval-sanitize-2-r3-012-4v9kc,phase=Pending node=None
12.0402,Job,MODIFIED,eval-sanitize-2-r3-012,
12.0441,TaskRequest,MODIFIED,eval-sanitize-2-r3-012,phase=Scheduled job=None
12.0448,Event,ADDED,eval-sanitize-2-r3-012.18d3d18a3e2ccb01,reason=SuccessfulCreate count=1 msg=Created pod: eval-sanitize-2-r3-012-4v9kc
12.045,Event,ADDED,eval-sanitize-2-r3-012-4v9kc.18d3d18a3e395b94,"reason=FailedScheduling count=None msg=0/6 nodes are available: 6 node(s) had untolerated taint(s). no new claims to deallocate, preemption: 0/6 nodes are available: 6 Preemption is not helpful for scheduling."
12.0461,Pod,MODIFIED,eval-sanitize-2-r3-012-4v9kc,phase=Pending node=None
12.0474,Node,MODIFIED,kind-worker2,taints=1
12.0506,Job,MODIFIED,eval-sanitize-2-r3-011,
12.0557,Node,MODIFIED,kind-worker2,taints=0
12.0597,Job,MODIFIED,eval-sanitize-2-r3-011,
12.0625,Pod,MODIFIED,eval-sanitize-2-r3-005-mnkl6,phase=Pending node=kind-worker2
12.066,Event,ADDED,eval-sanitize-2-r3-005-mnkl6.18d3d18a3fa31dbd,reason=Scheduled count=None msg=Successfully assigned compute/eval-sanitize-2-r3-005-mnkl6 to kind-worker2
12.0704,Pod,MODIFIED,eval-sanitize-2-r3-006-m98bf,phase=Pending node=kind-worker2
12.0733,Pod,MODIFIED,eval-sanitize-2-r3-005-mnkl6,phase=Pending node=kind-worker2
12.0747,Node,MODIFIED,kind-worker2,taints=0
12.0786,Event,ADDED,eval-sanitize-2-r3-007-t9hwl.18d3d18a40028289,"reason=FailedScheduling count=None msg=0/6 nodes are available: 1 c_wall violated: 2 conflicting context pair(s) with node memory, 5 node(s) had untolerated taint(s). no new claims to deallocate, preemption: 0/6 nodes are available: 1 No preemption victims found for incoming pod, 5 Preemption is not helpful for scheduling."
12.0789,Event,ADDED,eval-sanitize-2-r3-006-m98bf.18d3d18a401ec9c5,reason=Scheduled count=None msg=Successfully assigned compute/eval-sanitize-2-r3-006-m98bf to kind-worker2
12.0799,Pod,MODIFIED,eval-sanitize-2-r3-007-t9hwl,phase=Pending node=None
12.0843,Pod,MODIFIED,eval-sanitize-2-r3-006-m98bf,phase=Pending node=kind-worker2
12.0877,Pod,MODIFIED,eval-sanitize-2-r3-008-7vg7g,phase=Pending node=None
12.0881,Event,ADDED,eval-sanitize-2-r3-008-7vg7g.18d3d18a40def6be,"reason=FailedScheduling count=None msg=0/6 nodes are available: 1 c_wall violated: 2 conflicting context pair(s) with node memory, 5 node(s) had untolerated taint(s). no new claims to deallocate, preemption: 0/6 nodes are available: 1 No preemption victims found for incoming pod, 5 Preemption is not helpful for scheduling."
12.0958,Pod,MODIFIED,eval-sanitize-2-r3-009-j7dq8,phase=Pending node=None
12.096,Event,ADDED,eval-sanitize-2-r3-009-j7dq8.18d3d18a4159ee93,"reason=FailedScheduling count=None msg=0/6 nodes are available: 1 c_wall violated: 2 conflicting context pair(s) with node memory, 5 node(s) had untolerated taint(s). no new claims to deallocate, preemption: 0/6 nodes are available: 1 No preemption victims found for incoming pod, 5 Preemption is not helpful for scheduling."
12.1004,Node,MODIFIED,kind-worker2,taints=0
12.1045,Pod,MODIFIED,eval-sanitize-2-r3-010-c57dg,phase=Pending node=None
12.1048,Event,ADDED,eval-sanitize-2-r3-010-c57dg.18d3d18a41d9f11c,"reason=FailedScheduling count=None msg=0/6 nodes are available: 1 c_wall violated: 2 conflicting context pair(s) with node memory, 5 node(s) had untolerated taint(s). no new claims to deallocate, preemption: 0/6 nodes are available: 1 No preemption victims found for incoming pod, 5 Preemption is not helpful for scheduling."
12.1126,Pod,MODIFIED,eval-sanitize-2-r3-011-vt6dt,phase=Pending node=None
12.113,Event,ADDED,eval-sanitize-2-r3-011-vt6dt.18d3d18a425ca2a8,"reason=FailedScheduling count=None msg=0/6 nodes are available: 1 c_wall violated: 2 conflicting context pair(s) with node memory, 5 node(s) had untolerated taint(s). no new claims to deallocate, preemption: 0/6 nodes are available: 1 No preemption victims found for incoming pod, 5 Preemption is not helpful for scheduling."
12.1204,Node,MODIFIED,kind-worker2,taints=0
12.1238,Pod,MODIFIED,eval-sanitize-2-r3-012-4v9kc,phase=Pending node=kind-worker2
12.1244,Event,ADDED,eval-sanitize-2-r3-007-t9hwl.18d3d18a4308d6ac,"reason=FailedScheduling count=None msg=0/6 nodes are available: 1 c_wall violated: 2 conflicting context pair(s) with node memory, 5 node(s) had untolerated taint(s). no new claims to deallocate, preemption: 0/6 nodes are available: 1 No preemption victims found for incoming pod, 5 Preemption is not helpful for scheduling."
12.1267,Event,ADDED,eval-sanitize-2-r3-008-7vg7g.18d3d18a433cb600,"reason=FailedScheduling count=None msg=0/6 nodes are available: 1 c_wall violated: 2 conflicting context pair(s) with node memory, 5 node(s) had untolerated taint(s). no new claims to deallocate, preemption: 0/6 nodes are available: 1 No preemption victims found for incoming pod, 5 Preemption is not helpful for scheduling."
12.1291,Event,ADDED,eval-sanitize-2-r3-012-4v9kc.18d3d18a434c59b6,reason=Scheduled count=None msg=Successfully assigned compute/eval-sanitize-2-r3-012-4v9kc to kind-worker2
12.1352,Pod,MODIFIED,eval-sanitize-2-r3-012-4v9kc,phase=Pending node=kind-worker2
12.1432,Node,MODIFIED,kind-worker2,taints=0
12.1829,Event,ADDED,eval-sanitize-2-r3-009-j7dq8.18d3d18a46906834,"reason=FailedScheduling count=None msg=0/6 nodes are available: 1 c_wall violated: 2 conflicting context pair(s) with node memory, 5 node(s) had untolerated taint(s). no new claims to deallocate, preemption: 0/6 nodes are available: 1 No preemption victims found for incoming pod, 5 Preemption is not helpful for scheduling."
12.1856,Event,ADDED,eval-sanitize-2-r3-010-c57dg.18d3d18a46cb4eda,"reason=FailedScheduling count=None msg=0/6 nodes are available: 1 c_wall violated: 2 conflicting context pair(s) with node memory, 5 node(s) had untolerated taint(s). no new claims to deallocate, preemption: 0/6 nodes are available: 1 No preemption victims found for incoming pod, 5 Preemption is not helpful for scheduling."
12.1964,Event,ADDED,eval-sanitize-2-r3-011-vt6dt.18d3d18a477374fb,"reason=FailedScheduling count=None msg=0/6 nodes are available: 1 c_wall violated: 2 conflicting context pair(s) with node memory, 5 node(s) had untolerated taint(s). no new claims to deallocate, preemption: 0/6 nodes are available: 1 No preemption victims found for incoming pod, 5 Preemption is not helpful for scheduling."
12.2111,Event,MODIFIED,eval-sanitize-2-r3-007-t9hwl.18d3d18a4308d6ac,"reason=FailedScheduling count=None msg=0/6 nodes are available: 1 c_wall violated: 2 conflicting context pair(s) with node memory, 5 node(s) had untolerated taint(s). no new claims to deallocate, preemption: 0/6 nodes are available: 1 No preemption victims found for incoming pod, 5 Preemption is not helpful for scheduling."
12.2119,Event,MODIFIED,eval-sanitize-2-r3-008-7vg7g.18d3d18a433cb600,"reason=FailedScheduling count=None msg=0/6 nodes are available: 1 c_wall violated: 2 conflicting context pair(s) with node memory, 5 node(s) had untolerated taint(s). no new claims to deallocate, preemption: 0/6 nodes are available: 1 No preemption victims found for incoming pod, 5 Preemption is not helpful for scheduling."
12.2146,Event,MODIFIED,eval-sanitize-2-r3-009-j7dq8.18d3d18a46906834,"reason=FailedScheduling count=None msg=0/6 nodes are available: 1 c_wall violated: 2 conflicting context pair(s) with node memory, 5 node(s) had untolerated taint(s). no new claims to deallocate, preemption: 0/6 nodes are available: 1 No preemption victims found for incoming pod, 5 Preemption is not helpful for scheduling."
12.2186,Event,MODIFIED,eval-sanitize-2-r3-010-c57dg.18d3d18a46cb4eda,"reason=FailedScheduling count=None msg=0/6 nodes are available: 1 c_wall violated: 2 conflicting context pair(s) with node memory, 5 node(s) had untolerated taint(s). no new claims to deallocate, preemption: 0/6 nodes are available: 1 No preemption victims found for incoming pod, 5 Preemption is not helpful for scheduling."
12.4536,Pod,MODIFIED,eval-sanitize-2-r3-001-k9ccn,phase=Running node=kind-worker
12.4635,Event,MODIFIED,eval-sanitize-2-r3-011-vt6dt.18d3d18a477374fb,"reason=FailedScheduling count=None msg=0/6 nodes are available: 1 c_wall violated: 2 conflicting context pair(s) with node memory, 5 node(s) had untolerated taint(s). no new claims to deallocate, preemption: 0/6 nodes are available: 1 No preemption victims found for incoming pod, 5 Preemption is not helpful for scheduling."
12.4976,Event,ADDED,eval-sanitize-2-r3-005-mnkl6.18d3d18a59370ecb,"reason=Pulled count=1 msg=Container image ""busybox:musl"" already present on machine"
12.5016,Event,ADDED,eval-sanitize-2-r3-006-m98bf.18d3d18a597cdc13,"reason=Pulled count=1 msg=Container image ""busybox:musl"" already present on machine"
12.5198,Event,ADDED,eval-sanitize-2-r3-005-mnkl6.18d3d18a5aa40d06,reason=Created count=1 msg=Created container: task
12.5265,Event,ADDED,eval-sanitize-2-r3-006-m98bf.18d3d18a5b09666c,reason=Created count=1 msg=Created container: task
12.537,Event,ADDED,eval-sanitize-2-r3-012-4v9kc.18d3d18a5bb5c8e8,"reason=Pulled count=1 msg=Container image ""busybox:musl"" already present on machine"
12.5586,Event,ADDED,eval-sanitize-2-r3-005-mnkl6.18d3d18a5ce12124,reason=Started count=1 msg=Started container task
12.5633,Event,ADDED,eval-sanitize-2-r3-012-4v9kc.18d3d18a5cf57257,reason=Created count=1 msg=Created container: task
12.5674,Event,ADDED,eval-sanitize-2-r3-006-m98bf.18d3d18a5d293282,reason=Started count=1 msg=Started container task
12.5928,Event,ADDED,eval-sanitize-2-r3-012-4v9kc.18d3d18a5ef90e3c,reason=Started count=1 msg=Started container task
12.6715,Pod,MODIFIED,eval-sanitize-2-r3-012-4v9kc,phase=Running node=kind-worker2
12.6793,Pod,MODIFIED,eval-sanitize-2-r3-005-mnkl6,phase=Running node=kind-worker2
12.6806,Job,MODIFIED,eval-sanitize-2-r3-000,
12.6873,Pod,MODIFIED,eval-sanitize-2-r3-006-m98bf,phase=Running node=kind-worker2
12.6897,Pod,MODIFIED,eval-sanitize-2-r3-000-d2spv,phase=Succeeded node=kind-worker2
12.6909,Job,MODIFIED,eval-sanitize-2-r3-000,
13.0069,TaskRequest,ADDED,eval-sanitize-2-r3-013,phase=None job=None
13.0104,TaskRequest,MODIFIED,eval-sanitize-2-r3-013,phase=Pending job=None
13.0254,Job,ADDED,eval-sanitize-2-r3-013,
13.0312,Pod,ADDED,eval-sanitize-2-r3-013-cnzht,phase=Pending node=None
13.0314,TaskRequest,MODIFIED,eval-sanitize-2-r3-013,phase=Scheduled job=None
13.0354,Job,MODIFIED,eval-sanitize-2-r3-013,
13.0367,Event,ADDED,eval-sanitize-2-r3-013.18d3d18a796a619a,reason=SuccessfulCreate count=1 msg=Created pod: eval-sanitize-2-r3-013-cnzht
13.0406,Pod,MODIFIED,eval-sanitize-2-r3-013-cnzht,phase=Pending node=None
13.041,Event,ADDED,eval-sanitize-2-r3-013-cnzht.18d3d18a79a885c3,"reason=FailedScheduling count=None msg=0/6 nodes are available: 1 c_wall violated: 2 conflicting context pair(s) with node memory, 5 node(s) had untolerated taint(s). no new claims to deallocate, preemption: 0/6 nodes are available: 1 No preemption victims found for incoming pod, 5 Preemption is not helpful for scheduling."
13.0411,TaskRequest,MODIFIED,eval-sanitize-2-r3-013,phase=Scheduled job=None
13.0434,Job,MODIFIED,eval-sanitize-2-r3-012,
13.0459,Job,MODIFIED,eval-sanitize-2-r3-013,
13.048,Event,ADDED,eval-sanitize-2-r3-013-cnzht.18d3d18a7a338119,"reason=FailedScheduling count=None msg=0/6 nodes are available: 1 c_wall violated: 2 conflicting context pair(s) with node memory, 5 node(s) had untolerated taint(s). no new claims to deallocate, preemption: 0/6 nodes are available: 1 No preemption victims found for incoming pod, 5 Preemption is not helpful for scheduling."
13.0517,Job,MODIFIED,eval-sanitize-2-r3-012,
13.0542,Job,MODIFIED,eval-sanitize-2-r3-013,
13.0664,Job,MODIFIED,eval-sanitize-2-r3-005,
13.0741,Job,MODIFIED,eval-sanitize-2-r3-005,
13.0758,Job,MODIFIED,eval-sanitize-2-r3-006,
13.1199,Job,MODIFIED,eval-sanitize-2-r3-006,
13.3881,Pod,MODIFIED,eval-sanitize-2-r3-002-bb2jg,phase=Running node=kind-worker4
13.4143,Event,MODIFIED,eval-sanitize-2-r3-013-cnzht.18d3d18a7a338119,"reason=FailedScheduling count=None msg=0/6 nodes are available: 1 c_wall violated: 2 conflicting context pair(s) with node memory, 5 node(s) had untolerated taint(s). no new claims to deallocate, preemption: 0/6 nodes are available: 1 No preemption victims found for incoming pod, 5 Preemption is not helpful for scheduling."
13.4604,Job,MODIFIED,eval-sanitize-2-r3-001,
13.4722,Job,MODIFIED,eval-sanitize-2-r3-001,
13.5472,Pod,MODIFIED,eval-sanitize-2-r3-001-k9ccn,phase=Succeeded node=kind-worker
13.6875,Job,MODIFIED,eval-sanitize-2-r3-000,
13.6913,Job,MODIFIED,eval-sanitize-2-r3-000,
13.6943,Event,ADDED,eval-sanitize-2-r3-000.18d3d18aa0bfe9cc,reason=Completed count=1 msg=Job completed
13.7026,Job,MODIFIED,eval-sanitize-2-r3-000,
13.7075,TaskRequest,MODIFIED,eval-sanitize-2-r3-000,phase=Complete job=None
13.7165,Job,MODIFIED,eval-sanitize-2-r3-000,
14.0121,TaskRequest,ADDED,eval-sanitize-2-r3-014,phase=None job=None
14.0157,TaskRequest,MODIFIED,eval-sanitize-2-r3-014,phase=Pending job=None
14.0323,Job,ADDED,eval-sanitize-2-r3-014,
14.0371,Pod,ADDED,eval-sanitize-2-r3-014-k55b8,phase=Pending node=None
14.0386,TaskRequest,MODIFIED,eval-sanitize-2-r3-014,phase=Scheduled job=None
14.0414,Job,MODIFIED,eval-sanitize-2-r3-014,
14.0428,Event,ADDED,eval-sanitize-2-r3-014.18d3d18ab55f0160,reason=SuccessfulCreate count=1 msg=Created pod: eval-sanitize-2-r3-014-k55b8
14.0461,Pod,MODIFIED,eval-sanitize-2-r3-014-k55b8,phase=Pending node=kind-worker2
14.0462,TaskRequest,MODIFIED,eval-sanitize-2-r3-014,phase=Scheduled job=None
14.0495,Event,ADDED,eval-sanitize-2-r3-014-k55b8.18d3d18ab5df972a,reason=Scheduled count=None msg=Successfully assigned compute/eval-sanitize-2-r3-014-k55b8 to kind-worker2
14.0561,Pod,MODIFIED,eval-sanitize-2-r3-014-k55b8,phase=Pending node=kind-worker2
14.1304,Node,MODIFIED,kind-worker2,taints=1
14.1364,Pod,MODIFIED,eval-sanitize-2-r3-009-j7dq8,phase=Pending node=None
14.1416,Pod,MODIFIED,eval-sanitize-2-r3-010-c57dg,phase=Pending node=None
14.1449,Node,MODIFIED,kind-worker2,taints=1
14.1464,Pod,MODIFIED,eval-sanitize-2-r3-013-cnzht,phase=Pending node=None
14.1507,Pod,MODIFIED,eval-sanitize-2-r3-011-vt6dt,phase=Pending node=None
14.1553,Pod,MODIFIED,eval-sanitize-2-r3-007-t9hwl,phase=Pending node=None
14.1597,Pod,MODIFIED,eval-sanitize-2-r3-008-7vg7g,phase=Pending node=None
14.3461,Pod,MODIFIED,eval-sanitize-2-r3-003-fg2r7,phase=Running node=kind-worker5
14.3939,Job,MODIFIED,eval-sanitize-2-r3-002,
14.4056,Job,MODIFIED,eval-sanitize-2-r3-002,
14.4742,Job,MODIFIED,eval-sanitize-2-r3-001,
14.4846,Pod,MODIFIED,eval-sanitize-2-r3-001-k9ccn,phase=Succeeded node=kind-worker
14.4855,Job,MODIFIED,eval-sanitize-2-r3-001,
14.5505,Event,ADDED,eval-sanitize-2-r3-014-k55b8.18d3d18ad3b5eafb,"reason=Pulled count=1 msg=Container image ""busybox:musl"" already present on machine"
14.5679,Event,ADDED,eval-sanitize-2-r3-014-k55b8.18d3d18ad4c23cfb,reason=Created count=1 msg=Created container: task
14.5803,Pod,MODIFIED,eval-sanitize-2-r3-002-bb2jg,phase=Succeeded node=kind-worker4
14.6369,Event,ADDED,eval-sanitize-2-r3-014-k55b8.18d3d18ad8dea7bf,reason=Started count=1 msg=Started container task
14.6791,Pod,MODIFIED,eval-sanitize-2-r3-014-k55b8,phase=Running node=kind-worker2
14.703,Node,MODIFIED,kind-worker,taints=1
14.7472,Node,MODIFIED,kind-worker,taints=0
14.7532,Pod,MODIFIED,eval-sanitize-2-r3-009-j7dq8,phase=Pending node=kind-worker
14.7577,Pod,MODIFIED,eval-sanitize-2-r3-010-c57dg,phase=Pending node=kind-worker
14.7599,Event,ADDED,eval-sanitize-2-r3-009-j7dq8.18d3d18adffca3cf,reason=Scheduled count=None msg=Successfully assigned compute/eval-sanitize-2-r3-009-j7dq8 to kind-worker
14.7615,Node,MODIFIED,kind-worker,taints=0
14.7623,Pod,MODIFIED,eval-sanitize-2-r3-013-cnzht,phase=Pending node=kind-worker
14.7647,Pod,MODIFIED,eval-sanitize-2-r3-011-vt6dt,phase=Pending node=kind-worker
14.7686,Event,ADDED,eval-sanitize-2-r3-010-c57dg.18d3d18ae0492907,reason=Scheduled count=None msg=Successfully assigned compute/eval-sanitize-2-r3-010-c57dg to kind-worker
14.769,Event,ADDED,eval-sanitize-2-r3-013-cnzht.18d3d18ae073073e,reason=Scheduled count=None msg=Successfully assigned compute/eval-sanitize-2-r3-013-cnzht to kind-worker
14.7703,Pod,MODIFIED,eval-sanitize-2-r3-009-j7dq8,phase=Pending node=kind-worker
14.7711,Pod,MODIFIED,eval-sanitize-2-r3-007-t9hwl,phase=Pending node=kind-worker
14.7717,Event,ADDED,eval-sanitize-2-r3-011-vt6dt.18d3d18ae0ba0990,reason=Scheduled count=None msg=Successfully assigned compute/eval-sanitize-2-r3-011-vt6dt to kind-worker
14.7729,Pod,MODIFIED,eval-sanitize-2-r3-008-7vg7g,phase=Pending node=kind-worker
14.7775,Node,MODIFIED,kind-worker,taints=0
14.7809,Event,ADDED,eval-sanitize-2-r3-007-t9hwl.18d3d18ae0fac350,reason=Scheduled count=None msg=Successfully assigned compute/eval-sanitize-2-r3-007-t9hwl to kind-worker
14.7811,Event,ADDED,eval-sanitize-2-r3-008-7vg7g.18d3d18ae1352aa7,reason=Scheduled count=None msg=Successfully assigned compute/eval-sanitize-2-r3-008-7vg7g to kind-worker
14.7853,Pod,MODIFIED,eval-sanitize-2-r3-010-c57dg,phase=Pending node=kind-worker
14.7902,Node,MODIFIED,kind-worker,taints=0
14.7917,Pod,MODIFIED,eval-sanitize-2-r3-013-cnzht,phase=Pending node=kind-worker
14.7982,Pod,MODIFIED,eval-sanitize-2-r3-008-7vg7g,phase=Pending node=kind-worker
14.8008,Node,MODIFIED,kind-worker,taints=0
14.8072,Pod,MODIFIED,eval-sanitize-2-r3-011-vt6dt,phase=Pending node=kind-worker
14.8131,Pod,MODIFIED,eval-sanitize-2-r3-007-t9hwl,phase=Pending node=kind-worker
14.8641,Node,MODIFIED,kind-worker,taints=0
14.8733,Node,MODIFIED,kind-worker,taints=0
15.009,TaskRequest,ADDED,eval-sanitize-2-r3-015,phase=None job=None
15.0124,TaskRequest,MODIFIED,eval-sanitize-2-r3-015,phase=Pending job=None
15.0267,Job,ADDED,eval-sanitize-2-r3-015,
15.0294,TaskRequest,MODIFIED,eval-sanitize-2-r3-015,phase=Scheduled job=None
15.0336,Pod,ADDED,eval-sanitize-2-r3-015-9g8mh,phase=Pending node=None
15.0357,Job,MODIFIED,eval-sanitize-2-r3-015,
15.0379,Event,ADDED,eval-sanitize-2-r3-015.18d3d18af0bce632,reason=SuccessfulCreate count=1 msg=Created pod: eval-sanitize-2-r3-015-9g8mh
15.0381,TaskRequest,MODIFIED,eval-sanitize-2-r3-015,phase=Scheduled job=None
15.0424,Pod,MODIFIED,eval-sanitize-2-r3-015-9g8mh,phase=Pending node=kind-worker
15.0446,Job,MODIFIED,eval-sanitize-2-r3-014,
15.0453,Event,ADDED,eval-sanitize-2-r3-015-9g8mh.18d3d18af1384695,reason=Scheduled count=None msg=Successfully assigned compute/eval-sanitize-2-r3-015-9g8mh to kind-worker
15.0528,Node,MODIFIED,kind-worker,taints=0
15.0548,Pod,MODIFIED,eval-sanitize-2-r3-015-9g8mh,phase=Pending node=kind-worker
15.0555,Job,MODIFIED,eval-sanitize-2-r3-014,
15.0623,Node,MODIFIED,kind-worker,taints=0
15.2304,Event,ADDED,eval-sanitize-2-r3-009-j7dq8.18d3d18afc2f58e5,"reason=Pulled count=1 msg=Container image ""busybox:musl"" already present on machine"
15.2508,Event,ADDED,eval-sanitize-2-r3-009-j7dq8.18d3d18afd66f8c0,reason=Created count=1 msg=Created container: task
15.2674,Event,ADDED,eval-sanitize-2-r3-013-cnzht.18d3d18afe1f444e,"reason=Pulled count=1 msg=Container image ""busybox:musl"" already present on machine"
15.2719,Event,ADDED,eval-sanitize-2-r3-011-vt6dt.18d3d18afe6dd6cc,"reason=Pulled count=1 msg=Container image ""busybox:musl"" already present on machine"
15.2764,Event,ADDED,eval-sanitize-2-r3-008-7vg7g.18d3d18afe949b32,"reason=Pulled count=1 msg=Container image ""busybox:musl"" already present on machine"
15.2807,Event,ADDED,eval-sanitize-2-r3-010-c57dg.18d3d18afec4f609,"reason=Pulled count=1 msg=Container image ""busybox:musl"" already present on machine"
15.2849,Event,ADDED,eval-sanitize-2-r3-007-t9hwl.18d3d18afef4f0cc,"reason=Pulled count=1 msg=Container image ""busybox:musl"" already present on machine"
15.2915,Event,ADDED,eval-sanitize-2-r3-009-j7dq8.18d3d18affa7aff0,reason=Started count=1 msg=Started container task
15.3167,Event,ADDED,eval-sanitize-2-r3-013-cnzht.18d3d18b016bf79a,reason=Created count=1 msg=Created container: task
15.3216,Event,ADDED,eval-sanitize-2-r3-011-vt6dt.18d3d18b0189891b,reason=Created count=1 msg=Created container: task
15.3263,Event,ADDED,eval-sanitize-2-r3-008-7vg7g.18d3d18b01d338f5,reason=Created count=1 msg=Created container: task
15.3315,Event,ADDED,eval-sanitize-2-r3-010-c57dg.18d3d18b021561d5,reason=Created count=1 msg=Created container: task
15.3357,Event,ADDED,eval-sanitize-2-r3-007-t9hwl.18d3d18b023c1142,reason=Created count=1 msg=Created container: task
15.3455,Pod,MODIFIED,eval-sanitize-2-r3-004-8tv8k,phase=Running node=kind-worker3
15.3523,Job,MODIFIED,eval-sanitize-2-r3-003,
15.3673,Job,MODIFIED,eval-sanitize-2-r3-003,
15.3792,Event,ADDED,eval-sanitize-2-r3-013-cnzht.18d3d18b05132f43,reason=Started count=1 msg=Started container task
15.3866,Event,ADDED,eval-sanitize-2-r3-011-vt6dt.18d3d18b058f8a72,reason=Started count=1 msg=Started container task
15.3996,Job,MODIFIED,eval-sanitize-2-r3-002,
15.408,Pod,MODIFIED,eval-sanitize-2-r3-002-bb2jg,phase=Succeeded node=kind-worker4
15.4091,Job,MODIFIED,eval-sanitize-2-r3-002,
15.4491,Event,ADDED,eval-sanitize-2-r3-008-7vg7g.18d3d18b093d4a8f,reason=Started count=1 msg=Started container task
15.4619,Pod,MODIFIED,eval-sanitize-2-r3-009-j7dq8,phase=Running node=kind-worker
15.4653,Pod,MODIFIED,eval-sanitize-2-r3-003-fg2r7,phase=Succeeded node=kind-worker5
15.4678,Event,ADDED,eval-sanitize-2-r3-007-t9hwl.18d3d18b0a1fa864,reason=Started count=1 msg=Started container task
15.4761,Event,ADDED,eval-sanitize-2-r3-010-c57dg.18d3d18b0a1ff6d9,reason=Started count=1 msg=Started container task
15.4776,Pod,MODIFIED,eval-sanitize-2-r3-011-vt6dt,phase=Running node=kind-worker
15.48,Job,MODIFIED,eval-sanitize-2-r3-001,
15.4814,Event,ADDED,eval-sanitize-2-r3-015-9g8mh.18d3d18b0a75f46e,"reason=Pulled count=1 msg=Container image ""busybox:musl"" already present on machine"
15.4852,Job,MODIFIED,eval-sanitize-2-r3-001,
15.4889,Pod,MODIFIED,eval-sanitize-2-r3-013-cnzht,phase=Running node=kind-worker
15.4901,Event,ADDED,eval-sanitize-2-r3-001.18d3d18b0badd239,reason=Completed count=1 msg=Job completed
15.4954,Pod,MODIFIED,eval-sanitize-2-r3-008-7vg7g,phase=Running node=kind-worker
15.497,Job,MODIFIED,eval-sanitize-2-r3-001,
15.4974,Event,ADDED,eval-sanitize-2-r3-015-9g8mh.18d3d18b0c19269f,reason=Created count=1 msg=Created container: task
15.5028,TaskRequest,MODIFIED,eval-sanitize-2-r3-001,phase=Complete job=None
15.5138,Job,MODIFIED,eval-sanitize-2-r3-001,
15.5709,Event,ADDED,eval-sanitize-2-r3-015-9g8mh.18d3d18b108a7360,reason=Started count=1 msg=Started container task
16.0135,TaskRequest,ADDED,eval-sanitize-2-r3-016,phase=None job=None
16.0178,TaskRequest,MODIFIED,eval-sanitize-2-r3-016,phase=Pending job=None
16.0346,Job,ADDED,eval-sanitize-2-r3-016,
16.0382,Job,MODIFIED,eval-sanitize-2-r3-015,
16.0416,Pod,ADDED,eval-sanitize-2-r3-016-4jb2m,phase=Pending node=None
16.0419,TaskRequest,MODIFIED,eval-sanitize-2-r3-016,phase=Scheduled job=None
16.0447,Job,MODIFIED,eval-sanitize-2-r3-016,
16.0482,Event,ADDED,eval-sanitize-2-r3-016.18d3d18b2cd4f8a0,reason=SuccessfulCreate count=1 msg=Created pod: eval-sanitize-2-r3-016-4jb2m
16.0509,Pod,MODIFIED,eval-sanitize-2-r3-016-4jb2m,phase=Pending node=kind-worker
16.0524,TaskRequest,MODIFIED,eval-sanitize-2-r3-016,phase=Scheduled job=None
16.0533,Job,MODIFIED,eval-sanitize-2-r3-015,
16.0547,Event,ADDED,eval-sanitize-2-r3-016-4jb2m.18d3d18b2d5cfa3b,reason=Scheduled count=None msg=Successfully assigned compute/eval-sanitize-2-r3-016-4jb2m to kind-worker
16.0621,Pod,MODIFIED,eval-sanitize-2-r3-016-4jb2m,phase=Pending node=kind-worker
16.0641,Node,MODIFIED,kind-worker,taints=0
16.074,Node,MODIFIED,kind-worker,taints=0
16.3518,Job,MODIFIED,eval-sanitize-2-r3-004,
16.3572,Job,MODIFIED,eval-sanitize-2-r3-003,
16.3612,Job,MODIFIED,eval-sanitize-2-r3-004,
16.3665,Pod,MODIFIED,eval-sanitize-2-r3-003-fg2r7,phase=Succeeded node=kind-worker5
16.3694,Job,MODIFIED,eval-sanitize-2-r3-003,
16.4048,Job,MODIFIED,eval-sanitize-2-r3-002,
16.41,Job,MODIFIED,eval-sanitize-2-r3-002,
16.4136,Event,ADDED,eval-sanitize-2-r3-002.18d3d18b42c36748,reason=Completed count=1 msg=Job completed
16.4234,Job,MODIFIED,eval-sanitize-2-r3-002,
16.4275,TaskRequest,MODIFIED,eval-sanitize-2-r3-002,phase=Complete job=None
16.437,Job,MODIFIED,eval-sanitize-2-r3-002,
16.4494,Node,MODIFIED,kind-worker4,taints=1
16.467,Job,MODIFIED,eval-sanitize-2-r3-009,
16.4772,Pod,MODIFIED,eval-sanitize-2-r3-010-c57dg,phase=Running node=kind-worker
16.4783,Job,MODIFIED,eval-sanitize-2-r3-009,
16.4824,Job,MODIFIED,eval-sanitize-2-r3-011,
16.4856,Pod,MODIFIED,eval-sanitize-2-r3-007-t9hwl,phase=Running node=kind-worker
16.4859,Event,ADDED,eval-sanitize-2-r3-016-4jb2m.18d3d18b470b86cd,"reason=Pulled count=1 msg=Container image ""busybox:musl"" already present on machine"
16.4929,Pod,MODIFIED,eval-sanitize-2-r3-015-9g8mh,phase=Running node=kind-worker
16.4994,Job,MODIFIED,eval-sanitize-2-r3-011,
16.5003,Job,MODIFIED,eval-sanitize-2-r3-013,
16.5012,Job,MODIFIED,eval-sanitize-2-r3-008,
16.5054,Pod,MODIFIED,eval-sanitize-2-r3-004-8tv8k,phase=Succeeded node=kind-worker3
16.511,Job,MODIFIED,eval-sanitize-2-r3-013,
16.5117,Job,MODIFIED,eval-sanitize-2-r3-008,
16.5131,Event,ADDED,eval-sanitize-2-r3-016-4jb2m.18d3d18b48aff867,reason=Created count=1 msg=Created container: task
16.5222,Node,MODIFIED,kind-worker4,taints=1
16.5299,Node,MODIFIED,kind-worker4,taints=0
16.5402,Node,MODIFIED,kind-worker4,taints=0
16.5771,Event,ADDED,eval-sanitize-2-r3-016-4jb2m.18d3d18b4c8c05ab,reason=Started count=1 msg=Started container task
16.6466,Node,MODIFIED,kind-worker5,taints=1
16.6593,Node,MODIFIED,kind-worker5,taints=0
16.667,Node,MODIFIED,kind-worker5,taints=0
16.7213,Node,MODIFIED,kind-worker5,taints=0
16.7688,Node,MODIFIED,kind-worker,taints=1
16.7807,Node,MODIFIED,kind-worker,taints=1
17.0103,TaskRequest,ADDED,eval-sanitize-2-r3-017,phase=None job=None
17.0158,TaskRequest,MODIFIED,eval-sanitize-2-r3-017,phase=Pending job=None
17.0307,Job,ADDED,eval-sanitize-2-r3-017,
17.0359,Pod,ADDED,eval-sanitize-2-r3-017-98n66,phase=Pending node=None
17.0373,TaskRequest,MODIFIED,eval-sanitize-2-r3-017,phase=Scheduled job=None
17.0402,Job,MODIFIED,eval-sanitize-2-r3-017,
17.0414,Event,ADDED,eval-sanitize-2-r3-017.18d3d18b681a74d2,reason=SuccessfulCreate count=1 msg=Created pod: eval-sanitize-2-r3-017-98n66
17.044,Job,MODIFIED,eval-sanitize-2-r3-015,
17.0453,TaskRequest,MODIFIED,eval-sanitize-2-r3-017,phase=Scheduled job=None
17.0461,Job,MODIFIED,eval-sanitize-2-r3-016,
17.0515,Pod,MODIFIED,eval-sanitize-2-r3-017-98n66,phase=Pending node=kind-worker4
17.0536,Job,MODIFIED,eval-sanitize-2-r3-015,
17.0581,Job,MODIFIED,eval-sanitize-2-r3-016,
17.0585,Event,ADDED,eval-sanitize-2-r3-017-98n66.18d3d18b6904c3c4,reason=Scheduled count=None msg=Successfully assigned compute/eval-sanitize-2-r3-017-98n66 to kind-worker4
17.0619,Node,MODIFIED,kind-worker4,taints=0
17.0636,Pod,MODIFIED,eval-sanitize-2-r3-017-98n66,phase=Pending node=kind-worker4
17.0725,Node,MODIFIED,kind-worker4,taints=0
17.3571,Job,MODIFIED,eval-sanitize-2-r3-004,
17.3629,Job,MODIFIED,eval-sanitize-2-r3-003,
17.3682,Pod,MODIFIED,eval-sanitize-2-r3-004-8tv8k,phase=Succeeded node=kind-worker3
17.3816,Job,MODIFIED,eval-sanitize-2-r3-004,
17.3825,Job,MODIFIED,eval-sanitize-2-r3-003,
17.3863,Event,ADDED,eval-sanitize-2-r3-003.18d3d18b7cb4214c,reason=Completed count=1 msg=Job completed
17.3918,Job,MODIFIED,eval-sanitize-2-r3-003,
17.3961,TaskRequest,MODIFIED,eval-sanitize-2-r3-003,phase=Complete job=None
17.4076,Job,MODIFIED,eval-sanitize-2-r3-003,
17.4855,Job,MODIFIED,eval-sanitize-2-r3-010,
17.4885,Pod,MODIFIED,eval-sanitize-2-r3-016-4jb2m,phase=Running node=kind-worker
17.4903,Job,MODIFIED,eval-sanitize-2-r3-007,
17.4931,Event,ADDED,eval-sanitize-2-r3-017-98n66.18d3d18b831e9a19,"reason=Pulled count=1 msg=Container image ""busybox:musl"" already present on machine"
17.4962,Job,MODIFIED,eval-sanitize-2-r3-010,
17.4991,Job,MODIFIED,eval-sanitize-2-r3-007,
17.5123,Event,ADDED,eval-sanitize-2-r3-017-98n66.18d3d18b844f48da,reason=Created count=1 msg=Created container: task
17.545,Node,MODIFIED,kind-worker3,taints=1
17.5579,Node,MODIFIED,kind-worker3,taints=1
17.5672,Node,MODIFIED,kind-worker3,taints=0
17.5804,Node,MODIFIED,kind-worker3,taints=0
17.586,Event,ADDED,eval-sanitize-2-r3-017-98n66.18d3d18b88b2b3b0,reason=Started count=1 msg=Started container task
18.0133,TaskRequest,ADDED,eval-sanitize-2-r3-018,phase=None job=None
18.0169,TaskRequest,MODIFIED,eval-sanitize-2-r3-018,phase=Pending job=None
18.0331,Job,ADDED,eval-sanitize-2-r3-018,
18.0388,TaskRequest,MODIFIED,eval-sanitize-2-r3-018,phase=Scheduled job=None
18.0414,Pod,ADDED,eval-sanitize-2-r3-018-lhc4h,phase=Pending node=None
18.0441,Job,MODIFIED,eval-sanitize-2-r3-017,
18.0446,Job,MODIFIED,eval-sanitize-2-r3-018,
18.0459,Event,ADDED,eval-sanitize-2-r3-018.18d3d18ba40ca782,reason=SuccessfulCreate count=1 msg=Created pod: eval-sanitize-2-r3-018-lhc4h
18.046,TaskRequest,MODIFIED,eval-sanitize-2-r3-018,phase=Scheduled job=None
18.0509,Job,MODIFIED,eval-sanitize-2-r3-016,
18.0523,Pod,MODIFIED,eval-sanitize-2-r3-018-lhc4h,phase=Pending node=kind-worker5
18.0542,Job,MODIFIED,eval-sanitize-2-r3-017,
18.0562,Event,ADDED,eval-sanitize-2-r3-018-lhc4h.18d3d18ba4b5af83,reason=Scheduled count=None msg=Successfully assigned compute/eval-sanitize-2-r3-018-lhc4h to kind-worker5
18.0606,Job,MODIFIED,eval-sanitize-2-r3-016,
18.0634,Pod,MODIFIED,eval-sanitize-2-r3-018-lhc4h,phase=Pending node=kind-worker5
18.0648,Node,MODIFIED,kind-worker5,taints=0
18.0731,Node,MODIFIED,kind-worker5,taints=0
18.364,Job,MODIFIED,eval-sanitize-2-r3-004,
18.3691,Job,MODIFIED,eval-sanitize-2-r3-004,
18.3738,Event,ADDED,eval-sanitize-2-r3-004.18d3d18bb7905e18,reason=Completed count=1 msg=Job completed
18.3798,Job,MODIFIED,eval-sanitize-2-r3-004,
18.3848,TaskRequest,MODIFIED,eval-sanitize-2-r3-004,phase=Complete job=None
18.3959,Job,MODIFIED,eval-sanitize-2-r3-004,
18.4013,Pod,MODIFIED,eval-sanitize-2-r3-017-98n66,phase=Running node=kind-worker4
18.4755,Event,ADDED,eval-sanitize-2-r3-018-lhc4h.18d3d18bbd7a0407,"reason=Pulled count=1 msg=Container image ""busybox:musl"" already present on machine"
18.4933,Event,ADDED,eval-sanitize-2-r3-018-lhc4h.18d3d18bbeb84aa3,reason=Created count=1 msg=Created container: task
18.554,Node,MODIFIED,kind-worker4,taints=1
18.5669,Node,MODIFIED,kind-worker4,taints=1
18.5715,Event,ADDED,eval-sanitize-2-r3-018-lhc4h.18d3d18bc3708c59,reason=Started count=1 msg=Started container task
18.7284,Node,MODIFIED,kind-worker5,taints=1
18.7404,Node,MODIFIED,kind-worker5,taints=1
19.008,TaskRequest,ADDED,eval-sanitize-2-r3-019,phase=None job=None
19.0115,TaskRequest,MODIFIED,eval-sanitize-2-r3-019,phase=Pending job=None
19.0263,Job,ADDED,eval-sanitize-2-r3-019,
19.0325,Pod,ADDED,eval-sanitize-2-r3-019-rvslz,phase=Pending node=None
19.0338,TaskRequest,MODIFIED,eval-sanitize-2-r3-019,phase=Scheduled job=None
19.0347,Job,MODIFIED,eval-sanitize-2-r3-019,
19.0388,Event,ADDED,eval-sanitize-2-r3-019.18d3d18bdf1dc72d,reason=SuccessfulCreate count=1 msg=Created pod: eval-sanitize-2-r3-019-rvslz
19.0398,Pod,MODIFIED,eval-sanitize-2-r3-019-rvslz,phase=Pending node=kind-worker3
19.0419,TaskRequest,MODIFIED,eval-sanitize-2-r3-019,phase=Scheduled job=None
19.0445,Event,ADDED,eval-sanitize-2-r3-019-rvslz.18d3d18bdf887156,reason=Scheduled count=None msg=Successfully assigned compute/eval-sanitize-2-r3-019-rvslz to kind-worker3
19.0472,Job,MODIFIED,eval-sanitize-2-r3-018,
19.0497,Job,MODIFIED,eval-sanitize-2-r3-017,
19.0516,Node,MODIFIED,kind-worker3,taints=0
19.0527,Pod,MODIFIED,eval-sanitize-2-r3-019-rvslz,phase=Pending node=kind-worker3
19.0567,Job,MODIFIED,eval-sanitize-2-r3-018,
19.0584,Job,MODIFIED,eval-sanitize-2-r3-017,
19.0612,Node,MODIFIED,kind-worker3,taints=0
19.3566,Pod,MODIFIED,eval-sanitize-2-r3-018-lhc4h,phase=Running node=kind-worker5
19.4607,Event,ADDED,eval-sanitize-2-r3-019-rvslz.18d3d18bf864681a,"reason=Pulled count=1 msg=Container image ""busybox:musl"" already present on machine"
19.4824,Event,ADDED,eval-sanitize-2-r3-019-rvslz.18d3d18bf9a2ed8b,reason=Created count=1 msg=Created container: task
19.5146,Event,ADDED,eval-sanitize-2-r3-019-rvslz.18d3d18bfba2785d,reason=Started count=1 msg=Started container task
19.5878,Node,MODIFIED,kind-worker3,taints=1
19.5997,Node,MODIFIED,kind-worker3,taints=1
20.0247,TaskRequest,ADDED,eval-sanitize-2-r3-020,phase=None job=None
20.0285,TaskRequest,MODIFIED,eval-sanitize-2-r3-020,phase=Pending job=None
20.0383,Job,MODIFIED,eval-sanitize-2-r3-019,
20.0438,Job,ADDED,eval-sanitize-2-r3-020,
20.05,Pod,ADDED,eval-sanitize-2-r3-020-6k5gr,phase=Pending node=None
20.0519,Job,MODIFIED,eval-sanitize-2-r3-020,
20.052,TaskRequest,MODIFIED,eval-sanitize-2-r3-020,phase=Scheduled job=None
20.0548,Job,MODIFIED,eval-sanitize-2-r3-018,
20.0564,Event,ADDED,eval-sanitize-2-r3-020.18d3d18c1bc0c8c1,reason=SuccessfulCreate count=1 msg=Created pod: eval-sanitize-2-r3-020-6k5gr
20.0566,Event,ADDED,eval-sanitize-2-r3-020-6k5gr.18d3d18c1bcbc9ac,"reason=FailedScheduling count=None msg=0/6 nodes are available: 6 node(s) had untolerated taint(s). no new claims to deallocate, preemption: 0/6 nodes are available: 6 Preemption is not helpful for scheduling."
20.0577,Pod,MODIFIED,eval-sanitize-2-r3-020-6k5gr,phase=Pending node=None
20.0601,TaskRequest,MODIFIED,eval-sanitize-2-r3-020,phase=Scheduled job=None
20.0626,Job,MODIFIED,eval-sanitize-2-r3-019,
20.0645,Job,MODIFIED,eval-sanitize-2-r3-018,
20.3605,Pod,MODIFIED,eval-sanitize-2-r3-019-rvslz,phase=Running node=kind-worker3
21.0118,TaskRequest,ADDED,eval-sanitize-2-r3-021,phase=None job=None
21.0155,TaskRequest,MODIFIED,eval-sanitize-2-r3-021,phase=Pending job=None
21.0301,Job,ADDED,eval-sanitize-2-r3-021,
21.0368,Pod,ADDED,eval-sanitize-2-r3-021-4gw4x,phase=Pending node=None
21.0383,TaskRequest,MODIFIED,eval-sanitize-2-r3-021,phase=Scheduled job=None
21.0391,Job,MODIFIED,eval-sanitize-2-r3-021,
21.043,Event,ADDED,eval-sanitize-2-r3-021.18d3d18c5695cbf7,reason=SuccessfulCreate count=1 msg=Created pod: eval-sanitize-2-r3-021-4gw4x
21.0433,Event,ADDED,eval-sanitize-2-r3-021-4gw4x.18d3d18c569f7095,"reason=FailedScheduling count=None msg=0/6 nodes are available: 6 node(s) had untolerated taint(s). no new claims to deallocate, preemption: 0/6 nodes are available: 6 Preemption is not helpful for scheduling."
21.0442,Pod,MODIFIED,eval-sanitize-2-r3-021-4gw4x,phase=Pending node=None
21.0449,Job,MODIFIED,eval-sanitize-2-r3-019,
21.0457,TaskRequest,MODIFIED,eval-sanitize-2-r3-021,phase=Scheduled job=None
21.0521,Job,MODIFIED,eval-sanitize-2-r3-019,
21.0544,Job,MODIFIED,eval-sanitize-2-r3-020,
21.0623,Job,MODIFIED,eval-sanitize-2-r3-020,
22.014,TaskRequest,ADDED,eval-sanitize-2-r3-022,phase=None job=None
22.019,TaskRequest,MODIFIED,eval-sanitize-2-r3-022,phase=Pending job=None
22.0368,Job,ADDED,eval-sanitize-2-r3-022,
22.0412,Job,MODIFIED,eval-sanitize-2-r3-021,
22.0436,Pod,ADDED,eval-sanitize-2-r3-022-pbpff,phase=Pending node=None
22.0439,TaskRequest,MODIFIED,eval-sanitize-2-r3-022,phase=Scheduled job=None
22.0465,Job,MODIFIED,eval-sanitize-2-r3-022,
22.0506,Event,ADDED,eval-sanitize-2-r3-022.18d3d18c929897e5,reason=SuccessfulCreate count=1 msg=Created pod: eval-sanitize-2-r3-022-pbpff
22.0508,Event,ADDED,eval-sanitize-2-r3-022-pbpff.18d3d18c92a30cd2,"reason=FailedScheduling count=None msg=0/6 nodes are available: 6 node(s) had untolerated taint(s). no new claims to deallocate, preemption: 0/6 nodes are available: 6 Preemption is not helpful for scheduling."
22.0519,Pod,MODIFIED,eval-sanitize-2-r3-022-pbpff,phase=Pending node=None
22.052,TaskRequest,MODIFIED,eval-sanitize-2-r3-022,phase=Scheduled job=None
22.0541,Job,MODIFIED,eval-sanitize-2-r3-021,
22.6983,Pod,MODIFIED,eval-sanitize-2-r3-006-m98bf,phase=Running node=kind-worker2
22.704,Pod,MODIFIED,eval-sanitize-2-r3-005-mnkl6,phase=Running node=kind-worker2
23.0079,TaskRequest,ADDED,eval-sanitize-2-r3-023,phase=None job=None
23.015,TaskRequest,MODIFIED,eval-sanitize-2-r3-023,phase=Pending job=None
23.0291,Job,ADDED,eval-sanitize-2-r3-023,
23.0367,Pod,ADDED,eval-sanitize-2-r3-023-5wddd,phase=Pending node=None
23.0378,TaskRequest,MODIFIED,eval-sanitize-2-r3-023,phase=Scheduled job=None
23.0385,Job,MODIFIED,eval-sanitize-2-r3-023,
23.0417,Pod,MODIFIED,eval-sanitize-2-r3-023-5wddd,phase=Pending node=None
23.0427,Event,ADDED,eval-sanitize-2-r3-023.18d3d18ccdcd0764,reason=SuccessfulCreate count=1 msg=Created pod: eval-sanitize-2-r3-023-5wddd
23.0429,Event,ADDED,eval-sanitize-2-r3-023-5wddd.18d3d18ccdd43361,"reason=FailedScheduling count=None msg=0/6 nodes are available: 6 node(s) had untolerated taint(s). no new claims to deallocate, preemption: 0/6 nodes are available: 6 Preemption is not helpful for scheduling."
23.0451,TaskRequest,MODIFIED,eval-sanitize-2-r3-023,phase=Scheduled job=None
23.0483,Job,MODIFIED,eval-sanitize-2-r3-022,
23.0574,Job,MODIFIED,eval-sanitize-2-r3-022,
23.7036,Pod,MODIFIED,eval-sanitize-2-r3-012-4v9kc,phase=Running node=kind-worker2
23.7044,Job,MODIFIED,eval-sanitize-2-r3-006,
23.709,Job,MODIFIED,eval-sanitize-2-r3-005,
23.7144,Job,MODIFIED,eval-sanitize-2-r3-006,
23.7182,Job,MODIFIED,eval-sanitize-2-r3-005,
23.8834,Pod,MODIFIED,eval-sanitize-2-r3-006-m98bf,phase=Succeeded node=kind-worker2
23.9153,Pod,MODIFIED,eval-sanitize-2-r3-005-mnkl6,phase=Succeeded node=kind-worker2
24.0079,TaskRequest,ADDED,eval-sanitize-2-r3-024,phase=None job=None
24.0113,TaskRequest,MODIFIED,eval-sanitize-2-r3-024,phase=Pending job=None
24.0262,Job,ADDED,eval-sanitize-2-r3-024,
24.0304,TaskRequest,MODIFIED,eval-sanitize-2-r3-024,phase=Scheduled job=None
24.033,Pod,ADDED,eval-sanitize-2-r3-024-hqtgk,phase=Pending node=None
24.035,Job,MODIFIED,eval-sanitize-2-r3-024,
24.0393,Event,ADDED,eval-sanitize-2-r3-024.18d3d18d09344166,reason=SuccessfulCreate count=1 msg=Created pod: eval-sanitize-2-r3-024-hqtgk
24.0395,Event,ADDED,eval-sanitize-2-r3-024-hqtgk.18d3d18d093ce913,"reason=FailedScheduling count=None msg=0/6 nodes are available: 6 node(s) had untolerated taint(s). no new claims to deallocate, preemption: 0/6 nodes are available: 6 Preemption is not helpful for scheduling."
24.0404,Pod,MODIFIED,eval-sanitize-2-r3-024-hqtgk,phase=Pending node=None
24.0418,Job,MODIFIED,eval-sanitize-2-r3-023,
24.0433,TaskRequest,MODIFIED,eval-sanitize-2-r3-024,phase=Scheduled job=None
24.0497,Job,MODIFIED,eval-sanitize-2-r3-023,
24.7076,Pod,MODIFIED,eval-sanitize-2-r3-014-k55b8,phase=Running node=kind-worker2
24.7085,Job,MODIFIED,eval-sanitize-2-r3-012,
24.7106,Job,MODIFIED,eval-sanitize-2-r3-006,
24.7152,Job,MODIFIED,eval-sanitize-2-r3-005,
24.7188,Job,MODIFIED,eval-sanitize-2-r3-012,
24.7231,Pod,MODIFIED,eval-sanitize-2-r3-006-m98bf,phase=Succeeded node=kind-worker2
24.7244,Job,MODIFIED,eval-sanitize-2-r3-006,
24.7258,Pod,MODIFIED,eval-sanitize-2-r3-005-mnkl6,phase=Succeeded node=kind-worker2
24.7267,Job,MODIFIED,eval-sanitize-2-r3-005,
24.8046,Pod,MODIFIED,eval-sanitize-2-r3-012-4v9kc,phase=Succeeded node=kind-worker2
25.0093,TaskRequest,ADDED,eval-sanitize-2-r3-025,phase=None job=None
25.0128,TaskRequest,MODIFIED,eval-sanitize-2-r3-025,phase=Pending job=None
25.0278,Job,ADDED,eval-sanitize-2-r3-025,
25.0335,Pod,ADDED,eval-sanitize-2-r3-025-kpnrw,phase=Pending node=None
25.0352,TaskRequest,MODIFIED,eval-sanitize-2-r3-025,phase=Scheduled job=None
25.0382,Job,MODIFIED,eval-sanitize-2-r3-025,
25.0396,Job,MODIFIED,eval-sanitize-2-r3-024,
25.0401,Event,ADDED,eval-sanitize-2-r3-025.18d3d18d44d36518,reason=SuccessfulCreate count=1 msg=Created pod: eval-sanitize-2-r3-025-kpnrw
25.0405,Event,ADDED,eval-sanitize-2-r3-025-kpnrw.18d3d18d44e1d778,"reason=FailedScheduling count=None msg=0/6 nodes are available: 6 node(s) had untolerated taint(s). no new claims to deallocate, preemption: 0/6 nodes are available: 6 Preemption is not helpful for scheduling."
25.0414,Pod,MODIFIED,eval-sanitize-2-r3-025-kpnrw,phase=Pending node=None
25.0421,TaskRequest,MODIFIED,eval-sanitize-2-r3-025,phase=Scheduled job=None
25.0483,Job,MODIFIED,eval-sanitize-2-r3-024,
25.4992,Pod,MODIFIED,eval-sanitize-2-r3-009-j7dq8,phase=Running node=kind-worker
25.5049,Pod,MODIFIED,eval-sanitize-2-r3-011-vt6dt,phase=Running node=kind-worker
25.5113,Pod,MODIFIED,eval-sanitize-2-r3-013-cnzht,phase=Running node=kind-worker
25.7136,Job,MODIFIED,eval-sanitize-2-r3-014,
25.715,Job,MODIFIED,eval-sanitize-2-r3-012,
25.7162,Job,MODIFIED,eval-sanitize-2-r3-006,
25.7195,Job,MODIFIED,eval-sanitize-2-r3-006,
25.7216,Job,MODIFIED,eval-sanitize-2-r3-005,
25.7245,Job,MODIFIED,eval-sanitize-2-r3-014,
25.7261,Pod,MODIFIED,eval-sanitize-2-r3-012-4v9kc,phase=Succeeded node=kind-worker2
25.7265,Event,ADDED,eval-sanitize-2-r3-006.18d3d18d6db82df1,reason=Completed count=1 msg=Job completed
25.7273,Job,MODIFIED,eval-sanitize-2-r3-012,
25.7281,Job,MODIFIED,eval-sanitize-2-r3-005,
25.73,Event,ADDED,eval-sanitize-2-r3-005.18d3d18d6e25c11b,reason=Completed count=1 msg=Job completed
25.7328,Job,MODIFIED,eval-sanitize-2-r3-006,
25.7356,Job,MODIFIED,eval-sanitize-2-r3-005,
25.7383,TaskRequest,MODIFIED,eval-sanitize-2-r3-006,phase=Complete job=None
25.7424,Node,MODIFIED,kind-control-plane,taints=1
25.7433,TaskRequest,MODIFIED,eval-sanitize-2-r3-005,phase=Complete job=None
25.7482,Job,MODIFIED,eval-sanitize-2-r3-006,
25.7518,Job,MODIFIED,eval-sanitize-2-r3-005,
25.9082,Pod,MODIFIED,eval-sanitize-2-r3-014-k55b8,phase=Succeeded node=kind-worker2
26.0067,TaskRequest,ADDED,eval-sanitize-2-r3-026,phase=None job=None
26.0115,TaskRequest,MODIFIED,eval-sanitize-2-r3-026,phase=Pending job=None
26.0248,Job,ADDED,eval-sanitize-2-r3-026,
26.0313,Pod,ADDED,eval-sanitize-2-r3-026-sth58,phase=Pending node=None
26.0332,TaskRequest,MODIFIED,eval-sanitize-2-r3-026,phase=Scheduled job=None
26.0341,Job,MODIFIED,eval-sanitize-2-r3-026,
26.0372,Event,ADDED,eval-sanitize-2-r3-026.18d3d18d80528ff1,reason=SuccessfulCreate count=1 msg=Created pod: eval-sanitize-2-r3-026-sth58
26.0382,Pod,MODIFIED,eval-sanitize-2-r3-026-sth58,phase=Pending node=None
26.039,Event,ADDED,eval-sanitize-2-r3-026-sth58.18d3d18d805ca1f6,"reason=FailedScheduling count=None msg=0/6 nodes are available: 6 node(s) had untolerated taint(s). no new claims to deallocate, preemption: 0/6 nodes are available: 6 Preemption is not helpful for scheduling."
26.0398,Job,MODIFIED,eval-sanitize-2-r3-025,
26.0417,TaskRequest,MODIFIED,eval-sanitize-2-r3-026,phase=Scheduled job=None
26.0545,Job,MODIFIED,eval-sanitize-2-r3-025,
26.5067,Job,MODIFIED,eval-sanitize-2-r3-009,
26.5134,Pod,MODIFIED,eval-sanitize-2-r3-008-7vg7g,phase=Running node=kind-worker
26.515,Job,MODIFIED,eval-sanitize-2-r3-011,
26.5193,Job,MODIFIED,eval-sanitize-2-r3-013,
26.5209,Job,MODIFIED,eval-sanitize-2-r3-009,
26.5239,Pod,MODIFIED,eval-sanitize-2-r3-007-t9hwl,phase=Running node=kind-worker
26.5259,Job,MODIFIED,eval-sanitize-2-r3-011,
26.5375,Pod,MODIFIED,eval-sanitize-2-r3-015-9g8mh,phase=Running node=kind-worker
26.5442,Pod,MODIFIED,eval-sanitize-2-r3-010-c57dg,phase=Running node=kind-worker
26.6227,Node,MODIFIED,kind-worker2,taints=1
26.6354,Job,MODIFIED,eval-sanitize-2-r3-013,
26.6384,Node,MODIFIED,kind-worker2,taints=1
26.6445,Node,MODIFIED,kind-worker2,taints=0
26.6497,Pod,MODIFIED,eval-sanitize-2-r3-020-6k5gr,phase=Pending node=kind-worker2
26.6544,Event,ADDED,eval-sanitize-2-r3-020-6k5gr.18d3d18da52cd86a,reason=Scheduled count=None msg=Successfully assigned compute/eval-sanitize-2-r3-020-6k5gr to kind-worker2
26.6585,Node,MODIFIED,kind-worker2,taints=0
26.6596,Pod,MODIFIED,eval-sanitize-2-r3-021-4gw4x,phase=Pending node=kind-worker2
26.6671,Pod,MODIFIED,eval-sanitize-2-r3-020-6k5gr,phase=Pending node=kind-worker2
26.6674,Event,ADDED,eval-sanitize-2-r3-022-pbpff.18d3d18da5a4cda5,"reason=FailedScheduling count=None msg=0/6 nodes are available: 1 c_wall violated: 2 conflicting context pair(s) with node memory, 5 node(s) had untolerated taint(s). no new claims to deallocate, preemption: 0/6 nodes are available: 1 No preemption victims found for incoming pod, 5 Preemption is not helpful for scheduling."
26.6677,Event,ADDED,eval-sanitize-2-r3-021-4gw4x.18d3d18da5bd4747,reason=Scheduled count=None msg=Successfully assigned compute/eval-sanitize-2-r3-021-4gw4x to kind-worker2
26.669,Pod,MODIFIED,eval-sanitize-2-r3-022-pbpff,phase=Pending node=None
26.6709,Node,MODIFIED,kind-worker2,taints=0
26.6729,Pod,MODIFIED,eval-sanitize-2-r3-021-4gw4x,phase=Pending node=kind-worker2
26.6749,Pod,MODIFIED,eval-sanitize-2-r3-023-5wddd,phase=Pending node=None
26.6753,Event,ADDED,eval-sanitize-2-r3-023-5wddd.18d3d18da65d50eb,"reason=FailedScheduling count=None msg=0/6 nodes are available: 1 c_wall violated: 2 conflicting context pair(s) with node memory, 5 node(s) had untolerated taint(s). no new claims to deallocate, preemption: 0/6 nodes are available: 1 No preemption victims found for incoming pod, 5 Preemption is not helpful for scheduling."
26.6806,Pod,MODIFIED,eval-sanitize-2-r3-011-vt6dt,phase=Succeeded node=kind-worker
26.6841,Node,MODIFIED,kind-worker2,taints=0
26.6974,Pod,MODIFIED,eval-sanitize-2-r3-024-hqtgk,phase=Pending node=None
26.6986,Event,ADDED,eval-sanitize-2-r3-024-hqtgk.18d3d18da7b90767,"reason=FailedScheduling count=None msg=0/6 nodes are available: 1 c_wall violated: 2 conflicting context pair(s) with node memory, 5 node(s) had untolerated taint(s). no new claims to deallocate, preemption: 0/6 nodes are available: 1 No preemption victims found for incoming pod, 5 Preemption is not helpful for scheduling."
26.7122,Pod,MODIFIED,eval-sanitize-2-r3-025-kpnrw,phase=Pending node=None
26.7126,Event,ADDED,eval-sanitize-2-r3-025-kpnrw.18d3d18da88d9058,"reason=FailedScheduling count=None msg=0/6 nodes are available: 1 c_wall violated: 2 conflicting context pair(s) with node memory, 5 node(s) had untolerated taint(s). no new claims to deallocate, preemption: 0/6 nodes are available: 1 No preemption victims found for incoming pod, 5 Preemption is not helpful for scheduling."
26.7204,Node,MODIFIED,kind-worker2,taints=0
26.7225,Pod,MODIFIED,eval-sanitize-2-r3-026-sth58,phase=Pending node=kind-worker2
26.7233,Job,MODIFIED,eval-sanitize-2-r3-014,
26.7243,Job,MODIFIED,eval-sanitize-2-r3-012,
26.7247,Event,ADDED,eval-sanitize-2-r3-022-pbpff.18d3d18da9472646,"reason=FailedScheduling count=None msg=0/6 nodes are available: 1 c_wall violated: 2 conflicting context pair(s) with node memory, 5 node(s) had untolerated taint(s). no new claims to deallocate, preemption: 0/6 nodes are available: 1 No preemption victims found for incoming pod, 5 Preemption is not helpful for scheduling."
26.7314,Job,MODIFIED,eval-sanitize-2-r3-012,
26.7339,Event,ADDED,eval-sanitize-2-r3-026-sth58.18d3d18da96ffba4,reason=Scheduled count=None msg=Successfully assigned compute/eval-sanitize-2-r3-026-sth58 to kind-worker2
26.7342,Event,ADDED,eval-sanitize-2-r3-023-5wddd.18d3d18da981f306,"reason=FailedScheduling count=None msg=0/6 nodes are available: 1 c_wall violated: 2 conflicting context pair(s) with node memory, 5 node(s) had untolerated taint(s). no new claims to deallocate, preemption: 0/6 nodes are available: 1 No preemption victims found for incoming pod, 5 Preemption is not helpful for scheduling."
26.7361,Pod,MODIFIED,eval-sanitize-2-r3-014-k55b8,phase=Succeeded node=kind-worker2
26.7365,Event,ADDED,eval-sanitize-2-r3-024-hqtgk.18d3d18da9c02ef3,"reason=FailedScheduling count=None msg=0/6 nodes are available: 1 c_wall violated: 2 conflicting context pair(s) with node memory, 5 node(s) had untolerated taint(s). no new claims to deallocate, preemption: 0/6 nodes are available: 1 No preemption victims found for incoming pod, 5 Preemption is not helpful for scheduling."
26.7368,Event,ADDED,eval-sanitize-2-r3-025-kpnrw.18d3d18da9f6d52f,"reason=FailedScheduling count=None msg=0/6 nodes are available: 1 c_wall violated: 2 conflicting context pair(s) with node memory, 5 node(s) had untolerated taint(s). no new claims to deallocate, preemption: 0/6 nodes are available: 1 No preemption victims found for incoming pod, 5 Preemption is not helpful for scheduling."
26.737,Event,ADDED,eval-sanitize-2-r3-012.18d3d18da9f98775,reason=Completed count=1 msg=Job completed
26.7381,Job,MODIFIED,eval-sanitize-2-r3-014,
26.7392,Pod,MODIFIED,eval-sanitize-2-r3-026-sth58,phase=Pending node=kind-worker2
26.7408,Node,MODIFIED,kind-worker2,taints=0
26.7435,Job,MODIFIED,eval-sanitize-2-r3-012,
26.7496,TaskRequest,MODIFIED,eval-sanitize-2-r3-012,phase=Complete job=None
26.7556,Pod,MODIFIED,eval-sanitize-2-r3-009-j7dq8,phase=Succeeded node=kind-worker
26.759,Job,MODIFIED,eval-sanitize-2-r3-012,
26.8085,Pod,MODIFIED,eval-sanitize-2-r3-013-cnzht,phase=Succeeded node=kind-worker
26.8107,Event,MODIFIED,eval-sanitize-2-r3-022-pbpff.18d3d18da9472646,"reason=FailedScheduling count=None msg=0/6 nodes are available: 1 c_wall violated: 2 conflicting context pair(s) with node memory, 5 node(s) had untolerated taint(s). no new claims to deallocate, preemption: 0/6 nodes are available: 1 No preemption victims found for incoming pod, 5 Preemption is not helpful for scheduling."
26.8131,Event,MODIFIED,eval-sanitize-2-r3-023-5wddd.18d3d18da981f306,"reason=FailedScheduling count=None msg=0/6 nodes are available: 1 c_wall violated: 2 conflicting context pair(s) with node memory, 5 node(s) had untolerated taint(s). no new claims to deallocate, preemption: 0/6 nodes are available: 1 No preemption victims found for incoming pod, 5 Preemption is not helpful for scheduling."
26.8174,Event,MODIFIED,eval-sanitize-2-r3-024-hqtgk.18d3d18da9c02ef3,"reason=FailedScheduling count=None msg=0/6 nodes are available: 1 c_wall violated: 2 conflicting context pair(s) with node memory, 5 node(s) had untolerated taint(s). no new claims to deallocate, preemption: 0/6 nodes are available: 1 No preemption victims found for incoming pod, 5 Preemption is not helpful for scheduling."
26.8213,Event,MODIFIED,eval-sanitize-2-r3-025-kpnrw.18d3d18da9f6d52f,"reason=FailedScheduling count=None msg=0/6 nodes are available: 1 c_wall violated: 2 conflicting context pair(s) with node memory, 5 node(s) had untolerated taint(s). no new claims to deallocate, preemption: 0/6 nodes are available: 1 No preemption victims found for incoming pod, 5 Preemption is not helpful for scheduling."
27.0092,TaskRequest,ADDED,eval-sanitize-2-r3-027,phase=None job=None
27.014,TaskRequest,MODIFIED,eval-sanitize-2-r3-027,phase=Pending job=None
27.0293,Job,ADDED,eval-sanitize-2-r3-027,
27.0355,Pod,ADDED,eval-sanitize-2-r3-027-xnct6,phase=Pending node=None
27.0376,TaskRequest,MODIFIED,eval-sanitize-2-r3-027,phase=Scheduled job=None
27.0384,Job,MODIFIED,eval-sanitize-2-r3-026,
27.0435,Job,MODIFIED,eval-sanitize-2-r3-027,
27.0463,Event,ADDED,eval-sanitize-2-r3-027.18d3d18dbc24379f,reason=SuccessfulCreate count=1 msg=Created pod: eval-sanitize-2-r3-027-xnct6
27.0482,Pod,MODIFIED,eval-sanitize-2-r3-027-xnct6,phase=Pending node=kind-worker2
27.0484,TaskRequest,MODIFIED,eval-sanitize-2-r3-027,phase=Scheduled job=None
27.0507,Job,MODIFIED,eval-sanitize-2-r3-026,
27.0516,Event,ADDED,eval-sanitize-2-r3-027-xnct6.18d3d18dbcd6a28f,reason=Scheduled count=None msg=Successfully assigned compute/eval-sanitize-2-r3-027-xnct6 to kind-worker2
27.0593,Pod,MODIFIED,eval-sanitize-2-r3-027-xnct6,phase=Pending node=kind-worker2
27.0619,Node,MODIFIED,kind-worker2,taints=0
27.0734,Node,MODIFIED,kind-worker2,taints=0
27.083,Event,ADDED,eval-sanitize-2-r3-020-6k5gr.18d3d18dbeb48c23,"reason=Pulled count=1 msg=Container image ""busybox:musl"" already present on machine"
27.0874,Event,ADDED,eval-sanitize-2-r3-021-4gw4x.18d3d18dbedd3646,"reason=Pulled count=1 msg=Container image ""busybox:musl"" already present on machine"
27.1067,Event,ADDED,eval-sanitize-2-r3-020-6k5gr.18d3d18dc0230250,reason=Created count=1 msg=Created container: task
27.114,Event,ADDED,eval-sanitize-2-r3-021-4gw4x.18d3d18dc0586f4d,reason=Created count=1 msg=Created container: task
27.1252,Event,ADDED,eval-sanitize-2-r3-026-sth58.18d3d18dc1406ea3,"reason=Pulled count=1 msg=Container image ""busybox:musl"" already present on machine"
27.1459,Event,ADDED,eval-sanitize-2-r3-026-sth58.18d3d18dc27eff02,reason=Created count=1 msg=Created container: task
27.1498,Event,ADDED,eval-sanitize-2-r3-020-6k5gr.18d3d18dc28346c2,reason=Started count=1 msg=Started container task
27.1557,Event,ADDED,eval-sanitize-2-r3-021-4gw4x.18d3d18dc2840a56,reason=Started count=1 msg=Started container task
27.1792,Event,ADDED,eval-sanitize-2-r3-026-sth58.18d3d18dc4780311,reason=Started count=1 msg=Started container task
27.4841,Event,ADDED,eval-sanitize-2-r3-027-xnct6.18d3d18dd6a42162,"reason=Pulled count=1 msg=Container image ""busybox:musl"" already present on machine"
27.505,Event,ADDED,eval-sanitize-2-r3-027-xnct6.18d3d18dd7c04f63,reason=Created count=1 msg=Created container: task
27.5115,Job,MODIFIED,eval-sanitize-2-r3-009,
27.5149,Pod,MODIFIED,eval-sanitize-2-r3-016-4jb2m,phase=Running node=kind-worker
27.5183,Job,MODIFIED,eval-sanitize-2-r3-008,
27.5208,Job,MODIFIED,eval-sanitize-2-r3-011,
27.5229,Job,MODIFIED,eval-sanitize-2-r3-009,
27.5248,Pod,MODIFIED,eval-sanitize-2-r3-009-j7dq8,phase=Succeeded node=kind-worker
27.5257,Job,MODIFIED,eval-sanitize-2-r3-013,
27.5292,Job,MODIFIED,eval-sanitize-2-r3-007,
27.5324,Pod,MODIFIED,eval-sanitize-2-r3-011-vt6dt,phase=Succeeded node=kind-worker
27.5333,Job,MODIFIED,eval-sanitize-2-r3-008,
27.5344,Job,MODIFIED,eval-sanitize-2-r3-011,
27.5362,Pod,MODIFIED,eval-sanitize-2-r3-013-cnzht,phase=Succeeded node=kind-worker
27.5414,Job,MODIFIED,eval-sanitize-2-r3-013,
27.5424,Job,MODIFIED,eval-sanitize-2-r3-007,
27.5447,Job,MODIFIED,eval-sanitize-2-r3-015,
27.5512,Job,MODIFIED,eval-sanitize-2-r3-010,
27.5559,Job,MODIFIED,eval-sanitize-2-r3-015,
27.575,Event,ADDED,eval-sanitize-2-r3-027-xnct6.18d3d18ddc03c2f6,reason=Started count=1 msg=Started container task
27.6199,Job,MODIFIED,eval-sanitize-2-r3-010,
27.6991,Pod,MODIFIED,eval-sanitize-2-r3-015-9g8mh,phase=Succeeded node=kind-worker
27.7146,Pod,MODIFIED,eval-sanitize-2-r3-020-6k5gr,phase=Running node=kind-worker2
27.7208,Pod,MODIFIED,eval-sanitize-2-r3-021-4gw4x,phase=Running node=kind-worker2
27.7276,Pod,MODIFIED,eval-sanitize-2-r3-027-xnct6,phase=Running node=kind-worker2
27.7306,Job,MODIFIED,eval-sanitize-2-r3-014,
27.7351,Job,MODIFIED,eval-sanitize-2-r3-014,
27.7387,Pod,MODIFIED,eval-sanitize-2-r3-026-sth58,phase=Running node=kind-worker2
27.7392,Event,ADDED,eval-sanitize-2-r3-014.18d3d18de5d5f2a1,reason=Completed count=1 msg=Job completed
27.7424,Pod,MODIFIED,eval-sanitize-2-r3-007-t9hwl,phase=Succeeded node=kind-worker
27.7457,Job,MODIFIED,eval-sanitize-2-r3-014,
27.7504,Pod,MODIFIED,eval-sanitize-2-r3-010-c57dg,phase=Succeeded node=kind-worker
27.7505,TaskRequest,MODIFIED,eval-sanitize-2-r3-014,phase=Complete job=None
27.7568,Pod,MODIFIED,eval-sanitize-2-r3-008-7vg7g,phase=Succeeded node=kind-worker
27.759,Job,MODIFIED,eval-sanitize-2-r3-014,
28.008,TaskRequest,ADDED,eval-sanitize-2-r3-028,phase=None job=None
28.013,TaskRequest,MODIFIED,eval-sanitize-2-r3-028,phase=Pending job=None
28.0271,Job,ADDED,eval-sanitize-2-r3-028,
28.0323,TaskRequest,MODIFIED,eval-sanitize-2-r3-028,phase=Scheduled job=None
28.0349,Pod,ADDED,eval-sanitize-2-r3-028-c58x6,phase=Pending node=None
28.0355,Job,MODIFIED,eval-sanitize-2-r3-028,
28.0404,Job,MODIFIED,eval-sanitize-2-r3-027,
28.0416,Event,ADDED,eval-sanitize-2-r3-028.18d3d18df7ba621f,reason=SuccessfulCreate count=1 msg=Created pod: eval-sanitize-2-r3-028-c58x6
28.0418,TaskRequest,MODIFIED,eval-sanitize-2-r3-028,phase=Scheduled job=None
28.0451,Job,MODIFIED,eval-sanitize-2-r3-026,
28.0461,Pod,MODIFIED,eval-sanitize-2-r3-028-c58x6,phase=Pending node=kind-worker2
28.0503,Job,MODIFIED,eval-sanitize-2-r3-027,
28.0516,Event,ADDED,eval-sanitize-2-r3-028-c58x6.18d3d18df84ddad4,reason=Scheduled count=None msg=Successfully assigned compute/eval-sanitize-2-r3-028-c58x6 to kind-worker2
28.0541,Job,MODIFIED,eval-sanitize-2-r3-026,
28.0588,Pod,MODIFIED,eval-sanitize-2-r3-028-c58x6,phase=Pending node=kind-worker2
28.4208,Pod,MODIFIED,eval-sanitize-2-r3-017-98n66,phase=Running node=kind-worker4
28.4763,Event,ADDED,eval-sanitize-2-r3-028-c58x6.18d3d18e11a0dc50,"reason=Pulled count=1 msg=Container image ""busybox:musl"" already present on machine"
28.4939,Event,ADDED,eval-sanitize-2-r3-028-c58x6.18d3d18e12dbcf98,reason=Created count=1 msg=Created container: task
28.5172,Job,MODIFIED,eval-sanitize-2-r3-009,
28.5193,Job,MODIFIED,eval-sanitize-2-r3-016,
28.5229,Job,MODIFIED,eval-sanitize-2-r3-009,
28.5246,Job,MODIFIED,eval-sanitize-2-r3-008,
28.5266,Job,MODIFIED,eval-sanitize-2-r3-011,
28.528,Event,ADDED,eval-sanitize-2-r3-009.18d3d18e14d17f92,reason=Completed count=1 msg=Job completed
28.5288,Job,MODIFIED,eval-sanitize-2-r3-016,
28.5303,Job,MODIFIED,eval-sanitize-2-r3-013,
28.5349,Pod,MODIFIED,eval-sanitize-2-r3-008-7vg7g,phase=Succeeded node=kind-worker
28.5365,Job,MODIFIED,eval-sanitize-2-r3-011,
28.538,Job,MODIFIED,eval-sanitize-2-r3-007,
28.5396,Job,MODIFIED,eval-sanitize-2-r3-009,
28.541,Job,MODIFIED,eval-sanitize-2-r3-008,
28.5421,Job,MODIFIED,eval-sanitize-2-r3-013,
28.5424,Event,ADDED,eval-sanitize-2-r3-011.18d3d18e157c390f,reason=Completed count=1 msg=Job completed
28.5443,TaskRequest,MODIFIED,eval-sanitize-2-r3-009,phase=Complete job=None
28.5459,Pod,MODIFIED,eval-sanitize-2-r3-007-t9hwl,phase=Succeeded node=kind-worker
28.5471,Job,MODIFIED,eval-sanitize-2-r3-011,
28.5474,Event,ADDED,eval-sanitize-2-r3-013.18d3d18e15b55f2d,reason=Completed count=1 msg=Job completed
28.5511,Job,MODIFIED,eval-sanitize-2-r3-015,
28.552,Job,MODIFIED,eval-sanitize-2-r3-007,
28.5531,Job,MODIFIED,eval-sanitize-2-r3-013,
28.5569,Job,MODIFIED,eval-sanitize-2-r3-009,
28.557,TaskRequest,MODIFIED,eval-sanitize-2-r3-011,phase=Complete job=None
28.5604,Event,ADDED,eval-sanitize-2-r3-007.18d3d18e168102b3,reason=Completed count=1 msg=Job completed
28.5613,Job,MODIFIED,eval-sanitize-2-r3-010,
28.5648,Job,MODIFIED,eval-sanitize-2-r3-007,
28.5664,Pod,MODIFIED,eval-sanitize-2-r3-015-9g8mh,phase=Succeeded node=kind-worker
28.5723,Pod,MODIFIED,eval-sanitize-2-r3-010-c57dg,phase=Succeeded node=kind-worker
28.5732,Job,MODIFIED,eval-sanitize-2-r3-015,
28.5761,Job,MODIFIED,eval-sanitize-2-r3-010,
28.5765,Event,ADDED,eval-sanitize-2-r3-015.18d3d18e17bac219,reason=Completed count=1 msg=Job completed
28.5802,Event,ADDED,eval-sanitize-2-r3-010.18d3d18e17fd215e,reason=Completed count=1 msg=Job completed
28.6171,TaskRequest,MODIFIED,eval-sanitize-2-r3-007,phase=Complete job=None
28.6233,Job,MODIFIED,eval-sanitize-2-r3-011,
28.6234,TaskRequest,MODIFIED,eval-sanitize-2-r3-013,phase=Complete job=None
28.6269,Job,MODIFIED,eval-sanitize-2-r3-007,
28.6294,Job,MODIFIED,eval-sanitize-2-r3-015,
28.6313,Job,MODIFIED,eval-sanitize-2-r3-013,
28.6329,Job,MODIFIED,eval-sanitize-2-r3-010,
28.6342,TaskRequest,MODIFIED,eval-sanitize-2-r3-015,phase=Complete job=None
28.653,Event,ADDED,eval-sanitize-2-r3-028-c58x6.18d3d18e1c53a0e2,reason=Started count=1 msg=Started container task
28.6658,Node,MODIFIED,kind-worker2,taints=1
28.6696,Pod,MODIFIED,eval-sanitize-2-r3-023-5wddd,phase=Pending node=None
28.6752,Pod,MODIFIED,eval-sanitize-2-r3-024-hqtgk,phase=Pending node=None
28.68,Node,MODIFIED,kind-worker2,taints=1
28.6813,Pod,MODIFIED,eval-sanitize-2-r3-025-kpnrw,phase=Pending node=None
28.686,Pod,MODIFIED,eval-sanitize-2-r3-022-pbpff,phase=Pending node=None
28.7183,TaskRequest,MODIFIED,eval-sanitize-2-r3-010,phase=Complete job=None
28.7222,Job,MODIFIED,eval-sanitize-2-r3-020,
28.724,Job,MODIFIED,eval-sanitize-2-r3-015,
28.7256,Pod,MODIFIED,eval-sanitize-2-r3-028-c58x6,phase=Running node=kind-worker2
28.7263,Job,MODIFIED,eval-sanitize-2-r3-021,
28.7283,Job,MODIFIED,eval-sanitize-2-r3-010,
28.7297,Pod,MODIFIED,eval-sanitize-2-r3-016-4jb2m,phase=Succeeded node=kind-worker
28.7322,Job,MODIFIED,eval-sanitize-2-r3-020,
28.7342,Job,MODIFIED,eval-sanitize-2-r3-021,
29.0085,TaskRequest,ADDED,eval-sanitize-2-r3-029,phase=None job=None
29.0119,TaskRequest,MODIFIED,eval-sanitize-2-r3-029,phase=Pending job=None
29.0361,Job,ADDED,eval-sanitize-2-r3-029,
29.0406,Job,MODIFIED,eval-sanitize-2-r3-028,
29.0407,TaskRequest,MODIFIED,eval-sanitize-2-r3-029,phase=Scheduled job=None
29.0436,Pod,ADDED,eval-sanitize-2-r3-029-nb4jp,phase=Pending node=None
29.0457,Job,MODIFIED,eval-sanitize-2-r3-029,
29.0496,Event,ADDED,eval-sanitize-2-r3-029.18d3d18e33da0c36,reason=SuccessfulCreate count=1 msg=Created pod: eval-sanitize-2-r3-029-nb4jp
29.0498,Event,ADDED,eval-sanitize-2-r3-029-nb4jp.18d3d18e33e34f3f,"reason=FailedScheduling count=None msg=0/6 nodes are available: 6 node(s) had untolerated taint(s). no new claims to deallocate, preemption: 0/6 nodes are available: 6 Preemption is not helpful for scheduling."
29.0508,Pod,MODIFIED,eval-sanitize-2-r3-029-nb4jp,phase=Pending node=None
29.0517,Job,MODIFIED,eval-sanitize-2-r3-028,
29.0518,TaskRequest,MODIFIED,eval-sanitize-2-r3-029,phase=Scheduled job=None
29.378,Pod,MODIFIED,eval-sanitize-2-r3-018-lhc4h,phase=Running node=kind-worker5
29.4267,Job,MODIFIED,eval-sanitize-2-r3-017,
29.4371,Job,MODIFIED,eval-sanitize-2-r3-017,
29.5067,Pod,MODIFIED,eval-sanitize-2-r3-017-98n66,phase=Succeeded node=kind-worker4
29.5258,Job,MODIFIED,eval-sanitize-2-r3-016,
29.5295,Job,MODIFIED,eval-sanitize-2-r3-008,
29.5352,Job,MODIFIED,eval-sanitize-2-r3-008,
29.5367,Pod,MODIFIED,eval-sanitize-2-r3-016-4jb2m,phase=Succeeded node=kind-worker
29.5396,Job,MODIFIED,eval-sanitize-2-r3-016,
29.5414,Event,ADDED,eval-sanitize-2-r3-008.18d3d18e51266449,reason=Completed count=1 msg=Job completed
29.5481,Node,MODIFIED,kind-worker,taints=1
29.5491,Job,MODIFIED,eval-sanitize-2-r3-008,
29.5543,TaskRequest,MODIFIED,eval-sanitize-2-r3-008,phase=Complete job=None
29.5622,Node,MODIFIED,kind-worker,taints=0
29.5661,Job,MODIFIED,eval-sanitize-2-r3-008,
29.5683,Pod,MODIFIED,eval-sanitize-2-r3-023-5wddd,phase=Pending node=kind-worker
29.5726,Node,MODIFIED,kind-worker,taints=0
29.577,Pod,MODIFIED,eval-sanitize-2-r3-024-hqtgk,phase=Pending node=kind-worker
29.5781,Event,ADDED,eval-sanitize-2-r3-023-5wddd.18d3d18e5318ea30,reason=Scheduled count=None msg=Successfully assigned compute/eval-sanitize-2-r3-023-5wddd to kind-worker
29.5784,Event,ADDED,eval-sanitize-2-r3-025-kpnrw.18d3d18e5337bca1,"reason=FailedScheduling count=None msg=0/6 nodes are available: 1 c_wall violated: 1 conflicting context pair(s) with node memory, 5 node(s) had untolerated taint(s). no new claims to deallocate, preemption: 0/6 nodes are available: 1 No preemption victims found for incoming pod, 5 Preemption is not helpful for scheduling."
29.5795,Pod,MODIFIED,eval-sanitize-2-r3-025-kpnrw,phase=Pending node=None
29.5838,Pod,MODIFIED,eval-sanitize-2-r3-023-5wddd,phase=Pending node=kind-worker
29.5842,Event,ADDED,eval-sanitize-2-r3-024-hqtgk.18d3d18e539a47e9,reason=Scheduled count=None msg=Successfully assigned compute/eval-sanitize-2-r3-024-hqtgk to kind-worker
29.589,Node,MODIFIED,kind-worker,taints=0
29.5897,Event,ADDED,eval-sanitize-2-r3-022-pbpff.18d3d18e540a11c3,"reason=FailedScheduling count=None msg=0/6 nodes are available: 1 c_wall violated: 1 conflicting context pair(s) with node memory, 5 node(s) had untolerated taint(s). no new claims to deallocate, preemption: 0/6 nodes are available: 1 No preemption victims found for incoming pod, 5 Preemption is not helpful for scheduling."
29.5907,Pod,MODIFIED,eval-sanitize-2-r3-022-pbpff,phase=Pending node=None
29.5918,Pod,MODIFIED,eval-sanitize-2-r3-024-hqtgk,phase=Pending node=kind-worker
29.5999,Node,MODIFIED,kind-worker,taints=0
29.6002,Event,ADDED,eval-sanitize-2-r3-029-nb4jp.18d3d18e54ad9f01,"reason=FailedScheduling count=None msg=0/6 nodes are available: 1 c_wall violated: 2 conflicting context pair(s) with node memory, 5 node(s) had untolerated taint(s). no new claims to deallocate, preemption: 0/6 nodes are available: 1 No preemption victims found for incoming pod, 5 Preemption is not helpful for scheduling."
29.6012,Pod,MODIFIED,eval-sanitize-2-r3-029-nb4jp,phase=Pending node=None
29.609,Event,ADDED,eval-sanitize-2-r3-025-kpnrw.18d3d18e553e6c36,"reason=FailedScheduling count=None msg=0/6 nodes are available: 1 c_wall violated: 1 conflicting context pair(s) with node memory, 5 node(s) had untolerated taint(s). no new claims to deallocate, preemption: 0/6 nodes are available: 1 No preemption victims found for incoming pod, 5 Preemption is not helpful for scheduling."
29.6097,Event,ADDED,eval-sanitize-2-r3-022-pbpff.18d3d18e5568bc19,"reason=FailedScheduling count=None msg=0/6 nodes are available: 1 c_wall violated: 1 conflicting context pair(s) with node memory, 5 node(s) had untolerated taint(s). no new claims to deallocate, preemption: 0/6 nodes are available: 1 No preemption victims found for incoming pod, 5 Preemption is not helpful for scheduling."
29.6122,Event,ADDED,eval-sanitize-2-r3-029-nb4jp.18d3d18e559421c0,"reason=FailedScheduling count=None msg=0/6 nodes are available: 1 c_wall violated: 2 conflicting context pair(s) with node memory, 5 node(s) had untolerated taint(s). no new claims to deallocate, preemption: 0/6 nodes are available: 1 No preemption victims found for incoming pod, 5 Preemption is not helpful for scheduling."
29.6467,Node,MODIFIED,kind-worker,taints=0
29.6576,Event,MODIFIED,eval-sanitize-2-r3-025-kpnrw.18d3d18e553e6c36,"reason=FailedScheduling count=None msg=0/6 nodes are available: 1 c_wall violated: 1 conflicting context pair(s) with node memory, 5 node(s) had untolerated taint(s). no new claims to deallocate, preemption: 0/6 nodes are available: 1 No preemption victims found for incoming pod, 5 Preemption is not helpful for scheduling."
29.659,Node,MODIFIED,kind-worker,taints=0
29.6777,Event,MODIFIED,eval-sanitize-2-r3-022-pbpff.18d3d18e5568bc19,"reason=FailedScheduling count=None msg=0/6 nodes are available: 1 c_wall violated: 1 conflicting context pair(s) with node memory, 5 node(s) had untolerated taint(s). no new claims to deallocate, preemption: 0/6 nodes are available: 1 No preemption victims found for incoming pod, 5 Preemption is not helpful for scheduling."
29.6809,Event,MODIFIED,eval-sanitize-2-r3-029-nb4jp.18d3d18e559421c0,"reason=FailedScheduling count=None msg=0/6 nodes are available: 1 c_wall violated: 2 conflicting context pair(s) with node memory, 5 node(s) had untolerated taint(s). no new claims to deallocate, preemption: 0/6 nodes are available: 1 No preemption victims found for incoming pod, 5 Preemption is not helpful for scheduling."
30.0068,Event,ADDED,eval-sanitize-2-r3-023-5wddd.18d3d18e6cfbbb81,"reason=Pulled count=1 msg=Container image ""busybox:musl"" already present on machine"
30.0076,TaskRequest,ADDED,eval-sanitize-2-r3-030,phase=None job=None
30.0123,Event,ADDED,eval-sanitize-2-r3-024-hqtgk.18d3d18e6d58f6cf,"reason=Pulled count=1 msg=Container image ""busybox:musl"" already present on machine"
30.0157,TaskRequest,MODIFIED,eval-sanitize-2-r3-030,phase=Pending job=None
30.0315,Job,ADDED,eval-sanitize-2-r3-030,
30.034,Event,ADDED,eval-sanitize-2-r3-023-5wddd.18d3d18e6e986ec3,reason=Created count=1 msg=Created container: task
30.0357,TaskRequest,MODIFIED,eval-sanitize-2-r3-030,phase=Scheduled job=None
30.0397,Pod,ADDED,eval-sanitize-2-r3-030-vs7t5,phase=Pending node=None
30.0432,Job,MODIFIED,eval-sanitize-2-r3-030,
30.0446,Event,ADDED,eval-sanitize-2-r3-024-hqtgk.18d3d18e6f126538,reason=Created count=1 msg=Created container: task
30.0471,Event,ADDED,eval-sanitize-2-r3-030.18d3d18e6f312a96,reason=SuccessfulCreate count=1 msg=Created pod: eval-sanitize-2-r3-030-vs7t5
30.0472,TaskRequest,MODIFIED,eval-sanitize-2-r3-030,phase=Scheduled job=None
30.0495,Event,ADDED,eval-sanitize-2-r3-030-vs7t5.18d3d18e6f7b7d64,"reason=FailedScheduling count=None msg=0/6 nodes are available: 1 c_wall violated: 2 conflicting context pair(s) with node memory, 5 node(s) had untolerated taint(s). no new claims to deallocate, preemption: 0/6 nodes are available: 1 No preemption victims found for incoming pod, 5 Preemption is not helpful for scheduling."
30.0505,Pod,MODIFIED,eval-sanitize-2-r3-030-vs7t5,phase=Pending node=None
30.0512,Job,MODIFIED,eval-sanitize-2-r3-029,
30.0592,Event,ADDED,eval-sanitize-2-r3-030-vs7t5.18d3d18e701a26fd,"reason=FailedScheduling count=None msg=0/6 nodes are available: 1 c_wall violated: 2 conflicting context pair(s) with node memory, 5 node(s) had untolerated taint(s). no new claims to deallocate, preemption: 0/6 nodes are available: 1 No preemption victims found for incoming pod, 5 Preemption is not helpful for scheduling."
30.0622,Job,MODIFIED,eval-sanitize-2-r3-029,
30.0728,Event,ADDED,eval-sanitize-2-r3-023-5wddd.18d3d18e70f85f42,reason=Started count=1 msg=Started container task
30.077,Event,ADDED,eval-sanitize-2-r3-024-hqtgk.18d3d18e71451f67,reason=Started count=1 msg=Started container task
30.3786,Pod,MODIFIED,eval-sanitize-2-r3-019-rvslz,phase=Running node=kind-worker3
30.3828,Job,MODIFIED,eval-sanitize-2-r3-018,
30.3944,Job,MODIFIED,eval-sanitize-2-r3-018,
30.3995,Event,MODIFIED,eval-sanitize-2-r3-030-vs7t5.18d3d18e701a26fd,"reason=FailedScheduling count=None msg=0/6 nodes are available: 1 c_wall violated: 2 conflicting context pair(s) with node memory, 5 node(s) had untolerated taint(s). no new claims to deallocate, preemption: 0/6 nodes are available: 1 No preemption victims found for incoming pod, 5 Preemption is not helpful for scheduling."
30.4323,Job,MODIFIED,eval-sanitize-2-r3-017,
30.4403,Pod,MODIFIED,eval-sanitize-2-r3-017-98n66,phase=Succeeded node=kind-worker4
30.4414,Job,MODIFIED,eval-sanitize-2-r3-017,
30.5129,Pod,MODIFIED,eval-sanitize-2-r3-018-lhc4h,phase=Succeeded node=kind-worker5
30.5319,Job,MODIFIED,eval-sanitize-2-r3-016,
30.5347,Pod,MODIFIED,eval-sanitize-2-r3-024-hqtgk,phase=Running node=kind-worker
30.5384,Job,MODIFIED,eval-sanitize-2-r3-016,
30.5445,Pod,MODIFIED,eval-sanitize-2-r3-023-5wddd,phase=Running node=kind-worker
30.5449,Event,ADDED,eval-sanitize-2-r3-016.18d3d18e8cea1038,reason=Completed count=1 msg=Job completed
30.553,Job,MODIFIED,eval-sanitize-2-r3-016,
30.5576,TaskRequest,MODIFIED,eval-sanitize-2-r3-016,phase=Complete job=None
30.5681,Job,MODIFIED,eval-sanitize-2-r3-016,
30.9523,Node,MODIFIED,kind-worker4,taints=1
30.9649,Node,MODIFIED,kind-worker4,taints=1
30.9749,Node,MODIFIED,kind-worker4,taints=0
31.0064,TaskRequest,ADDED,eval-sanitize-2-r3-031,phase=None job=None
31.0122,TaskRequest,MODIFIED,eval-sanitize-2-r3-031,phase=Pending job=None
31.0157,Pod,MODIFIED,eval-sanitize-2-r3-030-vs7t5,phase=Pending node=kind-worker4
31.0231,Event,ADDED,eval-sanitize-2-r3-030-vs7t5.18d3d18ea961d70c,reason=Scheduled count=None msg=Successfully assigned compute/eval-sanitize-2-r3-030-vs7t5 to kind-worker4
31.0242,Pod,MODIFIED,eval-sanitize-2-r3-029-nb4jp,phase=Pending node=kind-worker4
31.0265,Node,MODIFIED,kind-worker4,taints=0
31.0309,Pod,MODIFIED,eval-sanitize-2-r3-030-vs7t5,phase=Pending node=kind-worker4
31.0315,Job,ADDED,eval-sanitize-2-r3-031,
31.032,Event,ADDED,eval-sanitize-2-r3-029-nb4jp.18d3d18ea9e23b6b,reason=Scheduled count=None msg=Successfully assigned compute/eval-sanitize-2-r3-029-nb4jp to kind-worker4
31.0377,Pod,MODIFIED,eval-sanitize-2-r3-029-nb4jp,phase=Pending node=kind-worker4
31.0378,TaskRequest,MODIFIED,eval-sanitize-2-r3-031,phase=Scheduled job=None
31.04,Pod,ADDED,eval-sanitize-2-r3-031-rd6x9,phase=Pending node=None
31.0416,Job,MODIFIED,eval-sanitize-2-r3-031,
31.0445,Job,MODIFIED,eval-sanitize-2-r3-030,
31.0461,Node,MODIFIED,kind-worker4,taints=0
31.0464,Event,ADDED,eval-sanitize-2-r3-031.18d3d18eaadc5272,reason=SuccessfulCreate count=1 msg=Created pod: eval-sanitize-2-r3-031-rd6x9
31.0485,TaskRequest,MODIFIED,eval-sanitize-2-r3-031,phase=Scheduled job=None
31.053,Job,MODIFIED,eval-sanitize-2-r3-030,
31.0554,Node,MODIFIED,kind-worker4,taints=0
31.0854,Pod,MODIFIED,eval-sanitize-2-r3-025-kpnrw,phase=Pending node=None
31.113,Pod,MODIFIED,eval-sanitize-2-r3-031-rd6x9,phase=Pending node=None
31.1142,Event,ADDED,eval-sanitize-2-r3-031-rd6x9.18d3d18eaecf63d8,"reason=FailedScheduling count=None msg=0/6 nodes are available: 2 c_wall violated: 1 conflicting context pair(s) with node memory, 4 node(s) had untolerated taint(s). no new claims to deallocate, preemption: 0/6 nodes are available: 2 No preemption victims found for incoming pod, 4 Preemption is not helpful for scheduling."
31.1156,Node,MODIFIED,kind-worker4,taints=0
31.1278,Pod,MODIFIED,eval-sanitize-2-r3-022-pbpff,phase=Pending node=None
31.1295,Node,MODIFIED,kind-worker4,taints=0
31.1368,Event,ADDED,eval-sanitize-2-r3-025-kpnrw.18d3d18eb05fdfab,"reason=FailedScheduling count=None msg=0/6 nodes are available: 2 c_wall violated: 1 conflicting context pair(s) with node memory, 4 node(s) had untolerated taint(s). no new claims to deallocate, preemption: 0/6 nodes are available: 2 No preemption victims found for incoming pod, 4 Preemption is not helpful for scheduling."
31.2115,Event,ADDED,eval-sanitize-2-r3-031-rd6x9.18d3d18eb4be1a70,"reason=FailedScheduling count=None msg=0/6 nodes are available: 2 c_wall violated: 1 conflicting context pair(s) with node memory, 4 node(s) had untolerated taint(s). no new claims to deallocate, preemption: 0/6 nodes are available: 2 No preemption victims found for incoming pod, 4 Preemption is not helpful for scheduling."
31.2176,Node,MODIFIED,kind-worker5,taints=1
31.2181,Event,ADDED,eval-sanitize-2-r3-022-pbpff.18d3d18eb5152211,"reason=FailedScheduling count=None msg=0/6 nodes are available: 2 c_wall violated: 1 conflicting context pair(s) with node memory, 4 node(s) had untolerated taint(s). no new claims to deallocate, preemption: 0/6 nodes are available: 2 No preemption victims found for incoming pod, 4 Preemption is not helpful for scheduling."
31.2219,Event,MODIFIED,eval-sanitize-2-r3-025-kpnrw.18d3d18eb05fdfab,"reason=FailedScheduling count=None msg=0/6 nodes are available: 2 c_wall violated: 1 conflicting context pair(s) with node memory, 4 node(s) had untolerated taint(s). no new claims to deallocate, preemption: 0/6 nodes are available: 2 No preemption victims found for incoming pod, 4 Preemption is not helpful for scheduling."
31.2423,Node,MODIFIED,kind-worker5,taints=1
31.2506,Node,MODIFIED,kind-worker5,taints=0
31.2616,Node,MODIFIED,kind-worker5,taints=0
31.3125,Event,MODIFIED,eval-sanitize-2-r3-031-rd6x9.18d3d18eb4be1a70,"reason=FailedScheduling count=None msg=0/6 nodes are available: 2 c_wall violated: 1 conflicting context pair(s) with node memory, 4 node(s) had untolerated taint(s). no new claims to deallocate, preemption: 0/6 nodes are available: 2 No preemption victims found for incoming pod, 4 Preemption is not helpful for scheduling."
31.3162,Pod,MODIFIED,eval-sanitize-2-r3-022-pbpff,phase=Pending node=kind-worker5
31.3194,Event,ADDED,eval-sanitize-2-r3-022-pbpff.18d3d18ebb49f7f0,reason=Scheduled count=None msg=Successfully assigned compute/eval-sanitize-2-r3-022-pbpff to kind-worker5
31.3252,Pod,MODIFIED,eval-sanitize-2-r3-022-pbpff,phase=Pending node=kind-worker5
31.3293,Node,MODIFIED,kind-worker5,taints=0
31.342,Node,MODIFIED,kind-worker5,taints=0
31.3841,Job,MODIFIED,eval-sanitize-2-r3-019,
31.3884,Job,MODIFIED,eval-sanitize-2-r3-018,
31.394,Job,MODIFIED,eval-sanitize-2-r3-019,
31.3966,Pod,MODIFIED,eval-sanitize-2-r3-018-lhc4h,phase=Succeeded node=kind-worker5
31.398,Job,MODIFIED,eval-sanitize-2-r3-018,
31.41,Pod,MODIFIED,eval-sanitize-2-r3-025-kpnrw,phase=Pending node=kind-worker5
31.4136,Event,ADDED,eval-sanitize-2-r3-025-kpnrw.18d3d18ec0e6e62a,reason=Scheduled count=None msg=Successfully assigned compute/eval-sanitize-2-r3-025-kpnrw to kind-worker5
31.422,Pod,MODIFIED,eval-sanitize-2-r3-025-kpnrw,phase=Pending node=kind-worker5
31.424,Pod,MODIFIED,eval-sanitize-2-r3-031-rd6x9,phase=Pending node=None
31.4376,Job,MODIFIED,eval-sanitize-2-r3-017,
31.4415,Job,MODIFIED,eval-sanitize-2-r3-017,
31.4445,Event,ADDED,eval-sanitize-2-r3-017.18d3d18ec2cb5ef3,reason=Completed count=1 msg=Job completed
31.4534,Job,MODIFIED,eval-sanitize-2-r3-017,
31.4585,TaskRequest,MODIFIED,eval-sanitize-2-r3-017,phase=Complete job=None
31.4701,Job,MODIFIED,eval-sanitize-2-r3-017,
31.5129,Event,ADDED,eval-sanitize-2-r3-031-rd6x9.18d3d18ec6b79fe2,"reason=FailedScheduling count=None msg=0/6 nodes are available: 3 c_wall violated: 1 conflicting context pair(s) with node memory, 3 node(s) had untolerated taint(s). no new claims to deallocate, preemption: 0/6 nodes are available: 3 No preemption victims found for incoming pod, 3 Preemption is not helpful for scheduling."
31.5317,Event,ADDED,eval-sanitize-2-r3-030-vs7t5.18d3d18ec7cb02a3,"reason=Pulled count=1 msg=Container image ""busybox:musl"" already present on machine"
31.5397,Event,ADDED,eval-sanitize-2-r3-029-nb4jp.18d3d18ec7e0b719,"reason=Pulled count=1 msg=Container image ""busybox:musl"" already present on machine"
31.541,Job,MODIFIED,eval-sanitize-2-r3-024,
31.5519,Job,MODIFIED,eval-sanitize-2-r3-023,
31.5543,Job,MODIFIED,eval-sanitize-2-r3-024,
31.558,Pod,MODIFIED,eval-sanitize-2-r3-019-rvslz,phase=Succeeded node=kind-worker3
31.5601,Event,ADDED,eval-sanitize-2-r3-030-vs7t5.18d3d18ec95907bc,reason=Created count=1 msg=Created container: task
31.5633,Job,MODIFIED,eval-sanitize-2-r3-023,
31.5647,Event,ADDED,eval-sanitize-2-r3-029-nb4jp.18d3d18ec9ce07bd,reason=Created count=1 msg=Created container: task
31.5816,Node,MODIFIED,kind-worker,taints=1
31.5961,Node,MODIFIED,kind-worker,taints=1
31.6112,Event,MODIFIED,eval-sanitize-2-r3-031-rd6x9.18d3d18ec6b79fe2,"reason=FailedScheduling count=None msg=0/6 nodes are available: 3 c_wall violated: 1 conflicting context pair(s) with node memory, 3 node(s) had untolerated taint(s). no new claims to deallocate, preemption: 0/6 nodes are available: 3 No preemption victims found for incoming pod, 3 Preemption is not helpful for scheduling."
31.6176,Pod,MODIFIED,eval-sanitize-2-r3-031-rd6x9,phase=Pending node=None
31.6214,Event,ADDED,eval-sanitize-2-r3-030-vs7t5.18d3d18ecd44986d,reason=Started count=1 msg=Started container task
31.6277,Event,ADDED,eval-sanitize-2-r3-029-nb4jp.18d3d18ecd9750e1,reason=Started count=1 msg=Started container task
31.6287,Event,ADDED,eval-sanitize-2-r3-031-rd6x9.18d3d18ecda77940,"reason=FailedScheduling count=None msg=0/6 nodes are available: 2 c_wall violated: 1 conflicting context pair(s) with node memory, 4 node(s) had untolerated taint(s). no new claims to deallocate, preemption: 0/6 nodes are available: 2 No preemption victims found for incoming pod, 4 Preemption is not helpful for scheduling."
31.733,Event,ADDED,eval-sanitize-2-r3-022-pbpff.18d3d18ed3e68211,"reason=Pulled count=1 msg=Container image ""busybox:musl"" already present on machine"
31.7531,Event,ADDED,eval-sanitize-2-r3-022-pbpff.18d3d18ed514ed36,reason=Created count=1 msg=Created container: task
31.7858,Event,ADDED,eval-sanitize-2-r3-022-pbpff.18d3d18ed701b5c1,reason=Started count=1 msg=Started container task
31.8051,Event,ADDED,eval-sanitize-2-r3-025-kpnrw.18d3d18ed83cc68d,"reason=Pulled count=1 msg=Container image ""busybox:musl"" already present on machine"
31.8213,Event,ADDED,eval-sanitize-2-r3-025-kpnrw.18d3d18ed9399c69,reason=Created count=1 msg=Created container: task
31.8546,Event,ADDED,eval-sanitize-2-r3-025-kpnrw.18d3d18edb2dd9bf,reason=Started count=1 msg=Started container task
31.9483,Node,MODIFIED,kind-worker3,taints=1
31.9615,Node,MODIFIED,kind-worker3,taints=1
31.9619,Event,MODIFIED,eval-sanitize-2-r3-031-rd6x9.18d3d18ecda77940,"reason=FailedScheduling count=None msg=0/6 nodes are available: 2 c_wall violated: 1 conflicting context pair(s) with node memory, 4 node(s) had untolerated taint(s). no new claims to deallocate, preemption: 0/6 nodes are available: 2 No preemption victims found for incoming pod, 4 Preemption is not helpful for scheduling."
31.9718,Node,MODIFIED,kind-worker3,taints=0
31.9832,Pod,MODIFIED,eval-sanitize-2-r3-031-rd6x9,phase=Pending node=kind-worker3
31.9849,Node,MODIFIED,kind-worker3,taints=0
31.9862,Event,ADDED,eval-sanitize-2-r3-031-rd6x9.18d3d18ee307baea,reason=Scheduled count=None msg=Successfully assigned compute/eval-sanitize-2-r3-031-rd6x9 to kind-worker3
31.993,Pod,MODIFIED,eval-sanitize-2-r3-031-rd6x9,phase=Pending node=kind-worker3
32.0086,Node,MODIFIED,kind-worker3,taints=0
32.0089,TaskRequest,ADDED,eval-sanitize-2-r3-032,phase=None job=None
32.0132,TaskRequest,MODIFIED,eval-sanitize-2-r3-032,phase=Pending job=None
32.0285,Job,ADDED,eval-sanitize-2-r3-032,
32.0353,Pod,ADDED,eval-sanitize-2-r3-032-hc2dv,phase=Pending node=None
32.0354,TaskRequest,MODIFIED,eval-sanitize-2-r3-032,phase=Scheduled job=None
32.0383,Job,MODIFIED,eval-sanitize-2-r3-032,
32.0404,Event,ADDED,eval-sanitize-2-r3-032.18d3d18ee62a0093,reason=SuccessfulCreate count=1 msg=Created pod: eval-sanitize-2-r3-032-hc2dv
32.0444,Node,MODIFIED,kind-worker3,taints=0
32.0446,TaskRequest,MODIFIED,eval-sanitize-2-r3-032,phase=Scheduled job=None
32.0453,Job,MODIFIED,eval-sanitize-2-r3-031,
32.0563,Job,MODIFIED,eval-sanitize-2-r3-031,
32.0603,Pod,MODIFIED,eval-sanitize-2-r3-032-hc2dv,phase=Pending node=kind-worker4
32.0634,Event,ADDED,eval-sanitize-2-r3-032-hc2dv.18d3d18ee7a2bb95,reason=Scheduled count=None msg=Successfully assigned compute/eval-sanitize-2-r3-032-hc2dv to kind-worker4
32.0693,Pod,MODIFIED,eval-sanitize-2-r3-032-hc2dv,phase=Pending node=kind-worker4
32.3839,Pod,MODIFIED,eval-sanitize-2-r3-022-pbpff,phase=Running node=kind-worker5
32.3892,Job,MODIFIED,eval-sanitize-2-r3-019,
32.392,Pod,MODIFIED,eval-sanitize-2-r3-025-kpnrw,phase=Running node=kind-worker5
32.3946,Job,MODIFIED,eval-sanitize-2-r3-018,
32.4006,Pod,MODIFIED,eval-sanitize-2-r3-019-rvslz,phase=Succeeded node=kind-worker3
32.4038,Job,MODIFIED,eval-sanitize-2-r3-018,
32.4048,Job,MODIFIED,eval-sanitize-2-r3-019,
32.4078,Event,ADDED,eval-sanitize-2-r3-031-rd6x9.18d3d18efbe9bd5c,"reason=Pulled count=1 msg=Container image ""busybox:musl"" already present on machine"
32.4094,Event,ADDED,eval-sanitize-2-r3-018.18d3d18efc1f0c64,reason=Completed count=1 msg=Job completed
32.4168,Job,MODIFIED,eval-sanitize-2-r3-018,
32.4232,TaskRequest,MODIFIED,eval-sanitize-2-r3-018,phase=Complete job=None
32.4296,Pod,MODIFIED,eval-sanitize-2-r3-029-nb4jp,phase=Running node=kind-worker4
32.4306,Event,ADDED,eval-sanitize-2-r3-031-rd6x9.18d3d18efd780867,reason=Created count=1 msg=Created container: task
32.4335,Job,MODIFIED,eval-sanitize-2-r3-018,
32.4365,Pod,MODIFIED,eval-sanitize-2-r3-030-vs7t5,phase=Running node=kind-worker4
32.4902,Event,ADDED,eval-sanitize-2-r3-032-hc2dv.18d3d18f01040574,"reason=Pulled count=1 msg=Container image ""busybox:musl"" already present on machine"
32.4986,Event,ADDED,eval-sanitize-2-r3-031-rd6x9.18d3d18f0177efa1,reason=Started count=1 msg=Started container task
32.5079,Event,ADDED,eval-sanitize-2-r3-032-hc2dv.18d3d18f0221adb3,reason=Created count=1 msg=Created container: task
32.5674,Event,ADDED,eval-sanitize-2-r3-032-hc2dv.18d3d18f05891a04,reason=Started count=1 msg=Started container task
33.0066,TaskRequest,ADDED,eval-sanitize-2-r3-033,phase=None job=None
33.0114,TaskRequest,MODIFIED,eval-sanitize-2-r3-033,phase=Pending job=None
33.027,Job,ADDED,eval-sanitize-2-r3-033,
33.034,TaskRequest,MODIFIED,eval-sanitize-2-r3-033,phase=Scheduled job=None
33.035,Pod,ADDED,eval-sanitize-2-r3-033-2l4qz,phase=Pending node=None
33.0374,Job,MODIFIED,eval-sanitize-2-r3-033,
33.0414,Event,ADDED,eval-sanitize-2-r3-033.18d3d18f21c30773,reason=SuccessfulCreate count=1 msg=Created pod: eval-sanitize-2-r3-033-2l4qz
33.0424,Job,MODIFIED,eval-sanitize-2-r3-032,
33.0443,TaskRequest,MODIFIED,eval-sanitize-2-r3-033,phase=Scheduled job=None
33.0522,Job,MODIFIED,eval-sanitize-2-r3-032,
33.0549,Node,MODIFIED,kind-worker4,taints=1
33.0566,Pod,MODIFIED,eval-sanitize-2-r3-033-2l4qz,phase=Pending node=kind-worker3
33.0606,Event,ADDED,eval-sanitize-2-r3-033-2l4qz.18d3d18f23090ef7,reason=Scheduled count=None msg=Successfully assigned compute/eval-sanitize-2-r3-033-2l4qz to kind-worker3
33.0667,Pod,MODIFIED,eval-sanitize-2-r3-033-2l4qz,phase=Pending node=kind-worker3
33.0689,Node,MODIFIED,kind-worker3,taints=0
33.1507,Node,MODIFIED,kind-worker4,taints=1
33.1554,Node,MODIFIED,kind-worker3,taints=0
33.2702,Node,MODIFIED,kind-worker5,taints=1
33.2816,Node,MODIFIED,kind-worker5,taints=1
33.3856,Pod,MODIFIED,eval-sanitize-2-r3-031-rd6x9,phase=Running node=kind-worker3
33.3892,Job,MODIFIED,eval-sanitize-2-r3-022,
33.3942,Job,MODIFIED,eval-sanitize-2-r3-019,
33.3968,Job,MODIFIED,eval-sanitize-2-r3-025,
33.3995,Job,MODIFIED,eval-sanitize-2-r3-019,
33.4002,Job,MODIFIED,eval-sanitize-2-r3-022,
33.4048,Event,ADDED,eval-sanitize-2-r3-019.18d3d18f377e9f09,reason=Completed count=1 msg=Job completed
33.4055,Job,MODIFIED,eval-sanitize-2-r3-025,
33.4094,Job,MODIFIED,eval-sanitize-2-r3-019,
33.4149,TaskRequest,MODIFIED,eval-sanitize-2-r3-019,phase=Complete job=None
33.4253,Job,MODIFIED,eval-sanitize-2-r3-019,
33.4312,Pod,MODIFIED,eval-sanitize-2-r3-032-hc2dv,phase=Running node=kind-worker4
33.4324,Job,MODIFIED,eval-sanitize-2-r3-029,
33.4409,Job,MODIFIED,eval-sanitize-2-r3-030,
33.4425,Job,MODIFIED,eval-sanitize-2-r3-029,
33.4499,Job,MODIFIED,eval-sanitize-2-r3-030,
33.4793,Event,ADDED,eval-sanitize-2-r3-033-2l4qz.18d3d18f3bd111f3,"reason=Pulled count=1 msg=Container image ""busybox:musl"" already present on machine"
33.4957,Event,ADDED,eval-sanitize-2-r3-033-2l4qz.18d3d18f3d00d19f,reason=Created count=1 msg=Created container: task
33.5615,Event,ADDED,eval-sanitize-2-r3-033-2l4qz.18d3d18f40efaceb,reason=Started count=1 msg=Started container task
33.995,Node,MODIFIED,kind-worker3,taints=1
34.0067,Node,MODIFIED,kind-worker3,taints=1
34.0074,TaskRequest,ADDED,eval-sanitize-2-r3-034,phase=None job=None
34.011,TaskRequest,MODIFIED,eval-sanitize-2-r3-034,phase=Pending job=None
34.026,Job,ADDED,eval-sanitize-2-r3-034,
34.0301,TaskRequest,MODIFIED,eval-sanitize-2-r3-034,phase=Scheduled job=None
34.0332,Pod,ADDED,eval-sanitize-2-r3-034-f9cq9,phase=Pending node=None
34.0352,Job,MODIFIED,eval-sanitize-2-r3-034,
34.0392,Event,ADDED,eval-sanitize-2-r3-034.18d3d18f5d41de2a,reason=SuccessfulCreate count=1 msg=Created pod: eval-sanitize-2-r3-034-f9cq9
34.0395,Event,ADDED,eval-sanitize-2-r3-034-f9cq9.18d3d18f5d4e3b14,"reason=FailedScheduling count=None msg=0/6 nodes are available: 6 node(s) had untolerated taint(s). no new claims to deallocate, preemption: 0/6 nodes are available: 6 Preemption is not helpful for scheduling."
34.0405,Pod,MODIFIED,eval-sanitize-2-r3-034-f9cq9,phase=Pending node=None
34.0406,TaskRequest,MODIFIED,eval-sanitize-2-r3-034,phase=Scheduled job=None
34.0414,Job,MODIFIED,eval-sanitize-2-r3-033,
34.0473,Job,MODIFIED,eval-sanitize-2-r3-032,
34.0495,Job,MODIFIED,eval-sanitize-2-r3-033,
34.056,Job,MODIFIED,eval-sanitize-2-r3-032,
34.3925,Pod,MODIFIED,eval-sanitize-2-r3-033-2l4qz,phase=Running node=kind-worker3
34.3939,Job,MODIFIED,eval-sanitize-2-r3-031,
34.4054,Job,MODIFIED,eval-sanitize-2-r3-031,
35.0066,TaskRequest,ADDED,eval-sanitize-2-r3-035,phase=None job=None
35.0131,TaskRequest,MODIFIED,eval-sanitize-2-r3-035,phase=Pending job=None
35.029,Job,ADDED,eval-sanitize-2-r3-035,
35.0358,Pod,ADDED,eval-sanitize-2-r3-035-6gkkd,phase=Pending node=None
35.0377,TaskRequest,MODIFIED,eval-sanitize-2-r3-035,phase=Scheduled job=None
35.0385,Job,MODIFIED,eval-sanitize-2-r3-035,
35.0393,Job,MODIFIED,eval-sanitize-2-r3-034,
35.0423,Event,ADDED,eval-sanitize-2-r3-035.18d3d18f99025470,reason=SuccessfulCreate count=1 msg=Created pod: eval-sanitize-2-r3-035-6gkkd
35.0426,Event,ADDED,eval-sanitize-2-r3-035-6gkkd.18d3d18f990c4f18,"reason=FailedScheduling count=None msg=0/6 nodes are available: 6 node(s) had untolerated taint(s). no new claims to deallocate, preemption: 0/6 nodes are available: 6 Preemption is not helpful for scheduling."
35.0436,Pod,MODIFIED,eval-sanitize-2-r3-035-6gkkd,phase=Pending node=None
35.0465,Job,MODIFIED,eval-sanitize-2-r3-033,
35.0481,TaskRequest,MODIFIED,eval-sanitize-2-r3-035,phase=Scheduled job=None
35.0505,Job,MODIFIED,eval-sanitize-2-r3-034,
35.055,Job,MODIFIED,eval-sanitize-2-r3-033,
36.0109,TaskRequest,ADDED,eval-sanitize-2-r3-036,phase=None job=None
36.0147,TaskRequest,MODIFIED,eval-sanitize-2-r3-036,phase=Pending job=None
36.0322,Job,ADDED,eval-sanitize-2-r3-036,
36.0368,TaskRequest,MODIFIED,eval-sanitize-2-r3-036,phase=Scheduled job=None
36.0398,Pod,ADDED,eval-sanitize-2-r3-036-k2ckt,phase=Pending node=None
36.0421,Job,MODIFIED,eval-sanitize-2-r3-035,
36.0429,Job,MODIFIED,eval-sanitize-2-r3-036,
36.046,Event,ADDED,eval-sanitize-2-r3-036.18d3d18fd4dc6aa5,reason=SuccessfulCreate count=1 msg=Created pod: eval-sanitize-2-r3-036-k2ckt
36.0463,Event,ADDED,eval-sanitize-2-r3-036-k2ckt.18d3d18fd4e7976d,"reason=FailedScheduling count=None msg=0/6 nodes are available: 6 node(s) had untolerated taint(s). no new claims to deallocate, preemption: 0/6 nodes are available: 6 Preemption is not helpful for scheduling."
36.0464,TaskRequest,MODIFIED,eval-sanitize-2-r3-036,phase=Scheduled job=None
36.0474,Pod,MODIFIED,eval-sanitize-2-r3-036-k2ckt,phase=Pending node=None
36.0508,Job,MODIFIED,eval-sanitize-2-r3-035,
37.0114,TaskRequest,ADDED,eval-sanitize-2-r3-037,phase=None job=None
37.0161,TaskRequest,MODIFIED,eval-sanitize-2-r3-037,phase=Pending job=None
37.0318,Job,ADDED,eval-sanitize-2-r3-037,
37.037,Pod,ADDED,eval-sanitize-2-r3-037-9n9rh,phase=Pending node=None
37.0383,TaskRequest,MODIFIED,eval-sanitize-2-r3-037,phase=Scheduled job=None
37.0408,Job,MODIFIED,eval-sanitize-2-r3-037,
37.0443,Event,ADDED,eval-sanitize-2-r3-037.18d3d190104f229f,reason=SuccessfulCreate count=1 msg=Created pod: eval-sanitize-2-r3-037-9n9rh
37.0445,Event,ADDED,eval-sanitize-2-r3-037-9n9rh.18d3d190105c0cbb,"reason=FailedScheduling count=None msg=0/6 nodes are available: 6 node(s) had untolerated taint(s). no new claims to deallocate, preemption: 0/6 nodes are available: 6 Preemption is not helpful for scheduling."
37.0454,Pod,MODIFIED,eval-sanitize-2-r3-037-9n9rh,phase=Pending node=None
37.0464,Job,MODIFIED,eval-sanitize-2-r3-036,
37.0476,TaskRequest,MODIFIED,eval-sanitize-2-r3-037,phase=Scheduled job=None
37.055,Job,MODIFIED,eval-sanitize-2-r3-036,
37.7415,Pod,MODIFIED,eval-sanitize-2-r3-026-sth58,phase=Running node=kind-worker2
37.7483,Pod,MODIFIED,eval-sanitize-2-r3-021-4gw4x,phase=Running node=kind-worker2
37.7559,Pod,MODIFIED,eval-sanitize-2-r3-027-xnct6,phase=Running node=kind-worker2
37.7616,Pod,MODIFIED,eval-sanitize-2-r3-020-6k5gr,phase=Running node=kind-worker2
38.0069,TaskRequest,ADDED,eval-sanitize-2-r3-038,phase=None job=None
38.0104,TaskRequest,MODIFIED,eval-sanitize-2-r3-038,phase=Pending job=None
38.0257,Job,ADDED,eval-sanitize-2-r3-038,
38.0328,Pod,ADDED,eval-sanitize-2-r3-038-bshss,phase=Pending node=None
38.0329,TaskRequest,MODIFIED,eval-sanitize-2-r3-038,phase=Scheduled job=None
38.0354,Job,MODIFIED,eval-sanitize-2-r3-038,
38.0369,Event,ADDED,eval-sanitize-2-r3-038.18d3d1904ba0529c,reason=SuccessfulCreate count=1 msg=Created pod: eval-sanitize-2-r3-038-bshss
38.0379,Pod,MODIFIED,eval-sanitize-2-r3-038-bshss,phase=Pending node=None
38.0386,Event,ADDED,eval-sanitize-2-r3-038-bshss.18d3d1904baca8b5,"reason=FailedScheduling count=None msg=0/6 nodes are available: 6 node(s) had untolerated taint(s). no new claims to deallocate, preemption: 0/6 nodes are available: 6 Preemption is not helpful for scheduling."
38.0394,TaskRequest,MODIFIED,eval-sanitize-2-r3-038,phase=Scheduled job=None
38.0423,Job,MODIFIED,eval-sanitize-2-r3-037,
38.0507,Job,MODIFIED,eval-sanitize-2-r3-037,
38.7508,Job,MODIFIED,eval-sanitize-2-r3-026,
38.7549,Pod,MODIFIED,eval-sanitize-2-r3-028-c58x6,phase=Running node=kind-worker2
38.7573,Job,MODIFIED,eval-sanitize-2-r3-021,
38.7625,Job,MODIFIED,eval-sanitize-2-r3-027,
38.764,Job,MODIFIED,eval-sanitize-2-r3-026,
38.7659,Job,MODIFIED,eval-sanitize-2-r3-020,
38.7682,Job,MODIFIED,eval-sanitize-2-r3-021,
38.7717,Job,MODIFIED,eval-sanitize-2-r3-027,
38.7773,Job,MODIFIED,eval-sanitize-2-r3-020,
38.9007,Pod,MODIFIED,eval-sanitize-2-r3-026-sth58,phase=Succeeded node=kind-worker2
38.9667,Pod,MODIFIED,eval-sanitize-2-r3-027-xnct6,phase=Succeeded node=kind-worker2
38.973,Pod,MODIFIED,eval-sanitize-2-r3-021-4gw4x,phase=Succeeded node=kind-worker2
38.9812,Pod,MODIFIED,eval-sanitize-2-r3-020-6k5gr,phase=Succeeded node=kind-worker2
39.0085,TaskRequest,ADDED,eval-sanitize-2-r3-039,phase=None job=None
39.0121,TaskRequest,MODIFIED,eval-sanitize-2-r3-039,phase=Pending job=None
39.0269,Job,ADDED,eval-sanitize-2-r3-039,
39.0337,Pod,ADDED,eval-sanitize-2-r3-039-gr78z,phase=Pending node=None
39.0339,TaskRequest,MODIFIED,eval-sanitize-2-r3-039,phase=Scheduled job=None
39.0368,Job,MODIFIED,eval-sanitize-2-r3-039,
39.0387,Event,ADDED,eval-sanitize-2-r3-039.18d3d190874ede20,reason=SuccessfulCreate count=1 msg=Created pod: eval-sanitize-2-r3-039-gr78z
39.0389,Event,ADDED,eval-sanitize-2-r3-039-gr78z.18d3d19087592f6d,"reason=FailedScheduling count=None msg=0/6 nodes are available: 6 node(s) had untolerated taint(s). no new claims to deallocate, preemption: 0/6 nodes are available: 6 Preemption is not helpful for scheduling."
39.0397,Pod,MODIFIED,eval-sanitize-2-r3-039-gr78z,phase=Pending node=None
39.0404,Job,MODIFIED,eval-sanitize-2-r3-038,
39.0411,TaskRequest,MODIFIED,eval-sanitize-2-r3-039,phase=Scheduled job=None
39.0475,Job,MODIFIED,eval-sanitize-2-r3-038,
39.7716,Job,MODIFIED,eval-sanitize-2-r3-026,
39.7738,Job,MODIFIED,eval-sanitize-2-r3-028,
39.7747,Job,MODIFIED,eval-sanitize-2-r3-021,
39.7757,Job,MODIFIED,eval-sanitize-2-r3-027,
39.7766,Job,MODIFIED,eval-sanitize-2-r3-020,
39.7816,Pod,MODIFIED,eval-sanitize-2-r3-026-sth58,phase=Succeeded node=kind-worker2
39.7848,Pod,MODIFIED,eval-sanitize-2-r3-020-6k5gr,phase=Succeeded node=kind-worker2
39.7862,Pod,MODIFIED,eval-sanitize-2-r3-027-xnct6,phase=Succeeded node=kind-worker2
39.787,Job,MODIFIED,eval-sanitize-2-r3-026,
39.7884,Pod,MODIFIED,eval-sanitize-2-r3-021-4gw4x,phase=Succeeded node=kind-worker2
39.7892,Job,MODIFIED,eval-sanitize-2-r3-028,
39.7908,Job,MODIFIED,eval-sanitize-2-r3-027,
39.7918,Job,MODIFIED,eval-sanitize-2-r3-020,
39.7926,Job,MODIFIED,eval-sanitize-2-r3-021,
39.7935,Event,ADDED,eval-sanitize-2-r3-020.18d3d190b45f2359,reason=Completed count=1 msg=Job completed
39.7968,Job,MODIFIED,eval-sanitize-2-r3-027,
39.7986,Job,MODIFIED,eval-sanitize-2-r3-021,
39.7989,Event,ADDED,eval-sanitize-2-r3-027.18d3d190b4611ce8,reason=Completed count=1 msg=Job completed
39.7999,Job,MODIFIED,eval-sanitize-2-r3-020,
39.8015,TaskRequest,MODIFIED,eval-sanitize-2-r3-027,phase=Complete job=None
39.8033,Event,ADDED,eval-sanitize-2-r3-021.18d3d190b462590a,reason=Completed count=1 msg=Job completed
39.8775,TaskRequest,MODIFIED,eval-sanitize-2-r3-021,phase=Complete job=None
39.8804,Job,MODIFIED,eval-sanitize-2-r3-027,
39.881,TaskRequest,MODIFIED,eval-sanitize-2-r3-020,phase=Complete job=None
39.8871,Job,MODIFIED,eval-sanitize-2-r3-021,
39.8895,Job,MODIFIED,eval-sanitize-2-r3-020,
39.9461,Pod,MODIFIED,eval-sanitize-2-r3-028-c58x6,phase=Succeeded node=kind-worker2
40.0147,TaskRequest,ADDED,eval-sanitize-2-r3-040,phase=None job=None
40.0178,TaskRequest,MODIFIED,eval-sanitize-2-r3-040,phase=Pending job=None
40.0322,Job,ADDED,eval-sanitize-2-r3-040,
40.0451,Job,MODIFIED,eval-sanitize-2-r3-039,
40.0509,Pod,ADDED,eval-sanitize-2-r3-040-62m2q,phase=Pending node=None
40.051,TaskRequest,MODIFIED,eval-sanitize-2-r3-040,phase=Scheduled job=None
40.0529,Job,MODIFIED,eval-sanitize-2-r3-040,
40.0579,Event,ADDED,eval-sanitize-2-r3-040.18d3d190c3e030b6,reason=SuccessfulCreate count=1 msg=Created pod: eval-sanitize-2-r3-040-62m2q
40.0581,Event,ADDED,eval-sanitize-2-r3-040-62m2q.18d3d190c3ec2020,"reason=FailedScheduling count=None msg=0/6 nodes are available: 6 node(s) had untolerated taint(s). no new claims to deallocate, preemption: 0/6 nodes are available: 6 Preemption is not helpful for scheduling."
40.059,Pod,MODIFIED,eval-sanitize-2-r3-040-62m2q,phase=Pending node=None
40.06,Job,MODIFIED,eval-sanitize-2-r3-039,
40.0709,TaskRequest,MODIFIED,eval-sanitize-2-r3-040,phase=Scheduled job=None
40.559,Pod,MODIFIED,eval-sanitize-2-r3-024-hqtgk,phase=Running node=kind-worker
40.5654,Pod,MODIFIED,eval-sanitize-2-r3-023-5wddd,phase=Running node=kind-worker
40.7837,Job,MODIFIED,eval-sanitize-2-r3-026,
40.7858,Job,MODIFIED,eval-sanitize-2-r3-028,
40.7881,Job,MODIFIED,eval-sanitize-2-r3-026,
40.7954,Event,ADDED,eval-sanitize-2-r3-026.18d3d190efd60494,reason=Completed count=1 msg=Job completed
40.7968,Pod,MODIFIED,eval-sanitize-2-r3-028-c58x6,phase=Succeeded node=kind-worker2
40.7978,Job,MODIFIED,eval-sanitize-2-r3-028,
40.802,Job,MODIFIED,eval-sanitize-2-r3-026,
40.8061,TaskRequest,MODIFIED,eval-sanitize-2-r3-026,phase=Complete job=None
40.8148,Job,MODIFIED,eval-sanitize-2-r3-026,
41.03,TaskRequest,ADDED,eval-sanitize-2-r3-041,phase=None job=None
41.0336,TaskRequest,MODIFIED,eval-sanitize-2-r3-041,phase=Pending job=None
41.0507,Job,ADDED,eval-sanitize-2-r3-041,
41.0557,Job,MODIFIED,eval-sanitize-2-r3-040,
41.0574,TaskRequest,MODIFIED,eval-sanitize-2-r3-041,phase=Scheduled job=None
41.0584,Pod,ADDED,eval-sanitize-2-r3-041-qffxl,phase=Pending node=None
41.0601,Job,MODIFIED,eval-sanitize-2-r3-041,
41.0639,Pod,MODIFIED,eval-sanitize-2-r3-041-qffxl,phase=Pending node=None
41.0651,Event,ADDED,eval-sanitize-2-r3-041.18d3d190fff00e55,reason=SuccessfulCreate count=1 msg=Created pod: eval-sanitize-2-r3-041-qffxl
41.0653,Event,ADDED,eval-sanitize-2-r3-041-qffxl.18d3d190fff893ba,"reason=FailedScheduling count=None msg=0/6 nodes are available: 6 node(s) had untolerated taint(s). no new claims to deallocate, preemption: 0/6 nodes are available: 6 Preemption is not helpful for scheduling."
41.0676,Job,MODIFIED,eval-sanitize-2-r3-040,
41.0677,TaskRequest,MODIFIED,eval-sanitize-2-r3-041,phase=Scheduled job=None
41.358,Node,MODIFIED,kind-worker2,taints=1
41.3693,Node,MODIFIED,kind-worker2,taints=1
41.3772,Node,MODIFIED,kind-worker2,taints=0
41.3837,Pod,MODIFIED,eval-sanitize-2-r3-034-f9cq9,phase=Pending node=kind-worker2
41.3893,Event,ADDED,eval-sanitize-2-r3-034-f9cq9.18d3d1911355b782,reason=Scheduled count=None msg=Successfully assigned compute/eval-sanitize-2-r3-034-f9cq9 to kind-worker2
41.3921,Event,ADDED,eval-sanitize-2-r3-035-6gkkd.18d3d19113778243,"reason=FailedScheduling count=None msg=0/6 nodes are available: 1 c_wall violated: 1 conflicting context pair(s) with node memory, 5 node(s) had untolerated taint(s). no new claims to deallocate, preemption: 0/6 nodes are available: 1 No preemption victims found for incoming pod, 5 Preemption is not helpful for scheduling."
41.3932,Pod,MODIFIED,eval-sanitize-2-r3-035-6gkkd,phase=Pending node=None
41.3958,Pod,MODIFIED,eval-sanitize-2-r3-034-f9cq9,phase=Pending node=kind-worker2
41.3972,Node,MODIFIED,kind-worker2,taints=0
41.403,Pod,MODIFIED,eval-sanitize-2-r3-036-k2ckt,phase=Pending node=kind-worker2
41.4041,Pod,MODIFIED,eval-sanitize-2-r3-037-9n9rh,phase=Pending node=kind-worker2
41.4084,Event,ADDED,eval-sanitize-2-r3-036-k2ckt.18d3d19114696ca7,reason=Scheduled count=None msg=Successfully assigned compute/eval-sanitize-2-r3-036-k2ckt to kind-worker2
41.4122,Event,ADDED,eval-sanitize-2-r3-038-bshss.18d3d19114749e62,"reason=FailedScheduling count=None msg=0/6 nodes are available: 1 c_wall violated: 2 conflicting context pair(s) with node memory, 5 node(s) had untolerated taint(s). no new claims to deallocate, preemption: 0/6 nodes are available: 1 No preemption victims found for incoming pod, 5 Preemption is not helpful for scheduling."
41.4125,Event,ADDED,eval-sanitize-2-r3-037-9n9rh.18d3d191147b6906,reason=Scheduled count=None msg=Successfully assigned compute/eval-sanitize-2-r3-037-9n9rh to kind-worker2
41.4139,Pod,MODIFIED,eval-sanitize-2-r3-038-bshss,phase=Pending node=None
41.4169,Pod,MODIFIED,eval-sanitize-2-r3-036-k2ckt,phase=Pending node=kind-worker2
41.4184,Node,MODIFIED,kind-worker2,taints=0
41.4221,Pod,MODIFIED,eval-sanitize-2-r3-039-gr78z,phase=Pending node=None
41.4235,Event,ADDED,eval-sanitize-2-r3-039-gr78z.18d3d19115572210,"reason=FailedScheduling count=None msg=0/6 nodes are available: 1 c_wall violated: 2 conflicting context pair(s) with node memory, 5 node(s) had untolerated taint(s). no new claims to deallocate, preemption: 0/6 nodes are available: 1 No preemption victims found for incoming pod, 5 Preemption is not helpful for scheduling."
41.4248,Pod,MODIFIED,eval-sanitize-2-r3-037-9n9rh,phase=Pending node=kind-worker2
41.4424,Node,MODIFIED,kind-worker2,taints=0
41.4527,Node,MODIFIED,kind-worker2,taints=0
41.4834,Pod,MODIFIED,eval-sanitize-2-r3-040-62m2q,phase=Pending node=None
41.4837,Event,ADDED,eval-sanitize-2-r3-040-62m2q.18d3d19118ecda68,"reason=FailedScheduling count=None msg=0/6 nodes are available: 1 c_wall violated: 1 conflicting context pair(s) with node memory, 5 node(s) had untolerated taint(s). no new claims to deallocate, preemption: 0/6 nodes are available: 1 No preemption victims found for incoming pod, 5 Preemption is not helpful for scheduling."
41.4917,Pod,MODIFIED,eval-sanitize-2-r3-041-qffxl,phase=Pending node=kind-worker2
41.4935,Event,ADDED,eval-sanitize-2-r3-035-6gkkd.18d3d19119a12f07,"reason=FailedScheduling count=None msg=0/6 nodes are available: 1 c_wall violated: 1 conflicting context pair(s) with node memory, 5 node(s) had untolerated taint(s). no new claims to deallocate, preemption: 0/6 nodes are available: 1 No preemption victims found for incoming pod, 5 Preemption is not helpful for scheduling."
41.4968,Event,ADDED,eval-sanitize-2-r3-041-qffxl.18d3d19119c00ce7,reason=Scheduled count=None msg=Successfully assigned compute/eval-sanitize-2-r3-041-qffxl to kind-worker2
41.4976,Event,ADDED,eval-sanitize-2-r3-038-bshss.18d3d19119e49fd4,"reason=FailedScheduling count=None msg=0/6 nodes are available: 1 c_wall violated: 2 conflicting context pair(s) with node memory, 5 node(s) had untolerated taint(s). no new claims to deallocate, preemption: 0/6 nodes are available: 1 No preemption victims found for incoming pod, 5 Preemption is not helpful for scheduling."
41.5016,Node,MODIFIED,kind-worker2,taints=0
41.5035,Pod,MODIFIED,eval-sanitize-2-r3-041-qffxl,phase=Pending node=kind-worker2
41.5081,Event,ADDED,eval-sanitize-2-r3-039-gr78z.18d3d1911a8bebe3,"reason=FailedScheduling count=None msg=0/6 nodes are available: 1 c_wall violated: 2 conflicting context pair(s) with node memory, 5 node(s) had untolerated taint(s). no new claims to deallocate, preemption: 0/6 nodes are available: 1 No preemption victims found for incoming pod, 5 Preemption is not helpful for scheduling."
41.5107,Event,ADDED,eval-sanitize-2-r3-040-62m2q.18d3d1911ab6cc12,"reason=FailedScheduling count=None msg=0/6 nodes are available: 1 c_wall violated: 1 conflicting context pair(s) with node memory, 5 node(s) had untolerated taint(s). no new claims to deallocate, preemption: 0/6 nodes are available: 1 No preemption victims found for incoming pod, 5 Preemption is not helpful for scheduling."
41.5147,Event,MODIFIED,eval-sanitize-2-r3-035-6gkkd.18d3d19119a12f07,"reason=FailedScheduling count=None msg=0/6 nodes are available: 1 c_wall violated: 1 conflicting context pair(s) with node memory, 5 node(s) had untolerated taint(s). no new claims to deallocate, preemption: 0/6 nodes are available: 1 No preemption victims found for incoming pod, 5 Preemption is not helpful for scheduling."
41.5595,Node,MODIFIED,kind-worker2,taints=0
41.5636,Job,MODIFIED,eval-sanitize-2-r3-024,
41.5703,Job,MODIFIED,eval-sanitize-2-r3-023,
41.575,Job,MODIFIED,eval-sanitize-2-r3-024,
41.5812,Event,MODIFIED,eval-sanitize-2-r3-038-bshss.18d3d19119e49fd4,"reason=FailedScheduling count=None msg=0/6 nodes are available: 1 c_wall violated: 2 conflicting context pair(s) with node memory, 5 node(s) had untolerated taint(s). no new claims to deallocate, preemption: 0/6 nodes are available: 1 No preemption victims found for incoming pod, 5 Preemption is not helpful for scheduling."
41.582,Job,MODIFIED,eval-sanitize-2-r3-023,
41.5872,Event,MODIFIED,eval-sanitize-2-r3-039-gr78z.18d3d1911a8bebe3,"reason=FailedScheduling count=None msg=0/6 nodes are available: 1 c_wall violated: 2 conflicting context pair(s) with node memory, 5 node(s) had untolerated taint(s). no new claims to deallocate, preemption: 0/6 nodes are available: 1 No preemption victims found for incoming pod, 5 Preemption is not helpful for scheduling."
41.5904,Event,MODIFIED,eval-sanitize-2-r3-040-62m2q.18d3d1911ab6cc12,"reason=FailedScheduling count=None msg=0/6 nodes are available: 1 c_wall violated: 1 conflicting context pair(s) with node memory, 5 node(s) had untolerated taint(s). no new claims to deallocate, preemption: 0/6 nodes are available: 1 No preemption victims found for incoming pod, 5 Preemption is not helpful for scheduling."
41.7094,Pod,MODIFIED,eval-sanitize-2-r3-023-5wddd,phase=Succeeded node=kind-worker
41.7531,Pod,MODIFIED,eval-sanitize-2-r3-024-hqtgk,phase=Succeeded node=kind-worker
41.7931,Job,MODIFIED,eval-sanitize-2-r3-028,
41.7978,Job,MODIFIED,eval-sanitize-2-r3-028,
41.8056,Event,ADDED,eval-sanitize-2-r3-028.18d3d1912c05c2bf,reason=Completed count=1 msg=Job completed
41.8183,Job,MODIFIED,eval-sanitize-2-r3-028,
41.8195,Event,ADDED,eval-sanitize-2-r3-034-f9cq9.18d3d1912d15bba0,"reason=Pulled count=1 msg=Container image ""busybox:musl"" already present on machine"
41.8232,TaskRequest,MODIFIED,eval-sanitize-2-r3-028,phase=Complete job=None
41.8336,Job,MODIFIED,eval-sanitize-2-r3-028,
41.844,Event,ADDED,eval-sanitize-2-r3-034-f9cq9.18d3d1912e877c94,reason=Created count=1 msg=Created container: task
41.9087,Event,ADDED,eval-sanitize-2-r3-037-9n9rh.18d3d191325f1ee7,"reason=Pulled count=1 msg=Container image ""busybox:musl"" already present on machine"
41.9122,Event,ADDED,eval-sanitize-2-r3-036-k2ckt.18d3d191328539b9,"reason=Pulled count=1 msg=Container image ""busybox:musl"" already present on machine"
41.9334,Event,ADDED,eval-sanitize-2-r3-037-9n9rh.18d3d19133b07167,reason=Created count=1 msg=Created container: task
41.9378,Event,ADDED,eval-sanitize-2-r3-036-k2ckt.18d3d19133fe91f1,reason=Created count=1 msg=Created container: task
41.9663,Event,ADDED,eval-sanitize-2-r3-034-f9cq9.18d3d19135cd6ccb,reason=Started count=1 msg=Started container task
41.9706,Event,ADDED,eval-sanitize-2-r3-037-9n9rh.18d3d19135cd6ccb,reason=Started count=1 msg=Started container task
41.9756,Event,ADDED,eval-sanitize-2-r3-036-k2ckt.18d3d19135f2801c,reason=Started count=1 msg=Started container task
41.9795,Event,ADDED,eval-sanitize-2-r3-041-qffxl.18d3d19136748c11,"reason=Pulled count=1 msg=Container image ""busybox:musl"" already present on machine"
41.9958,Event,ADDED,eval-sanitize-2-r3-041-qffxl.18d3d19137a3055e,reason=Created count=1 msg=Created container: task
42.0057,TaskRequest,ADDED,eval-sanitize-2-r3-042,phase=None job=None
42.012,TaskRequest,MODIFIED,eval-sanitize-2-r3-042,phase=Pending job=None
42.0252,Job,ADDED,eval-sanitize-2-r3-042,
42.0305,TaskRequest,MODIFIED,eval-sanitize-2-r3-042,phase=Scheduled job=None
42.0322,Pod,ADDED,eval-sanitize-2-r3-042-krw95,phase=Pending node=None
42.0337,Job,MODIFIED,eval-sanitize-2-r3-042,
42.0364,Event,ADDED,eval-sanitize-2-r3-042.18d3d19139ff553a,reason=SuccessfulCreate count=1 msg=Created pod: eval-sanitize-2-r3-042-krw95
42.0415,Pod,MODIFIED,eval-sanitize-2-r3-042-krw95,phase=Pending node=kind-worker2
42.0425,TaskRequest,MODIFIED,eval-sanitize-2-r3-042,phase=Scheduled job=None
42.0444,Event,ADDED,eval-sanitize-2-r3-042-krw95.18d3d1913a82b8bd,reason=Scheduled count=None msg=Successfully assigned compute/eval-sanitize-2-r3-042-krw95 to kind-worker2
42.0532,Pod,MODIFIED,eval-sanitize-2-r3-042-krw95,phase=Pending node=kind-worker2
42.064,Job,MODIFIED,eval-sanitize-2-r3-041,
42.0734,Job,MODIFIED,eval-sanitize-2-r3-041,
42.0737,Event,ADDED,eval-sanitize-2-r3-041-qffxl.18d3d1913c39e2b3,reason=Started count=1 msg=Started container task
42.1571,Node,MODIFIED,kind-worker,taints=1
42.1708,Node,MODIFIED,kind-worker,taints=0
42.1805,Node,MODIFIED,kind-worker,taints=0
42.2109,Pod,MODIFIED,eval-sanitize-2-r3-039-gr78z,phase=Pending node=kind-worker
42.2147,Event,ADDED,eval-sanitize-2-r3-039-gr78z.18d3d19144a2c25c,reason=Scheduled count=None msg=Successfully assigned compute/eval-sanitize-2-r3-039-gr78z to kind-worker
42.2182,Pod,MODIFIED,eval-sanitize-2-r3-040-62m2q,phase=Pending node=kind-worker
42.2213,Pod,MODIFIED,eval-sanitize-2-r3-039-gr78z,phase=Pending node=kind-worker
42.2249,Node,MODIFIED,kind-worker,taints=0
42.2268,Event,ADDED,eval-sanitize-2-r3-040-62m2q.18d3d191450aad0b,reason=Scheduled count=None msg=Successfully assigned compute/eval-sanitize-2-r3-040-62m2q to kind-worker
42.2277,Pod,MODIFIED,eval-sanitize-2-r3-035-6gkkd,phase=Pending node=kind-worker
42.2294,Pod,MODIFIED,eval-sanitize-2-r3-040-62m2q,phase=Pending node=kind-worker
42.2321,Event,ADDED,eval-sanitize-2-r3-035-6gkkd.18d3d191459f1e83,reason=Scheduled count=None msg=Successfully assigned compute/eval-sanitize-2-r3-035-6gkkd to kind-worker
42.2381,Node,MODIFIED,kind-worker,taints=0
42.2399,Pod,MODIFIED,eval-sanitize-2-r3-035-6gkkd,phase=Pending node=kind-worker
42.2502,Node,MODIFIED,kind-worker,taints=0
42.2605,Node,MODIFIED,kind-worker,taints=0
42.3118,Pod,MODIFIED,eval-sanitize-2-r3-038-bshss,phase=Pending node=kind-worker
42.315,Event,ADDED,eval-sanitize-2-r3-038-bshss.18d3d1914aa372b8,reason=Scheduled count=None msg=Successfully assigned compute/eval-sanitize-2-r3-038-bshss to kind-worker
42.3208,Pod,MODIFIED,eval-sanitize-2-r3-038-bshss,phase=Pending node=kind-worker
42.4018,Pod,MODIFIED,eval-sanitize-2-r3-022-pbpff,phase=Running node=kind-worker5
42.4077,Pod,MODIFIED,eval-sanitize-2-r3-025-kpnrw,phase=Running node=kind-worker5
42.452,Pod,MODIFIED,eval-sanitize-2-r3-030-vs7t5,phase=Running node=kind-worker4
42.4579,Pod,MODIFIED,eval-sanitize-2-r3-029-nb4jp,phase=Running node=kind-worker4
42.4821,Event,ADDED,eval-sanitize-2-r3-042-krw95.18d3d191546c6250,"reason=Pulled count=1 msg=Container image ""busybox:musl"" already present on machine"
42.4995,Event,ADDED,eval-sanitize-2-r3-042-krw95.18d3d191559de2e4,reason=Created count=1 msg=Created container: task
42.5336,Event,ADDED,eval-sanitize-2-r3-042-krw95.18d3d191579c5dc7,reason=Started count=1 msg=Started container task
42.5701,Job,MODIFIED,eval-sanitize-2-r3-024,
42.5769,Job,MODIFIED,eval-sanitize-2-r3-023,
42.581,Pod,MODIFIED,eval-sanitize-2-r3-024-hqtgk,phase=Succeeded node=kind-worker
42.5825,Job,MODIFIED,eval-sanitize-2-r3-024,
42.5892,Pod,MODIFIED,eval-sanitize-2-r3-023-5wddd,phase=Succeeded node=kind-worker
42.5904,Job,MODIFIED,eval-sanitize-2-r3-023,
42.7502,Event,ADDED,eval-sanitize-2-r3-040-62m2q.18d3d191647455f3,"reason=Pulled count=1 msg=Container image ""busybox:musl"" already present on machine"
42.7541,Event,ADDED,eval-sanitize-2-r3-039-gr78z.18d3d191648d49f6,"reason=Pulled count=1 msg=Container image ""busybox:musl"" already present on machine"
42.7588,Event,ADDED,eval-sanitize-2-r3-035-6gkkd.18d3d19164b6728d,"reason=Pulled count=1 msg=Container image ""busybox:musl"" already present on machine"
42.7665,Pod,MODIFIED,eval-sanitize-2-r3-037-9n9rh,phase=Running node=kind-worker2
42.7668,Event,ADDED,eval-sanitize-2-r3-038-bshss.18d3d19164e300f5,"reason=Pulled count=1 msg=Container image ""busybox:musl"" already present on machine"
42.7737,Pod,MODIFIED,eval-sanitize-2-r3-042-krw95,phase=Running node=kind-worker2
42.781,Pod,MODIFIED,eval-sanitize-2-r3-034-f9cq9,phase=Running node=kind-worker2
42.7888,Pod,MODIFIED,eval-sanitize-2-r3-036-k2ckt,phase=Running node=kind-worker2
42.7891,Event,ADDED,eval-sanitize-2-r3-040-62m2q.18d3d19166bb00c8,reason=Created count=1 msg=Created container: task
42.795,Pod,MODIFIED,eval-sanitize-2-r3-041-qffxl,phase=Running node=kind-worker2
42.8022,Event,ADDED,eval-sanitize-2-r3-035-6gkkd.18d3d19167ab269f,reason=Created count=1 msg=Created container: task
42.8063,Event,ADDED,eval-sanitize-2-r3-039-gr78z.18d3d19167cebf6b,reason=Created count=1 msg=Created container: task
42.811,Event,ADDED,eval-sanitize-2-r3-038-bshss.18d3d19168053797,reason=Created count=1 msg=Created container: task
42.8695,Event,ADDED,eval-sanitize-2-r3-040-62m2q.18d3d1916ba5b4d0,reason=Started count=1 msg=Started container task
42.8728,Event,ADDED,eval-sanitize-2-r3-038-bshss.18d3d1916ba93852,reason=Started count=1 msg=Started container task
42.876,Event,ADDED,eval-sanitize-2-r3-035-6gkkd.18d3d1916ba9464a,reason=Started count=1 msg=Started container task
42.8805,Event,ADDED,eval-sanitize-2-r3-039-gr78z.18d3d1916ba97483,reason=Started count=1 msg=Started container task
43.0229,TaskRequest,ADDED,eval-sanitize-2-r3-043,phase=None job=None
43.0263,TaskRequest,MODIFIED,eval-sanitize-2-r3-043,phase=Pending job=None
43.0379,Job,MODIFIED,eval-sanitize-2-r3-042,
43.0403,Job,ADDED,eval-sanitize-2-r3-043,
43.0463,Pod,ADDED,eval-sanitize-2-r3-043-rnsnf,phase=Pending node=None
43.0464,TaskRequest,MODIFIED,eval-sanitize-2-r3-043,phase=Scheduled job=None
43.0491,Job,MODIFIED,eval-sanitize-2-r3-043,
43.0516,Event,ADDED,eval-sanitize-2-r3-043.18d3d19176717a90,reason=SuccessfulCreate count=1 msg=Created pod: eval-sanitize-2-r3-043-rnsnf
43.0538,TaskRequest,MODIFIED,eval-sanitize-2-r3-043,phase=Scheduled job=None
43.0565,Job,MODIFIED,eval-sanitize-2-r3-042,
43.0588,Pod,MODIFIED,eval-sanitize-2-r3-043-rnsnf,phase=Pending node=None
43.0591,Event,ADDED,eval-sanitize-2-r3-043-rnsnf.18d3d19176e3b7c4,"reason=FailedScheduling count=None msg=0/6 nodes are available: 2 c_wall violated: 1 conflicting context pair(s) with node memory, 4 node(s) had untolerated taint(s). no new claims to deallocate, preemption: 0/6 nodes are available: 2 No preemption victims found for incoming pod, 4 Preemption is not helpful for scheduling."
43.0692,Job,MODIFIED,eval-sanitize-2-r3-041,
43.0695,Event,ADDED,eval-sanitize-2-r3-043-rnsnf.18d3d19177838b10,"reason=FailedScheduling count=None msg=0/6 nodes are available: 2 c_wall violated: 1 conflicting context pair(s) with node memory, 4 node(s) had untolerated taint(s). no new claims to deallocate, preemption: 0/6 nodes are available: 2 No preemption victims found for incoming pod, 4 Preemption is not helpful for scheduling."
43.0797,Job,MODIFIED,eval-sanitize-2-r3-041,
43.4154,Pod,MODIFIED,eval-sanitize-2-r3-031-rd6x9,phase=Running node=kind-worker3
43.4168,Job,MODIFIED,eval-sanitize-2-r3-022,
43.4175,Job,MODIFIED,eval-sanitize-2-r3-025,
43.4301,Job,MODIFIED,eval-sanitize-2-r3-022,
43.4314,Event,MODIFIED,eval-sanitize-2-r3-043-rnsnf.18d3d19177838b10,"reason=FailedScheduling count=None msg=0/6 nodes are available: 2 c_wall violated: 1 conflicting context pair(s) with node memory, 4 node(s) had untolerated taint(s). no new claims to deallocate, preemption: 0/6 nodes are available: 2 No preemption victims found for incoming pod, 4 Preemption is not helpful for scheduling."
43.4322,Job,MODIFIED,eval-sanitize-2-r3-025,
43.4484,Node,MODIFIED,kind-worker2,taints=1
43.4584,Pod,MODIFIED,eval-sanitize-2-r3-043-rnsnf,phase=Pending node=None
43.4617,Job,MODIFIED,eval-sanitize-2-r3-030,
43.463,Pod,MODIFIED,eval-sanitize-2-r3-032-hc2dv,phase=Running node=kind-worker4
43.4648,Job,MODIFIED,eval-sanitize-2-r3-029,
43.4676,Node,MODIFIED,kind-worker2,taints=1
43.4684,Event,ADDED,eval-sanitize-2-r3-043-rnsnf.18d3d1918f35e61e,"reason=FailedScheduling count=None msg=0/6 nodes are available: 1 c_wall violated: 1 conflicting context pair(s) with node memory, 5 node(s) had untolerated taint(s). no new claims to deallocate, preemption: 0/6 nodes are available: 1 No preemption victims found for incoming pod, 5 Preemption is not helpful for scheduling."
43.4745,Job,MODIFIED,eval-sanitize-2-r3-030,
43.476,Event,MODIFIED,eval-sanitize-2-r3-043-rnsnf.18d3d1918f35e61e,"reason=FailedScheduling count=None msg=0/6 nodes are available: 1 c_wall violated: 1 conflicting context pair(s) with node memory, 5 node(s) had untolerated taint(s). no new claims to deallocate, preemption: 0/6 nodes are available: 1 No preemption victims found for incoming pod, 5 Preemption is not helpful for scheduling."
43.4767,Job,MODIFIED,eval-sanitize-2-r3-029,
43.5707,Pod,MODIFIED,eval-sanitize-2-r3-035-6gkkd,phase=Running node=kind-worker
43.5754,Job,MODIFIED,eval-sanitize-2-r3-024,
43.5787,Pod,MODIFIED,eval-sanitize-2-r3-039-gr78z,phase=Running node=kind-worker
43.5802,Pod,MODIFIED,eval-sanitize-2-r3-025-kpnrw,phase=Succeeded node=kind-worker5
43.5812,Job,MODIFIED,eval-sanitize-2-r3-024,
43.5821,Job,MODIFIED,eval-sanitize-2-r3-023,
43.5853,Pod,MODIFIED,eval-sanitize-2-r3-038-bshss,phase=Running node=kind-worker
43.5862,Event,ADDED,eval-sanitize-2-r3-024.18d3d191963da724,reason=Completed count=1 msg=Job completed
43.5873,Job,MODIFIED,eval-sanitize-2-r3-023,
43.592,Event,ADDED,eval-sanitize-2-r3-023.18d3d19196a6a211,reason=Completed count=1 msg=Job completed
43.5937,Pod,MODIFIED,eval-sanitize-2-r3-040-62m2q,phase=Running node=kind-worker
43.5962,Job,MODIFIED,eval-sanitize-2-r3-024,
43.598,Job,MODIFIED,eval-sanitize-2-r3-023,
43.6019,TaskRequest,MODIFIED,eval-sanitize-2-r3-024,phase=Complete job=None
43.6071,TaskRequest,MODIFIED,eval-sanitize-2-r3-023,phase=Complete job=None
43.6158,Job,MODIFIED,eval-sanitize-2-r3-024,
43.6179,Job,MODIFIED,eval-sanitize-2-r3-023,
43.6224,Pod,MODIFIED,eval-sanitize-2-r3-022-pbpff,phase=Succeeded node=kind-worker5
43.6821,Pod,MODIFIED,eval-sanitize-2-r3-030-vs7t5,phase=Succeeded node=kind-worker4
43.7138,Pod,MODIFIED,eval-sanitize-2-r3-029-nb4jp,phase=Succeeded node=kind-worker4
43.7849,Job,MODIFIED,eval-sanitize-2-r3-037,
43.7864,Job,MODIFIED,eval-sanitize-2-r3-034,
43.7928,Job,MODIFIED,eval-sanitize-2-r3-036,
43.7948,Job,MODIFIED,eval-sanitize-2-r3-037,
43.7955,Job,MODIFIED,eval-sanitize-2-r3-034,
43.8001,Job,MODIFIED,eval-sanitize-2-r3-036,
43.8653,Node,MODIFIED,kind-worker5,taints=1
43.8776,Node,MODIFIED,kind-worker5,taints=1
43.8858,Node,MODIFIED,kind-worker5,taints=0
43.8933,Pod,MODIFIED,eval-sanitize-2-r3-043-rnsnf,phase=Pending node=kind-worker5
43.8962,Event,ADDED,eval-sanitize-2-r3-043-rnsnf.18d3d191a8e99ad8,reason=Scheduled count=None msg=Successfully assigned compute/eval-sanitize-2-r3-043-rnsnf to kind-worker5
43.9018,Node,MODIFIED,kind-worker5,taints=0
43.9036,Pod,MODIFIED,eval-sanitize-2-r3-043-rnsnf,phase=Pending node=kind-worker5
43.956,Node,MODIFIED,kind-worker5,taints=0
43.9661,Node,MODIFIED,kind-worker5,taints=0
43.9959,Node,MODIFIED,kind-worker2,taints=1
44.0093,TaskRequest,ADDED,eval-sanitize-2-r3-044,phase=None job=None
44.013,TaskRequest,MODIFIED,eval-sanitize-2-r3-044,phase=Pending job=None
44.0273,Job,ADDED,eval-sanitize-2-r3-044,
44.0324,Pod,ADDED,eval-sanitize-2-r3-044-qjrs6,phase=Pending node=None
44.0334,TaskRequest,MODIFIED,eval-sanitize-2-r3-044,phase=Scheduled job=None
44.0364,Job,MODIFIED,eval-sanitize-2-r3-044,
44.0377,Event,ADDED,eval-sanitize-2-r3-044.18d3d191b1376b35,reason=SuccessfulCreate count=1 msg=Created pod: eval-sanitize-2-r3-044-qjrs6
44.0412,TaskRequest,MODIFIED,eval-sanitize-2-r3-044,phase=Scheduled job=None
44.044,Pod,MODIFIED,eval-sanitize-2-r3-044-qjrs6,phase=Pending node=kind-worker5
44.0474,Event,ADDED,eval-sanitize-2-r3-044-qjrs6.18d3d191b1e7b3d9,reason=Scheduled count=None msg=Successfully assigned compute/eval-sanitize-2-r3-044-qjrs6 to kind-worker5
44.0517,Job,MODIFIED,eval-sanitize-2-r3-043,
44.055,Pod,MODIFIED,eval-sanitize-2-r3-044-qjrs6,phase=Pending node=kind-worker5
44.0565,Node,MODIFIED,kind-worker5,taints=0
44.0609,Job,MODIFIED,eval-sanitize-2-r3-043,
44.0643,Node,MODIFIED,kind-worker5,taints=0
44.1954,Node,MODIFIED,kind-worker,taints=1
44.2102,Node,MODIFIED,kind-worker,taints=1
44.3291,Event,ADDED,eval-sanitize-2-r3-043-rnsnf.18d3d191c2a304c2,"reason=Pulled count=1 msg=Container image ""busybox:musl"" already present on machine"
44.3481,Event,ADDED,eval-sanitize-2-r3-043-rnsnf.18d3d191c3cbc710,reason=Created count=1 msg=Created container: task
44.3819,Event,ADDED,eval-sanitize-2-r3-043-rnsnf.18d3d191c5c76738,reason=Started count=1 msg=Started container task
44.408,Pod,MODIFIED,eval-sanitize-2-r3-043-rnsnf,phase=Running node=kind-worker5
44.4099,Pod,MODIFIED,eval-sanitize-2-r3-033-2l4qz,phase=Running node=kind-worker3
44.4206,Job,MODIFIED,eval-sanitize-2-r3-031,
44.4224,Job,MODIFIED,eval-sanitize-2-r3-022,
44.4233,Job,MODIFIED,eval-sanitize-2-r3-025,
44.4312,Job,MODIFIED,eval-sanitize-2-r3-031,
44.4379,Pod,MODIFIED,eval-sanitize-2-r3-022-pbpff,phase=Succeeded node=kind-worker5
44.4387,Job,MODIFIED,eval-sanitize-2-r3-022,
44.4402,Pod,MODIFIED,eval-sanitize-2-r3-025-kpnrw,phase=Succeeded node=kind-worker5
44.441,Job,MODIFIED,eval-sanitize-2-r3-025,
44.4629,Event,ADDED,eval-sanitize-2-r3-044-qjrs6.18d3d191ca9a75be,"reason=Pulled count=1 msg=Container image ""busybox:musl"" already present on machine"
44.4686,Job,MODIFIED,eval-sanitize-2-r3-030,
44.4712,Job,MODIFIED,eval-sanitize-2-r3-032,
44.4726,Job,MODIFIED,eval-sanitize-2-r3-029,
44.4827,Pod,MODIFIED,eval-sanitize-2-r3-030-vs7t5,phase=Succeeded node=kind-worker4
44.4847,Job,MODIFIED,eval-sanitize-2-r3-030,
44.4878,Pod,MODIFIED,eval-sanitize-2-r3-029-nb4jp,phase=Succeeded node=kind-worker4
44.4882,Event,ADDED,eval-sanitize-2-r3-044-qjrs6.18d3d191cc0e07bc,reason=Created count=1 msg=Created container: task
44.4891,Job,MODIFIED,eval-sanitize-2-r3-032,
44.4901,Job,MODIFIED,eval-sanitize-2-r3-029,
44.555,Event,ADDED,eval-sanitize-2-r3-044-qjrs6.18d3d191d019f6a9,reason=Started count=1 msg=Started container task
44.5627,Pod,MODIFIED,eval-sanitize-2-r3-031-rd6x9,phase=Succeeded node=kind-worker3
44.575,Job,MODIFIED,eval-sanitize-2-r3-035,
44.5824,Job,MODIFIED,eval-sanitize-2-r3-039,
44.584,Job,MODIFIED,eval-sanitize-2-r3-035,
44.5895,Job,MODIFIED,eval-sanitize-2-r3-038,
44.5914,Job,MODIFIED,eval-sanitize-2-r3-039,
44.5972,Job,MODIFIED,eval-sanitize-2-r3-040,
44.5992,Job,MODIFIED,eval-sanitize-2-r3-038,
44.6066,Job,MODIFIED,eval-sanitize-2-r3-040,
44.6985,Pod,MODIFIED,eval-sanitize-2-r3-032-hc2dv,phase=Succeeded node=kind-worker4
45.0068,TaskRequest,ADDED,eval-sanitize-2-r3-045,phase=None job=None
45.0113,TaskRequest,MODIFIED,eval-sanitize-2-r3-045,phase=Pending job=None
45.0243,Job,ADDED,eval-sanitize-2-r3-045,
45.0304,Pod,ADDED,eval-sanitize-2-r3-045-xr64m,phase=Pending node=None
45.0317,TaskRequest,MODIFIED,eval-sanitize-2-r3-045,phase=Scheduled job=None
45.0344,Job,MODIFIED,eval-sanitize-2-r3-045,
45.0363,Event,ADDED,eval-sanitize-2-r3-045.18d3d191ecb748e5,reason=SuccessfulCreate count=1 msg=Created pod: eval-sanitize-2-r3-045-xr64m
45.0372,Job,MODIFIED,eval-sanitize-2-r3-044,
45.0392,Pod,MODIFIED,eval-sanitize-2-r3-045-xr64m,phase=Pending node=kind-worker5
45.0394,TaskRequest,MODIFIED,eval-sanitize-2-r3-045,phase=Scheduled job=None
45.0458,Event,ADDED,eval-sanitize-2-r3-045-xr64m.18d3d191ed3760fc,reason=Scheduled count=None msg=Successfully assigned compute/eval-sanitize-2-r3-045-xr64m to kind-worker5
45.0485,Job,MODIFIED,eval-sanitize-2-r3-044,
45.0529,Pod,MODIFIED,eval-sanitize-2-r3-045-xr64m,phase=Pending node=kind-worker5
45.0569,Job,MODIFIED,eval-sanitize-2-r3-043,
45.065,Job,MODIFIED,eval-sanitize-2-r3-043,
45.4139,Pod,MODIFIED,eval-sanitize-2-r3-044-qjrs6,phase=Running node=kind-worker5
45.4158,Job,MODIFIED,eval-sanitize-2-r3-033,
45.4377,Job,MODIFIED,eval-sanitize-2-r3-031,
45.4389,Job,MODIFIED,eval-sanitize-2-r3-025,
45.4397,Job,MODIFIED,eval-sanitize-2-r3-022,
45.4408,Job,MODIFIED,eval-sanitize-2-r3-033,
45.444,Job,MODIFIED,eval-sanitize-2-r3-022,
45.4458,Job,MODIFIED,eval-sanitize-2-r3-025,
45.4493,Job,MODIFIED,eval-sanitize-2-r3-031,
45.4497,Event,ADDED,eval-sanitize-2-r3-022.18d3d192055f0da5,reason=Completed count=1 msg=Job completed
45.451,Pod,MODIFIED,eval-sanitize-2-r3-031-rd6x9,phase=Succeeded node=kind-worker3
45.456,Event,ADDED,eval-sanitize-2-r3-025.18d3d192057abe25,reason=Completed count=1 msg=Job completed
45.457,Job,MODIFIED,eval-sanitize-2-r3-022,
45.4606,Job,MODIFIED,eval-sanitize-2-r3-025,
45.4618,TaskRequest,MODIFIED,eval-sanitize-2-r3-022,phase=Complete job=None
45.4683,TaskRequest,MODIFIED,eval-sanitize-2-r3-025,phase=Complete job=None
45.4798,Job,MODIFIED,eval-sanitize-2-r3-030,
45.4814,Job,MODIFIED,eval-sanitize-2-r3-022,
45.4823,Job,MODIFIED,eval-sanitize-2-r3-032,
45.4831,Job,MODIFIED,eval-sanitize-2-r3-029,
45.4861,Job,MODIFIED,eval-sanitize-2-r3-030,
45.4869,Job,MODIFIED,eval-sanitize-2-r3-029,
45.4896,Pod,MODIFIED,eval-sanitize-2-r3-032-hc2dv,phase=Succeeded node=kind-worker4
45.49,Event,ADDED,eval-sanitize-2-r3-030.18d3d19207e15f3f,reason=Completed count=1 msg=Job completed
45.4933,Job,MODIFIED,eval-sanitize-2-r3-032,
45.4938,Event,ADDED,eval-sanitize-2-r3-029.18d3d19207ef3ad1,reason=Completed count=1 msg=Job completed
45.4979,Event,ADDED,eval-sanitize-2-r3-032.18d3d192084b9c66,reason=Completed count=1 msg=Job completed
45.5176,Job,MODIFIED,eval-sanitize-2-r3-025,
45.5207,Job,MODIFIED,eval-sanitize-2-r3-030,
45.5226,Job,MODIFIED,eval-sanitize-2-r3-032,
45.5236,Job,MODIFIED,eval-sanitize-2-r3-029,
45.5251,TaskRequest,MODIFIED,eval-sanitize-2-r3-030,phase=Complete job=None
45.5303,TaskRequest,MODIFIED,eval-sanitize-2-r3-029,phase=Complete job=None
45.5343,TaskRequest,MODIFIED,eval-sanitize-2-r3-032,phase=Complete job=None
45.5368,Job,MODIFIED,eval-sanitize-2-r3-030,
45.5571,Event,ADDED,eval-sanitize-2-r3-045-xr64m.18d3d1920bced1c5,"reason=Pulled count=1 msg=Container image ""busybox:musl"" already present on machine"
45.5746,Event,ADDED,eval-sanitize-2-r3-045-xr64m.18d3d1920ce4d7cc,reason=Created count=1 msg=Created container: task
45.6228,Job,MODIFIED,eval-sanitize-2-r3-029,
45.6246,Job,MODIFIED,eval-sanitize-2-r3-032,
45.6327,Pod,MODIFIED,eval-sanitize-2-r3-033-2l4qz,phase=Succeeded node=kind-worker3
45.6486,Event,ADDED,eval-sanitize-2-r3-045-xr64m.18d3d19211489a79,reason=Started count=1 msg=Started container task
45.8644,Node,MODIFIED,kind-worker4,taints=1
45.953,Node,MODIFIED,kind-worker4,taints=0
45.9626,Node,MODIFIED,kind-worker4,taints=0
45.9648,Node,MODIFIED,kind-worker5,taints=1
45.9759,Node,MODIFIED,kind-worker4,taints=0
46.016,TaskRequest,ADDED,eval-sanitize-2-r3-046,phase=None job=None
46.0196,TaskRequest,MODIFIED,eval-sanitize-2-r3-046,phase=Pending job=None
46.0363,Job,MODIFIED,eval-sanitize-2-r3-045,
46.0389,Job,ADDED,eval-sanitize-2-r3-046,
46.0439,Job,MODIFIED,eval-sanitize-2-r3-044,
46.0471,Pod,ADDED,eval-sanitize-2-r3-046-k7wkf,phase=Pending node=None
46.0473,TaskRequest,MODIFIED,eval-sanitize-2-r3-046,phase=Scheduled job=None
46.0489,Node,MODIFIED,kind-worker5,taints=1
46.0507,Job,MODIFIED,eval-sanitize-2-r3-046,
46.0545,Event,ADDED,eval-sanitize-2-r3-046.18d3d192293cad11,reason=SuccessfulCreate count=1 msg=Created pod: eval-sanitize-2-r3-046-k7wkf
46.0555,Pod,MODIFIED,eval-sanitize-2-r3-046-k7wkf,phase=Pending node=kind-worker4
46.0583,TaskRequest,MODIFIED,eval-sanitize-2-r3-046,phase=Scheduled job=None
46.062,Event,ADDED,eval-sanitize-2-r3-046-k7wkf.18d3d19229bd52ed,reason=Scheduled count=None msg=Successfully assigned compute/eval-sanitize-2-r3-046-k7wkf to kind-worker4
46.0635,Job,MODIFIED,eval-sanitize-2-r3-045,
46.0643,Job,MODIFIED,eval-sanitize-2-r3-044,
46.0681,Node,MODIFIED,kind-worker4,taints=0
46.0699,Pod,MODIFIED,eval-sanitize-2-r3-046-k7wkf,phase=Pending node=kind-worker4
46.1543,Node,MODIFIED,kind-worker4,taints=0
46.4195,Pod,MODIFIED,eval-sanitize-2-r3-045-xr64m,phase=Running node=kind-worker5
46.4218,Job,MODIFIED,eval-sanitize-2-r3-033,
46.431,Pod,MODIFIED,eval-sanitize-2-r3-033-2l4qz,phase=Succeeded node=kind-worker3
46.432,Job,MODIFIED,eval-sanitize-2-r3-033,
46.4427,Job,MODIFIED,eval-sanitize-2-r3-031,
46.4466,Job,MODIFIED,eval-sanitize-2-r3-031,
46.4522,Event,ADDED,eval-sanitize-2-r3-031.18d3d192411c0840,reason=Completed count=1 msg=Job completed
46.4569,Job,MODIFIED,eval-sanitize-2-r3-031,
46.4627,TaskRequest,MODIFIED,eval-sanitize-2-r3-031,phase=Complete job=None
46.4736,Job,MODIFIED,eval-sanitize-2-r3-031,
46.5424,Event,ADDED,eval-sanitize-2-r3-046-k7wkf.18d3d19246990c04,"reason=Pulled count=1 msg=Container image ""busybox:musl"" already present on machine"
46.561,Event,ADDED,eval-sanitize-2-r3-046-k7wkf.18d3d19247ab4bd1,reason=Created count=1 msg=Created container: task
46.6397,Event,ADDED,eval-sanitize-2-r3-046-k7wkf.18d3d1924c6814aa,reason=Started count=1 msg=Started container task
46.7388,Node,MODIFIED,kind-worker3,taints=1
46.7508,Node,MODIFIED,kind-worker3,taints=0
46.7587,Node,MODIFIED,kind-worker3,taints=0
46.8206,Node,MODIFIED,kind-worker3,taints=0
47.0175,TaskRequest,ADDED,eval-sanitize-2-r3-047,phase=None job=None
47.0225,TaskRequest,MODIFIED,eval-sanitize-2-r3-047,phase=Pending job=None
47.0362,Job,ADDED,eval-sanitize-2-r3-047,
47.0407,Job,MODIFIED,eval-sanitize-2-r3-045,
47.0427,Pod,ADDED,eval-sanitize-2-r3-047-t6knr,phase=Pending node=None
47.0427,TaskRequest,MODIFIED,eval-sanitize-2-r3-047,phase=Scheduled job=None
47.0445,Job,MODIFIED,eval-sanitize-2-r3-047,
47.0475,Event,ADDED,eval-sanitize-2-r3-047.18d3d19264a93460,reason=SuccessfulCreate count=1 msg=Created pod: eval-sanitize-2-r3-047-t6knr
47.0484,TaskRequest,MODIFIED,eval-sanitize-2-r3-047,phase=Scheduled job=None
47.0511,Job,MODIFIED,eval-sanitize-2-r3-046,
47.0539,Job,MODIFIED,eval-sanitize-2-r3-045,
47.0618,Job,MODIFIED,eval-sanitize-2-r3-046,
47.0629,Pod,MODIFIED,eval-sanitize-2-r3-047-t6knr,phase=Pending node=kind-worker4
47.0672,Event,ADDED,eval-sanitize-2-r3-047-t6knr.18d3d19265d1e95c,reason=Scheduled count=None msg=Successfully assigned compute/eval-sanitize-2-r3-047-t6knr to kind-worker4
47.074,Node,MODIFIED,kind-worker4,taints=0
47.0757,Pod,MODIFIED,eval-sanitize-2-r3-047-t6knr,phase=Pending node=kind-worker4
47.084,Node,MODIFIED,kind-worker4,taints=0
47.4324,Job,MODIFIED,eval-sanitize-2-r3-033,
47.4366,Job,MODIFIED,eval-sanitize-2-r3-033,
47.4406,Event,ADDED,eval-sanitize-2-r3-033.18d3d1927c1fa212,reason=Completed count=1 msg=Job completed
47.4464,Job,MODIFIED,eval-sanitize-2-r3-033,
47.4504,TaskRequest,MODIFIED,eval-sanitize-2-r3-033,phase=Complete job=None
47.4588,Job,MODIFIED,eval-sanitize-2-r3-033,
47.4758,Pod,MODIFIED,eval-sanitize-2-r3-046-k7wkf,phase=Running node=kind-worker4
47.4975,Event,ADDED,eval-sanitize-2-r3-047-t6knr.18d3d1927f84ef40,"reason=Pulled count=1 msg=Container image ""busybox:musl"" already present on machine"
47.5158,Event,ADDED,eval-sanitize-2-r3-047-t6knr.18d3d19280999eb5,reason=Created count=1 msg=Created container: task
47.579,Event,ADDED,eval-sanitize-2-r3-047-t6knr.18d3d1928463c262,reason=Started count=1 msg=Started container task
47.9748,Node,MODIFIED,kind-worker4,taints=1
47.9864,Node,MODIFIED,kind-worker4,taints=1
48.0112,TaskRequest,ADDED,eval-sanitize-2-r3-048,phase=None job=None
48.0146,TaskRequest,MODIFIED,eval-sanitize-2-r3-048,phase=Pending job=None
48.0301,Job,ADDED,eval-sanitize-2-r3-048,
48.0366,Pod,ADDED,eval-sanitize-2-r3-048-m65n8,phase=Pending node=None
48.0368,TaskRequest,MODIFIED,eval-sanitize-2-r3-048,phase=Scheduled job=None
48.0392,Job,MODIFIED,eval-sanitize-2-r3-048,
48.0431,Event,ADDED,eval-sanitize-2-r3-048.18d3d1929fe72d69,reason=SuccessfulCreate count=1 msg=Created pod: eval-sanitize-2-r3-048-m65n8
48.044,Pod,MODIFIED,eval-sanitize-2-r3-048-m65n8,phase=Pending node=kind-worker3
48.0442,TaskRequest,MODIFIED,eval-sanitize-2-r3-048,phase=Scheduled job=None
48.0488,Job,MODIFIED,eval-sanitize-2-r3-047,
48.049,Event,ADDED,eval-sanitize-2-r3-048-m65n8.18d3d192a04f2a74,reason=Scheduled count=None msg=Successfully assigned compute/eval-sanitize-2-r3-048-m65n8 to kind-worker3
48.0531,Node,MODIFIED,kind-worker3,taints=0
48.055,Pod,MODIFIED,eval-sanitize-2-r3-048-m65n8,phase=Pending node=kind-worker3
48.0564,Job,MODIFIED,eval-sanitize-2-r3-046,
48.0583,Job,MODIFIED,eval-sanitize-2-r3-047,
48.0626,Node,MODIFIED,kind-worker3,taints=0
48.065,Job,MODIFIED,eval-sanitize-2-r3-046,
48.4693,Event,ADDED,eval-sanitize-2-r3-048-m65n8.18d3d192b95c1fc2,"reason=Pulled count=1 msg=Container image ""busybox:musl"" already present on machine"
48.4781,Pod,MODIFIED,eval-sanitize-2-r3-047-t6knr,phase=Running node=kind-worker4
48.4896,Event,ADDED,eval-sanitize-2-r3-048-m65n8.18d3d192ba9f7d8e,reason=Created count=1 msg=Created container: task
48.555,Event,ADDED,eval-sanitize-2-r3-048-m65n8.18d3d192be7c160e,reason=Started count=1 msg=Started container task
48.9441,Node,MODIFIED,kind-worker3,taints=1
48.9561,Node,MODIFIED,kind-worker3,taints=1
49.009,TaskRequest,ADDED,eval-sanitize-2-r3-049,phase=None job=None
49.015,TaskRequest,MODIFIED,eval-sanitize-2-r3-049,phase=Pending job=None
49.0298,Job,ADDED,eval-sanitize-2-r3-049,
49.0357,Pod,ADDED,eval-sanitize-2-r3-049-tdnps,phase=Pending node=None
49.037,TaskRequest,MODIFIED,eval-sanitize-2-r3-049,phase=Scheduled job=None
49.0398,Job,MODIFIED,eval-sanitize-2-r3-049,
49.0413,Event,ADDED,eval-sanitize-2-r3-049.18d3d192db6b21c5,reason=SuccessfulCreate count=1 msg=Created pod: eval-sanitize-2-r3-049-tdnps
49.0423,Job,MODIFIED,eval-sanitize-2-r3-048,
49.0427,Event,ADDED,eval-sanitize-2-r3-049-tdnps.18d3d192db7976b5,"reason=FailedScheduling count=None msg=0/6 nodes are available: 6 node(s) had untolerated taint(s). no new claims to deallocate, preemption: 0/6 nodes are available: 6 Preemption is not helpful for scheduling."
49.0437,Pod,MODIFIED,eval-sanitize-2-r3-049-tdnps,phase=Pending node=None
49.0438,TaskRequest,MODIFIED,eval-sanitize-2-r3-049,phase=Scheduled job=None
49.0504,Job,MODIFIED,eval-sanitize-2-r3-048,
49.053,Job,MODIFIED,eval-sanitize-2-r3-047,
49.061,Job,MODIFIED,eval-sanitize-2-r3-047,
49.427,Pod,MODIFIED,eval-sanitize-2-r3-048-m65n8,phase=Running node=kind-worker3
50.0109,TaskRequest,ADDED,eval-sanitize-2-r3-050,phase=None job=None
50.0148,TaskRequest,MODIFIED,eval-sanitize-2-r3-050,phase=Pending job=None
50.0304,Job,ADDED,eval-sanitize-2-r3-050,
50.0354,TaskRequest,MODIFIED,eval-sanitize-2-r3-050,phase=Scheduled job=None
50.0377,Pod,ADDED,eval-sanitize-2-r3-050-mkhrs,phase=Pending node=None
50.0406,Job,MODIFIED,eval-sanitize-2-r3-050,
50.0429,Job,MODIFIED,eval-sanitize-2-r3-049,
50.044,Pod,MODIFIED,eval-sanitize-2-r3-050-mkhrs,phase=Pending node=None
50.0444,Event,ADDED,eval-sanitize-2-r3-050.18d3d193172c4a2e,reason=SuccessfulCreate count=1 msg=Created pod: eval-sanitize-2-r3-050-mkhrs
50.0446,Event,ADDED,eval-sanitize-2-r3-050-mkhrs.18d3d1931737fe37,"reason=FailedScheduling count=None msg=0/6 nodes are available: 6 node(s) had untolerated taint(s). no new claims to deallocate, preemption: 0/6 nodes are available: 6 Preemption is not helpful for scheduling."
50.0447,TaskRequest,MODIFIED,eval-sanitize-2-r3-050,phase=Scheduled job=None
50.0475,Job,MODIFIED,eval-sanitize-2-r3-048,
50.0516,Job,MODIFIED,eval-sanitize-2-r3-049,
50.0554,Job,MODIFIED,eval-sanitize-2-r3-048,
51.0093,TaskRequest,ADDED,eval-sanitize-2-r3-051,phase=None job=None
51.0127,TaskRequest,MODIFIED,eval-sanitize-2-r3-051,phase=Pending job=None
51.0288,Job,ADDED,eval-sanitize-2-r3-051,
51.0344,Pod,ADDED,eval-sanitize-2-r3-051-zfn8s,phase=Pending node=None
51.0349,TaskRequest,MODIFIED,eval-sanitize-2-r3-051,phase=Scheduled job=None
51.0377,Job,MODIFIED,eval-sanitize-2-r3-051,
51.0499,Event,ADDED,eval-sanitize-2-r3-051.18d3d193528cbaf8,reason=SuccessfulCreate count=1 msg=Created pod: eval-sanitize-2-r3-051-zfn8s
51.0502,Event,ADDED,eval-sanitize-2-r3-051-zfn8s.18d3d19352957fac,"reason=FailedScheduling count=None msg=0/6 nodes are available: 6 node(s) had untolerated taint(s). no new claims to deallocate, preemption: 0/6 nodes are available: 6 Preemption is not helpful for scheduling."
51.0511,Pod,MODIFIED,eval-sanitize-2-r3-051-zfn8s,phase=Pending node=None
51.0512,TaskRequest,MODIFIED,eval-sanitize-2-r3-051,phase=Scheduled job=None
51.0518,Job,MODIFIED,eval-sanitize-2-r3-050,
51.0603,Job,MODIFIED,eval-sanitize-2-r3-050,
52.0076,TaskRequest,ADDED,eval-sanitize-2-r3-052,phase=None job=None
52.0113,TaskRequest,MODIFIED,eval-sanitize-2-r3-052,phase=Pending job=None
52.029,Job,ADDED,eval-sanitize-2-r3-052,
52.0337,TaskRequest,MODIFIED,eval-sanitize-2-r3-052,phase=Scheduled job=None
52.0367,Pod,ADDED,eval-sanitize-2-r3-052-qtqlf,phase=Pending node=None
52.0389,Job,MODIFIED,eval-sanitize-2-r3-052,
52.041,Job,MODIFIED,eval-sanitize-2-r3-051,
52.0433,Event,ADDED,eval-sanitize-2-r3-052.18d3d1938e5524d5,reason=SuccessfulCreate count=1 msg=Created pod: eval-sanitize-2-r3-052-qtqlf
52.0437,Event,ADDED,eval-sanitize-2-r3-052-qtqlf.18d3d1938e5d87b9,"reason=FailedScheduling count=None msg=0/6 nodes are available: 6 node(s) had untolerated taint(s). no new claims to deallocate, preemption: 0/6 nodes are available: 6 Preemption is not helpful for scheduling."
52.0446,Pod,MODIFIED,eval-sanitize-2-r3-052-qtqlf,phase=Pending node=None
52.0447,TaskRequest,MODIFIED,eval-sanitize-2-r3-052,phase=Scheduled job=None
52.0511,Job,MODIFIED,eval-sanitize-2-r3-051,
52.7915,Pod,MODIFIED,eval-sanitize-2-r3-037-9n9rh,phase=Running node=kind-worker2
52.7972,Pod,MODIFIED,eval-sanitize-2-r3-042-krw95,phase=Running node=kind-worker2
52.8042,Pod,MODIFIED,eval-sanitize-2-r3-034-f9cq9,phase=Running node=kind-worker2
52.8096,Pod,MODIFIED,eval-sanitize-2-r3-036-k2ckt,phase=Running node=kind-worker2
52.816,Pod,MODIFIED,eval-sanitize-2-r3-041-qffxl,phase=Running node=kind-worker2
53.0139,TaskRequest,ADDED,eval-sanitize-2-r3-053,phase=None job=None
53.0177,TaskRequest,MODIFIED,eval-sanitize-2-r3-053,phase=Pending job=None
53.0338,Job,ADDED,eval-sanitize-2-r3-053,
53.0391,TaskRequest,MODIFIED,eval-sanitize-2-r3-053,phase=Scheduled job=None
53.0421,Pod,ADDED,eval-sanitize-2-r3-053-bgzwf,phase=Pending node=None
53.0429,Job,MODIFIED,eval-sanitize-2-r3-052,
53.0442,Job,MODIFIED,eval-sanitize-2-r3-053,
53.0489,Event,ADDED,eval-sanitize-2-r3-053.18d3d193ca483690,reason=SuccessfulCreate count=1 msg=Created pod: eval-sanitize-2-r3-053-bgzwf
53.0492,Event,ADDED,eval-sanitize-2-r3-053-bgzwf.18d3d193ca4c03dc,"reason=FailedScheduling count=None msg=0/6 nodes are available: 6 node(s) had untolerated taint(s). no new claims to deallocate, preemption: 0/6 nodes are available: 6 Preemption is not helpful for scheduling."
53.0493,TaskRequest,MODIFIED,eval-sanitize-2-r3-053,phase=Scheduled job=None
53.0502,Pod,MODIFIED,eval-sanitize-2-r3-053-bgzwf,phase=Pending node=None
53.0513,Job,MODIFIED,eval-sanitize-2-r3-052,
53.5914,Pod,MODIFIED,eval-sanitize-2-r3-035-6gkkd,phase=Running node=kind-worker
53.5972,Pod,MODIFIED,eval-sanitize-2-r3-039-gr78z,phase=Running node=kind-worker
53.6053,Pod,MODIFIED,eval-sanitize-2-r3-038-bshss,phase=Running node=kind-worker
53.6116,Pod,MODIFIED,eval-sanitize-2-r3-040-62m2q,phase=Running node=kind-worker
53.8016,Job,MODIFIED,eval-sanitize-2-r3-037,
53.8052,Job,MODIFIED,eval-sanitize-2-r3-042,
53.8093,Job,MODIFIED,eval-sanitize-2-r3-034,
53.8126,Job,MODIFIED,eval-sanitize-2-r3-037,
53.8142,Job,MODIFIED,eval-sanitize-2-r3-036,
53.815,Job,MODIFIED,eval-sanitize-2-r3-042,
53.8184,Job,MODIFIED,eval-sanitize-2-r3-034,
53.8207,Job,MODIFIED,eval-sanitize-2-r3-041,
53.8236,Job,MODIFIED,eval-sanitize-2-r3-036,
53.8293,Job,MODIFIED,eval-sanitize-2-r3-041,
54.0089,TaskRequest,ADDED,eval-sanitize-2-r3-054,phase=None job=None
54.0157,TaskRequest,MODIFIED,eval-sanitize-2-r3-054,phase=Pending job=None
54.0259,Pod,MODIFIED,eval-sanitize-2-r3-036-k2ckt,phase=Succeeded node=kind-worker2
54.0321,Pod,MODIFIED,eval-sanitize-2-r3-034-f9cq9,phase=Succeeded node=kind-worker2
54.0329,Job,ADDED,eval-sanitize-2-r3-054,
54.0388,Pod,MODIFIED,eval-sanitize-2-r3-041-qffxl,phase=Succeeded node=kind-worker2
54.0395,TaskRequest,MODIFIED,eval-sanitize-2-r3-054,phase=Scheduled job=None
54.0403,Pod,ADDED,eval-sanitize-2-r3-054-r6q26,phase=Pending node=None
54.0419,Job,MODIFIED,eval-sanitize-2-r3-054,
54.0476,Event,ADDED,eval-sanitize-2-r3-054-r6q26.18d3d19405cc347c,"reason=FailedScheduling count=None msg=0/6 nodes are available: 6 node(s) had untolerated taint(s). no new claims to deallocate, preemption: 0/6 nodes are available: 6 Preemption is not helpful for scheduling."
54.0479,Event,ADDED,eval-sanitize-2-r3-054.18d3d19405c84b91,reason=SuccessfulCreate count=1 msg=Created pod: eval-sanitize-2-r3-054-r6q26
54.0489,Job,MODIFIED,eval-sanitize-2-r3-053,
54.0502,Pod,MODIFIED,eval-sanitize-2-r3-042-krw95,phase=Succeeded node=kind-worker2
54.0504,TaskRequest,MODIFIED,eval-sanitize-2-r3-054,phase=Scheduled job=None
54.0512,Pod,MODIFIED,eval-sanitize-2-r3-054-r6q26,phase=Pending node=None
54.0568,Job,MODIFIED,eval-sanitize-2-r3-053,
54.0591,Pod,MODIFIED,eval-sanitize-2-r3-037-9n9rh,phase=Succeeded node=kind-worker2
54.2542,Node,MODIFIED,kind-worker2,taints=1
54.3424,Node,MODIFIED,kind-worker2,taints=1
54.3503,Node,MODIFIED,kind-worker2,taints=0
54.3565,Pod,MODIFIED,eval-sanitize-2-r3-049-tdnps,phase=Pending node=kind-worker2
54.3599,Event,ADDED,eval-sanitize-2-r3-049-tdnps.18d3d194189930bd,reason=Scheduled count=None msg=Successfully assigned compute/eval-sanitize-2-r3-049-tdnps to kind-worker2
54.3649,Pod,MODIFIED,eval-sanitize-2-r3-050-mkhrs,phase=Pending node=None
54.3664,Event,ADDED,eval-sanitize-2-r3-050-mkhrs.18d3d19418d04a77,"reason=FailedScheduling count=None msg=0/6 nodes are available: 1 c_wall violated: 1 conflicting context pair(s) with node memory, 5 node(s) had untolerated taint(s). no new claims to deallocate, preemption: 0/6 nodes are available: 1 No preemption victims found for incoming pod, 5 Preemption is not helpful for scheduling."
54.3675,Pod,MODIFIED,eval-sanitize-2-r3-049-tdnps,phase=Pending node=kind-worker2
54.369,Node,MODIFIED,kind-worker2,taints=0
54.3732,Pod,MODIFIED,eval-sanitize-2-r3-051-zfn8s,phase=Pending node=kind-worker2
54.3761,Pod,MODIFIED,eval-sanitize-2-r3-052-qtqlf,phase=Pending node=kind-worker2
54.3806,Pod,MODIFIED,eval-sanitize-2-r3-053-bgzwf,phase=Pending node=kind-worker2
54.3838,Event,ADDED,eval-sanitize-2-r3-051-zfn8s.18d3d194199a5c13,reason=Scheduled count=None msg=Successfully assigned compute/eval-sanitize-2-r3-051-zfn8s to kind-worker2
54.3842,Event,ADDED,eval-sanitize-2-r3-052-qtqlf.18d3d19419c15452,reason=Scheduled count=None msg=Successfully assigned compute/eval-sanitize-2-r3-052-qtqlf to kind-worker2
54.3845,Event,ADDED,eval-sanitize-2-r3-054-r6q26.18d3d19419c4aca4,"reason=FailedScheduling count=None msg=0/6 nodes are available: 1 c_wall violated: 1 conflicting context pair(s) with node memory, 5 node(s) had untolerated taint(s). no new claims to deallocate, preemption: 0/6 nodes are available: 1 No preemption victims found for incoming pod, 5 Preemption is not helpful for scheduling."
54.3855,Pod,MODIFIED,eval-sanitize-2-r3-054-r6q26,phase=Pending node=None
54.3894,Node,MODIFIED,kind-worker2,taints=0
54.39,Event,ADDED,eval-sanitize-2-r3-053-bgzwf.18d3d1941a0b2b0b,reason=Scheduled count=None msg=Successfully assigned compute/eval-sanitize-2-r3-053-bgzwf to kind-worker2
54.3917,Pod,MODIFIED,eval-sanitize-2-r3-051-zfn8s,phase=Pending node=kind-worker2
54.3947,Pod,MODIFIED,eval-sanitize-2-r3-050-mkhrs,phase=Pending node=None
54.3959,Event,ADDED,eval-sanitize-2-r3-050-mkhrs.18d3d1941a8fa0f5,"reason=FailedScheduling count=None msg=0/6 nodes are available: 1 c_wall violated: 2 conflicting context pair(s) with node memory, 5 node(s) had untolerated taint(s). no new claims to deallocate, preemption: 0/6 nodes are available: 1 No preemption victims found for incoming pod, 5 Preemption is not helpful for scheduling."
54.3974,Pod,MODIFIED,eval-sanitize-2-r3-052-qtqlf,phase=Pending node=kind-worker2
54.4059,Pod,MODIFIED,eval-sanitize-2-r3-053-bgzwf,phase=Pending node=kind-worker2
54.4113,Event,ADDED,eval-sanitize-2-r3-054-r6q26.18d3d1941b908847,"reason=FailedScheduling count=None msg=0/6 nodes are available: 1 c_wall violated: 1 conflicting context pair(s) with node memory, 5 node(s) had untolerated taint(s). no new claims to deallocate, preemption: 0/6 nodes are available: 1 No preemption victims found for incoming pod, 5 Preemption is not helpful for scheduling."
54.415,Node,MODIFIED,kind-worker2,taints=0
54.4156,Event,ADDED,eval-sanitize-2-r3-050-mkhrs.18d3d1941bc04f92,"reason=FailedScheduling count=None msg=0/6 nodes are available: 1 c_wall violated: 2 conflicting context pair(s) with node memory, 5 node(s) had untolerated taint(s). no new claims to deallocate, preemption: 0/6 nodes are available: 1 No preemption victims found for incoming pod, 5 Preemption is not helpful for scheduling."
54.4166,Event,MODIFIED,eval-sanitize-2-r3-054-r6q26.18d3d1941b908847,"reason=FailedScheduling count=None msg=0/6 nodes are available: 1 c_wall violated: 1 conflicting context pair(s) with node memory, 5 node(s) had untolerated taint(s). no new claims to deallocate, preemption: 0/6 nodes are available: 1 No preemption victims found for incoming pod, 5 Preemption is not helpful for scheduling."
54.4324,Pod,MODIFIED,eval-sanitize-2-r3-043-rnsnf,phase=Running node=kind-worker5
54.4615,Node,MODIFIED,kind-worker2,taints=0
54.4798,Event,MODIFIED,eval-sanitize-2-r3-050-mkhrs.18d3d1941bc04f92,"reason=FailedScheduling count=None msg=0/6 nodes are available: 1 c_wall violated: 2 conflicting context pair(s) with node memory, 5 node(s) had untolerated taint(s). no new claims to deallocate, preemption: 0/6 nodes are available: 1 No preemption victims found for incoming pod, 5 Preemption is not helpful for scheduling."
54.5558,Node,MODIFIED,kind-worker2,taints=0
54.5975,Job,MODIFIED,eval-sanitize-2-r3-035,
54.6025,Job,MODIFIED,eval-sanitize-2-r3-039,
54.607,Job,MODIFIED,eval-sanitize-2-r3-035,
54.6095,Job,MODIFIED,eval-sanitize-2-r3-038,
54.6113,Job,MODIFIED,eval-sanitize-2-r3-039,
54.6151,Job,MODIFIED,eval-sanitize-2-r3-040,
54.6174,Job,MODIFIED,eval-sanitize-2-r3-038,
54.6237,Job,MODIFIED,eval-sanitize-2-r3-040,
54.809,Job,MODIFIED,eval-sanitize-2-r3-037,
54.8121,Job,MODIFIED,eval-sanitize-2-r3-042,
54.8186,Job,MODIFIED,eval-sanitize-2-r3-034,
54.8225,Job,MODIFIED,eval-sanitize-2-r3-037,
54.8255,Pod,MODIFIED,eval-sanitize-2-r3-037-9n9rh,phase=Succeeded node=kind-worker2
54.8266,Job,MODIFIED,eval-sanitize-2-r3-036,
54.8287,Pod,MODIFIED,eval-sanitize-2-r3-042-krw95,phase=Succeeded node=kind-worker2
54.8299,Job,MODIFIED,eval-sanitize-2-r3-042,
54.8314,Pod,MODIFIED,eval-sanitize-2-r3-034-f9cq9,phase=Succeeded node=kind-worker2
54.8368,Job,MODIFIED,eval-sanitize-2-r3-041,
54.8377,Job,MODIFIED,eval-sanitize-2-r3-034,
54.8391,Pod,MODIFIED,eval-sanitize-2-r3-036-k2ckt,phase=Succeeded node=kind-worker2
54.8402,Job,MODIFIED,eval-sanitize-2-r3-036,
54.8438,Pod,MODIFIED,eval-sanitize-2-r3-041-qffxl,phase=Succeeded node=kind-worker2
54.8459,Job,MODIFIED,eval-sanitize-2-r3-041,
54.8889,Event,ADDED,eval-sanitize-2-r3-051-zfn8s.18d3d19438158d92,"reason=Pulled count=1 msg=Container image ""busybox:musl"" already present on machine"
54.9097,Event,ADDED,eval-sanitize-2-r3-051-zfn8s.18d3d194392eba10,reason=Created count=1 msg=Created container: task
54.9211,Event,ADDED,eval-sanitize-2-r3-049-tdnps.18d3d19439c34955,"reason=Pulled count=1 msg=Container image ""busybox:musl"" already present on machine"
54.9287,Event,ADDED,eval-sanitize-2-r3-053-bgzwf.18d3d1943a771a28,"reason=Pulled count=1 msg=Container image ""busybox:musl"" already present on machine"
54.9328,Event,ADDED,eval-sanitize-2-r3-052-qtqlf.18d3d1943a8f7841,"reason=Pulled count=1 msg=Container image ""busybox:musl"" already present on machine"
54.9552,Event,ADDED,eval-sanitize-2-r3-049-tdnps.18d3d1943bd2f1f2,reason=Created count=1 msg=Created container: task
54.9672,Event,ADDED,eval-sanitize-2-r3-053-bgzwf.18d3d1943cb1122b,reason=Created count=1 msg=Created container: task
54.973,Pod,MODIFIED,eval-sanitize-2-r3-039-gr78z,phase=Succeeded node=kind-worker
54.9735,Event,ADDED,eval-sanitize-2-r3-052-qtqlf.18d3d1943d039e3b,reason=Created count=1 msg=Created container: task
54.9835,Pod,MODIFIED,eval-sanitize-2-r3-038-bshss,phase=Succeeded node=kind-worker
54.9845,Event,ADDED,eval-sanitize-2-r3-051-zfn8s.18d3d1943dc27f58,reason=Started count=1 msg=Started container task
55.0004,Event,ADDED,eval-sanitize-2-r3-049-tdnps.18d3d1943eba2ac6,reason=Started count=1 msg=Started container task
55.0077,TaskRequest,ADDED,eval-sanitize-2-r3-055,phase=None job=None
55.0126,TaskRequest,MODIFIED,eval-sanitize-2-r3-055,phase=Pending job=None
55.0157,Event,ADDED,eval-sanitize-2-r3-053-bgzwf.18d3d1943f82315d,reason=Started count=1 msg=Started container task
55.0171,Pod,MODIFIED,eval-sanitize-2-r3-035-6gkkd,phase=Succeeded node=kind-worker
55.0193,Event,ADDED,eval-sanitize-2-r3-052-qtqlf.18d3d1943f824ac1,reason=Started count=1 msg=Started container task
55.0297,Job,ADDED,eval-sanitize-2-r3-055,
55.0363,Pod,ADDED,eval-sanitize-2-r3-055-pgs46,phase=Pending node=None
55.0402,TaskRequest,MODIFIED,eval-sanitize-2-r3-055,phase=Scheduled job=None
55.0412,Job,MODIFIED,eval-sanitize-2-r3-055,
55.0427,Pod,MODIFIED,eval-sanitize-2-r3-040-62m2q,phase=Succeeded node=kind-worker
55.0431,Event,ADDED,eval-sanitize-2-r3-055.18d3d19441213da1,reason=SuccessfulCreate count=1 msg=Created pod: eval-sanitize-2-r3-055-pgs46
55.0449,Job,MODIFIED,eval-sanitize-2-r3-054,
55.0477,TaskRequest,MODIFIED,eval-sanitize-2-r3-055,phase=Scheduled job=None
55.0526,Job,MODIFIED,eval-sanitize-2-r3-054,
55.0759,Pod,MODIFIED,eval-sanitize-2-r3-055-pgs46,phase=Pending node=None
55.0762,Event,ADDED,eval-sanitize-2-r3-055-pgs46.18d3d194432d4b38,"reason=FailedScheduling count=None msg=0/6 nodes are available: 1 c_wall violated: 2 conflicting context pair(s) with node memory, 5 node(s) had untolerated taint(s). no new claims to deallocate, preemption: 0/6 nodes are available: 1 No preemption victims found for incoming pod, 5 Preemption is not helpful for scheduling."
55.0881,Event,ADDED,eval-sanitize-2-r3-055-pgs46.18d3d19443ff84b7,"reason=FailedScheduling count=None msg=0/6 nodes are available: 1 c_wall violated: 2 conflicting context pair(s) with node memory, 5 node(s) had untolerated taint(s). no new claims to deallocate, preemption: 0/6 nodes are available: 1 No preemption victims found for incoming pod, 5 Preemption is not helpful for scheduling."
55.3283,Node,MODIFIED,kind-worker,taints=1
55.3411,Node,MODIFIED,kind-worker,taints=0
55.3434,Event,MODIFIED,eval-sanitize-2-r3-055-pgs46.18d3d19443ff84b7,"reason=FailedScheduling count=None msg=0/6 nodes are available: 1 c_wall violated: 2 conflicting context pair(s) with node memory, 5 node(s) had untolerated taint(s). no new claims to deallocate, preemption: 0/6 nodes are available: 1 No preemption victims found for incoming pod, 5 Preemption is not helpful for scheduling."
55.3492,Pod,MODIFIED,eval-sanitize-2-r3-054-r6q26,phase=Pending node=kind-worker
55.3519,Node,MODIFIED,kind-worker,taints=0
55.3533,Event,ADDED,eval-sanitize-2-r3-054-r6q26.18d3d19453c78375,reason=Scheduled count=None msg=Successfully assigned compute/eval-sanitize-2-r3-054-r6q26 to kind-worker
55.3563,Pod,MODIFIED,eval-sanitize-2-r3-050-mkhrs,phase=Pending node=None
55.3611,Pod,MODIFIED,eval-sanitize-2-r3-054-r6q26,phase=Pending node=kind-worker
55.3772,Node,MODIFIED,kind-worker,taints=0
55.4131,Pod,MODIFIED,eval-sanitize-2-r3-055-pgs46,phase=Pending node=kind-worker
55.4172,Pod,MODIFIED,eval-sanitize-2-r3-050-mkhrs,phase=Pending node=None
55.4175,Event,ADDED,eval-sanitize-2-r3-050-mkhrs.18d3d194577f23e9,"reason=FailedScheduling count=None msg=0/6 nodes are available: 2 c_wall violated: 2 conflicting context pair(s) with node memory, 4 node(s) had untolerated taint(s). no new claims to deallocate, preemption: 0/6 nodes are available: 2 No preemption victims found for incoming pod, 4 Preemption is not helpful for scheduling."
55.4179,Event,ADDED,eval-sanitize-2-r3-055-pgs46.18d3d19457928857,reason=Scheduled count=None msg=Successfully assigned compute/eval-sanitize-2-r3-055-pgs46 to kind-worker
55.4226,Node,MODIFIED,kind-worker,taints=0
55.427,Pod,MODIFIED,eval-sanitize-2-r3-055-pgs46,phase=Pending node=kind-worker
55.4366,Node,MODIFIED,kind-worker,taints=0
55.439,Pod,MODIFIED,eval-sanitize-2-r3-044-qjrs6,phase=Running node=kind-worker5
55.4397,Job,MODIFIED,eval-sanitize-2-r3-043,
55.4475,Job,MODIFIED,eval-sanitize-2-r3-043,
55.483,Event,ADDED,eval-sanitize-2-r3-050-mkhrs.18d3d1945b67e40d,"reason=FailedScheduling count=None msg=0/6 nodes are available: 2 c_wall violated: 2 conflicting context pair(s) with node memory, 4 node(s) had untolerated taint(s). no new claims to deallocate, preemption: 0/6 nodes are available: 2 No preemption victims found for incoming pod, 4 Preemption is not helpful for scheduling."
55.4996,Node,MODIFIED,kind-worker,taints=0
55.5133,Pod,MODIFIED,eval-sanitize-2-r3-043-rnsnf,phase=Succeeded node=kind-worker5
55.5137,Event,MODIFIED,eval-sanitize-2-r3-050-mkhrs.18d3d1945b67e40d,"reason=FailedScheduling count=None msg=0/6 nodes are available: 2 c_wall violated: 2 conflicting context pair(s) with node memory, 4 node(s) had untolerated taint(s). no new claims to deallocate, preemption: 0/6 nodes are available: 2 No preemption victims found for incoming pod, 4 Preemption is not helpful for scheduling."
55.6039,Job,MODIFIED,eval-sanitize-2-r3-035,
55.6068,Job,MODIFIED,eval-sanitize-2-r3-039,
55.613,Pod,MODIFIED,eval-sanitize-2-r3-035-6gkkd,phase=Succeeded node=kind-worker
55.6153,Pod,MODIFIED,eval-sanitize-2-r3-039-gr78z,phase=Succeeded node=kind-worker
55.6161,Job,MODIFIED,eval-sanitize-2-r3-035,
55.6174,Job,MODIFIED,eval-sanitize-2-r3-038,
55.6185,Job,MODIFIED,eval-sanitize-2-r3-039,
55.6201,Node,MODIFIED,kind-worker,taints=0
55.6229,Job,MODIFIED,eval-sanitize-2-r3-040,
55.6241,Pod,MODIFIED,eval-sanitize-2-r3-038-bshss,phase=Succeeded node=kind-worker
55.6258,Job,MODIFIED,eval-sanitize-2-r3-038,
55.6325,Pod,MODIFIED,eval-sanitize-2-r3-040-62m2q,phase=Succeeded node=kind-worker
55.6335,Job,MODIFIED,eval-sanitize-2-r3-040,
55.7715,Event,ADDED,eval-sanitize-2-r3-054-r6q26.18d3d1946ca80a24,"reason=Pulled count=1 msg=Container image ""busybox:musl"" already present on machine"
55.7894,Event,ADDED,eval-sanitize-2-r3-054-r6q26.18d3d1946dc52562,reason=Created count=1 msg=Created container: task
55.8138,Pod,MODIFIED,eval-sanitize-2-r3-049-tdnps,phase=Running node=kind-worker2
55.816,Job,MODIFIED,eval-sanitize-2-r3-037,
55.8206,Job,MODIFIED,eval-sanitize-2-r3-042,
55.8242,Job,MODIFIED,eval-sanitize-2-r3-037,
55.8259,Pod,MODIFIED,eval-sanitize-2-r3-052-qtqlf,phase=Running node=kind-worker2
55.827,Job,MODIFIED,eval-sanitize-2-r3-034,
55.828,Job,MODIFIED,eval-sanitize-2-r3-042,
55.8322,Event,ADDED,eval-sanitize-2-r3-054-r6q26.18d3d1947002e343,reason=Started count=1 msg=Started container task
55.8331,Job,MODIFIED,eval-sanitize-2-r3-036,
55.8346,Event,ADDED,eval-sanitize-2-r3-037.18d3d194701e870d,reason=Completed count=1 msg=Job completed
55.8365,Job,MODIFIED,eval-sanitize-2-r3-034,
55.8391,Pod,MODIFIED,eval-sanitize-2-r3-053-bgzwf,phase=Running node=kind-worker2
55.8524,Job,MODIFIED,eval-sanitize-2-r3-036,
55.8542,Event,ADDED,eval-sanitize-2-r3-042.18d3d194703b9560,reason=Completed count=1 msg=Job completed
55.8565,Job,MODIFIED,eval-sanitize-2-r3-037,
55.8576,Job,MODIFIED,eval-sanitize-2-r3-042,
55.8584,Job,MODIFIED,eval-sanitize-2-r3-041,
55.8598,Pod,MODIFIED,eval-sanitize-2-r3-051-zfn8s,phase=Running node=kind-worker2
55.8609,Job,MODIFIED,eval-sanitize-2-r3-034,
55.8615,Event,ADDED,eval-sanitize-2-r3-055-pgs46.18d3d19471c8750b,"reason=Pulled count=1 msg=Container image ""busybox:musl"" already present on machine"
55.8624,Job,MODIFIED,eval-sanitize-2-r3-041,
55.8643,Event,ADDED,eval-sanitize-2-r3-034.18d3d19470bdb46d,reason=Completed count=1 msg=Job completed
55.8651,Job,MODIFIED,eval-sanitize-2-r3-036,
55.8671,TaskRequest,MODIFIED,eval-sanitize-2-r3-037,phase=Complete job=None
55.8682,Event,ADDED,eval-sanitize-2-r3-036.18d3d19471c1712e,reason=Completed count=1 msg=Job completed
55.8722,TaskRequest,MODIFIED,eval-sanitize-2-r3-042,phase=Complete job=None
55.8733,Event,ADDED,eval-sanitize-2-r3-041.18d3d194725f9c0a,reason=Completed count=1 msg=Job completed
55.8756,TaskRequest,MODIFIED,eval-sanitize-2-r3-034,phase=Complete job=None
55.88,Event,ADDED,eval-sanitize-2-r3-055-pgs46.18d3d194733f2f10,reason=Created count=1 msg=Created container: task
55.9141,TaskRequest,MODIFIED,eval-sanitize-2-r3-036,phase=Complete job=None
55.9174,Job,MODIFIED,eval-sanitize-2-r3-037,
55.9196,Job,MODIFIED,eval-sanitize-2-r3-042,
55.9205,Job,MODIFIED,eval-sanitize-2-r3-041,
55.9214,Job,MODIFIED,eval-sanitize-2-r3-034,
55.9229,Job,MODIFIED,eval-sanitize-2-r3-036,
55.9259,TaskRequest,MODIFIED,eval-sanitize-2-r3-041,phase=Complete job=None
55.9355,Job,MODIFIED,eval-sanitize-2-r3-041,
55.9435,Event,ADDED,eval-sanitize-2-r3-055-pgs46.18d3d19476f2dda1,reason=Started count=1 msg=Started container task
56.0079,TaskRequest,ADDED,eval-sanitize-2-r3-056,phase=None job=None
56.0114,TaskRequest,MODIFIED,eval-sanitize-2-r3-056,phase=Pending job=None
56.0274,Job,ADDED,eval-sanitize-2-r3-056,
56.0339,Pod,ADDED,eval-sanitize-2-r3-056-jjtbf,phase=Pending node=None
56.034,TaskRequest,MODIFIED,eval-sanitize-2-r3-056,phase=Scheduled job=None
56.0366,Job,MODIFIED,eval-sanitize-2-r3-056,
56.0406,Event,ADDED,eval-sanitize-2-r3-056.18d3d1947c95cfdd,reason=SuccessfulCreate count=1 msg=Created pod: eval-sanitize-2-r3-056-jjtbf
56.0415,Job,MODIFIED,eval-sanitize-2-r3-055,
56.0417,TaskRequest,MODIFIED,eval-sanitize-2-r3-056,phase=Scheduled job=None
56.0457,Pod,MODIFIED,eval-sanitize-2-r3-056-jjtbf,phase=Pending node=None
56.046,Event,ADDED,eval-sanitize-2-r3-056-jjtbf.18d3d1947d003ff5,"reason=FailedScheduling count=None msg=0/6 nodes are available: 1 c_wall violated: 1 conflicting context pair(s) with node memory, 1 c_wall violated: 2 conflicting context pair(s) with node memory, 4 node(s) had untolerated taint(s). no new claims to deallocate, preemption: 0/6 nodes are available: 2 No preemption victims found for incoming pod, 4 Preemption is not helpful for scheduling."
56.0514,Job,MODIFIED,eval-sanitize-2-r3-055,
56.0557,Event,ADDED,eval-sanitize-2-r3-056-jjtbf.18d3d1947db01771,"reason=FailedScheduling count=None msg=0/6 nodes are available: 1 c_wall violated: 1 conflicting context pair(s) with node memory, 1 c_wall violated: 2 conflicting context pair(s) with node memory, 4 node(s) had untolerated taint(s). no new claims to deallocate, preemption: 0/6 nodes are available: 2 No preemption victims found for incoming pod, 4 Preemption is not helpful for scheduling."
56.4473,Pod,MODIFIED,eval-sanitize-2-r3-045-xr64m,phase=Running node=kind-worker5
56.4483,Job,MODIFIED,eval-sanitize-2-r3-043,
56.449,Job,MODIFIED,eval-sanitize-2-r3-044,
56.4595,Pod,MODIFIED,eval-sanitize-2-r3-043-rnsnf,phase=Succeeded node=kind-worker5
56.4627,Job,MODIFIED,eval-sanitize-2-r3-043,
56.4635,Job,MODIFIED,eval-sanitize-2-r3-044,
56.4722,Node,MODIFIED,kind-worker2,taints=1
56.4728,Event,MODIFIED,eval-sanitize-2-r3-056-jjtbf.18d3d1947db01771,"reason=FailedScheduling count=None msg=0/6 nodes are available: 1 c_wall violated: 1 conflicting context pair(s) with node memory, 1 c_wall violated: 2 conflicting context pair(s) with node memory, 4 node(s) had untolerated taint(s). no new claims to deallocate, preemption: 0/6 nodes are available: 2 No preemption victims found for incoming pod, 4 Preemption is not helpful for scheduling."
56.4804,Pod,MODIFIED,eval-sanitize-2-r3-050-mkhrs,phase=Pending node=None
56.5101,Pod,MODIFIED,eval-sanitize-2-r3-056-jjtbf,phase=Pending node=None
56.5175,Event,ADDED,eval-sanitize-2-r3-050-mkhrs.18d3d194992e0e02,"reason=FailedScheduling count=None msg=0/6 nodes are available: 1 c_wall violated: 2 conflicting context pair(s) with node memory, 5 node(s) had untolerated taint(s). no new claims to deallocate, preemption: 0/6 nodes are available: 1 No preemption victims found for incoming pod, 5 Preemption is not helpful for scheduling."
56.5196,Event,ADDED,eval-sanitize-2-r3-056-jjtbf.18d3d19499574585,"reason=FailedScheduling count=None msg=0/6 nodes are available: 1 c_wall violated: 1 conflicting context pair(s) with node memory, 5 node(s) had untolerated taint(s). no new claims to deallocate, preemption: 0/6 nodes are available: 1 No preemption victims found for incoming pod, 5 Preemption is not helpful for scheduling."
56.5946,Pod,MODIFIED,eval-sanitize-2-r3-044-qjrs6,phase=Succeeded node=kind-worker5
56.6058,Pod,MODIFIED,eval-sanitize-2-r3-055-pgs46,phase=Running node=kind-worker
56.6061,Event,MODIFIED,eval-sanitize-2-r3-050-mkhrs.18d3d194992e0e02,"reason=FailedScheduling count=None msg=0/6 nodes are available: 1 c_wall violated: 2 conflicting context pair(s) with node memory, 5 node(s) had untolerated taint(s). no new claims to deallocate, preemption: 0/6 nodes are available: 1 No preemption victims found for incoming pod, 5 Preemption is not helpful for scheduling."
56.6099,Job,MODIFIED,eval-sanitize-2-r3-035,
56.611,Event,MODIFIED,eval-sanitize-2-r3-056-jjtbf.18d3d19499574585,"reason=FailedScheduling count=None msg=0/6 nodes are available: 1 c_wall violated: 1 conflicting context pair(s) with node memory, 5 node(s) had untolerated taint(s). no new claims to deallocate, preemption: 0/6 nodes are available: 1 No preemption victims found for incoming pod, 5 Preemption is not helpful for scheduling."
56.6144,Job,MODIFIED,eval-sanitize-2-r3-039,
56.6156,Pod,MODIFIED,eval-sanitize-2-r3-054-r6q26,phase=Running node=kind-worker
56.6165,Job,MODIFIED,eval-sanitize-2-r3-035,
56.6187,Job,MODIFIED,eval-sanitize-2-r3-039,
56.6204,Event,ADDED,eval-sanitize-2-r3-035.18d3d1949f29eaf4,reason=Completed count=1 msg=Job completed
56.6215,Job,MODIFIED,eval-sanitize-2-r3-038,
56.6253,Job,MODIFIED,eval-sanitize-2-r3-038,
56.6266,Event,ADDED,eval-sanitize-2-r3-039.18d3d1949f7751d3,reason=Completed count=1 msg=Job completed
56.6276,Job,MODIFIED,eval-sanitize-2-r3-035,
56.6294,Job,MODIFIED,eval-sanitize-2-r3-040,
56.6303,Job,MODIFIED,eval-sanitize-2-r3-039,
56.633,Event,ADDED,eval-sanitize-2-r3-038.18d3d1949fd5fa28,reason=Completed count=1 msg=Job completed
56.6332,TaskRequest,MODIFIED,eval-sanitize-2-r3-035,phase=Complete job=None
56.634,Job,MODIFIED,eval-sanitize-2-r3-040,
56.6387,Job,MODIFIED,eval-sanitize-2-r3-038,
56.6389,TaskRequest,MODIFIED,eval-sanitize-2-r3-039,phase=Complete job=None
56.6434,Job,MODIFIED,eval-sanitize-2-r3-035,
56.6475,Node,MODIFIED,kind-worker2,taints=1
56.6552,Event,ADDED,eval-sanitize-2-r3-040.18d3d194a059f8b0,reason=Completed count=1 msg=Job completed
56.7404,TaskRequest,MODIFIED,eval-sanitize-2-r3-038,phase=Complete job=None
56.7431,Job,MODIFIED,eval-sanitize-2-r3-039,
56.745,Job,MODIFIED,eval-sanitize-2-r3-040,
56.7491,Job,MODIFIED,eval-sanitize-2-r3-038,
56.7498,TaskRequest,MODIFIED,eval-sanitize-2-r3-040,phase=Complete job=None
56.7589,Job,MODIFIED,eval-sanitize-2-r3-040,
56.8187,Job,MODIFIED,eval-sanitize-2-r3-049,
56.8275,Job,MODIFIED,eval-sanitize-2-r3-049,
56.8294,Job,MODIFIED,eval-sanitize-2-r3-052,
56.8383,Job,MODIFIED,eval-sanitize-2-r3-052,
56.8404,Job,MODIFIED,eval-sanitize-2-r3-053,
56.8483,Job,MODIFIED,eval-sanitize-2-r3-053,
56.8622,Job,MODIFIED,eval-sanitize-2-r3-051,
56.8705,Job,MODIFIED,eval-sanitize-2-r3-051,
57.0075,TaskRequest,ADDED,eval-sanitize-2-r3-057,phase=None job=None
57.0125,TaskRequest,MODIFIED,eval-sanitize-2-r3-057,phase=Pending job=None
57.0258,Job,ADDED,eval-sanitize-2-r3-057,
57.0327,Pod,ADDED,eval-sanitize-2-r3-057-rhvv7,phase=Pending node=None
57.0328,TaskRequest,MODIFIED,eval-sanitize-2-r3-057,phase=Scheduled job=None
57.0352,Job,MODIFIED,eval-sanitize-2-r3-057,
57.0376,Event,ADDED,eval-sanitize-2-r3-057.18d3d194b81e82c6,reason=SuccessfulCreate count=1 msg=Created pod: eval-sanitize-2-r3-057-rhvv7
57.0408,Pod,MODIFIED,eval-sanitize-2-r3-057-rhvv7,phase=Pending node=None
57.0411,Event,ADDED,eval-sanitize-2-r3-057-rhvv7.18d3d194b85909a0,"reason=FailedScheduling count=None msg=0/6 nodes are available: 1 c_wall violated: 1 conflicting context pair(s) with node memory, 5 node(s) had untolerated taint(s). no new claims to deallocate, preemption: 0/6 nodes are available: 1 No preemption victims found for incoming pod, 5 Preemption is not helpful for scheduling."
57.0412,TaskRequest,MODIFIED,eval-sanitize-2-r3-057,phase=Scheduled job=None
57.0483,Event,ADDED,eval-sanitize-2-r3-057-rhvv7.18d3d194b8d1a4cb,"reason=FailedScheduling count=None msg=0/6 nodes are available: 1 c_wall violated: 1 conflicting context pair(s) with node memory, 5 node(s) had untolerated taint(s). no new claims to deallocate, preemption: 0/6 nodes are available: 1 No preemption victims found for incoming pod, 5 Preemption is not helpful for scheduling."
57.0554,Job,MODIFIED,eval-sanitize-2-r3-056,
57.0643,Job,MODIFIED,eval-sanitize-2-r3-056,
57.1056,Job,MODIFIED,eval-sanitize-2-r3-055,
57.1145,Job,MODIFIED,eval-sanitize-2-r3-055,
57.4304,Node,MODIFIED,kind-worker,taints=1
57.4361,Pod,MODIFIED,eval-sanitize-2-r3-050-mkhrs,phase=Pending node=None
57.4421,Pod,MODIFIED,eval-sanitize-2-r3-056-jjtbf,phase=Pending node=None
57.4447,Node,MODIFIED,kind-worker,taints=1
57.4481,Pod,MODIFIED,eval-sanitize-2-r3-057-rhvv7,phase=Pending node=None
57.4485,Event,MODIFIED,eval-sanitize-2-r3-057-rhvv7.18d3d194b8d1a4cb,"reason=FailedScheduling count=None msg=0/6 nodes are available: 1 c_wall violated: 1 conflicting context pair(s) with node memory, 5 node(s) had untolerated taint(s). no new claims to deallocate, preemption: 0/6 nodes are available: 1 No preemption victims found for incoming pod, 5 Preemption is not helpful for scheduling."
57.4508,Job,MODIFIED,eval-sanitize-2-r3-045,
57.4538,Job,MODIFIED,eval-sanitize-2-r3-044,
57.4552,Job,MODIFIED,eval-sanitize-2-r3-043,
57.4599,Job,MODIFIED,eval-sanitize-2-r3-043,
57.463,Pod,MODIFIED,eval-sanitize-2-r3-044-qjrs6,phase=Succeeded node=kind-worker5
57.464,Job,MODIFIED,eval-sanitize-2-r3-045,
57.468,Job,MODIFIED,eval-sanitize-2-r3-044,
57.4702,Event,ADDED,eval-sanitize-2-r3-043.18d3d194d19519b2,reason=Completed count=1 msg=Job completed
57.4809,Job,MODIFIED,eval-sanitize-2-r3-043,
57.4858,TaskRequest,MODIFIED,eval-sanitize-2-r3-043,phase=Complete job=None
57.4943,Pod,MODIFIED,eval-sanitize-2-r3-046-k7wkf,phase=Running node=kind-worker4
57.4956,Job,MODIFIED,eval-sanitize-2-r3-043,
57.541,Pod,MODIFIED,eval-sanitize-2-r3-045-xr64m,phase=Succeeded node=kind-worker5
57.6199,Job,MODIFIED,eval-sanitize-2-r3-054,
57.6281,Job,MODIFIED,eval-sanitize-2-r3-054,
58.0066,TaskRequest,ADDED,eval-sanitize-2-r3-058,phase=None job=None
58.0126,TaskRequest,MODIFIED,eval-sanitize-2-r3-058,phase=Pending job=None
58.0273,Job,ADDED,eval-sanitize-2-r3-058,
58.0329,TaskRequest,MODIFIED,eval-sanitize-2-r3-058,phase=Scheduled job=None
58.0347,Pod,ADDED,eval-sanitize-2-r3-058-sqvr7,phase=Pending node=None
58.0369,Job,MODIFIED,eval-sanitize-2-r3-058,
58.0395,Job,MODIFIED,eval-sanitize-2-r3-057,
58.0414,Event,ADDED,eval-sanitize-2-r3-058.18d3d194f3d7e0c4,reason=SuccessfulCreate count=1 msg=Created pod: eval-sanitize-2-r3-058-sqvr7
58.0417,Event,ADDED,eval-sanitize-2-r3-058-sqvr7.18d3d194f3e48e8b,"reason=FailedScheduling count=None msg=0/6 nodes are available: 6 node(s) had untolerated taint(s). no new claims to deallocate, preemption: 0/6 nodes are available: 6 Preemption is not helpful for scheduling."
58.0426,Pod,MODIFIED,eval-sanitize-2-r3-058-sqvr7,phase=Pending node=None
58.0429,TaskRequest,MODIFIED,eval-sanitize-2-r3-058,phase=Scheduled job=None
58.048,Job,MODIFIED,eval-sanitize-2-r3-057,
58.4571,Job,MODIFIED,eval-sanitize-2-r3-045,
58.4594,Job,MODIFIED,eval-sanitize-2-r3-044,
58.4648,Job,MODIFIED,eval-sanitize-2-r3-044,
58.4697,Pod,MODIFIED,eval-sanitize-2-r3-045-xr64m,phase=Succeeded node=kind-worker5
58.4704,Job,MODIFIED,eval-sanitize-2-r3-045,
58.4721,Event,ADDED,eval-sanitize-2-r3-044.18d3d1950d7af70a,reason=Completed count=1 msg=Job completed
58.4785,Job,MODIFIED,eval-sanitize-2-r3-044,
58.4844,TaskRequest,MODIFIED,eval-sanitize-2-r3-044,phase=Complete job=None
58.4955,Job,MODIFIED,eval-sanitize-2-r3-044,
58.4985,Pod,MODIFIED,eval-sanitize-2-r3-047-t6knr,phase=Running node=kind-worker4
58.4999,Job,MODIFIED,eval-sanitize-2-r3-046,
58.5095,Job,MODIFIED,eval-sanitize-2-r3-046,
58.6801,Pod,MODIFIED,eval-sanitize-2-r3-046-k7wkf,phase=Succeeded node=kind-worker4
59.0078,TaskRequest,ADDED,eval-sanitize-2-r3-059,phase=None job=None
59.0118,TaskRequest,MODIFIED,eval-sanitize-2-r3-059,phase=Pending job=None
59.0262,Job,ADDED,eval-sanitize-2-r3-059,
59.0303,TaskRequest,MODIFIED,eval-sanitize-2-r3-059,phase=Scheduled job=None
59.0343,Pod,ADDED,eval-sanitize-2-r3-059-dw2kg,phase=Pending node=None
59.0365,Job,MODIFIED,eval-sanitize-2-r3-059,
59.0387,Job,MODIFIED,eval-sanitize-2-r3-058,
59.0408,Event,ADDED,eval-sanitize-2-r3-059.18d3d1952f741d8f,reason=SuccessfulCreate count=1 msg=Created pod: eval-sanitize-2-r3-059-dw2kg
59.0411,Event,ADDED,eval-sanitize-2-r3-059-dw2kg.18d3d1952f7d4e47,"reason=FailedScheduling count=None msg=0/6 nodes are available: 6 node(s) had untolerated taint(s). no new claims to deallocate, preemption: 0/6 nodes are available: 6 Preemption is not helpful for scheduling."
59.0413,TaskRequest,MODIFIED,eval-sanitize-2-r3-059,phase=Scheduled job=None
59.0421,Pod,MODIFIED,eval-sanitize-2-r3-059-dw2kg,phase=Pending node=None
59.0471,Job,MODIFIED,eval-sanitize-2-r3-058,
59.2441,Node,MODIFIED,kind-worker5,taints=1
59.2567,Node,MODIFIED,kind-worker5,taints=0
59.2629,Pod,MODIFIED,eval-sanitize-2-r3-050-mkhrs,phase=Pending node=kind-worker5
59.2659,Node,MODIFIED,kind-worker5,taints=0
59.2695,Pod,MODIFIED,eval-sanitize-2-r3-056-jjtbf,phase=Pending node=kind-worker5
59.2703,Event,ADDED,eval-sanitize-2-r3-050-mkhrs.18d3d1953d07427c,reason=Scheduled count=None msg=Successfully assigned compute/eval-sanitize-2-r3-050-mkhrs to kind-worker5
59.2707,Event,ADDED,eval-sanitize-2-r3-057-rhvv7.18d3d1953d26f060,"reason=FailedScheduling count=None msg=0/6 nodes are available: 1 c_wall violated: 1 conflicting context pair(s) with node memory, 5 node(s) had untolerated taint(s). no new claims to deallocate, preemption: 0/6 nodes are available: 1 No preemption victims found for incoming pod, 5 Preemption is not helpful for scheduling."
59.2719,Pod,MODIFIED,eval-sanitize-2-r3-057-rhvv7,phase=Pending node=None
59.276,Pod,MODIFIED,eval-sanitize-2-r3-050-mkhrs,phase=Pending node=kind-worker5
59.2763,Event,ADDED,eval-sanitize-2-r3-056-jjtbf.18d3d1953d67bfad,reason=Scheduled count=None msg=Successfully assigned compute/eval-sanitize-2-r3-056-jjtbf to kind-worker5
59.2792,Node,MODIFIED,kind-worker5,taints=0
59.2805,Pod,MODIFIED,eval-sanitize-2-r3-058-sqvr7,phase=Pending node=None
59.2813,Event,ADDED,eval-sanitize-2-r3-058-sqvr7.18d3d1953dcaa3bc,"reason=FailedScheduling count=None msg=0/6 nodes are available: 1 c_wall violated: 2 conflicting context pair(s) with node memory, 5 node(s) had untolerated taint(s). no new claims to deallocate, preemption: 0/6 nodes are available: 1 No preemption victims found for incoming pod, 5 Preemption is not helpful for scheduling."
59.2851,Pod,MODIFIED,eval-sanitize-2-r3-056-jjtbf,phase=Pending node=kind-worker5
59.2888,Pod,MODIFIED,eval-sanitize-2-r3-059-dw2kg,phase=Pending node=kind-worker5
59.2934,Node,MODIFIED,kind-worker5,taints=0
59.2937,Event,ADDED,eval-sanitize-2-r3-057-rhvv7.18d3d1953e7e57af,"reason=FailedScheduling count=None msg=0/6 nodes are available: 1 c_wall violated: 1 conflicting context pair(s) with node memory, 5 node(s) had untolerated taint(s). no new claims to deallocate, preemption: 0/6 nodes are available: 1 No preemption victims found for incoming pod, 5 Preemption is not helpful for scheduling."
59.294,Event,ADDED,eval-sanitize-2-r3-059-dw2kg.18d3d1953e957cdb,reason=Scheduled count=None msg=Successfully assigned compute/eval-sanitize-2-r3-059-dw2kg to kind-worker5
59.2985,Pod,MODIFIED,eval-sanitize-2-r3-059-dw2kg,phase=Pending node=kind-worker5
59.3025,Node,MODIFIED,kind-worker5,taints=0
59.3071,Event,ADDED,eval-sanitize-2-r3-058-sqvr7.18d3d1953f81428b,"reason=FailedScheduling count=None msg=0/6 nodes are available: 1 c_wall violated: 2 conflicting context pair(s) with node memory, 5 node(s) had untolerated taint(s). no new claims to deallocate, preemption: 0/6 nodes are available: 1 No preemption victims found for incoming pod, 5 Preemption is not helpful for scheduling."
59.3109,Event,MODIFIED,eval-sanitize-2-r3-057-rhvv7.18d3d1953e7e57af,"reason=FailedScheduling count=None msg=0/6 nodes are available: 1 c_wall violated: 1 conflicting context pair(s) with node memory, 5 node(s) had untolerated taint(s). no new claims to deallocate, preemption: 0/6 nodes are available: 1 No preemption victims found for incoming pod, 5 Preemption is not helpful for scheduling."
59.3147,Event,MODIFIED,eval-sanitize-2-r3-058-sqvr7.18d3d1953f81428b,"reason=FailedScheduling count=None msg=0/6 nodes are available: 1 c_wall violated: 2 conflicting context pair(s) with node memory, 5 node(s) had untolerated taint(s). no new claims to deallocate, preemption: 0/6 nodes are available: 1 No preemption victims found for incoming pod, 5 Preemption is not helpful for scheduling."
59.3404,Node,MODIFIED,kind-worker5,taints=0
59.3533,Node,MODIFIED,kind-worker5,taints=0
59.4414,Pod,MODIFIED,eval-sanitize-2-r3-048-m65n8,phase=Running node=kind-worker3
59.4683,Job,MODIFIED,eval-sanitize-2-r3-045,
59.474,Job,MODIFIED,eval-sanitize-2-r3-045,
59.4782,Event,ADDED,eval-sanitize-2-r3-045.18d3d195499dd849,reason=Completed count=1 msg=Job completed
59.486,Job,MODIFIED,eval-sanitize-2-r3-045,
59.4917,TaskRequest,MODIFIED,eval-sanitize-2-r3-045,phase=Complete job=None
59.5017,Job,MODIFIED,eval-sanitize-2-r3-045,
59.5033,Job,MODIFIED,eval-sanitize-2-r3-047,
59.5051,Job,MODIFIED,eval-sanitize-2-r3-046,
59.5133,Job,MODIFIED,eval-sanitize-2-r3-047,
59.5177,Job,MODIFIED,eval-sanitize-2-r3-046,
59.5192,Pod,MODIFIED,eval-sanitize-2-r3-046-k7wkf,phase=Succeeded node=kind-worker4
59.6777,Pod,MODIFIED,eval-sanitize-2-r3-047-t6knr,phase=Succeeded node=kind-worker4
59.6992,Event,ADDED,eval-sanitize-2-r3-050-mkhrs.18d3d19556c12f45,"reason=Pulled count=1 msg=Container image ""busybox:musl"" already present on machine"
59.7035,Event,ADDED,eval-sanitize-2-r3-056-jjtbf.18d3d195570cbdea,"reason=Pulled count=1 msg=Container image ""busybox:musl"" already present on machine"
59.7132,Event,ADDED,eval-sanitize-2-r3-059-dw2kg.18d3d19557a5053a,"reason=Pulled count=1 msg=Container image ""busybox:musl"" already present on machine"
59.726,Event,ADDED,eval-sanitize-2-r3-050-mkhrs.18d3d195585d9315,reason=Created count=1 msg=Created container: task
59.7335,Event,ADDED,eval-sanitize-2-r3-056-jjtbf.18d3d19558d9937a,reason=Created count=1 msg=Created container: task
59.7429,Event,ADDED,eval-sanitize-2-r3-059-dw2kg.18d3d1955970e67b,reason=Created count=1 msg=Created container: task
59.8035,Event,ADDED,eval-sanitize-2-r3-050-mkhrs.18d3d1955cfcfb97,reason=Started count=1 msg=Started container task
59.8076,Event,ADDED,eval-sanitize-2-r3-056-jjtbf.18d3d1955d576e8c,reason=Started count=1 msg=Started container task
59.8122,Event,ADDED,eval-sanitize-2-r3-059-dw2kg.18d3d1955d58b5fc,reason=Started count=1 msg=Started container task
60.0079,TaskRequest,ADDED,eval-sanitize-2-r3-060,phase=None job=None
60.0114,TaskRequest,MODIFIED,eval-sanitize-2-r3-060,phase=Pending job=None
60.0166,Job,ADDED,eval-sanitize-2-r3-000,
60.0169,TaskRequest,ADDED,eval-sanitize-2-r3-000,phase=Complete job=None
60.0183,Job,ADDED,eval-sanitize-2-r3-001,
60.0184,TaskRequest,ADDED,eval-sanitize-2-r3-001,phase=Complete job=None
60.0185,TaskRequest,ADDED,eval-sanitize-2-r3-002,phase=Complete job=None
60.0189,Event,ADDED,eval-sanitize-2-r1-019-mhl65.18d3d0fc3c377bce,"reason=FailedScheduling count=None msg=0/6 nodes are available: 2 c_wall violated: 1 conflicting context pair(s) with node memory, 4 node(s) had untolerated taint(s). no new claims to deallocate, preemption: 0/6 nodes are available: 2 No preemption victims found for incoming pod, 4 Preemption is not helpful for scheduling."
60.0198,Job,ADDED,eval-sanitize-2-r3-002,
60.0199,TaskRequest,ADDED,eval-sanitize-2-r3-003,phase=Complete job=None
60.0199,TaskRequest,ADDED,eval-sanitize-2-r3-004,phase=Complete job=None
60.02,TaskRequest,ADDED,eval-sanitize-2-r3-005,phase=Complete job=None
60.0211,Pod,ADDED,eval-sanitize-2-r3-000-d2spv,phase=Succeeded node=kind-worker2
60.0227,Node,ADDED,kind-control-plane,taints=1
60.023,Event,ADDED,eval-sanitize-2-r1-019-mhl65.18d3d0fc41f2b0d0,"reason=FailedScheduling count=None msg=0/6 nodes are available: 1 c_wall violated: 1 conflicting context pair(s) with node memory, 5 node(s) had untolerated taint(s). no new claims to deallocate, preemption: 0/6 nodes are available: 1 No preemption victims found for incoming pod, 5 Preemption is not helpful for scheduling."
60.0232,Event,ADDED,eval-sanitize-2-r1-021-5zgd4.18d3d0fe181b1013,"reason=FailedScheduling count=None msg=0/6 nodes are available: 1 c_wall violated: 1 conflicting context pair(s) with node memory, 5 node(s) had untolerated taint(s). no new claims to deallocate, preemption: 0/6 nodes are available: 1 No preemption victims found for incoming pod, 5 Preemption is not helpful for scheduling."
60.0234,Event,ADDED,eval-sanitize-2-r1-022-j62jr.18d3d0fe1860fa77,"reason=FailedScheduling count=None msg=0/6 nodes are available: 1 c_wall violated: 1 conflicting context pair(s) with node memory, 5 node(s) had untolerated taint(s). no new claims to deallocate, preemption: 0/6 nodes are available: 1 No preemption victims found for incoming pod, 5 Preemption is not helpful for scheduling."
60.0235,TaskRequest,ADDED,eval-sanitize-2-r3-006,phase=Complete job=None
60.0236,TaskRequest,ADDED,eval-sanitize-2-r3-007,phase=Complete job=None
60.0236,TaskRequest,ADDED,eval-sanitize-2-r3-008,phase=Complete job=None
60.025,Job,ADDED,eval-sanitize-2-r3-003,
60.0253,Event,ADDED,eval-sanitize-2-r1-023-ghcb9.18d3d0fe192cbe0d,"reason=FailedScheduling count=None msg=0/6 nodes are available: 1 c_wall violated: 1 conflicting context pair(s) with node memory, 5 node(s) had untolerated taint(s). no new claims to deallocate, preemption: 0/6 nodes are available: 1 No preemption victims found for incoming pod, 5 Preemption is not helpful for scheduling."
60.0256,Event,ADDED,eval-sanitize-2-r1-023-ghcb9.18d3d0fecc8cbc7b,"reason=FailedScheduling count=None msg=0/6 nodes are available: 1 c_wall violated: 2 conflicting context pair(s) with node memory, 5 node(s) had untolerated taint(s). no new claims to deallocate, preemption: 0/6 nodes are available: 1 No preemption victims found for incoming pod, 5 Preemption is not helpful for scheduling."
60.0258,Event,ADDED,eval-sanitize-2-r1-025-dxjk5.18d3d0fe1e128c69,"reason=FailedScheduling count=None msg=0/6 nodes are available: 1 c_wall violated: 1 conflicting context pair(s) with node memory, 5 node(s) had untolerated taint(s). no new claims to deallocate, preemption: 0/6 nodes are available: 1 No preemption victims found for incoming pod, 5 Preemption is not helpful for scheduling."
60.0259,TaskRequest,ADDED,eval-sanitize-2-r3-009,phase=Complete job=None
60.0259,TaskRequest,ADDED,eval-sanitize-2-r3-010,phase=Complete job=None
60.0271,Pod,ADDED,eval-sanitize-2-r3-001-k9ccn,phase=Succeeded node=kind-worker
60.0283,Pod,ADDED,eval-sanitize-2-r3-002-bb2jg,phase=Succeeded node=kind-worker4
60.0287,Event,ADDED,eval-sanitize-2-r1-028-m45rp.18d3d0fe54f879aa,"reason=FailedScheduling count=None msg=0/6 nodes are available: 1 c_wall violated: 1 conflicting context pair(s) with node memory, 5 node(s) had untolerated taint(s). no new claims to deallocate, preemption: 0/6 nodes are available: 1 No preemption victims found for incoming pod, 5 Preemption is not helpful for scheduling."
60.0289,Event,ADDED,eval-sanitize-2-r1-029-8h5ds.18d3d0feccc23789,"reason=FailedScheduling count=None msg=0/6 nodes are available: 1 c_wall violated: 2 conflicting context pair(s) with node memory, 5 node(s) had untolerated taint(s). no new claims to deallocate, preemption: 0/6 nodes are available: 1 No preemption victims found for incoming pod, 5 Preemption is not helpful for scheduling."
60.029,TaskRequest,ADDED,eval-sanitize-2-r3-011,phase=Complete job=None
60.029,TaskRequest,ADDED,eval-sanitize-2-r3-012,phase=Complete job=None
60.0291,TaskRequest,ADDED,eval-sanitize-2-r3-013,phase=Complete job=None
60.0303,Node,ADDED,kind-worker,taints=1
60.0313,Job,ADDED,eval-sanitize-2-r3-004,
60.0324,Pod,ADDED,eval-sanitize-2-r3-003-fg2r7,phase=Succeeded node=kind-worker5
60.0328,Event,ADDED,eval-sanitize-2-r1-029-8h5ds.18d3d0ff07e8edce,"reason=FailedScheduling count=None msg=0/6 nodes are available: 1 c_wall violated: 3 conflicting context pair(s) with node memory, 5 node(s) had untolerated taint(s). no new claims to deallocate, preemption: 0/6 nodes are available: 1 No preemption victims found for incoming pod, 5 Preemption is not helpful for scheduling."
60.033,Event,ADDED,eval-sanitize-2-r1-029-8h5ds.18d3d0ff2bfac2c0,"reason=FailedScheduling count=None msg=0/6 nodes are available: 1 c_wall violated: 1 conflicting context pair(s) with node memory, 1 c_wall violated: 3 conflicting context pair(s) with node memory, 4 node(s) had untolerated taint(s). no new claims to deallocate, preemption: 0/6 nodes are available: 2 No preemption victims found for incoming pod, 4 Preemption is not helpful for scheduling."
60.0332,Event,ADDED,eval-sanitize-2-r1-030-qxfhr.18d3d0fed24a070e,"reason=FailedScheduling count=None msg=0/6 nodes are available: 1 c_wall violated: 2 conflicting context pair(s) with node memory, 5 node(s) had untolerated taint(s). no new claims to deallocate, preemption: 0/6 nodes are available: 1 No preemption victims found for incoming pod, 5 Preemption is not helpful for scheduling."
60.0333,TaskRequest,ADDED,eval-sanitize-2-r3-014,phase=Complete job=None
60.0333,TaskRequest,ADDED,eval-sanitize-2-r3-015,phase=Complete job=None
60.0333,TaskRequest,ADDED,eval-sanitize-2-r3-016,phase=Complete job=None
60.0345,Job,ADDED,eval-sanitize-2-r3-005,
60.036,Pod,ADDED,eval-sanitize-2-r3-004-8tv8k,phase=Succeeded node=kind-worker3
60.0374,Node,ADDED,kind-worker2,taints=1
60.0377,Event,ADDED,eval-sanitize-2-r1-033-l5hlx.18d3d0ff7e9bcade,"reason=FailedScheduling count=None msg=0/6 nodes are available: 1 c_wall violated: 1 conflicting context pair(s) with node memory, 1 c_wall violated: 2 conflicting context pair(s) with node memory, 4 node(s) had untolerated taint(s). no new claims to deallocate, preemption: 0/6 nodes are available: 2 No preemption victims found for incoming pod, 4 Preemption is not helpful for scheduling."
60.038,Event,ADDED,eval-sanitize-2-r1-035-zhx85.18d3d0fff5331675,"reason=FailedScheduling count=None msg=0/6 nodes are available: 1 c_wall violated: 2 conflicting context pair(s) with node memory, 5 node(s) had untolerated taint(s). no new claims to deallocate, preemption: 0/6 nodes are available: 1 No preemption victims found for incoming pod, 5 Preemption is not helpful for scheduling."
60.0383,Event,ADDED,eval-sanitize-2-r1-036-k6gqd.18d3d10143b6d5c6,"reason=FailedScheduling count=None msg=0/6 nodes are available: 1 c_wall violated: 1 conflicting context pair(s) with node memory, 5 node(s) had untolerated taint(s). no new claims to deallocate, preemption: 0/6 nodes are available: 1 No preemption victims found for incoming pod, 5 Preemption is not helpful for scheduling."
60.0384,TaskRequest,ADDED,eval-sanitize-2-r3-017,phase=Complete job=None
60.0385,TaskRequest,ADDED,eval-sanitize-2-r3-018,phase=Complete job=None
60.0395,Job,ADDED,eval-sanitize-2-r3-006,
60.0402,Event,ADDED,eval-sanitize-2-r1-037-n4x7c.18d3d101447d35b7,"reason=FailedScheduling count=None msg=0/6 nodes are available: 1 c_wall violated: 1 conflicting context pair(s) with node memory, 5 node(s) had untolerated taint(s). no new claims to deallocate, preemption: 0/6 nodes are available: 1 No preemption victims found for incoming pod, 5 Preemption is not helpful for scheduling."
60.0404,Event,ADDED,eval-sanitize-2-r1-039-9hqwx.18d3d10148b55f1a,"reason=FailedScheduling count=None msg=0/6 nodes are available: 1 c_wall violated: 1 conflicting context pair(s) with node memory, 5 node(s) had untolerated taint(s). no new claims to deallocate, preemption: 0/6 nodes are available: 1 No preemption victims found for incoming pod, 5 Preemption is not helpful for scheduling."
60.0406,Event,ADDED,eval-sanitize-2-r1-043-mqs67.18d3d10256ee65da,"reason=FailedScheduling count=None msg=0/6 nodes are available: 1 c_wall violated: 2 conflicting context pair(s) with node memory, 5 node(s) had untolerated taint(s). no new claims to deallocate, preemption: 0/6 nodes are available: 1 No preemption victims found for incoming pod, 5 Preemption is not helpful for scheduling."
60.0407,TaskRequest,ADDED,eval-sanitize-2-r3-019,phase=Complete job=None
60.0407,TaskRequest,ADDED,eval-sanitize-2-r3-020,phase=Complete job=None
60.0408,TaskRequest,ADDED,eval-sanitize-2-r3-021,phase=Complete job=None
60.0427,Pod,ADDED,eval-sanitize-2-r3-005-mnkl6,phase=Succeeded node=kind-worker2
60.0435,Event,ADDED,eval-sanitize-2-r1-043-mqs67.18d3d10262225b14,"reason=FailedScheduling count=None msg=0/6 nodes are available: 1 c_wall violated: 1 conflicting context pair(s) with node memory, 1 c_wall violated: 2 conflicting context pair(s) with node memory, 4 node(s) had untolerated taint(s). no new claims to deallocate, preemption: 0/6 nodes are available: 2 No preemption victims found for incoming pod, 4 Preemption is not helpful for scheduling."
60.0438,Event,ADDED,eval-sanitize-2-r1-044-qmqs2.18d3d102571a6b79,"reason=FailedScheduling count=None msg=0/6 nodes are available: 1 c_wall violated: 1 conflicting context pair(s) with node memory, 5 node(s) had untolerated taint(s). no new claims to deallocate, preemption: 0/6 nodes are available: 1 No preemption victims found for incoming pod, 5 Preemption is not helpful for scheduling."
60.0439,TaskRequest,ADDED,eval-sanitize-2-r3-022,phase=Complete job=None
60.044,TaskRequest,ADDED,eval-sanitize-2-r3-023,phase=Complete job=None
60.0453,Pod,ADDED,eval-sanitize-2-r3-006-m98bf,phase=Succeeded node=kind-worker2
60.0465,Job,ADDED,eval-sanitize-2-r3-007,
60.0478,Node,ADDED,kind-worker3,taints=1
60.0487,Event,ADDED,eval-sanitize-2-r1-044-qmqs2.18d3d10262b13a21,"reason=FailedScheduling count=None msg=0/6 nodes are available: 2 c_wall violated: 1 conflicting context pair(s) with node memory, 4 node(s) had untolerated taint(s). no new claims to deallocate, preemption: 0/6 nodes are available: 2 No preemption victims found for incoming pod, 4 Preemption is not helpful for scheduling."
60.0492,Event,ADDED,eval-sanitize-2-r1-044-qmqs2.18d3d10278a71b6f,"reason=FailedScheduling count=None msg=0/6 nodes are available: 3 c_wall violated: 1 conflicting context pair(s) with node memory, 3 node(s) had untolerated taint(s). no new claims to deallocate, preemption: 0/6 nodes are available: 3 No preemption victims found for incoming pod, 3 Preemption is not helpful for scheduling."
60.0497,Event,ADDED,eval-sanitize-2-r1-044-qmqs2.18d3d102cc1afcff,"reason=FailedScheduling count=None msg=0/6 nodes are available: 1 c_wall violated: 2 conflicting context pair(s) with node memory, 2 c_wall violated: 1 conflicting context pair(s) with node memory, 3 node(s) had untolerated taint(s). no new claims to deallocate, preemption: 0/6 nodes are available: 3 No preemption victims found for incoming pod, 3 Preemption is not helpful for scheduling."
60.0498,TaskRequest,ADDED,eval-sanitize-2-r3-024,phase=Complete job=None
60.0498,TaskRequest,ADDED,eval-sanitize-2-r3-025,phase=Complete job=None
60.0499,TaskRequest,ADDED,eval-sanitize-2-r3-026,phase=Complete job=None
60.05,TaskRequest,ADDED,eval-sanitize-2-r3-027,phase=Complete job=None
60.05,TaskRequest,ADDED,eval-sanitize-2-r3-028,phase=Complete job=None
60.05,TaskRequest,ADDED,eval-sanitize-2-r3-029,phase=Complete job=None
60.0517,Pod,ADDED,eval-sanitize-2-r3-007-t9hwl,phase=Succeeded node=kind-worker
60.0517,TaskRequest,ADDED,eval-sanitize-2-r3-030,phase=Complete job=None
60.0518,TaskRequest,ADDED,eval-sanitize-2-r3-031,phase=Complete job=None
60.0532,Node,ADDED,kind-worker4,taints=1
60.0539,Event,ADDED,eval-sanitize-2-r1-044-qmqs2.18d3d102d9f01f92,"reason=FailedScheduling count=None msg=0/6 nodes are available: 1 c_wall violated: 2 conflicting context pair(s) with node memory, 5 node(s) had untolerated taint(s). no new claims to deallocate, preemption: 0/6 nodes are available: 1 No preemption victims found for incoming pod, 5 Preemption is not helpful for scheduling."
60.0543,Event,ADDED,eval-sanitize-2-r1-045-nh7bx.18d3d1025ae3855e,"reason=FailedScheduling count=None msg=0/6 nodes are available: 1 c_wall violated: 1 conflicting context pair(s) with node memory, 5 node(s) had untolerated taint(s). no new claims to deallocate, preemption: 0/6 nodes are available: 1 No preemption victims found for incoming pod, 5 Preemption is not helpful for scheduling."
60.0545,Event,ADDED,eval-sanitize-2-r1-045-nh7bx.18d3d10266774b1d,"reason=FailedScheduling count=None msg=0/6 nodes are available: 2 c_wall violated: 1 conflicting context pair(s) with node memory, 4 node(s) had untolerated taint(s). no new claims to deallocate, preemption: 0/6 nodes are available: 2 No preemption victims found for incoming pod, 4 Preemption is not helpful for scheduling."
60.0554,Job,ADDED,eval-sanitize-2-r3-008,
60.0566,Pod,ADDED,eval-sanitize-2-r3-008-7vg7g,phase=Succeeded node=kind-worker
60.0567,TaskRequest,ADDED,eval-sanitize-2-r3-032,phase=Complete job=None
60.0567,TaskRequest,ADDED,eval-sanitize-2-r3-033,phase=Complete job=None
60.0567,TaskRequest,ADDED,eval-sanitize-2-r3-034,phase=Complete job=None
60.0568,TaskRequest,ADDED,eval-sanitize-2-r3-035,phase=Complete job=None
60.0568,TaskRequest,ADDED,eval-sanitize-2-r3-036,phase=Complete job=None
60.0569,TaskRequest,ADDED,eval-sanitize-2-r3-037,phase=Complete job=None
60.0573,Event,ADDED,eval-sanitize-2-r1-045-nh7bx.18d3d1027a937acb,"reason=FailedScheduling count=None msg=0/6 nodes are available: 3 c_wall violated: 1 conflicting context pair(s) with node memory, 3 node(s) had untolerated taint(s). no new claims to deallocate, preemption: 0/6 nodes are available: 3 No preemption victims found for incoming pod, 3 Preemption is not helpful for scheduling."
60.0575,Event,ADDED,eval-sanitize-2-r1-045-nh7bx.18d3d102cdbeb596,"reason=FailedScheduling count=None msg=0/6 nodes are available: 1 c_wall violated: 2 conflicting context pair(s) with node memory, 2 c_wall violated: 1 conflicting context pair(s) with node memory, 3 node(s) had untolerated taint(s). no new claims to deallocate, preemption: 0/6 nodes are available: 3 No preemption victims found for incoming pod, 3 Preemption is not helpful for scheduling."
60.0577,Event,ADDED,eval-sanitize-2-r1-045-nh7bx.18d3d102d9b6cded,"reason=FailedScheduling count=None msg=0/6 nodes are available: 1 c_wall violated: 2 conflicting context pair(s) with node memory, 5 node(s) had untolerated taint(s). no new claims to deallocate, preemption: 0/6 nodes are available: 1 No preemption victims found for incoming pod, 5 Preemption is not helpful for scheduling."
60.058,Event,ADDED,eval-sanitize-2-r1-049-4mlwq.18d3d10337b429ac,"reason=FailedScheduling count=None msg=0/6 nodes are available: 1 c_wall violated: 1 conflicting context pair(s) with node memory, 5 node(s) had untolerated taint(s). no new claims to deallocate, preemption: 0/6 nodes are available: 1 No preemption victims found for incoming pod, 5 Preemption is not helpful for scheduling."
60.0582,Event,ADDED,eval-sanitize-2-r1-055-pt5vj.18d3d104d2f03aa1,"reason=FailedScheduling count=None msg=0/6 nodes are available: 1 c_wall violated: 4 conflicting context pair(s) with node memory, 5 node(s) had untolerated taint(s). no new claims to deallocate, preemption: 0/6 nodes are available: 1 No preemption victims found for incoming pod, 5 Preemption is not helpful for scheduling."
60.0584,Event,ADDED,eval-sanitize-2-r1-055-pt5vj.18d3d104da0ce76c,"reason=FailedScheduling count=None msg=0/6 nodes are available: 1 c_wall violated: 4 conflicting context pair(s) with node memory, 5 node(s) had untolerated taint(s). no new claims to deallocate, preemption: 0/6 nodes are available: 1 No preemption victims found for incoming pod, 5 Preemption is not helpful for scheduling."
60.059,TaskRequest,ADDED,eval-sanitize-2-r3-038,phase=Complete job=None
60.0591,TaskRequest,ADDED,eval-sanitize-2-r3-039,phase=Complete job=None
60.0599,Job,ADDED,eval-sanitize-2-r3-009,
60.0602,Event,ADDED,eval-sanitize-2-r1-056-mlt6x.18d3d104da443e57,"reason=FailedScheduling count=None msg=0/6 nodes are available: 1 c_wall violated: 4 conflicting context pair(s) with node memory, 5 node(s) had untolerated taint(s). no new claims to deallocate, preemption: 0/6 nodes are available: 1 No preemption victims found for incoming pod, 5 Preemption is not helpful for scheduling."
60.0605,Event,ADDED,eval-sanitize-2-r1-057-chpmz.18d3d10514b8bec5,"reason=FailedScheduling count=None msg=0/6 nodes are available: 1 c_wall violated: 1 conflicting context pair(s) with node memory, 5 node(s) had untolerated taint(s). no new claims to deallocate, preemption: 0/6 nodes are available: 1 No preemption victims found for incoming pod, 5 Preemption is not helpful for scheduling."
60.062,Node,ADDED,kind-worker5,taints=0
60.0625,TaskRequest,ADDED,eval-sanitize-2-r3-040,phase=Complete job=None
60.0625,TaskRequest,ADDED,eval-sanitize-2-r3-041,phase=Complete job=None
60.0626,TaskRequest,ADDED,eval-sanitize-2-r3-042,phase=Complete job=None
60.0637,Pod,ADDED,eval-sanitize-2-r3-009-j7dq8,phase=Succeeded node=kind-worker
60.0645,Job,ADDED,eval-sanitize-2-r3-010,
60.0648,Event,ADDED,eval-sanitize-2-r1-058-j6wzt.18d3d1057317bc4f,"reason=FailedScheduling count=None msg=0/6 nodes are available: 1 c_wall violated: 1 conflicting context pair(s) with node memory, 5 node(s) had untolerated taint(s). no new claims to deallocate, preemption: 0/6 nodes are available: 1 No preemption victims found for incoming pod, 5 Preemption is not helpful for scheduling."
60.065,Event,ADDED,eval-sanitize-2-r1-062-82jrc.18d3d1063e6bd98a,"reason=FailedScheduling count=None msg=0/6 nodes are available: 1 c_wall violated: 1 conflicting context pair(s) with node memory, 5 node(s) had untolerated taint(s). no new claims to deallocate, preemption: 0/6 nodes are available: 1 No preemption victims found for incoming pod, 5 Preemption is not helpful for scheduling."
60.0653,Event,ADDED,eval-sanitize-2-r1-062-82jrc.18d3d1067bd11e8d,"reason=FailedScheduling count=None msg=0/6 nodes are available: 1 c_wall violated: 2 conflicting context pair(s) with node memory, 5 node(s) had untolerated taint(s). no new claims to deallocate, preemption: 0/6 nodes are available: 1 No preemption victims found for incoming pod, 5 Preemption is not helpful for scheduling."
60.0658,TaskRequest,ADDED,eval-sanitize-2-r3-043,phase=Complete job=None
60.0658,TaskRequest,ADDED,eval-sanitize-2-r3-044,phase=Complete job=None
60.067,Pod,ADDED,eval-sanitize-2-r3-010-c57dg,phase=Succeeded node=kind-worker
60.0678,Job,ADDED,eval-sanitize-2-r3-011,
60.0679,TaskRequest,ADDED,eval-sanitize-2-r3-045,phase=Complete job=None
60.0679,TaskRequest,ADDED,eval-sanitize-2-r3-046,phase=Scheduled job=None
60.068,TaskRequest,ADDED,eval-sanitize-2-r3-047,phase=Scheduled job=None
60.0683,Event,ADDED,eval-sanitize-2-r1-064-8xhvn.18d3d106b5be4626,"reason=FailedScheduling count=None msg=0/6 nodes are available: 1 c_wall violated: 1 conflicting context pair(s) with node memory, 5 node(s) had untolerated taint(s). no new claims to deallocate, preemption: 0/6 nodes are available: 1 No preemption victims found for incoming pod, 5 Preemption is not helpful for scheduling."
60.0685,Event,ADDED,eval-sanitize-2-r1-066-9hdg9.18d3d1080a849509,"reason=FailedScheduling count=None msg=0/6 nodes are available: 1 c_wall violated: 2 conflicting context pair(s) with node memory, 5 node(s) had untolerated taint(s). no new claims to deallocate, preemption: 0/6 nodes are available: 1 No preemption victims found for incoming pod, 5 Preemption is not helpful for scheduling."
60.0688,Event,ADDED,eval-sanitize-2-r1-067-bkrpl.18d3d1080add570a,"reason=FailedScheduling count=None msg=0/6 nodes are available: 1 c_wall violated: 2 conflicting context pair(s) with node memory, 5 node(s) had untolerated taint(s). no new claims to deallocate, preemption: 0/6 nodes are available: 1 No preemption victims found for incoming pod, 5 Preemption is not helpful for scheduling."
60.07,Pod,ADDED,eval-sanitize-2-r3-011-vt6dt,phase=Succeeded node=kind-worker
60.0713,Job,ADDED,eval-sanitize-2-r3-012,
60.0714,TaskRequest,ADDED,eval-sanitize-2-r3-048,phase=Scheduled job=None
60.0714,TaskRequest,ADDED,eval-sanitize-2-r3-049,phase=Scheduled job=None
60.0714,TaskRequest,ADDED,eval-sanitize-2-r3-050,phase=Scheduled job=None
60.0718,Event,ADDED,eval-sanitize-2-r1-070-bt2ks.18d3d1081b910e54,"reason=FailedScheduling count=None msg=0/6 nodes are available: 1 c_wall violated: 1 conflicting context pair(s) with node memory, 5 node(s) had untolerated taint(s). no new claims to deallocate, preemption: 0/6 nodes are available: 1 No preemption victims found for incoming pod, 5 Preemption is not helpful for scheduling."
60.072,Event,ADDED,eval-sanitize-2-r1-072-6qfr9.18d3d10964faf0b4,"reason=FailedScheduling count=None msg=0/6 nodes are available: 1 c_wall violated: 2 conflicting context pair(s) with node memory, 5 node(s) had untolerated taint(s). no new claims to deallocate, preemption: 0/6 nodes are available: 1 No preemption victims found for incoming pod, 5 Preemption is not helpful for scheduling."
60.0722,Event,ADDED,eval-sanitize-2-r1-072-6qfr9.18d3d1099a7125a7,"reason=FailedScheduling count=None msg=0/6 nodes are available: 2 c_wall violated: 2 conflicting context pair(s) with node memory, 4 node(s) had untolerated taint(s). no new claims to deallocate, preemption: 0/6 nodes are available: 2 No preemption victims found for incoming pod, 4 Preemption is not helpful for scheduling."
60.0734,Pod,ADDED,eval-sanitize-2-r3-012-4v9kc,phase=Succeeded node=kind-worker2
60.0737,TaskRequest,ADDED,eval-sanitize-2-r3-051,phase=Scheduled job=None
60.0738,TaskRequest,ADDED,eval-sanitize-2-r3-052,phase=Scheduled job=None
60.0743,Event,ADDED,eval-sanitize-2-r1-072-6qfr9.18d3d109f20ce905,"reason=FailedScheduling count=None msg=0/6 nodes are available: 1 c_wall violated: 2 conflicting context pair(s) with node memory, 5 node(s) had untolerated taint(s). no new claims to deallocate, preemption: 0/6 nodes are available: 1 No preemption victims found for incoming pod, 5 Preemption is not helpful for scheduling."
60.0746,Event,ADDED,eval-sanitize-2-r1-073-twh2n.18d3d109652df503,"reason=FailedScheduling count=None msg=0/6 nodes are available: 1 c_wall violated: 2 conflicting context pair(s) with node memory, 5 node(s) had untolerated taint(s). no new claims to deallocate, preemption: 0/6 nodes are available: 1 No preemption victims found for incoming pod, 5 Preemption is not helpful for scheduling."
60.0748,Event,ADDED,eval-sanitize-2-r1-075-88zts.18d3d10965573d35,"reason=FailedScheduling count=None msg=0/6 nodes are available: 1 c_wall violated: 1 conflicting context pair(s) with node memory, 5 node(s) had untolerated taint(s). no new claims to deallocate, preemption: 0/6 nodes are available: 1 No preemption victims found for incoming pod, 5 Preemption is not helpful for scheduling."
60.0751,Event,ADDED,eval-sanitize-2-r1-075-88zts.18d3d1099a29c03e,"reason=FailedScheduling count=None msg=0/6 nodes are available: 2 c_wall violated: 1 conflicting context pair(s) with node memory, 4 node(s) had untolerated taint(s). no new claims to deallocate, preemption: 0/6 nodes are available: 2 No preemption victims found for incoming pod, 4 Preemption is not helpful for scheduling."
60.0753,Event,ADDED,eval-sanitize-2-r1-075-88zts.18d3d109f1e557a6,"reason=FailedScheduling count=None msg=0/6 nodes are available: 1 c_wall violated: 1 conflicting context pair(s) with node memory, 5 node(s) had untolerated taint(s). no new claims to deallocate, preemption: 0/6 nodes are available: 1 No preemption victims found for incoming pod, 5 Preemption is not helpful for scheduling."
60.0755,Event,ADDED,eval-sanitize-2-r1-076-ttcm4.18d3d1098173edca,"reason=FailedScheduling count=None msg=0/6 nodes are available: 1 c_wall violated: 1 conflicting context pair(s) with node memory, 5 node(s) had untolerated taint(s). no new claims to deallocate, preemption: 0/6 nodes are available: 1 No preemption victims found for incoming pod, 5 Preemption is not helpful for scheduling."
60.0757,TaskRequest,ADDED,eval-sanitize-2-r3-053,phase=Scheduled job=None
60.0757,TaskRequest,ADDED,eval-sanitize-2-r3-054,phase=Scheduled job=None
60.0757,TaskRequest,ADDED,eval-sanitize-2-r3-055,phase=Scheduled job=None
60.0765,Job,ADDED,eval-sanitize-2-r3-013,
60.078,Pod,ADDED,eval-sanitize-2-r3-013-cnzht,phase=Succeeded node=kind-worker
60.0783,Event,ADDED,eval-sanitize-2-r1-078-wmv2z.18d3d109f8453d82,"reason=FailedScheduling count=None msg=0/6 nodes are available: 1 c_wall violated: 1 conflicting context pair(s) with node memory, 5 node(s) had untolerated taint(s). no new claims to deallocate, preemption: 0/6 nodes are available: 1 No preemption victims found for incoming pod, 5 Preemption is not helpful for scheduling."
60.0785,Event,ADDED,eval-sanitize-2-r1-080-wtxtp.18d3d10a7020ac48,"reason=FailedScheduling count=None msg=0/6 nodes are available: 2 c_wall violated: 1 conflicting context pair(s) with node memory, 4 node(s) had untolerated taint(s). no new claims to deallocate, preemption: 0/6 nodes are available: 2 No preemption victims found for incoming pod, 4 Preemption is not helpful for scheduling."
60.0786,TaskRequest,ADDED,eval-sanitize-2-r3-056,phase=Scheduled job=None
60.0787,TaskRequest,ADDED,eval-sanitize-2-r3-057,phase=Scheduled job=None
60.0787,TaskRequest,ADDED,eval-sanitize-2-r3-058,phase=Scheduled job=None
60.0788,TaskRequest,ADDED,eval-sanitize-2-r3-059,phase=Scheduled job=None
60.0788,TaskRequest,ADDED,eval-sanitize-2-r3-060,phase=Pending job=None
60.0799,Pod,ADDED,eval-sanitize-2-r3-014-k55b8,phase=Succeeded node=kind-worker2
60.0802,Event,ADDED,eval-sanitize-2-r1-080-wtxtp.18d3d10aaa836f11,"reason=FailedScheduling count=None msg=0/6 nodes are available: 1 c_wall violated: 1 conflicting context pair(s) with node memory, 5 node(s) had untolerated taint(s). no new claims to deallocate, preemption: 0/6 nodes are available: 1 No preemption victims found for incoming pod, 5 Preemption is not helpful for scheduling."
60.0804,Event,ADDED,eval-sanitize-2-r1-080-wtxtp.18d3d10aacc1ed75,"reason=FailedScheduling count=None msg=0/6 nodes are available: 1 c_wall violated: 2 conflicting context pair(s) with node memory, 5 node(s) had untolerated taint(s). no new claims to deallocate, preemption: 0/6 nodes are available: 1 No preemption victims found for incoming pod, 5 Preemption is not helpful for scheduling."
60.0806,Event,ADDED,eval-sanitize-2-r1-082-ncrsp.18d3d10b7b89cb61,"reason=FailedScheduling count=None msg=0/6 nodes are available: 1 c_wall violated: 1 conflicting context pair(s) with node memory, 5 node(s) had untolerated taint(s). no new claims to deallocate, preemption: 0/6 nodes are available: 1 No preemption victims found for incoming pod, 5 Preemption is not helpful for scheduling."
60.0814,Job,ADDED,eval-sanitize-2-r3-014,
60.0825,TaskRequest,MODIFIED,eval-sanitize-2-r3-060,phase=Scheduled job=None
60.0826,TaskRequest,MODIFIED,eval-sanitize-2-r3-060,phase=Scheduled job=None
60.0834,Job,ADDED,eval-sanitize-2-r3-015,
60.0836,Event,ADDED,eval-sanitize-2-r1-082-ncrsp.18d3d10b9b2b0152,"reason=FailedScheduling count=None msg=0/6 nodes are available: 1 c_wall violated: 2 conflicting context pair(s) with node memory, 5 node(s) had untolerated taint(s). no new claims to deallocate, preemption: 0/6 nodes are available: 1 No preemption victims found for incoming pod, 5 Preemption is not helpful for scheduling."
60.0838,Event,ADDED,eval-sanitize-2-r1-082-ncrsp.18d3d10c7e0047c0,"reason=FailedScheduling count=None msg=0/6 nodes are available: 1 c_wall violated: 1 conflicting context pair(s) with node memory, 5 node(s) had untolerated taint(s). no new claims to deallocate, preemption: 0/6 nodes are available: 1 No preemption victims found for incoming pod, 5 Preemption is not helpful for scheduling."
60.0841,Event,ADDED,eval-sanitize-2-r1-084-j2b28.18d3d10b7bb676e2,"reason=FailedScheduling count=None msg=0/6 nodes are available: 1 c_wall violated: 1 conflicting context pair(s) with node memory, 5 node(s) had untolerated taint(s). no new claims to deallocate, preemption: 0/6 nodes are available: 1 No preemption victims found for incoming pod, 5 Preemption is not helpful for scheduling."
60.0852,Pod,ADDED,eval-sanitize-2-r3-015-9g8mh,phase=Succeeded node=kind-worker
60.086,Job,ADDED,eval-sanitize-2-r3-016,
60.0863,Event,ADDED,eval-sanitize-2-r1-084-j2b28.18d3d10b9af96271,"reason=FailedScheduling count=None msg=0/6 nodes are available: 1 c_wall violated: 2 conflicting context pair(s) with node memory, 5 node(s) had untolerated taint(s). no new claims to deallocate, preemption: 0/6 nodes are available: 1 No preemption victims found for incoming pod, 5 Preemption is not helpful for scheduling."
60.0865,Event,ADDED,eval-sanitize-2-r1-084-j2b28.18d3d10c7e312a7c,"reason=FailedScheduling count=None msg=0/6 nodes are available: 1 c_wall violated: 1 conflicting context pair(s) with node memory, 5 node(s) had untolerated taint(s). no new claims to deallocate, preemption: 0/6 nodes are available: 1 No preemption victims found for incoming pod, 5 Preemption is not helpful for scheduling."
60.0867,Event,ADDED,eval-sanitize-2-r1-086-484rj.18d3d10bd5dcc012,"reason=FailedScheduling count=None msg=0/6 nodes are available: 1 c_wall violated: 1 conflicting context pair(s) with node memory, 5 node(s) had untolerated taint(s). no new claims to deallocate, preemption: 0/6 nodes are available: 1 No preemption victims found for incoming pod, 5 Preemption is not helpful for scheduling."
60.0879,Pod,ADDED,eval-sanitize-2-r3-016-4jb2m,phase=Succeeded node=kind-worker
60.0895,Job,ADDED,eval-sanitize-2-r3-017,
60.0909,Pod,ADDED,eval-sanitize-2-r3-017-98n66,phase=Succeeded node=kind-worker4
60.0912,Event,ADDED,eval-sanitize-2-r1-087-88smk.18d3d10c7e5e956d,"reason=FailedScheduling count=None msg=0/6 nodes are available: 1 c_wall violated: 1 conflicting context pair(s) with node memory, 5 node(s) had untolerated taint(s). no new claims to deallocate, preemption: 0/6 nodes are available: 1 No preemption victims found for incoming pod, 5 Preemption is not helpful for scheduling."
60.0914,Event,ADDED,eval-sanitize-2-r1-087-88smk.18d3d10cd6a7a32c,"reason=FailedScheduling count=None msg=0/6 nodes are available: 2 c_wall violated: 1 conflicting context pair(s) with node memory, 4 node(s) had untolerated taint(s). no new claims to deallocate, preemption: 0/6 nodes are available: 2 No preemption victims found for incoming pod, 4 Preemption is not helpful for scheduling."
60.0916,Event,ADDED,eval-sanitize-2-r1-087-88smk.18d3d10cf8efedf2,"reason=FailedScheduling count=None msg=0/6 nodes are available: 1 c_wall violated: 1 conflicting context pair(s) with node memory, 5 node(s) had untolerated taint(s). no new claims to deallocate, preemption: 0/6 nodes are available: 1 No preemption victims found for incoming pod, 5 Preemption is not helpful for scheduling."
60.0924,Job,ADDED,eval-sanitize-2-r3-018,
60.0935,Pod,ADDED,eval-sanitize-2-r3-018-lhc4h,phase=Succeeded node=kind-worker5
60.0938,Event,ADDED,eval-sanitize-2-r1-088-wtjq7.18d3d10c81801567,"reason=FailedScheduling count=None msg=0/6 nodes are available: 1 c_wall violated: 1 conflicting context pair(s) with node memory, 5 node(s) had untolerated taint(s). no new claims to deallocate, preemption: 0/6 nodes are available: 1 No preemption victims found for incoming pod, 5 Preemption is not helpful for scheduling."
60.094,Event,ADDED,eval-sanitize-2-r1-089-fshln.18d3d10c881d057e,"reason=FailedScheduling count=None msg=0/6 nodes are available: 1 c_wall violated: 1 conflicting context pair(s) with node memory, 5 node(s) had untolerated taint(s). no new claims to deallocate, preemption: 0/6 nodes are available: 1 No preemption victims found for incoming pod, 5 Preemption is not helpful for scheduling."
60.0953,Job,ADDED,eval-sanitize-2-r3-019,
60.0957,Event,ADDED,eval-sanitize-2-r1-089-fshln.18d3d10cd7010b5f,"reason=FailedScheduling count=None msg=0/6 nodes are available: 2 c_wall violated: 1 conflicting context pair(s) with node memory, 4 node(s) had untolerated taint(s). no new claims to deallocate, preemption: 0/6 nodes are available: 2 No preemption victims found for incoming pod, 4 Preemption is not helpful for scheduling."
60.0959,Event,ADDED,eval-sanitize-2-r1-089-fshln.18d3d10cf91bdad8,"reason=FailedScheduling count=None msg=0/6 nodes are available: 1 c_wall violated: 1 conflicting context pair(s) with node memory, 5 node(s) had untolerated taint(s). no new claims to deallocate, preemption: 0/6 nodes are available: 1 No preemption victims found for incoming pod, 5 Preemption is not helpful for scheduling."
60.0962,Event,ADDED,eval-sanitize-2-r1-089-fshln.18d3d10d75f47e4e,"reason=FailedScheduling count=None msg=0/6 nodes are available: 1 c_wall violated: 2 conflicting context pair(s) with node memory, 5 node(s) had untolerated taint(s). no new claims to deallocate, preemption: 0/6 nodes are available: 1 No preemption victims found for incoming pod, 5 Preemption is not helpful for scheduling."
60.0973,Pod,ADDED,eval-sanitize-2-r3-019-rvslz,phase=Succeeded node=kind-worker3
60.0982,Job,ADDED,eval-sanitize-2-r3-020,
60.0985,Event,ADDED,eval-sanitize-2-r1-090-972ws.18d3d10cc3aef0ac,"reason=FailedScheduling count=None msg=0/6 nodes are available: 1 c_wall violated: 1 conflicting context pair(s) with node memory, 5 node(s) had untolerated taint(s). no new claims to deallocate, preemption: 0/6 nodes are available: 1 No preemption victims found for incoming pod, 5 Preemption is not helpful for scheduling."
60.0987,Event,ADDED,eval-sanitize-2-r1-090-972ws.18d3d10cda9db9fb,"reason=FailedScheduling count=None msg=0/6 nodes are available: 2 c_wall violated: 1 conflicting context pair(s) with node memory, 4 node(s) had untolerated taint(s). no new claims to deallocate, preemption: 0/6 nodes are available: 2 No preemption victims found for incoming pod, 4 Preemption is not helpful for scheduling."
60.099,Event,ADDED,eval-sanitize-2-r1-090-972ws.18d3d10cf94304c9,"reason=FailedScheduling count=None msg=0/6 nodes are available: 1 c_wall violated: 1 conflicting context pair(s) with node memory, 5 node(s) had untolerated taint(s). no new claims to deallocate, preemption: 0/6 nodes are available: 1 No preemption victims found for incoming pod, 5 Preemption is not helpful for scheduling."
60.1011,Pod,ADDED,eval-sanitize-2-r3-020-6k5gr,phase=Succeeded node=kind-worker2
60.1019,Job,ADDED,eval-sanitize-2-r3-021,
60.103,Pod,ADDED,eval-sanitize-2-r3-021-4gw4x,phase=Succeeded node=kind-worker2
60.1033,Event,ADDED,eval-sanitize-2-r1-091-k8x2x.18d3d10cff16be0e,"reason=FailedScheduling count=None msg=0/6 nodes are available: 1 c_wall violated: 2 conflicting context pair(s) with node memory, 5 node(s) had untolerated taint(s). no new claims to deallocate, preemption: 0/6 nodes are available: 1 No preemption victims found for incoming pod, 5 Preemption is not helpful for scheduling."
60.1035,Event,ADDED,eval-sanitize-2-r1-093-xbsd6.18d3d10d77b9daac,"reason=FailedScheduling count=None msg=0/6 nodes are available: 1 c_wall violated: 3 conflicting context pair(s) with node memory, 5 node(s) had untolerated taint(s). no new claims to deallocate, preemption: 0/6 nodes are available: 1 No preemption victims found for incoming pod, 5 Preemption is not helpful for scheduling."
60.1037,Event,ADDED,eval-sanitize-2-r1-093-xbsd6.18d3d10e211f62c8,"reason=FailedScheduling count=None msg=0/6 nodes are available: 1 c_wall violated: 1 conflicting context pair(s) with node memory, 5 node(s) had untolerated taint(s). no new claims to deallocate, preemption: 0/6 nodes are available: 1 No preemption victims found for incoming pod, 5 Preemption is not helpful for scheduling."
60.1045,Job,ADDED,eval-sanitize-2-r3-022,
60.1057,Pod,ADDED,eval-sanitize-2-r3-022-pbpff,phase=Succeeded node=kind-worker5
60.106,Event,ADDED,eval-sanitize-2-r1-093-xbsd6.18d3d10e2220e53c,"reason=FailedScheduling count=None msg=0/6 nodes are available: 1 c_wall violated: 1 conflicting context pair(s) with node memory, 5 node(s) had untolerated taint(s). no new claims to deallocate, preemption: 0/6 nodes are available: 1 No preemption victims found for incoming pod, 5 Preemption is not helpful for scheduling."
60.1063,Event,ADDED,eval-sanitize-2-r1-096-ht5nh.18d3d10e28e3c7a8,"reason=FailedScheduling count=None msg=0/6 nodes are available: 1 c_wall violated: 1 conflicting context pair(s) with node memory, 5 node(s) had untolerated taint(s). no new claims to deallocate, preemption: 0/6 nodes are available: 1 No preemption victims found for incoming pod, 5 Preemption is not helpful for scheduling."
60.1067,Event,ADDED,eval-sanitize-2-r1-096-ht5nh.18d3d10eca5f1ff8,"reason=FailedScheduling count=None msg=0/6 nodes are available: 1 c_wall violated: 1 conflicting context pair(s) with node memory, 5 node(s) had untolerated taint(s). no new claims to deallocate, preemption: 0/6 nodes are available: 1 No preemption victims found for incoming pod, 5 Preemption is not helpful for scheduling."
60.1078,Job,ADDED,eval-sanitize-2-r3-023,
60.1094,Pod,ADDED,eval-sanitize-2-r3-023-5wddd,phase=Succeeded node=kind-worker
60.1098,Event,ADDED,eval-sanitize-2-r1-097-pqgfw.18d3d10e652baa44,"reason=FailedScheduling count=None msg=0/6 nodes are available: 1 c_wall violated: 1 conflicting context pair(s) with node memory, 5 node(s) had untolerated taint(s). no new claims to deallocate, preemption: 0/6 nodes are available: 1 No preemption victims found for incoming pod, 5 Preemption is not helpful for scheduling."
60.1101,Event,ADDED,eval-sanitize-2-r1-099-m4nhq.18d3d10edbee227a,"reason=FailedScheduling count=None msg=0/6 nodes are available: 1 c_wall violated: 1 conflicting context pair(s) with node memory, 5 node(s) had untolerated taint(s). no new claims to deallocate, preemption: 0/6 nodes are available: 1 No preemption victims found for incoming pod, 5 Preemption is not helpful for scheduling."
60.1109,Job,ADDED,eval-sanitize-2-r3-024,
60.1134,Pod,ADDED,eval-sanitize-2-r3-024-hqtgk,phase=Succeeded node=kind-worker
60.1137,Event,ADDED,eval-sanitize-2-r1-099-m4nhq.18d3d10fc9a7713d,"reason=FailedScheduling count=None msg=0/6 nodes are available: 1 c_wall violated: 1 conflicting context pair(s) with node memory, 5 node(s) had untolerated taint(s). no new claims to deallocate, preemption: 0/6 nodes are available: 1 No preemption victims found for incoming pod, 5 Preemption is not helpful for scheduling."
60.1139,Event,ADDED,eval-sanitize-2-r3-000-d2spv.18d3d187759d5541,reason=Scheduled count=None msg=Successfully assigned compute/eval-sanitize-2-r3-000-d2spv to kind-worker2
60.1141,Event,ADDED,eval-sanitize-2-r3-000-d2spv.18d3d1878e88956d,"reason=Pulled count=1 msg=Container image ""busybox:musl"" already present on machine"
60.1143,Event,ADDED,eval-sanitize-2-r3-000-d2spv.18d3d1878f97c7f7,reason=Created count=1 msg=Created container: task
60.1155,Job,ADDED,eval-sanitize-2-r3-025,
60.1158,Event,ADDED,eval-sanitize-2-r3-000-d2spv.18d3d18793b1d6be,reason=Started count=1 msg=Started container task
60.116,Event,ADDED,eval-sanitize-2-r3-000.18d3d18774c6748a,reason=SuccessfulCreate count=1 msg=Created pod: eval-sanitize-2-r3-000-d2spv
60.1162,Event,ADDED,eval-sanitize-2-r3-000.18d3d18aa0bfe9cc,reason=Completed count=1 msg=Job completed
60.1163,Event,ADDED,eval-sanitize-2-r3-001-k9ccn.18d3d187af8682db,reason=Scheduled count=None msg=Successfully assigned compute/eval-sanitize-2-r3-001-k9ccn to kind-worker
60.1175,Pod,ADDED,eval-sanitize-2-r3-025-kpnrw,phase=Succeeded node=kind-worker5
60.1183,Job,ADDED,eval-sanitize-2-r3-026,
60.1186,Event,ADDED,eval-sanitize-2-r3-001-k9ccn.18d3d187c8ccdc85,"reason=Pulled count=1 msg=Container image ""busybox:musl"" already present on machine"
60.1188,Event,ADDED,eval-sanitize-2-r3-001-k9ccn.18d3d187c9ed94ff,reason=Created count=1 msg=Created container: task
60.1192,Event,ADDED,eval-sanitize-2-r3-001-k9ccn.18d3d187ce466455,reason=Started count=1 msg=Started container task
60.1203,Pod,ADDED,eval-sanitize-2-r3-026-sth58,phase=Succeeded node=kind-worker2
60.121,Job,ADDED,eval-sanitize-2-r3-027,
60.1214,Event,ADDED,eval-sanitize-2-r3-001.18d3d187af18eb42,reason=SuccessfulCreate count=1 msg=Created pod: eval-sanitize-2-r3-001-k9ccn
60.1216,Event,ADDED,eval-sanitize-2-r3-001.18d3d18b0badd239,reason=Completed count=1 msg=Job completed
60.1217,Event,ADDED,eval-sanitize-2-r3-002-bb2jg.18d3d187eb2269ac,reason=Scheduled count=None msg=Successfully assigned compute/eval-sanitize-2-r3-002-bb2jg to kind-worker4
60.1219,Event,ADDED,eval-sanitize-2-r3-002-bb2jg.18d3d188049156f4,"reason=Pulled count=1 msg=Container image ""busybox:musl"" already present on machine"
60.1221,Event,ADDED,eval-sanitize-2-r3-002-bb2jg.18d3d18805af25ca,reason=Created count=1 msg=Created container: task
60.1224,Event,ADDED,eval-sanitize-2-r3-002-bb2jg.18d3d18809fddf73,reason=Started count=1 msg=Started container task
60.1226,Event,ADDED,eval-sanitize-2-r3-002.18d3d187ea8bd7a0,reason=SuccessfulCreate count=1 msg=Created pod: eval-sanitize-2-r3-002-bb2jg
60.1227,Event,ADDED,eval-sanitize-2-r3-002.18d3d18b42c36748,reason=Completed count=1 msg=Job completed
60.1239,Pod,ADDED,eval-sanitize-2-r3-027-xnct6,phase=Succeeded node=kind-worker2
60.1248,Job,ADDED,eval-sanitize-2-r3-028,
60.125,Event,ADDED,eval-sanitize-2-r3-003-fg2r7.18d3d1882632d39a,reason=Scheduled count=None msg=Successfully assigned compute/eval-sanitize-2-r3-003-fg2r7 to kind-worker5
60.1252,Event,ADDED,eval-sanitize-2-r3-003-fg2r7.18d3d1884003c0a5,"reason=Pulled count=1 msg=Container image ""busybox:musl"" already present on machine"
60.1255,Event,ADDED,eval-sanitize-2-r3-003-fg2r7.18d3d188412bb976,reason=Created count=1 msg=Created container: task
60.1274,Pod,ADDED,eval-sanitize-2-r3-028-c58x6,phase=Succeeded node=kind-worker2
60.1279,Event,ADDED,eval-sanitize-2-r3-003-fg2r7.18d3d188454e10e7,reason=Started count=1 msg=Started container task
60.1282,Event,ADDED,eval-sanitize-2-r3-003.18d3d1882598e3c1,reason=SuccessfulCreate count=1 msg=Created pod: eval-sanitize-2-r3-003-fg2r7
60.1284,Event,ADDED,eval-sanitize-2-r3-003.18d3d18b7cb4214c,reason=Completed count=1 msg=Job completed
60.1286,Event,ADDED,eval-sanitize-2-r3-004-8tv8k.18d3d18862b19beb,reason=Scheduled count=None msg=Successfully assigned compute/eval-sanitize-2-r3-004-8tv8k to kind-worker3
60.1295,Job,ADDED,eval-sanitize-2-r3-029,
60.1298,Event,ADDED,eval-sanitize-2-r3-004-8tv8k.18d3d1887cb9a793,"reason=Pulled count=1 msg=Container image ""busybox:musl"" already present on machine"
60.13,Event,ADDED,eval-sanitize-2-r3-004-8tv8k.18d3d1887dc820ba,reason=Created count=1 msg=Created container: task
60.1302,Event,ADDED,eval-sanitize-2-r3-004-8tv8k.18d3d188818a4337,reason=Started count=1 msg=Started container task
60.1304,Event,ADDED,eval-sanitize-2-r3-004.18d3d18861cb7e76,reason=SuccessfulCreate count=1 msg=Created pod: eval-sanitize-2-r3-004-8tv8k
60.1318,Pod,ADDED,eval-sanitize-2-r3-029-nb4jp,phase=Succeeded node=kind-worker4
60.1327,Job,ADDED,eval-sanitize-2-r3-030,
60.1331,Event,ADDED,eval-sanitize-2-r3-004.18d3d18bb7905e18,reason=Completed count=1 msg=Job completed
60.1333,Event,ADDED,eval-sanitize-2-r3-005-mnkl6.18d3d1889ce75ae0,"reason=FailedScheduling count=None msg=0/6 nodes are available: 6 node(s) had untolerated taint(s). no new claims to deallocate, preemption: 0/6 nodes are available: 6 Preemption is not helpful for scheduling."
60.1335,Event,ADDED,eval-sanitize-2-r3-005-mnkl6.18d3d18a3fa31dbd,reason=Scheduled count=None msg=Successfully assigned compute/eval-sanitize-2-r3-005-mnkl6 to kind-worker2
60.1348,Pod,ADDED,eval-sanitize-2-r3-030-vs7t5,phase=Succeeded node=kind-worker4
60.1352,Event,ADDED,eval-sanitize-2-r3-005-mnkl6.18d3d18a59370ecb,"reason=Pulled count=1 msg=Container image ""busybox:musl"" already present on machine"
60.1354,Event,ADDED,eval-sanitize-2-r3-005-mnkl6.18d3d18a5aa40d06,reason=Created count=1 msg=Created container: task
60.1356,Event,ADDED,eval-sanitize-2-r3-005-mnkl6.18d3d18a5ce12124,reason=Started count=1 msg=Started container task
60.1358,Event,ADDED,eval-sanitize-2-r3-005.18d3d1889cdd2778,reason=SuccessfulCreate count=1 msg=Created pod: eval-sanitize-2-r3-005-mnkl6
60.137,Pod,ADDED,eval-sanitize-2-r3-031-rd6x9,phase=Succeeded node=kind-worker3
60.1378,Job,ADDED,eval-sanitize-2-r3-031,
60.1381,Event,ADDED,eval-sanitize-2-r3-005.18d3d18d6e25c11b,reason=Completed count=1 msg=Job completed
60.1383,Event,ADDED,eval-sanitize-2-r3-006-m98bf.18d3d188d8fca8b6,"reason=FailedScheduling count=None msg=0/6 nodes are available: 6 node(s) had untolerated taint(s). no new claims to deallocate, preemption: 0/6 nodes are available: 6 Preemption is not helpful for scheduling."
60.1385,Event,ADDED,eval-sanitize-2-r3-006-m98bf.18d3d18a401ec9c5,reason=Scheduled count=None msg=Successfully assigned compute/eval-sanitize-2-r3-006-m98bf to kind-worker2
60.1386,Event,ADDED,eval-sanitize-2-r3-006-m98bf.18d3d18a597cdc13,"reason=Pulled count=1 msg=Container image ""busybox:musl"" already present on machine"
60.1399,Pod,ADDED,eval-sanitize-2-r3-032-hc2dv,phase=Succeeded node=kind-worker4
60.1407,Job,ADDED,eval-sanitize-2-r3-032,
60.141,Event,ADDED,eval-sanitize-2-r3-006-m98bf.18d3d18a5b09666c,reason=Created count=1 msg=Created container: task
60.1412,Event,ADDED,eval-sanitize-2-r3-006-m98bf.18d3d18a5d293282,reason=Started count=1 msg=Started container task
60.1414,Event,ADDED,eval-sanitize-2-r3-006.18d3d188d8f0149a,reason=SuccessfulCreate count=1 msg=Created pod: eval-sanitize-2-r3-006-m98bf
60.1417,Event,ADDED,eval-sanitize-2-r3-006.18d3d18d6db82df1,reason=Completed count=1 msg=Job completed
60.142,Event,ADDED,eval-sanitize-2-r3-007-t9hwl.18d3d18914ac490d,"reason=FailedScheduling count=None msg=0/6 nodes are available: 6 node(s) had untolerated taint(s). no new claims to deallocate, preemption: 0/6 nodes are available: 6 Preemption is not helpful for scheduling."
60.1421,Event,ADDED,eval-sanitize-2-r3-007-t9hwl.18d3d18a40028289,"reason=FailedScheduling count=None msg=0/6 nodes are available: 1 c_wall violated: 2 conflicting context pair(s) with node memory, 5 node(s) had untolerated taint(s). no new claims to deallocate, preemption: 0/6 nodes are available: 1 No preemption victims found for incoming pod, 5 Preemption is not helpful for scheduling."
60.1423,Event,ADDED,eval-sanitize-2-r3-007-t9hwl.18d3d18a4308d6ac,"reason=FailedScheduling count=None msg=0/6 nodes are available: 1 c_wall violated: 2 conflicting context pair(s) with node memory, 5 node(s) had untolerated taint(s). no new claims to deallocate, preemption: 0/6 nodes are available: 1 No preemption victims found for incoming pod, 5 Preemption is not helpful for scheduling."
60.1425,Event,ADDED,eval-sanitize-2-r3-007-t9hwl.18d3d18ae0fac350,reason=Scheduled count=None msg=Successfully assigned compute/eval-sanitize-2-r3-007-t9hwl to kind-worker
60.1428,Event,ADDED,eval-sanitize-2-r3-007-t9hwl.18d3d18afef4f0cc,"reason=Pulled count=1 msg=Container image ""busybox:musl"" already present on machine"
60.143,Event,ADDED,eval-sanitize-2-r3-007-t9hwl.18d3d18b023c1142,reason=Created count=1 msg=Created container: task
60.1438,Job,ADDED,eval-sanitize-2-r3-033,
60.145,Pod,ADDED,eval-sanitize-2-r3-033-2l4qz,phase=Succeeded node=kind-worker3
60.1453,Event,ADDED,eval-sanitize-2-r3-007-t9hwl.18d3d18b0a1fa864,reason=Started count=1 msg=Started container task
60.1455,Event,ADDED,eval-sanitize-2-r3-007.18d3d189149eb890,reason=SuccessfulCreate count=1 msg=Created pod: eval-sanitize-2-r3-007-t9hwl
60.1457,Event,ADDED,eval-sanitize-2-r3-007.18d3d18e168102b3,reason=Completed count=1 msg=Job completed
60.1458,Event,ADDED,eval-sanitize-2-r3-008-7vg7g.18d3d1894fc2f2ff,"reason=FailedScheduling count=None msg=0/6 nodes are available: 6 node(s) had untolerated taint(s). no new claims to deallocate, preemption: 0/6 nodes are available: 6 Preemption is not helpful for scheduling."
60.1467,Job,ADDED,eval-sanitize-2-r3-034,
60.1478,Pod,ADDED,eval-sanitize-2-r3-034-f9cq9,phase=Succeeded node=kind-worker2
60.148,Event,ADDED,eval-sanitize-2-r3-008-7vg7g.18d3d18a40def6be,"reason=FailedScheduling count=None msg=0/6 nodes are available: 1 c_wall violated: 2 conflicting context pair(s) with node memory, 5 node(s) had untolerated taint(s). no new claims to deallocate, preemption: 0/6 nodes are available: 1 No preemption victims found for incoming pod, 5 Preemption is not helpful for scheduling."
60.1483,Event,ADDED,eval-sanitize-2-r3-008-7vg7g.18d3d18a433cb600,"reason=FailedScheduling count=None msg=0/6 nodes are available: 1 c_wall violated: 2 conflicting context pair(s) with node memory, 5 node(s) had untolerated taint(s). no new claims to deallocate, preemption: 0/6 nodes are available: 1 No preemption victims found for incoming pod, 5 Preemption is not helpful for scheduling."
60.1484,Event,ADDED,eval-sanitize-2-r3-008-7vg7g.18d3d18ae1352aa7,reason=Scheduled count=None msg=Successfully assigned compute/eval-sanitize-2-r3-008-7vg7g to kind-worker
60.1494,Job,ADDED,eval-sanitize-2-r3-035,
60.1497,Event,ADDED,eval-sanitize-2-r3-008-7vg7g.18d3d18afe949b32,"reason=Pulled count=1 msg=Container image ""busybox:musl"" already present on machine"
60.1499,Event,ADDED,eval-sanitize-2-r3-008-7vg7g.18d3d18b01d338f5,reason=Created count=1 msg=Created container: task
60.15,Event,ADDED,eval-sanitize-2-r3-008-7vg7g.18d3d18b093d4a8f,reason=Started count=1 msg=Started container task
60.1502,Event,ADDED,eval-sanitize-2-r3-008.18d3d1894fb87914,reason=SuccessfulCreate count=1 msg=Created pod: eval-sanitize-2-r3-008-7vg7g
60.1515,Job,ADDED,eval-sanitize-2-r3-036,
60.1518,Event,ADDED,eval-sanitize-2-r3-008.18d3d18e51266449,reason=Completed count=1 msg=Job completed
60.152,Event,ADDED,eval-sanitize-2-r3-009-j7dq8.18d3d1898b42fa65,"reason=FailedScheduling count=None msg=0/6 nodes are available: 6 node(s) had untolerated taint(s). no new claims to deallocate, preemption: 0/6 nodes are available: 6 Preemption is not helpful for scheduling."
60.1522,Event,ADDED,eval-sanitize-2-r3-009-j7dq8.18d3d18a4159ee93,"reason=FailedScheduling count=None msg=0/6 nodes are available: 1 c_wall violated: 2 conflicting context pair(s) with node memory, 5 node(s) had untolerated taint(s). no new claims to deallocate, preemption: 0/6 nodes are available: 1 No preemption victims found for incoming pod, 5 Preemption is not helpful for scheduling."
60.1534,Pod,ADDED,eval-sanitize-2-r3-035-6gkkd,phase=Succeeded node=kind-worker
60.1542,Job,ADDED,eval-sanitize-2-r3-037,
60.1545,Event,ADDED,eval-sanitize-2-r3-009-j7dq8.18d3d18a46906834,"reason=FailedScheduling count=None msg=0/6 nodes are available: 1 c_wall violated: 2 conflicting context pair(s) with node memory, 5 node(s) had untolerated taint(s). no new claims to deallocate, preemption: 0/6 nodes are available: 1 No preemption victims found for incoming pod, 5 Preemption is not helpful for scheduling."
60.1547,Event,ADDED,eval-sanitize-2-r3-009-j7dq8.18d3d18adffca3cf,reason=Scheduled count=None msg=Successfully assigned compute/eval-sanitize-2-r3-009-j7dq8 to kind-worker
60.1549,Event,ADDED,eval-sanitize-2-r3-009-j7dq8.18d3d18afc2f58e5,"reason=Pulled count=1 msg=Container image ""busybox:musl"" already present on machine"
60.1562,Pod,ADDED,eval-sanitize-2-r3-036-k2ckt,phase=Succeeded node=kind-worker2
60.157,Job,ADDED,eval-sanitize-2-r3-038,
60.1573,Event,ADDED,eval-sanitize-2-r3-009-j7dq8.18d3d18afd66f8c0,reason=Created count=1 msg=Created container: task
60.1575,Event,ADDED,eval-sanitize-2-r3-009-j7dq8.18d3d18affa7aff0,reason=Started count=1 msg=Started container task
60.1577,Event,ADDED,eval-sanitize-2-r3-009.18d3d1898b3b2333,reason=SuccessfulCreate count=1 msg=Created pod: eval-sanitize-2-r3-009-j7dq8
60.158,Event,ADDED,eval-sanitize-2-r3-009.18d3d18e14d17f92,reason=Completed count=1 msg=Job completed
60.1586,Event,ADDED,eval-sanitize-2-r3-010-c57dg.18d3d189c6b231e2,"reason=FailedScheduling count=None msg=0/6 nodes are available: 6 node(s) had untolerated taint(s). no new claims to deallocate, preemption: 0/6 nodes are available: 6 Preemption is not helpful for scheduling."
60.1589,Event,ADDED,eval-sanitize-2-r3-010-c57dg.18d3d18a41d9f11c,"reason=FailedScheduling count=None msg=0/6 nodes are available: 1 c_wall violated: 2 conflicting context pair(s) with node memory, 5 node(s) had untolerated taint(s). no new claims to deallocate, preemption: 0/6 nodes are available: 1 No preemption victims found for incoming pod, 5 Preemption is not helpful for scheduling."
60.1593,Event,ADDED,eval-sanitize-2-r3-010-c57dg.18d3d18a46cb4eda,"reason=FailedScheduling count=None msg=0/6 nodes are available: 1 c_wall violated: 2 conflicting context pair(s) with node memory, 5 node(s) had untolerated taint(s). no new claims to deallocate, preemption: 0/6 nodes are available: 1 No preemption victims found for incoming pod, 5 Preemption is not helpful for scheduling."
60.1605,Pod,ADDED,eval-sanitize-2-r3-037-9n9rh,phase=Succeeded node=kind-worker2
60.1613,Job,ADDED,eval-sanitize-2-r3-039,
60.1616,Event,ADDED,eval-sanitize-2-r3-010-c57dg.18d3d18ae0492907,reason=Scheduled count=None msg=Successfully assigned compute/eval-sanitize-2-r3-010-c57dg to kind-worker
60.1618,Event,ADDED,eval-sanitize-2-r3-010-c57dg.18d3d18afec4f609,"reason=Pulled count=1 msg=Container image ""busybox:musl"" already present on machine"
60.162,Event,ADDED,eval-sanitize-2-r3-010-c57dg.18d3d18b021561d5,reason=Created count=1 msg=Created container: task
60.1622,Event,ADDED,eval-sanitize-2-r3-010-c57dg.18d3d18b0a1ff6d9,reason=Started count=1 msg=Started container task
60.1633,Pod,ADDED,eval-sanitize-2-r3-038-bshss,phase=Succeeded node=kind-worker
60.1641,Job,ADDED,eval-sanitize-2-r3-040,
60.1644,Event,ADDED,eval-sanitize-2-r3-010.18d3d189c6a88fee,reason=SuccessfulCreate count=1 msg=Created pod: eval-sanitize-2-r3-010-c57dg
60.1646,Event,ADDED,eval-sanitize-2-r3-010.18d3d18e17fd215e,reason=Completed count=1 msg=Job completed
60.1648,Event,ADDED,eval-sanitize-2-r3-011-vt6dt.18d3d18a03191bc7,"reason=FailedScheduling count=None msg=0/6 nodes are available: 6 node(s) had untolerated taint(s). no new claims to deallocate, preemption: 0/6 nodes are available: 6 Preemption is not helpful for scheduling."
60.165,Event,ADDED,eval-sanitize-2-r3-011-vt6dt.18d3d18a425ca2a8,"reason=FailedScheduling count=None msg=0/6 nodes are available: 1 c_wall violated: 2 conflicting context pair(s) with node memory, 5 node(s) had untolerated taint(s). no new claims to deallocate, preemption: 0/6 nodes are available: 1 No preemption victims found for incoming pod, 5 Preemption is not helpful for scheduling."
60.1652,Event,ADDED,eval-sanitize-2-r3-011-vt6dt.18d3d18a477374fb,"reason=FailedScheduling count=None msg=0/6 nodes are available: 1 c_wall violated: 2 conflicting context pair(s) with node memory, 5 node(s) had untolerated taint(s). no new claims to deallocate, preemption: 0/6 nodes are available: 1 No preemption victims found for incoming pod, 5 Preemption is not helpful for scheduling."
60.1654,Event,ADDED,eval-sanitize-2-r3-011-vt6dt.18d3d18ae0ba0990,reason=Scheduled count=None msg=Successfully assigned compute/eval-sanitize-2-r3-011-vt6dt to kind-worker
60.1657,Event,ADDED,eval-sanitize-2-r3-011-vt6dt.18d3d18afe6dd6cc,"reason=Pulled count=1 msg=Container image ""busybox:musl"" already present on machine"
60.1659,Event,ADDED,eval-sanitize-2-r3-011-vt6dt.18d3d18b0189891b,reason=Created count=1 msg=Created container: task
60.1662,Event,ADDED,eval-sanitize-2-r3-011-vt6dt.18d3d18b058f8a72,reason=Started count=1 msg=Started container task
60.1663,Event,ADDED,eval-sanitize-2-r3-011.18d3d18a030ae6a5,reason=SuccessfulCreate count=1 msg=Created pod: eval-sanitize-2-r3-011-vt6dt
60.1676,Pod,ADDED,eval-sanitize-2-r3-039-gr78z,phase=Succeeded node=kind-worker
60.1683,Job,ADDED,eval-sanitize-2-r3-041,
60.1686,Event,ADDED,eval-sanitize-2-r3-011.18d3d18e157c390f,reason=Completed count=1 msg=Job completed
60.1688,Event,ADDED,eval-sanitize-2-r3-012-4v9kc.18d3d18a3e395b94,"reason=FailedScheduling count=None msg=0/6 nodes are available: 6 node(s) had untolerated taint(s). no new claims to deallocate, preemption: 0/6 nodes are available: 6 Preemption is not helpful for scheduling."
60.169,Event,ADDED,eval-sanitize-2-r3-012-4v9kc.18d3d18a434c59b6,reason=Scheduled count=None msg=Successfully assigned compute/eval-sanitize-2-r3-012-4v9kc to kind-worker2
60.1692,Event,ADDED,eval-sanitize-2-r3-012-4v9kc.18d3d18a5bb5c8e8,"reason=Pulled count=1 msg=Container image ""busybox:musl"" already present on machine"
60.1709,Event,ADDED,eval-sanitize-2-r3-012-4v9kc.18d3d18a5cf57257,reason=Created count=1 msg=Created container: task
60.1711,Event,ADDED,eval-sanitize-2-r3-012-4v9kc.18d3d18a5ef90e3c,reason=Started count=1 msg=Started container task
60.1713,Event,ADDED,eval-sanitize-2-r3-012.18d3d18a3e2ccb01,reason=SuccessfulCreate count=1 msg=Created pod: eval-sanitize-2-r3-012-4v9kc
60.1715,Event,ADDED,eval-sanitize-2-r3-012.18d3d18da9f98775,reason=Completed count=1 msg=Job completed
60.1723,Job,ADDED,eval-sanitize-2-r3-042,
60.1726,Pod,ADDED,eval-sanitize-2-r3-040-62m2q,phase=Succeeded node=kind-worker
60.1728,Event,ADDED,eval-sanitize-2-r3-013-cnzht.18d3d18a79a885c3,"reason=FailedScheduling count=None msg=0/6 nodes are available: 1 c_wall violated: 2 conflicting context pair(s) with node memory, 5 node(s) had untolerated taint(s). no new claims to deallocate, preemption: 0/6 nodes are available: 1 No preemption victims found for incoming pod, 5 Preemption is not helpful for scheduling."
60.173,Event,ADDED,eval-sanitize-2-r3-013-cnzht.18d3d18a7a338119,"reason=FailedScheduling count=None msg=0/6 nodes are available: 1 c_wall violated: 2 conflicting context pair(s) with node memory, 5 node(s) had untolerated taint(s). no new claims to deallocate, preemption: 0/6 nodes are available: 1 No preemption victims found for incoming pod, 5 Preemption is not helpful for scheduling."
60.1732,Event,ADDED,eval-sanitize-2-r3-013-cnzht.18d3d18ae073073e,reason=Scheduled count=None msg=Successfully assigned compute/eval-sanitize-2-r3-013-cnzht to kind-worker
60.1734,Event,ADDED,eval-sanitize-2-r3-013-cnzht.18d3d18afe1f444e,"reason=Pulled count=1 msg=Container image ""busybox:musl"" already present on machine"
60.1736,Event,ADDED,eval-sanitize-2-r3-013-cnzht.18d3d18b016bf79a,reason=Created count=1 msg=Created container: task
60.1738,Event,ADDED,eval-sanitize-2-r3-013-cnzht.18d3d18b05132f43,reason=Started count=1 msg=Started container task
60.1748,Job,ADDED,eval-sanitize-2-r3-043,
60.1751,Event,ADDED,eval-sanitize-2-r3-013.18d3d18a796a619a,reason=SuccessfulCreate count=1 msg=Created pod: eval-sanitize-2-r3-013-cnzht
60.1753,Event,ADDED,eval-sanitize-2-r3-013.18d3d18e15b55f2d,reason=Completed count=1 msg=Job completed
60.1755,Event,ADDED,eval-sanitize-2-r3-014-k55b8.18d3d18ab5df972a,reason=Scheduled count=None msg=Successfully assigned compute/eval-sanitize-2-r3-014-k55b8 to kind-worker2
60.1757,Event,ADDED,eval-sanitize-2-r3-014-k55b8.18d3d18ad3b5eafb,"reason=Pulled count=1 msg=Container image ""busybox:musl"" already present on machine"
60.1768,Pod,ADDED,eval-sanitize-2-r3-041-qffxl,phase=Succeeded node=kind-worker2
60.1776,Job,ADDED,eval-sanitize-2-r3-044,
60.1779,Event,ADDED,eval-sanitize-2-r3-014-k55b8.18d3d18ad4c23cfb,reason=Created count=1 msg=Created container: task
60.1781,Event,ADDED,eval-sanitize-2-r3-014-k55b8.18d3d18ad8dea7bf,reason=Started count=1 msg=Started container task
60.1783,Event,ADDED,eval-sanitize-2-r3-014.18d3d18ab55f0160,reason=SuccessfulCreate count=1 msg=Created pod: eval-sanitize-2-r3-014-k55b8
60.1785,Event,ADDED,eval-sanitize-2-r3-014.18d3d18de5d5f2a1,reason=Completed count=1 msg=Job completed
60.1801,Pod,ADDED,eval-sanitize-2-r3-042-krw95,phase=Succeeded node=kind-worker2
60.1817,Pod,ADDED,eval-sanitize-2-r3-043-rnsnf,phase=Succeeded node=kind-worker5
60.1825,Job,ADDED,eval-sanitize-2-r3-045,
60.1828,Event,ADDED,eval-sanitize-2-r3-015-9g8mh.18d3d18af1384695,reason=Scheduled count=None msg=Successfully assigned compute/eval-sanitize-2-r3-015-9g8mh to kind-worker
60.183,Event,ADDED,eval-sanitize-2-r3-015-9g8mh.18d3d18b0a75f46e,"reason=Pulled count=1 msg=Container image ""busybox:musl"" already present on machine"
60.1832,Event,ADDED,eval-sanitize-2-r3-015-9g8mh.18d3d18b0c19269f,reason=Created count=1 msg=Created container: task
60.1843,Pod,ADDED,eval-sanitize-2-r3-044-qjrs6,phase=Succeeded node=kind-worker5
60.1851,Job,ADDED,eval-sanitize-2-r3-046,
60.1853,Event,ADDED,eval-sanitize-2-r3-015-9g8mh.18d3d18b108a7360,reason=Started count=1 msg=Started container task
60.1855,Event,ADDED,eval-sanitize-2-r3-015.18d3d18af0bce632,reason=SuccessfulCreate count=1 msg=Created pod: eval-sanitize-2-r3-015-9g8mh
60.1857,Event,ADDED,eval-sanitize-2-r3-015.18d3d18e17bac219,reason=Completed count=1 msg=Job completed
60.1859,Event,ADDED,eval-sanitize-2-r3-016-4jb2m.18d3d18b2d5cfa3b,reason=Scheduled count=None msg=Successfully assigned compute/eval-sanitize-2-r3-016-4jb2m to kind-worker
60.1868,Job,ADDED,eval-sanitize-2-r3-047,
60.1871,Event,ADDED,eval-sanitize-2-r3-016-4jb2m.18d3d18b470b86cd,"reason=Pulled count=1 msg=Container image ""busybox:musl"" already present on machine"
60.1873,Event,ADDED,eval-sanitize-2-r3-016-4jb2m.18d3d18b48aff867,reason=Created count=1 msg=Created container: task
60.1875,Event,ADDED,eval-sanitize-2-r3-016-4jb2m.18d3d18b4c8c05ab,reason=Started count=1 msg=Started container task
60.1877,Event,ADDED,eval-sanitize-2-r3-016.18d3d18b2cd4f8a0,reason=SuccessfulCreate count=1 msg=Created pod: eval-sanitize-2-r3-016-4jb2m
60.1887,Pod,ADDED,eval-sanitize-2-r3-045-xr64m,phase=Succeeded node=kind-worker5
60.1894,Job,ADDED,eval-sanitize-2-r3-048,
60.1897,Event,ADDED,eval-sanitize-2-r3-016.18d3d18e8cea1038,reason=Completed count=1 msg=Job completed
60.1899,Event,ADDED,eval-sanitize-2-r3-017-98n66.18d3d18b6904c3c4,reason=Scheduled count=None msg=Successfully assigned compute/eval-sanitize-2-r3-017-98n66 to kind-worker4
60.1901,Event,ADDED,eval-sanitize-2-r3-017-98n66.18d3d18b831e9a19,"reason=Pulled count=1 msg=Container image ""busybox:musl"" already present on machine"
60.1911,Pod,ADDED,eval-sanitize-2-r3-046-k7wkf,phase=Succeeded node=kind-worker4
60.1919,Job,ADDED,eval-sanitize-2-r3-049,
60.1921,Event,ADDED,eval-sanitize-2-r3-017-98n66.18d3d18b844f48da,reason=Created count=1 msg=Created container: task
60.1924,Event,ADDED,eval-sanitize-2-r3-017-98n66.18d3d18b88b2b3b0,reason=Started count=1 msg=Started container task
60.1926,Event,ADDED,eval-sanitize-2-r3-017.18d3d18b681a74d2,reason=SuccessfulCreate count=1 msg=Created pod: eval-sanitize-2-r3-017-98n66
60.1928,Event,ADDED,eval-sanitize-2-r3-017.18d3d18ec2cb5ef3,reason=Completed count=1 msg=Job completed
60.193,Event,ADDED,eval-sanitize-2-r3-018-lhc4h.18d3d18ba4b5af83,reason=Scheduled count=None msg=Successfully assigned compute/eval-sanitize-2-r3-018-lhc4h to kind-worker5
60.1932,Event,ADDED,eval-sanitize-2-r3-018-lhc4h.18d3d18bbd7a0407,"reason=Pulled count=1 msg=Container image ""busybox:musl"" already present on machine"
60.1934,Event,ADDED,eval-sanitize-2-r3-018-lhc4h.18d3d18bbeb84aa3,reason=Created count=1 msg=Created container: task
60.1936,Event,ADDED,eval-sanitize-2-r3-018-lhc4h.18d3d18bc3708c59,reason=Started count=1 msg=Started container task
60.1942,Job,ADDED,eval-sanitize-2-r3-050,
60.1972,Pod,ADDED,eval-sanitize-2-r3-047-t6knr,phase=Succeeded node=kind-worker4
60.1976,Event,ADDED,eval-sanitize-2-r3-018.18d3d18ba40ca782,reason=SuccessfulCreate count=1 msg=Created pod: eval-sanitize-2-r3-018-lhc4h
60.1978,Event,ADDED,eval-sanitize-2-r3-018.18d3d18efc1f0c64,reason=Completed count=1 msg=Job completed
60.198,Event,ADDED,eval-sanitize-2-r3-019-rvslz.18d3d18bdf887156,reason=Scheduled count=None msg=Successfully assigned compute/eval-sanitize-2-r3-019-rvslz to kind-worker3
60.1981,Event,ADDED,eval-sanitize-2-r3-019-rvslz.18d3d18bf864681a,"reason=Pulled count=1 msg=Container image ""busybox:musl"" already present on machine"
60.1984,Event,ADDED,eval-sanitize-2-r3-019-rvslz.18d3d18bf9a2ed8b,reason=Created count=1 msg=Created container: task
60.1986,Event,ADDED,eval-sanitize-2-r3-019-rvslz.18d3d18bfba2785d,reason=Started count=1 msg=Started container task
60.1988,Event,ADDED,eval-sanitize-2-r3-019.18d3d18bdf1dc72d,reason=SuccessfulCreate count=1 msg=Created pod: eval-sanitize-2-r3-019-rvslz
60.1995,Job,ADDED,eval-sanitize-2-r3-051,
60.2006,Pod,ADDED,eval-sanitize-2-r3-048-m65n8,phase=Running node=kind-worker3
60.2009,Event,ADDED,eval-sanitize-2-r3-019.18d3d18f377e9f09,reason=Completed count=1 msg=Job completed
60.2011,Event,ADDED,eval-sanitize-2-r3-020-6k5gr.18d3d18c1bcbc9ac,"reason=FailedScheduling count=None msg=0/6 nodes are available: 6 node(s) had untolerated taint(s). no new claims to deallocate, preemption: 0/6 nodes are available: 6 Preemption is not helpful for scheduling."
60.2013,Event,ADDED,eval-sanitize-2-r3-020-6k5gr.18d3d18da52cd86a,reason=Scheduled count=None msg=Successfully assigned compute/eval-sanitize-2-r3-020-6k5gr to kind-worker2
60.2014,Event,ADDED,eval-sanitize-2-r3-020-6k5gr.18d3d18dbeb48c23,"reason=Pulled count=1 msg=Container image ""busybox:musl"" already present on machine"
60.2026,Event,ADDED,eval-sanitize-2-r3-020-6k5gr.18d3d18dc0230250,reason=Created count=1 msg=Created container: task
60.203,Event,ADDED,eval-sanitize-2-r3-020-6k5gr.18d3d18dc28346c2,reason=Started count=1 msg=Started container task
60.2033,Event,ADDED,eval-sanitize-2-r3-020.18d3d18c1bc0c8c1,reason=SuccessfulCreate count=1 msg=Created pod: eval-sanitize-2-r3-020-6k5gr
60.2035,Event,ADDED,eval-sanitize-2-r3-020.18d3d190b45f2359,reason=Completed count=1 msg=Job completed
60.2047,Pod,ADDED,eval-sanitize-2-r3-049-tdnps,phase=Running node=kind-worker2
60.205,Event,ADDED,eval-sanitize-2-r3-021-4gw4x.18d3d18c569f7095,"reason=FailedScheduling count=None msg=0/6 nodes are available: 6 node(s) had untolerated taint(s). no new claims to deallocate, preemption: 0/6 nodes are available: 6 Preemption is not helpful for scheduling."
60.2052,Event,ADDED,eval-sanitize-2-r3-021-4gw4x.18d3d18da5bd4747,reason=Scheduled count=None msg=Successfully assigned compute/eval-sanitize-2-r3-021-4gw4x to kind-worker2
60.2054,Event,ADDED,eval-sanitize-2-r3-021-4gw4x.18d3d18dbedd3646,"reason=Pulled count=1 msg=Container image ""busybox:musl"" already present on machine"
60.2056,Job,ADDED,eval-sanitize-2-r3-052,
60.2068,Pod,ADDED,eval-sanitize-2-r3-050-mkhrs,phase=Pending node=kind-worker5
60.2071,Event,ADDED,eval-sanitize-2-r3-021-4gw4x.18d3d18dc0586f4d,reason=Created count=1 msg=Created container: task
60.2073,Event,ADDED,eval-sanitize-2-r3-021-4gw4x.18d3d18dc2840a56,reason=Started count=1 msg=Started container task
60.2075,Event,ADDED,eval-sanitize-2-r3-021.18d3d18c5695cbf7,reason=SuccessfulCreate count=1 msg=Created pod: eval-sanitize-2-r3-021-4gw4x
60.2076,Event,ADDED,eval-sanitize-2-r3-021.18d3d190b462590a,reason=Completed count=1 msg=Job completed
60.2078,Event,ADDED,eval-sanitize-2-r3-022-pbpff.18d3d18c92a30cd2,"reason=FailedScheduling count=None msg=0/6 nodes are available: 6 node(s) had untolerated taint(s). no new claims to deallocate, preemption: 0/6 nodes are available: 6 Preemption is not helpful for scheduling."
60.2081,Event,ADDED,eval-sanitize-2-r3-022-pbpff.18d3d18da5a4cda5,"reason=FailedScheduling count=None msg=0/6 nodes are available: 1 c_wall violated: 2 conflicting context pair(s) with node memory, 5 node(s) had untolerated taint(s). no new claims to deallocate, preemption: 0/6 nodes are available: 1 No preemption victims found for incoming pod, 5 Preemption is not helpful for scheduling."
60.2083,Event,ADDED,eval-sanitize-2-r3-022-pbpff.18d3d18da9472646,"reason=FailedScheduling count=None msg=0/6 nodes are available: 1 c_wall violated: 2 conflicting context pair(s) with node memory, 5 node(s) had untolerated taint(s). no new claims to deallocate, preemption: 0/6 nodes are available: 1 No preemption victims found for incoming pod, 5 Preemption is not helpful for scheduling."
60.209,Job,ADDED,eval-sanitize-2-r3-053,
60.2093,Event,ADDED,eval-sanitize-2-r3-022-pbpff.18d3d18e540a11c3,"reason=FailedScheduling count=None msg=0/6 nodes are available: 1 c_wall violated: 1 conflicting context pair(s) with node memory, 5 node(s) had untolerated taint(s). no new claims to deallocate, preemption: 0/6 nodes are available: 1 No preemption victims found for incoming pod, 5 Preemption is not helpful for scheduling."
60.2095,Event,ADDED,eval-sanitize-2-r3-022-pbpff.18d3d18e5568bc19,"reason=FailedScheduling count=None msg=0/6 nodes are available: 1 c_wall violated: 1 conflicting context pair(s) with node memory, 5 node(s) had untolerated taint(s). no new claims to deallocate, preemption: 0/6 nodes are available: 1 No preemption victims found for incoming pod, 5 Preemption is not helpful for scheduling."
60.2097,Event,ADDED,eval-sanitize-2-r3-022-pbpff.18d3d18eb5152211,"reason=FailedScheduling count=None msg=0/6 nodes are available: 2 c_wall violated: 1 conflicting context pair(s) with node memory, 4 node(s) had untolerated taint(s). no new claims to deallocate, preemption: 0/6 nodes are available: 2 No preemption victims found for incoming pod, 4 Preemption is not helpful for scheduling."
60.2108,Pod,ADDED,eval-sanitize-2-r3-051-zfn8s,phase=Running node=kind-worker2
60.2114,Job,ADDED,eval-sanitize-2-r3-054,
60.2117,Event,ADDED,eval-sanitize-2-r3-022-pbpff.18d3d18ebb49f7f0,reason=Scheduled count=None msg=Successfully assigned compute/eval-sanitize-2-r3-022-pbpff to kind-worker5
60.2119,Event,ADDED,eval-sanitize-2-r3-022-pbpff.18d3d18ed3e68211,"reason=Pulled count=1 msg=Container image ""busybox:musl"" already present on machine"
60.2121,Event,ADDED,eval-sanitize-2-r3-022-pbpff.18d3d18ed514ed36,reason=Created count=1 msg=Created container: task
60.2134,Pod,ADDED,eval-sanitize-2-r3-052-qtqlf,phase=Running node=kind-worker2
60.2141,Job,ADDED,eval-sanitize-2-r3-055,
60.2152,Pod,ADDED,eval-sanitize-2-r3-053-bgzwf,phase=Running node=kind-worker2
60.2155,Event,ADDED,eval-sanitize-2-r3-022-pbpff.18d3d18ed701b5c1,reason=Started count=1 msg=Started container task
60.2157,Event,ADDED,eval-sanitize-2-r3-022.18d3d18c929897e5,reason=SuccessfulCreate count=1 msg=Created pod: eval-sanitize-2-r3-022-pbpff
60.2159,Event,ADDED,eval-sanitize-2-r3-022.18d3d192055f0da5,reason=Completed count=1 msg=Job completed
60.216,Event,ADDED,eval-sanitize-2-r3-023-5wddd.18d3d18ccdd43361,"reason=FailedScheduling count=None msg=0/6 nodes are available: 6 node(s) had untolerated taint(s). no new claims to deallocate, preemption: 0/6 nodes are available: 6 Preemption is not helpful for scheduling."
60.2167,Job,ADDED,eval-sanitize-2-r3-056,
60.2179,Pod,ADDED,eval-sanitize-2-r3-054-r6q26,phase=Running node=kind-worker
60.2182,Event,ADDED,eval-sanitize-2-r3-023-5wddd.18d3d18da65d50eb,"reason=FailedScheduling count=None msg=0/6 nodes are available: 1 c_wall violated: 2 conflicting context pair(s) with node memory, 5 node(s) had untolerated taint(s). no new claims to deallocate, preemption: 0/6 nodes are available: 1 No preemption victims found for incoming pod, 5 Preemption is not helpful for scheduling."
60.2186,Event,ADDED,eval-sanitize-2-r3-023-5wddd.18d3d18da981f306,"reason=FailedScheduling count=None msg=0/6 nodes are available: 1 c_wall violated: 2 conflicting context pair(s) with node memory, 5 node(s) had untolerated taint(s). no new claims to deallocate, preemption: 0/6 nodes are available: 1 No preemption victims found for incoming pod, 5 Preemption is not helpful for scheduling."
60.2188,Event,ADDED,eval-sanitize-2-r3-023-5wddd.18d3d18e5318ea30,reason=Scheduled count=None msg=Successfully assigned compute/eval-sanitize-2-r3-023-5wddd to kind-worker
60.2197,Job,ADDED,eval-sanitize-2-r3-057,
60.2213,Pod,ADDED,eval-sanitize-2-r3-055-pgs46,phase=Running node=kind-worker
60.2215,Event,ADDED,eval-sanitize-2-r3-023-5wddd.18d3d18e6cfbbb81,"reason=Pulled count=1 msg=Container image ""busybox:musl"" already present on machine"
60.2218,Event,ADDED,eval-sanitize-2-r3-023-5wddd.18d3d18e6e986ec3,reason=Created count=1 msg=Created container: task
60.2221,Event,ADDED,eval-sanitize-2-r3-023-5wddd.18d3d18e70f85f42,reason=Started count=1 msg=Started container task
60.2224,Event,ADDED,eval-sanitize-2-r3-023.18d3d18ccdcd0764,reason=SuccessfulCreate count=1 msg=Created pod: eval-sanitize-2-r3-023-5wddd
60.2231,Job,ADDED,eval-sanitize-2-r3-058,
60.2248,Pod,ADDED,eval-sanitize-2-r3-056-jjtbf,phase=Pending node=kind-worker5
60.2252,Event,ADDED,eval-sanitize-2-r3-023.18d3d19196a6a211,reason=Completed count=1 msg=Job completed
60.2253,Event,ADDED,eval-sanitize-2-r3-024-hqtgk.18d3d18d093ce913,"reason=FailedScheduling count=None msg=0/6 nodes are available: 6 node(s) had untolerated taint(s). no new claims to deallocate, preemption: 0/6 nodes are available: 6 Preemption is not helpful for scheduling."
60.2255,Event,ADDED,eval-sanitize-2-r3-024-hqtgk.18d3d18da7b90767,"reason=FailedScheduling count=None msg=0/6 nodes are available: 1 c_wall violated: 2 conflicting context pair(s) with node memory, 5 node(s) had untolerated taint(s). no new claims to deallocate, preemption: 0/6 nodes are available: 1 No preemption victims found for incoming pod, 5 Preemption is not helpful for scheduling."
60.2261,Job,ADDED,eval-sanitize-2-r3-059,
60.2268,Pod,ADDED,eval-sanitize-2-r3-057-rhvv7,phase=Pending node=None
60.2272,Event,ADDED,eval-sanitize-2-r3-024-hqtgk.18d3d18da9c02ef3,"reason=FailedScheduling count=None msg=0/6 nodes are available: 1 c_wall violated: 2 conflicting context pair(s) with node memory, 5 node(s) had untolerated taint(s). no new claims to deallocate, preemption: 0/6 nodes are available: 1 No preemption victims found for incoming pod, 5 Preemption is not helpful for scheduling."
60.2273,Event,ADDED,eval-sanitize-2-r3-024-hqtgk.18d3d18e539a47e9,reason=Scheduled count=None msg=Successfully assigned compute/eval-sanitize-2-r3-024-hqtgk to kind-worker
60.2275,Event,ADDED,eval-sanitize-2-r3-024-hqtgk.18d3d18e6d58f6cf,"reason=Pulled count=1 msg=Container image ""busybox:musl"" already present on machine"
60.2277,Event,ADDED,eval-sanitize-2-r3-024-hqtgk.18d3d18e6f126538,reason=Created count=1 msg=Created container: task
60.2285,Job,ADDED,eval-sanitize-2-r3-060,
60.2289,Event,ADDED,eval-sanitize-2-r3-024-hqtgk.18d3d18e71451f67,reason=Started count=1 msg=Started container task
60.2292,Event,ADDED,eval-sanitize-2-r3-024.18d3d18d09344166,reason=SuccessfulCreate count=1 msg=Created pod: eval-sanitize-2-r3-024-hqtgk
60.2294,Event,ADDED,eval-sanitize-2-r3-024.18d3d191963da724,reason=Completed count=1 msg=Job completed
60.2302,Pod,ADDED,eval-sanitize-2-r3-058-sqvr7,phase=Pending node=None
60.2309,Job,MODIFIED,eval-sanitize-2-r3-060,
60.2312,Event,ADDED,eval-sanitize-2-r3-025-kpnrw.18d3d18d44e1d778,"reason=FailedScheduling count=None msg=0/6 nodes are available: 6 node(s) had untolerated taint(s). no new claims to deallocate, preemption: 0/6 nodes are available: 6 Preemption is not helpful for scheduling."
60.2314,Event,ADDED,eval-sanitize-2-r3-025-kpnrw.18d3d18da88d9058,"reason=FailedScheduling count=None msg=0/6 nodes are available: 1 c_wall violated: 2 conflicting context pair(s) with node memory, 5 node(s) had untolerated taint(s). no new claims to deallocate, preemption: 0/6 nodes are available: 1 No preemption victims found for incoming pod, 5 Preemption is not helpful for scheduling."
60.2316,Event,ADDED,eval-sanitize-2-r3-025-kpnrw.18d3d18da9f6d52f,"reason=FailedScheduling count=None msg=0/6 nodes are available: 1 c_wall violated: 2 conflicting context pair(s) with node memory, 5 node(s) had untolerated taint(s). no new claims to deallocate, preemption: 0/6 nodes are available: 1 No preemption victims found for incoming pod, 5 Preemption is not helpful for scheduling."
60.2328,Pod,ADDED,eval-sanitize-2-r3-059-dw2kg,phase=Pending node=kind-worker5
60.2335,Job,MODIFIED,eval-sanitize-2-r3-059,
60.2342,Pod,ADDED,eval-sanitize-2-r3-060-58r7q,phase=Pending node=None
60.2344,Event,ADDED,eval-sanitize-2-r3-025-kpnrw.18d3d18e5337bca1,"reason=FailedScheduling count=None msg=0/6 nodes are available: 1 c_wall violated: 1 conflicting context pair(s) with node memory, 5 node(s) had untolerated taint(s). no new claims to deallocate, preemption: 0/6 nodes are available: 1 No preemption victims found for incoming pod, 5 Preemption is not helpful for scheduling."
60.2347,Event,ADDED,eval-sanitize-2-r3-025-kpnrw.18d3d18e553e6c36,"reason=FailedScheduling count=None msg=0/6 nodes are available: 1 c_wall violated: 1 conflicting context pair(s) with node memory, 5 node(s) had untolerated taint(s). no new claims to deallocate, preemption: 0/6 nodes are available: 1 No preemption victims found for incoming pod, 5 Preemption is not helpful for scheduling."
60.235,Event,ADDED,eval-sanitize-2-r3-025-kpnrw.18d3d18eb05fdfab,"reason=FailedScheduling count=None msg=0/6 nodes are available: 2 c_wall violated: 1 conflicting context pair(s) with node memory, 4 node(s) had untolerated taint(s). no new claims to deallocate, preemption: 0/6 nodes are available: 2 No preemption victims found for incoming pod, 4 Preemption is not helpful for scheduling."
60.2352,Event,ADDED,eval-sanitize-2-r3-025-kpnrw.18d3d18ec0e6e62a,reason=Scheduled count=None msg=Successfully assigned compute/eval-sanitize-2-r3-025-kpnrw to kind-worker5
60.2355,Event,ADDED,eval-sanitize-2-r3-025-kpnrw.18d3d18ed83cc68d,"reason=Pulled count=1 msg=Container image ""busybox:musl"" already present on machine"
60.2357,Event,ADDED,eval-sanitize-2-r3-025-kpnrw.18d3d18ed9399c69,reason=Created count=1 msg=Created container: task
60.236,Event,ADDED,eval-sanitize-2-r3-025-kpnrw.18d3d18edb2dd9bf,reason=Started count=1 msg=Started container task
60.2362,Event,ADDED,eval-sanitize-2-r3-025.18d3d18d44d36518,reason=SuccessfulCreate count=1 msg=Created pod: eval-sanitize-2-r3-025-kpnrw
60.2365,Event,ADDED,eval-sanitize-2-r3-025.18d3d192057abe25,reason=Completed count=1 msg=Job completed
60.2367,Event,ADDED,eval-sanitize-2-r3-026-sth58.18d3d18d805ca1f6,"reason=FailedScheduling count=None msg=0/6 nodes are available: 6 node(s) had untolerated taint(s). no new claims to deallocate, preemption: 0/6 nodes are available: 6 Preemption is not helpful for scheduling."
60.2369,Event,ADDED,eval-sanitize-2-r3-026-sth58.18d3d18da96ffba4,reason=Scheduled count=None msg=Successfully assigned compute/eval-sanitize-2-r3-026-sth58 to kind-worker2
60.2372,Event,ADDED,eval-sanitize-2-r3-026-sth58.18d3d18dc1406ea3,"reason=Pulled count=1 msg=Container image ""busybox:musl"" already present on machine"
60.2374,Event,ADDED,eval-sanitize-2-r3-026-sth58.18d3d18dc27eff02,reason=Created count=1 msg=Created container: task
60.2377,Event,ADDED,eval-sanitize-2-r3-026-sth58.18d3d18dc4780311,reason=Started count=1 msg=Started container task
60.2384,Job,MODIFIED,eval-sanitize-2-r3-059,
60.2388,Event,ADDED,eval-sanitize-2-r3-026.18d3d18d80528ff1,reason=SuccessfulCreate count=1 msg=Created pod: eval-sanitize-2-r3-026-sth58
60.2391,Event,ADDED,eval-sanitize-2-r3-026.18d3d190efd60494,reason=Completed count=1 msg=Job completed
60.2393,Event,ADDED,eval-sanitize-2-r3-027-xnct6.18d3d18dbcd6a28f,reason=Scheduled count=None msg=Successfully assigned compute/eval-sanitize-2-r3-027-xnct6 to kind-worker2
60.2395,Event,ADDED,eval-sanitize-2-r3-027-xnct6.18d3d18dd6a42162,"reason=Pulled count=1 msg=Container image ""busybox:musl"" already present on machine"
60.2407,Pod,MODIFIED,eval-sanitize-2-r3-060-58r7q,phase=Pending node=kind-worker5
60.2411,Event,ADDED,eval-sanitize-2-r3-027-xnct6.18d3d18dd7c04f63,reason=Created count=1 msg=Created container: task
60.2414,Event,ADDED,eval-sanitize-2-r3-027-xnct6.18d3d18ddc03c2f6,reason=Started count=1 msg=Started container task
60.2417,Event,ADDED,eval-sanitize-2-r3-027.18d3d18dbc24379f,reason=SuccessfulCreate count=1 msg=Created pod: eval-sanitize-2-r3-027-xnct6
60.2419,Event,ADDED,eval-sanitize-2-r3-027.18d3d190b4611ce8,reason=Completed count=1 msg=Job completed
60.2423,Event,ADDED,eval-sanitize-2-r3-028-c58x6.18d3d18df84ddad4,reason=Scheduled count=None msg=Successfully assigned compute/eval-sanitize-2-r3-028-c58x6 to kind-worker2
60.2425,Event,ADDED,eval-sanitize-2-r3-028-c58x6.18d3d18e11a0dc50,"reason=Pulled count=1 msg=Container image ""busybox:musl"" already present on machine"
60.2427,Event,ADDED,eval-sanitize-2-r3-028-c58x6.18d3d18e12dbcf98,reason=Created count=1 msg=Created container: task
60.2439,Pod,MODIFIED,eval-sanitize-2-r3-060-58r7q,phase=Pending node=kind-worker5
60.2442,Event,ADDED,eval-sanitize-2-r3-028-c58x6.18d3d18e1c53a0e2,reason=Started count=1 msg=Started container task
60.2445,Event,ADDED,eval-sanitize-2-r3-028.18d3d18df7ba621f,reason=SuccessfulCreate count=1 msg=Created pod: eval-sanitize-2-r3-028-c58x6
60.2447,Event,ADDED,eval-sanitize-2-r3-028.18d3d1912c05c2bf,reason=Completed count=1 msg=Job completed
60.2449,Event,ADDED,eval-sanitize-2-r3-029-nb4jp.18d3d18e33e34f3f,"reason=FailedScheduling count=None msg=0/6 nodes are available: 6 node(s) had untolerated taint(s). no new claims to deallocate, preemption: 0/6 nodes are available: 6 Preemption is not helpful for scheduling."
60.2452,Event,ADDED,eval-sanitize-2-r3-029-nb4jp.18d3d18e54ad9f01,"reason=FailedScheduling count=None msg=0/6 nodes are available: 1 c_wall violated: 2 conflicting context pair(s) with node memory, 5 node(s) had untolerated taint(s). no new claims to deallocate, preemption: 0/6 nodes are available: 1 No preemption victims found for incoming pod, 5 Preemption is not helpful for scheduling."
60.2455,Event,ADDED,eval-sanitize-2-r3-029-nb4jp.18d3d18e559421c0,"reason=FailedScheduling count=None msg=0/6 nodes are available: 1 c_wall violated: 2 conflicting context pair(s) with node memory, 5 node(s) had untolerated taint(s). no new claims to deallocate, preemption: 0/6 nodes are available: 1 No preemption victims found for incoming pod, 5 Preemption is not helpful for scheduling."
60.2456,Event,ADDED,eval-sanitize-2-r3-029-nb4jp.18d3d18ea9e23b6b,reason=Scheduled count=None msg=Successfully assigned compute/eval-sanitize-2-r3-029-nb4jp to kind-worker4
60.2459,Event,ADDED,eval-sanitize-2-r3-029-nb4jp.18d3d18ec7e0b719,"reason=Pulled count=1 msg=Container image ""busybox:musl"" already present on machine"
60.2461,Event,ADDED,eval-sanitize-2-r3-029-nb4jp.18d3d18ec9ce07bd,reason=Created count=1 msg=Created container: task
60.2463,Event,ADDED,eval-sanitize-2-r3-029-nb4jp.18d3d18ecd9750e1,reason=Started count=1 msg=Started container task
60.2465,Event,ADDED,eval-sanitize-2-r3-029.18d3d18e33da0c36,reason=SuccessfulCreate count=1 msg=Created pod: eval-sanitize-2-r3-029-nb4jp
60.2468,Event,ADDED,eval-sanitize-2-r3-029.18d3d19207ef3ad1,reason=Completed count=1 msg=Job completed
60.247,Event,ADDED,eval-sanitize-2-r3-030-vs7t5.18d3d18e6f7b7d64,"reason=FailedScheduling count=None msg=0/6 nodes are available: 1 c_wall violated: 2 conflicting context pair(s) with node memory, 5 node(s) had untolerated taint(s). no new claims to deallocate, preemption: 0/6 nodes are available: 1 No preemption victims found for incoming pod, 5 Preemption is not helpful for scheduling."
60.2472,Event,ADDED,eval-sanitize-2-r3-030-vs7t5.18d3d18e701a26fd,"reason=FailedScheduling count=None msg=0/6 nodes are available: 1 c_wall violated: 2 conflicting context pair(s) with node memory, 5 node(s) had untolerated taint(s). no new claims to deallocate, preemption: 0/6 nodes are available: 1 No preemption victims found for incoming pod, 5 Preemption is not helpful for scheduling."
60.2475,Event,ADDED,eval-sanitize-2-r3-030-vs7t5.18d3d18ea961d70c,reason=Scheduled count=None msg=Successfully assigned compute/eval-sanitize-2-r3-030-vs7t5 to kind-worker4
60.2477,Event,ADDED,eval-sanitize-2-r3-030-vs7t5.18d3d18ec7cb02a3,"reason=Pulled count=1 msg=Container image ""busybox:musl"" already present on machine"
60.2479,Event,ADDED,eval-sanitize-2-r3-030-vs7t5.18d3d18ec95907bc,reason=Created count=1 msg=Created container: task
60.2481,Event,ADDED,eval-sanitize-2-r3-030-vs7t5.18d3d18ecd44986d,reason=Started count=1 msg=Started container task
60.2485,Event,ADDED,eval-sanitize-2-r3-030.18d3d18e6f312a96,reason=SuccessfulCreate count=1 msg=Created pod: eval-sanitize-2-r3-030-vs7t5
60.2487,Event,ADDED,eval-sanitize-2-r3-030.18d3d19207e15f3f,reason=Completed count=1 msg=Job completed
60.2489,Event,ADDED,eval-sanitize-2-r3-031-rd6x9.18d3d18eaecf63d8,"reason=FailedScheduling count=None msg=0/6 nodes are available: 2 c_wall violated: 1 conflicting context pair(s) with node memory, 4 node(s) had untolerated taint(s). no new claims to deallocate, preemption: 0/6 nodes are available: 2 No preemption victims found for incoming pod, 4 Preemption is not helpful for scheduling."
60.2492,Event,ADDED,eval-sanitize-2-r3-031-rd6x9.18d3d18eb4be1a70,"reason=FailedScheduling count=None msg=0/6 nodes are available: 2 c_wall violated: 1 conflicting context pair(s) with node memory, 4 node(s) had untolerated taint(s). no new claims to deallocate, preemption: 0/6 nodes are available: 2 No preemption victims found for incoming pod, 4 Preemption is not helpful for scheduling."
60.2495,Event,ADDED,eval-sanitize-2-r3-031-rd6x9.18d3d18ec6b79fe2,"reason=FailedScheduling count=None msg=0/6 nodes are available: 3 c_wall violated: 1 conflicting context pair(s) with node memory, 3 node(s) had untolerated taint(s). no new claims to deallocate, preemption: 0/6 nodes are available: 3 No preemption victims found for incoming pod, 3 Preemption is not helpful for scheduling."
60.2497,Event,ADDED,eval-sanitize-2-r3-031-rd6x9.18d3d18ecda77940,"reason=FailedScheduling count=None msg=0/6 nodes are available: 2 c_wall violated: 1 conflicting context pair(s) with node memory, 4 node(s) had untolerated taint(s). no new claims to deallocate, preemption: 0/6 nodes are available: 2 No preemption victims found for incoming pod, 4 Preemption is not helpful for scheduling."
60.2499,Event,ADDED,eval-sanitize-2-r3-031-rd6x9.18d3d18ee307baea,reason=Scheduled count=None msg=Successfully assigned compute/eval-sanitize-2-r3-031-rd6x9 to kind-worker3
60.2501,Event,ADDED,eval-sanitize-2-r3-031-rd6x9.18d3d18efbe9bd5c,"reason=Pulled count=1 msg=Container image ""busybox:musl"" already present on machine"
60.2503,Event,ADDED,eval-sanitize-2-r3-031-rd6x9.18d3d18efd780867,reason=Created count=1 msg=Created container: task
60.2506,Event,ADDED,eval-sanitize-2-r3-031-rd6x9.18d3d18f0177efa1,reason=Started count=1 msg=Started container task
60.2513,Event,ADDED,eval-sanitize-2-r3-031.18d3d18eaadc5272,reason=SuccessfulCreate count=1 msg=Created pod: eval-sanitize-2-r3-031-rd6x9
60.2515,Event,ADDED,eval-sanitize-2-r3-031.18d3d192411c0840,reason=Completed count=1 msg=Job completed
60.2517,Event,ADDED,eval-sanitize-2-r3-032-hc2dv.18d3d18ee7a2bb95,reason=Scheduled count=None msg=Successfully assigned compute/eval-sanitize-2-r3-032-hc2dv to kind-worker4
60.2521,Event,ADDED,eval-sanitize-2-r3-032-hc2dv.18d3d18f01040574,"reason=Pulled count=1 msg=Container image ""busybox:musl"" already present on machine"
60.2523,Event,ADDED,eval-sanitize-2-r3-032-hc2dv.18d3d18f0221adb3,reason=Created count=1 msg=Created container: task
60.2524,Event,ADDED,eval-sanitize-2-r3-032-hc2dv.18d3d18f05891a04,reason=Started count=1 msg=Started container task
60.2526,Event,ADDED,eval-sanitize-2-r3-032.18d3d18ee62a0093,reason=SuccessfulCreate count=1 msg=Created pod: eval-sanitize-2-r3-032-hc2dv
60.2529,Event,ADDED,eval-sanitize-2-r3-032.18d3d192084b9c66,reason=Completed count=1 msg=Job completed
60.2531,Event,ADDED,eval-sanitize-2-r3-033-2l4qz.18d3d18f23090ef7,reason=Scheduled count=None msg=Successfully assigned compute/eval-sanitize-2-r3-033-2l4qz to kind-worker3
60.2533,Event,ADDED,eval-sanitize-2-r3-033-2l4qz.18d3d18f3bd111f3,"reason=Pulled count=1 msg=Container image ""busybox:musl"" already present on machine"
60.2535,Event,ADDED,eval-sanitize-2-r3-033-2l4qz.18d3d18f3d00d19f,reason=Created count=1 msg=Created container: task
60.2538,Event,ADDED,eval-sanitize-2-r3-033-2l4qz.18d3d18f40efaceb,reason=Started count=1 msg=Started container task
60.254,Event,ADDED,eval-sanitize-2-r3-033.18d3d18f21c30773,reason=SuccessfulCreate count=1 msg=Created pod: eval-sanitize-2-r3-033-2l4qz
60.2542,Event,ADDED,eval-sanitize-2-r3-033.18d3d1927c1fa212,reason=Completed count=1 msg=Job completed
60.2544,Event,ADDED,eval-sanitize-2-r3-034-f9cq9.18d3d18f5d4e3b14,"reason=FailedScheduling count=None msg=0/6 nodes are available: 6 node(s) had untolerated taint(s). no new claims to deallocate, preemption: 0/6 nodes are available: 6 Preemption is not helpful for scheduling."
60.2546,Event,ADDED,eval-sanitize-2-r3-034-f9cq9.18d3d1911355b782,reason=Scheduled count=None msg=Successfully assigned compute/eval-sanitize-2-r3-034-f9cq9 to kind-worker2
60.2548,Event,ADDED,eval-sanitize-2-r3-034-f9cq9.18d3d1912d15bba0,"reason=Pulled count=1 msg=Container image ""busybox:musl"" already present on machine"
60.255,Event,ADDED,eval-sanitize-2-r3-034-f9cq9.18d3d1912e877c94,reason=Created count=1 msg=Created container: task
60.2553,Event,ADDED,eval-sanitize-2-r3-034-f9cq9.18d3d19135cd6ccb,reason=Started count=1 msg=Started container task
60.2555,Event,ADDED,eval-sanitize-2-r3-034.18d3d18f5d41de2a,reason=SuccessfulCreate count=1 msg=Created pod: eval-sanitize-2-r3-034-f9cq9
60.2557,Event,ADDED,eval-sanitize-2-r3-034.18d3d19470bdb46d,reason=Completed count=1 msg=Job completed
60.256,Event,ADDED,eval-sanitize-2-r3-035-6gkkd.18d3d18f990c4f18,"reason=FailedScheduling count=None msg=0/6 nodes are available: 6 node(s) had untolerated taint(s). no new claims to deallocate, preemption: 0/6 nodes are available: 6 Preemption is not helpful for scheduling."
60.2562,Event,ADDED,eval-sanitize-2-r3-035-6gkkd.18d3d19113778243,"reason=FailedScheduling count=None msg=0/6 nodes are available: 1 c_wall violated: 1 conflicting context pair(s) with node memory, 5 node(s) had untolerated taint(s). no new claims to deallocate, preemption: 0/6 nodes are available: 1 No preemption victims found for incoming pod, 5 Preemption is not helpful for scheduling."
60.2564,Event,ADDED,eval-sanitize-2-r3-035-6gkkd.18d3d19119a12f07,"reason=FailedScheduling count=None msg=0/6 nodes are available: 1 c_wall violated: 1 conflicting context pair(s) with node memory, 5 node(s) had untolerated taint(s). no new claims to deallocate, preemption: 0/6 nodes are available: 1 No preemption victims found for incoming pod, 5 Preemption is not helpful for scheduling."
60.2566,Event,ADDED,eval-sanitize-2-r3-035-6gkkd.18d3d191459f1e83,reason=Scheduled count=None msg=Successfully assigned compute/eval-sanitize-2-r3-035-6gkkd to kind-worker
60.257,Event,ADDED,eval-sanitize-2-r3-035-6gkkd.18d3d19164b6728d,"reason=Pulled count=1 msg=Container image ""busybox:musl"" already present on machine"
60.2572,Event,ADDED,eval-sanitize-2-r3-035-6gkkd.18d3d19167ab269f,reason=Created count=1 msg=Created container: task
60.2574,Event,ADDED,eval-sanitize-2-r3-035-6gkkd.18d3d1916ba9464a,reason=Started count=1 msg=Started container task
60.2577,Event,ADDED,eval-sanitize-2-r3-035.18d3d18f99025470,reason=SuccessfulCreate count=1 msg=Created pod: eval-sanitize-2-r3-035-6gkkd
60.2579,Event,ADDED,eval-sanitize-2-r3-035.18d3d1949f29eaf4,reason=Completed count=1 msg=Job completed
60.258,Event,ADDED,eval-sanitize-2-r3-036-k2ckt.18d3d18fd4e7976d,"reason=FailedScheduling count=None msg=0/6 nodes are available: 6 node(s) had untolerated taint(s). no new claims to deallocate, preemption: 0/6 nodes are available: 6 Preemption is not helpful for scheduling."
60.2582,Event,ADDED,eval-sanitize-2-r3-036-k2ckt.18d3d19114696ca7,reason=Scheduled count=None msg=Successfully assigned compute/eval-sanitize-2-r3-036-k2ckt to kind-worker2
60.2585,Event,ADDED,eval-sanitize-2-r3-036-k2ckt.18d3d191328539b9,"reason=Pulled count=1 msg=Container image ""busybox:musl"" already present on machine"
60.2587,Event,ADDED,eval-sanitize-2-r3-036-k2ckt.18d3d19133fe91f1,reason=Created count=1 msg=Created container: task
60.2589,Event,ADDED,eval-sanitize-2-r3-036-k2ckt.18d3d19135f2801c,reason=Started count=1 msg=Started container task
60.2591,Event,ADDED,eval-sanitize-2-r3-036.18d3d18fd4dc6aa5,reason=SuccessfulCreate count=1 msg=Created pod: eval-sanitize-2-r3-036-k2ckt
60.2593,Event,ADDED,eval-sanitize-2-r3-036.18d3d19471c1712e,reason=Completed count=1 msg=Job completed
60.2596,Event,ADDED,eval-sanitize-2-r3-037-9n9rh.18d3d190105c0cbb,"reason=FailedScheduling count=None msg=0/6 nodes are available: 6 node(s) had untolerated taint(s). no new claims to deallocate, preemption: 0/6 nodes are available: 6 Preemption is not helpful for scheduling."
60.2597,Event,ADDED,eval-sanitize-2-r3-037-9n9rh.18d3d191147b6906,reason=Scheduled count=None msg=Successfully assigned compute/eval-sanitize-2-r3-037-9n9rh to kind-worker2
60.26,Event,ADDED,eval-sanitize-2-r3-037-9n9rh.18d3d191325f1ee7,"reason=Pulled count=1 msg=Container image ""busybox:musl"" already present on machine"
60.2602,Event,ADDED,eval-sanitize-2-r3-037-9n9rh.18d3d19133b07167,reason=Created count=1 msg=Created container: task
60.2604,Event,ADDED,eval-sanitize-2-r3-037-9n9rh.18d3d19135cd6ccb,reason=Started count=1 msg=Started container task
60.2606,Event,ADDED,eval-sanitize-2-r3-037.18d3d190104f229f,reason=SuccessfulCreate count=1 msg=Created pod: eval-sanitize-2-r3-037-9n9rh
60.261,Event,ADDED,eval-sanitize-2-r3-037.18d3d194701e870d,reason=Completed count=1 msg=Job completed
60.2612,Event,ADDED,eval-sanitize-2-r3-038-bshss.18d3d1904baca8b5,"reason=FailedScheduling count=None msg=0/6 nodes are available: 6 node(s) had untolerated taint(s). no new claims to deallocate, preemption: 0/6 nodes are available: 6 Preemption is not helpful for scheduling."
60.2613,Event,ADDED,eval-sanitize-2-r3-038-bshss.18d3d19114749e62,"reason=FailedScheduling count=None msg=0/6 nodes are available: 1 c_wall violated: 2 conflicting context pair(s) with node memory, 5 node(s) had untolerated taint(s). no new claims to deallocate, preemption: 0/6 nodes are available: 1 No preemption victims found for incoming pod, 5 Preemption is not helpful for scheduling."
60.2618,Event,ADDED,eval-sanitize-2-r3-038-bshss.18d3d19119e49fd4,"reason=FailedScheduling count=None msg=0/6 nodes are available: 1 c_wall violated: 2 conflicting context pair(s) with node memory, 5 node(s) had untolerated taint(s). no new claims to deallocate, preemption: 0/6 nodes are available: 1 No preemption victims found for incoming pod, 5 Preemption is not helpful for scheduling."
60.262,Event,ADDED,eval-sanitize-2-r3-038-bshss.18d3d1914aa372b8,reason=Scheduled count=None msg=Successfully assigned compute/eval-sanitize-2-r3-038-bshss to kind-worker
60.2622,Event,ADDED,eval-sanitize-2-r3-038-bshss.18d3d19164e300f5,"reason=Pulled count=1 msg=Container image ""busybox:musl"" already present on machine"
60.2624,Event,ADDED,eval-sanitize-2-r3-038-bshss.18d3d19168053797,reason=Created count=1 msg=Created container: task
60.2627,Event,ADDED,eval-sanitize-2-r3-038-bshss.18d3d1916ba93852,reason=Started count=1 msg=Started container task
60.2629,Event,ADDED,eval-sanitize-2-r3-038.18d3d1904ba0529c,reason=SuccessfulCreate count=1 msg=Created pod: eval-sanitize-2-r3-038-bshss
60.2631,Event,ADDED,eval-sanitize-2-r3-038.18d3d1949fd5fa28,reason=Completed count=1 msg=Job completed
60.2634,Event,ADDED,eval-sanitize-2-r3-039-gr78z.18d3d19087592f6d,"reason=FailedScheduling count=None msg=0/6 nodes are available: 6 node(s) had untolerated taint(s). no new claims to deallocate, preemption: 0/6 nodes are available: 6 Preemption is not helpful for scheduling."
60.2636,Event,ADDED,eval-sanitize-2-r3-039-gr78z.18d3d19115572210,"reason=FailedScheduling count=None msg=0/6 nodes are available: 1 c_wall violated: 2 conflicting context pair(s) with node memory, 5 node(s) had untolerated taint(s). no new claims to deallocate, preemption: 0/6 nodes are available: 1 No preemption victims found for incoming pod, 5 Preemption is not helpful for scheduling."
60.2638,Event,ADDED,eval-sanitize-2-r3-039-gr78z.18d3d1911a8bebe3,"reason=FailedScheduling count=None msg=0/6 nodes are available: 1 c_wall violated: 2 conflicting context pair(s) with node memory, 5 node(s) had untolerated taint(s). no new claims to deallocate, preemption: 0/6 nodes are available: 1 No preemption victims found for incoming pod, 5 Preemption is not helpful for scheduling."
60.2641,Event,ADDED,eval-sanitize-2-r3-039-gr78z.18d3d19144a2c25c,reason=Scheduled count=None msg=Successfully assigned compute/eval-sanitize-2-r3-039-gr78z to kind-worker
60.2643,Event,ADDED,eval-sanitize-2-r3-039-gr78z.18d3d191648d49f6,"reason=Pulled count=1 msg=Container image ""busybox:musl"" already present on machine"
60.2645,Event,ADDED,eval-sanitize-2-r3-039-gr78z.18d3d19167cebf6b,reason=Created count=1 msg=Created container: task
60.2647,Event,ADDED,eval-sanitize-2-r3-039-gr78z.18d3d1916ba97483,reason=Started count=1 msg=Started container task
60.265,Event,ADDED,eval-sanitize-2-r3-039.18d3d190874ede20,reason=SuccessfulCreate count=1 msg=Created pod: eval-sanitize-2-r3-039-gr78z
60.2652,Event,ADDED,eval-sanitize-2-r3-039.18d3d1949f7751d3,reason=Completed count=1 msg=Job completed
60.2654,Event,ADDED,eval-sanitize-2-r3-040-62m2q.18d3d190c3ec2020,"reason=FailedScheduling count=None msg=0/6 nodes are available: 6 node(s) had untolerated taint(s). no new claims to deallocate, preemption: 0/6 nodes are available: 6 Preemption is not helpful for scheduling."
60.2656,Event,ADDED,eval-sanitize-2-r3-040-62m2q.18d3d19118ecda68,"reason=FailedScheduling count=None msg=0/6 nodes are available: 1 c_wall violated: 1 conflicting context pair(s) with node memory, 5 node(s) had untolerated taint(s). no new claims to deallocate, preemption: 0/6 nodes are available: 1 No preemption victims found for incoming pod, 5 Preemption is not helpful for scheduling."
60.2659,Event,ADDED,eval-sanitize-2-r3-040-62m2q.18d3d1911ab6cc12,"reason=FailedScheduling count=None msg=0/6 nodes are available: 1 c_wall violated: 1 conflicting context pair(s) with node memory, 5 node(s) had untolerated taint(s). no new claims to deallocate, preemption: 0/6 nodes are available: 1 No preemption victims found for incoming pod, 5 Preemption is not helpful for scheduling."
60.2661,Event,ADDED,eval-sanitize-2-r3-040-62m2q.18d3d191450aad0b,reason=Scheduled count=None msg=Successfully assigned compute/eval-sanitize-2-r3-040-62m2q to kind-worker
60.2663,Event,ADDED,eval-sanitize-2-r3-040-62m2q.18d3d191647455f3,"reason=Pulled count=1 msg=Container image ""busybox:musl"" already present on machine"
60.2666,Event,ADDED,eval-sanitize-2-r3-040-62m2q.18d3d19166bb00c8,reason=Created count=1 msg=Created container: task
60.2668,Event,ADDED,eval-sanitize-2-r3-040-62m2q.18d3d1916ba5b4d0,reason=Started count=1 msg=Started container task
60.267,Event,ADDED,eval-sanitize-2-r3-040.18d3d190c3e030b6,reason=SuccessfulCreate count=1 msg=Created pod: eval-sanitize-2-r3-040-62m2q
60.2672,Event,ADDED,eval-sanitize-2-r3-040.18d3d194a059f8b0,reason=Completed count=1 msg=Job completed
60.2675,Event,ADDED,eval-sanitize-2-r3-041-qffxl.18d3d190fff893ba,"reason=FailedScheduling count=None msg=0/6 nodes are available: 6 node(s) had untolerated taint(s). no new claims to deallocate, preemption: 0/6 nodes are available: 6 Preemption is not helpful for scheduling."
60.2677,Event,ADDED,eval-sanitize-2-r3-041-qffxl.18d3d19119c00ce7,reason=Scheduled count=None msg=Successfully assigned compute/eval-sanitize-2-r3-041-qffxl to kind-worker2
60.2679,Event,ADDED,eval-sanitize-2-r3-041-qffxl.18d3d19136748c11,"reason=Pulled count=1 msg=Container image ""busybox:musl"" already present on machine"
60.2682,Event,ADDED,eval-sanitize-2-r3-041-qffxl.18d3d19137a3055e,reason=Created count=1 msg=Created container: task
60.2684,Event,ADDED,eval-sanitize-2-r3-041-qffxl.18d3d1913c39e2b3,reason=Started count=1 msg=Started container task
60.2686,Event,ADDED,eval-sanitize-2-r3-041.18d3d190fff00e55,reason=SuccessfulCreate count=1 msg=Created pod: eval-sanitize-2-r3-041-qffxl
60.2688,Event,ADDED,eval-sanitize-2-r3-041.18d3d194725f9c0a,reason=Completed count=1 msg=Job completed
60.2692,Event,ADDED,eval-sanitize-2-r3-042-krw95.18d3d1913a82b8bd,reason=Scheduled count=None msg=Successfully assigned compute/eval-sanitize-2-r3-042-krw95 to kind-worker2
60.2694,Event,ADDED,eval-sanitize-2-r3-042-krw95.18d3d191546c6250,"reason=Pulled count=1 msg=Container image ""busybox:musl"" already present on machine"
60.2695,Event,ADDED,eval-sanitize-2-r3-042-krw95.18d3d191559de2e4,reason=Created count=1 msg=Created container: task
60.2699,Event,ADDED,eval-sanitize-2-r3-042-krw95.18d3d191579c5dc7,reason=Started count=1 msg=Started container task
60.2701,Event,ADDED,eval-sanitize-2-r3-042.18d3d19139ff553a,reason=SuccessfulCreate count=1 msg=Created pod: eval-sanitize-2-r3-042-krw95
60.2703,Event,ADDED,eval-sanitize-2-r3-042.18d3d194703b9560,reason=Completed count=1 msg=Job completed
60.2705,Event,ADDED,eval-sanitize-2-r3-043-rnsnf.18d3d19176e3b7c4,"reason=FailedScheduling count=None msg=0/6 nodes are available: 2 c_wall violated: 1 conflicting context pair(s) with node memory, 4 node(s) had untolerated taint(s). no new claims to deallocate, preemption: 0/6 nodes are available: 2 No preemption victims found for incoming pod, 4 Preemption is not helpful for scheduling."
60.2708,Event,ADDED,eval-sanitize-2-r3-043-rnsnf.18d3d19177838b10,"reason=FailedScheduling count=None msg=0/6 nodes are available: 2 c_wall violated: 1 conflicting context pair(s) with node memory, 4 node(s) had untolerated taint(s). no new claims to deallocate, preemption: 0/6 nodes are available: 2 No preemption victims found for incoming pod, 4 Preemption is not helpful for scheduling."
60.271,Event,ADDED,eval-sanitize-2-r3-043-rnsnf.18d3d1918f35e61e,"reason=FailedScheduling count=None msg=0/6 nodes are available: 1 c_wall violated: 1 conflicting context pair(s) with node memory, 5 node(s) had untolerated taint(s). no new claims to deallocate, preemption: 0/6 nodes are available: 1 No preemption victims found for incoming pod, 5 Preemption is not helpful for scheduling."
60.2714,Event,ADDED,eval-sanitize-2-r3-043-rnsnf.18d3d191a8e99ad8,reason=Scheduled count=None msg=Successfully assigned compute/eval-sanitize-2-r3-043-rnsnf to kind-worker5
60.2716,Event,ADDED,eval-sanitize-2-r3-043-rnsnf.18d3d191c2a304c2,"reason=Pulled count=1 msg=Container image ""busybox:musl"" already present on machine"
60.2719,Event,ADDED,eval-sanitize-2-r3-043-rnsnf.18d3d191c3cbc710,reason=Created count=1 msg=Created container: task
60.272,Event,ADDED,eval-sanitize-2-r3-043-rnsnf.18d3d191c5c76738,reason=Started count=1 msg=Started container task
60.2724,Event,ADDED,eval-sanitize-2-r3-043.18d3d19176717a90,reason=SuccessfulCreate count=1 msg=Created pod: eval-sanitize-2-r3-043-rnsnf
60.2731,Event,ADDED,eval-sanitize-2-r3-043.18d3d194d19519b2,reason=Completed count=1 msg=Job completed
60.2733,Event,ADDED,eval-sanitize-2-r3-044-qjrs6.18d3d191b1e7b3d9,reason=Scheduled count=None msg=Successfully assigned compute/eval-sanitize-2-r3-044-qjrs6 to kind-worker5
60.2735,Event,ADDED,eval-sanitize-2-r3-044-qjrs6.18d3d191ca9a75be,"reason=Pulled count=1 msg=Container image ""busybox:musl"" already present on machine"
60.2738,Event,ADDED,eval-sanitize-2-r3-044-qjrs6.18d3d191cc0e07bc,reason=Created count=1 msg=Created container: task
60.274,Event,ADDED,eval-sanitize-2-r3-044-qjrs6.18d3d191d019f6a9,reason=Started count=1 msg=Started container task
60.2742,Event,ADDED,eval-sanitize-2-r3-044.18d3d191b1376b35,reason=SuccessfulCreate count=1 msg=Created pod: eval-sanitize-2-r3-044-qjrs6
60.2744,Event,ADDED,eval-sanitize-2-r3-044.18d3d1950d7af70a,reason=Completed count=1 msg=Job completed
60.275,Event,ADDED,eval-sanitize-2-r3-045-xr64m.18d3d191ed3760fc,reason=Scheduled count=None msg=Successfully assigned compute/eval-sanitize-2-r3-045-xr64m to kind-worker5
60.2753,Event,ADDED,eval-sanitize-2-r3-045-xr64m.18d3d1920bced1c5,"reason=Pulled count=1 msg=Container image ""busybox:musl"" already present on machine"
60.2755,Event,ADDED,eval-sanitize-2-r3-045-xr64m.18d3d1920ce4d7cc,reason=Created count=1 msg=Created container: task
60.2757,Event,ADDED,eval-sanitize-2-r3-045-xr64m.18d3d19211489a79,reason=Started count=1 msg=Started container task
60.276,Event,ADDED,eval-sanitize-2-r3-045.18d3d191ecb748e5,reason=SuccessfulCreate count=1 msg=Created pod: eval-sanitize-2-r3-045-xr64m
60.2762,Event,ADDED,eval-sanitize-2-r3-045.18d3d195499dd849,reason=Completed count=1 msg=Job completed
60.2766,Event,ADDED,eval-sanitize-2-r3-046-k7wkf.18d3d19229bd52ed,reason=Scheduled count=None msg=Successfully assigned compute/eval-sanitize-2-r3-046-k7wkf to kind-worker4
60.2771,Event,ADDED,eval-sanitize-2-r3-046-k7wkf.18d3d19246990c04,"reason=Pulled count=1 msg=Container image ""busybox:musl"" already present on machine"
60.2774,Event,ADDED,eval-sanitize-2-r3-046-k7wkf.18d3d19247ab4bd1,reason=Created count=1 msg=Created container: task
60.2776,Event,ADDED,eval-sanitize-2-r3-046-k7wkf.18d3d1924c6814aa,reason=Started count=1 msg=Started container task
60.2778,Event,ADDED,eval-sanitize-2-r3-046.18d3d192293cad11,reason=SuccessfulCreate count=1 msg=Created pod: eval-sanitize-2-r3-046-k7wkf
60.2781,Event,ADDED,eval-sanitize-2-r3-047-t6knr.18d3d19265d1e95c,reason=Scheduled count=None msg=Successfully assigned compute/eval-sanitize-2-r3-047-t6knr to kind-worker4
60.2783,Event,ADDED,eval-sanitize-2-r3-047-t6knr.18d3d1927f84ef40,"reason=Pulled count=1 msg=Container image ""busybox:musl"" already present on machine"
60.2785,Event,ADDED,eval-sanitize-2-r3-047-t6knr.18d3d19280999eb5,reason=Created count=1 msg=Created container: task
60.2786,Event,ADDED,eval-sanitize-2-r3-047-t6knr.18d3d1928463c262,reason=Started count=1 msg=Started container task
60.2789,Event,ADDED,eval-sanitize-2-r3-047.18d3d19264a93460,reason=SuccessfulCreate count=1 msg=Created pod: eval-sanitize-2-r3-047-t6knr
60.2791,Event,ADDED,eval-sanitize-2-r3-048-m65n8.18d3d192a04f2a74,reason=Scheduled count=None msg=Successfully assigned compute/eval-sanitize-2-r3-048-m65n8 to kind-worker3
60.2793,Event,ADDED,eval-sanitize-2-r3-048-m65n8.18d3d192b95c1fc2,"reason=Pulled count=1 msg=Container image ""busybox:musl"" already present on machine"
60.2795,Event,ADDED,eval-sanitize-2-r3-048-m65n8.18d3d192ba9f7d8e,reason=Created count=1 msg=Created container: task
60.2797,Event,ADDED,eval-sanitize-2-r3-048-m65n8.18d3d192be7c160e,reason=Started count=1 msg=Started container task
60.28,Event,ADDED,eval-sanitize-2-r3-048.18d3d1929fe72d69,reason=SuccessfulCreate count=1 msg=Created pod: eval-sanitize-2-r3-048-m65n8
60.2802,Event,ADDED,eval-sanitize-2-r3-049-tdnps.18d3d192db7976b5,"reason=FailedScheduling count=None msg=0/6 nodes are available: 6 node(s) had untolerated taint(s). no new claims to deallocate, preemption: 0/6 nodes are available: 6 Preemption is not helpful for scheduling."
60.2805,Event,ADDED,eval-sanitize-2-r3-049-tdnps.18d3d194189930bd,reason=Scheduled count=None msg=Successfully assigned compute/eval-sanitize-2-r3-049-tdnps to kind-worker2
60.2807,Event,ADDED,eval-sanitize-2-r3-049-tdnps.18d3d19439c34955,"reason=Pulled count=1 msg=Container image ""busybox:musl"" already present on machine"
60.2809,Event,ADDED,eval-sanitize-2-r3-049-tdnps.18d3d1943bd2f1f2,reason=Created count=1 msg=Created container: task
60.2812,Event,ADDED,eval-sanitize-2-r3-049-tdnps.18d3d1943eba2ac6,reason=Started count=1 msg=Started container task
60.2814,Event,ADDED,eval-sanitize-2-r3-049.18d3d192db6b21c5,reason=SuccessfulCreate count=1 msg=Created pod: eval-sanitize-2-r3-049-tdnps
60.2816,Event,ADDED,eval-sanitize-2-r3-050-mkhrs.18d3d1931737fe37,"reason=FailedScheduling count=None msg=0/6 nodes are available: 6 node(s) had untolerated taint(s). no new claims to deallocate, preemption: 0/6 nodes are available: 6 Preemption is not helpful for scheduling."
60.2818,Event,ADDED,eval-sanitize-2-r3-050-mkhrs.18d3d19418d04a77,"reason=FailedScheduling count=None msg=0/6 nodes are available: 1 c_wall violated: 1 conflicting context pair(s) with node memory, 5 node(s) had untolerated taint(s). no new claims to deallocate, preemption: 0/6 nodes are available: 1 No preemption victims found for incoming pod, 5 Preemption is not helpful for scheduling."
60.2821,Event,ADDED,eval-sanitize-2-r3-050-mkhrs.18d3d1941a8fa0f5,"reason=FailedScheduling count=None msg=0/6 nodes are available: 1 c_wall violated: 2 conflicting context pair(s) with node memory, 5 node(s) had untolerated taint(s). no new claims to deallocate, preemption: 0/6 nodes are available: 1 No preemption victims found for incoming pod, 5 Preemption is not helpful for scheduling."
60.2823,Event,ADDED,eval-sanitize-2-r3-050-mkhrs.18d3d1941bc04f92,"reason=FailedScheduling count=None msg=0/6 nodes are available: 1 c_wall violated: 2 conflicting context pair(s) with node memory, 5 node(s) had untolerated taint(s). no new claims to deallocate, preemption: 0/6 nodes are available: 1 No preemption victims found for incoming pod, 5 Preemption is not helpful for scheduling."
60.2824,Event,ADDED,eval-sanitize-2-r3-050-mkhrs.18d3d194577f23e9,"reason=FailedScheduling count=None msg=0/6 nodes are available: 2 c_wall violated: 2 conflicting context pair(s) with node memory, 4 node(s) had untolerated taint(s). no new claims to deallocate, preemption: 0/6 nodes are available: 2 No preemption victims found for incoming pod, 4 Preemption is not helpful for scheduling."
60.2828,Event,ADDED,eval-sanitize-2-r3-050-mkhrs.18d3d1945b67e40d,"reason=FailedScheduling count=None msg=0/6 nodes are available: 2 c_wall violated: 2 conflicting context pair(s) with node memory, 4 node(s) had untolerated taint(s). no new claims to deallocate, preemption: 0/6 nodes are available: 2 No preemption victims found for incoming pod, 4 Preemption is not helpful for scheduling."
60.283,Event,ADDED,eval-sanitize-2-r3-050-mkhrs.18d3d194992e0e02,"reason=FailedScheduling count=None msg=0/6 nodes are available: 1 c_wall violated: 2 conflicting context pair(s) with node memory, 5 node(s) had untolerated taint(s). no new claims to deallocate, preemption: 0/6 nodes are available: 1 No preemption victims found for incoming pod, 5 Preemption is not helpful for scheduling."
60.2832,Event,ADDED,eval-sanitize-2-r3-050-mkhrs.18d3d1953d07427c,reason=Scheduled count=None msg=Successfully assigned compute/eval-sanitize-2-r3-050-mkhrs to kind-worker5
60.2835,Event,ADDED,eval-sanitize-2-r3-050-mkhrs.18d3d19556c12f45,"reason=Pulled count=1 msg=Container image ""busybox:musl"" already present on machine"
60.2837,Event,ADDED,eval-sanitize-2-r3-050-mkhrs.18d3d195585d9315,reason=Created count=1 msg=Created container: task
60.2839,Event,ADDED,eval-sanitize-2-r3-050-mkhrs.18d3d1955cfcfb97,reason=Started count=1 msg=Started container task
60.2841,Event,ADDED,eval-sanitize-2-r3-050.18d3d193172c4a2e,reason=SuccessfulCreate count=1 msg=Created pod: eval-sanitize-2-r3-050-mkhrs
60.2843,Event,ADDED,eval-sanitize-2-r3-051-zfn8s.18d3d19352957fac,"reason=FailedScheduling count=None msg=0/6 nodes are available: 6 node(s) had untolerated taint(s). no new claims to deallocate, preemption: 0/6 nodes are available: 6 Preemption is not helpful for scheduling."
60.2845,Event,ADDED,eval-sanitize-2-r3-051-zfn8s.18d3d194199a5c13,reason=Scheduled count=None msg=Successfully assigned compute/eval-sanitize-2-r3-051-zfn8s to kind-worker2
60.2847,Event,ADDED,eval-sanitize-2-r3-051-zfn8s.18d3d19438158d92,"reason=Pulled count=1 msg=Container image ""busybox:musl"" already present on machine"
60.285,Event,ADDED,eval-sanitize-2-r3-051-zfn8s.18d3d194392eba10,reason=Created count=1 msg=Created container: task
60.2852,Event,ADDED,eval-sanitize-2-r3-051-zfn8s.18d3d1943dc27f58,reason=Started count=1 msg=Started container task
60.2854,Event,ADDED,eval-sanitize-2-r3-051.18d3d193528cbaf8,reason=SuccessfulCreate count=1 msg=Created pod: eval-sanitize-2-r3-051-zfn8s
60.2856,Event,ADDED,eval-sanitize-2-r3-052-qtqlf.18d3d1938e5d87b9,"reason=FailedScheduling count=None msg=0/6 nodes are available: 6 node(s) had untolerated taint(s). no new claims to deallocate, preemption: 0/6 nodes are available: 6 Preemption is not helpful for scheduling."
60.2859,Event,ADDED,eval-sanitize-2-r3-052-qtqlf.18d3d19419c15452,reason=Scheduled count=None msg=Successfully assigned compute/eval-sanitize-2-r3-052-qtqlf to kind-worker2
60.286,Event,ADDED,eval-sanitize-2-r3-052-qtqlf.18d3d1943a8f7841,"reason=Pulled count=1 msg=Container image ""busybox:musl"" already present on machine"
60.2862,Event,ADDED,eval-sanitize-2-r3-052-qtqlf.18d3d1943d039e3b,reason=Created count=1 msg=Created container: task
60.2865,Event,ADDED,eval-sanitize-2-r3-052-qtqlf.18d3d1943f824ac1,reason=Started count=1 msg=Started container task
60.2867,Event,ADDED,eval-sanitize-2-r3-052.18d3d1938e5524d5,reason=SuccessfulCreate count=1 msg=Created pod: eval-sanitize-2-r3-052-qtqlf
60.2869,Event,ADDED,eval-sanitize-2-r3-053-bgzwf.18d3d193ca4c03dc,"reason=FailedScheduling count=None msg=0/6 nodes are available: 6 node(s) had untolerated taint(s). no new claims to deallocate, preemption: 0/6 nodes are available: 6 Preemption is not helpful for scheduling."
60.2871,Event,ADDED,eval-sanitize-2-r3-053-bgzwf.18d3d1941a0b2b0b,reason=Scheduled count=None msg=Successfully assigned compute/eval-sanitize-2-r3-053-bgzwf to kind-worker2
60.2873,Event,ADDED,eval-sanitize-2-r3-053-bgzwf.18d3d1943a771a28,"reason=Pulled count=1 msg=Container image ""busybox:musl"" already present on machine"
60.2876,Event,ADDED,eval-sanitize-2-r3-053-bgzwf.18d3d1943cb1122b,reason=Created count=1 msg=Created container: task
60.2878,Event,ADDED,eval-sanitize-2-r3-053-bgzwf.18d3d1943f82315d,reason=Started count=1 msg=Started container task
60.2881,Event,ADDED,eval-sanitize-2-r3-053.18d3d193ca483690,reason=SuccessfulCreate count=1 msg=Created pod: eval-sanitize-2-r3-053-bgzwf
60.2883,Event,ADDED,eval-sanitize-2-r3-054-r6q26.18d3d19405cc347c,"reason=FailedScheduling count=None msg=0/6 nodes are available: 6 node(s) had untolerated taint(s). no new claims to deallocate, preemption: 0/6 nodes are available: 6 Preemption is not helpful for scheduling."
60.2884,Event,ADDED,eval-sanitize-2-r3-054-r6q26.18d3d19419c4aca4,"reason=FailedScheduling count=None msg=0/6 nodes are available: 1 c_wall violated: 1 conflicting context pair(s) with node memory, 5 node(s) had untolerated taint(s). no new claims to deallocate, preemption: 0/6 nodes are available: 1 No preemption victims found for incoming pod, 5 Preemption is not helpful for scheduling."
60.2886,Event,ADDED,eval-sanitize-2-r3-054-r6q26.18d3d1941b908847,"reason=FailedScheduling count=None msg=0/6 nodes are available: 1 c_wall violated: 1 conflicting context pair(s) with node memory, 5 node(s) had untolerated taint(s). no new claims to deallocate, preemption: 0/6 nodes are available: 1 No preemption victims found for incoming pod, 5 Preemption is not helpful for scheduling."
60.2889,Event,ADDED,eval-sanitize-2-r3-054-r6q26.18d3d19453c78375,reason=Scheduled count=None msg=Successfully assigned compute/eval-sanitize-2-r3-054-r6q26 to kind-worker
60.2891,Event,ADDED,eval-sanitize-2-r3-054-r6q26.18d3d1946ca80a24,"reason=Pulled count=1 msg=Container image ""busybox:musl"" already present on machine"
60.2893,Event,ADDED,eval-sanitize-2-r3-054-r6q26.18d3d1946dc52562,reason=Created count=1 msg=Created container: task
60.2897,Event,ADDED,eval-sanitize-2-r3-054-r6q26.18d3d1947002e343,reason=Started count=1 msg=Started container task
60.2899,Event,ADDED,eval-sanitize-2-r3-054.18d3d19405c84b91,reason=SuccessfulCreate count=1 msg=Created pod: eval-sanitize-2-r3-054-r6q26
60.2901,Event,ADDED,eval-sanitize-2-r3-055-pgs46.18d3d194432d4b38,"reason=FailedScheduling count=None msg=0/6 nodes are available: 1 c_wall violated: 2 conflicting context pair(s) with node memory, 5 node(s) had untolerated taint(s). no new claims to deallocate, preemption: 0/6 nodes are available: 1 No preemption victims found for incoming pod, 5 Preemption is not helpful for scheduling."
60.2904,Event,ADDED,eval-sanitize-2-r3-055-pgs46.18d3d19443ff84b7,"reason=FailedScheduling count=None msg=0/6 nodes are available: 1 c_wall violated: 2 conflicting context pair(s) with node memory, 5 node(s) had untolerated taint(s). no new claims to deallocate, preemption: 0/6 nodes are available: 1 No preemption victims found for incoming pod, 5 Preemption is not helpful for scheduling."
60.2906,Event,ADDED,eval-sanitize-2-r3-055-pgs46.18d3d19457928857,reason=Scheduled count=None msg=Successfully assigned compute/eval-sanitize-2-r3-055-pgs46 to kind-worker
60.2908,Event,ADDED,eval-sanitize-2-r3-055-pgs46.18d3d19471c8750b,"reason=Pulled count=1 msg=Container image ""busybox:musl"" already present on machine"
60.291,Event,ADDED,eval-sanitize-2-r3-055-pgs46.18d3d194733f2f10,reason=Created count=1 msg=Created container: task
60.2913,Event,ADDED,eval-sanitize-2-r3-055-pgs46.18d3d19476f2dda1,reason=Started count=1 msg=Started container task
60.2915,Event,ADDED,eval-sanitize-2-r3-055.18d3d19441213da1,reason=SuccessfulCreate count=1 msg=Created pod: eval-sanitize-2-r3-055-pgs46
60.2917,Event,ADDED,eval-sanitize-2-r3-056-jjtbf.18d3d1947d003ff5,"reason=FailedScheduling count=None msg=0/6 nodes are available: 1 c_wall violated: 1 conflicting context pair(s) with node memory, 1 c_wall violated: 2 conflicting context pair(s) with node memory, 4 node(s) had untolerated taint(s). no new claims to deallocate, preemption: 0/6 nodes are available: 2 No preemption victims found for incoming pod, 4 Preemption is not helpful for scheduling."
60.292,Event,ADDED,eval-sanitize-2-r3-056-jjtbf.18d3d1947db01771,"reason=FailedScheduling count=None msg=0/6 nodes are available: 1 c_wall violated: 1 conflicting context pair(s) with node memory, 1 c_wall violated: 2 conflicting context pair(s) with node memory, 4 node(s) had untolerated taint(s). no new claims to deallocate, preemption: 0/6 nodes are available: 2 No preemption victims found for incoming pod, 4 Preemption is not helpful for scheduling."
60.2923,Event,ADDED,eval-sanitize-2-r3-056-jjtbf.18d3d19499574585,"reason=FailedScheduling count=None msg=0/6 nodes are available: 1 c_wall violated: 1 conflicting context pair(s) with node memory, 5 node(s) had untolerated taint(s). no new claims to deallocate, preemption: 0/6 nodes are available: 1 No preemption victims found for incoming pod, 5 Preemption is not helpful for scheduling."
60.2926,Event,ADDED,eval-sanitize-2-r3-056-jjtbf.18d3d1953d67bfad,reason=Scheduled count=None msg=Successfully assigned compute/eval-sanitize-2-r3-056-jjtbf to kind-worker5
60.2928,Event,ADDED,eval-sanitize-2-r3-056-jjtbf.18d3d195570cbdea,"reason=Pulled count=1 msg=Container image ""busybox:musl"" already present on machine"
60.2929,Event,ADDED,eval-sanitize-2-r3-056-jjtbf.18d3d19558d9937a,reason=Created count=1 msg=Created container: task
60.2932,Event,ADDED,eval-sanitize-2-r3-056-jjtbf.18d3d1955d576e8c,reason=Started count=1 msg=Started container task
60.2934,Event,ADDED,eval-sanitize-2-r3-056.18d3d1947c95cfdd,reason=SuccessfulCreate count=1 msg=Created pod: eval-sanitize-2-r3-056-jjtbf
60.2936,Event,ADDED,eval-sanitize-2-r3-057-rhvv7.18d3d194b85909a0,"reason=FailedScheduling count=None msg=0/6 nodes are available: 1 c_wall violated: 1 conflicting context pair(s) with node memory, 5 node(s) had untolerated taint(s). no new claims to deallocate, preemption: 0/6 nodes are available: 1 No preemption victims found for incoming pod, 5 Preemption is not helpful for scheduling."
60.294,Event,ADDED,eval-sanitize-2-r3-057-rhvv7.18d3d194b8d1a4cb,"reason=FailedScheduling count=None msg=0/6 nodes are available: 1 c_wall violated: 1 conflicting context pair(s) with node memory, 5 node(s) had untolerated taint(s). no new claims to deallocate, preemption: 0/6 nodes are available: 1 No preemption victims found for incoming pod, 5 Preemption is not helpful for scheduling."
60.2941,Event,ADDED,eval-sanitize-2-r3-057-rhvv7.18d3d1953d26f060,"reason=FailedScheduling count=None msg=0/6 nodes are available: 1 c_wall violated: 1 conflicting context pair(s) with node memory, 5 node(s) had untolerated taint(s). no new claims to deallocate, preemption: 0/6 nodes are available: 1 No preemption victims found for incoming pod, 5 Preemption is not helpful for scheduling."
60.2944,Event,ADDED,eval-sanitize-2-r3-057-rhvv7.18d3d1953e7e57af,"reason=FailedScheduling count=None msg=0/6 nodes are available: 1 c_wall violated: 1 conflicting context pair(s) with node memory, 5 node(s) had untolerated taint(s). no new claims to deallocate, preemption: 0/6 nodes are available: 1 No preemption victims found for incoming pod, 5 Preemption is not helpful for scheduling."
60.2945,Event,ADDED,eval-sanitize-2-r3-057.18d3d194b81e82c6,reason=SuccessfulCreate count=1 msg=Created pod: eval-sanitize-2-r3-057-rhvv7
60.2949,Event,ADDED,eval-sanitize-2-r3-058-sqvr7.18d3d194f3e48e8b,"reason=FailedScheduling count=None msg=0/6 nodes are available: 6 node(s) had untolerated taint(s). no new claims to deallocate, preemption: 0/6 nodes are available: 6 Preemption is not helpful for scheduling."
60.2951,Event,ADDED,eval-sanitize-2-r3-058-sqvr7.18d3d1953dcaa3bc,"reason=FailedScheduling count=None msg=0/6 nodes are available: 1 c_wall violated: 2 conflicting context pair(s) with node memory, 5 node(s) had untolerated taint(s). no new claims to deallocate, preemption: 0/6 nodes are available: 1 No preemption victims found for incoming pod, 5 Preemption is not helpful for scheduling."
60.2954,Event,ADDED,eval-sanitize-2-r3-058-sqvr7.18d3d1953f81428b,"reason=FailedScheduling count=None msg=0/6 nodes are available: 1 c_wall violated: 2 conflicting context pair(s) with node memory, 5 node(s) had untolerated taint(s). no new claims to deallocate, preemption: 0/6 nodes are available: 1 No preemption victims found for incoming pod, 5 Preemption is not helpful for scheduling."
60.2957,Event,ADDED,eval-sanitize-2-r3-058.18d3d194f3d7e0c4,reason=SuccessfulCreate count=1 msg=Created pod: eval-sanitize-2-r3-058-sqvr7
60.2959,Event,ADDED,eval-sanitize-2-r3-059-dw2kg.18d3d1952f7d4e47,"reason=FailedScheduling count=None msg=0/6 nodes are available: 6 node(s) had untolerated taint(s). no new claims to deallocate, preemption: 0/6 nodes are available: 6 Preemption is not helpful for scheduling."
60.296,Event,ADDED,eval-sanitize-2-r3-059-dw2kg.18d3d1953e957cdb,reason=Scheduled count=None msg=Successfully assigned compute/eval-sanitize-2-r3-059-dw2kg to kind-worker5
60.2965,Event,ADDED,eval-sanitize-2-r3-059-dw2kg.18d3d19557a5053a,"reason=Pulled count=1 msg=Container image ""busybox:musl"" already present on machine"
60.2967,Event,ADDED,eval-sanitize-2-r3-059-dw2kg.18d3d1955970e67b,reason=Created count=1 msg=Created container: task
60.2969,Event,ADDED,eval-sanitize-2-r3-059-dw2kg.18d3d1955d58b5fc,reason=Started count=1 msg=Started container task
60.2971,Event,ADDED,eval-sanitize-2-r3-059.18d3d1952f741d8f,reason=SuccessfulCreate count=1 msg=Created pod: eval-sanitize-2-r3-059-dw2kg
60.2974,Event,ADDED,eval-sanitize-2-r3-060.18d3d1956b1de283,reason=SuccessfulCreate count=1 msg=Created pod: eval-sanitize-2-r3-060-58r7q
60.2976,Event,ADDED,eval-sanitize-2-r3-060-58r7q.18d3d1956b8858c7,reason=Scheduled count=None msg=Successfully assigned compute/eval-sanitize-2-r3-060-58r7q to kind-worker5
60.4488,Job,MODIFIED,eval-sanitize-2-r3-048,
60.4599,Pod,MODIFIED,eval-sanitize-2-r3-059-dw2kg,phase=Running node=kind-worker5
60.4624,Event,ADDED,eval-sanitize-2-r3-060-58r7q.18d3d19583b832e6,"reason=Pulled count=1 msg=Container image ""busybox:musl"" already present on machine"
60.4634,Job,MODIFIED,eval-sanitize-2-r3-048,
60.4731,Pod,MODIFIED,eval-sanitize-2-r3-050-mkhrs,phase=Running node=kind-worker5
60.4818,Pod,MODIFIED,eval-sanitize-2-r3-056-jjtbf,phase=Running node=kind-worker5
60.4822,Event,ADDED,eval-sanitize-2-r3-060-58r7q.18d3d1958545978c,reason=Created count=1 msg=Created container: task
60.5136,Job,MODIFIED,eval-sanitize-2-r3-047,
60.5154,Job,MODIFIED,eval-sanitize-2-r3-046,
60.5198,Job,MODIFIED,eval-sanitize-2-r3-046,
60.5222,Pod,MODIFIED,eval-sanitize-2-r3-047-t6knr,phase=Succeeded node=kind-worker4
60.5239,Job,MODIFIED,eval-sanitize-2-r3-047,
60.5255,Event,ADDED,eval-sanitize-2-r3-046.18d3d19587fcd35e,reason=Completed count=1 msg=Job completed
60.5346,Job,MODIFIED,eval-sanitize-2-r3-046,
60.54,Pod,MODIFIED,eval-sanitize-2-r3-048-m65n8,phase=Succeeded node=kind-worker3
60.5402,TaskRequest,MODIFIED,eval-sanitize-2-r3-046,phase=Complete job=None
60.5531,Job,MODIFIED,eval-sanitize-2-r3-046,
60.5562,Event,ADDED,eval-sanitize-2-r3-060-58r7q.18d3d19589dc7b76,reason=Started count=1 msg=Started container task
60.9424,Node,MODIFIED,kind-worker4,taints=1
60.9562,Node,MODIFIED,kind-worker4,taints=1
60.9645,Node,MODIFIED,kind-worker4,taints=0
60.9755,Pod,MODIFIED,eval-sanitize-2-r3-058-sqvr7,phase=Pending node=kind-worker4
60.9765,Pod,MODIFIED,eval-sanitize-2-r3-057-rhvv7,phase=Pending node=None
60.9795,Event,ADDED,eval-sanitize-2-r3-058-sqvr7.18d3d195a2f5be73,reason=Scheduled count=None msg=Successfully assigned compute/eval-sanitize-2-r3-058-sqvr7 to kind-worker4
60.9831,Node,MODIFIED,kind-worker4,taints=0
60.985,Pod,MODIFIED,eval-sanitize-2-r3-058-sqvr7,phase=Pending node=kind-worker4
61.0108,TaskRequest,ADDED,eval-sanitize-2-r3-061,phase=None job=None
61.0112,Event,ADDED,eval-sanitize-2-r3-057-rhvv7.18d3d195a4e391d6,"reason=FailedScheduling count=None msg=0/6 nodes are available: 2 c_wall violated: 1 conflicting context pair(s) with node memory, 4 node(s) had untolerated taint(s). no new claims to deallocate, preemption: 0/6 nodes are available: 2 No preemption victims found for incoming pod, 4 Preemption is not helpful for scheduling."
61.0154,TaskRequest,MODIFIED,eval-sanitize-2-r3-061,phase=Pending job=None
61.0308,Job,ADDED,eval-sanitize-2-r3-061,
61.0358,Pod,ADDED,eval-sanitize-2-r3-061-4f8sq,phase=Pending node=None
61.0381,TaskRequest,MODIFIED,eval-sanitize-2-r3-061,phase=Scheduled job=None
61.0408,Event,ADDED,eval-sanitize-2-r3-061.18d3d195a6be6f24,reason=SuccessfulCreate count=1 msg=Created pod: eval-sanitize-2-r3-061-4f8sq
61.0416,Job,MODIFIED,eval-sanitize-2-r3-061,
61.0423,Job,MODIFIED,eval-sanitize-2-r3-060,
61.0436,Node,MODIFIED,kind-worker4,taints=0
61.0452,Job,MODIFIED,eval-sanitize-2-r3-059,
61.0513,Job,MODIFIED,eval-sanitize-2-r3-060,
61.0544,Node,MODIFIED,kind-worker4,taints=0
61.0556,Job,MODIFIED,eval-sanitize-2-r3-059,
61.0789,Pod,MODIFIED,eval-sanitize-2-r3-061-4f8sq,phase=Pending node=kind-worker5
61.0826,Event,ADDED,eval-sanitize-2-r3-061-4f8sq.18d3d195a94f2e01,reason=Scheduled count=None msg=Successfully assigned compute/eval-sanitize-2-r3-061-4f8sq to kind-worker5
61.0891,Pod,MODIFIED,eval-sanitize-2-r3-061-4f8sq,phase=Pending node=kind-worker5
61.1091,TaskRequest,MODIFIED,eval-sanitize-2-r3-061,phase=Scheduled job=None
61.3441,Node,MODIFIED,kind-worker5,taints=1
61.3527,Pod,MODIFIED,eval-sanitize-2-r3-057-rhvv7,phase=Pending node=None
61.3571,Node,MODIFIED,kind-worker5,taints=1
61.3612,Event,ADDED,eval-sanitize-2-r3-057-rhvv7.18d3d195b9d711ab,"reason=FailedScheduling count=None msg=0/6 nodes are available: 1 c_wall violated: 1 conflicting context pair(s) with node memory, 5 node(s) had untolerated taint(s). no new claims to deallocate, preemption: 0/6 nodes are available: 1 No preemption victims found for incoming pod, 5 Preemption is not helpful for scheduling."
61.4066,Event,ADDED,eval-sanitize-2-r3-058-sqvr7.18d3d195bc972e1a,"reason=Pulled count=1 msg=Container image ""busybox:musl"" already present on machine"
61.4267,Event,ADDED,eval-sanitize-2-r3-058-sqvr7.18d3d195bdcb5a68,reason=Created count=1 msg=Created container: task
61.4583,Job,MODIFIED,eval-sanitize-2-r3-048,
61.4656,Pod,MODIFIED,eval-sanitize-2-r3-060-58r7q,phase=Running node=kind-worker5
61.468,Event,ADDED,eval-sanitize-2-r3-058-sqvr7.18d3d195c007aeb1,reason=Started count=1 msg=Started container task
61.4714,Pod,MODIFIED,eval-sanitize-2-r3-048-m65n8,phase=Succeeded node=kind-worker3
61.4734,Job,MODIFIED,eval-sanitize-2-r3-048,
61.4775,Job,MODIFIED,eval-sanitize-2-r3-050,
61.485,Event,ADDED,eval-sanitize-2-r3-061-4f8sq.18d3d195c147802e,"reason=Pulled count=1 msg=Container image ""busybox:musl"" already present on machine"
61.4892,Job,MODIFIED,eval-sanitize-2-r3-056,
61.49,Job,MODIFIED,eval-sanitize-2-r3-050,
61.4992,Job,MODIFIED,eval-sanitize-2-r3-056,
61.5068,Pod,MODIFIED,eval-sanitize-2-r3-058-sqvr7,phase=Running node=kind-worker4
61.5072,Event,ADDED,eval-sanitize-2-r3-061-4f8sq.18d3d195c2828dfe,reason=Created count=1 msg=Created container: task
61.5195,Job,MODIFIED,eval-sanitize-2-r3-047,
61.5238,Job,MODIFIED,eval-sanitize-2-r3-047,
61.5275,Event,ADDED,eval-sanitize-2-r3-047.18d3d195c3d002f9,reason=Completed count=1 msg=Job completed
61.5355,Job,MODIFIED,eval-sanitize-2-r3-047,
61.5401,TaskRequest,MODIFIED,eval-sanitize-2-r3-047,phase=Complete job=None
61.5501,Job,MODIFIED,eval-sanitize-2-r3-047,
61.5706,Event,ADDED,eval-sanitize-2-r3-061-4f8sq.18d3d195c65a491f,reason=Started count=1 msg=Started container task
61.9843,Job,MODIFIED,eval-sanitize-2-r3-058,
61.9925,Job,MODIFIED,eval-sanitize-2-r3-058,
62.0064,TaskRequest,ADDED,eval-sanitize-2-r3-062,phase=None job=None
62.0094,TaskRequest,MODIFIED,eval-sanitize-2-r3-062,phase=Pending job=None
62.024,Job,ADDED,eval-sanitize-2-r3-062,
62.0281,TaskRequest,MODIFIED,eval-sanitize-2-r3-062,phase=Scheduled job=None
62.0313,Pod,ADDED,eval-sanitize-2-r3-062-bjbxn,phase=Pending node=None
62.0339,Job,MODIFIED,eval-sanitize-2-r3-062,
62.0371,Event,ADDED,eval-sanitize-2-r3-062.18d3d195e2173cd0,reason=SuccessfulCreate count=1 msg=Created pod: eval-sanitize-2-r3-062-bjbxn
62.0372,TaskRequest,MODIFIED,eval-sanitize-2-r3-062,phase=Scheduled job=None
62.0403,Pod,MODIFIED,eval-sanitize-2-r3-062-bjbxn,phase=Pending node=kind-worker4
62.0427,Job,MODIFIED,eval-sanitize-2-r3-061,
62.0439,Event,ADDED,eval-sanitize-2-r3-062-bjbxn.18d3d195e29d965f,reason=Scheduled count=None msg=Successfully assigned compute/eval-sanitize-2-r3-062-bjbxn to kind-worker4
62.0478,Job,MODIFIED,eval-sanitize-2-r3-060,
62.0489,Pod,MODIFIED,eval-sanitize-2-r3-057-rhvv7,phase=Pending node=None
62.0523,Node,MODIFIED,kind-worker4,taints=0
62.0539,Pod,MODIFIED,eval-sanitize-2-r3-062-bjbxn,phase=Pending node=kind-worker4
62.055,Job,MODIFIED,eval-sanitize-2-r3-061,
62.0561,Job,MODIFIED,eval-sanitize-2-r3-060,
62.0581,Event,ADDED,eval-sanitize-2-r3-057-rhvv7.18d3d195e3579eba,"reason=FailedScheduling count=None msg=0/6 nodes are available: 1 c_wall violated: 2 conflicting context pair(s) with node memory, 5 node(s) had untolerated taint(s). no new claims to deallocate, preemption: 0/6 nodes are available: 1 No preemption victims found for incoming pod, 5 Preemption is not helpful for scheduling."
62.1173,Node,MODIFIED,kind-worker3,taints=1
62.1191,Node,MODIFIED,kind-worker4,taints=0
62.1411,Node,MODIFIED,kind-worker3,taints=0
62.1489,Pod,MODIFIED,eval-sanitize-2-r3-057-rhvv7,phase=Pending node=kind-worker3
62.1507,Node,MODIFIED,kind-worker3,taints=0
62.1532,Event,ADDED,eval-sanitize-2-r3-057-rhvv7.18d3d195e90c7f2d,reason=Scheduled count=None msg=Successfully assigned compute/eval-sanitize-2-r3-057-rhvv7 to kind-worker3
62.1586,Pod,MODIFIED,eval-sanitize-2-r3-057-rhvv7,phase=Pending node=kind-worker3
62.1735,Node,MODIFIED,kind-worker3,taints=0
62.2167,Node,MODIFIED,kind-worker3,taints=0
62.227,Node,MODIFIED,kind-worker3,taints=0
62.4642,Job,MODIFIED,eval-sanitize-2-r3-048,
62.4688,Pod,MODIFIED,eval-sanitize-2-r3-061-4f8sq,phase=Running node=kind-worker5
62.4713,Job,MODIFIED,eval-sanitize-2-r3-048,
62.4769,Event,ADDED,eval-sanitize-2-r3-048.18d3d195fc3f3dd6,reason=Completed count=1 msg=Job completed
62.4801,Event,ADDED,eval-sanitize-2-r3-062-bjbxn.18d3d195fc3db3d8,"reason=Pulled count=1 msg=Container image ""busybox:musl"" already present on machine"
62.4888,Job,MODIFIED,eval-sanitize-2-r3-048,
62.494,TaskRequest,MODIFIED,eval-sanitize-2-r3-048,phase=Complete job=None
62.498,Event,ADDED,eval-sanitize-2-r3-062-bjbxn.18d3d195fdae585e,reason=Created count=1 msg=Created container: task
62.5053,Job,MODIFIED,eval-sanitize-2-r3-048,
62.5688,Event,ADDED,eval-sanitize-2-r3-062-bjbxn.18d3d19601cc2434,reason=Started count=1 msg=Started container task
62.58,Event,ADDED,eval-sanitize-2-r3-057-rhvv7.18d3d19602915d3f,"reason=Pulled count=1 msg=Container image ""busybox:musl"" already present on machine"
62.6004,Event,ADDED,eval-sanitize-2-r3-057-rhvv7.18d3d19603a022cf,reason=Created count=1 msg=Created container: task
62.6685,Event,ADDED,eval-sanitize-2-r3-057-rhvv7.18d3d19607d1db4c,reason=Started count=1 msg=Started container task
63.0083,TaskRequest,ADDED,eval-sanitize-2-r3-063,phase=None job=None
63.0116,TaskRequest,MODIFIED,eval-sanitize-2-r3-063,phase=Pending job=None
63.0272,Job,ADDED,eval-sanitize-2-r3-063,
63.032,TaskRequest,MODIFIED,eval-sanitize-2-r3-063,phase=Scheduled job=None
63.0342,Pod,ADDED,eval-sanitize-2-r3-063-4v862,phase=Pending node=None
63.0372,Job,MODIFIED,eval-sanitize-2-r3-063,
63.039,Job,MODIFIED,eval-sanitize-2-r3-062,
63.0393,Event,ADDED,eval-sanitize-2-r3-063.18d3d1961dd7fa13,reason=SuccessfulCreate count=1 msg=Created pod: eval-sanitize-2-r3-063-4v862
63.04,TaskRequest,MODIFIED,eval-sanitize-2-r3-063,phase=Scheduled job=None
63.0481,Node,MODIFIED,kind-worker4,taints=1
63.0489,Job,MODIFIED,eval-sanitize-2-r3-061,
63.0498,Pod,MODIFIED,eval-sanitize-2-r3-063-4v862,phase=Pending node=kind-worker3
63.0506,Job,MODIFIED,eval-sanitize-2-r3-062,
63.0523,Event,ADDED,eval-sanitize-2-r3-063-4v862.18d3d1961eb711d1,reason=Scheduled count=None msg=Successfully assigned compute/eval-sanitize-2-r3-063-4v862 to kind-worker3
63.0587,Node,MODIFIED,kind-worker3,taints=0
63.0604,Job,MODIFIED,eval-sanitize-2-r3-061,
63.0618,Node,MODIFIED,kind-worker4,taints=1
63.0629,Pod,MODIFIED,eval-sanitize-2-r3-063-4v862,phase=Pending node=kind-worker3
63.2432,Node,MODIFIED,kind-worker3,taints=0
63.4517,Pod,MODIFIED,eval-sanitize-2-r3-057-rhvv7,phase=Running node=kind-worker3
63.4845,Event,ADDED,eval-sanitize-2-r3-063-4v862.18d3d19638654df6,"reason=Pulled count=1 msg=Container image ""busybox:musl"" already present on machine"
63.5029,Event,ADDED,eval-sanitize-2-r3-063-4v862.18d3d1963979aa09,reason=Created count=1 msg=Created container: task
63.5137,Pod,MODIFIED,eval-sanitize-2-r3-062-bjbxn,phase=Running node=kind-worker4
63.5757,Event,ADDED,eval-sanitize-2-r3-063-4v862.18d3d1963de27443,reason=Started count=1 msg=Started container task
64.0158,TaskRequest,ADDED,eval-sanitize-2-r3-064,phase=None job=None
64.0207,TaskRequest,MODIFIED,eval-sanitize-2-r3-064,phase=Pending job=None
64.0346,Job,ADDED,eval-sanitize-2-r3-064,
64.039,Job,MODIFIED,eval-sanitize-2-r3-063,
64.0403,TaskRequest,MODIFIED,eval-sanitize-2-r3-064,phase=Scheduled job=None
64.0411,Pod,ADDED,eval-sanitize-2-r3-064-mtnfw,phase=Pending node=None
64.0431,Job,MODIFIED,eval-sanitize-2-r3-062,
64.0476,Job,MODIFIED,eval-sanitize-2-r3-064,
64.048,Event,ADDED,eval-sanitize-2-r3-064.18d3d19659e10d0a,reason=SuccessfulCreate count=1 msg=Created pod: eval-sanitize-2-r3-064-mtnfw
64.0511,Pod,MODIFIED,eval-sanitize-2-r3-064-mtnfw,phase=Pending node=None
64.0519,Job,MODIFIED,eval-sanitize-2-r3-063,
64.052,TaskRequest,MODIFIED,eval-sanitize-2-r3-064,phase=Scheduled job=None
64.0523,Event,ADDED,eval-sanitize-2-r3-064-mtnfw.18d3d1965a241ccc,"reason=FailedScheduling count=None msg=0/6 nodes are available: 1 c_wall violated: 1 conflicting context pair(s) with node memory, 5 node(s) had untolerated taint(s). no new claims to deallocate, preemption: 0/6 nodes are available: 1 No preemption victims found for incoming pod, 5 Preemption is not helpful for scheduling."
64.0531,Job,MODIFIED,eval-sanitize-2-r3-062,
64.0582,Event,ADDED,eval-sanitize-2-r3-064-mtnfw.18d3d1965ab5bf04,"reason=FailedScheduling count=None msg=0/6 nodes are available: 1 c_wall violated: 1 conflicting context pair(s) with node memory, 5 node(s) had untolerated taint(s). no new claims to deallocate, preemption: 0/6 nodes are available: 1 No preemption victims found for incoming pod, 5 Preemption is not helpful for scheduling."
64.161,Node,MODIFIED,kind-worker3,taints=1
64.1765,Pod,MODIFIED,eval-sanitize-2-r3-064-mtnfw,phase=Pending node=None
64.1769,Event,MODIFIED,eval-sanitize-2-r3-064-mtnfw.18d3d1965ab5bf04,"reason=FailedScheduling count=None msg=0/6 nodes are available: 1 c_wall violated: 1 conflicting context pair(s) with node memory, 5 node(s) had untolerated taint(s). no new claims to deallocate, preemption: 0/6 nodes are available: 1 No preemption victims found for incoming pod, 5 Preemption is not helpful for scheduling."
64.1807,Node,MODIFIED,kind-worker3,taints=1
64.4532,Pod,MODIFIED,eval-sanitize-2-r3-063-4v862,phase=Running node=kind-worker3
64.4569,Job,MODIFIED,eval-sanitize-2-r3-057,
64.4664,Job,MODIFIED,eval-sanitize-2-r3-057,
65.0104,TaskRequest,ADDED,eval-sanitize-2-r3-065,phase=None job=None
65.0149,TaskRequest,MODIFIED,eval-sanitize-2-r3-065,phase=Pending job=None
65.0311,Job,ADDED,eval-sanitize-2-r3-065,
65.0362,Pod,ADDED,eval-sanitize-2-r3-065-424qb,phase=Pending node=None
65.0376,TaskRequest,MODIFIED,eval-sanitize-2-r3-065,phase=Scheduled job=None
65.0402,Job,MODIFIED,eval-sanitize-2-r3-065,
65.0422,Event,ADDED,eval-sanitize-2-r3-065.18d3d196953247cd,reason=SuccessfulCreate count=1 msg=Created pod: eval-sanitize-2-r3-065-424qb
65.0425,Event,ADDED,eval-sanitize-2-r3-065-424qb.18d3d196953fab10,"reason=FailedScheduling count=None msg=0/6 nodes are available: 6 node(s) had untolerated taint(s). no new claims to deallocate, preemption: 0/6 nodes are available: 6 Preemption is not helpful for scheduling."
65.0434,Pod,MODIFIED,eval-sanitize-2-r3-065-424qb,phase=Pending node=None
65.0446,Job,MODIFIED,eval-sanitize-2-r3-063,
65.0459,TaskRequest,MODIFIED,eval-sanitize-2-r3-065,phase=Scheduled job=None
65.0469,Job,MODIFIED,eval-sanitize-2-r3-064,
65.0538,Job,MODIFIED,eval-sanitize-2-r3-063,
65.0555,Job,MODIFIED,eval-sanitize-2-r3-064,
65.8398,Pod,MODIFIED,eval-sanitize-2-r3-049-tdnps,phase=Running node=kind-worker2
65.8465,Pod,MODIFIED,eval-sanitize-2-r3-051-zfn8s,phase=Running node=kind-worker2
65.8527,Pod,MODIFIED,eval-sanitize-2-r3-052-qtqlf,phase=Running node=kind-worker2
65.8587,Pod,MODIFIED,eval-sanitize-2-r3-053-bgzwf,phase=Running node=kind-worker2
66.0092,TaskRequest,ADDED,eval-sanitize-2-r3-066,phase=None job=None
66.0127,TaskRequest,MODIFIED,eval-sanitize-2-r3-066,phase=Pending job=None
66.0274,Job,ADDED,eval-sanitize-2-r3-066,
66.0366,Pod,ADDED,eval-sanitize-2-r3-066-mg89j,phase=Pending node=None
66.0379,TaskRequest,MODIFIED,eval-sanitize-2-r3-066,phase=Scheduled job=None
66.0386,Job,MODIFIED,eval-sanitize-2-r3-066,
66.0426,Event,ADDED,eval-sanitize-2-r3-066.18d3d196d0d491a5,reason=SuccessfulCreate count=1 msg=Created pod: eval-sanitize-2-r3-066-mg89j
66.0428,Event,ADDED,eval-sanitize-2-r3-066-mg89j.18d3d196d0de0c01,"reason=FailedScheduling count=None msg=0/6 nodes are available: 6 node(s) had untolerated taint(s). no new claims to deallocate, preemption: 0/6 nodes are available: 6 Preemption is not helpful for scheduling."
66.0436,Job,MODIFIED,eval-sanitize-2-r3-065,
66.0445,Pod,MODIFIED,eval-sanitize-2-r3-066-mg89j,phase=Pending node=None
66.0455,TaskRequest,MODIFIED,eval-sanitize-2-r3-066,phase=Scheduled job=None
66.0511,Job,MODIFIED,eval-sanitize-2-r3-065,
66.6287,Pod,MODIFIED,eval-sanitize-2-r3-055-pgs46,phase=Running node=kind-worker
66.6345,Pod,MODIFIED,eval-sanitize-2-r3-054-r6q26,phase=Running node=kind-worker
66.8475,Job,MODIFIED,eval-sanitize-2-r3-049,
66.8533,Job,MODIFIED,eval-sanitize-2-r3-051,
66.8573,Job,MODIFIED,eval-sanitize-2-r3-049,
66.8593,Job,MODIFIED,eval-sanitize-2-r3-052,
66.8626,Job,MODIFIED,eval-sanitize-2-r3-051,
66.8643,Job,MODIFIED,eval-sanitize-2-r3-053,
66.8687,Job,MODIFIED,eval-sanitize-2-r3-052,
66.8727,Job,MODIFIED,eval-sanitize-2-r3-053,
67.0087,TaskRequest,ADDED,eval-sanitize-2-r3-067,phase=None job=None
67.0142,TaskRequest,MODIFIED,eval-sanitize-2-r3-067,phase=Pending job=None
67.0227,Pod,MODIFIED,eval-sanitize-2-r3-052-qtqlf,phase=Succeeded node=kind-worker2
67.0302,Job,ADDED,eval-sanitize-2-r3-067,
67.0354,Pod,ADDED,eval-sanitize-2-r3-067-cl65v,phase=Pending node=None
67.038,TaskRequest,MODIFIED,eval-sanitize-2-r3-067,phase=Scheduled job=None
67.0406,Event,ADDED,eval-sanitize-2-r3-067.18d3d1970c5e0556,reason=SuccessfulCreate count=1 msg=Created pod: eval-sanitize-2-r3-067-cl65v
67.0413,Job,MODIFIED,eval-sanitize-2-r3-067,
67.0423,Pod,MODIFIED,eval-sanitize-2-r3-067-cl65v,phase=Pending node=None
67.043,Event,ADDED,eval-sanitize-2-r3-067-cl65v.18d3d1970c6680ea,"reason=FailedScheduling count=None msg=0/6 nodes are available: 6 node(s) had untolerated taint(s). no new claims to deallocate, preemption: 0/6 nodes are available: 6 Preemption is not helpful for scheduling."
67.0438,Job,MODIFIED,eval-sanitize-2-r3-066,
67.0486,TaskRequest,MODIFIED,eval-sanitize-2-r3-067,phase=Scheduled job=None
67.0556,Job,MODIFIED,eval-sanitize-2-r3-066,
67.0634,Pod,MODIFIED,eval-sanitize-2-r3-049-tdnps,phase=Succeeded node=kind-worker2
67.0711,Pod,MODIFIED,eval-sanitize-2-r3-053-bgzwf,phase=Succeeded node=kind-worker2
67.079,Pod,MODIFIED,eval-sanitize-2-r3-051-zfn8s,phase=Succeeded node=kind-worker2
67.6352,Job,MODIFIED,eval-sanitize-2-r3-055,
67.6395,Job,MODIFIED,eval-sanitize-2-r3-054,
67.6454,Job,MODIFIED,eval-sanitize-2-r3-055,
67.6496,Job,MODIFIED,eval-sanitize-2-r3-054,
67.7434,Node,MODIFIED,kind-worker2,taints=1
67.7561,Node,MODIFIED,kind-worker2,taints=1
67.7661,Node,MODIFIED,kind-worker2,taints=0
67.7716,Pod,MODIFIED,eval-sanitize-2-r3-064-mtnfw,phase=Pending node=kind-worker2
67.7755,Pod,MODIFIED,eval-sanitize-2-r3-065-424qb,phase=Pending node=kind-worker2
67.7759,Event,ADDED,eval-sanitize-2-r3-064-mtnfw.18d3d197383d3991,reason=Scheduled count=None msg=Successfully assigned compute/eval-sanitize-2-r3-064-mtnfw to kind-worker2
67.7814,Pod,MODIFIED,eval-sanitize-2-r3-066-mg89j,phase=Pending node=kind-worker2
67.7849,Event,ADDED,eval-sanitize-2-r3-065-424qb.18d3d197386bf44b,reason=Scheduled count=None msg=Successfully assigned compute/eval-sanitize-2-r3-065-424qb to kind-worker2
67.7858,Pod,MODIFIED,eval-sanitize-2-r3-067-cl65v,phase=Pending node=kind-worker2
67.7875,Node,MODIFIED,kind-worker2,taints=0
67.7929,Pod,MODIFIED,eval-sanitize-2-r3-064-mtnfw,phase=Pending node=kind-worker2
67.7932,Event,ADDED,eval-sanitize-2-r3-066-mg89j.18d3d19738e6f81d,reason=Scheduled count=None msg=Successfully assigned compute/eval-sanitize-2-r3-066-mg89j to kind-worker2
67.7935,Event,ADDED,eval-sanitize-2-r3-067-cl65v.18d3d1973942c8b5,reason=Scheduled count=None msg=Successfully assigned compute/eval-sanitize-2-r3-067-cl65v to kind-worker2
67.799,Pod,MODIFIED,eval-sanitize-2-r3-067-cl65v,phase=Pending node=kind-worker2
67.8011,Node,MODIFIED,kind-worker2,taints=0
67.8046,Pod,MODIFIED,eval-sanitize-2-r3-055-pgs46,phase=Succeeded node=kind-worker
67.8066,Pod,MODIFIED,eval-sanitize-2-r3-065-424qb,phase=Pending node=kind-worker2
67.813,Pod,MODIFIED,eval-sanitize-2-r3-066-mg89j,phase=Pending node=kind-worker2
67.8262,Node,MODIFIED,kind-worker2,taints=0
67.8433,Pod,MODIFIED,eval-sanitize-2-r3-054-r6q26,phase=Succeeded node=kind-worker
67.852,Job,MODIFIED,eval-sanitize-2-r3-049,
67.8599,Job,MODIFIED,eval-sanitize-2-r3-051,
67.8624,Pod,MODIFIED,eval-sanitize-2-r3-049-tdnps,phase=Succeeded node=kind-worker2
67.865,Job,MODIFIED,eval-sanitize-2-r3-049,
67.8669,Job,MODIFIED,eval-sanitize-2-r3-052,
67.8693,Job,MODIFIED,eval-sanitize-2-r3-053,
67.8701,Job,MODIFIED,eval-sanitize-2-r3-051,
67.8714,Pod,MODIFIED,eval-sanitize-2-r3-051-zfn8s,phase=Succeeded node=kind-worker2
67.8762,Pod,MODIFIED,eval-sanitize-2-r3-052-qtqlf,phase=Succeeded node=kind-worker2
67.8784,Pod,MODIFIED,eval-sanitize-2-r3-053-bgzwf,phase=Succeeded node=kind-worker2
67.8792,Job,MODIFIED,eval-sanitize-2-r3-052,
67.8799,Job,MODIFIED,eval-sanitize-2-r3-053,
67.9691,Node,MODIFIED,kind-worker2,taints=0
67.9805,Node,MODIFIED,kind-worker2,taints=0
68.008,TaskRequest,ADDED,eval-sanitize-2-r3-068,phase=None job=None
68.0118,TaskRequest,MODIFIED,eval-sanitize-2-r3-068,phase=Pending job=None
68.0277,Job,ADDED,eval-sanitize-2-r3-068,
68.0322,TaskRequest,MODIFIED,eval-sanitize-2-r3-068,phase=Scheduled job=None
68.0358,Pod,ADDED,eval-sanitize-2-r3-068-8nbft,phase=Pending node=None
68.0372,Job,MODIFIED,eval-sanitize-2-r3-068,
68.0398,Job,MODIFIED,eval-sanitize-2-r3-067,
68.0411,Event,ADDED,eval-sanitize-2-r3-068.18d3d19747fa4b38,reason=SuccessfulCreate count=1 msg=Created pod: eval-sanitize-2-r3-068-8nbft
68.0412,TaskRequest,MODIFIED,eval-sanitize-2-r3-068,phase=Scheduled job=None
68.0441,Pod,MODIFIED,eval-sanitize-2-r3-068-8nbft,phase=Pending node=None
68.0444,Event,ADDED,eval-sanitize-2-r3-068-8nbft.18d3d19748386085,"reason=FailedScheduling count=None msg=0/6 nodes are available: 1 c_wall violated: 2 conflicting context pair(s) with node memory, 5 node(s) had untolerated taint(s). no new claims to deallocate, preemption: 0/6 nodes are available: 1 No preemption victims found for incoming pod, 5 Preemption is not helpful for scheduling."
68.0489,Job,MODIFIED,eval-sanitize-2-r3-067,
68.0507,Event,ADDED,eval-sanitize-2-r3-068-8nbft.18d3d19748af731d,"reason=FailedScheduling count=None msg=0/6 nodes are available: 1 c_wall violated: 2 conflicting context pair(s) with node memory, 5 node(s) had untolerated taint(s). no new claims to deallocate, preemption: 0/6 nodes are available: 1 No preemption victims found for incoming pod, 5 Preemption is not helpful for scheduling."
68.2135,Event,ADDED,eval-sanitize-2-r3-064-mtnfw.18d3d197521f67bb,"reason=Pulled count=1 msg=Container image ""busybox:musl"" already present on machine"
68.2197,Event,ADDED,eval-sanitize-2-r3-065-424qb.18d3d19752b0ffde,"reason=Pulled count=1 msg=Container image ""busybox:musl"" already present on machine"
68.2309,Event,ADDED,eval-sanitize-2-r3-067-cl65v.18d3d1975346c15b,"reason=Pulled count=1 msg=Container image ""busybox:musl"" already present on machine"
68.2363,Event,ADDED,eval-sanitize-2-r3-066-mg89j.18d3d197535df2e3,"reason=Pulled count=1 msg=Container image ""busybox:musl"" already present on machine"
68.2478,Event,ADDED,eval-sanitize-2-r3-064-mtnfw.18d3d1975466602a,reason=Created count=1 msg=Created container: task
68.2591,Event,ADDED,eval-sanitize-2-r3-065-424qb.18d3d19754e429e1,reason=Created count=1 msg=Created container: task
68.2674,Event,ADDED,eval-sanitize-2-r3-067-cl65v.18d3d1975593ba8b,reason=Created count=1 msg=Created container: task
68.2727,Event,ADDED,eval-sanitize-2-r3-066-mg89j.18d3d19755ec4016,reason=Created count=1 msg=Created container: task
68.3119,Event,ADDED,eval-sanitize-2-r3-064-mtnfw.18d3d19758242c60,reason=Started count=1 msg=Started container task
68.3325,Event,ADDED,eval-sanitize-2-r3-066-mg89j.18d3d197595220ee,reason=Started count=1 msg=Started container task
68.3367,Event,ADDED,eval-sanitize-2-r3-067-cl65v.18d3d19759532f7f,reason=Started count=1 msg=Started container task
68.343,Event,ADDED,eval-sanitize-2-r3-065-424qb.18d3d1975954cf33,reason=Started count=1 msg=Started container task
68.4413,Node,MODIFIED,kind-worker,taints=1
68.4492,Event,MODIFIED,eval-sanitize-2-r3-068-8nbft.18d3d19748af731d,"reason=FailedScheduling count=None msg=0/6 nodes are available: 1 c_wall violated: 2 conflicting context pair(s) with node memory, 5 node(s) had untolerated taint(s). no new claims to deallocate, preemption: 0/6 nodes are available: 1 No preemption victims found for incoming pod, 5 Preemption is not helpful for scheduling."
68.4532,Node,MODIFIED,kind-worker,taints=1
68.4624,Node,MODIFIED,kind-worker,taints=0
68.4736,Pod,MODIFIED,eval-sanitize-2-r3-068-8nbft,phase=Pending node=kind-worker
68.4789,Event,ADDED,eval-sanitize-2-r3-068-8nbft.18d3d19761fe31a3,reason=Scheduled count=None msg=Successfully assigned compute/eval-sanitize-2-r3-068-8nbft to kind-worker
68.4857,Node,MODIFIED,kind-worker,taints=0
68.4874,Pod,MODIFIED,eval-sanitize-2-r3-068-8nbft,phase=Pending node=kind-worker
68.5635,Node,MODIFIED,kind-worker,taints=0
68.6418,Job,MODIFIED,eval-sanitize-2-r3-055,
68.6447,Job,MODIFIED,eval-sanitize-2-r3-054,
68.648,Node,MODIFIED,kind-worker,taints=0
68.6508,Pod,MODIFIED,eval-sanitize-2-r3-055-pgs46,phase=Succeeded node=kind-worker
68.6544,Job,MODIFIED,eval-sanitize-2-r3-055,
68.6557,Job,MODIFIED,eval-sanitize-2-r3-054,
68.6579,Pod,MODIFIED,eval-sanitize-2-r3-054-r6q26,phase=Succeeded node=kind-worker
68.8581,Pod,MODIFIED,eval-sanitize-2-r3-064-mtnfw,phase=Running node=kind-worker2
68.8606,Job,MODIFIED,eval-sanitize-2-r3-049,
68.8643,Job,MODIFIED,eval-sanitize-2-r3-049,
68.8674,Job,MODIFIED,eval-sanitize-2-r3-051,
68.8678,Event,ADDED,eval-sanitize-2-r3-049.18d3d19779635ad1,reason=Completed count=1 msg=Job completed
68.8691,Pod,MODIFIED,eval-sanitize-2-r3-067-cl65v,phase=Running node=kind-worker2
68.8729,Job,MODIFIED,eval-sanitize-2-r3-051,
68.8737,Job,MODIFIED,eval-sanitize-2-r3-052,
68.8748,Job,MODIFIED,eval-sanitize-2-r3-053,
68.8777,Pod,MODIFIED,eval-sanitize-2-r3-065-424qb,phase=Running node=kind-worker2
68.8791,Event,ADDED,eval-sanitize-2-r3-051.18d3d19779e286a7,reason=Completed count=1 msg=Job completed
68.88,Job,MODIFIED,eval-sanitize-2-r3-052,
68.8809,Job,MODIFIED,eval-sanitize-2-r3-049,
68.8818,Job,MODIFIED,eval-sanitize-2-r3-053,
68.8855,Pod,MODIFIED,eval-sanitize-2-r3-066-mg89j,phase=Running node=kind-worker2
68.8865,Event,ADDED,eval-sanitize-2-r3-052.18d3d1977a487ee8,reason=Completed count=1 msg=Job completed
68.8867,TaskRequest,MODIFIED,eval-sanitize-2-r3-049,phase=Complete job=None
68.8882,Job,MODIFIED,eval-sanitize-2-r3-051,
68.8892,Job,MODIFIED,eval-sanitize-2-r3-052,
68.8902,Event,ADDED,eval-sanitize-2-r3-053.18d3d1977a4e874e,reason=Completed count=1 msg=Job completed
68.893,Job,MODIFIED,eval-sanitize-2-r3-053,
68.8963,TaskRequest,MODIFIED,eval-sanitize-2-r3-051,phase=Complete job=None
68.9022,Job,MODIFIED,eval-sanitize-2-r3-049,
68.9103,Event,ADDED,eval-sanitize-2-r3-068-8nbft.18d3d1977bd60d35,"reason=Pulled count=1 msg=Container image ""busybox:musl"" already present on machine"
68.9276,Event,ADDED,eval-sanitize-2-r3-068-8nbft.18d3d1977ce74834,reason=Created count=1 msg=Created container: task
68.9634,Event,ADDED,eval-sanitize-2-r3-068-8nbft.18d3d1977ef1cc6a,reason=Started count=1 msg=Started container task
68.9686,TaskRequest,MODIFIED,eval-sanitize-2-r3-052,phase=Complete job=None
68.9725,Job,MODIFIED,eval-sanitize-2-r3-051,
68.9736,TaskRequest,MODIFIED,eval-sanitize-2-r3-053,phase=Complete job=None
68.9782,Job,MODIFIED,eval-sanitize-2-r3-052,
68.9821,Job,MODIFIED,eval-sanitize-2-r3-053,
69.0126,TaskRequest,ADDED,eval-sanitize-2-r3-069,phase=None job=None
69.0159,TaskRequest,MODIFIED,eval-sanitize-2-r3-069,phase=Pending job=None
69.0309,Job,ADDED,eval-sanitize-2-r3-069,
69.0386,Pod,ADDED,eval-sanitize-2-r3-069-lsbjn,phase=Pending node=None
69.0387,TaskRequest,MODIFIED,eval-sanitize-2-r3-069,phase=Scheduled job=None
69.0413,Job,MODIFIED,eval-sanitize-2-r3-068,
69.0419,Job,MODIFIED,eval-sanitize-2-r3-069,
69.0431,Event,ADDED,eval-sanitize-2-r3-069.18d3d19783baeac3,reason=SuccessfulCreate count=1 msg=Created pod: eval-sanitize-2-r3-069-lsbjn
69.0458,Job,MODIFIED,eval-sanitize-2-r3-067,
69.0461,TaskRequest,MODIFIED,eval-sanitize-2-r3-069,phase=Scheduled job=None
69.0592,Pod,MODIFIED,eval-sanitize-2-r3-069-lsbjn,phase=Pending node=kind-worker
69.0627,Event,ADDED,eval-sanitize-2-r3-069-lsbjn.18d3d19784f92e18,reason=Scheduled count=None msg=Successfully assigned compute/eval-sanitize-2-r3-069-lsbjn to kind-worker
69.0693,Node,MODIFIED,kind-worker,taints=0
69.072,Pod,MODIFIED,eval-sanitize-2-r3-069-lsbjn,phase=Pending node=kind-worker
69.0754,Job,MODIFIED,eval-sanitize-2-r3-068,
69.0771,Job,MODIFIED,eval-sanitize-2-r3-067,
69.0797,Node,MODIFIED,kind-worker,taints=0
69.4982,Event,ADDED,eval-sanitize-2-r3-069-lsbjn.18d3d1979ebc17b8,"reason=Pulled count=1 msg=Container image ""busybox:musl"" already present on machine"
69.5152,Event,ADDED,eval-sanitize-2-r3-069-lsbjn.18d3d1979fd88587,reason=Created count=1 msg=Created container: task
69.5957,Event,ADDED,eval-sanitize-2-r3-069-lsbjn.18d3d197a4ae6969,reason=Started count=1 msg=Started container task
69.6408,Pod,MODIFIED,eval-sanitize-2-r3-068-8nbft,phase=Running node=kind-worker
69.6472,Job,MODIFIED,eval-sanitize-2-r3-055,
69.6496,Pod,MODIFIED,eval-sanitize-2-r3-069-lsbjn,phase=Running node=kind-worker
69.6539,Job,MODIFIED,eval-sanitize-2-r3-054,
69.6582,Job,MODIFIED,eval-sanitize-2-r3-055,
69.6609,Job,MODIFIED,eval-sanitize-2-r3-054,
69.6653,Event,ADDED,eval-sanitize-2-r3-055.18d3d197a8a64f10,reason=Completed count=1 msg=Job completed
69.6739,Event,ADDED,eval-sanitize-2-r3-054.18d3d197a8ccc43c,reason=Completed count=1 msg=Job completed
69.6749,Job,MODIFIED,eval-sanitize-2-r3-055,
69.6759,Job,MODIFIED,eval-sanitize-2-r3-054,
69.6806,TaskRequest,MODIFIED,eval-sanitize-2-r3-054,phase=Complete job=None
69.6853,TaskRequest,MODIFIED,eval-sanitize-2-r3-055,phase=Complete job=None
69.6905,Job,MODIFIED,eval-sanitize-2-r3-054,
69.6947,Job,MODIFIED,eval-sanitize-2-r3-055,
69.8658,Job,MODIFIED,eval-sanitize-2-r3-064,
69.8748,Job,MODIFIED,eval-sanitize-2-r3-064,
69.8829,Job,MODIFIED,eval-sanitize-2-r3-065,
69.8899,Job,MODIFIED,eval-sanitize-2-r3-066,
69.892,Job,MODIFIED,eval-sanitize-2-r3-065,
69.8996,Job,MODIFIED,eval-sanitize-2-r3-066,
69.9668,Node,MODIFIED,kind-worker2,taints=1
70.0076,TaskRequest,ADDED,eval-sanitize-2-r3-070,phase=None job=None
70.0113,TaskRequest,MODIFIED,eval-sanitize-2-r3-070,phase=Pending job=None
70.0279,Job,ADDED,eval-sanitize-2-r3-070,
70.0353,Pod,ADDED,eval-sanitize-2-r3-070-cvm92,phase=Pending node=None
70.0353,TaskRequest,MODIFIED,eval-sanitize-2-r3-070,phase=Scheduled job=None
70.038,Job,MODIFIED,eval-sanitize-2-r3-070,
70.0425,Event,ADDED,eval-sanitize-2-r3-070.18d3d197bf1bf8f9,reason=SuccessfulCreate count=1 msg=Created pod: eval-sanitize-2-r3-070-cvm92
70.0434,Job,MODIFIED,eval-sanitize-2-r3-069,
70.0453,TaskRequest,MODIFIED,eval-sanitize-2-r3-070,phase=Scheduled job=None
70.0476,Node,MODIFIED,kind-worker2,taints=1
70.0487,Pod,MODIFIED,eval-sanitize-2-r3-070-cvm92,phase=Pending node=kind-worker
70.0496,Job,MODIFIED,eval-sanitize-2-r3-068,
70.0501,Event,ADDED,eval-sanitize-2-r3-070-cvm92.18d3d197bfc1ec07,reason=Scheduled count=None msg=Successfully assigned compute/eval-sanitize-2-r3-070-cvm92 to kind-worker
70.0529,Job,MODIFIED,eval-sanitize-2-r3-069,
70.0564,Node,MODIFIED,kind-worker,taints=0
70.0585,Pod,MODIFIED,eval-sanitize-2-r3-070-cvm92,phase=Pending node=kind-worker
70.0595,Job,MODIFIED,eval-sanitize-2-r3-068,
70.1502,Node,MODIFIED,kind-worker,taints=0
70.4669,Event,ADDED,eval-sanitize-2-r3-070-cvm92.18d3d197d877706b,"reason=Pulled count=1 msg=Container image ""busybox:musl"" already present on machine"
70.4873,Pod,MODIFIED,eval-sanitize-2-r3-059-dw2kg,phase=Running node=kind-worker5
70.4882,Event,ADDED,eval-sanitize-2-r3-070-cvm92.18d3d197d9ba1c53,reason=Created count=1 msg=Created container: task
70.5004,Pod,MODIFIED,eval-sanitize-2-r3-056-jjtbf,phase=Running node=kind-worker5
70.5086,Pod,MODIFIED,eval-sanitize-2-r3-050-mkhrs,phase=Running node=kind-worker5
70.5266,Event,ADDED,eval-sanitize-2-r3-070-cvm92.18d3d197dc3066e8,reason=Started count=1 msg=Started container task
70.6448,Pod,MODIFIED,eval-sanitize-2-r3-070-cvm92,phase=Running node=kind-worker
70.6572,Node,MODIFIED,kind-worker,taints=1
70.9559,Node,MODIFIED,kind-worker,taints=1
71.0083,TaskRequest,ADDED,eval-sanitize-2-r3-071,phase=None job=None
71.0124,TaskRequest,MODIFIED,eval-sanitize-2-r3-071,phase=Pending job=None
71.0278,Job,ADDED,eval-sanitize-2-r3-071,
71.0353,Pod,ADDED,eval-sanitize-2-r3-071-22nf4,phase=Pending node=None
71.0355,TaskRequest,MODIFIED,eval-sanitize-2-r3-071,phase=Scheduled job=None
71.0373,Job,MODIFIED,eval-sanitize-2-r3-071,
71.0395,Job,MODIFIED,eval-sanitize-2-r3-070,
71.0415,Event,ADDED,eval-sanitize-2-r3-071.18d3d197fab6a145,reason=SuccessfulCreate count=1 msg=Created pod: eval-sanitize-2-r3-071-22nf4
71.0417,Event,ADDED,eval-sanitize-2-r3-071-22nf4.18d3d197fac5f009,"reason=FailedScheduling count=None msg=0/6 nodes are available: 6 node(s) had untolerated taint(s). no new claims to deallocate, preemption: 0/6 nodes are available: 6 Preemption is not helpful for scheduling."
71.0426,Pod,MODIFIED,eval-sanitize-2-r3-071-22nf4,phase=Pending node=None
71.0427,TaskRequest,MODIFIED,eval-sanitize-2-r3-071,phase=Scheduled job=None
71.0481,Job,MODIFIED,eval-sanitize-2-r3-070,
71.4934,Pod,MODIFIED,eval-sanitize-2-r3-060-58r7q,phase=Running node=kind-worker5
71.4943,Job,MODIFIED,eval-sanitize-2-r3-059,
71.5029,Job,MODIFIED,eval-sanitize-2-r3-059,
71.5048,Job,MODIFIED,eval-sanitize-2-r3-056,
71.512,Job,MODIFIED,eval-sanitize-2-r3-050,
71.5141,Job,MODIFIED,eval-sanitize-2-r3-056,
71.5206,Job,MODIFIED,eval-sanitize-2-r3-050,
71.53,Pod,MODIFIED,eval-sanitize-2-r3-058-sqvr7,phase=Running node=kind-worker4
71.7301,Pod,MODIFIED,eval-sanitize-2-r3-056-jjtbf,phase=Succeeded node=kind-worker5
71.736,Pod,MODIFIED,eval-sanitize-2-r3-050-mkhrs,phase=Succeeded node=kind-worker5
71.7778,Pod,MODIFIED,eval-sanitize-2-r3-059-dw2kg,phase=Succeeded node=kind-worker5
72.0083,TaskRequest,ADDED,eval-sanitize-2-r3-072,phase=None job=None
72.0119,TaskRequest,MODIFIED,eval-sanitize-2-r3-072,phase=Pending job=None
72.0269,Job,ADDED,eval-sanitize-2-r3-072,
72.033,Pod,ADDED,eval-sanitize-2-r3-072-sggsm,phase=Pending node=None
72.0345,TaskRequest,MODIFIED,eval-sanitize-2-r3-072,phase=Scheduled job=None
72.0353,Job,MODIFIED,eval-sanitize-2-r3-072,
72.0408,Event,ADDED,eval-sanitize-2-r3-072.18d3d19836333719,reason=SuccessfulCreate count=1 msg=Created pod: eval-sanitize-2-r3-072-sggsm
72.0411,Event,ADDED,eval-sanitize-2-r3-072-sggsm.18d3d198363b46c4,"reason=FailedScheduling count=None msg=0/6 nodes are available: 6 node(s) had untolerated taint(s). no new claims to deallocate, preemption: 0/6 nodes are available: 6 Preemption is not helpful for scheduling."
72.042,Job,MODIFIED,eval-sanitize-2-r3-071,
72.0427,Pod,MODIFIED,eval-sanitize-2-r3-072-sggsm,phase=Pending node=None
72.0429,TaskRequest,MODIFIED,eval-sanitize-2-r3-072,phase=Scheduled job=None
72.0493,Job,MODIFIED,eval-sanitize-2-r3-071,
72.3141,Event,MODIFIED,eval-sanitize-2-r3-057-rhvv7.18d3d195a4e391d6,"reason=FailedScheduling count=None msg=0/6 nodes are available: 2 c_wall violated: 1 conflicting context pair(s) with node memory, 4 node(s) had untolerated taint(s). no new claims to deallocate, preemption: 0/6 nodes are available: 2 No preemption victims found for incoming pod, 4 Preemption is not helpful for scheduling."
72.4984,Pod,MODIFIED,eval-sanitize-2-r3-061-4f8sq,phase=Running node=kind-worker5
72.4993,Job,MODIFIED,eval-sanitize-2-r3-060,
72.5011,Job,MODIFIED,eval-sanitize-2-r3-059,
72.5088,Job,MODIFIED,eval-sanitize-2-r3-060,
72.5118,Pod,MODIFIED,eval-sanitize-2-r3-059-dw2kg,phase=Succeeded node=kind-worker5
72.513,Job,MODIFIED,eval-sanitize-2-r3-056,
72.5141,Job,MODIFIED,eval-sanitize-2-r3-059,
72.5175,Job,MODIFIED,eval-sanitize-2-r3-050,
72.5228,Pod,MODIFIED,eval-sanitize-2-r3-056-jjtbf,phase=Succeeded node=kind-worker5
72.5241,Job,MODIFIED,eval-sanitize-2-r3-056,
72.5265,Pod,MODIFIED,eval-sanitize-2-r3-050-mkhrs,phase=Succeeded node=kind-worker5
72.5278,Job,MODIFIED,eval-sanitize-2-r3-050,
72.5334,Job,MODIFIED,eval-sanitize-2-r3-058,
72.5423,Job,MODIFIED,eval-sanitize-2-r3-058,
72.6422,Pod,MODIFIED,eval-sanitize-2-r3-060-58r7q,phase=Succeeded node=kind-worker5
72.7583,Pod,MODIFIED,eval-sanitize-2-r3-058-sqvr7,phase=Succeeded node=kind-worker4
73.0091,TaskRequest,ADDED,eval-sanitize-2-r3-073,phase=None job=None
73.0133,TaskRequest,MODIFIED,eval-sanitize-2-r3-073,phase=Pending job=None
73.0267,Job,ADDED,eval-sanitize-2-r3-073,
73.0304,TaskRequest,MODIFIED,eval-sanitize-2-r3-073,phase=Scheduled job=None
73.0341,Pod,ADDED,eval-sanitize-2-r3-073-xwrpv,phase=Pending node=None
73.036,Job,MODIFIED,eval-sanitize-2-r3-073,
73.0401,TaskRequest,MODIFIED,eval-sanitize-2-r3-073,phase=Scheduled job=None
73.0405,Event,ADDED,eval-sanitize-2-r3-073.18d3d19871df2f06,reason=SuccessfulCreate count=1 msg=Created pod: eval-sanitize-2-r3-073-xwrpv
73.0407,Event,ADDED,eval-sanitize-2-r3-073-xwrpv.18d3d19871eb380f,"reason=FailedScheduling count=None msg=0/6 nodes are available: 6 node(s) had untolerated taint(s). no new claims to deallocate, preemption: 0/6 nodes are available: 6 Preemption is not helpful for scheduling."
73.0416,Job,MODIFIED,eval-sanitize-2-r3-072,
73.0424,Pod,MODIFIED,eval-sanitize-2-r3-073-xwrpv,phase=Pending node=None
73.0499,Job,MODIFIED,eval-sanitize-2-r3-072,
73.4626,Event,MODIFIED,eval-sanitize-2-r3-057-rhvv7.18d3d195b9d711ab,"reason=FailedScheduling count=None msg=0/6 nodes are available: 1 c_wall violated: 1 conflicting context pair(s) with node memory, 5 node(s) had untolerated taint(s). no new claims to deallocate, preemption: 0/6 nodes are available: 1 No preemption victims found for incoming pod, 5 Preemption is not helpful for scheduling."
73.4739,Pod,MODIFIED,eval-sanitize-2-r3-057-rhvv7,phase=Running node=kind-worker3
73.5036,Job,MODIFIED,eval-sanitize-2-r3-061,
73.5058,Job,MODIFIED,eval-sanitize-2-r3-060,
73.5074,Job,MODIFIED,eval-sanitize-2-r3-059,
73.5127,Job,MODIFIED,eval-sanitize-2-r3-059,
73.5144,Job,MODIFIED,eval-sanitize-2-r3-061,
73.519,Pod,MODIFIED,eval-sanitize-2-r3-060-58r7q,phase=Succeeded node=kind-worker5
73.5215,Event,ADDED,eval-sanitize-2-r3-059.18d3d1988e63e26f,reason=Completed count=1 msg=Job completed
73.5224,Job,MODIFIED,eval-sanitize-2-r3-056,
73.5233,Job,MODIFIED,eval-sanitize-2-r3-060,
73.5246,Job,MODIFIED,eval-sanitize-2-r3-050,
73.5274,Job,MODIFIED,eval-sanitize-2-r3-056,
73.5301,Job,MODIFIED,eval-sanitize-2-r3-050,
73.531,Job,MODIFIED,eval-sanitize-2-r3-059,
73.5313,Event,ADDED,eval-sanitize-2-r3-056.18d3d1988f42edbe,reason=Completed count=1 msg=Job completed
73.5345,Job,MODIFIED,eval-sanitize-2-r3-056,
73.5377,Event,ADDED,eval-sanitize-2-r3-050.18d3d1988f70a0ea,reason=Completed count=1 msg=Job completed
73.5386,Job,MODIFIED,eval-sanitize-2-r3-058,
73.541,Pod,MODIFIED,eval-sanitize-2-r3-062-bjbxn,phase=Running node=kind-worker4
73.5433,Job,MODIFIED,eval-sanitize-2-r3-050,
73.547,Pod,MODIFIED,eval-sanitize-2-r3-058-sqvr7,phase=Succeeded node=kind-worker4
73.5513,Job,MODIFIED,eval-sanitize-2-r3-058,
73.5543,Event,ADDED,eval-sanitize-2-r3-058.18d3d19890b55727,reason=Completed count=1 msg=Job completed
73.5693,TaskRequest,MODIFIED,eval-sanitize-2-r3-059,phase=Complete job=None
73.5932,Pod,MODIFIED,eval-sanitize-2-r3-061-4f8sq,phase=Succeeded node=kind-worker5
73.6118,TaskRequest,MODIFIED,eval-sanitize-2-r3-056,phase=Complete job=None
73.6167,TaskRequest,MODIFIED,eval-sanitize-2-r3-050,phase=Complete job=None
73.6196,Job,MODIFIED,eval-sanitize-2-r3-059,
73.6217,Job,MODIFIED,eval-sanitize-2-r3-056,
73.6235,Job,MODIFIED,eval-sanitize-2-r3-058,
73.6256,Job,MODIFIED,eval-sanitize-2-r3-050,
73.6284,TaskRequest,MODIFIED,eval-sanitize-2-r3-058,phase=Complete job=None
73.6371,Job,MODIFIED,eval-sanitize-2-r3-058,
73.862,Event,MODIFIED,eval-sanitize-2-r3-057-rhvv7.18d3d195e3579eba,"reason=FailedScheduling count=None msg=0/6 nodes are available: 1 c_wall violated: 2 conflicting context pair(s) with node memory, 5 node(s) had untolerated taint(s). no new claims to deallocate, preemption: 0/6 nodes are available: 1 No preemption victims found for incoming pod, 5 Preemption is not helpful for scheduling."
74.0078,TaskRequest,ADDED,eval-sanitize-2-r3-074,phase=None job=None
74.0117,TaskRequest,MODIFIED,eval-sanitize-2-r3-074,phase=Pending job=None
74.0267,Job,ADDED,eval-sanitize-2-r3-074,
74.0305,TaskRequest,MODIFIED,eval-sanitize-2-r3-074,phase=Scheduled job=None
74.034,Pod,ADDED,eval-sanitize-2-r3-074-92n94,phase=Pending node=None
74.036,Job,MODIFIED,eval-sanitize-2-r3-074,
74.0401,Event,ADDED,eval-sanitize-2-r3-074.18d3d198ad73c889,reason=SuccessfulCreate count=1 msg=Created pod: eval-sanitize-2-r3-074-92n94
74.0405,Event,ADDED,eval-sanitize-2-r3-074-92n94.18d3d198ad7eaec2,"reason=FailedScheduling count=None msg=0/6 nodes are available: 6 node(s) had untolerated taint(s). no new claims to deallocate, preemption: 0/6 nodes are available: 6 Preemption is not helpful for scheduling."
74.0406,TaskRequest,MODIFIED,eval-sanitize-2-r3-074,phase=Scheduled job=None
74.0414,Job,MODIFIED,eval-sanitize-2-r3-073,
74.0421,Pod,MODIFIED,eval-sanitize-2-r3-074-92n94,phase=Pending node=None
74.0496,Job,MODIFIED,eval-sanitize-2-r3-073,
74.4516,Node,MODIFIED,kind-worker5,taints=1
74.4637,Node,MODIFIED,kind-worker5,taints=1
74.4765,Node,MODIFIED,kind-worker5,taints=0
74.479,Pod,MODIFIED,eval-sanitize-2-r3-063-4v862,phase=Running node=kind-worker3
74.4816,Job,MODIFIED,eval-sanitize-2-r3-057,
74.4841,Pod,MODIFIED,eval-sanitize-2-r3-071-22nf4,phase=Pending node=kind-worker5
74.4863,Pod,MODIFIED,eval-sanitize-2-r3-072-sggsm,phase=Pending node=kind-worker5
74.4917,Node,MODIFIED,kind-worker5,taints=0
74.4936,Event,ADDED,eval-sanitize-2-r3-071-22nf4.18d3d198c847c5a6,reason=Scheduled count=None msg=Successfully assigned compute/eval-sanitize-2-r3-071-22nf4 to kind-worker5
74.4946,Job,MODIFIED,eval-sanitize-2-r3-057,
74.495,Event,ADDED,eval-sanitize-2-r3-072-sggsm.18d3d198c8751cd6,reason=Scheduled count=None msg=Successfully assigned compute/eval-sanitize-2-r3-072-sggsm to kind-worker5
74.496,Pod,MODIFIED,eval-sanitize-2-r3-073-xwrpv,phase=Pending node=kind-worker5
74.5003,Event,ADDED,eval-sanitize-2-r3-074-92n94.18d3d198c88d5da7,"reason=FailedScheduling count=None msg=0/6 nodes are available: 1 c_wall violated: 1 conflicting context pair(s) with node memory, 5 node(s) had untolerated taint(s). no new claims to deallocate, preemption: 0/6 nodes are available: 1 No preemption victims found for incoming pod, 5 Preemption is not helpful for scheduling."
74.5021,Pod,MODIFIED,eval-sanitize-2-r3-074-92n94,phase=Pending node=None
74.5026,Event,ADDED,eval-sanitize-2-r3-073-xwrpv.18d3d198c8e44c7a,reason=Scheduled count=None msg=Successfully assigned compute/eval-sanitize-2-r3-073-xwrpv to kind-worker5
74.5042,Pod,MODIFIED,eval-sanitize-2-r3-071-22nf4,phase=Pending node=kind-worker5
74.5096,Job,MODIFIED,eval-sanitize-2-r3-061,
74.5149,Pod,MODIFIED,eval-sanitize-2-r3-072-sggsm,phase=Pending node=kind-worker5
74.5154,Event,MODIFIED,eval-sanitize-2-r3-074-92n94.18d3d198c88d5da7,"reason=FailedScheduling count=None msg=0/6 nodes are available: 1 c_wall violated: 1 conflicting context pair(s) with node memory, 5 node(s) had untolerated taint(s). no new claims to deallocate, preemption: 0/6 nodes are available: 1 No preemption victims found for incoming pod, 5 Preemption is not helpful for scheduling."
74.5168,Node,MODIFIED,kind-worker5,taints=0
74.5181,Job,MODIFIED,eval-sanitize-2-r3-060,
74.5202,Pod,MODIFIED,eval-sanitize-2-r3-061-4f8sq,phase=Succeeded node=kind-worker5
74.5214,Job,MODIFIED,eval-sanitize-2-r3-060,
74.5226,Pod,MODIFIED,eval-sanitize-2-r3-073-xwrpv,phase=Pending node=kind-worker5
74.5238,Job,MODIFIED,eval-sanitize-2-r3-061,
74.5288,Node,MODIFIED,kind-worker5,taints=0
74.5294,Event,ADDED,eval-sanitize-2-r3-060.18d3d198ca79ac2e,reason=Completed count=1 msg=Job completed
74.537,Job,MODIFIED,eval-sanitize-2-r3-060,
74.5439,Node,MODIFIED,kind-worker5,taints=0
74.5442,TaskRequest,MODIFIED,eval-sanitize-2-r3-060,phase=Complete job=None
74.5466,Job,MODIFIED,eval-sanitize-2-r3-062,
74.5536,Node,MODIFIED,kind-worker5,taints=0
74.5552,Job,MODIFIED,eval-sanitize-2-r3-060,
74.5559,Job,MODIFIED,eval-sanitize-2-r3-062,
74.5684,Pod,MODIFIED,eval-sanitize-2-r3-057-rhvv7,phase=Succeeded node=kind-worker3
74.5796,Event,ADDED,eval-sanitize-2-r3-074-92n94.18d3d198cdc7b794,"reason=FailedScheduling count=None msg=0/6 nodes are available: 1 c_wall violated: 1 conflicting context pair(s) with node memory, 5 node(s) had untolerated taint(s). no new claims to deallocate, preemption: 0/6 nodes are available: 1 No preemption victims found for incoming pod, 5 Preemption is not helpful for scheduling."
74.585,Event,MODIFIED,eval-sanitize-2-r3-074-92n94.18d3d198cdc7b794,"reason=FailedScheduling count=None msg=0/6 nodes are available: 1 c_wall violated: 1 conflicting context pair(s) with node memory, 5 node(s) had untolerated taint(s). no new claims to deallocate, preemption: 0/6 nodes are available: 1 No preemption victims found for incoming pod, 5 Preemption is not helpful for scheduling."
74.6939,Pod,MODIFIED,eval-sanitize-2-r3-062-bjbxn,phase=Succeeded node=kind-worker4
74.9233,Event,ADDED,eval-sanitize-2-r3-071-22nf4.18d3d198e2314ae7,"reason=Pulled count=1 msg=Container image ""busybox:musl"" already present on machine"
74.9276,Event,ADDED,eval-sanitize-2-r3-072-sggsm.18d3d198e26c9bbe,"reason=Pulled count=1 msg=Container image ""busybox:musl"" already present on machine"
74.9343,Event,ADDED,eval-sanitize-2-r3-073-xwrpv.18d3d198e29bfb7e,"reason=Pulled count=1 msg=Container image ""busybox:musl"" already present on machine"
74.9543,Event,ADDED,eval-sanitize-2-r3-071-22nf4.18d3d198e4136faa,reason=Created count=1 msg=Created container: task
74.9603,Event,ADDED,eval-sanitize-2-r3-072-sggsm.18d3d198e475ddfe,reason=Created count=1 msg=Created container: task
74.964,Event,ADDED,eval-sanitize-2-r3-073-xwrpv.18d3d198e4a8c702,reason=Created count=1 msg=Created container: task
75.0089,TaskRequest,ADDED,eval-sanitize-2-r3-075,phase=None job=None
75.0146,TaskRequest,MODIFIED,eval-sanitize-2-r3-075,phase=Pending job=None
75.0307,Job,ADDED,eval-sanitize-2-r3-075,
75.0376,TaskRequest,MODIFIED,eval-sanitize-2-r3-075,phase=Scheduled job=None
75.0416,Event,ADDED,eval-sanitize-2-r3-071-22nf4.18d3d198e9099374,reason=Started count=1 msg=Started container task
75.0429,Job,MODIFIED,eval-sanitize-2-r3-074,
75.0437,Pod,ADDED,eval-sanitize-2-r3-075-266p5,phase=Pending node=None
75.0443,Job,MODIFIED,eval-sanitize-2-r3-075,
75.0469,TaskRequest,MODIFIED,eval-sanitize-2-r3-075,phase=Scheduled job=None
75.0479,Event,ADDED,eval-sanitize-2-r3-072-sggsm.18d3d198e9749051,reason=Started count=1 msg=Started container task
75.0483,Event,ADDED,eval-sanitize-2-r3-075.18d3d198e98d1a4d,reason=SuccessfulCreate count=1 msg=Created pod: eval-sanitize-2-r3-075-266p5
75.0511,Pod,MODIFIED,eval-sanitize-2-r3-075-266p5,phase=Pending node=None
75.0527,Event,ADDED,eval-sanitize-2-r3-075-266p5.18d3d198e9d5e48f,"reason=FailedScheduling count=None msg=0/6 nodes are available: 1 c_wall violated: 1 conflicting context pair(s) with node memory, 5 node(s) had untolerated taint(s). no new claims to deallocate, preemption: 0/6 nodes are available: 1 No preemption victims found for incoming pod, 5 Preemption is not helpful for scheduling."
75.0536,Job,MODIFIED,eval-sanitize-2-r3-074,
75.0541,Event,ADDED,eval-sanitize-2-r3-073-xwrpv.18d3d198e9b337b3,reason=Started count=1 msg=Started container task
75.0581,Event,ADDED,eval-sanitize-2-r3-075-266p5.18d3d198ea567a88,"reason=FailedScheduling count=None msg=0/6 nodes are available: 1 c_wall violated: 1 conflicting context pair(s) with node memory, 5 node(s) had untolerated taint(s). no new claims to deallocate, preemption: 0/6 nodes are available: 1 No preemption victims found for incoming pod, 5 Preemption is not helpful for scheduling."
75.4839,Job,MODIFIED,eval-sanitize-2-r3-063,
75.4868,Job,MODIFIED,eval-sanitize-2-r3-057,
75.4937,Job,MODIFIED,eval-sanitize-2-r3-063,
75.496,Job,MODIFIED,eval-sanitize-2-r3-057,
75.4976,Pod,MODIFIED,eval-sanitize-2-r3-057-rhvv7,phase=Succeeded node=kind-worker3
75.5108,Pod,MODIFIED,eval-sanitize-2-r3-072-sggsm,phase=Running node=kind-worker5
75.5146,Job,MODIFIED,eval-sanitize-2-r3-061,
75.5201,Pod,MODIFIED,eval-sanitize-2-r3-073-xwrpv,phase=Running node=kind-worker5
75.5211,Job,MODIFIED,eval-sanitize-2-r3-061,
75.5225,Event,MODIFIED,eval-sanitize-2-r3-075-266p5.18d3d198ea567a88,"reason=FailedScheduling count=None msg=0/6 nodes are available: 1 c_wall violated: 1 conflicting context pair(s) with node memory, 5 node(s) had untolerated taint(s). no new claims to deallocate, preemption: 0/6 nodes are available: 1 No preemption victims found for incoming pod, 5 Preemption is not helpful for scheduling."
75.5252,Event,ADDED,eval-sanitize-2-r3-061.18d3d199060a7712,reason=Completed count=1 msg=Job completed
75.5267,Pod,MODIFIED,eval-sanitize-2-r3-071-22nf4,phase=Running node=kind-worker5
75.5345,Job,MODIFIED,eval-sanitize-2-r3-061,
75.5393,TaskRequest,MODIFIED,eval-sanitize-2-r3-061,phase=Complete job=None
75.55,Job,MODIFIED,eval-sanitize-2-r3-061,
75.5521,Job,MODIFIED,eval-sanitize-2-r3-062,
75.5602,Pod,MODIFIED,eval-sanitize-2-r3-062-bjbxn,phase=Succeeded node=kind-worker4
75.5626,Job,MODIFIED,eval-sanitize-2-r3-062,
75.6133,Pod,MODIFIED,eval-sanitize-2-r3-063-4v862,phase=Succeeded node=kind-worker3
75.8446,Node,MODIFIED,kind-worker4,taints=1
75.8609,Node,MODIFIED,kind-worker4,taints=0
75.8687,Pod,MODIFIED,eval-sanitize-2-r3-074-92n94,phase=Pending node=kind-worker4
75.8709,Node,MODIFIED,kind-worker4,taints=0
75.8733,Pod,MODIFIED,eval-sanitize-2-r3-075-266p5,phase=Pending node=kind-worker4
75.8746,Event,ADDED,eval-sanitize-2-r3-074-92n94.18d3d1991ad09125,reason=Scheduled count=None msg=Successfully assigned compute/eval-sanitize-2-r3-074-92n94 to kind-worker4
75.8763,Event,ADDED,eval-sanitize-2-r3-075-266p5.18d3d1991b19c2c3,reason=Scheduled count=None msg=Successfully assigned compute/eval-sanitize-2-r3-075-266p5 to kind-worker4
75.8815,Pod,MODIFIED,eval-sanitize-2-r3-074-92n94,phase=Pending node=kind-worker4
75.8836,Node,MODIFIED,kind-worker4,taints=0
75.8873,Pod,MODIFIED,eval-sanitize-2-r3-075-266p5,phase=Pending node=kind-worker4
75.9168,Node,MODIFIED,kind-worker4,taints=0
75.9402,Node,MODIFIED,kind-worker4,taints=0
76.0204,TaskRequest,ADDED,eval-sanitize-2-r3-076,phase=None job=None
76.0239,TaskRequest,MODIFIED,eval-sanitize-2-r3-076,phase=Pending job=None
76.0397,Job,ADDED,eval-sanitize-2-r3-076,
76.0433,TaskRequest,MODIFIED,eval-sanitize-2-r3-076,phase=Scheduled job=None
76.0463,Job,MODIFIED,eval-sanitize-2-r3-075,
76.0474,Pod,ADDED,eval-sanitize-2-r3-076-zlwzd,phase=Pending node=None
76.0491,Job,MODIFIED,eval-sanitize-2-r3-076,
76.0522,TaskRequest,MODIFIED,eval-sanitize-2-r3-076,phase=Scheduled job=None
76.0531,Event,ADDED,eval-sanitize-2-r3-076.18d3d199257f79d2,reason=SuccessfulCreate count=1 msg=Created pod: eval-sanitize-2-r3-076-zlwzd
76.0557,Job,MODIFIED,eval-sanitize-2-r3-075,
76.059,Pod,MODIFIED,eval-sanitize-2-r3-076-zlwzd,phase=Pending node=None
76.0598,Event,ADDED,eval-sanitize-2-r3-076-zlwzd.18d3d19925e75e35,"reason=FailedScheduling count=None msg=0/6 nodes are available: 2 c_wall violated: 1 conflicting context pair(s) with node memory, 4 node(s) had untolerated taint(s). no new claims to deallocate, preemption: 0/6 nodes are available: 2 No preemption victims found for incoming pod, 4 Preemption is not helpful for scheduling."
76.0671,Event,ADDED,eval-sanitize-2-r3-076-zlwzd.18d3d199267e542f,"reason=FailedScheduling count=None msg=0/6 nodes are available: 2 c_wall violated: 1 conflicting context pair(s) with node memory, 4 node(s) had untolerated taint(s). no new claims to deallocate, preemption: 0/6 nodes are available: 2 No preemption victims found for incoming pod, 4 Preemption is not helpful for scheduling."
76.2877,Event,ADDED,eval-sanitize-2-r3-074-92n94.18d3d199338f48a9,"reason=Pulled count=1 msg=Container image ""busybox:musl"" already present on machine"
76.2918,Event,ADDED,eval-sanitize-2-r3-075-266p5.18d3d19933a99517,"reason=Pulled count=1 msg=Container image ""busybox:musl"" already present on machine"
76.3119,Event,ADDED,eval-sanitize-2-r3-074-92n94.18d3d19934e88121,reason=Created count=1 msg=Created container: task
76.3194,Event,ADDED,eval-sanitize-2-r3-075-266p5.18d3d199357e7331,reason=Created count=1 msg=Created container: task
76.3768,Event,ADDED,eval-sanitize-2-r3-074-92n94.18d3d19938de0272,reason=Started count=1 msg=Started container task
76.3804,Event,ADDED,eval-sanitize-2-r3-075-266p5.18d3d19938de027b,reason=Started count=1 msg=Started container task
76.4904,Job,MODIFIED,eval-sanitize-2-r3-063,
76.4922,Job,MODIFIED,eval-sanitize-2-r3-057,
76.4967,Job,MODIFIED,eval-sanitize-2-r3-057,
76.4995,Pod,MODIFIED,eval-sanitize-2-r3-063-4v862,phase=Succeeded node=kind-worker3
76.5008,Job,MODIFIED,eval-sanitize-2-r3-063,
76.5022,Event,ADDED,eval-sanitize-2-r3-057.18d3d199404395b3,reason=Completed count=1 msg=Job completed
76.5087,Job,MODIFIED,eval-sanitize-2-r3-057,
76.515,Job,MODIFIED,eval-sanitize-2-r3-072,
76.5161,TaskRequest,MODIFIED,eval-sanitize-2-r3-057,phase=Complete job=None
76.5231,Job,MODIFIED,eval-sanitize-2-r3-073,
76.525,Job,MODIFIED,eval-sanitize-2-r3-057,
76.5273,Job,MODIFIED,eval-sanitize-2-r3-072,
76.5298,Job,MODIFIED,eval-sanitize-2-r3-071,
76.5318,Job,MODIFIED,eval-sanitize-2-r3-073,
76.5378,Job,MODIFIED,eval-sanitize-2-r3-071,
76.5468,Pod,MODIFIED,eval-sanitize-2-r3-074-92n94,phase=Running node=kind-worker4
76.552,Node,MODIFIED,kind-worker5,taints=1
76.5552,Pod,MODIFIED,eval-sanitize-2-r3-075-266p5,phase=Running node=kind-worker4
76.5592,Job,MODIFIED,eval-sanitize-2-r3-062,
76.5634,Pod,MODIFIED,eval-sanitize-2-r3-076-zlwzd,phase=Pending node=None
