t_recv,kind,type,name,detail
0.0212,Node,ADDED,kind-control-plane,taints=1
0.0226,Node,ADDED,kind-worker,taints=0
0.024,Node,ADDED,kind-worker2,taints=0
0.0253,Node,ADDED,kind-worker3,taints=0
0.0264,Node,ADDED,kind-worker4,taints=0
0.0276,Node,ADDED,kind-worker5,taints=0
0.0388,TaskRequest,ADDED,eval-sanitize-60-r2-000,phase=None job=None
0.0426,TaskRequest,MODIFIED,eval-sanitize-60-r2-000,phase=Pending job=None
0.0542,Event,ADDED,eval-sanitize-30-r0-009.18d4aaf6cb8d190f,reason=Completed count=1 msg=Job completed
0.0546,Event,ADDED,eval-sanitize-30-r0-010.18d4aaf728da063a,reason=Completed count=1 msg=Job completed
0.0548,Event,ADDED,eval-sanitize-30-r0-011.18d4aaf7555057c9,reason=Completed count=1 msg=Job completed
0.0551,Event,ADDED,eval-sanitize-30-r0-012-44c56.18d4aaf1d37f25f5,"reason=FailedScheduling count=None msg=0/6 nodes are available: 1 c_wall violated: 1 conflicting context pair(s) with node memory, 5 node(s) had untolerated taint(s). no new claims to deallocate, preemption: 0/6 nodes are available: 1 No preemption victims found for incoming pod, 5 Preemption is not helpful for scheduling."
0.0553,Event,ADDED,eval-sanitize-30-r0-012-44c56.18d4aaf20f499ae4,"reason=FailedScheduling count=None msg=0/6 nodes are available: 1 c_wall violated: 2 conflicting context pair(s) with node memory, 5 node(s) had untolerated taint(s). no new claims to deallocate, preemption: 0/6 nodes are available: 1 No preemption victims found for incoming pod, 5 Preemption is not helpful for scheduling."
0.0558,Event,ADDED,eval-sanitize-30-r0-012-44c56.18d4aaf8119a0d71,"reason=Pulled count=1 msg=Container image ""busybox:musl"" already present on machine"
0.056,Event,ADDED,eval-sanitize-30-r0-012-44c56.18d4aaf81380bd7a,reason=Created count=1 msg=Created container: task
0.0561,Event,ADDED,eval-sanitize-30-r0-012-44c56.18d4aaf816a0a00a,reason=Started count=1 msg=Started container task
0.0565,Event,ADDED,eval-sanitize-30-r0-012.18d4aafd3c48ee3f,reason=Completed count=1 msg=Job completed
0.0568,Event,ADDED,eval-sanitize-30-r0-013.18d4aaf7cd622cc9,reason=Completed count=1 msg=Job completed
0.057,Event,ADDED,eval-sanitize-30-r0-014.18d4aaf80a4c8b22,reason=Completed count=1 msg=Job completed
0.0572,Event,ADDED,eval-sanitize-30-r0-015-bxc9z.18d4aaf286602940,"reason=FailedScheduling count=None msg=0/6 nodes are available: 1 c_wall violated: 1 conflicting context pair(s) with node memory, 5 node(s) had untolerated taint(s). no new claims to deallocate, preemption: 0/6 nodes are available: 1 No preemption victims found for incoming pod, 5 Preemption is not helpful for scheduling."
0.0576,Event,ADDED,eval-sanitize-30-r0-015-bxc9z.18d4aaf816711043,"reason=Pulled count=1 msg=Container image ""busybox:musl"" already present on machine"
0.0578,Event,ADDED,eval-sanitize-30-r0-015-bxc9z.18d4aaf818a1da0b,reason=Created count=1 msg=Created container: task
0.0579,Event,ADDED,eval-sanitize-30-r0-015-bxc9z.18d4aaf81e15a879,reason=Started count=1 msg=Started container task
0.0583,Event,ADDED,eval-sanitize-30-r0-015.18d4aafd799c5227,reason=Completed count=1 msg=Job completed
0.0585,Event,ADDED,eval-sanitize-30-r0-016.18d4aaf88139285c,reason=Completed count=1 msg=Job completed
0.0587,Event,ADDED,eval-sanitize-30-r0-017-mbsqh.18d4aaf2fd629ed1,"reason=FailedScheduling count=None msg=0/6 nodes are available: 1 c_wall violated: 1 conflicting context pair(s) with node memory, 5 node(s) had untolerated taint(s). no new claims to deallocate, preemption: 0/6 nodes are available: 1 No preemption victims found for incoming pod, 5 Preemption is not helpful for scheduling."
0.0589,Event,ADDED,eval-sanitize-30-r0-017-mbsqh.18d4aaf8a7b8bcbe,"reason=Pulled count=1 msg=Container image ""busybox:musl"" already present on machine"
0.0593,Event,ADDED,eval-sanitize-30-r0-017-mbsqh.18d4aaf8a9314dfb,reason=Created count=1 msg=Created container: task
0.0595,Event,ADDED,eval-sanitize-30-r0-017-mbsqh.18d4aaf8ad66979b,reason=Started count=1 msg=Started container task
0.0597,Event,ADDED,eval-sanitize-30-r0-017.18d4aafeb72ea8cf,reason=Completed count=1 msg=Job completed
0.0602,Event,ADDED,eval-sanitize-30-r0-018-4qxvc.18d4aaf33913191b,"reason=FailedScheduling count=None msg=0/6 nodes are available: 1 c_wall violated: 2 conflicting context pair(s) with node memory, 5 node(s) had untolerated taint(s). no new claims to deallocate, preemption: 0/6 nodes are available: 1 No preemption victims found for incoming pod, 5 Preemption is not helpful for scheduling."
0.0604,Event,ADDED,eval-sanitize-30-r0-018-4qxvc.18d4aaf86c516fc5,"reason=Pulled count=1 msg=Container image ""busybox:musl"" already present on machine"
0.0606,Event,ADDED,eval-sanitize-30-r0-018-4qxvc.18d4aaf86e4508a6,reason=Created count=1 msg=Created container: task
0.0608,Event,ADDED,eval-sanitize-30-r0-018-4qxvc.18d4aaf871893599,reason=Started count=1 msg=Started container task
0.0612,Event,ADDED,eval-sanitize-30-r0-018.18d4aafeab39fd67,reason=Completed count=1 msg=Job completed
0.0615,Event,ADDED,eval-sanitize-30-r0-019.18d4aaf9380f9f26,reason=Completed count=1 msg=Job completed
0.0617,Event,ADDED,eval-sanitize-30-r0-020-44mcn.18d4aaf3afd66737,"reason=FailedScheduling count=None msg=0/6 nodes are available: 1 c_wall violated: 1 conflicting context pair(s) with node memory, 5 node(s) had untolerated taint(s). no new claims to deallocate, preemption: 0/6 nodes are available: 1 No preemption victims found for incoming pod, 5 Preemption is not helpful for scheduling."
0.0625,Job,ADDED,eval-sanitize-60-r2-000,
0.0628,Event,ADDED,eval-sanitize-30-r0-020-44mcn.18d4aaf811fe58b1,"reason=Pulled count=1 msg=Container image ""busybox:musl"" already present on machine"
0.063,Event,ADDED,eval-sanitize-30-r0-020-44mcn.18d4aaf813d5bf11,reason=Created count=1 msg=Created container: task
0.0632,Event,ADDED,eval-sanitize-30-r0-020-44mcn.18d4aaf8172fa436,reason=Started count=1 msg=Started container task
0.0634,Event,ADDED,eval-sanitize-30-r0-020.18d4aafd3c6c28e7,reason=Completed count=1 msg=Job completed
0.0638,Event,ADDED,eval-sanitize-30-r0-021-5x5ds.18d4aaf3eb6d476d,"reason=FailedScheduling count=None msg=0/6 nodes are available: 1 c_wall violated: 1 conflicting context pair(s) with node memory, 5 node(s) had untolerated taint(s). no new claims to deallocate, preemption: 0/6 nodes are available: 1 No preemption victims found for incoming pod, 5 Preemption is not helpful for scheduling."
0.064,Event,ADDED,eval-sanitize-30-r0-021-5x5ds.18d4aaf879c4d2d5,"reason=Pulled count=1 msg=Container image ""busybox:musl"" already present on machine"
0.0642,Event,ADDED,eval-sanitize-30-r0-021-5x5ds.18d4aaf87afe5b3f,reason=Created count=1 msg=Created container: task
0.0645,Event,ADDED,eval-sanitize-30-r0-021-5x5ds.18d4aaf87e98b8e2,reason=Started count=1 msg=Started container task
0.0647,Event,ADDED,eval-sanitize-30-r0-021.18d4aafea24389af,reason=Completed count=1 msg=Job completed
0.0648,Event,ADDED,eval-sanitize-30-r0-022.18d4aaf9e59353e9,reason=Completed count=1 msg=Job completed
0.065,Event,ADDED,eval-sanitize-30-r0-023.18d4aafa2193a83c,reason=Completed count=1 msg=Job completed
0.0657,Event,ADDED,eval-sanitize-30-r0-024-8b4hc.18d4aaf49fcfa192,"reason=FailedScheduling count=None msg=0/6 nodes are available: 1 c_wall violated: 1 conflicting context pair(s) with node memory, 5 node(s) had untolerated taint(s). no new claims to deallocate, preemption: 0/6 nodes are available: 1 No preemption victims found for incoming pod, 5 Preemption is not helpful for scheduling."
0.066,Event,ADDED,eval-sanitize-30-r0-024-8b4hc.18d4aaf82f437f3a,"reason=FailedScheduling count=None msg=0/6 nodes are available: 2 c_wall violated: 1 conflicting context pair(s) with node memory, 4 node(s) had untolerated taint(s). no new claims to deallocate, preemption: 0/6 nodes are available: 2 No preemption victims found for incoming pod, 4 Preemption is not helpful for scheduling."
0.0663,Event,ADDED,eval-sanitize-30-r0-024-8b4hc.18d4aaf8b621173c,"reason=Pulled count=1 msg=Container image ""busybox:musl"" already present on machine"
0.0664,TaskRequest,MODIFIED,eval-sanitize-60-r2-000,phase=Scheduled job=None
0.0668,Event,ADDED,eval-sanitize-30-r0-024-8b4hc.18d4aaf8b7565c8d,reason=Created count=1 msg=Created container: task
0.0669,Event,ADDED,eval-sanitize-30-r0-024-8b4hc.18d4aaf8bbd8d23d,reason=Started count=1 msg=Started container task
0.0672,Event,ADDED,eval-sanitize-30-r0-024.18d4aafeba1dd0fc,reason=Completed count=1 msg=Job completed
0.0679,Event,ADDED,eval-sanitize-30-r0-025.18d4aafa98c8a0c1,reason=Completed count=1 msg=Job completed
0.0682,Event,ADDED,eval-sanitize-30-r0-026.18d4aafa9885c8bb,reason=Completed count=1 msg=Job completed
0.0685,Event,ADDED,eval-sanitize-30-r0-027-jstrl.18d4aaf552c1b99f,"reason=FailedScheduling count=None msg=0/6 nodes are available: 1 c_wall violated: 1 conflicting context pair(s) with node memory, 5 node(s) had untolerated taint(s). no new claims to deallocate, preemption: 0/6 nodes are available: 1 No preemption victims found for incoming pod, 5 Preemption is not helpful for scheduling."
0.0687,Event,ADDED,eval-sanitize-30-r0-027-jstrl.18d4aaf8607f69c5,"reason=Pulled count=1 msg=Container image ""busybox:musl"" already present on machine"
0.0691,Event,ADDED,eval-sanitize-30-r0-027-jstrl.18d4aaf861e6e92f,reason=Created count=1 msg=Created container: task
0.0694,Event,ADDED,eval-sanitize-30-r0-027-jstrl.18d4aaf86633adf6,reason=Started count=1 msg=Started container task
0.0696,Event,ADDED,eval-sanitize-30-r0-027.18d4aafe7b864ae6,reason=Completed count=1 msg=Job completed
0.0705,Pod,ADDED,eval-sanitize-60-r2-000-fl8q6,phase=Pending node=None
0.0708,Event,ADDED,eval-sanitize-30-r0-028-28l4p.18d4aaf59492e1e4,"reason=FailedScheduling count=None msg=0/6 nodes are available: 1 c_wall violated: 2 conflicting context pair(s) with node memory, 5 node(s) had untolerated taint(s). no new claims to deallocate, preemption: 0/6 nodes are available: 1 No preemption victims found for incoming pod, 5 Preemption is not helpful for scheduling."
0.071,Event,ADDED,eval-sanitize-30-r0-028-28l4p.18d4aaf835dc0040,"reason=Pulled count=1 msg=Container image ""busybox:musl"" already present on machine"
0.0713,Event,ADDED,eval-sanitize-30-r0-028-28l4p.18d4aaf8370d583c,reason=Created count=1 msg=Created container: task
0.0715,Event,ADDED,eval-sanitize-30-r0-028-28l4p.18d4aaf844bab5f1,reason=Started count=1 msg=Started container task
0.0723,Event,ADDED,eval-sanitize-30-r0-028.18d4aafd79bf1d73,reason=Completed count=1 msg=Job completed
0.073,Event,ADDED,eval-sanitize-30-r0-029.18d4aafb8f631dc0,reason=Completed count=1 msg=Job completed
0.0733,Event,ADDED,eval-sanitize-30-r0-030-qs6dp.18d4aaf606b0cdf9,"reason=FailedScheduling count=None msg=0/6 nodes are available: 1 c_wall violated: 1 conflicting context pair(s) with node memory, 5 node(s) had untolerated taint(s). no new claims to deallocate, preemption: 0/6 nodes are available: 1 No preemption victims found for incoming pod, 5 Preemption is not helpful for scheduling."
0.0738,Event,ADDED,eval-sanitize-30-r0-030-qs6dp.18d4aaf8280aa8dd,"reason=FailedScheduling count=None msg=0/6 nodes are available: 2 c_wall violated: 1 conflicting context pair(s) with node memory, 4 node(s) had untolerated taint(s). no new claims to deallocate, preemption: 0/6 nodes are available: 2 No preemption victims found for incoming pod, 4 Preemption is not helpful for scheduling."
0.074,Event,ADDED,eval-sanitize-30-r0-030-qs6dp.18d4aaf8aea5bb27,"reason=Pulled count=1 msg=Container image ""busybox:musl"" already present on machine"
0.0741,Event,ADDED,eval-sanitize-30-r0-030-qs6dp.18d4aaf8b03cbd4d,reason=Created count=1 msg=Created container: task
0.0743,Event,ADDED,eval-sanitize-30-r0-030-qs6dp.18d4aaf8b5a23e7f,reason=Started count=1 msg=Started container task
0.0751,Job,MODIFIED,eval-sanitize-60-r2-000,
0.0754,Event,ADDED,eval-sanitize-30-r0-030.18d4aafeb41dbaf5,reason=Completed count=1 msg=Job completed
0.0759,Event,ADDED,eval-sanitize-30-r0-031-s5n6z.18d4aaf64af71186,"reason=FailedScheduling count=None msg=0/6 nodes are available: 1 c_wall violated: 1 conflicting context pair(s) with node memory, 5 node(s) had untolerated taint(s). no new claims to deallocate, preemption: 0/6 nodes are available: 1 No preemption victims found for incoming pod, 5 Preemption is not helpful for scheduling."
0.076,Event,ADDED,eval-sanitize-30-r0-031-s5n6z.18d4aaf81d021ec6,"reason=Pulled count=1 msg=Container image ""busybox:musl"" already present on machine"
0.0764,Event,ADDED,eval-sanitize-30-r0-031-s5n6z.18d4aaf81ef8d322,reason=Created count=1 msg=Created container: task
0.0766,Event,ADDED,eval-sanitize-30-r0-031-s5n6z.18d4aaf823ed6a5d,reason=Started count=1 msg=Started container task
0.0768,Event,ADDED,eval-sanitize-30-r0-031.18d4aafdb36f5fa3,reason=Completed count=1 msg=Job completed
0.0775,Event,ADDED,eval-sanitize-30-r0-032-2x2j5.18d4aaf67f7f0e97,"reason=FailedScheduling count=None msg=0/6 nodes are available: 1 c_wall violated: 2 conflicting context pair(s) with node memory, 5 node(s) had untolerated taint(s). no new claims to deallocate, preemption: 0/6 nodes are available: 1 No preemption victims found for incoming pod, 5 Preemption is not helpful for scheduling."
0.0779,Event,ADDED,eval-sanitize-30-r0-032-2x2j5.18d4aaf81e1fcd3c,"reason=Pulled count=1 msg=Container image ""busybox:musl"" already present on machine"
0.0782,Event,ADDED,eval-sanitize-30-r0-032-2x2j5.18d4aaf8206f7efa,reason=Created count=1 msg=Created container: task
0.0785,Event,ADDED,eval-sanitize-30-r0-032-2x2j5.18d4aaf824904d01,reason=Started count=1 msg=Started container task
0.0787,TaskRequest,MODIFIED,eval-sanitize-60-r2-000,phase=Scheduled job=None
0.0791,Event,ADDED,eval-sanitize-30-r0-032.18d4aafd78febca4,reason=Completed count=1 msg=Job completed
0.0794,Event,ADDED,eval-sanitize-30-r0-033-8k2wg.18d4aaf6c3a3ae64,"reason=FailedScheduling count=None msg=0/6 nodes are available: 1 c_wall violated: 2 conflicting context pair(s) with node memory, 5 node(s) had untolerated taint(s). no new claims to deallocate, preemption: 0/6 nodes are available: 1 No preemption victims found for incoming pod, 5 Preemption is not helpful for scheduling."
0.0796,Event,ADDED,eval-sanitize-30-r0-033-8k2wg.18d4aaf8849283d1,"reason=Pulled count=1 msg=Container image ""busybox:musl"" already present on machine"
0.0802,Event,ADDED,eval-sanitize-30-r0-033-8k2wg.18d4aaf885c1ed6e,reason=Created count=1 msg=Created container: task
0.0804,Event,ADDED,eval-sanitize-30-r0-033-8k2wg.18d4aaf888006690,reason=Started count=1 msg=Started container task
0.0806,Event,ADDED,eval-sanitize-30-r0-033.18d4aaf6bc11439c,reason=SuccessfulCreate count=1 msg=Created pod: eval-sanitize-30-r0-033-8k2wg
0.0807,Event,ADDED,eval-sanitize-30-r0-033.18d4aafe90679e45,reason=Completed count=1 msg=Job completed
0.0811,Event,ADDED,eval-sanitize-30-r0-034-fq7lt.18d4aaf70d6fe024,"reason=Pulled count=1 msg=Container image ""busybox:musl"" already present on machine"
0.0813,Event,ADDED,eval-sanitize-30-r0-034-fq7lt.18d4aaf70edfdfba,reason=Created count=1 msg=Created container: task
0.0815,Event,ADDED,eval-sanitize-30-r0-034-fq7lt.18d4aaf712cfa887,reason=Started count=1 msg=Started container task
0.0816,Event,ADDED,eval-sanitize-30-r0-034.18d4aaf6f10ee6e5,reason=SuccessfulCreate count=1 msg=Created pod: eval-sanitize-30-r0-034-fq7lt
0.0818,Event,ADDED,eval-sanitize-30-r0-034.18d4aafc7bfe6a90,reason=Completed count=1 msg=Job completed
0.082,Event,ADDED,eval-sanitize-30-r0-035-m449r.18d4aaf72dbfb548,"reason=FailedScheduling count=None msg=0/6 nodes are available: 1 c_wall violated: 1 conflicting context pair(s) with node memory, 5 node(s) had untolerated taint(s). no new claims to deallocate, preemption: 0/6 nodes are available: 1 No preemption victims found for incoming pod, 5 Preemption is not helpful for scheduling."
0.0822,Event,ADDED,eval-sanitize-30-r0-035-m449r.18d4aaf865dc0453,"reason=Pulled count=1 msg=Container image ""busybox:musl"" already present on machine"
0.0826,Event,ADDED,eval-sanitize-30-r0-035-m449r.18d4aaf8674b6e52,reason=Created count=1 msg=Created container: task
0.0831,Event,ADDED,eval-sanitize-30-r0-035-m449r.18d4aaf86b417422,reason=Started count=1 msg=Started container task
0.0834,Event,ADDED,eval-sanitize-30-r0-035.18d4aaf72c9342f5,reason=SuccessfulCreate count=1 msg=Created pod: eval-sanitize-30-r0-035-m449r
0.0836,Event,ADDED,eval-sanitize-30-r0-035.18d4aafe7e81b2a5,reason=Completed count=1 msg=Job completed
0.084,Event,ADDED,eval-sanitize-30-r0-036-lgt9v.18d4aaf76b3ee20b,"reason=FailedScheduling count=None msg=0/6 nodes are available: 1 c_wall violated: 3 conflicting context pair(s) with node memory, 5 node(s) had untolerated taint(s). no new claims to deallocate, preemption: 0/6 nodes are available: 1 No preemption victims found for incoming pod, 5 Preemption is not helpful for scheduling."
0.0842,Event,ADDED,eval-sanitize-30-r0-036-lgt9v.18d4aaf825301518,"reason=Pulled count=1 msg=Container image ""busybox:musl"" already present on machine"
0.0843,Event,ADDED,eval-sanitize-30-r0-036-lgt9v.18d4aaf8265cc510,reason=Created count=1 msg=Created container: task
0.0854,Pod,MODIFIED,eval-sanitize-60-r2-000-fl8q6,phase=Pending node=kind-worker3
0.0858,Event,ADDED,eval-sanitize-30-r0-036-lgt9v.18d4aaf82db3e4af,reason=Started count=1 msg=Started container task
0.086,Event,ADDED,eval-sanitize-30-r0-036.18d4aaf768378c2d,reason=SuccessfulCreate count=1 msg=Created pod: eval-sanitize-30-r0-036-lgt9v
0.0862,Event,ADDED,eval-sanitize-30-r0-036.18d4aafdb329a69f,reason=Completed count=1 msg=Job completed
0.0866,Event,ADDED,eval-sanitize-30-r0-037-sj4b5.18d4aaf7a6ca22d4,"reason=FailedScheduling count=None msg=0/6 nodes are available: 1 c_wall violated: 1 conflicting context pair(s) with node memory, 5 node(s) had untolerated taint(s). no new claims to deallocate, preemption: 0/6 nodes are available: 1 No preemption victims found for incoming pod, 5 Preemption is not helpful for scheduling."
0.0868,Event,ADDED,eval-sanitize-30-r0-037-sj4b5.18d4aaf82dbe7890,"reason=Pulled count=1 msg=Container image ""busybox:musl"" already present on machine"
0.087,Event,ADDED,eval-sanitize-30-r0-037-sj4b5.18d4aaf82f6525d5,reason=Created count=1 msg=Created container: task
0.0872,Event,ADDED,eval-sanitize-30-r0-037-sj4b5.18d4aaf834bec6fa,reason=Started count=1 msg=Started container task
0.0876,Event,ADDED,eval-sanitize-30-r0-037.18d4aaf7a4eed793,reason=SuccessfulCreate count=1 msg=Created pod: eval-sanitize-30-r0-037-sj4b5
0.0878,Event,ADDED,eval-sanitize-30-r0-037.18d4aafd785569ec,reason=Completed count=1 msg=Job completed
0.088,Event,ADDED,eval-sanitize-30-r0-038-xtd5k.18d4aaf7fafdc7f8,"reason=Pulled count=1 msg=Container image ""busybox:musl"" already present on machine"
0.0881,Event,ADDED,eval-sanitize-30-r0-038-xtd5k.18d4aaf7fc419d5b,reason=Created count=1 msg=Created container: task
0.0886,Event,ADDED,eval-sanitize-30-r0-038-xtd5k.18d4aaf801afdda0,reason=Started count=1 msg=Started container task
0.0889,Event,ADDED,eval-sanitize-30-r0-038.18d4aaf7df4e7990,reason=SuccessfulCreate count=1 msg=Created pod: eval-sanitize-30-r0-038-xtd5k
0.0893,Event,ADDED,eval-sanitize-30-r0-038.18d4aafd680128c4,reason=Completed count=1 msg=Job completed
0.0896,Event,ADDED,eval-sanitize-30-r0-039-g7tcw.18d4aaf872322cb6,"reason=Pulled count=1 msg=Container image ""busybox:musl"" already present on machine"
0.0898,Event,ADDED,eval-sanitize-30-r0-039-g7tcw.18d4aaf874785f75,reason=Created count=1 msg=Created container: task
0.09,Event,ADDED,eval-sanitize-30-r0-039-g7tcw.18d4aaf8791f61f7,reason=Started count=1 msg=Started container task
0.0902,Event,ADDED,eval-sanitize-30-r0-039.18d4aaf81b974a40,reason=SuccessfulCreate count=1 msg=Created pod: eval-sanitize-30-r0-039-g7tcw
0.0905,Event,ADDED,eval-sanitize-30-r0-039.18d4aafea53e2438,reason=Completed count=1 msg=Job completed
0.0906,Event,ADDED,eval-sanitize-30-r0-040-g9qpp.18d4aaf879424e62,"reason=Pulled count=1 msg=Container image ""busybox:musl"" already present on machine"
0.0908,Event,ADDED,eval-sanitize-30-r0-040-g9qpp.18d4aaf87aba8016,reason=Created count=1 msg=Created container: task
0.091,Event,ADDED,eval-sanitize-30-r0-040-g9qpp.18d4aaf87eb0b921,reason=Started count=1 msg=Started container task
0.0913,Event,ADDED,eval-sanitize-30-r0-040.18d4aaf8568e250d,reason=SuccessfulCreate count=1 msg=Created pod: eval-sanitize-30-r0-040-g9qpp
0.0915,Event,ADDED,eval-sanitize-30-r0-040.18d4aafdb4b34b1d,reason=Completed count=1 msg=Job completed
0.0917,Event,ADDED,eval-sanitize-30-r0-041-qxcjt.18d4aaf8ae9d4cfb,"reason=Pulled count=1 msg=Container image ""busybox:musl"" already present on machine"
0.092,Event,ADDED,eval-sanitize-30-r0-041-qxcjt.18d4aaf8b016f51f,reason=Created count=1 msg=Created container: task
0.0922,Event,ADDED,eval-sanitize-30-r0-041-qxcjt.18d4aaf8b5975f24,reason=Started count=1 msg=Started container task
0.0924,Event,ADDED,eval-sanitize-30-r0-041.18d4aaf8920c62ed,reason=SuccessfulCreate count=1 msg=Created pod: eval-sanitize-30-r0-041-qxcjt
0.0929,Event,ADDED,eval-sanitize-30-r0-041.18d4aafeda7ee3e4,reason=Completed count=1 msg=Job completed
0.0934,Event,ADDED,eval-sanitize-30-r0-042-hkw9f.18d4aaf8eb0e6a0c,"reason=Pulled count=1 msg=Container image ""busybox:musl"" already present on machine"
0.0936,Event,ADDED,eval-sanitize-30-r0-042-hkw9f.18d4aaf8ec1d9eb9,reason=Created count=1 msg=Created container: task
0.0938,Event,ADDED,eval-sanitize-30-r0-042-hkw9f.18d4aaf8efdf93db,reason=Started count=1 msg=Started container task
0.094,Event,ADDED,eval-sanitize-30-r0-042.18d4aaf8cda0c7ff,reason=SuccessfulCreate count=1 msg=Created pod: eval-sanitize-30-r0-042-hkw9f
0.0944,Event,ADDED,eval-sanitize-30-r0-042.18d4aafed1e6be6a,reason=Completed count=1 msg=Job completed
0.0946,Event,ADDED,eval-sanitize-30-r0-043-cz5s4.18d4aaf9255ecc4e,"reason=Pulled count=1 msg=Container image ""busybox:musl"" already present on machine"
0.0953,Event,ADDED,eval-sanitize-30-r0-043-cz5s4.18d4aaf9268933c1,reason=Created count=1 msg=Created container: task
0.0956,Event,ADDED,eval-sanitize-30-r0-043-cz5s4.18d4aaf92d0333f7,reason=Started count=1 msg=Started container task
0.0958,Event,ADDED,eval-sanitize-30-r0-043.18d4aaf90929e3b2,reason=SuccessfulCreate count=1 msg=Created pod: eval-sanitize-30-r0-043-cz5s4
0.096,Event,ADDED,eval-sanitize-30-r0-043.18d4aafec906d6cf,reason=Completed count=1 msg=Job completed
0.0962,Event,ADDED,eval-sanitize-30-r0-044-vckxh.18d4aaf95fe0fd7f,"reason=Pulled count=1 msg=Container image ""busybox:musl"" already present on machine"
0.0964,Event,ADDED,eval-sanitize-30-r0-044-vckxh.18d4aaf96103696a,reason=Created count=1 msg=Created container: task
0.0965,Event,ADDED,eval-sanitize-30-r0-044-vckxh.18d4aaf966731277,reason=Started count=1 msg=Started container task
0.0967,Event,ADDED,eval-sanitize-30-r0-044.18d4aaf944c73c17,reason=SuccessfulCreate count=1 msg=Created pod: eval-sanitize-30-r0-044-vckxh
0.097,Event,ADDED,eval-sanitize-30-r0-044.18d4aaff01b4676e,reason=Completed count=1 msg=Job completed
0.0985,Node,MODIFIED,kind-worker3,taints=0
0.0988,Event,ADDED,eval-sanitize-30-r0-045-z92l7.18d4aaf99d9952c0,"reason=Pulled count=1 msg=Container image ""busybox:musl"" already present on machine"
0.099,Event,ADDED,eval-sanitize-30-r0-045-z92l7.18d4aaf99eb26dbc,reason=Created count=1 msg=Created container: task
0.0993,Event,ADDED,eval-sanitize-30-r0-045-z92l7.18d4aaf9a798d774,reason=Started count=1 msg=Started container task
0.1004,Pod,MODIFIED,eval-sanitize-60-r2-000-fl8q6,phase=Pending node=kind-worker3
0.1008,Event,ADDED,eval-sanitize-30-r0-045.18d4aaf980ee167d,reason=SuccessfulCreate count=1 msg=Created pod: eval-sanitize-30-r0-045-z92l7
0.101,Event,ADDED,eval-sanitize-30-r0-045.18d4aaff377b38cd,reason=Completed count=1 msg=Job completed
0.1012,Event,ADDED,eval-sanitize-30-r0-046-jvw9v.18d4aaf9e1558243,"reason=Pulled count=1 msg=Container image ""busybox:musl"" already present on machine"
0.1014,Event,ADDED,eval-sanitize-30-r0-046-jvw9v.18d4aaf9e2a9f482,reason=Created count=1 msg=Created container: task
0.1017,Event,ADDED,eval-sanitize-30-r0-046-jvw9v.18d4aaf9e746464d,reason=Started count=1 msg=Started container task
0.1019,Event,ADDED,eval-sanitize-30-r0-046.18d4aaf9bc5cd4cd,reason=SuccessfulCreate count=1 msg=Created pod: eval-sanitize-30-r0-046-jvw9v
0.1021,Event,ADDED,eval-sanitize-30-r0-046.18d4aaff58a4cc57,reason=Completed count=1 msg=Job completed
0.1023,Event,ADDED,eval-sanitize-30-r0-047-8w6rz.18d4aafa1b42dea4,"reason=Pulled count=1 msg=Container image ""busybox:musl"" already present on machine"
0.1026,Event,ADDED,eval-sanitize-30-r0-047-8w6rz.18d4aafa1c64f80d,reason=Created count=1 msg=Created container: task
0.1028,Event,ADDED,eval-sanitize-30-r0-047-8w6rz.18d4aafa20d5898c,reason=Started count=1 msg=Started container task
0.103,Event,ADDED,eval-sanitize-30-r0-047.18d4aaf9f78d2f9b,reason=SuccessfulCreate count=1 msg=Created pod: eval-sanitize-30-r0-047-8w6rz
0.1033,Event,ADDED,eval-sanitize-30-r0-047.18d4aaff9965e4b9,reason=Completed count=1 msg=Job completed
0.1038,Event,ADDED,eval-sanitize-30-r0-048-qsr82.18d4aafa506a2a6b,"reason=Pulled count=1 msg=Container image ""busybox:musl"" already present on machine"
0.1041,Event,ADDED,eval-sanitize-30-r0-048-qsr82.18d4aafa519bb0a6,reason=Created count=1 msg=Created container: task
0.1043,Event,ADDED,eval-sanitize-30-r0-048-qsr82.18d4aafa565b9652,reason=Started count=1 msg=Started container task
0.1047,Event,ADDED,eval-sanitize-30-r0-048.18d4aafa32f9b6f4,reason=SuccessfulCreate count=1 msg=Created pod: eval-sanitize-30-r0-048-qsr82
0.1049,Event,ADDED,eval-sanitize-30-r0-048.18d4aaffc4dd49db,reason=Completed count=1 msg=Job completed
0.1051,Event,ADDED,eval-sanitize-30-r0-049-7hc2l.18d4aafa8a53b21a,"reason=Pulled count=1 msg=Container image ""busybox:musl"" already present on machine"
0.1053,Event,ADDED,eval-sanitize-30-r0-049-7hc2l.18d4aafa8c7ce35d,reason=Created count=1 msg=Created container: task
0.1056,Event,ADDED,eval-sanitize-30-r0-049-7hc2l.18d4aafa90f34547,reason=Started count=1 msg=Started container task
0.1058,Event,ADDED,eval-sanitize-30-r0-049.18d4aafa6eb8853d,reason=SuccessfulCreate count=1 msg=Created pod: eval-sanitize-30-r0-049-7hc2l
0.106,Event,ADDED,eval-sanitize-30-r0-049.18d4ab0000c6b3ad,reason=Completed count=1 msg=Job completed
0.1072,Node,MODIFIED,kind-worker3,taints=0
0.1078,Event,ADDED,eval-sanitize-30-r0-050-cm58g.18d4aafaad718d72,"reason=FailedScheduling count=None msg=0/6 nodes are available: 2 node(s) had untolerated taint(s), 4 c_wall violated: 1 conflicting context pair(s) with node memory. no new claims to deallocate, preemption: 0/6 nodes are available: 2 Preemption is not helpful for scheduling, 4 No preemption victims found for incoming pod."
0.1081,Event,ADDED,eval-sanitize-30-r0-050-cm58g.18d4aaff1250ea6b,"reason=FailedScheduling count=None msg=0/6 nodes are available: 3 c_wall violated: 1 conflicting context pair(s) with node memory, 3 node(s) had untolerated taint(s). no new claims to deallocate, preemption: 0/6 nodes are available: 3 No preemption victims found for incoming pod, 3 Preemption is not helpful for scheduling."
0.1083,Event,ADDED,eval-sanitize-30-r0-050-cm58g.18d4aaff49dd7ac3,"reason=FailedScheduling count=None msg=0/6 nodes are available: 2 c_wall violated: 1 conflicting context pair(s) with node memory, 4 node(s) had untolerated taint(s). no new claims to deallocate, preemption: 0/6 nodes are available: 2 No preemption victims found for incoming pod, 4 Preemption is not helpful for scheduling."
0.1087,Event,ADDED,eval-sanitize-30-r0-050-cm58g.18d4aaff86a609a6,"reason=FailedScheduling count=None msg=0/6 nodes are available: 1 c_wall violated: 1 conflicting context pair(s) with node memory, 5 node(s) had untolerated taint(s). no new claims to deallocate, preemption: 0/6 nodes are available: 1 No preemption victims found for incoming pod, 5 Preemption is not helpful for scheduling."
0.1088,Event,ADDED,eval-sanitize-30-r0-050-cm58g.18d4aaffa4146409,reason=Scheduled count=None msg=Successfully assigned compute/eval-sanitize-30-r0-050-cm58g to kind-worker4
0.1092,Event,ADDED,eval-sanitize-30-r0-050-cm58g.18d4aaffc1a9f4d2,"reason=Pulled count=1 msg=Container image ""busybox:musl"" already present on machine"
0.1094,Event,ADDED,eval-sanitize-30-r0-050-cm58g.18d4aaffc3b3503c,reason=Created count=1 msg=Created container: task
0.1096,Event,ADDED,eval-sanitize-30-r0-050-cm58g.18d4aaffc862da85,reason=Started count=1 msg=Started container task
0.1098,Event,ADDED,eval-sanitize-30-r0-050.18d4aafaaa34113e,reason=SuccessfulCreate count=1 msg=Created pod: eval-sanitize-30-r0-050-cm58g
0.1099,Event,ADDED,eval-sanitize-30-r0-050.18d4ab055879342a,reason=Completed count=1 msg=Job completed
0.1101,Event,ADDED,eval-sanitize-30-r0-051-msq4s.18d4aafb024c7e51,"reason=Pulled count=1 msg=Container image ""busybox:musl"" already present on machine"
0.1103,Event,ADDED,eval-sanitize-30-r0-051-msq4s.18d4aafb03622a23,reason=Created count=1 msg=Created container: task
0.1104,Event,ADDED,eval-sanitize-30-r0-051-msq4s.18d4aafb07f0bfbf,reason=Started count=1 msg=Started container task
0.1106,Event,ADDED,eval-sanitize-30-r0-051.18d4aafae61bb29e,reason=SuccessfulCreate count=1 msg=Created pod: eval-sanitize-30-r0-051-msq4s
0.1108,Event,ADDED,eval-sanitize-30-r0-051.18d4ab008b5217fe,reason=Completed count=1 msg=Job completed
0.1109,Event,ADDED,eval-sanitize-30-r0-052-x7hkf.18d4aafb3f382691,"reason=Pulled count=1 msg=Container image ""busybox:musl"" already present on machine"
0.1112,Event,ADDED,eval-sanitize-30-r0-052-x7hkf.18d4aafb4063cec8,reason=Created count=1 msg=Created container: task
0.1117,Event,ADDED,eval-sanitize-30-r0-052-x7hkf.18d4aafb42693c93,reason=Started count=1 msg=Started container task
0.112,Event,ADDED,eval-sanitize-30-r0-052.18d4aafb217518e1,reason=SuccessfulCreate count=1 msg=Created pod: eval-sanitize-30-r0-052-x7hkf
0.1122,Event,ADDED,eval-sanitize-30-r0-052.18d4ab00b5009439,reason=Completed count=1 msg=Job completed
0.1124,Event,ADDED,eval-sanitize-30-r0-053-rwgh5.18d4aafb8192235e,"reason=Pulled count=1 msg=Container image ""busybox:musl"" already present on machine"
0.1126,Event,ADDED,eval-sanitize-30-r0-053-rwgh5.18d4aafb82b9a37c,reason=Created count=1 msg=Created container: task
0.1128,Event,ADDED,eval-sanitize-30-r0-053-rwgh5.18d4aafb897b096b,reason=Started count=1 msg=Started container task
0.113,Event,ADDED,eval-sanitize-30-r0-053.18d4aafb600154b8,reason=SuccessfulCreate count=1 msg=Created pod: eval-sanitize-30-r0-053-rwgh5
0.1132,Event,ADDED,eval-sanitize-30-r0-053.18d4ab00f0b311d8,reason=Completed count=1 msg=Job completed
0.1136,Event,ADDED,eval-sanitize-30-r0-054-kwjlm.18d4aafb9b8537c8,"reason=FailedScheduling count=None msg=0/6 nodes are available: 2 node(s) had untolerated taint(s), 4 c_wall violated: 1 conflicting context pair(s) with node memory. no new claims to deallocate, preemption: 0/6 nodes are available: 2 Preemption is not helpful for scheduling, 4 No preemption victims found for incoming pod."
0.1138,Event,ADDED,eval-sanitize-30-r0-054-kwjlm.18d4aaff0d3f4b5a,"reason=FailedScheduling count=None msg=0/6 nodes are available: 3 c_wall violated: 1 conflicting context pair(s) with node memory, 3 node(s) had untolerated taint(s). no new claims to deallocate, preemption: 0/6 nodes are available: 3 No preemption victims found for incoming pod, 3 Preemption is not helpful for scheduling."
0.1142,Event,ADDED,eval-sanitize-30-r0-054-kwjlm.18d4aaff4f48a73a,"reason=FailedScheduling count=None msg=0/6 nodes are available: 2 c_wall violated: 1 conflicting context pair(s) with node memory, 4 node(s) had untolerated taint(s). no new claims to deallocate, preemption: 0/6 nodes are available: 2 No preemption victims found for incoming pod, 4 Preemption is not helpful for scheduling."
0.1144,Event,ADDED,eval-sanitize-30-r0-054-kwjlm.18d4aaff8a731b32,"reason=FailedScheduling count=None msg=0/6 nodes are available: 1 c_wall violated: 1 conflicting context pair(s) with node memory, 5 node(s) had untolerated taint(s). no new claims to deallocate, preemption: 0/6 nodes are available: 1 No preemption victims found for incoming pod, 5 Preemption is not helpful for scheduling."
0.1145,Event,ADDED,eval-sanitize-30-r0-054-kwjlm.18d4aaffa3ad68ea,reason=Scheduled count=None msg=Successfully assigned compute/eval-sanitize-30-r0-054-kwjlm to kind-worker4
0.1147,Event,ADDED,eval-sanitize-30-r0-054-kwjlm.18d4aaffc0df9861,"reason=Pulled count=1 msg=Container image ""busybox:musl"" already present on machine"
0.115,Event,ADDED,eval-sanitize-30-r0-054-kwjlm.18d4aaffc3477af1,reason=Created count=1 msg=Created container: task
0.1152,Event,ADDED,eval-sanitize-30-r0-054-kwjlm.18d4aaffc8621890,reason=Started count=1 msg=Started container task
0.1154,Event,ADDED,eval-sanitize-30-r0-054.18d4aafb98ad8335,reason=SuccessfulCreate count=1 msg=Created pod: eval-sanitize-30-r0-054-kwjlm
0.1157,Event,ADDED,eval-sanitize-30-r0-054.18d4ab0558c03a29,reason=Completed count=1 msg=Job completed
0.1159,Event,ADDED,eval-sanitize-30-r0-055-kfklg.18d4aafbef959c37,"reason=Pulled count=1 msg=Container image ""busybox:musl"" already present on machine"
0.116,Event,ADDED,eval-sanitize-30-r0-055-kfklg.18d4aafbf0c80178,reason=Created count=1 msg=Created container: task
0.1162,Event,ADDED,eval-sanitize-30-r0-055-kfklg.18d4aafbf51d531c,reason=Started count=1 msg=Started container task
0.1165,Event,ADDED,eval-sanitize-30-r0-055.18d4aafbd4656a1b,reason=SuccessfulCreate count=1 msg=Created pod: eval-sanitize-30-r0-055-kfklg
0.1167,Event,ADDED,eval-sanitize-30-r0-055.18d4ab017a5a0cf5,reason=Completed count=1 msg=Job completed
0.1169,Event,ADDED,eval-sanitize-30-r0-056-lg5qk.18d4aafc324ae007,"reason=Pulled count=1 msg=Container image ""busybox:musl"" already present on machine"
0.1171,Event,ADDED,eval-sanitize-30-r0-056-lg5qk.18d4aafc33779b26,reason=Created count=1 msg=Created container: task
0.1175,Event,ADDED,eval-sanitize-30-r0-056-lg5qk.18d4aafc391a12d6,reason=Started count=1 msg=Started container task
0.1177,Event,ADDED,eval-sanitize-30-r0-056.18d4aafc10114f09,reason=SuccessfulCreate count=1 msg=Created pod: eval-sanitize-30-r0-056-lg5qk
0.1179,Event,ADDED,eval-sanitize-30-r0-056.18d4ab01a52dc6eb,reason=Completed count=1 msg=Job completed
0.1181,Event,ADDED,eval-sanitize-30-r0-057-9h4gs.18d4aafc6cc5589b,"reason=Pulled count=1 msg=Container image ""busybox:musl"" already present on machine"
0.1183,Event,ADDED,eval-sanitize-30-r0-057-9h4gs.18d4aafc6e10fe5b,reason=Created count=1 msg=Created container: task
0.1184,Event,ADDED,eval-sanitize-30-r0-057-9h4gs.18d4aafc72231b6a,reason=Started count=1 msg=Started container task
0.1186,Event,ADDED,eval-sanitize-30-r0-057.18d4aafc4cd67740,reason=SuccessfulCreate count=1 msg=Created pod: eval-sanitize-30-r0-057-9h4gs
0.1188,Event,ADDED,eval-sanitize-30-r0-057.18d4ab01f1f93ab3,reason=Completed count=1 msg=Job completed
0.119,Event,ADDED,eval-sanitize-30-r0-058-8rplr.18d4aafca1fa1a1f,"reason=Pulled count=1 msg=Container image ""busybox:musl"" already present on machine"
0.1192,Event,ADDED,eval-sanitize-30-r0-058-8rplr.18d4aafca3358662,reason=Created count=1 msg=Created container: task
0.1194,Event,ADDED,eval-sanitize-30-r0-058-8rplr.18d4aafca7086844,reason=Started count=1 msg=Started container task
0.1196,Event,ADDED,eval-sanitize-30-r0-058.18d4aafc873eb95e,reason=SuccessfulCreate count=1 msg=Created pod: eval-sanitize-30-r0-058-8rplr
0.1198,Event,ADDED,eval-sanitize-30-r0-058.18d4ab022e0845af,reason=Completed count=1 msg=Job completed
0.12,Event,ADDED,eval-sanitize-30-r0-059-s5jxv.18d4aafce63a49ab,"reason=Pulled count=1 msg=Container image ""busybox:musl"" already present on machine"
0.1202,Event,ADDED,eval-sanitize-30-r0-059-s5jxv.18d4aafce75e1e19,reason=Created count=1 msg=Created container: task
0.1203,Event,ADDED,eval-sanitize-30-r0-059-s5jxv.18d4aafcebdb3a0b,reason=Started count=1 msg=Started container task
0.1205,Event,ADDED,eval-sanitize-30-r0-059.18d4aafcc302ac4b,reason=SuccessfulCreate count=1 msg=Created pod: eval-sanitize-30-r0-059-s5jxv
0.1207,Event,ADDED,eval-sanitize-30-r0-059.18d4ab021e3f4877,reason=Completed count=1 msg=Job completed
0.1208,Event,ADDED,eval-sanitize-30-r0-060-4zpf5.18d4aafd07b4b3da,reason=Scheduled count=None msg=Successfully assigned compute/eval-sanitize-30-r0-060-4zpf5 to kind-worker3
0.121,Event,ADDED,eval-sanitize-30-r0-060-4zpf5.18d4aafd23a7e8b9,"reason=Pulled count=1 msg=Container image ""busybox:musl"" already present on machine"
0.1212,Event,ADDED,eval-sanitize-30-r0-060-4zpf5.18d4aafd24ee3d52,reason=Created count=1 msg=Created container: task
0.1213,Event,ADDED,eval-sanitize-30-r0-060-4zpf5.18d4aafd2e33b30f,reason=Started count=1 msg=Started container task
0.1215,Event,ADDED,eval-sanitize-30-r0-060.18d4aafcfecbf69c,reason=SuccessfulCreate count=1 msg=Created pod: eval-sanitize-30-r0-060-4zpf5
0.1217,Event,ADDED,eval-sanitize-30-r0-060.18d4ab02a6a01ba6,reason=Completed count=1 msg=Job completed
0.1218,Event,ADDED,eval-sanitize-30-r0-061-ktln8.18d4aafd4e37c1a6,reason=Scheduled count=None msg=Successfully assigned compute/eval-sanitize-30-r0-061-ktln8 to kind-worker3
0.122,Event,ADDED,eval-sanitize-30-r0-061-ktln8.18d4aafd6b568bfc,"reason=Pulled count=1 msg=Container image ""busybox:musl"" already present on machine"
0.1222,Event,ADDED,eval-sanitize-30-r0-061-ktln8.18d4aafd6c8f5575,reason=Created count=1 msg=Created container: task
0.1223,Event,ADDED,eval-sanitize-30-r0-061-ktln8.18d4aafd728e4561,reason=Started count=1 msg=Started container task
0.1225,Event,ADDED,eval-sanitize-30-r0-061.18d4aafd4172f839,reason=SuccessfulCreate count=1 msg=Created pod: eval-sanitize-30-r0-061-ktln8
0.1234,Event,ADDED,eval-sanitize-30-r0-061.18d4ab02e29a4e9a,reason=Completed count=1 msg=Job completed
0.1237,Event,ADDED,eval-sanitize-30-r0-062-c4mtf.18d4aafd82d1026c,"reason=FailedScheduling count=None msg=0/6 nodes are available: 2 c_wall violated: 2 conflicting context pair(s) with node memory, 2 c_wall violated: 3 conflicting context pair(s) with node memory, 2 node(s) had untolerated taint(s). no new claims to deallocate, preemption: 0/6 nodes are available: 2 Preemption is not helpful for scheduling, 4 No preemption victims found for incoming pod."
0.1241,Event,ADDED,eval-sanitize-30-r0-062-c4mtf.18d4aafd94af5e5e,"reason=FailedScheduling count=None msg=0/6 nodes are available: 2 c_wall violated: 2 conflicting context pair(s) with node memory, 2 c_wall violated: 3 conflicting context pair(s) with node memory, 2 node(s) had untolerated taint(s). no new claims to deallocate, preemption: 0/6 nodes are available: 2 Preemption is not helpful for scheduling, 4 No preemption victims found for incoming pod."
0.1244,Event,ADDED,eval-sanitize-30-r0-062-c4mtf.18d4aaff07973bf5,"reason=FailedScheduling count=None msg=0/6 nodes are available: 1 c_wall violated: 2 conflicting context pair(s) with node memory, 2 c_wall violated: 3 conflicting context pair(s) with node memory, 3 node(s) had untolerated taint(s). no new claims to deallocate, preemption: 0/6 nodes are available: 3 No preemption victims found for incoming pod, 3 Preemption is not helpful for scheduling."
0.1246,Event,ADDED,eval-sanitize-30-r0-062-c4mtf.18d4aaff4edeb823,"reason=FailedScheduling count=None msg=0/6 nodes are available: 1 c_wall violated: 2 conflicting context pair(s) with node memory, 1 c_wall violated: 3 conflicting context pair(s) with node memory, 4 node(s) had untolerated taint(s). no new claims to deallocate, preemption: 0/6 nodes are available: 2 No preemption victims found for incoming pod, 4 Preemption is not helpful for scheduling."
0.1248,Event,ADDED,eval-sanitize-30-r0-062-c4mtf.18d4aaff894dfb79,"reason=FailedScheduling count=None msg=0/6 nodes are available: 1 c_wall violated: 2 conflicting context pair(s) with node memory, 5 node(s) had untolerated taint(s). no new claims to deallocate, preemption: 0/6 nodes are available: 1 No preemption victims found for incoming pod, 5 Preemption is not helpful for scheduling."
0.1251,Event,ADDED,eval-sanitize-30-r0-062-c4mtf.18d4aaffa946baa7,reason=Scheduled count=None msg=Successfully assigned compute/eval-sanitize-30-r0-062-c4mtf to kind-worker4
0.1253,Event,ADDED,eval-sanitize-30-r0-062-c4mtf.18d4aaffc868ae25,"reason=Pulled count=1 msg=Container image ""busybox:musl"" already present on machine"
0.1255,Event,ADDED,eval-sanitize-30-r0-062-c4mtf.18d4aaffc9d9803f,reason=Created count=1 msg=Created container: task
0.1257,Event,ADDED,eval-sanitize-30-r0-062-c4mtf.18d4aaffce251945,reason=Started count=1 msg=Started container task
0.1259,Event,ADDED,eval-sanitize-30-r0-062.18d4aafd75f31a30,reason=SuccessfulCreate count=1 msg=Created pod: eval-sanitize-30-r0-062-c4mtf
0.126,Event,ADDED,eval-sanitize-30-r0-062.18d4ab055a4162bf,reason=Completed count=1 msg=Job completed
0.1262,Event,ADDED,eval-sanitize-30-r0-063-4vjpq.18d4aafdba5032e4,reason=Scheduled count=None msg=Successfully assigned compute/eval-sanitize-30-r0-063-4vjpq to kind-worker5
0.1268,Event,ADDED,eval-sanitize-30-r0-063-4vjpq.18d4aafdd8fbc5c7,"reason=Pulled count=1 msg=Container image ""busybox:musl"" already present on machine"
0.1271,Event,ADDED,eval-sanitize-30-r0-063-4vjpq.18d4aafdda4f8662,reason=Created count=1 msg=Created container: task
0.1273,Event,ADDED,eval-sanitize-30-r0-063-4vjpq.18d4aafddf3b1096,reason=Started count=1 msg=Started container task
0.1274,Event,ADDED,eval-sanitize-30-r0-063.18d4aafdb1c323c6,reason=SuccessfulCreate count=1 msg=Created pod: eval-sanitize-30-r0-063-4vjpq
0.1278,Event,ADDED,eval-sanitize-30-r0-063.18d4ab035dde3fd0,reason=Completed count=1 msg=Job completed
0.128,Event,ADDED,eval-sanitize-30-r0-064-sfpfj.18d4aafe0c441ca0,reason=Scheduled count=None msg=Successfully assigned compute/eval-sanitize-30-r0-064-sfpfj to kind-worker2
0.1281,Event,ADDED,eval-sanitize-30-r0-064-sfpfj.18d4aafe29a2fa0c,"reason=Pulled count=1 msg=Container image ""busybox:musl"" already present on machine"
0.1284,Event,ADDED,eval-sanitize-30-r0-064-sfpfj.18d4aafe2ad54b71,reason=Created count=1 msg=Created container: task
0.1286,Event,ADDED,eval-sanitize-30-r0-064-sfpfj.18d4aafe2f5b5847,reason=Started count=1 msg=Started container task
0.1288,Event,ADDED,eval-sanitize-30-r0-064.18d4aafdfe5f9d6c,reason=SuccessfulCreate count=1 msg=Created pod: eval-sanitize-30-r0-064-sfpfj
0.129,Event,ADDED,eval-sanitize-30-r0-064.18d4ab03c708985a,reason=Completed count=1 msg=Job completed
0.1292,Event,ADDED,eval-sanitize-30-r0-065-ckv84.18d4aafe562742df,reason=Scheduled count=None msg=Successfully assigned compute/eval-sanitize-30-r0-065-ckv84 to kind-worker5
0.1294,Event,ADDED,eval-sanitize-30-r0-065-ckv84.18d4aafe706ce32b,"reason=Pulled count=1 msg=Container image ""busybox:musl"" already present on machine"
0.1296,Event,ADDED,eval-sanitize-30-r0-065-ckv84.18d4aafe718fa882,reason=Created count=1 msg=Created container: task
0.1298,Event,ADDED,eval-sanitize-30-r0-065-ckv84.18d4aafe73a9f2a2,reason=Started count=1 msg=Started container task
0.1301,Event,ADDED,eval-sanitize-30-r0-065.18d4aafe54fcd23b,reason=SuccessfulCreate count=1 msg=Created pod: eval-sanitize-30-r0-065-ckv84
0.1302,Event,ADDED,eval-sanitize-30-r0-065.18d4ab03d6307717,reason=Completed count=1 msg=Job completed
0.1304,Event,ADDED,eval-sanitize-30-r0-066-cl7hp.18d4aafe91489736,reason=Scheduled count=None msg=Successfully assigned compute/eval-sanitize-30-r0-066-cl7hp to kind-worker2
0.1307,Event,ADDED,eval-sanitize-30-r0-066-cl7hp.18d4aafeb376f14b,"reason=Pulled count=1 msg=Container image ""busybox:musl"" already present on machine"
0.1309,Event,ADDED,eval-sanitize-30-r0-066-cl7hp.18d4aafeb4d30131,reason=Created count=1 msg=Created container: task
0.1311,Event,ADDED,eval-sanitize-30-r0-066-cl7hp.18d4aafeb8dd3f90,reason=Started count=1 msg=Started container task
0.1313,Event,ADDED,eval-sanitize-30-r0-066.18d4aafe87a34428,reason=SuccessfulCreate count=1 msg=Created pod: eval-sanitize-30-r0-066-cl7hp
0.1317,Event,ADDED,eval-sanitize-30-r0-066.18d4ab04418d8a08,reason=Completed count=1 msg=Job completed
0.1318,Event,ADDED,eval-sanitize-30-r0-067-6x8cs.18d4aafec54a37dd,reason=Scheduled count=None msg=Successfully assigned compute/eval-sanitize-30-r0-067-6x8cs to kind-worker5
0.132,Event,ADDED,eval-sanitize-30-r0-067-6x8cs.18d4aafee3180300,"reason=Pulled count=1 msg=Container image ""busybox:musl"" already present on machine"
0.1322,Event,ADDED,eval-sanitize-30-r0-067-6x8cs.18d4aafee45a2e94,reason=Created count=1 msg=Created container: task
0.1325,Event,ADDED,eval-sanitize-30-r0-067-6x8cs.18d4aafee928b0f9,reason=Started count=1 msg=Started container task
0.1327,Event,ADDED,eval-sanitize-30-r0-067.18d4aafebd1695af,reason=SuccessfulCreate count=1 msg=Created pod: eval-sanitize-30-r0-067-6x8cs
0.1328,Event,ADDED,eval-sanitize-30-r0-067.18d4ab044db4336e,reason=Completed count=1 msg=Job completed
0.1331,Event,ADDED,eval-sanitize-30-r0-068-s54sl.18d4aafef538036b,reason=Scheduled count=None msg=Successfully assigned compute/eval-sanitize-30-r0-068-s54sl to kind-worker5
0.1333,Event,ADDED,eval-sanitize-30-r0-068-s54sl.18d4aaff0e9a985a,"reason=Pulled count=1 msg=Container image ""busybox:musl"" already present on machine"
0.1337,Event,ADDED,eval-sanitize-30-r0-068-s54sl.18d4aaff0fc0a81d,reason=Created count=1 msg=Created container: task
0.1338,Event,ADDED,eval-sanitize-30-r0-068-s54sl.18d4aaff1477c295,reason=Started count=1 msg=Started container task
0.1341,Event,ADDED,eval-sanitize-30-r0-068.18d4aafee9e88405,reason=SuccessfulCreate count=1 msg=Created pod: eval-sanitize-30-r0-068-s54sl
0.1342,Event,ADDED,eval-sanitize-30-r0-068.18d4ab048a7c106b,reason=Completed count=1 msg=Job completed
0.1344,Event,ADDED,eval-sanitize-30-r0-069-r4pvp.18d4aaff2510a92b,"reason=FailedScheduling count=None msg=0/6 nodes are available: 1 c_wall violated: 2 conflicting context pair(s) with node memory, 2 c_wall violated: 3 conflicting context pair(s) with node memory, 3 node(s) had untolerated taint(s). no new claims to deallocate, preemption: 0/6 nodes are available: 3 No preemption victims found for incoming pod, 3 Preemption is not helpful for scheduling."
0.1346,Event,ADDED,eval-sanitize-30-r0-069-r4pvp.18d4aaff31c57d83,"reason=FailedScheduling count=None msg=0/6 nodes are available: 1 c_wall violated: 2 conflicting context pair(s) with node memory, 2 c_wall violated: 3 conflicting context pair(s) with node memory, 3 node(s) had untolerated taint(s). no new claims to deallocate, preemption: 0/6 nodes are available: 3 No preemption victims found for incoming pod, 3 Preemption is not helpful for scheduling."
0.1348,Event,ADDED,eval-sanitize-30-r0-069-r4pvp.18d4aaff4a2ec177,"reason=FailedScheduling count=None msg=0/6 nodes are available: 1 c_wall violated: 2 conflicting context pair(s) with node memory, 1 c_wall violated: 3 conflicting context pair(s) with node memory, 4 node(s) had untolerated taint(s). no new claims to deallocate, preemption: 0/6 nodes are available: 2 No preemption victims found for incoming pod, 4 Preemption is not helpful for scheduling."
0.135,Event,ADDED,eval-sanitize-30-r0-069-r4pvp.18d4aaff86d31c55,"reason=FailedScheduling count=None msg=0/6 nodes are available: 1 c_wall violated: 2 conflicting context pair(s) with node memory, 5 node(s) had untolerated taint(s). no new claims to deallocate, preemption: 0/6 nodes are available: 1 No preemption victims found for incoming pod, 5 Preemption is not helpful for scheduling."
0.1351,Event,ADDED,eval-sanitize-30-r0-069-r4pvp.18d4aaffa8e91099,reason=Scheduled count=None msg=Successfully assigned compute/eval-sanitize-30-r0-069-r4pvp to kind-worker4
0.1353,Event,ADDED,eval-sanitize-30-r0-069-r4pvp.18d4aaffc8684028,"reason=Pulled count=1 msg=Container image ""busybox:musl"" already present on machine"
0.1355,Event,ADDED,eval-sanitize-30-r0-069-r4pvp.18d4aaffca345fd4,reason=Created count=1 msg=Created container: task
0.1356,Event,ADDED,eval-sanitize-30-r0-069-r4pvp.18d4aaffce628f0b,reason=Started count=1 msg=Started container task
0.1358,Event,ADDED,eval-sanitize-30-r0-069.18d4aaff1a2506f6,reason=SuccessfulCreate count=1 msg=Created pod: eval-sanitize-30-r0-069-r4pvp
0.136,Event,ADDED,eval-sanitize-30-r0-069.18d4ab055943bf34,reason=Completed count=1 msg=Job completed
0.1361,Event,ADDED,eval-sanitize-30-r0-070-rfhz8.18d4aaff563f81d6,reason=Scheduled count=None msg=Successfully assigned compute/eval-sanitize-30-r0-070-rfhz8 to kind-worker
0.1363,Event,ADDED,eval-sanitize-30-r0-070-rfhz8.18d4aaff70827dbe,"reason=Pulled count=1 msg=Container image ""busybox:musl"" already present on machine"
0.1365,Event,ADDED,eval-sanitize-30-r0-070-rfhz8.18d4aaff719b2a3c,reason=Created count=1 msg=Created container: task
0.1366,Event,ADDED,eval-sanitize-30-r0-070-rfhz8.18d4aaff76b4455d,reason=Started count=1 msg=Started container task
0.1368,Event,ADDED,eval-sanitize-30-r0-070.18d4aaff526af918,reason=SuccessfulCreate count=1 msg=Created pod: eval-sanitize-30-r0-070-rfhz8
0.137,Event,ADDED,eval-sanitize-30-r0-070.18d4ab04b22994ed,reason=Completed count=1 msg=Job completed
0.1371,Event,ADDED,eval-sanitize-30-r0-071-fsvqh.18d4aaff92af75e1,reason=Scheduled count=None msg=Successfully assigned compute/eval-sanitize-30-r0-071-fsvqh to kind-worker3
0.1373,Event,ADDED,eval-sanitize-30-r0-071-fsvqh.18d4aaffad62e75b,"reason=Pulled count=1 msg=Container image ""busybox:musl"" already present on machine"
0.1374,Event,ADDED,eval-sanitize-30-r0-071-fsvqh.18d4aaffaef16235,reason=Created count=1 msg=Created container: task
0.1381,Event,ADDED,eval-sanitize-30-r0-071-fsvqh.18d4aaffb3c4a6ab,reason=Started count=1 msg=Started container task
0.1383,Event,ADDED,eval-sanitize-30-r0-071.18d4aaff91d947a8,reason=SuccessfulCreate count=1 msg=Created pod: eval-sanitize-30-r0-071-fsvqh
0.1384,Event,ADDED,eval-sanitize-30-r0-071.18d4ab053c3260a1,reason=Completed count=1 msg=Job completed
0.1387,Event,ADDED,eval-sanitize-30-r0-072-6wq8p.18d4aaffcb40bc50,"reason=FailedScheduling count=None msg=0/6 nodes are available: 1 c_wall violated: 2 conflicting context pair(s) with node memory, 5 node(s) had untolerated taint(s). no new claims to deallocate, preemption: 0/6 nodes are available: 1 No preemption victims found for incoming pod, 5 Preemption is not helpful for scheduling."
0.1389,Event,ADDED,eval-sanitize-30-r0-072-6wq8p.18d4aaffcbcf7097,"reason=FailedScheduling count=None msg=0/6 nodes are available: 1 c_wall violated: 2 conflicting context pair(s) with node memory, 5 node(s) had untolerated taint(s). no new claims to deallocate, preemption: 0/6 nodes are available: 1 No preemption victims found for incoming pod, 5 Preemption is not helpful for scheduling."
0.139,Event,ADDED,eval-sanitize-30-r0-072-6wq8p.18d4ab0639ecb97e,"reason=FailedScheduling count=None msg=0/6 nodes are available: 2 c_wall violated: 2 conflicting context pair(s) with node memory, 4 node(s) had untolerated taint(s). no new claims to deallocate, preemption: 0/6 nodes are available: 2 No preemption victims found for incoming pod, 4 Preemption is not helpful for scheduling."
0.1392,Event,ADDED,eval-sanitize-30-r0-072-6wq8p.18d4ab06a514ea80,"reason=FailedScheduling count=None msg=0/6 nodes are available: 1 c_wall violated: 1 conflicting context pair(s) with node memory, 2 c_wall violated: 2 conflicting context pair(s) with node memory, 3 node(s) had untolerated taint(s). no new claims to deallocate, preemption: 0/6 nodes are available: 3 No preemption victims found for incoming pod, 3 Preemption is not helpful for scheduling."
0.1393,Event,ADDED,eval-sanitize-30-r0-072-6wq8p.18d4ab06c2f14ecc,reason=Scheduled count=None msg=Successfully assigned compute/eval-sanitize-30-r0-072-6wq8p to kind-worker
0.1395,Event,ADDED,eval-sanitize-30-r0-072-6wq8p.18d4ab06e03f7146,"reason=Pulled count=1 msg=Container image ""busybox:musl"" already present on machine"
0.1397,Event,ADDED,eval-sanitize-30-r0-072-6wq8p.18d4ab06e380c3ca,reason=Created count=1 msg=Created container: task
0.1399,Event,ADDED,eval-sanitize-30-r0-072-6wq8p.18d4ab06e8f84c89,reason=Started count=1 msg=Started container task
0.14,Event,ADDED,eval-sanitize-30-r0-072.18d4aaffcafc3442,reason=SuccessfulCreate count=1 msg=Created pod: eval-sanitize-30-r0-072-6wq8p
0.1402,Event,ADDED,eval-sanitize-30-r0-072.18d4ab0d1bad6f46,reason=Completed count=1 msg=Job completed
0.1403,Event,ADDED,eval-sanitize-30-r0-073-vtrk8.18d4ab0005ed87d5,reason=Scheduled count=None msg=Successfully assigned compute/eval-sanitize-30-r0-073-vtrk8 to kind-worker4
0.1405,Event,ADDED,eval-sanitize-30-r0-073-vtrk8.18d4ab0020c0fed9,"reason=Pulled count=1 msg=Container image ""busybox:musl"" already present on machine"
0.1407,Event,ADDED,eval-sanitize-30-r0-073-vtrk8.18d4ab00223bc5fd,reason=Created count=1 msg=Created container: task
0.1409,Event,ADDED,eval-sanitize-30-r0-073-vtrk8.18d4ab0026d97c55,reason=Started count=1 msg=Started container task
0.141,Event,ADDED,eval-sanitize-30-r0-073.18d4ab00054904bb,reason=SuccessfulCreate count=1 msg=Created pod: eval-sanitize-30-r0-073-vtrk8
0.1412,Event,ADDED,eval-sanitize-30-r0-073.18d4ab0594852bee,reason=Completed count=1 msg=Job completed
0.1414,Event,ADDED,eval-sanitize-30-r0-074-gzc75.18d4ab0043362a86,"reason=FailedScheduling count=None msg=0/6 nodes are available: 1 c_wall violated: 2 conflicting context pair(s) with node memory, 5 node(s) had untolerated taint(s). no new claims to deallocate, preemption: 0/6 nodes are available: 1 No preemption victims found for incoming pod, 5 Preemption is not helpful for scheduling."
0.1415,Event,ADDED,eval-sanitize-30-r0-074-gzc75.18d4ab0043e33180,"reason=FailedScheduling count=None msg=0/6 nodes are available: 1 c_wall violated: 2 conflicting context pair(s) with node memory, 5 node(s) had untolerated taint(s). no new claims to deallocate, preemption: 0/6 nodes are available: 1 No preemption victims found for incoming pod, 5 Preemption is not helpful for scheduling."
0.1417,Event,ADDED,eval-sanitize-30-r0-074-gzc75.18d4ab060fe60441,reason=Scheduled count=None msg=Successfully assigned compute/eval-sanitize-30-r0-074-gzc75 to kind-worker2
0.1419,Event,ADDED,eval-sanitize-30-r0-074-gzc75.18d4ab0633204609,"reason=Pulled count=1 msg=Container image ""busybox:musl"" already present on machine"
0.142,Event,ADDED,eval-sanitize-30-r0-074-gzc75.18d4ab063588d9dd,reason=Created count=1 msg=Created container: task
0.1422,Event,ADDED,eval-sanitize-30-r0-074-gzc75.18d4ab063b606d61,reason=Started count=1 msg=Started container task
0.1424,Event,ADDED,eval-sanitize-30-r0-074.18d4ab0042f280f3,reason=SuccessfulCreate count=1 msg=Created pod: eval-sanitize-30-r0-074-gzc75
0.1425,Event,ADDED,eval-sanitize-30-r0-074.18d4ab0b899e69aa,reason=Completed count=1 msg=Job completed
0.1427,Event,ADDED,eval-sanitize-30-r0-075-5q67f.18d4ab007dbb544b,reason=Scheduled count=None msg=Successfully assigned compute/eval-sanitize-30-r0-075-5q67f to kind-worker4
0.1429,Event,ADDED,eval-sanitize-30-r0-075-5q67f.18d4ab009743ec8a,"reason=Pulled count=1 msg=Container image ""busybox:musl"" already present on machine"
0.143,Event,ADDED,eval-sanitize-30-r0-075-5q67f.18d4ab009871a6a9,reason=Created count=1 msg=Created container: task
0.1432,Event,ADDED,eval-sanitize-30-r0-075-5q67f.18d4ab00a03a6a7b,reason=Started count=1 msg=Started container task
0.1434,Event,ADDED,eval-sanitize-30-r0-075.18d4ab007d20686a,reason=SuccessfulCreate count=1 msg=Created pod: eval-sanitize-30-r0-075-5q67f
0.1435,Event,ADDED,eval-sanitize-30-r0-075.18d4ab060c965cbe,reason=Completed count=1 msg=Job completed
0.1437,Event,ADDED,eval-sanitize-30-r0-076-52r65.18d4ab00ba5573fd,reason=Scheduled count=None msg=Successfully assigned compute/eval-sanitize-30-r0-076-52r65 to kind-worker4
0.1439,Event,ADDED,eval-sanitize-30-r0-076-52r65.18d4ab00d4d54dfb,"reason=Pulled count=1 msg=Container image ""busybox:musl"" already present on machine"
0.144,Event,ADDED,eval-sanitize-30-r0-076-52r65.18d4ab00d678df66,reason=Created count=1 msg=Created container: task
0.1442,Event,ADDED,eval-sanitize-30-r0-076-52r65.18d4ab00d8faf953,reason=Started count=1 msg=Started container task
0.1444,Event,ADDED,eval-sanitize-30-r0-076.18d4ab00b98ea10a,reason=SuccessfulCreate count=1 msg=Created pod: eval-sanitize-30-r0-076-52r65
0.1445,Event,ADDED,eval-sanitize-30-r0-076.18d4ab0649cf2031,reason=Completed count=1 msg=Job completed
0.1447,Event,ADDED,eval-sanitize-30-r0-077-g8b72.18d4ab00f4674c58,reason=Scheduled count=None msg=Successfully assigned compute/eval-sanitize-30-r0-077-g8b72 to kind-worker4
0.1448,Event,ADDED,eval-sanitize-30-r0-077-g8b72.18d4ab010edc63f9,"reason=Pulled count=1 msg=Container image ""busybox:musl"" already present on machine"
0.145,Event,ADDED,eval-sanitize-30-r0-077-g8b72.18d4ab01105a64c2,reason=Created count=1 msg=Created container: task
0.1453,Event,ADDED,eval-sanitize-30-r0-077-g8b72.18d4ab01160ef186,reason=Started count=1 msg=Started container task
0.1455,Event,ADDED,eval-sanitize-30-r0-077.18d4ab00f3ca27a7,reason=SuccessfulCreate count=1 msg=Created pod: eval-sanitize-30-r0-077-g8b72
0.1456,Event,ADDED,eval-sanitize-30-r0-077.18d4ab06879ae039,reason=Completed count=1 msg=Job completed
0.1458,Event,ADDED,eval-sanitize-30-r0-078-mm7ff.18d4ab01303f7b78,"reason=FailedScheduling count=None msg=0/6 nodes are available: 1 c_wall violated: 3 conflicting context pair(s) with node memory, 5 node(s) had untolerated taint(s). no new claims to deallocate, preemption: 0/6 nodes are available: 1 No preemption victims found for incoming pod, 5 Preemption is not helpful for scheduling."
0.146,Event,ADDED,eval-sanitize-30-r0-078-mm7ff.18d4ab0130f13350,"reason=FailedScheduling count=None msg=0/6 nodes are available: 1 c_wall violated: 3 conflicting context pair(s) with node memory, 5 node(s) had untolerated taint(s). no new claims to deallocate, preemption: 0/6 nodes are available: 1 No preemption victims found for incoming pod, 5 Preemption is not helpful for scheduling."
0.1461,Event,ADDED,eval-sanitize-30-r0-078-mm7ff.18d4ab060b210442,reason=Scheduled count=None msg=Successfully assigned compute/eval-sanitize-30-r0-078-mm7ff to kind-worker2
0.1463,Event,ADDED,eval-sanitize-30-r0-078-mm7ff.18d4ab0629aaccd7,"reason=Pulled count=1 msg=Container image ""busybox:musl"" already present on machine"
0.1464,Event,ADDED,eval-sanitize-30-r0-078-mm7ff.18d4ab062c789ab0,reason=Created count=1 msg=Created container: task
0.1466,Event,ADDED,eval-sanitize-30-r0-078-mm7ff.18d4ab0634b4a4e3,reason=Started count=1 msg=Started container task
0.1468,Event,ADDED,eval-sanitize-30-r0-078.18d4ab012fcad136,reason=SuccessfulCreate count=1 msg=Created pod: eval-sanitize-30-r0-078-mm7ff
0.1469,Event,ADDED,eval-sanitize-30-r0-078.18d4ab0b7f8997c8,reason=Completed count=1 msg=Job completed
0.1472,Event,ADDED,eval-sanitize-30-r0-079-q2h6g.18d4ab016c4f4747,reason=Scheduled count=None msg=Successfully assigned compute/eval-sanitize-30-r0-079-q2h6g to kind-worker4
0.1474,Event,ADDED,eval-sanitize-30-r0-079-q2h6g.18d4ab018841a062,"reason=Pulled count=1 msg=Container image ""busybox:musl"" already present on machine"
0.1476,Event,ADDED,eval-sanitize-30-r0-079-q2h6g.18d4ab0189a21891,reason=Created count=1 msg=Created container: task
0.148,Event,ADDED,eval-sanitize-30-r0-079-q2h6g.18d4ab018f7a1d28,reason=Started count=1 msg=Started container task
0.1482,Event,ADDED,eval-sanitize-30-r0-079.18d4ab016ba24676,reason=SuccessfulCreate count=1 msg=Created pod: eval-sanitize-30-r0-079-q2h6g
0.1484,Event,ADDED,eval-sanitize-30-r0-079.18d4ab070225fc85,reason=Completed count=1 msg=Job completed
0.1485,Event,ADDED,eval-sanitize-30-r0-080-tmqq5.18d4ab01a7b27d13,reason=Scheduled count=None msg=Successfully assigned compute/eval-sanitize-30-r0-080-tmqq5 to kind-worker4
0.1489,Event,ADDED,eval-sanitize-30-r0-080-tmqq5.18d4ab01c1e06d56,"reason=Pulled count=1 msg=Container image ""busybox:musl"" already present on machine"
0.149,Event,ADDED,eval-sanitize-30-r0-080-tmqq5.18d4ab01c30e0ccf,reason=Created count=1 msg=Created container: task
0.1492,Event,ADDED,eval-sanitize-30-r0-080-tmqq5.18d4ab01c651cdd3,reason=Started count=1 msg=Started container task
0.1494,Event,ADDED,eval-sanitize-30-r0-080.18d4ab01a6e39c6f,reason=SuccessfulCreate count=1 msg=Created pod: eval-sanitize-30-r0-080-tmqq5
0.1497,Event,ADDED,eval-sanitize-30-r0-080.18d4ab073831065e,reason=Completed count=1 msg=Job completed
0.1499,Event,ADDED,eval-sanitize-30-r0-081-99kgm.18d4ab01e39d0031,"reason=FailedScheduling count=None msg=0/6 nodes are available: 1 c_wall violated: 2 conflicting context pair(s) with node memory, 5 node(s) had untolerated taint(s). no new claims to deallocate, preemption: 0/6 nodes are available: 1 No preemption victims found for incoming pod, 5 Preemption is not helpful for scheduling."
0.1501,Event,ADDED,eval-sanitize-30-r0-081-99kgm.18d4ab01e4766832,"reason=FailedScheduling count=None msg=0/6 nodes are available: 1 c_wall violated: 2 conflicting context pair(s) with node memory, 5 node(s) had untolerated taint(s). no new claims to deallocate, preemption: 0/6 nodes are available: 1 No preemption victims found for incoming pod, 5 Preemption is not helpful for scheduling."
0.1502,Event,ADDED,eval-sanitize-30-r0-081-99kgm.18d4ab06108247e9,reason=Scheduled count=None msg=Successfully assigned compute/eval-sanitize-30-r0-081-99kgm to kind-worker2
0.1504,Event,ADDED,eval-sanitize-30-r0-081-99kgm.18d4ab0633cb6967,"reason=Pulled count=1 msg=Container image ""busybox:musl"" already present on machine"
0.1506,Event,ADDED,eval-sanitize-30-r0-081-99kgm.18d4ab0637115152,reason=Created count=1 msg=Created container: task
0.1508,Event,ADDED,eval-sanitize-30-r0-081-99kgm.18d4ab063d4bb20a,reason=Started count=1 msg=Started container task
0.1509,Event,ADDED,eval-sanitize-30-r0-081.18d4ab01e34a38e8,reason=SuccessfulCreate count=1 msg=Created pod: eval-sanitize-30-r0-081-99kgm
0.1511,Event,ADDED,eval-sanitize-30-r0-081.18d4ab0b895ea9d1,reason=Completed count=1 msg=Job completed
0.1513,Event,ADDED,eval-sanitize-30-r0-082-tw9xc.18d4ab021ef89a5f,"reason=FailedScheduling count=None msg=0/6 nodes are available: 1 c_wall violated: 2 conflicting context pair(s) with node memory, 5 node(s) had untolerated taint(s). no new claims to deallocate, preemption: 0/6 nodes are available: 1 No preemption victims found for incoming pod, 5 Preemption is not helpful for scheduling."
0.1515,Event,ADDED,eval-sanitize-30-r0-082-tw9xc.18d4ab021fb405c9,"reason=FailedScheduling count=None msg=0/6 nodes are available: 1 c_wall violated: 2 conflicting context pair(s) with node memory, 5 node(s) had untolerated taint(s). no new claims to deallocate, preemption: 0/6 nodes are available: 1 No preemption victims found for incoming pod, 5 Preemption is not helpful for scheduling."
0.1517,Event,ADDED,eval-sanitize-30-r0-082-tw9xc.18d4ab063a4c02f7,"reason=FailedScheduling count=None msg=0/6 nodes are available: 1 c_wall violated: 1 conflicting context pair(s) with node memory, 1 c_wall violated: 2 conflicting context pair(s) with node memory, 4 node(s) had untolerated taint(s). no new claims to deallocate, preemption: 0/6 nodes are available: 2 No preemption victims found for incoming pod, 4 Preemption is not helpful for scheduling."
0.1518,Event,ADDED,eval-sanitize-30-r0-082-tw9xc.18d4ab067be518c0,reason=Scheduled count=None msg=Successfully assigned compute/eval-sanitize-30-r0-082-tw9xc to kind-worker5
0.152,Event,ADDED,eval-sanitize-30-r0-082-tw9xc.18d4ab0697311f56,"reason=Pulled count=1 msg=Container image ""busybox:musl"" already present on machine"
0.1521,Event,ADDED,eval-sanitize-30-r0-082-tw9xc.18d4ab06991ea5ab,reason=Created count=1 msg=Created container: task
0.1523,Event,ADDED,eval-sanitize-30-r0-082-tw9xc.18d4ab069d9059b4,reason=Started count=1 msg=Started container task
0.1525,Event,ADDED,eval-sanitize-30-r0-082.18d4ab021e8f42a1,reason=SuccessfulCreate count=1 msg=Created pod: eval-sanitize-30-r0-082-tw9xc
0.1526,Event,ADDED,eval-sanitize-30-r0-082.18d4ab0cefe5e619,reason=Completed count=1 msg=Job completed
0.1528,Event,ADDED,eval-sanitize-30-r0-083-jwchs.18d4ab0259f97e08,"reason=FailedScheduling count=None msg=0/6 nodes are available: 1 c_wall violated: 2 conflicting context pair(s) with node memory, 5 node(s) had untolerated taint(s). no new claims to deallocate, preemption: 0/6 nodes are available: 1 No preemption victims found for incoming pod, 5 Preemption is not helpful for scheduling."
0.153,Event,ADDED,eval-sanitize-30-r0-083-jwchs.18d4ab025aa190b5,"reason=FailedScheduling count=None msg=0/6 nodes are available: 1 c_wall violated: 2 conflicting context pair(s) with node memory, 5 node(s) had untolerated taint(s). no new claims to deallocate, preemption: 0/6 nodes are available: 1 No preemption victims found for incoming pod, 5 Preemption is not helpful for scheduling."
0.1531,Event,ADDED,eval-sanitize-30-r0-083-jwchs.18d4ab06179e4616,reason=Scheduled count=None msg=Successfully assigned compute/eval-sanitize-30-r0-083-jwchs to kind-worker2
0.1533,Event,ADDED,eval-sanitize-30-r0-083-jwchs.18d4ab0634faa462,"reason=Pulled count=1 msg=Container image ""busybox:musl"" already present on machine"
0.1535,Event,ADDED,eval-sanitize-30-r0-083-jwchs.18d4ab063758de7e,reason=Created count=1 msg=Created container: task
0.1537,Event,ADDED,eval-sanitize-30-r0-083-jwchs.18d4ab063da2ae8f,reason=Started count=1 msg=Started container task
0.1539,Event,ADDED,eval-sanitize-30-r0-083.18d4ab0259b16c3a,reason=SuccessfulCreate count=1 msg=Created pod: eval-sanitize-30-r0-083-jwchs
0.1541,Event,ADDED,eval-sanitize-30-r0-083.18d4ab0b7f879f41,reason=Completed count=1 msg=Job completed
0.1543,Event,ADDED,eval-sanitize-30-r0-084-4xw7k.18d4ab029682a2a2,"reason=FailedScheduling count=None msg=0/6 nodes are available: 1 c_wall violated: 2 conflicting context pair(s) with node memory, 5 node(s) had untolerated taint(s). no new claims to deallocate, preemption: 0/6 nodes are available: 1 No preemption victims found for incoming pod, 5 Preemption is not helpful for scheduling."
0.1546,Event,ADDED,eval-sanitize-30-r0-084-4xw7k.18d4ab029729ff59,"reason=FailedScheduling count=None msg=0/6 nodes are available: 1 c_wall violated: 2 conflicting context pair(s) with node memory, 5 node(s) had untolerated taint(s). no new claims to deallocate, preemption: 0/6 nodes are available: 1 No preemption victims found for incoming pod, 5 Preemption is not helpful for scheduling."
0.1547,Event,ADDED,eval-sanitize-30-r0-084-4xw7k.18d4ab0651100eb2,"reason=FailedScheduling count=None msg=0/6 nodes are available: 1 c_wall violated: 1 conflicting context pair(s) with node memory, 1 c_wall violated: 2 conflicting context pair(s) with node memory, 4 node(s) had untolerated taint(s). no new claims to deallocate, preemption: 0/6 nodes are available: 2 No preemption victims found for incoming pod, 4 Preemption is not helpful for scheduling."
0.1549,Event,ADDED,eval-sanitize-30-r0-084-4xw7k.18d4ab066c4948d7,reason=Scheduled count=None msg=Successfully assigned compute/eval-sanitize-30-r0-084-4xw7k to kind-worker5
0.1551,Event,ADDED,eval-sanitize-30-r0-084-4xw7k.18d4ab068c12354b,"reason=Pulled count=1 msg=Container image ""busybox:musl"" already present on machine"
0.1552,Event,ADDED,eval-sanitize-30-r0-084-4xw7k.18d4ab068dc70976,reason=Created count=1 msg=Created container: task
0.1554,Event,ADDED,eval-sanitize-30-r0-084-4xw7k.18d4ab0690909d44,reason=Started count=1 msg=Started container task
0.1556,Event,ADDED,eval-sanitize-30-r0-084.18d4ab029639a84f,reason=SuccessfulCreate count=1 msg=Created pod: eval-sanitize-30-r0-084-4xw7k
0.1557,Event,ADDED,eval-sanitize-30-r0-084.18d4ab0c8f532ac1,reason=Completed count=1 msg=Job completed
0.1559,Event,ADDED,eval-sanitize-30-r0-085-q7bhr.18d4ab02d2380e2d,"reason=FailedScheduling count=None msg=0/6 nodes are available: 1 c_wall violated: 1 conflicting context pair(s) with node memory, 5 node(s) had untolerated taint(s). no new claims to deallocate, preemption: 0/6 nodes are available: 1 No preemption victims found for incoming pod, 5 Preemption is not helpful for scheduling."
0.1562,Event,ADDED,eval-sanitize-30-r0-085-q7bhr.18d4ab02d2dd23d9,"reason=FailedScheduling count=None msg=0/6 nodes are available: 1 c_wall violated: 1 conflicting context pair(s) with node memory, 5 node(s) had untolerated taint(s). no new claims to deallocate, preemption: 0/6 nodes are available: 1 No preemption victims found for incoming pod, 5 Preemption is not helpful for scheduling."
0.1563,Event,ADDED,eval-sanitize-30-r0-085-q7bhr.18d4ab06046d5edb,reason=Scheduled count=None msg=Successfully assigned compute/eval-sanitize-30-r0-085-q7bhr to kind-worker2
0.1565,Event,ADDED,eval-sanitize-30-r0-085-q7bhr.18d4ab0621390d3c,"reason=Pulled count=1 msg=Container image ""busybox:musl"" already present on machine"
0.1567,Event,ADDED,eval-sanitize-30-r0-085-q7bhr.18d4ab06232ca02c,reason=Created count=1 msg=Created container: task
0.1568,Event,ADDED,eval-sanitize-30-r0-085-q7bhr.18d4ab062986b55e,reason=Started count=1 msg=Started container task
0.157,Event,ADDED,eval-sanitize-30-r0-085.18d4ab02d1e9a6b3,reason=SuccessfulCreate count=1 msg=Created pod: eval-sanitize-30-r0-085-q7bhr
0.1572,Event,ADDED,eval-sanitize-30-r0-085.18d4ab0bbcc75411,reason=Completed count=1 msg=Job completed
0.1573,Event,ADDED,eval-sanitize-30-r0-086-v8drz.18d4ab030d9714e5,reason=Scheduled count=None msg=Successfully assigned compute/eval-sanitize-30-r0-086-v8drz to kind-worker4
0.1575,Event,ADDED,eval-sanitize-30-r0-086-v8drz.18d4ab0329ce9277,"reason=Pulled count=1 msg=Container image ""busybox:musl"" already present on machine"
0.1576,Event,ADDED,eval-sanitize-30-r0-086-v8drz.18d4ab032af6c0b0,reason=Created count=1 msg=Created container: task
0.1578,Event,ADDED,eval-sanitize-30-r0-086-v8drz.18d4ab03318f4f3c,reason=Started count=1 msg=Started container task
0.158,Event,ADDED,eval-sanitize-30-r0-086.18d4ab030ceddb1f,reason=SuccessfulCreate count=1 msg=Created pod: eval-sanitize-30-r0-086-v8drz
0.1582,Event,ADDED,eval-sanitize-30-r0-086.18d4ab08a19952ff,reason=Completed count=1 msg=Job completed
0.1584,Event,ADDED,eval-sanitize-30-r0-087-l8fx2.18d4ab03482daaa0,"reason=FailedScheduling count=None msg=0/6 nodes are available: 1 c_wall violated: 1 conflicting context pair(s) with node memory, 5 node(s) had untolerated taint(s). no new claims to deallocate, preemption: 0/6 nodes are available: 1 No preemption victims found for incoming pod, 5 Preemption is not helpful for scheduling."
0.1585,Event,ADDED,eval-sanitize-30-r0-087-l8fx2.18d4ab0348b10a8c,"reason=FailedScheduling count=None msg=0/6 nodes are available: 1 c_wall violated: 1 conflicting context pair(s) with node memory, 5 node(s) had untolerated taint(s). no new claims to deallocate, preemption: 0/6 nodes are available: 1 No preemption victims found for incoming pod, 5 Preemption is not helpful for scheduling."
0.1587,Event,ADDED,eval-sanitize-30-r0-087-l8fx2.18d4ab061cdeef0e,reason=Scheduled count=None msg=Successfully assigned compute/eval-sanitize-30-r0-087-l8fx2 to kind-worker2
0.1589,Event,ADDED,eval-sanitize-30-r0-087-l8fx2.18d4ab063e007216,"reason=Pulled count=1 msg=Container image ""busybox:musl"" already present on machine"
0.1591,Event,ADDED,eval-sanitize-30-r0-087-l8fx2.18d4ab063f8aa144,reason=Created count=1 msg=Created container: task
0.1593,Event,ADDED,eval-sanitize-30-r0-087-l8fx2.18d4ab0642777394,reason=Started count=1 msg=Started container task
0.1596,Event,ADDED,eval-sanitize-30-r0-087.18d4ab0347f2a67f,reason=SuccessfulCreate count=1 msg=Created pod: eval-sanitize-30-r0-087-l8fx2
0.1598,Event,ADDED,eval-sanitize-30-r0-087.18d4ab0b7f878301,reason=Completed count=1 msg=Job completed
0.16,Event,ADDED,eval-sanitize-30-r0-088-9zf7n.18d4ab03837eb3a7,"reason=FailedScheduling count=None msg=0/6 nodes are available: 1 c_wall violated: 3 conflicting context pair(s) with node memory, 5 node(s) had untolerated taint(s). no new claims to deallocate, preemption: 0/6 nodes are available: 1 No preemption victims found for incoming pod, 5 Preemption is not helpful for scheduling."
0.1603,Event,ADDED,eval-sanitize-30-r0-088-9zf7n.18d4ab0383fea70b,"reason=FailedScheduling count=None msg=0/6 nodes are available: 1 c_wall violated: 3 conflicting context pair(s) with node memory, 5 node(s) had untolerated taint(s). no new claims to deallocate, preemption: 0/6 nodes are available: 1 No preemption victims found for incoming pod, 5 Preemption is not helpful for scheduling."
0.1605,Event,ADDED,eval-sanitize-30-r0-088-9zf7n.18d4ab0622337e16,reason=Scheduled count=None msg=Successfully assigned compute/eval-sanitize-30-r0-088-9zf7n to kind-worker2
0.1607,Event,ADDED,eval-sanitize-30-r0-088-9zf7n.18d4ab06427ccccb,"reason=Pulled count=1 msg=Container image ""busybox:musl"" already present on machine"
0.161,Event,ADDED,eval-sanitize-30-r0-088-9zf7n.18d4ab06443a386e,reason=Created count=1 msg=Created container: task
0.1612,Event,ADDED,eval-sanitize-30-r0-088-9zf7n.18d4ab0649433de1,reason=Started count=1 msg=Started container task
0.1614,Event,ADDED,eval-sanitize-30-r0-088.18d4ab0383326f77,reason=SuccessfulCreate count=1 msg=Created pod: eval-sanitize-30-r0-088-9zf7n
0.1615,Event,ADDED,eval-sanitize-30-r0-088.18d4ab0b81c8825a,reason=Completed count=1 msg=Job completed
0.1618,Event,ADDED,eval-sanitize-30-r0-089-z4hfk.18d4ab03c0619ff5,"reason=FailedScheduling count=None msg=0/6 nodes are available: 1 c_wall violated: 2 conflicting context pair(s) with node memory, 5 node(s) had untolerated taint(s). no new claims to deallocate, preemption: 0/6 nodes are available: 1 No preemption victims found for incoming pod, 5 Preemption is not helpful for scheduling."
0.1621,Event,ADDED,eval-sanitize-30-r0-089-z4hfk.18d4ab03c1267d6f,"reason=FailedScheduling count=None msg=0/6 nodes are available: 1 c_wall violated: 2 conflicting context pair(s) with node memory, 5 node(s) had untolerated taint(s). no new claims to deallocate, preemption: 0/6 nodes are available: 1 No preemption victims found for incoming pod, 5 Preemption is not helpful for scheduling."
0.1622,Event,ADDED,eval-sanitize-30-r0-089-z4hfk.18d4ab0629803abd,reason=Scheduled count=None msg=Successfully assigned compute/eval-sanitize-30-r0-089-z4hfk to kind-worker2
0.1625,Event,ADDED,eval-sanitize-30-r0-089-z4hfk.18d4ab0644c2c9c9,"reason=Pulled count=1 msg=Container image ""busybox:musl"" already present on machine"
0.1627,Event,ADDED,eval-sanitize-30-r0-089-z4hfk.18d4ab06499a8efd,reason=Created count=1 msg=Created container: task
0.1629,Event,ADDED,eval-sanitize-30-r0-089-z4hfk.18d4ab064ce1cc52,reason=Started count=1 msg=Started container task
0.163,Event,ADDED,eval-sanitize-30-r0-089.18d4ab03bfd17eea,reason=SuccessfulCreate count=1 msg=Created pod: eval-sanitize-30-r0-089-z4hfk
0.1633,Event,ADDED,eval-sanitize-30-r0-089.18d4ab0b7f5114e8,reason=Completed count=1 msg=Job completed
0.1634,Event,ADDED,eval-sanitize-30-r0-090-lptzr.18d4ab03fcd14518,"reason=FailedScheduling count=None msg=0/6 nodes are available: 1 c_wall violated: 2 conflicting context pair(s) with node memory, 5 node(s) had untolerated taint(s). no new claims to deallocate, preemption: 0/6 nodes are available: 1 No preemption victims found for incoming pod, 5 Preemption is not helpful for scheduling."
0.1636,Event,ADDED,eval-sanitize-30-r0-090-lptzr.18d4ab03fd9b23ab,"reason=FailedScheduling count=None msg=0/6 nodes are available: 1 c_wall violated: 2 conflicting context pair(s) with node memory, 5 node(s) had untolerated taint(s). no new claims to deallocate, preemption: 0/6 nodes are available: 1 No preemption victims found for incoming pod, 5 Preemption is not helpful for scheduling."
0.1638,Event,ADDED,eval-sanitize-30-r0-090-lptzr.18d4ab064576cc49,"reason=FailedScheduling count=None msg=0/6 nodes are available: 2 c_wall violated: 2 conflicting context pair(s) with node memory, 4 node(s) had untolerated taint(s). no new claims to deallocate, preemption: 0/6 nodes are available: 2 No preemption victims found for incoming pod, 4 Preemption is not helpful for scheduling."
0.164,Event,ADDED,eval-sanitize-30-r0-090-lptzr.18d4ab06b73e2983,reason=Scheduled count=None msg=Successfully assigned compute/eval-sanitize-30-r0-090-lptzr to kind-worker
0.1641,Event,ADDED,eval-sanitize-30-r0-090-lptzr.18d4ab06d9724d73,"reason=Pulled count=1 msg=Container image ""busybox:musl"" already present on machine"
0.1643,Event,ADDED,eval-sanitize-30-r0-090-lptzr.18d4ab06db2698f6,reason=Created count=1 msg=Created container: task
0.1645,Event,ADDED,eval-sanitize-30-r0-090-lptzr.18d4ab06dff4cdb5,reason=Started count=1 msg=Started container task
0.1646,Event,ADDED,eval-sanitize-30-r0-090.18d4ab03fc7c28fc,reason=SuccessfulCreate count=1 msg=Created pod: eval-sanitize-30-r0-090-lptzr
0.1648,Event,ADDED,eval-sanitize-30-r0-090.18d4ab0d15ae75e0,reason=Completed count=1 msg=Job completed
0.165,Event,ADDED,eval-sanitize-30-r0-091-ksvxd.18d4ab0438c815c5,"reason=FailedScheduling count=None msg=0/6 nodes are available: 1 c_wall violated: 1 conflicting context pair(s) with node memory, 5 node(s) had untolerated taint(s). no new claims to deallocate, preemption: 0/6 nodes are available: 1 No preemption victims found for incoming pod, 5 Preemption is not helpful for scheduling."
0.1651,Event,ADDED,eval-sanitize-30-r0-091-ksvxd.18d4ab043f170c14,"reason=FailedScheduling count=None msg=0/6 nodes are available: 1 c_wall violated: 1 conflicting context pair(s) with node memory, 5 node(s) had untolerated taint(s). no new claims to deallocate, preemption: 0/6 nodes are available: 1 No preemption victims found for incoming pod, 5 Preemption is not helpful for scheduling."
0.1654,Event,ADDED,eval-sanitize-30-r0-091-ksvxd.18d4ab064ad6b11b,"reason=FailedScheduling count=None msg=0/6 nodes are available: 1 c_wall violated: 1 conflicting context pair(s) with node memory, 1 c_wall violated: 2 conflicting context pair(s) with node memory, 4 node(s) had untolerated taint(s). no new claims to deallocate, preemption: 0/6 nodes are available: 2 No preemption victims found for incoming pod, 4 Preemption is not helpful for scheduling."
0.1656,Event,ADDED,eval-sanitize-30-r0-091-ksvxd.18d4ab06bed04cf3,reason=Scheduled count=None msg=Successfully assigned compute/eval-sanitize-30-r0-091-ksvxd to kind-worker
0.1657,Event,ADDED,eval-sanitize-30-r0-091-ksvxd.18d4ab06e0154f04,"reason=Pulled count=1 msg=Container image ""busybox:musl"" already present on machine"
0.1659,Event,ADDED,eval-sanitize-30-r0-091-ksvxd.18d4ab06e3acc796,reason=Created count=1 msg=Created container: task
0.1661,Event,ADDED,eval-sanitize-30-r0-091-ksvxd.18d4ab06e99b337a,reason=Started count=1 msg=Started container task
0.1662,Event,ADDED,eval-sanitize-30-r0-091.18d4ab043741c71a,reason=SuccessfulCreate count=1 msg=Created pod: eval-sanitize-30-r0-091-ksvxd
0.1664,Event,ADDED,eval-sanitize-30-r0-091.18d4ab0d21cedbc6,reason=Completed count=1 msg=Job completed
0.1665,Event,ADDED,eval-sanitize-30-r0-092-gxsf7.18d4ab04766a7270,"reason=FailedScheduling count=None msg=0/6 nodes are available: 1 c_wall violated: 2 conflicting context pair(s) with node memory, 5 node(s) had untolerated taint(s). no new claims to deallocate, preemption: 0/6 nodes are available: 1 No preemption victims found for incoming pod, 5 Preemption is not helpful for scheduling."
0.1667,Event,ADDED,eval-sanitize-30-r0-092-gxsf7.18d4ab04883a41e0,"reason=FailedScheduling count=None msg=0/6 nodes are available: 1 c_wall violated: 2 conflicting context pair(s) with node memory, 5 node(s) had untolerated taint(s). no new claims to deallocate, preemption: 0/6 nodes are available: 1 No preemption victims found for incoming pod, 5 Preemption is not helpful for scheduling."
0.1669,Event,ADDED,eval-sanitize-30-r0-092-gxsf7.18d4ab064b797027,"reason=FailedScheduling count=None msg=0/6 nodes are available: 1 c_wall violated: 1 conflicting context pair(s) with node memory, 1 c_wall violated: 2 conflicting context pair(s) with node memory, 4 node(s) had untolerated taint(s). no new claims to deallocate, preemption: 0/6 nodes are available: 2 No preemption victims found for incoming pod, 4 Preemption is not helpful for scheduling."
0.1671,Event,ADDED,eval-sanitize-30-r0-092-gxsf7.18d4ab06a022e38d,reason=Scheduled count=None msg=Successfully assigned compute/eval-sanitize-30-r0-092-gxsf7 to kind-worker5
0.1673,Event,ADDED,eval-sanitize-30-r0-092-gxsf7.18d4ab06bee04c9d,"reason=Pulled count=1 msg=Container image ""busybox:musl"" already present on machine"
0.1674,Event,ADDED,eval-sanitize-30-r0-092-gxsf7.18d4ab06c0eb789d,reason=Created count=1 msg=Created container: task
0.1676,Event,ADDED,eval-sanitize-30-r0-092-gxsf7.18d4ab06c807622b,reason=Started count=1 msg=Started container task
0.1677,Event,ADDED,eval-sanitize-30-r0-092.18d4ab04755470f3,reason=SuccessfulCreate count=1 msg=Created pod: eval-sanitize-30-r0-092-gxsf7
0.1679,Event,ADDED,eval-sanitize-30-r0-092.18d4ab0ce8747c24,reason=Completed count=1 msg=Job completed
0.1681,Event,ADDED,eval-sanitize-30-r0-093-wn4ns.18d4ab04b53e30e4,reason=Scheduled count=None msg=Successfully assigned compute/eval-sanitize-30-r0-093-wn4ns to kind-worker4
0.1682,Event,ADDED,eval-sanitize-30-r0-093-wn4ns.18d4ab04d789c3a7,"reason=Pulled count=1 msg=Container image ""busybox:musl"" already present on machine"
0.1685,Event,ADDED,eval-sanitize-30-r0-093-wn4ns.18d4ab04d917631b,reason=Created count=1 msg=Created container: task
0.1686,Event,ADDED,eval-sanitize-30-r0-093-wn4ns.18d4ab04de199c1a,reason=Started count=1 msg=Started container task
0.1688,Event,ADDED,eval-sanitize-30-r0-093.18d4ab04b154231e,reason=SuccessfulCreate count=1 msg=Created pod: eval-sanitize-30-r0-093-wn4ns
0.169,Event,ADDED,eval-sanitize-30-r0-093.18d4ab0a08843149,reason=Completed count=1 msg=Job completed
0.1691,Event,ADDED,eval-sanitize-30-r0-094-skw2l.18d4ab04ebf06844,"reason=FailedScheduling count=None msg=0/6 nodes are available: 1 c_wall violated: 2 conflicting context pair(s) with node memory, 5 node(s) had untolerated taint(s). no new claims to deallocate, preemption: 0/6 nodes are available: 1 No preemption victims found for incoming pod, 5 Preemption is not helpful for scheduling."
0.1693,Event,ADDED,eval-sanitize-30-r0-094-skw2l.18d4ab04fd65c181,"reason=FailedScheduling count=None msg=0/6 nodes are available: 1 c_wall violated: 2 conflicting context pair(s) with node memory, 5 node(s) had untolerated taint(s). no new claims to deallocate, preemption: 0/6 nodes are available: 1 No preemption victims found for incoming pod, 5 Preemption is not helpful for scheduling."
0.1695,Event,ADDED,eval-sanitize-30-r0-094-skw2l.18d4ab063f700309,"reason=FailedScheduling count=None msg=0/6 nodes are available: 1 c_wall violated: 1 conflicting context pair(s) with node memory, 1 c_wall violated: 2 conflicting context pair(s) with node memory, 4 node(s) had untolerated taint(s). no new claims to deallocate, preemption: 0/6 nodes are available: 2 No preemption victims found for incoming pod, 4 Preemption is not helpful for scheduling."
0.1697,Event,ADDED,eval-sanitize-30-r0-094-skw2l.18d4ab068745aedf,reason=Scheduled count=None msg=Successfully assigned compute/eval-sanitize-30-r0-094-skw2l to kind-worker5
0.1698,Event,ADDED,eval-sanitize-30-r0-094-skw2l.18d4ab06a4b35f43,"reason=Pulled count=1 msg=Container image ""busybox:musl"" already present on machine"
0.17,Event,ADDED,eval-sanitize-30-r0-094-skw2l.18d4ab06a669745d,reason=Created count=1 msg=Created container: task
0.1702,Event,ADDED,eval-sanitize-30-r0-094-skw2l.18d4ab06ab983466,reason=Started count=1 msg=Started container task
0.1703,Event,ADDED,eval-sanitize-30-r0-094.18d4ab04eb84a22d,reason=SuccessfulCreate count=1 msg=Created pod: eval-sanitize-30-r0-094-skw2l
0.1705,Event,ADDED,eval-sanitize-30-r0-094.18d4ab0ce8adadef,reason=Completed count=1 msg=Job completed
0.1706,Event,ADDED,eval-sanitize-30-r0-095-zkf56.18d4ab052ff88028,reason=Scheduled count=None msg=Successfully assigned compute/eval-sanitize-30-r0-095-zkf56 to kind-worker4
0.1708,Event,ADDED,eval-sanitize-30-r0-095-zkf56.18d4ab054b901506,"reason=Pulled count=1 msg=Container image ""busybox:musl"" already present on machine"
0.171,Event,ADDED,eval-sanitize-30-r0-095-zkf56.18d4ab054cebc6bb,reason=Created count=1 msg=Created container: task
0.1711,Event,ADDED,eval-sanitize-30-r0-095-zkf56.18d4ab0553d970a1,reason=Started count=1 msg=Started container task
0.1713,Event,ADDED,eval-sanitize-30-r0-095.18d4ab052a9bad75,reason=SuccessfulCreate count=1 msg=Created pod: eval-sanitize-30-r0-095-zkf56
0.1715,Event,ADDED,eval-sanitize-30-r0-095.18d4ab0a80af5c95,reason=Completed count=1 msg=Job completed
0.1716,Event,ADDED,eval-sanitize-30-r0-096-qgtd4.18d4ab056928cf8f,"reason=FailedScheduling count=None msg=0/6 nodes are available: 1 c_wall violated: 2 conflicting context pair(s) with node memory, 5 node(s) had untolerated taint(s). no new claims to deallocate, preemption: 0/6 nodes are available: 1 No preemption victims found for incoming pod, 5 Preemption is not helpful for scheduling."
0.1718,Event,ADDED,eval-sanitize-30-r0-096-qgtd4.18d4ab0569eaf3af,"reason=FailedScheduling count=None msg=0/6 nodes are available: 1 c_wall violated: 2 conflicting context pair(s) with node memory, 5 node(s) had untolerated taint(s). no new claims to deallocate, preemption: 0/6 nodes are available: 1 No preemption victims found for incoming pod, 5 Preemption is not helpful for scheduling."
0.172,Event,ADDED,eval-sanitize-30-r0-096-qgtd4.18d4ab060531d1f5,reason=Scheduled count=None msg=Successfully assigned compute/eval-sanitize-30-r0-096-qgtd4 to kind-worker2
0.1721,Event,ADDED,eval-sanitize-30-r0-096-qgtd4.18d4ab06221ffcb8,"reason=Pulled count=1 msg=Container image ""busybox:musl"" already present on machine"
0.1724,Event,ADDED,eval-sanitize-30-r0-096-qgtd4.18d4ab0624487739,reason=Created count=1 msg=Created container: task
0.1725,Event,ADDED,eval-sanitize-30-r0-096-qgtd4.18d4ab06298522bf,reason=Started count=1 msg=Started container task
0.1727,Event,ADDED,eval-sanitize-30-r0-096.18d4ab05689f36f1,reason=SuccessfulCreate count=1 msg=Created pod: eval-sanitize-30-r0-096-qgtd4
0.1729,Event,ADDED,eval-sanitize-30-r0-096.18d4ab0b8357ae81,reason=Completed count=1 msg=Job completed
0.173,Event,ADDED,eval-sanitize-30-r0-097-bmscf.18d4ab059e39fdd8,"reason=FailedScheduling count=None msg=0/6 nodes are available: 1 c_wall violated: 2 conflicting context pair(s) with node memory, 5 node(s) had untolerated taint(s). no new claims to deallocate, preemption: 0/6 nodes are available: 1 No preemption victims found for incoming pod, 5 Preemption is not helpful for scheduling."
0.1732,Event,ADDED,eval-sanitize-30-r0-097-bmscf.18d4ab05afe23c36,"reason=FailedScheduling count=None msg=0/6 nodes are available: 1 c_wall violated: 2 conflicting context pair(s) with node memory, 5 node(s) had untolerated taint(s). no new claims to deallocate, preemption: 0/6 nodes are available: 1 No preemption victims found for incoming pod, 5 Preemption is not helpful for scheduling."
0.1734,Event,ADDED,eval-sanitize-30-r0-097-bmscf.18d4ab062e83d866,reason=Scheduled count=None msg=Successfully assigned compute/eval-sanitize-30-r0-097-bmscf to kind-worker2
0.1735,Event,ADDED,eval-sanitize-30-r0-097-bmscf.18d4ab064b2fe001,"reason=Pulled count=1 msg=Container image ""busybox:musl"" already present on machine"
0.1737,Event,ADDED,eval-sanitize-30-r0-097-bmscf.18d4ab064cb2fe2a,reason=Created count=1 msg=Created container: task
0.1739,Event,ADDED,eval-sanitize-30-r0-097-bmscf.18d4ab06527894ab,reason=Started count=1 msg=Started container task
0.174,Event,ADDED,eval-sanitize-30-r0-097.18d4ab059d08ee79,reason=SuccessfulCreate count=1 msg=Created pod: eval-sanitize-30-r0-097-bmscf
0.1742,Event,ADDED,eval-sanitize-30-r0-097.18d4ab0b81f83092,reason=Completed count=1 msg=Job completed
0.1743,Event,ADDED,eval-sanitize-30-r0-098-gslhk.18d4ab05dfe7b565,"reason=FailedScheduling count=None msg=0/6 nodes are available: 1 c_wall violated: 1 conflicting context pair(s) with node memory, 5 node(s) had untolerated taint(s). no new claims to deallocate, preemption: 0/6 nodes are available: 1 No preemption victims found for incoming pod, 5 Preemption is not helpful for scheduling."
0.1745,Event,ADDED,eval-sanitize-30-r0-098-gslhk.18d4ab05f19ee04a,"reason=FailedScheduling count=None msg=0/6 nodes are available: 1 c_wall violated: 1 conflicting context pair(s) with node memory, 5 node(s) had untolerated taint(s). no new claims to deallocate, preemption: 0/6 nodes are available: 1 No preemption victims found for incoming pod, 5 Preemption is not helpful for scheduling."
0.1747,Event,ADDED,eval-sanitize-30-r0-098-gslhk.18d4ab0644e77bc7,"reason=FailedScheduling count=None msg=0/6 nodes are available: 1 c_wall violated: 1 conflicting context pair(s) with node memory, 1 c_wall violated: 2 conflicting context pair(s) with node memory, 4 node(s) had untolerated taint(s). no new claims to deallocate, preemption: 0/6 nodes are available: 2 No preemption victims found for incoming pod, 4 Preemption is not helpful for scheduling."
0.1749,Event,ADDED,eval-sanitize-30-r0-098-gslhk.18d4ab06b1ad814f,reason=Scheduled count=None msg=Successfully assigned compute/eval-sanitize-30-r0-098-gslhk to kind-worker
0.175,Event,ADDED,eval-sanitize-30-r0-098-gslhk.18d4ab06d0a81322,"reason=Pulled count=1 msg=Container image ""busybox:musl"" already present on machine"
0.1752,Event,ADDED,eval-sanitize-30-r0-098-gslhk.18d4ab06d45cbe06,reason=Created count=1 msg=Created container: task
0.1753,Event,ADDED,eval-sanitize-30-r0-098-gslhk.18d4ab06da10681c,reason=Started count=1 msg=Started container task
0.1755,Event,ADDED,eval-sanitize-30-r0-098.18d4ab05dc06dae8,reason=SuccessfulCreate count=1 msg=Created pod: eval-sanitize-30-r0-098-gslhk
0.1757,Event,ADDED,eval-sanitize-30-r0-098.18d4ab0d134fa1cb,reason=Completed count=1 msg=Job completed
0.1758,Event,ADDED,eval-sanitize-30-r0-099-h6sjb.18d4ab0616454473,"reason=FailedScheduling count=None msg=0/6 nodes are available: 2 c_wall violated: 2 conflicting context pair(s) with node memory, 4 node(s) had untolerated taint(s). no new claims to deallocate, preemption: 0/6 nodes are available: 2 No preemption victims found for incoming pod, 4 Preemption is not helpful for scheduling."
0.176,Event,ADDED,eval-sanitize-30-r0-099-h6sjb.18d4ab063effe929,"reason=FailedScheduling count=None msg=0/6 nodes are available: 2 c_wall violated: 2 conflicting context pair(s) with node memory, 4 node(s) had untolerated taint(s). no new claims to deallocate, preemption: 0/6 nodes are available: 2 No preemption victims found for incoming pod, 4 Preemption is not helpful for scheduling."
0.1762,Event,ADDED,eval-sanitize-30-r0-099-h6sjb.18d4ab06aff08fbb,reason=Scheduled count=None msg=Successfully assigned compute/eval-sanitize-30-r0-099-h6sjb to kind-worker
0.1763,Event,ADDED,eval-sanitize-30-r0-099-h6sjb.18d4ab06dffa6708,"reason=Pulled count=1 msg=Container image ""busybox:musl"" already present on machine"
0.1765,Event,ADDED,eval-sanitize-30-r0-099-h6sjb.18d4ab06e2cb389c,reason=Created count=1 msg=Created container: task
0.1767,Event,ADDED,eval-sanitize-30-r0-099-h6sjb.18d4ab06e8f7b7c6,reason=Started count=1 msg=Started container task
0.1769,Event,ADDED,eval-sanitize-30-r0-099.18d4ab061485d4f9,reason=SuccessfulCreate count=1 msg=Created pod: eval-sanitize-30-r0-099-h6sjb
0.1771,Event,ADDED,eval-sanitize-30-r0-099.18d4ab0d18ab5ce8,reason=Completed count=1 msg=Job completed
0.1772,Event,ADDED,eval-sanitize-30-r0-100-m8hh4.18d4ab0651a0d07b,"reason=FailedScheduling count=None msg=0/6 nodes are available: 1 c_wall violated: 1 conflicting context pair(s) with node memory, 1 c_wall violated: 2 conflicting context pair(s) with node memory, 4 node(s) had untolerated taint(s). no new claims to deallocate, preemption: 0/6 nodes are available: 2 No preemption victims found for incoming pod, 4 Preemption is not helpful for scheduling."
0.1774,Event,ADDED,eval-sanitize-30-r0-100-m8hh4.18d4ab066f4af4a8,reason=Scheduled count=None msg=Successfully assigned compute/eval-sanitize-30-r0-100-m8hh4 to kind-worker5
0.1776,Event,ADDED,eval-sanitize-30-r0-100-m8hh4.18d4ab068dcc1c0b,"reason=Pulled count=1 msg=Container image ""busybox:musl"" already present on machine"
0.1778,Event,ADDED,eval-sanitize-30-r0-100-m8hh4.18d4ab068ff9afbd,reason=Created count=1 msg=Created container: task
0.1779,Event,ADDED,eval-sanitize-30-r0-100-m8hh4.18d4ab0692dee977,reason=Started count=1 msg=Started container task
0.1781,Event,ADDED,eval-sanitize-30-r0-100.18d4ab0650843898,reason=SuccessfulCreate count=1 msg=Created pod: eval-sanitize-30-r0-100-m8hh4
0.1783,Event,ADDED,eval-sanitize-30-r0-100.18d4ab0ce924d299,reason=Completed count=1 msg=Job completed
0.1784,Event,ADDED,eval-sanitize-30-r0-101-mrhv7.18d4ab06931b532a,reason=Scheduled count=None msg=Successfully assigned compute/eval-sanitize-30-r0-101-mrhv7 to kind-worker4
0.1786,Event,ADDED,eval-sanitize-30-r0-101-mrhv7.18d4ab06b32b30c7,"reason=Pulled count=1 msg=Container image ""busybox:musl"" already present on machine"
0.1788,Event,ADDED,eval-sanitize-30-r0-101-mrhv7.18d4ab06b49f91b2,reason=Created count=1 msg=Created container: task
0.1789,Event,ADDED,eval-sanitize-30-r0-101-mrhv7.18d4ab06ba3f6f47,reason=Started count=1 msg=Started container task
0.1791,Event,ADDED,eval-sanitize-30-r0-101.18d4ab068ae1a671,reason=SuccessfulCreate count=1 msg=Created pod: eval-sanitize-30-r0-101-mrhv7
0.1793,Event,ADDED,eval-sanitize-30-r0-101.18d4ab0c8fa50a76,reason=Completed count=1 msg=Job completed
0.1794,Event,ADDED,eval-sanitize-30-r0-102-sl9gx.18d4ab06ca431c43,reason=Scheduled count=None msg=Successfully assigned compute/eval-sanitize-30-r0-102-sl9gx to kind-worker2
0.1796,Event,ADDED,eval-sanitize-30-r0-102-sl9gx.18d4ab06e95842c4,"reason=Pulled count=1 msg=Container image ""busybox:musl"" already present on machine"
0.1798,Event,ADDED,eval-sanitize-30-r0-102-sl9gx.18d4ab06eac3333d,reason=Created count=1 msg=Created container: task
0.18,Event,ADDED,eval-sanitize-30-r0-102-sl9gx.18d4ab06f2341b96,reason=Started count=1 msg=Started container task
0.1802,Event,ADDED,eval-sanitize-30-r0-102.18d4ab06c8da749d,reason=SuccessfulCreate count=1 msg=Created pod: eval-sanitize-30-r0-102-sl9gx
0.1803,Event,ADDED,eval-sanitize-30-r0-102.18d4ab0d2a906c9b,reason=Completed count=1 msg=Job completed
0.1805,Event,ADDED,eval-sanitize-30-r0-103-ggbk2.18d4ab0705a3364c,reason=Scheduled count=None msg=Successfully assigned compute/eval-sanitize-30-r0-103-ggbk2 to kind-worker3
0.1807,Event,ADDED,eval-sanitize-30-r0-103-ggbk2.18d4ab07205d30cc,"reason=Pulled count=1 msg=Container image ""busybox:musl"" already present on machine"
0.1808,Event,ADDED,eval-sanitize-30-r0-103-ggbk2.18d4ab0721c4f484,reason=Created count=1 msg=Created container: task
0.181,Event,ADDED,eval-sanitize-30-r0-103-ggbk2.18d4ab072a2aa7d5,reason=Started count=1 msg=Started container task
0.1812,Event,ADDED,eval-sanitize-30-r0-103.18d4ab07044e5d0e,reason=SuccessfulCreate count=1 msg=Created pod: eval-sanitize-30-r0-103-ggbk2
0.1813,Event,ADDED,eval-sanitize-30-r0-103.18d4ab0cfcdf1b08,reason=Completed count=1 msg=Job completed
0.1815,Event,ADDED,eval-sanitize-30-r0-104-56vgx.18d4ab074b34ebb9,reason=Scheduled count=None msg=Successfully assigned compute/eval-sanitize-30-r0-104-56vgx to kind-worker5
0.1817,Event,ADDED,eval-sanitize-30-r0-104-56vgx.18d4ab076825c25d,"reason=Pulled count=1 msg=Container image ""busybox:musl"" already present on machine"
0.1818,Event,ADDED,eval-sanitize-30-r0-104-56vgx.18d4ab0769b41237,reason=Created count=1 msg=Created container: task
0.182,Event,ADDED,eval-sanitize-30-r0-104-56vgx.18d4ab077067cf27,reason=Started count=1 msg=Started container task
0.1822,Event,ADDED,eval-sanitize-30-r0-104.18d4ab0741b93223,reason=SuccessfulCreate count=1 msg=Created pod: eval-sanitize-30-r0-104-56vgx
0.1823,Event,ADDED,eval-sanitize-30-r0-104.18d4ab0d28500ac0,reason=Completed count=1 msg=Job completed
0.1825,Event,ADDED,eval-sanitize-30-r0-105-srl2n.18d4ab078114c880,reason=Scheduled count=None msg=Successfully assigned compute/eval-sanitize-30-r0-105-srl2n to kind-worker3
0.1826,Event,ADDED,eval-sanitize-30-r0-105-srl2n.18d4ab079dd25a42,"reason=Pulled count=1 msg=Container image ""busybox:musl"" already present on machine"
0.1828,Event,ADDED,eval-sanitize-30-r0-105-srl2n.18d4ab079f194442,reason=Created count=1 msg=Created container: task
0.183,Event,ADDED,eval-sanitize-30-r0-105-srl2n.18d4ab07a45d14a6,reason=Started count=1 msg=Started container task
0.1831,Event,ADDED,eval-sanitize-30-r0-105.18d4ab077acce509,reason=SuccessfulCreate count=1 msg=Created pod: eval-sanitize-30-r0-105-srl2n
0.1833,Event,ADDED,eval-sanitize-30-r0-105.18d4ab0d4844aff6,reason=Completed count=1 msg=Job completed
0.1834,Event,ADDED,eval-sanitize-30-r0-106-wdjq8.18d4ab07b74d6e81,reason=Scheduled count=None msg=Successfully assigned compute/eval-sanitize-30-r0-106-wdjq8 to kind-worker3
0.1836,Event,ADDED,eval-sanitize-30-r0-106-wdjq8.18d4ab07d46cefeb,"reason=Pulled count=1 msg=Container image ""busybox:musl"" already present on machine"
0.1838,Event,ADDED,eval-sanitize-30-r0-106-wdjq8.18d4ab07d5998c8d,reason=Created count=1 msg=Created container: task
0.1839,Event,ADDED,eval-sanitize-30-r0-106-wdjq8.18d4ab07da635a38,reason=Started count=1 msg=Started container task
0.1841,Event,ADDED,eval-sanitize-30-r0-106.18d4ab07b4f83e48,reason=SuccessfulCreate count=1 msg=Created pod: eval-sanitize-30-r0-106-wdjq8
0.1843,Event,ADDED,eval-sanitize-30-r0-106.18d4ab0d7b045135,reason=Completed count=1 msg=Job completed
0.1844,Event,ADDED,eval-sanitize-30-r0-107-hm688.18d4ab07f24227bd,reason=Scheduled count=None msg=Successfully assigned compute/eval-sanitize-30-r0-107-hm688 to kind-worker3
0.1846,Event,ADDED,eval-sanitize-30-r0-107-hm688.18d4ab080fbf7669,"reason=Pulled count=1 msg=Container image ""busybox:musl"" already present on machine"
0.1847,Event,ADDED,eval-sanitize-30-r0-107-hm688.18d4ab08111f9a93,reason=Created count=1 msg=Created container: task
0.1849,Event,ADDED,eval-sanitize-30-r0-107-hm688.18d4ab08179efd51,reason=Started count=1 msg=Started container task
0.1851,Event,ADDED,eval-sanitize-30-r0-107.18d4ab07f04f32a3,reason=SuccessfulCreate count=1 msg=Created pod: eval-sanitize-30-r0-107-hm688
0.1854,Event,ADDED,eval-sanitize-30-r0-107.18d4ab0dafece956,reason=Completed count=1 msg=Job completed
0.1856,Event,ADDED,eval-sanitize-30-r0-108-zht6r.18d4ab08340def0c,reason=Scheduled count=None msg=Successfully assigned compute/eval-sanitize-30-r0-108-zht6r to kind-worker5
0.1858,Event,ADDED,eval-sanitize-30-r0-108-zht6r.18d4ab0852cb9198,"reason=Pulled count=1 msg=Container image ""busybox:musl"" already present on machine"
0.1859,Event,ADDED,eval-sanitize-30-r0-108-zht6r.18d4ab08544315ca,reason=Created count=1 msg=Created container: task
0.1861,Event,ADDED,eval-sanitize-30-r0-108-zht6r.18d4ab085d0a7525,reason=Started count=1 msg=Started container task
0.1863,Event,ADDED,eval-sanitize-30-r0-108.18d4ab082cee737a,reason=SuccessfulCreate count=1 msg=Created pod: eval-sanitize-30-r0-108-zht6r
0.1864,Event,ADDED,eval-sanitize-30-r0-108.18d4ab0db0ae3d8d,reason=Completed count=1 msg=Job completed
0.1866,Event,ADDED,eval-sanitize-30-r0-109-zxf7q.18d4ab0870ab47f6,reason=Scheduled count=None msg=Successfully assigned compute/eval-sanitize-30-r0-109-zxf7q to kind-worker5
0.1868,Event,ADDED,eval-sanitize-30-r0-109-zxf7q.18d4ab088c62b12c,"reason=Pulled count=1 msg=Container image ""busybox:musl"" already present on machine"
0.1873,Event,ADDED,eval-sanitize-30-r0-109-zxf7q.18d4ab088d9facd3,reason=Created count=1 msg=Created container: task
0.1875,Event,ADDED,eval-sanitize-30-r0-109-zxf7q.18d4ab0892593471,reason=Started count=1 msg=Started container task
0.1877,Event,ADDED,eval-sanitize-30-r0-109.18d4ab0867fc76a6,reason=SuccessfulCreate count=1 msg=Created pod: eval-sanitize-30-r0-109-zxf7q
0.1879,Event,ADDED,eval-sanitize-30-r0-109.18d4ab0e3353fead,reason=Completed count=1 msg=Job completed
0.188,Event,ADDED,eval-sanitize-30-r0-110-8592j.18d4ab08a529bbe7,reason=Scheduled count=None msg=Successfully assigned compute/eval-sanitize-30-r0-110-8592j to kind-worker3
0.1882,Event,ADDED,eval-sanitize-30-r0-110-8592j.18d4ab08c7b7c88c,"reason=Pulled count=1 msg=Container image ""busybox:musl"" already present on machine"
0.1884,Event,ADDED,eval-sanitize-30-r0-110-8592j.18d4ab08c8ea8a53,reason=Created count=1 msg=Created container: task
0.1886,Event,ADDED,eval-sanitize-30-r0-110-8592j.18d4ab08cdce8101,reason=Started count=1 msg=Started container task
0.1887,Event,ADDED,eval-sanitize-30-r0-110.18d4ab08a37972d7,reason=SuccessfulCreate count=1 msg=Created pod: eval-sanitize-30-r0-110-8592j
0.1889,Event,ADDED,eval-sanitize-30-r0-110.18d4ab0e5706550e,reason=Completed count=1 msg=Job completed
0.189,Event,ADDED,eval-sanitize-30-r0-111-mxqjf.18d4ab08e5b47f9a,reason=Scheduled count=None msg=Successfully assigned compute/eval-sanitize-30-r0-111-mxqjf to kind-worker2
0.1892,Event,ADDED,eval-sanitize-30-r0-111-mxqjf.18d4ab08ffe2b9a5,"reason=Pulled count=1 msg=Container image ""busybox:musl"" already present on machine"
0.1894,Event,ADDED,eval-sanitize-30-r0-111-mxqjf.18d4ab09012b4032,reason=Created count=1 msg=Created container: task
0.1895,Event,ADDED,eval-sanitize-30-r0-111-mxqjf.18d4ab0906777742,reason=Started count=1 msg=Started container task
0.1897,Event,ADDED,eval-sanitize-30-r0-111.18d4ab08dea0ca2f,reason=SuccessfulCreate count=1 msg=Created pod: eval-sanitize-30-r0-111-mxqjf
0.1899,Event,ADDED,eval-sanitize-30-r0-111.18d4ab0e927adbed,reason=Completed count=1 msg=Job completed
0.19,Event,ADDED,eval-sanitize-30-r0-112-4dx2x.18d4ab091c73d0f3,reason=Scheduled count=None msg=Successfully assigned compute/eval-sanitize-30-r0-112-4dx2x to kind-worker5
0.1902,Event,ADDED,eval-sanitize-30-r0-112-4dx2x.18d4ab0937005fa1,"reason=Pulled count=1 msg=Container image ""busybox:musl"" already present on machine"
0.1905,Event,ADDED,eval-sanitize-30-r0-112-4dx2x.18d4ab09384e453d,reason=Created count=1 msg=Created container: task
0.1906,Event,ADDED,eval-sanitize-30-r0-112-4dx2x.18d4ab093aea2cca,reason=Started count=1 msg=Started container task
0.1908,Event,ADDED,eval-sanitize-30-r0-112.18d4ab091a458f77,reason=SuccessfulCreate count=1 msg=Created pod: eval-sanitize-30-r0-112-4dx2x
0.1909,Event,ADDED,eval-sanitize-30-r0-112.18d4ab0ee2cca397,reason=Completed count=1 msg=Job completed
0.1911,Event,ADDED,eval-sanitize-30-r0-113-4wfk9.18d4ab0957f6b78f,reason=Scheduled count=None msg=Successfully assigned compute/eval-sanitize-30-r0-113-4wfk9 to kind-worker2
0.1913,Event,ADDED,eval-sanitize-30-r0-113-4wfk9.18d4ab09734b2af9,"reason=Pulled count=1 msg=Container image ""busybox:musl"" already present on machine"
0.1914,Event,ADDED,eval-sanitize-30-r0-113-4wfk9.18d4ab0974d67a9f,reason=Created count=1 msg=Created container: task
0.1916,Event,ADDED,eval-sanitize-30-r0-113-4wfk9.18d4ab097981bbd7,reason=Started count=1 msg=Started container task
0.1918,Event,ADDED,eval-sanitize-30-r0-113.18d4ab0955cc3612,reason=SuccessfulCreate count=1 msg=Created pod: eval-sanitize-30-r0-113-4wfk9
0.1919,Event,ADDED,eval-sanitize-30-r0-113.18d4ab0f178633e1,reason=Completed count=1 msg=Job completed
0.1921,Event,ADDED,eval-sanitize-30-r0-114-k5shv.18d4ab0998bf32f4,reason=Scheduled count=None msg=Successfully assigned compute/eval-sanitize-30-r0-114-k5shv to kind-worker
0.1923,Event,ADDED,eval-sanitize-30-r0-114-k5shv.18d4ab09b932cb2b,"reason=Pulled count=1 msg=Container image ""busybox:musl"" already present on machine"
0.1924,Event,ADDED,eval-sanitize-30-r0-114-k5shv.18d4ab09ba820220,reason=Created count=1 msg=Created container: task
0.1926,Event,ADDED,eval-sanitize-30-r0-114-k5shv.18d4ab09bfc9746f,reason=Started count=1 msg=Started container task
0.1928,Event,ADDED,eval-sanitize-30-r0-114.18d4ab0991b28044,reason=SuccessfulCreate count=1 msg=Created pod: eval-sanitize-30-r0-114-k5shv
0.1929,Event,ADDED,eval-sanitize-30-r0-114.18d4ab0f4a582a0d,reason=Completed count=1 msg=Job completed
0.1931,Event,ADDED,eval-sanitize-30-r0-115-544bb.18d4ab09cf56373a,reason=Scheduled count=None msg=Successfully assigned compute/eval-sanitize-30-r0-115-544bb to kind-worker3
0.1932,Event,ADDED,eval-sanitize-30-r0-115-544bb.18d4ab09e9a9b5cd,"reason=Pulled count=1 msg=Container image ""busybox:musl"" already present on machine"
0.1934,Event,ADDED,eval-sanitize-30-r0-115-544bb.18d4ab09eae748c7,reason=Created count=1 msg=Created container: task
0.1936,Event,ADDED,eval-sanitize-30-r0-115-544bb.18d4ab09f1aaa143,reason=Started count=1 msg=Started container task
0.1937,Event,ADDED,eval-sanitize-30-r0-115.18d4ab09cd28ce2b,reason=SuccessfulCreate count=1 msg=Created pod: eval-sanitize-30-r0-115-544bb
0.1939,Event,ADDED,eval-sanitize-30-r0-115.18d4ab0f869e3dbe,reason=Completed count=1 msg=Job completed
0.1941,Event,ADDED,eval-sanitize-30-r0-116-nk7wv.18d4ab0a0b307ea0,reason=Scheduled count=None msg=Successfully assigned compute/eval-sanitize-30-r0-116-nk7wv to kind-worker
0.1942,Event,ADDED,eval-sanitize-30-r0-116-nk7wv.18d4ab0a294471f9,"reason=Pulled count=1 msg=Container image ""busybox:musl"" already present on machine"
0.1944,Event,ADDED,eval-sanitize-30-r0-116-nk7wv.18d4ab0a2adba42c,reason=Created count=1 msg=Created container: task
0.1945,Event,ADDED,eval-sanitize-30-r0-116-nk7wv.18d4ab0a34d6b28f,reason=Started count=1 msg=Started container task
0.1947,Event,ADDED,eval-sanitize-30-r0-116.18d4ab0a08d5dc62,reason=SuccessfulCreate count=1 msg=Created pod: eval-sanitize-30-r0-116-nk7wv
0.1949,Event,ADDED,eval-sanitize-30-r0-116.18d4ab0fb6dbd7cf,reason=Completed count=1 msg=Job completed
0.195,Event,ADDED,eval-sanitize-30-r0-117-d7nvd.18d4ab0a460c77a1,reason=Scheduled count=None msg=Successfully assigned compute/eval-sanitize-30-r0-117-d7nvd to kind-worker
0.1952,Event,ADDED,eval-sanitize-30-r0-117-d7nvd.18d4ab0a640de7f5,"reason=Pulled count=1 msg=Container image ""busybox:musl"" already present on machine"
0.1954,Event,ADDED,eval-sanitize-30-r0-117-d7nvd.18d4ab0a6552d599,reason=Created count=1 msg=Created container: task
0.1955,Event,ADDED,eval-sanitize-30-r0-117-d7nvd.18d4ab0a6da10091,reason=Started count=1 msg=Started container task
0.1957,Event,ADDED,eval-sanitize-30-r0-117.18d4ab0a443bc10f,reason=SuccessfulCreate count=1 msg=Created pod: eval-sanitize-30-r0-117-d7nvd
0.1959,Event,ADDED,eval-sanitize-30-r0-117.18d4ab0ffa169490,reason=Completed count=1 msg=Job completed
0.196,Event,ADDED,eval-sanitize-30-r0-118-bmqpt.18d4ab0a8820ec7f,reason=Scheduled count=None msg=Successfully assigned compute/eval-sanitize-30-r0-118-bmqpt to kind-worker
0.1962,Event,ADDED,eval-sanitize-30-r0-118-bmqpt.18d4ab0aae27c980,"reason=Pulled count=1 msg=Container image ""busybox:musl"" already present on machine"
0.1963,Event,ADDED,eval-sanitize-30-r0-118-bmqpt.18d4ab0aaf94fbc8,reason=Created count=1 msg=Created container: task
0.1965,Event,ADDED,eval-sanitize-30-r0-118-bmqpt.18d4ab0ab3e8975e,reason=Started count=1 msg=Started container task
0.1967,Event,ADDED,eval-sanitize-30-r0-118.18d4ab0a8206cce0,reason=SuccessfulCreate count=1 msg=Created pod: eval-sanitize-30-r0-118-bmqpt
0.1968,Event,ADDED,eval-sanitize-30-r0-118.18d4ab106f8ece80,reason=Completed count=1 msg=Job completed
0.1971,Event,ADDED,eval-sanitize-30-r0-119-rqvc9.18d4ab0ac45bcfe2,reason=Scheduled count=None msg=Successfully assigned compute/eval-sanitize-30-r0-119-rqvc9 to kind-worker5
0.1972,Event,ADDED,eval-sanitize-30-r0-119-rqvc9.18d4ab0ae7309d46,"reason=Pulled count=1 msg=Container image ""busybox:musl"" already present on machine"
0.1991,Event,ADDED,eval-sanitize-30-r0-119-rqvc9.18d4ab0ae92cd6db,reason=Created count=1 msg=Created container: task
0.1992,Event,ADDED,eval-sanitize-30-r0-119-rqvc9.18d4ab0af1e9e2e3,reason=Started count=1 msg=Started container task
0.1994,Event,ADDED,eval-sanitize-30-r0-119.18d4ab0ac1af40e0,reason=SuccessfulCreate count=1 msg=Created pod: eval-sanitize-30-r0-119-rqvc9
0.1996,Event,ADDED,eval-sanitize-30-r0-119.18d4ab107eab4dbe,reason=Completed count=1 msg=Job completed
0.1997,Event,ADDED,eval-sanitize-30-r0-120-5jgj8.18d4ab0afb7d21b6,reason=Scheduled count=None msg=Successfully assigned compute/eval-sanitize-30-r0-120-5jgj8 to kind-worker3
0.1999,Event,ADDED,eval-sanitize-30-r0-120-5jgj8.18d4ab0b1812e921,"reason=Pulled count=1 msg=Container image ""busybox:musl"" already present on machine"
0.2001,Event,ADDED,eval-sanitize-30-r0-120-5jgj8.18d4ab0b1966eabf,reason=Created count=1 msg=Created container: task
0.2002,Event,ADDED,eval-sanitize-30-r0-120-5jgj8.18d4ab0b1dcf0607,reason=Started count=1 msg=Started container task
0.2004,Event,ADDED,eval-sanitize-30-r0-120.18d4ab0af75deefe,reason=SuccessfulCreate count=1 msg=Created pod: eval-sanitize-30-r0-120-5jgj8
0.2006,Event,ADDED,eval-sanitize-30-r0-120.18d4ab10ba5d6595,reason=Completed count=1 msg=Job completed
0.2007,Event,ADDED,eval-sanitize-30-r0-121-g9xk8.18d4ab0b34cb4a62,reason=Scheduled count=None msg=Successfully assigned compute/eval-sanitize-30-r0-121-g9xk8 to kind-worker
0.2009,Event,ADDED,eval-sanitize-30-r0-121-g9xk8.18d4ab0b5cb33873,"reason=Pulled count=1 msg=Container image ""busybox:musl"" already present on machine"
0.2011,Event,ADDED,eval-sanitize-30-r0-121-g9xk8.18d4ab0b5e2c3c92,reason=Created count=1 msg=Created container: task
0.2012,Event,ADDED,eval-sanitize-30-r0-121-g9xk8.18d4ab0b63a2f8bb,reason=Started count=1 msg=Started container task
0.2014,Event,ADDED,eval-sanitize-30-r0-121.18d4ab0b32e0b1e6,reason=SuccessfulCreate count=1 msg=Created pod: eval-sanitize-30-r0-121-g9xk8
0.2016,Event,ADDED,eval-sanitize-30-r0-121.18d4ab10e6488512,reason=Completed count=1 msg=Job completed
0.2017,Event,ADDED,eval-sanitize-30-r0-122-9tv62.18d4ab0b75b404fc,reason=Scheduled count=None msg=Successfully assigned compute/eval-sanitize-30-r0-122-9tv62 to kind-worker2
0.2019,Event,ADDED,eval-sanitize-30-r0-122-9tv62.18d4ab0b955872b5,"reason=Pulled count=1 msg=Container image ""busybox:musl"" already present on machine"
0.202,Event,ADDED,eval-sanitize-30-r0-122-9tv62.18d4ab0b975bc419,reason=Created count=1 msg=Created container: task
0.2022,Event,ADDED,eval-sanitize-30-r0-122-9tv62.18d4ab0ba08ded3b,reason=Started count=1 msg=Started container task
0.2024,Event,ADDED,eval-sanitize-30-r0-122.18d4ab0b6e95654f,reason=SuccessfulCreate count=1 msg=Created pod: eval-sanitize-30-r0-122-9tv62
0.2025,Event,ADDED,eval-sanitize-30-r0-122.18d4ab1125659363,reason=Completed count=1 msg=Job completed
0.2027,Event,ADDED,eval-sanitize-30-r0-123-6vpcz.18d4ab0bb121a10f,reason=Scheduled count=None msg=Successfully assigned compute/eval-sanitize-30-r0-123-6vpcz to kind-worker
0.2029,Event,ADDED,eval-sanitize-30-r0-123-6vpcz.18d4ab0bd9eb05fb,"reason=Pulled count=1 msg=Container image ""busybox:musl"" already present on machine"
0.203,Event,ADDED,eval-sanitize-30-r0-123-6vpcz.18d4ab0bdbeb1b84,reason=Created count=1 msg=Created container: task
0.2032,Event,ADDED,eval-sanitize-30-r0-123-6vpcz.18d4ab0be41d611a,reason=Started count=1 msg=Started container task
0.2034,Event,ADDED,eval-sanitize-30-r0-123.18d4ab0baac467b2,reason=SuccessfulCreate count=1 msg=Created pod: eval-sanitize-30-r0-123-6vpcz
0.2035,Event,ADDED,eval-sanitize-30-r0-123.18d4ab1166ca013f,reason=Completed count=1 msg=Job completed
0.2037,Event,ADDED,eval-sanitize-30-r0-124-b59n8.18d4ab0be7fbfa0e,reason=Scheduled count=None msg=Successfully assigned compute/eval-sanitize-30-r0-124-b59n8 to kind-worker2
0.2038,Event,ADDED,eval-sanitize-30-r0-124-b59n8.18d4ab0c0222b749,"reason=Pulled count=1 msg=Container image ""busybox:musl"" already present on machine"
0.204,Event,ADDED,eval-sanitize-30-r0-124-b59n8.18d4ab0c04339a4b,reason=Created count=1 msg=Created container: task
0.2042,Event,ADDED,eval-sanitize-30-r0-124-b59n8.18d4ab0c0a8f9146,reason=Started count=1 msg=Started container task
0.2043,Event,ADDED,eval-sanitize-30-r0-124.18d4ab0be672bf69,reason=SuccessfulCreate count=1 msg=Created pod: eval-sanitize-30-r0-124-b59n8
0.2045,Event,ADDED,eval-sanitize-30-r0-124.18d4ab11a4f443ba,reason=Completed count=1 msg=Job completed
0.2047,Event,ADDED,eval-sanitize-30-r0-125-7hp54.18d4ab0c2ac71c48,reason=Scheduled count=None msg=Successfully assigned compute/eval-sanitize-30-r0-125-7hp54 to kind-worker3
0.2048,Event,ADDED,eval-sanitize-30-r0-125-7hp54.18d4ab0c49231002,"reason=Pulled count=1 msg=Container image ""busybox:musl"" already present on machine"
0.205,Event,ADDED,eval-sanitize-30-r0-125-7hp54.18d4ab0c4a7d5d32,reason=Created count=1 msg=Created container: task
0.2052,Event,ADDED,eval-sanitize-30-r0-125-7hp54.18d4ab0c539a0b4f,reason=Started count=1 msg=Started container task
0.2053,Event,ADDED,eval-sanitize-30-r0-125.18d4ab0c246cb574,reason=SuccessfulCreate count=1 msg=Created pod: eval-sanitize-30-r0-125-7hp54
0.2055,Event,ADDED,eval-sanitize-30-r0-125.18d4ab11e0fd3bb0,reason=Completed count=1 msg=Job completed
0.2056,Event,ADDED,eval-sanitize-30-r0-126-x4ks9.18d4ab0c976d7c95,reason=Scheduled count=None msg=Successfully assigned compute/eval-sanitize-30-r0-126-x4ks9 to kind-worker3
0.2059,Event,ADDED,eval-sanitize-30-r0-126-x4ks9.18d4ab0cbd53ee5a,"reason=Pulled count=1 msg=Container image ""busybox:musl"" already present on machine"
0.206,Event,ADDED,eval-sanitize-30-r0-126-x4ks9.18d4ab0cbebf6496,reason=Created count=1 msg=Created container: task
0.2062,Event,ADDED,eval-sanitize-30-r0-126-x4ks9.18d4ab0cc7d4c8b4,reason=Started count=1 msg=Started container task
0.2064,Event,ADDED,eval-sanitize-30-r0-126.18d4ab0c8f83c814,reason=SuccessfulCreate count=1 msg=Created pod: eval-sanitize-30-r0-126-x4ks9
0.2065,Event,ADDED,eval-sanitize-30-r0-126.18d4ab124f33e56b,reason=Completed count=1 msg=Job completed
0.2067,Event,ADDED,eval-sanitize-30-r0-127-bdlvs.18d4ab0cd2c165da,reason=Scheduled count=None msg=Successfully assigned compute/eval-sanitize-30-r0-127-bdlvs to kind-worker5
0.2068,Event,ADDED,eval-sanitize-30-r0-127-bdlvs.18d4ab0cf1ac0a78,"reason=Pulled count=1 msg=Container image ""busybox:musl"" already present on machine"
0.207,Event,ADDED,eval-sanitize-30-r0-127-bdlvs.18d4ab0cf34061c6,reason=Created count=1 msg=Created container: task
0.2072,Event,ADDED,eval-sanitize-30-r0-127-bdlvs.18d4ab0cfcb5f156,reason=Started count=1 msg=Started container task
0.2073,Event,ADDED,eval-sanitize-30-r0-127.18d4ab0ccb6d4007,reason=SuccessfulCreate count=1 msg=Created pod: eval-sanitize-30-r0-127-bdlvs
0.2075,Event,ADDED,eval-sanitize-30-r0-127.18d4ab1290be89b6,reason=Completed count=1 msg=Job completed
0.2076,Event,ADDED,eval-sanitize-30-r0-128-c5ldb.18d4ab0d06d054d2,reason=Scheduled count=None msg=Successfully assigned compute/eval-sanitize-30-r0-128-c5ldb to kind-worker2
0.2078,Event,ADDED,eval-sanitize-30-r0-128-c5ldb.18d4ab0d22090d17,"reason=Pulled count=1 msg=Container image ""busybox:musl"" already present on machine"
0.208,Event,ADDED,eval-sanitize-30-r0-128-c5ldb.18d4ab0d23832d05,reason=Created count=1 msg=Created container: task
0.2082,Event,ADDED,eval-sanitize-30-r0-128-c5ldb.18d4ab0d286b6ad7,reason=Started count=1 msg=Started container task
0.2083,Event,ADDED,eval-sanitize-30-r0-128.18d4ab0cfcb3b814,reason=SuccessfulCreate count=1 msg=Created pod: eval-sanitize-30-r0-128-c5ldb
0.2085,Event,ADDED,eval-sanitize-30-r0-128.18d4ab12cc51f217,reason=Completed count=1 msg=Job completed
0.2087,Event,ADDED,eval-sanitize-30-r0-129-p9xml.18d4ab0d3550b431,"reason=FailedScheduling count=None msg=0/6 nodes are available: 1 c_wall violated: 2 conflicting context pair(s) with node memory, 2 c_wall violated: 1 conflicting context pair(s) with node memory, 3 node(s) had untolerated taint(s). no new claims to deallocate, preemption: 0/6 nodes are available: 3 No preemption victims found for incoming pod, 3 Preemption is not helpful for scheduling."
0.2089,Event,ADDED,eval-sanitize-30-r0-129-p9xml.18d4ab0d3a4ddb1f,"reason=FailedScheduling count=None msg=0/6 nodes are available: 1 c_wall violated: 2 conflicting context pair(s) with node memory, 2 c_wall violated: 1 conflicting context pair(s) with node memory, 3 node(s) had untolerated taint(s). no new claims to deallocate, preemption: 0/6 nodes are available: 3 No preemption victims found for incoming pod, 3 Preemption is not helpful for scheduling."
0.2091,Event,ADDED,eval-sanitize-30-r0-129-p9xml.18d4ab0d6acf10ce,"reason=FailedScheduling count=None msg=0/6 nodes are available: 1 c_wall violated: 1 conflicting context pair(s) with node memory, 1 c_wall violated: 2 conflicting context pair(s) with node memory, 4 node(s) had untolerated taint(s). no new claims to deallocate, preemption: 0/6 nodes are available: 2 No preemption victims found for incoming pod, 4 Preemption is not helpful for scheduling."
0.2093,Event,ADDED,eval-sanitize-30-r0-129-p9xml.18d4ab0db199a242,"reason=FailedScheduling count=None msg=0/6 nodes are available: 1 c_wall violated: 1 conflicting context pair(s) with node memory, 5 node(s) had untolerated taint(s). no new claims to deallocate, preemption: 0/6 nodes are available: 1 No preemption victims found for incoming pod, 5 Preemption is not helpful for scheduling."
0.2094,Event,ADDED,eval-sanitize-30-r0-129-p9xml.18d4ab0ddf226032,reason=Scheduled count=None msg=Successfully assigned compute/eval-sanitize-30-r0-129-p9xml to kind-worker4
0.2096,Event,ADDED,eval-sanitize-30-r0-129-p9xml.18d4ab0e0dcb754e,"reason=Pulled count=1 msg=Container image ""busybox:musl"" already present on machine"
0.2098,Event,ADDED,eval-sanitize-30-r0-129-p9xml.18d4ab0e0f64a540,reason=Created count=1 msg=Created container: task
0.21,Event,ADDED,eval-sanitize-30-r0-129-p9xml.18d4ab0e17f27294,reason=Started count=1 msg=Started container task
0.2101,Event,ADDED,eval-sanitize-30-r0-129.18d4ab0d34933427,reason=SuccessfulCreate count=1 msg=Created pod: eval-sanitize-30-r0-129-p9xml
0.2103,Event,ADDED,eval-sanitize-30-r0-129.18d4ab13aa714270,reason=Completed count=1 msg=Job completed
0.2105,Event,ADDED,eval-sanitize-30-r0-130-ppvzx.18d4ab0d5670342c,reason=Scheduled count=None msg=Successfully assigned compute/eval-sanitize-30-r0-130-ppvzx to kind-worker5
0.2106,Event,ADDED,eval-sanitize-30-r0-130-ppvzx.18d4ab0d7a9c24ac,"reason=Pulled count=1 msg=Container image ""busybox:musl"" already present on machine"
0.2108,Event,ADDED,eval-sanitize-30-r0-130-ppvzx.18d4ab0d7d257bd0,reason=Created count=1 msg=Created container: task
0.211,Event,ADDED,eval-sanitize-30-r0-130-ppvzx.18d4ab0d8260713d,reason=Started count=1 msg=Started container task
0.2111,Event,ADDED,eval-sanitize-30-r0-130.18d4ab0d5515d946,reason=SuccessfulCreate count=1 msg=Created pod: eval-sanitize-30-r0-130-ppvzx
0.2113,Event,ADDED,eval-sanitize-30-r0-130.18d4ab1308fb8c1d,reason=Completed count=1 msg=Job completed
0.2114,Event,ADDED,eval-sanitize-30-r0-131-56pcw.18d4ab0d8af15ab5,reason=Scheduled count=None msg=Successfully assigned compute/eval-sanitize-30-r0-131-56pcw to kind-worker
0.2116,Event,ADDED,eval-sanitize-30-r0-131-56pcw.18d4ab0daeb60b32,"reason=Pulled count=1 msg=Container image ""busybox:musl"" already present on machine"
0.2118,Event,ADDED,eval-sanitize-30-r0-131-56pcw.18d4ab0db19ccc67,reason=Created count=1 msg=Created container: task
0.2119,Event,ADDED,eval-sanitize-30-r0-131-56pcw.18d4ab0dbe2e8bdf,reason=Started count=1 msg=Started container task
0.2122,Event,ADDED,eval-sanitize-30-r0-131.18d4ab0d8a03580d,reason=SuccessfulCreate count=1 msg=Created pod: eval-sanitize-30-r0-131-56pcw
0.2124,Event,ADDED,eval-sanitize-30-r0-131.18d4ab12f1b8002c,reason=Completed count=1 msg=Job completed
0.2126,Event,ADDED,eval-sanitize-30-r0-132-5xhtf.18d4ab0dc3dcd7ab,"reason=FailedScheduling count=None msg=0/6 nodes are available: 1 c_wall violated: 2 conflicting context pair(s) with node memory, 5 node(s) had untolerated taint(s). no new claims to deallocate, preemption: 0/6 nodes are available: 1 No preemption victims found for incoming pod, 5 Preemption is not helpful for scheduling."
0.2128,Event,ADDED,eval-sanitize-30-r0-132-5xhtf.18d4ab0dc48ee6f1,"reason=FailedScheduling count=None msg=0/6 nodes are available: 1 c_wall violated: 2 conflicting context pair(s) with node memory, 5 node(s) had untolerated taint(s). no new claims to deallocate, preemption: 0/6 nodes are available: 1 No preemption victims found for incoming pod, 5 Preemption is not helpful for scheduling."
0.213,Event,ADDED,eval-sanitize-30-r0-132-5xhtf.18d4ab0ddf43660b,"reason=FailedScheduling count=None msg=0/6 nodes are available: 1 c_wall violated: 1 conflicting context pair(s) with node memory, 5 node(s) had untolerated taint(s). no new claims to deallocate, preemption: 0/6 nodes are available: 1 No preemption victims found for incoming pod, 5 Preemption is not helpful for scheduling."
0.2132,Event,ADDED,eval-sanitize-30-r0-132-5xhtf.18d4ab0de1dc0d73,"reason=FailedScheduling count=None msg=0/6 nodes are available: 1 c_wall violated: 1 conflicting context pair(s) with node memory, 5 node(s) had untolerated taint(s). no new claims to deallocate, preemption: 0/6 nodes are available: 1 No preemption victims found for incoming pod, 5 Preemption is not helpful for scheduling."
0.2134,Event,ADDED,eval-sanitize-30-r0-132-5xhtf.18d4ab0e097e9d0b,"reason=FailedScheduling count=None msg=0/6 nodes are available: 1 c_wall violated: 2 conflicting context pair(s) with node memory, 5 node(s) had untolerated taint(s). no new claims to deallocate, preemption: 0/6 nodes are available: 1 No preemption victims found for incoming pod, 5 Preemption is not helpful for scheduling."
0.2136,Event,ADDED,eval-sanitize-30-r0-132-5xhtf.18d4ab14437a3f25,reason=Scheduled count=None msg=Successfully assigned compute/eval-sanitize-30-r0-132-5xhtf to kind-worker2
0.2137,Event,ADDED,eval-sanitize-30-r0-132-5xhtf.18d4ab145f7884c7,"reason=Pulled count=1 msg=Container image ""busybox:musl"" already present on machine"
0.2139,Event,ADDED,eval-sanitize-30-r0-132-5xhtf.18d4ab1460e54971,reason=Created count=1 msg=Created container: task
0.2141,Event,ADDED,eval-sanitize-30-r0-132-5xhtf.18d4ab14660ba907,reason=Started count=1 msg=Started container task
0.2142,Event,ADDED,eval-sanitize-30-r0-132.18d4ab0dc331f519,reason=SuccessfulCreate count=1 msg=Created pod: eval-sanitize-30-r0-132-5xhtf
0.2144,Event,ADDED,eval-sanitize-30-r0-132.18d4ab19c3675e89,reason=Completed count=1 msg=Job completed
0.2146,Event,ADDED,eval-sanitize-30-r0-133-5tddm.18d4ab0e0841c6ef,reason=Scheduled count=None msg=Successfully assigned compute/eval-sanitize-30-r0-133-5tddm to kind-worker4
0.2147,Event,ADDED,eval-sanitize-30-r0-133-5tddm.18d4ab0e28676150,"reason=Pulled count=1 msg=Container image ""busybox:musl"" already present on machine"
0.2149,Event,ADDED,eval-sanitize-30-r0-133-5tddm.18d4ab0e29c9db0b,reason=Created count=1 msg=Created container: task
0.2151,Event,ADDED,eval-sanitize-30-r0-133-5tddm.18d4ab0e32b7f9a3,reason=Started count=1 msg=Started container task
0.2152,Event,ADDED,eval-sanitize-30-r0-133.18d4ab0e076cd687,reason=SuccessfulCreate count=1 msg=Created pod: eval-sanitize-30-r0-133-5tddm
0.2154,Event,ADDED,eval-sanitize-30-r0-133.18d4ab1366fdbe54,reason=Completed count=1 msg=Job completed
0.2155,Event,ADDED,eval-sanitize-30-r0-134-2tmsp.18d4ab0e41791a8a,reason=Scheduled count=None msg=Successfully assigned compute/eval-sanitize-30-r0-134-2tmsp to kind-worker4
0.2157,Event,ADDED,eval-sanitize-30-r0-134-2tmsp.18d4ab0e65513213,"reason=Pulled count=1 msg=Container image ""busybox:musl"" already present on machine"
0.2159,Event,ADDED,eval-sanitize-30-r0-134-2tmsp.18d4ab0e66cecdbd,reason=Created count=1 msg=Created container: task
0.216,Event,ADDED,eval-sanitize-30-r0-134-2tmsp.18d4ab0e7188adaa,reason=Started count=1 msg=Started container task
0.2162,Event,ADDED,eval-sanitize-30-r0-134.18d4ab0e40c0e26a,reason=SuccessfulCreate count=1 msg=Created pod: eval-sanitize-30-r0-134-2tmsp
0.2168,Event,ADDED,eval-sanitize-30-r0-134.18d4ab13ea29ad47,reason=Completed count=1 msg=Job completed
0.217,Event,ADDED,eval-sanitize-30-r0-135-79x5k.18d4ab0e7f04d961,reason=Scheduled count=None msg=Successfully assigned compute/eval-sanitize-30-r0-135-79x5k to kind-worker4
0.2172,Event,ADDED,eval-sanitize-30-r0-135-79x5k.18d4ab0e9ece20cf,"reason=Pulled count=1 msg=Container image ""busybox:musl"" already present on machine"
0.2175,Event,ADDED,eval-sanitize-30-r0-135-79x5k.18d4ab0ea03b9694,reason=Created count=1 msg=Created container: task
0.2177,Event,ADDED,eval-sanitize-30-r0-135-79x5k.18d4ab0ea73d2c0a,reason=Started count=1 msg=Started container task
0.2179,Event,ADDED,eval-sanitize-30-r0-135.18d4ab0e7e40dea7,reason=SuccessfulCreate count=1 msg=Created pod: eval-sanitize-30-r0-135-79x5k
0.218,Event,ADDED,eval-sanitize-30-r0-135.18d4ab141aa969df,reason=Completed count=1 msg=Job completed
0.2182,Event,ADDED,eval-sanitize-30-r0-136-6nzts.18d4ab0eb45aa04d,"reason=FailedScheduling count=None msg=0/6 nodes are available: 1 c_wall violated: 2 conflicting context pair(s) with node memory, 5 node(s) had untolerated taint(s). no new claims to deallocate, preemption: 0/6 nodes are available: 1 No preemption victims found for incoming pod, 5 Preemption is not helpful for scheduling."
0.2184,Event,ADDED,eval-sanitize-30-r0-136-6nzts.18d4ab0eb51e067e,"reason=FailedScheduling count=None msg=0/6 nodes are available: 1 c_wall violated: 2 conflicting context pair(s) with node memory, 5 node(s) had untolerated taint(s). no new claims to deallocate, preemption: 0/6 nodes are available: 1 No preemption victims found for incoming pod, 5 Preemption is not helpful for scheduling."
0.2186,Event,ADDED,eval-sanitize-30-r0-136-6nzts.18d4ab146ce59a29,"reason=FailedScheduling count=None msg=0/6 nodes are available: 1 c_wall violated: 1 conflicting context pair(s) with node memory, 1 c_wall violated: 2 conflicting context pair(s) with node memory, 4 node(s) had untolerated taint(s). no new claims to deallocate, preemption: 0/6 nodes are available: 2 No preemption victims found for incoming pod, 4 Preemption is not helpful for scheduling."
0.219,Event,ADDED,eval-sanitize-30-r0-136-6nzts.18d4ab14cc07c979,"reason=FailedScheduling count=None msg=0/6 nodes are available: 1 c_wall violated: 1 conflicting context pair(s) with node memory, 2 c_wall violated: 2 conflicting context pair(s) with node memory, 3 node(s) had untolerated taint(s). no new claims to deallocate, preemption: 0/6 nodes are available: 3 No preemption victims found for incoming pod, 3 Preemption is not helpful for scheduling."
0.2192,Event,ADDED,eval-sanitize-30-r0-136-6nzts.18d4ab14fb29590e,reason=Scheduled count=None msg=Successfully assigned compute/eval-sanitize-30-r0-136-6nzts to kind-worker
0.2193,Event,ADDED,eval-sanitize-30-r0-136-6nzts.18d4ab151a84c1ed,"reason=Pulled count=1 msg=Container image ""busybox:musl"" already present on machine"
0.2196,Event,ADDED,eval-sanitize-30-r0-136-6nzts.18d4ab151c1471ac,reason=Created count=1 msg=Created container: task
0.2197,Event,ADDED,eval-sanitize-30-r0-136-6nzts.18d4ab1521e47280,reason=Started count=1 msg=Started container task
0.2199,Event,ADDED,eval-sanitize-30-r0-136.18d4ab0eb409b53c,reason=SuccessfulCreate count=1 msg=Created pod: eval-sanitize-30-r0-136-6nzts
0.2201,Event,ADDED,eval-sanitize-30-r0-136.18d4ab1b747076f7,reason=Completed count=1 msg=Job completed
0.2202,Event,ADDED,eval-sanitize-30-r0-137-mw7lp.18d4ab0ef314dd1e,"reason=FailedScheduling count=None msg=0/6 nodes are available: 1 c_wall violated: 2 conflicting context pair(s) with node memory, 5 node(s) had untolerated taint(s). no new claims to deallocate, preemption: 0/6 nodes are available: 1 No preemption victims found for incoming pod, 5 Preemption is not helpful for scheduling."
0.2204,Event,ADDED,eval-sanitize-30-r0-137-mw7lp.18d4ab0ef3fb3ecb,"reason=FailedScheduling count=None msg=0/6 nodes are available: 1 c_wall violated: 2 conflicting context pair(s) with node memory, 5 node(s) had untolerated taint(s). no new claims to deallocate, preemption: 0/6 nodes are available: 1 No preemption victims found for incoming pod, 5 Preemption is not helpful for scheduling."
0.2206,Event,ADDED,eval-sanitize-30-r0-137-mw7lp.18d4ab1472cc6b84,"reason=FailedScheduling count=None msg=0/6 nodes are available: 2 c_wall violated: 2 conflicting context pair(s) with node memory, 4 node(s) had untolerated taint(s). no new claims to deallocate, preemption: 0/6 nodes are available: 2 No preemption victims found for incoming pod, 4 Preemption is not helpful for scheduling."
0.2208,Event,ADDED,eval-sanitize-30-r0-137-mw7lp.18d4ab14d8fb679f,reason=Scheduled count=None msg=Successfully assigned compute/eval-sanitize-30-r0-137-mw7lp to kind-worker
0.2209,Event,ADDED,eval-sanitize-30-r0-137-mw7lp.18d4ab14f479e0bb,"reason=Pulled count=1 msg=Container image ""busybox:musl"" already present on machine"
0.2211,Event,ADDED,eval-sanitize-30-r0-137-mw7lp.18d4ab14f640d8ac,reason=Created count=1 msg=Created container: task
0.2213,Event,ADDED,eval-sanitize-30-r0-137-mw7lp.18d4ab14fb9aa4b1,reason=Started count=1 msg=Started container task
0.2214,Event,ADDED,eval-sanitize-30-r0-137.18d4ab0ef2c202e7,reason=SuccessfulCreate count=1 msg=Created pod: eval-sanitize-30-r0-137-mw7lp
0.2216,Event,ADDED,eval-sanitize-30-r0-137.18d4ab1a6bd4b052,reason=Completed count=1 msg=Job completed
0.2217,Event,ADDED,eval-sanitize-30-r0-138-5dsbw.18d4ab0f29e49267,"reason=FailedScheduling count=None msg=0/6 nodes are available: 1 c_wall violated: 2 conflicting context pair(s) with node memory, 5 node(s) had untolerated taint(s). no new claims to deallocate, preemption: 0/6 nodes are available: 1 No preemption victims found for incoming pod, 5 Preemption is not helpful for scheduling."
0.2219,Event,ADDED,eval-sanitize-30-r0-138-5dsbw.18d4ab0f2aa776f8,"reason=FailedScheduling count=None msg=0/6 nodes are available: 1 c_wall violated: 2 conflicting context pair(s) with node memory, 5 node(s) had untolerated taint(s). no new claims to deallocate, preemption: 0/6 nodes are available: 1 No preemption victims found for incoming pod, 5 Preemption is not helpful for scheduling."
0.2221,Event,ADDED,eval-sanitize-30-r0-138-5dsbw.18d4ab14200c7416,reason=Scheduled count=None msg=Successfully assigned compute/eval-sanitize-30-r0-138-5dsbw to kind-worker2
0.2222,Event,ADDED,eval-sanitize-30-r0-138-5dsbw.18d4ab143be54c51,"reason=Pulled count=1 msg=Container image ""busybox:musl"" already present on machine"
0.2224,Event,ADDED,eval-sanitize-30-r0-138-5dsbw.18d4ab143e17b72e,reason=Created count=1 msg=Created container: task
0.2226,Event,ADDED,eval-sanitize-30-r0-138-5dsbw.18d4ab1442efbf58,reason=Started count=1 msg=Started container task
0.2227,Event,ADDED,eval-sanitize-30-r0-138.18d4ab0f29910a1b,reason=SuccessfulCreate count=1 msg=Created pod: eval-sanitize-30-r0-138-5dsbw
0.2229,Event,ADDED,eval-sanitize-30-r0-138.18d4ab19c099f913,reason=Completed count=1 msg=Job completed
0.2231,Event,ADDED,eval-sanitize-30-r0-139-6vj9v.18d4ab0f7008ebbc,"reason=FailedScheduling count=None msg=0/6 nodes are available: 1 c_wall violated: 2 conflicting context pair(s) with node memory, 5 node(s) had untolerated taint(s). no new claims to deallocate, preemption: 0/6 nodes are available: 1 No preemption victims found for incoming pod, 5 Preemption is not helpful for scheduling."
0.2232,Event,ADDED,eval-sanitize-30-r0-139-6vj9v.18d4ab0f70b720cc,"reason=FailedScheduling count=None msg=0/6 nodes are available: 1 c_wall violated: 2 conflicting context pair(s) with node memory, 5 node(s) had untolerated taint(s). no new claims to deallocate, preemption: 0/6 nodes are available: 1 No preemption victims found for incoming pod, 5 Preemption is not helpful for scheduling."
0.2235,Event,ADDED,eval-sanitize-30-r0-139-6vj9v.18d4ab1454d5f9f5,"reason=FailedScheduling count=None msg=0/6 nodes are available: 2 c_wall violated: 2 conflicting context pair(s) with node memory, 4 node(s) had untolerated taint(s). no new claims to deallocate, preemption: 0/6 nodes are available: 2 No preemption victims found for incoming pod, 4 Preemption is not helpful for scheduling."
0.2236,Event,ADDED,eval-sanitize-30-r0-139-6vj9v.18d4ab14777d0007,"reason=FailedScheduling count=None msg=0/6 nodes are available: 2 c_wall violated: 2 conflicting context pair(s) with node memory, 4 node(s) had untolerated taint(s). no new claims to deallocate, preemption: 0/6 nodes are available: 2 No preemption victims found for incoming pod, 4 Preemption is not helpful for scheduling."
0.2238,Event,ADDED,eval-sanitize-30-r0-139-6vj9v.18d4ab149bd45f92,reason=Scheduled count=None msg=Successfully assigned compute/eval-sanitize-30-r0-139-6vj9v to kind-worker5
0.2239,Event,ADDED,eval-sanitize-30-r0-139-6vj9v.18d4ab14b8797045,"reason=Pulled count=1 msg=Container image ""busybox:musl"" already present on machine"
0.2241,Event,ADDED,eval-sanitize-30-r0-139-6vj9v.18d4ab14ba2f85a8,reason=Created count=1 msg=Created container: task
0.2243,Event,ADDED,eval-sanitize-30-r0-139-6vj9v.18d4ab14bf82b011,reason=Started count=1 msg=Started container task
0.2244,Event,ADDED,eval-sanitize-30-r0-139.18d4ab0f6f9da576,reason=SuccessfulCreate count=1 msg=Created pod: eval-sanitize-30-r0-139-6vj9v
0.2246,Event,ADDED,eval-sanitize-30-r0-139.18d4ab1acab4ac58,reason=Completed count=1 msg=Job completed
0.2249,Event,ADDED,eval-sanitize-30-r0-140-pd8rt.18d4ab0fa5c91bcf,reason=Scheduled count=None msg=Successfully assigned compute/eval-sanitize-30-r0-140-pd8rt to kind-worker4
0.225,Event,ADDED,eval-sanitize-30-r0-140-pd8rt.18d4ab0fc038ebd3,"reason=Pulled count=1 msg=Container image ""busybox:musl"" already present on machine"
0.2252,Event,ADDED,eval-sanitize-30-r0-140-pd8rt.18d4ab0fc19b533c,reason=Created count=1 msg=Created container: task
0.2254,Event,ADDED,eval-sanitize-30-r0-140-pd8rt.18d4ab0fcb392c76,reason=Started count=1 msg=Started container task
0.2256,Event,ADDED,eval-sanitize-30-r0-140.18d4ab0fa5107086,reason=SuccessfulCreate count=1 msg=Created pod: eval-sanitize-30-r0-140-pd8rt
0.2258,Event,ADDED,eval-sanitize-30-r0-140.18d4ab15438020fe,reason=Completed count=1 msg=Job completed
0.2259,Event,ADDED,eval-sanitize-30-r0-141-d9lw8.18d4ab0fdb39ce9b,"reason=FailedScheduling count=None msg=0/6 nodes are available: 1 c_wall violated: 1 conflicting context pair(s) with node memory, 5 node(s) had untolerated taint(s). no new claims to deallocate, preemption: 0/6 nodes are available: 1 No preemption victims found for incoming pod, 5 Preemption is not helpful for scheduling."
0.2261,Event,ADDED,eval-sanitize-30-r0-141-d9lw8.18d4ab0fdc0f9a1d,"reason=FailedScheduling count=None msg=0/6 nodes are available: 1 c_wall violated: 1 conflicting context pair(s) with node memory, 5 node(s) had untolerated taint(s). no new claims to deallocate, preemption: 0/6 nodes are available: 1 No preemption victims found for incoming pod, 5 Preemption is not helpful for scheduling."
0.2263,Event,ADDED,eval-sanitize-30-r0-141-d9lw8.18d4ab1460c52aa0,"reason=FailedScheduling count=None msg=0/6 nodes are available: 2 c_wall violated: 1 conflicting context pair(s) with node memory, 4 node(s) had untolerated taint(s). no new claims to deallocate, preemption: 0/6 nodes are available: 2 No preemption victims found for incoming pod, 4 Preemption is not helpful for scheduling."
0.2264,Event,ADDED,eval-sanitize-30-r0-141-d9lw8.18d4ab14ae7ec42f,"reason=FailedScheduling count=None msg=0/6 nodes are available: 1 c_wall violated: 2 conflicting context pair(s) with node memory, 2 c_wall violated: 1 conflicting context pair(s) with node memory, 3 node(s) had untolerated taint(s). no new claims to deallocate, preemption: 0/6 nodes are available: 3 No preemption victims found for incoming pod, 3 Preemption is not helpful for scheduling."
0.2266,Event,ADDED,eval-sanitize-30-r0-141-d9lw8.18d4ab14e464bf34,reason=Scheduled count=None msg=Successfully assigned compute/eval-sanitize-30-r0-141-d9lw8 to kind-worker
0.2268,Event,ADDED,eval-sanitize-30-r0-141-d9lw8.18d4ab15017c2633,"reason=Pulled count=1 msg=Container image ""busybox:musl"" already present on machine"
0.2269,Event,ADDED,eval-sanitize-30-r0-141-d9lw8.18d4ab150341bdad,reason=Created count=1 msg=Created container: task
0.2271,Event,ADDED,eval-sanitize-30-r0-141-d9lw8.18d4ab150b8890da,reason=Started count=1 msg=Started container task
0.2273,Event,ADDED,eval-sanitize-30-r0-141.18d4ab0fdaddaa3f,reason=SuccessfulCreate count=1 msg=Created pod: eval-sanitize-30-r0-141-d9lw8
0.2274,Event,ADDED,eval-sanitize-30-r0-141.18d4ab1b3e8c964b,reason=Completed count=1 msg=Job completed
0.2276,Event,ADDED,eval-sanitize-30-r0-142-59jh2.18d4ab1016c253e4,"reason=FailedScheduling count=None msg=0/6 nodes are available: 1 c_wall violated: 1 conflicting context pair(s) with node memory, 5 node(s) had untolerated taint(s). no new claims to deallocate, preemption: 0/6 nodes are available: 1 No preemption victims found for incoming pod, 5 Preemption is not helpful for scheduling."
0.2278,Event,ADDED,eval-sanitize-30-r0-142-59jh2.18d4ab1017b83d23,"reason=FailedScheduling count=None msg=0/6 nodes are available: 1 c_wall violated: 1 conflicting context pair(s) with node memory, 5 node(s) had untolerated taint(s). no new claims to deallocate, preemption: 0/6 nodes are available: 1 No preemption victims found for incoming pod, 5 Preemption is not helpful for scheduling."
0.228,Event,ADDED,eval-sanitize-30-r0-142-59jh2.18d4ab14659cb4f6,"reason=FailedScheduling count=None msg=0/6 nodes are available: 2 c_wall violated: 1 conflicting context pair(s) with node memory, 4 node(s) had untolerated taint(s). no new claims to deallocate, preemption: 0/6 nodes are available: 2 No preemption victims found for incoming pod, 4 Preemption is not helpful for scheduling."
0.2281,Event,ADDED,eval-sanitize-30-r0-142-59jh2.18d4ab14b4707b24,"reason=FailedScheduling count=None msg=0/6 nodes are available: 1 c_wall violated: 2 conflicting context pair(s) with node memory, 2 c_wall violated: 1 conflicting context pair(s) with node memory, 3 node(s) had untolerated taint(s). no new claims to deallocate, preemption: 0/6 nodes are available: 3 No preemption victims found for incoming pod, 3 Preemption is not helpful for scheduling."
0.2283,Event,ADDED,eval-sanitize-30-r0-142-59jh2.18d4ab14ebdfc7ab,reason=Scheduled count=None msg=Successfully assigned compute/eval-sanitize-30-r0-142-59jh2 to kind-worker
0.2285,Event,ADDED,eval-sanitize-30-r0-142-59jh2.18d4ab1508e2d861,"reason=Pulled count=1 msg=Container image ""busybox:musl"" already present on machine"
0.2287,Event,ADDED,eval-sanitize-30-r0-142-59jh2.18d4ab150ab20eb3,reason=Created count=1 msg=Created container: task
0.2288,Event,ADDED,eval-sanitize-30-r0-142-59jh2.18d4ab1511b85b55,reason=Started count=1 msg=Started container task
0.229,Event,ADDED,eval-sanitize-30-r0-142.18d4ab1016662f5a,reason=SuccessfulCreate count=1 msg=Created pod: eval-sanitize-30-r0-142-59jh2
0.2292,Event,ADDED,eval-sanitize-30-r0-142.18d4ab1b4ae67a8a,reason=Completed count=1 msg=Job completed
0.2293,Event,ADDED,eval-sanitize-30-r0-143-zb9rl.18d4ab1059dcb751,"reason=FailedScheduling count=None msg=0/6 nodes are available: 1 c_wall violated: 2 conflicting context pair(s) with node memory, 5 node(s) had untolerated taint(s). no new claims to deallocate, preemption: 0/6 nodes are available: 1 No preemption victims found for incoming pod, 5 Preemption is not helpful for scheduling."
0.2295,Event,ADDED,eval-sanitize-30-r0-143-zb9rl.18d4ab105a9fe892,"reason=FailedScheduling count=None msg=0/6 nodes are available: 1 c_wall violated: 2 conflicting context pair(s) with node memory, 5 node(s) had untolerated taint(s). no new claims to deallocate, preemption: 0/6 nodes are available: 1 No preemption victims found for incoming pod, 5 Preemption is not helpful for scheduling."
0.2296,Event,ADDED,eval-sanitize-30-r0-143-zb9rl.18d4ab1437fe5139,reason=Scheduled count=None msg=Successfully assigned compute/eval-sanitize-30-r0-143-zb9rl to kind-worker2
0.2298,Event,ADDED,eval-sanitize-30-r0-143-zb9rl.18d4ab14573895c9,"reason=Pulled count=1 msg=Container image ""busybox:musl"" already present on machine"
0.23,Event,ADDED,eval-sanitize-30-r0-143-zb9rl.18d4ab14596748a8,reason=Created count=1 msg=Created container: task
0.2301,Event,ADDED,eval-sanitize-30-r0-143-zb9rl.18d4ab145e303699,reason=Started count=1 msg=Started container task
0.2303,Event,ADDED,eval-sanitize-30-r0-143.18d4ab10597005cb,reason=SuccessfulCreate count=1 msg=Created pod: eval-sanitize-30-r0-143-zb9rl
0.2305,Event,ADDED,eval-sanitize-30-r0-143.18d4ab19c34faf96,reason=Completed count=1 msg=Job completed
0.2306,Event,ADDED,eval-sanitize-30-r0-144-mgn96.18d4ab109248753e,"reason=FailedScheduling count=None msg=0/6 nodes are available: 1 c_wall violated: 1 conflicting context pair(s) with node memory, 5 node(s) had untolerated taint(s). no new claims to deallocate, preemption: 0/6 nodes are available: 1 No preemption victims found for incoming pod, 5 Preemption is not helpful for scheduling."
0.2308,Event,ADDED,eval-sanitize-30-r0-144-mgn96.18d4ab1092f37901,"reason=FailedScheduling count=None msg=0/6 nodes are available: 1 c_wall violated: 1 conflicting context pair(s) with node memory, 5 node(s) had untolerated taint(s). no new claims to deallocate, preemption: 0/6 nodes are available: 1 No preemption victims found for incoming pod, 5 Preemption is not helpful for scheduling."
0.231,Event,ADDED,eval-sanitize-30-r0-144-mgn96.18d4ab143c95790f,reason=Scheduled count=None msg=Successfully assigned compute/eval-sanitize-30-r0-144-mgn96 to kind-worker2
0.2312,Event,ADDED,eval-sanitize-30-r0-144-mgn96.18d4ab1458861d1e,"reason=Pulled count=1 msg=Container image ""busybox:musl"" already present on machine"
0.2314,Event,ADDED,eval-sanitize-30-r0-144-mgn96.18d4ab145b26f30b,reason=Created count=1 msg=Created container: task
0.2315,Event,ADDED,eval-sanitize-30-r0-144-mgn96.18d4ab145ea6cb36,reason=Started count=1 msg=Started container task
0.2317,Event,ADDED,eval-sanitize-30-r0-144.18d4ab1091edf080,reason=SuccessfulCreate count=1 msg=Created pod: eval-sanitize-30-r0-144-mgn96
0.2319,Event,ADDED,eval-sanitize-30-r0-144.18d4ab19c1b5dbf9,reason=Completed count=1 msg=Job completed
0.232,Event,ADDED,eval-sanitize-30-r0-145-ct7jg.18d4ab10cf1b5730,"reason=FailedScheduling count=None msg=0/6 nodes are available: 1 c_wall violated: 1 conflicting context pair(s) with node memory, 5 node(s) had untolerated taint(s). no new claims to deallocate, preemption: 0/6 nodes are available: 1 No preemption victims found for incoming pod, 5 Preemption is not helpful for scheduling."
0.2322,Event,ADDED,eval-sanitize-30-r0-145-ct7jg.18d4ab10cfef9d29,"reason=FailedScheduling count=None msg=0/6 nodes are available: 1 c_wall violated: 1 conflicting context pair(s) with node memory, 5 node(s) had untolerated taint(s). no new claims to deallocate, preemption: 0/6 nodes are available: 1 No preemption victims found for incoming pod, 5 Preemption is not helpful for scheduling."
0.2324,Event,ADDED,eval-sanitize-30-r0-145-ct7jg.18d4ab1466b6eb54,"reason=FailedScheduling count=None msg=0/6 nodes are available: 2 c_wall violated: 1 conflicting context pair(s) with node memory, 4 node(s) had untolerated taint(s). no new claims to deallocate, preemption: 0/6 nodes are available: 2 No preemption victims found for incoming pod, 4 Preemption is not helpful for scheduling."
0.2325,Event,ADDED,eval-sanitize-30-r0-145-ct7jg.18d4ab14ba52d6a6,"reason=FailedScheduling count=None msg=0/6 nodes are available: 1 c_wall violated: 2 conflicting context pair(s) with node memory, 2 c_wall violated: 1 conflicting context pair(s) with node memory, 3 node(s) had untolerated taint(s). no new claims to deallocate, preemption: 0/6 nodes are available: 3 No preemption victims found for incoming pod, 3 Preemption is not helpful for scheduling."
0.2327,Event,ADDED,eval-sanitize-30-r0-145-ct7jg.18d4ab14f25ec8fd,reason=Scheduled count=None msg=Successfully assigned compute/eval-sanitize-30-r0-145-ct7jg to kind-worker
0.2329,Event,ADDED,eval-sanitize-30-r0-145-ct7jg.18d4ab1511b921f2,"reason=Pulled count=1 msg=Container image ""busybox:musl"" already present on machine"
0.233,Event,ADDED,eval-sanitize-30-r0-145-ct7jg.18d4ab1513e9994d,reason=Created count=1 msg=Created container: task
0.2332,Event,ADDED,eval-sanitize-30-r0-145-ct7jg.18d4ab15190374fe,reason=Started count=1 msg=Started container task
0.2334,Event,ADDED,eval-sanitize-30-r0-145.18d4ab10cec023c5,reason=SuccessfulCreate count=1 msg=Created pod: eval-sanitize-30-r0-145-ct7jg
0.2335,Event,ADDED,eval-sanitize-30-r0-145.18d4ab1b5093e1fe,reason=Completed count=1 msg=Job completed
0.2337,Event,ADDED,eval-sanitize-30-r0-146-sq2cb.18d4ab11053294a8,"reason=FailedScheduling count=None msg=0/6 nodes are available: 1 c_wall violated: 1 conflicting context pair(s) with node memory, 5 node(s) had untolerated taint(s). no new claims to deallocate, preemption: 0/6 nodes are available: 1 No preemption victims found for incoming pod, 5 Preemption is not helpful for scheduling."
0.2339,Event,ADDED,eval-sanitize-30-r0-146-sq2cb.18d4ab1105e96df5,"reason=FailedScheduling count=None msg=0/6 nodes are available: 1 c_wall violated: 1 conflicting context pair(s) with node memory, 5 node(s) had untolerated taint(s). no new claims to deallocate, preemption: 0/6 nodes are available: 1 No preemption victims found for incoming pod, 5 Preemption is not helpful for scheduling."
0.234,Event,ADDED,eval-sanitize-30-r0-146-sq2cb.18d4ab144ef73819,reason=Scheduled count=None msg=Successfully assigned compute/eval-sanitize-30-r0-146-sq2cb to kind-worker2
0.2342,Event,ADDED,eval-sanitize-30-r0-146-sq2cb.18d4ab146baeacab,"reason=Pulled count=1 msg=Container image ""busybox:musl"" already present on machine"
0.2343,Event,ADDED,eval-sanitize-30-r0-146-sq2cb.18d4ab146d0b4897,reason=Created count=1 msg=Created container: task
0.2345,Event,ADDED,eval-sanitize-30-r0-146-sq2cb.18d4ab147431fd7d,reason=Started count=1 msg=Started container task
0.2347,Event,ADDED,eval-sanitize-30-r0-146.18d4ab1104e3f44c,reason=SuccessfulCreate count=1 msg=Created pod: eval-sanitize-30-r0-146-sq2cb
0.2348,Event,ADDED,eval-sanitize-30-r0-146.18d4ab19fbc0d822,reason=Completed count=1 msg=Job completed
0.235,Event,ADDED,eval-sanitize-30-r0-147-2pz92.18d4ab1144dfa010,"reason=FailedScheduling count=None msg=0/6 nodes are available: 1 c_wall violated: 2 conflicting context pair(s) with node memory, 5 node(s) had untolerated taint(s). no new claims to deallocate, preemption: 0/6 nodes are available: 1 No preemption victims found for incoming pod, 5 Preemption is not helpful for scheduling."
0.2352,Event,ADDED,eval-sanitize-30-r0-147-2pz92.18d4ab11457991f6,"reason=FailedScheduling count=None msg=0/6 nodes are available: 1 c_wall violated: 2 conflicting context pair(s) with node memory, 5 node(s) had untolerated taint(s). no new claims to deallocate, preemption: 0/6 nodes are available: 1 No preemption victims found for incoming pod, 5 Preemption is not helpful for scheduling."
0.2353,Event,ADDED,eval-sanitize-30-r0-147-2pz92.18d4ab142aaf82e7,reason=Scheduled count=None msg=Successfully assigned compute/eval-sanitize-30-r0-147-2pz92 to kind-worker2
0.2355,Event,ADDED,eval-sanitize-30-r0-147-2pz92.18d4ab144889e2a2,"reason=Pulled count=1 msg=Container image ""busybox:musl"" already present on machine"
0.2356,Event,ADDED,eval-sanitize-30-r0-147-2pz92.18d4ab1449edcf96,reason=Created count=1 msg=Created container: task
0.2358,Event,ADDED,eval-sanitize-30-r0-147-2pz92.18d4ab145039fda7,reason=Started count=1 msg=Started container task
0.236,Event,ADDED,eval-sanitize-30-r0-147.18d4ab1144837b0c,reason=SuccessfulCreate count=1 msg=Created pod: eval-sanitize-30-r0-147-2pz92
0.2361,Event,ADDED,eval-sanitize-30-r0-147.18d4ab19c094a117,reason=Completed count=1 msg=Job completed
0.2363,Event,ADDED,eval-sanitize-30-r0-148-rfzf2.18d4ab1181e96082,"reason=FailedScheduling count=None msg=0/6 nodes are available: 1 c_wall violated: 1 conflicting context pair(s) with node memory, 5 node(s) had untolerated taint(s). no new claims to deallocate, preemption: 0/6 nodes are available: 1 No preemption victims found for incoming pod, 5 Preemption is not helpful for scheduling."
0.2365,Event,ADDED,eval-sanitize-30-r0-148-rfzf2.18d4ab1182a21885,"reason=FailedScheduling count=None msg=0/6 nodes are available: 1 c_wall violated: 1 conflicting context pair(s) with node memory, 5 node(s) had untolerated taint(s). no new claims to deallocate, preemption: 0/6 nodes are available: 1 No preemption victims found for incoming pod, 5 Preemption is not helpful for scheduling."
0.2367,Event,ADDED,eval-sanitize-30-r0-148-rfzf2.18d4ab145afd6649,"reason=FailedScheduling count=None msg=0/6 nodes are available: 2 c_wall violated: 1 conflicting context pair(s) with node memory, 4 node(s) had untolerated taint(s). no new claims to deallocate, preemption: 0/6 nodes are available: 2 No preemption victims found for incoming pod, 4 Preemption is not helpful for scheduling."
0.2368,Event,ADDED,eval-sanitize-30-r0-148-rfzf2.18d4ab14de17c7d1,reason=Scheduled count=None msg=Successfully assigned compute/eval-sanitize-30-r0-148-rfzf2 to kind-worker
0.237,Event,ADDED,eval-sanitize-30-r0-148-rfzf2.18d4ab14fb62af98,"reason=Pulled count=1 msg=Container image ""busybox:musl"" already present on machine"
0.2372,Event,ADDED,eval-sanitize-30-r0-148-rfzf2.18d4ab14fcf39e9d,reason=Created count=1 msg=Created container: task
0.2373,Event,ADDED,eval-sanitize-30-r0-148-rfzf2.18d4ab1502058037,reason=Started count=1 msg=Started container task
0.2376,Event,ADDED,eval-sanitize-30-r0-148.18d4ab11817bc8e6,reason=SuccessfulCreate count=1 msg=Created pod: eval-sanitize-30-r0-148-rfzf2
0.2377,Event,ADDED,eval-sanitize-30-r0-148.18d4ab1ad9ca222d,reason=Completed count=1 msg=Job completed
0.2379,Event,ADDED,eval-sanitize-30-r0-149-b87nv.18d4ab11b85b88ae,"reason=FailedScheduling count=None msg=0/6 nodes are available: 1 c_wall violated: 2 conflicting context pair(s) with node memory, 5 node(s) had untolerated taint(s). no new claims to deallocate, preemption: 0/6 nodes are available: 1 No preemption victims found for incoming pod, 5 Preemption is not helpful for scheduling."
0.2381,Event,ADDED,eval-sanitize-30-r0-149-b87nv.18d4ab11b91caf26,"reason=FailedScheduling count=None msg=0/6 nodes are available: 1 c_wall violated: 2 conflicting context pair(s) with node memory, 5 node(s) had untolerated taint(s). no new claims to deallocate, preemption: 0/6 nodes are available: 1 No preemption victims found for incoming pod, 5 Preemption is not helpful for scheduling."
0.2383,Event,ADDED,eval-sanitize-30-r0-149-b87nv.18d4ab145fb21e13,"reason=FailedScheduling count=None msg=0/6 nodes are available: 2 c_wall violated: 2 conflicting context pair(s) with node memory, 4 node(s) had untolerated taint(s). no new claims to deallocate, preemption: 0/6 nodes are available: 2 No preemption victims found for incoming pod, 4 Preemption is not helpful for scheduling."
0.2384,Event,ADDED,eval-sanitize-30-r0-149-b87nv.18d4ab147e83ba34,"reason=FailedScheduling count=None msg=0/6 nodes are available: 2 c_wall violated: 2 conflicting context pair(s) with node memory, 4 node(s) had untolerated taint(s). no new claims to deallocate, preemption: 0/6 nodes are available: 2 No preemption victims found for incoming pod, 4 Preemption is not helpful for scheduling."
0.2386,Event,ADDED,eval-sanitize-30-r0-149-b87nv.18d4ab14a91c7be9,reason=Scheduled count=None msg=Successfully assigned compute/eval-sanitize-30-r0-149-b87nv to kind-worker5
0.2388,Event,ADDED,eval-sanitize-30-r0-149-b87nv.18d4ab14c4325710,"reason=Pulled count=1 msg=Container image ""busybox:musl"" already present on machine"
0.2389,Event,ADDED,eval-sanitize-30-r0-149-b87nv.18d4ab14c5ca1c80,reason=Created count=1 msg=Created container: task
0.2391,Event,ADDED,eval-sanitize-30-r0-149-b87nv.18d4ab14d117f0f1,reason=Started count=1 msg=Started container task
0.2393,Event,ADDED,eval-sanitize-30-r0-149.18d4ab11b80341eb,reason=SuccessfulCreate count=1 msg=Created pod: eval-sanitize-30-r0-149-b87nv
0.2394,Event,ADDED,eval-sanitize-30-r0-149.18d4ab1ac790ef62,reason=Completed count=1 msg=Job completed
0.2396,Event,ADDED,eval-sanitize-30-r0-150-thbzl.18d4ab11f83843fb,reason=Scheduled count=None msg=Successfully assigned compute/eval-sanitize-30-r0-150-thbzl to kind-worker4
0.2397,Event,ADDED,eval-sanitize-30-r0-150-thbzl.18d4ab1214c4ba46,"reason=Pulled count=1 msg=Container image ""busybox:musl"" already present on machine"
0.2399,Event,ADDED,eval-sanitize-30-r0-150-thbzl.18d4ab12160056d0,reason=Created count=1 msg=Created container: task
0.2401,Event,ADDED,eval-sanitize-30-r0-150-thbzl.18d4ab121eda4315,reason=Started count=1 msg=Started container task
0.2402,Event,ADDED,eval-sanitize-30-r0-150.18d4ab11f7769959,reason=SuccessfulCreate count=1 msg=Created pod: eval-sanitize-30-r0-150-thbzl
0.2404,Event,ADDED,eval-sanitize-30-r0-150.18d4ab17967f8363,reason=Completed count=1 msg=Job completed
0.2406,Event,ADDED,eval-sanitize-30-r0-151-jbkvt.18d4ab1230c46fb6,"reason=FailedScheduling count=None msg=0/6 nodes are available: 1 c_wall violated: 1 conflicting context pair(s) with node memory, 5 node(s) had untolerated taint(s). no new claims to deallocate, preemption: 0/6 nodes are available: 1 No preemption victims found for incoming pod, 5 Preemption is not helpful for scheduling."
0.2407,Event,ADDED,eval-sanitize-30-r0-151-jbkvt.18d4ab1236d9203c,"reason=FailedScheduling count=None msg=0/6 nodes are available: 1 c_wall violated: 1 conflicting context pair(s) with node memory, 5 node(s) had untolerated taint(s). no new claims to deallocate, preemption: 0/6 nodes are available: 1 No preemption victims found for incoming pod, 5 Preemption is not helpful for scheduling."
0.2409,Event,ADDED,eval-sanitize-30-r0-151-jbkvt.18d4ab1459c93b32,"reason=FailedScheduling count=None msg=0/6 nodes are available: 1 c_wall violated: 1 conflicting context pair(s) with node memory, 1 c_wall violated: 2 conflicting context pair(s) with node memory, 4 node(s) had untolerated taint(s). no new claims to deallocate, preemption: 0/6 nodes are available: 2 No preemption victims found for incoming pod, 4 Preemption is not helpful for scheduling."
0.241,Event,ADDED,eval-sanitize-30-r0-151-jbkvt.18d4ab1478a6d8cc,"reason=FailedScheduling count=None msg=0/6 nodes are available: 1 c_wall violated: 1 conflicting context pair(s) with node memory, 1 c_wall violated: 2 conflicting context pair(s) with node memory, 4 node(s) had untolerated taint(s). no new claims to deallocate, preemption: 0/6 nodes are available: 2 No preemption victims found for incoming pod, 4 Preemption is not helpful for scheduling."
0.2412,Event,ADDED,eval-sanitize-30-r0-151-jbkvt.18d4ab149da056b6,reason=Scheduled count=None msg=Successfully assigned compute/eval-sanitize-30-r0-151-jbkvt to kind-worker5
0.2414,Event,ADDED,eval-sanitize-30-r0-151-jbkvt.18d4ab14b9313794,"reason=Pulled count=1 msg=Container image ""busybox:musl"" already present on machine"
0.2415,Event,ADDED,eval-sanitize-30-r0-151-jbkvt.18d4ab14bb1cce5c,reason=Created count=1 msg=Created container: task
0.2417,Event,ADDED,eval-sanitize-30-r0-151-jbkvt.18d4ab14c04eaf62,reason=Started count=1 msg=Started container task
0.2419,Event,ADDED,eval-sanitize-30-r0-151.18d4ab122ec7e1f4,reason=SuccessfulCreate count=1 msg=Created pod: eval-sanitize-30-r0-151-jbkvt
0.242,Event,ADDED,eval-sanitize-30-r0-151.18d4ab1abe9faf47,reason=Completed count=1 msg=Job completed
0.2422,Event,ADDED,eval-sanitize-30-r0-152-hl7nl.18d4ab126e3d2502,reason=Scheduled count=None msg=Successfully assigned compute/eval-sanitize-30-r0-152-hl7nl to kind-worker4
0.2423,Event,ADDED,eval-sanitize-30-r0-152-hl7nl.18d4ab128eec200e,"reason=Pulled count=1 msg=Container image ""busybox:musl"" already present on machine"
0.2425,Event,ADDED,eval-sanitize-30-r0-152-hl7nl.18d4ab1290dcdd08,reason=Created count=1 msg=Created container: task
0.2427,Event,ADDED,eval-sanitize-30-r0-152-hl7nl.18d4ab1298ad6eb9,reason=Started count=1 msg=Started container task
0.2428,Event,ADDED,eval-sanitize-30-r0-152.18d4ab126d795d16,reason=SuccessfulCreate count=1 msg=Created pod: eval-sanitize-30-r0-152-hl7nl
0.243,Event,ADDED,eval-sanitize-30-r0-152.18d4ab180fb262b0,reason=Completed count=1 msg=Job completed
0.2432,Event,ADDED,eval-sanitize-30-r0-153-9mvwc.18d4ab12a8cb95e9,reason=Scheduled count=None msg=Successfully assigned compute/eval-sanitize-30-r0-153-9mvwc to kind-worker4
0.2433,Event,ADDED,eval-sanitize-30-r0-153-9mvwc.18d4ab12ce64263f,"reason=Pulled count=1 msg=Container image ""busybox:musl"" already present on machine"
0.2435,Event,ADDED,eval-sanitize-30-r0-153-9mvwc.18d4ab12cfcd9b0e,reason=Created count=1 msg=Created container: task
0.2437,Event,ADDED,eval-sanitize-30-r0-153-9mvwc.18d4ab12da95249d,reason=Started count=1 msg=Started container task
0.2438,Event,ADDED,eval-sanitize-30-r0-153.18d4ab12a8056d21,reason=SuccessfulCreate count=1 msg=Created pod: eval-sanitize-30-r0-153-9mvwc
0.244,Event,ADDED,eval-sanitize-30-r0-153.18d4ab18105ca037,reason=Completed count=1 msg=Job completed
0.2441,Event,ADDED,eval-sanitize-30-r0-154-vfrq9.18d4ab12eda08561,reason=Scheduled count=None msg=Successfully assigned compute/eval-sanitize-30-r0-154-vfrq9 to kind-worker4
0.2443,Event,ADDED,eval-sanitize-30-r0-154-vfrq9.18d4ab1309ce911d,"reason=Pulled count=1 msg=Container image ""busybox:musl"" already present on machine"
0.2445,Event,ADDED,eval-sanitize-30-r0-154-vfrq9.18d4ab130b63ec35,reason=Created count=1 msg=Created container: task
0.2447,Event,ADDED,eval-sanitize-30-r0-154-vfrq9.18d4ab1311aa21ce,reason=Started count=1 msg=Started container task
0.2449,Event,ADDED,eval-sanitize-30-r0-154.18d4ab12ecdb0f13,reason=SuccessfulCreate count=1 msg=Created pod: eval-sanitize-30-r0-154-vfrq9
0.245,Event,ADDED,eval-sanitize-30-r0-154.18d4ab188762d7f3,reason=Completed count=1 msg=Job completed
0.2452,Event,ADDED,eval-sanitize-30-r0-155-4lz2h.18d4ab131ee7b548,"reason=FailedScheduling count=None msg=0/6 nodes are available: 1 c_wall violated: 1 conflicting context pair(s) with node memory, 5 node(s) had untolerated taint(s). no new claims to deallocate, preemption: 0/6 nodes are available: 1 No preemption victims found for incoming pod, 5 Preemption is not helpful for scheduling."
0.2454,Event,ADDED,eval-sanitize-30-r0-155-4lz2h.18d4ab131fa6756b,"reason=FailedScheduling count=None msg=0/6 nodes are available: 1 c_wall violated: 1 conflicting context pair(s) with node memory, 5 node(s) had untolerated taint(s). no new claims to deallocate, preemption: 0/6 nodes are available: 1 No preemption victims found for incoming pod, 5 Preemption is not helpful for scheduling."
0.2456,Event,ADDED,eval-sanitize-30-r0-155-4lz2h.18d4ab146ba62f18,"reason=FailedScheduling count=None msg=0/6 nodes are available: 2 c_wall violated: 1 conflicting context pair(s) with node memory, 4 node(s) had untolerated taint(s). no new claims to deallocate, preemption: 0/6 nodes are available: 2 No preemption victims found for incoming pod, 4 Preemption is not helpful for scheduling."
0.2457,Event,ADDED,eval-sanitize-30-r0-155-4lz2h.18d4ab14c03c1d06,"reason=FailedScheduling count=None msg=0/6 nodes are available: 1 c_wall violated: 2 conflicting context pair(s) with node memory, 2 c_wall violated: 1 conflicting context pair(s) with node memory, 3 node(s) had untolerated taint(s). no new claims to deallocate, preemption: 0/6 nodes are available: 3 No preemption victims found for incoming pod, 3 Preemption is not helpful for scheduling."
0.2458,Event,ADDED,eval-sanitize-30-r0-155-4lz2h.18d4ab14f50d2b78,reason=Scheduled count=None msg=Successfully assigned compute/eval-sanitize-30-r0-155-4lz2h to kind-worker
0.246,Event,ADDED,eval-sanitize-30-r0-155-4lz2h.18d4ab1511d39063,"reason=Pulled count=1 msg=Container image ""busybox:musl"" already present on machine"
0.2463,Event,ADDED,eval-sanitize-30-r0-155-4lz2h.18d4ab15145873e2,reason=Created count=1 msg=Created container: task
0.2464,Event,ADDED,eval-sanitize-30-r0-155-4lz2h.18d4ab15199b2f64,reason=Started count=1 msg=Started container task
0.2466,Event,ADDED,eval-sanitize-30-r0-155.18d4ab131e8f491b,reason=SuccessfulCreate count=1 msg=Created pod: eval-sanitize-30-r0-155-4lz2h
0.2468,Event,ADDED,eval-sanitize-30-r0-155.18d4ab1b6562dca4,reason=Completed count=1 msg=Job completed
0.2471,Event,ADDED,eval-sanitize-30-r0-156-254p8.18d4ab1359ff9a80,reason=Scheduled count=None msg=Successfully assigned compute/eval-sanitize-30-r0-156-254p8 to kind-worker4
0.2472,Event,ADDED,eval-sanitize-30-r0-156-254p8.18d4ab13779a97f1,"reason=Pulled count=1 msg=Container image ""busybox:musl"" already present on machine"
0.2474,Event,ADDED,eval-sanitize-30-r0-156-254p8.18d4ab1379be396c,reason=Created count=1 msg=Created container: task
0.2476,Event,ADDED,eval-sanitize-30-r0-156-254p8.18d4ab1381fee0bb,reason=Started count=1 msg=Started container task
0.2478,Event,ADDED,eval-sanitize-30-r0-156.18d4ab13591904b9,reason=SuccessfulCreate count=1 msg=Created pod: eval-sanitize-30-r0-156-254p8
0.2479,Event,ADDED,eval-sanitize-30-r0-156.18d4ab18fe5280f2,reason=Completed count=1 msg=Job completed
0.2481,Event,ADDED,eval-sanitize-30-r0-157-96n6d.18d4ab139acee1c1,"reason=FailedScheduling count=None msg=0/6 nodes are available: 1 c_wall violated: 1 conflicting context pair(s) with node memory, 5 node(s) had untolerated taint(s). no new claims to deallocate, preemption: 0/6 nodes are available: 1 No preemption victims found for incoming pod, 5 Preemption is not helpful for scheduling."
0.2483,Event,ADDED,eval-sanitize-30-r0-157-96n6d.18d4ab139ba43e1c,"reason=FailedScheduling count=None msg=0/6 nodes are available: 1 c_wall violated: 1 conflicting context pair(s) with node memory, 5 node(s) had untolerated taint(s). no new claims to deallocate, preemption: 0/6 nodes are available: 1 No preemption victims found for incoming pod, 5 Preemption is not helpful for scheduling."
0.2485,Event,ADDED,eval-sanitize-30-r0-157-96n6d.18d4ab1471b6c55d,"reason=FailedScheduling count=None msg=0/6 nodes are available: 2 c_wall violated: 1 conflicting context pair(s) with node memory, 4 node(s) had untolerated taint(s). no new claims to deallocate, preemption: 0/6 nodes are available: 2 No preemption victims found for incoming pod, 4 Preemption is not helpful for scheduling."
0.2486,Event,ADDED,eval-sanitize-30-r0-157-96n6d.18d4ab14d1f3651c,"reason=FailedScheduling count=None msg=0/6 nodes are available: 1 c_wall violated: 2 conflicting context pair(s) with node memory, 2 c_wall violated: 1 conflicting context pair(s) with node memory, 3 node(s) had untolerated taint(s). no new claims to deallocate, preemption: 0/6 nodes are available: 3 No preemption victims found for incoming pod, 3 Preemption is not helpful for scheduling."
0.2488,Event,ADDED,eval-sanitize-30-r0-157-96n6d.18d4ab1502d930c0,reason=Scheduled count=None msg=Successfully assigned compute/eval-sanitize-30-r0-157-96n6d to kind-worker
0.2489,Event,ADDED,eval-sanitize-30-r0-157-96n6d.18d4ab1521ec2521,"reason=Pulled count=1 msg=Container image ""busybox:musl"" already present on machine"
0.2491,Event,ADDED,eval-sanitize-30-r0-157-96n6d.18d4ab1523da9b7f,reason=Created count=1 msg=Created container: task
0.2493,Event,ADDED,eval-sanitize-30-r0-157-96n6d.18d4ab1529587069,reason=Started count=1 msg=Started container task
0.2494,Event,ADDED,eval-sanitize-30-r0-157.18d4ab139a7b46c8,reason=SuccessfulCreate count=1 msg=Created pod: eval-sanitize-30-r0-157-96n6d
0.2496,Event,ADDED,eval-sanitize-30-r0-157.18d4ab1b539a4c10,reason=Completed count=1 msg=Job completed
0.2498,Event,ADDED,eval-sanitize-30-r0-158-mqhlq.18d4ab13d1643879,reason=Scheduled count=None msg=Successfully assigned compute/eval-sanitize-30-r0-158-mqhlq to kind-worker4
0.2499,Event,ADDED,eval-sanitize-30-r0-158-mqhlq.18d4ab13f4578dd2,"reason=Pulled count=1 msg=Container image ""busybox:musl"" already present on machine"
0.2501,Event,ADDED,eval-sanitize-30-r0-158-mqhlq.18d4ab13f5ccb543,reason=Created count=1 msg=Created container: task
0.2503,Event,ADDED,eval-sanitize-30-r0-158-mqhlq.18d4ab13faa75b99,reason=Started count=1 msg=Started container task
0.2504,Event,ADDED,eval-sanitize-30-r0-158.18d4ab13d0b5a490,reason=SuccessfulCreate count=1 msg=Created pod: eval-sanitize-30-r0-158-mqhlq
0.2506,Event,ADDED,eval-sanitize-30-r0-158.18d4ab193b6cfb07,reason=Completed count=1 msg=Job completed
0.2507,Event,ADDED,eval-sanitize-30-r0-159-v7t6b.18d4ab140d12735a,reason=Scheduled count=None msg=Successfully assigned compute/eval-sanitize-30-r0-159-v7t6b to kind-worker4
0.2509,Event,ADDED,eval-sanitize-30-r0-159-v7t6b.18d4ab142844dcc7,"reason=Pulled count=1 msg=Container image ""busybox:musl"" already present on machine"
0.2511,Event,ADDED,eval-sanitize-30-r0-159-v7t6b.18d4ab1429b6648c,reason=Created count=1 msg=Created container: task
0.2512,Event,ADDED,eval-sanitize-30-r0-159-v7t6b.18d4ab142df65b11,reason=Started count=1 msg=Started container task
0.2514,Event,ADDED,eval-sanitize-30-r0-159.18d4ab140c5550ff,reason=SuccessfulCreate count=1 msg=Created pod: eval-sanitize-30-r0-159-v7t6b
0.2516,Event,ADDED,eval-sanitize-30-r0-159.18d4ab19b4f27834,reason=Completed count=1 msg=Job completed
0.2517,Event,ADDED,eval-sanitize-30-r0-160-5qq6v.18d4ab144a54d622,reason=Scheduled count=None msg=Successfully assigned compute/eval-sanitize-30-r0-160-5qq6v to kind-worker4
0.2519,Event,ADDED,eval-sanitize-30-r0-160-5qq6v.18d4ab1467b751c9,"reason=Pulled count=1 msg=Container image ""busybox:musl"" already present on machine"
0.2521,Event,ADDED,eval-sanitize-30-r0-160-5qq6v.18d4ab1468ebe838,reason=Created count=1 msg=Created container: task
0.2523,Event,ADDED,eval-sanitize-30-r0-160-5qq6v.18d4ab146bdd6c4c,reason=Started count=1 msg=Started container task
0.2524,Event,ADDED,eval-sanitize-30-r0-160.18d4ab14471c90b8,reason=SuccessfulCreate count=1 msg=Created pod: eval-sanitize-30-r0-160-5qq6v
0.2526,Event,ADDED,eval-sanitize-30-r0-160.18d4ab19f077c417,reason=Completed count=1 msg=Job completed
0.2527,Event,ADDED,eval-sanitize-30-r0-161-q748w.18d4ab148445f61f,reason=Scheduled count=None msg=Successfully assigned compute/eval-sanitize-30-r0-161-q748w to kind-worker2
0.2529,Event,ADDED,eval-sanitize-30-r0-161-q748w.18d4ab14a16baad8,"reason=Pulled count=1 msg=Container image ""busybox:musl"" already present on machine"
0.2531,Event,ADDED,eval-sanitize-30-r0-161-q748w.18d4ab14a2e09aa9,reason=Created count=1 msg=Created container: task
0.2532,Event,ADDED,eval-sanitize-30-r0-161-q748w.18d4ab14a8f118d9,reason=Started count=1 msg=Started container task
0.2534,Event,ADDED,eval-sanitize-30-r0-161.18d4ab14833b450a,reason=SuccessfulCreate count=1 msg=Created pod: eval-sanitize-30-r0-161-q748w
0.2536,Event,ADDED,eval-sanitize-30-r0-161.18d4ab1a3bab65b8,reason=Completed count=1 msg=Job completed
0.2537,Event,ADDED,eval-sanitize-30-r0-162-b5rbq.18d4ab14c574d873,reason=Scheduled count=None msg=Successfully assigned compute/eval-sanitize-30-r0-162-b5rbq to kind-worker5
0.2539,Event,ADDED,eval-sanitize-30-r0-162-b5rbq.18d4ab14e0d57733,"reason=Pulled count=1 msg=Container image ""busybox:musl"" already present on machine"
0.2541,Event,ADDED,eval-sanitize-30-r0-162-b5rbq.18d4ab14e2104f1c,reason=Created count=1 msg=Created container: task
0.2542,Event,ADDED,eval-sanitize-30-r0-162-b5rbq.18d4ab14e707c102,reason=Started count=1 msg=Started container task
0.2544,Event,ADDED,eval-sanitize-30-r0-162.18d4ab14bea172f3,reason=SuccessfulCreate count=1 msg=Created pod: eval-sanitize-30-r0-162-b5rbq
0.2545,Event,ADDED,eval-sanitize-30-r0-162.18d4ab1b23fc9edb,reason=Completed count=1 msg=Job completed
0.2547,Event,ADDED,eval-sanitize-30-r0-163-h96xf.18d4ab14fd114c6f,reason=Scheduled count=None msg=Successfully assigned compute/eval-sanitize-30-r0-163-h96xf to kind-worker2
0.2549,Event,ADDED,eval-sanitize-30-r0-163-h96xf.18d4ab151a708505,"reason=Pulled count=1 msg=Container image ""busybox:musl"" already present on machine"
0.255,Event,ADDED,eval-sanitize-30-r0-163-h96xf.18d4ab151c159540,reason=Created count=1 msg=Created container: task
0.2552,Event,ADDED,eval-sanitize-30-r0-163-h96xf.18d4ab1521e9a8d7,reason=Started count=1 msg=Started container task
0.2554,Event,ADDED,eval-sanitize-30-r0-163.18d4ab14fa871c83,reason=SuccessfulCreate count=1 msg=Created pod: eval-sanitize-30-r0-163-h96xf
0.2555,Event,ADDED,eval-sanitize-30-r0-163.18d4ab1b77408207,reason=Completed count=1 msg=Job completed
0.2557,Event,ADDED,eval-sanitize-30-r0-164-2fqsn.18d4ab15373909bb,reason=Scheduled count=None msg=Successfully assigned compute/eval-sanitize-30-r0-164-2fqsn to kind-worker3
0.2559,Event,ADDED,eval-sanitize-30-r0-164-2fqsn.18d4ab1552fefa89,"reason=Pulled count=1 msg=Container image ""busybox:musl"" already present on machine"
0.2561,Event,ADDED,eval-sanitize-30-r0-164-2fqsn.18d4ab1554d01102,reason=Created count=1 msg=Created container: task
0.2562,Event,ADDED,eval-sanitize-30-r0-164-2fqsn.18d4ab155a5ba474,reason=Started count=1 msg=Started container task
0.2564,Event,ADDED,eval-sanitize-30-r0-164.18d4ab1535d03686,reason=SuccessfulCreate count=1 msg=Created pod: eval-sanitize-30-r0-164-2fqsn
0.2566,Event,ADDED,eval-sanitize-30-r0-164.18d4ab1b38cc74c9,reason=Completed count=1 msg=Job completed
0.2567,Event,ADDED,eval-sanitize-30-r0-165-ntvl2.18d4ab1578894da8,reason=Scheduled count=None msg=Successfully assigned compute/eval-sanitize-30-r0-165-ntvl2 to kind-worker3
0.2569,Event,ADDED,eval-sanitize-30-r0-165-ntvl2.18d4ab159315283a,"reason=Pulled count=1 msg=Container image ""busybox:musl"" already present on machine"
0.2571,Event,ADDED,eval-sanitize-30-r0-165-ntvl2.18d4ab15945a6559,reason=Created count=1 msg=Created container: task
0.2572,Event,ADDED,eval-sanitize-30-r0-165-ntvl2.18d4ab159a1f655c,reason=Started count=1 msg=Started container task
0.2574,Event,ADDED,eval-sanitize-30-r0-165.18d4ab157165148c,reason=SuccessfulCreate count=1 msg=Created pod: eval-sanitize-30-r0-165-ntvl2
0.2576,Event,ADDED,eval-sanitize-30-r0-165.18d4ab1b630db079,reason=Completed count=1 msg=Job completed
0.2577,Event,ADDED,eval-sanitize-30-r0-166-5r9pv.18d4ab15af8688b0,reason=Scheduled count=None msg=Successfully assigned compute/eval-sanitize-30-r0-166-5r9pv to kind-worker
0.2579,Event,ADDED,eval-sanitize-30-r0-166-5r9pv.18d4ab15c8fe9ecb,"reason=Pulled count=1 msg=Container image ""busybox:musl"" already present on machine"
0.2581,Event,ADDED,eval-sanitize-30-r0-166-5r9pv.18d4ab15ca66746e,reason=Created count=1 msg=Created container: task
0.2582,Event,ADDED,eval-sanitize-30-r0-166-5r9pv.18d4ab15cd2b7e4e,reason=Started count=1 msg=Started container task
0.2584,Event,ADDED,eval-sanitize-30-r0-166.18d4ab15acd1c288,reason=SuccessfulCreate count=1 msg=Created pod: eval-sanitize-30-r0-166-5r9pv
0.2586,Event,ADDED,eval-sanitize-30-r0-166.18d4ab1b86e58a45,reason=Completed count=1 msg=Job completed
0.2587,Event,ADDED,eval-sanitize-30-r0-167-zkt7r.18d4ab15efa2dadb,reason=Scheduled count=None msg=Successfully assigned compute/eval-sanitize-30-r0-167-zkt7r to kind-worker5
0.2589,Event,ADDED,eval-sanitize-30-r0-167-zkt7r.18d4ab160de3aad6,"reason=Pulled count=1 msg=Container image ""busybox:musl"" already present on machine"
0.2591,Event,ADDED,eval-sanitize-30-r0-167-zkt7r.18d4ab160f413d73,reason=Created count=1 msg=Created container: task
0.2593,Event,ADDED,eval-sanitize-30-r0-167-zkt7r.18d4ab16190ee418,reason=Started count=1 msg=Started container task
0.2594,Event,ADDED,eval-sanitize-30-r0-167.18d4ab15e94aed0b,reason=SuccessfulCreate count=1 msg=Created pod: eval-sanitize-30-r0-167-zkt7r
0.2596,Event,ADDED,eval-sanitize-30-r0-167.18d4ab1bbecbfe30,reason=Completed count=1 msg=Job completed
0.2597,Event,ADDED,eval-sanitize-30-r0-168-q8lxg.18d4ab16263b67ba,reason=Scheduled count=None msg=Successfully assigned compute/eval-sanitize-30-r0-168-q8lxg to kind-worker
0.2599,Event,ADDED,eval-sanitize-30-r0-168-q8lxg.18d4ab1641ad30dd,"reason=Pulled count=1 msg=Container image ""busybox:musl"" already present on machine"
0.2601,Event,ADDED,eval-sanitize-30-r0-168-q8lxg.18d4ab1642fd8f3e,reason=Created count=1 msg=Created container: task
0.2602,Event,ADDED,eval-sanitize-30-r0-168-q8lxg.18d4ab16489b8362,reason=Started count=1 msg=Started container task
0.2604,Event,ADDED,eval-sanitize-30-r0-168.18d4ab162408caac,reason=SuccessfulCreate count=1 msg=Created pod: eval-sanitize-30-r0-168-q8lxg
0.2606,Event,ADDED,eval-sanitize-30-r0-168.18d4ab1bee73b3d6,reason=Completed count=1 msg=Job completed
0.2607,Event,ADDED,eval-sanitize-30-r0-169-wk8c9.18d4ab1661fdaff7,reason=Scheduled count=None msg=Successfully assigned compute/eval-sanitize-30-r0-169-wk8c9 to kind-worker3
0.2609,Event,ADDED,eval-sanitize-30-r0-169-wk8c9.18d4ab167dc2ccea,"reason=Pulled count=1 msg=Container image ""busybox:musl"" already present on machine"
0.2611,Event,ADDED,eval-sanitize-30-r0-169-wk8c9.18d4ab167f2fbf44,reason=Created count=1 msg=Created container: task
0.2612,Event,ADDED,eval-sanitize-30-r0-169-wk8c9.18d4ab168468b0bd,reason=Started count=1 msg=Started container task
0.2614,Event,ADDED,eval-sanitize-30-r0-169.18d4ab165ff2b44c,reason=SuccessfulCreate count=1 msg=Created pod: eval-sanitize-30-r0-169-wk8c9
0.2616,Event,ADDED,eval-sanitize-30-r0-169.18d4ab1c2525fe5f,reason=Completed count=1 msg=Job completed
0.2617,Event,ADDED,eval-sanitize-30-r0-170-t6wms.18d4ab16a1f3098b,"reason=FailedScheduling count=None msg=0/6 nodes are available: 1 c_wall violated: 1 conflicting context pair(s) with node memory, 1 c_wall violated: 3 conflicting context pair(s) with node memory, 2 c_wall violated: 2 conflicting context pair(s) with node memory, 2 node(s) had untolerated taint(s). no new claims to deallocate, preemption: 0/6 nodes are available: 2 Preemption is not helpful for scheduling, 4 No preemption victims found for incoming pod."
0.2619,Event,ADDED,eval-sanitize-30-r0-170-t6wms.18d4ab16a7f3d99d,"reason=FailedScheduling count=None msg=0/6 nodes are available: 1 c_wall violated: 1 conflicting context pair(s) with node memory, 1 c_wall violated: 3 conflicting context pair(s) with node memory, 2 c_wall violated: 2 conflicting context pair(s) with node memory, 2 node(s) had untolerated taint(s). no new claims to deallocate, preemption: 0/6 nodes are available: 2 Preemption is not helpful for scheduling, 4 No preemption victims found for incoming pod."
0.2621,Event,ADDED,eval-sanitize-30-r0-170-t6wms.18d4ab16eae0ef7e,"reason=FailedScheduling count=None msg=0/6 nodes are available: 1 c_wall violated: 1 conflicting context pair(s) with node memory, 1 c_wall violated: 2 conflicting context pair(s) with node memory, 2 c_wall violated: 3 conflicting context pair(s) with node memory, 2 node(s) had untolerated taint(s). no new claims to deallocate, preemption: 0/6 nodes are available: 2 Preemption is not helpful for scheduling, 4 No preemption victims found for incoming pod."
0.2622,Event,ADDED,eval-sanitize-30-r0-170-t6wms.18d4ab1b6f87978f,reason=Scheduled count=None msg=Successfully assigned compute/eval-sanitize-30-r0-170-t6wms to kind-worker2
0.2624,Event,ADDED,eval-sanitize-30-r0-170-t6wms.18d4ab1b8d6efc02,"reason=Pulled count=1 msg=Container image ""busybox:musl"" already present on machine"
0.2626,Event,ADDED,eval-sanitize-30-r0-170-t6wms.18d4ab1b8ebaeaee,reason=Created count=1 msg=Created container: task
0.2628,Event,ADDED,eval-sanitize-30-r0-170-t6wms.18d4ab1b9327e453,reason=Started count=1 msg=Started container task
0.263,Event,ADDED,eval-sanitize-30-r0-170.18d4ab169ba05f03,reason=SuccessfulCreate count=1 msg=Created pod: eval-sanitize-30-r0-170-t6wms
0.2632,Event,ADDED,eval-sanitize-30-r0-170.18d4ab20c8029e68,reason=Completed count=1 msg=Job completed
0.2633,Event,ADDED,eval-sanitize-30-r0-171-456r5.18d4ab16df327e79,reason=Scheduled count=None msg=Successfully assigned compute/eval-sanitize-30-r0-171-456r5 to kind-worker3
0.2635,Event,ADDED,eval-sanitize-30-r0-171-456r5.18d4ab16fbb76fac,"reason=Pulled count=1 msg=Container image ""busybox:musl"" already present on machine"
0.2637,Event,ADDED,eval-sanitize-30-r0-171-456r5.18d4ab16fd704cc1,reason=Created count=1 msg=Created container: task
0.2638,Event,ADDED,eval-sanitize-30-r0-171-456r5.18d4ab16fff2c695,reason=Started count=1 msg=Started container task
0.264,Event,ADDED,eval-sanitize-30-r0-171.18d4ab16d85cb464,reason=SuccessfulCreate count=1 msg=Created pod: eval-sanitize-30-r0-171-456r5
0.2642,Event,ADDED,eval-sanitize-30-r0-171.18d4ab1c964b8ac4,reason=Completed count=1 msg=Job completed
0.2643,Event,ADDED,eval-sanitize-30-r0-172-qchln.18d4ab171b1887d9,reason=Scheduled count=None msg=Successfully assigned compute/eval-sanitize-30-r0-172-qchln to kind-worker
0.2645,Event,ADDED,eval-sanitize-30-r0-172-qchln.18d4ab173798c4c0,"reason=Pulled count=1 msg=Container image ""busybox:musl"" already present on machine"
0.2647,Event,ADDED,eval-sanitize-30-r0-172-qchln.18d4ab1738e7bc55,reason=Created count=1 msg=Created container: task
0.2648,Event,ADDED,eval-sanitize-30-r0-172-qchln.18d4ab173e256f33,reason=Started count=1 msg=Started container task
0.265,Event,ADDED,eval-sanitize-30-r0-172.18d4ab1713537b72,reason=SuccessfulCreate count=1 msg=Created pod: eval-sanitize-30-r0-172-qchln
0.2651,Event,ADDED,eval-sanitize-30-r0-172.18d4ab1ccb09dc83,reason=Completed count=1 msg=Job completed
0.2653,Event,ADDED,eval-sanitize-30-r0-173-vkmvn.18d4ab1758489485,reason=Scheduled count=None msg=Successfully assigned compute/eval-sanitize-30-r0-173-vkmvn to kind-worker
0.2655,Event,ADDED,eval-sanitize-30-r0-173-vkmvn.18d4ab1773387a52,"reason=Pulled count=1 msg=Container image ""busybox:musl"" already present on machine"
0.2657,Event,ADDED,eval-sanitize-30-r0-173-vkmvn.18d4ab1774840446,reason=Created count=1 msg=Created container: task
0.2658,Event,ADDED,eval-sanitize-30-r0-173-vkmvn.18d4ab177b5d2d25,reason=Started count=1 msg=Started container task
0.266,Event,ADDED,eval-sanitize-30-r0-173.18d4ab174edc8629,reason=SuccessfulCreate count=1 msg=Created pod: eval-sanitize-30-r0-173-vkmvn
0.2662,Event,ADDED,eval-sanitize-30-r0-173.18d4ab1d07062e93,reason=Completed count=1 msg=Job completed
0.2664,Event,ADDED,eval-sanitize-30-r0-174-jgstd.18d4ab17915500ca,"reason=FailedScheduling count=None msg=0/6 nodes are available: 1 c_wall violated: 3 conflicting context pair(s) with node memory, 2 node(s) had untolerated taint(s), 3 c_wall violated: 1 conflicting context pair(s) with node memory. no new claims to deallocate, preemption: 0/6 nodes are available: 2 Preemption is not helpful for scheduling, 4 No preemption victims found for incoming pod."
0.2666,Event,ADDED,eval-sanitize-30-r0-174-jgstd.18d4ab179751f13f,"reason=FailedScheduling count=None msg=0/6 nodes are available: 1 c_wall violated: 3 conflicting context pair(s) with node memory, 2 node(s) had untolerated taint(s), 3 c_wall violated: 1 conflicting context pair(s) with node memory. no new claims to deallocate, preemption: 0/6 nodes are available: 2 Preemption is not helpful for scheduling, 4 No preemption victims found for incoming pod."
0.2667,Event,ADDED,eval-sanitize-30-r0-174-jgstd.18d4ab1b33d75e78,reason=Scheduled count=None msg=Successfully assigned compute/eval-sanitize-30-r0-174-jgstd to kind-worker2
0.2669,Event,ADDED,eval-sanitize-30-r0-174-jgstd.18d4ab1b4ed6587c,"reason=Pulled count=1 msg=Container image ""busybox:musl"" already present on machine"
0.2671,Event,ADDED,eval-sanitize-30-r0-174-jgstd.18d4ab1b5023153c,reason=Created count=1 msg=Created container: task
0.2672,Event,ADDED,eval-sanitize-30-r0-174-jgstd.18d4ab1b55f5a8dd,reason=Started count=1 msg=Started container task
0.2674,Event,ADDED,eval-sanitize-30-r0-174.18d4ab178cac097d,reason=SuccessfulCreate count=1 msg=Created pod: eval-sanitize-30-r0-174-jgstd
0.2676,Event,ADDED,eval-sanitize-30-r0-174.18d4ab20c61fb630,reason=Completed count=1 msg=Job completed
0.2677,Event,ADDED,eval-sanitize-30-r0-175-587qf.18d4ab17cc0d551c,"reason=FailedScheduling count=None msg=0/6 nodes are available: 1 c_wall violated: 1 conflicting context pair(s) with node memory, 1 c_wall violated: 2 conflicting context pair(s) with node memory, 2 c_wall violated: 3 conflicting context pair(s) with node memory, 2 node(s) had untolerated taint(s). no new claims to deallocate, preemption: 0/6 nodes are available: 2 Preemption is not helpful for scheduling, 4 No preemption victims found for incoming pod."
0.2679,Event,ADDED,eval-sanitize-30-r0-175-587qf.18d4ab17d21a7937,"reason=FailedScheduling count=None msg=0/6 nodes are available: 1 c_wall violated: 1 conflicting context pair(s) with node memory, 1 c_wall violated: 2 conflicting context pair(s) with node memory, 2 c_wall violated: 3 conflicting context pair(s) with node memory, 2 node(s) had untolerated taint(s). no new claims to deallocate, preemption: 0/6 nodes are available: 2 Preemption is not helpful for scheduling, 4 No preemption victims found for incoming pod."
0.2681,Event,ADDED,eval-sanitize-30-r0-175-587qf.18d4ab1b57cb0dcd,reason=Scheduled count=None msg=Successfully assigned compute/eval-sanitize-30-r0-175-587qf to kind-worker2
0.2682,Event,ADDED,eval-sanitize-30-r0-175-587qf.18d4ab1b769b8174,"reason=Pulled count=1 msg=Container image ""busybox:musl"" already present on machine"
0.2684,Event,ADDED,eval-sanitize-30-r0-175-587qf.18d4ab1b7804a3d6,reason=Created count=1 msg=Created container: task
0.2686,Event,ADDED,eval-sanitize-30-r0-175-587qf.18d4ab1b7f464abf,reason=Started count=1 msg=Started container task
0.2687,Event,ADDED,eval-sanitize-30-r0-175.18d4ab17c603733d,reason=SuccessfulCreate count=1 msg=Created pod: eval-sanitize-30-r0-175-587qf
0.2689,Event,ADDED,eval-sanitize-30-r0-175.18d4ab21044d1480,reason=Completed count=1 msg=Job completed
0.269,Event,ADDED,eval-sanitize-30-r0-176-r56b8.18d4ab1809573eac,reason=Scheduled count=None msg=Successfully assigned compute/eval-sanitize-30-r0-176-r56b8 to kind-worker5
0.2692,Event,ADDED,eval-sanitize-30-r0-176-r56b8.18d4ab182a05b4d2,"reason=Pulled count=1 msg=Container image ""busybox:musl"" already present on machine"
0.2694,Event,ADDED,eval-sanitize-30-r0-176-r56b8.18d4ab182b778833,reason=Created count=1 msg=Created container: task
0.2695,Event,ADDED,eval-sanitize-30-r0-176-r56b8.18d4ab18302cab80,reason=Started count=1 msg=Started container task
0.2697,Event,ADDED,eval-sanitize-30-r0-176.18d4ab1801a16307,reason=SuccessfulCreate count=1 msg=Created pod: eval-sanitize-30-r0-176-r56b8
0.2699,Event,ADDED,eval-sanitize-30-r0-176.18d4ab1dcd9f7e98,reason=Completed count=1 msg=Job completed
0.27,Event,ADDED,eval-sanitize-30-r0-177-7g67l.18d4ab183eca340c,reason=Scheduled count=None msg=Successfully assigned compute/eval-sanitize-30-r0-177-7g67l to kind-worker
0.2702,Event,ADDED,eval-sanitize-30-r0-177-7g67l.18d4ab1859610de9,"reason=Pulled count=1 msg=Container image ""busybox:musl"" already present on machine"
0.2704,Event,ADDED,eval-sanitize-30-r0-177-7g67l.18d4ab185b25a74a,reason=Created count=1 msg=Created container: task
0.2705,Event,ADDED,eval-sanitize-30-r0-177-7g67l.18d4ab185fc31d92,reason=Started count=1 msg=Started container task
0.2707,Event,ADDED,eval-sanitize-30-r0-177.18d4ab183c965ebf,reason=SuccessfulCreate count=1 msg=Created pod: eval-sanitize-30-r0-177-7g67l
0.2709,Event,ADDED,eval-sanitize-30-r0-177.18d4ab1df5fd2c27,reason=Completed count=1 msg=Job completed
0.271,Event,ADDED,eval-sanitize-30-r0-178-bv8gg.18d4ab18807e4a77,reason=Scheduled count=None msg=Successfully assigned compute/eval-sanitize-30-r0-178-bv8gg to kind-worker5
0.2712,Event,ADDED,eval-sanitize-30-r0-178-bv8gg.18d4ab189b094861,"reason=Pulled count=1 msg=Container image ""busybox:musl"" already present on machine"
0.2713,Event,ADDED,eval-sanitize-30-r0-178-bv8gg.18d4ab189c496357,reason=Created count=1 msg=Created container: task
0.2715,Event,ADDED,eval-sanitize-30-r0-178-bv8gg.18d4ab18a12511a3,reason=Started count=1 msg=Started container task
0.2717,Event,ADDED,eval-sanitize-30-r0-178.18d4ab1878344656,reason=SuccessfulCreate count=1 msg=Created pod: eval-sanitize-30-r0-178-bv8gg
0.2718,Event,ADDED,eval-sanitize-30-r0-178.18d4ab1e0981ea7e,reason=Completed count=1 msg=Job completed
0.272,Event,ADDED,eval-sanitize-30-r0-179-rjg4b.18d4ab18bad1ba0b,reason=Scheduled count=None msg=Successfully assigned compute/eval-sanitize-30-r0-179-rjg4b to kind-worker3
0.2722,Event,ADDED,eval-sanitize-30-r0-179-rjg4b.18d4ab18d5f17a79,"reason=Pulled count=1 msg=Container image ""busybox:musl"" already present on machine"
0.2723,Event,ADDED,eval-sanitize-30-r0-179-rjg4b.18d4ab18d73e50d1,reason=Created count=1 msg=Created container: task
0.2725,Event,ADDED,eval-sanitize-30-r0-179-rjg4b.18d4ab18ded472e0,reason=Started count=1 msg=Started container task
0.2726,Event,ADDED,eval-sanitize-30-r0-179.18d4ab18b3fdaacc,reason=SuccessfulCreate count=1 msg=Created pod: eval-sanitize-30-r0-179-rjg4b
0.2728,Event,ADDED,eval-sanitize-30-r0-179.18d4ab1e75e90c71,reason=Completed count=1 msg=Job completed
0.273,Event,ADDED,eval-sanitize-30-r0-180-psgwh.18d4ab18fd874946,reason=Scheduled count=None msg=Successfully assigned compute/eval-sanitize-30-r0-180-psgwh to kind-worker5
0.2732,Event,ADDED,eval-sanitize-30-r0-180-psgwh.18d4ab191d63fd59,"reason=Pulled count=1 msg=Container image ""busybox:musl"" already present on machine"
0.2733,Event,ADDED,eval-sanitize-30-r0-180-psgwh.18d4ab191f0702dd,reason=Created count=1 msg=Created container: task
0.2735,Event,ADDED,eval-sanitize-30-r0-180-psgwh.18d4ab1923c03ace,reason=Started count=1 msg=Started container task
0.2737,Event,ADDED,eval-sanitize-30-r0-180.18d4ab18f83c2389,reason=SuccessfulCreate count=1 msg=Created pod: eval-sanitize-30-r0-180-psgwh
0.2738,Event,ADDED,eval-sanitize-30-r0-180.18d4ab1ebb6bbea6,reason=Completed count=1 msg=Job completed
0.274,Event,ADDED,eval-sanitize-30-r0-181-bhg77.18d4ab1931fa7230,reason=Scheduled count=None msg=Successfully assigned compute/eval-sanitize-30-r0-181-bhg77 to kind-worker
0.2742,Event,ADDED,eval-sanitize-30-r0-181-bhg77.18d4ab195506febb,"reason=Pulled count=1 msg=Container image ""busybox:musl"" already present on machine"
0.2743,Event,ADDED,eval-sanitize-30-r0-181-bhg77.18d4ab19570d160d,reason=Created count=1 msg=Created container: task
0.2745,Event,ADDED,eval-sanitize-30-r0-181-bhg77.18d4ab195b73a5e8,reason=Started count=1 msg=Started container task
0.2747,Event,ADDED,eval-sanitize-30-r0-181.18d4ab192b7b9004,reason=SuccessfulCreate count=1 msg=Created pod: eval-sanitize-30-r0-181-bhg77
0.2752,Event,ADDED,eval-sanitize-30-r0-181.18d4ab1ee25dfc69,reason=Completed count=1 msg=Job completed
0.2754,Event,ADDED,eval-sanitize-30-r0-182-rp6hh.18d4ab19731cbdfd,"reason=FailedScheduling count=None msg=0/6 nodes are available: 1 c_wall violated: 3 conflicting context pair(s) with node memory, 2 node(s) had untolerated taint(s), 3 c_wall violated: 1 conflicting context pair(s) with node memory. no new claims to deallocate, preemption: 0/6 nodes are available: 2 Preemption is not helpful for scheduling, 4 No preemption victims found for incoming pod."
0.2757,Event,ADDED,eval-sanitize-30-r0-182-rp6hh.18d4ab1980a30280,"reason=FailedScheduling count=None msg=0/6 nodes are available: 1 c_wall violated: 3 conflicting context pair(s) with node memory, 2 node(s) had untolerated taint(s), 3 c_wall violated: 1 conflicting context pair(s) with node memory. no new claims to deallocate, preemption: 0/6 nodes are available: 2 Preemption is not helpful for scheduling, 4 No preemption victims found for incoming pod."
0.2761,Event,ADDED,eval-sanitize-30-r0-182-rp6hh.18d4ab1b4a602a88,reason=Scheduled count=None msg=Successfully assigned compute/eval-sanitize-30-r0-182-rp6hh to kind-worker2
0.2764,Event,ADDED,eval-sanitize-30-r0-182-rp6hh.18d4ab1b6b02ba09,"reason=Pulled count=1 msg=Container image ""busybox:musl"" already present on machine"
0.2766,Event,ADDED,eval-sanitize-30-r0-182-rp6hh.18d4ab1b6c83fc36,reason=Created count=1 msg=Created container: task
0.2769,Event,ADDED,eval-sanitize-30-r0-182-rp6hh.18d4ab1b71afbbed,reason=Started count=1 msg=Started container task
0.2773,Event,ADDED,eval-sanitize-30-r0-182.18d4ab1967592a99,reason=SuccessfulCreate count=1 msg=Created pod: eval-sanitize-30-r0-182-rp6hh
0.2775,Event,ADDED,eval-sanitize-30-r0-182.18d4ab20c6fb53ea,reason=Completed count=1 msg=Job completed
0.2777,Event,ADDED,eval-sanitize-30-r0-183-h8m2m.18d4ab19aec1674a,"reason=FailedScheduling count=None msg=0/6 nodes are available: 1 c_wall violated: 3 conflicting context pair(s) with node memory, 2 node(s) had untolerated taint(s), 3 c_wall violated: 1 conflicting context pair(s) with node memory. no new claims to deallocate, preemption: 0/6 nodes are available: 2 Preemption is not helpful for scheduling, 4 No preemption victims found for incoming pod."
0.2781,Event,ADDED,eval-sanitize-30-r0-183-h8m2m.18d4ab19d9977a06,"reason=FailedScheduling count=None msg=0/6 nodes are available: 1 c_wall violated: 3 conflicting context pair(s) with node memory, 2 node(s) had untolerated taint(s), 3 c_wall violated: 1 conflicting context pair(s) with node memory. no new claims to deallocate, preemption: 0/6 nodes are available: 2 Preemption is not helpful for scheduling, 4 No preemption victims found for incoming pod."
0.2783,Event,ADDED,eval-sanitize-30-r0-183-h8m2m.18d4ab1b628f53ee,reason=Scheduled count=None msg=Successfully assigned compute/eval-sanitize-30-r0-183-h8m2m to kind-worker2
0.2787,Event,ADDED,eval-sanitize-30-r0-183-h8m2m.18d4ab1b808d10eb,"reason=Pulled count=1 msg=Container image ""busybox:musl"" already present on machine"
0.2788,Event,ADDED,eval-sanitize-30-r0-183-h8m2m.18d4ab1b81d34e0b,reason=Created count=1 msg=Created container: task
0.2793,Event,ADDED,eval-sanitize-30-r0-183-h8m2m.18d4ab1b871d1508,reason=Started count=1 msg=Started container task
0.2795,Event,ADDED,eval-sanitize-30-r0-183.18d4ab19a2b687b8,reason=SuccessfulCreate count=1 msg=Created pod: eval-sanitize-30-r0-183-h8m2m
0.2796,Event,ADDED,eval-sanitize-30-r0-183.18d4ab20c7f542b9,reason=Completed count=1 msg=Job completed
0.28,Event,ADDED,eval-sanitize-30-r0-184-c8w8n.18d4ab19e63fbaee,reason=Scheduled count=None msg=Successfully assigned compute/eval-sanitize-30-r0-184-c8w8n to kind-worker5
0.2802,Event,ADDED,eval-sanitize-30-r0-184-c8w8n.18d4ab1a010cc130,"reason=Pulled count=1 msg=Container image ""busybox:musl"" already present on machine"
0.2804,Event,ADDED,eval-sanitize-30-r0-184-c8w8n.18d4ab1a024d2c01,reason=Created count=1 msg=Created container: task
0.2806,Event,ADDED,eval-sanitize-30-r0-184-c8w8n.18d4ab1a0f683709,reason=Started count=1 msg=Started container task
0.2808,Event,ADDED,eval-sanitize-30-r0-184.18d4ab19df386e49,reason=SuccessfulCreate count=1 msg=Created pod: eval-sanitize-30-r0-184-c8w8n
0.281,Event,ADDED,eval-sanitize-30-r0-184.18d4ab1fa911d075,reason=Completed count=1 msg=Job completed
0.2811,Event,ADDED,eval-sanitize-30-r0-185-5g6nx.18d4ab1a26e1775b,"reason=FailedScheduling count=None msg=0/6 nodes are available: 1 c_wall violated: 3 conflicting context pair(s) with node memory, 2 node(s) had untolerated taint(s), 3 c_wall violated: 1 conflicting context pair(s) with node memory. no new claims to deallocate, preemption: 0/6 nodes are available: 2 Preemption is not helpful for scheduling, 4 No preemption victims found for incoming pod."
0.2814,Event,ADDED,eval-sanitize-30-r0-185-5g6nx.18d4ab1a511d99eb,"reason=FailedScheduling count=None msg=0/6 nodes are available: 1 c_wall violated: 3 conflicting context pair(s) with node memory, 2 node(s) had untolerated taint(s), 3 c_wall violated: 1 conflicting context pair(s) with node memory. no new claims to deallocate, preemption: 0/6 nodes are available: 2 Preemption is not helpful for scheduling, 4 No preemption victims found for incoming pod."
0.2815,Event,ADDED,eval-sanitize-30-r0-185-5g6nx.18d4ab1b5187cc04,reason=Scheduled count=None msg=Successfully assigned compute/eval-sanitize-30-r0-185-5g6nx to kind-worker2
0.2817,Event,ADDED,eval-sanitize-30-r0-185-5g6nx.18d4ab1b6be99372,"reason=Pulled count=1 msg=Container image ""busybox:musl"" already present on machine"
0.2818,Event,ADDED,eval-sanitize-30-r0-185-5g6nx.18d4ab1b6dce3ebe,reason=Created count=1 msg=Created container: task
0.2821,Event,ADDED,eval-sanitize-30-r0-185-5g6nx.18d4ab1b722fb047,reason=Started count=1 msg=Started container task
0.2822,Event,ADDED,eval-sanitize-30-r0-185.18d4ab1a19a5bb50,reason=SuccessfulCreate count=1 msg=Created pod: eval-sanitize-30-r0-185-5g6nx
0.2824,Event,ADDED,eval-sanitize-30-r0-185.18d4ab20c8c5f746,reason=Completed count=1 msg=Job completed
0.2826,Event,ADDED,eval-sanitize-30-r0-186-p42w6.18d4ab1a693cca76,reason=Scheduled count=None msg=Successfully assigned compute/eval-sanitize-30-r0-186-p42w6 to kind-worker5
0.2827,Event,ADDED,eval-sanitize-30-r0-186-p42w6.18d4ab1a83fb7232,"reason=Pulled count=1 msg=Container image ""busybox:musl"" already present on machine"
0.2829,Event,ADDED,eval-sanitize-30-r0-186-p42w6.18d4ab1a855688dc,reason=Created count=1 msg=Created container: task
0.2831,Event,ADDED,eval-sanitize-30-r0-186-p42w6.18d4ab1a892f1080,reason=Started count=1 msg=Started container task
0.2833,Event,ADDED,eval-sanitize-30-r0-186.18d4ab1a5cf282be,reason=SuccessfulCreate count=1 msg=Created pod: eval-sanitize-30-r0-186-p42w6
0.2835,Event,ADDED,eval-sanitize-30-r0-186.18d4ab2020a31220,reason=Completed count=1 msg=Job completed
0.2837,Event,ADDED,eval-sanitize-30-r0-187-vqpc7.18d4ab1adaea76d5,reason=Scheduled count=None msg=Successfully assigned compute/eval-sanitize-30-r0-187-vqpc7 to kind-worker3
0.2839,Event,ADDED,eval-sanitize-30-r0-187-vqpc7.18d4ab1af9d06772,"reason=Pulled count=1 msg=Container image ""busybox:musl"" already present on machine"
0.2841,Event,ADDED,eval-sanitize-30-r0-187-vqpc7.18d4ab1afb3cef08,reason=Created count=1 msg=Created container: task
0.2843,Event,ADDED,eval-sanitize-30-r0-187-vqpc7.18d4ab1aff5746af,reason=Started count=1 msg=Started container task
0.2844,Event,ADDED,eval-sanitize-30-r0-187.18d4ab1ad398b47a,reason=SuccessfulCreate count=1 msg=Created pod: eval-sanitize-30-r0-187-vqpc7
0.2846,Event,ADDED,eval-sanitize-30-r0-187.18d4ab208d9742c0,reason=Completed count=1 msg=Job completed
0.2847,Event,ADDED,eval-sanitize-30-r0-188-mg9l5.18d4ab1b09d9ec71,"reason=FailedScheduling count=None msg=0/6 nodes are available: 1 c_wall violated: 1 conflicting context pair(s) with node memory, 1 c_wall violated: 2 conflicting context pair(s) with node memory, 2 c_wall violated: 3 conflicting context pair(s) with node memory, 2 node(s) had untolerated taint(s). no new claims to deallocate, preemption: 0/6 nodes are available: 2 Preemption is not helpful for scheduling, 4 No preemption victims found for incoming pod."
0.2849,Event,ADDED,eval-sanitize-30-r0-188-mg9l5.18d4ab1b39b06ca9,reason=Scheduled count=None msg=Successfully assigned compute/eval-sanitize-30-r0-188-mg9l5 to kind-worker2
0.285,Event,ADDED,eval-sanitize-30-r0-188-mg9l5.18d4ab1b54ed0dc0,"reason=Pulled count=1 msg=Container image ""busybox:musl"" already present on machine"
0.2852,Event,ADDED,eval-sanitize-30-r0-188-mg9l5.18d4ab1b5717bd25,reason=Created count=1 msg=Created container: task
0.2854,Event,ADDED,eval-sanitize-30-r0-188-mg9l5.18d4ab1b5c76c143,reason=Started count=1 msg=Started container task
0.2855,Event,ADDED,eval-sanitize-30-r0-188.18d4ab1b0040b57b,reason=SuccessfulCreate count=1 msg=Created pod: eval-sanitize-30-r0-188-mg9l5
0.2857,Event,ADDED,eval-sanitize-30-r0-188.18d4ab208a4c741a,reason=Completed count=1 msg=Job completed
0.2859,Event,ADDED,eval-sanitize-30-r0-189-zm8gv.18d4ab1b3ff14fc5,reason=Scheduled count=None msg=Successfully assigned compute/eval-sanitize-30-r0-189-zm8gv to kind-worker2
0.2861,Event,ADDED,eval-sanitize-30-r0-189-zm8gv.18d4ab1b5c81ee97,"reason=Pulled count=1 msg=Container image ""busybox:musl"" already present on machine"
0.2863,Event,ADDED,eval-sanitize-30-r0-189-zm8gv.18d4ab1b5e062f75,reason=Created count=1 msg=Created container: task
0.2864,Event,ADDED,eval-sanitize-30-r0-189-zm8gv.18d4ab1b65172552,reason=Started count=1 msg=Started container task
0.2866,Event,ADDED,eval-sanitize-30-r0-189.18d4ab1b35ddc75f,reason=SuccessfulCreate count=1 msg=Created pod: eval-sanitize-30-r0-189-zm8gv
0.2867,Event,ADDED,eval-sanitize-30-r0-189.18d4ab20c9ffe8ac,reason=Completed count=1 msg=Job completed
0.2869,Event,ADDED,eval-sanitize-30-r0-190-pphsh.18d4ab1b69635a33,reason=Scheduled count=None msg=Successfully assigned compute/eval-sanitize-30-r0-190-pphsh to kind-worker
0.2872,Event,ADDED,eval-sanitize-30-r0-190-pphsh.18d4ab1b86ff4f51,"reason=Pulled count=1 msg=Container image ""busybox:musl"" already present on machine"
0.2873,Event,ADDED,eval-sanitize-30-r0-190-pphsh.18d4ab1b889590d8,reason=Created count=1 msg=Created container: task
0.2875,Event,ADDED,eval-sanitize-30-r0-190-pphsh.18d4ab1b8d366209,reason=Started count=1 msg=Started container task
0.2877,Event,ADDED,eval-sanitize-30-r0-190.18d4ab1b5cc9e6f9,reason=SuccessfulCreate count=1 msg=Created pod: eval-sanitize-30-r0-190-pphsh
0.2878,Event,ADDED,eval-sanitize-30-r0-190.18d4ab20f7f6c93a,reason=Completed count=1 msg=Job completed
0.288,Event,ADDED,eval-sanitize-30-r0-191-vc2dt.18d4ab1b9880736d,reason=Scheduled count=None msg=Successfully assigned compute/eval-sanitize-30-r0-191-vc2dt to kind-worker2
0.2881,Event,ADDED,eval-sanitize-30-r0-191-vc2dt.18d4ab1bb6b1292a,"reason=Pulled count=1 msg=Container image ""busybox:musl"" already present on machine"
0.2883,Event,ADDED,eval-sanitize-30-r0-191-vc2dt.18d4ab1bb81863b8,reason=Created count=1 msg=Created container: task
0.2885,Event,ADDED,eval-sanitize-30-r0-191-vc2dt.18d4ab1bbc27c349,reason=Started count=1 msg=Started container task
0.2886,Event,ADDED,eval-sanitize-30-r0-191.18d4ab1b92748bd1,reason=SuccessfulCreate count=1 msg=Created pod: eval-sanitize-30-r0-191-vc2dt
0.2888,Event,ADDED,eval-sanitize-30-r0-191.18d4ab2141a5c10a,reason=Completed count=1 msg=Job completed
0.289,Event,ADDED,eval-sanitize-30-r0-192-4nnkl.18d4ab1bc2fb1a84,reason=Scheduled count=None msg=Successfully assigned compute/eval-sanitize-30-r0-192-4nnkl to kind-worker3
0.2891,Event,ADDED,eval-sanitize-30-r0-192-4nnkl.18d4ab1bdc8e1059,"reason=Pulled count=1 msg=Container image ""busybox:musl"" already present on machine"
0.2893,Event,ADDED,eval-sanitize-30-r0-192-4nnkl.18d4ab1bde0e2753,reason=Created count=1 msg=Created container: task
0.2895,Event,ADDED,eval-sanitize-30-r0-192-4nnkl.18d4ab1be3960c97,reason=Started count=1 msg=Started container task
0.2896,Event,ADDED,eval-sanitize-30-r0-192.18d4ab1bc1e2933f,reason=SuccessfulCreate count=1 msg=Created pod: eval-sanitize-30-r0-192-4nnkl
0.2898,Event,ADDED,eval-sanitize-30-r0-192.18d4ab217c86ffe3,reason=Completed count=1 msg=Job completed
0.2899,Event,ADDED,eval-sanitize-30-r0-193-8z7rh.18d4ab1bf88776cb,reason=Scheduled count=None msg=Successfully assigned compute/eval-sanitize-30-r0-193-8z7rh to kind-worker3
0.2901,Event,ADDED,eval-sanitize-30-r0-193-8z7rh.18d4ab1c13972b7d,"reason=Pulled count=1 msg=Container image ""busybox:musl"" already present on machine"
0.2903,Event,ADDED,eval-sanitize-30-r0-193-8z7rh.18d4ab1c14dbaf6e,reason=Created count=1 msg=Created container: task
0.2904,Event,ADDED,eval-sanitize-30-r0-193-8z7rh.18d4ab1c19485343,reason=Started count=1 msg=Started container task
0.2906,Event,ADDED,eval-sanitize-30-r0-193.18d4ab1bf796d0b0,reason=SuccessfulCreate count=1 msg=Created pod: eval-sanitize-30-r0-193-8z7rh
0.2908,Event,ADDED,eval-sanitize-30-r0-193.18d4ab21bcec7a2c,reason=Completed count=1 msg=Job completed
0.2909,Event,ADDED,eval-sanitize-30-r0-194-7pqk8.18d4ab1c33f93abc,reason=Scheduled count=None msg=Successfully assigned compute/eval-sanitize-30-r0-194-7pqk8 to kind-worker4
0.2911,Event,ADDED,eval-sanitize-30-r0-194-7pqk8.18d4ab1c54166bde,"reason=Pulled count=1 msg=Container image ""busybox:musl"" already present on machine"
0.2936,Event,ADDED,eval-sanitize-30-r0-194-7pqk8.18d4ab1c55711f22,reason=Created count=1 msg=Created container: task
0.2937,Event,ADDED,eval-sanitize-30-r0-194-7pqk8.18d4ab1c605db3dc,reason=Started count=1 msg=Started container task
0.2939,Event,ADDED,eval-sanitize-30-r0-194.18d4ab1c3310f5d8,reason=SuccessfulCreate count=1 msg=Created pod: eval-sanitize-30-r0-194-7pqk8
0.2941,Event,ADDED,eval-sanitize-30-r0-194.18d4ab21e12dad24,reason=Completed count=1 msg=Job completed
0.2944,Event,ADDED,eval-sanitize-30-r0-195-d5xfz.18d4ab1c6e92b5e4,"reason=FailedScheduling count=None msg=0/6 nodes are available: 2 c_wall violated: 1 conflicting context pair(s) with node memory, 4 node(s) had untolerated taint(s). no new claims to deallocate, preemption: 0/6 nodes are available: 2 No preemption victims found for incoming pod, 4 Preemption is not helpful for scheduling."
0.2946,Event,ADDED,eval-sanitize-30-r0-195-d5xfz.18d4ab1c6f92ca1c,"reason=FailedScheduling count=None msg=0/6 nodes are available: 2 c_wall violated: 1 conflicting context pair(s) with node memory, 4 node(s) had untolerated taint(s). no new claims to deallocate, preemption: 0/6 nodes are available: 2 No preemption victims found for incoming pod, 4 Preemption is not helpful for scheduling."
0.2948,Event,ADDED,eval-sanitize-30-r0-195-d5xfz.18d4ab223215d644,"reason=FailedScheduling count=None msg=0/6 nodes are available: 1 c_wall violated: 1 conflicting context pair(s) with node memory, 5 node(s) had untolerated taint(s). no new claims to deallocate, preemption: 0/6 nodes are available: 1 No preemption victims found for incoming pod, 5 Preemption is not helpful for scheduling."
0.295,Event,ADDED,eval-sanitize-30-r0-195-d5xfz.18d4ab2241e36ddc,reason=Scheduled count=None msg=Successfully assigned compute/eval-sanitize-30-r0-195-d5xfz to kind-worker2
0.2952,Event,ADDED,eval-sanitize-30-r0-195-d5xfz.18d4ab2262ffe79d,"reason=Pulled count=1 msg=Container image ""busybox:musl"" already present on machine"
0.2954,Event,ADDED,eval-sanitize-30-r0-195-d5xfz.18d4ab2264bcf495,reason=Created count=1 msg=Created container: task
0.2955,Event,ADDED,eval-sanitize-30-r0-195-d5xfz.18d4ab226ca0003a,reason=Started count=1 msg=Started container task
0.2957,Event,ADDED,eval-sanitize-30-r0-195.18d4ab1c6df1a277,reason=SuccessfulCreate count=1 msg=Created pod: eval-sanitize-30-r0-195-d5xfz
0.2959,Event,ADDED,eval-sanitize-30-r0-195.18d4ab2801b71de8,reason=Completed count=1 msg=Job completed
0.296,Event,ADDED,eval-sanitize-30-r0-196-bkpgn.18d4ab1cad36988a,reason=Scheduled count=None msg=Successfully assigned compute/eval-sanitize-30-r0-196-bkpgn to kind-worker4
0.2962,Event,ADDED,eval-sanitize-30-r0-196-bkpgn.18d4ab1cca7884e6,"reason=Pulled count=1 msg=Container image ""busybox:musl"" already present on machine"
0.2964,Event,ADDED,eval-sanitize-30-r0-196-bkpgn.18d4ab1ccc3c7888,reason=Created count=1 msg=Created container: task
0.2965,Event,ADDED,eval-sanitize-30-r0-196-bkpgn.18d4ab1cd0c37a5c,reason=Started count=1 msg=Started container task
0.2967,Event,ADDED,eval-sanitize-30-r0-196.18d4ab1cac5345d6,reason=SuccessfulCreate count=1 msg=Created pod: eval-sanitize-30-r0-196-bkpgn
0.2969,Event,ADDED,eval-sanitize-30-r0-196.18d4ab2259de69e1,reason=Completed count=1 msg=Job completed
0.297,Event,ADDED,eval-sanitize-30-r0-197-d84tq.18d4ab1ce5ad3080,reason=Scheduled count=None msg=Successfully assigned compute/eval-sanitize-30-r0-197-d84tq to kind-worker4
0.2972,Event,ADDED,eval-sanitize-30-r0-197-d84tq.18d4ab1d00c7befa,"reason=Pulled count=1 msg=Container image ""busybox:musl"" already present on machine"
0.2974,Event,ADDED,eval-sanitize-30-r0-197-d84tq.18d4ab1d0238cdc5,reason=Created count=1 msg=Created container: task
0.2975,Event,ADDED,eval-sanitize-30-r0-197-d84tq.18d4ab1d0804ab87,reason=Started count=1 msg=Started container task
0.2977,Event,ADDED,eval-sanitize-30-r0-197.18d4ab1ce4a612b3,reason=SuccessfulCreate count=1 msg=Created pod: eval-sanitize-30-r0-197-d84tq
0.2979,Event,ADDED,eval-sanitize-30-r0-197.18d4ab2297d23d45,reason=Completed count=1 msg=Job completed
0.298,Event,ADDED,eval-sanitize-30-r0-198-wrhv5.18d4ab1d235f7345,"reason=FailedScheduling count=None msg=0/6 nodes are available: 2 c_wall violated: 1 conflicting context pair(s) with node memory, 4 node(s) had untolerated taint(s). no new claims to deallocate, preemption: 0/6 nodes are available: 2 No preemption victims found for incoming pod, 4 Preemption is not helpful for scheduling."
0.2982,Event,ADDED,eval-sanitize-30-r0-198-wrhv5.18d4ab1d24494101,"reason=FailedScheduling count=None msg=0/6 nodes are available: 2 c_wall violated: 1 conflicting context pair(s) with node memory, 4 node(s) had untolerated taint(s). no new claims to deallocate, preemption: 0/6 nodes are available: 2 No preemption victims found for incoming pod, 4 Preemption is not helpful for scheduling."
0.2984,Event,ADDED,eval-sanitize-30-r0-198-wrhv5.18d4ab22323a4565,"reason=FailedScheduling count=None msg=0/6 nodes are available: 1 c_wall violated: 1 conflicting context pair(s) with node memory, 5 node(s) had untolerated taint(s). no new claims to deallocate, preemption: 0/6 nodes are available: 1 No preemption victims found for incoming pod, 5 Preemption is not helpful for scheduling."
0.2985,Event,ADDED,eval-sanitize-30-r0-198-wrhv5.18d4ab224261ddc4,reason=Scheduled count=None msg=Successfully assigned compute/eval-sanitize-30-r0-198-wrhv5 to kind-worker2
0.2987,Event,ADDED,eval-sanitize-30-r0-198-wrhv5.18d4ab2262e138ac,"reason=Pulled count=1 msg=Container image ""busybox:musl"" already present on machine"
0.2989,Event,ADDED,eval-sanitize-30-r0-198-wrhv5.18d4ab2264828309,reason=Created count=1 msg=Created container: task
0.299,Event,ADDED,eval-sanitize-30-r0-198-wrhv5.18d4ab226ca00062,reason=Started count=1 msg=Started container task
0.2997,Event,ADDED,eval-sanitize-30-r0-198.18d4ab1d22d70a24,reason=SuccessfulCreate count=1 msg=Created pod: eval-sanitize-30-r0-198-wrhv5
0.2998,Event,ADDED,eval-sanitize-30-r0-198.18d4ab2801dd8acc,reason=Completed count=1 msg=Job completed
0.3,Event,ADDED,eval-sanitize-30-r0-199-dqnvc.18d4ab1d67798b49,reason=Scheduled count=None msg=Successfully assigned compute/eval-sanitize-30-r0-199-dqnvc to kind-worker4
0.3003,Event,ADDED,eval-sanitize-30-r0-199-dqnvc.18d4ab1d8650ea61,"reason=Pulled count=1 msg=Container image ""busybox:musl"" already present on machine"
0.3005,Event,ADDED,eval-sanitize-30-r0-199-dqnvc.18d4ab1d87c17f29,reason=Created count=1 msg=Created container: task
0.3006,Event,ADDED,eval-sanitize-30-r0-199-dqnvc.18d4ab1d90cceea3,reason=Started count=1 msg=Started container task
0.3008,Event,ADDED,eval-sanitize-30-r0-199.18d4ab1d5f893001,reason=SuccessfulCreate count=1 msg=Created pod: eval-sanitize-30-r0-199-dqnvc
0.3016,Event,ADDED,eval-sanitize-30-r0-199.18d4ab230f6a9066,reason=Completed count=1 msg=Job completed
0.3017,Event,ADDED,eval-sanitize-30-r1-000-dnc76.18d4ab33c67ac632,reason=Scheduled count=None msg=Successfully assigned compute/eval-sanitize-30-r1-000-dnc76 to kind-worker3
0.3019,Event,ADDED,eval-sanitize-30-r1-000-dnc76.18d4ab33e2e96679,"reason=Pulled count=1 msg=Container image ""busybox:musl"" already present on machine"
0.3021,Event,ADDED,eval-sanitize-30-r1-000-dnc76.18d4ab33e4164e10,reason=Created count=1 msg=Created container: task
0.3024,Event,ADDED,eval-sanitize-30-r1-000-dnc76.18d4ab33e957bc7f,reason=Started count=1 msg=Started container task
0.3026,Event,ADDED,eval-sanitize-30-r1-000.18d4ab33c57ed02f,reason=SuccessfulCreate count=1 msg=Created pod: eval-sanitize-30-r1-000-dnc76
0.3028,Event,ADDED,eval-sanitize-30-r1-000.18d4ab3993b3a84e,reason=Completed count=1 msg=Job completed
0.3029,Event,ADDED,eval-sanitize-30-r1-001-2htsw.18d4ab33fe728d0d,reason=Scheduled count=None msg=Successfully assigned compute/eval-sanitize-30-r1-001-2htsw to kind-worker5
0.3032,Event,ADDED,eval-sanitize-30-r1-001-2htsw.18d4ab341e6312ad,"reason=Pulled count=1 msg=Container image ""busybox:musl"" already present on machine"
0.3034,Event,ADDED,eval-sanitize-30-r1-001-2htsw.18d4ab341f9e2ea3,reason=Created count=1 msg=Created container: task
0.3036,Event,ADDED,eval-sanitize-30-r1-001-2htsw.18d4ab342465409e,reason=Started count=1 msg=Started container task
0.3038,Event,ADDED,eval-sanitize-30-r1-001.18d4ab33fd4ebf19,reason=SuccessfulCreate count=1 msg=Created pod: eval-sanitize-30-r1-001-2htsw
0.3041,Event,ADDED,eval-sanitize-30-r1-001.18d4ab3993f10984,reason=Completed count=1 msg=Job completed
0.3042,Event,ADDED,eval-sanitize-30-r1-002-2zmsc.18d4ab343a52ab32,reason=Scheduled count=None msg=Successfully assigned compute/eval-sanitize-30-r1-002-2zmsc to kind-worker
0.3044,Event,ADDED,eval-sanitize-30-r1-002-2zmsc.18d4ab3460492d3f,"reason=Pulled count=1 msg=Container image ""busybox:musl"" already present on machine"
0.3047,Event,ADDED,eval-sanitize-30-r1-002-2zmsc.18d4ab346195603b,reason=Created count=1 msg=Created container: task
0.3049,Event,ADDED,eval-sanitize-30-r1-002-2zmsc.18d4ab346c4a1cdd,reason=Started count=1 msg=Started container task
0.3051,Event,ADDED,eval-sanitize-30-r1-002.18d4ab34392a9544,reason=SuccessfulCreate count=1 msg=Created pod: eval-sanitize-30-r1-002-2zmsc
0.3052,Event,ADDED,eval-sanitize-30-r1-002.18d4ab39f912aff2,reason=Completed count=1 msg=Job completed
0.3054,Event,ADDED,eval-sanitize-30-r1-003-n4gk7.18d4ab347b1b03d8,reason=Scheduled count=None msg=Successfully assigned compute/eval-sanitize-30-r1-003-n4gk7 to kind-worker3
0.3056,Event,ADDED,eval-sanitize-30-r1-003-n4gk7.18d4ab34a05d43e6,"reason=Pulled count=1 msg=Container image ""busybox:musl"" already present on machine"
0.3058,Event,ADDED,eval-sanitize-30-r1-003-n4gk7.18d4ab34a1723fd4,reason=Created count=1 msg=Created container: task
0.306,Event,ADDED,eval-sanitize-30-r1-003-n4gk7.18d4ab34a5301292,reason=Started count=1 msg=Started container task
0.3061,Event,ADDED,eval-sanitize-30-r1-003.18d4ab3479d4f211,reason=SuccessfulCreate count=1 msg=Created pod: eval-sanitize-30-r1-003-n4gk7
0.3063,Event,ADDED,eval-sanitize-30-r1-003.18d4ab3a3cdab16d,reason=Completed count=1 msg=Job completed
0.3064,Event,ADDED,eval-sanitize-30-r1-004-lwnv2.18d4ab34b17fa15c,reason=Scheduled count=None msg=Successfully assigned compute/eval-sanitize-30-r1-004-lwnv2 to kind-worker5
0.3067,Event,ADDED,eval-sanitize-30-r1-004-lwnv2.18d4ab34cf3abd3e,"reason=Pulled count=1 msg=Container image ""busybox:musl"" already present on machine"
0.3069,Event,ADDED,eval-sanitize-30-r1-004-lwnv2.18d4ab34d056861b,reason=Created count=1 msg=Created container: task
0.3071,Event,ADDED,eval-sanitize-30-r1-004-lwnv2.18d4ab34d47d9762,reason=Started count=1 msg=Started container task
0.3073,Event,ADDED,eval-sanitize-30-r1-004.18d4ab34b0515cb5,reason=SuccessfulCreate count=1 msg=Created pod: eval-sanitize-30-r1-004-lwnv2
0.3074,Event,ADDED,eval-sanitize-30-r1-004.18d4ab3a4aa7b695,reason=Completed count=1 msg=Job completed
0.3076,Event,ADDED,eval-sanitize-30-r1-005-fsf65.18d4ab34ef4c9dc8,reason=Scheduled count=None msg=Successfully assigned compute/eval-sanitize-30-r1-005-fsf65 to kind-worker
0.3077,Event,ADDED,eval-sanitize-30-r1-005-fsf65.18d4ab350e4a9d2d,"reason=Pulled count=1 msg=Container image ""busybox:musl"" already present on machine"
0.3079,Event,ADDED,eval-sanitize-30-r1-005-fsf65.18d4ab350f955a79,reason=Created count=1 msg=Created container: task
0.3081,Event,ADDED,eval-sanitize-30-r1-005-fsf65.18d4ab35144bdcf3,reason=Started count=1 msg=Started container task
0.3082,Event,ADDED,eval-sanitize-30-r1-005.18d4ab34ee212369,reason=SuccessfulCreate count=1 msg=Created pod: eval-sanitize-30-r1-005-fsf65
0.3084,Event,ADDED,eval-sanitize-30-r1-005.18d4ab3aaaf7065d,reason=Completed count=1 msg=Job completed
0.3085,Event,ADDED,eval-sanitize-30-r1-006-fcltv.18d4ab35297e4acb,reason=Scheduled count=None msg=Successfully assigned compute/eval-sanitize-30-r1-006-fcltv to kind-worker5
0.3087,Event,ADDED,eval-sanitize-30-r1-006-fcltv.18d4ab35446f7941,"reason=Pulled count=1 msg=Container image ""busybox:musl"" already present on machine"
0.3089,Event,ADDED,eval-sanitize-30-r1-006-fcltv.18d4ab35459769c8,reason=Created count=1 msg=Created container: task
0.3091,Event,ADDED,eval-sanitize-30-r1-006-fcltv.18d4ab354b68baf3,reason=Started count=1 msg=Started container task
0.3092,Event,ADDED,eval-sanitize-30-r1-006.18d4ab3528523151,reason=SuccessfulCreate count=1 msg=Created pod: eval-sanitize-30-r1-006-fcltv
0.3094,Event,ADDED,eval-sanitize-30-r1-006.18d4ab3ac921b442,reason=Completed count=1 msg=Job completed
0.3095,Event,ADDED,eval-sanitize-30-r1-007-8qz95.18d4ab356337d466,reason=Scheduled count=None msg=Successfully assigned compute/eval-sanitize-30-r1-007-8qz95 to kind-worker2
0.3097,Event,ADDED,eval-sanitize-30-r1-007-8qz95.18d4ab357c459467,"reason=Pulled count=1 msg=Container image ""busybox:musl"" already present on machine"
0.3099,Event,ADDED,eval-sanitize-30-r1-007-8qz95.18d4ab357d5a26dc,reason=Created count=1 msg=Created container: task
0.31,Event,ADDED,eval-sanitize-30-r1-007-8qz95.18d4ab357f548fc0,reason=Started count=1 msg=Started container task
0.3102,Event,ADDED,eval-sanitize-30-r1-007.18d4ab35621a1022,reason=SuccessfulCreate count=1 msg=Created pod: eval-sanitize-30-r1-007-8qz95
0.3107,Event,ADDED,eval-sanitize-30-r1-007.18d4ab3ae96c7ca8,reason=Completed count=1 msg=Job completed
0.3109,Event,ADDED,eval-sanitize-30-r1-008-btbsz.18d4ab35a08eb243,reason=Scheduled count=None msg=Successfully assigned compute/eval-sanitize-30-r1-008-btbsz to kind-worker4
0.3111,Event,ADDED,eval-sanitize-30-r1-008-btbsz.18d4ab35bdd8ecd5,"reason=Pulled count=1 msg=Container image ""busybox:musl"" already present on machine"
0.3114,Event,ADDED,eval-sanitize-30-r1-008-btbsz.18d4ab35beeb12e9,reason=Created count=1 msg=Created container: task
0.3116,Event,ADDED,eval-sanitize-30-r1-008-btbsz.18d4ab35c494e066,reason=Started count=1 msg=Started container task
0.3118,Event,ADDED,eval-sanitize-30-r1-008.18d4ab359f525256,reason=SuccessfulCreate count=1 msg=Created pod: eval-sanitize-30-r1-008-btbsz
0.312,Event,ADDED,eval-sanitize-30-r1-008.18d4ab3b4ebb4285,reason=Completed count=1 msg=Job completed
0.3123,Event,ADDED,eval-sanitize-30-r1-009-p5sdg.18d4ab35e1e38db1,reason=Scheduled count=None msg=Successfully assigned compute/eval-sanitize-30-r1-009-p5sdg to kind-worker
0.3125,Event,ADDED,eval-sanitize-30-r1-009-p5sdg.18d4ab35fd87ba9b,"reason=Pulled count=1 msg=Container image ""busybox:musl"" already present on machine"
0.3126,Event,ADDED,eval-sanitize-30-r1-009-p5sdg.18d4ab35fea3901d,reason=Created count=1 msg=Created container: task
0.3128,Event,ADDED,eval-sanitize-30-r1-009-p5sdg.18d4ab3603aebcf8,reason=Started count=1 msg=Started container task
0.313,Event,ADDED,eval-sanitize-30-r1-009.18d4ab35da017465,reason=SuccessfulCreate count=1 msg=Created pod: eval-sanitize-30-r1-009-p5sdg
0.3132,Event,ADDED,eval-sanitize-30-r1-009.18d4ab3b9a533d0f,reason=Completed count=1 msg=Job completed
0.3133,Event,ADDED,eval-sanitize-30-r1-010-df89d.18d4ab361774293f,reason=Scheduled count=None msg=Successfully assigned compute/eval-sanitize-30-r1-010-df89d to kind-worker4
0.3135,Event,ADDED,eval-sanitize-30-r1-010-df89d.18d4ab3630664eec,"reason=Pulled count=1 msg=Container image ""busybox:musl"" already present on machine"
0.3137,Event,ADDED,eval-sanitize-30-r1-010-df89d.18d4ab363173f042,reason=Created count=1 msg=Created container: task
0.3138,Event,ADDED,eval-sanitize-30-r1-010-df89d.18d4ab3637609afb,reason=Started count=1 msg=Started container task
0.314,Event,ADDED,eval-sanitize-30-r1-010.18d4ab36155fca5b,reason=SuccessfulCreate count=1 msg=Created pod: eval-sanitize-30-r1-010-df89d
0.3142,Event,ADDED,eval-sanitize-30-r1-010.18d4ab3bc6d11417,reason=Completed count=1 msg=Job completed
0.3143,Event,ADDED,eval-sanitize-30-r1-011-t7r4v.18d4ab3658619dd3,reason=Scheduled count=None msg=Successfully assigned compute/eval-sanitize-30-r1-011-t7r4v to kind-worker2
0.3145,Event,ADDED,eval-sanitize-30-r1-011-t7r4v.18d4ab3674d39521,"reason=Pulled count=1 msg=Container image ""busybox:musl"" already present on machine"
0.3147,Event,ADDED,eval-sanitize-30-r1-011-t7r4v.18d4ab36763344c9,reason=Created count=1 msg=Created container: task
0.3148,Event,ADDED,eval-sanitize-30-r1-011-t7r4v.18d4ab367c9b1ffc,reason=Started count=1 msg=Started container task
0.315,Event,ADDED,eval-sanitize-30-r1-011.18d4ab36513ebee8,reason=SuccessfulCreate count=1 msg=Created pod: eval-sanitize-30-r1-011-t7r4v
0.3152,Event,ADDED,eval-sanitize-30-r1-011.18d4ab3c16a003ab,reason=Completed count=1 msg=Job completed
0.3153,Event,ADDED,eval-sanitize-30-r1-012-5w922.18d4ab36942d9be7,reason=Scheduled count=None msg=Successfully assigned compute/eval-sanitize-30-r1-012-5w922 to kind-worker
0.3155,Event,ADDED,eval-sanitize-30-r1-012-5w922.18d4ab36ada60c27,"reason=Pulled count=1 msg=Container image ""busybox:musl"" already present on machine"
0.3157,Event,ADDED,eval-sanitize-30-r1-012-5w922.18d4ab36aed49de2,reason=Created count=1 msg=Created container: task
0.3158,Event,ADDED,eval-sanitize-30-r1-012-5w922.18d4ab36b11456e1,reason=Started count=1 msg=Started container task
0.316,Event,ADDED,eval-sanitize-30-r1-012.18d4ab368dd07326,reason=SuccessfulCreate count=1 msg=Created pod: eval-sanitize-30-r1-012-5w922
0.3162,Event,ADDED,eval-sanitize-30-r1-012.18d4ab3c48fb93d7,reason=Completed count=1 msg=Job completed
0.3163,Event,ADDED,eval-sanitize-30-r1-013-k456x.18d4ab36d42ef32c,reason=Scheduled count=None msg=Successfully assigned compute/eval-sanitize-30-r1-013-k456x to kind-worker
0.3165,Event,ADDED,eval-sanitize-30-r1-013-k456x.18d4ab36ee34fc98,"reason=Pulled count=1 msg=Container image ""busybox:musl"" already present on machine"
0.3167,Event,ADDED,eval-sanitize-30-r1-013-k456x.18d4ab36ef59ccdb,reason=Created count=1 msg=Created container: task
0.3168,Event,ADDED,eval-sanitize-30-r1-013-k456x.18d4ab36f2b05c42,reason=Started count=1 msg=Started container task
0.317,Event,ADDED,eval-sanitize-30-r1-013.18d4ab36c9a64cde,reason=SuccessfulCreate count=1 msg=Created pod: eval-sanitize-30-r1-013-k456x
0.3171,Event,ADDED,eval-sanitize-30-r1-013.18d4ab3c84d007e6,reason=Completed count=1 msg=Job completed
0.3173,Event,ADDED,eval-sanitize-30-r1-014-82bks.18d4ab370c651005,reason=Scheduled count=None msg=Successfully assigned compute/eval-sanitize-30-r1-014-82bks to kind-worker4
0.3175,Event,ADDED,eval-sanitize-30-r1-014-82bks.18d4ab3727168c44,"reason=Pulled count=1 msg=Container image ""busybox:musl"" already present on machine"
0.3177,Event,ADDED,eval-sanitize-30-r1-014-82bks.18d4ab372869c3b7,reason=Created count=1 msg=Created container: task
0.3179,Event,ADDED,eval-sanitize-30-r1-014-82bks.18d4ab372ce7647d,reason=Started count=1 msg=Started container task
0.318,Event,ADDED,eval-sanitize-30-r1-014.18d4ab3704bd714f,reason=SuccessfulCreate count=1 msg=Created pod: eval-sanitize-30-r1-014-82bks
0.3182,Event,ADDED,eval-sanitize-30-r1-014.18d4ab3cbb150a31,reason=Completed count=1 msg=Job completed
0.3183,Event,ADDED,eval-sanitize-30-r1-015-jzdpg.18d4ab3741dfadf2,reason=Scheduled count=None msg=Successfully assigned compute/eval-sanitize-30-r1-015-jzdpg to kind-worker5
0.3185,Event,ADDED,eval-sanitize-30-r1-015-jzdpg.18d4ab375b614b9c,"reason=Pulled count=1 msg=Container image ""busybox:musl"" already present on machine"
0.3187,Event,ADDED,eval-sanitize-30-r1-015-jzdpg.18d4ab375c943cc0,reason=Created count=1 msg=Created container: task
0.3189,Event,ADDED,eval-sanitize-30-r1-015-jzdpg.18d4ab3765203811,reason=Started count=1 msg=Started container task
0.3196,Event,ADDED,eval-sanitize-30-r1-015.18d4ab373f397063,reason=SuccessfulCreate count=1 msg=Created pod: eval-sanitize-30-r1-015-jzdpg
0.3199,Event,ADDED,eval-sanitize-30-r1-015.18d4ab3c9e800bdd,reason=Completed count=1 msg=Job completed
0.3201,Event,ADDED,eval-sanitize-30-r1-016-wgknr.18d4ab377d30916d,reason=Scheduled count=None msg=Successfully assigned compute/eval-sanitize-30-r1-016-wgknr to kind-worker3
0.3203,Event,ADDED,eval-sanitize-30-r1-016-wgknr.18d4ab3797c3df16,"reason=Pulled count=1 msg=Container image ""busybox:musl"" already present on machine"
0.3207,Event,ADDED,eval-sanitize-30-r1-016-wgknr.18d4ab3798f20801,reason=Created count=1 msg=Created container: task
0.3208,Event,ADDED,eval-sanitize-30-r1-016-wgknr.18d4ab37a08b5f5a,reason=Started count=1 msg=Started container task
0.321,Event,ADDED,eval-sanitize-30-r1-016.18d4ab377af1b6aa,reason=SuccessfulCreate count=1 msg=Created pod: eval-sanitize-30-r1-016-wgknr
0.3212,Event,ADDED,eval-sanitize-30-r1-016.18d4ab3d09b4f905,reason=Completed count=1 msg=Job completed
0.3214,Event,ADDED,eval-sanitize-30-r1-017-vd92d.18d4ab37b7c4004a,reason=Scheduled count=None msg=Successfully assigned compute/eval-sanitize-30-r1-017-vd92d to kind-worker
0.3216,Event,ADDED,eval-sanitize-30-r1-017-vd92d.18d4ab37d312c4c8,"reason=Pulled count=1 msg=Container image ""busybox:musl"" already present on machine"
0.3218,Event,ADDED,eval-sanitize-30-r1-017-vd92d.18d4ab37d43706e9,reason=Created count=1 msg=Created container: task
0.3224,Event,ADDED,eval-sanitize-30-r1-017-vd92d.18d4ab37d9674b7a,reason=Started count=1 msg=Started container task
0.3225,Event,ADDED,eval-sanitize-30-r1-017.18d4ab37b6898d4a,reason=SuccessfulCreate count=1 msg=Created pod: eval-sanitize-30-r1-017-vd92d
0.3227,Event,ADDED,eval-sanitize-30-r1-017.18d4ab3d74a78ccc,reason=Completed count=1 msg=Job completed
0.3229,Event,ADDED,eval-sanitize-30-r1-018-hm972.18d4ab37f311b51d,reason=Scheduled count=None msg=Successfully assigned compute/eval-sanitize-30-r1-018-hm972 to kind-worker3
0.3232,Event,ADDED,eval-sanitize-30-r1-018-hm972.18d4ab380ed8232b,"reason=Pulled count=1 msg=Container image ""busybox:musl"" already present on machine"
0.3233,Event,ADDED,eval-sanitize-30-r1-018-hm972.18d4ab38104d8fed,reason=Created count=1 msg=Created container: task
0.3235,Event,ADDED,eval-sanitize-30-r1-018-hm972.18d4ab3812a98bec,reason=Started count=1 msg=Started container task
0.3237,Event,ADDED,eval-sanitize-30-r1-018.18d4ab37f21e62eb,reason=SuccessfulCreate count=1 msg=Created pod: eval-sanitize-30-r1-018-hm972
0.324,Event,ADDED,eval-sanitize-30-r1-018.18d4ab3d7ff537d7,reason=Completed count=1 msg=Job completed
0.3241,Event,ADDED,eval-sanitize-30-r1-019-sh9pq.18d4ab382f622622,"reason=FailedScheduling count=None msg=0/6 nodes are available: 6 node(s) had untolerated taint(s). no new claims to deallocate, preemption: 0/6 nodes are available: 6 Preemption is not helpful for scheduling."
0.3243,Event,ADDED,eval-sanitize-30-r1-019-sh9pq.18d4ab3e4a4d70f8,reason=Scheduled count=None msg=Successfully assigned compute/eval-sanitize-30-r1-019-sh9pq to kind-worker2
0.3246,Event,ADDED,eval-sanitize-30-r1-019-sh9pq.18d4ab3e64fd1c7d,"reason=Pulled count=1 msg=Container image ""busybox:musl"" already present on machine"
0.3248,Event,ADDED,eval-sanitize-30-r1-019-sh9pq.18d4ab3e66d8e4c9,reason=Created count=1 msg=Created container: task
0.3249,Event,ADDED,eval-sanitize-30-r1-019-sh9pq.18d4ab3e6c20f5b9,reason=Started count=1 msg=Started container task
0.3251,Event,ADDED,eval-sanitize-30-r1-019.18d4ab382f624012,reason=SuccessfulCreate count=1 msg=Created pod: eval-sanitize-30-r1-019-sh9pq
0.3254,Event,ADDED,eval-sanitize-30-r1-019.18d4ab43ccef98ff,reason=Completed count=1 msg=Job completed
0.3256,Event,ADDED,eval-sanitize-30-r1-020-mqhq6.18d4ab38693c2127,"reason=FailedScheduling count=None msg=0/6 nodes are available: 6 node(s) had untolerated taint(s). no new claims to deallocate, preemption: 0/6 nodes are available: 6 Preemption is not helpful for scheduling."
0.3257,Event,ADDED,eval-sanitize-30-r1-020-mqhq6.18d4ab3e4aaf5a95,"reason=FailedScheduling count=None msg=0/6 nodes are available: 1 c_wall violated: 1 conflicting context pair(s) with node memory, 5 node(s) had untolerated taint(s). no new claims to deallocate, preemption: 0/6 nodes are available: 1 No preemption victims found for incoming pod, 5 Preemption is not helpful for scheduling."
0.3261,Event,ADDED,eval-sanitize-30-r1-020-mqhq6.18d4ab3e6d74e73f,"reason=FailedScheduling count=None msg=0/6 nodes are available: 1 c_wall violated: 1 conflicting context pair(s) with node memory, 5 node(s) had untolerated taint(s). no new claims to deallocate, preemption: 0/6 nodes are available: 1 No preemption victims found for incoming pod, 5 Preemption is not helpful for scheduling."
0.3262,Event,ADDED,eval-sanitize-30-r1-020-mqhq6.18d4ab3ec7c42cea,reason=Scheduled count=None msg=Successfully assigned compute/eval-sanitize-30-r1-020-mqhq6 to kind-worker5
0.3264,Event,ADDED,eval-sanitize-30-r1-020-mqhq6.18d4ab3ee4029b09,"reason=Pulled count=1 msg=Container image ""busybox:musl"" already present on machine"
0.3266,Event,ADDED,eval-sanitize-30-r1-020-mqhq6.18d4ab3ee624f06c,reason=Created count=1 msg=Created container: task
0.3268,Event,ADDED,eval-sanitize-30-r1-020-mqhq6.18d4ab3eee76be5f,reason=Started count=1 msg=Started container task
0.3269,Event,ADDED,eval-sanitize-30-r1-020.18d4ab38692e9b08,reason=SuccessfulCreate count=1 msg=Created pod: eval-sanitize-30-r1-020-mqhq6
0.3272,Event,ADDED,eval-sanitize-30-r1-020.18d4ab441ae0858c,reason=Completed count=1 msg=Job completed
0.3275,Event,ADDED,eval-sanitize-30-r1-021-qjrg2.18d4ab38a4bf9f6d,"reason=FailedScheduling count=None msg=0/6 nodes are available: 6 node(s) had untolerated taint(s). no new claims to deallocate, preemption: 0/6 nodes are available: 6 Preemption is not helpful for scheduling."
0.3276,Event,ADDED,eval-sanitize-30-r1-021-qjrg2.18d4ab3e4c0fde0b,reason=Scheduled count=None msg=Successfully assigned compute/eval-sanitize-30-r1-021-qjrg2 to kind-worker2
0.3278,Event,ADDED,eval-sanitize-30-r1-021-qjrg2.18d4ab3e663b679a,"reason=Pulled count=1 msg=Container image ""busybox:musl"" already present on machine"
0.328,Event,ADDED,eval-sanitize-30-r1-021-qjrg2.18d4ab3e684bc125,reason=Created count=1 msg=Created container: task
0.3283,Event,ADDED,eval-sanitize-30-r1-021-qjrg2.18d4ab3e6cae8296,reason=Started count=1 msg=Started container task
0.3285,Event,ADDED,eval-sanitize-30-r1-021.18d4ab38a4b687ed,reason=SuccessfulCreate count=1 msg=Created pod: eval-sanitize-30-r1-021-qjrg2
0.3287,Event,ADDED,eval-sanitize-30-r1-021.18d4ab4407535af6,reason=Completed count=1 msg=Job completed
0.3288,Event,ADDED,eval-sanitize-30-r1-022-mkpbd.18d4ab38e17cfedc,"reason=FailedScheduling count=None msg=0/6 nodes are available: 6 node(s) had untolerated taint(s). no new claims to deallocate, preemption: 0/6 nodes are available: 6 Preemption is not helpful for scheduling."
0.3292,Event,ADDED,eval-sanitize-30-r1-022-mkpbd.18d4ab3e4b94ed19,"reason=FailedScheduling count=None msg=0/6 nodes are available: 1 c_wall violated: 1 conflicting context pair(s) with node memory, 5 node(s) had untolerated taint(s). no new claims to deallocate, preemption: 0/6 nodes are available: 1 No preemption victims found for incoming pod, 5 Preemption is not helpful for scheduling."
0.3294,Event,ADDED,eval-sanitize-30-r1-022-mkpbd.18d4ab3e6dab2cba,"reason=FailedScheduling count=None msg=0/6 nodes are available: 1 c_wall violated: 1 conflicting context pair(s) with node memory, 5 node(s) had untolerated taint(s). no new claims to deallocate, preemption: 0/6 nodes are available: 1 No preemption victims found for incoming pod, 5 Preemption is not helpful for scheduling."
0.3295,Event,ADDED,eval-sanitize-30-r1-022-mkpbd.18d4ab3f0115e172,"reason=FailedScheduling count=None msg=0/6 nodes are available: 2 c_wall violated: 1 conflicting context pair(s) with node memory, 4 node(s) had untolerated taint(s). no new claims to deallocate, preemption: 0/6 nodes are available: 2 No preemption victims found for incoming pod, 4 Preemption is not helpful for scheduling."
0.3297,Event,ADDED,eval-sanitize-30-r1-022-mkpbd.18d4ab3f55dc8cd0,reason=Scheduled count=None msg=Successfully assigned compute/eval-sanitize-30-r1-022-mkpbd to kind-worker
0.3299,Event,ADDED,eval-sanitize-30-r1-022-mkpbd.18d4ab3f83163909,"reason=Pulled count=1 msg=Container image ""busybox:musl"" already present on machine"
0.3301,Event,ADDED,eval-sanitize-30-r1-022-mkpbd.18d4ab3f855213e3,reason=Created count=1 msg=Created container: task
0.3303,Event,ADDED,eval-sanitize-30-r1-022-mkpbd.18d4ab3f8bf9db9d,reason=Started count=1 msg=Started container task
0.3304,Event,ADDED,eval-sanitize-30-r1-022.18d4ab38e1739e19,reason=SuccessfulCreate count=1 msg=Created pod: eval-sanitize-30-r1-022-mkpbd
0.3306,Event,ADDED,eval-sanitize-30-r1-022.18d4ab46afc2ffcb,reason=Completed count=1 msg=Job completed
0.3307,Event,ADDED,eval-sanitize-30-r1-023-btgdp.18d4ab391c14895e,"reason=FailedScheduling count=None msg=0/6 nodes are available: 6 node(s) had untolerated taint(s). no new claims to deallocate, preemption: 0/6 nodes are available: 6 Preemption is not helpful for scheduling."
0.3309,Event,ADDED,eval-sanitize-30-r1-023-btgdp.18d4ab3e4ca4793e,"reason=FailedScheduling count=None msg=0/6 nodes are available: 1 c_wall violated: 1 conflicting context pair(s) with node memory, 5 node(s) had untolerated taint(s). no new claims to deallocate, preemption: 0/6 nodes are available: 1 No preemption victims found for incoming pod, 5 Preemption is not helpful for scheduling."
0.3311,Event,ADDED,eval-sanitize-30-r1-023-btgdp.18d4ab3e6ddaca8a,"reason=FailedScheduling count=None msg=0/6 nodes are available: 1 c_wall violated: 2 conflicting context pair(s) with node memory, 5 node(s) had untolerated taint(s). no new claims to deallocate, preemption: 0/6 nodes are available: 1 No preemption victims found for incoming pod, 5 Preemption is not helpful for scheduling."
0.3313,Event,ADDED,eval-sanitize-30-r1-023-btgdp.18d4ab3e8a95daeb,"reason=FailedScheduling count=None msg=0/6 nodes are available: 1 c_wall violated: 2 conflicting context pair(s) with node memory, 5 node(s) had untolerated taint(s). no new claims to deallocate, preemption: 0/6 nodes are available: 1 No preemption victims found for incoming pod, 5 Preemption is not helpful for scheduling."
0.3315,Event,ADDED,eval-sanitize-30-r1-023-btgdp.18d4ab3f0cc0b780,"reason=FailedScheduling count=None msg=0/6 nodes are available: 1 c_wall violated: 1 conflicting context pair(s) with node memory, 1 c_wall violated: 2 conflicting context pair(s) with node memory, 4 node(s) had untolerated taint(s). no new claims to deallocate, preemption: 0/6 nodes are available: 2 No preemption victims found for incoming pod, 4 Preemption is not helpful for scheduling."
0.3317,Event,ADDED,eval-sanitize-30-r1-023-btgdp.18d4ab3f6de97987,reason=Scheduled count=None msg=Successfully assigned compute/eval-sanitize-30-r1-023-btgdp to kind-worker3
0.3319,Event,ADDED,eval-sanitize-30-r1-023-btgdp.18d4ab3f8bef1658,"reason=Pulled count=1 msg=Container image ""busybox:musl"" already present on machine"
0.3321,Event,ADDED,eval-sanitize-30-r1-023-btgdp.18d4ab3f8dd9da48,reason=Created count=1 msg=Created container: task
0.3323,Event,ADDED,eval-sanitize-30-r1-023-btgdp.18d4ab3f91cad630,reason=Started count=1 msg=Started container task
0.3325,Event,ADDED,eval-sanitize-30-r1-023.18d4ab391c148148,reason=SuccessfulCreate count=1 msg=Created pod: eval-sanitize-30-r1-023-btgdp
0.3326,Event,ADDED,eval-sanitize-30-r1-023.18d4ab466d7963d0,reason=Completed count=1 msg=Job completed
0.3329,Event,ADDED,eval-sanitize-30-r1-024-cm68s.18d4ab39584a6244,"reason=FailedScheduling count=None msg=0/6 nodes are available: 6 node(s) had untolerated taint(s). no new claims to deallocate, preemption: 0/6 nodes are available: 6 Preemption is not helpful for scheduling."
0.3331,Event,ADDED,eval-sanitize-30-r1-024-cm68s.18d4ab3e4f146353,"reason=FailedScheduling count=None msg=0/6 nodes are available: 1 c_wall violated: 1 conflicting context pair(s) with node memory, 5 node(s) had untolerated taint(s). no new claims to deallocate, preemption: 0/6 nodes are available: 1 No preemption victims found for incoming pod, 5 Preemption is not helpful for scheduling."
0.3333,Event,ADDED,eval-sanitize-30-r1-024-cm68s.18d4ab3e71af84d2,"reason=FailedScheduling count=None msg=0/6 nodes are available: 1 c_wall violated: 1 conflicting context pair(s) with node memory, 5 node(s) had untolerated taint(s). no new claims to deallocate, preemption: 0/6 nodes are available: 1 No preemption victims found for incoming pod, 5 Preemption is not helpful for scheduling."
0.3335,Event,ADDED,eval-sanitize-30-r1-024-cm68s.18d4ab3ecc9ba909,reason=Scheduled count=None msg=Successfully assigned compute/eval-sanitize-30-r1-024-cm68s to kind-worker5
0.3337,Event,ADDED,eval-sanitize-30-r1-024-cm68s.18d4ab3eeecdea72,"reason=Pulled count=1 msg=Container image ""busybox:musl"" already present on machine"
0.3338,Event,ADDED,eval-sanitize-30-r1-024-cm68s.18d4ab3ef27a57d3,reason=Created count=1 msg=Created container: task
0.334,Event,ADDED,eval-sanitize-30-r1-024-cm68s.18d4ab3ef84bc3db,reason=Started count=1 msg=Started container task
0.3342,Event,ADDED,eval-sanitize-30-r1-024.18d4ab39583c8bd7,reason=SuccessfulCreate count=1 msg=Created pod: eval-sanitize-30-r1-024-cm68s
0.3343,Event,ADDED,eval-sanitize-30-r1-024.18d4ab4549ee0bfc,reason=Completed count=1 msg=Job completed
0.3345,Event,ADDED,eval-sanitize-30-r1-025-twh7m.18d4ab3995f936af,"reason=FailedScheduling count=None msg=0/6 nodes are available: 6 node(s) had untolerated taint(s). no new claims to deallocate, preemption: 0/6 nodes are available: 6 Preemption is not helpful for scheduling."
0.3347,Event,ADDED,eval-sanitize-30-r1-025-twh7m.18d4ab3e50773b45,reason=Scheduled count=None msg=Successfully assigned compute/eval-sanitize-30-r1-025-twh7m to kind-worker2
0.3348,Event,ADDED,eval-sanitize-30-r1-025-twh7m.18d4ab3e6cb7a650,"reason=Pulled count=1 msg=Container image ""busybox:musl"" already present on machine"
0.3352,Event,ADDED,eval-sanitize-30-r1-025-twh7m.18d4ab3e6e237907,reason=Created count=1 msg=Created container: task
0.3353,Event,ADDED,eval-sanitize-30-r1-025-twh7m.18d4ab3e75153e97,reason=Started count=1 msg=Started container task
0.3355,Event,ADDED,eval-sanitize-30-r1-025.18d4ab3995e582bf,reason=SuccessfulCreate count=1 msg=Created pod: eval-sanitize-30-r1-025-twh7m
0.3357,Event,ADDED,eval-sanitize-30-r1-025.18d4ab43ce051fca,reason=Completed count=1 msg=Job completed
0.3358,Event,ADDED,eval-sanitize-30-r1-026-55jph.18d4ab39d06f6b3a,"reason=FailedScheduling count=None msg=0/6 nodes are available: 6 node(s) had untolerated taint(s). no new claims to deallocate, preemption: 0/6 nodes are available: 6 Preemption is not helpful for scheduling."
0.336,Event,ADDED,eval-sanitize-30-r1-026-55jph.18d4ab3e504a2aaf,"reason=FailedScheduling count=None msg=0/6 nodes are available: 1 c_wall violated: 1 conflicting context pair(s) with node memory, 5 node(s) had untolerated taint(s). no new claims to deallocate, preemption: 0/6 nodes are available: 1 No preemption victims found for incoming pod, 5 Preemption is not helpful for scheduling."
0.3361,Event,ADDED,eval-sanitize-30-r1-026-55jph.18d4ab3e72bd2f09,"reason=FailedScheduling count=None msg=0/6 nodes are available: 1 c_wall violated: 2 conflicting context pair(s) with node memory, 5 node(s) had untolerated taint(s). no new claims to deallocate, preemption: 0/6 nodes are available: 1 No preemption victims found for incoming pod, 5 Preemption is not helpful for scheduling."
0.3363,Event,ADDED,eval-sanitize-30-r1-026-55jph.18d4ab3e8ad768ad,"reason=FailedScheduling count=None msg=0/6 nodes are available: 1 c_wall violated: 2 conflicting context pair(s) with node memory, 5 node(s) had untolerated taint(s). no new claims to deallocate, preemption: 0/6 nodes are available: 1 No preemption victims found for incoming pod, 5 Preemption is not helpful for scheduling."
0.3365,Event,ADDED,eval-sanitize-30-r1-026-55jph.18d4ab3f0d2b136a,"reason=FailedScheduling count=None msg=0/6 nodes are available: 1 c_wall violated: 1 conflicting context pair(s) with node memory, 1 c_wall violated: 2 conflicting context pair(s) with node memory, 4 node(s) had untolerated taint(s). no new claims to deallocate, preemption: 0/6 nodes are available: 2 No preemption victims found for incoming pod, 4 Preemption is not helpful for scheduling."
0.3366,Event,ADDED,eval-sanitize-30-r1-026-55jph.18d4ab3f7863fa2e,reason=Scheduled count=None msg=Successfully assigned compute/eval-sanitize-30-r1-026-55jph to kind-worker3
0.3368,Event,ADDED,eval-sanitize-30-r1-026-55jph.18d4ab3f930a1f75,"reason=Pulled count=1 msg=Container image ""busybox:musl"" already present on machine"
0.3369,Event,ADDED,eval-sanitize-30-r1-026-55jph.18d4ab3f94ce6f0c,reason=Created count=1 msg=Created container: task
0.3371,Event,ADDED,eval-sanitize-30-r1-026-55jph.18d4ab3f9907c449,reason=Started count=1 msg=Started container task
0.3373,Event,ADDED,eval-sanitize-30-r1-026.18d4ab39d0689d0b,reason=SuccessfulCreate count=1 msg=Created pod: eval-sanitize-30-r1-026-55jph
0.3374,Event,ADDED,eval-sanitize-30-r1-026.18d4ab4656be0c06,reason=Completed count=1 msg=Job completed
0.3376,Event,ADDED,eval-sanitize-30-r1-027-4vkpg.18d4ab3a0c9f905e,"reason=FailedScheduling count=None msg=0/6 nodes are available: 6 node(s) had untolerated taint(s). no new claims to deallocate, preemption: 0/6 nodes are available: 6 Preemption is not helpful for scheduling."
0.3377,Event,ADDED,eval-sanitize-30-r1-027-4vkpg.18d4ab3e5129e080,"reason=FailedScheduling count=None msg=0/6 nodes are available: 1 c_wall violated: 2 conflicting context pair(s) with node memory, 5 node(s) had untolerated taint(s). no new claims to deallocate, preemption: 0/6 nodes are available: 1 No preemption victims found for incoming pod, 5 Preemption is not helpful for scheduling."
0.3379,Event,ADDED,eval-sanitize-30-r1-027-4vkpg.18d4ab3e759fe191,"reason=FailedScheduling count=None msg=0/6 nodes are available: 1 c_wall violated: 3 conflicting context pair(s) with node memory, 5 node(s) had untolerated taint(s). no new claims to deallocate, preemption: 0/6 nodes are available: 1 No preemption victims found for incoming pod, 5 Preemption is not helpful for scheduling."
0.3381,Event,ADDED,eval-sanitize-30-r1-027-4vkpg.18d4ab3e8b0ebf33,"reason=FailedScheduling count=None msg=0/6 nodes are available: 1 c_wall violated: 3 conflicting context pair(s) with node memory, 5 node(s) had untolerated taint(s). no new claims to deallocate, preemption: 0/6 nodes are available: 1 No preemption victims found for incoming pod, 5 Preemption is not helpful for scheduling."
0.3382,Event,ADDED,eval-sanitize-30-r1-027-4vkpg.18d4ab3f0e17288c,"reason=FailedScheduling count=None msg=0/6 nodes are available: 1 c_wall violated: 1 conflicting context pair(s) with node memory, 1 c_wall violated: 3 conflicting context pair(s) with node memory, 4 node(s) had untolerated taint(s). no new claims to deallocate, preemption: 0/6 nodes are available: 2 No preemption victims found for incoming pod, 4 Preemption is not helpful for scheduling."
0.3384,Event,ADDED,eval-sanitize-30-r1-027-4vkpg.18d4ab3f8bd1b75a,reason=Scheduled count=None msg=Successfully assigned compute/eval-sanitize-30-r1-027-4vkpg to kind-worker4
0.3385,Event,ADDED,eval-sanitize-30-r1-027-4vkpg.18d4ab3faa6473b2,"reason=Pulled count=1 msg=Container image ""busybox:musl"" already present on machine"
0.3387,Event,ADDED,eval-sanitize-30-r1-027-4vkpg.18d4ab3fac37fb7e,reason=Created count=1 msg=Created container: task
0.3389,Event,ADDED,eval-sanitize-30-r1-027-4vkpg.18d4ab3fb1bd21a7,reason=Started count=1 msg=Started container task
0.3391,Event,ADDED,eval-sanitize-30-r1-027.18d4ab3a0c91bc53,reason=SuccessfulCreate count=1 msg=Created pod: eval-sanitize-30-r1-027-4vkpg
0.3392,Event,ADDED,eval-sanitize-30-r1-027.18d4ab46996ae6e1,reason=Completed count=1 msg=Job completed
0.3394,Event,ADDED,eval-sanitize-30-r1-028-zkddd.18d4ab3a4cba4f65,"reason=FailedScheduling count=None msg=0/6 nodes are available: 6 node(s) had untolerated taint(s). no new claims to deallocate, preemption: 0/6 nodes are available: 6 Preemption is not helpful for scheduling."
0.3395,Event,ADDED,eval-sanitize-30-r1-028-zkddd.18d4ab3e51eadb7c,"reason=FailedScheduling count=None msg=0/6 nodes are available: 1 c_wall violated: 2 conflicting context pair(s) with node memory, 5 node(s) had untolerated taint(s). no new claims to deallocate, preemption: 0/6 nodes are available: 1 No preemption victims found for incoming pod, 5 Preemption is not helpful for scheduling."
0.3397,Event,ADDED,eval-sanitize-30-r1-028-zkddd.18d4ab3e765cdac7,"reason=FailedScheduling count=None msg=0/6 nodes are available: 1 c_wall violated: 3 conflicting context pair(s) with node memory, 5 node(s) had untolerated taint(s). no new claims to deallocate, preemption: 0/6 nodes are available: 1 No preemption victims found for incoming pod, 5 Preemption is not helpful for scheduling."
0.3399,Event,ADDED,eval-sanitize-30-r1-028-zkddd.18d4ab3e8b4a6621,"reason=FailedScheduling count=None msg=0/6 nodes are available: 1 c_wall violated: 3 conflicting context pair(s) with node memory, 5 node(s) had untolerated taint(s). no new claims to deallocate, preemption: 0/6 nodes are available: 1 No preemption victims found for incoming pod, 5 Preemption is not helpful for scheduling."
0.34,Event,ADDED,eval-sanitize-30-r1-028-zkddd.18d4ab3f1320c235,reason=Scheduled count=None msg=Successfully assigned compute/eval-sanitize-30-r1-028-zkddd to kind-worker
0.3402,Event,ADDED,eval-sanitize-30-r1-028-zkddd.18d4ab3f36aa11e3,"reason=Pulled count=1 msg=Container image ""busybox:musl"" already present on machine"
0.3403,Event,ADDED,eval-sanitize-30-r1-028-zkddd.18d4ab3f3871dda7,reason=Created count=1 msg=Created container: task
0.3405,Event,ADDED,eval-sanitize-30-r1-028-zkddd.18d4ab3f444c83c0,reason=Started count=1 msg=Started container task
0.3407,Event,ADDED,eval-sanitize-30-r1-028.18d4ab3a4ca4e85f,reason=SuccessfulCreate count=1 msg=Created pod: eval-sanitize-30-r1-028-zkddd
0.3408,Event,ADDED,eval-sanitize-30-r1-028.18d4ab4477ebfc79,reason=Completed count=1 msg=Job completed
0.341,Event,ADDED,eval-sanitize-30-r1-029-6nqjh.18d4ab3a8212c88c,"reason=FailedScheduling count=None msg=0/6 nodes are available: 6 node(s) had untolerated taint(s). no new claims to deallocate, preemption: 0/6 nodes are available: 6 Preemption is not helpful for scheduling."
0.3411,Event,ADDED,eval-sanitize-30-r1-029-6nqjh.18d4ab3e55fce632,"reason=FailedScheduling count=None msg=0/6 nodes are available: 1 c_wall violated: 1 conflicting context pair(s) with node memory, 5 node(s) had untolerated taint(s). no new claims to deallocate, preemption: 0/6 nodes are available: 1 No preemption victims found for incoming pod, 5 Preemption is not helpful for scheduling."
0.3413,Event,ADDED,eval-sanitize-30-r1-029-6nqjh.18d4ab3e77a62fd6,"reason=FailedScheduling count=None msg=0/6 nodes are available: 1 c_wall violated: 2 conflicting context pair(s) with node memory, 5 node(s) had untolerated taint(s). no new claims to deallocate, preemption: 0/6 nodes are available: 1 No preemption victims found for incoming pod, 5 Preemption is not helpful for scheduling."
0.3415,Event,ADDED,eval-sanitize-30-r1-029-6nqjh.18d4ab3e8b812aed,"reason=FailedScheduling count=None msg=0/6 nodes are available: 1 c_wall violated: 2 conflicting context pair(s) with node memory, 5 node(s) had untolerated taint(s). no new claims to deallocate, preemption: 0/6 nodes are available: 1 No preemption victims found for incoming pod, 5 Preemption is not helpful for scheduling."
0.3416,Event,ADDED,eval-sanitize-30-r1-029-6nqjh.18d4ab3f18b3a945,"reason=FailedScheduling count=None msg=0/6 nodes are available: 1 c_wall violated: 2 conflicting context pair(s) with node memory, 2 c_wall violated: 1 conflicting context pair(s) with node memory, 3 node(s) had untolerated taint(s). no new claims to deallocate, preemption: 0/6 nodes are available: 3 No preemption victims found for incoming pod, 3 Preemption is not helpful for scheduling."
0.3418,Event,ADDED,eval-sanitize-30-r1-029-6nqjh.18d4ab3f965cd4fa,reason=Scheduled count=None msg=Successfully assigned compute/eval-sanitize-30-r1-029-6nqjh to kind-worker3
0.3421,Event,ADDED,eval-sanitize-30-r1-029-6nqjh.18d4ab3fb30a4590,"reason=Pulled count=1 msg=Container image ""busybox:musl"" already present on machine"
0.3423,Event,ADDED,eval-sanitize-30-r1-029-6nqjh.18d4ab3fb49cea8a,reason=Created count=1 msg=Created container: task
0.3425,Event,ADDED,eval-sanitize-30-r1-029-6nqjh.18d4ab3fbab11f74,reason=Started count=1 msg=Started container task
0.3426,Event,ADDED,eval-sanitize-30-r1-029.18d4ab3a8206cbbf,reason=SuccessfulCreate count=1 msg=Created pod: eval-sanitize-30-r1-029-6nqjh
0.3432,Event,ADDED,eval-sanitize-30-r1-029.18d4ab463fccd414,reason=Completed count=1 msg=Job completed
0.3433,Event,ADDED,eval-sanitize-30-r1-030-fwdjz.18d4ab3abd3c20c7,"reason=FailedScheduling count=None msg=0/6 nodes are available: 6 node(s) had untolerated taint(s). no new claims to deallocate, preemption: 0/6 nodes are available: 6 Preemption is not helpful for scheduling."
0.3435,Event,ADDED,eval-sanitize-30-r1-030-fwdjz.18d4ab3e5ac9aa76,"reason=FailedScheduling count=None msg=0/6 nodes are available: 1 c_wall violated: 2 conflicting context pair(s) with node memory, 5 node(s) had untolerated taint(s). no new claims to deallocate, preemption: 0/6 nodes are available: 1 No preemption victims found for incoming pod, 5 Preemption is not helpful for scheduling."
0.3436,Event,ADDED,eval-sanitize-30-r1-030-fwdjz.18d4ab3e78b36b03,"reason=FailedScheduling count=None msg=0/6 nodes are available: 1 c_wall violated: 3 conflicting context pair(s) with node memory, 5 node(s) had untolerated taint(s). no new claims to deallocate, preemption: 0/6 nodes are available: 1 No preemption victims found for incoming pod, 5 Preemption is not helpful for scheduling."
0.3438,Event,ADDED,eval-sanitize-30-r1-030-fwdjz.18d4ab3e8f92d634,"reason=FailedScheduling count=None msg=0/6 nodes are available: 1 c_wall violated: 3 conflicting context pair(s) with node memory, 5 node(s) had untolerated taint(s). no new claims to deallocate, preemption: 0/6 nodes are available: 1 No preemption victims found for incoming pod, 5 Preemption is not helpful for scheduling."
0.344,Event,ADDED,eval-sanitize-30-r1-030-fwdjz.18d4ab3f1fbcc878,reason=Scheduled count=None msg=Successfully assigned compute/eval-sanitize-30-r1-030-fwdjz to kind-worker
0.3441,Event,ADDED,eval-sanitize-30-r1-030-fwdjz.18d4ab3f395a57c6,"reason=Pulled count=1 msg=Container image ""busybox:musl"" already present on machine"
0.3443,Event,ADDED,eval-sanitize-30-r1-030-fwdjz.18d4ab3f3ad1d3b4,reason=Created count=1 msg=Created container: task
0.3445,Event,ADDED,eval-sanitize-30-r1-030-fwdjz.18d4ab3f445156fd,reason=Started count=1 msg=Started container task
0.3446,Event,ADDED,eval-sanitize-30-r1-030.18d4ab3abd3444b5,reason=SuccessfulCreate count=1 msg=Created pod: eval-sanitize-30-r1-030-fwdjz
0.3448,Event,ADDED,eval-sanitize-30-r1-030.18d4ab455f0c7689,reason=Completed count=1 msg=Job completed
0.3449,Event,ADDED,eval-sanitize-30-r1-031-rkxzs.18d4ab3af95d7b44,"reason=FailedScheduling count=None msg=0/6 nodes are available: 6 node(s) had untolerated taint(s). no new claims to deallocate, preemption: 0/6 nodes are available: 6 Preemption is not helpful for scheduling."
0.3451,Event,ADDED,eval-sanitize-30-r1-031-rkxzs.18d4ab3e5bc31bab,reason=Scheduled count=None msg=Successfully assigned compute/eval-sanitize-30-r1-031-rkxzs to kind-worker2
0.3453,Event,ADDED,eval-sanitize-30-r1-031-rkxzs.18d4ab3e7c1e3f64,"reason=Pulled count=1 msg=Container image ""busybox:musl"" already present on machine"
0.3454,Event,ADDED,eval-sanitize-30-r1-031-rkxzs.18d4ab3e7e7ec04b,reason=Created count=1 msg=Created container: task
0.3456,Event,ADDED,eval-sanitize-30-r1-031-rkxzs.18d4ab3e82c83721,reason=Started count=1 msg=Started container task
0.3458,Event,ADDED,eval-sanitize-30-r1-031.18d4ab3af955f793,reason=SuccessfulCreate count=1 msg=Created pod: eval-sanitize-30-r1-031-rkxzs
0.3459,Event,ADDED,eval-sanitize-30-r1-031.18d4ab43ce88e2fc,reason=Completed count=1 msg=Job completed
0.3461,Event,ADDED,eval-sanitize-30-r1-032-cssbz.18d4ab3b3466393f,"reason=FailedScheduling count=None msg=0/6 nodes are available: 6 node(s) had untolerated taint(s). no new claims to deallocate, preemption: 0/6 nodes are available: 6 Preemption is not helpful for scheduling."
0.3462,Event,ADDED,eval-sanitize-30-r1-032-cssbz.18d4ab3e5bb06436,"reason=FailedScheduling count=None msg=0/6 nodes are available: 1 c_wall violated: 1 conflicting context pair(s) with node memory, 5 node(s) had untolerated taint(s). no new claims to deallocate, preemption: 0/6 nodes are available: 1 No preemption victims found for incoming pod, 5 Preemption is not helpful for scheduling."
0.3464,Event,ADDED,eval-sanitize-30-r1-032-cssbz.18d4ab3e7a4223c4,"reason=FailedScheduling count=None msg=0/6 nodes are available: 1 c_wall violated: 2 conflicting context pair(s) with node memory, 5 node(s) had untolerated taint(s). no new claims to deallocate, preemption: 0/6 nodes are available: 1 No preemption victims found for incoming pod, 5 Preemption is not helpful for scheduling."
0.3466,Event,ADDED,eval-sanitize-30-r1-032-cssbz.18d4ab3e90db803c,"reason=FailedScheduling count=None msg=0/6 nodes are available: 1 c_wall violated: 2 conflicting context pair(s) with node memory, 5 node(s) had untolerated taint(s). no new claims to deallocate, preemption: 0/6 nodes are available: 1 No preemption victims found for incoming pod, 5 Preemption is not helpful for scheduling."
0.3468,Event,ADDED,eval-sanitize-30-r1-032-cssbz.18d4ab3ef4e2c669,"reason=FailedScheduling count=None msg=0/6 nodes are available: 1 c_wall violated: 1 conflicting context pair(s) with node memory, 1 c_wall violated: 2 conflicting context pair(s) with node memory, 4 node(s) had untolerated taint(s). no new claims to deallocate, preemption: 0/6 nodes are available: 2 No preemption victims found for incoming pod, 4 Preemption is not helpful for scheduling."
0.3469,Event,ADDED,eval-sanitize-30-r1-032-cssbz.18d4ab3f9ef1bb33,reason=Scheduled count=None msg=Successfully assigned compute/eval-sanitize-30-r1-032-cssbz to kind-worker3
0.3471,Event,ADDED,eval-sanitize-30-r1-032-cssbz.18d4ab3fbae46fe1,"reason=Pulled count=1 msg=Container image ""busybox:musl"" already present on machine"
0.3473,Event,ADDED,eval-sanitize-30-r1-032-cssbz.18d4ab3fbc612620,reason=Created count=1 msg=Created container: task
0.3474,Event,ADDED,eval-sanitize-30-r1-032-cssbz.18d4ab3fc127d6ef,reason=Started count=1 msg=Started container task
0.3476,Event,ADDED,eval-sanitize-30-r1-032.18d4ab3b345dad0d,reason=SuccessfulCreate count=1 msg=Created pod: eval-sanitize-30-r1-032-cssbz
0.3477,Event,ADDED,eval-sanitize-30-r1-032.18d4ab466d286a8f,reason=Completed count=1 msg=Job completed
0.3479,Event,ADDED,eval-sanitize-30-r1-033-2n4rj.18d4ab3b724f865f,"reason=FailedScheduling count=None msg=0/6 nodes are available: 6 node(s) had untolerated taint(s). no new claims to deallocate, preemption: 0/6 nodes are available: 6 Preemption is not helpful for scheduling."
0.3481,Event,ADDED,eval-sanitize-30-r1-033-2n4rj.18d4ab3e5c81ebe4,"reason=FailedScheduling count=None msg=0/6 nodes are available: 1 c_wall violated: 1 conflicting context pair(s) with node memory, 5 node(s) had untolerated taint(s). no new claims to deallocate, preemption: 0/6 nodes are available: 1 No preemption victims found for incoming pod, 5 Preemption is not helpful for scheduling."
0.3482,Event,ADDED,eval-sanitize-30-r1-033-2n4rj.18d4ab3e7da45934,"reason=FailedScheduling count=None msg=0/6 nodes are available: 1 c_wall violated: 2 conflicting context pair(s) with node memory, 5 node(s) had untolerated taint(s). no new claims to deallocate, preemption: 0/6 nodes are available: 1 No preemption victims found for incoming pod, 5 Preemption is not helpful for scheduling."
0.3484,Event,ADDED,eval-sanitize-30-r1-033-2n4rj.18d4ab3e91145485,"reason=FailedScheduling count=None msg=0/6 nodes are available: 1 c_wall violated: 2 conflicting context pair(s) with node memory, 5 node(s) had untolerated taint(s). no new claims to deallocate, preemption: 0/6 nodes are available: 1 No preemption victims found for incoming pod, 5 Preemption is not helpful for scheduling."
0.3485,Event,ADDED,eval-sanitize-30-r1-033-2n4rj.18d4ab3ef67023c2,"reason=FailedScheduling count=None msg=0/6 nodes are available: 1 c_wall violated: 1 conflicting context pair(s) with node memory, 1 c_wall violated: 2 conflicting context pair(s) with node memory, 4 node(s) had untolerated taint(s). no new claims to deallocate, preemption: 0/6 nodes are available: 2 No preemption victims found for incoming pod, 4 Preemption is not helpful for scheduling."
0.3487,Event,ADDED,eval-sanitize-30-r1-033-2n4rj.18d4ab3f43f943e6,reason=Scheduled count=None msg=Successfully assigned compute/eval-sanitize-30-r1-033-2n4rj to kind-worker3
0.3488,Event,ADDED,eval-sanitize-30-r1-033-2n4rj.18d4ab3f681032b2,"reason=Pulled count=1 msg=Container image ""busybox:musl"" already present on machine"
0.349,Event,ADDED,eval-sanitize-30-r1-033-2n4rj.18d4ab3f6a9645bb,reason=Created count=1 msg=Created container: task
0.3492,Event,ADDED,eval-sanitize-30-r1-033-2n4rj.18d4ab3f707916f0,reason=Started count=1 msg=Started container task
0.3493,Event,ADDED,eval-sanitize-30-r1-033.18d4ab3b7244a2d7,reason=SuccessfulCreate count=1 msg=Created pod: eval-sanitize-30-r1-033-2n4rj
0.3495,Event,ADDED,eval-sanitize-30-r1-033.18d4ab467d5b984e,reason=Completed count=1 msg=Job completed
0.3497,Event,ADDED,eval-sanitize-30-r1-034-gtgrt.18d4ab3babc8ebb5,"reason=FailedScheduling count=None msg=0/6 nodes are available: 6 node(s) had untolerated taint(s). no new claims to deallocate, preemption: 0/6 nodes are available: 6 Preemption is not helpful for scheduling."
0.3499,Event,ADDED,eval-sanitize-30-r1-034-gtgrt.18d4ab3e5d2e568f,"reason=FailedScheduling count=None msg=0/6 nodes are available: 1 c_wall violated: 1 conflicting context pair(s) with node memory, 5 node(s) had untolerated taint(s). no new claims to deallocate, preemption: 0/6 nodes are available: 1 No preemption victims found for incoming pod, 5 Preemption is not helpful for scheduling."
0.3501,Event,ADDED,eval-sanitize-30-r1-034-gtgrt.18d4ab3e7ee33335,"reason=FailedScheduling count=None msg=0/6 nodes are available: 1 c_wall violated: 1 conflicting context pair(s) with node memory, 5 node(s) had untolerated taint(s). no new claims to deallocate, preemption: 0/6 nodes are available: 1 No preemption victims found for incoming pod, 5 Preemption is not helpful for scheduling."
0.3503,Event,ADDED,eval-sanitize-30-r1-034-gtgrt.18d4ab3ecd044ef4,reason=Scheduled count=None msg=Successfully assigned compute/eval-sanitize-30-r1-034-gtgrt to kind-worker5
0.3505,Event,ADDED,eval-sanitize-30-r1-034-gtgrt.18d4ab3eeef5728d,"reason=Pulled count=1 msg=Container image ""busybox:musl"" already present on machine"
0.3506,Event,ADDED,eval-sanitize-30-r1-034-gtgrt.18d4ab3ef2f90773,reason=Created count=1 msg=Created container: task
0.3508,Event,ADDED,eval-sanitize-30-r1-034-gtgrt.18d4ab3ef7c120c0,reason=Started count=1 msg=Started container task
0.351,Event,ADDED,eval-sanitize-30-r1-034.18d4ab3babb8ea34,reason=SuccessfulCreate count=1 msg=Created pod: eval-sanitize-30-r1-034-gtgrt
0.3511,Event,ADDED,eval-sanitize-30-r1-034.18d4ab4549bc0483,reason=Completed count=1 msg=Job completed
0.3513,Event,ADDED,eval-sanitize-30-r1-035-wj9w9.18d4ab3beb39abcf,"reason=FailedScheduling count=None msg=0/6 nodes are available: 6 node(s) had untolerated taint(s). no new claims to deallocate, preemption: 0/6 nodes are available: 6 Preemption is not helpful for scheduling."
0.3514,Event,ADDED,eval-sanitize-30-r1-035-wj9w9.18d4ab3e5ddcf099,"reason=FailedScheduling count=None msg=0/6 nodes are available: 1 c_wall violated: 2 conflicting context pair(s) with node memory, 5 node(s) had untolerated taint(s). no new claims to deallocate, preemption: 0/6 nodes are available: 1 No preemption victims found for incoming pod, 5 Preemption is not helpful for scheduling."
0.3516,Event,ADDED,eval-sanitize-30-r1-035-wj9w9.18d4ab3e7fb96900,"reason=FailedScheduling count=None msg=0/6 nodes are available: 1 c_wall violated: 3 conflicting context pair(s) with node memory, 5 node(s) had untolerated taint(s). no new claims to deallocate, preemption: 0/6 nodes are available: 1 No preemption victims found for incoming pod, 5 Preemption is not helpful for scheduling."
0.3518,Event,ADDED,eval-sanitize-30-r1-035-wj9w9.18d4ab3e9149a04b,"reason=FailedScheduling count=None msg=0/6 nodes are available: 1 c_wall violated: 3 conflicting context pair(s) with node memory, 5 node(s) had untolerated taint(s). no new claims to deallocate, preemption: 0/6 nodes are available: 1 No preemption victims found for incoming pod, 5 Preemption is not helpful for scheduling."
0.3519,Event,ADDED,eval-sanitize-30-r1-035-wj9w9.18d4ab3efb256a0f,"reason=FailedScheduling count=None msg=0/6 nodes are available: 1 c_wall violated: 2 conflicting context pair(s) with node memory, 1 c_wall violated: 3 conflicting context pair(s) with node memory, 4 node(s) had untolerated taint(s). no new claims to deallocate, preemption: 0/6 nodes are available: 2 No preemption victims found for incoming pod, 4 Preemption is not helpful for scheduling."
0.3522,Event,ADDED,eval-sanitize-30-r1-035-wj9w9.18d4ab3f444c832a,reason=Scheduled count=None msg=Successfully assigned compute/eval-sanitize-30-r1-035-wj9w9 to kind-worker
0.3524,Event,ADDED,eval-sanitize-30-r1-035-wj9w9.18d4ab3f6814c106,"reason=Pulled count=1 msg=Container image ""busybox:musl"" already present on machine"
0.3526,Event,ADDED,eval-sanitize-30-r1-035-wj9w9.18d4ab3f6af26a29,reason=Created count=1 msg=Created container: task
0.3529,Event,ADDED,eval-sanitize-30-r1-035-wj9w9.18d4ab3f7051d4ee,reason=Started count=1 msg=Started container task
0.3531,Event,ADDED,eval-sanitize-30-r1-035.18d4ab3beb358d9e,reason=SuccessfulCreate count=1 msg=Created pod: eval-sanitize-30-r1-035-wj9w9
0.3532,Event,ADDED,eval-sanitize-30-r1-035.18d4ab4657cfd53b,reason=Completed count=1 msg=Job completed
0.3534,Event,ADDED,eval-sanitize-30-r1-036-lgjsr.18d4ab3c24a2f0c8,"reason=FailedScheduling count=None msg=0/6 nodes are available: 6 node(s) had untolerated taint(s). no new claims to deallocate, preemption: 0/6 nodes are available: 6 Preemption is not helpful for scheduling."
0.3537,Event,ADDED,eval-sanitize-30-r1-036-lgjsr.18d4ab3e60f55130,"reason=FailedScheduling count=None msg=0/6 nodes are available: 1 c_wall violated: 2 conflicting context pair(s) with node memory, 5 node(s) had untolerated taint(s). no new claims to deallocate, preemption: 0/6 nodes are available: 1 No preemption victims found for incoming pod, 5 Preemption is not helpful for scheduling."
0.3538,Event,ADDED,eval-sanitize-30-r1-036-lgjsr.18d4ab3e80761082,"reason=FailedScheduling count=None msg=0/6 nodes are available: 1 c_wall violated: 3 conflicting context pair(s) with node memory, 5 node(s) had untolerated taint(s). no new claims to deallocate, preemption: 0/6 nodes are available: 1 No preemption victims found for incoming pod, 5 Preemption is not helpful for scheduling."
0.354,Event,ADDED,eval-sanitize-30-r1-036-lgjsr.18d4ab3e9181a7d8,"reason=FailedScheduling count=None msg=0/6 nodes are available: 1 c_wall violated: 3 conflicting context pair(s) with node memory, 5 node(s) had untolerated taint(s). no new claims to deallocate, preemption: 0/6 nodes are available: 1 No preemption victims found for incoming pod, 5 Preemption is not helpful for scheduling."
0.3542,Event,ADDED,eval-sanitize-30-r1-036-lgjsr.18d4ab3efc06bec3,"reason=FailedScheduling count=None msg=0/6 nodes are available: 1 c_wall violated: 2 conflicting context pair(s) with node memory, 1 c_wall violated: 3 conflicting context pair(s) with node memory, 4 node(s) had untolerated taint(s). no new claims to deallocate, preemption: 0/6 nodes are available: 2 No preemption victims found for incoming pod, 4 Preemption is not helpful for scheduling."
0.3544,Event,ADDED,eval-sanitize-30-r1-036-lgjsr.18d4ab3f4ac63e23,reason=Scheduled count=None msg=Successfully assigned compute/eval-sanitize-30-r1-036-lgjsr to kind-worker
0.3546,Event,ADDED,eval-sanitize-30-r1-036-lgjsr.18d4ab3f7059cab9,"reason=Pulled count=1 msg=Container image ""busybox:musl"" already present on machine"
0.3547,Event,ADDED,eval-sanitize-30-r1-036-lgjsr.18d4ab3f71f9ee5c,reason=Created count=1 msg=Created container: task
0.3549,Event,ADDED,eval-sanitize-30-r1-036-lgjsr.18d4ab3f77478e41,reason=Started count=1 msg=Started container task
0.3551,Event,ADDED,eval-sanitize-30-r1-036.18d4ab3c24971ef3,reason=SuccessfulCreate count=1 msg=Created pod: eval-sanitize-30-r1-036-lgjsr
0.3552,Event,ADDED,eval-sanitize-30-r1-036.18d4ab4630dc5db4,reason=Completed count=1 msg=Job completed
0.3554,Event,ADDED,eval-sanitize-30-r1-037-ttdcs.18d4ab3c5ecc7491,"reason=FailedScheduling count=None msg=0/6 nodes are available: 6 node(s) had untolerated taint(s). no new claims to deallocate, preemption: 0/6 nodes are available: 6 Preemption is not helpful for scheduling."
0.3555,Event,ADDED,eval-sanitize-30-r1-037-ttdcs.18d4ab3e620b2077,reason=Scheduled count=None msg=Successfully assigned compute/eval-sanitize-30-r1-037-ttdcs to kind-worker2
0.3557,Event,ADDED,eval-sanitize-30-r1-037-ttdcs.18d4ab3e7e9cb7a9,"reason=Pulled count=1 msg=Container image ""busybox:musl"" already present on machine"
0.3559,Event,ADDED,eval-sanitize-30-r1-037-ttdcs.18d4ab3e80b6f693,reason=Created count=1 msg=Created container: task
0.3561,Event,ADDED,eval-sanitize-30-r1-037-ttdcs.18d4ab3e83ea5fdd,reason=Started count=1 msg=Started container task
0.3562,Event,ADDED,eval-sanitize-30-r1-037.18d4ab3c5ebd9afb,reason=SuccessfulCreate count=1 msg=Created pod: eval-sanitize-30-r1-037-ttdcs
0.3564,Event,ADDED,eval-sanitize-30-r1-037.18d4ab43ccee8a65,reason=Completed count=1 msg=Job completed
0.3565,Event,ADDED,eval-sanitize-30-r1-038-p8p8d.18d4ab3c9f4617fb,"reason=FailedScheduling count=None msg=0/6 nodes are available: 6 node(s) had untolerated taint(s). no new claims to deallocate, preemption: 0/6 nodes are available: 6 Preemption is not helpful for scheduling."
0.3567,Event,ADDED,eval-sanitize-30-r1-038-p8p8d.18d4ab3e626c3acf,reason=Scheduled count=None msg=Successfully assigned compute/eval-sanitize-30-r1-038-p8p8d to kind-worker2
0.3569,Event,ADDED,eval-sanitize-30-r1-038-p8p8d.18d4ab3e7e884b57,"reason=Pulled count=1 msg=Container image ""busybox:musl"" already present on machine"
0.357,Event,ADDED,eval-sanitize-30-r1-038-p8p8d.18d4ab3e806ebf81,reason=Created count=1 msg=Created container: task
0.3572,Event,ADDED,eval-sanitize-30-r1-038-p8p8d.18d4ab3e83ea5fca,reason=Started count=1 msg=Started container task
0.3574,Event,ADDED,eval-sanitize-30-r1-038.18d4ab3c9f3b709b,reason=SuccessfulCreate count=1 msg=Created pod: eval-sanitize-30-r1-038-p8p8d
0.3575,Event,ADDED,eval-sanitize-30-r1-038.18d4ab43ccf5ba5e,reason=Completed count=1 msg=Job completed
0.3577,Event,ADDED,eval-sanitize-30-r1-039-dkjks.18d4ab3cd85f0a45,"reason=FailedScheduling count=None msg=0/6 nodes are available: 6 node(s) had untolerated taint(s). no new claims to deallocate, preemption: 0/6 nodes are available: 6 Preemption is not helpful for scheduling."
0.3578,Event,ADDED,eval-sanitize-30-r1-039-dkjks.18d4ab3e62224d3b,"reason=FailedScheduling count=None msg=0/6 nodes are available: 1 c_wall violated: 1 conflicting context pair(s) with node memory, 5 node(s) had untolerated taint(s). no new claims to deallocate, preemption: 0/6 nodes are available: 1 No preemption victims found for incoming pod, 5 Preemption is not helpful for scheduling."
0.358,Event,ADDED,eval-sanitize-30-r1-039-dkjks.18d4ab3e84a55467,"reason=FailedScheduling count=None msg=0/6 nodes are available: 1 c_wall violated: 1 conflicting context pair(s) with node memory, 5 node(s) had untolerated taint(s). no new claims to deallocate, preemption: 0/6 nodes are available: 1 No preemption victims found for incoming pod, 5 Preemption is not helpful for scheduling."
0.3582,Event,ADDED,eval-sanitize-30-r1-039-dkjks.18d4ab3ed17044bd,reason=Scheduled count=None msg=Successfully assigned compute/eval-sanitize-30-r1-039-dkjks to kind-worker5
0.3584,Event,ADDED,eval-sanitize-30-r1-039-dkjks.18d4ab3ef67a12dd,"reason=Pulled count=1 msg=Container image ""busybox:musl"" already present on machine"
0.3586,Event,ADDED,eval-sanitize-30-r1-039-dkjks.18d4ab3ef800368f,reason=Created count=1 msg=Created container: task
0.3588,Event,ADDED,eval-sanitize-30-r1-039-dkjks.18d4ab3efef58032,reason=Started count=1 msg=Started container task
0.3593,Event,ADDED,eval-sanitize-30-r1-039.18d4ab3cd84fe940,reason=SuccessfulCreate count=1 msg=Created pod: eval-sanitize-30-r1-039-dkjks
0.3595,Event,ADDED,eval-sanitize-30-r1-039.18d4ab454ba541bb,reason=Completed count=1 msg=Job completed
0.3597,Event,ADDED,eval-sanitize-30-r1-040-9gp8t.18d4ab3d12249d96,"reason=FailedScheduling count=None msg=0/6 nodes are available: 6 node(s) had untolerated taint(s). no new claims to deallocate, preemption: 0/6 nodes are available: 6 Preemption is not helpful for scheduling."
0.3598,Event,ADDED,eval-sanitize-30-r1-040-9gp8t.18d4ab3e673e1ab4,reason=Scheduled count=None msg=Successfully assigned compute/eval-sanitize-30-r1-040-9gp8t to kind-worker2
0.3601,Event,ADDED,eval-sanitize-30-r1-040-9gp8t.18d4ab3e82e86611,"reason=Pulled count=1 msg=Container image ""busybox:musl"" already present on machine"
0.3603,Event,ADDED,eval-sanitize-30-r1-040-9gp8t.18d4ab3e84846cad,reason=Created count=1 msg=Created container: task
0.3605,Event,ADDED,eval-sanitize-30-r1-040-9gp8t.18d4ab3e8c564ca9,reason=Started count=1 msg=Started container task
0.361,Event,ADDED,eval-sanitize-30-r1-040.18d4ab3d121429f9,reason=SuccessfulCreate count=1 msg=Created pod: eval-sanitize-30-r1-040-9gp8t
0.3612,Event,ADDED,eval-sanitize-30-r1-040.18d4ab43ccbcf9cc,reason=Completed count=1 msg=Job completed
0.3613,Event,ADDED,eval-sanitize-30-r1-041-qcp9r.18d4ab3d4d3e4309,"reason=FailedScheduling count=None msg=0/6 nodes are available: 6 node(s) had untolerated taint(s). no new claims to deallocate, preemption: 0/6 nodes are available: 6 Preemption is not helpful for scheduling."
0.3615,Event,ADDED,eval-sanitize-30-r1-041-qcp9r.18d4ab3e6717b0e0,"reason=FailedScheduling count=None msg=0/6 nodes are available: 1 c_wall violated: 3 conflicting context pair(s) with node memory, 5 node(s) had untolerated taint(s). no new claims to deallocate, preemption: 0/6 nodes are available: 1 No preemption victims found for incoming pod, 5 Preemption is not helpful for scheduling."
0.3617,Event,ADDED,eval-sanitize-30-r1-041-qcp9r.18d4ab3e84e91c20,"reason=FailedScheduling count=None msg=0/6 nodes are available: 1 c_wall violated: 3 conflicting context pair(s) with node memory, 5 node(s) had untolerated taint(s). no new claims to deallocate, preemption: 0/6 nodes are available: 1 No preemption victims found for incoming pod, 5 Preemption is not helpful for scheduling."
0.3619,Event,ADDED,eval-sanitize-30-r1-041-qcp9r.18d4ab3f022a96ee,"reason=FailedScheduling count=None msg=0/6 nodes are available: 1 c_wall violated: 2 conflicting context pair(s) with node memory, 1 c_wall violated: 3 conflicting context pair(s) with node memory, 4 node(s) had untolerated taint(s). no new claims to deallocate, preemption: 0/6 nodes are available: 2 No preemption victims found for incoming pod, 4 Preemption is not helpful for scheduling."
0.362,Event,ADDED,eval-sanitize-30-r1-041-qcp9r.18d4ab3f5623780c,reason=Scheduled count=None msg=Successfully assigned compute/eval-sanitize-30-r1-041-qcp9r to kind-worker
0.3622,Event,ADDED,eval-sanitize-30-r1-041-qcp9r.18d4ab3f8336da0e,"reason=Pulled count=1 msg=Container image ""busybox:musl"" already present on machine"
0.3623,Event,ADDED,eval-sanitize-30-r1-041-qcp9r.18d4ab3f85c82706,reason=Created count=1 msg=Created container: task
0.3625,Event,ADDED,eval-sanitize-30-r1-041-qcp9r.18d4ab3f8c4d6db9,reason=Started count=1 msg=Started container task
0.3627,Event,ADDED,eval-sanitize-30-r1-041.18d4ab3d4d2d709d,reason=SuccessfulCreate count=1 msg=Created pod: eval-sanitize-30-r1-041-qcp9r
0.3629,Event,ADDED,eval-sanitize-30-r1-041.18d4ab46a5acb605,reason=Completed count=1 msg=Job completed
0.363,Event,ADDED,eval-sanitize-30-r1-042-hnzcj.18d4ab3d8bc1de88,"reason=FailedScheduling count=None msg=0/6 nodes are available: 6 node(s) had untolerated taint(s). no new claims to deallocate, preemption: 0/6 nodes are available: 6 Preemption is not helpful for scheduling."
0.3632,Event,ADDED,eval-sanitize-30-r1-042-hnzcj.18d4ab3e681e9b2f,"reason=FailedScheduling count=None msg=0/6 nodes are available: 1 c_wall violated: 1 conflicting context pair(s) with node memory, 5 node(s) had untolerated taint(s). no new claims to deallocate, preemption: 0/6 nodes are available: 1 No preemption victims found for incoming pod, 5 Preemption is not helpful for scheduling."
0.3634,Event,ADDED,eval-sanitize-30-r1-042-hnzcj.18d4ab3e852abd3a,"reason=FailedScheduling count=None msg=0/6 nodes are available: 1 c_wall violated: 1 conflicting context pair(s) with node memory, 5 node(s) had untolerated taint(s). no new claims to deallocate, preemption: 0/6 nodes are available: 1 No preemption victims found for incoming pod, 5 Preemption is not helpful for scheduling."
0.3635,Event,ADDED,eval-sanitize-30-r1-042-hnzcj.18d4ab3ed356cd67,reason=Scheduled count=None msg=Successfully assigned compute/eval-sanitize-30-r1-042-hnzcj to kind-worker5
0.3637,Event,ADDED,eval-sanitize-30-r1-042-hnzcj.18d4ab3ef7feef75,"reason=Pulled count=1 msg=Container image ""busybox:musl"" already present on machine"
0.3639,Event,ADDED,eval-sanitize-30-r1-042-hnzcj.18d4ab3ef99a9eb0,reason=Created count=1 msg=Created container: task
0.364,Event,ADDED,eval-sanitize-30-r1-042-hnzcj.18d4ab3f004f0b61,reason=Started count=1 msg=Started container task
0.3642,Event,ADDED,eval-sanitize-30-r1-042.18d4ab3d8bb36a5c,reason=SuccessfulCreate count=1 msg=Created pod: eval-sanitize-30-r1-042-hnzcj
0.3645,Event,ADDED,eval-sanitize-30-r1-042.18d4ab4542b9e822,reason=Completed count=1 msg=Job completed
0.3648,Event,ADDED,eval-sanitize-30-r1-043-sjmn8.18d4ab3dc49bc11a,"reason=FailedScheduling count=None msg=0/6 nodes are available: 6 node(s) had untolerated taint(s). no new claims to deallocate, preemption: 0/6 nodes are available: 6 Preemption is not helpful for scheduling."
0.365,Event,ADDED,eval-sanitize-30-r1-043-sjmn8.18d4ab3e68b53102,"reason=FailedScheduling count=None msg=0/6 nodes are available: 1 c_wall violated: 1 conflicting context pair(s) with node memory, 5 node(s) had untolerated taint(s). no new claims to deallocate, preemption: 0/6 nodes are available: 1 No preemption victims found for incoming pod, 5 Preemption is not helpful for scheduling."
0.3652,Event,ADDED,eval-sanitize-30-r1-043-sjmn8.18d4ab3e856387fb,"reason=FailedScheduling count=None msg=0/6 nodes are available: 1 c_wall violated: 1 conflicting context pair(s) with node memory, 5 node(s) had untolerated taint(s). no new claims to deallocate, preemption: 0/6 nodes are available: 1 No preemption victims found for incoming pod, 5 Preemption is not helpful for scheduling."
0.3656,Event,ADDED,eval-sanitize-30-r1-043-sjmn8.18d4ab3edc2f0b45,reason=Scheduled count=None msg=Successfully assigned compute/eval-sanitize-30-r1-043-sjmn8 to kind-worker5
0.3658,Event,ADDED,eval-sanitize-30-r1-043-sjmn8.18d4ab3ef90847f6,"reason=Pulled count=1 msg=Container image ""busybox:musl"" already present on machine"
0.366,Event,ADDED,eval-sanitize-30-r1-043-sjmn8.18d4ab3efa61195d,reason=Created count=1 msg=Created container: task
0.3661,Event,ADDED,eval-sanitize-30-r1-043-sjmn8.18d4ab3f0076bf57,reason=Started count=1 msg=Started container task
0.3665,Event,ADDED,eval-sanitize-30-r1-043.18d4ab3dc4927522,reason=SuccessfulCreate count=1 msg=Created pod: eval-sanitize-30-r1-043-sjmn8
0.3668,Event,ADDED,eval-sanitize-30-r1-043.18d4ab453fb6314e,reason=Completed count=1 msg=Job completed
0.3669,Event,ADDED,eval-sanitize-30-r1-044-9srbv.18d4ab3e02cce2bf,"reason=FailedScheduling count=None msg=0/6 nodes are available: 6 node(s) had untolerated taint(s). no new claims to deallocate, preemption: 0/6 nodes are available: 6 Preemption is not helpful for scheduling."
0.3671,Event,ADDED,eval-sanitize-30-r1-044-9srbv.18d4ab3e6bb883de,"reason=FailedScheduling count=None msg=0/6 nodes are available: 1 c_wall violated: 3 conflicting context pair(s) with node memory, 5 node(s) had untolerated taint(s). no new claims to deallocate, preemption: 0/6 nodes are available: 1 No preemption victims found for incoming pod, 5 Preemption is not helpful for scheduling."
0.3673,Event,ADDED,eval-sanitize-30-r1-044-9srbv.18d4ab3e85971d90,"reason=FailedScheduling count=None msg=0/6 nodes are available: 1 c_wall violated: 3 conflicting context pair(s) with node memory, 5 node(s) had untolerated taint(s). no new claims to deallocate, preemption: 0/6 nodes are available: 1 No preemption victims found for incoming pod, 5 Preemption is not helpful for scheduling."
0.3676,Event,ADDED,eval-sanitize-30-r1-044-9srbv.18d4ab3f06d08e73,"reason=FailedScheduling count=None msg=0/6 nodes are available: 1 c_wall violated: 2 conflicting context pair(s) with node memory, 1 c_wall violated: 3 conflicting context pair(s) with node memory, 4 node(s) had untolerated taint(s). no new claims to deallocate, preemption: 0/6 nodes are available: 2 No preemption victims found for incoming pod, 4 Preemption is not helpful for scheduling."
0.3678,Event,ADDED,eval-sanitize-30-r1-044-9srbv.18d4ab3f5be807fc,reason=Scheduled count=None msg=Successfully assigned compute/eval-sanitize-30-r1-044-9srbv to kind-worker
0.368,Event,ADDED,eval-sanitize-30-r1-044-9srbv.18d4ab3f77bf0758,"reason=Pulled count=1 msg=Container image ""busybox:musl"" already present on machine"
0.3683,Event,ADDED,eval-sanitize-30-r1-044-9srbv.18d4ab3f795693a7,reason=Created count=1 msg=Created container: task
0.3685,Event,ADDED,eval-sanitize-30-r1-044-9srbv.18d4ab3f7e0be518,reason=Started count=1 msg=Started container task
0.3687,Event,ADDED,eval-sanitize-30-r1-044.18d4ab3e02c06175,reason=SuccessfulCreate count=1 msg=Created pod: eval-sanitize-30-r1-044-9srbv
0.3688,Event,ADDED,eval-sanitize-30-r1-044.18d4ab461efc11c9,reason=Completed count=1 msg=Job completed
0.3691,Event,ADDED,eval-sanitize-30-r1-045-7tkmh.18d4ab3e3b4125b2,"reason=FailedScheduling count=None msg=0/6 nodes are available: 6 node(s) had untolerated taint(s). no new claims to deallocate, preemption: 0/6 nodes are available: 6 Preemption is not helpful for scheduling."
0.3693,Event,ADDED,eval-sanitize-30-r1-045-7tkmh.18d4ab3e6cd91337,"reason=FailedScheduling count=None msg=0/6 nodes are available: 1 c_wall violated: 1 conflicting context pair(s) with node memory, 5 node(s) had untolerated taint(s). no new claims to deallocate, preemption: 0/6 nodes are available: 1 No preemption victims found for incoming pod, 5 Preemption is not helpful for scheduling."
0.3695,Event,ADDED,eval-sanitize-30-r1-045-7tkmh.18d4ab3e8984f79f,"reason=FailedScheduling count=None msg=0/6 nodes are available: 1 c_wall violated: 1 conflicting context pair(s) with node memory, 5 node(s) had untolerated taint(s). no new claims to deallocate, preemption: 0/6 nodes are available: 1 No preemption victims found for incoming pod, 5 Preemption is not helpful for scheduling."
0.3698,Event,ADDED,eval-sanitize-30-r1-045-7tkmh.18d4ab3f07e47dea,"reason=FailedScheduling count=None msg=0/6 nodes are available: 2 c_wall violated: 1 conflicting context pair(s) with node memory, 4 node(s) had untolerated taint(s). no new claims to deallocate, preemption: 0/6 nodes are available: 2 No preemption victims found for incoming pod, 4 Preemption is not helpful for scheduling."
0.37,Event,ADDED,eval-sanitize-30-r1-045-7tkmh.18d4ab3f689ff964,reason=Scheduled count=None msg=Successfully assigned compute/eval-sanitize-30-r1-045-7tkmh to kind-worker4
0.3702,Event,ADDED,eval-sanitize-30-r1-045-7tkmh.18d4ab3f82fd9a01,"reason=Pulled count=1 msg=Container image ""busybox:musl"" already present on machine"
0.3705,Event,ADDED,eval-sanitize-30-r1-045-7tkmh.18d4ab3f84e7aa6b,reason=Created count=1 msg=Created container: task
0.3707,Event,ADDED,eval-sanitize-30-r1-045-7tkmh.18d4ab3f8bcc23ca,reason=Started count=1 msg=Started container task
0.3709,Event,ADDED,eval-sanitize-30-r1-045.18d4ab3e3b372dd7,reason=SuccessfulCreate count=1 msg=Created pod: eval-sanitize-30-r1-045-7tkmh
0.371,Event,ADDED,eval-sanitize-30-r1-045.18d4ab468f737da0,reason=Completed count=1 msg=Job completed
0.3712,Event,ADDED,eval-sanitize-30-r1-046-jvqcm.18d4ab3e795dc27d,"reason=FailedScheduling count=None msg=0/6 nodes are available: 1 c_wall violated: 1 conflicting context pair(s) with node memory, 5 node(s) had untolerated taint(s). no new claims to deallocate, preemption: 0/6 nodes are available: 1 No preemption victims found for incoming pod, 5 Preemption is not helpful for scheduling."
0.3715,Event,ADDED,eval-sanitize-30-r1-046-jvqcm.18d4ab3e90a78f48,"reason=FailedScheduling count=None msg=0/6 nodes are available: 1 c_wall violated: 1 conflicting context pair(s) with node memory, 5 node(s) had untolerated taint(s). no new claims to deallocate, preemption: 0/6 nodes are available: 1 No preemption victims found for incoming pod, 5 Preemption is not helpful for scheduling."
0.3717,Event,ADDED,eval-sanitize-30-r1-046-jvqcm.18d4ab3eefee3549,"reason=FailedScheduling count=None msg=0/6 nodes are available: 2 c_wall violated: 1 conflicting context pair(s) with node memory, 4 node(s) had untolerated taint(s). no new claims to deallocate, preemption: 0/6 nodes are available: 2 No preemption victims found for incoming pod, 4 Preemption is not helpful for scheduling."
0.3718,Event,ADDED,eval-sanitize-30-r1-046-jvqcm.18d4ab3f251b8701,reason=Scheduled count=None msg=Successfully assigned compute/eval-sanitize-30-r1-046-jvqcm to kind-worker
0.372,Event,ADDED,eval-sanitize-30-r1-046-jvqcm.18d4ab3f444ec7a2,"reason=Pulled count=1 msg=Container image ""busybox:musl"" already present on machine"
0.3722,Event,ADDED,eval-sanitize-30-r1-046-jvqcm.18d4ab3f45f84e5d,reason=Created count=1 msg=Created container: task
0.3724,Event,ADDED,eval-sanitize-30-r1-046-jvqcm.18d4ab3f4afbb679,reason=Started count=1 msg=Started container task
0.3725,Event,ADDED,eval-sanitize-30-r1-046.18d4ab3e785e2bf9,reason=SuccessfulCreate count=1 msg=Created pod: eval-sanitize-30-r1-046-jvqcm
0.3727,Event,ADDED,eval-sanitize-30-r1-046.18d4ab45714b1f9a,reason=Completed count=1 msg=Job completed
0.3728,Event,ADDED,eval-sanitize-30-r1-047-vv8v7.18d4ab3eb50eae49,reason=Scheduled count=None msg=Successfully assigned compute/eval-sanitize-30-r1-047-vv8v7 to kind-worker5
0.373,Event,ADDED,eval-sanitize-30-r1-047-vv8v7.18d4ab3ed06c5ddb,"reason=Pulled count=1 msg=Container image ""busybox:musl"" already present on machine"
0.3732,Event,ADDED,eval-sanitize-30-r1-047-vv8v7.18d4ab3ed1da949c,reason=Created count=1 msg=Created container: task
0.3733,Event,ADDED,eval-sanitize-30-r1-047-vv8v7.18d4ab3ed48189c2,reason=Started count=1 msg=Started container task
0.3735,Event,ADDED,eval-sanitize-30-r1-047.18d4ab3eb29c0e1d,reason=SuccessfulCreate count=1 msg=Created pod: eval-sanitize-30-r1-047-vv8v7
0.374,Event,ADDED,eval-sanitize-30-r1-047.18d4ab441a76e755,reason=Completed count=1 msg=Job completed
0.3741,Event,ADDED,eval-sanitize-30-r1-048-pvshw.18d4ab3ef55a9efe,"reason=FailedScheduling count=None msg=0/6 nodes are available: 1 c_wall violated: 1 conflicting context pair(s) with node memory, 1 c_wall violated: 2 conflicting context pair(s) with node memory, 4 node(s) had untolerated taint(s). no new claims to deallocate, preemption: 0/6 nodes are available: 2 No preemption victims found for incoming pod, 4 Preemption is not helpful for scheduling."
0.3743,Event,ADDED,eval-sanitize-30-r1-048-pvshw.18d4ab3f31e4c803,"reason=FailedScheduling count=None msg=0/6 nodes are available: 1 c_wall violated: 1 conflicting context pair(s) with node memory, 2 c_wall violated: 2 conflicting context pair(s) with node memory, 3 node(s) had untolerated taint(s). no new claims to deallocate, preemption: 0/6 nodes are available: 3 No preemption victims found for incoming pod, 3 Preemption is not helpful for scheduling."
0.3745,Event,ADDED,eval-sanitize-30-r1-048-pvshw.18d4ab3fa89b4500,reason=Scheduled count=None msg=Successfully assigned compute/eval-sanitize-30-r1-048-pvshw to kind-worker3
0.3746,Event,ADDED,eval-sanitize-30-r1-048-pvshw.18d4ab3fc78e616e,"reason=Pulled count=1 msg=Container image ""busybox:musl"" already present on machine"
0.3748,Event,ADDED,eval-sanitize-30-r1-048-pvshw.18d4ab3fc9504aec,reason=Created count=1 msg=Created container: task
0.375,Event,ADDED,eval-sanitize-30-r1-048-pvshw.18d4ab3fcd058d2c,reason=Started count=1 msg=Started container task
0.3752,Event,ADDED,eval-sanitize-30-r1-048.18d4ab3ef0adc796,reason=SuccessfulCreate count=1 msg=Created pod: eval-sanitize-30-r1-048-pvshw
0.3753,Event,ADDED,eval-sanitize-30-r1-048.18d4ab46476a6c87,reason=Completed count=1 msg=Job completed
0.3755,Event,ADDED,eval-sanitize-30-r1-049-fnxfd.18d4ab3f37630a93,reason=Scheduled count=None msg=Successfully assigned compute/eval-sanitize-30-r1-049-fnxfd to kind-worker
0.3756,Event,ADDED,eval-sanitize-30-r1-049-fnxfd.18d4ab3f55503a75,"reason=Pulled count=1 msg=Container image ""busybox:musl"" already present on machine"
0.3758,Event,ADDED,eval-sanitize-30-r1-049-fnxfd.18d4ab3f577b9030,reason=Created count=1 msg=Created container: task
0.376,Event,ADDED,eval-sanitize-30-r1-049-fnxfd.18d4ab3f5b57196e,reason=Started count=1 msg=Started container task
0.3761,Event,ADDED,eval-sanitize-30-r1-049.18d4ab3f3177f97f,reason=SuccessfulCreate count=1 msg=Created pod: eval-sanitize-30-r1-049-fnxfd
0.3763,Event,ADDED,eval-sanitize-30-r1-049.18d4ab461631e224,reason=Completed count=1 msg=Job completed
0.3765,Event,ADDED,eval-sanitize-30-r1-050-vhcfd.18d4ab3f7fee2001,reason=Scheduled count=None msg=Successfully assigned compute/eval-sanitize-30-r1-050-vhcfd to kind-worker3
0.3766,Event,ADDED,eval-sanitize-30-r1-050-vhcfd.18d4ab3f99d68054,"reason=Pulled count=1 msg=Container image ""busybox:musl"" already present on machine"
0.3768,Event,ADDED,eval-sanitize-30-r1-050-vhcfd.18d4ab3f9b000b30,reason=Created count=1 msg=Created container: task
0.377,Event,ADDED,eval-sanitize-30-r1-050-vhcfd.18d4ab3f9fdb18d7,reason=Started count=1 msg=Started container task
0.3771,Event,ADDED,eval-sanitize-30-r1-050.18d4ab3f6ed2663c,reason=SuccessfulCreate count=1 msg=Created pod: eval-sanitize-30-r1-050-vhcfd
0.3773,Event,ADDED,eval-sanitize-30-r1-050.18d4ab46473893cc,reason=Completed count=1 msg=Job completed
0.3775,Event,ADDED,eval-sanitize-30-r1-051-fdg2b.18d4ab3fafbd20b1,reason=Scheduled count=None msg=Successfully assigned compute/eval-sanitize-30-r1-051-fdg2b to kind-worker5
0.3777,Event,ADDED,eval-sanitize-30-r1-051-fdg2b.18d4ab3fcce65af5,"reason=Pulled count=1 msg=Container image ""busybox:musl"" already present on machine"
0.3778,Event,ADDED,eval-sanitize-30-r1-051-fdg2b.18d4ab3fce2c09a9,reason=Created count=1 msg=Created container: task
0.378,Event,ADDED,eval-sanitize-30-r1-051-fdg2b.18d4ab3fd417bba7,reason=Started count=1 msg=Started container task
0.3782,Event,ADDED,eval-sanitize-30-r1-051.18d4ab3fa1a70758,reason=SuccessfulCreate count=1 msg=Created pod: eval-sanitize-30-r1-051-fdg2b
0.3784,Event,ADDED,eval-sanitize-30-r1-051.18d4ab46873c4358,reason=Completed count=1 msg=Job completed
0.3785,Event,ADDED,eval-sanitize-30-r1-052-xx5l2.18d4ab3fe3f28afb,reason=Scheduled count=None msg=Successfully assigned compute/eval-sanitize-30-r1-052-xx5l2 to kind-worker4
0.3787,Event,ADDED,eval-sanitize-30-r1-052-xx5l2.18d4ab3ffe8e0af4,"reason=Pulled count=1 msg=Container image ""busybox:musl"" already present on machine"
0.3788,Event,ADDED,eval-sanitize-30-r1-052-xx5l2.18d4ab3fffa68f34,reason=Created count=1 msg=Created container: task
0.379,Event,ADDED,eval-sanitize-30-r1-052-xx5l2.18d4ab4004b4e67d,reason=Started count=1 msg=Started container task
0.3792,Event,ADDED,eval-sanitize-30-r1-052.18d4ab3fdcfe573f,reason=SuccessfulCreate count=1 msg=Created pod: eval-sanitize-30-r1-052-xx5l2
0.3793,Event,ADDED,eval-sanitize-30-r1-052.18d4ab46daafff4b,reason=Completed count=1 msg=Job completed
0.3795,Event,ADDED,eval-sanitize-30-r1-053-9jbzg.18d4ab401f9e971d,reason=Scheduled count=None msg=Successfully assigned compute/eval-sanitize-30-r1-053-9jbzg to kind-worker4
0.3797,Event,ADDED,eval-sanitize-30-r1-053-9jbzg.18d4ab403a319f85,"reason=Pulled count=1 msg=Container image ""busybox:musl"" already present on machine"
0.3798,Event,ADDED,eval-sanitize-30-r1-053-9jbzg.18d4ab403b53e994,reason=Created count=1 msg=Created container: task
0.3801,Event,ADDED,eval-sanitize-30-r1-053-9jbzg.18d4ab403f1c7649,reason=Started count=1 msg=Started container task
0.3803,Event,ADDED,eval-sanitize-30-r1-053.18d4ab40189971dd,reason=SuccessfulCreate count=1 msg=Created pod: eval-sanitize-30-r1-053-9jbzg
0.3805,Event,ADDED,eval-sanitize-30-r1-053.18d4ab46dddd036e,reason=Completed count=1 msg=Job completed
0.3806,Event,ADDED,eval-sanitize-30-r1-054-9fkzr.18d4ab40563b50b6,reason=Scheduled count=None msg=Successfully assigned compute/eval-sanitize-30-r1-054-9fkzr to kind-worker4
0.381,Event,ADDED,eval-sanitize-30-r1-054-9fkzr.18d4ab4070943c0e,"reason=Pulled count=1 msg=Container image ""busybox:musl"" already present on machine"
0.3812,Event,ADDED,eval-sanitize-30-r1-054-9fkzr.18d4ab4071c1adbb,reason=Created count=1 msg=Created container: task
0.3813,Event,ADDED,eval-sanitize-30-r1-054-9fkzr.18d4ab40766ee283,reason=Started count=1 msg=Started container task
0.3816,Event,ADDED,eval-sanitize-30-r1-054.18d4ab405413a7b9,reason=SuccessfulCreate count=1 msg=Created pod: eval-sanitize-30-r1-054-9fkzr
0.3818,Event,ADDED,eval-sanitize-30-r1-054.18d4ab46f1bab688,reason=Completed count=1 msg=Job completed
0.382,Event,ADDED,eval-sanitize-30-r1-055-74hgj.18d4ab40971c055a,reason=Scheduled count=None msg=Successfully assigned compute/eval-sanitize-30-r1-055-74hgj to kind-worker4
0.3822,Event,ADDED,eval-sanitize-30-r1-055-74hgj.18d4ab40b07493b5,"reason=Pulled count=1 msg=Container image ""busybox:musl"" already present on machine"
0.3823,Event,ADDED,eval-sanitize-30-r1-055-74hgj.18d4ab40b1aaae0a,reason=Created count=1 msg=Created container: task
0.3825,Event,ADDED,eval-sanitize-30-r1-055-74hgj.18d4ab40b64d74d6,reason=Started count=1 msg=Started container task
0.3827,Event,ADDED,eval-sanitize-30-r1-055.18d4ab40900735f5,reason=SuccessfulCreate count=1 msg=Created pod: eval-sanitize-30-r1-055-74hgj
0.3828,Event,ADDED,eval-sanitize-30-r1-055.18d4ab470c04e86f,reason=Completed count=1 msg=Job completed
0.383,Event,ADDED,eval-sanitize-30-r1-056-lwcxh.18d4ab40cd7bab20,reason=Scheduled count=None msg=Successfully assigned compute/eval-sanitize-30-r1-056-lwcxh to kind-worker5
0.3832,Event,ADDED,eval-sanitize-30-r1-056-lwcxh.18d4ab40e8bf28b3,"reason=Pulled count=1 msg=Container image ""busybox:musl"" already present on machine"
0.3833,Event,ADDED,eval-sanitize-30-r1-056-lwcxh.18d4ab40e9f2881a,reason=Created count=1 msg=Created container: task
0.3835,Event,ADDED,eval-sanitize-30-r1-056-lwcxh.18d4ab40efa258f3,reason=Started count=1 msg=Started container task
0.3837,Event,ADDED,eval-sanitize-30-r1-056.18d4ab40caf07145,reason=SuccessfulCreate count=1 msg=Created pod: eval-sanitize-30-r1-056-lwcxh
0.3839,Event,ADDED,eval-sanitize-30-r1-056.18d4ab4715244d08,reason=Completed count=1 msg=Job completed
0.384,Event,ADDED,eval-sanitize-30-r1-057-nkt9j.18d4ab410e16b42e,reason=Scheduled count=None msg=Successfully assigned compute/eval-sanitize-30-r1-057-nkt9j to kind-worker
0.3843,Event,ADDED,eval-sanitize-30-r1-057-nkt9j.18d4ab4129452932,"reason=Pulled count=1 msg=Container image ""busybox:musl"" already present on machine"
0.3845,Event,ADDED,eval-sanitize-30-r1-057-nkt9j.18d4ab412d8f8d0e,reason=Created count=1 msg=Created container: task
0.3847,Event,ADDED,eval-sanitize-30-r1-057-nkt9j.18d4ab413306679f,reason=Started count=1 msg=Started container task
0.3849,Event,ADDED,eval-sanitize-30-r1-057.18d4ab4106cf16e6,reason=SuccessfulCreate count=1 msg=Created pod: eval-sanitize-30-r1-057-nkt9j
0.3852,Event,ADDED,eval-sanitize-30-r1-057.18d4ab470264a5a5,reason=Completed count=1 msg=Job completed
0.3853,Event,ADDED,eval-sanitize-30-r1-058-5l6rl.18d4ab414481ad03,reason=Scheduled count=None msg=Successfully assigned compute/eval-sanitize-30-r1-058-5l6rl to kind-worker2
0.3855,Event,ADDED,eval-sanitize-30-r1-058-5l6rl.18d4ab4165503d89,"reason=Pulled count=1 msg=Container image ""busybox:musl"" already present on machine"
0.3858,Event,ADDED,eval-sanitize-30-r1-058-5l6rl.18d4ab41668192d2,reason=Created count=1 msg=Created container: task
0.3859,Event,ADDED,eval-sanitize-30-r1-058-5l6rl.18d4ab416dacdbff,reason=Started count=1 msg=Started container task
0.3861,Event,ADDED,eval-sanitize-30-r1-058.18d4ab41420f8428,reason=SuccessfulCreate count=1 msg=Created pod: eval-sanitize-30-r1-058-5l6rl
0.3863,Event,ADDED,eval-sanitize-30-r1-058.18d4ab470d5c81ff,reason=Completed count=1 msg=Job completed
0.3864,Event,ADDED,eval-sanitize-30-r1-059-5dmq6.18d4ab4185be3bfc,"reason=FailedScheduling count=None msg=0/6 nodes are available: 1 c_wall violated: 3 conflicting context pair(s) with node memory, 1 node(s) had untolerated taint(s), 4 c_wall violated: 1 conflicting context pair(s) with node memory. no new claims to deallocate, preemption: 0/6 nodes are available: 1 Preemption is not helpful for scheduling, 5 No preemption victims found for incoming pod."
0.3866,Event,ADDED,eval-sanitize-30-r1-059-5dmq6.18d4ab418c203cc3,"reason=FailedScheduling count=None msg=0/6 nodes are available: 1 c_wall violated: 3 conflicting context pair(s) with node memory, 1 node(s) had untolerated taint(s), 4 c_wall violated: 1 conflicting context pair(s) with node memory. no new claims to deallocate, preemption: 0/6 nodes are available: 1 Preemption is not helpful for scheduling, 5 No preemption victims found for incoming pod."
0.3868,Event,ADDED,eval-sanitize-30-r1-059-5dmq6.18d4ab456dc7ae38,"reason=FailedScheduling count=None msg=0/6 nodes are available: 2 node(s) had untolerated taint(s), 4 c_wall violated: 1 conflicting context pair(s) with node memory. no new claims to deallocate, preemption: 0/6 nodes are available: 2 Preemption is not helpful for scheduling, 4 No preemption victims found for incoming pod."
0.387,Event,ADDED,eval-sanitize-30-r1-059-5dmq6.18d4ab45e1081479,"reason=FailedScheduling count=None msg=0/6 nodes are available: 3 c_wall violated: 1 conflicting context pair(s) with node memory, 3 node(s) had untolerated taint(s). no new claims to deallocate, preemption: 0/6 nodes are available: 3 No preemption victims found for incoming pod, 3 Preemption is not helpful for scheduling."
0.3872,Event,ADDED,eval-sanitize-30-r1-059-5dmq6.18d4ab462e006e73,"reason=FailedScheduling count=None msg=0/6 nodes are available: 2 c_wall violated: 1 conflicting context pair(s) with node memory, 4 node(s) had untolerated taint(s). no new claims to deallocate, preemption: 0/6 nodes are available: 2 No preemption victims found for incoming pod, 4 Preemption is not helpful for scheduling."
0.3875,Event,ADDED,eval-sanitize-30-r1-059-5dmq6.18d4ab46444f6aa2,"reason=FailedScheduling count=None msg=0/6 nodes are available: 1 c_wall violated: 1 conflicting context pair(s) with node memory, 5 node(s) had untolerated taint(s). no new claims to deallocate, preemption: 0/6 nodes are available: 1 No preemption victims found for incoming pod, 5 Preemption is not helpful for scheduling."
0.3876,Event,ADDED,eval-sanitize-30-r1-059-5dmq6.18d4ab4c65898dfb,"reason=FailedScheduling count=None msg=0/6 nodes are available: 1 c_wall violated: 2 conflicting context pair(s) with node memory, 5 node(s) had untolerated taint(s). no new claims to deallocate, preemption: 0/6 nodes are available: 1 No preemption victims found for incoming pod, 5 Preemption is not helpful for scheduling."
0.3879,Event,ADDED,eval-sanitize-30-r1-059-5dmq6.18d4ab4c9ab5ce07,"reason=FailedScheduling count=None msg=0/6 nodes are available: 1 c_wall violated: 2 conflicting context pair(s) with node memory, 5 node(s) had untolerated taint(s). no new claims to deallocate, preemption: 0/6 nodes are available: 1 No preemption victims found for incoming pod, 5 Preemption is not helpful for scheduling."
0.388,Event,ADDED,eval-sanitize-30-r1-059-5dmq6.18d4ab4ce9470dc4,reason=Scheduled count=None msg=Successfully assigned compute/eval-sanitize-30-r1-059-5dmq6 to kind-worker5
0.3883,Event,ADDED,eval-sanitize-30-r1-059-5dmq6.18d4ab4d074d2b74,"reason=Pulled count=1 msg=Container image ""busybox:musl"" already present on machine"
0.3884,Event,ADDED,eval-sanitize-30-r1-059-5dmq6.18d4ab4d096044d7,reason=Created count=1 msg=Created container: task
0.3886,Event,ADDED,eval-sanitize-30-r1-059-5dmq6.18d4ab4d0d5ece07,reason=Started count=1 msg=Started container task
0.3888,Event,ADDED,eval-sanitize-30-r1-059.18d4ab417f5f312e,reason=SuccessfulCreate count=1 msg=Created pod: eval-sanitize-30-r1-059-5dmq6
0.389,Event,ADDED,eval-sanitize-30-r1-059.18d4ab54759a6e00,reason=Completed count=1 msg=Job completed
0.3891,Event,ADDED,eval-sanitize-30-r1-060-qws2z.18d4ab41c174355f,reason=Scheduled count=None msg=Successfully assigned compute/eval-sanitize-30-r1-060-qws2z to kind-worker5
0.3893,Event,ADDED,eval-sanitize-30-r1-060-qws2z.18d4ab41de509d59,"reason=Pulled count=1 msg=Container image ""busybox:musl"" already present on machine"
0.3895,Event,ADDED,eval-sanitize-30-r1-060-qws2z.18d4ab41dfa620fe,reason=Created count=1 msg=Created container: task
0.3896,Event,ADDED,eval-sanitize-30-r1-060-qws2z.18d4ab41e3c879c9,reason=Started count=1 msg=Started container task
0.3898,Event,ADDED,eval-sanitize-30-r1-060.18d4ab41ba24b066,reason=SuccessfulCreate count=1 msg=Created pod: eval-sanitize-30-r1-060-qws2z
0.39,Event,ADDED,eval-sanitize-30-r1-060.18d4ab4768b34a57,reason=Completed count=1 msg=Job completed
0.3901,Event,ADDED,eval-sanitize-30-r1-061-ff28x.18d4ab41fd126d29,"reason=FailedScheduling count=None msg=0/6 nodes are available: 1 c_wall violated: 3 conflicting context pair(s) with node memory, 1 node(s) had untolerated taint(s), 4 c_wall violated: 1 conflicting context pair(s) with node memory. no new claims to deallocate, preemption: 0/6 nodes are available: 1 Preemption is not helpful for scheduling, 5 No preemption victims found for incoming pod."
0.3904,Event,ADDED,eval-sanitize-30-r1-061-ff28x.18d4ab420f625347,"reason=FailedScheduling count=None msg=0/6 nodes are available: 1 c_wall violated: 3 conflicting context pair(s) with node memory, 1 node(s) had untolerated taint(s), 4 c_wall violated: 1 conflicting context pair(s) with node memory. no new claims to deallocate, preemption: 0/6 nodes are available: 1 Preemption is not helpful for scheduling, 5 No preemption victims found for incoming pod."
0.3906,Event,ADDED,eval-sanitize-30-r1-061-ff28x.18d4ab457af847bd,"reason=FailedScheduling count=None msg=0/6 nodes are available: 2 node(s) had untolerated taint(s), 4 c_wall violated: 1 conflicting context pair(s) with node memory. no new claims to deallocate, preemption: 0/6 nodes are available: 2 Preemption is not helpful for scheduling, 4 No preemption victims found for incoming pod."
0.3908,Event,ADDED,eval-sanitize-30-r1-061-ff28x.18d4ab45d4d59d33,"reason=FailedScheduling count=None msg=0/6 nodes are available: 3 c_wall violated: 1 conflicting context pair(s) with node memory, 3 node(s) had untolerated taint(s). no new claims to deallocate, preemption: 0/6 nodes are available: 3 No preemption victims found for incoming pod, 3 Preemption is not helpful for scheduling."
0.3909,Event,ADDED,eval-sanitize-30-r1-061-ff28x.18d4ab4627ac4197,"reason=FailedScheduling count=None msg=0/6 nodes are available: 2 c_wall violated: 1 conflicting context pair(s) with node memory, 4 node(s) had untolerated taint(s). no new claims to deallocate, preemption: 0/6 nodes are available: 2 No preemption victims found for incoming pod, 4 Preemption is not helpful for scheduling."
0.3911,Event,ADDED,eval-sanitize-30-r1-061-ff28x.18d4ab463fa48731,"reason=FailedScheduling count=None msg=0/6 nodes are available: 1 c_wall violated: 1 conflicting context pair(s) with node memory, 5 node(s) had untolerated taint(s). no new claims to deallocate, preemption: 0/6 nodes are available: 1 No preemption victims found for incoming pod, 5 Preemption is not helpful for scheduling."
0.3913,Event,ADDED,eval-sanitize-30-r1-061-ff28x.18d4ab4c6c3de8e1,"reason=FailedScheduling count=None msg=0/6 nodes are available: 1 c_wall violated: 2 conflicting context pair(s) with node memory, 5 node(s) had untolerated taint(s). no new claims to deallocate, preemption: 0/6 nodes are available: 1 No preemption victims found for incoming pod, 5 Preemption is not helpful for scheduling."
0.3915,Event,ADDED,eval-sanitize-30-r1-061-ff28x.18d4ab4c9b4bbce1,"reason=FailedScheduling count=None msg=0/6 nodes are available: 1 c_wall violated: 2 conflicting context pair(s) with node memory, 5 node(s) had untolerated taint(s). no new claims to deallocate, preemption: 0/6 nodes are available: 1 No preemption victims found for incoming pod, 5 Preemption is not helpful for scheduling."
0.3916,Event,ADDED,eval-sanitize-30-r1-061-ff28x.18d4ab4cf486924b,reason=Scheduled count=None msg=Successfully assigned compute/eval-sanitize-30-r1-061-ff28x to kind-worker5
0.3918,Event,ADDED,eval-sanitize-30-r1-061-ff28x.18d4ab4d12bfc769,"reason=Pulled count=1 msg=Container image ""busybox:musl"" already present on machine"
0.3919,Event,ADDED,eval-sanitize-30-r1-061-ff28x.18d4ab4d14632178,reason=Created count=1 msg=Created container: task
0.3921,Event,ADDED,eval-sanitize-30-r1-061-ff28x.18d4ab4d199e3db0,reason=Started count=1 msg=Started container task
0.3923,Event,ADDED,eval-sanitize-30-r1-061.18d4ab41f702662f,reason=SuccessfulCreate count=1 msg=Created pod: eval-sanitize-30-r1-061-ff28x
0.3924,Event,ADDED,eval-sanitize-30-r1-061.18d4ab5428230f08,reason=Completed count=1 msg=Job completed
0.3926,Event,ADDED,eval-sanitize-30-r1-062-pwqzg.18d4ab42395dfeef,reason=Scheduled count=None msg=Successfully assigned compute/eval-sanitize-30-r1-062-pwqzg to kind-worker3
0.3928,Event,ADDED,eval-sanitize-30-r1-062-pwqzg.18d4ab42572fd9d0,"reason=Pulled count=1 msg=Container image ""busybox:musl"" already present on machine"
0.3929,Event,ADDED,eval-sanitize-30-r1-062-pwqzg.18d4ab4258ab93a9,reason=Created count=1 msg=Created container: task
0.3931,Event,ADDED,eval-sanitize-30-r1-062-pwqzg.18d4ab425ddf16ed,reason=Started count=1 msg=Started container task
0.3933,Event,ADDED,eval-sanitize-30-r1-062.18d4ab4234429f25,reason=SuccessfulCreate count=1 msg=Created pod: eval-sanitize-30-r1-062-pwqzg
0.3935,Event,ADDED,eval-sanitize-30-r1-062.18d4ab478fa8cbbd,reason=Completed count=1 msg=Job completed
0.3936,Event,ADDED,eval-sanitize-30-r1-063-x77bt.18d4ab427e9cc7b1,reason=Scheduled count=None msg=Successfully assigned compute/eval-sanitize-30-r1-063-x77bt to kind-worker
0.3938,Event,ADDED,eval-sanitize-30-r1-063-x77bt.18d4ab429c1874d0,"reason=Pulled count=1 msg=Container image ""busybox:musl"" already present on machine"
0.394,Event,ADDED,eval-sanitize-30-r1-063-x77bt.18d4ab429dec792d,reason=Created count=1 msg=Created container: task
0.3941,Event,ADDED,eval-sanitize-30-r1-063-x77bt.18d4ab42a4ce1a8c,reason=Started count=1 msg=Started container task
0.3943,Event,ADDED,eval-sanitize-30-r1-063.18d4ab42738162b3,reason=SuccessfulCreate count=1 msg=Created pod: eval-sanitize-30-r1-063-x77bt
0.3945,Event,ADDED,eval-sanitize-30-r1-063.18d4ab4836e0f459,reason=Completed count=1 msg=Job completed
0.3946,Event,ADDED,eval-sanitize-30-r1-064-jcdtk.18d4ab42b2200fad,reason=Scheduled count=None msg=Successfully assigned compute/eval-sanitize-30-r1-064-jcdtk to kind-worker2
0.3948,Event,ADDED,eval-sanitize-30-r1-064-jcdtk.18d4ab42d37f40fa,"reason=Pulled count=1 msg=Container image ""busybox:musl"" already present on machine"
0.395,Event,ADDED,eval-sanitize-30-r1-064-jcdtk.18d4ab42d4de5d0e,reason=Created count=1 msg=Created container: task
0.3952,Event,ADDED,eval-sanitize-30-r1-064-jcdtk.18d4ab42d9b0471c,reason=Started count=1 msg=Started container task
0.3955,Event,ADDED,eval-sanitize-30-r1-064.18d4ab42ab8526f7,reason=SuccessfulCreate count=1 msg=Created pod: eval-sanitize-30-r1-064-jcdtk
0.3957,Event,ADDED,eval-sanitize-30-r1-064.18d4ab4874005dc0,reason=Completed count=1 msg=Job completed
0.3958,Event,ADDED,eval-sanitize-30-r1-065-86bxw.18d4ab42f2d9807b,reason=Scheduled count=None msg=Successfully assigned compute/eval-sanitize-30-r1-065-86bxw to kind-worker3
0.396,Event,ADDED,eval-sanitize-30-r1-065-86bxw.18d4ab430f21bb82,"reason=Pulled count=1 msg=Container image ""busybox:musl"" already present on machine"
0.3963,Event,ADDED,eval-sanitize-30-r1-065-86bxw.18d4ab4310b98d50,reason=Created count=1 msg=Created container: task
0.3965,Event,ADDED,eval-sanitize-30-r1-065-86bxw.18d4ab4314c2a8cb,reason=Started count=1 msg=Started container task
0.3967,Event,ADDED,eval-sanitize-30-r1-065.18d4ab42e6329b0a,reason=SuccessfulCreate count=1 msg=Created pod: eval-sanitize-30-r1-065-86bxw
0.3969,Event,ADDED,eval-sanitize-30-r1-065.18d4ab4878c74bd8,reason=Completed count=1 msg=Job completed
0.3971,Event,ADDED,eval-sanitize-30-r1-066-fbt4c.18d4ab432b5df83a,reason=Scheduled count=None msg=Successfully assigned compute/eval-sanitize-30-r1-066-fbt4c to kind-worker3
0.3973,Event,ADDED,eval-sanitize-30-r1-066-fbt4c.18d4ab434b32563a,"reason=Pulled count=1 msg=Container image ""busybox:musl"" already present on machine"
0.3975,Event,ADDED,eval-sanitize-30-r1-066-fbt4c.18d4ab434ca05631,reason=Created count=1 msg=Created container: task
0.3976,Event,ADDED,eval-sanitize-30-r1-066-fbt4c.18d4ab43514c8b0c,reason=Started count=1 msg=Started container task
0.3978,Event,ADDED,eval-sanitize-30-r1-066.18d4ab432067e5d3,reason=SuccessfulCreate count=1 msg=Created pod: eval-sanitize-30-r1-066-fbt4c
0.398,Event,ADDED,eval-sanitize-30-r1-066.18d4ab48b4480ea0,reason=Completed count=1 msg=Job completed
0.3981,Event,ADDED,eval-sanitize-30-r1-067-q2m8z.18d4ab4362fdc849,"reason=FailedScheduling count=None msg=0/6 nodes are available: 1 c_wall violated: 3 conflicting context pair(s) with node memory, 1 node(s) had untolerated taint(s), 4 c_wall violated: 1 conflicting context pair(s) with node memory. no new claims to deallocate, preemption: 0/6 nodes are available: 1 Preemption is not helpful for scheduling, 5 No preemption victims found for incoming pod."
0.3984,Event,ADDED,eval-sanitize-30-r1-067-q2m8z.18d4ab437b1efb11,"reason=FailedScheduling count=None msg=0/6 nodes are available: 1 c_wall violated: 3 conflicting context pair(s) with node memory, 1 node(s) had untolerated taint(s), 4 c_wall violated: 1 conflicting context pair(s) with node memory. no new claims to deallocate, preemption: 0/6 nodes are available: 1 Preemption is not helpful for scheduling, 5 No preemption victims found for incoming pod."
0.3986,Event,ADDED,eval-sanitize-30-r1-067-q2m8z.18d4ab4573e18894,"reason=FailedScheduling count=None msg=0/6 nodes are available: 2 node(s) had untolerated taint(s), 4 c_wall violated: 1 conflicting context pair(s) with node memory. no new claims to deallocate, preemption: 0/6 nodes are available: 2 Preemption is not helpful for scheduling, 4 No preemption victims found for incoming pod."
0.3988,Event,ADDED,eval-sanitize-30-r1-067-q2m8z.18d4ab45e6adcbca,"reason=FailedScheduling count=None msg=0/6 nodes are available: 3 c_wall violated: 1 conflicting context pair(s) with node memory, 3 node(s) had untolerated taint(s). no new claims to deallocate, preemption: 0/6 nodes are available: 3 No preemption victims found for incoming pod, 3 Preemption is not helpful for scheduling."
0.399,Event,ADDED,eval-sanitize-30-r1-067-q2m8z.18d4ab462690e384,"reason=FailedScheduling count=None msg=0/6 nodes are available: 2 c_wall violated: 1 conflicting context pair(s) with node memory, 4 node(s) had untolerated taint(s). no new claims to deallocate, preemption: 0/6 nodes are available: 2 No preemption victims found for incoming pod, 4 Preemption is not helpful for scheduling."
0.3992,Event,ADDED,eval-sanitize-30-r1-067-q2m8z.18d4ab463f646222,"reason=FailedScheduling count=None msg=0/6 nodes are available: 1 c_wall violated: 1 conflicting context pair(s) with node memory, 5 node(s) had untolerated taint(s). no new claims to deallocate, preemption: 0/6 nodes are available: 1 No preemption victims found for incoming pod, 5 Preemption is not helpful for scheduling."
0.3993,Event,ADDED,eval-sanitize-30-r1-067-q2m8z.18d4ab4c66c0ce88,"reason=FailedScheduling count=None msg=0/6 nodes are available: 1 c_wall violated: 2 conflicting context pair(s) with node memory, 5 node(s) had untolerated taint(s). no new claims to deallocate, preemption: 0/6 nodes are available: 1 No preemption victims found for incoming pod, 5 Preemption is not helpful for scheduling."
0.3995,Event,ADDED,eval-sanitize-30-r1-067-q2m8z.18d4ab4c9b01bb62,"reason=FailedScheduling count=None msg=0/6 nodes are available: 1 c_wall violated: 2 conflicting context pair(s) with node memory, 5 node(s) had untolerated taint(s). no new claims to deallocate, preemption: 0/6 nodes are available: 1 No preemption victims found for incoming pod, 5 Preemption is not helpful for scheduling."
0.3997,Event,ADDED,eval-sanitize-30-r1-067-q2m8z.18d4ab4ceea9054d,reason=Scheduled count=None msg=Successfully assigned compute/eval-sanitize-30-r1-067-q2m8z to kind-worker5
0.3998,Event,ADDED,eval-sanitize-30-r1-067-q2m8z.18d4ab4d0c7390b4,"reason=Pulled count=1 msg=Container image ""busybox:musl"" already present on machine"
0.4,Event,ADDED,eval-sanitize-30-r1-067-q2m8z.18d4ab4d0e74bb05,reason=Created count=1 msg=Created container: task
0.4002,Event,ADDED,eval-sanitize-30-r1-067-q2m8z.18d4ab4d132b9bed,reason=Started count=1 msg=Started container task
0.4003,Event,ADDED,eval-sanitize-30-r1-067.18d4ab435af3d796,reason=SuccessfulCreate count=1 msg=Created pod: eval-sanitize-30-r1-067-q2m8z
0.4005,Event,ADDED,eval-sanitize-30-r1-067.18d4ab54339f5f81,reason=Completed count=1 msg=Job completed
0.4007,Event,ADDED,eval-sanitize-30-r1-068-nm6gg.18d4ab43a5d2b378,reason=Scheduled count=None msg=Successfully assigned compute/eval-sanitize-30-r1-068-nm6gg to kind-worker2
0.4008,Event,ADDED,eval-sanitize-30-r1-068-nm6gg.18d4ab43c264b83f,"reason=Pulled count=1 msg=Container image ""busybox:musl"" already present on machine"
0.401,Event,ADDED,eval-sanitize-30-r1-068-nm6gg.18d4ab43c3ce91ab,reason=Created count=1 msg=Created container: task
0.4012,Event,ADDED,eval-sanitize-30-r1-068-nm6gg.18d4ab43c98c8f43,reason=Started count=1 msg=Started container task
0.4013,Event,ADDED,eval-sanitize-30-r1-068.18d4ab439c42a068,reason=SuccessfulCreate count=1 msg=Created pod: eval-sanitize-30-r1-068-nm6gg
0.4015,Event,ADDED,eval-sanitize-30-r1-068.18d4ab4963cff299,reason=Completed count=1 msg=Job completed
0.4017,Event,ADDED,eval-sanitize-30-r1-069-vzr86.18d4ab44029fb901,reason=Scheduled count=None msg=Successfully assigned compute/eval-sanitize-30-r1-069-vzr86 to kind-worker2
0.4018,Event,ADDED,eval-sanitize-30-r1-069-vzr86.18d4ab4426bc8484,"reason=Pulled count=1 msg=Container image ""busybox:musl"" already present on machine"
0.402,Event,ADDED,eval-sanitize-30-r1-069-vzr86.18d4ab44287297b8,reason=Created count=1 msg=Created container: task
0.4022,Event,ADDED,eval-sanitize-30-r1-069-vzr86.18d4ab442d58a626,reason=Started count=1 msg=Started container task
0.4023,Event,ADDED,eval-sanitize-30-r1-069.18d4ab43e6900b04,reason=SuccessfulCreate count=1 msg=Created pod: eval-sanitize-30-r1-069-vzr86
0.4025,Event,ADDED,eval-sanitize-30-r1-069.18d4ab499f410cbb,reason=Completed count=1 msg=Job completed
0.4026,Event,ADDED,eval-sanitize-30-r1-070-r7z8d.18d4ab442e4f6636,reason=Scheduled count=None msg=Successfully assigned compute/eval-sanitize-30-r1-070-r7z8d to kind-worker2
0.4028,Event,ADDED,eval-sanitize-30-r1-070-r7z8d.18d4ab444a808cdf,"reason=Pulled count=1 msg=Container image ""busybox:musl"" already present on machine"
0.403,Event,ADDED,eval-sanitize-30-r1-070-r7z8d.18d4ab444bedff26,reason=Created count=1 msg=Created container: task
0.4031,Event,ADDED,eval-sanitize-30-r1-070-r7z8d.18d4ab445495c74f,reason=Started count=1 msg=Started container task
0.4033,Event,ADDED,eval-sanitize-30-r1-070.18d4ab441e577893,reason=SuccessfulCreate count=1 msg=Created pod: eval-sanitize-30-r1-070-r7z8d
0.4039,Event,ADDED,eval-sanitize-30-r1-070.18d4ab49db3c6aaa,reason=Completed count=1 msg=Job completed
0.4041,Event,ADDED,eval-sanitize-30-r1-071-wfm7j.18d4ab446278100a,reason=Scheduled count=None msg=Successfully assigned compute/eval-sanitize-30-r1-071-wfm7j to kind-worker
0.4043,Event,ADDED,eval-sanitize-30-r1-071-wfm7j.18d4ab448164db7a,"reason=Pulled count=1 msg=Container image ""busybox:musl"" already present on machine"
0.4045,Event,ADDED,eval-sanitize-30-r1-071-wfm7j.18d4ab4482cefa24,reason=Created count=1 msg=Created container: task
0.4049,Event,ADDED,eval-sanitize-30-r1-071-wfm7j.18d4ab4486b92c50,reason=Started count=1 msg=Started container task
0.405,Event,ADDED,eval-sanitize-30-r1-071.18d4ab444cd7c5bd,reason=SuccessfulCreate count=1 msg=Created pod: eval-sanitize-30-r1-071-wfm7j
0.4052,Event,ADDED,eval-sanitize-30-r1-071.18d4ab4a12962115,reason=Completed count=1 msg=Job completed
0.4054,Event,ADDED,eval-sanitize-30-r1-072-lqd7f.18d4ab449dd7b45d,reason=Scheduled count=None msg=Successfully assigned compute/eval-sanitize-30-r1-072-lqd7f to kind-worker
0.4057,Event,ADDED,eval-sanitize-30-r1-072-lqd7f.18d4ab44bab31240,"reason=Pulled count=1 msg=Container image ""busybox:musl"" already present on machine"
0.4059,Event,ADDED,eval-sanitize-30-r1-072-lqd7f.18d4ab44bca10cca,reason=Created count=1 msg=Created container: task
0.4061,Event,ADDED,eval-sanitize-30-r1-072-lqd7f.18d4ab44c764d2db,reason=Started count=1 msg=Started container task
0.4064,Event,ADDED,eval-sanitize-30-r1-072.18d4ab44850c74da,reason=SuccessfulCreate count=1 msg=Created pod: eval-sanitize-30-r1-072-lqd7f
0.4066,Event,ADDED,eval-sanitize-30-r1-072.18d4ab4a4e3c1cd4,reason=Completed count=1 msg=Job completed
0.4067,Event,ADDED,eval-sanitize-30-r1-073-rgv74.18d4ab453646c2fb,reason=Scheduled count=None msg=Successfully assigned compute/eval-sanitize-30-r1-073-rgv74 to kind-worker
0.4069,Event,ADDED,eval-sanitize-30-r1-073-rgv74.18d4ab4567e9c943,"reason=Pulled count=1 msg=Container image ""busybox:musl"" already present on machine"
0.4072,Event,ADDED,eval-sanitize-30-r1-073-rgv74.18d4ab45698da320,reason=Created count=1 msg=Created container: task
0.4074,Event,ADDED,eval-sanitize-30-r1-073-rgv74.18d4ab45716cc6af,reason=Started count=1 msg=Started container task
0.4078,Event,ADDED,eval-sanitize-30-r1-073.18d4ab45237a5c0d,reason=SuccessfulCreate count=1 msg=Created pod: eval-sanitize-30-r1-073-rgv74
0.408,Event,ADDED,eval-sanitize-30-r1-073.18d4ab4b018bcf6a,reason=Completed count=1 msg=Job completed
0.4082,Event,ADDED,eval-sanitize-30-r1-074-4jmgh.18d4ab45811890f8,"reason=FailedScheduling count=None msg=0/6 nodes are available: 2 c_wall violated: 1 conflicting context pair(s) with node memory, 2 c_wall violated: 2 conflicting context pair(s) with node memory, 2 node(s) had untolerated taint(s). no new claims to deallocate, preemption: 0/6 nodes are available: 2 Preemption is not helpful for scheduling, 4 No preemption victims found for incoming pod."
0.4085,Event,ADDED,eval-sanitize-30-r1-074-4jmgh.18d4ab458710e5e2,"reason=FailedScheduling count=None msg=0/6 nodes are available: 2 c_wall violated: 1 conflicting context pair(s) with node memory, 2 c_wall violated: 2 conflicting context pair(s) with node memory, 2 node(s) had untolerated taint(s). no new claims to deallocate, preemption: 0/6 nodes are available: 2 Preemption is not helpful for scheduling, 4 No preemption victims found for incoming pod."
0.4087,Event,ADDED,eval-sanitize-30-r1-074-4jmgh.18d4ab45e04b8a8c,"reason=FailedScheduling count=None msg=0/6 nodes are available: 1 c_wall violated: 1 conflicting context pair(s) with node memory, 2 c_wall violated: 2 conflicting context pair(s) with node memory, 3 node(s) had untolerated taint(s). no new claims to deallocate, preemption: 0/6 nodes are available: 3 No preemption victims found for incoming pod, 3 Preemption is not helpful for scheduling."
0.4089,Event,ADDED,eval-sanitize-30-r1-074-4jmgh.18d4ab46283281a0,"reason=FailedScheduling count=None msg=0/6 nodes are available: 1 c_wall violated: 1 conflicting context pair(s) with node memory, 1 c_wall violated: 2 conflicting context pair(s) with node memory, 4 node(s) had untolerated taint(s). no new claims to deallocate, preemption: 0/6 nodes are available: 2 No preemption victims found for incoming pod, 4 Preemption is not helpful for scheduling."
0.4091,Event,ADDED,eval-sanitize-30-r1-074-4jmgh.18d4ab463fe61860,"reason=FailedScheduling count=None msg=0/6 nodes are available: 1 c_wall violated: 2 conflicting context pair(s) with node memory, 5 node(s) had untolerated taint(s). no new claims to deallocate, preemption: 0/6 nodes are available: 1 No preemption victims found for incoming pod, 5 Preemption is not helpful for scheduling."
0.4092,Event,ADDED,eval-sanitize-30-r1-074-4jmgh.18d4ab4c64f9b862,reason=Scheduled count=None msg=Successfully assigned compute/eval-sanitize-30-r1-074-4jmgh to kind-worker2
0.4094,Event,ADDED,eval-sanitize-30-r1-074-4jmgh.18d4ab4c820342bd,"reason=Pulled count=1 msg=Container image ""busybox:musl"" already present on machine"
0.4096,Event,ADDED,eval-sanitize-30-r1-074-4jmgh.18d4ab4c841e7c14,reason=Created count=1 msg=Created container: task
0.4097,Event,ADDED,eval-sanitize-30-r1-074-4jmgh.18d4ab4c8a07926f,reason=Started count=1 msg=Started container task
0.4099,Event,ADDED,eval-sanitize-30-r1-074.18d4ab457e93c14b,reason=SuccessfulCreate count=1 msg=Created pod: eval-sanitize-30-r1-074-4jmgh
0.4101,Event,ADDED,eval-sanitize-30-r1-074.18d4ab51d201e95a,reason=Completed count=1 msg=Job completed
0.4103,Event,ADDED,eval-sanitize-30-r1-075-wh8xs.18d4ab45dc4f2ead,reason=Scheduled count=None msg=Successfully assigned compute/eval-sanitize-30-r1-075-wh8xs to kind-worker4
0.4104,Event,ADDED,eval-sanitize-30-r1-075-wh8xs.18d4ab45fc1fac9a,"reason=Pulled count=1 msg=Container image ""busybox:musl"" already present on machine"
0.4106,Event,ADDED,eval-sanitize-30-r1-075-wh8xs.18d4ab45fee9c875,reason=Created count=1 msg=Created container: task
0.4109,Event,ADDED,eval-sanitize-30-r1-075-wh8xs.18d4ab4606fcb9bb,reason=Started count=1 msg=Started container task
0.4111,Event,ADDED,eval-sanitize-30-r1-075.18d4ab45d4b0e649,reason=SuccessfulCreate count=1 msg=Created pod: eval-sanitize-30-r1-075-wh8xs
0.4114,Event,ADDED,eval-sanitize-30-r1-075.18d4ab4b6b1f3d46,reason=Completed count=1 msg=Job completed
0.4115,Event,ADDED,eval-sanitize-30-r1-076-8z2xj.18d4ab45fc23cd27,reason=Scheduled count=None msg=Successfully assigned compute/eval-sanitize-30-r1-076-8z2xj to kind-worker
0.4117,Event,ADDED,eval-sanitize-30-r1-076-8z2xj.18d4ab461b62002c,"reason=Pulled count=1 msg=Container image ""busybox:musl"" already present on machine"
0.4119,Event,ADDED,eval-sanitize-30-r1-076-8z2xj.18d4ab461d04c1b3,reason=Created count=1 msg=Created container: task
0.4122,Event,ADDED,eval-sanitize-30-r1-076-8z2xj.18d4ab46218bc9b6,reason=Started count=1 msg=Started container task
0.4124,Event,ADDED,eval-sanitize-30-r1-076.18d4ab45f56ca33c,reason=SuccessfulCreate count=1 msg=Created pod: eval-sanitize-30-r1-076-8z2xj
0.4126,Event,ADDED,eval-sanitize-30-r1-076.18d4ab4bb5a903ff,reason=Completed count=1 msg=Job completed
0.4127,Event,ADDED,eval-sanitize-30-r1-077-8ldwk.18d4ab4620ad21fe,"reason=FailedScheduling count=None msg=0/6 nodes are available: 1 c_wall violated: 1 conflicting context pair(s) with node memory, 1 c_wall violated: 2 conflicting context pair(s) with node memory, 4 node(s) had untolerated taint(s). no new claims to deallocate, preemption: 0/6 nodes are available: 2 No preemption victims found for incoming pod, 4 Preemption is not helpful for scheduling."
0.413,Event,ADDED,eval-sanitize-30-r1-077-8ldwk.18d4ab462d8e700a,"reason=FailedScheduling count=None msg=0/6 nodes are available: 1 c_wall violated: 1 conflicting context pair(s) with node memory, 1 c_wall violated: 2 conflicting context pair(s) with node memory, 4 node(s) had untolerated taint(s). no new claims to deallocate, preemption: 0/6 nodes are available: 2 No preemption victims found for incoming pod, 4 Preemption is not helpful for scheduling."
0.4132,Event,ADDED,eval-sanitize-30-r1-077-8ldwk.18d4ab4640244f9f,"reason=FailedScheduling count=None msg=0/6 nodes are available: 1 c_wall violated: 2 conflicting context pair(s) with node memory, 5 node(s) had untolerated taint(s). no new claims to deallocate, preemption: 0/6 nodes are available: 1 No preemption victims found for incoming pod, 5 Preemption is not helpful for scheduling."
0.4134,Event,ADDED,eval-sanitize-30-r1-077-8ldwk.18d4ab4c6633a490,reason=Scheduled count=None msg=Successfully assigned compute/eval-sanitize-30-r1-077-8ldwk to kind-worker2
0.4137,Event,ADDED,eval-sanitize-30-r1-077-8ldwk.18d4ab4c83163bbe,"reason=Pulled count=1 msg=Container image ""busybox:musl"" already present on machine"
0.4139,Event,ADDED,eval-sanitize-30-r1-077-8ldwk.18d4ab4c86121a08,reason=Created count=1 msg=Created container: task
0.4141,Event,ADDED,eval-sanitize-30-r1-077-8ldwk.18d4ab4c8ae64c45,reason=Started count=1 msg=Started container task
0.4144,Event,ADDED,eval-sanitize-30-r1-077.18d4ab461c29057d,reason=SuccessfulCreate count=1 msg=Created pod: eval-sanitize-30-r1-077-8ldwk
0.4146,Event,ADDED,eval-sanitize-30-r1-077.18d4ab51d623eb37,reason=Completed count=1 msg=Job completed
0.4148,Event,ADDED,eval-sanitize-30-r1-078-zwrdf.18d4ab46496e12bf,reason=Scheduled count=None msg=Successfully assigned compute/eval-sanitize-30-r1-078-zwrdf to kind-worker4
0.4149,Event,ADDED,eval-sanitize-30-r1-078-zwrdf.18d4ab466480701c,"reason=Pulled count=1 msg=Container image ""busybox:musl"" already present on machine"
0.4153,Event,ADDED,eval-sanitize-30-r1-078-zwrdf.18d4ab4665c2f6ce,reason=Created count=1 msg=Created container: task
0.4155,Event,ADDED,eval-sanitize-30-r1-078-zwrdf.18d4ab466d3997e8,reason=Started count=1 msg=Started container task
0.4156,Event,ADDED,eval-sanitize-30-r1-078.18d4ab4648b897e0,reason=SuccessfulCreate count=1 msg=Created pod: eval-sanitize-30-r1-078-zwrdf
0.4158,Event,ADDED,eval-sanitize-30-r1-078.18d4ab4be3ea7466,reason=Completed count=1 msg=Job completed
0.4162,Event,ADDED,eval-sanitize-30-r1-079-qh457.18d4ab4685f4c33f,"reason=FailedScheduling count=None msg=0/6 nodes are available: 6 node(s) had untolerated taint(s). no new claims to deallocate, preemption: 0/6 nodes are available: 6 Preemption is not helpful for scheduling."
0.4164,Event,ADDED,eval-sanitize-30-r1-079-qh457.18d4ab4c71d6bc7c,reason=Scheduled count=None msg=Successfully assigned compute/eval-sanitize-30-r1-079-qh457 to kind-worker2
0.4165,Event,ADDED,eval-sanitize-30-r1-079-qh457.18d4ab4c8c08ef9e,"reason=Pulled count=1 msg=Container image ""busybox:musl"" already present on machine"
0.4168,Event,ADDED,eval-sanitize-30-r1-079-qh457.18d4ab4c8dc58b5f,reason=Created count=1 msg=Created container: task
0.417,Event,ADDED,eval-sanitize-30-r1-079-qh457.18d4ab4c999a460f,reason=Started count=1 msg=Started container task
0.4172,Event,ADDED,eval-sanitize-30-r1-079.18d4ab4685e9ba22,reason=SuccessfulCreate count=1 msg=Created pod: eval-sanitize-30-r1-079-qh457
0.4174,Event,ADDED,eval-sanitize-30-r1-079.18d4ab51d6212106,reason=Completed count=1 msg=Job completed
0.4176,Event,ADDED,eval-sanitize-30-r1-080-75k62.18d4ab46b916cc48,"reason=FailedScheduling count=None msg=0/6 nodes are available: 6 node(s) had untolerated taint(s). no new claims to deallocate, preemption: 0/6 nodes are available: 6 Preemption is not helpful for scheduling."
0.4178,Event,ADDED,eval-sanitize-30-r1-080-75k62.18d4ab4c71d71ca8,reason=Scheduled count=None msg=Successfully assigned compute/eval-sanitize-30-r1-080-75k62 to kind-worker2
0.418,Event,ADDED,eval-sanitize-30-r1-080-75k62.18d4ab4c8c80e1e7,"reason=Pulled count=1 msg=Container image ""busybox:musl"" already present on machine"
0.4183,Event,ADDED,eval-sanitize-30-r1-080-75k62.18d4ab4c8e2fb4d6,reason=Created count=1 msg=Created container: task
0.4185,Event,ADDED,eval-sanitize-30-r1-080-75k62.18d4ab4c97f983d4,reason=Started count=1 msg=Started container task
0.4187,Event,ADDED,eval-sanitize-30-r1-080.18d4ab46b909e864,reason=SuccessfulCreate count=1 msg=Created pod: eval-sanitize-30-r1-080-75k62
0.4188,Event,ADDED,eval-sanitize-30-r1-080.18d4ab51d7069051,reason=Completed count=1 msg=Job completed
0.4191,Event,ADDED,eval-sanitize-30-r1-081-rv87k.18d4ab46d8c8845f,"reason=FailedScheduling count=None msg=0/6 nodes are available: 6 node(s) had untolerated taint(s). no new claims to deallocate, preemption: 0/6 nodes are available: 6 Preemption is not helpful for scheduling."
0.4193,Event,ADDED,eval-sanitize-30-r1-081-rv87k.18d4ab4c6dce0f78,"reason=FailedScheduling count=None msg=0/6 nodes are available: 1 c_wall violated: 3 conflicting context pair(s) with node memory, 5 node(s) had untolerated taint(s). no new claims to deallocate, preemption: 0/6 nodes are available: 1 No preemption victims found for incoming pod, 5 Preemption is not helpful for scheduling."
0.4195,Event,ADDED,eval-sanitize-30-r1-081-rv87k.18d4ab4c9b9b39ce,"reason=FailedScheduling count=None msg=0/6 nodes are available: 1 c_wall violated: 3 conflicting context pair(s) with node memory, 5 node(s) had untolerated taint(s). no new claims to deallocate, preemption: 0/6 nodes are available: 1 No preemption victims found for incoming pod, 5 Preemption is not helpful for scheduling."
0.4198,Event,ADDED,eval-sanitize-30-r1-081-rv87k.18d4ab4d2405867a,"reason=FailedScheduling count=None msg=0/6 nodes are available: 1 c_wall violated: 1 conflicting context pair(s) with node memory, 1 c_wall violated: 3 conflicting context pair(s) with node memory, 4 node(s) had untolerated taint(s). no new claims to deallocate, preemption: 0/6 nodes are available: 2 No preemption victims found for incoming pod, 4 Preemption is not helpful for scheduling."
0.4199,Event,ADDED,eval-sanitize-30-r1-081-rv87k.18d4ab4d97c2f319,reason=Scheduled count=None msg=Successfully assigned compute/eval-sanitize-30-r1-081-rv87k to kind-worker4
0.4201,Event,ADDED,eval-sanitize-30-r1-081-rv87k.18d4ab4db43bfe30,"reason=Pulled count=1 msg=Container image ""busybox:musl"" already present on machine"
0.4203,Event,ADDED,eval-sanitize-30-r1-081-rv87k.18d4ab4db5b663c5,reason=Created count=1 msg=Created container: task
0.4205,Event,ADDED,eval-sanitize-30-r1-081-rv87k.18d4ab4dbac38b0e,reason=Started count=1 msg=Started container task
0.4207,Event,ADDED,eval-sanitize-30-r1-081.18d4ab46d8be6628,reason=SuccessfulCreate count=1 msg=Created pod: eval-sanitize-30-r1-081-rv87k
0.4208,Event,ADDED,eval-sanitize-30-r1-081.18d4ab555d48b6a9,reason=Completed count=1 msg=Job completed
0.4243,Event,ADDED,eval-sanitize-30-r1-082-t8mfq.18d4ab46f9eca912,"reason=FailedScheduling count=None msg=0/6 nodes are available: 6 node(s) had untolerated taint(s). no new claims to deallocate, preemption: 0/6 nodes are available: 6 Preemption is not helpful for scheduling."
0.4244,Event,ADDED,eval-sanitize-30-r1-082-t8mfq.18d4ab4c72b4da04,reason=Scheduled count=None msg=Successfully assigned compute/eval-sanitize-30-r1-082-t8mfq to kind-worker2
0.4246,Event,ADDED,eval-sanitize-30-r1-082-t8mfq.18d4ab4c9803c44b,"reason=Pulled count=1 msg=Container image ""busybox:musl"" already present on machine"
0.4248,Event,ADDED,eval-sanitize-30-r1-082-t8mfq.18d4ab4c9b2b142a,reason=Created count=1 msg=Created container: task
0.425,Event,ADDED,eval-sanitize-30-r1-082-t8mfq.18d4ab4c9f6816be,reason=Started count=1 msg=Started container task
0.4251,Event,ADDED,eval-sanitize-30-r1-082.18d4ab46f9e6a688,reason=SuccessfulCreate count=1 msg=Created pod: eval-sanitize-30-r1-082-t8mfq
0.4253,Event,ADDED,eval-sanitize-30-r1-082.18d4ab51d728dd82,reason=Completed count=1 msg=Job completed
0.4255,Event,ADDED,eval-sanitize-30-r1-083-tzg2s.18d4ab471c63bdcb,"reason=FailedScheduling count=None msg=0/6 nodes are available: 6 node(s) had untolerated taint(s). no new claims to deallocate, preemption: 0/6 nodes are available: 6 Preemption is not helpful for scheduling."
0.4256,Event,ADDED,eval-sanitize-30-r1-083-tzg2s.18d4ab4c73b9915e,reason=Scheduled count=None msg=Successfully assigned compute/eval-sanitize-30-r1-083-tzg2s to kind-worker2
0.4258,Event,ADDED,eval-sanitize-30-r1-083-tzg2s.18d4ab4c943618c5,"reason=Pulled count=1 msg=Container image ""busybox:musl"" already present on machine"
0.426,Event,ADDED,eval-sanitize-30-r1-083-tzg2s.18d4ab4c9610f8ea,reason=Created count=1 msg=Created container: task
0.4261,Event,ADDED,eval-sanitize-30-r1-083-tzg2s.18d4ab4c9a6fdae3,reason=Started count=1 msg=Started container task
0.4263,Event,ADDED,eval-sanitize-30-r1-083.18d4ab471c68cf11,reason=SuccessfulCreate count=1 msg=Created pod: eval-sanitize-30-r1-083-tzg2s
0.4265,Event,ADDED,eval-sanitize-30-r1-083.18d4ab51d52d3a83,reason=Completed count=1 msg=Job completed
0.4267,Event,ADDED,eval-sanitize-30-r1-084-s2grt.18d4ab4758146f9d,"reason=FailedScheduling count=None msg=0/6 nodes are available: 6 node(s) had untolerated taint(s). no new claims to deallocate, preemption: 0/6 nodes are available: 6 Preemption is not helpful for scheduling."
0.4269,Event,ADDED,eval-sanitize-30-r1-084-s2grt.18d4ab4c73bcec29,reason=Scheduled count=None msg=Successfully assigned compute/eval-sanitize-30-r1-084-s2grt to kind-worker2
0.4272,Event,ADDED,eval-sanitize-30-r1-084-s2grt.18d4ab4c980313a0,"reason=Pulled count=1 msg=Container image ""busybox:musl"" already present on machine"
0.4274,Event,ADDED,eval-sanitize-30-r1-084-s2grt.18d4ab4c9a6d0698,reason=Created count=1 msg=Created container: task
0.4277,Event,ADDED,eval-sanitize-30-r1-084-s2grt.18d4ab4c9f24f177,reason=Started count=1 msg=Started container task
0.4279,Event,ADDED,eval-sanitize-30-r1-084.18d4ab4758030472,reason=SuccessfulCreate count=1 msg=Created pod: eval-sanitize-30-r1-084-s2grt
0.428,Event,ADDED,eval-sanitize-30-r1-084.18d4ab53133091ef,reason=Completed count=1 msg=Job completed
0.4282,Event,ADDED,eval-sanitize-30-r1-085-2ptz6.18d4ab478f899627,"reason=FailedScheduling count=None msg=0/6 nodes are available: 6 node(s) had untolerated taint(s). no new claims to deallocate, preemption: 0/6 nodes are available: 6 Preemption is not helpful for scheduling."
0.4285,Event,ADDED,eval-sanitize-30-r1-085-2ptz6.18d4ab4c7695e491,"reason=FailedScheduling count=None msg=0/6 nodes are available: 1 c_wall violated: 2 conflicting context pair(s) with node memory, 5 node(s) had untolerated taint(s). no new claims to deallocate, preemption: 0/6 nodes are available: 1 No preemption victims found for incoming pod, 5 Preemption is not helpful for scheduling."
0.4287,Event,ADDED,eval-sanitize-30-r1-085-2ptz6.18d4ab4ca099dedb,"reason=FailedScheduling count=None msg=0/6 nodes are available: 1 c_wall violated: 2 conflicting context pair(s) with node memory, 5 node(s) had untolerated taint(s). no new claims to deallocate, preemption: 0/6 nodes are available: 1 No preemption victims found for incoming pod, 5 Preemption is not helpful for scheduling."
0.4289,Event,ADDED,eval-sanitize-30-r1-085-2ptz6.18d4ab4cfa974c4e,reason=Scheduled count=None msg=Successfully assigned compute/eval-sanitize-30-r1-085-2ptz6 to kind-worker5
0.4294,Event,ADDED,eval-sanitize-30-r1-085-2ptz6.18d4ab4d19430c74,"reason=Pulled count=1 msg=Container image ""busybox:musl"" already present on machine"
0.4296,Event,ADDED,eval-sanitize-30-r1-085-2ptz6.18d4ab4d1bab0461,reason=Created count=1 msg=Created container: task
0.4297,Event,ADDED,eval-sanitize-30-r1-085-2ptz6.18d4ab4d200c8952,reason=Started count=1 msg=Started container task
0.43,Event,ADDED,eval-sanitize-30-r1-085.18d4ab478f861294,reason=SuccessfulCreate count=1 msg=Created pod: eval-sanitize-30-r1-085-2ptz6
0.4302,Event,ADDED,eval-sanitize-30-r1-085.18d4ab54bd2a2c80,reason=Completed count=1 msg=Job completed
0.4304,Event,ADDED,eval-sanitize-30-r1-086-vs4q2.18d4ab47c7e87827,"reason=FailedScheduling count=None msg=0/6 nodes are available: 6 node(s) had untolerated taint(s). no new claims to deallocate, preemption: 0/6 nodes are available: 6 Preemption is not helpful for scheduling."
0.4305,Event,ADDED,eval-sanitize-30-r1-086-vs4q2.18d4ab4c77d3c2ca,"reason=FailedScheduling count=None msg=0/6 nodes are available: 1 c_wall violated: 3 conflicting context pair(s) with node memory, 5 node(s) had untolerated taint(s). no new claims to deallocate, preemption: 0/6 nodes are available: 1 No preemption victims found for incoming pod, 5 Preemption is not helpful for scheduling."
0.4312,Event,ADDED,eval-sanitize-30-r1-086-vs4q2.18d4ab4ca0d88449,"reason=FailedScheduling count=None msg=0/6 nodes are available: 1 c_wall violated: 3 conflicting context pair(s) with node memory, 5 node(s) had untolerated taint(s). no new claims to deallocate, preemption: 0/6 nodes are available: 1 No preemption victims found for incoming pod, 5 Preemption is not helpful for scheduling."
0.4313,Event,ADDED,eval-sanitize-30-r1-086-vs4q2.18d4ab4d29ac9d93,"reason=FailedScheduling count=None msg=0/6 nodes are available: 1 c_wall violated: 2 conflicting context pair(s) with node memory, 1 c_wall violated: 3 conflicting context pair(s) with node memory, 4 node(s) had untolerated taint(s). no new claims to deallocate, preemption: 0/6 nodes are available: 2 No preemption victims found for incoming pod, 4 Preemption is not helpful for scheduling."
0.4315,Event,ADDED,eval-sanitize-30-r1-086-vs4q2.18d4ab4d4f2422b2,reason=Scheduled count=None msg=Successfully assigned compute/eval-sanitize-30-r1-086-vs4q2 to kind-worker
0.4318,Event,ADDED,eval-sanitize-30-r1-086-vs4q2.18d4ab4d6d272edc,"reason=Pulled count=1 msg=Container image ""busybox:musl"" already present on machine"
0.432,Event,ADDED,eval-sanitize-30-r1-086-vs4q2.18d4ab4d6eecb4cb,reason=Created count=1 msg=Created container: task
0.4321,Event,ADDED,eval-sanitize-30-r1-086-vs4q2.18d4ab4d7432f204,reason=Started count=1 msg=Started container task
0.4323,Event,ADDED,eval-sanitize-30-r1-086.18d4ab47c7dc372a,reason=SuccessfulCreate count=1 msg=Created pod: eval-sanitize-30-r1-086-vs4q2
0.4326,Event,ADDED,eval-sanitize-30-r1-086.18d4ab54ada0ed3d,reason=Completed count=1 msg=Job completed
0.4327,Event,ADDED,eval-sanitize-30-r1-087-nwmdl.18d4ab480351b061,"reason=FailedScheduling count=None msg=0/6 nodes are available: 6 node(s) had untolerated taint(s). no new claims to deallocate, preemption: 0/6 nodes are available: 6 Preemption is not helpful for scheduling."
0.4329,Event,ADDED,eval-sanitize-30-r1-087-nwmdl.18d4ab4c78a10321,"reason=FailedScheduling count=None msg=0/6 nodes are available: 1 c_wall violated: 3 conflicting context pair(s) with node memory, 5 node(s) had untolerated taint(s). no new claims to deallocate, preemption: 0/6 nodes are available: 1 No preemption victims found for incoming pod, 5 Preemption is not helpful for scheduling."
0.4331,Event,ADDED,eval-sanitize-30-r1-087-nwmdl.18d4ab4ca117f6f4,"reason=FailedScheduling count=None msg=0/6 nodes are available: 1 c_wall violated: 3 conflicting context pair(s) with node memory, 5 node(s) had untolerated taint(s). no new claims to deallocate, preemption: 0/6 nodes are available: 1 No preemption victims found for incoming pod, 5 Preemption is not helpful for scheduling."
0.4333,Event,ADDED,eval-sanitize-30-r1-087-nwmdl.18d4ab4d2a2e34e6,"reason=FailedScheduling count=None msg=0/6 nodes are available: 1 c_wall violated: 2 conflicting context pair(s) with node memory, 1 c_wall violated: 3 conflicting context pair(s) with node memory, 4 node(s) had untolerated taint(s). no new claims to deallocate, preemption: 0/6 nodes are available: 2 No preemption victims found for incoming pod, 4 Preemption is not helpful for scheduling."
0.4334,Event,ADDED,eval-sanitize-30-r1-087-nwmdl.18d4ab4d563c392a,reason=Scheduled count=None msg=Successfully assigned compute/eval-sanitize-30-r1-087-nwmdl to kind-worker3
0.4336,Event,ADDED,eval-sanitize-30-r1-087-nwmdl.18d4ab4d739a14ab,"reason=Pulled count=1 msg=Container image ""busybox:musl"" already present on machine"
0.4338,Event,ADDED,eval-sanitize-30-r1-087-nwmdl.18d4ab4d7541a9dc,reason=Created count=1 msg=Created container: task
0.434,Event,ADDED,eval-sanitize-30-r1-087-nwmdl.18d4ab4d788f8b69,reason=Started count=1 msg=Started container task
0.4341,Event,ADDED,eval-sanitize-30-r1-087.18d4ab4803494f3d,reason=SuccessfulCreate count=1 msg=Created pod: eval-sanitize-30-r1-087-nwmdl
0.4343,Event,ADDED,eval-sanitize-30-r1-087.18d4ab54ed4cdad6,reason=Completed count=1 msg=Job completed
0.4344,Event,ADDED,eval-sanitize-30-r1-088-tv6z2.18d4ab483f7e38e1,"reason=FailedScheduling count=None msg=0/6 nodes are available: 6 node(s) had untolerated taint(s). no new claims to deallocate, preemption: 0/6 nodes are available: 6 Preemption is not helpful for scheduling."
0.4346,Event,ADDED,eval-sanitize-30-r1-088-tv6z2.18d4ab4c7c96f403,reason=Scheduled count=None msg=Successfully assigned compute/eval-sanitize-30-r1-088-tv6z2 to kind-worker2
0.4348,Event,ADDED,eval-sanitize-30-r1-088-tv6z2.18d4ab4c9b05f981,"reason=Pulled count=1 msg=Container image ""busybox:musl"" already present on machine"
0.4351,Event,ADDED,eval-sanitize-30-r1-088-tv6z2.18d4ab4c9ca58f8a,reason=Created count=1 msg=Created container: task
0.4353,Event,ADDED,eval-sanitize-30-r1-088-tv6z2.18d4ab4ca072ec6c,reason=Started count=1 msg=Started container task
0.4355,Event,ADDED,eval-sanitize-30-r1-088.18d4ab483f6ed6ef,reason=SuccessfulCreate count=1 msg=Created pod: eval-sanitize-30-r1-088-tv6z2
0.4357,Event,ADDED,eval-sanitize-30-r1-088.18d4ab51d13f0f80,reason=Completed count=1 msg=Job completed
0.4359,Event,ADDED,eval-sanitize-30-r1-089-wr9nc.18d4ab487b894307,"reason=FailedScheduling count=None msg=0/6 nodes are available: 6 node(s) had untolerated taint(s). no new claims to deallocate, preemption: 0/6 nodes are available: 6 Preemption is not helpful for scheduling."
0.4361,Event,ADDED,eval-sanitize-30-r1-089-wr9nc.18d4ab4c7ce5079a,"reason=FailedScheduling count=None msg=0/6 nodes are available: 1 c_wall violated: 1 conflicting context pair(s) with node memory, 5 node(s) had untolerated taint(s). no new claims to deallocate, preemption: 0/6 nodes are available: 1 No preemption victims found for incoming pod, 5 Preemption is not helpful for scheduling."
0.4363,Event,ADDED,eval-sanitize-30-r1-089-wr9nc.18d4ab4ca154b214,"reason=FailedScheduling count=None msg=0/6 nodes are available: 1 c_wall violated: 1 conflicting context pair(s) with node memory, 5 node(s) had untolerated taint(s). no new claims to deallocate, preemption: 0/6 nodes are available: 1 No preemption victims found for incoming pod, 5 Preemption is not helpful for scheduling."
0.4364,Event,ADDED,eval-sanitize-30-r1-089-wr9nc.18d4ab4d2f924863,"reason=FailedScheduling count=None msg=0/6 nodes are available: 1 c_wall violated: 1 conflicting context pair(s) with node memory, 1 c_wall violated: 3 conflicting context pair(s) with node memory, 4 node(s) had untolerated taint(s). no new claims to deallocate, preemption: 0/6 nodes are available: 2 No preemption victims found for incoming pod, 4 Preemption is not helpful for scheduling."
0.4366,Event,ADDED,eval-sanitize-30-r1-089-wr9nc.18d4ab4d5abd15cb,reason=Scheduled count=None msg=Successfully assigned compute/eval-sanitize-30-r1-089-wr9nc to kind-worker3
0.4367,Event,ADDED,eval-sanitize-30-r1-089-wr9nc.18d4ab4d785875cd,"reason=Pulled count=1 msg=Container image ""busybox:musl"" already present on machine"
0.4369,Event,ADDED,eval-sanitize-30-r1-089-wr9nc.18d4ab4d79e4e7ab,reason=Created count=1 msg=Created container: task
0.4371,Event,ADDED,eval-sanitize-30-r1-089-wr9nc.18d4ab4d801f2a60,reason=Started count=1 msg=Started container task
0.4373,Event,ADDED,eval-sanitize-30-r1-089.18d4ab487b7ead78,reason=SuccessfulCreate count=1 msg=Created pod: eval-sanitize-30-r1-089-wr9nc
0.4374,Event,ADDED,eval-sanitize-30-r1-089.18d4ab54e4e0d633,reason=Completed count=1 msg=Job completed
0.4376,Event,ADDED,eval-sanitize-30-r1-090-pt2wt.18d4ab48b5c9540b,"reason=FailedScheduling count=None msg=0/6 nodes are available: 6 node(s) had untolerated taint(s). no new claims to deallocate, preemption: 0/6 nodes are available: 6 Preemption is not helpful for scheduling."
0.4377,Event,ADDED,eval-sanitize-30-r1-090-pt2wt.18d4ab4c7e06ec56,"reason=FailedScheduling count=None msg=0/6 nodes are available: 1 c_wall violated: 1 conflicting context pair(s) with node memory, 5 node(s) had untolerated taint(s). no new claims to deallocate, preemption: 0/6 nodes are available: 1 No preemption victims found for incoming pod, 5 Preemption is not helpful for scheduling."
0.4379,Event,ADDED,eval-sanitize-30-r1-090-pt2wt.18d4ab4ca193e93b,"reason=FailedScheduling count=None msg=0/6 nodes are available: 1 c_wall violated: 1 conflicting context pair(s) with node memory, 5 node(s) had untolerated taint(s). no new claims to deallocate, preemption: 0/6 nodes are available: 1 No preemption victims found for incoming pod, 5 Preemption is not helpful for scheduling."
0.4381,Event,ADDED,eval-sanitize-30-r1-090-pt2wt.18d4ab4d06f0f8b4,reason=Scheduled count=None msg=Successfully assigned compute/eval-sanitize-30-r1-090-pt2wt to kind-worker5
0.4382,Event,ADDED,eval-sanitize-30-r1-090-pt2wt.18d4ab4d219655c6,"reason=Pulled count=1 msg=Container image ""busybox:musl"" already present on machine"
0.4384,Event,ADDED,eval-sanitize-30-r1-090-pt2wt.18d4ab4d23788b88,reason=Created count=1 msg=Created container: task
0.4386,Event,ADDED,eval-sanitize-30-r1-090-pt2wt.18d4ab4d28e59575,reason=Started count=1 msg=Started container task
0.4387,Event,ADDED,eval-sanitize-30-r1-090.18d4ab48b5c1614a,reason=SuccessfulCreate count=1 msg=Created pod: eval-sanitize-30-r1-090-pt2wt
0.4389,Event,ADDED,eval-sanitize-30-r1-090.18d4ab55020c5607,reason=Completed count=1 msg=Job completed
0.4391,Event,ADDED,eval-sanitize-30-r1-091-472zp.18d4ab48f1b68c12,"reason=FailedScheduling count=None msg=0/6 nodes are available: 6 node(s) had untolerated taint(s). no new claims to deallocate, preemption: 0/6 nodes are available: 6 Preemption is not helpful for scheduling."
0.4394,Event,ADDED,eval-sanitize-30-r1-091-472zp.18d4ab4c7eb2fd03,"reason=FailedScheduling count=None msg=0/6 nodes are available: 1 c_wall violated: 1 conflicting context pair(s) with node memory, 5 node(s) had untolerated taint(s). no new claims to deallocate, preemption: 0/6 nodes are available: 1 No preemption victims found for incoming pod, 5 Preemption is not helpful for scheduling."
0.4398,Event,ADDED,eval-sanitize-30-r1-091-472zp.18d4ab4ca6f2bb91,"reason=FailedScheduling count=None msg=0/6 nodes are available: 1 c_wall violated: 1 conflicting context pair(s) with node memory, 5 node(s) had untolerated taint(s). no new claims to deallocate, preemption: 0/6 nodes are available: 1 No preemption victims found for incoming pod, 5 Preemption is not helpful for scheduling."
0.4399,Event,ADDED,eval-sanitize-30-r1-091-472zp.18d4ab4d0c739d6c,reason=Scheduled count=None msg=Successfully assigned compute/eval-sanitize-30-r1-091-472zp to kind-worker5
0.4403,Event,ADDED,eval-sanitize-30-r1-091-472zp.18d4ab4d28eee242,"reason=Pulled count=1 msg=Container image ""busybox:musl"" already present on machine"
0.4405,Event,ADDED,eval-sanitize-30-r1-091-472zp.18d4ab4d2a839d99,reason=Created count=1 msg=Created container: task
0.4407,Event,ADDED,eval-sanitize-30-r1-091-472zp.18d4ab4d30570872,reason=Started count=1 msg=Started container task
0.441,Event,ADDED,eval-sanitize-30-r1-091.18d4ab48f1b5428d,reason=SuccessfulCreate count=1 msg=Created pod: eval-sanitize-30-r1-091-472zp
0.4412,Event,ADDED,eval-sanitize-30-r1-091.18d4ab5471ab6899,reason=Completed count=1 msg=Job completed
0.4414,Event,ADDED,eval-sanitize-30-r1-092-t4xwc.18d4ab492d755007,"reason=FailedScheduling count=None msg=0/6 nodes are available: 6 node(s) had untolerated taint(s). no new claims to deallocate, preemption: 0/6 nodes are available: 6 Preemption is not helpful for scheduling."
0.4415,Event,ADDED,eval-sanitize-30-r1-092-t4xwc.18d4ab4c832ec35b,reason=Scheduled count=None msg=Successfully assigned compute/eval-sanitize-30-r1-092-t4xwc to kind-worker2
0.442,Event,ADDED,eval-sanitize-30-r1-092-t4xwc.18d4ab4ca08fbdd8,"reason=Pulled count=1 msg=Container image ""busybox:musl"" already present on machine"
0.4422,Event,ADDED,eval-sanitize-30-r1-092-t4xwc.18d4ab4ca1fa1e0d,reason=Created count=1 msg=Created container: task
0.4424,Event,ADDED,eval-sanitize-30-r1-092-t4xwc.18d4ab4ca90d0f85,reason=Started count=1 msg=Started container task
0.4426,Event,ADDED,eval-sanitize-30-r1-092.18d4ab492d67e859,reason=SuccessfulCreate count=1 msg=Created pod: eval-sanitize-30-r1-092-t4xwc
0.443,Event,ADDED,eval-sanitize-30-r1-092.18d4ab53296152a1,reason=Completed count=1 msg=Job completed
0.4432,Event,ADDED,eval-sanitize-30-r1-093-fbkw9.18d4ab496bb6c7b4,"reason=FailedScheduling count=None msg=0/6 nodes are available: 6 node(s) had untolerated taint(s). no new claims to deallocate, preemption: 0/6 nodes are available: 6 Preemption is not helpful for scheduling."
0.4434,Event,ADDED,eval-sanitize-30-r1-093-fbkw9.18d4ab4c82fd6cf9,"reason=FailedScheduling count=None msg=0/6 nodes are available: 1 c_wall violated: 1 conflicting context pair(s) with node memory, 5 node(s) had untolerated taint(s). no new claims to deallocate, preemption: 0/6 nodes are available: 1 No preemption victims found for incoming pod, 5 Preemption is not helpful for scheduling."
0.4437,Event,ADDED,eval-sanitize-30-r1-093-fbkw9.18d4ab4ca759cb58,"reason=FailedScheduling count=None msg=0/6 nodes are available: 1 c_wall violated: 1 conflicting context pair(s) with node memory, 5 node(s) had untolerated taint(s). no new claims to deallocate, preemption: 0/6 nodes are available: 1 No preemption victims found for incoming pod, 5 Preemption is not helpful for scheduling."
0.4439,Event,ADDED,eval-sanitize-30-r1-093-fbkw9.18d4ab4d2ffac6cc,"reason=FailedScheduling count=None msg=0/6 nodes are available: 2 c_wall violated: 1 conflicting context pair(s) with node memory, 4 node(s) had untolerated taint(s). no new claims to deallocate, preemption: 0/6 nodes are available: 2 No preemption victims found for incoming pod, 4 Preemption is not helpful for scheduling."
0.4441,Event,ADDED,eval-sanitize-30-r1-093-fbkw9.18d4ab4d668e8713,reason=Scheduled count=None msg=Successfully assigned compute/eval-sanitize-30-r1-093-fbkw9 to kind-worker3
0.4443,Event,ADDED,eval-sanitize-30-r1-093-fbkw9.18d4ab4d80f7a610,"reason=Pulled count=1 msg=Container image ""busybox:musl"" already present on machine"
0.4445,Event,ADDED,eval-sanitize-30-r1-093-fbkw9.18d4ab4d82be242e,reason=Created count=1 msg=Created container: task
0.4447,Event,ADDED,eval-sanitize-30-r1-093-fbkw9.18d4ab4d889490ce,reason=Started count=1 msg=Started container task
0.4449,Event,ADDED,eval-sanitize-30-r1-093.18d4ab496ba9e1ff,reason=SuccessfulCreate count=1 msg=Created pod: eval-sanitize-30-r1-093-fbkw9
0.445,Event,ADDED,eval-sanitize-30-r1-093.18d4ab54e6ec9028,reason=Completed count=1 msg=Job completed
0.4452,Event,ADDED,eval-sanitize-30-r1-094-dcrwf.18d4ab49a40a62b5,"reason=FailedScheduling count=None msg=0/6 nodes are available: 6 node(s) had untolerated taint(s). no new claims to deallocate, preemption: 0/6 nodes are available: 6 Preemption is not helpful for scheduling."
0.4453,Event,ADDED,eval-sanitize-30-r1-094-dcrwf.18d4ab4c840b7efc,"reason=FailedScheduling count=None msg=0/6 nodes are available: 1 c_wall violated: 1 conflicting context pair(s) with node memory, 5 node(s) had untolerated taint(s). no new claims to deallocate, preemption: 0/6 nodes are available: 1 No preemption victims found for incoming pod, 5 Preemption is not helpful for scheduling."
0.4455,Event,ADDED,eval-sanitize-30-r1-094-dcrwf.18d4ab4cac73f479,"reason=FailedScheduling count=None msg=0/6 nodes are available: 1 c_wall violated: 1 conflicting context pair(s) with node memory, 5 node(s) had untolerated taint(s). no new claims to deallocate, preemption: 0/6 nodes are available: 1 No preemption victims found for incoming pod, 5 Preemption is not helpful for scheduling."
0.4457,Event,ADDED,eval-sanitize-30-r1-094-dcrwf.18d4ab4d305ecc0a,"reason=FailedScheduling count=None msg=0/6 nodes are available: 1 c_wall violated: 1 conflicting context pair(s) with node memory, 1 c_wall violated: 3 conflicting context pair(s) with node memory, 4 node(s) had untolerated taint(s). no new claims to deallocate, preemption: 0/6 nodes are available: 2 No preemption victims found for incoming pod, 4 Preemption is not helpful for scheduling."
0.4458,Event,ADDED,eval-sanitize-30-r1-094-dcrwf.18d4ab4d77d4f5d8,reason=Scheduled count=None msg=Successfully assigned compute/eval-sanitize-30-r1-094-dcrwf to kind-worker
0.4462,Event,ADDED,eval-sanitize-30-r1-094-dcrwf.18d4ab4d97d0763d,"reason=Pulled count=1 msg=Container image ""busybox:musl"" already present on machine"
0.4464,Event,ADDED,eval-sanitize-30-r1-094-dcrwf.18d4ab4d9a7598da,reason=Created count=1 msg=Created container: task
0.4465,Event,ADDED,eval-sanitize-30-r1-094-dcrwf.18d4ab4d9f1f765e,reason=Started count=1 msg=Started container task
0.4467,Event,ADDED,eval-sanitize-30-r1-094.18d4ab49a4027bd6,reason=SuccessfulCreate count=1 msg=Created pod: eval-sanitize-30-r1-094-dcrwf
0.447,Event,ADDED,eval-sanitize-30-r1-094.18d4ab5510deb72b,reason=Completed count=1 msg=Job completed
0.4472,Event,ADDED,eval-sanitize-30-r1-095-5tvg4.18d4ab49e05fd460,"reason=FailedScheduling count=None msg=0/6 nodes are available: 6 node(s) had untolerated taint(s). no new claims to deallocate, preemption: 0/6 nodes are available: 6 Preemption is not helpful for scheduling."
0.4474,Event,ADDED,eval-sanitize-30-r1-095-5tvg4.18d4ab4c84ec92b9,"reason=FailedScheduling count=None msg=0/6 nodes are available: 1 c_wall violated: 3 conflicting context pair(s) with node memory, 5 node(s) had untolerated taint(s). no new claims to deallocate, preemption: 0/6 nodes are available: 1 No preemption victims found for incoming pod, 5 Preemption is not helpful for scheduling."
0.4476,Event,ADDED,eval-sanitize-30-r1-095-5tvg4.18d4ab4cadb8e113,"reason=FailedScheduling count=None msg=0/6 nodes are available: 1 c_wall violated: 3 conflicting context pair(s) with node memory, 5 node(s) had untolerated taint(s). no new claims to deallocate, preemption: 0/6 nodes are available: 1 No preemption victims found for incoming pod, 5 Preemption is not helpful for scheduling."
0.4478,Event,ADDED,eval-sanitize-30-r1-095-5tvg4.18d4ab4cd09d5a24,reason=Scheduled count=None msg=Successfully assigned compute/eval-sanitize-30-r1-095-5tvg4 to kind-worker5
0.448,Event,ADDED,eval-sanitize-30-r1-095-5tvg4.18d4ab4ceca77dda,"reason=Pulled count=1 msg=Container image ""busybox:musl"" already present on machine"
0.4481,Event,ADDED,eval-sanitize-30-r1-095-5tvg4.18d4ab4cee5bb1b4,reason=Created count=1 msg=Created container: task
0.4483,Event,ADDED,eval-sanitize-30-r1-095-5tvg4.18d4ab4cf2b909e3,reason=Started count=1 msg=Started container task
0.4485,Event,ADDED,eval-sanitize-30-r1-095.18d4ab49e06094fd,reason=SuccessfulCreate count=1 msg=Created pod: eval-sanitize-30-r1-095-5tvg4
0.4486,Event,ADDED,eval-sanitize-30-r1-095.18d4ab541ebaf543,reason=Completed count=1 msg=Job completed
0.4488,Event,ADDED,eval-sanitize-30-r1-096-rmmxj.18d4ab4a1c5b7806,"reason=FailedScheduling count=None msg=0/6 nodes are available: 6 node(s) had untolerated taint(s). no new claims to deallocate, preemption: 0/6 nodes are available: 6 Preemption is not helpful for scheduling."
0.449,Event,ADDED,eval-sanitize-30-r1-096-rmmxj.18d4ab4c88a5d3e8,"reason=FailedScheduling count=None msg=0/6 nodes are available: 1 c_wall violated: 3 conflicting context pair(s) with node memory, 5 node(s) had untolerated taint(s). no new claims to deallocate, preemption: 0/6 nodes are available: 1 No preemption victims found for incoming pod, 5 Preemption is not helpful for scheduling."
0.4491,Event,ADDED,eval-sanitize-30-r1-096-rmmxj.18d4ab4cae3ab5a8,"reason=FailedScheduling count=None msg=0/6 nodes are available: 1 c_wall violated: 3 conflicting context pair(s) with node memory, 5 node(s) had untolerated taint(s). no new claims to deallocate, preemption: 0/6 nodes are available: 1 No preemption victims found for incoming pod, 5 Preemption is not helpful for scheduling."
0.4494,Event,ADDED,eval-sanitize-30-r1-096-rmmxj.18d4ab4d132c25f0,"reason=FailedScheduling count=None msg=0/6 nodes are available: 1 c_wall violated: 2 conflicting context pair(s) with node memory, 1 c_wall violated: 3 conflicting context pair(s) with node memory, 4 node(s) had untolerated taint(s). no new claims to deallocate, preemption: 0/6 nodes are available: 2 No preemption victims found for incoming pod, 4 Preemption is not helpful for scheduling."
0.4496,Event,ADDED,eval-sanitize-30-r1-096-rmmxj.18d4ab4d35e0a987,"reason=FailedScheduling count=None msg=0/6 nodes are available: 1 c_wall violated: 2 conflicting context pair(s) with node memory, 1 c_wall violated: 3 conflicting context pair(s) with node memory, 4 node(s) had untolerated taint(s). no new claims to deallocate, preemption: 0/6 nodes are available: 2 No preemption victims found for incoming pod, 4 Preemption is not helpful for scheduling."
0.4497,Event,ADDED,eval-sanitize-30-r1-096-rmmxj.18d4ab4d7e111fdd,reason=Scheduled count=None msg=Successfully assigned compute/eval-sanitize-30-r1-096-rmmxj to kind-worker3
0.4499,Event,ADDED,eval-sanitize-30-r1-096-rmmxj.18d4ab4d9f96046a,"reason=Pulled count=1 msg=Container image ""busybox:musl"" already present on machine"
0.4502,Event,ADDED,eval-sanitize-30-r1-096-rmmxj.18d4ab4da12d8479,reason=Created count=1 msg=Created container: task
0.4504,Event,ADDED,eval-sanitize-30-r1-096-rmmxj.18d4ab4da62da5fd,reason=Started count=1 msg=Started container task
0.4506,Event,ADDED,eval-sanitize-30-r1-096.18d4ab4a1c541287,reason=SuccessfulCreate count=1 msg=Created pod: eval-sanitize-30-r1-096-rmmxj
0.4508,Event,ADDED,eval-sanitize-30-r1-096.18d4ab55227d573e,reason=Completed count=1 msg=Job completed
0.4509,Event,ADDED,eval-sanitize-30-r1-097-zmddb.18d4ab4a57539ee4,"reason=FailedScheduling count=None msg=0/6 nodes are available: 6 node(s) had untolerated taint(s). no new claims to deallocate, preemption: 0/6 nodes are available: 6 Preemption is not helpful for scheduling."
0.4511,Event,ADDED,eval-sanitize-30-r1-097-zmddb.18d4ab4c898c772f,"reason=FailedScheduling count=None msg=0/6 nodes are available: 1 c_wall violated: 2 conflicting context pair(s) with node memory, 5 node(s) had untolerated taint(s). no new claims to deallocate, preemption: 0/6 nodes are available: 1 No preemption victims found for incoming pod, 5 Preemption is not helpful for scheduling."
0.4512,Event,ADDED,eval-sanitize-30-r1-097-zmddb.18d4ab4cb36a908e,"reason=FailedScheduling count=None msg=0/6 nodes are available: 1 c_wall violated: 2 conflicting context pair(s) with node memory, 5 node(s) had untolerated taint(s). no new claims to deallocate, preemption: 0/6 nodes are available: 1 No preemption victims found for incoming pod, 5 Preemption is not helpful for scheduling."
0.4514,Event,ADDED,eval-sanitize-30-r1-097-zmddb.18d4ab4cd58f4830,reason=Scheduled count=None msg=Successfully assigned compute/eval-sanitize-30-r1-097-zmddb to kind-worker5
0.4516,Event,ADDED,eval-sanitize-30-r1-097-zmddb.18d4ab4cf25b7f0c,"reason=Pulled count=1 msg=Container image ""busybox:musl"" already present on machine"
0.4517,Event,ADDED,eval-sanitize-30-r1-097-zmddb.18d4ab4cf442864e,reason=Created count=1 msg=Created container: task
0.452,Event,ADDED,eval-sanitize-30-r1-097-zmddb.18d4ab4cfa3ebd8a,reason=Started count=1 msg=Started container task
0.4523,Event,ADDED,eval-sanitize-30-r1-097.18d4ab4a57462b05,reason=SuccessfulCreate count=1 msg=Created pod: eval-sanitize-30-r1-097-zmddb
0.4525,Event,ADDED,eval-sanitize-30-r1-097.18d4ab54643c10a6,reason=Completed count=1 msg=Job completed
0.4526,Event,ADDED,eval-sanitize-30-r1-098-426db.18d4ab4a92c8ff91,"reason=FailedScheduling count=None msg=0/6 nodes are available: 6 node(s) had untolerated taint(s). no new claims to deallocate, preemption: 0/6 nodes are available: 6 Preemption is not helpful for scheduling."
0.4529,Event,ADDED,eval-sanitize-30-r1-098-426db.18d4ab4c8a930cca,"reason=FailedScheduling count=None msg=0/6 nodes are available: 1 c_wall violated: 3 conflicting context pair(s) with node memory, 5 node(s) had untolerated taint(s). no new claims to deallocate, preemption: 0/6 nodes are available: 1 No preemption victims found for incoming pod, 5 Preemption is not helpful for scheduling."
0.4531,Event,ADDED,eval-sanitize-30-r1-098-426db.18d4ab4cb3b08db6,"reason=FailedScheduling count=None msg=0/6 nodes are available: 1 c_wall violated: 3 conflicting context pair(s) with node memory, 5 node(s) had untolerated taint(s). no new claims to deallocate, preemption: 0/6 nodes are available: 1 No preemption victims found for incoming pod, 5 Preemption is not helpful for scheduling."
0.4532,Event,ADDED,eval-sanitize-30-r1-098-426db.18d4ab4d17ed482f,"reason=FailedScheduling count=None msg=0/6 nodes are available: 1 c_wall violated: 2 conflicting context pair(s) with node memory, 1 c_wall violated: 3 conflicting context pair(s) with node memory, 4 node(s) had untolerated taint(s). no new claims to deallocate, preemption: 0/6 nodes are available: 2 No preemption victims found for incoming pod, 4 Preemption is not helpful for scheduling."
0.4534,Event,ADDED,eval-sanitize-30-r1-098-426db.18d4ab4d36597fc1,"reason=FailedScheduling count=None msg=0/6 nodes are available: 1 c_wall violated: 2 conflicting context pair(s) with node memory, 1 c_wall violated: 3 conflicting context pair(s) with node memory, 4 node(s) had untolerated taint(s). no new claims to deallocate, preemption: 0/6 nodes are available: 2 No preemption victims found for incoming pod, 4 Preemption is not helpful for scheduling."
0.4535,Event,ADDED,eval-sanitize-30-r1-098-426db.18d4ab4d845fc310,reason=Scheduled count=None msg=Successfully assigned compute/eval-sanitize-30-r1-098-426db to kind-worker3
0.4537,Event,ADDED,eval-sanitize-30-r1-098-426db.18d4ab4da12eaab0,"reason=Pulled count=1 msg=Container image ""busybox:musl"" already present on machine"
0.4539,Event,ADDED,eval-sanitize-30-r1-098-426db.18d4ab4da2c33956,reason=Created count=1 msg=Created container: task
0.4541,Event,ADDED,eval-sanitize-30-r1-098-426db.18d4ab4da6fcff58,reason=Started count=1 msg=Started container task
0.4542,Event,ADDED,eval-sanitize-30-r1-098.18d4ab4a92c19ffa,reason=SuccessfulCreate count=1 msg=Created pod: eval-sanitize-30-r1-098-426db
0.4544,Event,ADDED,eval-sanitize-30-r1-098.18d4ab5510deb045,reason=Completed count=1 msg=Job completed
0.4545,Event,ADDED,eval-sanitize-30-r1-099-hppch.18d4ab4acec90bf6,"reason=FailedScheduling count=None msg=0/6 nodes are available: 6 node(s) had untolerated taint(s). no new claims to deallocate, preemption: 0/6 nodes are available: 6 Preemption is not helpful for scheduling."
0.4547,Event,ADDED,eval-sanitize-30-r1-099-hppch.18d4ab4c8b7be572,"reason=FailedScheduling count=None msg=0/6 nodes are available: 1 c_wall violated: 1 conflicting context pair(s) with node memory, 5 node(s) had untolerated taint(s). no new claims to deallocate, preemption: 0/6 nodes are available: 1 No preemption victims found for incoming pod, 5 Preemption is not helpful for scheduling."
0.4549,Event,ADDED,eval-sanitize-30-r1-099-hppch.18d4ab4cb4195c35,"reason=FailedScheduling count=None msg=0/6 nodes are available: 1 c_wall violated: 1 conflicting context pair(s) with node memory, 5 node(s) had untolerated taint(s). no new claims to deallocate, preemption: 0/6 nodes are available: 1 No preemption victims found for incoming pod, 5 Preemption is not helpful for scheduling."
0.4551,Event,ADDED,eval-sanitize-30-r1-099-hppch.18d4ab4d1c8fa716,"reason=FailedScheduling count=None msg=0/6 nodes are available: 1 c_wall violated: 1 conflicting context pair(s) with node memory, 1 c_wall violated: 3 conflicting context pair(s) with node memory, 4 node(s) had untolerated taint(s). no new claims to deallocate, preemption: 0/6 nodes are available: 2 No preemption victims found for incoming pod, 4 Preemption is not helpful for scheduling."
0.4553,Event,ADDED,eval-sanitize-30-r1-099-hppch.18d4ab4d3c760dd0,reason=Scheduled count=None msg=Successfully assigned compute/eval-sanitize-30-r1-099-hppch to kind-worker
0.4555,Event,ADDED,eval-sanitize-30-r1-099-hppch.18d4ab4d57aeed2c,"reason=Pulled count=1 msg=Container image ""busybox:musl"" already present on machine"
0.4558,Event,ADDED,eval-sanitize-30-r1-099-hppch.18d4ab4d59eb7c28,reason=Created count=1 msg=Created container: task
0.456,Event,ADDED,eval-sanitize-30-r1-099-hppch.18d4ab4d5f735812,reason=Started count=1 msg=Started container task
0.4562,Event,ADDED,eval-sanitize-30-r1-099.18d4ab4acebd71fb,reason=SuccessfulCreate count=1 msg=Created pod: eval-sanitize-30-r1-099-hppch
0.4563,Event,ADDED,eval-sanitize-30-r1-099.18d4ab5481b8a0d5,reason=Completed count=1 msg=Job completed
0.4565,Event,ADDED,eval-sanitize-30-r1-100-kk7fx.18d4ab4b0a61095c,"reason=FailedScheduling count=None msg=0/6 nodes are available: 6 node(s) had untolerated taint(s). no new claims to deallocate, preemption: 0/6 nodes are available: 6 Preemption is not helpful for scheduling."
0.4567,Event,ADDED,eval-sanitize-30-r1-100-kk7fx.18d4ab4c8f518a8d,reason=Scheduled count=None msg=Successfully assigned compute/eval-sanitize-30-r1-100-kk7fx to kind-worker2
0.4568,Event,ADDED,eval-sanitize-30-r1-100-kk7fx.18d4ab4caf4c1d18,"reason=Pulled count=1 msg=Container image ""busybox:musl"" already present on machine"
0.457,Event,ADDED,eval-sanitize-30-r1-100-kk7fx.18d4ab4cb152d056,reason=Created count=1 msg=Created container: task
0.4573,Event,ADDED,eval-sanitize-30-r1-100-kk7fx.18d4ab4cb5ae68af,reason=Started count=1 msg=Started container task
0.4575,Event,ADDED,eval-sanitize-30-r1-100.18d4ab4b0a54cbab,reason=SuccessfulCreate count=1 msg=Created pod: eval-sanitize-30-r1-100-kk7fx
0.4577,Event,ADDED,eval-sanitize-30-r1-100.18d4ab5213d13656,reason=Completed count=1 msg=Job completed
0.4579,Event,ADDED,eval-sanitize-30-r1-101-vc695.18d4ab4b45feff76,"reason=FailedScheduling count=None msg=0/6 nodes are available: 6 node(s) had untolerated taint(s). no new claims to deallocate, preemption: 0/6 nodes are available: 6 Preemption is not helpful for scheduling."
0.4581,Event,ADDED,eval-sanitize-30-r1-101-vc695.18d4ab4c8ede38d5,"reason=FailedScheduling count=None msg=0/6 nodes are available: 1 c_wall violated: 1 conflicting context pair(s) with node memory, 5 node(s) had untolerated taint(s). no new claims to deallocate, preemption: 0/6 nodes are available: 1 No preemption victims found for incoming pod, 5 Preemption is not helpful for scheduling."
0.4583,Event,ADDED,eval-sanitize-30-r1-101-vc695.18d4ab4cb745619b,"reason=FailedScheduling count=None msg=0/6 nodes are available: 1 c_wall violated: 1 conflicting context pair(s) with node memory, 5 node(s) had untolerated taint(s). no new claims to deallocate, preemption: 0/6 nodes are available: 1 No preemption victims found for incoming pod, 5 Preemption is not helpful for scheduling."
0.4584,Event,ADDED,eval-sanitize-30-r1-101-vc695.18d4ab4d1dfae8d2,"reason=FailedScheduling count=None msg=0/6 nodes are available: 2 c_wall violated: 1 conflicting context pair(s) with node memory, 4 node(s) had untolerated taint(s). no new claims to deallocate, preemption: 0/6 nodes are available: 2 No preemption victims found for incoming pod, 4 Preemption is not helpful for scheduling."
0.4586,Event,ADDED,eval-sanitize-30-r1-101-vc695.18d4ab4d4210b82e,reason=Scheduled count=None msg=Successfully assigned compute/eval-sanitize-30-r1-101-vc695 to kind-worker
0.4587,Event,ADDED,eval-sanitize-30-r1-101-vc695.18d4ab4d5fede571,"reason=Pulled count=1 msg=Container image ""busybox:musl"" already present on machine"
0.4589,Event,ADDED,eval-sanitize-30-r1-101-vc695.18d4ab4d612b3583,reason=Created count=1 msg=Created container: task
0.4592,Event,ADDED,eval-sanitize-30-r1-101-vc695.18d4ab4d669123a0,reason=Started count=1 msg=Started container task
0.4594,Event,ADDED,eval-sanitize-30-r1-101.18d4ab4b45f36b7c,reason=SuccessfulCreate count=1 msg=Created pod: eval-sanitize-30-r1-101-vc695
0.4595,Event,ADDED,eval-sanitize-30-r1-101.18d4ab5495de38be,reason=Completed count=1 msg=Job completed
0.4598,Event,ADDED,eval-sanitize-30-r1-102-r2g4p.18d4ab4b819c4d77,"reason=FailedScheduling count=None msg=0/6 nodes are available: 6 node(s) had untolerated taint(s). no new claims to deallocate, preemption: 0/6 nodes are available: 6 Preemption is not helpful for scheduling."
0.4599,Event,ADDED,eval-sanitize-30-r1-102-r2g4p.18d4ab4c920ac597,reason=Scheduled count=None msg=Successfully assigned compute/eval-sanitize-30-r1-102-r2g4p to kind-worker2
0.4601,Event,ADDED,eval-sanitize-30-r1-102-r2g4p.18d4ab4cb16ee686,"reason=Pulled count=1 msg=Container image ""busybox:musl"" already present on machine"
0.4603,Event,ADDED,eval-sanitize-30-r1-102-r2g4p.18d4ab4cb2fad1db,reason=Created count=1 msg=Created container: task
0.4604,Event,ADDED,eval-sanitize-30-r1-102-r2g4p.18d4ab4cb600bcb5,reason=Started count=1 msg=Started container task
0.4606,Event,ADDED,eval-sanitize-30-r1-102.18d4ab4b818e32a3,reason=SuccessfulCreate count=1 msg=Created pod: eval-sanitize-30-r1-102-r2g4p
0.4608,Event,ADDED,eval-sanitize-30-r1-102.18d4ab53041a288c,reason=Completed count=1 msg=Job completed
0.4609,Event,ADDED,eval-sanitize-30-r1-103-hjjxf.18d4ab4bbd788f14,"reason=FailedScheduling count=None msg=0/6 nodes are available: 6 node(s) had untolerated taint(s). no new claims to deallocate, preemption: 0/6 nodes are available: 6 Preemption is not helpful for scheduling."
0.4611,Event,ADDED,eval-sanitize-30-r1-103-hjjxf.18d4ab4c90d570e6,"reason=FailedScheduling count=None msg=0/6 nodes are available: 1 c_wall violated: 1 conflicting context pair(s) with node memory, 5 node(s) had untolerated taint(s). no new claims to deallocate, preemption: 0/6 nodes are available: 1 No preemption victims found for incoming pod, 5 Preemption is not helpful for scheduling."
0.4613,Event,ADDED,eval-sanitize-30-r1-103-hjjxf.18d4ab4cb8788ac5,"reason=FailedScheduling count=None msg=0/6 nodes are available: 1 c_wall violated: 1 conflicting context pair(s) with node memory, 5 node(s) had untolerated taint(s). no new claims to deallocate, preemption: 0/6 nodes are available: 1 No preemption victims found for incoming pod, 5 Preemption is not helpful for scheduling."
0.4614,Event,ADDED,eval-sanitize-30-r1-103-hjjxf.18d4ab4cddf01525,reason=Scheduled count=None msg=Successfully assigned compute/eval-sanitize-30-r1-103-hjjxf to kind-worker5
0.4616,Event,ADDED,eval-sanitize-30-r1-103-hjjxf.18d4ab4cfa44c791,"reason=Pulled count=1 msg=Container image ""busybox:musl"" already present on machine"
0.4618,Event,ADDED,eval-sanitize-30-r1-103-hjjxf.18d4ab4cfc0b4fb7,reason=Created count=1 msg=Created container: task
0.4619,Event,ADDED,eval-sanitize-30-r1-103-hjjxf.18d4ab4cff5bea1c,reason=Started count=1 msg=Started container task
0.4624,Event,ADDED,eval-sanitize-30-r1-103.18d4ab4bbd69dce2,reason=SuccessfulCreate count=1 msg=Created pod: eval-sanitize-30-r1-103-hjjxf
0.4626,Event,ADDED,eval-sanitize-30-r1-103.18d4ab54addb87aa,reason=Completed count=1 msg=Job completed
0.4627,Event,ADDED,eval-sanitize-30-r1-104-mfh4x.18d4ab4bf99cdc39,"reason=FailedScheduling count=None msg=0/6 nodes are available: 6 node(s) had untolerated taint(s). no new claims to deallocate, preemption: 0/6 nodes are available: 6 Preemption is not helpful for scheduling."
0.4629,Event,ADDED,eval-sanitize-30-r1-104-mfh4x.18d4ab4c94ec4011,"reason=FailedScheduling count=None msg=0/6 nodes are available: 1 c_wall violated: 3 conflicting context pair(s) with node memory, 5 node(s) had untolerated taint(s). no new claims to deallocate, preemption: 0/6 nodes are available: 1 No preemption victims found for incoming pod, 5 Preemption is not helpful for scheduling."
0.4632,Event,ADDED,eval-sanitize-30-r1-104-mfh4x.18d4ab4cb8b4cc89,"reason=FailedScheduling count=None msg=0/6 nodes are available: 1 c_wall violated: 3 conflicting context pair(s) with node memory, 5 node(s) had untolerated taint(s). no new claims to deallocate, preemption: 0/6 nodes are available: 1 No preemption victims found for incoming pod, 5 Preemption is not helpful for scheduling."
0.4634,Event,ADDED,eval-sanitize-30-r1-104-mfh4x.18d4ab4d1e817a4f,"reason=FailedScheduling count=None msg=0/6 nodes are available: 1 c_wall violated: 1 conflicting context pair(s) with node memory, 1 c_wall violated: 3 conflicting context pair(s) with node memory, 4 node(s) had untolerated taint(s). no new claims to deallocate, preemption: 0/6 nodes are available: 2 No preemption victims found for incoming pod, 4 Preemption is not helpful for scheduling."
0.4635,Event,ADDED,eval-sanitize-30-r1-104-mfh4x.18d4ab4d90013f94,reason=Scheduled count=None msg=Successfully assigned compute/eval-sanitize-30-r1-104-mfh4x to kind-worker4
0.4639,Event,ADDED,eval-sanitize-30-r1-104-mfh4x.18d4ab4dabc033a6,"reason=Pulled count=1 msg=Container image ""busybox:musl"" already present on machine"
0.4641,Event,ADDED,eval-sanitize-30-r1-104-mfh4x.18d4ab4dad9f77fa,reason=Created count=1 msg=Created container: task
0.4642,Event,ADDED,eval-sanitize-30-r1-104-mfh4x.18d4ab4db42a4f4c,reason=Started count=1 msg=Started container task
0.4644,Event,ADDED,eval-sanitize-30-r1-104.18d4ab4bf98faa05,reason=SuccessfulCreate count=1 msg=Created pod: eval-sanitize-30-r1-104-mfh4x
0.4647,Event,ADDED,eval-sanitize-30-r1-104.18d4ab553532aff7,reason=Completed count=1 msg=Job completed
0.4649,Event,ADDED,eval-sanitize-30-r1-105-x4zv8.18d4ab4c35ed9350,"reason=FailedScheduling count=None msg=0/6 nodes are available: 6 node(s) had untolerated taint(s). no new claims to deallocate, preemption: 0/6 nodes are available: 6 Preemption is not helpful for scheduling."
0.4651,Event,ADDED,eval-sanitize-30-r1-105-x4zv8.18d4ab4c96df5da3,"reason=FailedScheduling count=None msg=0/6 nodes are available: 1 c_wall violated: 1 conflicting context pair(s) with node memory, 5 node(s) had untolerated taint(s). no new claims to deallocate, preemption: 0/6 nodes are available: 1 No preemption victims found for incoming pod, 5 Preemption is not helpful for scheduling."
0.4654,Event,ADDED,eval-sanitize-30-r1-105-x4zv8.18d4ab4cb922301b,"reason=FailedScheduling count=None msg=0/6 nodes are available: 1 c_wall violated: 1 conflicting context pair(s) with node memory, 5 node(s) had untolerated taint(s). no new claims to deallocate, preemption: 0/6 nodes are available: 1 No preemption victims found for incoming pod, 5 Preemption is not helpful for scheduling."
0.4656,Event,ADDED,eval-sanitize-30-r1-105-x4zv8.18d4ab4ce8b064c9,reason=Scheduled count=None msg=Successfully assigned compute/eval-sanitize-30-r1-105-x4zv8 to kind-worker5
0.4659,Event,ADDED,eval-sanitize-30-r1-105-x4zv8.18d4ab4d06a410e0,"reason=Pulled count=1 msg=Container image ""busybox:musl"" already present on machine"
0.4665,Event,ADDED,eval-sanitize-30-r1-105-x4zv8.18d4ab4d08aede55,reason=Created count=1 msg=Created container: task
0.4669,Event,ADDED,eval-sanitize-30-r1-105-x4zv8.18d4ab4d0d5ee145,reason=Started count=1 msg=Started container task
0.4674,Event,ADDED,eval-sanitize-30-r1-105.18d4ab4c35e265a7,reason=SuccessfulCreate count=1 msg=Created pod: eval-sanitize-30-r1-105-x4zv8
0.468,Event,ADDED,eval-sanitize-30-r1-105.18d4ab543a2cb3b5,reason=Completed count=1 msg=Job completed
0.4683,Event,ADDED,eval-sanitize-30-r1-106-km7sd.18d4ab4c95ae4acb,"reason=FailedScheduling count=None msg=0/6 nodes are available: 1 c_wall violated: 3 conflicting context pair(s) with node memory, 5 node(s) had untolerated taint(s). no new claims to deallocate, preemption: 0/6 nodes are available: 1 No preemption victims found for incoming pod, 5 Preemption is not helpful for scheduling."
0.4685,Event,ADDED,eval-sanitize-30-r1-106-km7sd.18d4ab4cb8e8becb,"reason=FailedScheduling count=None msg=0/6 nodes are available: 1 c_wall violated: 3 conflicting context pair(s) with node memory, 5 node(s) had untolerated taint(s). no new claims to deallocate, preemption: 0/6 nodes are available: 1 No preemption victims found for incoming pod, 5 Preemption is not helpful for scheduling."
0.4687,Event,ADDED,eval-sanitize-30-r1-106-km7sd.18d4ab4ce371903a,reason=Scheduled count=None msg=Successfully assigned compute/eval-sanitize-30-r1-106-km7sd to kind-worker5
0.4692,Event,ADDED,eval-sanitize-30-r1-106-km7sd.18d4ab4cff63e8e3,"reason=Pulled count=1 msg=Container image ""busybox:musl"" already present on machine"
0.4697,Event,ADDED,eval-sanitize-30-r1-106-km7sd.18d4ab4d01c61281,reason=Created count=1 msg=Created container: task
0.4701,Event,ADDED,eval-sanitize-30-r1-106-km7sd.18d4ab4d074e2099,reason=Started count=1 msg=Started container task
0.4704,Event,ADDED,eval-sanitize-30-r1-106.18d4ab4c6fdbefbb,reason=SuccessfulCreate count=1 msg=Created pod: eval-sanitize-30-r1-106-km7sd
0.4708,Event,ADDED,eval-sanitize-30-r1-106.18d4ab54802d9b9d,reason=Completed count=1 msg=Job completed
0.471,Event,ADDED,eval-sanitize-30-r1-107-4wn4g.18d4ab4cacc3efd3,"reason=FailedScheduling count=None msg=0/6 nodes are available: 1 c_wall violated: 2 conflicting context pair(s) with node memory, 5 node(s) had untolerated taint(s). no new claims to deallocate, preemption: 0/6 nodes are available: 1 No preemption victims found for incoming pod, 5 Preemption is not helpful for scheduling."
0.4712,Event,ADDED,eval-sanitize-30-r1-107-4wn4g.18d4ab4ccb68c766,reason=Scheduled count=None msg=Successfully assigned compute/eval-sanitize-30-r1-107-4wn4g to kind-worker5
0.4715,Event,ADDED,eval-sanitize-30-r1-107-4wn4g.18d4ab4ce6be523e,"reason=Pulled count=1 msg=Container image ""busybox:musl"" already present on machine"
0.4717,Event,ADDED,eval-sanitize-30-r1-107-4wn4g.18d4ab4ce8415fb4,reason=Created count=1 msg=Created container: task
0.4719,Event,ADDED,eval-sanitize-30-r1-107-4wn4g.18d4ab4cedb4793a,reason=Started count=1 msg=Started container task
0.4721,Event,ADDED,eval-sanitize-30-r1-107.18d4ab4cac25e249,reason=SuccessfulCreate count=1 msg=Created pod: eval-sanitize-30-r1-107-4wn4g
0.4724,Event,ADDED,eval-sanitize-30-r1-107.18d4ab5472a2c342,reason=Completed count=1 msg=Job completed
0.4726,Event,ADDED,eval-sanitize-30-r1-108-r7r69.18d4ab4cef192476,reason=Scheduled count=None msg=Successfully assigned compute/eval-sanitize-30-r1-108-r7r69 to kind-worker2
0.473,Event,ADDED,eval-sanitize-30-r1-108-r7r69.18d4ab4d0c42c864,"reason=Pulled count=1 msg=Container image ""busybox:musl"" already present on machine"
0.4731,Event,ADDED,eval-sanitize-30-r1-108-r7r69.18d4ab4d0e443768,reason=Created count=1 msg=Created container: task
0.4733,Event,ADDED,eval-sanitize-30-r1-108-r7r69.18d4ab4d1302b6e0,reason=Started count=1 msg=Started container task
0.4736,Event,ADDED,eval-sanitize-30-r1-108.18d4ab4cecfa6f66,reason=SuccessfulCreate count=1 msg=Created pod: eval-sanitize-30-r1-108-r7r69
0.474,Event,ADDED,eval-sanitize-30-r1-108.18d4ab541343a0c6,reason=Completed count=1 msg=Job completed
0.4742,Event,ADDED,eval-sanitize-30-r1-109-pffvq.18d4ab4d25487ed0,reason=Scheduled count=None msg=Successfully assigned compute/eval-sanitize-30-r1-109-pffvq to kind-worker2
0.4744,Event,ADDED,eval-sanitize-30-r1-109-pffvq.18d4ab4d3f79fb04,"reason=Pulled count=1 msg=Container image ""busybox:musl"" already present on machine"
0.4747,Event,ADDED,eval-sanitize-30-r1-109-pffvq.18d4ab4d40caaf9f,reason=Created count=1 msg=Created container: task
0.4749,Event,ADDED,eval-sanitize-30-r1-109-pffvq.18d4ab4d45840084,reason=Started count=1 msg=Started container task
0.4752,Event,ADDED,eval-sanitize-30-r1-109.18d4ab4d22e914e8,reason=SuccessfulCreate count=1 msg=Created pod: eval-sanitize-30-r1-109-pffvq
0.4754,Event,ADDED,eval-sanitize-30-r1-109.18d4ab54f8d7f4af,reason=Completed count=1 msg=Job completed
0.4758,Event,ADDED,eval-sanitize-30-r1-110-95zv2.18d4ab4d6c2e44af,reason=Scheduled count=None msg=Successfully assigned compute/eval-sanitize-30-r1-110-95zv2 to kind-worker2
0.476,Event,ADDED,eval-sanitize-30-r1-110-95zv2.18d4ab4d88ba8c97,"reason=Pulled count=1 msg=Container image ""busybox:musl"" already present on machine"
0.4762,Event,ADDED,eval-sanitize-30-r1-110-95zv2.18d4ab4d8a1da60c,reason=Created count=1 msg=Created container: task
0.4763,Event,ADDED,eval-sanitize-30-r1-110-95zv2.18d4ab4d8fde8c6c,reason=Started count=1 msg=Started container task
0.4768,Event,ADDED,eval-sanitize-30-r1-110.18d4ab4d5e2bece4,reason=SuccessfulCreate count=1 msg=Created pod: eval-sanitize-30-r1-110-95zv2
0.477,Event,ADDED,eval-sanitize-30-r1-110.18d4ab54efc87336,reason=Completed count=1 msg=Job completed
0.4772,Event,ADDED,eval-sanitize-30-r1-111-hvmr2.18d4ab4da23a625b,reason=Scheduled count=None msg=Successfully assigned compute/eval-sanitize-30-r1-111-hvmr2 to kind-worker4
0.4775,Event,ADDED,eval-sanitize-30-r1-111-hvmr2.18d4ab4dc17312d6,"reason=Pulled count=1 msg=Container image ""busybox:musl"" already present on machine"
0.4776,Event,ADDED,eval-sanitize-30-r1-111-hvmr2.18d4ab4dc302f023,reason=Created count=1 msg=Created container: task
0.4778,Event,ADDED,eval-sanitize-30-r1-111-hvmr2.18d4ab4dc8d6c7f0,reason=Started count=1 msg=Started container task
0.478,Event,ADDED,eval-sanitize-30-r1-111.18d4ab4d9c9c3e52,reason=SuccessfulCreate count=1 msg=Created pod: eval-sanitize-30-r1-111-hvmr2
0.4784,Event,ADDED,eval-sanitize-30-r1-111.18d4ab55375bbfc4,reason=Completed count=1 msg=Job completed
0.4788,Event,ADDED,eval-sanitize-30-r1-112-bf6dh.18d4ab4ddc9d69b8,reason=Scheduled count=None msg=Successfully assigned compute/eval-sanitize-30-r1-112-bf6dh to kind-worker2
0.4789,Event,ADDED,eval-sanitize-30-r1-112-bf6dh.18d4ab4df8638281,"reason=Pulled count=1 msg=Container image ""busybox:musl"" already present on machine"
0.4792,Event,ADDED,eval-sanitize-30-r1-112-bf6dh.18d4ab4df9b887a8,reason=Created count=1 msg=Created container: task
0.4796,Event,ADDED,eval-sanitize-30-r1-112-bf6dh.18d4ab4dffe329ad,reason=Started count=1 msg=Started container task
0.4798,Event,ADDED,eval-sanitize-30-r1-112.18d4ab4dd537b698,reason=SuccessfulCreate count=1 msg=Created pod: eval-sanitize-30-r1-112-bf6dh
0.48,Event,ADDED,eval-sanitize-30-r1-112.18d4ab555e48ced8,reason=Completed count=1 msg=Job completed
0.4803,Event,ADDED,eval-sanitize-30-r1-113-tvbtq.18d4ab4e1aea29ce,reason=Scheduled count=None msg=Successfully assigned compute/eval-sanitize-30-r1-113-tvbtq to kind-worker
0.4805,Event,ADDED,eval-sanitize-30-r1-113-tvbtq.18d4ab4e3caefcea,"reason=Pulled count=1 msg=Container image ""busybox:musl"" already present on machine"
0.4806,Event,ADDED,eval-sanitize-30-r1-113-tvbtq.18d4ab4e3e1de6e7,reason=Created count=1 msg=Created container: task
0.4808,Event,ADDED,eval-sanitize-30-r1-113-tvbtq.18d4ab4e42cea732,reason=Started count=1 msg=Started container task
0.4811,Event,ADDED,eval-sanitize-30-r1-113.18d4ab4e1103c954,reason=SuccessfulCreate count=1 msg=Created pod: eval-sanitize-30-r1-113-tvbtq
0.4813,Event,ADDED,eval-sanitize-30-r1-113.18d4ab556d70b37b,reason=Completed count=1 msg=Job completed
0.4815,Event,ADDED,eval-sanitize-30-r1-114-nq96t.18d4ab4e572f0b7f,reason=Scheduled count=None msg=Successfully assigned compute/eval-sanitize-30-r1-114-nq96t to kind-worker3
0.4816,Event,ADDED,eval-sanitize-30-r1-114-nq96t.18d4ab4e739f1f28,"reason=Pulled count=1 msg=Container image ""busybox:musl"" already present on machine"
0.4819,Event,ADDED,eval-sanitize-30-r1-114-nq96t.18d4ab4e75053172,reason=Created count=1 msg=Created container: task
0.4821,Event,ADDED,eval-sanitize-30-r1-114-nq96t.18d4ab4e7a4225b9,reason=Started count=1 msg=Started container task
0.4822,Event,ADDED,eval-sanitize-30-r1-114.18d4ab4e4df73594,reason=SuccessfulCreate count=1 msg=Created pod: eval-sanitize-30-r1-114-nq96t
0.4824,Event,ADDED,eval-sanitize-30-r1-114.18d4ab558d7d54bf,reason=Completed count=1 msg=Job completed
0.4826,Event,ADDED,eval-sanitize-30-r1-115-29xwk.18d4ab4e8ce44d43,reason=Scheduled count=None msg=Successfully assigned compute/eval-sanitize-30-r1-115-29xwk to kind-worker2
0.4827,Event,ADDED,eval-sanitize-30-r1-115-29xwk.18d4ab4eb06e506c,"reason=Pulled count=1 msg=Container image ""busybox:musl"" already present on machine"
0.4829,Event,ADDED,eval-sanitize-30-r1-115-29xwk.18d4ab4eb1bfd466,reason=Created count=1 msg=Created container: task
0.4832,Event,ADDED,eval-sanitize-30-r1-115-29xwk.18d4ab4ebc80c84e,reason=Started count=1 msg=Started container task
0.4834,Event,ADDED,eval-sanitize-30-r1-115.18d4ab4e8b57abb3,reason=SuccessfulCreate count=1 msg=Created pod: eval-sanitize-30-r1-115-29xwk
0.4835,Event,ADDED,eval-sanitize-30-r1-115.18d4ab55a2b14346,reason=Completed count=1 msg=Job completed
0.4837,Event,ADDED,eval-sanitize-30-r1-116-j2n42.18d4ab4ecadfe981,reason=Scheduled count=None msg=Successfully assigned compute/eval-sanitize-30-r1-116-j2n42 to kind-worker3
0.484,Event,ADDED,eval-sanitize-30-r1-116-j2n42.18d4ab4ee70c3c0a,"reason=Pulled count=1 msg=Container image ""busybox:musl"" already present on machine"
0.4842,Event,ADDED,eval-sanitize-30-r1-116-j2n42.18d4ab4ee882b627,reason=Created count=1 msg=Created container: task
0.4844,Event,ADDED,eval-sanitize-30-r1-116-j2n42.18d4ab4eed0f48c2,reason=Started count=1 msg=Started container task
0.4847,Event,ADDED,eval-sanitize-30-r1-116.18d4ab4ec43c2e29,reason=SuccessfulCreate count=1 msg=Created pod: eval-sanitize-30-r1-116-j2n42
0.4849,Event,ADDED,eval-sanitize-30-r1-116.18d4ab55ae1d2df3,reason=Completed count=1 msg=Job completed
0.4851,Event,ADDED,eval-sanitize-30-r1-117-9tbgs.18d4ab4f075c06ac,reason=Scheduled count=None msg=Successfully assigned compute/eval-sanitize-30-r1-117-9tbgs to kind-worker
0.4853,Event,ADDED,eval-sanitize-30-r1-117-9tbgs.18d4ab4f2313f292,"reason=Pulled count=1 msg=Container image ""busybox:musl"" already present on machine"
0.4856,Event,ADDED,eval-sanitize-30-r1-117-9tbgs.18d4ab4f24797730,reason=Created count=1 msg=Created container: task
0.4858,Event,ADDED,eval-sanitize-30-r1-117-9tbgs.18d4ab4f2bc8f29a,reason=Started count=1 msg=Started container task
0.486,Event,ADDED,eval-sanitize-30-r1-117.18d4ab4f00125590,reason=SuccessfulCreate count=1 msg=Created pod: eval-sanitize-30-r1-117-9tbgs
0.4862,Event,ADDED,eval-sanitize-30-r1-117.18d4ab55d24fdec2,reason=Completed count=1 msg=Job completed
0.4865,Event,ADDED,eval-sanitize-30-r1-118-9hhjk.18d4ab4f4e7d77ee,reason=Scheduled count=None msg=Successfully assigned compute/eval-sanitize-30-r1-118-9hhjk to kind-worker2
0.4867,Event,ADDED,eval-sanitize-30-r1-118-9hhjk.18d4ab4f6c698d63,"reason=Pulled count=1 msg=Container image ""busybox:musl"" already present on machine"
0.4868,Event,ADDED,eval-sanitize-30-r1-118-9hhjk.18d4ab4f6dd7d2bd,reason=Created count=1 msg=Created container: task
0.4872,Event,ADDED,eval-sanitize-30-r1-118-9hhjk.18d4ab4f73cf3a2b,reason=Started count=1 msg=Started container task
0.4875,Event,ADDED,eval-sanitize-30-r1-118.18d4ab4f42bae7c8,reason=SuccessfulCreate count=1 msg=Created pod: eval-sanitize-30-r1-118-9hhjk
0.4877,Event,ADDED,eval-sanitize-30-r1-118.18d4ab55d8d5970a,reason=Completed count=1 msg=Job completed
0.4878,Event,ADDED,eval-sanitize-30-r1-119-p7vtg.18d4ab4f7dafcc15,reason=Scheduled count=None msg=Successfully assigned compute/eval-sanitize-30-r1-119-p7vtg to kind-worker
0.4882,Event,ADDED,eval-sanitize-30-r1-119-p7vtg.18d4ab4f9b7a90e6,"reason=Pulled count=1 msg=Container image ""busybox:musl"" already present on machine"
0.4884,Event,ADDED,eval-sanitize-30-r1-119-p7vtg.18d4ab4f9cf22ad3,reason=Created count=1 msg=Created container: task
0.4886,Event,ADDED,eval-sanitize-30-r1-119-p7vtg.18d4ab4fa1e93433,reason=Started count=1 msg=Started container task
0.4888,Event,ADDED,eval-sanitize-30-r1-119.18d4ab4f7636a8bb,reason=SuccessfulCreate count=1 msg=Created pod: eval-sanitize-30-r1-119-p7vtg
0.4891,Event,ADDED,eval-sanitize-30-r1-119.18d4ab55efbcd63c,reason=Completed count=1 msg=Job completed
0.4893,Event,ADDED,eval-sanitize-30-r1-120-j7l42.18d4ab4fbb32a397,reason=Scheduled count=None msg=Successfully assigned compute/eval-sanitize-30-r1-120-j7l42 to kind-worker4
0.4895,Event,ADDED,eval-sanitize-30-r1-120-j7l42.18d4ab4fd92256ba,"reason=Pulled count=1 msg=Container image ""busybox:musl"" already present on machine"
0.4898,Event,ADDED,eval-sanitize-30-r1-120-j7l42.18d4ab4fda7e7099,reason=Created count=1 msg=Created container: task
0.49,Event,ADDED,eval-sanitize-30-r1-120-j7l42.18d4ab4fe0317a15,reason=Started count=1 msg=Started container task
0.4902,Event,ADDED,eval-sanitize-30-r1-120.18d4ab4fb36e85d5,reason=SuccessfulCreate count=1 msg=Created pod: eval-sanitize-30-r1-120-j7l42
0.4904,Event,ADDED,eval-sanitize-30-r1-120.18d4ab55cec8aaa8,reason=Completed count=1 msg=Job completed
0.4912,Event,ADDED,eval-sanitize-30-r1-121-xqgds.18d4ab4ff83f2a3d,reason=Scheduled count=None msg=Successfully assigned compute/eval-sanitize-30-r1-121-xqgds to kind-worker3
0.4914,Event,ADDED,eval-sanitize-30-r1-121-xqgds.18d4ab501400da9e,"reason=Pulled count=1 msg=Container image ""busybox:musl"" already present on machine"
0.4916,Event,ADDED,eval-sanitize-30-r1-121-xqgds.18d4ab50156b70e5,reason=Created count=1 msg=Created container: task
0.4917,Event,ADDED,eval-sanitize-30-r1-121-xqgds.18d4ab501b11eaba,reason=Started count=1 msg=Started container task
0.4921,Event,ADDED,eval-sanitize-30-r1-121.18d4ab4fee4db0f2,reason=SuccessfulCreate count=1 msg=Created pod: eval-sanitize-30-r1-121-xqgds
0.4924,Event,ADDED,eval-sanitize-30-r1-121.18d4ab560204d019,reason=Completed count=1 msg=Job completed
0.4925,Event,ADDED,eval-sanitize-30-r1-122-t7hpb.18d4ab50338fc2da,reason=Scheduled count=None msg=Successfully assigned compute/eval-sanitize-30-r1-122-t7hpb to kind-worker2
0.4931,Event,ADDED,eval-sanitize-30-r1-122-t7hpb.18d4ab504fc76af2,"reason=Pulled count=1 msg=Container image ""busybox:musl"" already present on machine"
0.4932,Event,ADDED,eval-sanitize-30-r1-122-t7hpb.18d4ab5051ad467a,reason=Created count=1 msg=Created container: task
0.4934,Event,ADDED,eval-sanitize-30-r1-122-t7hpb.18d4ab505712971e,reason=Started count=1 msg=Started container task
0.4937,Event,ADDED,eval-sanitize-30-r1-122.18d4ab502a2c66b5,reason=SuccessfulCreate count=1 msg=Created pod: eval-sanitize-30-r1-122-t7hpb
0.494,Event,ADDED,eval-sanitize-30-r1-122.18d4ab55ff7080ca,reason=Completed count=1 msg=Job completed
0.4942,Event,ADDED,eval-sanitize-30-r1-123-nnf5m.18d4ab506cf60f51,reason=Scheduled count=None msg=Successfully assigned compute/eval-sanitize-30-r1-123-nnf5m to kind-worker3
0.4943,Event,ADDED,eval-sanitize-30-r1-123-nnf5m.18d4ab508919d16e,"reason=Pulled count=1 msg=Container image ""busybox:musl"" already present on machine"
0.4945,Event,ADDED,eval-sanitize-30-r1-123-nnf5m.18d4ab508a665e56,reason=Created count=1 msg=Created container: task
0.4949,Event,ADDED,eval-sanitize-30-r1-123-nnf5m.18d4ab508fbad1b0,reason=Started count=1 msg=Started container task
0.4951,Event,ADDED,eval-sanitize-30-r1-123.18d4ab50660e9798,reason=SuccessfulCreate count=1 msg=Created pod: eval-sanitize-30-r1-123-nnf5m
0.4954,Event,ADDED,eval-sanitize-30-r1-123.18d4ab562ebc7f23,reason=Completed count=1 msg=Job completed
0.4957,Event,ADDED,eval-sanitize-30-r1-124-ccq62.18d4ab50a8ad8c7b,reason=Scheduled count=None msg=Successfully assigned compute/eval-sanitize-30-r1-124-ccq62 to kind-worker2
0.4959,Event,ADDED,eval-sanitize-30-r1-124-ccq62.18d4ab50c636f058,"reason=Pulled count=1 msg=Container image ""busybox:musl"" already present on machine"
0.4961,Event,ADDED,eval-sanitize-30-r1-124-ccq62.18d4ab50c7ba99fb,reason=Created count=1 msg=Created container: task
0.4962,Event,ADDED,eval-sanitize-30-r1-124-ccq62.18d4ab50cdc07d0e,reason=Started count=1 msg=Started container task
0.4965,Event,ADDED,eval-sanitize-30-r1-124.18d4ab50a1b9b25b,reason=SuccessfulCreate count=1 msg=Created pod: eval-sanitize-30-r1-124-ccq62
0.4967,Event,ADDED,eval-sanitize-30-r1-124.18d4ab569baff9b6,reason=Completed count=1 msg=Job completed
0.4969,Event,ADDED,eval-sanitize-30-r1-125-jxdtk.18d4ab50e541319d,reason=Scheduled count=None msg=Successfully assigned compute/eval-sanitize-30-r1-125-jxdtk to kind-worker2
0.4971,Event,ADDED,eval-sanitize-30-r1-125-jxdtk.18d4ab510094b9b7,"reason=Pulled count=1 msg=Container image ""busybox:musl"" already present on machine"
0.4974,Event,ADDED,eval-sanitize-30-r1-125-jxdtk.18d4ab5101e709f7,reason=Created count=1 msg=Created container: task
0.4975,Event,ADDED,eval-sanitize-30-r1-125-jxdtk.18d4ab51072ff447,reason=Started count=1 msg=Started container task
0.4977,Event,ADDED,eval-sanitize-30-r1-125.18d4ab50dcf3ae5d,reason=SuccessfulCreate count=1 msg=Created pod: eval-sanitize-30-r1-125-jxdtk
0.498,Event,ADDED,eval-sanitize-30-r1-125.18d4ab56d033bf2a,reason=Completed count=1 msg=Job completed
0.4982,Event,ADDED,eval-sanitize-30-r1-126-66kjw.18d4ab51256d5bc5,reason=Scheduled count=None msg=Successfully assigned compute/eval-sanitize-30-r1-126-66kjw to kind-worker4
0.4984,Event,ADDED,eval-sanitize-30-r1-126-66kjw.18d4ab5140cc83e1,"reason=Pulled count=1 msg=Container image ""busybox:musl"" already present on machine"
0.4986,Event,ADDED,eval-sanitize-30-r1-126-66kjw.18d4ab5142e309d4,reason=Created count=1 msg=Created container: task
0.4988,Event,ADDED,eval-sanitize-30-r1-126-66kjw.18d4ab5153defc6b,reason=Started count=1 msg=Started container task
0.4989,Event,ADDED,eval-sanitize-30-r1-126.18d4ab51180db3bd,reason=SuccessfulCreate count=1 msg=Created pod: eval-sanitize-30-r1-126-66kjw
0.4992,Event,ADDED,eval-sanitize-30-r1-126.18d4ab56ec7a941f,reason=Completed count=1 msg=Job completed
0.4994,Event,ADDED,eval-sanitize-30-r1-127-bvpx5.18d4ab51634676a8,reason=Scheduled count=None msg=Successfully assigned compute/eval-sanitize-30-r1-127-bvpx5 to kind-worker
0.4997,Event,ADDED,eval-sanitize-30-r1-127-bvpx5.18d4ab517f4af583,"reason=Pulled count=1 msg=Container image ""busybox:musl"" already present on machine"
0.4999,Event,ADDED,eval-sanitize-30-r1-127-bvpx5.18d4ab5180a65932,reason=Created count=1 msg=Created container: task
0.5,Event,ADDED,eval-sanitize-30-r1-127-bvpx5.18d4ab5187f9e303,reason=Started count=1 msg=Started container task
0.5003,Event,ADDED,eval-sanitize-30-r1-127.18d4ab51563303de,reason=SuccessfulCreate count=1 msg=Created pod: eval-sanitize-30-r1-127-bvpx5
0.5005,Event,ADDED,eval-sanitize-30-r1-127.18d4ab56f7caa0a0,reason=Completed count=1 msg=Job completed
0.5007,Event,ADDED,eval-sanitize-30-r1-128-jfqf9.18d4ab51a4721d79,reason=Scheduled count=None msg=Successfully assigned compute/eval-sanitize-30-r1-128-jfqf9 to kind-worker2
0.5008,Event,ADDED,eval-sanitize-30-r1-128-jfqf9.18d4ab51cea03d15,"reason=Pulled count=1 msg=Container image ""busybox:musl"" already present on machine"
0.5011,Event,ADDED,eval-sanitize-30-r1-128-jfqf9.18d4ab51d32a8a42,reason=Created count=1 msg=Created container: task
0.5013,Event,ADDED,eval-sanitize-30-r1-128-jfqf9.18d4ab51dd99df37,reason=Started count=1 msg=Started container task
0.5015,Event,ADDED,eval-sanitize-30-r1-128.18d4ab519328d3a1,reason=SuccessfulCreate count=1 msg=Created pod: eval-sanitize-30-r1-128-jfqf9
0.5017,Event,ADDED,eval-sanitize-30-r1-128.18d4ab577448ca02,reason=Completed count=1 msg=Job completed
0.502,Event,ADDED,eval-sanitize-30-r1-129-bmq59.18d4ab51d937d6ab,reason=Scheduled count=None msg=Successfully assigned compute/eval-sanitize-30-r1-129-bmq59 to kind-worker
0.5022,Event,ADDED,eval-sanitize-30-r1-129-bmq59.18d4ab51fbe490b1,"reason=Pulled count=1 msg=Container image ""busybox:musl"" already present on machine"
0.5024,Event,ADDED,eval-sanitize-30-r1-129-bmq59.18d4ab51fd55285f,reason=Created count=1 msg=Created container: task
0.5026,Event,ADDED,eval-sanitize-30-r1-129-bmq59.18d4ab5205655f4b,reason=Started count=1 msg=Started container task
0.5028,Event,ADDED,eval-sanitize-30-r1-129.18d4ab51d2950c71,reason=SuccessfulCreate count=1 msg=Created pod: eval-sanitize-30-r1-129-bmq59
0.5029,Event,ADDED,eval-sanitize-30-r1-129.18d4ab5728bf796e,reason=Completed count=1 msg=Job completed
0.5032,Event,ADDED,eval-sanitize-30-r1-130-v7dsl.18d4ab52110b5733,reason=Scheduled count=None msg=Successfully assigned compute/eval-sanitize-30-r1-130-v7dsl to kind-worker4
0.5035,Event,ADDED,eval-sanitize-30-r1-130-v7dsl.18d4ab523b0ae3c5,"reason=Pulled count=1 msg=Container image ""busybox:musl"" already present on machine"
0.5038,Event,ADDED,eval-sanitize-30-r1-130-v7dsl.18d4ab523d21e44e,reason=Created count=1 msg=Created container: task
0.5039,Event,ADDED,eval-sanitize-30-r1-130-v7dsl.18d4ab5242a9f2d1,reason=Started count=1 msg=Started container task
0.5041,Event,ADDED,eval-sanitize-30-r1-130.18d4ab52074ee331,reason=SuccessfulCreate count=1 msg=Created pod: eval-sanitize-30-r1-130-v7dsl
0.5045,Event,ADDED,eval-sanitize-30-r1-130.18d4ab57cc753090,reason=Completed count=1 msg=Job completed
0.5047,Event,ADDED,eval-sanitize-30-r1-131-8dknh.18d4ab524998c355,reason=Scheduled count=None msg=Successfully assigned compute/eval-sanitize-30-r1-131-8dknh to kind-worker2
0.5049,Event,ADDED,eval-sanitize-30-r1-131-8dknh.18d4ab526e02b55b,"reason=Pulled count=1 msg=Container image ""busybox:musl"" already present on machine"
0.5052,Event,ADDED,eval-sanitize-30-r1-131-8dknh.18d4ab526fd52987,reason=Created count=1 msg=Created container: task
0.5054,Event,ADDED,eval-sanitize-30-r1-131-8dknh.18d4ab52740a666e,reason=Started count=1 msg=Started container task
0.5056,Event,ADDED,eval-sanitize-30-r1-131.18d4ab5245767688,reason=SuccessfulCreate count=1 msg=Created pod: eval-sanitize-30-r1-131-8dknh
0.5058,Event,ADDED,eval-sanitize-30-r1-131.18d4ab57ef8b273a,reason=Completed count=1 msg=Job completed
0.506,Event,ADDED,eval-sanitize-30-r1-132-j7kfz.18d4ab52ec744cfc,reason=Scheduled count=None msg=Successfully assigned compute/eval-sanitize-30-r1-132-j7kfz to kind-worker2
0.5062,Event,ADDED,eval-sanitize-30-r1-132-j7kfz.18d4ab53132778c3,"reason=Pulled count=1 msg=Container image ""busybox:musl"" already present on machine"
0.5064,Event,ADDED,eval-sanitize-30-r1-132-j7kfz.18d4ab531498d681,reason=Created count=1 msg=Created container: task
0.5066,Event,ADDED,eval-sanitize-30-r1-132-j7kfz.18d4ab531b24ec9b,reason=Started count=1 msg=Started container task
0.5067,Event,ADDED,eval-sanitize-30-r1-132.18d4ab52e2f451fa,reason=SuccessfulCreate count=1 msg=Created pod: eval-sanitize-30-r1-132-j7kfz
0.5069,Event,ADDED,eval-sanitize-30-r1-132.18d4ab58a054a294,reason=Completed count=1 msg=Job completed
0.5072,Event,ADDED,eval-sanitize-30-r1-133-2vtjt.18d4ab53608db7f2,reason=Scheduled count=None msg=Successfully assigned compute/eval-sanitize-30-r1-133-2vtjt to kind-worker2
0.5075,Event,ADDED,eval-sanitize-30-r1-133-2vtjt.18d4ab537c965b86,"reason=Pulled count=1 msg=Container image ""busybox:musl"" already present on machine"
0.5077,Event,ADDED,eval-sanitize-30-r1-133-2vtjt.18d4ab537e5442bc,reason=Created count=1 msg=Created container: task
0.5079,Event,ADDED,eval-sanitize-30-r1-133-2vtjt.18d4ab538874c5c8,reason=Started count=1 msg=Started container task
0.5081,Event,ADDED,eval-sanitize-30-r1-133.18d4ab535ab140b6,reason=SuccessfulCreate count=1 msg=Created pod: eval-sanitize-30-r1-133-2vtjt
0.5083,Event,ADDED,eval-sanitize-30-r1-133.18d4ab5917d4d462,reason=Completed count=1 msg=Job completed
0.5085,Event,ADDED,eval-sanitize-30-r1-134-7zfmp.18d4ab53ccc5b6b5,"reason=FailedScheduling count=None msg=0/6 nodes are available: 1 c_wall violated: 2 conflicting context pair(s) with node memory, 2 c_wall violated: 1 conflicting context pair(s) with node memory, 3 node(s) had untolerated taint(s). no new claims to deallocate, preemption: 0/6 nodes are available: 3 No preemption victims found for incoming pod, 3 Preemption is not helpful for scheduling."
0.5087,Event,ADDED,eval-sanitize-30-r1-134-7zfmp.18d4ab53d2a194e8,"reason=FailedScheduling count=None msg=0/6 nodes are available: 1 c_wall violated: 2 conflicting context pair(s) with node memory, 2 c_wall violated: 1 conflicting context pair(s) with node memory, 3 node(s) had untolerated taint(s). no new claims to deallocate, preemption: 0/6 nodes are available: 3 No preemption victims found for incoming pod, 3 Preemption is not helpful for scheduling."
0.5089,Event,ADDED,eval-sanitize-30-r1-134-7zfmp.18d4ab53e927ff31,reason=Scheduled count=None msg=Successfully assigned compute/eval-sanitize-30-r1-134-7zfmp to kind-worker5
0.509,Event,ADDED,eval-sanitize-30-r1-134-7zfmp.18d4ab54088c9b73,"reason=Pulled count=1 msg=Container image ""busybox:musl"" already present on machine"
0.5092,Event,ADDED,eval-sanitize-30-r1-134-7zfmp.18d4ab540a283062,reason=Created count=1 msg=Created container: task
0.5098,Event,ADDED,eval-sanitize-30-r1-134-7zfmp.18d4ab540ee55396,reason=Started count=1 msg=Started container task
0.51,Event,ADDED,eval-sanitize-30-r1-134.18d4ab53cbdc7c0f,reason=SuccessfulCreate count=1 msg=Created pod: eval-sanitize-30-r1-134-7zfmp
0.5101,Event,ADDED,eval-sanitize-30-r1-134.18d4ab599a01f64c,reason=Completed count=1 msg=Job completed
0.5103,Event,ADDED,eval-sanitize-30-r1-135-r9qjg.18d4ab53f1a4dc25,reason=Scheduled count=None msg=Successfully assigned compute/eval-sanitize-30-r1-135-r9qjg to kind-worker5
0.5105,Event,ADDED,eval-sanitize-30-r1-135-r9qjg.18d4ab541050f1bf,"reason=Pulled count=1 msg=Container image ""busybox:musl"" already present on machine"
0.5107,Event,ADDED,eval-sanitize-30-r1-135-r9qjg.18d4ab5411ae3516,reason=Created count=1 msg=Created container: task
0.5108,Event,ADDED,eval-sanitize-30-r1-135-r9qjg.18d4ab5416f78e37,reason=Started count=1 msg=Started container task
0.511,Event,ADDED,eval-sanitize-30-r1-135.18d4ab53ecc493dc,reason=SuccessfulCreate count=1 msg=Created pod: eval-sanitize-30-r1-135-r9qjg
0.5114,Event,ADDED,eval-sanitize-30-r1-135.18d4ab599a32fda0,reason=Completed count=1 msg=Job completed
0.5115,Event,ADDED,eval-sanitize-30-r1-136-858jb.18d4ab5426f5b220,reason=Scheduled count=None msg=Successfully assigned compute/eval-sanitize-30-r1-136-858jb to kind-worker4
0.5117,Event,ADDED,eval-sanitize-30-r1-136-858jb.18d4ab5444534292,"reason=Pulled count=1 msg=Container image ""busybox:musl"" already present on machine"
0.5119,Event,ADDED,eval-sanitize-30-r1-136-858jb.18d4ab5445b7926b,reason=Created count=1 msg=Created container: task
0.5122,Event,ADDED,eval-sanitize-30-r1-136-858jb.18d4ab545285d591,reason=Started count=1 msg=Started container task
0.5124,Event,ADDED,eval-sanitize-30-r1-136.18d4ab54254ba0a8,reason=SuccessfulCreate count=1 msg=Created pod: eval-sanitize-30-r1-136-858jb
0.5125,Event,ADDED,eval-sanitize-30-r1-136.18d4ab59eb5c6df6,reason=Completed count=1 msg=Job completed
0.5128,Event,ADDED,eval-sanitize-30-r1-137-scp28.18d4ab545477ef43,reason=Scheduled count=None msg=Successfully assigned compute/eval-sanitize-30-r1-137-scp28 to kind-worker3
0.513,Event,ADDED,eval-sanitize-30-r1-137-scp28.18d4ab5471914622,"reason=Pulled count=1 msg=Container image ""busybox:musl"" already present on machine"
0.5132,Event,ADDED,eval-sanitize-30-r1-137-scp28.18d4ab5473165f4a,reason=Created count=1 msg=Created container: task
0.5133,Event,ADDED,eval-sanitize-30-r1-137-scp28.18d4ab54776774b1,reason=Started count=1 msg=Started container task
0.5135,Event,ADDED,eval-sanitize-30-r1-137.18d4ab5452cbc272,reason=SuccessfulCreate count=1 msg=Created pod: eval-sanitize-30-r1-137-scp28
0.5137,Event,ADDED,eval-sanitize-30-r1-137.18d4ab5a05c65121,reason=Completed count=1 msg=Job completed
0.5139,Event,ADDED,eval-sanitize-30-r1-138-4r5l6.18d4ab54a06a697d,reason=Scheduled count=None msg=Successfully assigned compute/eval-sanitize-30-r1-138-4r5l6 to kind-worker5
0.514,Event,ADDED,eval-sanitize-30-r1-138-4r5l6.18d4ab54bdc555f5,"reason=Pulled count=1 msg=Container image ""busybox:musl"" already present on machine"
0.5142,Event,ADDED,eval-sanitize-30-r1-138-4r5l6.18d4ab54bf14b2f7,reason=Created count=1 msg=Created container: task
0.5145,Event,ADDED,eval-sanitize-30-r1-138-4r5l6.18d4ab54c1b01717,reason=Started count=1 msg=Started container task
0.5147,Event,ADDED,eval-sanitize-30-r1-138.18d4ab549fa3cb00,reason=SuccessfulCreate count=1 msg=Created pod: eval-sanitize-30-r1-138-4r5l6
0.5148,Event,ADDED,eval-sanitize-30-r1-138.18d4ab5a50c72991,reason=Completed count=1 msg=Job completed
0.515,Event,ADDED,eval-sanitize-30-r1-139-q54x7.18d4ab54cc357f14,reason=Scheduled count=None msg=Successfully assigned compute/eval-sanitize-30-r1-139-q54x7 to kind-worker5
0.5151,Event,ADDED,eval-sanitize-30-r1-139-q54x7.18d4ab54ed526fe9,"reason=Pulled count=1 msg=Container image ""busybox:musl"" already present on machine"
0.5153,Event,ADDED,eval-sanitize-30-r1-139-q54x7.18d4ab54eeb2382e,reason=Created count=1 msg=Created container: task
0.5155,Event,ADDED,eval-sanitize-30-r1-139-q54x7.18d4ab54f8e0f5a1,reason=Started count=1 msg=Started container task
0.5157,Event,ADDED,eval-sanitize-30-r1-139.18d4ab54cb6f212f,reason=SuccessfulCreate count=1 msg=Created pod: eval-sanitize-30-r1-139-q54x7
0.5158,Event,ADDED,eval-sanitize-30-r1-139.18d4ab5a8ebdbe15,reason=Completed count=1 msg=Job completed
0.5162,Event,ADDED,eval-sanitize-30-r1-140-j99vd.18d4ab54f96cd42b,"reason=FailedScheduling count=None msg=0/6 nodes are available: 1 c_wall violated: 1 conflicting context pair(s) with node memory, 5 node(s) had untolerated taint(s). no new claims to deallocate, preemption: 0/6 nodes are available: 1 No preemption victims found for incoming pod, 5 Preemption is not helpful for scheduling."
0.5164,Event,ADDED,eval-sanitize-30-r1-140-j99vd.18d4ab54fa274991,"reason=FailedScheduling count=None msg=0/6 nodes are available: 1 c_wall violated: 1 conflicting context pair(s) with node memory, 5 node(s) had untolerated taint(s). no new claims to deallocate, preemption: 0/6 nodes are available: 1 No preemption victims found for incoming pod, 5 Preemption is not helpful for scheduling."
0.5165,Event,ADDED,eval-sanitize-30-r1-140-j99vd.18d4ab5ac9b584f0,"reason=FailedScheduling count=None msg=0/6 nodes are available: 1 c_wall violated: 1 conflicting context pair(s) with node memory, 1 c_wall violated: 2 conflicting context pair(s) with node memory, 4 node(s) had untolerated taint(s). no new claims to deallocate, preemption: 0/6 nodes are available: 2 No preemption victims found for incoming pod, 4 Preemption is not helpful for scheduling."
0.5167,Event,ADDED,eval-sanitize-30-r1-140-j99vd.18d4ab5ae2eabfb5,"reason=FailedScheduling count=None msg=0/6 nodes are available: 1 c_wall violated: 2 conflicting context pair(s) with node memory, 5 node(s) had untolerated taint(s). no new claims to deallocate, preemption: 0/6 nodes are available: 1 No preemption victims found for incoming pod, 5 Preemption is not helpful for scheduling."
0.5169,Event,ADDED,eval-sanitize-30-r1-140-j99vd.18d4ab5af2623490,"reason=FailedScheduling count=None msg=0/6 nodes are available: 1 c_wall violated: 2 conflicting context pair(s) with node memory, 5 node(s) had untolerated taint(s). no new claims to deallocate, preemption: 0/6 nodes are available: 1 No preemption victims found for incoming pod, 5 Preemption is not helpful for scheduling."
0.5171,Event,ADDED,eval-sanitize-30-r1-140-j99vd.18d4ab5b818b6bd5,"reason=FailedScheduling count=None msg=0/6 nodes are available: 1 c_wall violated: 1 conflicting context pair(s) with node memory, 2 c_wall violated: 2 conflicting context pair(s) with node memory, 3 node(s) had untolerated taint(s). no new claims to deallocate, preemption: 0/6 nodes are available: 3 No preemption victims found for incoming pod, 3 Preemption is not helpful for scheduling."
0.5174,Event,ADDED,eval-sanitize-30-r1-140-j99vd.18d4ab5bacda6679,reason=Scheduled count=None msg=Successfully assigned compute/eval-sanitize-30-r1-140-j99vd to kind-worker4
0.5175,Event,ADDED,eval-sanitize-30-r1-140-j99vd.18d4ab5bc93920ce,"reason=Pulled count=1 msg=Container image ""busybox:musl"" already present on machine"
0.5177,Event,ADDED,eval-sanitize-30-r1-140-j99vd.18d4ab5bcb1aec9d,reason=Created count=1 msg=Created container: task
0.5179,Event,ADDED,eval-sanitize-30-r1-140-j99vd.18d4ab5bd388f6f3,reason=Started count=1 msg=Started container task
0.5182,Event,ADDED,eval-sanitize-30-r1-140.18d4ab54f9176d67,reason=SuccessfulCreate count=1 msg=Created pod: eval-sanitize-30-r1-140-j99vd
0.5184,Event,ADDED,eval-sanitize-30-r1-140.18d4ab61f487b50e,reason=Completed count=1 msg=Job completed
0.5185,Event,ADDED,eval-sanitize-30-r1-141-dzqsf.18d4ab552bbdef11,"reason=FailedScheduling count=None msg=0/6 nodes are available: 1 c_wall violated: 1 conflicting context pair(s) with node memory, 5 node(s) had untolerated taint(s). no new claims to deallocate, preemption: 0/6 nodes are available: 1 No preemption victims found for incoming pod, 5 Preemption is not helpful for scheduling."
0.5188,Event,ADDED,eval-sanitize-30-r1-141-dzqsf.18d4ab552cf167f8,"reason=FailedScheduling count=None msg=0/6 nodes are available: 1 c_wall violated: 1 conflicting context pair(s) with node memory, 5 node(s) had untolerated taint(s). no new claims to deallocate, preemption: 0/6 nodes are available: 1 No preemption victims found for incoming pod, 5 Preemption is not helpful for scheduling."
0.519,Event,ADDED,eval-sanitize-30-r1-141-dzqsf.18d4ab5a995dbc06,reason=Scheduled count=None msg=Successfully assigned compute/eval-sanitize-30-r1-141-dzqsf to kind-worker2
0.5192,Event,ADDED,eval-sanitize-30-r1-141-dzqsf.18d4ab5ab4d959eb,"reason=Pulled count=1 msg=Container image ""busybox:musl"" already present on machine"
