t_recv,kind,type,name,detail
0.0223,Node,ADDED,kind-control-plane,taints=1
0.0254,Node,ADDED,kind-worker,taints=0
0.0265,Node,ADDED,kind-worker2,taints=0
0.0277,Node,ADDED,kind-worker3,taints=0
0.0287,Node,ADDED,kind-worker4,taints=0
0.0301,Node,ADDED,kind-worker5,taints=0
0.0391,TaskRequest,ADDED,eval-sanitize-20-r1-000,phase=None job=None
0.0453,TaskRequest,MODIFIED,eval-sanitize-20-r1-000,phase=Pending job=None
0.062,Job,ADDED,eval-sanitize-20-r1-000,
0.0672,TaskRequest,MODIFIED,eval-sanitize-20-r1-000,phase=Scheduled job=None
0.0705,Pod,ADDED,eval-sanitize-20-r1-000-4gvxt,phase=Pending node=None
0.0725,Job,MODIFIED,eval-sanitize-20-r1-000,
0.077,TaskRequest,MODIFIED,eval-sanitize-20-r1-000,phase=Scheduled job=None
0.0778,Event,ADDED,eval-sanitize-20-r1-000.18d41a9e113b7a80,reason=SuccessfulCreate count=1 msg=Created pod: eval-sanitize-20-r1-000-4gvxt
0.0848,Pod,MODIFIED,eval-sanitize-20-r1-000-4gvxt,phase=Pending node=kind-worker3
0.0916,Event,ADDED,eval-sanitize-20-r1-000-4gvxt.18d41a9e12171fc1,reason=Scheduled count=None msg=Successfully assigned compute/eval-sanitize-20-r1-000-4gvxt to kind-worker3
0.0966,Node,MODIFIED,kind-worker3,taints=0
0.0986,Pod,MODIFIED,eval-sanitize-20-r1-000-4gvxt,phase=Pending node=kind-worker3
0.1096,Node,MODIFIED,kind-worker3,taints=0
0.509,Event,ADDED,eval-sanitize-20-r1-000-4gvxt.18d41a9e2b1eeb84,"reason=Pulled count=1 msg=Container image ""busybox:musl"" already present on machine"
0.5261,Event,ADDED,eval-sanitize-20-r1-000-4gvxt.18d41a9e2c30f8c3,reason=Created count=1 msg=Created container: task
0.5674,Event,ADDED,eval-sanitize-20-r1-000-4gvxt.18d41a9e2e9b2f4c,reason=Started count=1 msg=Started container task
1.013,TaskRequest,ADDED,eval-sanitize-20-r1-001,phase=None job=None
1.0166,TaskRequest,MODIFIED,eval-sanitize-20-r1-001,phase=Pending job=None
1.0324,Job,ADDED,eval-sanitize-20-r1-001,
1.038,TaskRequest,MODIFIED,eval-sanitize-20-r1-001,phase=Scheduled job=None
1.04,Pod,ADDED,eval-sanitize-20-r1-001-fhsgn,phase=Pending node=None
1.0414,Job,MODIFIED,eval-sanitize-20-r1-001,
1.0443,Event,ADDED,eval-sanitize-20-r1-001.18d41a9e4b0431a5,reason=SuccessfulCreate count=1 msg=Created pod: eval-sanitize-20-r1-001-fhsgn
1.0451,TaskRequest,MODIFIED,eval-sanitize-20-r1-001,phase=Scheduled job=None
1.0575,Pod,MODIFIED,eval-sanitize-20-r1-001-fhsgn,phase=Pending node=kind-worker5
1.0611,Event,ADDED,eval-sanitize-20-r1-001-fhsgn.18d41a9e4c0aef4c,reason=Scheduled count=None msg=Successfully assigned compute/eval-sanitize-20-r1-001-fhsgn to kind-worker5
1.0672,Node,MODIFIED,kind-worker5,taints=0
1.0688,Pod,MODIFIED,eval-sanitize-20-r1-001-fhsgn,phase=Pending node=kind-worker5
1.0747,Job,MODIFIED,eval-sanitize-20-r1-000,
1.0781,Node,MODIFIED,kind-worker5,taints=0
1.0832,Job,MODIFIED,eval-sanitize-20-r1-000,
1.5043,Event,ADDED,eval-sanitize-20-r1-001-fhsgn.18d41a9e66777406,"reason=Pulled count=1 msg=Container image ""busybox:musl"" already present on machine"
1.5228,Event,ADDED,eval-sanitize-20-r1-001-fhsgn.18d41a9e67882f9a,reason=Created count=1 msg=Created container: task
1.5352,Pod,MODIFIED,eval-sanitize-20-r1-000-4gvxt,phase=Running node=kind-worker3
1.5573,Event,ADDED,eval-sanitize-20-r1-001-fhsgn.18d41a9e699e6339,reason=Started count=1 msg=Started container task
2.0265,TaskRequest,ADDED,eval-sanitize-20-r1-002,phase=None job=None
2.0301,TaskRequest,MODIFIED,eval-sanitize-20-r1-002,phase=Pending job=None
2.0452,Job,MODIFIED,eval-sanitize-20-r1-001,
2.0472,Job,ADDED,eval-sanitize-20-r1-002,
2.0512,TaskRequest,MODIFIED,eval-sanitize-20-r1-002,phase=Scheduled job=None
2.0557,Pod,ADDED,eval-sanitize-20-r1-002-v2wms,phase=Pending node=None
2.0582,Job,MODIFIED,eval-sanitize-20-r1-002,
2.0623,Event,ADDED,eval-sanitize-20-r1-002.18d41a9e87921497,reason=SuccessfulCreate count=1 msg=Created pod: eval-sanitize-20-r1-002-v2wms
2.0624,TaskRequest,MODIFIED,eval-sanitize-20-r1-002,phase=Scheduled job=None
2.0646,Job,MODIFIED,eval-sanitize-20-r1-001,
2.0724,Pod,MODIFIED,eval-sanitize-20-r1-002-v2wms,phase=Pending node=kind-worker
2.0758,Event,ADDED,eval-sanitize-20-r1-002-v2wms.18d41a9e888f1e21,reason=Scheduled count=None msg=Successfully assigned compute/eval-sanitize-20-r1-002-v2wms to kind-worker
2.0794,Job,MODIFIED,eval-sanitize-20-r1-000,
2.0822,Pod,MODIFIED,eval-sanitize-20-r1-002-v2wms,phase=Pending node=kind-worker
2.0837,Node,MODIFIED,kind-worker,taints=0
2.0888,Job,MODIFIED,eval-sanitize-20-r1-000,
2.092,Node,MODIFIED,kind-worker,taints=0
2.1787,Pod,MODIFIED,eval-sanitize-20-r1-001-fhsgn,phase=Running node=kind-worker5
2.4923,Event,ADDED,eval-sanitize-20-r1-002-v2wms.18d41a9ea15647b3,"reason=Pulled count=1 msg=Container image ""busybox:musl"" already present on machine"
2.5099,Event,ADDED,eval-sanitize-20-r1-002-v2wms.18d41a9ea266d2ce,reason=Created count=1 msg=Created container: task
2.577,Event,ADDED,eval-sanitize-20-r1-002-v2wms.18d41a9ea6533c73,reason=Started count=1 msg=Started container task
3.0095,TaskRequest,ADDED,eval-sanitize-20-r1-003,phase=None job=None
3.0244,TaskRequest,MODIFIED,eval-sanitize-20-r1-003,phase=Pending job=None
3.041,Job,ADDED,eval-sanitize-20-r1-003,
3.0456,TaskRequest,MODIFIED,eval-sanitize-20-r1-003,phase=Scheduled job=None
3.0491,Pod,ADDED,eval-sanitize-20-r1-003-q9fhf,phase=Pending node=None
3.0519,Job,MODIFIED,eval-sanitize-20-r1-001,
3.0527,Job,MODIFIED,eval-sanitize-20-r1-003,
3.0554,Event,ADDED,eval-sanitize-20-r1-003.18d41a9ec2cb0f83,reason=SuccessfulCreate count=1 msg=Created pod: eval-sanitize-20-r1-003-q9fhf
3.0556,TaskRequest,MODIFIED,eval-sanitize-20-r1-003,phase=Scheduled job=None
3.0607,Job,MODIFIED,eval-sanitize-20-r1-002,
3.0625,Job,MODIFIED,eval-sanitize-20-r1-001,
3.0701,Pod,MODIFIED,eval-sanitize-20-r1-003-q9fhf,phase=Pending node=kind-worker3
3.0715,Job,MODIFIED,eval-sanitize-20-r1-002,
3.0733,Event,ADDED,eval-sanitize-20-r1-003-q9fhf.18d41a9ec4068e7b,reason=Scheduled count=None msg=Successfully assigned compute/eval-sanitize-20-r1-003-q9fhf to kind-worker3
3.0801,Pod,MODIFIED,eval-sanitize-20-r1-003-q9fhf,phase=Pending node=kind-worker3
3.5281,Event,ADDED,eval-sanitize-20-r1-003-q9fhf.18d41a9edf1162ac,"reason=Pulled count=1 msg=Container image ""busybox:musl"" already present on machine"
3.5465,Event,ADDED,eval-sanitize-20-r1-003-q9fhf.18d41a9ee02b0980,reason=Created count=1 msg=Created container: task
3.5866,Pod,MODIFIED,eval-sanitize-20-r1-002-v2wms,phase=Running node=kind-worker
3.5896,Event,ADDED,eval-sanitize-20-r1-003-q9fhf.18d41a9ee2c8c3fc,reason=Started count=1 msg=Started container task
4.0174,TaskRequest,ADDED,eval-sanitize-20-r1-004,phase=None job=None
4.0211,TaskRequest,MODIFIED,eval-sanitize-20-r1-004,phase=Pending job=None
4.0377,Job,ADDED,eval-sanitize-20-r1-004,
4.042,TaskRequest,MODIFIED,eval-sanitize-20-r1-004,phase=Scheduled job=None
4.0449,Pod,ADDED,eval-sanitize-20-r1-004-tf9vj,phase=Pending node=None
4.0476,Job,MODIFIED,eval-sanitize-20-r1-004,
4.0514,TaskRequest,MODIFIED,eval-sanitize-20-r1-004,phase=Scheduled job=None
4.0518,Event,ADDED,eval-sanitize-20-r1-004.18d41a9efe2ce9e3,reason=SuccessfulCreate count=1 msg=Created pod: eval-sanitize-20-r1-004-tf9vj
4.0545,Job,MODIFIED,eval-sanitize-20-r1-003,
4.0638,Job,MODIFIED,eval-sanitize-20-r1-003,
4.0646,Pod,MODIFIED,eval-sanitize-20-r1-004-tf9vj,phase=Pending node=kind-worker5
4.0665,Job,MODIFIED,eval-sanitize-20-r1-002,
4.0682,Event,ADDED,eval-sanitize-20-r1-004-tf9vj.18d41a9eff50964c,reason=Scheduled count=None msg=Successfully assigned compute/eval-sanitize-20-r1-004-tf9vj to kind-worker5
4.0762,Pod,MODIFIED,eval-sanitize-20-r1-004-tf9vj,phase=Pending node=kind-worker5
4.0772,Job,MODIFIED,eval-sanitize-20-r1-002,
4.5045,Event,ADDED,eval-sanitize-20-r1-004-tf9vj.18d41a9f194a2990,"reason=Pulled count=1 msg=Container image ""busybox:musl"" already present on machine"
4.5232,Event,ADDED,eval-sanitize-20-r1-004-tf9vj.18d41a9f1a621cb7,reason=Created count=1 msg=Created container: task
4.5427,Pod,MODIFIED,eval-sanitize-20-r1-003-q9fhf,phase=Running node=kind-worker3
4.5634,Event,ADDED,eval-sanitize-20-r1-004-tf9vj.18d41a9f1cc041b7,reason=Started count=1 msg=Started container task
5.0139,TaskRequest,ADDED,eval-sanitize-20-r1-005,phase=None job=None
5.0175,TaskRequest,MODIFIED,eval-sanitize-20-r1-005,phase=Pending job=None
5.0339,Job,ADDED,eval-sanitize-20-r1-005,
5.0391,TaskRequest,MODIFIED,eval-sanitize-20-r1-005,phase=Scheduled job=None
5.0404,Pod,ADDED,eval-sanitize-20-r1-005-hcgjl,phase=Pending node=None
5.0429,Job,MODIFIED,eval-sanitize-20-r1-005,
5.0461,Event,ADDED,eval-sanitize-20-r1-005.18d41a9f39734aca,reason=SuccessfulCreate count=1 msg=Created pod: eval-sanitize-20-r1-005-hcgjl
5.049,TaskRequest,MODIFIED,eval-sanitize-20-r1-005,phase=Scheduled job=None
5.0515,Job,MODIFIED,eval-sanitize-20-r1-004,
5.0591,Job,MODIFIED,eval-sanitize-20-r1-003,
5.0609,Job,MODIFIED,eval-sanitize-20-r1-004,
5.0622,Pod,MODIFIED,eval-sanitize-20-r1-005-hcgjl,phase=Pending node=kind-worker3
5.0646,Event,ADDED,eval-sanitize-20-r1-005-hcgjl.18d41a9f3ab91fa8,reason=Scheduled count=None msg=Successfully assigned compute/eval-sanitize-20-r1-005-hcgjl to kind-worker3
5.0677,Job,MODIFIED,eval-sanitize-20-r1-003,
5.0703,Pod,MODIFIED,eval-sanitize-20-r1-005-hcgjl,phase=Pending node=kind-worker3
5.0726,Node,MODIFIED,kind-worker3,taints=0
5.0828,Node,MODIFIED,kind-worker3,taints=0
5.1908,Pod,MODIFIED,eval-sanitize-20-r1-004-tf9vj,phase=Running node=kind-worker5
5.4884,Event,ADDED,eval-sanitize-20-r1-005-hcgjl.18d41a9f53f1f632,"reason=Pulled count=1 msg=Container image ""busybox:musl"" already present on machine"
5.5065,Event,ADDED,eval-sanitize-20-r1-005-hcgjl.18d41a9f54fad805,reason=Created count=1 msg=Created container: task
5.5398,Event,ADDED,eval-sanitize-20-r1-005-hcgjl.18d41a9f570456ab,reason=Started count=1 msg=Started container task
6.0192,TaskRequest,ADDED,eval-sanitize-20-r1-006,phase=None job=None
6.0227,TaskRequest,MODIFIED,eval-sanitize-20-r1-006,phase=Pending job=None
6.0487,Job,ADDED,eval-sanitize-20-r1-006,
6.0502,Job,MODIFIED,eval-sanitize-20-r1-005,
6.0549,Pod,ADDED,eval-sanitize-20-r1-006-bzlm5,phase=Pending node=None
6.0568,TaskRequest,MODIFIED,eval-sanitize-20-r1-006,phase=Scheduled job=None
6.0576,Job,MODIFIED,eval-sanitize-20-r1-004,
6.0595,Job,MODIFIED,eval-sanitize-20-r1-006,
6.0599,Event,ADDED,eval-sanitize-20-r1-006.18d41a9f75f68b92,reason=SuccessfulCreate count=1 msg=Created pod: eval-sanitize-20-r1-006-bzlm5
6.0674,TaskRequest,MODIFIED,eval-sanitize-20-r1-006,phase=Scheduled job=None
6.07,Job,MODIFIED,eval-sanitize-20-r1-005,
6.0708,Job,MODIFIED,eval-sanitize-20-r1-004,
6.0757,Pod,MODIFIED,eval-sanitize-20-r1-006-bzlm5,phase=Pending node=kind-worker4
6.0792,Event,ADDED,eval-sanitize-20-r1-006-bzlm5.18d41a9f77328ba6,reason=Scheduled count=None msg=Successfully assigned compute/eval-sanitize-20-r1-006-bzlm5 to kind-worker4
6.0854,Pod,MODIFIED,eval-sanitize-20-r1-006-bzlm5,phase=Pending node=kind-worker4
6.0876,Node,MODIFIED,kind-worker4,taints=0
6.098,Node,MODIFIED,kind-worker4,taints=0
6.5073,Event,ADDED,eval-sanitize-20-r1-006-bzlm5.18d41a9f90a58792,"reason=Pulled count=1 msg=Container image ""busybox:musl"" already present on machine"
6.5264,Event,ADDED,eval-sanitize-20-r1-006-bzlm5.18d41a9f91d56836,reason=Created count=1 msg=Created container: task
6.5474,Pod,MODIFIED,eval-sanitize-20-r1-005-hcgjl,phase=Running node=kind-worker3
6.5755,Event,ADDED,eval-sanitize-20-r1-006-bzlm5.18d41a9f94c04680,reason=Started count=1 msg=Started container task
7.0135,Pod,MODIFIED,eval-sanitize-20-r1-006-bzlm5,phase=Running node=kind-worker4
7.0139,TaskRequest,ADDED,eval-sanitize-20-r1-007,phase=None job=None
7.017,TaskRequest,MODIFIED,eval-sanitize-20-r1-007,phase=Pending job=None
7.0343,Job,ADDED,eval-sanitize-20-r1-007,
7.0401,TaskRequest,MODIFIED,eval-sanitize-20-r1-007,phase=Scheduled job=None
7.0421,Pod,ADDED,eval-sanitize-20-r1-007-5jj5w,phase=Pending node=None
7.0447,Job,MODIFIED,eval-sanitize-20-r1-007,
7.0473,Event,ADDED,eval-sanitize-20-r1-007.18d41a9fb0cb7156,reason=SuccessfulCreate count=1 msg=Created pod: eval-sanitize-20-r1-007-5jj5w
7.0563,Job,MODIFIED,eval-sanitize-20-r1-005,
7.06,Job,MODIFIED,eval-sanitize-20-r1-006,
7.0621,TaskRequest,MODIFIED,eval-sanitize-20-r1-007,phase=Scheduled job=None
7.0659,Job,MODIFIED,eval-sanitize-20-r1-005,
7.0686,Job,MODIFIED,eval-sanitize-20-r1-006,
7.1195,Pod,MODIFIED,eval-sanitize-20-r1-007-5jj5w,phase=Pending node=kind-worker2
7.1245,Event,ADDED,eval-sanitize-20-r1-007-5jj5w.18d41a9fb569d83f,reason=Scheduled count=None msg=Successfully assigned compute/eval-sanitize-20-r1-007-5jj5w to kind-worker2
7.13,Node,MODIFIED,kind-worker2,taints=0
7.1322,Pod,MODIFIED,eval-sanitize-20-r1-007-5jj5w,phase=Pending node=kind-worker2
7.1526,Node,MODIFIED,kind-worker2,taints=0
7.5441,Event,ADDED,eval-sanitize-20-r1-007-5jj5w.18d41a9fce7689d9,"reason=Pulled count=1 msg=Container image ""busybox:musl"" already present on machine"
7.5631,Event,ADDED,eval-sanitize-20-r1-007-5jj5w.18d41a9fcf8cb31e,reason=Created count=1 msg=Created container: task
7.6053,Event,ADDED,eval-sanitize-20-r1-007-5jj5w.18d41a9fd2275bf2,reason=Started count=1 msg=Started container task
8.0085,TaskRequest,ADDED,eval-sanitize-20-r1-008,phase=None job=None
8.0127,TaskRequest,MODIFIED,eval-sanitize-20-r1-008,phase=Pending job=None
8.0284,Job,ADDED,eval-sanitize-20-r1-008,
8.0342,TaskRequest,MODIFIED,eval-sanitize-20-r1-008,phase=Scheduled job=None
8.0351,Pod,ADDED,eval-sanitize-20-r1-008-vx6kf,phase=Pending node=None
8.0368,Job,MODIFIED,eval-sanitize-20-r1-008,
8.0399,Event,ADDED,eval-sanitize-20-r1-008.18d41a9febe9a4f5,reason=SuccessfulCreate count=1 msg=Created pod: eval-sanitize-20-r1-008-vx6kf
8.0423,TaskRequest,MODIFIED,eval-sanitize-20-r1-008,phase=Scheduled job=None
8.0473,Job,MODIFIED,eval-sanitize-20-r1-007,
8.0567,Job,MODIFIED,eval-sanitize-20-r1-007,
8.1117,Pod,MODIFIED,eval-sanitize-20-r1-008-vx6kf,phase=Pending node=kind-worker5
8.1169,Pod,MODIFIED,eval-sanitize-20-r1-007-5jj5w,phase=Running node=kind-worker2
8.1173,Event,ADDED,eval-sanitize-20-r1-008-vx6kf.18d41a9ff0788cc3,reason=Scheduled count=None msg=Successfully assigned compute/eval-sanitize-20-r1-008-vx6kf to kind-worker5
8.1217,Pod,MODIFIED,eval-sanitize-20-r1-008-vx6kf,phase=Pending node=kind-worker5
8.5472,Event,ADDED,eval-sanitize-20-r1-008-vx6kf.18d41aa00a296aa9,"reason=Pulled count=1 msg=Container image ""busybox:musl"" already present on machine"
8.5647,Event,ADDED,eval-sanitize-20-r1-008-vx6kf.18d41aa00b41bae2,reason=Created count=1 msg=Created container: task
8.6365,Event,ADDED,eval-sanitize-20-r1-008-vx6kf.18d41aa00f6046de,reason=Started count=1 msg=Started container task
9.0066,TaskRequest,ADDED,eval-sanitize-20-r1-009,phase=None job=None
9.0115,TaskRequest,MODIFIED,eval-sanitize-20-r1-009,phase=Pending job=None
9.0254,Job,ADDED,eval-sanitize-20-r1-009,
9.0306,TaskRequest,MODIFIED,eval-sanitize-20-r1-009,phase=Scheduled job=None
9.0335,Job,MODIFIED,eval-sanitize-20-r1-009,
9.0343,Pod,ADDED,eval-sanitize-20-r1-009-wrws4,phase=Pending node=None
9.0377,Event,ADDED,eval-sanitize-20-r1-009.18d41aa027726a79,reason=SuccessfulCreate count=1 msg=Created pod: eval-sanitize-20-r1-009-wrws4
9.0404,Job,MODIFIED,eval-sanitize-20-r1-008,
9.0405,TaskRequest,MODIFIED,eval-sanitize-20-r1-009,phase=Scheduled job=None
9.0508,Job,MODIFIED,eval-sanitize-20-r1-008,
9.0526,Job,MODIFIED,eval-sanitize-20-r1-007,
9.0609,Job,MODIFIED,eval-sanitize-20-r1-007,
9.1161,Pod,MODIFIED,eval-sanitize-20-r1-009-wrws4,phase=Pending node=kind-worker
9.1267,Event,ADDED,eval-sanitize-20-r1-009-wrws4.18d41aa02c4f60a8,reason=Scheduled count=None msg=Successfully assigned compute/eval-sanitize-20-r1-009-wrws4 to kind-worker
9.1322,Pod,MODIFIED,eval-sanitize-20-r1-009-wrws4,phase=Pending node=kind-worker
9.1882,Pod,MODIFIED,eval-sanitize-20-r1-008-vx6kf,phase=Running node=kind-worker5
9.5527,Event,ADDED,eval-sanitize-20-r1-009-wrws4.18d41aa0461e638b,"reason=Pulled count=1 msg=Container image ""busybox:musl"" already present on machine"
9.5718,Event,ADDED,eval-sanitize-20-r1-009-wrws4.18d41aa04742a58e,reason=Created count=1 msg=Created container: task
9.6141,Event,ADDED,eval-sanitize-20-r1-009-wrws4.18d41aa049b5dfd5,reason=Started count=1 msg=Started container task
10.0155,TaskRequest,ADDED,eval-sanitize-20-r1-010,phase=None job=None
10.0191,TaskRequest,MODIFIED,eval-sanitize-20-r1-010,phase=Pending job=None
10.0349,Job,ADDED,eval-sanitize-20-r1-010,
10.0389,Job,MODIFIED,eval-sanitize-20-r1-009,
10.0411,Pod,ADDED,eval-sanitize-20-r1-010-qvrjj,phase=Pending node=None
10.0413,TaskRequest,MODIFIED,eval-sanitize-20-r1-010,phase=Scheduled job=None
10.0443,Job,MODIFIED,eval-sanitize-20-r1-010,
10.0469,Job,MODIFIED,eval-sanitize-20-r1-008,
10.0477,Event,ADDED,eval-sanitize-20-r1-010.18d41aa0637fe086,reason=SuccessfulCreate count=1 msg=Created pod: eval-sanitize-20-r1-010-qvrjj
10.0488,TaskRequest,MODIFIED,eval-sanitize-20-r1-010,phase=Scheduled job=None
10.0515,Job,MODIFIED,eval-sanitize-20-r1-009,
10.0548,Job,MODIFIED,eval-sanitize-20-r1-008,
10.1188,Pod,MODIFIED,eval-sanitize-20-r1-010-qvrjj,phase=Pending node=kind-worker
10.1222,Event,ADDED,eval-sanitize-20-r1-010-qvrjj.18d41aa0681ae48e,reason=Scheduled count=None msg=Successfully assigned compute/eval-sanitize-20-r1-010-qvrjj to kind-worker
10.1293,Node,MODIFIED,kind-worker,taints=0
10.1309,Pod,MODIFIED,eval-sanitize-20-r1-010-qvrjj,phase=Pending node=kind-worker
10.1392,Node,MODIFIED,kind-worker,taints=0
10.538,Event,ADDED,eval-sanitize-20-r1-010-qvrjj.18d41aa080dbb854,"reason=Pulled count=1 msg=Container image ""busybox:musl"" already present on machine"
10.5567,Event,ADDED,eval-sanitize-20-r1-010-qvrjj.18d41aa081e6a640,reason=Created count=1 msg=Created container: task
10.5912,Pod,MODIFIED,eval-sanitize-20-r1-009-wrws4,phase=Running node=kind-worker
10.5916,Event,ADDED,eval-sanitize-20-r1-010-qvrjj.18d41aa0841714b2,reason=Started count=1 msg=Started container task
11.0151,TaskRequest,ADDED,eval-sanitize-20-r1-011,phase=None job=None
11.0191,TaskRequest,MODIFIED,eval-sanitize-20-r1-011,phase=Pending job=None
11.0355,Job,ADDED,eval-sanitize-20-r1-011,
11.0397,TaskRequest,MODIFIED,eval-sanitize-20-r1-011,phase=Scheduled job=None
11.0434,Pod,ADDED,eval-sanitize-20-r1-011-hkzpx,phase=Pending node=None
11.0461,Job,MODIFIED,eval-sanitize-20-r1-011,
11.0471,Job,MODIFIED,eval-sanitize-20-r1-009,
11.0478,Job,MODIFIED,eval-sanitize-20-r1-010,
11.0484,Event,ADDED,eval-sanitize-20-r1-011.18d41aa09f402150,reason=SuccessfulCreate count=1 msg=Created pod: eval-sanitize-20-r1-011-hkzpx
11.0486,TaskRequest,MODIFIED,eval-sanitize-20-r1-011,phase=Scheduled job=None
11.0587,Job,MODIFIED,eval-sanitize-20-r1-009,
11.0604,Job,MODIFIED,eval-sanitize-20-r1-010,
11.1176,Pod,MODIFIED,eval-sanitize-20-r1-011-hkzpx,phase=Pending node=kind-worker4
11.121,Event,ADDED,eval-sanitize-20-r1-011-hkzpx.18d41aa0a3a65fe3,reason=Scheduled count=None msg=Successfully assigned compute/eval-sanitize-20-r1-011-hkzpx to kind-worker4
11.1274,Node,MODIFIED,kind-worker4,taints=0
11.1303,Pod,MODIFIED,eval-sanitize-20-r1-011-hkzpx,phase=Pending node=kind-worker4
11.1379,Node,MODIFIED,kind-worker4,taints=0
11.5379,Event,ADDED,eval-sanitize-20-r1-011-hkzpx.18d41aa0bc6b664f,"reason=Pulled count=1 msg=Container image ""busybox:musl"" already present on machine"
11.5591,Pod,MODIFIED,eval-sanitize-20-r1-000-4gvxt,phase=Running node=kind-worker3
11.5594,Event,ADDED,eval-sanitize-20-r1-011-hkzpx.18d41aa0bda63e23,reason=Created count=1 msg=Created container: task
11.5966,Pod,MODIFIED,eval-sanitize-20-r1-010-qvrjj,phase=Running node=kind-worker
11.6547,Event,ADDED,eval-sanitize-20-r1-011-hkzpx.18d41aa0c366c136,reason=Started count=1 msg=Started container task
12.0145,TaskRequest,ADDED,eval-sanitize-20-r1-012,phase=None job=None
12.0182,TaskRequest,MODIFIED,eval-sanitize-20-r1-012,phase=Pending job=None
12.0225,Pod,MODIFIED,eval-sanitize-20-r1-011-hkzpx,phase=Running node=kind-worker4
12.033,Job,ADDED,eval-sanitize-20-r1-012,
12.0384,TaskRequest,MODIFIED,eval-sanitize-20-r1-012,phase=Scheduled job=None
12.0402,Pod,ADDED,eval-sanitize-20-r1-012-m6skw,phase=Pending node=None
12.0421,Job,MODIFIED,eval-sanitize-20-r1-012,
12.0446,Event,ADDED,eval-sanitize-20-r1-012.18d41aa0daaa7fe0,reason=SuccessfulCreate count=1 msg=Created pod: eval-sanitize-20-r1-012-m6skw
12.0482,Job,MODIFIED,eval-sanitize-20-r1-011,
12.0525,Job,MODIFIED,eval-sanitize-20-r1-010,
12.0585,Job,MODIFIED,eval-sanitize-20-r1-011,
12.0612,Job,MODIFIED,eval-sanitize-20-r1-010,
12.1193,TaskRequest,MODIFIED,eval-sanitize-20-r1-012,phase=Scheduled job=None
12.1229,Pod,MODIFIED,eval-sanitize-20-r1-012-m6skw,phase=Pending node=None
12.1232,Event,ADDED,eval-sanitize-20-r1-012-m6skw.18d41aa0df3965ab,"reason=FailedScheduling count=None msg=0/6 nodes are available: 1 node(s) had untolerated taint(s), 2 c_wall violated: 2 conflicting context pair(s) with node memory, 3 c_wall violated: 1 conflicting context pair(s) with node memory. no new claims to deallocate, preemption: 0/6 nodes are available: 1 Preemption is not helpful for scheduling, 5 No preemption victims found for incoming pod."
12.1958,Pod,MODIFIED,eval-sanitize-20-r1-001-fhsgn,phase=Running node=kind-worker5
12.2234,Event,ADDED,eval-sanitize-20-r1-012-m6skw.18d41aa0e5463ab7,"reason=FailedScheduling count=None msg=0/6 nodes are available: 1 node(s) had untolerated taint(s), 2 c_wall violated: 2 conflicting context pair(s) with node memory, 3 c_wall violated: 1 conflicting context pair(s) with node memory. no new claims to deallocate, preemption: 0/6 nodes are available: 1 Preemption is not helpful for scheduling, 5 No preemption victims found for incoming pod."
12.42,Event,MODIFIED,eval-sanitize-20-r1-012-m6skw.18d41aa0e5463ab7,"reason=FailedScheduling count=None msg=0/6 nodes are available: 1 node(s) had untolerated taint(s), 2 c_wall violated: 2 conflicting context pair(s) with node memory, 3 c_wall violated: 1 conflicting context pair(s) with node memory. no new claims to deallocate, preemption: 0/6 nodes are available: 1 Preemption is not helpful for scheduling, 5 No preemption victims found for incoming pod."
12.565,Job,MODIFIED,eval-sanitize-20-r1-000,
12.5763,Job,MODIFIED,eval-sanitize-20-r1-000,
12.6931,Pod,MODIFIED,eval-sanitize-20-r1-000-4gvxt,phase=Succeeded node=kind-worker3
13.0082,TaskRequest,ADDED,eval-sanitize-20-r1-013,phase=None job=None
13.0118,TaskRequest,MODIFIED,eval-sanitize-20-r1-013,phase=Pending job=None
13.0255,Job,ADDED,eval-sanitize-20-r1-013,
13.0314,Pod,ADDED,eval-sanitize-20-r1-013-9wf2v,phase=Pending node=None
13.0317,TaskRequest,MODIFIED,eval-sanitize-20-r1-013,phase=Scheduled job=None
13.0347,Job,MODIFIED,eval-sanitize-20-r1-013,
13.0387,Event,ADDED,eval-sanitize-20-r1-013.18d41aa115be3abf,reason=SuccessfulCreate count=1 msg=Created pod: eval-sanitize-20-r1-013-9wf2v
13.0393,TaskRequest,MODIFIED,eval-sanitize-20-r1-013,phase=Scheduled job=None
13.045,Job,MODIFIED,eval-sanitize-20-r1-012,
13.054,Job,MODIFIED,eval-sanitize-20-r1-012,
13.1164,Pod,MODIFIED,eval-sanitize-20-r1-013-9wf2v,phase=Pending node=kind-worker3
13.1197,Event,ADDED,eval-sanitize-20-r1-013-9wf2v.18d41aa11abe7e8d,reason=Scheduled count=None msg=Successfully assigned compute/eval-sanitize-20-r1-013-9wf2v to kind-worker3
13.1263,Pod,MODIFIED,eval-sanitize-20-r1-013-9wf2v,phase=Pending node=kind-worker3
13.2013,Job,MODIFIED,eval-sanitize-20-r1-001,
13.2119,Job,MODIFIED,eval-sanitize-20-r1-001,
13.3232,Pod,MODIFIED,eval-sanitize-20-r1-001-fhsgn,phase=Succeeded node=kind-worker5
13.5407,Event,ADDED,eval-sanitize-20-r1-013-9wf2v.18d41aa133c07552,"reason=Pulled count=1 msg=Container image ""busybox:musl"" already present on machine"
13.5565,Event,ADDED,eval-sanitize-20-r1-013-9wf2v.18d41aa134d230e1,reason=Created count=1 msg=Created container: task
13.5701,Job,MODIFIED,eval-sanitize-20-r1-000,
13.578,Pod,MODIFIED,eval-sanitize-20-r1-000-4gvxt,phase=Succeeded node=kind-worker3
13.5793,Job,MODIFIED,eval-sanitize-20-r1-000,
13.5993,Pod,MODIFIED,eval-sanitize-20-r1-002-v2wms,phase=Running node=kind-worker
13.6867,Event,ADDED,eval-sanitize-20-r1-013-9wf2v.18d41aa13c7d4594,reason=Started count=1 msg=Started container task
14.0143,TaskRequest,ADDED,eval-sanitize-20-r1-014,phase=None job=None
14.0181,TaskRequest,MODIFIED,eval-sanitize-20-r1-014,phase=Pending job=None
14.0339,Job,ADDED,eval-sanitize-20-r1-014,
14.0362,Job,MODIFIED,eval-sanitize-20-r1-013,
14.0403,Pod,ADDED,eval-sanitize-20-r1-014-f5l6t,phase=Pending node=None
14.041,TaskRequest,MODIFIED,eval-sanitize-20-r1-014,phase=Scheduled job=None
14.0436,Job,MODIFIED,eval-sanitize-20-r1-014,
14.0461,Event,ADDED,eval-sanitize-20-r1-014.18d41aa151dee847,reason=SuccessfulCreate count=1 msg=Created pod: eval-sanitize-20-r1-014-f5l6t
14.0487,TaskRequest,MODIFIED,eval-sanitize-20-r1-014,phase=Scheduled job=None
14.0513,Job,MODIFIED,eval-sanitize-20-r1-013,
14.1142,Pod,MODIFIED,eval-sanitize-20-r1-014-f5l6t,phase=Pending node=kind-worker5
14.1197,Event,ADDED,eval-sanitize-20-r1-014-f5l6t.18d41aa15649c77d,reason=Scheduled count=None msg=Successfully assigned compute/eval-sanitize-20-r1-014-f5l6t to kind-worker5
14.1269,Node,MODIFIED,kind-worker5,taints=0
14.1284,Pod,MODIFIED,eval-sanitize-20-r1-014-f5l6t,phase=Pending node=kind-worker5
14.1398,Node,MODIFIED,kind-worker,taints=1
14.1414,Node,MODIFIED,kind-worker5,taints=0
14.1535,Node,MODIFIED,kind-worker,taints=1
14.2072,Job,MODIFIED,eval-sanitize-20-r1-001,
14.2161,Pod,MODIFIED,eval-sanitize-20-r1-001-fhsgn,phase=Succeeded node=kind-worker5
14.2184,Job,MODIFIED,eval-sanitize-20-r1-001,
14.3208,Pod,MODIFIED,eval-sanitize-20-r1-012-m6skw,phase=Pending node=None
14.4142,Event,ADDED,eval-sanitize-20-r1-012-m6skw.18d41aa167dc56a0,"reason=FailedScheduling count=None msg=0/6 nodes are available: 1 c_wall violated: 2 conflicting context pair(s) with node memory, 2 node(s) had untolerated taint(s), 3 c_wall violated: 1 conflicting context pair(s) with node memory. no new claims to deallocate, preemption: 0/6 nodes are available: 2 Preemption is not helpful for scheduling, 4 No preemption victims found for incoming pod."
14.5389,Event,ADDED,eval-sanitize-20-r1-014-f5l6t.18d41aa16f598491,"reason=Pulled count=1 msg=Container image ""busybox:musl"" already present on machine"
14.5559,Event,ADDED,eval-sanitize-20-r1-014-f5l6t.18d41aa1706307f5,reason=Created count=1 msg=Created container: task
14.5667,Pod,MODIFIED,eval-sanitize-20-r1-003-q9fhf,phase=Running node=kind-worker3
14.5744,Pod,MODIFIED,eval-sanitize-20-r1-013-9wf2v,phase=Running node=kind-worker3
14.5765,Job,MODIFIED,eval-sanitize-20-r1-000,
14.581,Job,MODIFIED,eval-sanitize-20-r1-000,
14.5855,Event,ADDED,eval-sanitize-20-r1-000.18d41aa1721aba2f,reason=Completed count=1 msg=Job completed
14.5897,Event,MODIFIED,eval-sanitize-20-r1-012-m6skw.18d41aa167dc56a0,"reason=FailedScheduling count=None msg=0/6 nodes are available: 1 c_wall violated: 2 conflicting context pair(s) with node memory, 2 node(s) had untolerated taint(s), 3 c_wall violated: 1 conflicting context pair(s) with node memory. no new claims to deallocate, preemption: 0/6 nodes are available: 2 Preemption is not helpful for scheduling, 4 No preemption victims found for incoming pod."
14.5939,Job,MODIFIED,eval-sanitize-20-r1-000,
14.5998,TaskRequest,MODIFIED,eval-sanitize-20-r1-000,phase=Complete job=None
14.6036,Job,MODIFIED,eval-sanitize-20-r1-002,
14.6101,Job,MODIFIED,eval-sanitize-20-r1-000,
14.6124,Job,MODIFIED,eval-sanitize-20-r1-002,
14.699,Event,ADDED,eval-sanitize-20-r1-014-f5l6t.18d41aa178dc6a28,reason=Started count=1 msg=Started container task
14.8162,Pod,MODIFIED,eval-sanitize-20-r1-002-v2wms,phase=Succeeded node=kind-worker
15.003,Node,MODIFIED,kind-worker4,taints=1
15.0116,TaskRequest,ADDED,eval-sanitize-20-r1-015,phase=None job=None
15.0182,Node,MODIFIED,kind-worker4,taints=1
15.0186,TaskRequest,MODIFIED,eval-sanitize-20-r1-015,phase=Pending job=None
15.022,Pod,MODIFIED,eval-sanitize-20-r1-012-m6skw,phase=Pending node=None
15.0367,Job,ADDED,eval-sanitize-20-r1-015,
15.0413,Job,MODIFIED,eval-sanitize-20-r1-013,
15.0429,TaskRequest,MODIFIED,eval-sanitize-20-r1-015,phase=Scheduled job=None
15.0441,Pod,ADDED,eval-sanitize-20-r1-015-tkjff,phase=Pending node=None
15.0459,Job,MODIFIED,eval-sanitize-20-r1-014,
15.0528,Job,MODIFIED,eval-sanitize-20-r1-015,
15.0546,Event,ADDED,eval-sanitize-20-r1-015.18d41aa18dad2ab7,reason=SuccessfulCreate count=1 msg=Created pod: eval-sanitize-20-r1-015-tkjff
15.0568,TaskRequest,MODIFIED,eval-sanitize-20-r1-015,phase=Scheduled job=None
15.0576,Job,MODIFIED,eval-sanitize-20-r1-013,
15.0597,Job,MODIFIED,eval-sanitize-20-r1-014,
15.133,Pod,MODIFIED,eval-sanitize-20-r1-015-tkjff,phase=Pending node=kind-worker2
15.1364,Event,ADDED,eval-sanitize-20-r1-015-tkjff.18d41aa192f5b04e,reason=Scheduled count=None msg=Successfully assigned compute/eval-sanitize-20-r1-015-tkjff to kind-worker2
15.1423,Pod,MODIFIED,eval-sanitize-20-r1-015-tkjff,phase=Pending node=kind-worker2
15.2044,Pod,MODIFIED,eval-sanitize-20-r1-004-tf9vj,phase=Running node=kind-worker5
15.2137,Pod,MODIFIED,eval-sanitize-20-r1-014-f5l6t,phase=Running node=kind-worker5
15.2146,Job,MODIFIED,eval-sanitize-20-r1-001,
15.2197,Job,MODIFIED,eval-sanitize-20-r1-001,
15.2207,Event,ADDED,eval-sanitize-20-r1-012-m6skw.18d41aa197e5e65e,"reason=FailedScheduling count=None msg=0/6 nodes are available: 1 c_wall violated: 2 conflicting context pair(s) with node memory, 2 c_wall violated: 1 conflicting context pair(s) with node memory, 3 node(s) had untolerated taint(s). no new claims to deallocate, preemption: 0/6 nodes are available: 3 No preemption victims found for incoming pod, 3 Preemption is not helpful for scheduling."
15.2237,Event,ADDED,eval-sanitize-20-r1-001.18d41aa1982c791d,reason=Completed count=1 msg=Job completed
15.2299,Job,MODIFIED,eval-sanitize-20-r1-001,
15.2347,TaskRequest,MODIFIED,eval-sanitize-20-r1-001,phase=Complete job=None
15.243,Job,MODIFIED,eval-sanitize-20-r1-001,
15.3138,Event,MODIFIED,eval-sanitize-20-r1-012-m6skw.18d41aa197e5e65e,"reason=FailedScheduling count=None msg=0/6 nodes are available: 1 c_wall violated: 2 conflicting context pair(s) with node memory, 2 c_wall violated: 1 conflicting context pair(s) with node memory, 3 node(s) had untolerated taint(s). no new claims to deallocate, preemption: 0/6 nodes are available: 3 No preemption victims found for incoming pod, 3 Preemption is not helpful for scheduling."
15.5722,Job,MODIFIED,eval-sanitize-20-r1-003,
15.5753,Pod,MODIFIED,eval-sanitize-20-r1-005-hcgjl,phase=Running node=kind-worker3
15.5819,Job,MODIFIED,eval-sanitize-20-r1-003,
15.6119,Job,MODIFIED,eval-sanitize-20-r1-002,
15.6208,Pod,MODIFIED,eval-sanitize-20-r1-002-v2wms,phase=Succeeded node=kind-worker
15.6228,Job,MODIFIED,eval-sanitize-20-r1-002,
15.6593,Node,MODIFIED,kind-worker3,taints=1
15.6721,Pod,MODIFIED,eval-sanitize-20-r1-012-m6skw,phase=Pending node=None
15.6751,Event,ADDED,eval-sanitize-20-r1-015-tkjff.18d41aa1b2dd004f,"reason=Pulled count=1 msg=Container image ""busybox:musl"" already present on machine"
15.6767,Node,MODIFIED,kind-worker3,taints=1
15.6851,Event,ADDED,eval-sanitize-20-r1-012-m6skw.18d41aa1b3948e66,"reason=FailedScheduling count=None msg=0/6 nodes are available: 2 c_wall violated: 1 conflicting context pair(s) with node memory, 4 node(s) had untolerated taint(s). no new claims to deallocate, preemption: 0/6 nodes are available: 2 No preemption victims found for incoming pod, 4 Preemption is not helpful for scheduling."
15.6893,Event,MODIFIED,eval-sanitize-20-r1-012-m6skw.18d41aa1b3948e66,"reason=FailedScheduling count=None msg=0/6 nodes are available: 2 c_wall violated: 1 conflicting context pair(s) with node memory, 4 node(s) had untolerated taint(s). no new claims to deallocate, preemption: 0/6 nodes are available: 2 No preemption victims found for incoming pod, 4 Preemption is not helpful for scheduling."
15.6936,Event,ADDED,eval-sanitize-20-r1-015-tkjff.18d41aa1b43e8ef6,reason=Created count=1 msg=Created container: task
15.7674,Event,ADDED,eval-sanitize-20-r1-015-tkjff.18d41aa1b8952404,reason=Started count=1 msg=Started container task
15.8374,Pod,MODIFIED,eval-sanitize-20-r1-003-q9fhf,phase=Succeeded node=kind-worker3
16.0079,TaskRequest,ADDED,eval-sanitize-20-r1-016,phase=None job=None
16.0115,TaskRequest,MODIFIED,eval-sanitize-20-r1-016,phase=Pending job=None
16.0281,Job,ADDED,eval-sanitize-20-r1-016,
16.0332,TaskRequest,MODIFIED,eval-sanitize-20-r1-016,phase=Scheduled job=None
16.0356,Pod,ADDED,eval-sanitize-20-r1-016-rhx4s,phase=Pending node=None
16.0374,Job,MODIFIED,eval-sanitize-20-r1-016,
16.0415,Event,ADDED,eval-sanitize-20-r1-016.18d41aa1c8ce0d83,reason=SuccessfulCreate count=1 msg=Created pod: eval-sanitize-20-r1-016-rhx4s
16.0416,TaskRequest,MODIFIED,eval-sanitize-20-r1-016,phase=Scheduled job=None
16.0483,Pod,MODIFIED,eval-sanitize-20-r1-016-rhx4s,phase=Pending node=None
16.0493,Event,ADDED,eval-sanitize-20-r1-016-rhx4s.18d41aa1c94066eb,"reason=FailedScheduling count=None msg=0/6 nodes are available: 2 c_wall violated: 1 conflicting context pair(s) with node memory, 4 node(s) had untolerated taint(s). no new claims to deallocate, preemption: 0/6 nodes are available: 2 No preemption victims found for incoming pod, 4 Preemption is not helpful for scheduling."
16.0501,Job,MODIFIED,eval-sanitize-20-r1-015,
16.0522,Job,MODIFIED,eval-sanitize-20-r1-014,
16.0605,Job,MODIFIED,eval-sanitize-20-r1-015,
16.0618,Event,ADDED,eval-sanitize-20-r1-016-rhx4s.18d41aa1ca08d5b7,"reason=FailedScheduling count=None msg=0/6 nodes are available: 2 c_wall violated: 1 conflicting context pair(s) with node memory, 4 node(s) had untolerated taint(s). no new claims to deallocate, preemption: 0/6 nodes are available: 2 No preemption victims found for incoming pod, 4 Preemption is not helpful for scheduling."
16.0625,Job,MODIFIED,eval-sanitize-20-r1-014,
16.1318,Pod,MODIFIED,eval-sanitize-20-r1-015-tkjff,phase=Running node=kind-worker2
16.1488,Event,MODIFIED,eval-sanitize-20-r1-016-rhx4s.18d41aa1ca08d5b7,"reason=FailedScheduling count=None msg=0/6 nodes are available: 2 c_wall violated: 1 conflicting context pair(s) with node memory, 4 node(s) had untolerated taint(s). no new claims to deallocate, preemption: 0/6 nodes are available: 2 No preemption victims found for incoming pod, 4 Preemption is not helpful for scheduling."
16.2141,Job,MODIFIED,eval-sanitize-20-r1-004,
16.2241,Job,MODIFIED,eval-sanitize-20-r1-004,
16.3356,Pod,MODIFIED,eval-sanitize-20-r1-004-tf9vj,phase=Succeeded node=kind-worker5
16.5996,Job,MODIFIED,eval-sanitize-20-r1-003,
16.602,Job,MODIFIED,eval-sanitize-20-r1-005,
16.6077,Pod,MODIFIED,eval-sanitize-20-r1-003-q9fhf,phase=Succeeded node=kind-worker3
16.6096,Job,MODIFIED,eval-sanitize-20-r1-003,
16.6108,Job,MODIFIED,eval-sanitize-20-r1-005,
16.6161,Job,MODIFIED,eval-sanitize-20-r1-002,
16.6206,Job,MODIFIED,eval-sanitize-20-r1-002,
16.6248,Event,ADDED,eval-sanitize-20-r1-002.18d41aa1eba5953b,reason=Completed count=1 msg=Job completed
16.6306,Job,MODIFIED,eval-sanitize-20-r1-002,
16.6349,TaskRequest,MODIFIED,eval-sanitize-20-r1-002,phase=Complete job=None
16.6453,Job,MODIFIED,eval-sanitize-20-r1-002,
16.7339,Pod,MODIFIED,eval-sanitize-20-r1-005-hcgjl,phase=Succeeded node=kind-worker3
16.9558,Node,MODIFIED,kind-worker2,taints=1
16.964,Pod,MODIFIED,eval-sanitize-20-r1-012-m6skw,phase=Pending node=None
16.9682,Node,MODIFIED,kind-worker2,taints=1
16.9714,Pod,MODIFIED,eval-sanitize-20-r1-016-rhx4s,phase=Pending node=None
16.979,Event,ADDED,eval-sanitize-20-r1-012-m6skw.18d41aa200c7d429,"reason=FailedScheduling count=None msg=0/6 nodes are available: 1 c_wall violated: 1 conflicting context pair(s) with node memory, 5 node(s) had untolerated taint(s). no new claims to deallocate, preemption: 0/6 nodes are available: 1 No preemption victims found for incoming pod, 5 Preemption is not helpful for scheduling."
16.9797,Event,ADDED,eval-sanitize-20-r1-016-rhx4s.18d41aa200eb824c,"reason=FailedScheduling count=None msg=0/6 nodes are available: 1 c_wall violated: 1 conflicting context pair(s) with node memory, 5 node(s) had untolerated taint(s). no new claims to deallocate, preemption: 0/6 nodes are available: 1 No preemption victims found for incoming pod, 5 Preemption is not helpful for scheduling."
17.0095,TaskRequest,ADDED,eval-sanitize-20-r1-017,phase=None job=None
17.0146,TaskRequest,MODIFIED,eval-sanitize-20-r1-017,phase=Pending job=None
17.0308,Job,ADDED,eval-sanitize-20-r1-017,
17.0336,Pod,MODIFIED,eval-sanitize-20-r1-006-bzlm5,phase=Running node=kind-worker4
17.0364,Pod,ADDED,eval-sanitize-20-r1-017-82hwg,phase=Pending node=None
17.0381,TaskRequest,MODIFIED,eval-sanitize-20-r1-017,phase=Scheduled job=None
17.0418,Job,MODIFIED,eval-sanitize-20-r1-016,
17.0424,Event,ADDED,eval-sanitize-20-r1-017.18d41aa20477fe06,reason=SuccessfulCreate count=1 msg=Created pod: eval-sanitize-20-r1-017-82hwg
17.0437,Job,MODIFIED,eval-sanitize-20-r1-017,
17.0471,Pod,MODIFIED,eval-sanitize-20-r1-017-82hwg,phase=Pending node=kind-worker5
17.0476,Event,MODIFIED,eval-sanitize-20-r1-012-m6skw.18d41aa200c7d429,"reason=FailedScheduling count=None msg=0/6 nodes are available: 1 c_wall violated: 1 conflicting context pair(s) with node memory, 5 node(s) had untolerated taint(s). no new claims to deallocate, preemption: 0/6 nodes are available: 1 No preemption victims found for incoming pod, 5 Preemption is not helpful for scheduling."
17.0492,TaskRequest,MODIFIED,eval-sanitize-20-r1-017,phase=Scheduled job=None
17.0505,Job,MODIFIED,eval-sanitize-20-r1-017,
17.0541,Event,MODIFIED,eval-sanitize-20-r1-016-rhx4s.18d41aa200eb824c,"reason=FailedScheduling count=None msg=0/6 nodes are available: 1 c_wall violated: 1 conflicting context pair(s) with node memory, 5 node(s) had untolerated taint(s). no new claims to deallocate, preemption: 0/6 nodes are available: 1 No preemption victims found for incoming pod, 5 Preemption is not helpful for scheduling."
17.0588,Event,ADDED,eval-sanitize-20-r1-017-82hwg.18d41aa2050b5e0b,reason=Scheduled count=None msg=Successfully assigned compute/eval-sanitize-20-r1-017-82hwg to kind-worker5
17.0598,Job,MODIFIED,eval-sanitize-20-r1-016,
17.0614,Job,MODIFIED,eval-sanitize-20-r1-015,
17.0628,Pod,MODIFIED,eval-sanitize-20-r1-017-82hwg,phase=Pending node=kind-worker5
17.0635,Job,MODIFIED,eval-sanitize-20-r1-017,
17.1006,Job,MODIFIED,eval-sanitize-20-r1-015,
17.2205,Job,MODIFIED,eval-sanitize-20-r1-004,
17.2301,Pod,MODIFIED,eval-sanitize-20-r1-004-tf9vj,phase=Succeeded node=kind-worker5
17.2322,Job,MODIFIED,eval-sanitize-20-r1-004,
17.2335,Node,MODIFIED,kind-worker5,taints=1
17.2374,Pod,MODIFIED,eval-sanitize-20-r1-012-m6skw,phase=Pending node=None
17.2425,Pod,MODIFIED,eval-sanitize-20-r1-016-rhx4s,phase=Pending node=None
17.2454,Node,MODIFIED,kind-worker5,taints=1
17.4825,Event,ADDED,eval-sanitize-20-r1-017-82hwg.18d41aa21ec45fb1,"reason=Pulled count=1 msg=Container image ""busybox:musl"" already present on machine"
17.5022,Event,ADDED,eval-sanitize-20-r1-017-82hwg.18d41aa21ff5a321,reason=Created count=1 msg=Created container: task
17.5377,Event,ADDED,eval-sanitize-20-r1-017-82hwg.18d41aa2220ec297,reason=Started count=1 msg=Started container task
17.6087,Job,MODIFIED,eval-sanitize-20-r1-003,
17.61,Job,MODIFIED,eval-sanitize-20-r1-005,
17.6124,Job,MODIFIED,eval-sanitize-20-r1-003,
17.6159,Event,ADDED,eval-sanitize-20-r1-003.18d41aa226d07322,reason=Completed count=1 msg=Job completed
17.6194,Pod,MODIFIED,eval-sanitize-20-r1-005-hcgjl,phase=Succeeded node=kind-worker3
17.6238,Job,MODIFIED,eval-sanitize-20-r1-005,
17.6297,Event,ADDED,eval-sanitize-20-r1-005.18d41aa22779454b,reason=Completed count=1 msg=Job completed
17.7155,Job,MODIFIED,eval-sanitize-20-r1-003,
17.7166,Job,MODIFIED,eval-sanitize-20-r1-005,
17.7193,TaskRequest,MODIFIED,eval-sanitize-20-r1-003,phase=Complete job=None
17.7977,TaskRequest,MODIFIED,eval-sanitize-20-r1-005,phase=Complete job=None
17.8028,Job,MODIFIED,eval-sanitize-20-r1-003,
17.8077,Job,MODIFIED,eval-sanitize-20-r1-005,
18.0221,TaskRequest,ADDED,eval-sanitize-20-r1-018,phase=None job=None
18.0261,TaskRequest,MODIFIED,eval-sanitize-20-r1-018,phase=Pending job=None
18.0394,Job,MODIFIED,eval-sanitize-20-r1-006,
18.0423,Job,ADDED,eval-sanitize-20-r1-018,
18.0491,TaskRequest,MODIFIED,eval-sanitize-20-r1-018,phase=Scheduled job=None
18.0558,Pod,ADDED,eval-sanitize-20-r1-018-tml46,phase=Pending node=None
18.0566,Job,MODIFIED,eval-sanitize-20-r1-018,
18.06,Event,ADDED,eval-sanitize-20-r1-018.18d41aa2411e431f,reason=SuccessfulCreate count=1 msg=Created pod: eval-sanitize-20-r1-018-tml46
18.061,Pod,MODIFIED,eval-sanitize-20-r1-018-tml46,phase=Pending node=None
18.0615,Event,ADDED,eval-sanitize-20-r1-018-tml46.18d41aa241282aa5,"reason=FailedScheduling count=None msg=0/6 nodes are available: 6 node(s) had untolerated taint(s). no new claims to deallocate, preemption: 0/6 nodes are available: 6 Preemption is not helpful for scheduling."
18.0618,TaskRequest,MODIFIED,eval-sanitize-20-r1-018,phase=Scheduled job=None
18.0625,Job,MODIFIED,eval-sanitize-20-r1-006,
18.1308,Pod,MODIFIED,eval-sanitize-20-r1-006-bzlm5,phase=Succeeded node=kind-worker4
18.1356,Pod,MODIFIED,eval-sanitize-20-r1-007-5jj5w,phase=Running node=kind-worker2
18.2133,Pod,MODIFIED,eval-sanitize-20-r1-017-82hwg,phase=Running node=kind-worker5
18.2259,Job,MODIFIED,eval-sanitize-20-r1-004,
18.2309,Job,MODIFIED,eval-sanitize-20-r1-004,
18.2357,Event,ADDED,eval-sanitize-20-r1-004.18d41aa24ba72ca8,reason=Completed count=1 msg=Job completed
18.242,Job,MODIFIED,eval-sanitize-20-r1-004,
18.2465,TaskRequest,MODIFIED,eval-sanitize-20-r1-004,phase=Complete job=None
18.2565,Job,MODIFIED,eval-sanitize-20-r1-004,
19.0063,TaskRequest,ADDED,eval-sanitize-20-r1-019,phase=None job=None
19.0098,TaskRequest,MODIFIED,eval-sanitize-20-r1-019,phase=Pending job=None
19.0244,Job,ADDED,eval-sanitize-20-r1-019,
19.0276,TaskRequest,MODIFIED,eval-sanitize-20-r1-019,phase=Scheduled job=None
19.0307,Pod,ADDED,eval-sanitize-20-r1-019-dl74d,phase=Pending node=None
19.034,Job,MODIFIED,eval-sanitize-20-r1-019,
19.0358,Event,ADDED,eval-sanitize-20-r1-019.18d41aa27b55d0cb,reason=SuccessfulCreate count=1 msg=Created pod: eval-sanitize-20-r1-019-dl74d
19.0358,TaskRequest,MODIFIED,eval-sanitize-20-r1-019,phase=Scheduled job=None
19.0366,Pod,MODIFIED,eval-sanitize-20-r1-019-dl74d,phase=Pending node=None
19.0369,Event,ADDED,eval-sanitize-20-r1-019-dl74d.18d41aa27b634e54,"reason=FailedScheduling count=None msg=0/6 nodes are available: 6 node(s) had untolerated taint(s). no new claims to deallocate, preemption: 0/6 nodes are available: 6 Preemption is not helpful for scheduling."
19.0431,Job,MODIFIED,eval-sanitize-20-r1-006,
19.0503,Pod,MODIFIED,eval-sanitize-20-r1-006-bzlm5,phase=Succeeded node=kind-worker4
19.0518,Job,MODIFIED,eval-sanitize-20-r1-006,
19.0579,Job,MODIFIED,eval-sanitize-20-r1-018,
19.0662,Job,MODIFIED,eval-sanitize-20-r1-018,
19.1411,Job,MODIFIED,eval-sanitize-20-r1-007,
19.1532,Job,MODIFIED,eval-sanitize-20-r1-007,
19.2153,Pod,MODIFIED,eval-sanitize-20-r1-008-vx6kf,phase=Running node=kind-worker5
19.2166,Pod,MODIFIED,eval-sanitize-20-r1-007-5jj5w,phase=Succeeded node=kind-worker2
19.2182,Job,MODIFIED,eval-sanitize-20-r1-017,
19.2266,Job,MODIFIED,eval-sanitize-20-r1-017,
20.0221,TaskRequest,ADDED,eval-sanitize-20-r1-020,phase=None job=None
20.0259,TaskRequest,MODIFIED,eval-sanitize-20-r1-020,phase=Pending job=None
20.0366,Job,MODIFIED,eval-sanitize-20-r1-019,
20.0402,Job,ADDED,eval-sanitize-20-r1-020,
20.047,Pod,ADDED,eval-sanitize-20-r1-020-xv9d4,phase=Pending node=None
20.0479,TaskRequest,MODIFIED,eval-sanitize-20-r1-020,phase=Scheduled job=None
20.0488,Job,MODIFIED,eval-sanitize-20-r1-006,
20.0507,Job,MODIFIED,eval-sanitize-20-r1-020,
20.0528,Event,ADDED,eval-sanitize-20-r1-020.18d41aa2b7e3bcc2,reason=SuccessfulCreate count=1 msg=Created pod: eval-sanitize-20-r1-020-xv9d4
20.053,Event,ADDED,eval-sanitize-20-r1-020-xv9d4.18d41aa2b7ef56ba,"reason=FailedScheduling count=None msg=0/6 nodes are available: 6 node(s) had untolerated taint(s). no new claims to deallocate, preemption: 0/6 nodes are available: 6 Preemption is not helpful for scheduling."
20.0539,Job,MODIFIED,eval-sanitize-20-r1-006,
20.0548,Pod,MODIFIED,eval-sanitize-20-r1-020-xv9d4,phase=Pending node=None
20.0572,TaskRequest,MODIFIED,eval-sanitize-20-r1-020,phase=Scheduled job=None
20.0593,Event,ADDED,eval-sanitize-20-r1-006.18d41aa2b847de52,reason=Completed count=1 msg=Job completed
20.0602,Job,MODIFIED,eval-sanitize-20-r1-019,
20.0619,Job,MODIFIED,eval-sanitize-20-r1-006,
20.0767,TaskRequest,MODIFIED,eval-sanitize-20-r1-006,phase=Complete job=None
20.0904,Job,MODIFIED,eval-sanitize-20-r1-006,
20.1478,Job,MODIFIED,eval-sanitize-20-r1-007,
20.1569,Pod,MODIFIED,eval-sanitize-20-r1-007-5jj5w,phase=Succeeded node=kind-worker2
20.1579,Job,MODIFIED,eval-sanitize-20-r1-007,
20.2233,Job,MODIFIED,eval-sanitize-20-r1-008,
20.235,Job,MODIFIED,eval-sanitize-20-r1-008,
20.3982,Pod,MODIFIED,eval-sanitize-20-r1-008-vx6kf,phase=Succeeded node=kind-worker5
20.614,Pod,MODIFIED,eval-sanitize-20-r1-009-wrws4,phase=Running node=kind-worker
21.0062,TaskRequest,ADDED,eval-sanitize-20-r1-021,phase=None job=None
21.011,TaskRequest,MODIFIED,eval-sanitize-20-r1-021,phase=Pending job=None
21.0247,Job,ADDED,eval-sanitize-20-r1-021,
21.0306,Pod,ADDED,eval-sanitize-20-r1-021-77dzv,phase=Pending node=None
21.0322,TaskRequest,MODIFIED,eval-sanitize-20-r1-021,phase=Scheduled job=None
21.0348,Job,MODIFIED,eval-sanitize-20-r1-021,
21.0382,Event,ADDED,eval-sanitize-20-r1-021.18d41aa2f28e5409,reason=SuccessfulCreate count=1 msg=Created pod: eval-sanitize-20-r1-021-77dzv
21.0384,Event,ADDED,eval-sanitize-20-r1-021-77dzv.18d41aa2f29b9568,"reason=FailedScheduling count=None msg=0/6 nodes are available: 6 node(s) had untolerated taint(s). no new claims to deallocate, preemption: 0/6 nodes are available: 6 Preemption is not helpful for scheduling."
21.0392,Pod,MODIFIED,eval-sanitize-20-r1-021-77dzv,phase=Pending node=None
21.0393,TaskRequest,MODIFIED,eval-sanitize-20-r1-021,phase=Scheduled job=None
21.0517,Job,MODIFIED,eval-sanitize-20-r1-020,
21.0603,Job,MODIFIED,eval-sanitize-20-r1-020,
21.1529,Job,MODIFIED,eval-sanitize-20-r1-007,
21.1574,Job,MODIFIED,eval-sanitize-20-r1-007,
21.1619,Event,ADDED,eval-sanitize-20-r1-007.18d41aa2fa1df424,reason=Completed count=1 msg=Job completed
21.1675,Job,MODIFIED,eval-sanitize-20-r1-007,
21.1724,TaskRequest,MODIFIED,eval-sanitize-20-r1-007,phase=Complete job=None
21.1815,Job,MODIFIED,eval-sanitize-20-r1-007,
21.2293,Job,MODIFIED,eval-sanitize-20-r1-008,
21.2378,Pod,MODIFIED,eval-sanitize-20-r1-008-vx6kf,phase=Succeeded node=kind-worker5
21.239,Job,MODIFIED,eval-sanitize-20-r1-008,
21.6194,Pod,MODIFIED,eval-sanitize-20-r1-010-qvrjj,phase=Running node=kind-worker
21.6204,Job,MODIFIED,eval-sanitize-20-r1-009,
21.6304,Job,MODIFIED,eval-sanitize-20-r1-009,
21.7472,Pod,MODIFIED,eval-sanitize-20-r1-009-wrws4,phase=Succeeded node=kind-worker
22.0096,TaskRequest,ADDED,eval-sanitize-20-r1-022,phase=None job=None
22.0147,TaskRequest,MODIFIED,eval-sanitize-20-r1-022,phase=Pending job=None
22.0298,Job,ADDED,eval-sanitize-20-r1-022,
22.0361,Job,MODIFIED,eval-sanitize-20-r1-021,
22.0379,TaskRequest,MODIFIED,eval-sanitize-20-r1-022,phase=Scheduled job=None
22.0393,Pod,ADDED,eval-sanitize-20-r1-022-qr2sk,phase=Pending node=None
22.0405,Job,MODIFIED,eval-sanitize-20-r1-022,
22.0453,Event,ADDED,eval-sanitize-20-r1-022.18d41aa32ea0a511,reason=SuccessfulCreate count=1 msg=Created pod: eval-sanitize-20-r1-022-qr2sk
22.0456,Event,ADDED,eval-sanitize-20-r1-022-qr2sk.18d41aa32ead56ed,"reason=FailedScheduling count=None msg=0/6 nodes are available: 6 node(s) had untolerated taint(s). no new claims to deallocate, preemption: 0/6 nodes are available: 6 Preemption is not helpful for scheduling."
22.0471,Pod,MODIFIED,eval-sanitize-20-r1-011-hkzpx,phase=Running node=kind-worker4
22.0472,TaskRequest,MODIFIED,eval-sanitize-20-r1-022,phase=Scheduled job=None
22.048,Pod,MODIFIED,eval-sanitize-20-r1-022-qr2sk,phase=Pending node=None
22.0495,Job,MODIFIED,eval-sanitize-20-r1-021,
22.2365,Job,MODIFIED,eval-sanitize-20-r1-008,
22.2409,Job,MODIFIED,eval-sanitize-20-r1-008,
22.2459,Event,ADDED,eval-sanitize-20-r1-008.18d41aa33ab0c46d,reason=Completed count=1 msg=Job completed
22.2523,Job,MODIFIED,eval-sanitize-20-r1-008,
22.2594,TaskRequest,MODIFIED,eval-sanitize-20-r1-008,phase=Complete job=None
22.2694,Job,MODIFIED,eval-sanitize-20-r1-008,
22.6285,Job,MODIFIED,eval-sanitize-20-r1-010,
22.6302,Job,MODIFIED,eval-sanitize-20-r1-009,
22.641,Job,MODIFIED,eval-sanitize-20-r1-010,
22.6425,Pod,MODIFIED,eval-sanitize-20-r1-009-wrws4,phase=Succeeded node=kind-worker
22.6443,Job,MODIFIED,eval-sanitize-20-r1-009,
22.7563,Pod,MODIFIED,eval-sanitize-20-r1-010-qvrjj,phase=Succeeded node=kind-worker
23.0109,TaskRequest,ADDED,eval-sanitize-20-r1-023,phase=None job=None
23.0149,TaskRequest,MODIFIED,eval-sanitize-20-r1-023,phase=Pending job=None
23.0304,Job,ADDED,eval-sanitize-20-r1-023,
23.0363,Pod,ADDED,eval-sanitize-20-r1-023-lhw8g,phase=Pending node=None
23.0384,Job,MODIFIED,eval-sanitize-20-r1-023,
23.0386,TaskRequest,MODIFIED,eval-sanitize-20-r1-023,phase=Scheduled job=None
23.0417,Event,ADDED,eval-sanitize-20-r1-023.18d41aa36a1d9185,reason=SuccessfulCreate count=1 msg=Created pod: eval-sanitize-20-r1-023-lhw8g
23.0427,Pod,MODIFIED,eval-sanitize-20-r1-023-lhw8g,phase=Pending node=None
23.044,Event,ADDED,eval-sanitize-20-r1-023-lhw8g.18d41aa36a2b6f02,"reason=FailedScheduling count=None msg=0/6 nodes are available: 6 node(s) had untolerated taint(s). no new claims to deallocate, preemption: 0/6 nodes are available: 6 Preemption is not helpful for scheduling."
23.0451,Job,MODIFIED,eval-sanitize-20-r1-022,
23.0478,TaskRequest,MODIFIED,eval-sanitize-20-r1-023,phase=Scheduled job=None
23.0509,Job,MODIFIED,eval-sanitize-20-r1-011,
23.0537,Job,MODIFIED,eval-sanitize-20-r1-022,
23.0596,Job,MODIFIED,eval-sanitize-20-r1-011,
23.1847,Pod,MODIFIED,eval-sanitize-20-r1-011-hkzpx,phase=Succeeded node=kind-worker4
23.6384,Job,MODIFIED,eval-sanitize-20-r1-010,
23.6402,Job,MODIFIED,eval-sanitize-20-r1-009,
23.6443,Job,MODIFIED,eval-sanitize-20-r1-009,
23.6469,Pod,MODIFIED,eval-sanitize-20-r1-010-qvrjj,phase=Succeeded node=kind-worker
23.6482,Job,MODIFIED,eval-sanitize-20-r1-010,
23.6496,Event,ADDED,eval-sanitize-20-r1-009.18d41aa38e5cde1d,reason=Completed count=1 msg=Job completed
23.657,Job,MODIFIED,eval-sanitize-20-r1-009,
23.6614,TaskRequest,MODIFIED,eval-sanitize-20-r1-009,phase=Complete job=None
23.6708,Job,MODIFIED,eval-sanitize-20-r1-009,
24.0112,TaskRequest,ADDED,eval-sanitize-20-r1-024,phase=None job=None
24.0155,TaskRequest,MODIFIED,eval-sanitize-20-r1-024,phase=Pending job=None
24.0318,Job,ADDED,eval-sanitize-20-r1-024,
24.0388,Pod,ADDED,eval-sanitize-20-r1-024-jjnk6,phase=Pending node=None
24.0408,TaskRequest,MODIFIED,eval-sanitize-20-r1-024,phase=Scheduled job=None
24.0415,Job,MODIFIED,eval-sanitize-20-r1-024,
24.0435,Job,MODIFIED,eval-sanitize-20-r1-023,
24.0454,Event,ADDED,eval-sanitize-20-r1-024.18d41aa3a5d908e7,reason=SuccessfulCreate count=1 msg=Created pod: eval-sanitize-20-r1-024-jjnk6
24.0457,Event,ADDED,eval-sanitize-20-r1-024-jjnk6.18d41aa3a5e2fe6f,"reason=FailedScheduling count=None msg=0/6 nodes are available: 6 node(s) had untolerated taint(s). no new claims to deallocate, preemption: 0/6 nodes are available: 6 Preemption is not helpful for scheduling."
24.0466,Pod,MODIFIED,eval-sanitize-20-r1-024-jjnk6,phase=Pending node=None
24.0502,TaskRequest,MODIFIED,eval-sanitize-20-r1-024,phase=Scheduled job=None
24.0539,Job,MODIFIED,eval-sanitize-20-r1-023,
24.0559,Job,MODIFIED,eval-sanitize-20-r1-011,
24.065,Pod,MODIFIED,eval-sanitize-20-r1-011-hkzpx,phase=Succeeded node=kind-worker4
24.0663,Job,MODIFIED,eval-sanitize-20-r1-011,
24.5983,Pod,MODIFIED,eval-sanitize-20-r1-013-9wf2v,phase=Running node=kind-worker3
24.644,Job,MODIFIED,eval-sanitize-20-r1-010,
24.6487,Job,MODIFIED,eval-sanitize-20-r1-010,
24.6544,Event,ADDED,eval-sanitize-20-r1-010.18d41aa3ca386bd5,reason=Completed count=1 msg=Job completed
24.6608,Job,MODIFIED,eval-sanitize-20-r1-010,
24.6654,TaskRequest,MODIFIED,eval-sanitize-20-r1-010,phase=Complete job=None
24.6746,Job,MODIFIED,eval-sanitize-20-r1-010,
25.0156,TaskRequest,ADDED,eval-sanitize-20-r1-025,phase=None job=None
25.0211,TaskRequest,MODIFIED,eval-sanitize-20-r1-025,phase=Pending job=None
25.0376,Job,ADDED,eval-sanitize-20-r1-025,
25.0447,Job,MODIFIED,eval-sanitize-20-r1-024,
25.0462,TaskRequest,MODIFIED,eval-sanitize-20-r1-025,phase=Scheduled job=None
25.0473,Pod,ADDED,eval-sanitize-20-r1-025-rp76f,phase=Pending node=None
25.0499,Job,MODIFIED,eval-sanitize-20-r1-025,
25.0544,Event,ADDED,eval-sanitize-20-r1-025.18d41aa3e1f3710c,reason=SuccessfulCreate count=1 msg=Created pod: eval-sanitize-20-r1-025-rp76f
25.0546,Event,ADDED,eval-sanitize-20-r1-025-rp76f.18d41aa3e1fd7121,"reason=FailedScheduling count=None msg=0/6 nodes are available: 6 node(s) had untolerated taint(s). no new claims to deallocate, preemption: 0/6 nodes are available: 6 Preemption is not helpful for scheduling."
25.0555,Pod,MODIFIED,eval-sanitize-20-r1-025-rp76f,phase=Pending node=None
25.056,TaskRequest,MODIFIED,eval-sanitize-20-r1-025,phase=Scheduled job=None
25.06,Job,MODIFIED,eval-sanitize-20-r1-024,
25.0621,Job,MODIFIED,eval-sanitize-20-r1-011,
25.066,Job,MODIFIED,eval-sanitize-20-r1-011,
25.0701,Event,ADDED,eval-sanitize-20-r1-011.18d41aa3e31a49c1,reason=Completed count=1 msg=Job completed
25.1022,Job,MODIFIED,eval-sanitize-20-r1-011,
25.1068,TaskRequest,MODIFIED,eval-sanitize-20-r1-011,phase=Complete job=None
25.1176,Job,MODIFIED,eval-sanitize-20-r1-011,
25.2289,Pod,MODIFIED,eval-sanitize-20-r1-014-f5l6t,phase=Running node=kind-worker5
25.605,Job,MODIFIED,eval-sanitize-20-r1-013,
25.6145,Job,MODIFIED,eval-sanitize-20-r1-013,
25.6981,Pod,MODIFIED,eval-sanitize-20-r1-013-9wf2v,phase=Succeeded node=kind-worker3
26.0115,TaskRequest,ADDED,eval-sanitize-20-r1-026,phase=None job=None
26.0158,TaskRequest,MODIFIED,eval-sanitize-20-r1-026,phase=Pending job=None
26.0327,Job,ADDED,eval-sanitize-20-r1-026,
26.0395,Pod,ADDED,eval-sanitize-20-r1-026-cdlxh,phase=Pending node=None
26.0403,TaskRequest,MODIFIED,eval-sanitize-20-r1-026,phase=Scheduled job=None
26.0426,Job,MODIFIED,eval-sanitize-20-r1-026,
26.0453,Event,ADDED,eval-sanitize-20-r1-026.18d41aa41d1d4e48,reason=SuccessfulCreate count=1 msg=Created pod: eval-sanitize-20-r1-026-cdlxh
26.0464,Pod,MODIFIED,eval-sanitize-20-r1-026-cdlxh,phase=Pending node=None
26.0474,Event,ADDED,eval-sanitize-20-r1-026-cdlxh.18d41aa41d2995a9,"reason=FailedScheduling count=None msg=0/6 nodes are available: 6 node(s) had untolerated taint(s). no new claims to deallocate, preemption: 0/6 nodes are available: 6 Preemption is not helpful for scheduling."
26.0495,TaskRequest,MODIFIED,eval-sanitize-20-r1-026,phase=Scheduled job=None
26.0516,Job,MODIFIED,eval-sanitize-20-r1-025,
26.0601,Job,MODIFIED,eval-sanitize-20-r1-025,
26.1541,Pod,MODIFIED,eval-sanitize-20-r1-015-tkjff,phase=Running node=kind-worker2
26.2363,Job,MODIFIED,eval-sanitize-20-r1-014,
26.2461,Job,MODIFIED,eval-sanitize-20-r1-014,
26.3664,Pod,MODIFIED,eval-sanitize-20-r1-014-f5l6t,phase=Succeeded node=kind-worker5
26.6121,Job,MODIFIED,eval-sanitize-20-r1-013,
26.6201,Pod,MODIFIED,eval-sanitize-20-r1-013-9wf2v,phase=Succeeded node=kind-worker3
26.6214,Job,MODIFIED,eval-sanitize-20-r1-013,
27.0088,TaskRequest,ADDED,eval-sanitize-20-r1-027,phase=None job=None
27.0137,TaskRequest,MODIFIED,eval-sanitize-20-r1-027,phase=Pending job=None
27.0303,Job,ADDED,eval-sanitize-20-r1-027,
27.0366,Pod,ADDED,eval-sanitize-20-r1-027-t6jkc,phase=Pending node=None
27.0376,TaskRequest,MODIFIED,eval-sanitize-20-r1-027,phase=Scheduled job=None
27.0384,Job,MODIFIED,eval-sanitize-20-r1-027,
27.0422,Event,ADDED,eval-sanitize-20-r1-027.18d41aa45886c791,reason=SuccessfulCreate count=1 msg=Created pod: eval-sanitize-20-r1-027-t6jkc
27.0424,Event,ADDED,eval-sanitize-20-r1-027-t6jkc.18d41aa458942516,"reason=FailedScheduling count=None msg=0/6 nodes are available: 6 node(s) had untolerated taint(s). no new claims to deallocate, preemption: 0/6 nodes are available: 6 Preemption is not helpful for scheduling."
27.0434,Pod,MODIFIED,eval-sanitize-20-r1-027-t6jkc,phase=Pending node=None
27.0444,Job,MODIFIED,eval-sanitize-20-r1-026,
27.047,TaskRequest,MODIFIED,eval-sanitize-20-r1-027,phase=Scheduled job=None
27.0546,Job,MODIFIED,eval-sanitize-20-r1-026,
27.1601,Job,MODIFIED,eval-sanitize-20-r1-015,
27.1698,Job,MODIFIED,eval-sanitize-20-r1-015,
27.233,Pod,MODIFIED,eval-sanitize-20-r1-015-tkjff,phase=Succeeded node=kind-worker2
27.2419,Job,MODIFIED,eval-sanitize-20-r1-014,
27.2515,Pod,MODIFIED,eval-sanitize-20-r1-014-f5l6t,phase=Succeeded node=kind-worker5
27.2524,Job,MODIFIED,eval-sanitize-20-r1-014,
27.6209,Job,MODIFIED,eval-sanitize-20-r1-013,
27.6256,Job,MODIFIED,eval-sanitize-20-r1-013,
27.6283,Event,ADDED,eval-sanitize-20-r1-013.18d41aa47ba7b2d0,reason=Completed count=1 msg=Job completed
27.6369,Job,MODIFIED,eval-sanitize-20-r1-013,
27.6408,TaskRequest,MODIFIED,eval-sanitize-20-r1-013,phase=Complete job=None
27.6493,Job,MODIFIED,eval-sanitize-20-r1-013,
28.011,TaskRequest,ADDED,eval-sanitize-20-r1-028,phase=None job=None
28.0163,TaskRequest,MODIFIED,eval-sanitize-20-r1-028,phase=Pending job=None
28.0318,Job,ADDED,eval-sanitize-20-r1-028,
28.0391,Pod,ADDED,eval-sanitize-20-r1-028-26fpq,phase=Pending node=None
28.0393,TaskRequest,MODIFIED,eval-sanitize-20-r1-028,phase=Scheduled job=None
28.0417,Job,MODIFIED,eval-sanitize-20-r1-028,
28.0448,Pod,MODIFIED,eval-sanitize-20-r1-028-26fpq,phase=Pending node=None
28.0456,Event,ADDED,eval-sanitize-20-r1-028.18d41aa49445debb,reason=SuccessfulCreate count=1 msg=Created pod: eval-sanitize-20-r1-028-26fpq
28.0459,Event,ADDED,eval-sanitize-20-r1-028-26fpq.18d41aa4945182ce,"reason=FailedScheduling count=None msg=0/6 nodes are available: 6 node(s) had untolerated taint(s). no new claims to deallocate, preemption: 0/6 nodes are available: 6 Preemption is not helpful for scheduling."
28.0466,Job,MODIFIED,eval-sanitize-20-r1-027,
28.0468,TaskRequest,MODIFIED,eval-sanitize-20-r1-028,phase=Scheduled job=None
28.0536,Job,MODIFIED,eval-sanitize-20-r1-027,
28.1681,Job,MODIFIED,eval-sanitize-20-r1-015,
28.1759,Pod,MODIFIED,eval-sanitize-20-r1-015-tkjff,phase=Succeeded node=kind-worker2
28.1773,Job,MODIFIED,eval-sanitize-20-r1-015,
28.2365,Pod,MODIFIED,eval-sanitize-20-r1-017-82hwg,phase=Running node=kind-worker5
28.2469,Job,MODIFIED,eval-sanitize-20-r1-014,
28.251,Job,MODIFIED,eval-sanitize-20-r1-014,
28.2557,Event,ADDED,eval-sanitize-20-r1-014.18d41aa4a0f19e6f,reason=Completed count=1 msg=Job completed
28.2623,Job,MODIFIED,eval-sanitize-20-r1-014,
28.267,TaskRequest,MODIFIED,eval-sanitize-20-r1-014,phase=Complete job=None
28.276,Job,MODIFIED,eval-sanitize-20-r1-014,
29.0088,TaskRequest,ADDED,eval-sanitize-20-r1-029,phase=None job=None
29.0125,TaskRequest,MODIFIED,eval-sanitize-20-r1-029,phase=Pending job=None
29.0288,Job,ADDED,eval-sanitize-20-r1-029,
29.0353,Pod,ADDED,eval-sanitize-20-r1-029-cjqck,phase=Pending node=None
29.0354,TaskRequest,MODIFIED,eval-sanitize-20-r1-029,phase=Scheduled job=None
29.0377,Job,MODIFIED,eval-sanitize-20-r1-029,
29.0402,Pod,MODIFIED,eval-sanitize-20-r1-029-cjqck,phase=Pending node=None
29.042,Event,ADDED,eval-sanitize-20-r1-029.18d41aa4cfaa9682,reason=SuccessfulCreate count=1 msg=Created pod: eval-sanitize-20-r1-029-cjqck
29.0423,Event,ADDED,eval-sanitize-20-r1-029-cjqck.18d41aa4cfb62ad5,"reason=FailedScheduling count=None msg=0/6 nodes are available: 6 node(s) had untolerated taint(s). no new claims to deallocate, preemption: 0/6 nodes are available: 6 Preemption is not helpful for scheduling."
29.0438,TaskRequest,MODIFIED,eval-sanitize-20-r1-029,phase=Scheduled job=None
29.0445,Job,MODIFIED,eval-sanitize-20-r1-028,
29.0546,Job,MODIFIED,eval-sanitize-20-r1-028,
29.1749,Job,MODIFIED,eval-sanitize-20-r1-015,
29.1789,Job,MODIFIED,eval-sanitize-20-r1-015,
29.1847,Event,ADDED,eval-sanitize-20-r1-015.18d41aa4d8411ef6,reason=Completed count=1 msg=Job completed
29.189,Job,MODIFIED,eval-sanitize-20-r1-015,
29.1944,TaskRequest,MODIFIED,eval-sanitize-20-r1-015,phase=Complete job=None
29.2026,Job,MODIFIED,eval-sanitize-20-r1-015,
29.2458,Job,MODIFIED,eval-sanitize-20-r1-017,
29.2557,Job,MODIFIED,eval-sanitize-20-r1-017,
29.4066,Pod,MODIFIED,eval-sanitize-20-r1-017-82hwg,phase=Succeeded node=kind-worker5
30.0111,TaskRequest,ADDED,eval-sanitize-20-r1-030,phase=None job=None
30.0172,TaskRequest,MODIFIED,eval-sanitize-20-r1-030,phase=Pending job=None
30.0312,Job,ADDED,eval-sanitize-20-r1-030,
30.0375,Pod,ADDED,eval-sanitize-20-r1-030-8p8k8,phase=Pending node=None
30.0389,TaskRequest,MODIFIED,eval-sanitize-20-r1-030,phase=Scheduled job=None
30.0395,Job,MODIFIED,eval-sanitize-20-r1-030,
30.0412,Job,MODIFIED,eval-sanitize-20-r1-029,
30.0431,Event,ADDED,eval-sanitize-20-r1-030.18d41aa50b6b9426,reason=SuccessfulCreate count=1 msg=Created pod: eval-sanitize-20-r1-030-8p8k8
30.0433,Event,ADDED,eval-sanitize-20-r1-030-8p8k8.18d41aa50b78d5e5,"reason=FailedScheduling count=None msg=0/6 nodes are available: 6 node(s) had untolerated taint(s). no new claims to deallocate, preemption: 0/6 nodes are available: 6 Preemption is not helpful for scheduling."
30.044,Pod,MODIFIED,eval-sanitize-20-r1-030-8p8k8,phase=Pending node=None
30.0471,TaskRequest,MODIFIED,eval-sanitize-20-r1-030,phase=Scheduled job=None
30.05,Job,MODIFIED,eval-sanitize-20-r1-029,
30.2528,Job,MODIFIED,eval-sanitize-20-r1-017,
30.2611,Pod,MODIFIED,eval-sanitize-20-r1-017-82hwg,phase=Succeeded node=kind-worker5
30.2627,Job,MODIFIED,eval-sanitize-20-r1-017,
31.0084,TaskRequest,ADDED,eval-sanitize-20-r1-031,phase=None job=None
31.012,TaskRequest,MODIFIED,eval-sanitize-20-r1-031,phase=Pending job=None
31.0261,Job,ADDED,eval-sanitize-20-r1-031,
31.0324,TaskRequest,MODIFIED,eval-sanitize-20-r1-031,phase=Scheduled job=None
31.0359,Job,MODIFIED,eval-sanitize-20-r1-031,
31.0367,Pod,ADDED,eval-sanitize-20-r1-031-dpf7x,phase=Pending node=None
31.0389,Event,ADDED,eval-sanitize-20-r1-031.18d41aa546eb3389,reason=SuccessfulCreate count=1 msg=Created pod: eval-sanitize-20-r1-031-dpf7x
31.0443,Event,ADDED,eval-sanitize-20-r1-031-dpf7x.18d41aa546f82ba3,"reason=FailedScheduling count=None msg=0/6 nodes are available: 6 node(s) had untolerated taint(s). no new claims to deallocate, preemption: 0/6 nodes are available: 6 Preemption is not helpful for scheduling."
31.0445,TaskRequest,MODIFIED,eval-sanitize-20-r1-031,phase=Scheduled job=None
31.0453,Job,MODIFIED,eval-sanitize-20-r1-030,
31.0461,Pod,MODIFIED,eval-sanitize-20-r1-031-dpf7x,phase=Pending node=None
31.0558,Job,MODIFIED,eval-sanitize-20-r1-030,
31.2628,Job,MODIFIED,eval-sanitize-20-r1-017,
31.2673,Job,MODIFIED,eval-sanitize-20-r1-017,
31.2721,Event,ADDED,eval-sanitize-20-r1-017.18d41aa554ba9724,reason=Completed count=1 msg=Job completed
31.2783,Job,MODIFIED,eval-sanitize-20-r1-017,
31.2819,TaskRequest,MODIFIED,eval-sanitize-20-r1-017,phase=Complete job=None
31.2907,Job,MODIFIED,eval-sanitize-20-r1-017,
32.0109,TaskRequest,ADDED,eval-sanitize-20-r1-032,phase=None job=None
32.015,TaskRequest,MODIFIED,eval-sanitize-20-r1-032,phase=Pending job=None
32.0312,Job,ADDED,eval-sanitize-20-r1-032,
32.0355,TaskRequest,MODIFIED,eval-sanitize-20-r1-032,phase=Scheduled job=None
32.0383,Pod,ADDED,eval-sanitize-20-r1-032-v889x,phase=Pending node=None
32.0403,Job,MODIFIED,eval-sanitize-20-r1-032,
32.0427,Job,MODIFIED,eval-sanitize-20-r1-031,
32.045,Event,ADDED,eval-sanitize-20-r1-032.18d41aa582b2c0ce,reason=SuccessfulCreate count=1 msg=Created pod: eval-sanitize-20-r1-032-v889x
32.0454,Event,ADDED,eval-sanitize-20-r1-032-v889x.18d41aa582bd3bb9,"reason=FailedScheduling count=None msg=0/6 nodes are available: 6 node(s) had untolerated taint(s). no new claims to deallocate, preemption: 0/6 nodes are available: 6 Preemption is not helpful for scheduling."
32.0456,TaskRequest,MODIFIED,eval-sanitize-20-r1-032,phase=Scheduled job=None
32.0465,Pod,MODIFIED,eval-sanitize-20-r1-032-v889x,phase=Pending node=None
32.052,Job,MODIFIED,eval-sanitize-20-r1-031,
33.0084,TaskRequest,ADDED,eval-sanitize-20-r1-033,phase=None job=None
33.0122,TaskRequest,MODIFIED,eval-sanitize-20-r1-033,phase=Pending job=None
33.03,Job,ADDED,eval-sanitize-20-r1-033,
33.034,TaskRequest,MODIFIED,eval-sanitize-20-r1-033,phase=Scheduled job=None
33.0378,Pod,ADDED,eval-sanitize-20-r1-033-sstrx,phase=Pending node=None
33.0392,Job,MODIFIED,eval-sanitize-20-r1-033,
33.0438,Event,ADDED,eval-sanitize-20-r1-033.18d41aa5be3ba736,reason=SuccessfulCreate count=1 msg=Created pod: eval-sanitize-20-r1-033-sstrx
33.044,TaskRequest,MODIFIED,eval-sanitize-20-r1-033,phase=Scheduled job=None
33.0455,Pod,MODIFIED,eval-sanitize-20-r1-033-sstrx,phase=Pending node=None
33.0459,Event,ADDED,eval-sanitize-20-r1-033-sstrx.18d41aa5be4cd07a,"reason=FailedScheduling count=None msg=0/6 nodes are available: 6 node(s) had untolerated taint(s). no new claims to deallocate, preemption: 0/6 nodes are available: 6 Preemption is not helpful for scheduling."
33.0468,Job,MODIFIED,eval-sanitize-20-r1-032,
33.0568,Job,MODIFIED,eval-sanitize-20-r1-032,
34.0109,TaskRequest,ADDED,eval-sanitize-20-r1-034,phase=None job=None
34.0156,TaskRequest,MODIFIED,eval-sanitize-20-r1-034,phase=Pending job=None
34.0296,Job,ADDED,eval-sanitize-20-r1-034,
34.0346,TaskRequest,MODIFIED,eval-sanitize-20-r1-034,phase=Scheduled job=None
34.038,Pod,ADDED,eval-sanitize-20-r1-034-48s2k,phase=Pending node=None
34.0395,Job,MODIFIED,eval-sanitize-20-r1-034,
34.0419,Job,MODIFIED,eval-sanitize-20-r1-033,
34.0435,TaskRequest,MODIFIED,eval-sanitize-20-r1-034,phase=Scheduled job=None
34.0439,Event,ADDED,eval-sanitize-20-r1-034.18d41aa5f9de09be,reason=SuccessfulCreate count=1 msg=Created pod: eval-sanitize-20-r1-034-48s2k
34.0441,Event,ADDED,eval-sanitize-20-r1-034-48s2k.18d41aa5f9eb40b5,"reason=FailedScheduling count=None msg=0/6 nodes are available: 6 node(s) had untolerated taint(s). no new claims to deallocate, preemption: 0/6 nodes are available: 6 Preemption is not helpful for scheduling."
34.045,Pod,MODIFIED,eval-sanitize-20-r1-034-48s2k,phase=Pending node=None
34.0504,Job,MODIFIED,eval-sanitize-20-r1-033,
34.3541,Node,MODIFIED,kind-worker,taints=1
34.3678,Node,MODIFIED,kind-worker,taints=0
34.3731,Pod,MODIFIED,eval-sanitize-20-r1-012-m6skw,phase=Pending node=kind-worker
34.3792,Node,MODIFIED,kind-worker,taints=0
34.3796,Event,ADDED,eval-sanitize-20-r1-012-m6skw.18d41aa60dd2a2c8,reason=Scheduled count=None msg=Successfully assigned compute/eval-sanitize-20-r1-012-m6skw to kind-worker
34.3831,Pod,MODIFIED,eval-sanitize-20-r1-016-rhx4s,phase=Pending node=kind-worker
34.3863,Pod,MODIFIED,eval-sanitize-20-r1-012-m6skw,phase=Pending node=kind-worker
34.3895,Pod,MODIFIED,eval-sanitize-20-r1-018-tml46,phase=Pending node=kind-worker
34.3918,Event,ADDED,eval-sanitize-20-r1-016-rhx4s.18d41aa60e7381ef,reason=Scheduled count=None msg=Successfully assigned compute/eval-sanitize-20-r1-016-rhx4s to kind-worker
34.3921,Event,ADDED,eval-sanitize-20-r1-019-dl74d.18d41aa60e9196a5,"reason=FailedScheduling count=None msg=0/6 nodes are available: 1 c_wall violated: 2 conflicting context pair(s) with node memory, 5 node(s) had untolerated taint(s). no new claims to deallocate, preemption: 0/6 nodes are available: 1 No preemption victims found for incoming pod, 5 Preemption is not helpful for scheduling."
34.393,Pod,MODIFIED,eval-sanitize-20-r1-019-dl74d,phase=Pending node=None
34.3943,Node,MODIFIED,kind-worker,taints=0
34.3991,Pod,MODIFIED,eval-sanitize-20-r1-016-rhx4s,phase=Pending node=kind-worker
34.4002,Event,ADDED,eval-sanitize-20-r1-018-tml46.18d41aa60edb3ebc,reason=Scheduled count=None msg=Successfully assigned compute/eval-sanitize-20-r1-018-tml46 to kind-worker
34.4026,Event,ADDED,eval-sanitize-20-r1-020-xv9d4.18d41aa60f41daa4,"reason=FailedScheduling count=None msg=0/6 nodes are available: 1 c_wall violated: 1 conflicting context pair(s) with node memory, 5 node(s) had untolerated taint(s). no new claims to deallocate, preemption: 0/6 nodes are available: 1 No preemption victims found for incoming pod, 5 Preemption is not helpful for scheduling."
34.4036,Pod,MODIFIED,eval-sanitize-20-r1-020-xv9d4,phase=Pending node=None
34.4058,Pod,MODIFIED,eval-sanitize-20-r1-018-tml46,phase=Pending node=kind-worker
34.4449,Pod,MODIFIED,eval-sanitize-20-r1-021-77dzv,phase=Pending node=None
34.4461,Event,ADDED,eval-sanitize-20-r1-021-77dzv.18d41aa611b9b5fd,"reason=FailedScheduling count=None msg=0/6 nodes are available: 1 c_wall violated: 2 conflicting context pair(s) with node memory, 5 node(s) had untolerated taint(s). no new claims to deallocate, preemption: 0/6 nodes are available: 1 No preemption victims found for incoming pod, 5 Preemption is not helpful for scheduling."
34.4476,Node,MODIFIED,kind-worker,taints=0
34.4574,Node,MODIFIED,kind-worker,taints=0
34.4832,Pod,MODIFIED,eval-sanitize-20-r1-022-qr2sk,phase=Pending node=None
34.4838,Event,ADDED,eval-sanitize-20-r1-022-qr2sk.18d41aa613da7d98,"reason=FailedScheduling count=None msg=0/6 nodes are available: 1 c_wall violated: 2 conflicting context pair(s) with node memory, 5 node(s) had untolerated taint(s). no new claims to deallocate, preemption: 0/6 nodes are available: 1 No preemption victims found for incoming pod, 5 Preemption is not helpful for scheduling."
34.4915,Pod,MODIFIED,eval-sanitize-20-r1-023-lhw8g,phase=Pending node=None
34.4932,Event,ADDED,eval-sanitize-20-r1-023-lhw8g.18d41aa614a38db8,"reason=FailedScheduling count=None msg=0/6 nodes are available: 1 c_wall violated: 1 conflicting context pair(s) with node memory, 5 node(s) had untolerated taint(s). no new claims to deallocate, preemption: 0/6 nodes are available: 1 No preemption victims found for incoming pod, 5 Preemption is not helpful for scheduling."
34.5006,Event,ADDED,eval-sanitize-20-r1-024-jjnk6.18d41aa6151d30f4,"reason=FailedScheduling count=None msg=0/6 nodes are available: 1 c_wall violated: 2 conflicting context pair(s) with node memory, 5 node(s) had untolerated taint(s). no new claims to deallocate, preemption: 0/6 nodes are available: 1 No preemption victims found for incoming pod, 5 Preemption is not helpful for scheduling."
34.5017,Pod,MODIFIED,eval-sanitize-20-r1-024-jjnk6,phase=Pending node=None
34.541,Pod,MODIFIED,eval-sanitize-20-r1-025-rp76f,phase=Pending node=kind-worker
34.5428,Event,ADDED,eval-sanitize-20-r1-026-cdlxh.18d41aa617a8c651,"reason=FailedScheduling count=None msg=0/6 nodes are available: 1 c_wall violated: 1 conflicting context pair(s) with node memory, 5 node(s) had untolerated taint(s). no new claims to deallocate, preemption: 0/6 nodes are available: 1 No preemption victims found for incoming pod, 5 Preemption is not helpful for scheduling."
34.5437,Pod,MODIFIED,eval-sanitize-20-r1-026-cdlxh,phase=Pending node=None
34.5442,Event,ADDED,eval-sanitize-20-r1-025-rp76f.18d41aa617da515a,reason=Scheduled count=None msg=Successfully assigned compute/eval-sanitize-20-r1-025-rp76f to kind-worker
34.5456,Node,MODIFIED,kind-worker,taints=0
34.5522,Pod,MODIFIED,eval-sanitize-20-r1-025-rp76f,phase=Pending node=kind-worker
34.5536,Pod,MODIFIED,eval-sanitize-20-r1-027-t6jkc,phase=Pending node=kind-worker
34.556,Pod,MODIFIED,eval-sanitize-20-r1-028-26fpq,phase=Pending node=kind-worker
34.5575,Node,MODIFIED,kind-worker,taints=0
34.5578,Event,ADDED,eval-sanitize-20-r1-027-t6jkc.18d41aa6189fed7d,reason=Scheduled count=None msg=Successfully assigned compute/eval-sanitize-20-r1-027-t6jkc to kind-worker
34.561,Event,ADDED,eval-sanitize-20-r1-028-26fpq.18d41aa618c12e89,reason=Scheduled count=None msg=Successfully assigned compute/eval-sanitize-20-r1-028-26fpq to kind-worker
34.5644,Pod,MODIFIED,eval-sanitize-20-r1-027-t6jkc,phase=Pending node=kind-worker
34.5701,Pod,MODIFIED,eval-sanitize-20-r1-028-26fpq,phase=Pending node=kind-worker
34.5866,Pod,MODIFIED,eval-sanitize-20-r1-029-cjqck,phase=Pending node=kind-worker
34.5895,Pod,MODIFIED,eval-sanitize-20-r1-030-8p8k8,phase=Pending node=kind-worker
34.5898,Event,ADDED,eval-sanitize-20-r1-029-cjqck.18d41aa61a8bba64,reason=Scheduled count=None msg=Successfully assigned compute/eval-sanitize-20-r1-029-cjqck to kind-worker
34.5957,Pod,MODIFIED,eval-sanitize-20-r1-031-dpf7x,phase=Pending node=kind-worker
34.596,Event,ADDED,eval-sanitize-20-r1-030-8p8k8.18d41aa61ac1cf53,reason=Scheduled count=None msg=Successfully assigned compute/eval-sanitize-20-r1-030-8p8k8 to kind-worker
34.5992,Event,ADDED,eval-sanitize-20-r1-031-dpf7x.18d41aa61b1bb109,reason=Scheduled count=None msg=Successfully assigned compute/eval-sanitize-20-r1-031-dpf7x to kind-worker
34.6054,Pod,MODIFIED,eval-sanitize-20-r1-029-cjqck,phase=Pending node=kind-worker
34.6068,Node,MODIFIED,kind-worker,taints=0
34.6123,Pod,MODIFIED,eval-sanitize-20-r1-031-dpf7x,phase=Pending node=kind-worker
34.6159,Node,MODIFIED,kind-worker,taints=0
34.6176,Pod,MODIFIED,eval-sanitize-20-r1-030-8p8k8,phase=Pending node=kind-worker
34.6478,Pod,MODIFIED,eval-sanitize-20-r1-032-v889x,phase=Pending node=None
34.6482,Event,ADDED,eval-sanitize-20-r1-032-v889x.18d41aa61d7ad12b,"reason=FailedScheduling count=None msg=0/6 nodes are available: 1 c_wall violated: 2 conflicting context pair(s) with node memory, 5 node(s) had untolerated taint(s). no new claims to deallocate, preemption: 0/6 nodes are available: 1 No preemption victims found for incoming pod, 5 Preemption is not helpful for scheduling."
34.7424,Pod,MODIFIED,eval-sanitize-20-r1-033-sstrx,phase=Pending node=kind-worker
34.7462,Pod,MODIFIED,eval-sanitize-20-r1-034-48s2k,phase=Pending node=None
34.7465,Event,ADDED,eval-sanitize-20-r1-034-48s2k.18d41aa623b1620b,"reason=FailedScheduling count=None msg=0/6 nodes are available: 1 c_wall violated: 2 conflicting context pair(s) with node memory, 5 node(s) had untolerated taint(s). no new claims to deallocate, preemption: 0/6 nodes are available: 1 No preemption victims found for incoming pod, 5 Preemption is not helpful for scheduling."
34.7467,Event,ADDED,eval-sanitize-20-r1-033-sstrx.18d41aa623da34cb,reason=Scheduled count=None msg=Successfully assigned compute/eval-sanitize-20-r1-033-sstrx to kind-worker
34.7544,Pod,MODIFIED,eval-sanitize-20-r1-033-sstrx,phase=Pending node=kind-worker
34.7549,Event,ADDED,eval-sanitize-20-r1-019-dl74d.18d41aa624594873,"reason=FailedScheduling count=None msg=0/6 nodes are available: 1 c_wall violated: 2 conflicting context pair(s) with node memory, 5 node(s) had untolerated taint(s). no new claims to deallocate, preemption: 0/6 nodes are available: 1 No preemption victims found for incoming pod, 5 Preemption is not helpful for scheduling."
34.7579,Pod,MODIFIED,eval-sanitize-20-r1-020-xv9d4,phase=Pending node=None
34.7582,Event,ADDED,eval-sanitize-20-r1-020-xv9d4.18d41aa624819806,"reason=FailedScheduling count=None msg=0/6 nodes are available: 1 c_wall violated: 2 conflicting context pair(s) with node memory, 5 node(s) had untolerated taint(s). no new claims to deallocate, preemption: 0/6 nodes are available: 1 No preemption victims found for incoming pod, 5 Preemption is not helpful for scheduling."
34.8213,Event,ADDED,eval-sanitize-20-r1-012-m6skw.18d41aa62846d55f,"reason=Pulled count=1 msg=Container image ""busybox:musl"" already present on machine"
34.8328,Event,ADDED,eval-sanitize-20-r1-016-rhx4s.18d41aa62909f51b,"reason=Pulled count=1 msg=Container image ""busybox:musl"" already present on machine"
34.8389,Event,ADDED,eval-sanitize-20-r1-018-tml46.18d41aa6294226f8,"reason=Pulled count=1 msg=Container image ""busybox:musl"" already present on machine"
34.8419,Event,ADDED,eval-sanitize-20-r1-021-77dzv.18d41aa6298ecc45,"reason=FailedScheduling count=None msg=0/6 nodes are available: 1 c_wall violated: 2 conflicting context pair(s) with node memory, 5 node(s) had untolerated taint(s). no new claims to deallocate, preemption: 0/6 nodes are available: 1 No preemption victims found for incoming pod, 5 Preemption is not helpful for scheduling."
34.8452,Event,ADDED,eval-sanitize-20-r1-022-qr2sk.18d41aa629c0853a,"reason=FailedScheduling count=None msg=0/6 nodes are available: 1 c_wall violated: 2 conflicting context pair(s) with node memory, 5 node(s) had untolerated taint(s). no new claims to deallocate, preemption: 0/6 nodes are available: 1 No preemption victims found for incoming pod, 5 Preemption is not helpful for scheduling."
34.8467,Event,ADDED,eval-sanitize-20-r1-012-m6skw.18d41aa629d221b9,reason=Created count=1 msg=Created container: task
34.8505,Event,ADDED,eval-sanitize-20-r1-023-lhw8g.18d41aa629f759a2,"reason=FailedScheduling count=None msg=0/6 nodes are available: 1 c_wall violated: 1 conflicting context pair(s) with node memory, 5 node(s) had untolerated taint(s). no new claims to deallocate, preemption: 0/6 nodes are available: 1 No preemption victims found for incoming pod, 5 Preemption is not helpful for scheduling."
34.8521,Event,ADDED,eval-sanitize-20-r1-024-jjnk6.18d41aa62a2b7de3,"reason=FailedScheduling count=None msg=0/6 nodes are available: 1 c_wall violated: 2 conflicting context pair(s) with node memory, 5 node(s) had untolerated taint(s). no new claims to deallocate, preemption: 0/6 nodes are available: 1 No preemption victims found for incoming pod, 5 Preemption is not helpful for scheduling."
34.8577,Pod,MODIFIED,eval-sanitize-20-r1-026-cdlxh,phase=Pending node=None
34.8579,Event,ADDED,eval-sanitize-20-r1-026-cdlxh.18d41aa62a61cc1a,"reason=FailedScheduling count=None msg=0/6 nodes are available: 1 c_wall violated: 2 conflicting context pair(s) with node memory, 5 node(s) had untolerated taint(s). no new claims to deallocate, preemption: 0/6 nodes are available: 1 No preemption victims found for incoming pod, 5 Preemption is not helpful for scheduling."
34.8648,Event,ADDED,eval-sanitize-20-r1-032-v889x.18d41aa62ae9127b,"reason=FailedScheduling count=None msg=0/6 nodes are available: 1 c_wall violated: 2 conflicting context pair(s) with node memory, 5 node(s) had untolerated taint(s). no new claims to deallocate, preemption: 0/6 nodes are available: 1 No preemption victims found for incoming pod, 5 Preemption is not helpful for scheduling."
34.8695,Event,ADDED,eval-sanitize-20-r1-016-rhx4s.18d41aa62af82547,reason=Created count=1 msg=Created container: task
34.8704,Event,ADDED,eval-sanitize-20-r1-034-48s2k.18d41aa62b1431af,"reason=FailedScheduling count=None msg=0/6 nodes are available: 1 c_wall violated: 2 conflicting context pair(s) with node memory, 5 node(s) had untolerated taint(s). no new claims to deallocate, preemption: 0/6 nodes are available: 1 No preemption victims found for incoming pod, 5 Preemption is not helpful for scheduling."
34.8734,Event,ADDED,eval-sanitize-20-r1-018-tml46.18d41aa62b808ba9,reason=Created count=1 msg=Created container: task
34.9107,Event,ADDED,eval-sanitize-20-r1-012-m6skw.18d41aa62d83b95d,reason=Started count=1 msg=Started container task
34.918,Event,MODIFIED,eval-sanitize-20-r1-019-dl74d.18d41aa624594873,"reason=FailedScheduling count=None msg=0/6 nodes are available: 1 c_wall violated: 2 conflicting context pair(s) with node memory, 5 node(s) had untolerated taint(s). no new claims to deallocate, preemption: 0/6 nodes are available: 1 No preemption victims found for incoming pod, 5 Preemption is not helpful for scheduling."
34.9182,Event,ADDED,eval-sanitize-20-r1-020-xv9d4.18d41aa62dec6695,"reason=FailedScheduling count=None msg=0/6 nodes are available: 1 c_wall violated: 2 conflicting context pair(s) with node memory, 5 node(s) had untolerated taint(s). no new claims to deallocate, preemption: 0/6 nodes are available: 1 No preemption victims found for incoming pod, 5 Preemption is not helpful for scheduling."
34.9185,Event,ADDED,eval-sanitize-20-r1-026-cdlxh.18d41aa62e2466f9,"reason=FailedScheduling count=None msg=0/6 nodes are available: 1 c_wall violated: 2 conflicting context pair(s) with node memory, 5 node(s) had untolerated taint(s). no new claims to deallocate, preemption: 0/6 nodes are available: 1 No preemption victims found for incoming pod, 5 Preemption is not helpful for scheduling."
34.9248,Event,ADDED,eval-sanitize-20-r1-016-rhx4s.18d41aa62e6fec0e,reason=Started count=1 msg=Started container task
34.9298,Event,ADDED,eval-sanitize-20-r1-018-tml46.18d41aa62e71b816,reason=Started count=1 msg=Started container task
35.0236,TaskRequest,ADDED,eval-sanitize-20-r1-035,phase=None job=None
35.029,TaskRequest,MODIFIED,eval-sanitize-20-r1-035,phase=Pending job=None
35.0382,Event,ADDED,eval-sanitize-20-r1-025-rp76f.18d41aa635176be4,"reason=Pulled count=1 msg=Container image ""busybox:musl"" already present on machine"
35.0443,Job,MODIFIED,eval-sanitize-20-r1-034,
35.045,Event,ADDED,eval-sanitize-20-r1-027-t6jkc.18d41aa635458f66,"reason=Pulled count=1 msg=Container image ""busybox:musl"" already present on machine"
35.0499,Job,ADDED,eval-sanitize-20-r1-035,
35.0502,Event,ADDED,eval-sanitize-20-r1-028-26fpq.18d41aa635d60c92,"reason=Pulled count=1 msg=Container image ""busybox:musl"" already present on machine"
35.059,Pod,ADDED,eval-sanitize-20-r1-035-sj97h,phase=Pending node=None
35.0607,TaskRequest,MODIFIED,eval-sanitize-20-r1-035,phase=Scheduled job=None
35.0617,Job,MODIFIED,eval-sanitize-20-r1-035,
35.0665,Event,ADDED,eval-sanitize-20-r1-035.18d41aa636bee3cd,reason=SuccessfulCreate count=1 msg=Created pod: eval-sanitize-20-r1-035-sj97h
35.0696,Event,ADDED,eval-sanitize-20-r1-035-sj97h.18d41aa63702d587,"reason=FailedScheduling count=None msg=0/6 nodes are available: 1 c_wall violated: 2 conflicting context pair(s) with node memory, 5 node(s) had untolerated taint(s). no new claims to deallocate, preemption: 0/6 nodes are available: 1 No preemption victims found for incoming pod, 5 Preemption is not helpful for scheduling."
35.0706,Pod,MODIFIED,eval-sanitize-20-r1-035-sj97h,phase=Pending node=None
35.0722,Event,ADDED,eval-sanitize-20-r1-025-rp76f.18d41aa637154125,reason=Created count=1 msg=Created container: task
35.0723,TaskRequest,MODIFIED,eval-sanitize-20-r1-035,phase=Scheduled job=None
35.0733,Job,MODIFIED,eval-sanitize-20-r1-034,
35.0772,Event,ADDED,eval-sanitize-20-r1-031-dpf7x.18d41aa6374c5963,"reason=Pulled count=1 msg=Container image ""busybox:musl"" already present on machine"
35.0793,Event,ADDED,eval-sanitize-20-r1-035-sj97h.18d41aa637b15ea1,"reason=FailedScheduling count=None msg=0/6 nodes are available: 1 c_wall violated: 2 conflicting context pair(s) with node memory, 5 node(s) had untolerated taint(s). no new claims to deallocate, preemption: 0/6 nodes are available: 1 No preemption victims found for incoming pod, 5 Preemption is not helpful for scheduling."
35.0845,Event,ADDED,eval-sanitize-20-r1-029-cjqck.18d41aa637654f96,"reason=Pulled count=1 msg=Container image ""busybox:musl"" already present on machine"
35.0888,Event,ADDED,eval-sanitize-20-r1-030-8p8k8.18d41aa63790c885,"reason=Pulled count=1 msg=Container image ""busybox:musl"" already present on machine"
35.093,Event,ADDED,eval-sanitize-20-r1-027-t6jkc.18d41aa6383236fd,reason=Created count=1 msg=Created container: task
35.1049,Event,ADDED,eval-sanitize-20-r1-028-26fpq.18d41aa639464f4e,reason=Created count=1 msg=Created container: task
35.1275,Event,ADDED,eval-sanitize-20-r1-031-dpf7x.18d41aa63a44de83,reason=Created count=1 msg=Created container: task
35.1338,Event,ADDED,eval-sanitize-20-r1-029-cjqck.18d41aa63af07e1b,reason=Created count=1 msg=Created container: task
35.1382,Event,ADDED,eval-sanitize-20-r1-030-8p8k8.18d41aa63b10117d,reason=Created count=1 msg=Created container: task
35.1422,Event,ADDED,eval-sanitize-20-r1-025-rp76f.18d41aa63b10ea9c,reason=Started count=1 msg=Started container task
35.1494,Event,ADDED,eval-sanitize-20-r1-027-t6jkc.18d41aa63b66d16f,reason=Started count=1 msg=Started container task
35.1539,Event,ADDED,eval-sanitize-20-r1-028-26fpq.18d41aa63bb08e49,reason=Started count=1 msg=Started container task
35.162,Event,ADDED,eval-sanitize-20-r1-031-dpf7x.18d41aa63c97d750,reason=Started count=1 msg=Started container task
35.1777,Event,ADDED,eval-sanitize-20-r1-029-cjqck.18d41aa63d93d19c,reason=Started count=1 msg=Started container task
35.1831,Event,ADDED,eval-sanitize-20-r1-030-8p8k8.18d41aa63d9464f3,reason=Started count=1 msg=Started container task
35.2015,Event,ADDED,eval-sanitize-20-r1-033-sstrx.18d41aa63f030f29,"reason=Pulled count=1 msg=Container image ""busybox:musl"" already present on machine"
35.2147,Node,MODIFIED,kind-worker4,taints=1
35.2203,Event,ADDED,eval-sanitize-20-r1-033-sstrx.18d41aa640216a5a,reason=Created count=1 msg=Created container: task
35.2242,Event,MODIFIED,eval-sanitize-20-r1-021-77dzv.18d41aa6298ecc45,"reason=FailedScheduling count=None msg=0/6 nodes are available: 1 c_wall violated: 2 conflicting context pair(s) with node memory, 5 node(s) had untolerated taint(s). no new claims to deallocate, preemption: 0/6 nodes are available: 1 No preemption victims found for incoming pod, 5 Preemption is not helpful for scheduling."
35.2279,Node,MODIFIED,kind-worker4,taints=1
35.23,Event,MODIFIED,eval-sanitize-20-r1-022-qr2sk.18d41aa629c0853a,"reason=FailedScheduling count=None msg=0/6 nodes are available: 1 c_wall violated: 2 conflicting context pair(s) with node memory, 5 node(s) had untolerated taint(s). no new claims to deallocate, preemption: 0/6 nodes are available: 1 No preemption victims found for incoming pod, 5 Preemption is not helpful for scheduling."
35.2339,Event,MODIFIED,eval-sanitize-20-r1-024-jjnk6.18d41aa62a2b7de3,"reason=FailedScheduling count=None msg=0/6 nodes are available: 1 c_wall violated: 2 conflicting context pair(s) with node memory, 5 node(s) had untolerated taint(s). no new claims to deallocate, preemption: 0/6 nodes are available: 1 No preemption victims found for incoming pod, 5 Preemption is not helpful for scheduling."
35.2344,Event,MODIFIED,eval-sanitize-20-r1-023-lhw8g.18d41aa629f759a2,"reason=FailedScheduling count=None msg=0/6 nodes are available: 1 c_wall violated: 1 conflicting context pair(s) with node memory, 5 node(s) had untolerated taint(s). no new claims to deallocate, preemption: 0/6 nodes are available: 1 No preemption victims found for incoming pod, 5 Preemption is not helpful for scheduling."
35.2382,Node,MODIFIED,kind-worker4,taints=0
35.2386,Event,MODIFIED,eval-sanitize-20-r1-032-v889x.18d41aa62ae9127b,"reason=FailedScheduling count=None msg=0/6 nodes are available: 1 c_wall violated: 2 conflicting context pair(s) with node memory, 5 node(s) had untolerated taint(s). no new claims to deallocate, preemption: 0/6 nodes are available: 1 No preemption victims found for incoming pod, 5 Preemption is not helpful for scheduling."
35.2403,Event,MODIFIED,eval-sanitize-20-r1-034-48s2k.18d41aa62b1431af,"reason=FailedScheduling count=None msg=0/6 nodes are available: 1 c_wall violated: 2 conflicting context pair(s) with node memory, 5 node(s) had untolerated taint(s). no new claims to deallocate, preemption: 0/6 nodes are available: 1 No preemption victims found for incoming pod, 5 Preemption is not helpful for scheduling."
35.2459,Pod,MODIFIED,eval-sanitize-20-r1-020-xv9d4,phase=Pending node=kind-worker4
35.2488,Event,ADDED,eval-sanitize-20-r1-020-xv9d4.18d41aa641dcc573,reason=Scheduled count=None msg=Successfully assigned compute/eval-sanitize-20-r1-020-xv9d4 to kind-worker4
35.2557,Node,MODIFIED,kind-worker4,taints=0
35.2571,Pod,MODIFIED,eval-sanitize-20-r1-020-xv9d4,phase=Pending node=kind-worker4
35.2829,Event,ADDED,eval-sanitize-20-r1-033-sstrx.18d41aa643dfd9ce,reason=Started count=1 msg=Started container task
35.3153,Node,MODIFIED,kind-worker4,taints=0
35.3184,Pod,MODIFIED,eval-sanitize-20-r1-026-cdlxh,phase=Pending node=kind-worker4
35.3212,Pod,MODIFIED,eval-sanitize-20-r1-035-sj97h,phase=Pending node=None
35.3219,Event,MODIFIED,eval-sanitize-20-r1-035-sj97h.18d41aa637b15ea1,"reason=FailedScheduling count=None msg=0/6 nodes are available: 1 c_wall violated: 2 conflicting context pair(s) with node memory, 5 node(s) had untolerated taint(s). no new claims to deallocate, preemption: 0/6 nodes are available: 1 No preemption victims found for incoming pod, 5 Preemption is not helpful for scheduling."
35.3222,Event,ADDED,eval-sanitize-20-r1-026-cdlxh.18d41aa6462f9f74,reason=Scheduled count=None msg=Successfully assigned compute/eval-sanitize-20-r1-026-cdlxh to kind-worker4
35.327,Node,MODIFIED,kind-worker4,taints=0
35.3346,Pod,MODIFIED,eval-sanitize-20-r1-026-cdlxh,phase=Pending node=kind-worker4
35.3357,Pod,MODIFIED,eval-sanitize-20-r1-021-77dzv,phase=Pending node=None
35.3554,Node,MODIFIED,kind-worker4,taints=0
35.3648,Node,MODIFIED,kind-worker4,taints=0
35.4162,Pod,MODIFIED,eval-sanitize-20-r1-022-qr2sk,phase=Pending node=None
35.4261,Pod,MODIFIED,eval-sanitize-20-r1-023-lhw8g,phase=Pending node=None
35.437,Pod,MODIFIED,eval-sanitize-20-r1-024-jjnk6,phase=Pending node=None
35.5133,Pod,MODIFIED,eval-sanitize-20-r1-032-v889x,phase=Pending node=None
35.5228,Pod,MODIFIED,eval-sanitize-20-r1-034-48s2k,phase=Pending node=None
35.5321,Pod,MODIFIED,eval-sanitize-20-r1-019-dl74d,phase=Pending node=None
35.5412,Event,ADDED,eval-sanitize-20-r1-035-sj97h.18d41aa65348362d,"reason=FailedScheduling count=None msg=0/6 nodes are available: 2 c_wall violated: 2 conflicting context pair(s) with node memory, 4 node(s) had untolerated taint(s). no new claims to deallocate, preemption: 0/6 nodes are available: 2 No preemption victims found for incoming pod, 4 Preemption is not helpful for scheduling."
35.6182,Event,ADDED,eval-sanitize-20-r1-021-77dzv.18d41aa657834e4d,"reason=FailedScheduling count=None msg=0/6 nodes are available: 2 c_wall violated: 2 conflicting context pair(s) with node memory, 4 node(s) had untolerated taint(s). no new claims to deallocate, preemption: 0/6 nodes are available: 2 No preemption victims found for incoming pod, 4 Preemption is not helpful for scheduling."
35.6188,Event,ADDED,eval-sanitize-20-r1-022-qr2sk.18d41aa657e14713,"reason=FailedScheduling count=None msg=0/6 nodes are available: 1 c_wall violated: 1 conflicting context pair(s) with node memory, 1 c_wall violated: 2 conflicting context pair(s) with node memory, 4 node(s) had untolerated taint(s). no new claims to deallocate, preemption: 0/6 nodes are available: 2 No preemption victims found for incoming pod, 4 Preemption is not helpful for scheduling."
35.6246,Event,ADDED,eval-sanitize-20-r1-023-lhw8g.18d41aa65835ca5c,"reason=FailedScheduling count=None msg=0/6 nodes are available: 2 c_wall violated: 1 conflicting context pair(s) with node memory, 4 node(s) had untolerated taint(s). no new claims to deallocate, preemption: 0/6 nodes are available: 2 No preemption victims found for incoming pod, 4 Preemption is not helpful for scheduling."
35.6495,Pod,MODIFIED,eval-sanitize-20-r1-033-sstrx,phase=Running node=kind-worker
35.6556,Pod,MODIFIED,eval-sanitize-20-r1-029-cjqck,phase=Running node=kind-worker
35.6625,Pod,MODIFIED,eval-sanitize-20-r1-018-tml46,phase=Running node=kind-worker
35.6693,Pod,MODIFIED,eval-sanitize-20-r1-012-m6skw,phase=Running node=kind-worker
35.6772,Pod,MODIFIED,eval-sanitize-20-r1-031-dpf7x,phase=Running node=kind-worker
35.6852,Pod,MODIFIED,eval-sanitize-20-r1-030-8p8k8,phase=Running node=kind-worker
35.6948,Pod,MODIFIED,eval-sanitize-20-r1-028-26fpq,phase=Running node=kind-worker
35.6951,Event,ADDED,eval-sanitize-20-r1-020-xv9d4.18d41aa65c42e140,"reason=Pulled count=1 msg=Container image ""busybox:musl"" already present on machine"
35.7038,Pod,MODIFIED,eval-sanitize-20-r1-025-rp76f,phase=Running node=kind-worker
35.7131,Pod,MODIFIED,eval-sanitize-20-r1-016-rhx4s,phase=Running node=kind-worker
35.7147,Event,ADDED,eval-sanitize-20-r1-024-jjnk6.18d41aa65d87bcab,"reason=FailedScheduling count=None msg=0/6 nodes are available: 1 c_wall violated: 1 conflicting context pair(s) with node memory, 1 c_wall violated: 2 conflicting context pair(s) with node memory, 4 node(s) had untolerated taint(s). no new claims to deallocate, preemption: 0/6 nodes are available: 2 No preemption victims found for incoming pod, 4 Preemption is not helpful for scheduling."
35.7154,Event,ADDED,eval-sanitize-20-r1-020-xv9d4.18d41aa65d91403f,reason=Created count=1 msg=Created container: task
35.7202,Pod,MODIFIED,eval-sanitize-20-r1-027-t6jkc,phase=Running node=kind-worker
35.7223,Event,ADDED,eval-sanitize-20-r1-032-v889x.18d41aa65df82f28,"reason=FailedScheduling count=None msg=0/6 nodes are available: 1 c_wall violated: 1 conflicting context pair(s) with node memory, 1 c_wall violated: 2 conflicting context pair(s) with node memory, 4 node(s) had untolerated taint(s). no new claims to deallocate, preemption: 0/6 nodes are available: 2 No preemption victims found for incoming pod, 4 Preemption is not helpful for scheduling."
35.7366,Event,ADDED,eval-sanitize-20-r1-026-cdlxh.18d41aa65ee85f6a,"reason=Pulled count=1 msg=Container image ""busybox:musl"" already present on machine"
35.7497,Event,ADDED,eval-sanitize-20-r1-020-xv9d4.18d41aa65fb6a7ca,reason=Started count=1 msg=Started container task
35.756,Event,ADDED,eval-sanitize-20-r1-026-cdlxh.18d41aa6601d2547,reason=Created count=1 msg=Created container: task
35.7888,Node,MODIFIED,kind-worker3,taints=1
35.7936,Event,ADDED,eval-sanitize-20-r1-026-cdlxh.18d41aa662431740,reason=Started count=1 msg=Started container task
35.8128,Event,ADDED,eval-sanitize-20-r1-034-48s2k.18d41aa6635bba0d,"reason=FailedScheduling count=None msg=0/6 nodes are available: 2 c_wall violated: 2 conflicting context pair(s) with node memory, 4 node(s) had untolerated taint(s). no new claims to deallocate, preemption: 0/6 nodes are available: 2 No preemption victims found for incoming pod, 4 Preemption is not helpful for scheduling."
35.8172,Event,ADDED,eval-sanitize-20-r1-019-dl74d.18d41aa663bcd277,"reason=FailedScheduling count=None msg=0/6 nodes are available: 1 c_wall violated: 1 conflicting context pair(s) with node memory, 1 c_wall violated: 2 conflicting context pair(s) with node memory, 4 node(s) had untolerated taint(s). no new claims to deallocate, preemption: 0/6 nodes are available: 2 No preemption victims found for incoming pod, 4 Preemption is not helpful for scheduling."
35.8242,Event,MODIFIED,eval-sanitize-20-r1-035-sj97h.18d41aa65348362d,"reason=FailedScheduling count=None msg=0/6 nodes are available: 2 c_wall violated: 2 conflicting context pair(s) with node memory, 4 node(s) had untolerated taint(s). no new claims to deallocate, preemption: 0/6 nodes are available: 2 No preemption victims found for incoming pod, 4 Preemption is not helpful for scheduling."
35.855,Node,MODIFIED,kind-worker3,taints=0
35.8636,Node,MODIFIED,kind-worker3,taints=0
35.8743,Node,MODIFIED,kind-worker3,taints=0
35.9133,Event,MODIFIED,eval-sanitize-20-r1-021-77dzv.18d41aa657834e4d,"reason=FailedScheduling count=None msg=0/6 nodes are available: 2 c_wall violated: 2 conflicting context pair(s) with node memory, 4 node(s) had untolerated taint(s). no new claims to deallocate, preemption: 0/6 nodes are available: 2 No preemption victims found for incoming pod, 4 Preemption is not helpful for scheduling."
35.9199,Pod,MODIFIED,eval-sanitize-20-r1-022-qr2sk,phase=Pending node=kind-worker3
35.9238,Event,ADDED,eval-sanitize-20-r1-022-qr2sk.18d41aa66a04a3a5,reason=Scheduled count=None msg=Successfully assigned compute/eval-sanitize-20-r1-022-qr2sk to kind-worker3
35.9294,Node,MODIFIED,kind-worker3,taints=0
35.9314,Pod,MODIFIED,eval-sanitize-20-r1-022-qr2sk,phase=Pending node=kind-worker3
35.9554,Node,MODIFIED,kind-worker3,taints=0
36.0082,TaskRequest,ADDED,eval-sanitize-20-r1-036,phase=None job=None
36.0125,Pod,MODIFIED,eval-sanitize-20-r1-023-lhw8g,phase=Pending node=kind-worker3
36.0134,TaskRequest,MODIFIED,eval-sanitize-20-r1-036,phase=Pending job=None
36.0162,Event,ADDED,eval-sanitize-20-r1-023-lhw8g.18d41aa66f8fe15e,reason=Scheduled count=None msg=Successfully assigned compute/eval-sanitize-20-r1-023-lhw8g to kind-worker3
36.0233,Pod,MODIFIED,eval-sanitize-20-r1-023-lhw8g,phase=Pending node=kind-worker3
36.0253,Pod,MODIFIED,eval-sanitize-20-r1-024-jjnk6,phase=Pending node=kind-worker3
36.0269,Node,MODIFIED,kind-worker3,taints=0
36.0286,Event,ADDED,eval-sanitize-20-r1-024-jjnk6.18d41aa670539629,reason=Scheduled count=None msg=Successfully assigned compute/eval-sanitize-20-r1-024-jjnk6 to kind-worker3
36.0315,Job,ADDED,eval-sanitize-20-r1-036,
36.0362,Node,MODIFIED,kind-worker3,taints=0
36.0381,Pod,MODIFIED,eval-sanitize-20-r1-024-jjnk6,phase=Pending node=kind-worker3
36.0388,TaskRequest,MODIFIED,eval-sanitize-20-r1-036,phase=Scheduled job=None
36.0397,Pod,ADDED,eval-sanitize-20-r1-036-qpnd7,phase=Pending node=None
36.0412,Job,MODIFIED,eval-sanitize-20-r1-036,
36.0435,Event,ADDED,eval-sanitize-20-r1-036.18d41aa67130c0da,reason=SuccessfulCreate count=1 msg=Created pod: eval-sanitize-20-r1-036-qpnd7
36.045,TaskRequest,MODIFIED,eval-sanitize-20-r1-036,phase=Scheduled job=None
36.0632,Job,MODIFIED,eval-sanitize-20-r1-035,
36.0718,Job,MODIFIED,eval-sanitize-20-r1-035,
36.075,Pod,MODIFIED,eval-sanitize-20-r1-026-cdlxh,phase=Running node=kind-worker4
36.0817,Pod,MODIFIED,eval-sanitize-20-r1-020-xv9d4,phase=Running node=kind-worker4
36.1171,Pod,MODIFIED,eval-sanitize-20-r1-032-v889x,phase=Pending node=kind-worker3
36.122,Event,ADDED,eval-sanitize-20-r1-032-v889x.18d41aa675c78b1e,reason=Scheduled count=None msg=Successfully assigned compute/eval-sanitize-20-r1-032-v889x to kind-worker3
36.1267,Pod,MODIFIED,eval-sanitize-20-r1-036-qpnd7,phase=Pending node=None
36.128,Event,ADDED,eval-sanitize-20-r1-036-qpnd7.18d41aa67619b9c2,"reason=FailedScheduling count=None msg=0/6 nodes are available: 1 c_wall violated: 1 conflicting context pair(s) with node memory, 2 c_wall violated: 2 conflicting context pair(s) with node memory, 3 node(s) had untolerated taint(s). no new claims to deallocate, preemption: 0/6 nodes are available: 3 No preemption victims found for incoming pod, 3 Preemption is not helpful for scheduling."
36.1293,Pod,MODIFIED,eval-sanitize-20-r1-032-v889x,phase=Pending node=kind-worker3
36.2224,Pod,MODIFIED,eval-sanitize-20-r1-034-48s2k,phase=Pending node=None
36.2228,Event,MODIFIED,eval-sanitize-20-r1-034-48s2k.18d41aa6635bba0d,"reason=FailedScheduling count=None msg=0/6 nodes are available: 2 c_wall violated: 2 conflicting context pair(s) with node memory, 4 node(s) had untolerated taint(s). no new claims to deallocate, preemption: 0/6 nodes are available: 2 No preemption victims found for incoming pod, 4 Preemption is not helpful for scheduling."
36.3172,Pod,MODIFIED,eval-sanitize-20-r1-019-dl74d,phase=Pending node=kind-worker3
36.3287,Event,ADDED,eval-sanitize-20-r1-019-dl74d.18d41aa681b7baee,reason=Scheduled count=None msg=Successfully assigned compute/eval-sanitize-20-r1-019-dl74d to kind-worker3
36.3341,Pod,MODIFIED,eval-sanitize-20-r1-035-sj97h,phase=Pending node=kind-worker3
36.3374,Pod,MODIFIED,eval-sanitize-20-r1-019-dl74d,phase=Pending node=kind-worker3
36.3378,Event,ADDED,eval-sanitize-20-r1-035-sj97h.18d41aa682b7cf71,reason=Scheduled count=None msg=Successfully assigned compute/eval-sanitize-20-r1-035-sj97h to kind-worker3
36.3466,Pod,MODIFIED,eval-sanitize-20-r1-035-sj97h,phase=Pending node=kind-worker3
36.3491,Node,MODIFIED,kind-worker3,taints=0
36.3605,Node,MODIFIED,kind-worker3,taints=0
36.3675,Event,ADDED,eval-sanitize-20-r1-022-qr2sk.18d41aa68436395f,"reason=Pulled count=1 msg=Container image ""busybox:musl"" already present on machine"
36.3981,Event,ADDED,eval-sanitize-20-r1-022-qr2sk.18d41aa68650a0d5,reason=Created count=1 msg=Created container: task
36.415,Pod,MODIFIED,eval-sanitize-20-r1-021-77dzv,phase=Pending node=None
36.429,Event,ADDED,eval-sanitize-20-r1-036-qpnd7.18d41aa6882ce074,"reason=FailedScheduling count=None msg=0/6 nodes are available: 1 c_wall violated: 1 conflicting context pair(s) with node memory, 2 c_wall violated: 2 conflicting context pair(s) with node memory, 3 node(s) had untolerated taint(s). no new claims to deallocate, preemption: 0/6 nodes are available: 3 No preemption victims found for incoming pod, 3 Preemption is not helpful for scheduling."
36.4715,Event,ADDED,eval-sanitize-20-r1-023-lhw8g.18d41aa68a6f10ef,"reason=Pulled count=1 msg=Container image ""busybox:musl"" already present on machine"
36.478,Event,ADDED,eval-sanitize-20-r1-022-qr2sk.18d41aa68af1ed7e,reason=Started count=1 msg=Started container task
36.4819,Event,ADDED,eval-sanitize-20-r1-024-jjnk6.18d41aa68af4ee32,"reason=Pulled count=1 msg=Container image ""busybox:musl"" already present on machine"
36.4912,Event,ADDED,eval-sanitize-20-r1-023-lhw8g.18d41aa68bdd9e75,reason=Created count=1 msg=Created container: task
36.5005,Event,ADDED,eval-sanitize-20-r1-024-jjnk6.18d41aa68c70693c,reason=Created count=1 msg=Created container: task
36.5152,Event,ADDED,eval-sanitize-20-r1-032-v889x.18d41aa68d2f5c13,"reason=Pulled count=1 msg=Container image ""busybox:musl"" already present on machine"
36.5241,Event,ADDED,eval-sanitize-20-r1-034-48s2k.18d41aa68dbd71c5,"reason=FailedScheduling count=None msg=0/6 nodes are available: 1 c_wall violated: 1 conflicting context pair(s) with node memory, 2 c_wall violated: 2 conflicting context pair(s) with node memory, 3 node(s) had untolerated taint(s). no new claims to deallocate, preemption: 0/6 nodes are available: 3 No preemption victims found for incoming pod, 3 Preemption is not helpful for scheduling."
36.5284,Event,ADDED,eval-sanitize-20-r1-023-lhw8g.18d41aa68e15fa56,reason=Started count=1 msg=Started container task
36.5336,Event,ADDED,eval-sanitize-20-r1-032-v889x.18d41aa68e73ffee,reason=Created count=1 msg=Created container: task
36.5394,Event,ADDED,eval-sanitize-20-r1-024-jjnk6.18d41aa68e961804,reason=Started count=1 msg=Started container task
36.5744,Event,ADDED,eval-sanitize-20-r1-032-v889x.18d41aa690c09c57,reason=Started count=1 msg=Started container task
36.6175,Pod,MODIFIED,eval-sanitize-20-r1-032-v889x,phase=Running node=kind-worker3
36.6178,Event,ADDED,eval-sanitize-20-r1-021-77dzv.18d41aa693430262,"reason=FailedScheduling count=None msg=0/6 nodes are available: 1 c_wall violated: 1 conflicting context pair(s) with node memory, 2 c_wall violated: 2 conflicting context pair(s) with node memory, 3 node(s) had untolerated taint(s). no new claims to deallocate, preemption: 0/6 nodes are available: 3 No preemption victims found for incoming pod, 3 Preemption is not helpful for scheduling."
36.6235,Pod,MODIFIED,eval-sanitize-20-r1-023-lhw8g,phase=Running node=kind-worker3
36.63,Pod,MODIFIED,eval-sanitize-20-r1-022-qr2sk,phase=Running node=kind-worker3
36.632,Event,MODIFIED,eval-sanitize-20-r1-036-qpnd7.18d41aa6882ce074,"reason=FailedScheduling count=None msg=0/6 nodes are available: 1 c_wall violated: 1 conflicting context pair(s) with node memory, 2 c_wall violated: 2 conflicting context pair(s) with node memory, 3 node(s) had untolerated taint(s). no new claims to deallocate, preemption: 0/6 nodes are available: 3 No preemption victims found for incoming pod, 3 Preemption is not helpful for scheduling."
36.6363,Pod,MODIFIED,eval-sanitize-20-r1-024-jjnk6,phase=Running node=kind-worker3
36.6546,Job,MODIFIED,eval-sanitize-20-r1-033,
36.6611,Job,MODIFIED,eval-sanitize-20-r1-029,
36.6648,Job,MODIFIED,eval-sanitize-20-r1-033,
36.6679,Job,MODIFIED,eval-sanitize-20-r1-018,
36.6701,Job,MODIFIED,eval-sanitize-20-r1-029,
36.6738,Job,MODIFIED,eval-sanitize-20-r1-012,
36.6793,Job,MODIFIED,eval-sanitize-20-r1-018,
36.6816,Job,MODIFIED,eval-sanitize-20-r1-031,
36.6843,Job,MODIFIED,eval-sanitize-20-r1-012,
36.6916,Job,MODIFIED,eval-sanitize-20-r1-030,
36.6937,Job,MODIFIED,eval-sanitize-20-r1-031,
36.6988,Job,MODIFIED,eval-sanitize-20-r1-028,
36.7006,Job,MODIFIED,eval-sanitize-20-r1-030,
36.7069,Job,MODIFIED,eval-sanitize-20-r1-028,
36.7087,Job,MODIFIED,eval-sanitize-20-r1-025,
36.7176,Job,MODIFIED,eval-sanitize-20-r1-016,
36.7197,Job,MODIFIED,eval-sanitize-20-r1-025,
36.7206,Event,MODIFIED,eval-sanitize-20-r1-034-48s2k.18d41aa68dbd71c5,"reason=FailedScheduling count=None msg=0/6 nodes are available: 1 c_wall violated: 1 conflicting context pair(s) with node memory, 2 c_wall violated: 2 conflicting context pair(s) with node memory, 3 node(s) had untolerated taint(s). no new claims to deallocate, preemption: 0/6 nodes are available: 3 No preemption victims found for incoming pod, 3 Preemption is not helpful for scheduling."
36.7239,Job,MODIFIED,eval-sanitize-20-r1-027,
36.757,Event,ADDED,eval-sanitize-20-r1-019-dl74d.18d41aa69bafb0d2,"reason=Pulled count=1 msg=Container image ""busybox:musl"" already present on machine"
36.7664,Event,ADDED,eval-sanitize-20-r1-035-sj97h.18d41aa69c1f62d6,"reason=Pulled count=1 msg=Container image ""busybox:musl"" already present on machine"
36.7699,Job,MODIFIED,eval-sanitize-20-r1-016,
36.7706,Job,MODIFIED,eval-sanitize-20-r1-027,
36.784,Event,ADDED,eval-sanitize-20-r1-019-dl74d.18d41aa69d37960b,reason=Created count=1 msg=Created container: task
36.7907,Event,ADDED,eval-sanitize-20-r1-035-sj97h.18d41aa69db92ab8,reason=Created count=1 msg=Created container: task
36.8195,Event,MODIFIED,eval-sanitize-20-r1-021-77dzv.18d41aa693430262,"reason=FailedScheduling count=None msg=0/6 nodes are available: 1 c_wall violated: 1 conflicting context pair(s) with node memory, 2 c_wall violated: 2 conflicting context pair(s) with node memory, 3 node(s) had untolerated taint(s). no new claims to deallocate, preemption: 0/6 nodes are available: 3 No preemption victims found for incoming pod, 3 Preemption is not helpful for scheduling."
36.8668,Event,ADDED,eval-sanitize-20-r1-035-sj97h.18d41aa6a23e7c25,reason=Started count=1 msg=Started container task
36.872,Event,ADDED,eval-sanitize-20-r1-019-dl74d.18d41aa6a23e7c2f,reason=Started count=1 msg=Started container task
36.9319,Job,MODIFIED,eval-sanitize-20-r1-022,
36.9411,Job,MODIFIED,eval-sanitize-20-r1-022,
37.0157,TaskRequest,ADDED,eval-sanitize-20-r1-037,phase=None job=None
37.0184,Job,MODIFIED,eval-sanitize-20-r1-023,
37.0203,TaskRequest,MODIFIED,eval-sanitize-20-r1-037,phase=Pending job=None
37.0321,Job,MODIFIED,eval-sanitize-20-r1-024,
37.0357,Job,ADDED,eval-sanitize-20-r1-037,
37.0395,TaskRequest,MODIFIED,eval-sanitize-20-r1-037,phase=Scheduled job=None
37.0425,Pod,ADDED,eval-sanitize-20-r1-037-lgp4f,phase=Pending node=None
37.0455,Job,MODIFIED,eval-sanitize-20-r1-037,
37.0464,Job,MODIFIED,eval-sanitize-20-r1-036,
37.0495,Event,ADDED,eval-sanitize-20-r1-037.18d41aa6acf9f7a2,reason=SuccessfulCreate count=1 msg=Created pod: eval-sanitize-20-r1-037-lgp4f
37.0496,TaskRequest,MODIFIED,eval-sanitize-20-r1-037,phase=Scheduled job=None
37.0523,Job,MODIFIED,eval-sanitize-20-r1-023,
37.0531,Job,MODIFIED,eval-sanitize-20-r1-024,
37.0549,Job,MODIFIED,eval-sanitize-20-r1-036,
37.059,Pod,MODIFIED,eval-sanitize-20-r1-037-lgp4f,phase=Pending node=kind-worker3
37.0624,Event,ADDED,eval-sanitize-20-r1-037-lgp4f.18d41aa6adf23cf9,reason=Scheduled count=None msg=Successfully assigned compute/eval-sanitize-20-r1-037-lgp4f to kind-worker3
37.0686,Pod,MODIFIED,eval-sanitize-20-r1-037-lgp4f,phase=Pending node=kind-worker3
37.0787,Job,MODIFIED,eval-sanitize-20-r1-026,
37.0858,Job,MODIFIED,eval-sanitize-20-r1-020,
37.0965,Job,MODIFIED,eval-sanitize-20-r1-026,
37.0982,Job,MODIFIED,eval-sanitize-20-r1-020,
37.1288,Job,MODIFIED,eval-sanitize-20-r1-032,
37.1373,Job,MODIFIED,eval-sanitize-20-r1-032,
37.1521,Node,MODIFIED,kind-worker2,taints=1
37.1635,Node,MODIFIED,kind-worker2,taints=1
37.1712,Node,MODIFIED,kind-worker2,taints=0
37.1821,Node,MODIFIED,kind-worker2,taints=0
37.238,Pod,MODIFIED,eval-sanitize-20-r1-034-48s2k,phase=Pending node=kind-worker2
37.2413,Event,ADDED,eval-sanitize-20-r1-034-48s2k.18d41aa6b89ba573,reason=Scheduled count=None msg=Successfully assigned compute/eval-sanitize-20-r1-034-48s2k to kind-worker2
37.2471,Pod,MODIFIED,eval-sanitize-20-r1-034-48s2k,phase=Pending node=kind-worker2
37.2503,Node,MODIFIED,kind-worker2,taints=0
37.2598,Node,MODIFIED,kind-worker2,taints=0
37.321,Pod,MODIFIED,eval-sanitize-20-r1-021-77dzv,phase=Pending node=kind-worker2
37.3242,Event,ADDED,eval-sanitize-20-r1-021-77dzv.18d41aa6bd86e679,reason=Scheduled count=None msg=Successfully assigned compute/eval-sanitize-20-r1-021-77dzv to kind-worker2
37.3306,Pod,MODIFIED,eval-sanitize-20-r1-021-77dzv,phase=Pending node=kind-worker2
37.4132,Node,MODIFIED,kind-worker5,taints=1
37.4191,Pod,MODIFIED,eval-sanitize-20-r1-036-qpnd7,phase=Pending node=kind-worker2
37.4234,Event,ADDED,eval-sanitize-20-r1-036-qpnd7.18d41aa6c3653b97,reason=Scheduled count=None msg=Successfully assigned compute/eval-sanitize-20-r1-036-qpnd7 to kind-worker2
37.4287,Node,MODIFIED,kind-worker5,taints=1
37.4342,Pod,MODIFIED,eval-sanitize-20-r1-036-qpnd7,phase=Pending node=kind-worker2
37.4389,Node,MODIFIED,kind-worker5,taints=0
37.4508,Node,MODIFIED,kind-worker5,taints=0
37.4947,Event,ADDED,eval-sanitize-20-r1-037-lgp4f.18d41aa6c7a1b64a,"reason=Pulled count=1 msg=Container image ""busybox:musl"" already present on machine"
37.5117,Event,ADDED,eval-sanitize-20-r1-037-lgp4f.18d41aa6c8b57072,reason=Created count=1 msg=Created container: task
37.5807,Event,ADDED,eval-sanitize-20-r1-037-lgp4f.18d41aa6ccd0b718,reason=Started count=1 msg=Started container task
37.6248,Pod,MODIFIED,eval-sanitize-20-r1-019-dl74d,phase=Running node=kind-worker3
37.6312,Pod,MODIFIED,eval-sanitize-20-r1-035-sj97h,phase=Running node=kind-worker3
37.6373,Pod,MODIFIED,eval-sanitize-20-r1-037-lgp4f,phase=Running node=kind-worker3
37.6789,Event,ADDED,eval-sanitize-20-r1-034-48s2k.18d41aa6d295260c,"reason=Pulled count=1 msg=Container image ""busybox:musl"" already present on machine"
37.7025,Event,ADDED,eval-sanitize-20-r1-034-48s2k.18d41aa6d3ba7db6,reason=Created count=1 msg=Created container: task
37.7214,Event,ADDED,eval-sanitize-20-r1-021-77dzv.18d41aa6d52ffaf2,"reason=Pulled count=1 msg=Container image ""busybox:musl"" already present on machine"
37.7338,Event,ADDED,eval-sanitize-20-r1-034-48s2k.18d41aa6d5f16680,reason=Started count=1 msg=Started container task
37.7412,Event,ADDED,eval-sanitize-20-r1-021-77dzv.18d41aa6d66fcf6d,reason=Created count=1 msg=Created container: task
37.8079,Event,ADDED,eval-sanitize-20-r1-021-77dzv.18d41aa6da526eb0,reason=Started count=1 msg=Started container task
37.9085,Event,ADDED,eval-sanitize-20-r1-036-qpnd7.18d41aa6dff5bc37,"reason=Pulled count=1 msg=Container image ""busybox:musl"" already present on machine"
37.9274,Event,ADDED,eval-sanitize-20-r1-036-qpnd7.18d41aa6e16072f4,reason=Created count=1 msg=Created container: task
38.0129,Event,ADDED,eval-sanitize-20-r1-036-qpnd7.18d41aa6e604a09e,reason=Started count=1 msg=Started container task
38.0135,TaskRequest,ADDED,eval-sanitize-20-r1-038,phase=None job=None
38.0182,TaskRequest,MODIFIED,eval-sanitize-20-r1-038,phase=Pending job=None
38.0325,Job,ADDED,eval-sanitize-20-r1-038,
38.0385,Pod,ADDED,eval-sanitize-20-r1-038-9lwb4,phase=Pending node=None
38.04,TaskRequest,MODIFIED,eval-sanitize-20-r1-038,phase=Scheduled job=None
38.0425,Job,MODIFIED,eval-sanitize-20-r1-038,
38.044,Event,ADDED,eval-sanitize-20-r1-038.18d41aa6e844f047,reason=SuccessfulCreate count=1 msg=Created pod: eval-sanitize-20-r1-038-9lwb4
38.0468,Job,MODIFIED,eval-sanitize-20-r1-037,
38.0479,TaskRequest,MODIFIED,eval-sanitize-20-r1-038,phase=Scheduled job=None
38.0559,Job,MODIFIED,eval-sanitize-20-r1-037,
38.1462,Pod,MODIFIED,eval-sanitize-20-r1-038-9lwb4,phase=Pending node=kind-worker5
38.1495,Event,ADDED,eval-sanitize-20-r1-038-9lwb4.18d41aa6eea9a1c5,reason=Scheduled count=None msg=Successfully assigned compute/eval-sanitize-20-r1-038-9lwb4 to kind-worker5
38.1551,Pod,MODIFIED,eval-sanitize-20-r1-038-9lwb4,phase=Pending node=kind-worker5
38.1573,Node,MODIFIED,kind-worker5,taints=0
38.1672,Node,MODIFIED,kind-worker5,taints=0
38.1723,Pod,MODIFIED,eval-sanitize-20-r1-036-qpnd7,phase=Running node=kind-worker2
38.1784,Pod,MODIFIED,eval-sanitize-20-r1-034-48s2k,phase=Running node=kind-worker2
38.1848,Pod,MODIFIED,eval-sanitize-20-r1-021-77dzv,phase=Running node=kind-worker2
38.2509,Job,MODIFIED,eval-sanitize-20-r1-034,
38.2601,Job,MODIFIED,eval-sanitize-20-r1-034,
38.5754,Event,ADDED,eval-sanitize-20-r1-038-9lwb4.18d41aa70807ff4a,"reason=Pulled count=1 msg=Container image ""busybox:musl"" already present on machine"
38.5954,Event,ADDED,eval-sanitize-20-r1-038-9lwb4.18d41aa7090cacd2,reason=Created count=1 msg=Created container: task
38.6435,Job,MODIFIED,eval-sanitize-20-r1-019,
38.6454,Job,MODIFIED,eval-sanitize-20-r1-035,
38.6528,Job,MODIFIED,eval-sanitize-20-r1-019,
38.655,Job,MODIFIED,eval-sanitize-20-r1-035,
38.6676,Event,ADDED,eval-sanitize-20-r1-038-9lwb4.18d41aa70d8d5e55,reason=Started count=1 msg=Started container task
39.0118,TaskRequest,ADDED,eval-sanitize-20-r1-039,phase=None job=None
39.0157,TaskRequest,MODIFIED,eval-sanitize-20-r1-039,phase=Pending job=None
39.0304,Job,ADDED,eval-sanitize-20-r1-039,
39.0371,Pod,ADDED,eval-sanitize-20-r1-039-m6b7m,phase=Pending node=None
39.0396,Job,MODIFIED,eval-sanitize-20-r1-039,
39.0397,TaskRequest,MODIFIED,eval-sanitize-20-r1-039,phase=Scheduled job=None
39.0433,Event,ADDED,eval-sanitize-20-r1-039.18d41aa723ca2bb4,reason=SuccessfulCreate count=1 msg=Created pod: eval-sanitize-20-r1-039-m6b7m
39.0443,Job,MODIFIED,eval-sanitize-20-r1-038,
39.049,TaskRequest,MODIFIED,eval-sanitize-20-r1-039,phase=Scheduled job=None
39.0528,Job,MODIFIED,eval-sanitize-20-r1-038,
39.113,Pod,MODIFIED,eval-sanitize-20-r1-039-m6b7m,phase=Pending node=kind-worker4
39.1175,Event,ADDED,eval-sanitize-20-r1-039-m6b7m.18d41aa72848ea50,reason=Scheduled count=None msg=Successfully assigned compute/eval-sanitize-20-r1-039-m6b7m to kind-worker4
39.1233,Pod,MODIFIED,eval-sanitize-20-r1-039-m6b7m,phase=Pending node=kind-worker4
39.1792,Job,MODIFIED,eval-sanitize-20-r1-036,
39.1887,Job,MODIFIED,eval-sanitize-20-r1-036,
39.1907,Job,MODIFIED,eval-sanitize-20-r1-021,
39.199,Job,MODIFIED,eval-sanitize-20-r1-021,
39.2638,Pod,MODIFIED,eval-sanitize-20-r1-038-9lwb4,phase=Running node=kind-worker5
39.5452,Event,ADDED,eval-sanitize-20-r1-039-m6b7m.18d41aa741bea1c6,"reason=Pulled count=1 msg=Container image ""busybox:musl"" already present on machine"
39.5629,Event,ADDED,eval-sanitize-20-r1-039-m6b7m.18d41aa742e70c0c,reason=Created count=1 msg=Created container: task
39.6454,Event,ADDED,eval-sanitize-20-r1-039-m6b7m.18d41aa747cf5e33,reason=Started count=1 msg=Started container task
40.0132,TaskRequest,ADDED,eval-sanitize-20-r1-040,phase=None job=None
40.0187,TaskRequest,MODIFIED,eval-sanitize-20-r1-040,phase=Pending job=None
40.0333,Job,ADDED,eval-sanitize-20-r1-040,
40.0405,Pod,ADDED,eval-sanitize-20-r1-040-vrmnl,phase=Pending node=None
40.0406,TaskRequest,MODIFIED,eval-sanitize-20-r1-040,phase=Scheduled job=None
40.0433,Job,MODIFIED,eval-sanitize-20-r1-039,
40.0445,Job,MODIFIED,eval-sanitize-20-r1-040,
40.0466,Event,ADDED,eval-sanitize-20-r1-040.18d41aa75f8b0c33,reason=SuccessfulCreate count=1 msg=Created pod: eval-sanitize-20-r1-040-vrmnl
40.05,TaskRequest,MODIFIED,eval-sanitize-20-r1-040,phase=Scheduled job=None
40.0511,Job,MODIFIED,eval-sanitize-20-r1-038,
40.0548,Job,MODIFIED,eval-sanitize-20-r1-039,
40.0607,Job,MODIFIED,eval-sanitize-20-r1-038,
40.0905,Pod,MODIFIED,eval-sanitize-20-r1-039-m6b7m,phase=Running node=kind-worker4
40.1145,Pod,MODIFIED,eval-sanitize-20-r1-040-vrmnl,phase=Pending node=kind-worker5
40.1191,Event,ADDED,eval-sanitize-20-r1-040-vrmnl.18d41aa764010186,reason=Scheduled count=None msg=Successfully assigned compute/eval-sanitize-20-r1-040-vrmnl to kind-worker5
40.1249,Pod,MODIFIED,eval-sanitize-20-r1-040-vrmnl,phase=Pending node=kind-worker5
40.5651,Event,ADDED,eval-sanitize-20-r1-040-vrmnl.18d41aa77e97ccba,"reason=Pulled count=1 msg=Container image ""busybox:musl"" already present on machine"
40.5834,Event,ADDED,eval-sanitize-20-r1-040-vrmnl.18d41aa77fba022e,reason=Created count=1 msg=Created container: task
40.6638,Event,ADDED,eval-sanitize-20-r1-040-vrmnl.18d41aa7846ff748,reason=Started count=1 msg=Started container task
41.0127,TaskRequest,ADDED,eval-sanitize-20-r1-041,phase=None job=None
41.0164,TaskRequest,MODIFIED,eval-sanitize-20-r1-041,phase=Pending job=None
41.0319,Job,ADDED,eval-sanitize-20-r1-041,
41.039,Pod,ADDED,eval-sanitize-20-r1-041-sh74p,phase=Pending node=None
41.0391,TaskRequest,MODIFIED,eval-sanitize-20-r1-041,phase=Scheduled job=None
41.0417,Job,MODIFIED,eval-sanitize-20-r1-041,
41.0462,Event,ADDED,eval-sanitize-20-r1-041.18d41aa79b17ac3b,reason=SuccessfulCreate count=1 msg=Created pod: eval-sanitize-20-r1-041-sh74p
41.0471,Job,MODIFIED,eval-sanitize-20-r1-040,
41.0481,TaskRequest,MODIFIED,eval-sanitize-20-r1-041,phase=Scheduled job=None
41.0491,Job,MODIFIED,eval-sanitize-20-r1-039,
41.0564,Job,MODIFIED,eval-sanitize-20-r1-040,
41.0584,Job,MODIFIED,eval-sanitize-20-r1-039,
41.1117,Pod,MODIFIED,eval-sanitize-20-r1-041-sh74p,phase=Pending node=kind-worker4
41.1171,Event,ADDED,eval-sanitize-20-r1-041-sh74p.18d41aa79f6a9328,reason=Scheduled count=None msg=Successfully assigned compute/eval-sanitize-20-r1-041-sh74p to kind-worker4
41.1212,Node,MODIFIED,kind-worker4,taints=0
41.1234,Pod,MODIFIED,eval-sanitize-20-r1-041-sh74p,phase=Pending node=kind-worker4
41.1315,Node,MODIFIED,kind-worker4,taints=0
41.2662,Pod,MODIFIED,eval-sanitize-20-r1-040-vrmnl,phase=Running node=kind-worker5
41.5761,Event,ADDED,eval-sanitize-20-r1-041-sh74p.18d41aa7bad0fe39,"reason=Pulled count=1 msg=Container image ""busybox:musl"" already present on machine"
41.5942,Event,ADDED,eval-sanitize-20-r1-041-sh74p.18d41aa7bbfb6641,reason=Created count=1 msg=Created container: task
41.6665,Event,ADDED,eval-sanitize-20-r1-041-sh74p.18d41aa7c045de9f,reason=Started count=1 msg=Started container task
42.0177,TaskRequest,ADDED,eval-sanitize-20-r1-042,phase=None job=None
42.0217,TaskRequest,MODIFIED,eval-sanitize-20-r1-042,phase=Pending job=None
42.0398,Job,ADDED,eval-sanitize-20-r1-042,
42.0437,Job,MODIFIED,eval-sanitize-20-r1-041,
42.0441,TaskRequest,MODIFIED,eval-sanitize-20-r1-042,phase=Scheduled job=None
42.0475,Pod,ADDED,eval-sanitize-20-r1-042-bpmh6,phase=Pending node=None
42.0506,Job,MODIFIED,eval-sanitize-20-r1-042,
42.0533,Job,MODIFIED,eval-sanitize-20-r1-040,
42.0545,Event,ADDED,eval-sanitize-20-r1-042.18d41aa7d736707b,reason=SuccessfulCreate count=1 msg=Created pod: eval-sanitize-20-r1-042-bpmh6
42.0555,TaskRequest,MODIFIED,eval-sanitize-20-r1-042,phase=Scheduled job=None
42.0598,Job,MODIFIED,eval-sanitize-20-r1-041,
42.0653,Job,MODIFIED,eval-sanitize-20-r1-040,
42.0958,Pod,MODIFIED,eval-sanitize-20-r1-041-sh74p,phase=Running node=kind-worker4
42.1226,Pod,MODIFIED,eval-sanitize-20-r1-042-bpmh6,phase=Pending node=kind-worker5
42.1259,Event,ADDED,eval-sanitize-20-r1-042-bpmh6.18d41aa7dbab14cb,reason=Scheduled count=None msg=Successfully assigned compute/eval-sanitize-20-r1-042-bpmh6 to kind-worker5
42.1323,Pod,MODIFIED,eval-sanitize-20-r1-042-bpmh6,phase=Pending node=kind-worker5
42.1344,Node,MODIFIED,kind-worker5,taints=0
42.1457,Node,MODIFIED,kind-worker5,taints=0
42.5843,Event,ADDED,eval-sanitize-20-r1-042-bpmh6.18d41aa7f6f599e5,"reason=Pulled count=1 msg=Container image ""busybox:musl"" already present on machine"
42.6025,Event,ADDED,eval-sanitize-20-r1-042-bpmh6.18d41aa7f80a4707,reason=Created count=1 msg=Created container: task
42.695,Event,ADDED,eval-sanitize-20-r1-042-bpmh6.18d41aa7fd841e5f,reason=Started count=1 msg=Started container task
43.0086,TaskRequest,ADDED,eval-sanitize-20-r1-043,phase=None job=None
43.0127,TaskRequest,MODIFIED,eval-sanitize-20-r1-043,phase=Pending job=None
43.0291,Job,ADDED,eval-sanitize-20-r1-043,
43.0375,Pod,ADDED,eval-sanitize-20-r1-043-kzxd7,phase=Pending node=None
43.0376,TaskRequest,MODIFIED,eval-sanitize-20-r1-043,phase=Scheduled job=None
43.0397,Job,MODIFIED,eval-sanitize-20-r1-043,
43.0421,Event,ADDED,eval-sanitize-20-r1-043.18d41aa8121f26ea,reason=SuccessfulCreate count=1 msg=Created pod: eval-sanitize-20-r1-043-kzxd7
43.0452,TaskRequest,MODIFIED,eval-sanitize-20-r1-043,phase=Scheduled job=None
43.0487,Job,MODIFIED,eval-sanitize-20-r1-041,
43.0536,Job,MODIFIED,eval-sanitize-20-r1-042,
43.0584,Job,MODIFIED,eval-sanitize-20-r1-041,
43.0621,Job,MODIFIED,eval-sanitize-20-r1-042,
43.1145,Pod,MODIFIED,eval-sanitize-20-r1-043-kzxd7,phase=Pending node=kind-worker
43.1193,Event,ADDED,eval-sanitize-20-r1-043-kzxd7.18d41aa816cb0a89,reason=Scheduled count=None msg=Successfully assigned compute/eval-sanitize-20-r1-043-kzxd7 to kind-worker
43.1257,Pod,MODIFIED,eval-sanitize-20-r1-043-kzxd7,phase=Pending node=kind-worker
43.2699,Pod,MODIFIED,eval-sanitize-20-r1-042-bpmh6,phase=Running node=kind-worker5
43.5787,Event,ADDED,eval-sanitize-20-r1-043-kzxd7.18d41aa8323e057f,"reason=Pulled count=1 msg=Container image ""busybox:musl"" already present on machine"
43.5964,Event,ADDED,eval-sanitize-20-r1-043-kzxd7.18d41aa8334d8f4a,reason=Created count=1 msg=Created container: task
43.6404,Event,ADDED,eval-sanitize-20-r1-043-kzxd7.18d41aa835ddb8cd,reason=Started count=1 msg=Started container task
43.6784,Pod,MODIFIED,eval-sanitize-20-r1-043-kzxd7,phase=Running node=kind-worker
44.0136,TaskRequest,ADDED,eval-sanitize-20-r1-044,phase=None job=None
44.0191,TaskRequest,MODIFIED,eval-sanitize-20-r1-044,phase=Pending job=None
44.0339,Job,ADDED,eval-sanitize-20-r1-044,
44.0394,TaskRequest,MODIFIED,eval-sanitize-20-r1-044,phase=Scheduled job=None
44.0422,Pod,ADDED,eval-sanitize-20-r1-044-7jzzf,phase=Pending node=None
44.0433,Job,MODIFIED,eval-sanitize-20-r1-043,
44.0443,Job,MODIFIED,eval-sanitize-20-r1-044,
44.0466,Event,ADDED,eval-sanitize-20-r1-044.18d41aa84e1f1ff9,reason=SuccessfulCreate count=1 msg=Created pod: eval-sanitize-20-r1-044-7jzzf
44.0477,TaskRequest,MODIFIED,eval-sanitize-20-r1-044,phase=Scheduled job=None
44.0514,Job,MODIFIED,eval-sanitize-20-r1-043,
44.0579,Job,MODIFIED,eval-sanitize-20-r1-042,
44.0661,Job,MODIFIED,eval-sanitize-20-r1-042,
44.1153,Pod,MODIFIED,eval-sanitize-20-r1-044-7jzzf,phase=Pending node=kind-worker
44.121,Event,ADDED,eval-sanitize-20-r1-044-7jzzf.18d41aa85273ac92,reason=Scheduled count=None msg=Successfully assigned compute/eval-sanitize-20-r1-044-7jzzf to kind-worker
44.1263,Pod,MODIFIED,eval-sanitize-20-r1-044-7jzzf,phase=Pending node=kind-worker
44.5773,Event,ADDED,eval-sanitize-20-r1-044-7jzzf.18d41aa86dc0d20d,"reason=Pulled count=1 msg=Container image ""busybox:musl"" already present on machine"
44.5959,Event,ADDED,eval-sanitize-20-r1-044-7jzzf.18d41aa86ee3c0c5,reason=Created count=1 msg=Created container: task
44.6902,Event,ADDED,eval-sanitize-20-r1-044-7jzzf.18d41aa87471e0d9,reason=Started count=1 msg=Started container task
45.0069,TaskRequest,ADDED,eval-sanitize-20-r1-045,phase=None job=None
45.0112,TaskRequest,MODIFIED,eval-sanitize-20-r1-045,phase=Pending job=None
45.0269,Job,ADDED,eval-sanitize-20-r1-045,
45.0311,TaskRequest,MODIFIED,eval-sanitize-20-r1-045,phase=Scheduled job=None
45.0339,Pod,ADDED,eval-sanitize-20-r1-045-zpzl7,phase=Pending node=None
45.036,Job,MODIFIED,eval-sanitize-20-r1-045,
45.0402,Event,ADDED,eval-sanitize-20-r1-045.18d41aa8893ea93c,reason=SuccessfulCreate count=1 msg=Created pod: eval-sanitize-20-r1-045-zpzl7
45.0403,TaskRequest,MODIFIED,eval-sanitize-20-r1-045,phase=Scheduled job=None
45.0472,Job,MODIFIED,eval-sanitize-20-r1-044,
45.0557,Job,MODIFIED,eval-sanitize-20-r1-044,
45.1137,Pod,MODIFIED,eval-sanitize-20-r1-045-zpzl7,phase=Pending node=kind-worker5
45.1184,Event,ADDED,eval-sanitize-20-r1-045-zpzl7.18d41aa88dfffb2a,reason=Scheduled count=None msg=Successfully assigned compute/eval-sanitize-20-r1-045-zpzl7 to kind-worker5
45.1242,Pod,MODIFIED,eval-sanitize-20-r1-045-zpzl7,phase=Pending node=kind-worker5
45.5494,Event,ADDED,eval-sanitize-20-r1-045-zpzl7.18d41aa8a7b2eec3,"reason=Pulled count=1 msg=Container image ""busybox:musl"" already present on machine"
45.5661,Event,ADDED,eval-sanitize-20-r1-045-zpzl7.18d41aa8a8bdf2cf,reason=Created count=1 msg=Created container: task
45.6271,Event,ADDED,eval-sanitize-20-r1-045-zpzl7.18d41aa8ac4cb393,reason=Started count=1 msg=Started container task
45.6864,Pod,MODIFIED,eval-sanitize-20-r1-031-dpf7x,phase=Running node=kind-worker
45.6932,Pod,MODIFIED,eval-sanitize-20-r1-030-8p8k8,phase=Running node=kind-worker
45.6991,Pod,MODIFIED,eval-sanitize-20-r1-028-26fpq,phase=Running node=kind-worker
45.7054,Pod,MODIFIED,eval-sanitize-20-r1-025-rp76f,phase=Running node=kind-worker
45.7125,Pod,MODIFIED,eval-sanitize-20-r1-029-cjqck,phase=Running node=kind-worker
45.7184,Pod,MODIFIED,eval-sanitize-20-r1-016-rhx4s,phase=Running node=kind-worker
45.7243,Pod,MODIFIED,eval-sanitize-20-r1-027-t6jkc,phase=Running node=kind-worker
45.7298,Pod,MODIFIED,eval-sanitize-20-r1-044-7jzzf,phase=Running node=kind-worker
45.7359,Pod,MODIFIED,eval-sanitize-20-r1-018-tml46,phase=Running node=kind-worker
45.7416,Pod,MODIFIED,eval-sanitize-20-r1-012-m6skw,phase=Running node=kind-worker
45.7475,Pod,MODIFIED,eval-sanitize-20-r1-033-sstrx,phase=Running node=kind-worker
46.0095,TaskRequest,ADDED,eval-sanitize-20-r1-046,phase=None job=None
46.0129,TaskRequest,MODIFIED,eval-sanitize-20-r1-046,phase=Pending job=None
46.028,Job,ADDED,eval-sanitize-20-r1-046,
46.0344,Pod,ADDED,eval-sanitize-20-r1-046-mlxd2,phase=Pending node=None
46.0345,TaskRequest,MODIFIED,eval-sanitize-20-r1-046,phase=Scheduled job=None
46.0374,Job,MODIFIED,eval-sanitize-20-r1-046,
46.0396,Job,MODIFIED,eval-sanitize-20-r1-045,
46.04,Event,ADDED,eval-sanitize-20-r1-046.18d41aa8c4dd50bc,reason=SuccessfulCreate count=1 msg=Created pod: eval-sanitize-20-r1-046-mlxd2
46.0439,TaskRequest,MODIFIED,eval-sanitize-20-r1-046,phase=Scheduled job=None
46.0482,Job,MODIFIED,eval-sanitize-20-r1-045,
46.0522,Job,MODIFIED,eval-sanitize-20-r1-044,
46.0608,Job,MODIFIED,eval-sanitize-20-r1-044,
46.0991,Pod,MODIFIED,eval-sanitize-20-r1-026-cdlxh,phase=Running node=kind-worker4
46.1053,Pod,MODIFIED,eval-sanitize-20-r1-020-xv9d4,phase=Running node=kind-worker4
46.1145,Pod,MODIFIED,eval-sanitize-20-r1-046-mlxd2,phase=Pending node=kind-worker4
46.1206,Event,ADDED,eval-sanitize-20-r1-046-mlxd2.18d41aa8c9a77c12,reason=Scheduled count=None msg=Successfully assigned compute/eval-sanitize-20-r1-046-mlxd2 to kind-worker4
46.1262,Pod,MODIFIED,eval-sanitize-20-r1-046-mlxd2,phase=Pending node=kind-worker4
46.2762,Pod,MODIFIED,eval-sanitize-20-r1-045-zpzl7,phase=Running node=kind-worker5
46.6324,Event,ADDED,eval-sanitize-20-r1-046-mlxd2.18d41aa8e838f6c5,"reason=Pulled count=1 msg=Container image ""busybox:musl"" already present on machine"
46.6445,Pod,MODIFIED,eval-sanitize-20-r1-022-qr2sk,phase=Running node=kind-worker3
46.6517,Pod,MODIFIED,eval-sanitize-20-r1-032-v889x,phase=Running node=kind-worker3
46.653,Event,ADDED,eval-sanitize-20-r1-046-mlxd2.18d41aa8e98a165d,reason=Created count=1 msg=Created container: task
46.6578,Pod,MODIFIED,eval-sanitize-20-r1-024-jjnk6,phase=Running node=kind-worker3
46.6915,Job,MODIFIED,eval-sanitize-20-r1-031,
46.7004,Job,MODIFIED,eval-sanitize-20-r1-030,
46.7083,Job,MODIFIED,eval-sanitize-20-r1-031,
46.7098,Job,MODIFIED,eval-sanitize-20-r1-028,
46.7139,Job,MODIFIED,eval-sanitize-20-r1-025,
46.7181,Job,MODIFIED,eval-sanitize-20-r1-030,
46.7232,Job,MODIFIED,eval-sanitize-20-r1-029,
46.7263,Job,MODIFIED,eval-sanitize-20-r1-028,
46.73,Job,MODIFIED,eval-sanitize-20-r1-016,
46.7308,Job,MODIFIED,eval-sanitize-20-r1-025,
46.7331,Job,MODIFIED,eval-sanitize-20-r1-027,
46.7343,Job,MODIFIED,eval-sanitize-20-r1-029,
46.7397,Job,MODIFIED,eval-sanitize-20-r1-018,
46.7459,Job,MODIFIED,eval-sanitize-20-r1-012,
46.7507,Job,MODIFIED,eval-sanitize-20-r1-033,
46.8157,Job,MODIFIED,eval-sanitize-20-r1-016,
46.818,Job,MODIFIED,eval-sanitize-20-r1-027,
46.8188,Job,MODIFIED,eval-sanitize-20-r1-018,
46.8196,Job,MODIFIED,eval-sanitize-20-r1-012,
46.8204,Job,MODIFIED,eval-sanitize-20-r1-033,
46.8296,Event,ADDED,eval-sanitize-20-r1-046-mlxd2.18d41aa8f3c0c23a,reason=Started count=1 msg=Started container task
46.858,Pod,MODIFIED,eval-sanitize-20-r1-030-8p8k8,phase=Succeeded node=kind-worker
46.8943,Pod,MODIFIED,eval-sanitize-20-r1-016-rhx4s,phase=Succeeded node=kind-worker
46.9215,Pod,MODIFIED,eval-sanitize-20-r1-031-dpf7x,phase=Succeeded node=kind-worker
46.9279,Pod,MODIFIED,eval-sanitize-20-r1-033-sstrx,phase=Succeeded node=kind-worker
46.9357,Pod,MODIFIED,eval-sanitize-20-r1-027-t6jkc,phase=Succeeded node=kind-worker
46.9444,Pod,MODIFIED,eval-sanitize-20-r1-028-26fpq,phase=Succeeded node=kind-worker
46.9503,Pod,MODIFIED,eval-sanitize-20-r1-029-cjqck,phase=Succeeded node=kind-worker
46.956,Pod,MODIFIED,eval-sanitize-20-r1-025-rp76f,phase=Succeeded node=kind-worker
46.9618,Pod,MODIFIED,eval-sanitize-20-r1-018-tml46,phase=Succeeded node=kind-worker
46.968,Pod,MODIFIED,eval-sanitize-20-r1-012-m6skw,phase=Succeeded node=kind-worker
47.0148,TaskRequest,ADDED,eval-sanitize-20-r1-047,phase=None job=None
47.0185,TaskRequest,MODIFIED,eval-sanitize-20-r1-047,phase=Pending job=None
47.0337,Job,ADDED,eval-sanitize-20-r1-047,
47.0381,Job,MODIFIED,eval-sanitize-20-r1-046,
47.0426,TaskRequest,MODIFIED,eval-sanitize-20-r1-047,phase=Scheduled job=None
47.0437,Pod,ADDED,eval-sanitize-20-r1-047-sffms,phase=Pending node=None
47.0445,Job,MODIFIED,eval-sanitize-20-r1-047,
47.0458,Job,MODIFIED,eval-sanitize-20-r1-045,
47.047,Event,ADDED,eval-sanitize-20-r1-047.18d41aa901004ddd,reason=SuccessfulCreate count=1 msg=Created pod: eval-sanitize-20-r1-047-sffms
47.0529,Job,MODIFIED,eval-sanitize-20-r1-046,
47.0546,TaskRequest,MODIFIED,eval-sanitize-20-r1-047,phase=Scheduled job=None
47.0552,Job,MODIFIED,eval-sanitize-20-r1-045,
47.104,Job,MODIFIED,eval-sanitize-20-r1-026,
47.1086,Pod,MODIFIED,eval-sanitize-20-r1-046-mlxd2,phase=Running node=kind-worker4
47.1109,Job,MODIFIED,eval-sanitize-20-r1-020,
47.1134,Pod,MODIFIED,eval-sanitize-20-r1-047-sffms,phase=Pending node=kind-worker4
47.115,Job,MODIFIED,eval-sanitize-20-r1-026,
47.1214,Event,ADDED,eval-sanitize-20-r1-047-sffms.18d41aa90531266f,reason=Scheduled count=None msg=Successfully assigned compute/eval-sanitize-20-r1-047-sffms to kind-worker4
47.1261,Job,MODIFIED,eval-sanitize-20-r1-020,
47.1295,Pod,MODIFIED,eval-sanitize-20-r1-047-sffms,phase=Pending node=kind-worker4
47.2447,Pod,MODIFIED,eval-sanitize-20-r1-020-xv9d4,phase=Succeeded node=kind-worker4
47.306,Pod,MODIFIED,eval-sanitize-20-r1-026-cdlxh,phase=Succeeded node=kind-worker4
47.5429,Event,ADDED,eval-sanitize-20-r1-047-sffms.18d41aa91e89e876,"reason=Pulled count=1 msg=Container image ""busybox:musl"" already present on machine"
47.5622,Event,ADDED,eval-sanitize-20-r1-047-sffms.18d41aa91f9cc492,reason=Created count=1 msg=Created container: task
47.5957,Event,ADDED,eval-sanitize-20-r1-047-sffms.18d41aa921b20428,reason=Started count=1 msg=Started container task
47.6573,Pod,MODIFIED,eval-sanitize-20-r1-035-sj97h,phase=Running node=kind-worker3
47.6586,Job,MODIFIED,eval-sanitize-20-r1-022,
47.6595,Job,MODIFIED,eval-sanitize-20-r1-032,
47.6646,Job,MODIFIED,eval-sanitize-20-r1-024,
47.6662,Pod,MODIFIED,eval-sanitize-20-r1-037-lgp4f,phase=Running node=kind-worker3
47.6729,Job,MODIFIED,eval-sanitize-20-r1-022,
47.6763,Pod,MODIFIED,eval-sanitize-20-r1-023-lhw8g,phase=Running node=kind-worker3
47.6771,Job,MODIFIED,eval-sanitize-20-r1-032,
47.6778,Job,MODIFIED,eval-sanitize-20-r1-024,
47.6843,Pod,MODIFIED,eval-sanitize-20-r1-019-dl74d,phase=Running node=kind-worker3
47.6965,Job,MODIFIED,eval-sanitize-20-r1-031,
47.7053,Job,MODIFIED,eval-sanitize-20-r1-030,
47.7088,Pod,MODIFIED,eval-sanitize-20-r1-031-dpf7x,phase=Succeeded node=kind-worker
47.7097,Job,MODIFIED,eval-sanitize-20-r1-031,
47.7152,Pod,MODIFIED,eval-sanitize-20-r1-030-8p8k8,phase=Succeeded node=kind-worker
47.7176,Job,MODIFIED,eval-sanitize-20-r1-028,
47.7184,Job,MODIFIED,eval-sanitize-20-r1-030,
47.7193,Job,MODIFIED,eval-sanitize-20-r1-025,
47.7272,Pod,MODIFIED,eval-sanitize-20-r1-028-26fpq,phase=Succeeded node=kind-worker
47.7285,Job,MODIFIED,eval-sanitize-20-r1-029,
47.7299,Pod,MODIFIED,eval-sanitize-20-r1-025-rp76f,phase=Succeeded node=kind-worker
47.7308,Job,MODIFIED,eval-sanitize-20-r1-028,
47.7352,Job,MODIFIED,eval-sanitize-20-r1-025,
47.7373,Event,ADDED,eval-sanitize-20-r1-028.18d41aa929ffeb54,reason=Completed count=1 msg=Job completed
47.7381,Job,MODIFIED,eval-sanitize-20-r1-016,
47.7419,Job,MODIFIED,eval-sanitize-20-r1-027,
47.7423,Event,ADDED,eval-sanitize-20-r1-025.18d41aa92a4039a7,reason=Completed count=1 msg=Job completed
47.7436,Pod,MODIFIED,eval-sanitize-20-r1-029-cjqck,phase=Succeeded node=kind-worker
47.7449,Job,MODIFIED,eval-sanitize-20-r1-018,
47.7471,Job,MODIFIED,eval-sanitize-20-r1-029,
47.7488,Pod,MODIFIED,eval-sanitize-20-r1-016-rhx4s,phase=Succeeded node=kind-worker
47.75,Pod,MODIFIED,eval-sanitize-20-r1-027-t6jkc,phase=Succeeded node=kind-worker
47.7522,Job,MODIFIED,eval-sanitize-20-r1-012,
47.7539,Event,ADDED,eval-sanitize-20-r1-029.18d41aa92af828d7,reason=Completed count=1 msg=Job completed
47.7552,Pod,MODIFIED,eval-sanitize-20-r1-018-tml46,phase=Succeeded node=kind-worker
47.7561,Job,MODIFIED,eval-sanitize-20-r1-016,
47.757,Job,MODIFIED,eval-sanitize-20-r1-027,
47.7577,Job,MODIFIED,eval-sanitize-20-r1-033,
47.7614,Pod,MODIFIED,eval-sanitize-20-r1-012-m6skw,phase=Succeeded node=kind-worker
47.7678,Job,MODIFIED,eval-sanitize-20-r1-028,
47.7742,Job,MODIFIED,eval-sanitize-20-r1-025,
47.7769,Job,MODIFIED,eval-sanitize-20-r1-029,
47.7779,Job,MODIFIED,eval-sanitize-20-r1-016,
47.7787,Job,MODIFIED,eval-sanitize-20-r1-027,
47.8002,Event,ADDED,eval-sanitize-20-r1-027.18d41aa92b675631,reason=Completed count=1 msg=Job completed
47.8066,Pod,MODIFIED,eval-sanitize-20-r1-024-jjnk6,phase=Succeeded node=kind-worker3
47.8484,Pod,MODIFIED,eval-sanitize-20-r1-022-qr2sk,phase=Succeeded node=kind-worker3
47.8614,Job,MODIFIED,eval-sanitize-20-r1-018,
47.8659,Pod,MODIFIED,eval-sanitize-20-r1-032-v889x,phase=Succeeded node=kind-worker3
47.866,TaskRequest,MODIFIED,eval-sanitize-20-r1-025,phase=Complete job=None
47.8716,TaskRequest,MODIFIED,eval-sanitize-20-r1-027,phase=Complete job=None
47.8749,TaskRequest,MODIFIED,eval-sanitize-20-r1-029,phase=Complete job=None
47.8777,Job,MODIFIED,eval-sanitize-20-r1-018,
47.8796,Job,MODIFIED,eval-sanitize-20-r1-025,
47.8804,Job,MODIFIED,eval-sanitize-20-r1-012,
47.8811,Job,MODIFIED,eval-sanitize-20-r1-033,
47.8919,TaskRequest,MODIFIED,eval-sanitize-20-r1-016,phase=Complete job=None
47.9035,Pod,MODIFIED,eval-sanitize-20-r1-033-sstrx,phase=Succeeded node=kind-worker
47.9636,TaskRequest,MODIFIED,eval-sanitize-20-r1-028,phase=Complete job=None
47.9671,Job,MODIFIED,eval-sanitize-20-r1-027,
47.9683,Job,MODIFIED,eval-sanitize-20-r1-029,
47.9684,TaskRequest,MODIFIED,eval-sanitize-20-r1-018,phase=Complete job=None
47.9694,Job,MODIFIED,eval-sanitize-20-r1-016,
47.9746,Job,MODIFIED,eval-sanitize-20-r1-028,
47.9761,Job,MODIFIED,eval-sanitize-20-r1-018,
48.0048,Event,ADDED,eval-sanitize-20-r1-016.18d41aa92b6c11d9,reason=Completed count=1 msg=Job completed
48.0071,TaskRequest,ADDED,eval-sanitize-20-r1-048,phase=None job=None
48.0109,TaskRequest,MODIFIED,eval-sanitize-20-r1-048,phase=Pending job=None
48.0261,Job,ADDED,eval-sanitize-20-r1-048,
48.0301,TaskRequest,MODIFIED,eval-sanitize-20-r1-048,phase=Scheduled job=None
48.0337,Job,MODIFIED,eval-sanitize-20-r1-048,
48.0767,TaskRequest,MODIFIED,eval-sanitize-20-r1-048,phase=Scheduled job=None
48.1039,Event,ADDED,eval-sanitize-20-r1-018.18d41aa931a95888,reason=Completed count=1 msg=Job completed
48.1104,Pod,MODIFIED,eval-sanitize-20-r1-047-sffms,phase=Running node=kind-worker4
48.1622,Pod,ADDED,eval-sanitize-20-r1-048-6wbxl,phase=Pending node=None
48.1944,Pod,MODIFIED,eval-sanitize-20-r1-036-qpnd7,phase=Running node=kind-worker2
48.2015,Pod,MODIFIED,eval-sanitize-20-r1-034-48s2k,phase=Running node=kind-worker2
48.2024,Job,MODIFIED,eval-sanitize-20-r1-046,
48.2086,Pod,MODIFIED,eval-sanitize-20-r1-021-77dzv,phase=Running node=kind-worker2
48.2123,Job,MODIFIED,eval-sanitize-20-r1-046,
48.2393,Pod,MODIFIED,eval-sanitize-20-r1-048-6wbxl,phase=Pending node=kind-worker4
48.2439,Event,ADDED,eval-sanitize-20-r1-048-6wbxl.18d41aa9484816c9,reason=Scheduled count=None msg=Successfully assigned compute/eval-sanitize-20-r1-048-6wbxl to kind-worker4
48.2495,Pod,MODIFIED,eval-sanitize-20-r1-048-6wbxl,phase=Pending node=kind-worker4
48.2509,Job,MODIFIED,eval-sanitize-20-r1-047,
48.2596,Job,MODIFIED,eval-sanitize-20-r1-047,
48.3003,Job,MODIFIED,eval-sanitize-20-r1-026,
48.3098,Job,MODIFIED,eval-sanitize-20-r1-026,
48.3546,Job,MODIFIED,eval-sanitize-20-r1-020,
48.3634,Job,MODIFIED,eval-sanitize-20-r1-020,
48.4539,Event,ADDED,eval-sanitize-20-r1-048.18d41aa943b3d06f,reason=SuccessfulCreate count=1 msg=Created pod: eval-sanitize-20-r1-048-6wbxl
48.5046,Pod,MODIFIED,eval-sanitize-20-r1-026-cdlxh,phase=Succeeded node=kind-worker4
48.5584,Pod,MODIFIED,eval-sanitize-20-r1-020-xv9d4,phase=Succeeded node=kind-worker4
48.684,Event,ADDED,eval-sanitize-20-r1-048-6wbxl.18d41aa9628157bf,"reason=Pulled count=1 msg=Container image ""busybox:musl"" already present on machine"
48.7006,Job,MODIFIED,eval-sanitize-20-r1-035,
48.7059,Event,ADDED,eval-sanitize-20-r1-048-6wbxl.18d41aa963e9f624,reason=Created count=1 msg=Created container: task
48.7094,Job,MODIFIED,eval-sanitize-20-r1-035,
48.7655,Job,MODIFIED,eval-sanitize-20-r1-022,
48.7772,Job,MODIFIED,eval-sanitize-20-r1-022,
48.7775,Event,ADDED,eval-sanitize-20-r1-048-6wbxl.18d41aa9680be022,reason=Started count=1 msg=Started container task
48.805,Job,MODIFIED,eval-sanitize-20-r1-032,
48.8144,Job,MODIFIED,eval-sanitize-20-r1-032,
48.8344,Pod,MODIFIED,eval-sanitize-20-r1-019-dl74d,phase=Succeeded node=kind-worker3
48.8504,Job,MODIFIED,eval-sanitize-20-r1-024,
48.8598,Job,MODIFIED,eval-sanitize-20-r1-024,
48.8891,Pod,MODIFIED,eval-sanitize-20-r1-037-lgp4f,phase=Succeeded node=kind-worker3
48.8951,Pod,MODIFIED,eval-sanitize-20-r1-035-sj97h,phase=Succeeded node=kind-worker3
48.8996,Job,MODIFIED,eval-sanitize-20-r1-037,
48.9022,Pod,MODIFIED,eval-sanitize-20-r1-023-lhw8g,phase=Succeeded node=kind-worker3
48.9114,Job,MODIFIED,eval-sanitize-20-r1-037,
48.9567,Job,MODIFIED,eval-sanitize-20-r1-023,
48.9659,Job,MODIFIED,eval-sanitize-20-r1-023,
49.0105,Pod,MODIFIED,eval-sanitize-20-r1-022-qr2sk,phase=Succeeded node=kind-worker3
49.0106,TaskRequest,ADDED,eval-sanitize-20-r1-049,phase=None job=None
49.0142,TaskRequest,MODIFIED,eval-sanitize-20-r1-049,phase=Pending job=None
49.0291,Job,ADDED,eval-sanitize-20-r1-049,
49.0356,TaskRequest,MODIFIED,eval-sanitize-20-r1-049,phase=Scheduled job=None
49.0379,Job,MODIFIED,eval-sanitize-20-r1-049,
49.0415,TaskRequest,MODIFIED,eval-sanitize-20-r1-049,phase=Scheduled job=None
49.0534,Pod,MODIFIED,eval-sanitize-20-r1-032-v889x,phase=Succeeded node=kind-worker3
49.1095,Pod,MODIFIED,eval-sanitize-20-r1-024-jjnk6,phase=Succeeded node=kind-worker3
49.1145,Pod,MODIFIED,eval-sanitize-20-r1-048-6wbxl,phase=Running node=kind-worker4
49.1493,Job,MODIFIED,eval-sanitize-20-r1-019,
49.1585,Job,MODIFIED,eval-sanitize-20-r1-019,
49.2068,Job,MODIFIED,eval-sanitize-20-r1-031,
49.2205,Job,MODIFIED,eval-sanitize-20-r1-031,
49.2896,Pod,MODIFIED,eval-sanitize-20-r1-038-9lwb4,phase=Running node=kind-worker5
49.4035,Pod,MODIFIED,eval-sanitize-20-r1-021-77dzv,phase=Succeeded node=kind-worker2
49.405,Pod,MODIFIED,eval-sanitize-20-r1-019-dl74d,phase=Succeeded node=kind-worker3
49.4271,Pod,MODIFIED,eval-sanitize-20-r1-034-48s2k,phase=Succeeded node=kind-worker2
49.4349,Pod,MODIFIED,eval-sanitize-20-r1-036-qpnd7,phase=Succeeded node=kind-worker2
49.5086,Job,MODIFIED,eval-sanitize-20-r1-030,
49.5176,Job,MODIFIED,eval-sanitize-20-r1-030,
49.5498,Job,MODIFIED,eval-sanitize-20-r1-012,
49.559,Job,MODIFIED,eval-sanitize-20-r1-012,
49.6075,Job,MODIFIED,eval-sanitize-20-r1-033,
49.6165,Job,MODIFIED,eval-sanitize-20-r1-033,
49.7135,Pod,ADDED,eval-sanitize-20-r1-049-88mmc,phase=Pending node=None
49.7403,Pod,MODIFIED,eval-sanitize-20-r1-049-88mmc,phase=Pending node=kind-worker
49.7449,Event,ADDED,eval-sanitize-20-r1-049-88mmc.18d41aa9a1c6d26f,reason=Scheduled count=None msg=Successfully assigned compute/eval-sanitize-20-r1-049-88mmc to kind-worker
49.7504,Pod,MODIFIED,eval-sanitize-20-r1-049-88mmc,phase=Pending node=kind-worker
49.9074,Job,MODIFIED,eval-sanitize-20-r1-048,
49.9158,Job,MODIFIED,eval-sanitize-20-r1-048,
49.9508,Event,ADDED,eval-sanitize-20-r1-049.18d41aa9a02d13b6,reason=SuccessfulCreate count=1 msg=Created pod: eval-sanitize-20-r1-049-88mmc
50.0075,Job,MODIFIED,eval-sanitize-20-r1-049,
50.0175,Job,MODIFIED,eval-sanitize-20-r1-049,
50.0208,TaskRequest,ADDED,eval-sanitize-20-r1-050,phase=None job=None
50.0245,TaskRequest,MODIFIED,eval-sanitize-20-r1-050,phase=Pending job=None
50.0402,Job,ADDED,eval-sanitize-20-r1-050,
50.044,TaskRequest,MODIFIED,eval-sanitize-20-r1-050,phase=Scheduled job=None
50.0487,Job,MODIFIED,eval-sanitize-20-r1-050,
50.0507,Job,MODIFIED,eval-sanitize-20-r1-047,
50.0533,TaskRequest,MODIFIED,eval-sanitize-20-r1-050,phase=Scheduled job=None
50.0594,Job,MODIFIED,eval-sanitize-20-r1-047,
50.1014,Job,MODIFIED,eval-sanitize-20-r1-036,
50.1113,Job,MODIFIED,eval-sanitize-20-r1-036,
50.1168,Pod,MODIFIED,eval-sanitize-20-r1-039-m6b7m,phase=Running node=kind-worker4
50.1611,Job,MODIFIED,eval-sanitize-20-r1-034,
50.1686,Event,ADDED,eval-sanitize-20-r1-049-88mmc.18d41aa9bb005f52,"reason=Pulled count=1 msg=Container image ""busybox:musl"" already present on machine"
50.172,Job,MODIFIED,eval-sanitize-20-r1-034,
50.1862,Event,ADDED,eval-sanitize-20-r1-049-88mmc.18d41aa9bc23ec1e,reason=Created count=1 msg=Created container: task
50.2012,Job,MODIFIED,eval-sanitize-20-r1-021,
50.2111,Job,MODIFIED,eval-sanitize-20-r1-021,
50.2218,Event,ADDED,eval-sanitize-20-r1-049-88mmc.18d41aa9be464c3d,reason=Started count=1 msg=Started container task
50.2671,Job,MODIFIED,eval-sanitize-20-r1-026,
50.277,Job,MODIFIED,eval-sanitize-20-r1-026,
50.304,Job,MODIFIED,eval-sanitize-20-r1-020,
50.3147,Job,MODIFIED,eval-sanitize-20-r1-020,
50.3696,Pod,MODIFIED,eval-sanitize-20-r1-036-qpnd7,phase=Succeeded node=kind-worker2
50.3842,Pod,MODIFIED,eval-sanitize-20-r1-038-9lwb4,phase=Succeeded node=kind-worker5
50.4051,Pod,MODIFIED,eval-sanitize-20-r1-034-48s2k,phase=Succeeded node=kind-worker2
50.4593,Pod,MODIFIED,eval-sanitize-20-r1-021-77dzv,phase=Succeeded node=kind-worker2
50.7368,Pod,MODIFIED,eval-sanitize-20-r1-049-88mmc,phase=Running node=kind-worker
50.7498,Job,MODIFIED,eval-sanitize-20-r1-035,
50.7588,Job,MODIFIED,eval-sanitize-20-r1-035,
50.8026,Job,MODIFIED,eval-sanitize-20-r1-022,
50.8125,Job,MODIFIED,eval-sanitize-20-r1-022,
50.8558,Job,MODIFIED,eval-sanitize-20-r1-032,
50.8651,Job,MODIFIED,eval-sanitize-20-r1-032,
50.9001,Job,MODIFIED,eval-sanitize-20-r1-019,
50.9088,Job,MODIFIED,eval-sanitize-20-r1-019,
50.956,Job,MODIFIED,eval-sanitize-20-r1-024,
50.9652,Job,MODIFIED,eval-sanitize-20-r1-024,
51.0094,Pod,MODIFIED,eval-sanitize-20-r1-035-sj97h,phase=Succeeded node=kind-worker3
51.0119,TaskRequest,ADDED,eval-sanitize-20-r1-051,phase=None job=None
51.0169,TaskRequest,MODIFIED,eval-sanitize-20-r1-051,phase=Pending job=None
51.0306,Job,ADDED,eval-sanitize-20-r1-051,
51.0363,TaskRequest,MODIFIED,eval-sanitize-20-r1-051,phase=Scheduled job=None
51.04,Job,MODIFIED,eval-sanitize-20-r1-051,
51.0428,TaskRequest,MODIFIED,eval-sanitize-20-r1-051,phase=Scheduled job=None
51.2126,Pod,MODIFIED,eval-sanitize-20-r1-039-m6b7m,phase=Succeeded node=kind-worker4
51.2937,Pod,MODIFIED,eval-sanitize-20-r1-040-vrmnl,phase=Running node=kind-worker5
51.2991,Job,MODIFIED,eval-sanitize-20-r1-037,
51.3091,Job,MODIFIED,eval-sanitize-20-r1-037,
51.3577,Job,MODIFIED,eval-sanitize-20-r1-023,
51.3663,Job,MODIFIED,eval-sanitize-20-r1-023,
51.4131,Job,MODIFIED,eval-sanitize-20-r1-049,
51.4228,Job,MODIFIED,eval-sanitize-20-r1-049,
51.4747,Pod,ADDED,eval-sanitize-20-r1-050-pvcrv,phase=Pending node=None
51.5019,Pod,MODIFIED,eval-sanitize-20-r1-050-pvcrv,phase=Pending node=kind-worker4
51.5036,Job,MODIFIED,eval-sanitize-20-r1-031,
51.5054,Event,ADDED,eval-sanitize-20-r1-050-pvcrv.18d41aaa0abfadbe,reason=Scheduled count=None msg=Successfully assigned compute/eval-sanitize-20-r1-050-pvcrv to kind-worker4
51.509,TaskRequest,MODIFIED,eval-sanitize-20-r1-031,phase=Complete job=None
51.5127,Pod,MODIFIED,eval-sanitize-20-r1-050-pvcrv,phase=Pending node=kind-worker4
51.5195,Job,MODIFIED,eval-sanitize-20-r1-031,
51.5639,Pod,MODIFIED,eval-sanitize-20-r1-037-lgp4f,phase=Succeeded node=kind-worker3
51.6045,Pod,MODIFIED,eval-sanitize-20-r1-023-lhw8g,phase=Succeeded node=kind-worker3
51.6679,Job,MODIFIED,eval-sanitize-20-r1-038,
51.6778,Job,MODIFIED,eval-sanitize-20-r1-038,
51.7036,Job,MODIFIED,eval-sanitize-20-r1-050,
51.7132,Job,MODIFIED,eval-sanitize-20-r1-050,
51.7544,Event,ADDED,eval-sanitize-20-r1-050.18d41aaa0928ef88,reason=SuccessfulCreate count=1 msg=Created pod: eval-sanitize-20-r1-050-pvcrv
51.808,Job,MODIFIED,eval-sanitize-20-r1-030,
51.8144,TaskRequest,MODIFIED,eval-sanitize-20-r1-030,phase=Complete job=None
51.8264,Job,MODIFIED,eval-sanitize-20-r1-030,
51.929,Event,ADDED,eval-sanitize-20-r1-050-pvcrv.18d41aaa23f6f48b,"reason=Pulled count=1 msg=Container image ""busybox:musl"" already present on machine"
51.9475,Event,ADDED,eval-sanitize-20-r1-050-pvcrv.18d41aaa250bdb83,reason=Created count=1 msg=Created container: task
51.9542,Pod,MODIFIED,eval-sanitize-20-r1-038-9lwb4,phase=Succeeded node=kind-worker5
51.9787,Event,ADDED,eval-sanitize-20-r1-050-pvcrv.18d41aaa26f4c22d,reason=Started count=1 msg=Started container task
51.9994,Job,MODIFIED,eval-sanitize-20-r1-012,
52.0032,TaskRequest,MODIFIED,eval-sanitize-20-r1-012,phase=Complete job=None
52.0131,Job,MODIFIED,eval-sanitize-20-r1-012,
52.0132,TaskRequest,ADDED,eval-sanitize-20-r1-052,phase=None job=None
52.0166,TaskRequest,MODIFIED,eval-sanitize-20-r1-052,phase=Pending job=None
52.0324,Job,ADDED,eval-sanitize-20-r1-052,
52.0366,TaskRequest,MODIFIED,eval-sanitize-20-r1-052,phase=Scheduled job=None
52.0414,Job,MODIFIED,eval-sanitize-20-r1-052,
52.0433,TaskRequest,MODIFIED,eval-sanitize-20-r1-052,phase=Scheduled job=None
52.0484,Event,ADDED,eval-sanitize-20-r1-031.18d41aaa0ae0c3cb,reason=Completed count=1 msg=Job completed
52.1062,Job,MODIFIED,eval-sanitize-20-r1-036,
52.1168,Job,MODIFIED,eval-sanitize-20-r1-036,
52.1233,Pod,MODIFIED,eval-sanitize-20-r1-041-sh74p,phase=Running node=kind-worker4
52.1312,Pod,MODIFIED,eval-sanitize-20-r1-050-pvcrv,phase=Running node=kind-worker4
52.1494,Job,MODIFIED,eval-sanitize-20-r1-033,
52.1537,TaskRequest,MODIFIED,eval-sanitize-20-r1-033,phase=Complete job=None
52.1625,Job,MODIFIED,eval-sanitize-20-r1-033,
52.2067,Job,MODIFIED,eval-sanitize-20-r1-034,
52.2165,Job,MODIFIED,eval-sanitize-20-r1-034,
52.3088,Job,MODIFIED,eval-sanitize-20-r1-021,
52.3191,Job,MODIFIED,eval-sanitize-20-r1-021,
52.3485,Event,ADDED,eval-sanitize-20-r1-030.18d41aaa1d00a263,reason=Completed count=1 msg=Job completed
52.4223,Pod,MODIFIED,eval-sanitize-20-r1-040-vrmnl,phase=Succeeded node=kind-worker5
52.4667,Pod,ADDED,eval-sanitize-20-r1-051-dx4xm,phase=Pending node=None
52.5144,Pod,MODIFIED,eval-sanitize-20-r1-051-dx4xm,phase=Pending node=kind-worker3
52.5178,Event,ADDED,eval-sanitize-20-r1-051-dx4xm.18d41aaa471c85a9,reason=Scheduled count=None msg=Successfully assigned compute/eval-sanitize-20-r1-051-dx4xm to kind-worker3
52.5241,Pod,MODIFIED,eval-sanitize-20-r1-051-dx4xm,phase=Pending node=kind-worker3
52.5702,Job,MODIFIED,eval-sanitize-20-r1-039,
52.5795,Job,MODIFIED,eval-sanitize-20-r1-039,
52.6549,Event,ADDED,eval-sanitize-20-r1-012.18d41aaa286ee6f0,reason=Completed count=1 msg=Job completed
52.702,Job,MODIFIED,eval-sanitize-20-r1-026,
52.7057,TaskRequest,MODIFIED,eval-sanitize-20-r1-026,phase=Complete job=None
52.7163,Job,MODIFIED,eval-sanitize-20-r1-026,
52.7608,Job,MODIFIED,eval-sanitize-20-r1-051,
52.7688,Job,MODIFIED,eval-sanitize-20-r1-051,
52.8165,Job,MODIFIED,eval-sanitize-20-r1-020,
52.8199,TaskRequest,MODIFIED,eval-sanitize-20-r1-020,phase=Complete job=None
52.831,Job,MODIFIED,eval-sanitize-20-r1-020,
52.8546,Pod,MODIFIED,eval-sanitize-20-r1-039-m6b7m,phase=Succeeded node=kind-worker4
52.9025,Job,MODIFIED,eval-sanitize-20-r1-035,
52.9122,Job,MODIFIED,eval-sanitize-20-r1-035,
52.9531,Event,ADDED,eval-sanitize-20-r1-033.18d41aaa316024dc,reason=Completed count=1 msg=Job completed
52.9596,Event,ADDED,eval-sanitize-20-r1-051-dx4xm.18d41aaa6175f91c,"reason=Pulled count=1 msg=Container image ""busybox:musl"" already present on machine"
52.9789,Event,ADDED,eval-sanitize-20-r1-051-dx4xm.18d41aaa628166ed,reason=Created count=1 msg=Created container: task
53.0003,Job,MODIFIED,eval-sanitize-20-r1-022,
53.0049,TaskRequest,MODIFIED,eval-sanitize-20-r1-022,phase=Complete job=None
53.0061,TaskRequest,ADDED,eval-sanitize-20-r1-053,phase=None job=None
53.0099,TaskRequest,MODIFIED,eval-sanitize-20-r1-053,phase=Pending job=None
53.0152,Job,MODIFIED,eval-sanitize-20-r1-022,
53.0252,Job,ADDED,eval-sanitize-20-r1-053,
53.0315,TaskRequest,MODIFIED,eval-sanitize-20-r1-053,phase=Scheduled job=None
53.0342,Job,MODIFIED,eval-sanitize-20-r1-053,
53.0404,TaskRequest,MODIFIED,eval-sanitize-20-r1-053,phase=Scheduled job=None
53.0411,Event,ADDED,eval-sanitize-20-r1-051-dx4xm.18d41aaa6643424d,reason=Started count=1 msg=Started container task
53.0493,Job,MODIFIED,eval-sanitize-20-r1-032,
53.054,TaskRequest,MODIFIED,eval-sanitize-20-r1-032,phase=Complete job=None
53.0624,Job,MODIFIED,eval-sanitize-20-r1-032,
53.1,Job,MODIFIED,eval-sanitize-20-r1-019,
53.1034,TaskRequest,MODIFIED,eval-sanitize-20-r1-019,phase=Complete job=None
53.1129,Job,MODIFIED,eval-sanitize-20-r1-019,
53.2552,Event,ADDED,eval-sanitize-20-r1-051.18d41aaa44459652,reason=SuccessfulCreate count=1 msg=Created pod: eval-sanitize-20-r1-051-dx4xm
53.2636,Pod,MODIFIED,eval-sanitize-20-r1-041-sh74p,phase=Succeeded node=kind-worker4
53.3072,Job,MODIFIED,eval-sanitize-20-r1-024,
53.3127,Pod,MODIFIED,eval-sanitize-20-r1-042-bpmh6,phase=Running node=kind-worker5
53.3134,TaskRequest,MODIFIED,eval-sanitize-20-r1-024,phase=Complete job=None
53.3228,Job,MODIFIED,eval-sanitize-20-r1-024,
53.3653,Pod,ADDED,eval-sanitize-20-r1-052-m54h2,phase=Pending node=None
53.4086,Job,MODIFIED,eval-sanitize-20-r1-040,
53.414,Pod,MODIFIED,eval-sanitize-20-r1-052-m54h2,phase=Pending node=kind-worker5
53.4194,Job,MODIFIED,eval-sanitize-20-r1-040,
53.4197,Event,ADDED,eval-sanitize-20-r1-052-m54h2.18d41aaa7cbbe3b7,reason=Scheduled count=None msg=Successfully assigned compute/eval-sanitize-20-r1-052-m54h2 to kind-worker5
53.4242,Pod,MODIFIED,eval-sanitize-20-r1-052-m54h2,phase=Pending node=kind-worker5
53.465,Job,MODIFIED,eval-sanitize-20-r1-037,
53.4741,Job,MODIFIED,eval-sanitize-20-r1-037,
53.5159,Job,MODIFIED,eval-sanitize-20-r1-023,
53.5253,Job,MODIFIED,eval-sanitize-20-r1-023,
53.5505,Event,ADDED,eval-sanitize-20-r1-026.18d41aaa524b4b22,reason=Completed count=1 msg=Job completed
53.6054,Job,MODIFIED,eval-sanitize-20-r1-050,
53.6144,Job,MODIFIED,eval-sanitize-20-r1-050,
53.6653,Job,MODIFIED,eval-sanitize-20-r1-052,
53.6741,Job,MODIFIED,eval-sanitize-20-r1-052,
53.6767,Pod,MODIFIED,eval-sanitize-20-r1-051-dx4xm,phase=Running node=kind-worker3
53.7048,Pod,MODIFIED,eval-sanitize-20-r1-040-vrmnl,phase=Succeeded node=kind-worker5
53.7334,Pod,MODIFIED,eval-sanitize-20-r1-043-kzxd7,phase=Running node=kind-worker
53.8439,Event,ADDED,eval-sanitize-20-r1-052-m54h2.18d41aaa961e8a94,"reason=Pulled count=1 msg=Container image ""busybox:musl"" already present on machine"
53.851,Event,ADDED,eval-sanitize-20-r1-020.18d41aaa591cf8b6,reason=Completed count=1 msg=Job completed
53.8613,Event,ADDED,eval-sanitize-20-r1-052-m54h2.18d41aaa97385c1c,reason=Created count=1 msg=Created container: task
53.8943,Event,ADDED,eval-sanitize-20-r1-052-m54h2.18d41aaa99258b88,reason=Started count=1 msg=Started container task
53.8995,Job,MODIFIED,eval-sanitize-20-r1-038,
53.9083,Job,MODIFIED,eval-sanitize-20-r1-038,
53.9507,Pod,ADDED,eval-sanitize-20-r1-053-btx8q,phase=Pending node=None
53.9777,Pod,MODIFIED,eval-sanitize-20-r1-053-btx8q,phase=Pending node=kind-worker4
53.9813,Event,ADDED,eval-sanitize-20-r1-053-btx8q.18d41aaa9e570716,reason=Scheduled count=None msg=Successfully assigned compute/eval-sanitize-20-r1-053-btx8q to kind-worker4
53.9872,Pod,MODIFIED,eval-sanitize-20-r1-053-btx8q,phase=Pending node=kind-worker4
54.0068,TaskRequest,ADDED,eval-sanitize-20-r1-054,phase=None job=None
54.0123,TaskRequest,MODIFIED,eval-sanitize-20-r1-054,phase=Pending job=None
54.027,Job,ADDED,eval-sanitize-20-r1-054,
54.0328,TaskRequest,MODIFIED,eval-sanitize-20-r1-054,phase=Scheduled job=None
54.0383,Job,MODIFIED,eval-sanitize-20-r1-054,
54.0392,TaskRequest,MODIFIED,eval-sanitize-20-r1-054,phase=Scheduled job=None
54.0504,Job,MODIFIED,eval-sanitize-20-r1-036,
54.0533,TaskRequest,MODIFIED,eval-sanitize-20-r1-036,phase=Complete job=None
54.0626,Job,MODIFIED,eval-sanitize-20-r1-036,
54.106,Job,MODIFIED,eval-sanitize-20-r1-041,
54.116,Job,MODIFIED,eval-sanitize-20-r1-041,
54.1489,Event,ADDED,eval-sanitize-20-r1-022.18d41aaa641dc5e1,reason=Completed count=1 msg=Job completed
54.25,Job,MODIFIED,eval-sanitize-20-r1-053,
54.2586,Job,MODIFIED,eval-sanitize-20-r1-053,
54.3004,Pod,MODIFIED,eval-sanitize-20-r1-052-m54h2,phase=Running node=kind-worker5
54.3014,Job,MODIFIED,eval-sanitize-20-r1-034,
54.3068,TaskRequest,MODIFIED,eval-sanitize-20-r1-034,phase=Complete job=None
54.3178,Job,MODIFIED,eval-sanitize-20-r1-034,
54.3558,Job,MODIFIED,eval-sanitize-20-r1-021,
54.3591,TaskRequest,MODIFIED,eval-sanitize-20-r1-021,phase=Complete job=None
54.3691,Job,MODIFIED,eval-sanitize-20-r1-021,
54.3861,Node,MODIFIED,kind-worker,taints=1
54.3991,Node,MODIFIED,kind-worker,taints=1
54.4047,Pod,MODIFIED,eval-sanitize-20-r1-041-sh74p,phase=Succeeded node=kind-worker4
54.4151,Event,ADDED,eval-sanitize-20-r1-053-btx8q.18d41aaab83750ff,"reason=Pulled count=1 msg=Container image ""busybox:musl"" already present on machine"
54.4347,Event,ADDED,eval-sanitize-20-r1-053-btx8q.18d41aaab9643f93,reason=Created count=1 msg=Created container: task
54.4501,Event,ADDED,eval-sanitize-20-r1-032.18d41aaa670545d2,reason=Completed count=1 msg=Job completed
54.4634,Pod,MODIFIED,eval-sanitize-20-r1-042-bpmh6,phase=Succeeded node=kind-worker5
54.4695,Event,ADDED,eval-sanitize-20-r1-053-btx8q.18d41aaabb73d4c4,reason=Started count=1 msg=Started container task
54.5016,Job,MODIFIED,eval-sanitize-20-r1-051,
54.5105,Job,MODIFIED,eval-sanitize-20-r1-051,
54.5508,Job,MODIFIED,eval-sanitize-20-r1-039,
54.5607,Job,MODIFIED,eval-sanitize-20-r1-039,
54.6031,Job,MODIFIED,eval-sanitize-20-r1-035,
54.6079,TaskRequest,MODIFIED,eval-sanitize-20-r1-035,phase=Complete job=None
54.6177,Job,MODIFIED,eval-sanitize-20-r1-035,
54.6508,Job,MODIFIED,eval-sanitize-20-r1-040,
54.6602,Job,MODIFIED,eval-sanitize-20-r1-040,
54.7497,Event,ADDED,eval-sanitize-20-r1-019.18d41aaa6a0d3a90,reason=Completed count=1 msg=Job completed
54.8041,Pod,ADDED,eval-sanitize-20-r1-054-m6l4n,phase=Pending node=None
54.8105,Pod,MODIFIED,eval-sanitize-20-r1-043-kzxd7,phase=Succeeded node=kind-worker
54.8255,Pod,MODIFIED,eval-sanitize-20-r1-054-m6l4n,phase=Pending node=kind-worker4
54.829,Event,ADDED,eval-sanitize-20-r1-054-m6l4n.18d41aaad0e3054e,reason=Scheduled count=None msg=Successfully assigned compute/eval-sanitize-20-r1-054-m6l4n to kind-worker4
54.8356,Pod,MODIFIED,eval-sanitize-20-r1-054-m6l4n,phase=Pending node=kind-worker4
54.9009,Job,MODIFIED,eval-sanitize-20-r1-042,
54.9101,Job,MODIFIED,eval-sanitize-20-r1-042,
55.0007,Job,MODIFIED,eval-sanitize-20-r1-052,
55.0094,Job,MODIFIED,eval-sanitize-20-r1-052,
55.0101,TaskRequest,ADDED,eval-sanitize-20-r1-055,phase=None job=None
55.0145,TaskRequest,MODIFIED,eval-sanitize-20-r1-055,phase=Pending job=None
55.0288,Job,ADDED,eval-sanitize-20-r1-055,
55.0343,TaskRequest,MODIFIED,eval-sanitize-20-r1-055,phase=Scheduled job=None
55.0372,Job,MODIFIED,eval-sanitize-20-r1-055,
55.0401,TaskRequest,MODIFIED,eval-sanitize-20-r1-055,phase=Scheduled job=None
55.0487,Event,ADDED,eval-sanitize-20-r1-024.18d41aaa76422f86,reason=Completed count=1 msg=Job completed
55.1,Job,MODIFIED,eval-sanitize-20-r1-054,
55.109,Job,MODIFIED,eval-sanitize-20-r1-054,
55.1372,Pod,MODIFIED,eval-sanitize-20-r1-053-btx8q,phase=Running node=kind-worker4
55.1524,Job,MODIFIED,eval-sanitize-20-r1-037,
55.1573,TaskRequest,MODIFIED,eval-sanitize-20-r1-037,phase=Complete job=None
55.167,Job,MODIFIED,eval-sanitize-20-r1-037,
55.2044,Pod,MODIFIED,eval-sanitize-20-r1-042-bpmh6,phase=Succeeded node=kind-worker5
55.2591,Job,MODIFIED,eval-sanitize-20-r1-023,
55.2632,Event,ADDED,eval-sanitize-20-r1-054-m6l4n.18d41aaaeab8f673,"reason=Pulled count=1 msg=Container image ""busybox:musl"" already present on machine"
55.2659,TaskRequest,MODIFIED,eval-sanitize-20-r1-023,phase=Complete job=None
55.2774,Job,MODIFIED,eval-sanitize-20-r1-023,
55.2831,Event,ADDED,eval-sanitize-20-r1-054-m6l4n.18d41aaaebf0bbc4,reason=Created count=1 msg=Created container: task
55.2995,Job,MODIFIED,eval-sanitize-20-r1-041,
55.3087,Job,MODIFIED,eval-sanitize-20-r1-041,
55.3157,Node,MODIFIED,kind-worker4,taints=1
55.3292,Node,MODIFIED,kind-worker4,taints=1
55.3486,Event,ADDED,eval-sanitize-20-r1-052.18d41aaa79dd5454,reason=SuccessfulCreate count=1 msg=Created pod: eval-sanitize-20-r1-052-m54h2
55.3491,Event,ADDED,eval-sanitize-20-r1-054-m6l4n.18d41aaaefdc1210,reason=Started count=1 msg=Started container task
55.404,Job,MODIFIED,eval-sanitize-20-r1-043,
55.413,Job,MODIFIED,eval-sanitize-20-r1-043,
55.4569,Job,MODIFIED,eval-sanitize-20-r1-038,
55.4602,TaskRequest,MODIFIED,eval-sanitize-20-r1-038,phase=Complete job=None
55.4696,Job,MODIFIED,eval-sanitize-20-r1-038,
55.5569,Job,MODIFIED,eval-sanitize-20-r1-040,
55.561,TaskRequest,MODIFIED,eval-sanitize-20-r1-040,phase=Complete job=None
55.5702,Job,MODIFIED,eval-sanitize-20-r1-040,
55.6509,Event,ADDED,eval-sanitize-20-r1-053.18d41aaa9cbf837b,reason=SuccessfulCreate count=1 msg=Created pod: eval-sanitize-20-r1-053-btx8q
55.7109,Pod,MODIFIED,eval-sanitize-20-r1-043-kzxd7,phase=Succeeded node=kind-worker
55.7381,Pod,MODIFIED,eval-sanitize-20-r1-044-7jzzf,phase=Running node=kind-worker
55.7509,Pod,ADDED,eval-sanitize-20-r1-055-bzm98,phase=Pending node=None
55.7655,Pod,MODIFIED,eval-sanitize-20-r1-055-bzm98,phase=Pending node=None
55.7658,Event,ADDED,eval-sanitize-20-r1-055-bzm98.18d41aab08a043e7,"reason=FailedScheduling count=None msg=0/6 nodes are available: 3 c_wall violated: 1 conflicting context pair(s) with node memory, 3 node(s) had untolerated taint(s). no new claims to deallocate, preemption: 0/6 nodes are available: 3 No preemption victims found for incoming pod, 3 Preemption is not helpful for scheduling."
55.8096,Job,MODIFIED,eval-sanitize-20-r1-053,
55.8146,Event,ADDED,eval-sanitize-20-r1-055-bzm98.18d41aab0b863768,"reason=FailedScheduling count=None msg=0/6 nodes are available: 3 c_wall violated: 1 conflicting context pair(s) with node memory, 3 node(s) had untolerated taint(s). no new claims to deallocate, preemption: 0/6 nodes are available: 3 No preemption victims found for incoming pod, 3 Preemption is not helpful for scheduling."
55.818,Job,MODIFIED,eval-sanitize-20-r1-053,
55.8498,Job,MODIFIED,eval-sanitize-20-r1-042,
55.8591,Job,MODIFIED,eval-sanitize-20-r1-042,
55.8716,Node,MODIFIED,kind-worker3,taints=1
55.8821,Pod,MODIFIED,eval-sanitize-20-r1-055-bzm98,phase=Pending node=None
55.8842,Event,MODIFIED,eval-sanitize-20-r1-055-bzm98.18d41aab0b863768,"reason=FailedScheduling count=None msg=0/6 nodes are available: 3 c_wall violated: 1 conflicting context pair(s) with node memory, 3 node(s) had untolerated taint(s). no new claims to deallocate, preemption: 0/6 nodes are available: 3 No preemption victims found for incoming pod, 3 Preemption is not helpful for scheduling."
55.8856,Node,MODIFIED,kind-worker3,taints=1
55.8994,Job,MODIFIED,eval-sanitize-20-r1-039,
55.9044,TaskRequest,MODIFIED,eval-sanitize-20-r1-039,phase=Complete job=None
55.9086,Event,ADDED,eval-sanitize-20-r1-055-bzm98.18d41aab1138d594,"reason=FailedScheduling count=None msg=0/6 nodes are available: 2 c_wall violated: 1 conflicting context pair(s) with node memory, 4 node(s) had untolerated taint(s). no new claims to deallocate, preemption: 0/6 nodes are available: 2 No preemption victims found for incoming pod, 4 Preemption is not helpful for scheduling."
55.9126,Job,MODIFIED,eval-sanitize-20-r1-039,
55.9164,Event,MODIFIED,eval-sanitize-20-r1-055-bzm98.18d41aab1138d594,"reason=FailedScheduling count=None msg=0/6 nodes are available: 2 c_wall violated: 1 conflicting context pair(s) with node memory, 4 node(s) had untolerated taint(s). no new claims to deallocate, preemption: 0/6 nodes are available: 2 No preemption victims found for incoming pod, 4 Preemption is not helpful for scheduling."
55.9485,Event,ADDED,eval-sanitize-20-r1-036.18d41aaaa2ab91e3,reason=Completed count=1 msg=Job completed
56.013,TaskRequest,ADDED,eval-sanitize-20-r1-056,phase=None job=None
56.0177,TaskRequest,MODIFIED,eval-sanitize-20-r1-056,phase=Pending job=None
56.0337,Job,ADDED,eval-sanitize-20-r1-056,
56.0393,TaskRequest,MODIFIED,eval-sanitize-20-r1-056,phase=Scheduled job=None
56.0417,Job,MODIFIED,eval-sanitize-20-r1-056,
56.0454,TaskRequest,MODIFIED,eval-sanitize-20-r1-056,phase=Scheduled job=None
56.0491,Job,MODIFIED,eval-sanitize-20-r1-055,
56.0576,Job,MODIFIED,eval-sanitize-20-r1-055,
56.1073,Job,MODIFIED,eval-sanitize-20-r1-041,
56.1116,TaskRequest,MODIFIED,eval-sanitize-20-r1-041,phase=Complete job=None
56.121,Job,MODIFIED,eval-sanitize-20-r1-041,
56.1378,Pod,MODIFIED,eval-sanitize-20-r1-054-m6l4n,phase=Running node=kind-worker4
56.2058,Event,ADDED,eval-sanitize-20-r1-034.18d41aaab1a89461,reason=Completed count=1 msg=Job completed
56.2488,Job,MODIFIED,eval-sanitize-20-r1-043,
56.2578,Job,MODIFIED,eval-sanitize-20-r1-043,
56.3098,Pod,ADDED,eval-sanitize-20-r1-056-sqhx4,phase=Pending node=None
56.3121,Pod,MODIFIED,eval-sanitize-20-r1-045-zpzl7,phase=Running node=kind-worker5
56.3208,Pod,MODIFIED,eval-sanitize-20-r1-056-sqhx4,phase=Pending node=None
56.3211,Event,ADDED,eval-sanitize-20-r1-056-sqhx4.18d41aab29bf794e,"reason=FailedScheduling count=None msg=0/6 nodes are available: 2 c_wall violated: 1 conflicting context pair(s) with node memory, 4 node(s) had untolerated taint(s). no new claims to deallocate, preemption: 0/6 nodes are available: 2 No preemption victims found for incoming pod, 4 Preemption is not helpful for scheduling."
56.3341,Event,ADDED,eval-sanitize-20-r1-056-sqhx4.18d41aab2a9edaa1,"reason=FailedScheduling count=None msg=0/6 nodes are available: 2 c_wall violated: 1 conflicting context pair(s) with node memory, 4 node(s) had untolerated taint(s). no new claims to deallocate, preemption: 0/6 nodes are available: 2 No preemption victims found for incoming pod, 4 Preemption is not helpful for scheduling."
56.3502,Event,ADDED,eval-sanitize-20-r1-021.18d41aaab4e0ae5f,reason=Completed count=1 msg=Job completed
56.5048,Event,ADDED,eval-sanitize-20-r1-035.18d41aaac3a16810,reason=Completed count=1 msg=Job completed
56.5557,Job,MODIFIED,eval-sanitize-20-r1-042,
56.5605,TaskRequest,MODIFIED,eval-sanitize-20-r1-042,phase=Complete job=None
56.5691,Job,MODIFIED,eval-sanitize-20-r1-042,
56.6115,Event,ADDED,eval-sanitize-20-r1-054.18d41aaacf99c3e4,reason=SuccessfulCreate count=1 msg=Created pod: eval-sanitize-20-r1-054-m6l4n
56.6707,Event,ADDED,eval-sanitize-20-r1-037.18d41aaae460bed0,reason=Completed count=1 msg=Job completed
56.7138,Event,ADDED,eval-sanitize-20-r1-023.18d41aaaeabb4ec3,reason=Completed count=1 msg=Job completed
56.7583,Event,ADDED,eval-sanitize-20-r1-038.18d41aaaf686f87c,reason=Completed count=1 msg=Job completed
56.804,Job,MODIFIED,eval-sanitize-20-r1-044,
56.8134,Job,MODIFIED,eval-sanitize-20-r1-044,
56.8488,Event,ADDED,eval-sanitize-20-r1-040.18d41aaafc780a93,reason=Completed count=1 msg=Job completed
56.8985,Event,ADDED,eval-sanitize-20-r1-055.18d41aab080a5b2c,reason=SuccessfulCreate count=1 msg=Created pod: eval-sanitize-20-r1-055-bzm98
56.9186,Pod,MODIFIED,eval-sanitize-20-r1-044-7jzzf,phase=Succeeded node=kind-worker
56.9349,Event,MODIFIED,eval-sanitize-20-r1-056-sqhx4.18d41aab2a9edaa1,"reason=FailedScheduling count=None msg=0/6 nodes are available: 2 c_wall violated: 1 conflicting context pair(s) with node memory, 4 node(s) had untolerated taint(s). no new claims to deallocate, preemption: 0/6 nodes are available: 2 No preemption victims found for incoming pod, 4 Preemption is not helpful for scheduling."
56.9479,Event,ADDED,eval-sanitize-20-r1-039.18d41aab10e8c785,reason=Completed count=1 msg=Job completed
56.9994,Event,ADDED,eval-sanitize-20-r1-041.18d41aab1d485de0,reason=Completed count=1 msg=Job completed
57.0055,TaskRequest,ADDED,eval-sanitize-20-r1-057,phase=None job=None
57.0105,TaskRequest,MODIFIED,eval-sanitize-20-r1-057,phase=Pending job=None
57.024,Job,ADDED,eval-sanitize-20-r1-057,
57.0291,TaskRequest,MODIFIED,eval-sanitize-20-r1-057,phase=Scheduled job=None
57.0322,Job,MODIFIED,eval-sanitize-20-r1-057,
57.0355,TaskRequest,MODIFIED,eval-sanitize-20-r1-057,phase=Scheduled job=None
57.0486,Job,MODIFIED,eval-sanitize-20-r1-043,
57.0522,TaskRequest,MODIFIED,eval-sanitize-20-r1-043,phase=Complete job=None
57.0609,Job,MODIFIED,eval-sanitize-20-r1-043,
57.1085,Event,ADDED,eval-sanitize-20-r1-056.18d41aab295e812a,reason=SuccessfulCreate count=1 msg=Created pod: eval-sanitize-20-r1-056-sqhx4
57.1545,Pod,MODIFIED,eval-sanitize-20-r1-046-mlxd2,phase=Running node=kind-worker4
57.1553,Pod,ADDED,eval-sanitize-20-r1-057-rkz4v,phase=Pending node=None
57.1722,Pod,MODIFIED,eval-sanitize-20-r1-057-rkz4v,phase=Pending node=kind-worker2
57.1778,Pod,MODIFIED,eval-sanitize-20-r1-056-sqhx4,phase=Pending node=None
57.179,Event,ADDED,eval-sanitize-20-r1-057-rkz4v.18d41aab5cc34f01,reason=Scheduled count=None msg=Successfully assigned compute/eval-sanitize-20-r1-057-rkz4v to kind-worker2
57.1838,Node,MODIFIED,kind-worker2,taints=0
57.1853,Pod,MODIFIED,eval-sanitize-20-r1-057-rkz4v,phase=Pending node=kind-worker2
57.1938,Node,MODIFIED,kind-worker2,taints=1
57.1993,Job,MODIFIED,eval-sanitize-20-r1-056,
57.2025,Node,MODIFIED,kind-worker2,taints=1
57.2078,Job,MODIFIED,eval-sanitize-20-r1-056,
57.2131,Pod,MODIFIED,eval-sanitize-20-r1-055-bzm98,phase=Pending node=None
57.221,Pod,MODIFIED,eval-sanitize-20-r1-056-sqhx4,phase=Pending node=None
57.2213,Event,ADDED,eval-sanitize-20-r1-056-sqhx4.18d41aab5f696e80,"reason=FailedScheduling count=None msg=0/6 nodes are available: 1 c_wall violated: 1 conflicting context pair(s) with node memory, 5 node(s) had untolerated taint(s). no new claims to deallocate, preemption: 0/6 nodes are available: 1 No preemption victims found for incoming pod, 5 Preemption is not helpful for scheduling."
57.2285,Pod,MODIFIED,eval-sanitize-20-r1-055-bzm98,phase=Pending node=None
57.2292,Event,ADDED,eval-sanitize-20-r1-055-bzm98.18d41aab5fdcc691,"reason=FailedScheduling count=None msg=0/6 nodes are available: 1 c_wall violated: 1 conflicting context pair(s) with node memory, 5 node(s) had untolerated taint(s). no new claims to deallocate, preemption: 0/6 nodes are available: 1 No preemption victims found for incoming pod, 5 Preemption is not helpful for scheduling."
57.2366,Event,ADDED,eval-sanitize-20-r1-056-sqhx4.18d41aab606b2c56,"reason=FailedScheduling count=None msg=0/6 nodes are available: 1 c_wall violated: 1 conflicting context pair(s) with node memory, 5 node(s) had untolerated taint(s). no new claims to deallocate, preemption: 0/6 nodes are available: 1 No preemption victims found for incoming pod, 5 Preemption is not helpful for scheduling."
57.2391,Event,ADDED,eval-sanitize-20-r1-055-bzm98.18d41aab609283a9,"reason=FailedScheduling count=None msg=0/6 nodes are available: 1 c_wall violated: 1 conflicting context pair(s) with node memory, 5 node(s) had untolerated taint(s). no new claims to deallocate, preemption: 0/6 nodes are available: 1 No preemption victims found for incoming pod, 5 Preemption is not helpful for scheduling."
57.2498,Event,ADDED,eval-sanitize-20-r1-042.18d41aab38047965,reason=Completed count=1 msg=Job completed
57.309,Job,MODIFIED,eval-sanitize-20-r1-054,
57.3171,Node,MODIFIED,kind-worker2,taints=1
57.3186,Job,MODIFIED,eval-sanitize-20-r1-054,
57.3259,Event,MODIFIED,eval-sanitize-20-r1-056-sqhx4.18d41aab606b2c56,"reason=FailedScheduling count=None msg=0/6 nodes are available: 1 c_wall violated: 1 conflicting context pair(s) with node memory, 5 node(s) had untolerated taint(s). no new claims to deallocate, preemption: 0/6 nodes are available: 1 No preemption victims found for incoming pod, 5 Preemption is not helpful for scheduling."
57.3289,Event,MODIFIED,eval-sanitize-20-r1-055-bzm98.18d41aab609283a9,"reason=FailedScheduling count=None msg=0/6 nodes are available: 1 c_wall violated: 1 conflicting context pair(s) with node memory, 5 node(s) had untolerated taint(s). no new claims to deallocate, preemption: 0/6 nodes are available: 1 No preemption victims found for incoming pod, 5 Preemption is not helpful for scheduling."
57.3995,Event,ADDED,eval-sanitize-20-r1-043.18d41aab5568963c,reason=Completed count=1 msg=Job completed
57.4654,Job,MODIFIED,eval-sanitize-20-r1-045,
57.4687,Node,MODIFIED,kind-worker5,taints=1
57.4738,Pod,MODIFIED,eval-sanitize-20-r1-045-zpzl7,phase=Succeeded node=kind-worker5
57.4754,Pod,MODIFIED,eval-sanitize-20-r1-056-sqhx4,phase=Pending node=None
57.4775,Job,MODIFIED,eval-sanitize-20-r1-045,
57.4801,Pod,MODIFIED,eval-sanitize-20-r1-055-bzm98,phase=Pending node=None
57.4836,Node,MODIFIED,kind-worker5,taints=1
57.4984,Event,ADDED,eval-sanitize-20-r1-057.18d41aab5bb44f43,reason=SuccessfulCreate count=1 msg=Created pod: eval-sanitize-20-r1-057-rkz4v
57.6117,Event,ADDED,eval-sanitize-20-r1-057-rkz4v.18d41aab76afad54,"reason=Pulled count=1 msg=Container image ""busybox:musl"" already present on machine"
57.6336,Event,ADDED,eval-sanitize-20-r1-057-rkz4v.18d41aab780b7494,reason=Created count=1 msg=Created container: task
57.6975,Event,ADDED,eval-sanitize-20-r1-057-rkz4v.18d41aab7bc9348a,reason=Started count=1 msg=Started container task
57.8163,Job,MODIFIED,eval-sanitize-20-r1-044,
57.8247,Pod,MODIFIED,eval-sanitize-20-r1-044-7jzzf,phase=Succeeded node=kind-worker
57.8261,Job,MODIFIED,eval-sanitize-20-r1-044,
58.015,TaskRequest,ADDED,eval-sanitize-20-r1-058,phase=None job=None
58.0206,TaskRequest,MODIFIED,eval-sanitize-20-r1-058,phase=Pending job=None
58.0346,Job,ADDED,eval-sanitize-20-r1-058,
58.0373,Job,MODIFIED,eval-sanitize-20-r1-057,
58.0407,Pod,ADDED,eval-sanitize-20-r1-058-d9b2t,phase=Pending node=None
58.0412,TaskRequest,MODIFIED,eval-sanitize-20-r1-058,phase=Scheduled job=None
58.044,Job,MODIFIED,eval-sanitize-20-r1-058,
58.0473,Event,ADDED,eval-sanitize-20-r1-058.18d41aab908ddf1d,reason=SuccessfulCreate count=1 msg=Created pod: eval-sanitize-20-r1-058-d9b2t
58.0477,Event,ADDED,eval-sanitize-20-r1-058-d9b2t.18d41aab90995349,"reason=FailedScheduling count=None msg=0/6 nodes are available: 6 node(s) had untolerated taint(s). no new claims to deallocate, preemption: 0/6 nodes are available: 6 Preemption is not helpful for scheduling."
58.0486,Pod,MODIFIED,eval-sanitize-20-r1-058-d9b2t,phase=Pending node=None
58.0494,TaskRequest,MODIFIED,eval-sanitize-20-r1-058,phase=Scheduled job=None
58.0521,Job,MODIFIED,eval-sanitize-20-r1-057,
58.1453,Pod,MODIFIED,eval-sanitize-20-r1-047-sffms,phase=Running node=kind-worker4
58.1616,Job,MODIFIED,eval-sanitize-20-r1-046,
58.1711,Job,MODIFIED,eval-sanitize-20-r1-046,
58.227,Pod,MODIFIED,eval-sanitize-20-r1-057-rkz4v,phase=Running node=kind-worker2
58.2768,Pod,MODIFIED,eval-sanitize-20-r1-046-mlxd2,phase=Succeeded node=kind-worker4
58.4794,Job,MODIFIED,eval-sanitize-20-r1-045,
58.4885,Pod,MODIFIED,eval-sanitize-20-r1-045-zpzl7,phase=Succeeded node=kind-worker5
58.4893,Job,MODIFIED,eval-sanitize-20-r1-045,
58.8224,Job,MODIFIED,eval-sanitize-20-r1-044,
58.8266,Job,MODIFIED,eval-sanitize-20-r1-044,
58.8317,Event,ADDED,eval-sanitize-20-r1-044.18d41aabbf640dfb,reason=Completed count=1 msg=Job completed
58.838,Job,MODIFIED,eval-sanitize-20-r1-044,
58.8444,TaskRequest,MODIFIED,eval-sanitize-20-r1-044,phase=Complete job=None
58.8545,Job,MODIFIED,eval-sanitize-20-r1-044,
59.024,TaskRequest,ADDED,eval-sanitize-20-r1-059,phase=None job=None
59.0282,TaskRequest,MODIFIED,eval-sanitize-20-r1-059,phase=Pending job=None
59.0433,Job,MODIFIED,eval-sanitize-20-r1-057,
59.0446,Job,ADDED,eval-sanitize-20-r1-059,
59.0468,Job,MODIFIED,eval-sanitize-20-r1-058,
59.0522,TaskRequest,MODIFIED,eval-sanitize-20-r1-059,phase=Scheduled job=None
59.0531,Pod,ADDED,eval-sanitize-20-r1-059-vz4jf,phase=Pending node=None
59.0581,Job,MODIFIED,eval-sanitize-20-r1-059,
59.0595,Event,ADDED,eval-sanitize-20-r1-059-vz4jf.18d41aabcced1440,"reason=FailedScheduling count=None msg=0/6 nodes are available: 6 node(s) had untolerated taint(s). no new claims to deallocate, preemption: 0/6 nodes are available: 6 Preemption is not helpful for scheduling."
59.06,Event,ADDED,eval-sanitize-20-r1-059.18d41aabccddf256,reason=SuccessfulCreate count=1 msg=Created pod: eval-sanitize-20-r1-059-vz4jf
59.0609,Pod,MODIFIED,eval-sanitize-20-r1-059-vz4jf,phase=Pending node=None
59.0611,TaskRequest,MODIFIED,eval-sanitize-20-r1-059,phase=Scheduled job=None
59.0639,Job,MODIFIED,eval-sanitize-20-r1-057,
59.0659,Job,MODIFIED,eval-sanitize-20-r1-058,
59.1523,Pod,MODIFIED,eval-sanitize-20-r1-048-6wbxl,phase=Running node=kind-worker4
59.1532,Job,MODIFIED,eval-sanitize-20-r1-047,
59.1634,Job,MODIFIED,eval-sanitize-20-r1-047,
59.1687,Job,MODIFIED,eval-sanitize-20-r1-046,
59.1782,Pod,MODIFIED,eval-sanitize-20-r1-046-mlxd2,phase=Succeeded node=kind-worker4
59.1796,Job,MODIFIED,eval-sanitize-20-r1-046,
59.2903,Pod,MODIFIED,eval-sanitize-20-r1-047-sffms,phase=Succeeded node=kind-worker4
59.4856,Job,MODIFIED,eval-sanitize-20-r1-045,
59.4902,Job,MODIFIED,eval-sanitize-20-r1-045,
59.4931,Event,ADDED,eval-sanitize-20-r1-045.18d41aabe6ee3407,reason=Completed count=1 msg=Job completed
59.5036,Job,MODIFIED,eval-sanitize-20-r1-045,
59.5094,TaskRequest,MODIFIED,eval-sanitize-20-r1-045,phase=Complete job=None
59.5185,Job,MODIFIED,eval-sanitize-20-r1-045,
60.0105,TaskRequest,ADDED,eval-sanitize-20-r1-060,phase=None job=None
60.0173,TaskRequest,MODIFIED,eval-sanitize-20-r1-060,phase=Pending job=None
60.021,Pod,ADDED,eval-sanitize-20-r1-000-4gvxt,phase=Succeeded node=kind-worker3
60.0237,Node,ADDED,kind-control-plane,taints=1
60.0238,TaskRequest,ADDED,eval-sanitize-20-r1-000,phase=Complete job=None
60.0239,TaskRequest,ADDED,eval-sanitize-20-r1-001,phase=Complete job=None
60.024,TaskRequest,ADDED,eval-sanitize-20-r1-002,phase=Complete job=None
60.0253,Pod,ADDED,eval-sanitize-20-r1-001-fhsgn,phase=Succeeded node=kind-worker5
60.0257,Event,ADDED,eval-sanitize-20-r1-000-4gvxt.18d41a9e12171fc1,reason=Scheduled count=None msg=Successfully assigned compute/eval-sanitize-20-r1-000-4gvxt to kind-worker3
60.0267,Job,ADDED,eval-sanitize-20-r1-000,
60.0268,TaskRequest,ADDED,eval-sanitize-20-r1-003,phase=Complete job=None
60.0269,TaskRequest,ADDED,eval-sanitize-20-r1-004,phase=Complete job=None
60.0269,TaskRequest,ADDED,eval-sanitize-20-r1-005,phase=Complete job=None
60.0285,Node,ADDED,kind-worker,taints=1
60.0288,Event,ADDED,eval-sanitize-20-r1-000-4gvxt.18d41a9e2b1eeb84,"reason=Pulled count=1 msg=Container image ""busybox:musl"" already present on machine"
60.0291,Event,ADDED,eval-sanitize-20-r1-000-4gvxt.18d41a9e2c30f8c3,reason=Created count=1 msg=Created container: task
60.0293,Event,ADDED,eval-sanitize-20-r1-000-4gvxt.18d41a9e2e9b2f4c,reason=Started count=1 msg=Started container task
60.0295,Event,ADDED,eval-sanitize-20-r1-000.18d41a9e113b7a80,reason=SuccessfulCreate count=1 msg=Created pod: eval-sanitize-20-r1-000-4gvxt
60.0298,Event,ADDED,eval-sanitize-20-r1-000.18d41aa1721aba2f,reason=Completed count=1 msg=Job completed
60.03,Event,ADDED,eval-sanitize-20-r1-001-fhsgn.18d41a9e4c0aef4c,reason=Scheduled count=None msg=Successfully assigned compute/eval-sanitize-20-r1-001-fhsgn to kind-worker5
60.0302,Event,ADDED,eval-sanitize-20-r1-001-fhsgn.18d41a9e66777406,"reason=Pulled count=1 msg=Container image ""busybox:musl"" already present on machine"
60.0304,Event,ADDED,eval-sanitize-20-r1-001-fhsgn.18d41a9e67882f9a,reason=Created count=1 msg=Created container: task
60.0316,Pod,ADDED,eval-sanitize-20-r1-002-v2wms,phase=Succeeded node=kind-worker
60.0328,Node,ADDED,kind-worker2,taints=1
60.0335,Job,ADDED,eval-sanitize-20-r1-001,
60.0338,Event,ADDED,eval-sanitize-20-r1-001-fhsgn.18d41a9e699e6339,reason=Started count=1 msg=Started container task
60.034,Event,ADDED,eval-sanitize-20-r1-001.18d41a9e4b0431a5,reason=SuccessfulCreate count=1 msg=Created pod: eval-sanitize-20-r1-001-fhsgn
60.0342,Event,ADDED,eval-sanitize-20-r1-001.18d41aa1982c791d,reason=Completed count=1 msg=Job completed
60.0354,Pod,ADDED,eval-sanitize-20-r1-003-q9fhf,phase=Succeeded node=kind-worker3
60.0364,Pod,ADDED,eval-sanitize-20-r1-004-tf9vj,phase=Succeeded node=kind-worker5
60.0378,Job,ADDED,eval-sanitize-20-r1-002,
60.0381,Event,ADDED,eval-sanitize-20-r1-002-v2wms.18d41a9e888f1e21,reason=Scheduled count=None msg=Successfully assigned compute/eval-sanitize-20-r1-002-v2wms to kind-worker
60.0383,Event,ADDED,eval-sanitize-20-r1-002-v2wms.18d41a9ea15647b3,"reason=Pulled count=1 msg=Container image ""busybox:musl"" already present on machine"
60.0385,Event,ADDED,eval-sanitize-20-r1-002-v2wms.18d41a9ea266d2ce,reason=Created count=1 msg=Created container: task
60.0387,Event,ADDED,eval-sanitize-20-r1-002-v2wms.18d41a9ea6533c73,reason=Started count=1 msg=Started container task
60.0388,TaskRequest,ADDED,eval-sanitize-20-r1-006,phase=Complete job=None
60.0389,TaskRequest,ADDED,eval-sanitize-20-r1-007,phase=Complete job=None
60.0389,TaskRequest,ADDED,eval-sanitize-20-r1-008,phase=Complete job=None
60.0404,Node,ADDED,kind-worker3,taints=1
60.0417,Pod,ADDED,eval-sanitize-20-r1-005-hcgjl,phase=Succeeded node=kind-worker3
60.043,Pod,ADDED,eval-sanitize-20-r1-006-bzlm5,phase=Succeeded node=kind-worker4
60.0431,TaskRequest,ADDED,eval-sanitize-20-r1-009,phase=Complete job=None
60.0431,TaskRequest,ADDED,eval-sanitize-20-r1-010,phase=Complete job=None
60.0432,TaskRequest,ADDED,eval-sanitize-20-r1-011,phase=Complete job=None
60.0432,TaskRequest,ADDED,eval-sanitize-20-r1-012,phase=Complete job=None
60.0432,TaskRequest,ADDED,eval-sanitize-20-r1-013,phase=Complete job=None
60.0441,Job,ADDED,eval-sanitize-20-r1-003,
60.0456,Node,ADDED,kind-worker4,taints=1
60.0456,TaskRequest,ADDED,eval-sanitize-20-r1-014,phase=Complete job=None
60.0457,TaskRequest,ADDED,eval-sanitize-20-r1-015,phase=Complete job=None
60.0458,TaskRequest,ADDED,eval-sanitize-20-r1-016,phase=Complete job=None
60.048,Job,ADDED,eval-sanitize-20-r1-004,
60.0485,Event,ADDED,eval-sanitize-20-r1-002.18d41a9e87921497,reason=SuccessfulCreate count=1 msg=Created pod: eval-sanitize-20-r1-002-v2wms
60.0487,Event,ADDED,eval-sanitize-20-r1-002.18d41aa1eba5953b,reason=Completed count=1 msg=Job completed
60.0489,Event,ADDED,eval-sanitize-20-r1-003-q9fhf.18d41a9ec4068e7b,reason=Scheduled count=None msg=Successfully assigned compute/eval-sanitize-20-r1-003-q9fhf to kind-worker3
60.0491,Event,ADDED,eval-sanitize-20-r1-003-q9fhf.18d41a9edf1162ac,"reason=Pulled count=1 msg=Container image ""busybox:musl"" already present on machine"
60.0503,Pod,ADDED,eval-sanitize-20-r1-007-5jj5w,phase=Succeeded node=kind-worker2
60.052,Node,ADDED,kind-worker5,taints=1
60.0524,Event,ADDED,eval-sanitize-20-r1-003-q9fhf.18d41a9ee02b0980,reason=Created count=1 msg=Created container: task
60.0526,Event,ADDED,eval-sanitize-20-r1-003-q9fhf.18d41a9ee2c8c3fc,reason=Started count=1 msg=Started container task
60.0528,Event,ADDED,eval-sanitize-20-r1-003.18d41a9ec2cb0f83,reason=SuccessfulCreate count=1 msg=Created pod: eval-sanitize-20-r1-003-q9fhf
60.0539,Pod,ADDED,eval-sanitize-20-r1-008-vx6kf,phase=Succeeded node=kind-worker5
60.054,TaskRequest,ADDED,eval-sanitize-20-r1-017,phase=Complete job=None
60.0541,TaskRequest,ADDED,eval-sanitize-20-r1-018,phase=Complete job=None
60.0541,TaskRequest,ADDED,eval-sanitize-20-r1-019,phase=Complete job=None
60.0542,TaskRequest,ADDED,eval-sanitize-20-r1-020,phase=Complete job=None
60.0542,TaskRequest,ADDED,eval-sanitize-20-r1-021,phase=Complete job=None
60.0551,Job,ADDED,eval-sanitize-20-r1-005,
60.0554,Event,ADDED,eval-sanitize-20-r1-003.18d41aa226d07322,reason=Completed count=1 msg=Job completed
60.0556,Event,ADDED,eval-sanitize-20-r1-004-tf9vj.18d41a9eff50964c,reason=Scheduled count=None msg=Successfully assigned compute/eval-sanitize-20-r1-004-tf9vj to kind-worker5
60.0558,Event,ADDED,eval-sanitize-20-r1-004-tf9vj.18d41a9f194a2990,"reason=Pulled count=1 msg=Container image ""busybox:musl"" already present on machine"
60.056,Event,ADDED,eval-sanitize-20-r1-004-tf9vj.18d41a9f1a621cb7,reason=Created count=1 msg=Created container: task
60.0562,Event,ADDED,eval-sanitize-20-r1-004-tf9vj.18d41a9f1cc041b7,reason=Started count=1 msg=Started container task
60.0564,Event,ADDED,eval-sanitize-20-r1-004.18d41a9efe2ce9e3,reason=SuccessfulCreate count=1 msg=Created pod: eval-sanitize-20-r1-004-tf9vj
60.0566,Event,ADDED,eval-sanitize-20-r1-004.18d41aa24ba72ca8,reason=Completed count=1 msg=Job completed
60.0569,Event,ADDED,eval-sanitize-20-r1-005-hcgjl.18d41a9f3ab91fa8,reason=Scheduled count=None msg=Successfully assigned compute/eval-sanitize-20-r1-005-hcgjl to kind-worker3
60.057,TaskRequest,ADDED,eval-sanitize-20-r1-022,phase=Complete job=None
60.057,TaskRequest,ADDED,eval-sanitize-20-r1-023,phase=Complete job=None
60.0584,Pod,ADDED,eval-sanitize-20-r1-009-wrws4,phase=Succeeded node=kind-worker
60.0588,Event,ADDED,eval-sanitize-20-r1-005-hcgjl.18d41a9f53f1f632,"reason=Pulled count=1 msg=Container image ""busybox:musl"" already present on machine"
60.0591,Event,ADDED,eval-sanitize-20-r1-005-hcgjl.18d41a9f54fad805,reason=Created count=1 msg=Created container: task
60.0593,Event,ADDED,eval-sanitize-20-r1-005-hcgjl.18d41a9f570456ab,reason=Started count=1 msg=Started container task
60.0596,Event,ADDED,eval-sanitize-20-r1-005.18d41a9f39734aca,reason=SuccessfulCreate count=1 msg=Created pod: eval-sanitize-20-r1-005-hcgjl
60.0598,Event,ADDED,eval-sanitize-20-r1-005.18d41aa22779454b,reason=Completed count=1 msg=Job completed
60.0599,Event,ADDED,eval-sanitize-20-r1-006-bzlm5.18d41a9f77328ba6,reason=Scheduled count=None msg=Successfully assigned compute/eval-sanitize-20-r1-006-bzlm5 to kind-worker4
60.0601,Event,ADDED,eval-sanitize-20-r1-006-bzlm5.18d41a9f90a58792,"reason=Pulled count=1 msg=Container image ""busybox:musl"" already present on machine"
60.0603,TaskRequest,ADDED,eval-sanitize-20-r1-024,phase=Complete job=None
60.0603,TaskRequest,ADDED,eval-sanitize-20-r1-025,phase=Complete job=None
60.0603,TaskRequest,ADDED,eval-sanitize-20-r1-026,phase=Complete job=None
60.0619,Pod,ADDED,eval-sanitize-20-r1-010-qvrjj,phase=Succeeded node=kind-worker
60.0635,Job,ADDED,eval-sanitize-20-r1-006,
60.0638,Event,ADDED,eval-sanitize-20-r1-006-bzlm5.18d41a9f91d56836,reason=Created count=1 msg=Created container: task
60.064,Event,ADDED,eval-sanitize-20-r1-006-bzlm5.18d41a9f94c04680,reason=Started count=1 msg=Started container task
60.0642,Event,ADDED,eval-sanitize-20-r1-006.18d41a9f75f68b92,reason=SuccessfulCreate count=1 msg=Created pod: eval-sanitize-20-r1-006-bzlm5
60.0644,Event,ADDED,eval-sanitize-20-r1-006.18d41aa2b847de52,reason=Completed count=1 msg=Job completed
60.0645,TaskRequest,ADDED,eval-sanitize-20-r1-027,phase=Complete job=None
60.0645,TaskRequest,ADDED,eval-sanitize-20-r1-028,phase=Complete job=None
60.0645,TaskRequest,ADDED,eval-sanitize-20-r1-029,phase=Complete job=None
60.065,Event,ADDED,eval-sanitize-20-r1-007-5jj5w.18d41a9fb569d83f,reason=Scheduled count=None msg=Successfully assigned compute/eval-sanitize-20-r1-007-5jj5w to kind-worker2
60.0652,Event,ADDED,eval-sanitize-20-r1-007-5jj5w.18d41a9fce7689d9,"reason=Pulled count=1 msg=Container image ""busybox:musl"" already present on machine"
60.0654,Event,ADDED,eval-sanitize-20-r1-007-5jj5w.18d41a9fcf8cb31e,reason=Created count=1 msg=Created container: task
60.0655,TaskRequest,ADDED,eval-sanitize-20-r1-030,phase=Complete job=None
60.0655,TaskRequest,ADDED,eval-sanitize-20-r1-031,phase=Complete job=None
60.0671,Pod,ADDED,eval-sanitize-20-r1-011-hkzpx,phase=Succeeded node=kind-worker4
60.0683,Pod,ADDED,eval-sanitize-20-r1-012-m6skw,phase=Succeeded node=kind-worker
60.0686,Event,ADDED,eval-sanitize-20-r1-007-5jj5w.18d41a9fd2275bf2,reason=Started count=1 msg=Started container task
60.0688,Event,ADDED,eval-sanitize-20-r1-007.18d41a9fb0cb7156,reason=SuccessfulCreate count=1 msg=Created pod: eval-sanitize-20-r1-007-5jj5w
60.069,Event,ADDED,eval-sanitize-20-r1-007.18d41aa2fa1df424,reason=Completed count=1 msg=Job completed
60.0692,Event,ADDED,eval-sanitize-20-r1-008-vx6kf.18d41a9ff0788cc3,reason=Scheduled count=None msg=Successfully assigned compute/eval-sanitize-20-r1-008-vx6kf to kind-worker5
60.0693,TaskRequest,ADDED,eval-sanitize-20-r1-032,phase=Complete job=None
60.0693,TaskRequest,ADDED,eval-sanitize-20-r1-033,phase=Complete job=None
60.0694,TaskRequest,ADDED,eval-sanitize-20-r1-034,phase=Complete job=None
60.0706,Event,ADDED,eval-sanitize-20-r1-008-vx6kf.18d41aa00a296aa9,"reason=Pulled count=1 msg=Container image ""busybox:musl"" already present on machine"
60.0708,Event,ADDED,eval-sanitize-20-r1-008-vx6kf.18d41aa00b41bae2,reason=Created count=1 msg=Created container: task
60.071,Event,ADDED,eval-sanitize-20-r1-008-vx6kf.18d41aa00f6046de,reason=Started count=1 msg=Started container task
60.0712,Event,ADDED,eval-sanitize-20-r1-008.18d41a9febe9a4f5,reason=SuccessfulCreate count=1 msg=Created pod: eval-sanitize-20-r1-008-vx6kf
60.0713,TaskRequest,ADDED,eval-sanitize-20-r1-035,phase=Complete job=None
60.0713,TaskRequest,ADDED,eval-sanitize-20-r1-036,phase=Complete job=None
60.0721,Job,ADDED,eval-sanitize-20-r1-007,
60.0732,Pod,ADDED,eval-sanitize-20-r1-013-9wf2v,phase=Succeeded node=kind-worker3
60.0746,Pod,ADDED,eval-sanitize-20-r1-014-f5l6t,phase=Succeeded node=kind-worker5
60.0747,TaskRequest,ADDED,eval-sanitize-20-r1-037,phase=Complete job=None
60.0747,TaskRequest,ADDED,eval-sanitize-20-r1-038,phase=Complete job=None
60.0748,TaskRequest,ADDED,eval-sanitize-20-r1-039,phase=Complete job=None
60.0756,Job,ADDED,eval-sanitize-20-r1-008,
60.0759,Event,ADDED,eval-sanitize-20-r1-008.18d41aa33ab0c46d,reason=Completed count=1 msg=Job completed
60.0761,Event,ADDED,eval-sanitize-20-r1-009-wrws4.18d41aa02c4f60a8,reason=Scheduled count=None msg=Successfully assigned compute/eval-sanitize-20-r1-009-wrws4 to kind-worker
60.0764,Event,ADDED,eval-sanitize-20-r1-009-wrws4.18d41aa0461e638b,"reason=Pulled count=1 msg=Container image ""busybox:musl"" already present on machine"
60.0766,TaskRequest,ADDED,eval-sanitize-20-r1-040,phase=Complete job=None
60.0767,TaskRequest,ADDED,eval-sanitize-20-r1-041,phase=Complete job=None
60.0768,TaskRequest,ADDED,eval-sanitize-20-r1-042,phase=Complete job=None
60.0777,Job,ADDED,eval-sanitize-20-r1-009,
60.0778,TaskRequest,ADDED,eval-sanitize-20-r1-043,phase=Complete job=None
60.0778,TaskRequest,ADDED,eval-sanitize-20-r1-044,phase=Complete job=None
60.0781,Event,ADDED,eval-sanitize-20-r1-009-wrws4.18d41aa04742a58e,reason=Created count=1 msg=Created container: task
60.0783,Event,ADDED,eval-sanitize-20-r1-009-wrws4.18d41aa049b5dfd5,reason=Started count=1 msg=Started container task
60.0785,Event,ADDED,eval-sanitize-20-r1-009.18d41aa027726a79,reason=SuccessfulCreate count=1 msg=Created pod: eval-sanitize-20-r1-009-wrws4
60.0787,Event,ADDED,eval-sanitize-20-r1-009.18d41aa38e5cde1d,reason=Completed count=1 msg=Job completed
60.0798,Pod,ADDED,eval-sanitize-20-r1-015-tkjff,phase=Succeeded node=kind-worker2
60.0805,Job,ADDED,eval-sanitize-20-r1-010,
60.0819,Pod,ADDED,eval-sanitize-20-r1-016-rhx4s,phase=Succeeded node=kind-worker
60.0828,Job,ADDED,eval-sanitize-20-r1-011,
60.0837,Job,ADDED,eval-sanitize-20-r1-012,
60.0839,Event,ADDED,eval-sanitize-20-r1-010-qvrjj.18d41aa0681ae48e,reason=Scheduled count=None msg=Successfully assigned compute/eval-sanitize-20-r1-010-qvrjj to kind-worker
60.0841,Event,ADDED,eval-sanitize-20-r1-010-qvrjj.18d41aa080dbb854,"reason=Pulled count=1 msg=Container image ""busybox:musl"" already present on machine"
60.0843,Event,ADDED,eval-sanitize-20-r1-010-qvrjj.18d41aa081e6a640,reason=Created count=1 msg=Created container: task
60.0845,Event,ADDED,eval-sanitize-20-r1-010-qvrjj.18d41aa0841714b2,reason=Started count=1 msg=Started container task
60.0846,TaskRequest,ADDED,eval-sanitize-20-r1-045,phase=Complete job=None
60.0846,TaskRequest,ADDED,eval-sanitize-20-r1-046,phase=Scheduled job=None
60.0846,TaskRequest,ADDED,eval-sanitize-20-r1-047,phase=Scheduled job=None
60.0858,Pod,ADDED,eval-sanitize-20-r1-017-82hwg,phase=Succeeded node=kind-worker5
60.087,Pod,ADDED,eval-sanitize-20-r1-018-tml46,phase=Succeeded node=kind-worker
60.0871,TaskRequest,ADDED,eval-sanitize-20-r1-048,phase=Scheduled job=None
60.0872,TaskRequest,ADDED,eval-sanitize-20-r1-049,phase=Scheduled job=None
60.0872,TaskRequest,ADDED,eval-sanitize-20-r1-050,phase=Scheduled job=None
60.0876,Event,ADDED,eval-sanitize-20-r1-010.18d41aa0637fe086,reason=SuccessfulCreate count=1 msg=Created pod: eval-sanitize-20-r1-010-qvrjj
60.0878,Event,ADDED,eval-sanitize-20-r1-010.18d41aa3ca386bd5,reason=Completed count=1 msg=Job completed
60.088,Event,ADDED,eval-sanitize-20-r1-011-hkzpx.18d41aa0a3a65fe3,reason=Scheduled count=None msg=Successfully assigned compute/eval-sanitize-20-r1-011-hkzpx to kind-worker4
60.0887,Job,ADDED,eval-sanitize-20-r1-013,
60.0895,Job,ADDED,eval-sanitize-20-r1-014,
60.0898,Event,ADDED,eval-sanitize-20-r1-011-hkzpx.18d41aa0bc6b664f,"reason=Pulled count=1 msg=Container image ""busybox:musl"" already present on machine"
60.09,Event,ADDED,eval-sanitize-20-r1-011-hkzpx.18d41aa0bda63e23,reason=Created count=1 msg=Created container: task
60.0902,Event,ADDED,eval-sanitize-20-r1-011-hkzpx.18d41aa0c366c136,reason=Started count=1 msg=Started container task
60.0904,Event,ADDED,eval-sanitize-20-r1-011.18d41aa09f402150,reason=SuccessfulCreate count=1 msg=Created pod: eval-sanitize-20-r1-011-hkzpx
60.0916,Pod,ADDED,eval-sanitize-20-r1-019-dl74d,phase=Succeeded node=kind-worker3
60.0917,TaskRequest,ADDED,eval-sanitize-20-r1-051,phase=Scheduled job=None
60.0918,TaskRequest,ADDED,eval-sanitize-20-r1-052,phase=Scheduled job=None
60.0918,TaskRequest,ADDED,eval-sanitize-20-r1-053,phase=Scheduled job=None
60.0918,TaskRequest,ADDED,eval-sanitize-20-r1-054,phase=Scheduled job=None
60.0919,TaskRequest,ADDED,eval-sanitize-20-r1-055,phase=Scheduled job=None
60.0919,TaskRequest,ADDED,eval-sanitize-20-r1-056,phase=Scheduled job=None
60.0919,TaskRequest,ADDED,eval-sanitize-20-r1-057,phase=Scheduled job=None
60.092,TaskRequest,ADDED,eval-sanitize-20-r1-058,phase=Scheduled job=None
60.0931,Pod,ADDED,eval-sanitize-20-r1-020-xv9d4,phase=Succeeded node=kind-worker4
60.0939,Job,ADDED,eval-sanitize-20-r1-015,
60.095,Job,ADDED,eval-sanitize-20-r1-016,
60.0951,TaskRequest,ADDED,eval-sanitize-20-r1-059,phase=Scheduled job=None
60.0951,TaskRequest,ADDED,eval-sanitize-20-r1-060,phase=Pending job=None
60.0954,Event,ADDED,eval-sanitize-20-r1-011.18d41aa3e31a49c1,reason=Completed count=1 msg=Job completed
60.0956,Event,ADDED,eval-sanitize-20-r1-012-m6skw.18d41aa0df3965ab,"reason=FailedScheduling count=None msg=0/6 nodes are available: 1 node(s) had untolerated taint(s), 2 c_wall violated: 2 conflicting context pair(s) with node memory, 3 c_wall violated: 1 conflicting context pair(s) with node memory. no new claims to deallocate, preemption: 0/6 nodes are available: 1 Preemption is not helpful for scheduling, 5 No preemption victims found for incoming pod."
60.0958,Event,ADDED,eval-sanitize-20-r1-012-m6skw.18d41aa0e5463ab7,"reason=FailedScheduling count=None msg=0/6 nodes are available: 1 node(s) had untolerated taint(s), 2 c_wall violated: 2 conflicting context pair(s) with node memory, 3 c_wall violated: 1 conflicting context pair(s) with node memory. no new claims to deallocate, preemption: 0/6 nodes are available: 1 Preemption is not helpful for scheduling, 5 No preemption victims found for incoming pod."
60.0959,TaskRequest,MODIFIED,eval-sanitize-20-r1-060,phase=Scheduled job=None
60.0971,Pod,ADDED,eval-sanitize-20-r1-021-77dzv,phase=Succeeded node=kind-worker2
60.0974,Event,ADDED,eval-sanitize-20-r1-012-m6skw.18d41aa167dc56a0,"reason=FailedScheduling count=None msg=0/6 nodes are available: 1 c_wall violated: 2 conflicting context pair(s) with node memory, 2 node(s) had untolerated taint(s), 3 c_wall violated: 1 conflicting context pair(s) with node memory. no new claims to deallocate, preemption: 0/6 nodes are available: 2 Preemption is not helpful for scheduling, 4 No preemption victims found for incoming pod."
60.0976,Event,ADDED,eval-sanitize-20-r1-012-m6skw.18d41aa197e5e65e,"reason=FailedScheduling count=None msg=0/6 nodes are available: 1 c_wall violated: 2 conflicting context pair(s) with node memory, 2 c_wall violated: 1 conflicting context pair(s) with node memory, 3 node(s) had untolerated taint(s). no new claims to deallocate, preemption: 0/6 nodes are available: 3 No preemption victims found for incoming pod, 3 Preemption is not helpful for scheduling."
60.0978,Event,ADDED,eval-sanitize-20-r1-012-m6skw.18d41aa1b3948e66,"reason=FailedScheduling count=None msg=0/6 nodes are available: 2 c_wall violated: 1 conflicting context pair(s) with node memory, 4 node(s) had untolerated taint(s). no new claims to deallocate, preemption: 0/6 nodes are available: 2 No preemption victims found for incoming pod, 4 Preemption is not helpful for scheduling."
60.0987,Job,ADDED,eval-sanitize-20-r1-017,
60.0988,TaskRequest,MODIFIED,eval-sanitize-20-r1-060,phase=Scheduled job=None
60.0999,Pod,ADDED,eval-sanitize-20-r1-022-qr2sk,phase=Succeeded node=kind-worker3
60.1002,Event,ADDED,eval-sanitize-20-r1-012-m6skw.18d41aa200c7d429,"reason=FailedScheduling count=None msg=0/6 nodes are available: 1 c_wall violated: 1 conflicting context pair(s) with node memory, 5 node(s) had untolerated taint(s). no new claims to deallocate, preemption: 0/6 nodes are available: 1 No preemption victims found for incoming pod, 5 Preemption is not helpful for scheduling."
60.1004,Event,ADDED,eval-sanitize-20-r1-012-m6skw.18d41aa60dd2a2c8,reason=Scheduled count=None msg=Successfully assigned compute/eval-sanitize-20-r1-012-m6skw to kind-worker
60.1007,Event,ADDED,eval-sanitize-20-r1-012-m6skw.18d41aa62846d55f,"reason=Pulled count=1 msg=Container image ""busybox:musl"" already present on machine"
60.1015,Job,ADDED,eval-sanitize-20-r1-018,
60.1019,Event,ADDED,eval-sanitize-20-r1-012-m6skw.18d41aa629d221b9,reason=Created count=1 msg=Created container: task
60.1021,Event,ADDED,eval-sanitize-20-r1-012-m6skw.18d41aa62d83b95d,reason=Started count=1 msg=Started container task
60.1023,Event,ADDED,eval-sanitize-20-r1-012.18d41aa0daaa7fe0,reason=SuccessfulCreate count=1 msg=Created pod: eval-sanitize-20-r1-012-m6skw
60.1025,Event,ADDED,eval-sanitize-20-r1-012.18d41aaa286ee6f0,reason=Completed count=1 msg=Job completed
60.1027,Event,ADDED,eval-sanitize-20-r1-013-9wf2v.18d41aa11abe7e8d,reason=Scheduled count=None msg=Successfully assigned compute/eval-sanitize-20-r1-013-9wf2v to kind-worker3
60.1029,Event,ADDED,eval-sanitize-20-r1-013-9wf2v.18d41aa133c07552,"reason=Pulled count=1 msg=Container image ""busybox:musl"" already present on machine"
60.1031,Event,ADDED,eval-sanitize-20-r1-013-9wf2v.18d41aa134d230e1,reason=Created count=1 msg=Created container: task
60.1033,Event,ADDED,eval-sanitize-20-r1-013-9wf2v.18d41aa13c7d4594,reason=Started count=1 msg=Started container task
60.1035,Event,ADDED,eval-sanitize-20-r1-013.18d41aa115be3abf,reason=SuccessfulCreate count=1 msg=Created pod: eval-sanitize-20-r1-013-9wf2v
60.1037,Event,ADDED,eval-sanitize-20-r1-013.18d41aa47ba7b2d0,reason=Completed count=1 msg=Job completed
60.1039,Event,ADDED,eval-sanitize-20-r1-014-f5l6t.18d41aa15649c77d,reason=Scheduled count=None msg=Successfully assigned compute/eval-sanitize-20-r1-014-f5l6t to kind-worker5
60.1047,Job,ADDED,eval-sanitize-20-r1-019,
60.1059,Pod,ADDED,eval-sanitize-20-r1-023-lhw8g,phase=Succeeded node=kind-worker3
60.1062,Event,ADDED,eval-sanitize-20-r1-014-f5l6t.18d41aa16f598491,"reason=Pulled count=1 msg=Container image ""busybox:musl"" already present on machine"
60.1064,Event,ADDED,eval-sanitize-20-r1-014-f5l6t.18d41aa1706307f5,reason=Created count=1 msg=Created container: task
60.1066,Event,ADDED,eval-sanitize-20-r1-014-f5l6t.18d41aa178dc6a28,reason=Started count=1 msg=Started container task
60.1068,Event,ADDED,eval-sanitize-20-r1-014.18d41aa151dee847,reason=SuccessfulCreate count=1 msg=Created pod: eval-sanitize-20-r1-014-f5l6t
60.1077,Job,ADDED,eval-sanitize-20-r1-020,
60.1088,Pod,ADDED,eval-sanitize-20-r1-024-jjnk6,phase=Succeeded node=kind-worker3
60.1091,Event,ADDED,eval-sanitize-20-r1-014.18d41aa4a0f19e6f,reason=Completed count=1 msg=Job completed
60.1093,Event,ADDED,eval-sanitize-20-r1-015-tkjff.18d41aa192f5b04e,reason=Scheduled count=None msg=Successfully assigned compute/eval-sanitize-20-r1-015-tkjff to kind-worker2
60.1095,Event,ADDED,eval-sanitize-20-r1-015-tkjff.18d41aa1b2dd004f,"reason=Pulled count=1 msg=Container image ""busybox:musl"" already present on machine"
60.1103,Job,ADDED,eval-sanitize-20-r1-021,
60.1107,Event,ADDED,eval-sanitize-20-r1-015-tkjff.18d41aa1b43e8ef6,reason=Created count=1 msg=Created container: task
60.1109,Event,ADDED,eval-sanitize-20-r1-015-tkjff.18d41aa1b8952404,reason=Started count=1 msg=Started container task
60.1111,Event,ADDED,eval-sanitize-20-r1-015.18d41aa18dad2ab7,reason=SuccessfulCreate count=1 msg=Created pod: eval-sanitize-20-r1-015-tkjff
60.1113,Event,ADDED,eval-sanitize-20-r1-015.18d41aa4d8411ef6,reason=Completed count=1 msg=Job completed
60.1124,Pod,ADDED,eval-sanitize-20-r1-025-rp76f,phase=Succeeded node=kind-worker
60.1133,Job,ADDED,eval-sanitize-20-r1-022,
60.1136,Event,ADDED,eval-sanitize-20-r1-016-rhx4s.18d41aa1c94066eb,"reason=FailedScheduling count=None msg=0/6 nodes are available: 2 c_wall violated: 1 conflicting context pair(s) with node memory, 4 node(s) had untolerated taint(s). no new claims to deallocate, preemption: 0/6 nodes are available: 2 No preemption victims found for incoming pod, 4 Preemption is not helpful for scheduling."
60.1139,Event,ADDED,eval-sanitize-20-r1-016-rhx4s.18d41aa1ca08d5b7,"reason=FailedScheduling count=None msg=0/6 nodes are available: 2 c_wall violated: 1 conflicting context pair(s) with node memory, 4 node(s) had untolerated taint(s). no new claims to deallocate, preemption: 0/6 nodes are available: 2 No preemption victims found for incoming pod, 4 Preemption is not helpful for scheduling."
60.1141,Event,ADDED,eval-sanitize-20-r1-016-rhx4s.18d41aa200eb824c,"reason=FailedScheduling count=None msg=0/6 nodes are available: 1 c_wall violated: 1 conflicting context pair(s) with node memory, 5 node(s) had untolerated taint(s). no new claims to deallocate, preemption: 0/6 nodes are available: 1 No preemption victims found for incoming pod, 5 Preemption is not helpful for scheduling."
60.1166,Pod,ADDED,eval-sanitize-20-r1-026-cdlxh,phase=Succeeded node=kind-worker4
60.1173,Job,ADDED,eval-sanitize-20-r1-023,
60.1185,Pod,ADDED,eval-sanitize-20-r1-027-t6jkc,phase=Succeeded node=kind-worker
60.1187,Event,ADDED,eval-sanitize-20-r1-016-rhx4s.18d41aa60e7381ef,reason=Scheduled count=None msg=Successfully assigned compute/eval-sanitize-20-r1-016-rhx4s to kind-worker
60.119,Event,ADDED,eval-sanitize-20-r1-016-rhx4s.18d41aa62909f51b,"reason=Pulled count=1 msg=Container image ""busybox:musl"" already present on machine"
60.1192,Event,ADDED,eval-sanitize-20-r1-016-rhx4s.18d41aa62af82547,reason=Created count=1 msg=Created container: task
60.1201,Job,ADDED,eval-sanitize-20-r1-024,
60.1213,Pod,ADDED,eval-sanitize-20-r1-028-26fpq,phase=Succeeded node=kind-worker
60.1216,Event,ADDED,eval-sanitize-20-r1-016-rhx4s.18d41aa62e6fec0e,reason=Started count=1 msg=Started container task
60.1218,Event,ADDED,eval-sanitize-20-r1-016.18d41aa1c8ce0d83,reason=SuccessfulCreate count=1 msg=Created pod: eval-sanitize-20-r1-016-rhx4s
60.122,Event,ADDED,eval-sanitize-20-r1-016.18d41aa92b6c11d9,reason=Completed count=1 msg=Job completed
60.1222,Event,ADDED,eval-sanitize-20-r1-017-82hwg.18d41aa2050b5e0b,reason=Scheduled count=None msg=Successfully assigned compute/eval-sanitize-20-r1-017-82hwg to kind-worker5
60.1226,Event,ADDED,eval-sanitize-20-r1-017-82hwg.18d41aa21ec45fb1,"reason=Pulled count=1 msg=Container image ""busybox:musl"" already present on machine"
60.1228,Event,ADDED,eval-sanitize-20-r1-017-82hwg.18d41aa21ff5a321,reason=Created count=1 msg=Created container: task
60.123,Event,ADDED,eval-sanitize-20-r1-017-82hwg.18d41aa2220ec297,reason=Started count=1 msg=Started container task
60.1232,Event,ADDED,eval-sanitize-20-r1-017.18d41aa20477fe06,reason=SuccessfulCreate count=1 msg=Created pod: eval-sanitize-20-r1-017-82hwg
60.1247,Pod,ADDED,eval-sanitize-20-r1-029-cjqck,phase=Succeeded node=kind-worker
60.1255,Job,ADDED,eval-sanitize-20-r1-025,
60.1258,Event,ADDED,eval-sanitize-20-r1-017.18d41aa554ba9724,reason=Completed count=1 msg=Job completed
60.126,Event,ADDED,eval-sanitize-20-r1-018-tml46.18d41aa241282aa5,"reason=FailedScheduling count=None msg=0/6 nodes are available: 6 node(s) had untolerated taint(s). no new claims to deallocate, preemption: 0/6 nodes are available: 6 Preemption is not helpful for scheduling."
60.1262,Event,ADDED,eval-sanitize-20-r1-018-tml46.18d41aa60edb3ebc,reason=Scheduled count=None msg=Successfully assigned compute/eval-sanitize-20-r1-018-tml46 to kind-worker
60.1273,Pod,ADDED,eval-sanitize-20-r1-030-8p8k8,phase=Succeeded node=kind-worker
60.1281,Job,ADDED,eval-sanitize-20-r1-026,
60.1284,Event,ADDED,eval-sanitize-20-r1-018-tml46.18d41aa6294226f8,"reason=Pulled count=1 msg=Container image ""busybox:musl"" already present on machine"
60.1286,Event,ADDED,eval-sanitize-20-r1-018-tml46.18d41aa62b808ba9,reason=Created count=1 msg=Created container: task
60.1288,Event,ADDED,eval-sanitize-20-r1-018-tml46.18d41aa62e71b816,reason=Started count=1 msg=Started container task
60.129,Event,ADDED,eval-sanitize-20-r1-018.18d41aa2411e431f,reason=SuccessfulCreate count=1 msg=Created pod: eval-sanitize-20-r1-018-tml46
60.1292,Event,ADDED,eval-sanitize-20-r1-018.18d41aa931a95888,reason=Completed count=1 msg=Job completed
60.1294,Event,ADDED,eval-sanitize-20-r1-019-dl74d.18d41aa27b634e54,"reason=FailedScheduling count=None msg=0/6 nodes are available: 6 node(s) had untolerated taint(s). no new claims to deallocate, preemption: 0/6 nodes are available: 6 Preemption is not helpful for scheduling."
60.1295,Event,ADDED,eval-sanitize-20-r1-019-dl74d.18d41aa60e9196a5,"reason=FailedScheduling count=None msg=0/6 nodes are available: 1 c_wall violated: 2 conflicting context pair(s) with node memory, 5 node(s) had untolerated taint(s). no new claims to deallocate, preemption: 0/6 nodes are available: 1 No preemption victims found for incoming pod, 5 Preemption is not helpful for scheduling."
60.1297,Event,ADDED,eval-sanitize-20-r1-019-dl74d.18d41aa624594873,"reason=FailedScheduling count=None msg=0/6 nodes are available: 1 c_wall violated: 2 conflicting context pair(s) with node memory, 5 node(s) had untolerated taint(s). no new claims to deallocate, preemption: 0/6 nodes are available: 1 No preemption victims found for incoming pod, 5 Preemption is not helpful for scheduling."
60.13,Event,ADDED,eval-sanitize-20-r1-019-dl74d.18d41aa663bcd277,"reason=FailedScheduling count=None msg=0/6 nodes are available: 1 c_wall violated: 1 conflicting context pair(s) with node memory, 1 c_wall violated: 2 conflicting context pair(s) with node memory, 4 node(s) had untolerated taint(s). no new claims to deallocate, preemption: 0/6 nodes are available: 2 No preemption victims found for incoming pod, 4 Preemption is not helpful for scheduling."
60.1302,Event,ADDED,eval-sanitize-20-r1-019-dl74d.18d41aa681b7baee,reason=Scheduled count=None msg=Successfully assigned compute/eval-sanitize-20-r1-019-dl74d to kind-worker3
60.1304,Event,ADDED,eval-sanitize-20-r1-019-dl74d.18d41aa69bafb0d2,"reason=Pulled count=1 msg=Container image ""busybox:musl"" already present on machine"
60.1316,Pod,ADDED,eval-sanitize-20-r1-031-dpf7x,phase=Succeeded node=kind-worker
60.1329,Pod,ADDED,eval-sanitize-20-r1-032-v889x,phase=Succeeded node=kind-worker3
60.1332,Event,ADDED,eval-sanitize-20-r1-019-dl74d.18d41aa69d37960b,reason=Created count=1 msg=Created container: task
60.1334,Event,ADDED,eval-sanitize-20-r1-019-dl74d.18d41aa6a23e7c2f,reason=Started count=1 msg=Started container task
60.1337,Event,ADDED,eval-sanitize-20-r1-019.18d41aa27b55d0cb,reason=SuccessfulCreate count=1 msg=Created pod: eval-sanitize-20-r1-019-dl74d
60.1346,Job,ADDED,eval-sanitize-20-r1-027,
60.1351,Event,ADDED,eval-sanitize-20-r1-019.18d41aaa6a0d3a90,reason=Completed count=1 msg=Job completed
60.1354,Event,ADDED,eval-sanitize-20-r1-020-xv9d4.18d41aa2b7ef56ba,"reason=FailedScheduling count=None msg=0/6 nodes are available: 6 node(s) had untolerated taint(s). no new claims to deallocate, preemption: 0/6 nodes are available: 6 Preemption is not helpful for scheduling."
60.1356,Event,ADDED,eval-sanitize-20-r1-020-xv9d4.18d41aa60f41daa4,"reason=FailedScheduling count=None msg=0/6 nodes are available: 1 c_wall violated: 1 conflicting context pair(s) with node memory, 5 node(s) had untolerated taint(s). no new claims to deallocate, preemption: 0/6 nodes are available: 1 No preemption victims found for incoming pod, 5 Preemption is not helpful for scheduling."
60.1364,Job,ADDED,eval-sanitize-20-r1-028,
60.1375,Pod,ADDED,eval-sanitize-20-r1-033-sstrx,phase=Succeeded node=kind-worker
60.1378,Event,ADDED,eval-sanitize-20-r1-020-xv9d4.18d41aa624819806,"reason=FailedScheduling count=None msg=0/6 nodes are available: 1 c_wall violated: 2 conflicting context pair(s) with node memory, 5 node(s) had untolerated taint(s). no new claims to deallocate, preemption: 0/6 nodes are available: 1 No preemption victims found for incoming pod, 5 Preemption is not helpful for scheduling."
60.138,Event,ADDED,eval-sanitize-20-r1-020-xv9d4.18d41aa62dec6695,"reason=FailedScheduling count=None msg=0/6 nodes are available: 1 c_wall violated: 2 conflicting context pair(s) with node memory, 5 node(s) had untolerated taint(s). no new claims to deallocate, preemption: 0/6 nodes are available: 1 No preemption victims found for incoming pod, 5 Preemption is not helpful for scheduling."
60.1382,Event,ADDED,eval-sanitize-20-r1-020-xv9d4.18d41aa641dcc573,reason=Scheduled count=None msg=Successfully assigned compute/eval-sanitize-20-r1-020-xv9d4 to kind-worker4
60.1384,Event,ADDED,eval-sanitize-20-r1-020-xv9d4.18d41aa65c42e140,"reason=Pulled count=1 msg=Container image ""busybox:musl"" already present on machine"
60.1399,Pod,ADDED,eval-sanitize-20-r1-034-48s2k,phase=Succeeded node=kind-worker2
60.1401,Event,ADDED,eval-sanitize-20-r1-020-xv9d4.18d41aa65d91403f,reason=Created count=1 msg=Created container: task
60.1403,Event,ADDED,eval-sanitize-20-r1-020-xv9d4.18d41aa65fb6a7ca,reason=Started count=1 msg=Started container task
60.1405,Event,ADDED,eval-sanitize-20-r1-020.18d41aa2b7e3bcc2,reason=SuccessfulCreate count=1 msg=Created pod: eval-sanitize-20-r1-020-xv9d4
60.1407,Event,ADDED,eval-sanitize-20-r1-020.18d41aaa591cf8b6,reason=Completed count=1 msg=Job completed
60.1415,Job,ADDED,eval-sanitize-20-r1-029,
60.1423,Job,ADDED,eval-sanitize-20-r1-030,
60.1435,Pod,ADDED,eval-sanitize-20-r1-035-sj97h,phase=Succeeded node=kind-worker3
60.1438,Event,ADDED,eval-sanitize-20-r1-021-77dzv.18d41aa2f29b9568,"reason=FailedScheduling count=None msg=0/6 nodes are available: 6 node(s) had untolerated taint(s). no new claims to deallocate, preemption: 0/6 nodes are available: 6 Preemption is not helpful for scheduling."
60.144,Event,ADDED,eval-sanitize-20-r1-021-77dzv.18d41aa611b9b5fd,"reason=FailedScheduling count=None msg=0/6 nodes are available: 1 c_wall violated: 2 conflicting context pair(s) with node memory, 5 node(s) had untolerated taint(s). no new claims to deallocate, preemption: 0/6 nodes are available: 1 No preemption victims found for incoming pod, 5 Preemption is not helpful for scheduling."
60.1442,Event,ADDED,eval-sanitize-20-r1-021-77dzv.18d41aa6298ecc45,"reason=FailedScheduling count=None msg=0/6 nodes are available: 1 c_wall violated: 2 conflicting context pair(s) with node memory, 5 node(s) had untolerated taint(s). no new claims to deallocate, preemption: 0/6 nodes are available: 1 No preemption victims found for incoming pod, 5 Preemption is not helpful for scheduling."
60.1455,Pod,ADDED,eval-sanitize-20-r1-036-qpnd7,phase=Succeeded node=kind-worker2
60.1462,Job,ADDED,eval-sanitize-20-r1-031,
60.1465,Event,ADDED,eval-sanitize-20-r1-021-77dzv.18d41aa657834e4d,"reason=FailedScheduling count=None msg=0/6 nodes are available: 2 c_wall violated: 2 conflicting context pair(s) with node memory, 4 node(s) had untolerated taint(s). no new claims to deallocate, preemption: 0/6 nodes are available: 2 No preemption victims found for incoming pod, 4 Preemption is not helpful for scheduling."
60.1468,Event,ADDED,eval-sanitize-20-r1-021-77dzv.18d41aa693430262,"reason=FailedScheduling count=None msg=0/6 nodes are available: 1 c_wall violated: 1 conflicting context pair(s) with node memory, 2 c_wall violated: 2 conflicting context pair(s) with node memory, 3 node(s) had untolerated taint(s). no new claims to deallocate, preemption: 0/6 nodes are available: 3 No preemption victims found for incoming pod, 3 Preemption is not helpful for scheduling."
60.1469,Event,ADDED,eval-sanitize-20-r1-021-77dzv.18d41aa6bd86e679,reason=Scheduled count=None msg=Successfully assigned compute/eval-sanitize-20-r1-021-77dzv to kind-worker2
60.1481,Pod,ADDED,eval-sanitize-20-r1-037-lgp4f,phase=Succeeded node=kind-worker3
60.1483,Event,ADDED,eval-sanitize-20-r1-021-77dzv.18d41aa6d52ffaf2,"reason=Pulled count=1 msg=Container image ""busybox:musl"" already present on machine"
60.1485,Event,ADDED,eval-sanitize-20-r1-021-77dzv.18d41aa6d66fcf6d,reason=Created count=1 msg=Created container: task
60.1488,Event,ADDED,eval-sanitize-20-r1-021-77dzv.18d41aa6da526eb0,reason=Started count=1 msg=Started container task
60.1495,Job,ADDED,eval-sanitize-20-r1-032,
60.1509,Pod,ADDED,eval-sanitize-20-r1-038-9lwb4,phase=Succeeded node=kind-worker5
60.1512,Event,ADDED,eval-sanitize-20-r1-021.18d41aa2f28e5409,reason=SuccessfulCreate count=1 msg=Created pod: eval-sanitize-20-r1-021-77dzv
60.1514,Event,ADDED,eval-sanitize-20-r1-021.18d41aaab4e0ae5f,reason=Completed count=1 msg=Job completed
60.1515,Event,ADDED,eval-sanitize-20-r1-022-qr2sk.18d41aa32ead56ed,"reason=FailedScheduling count=None msg=0/6 nodes are available: 6 node(s) had untolerated taint(s). no new claims to deallocate, preemption: 0/6 nodes are available: 6 Preemption is not helpful for scheduling."
60.1517,Event,ADDED,eval-sanitize-20-r1-022-qr2sk.18d41aa613da7d98,"reason=FailedScheduling count=None msg=0/6 nodes are available: 1 c_wall violated: 2 conflicting context pair(s) with node memory, 5 node(s) had untolerated taint(s). no new claims to deallocate, preemption: 0/6 nodes are available: 1 No preemption victims found for incoming pod, 5 Preemption is not helpful for scheduling."
60.1525,Job,ADDED,eval-sanitize-20-r1-033,
60.1529,Event,ADDED,eval-sanitize-20-r1-022-qr2sk.18d41aa629c0853a,"reason=FailedScheduling count=None msg=0/6 nodes are available: 1 c_wall violated: 2 conflicting context pair(s) with node memory, 5 node(s) had untolerated taint(s). no new claims to deallocate, preemption: 0/6 nodes are available: 1 No preemption victims found for incoming pod, 5 Preemption is not helpful for scheduling."
60.1531,Event,ADDED,eval-sanitize-20-r1-022-qr2sk.18d41aa657e14713,"reason=FailedScheduling count=None msg=0/6 nodes are available: 1 c_wall violated: 1 conflicting context pair(s) with node memory, 1 c_wall violated: 2 conflicting context pair(s) with node memory, 4 node(s) had untolerated taint(s). no new claims to deallocate, preemption: 0/6 nodes are available: 2 No preemption victims found for incoming pod, 4 Preemption is not helpful for scheduling."
60.1533,Event,ADDED,eval-sanitize-20-r1-022-qr2sk.18d41aa66a04a3a5,reason=Scheduled count=None msg=Successfully assigned compute/eval-sanitize-20-r1-022-qr2sk to kind-worker3
60.1544,Pod,ADDED,eval-sanitize-20-r1-039-m6b7m,phase=Succeeded node=kind-worker4
60.1552,Job,ADDED,eval-sanitize-20-r1-034,
60.1555,Event,ADDED,eval-sanitize-20-r1-022-qr2sk.18d41aa68436395f,"reason=Pulled count=1 msg=Container image ""busybox:musl"" already present on machine"
60.1556,Event,ADDED,eval-sanitize-20-r1-022-qr2sk.18d41aa68650a0d5,reason=Created count=1 msg=Created container: task
60.1558,Event,ADDED,eval-sanitize-20-r1-022-qr2sk.18d41aa68af1ed7e,reason=Started count=1 msg=Started container task
60.1569,Pod,ADDED,eval-sanitize-20-r1-040-vrmnl,phase=Succeeded node=kind-worker5
60.1578,Job,ADDED,eval-sanitize-20-r1-035,
60.159,Pod,ADDED,eval-sanitize-20-r1-041-sh74p,phase=Succeeded node=kind-worker4
60.1593,Event,ADDED,eval-sanitize-20-r1-022.18d41aa32ea0a511,reason=SuccessfulCreate count=1 msg=Created pod: eval-sanitize-20-r1-022-qr2sk
60.1596,Event,ADDED,eval-sanitize-20-r1-022.18d41aaa641dc5e1,reason=Completed count=1 msg=Job completed
60.1598,Event,ADDED,eval-sanitize-20-r1-023-lhw8g.18d41aa36a2b6f02,"reason=FailedScheduling count=None msg=0/6 nodes are available: 6 node(s) had untolerated taint(s). no new claims to deallocate, preemption: 0/6 nodes are available: 6 Preemption is not helpful for scheduling."
60.1599,Event,ADDED,eval-sanitize-20-r1-023-lhw8g.18d41aa614a38db8,"reason=FailedScheduling count=None msg=0/6 nodes are available: 1 c_wall violated: 1 conflicting context pair(s) with node memory, 5 node(s) had untolerated taint(s). no new claims to deallocate, preemption: 0/6 nodes are available: 1 No preemption victims found for incoming pod, 5 Preemption is not helpful for scheduling."
60.1607,Job,ADDED,eval-sanitize-20-r1-036,
60.1618,Pod,ADDED,eval-sanitize-20-r1-042-bpmh6,phase=Succeeded node=kind-worker5
60.1622,Event,ADDED,eval-sanitize-20-r1-023-lhw8g.18d41aa629f759a2,"reason=FailedScheduling count=None msg=0/6 nodes are available: 1 c_wall violated: 1 conflicting context pair(s) with node memory, 5 node(s) had untolerated taint(s). no new claims to deallocate, preemption: 0/6 nodes are available: 1 No preemption victims found for incoming pod, 5 Preemption is not helpful for scheduling."
60.1624,Event,ADDED,eval-sanitize-20-r1-023-lhw8g.18d41aa65835ca5c,"reason=FailedScheduling count=None msg=0/6 nodes are available: 2 c_wall violated: 1 conflicting context pair(s) with node memory, 4 node(s) had untolerated taint(s). no new claims to deallocate, preemption: 0/6 nodes are available: 2 No preemption victims found for incoming pod, 4 Preemption is not helpful for scheduling."
60.1625,Event,ADDED,eval-sanitize-20-r1-023-lhw8g.18d41aa66f8fe15e,reason=Scheduled count=None msg=Successfully assigned compute/eval-sanitize-20-r1-023-lhw8g to kind-worker3
60.1638,Pod,ADDED,eval-sanitize-20-r1-043-kzxd7,phase=Succeeded node=kind-worker
60.164,Event,ADDED,eval-sanitize-20-r1-023-lhw8g.18d41aa68a6f10ef,"reason=Pulled count=1 msg=Container image ""busybox:musl"" already present on machine"
60.1642,Event,ADDED,eval-sanitize-20-r1-023-lhw8g.18d41aa68bdd9e75,reason=Created count=1 msg=Created container: task
60.1644,Event,ADDED,eval-sanitize-20-r1-023-lhw8g.18d41aa68e15fa56,reason=Started count=1 msg=Started container task
60.1646,Event,ADDED,eval-sanitize-20-r1-023.18d41aa36a1d9185,reason=SuccessfulCreate count=1 msg=Created pod: eval-sanitize-20-r1-023-lhw8g
60.1654,Job,ADDED,eval-sanitize-20-r1-037,
60.1665,Pod,ADDED,eval-sanitize-20-r1-044-7jzzf,phase=Succeeded node=kind-worker
60.1668,Event,ADDED,eval-sanitize-20-r1-023.18d41aaaeabb4ec3,reason=Completed count=1 msg=Job completed
60.167,Event,ADDED,eval-sanitize-20-r1-024-jjnk6.18d41aa3a5e2fe6f,"reason=FailedScheduling count=None msg=0/6 nodes are available: 6 node(s) had untolerated taint(s). no new claims to deallocate, preemption: 0/6 nodes are available: 6 Preemption is not helpful for scheduling."
60.1674,Event,ADDED,eval-sanitize-20-r1-024-jjnk6.18d41aa6151d30f4,"reason=FailedScheduling count=None msg=0/6 nodes are available: 1 c_wall violated: 2 conflicting context pair(s) with node memory, 5 node(s) had untolerated taint(s). no new claims to deallocate, preemption: 0/6 nodes are available: 1 No preemption victims found for incoming pod, 5 Preemption is not helpful for scheduling."
60.1683,Job,ADDED,eval-sanitize-20-r1-038,
60.1687,Event,ADDED,eval-sanitize-20-r1-024-jjnk6.18d41aa62a2b7de3,"reason=FailedScheduling count=None msg=0/6 nodes are available: 1 c_wall violated: 2 conflicting context pair(s) with node memory, 5 node(s) had untolerated taint(s). no new claims to deallocate, preemption: 0/6 nodes are available: 1 No preemption victims found for incoming pod, 5 Preemption is not helpful for scheduling."
60.1689,Event,ADDED,eval-sanitize-20-r1-024-jjnk6.18d41aa65d87bcab,"reason=FailedScheduling count=None msg=0/6 nodes are available: 1 c_wall violated: 1 conflicting context pair(s) with node memory, 1 c_wall violated: 2 conflicting context pair(s) with node memory, 4 node(s) had untolerated taint(s). no new claims to deallocate, preemption: 0/6 nodes are available: 2 No preemption victims found for incoming pod, 4 Preemption is not helpful for scheduling."
60.1691,Event,ADDED,eval-sanitize-20-r1-024-jjnk6.18d41aa670539629,reason=Scheduled count=None msg=Successfully assigned compute/eval-sanitize-20-r1-024-jjnk6 to kind-worker3
60.1701,Event,ADDED,eval-sanitize-20-r1-024-jjnk6.18d41aa68af4ee32,"reason=Pulled count=1 msg=Container image ""busybox:musl"" already present on machine"
60.1706,Event,ADDED,eval-sanitize-20-r1-024-jjnk6.18d41aa68c70693c,reason=Created count=1 msg=Created container: task
60.1711,Event,ADDED,eval-sanitize-20-r1-024-jjnk6.18d41aa68e961804,reason=Started count=1 msg=Started container task
60.1715,Event,ADDED,eval-sanitize-20-r1-024.18d41aa3a5d908e7,reason=SuccessfulCreate count=1 msg=Created pod: eval-sanitize-20-r1-024-jjnk6
60.1727,Pod,ADDED,eval-sanitize-20-r1-045-zpzl7,phase=Succeeded node=kind-worker5
60.174,Pod,ADDED,eval-sanitize-20-r1-046-mlxd2,phase=Succeeded node=kind-worker4
60.1743,Event,ADDED,eval-sanitize-20-r1-024.18d41aaa76422f86,reason=Completed count=1 msg=Job completed
60.1745,Event,ADDED,eval-sanitize-20-r1-025-rp76f.18d41aa3e1fd7121,"reason=FailedScheduling count=None msg=0/6 nodes are available: 6 node(s) had untolerated taint(s). no new claims to deallocate, preemption: 0/6 nodes are available: 6 Preemption is not helpful for scheduling."
60.1746,Event,ADDED,eval-sanitize-20-r1-025-rp76f.18d41aa617da515a,reason=Scheduled count=None msg=Successfully assigned compute/eval-sanitize-20-r1-025-rp76f to kind-worker
60.1756,Job,ADDED,eval-sanitize-20-r1-039,
60.1767,Pod,ADDED,eval-sanitize-20-r1-047-sffms,phase=Succeeded node=kind-worker4
60.1776,Job,ADDED,eval-sanitize-20-r1-040,
60.1779,Event,ADDED,eval-sanitize-20-r1-025-rp76f.18d41aa635176be4,"reason=Pulled count=1 msg=Container image ""busybox:musl"" already present on machine"
60.1781,Event,ADDED,eval-sanitize-20-r1-025-rp76f.18d41aa637154125,reason=Created count=1 msg=Created container: task
60.1784,Event,ADDED,eval-sanitize-20-r1-025-rp76f.18d41aa63b10ea9c,reason=Started count=1 msg=Started container task
60.1789,Event,ADDED,eval-sanitize-20-r1-025.18d41aa3e1f3710c,reason=SuccessfulCreate count=1 msg=Created pod: eval-sanitize-20-r1-025-rp76f
60.1805,Pod,ADDED,eval-sanitize-20-r1-048-6wbxl,phase=Running node=kind-worker4
60.1809,Event,ADDED,eval-sanitize-20-r1-025.18d41aa92a4039a7,reason=Completed count=1 msg=Job completed
60.1811,Event,ADDED,eval-sanitize-20-r1-026-cdlxh.18d41aa41d2995a9,"reason=FailedScheduling count=None msg=0/6 nodes are available: 6 node(s) had untolerated taint(s). no new claims to deallocate, preemption: 0/6 nodes are available: 6 Preemption is not helpful for scheduling."
60.1813,Event,ADDED,eval-sanitize-20-r1-026-cdlxh.18d41aa617a8c651,"reason=FailedScheduling count=None msg=0/6 nodes are available: 1 c_wall violated: 1 conflicting context pair(s) with node memory, 5 node(s) had untolerated taint(s). no new claims to deallocate, preemption: 0/6 nodes are available: 1 No preemption victims found for incoming pod, 5 Preemption is not helpful for scheduling."
60.1815,Event,ADDED,eval-sanitize-20-r1-026-cdlxh.18d41aa62a61cc1a,"reason=FailedScheduling count=None msg=0/6 nodes are available: 1 c_wall violated: 2 conflicting context pair(s) with node memory, 5 node(s) had untolerated taint(s). no new claims to deallocate, preemption: 0/6 nodes are available: 1 No preemption victims found for incoming pod, 5 Preemption is not helpful for scheduling."
60.1817,Event,ADDED,eval-sanitize-20-r1-026-cdlxh.18d41aa62e2466f9,"reason=FailedScheduling count=None msg=0/6 nodes are available: 1 c_wall violated: 2 conflicting context pair(s) with node memory, 5 node(s) had untolerated taint(s). no new claims to deallocate, preemption: 0/6 nodes are available: 1 No preemption victims found for incoming pod, 5 Preemption is not helpful for scheduling."
60.1819,Event,ADDED,eval-sanitize-20-r1-026-cdlxh.18d41aa6462f9f74,reason=Scheduled count=None msg=Successfully assigned compute/eval-sanitize-20-r1-026-cdlxh to kind-worker4
60.1822,Event,ADDED,eval-sanitize-20-r1-026-cdlxh.18d41aa65ee85f6a,"reason=Pulled count=1 msg=Container image ""busybox:musl"" already present on machine"
60.1831,Job,ADDED,eval-sanitize-20-r1-041,
60.1844,Pod,ADDED,eval-sanitize-20-r1-049-88mmc,phase=Running node=kind-worker
60.1847,Event,ADDED,eval-sanitize-20-r1-026-cdlxh.18d41aa6601d2547,reason=Created count=1 msg=Created container: task
60.1849,Event,ADDED,eval-sanitize-20-r1-026-cdlxh.18d41aa662431740,reason=Started count=1 msg=Started container task
60.1851,Event,ADDED,eval-sanitize-20-r1-026.18d41aa41d1d4e48,reason=SuccessfulCreate count=1 msg=Created pod: eval-sanitize-20-r1-026-cdlxh
60.186,Job,ADDED,eval-sanitize-20-r1-042,
60.1871,Pod,ADDED,eval-sanitize-20-r1-050-pvcrv,phase=Running node=kind-worker4
60.1875,Event,ADDED,eval-sanitize-20-r1-026.18d41aaa524b4b22,reason=Completed count=1 msg=Job completed
60.1877,Event,ADDED,eval-sanitize-20-r1-027-t6jkc.18d41aa458942516,"reason=FailedScheduling count=None msg=0/6 nodes are available: 6 node(s) had untolerated taint(s). no new claims to deallocate, preemption: 0/6 nodes are available: 6 Preemption is not helpful for scheduling."
60.1879,Event,ADDED,eval-sanitize-20-r1-027-t6jkc.18d41aa6189fed7d,reason=Scheduled count=None msg=Successfully assigned compute/eval-sanitize-20-r1-027-t6jkc to kind-worker
60.1882,Event,ADDED,eval-sanitize-20-r1-027-t6jkc.18d41aa635458f66,"reason=Pulled count=1 msg=Container image ""busybox:musl"" already present on machine"
60.1893,Job,ADDED,eval-sanitize-20-r1-043,
60.1906,Pod,ADDED,eval-sanitize-20-r1-051-dx4xm,phase=Running node=kind-worker3
60.1909,Event,ADDED,eval-sanitize-20-r1-027-t6jkc.18d41aa6383236fd,reason=Created count=1 msg=Created container: task
60.1911,Event,ADDED,eval-sanitize-20-r1-027-t6jkc.18d41aa63b66d16f,reason=Started count=1 msg=Started container task
60.1913,Event,ADDED,eval-sanitize-20-r1-027.18d41aa45886c791,reason=SuccessfulCreate count=1 msg=Created pod: eval-sanitize-20-r1-027-t6jkc
60.1916,Event,ADDED,eval-sanitize-20-r1-027.18d41aa92b675631,reason=Completed count=1 msg=Job completed
60.1924,Job,ADDED,eval-sanitize-20-r1-044,
60.1935,Pod,ADDED,eval-sanitize-20-r1-052-m54h2,phase=Running node=kind-worker5
60.1937,Event,ADDED,eval-sanitize-20-r1-028-26fpq.18d41aa4945182ce,"reason=FailedScheduling count=None msg=0/6 nodes are available: 6 node(s) had untolerated taint(s). no new claims to deallocate, preemption: 0/6 nodes are available: 6 Preemption is not helpful for scheduling."
60.194,Event,ADDED,eval-sanitize-20-r1-028-26fpq.18d41aa618c12e89,reason=Scheduled count=None msg=Successfully assigned compute/eval-sanitize-20-r1-028-26fpq to kind-worker
60.1942,Event,ADDED,eval-sanitize-20-r1-028-26fpq.18d41aa635d60c92,"reason=Pulled count=1 msg=Container image ""busybox:musl"" already present on machine"
60.1944,Event,ADDED,eval-sanitize-20-r1-028-26fpq.18d41aa639464f4e,reason=Created count=1 msg=Created container: task
60.1946,Event,ADDED,eval-sanitize-20-r1-028-26fpq.18d41aa63bb08e49,reason=Started count=1 msg=Started container task
60.1948,Event,ADDED,eval-sanitize-20-r1-028.18d41aa49445debb,reason=SuccessfulCreate count=1 msg=Created pod: eval-sanitize-20-r1-028-26fpq
60.195,Event,ADDED,eval-sanitize-20-r1-028.18d41aa929ffeb54,reason=Completed count=1 msg=Job completed
60.1959,Job,ADDED,eval-sanitize-20-r1-045,
60.1962,Event,ADDED,eval-sanitize-20-r1-029-cjqck.18d41aa4cfb62ad5,"reason=FailedScheduling count=None msg=0/6 nodes are available: 6 node(s) had untolerated taint(s). no new claims to deallocate, preemption: 0/6 nodes are available: 6 Preemption is not helpful for scheduling."
60.1964,Event,ADDED,eval-sanitize-20-r1-029-cjqck.18d41aa61a8bba64,reason=Scheduled count=None msg=Successfully assigned compute/eval-sanitize-20-r1-029-cjqck to kind-worker
60.1966,Event,ADDED,eval-sanitize-20-r1-029-cjqck.18d41aa637654f96,"reason=Pulled count=1 msg=Container image ""busybox:musl"" already present on machine"
60.1975,Job,ADDED,eval-sanitize-20-r1-046,
60.1986,Pod,ADDED,eval-sanitize-20-r1-053-btx8q,phase=Running node=kind-worker4
60.199,Event,ADDED,eval-sanitize-20-r1-029-cjqck.18d41aa63af07e1b,reason=Created count=1 msg=Created container: task
60.1992,Event,ADDED,eval-sanitize-20-r1-029-cjqck.18d41aa63d93d19c,reason=Started count=1 msg=Started container task
60.1995,Event,ADDED,eval-sanitize-20-r1-029.18d41aa4cfaa9682,reason=SuccessfulCreate count=1 msg=Created pod: eval-sanitize-20-r1-029-cjqck
60.1997,Event,ADDED,eval-sanitize-20-r1-029.18d41aa92af828d7,reason=Completed count=1 msg=Job completed
60.2,TaskRequest,MODIFIED,eval-sanitize-20-r1-046,phase=Complete job=None
60.2003,Event,ADDED,eval-sanitize-20-r1-030-8p8k8.18d41aa50b78d5e5,"reason=FailedScheduling count=None msg=0/6 nodes are available: 6 node(s) had untolerated taint(s). no new claims to deallocate, preemption: 0/6 nodes are available: 6 Preemption is not helpful for scheduling."
60.2005,Event,ADDED,eval-sanitize-20-r1-030-8p8k8.18d41aa61ac1cf53,reason=Scheduled count=None msg=Successfully assigned compute/eval-sanitize-20-r1-030-8p8k8 to kind-worker
60.2008,Event,ADDED,eval-sanitize-20-r1-030-8p8k8.18d41aa63790c885,"reason=Pulled count=1 msg=Container image ""busybox:musl"" already present on machine"
60.201,Event,ADDED,eval-sanitize-20-r1-030-8p8k8.18d41aa63b10117d,reason=Created count=1 msg=Created container: task
60.2021,Pod,ADDED,eval-sanitize-20-r1-054-m6l4n,phase=Running node=kind-worker4
60.2027,Job,ADDED,eval-sanitize-20-r1-047,
60.203,Event,ADDED,eval-sanitize-20-r1-030-8p8k8.18d41aa63d9464f3,reason=Started count=1 msg=Started container task
60.2033,Event,ADDED,eval-sanitize-20-r1-030.18d41aa50b6b9426,reason=SuccessfulCreate count=1 msg=Created pod: eval-sanitize-20-r1-030-8p8k8
60.2036,Event,ADDED,eval-sanitize-20-r1-030.18d41aaa1d00a263,reason=Completed count=1 msg=Job completed
60.2045,Pod,ADDED,eval-sanitize-20-r1-055-bzm98,phase=Pending node=None
60.2052,Job,ADDED,eval-sanitize-20-r1-048,
60.2055,Event,ADDED,eval-sanitize-20-r1-031-dpf7x.18d41aa546f82ba3,"reason=FailedScheduling count=None msg=0/6 nodes are available: 6 node(s) had untolerated taint(s). no new claims to deallocate, preemption: 0/6 nodes are available: 6 Preemption is not helpful for scheduling."
60.2057,Event,ADDED,eval-sanitize-20-r1-031-dpf7x.18d41aa61b1bb109,reason=Scheduled count=None msg=Successfully assigned compute/eval-sanitize-20-r1-031-dpf7x to kind-worker
60.206,Event,ADDED,eval-sanitize-20-r1-031-dpf7x.18d41aa6374c5963,"reason=Pulled count=1 msg=Container image ""busybox:musl"" already present on machine"
60.2062,Event,ADDED,eval-sanitize-20-r1-031-dpf7x.18d41aa63a44de83,reason=Created count=1 msg=Created container: task
60.2067,Event,ADDED,eval-sanitize-20-r1-031-dpf7x.18d41aa63c97d750,reason=Started count=1 msg=Started container task
60.2069,Event,ADDED,eval-sanitize-20-r1-031.18d41aa546eb3389,reason=SuccessfulCreate count=1 msg=Created pod: eval-sanitize-20-r1-031-dpf7x
60.2071,Event,ADDED,eval-sanitize-20-r1-031.18d41aaa0ae0c3cb,reason=Completed count=1 msg=Job completed
60.2074,Event,ADDED,eval-sanitize-20-r1-032-v889x.18d41aa582bd3bb9,"reason=FailedScheduling count=None msg=0/6 nodes are available: 6 node(s) had untolerated taint(s). no new claims to deallocate, preemption: 0/6 nodes are available: 6 Preemption is not helpful for scheduling."
60.2084,Pod,ADDED,eval-sanitize-20-r1-056-sqhx4,phase=Pending node=None
60.2087,Event,ADDED,eval-sanitize-20-r1-032-v889x.18d41aa61d7ad12b,"reason=FailedScheduling count=None msg=0/6 nodes are available: 1 c_wall violated: 2 conflicting context pair(s) with node memory, 5 node(s) had untolerated taint(s). no new claims to deallocate, preemption: 0/6 nodes are available: 1 No preemption victims found for incoming pod, 5 Preemption is not helpful for scheduling."
60.209,Event,ADDED,eval-sanitize-20-r1-032-v889x.18d41aa62ae9127b,"reason=FailedScheduling count=None msg=0/6 nodes are available: 1 c_wall violated: 2 conflicting context pair(s) with node memory, 5 node(s) had untolerated taint(s). no new claims to deallocate, preemption: 0/6 nodes are available: 1 No preemption victims found for incoming pod, 5 Preemption is not helpful for scheduling."
60.2096,Job,ADDED,eval-sanitize-20-r1-049,
60.2106,Pod,ADDED,eval-sanitize-20-r1-057-rkz4v,phase=Running node=kind-worker2
60.2115,Pod,ADDED,eval-sanitize-20-r1-058-d9b2t,phase=Pending node=None
60.2122,Job,ADDED,eval-sanitize-20-r1-050,
60.213,Event,ADDED,eval-sanitize-20-r1-032-v889x.18d41aa65df82f28,"reason=FailedScheduling count=None msg=0/6 nodes are available: 1 c_wall violated: 1 conflicting context pair(s) with node memory, 1 c_wall violated: 2 conflicting context pair(s) with node memory, 4 node(s) had untolerated taint(s). no new claims to deallocate, preemption: 0/6 nodes are available: 2 No preemption victims found for incoming pod, 4 Preemption is not helpful for scheduling."
60.2134,Event,ADDED,eval-sanitize-20-r1-032-v889x.18d41aa675c78b1e,reason=Scheduled count=None msg=Successfully assigned compute/eval-sanitize-20-r1-032-v889x to kind-worker3
60.2137,Event,ADDED,eval-sanitize-20-r1-032-v889x.18d41aa68d2f5c13,"reason=Pulled count=1 msg=Container image ""busybox:musl"" already present on machine"
60.214,Event,ADDED,eval-sanitize-20-r1-032-v889x.18d41aa68e73ffee,reason=Created count=1 msg=Created container: task
60.2148,Pod,ADDED,eval-sanitize-20-r1-059-vz4jf,phase=Pending node=None
60.2156,Job,ADDED,eval-sanitize-20-r1-051,
60.2158,Event,ADDED,eval-sanitize-20-r1-032-v889x.18d41aa690c09c57,reason=Started count=1 msg=Started container task
60.2161,Event,ADDED,eval-sanitize-20-r1-032.18d41aa582b2c0ce,reason=SuccessfulCreate count=1 msg=Created pod: eval-sanitize-20-r1-032-v889x
60.2164,Event,ADDED,eval-sanitize-20-r1-032.18d41aaa670545d2,reason=Completed count=1 msg=Job completed
60.2167,Event,ADDED,eval-sanitize-20-r1-033-sstrx.18d41aa5be4cd07a,"reason=FailedScheduling count=None msg=0/6 nodes are available: 6 node(s) had untolerated taint(s). no new claims to deallocate, preemption: 0/6 nodes are available: 6 Preemption is not helpful for scheduling."
60.217,Event,ADDED,eval-sanitize-20-r1-033-sstrx.18d41aa623da34cb,reason=Scheduled count=None msg=Successfully assigned compute/eval-sanitize-20-r1-033-sstrx to kind-worker
60.2172,Event,ADDED,eval-sanitize-20-r1-033-sstrx.18d41aa63f030f29,"reason=Pulled count=1 msg=Container image ""busybox:musl"" already present on machine"
60.2174,Event,ADDED,eval-sanitize-20-r1-033-sstrx.18d41aa640216a5a,reason=Created count=1 msg=Created container: task
60.218,Job,ADDED,eval-sanitize-20-r1-052,
60.2186,Pod,ADDED,eval-sanitize-20-r1-060-nkffm,phase=Pending node=None
60.2189,Event,ADDED,eval-sanitize-20-r1-033-sstrx.18d41aa643dfd9ce,reason=Started count=1 msg=Started container task
60.2191,Event,ADDED,eval-sanitize-20-r1-033.18d41aa5be3ba736,reason=SuccessfulCreate count=1 msg=Created pod: eval-sanitize-20-r1-033-sstrx
60.2193,Event,ADDED,eval-sanitize-20-r1-033.18d41aaa316024dc,reason=Completed count=1 msg=Job completed
60.2223,Event,ADDED,eval-sanitize-20-r1-034-48s2k.18d41aa5f9eb40b5,"reason=FailedScheduling count=None msg=0/6 nodes are available: 6 node(s) had untolerated taint(s). no new claims to deallocate, preemption: 0/6 nodes are available: 6 Preemption is not helpful for scheduling."
60.2225,Event,ADDED,eval-sanitize-20-r1-034-48s2k.18d41aa623b1620b,"reason=FailedScheduling count=None msg=0/6 nodes are available: 1 c_wall violated: 2 conflicting context pair(s) with node memory, 5 node(s) had untolerated taint(s). no new claims to deallocate, preemption: 0/6 nodes are available: 1 No preemption victims found for incoming pod, 5 Preemption is not helpful for scheduling."
60.2228,Event,ADDED,eval-sanitize-20-r1-034-48s2k.18d41aa62b1431af,"reason=FailedScheduling count=None msg=0/6 nodes are available: 1 c_wall violated: 2 conflicting context pair(s) with node memory, 5 node(s) had untolerated taint(s). no new claims to deallocate, preemption: 0/6 nodes are available: 1 No preemption victims found for incoming pod, 5 Preemption is not helpful for scheduling."
60.223,Event,ADDED,eval-sanitize-20-r1-034-48s2k.18d41aa6635bba0d,"reason=FailedScheduling count=None msg=0/6 nodes are available: 2 c_wall violated: 2 conflicting context pair(s) with node memory, 4 node(s) had untolerated taint(s). no new claims to deallocate, preemption: 0/6 nodes are available: 2 No preemption victims found for incoming pod, 4 Preemption is not helpful for scheduling."
60.2237,Job,ADDED,eval-sanitize-20-r1-053,
60.2243,Job,ADDED,eval-sanitize-20-r1-054,
60.2246,Event,ADDED,eval-sanitize-20-r1-034-48s2k.18d41aa68dbd71c5,"reason=FailedScheduling count=None msg=0/6 nodes are available: 1 c_wall violated: 1 conflicting context pair(s) with node memory, 2 c_wall violated: 2 conflicting context pair(s) with node memory, 3 node(s) had untolerated taint(s). no new claims to deallocate, preemption: 0/6 nodes are available: 3 No preemption victims found for incoming pod, 3 Preemption is not helpful for scheduling."
60.2248,Event,ADDED,eval-sanitize-20-r1-034-48s2k.18d41aa6b89ba573,reason=Scheduled count=None msg=Successfully assigned compute/eval-sanitize-20-r1-034-48s2k to kind-worker2
60.225,Event,ADDED,eval-sanitize-20-r1-034-48s2k.18d41aa6d295260c,"reason=Pulled count=1 msg=Container image ""busybox:musl"" already present on machine"
60.2257,Pod,MODIFIED,eval-sanitize-20-r1-060-nkffm,phase=Pending node=None
60.2264,Job,ADDED,eval-sanitize-20-r1-055,
60.2275,Pod,MODIFIED,eval-sanitize-20-r1-047-sffms,phase=Succeeded node=kind-worker4
60.2278,Event,ADDED,eval-sanitize-20-r1-034-48s2k.18d41aa6d3ba7db6,reason=Created count=1 msg=Created container: task
60.2281,Event,ADDED,eval-sanitize-20-r1-034-48s2k.18d41aa6d5f16680,reason=Started count=1 msg=Started container task
60.2283,Event,ADDED,eval-sanitize-20-r1-034.18d41aa5f9de09be,reason=SuccessfulCreate count=1 msg=Created pod: eval-sanitize-20-r1-034-48s2k
60.2284,Event,ADDED,eval-sanitize-20-r1-034.18d41aaab1a89461,reason=Completed count=1 msg=Job completed
60.2296,Job,ADDED,eval-sanitize-20-r1-056,
60.23,Event,ADDED,eval-sanitize-20-r1-035-sj97h.18d41aa63702d587,"reason=FailedScheduling count=None msg=0/6 nodes are available: 1 c_wall violated: 2 conflicting context pair(s) with node memory, 5 node(s) had untolerated taint(s). no new claims to deallocate, preemption: 0/6 nodes are available: 1 No preemption victims found for incoming pod, 5 Preemption is not helpful for scheduling."
60.2303,Event,ADDED,eval-sanitize-20-r1-035-sj97h.18d41aa637b15ea1,"reason=FailedScheduling count=None msg=0/6 nodes are available: 1 c_wall violated: 2 conflicting context pair(s) with node memory, 5 node(s) had untolerated taint(s). no new claims to deallocate, preemption: 0/6 nodes are available: 1 No preemption victims found for incoming pod, 5 Preemption is not helpful for scheduling."
60.2305,Event,ADDED,eval-sanitize-20-r1-035-sj97h.18d41aa65348362d,"reason=FailedScheduling count=None msg=0/6 nodes are available: 2 c_wall violated: 2 conflicting context pair(s) with node memory, 4 node(s) had untolerated taint(s). no new claims to deallocate, preemption: 0/6 nodes are available: 2 No preemption victims found for incoming pod, 4 Preemption is not helpful for scheduling."
60.2308,Event,ADDED,eval-sanitize-20-r1-035-sj97h.18d41aa682b7cf71,reason=Scheduled count=None msg=Successfully assigned compute/eval-sanitize-20-r1-035-sj97h to kind-worker3
60.231,Event,ADDED,eval-sanitize-20-r1-035-sj97h.18d41aa69c1f62d6,"reason=Pulled count=1 msg=Container image ""busybox:musl"" already present on machine"
60.2314,Event,ADDED,eval-sanitize-20-r1-035-sj97h.18d41aa69db92ab8,reason=Created count=1 msg=Created container: task
60.232,Job,ADDED,eval-sanitize-20-r1-057,
60.2323,Event,ADDED,eval-sanitize-20-r1-035-sj97h.18d41aa6a23e7c25,reason=Started count=1 msg=Started container task
60.2325,Event,ADDED,eval-sanitize-20-r1-035.18d41aa636bee3cd,reason=SuccessfulCreate count=1 msg=Created pod: eval-sanitize-20-r1-035-sj97h
60.2327,Event,ADDED,eval-sanitize-20-r1-035.18d41aaac3a16810,reason=Completed count=1 msg=Job completed
60.2329,Event,ADDED,eval-sanitize-20-r1-036-qpnd7.18d41aa67619b9c2,"reason=FailedScheduling count=None msg=0/6 nodes are available: 1 c_wall violated: 1 conflicting context pair(s) with node memory, 2 c_wall violated: 2 conflicting context pair(s) with node memory, 3 node(s) had untolerated taint(s). no new claims to deallocate, preemption: 0/6 nodes are available: 3 No preemption victims found for incoming pod, 3 Preemption is not helpful for scheduling."
60.2335,Job,ADDED,eval-sanitize-20-r1-058,
60.2339,Event,ADDED,eval-sanitize-20-r1-036-qpnd7.18d41aa6882ce074,"reason=FailedScheduling count=None msg=0/6 nodes are available: 1 c_wall violated: 1 conflicting context pair(s) with node memory, 2 c_wall violated: 2 conflicting context pair(s) with node memory, 3 node(s) had untolerated taint(s). no new claims to deallocate, preemption: 0/6 nodes are available: 3 No preemption victims found for incoming pod, 3 Preemption is not helpful for scheduling."
60.2341,Event,ADDED,eval-sanitize-20-r1-036-qpnd7.18d41aa6c3653b97,reason=Scheduled count=None msg=Successfully assigned compute/eval-sanitize-20-r1-036-qpnd7 to kind-worker2
60.2342,Event,ADDED,eval-sanitize-20-r1-036-qpnd7.18d41aa6dff5bc37,"reason=Pulled count=1 msg=Container image ""busybox:musl"" already present on machine"
60.2345,Event,ADDED,eval-sanitize-20-r1-036-qpnd7.18d41aa6e16072f4,reason=Created count=1 msg=Created container: task
60.2347,Event,ADDED,eval-sanitize-20-r1-036-qpnd7.18d41aa6e604a09e,reason=Started count=1 msg=Started container task
60.2349,Event,ADDED,eval-sanitize-20-r1-036.18d41aa67130c0da,reason=SuccessfulCreate count=1 msg=Created pod: eval-sanitize-20-r1-036-qpnd7
60.2351,Event,ADDED,eval-sanitize-20-r1-036.18d41aaaa2ab91e3,reason=Completed count=1 msg=Job completed
60.2356,Job,ADDED,eval-sanitize-20-r1-059,
60.2359,Event,ADDED,eval-sanitize-20-r1-037-lgp4f.18d41aa6adf23cf9,reason=Scheduled count=None msg=Successfully assigned compute/eval-sanitize-20-r1-037-lgp4f to kind-worker3
60.2361,Event,ADDED,eval-sanitize-20-r1-037-lgp4f.18d41aa6c7a1b64a,"reason=Pulled count=1 msg=Container image ""busybox:musl"" already present on machine"
60.2363,Event,ADDED,eval-sanitize-20-r1-037-lgp4f.18d41aa6c8b57072,reason=Created count=1 msg=Created container: task
60.2373,Job,ADDED,eval-sanitize-20-r1-060,
60.2377,Event,ADDED,eval-sanitize-20-r1-037-lgp4f.18d41aa6ccd0b718,reason=Started count=1 msg=Started container task
60.2379,Event,ADDED,eval-sanitize-20-r1-037.18d41aa6acf9f7a2,reason=SuccessfulCreate count=1 msg=Created pod: eval-sanitize-20-r1-037-lgp4f
60.2381,Event,ADDED,eval-sanitize-20-r1-037.18d41aaae460bed0,reason=Completed count=1 msg=Job completed
60.2382,Event,ADDED,eval-sanitize-20-r1-038-9lwb4.18d41aa6eea9a1c5,reason=Scheduled count=None msg=Successfully assigned compute/eval-sanitize-20-r1-038-9lwb4 to kind-worker5
60.2394,Pod,MODIFIED,eval-sanitize-20-r1-048-6wbxl,phase=Succeeded node=kind-worker4
60.2397,Event,ADDED,eval-sanitize-20-r1-038-9lwb4.18d41aa70807ff4a,"reason=Pulled count=1 msg=Container image ""busybox:musl"" already present on machine"
60.2399,Event,ADDED,eval-sanitize-20-r1-038-9lwb4.18d41aa7090cacd2,reason=Created count=1 msg=Created container: task
60.2401,Event,ADDED,eval-sanitize-20-r1-038-9lwb4.18d41aa70d8d5e55,reason=Started count=1 msg=Started container task
60.2402,Event,ADDED,eval-sanitize-20-r1-038.18d41aa6e844f047,reason=SuccessfulCreate count=1 msg=Created pod: eval-sanitize-20-r1-038-9lwb4
60.2408,Job,MODIFIED,eval-sanitize-20-r1-060,
60.241,Event,ADDED,eval-sanitize-20-r1-038.18d41aaaf686f87c,reason=Completed count=1 msg=Job completed
60.2412,Event,ADDED,eval-sanitize-20-r1-039-m6b7m.18d41aa72848ea50,reason=Scheduled count=None msg=Successfully assigned compute/eval-sanitize-20-r1-039-m6b7m to kind-worker4
60.2415,Event,ADDED,eval-sanitize-20-r1-039-m6b7m.18d41aa741bea1c6,"reason=Pulled count=1 msg=Container image ""busybox:musl"" already present on machine"
60.2419,Event,ADDED,eval-sanitize-20-r1-039-m6b7m.18d41aa742e70c0c,reason=Created count=1 msg=Created container: task
60.2422,Event,ADDED,eval-sanitize-20-r1-039-m6b7m.18d41aa747cf5e33,reason=Started count=1 msg=Started container task
60.2425,Event,ADDED,eval-sanitize-20-r1-039.18d41aa723ca2bb4,reason=SuccessfulCreate count=1 msg=Created pod: eval-sanitize-20-r1-039-m6b7m
60.2427,Event,ADDED,eval-sanitize-20-r1-039.18d41aab10e8c785,reason=Completed count=1 msg=Job completed
60.2434,Job,MODIFIED,eval-sanitize-20-r1-059,
60.2436,Event,ADDED,eval-sanitize-20-r1-040-vrmnl.18d41aa764010186,reason=Scheduled count=None msg=Successfully assigned compute/eval-sanitize-20-r1-040-vrmnl to kind-worker5
60.2439,Event,ADDED,eval-sanitize-20-r1-040-vrmnl.18d41aa77e97ccba,"reason=Pulled count=1 msg=Container image ""busybox:musl"" already present on machine"
60.244,Event,ADDED,eval-sanitize-20-r1-040-vrmnl.18d41aa77fba022e,reason=Created count=1 msg=Created container: task
60.2442,Event,ADDED,eval-sanitize-20-r1-040-vrmnl.18d41aa7846ff748,reason=Started count=1 msg=Started container task
60.2451,Job,MODIFIED,eval-sanitize-20-r1-059,
60.2454,Event,ADDED,eval-sanitize-20-r1-040.18d41aa75f8b0c33,reason=SuccessfulCreate count=1 msg=Created pod: eval-sanitize-20-r1-040-vrmnl
60.2456,Event,ADDED,eval-sanitize-20-r1-040.18d41aaafc780a93,reason=Completed count=1 msg=Job completed
60.2458,Event,ADDED,eval-sanitize-20-r1-041-sh74p.18d41aa79f6a9328,reason=Scheduled count=None msg=Successfully assigned compute/eval-sanitize-20-r1-041-sh74p to kind-worker4
60.2465,Job,MODIFIED,eval-sanitize-20-r1-048,
60.2468,Event,ADDED,eval-sanitize-20-r1-041-sh74p.18d41aa7bad0fe39,"reason=Pulled count=1 msg=Container image ""busybox:musl"" already present on machine"
60.2471,Event,ADDED,eval-sanitize-20-r1-041-sh74p.18d41aa7bbfb6641,reason=Created count=1 msg=Created container: task
60.2473,Event,ADDED,eval-sanitize-20-r1-041-sh74p.18d41aa7c045de9f,reason=Started count=1 msg=Started container task
60.2475,Event,ADDED,eval-sanitize-20-r1-041.18d41aa79b17ac3b,reason=SuccessfulCreate count=1 msg=Created pod: eval-sanitize-20-r1-041-sh74p
60.2479,Event,ADDED,eval-sanitize-20-r1-041.18d41aab1d485de0,reason=Completed count=1 msg=Job completed
60.2482,Event,ADDED,eval-sanitize-20-r1-042-bpmh6.18d41aa7dbab14cb,reason=Scheduled count=None msg=Successfully assigned compute/eval-sanitize-20-r1-042-bpmh6 to kind-worker5
60.2484,Event,ADDED,eval-sanitize-20-r1-042-bpmh6.18d41aa7f6f599e5,"reason=Pulled count=1 msg=Container image ""busybox:musl"" already present on machine"
60.2487,Event,ADDED,eval-sanitize-20-r1-042-bpmh6.18d41aa7f80a4707,reason=Created count=1 msg=Created container: task
60.2493,Job,MODIFIED,eval-sanitize-20-r1-047,
60.2497,Event,ADDED,eval-sanitize-20-r1-042-bpmh6.18d41aa7fd841e5f,reason=Started count=1 msg=Started container task
60.2499,Event,ADDED,eval-sanitize-20-r1-042.18d41aa7d736707b,reason=SuccessfulCreate count=1 msg=Created pod: eval-sanitize-20-r1-042-bpmh6
60.2501,Event,ADDED,eval-sanitize-20-r1-042.18d41aab38047965,reason=Completed count=1 msg=Job completed
60.2508,Job,MODIFIED,eval-sanitize-20-r1-048,
60.2512,Event,ADDED,eval-sanitize-20-r1-043-kzxd7.18d41aa816cb0a89,reason=Scheduled count=None msg=Successfully assigned compute/eval-sanitize-20-r1-043-kzxd7 to kind-worker
60.2514,Event,ADDED,eval-sanitize-20-r1-043-kzxd7.18d41aa8323e057f,"reason=Pulled count=1 msg=Container image ""busybox:musl"" already present on machine"
60.2516,Event,ADDED,eval-sanitize-20-r1-043-kzxd7.18d41aa8334d8f4a,reason=Created count=1 msg=Created container: task
60.2518,Event,ADDED,eval-sanitize-20-r1-043-kzxd7.18d41aa835ddb8cd,reason=Started count=1 msg=Started container task
60.2526,Job,MODIFIED,eval-sanitize-20-r1-047,
60.2528,Event,ADDED,eval-sanitize-20-r1-043.18d41aa8121f26ea,reason=SuccessfulCreate count=1 msg=Created pod: eval-sanitize-20-r1-043-kzxd7
60.2531,Event,ADDED,eval-sanitize-20-r1-043.18d41aab5568963c,reason=Completed count=1 msg=Job completed
60.2533,Event,ADDED,eval-sanitize-20-r1-044-7jzzf.18d41aa85273ac92,reason=Scheduled count=None msg=Successfully assigned compute/eval-sanitize-20-r1-044-7jzzf to kind-worker
60.2534,Event,ADDED,eval-sanitize-20-r1-044-7jzzf.18d41aa86dc0d20d,"reason=Pulled count=1 msg=Container image ""busybox:musl"" already present on machine"
60.2542,Job,MODIFIED,eval-sanitize-20-r1-046,
60.2544,Event,ADDED,eval-sanitize-20-r1-044-7jzzf.18d41aa86ee3c0c5,reason=Created count=1 msg=Created container: task
60.2546,Event,ADDED,eval-sanitize-20-r1-044-7jzzf.18d41aa87471e0d9,reason=Started count=1 msg=Started container task
60.2548,Event,ADDED,eval-sanitize-20-r1-044.18d41aa84e1f1ff9,reason=SuccessfulCreate count=1 msg=Created pod: eval-sanitize-20-r1-044-7jzzf
60.2551,Event,ADDED,eval-sanitize-20-r1-044.18d41aabbf640dfb,reason=Completed count=1 msg=Job completed
60.2554,Event,ADDED,eval-sanitize-20-r1-045-zpzl7.18d41aa88dfffb2a,reason=Scheduled count=None msg=Successfully assigned compute/eval-sanitize-20-r1-045-zpzl7 to kind-worker5
60.2556,Event,ADDED,eval-sanitize-20-r1-045-zpzl7.18d41aa8a7b2eec3,"reason=Pulled count=1 msg=Container image ""busybox:musl"" already present on machine"
60.2558,Event,ADDED,eval-sanitize-20-r1-045-zpzl7.18d41aa8a8bdf2cf,reason=Created count=1 msg=Created container: task
60.2567,Job,MODIFIED,eval-sanitize-20-r1-046,
60.257,Event,ADDED,eval-sanitize-20-r1-045-zpzl7.18d41aa8ac4cb393,reason=Started count=1 msg=Started container task
60.2572,Event,ADDED,eval-sanitize-20-r1-045.18d41aa8893ea93c,reason=SuccessfulCreate count=1 msg=Created pod: eval-sanitize-20-r1-045-zpzl7
60.2574,Event,ADDED,eval-sanitize-20-r1-045.18d41aabe6ee3407,reason=Completed count=1 msg=Job completed
60.2576,Event,ADDED,eval-sanitize-20-r1-046-mlxd2.18d41aa8c9a77c12,reason=Scheduled count=None msg=Successfully assigned compute/eval-sanitize-20-r1-046-mlxd2 to kind-worker4
60.2578,Event,ADDED,eval-sanitize-20-r1-046-mlxd2.18d41aa8e838f6c5,"reason=Pulled count=1 msg=Container image ""busybox:musl"" already present on machine"
60.2581,Event,ADDED,eval-sanitize-20-r1-046-mlxd2.18d41aa8e98a165d,reason=Created count=1 msg=Created container: task
60.2582,Event,ADDED,eval-sanitize-20-r1-046-mlxd2.18d41aa8f3c0c23a,reason=Started count=1 msg=Started container task
60.259,Job,MODIFIED,eval-sanitize-20-r1-046,
60.2594,Event,ADDED,eval-sanitize-20-r1-046.18d41aa8c4dd50bc,reason=SuccessfulCreate count=1 msg=Created pod: eval-sanitize-20-r1-046-mlxd2
60.2596,Event,ADDED,eval-sanitize-20-r1-047-sffms.18d41aa90531266f,reason=Scheduled count=None msg=Successfully assigned compute/eval-sanitize-20-r1-047-sffms to kind-worker4
60.2597,Event,ADDED,eval-sanitize-20-r1-047-sffms.18d41aa91e89e876,"reason=Pulled count=1 msg=Container image ""busybox:musl"" already present on machine"
60.2599,Event,ADDED,eval-sanitize-20-r1-047-sffms.18d41aa91f9cc492,reason=Created count=1 msg=Created container: task
60.2603,Event,ADDED,eval-sanitize-20-r1-047-sffms.18d41aa921b20428,reason=Started count=1 msg=Started container task
60.2605,Event,ADDED,eval-sanitize-20-r1-047.18d41aa901004ddd,reason=SuccessfulCreate count=1 msg=Created pod: eval-sanitize-20-r1-047-sffms
60.2606,Event,ADDED,eval-sanitize-20-r1-048-6wbxl.18d41aa9484816c9,reason=Scheduled count=None msg=Successfully assigned compute/eval-sanitize-20-r1-048-6wbxl to kind-worker4
60.2614,Job,MODIFIED,eval-sanitize-20-r1-046,
60.2617,Event,ADDED,eval-sanitize-20-r1-048-6wbxl.18d41aa9628157bf,"reason=Pulled count=1 msg=Container image ""busybox:musl"" already present on machine"
60.2619,Event,ADDED,eval-sanitize-20-r1-048-6wbxl.18d41aa963e9f624,reason=Created count=1 msg=Created container: task
60.2621,Event,ADDED,eval-sanitize-20-r1-048-6wbxl.18d41aa9680be022,reason=Started count=1 msg=Started container task
60.2622,Event,ADDED,eval-sanitize-20-r1-048.18d41aa943b3d06f,reason=SuccessfulCreate count=1 msg=Created pod: eval-sanitize-20-r1-048-6wbxl
60.2625,Event,ADDED,eval-sanitize-20-r1-049-88mmc.18d41aa9a1c6d26f,reason=Scheduled count=None msg=Successfully assigned compute/eval-sanitize-20-r1-049-88mmc to kind-worker
60.2627,Event,ADDED,eval-sanitize-20-r1-049-88mmc.18d41aa9bb005f52,"reason=Pulled count=1 msg=Container image ""busybox:musl"" already present on machine"
60.2629,Event,ADDED,eval-sanitize-20-r1-049-88mmc.18d41aa9bc23ec1e,reason=Created count=1 msg=Created container: task
60.2631,Event,ADDED,eval-sanitize-20-r1-049-88mmc.18d41aa9be464c3d,reason=Started count=1 msg=Started container task
60.2634,Event,ADDED,eval-sanitize-20-r1-049.18d41aa9a02d13b6,reason=SuccessfulCreate count=1 msg=Created pod: eval-sanitize-20-r1-049-88mmc
60.2637,Event,ADDED,eval-sanitize-20-r1-050-pvcrv.18d41aaa0abfadbe,reason=Scheduled count=None msg=Successfully assigned compute/eval-sanitize-20-r1-050-pvcrv to kind-worker4
60.2639,Event,ADDED,eval-sanitize-20-r1-050-pvcrv.18d41aaa23f6f48b,"reason=Pulled count=1 msg=Container image ""busybox:musl"" already present on machine"
60.2641,Event,ADDED,eval-sanitize-20-r1-050-pvcrv.18d41aaa250bdb83,reason=Created count=1 msg=Created container: task
60.2644,Event,ADDED,eval-sanitize-20-r1-050-pvcrv.18d41aaa26f4c22d,reason=Started count=1 msg=Started container task
60.2646,Event,ADDED,eval-sanitize-20-r1-050.18d41aaa0928ef88,reason=SuccessfulCreate count=1 msg=Created pod: eval-sanitize-20-r1-050-pvcrv
60.2647,Event,ADDED,eval-sanitize-20-r1-051-dx4xm.18d41aaa471c85a9,reason=Scheduled count=None msg=Successfully assigned compute/eval-sanitize-20-r1-051-dx4xm to kind-worker3
60.265,Event,ADDED,eval-sanitize-20-r1-051-dx4xm.18d41aaa6175f91c,"reason=Pulled count=1 msg=Container image ""busybox:musl"" already present on machine"
60.2652,Event,ADDED,eval-sanitize-20-r1-051-dx4xm.18d41aaa628166ed,reason=Created count=1 msg=Created container: task
60.2654,Event,ADDED,eval-sanitize-20-r1-051-dx4xm.18d41aaa6643424d,reason=Started count=1 msg=Started container task
60.2656,Event,ADDED,eval-sanitize-20-r1-051.18d41aaa44459652,reason=SuccessfulCreate count=1 msg=Created pod: eval-sanitize-20-r1-051-dx4xm
60.2659,Event,ADDED,eval-sanitize-20-r1-052-m54h2.18d41aaa7cbbe3b7,reason=Scheduled count=None msg=Successfully assigned compute/eval-sanitize-20-r1-052-m54h2 to kind-worker5
60.2661,Event,ADDED,eval-sanitize-20-r1-052-m54h2.18d41aaa961e8a94,"reason=Pulled count=1 msg=Container image ""busybox:musl"" already present on machine"
60.2663,Event,ADDED,eval-sanitize-20-r1-052-m54h2.18d41aaa97385c1c,reason=Created count=1 msg=Created container: task
60.2666,Event,ADDED,eval-sanitize-20-r1-052-m54h2.18d41aaa99258b88,reason=Started count=1 msg=Started container task
60.2668,Event,ADDED,eval-sanitize-20-r1-052.18d41aaa79dd5454,reason=SuccessfulCreate count=1 msg=Created pod: eval-sanitize-20-r1-052-m54h2
60.267,Event,ADDED,eval-sanitize-20-r1-053-btx8q.18d41aaa9e570716,reason=Scheduled count=None msg=Successfully assigned compute/eval-sanitize-20-r1-053-btx8q to kind-worker4
60.2672,Event,ADDED,eval-sanitize-20-r1-053-btx8q.18d41aaab83750ff,"reason=Pulled count=1 msg=Container image ""busybox:musl"" already present on machine"
60.2675,Event,ADDED,eval-sanitize-20-r1-053-btx8q.18d41aaab9643f93,reason=Created count=1 msg=Created container: task
60.2678,Event,ADDED,eval-sanitize-20-r1-053-btx8q.18d41aaabb73d4c4,reason=Started count=1 msg=Started container task
60.2679,Event,ADDED,eval-sanitize-20-r1-053.18d41aaa9cbf837b,reason=SuccessfulCreate count=1 msg=Created pod: eval-sanitize-20-r1-053-btx8q
60.2682,Event,ADDED,eval-sanitize-20-r1-054-m6l4n.18d41aaad0e3054e,reason=Scheduled count=None msg=Successfully assigned compute/eval-sanitize-20-r1-054-m6l4n to kind-worker4
60.2684,Event,ADDED,eval-sanitize-20-r1-054-m6l4n.18d41aaaeab8f673,"reason=Pulled count=1 msg=Container image ""busybox:musl"" already present on machine"
60.2686,Event,ADDED,eval-sanitize-20-r1-054-m6l4n.18d41aaaebf0bbc4,reason=Created count=1 msg=Created container: task
60.2688,Event,ADDED,eval-sanitize-20-r1-054-m6l4n.18d41aaaefdc1210,reason=Started count=1 msg=Started container task
60.2691,Event,ADDED,eval-sanitize-20-r1-054.18d41aaacf99c3e4,reason=SuccessfulCreate count=1 msg=Created pod: eval-sanitize-20-r1-054-m6l4n
60.2693,Event,ADDED,eval-sanitize-20-r1-055-bzm98.18d41aab08a043e7,"reason=FailedScheduling count=None msg=0/6 nodes are available: 3 c_wall violated: 1 conflicting context pair(s) with node memory, 3 node(s) had untolerated taint(s). no new claims to deallocate, preemption: 0/6 nodes are available: 3 No preemption victims found for incoming pod, 3 Preemption is not helpful for scheduling."
60.2695,Event,ADDED,eval-sanitize-20-r1-055-bzm98.18d41aab0b863768,"reason=FailedScheduling count=None msg=0/6 nodes are available: 3 c_wall violated: 1 conflicting context pair(s) with node memory, 3 node(s) had untolerated taint(s). no new claims to deallocate, preemption: 0/6 nodes are available: 3 No preemption victims found for incoming pod, 3 Preemption is not helpful for scheduling."
60.2698,Event,ADDED,eval-sanitize-20-r1-055-bzm98.18d41aab1138d594,"reason=FailedScheduling count=None msg=0/6 nodes are available: 2 c_wall violated: 1 conflicting context pair(s) with node memory, 4 node(s) had untolerated taint(s). no new claims to deallocate, preemption: 0/6 nodes are available: 2 No preemption victims found for incoming pod, 4 Preemption is not helpful for scheduling."
60.27,Event,ADDED,eval-sanitize-20-r1-055-bzm98.18d41aab5fdcc691,"reason=FailedScheduling count=None msg=0/6 nodes are available: 1 c_wall violated: 1 conflicting context pair(s) with node memory, 5 node(s) had untolerated taint(s). no new claims to deallocate, preemption: 0/6 nodes are available: 1 No preemption victims found for incoming pod, 5 Preemption is not helpful for scheduling."
60.2702,Event,ADDED,eval-sanitize-20-r1-055-bzm98.18d41aab609283a9,"reason=FailedScheduling count=None msg=0/6 nodes are available: 1 c_wall violated: 1 conflicting context pair(s) with node memory, 5 node(s) had untolerated taint(s). no new claims to deallocate, preemption: 0/6 nodes are available: 1 No preemption victims found for incoming pod, 5 Preemption is not helpful for scheduling."
60.2705,Event,ADDED,eval-sanitize-20-r1-055.18d41aab080a5b2c,reason=SuccessfulCreate count=1 msg=Created pod: eval-sanitize-20-r1-055-bzm98
60.2707,Event,ADDED,eval-sanitize-20-r1-056-sqhx4.18d41aab29bf794e,"reason=FailedScheduling count=None msg=0/6 nodes are available: 2 c_wall violated: 1 conflicting context pair(s) with node memory, 4 node(s) had untolerated taint(s). no new claims to deallocate, preemption: 0/6 nodes are available: 2 No preemption victims found for incoming pod, 4 Preemption is not helpful for scheduling."
60.2709,Event,ADDED,eval-sanitize-20-r1-056-sqhx4.18d41aab2a9edaa1,"reason=FailedScheduling count=None msg=0/6 nodes are available: 2 c_wall violated: 1 conflicting context pair(s) with node memory, 4 node(s) had untolerated taint(s). no new claims to deallocate, preemption: 0/6 nodes are available: 2 No preemption victims found for incoming pod, 4 Preemption is not helpful for scheduling."
60.2711,Event,ADDED,eval-sanitize-20-r1-056-sqhx4.18d41aab5f696e80,"reason=FailedScheduling count=None msg=0/6 nodes are available: 1 c_wall violated: 1 conflicting context pair(s) with node memory, 5 node(s) had untolerated taint(s). no new claims to deallocate, preemption: 0/6 nodes are available: 1 No preemption victims found for incoming pod, 5 Preemption is not helpful for scheduling."
60.2714,Event,ADDED,eval-sanitize-20-r1-056-sqhx4.18d41aab606b2c56,"reason=FailedScheduling count=None msg=0/6 nodes are available: 1 c_wall violated: 1 conflicting context pair(s) with node memory, 5 node(s) had untolerated taint(s). no new claims to deallocate, preemption: 0/6 nodes are available: 1 No preemption victims found for incoming pod, 5 Preemption is not helpful for scheduling."
60.2717,Event,ADDED,eval-sanitize-20-r1-056.18d41aab295e812a,reason=SuccessfulCreate count=1 msg=Created pod: eval-sanitize-20-r1-056-sqhx4
60.2719,Event,ADDED,eval-sanitize-20-r1-057-rkz4v.18d41aab5cc34f01,reason=Scheduled count=None msg=Successfully assigned compute/eval-sanitize-20-r1-057-rkz4v to kind-worker2
60.2722,Event,ADDED,eval-sanitize-20-r1-057-rkz4v.18d41aab76afad54,"reason=Pulled count=1 msg=Container image ""busybox:musl"" already present on machine"
60.2724,Event,ADDED,eval-sanitize-20-r1-057-rkz4v.18d41aab780b7494,reason=Created count=1 msg=Created container: task
60.2725,Event,ADDED,eval-sanitize-20-r1-057-rkz4v.18d41aab7bc9348a,reason=Started count=1 msg=Started container task
60.2728,Event,ADDED,eval-sanitize-20-r1-057.18d41aab5bb44f43,reason=SuccessfulCreate count=1 msg=Created pod: eval-sanitize-20-r1-057-rkz4v
60.273,Event,ADDED,eval-sanitize-20-r1-058-d9b2t.18d41aab90995349,"reason=FailedScheduling count=None msg=0/6 nodes are available: 6 node(s) had untolerated taint(s). no new claims to deallocate, preemption: 0/6 nodes are available: 6 Preemption is not helpful for scheduling."
60.2732,Event,ADDED,eval-sanitize-20-r1-058.18d41aab908ddf1d,reason=SuccessfulCreate count=1 msg=Created pod: eval-sanitize-20-r1-058-d9b2t
60.2734,Event,ADDED,eval-sanitize-20-r1-059-vz4jf.18d41aabcced1440,"reason=FailedScheduling count=None msg=0/6 nodes are available: 6 node(s) had untolerated taint(s). no new claims to deallocate, preemption: 0/6 nodes are available: 6 Preemption is not helpful for scheduling."
60.2737,Event,ADDED,eval-sanitize-20-r1-059.18d41aabccddf256,reason=SuccessfulCreate count=1 msg=Created pod: eval-sanitize-20-r1-059-vz4jf
60.2741,Event,ADDED,eval-sanitize-20-r1-060.18d41aac07b8c4cf,reason=SuccessfulCreate count=1 msg=Created pod: eval-sanitize-20-r1-060-nkffm
60.2744,Event,ADDED,eval-sanitize-20-r1-060-nkffm.18d41aac07c5673c,"reason=FailedScheduling count=None msg=0/6 nodes are available: 6 node(s) had untolerated taint(s). no new claims to deallocate, preemption: 0/6 nodes are available: 6 Preemption is not helpful for scheduling."
60.2747,Event,ADDED,eval-sanitize-20-r1-046.18d41aac100ea01c,reason=Completed count=1 msg=Job completed
60.7574,Pod,MODIFIED,eval-sanitize-20-r1-049-88mmc,phase=Running node=kind-worker
61.0084,TaskRequest,ADDED,eval-sanitize-20-r1-061,phase=None job=None
61.0118,TaskRequest,MODIFIED,eval-sanitize-20-r1-061,phase=Pending job=None
61.0277,Job,ADDED,eval-sanitize-20-r1-061,
61.0306,TaskRequest,MODIFIED,eval-sanitize-20-r1-061,phase=Scheduled job=None
61.0349,Pod,ADDED,eval-sanitize-20-r1-061-sjpk6,phase=Pending node=None
61.0372,Job,MODIFIED,eval-sanitize-20-r1-061,
61.0386,TaskRequest,MODIFIED,eval-sanitize-20-r1-061,phase=Scheduled job=None
61.041,Event,ADDED,eval-sanitize-20-r1-061.18d41aac4305c081,reason=SuccessfulCreate count=1 msg=Created pod: eval-sanitize-20-r1-061-sjpk6
61.0418,Pod,MODIFIED,eval-sanitize-20-r1-061-sjpk6,phase=Pending node=None
61.0423,Event,ADDED,eval-sanitize-20-r1-061-sjpk6.18d41aac43156f8a,"reason=FailedScheduling count=None msg=0/6 nodes are available: 6 node(s) had untolerated taint(s). no new claims to deallocate, preemption: 0/6 nodes are available: 6 Preemption is not helpful for scheduling."
61.0447,Job,MODIFIED,eval-sanitize-20-r1-060,
61.0529,Job,MODIFIED,eval-sanitize-20-r1-060,
61.1651,Job,MODIFIED,eval-sanitize-20-r1-048,
61.167,Job,MODIFIED,eval-sanitize-20-r1-047,
61.1702,Job,MODIFIED,eval-sanitize-20-r1-047,
61.1736,Pod,MODIFIED,eval-sanitize-20-r1-048-6wbxl,phase=Succeeded node=kind-worker4
61.1753,Job,MODIFIED,eval-sanitize-20-r1-048,
61.1765,Event,ADDED,eval-sanitize-20-r1-047.18d41aac4b19cb45,reason=Completed count=1 msg=Job completed
61.1838,Job,MODIFIED,eval-sanitize-20-r1-047,
61.1886,TaskRequest,MODIFIED,eval-sanitize-20-r1-047,phase=Complete job=None
61.1973,Job,MODIFIED,eval-sanitize-20-r1-047,
61.7693,Job,MODIFIED,eval-sanitize-20-r1-049,
61.7783,Job,MODIFIED,eval-sanitize-20-r1-049,
61.8359,Pod,MODIFIED,eval-sanitize-20-r1-049-88mmc,phase=Succeeded node=kind-worker
62.0083,TaskRequest,ADDED,eval-sanitize-20-r1-062,phase=None job=None
62.0133,TaskRequest,MODIFIED,eval-sanitize-20-r1-062,phase=Pending job=None
62.0286,Job,ADDED,eval-sanitize-20-r1-062,
62.0356,Pod,ADDED,eval-sanitize-20-r1-062-j6dn5,phase=Pending node=None
62.0367,TaskRequest,MODIFIED,eval-sanitize-20-r1-062,phase=Scheduled job=None
62.0394,Job,MODIFIED,eval-sanitize-20-r1-062,
62.0413,Event,ADDED,eval-sanitize-20-r1-062.18d41aac7eaa240d,reason=SuccessfulCreate count=1 msg=Created pod: eval-sanitize-20-r1-062-j6dn5
62.042,Job,MODIFIED,eval-sanitize-20-r1-061,
62.0428,Pod,MODIFIED,eval-sanitize-20-r1-062-j6dn5,phase=Pending node=None
62.0431,Event,ADDED,eval-sanitize-20-r1-062-j6dn5.18d41aac7eb718c7,"reason=FailedScheduling count=None msg=0/6 nodes are available: 6 node(s) had untolerated taint(s). no new claims to deallocate, preemption: 0/6 nodes are available: 6 Preemption is not helpful for scheduling."
62.0463,TaskRequest,MODIFIED,eval-sanitize-20-r1-062,phase=Scheduled job=None
62.0501,Job,MODIFIED,eval-sanitize-20-r1-061,
62.1594,Pod,MODIFIED,eval-sanitize-20-r1-050-pvcrv,phase=Running node=kind-worker4
62.1696,Job,MODIFIED,eval-sanitize-20-r1-048,
62.1737,Job,MODIFIED,eval-sanitize-20-r1-048,
62.1768,Event,ADDED,eval-sanitize-20-r1-048.18d41aac86e8604a,reason=Completed count=1 msg=Job completed
62.1854,Job,MODIFIED,eval-sanitize-20-r1-048,
62.19,TaskRequest,MODIFIED,eval-sanitize-20-r1-048,phase=Complete job=None
62.1992,Job,MODIFIED,eval-sanitize-20-r1-048,
62.7789,Job,MODIFIED,eval-sanitize-20-r1-049,
62.7885,Pod,MODIFIED,eval-sanitize-20-r1-049-88mmc,phase=Succeeded node=kind-worker
62.7903,Job,MODIFIED,eval-sanitize-20-r1-049,
63.0087,TaskRequest,ADDED,eval-sanitize-20-r1-063,phase=None job=None
63.0124,TaskRequest,MODIFIED,eval-sanitize-20-r1-063,phase=Pending job=None
63.0289,Job,ADDED,eval-sanitize-20-r1-063,
63.0354,Pod,ADDED,eval-sanitize-20-r1-063-9s6g7,phase=Pending node=None
63.0356,TaskRequest,MODIFIED,eval-sanitize-20-r1-063,phase=Scheduled job=None
63.0383,Job,MODIFIED,eval-sanitize-20-r1-063,
63.0412,Event,ADDED,eval-sanitize-20-r1-063.18d41aacba417b2e,reason=SuccessfulCreate count=1 msg=Created pod: eval-sanitize-20-r1-063-9s6g7
63.042,Job,MODIFIED,eval-sanitize-20-r1-062,
63.043,Pod,MODIFIED,eval-sanitize-20-r1-063-9s6g7,phase=Pending node=None
63.0434,Event,ADDED,eval-sanitize-20-r1-063-9s6g7.18d41aacba4983af,"reason=FailedScheduling count=None msg=0/6 nodes are available: 6 node(s) had untolerated taint(s). no new claims to deallocate, preemption: 0/6 nodes are available: 6 Preemption is not helpful for scheduling."
63.0435,TaskRequest,MODIFIED,eval-sanitize-20-r1-063,phase=Scheduled job=None
63.0516,Job,MODIFIED,eval-sanitize-20-r1-062,
63.1697,Job,MODIFIED,eval-sanitize-20-r1-050,
63.1799,Job,MODIFIED,eval-sanitize-20-r1-050,
63.301,Pod,MODIFIED,eval-sanitize-20-r1-050-pvcrv,phase=Succeeded node=kind-worker4
63.6983,Pod,MODIFIED,eval-sanitize-20-r1-051-dx4xm,phase=Running node=kind-worker3
63.7861,Job,MODIFIED,eval-sanitize-20-r1-049,
63.7909,Job,MODIFIED,eval-sanitize-20-r1-049,
63.7959,Event,ADDED,eval-sanitize-20-r1-049.18d41aace74cc152,reason=Completed count=1 msg=Job completed
63.8059,Job,MODIFIED,eval-sanitize-20-r1-049,
63.8125,TaskRequest,MODIFIED,eval-sanitize-20-r1-049,phase=Complete job=None
63.8226,Job,MODIFIED,eval-sanitize-20-r1-049,
64.0101,TaskRequest,ADDED,eval-sanitize-20-r1-064,phase=None job=None
64.014,TaskRequest,MODIFIED,eval-sanitize-20-r1-064,phase=Pending job=None
64.0298,Job,ADDED,eval-sanitize-20-r1-064,
64.036,Pod,ADDED,eval-sanitize-20-r1-064-nlrbv,phase=Pending node=None
64.0379,TaskRequest,MODIFIED,eval-sanitize-20-r1-064,phase=Scheduled job=None
64.0386,Job,MODIFIED,eval-sanitize-20-r1-064,
64.041,Job,MODIFIED,eval-sanitize-20-r1-063,
64.0426,Event,ADDED,eval-sanitize-20-r1-064.18d41aacf5e79e5b,reason=SuccessfulCreate count=1 msg=Created pod: eval-sanitize-20-r1-064-nlrbv
64.043,Event,ADDED,eval-sanitize-20-r1-064-nlrbv.18d41aacf5f32817,"reason=FailedScheduling count=None msg=0/6 nodes are available: 6 node(s) had untolerated taint(s). no new claims to deallocate, preemption: 0/6 nodes are available: 6 Preemption is not helpful for scheduling."
64.0441,Pod,MODIFIED,eval-sanitize-20-r1-064-nlrbv,phase=Pending node=None
64.0479,TaskRequest,MODIFIED,eval-sanitize-20-r1-064,phase=Scheduled job=None
64.0507,Job,MODIFIED,eval-sanitize-20-r1-063,
64.1772,Job,MODIFIED,eval-sanitize-20-r1-050,
64.1863,Pod,MODIFIED,eval-sanitize-20-r1-050-pvcrv,phase=Succeeded node=kind-worker4
64.1886,Job,MODIFIED,eval-sanitize-20-r1-050,
64.3223,Pod,MODIFIED,eval-sanitize-20-r1-052-m54h2,phase=Running node=kind-worker5
64.7052,Job,MODIFIED,eval-sanitize-20-r1-051,
64.7165,Job,MODIFIED,eval-sanitize-20-r1-051,
64.8051,Pod,MODIFIED,eval-sanitize-20-r1-051-dx4xm,phase=Succeeded node=kind-worker3
65.0081,TaskRequest,ADDED,eval-sanitize-20-r1-065,phase=None job=None
65.0124,TaskRequest,MODIFIED,eval-sanitize-20-r1-065,phase=Pending job=None
65.0294,Job,ADDED,eval-sanitize-20-r1-065,
65.0379,Pod,ADDED,eval-sanitize-20-r1-065-jxz5x,phase=Pending node=None
65.0383,TaskRequest,MODIFIED,eval-sanitize-20-r1-065,phase=Scheduled job=None
65.0393,Job,MODIFIED,eval-sanitize-20-r1-065,
65.0436,Event,ADDED,eval-sanitize-20-r1-065.18d41aad319096d8,reason=SuccessfulCreate count=1 msg=Created pod: eval-sanitize-20-r1-065-jxz5x
65.0439,Event,ADDED,eval-sanitize-20-r1-065-jxz5x.18d41aad319c4785,"reason=FailedScheduling count=None msg=0/6 nodes are available: 6 node(s) had untolerated taint(s). no new claims to deallocate, preemption: 0/6 nodes are available: 6 Preemption is not helpful for scheduling."
65.0447,Job,MODIFIED,eval-sanitize-20-r1-064,
65.0457,Pod,MODIFIED,eval-sanitize-20-r1-065-jxz5x,phase=Pending node=None
65.0475,TaskRequest,MODIFIED,eval-sanitize-20-r1-065,phase=Scheduled job=None
65.0537,Job,MODIFIED,eval-sanitize-20-r1-064,
65.1723,Pod,MODIFIED,eval-sanitize-20-r1-053-btx8q,phase=Running node=kind-worker4
65.1827,Job,MODIFIED,eval-sanitize-20-r1-050,
65.1877,Job,MODIFIED,eval-sanitize-20-r1-050,
65.194,Event,ADDED,eval-sanitize-20-r1-050.18d41aad3a8e8d05,reason=Completed count=1 msg=Job completed
65.1994,Job,MODIFIED,eval-sanitize-20-r1-050,
65.2051,TaskRequest,MODIFIED,eval-sanitize-20-r1-050,phase=Complete job=None
65.2154,Job,MODIFIED,eval-sanitize-20-r1-050,
65.3303,Job,MODIFIED,eval-sanitize-20-r1-052,
65.3414,Job,MODIFIED,eval-sanitize-20-r1-052,
65.4938,Pod,MODIFIED,eval-sanitize-20-r1-052-m54h2,phase=Succeeded node=kind-worker5
65.7129,Job,MODIFIED,eval-sanitize-20-r1-051,
65.7224,Pod,MODIFIED,eval-sanitize-20-r1-051-dx4xm,phase=Succeeded node=kind-worker3
65.7238,Job,MODIFIED,eval-sanitize-20-r1-051,
65.9527,Node,MODIFIED,kind-worker2,taints=1
66.0099,TaskRequest,ADDED,eval-sanitize-20-r1-066,phase=None job=None
66.0138,TaskRequest,MODIFIED,eval-sanitize-20-r1-066,phase=Pending job=None
66.0299,Job,ADDED,eval-sanitize-20-r1-066,
66.0356,TaskRequest,MODIFIED,eval-sanitize-20-r1-066,phase=Scheduled job=None
66.038,Pod,ADDED,eval-sanitize-20-r1-066-mp8pn,phase=Pending node=None
66.0405,Job,MODIFIED,eval-sanitize-20-r1-066,
66.0428,Job,MODIFIED,eval-sanitize-20-r1-065,
66.0445,Event,ADDED,eval-sanitize-20-r1-066.18d41aad6d3f9dc2,reason=SuccessfulCreate count=1 msg=Created pod: eval-sanitize-20-r1-066-mp8pn
66.0447,Event,ADDED,eval-sanitize-20-r1-066-mp8pn.18d41aad6d4d6cdb,"reason=FailedScheduling count=None msg=0/6 nodes are available: 6 node(s) had untolerated taint(s). no new claims to deallocate, preemption: 0/6 nodes are available: 6 Preemption is not helpful for scheduling."
66.0448,TaskRequest,MODIFIED,eval-sanitize-20-r1-066,phase=Scheduled job=None
66.0457,Pod,MODIFIED,eval-sanitize-20-r1-066-mp8pn,phase=Pending node=None
66.0522,Job,MODIFIED,eval-sanitize-20-r1-065,
66.1733,Pod,MODIFIED,eval-sanitize-20-r1-054-m6l4n,phase=Running node=kind-worker4
66.1777,Job,MODIFIED,eval-sanitize-20-r1-053,
66.1872,Job,MODIFIED,eval-sanitize-20-r1-053,
66.3378,Job,MODIFIED,eval-sanitize-20-r1-052,
66.3478,Pod,MODIFIED,eval-sanitize-20-r1-052-m54h2,phase=Succeeded node=kind-worker5
66.3486,Job,MODIFIED,eval-sanitize-20-r1-052,
66.3894,Pod,MODIFIED,eval-sanitize-20-r1-053-btx8q,phase=Succeeded node=kind-worker4
66.7228,Job,MODIFIED,eval-sanitize-20-r1-051,
66.7279,Job,MODIFIED,eval-sanitize-20-r1-051,
66.7329,Event,ADDED,eval-sanitize-20-r1-051.18d41aad965d02e7,reason=Completed count=1 msg=Job completed
66.7381,Job,MODIFIED,eval-sanitize-20-r1-051,
66.743,TaskRequest,MODIFIED,eval-sanitize-20-r1-051,phase=Complete job=None
66.7554,Job,MODIFIED,eval-sanitize-20-r1-051,
67.0084,TaskRequest,ADDED,eval-sanitize-20-r1-067,phase=None job=None
67.0137,TaskRequest,MODIFIED,eval-sanitize-20-r1-067,phase=Pending job=None
67.0269,Job,ADDED,eval-sanitize-20-r1-067,
67.0335,Pod,ADDED,eval-sanitize-20-r1-067-wl7jk,phase=Pending node=None
67.0336,TaskRequest,MODIFIED,eval-sanitize-20-r1-067,phase=Scheduled job=None
67.0363,Job,MODIFIED,eval-sanitize-20-r1-067,
67.04,Event,ADDED,eval-sanitize-20-r1-067.18d41aada8923097,reason=SuccessfulCreate count=1 msg=Created pod: eval-sanitize-20-r1-067-wl7jk
67.0402,Event,ADDED,eval-sanitize-20-r1-067-wl7jk.18d41aada8a0a9f4,"reason=FailedScheduling count=None msg=0/6 nodes are available: 6 node(s) had untolerated taint(s). no new claims to deallocate, preemption: 0/6 nodes are available: 6 Preemption is not helpful for scheduling."
67.0411,Pod,MODIFIED,eval-sanitize-20-r1-067-wl7jk,phase=Pending node=None
67.0417,TaskRequest,MODIFIED,eval-sanitize-20-r1-067,phase=Scheduled job=None
67.0425,Job,MODIFIED,eval-sanitize-20-r1-066,
67.0517,Job,MODIFIED,eval-sanitize-20-r1-066,
67.1787,Job,MODIFIED,eval-sanitize-20-r1-054,
67.1831,Job,MODIFIED,eval-sanitize-20-r1-053,
67.1885,Job,MODIFIED,eval-sanitize-20-r1-054,
67.1941,Pod,MODIFIED,eval-sanitize-20-r1-053-btx8q,phase=Succeeded node=kind-worker4
67.1955,Job,MODIFIED,eval-sanitize-20-r1-053,
67.2642,Pod,MODIFIED,eval-sanitize-20-r1-054-m6l4n,phase=Succeeded node=kind-worker4
67.3444,Job,MODIFIED,eval-sanitize-20-r1-052,
67.3486,Job,MODIFIED,eval-sanitize-20-r1-052,
67.3517,Event,ADDED,eval-sanitize-20-r1-052.18d41aadbb5d8f29,reason=Completed count=1 msg=Job completed
67.3611,Job,MODIFIED,eval-sanitize-20-r1-052,
67.3651,TaskRequest,MODIFIED,eval-sanitize-20-r1-052,phase=Complete job=None
67.3744,Job,MODIFIED,eval-sanitize-20-r1-052,
68.0119,TaskRequest,ADDED,eval-sanitize-20-r1-068,phase=None job=None
68.0157,TaskRequest,MODIFIED,eval-sanitize-20-r1-068,phase=Pending job=None
68.0312,Job,ADDED,eval-sanitize-20-r1-068,
68.036,Pod,ADDED,eval-sanitize-20-r1-068-lnvtw,phase=Pending node=None
68.0374,TaskRequest,MODIFIED,eval-sanitize-20-r1-068,phase=Scheduled job=None
68.0382,Job,MODIFIED,eval-sanitize-20-r1-067,
68.0403,Job,MODIFIED,eval-sanitize-20-r1-068,
68.0418,Event,ADDED,eval-sanitize-20-r1-068.18d41aade4449df3,reason=SuccessfulCreate count=1 msg=Created pod: eval-sanitize-20-r1-068-lnvtw
68.0423,Event,ADDED,eval-sanitize-20-r1-068-lnvtw.18d41aade44edfb6,"reason=FailedScheduling count=None msg=0/6 nodes are available: 6 node(s) had untolerated taint(s). no new claims to deallocate, preemption: 0/6 nodes are available: 6 Preemption is not helpful for scheduling."
68.0432,Pod,MODIFIED,eval-sanitize-20-r1-068-lnvtw,phase=Pending node=None
68.0461,Job,MODIFIED,eval-sanitize-20-r1-068,
68.0463,TaskRequest,MODIFIED,eval-sanitize-20-r1-068,phase=Scheduled job=None
68.0489,Job,MODIFIED,eval-sanitize-20-r1-067,
68.0567,Job,MODIFIED,eval-sanitize-20-r1-068,
68.1847,Job,MODIFIED,eval-sanitize-20-r1-054,
68.189,Job,MODIFIED,eval-sanitize-20-r1-053,
68.1941,Pod,MODIFIED,eval-sanitize-20-r1-054-m6l4n,phase=Succeeded node=kind-worker4
68.1957,Job,MODIFIED,eval-sanitize-20-r1-053,
68.1968,Job,MODIFIED,eval-sanitize-20-r1-054,
68.1985,Event,ADDED,eval-sanitize-20-r1-053.18d41aadedc602ec,reason=Completed count=1 msg=Job completed
68.2034,Job,MODIFIED,eval-sanitize-20-r1-053,
68.2069,TaskRequest,MODIFIED,eval-sanitize-20-r1-053,phase=Complete job=None
68.2155,Job,MODIFIED,eval-sanitize-20-r1-053,
68.2334,Pod,MODIFIED,eval-sanitize-20-r1-057-rkz4v,phase=Running node=kind-worker2
69.0246,TaskRequest,ADDED,eval-sanitize-20-r1-069,phase=None job=None
69.0284,TaskRequest,MODIFIED,eval-sanitize-20-r1-069,phase=Pending job=None
69.048,Job,ADDED,eval-sanitize-20-r1-069,
69.0557,Pod,ADDED,eval-sanitize-20-r1-069-dxq4t,phase=Pending node=None
69.0558,TaskRequest,MODIFIED,eval-sanitize-20-r1-069,phase=Scheduled job=None
69.0591,Job,MODIFIED,eval-sanitize-20-r1-069,
69.0608,Event,ADDED,eval-sanitize-20-r1-069.18d41aae20fdbc07,reason=SuccessfulCreate count=1 msg=Created pod: eval-sanitize-20-r1-069-dxq4t
69.0619,Pod,MODIFIED,eval-sanitize-20-r1-069-dxq4t,phase=Pending node=None
69.0627,Event,ADDED,eval-sanitize-20-r1-069-dxq4t.18d41aae2107de93,"reason=FailedScheduling count=None msg=0/6 nodes are available: 6 node(s) had untolerated taint(s). no new claims to deallocate, preemption: 0/6 nodes are available: 6 Preemption is not helpful for scheduling."
69.0636,TaskRequest,MODIFIED,eval-sanitize-20-r1-069,phase=Scheduled job=None
69.1916,Job,MODIFIED,eval-sanitize-20-r1-054,
69.1985,Job,MODIFIED,eval-sanitize-20-r1-054,
69.2045,Event,ADDED,eval-sanitize-20-r1-054.18d41aae298c2d3f,reason=Completed count=1 msg=Job completed
69.2114,Job,MODIFIED,eval-sanitize-20-r1-054,
69.2159,TaskRequest,MODIFIED,eval-sanitize-20-r1-054,phase=Complete job=None
69.2251,Job,MODIFIED,eval-sanitize-20-r1-054,
69.2384,Job,MODIFIED,eval-sanitize-20-r1-057,
69.2481,Job,MODIFIED,eval-sanitize-20-r1-057,
69.3459,Pod,MODIFIED,eval-sanitize-20-r1-057-rkz4v,phase=Succeeded node=kind-worker2
70.0083,TaskRequest,ADDED,eval-sanitize-20-r1-070,phase=None job=None
70.0128,TaskRequest,MODIFIED,eval-sanitize-20-r1-070,phase=Pending job=None
70.0289,Job,ADDED,eval-sanitize-20-r1-070,
70.0354,Pod,ADDED,eval-sanitize-20-r1-070-c8j2t,phase=Pending node=None
70.0367,TaskRequest,MODIFIED,eval-sanitize-20-r1-070,phase=Scheduled job=None
70.0376,Job,MODIFIED,eval-sanitize-20-r1-070,
70.0416,Event,ADDED,eval-sanitize-20-r1-070.18d41aae5b6c29a8,reason=SuccessfulCreate count=1 msg=Created pod: eval-sanitize-20-r1-070-c8j2t
70.042,Event,ADDED,eval-sanitize-20-r1-070-c8j2t.18d41aae5b7c6170,"reason=FailedScheduling count=None msg=0/6 nodes are available: 6 node(s) had untolerated taint(s). no new claims to deallocate, preemption: 0/6 nodes are available: 6 Preemption is not helpful for scheduling."
70.0434,Pod,MODIFIED,eval-sanitize-20-r1-070-c8j2t,phase=Pending node=None
70.0462,TaskRequest,MODIFIED,eval-sanitize-20-r1-070,phase=Scheduled job=None
70.0599,Job,MODIFIED,eval-sanitize-20-r1-069,
70.0692,Job,MODIFIED,eval-sanitize-20-r1-069,
70.245,Job,MODIFIED,eval-sanitize-20-r1-057,
70.2545,Pod,MODIFIED,eval-sanitize-20-r1-057-rkz4v,phase=Succeeded node=kind-worker2
70.2556,Job,MODIFIED,eval-sanitize-20-r1-057,
71.0083,TaskRequest,ADDED,eval-sanitize-20-r1-071,phase=None job=None
71.0136,TaskRequest,MODIFIED,eval-sanitize-20-r1-071,phase=Pending job=None
71.0286,Job,ADDED,eval-sanitize-20-r1-071,
71.0364,Pod,ADDED,eval-sanitize-20-r1-071-b576n,phase=Pending node=None
71.0365,TaskRequest,MODIFIED,eval-sanitize-20-r1-071,phase=Scheduled job=None
71.039,Job,MODIFIED,eval-sanitize-20-r1-071,
71.0413,Job,MODIFIED,eval-sanitize-20-r1-070,
71.0434,Event,ADDED,eval-sanitize-20-r1-071.18d41aae971663cd,reason=SuccessfulCreate count=1 msg=Created pod: eval-sanitize-20-r1-071-b576n
71.0438,Event,ADDED,eval-sanitize-20-r1-071-b576n.18d41aae971e120d,"reason=FailedScheduling count=None msg=0/6 nodes are available: 6 node(s) had untolerated taint(s). no new claims to deallocate, preemption: 0/6 nodes are available: 6 Preemption is not helpful for scheduling."
71.0448,Pod,MODIFIED,eval-sanitize-20-r1-071-b576n,phase=Pending node=None
71.046,TaskRequest,MODIFIED,eval-sanitize-20-r1-071,phase=Scheduled job=None
71.0512,Job,MODIFIED,eval-sanitize-20-r1-070,
71.2511,Job,MODIFIED,eval-sanitize-20-r1-057,
71.2557,Job,MODIFIED,eval-sanitize-20-r1-057,
71.2611,Event,ADDED,eval-sanitize-20-r1-057.18d41aaea432cd77,reason=Completed count=1 msg=Job completed
71.2673,Job,MODIFIED,eval-sanitize-20-r1-057,
71.2734,TaskRequest,MODIFIED,eval-sanitize-20-r1-057,phase=Complete job=None
71.2848,Job,MODIFIED,eval-sanitize-20-r1-057,
72.0105,TaskRequest,ADDED,eval-sanitize-20-r1-072,phase=None job=None
72.0142,TaskRequest,MODIFIED,eval-sanitize-20-r1-072,phase=Pending job=None
72.0308,Job,ADDED,eval-sanitize-20-r1-072,
72.0375,Pod,ADDED,eval-sanitize-20-r1-072-q7qwt,phase=Pending node=None
72.0376,TaskRequest,MODIFIED,eval-sanitize-20-r1-072,phase=Scheduled job=None
72.0407,Job,MODIFIED,eval-sanitize-20-r1-072,
72.043,Job,MODIFIED,eval-sanitize-20-r1-071,
72.0455,Pod,MODIFIED,eval-sanitize-20-r1-072-q7qwt,phase=Pending node=None
72.046,Event,ADDED,eval-sanitize-20-r1-072.18d41aaed2c5de22,reason=SuccessfulCreate count=1 msg=Created pod: eval-sanitize-20-r1-072-q7qwt
72.0462,Event,ADDED,eval-sanitize-20-r1-072-q7qwt.18d41aaed2d395f8,"reason=FailedScheduling count=None msg=0/6 nodes are available: 6 node(s) had untolerated taint(s). no new claims to deallocate, preemption: 0/6 nodes are available: 6 Preemption is not helpful for scheduling."
72.0463,TaskRequest,MODIFIED,eval-sanitize-20-r1-072,phase=Scheduled job=None
72.0523,Job,MODIFIED,eval-sanitize-20-r1-071,
73.0126,TaskRequest,ADDED,eval-sanitize-20-r1-073,phase=None job=None
73.0163,TaskRequest,MODIFIED,eval-sanitize-20-r1-073,phase=Pending job=None
73.0318,Job,ADDED,eval-sanitize-20-r1-073,
73.036,TaskRequest,MODIFIED,eval-sanitize-20-r1-073,phase=Scheduled job=None
73.0395,Pod,ADDED,eval-sanitize-20-r1-073-8t5bg,phase=Pending node=None
73.0409,Job,MODIFIED,eval-sanitize-20-r1-073,
73.043,Job,MODIFIED,eval-sanitize-20-r1-072,
73.0448,Event,ADDED,eval-sanitize-20-r1-073.18d41aaf0e79628e,reason=SuccessfulCreate count=1 msg=Created pod: eval-sanitize-20-r1-073-8t5bg
73.045,TaskRequest,MODIFIED,eval-sanitize-20-r1-073,phase=Scheduled job=None
73.0454,Event,ADDED,eval-sanitize-20-r1-073-8t5bg.18d41aaf0e84844e,"reason=FailedScheduling count=None msg=0/6 nodes are available: 6 node(s) had untolerated taint(s). no new claims to deallocate, preemption: 0/6 nodes are available: 6 Preemption is not helpful for scheduling."
73.0462,Pod,MODIFIED,eval-sanitize-20-r1-073-8t5bg,phase=Pending node=None
73.0519,Job,MODIFIED,eval-sanitize-20-r1-072,
74.0161,TaskRequest,ADDED,eval-sanitize-20-r1-074,phase=None job=None
74.0215,TaskRequest,MODIFIED,eval-sanitize-20-r1-074,phase=Pending job=None
74.0363,Job,ADDED,eval-sanitize-20-r1-074,
74.0425,Pod,ADDED,eval-sanitize-20-r1-074-4hsdp,phase=Pending node=None
74.0449,Job,MODIFIED,eval-sanitize-20-r1-073,
74.0449,TaskRequest,MODIFIED,eval-sanitize-20-r1-074,phase=Scheduled job=None
74.0469,Job,MODIFIED,eval-sanitize-20-r1-074,
74.0508,Event,ADDED,eval-sanitize-20-r1-074.18d41aaf4a4ca2a9,reason=SuccessfulCreate count=1 msg=Created pod: eval-sanitize-20-r1-074-4hsdp
74.0511,Event,ADDED,eval-sanitize-20-r1-074-4hsdp.18d41aaf4a560b62,"reason=FailedScheduling count=None msg=0/6 nodes are available: 6 node(s) had untolerated taint(s). no new claims to deallocate, preemption: 0/6 nodes are available: 6 Preemption is not helpful for scheduling."
74.0521,Pod,MODIFIED,eval-sanitize-20-r1-074-4hsdp,phase=Pending node=None
74.0534,TaskRequest,MODIFIED,eval-sanitize-20-r1-074,phase=Scheduled job=None
74.0562,Job,MODIFIED,eval-sanitize-20-r1-073,
74.7532,Node,MODIFIED,kind-worker,taints=1
74.8106,Node,MODIFIED,kind-worker,taints=0
74.8164,Pod,MODIFIED,eval-sanitize-20-r1-056-sqhx4,phase=Pending node=kind-worker
74.8209,Node,MODIFIED,kind-worker,taints=0
74.8232,Event,ADDED,eval-sanitize-20-r1-056-sqhx4.18d41aaf78691d53,reason=Scheduled count=None msg=Successfully assigned compute/eval-sanitize-20-r1-056-sqhx4 to kind-worker
74.8292,Pod,MODIFIED,eval-sanitize-20-r1-056-sqhx4,phase=Pending node=kind-worker
74.832,Node,MODIFIED,kind-worker,taints=0
74.8849,Pod,MODIFIED,eval-sanitize-20-r1-055-bzm98,phase=Pending node=kind-worker
74.8867,Pod,MODIFIED,eval-sanitize-20-r1-058-d9b2t,phase=Pending node=kind-worker
74.8903,Event,ADDED,eval-sanitize-20-r1-055-bzm98.18d41aaf7c77a69d,reason=Scheduled count=None msg=Successfully assigned compute/eval-sanitize-20-r1-055-bzm98 to kind-worker
74.8948,Event,ADDED,eval-sanitize-20-r1-059-vz4jf.18d41aaf7c97b2e0,"reason=FailedScheduling count=None msg=0/6 nodes are available: 1 c_wall violated: 1 conflicting context pair(s) with node memory, 5 node(s) had untolerated taint(s). no new claims to deallocate, preemption: 0/6 nodes are available: 1 No preemption victims found for incoming pod, 5 Preemption is not helpful for scheduling."
74.8951,Event,ADDED,eval-sanitize-20-r1-058-d9b2t.18d41aaf7c980b39,reason=Scheduled count=None msg=Successfully assigned compute/eval-sanitize-20-r1-058-d9b2t to kind-worker
74.8961,Pod,MODIFIED,eval-sanitize-20-r1-059-vz4jf,phase=Pending node=None
74.9015,Node,MODIFIED,kind-worker,taints=0
74.9043,Pod,MODIFIED,eval-sanitize-20-r1-055-bzm98,phase=Pending node=kind-worker
74.9057,Pod,MODIFIED,eval-sanitize-20-r1-060-nkffm,phase=Pending node=kind-worker
74.9089,Pod,MODIFIED,eval-sanitize-20-r1-061-sjpk6,phase=Pending node=None
74.9092,Event,ADDED,eval-sanitize-20-r1-061-sjpk6.18d41aaf7d8ed302,"reason=FailedScheduling count=None msg=0/6 nodes are available: 1 c_wall violated: 1 conflicting context pair(s) with node memory, 5 node(s) had untolerated taint(s). no new claims to deallocate, preemption: 0/6 nodes are available: 1 No preemption victims found for incoming pod, 5 Preemption is not helpful for scheduling."
74.9122,Event,ADDED,eval-sanitize-20-r1-060-nkffm.18d41aaf7dbe0afc,reason=Scheduled count=None msg=Successfully assigned compute/eval-sanitize-20-r1-060-nkffm to kind-worker
74.9141,Node,MODIFIED,kind-worker,taints=0
74.9163,Pod,MODIFIED,eval-sanitize-20-r1-058-d9b2t,phase=Pending node=kind-worker
74.9237,Pod,MODIFIED,eval-sanitize-20-r1-060-nkffm,phase=Pending node=kind-worker
74.9377,Pod,MODIFIED,eval-sanitize-20-r1-062-j6dn5,phase=Pending node=None
74.938,Event,ADDED,eval-sanitize-20-r1-062-j6dn5.18d41aaf7f59e7f8,"reason=FailedScheduling count=None msg=0/6 nodes are available: 1 c_wall violated: 1 conflicting context pair(s) with node memory, 5 node(s) had untolerated taint(s). no new claims to deallocate, preemption: 0/6 nodes are available: 1 No preemption victims found for incoming pod, 5 Preemption is not helpful for scheduling."
74.9432,Node,MODIFIED,kind-worker,taints=0
74.9532,Node,MODIFIED,kind-worker,taints=0
74.991,Pod,MODIFIED,eval-sanitize-20-r1-063-9s6g7,phase=Pending node=kind-worker
74.9929,Pod,MODIFIED,eval-sanitize-20-r1-064-nlrbv,phase=Pending node=kind-worker
74.9965,Pod,MODIFIED,eval-sanitize-20-r1-065-jxz5x,phase=Pending node=kind-worker
75.0033,Event,ADDED,eval-sanitize-20-r1-063-9s6g7.18d41aaf82cca858,reason=Scheduled count=None msg=Successfully assigned compute/eval-sanitize-20-r1-063-9s6g7 to kind-worker
75.0038,Event,ADDED,eval-sanitize-20-r1-064-nlrbv.18d41aaf82ee688d,reason=Scheduled count=None msg=Successfully assigned compute/eval-sanitize-20-r1-064-nlrbv to kind-worker
75.0054,Pod,MODIFIED,eval-sanitize-20-r1-066-mp8pn,phase=Pending node=kind-worker
75.0071,Event,ADDED,eval-sanitize-20-r1-065-jxz5x.18d41aaf832af2db,reason=Scheduled count=None msg=Successfully assigned compute/eval-sanitize-20-r1-065-jxz5x to kind-worker
75.0079,Pod,MODIFIED,eval-sanitize-20-r1-067-wl7jk,phase=Pending node=kind-worker
75.0088,Pod,MODIFIED,eval-sanitize-20-r1-068-lnvtw,phase=Pending node=kind-worker
75.0132,Pod,MODIFIED,eval-sanitize-20-r1-063-9s6g7,phase=Pending node=kind-worker
75.0269,Event,ADDED,eval-sanitize-20-r1-066-mp8pn.18d41aaf8396b2d1,reason=Scheduled count=None msg=Successfully assigned compute/eval-sanitize-20-r1-066-mp8pn to kind-worker
75.0272,Event,ADDED,eval-sanitize-20-r1-069-dxq4t.18d41aaf8397f814,"reason=FailedScheduling count=None msg=0/6 nodes are available: 1 c_wall violated: 2 conflicting context pair(s) with node memory, 5 node(s) had untolerated taint(s). no new claims to deallocate, preemption: 0/6 nodes are available: 1 No preemption victims found for incoming pod, 5 Preemption is not helpful for scheduling."
75.0286,Pod,MODIFIED,eval-sanitize-20-r1-069-dxq4t,phase=Pending node=None
75.0292,Event,ADDED,eval-sanitize-20-r1-068-lnvtw.18d41aaf83be2973,reason=Scheduled count=None msg=Successfully assigned compute/eval-sanitize-20-r1-068-lnvtw to kind-worker
75.0296,Event,ADDED,eval-sanitize-20-r1-067-wl7jk.18d41aaf83b95dba,reason=Scheduled count=None msg=Successfully assigned compute/eval-sanitize-20-r1-067-wl7jk to kind-worker
75.0319,Node,MODIFIED,kind-worker,taints=0
75.0365,Pod,MODIFIED,eval-sanitize-20-r1-065-jxz5x,phase=Pending node=kind-worker
75.0428,Node,MODIFIED,kind-worker,taints=0
75.0465,Pod,MODIFIED,eval-sanitize-20-r1-064-nlrbv,phase=Pending node=kind-worker
75.0493,Job,MODIFIED,eval-sanitize-20-r1-074,
75.0546,Pod,MODIFIED,eval-sanitize-20-r1-066-mp8pn,phase=Pending node=kind-worker
75.0584,Job,MODIFIED,eval-sanitize-20-r1-074,
75.0612,Pod,MODIFIED,eval-sanitize-20-r1-068-lnvtw,phase=Pending node=kind-worker
75.0669,Pod,MODIFIED,eval-sanitize-20-r1-067-wl7jk,phase=Pending node=kind-worker
75.0745,TaskRequest,ADDED,eval-sanitize-20-r1-075,phase=None job=None
75.0792,TaskRequest,MODIFIED,eval-sanitize-20-r1-075,phase=Pending job=None
75.0879,Pod,MODIFIED,eval-sanitize-20-r1-070-c8j2t,phase=Pending node=None
75.0882,Event,ADDED,eval-sanitize-20-r1-070-c8j2t.18d41aaf88532f42,"reason=FailedScheduling count=None msg=0/6 nodes are available: 1 c_wall violated: 2 conflicting context pair(s) with node memory, 5 node(s) had untolerated taint(s). no new claims to deallocate, preemption: 0/6 nodes are available: 1 No preemption victims found for incoming pod, 5 Preemption is not helpful for scheduling."
75.094,Job,ADDED,eval-sanitize-20-r1-075,
75.0957,Event,ADDED,eval-sanitize-20-r1-071-b576n.18d41aaf88cb9e84,"reason=FailedScheduling count=None msg=0/6 nodes are available: 1 c_wall violated: 2 conflicting context pair(s) with node memory, 5 node(s) had untolerated taint(s). no new claims to deallocate, preemption: 0/6 nodes are available: 1 No preemption victims found for incoming pod, 5 Preemption is not helpful for scheduling."
75.0966,Pod,MODIFIED,eval-sanitize-20-r1-071-b576n,phase=Pending node=None
75.1002,Pod,ADDED,eval-sanitize-20-r1-075-6hdmw,phase=Pending node=None
75.1004,TaskRequest,MODIFIED,eval-sanitize-20-r1-075,phase=Scheduled job=None
75.1066,Job,MODIFIED,eval-sanitize-20-r1-075,
75.1071,Event,ADDED,eval-sanitize-20-r1-072-q7qwt.18d41aaf894f9c92,"reason=FailedScheduling count=None msg=0/6 nodes are available: 1 c_wall violated: 2 conflicting context pair(s) with node memory, 5 node(s) had untolerated taint(s). no new claims to deallocate, preemption: 0/6 nodes are available: 1 No preemption victims found for incoming pod, 5 Preemption is not helpful for scheduling."
75.1073,Event,ADDED,eval-sanitize-20-r1-075.18d41aaf895a5127,reason=SuccessfulCreate count=1 msg=Created pod: eval-sanitize-20-r1-075-6hdmw
75.1081,Pod,MODIFIED,eval-sanitize-20-r1-072-q7qwt,phase=Pending node=None
75.109,TaskRequest,MODIFIED,eval-sanitize-20-r1-075,phase=Scheduled job=None
75.1157,Pod,MODIFIED,eval-sanitize-20-r1-075-6hdmw,phase=Pending node=kind-worker
75.1184,Pod,MODIFIED,eval-sanitize-20-r1-073-8t5bg,phase=Pending node=kind-worker
75.1257,Pod,MODIFIED,eval-sanitize-20-r1-075-6hdmw,phase=Pending node=kind-worker
75.1325,Pod,MODIFIED,eval-sanitize-20-r1-073-8t5bg,phase=Pending node=kind-worker
75.1919,Pod,MODIFIED,eval-sanitize-20-r1-074-4hsdp,phase=Pending node=None
75.1929,Event,ADDED,eval-sanitize-20-r1-075-6hdmw.18d41aaf8e0e75fe,reason=Scheduled count=None msg=Successfully assigned compute/eval-sanitize-20-r1-075-6hdmw to kind-worker
75.1931,Event,ADDED,eval-sanitize-20-r1-073-8t5bg.18d41aaf8e08ca2c,reason=Scheduled count=None msg=Successfully assigned compute/eval-sanitize-20-r1-073-8t5bg to kind-worker
75.1933,Event,ADDED,eval-sanitize-20-r1-074-4hsdp.18d41aaf8e0b7003,"reason=FailedScheduling count=None msg=0/6 nodes are available: 1 c_wall violated: 2 conflicting context pair(s) with node memory, 5 node(s) had untolerated taint(s). no new claims to deallocate, preemption: 0/6 nodes are available: 1 No preemption victims found for incoming pod, 5 Preemption is not helpful for scheduling."
75.201,Pod,MODIFIED,eval-sanitize-20-r1-059-vz4jf,phase=Pending node=None
75.2018,Event,ADDED,eval-sanitize-20-r1-059-vz4jf.18d41aaf8f069292,"reason=FailedScheduling count=None msg=0/6 nodes are available: 1 c_wall violated: 2 conflicting context pair(s) with node memory, 5 node(s) had untolerated taint(s). no new claims to deallocate, preemption: 0/6 nodes are available: 1 No preemption victims found for incoming pod, 5 Preemption is not helpful for scheduling."
75.2115,Pod,MODIFIED,eval-sanitize-20-r1-061-sjpk6,phase=Pending node=None
75.2118,Event,ADDED,eval-sanitize-20-r1-061-sjpk6.18d41aaf8f8a8d7e,"reason=FailedScheduling count=None msg=0/6 nodes are available: 1 c_wall violated: 2 conflicting context pair(s) with node memory, 5 node(s) had untolerated taint(s). no new claims to deallocate, preemption: 0/6 nodes are available: 1 No preemption victims found for incoming pod, 5 Preemption is not helpful for scheduling."
75.2225,Pod,MODIFIED,eval-sanitize-20-r1-062-j6dn5,phase=Pending node=None
75.223,Event,ADDED,eval-sanitize-20-r1-062-j6dn5.18d41aaf902957e1,"reason=FailedScheduling count=None msg=0/6 nodes are available: 1 c_wall violated: 2 conflicting context pair(s) with node memory, 5 node(s) had untolerated taint(s). no new claims to deallocate, preemption: 0/6 nodes are available: 1 No preemption victims found for incoming pod, 5 Preemption is not helpful for scheduling."
75.2305,Event,ADDED,eval-sanitize-20-r1-069-dxq4t.18d41aaf90cc68df,"reason=FailedScheduling count=None msg=0/6 nodes are available: 1 c_wall violated: 2 conflicting context pair(s) with node memory, 5 node(s) had untolerated taint(s). no new claims to deallocate, preemption: 0/6 nodes are available: 1 No preemption victims found for incoming pod, 5 Preemption is not helpful for scheduling."
75.2328,Event,ADDED,eval-sanitize-20-r1-070-c8j2t.18d41aaf9104acd4,"reason=FailedScheduling count=None msg=0/6 nodes are available: 1 c_wall violated: 2 conflicting context pair(s) with node memory, 5 node(s) had untolerated taint(s). no new claims to deallocate, preemption: 0/6 nodes are available: 1 No preemption victims found for incoming pod, 5 Preemption is not helpful for scheduling."
75.239,Event,ADDED,eval-sanitize-20-r1-071-b576n.18d41aaf91415639,"reason=FailedScheduling count=None msg=0/6 nodes are available: 1 c_wall violated: 2 conflicting context pair(s) with node memory, 5 node(s) had untolerated taint(s). no new claims to deallocate, preemption: 0/6 nodes are available: 1 No preemption victims found for incoming pod, 5 Preemption is not helpful for scheduling."
75.2472,Event,ADDED,eval-sanitize-20-r1-056-sqhx4.18d41aaf91d136e9,"reason=Pulled count=1 msg=Container image ""busybox:musl"" already present on machine"
75.28,Event,ADDED,eval-sanitize-20-r1-072-q7qwt.18d41aaf93bbadfc,"reason=FailedScheduling count=None msg=0/6 nodes are available: 1 c_wall violated: 2 conflicting context pair(s) with node memory, 5 node(s) had untolerated taint(s). no new claims to deallocate, preemption: 0/6 nodes are available: 1 No preemption victims found for incoming pod, 5 Preemption is not helpful for scheduling."
75.2855,Event,ADDED,eval-sanitize-20-r1-056-sqhx4.18d41aaf942087d2,reason=Created count=1 msg=Created container: task
75.3082,Event,ADDED,eval-sanitize-20-r1-055-bzm98.18d41aaf955819c7,"reason=Pulled count=1 msg=Container image ""busybox:musl"" already present on machine"
75.3139,Event,ADDED,eval-sanitize-20-r1-074-4hsdp.18d41aaf95a16ace,"reason=FailedScheduling count=None msg=0/6 nodes are available: 1 c_wall violated: 2 conflicting context pair(s) with node memory, 5 node(s) had untolerated taint(s). no new claims to deallocate, preemption: 0/6 nodes are available: 1 No preemption victims found for incoming pod, 5 Preemption is not helpful for scheduling."
75.3148,Event,ADDED,eval-sanitize-20-r1-059-vz4jf.18d41aaf95e3cb25,"reason=FailedScheduling count=None msg=0/6 nodes are available: 1 c_wall violated: 2 conflicting context pair(s) with node memory, 5 node(s) had untolerated taint(s). no new claims to deallocate, preemption: 0/6 nodes are available: 1 No preemption victims found for incoming pod, 5 Preemption is not helpful for scheduling."
75.3178,Event,ADDED,eval-sanitize-20-r1-061-sjpk6.18d41aaf96151266,"reason=FailedScheduling count=None msg=0/6 nodes are available: 1 c_wall violated: 2 conflicting context pair(s) with node memory, 5 node(s) had untolerated taint(s). no new claims to deallocate, preemption: 0/6 nodes are available: 1 No preemption victims found for incoming pod, 5 Preemption is not helpful for scheduling."
75.327,Event,ADDED,eval-sanitize-20-r1-062-j6dn5.18d41aaf964b0a8b,"reason=FailedScheduling count=None msg=0/6 nodes are available: 1 c_wall violated: 2 conflicting context pair(s) with node memory, 5 node(s) had untolerated taint(s). no new claims to deallocate, preemption: 0/6 nodes are available: 1 No preemption victims found for incoming pod, 5 Preemption is not helpful for scheduling."
75.3278,Event,ADDED,eval-sanitize-20-r1-058-d9b2t.18d41aaf96862634,"reason=Pulled count=1 msg=Container image ""busybox:musl"" already present on machine"
75.3324,Event,ADDED,eval-sanitize-20-r1-056-sqhx4.18d41aaf96cda10d,reason=Started count=1 msg=Started container task
75.3476,Event,ADDED,eval-sanitize-20-r1-060-nkffm.18d41aaf97ce788c,"reason=Pulled count=1 msg=Container image ""busybox:musl"" already present on machine"
75.3817,Event,ADDED,eval-sanitize-20-r1-055-bzm98.18d41aaf99be2645,reason=Created count=1 msg=Created container: task
75.4186,Event,ADDED,eval-sanitize-20-r1-058-d9b2t.18d41aaf9c0226a2,reason=Created count=1 msg=Created container: task
75.44,Event,ADDED,eval-sanitize-20-r1-060-nkffm.18d41aaf9d4b7e49,reason=Created count=1 msg=Created container: task
75.454,Event,ADDED,eval-sanitize-20-r1-055-bzm98.18d41aaf9e23fddf,reason=Started count=1 msg=Started container task
75.4632,Event,ADDED,eval-sanitize-20-r1-058-d9b2t.18d41aaf9eb3411c,reason=Started count=1 msg=Started container task
75.486,Event,ADDED,eval-sanitize-20-r1-063-9s6g7.18d41aaf9ff9fb49,"reason=Pulled count=1 msg=Container image ""busybox:musl"" already present on machine"
75.5119,Event,ADDED,eval-sanitize-20-r1-060-nkffm.18d41aafa1a086a7,reason=Started count=1 msg=Started container task
75.5203,Event,ADDED,eval-sanitize-20-r1-064-nlrbv.18d41aafa1f712f0,"reason=Pulled count=1 msg=Container image ""busybox:musl"" already present on machine"
75.5262,Event,ADDED,eval-sanitize-20-r1-063-9s6g7.18d41aafa27885ef,reason=Created count=1 msg=Created container: task
75.5394,Event,ADDED,eval-sanitize-20-r1-066-mp8pn.18d41aafa32939d6,"reason=Pulled count=1 msg=Container image ""busybox:musl"" already present on machine"
75.5451,Event,ADDED,eval-sanitize-20-r1-064-nlrbv.18d41aafa38afbea,reason=Created count=1 msg=Created container: task
75.5549,Event,ADDED,eval-sanitize-20-r1-065-jxz5x.18d41aafa3ac315d,"reason=Pulled count=1 msg=Container image ""busybox:musl"" already present on machine"
75.5595,Event,ADDED,eval-sanitize-20-r1-067-wl7jk.18d41aafa3cd92f6,"reason=Pulled count=1 msg=Container image ""busybox:musl"" already present on machine"
75.5667,Event,ADDED,eval-sanitize-20-r1-068-lnvtw.18d41aafa493badd,"reason=Pulled count=1 msg=Container image ""busybox:musl"" already present on machine"
75.574,Event,ADDED,eval-sanitize-20-r1-075-6hdmw.18d41aafa54bcb05,"reason=Pulled count=1 msg=Container image ""busybox:musl"" already present on machine"
75.5811,Event,ADDED,eval-sanitize-20-r1-063-9s6g7.18d41aafa5c49308,reason=Started count=1 msg=Started container task
75.5855,Event,ADDED,eval-sanitize-20-r1-064-nlrbv.18d41aafa5f42c49,reason=Started count=1 msg=Started container task
75.5947,Event,ADDED,eval-sanitize-20-r1-066-mp8pn.18d41aafa63a7308,reason=Created count=1 msg=Created container: task
75.5984,Event,ADDED,eval-sanitize-20-r1-073-8t5bg.18d41aafa661be17,"reason=Pulled count=1 msg=Container image ""busybox:musl"" already present on machine"
75.61,Event,ADDED,eval-sanitize-20-r1-067-wl7jk.18d41aafa7704e2e,reason=Created count=1 msg=Created container: task
75.6151,Event,ADDED,eval-sanitize-20-r1-065-jxz5x.18d41aafa79e3f02,reason=Created count=1 msg=Created container: task
75.6312,Event,ADDED,eval-sanitize-20-r1-075-6hdmw.18d41aafa8af21d6,reason=Created count=1 msg=Created container: task
75.6364,Event,ADDED,eval-sanitize-20-r1-068-lnvtw.18d41aafa8b1f788,reason=Created count=1 msg=Created container: task
75.6407,Event,ADDED,eval-sanitize-20-r1-066-mp8pn.18d41aafa8b61429,reason=Started count=1 msg=Started container task
75.6474,Event,ADDED,eval-sanitize-20-r1-073-8t5bg.18d41aafa91bcaf2,reason=Created count=1 msg=Created container: task
75.659,Event,ADDED,eval-sanitize-20-r1-067-wl7jk.18d41aafaa6b9319,reason=Started count=1 msg=Started container task
75.6654,Event,ADDED,eval-sanitize-20-r1-065-jxz5x.18d41aafaa6d5dc7,reason=Started count=1 msg=Started container task
75.6804,Event,ADDED,eval-sanitize-20-r1-068-lnvtw.18d41aafabb80be1,reason=Started count=1 msg=Started container task
75.6838,Event,ADDED,eval-sanitize-20-r1-075-6hdmw.18d41aafabb80bdc,reason=Started count=1 msg=Started container task
75.6875,Event,ADDED,eval-sanitize-20-r1-073-8t5bg.18d41aafabb8bebb,reason=Started count=1 msg=Started container task
75.7879,Pod,MODIFIED,eval-sanitize-20-r1-067-wl7jk,phase=Running node=kind-worker
75.797,Pod,MODIFIED,eval-sanitize-20-r1-073-8t5bg,phase=Running node=kind-worker
75.7988,Event,MODIFIED,eval-sanitize-20-r1-069-dxq4t.18d41aaf90cc68df,"reason=FailedScheduling count=None msg=0/6 nodes are available: 1 c_wall violated: 2 conflicting context pair(s) with node memory, 5 node(s) had untolerated taint(s). no new claims to deallocate, preemption: 0/6 nodes are available: 1 No preemption victims found for incoming pod, 5 Preemption is not helpful for scheduling."
75.8004,Event,MODIFIED,eval-sanitize-20-r1-070-c8j2t.18d41aaf9104acd4,"reason=FailedScheduling count=None msg=0/6 nodes are available: 1 c_wall violated: 2 conflicting context pair(s) with node memory, 5 node(s) had untolerated taint(s). no new claims to deallocate, preemption: 0/6 nodes are available: 1 No preemption victims found for incoming pod, 5 Preemption is not helpful for scheduling."
75.8044,Pod,MODIFIED,eval-sanitize-20-r1-056-sqhx4,phase=Running node=kind-worker
75.8069,Node,MODIFIED,kind-worker4,taints=1
75.8091,Event,MODIFIED,eval-sanitize-20-r1-071-b576n.18d41aaf91415639,"reason=FailedScheduling count=None msg=0/6 nodes are available: 1 c_wall violated: 2 conflicting context pair(s) with node memory, 5 node(s) had untolerated taint(s). no new claims to deallocate, preemption: 0/6 nodes are available: 1 No preemption victims found for incoming pod, 5 Preemption is not helpful for scheduling."
75.8118,Event,MODIFIED,eval-sanitize-20-r1-072-q7qwt.18d41aaf93bbadfc,"reason=FailedScheduling count=None msg=0/6 nodes are available: 1 c_wall violated: 2 conflicting context pair(s) with node memory, 5 node(s) had untolerated taint(s). no new claims to deallocate, preemption: 0/6 nodes are available: 1 No preemption victims found for incoming pod, 5 Preemption is not helpful for scheduling."
75.8133,Pod,MODIFIED,eval-sanitize-20-r1-065-jxz5x,phase=Running node=kind-worker
75.8153,Event,MODIFIED,eval-sanitize-20-r1-074-4hsdp.18d41aaf95a16ace,"reason=FailedScheduling count=None msg=0/6 nodes are available: 1 c_wall violated: 2 conflicting context pair(s) with node memory, 5 node(s) had untolerated taint(s). no new claims to deallocate, preemption: 0/6 nodes are available: 1 No preemption victims found for incoming pod, 5 Preemption is not helpful for scheduling."
75.8163,Event,MODIFIED,eval-sanitize-20-r1-059-vz4jf.18d41aaf95e3cb25,"reason=FailedScheduling count=None msg=0/6 nodes are available: 1 c_wall violated: 2 conflicting context pair(s) with node memory, 5 node(s) had untolerated taint(s). no new claims to deallocate, preemption: 0/6 nodes are available: 1 No preemption victims found for incoming pod, 5 Preemption is not helpful for scheduling."
75.8221,Pod,MODIFIED,eval-sanitize-20-r1-075-6hdmw,phase=Running node=kind-worker
75.8239,Job,MODIFIED,eval-sanitize-20-r1-056,
75.8254,Node,MODIFIED,kind-worker4,taints=1
75.8292,Pod,MODIFIED,eval-sanitize-20-r1-063-9s6g7,phase=Running node=kind-worker
75.8317,Node,MODIFIED,kind-worker4,taints=0
75.8349,Job,MODIFIED,eval-sanitize-20-r1-056,
75.8377,Pod,MODIFIED,eval-sanitize-20-r1-066-mp8pn,phase=Running node=kind-worker
75.8445,Pod,MODIFIED,eval-sanitize-20-r1-055-bzm98,phase=Running node=kind-worker
75.8467,Node,MODIFIED,kind-worker4,taints=0
75.8533,Pod,MODIFIED,eval-sanitize-20-r1-058-d9b2t,phase=Running node=kind-worker
75.8593,Pod,MODIFIED,eval-sanitize-20-r1-060-nkffm,phase=Running node=kind-worker
75.8656,Pod,MODIFIED,eval-sanitize-20-r1-064-nlrbv,phase=Running node=kind-worker
75.8711,Pod,MODIFIED,eval-sanitize-20-r1-068-lnvtw,phase=Running node=kind-worker
75.8856,Event,MODIFIED,eval-sanitize-20-r1-061-sjpk6.18d41aaf96151266,"reason=FailedScheduling count=None msg=0/6 nodes are available: 1 c_wall violated: 2 conflicting context pair(s) with node memory, 5 node(s) had untolerated taint(s). no new claims to deallocate, preemption: 0/6 nodes are available: 1 No preemption victims found for incoming pod, 5 Preemption is not helpful for scheduling."
75.887,Event,MODIFIED,eval-sanitize-20-r1-062-j6dn5.18d41aaf964b0a8b,"reason=FailedScheduling count=None msg=0/6 nodes are available: 1 c_wall violated: 2 conflicting context pair(s) with node memory, 5 node(s) had untolerated taint(s). no new claims to deallocate, preemption: 0/6 nodes are available: 1 No preemption victims found for incoming pod, 5 Preemption is not helpful for scheduling."
75.8895,Job,MODIFIED,eval-sanitize-20-r1-055,
75.8922,Pod,MODIFIED,eval-sanitize-20-r1-069-dxq4t,phase=Pending node=kind-worker4
75.8937,Job,MODIFIED,eval-sanitize-20-r1-058,
75.8996,Event,ADDED,eval-sanitize-20-r1-069-dxq4t.18d41aafb8842d7c,reason=Scheduled count=None msg=Successfully assigned compute/eval-sanitize-20-r1-069-dxq4t to kind-worker4
75.9025,Job,MODIFIED,eval-sanitize-20-r1-055,
75.9045,Node,MODIFIED,kind-worker4,taints=0
75.9054,Job,MODIFIED,eval-sanitize-20-r1-058,
75.9077,Pod,MODIFIED,eval-sanitize-20-r1-069-dxq4t,phase=Pending node=kind-worker4
75.9122,Job,MODIFIED,eval-sanitize-20-r1-060,
75.9154,Node,MODIFIED,kind-worker4,taints=0
75.9214,Job,MODIFIED,eval-sanitize-20-r1-060,
75.978,Pod,MODIFIED,eval-sanitize-20-r1-070-c8j2t,phase=Pending node=None
75.9878,Pod,MODIFIED,eval-sanitize-20-r1-071-b576n,phase=Pending node=None
75.9965,Job,MODIFIED,eval-sanitize-20-r1-063,
75.998,Job,MODIFIED,eval-sanitize-20-r1-064,
75.9988,Pod,MODIFIED,eval-sanitize-20-r1-072-q7qwt,phase=Pending node=None
76.0009,Job,MODIFIED,eval-sanitize-20-r1-065,
76.0062,Job,MODIFIED,eval-sanitize-20-r1-063,
76.0091,Job,MODIFIED,eval-sanitize-20-r1-064,
76.0115,Job,MODIFIED,eval-sanitize-20-r1-066,
76.0122,Job,MODIFIED,eval-sanitize-20-r1-065,
76.0129,Job,MODIFIED,eval-sanitize-20-r1-068,
76.0135,Job,MODIFIED,eval-sanitize-20-r1-067,
76.0234,Job,MODIFIED,eval-sanitize-20-r1-066,
76.0253,Job,MODIFIED,eval-sanitize-20-r1-068,
76.026,Job,MODIFIED,eval-sanitize-20-r1-067,
76.058,Node,MODIFIED,kind-worker3,taints=1
76.0827,TaskRequest,ADDED,eval-sanitize-20-r1-076,phase=None job=None
76.0864,Pod,MODIFIED,eval-sanitize-20-r1-074-4hsdp,phase=Pending node=kind-worker4
76.0867,TaskRequest,MODIFIED,eval-sanitize-20-r1-076,phase=Pending job=None
76.0925,Pod,MODIFIED,eval-sanitize-20-r1-059-vz4jf,phase=Pending node=None
76.0931,Event,ADDED,eval-sanitize-20-r1-074-4hsdp.18d41aafc416e0b1,reason=Scheduled count=None msg=Successfully assigned compute/eval-sanitize-20-r1-074-4hsdp to kind-worker4
76.1007,Pod,MODIFIED,eval-sanitize-20-r1-074-4hsdp,phase=Pending node=kind-worker4
76.1027,Node,MODIFIED,kind-worker4,taints=0
76.1038,Job,ADDED,eval-sanitize-20-r1-076,
76.1063,Job,MODIFIED,eval-sanitize-20-r1-075,
76.1078,Node,MODIFIED,kind-worker3,taints=0
76.1097,TaskRequest,MODIFIED,eval-sanitize-20-r1-076,phase=Scheduled job=None
76.1109,Pod,ADDED,eval-sanitize-20-r1-076-pcw8z,phase=Pending node=None
76.1153,Job,MODIFIED,eval-sanitize-20-r1-076,
76.1168,Event,ADDED,eval-sanitize-20-r1-076.18d41aafc58f8d76,reason=SuccessfulCreate count=1 msg=Created pod: eval-sanitize-20-r1-076-pcw8z
76.1183,Node,MODIFIED,kind-worker3,taints=0
76.1186,TaskRequest,MODIFIED,eval-sanitize-20-r1-076,phase=Scheduled job=None
76.1194,Job,MODIFIED,eval-sanitize-20-r1-075,
76.1228,Job,MODIFIED,eval-sanitize-20-r1-073,
76.1319,Job,MODIFIED,eval-sanitize-20-r1-073,
76.1542,Node,MODIFIED,kind-worker4,taints=0
76.1562,Node,MODIFIED,kind-worker3,taints=0
76.1768,Pod,MODIFIED,eval-sanitize-20-r1-061-sjpk6,phase=Pending node=None
76.1873,Pod,MODIFIED,eval-sanitize-20-r1-076-pcw8z,phase=Pending node=kind-worker3
76.1909,Event,ADDED,eval-sanitize-20-r1-076-pcw8z.18d41aafca1f7b03,reason=Scheduled count=None msg=Successfully assigned compute/eval-sanitize-20-r1-076-pcw8z to kind-worker3
76.1972,Node,MODIFIED,kind-worker3,taints=0
76.1991,Pod,MODIFIED,eval-sanitize-20-r1-076-pcw8z,phase=Pending node=kind-worker3
76.209,Node,MODIFIED,kind-worker3,taints=0
76.2123,Pod,MODIFIED,eval-sanitize-20-r1-062-j6dn5,phase=Pending node=kind-worker3
76.2162,Event,ADDED,eval-sanitize-20-r1-062-j6dn5.18d41aafcb9a01eb,reason=Scheduled count=None msg=Successfully assigned compute/eval-sanitize-20-r1-062-j6dn5 to kind-worker3
76.2225,Pod,MODIFIED,eval-sanitize-20-r1-062-j6dn5,phase=Pending node=kind-worker3
76.2253,Node,MODIFIED,kind-worker3,taints=0
76.2361,Node,MODIFIED,kind-worker3,taints=0
76.2907,Pod,MODIFIED,eval-sanitize-20-r1-070-c8j2t,phase=Pending node=kind-worker3
76.2936,Event,ADDED,eval-sanitize-20-r1-070-c8j2t.18d41aafd042fa8f,reason=Scheduled count=None msg=Successfully assigned compute/eval-sanitize-20-r1-070-c8j2t to kind-worker3
76.3036,Pod,MODIFIED,eval-sanitize-20-r1-070-c8j2t,phase=Pending node=kind-worker3
76.3148,Event,ADDED,eval-sanitize-20-r1-069-dxq4t.18d41aafd1735749,"reason=Pulled count=1 msg=Container image ""busybox:musl"" already present on machine"
76.3324,Event,ADDED,eval-sanitize-20-r1-069-dxq4t.18d41aafd293874b,reason=Created count=1 msg=Created container: task
76.3909,Pod,MODIFIED,eval-sanitize-20-r1-071-b576n,phase=Pending node=kind-worker3
76.394,Event,ADDED,eval-sanitize-20-r1-071-b576n.18d41aafd62ad2d1,reason=Scheduled count=None msg=Successfully assigned compute/eval-sanitize-20-r1-071-b576n to kind-worker3
76.4011,Pod,MODIFIED,eval-sanitize-20-r1-071-b576n,phase=Pending node=kind-worker3
76.4105,Event,ADDED,eval-sanitize-20-r1-069-dxq4t.18d41aafd73179b1,reason=Started count=1 msg=Started container task
76.4836,Pod,MODIFIED,eval-sanitize-20-r1-072-q7qwt,phase=Pending node=kind-worker3
76.488,Event,ADDED,eval-sanitize-20-r1-072-q7qwt.18d41aafdbc561b7,reason=Scheduled count=None msg=Successfully assigned compute/eval-sanitize-20-r1-072-q7qwt to kind-worker3
76.4938,Pod,MODIFIED,eval-sanitize-20-r1-072-q7qwt,phase=Pending node=kind-worker3
76.511,Pod,MODIFIED,eval-sanitize-20-r1-059-vz4jf,phase=Pending node=kind-worker3
76.5147,Event,ADDED,eval-sanitize-20-r1-059-vz4jf.18d41aafdd68e482,reason=Scheduled count=None msg=Successfully assigned compute/eval-sanitize-20-r1-059-vz4jf to kind-worker3
76.5219,Pod,MODIFIED,eval-sanitize-20-r1-059-vz4jf,phase=Pending node=kind-worker3
76.5226,Event,ADDED,eval-sanitize-20-r1-074-4hsdp.18d41aafdde0e027,"reason=Pulled count=1 msg=Container image ""busybox:musl"" already present on machine"
76.5492,Event,ADDED,eval-sanitize-20-r1-074-4hsdp.18d41aafdf61f864,reason=Created count=1 msg=Created container: task
76.5872,Pod,MODIFIED,eval-sanitize-20-r1-061-sjpk6,phase=Pending node=kind-worker3
76.5941,Event,ADDED,eval-sanitize-20-r1-061-sjpk6.18d41aafe1f0ec36,reason=Scheduled count=None msg=Successfully assigned compute/eval-sanitize-20-r1-061-sjpk6 to kind-worker3
76.6013,Pod,MODIFIED,eval-sanitize-20-r1-061-sjpk6,phase=Pending node=kind-worker3
76.6177,Event,ADDED,eval-sanitize-20-r1-074-4hsdp.18d41aafe380486f,reason=Started count=1 msg=Started container task
76.6221,Event,ADDED,eval-sanitize-20-r1-076-pcw8z.18d41aafe3cb673b,"reason=Pulled count=1 msg=Container image ""busybox:musl"" already present on machine"
76.6443,Event,ADDED,eval-sanitize-20-r1-062-j6dn5.18d41aafe502ab2a,"reason=Pulled count=1 msg=Container image ""busybox:musl"" already present on machine"
76.6478,Event,ADDED,eval-sanitize-20-r1-076-pcw8z.18d41aafe566260c,reason=Created count=1 msg=Created container: task
76.6679,Event,ADDED,eval-sanitize-20-r1-062-j6dn5.18d41aafe697eb76,reason=Created count=1 msg=Created container: task
76.7134,Event,ADDED,eval-sanitize-20-r1-076-pcw8z.18d41aafe92d1253,reason=Started count=1 msg=Started container task
76.7199,Event,ADDED,eval-sanitize-20-r1-062-j6dn5.18d41aafe99cd433,reason=Started count=1 msg=Started container task
76.7269,Pod,MODIFIED,eval-sanitize-20-r1-076-pcw8z,phase=Running node=kind-worker3
76.7273,Event,ADDED,eval-sanitize-20-r1-070-c8j2t.18d41aafe9d2b57d,"reason=Pulled count=1 msg=Container image ""busybox:musl"" already present on machine"
76.7342,Pod,MODIFIED,eval-sanitize-20-r1-062-j6dn5,phase=Running node=kind-worker3
76.7478,Event,ADDED,eval-sanitize-20-r1-070-c8j2t.18d41aafeb538007,reason=Created count=1 msg=Created container: task
76.8279,Event,ADDED,eval-sanitize-20-r1-070-c8j2t.18d41aaff009381a,reason=Started count=1 msg=Started container task
76.8427,Event,ADDED,eval-sanitize-20-r1-071-b576n.18d41aaff0d63756,"reason=Pulled count=1 msg=Container image ""busybox:musl"" already present on machine"
76.8646,Event,ADDED,eval-sanitize-20-r1-071-b576n.18d41aaff224efd1,reason=Created count=1 msg=Created container: task
76.8798,Event,ADDED,eval-sanitize-20-r1-072-q7qwt.18d41aaff324b2c6,"reason=Pulled count=1 msg=Container image ""busybox:musl"" already present on machine"
76.8993,Event,ADDED,eval-sanitize-20-r1-071-b576n.18d41aaff44b2096,reason=Started count=1 msg=Started container task
76.905,Event,ADDED,eval-sanitize-20-r1-072-q7qwt.18d41aaff45fb6e9,reason=Created count=1 msg=Created container: task
76.9148,Event,ADDED,eval-sanitize-20-r1-059-vz4jf.18d41aaff53c1028,"reason=Pulled count=1 msg=Container image ""busybox:musl"" already present on machine"
76.9361,Event,ADDED,eval-sanitize-20-r1-072-q7qwt.18d41aaff684d719,reason=Started count=1 msg=Started container task
76.9406,Event,ADDED,eval-sanitize-20-r1-059-vz4jf.18d41aaff6a14c35,reason=Created count=1 msg=Created container: task
77.0086,TaskRequest,ADDED,eval-sanitize-20-r1-077,phase=None job=None
77.0138,TaskRequest,MODIFIED,eval-sanitize-20-r1-077,phase=Pending job=None
77.0149,Event,ADDED,eval-sanitize-20-r1-059-vz4jf.18d41aaffb469c47,reason=Started count=1 msg=Started container task
77.0283,Event,ADDED,eval-sanitize-20-r1-061-sjpk6.18d41aaffc07e525,"reason=Pulled count=1 msg=Container image ""busybox:musl"" already present on machine"
77.0309,Job,ADDED,eval-sanitize-20-r1-077,
77.0386,Pod,ADDED,eval-sanitize-20-r1-077-h59q8,phase=Pending node=None
77.0405,TaskRequest,MODIFIED,eval-sanitize-20-r1-077,phase=Scheduled job=None
77.0413,Job,MODIFIED,eval-sanitize-20-r1-077,
77.0441,Event,ADDED,eval-sanitize-20-r1-077.18d41aaffcdecc6f,reason=SuccessfulCreate count=1 msg=Created pod: eval-sanitize-20-r1-077-h59q8
77.0518,Event,ADDED,eval-sanitize-20-r1-061-sjpk6.18d41aaffd51a54d,reason=Created count=1 msg=Created container: task
77.054,Pod,MODIFIED,eval-sanitize-20-r1-077-h59q8,phase=Pending node=kind-worker4
77.0553,TaskRequest,MODIFIED,eval-sanitize-20-r1-077,phase=Scheduled job=None
77.0575,Event,ADDED,eval-sanitize-20-r1-077-h59q8.18d41aaffdc8c6fc,reason=Scheduled count=None msg=Successfully assigned compute/eval-sanitize-20-r1-077-h59q8 to kind-worker4
77.0633,Pod,MODIFIED,eval-sanitize-20-r1-077-h59q8,phase=Pending node=kind-worker4
77.0655,Node,MODIFIED,kind-worker4,taints=0
77.0751,Node,MODIFIED,kind-worker4,taints=0
77.1156,Job,MODIFIED,eval-sanitize-20-r1-076,
77.1159,Event,ADDED,eval-sanitize-20-r1-061-sjpk6.18d41ab0012d9b82,reason=Started count=1 msg=Started container task
77.1242,Job,MODIFIED,eval-sanitize-20-r1-076,
77.1968,Pod,MODIFIED,eval-sanitize-20-r1-074-4hsdp,phase=Running node=kind-worker4
77.2028,Pod,MODIFIED,eval-sanitize-20-r1-069-dxq4t,phase=Running node=kind-worker4
77.2169,Job,MODIFIED,eval-sanitize-20-r1-062,
77.2253,Job,MODIFIED,eval-sanitize-20-r1-062,
77.4035,Node,MODIFIED,kind-worker2,taints=1
77.4179,Node,MODIFIED,kind-worker2,taints=0
77.4282,Node,MODIFIED,kind-worker2,taints=0
77.4375,Node,MODIFIED,kind-worker2,taints=0
77.5194,Event,ADDED,eval-sanitize-20-r1-077-h59q8.18d41ab0194d6a3f,"reason=Pulled count=1 msg=Container image ""busybox:musl"" already present on machine"
77.5363,Event,ADDED,eval-sanitize-20-r1-077-h59q8.18d41ab01a5a3e7c,reason=Created count=1 msg=Created container: task
77.6022,Event,ADDED,eval-sanitize-20-r1-077-h59q8.18d41ab01e3c4286,reason=Started count=1 msg=Started container task
77.6575,Node,MODIFIED,kind-worker5,taints=1
77.6728,Node,MODIFIED,kind-worker5,taints=1
77.6807,Node,MODIFIED,kind-worker5,taints=0
77.7326,Pod,MODIFIED,eval-sanitize-20-r1-072-q7qwt,phase=Running node=kind-worker3
77.7387,Pod,MODIFIED,eval-sanitize-20-r1-059-vz4jf,phase=Running node=kind-worker3
77.7452,Pod,MODIFIED,eval-sanitize-20-r1-071-b576n,phase=Running node=kind-worker3
77.7496,Node,MODIFIED,kind-worker5,taints=0
77.7511,Pod,MODIFIED,eval-sanitize-20-r1-061-sjpk6,phase=Running node=kind-worker3
77.7567,Pod,MODIFIED,eval-sanitize-20-r1-070-c8j2t,phase=Running node=kind-worker3
78.012,TaskRequest,ADDED,eval-sanitize-20-r1-078,phase=None job=None
78.0166,TaskRequest,MODIFIED,eval-sanitize-20-r1-078,phase=Pending job=None
78.0306,Job,ADDED,eval-sanitize-20-r1-078,
78.0355,TaskRequest,MODIFIED,eval-sanitize-20-r1-078,phase=Scheduled job=None
78.0389,Job,MODIFIED,eval-sanitize-20-r1-078,
78.0404,Pod,ADDED,eval-sanitize-20-r1-078-6cjg2,phase=Pending node=None
78.0435,Job,MODIFIED,eval-sanitize-20-r1-077,
78.0446,Event,ADDED,eval-sanitize-20-r1-078.18d41ab0387d8503,reason=SuccessfulCreate count=1 msg=Created pod: eval-sanitize-20-r1-078-6cjg2
78.0447,TaskRequest,MODIFIED,eval-sanitize-20-r1-078,phase=Scheduled job=None
78.0531,Job,MODIFIED,eval-sanitize-20-r1-077,
78.0629,Pod,MODIFIED,eval-sanitize-20-r1-078-6cjg2,phase=Pending node=kind-worker5
78.067,Event,ADDED,eval-sanitize-20-r1-078-6cjg2.18d41ab039ec861c,reason=Scheduled count=None msg=Successfully assigned compute/eval-sanitize-20-r1-078-6cjg2 to kind-worker5
78.0729,Node,MODIFIED,kind-worker5,taints=0
78.0748,Pod,MODIFIED,eval-sanitize-20-r1-078-6cjg2,phase=Pending node=kind-worker5
78.0827,Node,MODIFIED,kind-worker5,taints=0
78.2058,Pod,MODIFIED,eval-sanitize-20-r1-077-h59q8,phase=Running node=kind-worker4
78.2069,Job,MODIFIED,eval-sanitize-20-r1-074,
78.2088,Job,MODIFIED,eval-sanitize-20-r1-069,
78.2156,Job,MODIFIED,eval-sanitize-20-r1-074,
78.2175,Job,MODIFIED,eval-sanitize-20-r1-069,
78.484,Event,ADDED,eval-sanitize-20-r1-078-6cjg2.18d41ab052b25890,"reason=Pulled count=1 msg=Container image ""busybox:musl"" already present on machine"
78.509,Event,ADDED,eval-sanitize-20-r1-078-6cjg2.18d41ab0544ae105,reason=Created count=1 msg=Created container: task
78.576,Event,ADDED,eval-sanitize-20-r1-078-6cjg2.18d41ab0584abfb7,reason=Started count=1 msg=Started container task
78.7412,Job,MODIFIED,eval-sanitize-20-r1-072,
78.7428,Job,MODIFIED,eval-sanitize-20-r1-059,
78.7495,Job,MODIFIED,eval-sanitize-20-r1-071,
78.7512,Job,MODIFIED,eval-sanitize-20-r1-072,
78.753,Job,MODIFIED,eval-sanitize-20-r1-059,
78.7549,Job,MODIFIED,eval-sanitize-20-r1-061,
78.7576,Job,MODIFIED,eval-sanitize-20-r1-071,
78.7606,Job,MODIFIED,eval-sanitize-20-r1-070,
78.7625,Job,MODIFIED,eval-sanitize-20-r1-061,
78.7688,Job,MODIFIED,eval-sanitize-20-r1-070,
79.0084,TaskRequest,ADDED,eval-sanitize-20-r1-079,phase=None job=None
79.0124,TaskRequest,MODIFIED,eval-sanitize-20-r1-079,phase=Pending job=None
79.0292,Job,ADDED,eval-sanitize-20-r1-079,
79.0356,Pod,ADDED,eval-sanitize-20-r1-079-tz46z,phase=Pending node=None
79.0359,TaskRequest,MODIFIED,eval-sanitize-20-r1-079,phase=Scheduled job=None
79.0407,Job,MODIFIED,eval-sanitize-20-r1-079,
79.0419,Event,ADDED,eval-sanitize-20-r1-079.18d41ab073ec4d2b,reason=SuccessfulCreate count=1 msg=Created pod: eval-sanitize-20-r1-079-tz46z
79.0445,Job,MODIFIED,eval-sanitize-20-r1-078,
79.0447,TaskRequest,MODIFIED,eval-sanitize-20-r1-079,phase=Scheduled job=None
79.0481,Job,MODIFIED,eval-sanitize-20-r1-077,
79.054,Job,MODIFIED,eval-sanitize-20-r1-078,
79.056,Job,MODIFIED,eval-sanitize-20-r1-077,
79.0598,Pod,MODIFIED,eval-sanitize-20-r1-079-tz46z,phase=Pending node=kind-worker5
79.063,Event,ADDED,eval-sanitize-20-r1-079-tz46z.18d41ab075591f03,reason=Scheduled count=None msg=Successfully assigned compute/eval-sanitize-20-r1-079-tz46z to kind-worker5
79.0692,Node,MODIFIED,kind-worker5,taints=0
79.0714,Pod,MODIFIED,eval-sanitize-20-r1-079-tz46z,phase=Pending node=kind-worker5
79.0789,Node,MODIFIED,kind-worker5,taints=0
79.3591,Pod,MODIFIED,eval-sanitize-20-r1-078-6cjg2,phase=Running node=kind-worker5
79.4854,Event,ADDED,eval-sanitize-20-r1-079-tz46z.18d41ab08e79705d,"reason=Pulled count=1 msg=Container image ""busybox:musl"" already present on machine"
79.5034,Event,ADDED,eval-sanitize-20-r1-079-tz46z.18d41ab08f9177f3,reason=Created count=1 msg=Created container: task
79.5896,Event,ADDED,eval-sanitize-20-r1-079-tz46z.18d41ab0949bf2d7,reason=Started count=1 msg=Started container task
80.0089,TaskRequest,ADDED,eval-sanitize-20-r1-080,phase=None job=None
80.0142,TaskRequest,MODIFIED,eval-sanitize-20-r1-080,phase=Pending job=None
80.0352,Job,ADDED,eval-sanitize-20-r1-080,
80.0402,Job,MODIFIED,eval-sanitize-20-r1-079,
80.0416,TaskRequest,MODIFIED,eval-sanitize-20-r1-080,phase=Scheduled job=None
80.0427,Pod,ADDED,eval-sanitize-20-r1-080-lt4pd,phase=Pending node=None
80.0454,Job,MODIFIED,eval-sanitize-20-r1-080,
80.0499,Event,ADDED,eval-sanitize-20-r1-080.18d41ab0aff0ffd1,reason=SuccessfulCreate count=1 msg=Created pod: eval-sanitize-20-r1-080-lt4pd
80.0508,Job,MODIFIED,eval-sanitize-20-r1-078,
80.0519,TaskRequest,MODIFIED,eval-sanitize-20-r1-080,phase=Scheduled job=None
80.0529,Job,MODIFIED,eval-sanitize-20-r1-079,
80.059,Job,MODIFIED,eval-sanitize-20-r1-078,
80.0663,Pod,MODIFIED,eval-sanitize-20-r1-080-lt4pd,phase=Pending node=kind-worker2
80.0697,Event,ADDED,eval-sanitize-20-r1-080-lt4pd.18d41ab0b152e3d9,reason=Scheduled count=None msg=Successfully assigned compute/eval-sanitize-20-r1-080-lt4pd to kind-worker2
80.0753,Pod,MODIFIED,eval-sanitize-20-r1-080-lt4pd,phase=Pending node=kind-worker2
80.0778,Node,MODIFIED,kind-worker2,taints=0
80.087,Node,MODIFIED,kind-worker2,taints=0
80.3619,Pod,MODIFIED,eval-sanitize-20-r1-079-tz46z,phase=Running node=kind-worker5
80.5732,Event,ADDED,eval-sanitize-20-r1-080-lt4pd.18d41ab0cf4fc43a,"reason=Pulled count=1 msg=Container image ""busybox:musl"" already present on machine"
80.5913,Event,ADDED,eval-sanitize-20-r1-080-lt4pd.18d41ab0d06c8acd,reason=Created count=1 msg=Created container: task
80.6617,Event,ADDED,eval-sanitize-20-r1-080-lt4pd.18d41ab0d4797bae,reason=Started count=1 msg=Started container task
81.0286,TaskRequest,ADDED,eval-sanitize-20-r1-081,phase=None job=None
81.0328,TaskRequest,MODIFIED,eval-sanitize-20-r1-081,phase=Pending job=None
81.0463,Job,MODIFIED,eval-sanitize-20-r1-079,
81.0487,Job,MODIFIED,eval-sanitize-20-r1-080,
81.0493,Job,ADDED,eval-sanitize-20-r1-081,
81.0537,TaskRequest,MODIFIED,eval-sanitize-20-r1-081,phase=Scheduled job=None
81.0587,Pod,ADDED,eval-sanitize-20-r1-081-r27jp,phase=Pending node=None
81.0603,Job,MODIFIED,eval-sanitize-20-r1-081,
81.0647,Event,ADDED,eval-sanitize-20-r1-081.18d41ab0ec708910,reason=SuccessfulCreate count=1 msg=Created pod: eval-sanitize-20-r1-081-r27jp
81.0649,TaskRequest,MODIFIED,eval-sanitize-20-r1-081,phase=Scheduled job=None
81.0658,Job,MODIFIED,eval-sanitize-20-r1-079,
81.0708,Job,MODIFIED,eval-sanitize-20-r1-080,
81.1184,Pod,MODIFIED,eval-sanitize-20-r1-081-r27jp,phase=Pending node=kind-worker2
81.1219,Event,ADDED,eval-sanitize-20-r1-081-r27jp.18d41ab0f00b5999,reason=Scheduled count=None msg=Successfully assigned compute/eval-sanitize-20-r1-081-r27jp to kind-worker2
81.129,Pod,MODIFIED,eval-sanitize-20-r1-081-r27jp,phase=Pending node=kind-worker2
81.1317,Node,MODIFIED,kind-worker2,taints=0
81.1421,Node,MODIFIED,kind-worker2,taints=0
81.2616,Pod,MODIFIED,eval-sanitize-20-r1-080-lt4pd,phase=Running node=kind-worker2
81.6003,Event,ADDED,eval-sanitize-20-r1-081-r27jp.18d41ab10c88c15b,"reason=Pulled count=1 msg=Container image ""busybox:musl"" already present on machine"
81.6192,Event,ADDED,eval-sanitize-20-r1-081-r27jp.18d41ab10d9ef4ec,reason=Created count=1 msg=Created container: task
81.6912,Event,ADDED,eval-sanitize-20-r1-081-r27jp.18d41ab111f3b8c4,reason=Started count=1 msg=Started container task
82.0134,TaskRequest,ADDED,eval-sanitize-20-r1-082,phase=None job=None
82.0187,TaskRequest,MODIFIED,eval-sanitize-20-r1-082,phase=Pending job=None
82.0347,Job,ADDED,eval-sanitize-20-r1-082,
82.0405,Pod,ADDED,eval-sanitize-20-r1-082-2rds5,phase=Pending node=None
82.0421,TaskRequest,MODIFIED,eval-sanitize-20-r1-082,phase=Scheduled job=None
82.0451,Job,MODIFIED,eval-sanitize-20-r1-082,
82.0454,Event,ADDED,eval-sanitize-20-r1-082.18d41ab127012acd,reason=SuccessfulCreate count=1 msg=Created pod: eval-sanitize-20-r1-082-2rds5
82.0492,TaskRequest,MODIFIED,eval-sanitize-20-r1-082,phase=Scheduled job=None
82.0519,Job,MODIFIED,eval-sanitize-20-r1-082,
82.0543,Job,MODIFIED,eval-sanitize-20-r1-080,
82.0635,Job,MODIFIED,eval-sanitize-20-r1-082,
82.0644,Job,MODIFIED,eval-sanitize-20-r1-081,
82.0653,Job,MODIFIED,eval-sanitize-20-r1-080,
82.0733,Job,MODIFIED,eval-sanitize-20-r1-081,
82.1163,Pod,MODIFIED,eval-sanitize-20-r1-082-2rds5,phase=Pending node=kind-worker5
82.1198,Event,ADDED,eval-sanitize-20-r1-082-2rds5.18d41ab12b8f705e,reason=Scheduled count=None msg=Successfully assigned compute/eval-sanitize-20-r1-082-2rds5 to kind-worker5
82.1258,Pod,MODIFIED,eval-sanitize-20-r1-082-2rds5,phase=Pending node=kind-worker5
82.128,Node,MODIFIED,kind-worker5,taints=0
82.1378,Node,MODIFIED,kind-worker5,taints=0
82.2667,Pod,MODIFIED,eval-sanitize-20-r1-081-r27jp,phase=Running node=kind-worker2
82.6009,Event,ADDED,eval-sanitize-20-r1-082-2rds5.18d41ab148196a9b,"reason=Pulled count=1 msg=Container image ""busybox:musl"" already present on machine"
82.618,Event,ADDED,eval-sanitize-20-r1-082-2rds5.18d41ab1493a1ba0,reason=Created count=1 msg=Created container: task
82.6698,Event,ADDED,eval-sanitize-20-r1-082-2rds5.18d41ab14c462f0a,reason=Started count=1 msg=Started container task
83.022,TaskRequest,ADDED,eval-sanitize-20-r1-083,phase=None job=None
83.027,TaskRequest,MODIFIED,eval-sanitize-20-r1-083,phase=Pending job=None
83.0405,Job,ADDED,eval-sanitize-20-r1-083,
83.0527,Pod,ADDED,eval-sanitize-20-r1-083-lrj6h,phase=Pending node=None
83.0567,Job,MODIFIED,eval-sanitize-20-r1-083,
83.0572,Event,ADDED,eval-sanitize-20-r1-083.18d41ab1635b96de,reason=SuccessfulCreate count=1 msg=Created pod: eval-sanitize-20-r1-083-lrj6h
83.0681,Job,MODIFIED,eval-sanitize-20-r1-081,
83.1065,TaskRequest,MODIFIED,eval-sanitize-20-r1-083,phase=Scheduled job=None
83.1094,Job,MODIFIED,eval-sanitize-20-r1-083,
83.1137,Pod,MODIFIED,eval-sanitize-20-r1-083-lrj6h,phase=Pending node=kind-worker5
83.1139,TaskRequest,MODIFIED,eval-sanitize-20-r1-083,phase=Scheduled job=None
83.1158,Job,MODIFIED,eval-sanitize-20-r1-081,
83.1167,Event,ADDED,eval-sanitize-20-r1-083-lrj6h.18d41ab166f92bc2,reason=Scheduled count=None msg=Successfully assigned compute/eval-sanitize-20-r1-083-lrj6h to kind-worker5
83.1239,Pod,MODIFIED,eval-sanitize-20-r1-083-lrj6h,phase=Pending node=kind-worker5
83.1971,Job,MODIFIED,eval-sanitize-20-r1-083,
83.3667,Pod,MODIFIED,eval-sanitize-20-r1-082-2rds5,phase=Running node=kind-worker5
83.5988,Event,ADDED,eval-sanitize-20-r1-083-lrj6h.18d41ab183a1a4f5,"reason=Pulled count=1 msg=Container image ""busybox:musl"" already present on machine"
83.6202,Event,ADDED,eval-sanitize-20-r1-083-lrj6h.18d41ab184c92986,reason=Created count=1 msg=Created container: task
83.7106,Event,ADDED,eval-sanitize-20-r1-083-lrj6h.18d41ab18a4da6a2,reason=Started count=1 msg=Started container task
84.018,TaskRequest,ADDED,eval-sanitize-20-r1-084,phase=None job=None
84.0218,TaskRequest,MODIFIED,eval-sanitize-20-r1-084,phase=Pending job=None
84.0381,Job,ADDED,eval-sanitize-20-r1-084,
84.0427,TaskRequest,MODIFIED,eval-sanitize-20-r1-084,phase=Scheduled job=None
84.0459,Pod,ADDED,eval-sanitize-20-r1-084-cxfx5,phase=Pending node=None
84.0478,Job,MODIFIED,eval-sanitize-20-r1-084,
84.0519,Event,ADDED,eval-sanitize-20-r1-084.18d41ab19e8def12,reason=SuccessfulCreate count=1 msg=Created pod: eval-sanitize-20-r1-084-cxfx5
84.052,TaskRequest,MODIFIED,eval-sanitize-20-r1-084,phase=Scheduled job=None
84.1121,Pod,MODIFIED,eval-sanitize-20-r1-084-cxfx5,phase=Pending node=kind-worker2
84.1159,Event,ADDED,eval-sanitize-20-r1-084-cxfx5.18d41ab1a2830454,reason=Scheduled count=None msg=Successfully assigned compute/eval-sanitize-20-r1-084-cxfx5 to kind-worker2
84.1219,Pod,MODIFIED,eval-sanitize-20-r1-084-cxfx5,phase=Pending node=kind-worker2
84.1241,Node,MODIFIED,kind-worker2,taints=0
84.1341,Node,MODIFIED,kind-worker2,taints=0
84.3719,Pod,MODIFIED,eval-sanitize-20-r1-083-lrj6h,phase=Running node=kind-worker5
84.3728,Job,MODIFIED,eval-sanitize-20-r1-082,
84.3823,Job,MODIFIED,eval-sanitize-20-r1-082,
84.5789,Event,ADDED,eval-sanitize-20-r1-084-cxfx5.18d41ab1be0fbe5c,"reason=Pulled count=1 msg=Container image ""busybox:musl"" already present on machine"
84.5989,Event,ADDED,eval-sanitize-20-r1-084-cxfx5.18d41ab1bf3c1140,reason=Created count=1 msg=Created container: task
84.6659,Event,ADDED,eval-sanitize-20-r1-084-cxfx5.18d41ab1c34b56c6,reason=Started count=1 msg=Started container task
85.0079,TaskRequest,ADDED,eval-sanitize-20-r1-085,phase=None job=None
85.012,TaskRequest,MODIFIED,eval-sanitize-20-r1-085,phase=Pending job=None
85.0283,Job,ADDED,eval-sanitize-20-r1-085,
85.035,Pod,ADDED,eval-sanitize-20-r1-085-d2r7k,phase=Pending node=None
85.0364,TaskRequest,MODIFIED,eval-sanitize-20-r1-085,phase=Scheduled job=None
85.0371,Job,MODIFIED,eval-sanitize-20-r1-085,
85.0399,Event,ADDED,eval-sanitize-20-r1-085.18d41ab1d9854844,reason=SuccessfulCreate count=1 msg=Created pod: eval-sanitize-20-r1-085-d2r7k
85.0459,TaskRequest,MODIFIED,eval-sanitize-20-r1-085,phase=Scheduled job=None
85.0518,Job,MODIFIED,eval-sanitize-20-r1-084,
85.0608,Job,MODIFIED,eval-sanitize-20-r1-084,
85.1131,Pod,MODIFIED,eval-sanitize-20-r1-085-d2r7k,phase=Pending node=kind-worker
85.1171,Event,ADDED,eval-sanitize-20-r1-085-d2r7k.18d41ab1de2b4cae,reason=Scheduled count=None msg=Successfully assigned compute/eval-sanitize-20-r1-085-d2r7k to kind-worker
85.1239,Pod,MODIFIED,eval-sanitize-20-r1-085-d2r7k,phase=Pending node=kind-worker
85.2732,Pod,MODIFIED,eval-sanitize-20-r1-084-cxfx5,phase=Running node=kind-worker2
85.377,Job,MODIFIED,eval-sanitize-20-r1-083,
85.3866,Job,MODIFIED,eval-sanitize-20-r1-083,
85.5861,Event,ADDED,eval-sanitize-20-r1-085-d2r7k.18d41ab1fa0be5b3,"reason=Pulled count=1 msg=Container image ""busybox:musl"" already present on machine"
85.6092,Event,ADDED,eval-sanitize-20-r1-085-d2r7k.18d41ab1fb7c87a5,reason=Created count=1 msg=Created container: task
85.6816,Event,ADDED,eval-sanitize-20-r1-085-d2r7k.18d41ab1ffa84a8e,reason=Started count=1 msg=Started container task
85.8294,Pod,MODIFIED,eval-sanitize-20-r1-066-mp8pn,phase=Running node=kind-worker
85.8359,Pod,MODIFIED,eval-sanitize-20-r1-055-bzm98,phase=Running node=kind-worker
85.843,Pod,MODIFIED,eval-sanitize-20-r1-073-8t5bg,phase=Running node=kind-worker
85.8492,Pod,MODIFIED,eval-sanitize-20-r1-056-sqhx4,phase=Running node=kind-worker
85.8549,Pod,MODIFIED,eval-sanitize-20-r1-065-jxz5x,phase=Running node=kind-worker
85.8619,Pod,MODIFIED,eval-sanitize-20-r1-064-nlrbv,phase=Running node=kind-worker
85.8681,Pod,MODIFIED,eval-sanitize-20-r1-068-lnvtw,phase=Running node=kind-worker
85.8748,Pod,MODIFIED,eval-sanitize-20-r1-063-9s6g7,phase=Running node=kind-worker
85.8806,Pod,MODIFIED,eval-sanitize-20-r1-085-d2r7k,phase=Running node=kind-worker
85.8871,Pod,MODIFIED,eval-sanitize-20-r1-058-d9b2t,phase=Running node=kind-worker
85.8926,Pod,MODIFIED,eval-sanitize-20-r1-067-wl7jk,phase=Running node=kind-worker
85.8984,Pod,MODIFIED,eval-sanitize-20-r1-060-nkffm,phase=Running node=kind-worker
86.0078,TaskRequest,ADDED,eval-sanitize-20-r1-086,phase=None job=None
86.0116,TaskRequest,MODIFIED,eval-sanitize-20-r1-086,phase=Pending job=None
86.0257,Job,ADDED,eval-sanitize-20-r1-086,
86.0297,TaskRequest,MODIFIED,eval-sanitize-20-r1-086,phase=Scheduled job=None
86.0329,Pod,ADDED,eval-sanitize-20-r1-086-hff6x,phase=Pending node=None
86.0348,Job,MODIFIED,eval-sanitize-20-r1-086,
86.0386,Event,ADDED,eval-sanitize-20-r1-086.18d41ab215015ce1,reason=SuccessfulCreate count=1 msg=Created pod: eval-sanitize-20-r1-086-hff6x
86.0388,TaskRequest,MODIFIED,eval-sanitize-20-r1-086,phase=Scheduled job=None
86.0408,Job,MODIFIED,eval-sanitize-20-r1-085,
86.0504,Job,MODIFIED,eval-sanitize-20-r1-085,
86.0563,Job,MODIFIED,eval-sanitize-20-r1-084,
86.0642,Job,MODIFIED,eval-sanitize-20-r1-084,
86.1148,Pod,MODIFIED,eval-sanitize-20-r1-086-hff6x,phase=Pending node=kind-worker5
86.1181,Event,ADDED,eval-sanitize-20-r1-086-hff6x.18d41ab219e0d563,reason=Scheduled count=None msg=Successfully assigned compute/eval-sanitize-20-r1-086-hff6x to kind-worker5
86.124,Pod,MODIFIED,eval-sanitize-20-r1-086-hff6x,phase=Pending node=kind-worker5
86.5412,Event,ADDED,eval-sanitize-20-r1-086-hff6x.18d41ab232f60a78,"reason=Pulled count=1 msg=Container image ""busybox:musl"" already present on machine"
86.5572,Event,ADDED,eval-sanitize-20-r1-086-hff6x.18d41ab2340df584,reason=Created count=1 msg=Created container: task
86.6218,Event,ADDED,eval-sanitize-20-r1-086-hff6x.18d41ab237d322cb,reason=Started count=1 msg=Started container task
86.7567,Pod,MODIFIED,eval-sanitize-20-r1-076-pcw8z,phase=Running node=kind-worker3
86.7627,Pod,MODIFIED,eval-sanitize-20-r1-062-j6dn5,phase=Running node=kind-worker3
86.8359,Job,MODIFIED,eval-sanitize-20-r1-066,
86.8453,Job,MODIFIED,eval-sanitize-20-r1-055,
86.8509,Job,MODIFIED,eval-sanitize-20-r1-066,
86.8558,Job,MODIFIED,eval-sanitize-20-r1-073,
86.8585,Pod,MODIFIED,eval-sanitize-20-r1-075-6hdmw,phase=Running node=kind-worker
86.8608,Job,MODIFIED,eval-sanitize-20-r1-056,
86.8643,Job,MODIFIED,eval-sanitize-20-r1-055,
86.865,Job,MODIFIED,eval-sanitize-20-r1-065,
86.8663,Job,MODIFIED,eval-sanitize-20-r1-064,
86.8672,Job,MODIFIED,eval-sanitize-20-r1-073,
86.8702,Job,MODIFIED,eval-sanitize-20-r1-056,
86.8726,Job,MODIFIED,eval-sanitize-20-r1-068,
86.8748,Job,MODIFIED,eval-sanitize-20-r1-065,
86.877,Job,MODIFIED,eval-sanitize-20-r1-064,
86.8794,Job,MODIFIED,eval-sanitize-20-r1-063,
86.8811,Job,MODIFIED,eval-sanitize-20-r1-068,
86.8917,Job,MODIFIED,eval-sanitize-20-r1-058,
86.895,Job,MODIFIED,eval-sanitize-20-r1-063,
86.8989,Job,MODIFIED,eval-sanitize-20-r1-067,
86.9,Job,MODIFIED,eval-sanitize-20-r1-058,
86.9022,Job,MODIFIED,eval-sanitize-20-r1-060,
86.9687,Job,MODIFIED,eval-sanitize-20-r1-067,
86.9703,Job,MODIFIED,eval-sanitize-20-r1-060,
87.0138,TaskRequest,ADDED,eval-sanitize-20-r1-087,phase=None job=None
87.0188,TaskRequest,MODIFIED,eval-sanitize-20-r1-087,phase=Pending job=None
87.0403,Job,ADDED,eval-sanitize-20-r1-087,
87.048,Job,MODIFIED,eval-sanitize-20-r1-086,
87.0524,Pod,ADDED,eval-sanitize-20-r1-087-4lvhn,phase=Pending node=None
87.0537,TaskRequest,MODIFIED,eval-sanitize-20-r1-087,phase=Scheduled job=None
87.0547,Job,MODIFIED,eval-sanitize-20-r1-087,
87.0576,Event,ADDED,eval-sanitize-20-r1-087.18d41ab251c34860,reason=SuccessfulCreate count=1 msg=Created pod: eval-sanitize-20-r1-087-4lvhn
87.0632,TaskRequest,MODIFIED,eval-sanitize-20-r1-087,phase=Scheduled job=None
87.0656,Job,MODIFIED,eval-sanitize-20-r1-086,
87.1174,Pod,MODIFIED,eval-sanitize-20-r1-068-lnvtw,phase=Succeeded node=kind-worker
87.1183,Pod,MODIFIED,eval-sanitize-20-r1-087-4lvhn,phase=Pending node=kind-worker2
87.1224,Event,ADDED,eval-sanitize-20-r1-087-4lvhn.18d41ab255b3b402,reason=Scheduled count=None msg=Successfully assigned compute/eval-sanitize-20-r1-087-4lvhn to kind-worker2
87.1284,Pod,MODIFIED,eval-sanitize-20-r1-087-4lvhn,phase=Pending node=kind-worker2
87.1489,Pod,MODIFIED,eval-sanitize-20-r1-056-sqhx4,phase=Succeeded node=kind-worker
87.1957,Pod,MODIFIED,eval-sanitize-20-r1-064-nlrbv,phase=Succeeded node=kind-worker
87.2023,Pod,MODIFIED,eval-sanitize-20-r1-067-wl7jk,phase=Succeeded node=kind-worker
87.2094,Pod,MODIFIED,eval-sanitize-20-r1-073-8t5bg,phase=Succeeded node=kind-worker
87.2157,Pod,MODIFIED,eval-sanitize-20-r1-060-nkffm,phase=Succeeded node=kind-worker
87.2214,Pod,MODIFIED,eval-sanitize-20-r1-074-4hsdp,phase=Running node=kind-worker4
87.2236,Pod,MODIFIED,eval-sanitize-20-r1-065-jxz5x,phase=Succeeded node=kind-worker
87.2284,Pod,MODIFIED,eval-sanitize-20-r1-069-dxq4t,phase=Running node=kind-worker4
87.2301,Pod,MODIFIED,eval-sanitize-20-r1-063-9s6g7,phase=Succeeded node=kind-worker
87.2356,Pod,MODIFIED,eval-sanitize-20-r1-055-bzm98,phase=Succeeded node=kind-worker
87.2411,Pod,MODIFIED,eval-sanitize-20-r1-058-d9b2t,phase=Succeeded node=kind-worker
87.247,Pod,MODIFIED,eval-sanitize-20-r1-066-mp8pn,phase=Succeeded node=kind-worker
87.3778,Pod,MODIFIED,eval-sanitize-20-r1-086-hff6x,phase=Running node=kind-worker5
87.5315,Event,ADDED,eval-sanitize-20-r1-087-4lvhn.18d41ab26e182b0c,"reason=Pulled count=1 msg=Container image ""busybox:musl"" already present on machine"
87.5494,Event,ADDED,eval-sanitize-20-r1-087-4lvhn.18d41ab26f22998c,reason=Created count=1 msg=Created container: task
87.626,Event,ADDED,eval-sanitize-20-r1-087-4lvhn.18d41ab273bd977a,reason=Started count=1 msg=Started container task
87.7626,Pod,MODIFIED,eval-sanitize-20-r1-061-sjpk6,phase=Running node=kind-worker3
87.7638,Job,MODIFIED,eval-sanitize-20-r1-076,
87.7683,Job,MODIFIED,eval-sanitize-20-r1-062,
87.7714,Pod,MODIFIED,eval-sanitize-20-r1-070-c8j2t,phase=Running node=kind-worker3
87.7738,Job,MODIFIED,eval-sanitize-20-r1-076,
87.7775,Job,MODIFIED,eval-sanitize-20-r1-062,
87.7815,Pod,MODIFIED,eval-sanitize-20-r1-072-q7qwt,phase=Running node=kind-worker3
87.7915,Pod,MODIFIED,eval-sanitize-20-r1-059-vz4jf,phase=Running node=kind-worker3
87.7986,Pod,MODIFIED,eval-sanitize-20-r1-071-b576n,phase=Running node=kind-worker3
87.8432,Job,MODIFIED,eval-sanitize-20-r1-066,
87.8504,Job,MODIFIED,eval-sanitize-20-r1-055,
87.8542,Pod,MODIFIED,eval-sanitize-20-r1-066-mp8pn,phase=Succeeded node=kind-worker
87.8555,Job,MODIFIED,eval-sanitize-20-r1-066,
87.8613,Pod,MODIFIED,eval-sanitize-20-r1-055-bzm98,phase=Succeeded node=kind-worker
87.8637,Job,MODIFIED,eval-sanitize-20-r1-055,
87.8647,Job,MODIFIED,eval-sanitize-20-r1-073,
87.8656,Job,MODIFIED,eval-sanitize-20-r1-075,
87.8695,Job,MODIFIED,eval-sanitize-20-r1-056,
87.8734,Job,MODIFIED,eval-sanitize-20-r1-065,
87.8747,Job,MODIFIED,eval-sanitize-20-r1-064,
87.8768,Pod,MODIFIED,eval-sanitize-20-r1-073-8t5bg,phase=Succeeded node=kind-worker
87.878,Job,MODIFIED,eval-sanitize-20-r1-073,
87.8794,Job,MODIFIED,eval-sanitize-20-r1-075,
87.881,Pod,MODIFIED,eval-sanitize-20-r1-056-sqhx4,phase=Succeeded node=kind-worker
87.8823,Job,MODIFIED,eval-sanitize-20-r1-068,
87.8845,Pod,MODIFIED,eval-sanitize-20-r1-065-jxz5x,phase=Succeeded node=kind-worker
87.8853,Job,MODIFIED,eval-sanitize-20-r1-056,
87.8869,Pod,MODIFIED,eval-sanitize-20-r1-064-nlrbv,phase=Succeeded node=kind-worker
87.8877,Job,MODIFIED,eval-sanitize-20-r1-065,
87.8894,Job,MODIFIED,eval-sanitize-20-r1-064,
87.8948,Pod,MODIFIED,eval-sanitize-20-r1-068-lnvtw,phase=Succeeded node=kind-worker
87.8956,Job,MODIFIED,eval-sanitize-20-r1-063,
87.8963,Job,MODIFIED,eval-sanitize-20-r1-068,
87.9003,Job,MODIFIED,eval-sanitize-20-r1-058,
87.9057,Pod,MODIFIED,eval-sanitize-20-r1-063-9s6g7,phase=Succeeded node=kind-worker
87.9077,Job,MODIFIED,eval-sanitize-20-r1-067,
87.9085,Job,MODIFIED,eval-sanitize-20-r1-060,
87.9109,Job,MODIFIED,eval-sanitize-20-r1-063,
87.9124,Pod,MODIFIED,eval-sanitize-20-r1-058-d9b2t,phase=Succeeded node=kind-worker
87.914,Pod,MODIFIED,eval-sanitize-20-r1-076-pcw8z,phase=Succeeded node=kind-worker3
87.9168,Pod,MODIFIED,eval-sanitize-20-r1-060-nkffm,phase=Succeeded node=kind-worker
87.9187,Pod,MODIFIED,eval-sanitize-20-r1-067-wl7jk,phase=Succeeded node=kind-worker
87.9542,Pod,MODIFIED,eval-sanitize-20-r1-062-j6dn5,phase=Succeeded node=kind-worker3
87.9631,Event,ADDED,eval-sanitize-20-r1-063.18d41ab284e52b0f,reason=Completed count=1 msg=Job completed
87.968,Job,MODIFIED,eval-sanitize-20-r1-063,
87.97,Job,MODIFIED,eval-sanitize-20-r1-058,
87.9713,Job,MODIFIED,eval-sanitize-20-r1-060,
87.9721,Job,MODIFIED,eval-sanitize-20-r1-067,
87.9735,TaskRequest,MODIFIED,eval-sanitize-20-r1-063,phase=Complete job=None
87.995,Job,MODIFIED,eval-sanitize-20-r1-063,
88.0079,TaskRequest,ADDED,eval-sanitize-20-r1-088,phase=None job=None
88.0116,TaskRequest,MODIFIED,eval-sanitize-20-r1-088,phase=Pending job=None
88.053,Pod,MODIFIED,eval-sanitize-20-r1-075-6hdmw,phase=Succeeded node=kind-worker
88.0663,Job,ADDED,eval-sanitize-20-r1-088,
88.0702,TaskRequest,MODIFIED,eval-sanitize-20-r1-088,phase=Scheduled job=None
88.075,Job,MODIFIED,eval-sanitize-20-r1-088,
88.0765,TaskRequest,MODIFIED,eval-sanitize-20-r1-088,phase=Scheduled job=None
88.1618,Job,MODIFIED,eval-sanitize-20-r1-086,
88.1707,Job,MODIFIED,eval-sanitize-20-r1-086,
88.2134,Job,MODIFIED,eval-sanitize-20-r1-087,
88.223,Job,MODIFIED,eval-sanitize-20-r1-087,
88.2262,Pod,MODIFIED,eval-sanitize-20-r1-077-h59q8,phase=Running node=kind-worker4
88.2632,Pod,ADDED,eval-sanitize-20-r1-088-wkvql,phase=Pending node=None
88.2802,Pod,MODIFIED,eval-sanitize-20-r1-087-4lvhn,phase=Running node=kind-worker2
88.3115,Pod,MODIFIED,eval-sanitize-20-r1-088-wkvql,phase=Pending node=kind-worker
88.3135,Job,MODIFIED,eval-sanitize-20-r1-074,
88.3154,Event,ADDED,eval-sanitize-20-r1-088-wkvql.18d41ab29ccd0bea,reason=Scheduled count=None msg=Successfully assigned compute/eval-sanitize-20-r1-088-wkvql to kind-worker
88.3216,Pod,MODIFIED,eval-sanitize-20-r1-088-wkvql,phase=Pending node=kind-worker
88.3233,Job,MODIFIED,eval-sanitize-20-r1-074,
88.3618,Job,MODIFIED,eval-sanitize-20-r1-069,
88.3709,Job,MODIFIED,eval-sanitize-20-r1-069,
88.4473,Pod,MODIFIED,eval-sanitize-20-r1-074-4hsdp,phase=Succeeded node=kind-worker4
88.4601,Event,ADDED,eval-sanitize-20-r1-088.18d41ab299f2234f,reason=SuccessfulCreate count=1 msg=Created pod: eval-sanitize-20-r1-088-wkvql
88.4798,Pod,MODIFIED,eval-sanitize-20-r1-069-dxq4t,phase=Succeeded node=kind-worker4
88.753,Event,ADDED,eval-sanitize-20-r1-088-wkvql.18d41ab2b6c66143,"reason=Pulled count=1 msg=Container image ""busybox:musl"" already present on machine"
88.7723,Job,MODIFIED,eval-sanitize-20-r1-061,
88.7756,Job,MODIFIED,eval-sanitize-20-r1-076,
88.7764,Event,ADDED,eval-sanitize-20-r1-088-wkvql.18d41ab2b803f90b,reason=Created count=1 msg=Created container: task
88.778,Job,MODIFIED,eval-sanitize-20-r1-062,
88.7794,Job,MODIFIED,eval-sanitize-20-r1-070,
88.7878,Job,MODIFIED,eval-sanitize-20-r1-061,
88.7927,Pod,MODIFIED,eval-sanitize-20-r1-076-pcw8z,phase=Succeeded node=kind-worker3
88.7952,Pod,MODIFIED,eval-sanitize-20-r1-062-j6dn5,phase=Succeeded node=kind-worker3
88.7959,Job,MODIFIED,eval-sanitize-20-r1-076,
88.7973,Job,MODIFIED,eval-sanitize-20-r1-070,
88.7986,Job,MODIFIED,eval-sanitize-20-r1-062,
88.8119,Job,MODIFIED,eval-sanitize-20-r1-072,
88.821,Job,MODIFIED,eval-sanitize-20-r1-072,
88.8619,Job,MODIFIED,eval-sanitize-20-r1-059,
88.8718,Job,MODIFIED,eval-sanitize-20-r1-059,
88.9046,Event,ADDED,eval-sanitize-20-r1-088-wkvql.18d41ab2bfe60d79,reason=Started count=1 msg=Started container task
88.9902,Pod,MODIFIED,eval-sanitize-20-r1-061-sjpk6,phase=Succeeded node=kind-worker3
88.9962,Pod,MODIFIED,eval-sanitize-20-r1-070-c8j2t,phase=Succeeded node=kind-worker3
89.0019,Pod,MODIFIED,eval-sanitize-20-r1-072-q7qwt,phase=Succeeded node=kind-worker3
89.0081,Pod,MODIFIED,eval-sanitize-20-r1-059-vz4jf,phase=Succeeded node=kind-worker3
89.0102,TaskRequest,ADDED,eval-sanitize-20-r1-089,phase=None job=None
89.0126,Job,MODIFIED,eval-sanitize-20-r1-071,
89.014,TaskRequest,MODIFIED,eval-sanitize-20-r1-089,phase=Pending job=None
89.0252,Pod,MODIFIED,eval-sanitize-20-r1-071-b576n,phase=Succeeded node=kind-worker3
89.0283,Job,ADDED,eval-sanitize-20-r1-089,
89.0343,TaskRequest,MODIFIED,eval-sanitize-20-r1-089,phase=Scheduled job=None
89.037,Job,MODIFIED,eval-sanitize-20-r1-089,
89.0405,TaskRequest,MODIFIED,eval-sanitize-20-r1-089,phase=Scheduled job=None
89.0431,Job,MODIFIED,eval-sanitize-20-r1-071,
89.0617,Job,MODIFIED,eval-sanitize-20-r1-066,
89.0708,Job,MODIFIED,eval-sanitize-20-r1-066,
89.1125,Job,MODIFIED,eval-sanitize-20-r1-055,
89.1211,Job,MODIFIED,eval-sanitize-20-r1-055,
89.1614,Job,MODIFIED,eval-sanitize-20-r1-073,
89.1699,Job,MODIFIED,eval-sanitize-20-r1-073,
89.2122,Job,MODIFIED,eval-sanitize-20-r1-075,
89.2211,Job,MODIFIED,eval-sanitize-20-r1-075,
89.2628,Job,MODIFIED,eval-sanitize-20-r1-056,
89.2732,Job,MODIFIED,eval-sanitize-20-r1-056,
89.3422,Pod,MODIFIED,eval-sanitize-20-r1-077-h59q8,phase=Succeeded node=kind-worker4
89.3834,Pod,MODIFIED,eval-sanitize-20-r1-078-6cjg2,phase=Running node=kind-worker5
89.4686,Pod,MODIFIED,eval-sanitize-20-r1-075-6hdmw,phase=Succeeded node=kind-worker
89.561,Job,MODIFIED,eval-sanitize-20-r1-065,
89.5697,Job,MODIFIED,eval-sanitize-20-r1-065,
89.6115,Job,MODIFIED,eval-sanitize-20-r1-064,
89.6203,Job,MODIFIED,eval-sanitize-20-r1-064,
89.663,Job,MODIFIED,eval-sanitize-20-r1-068,
89.6718,Job,MODIFIED,eval-sanitize-20-r1-068,
89.7639,Job,MODIFIED,eval-sanitize-20-r1-058,
89.7733,Job,MODIFIED,eval-sanitize-20-r1-058,
89.8794,Pod,MODIFIED,eval-sanitize-20-r1-088-wkvql,phase=Running node=kind-worker
89.9636,Job,MODIFIED,eval-sanitize-20-r1-067,
89.9722,Job,MODIFIED,eval-sanitize-20-r1-067,
90.012,TaskRequest,ADDED,eval-sanitize-20-r1-090,phase=None job=None
90.0165,TaskRequest,MODIFIED,eval-sanitize-20-r1-090,phase=Pending job=None
90.0293,Job,ADDED,eval-sanitize-20-r1-090,
90.0341,TaskRequest,MODIFIED,eval-sanitize-20-r1-090,phase=Scheduled job=None
90.0379,Job,MODIFIED,eval-sanitize-20-r1-090,
90.0399,TaskRequest,MODIFIED,eval-sanitize-20-r1-090,phase=Scheduled job=None
90.0611,Job,MODIFIED,eval-sanitize-20-r1-060,
90.0692,Job,MODIFIED,eval-sanitize-20-r1-060,
90.114,Pod,ADDED,eval-sanitize-20-r1-089-gkjss,phase=Pending node=None
90.1413,Pod,MODIFIED,eval-sanitize-20-r1-089-gkjss,phase=Pending node=kind-worker4
90.1447,Event,ADDED,eval-sanitize-20-r1-089-gkjss.18d41ab309dd86b4,reason=Scheduled count=None msg=Successfully assigned compute/eval-sanitize-20-r1-089-gkjss to kind-worker4
90.1505,Pod,MODIFIED,eval-sanitize-20-r1-089-gkjss,phase=Pending node=kind-worker4
90.1613,Job,MODIFIED,eval-sanitize-20-r1-088,
90.1694,Job,MODIFIED,eval-sanitize-20-r1-088,
90.2629,Job,MODIFIED,eval-sanitize-20-r1-087,
90.2715,Job,MODIFIED,eval-sanitize-20-r1-087,
90.3625,Job,MODIFIED,eval-sanitize-20-r1-089,
90.3732,Job,MODIFIED,eval-sanitize-20-r1-089,
90.386,Pod,MODIFIED,eval-sanitize-20-r1-079-tz46z,phase=Running node=kind-worker5
90.4124,Event,ADDED,eval-sanitize-20-r1-089.18d41ab30844551f,reason=SuccessfulCreate count=1 msg=Created pod: eval-sanitize-20-r1-089-gkjss
90.4617,Job,MODIFIED,eval-sanitize-20-r1-077,
90.4708,Job,MODIFIED,eval-sanitize-20-r1-077,
90.5154,Job,MODIFIED,eval-sanitize-20-r1-074,
90.5255,Job,MODIFIED,eval-sanitize-20-r1-074,
90.5529,Pod,MODIFIED,eval-sanitize-20-r1-078-6cjg2,phase=Succeeded node=kind-worker5
90.5621,Job,MODIFIED,eval-sanitize-20-r1-069,
90.5714,Job,MODIFIED,eval-sanitize-20-r1-069,
90.5717,Event,ADDED,eval-sanitize-20-r1-089-gkjss.18d41ab3234dfa0c,"reason=Pulled count=1 msg=Container image ""busybox:musl"" already present on machine"
90.5884,Event,ADDED,eval-sanitize-20-r1-089-gkjss.18d41ab32460c0ec,reason=Created count=1 msg=Created container: task
90.6189,Job,MODIFIED,eval-sanitize-20-r1-061,
90.6213,Event,ADDED,eval-sanitize-20-r1-089-gkjss.18d41ab326485fa3,reason=Started count=1 msg=Started container task
90.6276,Job,MODIFIED,eval-sanitize-20-r1-061,
90.6628,Job,MODIFIED,eval-sanitize-20-r1-076,
90.6746,Job,MODIFIED,eval-sanitize-20-r1-076,
90.7168,Pod,MODIFIED,eval-sanitize-20-r1-077-h59q8,phase=Succeeded node=kind-worker4
90.7666,Pod,MODIFIED,eval-sanitize-20-r1-074-4hsdp,phase=Succeeded node=kind-worker4
90.8174,Pod,MODIFIED,eval-sanitize-20-r1-069-dxq4t,phase=Succeeded node=kind-worker4
90.8662,Pod,MODIFIED,eval-sanitize-20-r1-061-sjpk6,phase=Succeeded node=kind-worker3
91.0078,TaskRequest,ADDED,eval-sanitize-20-r1-091,phase=None job=None
91.0125,TaskRequest,MODIFIED,eval-sanitize-20-r1-091,phase=Pending job=None
91.026,Job,ADDED,eval-sanitize-20-r1-091,
91.0317,TaskRequest,MODIFIED,eval-sanitize-20-r1-091,phase=Scheduled job=None
91.035,Job,MODIFIED,eval-sanitize-20-r1-091,
91.0376,TaskRequest,MODIFIED,eval-sanitize-20-r1-091,phase=Scheduled job=None
91.1618,Job,MODIFIED,eval-sanitize-20-r1-062,
91.1705,Job,MODIFIED,eval-sanitize-20-r1-062,
91.2132,Job,MODIFIED,eval-sanitize-20-r1-070,
91.2217,Job,MODIFIED,eval-sanitize-20-r1-070,
91.2386,Pod,MODIFIED,eval-sanitize-20-r1-089-gkjss,phase=Running node=kind-worker4
91.2648,Job,MODIFIED,eval-sanitize-20-r1-072,
91.274,Job,MODIFIED,eval-sanitize-20-r1-072,
91.2879,Pod,MODIFIED,eval-sanitize-20-r1-080-lt4pd,phase=Running node=kind-worker2
91.3138,Job,MODIFIED,eval-sanitize-20-r1-059,
91.3232,Job,MODIFIED,eval-sanitize-20-r1-059,
91.369,Job,MODIFIED,eval-sanitize-20-r1-071,
91.378,Job,MODIFIED,eval-sanitize-20-r1-071,
91.4664,Pod,MODIFIED,eval-sanitize-20-r1-070-c8j2t,phase=Succeeded node=kind-worker3
91.5148,Pod,MODIFIED,eval-sanitize-20-r1-079-tz46z,phase=Succeeded node=kind-worker5
91.5173,Pod,MODIFIED,eval-sanitize-20-r1-072-q7qwt,phase=Succeeded node=kind-worker3
91.5657,Pod,MODIFIED,eval-sanitize-20-r1-059-vz4jf,phase=Succeeded node=kind-worker3
91.6169,Pod,MODIFIED,eval-sanitize-20-r1-071-b576n,phase=Succeeded node=kind-worker3
91.6651,Pod,ADDED,eval-sanitize-20-r1-090-xz2jk,phase=Pending node=None
91.7101,Pod,MODIFIED,eval-sanitize-20-r1-090-xz2jk,phase=Pending node=kind-worker4
91.7168,Event,ADDED,eval-sanitize-20-r1-090-xz2jk.18d41ab3675f6811,reason=Scheduled count=None msg=Successfully assigned compute/eval-sanitize-20-r1-090-xz2jk to kind-worker4
91.7324,Pod,MODIFIED,eval-sanitize-20-r1-090-xz2jk,phase=Pending node=kind-worker4
91.914,Job,MODIFIED,eval-sanitize-20-r1-090,
91.9227,Job,MODIFIED,eval-sanitize-20-r1-090,
91.9639,Event,ADDED,eval-sanitize-20-r1-090.18d41ab364b5e740,reason=SuccessfulCreate count=1 msg=Created pod: eval-sanitize-20-r1-090-xz2jk
92.0141,Job,MODIFIED,eval-sanitize-20-r1-066,
92.0142,TaskRequest,ADDED,eval-sanitize-20-r1-092,phase=None job=None
92.0184,TaskRequest,MODIFIED,eval-sanitize-20-r1-066,phase=Complete job=None
92.0246,TaskRequest,MODIFIED,eval-sanitize-20-r1-092,phase=Pending job=None
92.0299,Job,MODIFIED,eval-sanitize-20-r1-066,
92.0411,Job,ADDED,eval-sanitize-20-r1-092,
92.0452,TaskRequest,MODIFIED,eval-sanitize-20-r1-092,phase=Scheduled job=None
92.0501,Job,MODIFIED,eval-sanitize-20-r1-092,
92.0517,TaskRequest,MODIFIED,eval-sanitize-20-r1-092,phase=Scheduled job=None
92.061,Job,MODIFIED,eval-sanitize-20-r1-055,
92.0683,TaskRequest,MODIFIED,eval-sanitize-20-r1-055,phase=Complete job=None
92.0998,Job,MODIFIED,eval-sanitize-20-r1-055,
92.1115,Job,MODIFIED,eval-sanitize-20-r1-073,
92.1154,TaskRequest,MODIFIED,eval-sanitize-20-r1-073,phase=Complete job=None
92.1252,Job,MODIFIED,eval-sanitize-20-r1-073,
92.1395,Event,ADDED,eval-sanitize-20-r1-090-xz2jk.18d41ab380cbe1eb,"reason=Pulled count=1 msg=Container image ""busybox:musl"" already present on machine"
92.1561,Event,ADDED,eval-sanitize-20-r1-090-xz2jk.18d41ab381d10823,reason=Created count=1 msg=Created container: task
92.1616,Job,MODIFIED,eval-sanitize-20-r1-075,
92.1717,Job,MODIFIED,eval-sanitize-20-r1-075,
92.212,Job,MODIFIED,eval-sanitize-20-r1-056,
92.2166,TaskRequest,MODIFIED,eval-sanitize-20-r1-056,phase=Complete job=None
92.2272,Job,MODIFIED,eval-sanitize-20-r1-056,
92.2276,Event,ADDED,eval-sanitize-20-r1-090-xz2jk.18d41ab385f6001b,reason=Started count=1 msg=Started container task
92.2389,Pod,MODIFIED,eval-sanitize-20-r1-090-xz2jk,phase=Running node=kind-worker4
92.2619,Job,MODIFIED,eval-sanitize-20-r1-089,
92.27,Job,MODIFIED,eval-sanitize-20-r1-089,
92.2908,Pod,MODIFIED,eval-sanitize-20-r1-081-r27jp,phase=Running node=kind-worker2
92.3108,Event,ADDED,eval-sanitize-20-r1-066.18d41ab3797fbbc4,reason=Completed count=1 msg=Job completed
92.3637,Job,MODIFIED,eval-sanitize-20-r1-078,
92.3708,Pod,MODIFIED,eval-sanitize-20-r1-080-lt4pd,phase=Succeeded node=kind-worker2
92.3746,Job,MODIFIED,eval-sanitize-20-r1-078,
92.4129,Job,MODIFIED,eval-sanitize-20-r1-065,
92.4164,TaskRequest,MODIFIED,eval-sanitize-20-r1-065,phase=Complete job=None
92.4256,Job,MODIFIED,eval-sanitize-20-r1-065,
92.5127,Job,MODIFIED,eval-sanitize-20-r1-064,
92.5169,TaskRequest,MODIFIED,eval-sanitize-20-r1-064,phase=Complete job=None
92.5256,Job,MODIFIED,eval-sanitize-20-r1-064,
92.5618,Job,MODIFIED,eval-sanitize-20-r1-068,
92.5651,TaskRequest,MODIFIED,eval-sanitize-20-r1-068,phase=Complete job=None
92.5734,Job,MODIFIED,eval-sanitize-20-r1-068,
92.6106,Event,ADDED,eval-sanitize-20-r1-055.18d41ab37c58c024,reason=Completed count=1 msg=Job completed
92.6662,Pod,MODIFIED,eval-sanitize-20-r1-078-6cjg2,phase=Succeeded node=kind-worker5
92.7123,Job,MODIFIED,eval-sanitize-20-r1-058,
92.7156,TaskRequest,MODIFIED,eval-sanitize-20-r1-058,phase=Complete job=None
92.7247,Job,MODIFIED,eval-sanitize-20-r1-058,
92.7624,Job,MODIFIED,eval-sanitize-20-r1-077,
92.7709,Job,MODIFIED,eval-sanitize-20-r1-077,
92.8147,Job,MODIFIED,eval-sanitize-20-r1-067,
92.8194,TaskRequest,MODIFIED,eval-sanitize-20-r1-067,phase=Complete job=None
92.8287,Job,MODIFIED,eval-sanitize-20-r1-067,
92.8641,Pod,ADDED,eval-sanitize-20-r1-091-dd6jj,phase=Pending node=None
92.8918,Pod,MODIFIED,eval-sanitize-20-r1-091-dd6jj,phase=Pending node=kind-worker2
92.8954,Event,ADDED,eval-sanitize-20-r1-091-dd6jj.18d41ab3addaa683,reason=Scheduled count=None msg=Successfully assigned compute/eval-sanitize-20-r1-091-dd6jj to kind-worker2
92.9034,Pod,MODIFIED,eval-sanitize-20-r1-091-dd6jj,phase=Pending node=kind-worker2
92.9097,Event,ADDED,eval-sanitize-20-r1-073.18d41ab37f5671c8,reason=Completed count=1 msg=Job completed
93.0078,TaskRequest,ADDED,eval-sanitize-20-r1-093,phase=None job=None
93.0116,Job,MODIFIED,eval-sanitize-20-r1-060,
93.0118,TaskRequest,MODIFIED,eval-sanitize-20-r1-093,phase=Pending job=None
93.0271,Job,ADDED,eval-sanitize-20-r1-093,
93.0316,TaskRequest,MODIFIED,eval-sanitize-20-r1-093,phase=Scheduled job=None
93.0346,Job,MODIFIED,eval-sanitize-20-r1-093,
93.0351,TaskRequest,MODIFIED,eval-sanitize-20-r1-060,phase=Complete job=None
93.0385,TaskRequest,MODIFIED,eval-sanitize-20-r1-093,phase=Scheduled job=None
93.0441,Job,MODIFIED,eval-sanitize-20-r1-060,
93.1123,Job,MODIFIED,eval-sanitize-20-r1-079,
93.1218,Job,MODIFIED,eval-sanitize-20-r1-079,
93.1635,Job,MODIFIED,eval-sanitize-20-r1-091,
93.1721,Job,MODIFIED,eval-sanitize-20-r1-091,
93.2115,Event,ADDED,eval-sanitize-20-r1-056.18d41ab38555659a,reason=Completed count=1 msg=Job completed
93.2687,Job,MODIFIED,eval-sanitize-20-r1-074,
93.2778,Job,MODIFIED,eval-sanitize-20-r1-074,
93.3121,Job,MODIFIED,eval-sanitize-20-r1-069,
93.3241,Job,MODIFIED,eval-sanitize-20-r1-069,
93.3322,Event,ADDED,eval-sanitize-20-r1-091-dd6jj.18d41ab3c7dd3ce1,"reason=Pulled count=1 msg=Container image ""busybox:musl"" already present on machine"
93.3517,Event,ADDED,eval-sanitize-20-r1-091-dd6jj.18d41ab3c8f28c5a,reason=Created count=1 msg=Created container: task
93.3615,Job,MODIFIED,eval-sanitize-20-r1-061,
93.3714,Job,MODIFIED,eval-sanitize-20-r1-061,
93.4041,Pod,MODIFIED,eval-sanitize-20-r1-082-2rds5,phase=Running node=kind-worker5
93.4148,Pod,MODIFIED,eval-sanitize-20-r1-079-tz46z,phase=Succeeded node=kind-worker5
93.4344,Event,ADDED,eval-sanitize-20-r1-091-dd6jj.18d41ab3cdf1aefb,reason=Started count=1 msg=Started container task
93.4613,Job,MODIFIED,eval-sanitize-20-r1-076,
93.4653,TaskRequest,MODIFIED,eval-sanitize-20-r1-076,phase=Complete job=None
93.4749,Job,MODIFIED,eval-sanitize-20-r1-076,
93.477,Pod,MODIFIED,eval-sanitize-20-r1-081-r27jp,phase=Succeeded node=kind-worker2
93.513,Event,ADDED,eval-sanitize-20-r1-065.18d41ab3914a2b19,reason=Completed count=1 msg=Job completed
93.7639,Pod,ADDED,eval-sanitize-20-r1-092-4642z,phase=Pending node=None
93.7901,Pod,MODIFIED,eval-sanitize-20-r1-092-4642z,phase=Pending node=kind-worker3
93.7936,Event,ADDED,eval-sanitize-20-r1-092-4642z.18d41ab3e35cb6af,reason=Scheduled count=None msg=Successfully assigned compute/eval-sanitize-20-r1-092-4642z to kind-worker3
93.7997,Pod,MODIFIED,eval-sanitize-20-r1-092-4642z,phase=Pending node=kind-worker3
93.8024,Node,MODIFIED,kind-worker3,taints=0
93.81,Event,ADDED,eval-sanitize-20-r1-064.18d41ab3973e8e06,reason=Completed count=1 msg=Job completed
93.8136,Node,MODIFIED,kind-worker3,taints=0
93.8671,Job,MODIFIED,eval-sanitize-20-r1-062,
93.8719,TaskRequest,MODIFIED,eval-sanitize-20-r1-062,phase=Complete job=None
93.8807,Job,MODIFIED,eval-sanitize-20-r1-062,
93.9119,Job,MODIFIED,eval-sanitize-20-r1-070,
93.9201,Job,MODIFIED,eval-sanitize-20-r1-070,
93.963,Job,MODIFIED,eval-sanitize-20-r1-072,
93.9718,Job,MODIFIED,eval-sanitize-20-r1-072,
94.0079,TaskRequest,ADDED,eval-sanitize-20-r1-094,phase=None job=None
94.0126,Job,MODIFIED,eval-sanitize-20-r1-080,
94.0128,TaskRequest,MODIFIED,eval-sanitize-20-r1-094,phase=Pending job=None
94.0285,Job,ADDED,eval-sanitize-20-r1-094,
94.0328,TaskRequest,MODIFIED,eval-sanitize-20-r1-094,phase=Scheduled job=None
94.0382,Job,MODIFIED,eval-sanitize-20-r1-094,
94.0411,TaskRequest,MODIFIED,eval-sanitize-20-r1-094,phase=Scheduled job=None
94.0439,Job,MODIFIED,eval-sanitize-20-r1-080,
94.0609,Job,MODIFIED,eval-sanitize-20-r1-092,
94.0694,Job,MODIFIED,eval-sanitize-20-r1-092,
94.1108,Event,ADDED,eval-sanitize-20-r1-068.18d41ab39a2eeeeb,reason=Completed count=1 msg=Job completed
94.1627,Job,MODIFIED,eval-sanitize-20-r1-059,
94.1718,Job,MODIFIED,eval-sanitize-20-r1-059,
94.2295,Event,ADDED,eval-sanitize-20-r1-092-4642z.18d41ab3fd5acedb,"reason=Pulled count=1 msg=Container image ""busybox:musl"" already present on machine"
94.2503,Event,ADDED,eval-sanitize-20-r1-092-4642z.18d41ab3fe738493,reason=Created count=1 msg=Created container: task
94.3088,Pod,MODIFIED,eval-sanitize-20-r1-091-dd6jj,phase=Running node=kind-worker2
94.3118,Event,ADDED,eval-sanitize-20-r1-092-4642z.18d41ab402466c24,reason=Started count=1 msg=Started container task
94.315,Pod,MODIFIED,eval-sanitize-20-r1-080-lt4pd,phase=Succeeded node=kind-worker2
94.3626,Job,MODIFIED,eval-sanitize-20-r1-071,
94.3715,Job,MODIFIED,eval-sanitize-20-r1-071,
94.4027,Pod,MODIFIED,eval-sanitize-20-r1-083-lrj6h,phase=Running node=kind-worker5
94.4137,Event,ADDED,eval-sanitize-20-r1-058.18d41ab3a322cb15,reason=Completed count=1 msg=Job completed
94.5167,Job,MODIFIED,eval-sanitize-20-r1-090,
94.5256,Job,MODIFIED,eval-sanitize-20-r1-090,
94.5645,Pod,MODIFIED,eval-sanitize-20-r1-082-2rds5,phase=Succeeded node=kind-worker5
94.5652,Pod,ADDED,eval-sanitize-20-r1-093-dxr9x,phase=Pending node=None
94.5948,Pod,MODIFIED,eval-sanitize-20-r1-093-dxr9x,phase=Pending node=kind-worker
94.5988,Event,ADDED,eval-sanitize-20-r1-093-dxr9x.18d41ab4135d7344,reason=Scheduled count=None msg=Successfully assigned compute/eval-sanitize-20-r1-093-dxr9x to kind-worker
94.6047,Pod,MODIFIED,eval-sanitize-20-r1-093-dxr9x,phase=Pending node=kind-worker
94.7295,Event,ADDED,eval-sanitize-20-r1-067.18d41ab3a93e1f02,reason=Completed count=1 msg=Job completed
94.7745,Job,MODIFIED,eval-sanitize-20-r1-075,
94.7797,TaskRequest,MODIFIED,eval-sanitize-20-r1-075,phase=Complete job=None
94.7909,Job,MODIFIED,eval-sanitize-20-r1-075,
94.7934,Pod,MODIFIED,eval-sanitize-20-r1-092-4642z,phase=Running node=kind-worker3
94.8112,Job,MODIFIED,eval-sanitize-20-r1-081,
94.8203,Job,MODIFIED,eval-sanitize-20-r1-081,
94.83,Node,MODIFIED,kind-worker,taints=1
94.8428,Node,MODIFIED,kind-worker,taints=1
94.8613,Job,MODIFIED,eval-sanitize-20-r1-093,
94.8696,Job,MODIFIED,eval-sanitize-20-r1-093,
94.9123,Job,MODIFIED,eval-sanitize-20-r1-078,
94.9217,Job,MODIFIED,eval-sanitize-20-r1-078,
94.9668,Job,MODIFIED,eval-sanitize-20-r1-077,
94.9714,TaskRequest,MODIFIED,eval-sanitize-20-r1-077,phase=Complete job=None
94.9805,Job,MODIFIED,eval-sanitize-20-r1-077,
95.0093,TaskRequest,ADDED,eval-sanitize-20-r1-095,phase=None job=None
95.0119,Event,ADDED,eval-sanitize-20-r1-091.18d41ab3ac3459b2,reason=SuccessfulCreate count=1 msg=Created pod: eval-sanitize-20-r1-091-dd6jj
95.0131,TaskRequest,MODIFIED,eval-sanitize-20-r1-095,phase=Pending job=None
95.0158,Event,ADDED,eval-sanitize-20-r1-093-dxr9x.18d41ab42c3e0f2b,"reason=Pulled count=1 msg=Container image ""busybox:musl"" already present on machine"
95.0291,Job,ADDED,eval-sanitize-20-r1-095,
95.0334,TaskRequest,MODIFIED,eval-sanitize-20-r1-095,phase=Scheduled job=None
95.0381,Job,MODIFIED,eval-sanitize-20-r1-095,
95.0386,Event,ADDED,eval-sanitize-20-r1-093-dxr9x.18d41ab42d98f1e1,reason=Created count=1 msg=Created container: task
95.0548,TaskRequest,MODIFIED,eval-sanitize-20-r1-095,phase=Scheduled job=None
95.0613,Job,MODIFIED,eval-sanitize-20-r1-091,
95.0696,Job,MODIFIED,eval-sanitize-20-r1-091,
95.129,Pod,MODIFIED,eval-sanitize-20-r1-081-r27jp,phase=Succeeded node=kind-worker2
95.1322,Event,ADDED,eval-sanitize-20-r1-093-dxr9x.18d41ab4332fa5e2,reason=Started count=1 msg=Started container task
95.1849,Pod,ADDED,eval-sanitize-20-r1-094-88d8m,phase=Pending node=None
95.2039,Pod,MODIFIED,eval-sanitize-20-r1-094-88d8m,phase=Pending node=kind-worker4
95.2073,Event,ADDED,eval-sanitize-20-r1-094-88d8m.18d41ab437a61d14,reason=Scheduled count=None msg=Successfully assigned compute/eval-sanitize-20-r1-094-88d8m to kind-worker4
95.2137,Pod,MODIFIED,eval-sanitize-20-r1-094-88d8m,phase=Pending node=kind-worker4
95.2745,Job,MODIFIED,eval-sanitize-20-r1-079,
95.2834,Job,MODIFIED,eval-sanitize-20-r1-079,
95.3036,Pod,MODIFIED,eval-sanitize-20-r1-084-cxfx5,phase=Running node=kind-worker2
95.3101,Event,ADDED,eval-sanitize-20-r1-060.18d41ab3b4fd792a,reason=Completed count=1 msg=Job completed
95.3722,Job,MODIFIED,eval-sanitize-20-r1-074,
95.3753,TaskRequest,MODIFIED,eval-sanitize-20-r1-074,phase=Complete job=None
95.3848,Job,MODIFIED,eval-sanitize-20-r1-074,
95.4678,Job,MODIFIED,eval-sanitize-20-r1-094,
95.4764,Job,MODIFIED,eval-sanitize-20-r1-094,
95.5113,Job,MODIFIED,eval-sanitize-20-r1-069,
95.5151,TaskRequest,MODIFIED,eval-sanitize-20-r1-069,phase=Complete job=None
95.5251,Job,MODIFIED,eval-sanitize-20-r1-069,
95.5685,Pod,MODIFIED,eval-sanitize-20-r1-083-lrj6h,phase=Succeeded node=kind-worker5
95.6112,Event,ADDED,eval-sanitize-20-r1-076.18d41ab3cfcb0902,reason=Completed count=1 msg=Job completed
95.6313,Event,ADDED,eval-sanitize-20-r1-094-88d8m.18d41ab450d8f832,"reason=Pulled count=1 msg=Container image ""busybox:musl"" already present on machine"
95.6481,Event,ADDED,eval-sanitize-20-r1-094-88d8m.18d41ab451f0b814,reason=Created count=1 msg=Created container: task
95.6622,Job,MODIFIED,eval-sanitize-20-r1-061,
95.6674,TaskRequest,MODIFIED,eval-sanitize-20-r1-061,phase=Complete job=None
95.6793,Job,MODIFIED,eval-sanitize-20-r1-061,
95.6811,Event,ADDED,eval-sanitize-20-r1-094-88d8m.18d41ab453e6ddac,reason=Started count=1 msg=Started container task
95.7114,Job,MODIFIED,eval-sanitize-20-r1-082,
95.7205,Job,MODIFIED,eval-sanitize-20-r1-082,
95.768,Job,MODIFIED,eval-sanitize-20-r1-092,
95.7763,Job,MODIFIED,eval-sanitize-20-r1-092,
95.823,Job,MODIFIED,eval-sanitize-20-r1-070,
95.8269,TaskRequest,MODIFIED,eval-sanitize-20-r1-070,phase=Complete job=None
95.8366,Job,MODIFIED,eval-sanitize-20-r1-070,
95.8521,Node,MODIFIED,kind-worker4,taints=1
95.8609,Job,MODIFIED,eval-sanitize-20-r1-072,
95.8649,Node,MODIFIED,kind-worker4,taints=1
95.865,TaskRequest,MODIFIED,eval-sanitize-20-r1-072,phase=Complete job=None
95.8732,Job,MODIFIED,eval-sanitize-20-r1-072,
95.8928,Pod,MODIFIED,eval-sanitize-20-r1-093-dxr9x,phase=Running node=kind-worker
95.8979,Pod,MODIFIED,eval-sanitize-20-r1-085-d2r7k,phase=Running node=kind-worker
95.9099,Event,ADDED,eval-sanitize-20-r1-092.18d41ab3e1d2279d,reason=SuccessfulCreate count=1 msg=Created pod: eval-sanitize-20-r1-092-4642z
95.9626,Job,MODIFIED,eval-sanitize-20-r1-080,
95.9715,Job,MODIFIED,eval-sanitize-20-r1-080,
96.0151,TaskRequest,ADDED,eval-sanitize-20-r1-096,phase=None job=None
96.0186,Pod,MODIFIED,eval-sanitize-20-r1-082-2rds5,phase=Succeeded node=kind-worker5
96.0188,TaskRequest,MODIFIED,eval-sanitize-20-r1-096,phase=Pending job=None
96.0333,Job,ADDED,eval-sanitize-20-r1-096,
96.0378,TaskRequest,MODIFIED,eval-sanitize-20-r1-096,phase=Scheduled job=None
96.0421,Job,MODIFIED,eval-sanitize-20-r1-096,
96.0449,TaskRequest,MODIFIED,eval-sanitize-20-r1-096,phase=Scheduled job=None
96.0618,Pod,ADDED,eval-sanitize-20-r1-095-rwhnl,phase=Pending node=None
96.0773,Pod,MODIFIED,eval-sanitize-20-r1-095-rwhnl,phase=Pending node=kind-worker3
96.0819,Event,ADDED,eval-sanitize-20-r1-095-rwhnl.18d41ab46bb43e2d,reason=Scheduled count=None msg=Successfully assigned compute/eval-sanitize-20-r1-095-rwhnl to kind-worker3
96.0877,Pod,MODIFIED,eval-sanitize-20-r1-095-rwhnl,phase=Pending node=kind-worker3
96.1147,Job,MODIFIED,eval-sanitize-20-r1-059,
96.1193,TaskRequest,MODIFIED,eval-sanitize-20-r1-059,phase=Complete job=None
96.1303,Job,MODIFIED,eval-sanitize-20-r1-059,
96.1763,Node,MODIFIED,kind-worker3,taints=1
96.1775,Job,MODIFIED,eval-sanitize-20-r1-071,
96.1824,TaskRequest,MODIFIED,eval-sanitize-20-r1-071,phase=Complete job=None
96.1887,Node,MODIFIED,kind-worker3,taints=1
96.1916,Job,MODIFIED,eval-sanitize-20-r1-071,
96.2097,Event,ADDED,eval-sanitize-20-r1-062.18d41ab3e7f60a8c,reason=Completed count=1 msg=Job completed
96.2478,Pod,MODIFIED,eval-sanitize-20-r1-094-88d8m,phase=Running node=kind-worker4
96.3656,Job,MODIFIED,eval-sanitize-20-r1-095,
96.3746,Job,MODIFIED,eval-sanitize-20-r1-095,
96.4121,Job,MODIFIED,eval-sanitize-20-r1-083,
96.4217,Job,MODIFIED,eval-sanitize-20-r1-083,
96.435,Pod,MODIFIED,eval-sanitize-20-r1-084-cxfx5,phase=Succeeded node=kind-worker2
96.4669,Job,MODIFIED,eval-sanitize-20-r1-093,
96.4757,Job,MODIFIED,eval-sanitize-20-r1-093,
96.4982,Event,ADDED,eval-sanitize-20-r1-095-rwhnl.18d41ab4849a4c7c,"reason=Pulled count=1 msg=Container image ""busybox:musl"" already present on machine"
96.5116,Event,ADDED,eval-sanitize-20-r1-093.18d41ab4118c43ae,reason=SuccessfulCreate count=1 msg=Created pod: eval-sanitize-20-r1-093-dxr9x
96.5179,Event,ADDED,eval-sanitize-20-r1-095-rwhnl.18d41ab485c6d6d4,reason=Created count=1 msg=Created container: task
96.5622,Job,MODIFIED,eval-sanitize-20-r1-081,
96.5717,Job,MODIFIED,eval-sanitize-20-r1-081,
96.5779,Event,ADDED,eval-sanitize-20-r1-095-rwhnl.18d41ab4895c0697,reason=Started count=1 msg=Started container task
96.6253,Job,MODIFIED,eval-sanitize-20-r1-078,
96.6298,TaskRequest,MODIFIED,eval-sanitize-20-r1-078,phase=Complete job=None
96.6395,Job,MODIFIED,eval-sanitize-20-r1-078,
96.6639,Pod,ADDED,eval-sanitize-20-r1-096-52wjb,phase=Pending node=None
96.6741,Pod,MODIFIED,eval-sanitize-20-r1-096-52wjb,phase=Pending node=None
96.6744,Event,ADDED,eval-sanitize-20-r1-096-52wjb.18d41ab48f07b225,"reason=FailedScheduling count=None msg=0/6 nodes are available: 1 c_wall violated: 1 conflicting context pair(s) with node memory, 1 c_wall violated: 2 conflicting context pair(s) with node memory, 4 node(s) had untolerated taint(s). no new claims to deallocate, preemption: 0/6 nodes are available: 2 No preemption victims found for incoming pod, 4 Preemption is not helpful for scheduling."
96.6832,Event,ADDED,eval-sanitize-20-r1-096-52wjb.18d41ab48f9a3bfd,"reason=FailedScheduling count=None msg=0/6 nodes are available: 1 c_wall violated: 1 conflicting context pair(s) with node memory, 1 c_wall violated: 2 conflicting context pair(s) with node memory, 4 node(s) had untolerated taint(s). no new claims to deallocate, preemption: 0/6 nodes are available: 2 No preemption victims found for incoming pod, 4 Preemption is not helpful for scheduling."
96.7187,Pod,MODIFIED,eval-sanitize-20-r1-083-lrj6h,phase=Succeeded node=kind-worker5
96.7658,Job,MODIFIED,eval-sanitize-20-r1-094,
96.7745,Job,MODIFIED,eval-sanitize-20-r1-094,
96.803,Pod,MODIFIED,eval-sanitize-20-r1-095-rwhnl,phase=Running node=kind-worker3
96.81,Event,ADDED,eval-sanitize-20-r1-075.18d41ab41e0d23d5,reason=Completed count=1 msg=Job completed
96.8132,Event,MODIFIED,eval-sanitize-20-r1-096-52wjb.18d41ab48f9a3bfd,"reason=FailedScheduling count=None msg=0/6 nodes are available: 1 c_wall violated: 1 conflicting context pair(s) with node memory, 1 c_wall violated: 2 conflicting context pair(s) with node memory, 4 node(s) had untolerated taint(s). no new claims to deallocate, preemption: 0/6 nodes are available: 2 No preemption victims found for incoming pod, 4 Preemption is not helpful for scheduling."
96.9205,Job,MODIFIED,eval-sanitize-20-r1-079,
96.9246,TaskRequest,MODIFIED,eval-sanitize-20-r1-079,phase=Complete job=None
96.9344,Job,MODIFIED,eval-sanitize-20-r1-079,
96.9792,Job,MODIFIED,eval-sanitize-20-r1-096,
96.9879,Job,MODIFIED,eval-sanitize-20-r1-096,
97.0131,TaskRequest,ADDED,eval-sanitize-20-r1-097,phase=None job=None
97.0168,TaskRequest,MODIFIED,eval-sanitize-20-r1-097,phase=Pending job=None
97.0231,Pod,MODIFIED,eval-sanitize-20-r1-085-d2r7k,phase=Succeeded node=kind-worker
97.0329,Job,ADDED,eval-sanitize-20-r1-097,
97.0371,TaskRequest,MODIFIED,eval-sanitize-20-r1-097,phase=Scheduled job=None
97.0415,Job,MODIFIED,eval-sanitize-20-r1-097,
97.0435,TaskRequest,MODIFIED,eval-sanitize-20-r1-097,phase=Scheduled job=None
97.0605,Job,MODIFIED,eval-sanitize-20-r1-084,
97.0693,Job,MODIFIED,eval-sanitize-20-r1-084,
97.1245,Event,ADDED,eval-sanitize-20-r1-077.18d41ab429874ac6,reason=Completed count=1 msg=Job completed
97.1716,Job,MODIFIED,eval-sanitize-20-r1-082,
97.1826,Job,MODIFIED,eval-sanitize-20-r1-082,
97.2114,Job,MODIFIED,eval-sanitize-20-r1-095,
97.2196,Job,MODIFIED,eval-sanitize-20-r1-095,
97.2673,Job,MODIFIED,eval-sanitize-20-r1-085,
97.2756,Job,MODIFIED,eval-sanitize-20-r1-085,
97.3157,Job,MODIFIED,eval-sanitize-20-r1-080,
97.3203,TaskRequest,MODIFIED,eval-sanitize-20-r1-080,phase=Complete job=None
97.3296,Job,MODIFIED,eval-sanitize-20-r1-080,
97.3747,Pod,MODIFIED,eval-sanitize-20-r1-084-cxfx5,phase=Succeeded node=kind-worker2
97.4088,Pod,MODIFIED,eval-sanitize-20-r1-086-hff6x,phase=Running node=kind-worker5
97.4102,Event,ADDED,eval-sanitize-20-r1-094.18d41ab4368b2ecd,reason=SuccessfulCreate count=1 msg=Created pod: eval-sanitize-20-r1-094-88d8m
97.4406,Node,MODIFIED,kind-worker2,taints=1
97.4484,Pod,MODIFIED,eval-sanitize-20-r1-096-52wjb,phase=Pending node=None
97.4533,Node,MODIFIED,kind-worker2,taints=1
97.4552,Event,ADDED,eval-sanitize-20-r1-096-52wjb.18d41ab4bda99bd1,"reason=FailedScheduling count=None msg=0/6 nodes are available: 1 c_wall violated: 2 conflicting context pair(s) with node memory, 5 node(s) had untolerated taint(s). no new claims to deallocate, preemption: 0/6 nodes are available: 1 No preemption victims found for incoming pod, 5 Preemption is not helpful for scheduling."
97.4594,Event,MODIFIED,eval-sanitize-20-r1-096-52wjb.18d41ab4bda99bd1,"reason=FailedScheduling count=None msg=0/6 nodes are available: 1 c_wall violated: 2 conflicting context pair(s) with node memory, 5 node(s) had untolerated taint(s). no new claims to deallocate, preemption: 0/6 nodes are available: 1 No preemption victims found for incoming pod, 5 Preemption is not helpful for scheduling."
97.5113,Job,MODIFIED,eval-sanitize-20-r1-083,
97.5201,Job,MODIFIED,eval-sanitize-20-r1-083,
97.5708,Pod,ADDED,eval-sanitize-20-r1-097-2bqqh,phase=Pending node=None
97.5789,Pod,MODIFIED,eval-sanitize-20-r1-097-2bqqh,phase=Pending node=None
97.5792,Event,ADDED,eval-sanitize-20-r1-097-2bqqh.18d41ab4c4f2ca0b,"reason=FailedScheduling count=None msg=0/6 nodes are available: 1 c_wall violated: 2 conflicting context pair(s) with node memory, 5 node(s) had untolerated taint(s). no new claims to deallocate, preemption: 0/6 nodes are available: 1 No preemption victims found for incoming pod, 5 Preemption is not helpful for scheduling."
97.5846,Event,ADDED,eval-sanitize-20-r1-097-2bqqh.18d41ab4c56ac95c,"reason=FailedScheduling count=None msg=0/6 nodes are available: 1 c_wall violated: 2 conflicting context pair(s) with node memory, 5 node(s) had untolerated taint(s). no new claims to deallocate, preemption: 0/6 nodes are available: 1 No preemption victims found for incoming pod, 5 Preemption is not helpful for scheduling."
97.6613,Event,ADDED,eval-sanitize-20-r1-074.18d41ab441b3dc85,reason=Completed count=1 msg=Job completed
97.758,Node,MODIFIED,kind-worker5,taints=1
97.7615,Job,MODIFIED,eval-sanitize-20-r1-081,
97.7636,Pod,MODIFIED,eval-sanitize-20-r1-096-52wjb,phase=Pending node=None
97.765,TaskRequest,MODIFIED,eval-sanitize-20-r1-081,phase=Complete job=None
97.7686,Pod,MODIFIED,eval-sanitize-20-r1-097-2bqqh,phase=Pending node=None
97.7701,Event,MODIFIED,eval-sanitize-20-r1-097-2bqqh.18d41ab4c56ac95c,"reason=FailedScheduling count=None msg=0/6 nodes are available: 1 c_wall violated: 2 conflicting context pair(s) with node memory, 5 node(s) had untolerated taint(s). no new claims to deallocate, preemption: 0/6 nodes are available: 1 No preemption victims found for incoming pod, 5 Preemption is not helpful for scheduling."
97.7717,Node,MODIFIED,kind-worker5,taints=1
97.7751,Job,MODIFIED,eval-sanitize-20-r1-081,
97.8247,Job,MODIFIED,eval-sanitize-20-r1-097,
97.8341,Job,MODIFIED,eval-sanitize-20-r1-097,
97.8663,Job,MODIFIED,eval-sanitize-20-r1-084,
97.8979,Job,MODIFIED,eval-sanitize-20-r1-084,
97.9109,Event,ADDED,eval-sanitize-20-r1-069.18d41ab449f89b18,reason=Completed count=1 msg=Job completed
97.9656,Job,MODIFIED,eval-sanitize-20-r1-083,
97.9707,TaskRequest,MODIFIED,eval-sanitize-20-r1-083,phase=Complete job=None
97.9809,Job,MODIFIED,eval-sanitize-20-r1-083,
98.028,TaskRequest,ADDED,eval-sanitize-20-r1-098,phase=None job=None
98.0327,TaskRequest,MODIFIED,eval-sanitize-20-r1-098,phase=Pending job=None
98.0464,Job,ADDED,eval-sanitize-20-r1-098,
98.0521,TaskRequest,MODIFIED,eval-sanitize-20-r1-098,phase=Scheduled job=None
98.0551,Job,MODIFIED,eval-sanitize-20-r1-098,
98.0591,TaskRequest,MODIFIED,eval-sanitize-20-r1-098,phase=Scheduled job=None
98.0599,Event,ADDED,eval-sanitize-20-r1-061.18d41ab452faa428,reason=Completed count=1 msg=Job completed
98.1231,Job,MODIFIED,eval-sanitize-20-r1-085,
98.1317,Job,MODIFIED,eval-sanitize-20-r1-085,
98.1613,Pod,ADDED,eval-sanitize-20-r1-098-k4zs9,phase=Pending node=None
98.1665,Pod,MODIFIED,eval-sanitize-20-r1-098-k4zs9,phase=Pending node=None
98.1673,Event,ADDED,eval-sanitize-20-r1-098-k4zs9.18d41ab4e7ee1c56,"reason=FailedScheduling count=None msg=0/6 nodes are available: 6 node(s) had untolerated taint(s). no new claims to deallocate, preemption: 0/6 nodes are available: 6 Preemption is not helpful for scheduling."
98.2407,Event,ADDED,eval-sanitize-20-r1-070.18d41ab45c8d8f61,reason=Completed count=1 msg=Job completed
98.266,Pod,MODIFIED,eval-sanitize-20-r1-085-d2r7k,phase=Succeeded node=kind-worker
98.3192,Pod,MODIFIED,eval-sanitize-20-r1-087-4lvhn,phase=Running node=kind-worker2
98.3618,Job,MODIFIED,eval-sanitize-20-r1-082,
98.3666,TaskRequest,MODIFIED,eval-sanitize-20-r1-082,phase=Complete job=None
98.3762,Job,MODIFIED,eval-sanitize-20-r1-082,
98.418,Event,ADDED,eval-sanitize-20-r1-072.18d41ab45ed3a250,reason=Completed count=1 msg=Job completed
98.5469,Job,MODIFIED,eval-sanitize-20-r1-086,
98.5576,Pod,MODIFIED,eval-sanitize-20-r1-086-hff6x,phase=Succeeded node=kind-worker5
98.5584,Job,MODIFIED,eval-sanitize-20-r1-086,
98.5609,Event,ADDED,eval-sanitize-20-r1-095.18d41ab46aceb21c,reason=SuccessfulCreate count=1 msg=Created pod: eval-sanitize-20-r1-095-rwhnl
98.6264,Event,ADDED,eval-sanitize-20-r1-059.18d41ab46df1962b,reason=Completed count=1 msg=Job completed
98.6991,Job,MODIFIED,eval-sanitize-20-r1-084,
98.7056,TaskRequest,MODIFIED,eval-sanitize-20-r1-084,phase=Complete job=None
98.7102,Event,ADDED,eval-sanitize-20-r1-071.18d41ab471b46e25,reason=Completed count=1 msg=Job completed
98.7153,Job,MODIFIED,eval-sanitize-20-r1-084,
98.7754,Event,ADDED,eval-sanitize-20-r1-078.18d41ab48c5c5559,reason=Completed count=1 msg=Job completed
98.8111,Event,ADDED,eval-sanitize-20-r1-096.18d41ab48eb4b670,reason=SuccessfulCreate count=1 msg=Created pod: eval-sanitize-20-r1-096-52wjb
98.8922,Event,ADDED,eval-sanitize-20-r1-079.18d41ab49df70e34,reason=Completed count=1 msg=Job completed
98.9108,Event,ADDED,eval-sanitize-20-r1-080.18d41ab4b58dc69c,reason=Completed count=1 msg=Job completed
98.9756,Event,ADDED,eval-sanitize-20-r1-097.18d41ab4c4bf289d,reason=SuccessfulCreate count=1 msg=Created pod: eval-sanitize-20-r1-097-2bqqh
99.0189,Event,ADDED,eval-sanitize-20-r1-081.18d41ab4d020fb38,reason=Completed count=1 msg=Job completed
99.0193,TaskRequest,ADDED,eval-sanitize-20-r1-099,phase=None job=None
99.0228,TaskRequest,MODIFIED,eval-sanitize-20-r1-099,phase=Pending job=None
99.0397,Job,ADDED,eval-sanitize-20-r1-099,
99.0448,TaskRequest,MODIFIED,eval-sanitize-20-r1-099,phase=Scheduled job=None
99.0493,Job,MODIFIED,eval-sanitize-20-r1-099,
99.0514,TaskRequest,MODIFIED,eval-sanitize-20-r1-099,phase=Scheduled job=None
99.06,Event,ADDED,eval-sanitize-20-r1-083.18d41ab4dc31c850,reason=Completed count=1 msg=Job completed
99.1271,Pod,ADDED,eval-sanitize-20-r1-099-2ss89,phase=Pending node=None
99.1326,Pod,MODIFIED,eval-sanitize-20-r1-099-2ss89,phase=Pending node=None
99.133,Event,ADDED,eval-sanitize-20-r1-099-2ss89.18d41ab5217cc021,"reason=FailedScheduling count=None msg=0/6 nodes are available: 6 node(s) had untolerated taint(s). no new claims to deallocate, preemption: 0/6 nodes are available: 6 Preemption is not helpful for scheduling."
99.1998,Job,MODIFIED,eval-sanitize-20-r1-098,
99.2089,Job,MODIFIED,eval-sanitize-20-r1-098,
99.2097,Event,ADDED,eval-sanitize-20-r1-098.18d41ab4e7e5b09f,reason=SuccessfulCreate count=1 msg=Created pod: eval-sanitize-20-r1-098-k4zs9
99.2978,Job,MODIFIED,eval-sanitize-20-r1-085,
99.3072,Job,MODIFIED,eval-sanitize-20-r1-085,
99.3985,Event,ADDED,eval-sanitize-20-r1-082.18d41ab4f3d1737b,reason=Completed count=1 msg=Job completed
99.4059,Pod,MODIFIED,eval-sanitize-20-r1-087-4lvhn,phase=Succeeded node=kind-worker2
99.4735,Job,MODIFIED,eval-sanitize-20-r1-087,
99.4823,Job,MODIFIED,eval-sanitize-20-r1-087,
99.5476,Event,ADDED,eval-sanitize-20-r1-084.18d41ab507ef1eb8,reason=Completed count=1 msg=Job completed
99.5608,Job,MODIFIED,eval-sanitize-20-r1-086,
99.5701,Job,MODIFIED,eval-sanitize-20-r1-086,
99.6386,Event,ADDED,eval-sanitize-20-r1-099.18d41ab52172d896,reason=SuccessfulCreate count=1 msg=Created pod: eval-sanitize-20-r1-099-2ss89
99.6828,Pod,MODIFIED,eval-sanitize-20-r1-086-hff6x,phase=Succeeded node=kind-worker5
99.9141,Pod,MODIFIED,eval-sanitize-20-r1-088-wkvql,phase=Running node=kind-worker
100.0631,Job,MODIFIED,eval-sanitize-20-r1-099,
100.0728,Job,MODIFIED,eval-sanitize-20-r1-099,
100.3101,Job,MODIFIED,eval-sanitize-20-r1-085,
100.3139,Event,ADDED,eval-sanitize-20-r1-085.18d41ab567f62916,reason=Completed count=1 msg=Job completed
100.3146,TaskRequest,MODIFIED,eval-sanitize-20-r1-085,phase=Complete job=None
100.3262,Job,MODIFIED,eval-sanitize-20-r1-085,
100.427,Job,MODIFIED,eval-sanitize-20-r1-087,
100.4357,Pod,MODIFIED,eval-sanitize-20-r1-087-4lvhn,phase=Succeeded node=kind-worker2
100.4369,Job,MODIFIED,eval-sanitize-20-r1-087,
100.567,Job,MODIFIED,eval-sanitize-20-r1-086,
100.5731,Job,MODIFIED,eval-sanitize-20-r1-086,
100.5766,Event,ADDED,eval-sanitize-20-r1-086.18d41ab5779a3415,reason=Completed count=1 msg=Job completed
100.583,Job,MODIFIED,eval-sanitize-20-r1-086,
100.5889,TaskRequest,MODIFIED,eval-sanitize-20-r1-086,phase=Complete job=None
100.5979,Job,MODIFIED,eval-sanitize-20-r1-086,
100.9206,Job,MODIFIED,eval-sanitize-20-r1-088,
100.9308,Job,MODIFIED,eval-sanitize-20-r1-088,
100.9905,Pod,MODIFIED,eval-sanitize-20-r1-088-wkvql,phase=Succeeded node=kind-worker
101.2578,Pod,MODIFIED,eval-sanitize-20-r1-089-gkjss,phase=Running node=kind-worker4
101.4342,Job,MODIFIED,eval-sanitize-20-r1-087,
101.4381,Job,MODIFIED,eval-sanitize-20-r1-087,
101.4412,Event,ADDED,eval-sanitize-20-r1-087.18d41ab5ab3697d0,reason=Completed count=1 msg=Job completed
101.4501,Job,MODIFIED,eval-sanitize-20-r1-087,
101.4557,TaskRequest,MODIFIED,eval-sanitize-20-r1-087,phase=Complete job=None
101.4652,Job,MODIFIED,eval-sanitize-20-r1-087,
101.9276,Job,MODIFIED,eval-sanitize-20-r1-088,
101.9365,Pod,MODIFIED,eval-sanitize-20-r1-088-wkvql,phase=Succeeded node=kind-worker
101.9378,Job,MODIFIED,eval-sanitize-20-r1-088,
102.261,Pod,MODIFIED,eval-sanitize-20-r1-090-xz2jk,phase=Running node=kind-worker4
102.2633,Job,MODIFIED,eval-sanitize-20-r1-089,
102.2743,Job,MODIFIED,eval-sanitize-20-r1-089,
102.3935,Pod,MODIFIED,eval-sanitize-20-r1-089-gkjss,phase=Succeeded node=kind-worker4
102.9347,Job,MODIFIED,eval-sanitize-20-r1-088,
102.9393,Job,MODIFIED,eval-sanitize-20-r1-088,
102.9465,Event,ADDED,eval-sanitize-20-r1-088.18d41ab604a97284,reason=Completed count=1 msg=Job completed
102.952,Job,MODIFIED,eval-sanitize-20-r1-088,
102.958,TaskRequest,MODIFIED,eval-sanitize-20-r1-088,phase=Complete job=None
102.9673,Job,MODIFIED,eval-sanitize-20-r1-088,
103.2674,Job,MODIFIED,eval-sanitize-20-r1-090,
103.2694,Job,MODIFIED,eval-sanitize-20-r1-089,
103.2774,Job,MODIFIED,eval-sanitize-20-r1-090,
103.2808,Pod,MODIFIED,eval-sanitize-20-r1-089-gkjss,phase=Succeeded node=kind-worker4
103.2844,Job,MODIFIED,eval-sanitize-20-r1-089,
103.3624,Pod,MODIFIED,eval-sanitize-20-r1-090-xz2jk,phase=Succeeded node=kind-worker4
104.2743,Job,MODIFIED,eval-sanitize-20-r1-090,
104.2766,Job,MODIFIED,eval-sanitize-20-r1-089,
104.2812,Job,MODIFIED,eval-sanitize-20-r1-089,
104.2834,Job,MODIFIED,eval-sanitize-20-r1-090,
104.285,Pod,MODIFIED,eval-sanitize-20-r1-090-xz2jk,phase=Succeeded node=kind-worker4
104.2863,Event,ADDED,eval-sanitize-20-r1-089.18d41ab654acfd2b,reason=Completed count=1 msg=Job completed
104.2927,Job,MODIFIED,eval-sanitize-20-r1-089,
104.2981,TaskRequest,MODIFIED,eval-sanitize-20-r1-089,phase=Complete job=None
104.3072,Job,MODIFIED,eval-sanitize-20-r1-089,
104.3277,Pod,MODIFIED,eval-sanitize-20-r1-091-dd6jj,phase=Running node=kind-worker2
104.8204,Pod,MODIFIED,eval-sanitize-20-r1-092-4642z,phase=Running node=kind-worker3
105.2821,Job,MODIFIED,eval-sanitize-20-r1-090,
105.2861,Job,MODIFIED,eval-sanitize-20-r1-090,
105.2891,Event,ADDED,eval-sanitize-20-r1-090.18d41ab6909150f6,reason=Completed count=1 msg=Job completed
105.2984,Job,MODIFIED,eval-sanitize-20-r1-090,
105.3038,TaskRequest,MODIFIED,eval-sanitize-20-r1-090,phase=Complete job=None
105.3265,Job,MODIFIED,eval-sanitize-20-r1-090,
105.3333,Job,MODIFIED,eval-sanitize-20-r1-091,
105.3432,Job,MODIFIED,eval-sanitize-20-r1-091,
105.4233,Pod,MODIFIED,eval-sanitize-20-r1-091-dd6jj,phase=Succeeded node=kind-worker2
105.8284,Job,MODIFIED,eval-sanitize-20-r1-092,
105.8403,Job,MODIFIED,eval-sanitize-20-r1-092,
105.8986,Pod,MODIFIED,eval-sanitize-20-r1-092-4642z,phase=Succeeded node=kind-worker3
105.9268,Pod,MODIFIED,eval-sanitize-20-r1-093-dxr9x,phase=Running node=kind-worker
106.2769,Pod,MODIFIED,eval-sanitize-20-r1-094-88d8m,phase=Running node=kind-worker4
106.3392,Job,MODIFIED,eval-sanitize-20-r1-091,
106.3521,Pod,MODIFIED,eval-sanitize-20-r1-091-dd6jj,phase=Succeeded node=kind-worker2
106.3533,Job,MODIFIED,eval-sanitize-20-r1-091,
106.8226,Pod,MODIFIED,eval-sanitize-20-r1-095-rwhnl,phase=Running node=kind-worker3
106.8323,Job,MODIFIED,eval-sanitize-20-r1-092,
106.8404,Pod,MODIFIED,eval-sanitize-20-r1-092-4642z,phase=Succeeded node=kind-worker3
106.8421,Job,MODIFIED,eval-sanitize-20-r1-092,
106.933,Job,MODIFIED,eval-sanitize-20-r1-093,
106.9429,Job,MODIFIED,eval-sanitize-20-r1-093,
107.0254,Pod,MODIFIED,eval-sanitize-20-r1-093-dxr9x,phase=Succeeded node=kind-worker
107.283,Job,MODIFIED,eval-sanitize-20-r1-094,
107.2922,Job,MODIFIED,eval-sanitize-20-r1-094,
107.3444,Job,MODIFIED,eval-sanitize-20-r1-091,
107.3488,Job,MODIFIED,eval-sanitize-20-r1-091,
107.3512,Pod,MODIFIED,eval-sanitize-20-r1-094-88d8m,phase=Succeeded node=kind-worker4
107.3539,Event,ADDED,eval-sanitize-20-r1-091.18d41ab70b852056,reason=Completed count=1 msg=Job completed
107.3599,Job,MODIFIED,eval-sanitize-20-r1-091,
107.3675,TaskRequest,MODIFIED,eval-sanitize-20-r1-091,phase=Complete job=None
107.3761,Job,MODIFIED,eval-sanitize-20-r1-091,
107.8294,Job,MODIFIED,eval-sanitize-20-r1-095,
107.8383,Job,MODIFIED,eval-sanitize-20-r1-092,
107.8426,Job,MODIFIED,eval-sanitize-20-r1-095,
107.845,Job,MODIFIED,eval-sanitize-20-r1-092,
107.8483,Event,ADDED,eval-sanitize-20-r1-092.18d41ab7291b16ec,reason=Completed count=1 msg=Job completed
107.8549,Job,MODIFIED,eval-sanitize-20-r1-092,
107.861,TaskRequest,MODIFIED,eval-sanitize-20-r1-092,phase=Complete job=None
107.8707,Job,MODIFIED,eval-sanitize-20-r1-092,
107.9043,Pod,MODIFIED,eval-sanitize-20-r1-095-rwhnl,phase=Succeeded node=kind-worker3
107.9407,Job,MODIFIED,eval-sanitize-20-r1-093,
107.949,Pod,MODIFIED,eval-sanitize-20-r1-093-dxr9x,phase=Succeeded node=kind-worker
107.9506,Job,MODIFIED,eval-sanitize-20-r1-093,
108.2928,Job,MODIFIED,eval-sanitize-20-r1-094,
108.3019,Pod,MODIFIED,eval-sanitize-20-r1-094-88d8m,phase=Succeeded node=kind-worker4
108.3028,Job,MODIFIED,eval-sanitize-20-r1-094,
108.8357,Job,MODIFIED,eval-sanitize-20-r1-095,
108.8448,Pod,MODIFIED,eval-sanitize-20-r1-095-rwhnl,phase=Succeeded node=kind-worker3
108.8466,Job,MODIFIED,eval-sanitize-20-r1-095,
108.9481,Job,MODIFIED,eval-sanitize-20-r1-093,
108.9533,Job,MODIFIED,eval-sanitize-20-r1-093,
108.9583,Event,ADDED,eval-sanitize-20-r1-093.18d41ab76b2c046f,reason=Completed count=1 msg=Job completed
108.9657,Job,MODIFIED,eval-sanitize-20-r1-093,
108.9706,TaskRequest,MODIFIED,eval-sanitize-20-r1-093,phase=Complete job=None
108.98,Job,MODIFIED,eval-sanitize-20-r1-093,
109.2991,Job,MODIFIED,eval-sanitize-20-r1-094,
109.304,Job,MODIFIED,eval-sanitize-20-r1-094,
109.3088,Event,ADDED,eval-sanitize-20-r1-094.18d41ab7800f3426,reason=Completed count=1 msg=Job completed
109.3172,Job,MODIFIED,eval-sanitize-20-r1-094,
109.3218,TaskRequest,MODIFIED,eval-sanitize-20-r1-094,phase=Complete job=None
109.332,Job,MODIFIED,eval-sanitize-20-r1-094,
109.8436,Job,MODIFIED,eval-sanitize-20-r1-095,
109.8482,Job,MODIFIED,eval-sanitize-20-r1-095,
109.853,Event,ADDED,eval-sanitize-20-r1-095.18d41ab7a0861361,reason=Completed count=1 msg=Job completed
109.8597,Job,MODIFIED,eval-sanitize-20-r1-095,
109.8648,TaskRequest,MODIFIED,eval-sanitize-20-r1-095,phase=Complete job=None
109.8753,Job,MODIFIED,eval-sanitize-20-r1-095,
115.606,Node,MODIFIED,kind-worker,taints=1
115.6217,Node,MODIFIED,kind-worker,taints=0
115.6274,Pod,MODIFIED,eval-sanitize-20-r1-096-52wjb,phase=Pending node=kind-worker
115.6325,Node,MODIFIED,kind-worker,taints=0
115.6389,Event,ADDED,eval-sanitize-20-r1-096-52wjb.18d41ab8f8f89ad4,reason=Scheduled count=None msg=Successfully assigned compute/eval-sanitize-20-r1-096-52wjb to kind-worker
115.6425,Event,ADDED,eval-sanitize-20-r1-098-k4zs9.18d41ab8f9675b3f,"reason=FailedScheduling count=None msg=0/6 nodes are available: 1 c_wall violated: 1 conflicting context pair(s) with node memory, 5 node(s) had untolerated taint(s). no new claims to deallocate, preemption: 0/6 nodes are available: 1 No preemption victims found for incoming pod, 5 Preemption is not helpful for scheduling."
115.6438,Pod,MODIFIED,eval-sanitize-20-r1-097-2bqqh,phase=Pending node=kind-worker
115.6453,Pod,MODIFIED,eval-sanitize-20-r1-098-k4zs9,phase=Pending node=None
115.6466,Node,MODIFIED,kind-worker,taints=0
115.6503,Pod,MODIFIED,eval-sanitize-20-r1-096-52wjb,phase=Pending node=kind-worker
115.6522,Event,ADDED,eval-sanitize-20-r1-097-2bqqh.18d41ab8f9ebdd52,reason=Scheduled count=None msg=Successfully assigned compute/eval-sanitize-20-r1-097-2bqqh to kind-worker
115.6547,Event,ADDED,eval-sanitize-20-r1-099-2ss89.18d41ab8fa2e3915,"reason=FailedScheduling count=None msg=0/6 nodes are available: 1 c_wall violated: 1 conflicting context pair(s) with node memory, 5 node(s) had untolerated taint(s). no new claims to deallocate, preemption: 0/6 nodes are available: 1 No preemption victims found for incoming pod, 5 Preemption is not helpful for scheduling."
115.6557,Pod,MODIFIED,eval-sanitize-20-r1-099-2ss89,phase=Pending node=None
115.6584,Pod,MODIFIED,eval-sanitize-20-r1-097-2bqqh,phase=Pending node=kind-worker
115.6633,Node,MODIFIED,kind-worker,taints=0
115.6804,Event,ADDED,eval-sanitize-20-r1-098-k4zs9.18d41ab8fbf63205,"reason=FailedScheduling count=None msg=0/6 nodes are available: 1 c_wall violated: 1 conflicting context pair(s) with node memory, 5 node(s) had untolerated taint(s). no new claims to deallocate, preemption: 0/6 nodes are available: 1 No preemption victims found for incoming pod, 5 Preemption is not helpful for scheduling."
115.6841,Event,ADDED,eval-sanitize-20-r1-099-2ss89.18d41ab8fc2d610c,"reason=FailedScheduling count=None msg=0/6 nodes are available: 1 c_wall violated: 1 conflicting context pair(s) with node memory, 5 node(s) had untolerated taint(s). no new claims to deallocate, preemption: 0/6 nodes are available: 1 No preemption victims found for incoming pod, 5 Preemption is not helpful for scheduling."
115.6875,Node,MODIFIED,kind-worker,taints=0
115.7035,Node,MODIFIED,kind-worker,taints=0
115.7064,Event,MODIFIED,eval-sanitize-20-r1-098-k4zs9.18d41ab8fbf63205,"reason=FailedScheduling count=None msg=0/6 nodes are available: 1 c_wall violated: 1 conflicting context pair(s) with node memory, 5 node(s) had untolerated taint(s). no new claims to deallocate, preemption: 0/6 nodes are available: 1 No preemption victims found for incoming pod, 5 Preemption is not helpful for scheduling."
115.7108,Event,MODIFIED,eval-sanitize-20-r1-099-2ss89.18d41ab8fc2d610c,"reason=FailedScheduling count=None msg=0/6 nodes are available: 1 c_wall violated: 1 conflicting context pair(s) with node memory, 5 node(s) had untolerated taint(s). no new claims to deallocate, preemption: 0/6 nodes are available: 1 No preemption victims found for incoming pod, 5 Preemption is not helpful for scheduling."
115.7143,Node,MODIFIED,kind-worker,taints=0
116.0671,Event,ADDED,eval-sanitize-20-r1-096-52wjb.18d41ab912ef5584,"reason=Pulled count=1 msg=Container image ""busybox:musl"" already present on machine"
116.0706,Event,ADDED,eval-sanitize-20-r1-097-2bqqh.18d41ab913128802,"reason=Pulled count=1 msg=Container image ""busybox:musl"" already present on machine"
116.0897,Event,ADDED,eval-sanitize-20-r1-096-52wjb.18d41ab9144ab485,reason=Created count=1 msg=Created container: task
116.0967,Event,ADDED,eval-sanitize-20-r1-097-2bqqh.18d41ab914ae250f,reason=Created count=1 msg=Created container: task
116.16,Event,ADDED,eval-sanitize-20-r1-096-52wjb.18d41ab91880e4ac,reason=Started count=1 msg=Started container task
116.1636,Event,ADDED,eval-sanitize-20-r1-097-2bqqh.18d41ab91880e493,reason=Started count=1 msg=Started container task
116.2502,Node,MODIFIED,kind-worker4,taints=1
116.2637,Node,MODIFIED,kind-worker4,taints=1
116.2723,Node,MODIFIED,kind-worker4,taints=0
116.2808,Pod,MODIFIED,eval-sanitize-20-r1-098-k4zs9,phase=Pending node=kind-worker4
116.2855,Node,MODIFIED,kind-worker4,taints=0
116.2904,Pod,MODIFIED,eval-sanitize-20-r1-098-k4zs9,phase=Pending node=kind-worker4
116.3359,Event,ADDED,eval-sanitize-20-r1-098-k4zs9.18d41ab922e57ee5,reason=Scheduled count=None msg=Successfully assigned compute/eval-sanitize-20-r1-098-k4zs9 to kind-worker4
116.3407,Node,MODIFIED,kind-worker4,taints=0
116.3426,Pod,MODIFIED,eval-sanitize-20-r1-099-2ss89,phase=Pending node=kind-worker4
116.3461,Event,ADDED,eval-sanitize-20-r1-099-2ss89.18d41ab923966f9d,reason=Scheduled count=None msg=Successfully assigned compute/eval-sanitize-20-r1-099-2ss89 to kind-worker4
116.3512,Node,MODIFIED,kind-worker4,taints=0
116.3535,Pod,MODIFIED,eval-sanitize-20-r1-099-2ss89,phase=Pending node=kind-worker4
116.5533,Node,MODIFIED,kind-worker3,taints=1
116.5657,Node,MODIFIED,kind-worker3,taints=0
116.5757,Node,MODIFIED,kind-worker3,taints=0
116.5874,Node,MODIFIED,kind-worker3,taints=0
116.703,Event,ADDED,eval-sanitize-20-r1-098-k4zs9.18d41ab938c312d2,"reason=Pulled count=1 msg=Container image ""busybox:musl"" already present on machine"
116.7211,Event,ADDED,eval-sanitize-20-r1-098-k4zs9.18d41ab939e35683,reason=Created count=1 msg=Created container: task
116.7482,Event,ADDED,eval-sanitize-20-r1-099-2ss89.18d41ab93b8aeff0,"reason=Pulled count=1 msg=Container image ""busybox:musl"" already present on machine"
116.7551,Event,ADDED,eval-sanitize-20-r1-098-k4zs9.18d41ab93c05aff3,reason=Started count=1 msg=Started container task
116.7662,Event,ADDED,eval-sanitize-20-r1-099-2ss89.18d41ab93cafa7c0,reason=Created count=1 msg=Created container: task
116.8262,Event,ADDED,eval-sanitize-20-r1-099-2ss89.18d41ab940242907,reason=Started count=1 msg=Started container task
116.9581,Pod,MODIFIED,eval-sanitize-20-r1-097-2bqqh,phase=Running node=kind-worker
116.9641,Pod,MODIFIED,eval-sanitize-20-r1-096-52wjb,phase=Running node=kind-worker
117.2984,Pod,MODIFIED,eval-sanitize-20-r1-099-2ss89,phase=Running node=kind-worker4
117.3051,Pod,MODIFIED,eval-sanitize-20-r1-098-k4zs9,phase=Running node=kind-worker4
117.7643,Node,MODIFIED,kind-worker2,taints=1
117.7781,Node,MODIFIED,kind-worker2,taints=0
117.7881,Node,MODIFIED,kind-worker2,taints=0
117.8521,Node,MODIFIED,kind-worker2,taints=0
117.9634,Job,MODIFIED,eval-sanitize-20-r1-097,
117.9678,Job,MODIFIED,eval-sanitize-20-r1-096,
117.9723,Job,MODIFIED,eval-sanitize-20-r1-097,
117.9755,Job,MODIFIED,eval-sanitize-20-r1-096,
118.0662,Node,MODIFIED,kind-worker5,taints=1
118.1466,Node,MODIFIED,kind-worker5,taints=1
118.1575,Node,MODIFIED,kind-worker5,taints=0
118.1695,Node,MODIFIED,kind-worker5,taints=0
118.3048,Job,MODIFIED,eval-sanitize-20-r1-099,
118.3103,Job,MODIFIED,eval-sanitize-20-r1-098,
118.3142,Job,MODIFIED,eval-sanitize-20-r1-099,
118.318,Job,MODIFIED,eval-sanitize-20-r1-098,
120.0207,Node,ADDED,kind-control-plane,taints=1
120.0227,Pod,ADDED,eval-sanitize-20-r1-000-4gvxt,phase=Succeeded node=kind-worker3
120.0237,Event,ADDED,eval-sanitize-20-r1-000-4gvxt.18d41a9e12171fc1,reason=Scheduled count=None msg=Successfully assigned compute/eval-sanitize-20-r1-000-4gvxt to kind-worker3
120.0239,Event,ADDED,eval-sanitize-20-r1-000-4gvxt.18d41a9e2b1eeb84,"reason=Pulled count=1 msg=Container image ""busybox:musl"" already present on machine"
120.0242,Event,ADDED,eval-sanitize-20-r1-000-4gvxt.18d41a9e2c30f8c3,reason=Created count=1 msg=Created container: task
120.0245,Event,ADDED,eval-sanitize-20-r1-000-4gvxt.18d41a9e2e9b2f4c,reason=Started count=1 msg=Started container task
120.0249,Event,ADDED,eval-sanitize-20-r1-000.18d41a9e113b7a80,reason=SuccessfulCreate count=1 msg=Created pod: eval-sanitize-20-r1-000-4gvxt
120.025,TaskRequest,ADDED,eval-sanitize-20-r1-000,phase=Complete job=None
120.0268,Pod,ADDED,eval-sanitize-20-r1-001-fhsgn,phase=Succeeded node=kind-worker5
120.0271,Event,ADDED,eval-sanitize-20-r1-000.18d41aa1721aba2f,reason=Completed count=1 msg=Job completed
120.0273,Event,ADDED,eval-sanitize-20-r1-001-fhsgn.18d41a9e4c0aef4c,reason=Scheduled count=None msg=Successfully assigned compute/eval-sanitize-20-r1-001-fhsgn to kind-worker5
120.0275,Event,ADDED,eval-sanitize-20-r1-001-fhsgn.18d41a9e66777406,"reason=Pulled count=1 msg=Container image ""busybox:musl"" already present on machine"
120.0277,Event,ADDED,eval-sanitize-20-r1-001-fhsgn.18d41a9e67882f9a,reason=Created count=1 msg=Created container: task
120.0279,TaskRequest,ADDED,eval-sanitize-20-r1-001,phase=Complete job=None
120.0279,TaskRequest,ADDED,eval-sanitize-20-r1-002,phase=Complete job=None
120.0295,Node,ADDED,kind-worker,taints=0
120.0304,Job,ADDED,eval-sanitize-20-r1-000,
120.0319,Pod,ADDED,eval-sanitize-20-r1-002-v2wms,phase=Succeeded node=kind-worker
120.0325,Event,ADDED,eval-sanitize-20-r1-001-fhsgn.18d41a9e699e6339,reason=Started count=1 msg=Started container task
120.0329,Event,ADDED,eval-sanitize-20-r1-001.18d41a9e4b0431a5,reason=SuccessfulCreate count=1 msg=Created pod: eval-sanitize-20-r1-001-fhsgn
120.0332,Event,ADDED,eval-sanitize-20-r1-001.18d41aa1982c791d,reason=Completed count=1 msg=Job completed
120.0337,Event,ADDED,eval-sanitize-20-r1-002-v2wms.18d41a9e888f1e21,reason=Scheduled count=None msg=Successfully assigned compute/eval-sanitize-20-r1-002-v2wms to kind-worker
120.0339,Event,ADDED,eval-sanitize-20-r1-002-v2wms.18d41a9ea15647b3,"reason=Pulled count=1 msg=Container image ""busybox:musl"" already present on machine"
120.0342,Event,ADDED,eval-sanitize-20-r1-002-v2wms.18d41a9ea266d2ce,reason=Created count=1 msg=Created container: task
120.0344,Event,ADDED,eval-sanitize-20-r1-002-v2wms.18d41a9ea6533c73,reason=Started count=1 msg=Started container task
120.0346,Event,ADDED,eval-sanitize-20-r1-002.18d41a9e87921497,reason=SuccessfulCreate count=1 msg=Created pod: eval-sanitize-20-r1-002-v2wms
120.0349,Event,ADDED,eval-sanitize-20-r1-002.18d41aa1eba5953b,reason=Completed count=1 msg=Job completed
120.0351,Event,ADDED,eval-sanitize-20-r1-003-q9fhf.18d41a9ec4068e7b,reason=Scheduled count=None msg=Successfully assigned compute/eval-sanitize-20-r1-003-q9fhf to kind-worker3
120.0353,Event,ADDED,eval-sanitize-20-r1-003-q9fhf.18d41a9edf1162ac,"reason=Pulled count=1 msg=Container image ""busybox:musl"" already present on machine"
120.0356,Event,ADDED,eval-sanitize-20-r1-003-q9fhf.18d41a9ee02b0980,reason=Created count=1 msg=Created container: task
120.0359,Event,ADDED,eval-sanitize-20-r1-003-q9fhf.18d41a9ee2c8c3fc,reason=Started count=1 msg=Started container task
120.0361,Event,ADDED,eval-sanitize-20-r1-003.18d41a9ec2cb0f83,reason=SuccessfulCreate count=1 msg=Created pod: eval-sanitize-20-r1-003-q9fhf
120.0374,Pod,ADDED,eval-sanitize-20-r1-003-q9fhf,phase=Succeeded node=kind-worker3
120.0384,Job,ADDED,eval-sanitize-20-r1-001,
120.0385,TaskRequest,ADDED,eval-sanitize-20-r1-003,phase=Complete job=None
120.0386,TaskRequest,ADDED,eval-sanitize-20-r1-004,phase=Complete job=None
120.0387,TaskRequest,ADDED,eval-sanitize-20-r1-005,phase=Complete job=None
120.0401,Node,ADDED,kind-worker2,taints=0
120.0405,Event,ADDED,eval-sanitize-20-r1-003.18d41aa226d07322,reason=Completed count=1 msg=Job completed
120.0408,Event,ADDED,eval-sanitize-20-r1-004-tf9vj.18d41a9eff50964c,reason=Scheduled count=None msg=Successfully assigned compute/eval-sanitize-20-r1-004-tf9vj to kind-worker5
120.0411,Event,ADDED,eval-sanitize-20-r1-004-tf9vj.18d41a9f194a2990,"reason=Pulled count=1 msg=Container image ""busybox:musl"" already present on machine"
120.0414,Event,ADDED,eval-sanitize-20-r1-004-tf9vj.18d41a9f1a621cb7,reason=Created count=1 msg=Created container: task
120.0426,Pod,ADDED,eval-sanitize-20-r1-004-tf9vj,phase=Succeeded node=kind-worker5
120.0434,Job,ADDED,eval-sanitize-20-r1-002,
120.0436,TaskRequest,ADDED,eval-sanitize-20-r1-006,phase=Complete job=None
120.0436,TaskRequest,ADDED,eval-sanitize-20-r1-007,phase=Complete job=None
120.0437,TaskRequest,ADDED,eval-sanitize-20-r1-008,phase=Complete job=None
120.0441,Event,ADDED,eval-sanitize-20-r1-004-tf9vj.18d41a9f1cc041b7,reason=Started count=1 msg=Started container task
120.0443,Event,ADDED,eval-sanitize-20-r1-004.18d41a9efe2ce9e3,reason=SuccessfulCreate count=1 msg=Created pod: eval-sanitize-20-r1-004-tf9vj
120.0445,Event,ADDED,eval-sanitize-20-r1-004.18d41aa24ba72ca8,reason=Completed count=1 msg=Job completed
120.0446,Event,ADDED,eval-sanitize-20-r1-005-hcgjl.18d41a9f3ab91fa8,reason=Scheduled count=None msg=Successfully assigned compute/eval-sanitize-20-r1-005-hcgjl to kind-worker3
120.0448,TaskRequest,ADDED,eval-sanitize-20-r1-009,phase=Complete job=None
120.0449,TaskRequest,ADDED,eval-sanitize-20-r1-010,phase=Complete job=None
120.0467,Node,ADDED,kind-worker3,taints=0
120.0471,Event,ADDED,eval-sanitize-20-r1-005-hcgjl.18d41a9f53f1f632,"reason=Pulled count=1 msg=Container image ""busybox:musl"" already present on machine"
120.0473,Event,ADDED,eval-sanitize-20-r1-005-hcgjl.18d41a9f54fad805,reason=Created count=1 msg=Created container: task
120.0475,Event,ADDED,eval-sanitize-20-r1-005-hcgjl.18d41a9f570456ab,reason=Started count=1 msg=Started container task
120.049,Pod,ADDED,eval-sanitize-20-r1-005-hcgjl,phase=Succeeded node=kind-worker3
120.0501,Job,ADDED,eval-sanitize-20-r1-003,
120.0502,TaskRequest,ADDED,eval-sanitize-20-r1-011,phase=Complete job=None
120.0502,TaskRequest,ADDED,eval-sanitize-20-r1-012,phase=Complete job=None
120.0503,TaskRequest,ADDED,eval-sanitize-20-r1-013,phase=Complete job=None
120.0505,Event,ADDED,eval-sanitize-20-r1-005.18d41a9f39734aca,reason=SuccessfulCreate count=1 msg=Created pod: eval-sanitize-20-r1-005-hcgjl
120.0507,Event,ADDED,eval-sanitize-20-r1-005.18d41aa22779454b,reason=Completed count=1 msg=Job completed
120.0509,Event,ADDED,eval-sanitize-20-r1-006-bzlm5.18d41a9f77328ba6,reason=Scheduled count=None msg=Successfully assigned compute/eval-sanitize-20-r1-006-bzlm5 to kind-worker4
120.0511,Event,ADDED,eval-sanitize-20-r1-006-bzlm5.18d41a9f90a58792,"reason=Pulled count=1 msg=Container image ""busybox:musl"" already present on machine"
120.0523,Pod,ADDED,eval-sanitize-20-r1-006-bzlm5,phase=Succeeded node=kind-worker4
120.0531,Job,ADDED,eval-sanitize-20-r1-004,
120.0532,TaskRequest,ADDED,eval-sanitize-20-r1-014,phase=Complete job=None
120.0532,TaskRequest,ADDED,eval-sanitize-20-r1-015,phase=Complete job=None
120.0533,TaskRequest,ADDED,eval-sanitize-20-r1-016,phase=Complete job=None
120.0546,Node,ADDED,kind-worker4,taints=0
120.055,Event,ADDED,eval-sanitize-20-r1-006-bzlm5.18d41a9f91d56836,reason=Created count=1 msg=Created container: task
120.0552,Event,ADDED,eval-sanitize-20-r1-006-bzlm5.18d41a9f94c04680,reason=Started count=1 msg=Started container task
120.0554,Event,ADDED,eval-sanitize-20-r1-006.18d41a9f75f68b92,reason=SuccessfulCreate count=1 msg=Created pod: eval-sanitize-20-r1-006-bzlm5
120.0556,Event,ADDED,eval-sanitize-20-r1-006.18d41aa2b847de52,reason=Completed count=1 msg=Job completed
120.0558,TaskRequest,ADDED,eval-sanitize-20-r1-017,phase=Complete job=None
120.0559,TaskRequest,ADDED,eval-sanitize-20-r1-018,phase=Complete job=None
120.056,TaskRequest,ADDED,eval-sanitize-20-r1-019,phase=Complete job=None
120.056,TaskRequest,ADDED,eval-sanitize-20-r1-020,phase=Complete job=None
120.056,TaskRequest,ADDED,eval-sanitize-20-r1-021,phase=Complete job=None
120.0573,Pod,ADDED,eval-sanitize-20-r1-007-5jj5w,phase=Succeeded node=kind-worker2
120.0582,Job,ADDED,eval-sanitize-20-r1-005,
120.0584,Event,ADDED,eval-sanitize-20-r1-007-5jj5w.18d41a9fb569d83f,reason=Scheduled count=None msg=Successfully assigned compute/eval-sanitize-20-r1-007-5jj5w to kind-worker2
120.0587,Event,ADDED,eval-sanitize-20-r1-007-5jj5w.18d41a9fce7689d9,"reason=Pulled count=1 msg=Container image ""busybox:musl"" already present on machine"
120.0589,Event,ADDED,eval-sanitize-20-r1-007-5jj5w.18d41a9fcf8cb31e,reason=Created count=1 msg=Created container: task
120.0601,Node,ADDED,kind-worker5,taints=0
120.0602,TaskRequest,ADDED,eval-sanitize-20-r1-022,phase=Complete job=None
120.0603,TaskRequest,ADDED,eval-sanitize-20-r1-023,phase=Complete job=None
120.0615,Pod,ADDED,eval-sanitize-20-r1-008-vx6kf,phase=Succeeded node=kind-worker5
120.0624,Job,ADDED,eval-sanitize-20-r1-006,
120.0627,Event,ADDED,eval-sanitize-20-r1-007-5jj5w.18d41a9fd2275bf2,reason=Started count=1 msg=Started container task
