t_recv,kind,type,name,detail
0.0223,Node,ADDED,kind-control-plane,taints=1
0.0238,Node,ADDED,kind-worker,taints=0
0.0251,Node,ADDED,kind-worker2,taints=0
0.0266,Node,ADDED,kind-worker3,taints=0
0.0285,Node,ADDED,kind-worker4,taints=0
0.0298,Node,ADDED,kind-worker5,taints=0
0.0556,Event,ADDED,eval-sanitize-1-r0-008-xjcpg.18d4a1e9c947d4b5,"reason=FailedScheduling count=None msg=0/6 nodes are available: 1 c_wall violated: 1 conflicting context pair(s) with node memory, 5 node(s) had untolerated taint(s). no new claims to deallocate, preemption: 0/6 nodes are available: 1 No preemption victims found for incoming pod, 5 Preemption is not helpful for scheduling."
0.0561,Event,ADDED,eval-sanitize-1-r0-009-xq8hk.18d4a1e9d2eb1732,"reason=FailedScheduling count=None msg=0/6 nodes are available: 1 c_wall violated: 2 conflicting context pair(s) with node memory, 5 node(s) had untolerated taint(s). no new claims to deallocate, preemption: 0/6 nodes are available: 1 No preemption victims found for incoming pod, 5 Preemption is not helpful for scheduling."
0.0563,Event,ADDED,eval-sanitize-1-r0-009-xq8hk.18d4a1ea32474b03,"reason=FailedScheduling count=None msg=0/6 nodes are available: 1 c_wall violated: 2 conflicting context pair(s) with node memory, 5 node(s) had untolerated taint(s). no new claims to deallocate, preemption: 0/6 nodes are available: 1 No preemption victims found for incoming pod, 5 Preemption is not helpful for scheduling."
0.0565,Event,ADDED,eval-sanitize-1-r0-013-9dnkt.18d4a1e9ccb411ba,"reason=FailedScheduling count=None msg=0/6 nodes are available: 1 c_wall violated: 1 conflicting context pair(s) with node memory, 5 node(s) had untolerated taint(s). no new claims to deallocate, preemption: 0/6 nodes are available: 1 No preemption victims found for incoming pod, 5 Preemption is not helpful for scheduling."
0.057,Event,ADDED,eval-sanitize-1-r0-014-zhtr8.18d4a1e9d32500b5,"reason=FailedScheduling count=None msg=0/6 nodes are available: 1 c_wall violated: 3 conflicting context pair(s) with node memory, 5 node(s) had untolerated taint(s). no new claims to deallocate, preemption: 0/6 nodes are available: 1 No preemption victims found for incoming pod, 5 Preemption is not helpful for scheduling."
0.0572,Event,ADDED,eval-sanitize-1-r0-014-zhtr8.18d4a1ea3770d8f2,"reason=FailedScheduling count=None msg=0/6 nodes are available: 1 c_wall violated: 2 conflicting context pair(s) with node memory, 5 node(s) had untolerated taint(s). no new claims to deallocate, preemption: 0/6 nodes are available: 1 No preemption victims found for incoming pod, 5 Preemption is not helpful for scheduling."
0.0574,Event,ADDED,eval-sanitize-1-r0-016-7mb4n.18d4a1e9cd8eb7a2,"reason=FailedScheduling count=None msg=0/6 nodes are available: 1 c_wall violated: 3 conflicting context pair(s) with node memory, 5 node(s) had untolerated taint(s). no new claims to deallocate, preemption: 0/6 nodes are available: 1 No preemption victims found for incoming pod, 5 Preemption is not helpful for scheduling."
0.0578,Event,ADDED,eval-sanitize-1-r0-016-7mb4n.18d4a1ea37fe6c4c,"reason=FailedScheduling count=None msg=0/6 nodes are available: 1 c_wall violated: 2 conflicting context pair(s) with node memory, 5 node(s) had untolerated taint(s). no new claims to deallocate, preemption: 0/6 nodes are available: 1 No preemption victims found for incoming pod, 5 Preemption is not helpful for scheduling."
0.058,Event,ADDED,eval-sanitize-1-r0-018-6l9xb.18d4a1e9cf4b2dfc,"reason=FailedScheduling count=None msg=0/6 nodes are available: 1 c_wall violated: 2 conflicting context pair(s) with node memory, 5 node(s) had untolerated taint(s). no new claims to deallocate, preemption: 0/6 nodes are available: 1 No preemption victims found for incoming pod, 5 Preemption is not helpful for scheduling."
0.0585,Event,ADDED,eval-sanitize-1-r0-020-x7b6m.18d4a1e9cf9078e7,"reason=FailedScheduling count=None msg=0/6 nodes are available: 1 c_wall violated: 2 conflicting context pair(s) with node memory, 5 node(s) had untolerated taint(s). no new claims to deallocate, preemption: 0/6 nodes are available: 1 No preemption victims found for incoming pod, 5 Preemption is not helpful for scheduling."
0.0587,Event,ADDED,eval-sanitize-1-r0-024-gzh4k.18d4a1ea371163b9,"reason=FailedScheduling count=None msg=0/6 nodes are available: 1 c_wall violated: 2 conflicting context pair(s) with node memory, 5 node(s) had untolerated taint(s). no new claims to deallocate, preemption: 0/6 nodes are available: 1 No preemption victims found for incoming pod, 5 Preemption is not helpful for scheduling."
0.0589,Event,ADDED,eval-sanitize-1-r0-024-gzh4k.18d4a1ea6605d6c1,"reason=FailedScheduling count=None msg=0/6 nodes are available: 1 c_wall violated: 2 conflicting context pair(s) with node memory, 5 node(s) had untolerated taint(s). no new claims to deallocate, preemption: 0/6 nodes are available: 1 No preemption victims found for incoming pod, 5 Preemption is not helpful for scheduling."
0.0593,Event,ADDED,eval-sanitize-1-r0-030-vw62w.18d4a1ef6013c693,"reason=FailedScheduling count=None msg=0/6 nodes are available: 1 c_wall violated: 3 conflicting context pair(s) with node memory, 5 node(s) had untolerated taint(s). no new claims to deallocate, preemption: 0/6 nodes are available: 1 No preemption victims found for incoming pod, 5 Preemption is not helpful for scheduling."
0.0595,Event,ADDED,eval-sanitize-1-r0-030-vw62w.18d4a1efc5422c96,"reason=FailedScheduling count=None msg=0/6 nodes are available: 1 c_wall violated: 1 conflicting context pair(s) with node memory, 5 node(s) had untolerated taint(s). no new claims to deallocate, preemption: 0/6 nodes are available: 1 No preemption victims found for incoming pod, 5 Preemption is not helpful for scheduling."
0.0597,Event,ADDED,eval-sanitize-1-r0-032-sgw5t.18d4a1ef579e1698,"reason=FailedScheduling count=None msg=0/6 nodes are available: 1 c_wall violated: 1 conflicting context pair(s) with node memory, 5 node(s) had untolerated taint(s). no new claims to deallocate, preemption: 0/6 nodes are available: 1 No preemption victims found for incoming pod, 5 Preemption is not helpful for scheduling."
0.06,Event,ADDED,eval-sanitize-1-r0-033-dqq5s.18d4a1ef64b5615f,"reason=FailedScheduling count=None msg=0/6 nodes are available: 1 c_wall violated: 3 conflicting context pair(s) with node memory, 5 node(s) had untolerated taint(s). no new claims to deallocate, preemption: 0/6 nodes are available: 1 No preemption victims found for incoming pod, 5 Preemption is not helpful for scheduling."
0.0603,Event,ADDED,eval-sanitize-1-r0-033-dqq5s.18d4a1efc8c61c35,"reason=FailedScheduling count=None msg=0/6 nodes are available: 1 c_wall violated: 1 conflicting context pair(s) with node memory, 5 node(s) had untolerated taint(s). no new claims to deallocate, preemption: 0/6 nodes are available: 1 No preemption victims found for incoming pod, 5 Preemption is not helpful for scheduling."
0.0605,Event,ADDED,eval-sanitize-1-r0-035-ztqvr.18d4a1ef59b12f81,"reason=FailedScheduling count=None msg=0/6 nodes are available: 1 c_wall violated: 3 conflicting context pair(s) with node memory, 5 node(s) had untolerated taint(s). no new claims to deallocate, preemption: 0/6 nodes are available: 1 No preemption victims found for incoming pod, 5 Preemption is not helpful for scheduling."
0.0609,Event,ADDED,eval-sanitize-1-r0-036-m42xk.18d4a1ef59e7dce9,"reason=FailedScheduling count=None msg=0/6 nodes are available: 1 c_wall violated: 1 conflicting context pair(s) with node memory, 5 node(s) had untolerated taint(s). no new claims to deallocate, preemption: 0/6 nodes are available: 1 No preemption victims found for incoming pod, 5 Preemption is not helpful for scheduling."
0.0611,Event,ADDED,eval-sanitize-1-r0-038-zk8s4.18d4a1ef5a1c9978,"reason=FailedScheduling count=None msg=0/6 nodes are available: 1 c_wall violated: 3 conflicting context pair(s) with node memory, 5 node(s) had untolerated taint(s). no new claims to deallocate, preemption: 0/6 nodes are available: 1 No preemption victims found for incoming pod, 5 Preemption is not helpful for scheduling."
0.0613,Event,ADDED,eval-sanitize-1-r0-040-wvscn.18d4a1ef5a4b72a4,"reason=FailedScheduling count=None msg=0/6 nodes are available: 1 c_wall violated: 1 conflicting context pair(s) with node memory, 5 node(s) had untolerated taint(s). no new claims to deallocate, preemption: 0/6 nodes are available: 1 No preemption victims found for incoming pod, 5 Preemption is not helpful for scheduling."
0.0617,Event,ADDED,eval-sanitize-1-r0-040-wvscn.18d4a1efc3e8b338,"reason=FailedScheduling count=None msg=0/6 nodes are available: 1 c_wall violated: 1 conflicting context pair(s) with node memory, 5 node(s) had untolerated taint(s). no new claims to deallocate, preemption: 0/6 nodes are available: 1 No preemption victims found for incoming pod, 5 Preemption is not helpful for scheduling."
0.0619,Event,ADDED,eval-sanitize-1-r0-041-wblcb.18d4a1ef5a83eb2e,"reason=FailedScheduling count=None msg=0/6 nodes are available: 1 c_wall violated: 3 conflicting context pair(s) with node memory, 5 node(s) had untolerated taint(s). no new claims to deallocate, preemption: 0/6 nodes are available: 1 No preemption victims found for incoming pod, 5 Preemption is not helpful for scheduling."
0.0624,Event,ADDED,eval-sanitize-1-r0-042-8j6tf.18d4a1ef5eb6b07f,"reason=FailedScheduling count=None msg=0/6 nodes are available: 1 c_wall violated: 2 conflicting context pair(s) with node memory, 5 node(s) had untolerated taint(s). no new claims to deallocate, preemption: 0/6 nodes are available: 1 No preemption victims found for incoming pod, 5 Preemption is not helpful for scheduling."
0.0626,Event,ADDED,eval-sanitize-1-r0-042-8j6tf.18d4a1efc41a5164,"reason=FailedScheduling count=None msg=0/6 nodes are available: 1 c_wall violated: 1 conflicting context pair(s) with node memory, 5 node(s) had untolerated taint(s). no new claims to deallocate, preemption: 0/6 nodes are available: 1 No preemption victims found for incoming pod, 5 Preemption is not helpful for scheduling."
0.0628,Event,ADDED,eval-sanitize-1-r0-042-8j6tf.18d4a1f0163e26a2,"reason=FailedScheduling count=None msg=0/6 nodes are available: 1 c_wall violated: 1 conflicting context pair(s) with node memory, 5 node(s) had untolerated taint(s). no new claims to deallocate, preemption: 0/6 nodes are available: 1 No preemption victims found for incoming pod, 5 Preemption is not helpful for scheduling."
0.0632,Event,ADDED,eval-sanitize-1-r0-042-8j6tf.18d4a1f06ac459f6,"reason=FailedScheduling count=None msg=0/6 nodes are available: 1 c_wall violated: 1 conflicting context pair(s) with node memory, 5 node(s) had untolerated taint(s). no new claims to deallocate, preemption: 0/6 nodes are available: 1 No preemption victims found for incoming pod, 5 Preemption is not helpful for scheduling."
0.0634,Event,ADDED,eval-sanitize-1-r0-043-mzbz2.18d4a1ef5efefa2b,"reason=FailedScheduling count=None msg=0/6 nodes are available: 1 c_wall violated: 2 conflicting context pair(s) with node memory, 5 node(s) had untolerated taint(s). no new claims to deallocate, preemption: 0/6 nodes are available: 1 No preemption victims found for incoming pod, 5 Preemption is not helpful for scheduling."
0.0636,Event,ADDED,eval-sanitize-1-r0-043-mzbz2.18d4a1efc5133bb3,"reason=FailedScheduling count=None msg=0/6 nodes are available: 1 c_wall violated: 1 conflicting context pair(s) with node memory, 5 node(s) had untolerated taint(s). no new claims to deallocate, preemption: 0/6 nodes are available: 1 No preemption victims found for incoming pod, 5 Preemption is not helpful for scheduling."
0.064,Event,ADDED,eval-sanitize-1-r0-043-mzbz2.18d4a1f0166cd967,"reason=FailedScheduling count=None msg=0/6 nodes are available: 1 c_wall violated: 1 conflicting context pair(s) with node memory, 5 node(s) had untolerated taint(s). no new claims to deallocate, preemption: 0/6 nodes are available: 1 No preemption victims found for incoming pod, 5 Preemption is not helpful for scheduling."
0.0642,Event,ADDED,eval-sanitize-1-r0-043-mzbz2.18d4a1f06b07e4ea,"reason=FailedScheduling count=None msg=0/6 nodes are available: 1 c_wall violated: 1 conflicting context pair(s) with node memory, 5 node(s) had untolerated taint(s). no new claims to deallocate, preemption: 0/6 nodes are available: 1 No preemption victims found for incoming pod, 5 Preemption is not helpful for scheduling."
0.0644,Event,ADDED,eval-sanitize-1-r0-045-g45gd.18d4a1ef5fd82eea,"reason=FailedScheduling count=None msg=0/6 nodes are available: 1 c_wall violated: 1 conflicting context pair(s) with node memory, 5 node(s) had untolerated taint(s). no new claims to deallocate, preemption: 0/6 nodes are available: 1 No preemption victims found for incoming pod, 5 Preemption is not helpful for scheduling."
0.0648,Event,ADDED,eval-sanitize-1-r0-048-v6658.18d4a1efe630c432,"reason=FailedScheduling count=None msg=0/6 nodes are available: 1 c_wall violated: 1 conflicting context pair(s) with node memory, 5 node(s) had untolerated taint(s). no new claims to deallocate, preemption: 0/6 nodes are available: 1 No preemption victims found for incoming pod, 5 Preemption is not helpful for scheduling."
0.065,Event,ADDED,eval-sanitize-1-r0-048-v6658.18d4a1f016a0af8c,"reason=FailedScheduling count=None msg=0/6 nodes are available: 1 c_wall violated: 2 conflicting context pair(s) with node memory, 5 node(s) had untolerated taint(s). no new claims to deallocate, preemption: 0/6 nodes are available: 1 No preemption victims found for incoming pod, 5 Preemption is not helpful for scheduling."
0.0652,Event,ADDED,eval-sanitize-1-r0-049-8c67j.18d4a1f048b899fd,"reason=FailedScheduling count=None msg=0/6 nodes are available: 1 c_wall violated: 1 conflicting context pair(s) with node memory, 5 node(s) had untolerated taint(s). no new claims to deallocate, preemption: 0/6 nodes are available: 1 No preemption victims found for incoming pod, 5 Preemption is not helpful for scheduling."
0.0655,Event,ADDED,eval-sanitize-1-r0-050-2wdl4.18d4a1f0ee536f21,"reason=FailedScheduling count=None msg=0/6 nodes are available: 1 c_wall violated: 1 conflicting context pair(s) with node memory, 5 node(s) had untolerated taint(s). no new claims to deallocate, preemption: 0/6 nodes are available: 1 No preemption victims found for incoming pod, 5 Preemption is not helpful for scheduling."
0.0658,Event,ADDED,eval-sanitize-1-r0-051-6r7z5.18d4a1f0f27fd9c3,"reason=FailedScheduling count=None msg=0/6 nodes are available: 1 c_wall violated: 1 conflicting context pair(s) with node memory, 5 node(s) had untolerated taint(s). no new claims to deallocate, preemption: 0/6 nodes are available: 1 No preemption victims found for incoming pod, 5 Preemption is not helpful for scheduling."
0.0662,Event,ADDED,eval-sanitize-1-r0-051-6r7z5.18d4a1f4f0628df0,"reason=FailedScheduling count=None msg=0/6 nodes are available: 1 c_wall violated: 1 conflicting context pair(s) with node memory, 5 node(s) had untolerated taint(s). no new claims to deallocate, preemption: 0/6 nodes are available: 1 No preemption victims found for incoming pod, 5 Preemption is not helpful for scheduling."
0.0664,Event,ADDED,eval-sanitize-1-r0-052-br5gp.18d4a1f0f2b57232,"reason=FailedScheduling count=None msg=0/6 nodes are available: 1 c_wall violated: 1 conflicting context pair(s) with node memory, 5 node(s) had untolerated taint(s). no new claims to deallocate, preemption: 0/6 nodes are available: 1 No preemption victims found for incoming pod, 5 Preemption is not helpful for scheduling."
0.0666,Event,ADDED,eval-sanitize-1-r0-053-lqtg7.18d4a1f0ff30859b,"reason=FailedScheduling count=None msg=0/6 nodes are available: 1 c_wall violated: 1 conflicting context pair(s) with node memory, 5 node(s) had untolerated taint(s). no new claims to deallocate, preemption: 0/6 nodes are available: 1 No preemption victims found for incoming pod, 5 Preemption is not helpful for scheduling."
0.0669,Event,ADDED,eval-sanitize-1-r0-054-7pxw8.18d4a1f11c3c516f,"reason=FailedScheduling count=None msg=0/6 nodes are available: 1 c_wall violated: 1 conflicting context pair(s) with node memory, 5 node(s) had untolerated taint(s). no new claims to deallocate, preemption: 0/6 nodes are available: 1 No preemption victims found for incoming pod, 5 Preemption is not helpful for scheduling."
0.0671,Event,ADDED,eval-sanitize-1-r0-054-7pxw8.18d4a1f4f03a908d,"reason=FailedScheduling count=None msg=0/6 nodes are available: 1 c_wall violated: 1 conflicting context pair(s) with node memory, 5 node(s) had untolerated taint(s). no new claims to deallocate, preemption: 0/6 nodes are available: 1 No preemption victims found for incoming pod, 5 Preemption is not helpful for scheduling."
0.0673,Event,ADDED,eval-sanitize-1-r0-056-mjw5f.18d4a1f4f097322b,"reason=FailedScheduling count=None msg=0/6 nodes are available: 1 c_wall violated: 2 conflicting context pair(s) with node memory, 5 node(s) had untolerated taint(s). no new claims to deallocate, preemption: 0/6 nodes are available: 1 No preemption victims found for incoming pod, 5 Preemption is not helpful for scheduling."
0.0676,Event,ADDED,eval-sanitize-1-r0-056-mjw5f.18d4a1f55483256b,"reason=FailedScheduling count=None msg=0/6 nodes are available: 1 c_wall violated: 1 conflicting context pair(s) with node memory, 5 node(s) had untolerated taint(s). no new claims to deallocate, preemption: 0/6 nodes are available: 1 No preemption victims found for incoming pod, 5 Preemption is not helpful for scheduling."
0.0678,Event,ADDED,eval-sanitize-1-r0-056-mjw5f.18d4a1f5af3277c2,"reason=FailedScheduling count=None msg=0/6 nodes are available: 1 c_wall violated: 2 conflicting context pair(s) with node memory, 5 node(s) had untolerated taint(s). no new claims to deallocate, preemption: 0/6 nodes are available: 1 No preemption victims found for incoming pod, 5 Preemption is not helpful for scheduling."
0.0679,Event,ADDED,eval-sanitize-1-r0-056-mjw5f.18d4a1f5ccc59036,"reason=FailedScheduling count=None msg=0/6 nodes are available: 1 c_wall violated: 1 conflicting context pair(s) with node memory, 1 c_wall violated: 2 conflicting context pair(s) with node memory, 4 node(s) had untolerated taint(s). no new claims to deallocate, preemption: 0/6 nodes are available: 2 No preemption victims found for incoming pod, 4 Preemption is not helpful for scheduling."
0.0681,Event,ADDED,eval-sanitize-1-r0-056-mjw5f.18d4a1f5f10f8c99,"reason=FailedScheduling count=None msg=0/6 nodes are available: 1 c_wall violated: 1 conflicting context pair(s) with node memory, 5 node(s) had untolerated taint(s). no new claims to deallocate, preemption: 0/6 nodes are available: 1 No preemption victims found for incoming pod, 5 Preemption is not helpful for scheduling."
0.0683,Event,ADDED,eval-sanitize-1-r0-057-b57zn.18d4a1f4f3aec8dc,"reason=FailedScheduling count=None msg=0/6 nodes are available: 1 c_wall violated: 2 conflicting context pair(s) with node memory, 5 node(s) had untolerated taint(s). no new claims to deallocate, preemption: 0/6 nodes are available: 1 No preemption victims found for incoming pod, 5 Preemption is not helpful for scheduling."
0.0685,Event,ADDED,eval-sanitize-1-r0-057-b57zn.18d4a1f55ba27d5d,"reason=FailedScheduling count=None msg=0/6 nodes are available: 1 c_wall violated: 2 conflicting context pair(s) with node memory, 5 node(s) had untolerated taint(s). no new claims to deallocate, preemption: 0/6 nodes are available: 1 No preemption victims found for incoming pod, 5 Preemption is not helpful for scheduling."
0.0688,Event,ADDED,eval-sanitize-1-r0-059-fn7qr.18d4a1f4f5173214,"reason=FailedScheduling count=None msg=0/6 nodes are available: 1 c_wall violated: 1 conflicting context pair(s) with node memory, 5 node(s) had untolerated taint(s). no new claims to deallocate, preemption: 0/6 nodes are available: 1 No preemption victims found for incoming pod, 5 Preemption is not helpful for scheduling."
0.0689,Event,ADDED,eval-sanitize-1-r0-060-wjq6s.18d4a1f4f5667260,"reason=FailedScheduling count=None msg=0/6 nodes are available: 1 c_wall violated: 2 conflicting context pair(s) with node memory, 5 node(s) had untolerated taint(s). no new claims to deallocate, preemption: 0/6 nodes are available: 1 No preemption victims found for incoming pod, 5 Preemption is not helpful for scheduling."
0.0693,Event,ADDED,eval-sanitize-1-r0-060-wjq6s.18d4a1f5560214d4,"reason=FailedScheduling count=None msg=0/6 nodes are available: 1 c_wall violated: 1 conflicting context pair(s) with node memory, 5 node(s) had untolerated taint(s). no new claims to deallocate, preemption: 0/6 nodes are available: 1 No preemption victims found for incoming pod, 5 Preemption is not helpful for scheduling."
0.0695,Event,ADDED,eval-sanitize-1-r0-060-wjq6s.18d4a1f5aa2e8ed0,"reason=FailedScheduling count=None msg=0/6 nodes are available: 1 c_wall violated: 2 conflicting context pair(s) with node memory, 5 node(s) had untolerated taint(s). no new claims to deallocate, preemption: 0/6 nodes are available: 1 No preemption victims found for incoming pod, 5 Preemption is not helpful for scheduling."
0.0697,Event,ADDED,eval-sanitize-1-r0-060-wjq6s.18d4a1f5cd22bba5,"reason=FailedScheduling count=None msg=0/6 nodes are available: 1 c_wall violated: 1 conflicting context pair(s) with node memory, 1 c_wall violated: 2 conflicting context pair(s) with node memory, 4 node(s) had untolerated taint(s). no new claims to deallocate, preemption: 0/6 nodes are available: 2 No preemption victims found for incoming pod, 4 Preemption is not helpful for scheduling."
0.0699,Event,ADDED,eval-sanitize-1-r0-060-wjq6s.18d4a1f5f1501808,"reason=FailedScheduling count=None msg=0/6 nodes are available: 1 c_wall violated: 1 conflicting context pair(s) with node memory, 5 node(s) had untolerated taint(s). no new claims to deallocate, preemption: 0/6 nodes are available: 1 No preemption victims found for incoming pod, 5 Preemption is not helpful for scheduling."
0.0701,Event,ADDED,eval-sanitize-1-r0-061-jvv6k.18d4a1f4f6559069,"reason=FailedScheduling count=None msg=0/6 nodes are available: 1 c_wall violated: 2 conflicting context pair(s) with node memory, 5 node(s) had untolerated taint(s). no new claims to deallocate, preemption: 0/6 nodes are available: 1 No preemption victims found for incoming pod, 5 Preemption is not helpful for scheduling."
0.0703,Event,ADDED,eval-sanitize-1-r0-062-rbcw4.18d4a1f4f693ee29,"reason=FailedScheduling count=None msg=0/6 nodes are available: 1 c_wall violated: 3 conflicting context pair(s) with node memory, 5 node(s) had untolerated taint(s). no new claims to deallocate, preemption: 0/6 nodes are available: 1 No preemption victims found for incoming pod, 5 Preemption is not helpful for scheduling."
0.0707,Event,ADDED,eval-sanitize-1-r0-062-rbcw4.18d4a1f5563e6096,"reason=FailedScheduling count=None msg=0/6 nodes are available: 1 c_wall violated: 1 conflicting context pair(s) with node memory, 5 node(s) had untolerated taint(s). no new claims to deallocate, preemption: 0/6 nodes are available: 1 No preemption victims found for incoming pod, 5 Preemption is not helpful for scheduling."
0.0709,Event,ADDED,eval-sanitize-1-r0-063-ttkvl.18d4a1f4f6fc9ef9,"reason=FailedScheduling count=None msg=0/6 nodes are available: 1 c_wall violated: 1 conflicting context pair(s) with node memory, 5 node(s) had untolerated taint(s). no new claims to deallocate, preemption: 0/6 nodes are available: 1 No preemption victims found for incoming pod, 5 Preemption is not helpful for scheduling."
0.071,Event,ADDED,eval-sanitize-1-r0-066-fvhwf.18d4a1f4fb5663c1,"reason=FailedScheduling count=None msg=0/6 nodes are available: 1 c_wall violated: 2 conflicting context pair(s) with node memory, 5 node(s) had untolerated taint(s). no new claims to deallocate, preemption: 0/6 nodes are available: 1 No preemption victims found for incoming pod, 5 Preemption is not helpful for scheduling."
0.0714,Event,ADDED,eval-sanitize-1-r0-066-fvhwf.18d4a1f556b2f382,"reason=FailedScheduling count=None msg=0/6 nodes are available: 1 c_wall violated: 1 conflicting context pair(s) with node memory, 5 node(s) had untolerated taint(s). no new claims to deallocate, preemption: 0/6 nodes are available: 1 No preemption victims found for incoming pod, 5 Preemption is not helpful for scheduling."
0.0716,Event,ADDED,eval-sanitize-1-r0-066-fvhwf.18d4a1f5ae318c47,"reason=FailedScheduling count=None msg=0/6 nodes are available: 1 c_wall violated: 2 conflicting context pair(s) with node memory, 5 node(s) had untolerated taint(s). no new claims to deallocate, preemption: 0/6 nodes are available: 1 No preemption victims found for incoming pod, 5 Preemption is not helpful for scheduling."
0.0718,Event,ADDED,eval-sanitize-1-r0-066-fvhwf.18d4a1f5c7fb8803,"reason=FailedScheduling count=None msg=0/6 nodes are available: 1 c_wall violated: 1 conflicting context pair(s) with node memory, 1 c_wall violated: 2 conflicting context pair(s) with node memory, 4 node(s) had untolerated taint(s). no new claims to deallocate, preemption: 0/6 nodes are available: 2 No preemption victims found for incoming pod, 4 Preemption is not helpful for scheduling."
0.0721,Event,ADDED,eval-sanitize-1-r0-066-fvhwf.18d4a1f5f0d0e3ec,"reason=FailedScheduling count=None msg=0/6 nodes are available: 1 c_wall violated: 1 conflicting context pair(s) with node memory, 5 node(s) had untolerated taint(s). no new claims to deallocate, preemption: 0/6 nodes are available: 1 No preemption victims found for incoming pod, 5 Preemption is not helpful for scheduling."
0.0723,Event,ADDED,eval-sanitize-1-r0-067-d9jz6.18d4a1f4fc0ca83f,"reason=FailedScheduling count=None msg=0/6 nodes are available: 1 c_wall violated: 2 conflicting context pair(s) with node memory, 5 node(s) had untolerated taint(s). no new claims to deallocate, preemption: 0/6 nodes are available: 1 No preemption victims found for incoming pod, 5 Preemption is not helpful for scheduling."
0.0726,Event,ADDED,eval-sanitize-1-r0-068-skrlk.18d4a1f4fc63edad,"reason=FailedScheduling count=None msg=0/6 nodes are available: 1 c_wall violated: 1 conflicting context pair(s) with node memory, 5 node(s) had untolerated taint(s). no new claims to deallocate, preemption: 0/6 nodes are available: 1 No preemption victims found for incoming pod, 5 Preemption is not helpful for scheduling."
0.0728,Event,ADDED,eval-sanitize-1-r0-069-hr6mw.18d4a1f500f71c5d,"reason=FailedScheduling count=None msg=0/6 nodes are available: 1 c_wall violated: 4 conflicting context pair(s) with node memory, 5 node(s) had untolerated taint(s). no new claims to deallocate, preemption: 0/6 nodes are available: 1 No preemption victims found for incoming pod, 5 Preemption is not helpful for scheduling."
0.073,Event,ADDED,eval-sanitize-1-r0-069-hr6mw.18d4a1f55450ca64,"reason=FailedScheduling count=None msg=0/6 nodes are available: 1 c_wall violated: 1 conflicting context pair(s) with node memory, 5 node(s) had untolerated taint(s). no new claims to deallocate, preemption: 0/6 nodes are available: 1 No preemption victims found for incoming pod, 5 Preemption is not helpful for scheduling."
0.0732,Event,ADDED,eval-sanitize-1-r0-069-hr6mw.18d4a1f5a9703194,"reason=FailedScheduling count=None msg=0/6 nodes are available: 1 c_wall violated: 1 conflicting context pair(s) with node memory, 5 node(s) had untolerated taint(s). no new claims to deallocate, preemption: 0/6 nodes are available: 1 No preemption victims found for incoming pod, 5 Preemption is not helpful for scheduling."
0.0734,Event,ADDED,eval-sanitize-1-r0-072-wtpgw.18d4a1f5568001a1,"reason=FailedScheduling count=None msg=0/6 nodes are available: 1 c_wall violated: 1 conflicting context pair(s) with node memory, 5 node(s) had untolerated taint(s). no new claims to deallocate, preemption: 0/6 nodes are available: 1 No preemption victims found for incoming pod, 5 Preemption is not helpful for scheduling."
0.0736,Event,ADDED,eval-sanitize-1-r0-072-wtpgw.18d4a1f5a868b4c4,"reason=FailedScheduling count=None msg=0/6 nodes are available: 1 c_wall violated: 1 conflicting context pair(s) with node memory, 5 node(s) had untolerated taint(s). no new claims to deallocate, preemption: 0/6 nodes are available: 1 No preemption victims found for incoming pod, 5 Preemption is not helpful for scheduling."
0.0739,Event,ADDED,eval-sanitize-1-r0-072-wtpgw.18d4a1f5c79d7c98,"reason=FailedScheduling count=None msg=0/6 nodes are available: 2 c_wall violated: 1 conflicting context pair(s) with node memory, 4 node(s) had untolerated taint(s). no new claims to deallocate, preemption: 0/6 nodes are available: 2 No preemption victims found for incoming pod, 4 Preemption is not helpful for scheduling."
0.0741,Event,ADDED,eval-sanitize-1-r0-072-wtpgw.18d4a1f5f1835c2c,"reason=FailedScheduling count=None msg=0/6 nodes are available: 1 c_wall violated: 1 conflicting context pair(s) with node memory, 5 node(s) had untolerated taint(s). no new claims to deallocate, preemption: 0/6 nodes are available: 1 No preemption victims found for incoming pod, 5 Preemption is not helpful for scheduling."
0.0743,Event,ADDED,eval-sanitize-1-r0-072-wtpgw.18d4a1f67818cb68,"reason=FailedScheduling count=None msg=0/6 nodes are available: 1 c_wall violated: 1 conflicting context pair(s) with node memory, 5 node(s) had untolerated taint(s). no new claims to deallocate, preemption: 0/6 nodes are available: 1 No preemption victims found for incoming pod, 5 Preemption is not helpful for scheduling."
0.0745,Event,ADDED,eval-sanitize-1-r0-074-vnnb9.18d4a1f5f55595b8,"reason=FailedScheduling count=None msg=0/6 nodes are available: 1 c_wall violated: 1 conflicting context pair(s) with node memory, 5 node(s) had untolerated taint(s). no new claims to deallocate, preemption: 0/6 nodes are available: 1 No preemption victims found for incoming pod, 5 Preemption is not helpful for scheduling."
0.0747,Event,ADDED,eval-sanitize-1-r0-075-xgcrg.18d4a1f6784e2228,"reason=FailedScheduling count=None msg=0/6 nodes are available: 1 c_wall violated: 1 conflicting context pair(s) with node memory, 5 node(s) had untolerated taint(s). no new claims to deallocate, preemption: 0/6 nodes are available: 1 No preemption victims found for incoming pod, 5 Preemption is not helpful for scheduling."
0.0749,Event,ADDED,eval-sanitize-1-r0-076-dxgnq.18d4a1f6788733f1,"reason=FailedScheduling count=None msg=0/6 nodes are available: 1 c_wall violated: 2 conflicting context pair(s) with node memory, 5 node(s) had untolerated taint(s). no new claims to deallocate, preemption: 0/6 nodes are available: 1 No preemption victims found for incoming pod, 5 Preemption is not helpful for scheduling."
0.0751,Event,ADDED,eval-sanitize-1-r0-076-dxgnq.18d4a1fa9a1b9924,"reason=FailedScheduling count=None msg=0/6 nodes are available: 1 c_wall violated: 4 conflicting context pair(s) with node memory, 5 node(s) had untolerated taint(s). no new claims to deallocate, preemption: 0/6 nodes are available: 1 No preemption victims found for incoming pod, 5 Preemption is not helpful for scheduling."
0.0753,Event,ADDED,eval-sanitize-1-r0-076-dxgnq.18d4a1faf20055d9,"reason=FailedScheduling count=None msg=0/6 nodes are available: 1 c_wall violated: 1 conflicting context pair(s) with node memory, 5 node(s) had untolerated taint(s). no new claims to deallocate, preemption: 0/6 nodes are available: 1 No preemption victims found for incoming pod, 5 Preemption is not helpful for scheduling."
0.0756,Event,ADDED,eval-sanitize-1-r0-077-8xn87.18d4a1f6845010c1,"reason=FailedScheduling count=None msg=0/6 nodes are available: 1 c_wall violated: 1 conflicting context pair(s) with node memory, 5 node(s) had untolerated taint(s). no new claims to deallocate, preemption: 0/6 nodes are available: 1 No preemption victims found for incoming pod, 5 Preemption is not helpful for scheduling."
0.0757,Event,ADDED,eval-sanitize-1-r0-078-775c5.18d4a1f6b02ae2c4,"reason=FailedScheduling count=None msg=0/6 nodes are available: 1 c_wall violated: 2 conflicting context pair(s) with node memory, 5 node(s) had untolerated taint(s). no new claims to deallocate, preemption: 0/6 nodes are available: 1 No preemption victims found for incoming pod, 5 Preemption is not helpful for scheduling."
0.0759,Event,ADDED,eval-sanitize-1-r0-078-775c5.18d4a1fa9e889a78,"reason=FailedScheduling count=None msg=0/6 nodes are available: 1 c_wall violated: 4 conflicting context pair(s) with node memory, 5 node(s) had untolerated taint(s). no new claims to deallocate, preemption: 0/6 nodes are available: 1 No preemption victims found for incoming pod, 5 Preemption is not helpful for scheduling."
0.0763,Event,ADDED,eval-sanitize-1-r0-078-775c5.18d4a1faf59d2ab8,"reason=FailedScheduling count=None msg=0/6 nodes are available: 1 c_wall violated: 1 conflicting context pair(s) with node memory, 5 node(s) had untolerated taint(s). no new claims to deallocate, preemption: 0/6 nodes are available: 1 No preemption victims found for incoming pod, 5 Preemption is not helpful for scheduling."
0.0765,Event,ADDED,eval-sanitize-1-r0-080-rk94z.18d4a1fa9540baca,"reason=FailedScheduling count=None msg=0/6 nodes are available: 1 c_wall violated: 1 conflicting context pair(s) with node memory, 5 node(s) had untolerated taint(s). no new claims to deallocate, preemption: 0/6 nodes are available: 1 No preemption victims found for incoming pod, 5 Preemption is not helpful for scheduling."
0.0767,Event,ADDED,eval-sanitize-1-r0-082-ckmtn.18d4a1fa95901b4a,"reason=FailedScheduling count=None msg=0/6 nodes are available: 1 c_wall violated: 2 conflicting context pair(s) with node memory, 5 node(s) had untolerated taint(s). no new claims to deallocate, preemption: 0/6 nodes are available: 1 No preemption victims found for incoming pod, 5 Preemption is not helpful for scheduling."
0.077,Event,ADDED,eval-sanitize-1-r0-082-ckmtn.18d4a1faf5ca4dc9,"reason=FailedScheduling count=None msg=0/6 nodes are available: 1 c_wall violated: 1 conflicting context pair(s) with node memory, 5 node(s) had untolerated taint(s). no new claims to deallocate, preemption: 0/6 nodes are available: 1 No preemption victims found for incoming pod, 5 Preemption is not helpful for scheduling."
0.0772,Event,ADDED,eval-sanitize-1-r0-085-pk5pl.18d4a1fa95ec74a6,"reason=FailedScheduling count=None msg=0/6 nodes are available: 1 c_wall violated: 1 conflicting context pair(s) with node memory, 5 node(s) had untolerated taint(s). no new claims to deallocate, preemption: 0/6 nodes are available: 1 No preemption victims found for incoming pod, 5 Preemption is not helpful for scheduling."
0.0774,Event,ADDED,eval-sanitize-1-r0-087-nx8ps.18d4a1fa96444101,"reason=FailedScheduling count=None msg=0/6 nodes are available: 1 c_wall violated: 2 conflicting context pair(s) with node memory, 5 node(s) had untolerated taint(s). no new claims to deallocate, preemption: 0/6 nodes are available: 1 No preemption victims found for incoming pod, 5 Preemption is not helpful for scheduling."
0.0777,Event,ADDED,eval-sanitize-1-r0-087-nx8ps.18d4a1faf1641908,"reason=FailedScheduling count=None msg=0/6 nodes are available: 1 c_wall violated: 1 conflicting context pair(s) with node memory, 5 node(s) had untolerated taint(s). no new claims to deallocate, preemption: 0/6 nodes are available: 1 No preemption victims found for incoming pod, 5 Preemption is not helpful for scheduling."
0.0779,Event,ADDED,eval-sanitize-1-r0-088-mk4c8.18d4a1fa988fbaad,"reason=FailedScheduling count=None msg=0/6 nodes are available: 1 c_wall violated: 1 conflicting context pair(s) with node memory, 5 node(s) had untolerated taint(s). no new claims to deallocate, preemption: 0/6 nodes are available: 1 No preemption victims found for incoming pod, 5 Preemption is not helpful for scheduling."
0.0781,Event,ADDED,eval-sanitize-1-r0-089-wsn8f.18d4a1fa98d35675,"reason=FailedScheduling count=None msg=0/6 nodes are available: 1 c_wall violated: 1 conflicting context pair(s) with node memory, 5 node(s) had untolerated taint(s). no new claims to deallocate, preemption: 0/6 nodes are available: 1 No preemption victims found for incoming pod, 5 Preemption is not helpful for scheduling."
0.0785,Event,ADDED,eval-sanitize-1-r0-091-b8v5n.18d4a1fa9912c9dd,"reason=FailedScheduling count=None msg=0/6 nodes are available: 1 c_wall violated: 1 conflicting context pair(s) with node memory, 5 node(s) had untolerated taint(s). no new claims to deallocate, preemption: 0/6 nodes are available: 1 No preemption victims found for incoming pod, 5 Preemption is not helpful for scheduling."
0.0787,Event,ADDED,eval-sanitize-1-r0-092-fqjfm.18d4a1fa9952c533,"reason=FailedScheduling count=None msg=0/6 nodes are available: 1 c_wall violated: 2 conflicting context pair(s) with node memory, 5 node(s) had untolerated taint(s). no new claims to deallocate, preemption: 0/6 nodes are available: 1 No preemption victims found for incoming pod, 5 Preemption is not helpful for scheduling."
0.0789,Event,ADDED,eval-sanitize-1-r0-092-fqjfm.18d4a1faf1a0b93a,"reason=FailedScheduling count=None msg=0/6 nodes are available: 1 c_wall violated: 1 conflicting context pair(s) with node memory, 5 node(s) had untolerated taint(s). no new claims to deallocate, preemption: 0/6 nodes are available: 1 No preemption victims found for incoming pod, 5 Preemption is not helpful for scheduling."
0.0791,TaskRequest,ADDED,eval-sanitize-5-r0-000,phase=None job=None
0.0794,Event,ADDED,eval-sanitize-1-r0-094-xfvvp.18d4a1fa9993a374,"reason=FailedScheduling count=None msg=0/6 nodes are available: 1 c_wall violated: 1 conflicting context pair(s) with node memory, 5 node(s) had untolerated taint(s). no new claims to deallocate, preemption: 0/6 nodes are available: 1 No preemption victims found for incoming pod, 5 Preemption is not helpful for scheduling."
0.0796,Event,ADDED,eval-sanitize-1-r0-095-765mj.18d4a1faf1cb24e3,"reason=FailedScheduling count=None msg=0/6 nodes are available: 1 c_wall violated: 1 conflicting context pair(s) with node memory, 5 node(s) had untolerated taint(s). no new claims to deallocate, preemption: 0/6 nodes are available: 1 No preemption victims found for incoming pod, 5 Preemption is not helpful for scheduling."
0.0802,Event,ADDED,eval-sanitize-1-r0-095-765mj.18d4a1fb14a97169,"reason=FailedScheduling count=None msg=0/6 nodes are available: 2 c_wall violated: 1 conflicting context pair(s) with node memory, 4 node(s) had untolerated taint(s). no new claims to deallocate, preemption: 0/6 nodes are available: 2 No preemption victims found for incoming pod, 4 Preemption is not helpful for scheduling."
0.0804,Event,ADDED,eval-sanitize-1-r0-099-8hrsf.18d4a1fbf85a985e,"reason=FailedScheduling count=None msg=0/6 nodes are available: 1 c_wall violated: 1 conflicting context pair(s) with node memory, 5 node(s) had untolerated taint(s). no new claims to deallocate, preemption: 0/6 nodes are available: 1 No preemption victims found for incoming pod, 5 Preemption is not helpful for scheduling."
0.0808,Event,ADDED,eval-sanitize-1-r0-100-6m4d9.18d4a1fc1adf97ef,"reason=FailedScheduling count=None msg=0/6 nodes are available: 1 c_wall violated: 1 conflicting context pair(s) with node memory, 5 node(s) had untolerated taint(s). no new claims to deallocate, preemption: 0/6 nodes are available: 1 No preemption victims found for incoming pod, 5 Preemption is not helpful for scheduling."
0.0811,Event,ADDED,eval-sanitize-1-r0-106-fk2pc.18d4a2009a5db657,"reason=FailedScheduling count=None msg=0/6 nodes are available: 1 c_wall violated: 1 conflicting context pair(s) with node memory, 1 c_wall violated: 2 conflicting context pair(s) with node memory, 4 node(s) had untolerated taint(s). no new claims to deallocate, preemption: 0/6 nodes are available: 2 No preemption victims found for incoming pod, 4 Preemption is not helpful for scheduling."
0.0813,Event,ADDED,eval-sanitize-1-r0-106-fk2pc.18d4a200d187cfb5,"reason=FailedScheduling count=None msg=0/6 nodes are available: 1 c_wall violated: 1 conflicting context pair(s) with node memory, 5 node(s) had untolerated taint(s). no new claims to deallocate, preemption: 0/6 nodes are available: 1 No preemption victims found for incoming pod, 5 Preemption is not helpful for scheduling."
0.0815,Event,ADDED,eval-sanitize-1-r0-109-8qs95.18d4a2008d4227c8,"reason=FailedScheduling count=None msg=0/6 nodes are available: 1 c_wall violated: 1 conflicting context pair(s) with node memory, 1 c_wall violated: 3 conflicting context pair(s) with node memory, 4 node(s) had untolerated taint(s). no new claims to deallocate, preemption: 0/6 nodes are available: 2 No preemption victims found for incoming pod, 4 Preemption is not helpful for scheduling."
0.0818,Event,ADDED,eval-sanitize-1-r0-117-jl6lr.18d4a20099792e67,"reason=FailedScheduling count=None msg=0/6 nodes are available: 1 c_wall violated: 1 conflicting context pair(s) with node memory, 1 c_wall violated: 2 conflicting context pair(s) with node memory, 4 node(s) had untolerated taint(s). no new claims to deallocate, preemption: 0/6 nodes are available: 2 No preemption victims found for incoming pod, 4 Preemption is not helpful for scheduling."
0.0819,Event,ADDED,eval-sanitize-1-r0-117-jl6lr.18d4a200d156ac3a,"reason=FailedScheduling count=None msg=0/6 nodes are available: 1 c_wall violated: 1 conflicting context pair(s) with node memory, 5 node(s) had untolerated taint(s). no new claims to deallocate, preemption: 0/6 nodes are available: 1 No preemption victims found for incoming pod, 5 Preemption is not helpful for scheduling."
0.0821,Event,ADDED,eval-sanitize-1-r0-121-78tdc.18d4a2012433d5f5,"reason=FailedScheduling count=None msg=0/6 nodes are available: 1 c_wall violated: 1 conflicting context pair(s) with node memory, 5 node(s) had untolerated taint(s). no new claims to deallocate, preemption: 0/6 nodes are available: 1 No preemption victims found for incoming pod, 5 Preemption is not helpful for scheduling."
0.0824,Event,ADDED,eval-sanitize-1-r0-123-pfdnr.18d4a205d183161b,"reason=FailedScheduling count=None msg=0/6 nodes are available: 1 c_wall violated: 2 conflicting context pair(s) with node memory, 5 node(s) had untolerated taint(s). no new claims to deallocate, preemption: 0/6 nodes are available: 1 No preemption victims found for incoming pod, 5 Preemption is not helpful for scheduling."
0.0826,Event,ADDED,eval-sanitize-1-r0-123-pfdnr.18d4a2060d13d5ec,"reason=FailedScheduling count=None msg=0/6 nodes are available: 1 c_wall violated: 3 conflicting context pair(s) with node memory, 5 node(s) had untolerated taint(s). no new claims to deallocate, preemption: 0/6 nodes are available: 1 No preemption victims found for incoming pod, 5 Preemption is not helpful for scheduling."
0.083,Event,ADDED,eval-sanitize-1-r0-123-pfdnr.18d4a206680bda3c,"reason=FailedScheduling count=None msg=0/6 nodes are available: 1 c_wall violated: 1 conflicting context pair(s) with node memory, 5 node(s) had untolerated taint(s). no new claims to deallocate, preemption: 0/6 nodes are available: 1 No preemption victims found for incoming pod, 5 Preemption is not helpful for scheduling."
0.0832,Event,ADDED,eval-sanitize-1-r0-127-jslxp.18d4a205c56a8161,"reason=FailedScheduling count=None msg=0/6 nodes are available: 1 c_wall violated: 1 conflicting context pair(s) with node memory, 5 node(s) had untolerated taint(s). no new claims to deallocate, preemption: 0/6 nodes are available: 1 No preemption victims found for incoming pod, 5 Preemption is not helpful for scheduling."
0.0835,Event,ADDED,eval-sanitize-1-r0-127-jslxp.18d4a2060d489f30,"reason=FailedScheduling count=None msg=0/6 nodes are available: 1 c_wall violated: 2 conflicting context pair(s) with node memory, 5 node(s) had untolerated taint(s). no new claims to deallocate, preemption: 0/6 nodes are available: 1 No preemption victims found for incoming pod, 5 Preemption is not helpful for scheduling."
0.0839,Event,ADDED,eval-sanitize-1-r0-128-dqczf.18d4a205c8d4c990,"reason=FailedScheduling count=None msg=0/6 nodes are available: 1 c_wall violated: 1 conflicting context pair(s) with node memory, 5 node(s) had untolerated taint(s). no new claims to deallocate, preemption: 0/6 nodes are available: 1 No preemption victims found for incoming pod, 5 Preemption is not helpful for scheduling."
0.0841,Event,ADDED,eval-sanitize-1-r0-129-lhfnh.18d4a205c9176a3e,"reason=FailedScheduling count=None msg=0/6 nodes are available: 1 c_wall violated: 2 conflicting context pair(s) with node memory, 5 node(s) had untolerated taint(s). no new claims to deallocate, preemption: 0/6 nodes are available: 1 No preemption victims found for incoming pod, 5 Preemption is not helpful for scheduling."
0.0844,Event,ADDED,eval-sanitize-1-r0-129-lhfnh.18d4a20608873589,"reason=FailedScheduling count=None msg=0/6 nodes are available: 1 c_wall violated: 3 conflicting context pair(s) with node memory, 5 node(s) had untolerated taint(s). no new claims to deallocate, preemption: 0/6 nodes are available: 1 No preemption victims found for incoming pod, 5 Preemption is not helpful for scheduling."
0.0845,TaskRequest,MODIFIED,eval-sanitize-5-r0-000,phase=Pending job=None
0.0849,Event,ADDED,eval-sanitize-1-r0-129-lhfnh.18d4a20667143b95,"reason=FailedScheduling count=None msg=0/6 nodes are available: 1 c_wall violated: 1 conflicting context pair(s) with node memory, 5 node(s) had untolerated taint(s). no new claims to deallocate, preemption: 0/6 nodes are available: 1 No preemption victims found for incoming pod, 5 Preemption is not helpful for scheduling."
0.0851,Event,ADDED,eval-sanitize-1-r0-130-lz4lr.18d4a205c94847a9,"reason=FailedScheduling count=None msg=0/6 nodes are available: 1 c_wall violated: 2 conflicting context pair(s) with node memory, 5 node(s) had untolerated taint(s). no new claims to deallocate, preemption: 0/6 nodes are available: 1 No preemption victims found for incoming pod, 5 Preemption is not helpful for scheduling."
0.0853,Event,ADDED,eval-sanitize-1-r0-131-lqs5r.18d4a205ca553c63,"reason=FailedScheduling count=None msg=0/6 nodes are available: 1 c_wall violated: 1 conflicting context pair(s) with node memory, 5 node(s) had untolerated taint(s). no new claims to deallocate, preemption: 0/6 nodes are available: 1 No preemption victims found for incoming pod, 5 Preemption is not helpful for scheduling."
0.0856,Event,ADDED,eval-sanitize-1-r0-131-lqs5r.18d4a20608c3aed1,"reason=FailedScheduling count=None msg=0/6 nodes are available: 1 c_wall violated: 2 conflicting context pair(s) with node memory, 5 node(s) had untolerated taint(s). no new claims to deallocate, preemption: 0/6 nodes are available: 1 No preemption victims found for incoming pod, 5 Preemption is not helpful for scheduling."
0.0858,Event,ADDED,eval-sanitize-1-r0-132-zcswb.18d4a205cb4176a3,"reason=FailedScheduling count=None msg=0/6 nodes are available: 1 c_wall violated: 2 conflicting context pair(s) with node memory, 5 node(s) had untolerated taint(s). no new claims to deallocate, preemption: 0/6 nodes are available: 1 No preemption victims found for incoming pod, 5 Preemption is not helpful for scheduling."
0.086,Event,ADDED,eval-sanitize-1-r0-132-zcswb.18d4a20608efe4bb,"reason=FailedScheduling count=None msg=0/6 nodes are available: 1 c_wall violated: 1 conflicting context pair(s) with node memory, 5 node(s) had untolerated taint(s). no new claims to deallocate, preemption: 0/6 nodes are available: 1 No preemption victims found for incoming pod, 5 Preemption is not helpful for scheduling."
0.0863,Event,ADDED,eval-sanitize-1-r0-133-x6n68.18d4a205cb8e3051,"reason=FailedScheduling count=None msg=0/6 nodes are available: 1 c_wall violated: 2 conflicting context pair(s) with node memory, 5 node(s) had untolerated taint(s). no new claims to deallocate, preemption: 0/6 nodes are available: 1 No preemption victims found for incoming pod, 5 Preemption is not helpful for scheduling."
0.0865,Event,ADDED,eval-sanitize-1-r0-133-x6n68.18d4a2060a6b8a05,"reason=FailedScheduling count=None msg=0/6 nodes are available: 1 c_wall violated: 3 conflicting context pair(s) with node memory, 5 node(s) had untolerated taint(s). no new claims to deallocate, preemption: 0/6 nodes are available: 1 No preemption victims found for incoming pod, 5 Preemption is not helpful for scheduling."
0.0867,Event,ADDED,eval-sanitize-1-r0-133-x6n68.18d4a20667a0f509,"reason=FailedScheduling count=None msg=0/6 nodes are available: 1 c_wall violated: 1 conflicting context pair(s) with node memory, 5 node(s) had untolerated taint(s). no new claims to deallocate, preemption: 0/6 nodes are available: 1 No preemption victims found for incoming pod, 5 Preemption is not helpful for scheduling."
0.0868,Event,ADDED,eval-sanitize-1-r0-134-hx6pk.18d4a205cbc36027,"reason=FailedScheduling count=None msg=0/6 nodes are available: 1 c_wall violated: 1 conflicting context pair(s) with node memory, 5 node(s) had untolerated taint(s). no new claims to deallocate, preemption: 0/6 nodes are available: 1 No preemption victims found for incoming pod, 5 Preemption is not helpful for scheduling."
0.087,Event,ADDED,eval-sanitize-1-r0-134-hx6pk.18d4a2060bee6259,"reason=FailedScheduling count=None msg=0/6 nodes are available: 1 c_wall violated: 2 conflicting context pair(s) with node memory, 5 node(s) had untolerated taint(s). no new claims to deallocate, preemption: 0/6 nodes are available: 1 No preemption victims found for incoming pod, 5 Preemption is not helpful for scheduling."
0.0872,Event,ADDED,eval-sanitize-1-r0-135-tbqnb.18d4a205cbf73569,"reason=FailedScheduling count=None msg=0/6 nodes are available: 1 c_wall violated: 2 conflicting context pair(s) with node memory, 5 node(s) had untolerated taint(s). no new claims to deallocate, preemption: 0/6 nodes are available: 1 No preemption victims found for incoming pod, 5 Preemption is not helpful for scheduling."
0.0874,Event,ADDED,eval-sanitize-1-r0-137-8p6w5.18d4a205cc26de31,"reason=FailedScheduling count=None msg=0/6 nodes are available: 1 c_wall violated: 1 conflicting context pair(s) with node memory, 5 node(s) had untolerated taint(s). no new claims to deallocate, preemption: 0/6 nodes are available: 1 No preemption victims found for incoming pod, 5 Preemption is not helpful for scheduling."
0.0876,Event,ADDED,eval-sanitize-1-r0-137-8p6w5.18d4a2060cd582bf,"reason=FailedScheduling count=None msg=0/6 nodes are available: 1 c_wall violated: 2 conflicting context pair(s) with node memory, 5 node(s) had untolerated taint(s). no new claims to deallocate, preemption: 0/6 nodes are available: 1 No preemption victims found for incoming pod, 5 Preemption is not helpful for scheduling."
0.0878,Event,ADDED,eval-sanitize-1-r0-138-sjv85.18d4a205d02f2438,"reason=FailedScheduling count=None msg=0/6 nodes are available: 1 c_wall violated: 2 conflicting context pair(s) with node memory, 5 node(s) had untolerated taint(s). no new claims to deallocate, preemption: 0/6 nodes are available: 1 No preemption victims found for incoming pod, 5 Preemption is not helpful for scheduling."
0.088,Event,ADDED,eval-sanitize-1-r0-140-r68d4.18d4a205d14f12d4,"reason=FailedScheduling count=None msg=0/6 nodes are available: 1 c_wall violated: 2 conflicting context pair(s) with node memory, 5 node(s) had untolerated taint(s). no new claims to deallocate, preemption: 0/6 nodes are available: 1 No preemption victims found for incoming pod, 5 Preemption is not helpful for scheduling."
0.0881,Event,ADDED,eval-sanitize-1-r0-144-l4fbx.18d4a20667d724a3,"reason=FailedScheduling count=None msg=0/6 nodes are available: 1 c_wall violated: 1 conflicting context pair(s) with node memory, 5 node(s) had untolerated taint(s). no new claims to deallocate, preemption: 0/6 nodes are available: 1 No preemption victims found for incoming pod, 5 Preemption is not helpful for scheduling."
0.0883,Event,ADDED,eval-sanitize-1-r0-144-l4fbx.18d4a206e2573bb9,"reason=FailedScheduling count=None msg=0/6 nodes are available: 1 c_wall violated: 1 conflicting context pair(s) with node memory, 5 node(s) had untolerated taint(s). no new claims to deallocate, preemption: 0/6 nodes are available: 1 No preemption victims found for incoming pod, 5 Preemption is not helpful for scheduling."
0.0885,Event,ADDED,eval-sanitize-1-r0-144-l4fbx.18d4a20762d7eb46,"reason=FailedScheduling count=None msg=0/6 nodes are available: 1 c_wall violated: 2 conflicting context pair(s) with node memory, 5 node(s) had untolerated taint(s). no new claims to deallocate, preemption: 0/6 nodes are available: 1 No preemption victims found for incoming pod, 5 Preemption is not helpful for scheduling."
0.0887,Event,ADDED,eval-sanitize-1-r0-144-l4fbx.18d4a20b59a8f68c,"reason=FailedScheduling count=None msg=0/6 nodes are available: 1 c_wall violated: 1 conflicting context pair(s) with node memory, 5 node(s) had untolerated taint(s). no new claims to deallocate, preemption: 0/6 nodes are available: 1 No preemption victims found for incoming pod, 5 Preemption is not helpful for scheduling."
0.0889,Event,ADDED,eval-sanitize-1-r0-145-r6vdb.18d4a206e73099b1,"reason=FailedScheduling count=None msg=0/6 nodes are available: 1 c_wall violated: 1 conflicting context pair(s) with node memory, 5 node(s) had untolerated taint(s). no new claims to deallocate, preemption: 0/6 nodes are available: 1 No preemption victims found for incoming pod, 5 Preemption is not helpful for scheduling."
0.0891,Event,ADDED,eval-sanitize-1-r0-145-r6vdb.18d4a20763053bfb,"reason=FailedScheduling count=None msg=0/6 nodes are available: 1 c_wall violated: 1 conflicting context pair(s) with node memory, 5 node(s) had untolerated taint(s). no new claims to deallocate, preemption: 0/6 nodes are available: 1 No preemption victims found for incoming pod, 5 Preemption is not helpful for scheduling."
0.0892,Event,ADDED,eval-sanitize-1-r0-146-qzd9v.18d4a206fb0d0cf9,"reason=FailedScheduling count=None msg=0/6 nodes are available: 1 c_wall violated: 1 conflicting context pair(s) with node memory, 5 node(s) had untolerated taint(s). no new claims to deallocate, preemption: 0/6 nodes are available: 1 No preemption victims found for incoming pod, 5 Preemption is not helpful for scheduling."
0.0894,Event,ADDED,eval-sanitize-1-r0-147-p7c54.18d4a2072cedaae0,"reason=FailedScheduling count=None msg=0/6 nodes are available: 1 c_wall violated: 2 conflicting context pair(s) with node memory, 5 node(s) had untolerated taint(s). no new claims to deallocate, preemption: 0/6 nodes are available: 1 No preemption victims found for incoming pod, 5 Preemption is not helpful for scheduling."
0.0896,Event,ADDED,eval-sanitize-1-r0-149-8sckt.18d4a2076330ee67,"reason=FailedScheduling count=None msg=0/6 nodes are available: 1 c_wall violated: 2 conflicting context pair(s) with node memory, 5 node(s) had untolerated taint(s). no new claims to deallocate, preemption: 0/6 nodes are available: 1 No preemption victims found for incoming pod, 5 Preemption is not helpful for scheduling."
0.0898,Event,ADDED,eval-sanitize-1-r0-150-7rpq8.18d4a207844701bb,"reason=FailedScheduling count=None msg=0/6 nodes are available: 1 c_wall violated: 2 conflicting context pair(s) with node memory, 5 node(s) had untolerated taint(s). no new claims to deallocate, preemption: 0/6 nodes are available: 1 No preemption victims found for incoming pod, 5 Preemption is not helpful for scheduling."
0.0901,Event,ADDED,eval-sanitize-1-r0-155-dfm25.18d4a20bcd0cf81e,"reason=FailedScheduling count=None msg=0/6 nodes are available: 2 c_wall violated: 1 conflicting context pair(s) with node memory, 4 node(s) had untolerated taint(s). no new claims to deallocate, preemption: 0/6 nodes are available: 2 No preemption victims found for incoming pod, 4 Preemption is not helpful for scheduling."
0.0903,Event,ADDED,eval-sanitize-1-r0-155-dfm25.18d4a20be4fcade3,"reason=FailedScheduling count=None msg=0/6 nodes are available: 1 c_wall violated: 1 conflicting context pair(s) with node memory, 5 node(s) had untolerated taint(s). no new claims to deallocate, preemption: 0/6 nodes are available: 1 No preemption victims found for incoming pod, 5 Preemption is not helpful for scheduling."
0.0907,Event,ADDED,eval-sanitize-1-r0-157-hx2rb.18d4a20bcdc77847,"reason=FailedScheduling count=None msg=0/6 nodes are available: 2 c_wall violated: 1 conflicting context pair(s) with node memory, 4 node(s) had untolerated taint(s). no new claims to deallocate, preemption: 0/6 nodes are available: 2 No preemption victims found for incoming pod, 4 Preemption is not helpful for scheduling."
0.0909,Event,ADDED,eval-sanitize-1-r0-157-hx2rb.18d4a20be5387756,"reason=FailedScheduling count=None msg=0/6 nodes are available: 1 c_wall violated: 1 conflicting context pair(s) with node memory, 5 node(s) had untolerated taint(s). no new claims to deallocate, preemption: 0/6 nodes are available: 1 No preemption victims found for incoming pod, 5 Preemption is not helpful for scheduling."
0.0911,Event,ADDED,eval-sanitize-1-r0-162-jv62p.18d4a20bd33a4b12,"reason=FailedScheduling count=None msg=0/6 nodes are available: 2 c_wall violated: 1 conflicting context pair(s) with node memory, 4 node(s) had untolerated taint(s). no new claims to deallocate, preemption: 0/6 nodes are available: 2 No preemption victims found for incoming pod, 4 Preemption is not helpful for scheduling."
0.0914,Event,ADDED,eval-sanitize-1-r0-162-jv62p.18d4a20be56d2610,"reason=FailedScheduling count=None msg=0/6 nodes are available: 1 c_wall violated: 1 conflicting context pair(s) with node memory, 5 node(s) had untolerated taint(s). no new claims to deallocate, preemption: 0/6 nodes are available: 1 No preemption victims found for incoming pod, 5 Preemption is not helpful for scheduling."
0.0916,Event,ADDED,eval-sanitize-1-r0-162-jv62p.18d4a20c78675c00,"reason=FailedScheduling count=None msg=0/6 nodes are available: 1 c_wall violated: 3 conflicting context pair(s) with node memory, 5 node(s) had untolerated taint(s). no new claims to deallocate, preemption: 0/6 nodes are available: 1 No preemption victims found for incoming pod, 5 Preemption is not helpful for scheduling."
0.0918,Event,ADDED,eval-sanitize-1-r0-166-kqqrs.18d4a20bd3a1d550,"reason=FailedScheduling count=None msg=0/6 nodes are available: 1 c_wall violated: 1 conflicting context pair(s) with node memory, 1 c_wall violated: 2 conflicting context pair(s) with node memory, 4 node(s) had untolerated taint(s). no new claims to deallocate, preemption: 0/6 nodes are available: 2 No preemption victims found for incoming pod, 4 Preemption is not helpful for scheduling."
0.0921,Event,ADDED,eval-sanitize-1-r0-166-kqqrs.18d4a20be5a884b5,"reason=FailedScheduling count=None msg=0/6 nodes are available: 1 c_wall violated: 2 conflicting context pair(s) with node memory, 5 node(s) had untolerated taint(s). no new claims to deallocate, preemption: 0/6 nodes are available: 1 No preemption victims found for incoming pod, 5 Preemption is not helpful for scheduling."
0.0923,Event,ADDED,eval-sanitize-1-r0-172-rzqlr.18d4a20d0c3e6961,"reason=FailedScheduling count=None msg=0/6 nodes are available: 1 c_wall violated: 2 conflicting context pair(s) with node memory, 5 node(s) had untolerated taint(s). no new claims to deallocate, preemption: 0/6 nodes are available: 1 No preemption victims found for incoming pod, 5 Preemption is not helpful for scheduling."
0.0926,Event,ADDED,eval-sanitize-1-r0-178-ks6sw.18d4a21157f4f141,"reason=FailedScheduling count=None msg=0/6 nodes are available: 1 c_wall violated: 3 conflicting context pair(s) with node memory, 5 node(s) had untolerated taint(s). no new claims to deallocate, preemption: 0/6 nodes are available: 1 No preemption victims found for incoming pod, 5 Preemption is not helpful for scheduling."
0.093,Event,ADDED,eval-sanitize-1-r0-180-fphfd.18d4a21159388cc7,"reason=FailedScheduling count=None msg=0/6 nodes are available: 1 c_wall violated: 4 conflicting context pair(s) with node memory, 5 node(s) had untolerated taint(s). no new claims to deallocate, preemption: 0/6 nodes are available: 1 No preemption victims found for incoming pod, 5 Preemption is not helpful for scheduling."
0.0932,Event,ADDED,eval-sanitize-1-r0-180-fphfd.18d4a211aba261a7,"reason=FailedScheduling count=None msg=0/6 nodes are available: 2 c_wall violated: 1 conflicting context pair(s) with node memory, 4 node(s) had untolerated taint(s). no new claims to deallocate, preemption: 0/6 nodes are available: 2 No preemption victims found for incoming pod, 4 Preemption is not helpful for scheduling."
0.0935,Event,ADDED,eval-sanitize-1-r0-181-6nzxf.18d4a211596f405a,"reason=FailedScheduling count=None msg=0/6 nodes are available: 1 c_wall violated: 1 conflicting context pair(s) with node memory, 5 node(s) had untolerated taint(s). no new claims to deallocate, preemption: 0/6 nodes are available: 1 No preemption victims found for incoming pod, 5 Preemption is not helpful for scheduling."
0.0937,Event,ADDED,eval-sanitize-1-r0-182-8brr9.18d4a2115c7990ea,"reason=FailedScheduling count=None msg=0/6 nodes are available: 1 c_wall violated: 4 conflicting context pair(s) with node memory, 5 node(s) had untolerated taint(s). no new claims to deallocate, preemption: 0/6 nodes are available: 1 No preemption victims found for incoming pod, 5 Preemption is not helpful for scheduling."
0.0939,Event,ADDED,eval-sanitize-1-r0-182-8brr9.18d4a211b15516ce,"reason=FailedScheduling count=None msg=0/6 nodes are available: 2 c_wall violated: 1 conflicting context pair(s) with node memory, 4 node(s) had untolerated taint(s). no new claims to deallocate, preemption: 0/6 nodes are available: 2 No preemption victims found for incoming pod, 4 Preemption is not helpful for scheduling."
0.0941,Event,ADDED,eval-sanitize-1-r0-185-5hxgz.18d4a2116114faa2,"reason=FailedScheduling count=None msg=0/6 nodes are available: 1 c_wall violated: 2 conflicting context pair(s) with node memory, 5 node(s) had untolerated taint(s). no new claims to deallocate, preemption: 0/6 nodes are available: 1 No preemption victims found for incoming pod, 5 Preemption is not helpful for scheduling."
0.0943,Event,ADDED,eval-sanitize-1-r0-185-5hxgz.18d4a211b5d7975f,"reason=FailedScheduling count=None msg=0/6 nodes are available: 2 c_wall violated: 1 conflicting context pair(s) with node memory, 4 node(s) had untolerated taint(s). no new claims to deallocate, preemption: 0/6 nodes are available: 2 No preemption victims found for incoming pod, 4 Preemption is not helpful for scheduling."
0.0945,Event,ADDED,eval-sanitize-1-r0-187-kr8bp.18d4a211616e1708,"reason=FailedScheduling count=None msg=0/6 nodes are available: 1 c_wall violated: 1 conflicting context pair(s) with node memory, 5 node(s) had untolerated taint(s). no new claims to deallocate, preemption: 0/6 nodes are available: 1 No preemption victims found for incoming pod, 5 Preemption is not helpful for scheduling."
0.0947,Event,ADDED,eval-sanitize-1-r0-188-sdqtn.18d4a21161b29b10,"reason=FailedScheduling count=None msg=0/6 nodes are available: 1 c_wall violated: 3 conflicting context pair(s) with node memory, 5 node(s) had untolerated taint(s). no new claims to deallocate, preemption: 0/6 nodes are available: 1 No preemption victims found for incoming pod, 5 Preemption is not helpful for scheduling."
0.0949,Event,ADDED,eval-sanitize-1-r0-189-xp29g.18d4a21161f78b4e,"reason=FailedScheduling count=None msg=0/6 nodes are available: 1 c_wall violated: 4 conflicting context pair(s) with node memory, 5 node(s) had untolerated taint(s). no new claims to deallocate, preemption: 0/6 nodes are available: 1 No preemption victims found for incoming pod, 5 Preemption is not helpful for scheduling."
0.0952,Event,ADDED,eval-sanitize-1-r0-189-xp29g.18d4a211aa0db901,"reason=FailedScheduling count=None msg=0/6 nodes are available: 2 c_wall violated: 1 conflicting context pair(s) with node memory, 4 node(s) had untolerated taint(s). no new claims to deallocate, preemption: 0/6 nodes are available: 2 No preemption victims found for incoming pod, 4 Preemption is not helpful for scheduling."
0.0955,Event,ADDED,eval-sanitize-1-r0-190-wbcwf.18d4a2116386ac6e,"reason=FailedScheduling count=None msg=0/6 nodes are available: 1 c_wall violated: 4 conflicting context pair(s) with node memory, 5 node(s) had untolerated taint(s). no new claims to deallocate, preemption: 0/6 nodes are available: 1 No preemption victims found for incoming pod, 5 Preemption is not helpful for scheduling."
0.0957,Event,ADDED,eval-sanitize-1-r0-190-wbcwf.18d4a211ab48a42a,"reason=FailedScheduling count=None msg=0/6 nodes are available: 2 c_wall violated: 1 conflicting context pair(s) with node memory, 4 node(s) had untolerated taint(s). no new claims to deallocate, preemption: 0/6 nodes are available: 2 No preemption victims found for incoming pod, 4 Preemption is not helpful for scheduling."
0.0959,Event,ADDED,eval-sanitize-1-r0-193-ctk77.18d4a211b0f46cc0,"reason=FailedScheduling count=None msg=0/6 nodes are available: 2 c_wall violated: 1 conflicting context pair(s) with node memory, 4 node(s) had untolerated taint(s). no new claims to deallocate, preemption: 0/6 nodes are available: 2 No preemption victims found for incoming pod, 4 Preemption is not helpful for scheduling."
0.0961,Event,ADDED,eval-sanitize-1-r0-197-rnqdx.18d4a212bde378ff,"reason=FailedScheduling count=None msg=0/6 nodes are available: 1 c_wall violated: 2 conflicting context pair(s) with node memory, 5 node(s) had untolerated taint(s). no new claims to deallocate, preemption: 0/6 nodes are available: 1 No preemption victims found for incoming pod, 5 Preemption is not helpful for scheduling."
0.0962,Event,ADDED,eval-sanitize-1-r0-198-k96z2.18d4a212c710aa5c,"reason=FailedScheduling count=None msg=0/6 nodes are available: 1 c_wall violated: 1 conflicting context pair(s) with node memory, 5 node(s) had untolerated taint(s). no new claims to deallocate, preemption: 0/6 nodes are available: 1 No preemption victims found for incoming pod, 5 Preemption is not helpful for scheduling."
0.0964,Event,ADDED,eval-sanitize-1-r0-198-k96z2.18d4a217609c2b43,"reason=FailedScheduling count=None msg=0/6 nodes are available: 1 c_wall violated: 1 conflicting context pair(s) with node memory, 5 node(s) had untolerated taint(s). no new claims to deallocate, preemption: 0/6 nodes are available: 1 No preemption victims found for incoming pod, 5 Preemption is not helpful for scheduling."
0.0966,Event,ADDED,eval-sanitize-1-r0-199-tczbx.18d4a21760cc6d96,"reason=FailedScheduling count=None msg=0/6 nodes are available: 1 c_wall violated: 1 conflicting context pair(s) with node memory, 5 node(s) had untolerated taint(s). no new claims to deallocate, preemption: 0/6 nodes are available: 1 No preemption victims found for incoming pod, 5 Preemption is not helpful for scheduling."
0.0968,Event,ADDED,eval-sanitize-1-r1-008-54ljj.18d4a22cff5c738c,"reason=FailedScheduling count=None msg=0/6 nodes are available: 1 c_wall violated: 3 conflicting context pair(s) with node memory, 5 node(s) had untolerated taint(s). no new claims to deallocate, preemption: 0/6 nodes are available: 1 No preemption victims found for incoming pod, 5 Preemption is not helpful for scheduling."
0.097,Event,ADDED,eval-sanitize-1-r1-008-54ljj.18d4a22d7981125d,"reason=FailedScheduling count=None msg=0/6 nodes are available: 1 c_wall violated: 2 conflicting context pair(s) with node memory, 5 node(s) had untolerated taint(s). no new claims to deallocate, preemption: 0/6 nodes are available: 1 No preemption victims found for incoming pod, 5 Preemption is not helpful for scheduling."
0.0972,Event,ADDED,eval-sanitize-1-r1-008-54ljj.18d4a22db3273eda,"reason=FailedScheduling count=None msg=0/6 nodes are available: 1 c_wall violated: 1 conflicting context pair(s) with node memory, 5 node(s) had untolerated taint(s). no new claims to deallocate, preemption: 0/6 nodes are available: 1 No preemption victims found for incoming pod, 5 Preemption is not helpful for scheduling."
0.0974,Event,ADDED,eval-sanitize-1-r1-009-pcsqk.18d4a22d0632282d,"reason=FailedScheduling count=None msg=0/6 nodes are available: 1 c_wall violated: 2 conflicting context pair(s) with node memory, 5 node(s) had untolerated taint(s). no new claims to deallocate, preemption: 0/6 nodes are available: 1 No preemption victims found for incoming pod, 5 Preemption is not helpful for scheduling."
0.0976,Event,ADDED,eval-sanitize-1-r1-009-pcsqk.18d4a22d79aeec40,"reason=FailedScheduling count=None msg=0/6 nodes are available: 1 c_wall violated: 3 conflicting context pair(s) with node memory, 5 node(s) had untolerated taint(s). no new claims to deallocate, preemption: 0/6 nodes are available: 1 No preemption victims found for incoming pod, 5 Preemption is not helpful for scheduling."
0.0978,Event,ADDED,eval-sanitize-1-r1-010-fzljc.18d4a22d03d04d3b,"reason=FailedScheduling count=None msg=0/6 nodes are available: 1 c_wall violated: 3 conflicting context pair(s) with node memory, 5 node(s) had untolerated taint(s). no new claims to deallocate, preemption: 0/6 nodes are available: 1 No preemption victims found for incoming pod, 5 Preemption is not helpful for scheduling."
0.0979,Event,ADDED,eval-sanitize-1-r1-012-snd79.18d4a22d0b52f029,"reason=FailedScheduling count=None msg=0/6 nodes are available: 1 c_wall violated: 4 conflicting context pair(s) with node memory, 5 node(s) had untolerated taint(s). no new claims to deallocate, preemption: 0/6 nodes are available: 1 No preemption victims found for incoming pod, 5 Preemption is not helpful for scheduling."
0.0981,Event,ADDED,eval-sanitize-1-r1-012-snd79.18d4a22d79dce1b8,"reason=FailedScheduling count=None msg=0/6 nodes are available: 1 c_wall violated: 3 conflicting context pair(s) with node memory, 5 node(s) had untolerated taint(s). no new claims to deallocate, preemption: 0/6 nodes are available: 1 No preemption victims found for incoming pod, 5 Preemption is not helpful for scheduling."
0.0984,Event,ADDED,eval-sanitize-1-r1-013-fckpr.18d4a22d048590dd,"reason=FailedScheduling count=None msg=0/6 nodes are available: 1 c_wall violated: 1 conflicting context pair(s) with node memory, 5 node(s) had untolerated taint(s). no new claims to deallocate, preemption: 0/6 nodes are available: 1 No preemption victims found for incoming pod, 5 Preemption is not helpful for scheduling."
0.0986,Event,ADDED,eval-sanitize-1-r1-015-qvnqr.18d4a22d0b8b4a44,"reason=FailedScheduling count=None msg=0/6 nodes are available: 1 c_wall violated: 2 conflicting context pair(s) with node memory, 5 node(s) had untolerated taint(s). no new claims to deallocate, preemption: 0/6 nodes are available: 1 No preemption victims found for incoming pod, 5 Preemption is not helpful for scheduling."
0.0989,Event,ADDED,eval-sanitize-1-r1-015-qvnqr.18d4a22d7a0aaddb,"reason=FailedScheduling count=None msg=0/6 nodes are available: 1 c_wall violated: 3 conflicting context pair(s) with node memory, 5 node(s) had untolerated taint(s). no new claims to deallocate, preemption: 0/6 nodes are available: 1 No preemption victims found for incoming pod, 5 Preemption is not helpful for scheduling."
0.0991,Event,ADDED,eval-sanitize-1-r1-016-sj7m6.18d4a22d0538bee0,"reason=FailedScheduling count=None msg=0/6 nodes are available: 1 c_wall violated: 1 conflicting context pair(s) with node memory, 5 node(s) had untolerated taint(s). no new claims to deallocate, preemption: 0/6 nodes are available: 1 No preemption victims found for incoming pod, 5 Preemption is not helpful for scheduling."
0.0997,Event,ADDED,eval-sanitize-1-r1-020-ck47z.18d4a22d0565250b,"reason=FailedScheduling count=None msg=0/6 nodes are available: 1 c_wall violated: 3 conflicting context pair(s) with node memory, 5 node(s) had untolerated taint(s). no new claims to deallocate, preemption: 0/6 nodes are available: 1 No preemption victims found for incoming pod, 5 Preemption is not helpful for scheduling."
0.0999,Event,ADDED,eval-sanitize-1-r1-020-ck47z.18d4a22d791e5d49,"reason=FailedScheduling count=None msg=0/6 nodes are available: 1 c_wall violated: 2 conflicting context pair(s) with node memory, 5 node(s) had untolerated taint(s). no new claims to deallocate, preemption: 0/6 nodes are available: 1 No preemption victims found for incoming pod, 5 Preemption is not helpful for scheduling."
0.1001,Event,ADDED,eval-sanitize-1-r1-020-ck47z.18d4a22db387ed0b,"reason=FailedScheduling count=None msg=0/6 nodes are available: 1 c_wall violated: 1 conflicting context pair(s) with node memory, 5 node(s) had untolerated taint(s). no new claims to deallocate, preemption: 0/6 nodes are available: 1 No preemption victims found for incoming pod, 5 Preemption is not helpful for scheduling."
0.1003,Event,ADDED,eval-sanitize-1-r1-021-vdm6r.18d4a22d0599a538,"reason=FailedScheduling count=None msg=0/6 nodes are available: 1 c_wall violated: 3 conflicting context pair(s) with node memory, 5 node(s) had untolerated taint(s). no new claims to deallocate, preemption: 0/6 nodes are available: 1 No preemption victims found for incoming pod, 5 Preemption is not helpful for scheduling."
0.1005,Event,ADDED,eval-sanitize-1-r1-021-vdm6r.18d4a22d79549ce8,"reason=FailedScheduling count=None msg=0/6 nodes are available: 1 c_wall violated: 2 conflicting context pair(s) with node memory, 5 node(s) had untolerated taint(s). no new claims to deallocate, preemption: 0/6 nodes are available: 1 No preemption victims found for incoming pod, 5 Preemption is not helpful for scheduling."
0.1007,Event,ADDED,eval-sanitize-1-r1-021-vdm6r.18d4a22db13ff6b2,"reason=FailedScheduling count=None msg=0/6 nodes are available: 1 c_wall violated: 1 conflicting context pair(s) with node memory, 5 node(s) had untolerated taint(s). no new claims to deallocate, preemption: 0/6 nodes are available: 1 No preemption victims found for incoming pod, 5 Preemption is not helpful for scheduling."
0.1009,Event,ADDED,eval-sanitize-1-r1-025-5wqbg.18d4a22d9930b3f8,"reason=FailedScheduling count=None msg=0/6 nodes are available: 1 c_wall violated: 1 conflicting context pair(s) with node memory, 5 node(s) had untolerated taint(s). no new claims to deallocate, preemption: 0/6 nodes are available: 1 No preemption victims found for incoming pod, 5 Preemption is not helpful for scheduling."
0.1011,Event,ADDED,eval-sanitize-1-r1-031-sxkst.18d4a232914a8a2e,"reason=FailedScheduling count=None msg=0/6 nodes are available: 1 c_wall violated: 2 conflicting context pair(s) with node memory, 5 node(s) had untolerated taint(s). no new claims to deallocate, preemption: 0/6 nodes are available: 1 No preemption victims found for incoming pod, 5 Preemption is not helpful for scheduling."
0.1013,Event,ADDED,eval-sanitize-1-r1-032-5nhpx.18d4a23288e712d4,"reason=FailedScheduling count=None msg=0/6 nodes are available: 1 c_wall violated: 1 conflicting context pair(s) with node memory, 5 node(s) had untolerated taint(s). no new claims to deallocate, preemption: 0/6 nodes are available: 1 No preemption victims found for incoming pod, 5 Preemption is not helpful for scheduling."
0.1017,Event,ADDED,eval-sanitize-1-r1-033-mpbml.18d4a23295a06a1d,"reason=FailedScheduling count=None msg=0/6 nodes are available: 1 c_wall violated: 2 conflicting context pair(s) with node memory, 5 node(s) had untolerated taint(s). no new claims to deallocate, preemption: 0/6 nodes are available: 1 No preemption victims found for incoming pod, 5 Preemption is not helpful for scheduling."
0.102,Event,ADDED,eval-sanitize-1-r1-035-5xqph.18d4a23289d5af13,"reason=FailedScheduling count=None msg=0/6 nodes are available: 1 c_wall violated: 1 conflicting context pair(s) with node memory, 5 node(s) had untolerated taint(s). no new claims to deallocate, preemption: 0/6 nodes are available: 1 No preemption victims found for incoming pod, 5 Preemption is not helpful for scheduling."
0.1022,Event,ADDED,eval-sanitize-1-r1-036-ccvfg.18d4a2328c70bfd9,"reason=FailedScheduling count=None msg=0/6 nodes are available: 1 c_wall violated: 1 conflicting context pair(s) with node memory, 5 node(s) had untolerated taint(s). no new claims to deallocate, preemption: 0/6 nodes are available: 1 No preemption victims found for incoming pod, 5 Preemption is not helpful for scheduling."
0.1026,Event,ADDED,eval-sanitize-1-r1-037-4zq86.18d4a2328cac211d,"reason=FailedScheduling count=None msg=0/6 nodes are available: 1 c_wall violated: 2 conflicting context pair(s) with node memory, 5 node(s) had untolerated taint(s). no new claims to deallocate, preemption: 0/6 nodes are available: 1 No preemption victims found for incoming pod, 5 Preemption is not helpful for scheduling."
0.1028,Event,ADDED,eval-sanitize-1-r1-037-4zq86.18d4a232fb66b7a3,"reason=FailedScheduling count=None msg=0/6 nodes are available: 1 c_wall violated: 3 conflicting context pair(s) with node memory, 5 node(s) had untolerated taint(s). no new claims to deallocate, preemption: 0/6 nodes are available: 1 No preemption victims found for incoming pod, 5 Preemption is not helpful for scheduling."
0.103,Event,ADDED,eval-sanitize-1-r1-037-4zq86.18d4a233309543db,"reason=FailedScheduling count=None msg=0/6 nodes are available: 1 c_wall violated: 1 conflicting context pair(s) with node memory, 5 node(s) had untolerated taint(s). no new claims to deallocate, preemption: 0/6 nodes are available: 1 No preemption victims found for incoming pod, 5 Preemption is not helpful for scheduling."
0.1037,Job,ADDED,eval-sanitize-5-r0-000,
0.1041,Event,ADDED,eval-sanitize-1-r1-038-xhjh9.18d4a2328ceb140e,"reason=FailedScheduling count=None msg=0/6 nodes are available: 1 c_wall violated: 1 conflicting context pair(s) with node memory, 5 node(s) had untolerated taint(s). no new claims to deallocate, preemption: 0/6 nodes are available: 1 No preemption victims found for incoming pod, 5 Preemption is not helpful for scheduling."
0.1043,Event,ADDED,eval-sanitize-1-r1-038-xhjh9.18d4a232fb925183,"reason=FailedScheduling count=None msg=0/6 nodes are available: 1 c_wall violated: 3 conflicting context pair(s) with node memory, 5 node(s) had untolerated taint(s). no new claims to deallocate, preemption: 0/6 nodes are available: 1 No preemption victims found for incoming pod, 5 Preemption is not helpful for scheduling."
0.1048,Event,ADDED,eval-sanitize-1-r1-038-xhjh9.18d4a23331a2c4c8,"reason=FailedScheduling count=None msg=0/6 nodes are available: 1 c_wall violated: 1 conflicting context pair(s) with node memory, 5 node(s) had untolerated taint(s). no new claims to deallocate, preemption: 0/6 nodes are available: 1 No preemption victims found for incoming pod, 5 Preemption is not helpful for scheduling."
0.1051,Event,ADDED,eval-sanitize-1-r1-038-xhjh9.18d4a2336de91c60,"reason=FailedScheduling count=None msg=0/6 nodes are available: 2 c_wall violated: 1 conflicting context pair(s) with node memory, 4 node(s) had untolerated taint(s). no new claims to deallocate, preemption: 0/6 nodes are available: 2 No preemption victims found for incoming pod, 4 Preemption is not helpful for scheduling."
0.1056,Event,ADDED,eval-sanitize-1-r1-038-xhjh9.18d4a233756adb37,"reason=FailedScheduling count=None msg=0/6 nodes are available: 1 c_wall violated: 1 conflicting context pair(s) with node memory, 5 node(s) had untolerated taint(s). no new claims to deallocate, preemption: 0/6 nodes are available: 1 No preemption victims found for incoming pod, 5 Preemption is not helpful for scheduling."
0.1061,Event,ADDED,eval-sanitize-1-r1-039-v5lhr.18d4a2328d26df02,"reason=FailedScheduling count=None msg=0/6 nodes are available: 1 c_wall violated: 2 conflicting context pair(s) with node memory, 5 node(s) had untolerated taint(s). no new claims to deallocate, preemption: 0/6 nodes are available: 1 No preemption victims found for incoming pod, 5 Preemption is not helpful for scheduling."
0.1066,Event,ADDED,eval-sanitize-1-r1-039-v5lhr.18d4a232fc06dfd7,"reason=FailedScheduling count=None msg=0/6 nodes are available: 1 c_wall violated: 3 conflicting context pair(s) with node memory, 5 node(s) had untolerated taint(s). no new claims to deallocate, preemption: 0/6 nodes are available: 1 No preemption victims found for incoming pod, 5 Preemption is not helpful for scheduling."
0.1069,Event,ADDED,eval-sanitize-1-r1-039-v5lhr.18d4a23331d45da9,"reason=FailedScheduling count=None msg=0/6 nodes are available: 1 c_wall violated: 1 conflicting context pair(s) with node memory, 5 node(s) had untolerated taint(s). no new claims to deallocate, preemption: 0/6 nodes are available: 1 No preemption victims found for incoming pod, 5 Preemption is not helpful for scheduling."
0.1071,TaskRequest,MODIFIED,eval-sanitize-5-r0-000,phase=Scheduled job=None
0.1075,Event,ADDED,eval-sanitize-1-r1-040-xnms4.18d4a2328d61ae1b,"reason=FailedScheduling count=None msg=0/6 nodes are available: 1 c_wall violated: 1 conflicting context pair(s) with node memory, 5 node(s) had untolerated taint(s). no new claims to deallocate, preemption: 0/6 nodes are available: 1 No preemption victims found for incoming pod, 5 Preemption is not helpful for scheduling."
0.1077,Event,ADDED,eval-sanitize-1-r1-041-7b2x4.18d4a2328fc107ba,"reason=FailedScheduling count=None msg=0/6 nodes are available: 1 c_wall violated: 2 conflicting context pair(s) with node memory, 5 node(s) had untolerated taint(s). no new claims to deallocate, preemption: 0/6 nodes are available: 1 No preemption victims found for incoming pod, 5 Preemption is not helpful for scheduling."
0.1082,Event,ADDED,eval-sanitize-1-r1-042-q6xs7.18d4a23290b83daf,"reason=FailedScheduling count=None msg=0/6 nodes are available: 1 c_wall violated: 2 conflicting context pair(s) with node memory, 5 node(s) had untolerated taint(s). no new claims to deallocate, preemption: 0/6 nodes are available: 1 No preemption victims found for incoming pod, 5 Preemption is not helpful for scheduling."
0.109,Event,ADDED,eval-sanitize-1-r1-044-z5qvl.18d4a23290ec741c,"reason=FailedScheduling count=None msg=0/6 nodes are available: 1 c_wall violated: 2 conflicting context pair(s) with node memory, 5 node(s) had untolerated taint(s). no new claims to deallocate, preemption: 0/6 nodes are available: 1 No preemption victims found for incoming pod, 5 Preemption is not helpful for scheduling."
0.1095,Event,ADDED,eval-sanitize-1-r1-044-z5qvl.18d4a232fae6a711,"reason=FailedScheduling count=None msg=0/6 nodes are available: 1 c_wall violated: 3 conflicting context pair(s) with node memory, 5 node(s) had untolerated taint(s). no new claims to deallocate, preemption: 0/6 nodes are available: 1 No preemption victims found for incoming pod, 5 Preemption is not helpful for scheduling."
0.1099,Event,ADDED,eval-sanitize-1-r1-044-z5qvl.18d4a23332052492,"reason=FailedScheduling count=None msg=0/6 nodes are available: 1 c_wall violated: 1 conflicting context pair(s) with node memory, 5 node(s) had untolerated taint(s). no new claims to deallocate, preemption: 0/6 nodes are available: 1 No preemption victims found for incoming pod, 5 Preemption is not helpful for scheduling."
0.1107,Event,ADDED,eval-sanitize-1-r1-046-qcrmd.18d4a2329118cac5,"reason=FailedScheduling count=None msg=0/6 nodes are available: 1 c_wall violated: 1 conflicting context pair(s) with node memory, 5 node(s) had untolerated taint(s). no new claims to deallocate, preemption: 0/6 nodes are available: 1 No preemption victims found for incoming pod, 5 Preemption is not helpful for scheduling."
0.1112,Event,ADDED,eval-sanitize-1-r1-046-qcrmd.18d4a232fb122580,"reason=FailedScheduling count=None msg=0/6 nodes are available: 1 c_wall violated: 1 conflicting context pair(s) with node memory, 5 node(s) had untolerated taint(s). no new claims to deallocate, preemption: 0/6 nodes are available: 1 No preemption victims found for incoming pod, 5 Preemption is not helpful for scheduling."
0.1116,Event,ADDED,eval-sanitize-1-r1-047-dr2vt.18d4a232fb3d1a95,"reason=FailedScheduling count=None msg=0/6 nodes are available: 1 c_wall violated: 3 conflicting context pair(s) with node memory, 5 node(s) had untolerated taint(s). no new claims to deallocate, preemption: 0/6 nodes are available: 1 No preemption victims found for incoming pod, 5 Preemption is not helpful for scheduling."
0.112,Event,ADDED,eval-sanitize-1-r1-047-dr2vt.18d4a2332f76f6a9,"reason=FailedScheduling count=None msg=0/6 nodes are available: 1 c_wall violated: 1 conflicting context pair(s) with node memory, 5 node(s) had untolerated taint(s). no new claims to deallocate, preemption: 0/6 nodes are available: 1 No preemption victims found for incoming pod, 5 Preemption is not helpful for scheduling."
0.1124,Event,ADDED,eval-sanitize-1-r1-051-7vljw.18d4a234001fa5d9,"reason=FailedScheduling count=None msg=0/6 nodes are available: 1 c_wall violated: 1 conflicting context pair(s) with node memory, 5 node(s) had untolerated taint(s). no new claims to deallocate, preemption: 0/6 nodes are available: 1 No preemption victims found for incoming pod, 5 Preemption is not helpful for scheduling."
0.1137,Pod,ADDED,eval-sanitize-5-r0-000-qh6gr,phase=Pending node=None
0.1143,Event,ADDED,eval-sanitize-1-r1-052-hz5cp.18d4a2342287faaf,"reason=FailedScheduling count=None msg=0/6 nodes are available: 1 c_wall violated: 1 conflicting context pair(s) with node memory, 5 node(s) had untolerated taint(s). no new claims to deallocate, preemption: 0/6 nodes are available: 1 No preemption victims found for incoming pod, 5 Preemption is not helpful for scheduling."
0.1147,Event,ADDED,eval-sanitize-1-r1-053-nnjhr.18d4a238158e8a17,"reason=FailedScheduling count=None msg=0/6 nodes are available: 1 c_wall violated: 2 conflicting context pair(s) with node memory, 5 node(s) had untolerated taint(s). no new claims to deallocate, preemption: 0/6 nodes are available: 1 No preemption victims found for incoming pod, 5 Preemption is not helpful for scheduling."
0.1152,Event,ADDED,eval-sanitize-1-r1-054-c6l96.18d4a23806f0ea06,"reason=FailedScheduling count=None msg=0/6 nodes are available: 1 c_wall violated: 1 conflicting context pair(s) with node memory, 5 node(s) had untolerated taint(s). no new claims to deallocate, preemption: 0/6 nodes are available: 1 No preemption victims found for incoming pod, 5 Preemption is not helpful for scheduling."
0.1156,Event,ADDED,eval-sanitize-1-r1-057-k6kh2.18d4a23816f7f7ac,"reason=FailedScheduling count=None msg=0/6 nodes are available: 1 c_wall violated: 4 conflicting context pair(s) with node memory, 5 node(s) had untolerated taint(s). no new claims to deallocate, preemption: 0/6 nodes are available: 1 No preemption victims found for incoming pod, 5 Preemption is not helpful for scheduling."
0.1158,Event,ADDED,eval-sanitize-1-r1-057-k6kh2.18d4a23878ad5df5,"reason=FailedScheduling count=None msg=0/6 nodes are available: 1 c_wall violated: 1 conflicting context pair(s) with node memory, 5 node(s) had untolerated taint(s). no new claims to deallocate, preemption: 0/6 nodes are available: 1 No preemption victims found for incoming pod, 5 Preemption is not helpful for scheduling."
0.116,Event,ADDED,eval-sanitize-1-r1-057-k6kh2.18d4a238bb462a54,"reason=FailedScheduling count=None msg=0/6 nodes are available: 1 c_wall violated: 1 conflicting context pair(s) with node memory, 5 node(s) had untolerated taint(s). no new claims to deallocate, preemption: 0/6 nodes are available: 1 No preemption victims found for incoming pod, 5 Preemption is not helpful for scheduling."
0.1166,Event,ADDED,eval-sanitize-1-r1-057-k6kh2.18d4a238e03ecff2,"reason=FailedScheduling count=None msg=0/6 nodes are available: 2 c_wall violated: 1 conflicting context pair(s) with node memory, 4 node(s) had untolerated taint(s). no new claims to deallocate, preemption: 0/6 nodes are available: 2 No preemption victims found for incoming pod, 4 Preemption is not helpful for scheduling."
0.1169,Event,ADDED,eval-sanitize-1-r1-057-k6kh2.18d4a238eca2d474,"reason=FailedScheduling count=None msg=0/6 nodes are available: 1 c_wall violated: 1 conflicting context pair(s) with node memory, 5 node(s) had untolerated taint(s). no new claims to deallocate, preemption: 0/6 nodes are available: 1 No preemption victims found for incoming pod, 5 Preemption is not helpful for scheduling."
0.1172,Event,ADDED,eval-sanitize-1-r1-059-jg4qr.18d4a2381b39d7a7,"reason=FailedScheduling count=None msg=0/6 nodes are available: 1 c_wall violated: 3 conflicting context pair(s) with node memory, 5 node(s) had untolerated taint(s). no new claims to deallocate, preemption: 0/6 nodes are available: 1 No preemption victims found for incoming pod, 5 Preemption is not helpful for scheduling."
0.1179,Job,MODIFIED,eval-sanitize-5-r0-000,
0.1181,TaskRequest,MODIFIED,eval-sanitize-5-r0-000,phase=Scheduled job=None
0.1186,Event,ADDED,eval-sanitize-1-r1-059-jg4qr.18d4a23879965327,"reason=FailedScheduling count=None msg=0/6 nodes are available: 1 c_wall violated: 1 conflicting context pair(s) with node memory, 5 node(s) had untolerated taint(s). no new claims to deallocate, preemption: 0/6 nodes are available: 1 No preemption victims found for incoming pod, 5 Preemption is not helpful for scheduling."
0.1188,Event,ADDED,eval-sanitize-1-r1-060-f5kbh.18d4a2381b6c2d02,"reason=FailedScheduling count=None msg=0/6 nodes are available: 1 c_wall violated: 2 conflicting context pair(s) with node memory, 5 node(s) had untolerated taint(s). no new claims to deallocate, preemption: 0/6 nodes are available: 1 No preemption victims found for incoming pod, 5 Preemption is not helpful for scheduling."
0.1192,Event,ADDED,eval-sanitize-1-r1-060-f5kbh.18d4a23879c5cf4b,"reason=FailedScheduling count=None msg=0/6 nodes are available: 1 c_wall violated: 1 conflicting context pair(s) with node memory, 5 node(s) had untolerated taint(s). no new claims to deallocate, preemption: 0/6 nodes are available: 1 No preemption victims found for incoming pod, 5 Preemption is not helpful for scheduling."
0.1194,Event,ADDED,eval-sanitize-1-r1-060-f5kbh.18d4a238bc24fef7,"reason=FailedScheduling count=None msg=0/6 nodes are available: 1 c_wall violated: 2 conflicting context pair(s) with node memory, 5 node(s) had untolerated taint(s). no new claims to deallocate, preemption: 0/6 nodes are available: 1 No preemption victims found for incoming pod, 5 Preemption is not helpful for scheduling."
0.1197,Event,ADDED,eval-sanitize-1-r1-062-dz2tv.18d4a238112100cd,"reason=FailedScheduling count=None msg=0/6 nodes are available: 1 c_wall violated: 1 conflicting context pair(s) with node memory, 5 node(s) had untolerated taint(s). no new claims to deallocate, preemption: 0/6 nodes are available: 1 No preemption victims found for incoming pod, 5 Preemption is not helpful for scheduling."
0.1201,Event,ADDED,eval-sanitize-1-r1-064-624s9.18d4a2381153223b,"reason=FailedScheduling count=None msg=0/6 nodes are available: 1 c_wall violated: 3 conflicting context pair(s) with node memory, 5 node(s) had untolerated taint(s). no new claims to deallocate, preemption: 0/6 nodes are available: 1 No preemption victims found for incoming pod, 5 Preemption is not helpful for scheduling."
0.1204,Event,ADDED,eval-sanitize-1-r1-067-xtj9w.18d4a23811882221,"reason=FailedScheduling count=None msg=0/6 nodes are available: 1 c_wall violated: 1 conflicting context pair(s) with node memory, 5 node(s) had untolerated taint(s). no new claims to deallocate, preemption: 0/6 nodes are available: 1 No preemption victims found for incoming pod, 5 Preemption is not helpful for scheduling."
0.1208,Event,ADDED,eval-sanitize-1-r1-069-7p8r4.18d4a23811bb6e9c,"reason=FailedScheduling count=None msg=0/6 nodes are available: 1 c_wall violated: 2 conflicting context pair(s) with node memory, 5 node(s) had untolerated taint(s). no new claims to deallocate, preemption: 0/6 nodes are available: 1 No preemption victims found for incoming pod, 5 Preemption is not helpful for scheduling."
0.1212,Event,ADDED,eval-sanitize-1-r1-070-8rv27.18d4a2382165ba7c,"reason=FailedScheduling count=None msg=0/6 nodes are available: 1 c_wall violated: 1 conflicting context pair(s) with node memory, 5 node(s) had untolerated taint(s). no new claims to deallocate, preemption: 0/6 nodes are available: 1 No preemption victims found for incoming pod, 5 Preemption is not helpful for scheduling."
0.1214,Event,ADDED,eval-sanitize-1-r1-072-6v2rf.18d4a2389806bd4f,"reason=FailedScheduling count=None msg=0/6 nodes are available: 1 c_wall violated: 1 conflicting context pair(s) with node memory, 5 node(s) had untolerated taint(s). no new claims to deallocate, preemption: 0/6 nodes are available: 1 No preemption victims found for incoming pod, 5 Preemption is not helpful for scheduling."
0.1216,Event,ADDED,eval-sanitize-1-r1-072-6v2rf.18d4a238b86a64ec,"reason=FailedScheduling count=None msg=0/6 nodes are available: 1 c_wall violated: 2 conflicting context pair(s) with node memory, 5 node(s) had untolerated taint(s). no new claims to deallocate, preemption: 0/6 nodes are available: 1 No preemption victims found for incoming pod, 5 Preemption is not helpful for scheduling."
0.1222,Event,ADDED,eval-sanitize-1-r1-075-qnp7w.18d4a239a28251cf,"reason=FailedScheduling count=None msg=0/6 nodes are available: 1 c_wall violated: 2 conflicting context pair(s) with node memory, 5 node(s) had untolerated taint(s). no new claims to deallocate, preemption: 0/6 nodes are available: 1 No preemption victims found for incoming pod, 5 Preemption is not helpful for scheduling."
0.1226,Event,ADDED,eval-sanitize-1-r1-076-27w26.18d4a239a2b39aca,"reason=FailedScheduling count=None msg=0/6 nodes are available: 1 c_wall violated: 1 conflicting context pair(s) with node memory, 5 node(s) had untolerated taint(s). no new claims to deallocate, preemption: 0/6 nodes are available: 1 No preemption victims found for incoming pod, 5 Preemption is not helpful for scheduling."
0.1229,Event,ADDED,eval-sanitize-1-r1-076-27w26.18d4a23d98cb24c5,"reason=FailedScheduling count=None msg=0/6 nodes are available: 1 c_wall violated: 3 conflicting context pair(s) with node memory, 5 node(s) had untolerated taint(s). no new claims to deallocate, preemption: 0/6 nodes are available: 1 No preemption victims found for incoming pod, 5 Preemption is not helpful for scheduling."
0.1233,Event,ADDED,eval-sanitize-1-r1-076-27w26.18d4a23dfb086c9e,"reason=FailedScheduling count=None msg=0/6 nodes are available: 1 c_wall violated: 1 conflicting context pair(s) with node memory, 5 node(s) had untolerated taint(s). no new claims to deallocate, preemption: 0/6 nodes are available: 1 No preemption victims found for incoming pod, 5 Preemption is not helpful for scheduling."
0.1235,Event,ADDED,eval-sanitize-1-r1-076-27w26.18d4a23e88730e81,"reason=FailedScheduling count=None msg=0/6 nodes are available: 1 c_wall violated: 1 conflicting context pair(s) with node memory, 5 node(s) had untolerated taint(s). no new claims to deallocate, preemption: 0/6 nodes are available: 1 No preemption victims found for incoming pod, 5 Preemption is not helpful for scheduling."
0.1237,Event,ADDED,eval-sanitize-1-r1-076-27w26.18d4a23ec4369c8e,"reason=FailedScheduling count=None msg=0/6 nodes are available: 2 c_wall violated: 1 conflicting context pair(s) with node memory, 4 node(s) had untolerated taint(s). no new claims to deallocate, preemption: 0/6 nodes are available: 2 No preemption victims found for incoming pod, 4 Preemption is not helpful for scheduling."
0.1245,Job,MODIFIED,eval-sanitize-5-r0-000,
0.1248,Event,ADDED,eval-sanitize-1-r1-076-27w26.18d4a23ed051272e,"reason=FailedScheduling count=None msg=0/6 nodes are available: 1 c_wall violated: 1 conflicting context pair(s) with node memory, 5 node(s) had untolerated taint(s). no new claims to deallocate, preemption: 0/6 nodes are available: 1 No preemption victims found for incoming pod, 5 Preemption is not helpful for scheduling."
0.1254,Event,ADDED,eval-sanitize-1-r1-076-27w26.18d4a23ed71fc8c6,"reason=FailedScheduling count=None msg=0/6 nodes are available: 1 c_wall violated: 2 conflicting context pair(s) with node memory, 5 node(s) had untolerated taint(s). no new claims to deallocate, preemption: 0/6 nodes are available: 1 No preemption victims found for incoming pod, 5 Preemption is not helpful for scheduling."
0.1259,Event,ADDED,eval-sanitize-1-r1-077-2zpts.18d4a239c001051f,"reason=FailedScheduling count=None msg=0/6 nodes are available: 1 c_wall violated: 2 conflicting context pair(s) with node memory, 5 node(s) had untolerated taint(s). no new claims to deallocate, preemption: 0/6 nodes are available: 1 No preemption victims found for incoming pod, 5 Preemption is not helpful for scheduling."
0.1261,Event,ADDED,eval-sanitize-1-r1-081-j2c75.18d4a23d9176c292,"reason=FailedScheduling count=None msg=0/6 nodes are available: 1 c_wall violated: 2 conflicting context pair(s) with node memory, 5 node(s) had untolerated taint(s). no new claims to deallocate, preemption: 0/6 nodes are available: 1 No preemption victims found for incoming pod, 5 Preemption is not helpful for scheduling."
0.1263,Event,ADDED,eval-sanitize-1-r1-081-j2c75.18d4a23dff90b876,"reason=FailedScheduling count=None msg=0/6 nodes are available: 1 c_wall violated: 2 conflicting context pair(s) with node memory, 5 node(s) had untolerated taint(s). no new claims to deallocate, preemption: 0/6 nodes are available: 1 No preemption victims found for incoming pod, 5 Preemption is not helpful for scheduling."
0.1265,Event,ADDED,eval-sanitize-1-r1-084-f4zcw.18d4a23d91d92d58,"reason=FailedScheduling count=None msg=0/6 nodes are available: 1 c_wall violated: 1 conflicting context pair(s) with node memory, 5 node(s) had untolerated taint(s). no new claims to deallocate, preemption: 0/6 nodes are available: 1 No preemption victims found for incoming pod, 5 Preemption is not helpful for scheduling."
0.1267,Event,ADDED,eval-sanitize-1-r1-084-f4zcw.18d4a23dfc0e3626,"reason=FailedScheduling count=None msg=0/6 nodes are available: 1 c_wall violated: 1 conflicting context pair(s) with node memory, 5 node(s) had untolerated taint(s). no new claims to deallocate, preemption: 0/6 nodes are available: 1 No preemption victims found for incoming pod, 5 Preemption is not helpful for scheduling."
0.1271,Event,ADDED,eval-sanitize-1-r1-084-f4zcw.18d4a23e8899a89f,"reason=FailedScheduling count=None msg=0/6 nodes are available: 1 c_wall violated: 2 conflicting context pair(s) with node memory, 5 node(s) had untolerated taint(s). no new claims to deallocate, preemption: 0/6 nodes are available: 1 No preemption victims found for incoming pod, 5 Preemption is not helpful for scheduling."
0.1275,Event,ADDED,eval-sanitize-1-r1-085-7rql6.18d4a23d93dc37bc,"reason=FailedScheduling count=None msg=0/6 nodes are available: 1 c_wall violated: 2 conflicting context pair(s) with node memory, 5 node(s) had untolerated taint(s). no new claims to deallocate, preemption: 0/6 nodes are available: 1 No preemption victims found for incoming pod, 5 Preemption is not helpful for scheduling."
0.1278,Event,ADDED,eval-sanitize-1-r1-086-qvrbj.18d4a23d9a3ed6e6,"reason=FailedScheduling count=None msg=0/6 nodes are available: 1 c_wall violated: 4 conflicting context pair(s) with node memory, 5 node(s) had untolerated taint(s). no new claims to deallocate, preemption: 0/6 nodes are available: 1 No preemption victims found for incoming pod, 5 Preemption is not helpful for scheduling."
0.128,Event,ADDED,eval-sanitize-1-r1-086-qvrbj.18d4a23dfc4484af,"reason=FailedScheduling count=None msg=0/6 nodes are available: 1 c_wall violated: 1 conflicting context pair(s) with node memory, 5 node(s) had untolerated taint(s). no new claims to deallocate, preemption: 0/6 nodes are available: 1 No preemption victims found for incoming pod, 5 Preemption is not helpful for scheduling."
0.1294,Pod,MODIFIED,eval-sanitize-5-r0-000-qh6gr,phase=Pending node=kind-worker5
0.1297,Event,ADDED,eval-sanitize-1-r1-087-6cjgv.18d4a23d94a117ae,"reason=FailedScheduling count=None msg=0/6 nodes are available: 1 c_wall violated: 2 conflicting context pair(s) with node memory, 5 node(s) had untolerated taint(s). no new claims to deallocate, preemption: 0/6 nodes are available: 1 No preemption victims found for incoming pod, 5 Preemption is not helpful for scheduling."
0.1299,Event,ADDED,eval-sanitize-1-r1-088-kdrft.18d4a23d9a703cb4,"reason=FailedScheduling count=None msg=0/6 nodes are available: 1 c_wall violated: 2 conflicting context pair(s) with node memory, 5 node(s) had untolerated taint(s). no new claims to deallocate, preemption: 0/6 nodes are available: 1 No preemption victims found for incoming pod, 5 Preemption is not helpful for scheduling."
0.1301,Event,ADDED,eval-sanitize-1-r1-090-lng2f.18d4a23d964cc431,"reason=FailedScheduling count=None msg=0/6 nodes are available: 1 c_wall violated: 2 conflicting context pair(s) with node memory, 5 node(s) had untolerated taint(s). no new claims to deallocate, preemption: 0/6 nodes are available: 1 No preemption victims found for incoming pod, 5 Preemption is not helpful for scheduling."
0.1306,Event,ADDED,eval-sanitize-1-r1-090-lng2f.18d4a23dff4038b5,"reason=FailedScheduling count=None msg=0/6 nodes are available: 1 c_wall violated: 2 conflicting context pair(s) with node memory, 5 node(s) had untolerated taint(s). no new claims to deallocate, preemption: 0/6 nodes are available: 1 No preemption victims found for incoming pod, 5 Preemption is not helpful for scheduling."
0.1308,Event,ADDED,eval-sanitize-1-r1-094-tl9kp.18d4a23dab5a297a,"reason=FailedScheduling count=None msg=0/6 nodes are available: 1 c_wall violated: 2 conflicting context pair(s) with node memory, 5 node(s) had untolerated taint(s). no new claims to deallocate, preemption: 0/6 nodes are available: 1 No preemption victims found for incoming pod, 5 Preemption is not helpful for scheduling."
0.1313,Event,ADDED,eval-sanitize-1-r1-095-jmhgd.18d4a23e0766e3ce,"reason=FailedScheduling count=None msg=0/6 nodes are available: 1 c_wall violated: 1 conflicting context pair(s) with node memory, 5 node(s) had untolerated taint(s). no new claims to deallocate, preemption: 0/6 nodes are available: 1 No preemption victims found for incoming pod, 5 Preemption is not helpful for scheduling."
0.1317,Event,ADDED,eval-sanitize-1-r1-095-jmhgd.18d4a23e884a19f9,"reason=FailedScheduling count=None msg=0/6 nodes are available: 1 c_wall violated: 2 conflicting context pair(s) with node memory, 5 node(s) had untolerated taint(s). no new claims to deallocate, preemption: 0/6 nodes are available: 1 No preemption victims found for incoming pod, 5 Preemption is not helpful for scheduling."
0.1319,Event,ADDED,eval-sanitize-1-r1-096-gzvlz.18d4a23e88ca42ec,"reason=FailedScheduling count=None msg=0/6 nodes are available: 1 c_wall violated: 2 conflicting context pair(s) with node memory, 5 node(s) had untolerated taint(s). no new claims to deallocate, preemption: 0/6 nodes are available: 1 No preemption victims found for incoming pod, 5 Preemption is not helpful for scheduling."
0.1323,Event,ADDED,eval-sanitize-1-r1-097-tqtmq.18d4a23ea17aec04,"reason=FailedScheduling count=None msg=0/6 nodes are available: 1 c_wall violated: 2 conflicting context pair(s) with node memory, 5 node(s) had untolerated taint(s). no new claims to deallocate, preemption: 0/6 nodes are available: 1 No preemption victims found for incoming pod, 5 Preemption is not helpful for scheduling."
0.1326,Event,ADDED,eval-sanitize-1-r1-099-vnl6p.18d4a23f0c562dee,"reason=FailedScheduling count=None msg=0/6 nodes are available: 1 c_wall violated: 1 conflicting context pair(s) with node memory, 5 node(s) had untolerated taint(s). no new claims to deallocate, preemption: 0/6 nodes are available: 1 No preemption victims found for incoming pod, 5 Preemption is not helpful for scheduling."
0.1328,Event,ADDED,eval-sanitize-1-r1-100-2mmth.18d4a23f2dcf4dd9,"reason=FailedScheduling count=None msg=0/6 nodes are available: 1 c_wall violated: 1 conflicting context pair(s) with node memory, 5 node(s) had untolerated taint(s). no new claims to deallocate, preemption: 0/6 nodes are available: 1 No preemption victims found for incoming pod, 5 Preemption is not helpful for scheduling."
0.1332,Event,ADDED,eval-sanitize-1-r1-103-2zx4c.18d4a2444e537a52,"reason=FailedScheduling count=None msg=0/6 nodes are available: 1 c_wall violated: 2 conflicting context pair(s) with node memory, 5 node(s) had untolerated taint(s). no new claims to deallocate, preemption: 0/6 nodes are available: 1 No preemption victims found for incoming pod, 5 Preemption is not helpful for scheduling."
0.1334,Event,ADDED,eval-sanitize-1-r1-111-wmwlw.18d4a2444e8fc02c,"reason=FailedScheduling count=None msg=0/6 nodes are available: 1 c_wall violated: 1 conflicting context pair(s) with node memory, 5 node(s) had untolerated taint(s). no new claims to deallocate, preemption: 0/6 nodes are available: 1 No preemption victims found for incoming pod, 5 Preemption is not helpful for scheduling."
0.1336,Event,ADDED,eval-sanitize-1-r1-115-dltsh.18d4a2444ec13291,"reason=FailedScheduling count=None msg=0/6 nodes are available: 1 c_wall violated: 1 conflicting context pair(s) with node memory, 5 node(s) had untolerated taint(s). no new claims to deallocate, preemption: 0/6 nodes are available: 1 No preemption victims found for incoming pod, 5 Preemption is not helpful for scheduling."
0.1341,Event,ADDED,eval-sanitize-1-r1-116-529zn.18d4a2444a1ee163,"reason=FailedScheduling count=None msg=0/6 nodes are available: 1 c_wall violated: 1 conflicting context pair(s) with node memory, 5 node(s) had untolerated taint(s). no new claims to deallocate, preemption: 0/6 nodes are available: 1 No preemption victims found for incoming pod, 5 Preemption is not helpful for scheduling."
0.1343,Event,ADDED,eval-sanitize-1-r1-117-wb2jr.18d4a2444a543432,"reason=FailedScheduling count=None msg=0/6 nodes are available: 1 c_wall violated: 2 conflicting context pair(s) with node memory, 5 node(s) had untolerated taint(s). no new claims to deallocate, preemption: 0/6 nodes are available: 1 No preemption victims found for incoming pod, 5 Preemption is not helpful for scheduling."
0.1346,Event,ADDED,eval-sanitize-1-r1-118-dbnc7.18d4a2444a847876,"reason=FailedScheduling count=None msg=0/6 nodes are available: 1 c_wall violated: 1 conflicting context pair(s) with node memory, 5 node(s) had untolerated taint(s). no new claims to deallocate, preemption: 0/6 nodes are available: 1 No preemption victims found for incoming pod, 5 Preemption is not helpful for scheduling."
0.136,Job,MODIFIED,eval-sanitize-5-r0-000,
0.1364,Event,ADDED,eval-sanitize-1-r1-123-sl7r8.18d4a244712892ea,"reason=FailedScheduling count=None msg=0/6 nodes are available: 1 c_wall violated: 1 conflicting context pair(s) with node memory, 1 c_wall violated: 2 conflicting context pair(s) with node memory, 4 node(s) had untolerated taint(s). no new claims to deallocate, preemption: 0/6 nodes are available: 2 No preemption victims found for incoming pod, 4 Preemption is not helpful for scheduling."
0.1366,Event,ADDED,eval-sanitize-1-r1-123-sl7r8.18d4a24497aa3a5b,"reason=FailedScheduling count=None msg=0/6 nodes are available: 1 c_wall violated: 1 conflicting context pair(s) with node memory, 5 node(s) had untolerated taint(s). no new claims to deallocate, preemption: 0/6 nodes are available: 1 No preemption victims found for incoming pod, 5 Preemption is not helpful for scheduling."
0.137,Event,ADDED,eval-sanitize-1-r1-125-r4jn5.18d4a2456c5399be,"reason=FailedScheduling count=None msg=0/6 nodes are available: 1 c_wall violated: 2 conflicting context pair(s) with node memory, 5 node(s) had untolerated taint(s). no new claims to deallocate, preemption: 0/6 nodes are available: 1 No preemption victims found for incoming pod, 5 Preemption is not helpful for scheduling."
0.1372,Event,ADDED,eval-sanitize-1-r1-125-r4jn5.18d4a2497328684b,"reason=FailedScheduling count=None msg=0/6 nodes are available: 1 c_wall violated: 1 conflicting context pair(s) with node memory, 5 node(s) had untolerated taint(s). no new claims to deallocate, preemption: 0/6 nodes are available: 1 No preemption victims found for incoming pod, 5 Preemption is not helpful for scheduling."
0.1374,Event,ADDED,eval-sanitize-1-r1-125-r4jn5.18d4a24a75922798,"reason=FailedScheduling count=None msg=0/6 nodes are available: 1 c_wall violated: 1 conflicting context pair(s) with node memory, 5 node(s) had untolerated taint(s). no new claims to deallocate, preemption: 0/6 nodes are available: 1 No preemption victims found for incoming pod, 5 Preemption is not helpful for scheduling."
0.1388,Node,MODIFIED,kind-worker5,taints=0
0.1399,Pod,MODIFIED,eval-sanitize-5-r0-000-qh6gr,phase=Pending node=kind-worker5
0.1402,Event,ADDED,eval-sanitize-1-r1-125-r4jn5.18d4a24a9d9d51ea,"reason=FailedScheduling count=None msg=0/6 nodes are available: 2 c_wall violated: 1 conflicting context pair(s) with node memory, 4 node(s) had untolerated taint(s). no new claims to deallocate, preemption: 0/6 nodes are available: 2 No preemption victims found for incoming pod, 4 Preemption is not helpful for scheduling."
0.1404,Event,ADDED,eval-sanitize-1-r1-125-r4jn5.18d4a24acc78ba6c,"reason=FailedScheduling count=None msg=0/6 nodes are available: 1 c_wall violated: 1 conflicting context pair(s) with node memory, 5 node(s) had untolerated taint(s). no new claims to deallocate, preemption: 0/6 nodes are available: 1 No preemption victims found for incoming pod, 5 Preemption is not helpful for scheduling."
0.1406,Event,ADDED,eval-sanitize-1-r1-125-r4jn5.18d4a24aea33d2bc,"reason=FailedScheduling count=None msg=0/6 nodes are available: 1 c_wall violated: 1 conflicting context pair(s) with node memory, 5 node(s) had untolerated taint(s). no new claims to deallocate, preemption: 0/6 nodes are available: 1 No preemption victims found for incoming pod, 5 Preemption is not helpful for scheduling."
0.141,Event,ADDED,eval-sanitize-1-r1-126-sssrt.18d4a2456c2705fa,"reason=FailedScheduling count=None msg=0/6 nodes are available: 1 c_wall violated: 1 conflicting context pair(s) with node memory, 5 node(s) had untolerated taint(s). no new claims to deallocate, preemption: 0/6 nodes are available: 1 No preemption victims found for incoming pod, 5 Preemption is not helpful for scheduling."
0.1414,Event,ADDED,eval-sanitize-1-r1-128-944xf.18d4a24594720fd3,"reason=FailedScheduling count=None msg=0/6 nodes are available: 1 c_wall violated: 1 conflicting context pair(s) with node memory, 5 node(s) had untolerated taint(s). no new claims to deallocate, preemption: 0/6 nodes are available: 1 No preemption victims found for incoming pod, 5 Preemption is not helpful for scheduling."
0.1416,Event,ADDED,eval-sanitize-1-r1-131-sqjg8.18d4a249735e9758,"reason=FailedScheduling count=None msg=0/6 nodes are available: 1 c_wall violated: 1 conflicting context pair(s) with node memory, 5 node(s) had untolerated taint(s). no new claims to deallocate, preemption: 0/6 nodes are available: 1 No preemption victims found for incoming pod, 5 Preemption is not helpful for scheduling."
0.142,Event,ADDED,eval-sanitize-1-r1-133-h9qbg.18d4a24973b8f03e,"reason=FailedScheduling count=None msg=0/6 nodes are available: 1 c_wall violated: 1 conflicting context pair(s) with node memory, 5 node(s) had untolerated taint(s). no new claims to deallocate, preemption: 0/6 nodes are available: 1 No preemption victims found for incoming pod, 5 Preemption is not helpful for scheduling."
0.1422,Event,ADDED,eval-sanitize-1-r1-134-5lb9m.18d4a24975436d98,"reason=FailedScheduling count=None msg=0/6 nodes are available: 1 c_wall violated: 1 conflicting context pair(s) with node memory, 5 node(s) had untolerated taint(s). no new claims to deallocate, preemption: 0/6 nodes are available: 1 No preemption victims found for incoming pod, 5 Preemption is not helpful for scheduling."
0.1425,Event,ADDED,eval-sanitize-1-r1-134-5lb9m.18d4a24a763bfa66,"reason=FailedScheduling count=None msg=0/6 nodes are available: 1 c_wall violated: 1 conflicting context pair(s) with node memory, 5 node(s) had untolerated taint(s). no new claims to deallocate, preemption: 0/6 nodes are available: 1 No preemption victims found for incoming pod, 5 Preemption is not helpful for scheduling."
0.1428,Event,ADDED,eval-sanitize-1-r1-134-5lb9m.18d4a24aa28597ff,"reason=FailedScheduling count=None msg=0/6 nodes are available: 2 c_wall violated: 1 conflicting context pair(s) with node memory, 4 node(s) had untolerated taint(s). no new claims to deallocate, preemption: 0/6 nodes are available: 2 No preemption victims found for incoming pod, 4 Preemption is not helpful for scheduling."
0.143,Event,ADDED,eval-sanitize-1-r1-134-5lb9m.18d4a24acca9c53f,"reason=FailedScheduling count=None msg=0/6 nodes are available: 1 c_wall violated: 1 conflicting context pair(s) with node memory, 5 node(s) had untolerated taint(s). no new claims to deallocate, preemption: 0/6 nodes are available: 1 No preemption victims found for incoming pod, 5 Preemption is not helpful for scheduling."
0.1433,Event,ADDED,eval-sanitize-1-r1-134-5lb9m.18d4a24aea6684d5,"reason=FailedScheduling count=None msg=0/6 nodes are available: 1 c_wall violated: 1 conflicting context pair(s) with node memory, 5 node(s) had untolerated taint(s). no new claims to deallocate, preemption: 0/6 nodes are available: 1 No preemption victims found for incoming pod, 5 Preemption is not helpful for scheduling."
0.1435,Event,ADDED,eval-sanitize-1-r1-135-kqpj2.18d4a249757e3960,"reason=FailedScheduling count=None msg=0/6 nodes are available: 1 c_wall violated: 2 conflicting context pair(s) with node memory, 5 node(s) had untolerated taint(s). no new claims to deallocate, preemption: 0/6 nodes are available: 1 No preemption victims found for incoming pod, 5 Preemption is not helpful for scheduling."
0.1436,Event,ADDED,eval-sanitize-1-r1-136-v5hmk.18d4a24975aadf02,"reason=FailedScheduling count=None msg=0/6 nodes are available: 1 c_wall violated: 1 conflicting context pair(s) with node memory, 5 node(s) had untolerated taint(s). no new claims to deallocate, preemption: 0/6 nodes are available: 1 No preemption victims found for incoming pod, 5 Preemption is not helpful for scheduling."
0.1441,Event,ADDED,eval-sanitize-1-r1-137-2h49b.18d4a24977281892,"reason=FailedScheduling count=None msg=0/6 nodes are available: 1 c_wall violated: 2 conflicting context pair(s) with node memory, 5 node(s) had untolerated taint(s). no new claims to deallocate, preemption: 0/6 nodes are available: 1 No preemption victims found for incoming pod, 5 Preemption is not helpful for scheduling."
0.1443,Event,ADDED,eval-sanitize-1-r1-139-s28q8.18d4a24978aaec00,"reason=FailedScheduling count=None msg=0/6 nodes are available: 1 c_wall violated: 2 conflicting context pair(s) with node memory, 5 node(s) had untolerated taint(s). no new claims to deallocate, preemption: 0/6 nodes are available: 1 No preemption victims found for incoming pod, 5 Preemption is not helpful for scheduling."
0.1444,Event,ADDED,eval-sanitize-1-r1-140-qfqhd.18d4a24979b224a1,"reason=FailedScheduling count=None msg=0/6 nodes are available: 1 c_wall violated: 1 conflicting context pair(s) with node memory, 5 node(s) had untolerated taint(s). no new claims to deallocate, preemption: 0/6 nodes are available: 1 No preemption victims found for incoming pod, 5 Preemption is not helpful for scheduling."
0.145,Event,ADDED,eval-sanitize-1-r1-140-qfqhd.18d4a24a79da9d01,"reason=FailedScheduling count=None msg=0/6 nodes are available: 1 c_wall violated: 1 conflicting context pair(s) with node memory, 5 node(s) had untolerated taint(s). no new claims to deallocate, preemption: 0/6 nodes are available: 1 No preemption victims found for incoming pod, 5 Preemption is not helpful for scheduling."
0.1452,Event,ADDED,eval-sanitize-1-r1-140-qfqhd.18d4a24a9ce02550,"reason=FailedScheduling count=None msg=0/6 nodes are available: 2 c_wall violated: 1 conflicting context pair(s) with node memory, 4 node(s) had untolerated taint(s). no new claims to deallocate, preemption: 0/6 nodes are available: 2 No preemption victims found for incoming pod, 4 Preemption is not helpful for scheduling."
0.1454,Event,ADDED,eval-sanitize-1-r1-140-qfqhd.18d4a24acc3de956,"reason=FailedScheduling count=None msg=0/6 nodes are available: 1 c_wall violated: 1 conflicting context pair(s) with node memory, 5 node(s) had untolerated taint(s). no new claims to deallocate, preemption: 0/6 nodes are available: 1 No preemption victims found for incoming pod, 5 Preemption is not helpful for scheduling."
0.1458,Event,ADDED,eval-sanitize-1-r1-140-qfqhd.18d4a24aea02ad90,"reason=FailedScheduling count=None msg=0/6 nodes are available: 1 c_wall violated: 1 conflicting context pair(s) with node memory, 5 node(s) had untolerated taint(s). no new claims to deallocate, preemption: 0/6 nodes are available: 1 No preemption victims found for incoming pod, 5 Preemption is not helpful for scheduling."
0.146,Event,ADDED,eval-sanitize-1-r1-141-hfwx8.18d4a24979e4a875,"reason=FailedScheduling count=None msg=0/6 nodes are available: 1 c_wall violated: 2 conflicting context pair(s) with node memory, 5 node(s) had untolerated taint(s). no new claims to deallocate, preemption: 0/6 nodes are available: 1 No preemption victims found for incoming pod, 5 Preemption is not helpful for scheduling."
0.1462,Event,ADDED,eval-sanitize-1-r1-142-wwvlq.18d4a2497a161119,"reason=FailedScheduling count=None msg=0/6 nodes are available: 1 c_wall violated: 1 conflicting context pair(s) with node memory, 5 node(s) had untolerated taint(s). no new claims to deallocate, preemption: 0/6 nodes are available: 1 No preemption victims found for incoming pod, 5 Preemption is not helpful for scheduling."
0.1467,Event,ADDED,eval-sanitize-1-r1-142-wwvlq.18d4a24a003ef08d,"reason=FailedScheduling count=None msg=0/6 nodes are available: 1 c_wall violated: 2 conflicting context pair(s) with node memory, 5 node(s) had untolerated taint(s). no new claims to deallocate, preemption: 0/6 nodes are available: 1 No preemption victims found for incoming pod, 5 Preemption is not helpful for scheduling."
0.1469,Event,ADDED,eval-sanitize-1-r1-144-lgngv.18d4a2497a5495b3,"reason=FailedScheduling count=None msg=0/6 nodes are available: 1 c_wall violated: 1 conflicting context pair(s) with node memory, 5 node(s) had untolerated taint(s). no new claims to deallocate, preemption: 0/6 nodes are available: 1 No preemption victims found for incoming pod, 5 Preemption is not helpful for scheduling."
0.1472,Event,ADDED,eval-sanitize-1-r1-147-dbvhw.18d4a24a8499f093,"reason=FailedScheduling count=None msg=0/6 nodes are available: 1 c_wall violated: 2 conflicting context pair(s) with node memory, 5 node(s) had untolerated taint(s). no new claims to deallocate, preemption: 0/6 nodes are available: 1 No preemption victims found for incoming pod, 5 Preemption is not helpful for scheduling."
0.1478,Event,ADDED,eval-sanitize-1-r1-147-dbvhw.18d4a24aa2de5abb,"reason=FailedScheduling count=None msg=0/6 nodes are available: 1 c_wall violated: 1 conflicting context pair(s) with node memory, 1 c_wall violated: 2 conflicting context pair(s) with node memory, 4 node(s) had untolerated taint(s). no new claims to deallocate, preemption: 0/6 nodes are available: 2 No preemption victims found for incoming pod, 4 Preemption is not helpful for scheduling."
0.1481,Event,ADDED,eval-sanitize-1-r1-149-fp4fx.18d4a24aeaa15231,"reason=FailedScheduling count=None msg=0/6 nodes are available: 1 c_wall violated: 1 conflicting context pair(s) with node memory, 5 node(s) had untolerated taint(s). no new claims to deallocate, preemption: 0/6 nodes are available: 1 No preemption victims found for incoming pod, 5 Preemption is not helpful for scheduling."
0.1485,Event,ADDED,eval-sanitize-1-r1-149-fp4fx.18d4a24ecf263492,"reason=FailedScheduling count=None msg=0/6 nodes are available: 1 c_wall violated: 2 conflicting context pair(s) with node memory, 5 node(s) had untolerated taint(s). no new claims to deallocate, preemption: 0/6 nodes are available: 1 No preemption victims found for incoming pod, 5 Preemption is not helpful for scheduling."
0.1487,Event,ADDED,eval-sanitize-1-r1-150-crp5h.18d4a24ecf5393be,"reason=FailedScheduling count=None msg=0/6 nodes are available: 1 c_wall violated: 2 conflicting context pair(s) with node memory, 5 node(s) had untolerated taint(s). no new claims to deallocate, preemption: 0/6 nodes are available: 1 No preemption victims found for incoming pod, 5 Preemption is not helpful for scheduling."
0.1489,Event,ADDED,eval-sanitize-1-r1-150-crp5h.18d4a2505fa87006,"reason=FailedScheduling count=None msg=0/6 nodes are available: 1 c_wall violated: 2 conflicting context pair(s) with node memory, 5 node(s) had untolerated taint(s). no new claims to deallocate, preemption: 0/6 nodes are available: 1 No preemption victims found for incoming pod, 5 Preemption is not helpful for scheduling."
0.1493,Event,ADDED,eval-sanitize-1-r1-150-crp5h.18d4a250c9cde3a4,"reason=FailedScheduling count=None msg=0/6 nodes are available: 1 c_wall violated: 1 conflicting context pair(s) with node memory, 5 node(s) had untolerated taint(s). no new claims to deallocate, preemption: 0/6 nodes are available: 1 No preemption victims found for incoming pod, 5 Preemption is not helpful for scheduling."
0.1495,Event,ADDED,eval-sanitize-1-r1-153-dcfbm.18d4a24ec6485bab,"reason=FailedScheduling count=None msg=0/6 nodes are available: 1 c_wall violated: 2 conflicting context pair(s) with node memory, 5 node(s) had untolerated taint(s). no new claims to deallocate, preemption: 0/6 nodes are available: 1 No preemption victims found for incoming pod, 5 Preemption is not helpful for scheduling."
0.1497,Event,ADDED,eval-sanitize-1-r1-155-gcvx2.18d4a24ec88281f8,"reason=FailedScheduling count=None msg=0/6 nodes are available: 1 c_wall violated: 2 conflicting context pair(s) with node memory, 5 node(s) had untolerated taint(s). no new claims to deallocate, preemption: 0/6 nodes are available: 1 No preemption victims found for incoming pod, 5 Preemption is not helpful for scheduling."
0.1512,Node,MODIFIED,kind-worker5,taints=0
0.1515,Event,ADDED,eval-sanitize-1-r1-156-rsm5t.18d4a24ec8b7e940,"reason=FailedScheduling count=None msg=0/6 nodes are available: 1 c_wall violated: 1 conflicting context pair(s) with node memory, 5 node(s) had untolerated taint(s). no new claims to deallocate, preemption: 0/6 nodes are available: 1 No preemption victims found for incoming pod, 5 Preemption is not helpful for scheduling."
0.1517,Event,ADDED,eval-sanitize-1-r1-158-nnc85.18d4a24ec8ea6212,"reason=FailedScheduling count=None msg=0/6 nodes are available: 1 c_wall violated: 3 conflicting context pair(s) with node memory, 5 node(s) had untolerated taint(s). no new claims to deallocate, preemption: 0/6 nodes are available: 1 No preemption victims found for incoming pod, 5 Preemption is not helpful for scheduling."
0.152,Event,ADDED,eval-sanitize-1-r1-159-pzvf4.18d4a24ec91a4263,"reason=FailedScheduling count=None msg=0/6 nodes are available: 1 c_wall violated: 1 conflicting context pair(s) with node memory, 5 node(s) had untolerated taint(s). no new claims to deallocate, preemption: 0/6 nodes are available: 1 No preemption victims found for incoming pod, 5 Preemption is not helpful for scheduling."
0.1523,Event,ADDED,eval-sanitize-1-r1-160-7k4m8.18d4a24ec94b5a44,"reason=FailedScheduling count=None msg=0/6 nodes are available: 1 c_wall violated: 2 conflicting context pair(s) with node memory, 5 node(s) had untolerated taint(s). no new claims to deallocate, preemption: 0/6 nodes are available: 1 No preemption victims found for incoming pod, 5 Preemption is not helpful for scheduling."
0.1525,Event,ADDED,eval-sanitize-1-r1-161-qwktj.18d4a24ec978a917,"reason=FailedScheduling count=None msg=0/6 nodes are available: 1 c_wall violated: 2 conflicting context pair(s) with node memory, 5 node(s) had untolerated taint(s). no new claims to deallocate, preemption: 0/6 nodes are available: 1 No preemption victims found for incoming pod, 5 Preemption is not helpful for scheduling."
0.1527,Event,ADDED,eval-sanitize-1-r1-162-gjc7m.18d4a24ecd5bac4d,"reason=FailedScheduling count=None msg=0/6 nodes are available: 1 c_wall violated: 2 conflicting context pair(s) with node memory, 5 node(s) had untolerated taint(s). no new claims to deallocate, preemption: 0/6 nodes are available: 1 No preemption victims found for incoming pod, 5 Preemption is not helpful for scheduling."
0.153,Event,ADDED,eval-sanitize-1-r1-163-69g7n.18d4a24ece8cb35e,"reason=FailedScheduling count=None msg=0/6 nodes are available: 1 c_wall violated: 2 conflicting context pair(s) with node memory, 5 node(s) had untolerated taint(s). no new claims to deallocate, preemption: 0/6 nodes are available: 1 No preemption victims found for incoming pod, 5 Preemption is not helpful for scheduling."
0.1532,Event,ADDED,eval-sanitize-1-r1-163-69g7n.18d4a2505de8827c,"reason=FailedScheduling count=None msg=0/6 nodes are available: 1 c_wall violated: 2 conflicting context pair(s) with node memory, 5 node(s) had untolerated taint(s). no new claims to deallocate, preemption: 0/6 nodes are available: 1 No preemption victims found for incoming pod, 5 Preemption is not helpful for scheduling."
0.1535,Event,ADDED,eval-sanitize-1-r1-163-69g7n.18d4a250b6580bdd,"reason=FailedScheduling count=None msg=0/6 nodes are available: 1 c_wall violated: 1 conflicting context pair(s) with node memory, 2 c_wall violated: 2 conflicting context pair(s) with node memory, 3 node(s) had untolerated taint(s). no new claims to deallocate, preemption: 0/6 nodes are available: 3 No preemption victims found for incoming pod, 3 Preemption is not helpful for scheduling."
0.1537,Event,ADDED,eval-sanitize-1-r1-163-69g7n.18d4a250ca3871a7,"reason=FailedScheduling count=None msg=0/6 nodes are available: 1 c_wall violated: 1 conflicting context pair(s) with node memory, 5 node(s) had untolerated taint(s). no new claims to deallocate, preemption: 0/6 nodes are available: 1 No preemption victims found for incoming pod, 5 Preemption is not helpful for scheduling."
0.1539,Event,ADDED,eval-sanitize-1-r1-164-m2qzw.18d4a24ecec8230c,"reason=FailedScheduling count=None msg=0/6 nodes are available: 1 c_wall violated: 3 conflicting context pair(s) with node memory, 5 node(s) had untolerated taint(s). no new claims to deallocate, preemption: 0/6 nodes are available: 1 No preemption victims found for incoming pod, 5 Preemption is not helpful for scheduling."
0.1541,Event,ADDED,eval-sanitize-1-r1-164-m2qzw.18d4a2505f70da4a,"reason=FailedScheduling count=None msg=0/6 nodes are available: 1 c_wall violated: 2 conflicting context pair(s) with node memory, 5 node(s) had untolerated taint(s). no new claims to deallocate, preemption: 0/6 nodes are available: 1 No preemption victims found for incoming pod, 5 Preemption is not helpful for scheduling."
0.1543,Event,ADDED,eval-sanitize-1-r1-166-zdpnq.18d4a24ecef8637c,"reason=FailedScheduling count=None msg=0/6 nodes are available: 1 c_wall violated: 1 conflicting context pair(s) with node memory, 5 node(s) had untolerated taint(s). no new claims to deallocate, preemption: 0/6 nodes are available: 1 No preemption victims found for incoming pod, 5 Preemption is not helpful for scheduling."
0.1545,Event,ADDED,eval-sanitize-1-r1-170-gjj5w.18d4a25060324209,"reason=FailedScheduling count=None msg=0/6 nodes are available: 1 c_wall violated: 2 conflicting context pair(s) with node memory, 5 node(s) had untolerated taint(s). no new claims to deallocate, preemption: 0/6 nodes are available: 1 No preemption victims found for incoming pod, 5 Preemption is not helpful for scheduling."
0.155,Event,ADDED,eval-sanitize-1-r1-174-nzghb.18d4a250ca0134a7,"reason=FailedScheduling count=None msg=0/6 nodes are available: 1 c_wall violated: 1 conflicting context pair(s) with node memory, 5 node(s) had untolerated taint(s). no new claims to deallocate, preemption: 0/6 nodes are available: 1 No preemption victims found for incoming pod, 5 Preemption is not helpful for scheduling."
0.1552,Event,ADDED,eval-sanitize-1-r1-177-rr774.18d4a25466ce03c3,"reason=FailedScheduling count=None msg=0/6 nodes are available: 1 c_wall violated: 1 conflicting context pair(s) with node memory, 5 node(s) had untolerated taint(s). no new claims to deallocate, preemption: 0/6 nodes are available: 1 No preemption victims found for incoming pod, 5 Preemption is not helpful for scheduling."
0.1554,Event,ADDED,eval-sanitize-1-r1-196-jjtkn.18d4a2561e0ff726,"reason=FailedScheduling count=None msg=0/6 nodes are available: 1 c_wall violated: 1 conflicting context pair(s) with node memory, 1 c_wall violated: 2 conflicting context pair(s) with node memory, 4 node(s) had untolerated taint(s). no new claims to deallocate, preemption: 0/6 nodes are available: 2 No preemption victims found for incoming pod, 4 Preemption is not helpful for scheduling."
0.1558,Event,ADDED,eval-sanitize-1-r1-196-jjtkn.18d4a25641b3e82a,"reason=FailedScheduling count=None msg=0/6 nodes are available: 1 c_wall violated: 2 conflicting context pair(s) with node memory, 5 node(s) had untolerated taint(s). no new claims to deallocate, preemption: 0/6 nodes are available: 1 No preemption victims found for incoming pod, 5 Preemption is not helpful for scheduling."
0.156,Event,ADDED,eval-sanitize-1-r2-007-gqkxz.18d4a26f0041a9b1,"reason=FailedScheduling count=None msg=0/6 nodes are available: 1 c_wall violated: 2 conflicting context pair(s) with node memory, 5 node(s) had untolerated taint(s). no new claims to deallocate, preemption: 0/6 nodes are available: 1 No preemption victims found for incoming pod, 5 Preemption is not helpful for scheduling."
0.1564,Event,ADDED,eval-sanitize-1-r2-007-gqkxz.18d4a26f507c4ec2,"reason=FailedScheduling count=None msg=0/6 nodes are available: 1 c_wall violated: 2 conflicting context pair(s) with node memory, 5 node(s) had untolerated taint(s). no new claims to deallocate, preemption: 0/6 nodes are available: 1 No preemption victims found for incoming pod, 5 Preemption is not helpful for scheduling."
0.1566,Event,ADDED,eval-sanitize-1-r2-007-gqkxz.18d4a26f7ec35dd1,"reason=FailedScheduling count=None msg=0/6 nodes are available: 1 c_wall violated: 1 conflicting context pair(s) with node memory, 1 c_wall violated: 2 conflicting context pair(s) with node memory, 4 node(s) had untolerated taint(s). no new claims to deallocate, preemption: 0/6 nodes are available: 2 No preemption victims found for incoming pod, 4 Preemption is not helpful for scheduling."
0.1567,Event,ADDED,eval-sanitize-1-r2-009-6bkgh.18d4a26ef74eba40,"reason=FailedScheduling count=None msg=0/6 nodes are available: 1 c_wall violated: 1 conflicting context pair(s) with node memory, 5 node(s) had untolerated taint(s). no new claims to deallocate, preemption: 0/6 nodes are available: 1 No preemption victims found for incoming pod, 5 Preemption is not helpful for scheduling."
0.157,Event,ADDED,eval-sanitize-1-r2-009-6bkgh.18d4a26f50af207d,"reason=FailedScheduling count=None msg=0/6 nodes are available: 1 c_wall violated: 1 conflicting context pair(s) with node memory, 5 node(s) had untolerated taint(s). no new claims to deallocate, preemption: 0/6 nodes are available: 1 No preemption victims found for incoming pod, 5 Preemption is not helpful for scheduling."
0.1572,Event,ADDED,eval-sanitize-1-r2-010-9pm5k.18d4a26f01527480,"reason=FailedScheduling count=None msg=0/6 nodes are available: 1 c_wall violated: 3 conflicting context pair(s) with node memory, 5 node(s) had untolerated taint(s). no new claims to deallocate, preemption: 0/6 nodes are available: 1 No preemption victims found for incoming pod, 5 Preemption is not helpful for scheduling."
0.1574,Event,ADDED,eval-sanitize-1-r2-011-rtrl2.18d4a26f0195eeed,"reason=FailedScheduling count=None msg=0/6 nodes are available: 1 c_wall violated: 3 conflicting context pair(s) with node memory, 5 node(s) had untolerated taint(s). no new claims to deallocate, preemption: 0/6 nodes are available: 1 No preemption victims found for incoming pod, 5 Preemption is not helpful for scheduling."
0.1577,Event,ADDED,eval-sanitize-1-r2-015-s4gn8.18d4a26efa5623d2,"reason=FailedScheduling count=None msg=0/6 nodes are available: 1 c_wall violated: 2 conflicting context pair(s) with node memory, 5 node(s) had untolerated taint(s). no new claims to deallocate, preemption: 0/6 nodes are available: 1 No preemption victims found for incoming pod, 5 Preemption is not helpful for scheduling."
0.1578,Event,ADDED,eval-sanitize-1-r2-015-s4gn8.18d4a26f4d3c9ed2,"reason=FailedScheduling count=None msg=0/6 nodes are available: 1 c_wall violated: 2 conflicting context pair(s) with node memory, 5 node(s) had untolerated taint(s). no new claims to deallocate, preemption: 0/6 nodes are available: 1 No preemption victims found for incoming pod, 5 Preemption is not helpful for scheduling."
0.158,Event,ADDED,eval-sanitize-1-r2-016-scn2f.18d4a26efa8610ad,"reason=FailedScheduling count=None msg=0/6 nodes are available: 1 c_wall violated: 3 conflicting context pair(s) with node memory, 5 node(s) had untolerated taint(s). no new claims to deallocate, preemption: 0/6 nodes are available: 1 No preemption victims found for incoming pod, 5 Preemption is not helpful for scheduling."
0.1582,Event,ADDED,eval-sanitize-1-r2-019-hnhx9.18d4a26efabdceb9,"reason=FailedScheduling count=None msg=0/6 nodes are available: 1 c_wall violated: 1 conflicting context pair(s) with node memory, 5 node(s) had untolerated taint(s). no new claims to deallocate, preemption: 0/6 nodes are available: 1 No preemption victims found for incoming pod, 5 Preemption is not helpful for scheduling."
0.1585,Event,ADDED,eval-sanitize-1-r2-019-hnhx9.18d4a26f4d6bcce9,"reason=FailedScheduling count=None msg=0/6 nodes are available: 1 c_wall violated: 1 conflicting context pair(s) with node memory, 5 node(s) had untolerated taint(s). no new claims to deallocate, preemption: 0/6 nodes are available: 1 No preemption victims found for incoming pod, 5 Preemption is not helpful for scheduling."
0.1588,Event,ADDED,eval-sanitize-1-r2-020-hhd6m.18d4a26efb7b589f,"reason=FailedScheduling count=None msg=0/6 nodes are available: 1 c_wall violated: 3 conflicting context pair(s) with node memory, 5 node(s) had untolerated taint(s). no new claims to deallocate, preemption: 0/6 nodes are available: 1 No preemption victims found for incoming pod, 5 Preemption is not helpful for scheduling."
0.1591,Event,ADDED,eval-sanitize-1-r2-022-d4pvk.18d4a26efbbe70d1,"reason=FailedScheduling count=None msg=0/6 nodes are available: 1 c_wall violated: 2 conflicting context pair(s) with node memory, 5 node(s) had untolerated taint(s). no new claims to deallocate, preemption: 0/6 nodes are available: 1 No preemption victims found for incoming pod, 5 Preemption is not helpful for scheduling."
0.1593,Event,ADDED,eval-sanitize-1-r2-022-d4pvk.18d4a26f4ee91922,"reason=FailedScheduling count=None msg=0/6 nodes are available: 1 c_wall violated: 2 conflicting context pair(s) with node memory, 5 node(s) had untolerated taint(s). no new claims to deallocate, preemption: 0/6 nodes are available: 1 No preemption victims found for incoming pod, 5 Preemption is not helpful for scheduling."
0.1595,Event,ADDED,eval-sanitize-1-r2-023-mrbjr.18d4a26f00a2adbf,"reason=FailedScheduling count=None msg=0/6 nodes are available: 1 c_wall violated: 2 conflicting context pair(s) with node memory, 5 node(s) had untolerated taint(s). no new claims to deallocate, preemption: 0/6 nodes are available: 1 No preemption victims found for incoming pod, 5 Preemption is not helpful for scheduling."
0.1598,Event,ADDED,eval-sanitize-1-r2-023-mrbjr.18d4a26f50d901aa,"reason=FailedScheduling count=None msg=0/6 nodes are available: 1 c_wall violated: 2 conflicting context pair(s) with node memory, 5 node(s) had untolerated taint(s). no new claims to deallocate, preemption: 0/6 nodes are available: 1 No preemption victims found for incoming pod, 5 Preemption is not helpful for scheduling."
0.16,Event,ADDED,eval-sanitize-1-r2-023-mrbjr.18d4a26f7f0c9173,"reason=FailedScheduling count=None msg=0/6 nodes are available: 1 c_wall violated: 1 conflicting context pair(s) with node memory, 1 c_wall violated: 2 conflicting context pair(s) with node memory, 4 node(s) had untolerated taint(s). no new claims to deallocate, preemption: 0/6 nodes are available: 2 No preemption victims found for incoming pod, 4 Preemption is not helpful for scheduling."
0.1602,Event,ADDED,eval-sanitize-1-r2-028.18d4a279ef5e0d8c,reason=Completed count=1 msg=Job completed
0.1603,Event,ADDED,eval-sanitize-1-r2-029.18d4a279ef832a7c,reason=Completed count=1 msg=Job completed
0.1605,Event,ADDED,eval-sanitize-1-r2-030-knm6p.18d4a27491f94f91,"reason=FailedScheduling count=None msg=0/6 nodes are available: 1 c_wall violated: 1 conflicting context pair(s) with node memory, 5 node(s) had untolerated taint(s). no new claims to deallocate, preemption: 0/6 nodes are available: 1 No preemption victims found for incoming pod, 5 Preemption is not helpful for scheduling."
0.1607,Event,ADDED,eval-sanitize-1-r2-030-knm6p.18d4a27539bd557d,"reason=FailedScheduling count=None msg=0/6 nodes are available: 1 c_wall violated: 1 conflicting context pair(s) with node memory, 1 c_wall violated: 3 conflicting context pair(s) with node memory, 4 node(s) had untolerated taint(s). no new claims to deallocate, preemption: 0/6 nodes are available: 2 No preemption victims found for incoming pod, 4 Preemption is not helpful for scheduling."
0.1609,Event,ADDED,eval-sanitize-1-r2-030-knm6p.18d4a2754b9568b1,"reason=FailedScheduling count=None msg=0/6 nodes are available: 1 c_wall violated: 3 conflicting context pair(s) with node memory, 5 node(s) had untolerated taint(s). no new claims to deallocate, preemption: 0/6 nodes are available: 1 No preemption victims found for incoming pod, 5 Preemption is not helpful for scheduling."
0.1611,Event,ADDED,eval-sanitize-1-r2-030.18d4a27be9951c4e,reason=Completed count=1 msg=Job completed
0.1612,Event,ADDED,eval-sanitize-1-r2-031-qgk85.18d4a274922cc725,"reason=FailedScheduling count=None msg=0/6 nodes are available: 1 c_wall violated: 2 conflicting context pair(s) with node memory, 5 node(s) had untolerated taint(s). no new claims to deallocate, preemption: 0/6 nodes are available: 1 No preemption victims found for incoming pod, 5 Preemption is not helpful for scheduling."
0.1614,Event,ADDED,eval-sanitize-1-r2-031.18d4a27b9c9e312a,reason=Completed count=1 msg=Job completed
0.1616,Event,ADDED,eval-sanitize-1-r2-032-4swd9.18d4a274926025d0,"reason=FailedScheduling count=None msg=0/6 nodes are available: 1 c_wall violated: 1 conflicting context pair(s) with node memory, 5 node(s) had untolerated taint(s). no new claims to deallocate, preemption: 0/6 nodes are available: 1 No preemption victims found for incoming pod, 5 Preemption is not helpful for scheduling."
0.1618,Event,ADDED,eval-sanitize-1-r2-032.18d4a27a867e3b81,reason=Completed count=1 msg=Job completed
0.162,Event,ADDED,eval-sanitize-1-r2-033-z8r6s.18d4a274929af1e9,"reason=FailedScheduling count=None msg=0/6 nodes are available: 1 c_wall violated: 1 conflicting context pair(s) with node memory, 5 node(s) had untolerated taint(s). no new claims to deallocate, preemption: 0/6 nodes are available: 1 No preemption victims found for incoming pod, 5 Preemption is not helpful for scheduling."
0.1622,Event,ADDED,eval-sanitize-1-r2-033.18d4a27bde023beb,reason=Completed count=1 msg=Job completed
0.1625,Event,ADDED,eval-sanitize-1-r2-034-mqbqs.18d4a27496c5da65,"reason=FailedScheduling count=None msg=0/6 nodes are available: 1 c_wall violated: 2 conflicting context pair(s) with node memory, 5 node(s) had untolerated taint(s). no new claims to deallocate, preemption: 0/6 nodes are available: 1 No preemption victims found for incoming pod, 5 Preemption is not helpful for scheduling."
0.1628,Event,ADDED,eval-sanitize-1-r2-034.18d4a27b9ec8304c,reason=Completed count=1 msg=Job completed
0.163,Event,ADDED,eval-sanitize-1-r2-035.18d4a27a2a885df3,reason=Completed count=1 msg=Job completed
0.1632,Event,ADDED,eval-sanitize-1-r2-036-prlm4.18d4a27497d24135,"reason=FailedScheduling count=None msg=0/6 nodes are available: 1 c_wall violated: 1 conflicting context pair(s) with node memory, 5 node(s) had untolerated taint(s). no new claims to deallocate, preemption: 0/6 nodes are available: 1 No preemption victims found for incoming pod, 5 Preemption is not helpful for scheduling."
0.1634,Event,ADDED,eval-sanitize-1-r2-036.18d4a27bce81bf58,reason=Completed count=1 msg=Job completed
0.1637,Event,ADDED,eval-sanitize-1-r2-037-hkgzl.18d4a27498043e03,"reason=FailedScheduling count=None msg=0/6 nodes are available: 1 c_wall violated: 1 conflicting context pair(s) with node memory, 5 node(s) had untolerated taint(s). no new claims to deallocate, preemption: 0/6 nodes are available: 1 No preemption victims found for incoming pod, 5 Preemption is not helpful for scheduling."
0.1639,Event,ADDED,eval-sanitize-1-r2-037.18d4a27bde207366,reason=Completed count=1 msg=Job completed
0.1641,Event,ADDED,eval-sanitize-1-r2-038.18d4a27a2aa7e36f,reason=Completed count=1 msg=Job completed
0.1644,Event,ADDED,eval-sanitize-1-r2-039-pxsc8.18d4a2749832054d,"reason=FailedScheduling count=None msg=0/6 nodes are available: 1 c_wall violated: 2 conflicting context pair(s) with node memory, 5 node(s) had untolerated taint(s). no new claims to deallocate, preemption: 0/6 nodes are available: 1 No preemption victims found for incoming pod, 5 Preemption is not helpful for scheduling."
0.1646,Event,ADDED,eval-sanitize-1-r2-039.18d4a27bc910f140,reason=Completed count=1 msg=Job completed
0.1649,Event,ADDED,eval-sanitize-1-r2-040-8dbzf.18d4a2749870795a,"reason=FailedScheduling count=None msg=0/6 nodes are available: 1 c_wall violated: 1 conflicting context pair(s) with node memory, 5 node(s) had untolerated taint(s). no new claims to deallocate, preemption: 0/6 nodes are available: 1 No preemption victims found for incoming pod, 5 Preemption is not helpful for scheduling."
0.165,Event,ADDED,eval-sanitize-1-r2-040.18d4a27a86c48854,reason=Completed count=1 msg=Job completed
0.1654,Event,ADDED,eval-sanitize-1-r2-041-c5cqd.18d4a27498a60972,"reason=FailedScheduling count=None msg=0/6 nodes are available: 1 c_wall violated: 2 conflicting context pair(s) with node memory, 5 node(s) had untolerated taint(s). no new claims to deallocate, preemption: 0/6 nodes are available: 1 No preemption victims found for incoming pod, 5 Preemption is not helpful for scheduling."
0.1656,Event,ADDED,eval-sanitize-1-r2-041.18d4a27b9601e249,reason=Completed count=1 msg=Job completed
0.1658,Event,ADDED,eval-sanitize-1-r2-042-zlhwm.18d4a27498d291a4,"reason=FailedScheduling count=None msg=0/6 nodes are available: 1 c_wall violated: 1 conflicting context pair(s) with node memory, 5 node(s) had untolerated taint(s). no new claims to deallocate, preemption: 0/6 nodes are available: 1 No preemption victims found for incoming pod, 5 Preemption is not helpful for scheduling."
0.166,Event,ADDED,eval-sanitize-1-r2-042-zlhwm.18d4a27539655db8,"reason=FailedScheduling count=None msg=0/6 nodes are available: 1 c_wall violated: 1 conflicting context pair(s) with node memory, 1 c_wall violated: 3 conflicting context pair(s) with node memory, 4 node(s) had untolerated taint(s). no new claims to deallocate, preemption: 0/6 nodes are available: 2 No preemption victims found for incoming pod, 4 Preemption is not helpful for scheduling."
0.1662,Event,ADDED,eval-sanitize-1-r2-042-zlhwm.18d4a2754b6099a4,"reason=FailedScheduling count=None msg=0/6 nodes are available: 1 c_wall violated: 3 conflicting context pair(s) with node memory, 5 node(s) had untolerated taint(s). no new claims to deallocate, preemption: 0/6 nodes are available: 1 No preemption victims found for incoming pod, 5 Preemption is not helpful for scheduling."
0.1664,Event,ADDED,eval-sanitize-1-r2-042.18d4a27bf14d957a,reason=Completed count=1 msg=Job completed
0.1666,Event,ADDED,eval-sanitize-1-r2-043-zqfsq.18d4a2749cd23636,"reason=FailedScheduling count=None msg=0/6 nodes are available: 1 c_wall violated: 1 conflicting context pair(s) with node memory, 5 node(s) had untolerated taint(s). no new claims to deallocate, preemption: 0/6 nodes are available: 1 No preemption victims found for incoming pod, 5 Preemption is not helpful for scheduling."
0.1668,Event,ADDED,eval-sanitize-1-r2-043.18d4a27bcb7f18fb,reason=Completed count=1 msg=Job completed
0.167,Event,ADDED,eval-sanitize-1-r2-044-hkqt8.18d4a2749de687e7,"reason=FailedScheduling count=None msg=0/6 nodes are available: 1 c_wall violated: 1 conflicting context pair(s) with node memory, 5 node(s) had untolerated taint(s). no new claims to deallocate, preemption: 0/6 nodes are available: 1 No preemption victims found for incoming pod, 5 Preemption is not helpful for scheduling."
0.1671,Event,ADDED,eval-sanitize-1-r2-044.18d4a27bd599d109,reason=Completed count=1 msg=Job completed
0.1673,Event,ADDED,eval-sanitize-1-r2-045-z5p9v.18d4a2749e1a2b9c,"reason=FailedScheduling count=None msg=0/6 nodes are available: 1 c_wall violated: 1 conflicting context pair(s) with node memory, 5 node(s) had untolerated taint(s). no new claims to deallocate, preemption: 0/6 nodes are available: 1 No preemption victims found for incoming pod, 5 Preemption is not helpful for scheduling."
0.1675,Event,ADDED,eval-sanitize-1-r2-045.18d4a27b4b4a642c,reason=Completed count=1 msg=Job completed
0.1678,Event,ADDED,eval-sanitize-1-r2-046-dvkm4.18d4a2749ea1219e,"reason=FailedScheduling count=None msg=0/6 nodes are available: 1 c_wall violated: 2 conflicting context pair(s) with node memory, 5 node(s) had untolerated taint(s). no new claims to deallocate, preemption: 0/6 nodes are available: 1 No preemption victims found for incoming pod, 5 Preemption is not helpful for scheduling."
0.168,Event,ADDED,eval-sanitize-1-r2-046.18d4a27b9cb89877,reason=Completed count=1 msg=Job completed
0.1682,Event,ADDED,eval-sanitize-1-r2-047-z9nx5.18d4a2749e58ef4f,"reason=FailedScheduling count=None msg=0/6 nodes are available: 1 c_wall violated: 1 conflicting context pair(s) with node memory, 5 node(s) had untolerated taint(s). no new claims to deallocate, preemption: 0/6 nodes are available: 1 No preemption victims found for incoming pod, 5 Preemption is not helpful for scheduling."
0.1683,Event,ADDED,eval-sanitize-1-r2-047.18d4a27bbfa3bcb5,reason=Completed count=1 msg=Job completed
0.1688,Event,ADDED,eval-sanitize-1-r2-048.18d4a27a86805456,reason=Completed count=1 msg=Job completed
0.169,Event,ADDED,eval-sanitize-1-r2-049.18d4a27b83e43e98,reason=Completed count=1 msg=Job completed
0.1692,Event,ADDED,eval-sanitize-1-r2-050-d9hp6.18d4a2758e82b431,"reason=FailedScheduling count=None msg=0/6 nodes are available: 1 c_wall violated: 1 conflicting context pair(s) with node memory, 5 node(s) had untolerated taint(s). no new claims to deallocate, preemption: 0/6 nodes are available: 1 No preemption victims found for incoming pod, 5 Preemption is not helpful for scheduling."
0.1695,Event,ADDED,eval-sanitize-1-r2-050-d9hp6.18d4a27a224d3433,reason=Scheduled count=None msg=Successfully assigned compute/eval-sanitize-1-r2-050-d9hp6 to kind-worker3
0.1696,Event,ADDED,eval-sanitize-1-r2-050-d9hp6.18d4a27a3c0e0b48,"reason=Pulled count=1 msg=Container image ""busybox:musl"" already present on machine"
0.1698,Event,ADDED,eval-sanitize-1-r2-050-d9hp6.18d4a27a3d413d66,reason=Created count=1 msg=Created container: task
0.17,Event,ADDED,eval-sanitize-1-r2-050-d9hp6.18d4a27a40f9c6a1,reason=Started count=1 msg=Started container task
0.1703,Event,ADDED,eval-sanitize-1-r2-050.18d4a27fc845cc92,reason=Completed count=1 msg=Job completed
0.1705,Event,ADDED,eval-sanitize-1-r2-051-c72wk.18d4a27a228659ab,"reason=FailedScheduling count=None msg=0/6 nodes are available: 1 c_wall violated: 1 conflicting context pair(s) with node memory, 5 node(s) had untolerated taint(s). no new claims to deallocate, preemption: 0/6 nodes are available: 1 No preemption victims found for incoming pod, 5 Preemption is not helpful for scheduling."
0.1707,Event,ADDED,eval-sanitize-1-r2-051-c72wk.18d4a27a3a545159,"reason=FailedScheduling count=None msg=0/6 nodes are available: 1 c_wall violated: 1 conflicting context pair(s) with node memory, 5 node(s) had untolerated taint(s). no new claims to deallocate, preemption: 0/6 nodes are available: 1 No preemption victims found for incoming pod, 5 Preemption is not helpful for scheduling."
0.171,Event,ADDED,eval-sanitize-1-r2-051-c72wk.18d4a27a80af49b9,"reason=FailedScheduling count=None msg=0/6 nodes are available: 1 c_wall violated: 3 conflicting context pair(s) with node memory, 5 node(s) had untolerated taint(s). no new claims to deallocate, preemption: 0/6 nodes are available: 1 No preemption victims found for incoming pod, 5 Preemption is not helpful for scheduling."
0.1711,Event,ADDED,eval-sanitize-1-r2-051-c72wk.18d4a27aa6b68ffb,"reason=FailedScheduling count=None msg=0/6 nodes are available: 1 c_wall violated: 1 conflicting context pair(s) with node memory, 5 node(s) had untolerated taint(s). no new claims to deallocate, preemption: 0/6 nodes are available: 1 No preemption victims found for incoming pod, 5 Preemption is not helpful for scheduling."
0.1713,Event,ADDED,eval-sanitize-1-r2-051-c72wk.18d4a27aaba38239,"reason=FailedScheduling count=None msg=0/6 nodes are available: 1 c_wall violated: 1 conflicting context pair(s) with node memory, 5 node(s) had untolerated taint(s). no new claims to deallocate, preemption: 0/6 nodes are available: 1 No preemption victims found for incoming pod, 5 Preemption is not helpful for scheduling."
0.1715,Event,ADDED,eval-sanitize-1-r2-051-c72wk.18d4a27ac0eea04d,"reason=FailedScheduling count=None msg=0/6 nodes are available: 2 c_wall violated: 1 conflicting context pair(s) with node memory, 4 node(s) had untolerated taint(s). no new claims to deallocate, preemption: 0/6 nodes are available: 2 No preemption victims found for incoming pod, 4 Preemption is not helpful for scheduling."
0.1716,Event,ADDED,eval-sanitize-1-r2-051-c72wk.18d4a27acef359d5,reason=Scheduled count=None msg=Successfully assigned compute/eval-sanitize-1-r2-051-c72wk to kind-worker4
0.1718,Event,ADDED,eval-sanitize-1-r2-051-c72wk.18d4a27aea857430,"reason=Pulled count=1 msg=Container image ""busybox:musl"" already present on machine"
0.172,Event,ADDED,eval-sanitize-1-r2-051-c72wk.18d4a27aebe25f26,reason=Created count=1 msg=Created container: task
0.1722,Event,ADDED,eval-sanitize-1-r2-051-c72wk.18d4a27aeffdf185,reason=Started count=1 msg=Started container task
0.1723,Event,ADDED,eval-sanitize-1-r2-051.18d4a2818b2e06ed,reason=Completed count=1 msg=Job completed
0.1725,Event,ADDED,eval-sanitize-1-r2-052-fw56n.18d4a27a234af1f0,reason=Scheduled count=None msg=Successfully assigned compute/eval-sanitize-1-r2-052-fw56n to kind-worker3
0.1727,Event,ADDED,eval-sanitize-1-r2-052-fw56n.18d4a27a3faddbbc,"reason=Pulled count=1 msg=Container image ""busybox:musl"" already present on machine"
0.1728,Event,ADDED,eval-sanitize-1-r2-052-fw56n.18d4a27a410ef2f5,reason=Created count=1 msg=Created container: task
0.173,Event,ADDED,eval-sanitize-1-r2-052-fw56n.18d4a27a49c64b6e,reason=Started count=1 msg=Started container task
0.1732,Event,ADDED,eval-sanitize-1-r2-052.18d4a27fc84514c4,reason=Completed count=1 msg=Job completed
0.1733,Event,ADDED,eval-sanitize-1-r2-053-6vgfv.18d4a27a234140a8,"reason=FailedScheduling count=None msg=0/6 nodes are available: 1 c_wall violated: 2 conflicting context pair(s) with node memory, 5 node(s) had untolerated taint(s). no new claims to deallocate, preemption: 0/6 nodes are available: 1 No preemption victims found for incoming pod, 5 Preemption is not helpful for scheduling."
0.1735,Event,ADDED,eval-sanitize-1-r2-053-6vgfv.18d4a27a3a84d170,"reason=FailedScheduling count=None msg=0/6 nodes are available: 1 c_wall violated: 2 conflicting context pair(s) with node memory, 5 node(s) had untolerated taint(s). no new claims to deallocate, preemption: 0/6 nodes are available: 1 No preemption victims found for incoming pod, 5 Preemption is not helpful for scheduling."
0.1736,Event,ADDED,eval-sanitize-1-r2-053-6vgfv.18d4a27a7365ec83,reason=Scheduled count=None msg=Successfully assigned compute/eval-sanitize-1-r2-053-6vgfv to kind-worker5
0.1738,Event,ADDED,eval-sanitize-1-r2-053-6vgfv.18d4a27a8eb5257a,"reason=Pulled count=1 msg=Container image ""busybox:musl"" already present on machine"
0.174,Event,ADDED,eval-sanitize-1-r2-053-6vgfv.18d4a27a91908560,reason=Created count=1 msg=Created container: task
0.1741,Event,ADDED,eval-sanitize-1-r2-053-6vgfv.18d4a27a94128abf,reason=Started count=1 msg=Started container task
0.1744,Event,ADDED,eval-sanitize-1-r2-053.18d4a2813554bfc6,reason=Completed count=1 msg=Job completed
0.1746,Event,ADDED,eval-sanitize-1-r2-054-66ktp.18d4a27a23f3cd24,"reason=FailedScheduling count=None msg=0/6 nodes are available: 1 c_wall violated: 2 conflicting context pair(s) with node memory, 5 node(s) had untolerated taint(s). no new claims to deallocate, preemption: 0/6 nodes are available: 1 No preemption victims found for incoming pod, 5 Preemption is not helpful for scheduling."
0.1748,Event,ADDED,eval-sanitize-1-r2-054-66ktp.18d4a27a3ab72e9e,"reason=FailedScheduling count=None msg=0/6 nodes are available: 1 c_wall violated: 2 conflicting context pair(s) with node memory, 5 node(s) had untolerated taint(s). no new claims to deallocate, preemption: 0/6 nodes are available: 1 No preemption victims found for incoming pod, 5 Preemption is not helpful for scheduling."
0.175,Event,ADDED,eval-sanitize-1-r2-054-66ktp.18d4a27aa008b4e4,reason=Scheduled count=None msg=Successfully assigned compute/eval-sanitize-1-r2-054-66ktp to kind-worker
0.1752,Event,ADDED,eval-sanitize-1-r2-054-66ktp.18d4a27ac00b1abd,"reason=Pulled count=1 msg=Container image ""busybox:musl"" already present on machine"
0.1754,Event,ADDED,eval-sanitize-1-r2-054-66ktp.18d4a27ac2d4cf66,reason=Created count=1 msg=Created container: task
0.1757,Event,ADDED,eval-sanitize-1-r2-054-66ktp.18d4a27ac833190b,reason=Started count=1 msg=Started container task
0.1758,Event,ADDED,eval-sanitize-1-r2-054.18d4a28191c3dcb6,reason=Completed count=1 msg=Job completed
0.176,Event,ADDED,eval-sanitize-1-r2-055-j5v7t.18d4a27a26206f58,"reason=FailedScheduling count=None msg=0/6 nodes are available: 1 c_wall violated: 1 conflicting context pair(s) with node memory, 5 node(s) had untolerated taint(s). no new claims to deallocate, preemption: 0/6 nodes are available: 1 No preemption victims found for incoming pod, 5 Preemption is not helpful for scheduling."
0.1762,Event,ADDED,eval-sanitize-1-r2-055-j5v7t.18d4a27a3ae62e2e,"reason=FailedScheduling count=None msg=0/6 nodes are available: 1 c_wall violated: 1 conflicting context pair(s) with node memory, 5 node(s) had untolerated taint(s). no new claims to deallocate, preemption: 0/6 nodes are available: 1 No preemption victims found for incoming pod, 5 Preemption is not helpful for scheduling."
0.1764,Event,ADDED,eval-sanitize-1-r2-055-j5v7t.18d4a27a821f1380,"reason=FailedScheduling count=None msg=0/6 nodes are available: 1 c_wall violated: 2 conflicting context pair(s) with node memory, 5 node(s) had untolerated taint(s). no new claims to deallocate, preemption: 0/6 nodes are available: 1 No preemption victims found for incoming pod, 5 Preemption is not helpful for scheduling."
0.1765,Event,ADDED,eval-sanitize-1-r2-055-j5v7t.18d4a27aa0c730e1,reason=Scheduled count=None msg=Successfully assigned compute/eval-sanitize-1-r2-055-j5v7t to kind-worker
0.1768,Event,ADDED,eval-sanitize-1-r2-055-j5v7t.18d4a27ac027a865,"reason=Pulled count=1 msg=Container image ""busybox:musl"" already present on machine"
0.1769,Event,ADDED,eval-sanitize-1-r2-055-j5v7t.18d4a27ac35750d4,reason=Created count=1 msg=Created container: task
0.1771,Event,ADDED,eval-sanitize-1-r2-055-j5v7t.18d4a27ac8333351,reason=Started count=1 msg=Started container task
0.1774,Event,ADDED,eval-sanitize-1-r2-055.18d4a281756b95d4,reason=Completed count=1 msg=Job completed
0.1776,Event,ADDED,eval-sanitize-1-r2-056-pgjd4.18d4a27a274d2578,"reason=FailedScheduling count=None msg=0/6 nodes are available: 1 c_wall violated: 1 conflicting context pair(s) with node memory, 5 node(s) had untolerated taint(s). no new claims to deallocate, preemption: 0/6 nodes are available: 1 No preemption victims found for incoming pod, 5 Preemption is not helpful for scheduling."
0.1778,Event,ADDED,eval-sanitize-1-r2-056-pgjd4.18d4a27a3b0f8c26,"reason=FailedScheduling count=None msg=0/6 nodes are available: 1 c_wall violated: 1 conflicting context pair(s) with node memory, 5 node(s) had untolerated taint(s). no new claims to deallocate, preemption: 0/6 nodes are available: 1 No preemption victims found for incoming pod, 5 Preemption is not helpful for scheduling."
0.1779,Event,ADDED,eval-sanitize-1-r2-056-pgjd4.18d4a27a76d9f88a,reason=Scheduled count=None msg=Successfully assigned compute/eval-sanitize-1-r2-056-pgjd4 to kind-worker5
0.1782,Event,ADDED,eval-sanitize-1-r2-056-pgjd4.18d4a27a91aa8e0c,"reason=Pulled count=1 msg=Container image ""busybox:musl"" already present on machine"
0.1784,Event,ADDED,eval-sanitize-1-r2-056-pgjd4.18d4a27a939ac52a,reason=Created count=1 msg=Created container: task
0.1786,Event,ADDED,eval-sanitize-1-r2-056-pgjd4.18d4a27a9619f385,reason=Started count=1 msg=Started container task
0.179,Event,ADDED,eval-sanitize-1-r2-056.18d4a27fe4325d5e,reason=Completed count=1 msg=Job completed
0.1792,Event,ADDED,eval-sanitize-1-r2-057-cn25z.18d4a27a285c7986,"reason=FailedScheduling count=None msg=0/6 nodes are available: 1 c_wall violated: 1 conflicting context pair(s) with node memory, 5 node(s) had untolerated taint(s). no new claims to deallocate, preemption: 0/6 nodes are available: 1 No preemption victims found for incoming pod, 5 Preemption is not helpful for scheduling."
0.1794,Event,ADDED,eval-sanitize-1-r2-057-cn25z.18d4a27a3b51f79a,"reason=FailedScheduling count=None msg=0/6 nodes are available: 1 c_wall violated: 1 conflicting context pair(s) with node memory, 5 node(s) had untolerated taint(s). no new claims to deallocate, preemption: 0/6 nodes are available: 1 No preemption victims found for incoming pod, 5 Preemption is not helpful for scheduling."
0.1796,Event,ADDED,eval-sanitize-1-r2-057-cn25z.18d4a27a8255541d,"reason=FailedScheduling count=None msg=0/6 nodes are available: 1 c_wall violated: 2 conflicting context pair(s) with node memory, 5 node(s) had untolerated taint(s). no new claims to deallocate, preemption: 0/6 nodes are available: 1 No preemption victims found for incoming pod, 5 Preemption is not helpful for scheduling."
0.1798,Event,ADDED,eval-sanitize-1-r2-057-cn25z.18d4a27a8e3ebb63,reason=Scheduled count=None msg=Successfully assigned compute/eval-sanitize-1-r2-057-cn25z to kind-worker
0.18,Event,ADDED,eval-sanitize-1-r2-057-cn25z.18d4a27aaa4d35e8,"reason=Pulled count=1 msg=Container image ""busybox:musl"" already present on machine"
0.1801,Event,ADDED,eval-sanitize-1-r2-057-cn25z.18d4a27aac290234,reason=Created count=1 msg=Created container: task
0.1805,Event,ADDED,eval-sanitize-1-r2-057-cn25z.18d4a27ab52840f2,reason=Started count=1 msg=Started container task
0.1806,Event,ADDED,eval-sanitize-1-r2-057.18d4a280fd674ad4,reason=Completed count=1 msg=Job completed
0.1808,Event,ADDED,eval-sanitize-1-r2-058-4rp4s.18d4a27a2bddf44b,"reason=FailedScheduling count=None msg=0/6 nodes are available: 1 c_wall violated: 2 conflicting context pair(s) with node memory, 5 node(s) had untolerated taint(s). no new claims to deallocate, preemption: 0/6 nodes are available: 1 No preemption victims found for incoming pod, 5 Preemption is not helpful for scheduling."
0.1812,Event,ADDED,eval-sanitize-1-r2-058-4rp4s.18d4a27a403dfb82,"reason=FailedScheduling count=None msg=0/6 nodes are available: 1 c_wall violated: 2 conflicting context pair(s) with node memory, 5 node(s) had untolerated taint(s). no new claims to deallocate, preemption: 0/6 nodes are available: 1 No preemption victims found for incoming pod, 5 Preemption is not helpful for scheduling."
0.1813,Event,ADDED,eval-sanitize-1-r2-058-4rp4s.18d4a27a77d217c3,reason=Scheduled count=None msg=Successfully assigned compute/eval-sanitize-1-r2-058-4rp4s to kind-worker5
0.1815,Event,ADDED,eval-sanitize-1-r2-058-4rp4s.18d4a27a93a3309a,"reason=Pulled count=1 msg=Container image ""busybox:musl"" already present on machine"
0.1817,Event,ADDED,eval-sanitize-1-r2-058-4rp4s.18d4a27a950c9e4d,reason=Created count=1 msg=Created container: task
0.182,Event,ADDED,eval-sanitize-1-r2-058-4rp4s.18d4a27a970c5509,reason=Started count=1 msg=Started container task
0.1822,Event,ADDED,eval-sanitize-1-r2-058.18d4a2814a3d3541,reason=Completed count=1 msg=Job completed
0.1824,Event,ADDED,eval-sanitize-1-r2-059-s2rln.18d4a27a2c70d813,"reason=FailedScheduling count=None msg=0/6 nodes are available: 1 c_wall violated: 1 conflicting context pair(s) with node memory, 5 node(s) had untolerated taint(s). no new claims to deallocate, preemption: 0/6 nodes are available: 1 No preemption victims found for incoming pod, 5 Preemption is not helpful for scheduling."
0.1827,Event,ADDED,eval-sanitize-1-r2-059-s2rln.18d4a27a4076b321,"reason=FailedScheduling count=None msg=0/6 nodes are available: 1 c_wall violated: 1 conflicting context pair(s) with node memory, 5 node(s) had untolerated taint(s). no new claims to deallocate, preemption: 0/6 nodes are available: 1 No preemption victims found for incoming pod, 5 Preemption is not helpful for scheduling."
0.1828,Event,ADDED,eval-sanitize-1-r2-059-s2rln.18d4a27a5e98b40b,reason=Scheduled count=None msg=Successfully assigned compute/eval-sanitize-1-r2-059-s2rln to kind-worker5
0.183,Event,ADDED,eval-sanitize-1-r2-059-s2rln.18d4a27a8460e397,"reason=Pulled count=1 msg=Container image ""busybox:musl"" already present on machine"
0.1832,Event,ADDED,eval-sanitize-1-r2-059-s2rln.18d4a27a862f513c,reason=Created count=1 msg=Created container: task
0.1834,Event,ADDED,eval-sanitize-1-r2-059-s2rln.18d4a27a8ad49028,reason=Started count=1 msg=Started container task
0.1835,Event,ADDED,eval-sanitize-1-r2-059.18d4a2815335cd4a,reason=Completed count=1 msg=Job completed
0.1837,Event,ADDED,eval-sanitize-1-r2-060-4t8dg.18d4a27a2d0bbf3d,"reason=FailedScheduling count=None msg=0/6 nodes are available: 1 c_wall violated: 2 conflicting context pair(s) with node memory, 5 node(s) had untolerated taint(s). no new claims to deallocate, preemption: 0/6 nodes are available: 1 No preemption victims found for incoming pod, 5 Preemption is not helpful for scheduling."
0.1839,Event,ADDED,eval-sanitize-1-r2-060-4t8dg.18d4a27a40b0ae52,"reason=FailedScheduling count=None msg=0/6 nodes are available: 1 c_wall violated: 2 conflicting context pair(s) with node memory, 5 node(s) had untolerated taint(s). no new claims to deallocate, preemption: 0/6 nodes are available: 1 No preemption victims found for incoming pod, 5 Preemption is not helpful for scheduling."
0.1841,Event,ADDED,eval-sanitize-1-r2-060-4t8dg.18d4a27a77ad3e63,"reason=FailedScheduling count=None msg=0/6 nodes are available: 1 c_wall violated: 2 conflicting context pair(s) with node memory, 5 node(s) had untolerated taint(s). no new claims to deallocate, preemption: 0/6 nodes are available: 1 No preemption victims found for incoming pod, 5 Preemption is not helpful for scheduling."
0.1842,Event,ADDED,eval-sanitize-1-r2-060-4t8dg.18d4a27a829444db,"reason=FailedScheduling count=None msg=0/6 nodes are available: 1 c_wall violated: 2 conflicting context pair(s) with node memory, 5 node(s) had untolerated taint(s). no new claims to deallocate, preemption: 0/6 nodes are available: 1 No preemption victims found for incoming pod, 5 Preemption is not helpful for scheduling."
0.1844,Event,ADDED,eval-sanitize-1-r2-060-4t8dg.18d4a27a8e942167,reason=Scheduled count=None msg=Successfully assigned compute/eval-sanitize-1-r2-060-4t8dg to kind-worker
0.1845,Event,ADDED,eval-sanitize-1-r2-060-4t8dg.18d4a27aaa8a2e4e,"reason=Pulled count=1 msg=Container image ""busybox:musl"" already present on machine"
0.1847,Event,ADDED,eval-sanitize-1-r2-060-4t8dg.18d4a27aacb398dd,reason=Created count=1 msg=Created container: task
0.1849,Event,ADDED,eval-sanitize-1-r2-060-4t8dg.18d4a27ab5266f37,reason=Started count=1 msg=Started container task
0.185,Event,ADDED,eval-sanitize-1-r2-060.18d4a28182fb7b66,reason=Completed count=1 msg=Job completed
0.1852,Event,ADDED,eval-sanitize-1-r2-061-g8jzf.18d4a277cea9a9e0,"reason=FailedScheduling count=None msg=0/6 nodes are available: 6 node(s) had untolerated taint(s). no new claims to deallocate, preemption: 0/6 nodes are available: 6 Preemption is not helpful for scheduling."
0.1854,Event,ADDED,eval-sanitize-1-r2-061-g8jzf.18d4a27a2de1b119,"reason=FailedScheduling count=None msg=0/6 nodes are available: 1 c_wall violated: 2 conflicting context pair(s) with node memory, 5 node(s) had untolerated taint(s). no new claims to deallocate, preemption: 0/6 nodes are available: 1 No preemption victims found for incoming pod, 5 Preemption is not helpful for scheduling."
0.1856,Event,ADDED,eval-sanitize-1-r2-061-g8jzf.18d4a27a40e2fd5c,"reason=FailedScheduling count=None msg=0/6 nodes are available: 1 c_wall violated: 2 conflicting context pair(s) with node memory, 5 node(s) had untolerated taint(s). no new claims to deallocate, preemption: 0/6 nodes are available: 1 No preemption victims found for incoming pod, 5 Preemption is not helpful for scheduling."
0.1857,Event,ADDED,eval-sanitize-1-r2-061-g8jzf.18d4a27a644553dd,reason=Scheduled count=None msg=Successfully assigned compute/eval-sanitize-1-r2-061-g8jzf to kind-worker5
0.1859,Event,ADDED,eval-sanitize-1-r2-061-g8jzf.18d4a27a86fcc0ab,"reason=Pulled count=1 msg=Container image ""busybox:musl"" already present on machine"
0.1861,Event,ADDED,eval-sanitize-1-r2-061-g8jzf.18d4a27a892fb0f1,reason=Created count=1 msg=Created container: task
0.1863,Event,ADDED,eval-sanitize-1-r2-061-g8jzf.18d4a27a8b8054d4,reason=Started count=1 msg=Started container task
0.1864,Event,ADDED,eval-sanitize-1-r2-061.18d4a277ce9cb4da,reason=SuccessfulCreate count=1 msg=Created pod: eval-sanitize-1-r2-061-g8jzf
0.1866,Event,ADDED,eval-sanitize-1-r2-061.18d4a27fe4343083,reason=Completed count=1 msg=Job completed
0.1868,Event,ADDED,eval-sanitize-1-r2-062-mnmcg.18d4a278096240bf,"reason=FailedScheduling count=None msg=0/6 nodes are available: 6 node(s) had untolerated taint(s). no new claims to deallocate, preemption: 0/6 nodes are available: 6 Preemption is not helpful for scheduling."
0.1869,Event,ADDED,eval-sanitize-1-r2-062-mnmcg.18d4a27a2ed92c4a,reason=Scheduled count=None msg=Successfully assigned compute/eval-sanitize-1-r2-062-mnmcg to kind-worker3
0.1872,Event,ADDED,eval-sanitize-1-r2-062-mnmcg.18d4a27a4eae3b65,"reason=Pulled count=1 msg=Container image ""busybox:musl"" already present on machine"
0.1874,Event,ADDED,eval-sanitize-1-r2-062-mnmcg.18d4a27a4fbb217f,reason=Created count=1 msg=Created container: task
0.1875,Event,ADDED,eval-sanitize-1-r2-062-mnmcg.18d4a27a533daed7,reason=Started count=1 msg=Started container task
0.1877,Event,ADDED,eval-sanitize-1-r2-062.18d4a27809555074,reason=SuccessfulCreate count=1 msg=Created pod: eval-sanitize-1-r2-062-mnmcg
0.1879,Event,ADDED,eval-sanitize-1-r2-062.18d4a27fc8146d0f,reason=Completed count=1 msg=Job completed
0.1881,Event,ADDED,eval-sanitize-1-r2-063-h4ccr.18d4a27845f03e03,"reason=FailedScheduling count=None msg=0/6 nodes are available: 6 node(s) had untolerated taint(s). no new claims to deallocate, preemption: 0/6 nodes are available: 6 Preemption is not helpful for scheduling."
0.1882,Event,ADDED,eval-sanitize-1-r2-063-h4ccr.18d4a27a2e9cb05f,"reason=FailedScheduling count=None msg=0/6 nodes are available: 1 c_wall violated: 2 conflicting context pair(s) with node memory, 5 node(s) had untolerated taint(s). no new claims to deallocate, preemption: 0/6 nodes are available: 1 No preemption victims found for incoming pod, 5 Preemption is not helpful for scheduling."
0.1884,Event,ADDED,eval-sanitize-1-r2-063-h4ccr.18d4a27a411286e4,"reason=FailedScheduling count=None msg=0/6 nodes are available: 1 c_wall violated: 2 conflicting context pair(s) with node memory, 5 node(s) had untolerated taint(s). no new claims to deallocate, preemption: 0/6 nodes are available: 1 No preemption victims found for incoming pod, 5 Preemption is not helpful for scheduling."
0.1886,Event,ADDED,eval-sanitize-1-r2-063-h4ccr.18d4a27a7bcaee79,"reason=FailedScheduling count=None msg=0/6 nodes are available: 1 c_wall violated: 1 conflicting context pair(s) with node memory, 5 node(s) had untolerated taint(s). no new claims to deallocate, preemption: 0/6 nodes are available: 1 No preemption victims found for incoming pod, 5 Preemption is not helpful for scheduling."
0.1888,Event,ADDED,eval-sanitize-1-r2-063-h4ccr.18d4a27a82c00599,"reason=FailedScheduling count=None msg=0/6 nodes are available: 1 c_wall violated: 1 conflicting context pair(s) with node memory, 5 node(s) had untolerated taint(s). no new claims to deallocate, preemption: 0/6 nodes are available: 1 No preemption victims found for incoming pod, 5 Preemption is not helpful for scheduling."
0.189,Event,ADDED,eval-sanitize-1-r2-063-h4ccr.18d4a27aa5a22291,"reason=FailedScheduling count=None msg=0/6 nodes are available: 2 c_wall violated: 1 conflicting context pair(s) with node memory, 4 node(s) had untolerated taint(s). no new claims to deallocate, preemption: 0/6 nodes are available: 2 No preemption victims found for incoming pod, 4 Preemption is not helpful for scheduling."
0.1892,Event,ADDED,eval-sanitize-1-r2-063-h4ccr.18d4a27aabcbd864,"reason=FailedScheduling count=None msg=0/6 nodes are available: 1 c_wall violated: 1 conflicting context pair(s) with node memory, 5 node(s) had untolerated taint(s). no new claims to deallocate, preemption: 0/6 nodes are available: 1 No preemption victims found for incoming pod, 5 Preemption is not helpful for scheduling."
0.1894,Event,ADDED,eval-sanitize-1-r2-063-h4ccr.18d4a27ac1428ac0,reason=Scheduled count=None msg=Successfully assigned compute/eval-sanitize-1-r2-063-h4ccr to kind-worker2
0.1896,Event,ADDED,eval-sanitize-1-r2-063-h4ccr.18d4a27add570c7d,"reason=Pulled count=1 msg=Container image ""busybox:musl"" already present on machine"
0.1897,Event,ADDED,eval-sanitize-1-r2-063-h4ccr.18d4a27adf26523e,reason=Created count=1 msg=Created container: task
0.1899,Event,ADDED,eval-sanitize-1-r2-063-h4ccr.18d4a27ae32470c3,reason=Started count=1 msg=Started container task
0.1901,Event,ADDED,eval-sanitize-1-r2-063.18d4a27845e57af3,reason=SuccessfulCreate count=1 msg=Created pod: eval-sanitize-1-r2-063-h4ccr
0.1902,Event,ADDED,eval-sanitize-1-r2-063.18d4a281625d71af,reason=Completed count=1 msg=Job completed
0.1905,Event,ADDED,eval-sanitize-1-r2-064-47vfp.18d4a278808b7e70,"reason=FailedScheduling count=None msg=0/6 nodes are available: 6 node(s) had untolerated taint(s). no new claims to deallocate, preemption: 0/6 nodes are available: 6 Preemption is not helpful for scheduling."
0.1907,Event,ADDED,eval-sanitize-1-r2-064-47vfp.18d4a27a31d41dc4,"reason=FailedScheduling count=None msg=0/6 nodes are available: 1 c_wall violated: 1 conflicting context pair(s) with node memory, 5 node(s) had untolerated taint(s). no new claims to deallocate, preemption: 0/6 nodes are available: 1 No preemption victims found for incoming pod, 5 Preemption is not helpful for scheduling."
0.1909,Event,ADDED,eval-sanitize-1-r2-064-47vfp.18d4a27a4142c7c3,"reason=FailedScheduling count=None msg=0/6 nodes are available: 1 c_wall violated: 1 conflicting context pair(s) with node memory, 5 node(s) had untolerated taint(s). no new claims to deallocate, preemption: 0/6 nodes are available: 1 No preemption victims found for incoming pod, 5 Preemption is not helpful for scheduling."
0.1911,Event,ADDED,eval-sanitize-1-r2-064-47vfp.18d4a27a6a3cd7a8,reason=Scheduled count=None msg=Successfully assigned compute/eval-sanitize-1-r2-064-47vfp to kind-worker5
0.1913,Event,ADDED,eval-sanitize-1-r2-064-47vfp.18d4a27a840f4f33,"reason=Pulled count=1 msg=Container image ""busybox:musl"" already present on machine"
0.1914,Event,ADDED,eval-sanitize-1-r2-064-47vfp.18d4a27a8599348a,reason=Created count=1 msg=Created container: task
0.1916,Event,ADDED,eval-sanitize-1-r2-064-47vfp.18d4a27a8a8839f2,reason=Started count=1 msg=Started container task
0.1918,Event,ADDED,eval-sanitize-1-r2-064.18d4a27880828659,reason=SuccessfulCreate count=1 msg=Created pod: eval-sanitize-1-r2-064-47vfp
0.192,Event,ADDED,eval-sanitize-1-r2-064.18d4a28142de5f29,reason=Completed count=1 msg=Job completed
0.1921,Event,ADDED,eval-sanitize-1-r2-065-mdh2v.18d4a278bbed9e48,"reason=FailedScheduling count=None msg=0/6 nodes are available: 6 node(s) had untolerated taint(s). no new claims to deallocate, preemption: 0/6 nodes are available: 6 Preemption is not helpful for scheduling."
0.1923,Event,ADDED,eval-sanitize-1-r2-065-mdh2v.18d4a27a347bbbe5,"reason=FailedScheduling count=None msg=0/6 nodes are available: 1 c_wall violated: 2 conflicting context pair(s) with node memory, 5 node(s) had untolerated taint(s). no new claims to deallocate, preemption: 0/6 nodes are available: 1 No preemption victims found for incoming pod, 5 Preemption is not helpful for scheduling."
0.1925,Event,ADDED,eval-sanitize-1-r2-065-mdh2v.18d4a27a46378537,"reason=FailedScheduling count=None msg=0/6 nodes are available: 1 c_wall violated: 2 conflicting context pair(s) with node memory, 5 node(s) had untolerated taint(s). no new claims to deallocate, preemption: 0/6 nodes are available: 1 No preemption victims found for incoming pod, 5 Preemption is not helpful for scheduling."
0.1927,Event,ADDED,eval-sanitize-1-r2-065-mdh2v.18d4a27a7c5cdbc4,"reason=FailedScheduling count=None msg=0/6 nodes are available: 1 c_wall violated: 2 conflicting context pair(s) with node memory, 5 node(s) had untolerated taint(s). no new claims to deallocate, preemption: 0/6 nodes are available: 1 No preemption victims found for incoming pod, 5 Preemption is not helpful for scheduling."
0.1928,Event,ADDED,eval-sanitize-1-r2-065-mdh2v.18d4a27a87c3f2e6,"reason=FailedScheduling count=None msg=0/6 nodes are available: 1 c_wall violated: 2 conflicting context pair(s) with node memory, 5 node(s) had untolerated taint(s). no new claims to deallocate, preemption: 0/6 nodes are available: 1 No preemption victims found for incoming pod, 5 Preemption is not helpful for scheduling."
0.193,Event,ADDED,eval-sanitize-1-r2-065-mdh2v.18d4a27a9447d871,reason=Scheduled count=None msg=Successfully assigned compute/eval-sanitize-1-r2-065-mdh2v to kind-worker
0.1932,Event,ADDED,eval-sanitize-1-r2-065-mdh2v.18d4a27ab52c98a1,"reason=Pulled count=1 msg=Container image ""busybox:musl"" already present on machine"
0.1933,Event,ADDED,eval-sanitize-1-r2-065-mdh2v.18d4a27ab8236ef5,reason=Created count=1 msg=Created container: task
0.1935,Event,ADDED,eval-sanitize-1-r2-065-mdh2v.18d4a27abfffab7e,reason=Started count=1 msg=Started container task
0.1937,Event,ADDED,eval-sanitize-1-r2-065.18d4a278bbe2ad9e,reason=SuccessfulCreate count=1 msg=Created pod: eval-sanitize-1-r2-065-mdh2v
0.1938,Event,ADDED,eval-sanitize-1-r2-065.18d4a281757e2161,reason=Completed count=1 msg=Job completed
0.194,Event,ADDED,eval-sanitize-1-r2-066-vthn7.18d4a278f7a110df,"reason=FailedScheduling count=None msg=0/6 nodes are available: 6 node(s) had untolerated taint(s). no new claims to deallocate, preemption: 0/6 nodes are available: 6 Preemption is not helpful for scheduling."
0.1943,Event,ADDED,eval-sanitize-1-r2-066-vthn7.18d4a27a34f3a913,"reason=FailedScheduling count=None msg=0/6 nodes are available: 1 c_wall violated: 2 conflicting context pair(s) with node memory, 5 node(s) had untolerated taint(s). no new claims to deallocate, preemption: 0/6 nodes are available: 1 No preemption victims found for incoming pod, 5 Preemption is not helpful for scheduling."
0.1946,Event,ADDED,eval-sanitize-1-r2-066-vthn7.18d4a27a46616362,"reason=FailedScheduling count=None msg=0/6 nodes are available: 1 c_wall violated: 2 conflicting context pair(s) with node memory, 5 node(s) had untolerated taint(s). no new claims to deallocate, preemption: 0/6 nodes are available: 1 No preemption victims found for incoming pod, 5 Preemption is not helpful for scheduling."
0.1949,Event,ADDED,eval-sanitize-1-r2-066-vthn7.18d4a27a7cd973a3,"reason=FailedScheduling count=None msg=0/6 nodes are available: 1 c_wall violated: 1 conflicting context pair(s) with node memory, 5 node(s) had untolerated taint(s). no new claims to deallocate, preemption: 0/6 nodes are available: 1 No preemption victims found for incoming pod, 5 Preemption is not helpful for scheduling."
0.195,Event,ADDED,eval-sanitize-1-r2-066-vthn7.18d4a27aa5cd3b08,"reason=FailedScheduling count=None msg=0/6 nodes are available: 1 c_wall violated: 1 conflicting context pair(s) with node memory, 5 node(s) had untolerated taint(s). no new claims to deallocate, preemption: 0/6 nodes are available: 1 No preemption victims found for incoming pod, 5 Preemption is not helpful for scheduling."
0.1952,Event,ADDED,eval-sanitize-1-r2-066-vthn7.18d4a27aa7e92ee7,"reason=FailedScheduling count=None msg=0/6 nodes are available: 1 c_wall violated: 1 conflicting context pair(s) with node memory, 5 node(s) had untolerated taint(s). no new claims to deallocate, preemption: 0/6 nodes are available: 1 No preemption victims found for incoming pod, 5 Preemption is not helpful for scheduling."
0.1954,Event,ADDED,eval-sanitize-1-r2-066-vthn7.18d4a27abffb1e5e,reason=Scheduled count=None msg=Successfully assigned compute/eval-sanitize-1-r2-066-vthn7 to kind-worker2
0.1957,Event,ADDED,eval-sanitize-1-r2-066-vthn7.18d4a27adc4c9d03,"reason=Pulled count=1 msg=Container image ""busybox:musl"" already present on machine"
0.1959,Event,ADDED,eval-sanitize-1-r2-066-vthn7.18d4a27adde1b71f,reason=Created count=1 msg=Created container: task
0.196,Event,ADDED,eval-sanitize-1-r2-066-vthn7.18d4a27ae2695760,reason=Started count=1 msg=Started container task
0.1963,Event,ADDED,eval-sanitize-1-r2-066.18d4a278f7945e06,reason=SuccessfulCreate count=1 msg=Created pod: eval-sanitize-1-r2-066-vthn7
0.1965,Event,ADDED,eval-sanitize-1-r2-066.18d4a281ae932445,reason=Completed count=1 msg=Job completed
0.1966,Event,ADDED,eval-sanitize-1-r2-067-j9px8.18d4a2793400913b,"reason=FailedScheduling count=None msg=0/6 nodes are available: 6 node(s) had untolerated taint(s). no new claims to deallocate, preemption: 0/6 nodes are available: 6 Preemption is not helpful for scheduling."
0.1968,Event,ADDED,eval-sanitize-1-r2-067-j9px8.18d4a27a356d8a19,"reason=FailedScheduling count=None msg=0/6 nodes are available: 1 c_wall violated: 1 conflicting context pair(s) with node memory, 5 node(s) had untolerated taint(s). no new claims to deallocate, preemption: 0/6 nodes are available: 1 No preemption victims found for incoming pod, 5 Preemption is not helpful for scheduling."
0.1971,Event,ADDED,eval-sanitize-1-r2-067-j9px8.18d4a27a4688edac,"reason=FailedScheduling count=None msg=0/6 nodes are available: 1 c_wall violated: 1 conflicting context pair(s) with node memory, 5 node(s) had untolerated taint(s). no new claims to deallocate, preemption: 0/6 nodes are available: 1 No preemption victims found for incoming pod, 5 Preemption is not helpful for scheduling."
0.1973,Event,ADDED,eval-sanitize-1-r2-067-j9px8.18d4a27a6e6f6285,reason=Scheduled count=None msg=Successfully assigned compute/eval-sanitize-1-r2-067-j9px8 to kind-worker5
0.1974,Event,ADDED,eval-sanitize-1-r2-067-j9px8.18d4a27a8afd9cd4,"reason=Pulled count=1 msg=Container image ""busybox:musl"" already present on machine"
0.1976,Event,ADDED,eval-sanitize-1-r2-067-j9px8.18d4a27a8d85d1da,reason=Created count=1 msg=Created container: task
0.1978,Event,ADDED,eval-sanitize-1-r2-067-j9px8.18d4a27a9091a020,reason=Started count=1 msg=Started container task
0.198,Event,ADDED,eval-sanitize-1-r2-067.18d4a27933f6a865,reason=SuccessfulCreate count=1 msg=Created pod: eval-sanitize-1-r2-067-j9px8
0.1981,Event,ADDED,eval-sanitize-1-r2-067.18d4a28142db97d7,reason=Completed count=1 msg=Job completed
0.1983,Event,ADDED,eval-sanitize-1-r2-068-dv967.18d4a279738b9264,"reason=FailedScheduling count=None msg=0/6 nodes are available: 6 node(s) had untolerated taint(s). no new claims to deallocate, preemption: 0/6 nodes are available: 6 Preemption is not helpful for scheduling."
0.1984,Event,ADDED,eval-sanitize-1-r2-068-dv967.18d4a27a35f2d237,"reason=FailedScheduling count=None msg=0/6 nodes are available: 1 c_wall violated: 2 conflicting context pair(s) with node memory, 5 node(s) had untolerated taint(s). no new claims to deallocate, preemption: 0/6 nodes are available: 1 No preemption victims found for incoming pod, 5 Preemption is not helpful for scheduling."
0.1986,Event,ADDED,eval-sanitize-1-r2-068-dv967.18d4a27a46b507cb,"reason=FailedScheduling count=None msg=0/6 nodes are available: 1 c_wall violated: 2 conflicting context pair(s) with node memory, 5 node(s) had untolerated taint(s). no new claims to deallocate, preemption: 0/6 nodes are available: 1 No preemption victims found for incoming pod, 5 Preemption is not helpful for scheduling."
0.1989,Event,ADDED,eval-sanitize-1-r2-068-dv967.18d4a27a7d1c646d,"reason=FailedScheduling count=None msg=0/6 nodes are available: 1 c_wall violated: 1 conflicting context pair(s) with node memory, 5 node(s) had untolerated taint(s). no new claims to deallocate, preemption: 0/6 nodes are available: 1 No preemption victims found for incoming pod, 5 Preemption is not helpful for scheduling."
0.199,Event,ADDED,eval-sanitize-1-r2-068-dv967.18d4a27aa63f3587,"reason=FailedScheduling count=None msg=0/6 nodes are available: 1 c_wall violated: 1 conflicting context pair(s) with node memory, 5 node(s) had untolerated taint(s). no new claims to deallocate, preemption: 0/6 nodes are available: 1 No preemption victims found for incoming pod, 5 Preemption is not helpful for scheduling."
0.1992,Event,ADDED,eval-sanitize-1-r2-068-dv967.18d4a27aab6de0f9,"reason=FailedScheduling count=None msg=0/6 nodes are available: 1 c_wall violated: 1 conflicting context pair(s) with node memory, 5 node(s) had untolerated taint(s). no new claims to deallocate, preemption: 0/6 nodes are available: 1 No preemption victims found for incoming pod, 5 Preemption is not helpful for scheduling."
0.1995,Event,ADDED,eval-sanitize-1-r2-068-dv967.18d4a27ac02697f5,reason=Scheduled count=None msg=Successfully assigned compute/eval-sanitize-1-r2-068-dv967 to kind-worker2
0.1996,Event,ADDED,eval-sanitize-1-r2-068-dv967.18d4a27add4164a7,"reason=Pulled count=1 msg=Container image ""busybox:musl"" already present on machine"
0.1999,Event,ADDED,eval-sanitize-1-r2-068-dv967.18d4a27adedc04ff,reason=Created count=1 msg=Created container: task
0.2001,Event,ADDED,eval-sanitize-1-r2-068-dv967.18d4a27ae3247ea7,reason=Started count=1 msg=Started container task
0.2004,Event,ADDED,eval-sanitize-1-r2-068.18d4a2797391e823,reason=SuccessfulCreate count=1 msg=Created pod: eval-sanitize-1-r2-068-dv967
0.2006,Event,ADDED,eval-sanitize-1-r2-068.18d4a281b06ea6ec,reason=Completed count=1 msg=Job completed
0.2008,Event,ADDED,eval-sanitize-1-r2-069-7wt98.18d4a279aa84fd45,"reason=FailedScheduling count=None msg=0/6 nodes are available: 6 node(s) had untolerated taint(s). no new claims to deallocate, preemption: 0/6 nodes are available: 6 Preemption is not helpful for scheduling."
0.2012,Event,ADDED,eval-sanitize-1-r2-069-7wt98.18d4a27a367e28a4,"reason=FailedScheduling count=None msg=0/6 nodes are available: 1 c_wall violated: 2 conflicting context pair(s) with node memory, 5 node(s) had untolerated taint(s). no new claims to deallocate, preemption: 0/6 nodes are available: 1 No preemption victims found for incoming pod, 5 Preemption is not helpful for scheduling."
0.2015,Event,ADDED,eval-sanitize-1-r2-069-7wt98.18d4a27a46ddb5d1,"reason=FailedScheduling count=None msg=0/6 nodes are available: 1 c_wall violated: 2 conflicting context pair(s) with node memory, 5 node(s) had untolerated taint(s). no new claims to deallocate, preemption: 0/6 nodes are available: 1 No preemption victims found for incoming pod, 5 Preemption is not helpful for scheduling."
0.2016,Event,ADDED,eval-sanitize-1-r2-069-7wt98.18d4a27a9d5989c0,reason=Scheduled count=None msg=Successfully assigned compute/eval-sanitize-1-r2-069-7wt98 to kind-worker
0.202,Event,ADDED,eval-sanitize-1-r2-069-7wt98.18d4a27ac05176f3,"reason=Pulled count=1 msg=Container image ""busybox:musl"" already present on machine"
0.2022,Event,ADDED,eval-sanitize-1-r2-069-7wt98.18d4a27ac385f5ca,reason=Created count=1 msg=Created container: task
0.2024,Event,ADDED,eval-sanitize-1-r2-069-7wt98.18d4a27ac830e14e,reason=Started count=1 msg=Started container task
0.2025,Event,ADDED,eval-sanitize-1-r2-069.18d4a279aa77d816,reason=SuccessfulCreate count=1 msg=Created pod: eval-sanitize-1-r2-069-7wt98
0.2031,Event,ADDED,eval-sanitize-1-r2-069.18d4a28190fc4366,reason=Completed count=1 msg=Job completed
0.2036,Event,ADDED,eval-sanitize-1-r2-070-6dfdm.18d4a279e6126b9d,"reason=FailedScheduling count=None msg=0/6 nodes are available: 6 node(s) had untolerated taint(s). no new claims to deallocate, preemption: 0/6 nodes are available: 6 Preemption is not helpful for scheduling."
0.2038,Event,ADDED,eval-sanitize-1-r2-070-6dfdm.18d4a27a3814190f,"reason=FailedScheduling count=None msg=0/6 nodes are available: 1 c_wall violated: 2 conflicting context pair(s) with node memory, 5 node(s) had untolerated taint(s). no new claims to deallocate, preemption: 0/6 nodes are available: 1 No preemption victims found for incoming pod, 5 Preemption is not helpful for scheduling."
0.2041,Event,ADDED,eval-sanitize-1-r2-070-6dfdm.18d4a27a472602c4,"reason=FailedScheduling count=None msg=0/6 nodes are available: 1 c_wall violated: 2 conflicting context pair(s) with node memory, 5 node(s) had untolerated taint(s). no new claims to deallocate, preemption: 0/6 nodes are available: 1 No preemption victims found for incoming pod, 5 Preemption is not helpful for scheduling."
0.2043,Event,ADDED,eval-sanitize-1-r2-070-6dfdm.18d4a27a70a8fcb7,reason=Scheduled count=None msg=Successfully assigned compute/eval-sanitize-1-r2-070-6dfdm to kind-worker5
0.2044,Event,ADDED,eval-sanitize-1-r2-070-6dfdm.18d4a27a8fe515c5,"reason=Pulled count=1 msg=Container image ""busybox:musl"" already present on machine"
0.2047,Event,ADDED,eval-sanitize-1-r2-070-6dfdm.18d4a27a92d18e1f,reason=Created count=1 msg=Created container: task
0.2049,Event,ADDED,eval-sanitize-1-r2-070-6dfdm.18d4a27a95703bf3,reason=Started count=1 msg=Started container task
0.205,Event,ADDED,eval-sanitize-1-r2-070.18d4a279e60ab66f,reason=SuccessfulCreate count=1 msg=Created pod: eval-sanitize-1-r2-070-6dfdm
0.2052,Event,ADDED,eval-sanitize-1-r2-070.18d4a2814a7300fc,reason=Completed count=1 msg=Job completed
0.2053,Event,ADDED,eval-sanitize-1-r2-071-892mn.18d4a27a37287c41,"reason=FailedScheduling count=None msg=0/6 nodes are available: 1 c_wall violated: 1 conflicting context pair(s) with node memory, 5 node(s) had untolerated taint(s). no new claims to deallocate, preemption: 0/6 nodes are available: 1 No preemption victims found for incoming pod, 5 Preemption is not helpful for scheduling."
0.2055,Event,ADDED,eval-sanitize-1-r2-071-892mn.18d4a27a47016d9a,"reason=FailedScheduling count=None msg=0/6 nodes are available: 1 c_wall violated: 1 conflicting context pair(s) with node memory, 5 node(s) had untolerated taint(s). no new claims to deallocate, preemption: 0/6 nodes are available: 1 No preemption victims found for incoming pod, 5 Preemption is not helpful for scheduling."
0.2057,Event,ADDED,eval-sanitize-1-r2-071-892mn.18d4a27a7098e81b,reason=Scheduled count=None msg=Successfully assigned compute/eval-sanitize-1-r2-071-892mn to kind-worker5
0.2059,Event,ADDED,eval-sanitize-1-r2-071-892mn.18d4a27a8fb595ab,"reason=Pulled count=1 msg=Container image ""busybox:musl"" already present on machine"
0.206,Event,ADDED,eval-sanitize-1-r2-071-892mn.18d4a27a928fd9ae,reason=Created count=1 msg=Created container: task
0.2062,Event,ADDED,eval-sanitize-1-r2-071-892mn.18d4a27a95703195,reason=Started count=1 msg=Started container task
0.2063,Event,ADDED,eval-sanitize-1-r2-071.18d4a27a236d2fc4,reason=SuccessfulCreate count=1 msg=Created pod: eval-sanitize-1-r2-071-892mn
0.2065,Event,ADDED,eval-sanitize-1-r2-071.18d4a27fe43285c8,reason=Completed count=1 msg=Job completed
0.2067,Event,ADDED,eval-sanitize-1-r2-072-97zct.18d4a27a64a54715,reason=Scheduled count=None msg=Successfully assigned compute/eval-sanitize-1-r2-072-97zct to kind-worker5
0.2068,Event,ADDED,eval-sanitize-1-r2-072-97zct.18d4a27a7fb1c3eb,"reason=Pulled count=1 msg=Container image ""busybox:musl"" already present on machine"
0.207,Event,ADDED,eval-sanitize-1-r2-072-97zct.18d4a27a80dfea3c,reason=Created count=1 msg=Created container: task
0.2072,Event,ADDED,eval-sanitize-1-r2-072-97zct.18d4a27a83f705d3,reason=Started count=1 msg=Started container task
0.2073,Event,ADDED,eval-sanitize-1-r2-072.18d4a27a5fdc7f8e,reason=SuccessfulCreate count=1 msg=Created pod: eval-sanitize-1-r2-072-97zct
0.2075,Event,ADDED,eval-sanitize-1-r2-072.18d4a281616bd363,reason=Completed count=1 msg=Job completed
0.2076,Event,ADDED,eval-sanitize-1-r2-073-l5xc2.18d4a27aa044bab9,reason=Scheduled count=None msg=Successfully assigned compute/eval-sanitize-1-r2-073-l5xc2 to kind-worker5
0.2078,Event,ADDED,eval-sanitize-1-r2-073-l5xc2.18d4a27abff822ce,"reason=Pulled count=1 msg=Container image ""busybox:musl"" already present on machine"
0.208,Event,ADDED,eval-sanitize-1-r2-073-l5xc2.18d4a27ac23fc2ed,reason=Created count=1 msg=Created container: task
0.2081,Event,ADDED,eval-sanitize-1-r2-073-l5xc2.18d4a27ac726a2d4,reason=Started count=1 msg=Started container task
0.2083,Event,ADDED,eval-sanitize-1-r2-073.18d4a27a9e6fd015,reason=SuccessfulCreate count=1 msg=Created pod: eval-sanitize-1-r2-073-l5xc2
0.2084,Event,ADDED,eval-sanitize-1-r2-073.18d4a28194ce7213,reason=Completed count=1 msg=Job completed
0.2086,Event,ADDED,eval-sanitize-1-r2-074-cwfv9.18d4a27b26ef3cfa,"reason=FailedScheduling count=None msg=0/6 nodes are available: 6 node(s) had untolerated taint(s). no new claims to deallocate, preemption: 0/6 nodes are available: 6 Preemption is not helpful for scheduling."
0.2087,Event,ADDED,eval-sanitize-1-r2-074-cwfv9.18d4a27fa2c401f6,reason=Scheduled count=None msg=Successfully assigned compute/eval-sanitize-1-r2-074-cwfv9 to kind-worker3
0.2089,Event,ADDED,eval-sanitize-1-r2-074-cwfv9.18d4a27fbe5582a2,"reason=Pulled count=1 msg=Container image ""busybox:musl"" already present on machine"
0.2113,Event,ADDED,eval-sanitize-1-r2-074-cwfv9.18d4a27fbfaf3249,reason=Created count=1 msg=Created container: task
0.2115,Event,ADDED,eval-sanitize-1-r2-074-cwfv9.18d4a27fc771d171,reason=Started count=1 msg=Started container task
0.2119,Event,ADDED,eval-sanitize-1-r2-074.18d4a27b26e11f05,reason=SuccessfulCreate count=1 msg=Created pod: eval-sanitize-1-r2-074-cwfv9
0.212,Event,ADDED,eval-sanitize-1-r2-074.18d4a2855f08b059,reason=Completed count=1 msg=Job completed
0.2122,Event,ADDED,eval-sanitize-1-r2-075-8h6zj.18d4a27b82ce8acc,"reason=FailedScheduling count=None msg=0/6 nodes are available: 6 node(s) had untolerated taint(s). no new claims to deallocate, preemption: 0/6 nodes are available: 6 Preemption is not helpful for scheduling."
0.2123,Event,ADDED,eval-sanitize-1-r2-075-8h6zj.18d4a27fa32260e7,"reason=FailedScheduling count=None msg=0/6 nodes are available: 1 c_wall violated: 1 conflicting context pair(s) with node memory, 5 node(s) had untolerated taint(s). no new claims to deallocate, preemption: 0/6 nodes are available: 1 No preemption victims found for incoming pod, 5 Preemption is not helpful for scheduling."
0.2129,Event,ADDED,eval-sanitize-1-r2-075-8h6zj.18d4a27fbf3cbd96,"reason=FailedScheduling count=None msg=0/6 nodes are available: 1 c_wall violated: 2 conflicting context pair(s) with node memory, 5 node(s) had untolerated taint(s). no new claims to deallocate, preemption: 0/6 nodes are available: 1 No preemption victims found for incoming pod, 5 Preemption is not helpful for scheduling."
0.2131,Event,ADDED,eval-sanitize-1-r2-075-8h6zj.18d4a27fcf8ed68f,"reason=FailedScheduling count=None msg=0/6 nodes are available: 1 c_wall violated: 2 conflicting context pair(s) with node memory, 5 node(s) had untolerated taint(s). no new claims to deallocate, preemption: 0/6 nodes are available: 1 No preemption victims found for incoming pod, 5 Preemption is not helpful for scheduling."
0.2133,Event,ADDED,eval-sanitize-1-r2-075-8h6zj.18d4a27ffbf1e298,reason=Scheduled count=None msg=Successfully assigned compute/eval-sanitize-1-r2-075-8h6zj to kind-worker
0.2137,Event,ADDED,eval-sanitize-1-r2-075-8h6zj.18d4a280164855fd,"reason=Pulled count=1 msg=Container image ""busybox:musl"" already present on machine"
0.2139,Event,ADDED,eval-sanitize-1-r2-075-8h6zj.18d4a2801857778e,reason=Created count=1 msg=Created container: task
0.2141,Event,ADDED,eval-sanitize-1-r2-075-8h6zj.18d4a2801cbb5496,reason=Started count=1 msg=Started container task
0.2143,Event,ADDED,eval-sanitize-1-r2-075.18d4a27b82c57edc,reason=SuccessfulCreate count=1 msg=Created pod: eval-sanitize-1-r2-075-8h6zj
0.2145,Event,ADDED,eval-sanitize-1-r2-075.18d4a286f1a42cb6,reason=Completed count=1 msg=Job completed
0.2146,Event,ADDED,eval-sanitize-1-r2-076-9kd86.18d4a27ba4dff7b3,"reason=FailedScheduling count=None msg=0/6 nodes are available: 6 node(s) had untolerated taint(s). no new claims to deallocate, preemption: 0/6 nodes are available: 6 Preemption is not helpful for scheduling."
0.2148,Event,ADDED,eval-sanitize-1-r2-076-9kd86.18d4a27fa3ed0747,"reason=FailedScheduling count=None msg=0/6 nodes are available: 1 c_wall violated: 1 conflicting context pair(s) with node memory, 5 node(s) had untolerated taint(s). no new claims to deallocate, preemption: 0/6 nodes are available: 1 No preemption victims found for incoming pod, 5 Preemption is not helpful for scheduling."
0.2151,Event,ADDED,eval-sanitize-1-r2-076-9kd86.18d4a27fbfbb14bb,"reason=FailedScheduling count=None msg=0/6 nodes are available: 1 c_wall violated: 1 conflicting context pair(s) with node memory, 5 node(s) had untolerated taint(s). no new claims to deallocate, preemption: 0/6 nodes are available: 1 No preemption victims found for incoming pod, 5 Preemption is not helpful for scheduling."
0.2153,Event,ADDED,eval-sanitize-1-r2-076-9kd86.18d4a27ffc53e182,reason=Scheduled count=None msg=Successfully assigned compute/eval-sanitize-1-r2-076-9kd86 to kind-worker
0.2155,Event,ADDED,eval-sanitize-1-r2-076-9kd86.18d4a28019aa6e5c,"reason=Pulled count=1 msg=Container image ""busybox:musl"" already present on machine"
0.2158,Event,ADDED,eval-sanitize-1-r2-076-9kd86.18d4a2801af1ad19,reason=Created count=1 msg=Created container: task
0.216,Event,ADDED,eval-sanitize-1-r2-076-9kd86.18d4a2802219dc90,reason=Started count=1 msg=Started container task
0.2161,Event,ADDED,eval-sanitize-1-r2-076.18d4a27ba4d665bb,reason=SuccessfulCreate count=1 msg=Created pod: eval-sanitize-1-r2-076-9kd86
0.2163,Event,ADDED,eval-sanitize-1-r2-076.18d4a286f69bb0b6,reason=Completed count=1 msg=Job completed
0.2165,Event,ADDED,eval-sanitize-1-r2-077-8wp8w.18d4a27bc2a91ed9,"reason=FailedScheduling count=None msg=0/6 nodes are available: 6 node(s) had untolerated taint(s). no new claims to deallocate, preemption: 0/6 nodes are available: 6 Preemption is not helpful for scheduling."
0.2167,Event,ADDED,eval-sanitize-1-r2-077-8wp8w.18d4a27fa4eaba35,"reason=FailedScheduling count=None msg=0/6 nodes are available: 1 c_wall violated: 1 conflicting context pair(s) with node memory, 5 node(s) had untolerated taint(s). no new claims to deallocate, preemption: 0/6 nodes are available: 1 No preemption victims found for incoming pod, 5 Preemption is not helpful for scheduling."
0.2169,Event,ADDED,eval-sanitize-1-r2-077-8wp8w.18d4a27fbffcadcb,"reason=FailedScheduling count=None msg=0/6 nodes are available: 1 c_wall violated: 1 conflicting context pair(s) with node memory, 5 node(s) had untolerated taint(s). no new claims to deallocate, preemption: 0/6 nodes are available: 1 No preemption victims found for incoming pod, 5 Preemption is not helpful for scheduling."
0.217,Event,ADDED,eval-sanitize-1-r2-077-8wp8w.18d4a27ffc2bb9ff,"reason=FailedScheduling count=None msg=0/6 nodes are available: 1 c_wall violated: 1 conflicting context pair(s) with node memory, 5 node(s) had untolerated taint(s). no new claims to deallocate, preemption: 0/6 nodes are available: 1 No preemption victims found for incoming pod, 5 Preemption is not helpful for scheduling."
0.2172,Event,ADDED,eval-sanitize-1-r2-077-8wp8w.18d4a28011854023,"reason=FailedScheduling count=None msg=0/6 nodes are available: 1 c_wall violated: 2 conflicting context pair(s) with node memory, 5 node(s) had untolerated taint(s). no new claims to deallocate, preemption: 0/6 nodes are available: 1 No preemption victims found for incoming pod, 5 Preemption is not helpful for scheduling."
0.2173,Event,ADDED,eval-sanitize-1-r2-077-8wp8w.18d4a2802983d9a3,reason=Scheduled count=None msg=Successfully assigned compute/eval-sanitize-1-r2-077-8wp8w to kind-worker5
0.2175,Event,ADDED,eval-sanitize-1-r2-077-8wp8w.18d4a28044228883,"reason=Pulled count=1 msg=Container image ""busybox:musl"" already present on machine"
0.2177,Event,ADDED,eval-sanitize-1-r2-077-8wp8w.18d4a280455fa4d1,reason=Created count=1 msg=Created container: task
0.2178,Event,ADDED,eval-sanitize-1-r2-077-8wp8w.18d4a2804789d042,reason=Started count=1 msg=Started container task
0.218,Event,ADDED,eval-sanitize-1-r2-077.18d4a27bc29fc82d,reason=SuccessfulCreate count=1 msg=Created pod: eval-sanitize-1-r2-077-8wp8w
0.2182,Event,ADDED,eval-sanitize-1-r2-077.18d4a286fd3b608e,reason=Completed count=1 msg=Job completed
0.2183,Event,ADDED,eval-sanitize-1-r2-078-p4lr2.18d4a27be07f778f,"reason=FailedScheduling count=None msg=0/6 nodes are available: 6 node(s) had untolerated taint(s). no new claims to deallocate, preemption: 0/6 nodes are available: 6 Preemption is not helpful for scheduling."
0.2185,Event,ADDED,eval-sanitize-1-r2-078-p4lr2.18d4a27fa5f27465,reason=Scheduled count=None msg=Successfully assigned compute/eval-sanitize-1-r2-078-p4lr2 to kind-worker3
0.2187,Event,ADDED,eval-sanitize-1-r2-078-p4lr2.18d4a27fc7749f7b,"reason=Pulled count=1 msg=Container image ""busybox:musl"" already present on machine"
0.2188,Event,ADDED,eval-sanitize-1-r2-078-p4lr2.18d4a27fc9c3901b,reason=Created count=1 msg=Created container: task
0.219,Event,ADDED,eval-sanitize-1-r2-078-p4lr2.18d4a27fce4a9cdc,reason=Started count=1 msg=Started container task
0.2192,Event,ADDED,eval-sanitize-1-r2-078.18d4a27be073ffbc,reason=SuccessfulCreate count=1 msg=Created pod: eval-sanitize-1-r2-078-p4lr2
0.2193,Event,ADDED,eval-sanitize-1-r2-078.18d4a2855eecfd2a,reason=Completed count=1 msg=Job completed
0.2195,Event,ADDED,eval-sanitize-1-r2-079-pfcxf.18d4a27c013841a3,"reason=FailedScheduling count=None msg=0/6 nodes are available: 6 node(s) had untolerated taint(s). no new claims to deallocate, preemption: 0/6 nodes are available: 6 Preemption is not helpful for scheduling."
0.2196,Event,ADDED,eval-sanitize-1-r2-079-pfcxf.18d4a27fa890467e,"reason=FailedScheduling count=None msg=0/6 nodes are available: 1 c_wall violated: 1 conflicting context pair(s) with node memory, 5 node(s) had untolerated taint(s). no new claims to deallocate, preemption: 0/6 nodes are available: 1 No preemption victims found for incoming pod, 5 Preemption is not helpful for scheduling."
0.2198,Event,ADDED,eval-sanitize-1-r2-079-pfcxf.18d4a27fc03a951d,"reason=FailedScheduling count=None msg=0/6 nodes are available: 1 c_wall violated: 1 conflicting context pair(s) with node memory, 5 node(s) had untolerated taint(s). no new claims to deallocate, preemption: 0/6 nodes are available: 1 No preemption victims found for incoming pod, 5 Preemption is not helpful for scheduling."
0.22,Event,ADDED,eval-sanitize-1-r2-079-pfcxf.18d4a27ffd5983b9,reason=Scheduled count=None msg=Successfully assigned compute/eval-sanitize-1-r2-079-pfcxf to kind-worker
0.2201,Event,ADDED,eval-sanitize-1-r2-079-pfcxf.18d4a2801b77cccb,"reason=Pulled count=1 msg=Container image ""busybox:musl"" already present on machine"
0.2203,Event,ADDED,eval-sanitize-1-r2-079-pfcxf.18d4a2801cd465bd,reason=Created count=1 msg=Created container: task
0.2205,Event,ADDED,eval-sanitize-1-r2-079-pfcxf.18d4a280229b4aab,reason=Started count=1 msg=Started container task
0.2207,Event,ADDED,eval-sanitize-1-r2-079.18d4a27c012df38b,reason=SuccessfulCreate count=1 msg=Created pod: eval-sanitize-1-r2-079-pfcxf
0.2208,Event,ADDED,eval-sanitize-1-r2-079.18d4a286eab793a8,reason=Completed count=1 msg=Job completed
0.221,Event,ADDED,eval-sanitize-1-r2-080-gqrjs.18d4a27c3ad9bc10,"reason=FailedScheduling count=None msg=0/6 nodes are available: 6 node(s) had untolerated taint(s). no new claims to deallocate, preemption: 0/6 nodes are available: 6 Preemption is not helpful for scheduling."
0.2211,Event,ADDED,eval-sanitize-1-r2-080-gqrjs.18d4a27fa9298d69,"reason=FailedScheduling count=None msg=0/6 nodes are available: 1 c_wall violated: 1 conflicting context pair(s) with node memory, 5 node(s) had untolerated taint(s). no new claims to deallocate, preemption: 0/6 nodes are available: 1 No preemption victims found for incoming pod, 5 Preemption is not helpful for scheduling."
0.2214,Event,ADDED,eval-sanitize-1-r2-080-gqrjs.18d4a27fc3a185d3,"reason=FailedScheduling count=None msg=0/6 nodes are available: 1 c_wall violated: 1 conflicting context pair(s) with node memory, 5 node(s) had untolerated taint(s). no new claims to deallocate, preemption: 0/6 nodes are available: 1 No preemption victims found for incoming pod, 5 Preemption is not helpful for scheduling."
0.2215,Event,ADDED,eval-sanitize-1-r2-080-gqrjs.18d4a27ffd2e11ca,"reason=FailedScheduling count=None msg=0/6 nodes are available: 1 c_wall violated: 2 conflicting context pair(s) with node memory, 5 node(s) had untolerated taint(s). no new claims to deallocate, preemption: 0/6 nodes are available: 1 No preemption victims found for incoming pod, 5 Preemption is not helpful for scheduling."
0.2217,Event,ADDED,eval-sanitize-1-r2-080-gqrjs.18d4a280122a1034,"reason=FailedScheduling count=None msg=0/6 nodes are available: 1 c_wall violated: 2 conflicting context pair(s) with node memory, 5 node(s) had untolerated taint(s). no new claims to deallocate, preemption: 0/6 nodes are available: 1 No preemption victims found for incoming pod, 5 Preemption is not helpful for scheduling."
0.2218,Event,ADDED,eval-sanitize-1-r2-080-gqrjs.18d4a2802ac0a532,reason=Scheduled count=None msg=Successfully assigned compute/eval-sanitize-1-r2-080-gqrjs to kind-worker5
0.222,Event,ADDED,eval-sanitize-1-r2-080-gqrjs.18d4a280474a564c,"reason=Pulled count=1 msg=Container image ""busybox:musl"" already present on machine"
0.2222,Event,ADDED,eval-sanitize-1-r2-080-gqrjs.18d4a28048944e87,reason=Created count=1 msg=Created container: task
0.2223,Event,ADDED,eval-sanitize-1-r2-080-gqrjs.18d4a2804c750768,reason=Started count=1 msg=Started container task
0.2225,Event,ADDED,eval-sanitize-1-r2-080.18d4a27c3ad009fc,reason=SuccessfulCreate count=1 msg=Created pod: eval-sanitize-1-r2-080-gqrjs
0.2227,Event,ADDED,eval-sanitize-1-r2-080.18d4a287115dd8d9,reason=Completed count=1 msg=Job completed
0.2229,Event,ADDED,eval-sanitize-1-r2-081-vq5x7.18d4a27c788ed14f,"reason=FailedScheduling count=None msg=0/6 nodes are available: 6 node(s) had untolerated taint(s). no new claims to deallocate, preemption: 0/6 nodes are available: 6 Preemption is not helpful for scheduling."
0.2231,Event,ADDED,eval-sanitize-1-r2-081-vq5x7.18d4a27fa9ba112a,"reason=FailedScheduling count=None msg=0/6 nodes are available: 1 c_wall violated: 1 conflicting context pair(s) with node memory, 5 node(s) had untolerated taint(s). no new claims to deallocate, preemption: 0/6 nodes are available: 1 No preemption victims found for incoming pod, 5 Preemption is not helpful for scheduling."
0.2232,Event,ADDED,eval-sanitize-1-r2-081-vq5x7.18d4a27fc4c52b75,"reason=FailedScheduling count=None msg=0/6 nodes are available: 1 c_wall violated: 1 conflicting context pair(s) with node memory, 5 node(s) had untolerated taint(s). no new claims to deallocate, preemption: 0/6 nodes are available: 1 No preemption victims found for incoming pod, 5 Preemption is not helpful for scheduling."
0.2235,Event,ADDED,eval-sanitize-1-r2-081-vq5x7.18d4a28001fe59d8,"reason=FailedScheduling count=None msg=0/6 nodes are available: 1 c_wall violated: 1 conflicting context pair(s) with node memory, 5 node(s) had untolerated taint(s). no new claims to deallocate, preemption: 0/6 nodes are available: 1 No preemption victims found for incoming pod, 5 Preemption is not helpful for scheduling."
0.2237,Event,ADDED,eval-sanitize-1-r2-081-vq5x7.18d4a28015b9d18f,reason=Scheduled count=None msg=Successfully assigned compute/eval-sanitize-1-r2-081-vq5x7 to kind-worker5
0.2239,Event,ADDED,eval-sanitize-1-r2-081-vq5x7.18d4a2802e602153,"reason=Pulled count=1 msg=Container image ""busybox:musl"" already present on machine"
0.2242,Event,ADDED,eval-sanitize-1-r2-081-vq5x7.18d4a2803054396c,reason=Created count=1 msg=Created container: task
0.2244,Event,ADDED,eval-sanitize-1-r2-081-vq5x7.18d4a28032c0bb2d,reason=Started count=1 msg=Started container task
0.2245,Event,ADDED,eval-sanitize-1-r2-081.18d4a27c7885fd32,reason=SuccessfulCreate count=1 msg=Created pod: eval-sanitize-1-r2-081-vq5x7
0.2247,Event,ADDED,eval-sanitize-1-r2-081.18d4a287060edb97,reason=Completed count=1 msg=Job completed
0.2249,Event,ADDED,eval-sanitize-1-r2-082-bc65r.18d4a27cb410512f,"reason=FailedScheduling count=None msg=0/6 nodes are available: 6 node(s) had untolerated taint(s). no new claims to deallocate, preemption: 0/6 nodes are available: 6 Preemption is not helpful for scheduling."
0.2251,Event,ADDED,eval-sanitize-1-r2-082-bc65r.18d4a27faa87428f,"reason=FailedScheduling count=None msg=0/6 nodes are available: 1 c_wall violated: 1 conflicting context pair(s) with node memory, 5 node(s) had untolerated taint(s). no new claims to deallocate, preemption: 0/6 nodes are available: 1 No preemption victims found for incoming pod, 5 Preemption is not helpful for scheduling."
0.2252,Event,ADDED,eval-sanitize-1-r2-082-bc65r.18d4a27fc4f5a40b,"reason=FailedScheduling count=None msg=0/6 nodes are available: 1 c_wall violated: 2 conflicting context pair(s) with node memory, 5 node(s) had untolerated taint(s). no new claims to deallocate, preemption: 0/6 nodes are available: 1 No preemption victims found for incoming pod, 5 Preemption is not helpful for scheduling."
0.2254,Event,ADDED,eval-sanitize-1-r2-082-bc65r.18d4a27fd197b1a6,"reason=FailedScheduling count=None msg=0/6 nodes are available: 1 c_wall violated: 2 conflicting context pair(s) with node memory, 5 node(s) had untolerated taint(s). no new claims to deallocate, preemption: 0/6 nodes are available: 1 No preemption victims found for incoming pod, 5 Preemption is not helpful for scheduling."
0.2256,Event,ADDED,eval-sanitize-1-r2-082-bc65r.18d4a28002f6f1b4,reason=Scheduled count=None msg=Successfully assigned compute/eval-sanitize-1-r2-082-bc65r to kind-worker
0.2258,Event,ADDED,eval-sanitize-1-r2-082-bc65r.18d4a2801d61be21,"reason=Pulled count=1 msg=Container image ""busybox:musl"" already present on machine"
0.226,Event,ADDED,eval-sanitize-1-r2-082-bc65r.18d4a2801ed708ce,reason=Created count=1 msg=Created container: task
0.2262,Event,ADDED,eval-sanitize-1-r2-082-bc65r.18d4a28020e3ac51,reason=Started count=1 msg=Started container task
0.2264,Event,ADDED,eval-sanitize-1-r2-082.18d4a27cb404b724,reason=SuccessfulCreate count=1 msg=Created pod: eval-sanitize-1-r2-082-bc65r
0.2265,Event,ADDED,eval-sanitize-1-r2-082.18d4a286dba79d2a,reason=Completed count=1 msg=Job completed
0.2268,Event,ADDED,eval-sanitize-1-r2-083-hnlzb.18d4a27ced7d4874,"reason=FailedScheduling count=None msg=0/6 nodes are available: 6 node(s) had untolerated taint(s). no new claims to deallocate, preemption: 0/6 nodes are available: 6 Preemption is not helpful for scheduling."
0.2269,Event,ADDED,eval-sanitize-1-r2-083-hnlzb.18d4a27fae869e72,"reason=FailedScheduling count=None msg=0/6 nodes are available: 1 c_wall violated: 1 conflicting context pair(s) with node memory, 5 node(s) had untolerated taint(s). no new claims to deallocate, preemption: 0/6 nodes are available: 1 No preemption victims found for incoming pod, 5 Preemption is not helpful for scheduling."
0.2271,Event,ADDED,eval-sanitize-1-r2-083-hnlzb.18d4a27fc7ff73f6,"reason=FailedScheduling count=None msg=0/6 nodes are available: 1 c_wall violated: 1 conflicting context pair(s) with node memory, 5 node(s) had untolerated taint(s). no new claims to deallocate, preemption: 0/6 nodes are available: 1 No preemption victims found for incoming pod, 5 Preemption is not helpful for scheduling."
0.2272,Event,ADDED,eval-sanitize-1-r2-083-hnlzb.18d4a28002cdc45c,"reason=FailedScheduling count=None msg=0/6 nodes are available: 1 c_wall violated: 2 conflicting context pair(s) with node memory, 5 node(s) had untolerated taint(s). no new claims to deallocate, preemption: 0/6 nodes are available: 1 No preemption victims found for incoming pod, 5 Preemption is not helpful for scheduling."
0.2274,Event,ADDED,eval-sanitize-1-r2-083-hnlzb.18d4a28017acc392,reason=Scheduled count=None msg=Successfully assigned compute/eval-sanitize-1-r2-083-hnlzb to kind-worker5
0.2276,Event,ADDED,eval-sanitize-1-r2-083-hnlzb.18d4a280312f4455,"reason=Pulled count=1 msg=Container image ""busybox:musl"" already present on machine"
0.2277,Event,ADDED,eval-sanitize-1-r2-083-hnlzb.18d4a2803311de03,reason=Created count=1 msg=Created container: task
0.2279,Event,ADDED,eval-sanitize-1-r2-083-hnlzb.18d4a2803c0053fb,reason=Started count=1 msg=Started container task
0.2281,Event,ADDED,eval-sanitize-1-r2-083.18d4a27ced74c445,reason=SuccessfulCreate count=1 msg=Created pod: eval-sanitize-1-r2-083-hnlzb
0.2282,Event,ADDED,eval-sanitize-1-r2-083.18d4a286ffb450d4,reason=Completed count=1 msg=Job completed
0.2284,Event,ADDED,eval-sanitize-1-r2-084-rz595.18d4a27d2a7fe34e,"reason=FailedScheduling count=None msg=0/6 nodes are available: 6 node(s) had untolerated taint(s). no new claims to deallocate, preemption: 0/6 nodes are available: 6 Preemption is not helpful for scheduling."
0.2285,Event,ADDED,eval-sanitize-1-r2-084-rz595.18d4a27fb32b31ba,reason=Scheduled count=None msg=Successfully assigned compute/eval-sanitize-1-r2-084-rz595 to kind-worker3
0.2287,Event,ADDED,eval-sanitize-1-r2-084-rz595.18d4a27fcfdc1e4c,"reason=Pulled count=1 msg=Container image ""busybox:musl"" already present on machine"
0.2288,Event,ADDED,eval-sanitize-1-r2-084-rz595.18d4a27fd24f24b8,reason=Created count=1 msg=Created container: task
0.229,Event,ADDED,eval-sanitize-1-r2-084-rz595.18d4a27fdd18a9d5,reason=Started count=1 msg=Started container task
0.2292,Event,ADDED,eval-sanitize-1-r2-084.18d4a27d2a754031,reason=SuccessfulCreate count=1 msg=Created pod: eval-sanitize-1-r2-084-rz595
0.2293,Event,ADDED,eval-sanitize-1-r2-084.18d4a285604f204a,reason=Completed count=1 msg=Job completed
0.2295,Event,ADDED,eval-sanitize-1-r2-085-mjmdc.18d4a27d6422c678,"reason=FailedScheduling count=None msg=0/6 nodes are available: 6 node(s) had untolerated taint(s). no new claims to deallocate, preemption: 0/6 nodes are available: 6 Preemption is not helpful for scheduling."
0.2296,Event,ADDED,eval-sanitize-1-r2-085-mjmdc.18d4a27fb366eca7,reason=Scheduled count=None msg=Successfully assigned compute/eval-sanitize-1-r2-085-mjmdc to kind-worker3
0.2298,Event,ADDED,eval-sanitize-1-r2-085-mjmdc.18d4a27fcfbf4ead,"reason=Pulled count=1 msg=Container image ""busybox:musl"" already present on machine"
0.23,Event,ADDED,eval-sanitize-1-r2-085-mjmdc.18d4a27fd1fb7c65,reason=Created count=1 msg=Created container: task
0.2301,Event,ADDED,eval-sanitize-1-r2-085-mjmdc.18d4a27fdd1c1df4,reason=Started count=1 msg=Started container task
0.2303,Event,ADDED,eval-sanitize-1-r2-085.18d4a27d64114431,reason=SuccessfulCreate count=1 msg=Created pod: eval-sanitize-1-r2-085-mjmdc
0.2305,Event,ADDED,eval-sanitize-1-r2-085.18d4a285242afa59,reason=Completed count=1 msg=Job completed
0.2307,Event,ADDED,eval-sanitize-1-r2-086-27qdc.18d4a27d9fc87352,"reason=FailedScheduling count=None msg=0/6 nodes are available: 6 node(s) had untolerated taint(s). no new claims to deallocate, preemption: 0/6 nodes are available: 6 Preemption is not helpful for scheduling."
0.2308,Event,ADDED,eval-sanitize-1-r2-086-27qdc.18d4a27fb3379077,"reason=FailedScheduling count=None msg=0/6 nodes are available: 1 c_wall violated: 1 conflicting context pair(s) with node memory, 5 node(s) had untolerated taint(s). no new claims to deallocate, preemption: 0/6 nodes are available: 1 No preemption victims found for incoming pod, 5 Preemption is not helpful for scheduling."
0.231,Event,ADDED,eval-sanitize-1-r2-086-27qdc.18d4a27fc839b291,"reason=FailedScheduling count=None msg=0/6 nodes are available: 1 c_wall violated: 1 conflicting context pair(s) with node memory, 5 node(s) had untolerated taint(s). no new claims to deallocate, preemption: 0/6 nodes are available: 1 No preemption victims found for incoming pod, 5 Preemption is not helpful for scheduling."
0.2312,Event,ADDED,eval-sanitize-1-r2-086-27qdc.18d4a28007eaaa54,reason=Scheduled count=None msg=Successfully assigned compute/eval-sanitize-1-r2-086-27qdc to kind-worker
0.2313,Event,ADDED,eval-sanitize-1-r2-086-27qdc.18d4a28022a1aa77,"reason=Pulled count=1 msg=Container image ""busybox:musl"" already present on machine"
0.2315,Event,ADDED,eval-sanitize-1-r2-086-27qdc.18d4a280242c9d25,reason=Created count=1 msg=Created container: task
0.2317,Event,ADDED,eval-sanitize-1-r2-086-27qdc.18d4a2802895ef93,reason=Started count=1 msg=Started container task
0.2318,Event,ADDED,eval-sanitize-1-r2-086.18d4a27d9fb8d2db,reason=SuccessfulCreate count=1 msg=Created pod: eval-sanitize-1-r2-086-27qdc
0.232,Event,ADDED,eval-sanitize-1-r2-086.18d4a286cf0bee7e,reason=Completed count=1 msg=Job completed
0.2321,Event,ADDED,eval-sanitize-1-r2-087-n4x6s.18d4a27ddc669cd6,"reason=FailedScheduling count=None msg=0/6 nodes are available: 6 node(s) had untolerated taint(s). no new claims to deallocate, preemption: 0/6 nodes are available: 6 Preemption is not helpful for scheduling."
0.2323,Event,ADDED,eval-sanitize-1-r2-087-n4x6s.18d4a27fb3e88cf5,"reason=FailedScheduling count=None msg=0/6 nodes are available: 1 c_wall violated: 1 conflicting context pair(s) with node memory, 5 node(s) had untolerated taint(s). no new claims to deallocate, preemption: 0/6 nodes are available: 1 No preemption victims found for incoming pod, 5 Preemption is not helpful for scheduling."
0.2325,Event,ADDED,eval-sanitize-1-r2-087-n4x6s.18d4a27fc895e921,"reason=FailedScheduling count=None msg=0/6 nodes are available: 1 c_wall violated: 1 conflicting context pair(s) with node memory, 5 node(s) had untolerated taint(s). no new claims to deallocate, preemption: 0/6 nodes are available: 1 No preemption victims found for incoming pod, 5 Preemption is not helpful for scheduling."
0.2327,Event,ADDED,eval-sanitize-1-r2-087-n4x6s.18d4a28007edd161,"reason=FailedScheduling count=None msg=0/6 nodes are available: 1 c_wall violated: 2 conflicting context pair(s) with node memory, 5 node(s) had untolerated taint(s). no new claims to deallocate, preemption: 0/6 nodes are available: 1 No preemption victims found for incoming pod, 5 Preemption is not helpful for scheduling."
0.2328,Event,ADDED,eval-sanitize-1-r2-087-n4x6s.18d4a280189b9027,reason=Scheduled count=None msg=Successfully assigned compute/eval-sanitize-1-r2-087-n4x6s to kind-worker5
0.233,Event,ADDED,eval-sanitize-1-r2-087-n4x6s.18d4a280330bab4e,"reason=Pulled count=1 msg=Container image ""busybox:musl"" already present on machine"
0.2332,Event,ADDED,eval-sanitize-1-r2-087-n4x6s.18d4a28034476dc9,reason=Created count=1 msg=Created container: task
0.2333,Event,ADDED,eval-sanitize-1-r2-087-n4x6s.18d4a2803ca10cbb,reason=Started count=1 msg=Started container task
0.2335,Event,ADDED,eval-sanitize-1-r2-087.18d4a27ddc5a2ebd,reason=SuccessfulCreate count=1 msg=Created pod: eval-sanitize-1-r2-087-n4x6s
0.2337,Event,ADDED,eval-sanitize-1-r2-087.18d4a2871750ad39,reason=Completed count=1 msg=Job completed
0.2338,Event,ADDED,eval-sanitize-1-r2-088-2rjn4.18d4a27e1b1e4f0f,"reason=FailedScheduling count=None msg=0/6 nodes are available: 6 node(s) had untolerated taint(s). no new claims to deallocate, preemption: 0/6 nodes are available: 6 Preemption is not helpful for scheduling."
0.234,Event,ADDED,eval-sanitize-1-r2-088-2rjn4.18d4a27fb4898891,"reason=FailedScheduling count=None msg=0/6 nodes are available: 1 c_wall violated: 1 conflicting context pair(s) with node memory, 5 node(s) had untolerated taint(s). no new claims to deallocate, preemption: 0/6 nodes are available: 1 No preemption victims found for incoming pod, 5 Preemption is not helpful for scheduling."
0.2342,Event,ADDED,eval-sanitize-1-r2-088-2rjn4.18d4a27fc99b5e43,"reason=FailedScheduling count=None msg=0/6 nodes are available: 1 c_wall violated: 1 conflicting context pair(s) with node memory, 5 node(s) had untolerated taint(s). no new claims to deallocate, preemption: 0/6 nodes are available: 1 No preemption victims found for incoming pod, 5 Preemption is not helpful for scheduling."
0.2343,Event,ADDED,eval-sanitize-1-r2-088-2rjn4.18d4a2800aa76d85,"reason=FailedScheduling count=None msg=0/6 nodes are available: 1 c_wall violated: 3 conflicting context pair(s) with node memory, 5 node(s) had untolerated taint(s). no new claims to deallocate, preemption: 0/6 nodes are available: 1 No preemption victims found for incoming pod, 5 Preemption is not helpful for scheduling."
0.2345,Event,ADDED,eval-sanitize-1-r2-088-2rjn4.18d4a280188cd7ee,"reason=FailedScheduling count=None msg=0/6 nodes are available: 1 c_wall violated: 1 conflicting context pair(s) with node memory, 1 c_wall violated: 3 conflicting context pair(s) with node memory, 4 node(s) had untolerated taint(s). no new claims to deallocate, preemption: 0/6 nodes are available: 2 No preemption victims found for incoming pod, 4 Preemption is not helpful for scheduling."
0.2346,Event,ADDED,eval-sanitize-1-r2-088-2rjn4.18d4a2802f11824b,"reason=FailedScheduling count=None msg=0/6 nodes are available: 1 c_wall violated: 1 conflicting context pair(s) with node memory, 1 c_wall violated: 3 conflicting context pair(s) with node memory, 4 node(s) had untolerated taint(s). no new claims to deallocate, preemption: 0/6 nodes are available: 2 No preemption victims found for incoming pod, 4 Preemption is not helpful for scheduling."
0.2348,Event,ADDED,eval-sanitize-1-r2-088-2rjn4.18d4a280485cf1ae,reason=Scheduled count=None msg=Successfully assigned compute/eval-sanitize-1-r2-088-2rjn4 to kind-worker2
0.235,Event,ADDED,eval-sanitize-1-r2-088-2rjn4.18d4a28061edd6c2,"reason=Pulled count=1 msg=Container image ""busybox:musl"" already present on machine"
0.2351,Event,ADDED,eval-sanitize-1-r2-088-2rjn4.18d4a280634e0e87,reason=Created count=1 msg=Created container: task
0.2353,Event,ADDED,eval-sanitize-1-r2-088-2rjn4.18d4a280665f8d76,reason=Started count=1 msg=Started container task
0.2355,Event,ADDED,eval-sanitize-1-r2-088.18d4a27e1b0ed3f5,reason=SuccessfulCreate count=1 msg=Created pod: eval-sanitize-1-r2-088-2rjn4
0.2356,Event,ADDED,eval-sanitize-1-r2-088.18d4a28732d62041,reason=Completed count=1 msg=Job completed
0.2358,Event,ADDED,eval-sanitize-1-r2-089-trzv4.18d4a27e529ef323,"reason=FailedScheduling count=None msg=0/6 nodes are available: 6 node(s) had untolerated taint(s). no new claims to deallocate, preemption: 0/6 nodes are available: 6 Preemption is not helpful for scheduling."
0.2359,Event,ADDED,eval-sanitize-1-r2-089-trzv4.18d4a27fb7b6506d,"reason=FailedScheduling count=None msg=0/6 nodes are available: 1 c_wall violated: 2 conflicting context pair(s) with node memory, 5 node(s) had untolerated taint(s). no new claims to deallocate, preemption: 0/6 nodes are available: 1 No preemption victims found for incoming pod, 5 Preemption is not helpful for scheduling."
0.2361,Event,ADDED,eval-sanitize-1-r2-089-trzv4.18d4a27fcac9a195,"reason=FailedScheduling count=None msg=0/6 nodes are available: 1 c_wall violated: 2 conflicting context pair(s) with node memory, 5 node(s) had untolerated taint(s). no new claims to deallocate, preemption: 0/6 nodes are available: 1 No preemption victims found for incoming pod, 5 Preemption is not helpful for scheduling."
0.2363,Event,ADDED,eval-sanitize-1-r2-089-trzv4.18d4a2800b3fb1bf,"reason=FailedScheduling count=None msg=0/6 nodes are available: 1 c_wall violated: 1 conflicting context pair(s) with node memory, 5 node(s) had untolerated taint(s). no new claims to deallocate, preemption: 0/6 nodes are available: 1 No preemption victims found for incoming pod, 5 Preemption is not helpful for scheduling."
0.2364,Event,ADDED,eval-sanitize-1-r2-089-trzv4.18d4a2801d7d7891,reason=Scheduled count=None msg=Successfully assigned compute/eval-sanitize-1-r2-089-trzv4 to kind-worker5
0.2366,Event,ADDED,eval-sanitize-1-r2-089-trzv4.18d4a2803c461c5d,"reason=Pulled count=1 msg=Container image ""busybox:musl"" already present on machine"
0.2367,Event,ADDED,eval-sanitize-1-r2-089-trzv4.18d4a2803ea184ef,reason=Created count=1 msg=Created container: task
0.2369,Event,ADDED,eval-sanitize-1-r2-089-trzv4.18d4a28043283d81,reason=Started count=1 msg=Started container task
0.2371,Event,ADDED,eval-sanitize-1-r2-089.18d4a27e5295b35e,reason=SuccessfulCreate count=1 msg=Created pod: eval-sanitize-1-r2-089-trzv4
0.2372,Event,ADDED,eval-sanitize-1-r2-089.18d4a2871a4d14c2,reason=Completed count=1 msg=Job completed
0.2374,Event,ADDED,eval-sanitize-1-r2-090-th9bk.18d4a27e8e9fa35f,"reason=FailedScheduling count=None msg=0/6 nodes are available: 6 node(s) had untolerated taint(s). no new claims to deallocate, preemption: 0/6 nodes are available: 6 Preemption is not helpful for scheduling."
0.2376,Event,ADDED,eval-sanitize-1-r2-090-th9bk.18d4a27fb9621338,"reason=FailedScheduling count=None msg=0/6 nodes are available: 1 c_wall violated: 1 conflicting context pair(s) with node memory, 5 node(s) had untolerated taint(s). no new claims to deallocate, preemption: 0/6 nodes are available: 1 No preemption victims found for incoming pod, 5 Preemption is not helpful for scheduling."
0.2378,Event,ADDED,eval-sanitize-1-r2-090-th9bk.18d4a27fcafb553a,"reason=FailedScheduling count=None msg=0/6 nodes are available: 1 c_wall violated: 1 conflicting context pair(s) with node memory, 5 node(s) had untolerated taint(s). no new claims to deallocate, preemption: 0/6 nodes are available: 1 No preemption victims found for incoming pod, 5 Preemption is not helpful for scheduling."
0.238,Event,ADDED,eval-sanitize-1-r2-090-th9bk.18d4a2800c374296,"reason=FailedScheduling count=None msg=0/6 nodes are available: 1 c_wall violated: 3 conflicting context pair(s) with node memory, 5 node(s) had untolerated taint(s). no new claims to deallocate, preemption: 0/6 nodes are available: 1 No preemption victims found for incoming pod, 5 Preemption is not helpful for scheduling."
0.2381,Event,ADDED,eval-sanitize-1-r2-090-th9bk.18d4a2801fc50c0c,"reason=FailedScheduling count=None msg=0/6 nodes are available: 1 c_wall violated: 1 conflicting context pair(s) with node memory, 1 c_wall violated: 3 conflicting context pair(s) with node memory, 4 node(s) had untolerated taint(s). no new claims to deallocate, preemption: 0/6 nodes are available: 2 No preemption victims found for incoming pod, 4 Preemption is not helpful for scheduling."
0.2383,Event,ADDED,eval-sanitize-1-r2-090-th9bk.18d4a28034fb18c4,"reason=FailedScheduling count=None msg=0/6 nodes are available: 1 c_wall violated: 1 conflicting context pair(s) with node memory, 1 c_wall violated: 3 conflicting context pair(s) with node memory, 4 node(s) had untolerated taint(s). no new claims to deallocate, preemption: 0/6 nodes are available: 2 No preemption victims found for incoming pod, 4 Preemption is not helpful for scheduling."
0.2384,Event,ADDED,eval-sanitize-1-r2-090-th9bk.18d4a2803cc1f079,reason=Scheduled count=None msg=Successfully assigned compute/eval-sanitize-1-r2-090-th9bk to kind-worker2
0.2387,Event,ADDED,eval-sanitize-1-r2-090-th9bk.18d4a28055f00fde,"reason=Pulled count=1 msg=Container image ""busybox:musl"" already present on machine"
0.2388,Event,ADDED,eval-sanitize-1-r2-090-th9bk.18d4a2805745f7c6,reason=Created count=1 msg=Created container: task
0.239,Event,ADDED,eval-sanitize-1-r2-090-th9bk.18d4a2805af7e64d,reason=Started count=1 msg=Started container task
0.2392,Event,ADDED,eval-sanitize-1-r2-090.18d4a27e8e926d77,reason=SuccessfulCreate count=1 msg=Created pod: eval-sanitize-1-r2-090-th9bk
0.2393,Event,ADDED,eval-sanitize-1-r2-090.18d4a2873f22e2f1,reason=Completed count=1 msg=Job completed
0.2395,Event,ADDED,eval-sanitize-1-r2-091-rw6rb.18d4a27ec9c43682,"reason=FailedScheduling count=None msg=0/6 nodes are available: 6 node(s) had untolerated taint(s). no new claims to deallocate, preemption: 0/6 nodes are available: 6 Preemption is not helpful for scheduling."
0.2396,Event,ADDED,eval-sanitize-1-r2-091-rw6rb.18d4a27fba873f17,reason=Scheduled count=None msg=Successfully assigned compute/eval-sanitize-1-r2-091-rw6rb to kind-worker3
0.2398,Event,ADDED,eval-sanitize-1-r2-091-rw6rb.18d4a27fdd21316b,"reason=Pulled count=1 msg=Container image ""busybox:musl"" already present on machine"
0.24,Event,ADDED,eval-sanitize-1-r2-091-rw6rb.18d4a27fe4281d16,reason=Created count=1 msg=Created container: task
0.2401,Event,ADDED,eval-sanitize-1-r2-091-rw6rb.18d4a27fe94c5310,reason=Started count=1 msg=Started container task
0.2403,Event,ADDED,eval-sanitize-1-r2-091.18d4a27ec9b5d4ef,reason=SuccessfulCreate count=1 msg=Created pod: eval-sanitize-1-r2-091-rw6rb
0.2405,Event,ADDED,eval-sanitize-1-r2-091.18d4a2856020d084,reason=Completed count=1 msg=Job completed
0.2406,Event,ADDED,eval-sanitize-1-r2-092-dln26.18d4a27f0788b7bb,"reason=FailedScheduling count=None msg=0/6 nodes are available: 6 node(s) had untolerated taint(s). no new claims to deallocate, preemption: 0/6 nodes are available: 6 Preemption is not helpful for scheduling."
0.2408,Event,ADDED,eval-sanitize-1-r2-092-dln26.18d4a27fba3cf837,"reason=FailedScheduling count=None msg=0/6 nodes are available: 1 c_wall violated: 1 conflicting context pair(s) with node memory, 5 node(s) had untolerated taint(s). no new claims to deallocate, preemption: 0/6 nodes are available: 1 No preemption victims found for incoming pod, 5 Preemption is not helpful for scheduling."
0.2412,Event,ADDED,eval-sanitize-1-r2-092-dln26.18d4a27fcb2c84ca,"reason=FailedScheduling count=None msg=0/6 nodes are available: 1 c_wall violated: 1 conflicting context pair(s) with node memory, 5 node(s) had untolerated taint(s). no new claims to deallocate, preemption: 0/6 nodes are available: 1 No preemption victims found for incoming pod, 5 Preemption is not helpful for scheduling."
0.2414,Event,ADDED,eval-sanitize-1-r2-092-dln26.18d4a2800cad9ee6,"reason=FailedScheduling count=None msg=0/6 nodes are available: 1 c_wall violated: 2 conflicting context pair(s) with node memory, 5 node(s) had untolerated taint(s). no new claims to deallocate, preemption: 0/6 nodes are available: 1 No preemption victims found for incoming pod, 5 Preemption is not helpful for scheduling."
0.2416,Event,ADDED,eval-sanitize-1-r2-092-dln26.18d4a2802382912e,reason=Scheduled count=None msg=Successfully assigned compute/eval-sanitize-1-r2-092-dln26 to kind-worker5
0.2419,Event,ADDED,eval-sanitize-1-r2-092-dln26.18d4a2803cff35f4,"reason=Pulled count=1 msg=Container image ""busybox:musl"" already present on machine"
0.2421,Event,ADDED,eval-sanitize-1-r2-092-dln26.18d4a2803eff21a9,reason=Created count=1 msg=Created container: task
0.2422,Event,ADDED,eval-sanitize-1-r2-092-dln26.18d4a28043279230,reason=Started count=1 msg=Started container task
0.2424,Event,ADDED,eval-sanitize-1-r2-092.18d4a27f07825279,reason=SuccessfulCreate count=1 msg=Created pod: eval-sanitize-1-r2-092-dln26
0.2426,Event,ADDED,eval-sanitize-1-r2-092.18d4a28729379e79,reason=Completed count=1 msg=Job completed
0.2427,Event,ADDED,eval-sanitize-1-r2-093-pwln4.18d4a27f4536d263,"reason=FailedScheduling count=None msg=0/6 nodes are available: 6 node(s) had untolerated taint(s). no new claims to deallocate, preemption: 0/6 nodes are available: 6 Preemption is not helpful for scheduling."
0.2429,Event,ADDED,eval-sanitize-1-r2-093-pwln4.18d4a27fbb152b81,"reason=FailedScheduling count=None msg=0/6 nodes are available: 1 c_wall violated: 1 conflicting context pair(s) with node memory, 5 node(s) had untolerated taint(s). no new claims to deallocate, preemption: 0/6 nodes are available: 1 No preemption victims found for incoming pod, 5 Preemption is not helpful for scheduling."
0.2431,Event,ADDED,eval-sanitize-1-r2-093-pwln4.18d4a27fcb585825,"reason=FailedScheduling count=None msg=0/6 nodes are available: 1 c_wall violated: 1 conflicting context pair(s) with node memory, 5 node(s) had untolerated taint(s). no new claims to deallocate, preemption: 0/6 nodes are available: 1 No preemption victims found for incoming pod, 5 Preemption is not helpful for scheduling."
0.2433,Event,ADDED,eval-sanitize-1-r2-093-pwln4.18d4a2800fc858c3,"reason=FailedScheduling count=None msg=0/6 nodes are available: 1 c_wall violated: 2 conflicting context pair(s) with node memory, 5 node(s) had untolerated taint(s). no new claims to deallocate, preemption: 0/6 nodes are available: 1 No preemption victims found for incoming pod, 5 Preemption is not helpful for scheduling."
0.2434,Event,ADDED,eval-sanitize-1-r2-093-pwln4.18d4a280240fbb01,"reason=FailedScheduling count=None msg=0/6 nodes are available: 1 c_wall violated: 2 conflicting context pair(s) with node memory, 1 c_wall violated: 3 conflicting context pair(s) with node memory, 4 node(s) had untolerated taint(s). no new claims to deallocate, preemption: 0/6 nodes are available: 2 No preemption victims found for incoming pod, 4 Preemption is not helpful for scheduling."
0.2438,Event,ADDED,eval-sanitize-1-r2-093-pwln4.18d4a28036260fc5,"reason=FailedScheduling count=None msg=0/6 nodes are available: 1 c_wall violated: 2 conflicting context pair(s) with node memory, 1 c_wall violated: 3 conflicting context pair(s) with node memory, 4 node(s) had untolerated taint(s). no new claims to deallocate, preemption: 0/6 nodes are available: 2 No preemption victims found for incoming pod, 4 Preemption is not helpful for scheduling."
0.2439,Event,ADDED,eval-sanitize-1-r2-093-pwln4.18d4a28042b248c0,reason=Scheduled count=None msg=Successfully assigned compute/eval-sanitize-1-r2-093-pwln4 to kind-worker2
0.2441,Event,ADDED,eval-sanitize-1-r2-093-pwln4.18d4a2805c216d08,"reason=Pulled count=1 msg=Container image ""busybox:musl"" already present on machine"
0.2443,Event,ADDED,eval-sanitize-1-r2-093-pwln4.18d4a2805da618e5,reason=Created count=1 msg=Created container: task
0.2445,Event,ADDED,eval-sanitize-1-r2-093-pwln4.18d4a28061a6dbd3,reason=Started count=1 msg=Started container task
0.2446,Event,ADDED,eval-sanitize-1-r2-093.18d4a27f452c241a,reason=SuccessfulCreate count=1 msg=Created pod: eval-sanitize-1-r2-093-pwln4
0.2448,Event,ADDED,eval-sanitize-1-r2-093.18d4a28732f130ec,reason=Completed count=1 msg=Job completed
0.245,Event,ADDED,eval-sanitize-1-r2-094-75vrs.18d4a27f7c635194,"reason=FailedScheduling count=None msg=0/6 nodes are available: 6 node(s) had untolerated taint(s). no new claims to deallocate, preemption: 0/6 nodes are available: 6 Preemption is not helpful for scheduling."
0.2451,Event,ADDED,eval-sanitize-1-r2-094-75vrs.18d4a27fbeb67b6b,"reason=FailedScheduling count=None msg=0/6 nodes are available: 1 c_wall violated: 1 conflicting context pair(s) with node memory, 5 node(s) had untolerated taint(s). no new claims to deallocate, preemption: 0/6 nodes are available: 1 No preemption victims found for incoming pod, 5 Preemption is not helpful for scheduling."
0.2453,Event,ADDED,eval-sanitize-1-r2-094-75vrs.18d4a27fcc7b6fd8,"reason=FailedScheduling count=None msg=0/6 nodes are available: 1 c_wall violated: 1 conflicting context pair(s) with node memory, 5 node(s) had untolerated taint(s). no new claims to deallocate, preemption: 0/6 nodes are available: 1 No preemption victims found for incoming pod, 5 Preemption is not helpful for scheduling."
0.2454,Event,ADDED,eval-sanitize-1-r2-094-75vrs.18d4a280108fd353,"reason=FailedScheduling count=None msg=0/6 nodes are available: 1 c_wall violated: 2 conflicting context pair(s) with node memory, 5 node(s) had untolerated taint(s). no new claims to deallocate, preemption: 0/6 nodes are available: 1 No preemption victims found for incoming pod, 5 Preemption is not helpful for scheduling."
0.2456,Event,ADDED,eval-sanitize-1-r2-094-75vrs.18d4a2802539112f,reason=Scheduled count=None msg=Successfully assigned compute/eval-sanitize-1-r2-094-75vrs to kind-worker5
0.2458,Event,ADDED,eval-sanitize-1-r2-094-75vrs.18d4a2803f8aa94b,"reason=Pulled count=1 msg=Container image ""busybox:musl"" already present on machine"
0.246,Event,ADDED,eval-sanitize-1-r2-094-75vrs.18d4a280412ee4b1,reason=Created count=1 msg=Created container: task
0.2462,Event,ADDED,eval-sanitize-1-r2-094-75vrs.18d4a28044576c58,reason=Started count=1 msg=Started container task
0.2464,Event,ADDED,eval-sanitize-1-r2-094.18d4a27f7c5b8ffd,reason=SuccessfulCreate count=1 msg=Created pod: eval-sanitize-1-r2-094-75vrs
0.2466,Event,ADDED,eval-sanitize-1-r2-094.18d4a287089023ce,reason=Completed count=1 msg=Job completed
0.2468,Event,ADDED,eval-sanitize-1-r2-095-nsvpn.18d4a27fbdaa9f2a,"reason=FailedScheduling count=None msg=0/6 nodes are available: 1 c_wall violated: 2 conflicting context pair(s) with node memory, 5 node(s) had untolerated taint(s). no new claims to deallocate, preemption: 0/6 nodes are available: 1 No preemption victims found for incoming pod, 5 Preemption is not helpful for scheduling."
0.247,Event,ADDED,eval-sanitize-1-r2-095-nsvpn.18d4a27fcb848071,"reason=FailedScheduling count=None msg=0/6 nodes are available: 1 c_wall violated: 2 conflicting context pair(s) with node memory, 5 node(s) had untolerated taint(s). no new claims to deallocate, preemption: 0/6 nodes are available: 1 No preemption victims found for incoming pod, 5 Preemption is not helpful for scheduling."
0.2472,Event,ADDED,eval-sanitize-1-r2-095-nsvpn.18d4a28010ce4b16,reason=Scheduled count=None msg=Successfully assigned compute/eval-sanitize-1-r2-095-nsvpn to kind-worker
0.2474,Event,ADDED,eval-sanitize-1-r2-095-nsvpn.18d4a28029e27147,"reason=Pulled count=1 msg=Container image ""busybox:musl"" already present on machine"
0.2476,Event,ADDED,eval-sanitize-1-r2-095-nsvpn.18d4a2802b582e8c,reason=Created count=1 msg=Created container: task
0.2477,Event,ADDED,eval-sanitize-1-r2-095-nsvpn.18d4a2802e79d166,reason=Started count=1 msg=Started container task
0.2479,Event,ADDED,eval-sanitize-1-r2-095.18d4a27fba49f2b1,reason=SuccessfulCreate count=1 msg=Created pod: eval-sanitize-1-r2-095-nsvpn
0.2481,Event,ADDED,eval-sanitize-1-r2-095.18d4a286f381e4d5,reason=Completed count=1 msg=Job completed
0.2482,Event,ADDED,eval-sanitize-1-r2-096-phrmx.18d4a2800bcabe7b,"reason=FailedScheduling count=None msg=0/6 nodes are available: 1 c_wall violated: 3 conflicting context pair(s) with node memory, 5 node(s) had untolerated taint(s). no new claims to deallocate, preemption: 0/6 nodes are available: 1 No preemption victims found for incoming pod, 5 Preemption is not helpful for scheduling."
0.2484,Event,ADDED,eval-sanitize-1-r2-096-phrmx.18d4a2801e3839b6,"reason=FailedScheduling count=None msg=0/6 nodes are available: 1 c_wall violated: 1 conflicting context pair(s) with node memory, 1 c_wall violated: 3 conflicting context pair(s) with node memory, 4 node(s) had untolerated taint(s). no new claims to deallocate, preemption: 0/6 nodes are available: 2 No preemption victims found for incoming pod, 4 Preemption is not helpful for scheduling."
0.2486,Event,ADDED,eval-sanitize-1-r2-096-phrmx.18d4a28033950e8b,"reason=FailedScheduling count=None msg=0/6 nodes are available: 1 c_wall violated: 1 conflicting context pair(s) with node memory, 1 c_wall violated: 3 conflicting context pair(s) with node memory, 4 node(s) had untolerated taint(s). no new claims to deallocate, preemption: 0/6 nodes are available: 2 No preemption victims found for incoming pod, 4 Preemption is not helpful for scheduling."
0.2487,Event,ADDED,eval-sanitize-1-r2-096-phrmx.18d4a2804d28a5bd,reason=Scheduled count=None msg=Successfully assigned compute/eval-sanitize-1-r2-096-phrmx to kind-worker2
0.249,Event,ADDED,eval-sanitize-1-r2-096-phrmx.18d4a280648d7baa,"reason=Pulled count=1 msg=Container image ""busybox:musl"" already present on machine"
0.2492,Event,ADDED,eval-sanitize-1-r2-096-phrmx.18d4a280668f12dc,reason=Created count=1 msg=Created container: task
0.2493,Event,ADDED,eval-sanitize-1-r2-096-phrmx.18d4a2806a8059da,reason=Started count=1 msg=Started container task
0.2495,Event,ADDED,eval-sanitize-1-r2-096.18d4a2800b783ecb,reason=SuccessfulCreate count=1 msg=Created pod: eval-sanitize-1-r2-096-phrmx
0.2497,Event,ADDED,eval-sanitize-1-r2-096.18d4a2872c1f5d70,reason=Completed count=1 msg=Job completed
0.2498,Event,ADDED,eval-sanitize-1-r2-097-fv4lf.18d4a280afb52d5e,reason=Scheduled count=None msg=Successfully assigned compute/eval-sanitize-1-r2-097-fv4lf to kind-worker4
0.25,Event,ADDED,eval-sanitize-1-r2-097-fv4lf.18d4a280cb54528c,"reason=Pulled count=1 msg=Container image ""busybox:musl"" already present on machine"
0.2501,Event,ADDED,eval-sanitize-1-r2-097-fv4lf.18d4a280cca04856,reason=Created count=1 msg=Created container: task
0.2503,Event,ADDED,eval-sanitize-1-r2-097-fv4lf.18d4a280d35c93c4,reason=Started count=1 msg=Started container task
0.2506,Event,ADDED,eval-sanitize-1-r2-097.18d4a280af5f3c94,reason=SuccessfulCreate count=1 msg=Created pod: eval-sanitize-1-r2-097-fv4lf
0.2508,Event,ADDED,eval-sanitize-1-r2-097.18d4a2874cef65af,reason=Completed count=1 msg=Job completed
0.2509,Event,ADDED,eval-sanitize-1-r2-098-zqlhb.18d4a280fff8e68f,"reason=FailedScheduling count=None msg=0/6 nodes are available: 6 node(s) had untolerated taint(s). no new claims to deallocate, preemption: 0/6 nodes are available: 6 Preemption is not helpful for scheduling."
0.2511,Event,ADDED,eval-sanitize-1-r2-098-zqlhb.18d4a2851fe5bc8e,reason=Scheduled count=None msg=Successfully assigned compute/eval-sanitize-1-r2-098-zqlhb to kind-worker3
0.2513,Event,ADDED,eval-sanitize-1-r2-098-zqlhb.18d4a2853a1c673c,"reason=Pulled count=1 msg=Container image ""busybox:musl"" already present on machine"
0.2515,Event,ADDED,eval-sanitize-1-r2-098-zqlhb.18d4a2853ba04186,reason=Created count=1 msg=Created container: task
0.2517,Event,ADDED,eval-sanitize-1-r2-098-zqlhb.18d4a2853e04c9dd,reason=Started count=1 msg=Started container task
0.2518,Event,ADDED,eval-sanitize-1-r2-098.18d4a280ffeccc5d,reason=SuccessfulCreate count=1 msg=Created pod: eval-sanitize-1-r2-098-zqlhb
0.252,Event,ADDED,eval-sanitize-1-r2-098.18d4a28abefe56b2,reason=Completed count=1 msg=Job completed
0.2522,Event,ADDED,eval-sanitize-1-r2-099-ptdlv.18d4a28142c408b1,"reason=FailedScheduling count=None msg=0/6 nodes are available: 6 node(s) had untolerated taint(s). no new claims to deallocate, preemption: 0/6 nodes are available: 6 Preemption is not helpful for scheduling."
0.2523,Event,ADDED,eval-sanitize-1-r2-099-ptdlv.18d4a285201fcc3b,"reason=FailedScheduling count=None msg=0/6 nodes are available: 1 c_wall violated: 1 conflicting context pair(s) with node memory, 5 node(s) had untolerated taint(s). no new claims to deallocate, preemption: 0/6 nodes are available: 1 No preemption victims found for incoming pod, 5 Preemption is not helpful for scheduling."
0.2525,Event,ADDED,eval-sanitize-1-r2-099-ptdlv.18d4a285351c94ef,"reason=FailedScheduling count=None msg=0/6 nodes are available: 1 c_wall violated: 2 conflicting context pair(s) with node memory, 5 node(s) had untolerated taint(s). no new claims to deallocate, preemption: 0/6 nodes are available: 1 No preemption victims found for incoming pod, 5 Preemption is not helpful for scheduling."
0.2527,Event,ADDED,eval-sanitize-1-r2-099-ptdlv.18d4a28542581ec6,"reason=FailedScheduling count=None msg=0/6 nodes are available: 1 c_wall violated: 2 conflicting context pair(s) with node memory, 5 node(s) had untolerated taint(s). no new claims to deallocate, preemption: 0/6 nodes are available: 1 No preemption victims found for incoming pod, 5 Preemption is not helpful for scheduling."
0.2529,Event,ADDED,eval-sanitize-1-r2-099-ptdlv.18d4a2857911e2e1,"reason=FailedScheduling count=None msg=0/6 nodes are available: 1 c_wall violated: 1 conflicting context pair(s) with node memory, 5 node(s) had untolerated taint(s). no new claims to deallocate, preemption: 0/6 nodes are available: 1 No preemption victims found for incoming pod, 5 Preemption is not helpful for scheduling."
0.253,Event,ADDED,eval-sanitize-1-r2-099-ptdlv.18d4a285ce5a73de,"reason=FailedScheduling count=None msg=0/6 nodes are available: 1 c_wall violated: 2 conflicting context pair(s) with node memory, 5 node(s) had untolerated taint(s). no new claims to deallocate, preemption: 0/6 nodes are available: 1 No preemption victims found for incoming pod, 5 Preemption is not helpful for scheduling."
0.2532,Event,ADDED,eval-sanitize-1-r2-099-ptdlv.18d4a285d73844d8,"reason=FailedScheduling count=None msg=0/6 nodes are available: 1 c_wall violated: 2 conflicting context pair(s) with node memory, 5 node(s) had untolerated taint(s). no new claims to deallocate, preemption: 0/6 nodes are available: 1 No preemption victims found for incoming pod, 5 Preemption is not helpful for scheduling."
0.2534,Event,ADDED,eval-sanitize-1-r2-099-ptdlv.18d4a285eeff3605,"reason=FailedScheduling count=None msg=0/6 nodes are available: 1 c_wall violated: 1 conflicting context pair(s) with node memory, 1 c_wall violated: 2 conflicting context pair(s) with node memory, 4 node(s) had untolerated taint(s). no new claims to deallocate, preemption: 0/6 nodes are available: 2 No preemption victims found for incoming pod, 4 Preemption is not helpful for scheduling."
0.2536,Event,ADDED,eval-sanitize-1-r2-099-ptdlv.18d4a2863c7828ef,"reason=FailedScheduling count=None msg=0/6 nodes are available: 1 c_wall violated: 1 conflicting context pair(s) with node memory, 5 node(s) had untolerated taint(s). no new claims to deallocate, preemption: 0/6 nodes are available: 1 No preemption victims found for incoming pod, 5 Preemption is not helpful for scheduling."
0.2537,Event,ADDED,eval-sanitize-1-r2-099-ptdlv.18d4a2866d9016b5,reason=Scheduled count=None msg=Successfully assigned compute/eval-sanitize-1-r2-099-ptdlv to kind-worker4
0.2539,Event,ADDED,eval-sanitize-1-r2-099-ptdlv.18d4a28688dc54e4,"reason=Pulled count=1 msg=Container image ""busybox:musl"" already present on machine"
0.2541,Event,ADDED,eval-sanitize-1-r2-099-ptdlv.18d4a2868ad2d0d5,reason=Created count=1 msg=Created container: task
0.2543,Event,ADDED,eval-sanitize-1-r2-099-ptdlv.18d4a28690789e93,reason=Started count=1 msg=Started container task
0.2544,Event,ADDED,eval-sanitize-1-r2-099.18d4a28142b40004,reason=SuccessfulCreate count=1 msg=Created pod: eval-sanitize-1-r2-099-ptdlv
0.2546,Event,ADDED,eval-sanitize-1-r2-099.18d4a28c91c52b9a,reason=Completed count=1 msg=Job completed
0.2547,Event,ADDED,eval-sanitize-1-r2-100-2mw88.18d4a281520c9942,"reason=FailedScheduling count=None msg=0/6 nodes are available: 6 node(s) had untolerated taint(s). no new claims to deallocate, preemption: 0/6 nodes are available: 6 Preemption is not helpful for scheduling."
0.2549,Event,ADDED,eval-sanitize-1-r2-100-2mw88.18d4a28520fcecab,reason=Scheduled count=None msg=Successfully assigned compute/eval-sanitize-1-r2-100-2mw88 to kind-worker3
0.2551,Event,ADDED,eval-sanitize-1-r2-100-2mw88.18d4a2853b2df3a4,"reason=Pulled count=1 msg=Container image ""busybox:musl"" already present on machine"
0.2552,Event,ADDED,eval-sanitize-1-r2-100-2mw88.18d4a2853d37dffd,reason=Created count=1 msg=Created container: task
0.2554,Event,ADDED,eval-sanitize-1-r2-100-2mw88.18d4a285406be51a,reason=Started count=1 msg=Started container task
0.2556,Event,ADDED,eval-sanitize-1-r2-100.18d4a28152099b76,reason=SuccessfulCreate count=1 msg=Created pod: eval-sanitize-1-r2-100-2mw88
0.2557,Event,ADDED,eval-sanitize-1-r2-100.18d4a28abf751515,reason=Completed count=1 msg=Job completed
0.2559,Event,ADDED,eval-sanitize-1-r2-101-jhm66.18d4a28165a00056,"reason=FailedScheduling count=None msg=0/6 nodes are available: 6 node(s) had untolerated taint(s). no new claims to deallocate, preemption: 0/6 nodes are available: 6 Preemption is not helpful for scheduling."
0.256,Event,ADDED,eval-sanitize-1-r2-101-jhm66.18d4a28520e4ea9c,"reason=FailedScheduling count=None msg=0/6 nodes are available: 1 c_wall violated: 1 conflicting context pair(s) with node memory, 5 node(s) had untolerated taint(s). no new claims to deallocate, preemption: 0/6 nodes are available: 1 No preemption victims found for incoming pod, 5 Preemption is not helpful for scheduling."
0.2563,Event,ADDED,eval-sanitize-1-r2-101-jhm66.18d4a285361ede3b,"reason=FailedScheduling count=None msg=0/6 nodes are available: 1 c_wall violated: 2 conflicting context pair(s) with node memory, 5 node(s) had untolerated taint(s). no new claims to deallocate, preemption: 0/6 nodes are available: 1 No preemption victims found for incoming pod, 5 Preemption is not helpful for scheduling."
0.2565,Event,ADDED,eval-sanitize-1-r2-101-jhm66.18d4a285433ea319,"reason=FailedScheduling count=None msg=0/6 nodes are available: 1 c_wall violated: 2 conflicting context pair(s) with node memory, 5 node(s) had untolerated taint(s). no new claims to deallocate, preemption: 0/6 nodes are available: 1 No preemption victims found for incoming pod, 5 Preemption is not helpful for scheduling."
0.2567,Event,ADDED,eval-sanitize-1-r2-101-jhm66.18d4a285d1fff88a,reason=Scheduled count=None msg=Successfully assigned compute/eval-sanitize-1-r2-101-jhm66 to kind-worker2
0.2568,Event,ADDED,eval-sanitize-1-r2-101-jhm66.18d4a285f32f483e,"reason=Pulled count=1 msg=Container image ""busybox:musl"" already present on machine"
0.2571,Event,ADDED,eval-sanitize-1-r2-101-jhm66.18d4a285f64dde0c,reason=Created count=1 msg=Created container: task
0.2572,Event,ADDED,eval-sanitize-1-r2-101-jhm66.18d4a285fed9bb1f,reason=Started count=1 msg=Started container task
0.2574,Event,ADDED,eval-sanitize-1-r2-101.18d4a2816593c1ab,reason=SuccessfulCreate count=1 msg=Created pod: eval-sanitize-1-r2-101-jhm66
0.2576,Event,ADDED,eval-sanitize-1-r2-101.18d4a28c67e26906,reason=Completed count=1 msg=Job completed
0.2577,Event,ADDED,eval-sanitize-1-r2-102-4mk2c.18d4a2818b3839af,"reason=FailedScheduling count=None msg=0/6 nodes are available: 6 node(s) had untolerated taint(s). no new claims to deallocate, preemption: 0/6 nodes are available: 6 Preemption is not helpful for scheduling."
0.2579,Event,ADDED,eval-sanitize-1-r2-102-4mk2c.18d4a28522022ac3,reason=Scheduled count=None msg=Successfully assigned compute/eval-sanitize-1-r2-102-4mk2c to kind-worker3
0.2581,Event,ADDED,eval-sanitize-1-r2-102-4mk2c.18d4a2853ba3fb21,"reason=Pulled count=1 msg=Container image ""busybox:musl"" already present on machine"
0.2582,Event,ADDED,eval-sanitize-1-r2-102-4mk2c.18d4a2853dfab4bc,reason=Created count=1 msg=Created container: task
0.2584,Event,ADDED,eval-sanitize-1-r2-102-4mk2c.18d4a2854364e384,reason=Started count=1 msg=Started container task
0.2586,Event,ADDED,eval-sanitize-1-r2-102.18d4a2818b2e158e,reason=SuccessfulCreate count=1 msg=Created pod: eval-sanitize-1-r2-102-4mk2c
0.2587,Event,ADDED,eval-sanitize-1-r2-102.18d4a28ac051c331,reason=Completed count=1 msg=Job completed
0.2589,Event,ADDED,eval-sanitize-1-r2-103-rbjmd.18d4a2819ddaed6c,"reason=FailedScheduling count=None msg=0/6 nodes are available: 6 node(s) had untolerated taint(s). no new claims to deallocate, preemption: 0/6 nodes are available: 6 Preemption is not helpful for scheduling."
0.259,Event,ADDED,eval-sanitize-1-r2-103-rbjmd.18d4a28522f20558,reason=Scheduled count=None msg=Successfully assigned compute/eval-sanitize-1-r2-103-rbjmd to kind-worker3
0.2592,Event,ADDED,eval-sanitize-1-r2-103-rbjmd.18d4a2853c453b09,"reason=Pulled count=1 msg=Container image ""busybox:musl"" already present on machine"
0.2594,Event,ADDED,eval-sanitize-1-r2-103-rbjmd.18d4a2853efa967c,reason=Created count=1 msg=Created container: task
0.2597,Event,ADDED,eval-sanitize-1-r2-103-rbjmd.18d4a28546ee2d11,reason=Started count=1 msg=Started container task
0.2598,Event,ADDED,eval-sanitize-1-r2-103.18d4a2819de161a6,reason=SuccessfulCreate count=1 msg=Created pod: eval-sanitize-1-r2-103-rbjmd
0.26,Event,ADDED,eval-sanitize-1-r2-103.18d4a28ac0af4f6a,reason=Completed count=1 msg=Job completed
0.2603,Event,ADDED,eval-sanitize-1-r2-104-t6ps7.18d4a281dabb8f37,"reason=FailedScheduling count=None msg=0/6 nodes are available: 6 node(s) had untolerated taint(s). no new claims to deallocate, preemption: 0/6 nodes are available: 6 Preemption is not helpful for scheduling."
0.2604,Event,ADDED,eval-sanitize-1-r2-104-t6ps7.18d4a28521f902f5,"reason=FailedScheduling count=None msg=0/6 nodes are available: 1 c_wall violated: 1 conflicting context pair(s) with node memory, 5 node(s) had untolerated taint(s). no new claims to deallocate, preemption: 0/6 nodes are available: 1 No preemption victims found for incoming pod, 5 Preemption is not helpful for scheduling."
0.2606,Event,ADDED,eval-sanitize-1-r2-104-t6ps7.18d4a28536cdda4e,"reason=FailedScheduling count=None msg=0/6 nodes are available: 1 c_wall violated: 1 conflicting context pair(s) with node memory, 5 node(s) had untolerated taint(s). no new claims to deallocate, preemption: 0/6 nodes are available: 1 No preemption victims found for incoming pod, 5 Preemption is not helpful for scheduling."
0.2608,Event,ADDED,eval-sanitize-1-r2-104-t6ps7.18d4a2857224dd55,reason=Scheduled count=None msg=Successfully assigned compute/eval-sanitize-1-r2-104-t6ps7 to kind-worker
0.261,Event,ADDED,eval-sanitize-1-r2-104-t6ps7.18d4a2858f4fc4aa,"reason=Pulled count=1 msg=Container image ""busybox:musl"" already present on machine"
0.2612,Event,ADDED,eval-sanitize-1-r2-104-t6ps7.18d4a28590df2a1c,reason=Created count=1 msg=Created container: task
0.2613,Event,ADDED,eval-sanitize-1-r2-104-t6ps7.18d4a28597ae6517,reason=Started count=1 msg=Started container task
0.2615,Event,ADDED,eval-sanitize-1-r2-104.18d4a281daaf036d,reason=SuccessfulCreate count=1 msg=Created pod: eval-sanitize-1-r2-104-t6ps7
0.2617,Event,ADDED,eval-sanitize-1-r2-104.18d4a28bb51c48a9,reason=Completed count=1 msg=Job completed
0.2618,Event,ADDED,eval-sanitize-1-r2-105-dtkpv.18d4a2820dc2b50d,"reason=FailedScheduling count=None msg=0/6 nodes are available: 6 node(s) had untolerated taint(s). no new claims to deallocate, preemption: 0/6 nodes are available: 6 Preemption is not helpful for scheduling."
0.262,Event,ADDED,eval-sanitize-1-r2-105-dtkpv.18d4a285256fb81d,"reason=FailedScheduling count=None msg=0/6 nodes are available: 1 c_wall violated: 1 conflicting context pair(s) with node memory, 5 node(s) had untolerated taint(s). no new claims to deallocate, preemption: 0/6 nodes are available: 1 No preemption victims found for incoming pod, 5 Preemption is not helpful for scheduling."
0.2622,Event,ADDED,eval-sanitize-1-r2-105-dtkpv.18d4a28536ffb8a6,"reason=FailedScheduling count=None msg=0/6 nodes are available: 1 c_wall violated: 1 conflicting context pair(s) with node memory, 5 node(s) had untolerated taint(s). no new claims to deallocate, preemption: 0/6 nodes are available: 1 No preemption victims found for incoming pod, 5 Preemption is not helpful for scheduling."
0.2623,Event,ADDED,eval-sanitize-1-r2-105-dtkpv.18d4a28572732097,reason=Scheduled count=None msg=Successfully assigned compute/eval-sanitize-1-r2-105-dtkpv to kind-worker
0.2625,Event,ADDED,eval-sanitize-1-r2-105-dtkpv.18d4a2858e602f07,"reason=Pulled count=1 msg=Container image ""busybox:musl"" already present on machine"
0.2627,Event,ADDED,eval-sanitize-1-r2-105-dtkpv.18d4a2859037d4b2,reason=Created count=1 msg=Created container: task
0.2628,Event,ADDED,eval-sanitize-1-r2-105-dtkpv.18d4a28597ae70ed,reason=Started count=1 msg=Started container task
0.263,Event,ADDED,eval-sanitize-1-r2-105.18d4a2820db92b9f,reason=SuccessfulCreate count=1 msg=Created pod: eval-sanitize-1-r2-105-dtkpv
0.2634,Event,ADDED,eval-sanitize-1-r2-105.18d4a28bca4ff4a3,reason=Completed count=1 msg=Job completed
0.2637,Event,ADDED,eval-sanitize-1-r2-106-99rts.18d4a282480bdb4c,"reason=FailedScheduling count=None msg=0/6 nodes are available: 6 node(s) had untolerated taint(s). no new claims to deallocate, preemption: 0/6 nodes are available: 6 Preemption is not helpful for scheduling."
0.2639,Event,ADDED,eval-sanitize-1-r2-106-99rts.18d4a28525f1673a,"reason=FailedScheduling count=None msg=0/6 nodes are available: 1 c_wall violated: 2 conflicting context pair(s) with node memory, 5 node(s) had untolerated taint(s). no new claims to deallocate, preemption: 0/6 nodes are available: 1 No preemption victims found for incoming pod, 5 Preemption is not helpful for scheduling."
0.264,Event,ADDED,eval-sanitize-1-r2-106-99rts.18d4a2853730e096,"reason=FailedScheduling count=None msg=0/6 nodes are available: 1 c_wall violated: 3 conflicting context pair(s) with node memory, 5 node(s) had untolerated taint(s). no new claims to deallocate, preemption: 0/6 nodes are available: 1 No preemption victims found for incoming pod, 5 Preemption is not helpful for scheduling."
0.2643,Event,ADDED,eval-sanitize-1-r2-106-99rts.18d4a28543db1964,"reason=FailedScheduling count=None msg=0/6 nodes are available: 1 c_wall violated: 3 conflicting context pair(s) with node memory, 5 node(s) had untolerated taint(s). no new claims to deallocate, preemption: 0/6 nodes are available: 1 No preemption victims found for incoming pod, 5 Preemption is not helpful for scheduling."
0.2645,Event,ADDED,eval-sanitize-1-r2-106-99rts.18d4a2857cbf9696,"reason=FailedScheduling count=None msg=0/6 nodes are available: 1 c_wall violated: 1 conflicting context pair(s) with node memory, 5 node(s) had untolerated taint(s). no new claims to deallocate, preemption: 0/6 nodes are available: 1 No preemption victims found for incoming pod, 5 Preemption is not helpful for scheduling."
0.2646,Event,ADDED,eval-sanitize-1-r2-106-99rts.18d4a285d20122ca,reason=Scheduled count=None msg=Successfully assigned compute/eval-sanitize-1-r2-106-99rts to kind-worker2
0.2649,Event,ADDED,eval-sanitize-1-r2-106-99rts.18d4a285f2e452a4,"reason=Pulled count=1 msg=Container image ""busybox:musl"" already present on machine"
0.265,Event,ADDED,eval-sanitize-1-r2-106-99rts.18d4a285f4ccb887,reason=Created count=1 msg=Created container: task
0.2653,Event,ADDED,eval-sanitize-1-r2-106-99rts.18d4a285fedb07a8,reason=Started count=1 msg=Started container task
0.2656,Event,ADDED,eval-sanitize-1-r2-106.18d4a2824801f10f,reason=SuccessfulCreate count=1 msg=Created pod: eval-sanitize-1-r2-106-99rts
0.2658,Event,ADDED,eval-sanitize-1-r2-106.18d4a28c5a39b4db,reason=Completed count=1 msg=Job completed
0.2659,Event,ADDED,eval-sanitize-1-r2-107-vfmvr.18d4a28283a2d262,"reason=FailedScheduling count=None msg=0/6 nodes are available: 6 node(s) had untolerated taint(s). no new claims to deallocate, preemption: 0/6 nodes are available: 6 Preemption is not helpful for scheduling."
0.2661,Event,ADDED,eval-sanitize-1-r2-107-vfmvr.18d4a2852733512b,"reason=FailedScheduling count=None msg=0/6 nodes are available: 1 c_wall violated: 1 conflicting context pair(s) with node memory, 5 node(s) had untolerated taint(s). no new claims to deallocate, preemption: 0/6 nodes are available: 1 No preemption victims found for incoming pod, 5 Preemption is not helpful for scheduling."
0.2664,Event,ADDED,eval-sanitize-1-r2-107-vfmvr.18d4a28538efc8d3,"reason=FailedScheduling count=None msg=0/6 nodes are available: 1 c_wall violated: 1 conflicting context pair(s) with node memory, 5 node(s) had untolerated taint(s). no new claims to deallocate, preemption: 0/6 nodes are available: 1 No preemption victims found for incoming pod, 5 Preemption is not helpful for scheduling."
0.2666,Event,ADDED,eval-sanitize-1-r2-107-vfmvr.18d4a28561be5be8,reason=Scheduled count=None msg=Successfully assigned compute/eval-sanitize-1-r2-107-vfmvr to kind-worker
0.2668,Event,ADDED,eval-sanitize-1-r2-107-vfmvr.18d4a2858274704c,"reason=Pulled count=1 msg=Container image ""busybox:musl"" already present on machine"
0.2671,Event,ADDED,eval-sanitize-1-r2-107-vfmvr.18d4a28584b924b2,reason=Created count=1 msg=Created container: task
0.2673,Event,ADDED,eval-sanitize-1-r2-107-vfmvr.18d4a2858948c3c4,reason=Started count=1 msg=Started container task
0.2675,Event,ADDED,eval-sanitize-1-r2-107.18d4a2828394ac1a,reason=SuccessfulCreate count=1 msg=Created pod: eval-sanitize-1-r2-107-vfmvr
0.2676,Event,ADDED,eval-sanitize-1-r2-107.18d4a28ba9629b69,reason=Completed count=1 msg=Job completed
0.2681,Event,ADDED,eval-sanitize-1-r2-108-4z64w.18d4a282c022d5a5,"reason=FailedScheduling count=None msg=0/6 nodes are available: 6 node(s) had untolerated taint(s). no new claims to deallocate, preemption: 0/6 nodes are available: 6 Preemption is not helpful for scheduling."
0.2684,Event,ADDED,eval-sanitize-1-r2-108-4z64w.18d4a28527a21f84,"reason=FailedScheduling count=None msg=0/6 nodes are available: 1 c_wall violated: 2 conflicting context pair(s) with node memory, 5 node(s) had untolerated taint(s). no new claims to deallocate, preemption: 0/6 nodes are available: 1 No preemption victims found for incoming pod, 5 Preemption is not helpful for scheduling."
0.2687,Event,ADDED,eval-sanitize-1-r2-108-4z64w.18d4a285393a8aa2,"reason=FailedScheduling count=None msg=0/6 nodes are available: 1 c_wall violated: 3 conflicting context pair(s) with node memory, 5 node(s) had untolerated taint(s). no new claims to deallocate, preemption: 0/6 nodes are available: 1 No preemption victims found for incoming pod, 5 Preemption is not helpful for scheduling."
0.2691,Event,ADDED,eval-sanitize-1-r2-108-4z64w.18d4a28548602c50,"reason=FailedScheduling count=None msg=0/6 nodes are available: 1 c_wall violated: 3 conflicting context pair(s) with node memory, 5 node(s) had untolerated taint(s). no new claims to deallocate, preemption: 0/6 nodes are available: 1 No preemption victims found for incoming pod, 5 Preemption is not helpful for scheduling."
0.2693,Event,ADDED,eval-sanitize-1-r2-108-4z64w.18d4a2857384dd12,"reason=FailedScheduling count=None msg=0/6 nodes are available: 1 c_wall violated: 1 conflicting context pair(s) with node memory, 5 node(s) had untolerated taint(s). no new claims to deallocate, preemption: 0/6 nodes are available: 1 No preemption victims found for incoming pod, 5 Preemption is not helpful for scheduling."
0.2695,Event,ADDED,eval-sanitize-1-r2-108-4z64w.18d4a2857db0589c,"reason=FailedScheduling count=None msg=0/6 nodes are available: 1 c_wall violated: 1 conflicting context pair(s) with node memory, 5 node(s) had untolerated taint(s). no new claims to deallocate, preemption: 0/6 nodes are available: 1 No preemption victims found for incoming pod, 5 Preemption is not helpful for scheduling."
0.2698,Event,ADDED,eval-sanitize-1-r2-108-4z64w.18d4a285cbea9846,reason=Scheduled count=None msg=Successfully assigned compute/eval-sanitize-1-r2-108-4z64w to kind-worker2
0.27,Event,ADDED,eval-sanitize-1-r2-108-4z64w.18d4a285e6d959f7,"reason=Pulled count=1 msg=Container image ""busybox:musl"" already present on machine"
0.2701,Event,ADDED,eval-sanitize-1-r2-108-4z64w.18d4a285ea840fb2,reason=Created count=1 msg=Created container: task
0.2703,Event,ADDED,eval-sanitize-1-r2-108-4z64w.18d4a285f2dd9468,reason=Started count=1 msg=Started container task
0.2705,Event,ADDED,eval-sanitize-1-r2-108.18d4a282c017afb8,reason=SuccessfulCreate count=1 msg=Created pod: eval-sanitize-1-r2-108-4z64w
0.2707,Event,ADDED,eval-sanitize-1-r2-108.18d4a28c55f8c6bd,reason=Completed count=1 msg=Job completed
0.2709,Event,ADDED,eval-sanitize-1-r2-109-4vv67.18d4a282fa5fb0a7,"reason=FailedScheduling count=None msg=0/6 nodes are available: 6 node(s) had untolerated taint(s). no new claims to deallocate, preemption: 0/6 nodes are available: 6 Preemption is not helpful for scheduling."
0.2712,Event,ADDED,eval-sanitize-1-r2-109-4vv67.18d4a2852928e419,"reason=FailedScheduling count=None msg=0/6 nodes are available: 1 c_wall violated: 3 conflicting context pair(s) with node memory, 5 node(s) had untolerated taint(s). no new claims to deallocate, preemption: 0/6 nodes are available: 1 No preemption victims found for incoming pod, 5 Preemption is not helpful for scheduling."
0.2714,Event,ADDED,eval-sanitize-1-r2-109-4vv67.18d4a2853accfe13,"reason=FailedScheduling count=None msg=0/6 nodes are available: 1 c_wall violated: 4 conflicting context pair(s) with node memory, 5 node(s) had untolerated taint(s). no new claims to deallocate, preemption: 0/6 nodes are available: 1 No preemption victims found for incoming pod, 5 Preemption is not helpful for scheduling."
0.2716,Event,ADDED,eval-sanitize-1-r2-109-4vv67.18d4a2854932f320,"reason=FailedScheduling count=None msg=0/6 nodes are available: 1 c_wall violated: 4 conflicting context pair(s) with node memory, 5 node(s) had untolerated taint(s). no new claims to deallocate, preemption: 0/6 nodes are available: 1 No preemption victims found for incoming pod, 5 Preemption is not helpful for scheduling."
0.2718,Event,ADDED,eval-sanitize-1-r2-109-4vv67.18d4a285766cb03a,"reason=FailedScheduling count=None msg=0/6 nodes are available: 1 c_wall violated: 1 conflicting context pair(s) with node memory, 5 node(s) had untolerated taint(s). no new claims to deallocate, preemption: 0/6 nodes are available: 1 No preemption victims found for incoming pod, 5 Preemption is not helpful for scheduling."
0.272,Event,ADDED,eval-sanitize-1-r2-109-4vv67.18d4a2857ddc8e5d,"reason=FailedScheduling count=None msg=0/6 nodes are available: 1 c_wall violated: 1 conflicting context pair(s) with node memory, 5 node(s) had untolerated taint(s). no new claims to deallocate, preemption: 0/6 nodes are available: 1 No preemption victims found for incoming pod, 5 Preemption is not helpful for scheduling."
0.2722,Event,ADDED,eval-sanitize-1-r2-109-4vv67.18d4a285cbcd41e7,"reason=FailedScheduling count=None msg=0/6 nodes are available: 1 c_wall violated: 1 conflicting context pair(s) with node memory, 5 node(s) had untolerated taint(s). no new claims to deallocate, preemption: 0/6 nodes are available: 1 No preemption victims found for incoming pod, 5 Preemption is not helpful for scheduling."
0.2725,Event,ADDED,eval-sanitize-1-r2-109-4vv67.18d4a285d26be044,"reason=FailedScheduling count=None msg=0/6 nodes are available: 1 c_wall violated: 1 conflicting context pair(s) with node memory, 5 node(s) had untolerated taint(s). no new claims to deallocate, preemption: 0/6 nodes are available: 1 No preemption victims found for incoming pod, 5 Preemption is not helpful for scheduling."
0.2726,Event,ADDED,eval-sanitize-1-r2-109-4vv67.18d4a285e63492fe,reason=Scheduled count=None msg=Successfully assigned compute/eval-sanitize-1-r2-109-4vv67 to kind-worker5
0.2728,Event,ADDED,eval-sanitize-1-r2-109-4vv67.18d4a28605b61447,"reason=Pulled count=1 msg=Container image ""busybox:musl"" already present on machine"
0.273,Event,ADDED,eval-sanitize-1-r2-109-4vv67.18d4a28606e40db2,reason=Created count=1 msg=Created container: task
0.2731,Event,ADDED,eval-sanitize-1-r2-109-4vv67.18d4a2860c41b047,reason=Started count=1 msg=Started container task
0.2734,Event,ADDED,eval-sanitize-1-r2-109.18d4a282fa5541ed,reason=SuccessfulCreate count=1 msg=Created pod: eval-sanitize-1-r2-109-4vv67
0.2735,Event,ADDED,eval-sanitize-1-r2-109.18d4a28c3b4339b8,reason=Completed count=1 msg=Job completed
0.2737,Event,ADDED,eval-sanitize-1-r2-110-47c8s.18d4a28337e0cf39,"reason=FailedScheduling count=None msg=0/6 nodes are available: 6 node(s) had untolerated taint(s). no new claims to deallocate, preemption: 0/6 nodes are available: 6 Preemption is not helpful for scheduling."
0.2738,Event,ADDED,eval-sanitize-1-r2-110-47c8s.18d4a28529a8a23f,"reason=FailedScheduling count=None msg=0/6 nodes are available: 1 c_wall violated: 3 conflicting context pair(s) with node memory, 5 node(s) had untolerated taint(s). no new claims to deallocate, preemption: 0/6 nodes are available: 1 No preemption victims found for incoming pod, 5 Preemption is not helpful for scheduling."
0.274,Event,ADDED,eval-sanitize-1-r2-110-47c8s.18d4a2853c487ee9,"reason=FailedScheduling count=None msg=0/6 nodes are available: 1 c_wall violated: 4 conflicting context pair(s) with node memory, 5 node(s) had untolerated taint(s). no new claims to deallocate, preemption: 0/6 nodes are available: 1 No preemption victims found for incoming pod, 5 Preemption is not helpful for scheduling."
0.2742,Event,ADDED,eval-sanitize-1-r2-110-47c8s.18d4a285495fcd12,"reason=FailedScheduling count=None msg=0/6 nodes are available: 1 c_wall violated: 4 conflicting context pair(s) with node memory, 5 node(s) had untolerated taint(s). no new claims to deallocate, preemption: 0/6 nodes are available: 1 No preemption victims found for incoming pod, 5 Preemption is not helpful for scheduling."
0.2743,Event,ADDED,eval-sanitize-1-r2-110-47c8s.18d4a2857732b909,"reason=FailedScheduling count=None msg=0/6 nodes are available: 1 c_wall violated: 1 conflicting context pair(s) with node memory, 5 node(s) had untolerated taint(s). no new claims to deallocate, preemption: 0/6 nodes are available: 1 No preemption victims found for incoming pod, 5 Preemption is not helpful for scheduling."
0.2745,Event,ADDED,eval-sanitize-1-r2-110-47c8s.18d4a285cc8c9dc7,"reason=FailedScheduling count=None msg=0/6 nodes are available: 1 c_wall violated: 1 conflicting context pair(s) with node memory, 5 node(s) had untolerated taint(s). no new claims to deallocate, preemption: 0/6 nodes are available: 1 No preemption victims found for incoming pod, 5 Preemption is not helpful for scheduling."
0.2747,Event,ADDED,eval-sanitize-1-r2-110-47c8s.18d4a285d29cd8c1,"reason=FailedScheduling count=None msg=0/6 nodes are available: 1 c_wall violated: 1 conflicting context pair(s) with node memory, 5 node(s) had untolerated taint(s). no new claims to deallocate, preemption: 0/6 nodes are available: 1 No preemption victims found for incoming pod, 5 Preemption is not helpful for scheduling."
0.2748,Event,ADDED,eval-sanitize-1-r2-110-47c8s.18d4a285de3a3b93,reason=Scheduled count=None msg=Successfully assigned compute/eval-sanitize-1-r2-110-47c8s to kind-worker5
0.275,Event,ADDED,eval-sanitize-1-r2-110-47c8s.18d4a285fedb5143,"reason=Pulled count=1 msg=Container image ""busybox:musl"" already present on machine"
0.2752,Event,ADDED,eval-sanitize-1-r2-110-47c8s.18d4a28600bffe80,reason=Created count=1 msg=Created container: task
0.2753,Event,ADDED,eval-sanitize-1-r2-110-47c8s.18d4a28604ca641e,reason=Started count=1 msg=Started container task
0.2755,Event,ADDED,eval-sanitize-1-r2-110.18d4a28337d796e8,reason=SuccessfulCreate count=1 msg=Created pod: eval-sanitize-1-r2-110-47c8s
0.2757,Event,ADDED,eval-sanitize-1-r2-110.18d4a28c7917d56f,reason=Completed count=1 msg=Job completed
0.2758,Event,ADDED,eval-sanitize-1-r2-111-xr87v.18d4a2837350ce6f,"reason=FailedScheduling count=None msg=0/6 nodes are available: 6 node(s) had untolerated taint(s). no new claims to deallocate, preemption: 0/6 nodes are available: 6 Preemption is not helpful for scheduling."
0.2759,Event,ADDED,eval-sanitize-1-r2-111-xr87v.18d4a2852a6d159b,reason=Scheduled count=None msg=Successfully assigned compute/eval-sanitize-1-r2-111-xr87v to kind-worker3
0.2761,Event,ADDED,eval-sanitize-1-r2-111-xr87v.18d4a28547167b64,"reason=Pulled count=1 msg=Container image ""busybox:musl"" already present on machine"
0.2763,Event,ADDED,eval-sanitize-1-r2-111-xr87v.18d4a28548d0fb7a,reason=Created count=1 msg=Created container: task
0.2764,Event,ADDED,eval-sanitize-1-r2-111-xr87v.18d4a2854f2e9ed0,reason=Started count=1 msg=Started container task
0.2766,Event,ADDED,eval-sanitize-1-r2-111.18d4a2837346498e,reason=SuccessfulCreate count=1 msg=Created pod: eval-sanitize-1-r2-111-xr87v
0.2768,Event,ADDED,eval-sanitize-1-r2-111.18d4a28abf2ee584,reason=Completed count=1 msg=Job completed
0.2769,Event,ADDED,eval-sanitize-1-r2-112-trcmc.18d4a283b2b4148c,"reason=FailedScheduling count=None msg=0/6 nodes are available: 6 node(s) had untolerated taint(s). no new claims to deallocate, preemption: 0/6 nodes are available: 6 Preemption is not helpful for scheduling."
0.2771,Event,ADDED,eval-sanitize-1-r2-112-trcmc.18d4a2852b667031,"reason=FailedScheduling count=None msg=0/6 nodes are available: 1 c_wall violated: 2 conflicting context pair(s) with node memory, 5 node(s) had untolerated taint(s). no new claims to deallocate, preemption: 0/6 nodes are available: 1 No preemption victims found for incoming pod, 5 Preemption is not helpful for scheduling."
0.2773,Event,ADDED,eval-sanitize-1-r2-112-trcmc.18d4a2853d07538c,"reason=FailedScheduling count=None msg=0/6 nodes are available: 1 c_wall violated: 2 conflicting context pair(s) with node memory, 5 node(s) had untolerated taint(s). no new claims to deallocate, preemption: 0/6 nodes are available: 1 No preemption victims found for incoming pod, 5 Preemption is not helpful for scheduling."
0.2776,Event,ADDED,eval-sanitize-1-r2-112-trcmc.18d4a28577d8c084,"reason=FailedScheduling count=None msg=0/6 nodes are available: 1 c_wall violated: 2 conflicting context pair(s) with node memory, 5 node(s) had untolerated taint(s). no new claims to deallocate, preemption: 0/6 nodes are available: 1 No preemption victims found for incoming pod, 5 Preemption is not helpful for scheduling."
0.2777,Event,ADDED,eval-sanitize-1-r2-112-trcmc.18d4a2857eb9b51d,"reason=FailedScheduling count=None msg=0/6 nodes are available: 1 c_wall violated: 2 conflicting context pair(s) with node memory, 5 node(s) had untolerated taint(s). no new claims to deallocate, preemption: 0/6 nodes are available: 1 No preemption victims found for incoming pod, 5 Preemption is not helpful for scheduling."
0.278,Event,ADDED,eval-sanitize-1-r2-112-trcmc.18d4a285cca61b71,reason=Scheduled count=None msg=Successfully assigned compute/eval-sanitize-1-r2-112-trcmc to kind-worker2
0.2781,Event,ADDED,eval-sanitize-1-r2-112-trcmc.18d4a285e7ca861c,"reason=Pulled count=1 msg=Container image ""busybox:musl"" already present on machine"
0.2783,Event,ADDED,eval-sanitize-1-r2-112-trcmc.18d4a285eafff7a4,reason=Created count=1 msg=Created container: task
0.2785,Event,ADDED,eval-sanitize-1-r2-112-trcmc.18d4a285f2e0c005,reason=Started count=1 msg=Started container task
0.2786,Event,ADDED,eval-sanitize-1-r2-112.18d4a283b2a83930,reason=SuccessfulCreate count=1 msg=Created pod: eval-sanitize-1-r2-112-trcmc
0.2788,Event,ADDED,eval-sanitize-1-r2-112.18d4a28c701f3b97,reason=Completed count=1 msg=Job completed
0.2789,Event,ADDED,eval-sanitize-1-r2-113-mvvs9.18d4a283e912835a,"reason=FailedScheduling count=None msg=0/6 nodes are available: 6 node(s) had untolerated taint(s). no new claims to deallocate, preemption: 0/6 nodes are available: 6 Preemption is not helpful for scheduling."
0.2791,Event,ADDED,eval-sanitize-1-r2-113-mvvs9.18d4a2852be59cff,"reason=FailedScheduling count=None msg=0/6 nodes are available: 1 c_wall violated: 3 conflicting context pair(s) with node memory, 5 node(s) had untolerated taint(s). no new claims to deallocate, preemption: 0/6 nodes are available: 1 No preemption victims found for incoming pod, 5 Preemption is not helpful for scheduling."
0.2792,Event,ADDED,eval-sanitize-1-r2-113-mvvs9.18d4a2853d56bc12,"reason=FailedScheduling count=None msg=0/6 nodes are available: 1 c_wall violated: 4 conflicting context pair(s) with node memory, 5 node(s) had untolerated taint(s). no new claims to deallocate, preemption: 0/6 nodes are available: 1 No preemption victims found for incoming pod, 5 Preemption is not helpful for scheduling."
0.2794,Event,ADDED,eval-sanitize-1-r2-113-mvvs9.18d4a28549be6de7,"reason=FailedScheduling count=None msg=0/6 nodes are available: 1 c_wall violated: 4 conflicting context pair(s) with node memory, 5 node(s) had untolerated taint(s). no new claims to deallocate, preemption: 0/6 nodes are available: 1 No preemption victims found for incoming pod, 5 Preemption is not helpful for scheduling."
0.2796,Event,ADDED,eval-sanitize-1-r2-113-mvvs9.18d4a28578571003,"reason=FailedScheduling count=None msg=0/6 nodes are available: 1 c_wall violated: 1 conflicting context pair(s) with node memory, 5 node(s) had untolerated taint(s). no new claims to deallocate, preemption: 0/6 nodes are available: 1 No preemption victims found for incoming pod, 5 Preemption is not helpful for scheduling."
0.2798,Event,ADDED,eval-sanitize-1-r2-113-mvvs9.18d4a285cd4d2d46,"reason=FailedScheduling count=None msg=0/6 nodes are available: 1 c_wall violated: 1 conflicting context pair(s) with node memory, 5 node(s) had untolerated taint(s). no new claims to deallocate, preemption: 0/6 nodes are available: 1 No preemption victims found for incoming pod, 5 Preemption is not helpful for scheduling."
0.2799,Event,ADDED,eval-sanitize-1-r2-113-mvvs9.18d4a285d2cbc3d9,"reason=FailedScheduling count=None msg=0/6 nodes are available: 1 c_wall violated: 1 conflicting context pair(s) with node memory, 5 node(s) had untolerated taint(s). no new claims to deallocate, preemption: 0/6 nodes are available: 1 No preemption victims found for incoming pod, 5 Preemption is not helpful for scheduling."
0.2801,Event,ADDED,eval-sanitize-1-r2-113-mvvs9.18d4a285dfd71b90,reason=Scheduled count=None msg=Successfully assigned compute/eval-sanitize-1-r2-113-mvvs9 to kind-worker5
0.2802,Event,ADDED,eval-sanitize-1-r2-113-mvvs9.18d4a285fefebcef,"reason=Pulled count=1 msg=Container image ""busybox:musl"" already present on machine"
0.2804,Event,ADDED,eval-sanitize-1-r2-113-mvvs9.18d4a2860173f408,reason=Created count=1 msg=Created container: task
0.2806,Event,ADDED,eval-sanitize-1-r2-113-mvvs9.18d4a2860533dbf0,reason=Started count=1 msg=Started container task
0.2808,Event,ADDED,eval-sanitize-1-r2-113.18d4a283e9062dce,reason=SuccessfulCreate count=1 msg=Created pod: eval-sanitize-1-r2-113-mvvs9
0.2809,Event,ADDED,eval-sanitize-1-r2-113.18d4a28c382d35fb,reason=Completed count=1 msg=Job completed
0.2811,Event,ADDED,eval-sanitize-1-r2-114-57jdt.18d4a2842aead51c,"reason=FailedScheduling count=None msg=0/6 nodes are available: 6 node(s) had untolerated taint(s). no new claims to deallocate, preemption: 0/6 nodes are available: 6 Preemption is not helpful for scheduling."
0.2814,Event,ADDED,eval-sanitize-1-r2-114-57jdt.18d4a2852edd66fa,reason=Scheduled count=None msg=Successfully assigned compute/eval-sanitize-1-r2-114-57jdt to kind-worker3
0.2816,Event,ADDED,eval-sanitize-1-r2-114-57jdt.18d4a285487c44c9,"reason=Pulled count=1 msg=Container image ""busybox:musl"" already present on machine"
0.2817,Event,ADDED,eval-sanitize-1-r2-114-57jdt.18d4a28549c8dc98,reason=Created count=1 msg=Created container: task
0.2819,Event,ADDED,eval-sanitize-1-r2-114-57jdt.18d4a2854f312353,reason=Started count=1 msg=Started container task
0.2822,Event,ADDED,eval-sanitize-1-r2-114.18d4a2842ae0962a,reason=SuccessfulCreate count=1 msg=Created pod: eval-sanitize-1-r2-114-57jdt
0.2824,Event,ADDED,eval-sanitize-1-r2-114.18d4a28ac0214770,reason=Completed count=1 msg=Job completed
0.2825,Event,ADDED,eval-sanitize-1-r2-115-6dddm.18d4a2846001acf8,"reason=FailedScheduling count=None msg=0/6 nodes are available: 6 node(s) had untolerated taint(s). no new claims to deallocate, preemption: 0/6 nodes are available: 6 Preemption is not helpful for scheduling."
0.2827,Event,ADDED,eval-sanitize-1-r2-115-6dddm.18d4a2852edcc027,reason=Scheduled count=None msg=Successfully assigned compute/eval-sanitize-1-r2-115-6dddm to kind-worker3
0.283,Event,ADDED,eval-sanitize-1-r2-115-6dddm.18d4a2854c09d5f9,"reason=Pulled count=1 msg=Container image ""busybox:musl"" already present on machine"
0.2831,Event,ADDED,eval-sanitize-1-r2-115-6dddm.18d4a2854d8c8f8b,reason=Created count=1 msg=Created container: task
0.2833,Event,ADDED,eval-sanitize-1-r2-115-6dddm.18d4a285508a6985,reason=Started count=1 msg=Started container task
0.2835,Event,ADDED,eval-sanitize-1-r2-115.18d4a2845ff9d538,reason=SuccessfulCreate count=1 msg=Created pod: eval-sanitize-1-r2-115-6dddm
0.2836,Event,ADDED,eval-sanitize-1-r2-115.18d4a28abf2e1d6b,reason=Completed count=1 msg=Job completed
0.2838,Event,ADDED,eval-sanitize-1-r2-116-wmxf7.18d4a2849b925863,"reason=FailedScheduling count=None msg=0/6 nodes are available: 6 node(s) had untolerated taint(s). no new claims to deallocate, preemption: 0/6 nodes are available: 6 Preemption is not helpful for scheduling."
0.2839,Event,ADDED,eval-sanitize-1-r2-116-wmxf7.18d4a2852edfa874,"reason=FailedScheduling count=None msg=0/6 nodes are available: 1 c_wall violated: 2 conflicting context pair(s) with node memory, 5 node(s) had untolerated taint(s). no new claims to deallocate, preemption: 0/6 nodes are available: 1 No preemption victims found for incoming pod, 5 Preemption is not helpful for scheduling."
0.2841,Event,ADDED,eval-sanitize-1-r2-116-wmxf7.18d4a2853e081fdc,"reason=FailedScheduling count=None msg=0/6 nodes are available: 1 c_wall violated: 2 conflicting context pair(s) with node memory, 5 node(s) had untolerated taint(s). no new claims to deallocate, preemption: 0/6 nodes are available: 1 No preemption victims found for incoming pod, 5 Preemption is not helpful for scheduling."
0.2843,Event,ADDED,eval-sanitize-1-r2-116-wmxf7.18d4a28578de2eb5,"reason=FailedScheduling count=None msg=0/6 nodes are available: 1 c_wall violated: 1 conflicting context pair(s) with node memory, 5 node(s) had untolerated taint(s). no new claims to deallocate, preemption: 0/6 nodes are available: 1 No preemption victims found for incoming pod, 5 Preemption is not helpful for scheduling."
0.2845,Event,ADDED,eval-sanitize-1-r2-116-wmxf7.18d4a285cdea7ed2,"reason=FailedScheduling count=None msg=0/6 nodes are available: 1 c_wall violated: 2 conflicting context pair(s) with node memory, 5 node(s) had untolerated taint(s). no new claims to deallocate, preemption: 0/6 nodes are available: 1 No preemption victims found for incoming pod, 5 Preemption is not helpful for scheduling."
0.2847,Event,ADDED,eval-sanitize-1-r2-116-wmxf7.18d4a285d301a95b,"reason=FailedScheduling count=None msg=0/6 nodes are available: 1 c_wall violated: 2 conflicting context pair(s) with node memory, 5 node(s) had untolerated taint(s). no new claims to deallocate, preemption: 0/6 nodes are available: 1 No preemption victims found for incoming pod, 5 Preemption is not helpful for scheduling."
0.2849,Event,ADDED,eval-sanitize-1-r2-116-wmxf7.18d4a285ea590490,"reason=FailedScheduling count=None msg=0/6 nodes are available: 1 c_wall violated: 1 conflicting context pair(s) with node memory, 1 c_wall violated: 2 conflicting context pair(s) with node memory, 4 node(s) had untolerated taint(s). no new claims to deallocate, preemption: 0/6 nodes are available: 2 No preemption victims found for incoming pod, 4 Preemption is not helpful for scheduling."
0.285,Event,ADDED,eval-sanitize-1-r2-116-wmxf7.18d4a2863ce58096,"reason=FailedScheduling count=None msg=0/6 nodes are available: 1 c_wall violated: 1 conflicting context pair(s) with node memory, 5 node(s) had untolerated taint(s). no new claims to deallocate, preemption: 0/6 nodes are available: 1 No preemption victims found for incoming pod, 5 Preemption is not helpful for scheduling."
0.2852,Event,ADDED,eval-sanitize-1-r2-116-wmxf7.18d4a2866df6b55d,reason=Scheduled count=None msg=Successfully assigned compute/eval-sanitize-1-r2-116-wmxf7 to kind-worker4
0.2854,Event,ADDED,eval-sanitize-1-r2-116-wmxf7.18d4a28689209c8f,"reason=Pulled count=1 msg=Container image ""busybox:musl"" already present on machine"
0.2855,Event,ADDED,eval-sanitize-1-r2-116-wmxf7.18d4a2868b6d8108,reason=Created count=1 msg=Created container: task
0.2858,Event,ADDED,eval-sanitize-1-r2-116-wmxf7.18d4a2869079e5a4,reason=Started count=1 msg=Started container task
0.2859,Event,ADDED,eval-sanitize-1-r2-116.18d4a2849b85d19d,reason=SuccessfulCreate count=1 msg=Created pod: eval-sanitize-1-r2-116-wmxf7
0.2861,Event,ADDED,eval-sanitize-1-r2-116.18d4a28c79ecba57,reason=Completed count=1 msg=Job completed
0.2862,Event,ADDED,eval-sanitize-1-r2-117-m4bs8.18d4a284d781f510,"reason=FailedScheduling count=None msg=0/6 nodes are available: 6 node(s) had untolerated taint(s). no new claims to deallocate, preemption: 0/6 nodes are available: 6 Preemption is not helpful for scheduling."
0.2864,Event,ADDED,eval-sanitize-1-r2-117-m4bs8.18d4a2852f6941f4,"reason=FailedScheduling count=None msg=0/6 nodes are available: 1 c_wall violated: 1 conflicting context pair(s) with node memory, 5 node(s) had untolerated taint(s). no new claims to deallocate, preemption: 0/6 nodes are available: 1 No preemption victims found for incoming pod, 5 Preemption is not helpful for scheduling."
0.2866,Event,ADDED,eval-sanitize-1-r2-117-m4bs8.18d4a2853e3ecdcc,"reason=FailedScheduling count=None msg=0/6 nodes are available: 1 c_wall violated: 1 conflicting context pair(s) with node memory, 5 node(s) had untolerated taint(s). no new claims to deallocate, preemption: 0/6 nodes are available: 1 No preemption victims found for incoming pod, 5 Preemption is not helpful for scheduling."
0.2867,Event,ADDED,eval-sanitize-1-r2-117-m4bs8.18d4a2856ca3b374,reason=Scheduled count=None msg=Successfully assigned compute/eval-sanitize-1-r2-117-m4bs8 to kind-worker
0.2869,Event,ADDED,eval-sanitize-1-r2-117-m4bs8.18d4a2858a1bf1bd,"reason=Pulled count=1 msg=Container image ""busybox:musl"" already present on machine"
0.2871,Event,ADDED,eval-sanitize-1-r2-117-m4bs8.18d4a2858bd4c322,reason=Created count=1 msg=Created container: task
0.2872,Event,ADDED,eval-sanitize-1-r2-117-m4bs8.18d4a2858f51d323,reason=Started count=1 msg=Started container task
0.2875,Event,ADDED,eval-sanitize-1-r2-117.18d4a284d7771700,reason=SuccessfulCreate count=1 msg=Created pod: eval-sanitize-1-r2-117-m4bs8
0.2877,Event,ADDED,eval-sanitize-1-r2-117.18d4a28ba62ddbc8,reason=Completed count=1 msg=Job completed
0.2879,Event,ADDED,eval-sanitize-1-r2-118-zmhb6.18d4a28516430169,"reason=FailedScheduling count=None msg=0/6 nodes are available: 6 node(s) had untolerated taint(s). no new claims to deallocate, preemption: 0/6 nodes are available: 6 Preemption is not helpful for scheduling."
0.2881,Event,ADDED,eval-sanitize-1-r2-118-zmhb6.18d4a285313ff05f,"reason=FailedScheduling count=None msg=0/6 nodes are available: 1 c_wall violated: 2 conflicting context pair(s) with node memory, 5 node(s) had untolerated taint(s). no new claims to deallocate, preemption: 0/6 nodes are available: 1 No preemption victims found for incoming pod, 5 Preemption is not helpful for scheduling."
0.2884,Event,ADDED,eval-sanitize-1-r2-118-zmhb6.18d4a28542221b77,"reason=FailedScheduling count=None msg=0/6 nodes are available: 1 c_wall violated: 2 conflicting context pair(s) with node memory, 5 node(s) had untolerated taint(s). no new claims to deallocate, preemption: 0/6 nodes are available: 1 No preemption victims found for incoming pod, 5 Preemption is not helpful for scheduling."
0.2886,Event,ADDED,eval-sanitize-1-r2-118-zmhb6.18d4a2856db2affa,reason=Scheduled count=None msg=Successfully assigned compute/eval-sanitize-1-r2-118-zmhb6 to kind-worker
0.2887,Event,ADDED,eval-sanitize-1-r2-118-zmhb6.18d4a2858a842018,"reason=Pulled count=1 msg=Container image ""busybox:musl"" already present on machine"
0.2891,Event,ADDED,eval-sanitize-1-r2-118-zmhb6.18d4a2858c2f9cf3,reason=Created count=1 msg=Created container: task
0.2892,Event,ADDED,eval-sanitize-1-r2-118-zmhb6.18d4a2858f4bb854,reason=Started count=1 msg=Started container task
0.2894,Event,ADDED,eval-sanitize-1-r2-118.18d4a28516310c8d,reason=SuccessfulCreate count=1 msg=Created pod: eval-sanitize-1-r2-118-zmhb6
0.2896,Event,ADDED,eval-sanitize-1-r2-118.18d4a28bafecfcc1,reason=Completed count=1 msg=Job completed
0.2898,Event,ADDED,eval-sanitize-1-r2-119-p5wl8.18d4a2854fd53169,"reason=FailedScheduling count=None msg=0/6 nodes are available: 1 c_wall violated: 3 conflicting context pair(s) with node memory, 5 node(s) had untolerated taint(s). no new claims to deallocate, preemption: 0/6 nodes are available: 1 No preemption victims found for incoming pod, 5 Preemption is not helpful for scheduling."
0.29,Event,ADDED,eval-sanitize-1-r2-119-p5wl8.18d4a2855bd54f27,"reason=FailedScheduling count=None msg=0/6 nodes are available: 1 c_wall violated: 3 conflicting context pair(s) with node memory, 5 node(s) had untolerated taint(s). no new claims to deallocate, preemption: 0/6 nodes are available: 1 No preemption victims found for incoming pod, 5 Preemption is not helpful for scheduling."
0.2902,Event,ADDED,eval-sanitize-1-r2-119-p5wl8.18d4a2857c987424,"reason=FailedScheduling count=None msg=0/6 nodes are available: 1 c_wall violated: 1 conflicting context pair(s) with node memory, 5 node(s) had untolerated taint(s). no new claims to deallocate, preemption: 0/6 nodes are available: 1 No preemption victims found for incoming pod, 5 Preemption is not helpful for scheduling."
0.2904,Event,ADDED,eval-sanitize-1-r2-119-p5wl8.18d4a285d1fdc7ca,reason=Scheduled count=None msg=Successfully assigned compute/eval-sanitize-1-r2-119-p5wl8 to kind-worker2
0.2906,Event,ADDED,eval-sanitize-1-r2-119-p5wl8.18d4a285f2f7ab8a,"reason=Pulled count=1 msg=Container image ""busybox:musl"" already present on machine"
0.2907,Event,ADDED,eval-sanitize-1-r2-119-p5wl8.18d4a285f5d6895c,reason=Created count=1 msg=Created container: task
0.2909,Event,ADDED,eval-sanitize-1-r2-119-p5wl8.18d4a285fed956d5,reason=Started count=1 msg=Started container task
0.2911,Event,ADDED,eval-sanitize-1-r2-119.18d4a2854f4c5c8f,reason=SuccessfulCreate count=1 msg=Created pod: eval-sanitize-1-r2-119-p5wl8
0.2912,Event,ADDED,eval-sanitize-1-r2-119.18d4a28c64de4dc7,reason=Completed count=1 msg=Job completed
0.2914,Event,ADDED,eval-sanitize-1-r2-120-kgzst.18d4a285dd410769,"reason=FailedScheduling count=None msg=0/6 nodes are available: 1 c_wall violated: 2 conflicting context pair(s) with node memory, 5 node(s) had untolerated taint(s). no new claims to deallocate, preemption: 0/6 nodes are available: 1 No preemption victims found for incoming pod, 5 Preemption is not helpful for scheduling."
0.2916,Event,ADDED,eval-sanitize-1-r2-120-kgzst.18d4a285e9497177,"reason=FailedScheduling count=None msg=0/6 nodes are available: 1 c_wall violated: 1 conflicting context pair(s) with node memory, 1 c_wall violated: 2 conflicting context pair(s) with node memory, 4 node(s) had untolerated taint(s). no new claims to deallocate, preemption: 0/6 nodes are available: 2 No preemption victims found for incoming pod, 4 Preemption is not helpful for scheduling."
0.2918,Event,ADDED,eval-sanitize-1-r2-120-kgzst.18d4a285effd1da3,"reason=FailedScheduling count=None msg=0/6 nodes are available: 1 c_wall violated: 1 conflicting context pair(s) with node memory, 1 c_wall violated: 2 conflicting context pair(s) with node memory, 4 node(s) had untolerated taint(s). no new claims to deallocate, preemption: 0/6 nodes are available: 2 No preemption victims found for incoming pod, 4 Preemption is not helpful for scheduling."
0.292,Event,ADDED,eval-sanitize-1-r2-120-kgzst.18d4a2863cb3a1c4,"reason=FailedScheduling count=None msg=0/6 nodes are available: 1 c_wall violated: 1 conflicting context pair(s) with node memory, 5 node(s) had untolerated taint(s). no new claims to deallocate, preemption: 0/6 nodes are available: 1 No preemption victims found for incoming pod, 5 Preemption is not helpful for scheduling."
0.2923,Event,ADDED,eval-sanitize-1-r2-120-kgzst.18d4a2866dc04218,reason=Scheduled count=None msg=Successfully assigned compute/eval-sanitize-1-r2-120-kgzst to kind-worker4
0.2925,Event,ADDED,eval-sanitize-1-r2-120-kgzst.18d4a28688fe1b65,"reason=Pulled count=1 msg=Container image ""busybox:musl"" already present on machine"
0.2926,Event,ADDED,eval-sanitize-1-r2-120-kgzst.18d4a2868b2fff9f,reason=Created count=1 msg=Created container: task
0.293,Event,ADDED,eval-sanitize-1-r2-120-kgzst.18d4a28690794d8b,reason=Started count=1 msg=Started container task
0.2931,Event,ADDED,eval-sanitize-1-r2-120.18d4a285db258c85,reason=SuccessfulCreate count=1 msg=Created pod: eval-sanitize-1-r2-120-kgzst
0.2933,Event,ADDED,eval-sanitize-1-r2-120.18d4a28c7fcf119d,reason=Completed count=1 msg=Job completed
0.2935,Event,ADDED,eval-sanitize-1-r2-121-cskbm.18d4a2864ac53e4b,"reason=FailedScheduling count=None msg=0/6 nodes are available: 6 node(s) had untolerated taint(s). no new claims to deallocate, preemption: 0/6 nodes are available: 6 Preemption is not helpful for scheduling."
0.2938,Event,ADDED,eval-sanitize-1-r2-121-cskbm.18d4a2866dddc4a1,"reason=FailedScheduling count=None msg=0/6 nodes are available: 1 c_wall violated: 2 conflicting context pair(s) with node memory, 5 node(s) had untolerated taint(s). no new claims to deallocate, preemption: 0/6 nodes are available: 1 No preemption victims found for incoming pod, 5 Preemption is not helpful for scheduling."
0.294,Event,ADDED,eval-sanitize-1-r2-121-cskbm.18d4a2866e78142f,"reason=FailedScheduling count=None msg=0/6 nodes are available: 1 c_wall violated: 2 conflicting context pair(s) with node memory, 5 node(s) had untolerated taint(s). no new claims to deallocate, preemption: 0/6 nodes are available: 1 No preemption victims found for incoming pod, 5 Preemption is not helpful for scheduling."
0.2941,Event,ADDED,eval-sanitize-1-r2-121-cskbm.18d4a28a8c6a0df7,reason=Scheduled count=None msg=Successfully assigned compute/eval-sanitize-1-r2-121-cskbm to kind-worker3
0.2944,Event,ADDED,eval-sanitize-1-r2-121-cskbm.18d4a28aa77c88e3,"reason=Pulled count=1 msg=Container image ""busybox:musl"" already present on machine"
0.2946,Event,ADDED,eval-sanitize-1-r2-121-cskbm.18d4a28aa8f69538,reason=Created count=1 msg=Created container: task
0.2948,Event,ADDED,eval-sanitize-1-r2-121-cskbm.18d4a28aad2ea2f6,reason=Started count=1 msg=Started container task
0.2949,Event,ADDED,eval-sanitize-1-r2-121.18d4a2864abe3f91,reason=SuccessfulCreate count=1 msg=Created pod: eval-sanitize-1-r2-121-cskbm
0.2951,Event,ADDED,eval-sanitize-1-r2-121.18d4a29025669d3c,reason=Completed count=1 msg=Job completed
0.2953,Event,ADDED,eval-sanitize-1-r2-122-j55j4.18d4a286891e9eeb,"reason=FailedScheduling count=None msg=0/6 nodes are available: 1 c_wall violated: 1 conflicting context pair(s) with node memory, 5 node(s) had untolerated taint(s). no new claims to deallocate, preemption: 0/6 nodes are available: 1 No preemption victims found for incoming pod, 5 Preemption is not helpful for scheduling."
0.2955,Event,ADDED,eval-sanitize-1-r2-122-j55j4.18d4a28689b14424,"reason=FailedScheduling count=None msg=0/6 nodes are available: 1 c_wall violated: 1 conflicting context pair(s) with node memory, 5 node(s) had untolerated taint(s). no new claims to deallocate, preemption: 0/6 nodes are available: 1 No preemption victims found for incoming pod, 5 Preemption is not helpful for scheduling."
0.2957,Event,ADDED,eval-sanitize-1-r2-122-j55j4.18d4a28a8d114eaf,reason=Scheduled count=None msg=Successfully assigned compute/eval-sanitize-1-r2-122-j55j4 to kind-worker3
0.2959,Event,ADDED,eval-sanitize-1-r2-122-j55j4.18d4a28aa907fd48,"reason=Pulled count=1 msg=Container image ""busybox:musl"" already present on machine"
0.2961,Event,ADDED,eval-sanitize-1-r2-122-j55j4.18d4a28aab40589c,reason=Created count=1 msg=Created container: task
0.2965,Event,ADDED,eval-sanitize-1-r2-122-j55j4.18d4a28aaf334f8e,reason=Started count=1 msg=Started container task
0.2966,Event,ADDED,eval-sanitize-1-r2-122.18d4a28688de9196,reason=SuccessfulCreate count=1 msg=Created pod: eval-sanitize-1-r2-122-j55j4
0.2968,Event,ADDED,eval-sanitize-1-r2-122.18d4a290262e1c91,reason=Completed count=1 msg=Job completed
0.297,Event,ADDED,eval-sanitize-1-r2-123-dx9xl.18d4a286a9728caf,"reason=FailedScheduling count=None msg=0/6 nodes are available: 1 c_wall violated: 1 conflicting context pair(s) with node memory, 5 node(s) had untolerated taint(s). no new claims to deallocate, preemption: 0/6 nodes are available: 1 No preemption victims found for incoming pod, 5 Preemption is not helpful for scheduling."
0.2973,Event,ADDED,eval-sanitize-1-r2-123-dx9xl.18d4a286a9e67d6a,"reason=FailedScheduling count=None msg=0/6 nodes are available: 1 c_wall violated: 1 conflicting context pair(s) with node memory, 5 node(s) had untolerated taint(s). no new claims to deallocate, preemption: 0/6 nodes are available: 1 No preemption victims found for incoming pod, 5 Preemption is not helpful for scheduling."
0.2975,Event,ADDED,eval-sanitize-1-r2-123-dx9xl.18d4a28a8d3ff11b,reason=Scheduled count=None msg=Successfully assigned compute/eval-sanitize-1-r2-123-dx9xl to kind-worker3
0.2977,Event,ADDED,eval-sanitize-1-r2-123-dx9xl.18d4a28aa94651f5,"reason=Pulled count=1 msg=Container image ""busybox:musl"" already present on machine"
0.2979,Event,ADDED,eval-sanitize-1-r2-123-dx9xl.18d4a28aabf9aa1c,reason=Created count=1 msg=Created container: task
0.2981,Event,ADDED,eval-sanitize-1-r2-123-dx9xl.18d4a28ab47703c2,reason=Started count=1 msg=Started container task
0.2983,Event,ADDED,eval-sanitize-1-r2-123.18d4a286a93ab0fc,reason=SuccessfulCreate count=1 msg=Created pod: eval-sanitize-1-r2-123-dx9xl
0.2984,Event,ADDED,eval-sanitize-1-r2-123.18d4a28fe8b3d6a3,reason=Completed count=1 msg=Job completed
0.2986,Event,ADDED,eval-sanitize-1-r2-124-mwcrl.18d4a286e7c1e1e3,"reason=FailedScheduling count=None msg=0/6 nodes are available: 6 node(s) had untolerated taint(s). no new claims to deallocate, preemption: 0/6 nodes are available: 6 Preemption is not helpful for scheduling."
0.2988,Event,ADDED,eval-sanitize-1-r2-124-mwcrl.18d4a28a8d12c8c2,"reason=FailedScheduling count=None msg=0/6 nodes are available: 1 c_wall violated: 1 conflicting context pair(s) with node memory, 5 node(s) had untolerated taint(s). no new claims to deallocate, preemption: 0/6 nodes are available: 1 No preemption victims found for incoming pod, 5 Preemption is not helpful for scheduling."
0.299,Event,ADDED,eval-sanitize-1-r2-124-mwcrl.18d4a28aa1865371,"reason=FailedScheduling count=None msg=0/6 nodes are available: 1 c_wall violated: 1 conflicting context pair(s) with node memory, 5 node(s) had untolerated taint(s). no new claims to deallocate, preemption: 0/6 nodes are available: 1 No preemption victims found for incoming pod, 5 Preemption is not helpful for scheduling."
0.2991,Event,ADDED,eval-sanitize-1-r2-124-mwcrl.18d4a28b0b3896ec,reason=Scheduled count=None msg=Successfully assigned compute/eval-sanitize-1-r2-124-mwcrl to kind-worker
0.2993,Event,ADDED,eval-sanitize-1-r2-124-mwcrl.18d4a28b25f94227,"reason=Pulled count=1 msg=Container image ""busybox:musl"" already present on machine"
0.2995,Event,ADDED,eval-sanitize-1-r2-124-mwcrl.18d4a28b2aa71697,reason=Created count=1 msg=Created container: task
0.2998,Event,ADDED,eval-sanitize-1-r2-124-mwcrl.18d4a28b2d7cfc23,reason=Started count=1 msg=Started container task
0.3,Event,ADDED,eval-sanitize-1-r2-124.18d4a286e7b91366,reason=SuccessfulCreate count=1 msg=Created pod: eval-sanitize-1-r2-124-mwcrl
0.3001,Event,ADDED,eval-sanitize-1-r2-124.18d4a2911b6de144,reason=Completed count=1 msg=Job completed
0.3003,Event,ADDED,eval-sanitize-1-r2-125-pdtnk.18d4a2870fc41500,"reason=FailedScheduling count=None msg=0/6 nodes are available: 6 node(s) had untolerated taint(s). no new claims to deallocate, preemption: 0/6 nodes are available: 6 Preemption is not helpful for scheduling."
0.3004,Event,ADDED,eval-sanitize-1-r2-125-pdtnk.18d4a28a8e240480,reason=Scheduled count=None msg=Successfully assigned compute/eval-sanitize-1-r2-125-pdtnk to kind-worker3
0.3006,Event,ADDED,eval-sanitize-1-r2-125-pdtnk.18d4a28aa9244695,"reason=Pulled count=1 msg=Container image ""busybox:musl"" already present on machine"
0.3008,Event,ADDED,eval-sanitize-1-r2-125-pdtnk.18d4a28aabc56be6,reason=Created count=1 msg=Created container: task
0.3009,Event,ADDED,eval-sanitize-1-r2-125-pdtnk.18d4a28ab235d289,reason=Started count=1 msg=Started container task
0.3011,Event,ADDED,eval-sanitize-1-r2-125.18d4a2870fb829f4,reason=SuccessfulCreate count=1 msg=Created pod: eval-sanitize-1-r2-125-pdtnk
0.3013,Event,ADDED,eval-sanitize-1-r2-125.18d4a290b62982ce,reason=Completed count=1 msg=Job completed
0.3014,Event,ADDED,eval-sanitize-1-r2-126-gxglb.18d4a287351e8284,"reason=FailedScheduling count=None msg=0/6 nodes are available: 6 node(s) had untolerated taint(s). no new claims to deallocate, preemption: 0/6 nodes are available: 6 Preemption is not helpful for scheduling."
0.3016,Event,ADDED,eval-sanitize-1-r2-126-gxglb.18d4a28a8df1c068,"reason=FailedScheduling count=None msg=0/6 nodes are available: 1 c_wall violated: 1 conflicting context pair(s) with node memory, 5 node(s) had untolerated taint(s). no new claims to deallocate, preemption: 0/6 nodes are available: 1 No preemption victims found for incoming pod, 5 Preemption is not helpful for scheduling."
0.3018,Event,ADDED,eval-sanitize-1-r2-126-gxglb.18d4a28aa3fe2ec8,"reason=FailedScheduling count=None msg=0/6 nodes are available: 1 c_wall violated: 1 conflicting context pair(s) with node memory, 5 node(s) had untolerated taint(s). no new claims to deallocate, preemption: 0/6 nodes are available: 1 No preemption victims found for incoming pod, 5 Preemption is not helpful for scheduling."
0.3019,Event,ADDED,eval-sanitize-1-r2-126-gxglb.18d4a28b0b0132f4,"reason=FailedScheduling count=None msg=0/6 nodes are available: 1 c_wall violated: 1 conflicting context pair(s) with node memory, 5 node(s) had untolerated taint(s). no new claims to deallocate, preemption: 0/6 nodes are available: 1 No preemption victims found for incoming pod, 5 Preemption is not helpful for scheduling."
0.3022,Event,ADDED,eval-sanitize-1-r2-126-gxglb.18d4a28b128ffd0e,"reason=FailedScheduling count=None msg=0/6 nodes are available: 1 c_wall violated: 3 conflicting context pair(s) with node memory, 5 node(s) had untolerated taint(s). no new claims to deallocate, preemption: 0/6 nodes are available: 1 No preemption victims found for incoming pod, 5 Preemption is not helpful for scheduling."
0.3023,Event,ADDED,eval-sanitize-1-r2-126-gxglb.18d4a28b23341d88,"reason=FailedScheduling count=None msg=0/6 nodes are available: 1 c_wall violated: 3 conflicting context pair(s) with node memory, 5 node(s) had untolerated taint(s). no new claims to deallocate, preemption: 0/6 nodes are available: 1 No preemption victims found for incoming pod, 5 Preemption is not helpful for scheduling."
0.3025,Event,ADDED,eval-sanitize-1-r2-126-gxglb.18d4a28c627c5da7,reason=Scheduled count=None msg=Successfully assigned compute/eval-sanitize-1-r2-126-gxglb to kind-worker2
0.3028,Event,ADDED,eval-sanitize-1-r2-126-gxglb.18d4a28c83eb78b9,"reason=Pulled count=1 msg=Container image ""busybox:musl"" already present on machine"
0.3032,Event,ADDED,eval-sanitize-1-r2-126-gxglb.18d4a28c86c51980,reason=Created count=1 msg=Created container: task
0.3035,Event,ADDED,eval-sanitize-1-r2-126-gxglb.18d4a28c9051b218,reason=Started count=1 msg=Started container task
0.3037,Event,ADDED,eval-sanitize-1-r2-126.18d4a2873512f5b4,reason=SuccessfulCreate count=1 msg=Created pod: eval-sanitize-1-r2-126-gxglb
0.3041,Event,ADDED,eval-sanitize-1-r2-126.18d4a2920b64a096,reason=Completed count=1 msg=Job completed
0.3043,Event,ADDED,eval-sanitize-1-r2-127-724zf.18d4a2873f4c0bbb,"reason=FailedScheduling count=None msg=0/6 nodes are available: 6 node(s) had untolerated taint(s). no new claims to deallocate, preemption: 0/6 nodes are available: 6 Preemption is not helpful for scheduling."
0.3046,Event,ADDED,eval-sanitize-1-r2-127-724zf.18d4a28a929e59c5,reason=Scheduled count=None msg=Successfully assigned compute/eval-sanitize-1-r2-127-724zf to kind-worker3
0.3048,Event,ADDED,eval-sanitize-1-r2-127-724zf.18d4a28aacb94950,"reason=Pulled count=1 msg=Container image ""busybox:musl"" already present on machine"
0.305,Event,ADDED,eval-sanitize-1-r2-127-724zf.18d4a28aaea7e2e7,reason=Created count=1 msg=Created container: task
0.3052,Event,ADDED,eval-sanitize-1-r2-127-724zf.18d4a28ab2be5f1f,reason=Started count=1 msg=Started container task
0.3054,Event,ADDED,eval-sanitize-1-r2-127.18d4a2873f40f6c8,reason=SuccessfulCreate count=1 msg=Created pod: eval-sanitize-1-r2-127-724zf
0.3056,Event,ADDED,eval-sanitize-1-r2-127.18d4a2902732e414,reason=Completed count=1 msg=Job completed
0.3058,Event,ADDED,eval-sanitize-1-r2-128-55c5p.18d4a2876f40b365,"reason=FailedScheduling count=None msg=0/6 nodes are available: 6 node(s) had untolerated taint(s). no new claims to deallocate, preemption: 0/6 nodes are available: 6 Preemption is not helpful for scheduling."
0.3059,Event,ADDED,eval-sanitize-1-r2-128-55c5p.18d4a28a924f74a5,"reason=FailedScheduling count=None msg=0/6 nodes are available: 1 c_wall violated: 1 conflicting context pair(s) with node memory, 5 node(s) had untolerated taint(s). no new claims to deallocate, preemption: 0/6 nodes are available: 1 No preemption victims found for incoming pod, 5 Preemption is not helpful for scheduling."
0.3061,Event,ADDED,eval-sanitize-1-r2-128-55c5p.18d4a28aa42bd079,"reason=FailedScheduling count=None msg=0/6 nodes are available: 1 c_wall violated: 1 conflicting context pair(s) with node memory, 5 node(s) had untolerated taint(s). no new claims to deallocate, preemption: 0/6 nodes are available: 1 No preemption victims found for incoming pod, 5 Preemption is not helpful for scheduling."
0.3063,Event,ADDED,eval-sanitize-1-r2-128-55c5p.18d4a28b0bea8942,"reason=FailedScheduling count=None msg=0/6 nodes are available: 1 c_wall violated: 1 conflicting context pair(s) with node memory, 5 node(s) had untolerated taint(s). no new claims to deallocate, preemption: 0/6 nodes are available: 1 No preemption victims found for incoming pod, 5 Preemption is not helpful for scheduling."
0.3065,Event,ADDED,eval-sanitize-1-r2-128-55c5p.18d4a28b170f637a,"reason=FailedScheduling count=None msg=0/6 nodes are available: 1 c_wall violated: 3 conflicting context pair(s) with node memory, 5 node(s) had untolerated taint(s). no new claims to deallocate, preemption: 0/6 nodes are available: 1 No preemption victims found for incoming pod, 5 Preemption is not helpful for scheduling."
0.3067,Event,ADDED,eval-sanitize-1-r2-128-55c5p.18d4a28b236a0219,"reason=FailedScheduling count=None msg=0/6 nodes are available: 1 c_wall violated: 3 conflicting context pair(s) with node memory, 5 node(s) had untolerated taint(s). no new claims to deallocate, preemption: 0/6 nodes are available: 1 No preemption victims found for incoming pod, 5 Preemption is not helpful for scheduling."
0.3068,Event,ADDED,eval-sanitize-1-r2-128-55c5p.18d4a28c610f16cd,reason=Scheduled count=None msg=Successfully assigned compute/eval-sanitize-1-r2-128-55c5p to kind-worker2
0.307,Event,ADDED,eval-sanitize-1-r2-128-55c5p.18d4a28c828671c3,"reason=Pulled count=1 msg=Container image ""busybox:musl"" already present on machine"
0.3072,Event,ADDED,eval-sanitize-1-r2-128-55c5p.18d4a28c83c4247e,reason=Created count=1 msg=Created container: task
0.3074,Event,ADDED,eval-sanitize-1-r2-128-55c5p.18d4a28c85fc381e,reason=Started count=1 msg=Started container task
0.3075,Event,ADDED,eval-sanitize-1-r2-128.18d4a2876f35f51f,reason=SuccessfulCreate count=1 msg=Created pod: eval-sanitize-1-r2-128-55c5p
0.3077,Event,ADDED,eval-sanitize-1-r2-128.18d4a2920fad396c,reason=Completed count=1 msg=Job completed
0.3078,Event,ADDED,eval-sanitize-1-r2-129-bzgzh.18d4a287a2a63a07,"reason=FailedScheduling count=None msg=0/6 nodes are available: 6 node(s) had untolerated taint(s). no new claims to deallocate, preemption: 0/6 nodes are available: 6 Preemption is not helpful for scheduling."
0.308,Event,ADDED,eval-sanitize-1-r2-129-bzgzh.18d4a28a9883576c,reason=Scheduled count=None msg=Successfully assigned compute/eval-sanitize-1-r2-129-bzgzh to kind-worker3
0.3082,Event,ADDED,eval-sanitize-1-r2-129-bzgzh.18d4a28ab3a21d6d,"reason=Pulled count=1 msg=Container image ""busybox:musl"" already present on machine"
0.3084,Event,ADDED,eval-sanitize-1-r2-129-bzgzh.18d4a28ab7f95146,reason=Created count=1 msg=Created container: task
0.3085,Event,ADDED,eval-sanitize-1-r2-129-bzgzh.18d4a28abcc56452,reason=Started count=1 msg=Started container task
0.3087,Event,ADDED,eval-sanitize-1-r2-129.18d4a287a29a6c7d,reason=SuccessfulCreate count=1 msg=Created pod: eval-sanitize-1-r2-129-bzgzh
0.3089,Event,ADDED,eval-sanitize-1-r2-129.18d4a2902791de1b,reason=Completed count=1 msg=Job completed
0.309,Event,ADDED,eval-sanitize-1-r2-130-fzpx6.18d4a287decad31e,"reason=FailedScheduling count=None msg=0/6 nodes are available: 6 node(s) had untolerated taint(s). no new claims to deallocate, preemption: 0/6 nodes are available: 6 Preemption is not helpful for scheduling."
0.3092,Event,ADDED,eval-sanitize-1-r2-130-fzpx6.18d4a28a936a3fc7,"reason=FailedScheduling count=None msg=0/6 nodes are available: 1 c_wall violated: 2 conflicting context pair(s) with node memory, 5 node(s) had untolerated taint(s). no new claims to deallocate, preemption: 0/6 nodes are available: 1 No preemption victims found for incoming pod, 5 Preemption is not helpful for scheduling."
0.3094,Event,ADDED,eval-sanitize-1-r2-130-fzpx6.18d4a28aa457ff7f,"reason=FailedScheduling count=None msg=0/6 nodes are available: 1 c_wall violated: 2 conflicting context pair(s) with node memory, 5 node(s) had untolerated taint(s). no new claims to deallocate, preemption: 0/6 nodes are available: 1 No preemption victims found for incoming pod, 5 Preemption is not helpful for scheduling."
0.3095,Event,ADDED,eval-sanitize-1-r2-130-fzpx6.18d4a28b0d8b2fea,reason=Scheduled count=None msg=Successfully assigned compute/eval-sanitize-1-r2-130-fzpx6 to kind-worker
0.3097,Event,ADDED,eval-sanitize-1-r2-130-fzpx6.18d4a28b2bcefc3a,"reason=Pulled count=1 msg=Container image ""busybox:musl"" already present on machine"
0.3099,Event,ADDED,eval-sanitize-1-r2-130-fzpx6.18d4a28b2d2f446a,reason=Created count=1 msg=Created container: task
0.3101,Event,ADDED,eval-sanitize-1-r2-130-fzpx6.18d4a28b2ffa55a4,reason=Started count=1 msg=Started container task
0.3102,Event,ADDED,eval-sanitize-1-r2-130.18d4a287debd664f,reason=SuccessfulCreate count=1 msg=Created pod: eval-sanitize-1-r2-130-fzpx6
0.3104,Event,ADDED,eval-sanitize-1-r2-130.18d4a29124602f2c,reason=Completed count=1 msg=Job completed
0.3106,Event,ADDED,eval-sanitize-1-r2-131-vqmjx.18d4a28819d19bd3,"reason=FailedScheduling count=None msg=0/6 nodes are available: 6 node(s) had untolerated taint(s). no new claims to deallocate, preemption: 0/6 nodes are available: 6 Preemption is not helpful for scheduling."
0.3107,Event,ADDED,eval-sanitize-1-r2-131-vqmjx.18d4a28a993391e7,reason=Scheduled count=None msg=Successfully assigned compute/eval-sanitize-1-r2-131-vqmjx to kind-worker3
0.3109,Event,ADDED,eval-sanitize-1-r2-131-vqmjx.18d4a28ab4ec625f,"reason=Pulled count=1 msg=Container image ""busybox:musl"" already present on machine"
0.3111,Event,ADDED,eval-sanitize-1-r2-131-vqmjx.18d4a28ab8774599,reason=Created count=1 msg=Created container: task
0.3112,Event,ADDED,eval-sanitize-1-r2-131-vqmjx.18d4a28abcbd686a,reason=Started count=1 msg=Started container task
0.3114,Event,ADDED,eval-sanitize-1-r2-131.18d4a28819c5216d,reason=SuccessfulCreate count=1 msg=Created pod: eval-sanitize-1-r2-131-vqmjx
0.3116,Event,ADDED,eval-sanitize-1-r2-131.18d4a290c7ffec6b,reason=Completed count=1 msg=Job completed
0.3117,Event,ADDED,eval-sanitize-1-r2-132-tmgbr.18d4a288563b29c1,"reason=FailedScheduling count=None msg=0/6 nodes are available: 6 node(s) had untolerated taint(s). no new claims to deallocate, preemption: 0/6 nodes are available: 6 Preemption is not helpful for scheduling."
0.3119,Event,ADDED,eval-sanitize-1-r2-132-tmgbr.18d4a28a9914b8e4,"reason=FailedScheduling count=None msg=0/6 nodes are available: 1 c_wall violated: 2 conflicting context pair(s) with node memory, 5 node(s) had untolerated taint(s). no new claims to deallocate, preemption: 0/6 nodes are available: 1 No preemption victims found for incoming pod, 5 Preemption is not helpful for scheduling."
0.3122,Event,ADDED,eval-sanitize-1-r2-132-tmgbr.18d4a28aa47f40e5,"reason=FailedScheduling count=None msg=0/6 nodes are available: 1 c_wall violated: 2 conflicting context pair(s) with node memory, 5 node(s) had untolerated taint(s). no new claims to deallocate, preemption: 0/6 nodes are available: 1 No preemption victims found for incoming pod, 5 Preemption is not helpful for scheduling."
0.3124,Event,ADDED,eval-sanitize-1-r2-132-tmgbr.18d4a28b0cc025f3,"reason=FailedScheduling count=None msg=0/6 nodes are available: 1 c_wall violated: 2 conflicting context pair(s) with node memory, 5 node(s) had untolerated taint(s). no new claims to deallocate, preemption: 0/6 nodes are available: 1 No preemption victims found for incoming pod, 5 Preemption is not helpful for scheduling."
0.3126,Event,ADDED,eval-sanitize-1-r2-132-tmgbr.18d4a28b1dbcc66f,"reason=FailedScheduling count=None msg=0/6 nodes are available: 1 c_wall violated: 3 conflicting context pair(s) with node memory, 5 node(s) had untolerated taint(s). no new claims to deallocate, preemption: 0/6 nodes are available: 1 No preemption victims found for incoming pod, 5 Preemption is not helpful for scheduling."
0.313,Event,ADDED,eval-sanitize-1-r2-132-tmgbr.18d4a28b23a62982,"reason=FailedScheduling count=None msg=0/6 nodes are available: 1 c_wall violated: 3 conflicting context pair(s) with node memory, 5 node(s) had untolerated taint(s). no new claims to deallocate, preemption: 0/6 nodes are available: 1 No preemption victims found for incoming pod, 5 Preemption is not helpful for scheduling."
0.3132,Event,ADDED,eval-sanitize-1-r2-132-tmgbr.18d4a28c6178283e,"reason=FailedScheduling count=None msg=0/6 nodes are available: 1 c_wall violated: 1 conflicting context pair(s) with node memory, 5 node(s) had untolerated taint(s). no new claims to deallocate, preemption: 0/6 nodes are available: 1 No preemption victims found for incoming pod, 5 Preemption is not helpful for scheduling."
0.3134,Event,ADDED,eval-sanitize-1-r2-132-tmgbr.18d4a28c682e7ace,"reason=FailedScheduling count=None msg=0/6 nodes are available: 1 c_wall violated: 2 conflicting context pair(s) with node memory, 5 node(s) had untolerated taint(s). no new claims to deallocate, preemption: 0/6 nodes are available: 1 No preemption victims found for incoming pod, 5 Preemption is not helpful for scheduling."
0.3137,Event,ADDED,eval-sanitize-1-r2-132-tmgbr.18d4a28c6dc87e05,"reason=FailedScheduling count=None msg=0/6 nodes are available: 1 c_wall violated: 2 conflicting context pair(s) with node memory, 5 node(s) had untolerated taint(s). no new claims to deallocate, preemption: 0/6 nodes are available: 1 No preemption victims found for incoming pod, 5 Preemption is not helpful for scheduling."
0.3139,Event,ADDED,eval-sanitize-1-r2-132-tmgbr.18d4a28c8724ec94,"reason=FailedScheduling count=None msg=0/6 nodes are available: 1 c_wall violated: 1 conflicting context pair(s) with node memory, 1 c_wall violated: 2 conflicting context pair(s) with node memory, 4 node(s) had untolerated taint(s). no new claims to deallocate, preemption: 0/6 nodes are available: 2 No preemption victims found for incoming pod, 4 Preemption is not helpful for scheduling."
0.3141,Event,ADDED,eval-sanitize-1-r2-132-tmgbr.18d4a28ca3faf95f,reason=Scheduled count=None msg=Successfully assigned compute/eval-sanitize-1-r2-132-tmgbr to kind-worker5
0.3143,Event,ADDED,eval-sanitize-1-r2-132-tmgbr.18d4a28cc2480380,"reason=Pulled count=1 msg=Container image ""busybox:musl"" already present on machine"
0.3146,Event,ADDED,eval-sanitize-1-r2-132-tmgbr.18d4a28cc39477b3,reason=Created count=1 msg=Created container: task
0.3148,Event,ADDED,eval-sanitize-1-r2-132-tmgbr.18d4a28cc5bd63b7,reason=Started count=1 msg=Started container task
0.315,Event,ADDED,eval-sanitize-1-r2-132.18d4a288562e5a5a,reason=SuccessfulCreate count=1 msg=Created pod: eval-sanitize-1-r2-132-tmgbr
0.3153,Event,ADDED,eval-sanitize-1-r2-132.18d4a292f1277ffa,reason=Completed count=1 msg=Job completed
0.3155,Event,ADDED,eval-sanitize-1-r2-133-r8d6f.18d4a28890e63322,"reason=FailedScheduling count=None msg=0/6 nodes are available: 6 node(s) had untolerated taint(s). no new claims to deallocate, preemption: 0/6 nodes are available: 6 Preemption is not helpful for scheduling."
0.3156,Event,ADDED,eval-sanitize-1-r2-133-r8d6f.18d4a28a99cbaea9,"reason=FailedScheduling count=None msg=0/6 nodes are available: 1 c_wall violated: 1 conflicting context pair(s) with node memory, 5 node(s) had untolerated taint(s). no new claims to deallocate, preemption: 0/6 nodes are available: 1 No preemption victims found for incoming pod, 5 Preemption is not helpful for scheduling."
0.316,Event,ADDED,eval-sanitize-1-r2-133-r8d6f.18d4a28aa4a79dff,"reason=FailedScheduling count=None msg=0/6 nodes are available: 1 c_wall violated: 1 conflicting context pair(s) with node memory, 5 node(s) had untolerated taint(s). no new claims to deallocate, preemption: 0/6 nodes are available: 1 No preemption victims found for incoming pod, 5 Preemption is not helpful for scheduling."
0.3162,Event,ADDED,eval-sanitize-1-r2-133-r8d6f.18d4a28b112b906f,reason=Scheduled count=None msg=Successfully assigned compute/eval-sanitize-1-r2-133-r8d6f to kind-worker
0.3163,Event,ADDED,eval-sanitize-1-r2-133-r8d6f.18d4a28b2d3e5754,"reason=Pulled count=1 msg=Container image ""busybox:musl"" already present on machine"
0.3165,Event,ADDED,eval-sanitize-1-r2-133-r8d6f.18d4a28b2ec1b063,reason=Created count=1 msg=Created container: task
0.3168,Event,ADDED,eval-sanitize-1-r2-133-r8d6f.18d4a28b30fc23b0,reason=Started count=1 msg=Started container task
0.317,Event,ADDED,eval-sanitize-1-r2-133.18d4a28890d91243,reason=SuccessfulCreate count=1 msg=Created pod: eval-sanitize-1-r2-133-r8d6f
0.3172,Event,ADDED,eval-sanitize-1-r2-133.18d4a2912493fbfc,reason=Completed count=1 msg=Job completed
0.3173,Event,ADDED,eval-sanitize-1-r2-134-r7tsb.18d4a288ccd1ce6c,"reason=FailedScheduling count=None msg=0/6 nodes are available: 6 node(s) had untolerated taint(s). no new claims to deallocate, preemption: 0/6 nodes are available: 6 Preemption is not helpful for scheduling."
0.3176,Event,ADDED,eval-sanitize-1-r2-134-r7tsb.18d4a28a9a41a3f4,"reason=FailedScheduling count=None msg=0/6 nodes are available: 1 c_wall violated: 2 conflicting context pair(s) with node memory, 5 node(s) had untolerated taint(s). no new claims to deallocate, preemption: 0/6 nodes are available: 1 No preemption victims found for incoming pod, 5 Preemption is not helpful for scheduling."
0.3178,Event,ADDED,eval-sanitize-1-r2-134-r7tsb.18d4a28aa4d43ccf,"reason=FailedScheduling count=None msg=0/6 nodes are available: 1 c_wall violated: 2 conflicting context pair(s) with node memory, 5 node(s) had untolerated taint(s). no new claims to deallocate, preemption: 0/6 nodes are available: 1 No preemption victims found for incoming pod, 5 Preemption is not helpful for scheduling."
0.318,Event,ADDED,eval-sanitize-1-r2-134-r7tsb.18d4a28b115b2eaa,reason=Scheduled count=None msg=Successfully assigned compute/eval-sanitize-1-r2-134-r7tsb to kind-worker
0.3184,Event,ADDED,eval-sanitize-1-r2-134-r7tsb.18d4a28b2eff21ab,"reason=Pulled count=1 msg=Container image ""busybox:musl"" already present on machine"
0.3186,Event,ADDED,eval-sanitize-1-r2-134-r7tsb.18d4a28b316c2327,reason=Created count=1 msg=Created container: task
0.3188,Event,ADDED,eval-sanitize-1-r2-134-r7tsb.18d4a28b33b59fd8,reason=Started count=1 msg=Started container task
0.3189,Event,ADDED,eval-sanitize-1-r2-134.18d4a288ccc805a8,reason=SuccessfulCreate count=1 msg=Created pod: eval-sanitize-1-r2-134-r7tsb
0.3192,Event,ADDED,eval-sanitize-1-r2-134.18d4a291249455df,reason=Completed count=1 msg=Job completed
0.3194,Event,ADDED,eval-sanitize-1-r2-135-k9s8g.18d4a2890945e938,"reason=FailedScheduling count=None msg=0/6 nodes are available: 6 node(s) had untolerated taint(s). no new claims to deallocate, preemption: 0/6 nodes are available: 6 Preemption is not helpful for scheduling."
0.3196,Event,ADDED,eval-sanitize-1-r2-135-k9s8g.18d4a28a9abd8e95,"reason=FailedScheduling count=None msg=0/6 nodes are available: 1 c_wall violated: 1 conflicting context pair(s) with node memory, 5 node(s) had untolerated taint(s). no new claims to deallocate, preemption: 0/6 nodes are available: 1 No preemption victims found for incoming pod, 5 Preemption is not helpful for scheduling."
0.3199,Event,ADDED,eval-sanitize-1-r2-135-k9s8g.18d4a28aa5932336,"reason=FailedScheduling count=None msg=0/6 nodes are available: 1 c_wall violated: 1 conflicting context pair(s) with node memory, 5 node(s) had untolerated taint(s). no new claims to deallocate, preemption: 0/6 nodes are available: 1 No preemption victims found for incoming pod, 5 Preemption is not helpful for scheduling."
0.32,Event,ADDED,eval-sanitize-1-r2-135-k9s8g.18d4a28b11db7318,reason=Scheduled count=None msg=Successfully assigned compute/eval-sanitize-1-r2-135-k9s8g to kind-worker
0.3202,Event,ADDED,eval-sanitize-1-r2-135-k9s8g.18d4a28b2ecb195c,"reason=Pulled count=1 msg=Container image ""busybox:musl"" already present on machine"
0.3205,Event,ADDED,eval-sanitize-1-r2-135-k9s8g.18d4a28b31185100,reason=Created count=1 msg=Created container: task
0.3206,Event,ADDED,eval-sanitize-1-r2-135-k9s8g.18d4a28b3377f77a,reason=Started count=1 msg=Started container task
0.3208,Event,ADDED,eval-sanitize-1-r2-135.18d4a28909392c60,reason=SuccessfulCreate count=1 msg=Created pod: eval-sanitize-1-r2-135-k9s8g
0.321,Event,ADDED,eval-sanitize-1-r2-135.18d4a291364b172c,reason=Completed count=1 msg=Job completed
0.3213,Event,ADDED,eval-sanitize-1-r2-136-nnv2w.18d4a28944205471,"reason=FailedScheduling count=None msg=0/6 nodes are available: 6 node(s) had untolerated taint(s). no new claims to deallocate, preemption: 0/6 nodes are available: 6 Preemption is not helpful for scheduling."
0.3215,Event,ADDED,eval-sanitize-1-r2-136-nnv2w.18d4a28a9e401960,reason=Scheduled count=None msg=Successfully assigned compute/eval-sanitize-1-r2-136-nnv2w to kind-worker3
0.3216,Event,ADDED,eval-sanitize-1-r2-136-nnv2w.18d4a28abbe515c9,"reason=Pulled count=1 msg=Container image ""busybox:musl"" already present on machine"
0.3218,Event,ADDED,eval-sanitize-1-r2-136-nnv2w.18d4a28abe4fca04,reason=Created count=1 msg=Created container: task
0.322,Event,ADDED,eval-sanitize-1-r2-136-nnv2w.18d4a28ac304dd45,reason=Started count=1 msg=Started container task
0.3221,Event,ADDED,eval-sanitize-1-r2-136.18d4a289441288b6,reason=SuccessfulCreate count=1 msg=Created pod: eval-sanitize-1-r2-136-nnv2w
0.3223,Event,ADDED,eval-sanitize-1-r2-136.18d4a29027920789,reason=Completed count=1 msg=Job completed
0.3226,Event,ADDED,eval-sanitize-1-r2-137-mkc28.18d4a2897f955a8f,"reason=FailedScheduling count=None msg=0/6 nodes are available: 6 node(s) had untolerated taint(s). no new claims to deallocate, preemption: 0/6 nodes are available: 6 Preemption is not helpful for scheduling."
0.3228,Event,ADDED,eval-sanitize-1-r2-137-mkc28.18d4a28a9ea5c09e,reason=Scheduled count=None msg=Successfully assigned compute/eval-sanitize-1-r2-137-mkc28 to kind-worker3
0.323,Event,ADDED,eval-sanitize-1-r2-137-mkc28.18d4a28abba99a7d,"reason=Pulled count=1 msg=Container image ""busybox:musl"" already present on machine"
0.3232,Event,ADDED,eval-sanitize-1-r2-137-mkc28.18d4a28abd96eda6,reason=Created count=1 msg=Created container: task
0.3235,Event,ADDED,eval-sanitize-1-r2-137-mkc28.18d4a28ac2383bb3,reason=Started count=1 msg=Started container task
0.3236,Event,ADDED,eval-sanitize-1-r2-137.18d4a2897f852d67,reason=SuccessfulCreate count=1 msg=Created pod: eval-sanitize-1-r2-137-mkc28
0.3238,Event,ADDED,eval-sanitize-1-r2-137.18d4a290bf139796,reason=Completed count=1 msg=Job completed
0.3241,Event,ADDED,eval-sanitize-1-r2-138-r5d8q.18d4a289bb365b5e,"reason=FailedScheduling count=None msg=0/6 nodes are available: 6 node(s) had untolerated taint(s). no new claims to deallocate, preemption: 0/6 nodes are available: 6 Preemption is not helpful for scheduling."
0.3242,Event,ADDED,eval-sanitize-1-r2-138-r5d8q.18d4a28a9fa477b6,reason=Scheduled count=None msg=Successfully assigned compute/eval-sanitize-1-r2-138-r5d8q to kind-worker3
0.3244,Event,ADDED,eval-sanitize-1-r2-138-r5d8q.18d4a28abd81b86e,"reason=Pulled count=1 msg=Container image ""busybox:musl"" already present on machine"
0.3246,Event,ADDED,eval-sanitize-1-r2-138-r5d8q.18d4a28abfcbbd56,reason=Created count=1 msg=Created container: task
0.3248,Event,ADDED,eval-sanitize-1-r2-138-r5d8q.18d4a28ac35889e4,reason=Started count=1 msg=Started container task
0.325,Event,ADDED,eval-sanitize-1-r2-138.18d4a289bb2823cb,reason=SuccessfulCreate count=1 msg=Created pod: eval-sanitize-1-r2-138-r5d8q
0.3251,Event,ADDED,eval-sanitize-1-r2-138.18d4a290276c2ef5,reason=Completed count=1 msg=Job completed
0.3253,Event,ADDED,eval-sanitize-1-r2-139-5gt8l.18d4a289f9fe399b,"reason=FailedScheduling count=None msg=0/6 nodes are available: 6 node(s) had untolerated taint(s). no new claims to deallocate, preemption: 0/6 nodes are available: 6 Preemption is not helpful for scheduling."
0.3254,Event,ADDED,eval-sanitize-1-r2-139-5gt8l.18d4a28a9f9ecc65,reason=Scheduled count=None msg=Successfully assigned compute/eval-sanitize-1-r2-139-5gt8l to kind-worker3
0.3256,Event,ADDED,eval-sanitize-1-r2-139-5gt8l.18d4a28abdce7720,"reason=Pulled count=1 msg=Container image ""busybox:musl"" already present on machine"
0.3258,Event,ADDED,eval-sanitize-1-r2-139-5gt8l.18d4a28abfc90061,reason=Created count=1 msg=Created container: task
0.326,Event,ADDED,eval-sanitize-1-r2-139-5gt8l.18d4a28ac35b0237,reason=Started count=1 msg=Started container task
0.3261,Event,ADDED,eval-sanitize-1-r2-139.18d4a289f9f1e9cf,reason=SuccessfulCreate count=1 msg=Created pod: eval-sanitize-1-r2-139-5gt8l
0.3263,Event,ADDED,eval-sanitize-1-r2-139.18d4a290cb2b5216,reason=Completed count=1 msg=Job completed
0.3264,Event,ADDED,eval-sanitize-1-r2-140-kwsms.18d4a28a32e67694,"reason=FailedScheduling count=None msg=0/6 nodes are available: 6 node(s) had untolerated taint(s). no new claims to deallocate, preemption: 0/6 nodes are available: 6 Preemption is not helpful for scheduling."
0.3266,Event,ADDED,eval-sanitize-1-r2-140-kwsms.18d4a28a9ece1124,"reason=FailedScheduling count=None msg=0/6 nodes are available: 1 c_wall violated: 1 conflicting context pair(s) with node memory, 5 node(s) had untolerated taint(s). no new claims to deallocate, preemption: 0/6 nodes are available: 1 No preemption victims found for incoming pod, 5 Preemption is not helpful for scheduling."
0.3268,Event,ADDED,eval-sanitize-1-r2-140-kwsms.18d4a28aab8706c2,"reason=FailedScheduling count=None msg=0/6 nodes are available: 1 c_wall violated: 1 conflicting context pair(s) with node memory, 5 node(s) had untolerated taint(s). no new claims to deallocate, preemption: 0/6 nodes are available: 1 No preemption victims found for incoming pod, 5 Preemption is not helpful for scheduling."
0.3269,Event,ADDED,eval-sanitize-1-r2-140-kwsms.18d4a28b116f2dba,"reason=FailedScheduling count=None msg=0/6 nodes are available: 1 c_wall violated: 3 conflicting context pair(s) with node memory, 5 node(s) had untolerated taint(s). no new claims to deallocate, preemption: 0/6 nodes are available: 1 No preemption victims found for incoming pod, 5 Preemption is not helpful for scheduling."
0.3271,Event,ADDED,eval-sanitize-1-r2-140-kwsms.18d4a28b22fdb450,"reason=FailedScheduling count=None msg=0/6 nodes are available: 1 c_wall violated: 3 conflicting context pair(s) with node memory, 5 node(s) had untolerated taint(s). no new claims to deallocate, preemption: 0/6 nodes are available: 1 No preemption victims found for incoming pod, 5 Preemption is not helpful for scheduling."
0.3273,Event,ADDED,eval-sanitize-1-r2-140-kwsms.18d4a28c626af04d,reason=Scheduled count=None msg=Successfully assigned compute/eval-sanitize-1-r2-140-kwsms to kind-worker2
0.3274,Event,ADDED,eval-sanitize-1-r2-140-kwsms.18d4a28c83d17caa,"reason=Pulled count=1 msg=Container image ""busybox:musl"" already present on machine"
0.3276,Event,ADDED,eval-sanitize-1-r2-140-kwsms.18d4a28c863de3a3,reason=Created count=1 msg=Created container: task
0.3305,Event,ADDED,eval-sanitize-1-r2-140-kwsms.18d4a28c9051e301,reason=Started count=1 msg=Started container task
0.3306,Event,ADDED,eval-sanitize-1-r2-140.18d4a28a32da4fec,reason=SuccessfulCreate count=1 msg=Created pod: eval-sanitize-1-r2-140-kwsms
0.3308,Event,ADDED,eval-sanitize-1-r2-140.18d4a2920cb9bbb9,reason=Completed count=1 msg=Job completed
0.331,Event,ADDED,eval-sanitize-1-r2-141-dnxdp.18d4a28a6e49870c,"reason=FailedScheduling count=None msg=0/6 nodes are available: 6 node(s) had untolerated taint(s). no new claims to deallocate, preemption: 0/6 nodes are available: 6 Preemption is not helpful for scheduling."
0.3311,Event,ADDED,eval-sanitize-1-r2-141-dnxdp.18d4a28a9fecf7cb,"reason=FailedScheduling count=None msg=0/6 nodes are available: 1 c_wall violated: 2 conflicting context pair(s) with node memory, 5 node(s) had untolerated taint(s). no new claims to deallocate, preemption: 0/6 nodes are available: 1 No preemption victims found for incoming pod, 5 Preemption is not helpful for scheduling."
0.3313,Event,ADDED,eval-sanitize-1-r2-141-dnxdp.18d4a28aabcae913,"reason=FailedScheduling count=None msg=0/6 nodes are available: 1 c_wall violated: 2 conflicting context pair(s) with node memory, 5 node(s) had untolerated taint(s). no new claims to deallocate, preemption: 0/6 nodes are available: 1 No preemption victims found for incoming pod, 5 Preemption is not helpful for scheduling."
0.3315,Event,ADDED,eval-sanitize-1-r2-141-dnxdp.18d4a28b1275f6e7,reason=Scheduled count=None msg=Successfully assigned compute/eval-sanitize-1-r2-141-dnxdp to kind-worker
0.3316,Event,ADDED,eval-sanitize-1-r2-141-dnxdp.18d4a28b2f46f358,"reason=Pulled count=1 msg=Container image ""busybox:musl"" already present on machine"
0.3318,Event,ADDED,eval-sanitize-1-r2-141-dnxdp.18d4a28b31d2bc33,reason=Created count=1 msg=Created container: task
0.3319,Event,ADDED,eval-sanitize-1-r2-141-dnxdp.18d4a28b343e1122,reason=Started count=1 msg=Started container task
0.3321,Event,ADDED,eval-sanitize-1-r2-141.18d4a28a6e3fa164,reason=SuccessfulCreate count=1 msg=Created pod: eval-sanitize-1-r2-141-dnxdp
0.3323,Event,ADDED,eval-sanitize-1-r2-141.18d4a29139306bcd,reason=Completed count=1 msg=Job completed
0.3324,Event,ADDED,eval-sanitize-1-r2-142-c74st.18d4a28aac0a86a9,"reason=FailedScheduling count=None msg=0/6 nodes are available: 1 c_wall violated: 1 conflicting context pair(s) with node memory, 5 node(s) had untolerated taint(s). no new claims to deallocate, preemption: 0/6 nodes are available: 1 No preemption victims found for incoming pod, 5 Preemption is not helpful for scheduling."
0.3326,Event,ADDED,eval-sanitize-1-r2-142-c74st.18d4a28ab18ab7c2,"reason=FailedScheduling count=None msg=0/6 nodes are available: 1 c_wall violated: 1 conflicting context pair(s) with node memory, 5 node(s) had untolerated taint(s). no new claims to deallocate, preemption: 0/6 nodes are available: 1 No preemption victims found for incoming pod, 5 Preemption is not helpful for scheduling."
0.3328,Event,ADDED,eval-sanitize-1-r2-142-c74st.18d4a28b0c1f99ec,reason=Scheduled count=None msg=Successfully assigned compute/eval-sanitize-1-r2-142-c74st to kind-worker
0.3329,Event,ADDED,eval-sanitize-1-r2-142-c74st.18d4a28b26e7fafe,"reason=Pulled count=1 msg=Container image ""busybox:musl"" already present on machine"
0.3332,Event,ADDED,eval-sanitize-1-r2-142-c74st.18d4a28b2b52f461,reason=Created count=1 msg=Created container: task
0.3334,Event,ADDED,eval-sanitize-1-r2-142-c74st.18d4a28b2e807bf2,reason=Started count=1 msg=Started container task
0.3336,Event,ADDED,eval-sanitize-1-r2-142.18d4a28aaa2ffdcc,reason=SuccessfulCreate count=1 msg=Created pod: eval-sanitize-1-r2-142-c74st
0.3338,Event,ADDED,eval-sanitize-1-r2-142.18d4a2914c2736f1,reason=Completed count=1 msg=Job completed
0.3341,Event,ADDED,eval-sanitize-1-r2-143-4sbc5.18d4a28b01ab30d7,"reason=FailedScheduling count=None msg=0/6 nodes are available: 6 node(s) had untolerated taint(s). no new claims to deallocate, preemption: 0/6 nodes are available: 6 Preemption is not helpful for scheduling."
0.3343,Event,ADDED,eval-sanitize-1-r2-143-4sbc5.18d4a28b12a4bd80,reason=Scheduled count=None msg=Successfully assigned compute/eval-sanitize-1-r2-143-4sbc5 to kind-worker
0.3345,Event,ADDED,eval-sanitize-1-r2-143-4sbc5.18d4a28b30308adb,"reason=Pulled count=1 msg=Container image ""busybox:musl"" already present on machine"
0.3346,Event,ADDED,eval-sanitize-1-r2-143-4sbc5.18d4a28b3284de6d,reason=Created count=1 msg=Created container: task
0.3349,Event,ADDED,eval-sanitize-1-r2-143-4sbc5.18d4a28b34b7ebfb,reason=Started count=1 msg=Started container task
0.335,Event,ADDED,eval-sanitize-1-r2-143.18d4a28b01a0c4ba,reason=SuccessfulCreate count=1 msg=Created pod: eval-sanitize-1-r2-143-4sbc5
0.3352,Event,ADDED,eval-sanitize-1-r2-143.18d4a2914bdce348,reason=Completed count=1 msg=Job completed
0.3355,Event,ADDED,eval-sanitize-1-r2-144-56g62.18d4a28b3bb390ae,"reason=FailedScheduling count=None msg=0/6 nodes are available: 1 c_wall violated: 3 conflicting context pair(s) with node memory, 5 node(s) had untolerated taint(s). no new claims to deallocate, preemption: 0/6 nodes are available: 1 No preemption victims found for incoming pod, 5 Preemption is not helpful for scheduling."
0.3357,Event,ADDED,eval-sanitize-1-r2-144-56g62.18d4a28b3c30f7aa,"reason=FailedScheduling count=None msg=0/6 nodes are available: 1 c_wall violated: 3 conflicting context pair(s) with node memory, 5 node(s) had untolerated taint(s). no new claims to deallocate, preemption: 0/6 nodes are available: 1 No preemption victims found for incoming pod, 5 Preemption is not helpful for scheduling."
0.3359,Event,ADDED,eval-sanitize-1-r2-144-56g62.18d4a28c60f25342,"reason=FailedScheduling count=None msg=0/6 nodes are available: 1 c_wall violated: 1 conflicting context pair(s) with node memory, 5 node(s) had untolerated taint(s). no new claims to deallocate, preemption: 0/6 nodes are available: 1 No preemption victims found for incoming pod, 5 Preemption is not helpful for scheduling."
0.3364,Event,ADDED,eval-sanitize-1-r2-144-56g62.18d4a28c67ef0040,"reason=FailedScheduling count=None msg=0/6 nodes are available: 1 c_wall violated: 1 conflicting context pair(s) with node memory, 5 node(s) had untolerated taint(s). no new claims to deallocate, preemption: 0/6 nodes are available: 1 No preemption victims found for incoming pod, 5 Preemption is not helpful for scheduling."
0.3366,Event,ADDED,eval-sanitize-1-r2-144-56g62.18d4a28c86b04d65,"reason=FailedScheduling count=None msg=0/6 nodes are available: 2 c_wall violated: 1 conflicting context pair(s) with node memory, 4 node(s) had untolerated taint(s). no new claims to deallocate, preemption: 0/6 nodes are available: 2 No preemption victims found for incoming pod, 4 Preemption is not helpful for scheduling."
0.3368,Event,ADDED,eval-sanitize-1-r2-144-56g62.18d4a28caa90ab5e,"reason=FailedScheduling count=None msg=0/6 nodes are available: 3 c_wall violated: 1 conflicting context pair(s) with node memory, 3 node(s) had untolerated taint(s). no new claims to deallocate, preemption: 0/6 nodes are available: 3 No preemption victims found for incoming pod, 3 Preemption is not helpful for scheduling."
0.3371,Event,ADDED,eval-sanitize-1-r2-144-56g62.18d4a28cd43314e9,"reason=FailedScheduling count=None msg=0/6 nodes are available: 2 c_wall violated: 1 conflicting context pair(s) with node memory, 4 node(s) had untolerated taint(s). no new claims to deallocate, preemption: 0/6 nodes are available: 2 No preemption victims found for incoming pod, 4 Preemption is not helpful for scheduling."
0.3372,Event,ADDED,eval-sanitize-1-r2-144-56g62.18d4a28cdb09dffd,"reason=FailedScheduling count=None msg=0/6 nodes are available: 1 c_wall violated: 1 conflicting context pair(s) with node memory, 5 node(s) had untolerated taint(s). no new claims to deallocate, preemption: 0/6 nodes are available: 1 No preemption victims found for incoming pod, 5 Preemption is not helpful for scheduling."
0.3374,Event,ADDED,eval-sanitize-1-r2-144-56g62.18d4a2910c46996b,reason=Scheduled count=None msg=Successfully assigned compute/eval-sanitize-1-r2-144-56g62 to kind-worker3
0.3376,Event,ADDED,eval-sanitize-1-r2-144-56g62.18d4a2912ea53eb3,"reason=Pulled count=1 msg=Container image ""busybox:musl"" already present on machine"
0.3377,Event,ADDED,eval-sanitize-1-r2-144-56g62.18d4a291325f1959,reason=Created count=1 msg=Created container: task
0.3379,Event,ADDED,eval-sanitize-1-r2-144-56g62.18d4a2913cb055f3,reason=Started count=1 msg=Started container task
0.3381,Event,ADDED,eval-sanitize-1-r2-144.18d4a28b3b7d624c,reason=SuccessfulCreate count=1 msg=Created pod: eval-sanitize-1-r2-144-56g62
0.3383,Event,ADDED,eval-sanitize-1-r2-144.18d4a296b7748bb2,reason=Completed count=1 msg=Job completed
0.3384,Event,ADDED,eval-sanitize-1-r2-145-7mbmq.18d4a28bb2257f73,"reason=FailedScheduling count=None msg=0/6 nodes are available: 6 node(s) had untolerated taint(s). no new claims to deallocate, preemption: 0/6 nodes are available: 6 Preemption is not helpful for scheduling."
0.3386,Event,ADDED,eval-sanitize-1-r2-145-7mbmq.18d4a28c63099441,reason=Scheduled count=None msg=Successfully assigned compute/eval-sanitize-1-r2-145-7mbmq to kind-worker2
0.3387,Event,ADDED,eval-sanitize-1-r2-145-7mbmq.18d4a28c841833c4,"reason=Pulled count=1 msg=Container image ""busybox:musl"" already present on machine"
0.3389,Event,ADDED,eval-sanitize-1-r2-145-7mbmq.18d4a28c870c9960,reason=Created count=1 msg=Created container: task
0.3391,Event,ADDED,eval-sanitize-1-r2-145-7mbmq.18d4a28c90535a64,reason=Started count=1 msg=Started container task
0.3392,Event,ADDED,eval-sanitize-1-r2-145.18d4a28bb2215cb9,reason=SuccessfulCreate count=1 msg=Created pod: eval-sanitize-1-r2-145-7mbmq
0.3394,Event,ADDED,eval-sanitize-1-r2-145.18d4a2920bac761e,reason=Completed count=1 msg=Job completed
0.3396,Event,ADDED,eval-sanitize-1-r2-146-p8nn9.18d4a28bf11617c5,"reason=FailedScheduling count=None msg=0/6 nodes are available: 6 node(s) had untolerated taint(s). no new claims to deallocate, preemption: 0/6 nodes are available: 6 Preemption is not helpful for scheduling."
0.3397,Event,ADDED,eval-sanitize-1-r2-146-p8nn9.18d4a28c62a8a703,"reason=FailedScheduling count=None msg=0/6 nodes are available: 1 c_wall violated: 2 conflicting context pair(s) with node memory, 5 node(s) had untolerated taint(s). no new claims to deallocate, preemption: 0/6 nodes are available: 1 No preemption victims found for incoming pod, 5 Preemption is not helpful for scheduling."
0.3399,Event,ADDED,eval-sanitize-1-r2-146-p8nn9.18d4a28c6a921e2c,"reason=FailedScheduling count=None msg=0/6 nodes are available: 1 c_wall violated: 2 conflicting context pair(s) with node memory, 5 node(s) had untolerated taint(s). no new claims to deallocate, preemption: 0/6 nodes are available: 1 No preemption victims found for incoming pod, 5 Preemption is not helpful for scheduling."
0.3401,Event,ADDED,eval-sanitize-1-r2-146-p8nn9.18d4a28c878bd79f,"reason=FailedScheduling count=None msg=0/6 nodes are available: 1 c_wall violated: 1 conflicting context pair(s) with node memory, 1 c_wall violated: 2 conflicting context pair(s) with node memory, 4 node(s) had untolerated taint(s). no new claims to deallocate, preemption: 0/6 nodes are available: 2 No preemption victims found for incoming pod, 4 Preemption is not helpful for scheduling."
0.3402,Event,ADDED,eval-sanitize-1-r2-146-p8nn9.18d4a28ca3fa3d9d,reason=Scheduled count=None msg=Successfully assigned compute/eval-sanitize-1-r2-146-p8nn9 to kind-worker5
0.3404,Event,ADDED,eval-sanitize-1-r2-146-p8nn9.18d4a28cd52705d3,"reason=Pulled count=1 msg=Container image ""busybox:musl"" already present on machine"
0.3406,Event,ADDED,eval-sanitize-1-r2-146-p8nn9.18d4a28cd6846650,reason=Created count=1 msg=Created container: task
0.3407,Event,ADDED,eval-sanitize-1-r2-146-p8nn9.18d4a28cd888d47a,reason=Started count=1 msg=Started container task
0.3409,Event,ADDED,eval-sanitize-1-r2-146.18d4a28bf10f25ae,reason=SuccessfulCreate count=1 msg=Created pod: eval-sanitize-1-r2-146-p8nn9
0.3411,Event,ADDED,eval-sanitize-1-r2-146.18d4a292cbfd5bb4,reason=Completed count=1 msg=Job completed
0.3412,Event,ADDED,eval-sanitize-1-r2-147-vr622.18d4a28c1a891a76,"reason=FailedScheduling count=None msg=0/6 nodes are available: 6 node(s) had untolerated taint(s). no new claims to deallocate, preemption: 0/6 nodes are available: 6 Preemption is not helpful for scheduling."
0.3414,Event,ADDED,eval-sanitize-1-r2-147-vr622.18d4a28c6708d508,reason=Scheduled count=None msg=Successfully assigned compute/eval-sanitize-1-r2-147-vr622 to kind-worker2
0.3416,Event,ADDED,eval-sanitize-1-r2-147-vr622.18d4a28c843b06e5,"reason=Pulled count=1 msg=Container image ""busybox:musl"" already present on machine"
0.3418,Event,ADDED,eval-sanitize-1-r2-147-vr622.18d4a28c878ed440,reason=Created count=1 msg=Created container: task
0.342,Event,ADDED,eval-sanitize-1-r2-147-vr622.18d4a28c905f4eae,reason=Started count=1 msg=Started container task
0.3421,Event,ADDED,eval-sanitize-1-r2-147.18d4a28c1a7eed5d,reason=SuccessfulCreate count=1 msg=Created pod: eval-sanitize-1-r2-147-vr622
0.3423,Event,ADDED,eval-sanitize-1-r2-147.18d4a29212b2e265,reason=Completed count=1 msg=Job completed
0.3424,Event,ADDED,eval-sanitize-1-r2-148-x7s9z.18d4a28c4755aa88,"reason=FailedScheduling count=None msg=0/6 nodes are available: 6 node(s) had untolerated taint(s). no new claims to deallocate, preemption: 0/6 nodes are available: 6 Preemption is not helpful for scheduling."
0.3426,Event,ADDED,eval-sanitize-1-r2-148-x7s9z.18d4a28c66ef5fb9,"reason=FailedScheduling count=None msg=0/6 nodes are available: 1 c_wall violated: 1 conflicting context pair(s) with node memory, 5 node(s) had untolerated taint(s). no new claims to deallocate, preemption: 0/6 nodes are available: 1 No preemption victims found for incoming pod, 5 Preemption is not helpful for scheduling."
0.3428,Event,ADDED,eval-sanitize-1-r2-148-x7s9z.18d4a28c6c77bd9a,"reason=FailedScheduling count=None msg=0/6 nodes are available: 1 c_wall violated: 1 conflicting context pair(s) with node memory, 5 node(s) had untolerated taint(s). no new claims to deallocate, preemption: 0/6 nodes are available: 1 No preemption victims found for incoming pod, 5 Preemption is not helpful for scheduling."
0.343,Event,ADDED,eval-sanitize-1-r2-148-x7s9z.18d4a28c7bc5d411,reason=Scheduled count=None msg=Successfully assigned compute/eval-sanitize-1-r2-148-x7s9z to kind-worker4
0.3431,Event,ADDED,eval-sanitize-1-r2-148-x7s9z.18d4a28c9a27d023,"reason=Pulled count=1 msg=Container image ""busybox:musl"" already present on machine"
0.3433,Event,ADDED,eval-sanitize-1-r2-148-x7s9z.18d4a28c9bc8459a,reason=Created count=1 msg=Created container: task
0.3435,Event,ADDED,eval-sanitize-1-r2-148-x7s9z.18d4a28ca3e20464,reason=Started count=1 msg=Started container task
0.3436,Event,ADDED,eval-sanitize-1-r2-148.18d4a28c474af3cb,reason=SuccessfulCreate count=1 msg=Created pod: eval-sanitize-1-r2-148-x7s9z
0.3438,Event,ADDED,eval-sanitize-1-r2-148.18d4a29274d12067,reason=Completed count=1 msg=Job completed
0.3439,Event,ADDED,eval-sanitize-1-r2-149-bz4b5.18d4a28c634b5988,"reason=FailedScheduling count=None msg=0/6 nodes are available: 1 c_wall violated: 1 conflicting context pair(s) with node memory, 5 node(s) had untolerated taint(s). no new claims to deallocate, preemption: 0/6 nodes are available: 1 No preemption victims found for incoming pod, 5 Preemption is not helpful for scheduling."
0.3441,Event,ADDED,eval-sanitize-1-r2-149-bz4b5.18d4a28c6ac0336d,"reason=FailedScheduling count=None msg=0/6 nodes are available: 1 c_wall violated: 1 conflicting context pair(s) with node memory, 5 node(s) had untolerated taint(s). no new claims to deallocate, preemption: 0/6 nodes are available: 1 No preemption victims found for incoming pod, 5 Preemption is not helpful for scheduling."
0.3443,Event,ADDED,eval-sanitize-1-r2-149-bz4b5.18d4a28c7b294680,reason=Scheduled count=None msg=Successfully assigned compute/eval-sanitize-1-r2-149-bz4b5 to kind-worker4
0.3445,Event,ADDED,eval-sanitize-1-r2-149-bz4b5.18d4a28c99f9a8b0,"reason=Pulled count=1 msg=Container image ""busybox:musl"" already present on machine"
0.3446,Event,ADDED,eval-sanitize-1-r2-149-bz4b5.18d4a28c9b71d2a0,reason=Created count=1 msg=Created container: task
0.3448,Event,ADDED,eval-sanitize-1-r2-149-bz4b5.18d4a28ca3e0436f,reason=Started count=1 msg=Started container task
0.345,Event,ADDED,eval-sanitize-1-r2-149.18d4a28c62396257,reason=SuccessfulCreate count=1 msg=Created pod: eval-sanitize-1-r2-149-bz4b5
0.3451,Event,ADDED,eval-sanitize-1-r2-149.18d4a29274f11d12,reason=Completed count=1 msg=Job completed
0.3453,Event,ADDED,eval-sanitize-1-r2-150-t8btn.18d4a28c91a4c2e6,reason=Scheduled count=None msg=Successfully assigned compute/eval-sanitize-1-r2-150-t8btn to kind-worker4
0.3454,Event,ADDED,eval-sanitize-1-r2-150-t8btn.18d4a28caeec1ca3,"reason=Pulled count=1 msg=Container image ""busybox:musl"" already present on machine"
0.3456,Event,ADDED,eval-sanitize-1-r2-150-t8btn.18d4a28cb043deaa,reason=Created count=1 msg=Created container: task
0.3458,Event,ADDED,eval-sanitize-1-r2-150-t8btn.18d4a28cbb55efc2,reason=Started count=1 msg=Started container task
0.3459,Event,ADDED,eval-sanitize-1-r2-150.18d4a28c904ebbe0,reason=SuccessfulCreate count=1 msg=Created pod: eval-sanitize-1-r2-150-t8btn
0.3461,Event,ADDED,eval-sanitize-1-r2-150.18d4a292b6a83d29,reason=Completed count=1 msg=Job completed
0.3463,Event,ADDED,eval-sanitize-1-r2-151-8s52v.18d4a28cc44bee03,reason=Scheduled count=None msg=Successfully assigned compute/eval-sanitize-1-r2-151-8s52v to kind-worker5
0.3465,Event,ADDED,eval-sanitize-1-r2-151-8s52v.18d4a28ce0f5ad20,"reason=Pulled count=1 msg=Container image ""busybox:musl"" already present on machine"
0.3467,Event,ADDED,eval-sanitize-1-r2-151-8s52v.18d4a28ce26bb013,reason=Created count=1 msg=Created container: task
0.3468,Event,ADDED,eval-sanitize-1-r2-151-8s52v.18d4a28cea7941c2,reason=Started count=1 msg=Started container task
0.347,Event,ADDED,eval-sanitize-1-r2-151.18d4a28cc347bc0a,reason=SuccessfulCreate count=1 msg=Created pod: eval-sanitize-1-r2-151-8s52v
0.3472,Event,ADDED,eval-sanitize-1-r2-151.18d4a292e6c23916,reason=Completed count=1 msg=Job completed
0.3474,Event,ADDED,eval-sanitize-1-r2-152-5sg95.18d4a28cff3deb08,reason=Scheduled count=None msg=Successfully assigned compute/eval-sanitize-1-r2-152-5sg95 to kind-worker5
0.3476,Event,ADDED,eval-sanitize-1-r2-152-5sg95.18d4a28d1c162896,"reason=Pulled count=1 msg=Container image ""busybox:musl"" already present on machine"
0.3477,Event,ADDED,eval-sanitize-1-r2-152-5sg95.18d4a28d1d32ad18,reason=Created count=1 msg=Created container: task
0.3479,Event,ADDED,eval-sanitize-1-r2-152-5sg95.18d4a28d2152ad4d,reason=Started count=1 msg=Started container task
0.3481,Event,ADDED,eval-sanitize-1-r2-152.18d4a28cfeae4509,reason=SuccessfulCreate count=1 msg=Created pod: eval-sanitize-1-r2-152-5sg95
0.3482,Event,ADDED,eval-sanitize-1-r2-152.18d4a2930769e0cd,reason=Completed count=1 msg=Job completed
0.3484,Event,ADDED,eval-sanitize-1-r2-153-227rw.18d4a28d393aeb53,"reason=FailedScheduling count=None msg=0/6 nodes are available: 6 node(s) had untolerated taint(s). no new claims to deallocate, preemption: 0/6 nodes are available: 6 Preemption is not helpful for scheduling."
0.3485,Event,ADDED,eval-sanitize-1-r2-153-227rw.18d4a2910c9fec6f,"reason=FailedScheduling count=None msg=0/6 nodes are available: 1 c_wall violated: 1 conflicting context pair(s) with node memory, 5 node(s) had untolerated taint(s). no new claims to deallocate, preemption: 0/6 nodes are available: 1 No preemption victims found for incoming pod, 5 Preemption is not helpful for scheduling."
0.3487,Event,ADDED,eval-sanitize-1-r2-153-227rw.18d4a2912628129b,reason=Scheduled count=None msg=Successfully assigned compute/eval-sanitize-1-r2-153-227rw to kind-worker
0.3489,Event,ADDED,eval-sanitize-1-r2-153-227rw.18d4a2914094ce5d,"reason=Pulled count=1 msg=Container image ""busybox:musl"" already present on machine"
0.3491,Event,ADDED,eval-sanitize-1-r2-153-227rw.18d4a291421c39b5,reason=Created count=1 msg=Created container: task
0.3493,Event,ADDED,eval-sanitize-1-r2-153-227rw.18d4a2914bf60c92,reason=Started count=1 msg=Started container task
0.3494,Event,ADDED,eval-sanitize-1-r2-153.18d4a28d393161f3,reason=SuccessfulCreate count=1 msg=Created pod: eval-sanitize-1-r2-153-227rw
0.3496,Event,ADDED,eval-sanitize-1-r2-153.18d4a296c1b40b3f,reason=Completed count=1 msg=Job completed
0.3497,Event,ADDED,eval-sanitize-1-r2-154-7kldt.18d4a28d75296a63,"reason=FailedScheduling count=None msg=0/6 nodes are available: 6 node(s) had untolerated taint(s). no new claims to deallocate, preemption: 0/6 nodes are available: 6 Preemption is not helpful for scheduling."
0.3499,Event,ADDED,eval-sanitize-1-r2-154-7kldt.18d4a2910d2d71ab,"reason=FailedScheduling count=None msg=0/6 nodes are available: 1 c_wall violated: 1 conflicting context pair(s) with node memory, 5 node(s) had untolerated taint(s). no new claims to deallocate, preemption: 0/6 nodes are available: 1 No preemption victims found for incoming pod, 5 Preemption is not helpful for scheduling."
0.35,Event,ADDED,eval-sanitize-1-r2-154-7kldt.18d4a2912a658cae,"reason=FailedScheduling count=None msg=0/6 nodes are available: 1 c_wall violated: 1 conflicting context pair(s) with node memory, 1 c_wall violated: 2 conflicting context pair(s) with node memory, 4 node(s) had untolerated taint(s). no new claims to deallocate, preemption: 0/6 nodes are available: 2 No preemption victims found for incoming pod, 4 Preemption is not helpful for scheduling."
0.3502,Event,ADDED,eval-sanitize-1-r2-154-7kldt.18d4a29140bac5c1,"reason=FailedScheduling count=None msg=0/6 nodes are available: 1 c_wall violated: 1 conflicting context pair(s) with node memory, 1 c_wall violated: 2 conflicting context pair(s) with node memory, 4 node(s) had untolerated taint(s). no new claims to deallocate, preemption: 0/6 nodes are available: 2 No preemption victims found for incoming pod, 4 Preemption is not helpful for scheduling."
0.3504,Event,ADDED,eval-sanitize-1-r2-154-7kldt.18d4a2917393ffc4,"reason=FailedScheduling count=None msg=0/6 nodes are available: 6 node(s) had untolerated taint(s). no new claims to deallocate, preemption: 0/6 nodes are available: 6 Preemption is not helpful for scheduling."
0.3505,Event,ADDED,eval-sanitize-1-r2-154-7kldt.18d4a291d7e96618,reason=Scheduled count=None msg=Successfully assigned compute/eval-sanitize-1-r2-154-7kldt to kind-worker2
0.3507,Event,ADDED,eval-sanitize-1-r2-154-7kldt.18d4a291f38fbd62,"reason=Pulled count=1 msg=Container image ""busybox:musl"" already present on machine"
0.3508,Event,ADDED,eval-sanitize-1-r2-154-7kldt.18d4a291f741fe69,reason=Created count=1 msg=Created container: task
0.351,Event,ADDED,eval-sanitize-1-r2-154-7kldt.18d4a292007a1953,reason=Started count=1 msg=Started container task
0.3512,Event,ADDED,eval-sanitize-1-r2-154.18d4a28d751f1026,reason=SuccessfulCreate count=1 msg=Created pod: eval-sanitize-1-r2-154-7kldt
0.3513,Event,ADDED,eval-sanitize-1-r2-154.18d4a2981463c912,reason=Completed count=1 msg=Job completed
0.3515,Event,ADDED,eval-sanitize-1-r2-155-wmcrd.18d4a28db06a5c19,"reason=FailedScheduling count=None msg=0/6 nodes are available: 6 node(s) had untolerated taint(s). no new claims to deallocate, preemption: 0/6 nodes are available: 6 Preemption is not helpful for scheduling."
0.3516,Event,ADDED,eval-sanitize-1-r2-155-wmcrd.18d4a2910db739f1,"reason=FailedScheduling count=None msg=0/6 nodes are available: 1 c_wall violated: 1 conflicting context pair(s) with node memory, 5 node(s) had untolerated taint(s). no new claims to deallocate, preemption: 0/6 nodes are available: 1 No preemption victims found for incoming pod, 5 Preemption is not helpful for scheduling."
0.3518,Event,ADDED,eval-sanitize-1-r2-155-wmcrd.18d4a2912b292bac,"reason=FailedScheduling count=None msg=0/6 nodes are available: 1 c_wall violated: 1 conflicting context pair(s) with node memory, 1 c_wall violated: 2 conflicting context pair(s) with node memory, 4 node(s) had untolerated taint(s). no new claims to deallocate, preemption: 0/6 nodes are available: 2 No preemption victims found for incoming pod, 4 Preemption is not helpful for scheduling."
0.352,Event,ADDED,eval-sanitize-1-r2-155-wmcrd.18d4a29141138321,"reason=FailedScheduling count=None msg=0/6 nodes are available: 1 c_wall violated: 1 conflicting context pair(s) with node memory, 1 c_wall violated: 2 conflicting context pair(s) with node memory, 4 node(s) had untolerated taint(s). no new claims to deallocate, preemption: 0/6 nodes are available: 2 No preemption victims found for incoming pod, 4 Preemption is not helpful for scheduling."
0.3521,Event,ADDED,eval-sanitize-1-r2-155-wmcrd.18d4a29173f6b697,"reason=FailedScheduling count=None msg=0/6 nodes are available: 6 node(s) had untolerated taint(s). no new claims to deallocate, preemption: 0/6 nodes are available: 6 Preemption is not helpful for scheduling."
0.3523,Event,ADDED,eval-sanitize-1-r2-155-wmcrd.18d4a291d7e41857,reason=Scheduled count=None msg=Successfully assigned compute/eval-sanitize-1-r2-155-wmcrd to kind-worker2
0.3524,Event,ADDED,eval-sanitize-1-r2-155-wmcrd.18d4a291f3e4f4b9,"reason=Pulled count=1 msg=Container image ""busybox:musl"" already present on machine"
0.3526,Event,ADDED,eval-sanitize-1-r2-155-wmcrd.18d4a291f80a9a32,reason=Created count=1 msg=Created container: task
0.3528,Event,ADDED,eval-sanitize-1-r2-155-wmcrd.18d4a292007a247e,reason=Started count=1 msg=Started container task
0.3529,Event,ADDED,eval-sanitize-1-r2-155.18d4a28db05d35ed,reason=SuccessfulCreate count=1 msg=Created pod: eval-sanitize-1-r2-155-wmcrd
0.3531,Event,ADDED,eval-sanitize-1-r2-155.18d4a297eddf2b88,reason=Completed count=1 msg=Job completed
0.3532,Event,ADDED,eval-sanitize-1-r2-156-8cdmb.18d4a28dec0912cb,"reason=FailedScheduling count=None msg=0/6 nodes are available: 6 node(s) had untolerated taint(s). no new claims to deallocate, preemption: 0/6 nodes are available: 6 Preemption is not helpful for scheduling."
0.3534,Event,ADDED,eval-sanitize-1-r2-156-8cdmb.18d4a2910e347f83,"reason=FailedScheduling count=None msg=0/6 nodes are available: 1 c_wall violated: 1 conflicting context pair(s) with node memory, 5 node(s) had untolerated taint(s). no new claims to deallocate, preemption: 0/6 nodes are available: 1 No preemption victims found for incoming pod, 5 Preemption is not helpful for scheduling."
0.3535,Event,ADDED,eval-sanitize-1-r2-156-8cdmb.18d4a2912bd3f72e,"reason=FailedScheduling count=None msg=0/6 nodes are available: 1 c_wall violated: 1 conflicting context pair(s) with node memory, 1 c_wall violated: 2 conflicting context pair(s) with node memory, 4 node(s) had untolerated taint(s). no new claims to deallocate, preemption: 0/6 nodes are available: 2 No preemption victims found for incoming pod, 4 Preemption is not helpful for scheduling."
0.3537,Event,ADDED,eval-sanitize-1-r2-156-8cdmb.18d4a291417244fb,"reason=FailedScheduling count=None msg=0/6 nodes are available: 2 c_wall violated: 2 conflicting context pair(s) with node memory, 4 node(s) had untolerated taint(s). no new claims to deallocate, preemption: 0/6 nodes are available: 2 No preemption victims found for incoming pod, 4 Preemption is not helpful for scheduling."
0.354,Event,ADDED,eval-sanitize-1-r2-156-8cdmb.18d4a2916171f7b9,"reason=FailedScheduling count=None msg=0/6 nodes are available: 1 c_wall violated: 2 conflicting context pair(s) with node memory, 5 node(s) had untolerated taint(s). no new claims to deallocate, preemption: 0/6 nodes are available: 1 No preemption victims found for incoming pod, 5 Preemption is not helpful for scheduling."
0.3541,Event,ADDED,eval-sanitize-1-r2-156-8cdmb.18d4a291743ead9a,"reason=FailedScheduling count=None msg=0/6 nodes are available: 6 node(s) had untolerated taint(s). no new claims to deallocate, preemption: 0/6 nodes are available: 6 Preemption is not helpful for scheduling."
0.3543,Event,ADDED,eval-sanitize-1-r2-156-8cdmb.18d4a291d42a5adb,"reason=FailedScheduling count=None msg=0/6 nodes are available: 1 c_wall violated: 2 conflicting context pair(s) with node memory, 5 node(s) had untolerated taint(s). no new claims to deallocate, preemption: 0/6 nodes are available: 1 No preemption victims found for incoming pod, 5 Preemption is not helpful for scheduling."
0.3545,Event,ADDED,eval-sanitize-1-r2-156-8cdmb.18d4a291d9eec321,"reason=FailedScheduling count=None msg=0/6 nodes are available: 1 c_wall violated: 2 conflicting context pair(s) with node memory, 5 node(s) had untolerated taint(s). no new claims to deallocate, preemption: 0/6 nodes are available: 1 No preemption victims found for incoming pod, 5 Preemption is not helpful for scheduling."
0.3546,Event,ADDED,eval-sanitize-1-r2-156-8cdmb.18d4a29217215a07,reason=Scheduled count=None msg=Successfully assigned compute/eval-sanitize-1-r2-156-8cdmb to kind-worker4
0.3548,Event,ADDED,eval-sanitize-1-r2-156-8cdmb.18d4a292336de22e,"reason=Pulled count=1 msg=Container image ""busybox:musl"" already present on machine"
0.355,Event,ADDED,eval-sanitize-1-r2-156-8cdmb.18d4a292348ef844,reason=Created count=1 msg=Created container: task
0.3552,Event,ADDED,eval-sanitize-1-r2-156-8cdmb.18d4a2923796b0b4,reason=Started count=1 msg=Started container task
0.3553,Event,ADDED,eval-sanitize-1-r2-156.18d4a28debf8ca1d,reason=SuccessfulCreate count=1 msg=Created pod: eval-sanitize-1-r2-156-8cdmb
0.3555,Event,ADDED,eval-sanitize-1-r2-156.18d4a297e2b06dd7,reason=Completed count=1 msg=Job completed
0.3558,Event,ADDED,eval-sanitize-1-r2-157-k6wnr.18d4a28e279096cd,"reason=FailedScheduling count=None msg=0/6 nodes are available: 6 node(s) had untolerated taint(s). no new claims to deallocate, preemption: 0/6 nodes are available: 6 Preemption is not helpful for scheduling."
0.3559,Event,ADDED,eval-sanitize-1-r2-157-k6wnr.18d4a2910f39e477,reason=Scheduled count=None msg=Successfully assigned compute/eval-sanitize-1-r2-157-k6wnr to kind-worker3
0.3561,Event,ADDED,eval-sanitize-1-r2-157-k6wnr.18d4a2912f8250eb,"reason=Pulled count=1 msg=Container image ""busybox:musl"" already present on machine"
0.3563,Event,ADDED,eval-sanitize-1-r2-157-k6wnr.18d4a2913288f9aa,reason=Created count=1 msg=Created container: task
0.3565,Event,ADDED,eval-sanitize-1-r2-157-k6wnr.18d4a2913e7492dd,reason=Started count=1 msg=Started container task
0.3566,Event,ADDED,eval-sanitize-1-r2-157.18d4a28e27845ec5,reason=SuccessfulCreate count=1 msg=Created pod: eval-sanitize-1-r2-157-k6wnr
0.3568,Event,ADDED,eval-sanitize-1-r2-157.18d4a296b83ab9fa,reason=Completed count=1 msg=Job completed
0.357,Event,ADDED,eval-sanitize-1-r2-158-9mccj.18d4a28e6315f397,"reason=FailedScheduling count=None msg=0/6 nodes are available: 6 node(s) had untolerated taint(s). no new claims to deallocate, preemption: 0/6 nodes are available: 6 Preemption is not helpful for scheduling."
0.3571,Event,ADDED,eval-sanitize-1-r2-158-9mccj.18d4a2910f296da8,"reason=FailedScheduling count=None msg=0/6 nodes are available: 1 c_wall violated: 1 conflicting context pair(s) with node memory, 5 node(s) had untolerated taint(s). no new claims to deallocate, preemption: 0/6 nodes are available: 1 No preemption victims found for incoming pod, 5 Preemption is not helpful for scheduling."
0.3573,Event,ADDED,eval-sanitize-1-r2-158-9mccj.18d4a2912f022b07,"reason=FailedScheduling count=None msg=0/6 nodes are available: 2 c_wall violated: 1 conflicting context pair(s) with node memory, 4 node(s) had untolerated taint(s). no new claims to deallocate, preemption: 0/6 nodes are available: 2 No preemption victims found for incoming pod, 4 Preemption is not helpful for scheduling."
0.3575,Event,ADDED,eval-sanitize-1-r2-158-9mccj.18d4a29146bc5cb4,"reason=FailedScheduling count=None msg=0/6 nodes are available: 2 c_wall violated: 1 conflicting context pair(s) with node memory, 4 node(s) had untolerated taint(s). no new claims to deallocate, preemption: 0/6 nodes are available: 2 No preemption victims found for incoming pod, 4 Preemption is not helpful for scheduling."
0.3577,Event,ADDED,eval-sanitize-1-r2-158-9mccj.18d4a291749e4277,"reason=FailedScheduling count=None msg=0/6 nodes are available: 6 node(s) had untolerated taint(s). no new claims to deallocate, preemption: 0/6 nodes are available: 6 Preemption is not helpful for scheduling."
0.3579,Event,ADDED,eval-sanitize-1-r2-158-9mccj.18d4a291d8b96d9a,reason=Scheduled count=None msg=Successfully assigned compute/eval-sanitize-1-r2-158-9mccj to kind-worker2
0.3581,Event,ADDED,eval-sanitize-1-r2-158-9mccj.18d4a291f3b84dd4,"reason=Pulled count=1 msg=Container image ""busybox:musl"" already present on machine"
0.3583,Event,ADDED,eval-sanitize-1-r2-158-9mccj.18d4a291f7badf86,reason=Created count=1 msg=Created container: task
0.3585,Event,ADDED,eval-sanitize-1-r2-158-9mccj.18d4a2920081ea02,reason=Started count=1 msg=Started container task
0.3587,Event,ADDED,eval-sanitize-1-r2-158.18d4a28e630c9953,reason=SuccessfulCreate count=1 msg=Created pod: eval-sanitize-1-r2-158-9mccj
0.3589,Event,ADDED,eval-sanitize-1-r2-158.18d4a2980c0afb39,reason=Completed count=1 msg=Job completed
0.359,Event,ADDED,eval-sanitize-1-r2-159-q62r9.18d4a28ea1b06c73,"reason=FailedScheduling count=None msg=0/6 nodes are available: 6 node(s) had untolerated taint(s). no new claims to deallocate, preemption: 0/6 nodes are available: 6 Preemption is not helpful for scheduling."
0.3592,Event,ADDED,eval-sanitize-1-r2-159-q62r9.18d4a2911144daed,reason=Scheduled count=None msg=Successfully assigned compute/eval-sanitize-1-r2-159-q62r9 to kind-worker3
0.3593,Event,ADDED,eval-sanitize-1-r2-159-q62r9.18d4a2913447e406,"reason=Pulled count=1 msg=Container image ""busybox:musl"" already present on machine"
0.3595,Event,ADDED,eval-sanitize-1-r2-159-q62r9.18d4a291367da87e,reason=Created count=1 msg=Created container: task
0.3597,Event,ADDED,eval-sanitize-1-r2-159-q62r9.18d4a2913909e2a9,reason=Started count=1 msg=Started container task
0.3598,Event,ADDED,eval-sanitize-1-r2-159.18d4a28ea1a4081d,reason=SuccessfulCreate count=1 msg=Created pod: eval-sanitize-1-r2-159-q62r9
0.36,Event,ADDED,eval-sanitize-1-r2-159.18d4a296b7719f43,reason=Completed count=1 msg=Job completed
0.3602,Event,ADDED,eval-sanitize-1-r2-160-xkmgq.18d4a28eda4fa5b3,"reason=FailedScheduling count=None msg=0/6 nodes are available: 6 node(s) had untolerated taint(s). no new claims to deallocate, preemption: 0/6 nodes are available: 6 Preemption is not helpful for scheduling."
0.3603,Event,ADDED,eval-sanitize-1-r2-160-xkmgq.18d4a29111700666,reason=Scheduled count=None msg=Successfully assigned compute/eval-sanitize-1-r2-160-xkmgq to kind-worker3
0.3605,Event,ADDED,eval-sanitize-1-r2-160-xkmgq.18d4a291348f8856,"reason=Pulled count=1 msg=Container image ""busybox:musl"" already present on machine"
0.3606,Event,ADDED,eval-sanitize-1-r2-160-xkmgq.18d4a29137876dbc,reason=Created count=1 msg=Created container: task
0.3608,Event,ADDED,eval-sanitize-1-r2-160-xkmgq.18d4a29139fb72ba,reason=Started count=1 msg=Started container task
0.361,Event,ADDED,eval-sanitize-1-r2-160.18d4a28eda444db5,reason=SuccessfulCreate count=1 msg=Created pod: eval-sanitize-1-r2-160-xkmgq
0.3611,Event,ADDED,eval-sanitize-1-r2-160.18d4a296b7738a67,reason=Completed count=1 msg=Job completed
0.3613,Event,ADDED,eval-sanitize-1-r2-161-lqddh.18d4a28f160c54b5,"reason=FailedScheduling count=None msg=0/6 nodes are available: 6 node(s) had untolerated taint(s). no new claims to deallocate, preemption: 0/6 nodes are available: 6 Preemption is not helpful for scheduling."
0.3614,Event,ADDED,eval-sanitize-1-r2-161-lqddh.18d4a291128c7983,reason=Scheduled count=None msg=Successfully assigned compute/eval-sanitize-1-r2-161-lqddh to kind-worker3
0.3616,Event,ADDED,eval-sanitize-1-r2-161-lqddh.18d4a29134554698,"reason=Pulled count=1 msg=Container image ""busybox:musl"" already present on machine"
0.3618,Event,ADDED,eval-sanitize-1-r2-161-lqddh.18d4a291372374d0,reason=Created count=1 msg=Created container: task
0.3619,Event,ADDED,eval-sanitize-1-r2-161-lqddh.18d4a29139c3b82f,reason=Started count=1 msg=Started container task
0.3621,Event,ADDED,eval-sanitize-1-r2-161.18d4a28f1603e3c4,reason=SuccessfulCreate count=1 msg=Created pod: eval-sanitize-1-r2-161-lqddh
0.3623,Event,ADDED,eval-sanitize-1-r2-161.18d4a296b8100239,reason=Completed count=1 msg=Job completed
0.3624,Event,ADDED,eval-sanitize-1-r2-162-ng2q9.18d4a28f528e5cde,"reason=FailedScheduling count=None msg=0/6 nodes are available: 6 node(s) had untolerated taint(s). no new claims to deallocate, preemption: 0/6 nodes are available: 6 Preemption is not helpful for scheduling."
0.3626,Event,ADDED,eval-sanitize-1-r2-162-ng2q9.18d4a291117a0b80,"reason=FailedScheduling count=None msg=0/6 nodes are available: 1 c_wall violated: 2 conflicting context pair(s) with node memory, 5 node(s) had untolerated taint(s). no new claims to deallocate, preemption: 0/6 nodes are available: 1 No preemption victims found for incoming pod, 5 Preemption is not helpful for scheduling."
0.3627,Event,ADDED,eval-sanitize-1-r2-162-ng2q9.18d4a291302e84d3,"reason=FailedScheduling count=None msg=0/6 nodes are available: 1 c_wall violated: 1 conflicting context pair(s) with node memory, 1 c_wall violated: 2 conflicting context pair(s) with node memory, 4 node(s) had untolerated taint(s). no new claims to deallocate, preemption: 0/6 nodes are available: 2 No preemption victims found for incoming pod, 4 Preemption is not helpful for scheduling."
0.3629,Event,ADDED,eval-sanitize-1-r2-162-ng2q9.18d4a291470efeba,"reason=FailedScheduling count=None msg=0/6 nodes are available: 1 c_wall violated: 1 conflicting context pair(s) with node memory, 1 c_wall violated: 2 conflicting context pair(s) with node memory, 4 node(s) had untolerated taint(s). no new claims to deallocate, preemption: 0/6 nodes are available: 2 No preemption victims found for incoming pod, 4 Preemption is not helpful for scheduling."
0.3631,Event,ADDED,eval-sanitize-1-r2-162-ng2q9.18d4a291cfd8e11b,reason=Scheduled count=None msg=Successfully assigned compute/eval-sanitize-1-r2-162-ng2q9 to kind-worker2
0.3632,Event,ADDED,eval-sanitize-1-r2-162-ng2q9.18d4a2920adea439,"reason=Pulled count=1 msg=Container image ""busybox:musl"" already present on machine"
0.3634,Event,ADDED,eval-sanitize-1-r2-162-ng2q9.18d4a2920d5ed509,reason=Created count=1 msg=Created container: task
0.3636,Event,ADDED,eval-sanitize-1-r2-162-ng2q9.18d4a29212375944,reason=Started count=1 msg=Started container task
0.3638,Event,ADDED,eval-sanitize-1-r2-162.18d4a28f528204ad,reason=SuccessfulCreate count=1 msg=Created pod: eval-sanitize-1-r2-162-ng2q9
0.364,Event,ADDED,eval-sanitize-1-r2-162.18d4a2981d5e3fd9,reason=Completed count=1 msg=Job completed
0.3642,Event,ADDED,eval-sanitize-1-r2-163-xdkkx.18d4a28f9068aa47,"reason=FailedScheduling count=None msg=0/6 nodes are available: 6 node(s) had untolerated taint(s). no new claims to deallocate, preemption: 0/6 nodes are available: 6 Preemption is not helpful for scheduling."
0.3644,Event,ADDED,eval-sanitize-1-r2-163-xdkkx.18d4a29112d20405,"reason=FailedScheduling count=None msg=0/6 nodes are available: 1 c_wall violated: 2 conflicting context pair(s) with node memory, 5 node(s) had untolerated taint(s). no new claims to deallocate, preemption: 0/6 nodes are available: 1 No preemption victims found for incoming pod, 5 Preemption is not helpful for scheduling."
0.3646,Event,ADDED,eval-sanitize-1-r2-163-xdkkx.18d4a2913580bec0,reason=Scheduled count=None msg=Successfully assigned compute/eval-sanitize-1-r2-163-xdkkx to kind-worker
0.3647,Event,ADDED,eval-sanitize-1-r2-163-xdkkx.18d4a29160822b58,"reason=Pulled count=1 msg=Container image ""busybox:musl"" already present on machine"
0.365,Event,ADDED,eval-sanitize-1-r2-163-xdkkx.18d4a2916265d810,reason=Created count=1 msg=Created container: task
0.3652,Event,ADDED,eval-sanitize-1-r2-163-xdkkx.18d4a29172ff999a,reason=Started count=1 msg=Started container task
0.3654,Event,ADDED,eval-sanitize-1-r2-163.18d4a28f905f1ef1,reason=SuccessfulCreate count=1 msg=Created pod: eval-sanitize-1-r2-163-xdkkx
0.3657,Event,ADDED,eval-sanitize-1-r2-163.18d4a296c6e67c2a,reason=Completed count=1 msg=Job completed
0.3659,Event,ADDED,eval-sanitize-1-r2-164-p68zw.18d4a28fc8e6124b,"reason=FailedScheduling count=None msg=0/6 nodes are available: 6 node(s) had untolerated taint(s). no new claims to deallocate, preemption: 0/6 nodes are available: 6 Preemption is not helpful for scheduling."
0.3661,Event,ADDED,eval-sanitize-1-r2-164-p68zw.18d4a29114a3399c,"reason=FailedScheduling count=None msg=0/6 nodes are available: 1 c_wall violated: 1 conflicting context pair(s) with node memory, 5 node(s) had untolerated taint(s). no new claims to deallocate, preemption: 0/6 nodes are available: 1 No preemption victims found for incoming pod, 5 Preemption is not helpful for scheduling."
0.3662,Event,ADDED,eval-sanitize-1-r2-164-p68zw.18d4a29136018732,"reason=FailedScheduling count=None msg=0/6 nodes are available: 2 c_wall violated: 1 conflicting context pair(s) with node memory, 4 node(s) had untolerated taint(s). no new claims to deallocate, preemption: 0/6 nodes are available: 2 No preemption victims found for incoming pod, 4 Preemption is not helpful for scheduling."
0.3665,Event,ADDED,eval-sanitize-1-r2-164-p68zw.18d4a291479f2af1,"reason=FailedScheduling count=None msg=0/6 nodes are available: 2 c_wall violated: 1 conflicting context pair(s) with node memory, 4 node(s) had untolerated taint(s). no new claims to deallocate, preemption: 0/6 nodes are available: 2 No preemption victims found for incoming pod, 4 Preemption is not helpful for scheduling."
0.3667,Event,ADDED,eval-sanitize-1-r2-164-p68zw.18d4a291d32b4b40,reason=Scheduled count=None msg=Successfully assigned compute/eval-sanitize-1-r2-164-p68zw to kind-worker2
0.3669,Event,ADDED,eval-sanitize-1-r2-164-p68zw.18d4a2920b4d8635,"reason=Pulled count=1 msg=Container image ""busybox:musl"" already present on machine"
0.3672,Event,ADDED,eval-sanitize-1-r2-164-p68zw.18d4a2920ed6a63c,reason=Created count=1 msg=Created container: task
0.3674,Event,ADDED,eval-sanitize-1-r2-164-p68zw.18d4a292136e22da,reason=Started count=1 msg=Started container task
0.3676,Event,ADDED,eval-sanitize-1-r2-164.18d4a28fc8dc6c5b,reason=SuccessfulCreate count=1 msg=Created pod: eval-sanitize-1-r2-164-p68zw
0.3677,Event,ADDED,eval-sanitize-1-r2-164.18d4a298110a342c,reason=Completed count=1 msg=Job completed
0.3679,Event,ADDED,eval-sanitize-1-r2-165-lc9c4.18d4a290049fb7c6,"reason=FailedScheduling count=None msg=0/6 nodes are available: 6 node(s) had untolerated taint(s). no new claims to deallocate, preemption: 0/6 nodes are available: 6 Preemption is not helpful for scheduling."
0.3681,Event,ADDED,eval-sanitize-1-r2-165-lc9c4.18d4a2911ac37f3c,reason=Scheduled count=None msg=Successfully assigned compute/eval-sanitize-1-r2-165-lc9c4 to kind-worker3
0.3683,Event,ADDED,eval-sanitize-1-r2-165-lc9c4.18d4a2913a316378,"reason=Pulled count=1 msg=Container image ""busybox:musl"" already present on machine"
0.3686,Event,ADDED,eval-sanitize-1-r2-165-lc9c4.18d4a2913bff9419,reason=Created count=1 msg=Created container: task
0.3687,Event,ADDED,eval-sanitize-1-r2-165-lc9c4.18d4a2913f44f13f,reason=Started count=1 msg=Started container task
0.369,Event,ADDED,eval-sanitize-1-r2-165.18d4a2900498643b,reason=SuccessfulCreate count=1 msg=Created pod: eval-sanitize-1-r2-165-lc9c4
0.3692,Event,ADDED,eval-sanitize-1-r2-165.18d4a296b76f4b44,reason=Completed count=1 msg=Job completed
0.3693,Event,ADDED,eval-sanitize-1-r2-166-s2tzb.18d4a2904df919c9,"reason=FailedScheduling count=None msg=0/6 nodes are available: 6 node(s) had untolerated taint(s). no new claims to deallocate, preemption: 0/6 nodes are available: 6 Preemption is not helpful for scheduling."
0.3695,Event,ADDED,eval-sanitize-1-r2-166-s2tzb.18d4a2911af96531,reason=Scheduled count=None msg=Successfully assigned compute/eval-sanitize-1-r2-166-s2tzb to kind-worker3
0.3698,Event,ADDED,eval-sanitize-1-r2-166-s2tzb.18d4a2913ef73953,"reason=Pulled count=1 msg=Container image ""busybox:musl"" already present on machine"
0.3699,Event,ADDED,eval-sanitize-1-r2-166-s2tzb.18d4a291410d3b25,reason=Created count=1 msg=Created container: task
0.3701,Event,ADDED,eval-sanitize-1-r2-166-s2tzb.18d4a2914bf0cf18,reason=Started count=1 msg=Started container task
0.3703,Event,ADDED,eval-sanitize-1-r2-166.18d4a2904df0463c,reason=SuccessfulCreate count=1 msg=Created pod: eval-sanitize-1-r2-166-s2tzb
0.3704,Event,ADDED,eval-sanitize-1-r2-166.18d4a296b72be762,reason=Completed count=1 msg=Job completed
0.3706,Event,ADDED,eval-sanitize-1-r2-167-fnvsp.18d4a290b4def7cb,"reason=FailedScheduling count=None msg=0/6 nodes are available: 6 node(s) had untolerated taint(s). no new claims to deallocate, preemption: 0/6 nodes are available: 6 Preemption is not helpful for scheduling."
0.3707,Event,ADDED,eval-sanitize-1-r2-167-fnvsp.18d4a2911ad8d560,"reason=FailedScheduling count=None msg=0/6 nodes are available: 1 c_wall violated: 2 conflicting context pair(s) with node memory, 5 node(s) had untolerated taint(s). no new claims to deallocate, preemption: 0/6 nodes are available: 1 No preemption victims found for incoming pod, 5 Preemption is not helpful for scheduling."
0.3709,Event,ADDED,eval-sanitize-1-r2-167-fnvsp.18d4a2913af674ab,"reason=FailedScheduling count=None msg=0/6 nodes are available: 1 c_wall violated: 1 conflicting context pair(s) with node memory, 1 c_wall violated: 2 conflicting context pair(s) with node memory, 4 node(s) had untolerated taint(s). no new claims to deallocate, preemption: 0/6 nodes are available: 2 No preemption victims found for incoming pod, 4 Preemption is not helpful for scheduling."
0.3711,Event,ADDED,eval-sanitize-1-r2-167-fnvsp.18d4a2914cd7160f,"reason=FailedScheduling count=None msg=0/6 nodes are available: 1 c_wall violated: 1 conflicting context pair(s) with node memory, 1 c_wall violated: 2 conflicting context pair(s) with node memory, 4 node(s) had untolerated taint(s). no new claims to deallocate, preemption: 0/6 nodes are available: 2 No preemption victims found for incoming pod, 4 Preemption is not helpful for scheduling."
0.3712,Event,ADDED,eval-sanitize-1-r2-167-fnvsp.18d4a291d32a5203,reason=Scheduled count=None msg=Successfully assigned compute/eval-sanitize-1-r2-167-fnvsp to kind-worker2
0.3714,Event,ADDED,eval-sanitize-1-r2-167-fnvsp.18d4a2920b299f26,"reason=Pulled count=1 msg=Container image ""busybox:musl"" already present on machine"
0.3716,Event,ADDED,eval-sanitize-1-r2-167-fnvsp.18d4a2920e7a9f6a,reason=Created count=1 msg=Created container: task
0.3717,Event,ADDED,eval-sanitize-1-r2-167-fnvsp.18d4a292136bbbfa,reason=Started count=1 msg=Started container task
0.3719,Event,ADDED,eval-sanitize-1-r2-167.18d4a290b4d6417c,reason=SuccessfulCreate count=1 msg=Created pod: eval-sanitize-1-r2-167-fnvsp
0.372,Event,ADDED,eval-sanitize-1-r2-167.18d4a297ff8e96a0,reason=Completed count=1 msg=Job completed
0.3722,Event,ADDED,eval-sanitize-1-r2-168-cxgd9.18d4a290df5a9d90,"reason=FailedScheduling count=None msg=0/6 nodes are available: 6 node(s) had untolerated taint(s). no new claims to deallocate, preemption: 0/6 nodes are available: 6 Preemption is not helpful for scheduling."
0.3723,Event,ADDED,eval-sanitize-1-r2-168-cxgd9.18d4a2911ebc85f6,"reason=FailedScheduling count=None msg=0/6 nodes are available: 1 c_wall violated: 2 conflicting context pair(s) with node memory, 5 node(s) had untolerated taint(s). no new claims to deallocate, preemption: 0/6 nodes are available: 1 No preemption victims found for incoming pod, 5 Preemption is not helpful for scheduling."
0.3725,Event,ADDED,eval-sanitize-1-r2-168-cxgd9.18d4a2913bd1d8f3,"reason=FailedScheduling count=None msg=0/6 nodes are available: 1 c_wall violated: 1 conflicting context pair(s) with node memory, 1 c_wall violated: 2 conflicting context pair(s) with node memory, 4 node(s) had untolerated taint(s). no new claims to deallocate, preemption: 0/6 nodes are available: 2 No preemption victims found for incoming pod, 4 Preemption is not helpful for scheduling."
0.3727,Event,ADDED,eval-sanitize-1-r2-168-cxgd9.18d4a2914d6a664d,"reason=FailedScheduling count=None msg=0/6 nodes are available: 1 c_wall violated: 1 conflicting context pair(s) with node memory, 1 c_wall violated: 2 conflicting context pair(s) with node memory, 4 node(s) had untolerated taint(s). no new claims to deallocate, preemption: 0/6 nodes are available: 2 No preemption victims found for incoming pod, 4 Preemption is not helpful for scheduling."
0.3728,Event,ADDED,eval-sanitize-1-r2-168-cxgd9.18d4a291d7b6b4c3,reason=Scheduled count=None msg=Successfully assigned compute/eval-sanitize-1-r2-168-cxgd9 to kind-worker2
0.373,Event,ADDED,eval-sanitize-1-r2-168-cxgd9.18d4a291f36dd017,"reason=Pulled count=1 msg=Container image ""busybox:musl"" already present on machine"
0.3732,Event,ADDED,eval-sanitize-1-r2-168-cxgd9.18d4a291f5bb6103,reason=Created count=1 msg=Created container: task
0.3733,Event,ADDED,eval-sanitize-1-r2-168-cxgd9.18d4a291feb1bf35,reason=Started count=1 msg=Started container task
0.3735,Event,ADDED,eval-sanitize-1-r2-168.18d4a290df4e19e7,reason=SuccessfulCreate count=1 msg=Created pod: eval-sanitize-1-r2-168-cxgd9
0.3736,Event,ADDED,eval-sanitize-1-r2-168.18d4a297f0d7b85d,reason=Completed count=1 msg=Job completed
0.3738,Event,ADDED,eval-sanitize-1-r2-169-9zzmb.18d4a2910aee3ee4,"reason=FailedScheduling count=None msg=0/6 nodes are available: 6 node(s) had untolerated taint(s). no new claims to deallocate, preemption: 0/6 nodes are available: 6 Preemption is not helpful for scheduling."
0.3739,Event,ADDED,eval-sanitize-1-r2-169-9zzmb.18d4a2912543ab5c,reason=Scheduled count=None msg=Successfully assigned compute/eval-sanitize-1-r2-169-9zzmb to kind-worker
0.3742,Event,ADDED,eval-sanitize-1-r2-169-9zzmb.18d4a2913f6182c9,"reason=Pulled count=1 msg=Container image ""busybox:musl"" already present on machine"
0.3743,Event,ADDED,eval-sanitize-1-r2-169-9zzmb.18d4a2914133fe11,reason=Created count=1 msg=Created container: task
0.3745,Event,ADDED,eval-sanitize-1-r2-169-9zzmb.18d4a2914bf6de05,reason=Started count=1 msg=Started container task
0.3747,Event,ADDED,eval-sanitize-1-r2-169.18d4a2910ae5a721,reason=SuccessfulCreate count=1 msg=Created pod: eval-sanitize-1-r2-169-9zzmb
0.3748,Event,ADDED,eval-sanitize-1-r2-169.18d4a296bb0f32f3,reason=Completed count=1 msg=Job completed
0.375,Event,ADDED,eval-sanitize-1-r2-170-46zc8.18d4a291353ef858,"reason=FailedScheduling count=None msg=0/6 nodes are available: 2 c_wall violated: 2 conflicting context pair(s) with node memory, 4 node(s) had untolerated taint(s). no new claims to deallocate, preemption: 0/6 nodes are available: 2 No preemption victims found for incoming pod, 4 Preemption is not helpful for scheduling."
0.3752,Event,ADDED,eval-sanitize-1-r2-170-46zc8.18d4a2914754c62a,"reason=FailedScheduling count=None msg=0/6 nodes are available: 2 c_wall violated: 2 conflicting context pair(s) with node memory, 4 node(s) had untolerated taint(s). no new claims to deallocate, preemption: 0/6 nodes are available: 2 No preemption victims found for incoming pod, 4 Preemption is not helpful for scheduling."
0.3754,Event,ADDED,eval-sanitize-1-r2-170-46zc8.18d4a291d32f2019,reason=Scheduled count=None msg=Successfully assigned compute/eval-sanitize-1-r2-170-46zc8 to kind-worker2
0.3756,Event,ADDED,eval-sanitize-1-r2-170-46zc8.18d4a2920b0431df,"reason=Pulled count=1 msg=Container image ""busybox:musl"" already present on machine"
0.3758,Event,ADDED,eval-sanitize-1-r2-170-46zc8.18d4a2920e08b9ae,reason=Created count=1 msg=Created container: task
0.3759,Event,ADDED,eval-sanitize-1-r2-170-46zc8.18d4a292137072d4,reason=Started count=1 msg=Started container task
0.3762,Event,ADDED,eval-sanitize-1-r2-170.18d4a29133b16440,reason=SuccessfulCreate count=1 msg=Created pod: eval-sanitize-1-r2-170-46zc8
0.3763,Event,ADDED,eval-sanitize-1-r2-170.18d4a297f7c1d7bd,reason=Completed count=1 msg=Job completed
0.3765,Event,ADDED,eval-sanitize-1-r2-171-dqpfr.18d4a2917549147f,"reason=FailedScheduling count=None msg=0/6 nodes are available: 6 node(s) had untolerated taint(s). no new claims to deallocate, preemption: 0/6 nodes are available: 6 Preemption is not helpful for scheduling."
0.3766,Event,ADDED,eval-sanitize-1-r2-171-dqpfr.18d4a291d854f277,"reason=FailedScheduling count=None msg=0/6 nodes are available: 1 c_wall violated: 1 conflicting context pair(s) with node memory, 5 node(s) had untolerated taint(s). no new claims to deallocate, preemption: 0/6 nodes are available: 1 No preemption victims found for incoming pod, 5 Preemption is not helpful for scheduling."
0.3768,Event,ADDED,eval-sanitize-1-r2-171-dqpfr.18d4a291da34cb86,"reason=FailedScheduling count=None msg=0/6 nodes are available: 1 c_wall violated: 1 conflicting context pair(s) with node memory, 5 node(s) had untolerated taint(s). no new claims to deallocate, preemption: 0/6 nodes are available: 1 No preemption victims found for incoming pod, 5 Preemption is not helpful for scheduling."
0.377,Event,ADDED,eval-sanitize-1-r2-171-dqpfr.18d4a29216eea06a,"reason=FailedScheduling count=None msg=0/6 nodes are available: 1 c_wall violated: 1 conflicting context pair(s) with node memory, 5 node(s) had untolerated taint(s). no new claims to deallocate, preemption: 0/6 nodes are available: 1 No preemption victims found for incoming pod, 5 Preemption is not helpful for scheduling."
0.3771,Event,ADDED,eval-sanitize-1-r2-171-dqpfr.18d4a2921839a6d9,"reason=FailedScheduling count=None msg=0/6 nodes are available: 1 c_wall violated: 1 conflicting context pair(s) with node memory, 5 node(s) had untolerated taint(s). no new claims to deallocate, preemption: 0/6 nodes are available: 1 No preemption victims found for incoming pod, 5 Preemption is not helpful for scheduling."
0.3773,Event,ADDED,eval-sanitize-1-r2-171-dqpfr.18d4a292d0ac0d41,reason=Scheduled count=None msg=Successfully assigned compute/eval-sanitize-1-r2-171-dqpfr to kind-worker5
0.3775,Event,ADDED,eval-sanitize-1-r2-171-dqpfr.18d4a2930789ec8b,"reason=Pulled count=1 msg=Container image ""busybox:musl"" already present on machine"
0.3776,Event,ADDED,eval-sanitize-1-r2-171-dqpfr.18d4a2930a50fac3,reason=Created count=1 msg=Created container: task
0.3778,Event,ADDED,eval-sanitize-1-r2-171-dqpfr.18d4a2930ebf4690,reason=Started count=1 msg=Started container task
0.378,Event,ADDED,eval-sanitize-1-r2-171.18d4a2917540e4f2,reason=SuccessfulCreate count=1 msg=Created pod: eval-sanitize-1-r2-171-dqpfr
0.3781,Event,ADDED,eval-sanitize-1-r2-171.18d4a298ac0898f8,reason=Completed count=1 msg=Job completed
0.3783,Event,ADDED,eval-sanitize-1-r2-172-zmf44.18d4a291ab47e569,"reason=FailedScheduling count=None msg=0/6 nodes are available: 6 node(s) had untolerated taint(s). no new claims to deallocate, preemption: 0/6 nodes are available: 6 Preemption is not helpful for scheduling."
0.3785,Event,ADDED,eval-sanitize-1-r2-172-zmf44.18d4a291d9213f67,"reason=FailedScheduling count=None msg=0/6 nodes are available: 1 c_wall violated: 1 conflicting context pair(s) with node memory, 5 node(s) had untolerated taint(s). no new claims to deallocate, preemption: 0/6 nodes are available: 1 No preemption victims found for incoming pod, 5 Preemption is not helpful for scheduling."
0.3787,Event,ADDED,eval-sanitize-1-r2-172-zmf44.18d4a291dba36d5a,"reason=FailedScheduling count=None msg=0/6 nodes are available: 1 c_wall violated: 1 conflicting context pair(s) with node memory, 5 node(s) had untolerated taint(s). no new claims to deallocate, preemption: 0/6 nodes are available: 1 No preemption victims found for incoming pod, 5 Preemption is not helpful for scheduling."
0.3788,Event,ADDED,eval-sanitize-1-r2-172-zmf44.18d4a29217a7f9c9,"reason=FailedScheduling count=None msg=0/6 nodes are available: 1 c_wall violated: 1 conflicting context pair(s) with node memory, 5 node(s) had untolerated taint(s). no new claims to deallocate, preemption: 0/6 nodes are available: 1 No preemption victims found for incoming pod, 5 Preemption is not helpful for scheduling."
0.379,Event,ADDED,eval-sanitize-1-r2-172-zmf44.18d4a292186bd234,"reason=FailedScheduling count=None msg=0/6 nodes are available: 1 c_wall violated: 1 conflicting context pair(s) with node memory, 5 node(s) had untolerated taint(s). no new claims to deallocate, preemption: 0/6 nodes are available: 1 No preemption victims found for incoming pod, 5 Preemption is not helpful for scheduling."
0.3791,Event,ADDED,eval-sanitize-1-r2-172-zmf44.18d4a292d0674b08,reason=Scheduled count=None msg=Successfully assigned compute/eval-sanitize-1-r2-172-zmf44 to kind-worker5
0.3793,Event,ADDED,eval-sanitize-1-r2-172-zmf44.18d4a293075ec0e9,"reason=Pulled count=1 msg=Container image ""busybox:musl"" already present on machine"
0.3795,Event,ADDED,eval-sanitize-1-r2-172-zmf44.18d4a29309b5e2c7,reason=Created count=1 msg=Created container: task
0.3796,Event,ADDED,eval-sanitize-1-r2-172-zmf44.18d4a2930ddb9664,reason=Started count=1 msg=Started container task
0.3798,Event,ADDED,eval-sanitize-1-r2-172.18d4a291ab3dab2e,reason=SuccessfulCreate count=1 msg=Created pod: eval-sanitize-1-r2-172-zmf44
0.38,Event,ADDED,eval-sanitize-1-r2-172.18d4a298b1e80f63,reason=Completed count=1 msg=Job completed
0.3801,Event,ADDED,eval-sanitize-1-r2-173-nxmln.18d4a291eceb0f8c,reason=Scheduled count=None msg=Successfully assigned compute/eval-sanitize-1-r2-173-nxmln to kind-worker2
0.3803,Event,ADDED,eval-sanitize-1-r2-173-nxmln.18d4a2920b749c84,"reason=Pulled count=1 msg=Container image ""busybox:musl"" already present on machine"
0.3805,Event,ADDED,eval-sanitize-1-r2-173-nxmln.18d4a2920eed89de,reason=Created count=1 msg=Created container: task
0.3806,Event,ADDED,eval-sanitize-1-r2-173-nxmln.18d4a292136fc53a,reason=Started count=1 msg=Started container task
0.3808,Event,ADDED,eval-sanitize-1-r2-173.18d4a291ec445917,reason=SuccessfulCreate count=1 msg=Created pod: eval-sanitize-1-r2-173-nxmln
0.381,Event,ADDED,eval-sanitize-1-r2-173.18d4a298033c5254,reason=Completed count=1 msg=Job completed
0.3811,Event,ADDED,eval-sanitize-1-r2-174-6bv4j.18d4a29248bb44b4,"reason=FailedScheduling count=None msg=0/6 nodes are available: 1 c_wall violated: 1 conflicting context pair(s) with node memory, 5 node(s) had untolerated taint(s). no new claims to deallocate, preemption: 0/6 nodes are available: 1 No preemption victims found for incoming pod, 5 Preemption is not helpful for scheduling."
0.3813,Event,ADDED,eval-sanitize-1-r2-174-6bv4j.18d4a29249330fdd,"reason=FailedScheduling count=None msg=0/6 nodes are available: 1 c_wall violated: 1 conflicting context pair(s) with node memory, 5 node(s) had untolerated taint(s). no new claims to deallocate, preemption: 0/6 nodes are available: 1 No preemption victims found for incoming pod, 5 Preemption is not helpful for scheduling."
0.3814,Event,ADDED,eval-sanitize-1-r2-174-6bv4j.18d4a292d0f91804,reason=Scheduled count=None msg=Successfully assigned compute/eval-sanitize-1-r2-174-6bv4j to kind-worker5
0.3817,Event,ADDED,eval-sanitize-1-r2-174-6bv4j.18d4a29307b9719b,"reason=Pulled count=1 msg=Container image ""busybox:musl"" already present on machine"
0.3818,Event,ADDED,eval-sanitize-1-r2-174-6bv4j.18d4a2930ab21373,reason=Created count=1 msg=Created container: task
0.382,Event,ADDED,eval-sanitize-1-r2-174-6bv4j.18d4a2930ec31225,reason=Started count=1 msg=Started container task
0.3822,Event,ADDED,eval-sanitize-1-r2-174.18d4a292488de6fa,reason=SuccessfulCreate count=1 msg=Created pod: eval-sanitize-1-r2-174-6bv4j
0.3823,Event,ADDED,eval-sanitize-1-r2-174.18d4a298ad3a1174,reason=Completed count=1 msg=Job completed
0.3825,Event,ADDED,eval-sanitize-1-r2-175-z74tw.18d4a2926982e163,"reason=FailedScheduling count=None msg=0/6 nodes are available: 1 c_wall violated: 1 conflicting context pair(s) with node memory, 5 node(s) had untolerated taint(s). no new claims to deallocate, preemption: 0/6 nodes are available: 1 No preemption victims found for incoming pod, 5 Preemption is not helpful for scheduling."
0.3827,Event,ADDED,eval-sanitize-1-r2-175-z74tw.18d4a29269feaf61,"reason=FailedScheduling count=None msg=0/6 nodes are available: 1 c_wall violated: 1 conflicting context pair(s) with node memory, 5 node(s) had untolerated taint(s). no new claims to deallocate, preemption: 0/6 nodes are available: 1 No preemption victims found for incoming pod, 5 Preemption is not helpful for scheduling."
0.3828,Event,ADDED,eval-sanitize-1-r2-175-z74tw.18d4a292d13905a5,reason=Scheduled count=None msg=Successfully assigned compute/eval-sanitize-1-r2-175-z74tw to kind-worker5
0.383,Event,ADDED,eval-sanitize-1-r2-175-z74tw.18d4a29307e056a3,"reason=Pulled count=1 msg=Container image ""busybox:musl"" already present on machine"
0.3831,Event,ADDED,eval-sanitize-1-r2-175-z74tw.18d4a2930ae3bee3,reason=Created count=1 msg=Created container: task
0.3833,Event,ADDED,eval-sanitize-1-r2-175-z74tw.18d4a2930ebf9f34,reason=Started count=1 msg=Started container task
0.3835,Event,ADDED,eval-sanitize-1-r2-175.18d4a2926941c68a,reason=SuccessfulCreate count=1 msg=Created pod: eval-sanitize-1-r2-175-z74tw
0.3836,Event,ADDED,eval-sanitize-1-r2-175.18d4a298a4bfa51d,reason=Completed count=1 msg=Job completed
0.3838,Event,ADDED,eval-sanitize-1-r2-176-ghjrj.18d4a292b42f8163,"reason=FailedScheduling count=None msg=0/6 nodes are available: 6 node(s) had untolerated taint(s). no new claims to deallocate, preemption: 0/6 nodes are available: 6 Preemption is not helpful for scheduling."
0.3839,Event,ADDED,eval-sanitize-1-r2-176-ghjrj.18d4a292d0e8156d,"reason=FailedScheduling count=None msg=0/6 nodes are available: 1 c_wall violated: 2 conflicting context pair(s) with node memory, 5 node(s) had untolerated taint(s). no new claims to deallocate, preemption: 0/6 nodes are available: 1 No preemption victims found for incoming pod, 5 Preemption is not helpful for scheduling."
0.3843,Event,ADDED,eval-sanitize-1-r2-176-ghjrj.18d4a292d1c3adb8,"reason=FailedScheduling count=None msg=0/6 nodes are available: 1 c_wall violated: 2 conflicting context pair(s) with node memory, 5 node(s) had untolerated taint(s). no new claims to deallocate, preemption: 0/6 nodes are available: 1 No preemption victims found for incoming pod, 5 Preemption is not helpful for scheduling."
0.3845,Event,ADDED,eval-sanitize-1-r2-176-ghjrj.18d4a296a5b47762,reason=Scheduled count=None msg=Successfully assigned compute/eval-sanitize-1-r2-176-ghjrj to kind-worker3
0.3846,Event,ADDED,eval-sanitize-1-r2-176-ghjrj.18d4a296c7091154,"reason=Pulled count=1 msg=Container image ""busybox:musl"" already present on machine"
0.3851,Event,ADDED,eval-sanitize-1-r2-176-ghjrj.18d4a296c85b6df2,reason=Created count=1 msg=Created container: task
0.3853,Event,ADDED,eval-sanitize-1-r2-176-ghjrj.18d4a296cd4acf00,reason=Started count=1 msg=Started container task
0.3855,Event,ADDED,eval-sanitize-1-r2-176.18d4a292b424646e,reason=SuccessfulCreate count=1 msg=Created pod: eval-sanitize-1-r2-176-ghjrj
0.3856,Event,ADDED,eval-sanitize-1-r2-176.18d4a29c49b8235d,reason=Completed count=1 msg=Job completed
0.3859,Event,ADDED,eval-sanitize-1-r2-177-922j6.18d4a292d60e3c08,"reason=FailedScheduling count=None msg=0/6 nodes are available: 1 c_wall violated: 2 conflicting context pair(s) with node memory, 5 node(s) had untolerated taint(s). no new claims to deallocate, preemption: 0/6 nodes are available: 1 No preemption victims found for incoming pod, 5 Preemption is not helpful for scheduling."
0.3861,Event,ADDED,eval-sanitize-1-r2-177-922j6.18d4a292d6aade74,"reason=FailedScheduling count=None msg=0/6 nodes are available: 1 c_wall violated: 2 conflicting context pair(s) with node memory, 5 node(s) had untolerated taint(s). no new claims to deallocate, preemption: 0/6 nodes are available: 1 No preemption victims found for incoming pod, 5 Preemption is not helpful for scheduling."
0.3863,Event,ADDED,eval-sanitize-1-r2-177-922j6.18d4a296a630ef10,reason=Scheduled count=None msg=Successfully assigned compute/eval-sanitize-1-r2-177-922j6 to kind-worker3
0.3866,Event,ADDED,eval-sanitize-1-r2-177-922j6.18d4a296c0925e60,"reason=Pulled count=1 msg=Container image ""busybox:musl"" already present on machine"
0.3868,Event,ADDED,eval-sanitize-1-r2-177-922j6.18d4a296c31ae8f6,reason=Created count=1 msg=Created container: task
0.387,Event,ADDED,eval-sanitize-1-r2-177-922j6.18d4a296c804d0a9,reason=Started count=1 msg=Started container task
0.3873,Event,ADDED,eval-sanitize-1-r2-177.18d4a292d47e6ace,reason=SuccessfulCreate count=1 msg=Created pod: eval-sanitize-1-r2-177-922j6
0.3875,Event,ADDED,eval-sanitize-1-r2-177.18d4a29c4a37e5de,reason=Completed count=1 msg=Job completed
0.3877,Event,ADDED,eval-sanitize-1-r2-178-h95hl.18d4a2930bff297c,"reason=FailedScheduling count=None msg=0/6 nodes are available: 1 c_wall violated: 1 conflicting context pair(s) with node memory, 5 node(s) had untolerated taint(s). no new claims to deallocate, preemption: 0/6 nodes are available: 1 No preemption victims found for incoming pod, 5 Preemption is not helpful for scheduling."
0.3879,Event,ADDED,eval-sanitize-1-r2-178-h95hl.18d4a2930cac9b49,"reason=FailedScheduling count=None msg=0/6 nodes are available: 1 c_wall violated: 1 conflicting context pair(s) with node memory, 5 node(s) had untolerated taint(s). no new claims to deallocate, preemption: 0/6 nodes are available: 1 No preemption victims found for incoming pod, 5 Preemption is not helpful for scheduling."
0.3882,Event,ADDED,eval-sanitize-1-r2-178-h95hl.18d4a296a67c7420,reason=Scheduled count=None msg=Successfully assigned compute/eval-sanitize-1-r2-178-h95hl to kind-worker3
0.3884,Event,ADDED,eval-sanitize-1-r2-178-h95hl.18d4a296c0792762,"reason=Pulled count=1 msg=Container image ""busybox:musl"" already present on machine"
0.3886,Event,ADDED,eval-sanitize-1-r2-178-h95hl.18d4a296c302d741,reason=Created count=1 msg=Created container: task
0.389,Event,ADDED,eval-sanitize-1-r2-178-h95hl.18d4a296c805110b,reason=Started count=1 msg=Started container task
0.3892,Event,ADDED,eval-sanitize-1-r2-178.18d4a2930bbd7f85,reason=SuccessfulCreate count=1 msg=Created pod: eval-sanitize-1-r2-178-h95hl
0.3894,Event,ADDED,eval-sanitize-1-r2-178.18d4a29c9c7f9c00,reason=Completed count=1 msg=Job completed
0.3895,Event,ADDED,eval-sanitize-1-r2-179-49zd8.18d4a29346ea46f6,"reason=FailedScheduling count=None msg=0/6 nodes are available: 6 node(s) had untolerated taint(s). no new claims to deallocate, preemption: 0/6 nodes are available: 6 Preemption is not helpful for scheduling."
0.3898,Event,ADDED,eval-sanitize-1-r2-179-49zd8.18d4a296a6560858,"reason=FailedScheduling count=None msg=0/6 nodes are available: 1 c_wall violated: 1 conflicting context pair(s) with node memory, 5 node(s) had untolerated taint(s). no new claims to deallocate, preemption: 0/6 nodes are available: 1 No preemption victims found for incoming pod, 5 Preemption is not helpful for scheduling."
0.39,Event,ADDED,eval-sanitize-1-r2-179-49zd8.18d4a296c5db61b8,reason=Scheduled count=None msg=Successfully assigned compute/eval-sanitize-1-r2-179-49zd8 to kind-worker
0.3902,Event,ADDED,eval-sanitize-1-r2-179-49zd8.18d4a296e167686a,"reason=Pulled count=1 msg=Container image ""busybox:musl"" already present on machine"
0.3904,Event,ADDED,eval-sanitize-1-r2-179-49zd8.18d4a296e3157516,reason=Created count=1 msg=Created container: task
0.3906,Event,ADDED,eval-sanitize-1-r2-179-49zd8.18d4a296e5992148,reason=Started count=1 msg=Started container task
0.3907,Event,ADDED,eval-sanitize-1-r2-179.18d4a29346df5fb9,reason=SuccessfulCreate count=1 msg=Created pod: eval-sanitize-1-r2-179-49zd8
0.3909,Event,ADDED,eval-sanitize-1-r2-179.18d4a29ca29b6ad8,reason=Completed count=1 msg=Job completed
0.3911,Event,ADDED,eval-sanitize-1-r2-180-87tk8.18d4a29382865d86,"reason=FailedScheduling count=None msg=0/6 nodes are available: 6 node(s) had untolerated taint(s). no new claims to deallocate, preemption: 0/6 nodes are available: 6 Preemption is not helpful for scheduling."
0.3913,Event,ADDED,eval-sanitize-1-r2-180-87tk8.18d4a296aafb0ebe,"reason=FailedScheduling count=None msg=0/6 nodes are available: 1 c_wall violated: 2 conflicting context pair(s) with node memory, 5 node(s) had untolerated taint(s). no new claims to deallocate, preemption: 0/6 nodes are available: 1 No preemption victims found for incoming pod, 5 Preemption is not helpful for scheduling."
0.3914,Event,ADDED,eval-sanitize-1-r2-180-87tk8.18d4a296c5d9129c,"reason=FailedScheduling count=None msg=0/6 nodes are available: 1 c_wall violated: 1 conflicting context pair(s) with node memory, 1 c_wall violated: 2 conflicting context pair(s) with node memory, 4 node(s) had untolerated taint(s). no new claims to deallocate, preemption: 0/6 nodes are available: 2 No preemption victims found for incoming pod, 4 Preemption is not helpful for scheduling."
0.3916,Event,ADDED,eval-sanitize-1-r2-180-87tk8.18d4a296d711115c,"reason=FailedScheduling count=None msg=0/6 nodes are available: 1 c_wall violated: 1 conflicting context pair(s) with node memory, 1 c_wall violated: 2 conflicting context pair(s) with node memory, 4 node(s) had untolerated taint(s). no new claims to deallocate, preemption: 0/6 nodes are available: 2 No preemption victims found for incoming pod, 4 Preemption is not helpful for scheduling."
0.3918,Event,ADDED,eval-sanitize-1-r2-180-87tk8.18d4a296fcf50995,"reason=FailedScheduling count=None msg=0/6 nodes are available: 1 c_wall violated: 1 conflicting context pair(s) with node memory, 5 node(s) had untolerated taint(s). no new claims to deallocate, preemption: 0/6 nodes are available: 1 No preemption victims found for incoming pod, 5 Preemption is not helpful for scheduling."
0.392,Event,ADDED,eval-sanitize-1-r2-180-87tk8.18d4a297c0bf915f,reason=Scheduled count=None msg=Successfully assigned compute/eval-sanitize-1-r2-180-87tk8 to kind-worker4
0.3922,Event,ADDED,eval-sanitize-1-r2-180-87tk8.18d4a297dad56852,"reason=Pulled count=1 msg=Container image ""busybox:musl"" already present on machine"
0.3923,Event,ADDED,eval-sanitize-1-r2-180-87tk8.18d4a297dc602165,reason=Created count=1 msg=Created container: task
0.3925,Event,ADDED,eval-sanitize-1-r2-180-87tk8.18d4a297e2aeb0c1,reason=Started count=1 msg=Started container task
0.3926,Event,ADDED,eval-sanitize-1-r2-180.18d4a293827c66fc,reason=SuccessfulCreate count=1 msg=Created pod: eval-sanitize-1-r2-180-87tk8
0.3929,Event,ADDED,eval-sanitize-1-r2-180.18d4a29d7e2bc1cf,reason=Completed count=1 msg=Job completed
0.3931,Event,ADDED,eval-sanitize-1-r2-181-94qg5.18d4a293c362376c,"reason=FailedScheduling count=None msg=0/6 nodes are available: 6 node(s) had untolerated taint(s). no new claims to deallocate, preemption: 0/6 nodes are available: 6 Preemption is not helpful for scheduling."
0.3933,Event,ADDED,eval-sanitize-1-r2-181-94qg5.18d4a296ab7ad732,"reason=FailedScheduling count=None msg=0/6 nodes are available: 1 c_wall violated: 1 conflicting context pair(s) with node memory, 5 node(s) had untolerated taint(s). no new claims to deallocate, preemption: 0/6 nodes are available: 1 No preemption victims found for incoming pod, 5 Preemption is not helpful for scheduling."
0.3935,Event,ADDED,eval-sanitize-1-r2-181-94qg5.18d4a296cb9b1dcd,reason=Scheduled count=None msg=Successfully assigned compute/eval-sanitize-1-r2-181-94qg5 to kind-worker
0.3937,Event,ADDED,eval-sanitize-1-r2-181-94qg5.18d4a296e51ea9c7,"reason=Pulled count=1 msg=Container image ""busybox:musl"" already present on machine"
0.3938,Event,ADDED,eval-sanitize-1-r2-181-94qg5.18d4a296e6d9fc54,reason=Created count=1 msg=Created container: task
0.394,Event,ADDED,eval-sanitize-1-r2-181-94qg5.18d4a296eb23289e,reason=Started count=1 msg=Started container task
0.3942,Event,ADDED,eval-sanitize-1-r2-181.18d4a293c357ab07,reason=SuccessfulCreate count=1 msg=Created pod: eval-sanitize-1-r2-181-94qg5
0.3944,Event,ADDED,eval-sanitize-1-r2-181.18d4a29cc120e0a2,reason=Completed count=1 msg=Job completed
0.3946,Event,ADDED,eval-sanitize-1-r2-182-jgbf8.18d4a29400e5a07b,"reason=FailedScheduling count=None msg=0/6 nodes are available: 6 node(s) had untolerated taint(s). no new claims to deallocate, preemption: 0/6 nodes are available: 6 Preemption is not helpful for scheduling."
0.3948,Event,ADDED,eval-sanitize-1-r2-182-jgbf8.18d4a296abf7ed1d,"reason=FailedScheduling count=None msg=0/6 nodes are available: 1 c_wall violated: 1 conflicting context pair(s) with node memory, 5 node(s) had untolerated taint(s). no new claims to deallocate, preemption: 0/6 nodes are available: 1 No preemption victims found for incoming pod, 5 Preemption is not helpful for scheduling."
0.395,Event,ADDED,eval-sanitize-1-r2-182-jgbf8.18d4a296cc085513,reason=Scheduled count=None msg=Successfully assigned compute/eval-sanitize-1-r2-182-jgbf8 to kind-worker
0.3952,Event,ADDED,eval-sanitize-1-r2-182-jgbf8.18d4a296e59ba084,"reason=Pulled count=1 msg=Container image ""busybox:musl"" already present on machine"
0.3954,Event,ADDED,eval-sanitize-1-r2-182-jgbf8.18d4a296e73fb0c0,reason=Created count=1 msg=Created container: task
0.3957,Event,ADDED,eval-sanitize-1-r2-182-jgbf8.18d4a296eb23288a,reason=Started count=1 msg=Started container task
0.3958,Event,ADDED,eval-sanitize-1-r2-182.18d4a29400df32df,reason=SuccessfulCreate count=1 msg=Created pod: eval-sanitize-1-r2-182-jgbf8
0.396,Event,ADDED,eval-sanitize-1-r2-182.18d4a29ccc3e973d,reason=Completed count=1 msg=Job completed
0.3962,Event,ADDED,eval-sanitize-1-r2-183-v56gf.18d4a294358f1d6a,"reason=FailedScheduling count=None msg=0/6 nodes are available: 6 node(s) had untolerated taint(s). no new claims to deallocate, preemption: 0/6 nodes are available: 6 Preemption is not helpful for scheduling."
0.3963,Event,ADDED,eval-sanitize-1-r2-183-v56gf.18d4a296acb50747,"reason=FailedScheduling count=None msg=0/6 nodes are available: 1 c_wall violated: 1 conflicting context pair(s) with node memory, 5 node(s) had untolerated taint(s). no new claims to deallocate, preemption: 0/6 nodes are available: 1 No preemption victims found for incoming pod, 5 Preemption is not helpful for scheduling."
0.3965,Event,ADDED,eval-sanitize-1-r2-183-v56gf.18d4a296cc164825,"reason=FailedScheduling count=None msg=0/6 nodes are available: 1 c_wall violated: 1 conflicting context pair(s) with node memory, 1 c_wall violated: 3 conflicting context pair(s) with node memory, 4 node(s) had untolerated taint(s). no new claims to deallocate, preemption: 0/6 nodes are available: 2 No preemption victims found for incoming pod, 4 Preemption is not helpful for scheduling."
0.3967,Event,ADDED,eval-sanitize-1-r2-183-v56gf.18d4a296d7711eb3,"reason=FailedScheduling count=None msg=0/6 nodes are available: 1 c_wall violated: 1 conflicting context pair(s) with node memory, 1 c_wall violated: 3 conflicting context pair(s) with node memory, 4 node(s) had untolerated taint(s). no new claims to deallocate, preemption: 0/6 nodes are available: 2 No preemption victims found for incoming pod, 4 Preemption is not helpful for scheduling."
