t_recv,kind,type,name,detail
0.0214,Node,ADDED,kind-control-plane,taints=1
0.0232,Node,ADDED,kind-worker,taints=0
0.0246,Node,ADDED,kind-worker2,taints=0
0.026,Node,ADDED,kind-worker3,taints=0
0.0272,Node,ADDED,kind-worker4,taints=0
0.0287,Node,ADDED,kind-worker5,taints=0
0.0555,Event,ADDED,eval-conflicts-rho010-r0-019-vrx7r.18d4663df244c894,"reason=FailedScheduling count=None msg=0/6 nodes are available: 1 c_wall violated: 2 conflicting context pair(s) with node memory, 5 node(s) had untolerated taint(s). no new claims to deallocate, preemption: 0/6 nodes are available: 1 No preemption victims found for incoming pod, 5 Preemption is not helpful for scheduling."
0.0561,Event,ADDED,eval-conflicts-rho010-r0-020-hzzxp.18d4663df28945da,"reason=FailedScheduling count=None msg=0/6 nodes are available: 1 c_wall violated: 1 conflicting context pair(s) with node memory, 5 node(s) had untolerated taint(s). no new claims to deallocate, preemption: 0/6 nodes are available: 1 No preemption victims found for incoming pod, 5 Preemption is not helpful for scheduling."
0.0565,Event,ADDED,eval-conflicts-rho010-r0-020-hzzxp.18d4663ed97f452c,"reason=FailedScheduling count=None msg=0/6 nodes are available: 2 c_wall violated: 1 conflicting context pair(s) with node memory, 4 node(s) had untolerated taint(s). no new claims to deallocate, preemption: 0/6 nodes are available: 2 No preemption victims found for incoming pod, 4 Preemption is not helpful for scheduling."
0.0567,Event,ADDED,eval-conflicts-rho010-r0-023-ksjvl.18d4663e32a1ea4c,"reason=FailedScheduling count=None msg=0/6 nodes are available: 1 c_wall violated: 2 conflicting context pair(s) with node memory, 5 node(s) had untolerated taint(s). no new claims to deallocate, preemption: 0/6 nodes are available: 1 No preemption victims found for incoming pod, 5 Preemption is not helpful for scheduling."
0.0572,Event,ADDED,eval-conflicts-rho010-r0-028-gfz56.18d4663f5d38f64b,"reason=FailedScheduling count=None msg=0/6 nodes are available: 2 c_wall violated: 1 conflicting context pair(s) with node memory, 4 node(s) had untolerated taint(s). no new claims to deallocate, preemption: 0/6 nodes are available: 2 No preemption victims found for incoming pod, 4 Preemption is not helpful for scheduling."
0.0574,Event,ADDED,eval-conflicts-rho010-r0-032-6zslz.18d466404b77ca0d,"reason=FailedScheduling count=None msg=0/6 nodes are available: 2 c_wall violated: 1 conflicting context pair(s) with node memory, 4 node(s) had untolerated taint(s). no new claims to deallocate, preemption: 0/6 nodes are available: 2 No preemption victims found for incoming pod, 4 Preemption is not helpful for scheduling."
0.0577,Event,ADDED,eval-conflicts-rho010-r0-050-mhqmc.18d466447c820208,"reason=FailedScheduling count=None msg=0/6 nodes are available: 1 c_wall violated: 1 conflicting context pair(s) with node memory, 1 c_wall violated: 2 conflicting context pair(s) with node memory, 4 node(s) had untolerated taint(s). no new claims to deallocate, preemption: 0/6 nodes are available: 2 No preemption victims found for incoming pod, 4 Preemption is not helpful for scheduling."
0.0579,Event,ADDED,eval-conflicts-rho010-r0-050-mhqmc.18d46644ff0a0aa0,"reason=FailedScheduling count=None msg=0/6 nodes are available: 1 c_wall violated: 2 conflicting context pair(s) with node memory, 5 node(s) had untolerated taint(s). no new claims to deallocate, preemption: 0/6 nodes are available: 1 No preemption victims found for incoming pod, 5 Preemption is not helpful for scheduling."
0.0581,Event,ADDED,eval-conflicts-rho010-r0-057-5rfpp.18d4664625e55eaa,"reason=FailedScheduling count=None msg=0/6 nodes are available: 1 c_wall violated: 1 conflicting context pair(s) with node memory, 5 node(s) had untolerated taint(s). no new claims to deallocate, preemption: 0/6 nodes are available: 1 No preemption victims found for incoming pod, 5 Preemption is not helpful for scheduling."
0.0583,Event,ADDED,eval-conflicts-rho010-r0-059-rd4p2.18d4664694def1d0,"reason=FailedScheduling count=None msg=0/6 nodes are available: 1 c_wall violated: 1 conflicting context pair(s) with node memory, 5 node(s) had untolerated taint(s). no new claims to deallocate, preemption: 0/6 nodes are available: 1 No preemption victims found for incoming pod, 5 Preemption is not helpful for scheduling."
0.0585,Event,ADDED,eval-conflicts-rho010-r0-068-28f66.18d46648addf7dbb,"reason=FailedScheduling count=None msg=0/6 nodes are available: 2 c_wall violated: 1 conflicting context pair(s) with node memory, 4 node(s) had untolerated taint(s). no new claims to deallocate, preemption: 0/6 nodes are available: 2 No preemption victims found for incoming pod, 4 Preemption is not helpful for scheduling."
0.0587,Event,ADDED,eval-conflicts-rho010-r0-068-28f66.18d46649aa2e1b13,"reason=FailedScheduling count=None msg=0/6 nodes are available: 1 c_wall violated: 1 conflicting context pair(s) with node memory, 5 node(s) had untolerated taint(s). no new claims to deallocate, preemption: 0/6 nodes are available: 1 No preemption victims found for incoming pod, 5 Preemption is not helpful for scheduling."
0.0589,Event,ADDED,eval-conflicts-rho010-r0-088-kqdcz.18d4664d555c0ea5,"reason=FailedScheduling count=None msg=0/6 nodes are available: 1 c_wall violated: 1 conflicting context pair(s) with node memory, 5 node(s) had untolerated taint(s). no new claims to deallocate, preemption: 0/6 nodes are available: 1 No preemption victims found for incoming pod, 5 Preemption is not helpful for scheduling."
0.0591,Event,ADDED,eval-conflicts-rho010-r0-091-wj8jk.18d4664e07d44fad,"reason=FailedScheduling count=None msg=0/6 nodes are available: 1 c_wall violated: 1 conflicting context pair(s) with node memory, 5 node(s) had untolerated taint(s). no new claims to deallocate, preemption: 0/6 nodes are available: 1 No preemption victims found for incoming pod, 5 Preemption is not helpful for scheduling."
0.0593,Event,ADDED,eval-conflicts-rho010-r0-091-wj8jk.18d4664e78d6da61,"reason=FailedScheduling count=None msg=0/6 nodes are available: 2 c_wall violated: 1 conflicting context pair(s) with node memory, 4 node(s) had untolerated taint(s). no new claims to deallocate, preemption: 0/6 nodes are available: 2 No preemption victims found for incoming pod, 4 Preemption is not helpful for scheduling."
0.0595,Event,ADDED,eval-conflicts-rho010-r0-091-wj8jk.18d4664e8d63901f,"reason=FailedScheduling count=None msg=0/6 nodes are available: 1 c_wall violated: 1 conflicting context pair(s) with node memory, 5 node(s) had untolerated taint(s). no new claims to deallocate, preemption: 0/6 nodes are available: 1 No preemption victims found for incoming pod, 5 Preemption is not helpful for scheduling."
0.0597,Event,ADDED,eval-conflicts-rho010-r0-099-kxkzl.18d4664fe52ac8a1,"reason=FailedScheduling count=None msg=0/6 nodes are available: 2 c_wall violated: 1 conflicting context pair(s) with node memory, 4 node(s) had untolerated taint(s). no new claims to deallocate, preemption: 0/6 nodes are available: 2 No preemption victims found for incoming pod, 4 Preemption is not helpful for scheduling."
0.0601,Event,ADDED,eval-conflicts-rho010-r0-099-kxkzl.18d46650c96df63f,"reason=FailedScheduling count=None msg=0/6 nodes are available: 1 c_wall violated: 1 conflicting context pair(s) with node memory, 5 node(s) had untolerated taint(s). no new claims to deallocate, preemption: 0/6 nodes are available: 1 No preemption victims found for incoming pod, 5 Preemption is not helpful for scheduling."
0.0606,Event,ADDED,eval-conflicts-rho010-r1-015-nzvvk.18d4665efcf65c4c,"reason=FailedScheduling count=None msg=0/6 nodes are available: 1 c_wall violated: 1 conflicting context pair(s) with node memory, 5 node(s) had untolerated taint(s). no new claims to deallocate, preemption: 0/6 nodes are available: 1 No preemption victims found for incoming pod, 5 Preemption is not helpful for scheduling."
0.0612,Event,ADDED,eval-conflicts-rho010-r1-015-nzvvk.18d4665f4e275e90,"reason=FailedScheduling count=None msg=0/6 nodes are available: 2 c_wall violated: 1 conflicting context pair(s) with node memory, 4 node(s) had untolerated taint(s). no new claims to deallocate, preemption: 0/6 nodes are available: 2 No preemption victims found for incoming pod, 4 Preemption is not helpful for scheduling."
0.0618,Event,ADDED,eval-conflicts-rho010-r1-021-npl92.18d4665efd20df7f,"reason=FailedScheduling count=None msg=0/6 nodes are available: 1 c_wall violated: 1 conflicting context pair(s) with node memory, 5 node(s) had untolerated taint(s). no new claims to deallocate, preemption: 0/6 nodes are available: 1 No preemption victims found for incoming pod, 5 Preemption is not helpful for scheduling."
0.0621,Event,ADDED,eval-conflicts-rho010-r1-023-n8cpf.18d4665f08d24cd6,"reason=FailedScheduling count=None msg=0/6 nodes are available: 1 c_wall violated: 1 conflicting context pair(s) with node memory, 5 node(s) had untolerated taint(s). no new claims to deallocate, preemption: 0/6 nodes are available: 1 No preemption victims found for incoming pod, 5 Preemption is not helpful for scheduling."
0.0623,Event,ADDED,eval-conflicts-rho010-r1-023-n8cpf.18d4665f4e7c4cad,"reason=FailedScheduling count=None msg=0/6 nodes are available: 2 c_wall violated: 1 conflicting context pair(s) with node memory, 4 node(s) had untolerated taint(s). no new claims to deallocate, preemption: 0/6 nodes are available: 2 No preemption victims found for incoming pod, 4 Preemption is not helpful for scheduling."
0.0625,Event,ADDED,eval-conflicts-rho010-r1-046-4ccdd.18d466645f4fe358,"reason=FailedScheduling count=None msg=0/6 nodes are available: 1 c_wall violated: 1 conflicting context pair(s) with node memory, 5 node(s) had untolerated taint(s). no new claims to deallocate, preemption: 0/6 nodes are available: 1 No preemption victims found for incoming pod, 5 Preemption is not helpful for scheduling."
0.0627,Event,ADDED,eval-conflicts-rho010-r1-082-5247m.18d4666cc1e72a3b,"reason=FailedScheduling count=None msg=0/6 nodes are available: 1 c_wall violated: 1 conflicting context pair(s) with node memory, 1 c_wall violated: 2 conflicting context pair(s) with node memory, 4 node(s) had untolerated taint(s). no new claims to deallocate, preemption: 0/6 nodes are available: 2 No preemption victims found for incoming pod, 4 Preemption is not helpful for scheduling."
0.0629,Event,ADDED,eval-conflicts-rho010-r1-082-5247m.18d4666d1d42e46d,"reason=FailedScheduling count=None msg=0/6 nodes are available: 1 c_wall violated: 1 conflicting context pair(s) with node memory, 5 node(s) had untolerated taint(s). no new claims to deallocate, preemption: 0/6 nodes are available: 1 No preemption victims found for incoming pod, 5 Preemption is not helpful for scheduling."
0.0631,Event,ADDED,eval-conflicts-rho010-r1-085-tdjwc.18d4666d76f07b1a,"reason=FailedScheduling count=None msg=0/6 nodes are available: 1 c_wall violated: 1 conflicting context pair(s) with node memory, 5 node(s) had untolerated taint(s). no new claims to deallocate, preemption: 0/6 nodes are available: 1 No preemption victims found for incoming pod, 5 Preemption is not helpful for scheduling."
0.0633,Event,ADDED,eval-conflicts-rho010-r2-017-kxhcw.18d4667dbc55d293,"reason=FailedScheduling count=None msg=0/6 nodes are available: 1 c_wall violated: 1 conflicting context pair(s) with node memory, 5 node(s) had untolerated taint(s). no new claims to deallocate, preemption: 0/6 nodes are available: 1 No preemption victims found for incoming pod, 5 Preemption is not helpful for scheduling."
0.0634,Event,ADDED,eval-conflicts-rho010-r2-028-djcp6.18d4667fbcc3f716,"reason=FailedScheduling count=None msg=0/6 nodes are available: 3 c_wall violated: 2 conflicting context pair(s) with node memory, 3 node(s) had untolerated taint(s). no new claims to deallocate, preemption: 0/6 nodes are available: 3 No preemption victims found for incoming pod, 3 Preemption is not helpful for scheduling."
0.0636,Event,ADDED,eval-conflicts-rho010-r2-028-djcp6.18d466800c35eaf2,"reason=FailedScheduling count=None msg=0/6 nodes are available: 2 c_wall violated: 2 conflicting context pair(s) with node memory, 4 node(s) had untolerated taint(s). no new claims to deallocate, preemption: 0/6 nodes are available: 2 No preemption victims found for incoming pod, 4 Preemption is not helpful for scheduling."
0.0638,Event,ADDED,eval-conflicts-rho010-r2-028-djcp6.18d466801bd0ada6,"reason=FailedScheduling count=None msg=0/6 nodes are available: 1 c_wall violated: 2 conflicting context pair(s) with node memory, 5 node(s) had untolerated taint(s). no new claims to deallocate, preemption: 0/6 nodes are available: 1 No preemption victims found for incoming pod, 5 Preemption is not helpful for scheduling."
0.0641,Event,ADDED,eval-conflicts-rho010-r2-078-dtlbb.18d4668b5f857183,"reason=FailedScheduling count=None msg=0/6 nodes are available: 1 c_wall violated: 1 conflicting context pair(s) with node memory, 5 node(s) had untolerated taint(s). no new claims to deallocate, preemption: 0/6 nodes are available: 1 No preemption victims found for incoming pod, 5 Preemption is not helpful for scheduling."
0.0643,Event,ADDED,eval-conflicts-rho010-r2-079-79xcd.18d4668b9a46ca82,"reason=FailedScheduling count=None msg=0/6 nodes are available: 1 c_wall violated: 1 conflicting context pair(s) with node memory, 5 node(s) had untolerated taint(s). no new claims to deallocate, preemption: 0/6 nodes are available: 1 No preemption victims found for incoming pod, 5 Preemption is not helpful for scheduling."
0.0645,Event,ADDED,eval-conflicts-rho010-r2-097-m54b7.18d4668fcbe1b942,"reason=FailedScheduling count=None msg=0/6 nodes are available: 1 c_wall violated: 1 conflicting context pair(s) with node memory, 5 node(s) had untolerated taint(s). no new claims to deallocate, preemption: 0/6 nodes are available: 1 No preemption victims found for incoming pod, 5 Preemption is not helpful for scheduling."
0.0649,Event,ADDED,eval-conflicts-rho010-r2-098-fjj9p.18d466900812e9e7,"reason=FailedScheduling count=None msg=0/6 nodes are available: 1 c_wall violated: 1 conflicting context pair(s) with node memory, 5 node(s) had untolerated taint(s). no new claims to deallocate, preemption: 0/6 nodes are available: 1 No preemption victims found for incoming pod, 5 Preemption is not helpful for scheduling."
0.0651,Event,ADDED,eval-conflicts-rho010-r2-098-fjj9p.18d46690afef1170,"reason=FailedScheduling count=None msg=0/6 nodes are available: 2 c_wall violated: 1 conflicting context pair(s) with node memory, 4 node(s) had untolerated taint(s). no new claims to deallocate, preemption: 0/6 nodes are available: 2 No preemption victims found for incoming pod, 4 Preemption is not helpful for scheduling."
0.0652,Event,ADDED,eval-conflicts-rho010-r2-098-fjj9p.18d46690c7cf43b4,"reason=FailedScheduling count=None msg=0/6 nodes are available: 1 c_wall violated: 1 conflicting context pair(s) with node memory, 5 node(s) had untolerated taint(s). no new claims to deallocate, preemption: 0/6 nodes are available: 1 No preemption victims found for incoming pod, 5 Preemption is not helpful for scheduling."
0.0655,Event,ADDED,eval-conflicts-rho010-r2-099-hbfqc.18d4669042a5e6f2,"reason=FailedScheduling count=None msg=0/6 nodes are available: 1 c_wall violated: 1 conflicting context pair(s) with node memory, 5 node(s) had untolerated taint(s). no new claims to deallocate, preemption: 0/6 nodes are available: 1 No preemption victims found for incoming pod, 5 Preemption is not helpful for scheduling."
0.0657,Event,ADDED,eval-conflicts-rho010-r3-000-kzrhp.18d46698d8b2baf8,reason=Scheduled count=None msg=Successfully assigned compute/eval-conflicts-rho010-r3-000-kzrhp to kind-worker
0.066,Event,ADDED,eval-conflicts-rho010-r3-000-kzrhp.18d46698f241a62e,"reason=Pulled count=1 msg=Container image ""busybox:musl"" already present on machine"
0.0662,Event,ADDED,eval-conflicts-rho010-r3-000-kzrhp.18d46698f3587087,reason=Created count=1 msg=Created container: task
0.0664,Event,ADDED,eval-conflicts-rho010-r3-000-kzrhp.18d46698f843233d,reason=Started count=1 msg=Started container task
0.0666,Event,ADDED,eval-conflicts-rho010-r3-000.18d46698d7cf2177,reason=SuccessfulCreate count=1 msg=Created pod: eval-conflicts-rho010-r3-000-kzrhp
0.0668,Event,ADDED,eval-conflicts-rho010-r3-000.18d4669c2055c1e3,reason=Completed count=1 msg=Job completed
0.0669,Event,ADDED,eval-conflicts-rho010-r3-001-f8zf7.18d466991385df86,reason=Scheduled count=None msg=Successfully assigned compute/eval-conflicts-rho010-r3-001-f8zf7 to kind-worker5
0.0671,Event,ADDED,eval-conflicts-rho010-r3-001-f8zf7.18d466992c054700,"reason=Pulled count=1 msg=Container image ""busybox:musl"" already present on machine"
0.0673,Event,ADDED,eval-conflicts-rho010-r3-001-f8zf7.18d466992d4fbada,reason=Created count=1 msg=Created container: task
0.0675,Event,ADDED,eval-conflicts-rho010-r3-001-f8zf7.18d466992f46db41,reason=Started count=1 msg=Started container task
0.0676,Event,ADDED,eval-conflicts-rho010-r3-001.18d4669912620cdd,reason=SuccessfulCreate count=1 msg=Created pod: eval-conflicts-rho010-r3-001-f8zf7
0.0678,Event,ADDED,eval-conflicts-rho010-r3-001.18d4669c6598fcfc,reason=Completed count=1 msg=Job completed
0.068,Event,ADDED,eval-conflicts-rho010-r3-002-bwz82.18d466994df47e45,reason=Scheduled count=None msg=Successfully assigned compute/eval-conflicts-rho010-r3-002-bwz82 to kind-worker2
0.0682,Event,ADDED,eval-conflicts-rho010-r3-002-bwz82.18d46699674d7c78,"reason=Pulled count=1 msg=Container image ""busybox:musl"" already present on machine"
0.0684,Event,ADDED,eval-conflicts-rho010-r3-002-bwz82.18d4669968626240,reason=Created count=1 msg=Created container: task
0.0686,Event,ADDED,eval-conflicts-rho010-r3-002-bwz82.18d466996a7e992e,reason=Started count=1 msg=Started container task
0.0688,Event,ADDED,eval-conflicts-rho010-r3-002.18d466994cfc1403,reason=SuccessfulCreate count=1 msg=Created pod: eval-conflicts-rho010-r3-002-bwz82
0.069,Event,ADDED,eval-conflicts-rho010-r3-002.18d4669ca2fe662d,reason=Completed count=1 msg=Job completed
0.0691,Event,ADDED,eval-conflicts-rho010-r3-003-gv7tx.18d4669989ab6e45,reason=Scheduled count=None msg=Successfully assigned compute/eval-conflicts-rho010-r3-003-gv7tx to kind-worker5
0.0693,Event,ADDED,eval-conflicts-rho010-r3-003-gv7tx.18d46699a322199a,"reason=Pulled count=1 msg=Container image ""busybox:musl"" already present on machine"
0.0695,Event,ADDED,eval-conflicts-rho010-r3-003-gv7tx.18d46699a435dd3f,reason=Created count=1 msg=Created container: task
0.0696,Event,ADDED,eval-conflicts-rho010-r3-003-gv7tx.18d46699a64c0361,reason=Started count=1 msg=Started container task
0.0698,Event,ADDED,eval-conflicts-rho010-r3-003.18d46699888f5ad9,reason=SuccessfulCreate count=1 msg=Created pod: eval-conflicts-rho010-r3-003-gv7tx
0.0701,Event,ADDED,eval-conflicts-rho010-r3-003.18d4669cdd356f0c,reason=Completed count=1 msg=Job completed
0.0703,Event,ADDED,eval-conflicts-rho010-r3-004-npkrv.18d46699c51ad480,reason=Scheduled count=None msg=Successfully assigned compute/eval-conflicts-rho010-r3-004-npkrv to kind-worker2
0.0705,Event,ADDED,eval-conflicts-rho010-r3-004-npkrv.18d46699dd4fb794,"reason=Pulled count=1 msg=Container image ""busybox:musl"" already present on machine"
0.0706,Event,ADDED,eval-conflicts-rho010-r3-004-npkrv.18d46699de60b6dc,reason=Created count=1 msg=Created container: task
0.0708,Event,ADDED,eval-conflicts-rho010-r3-004-npkrv.18d46699e04fa957,reason=Started count=1 msg=Started container task
0.071,Event,ADDED,eval-conflicts-rho010-r3-004.18d46699c3f76431,reason=SuccessfulCreate count=1 msg=Created pod: eval-conflicts-rho010-r3-004-npkrv
0.0712,Event,ADDED,eval-conflicts-rho010-r3-004.18d4669d1ab2733c,reason=Completed count=1 msg=Job completed
0.0713,Event,ADDED,eval-conflicts-rho010-r3-005-dg4s6.18d4669a00b1cac6,reason=Scheduled count=None msg=Successfully assigned compute/eval-conflicts-rho010-r3-005-dg4s6 to kind-worker
0.0715,Event,ADDED,eval-conflicts-rho010-r3-005-dg4s6.18d4669a196198f6,"reason=Pulled count=1 msg=Container image ""busybox:musl"" already present on machine"
0.0717,Event,ADDED,eval-conflicts-rho010-r3-005-dg4s6.18d4669a1a6ab7b8,reason=Created count=1 msg=Created container: task
0.0718,Event,ADDED,eval-conflicts-rho010-r3-005-dg4s6.18d4669a1c7628c6,reason=Started count=1 msg=Started container task
0.072,Event,ADDED,eval-conflicts-rho010-r3-005.18d46699ffacfee6,reason=SuccessfulCreate count=1 msg=Created pod: eval-conflicts-rho010-r3-005-dg4s6
0.0723,Event,ADDED,eval-conflicts-rho010-r3-005.18d4669d4c5fdb36,reason=Completed count=1 msg=Job completed
0.0724,Event,ADDED,eval-conflicts-rho010-r3-006-dz8pf.18d4669a3c61eb7f,reason=Scheduled count=None msg=Successfully assigned compute/eval-conflicts-rho010-r3-006-dz8pf to kind-worker4
0.0727,Event,ADDED,eval-conflicts-rho010-r3-006-dz8pf.18d4669a554d4ad2,"reason=Pulled count=1 msg=Container image ""busybox:musl"" already present on machine"
0.0728,Event,ADDED,eval-conflicts-rho010-r3-006-dz8pf.18d4669a5680e6a3,reason=Created count=1 msg=Created container: task
0.073,Event,ADDED,eval-conflicts-rho010-r3-006-dz8pf.18d4669a58c57725,reason=Started count=1 msg=Started container task
0.0732,Event,ADDED,eval-conflicts-rho010-r3-006.18d4669a3b808cc4,reason=SuccessfulCreate count=1 msg=Created pod: eval-conflicts-rho010-r3-006-dz8pf
0.0734,Event,ADDED,eval-conflicts-rho010-r3-006.18d4669d9f0ce22d,reason=Completed count=1 msg=Job completed
0.0735,Event,ADDED,eval-conflicts-rho010-r3-007-nj2nk.18d4669a7755b8f8,reason=Scheduled count=None msg=Successfully assigned compute/eval-conflicts-rho010-r3-007-nj2nk to kind-worker3
0.0737,Event,ADDED,eval-conflicts-rho010-r3-007-nj2nk.18d4669a8fc59a28,"reason=Pulled count=1 msg=Container image ""busybox:musl"" already present on machine"
0.0739,Event,ADDED,eval-conflicts-rho010-r3-007-nj2nk.18d4669a90cb47ab,reason=Created count=1 msg=Created container: task
0.074,Event,ADDED,eval-conflicts-rho010-r3-007-nj2nk.18d4669a95325508,reason=Started count=1 msg=Started container task
0.0742,Event,ADDED,eval-conflicts-rho010-r3-007.18d4669a76d08002,reason=SuccessfulCreate count=1 msg=Created pod: eval-conflicts-rho010-r3-007-nj2nk
0.0744,Event,ADDED,eval-conflicts-rho010-r3-007.18d4669dbfe4c25c,reason=Completed count=1 msg=Job completed
0.0745,Event,ADDED,eval-conflicts-rho010-r3-008-lkbq4.18d4669ab37f216a,reason=Scheduled count=None msg=Successfully assigned compute/eval-conflicts-rho010-r3-008-lkbq4 to kind-worker5
0.0747,Event,ADDED,eval-conflicts-rho010-r3-008-lkbq4.18d4669acdacc861,"reason=Pulled count=1 msg=Container image ""busybox:musl"" already present on machine"
0.0749,Event,ADDED,eval-conflicts-rho010-r3-008-lkbq4.18d4669acec4d1c4,reason=Created count=1 msg=Created container: task
0.0751,Event,ADDED,eval-conflicts-rho010-r3-008-lkbq4.18d4669ad208d225,reason=Started count=1 msg=Started container task
0.0752,Event,ADDED,eval-conflicts-rho010-r3-008.18d4669ab2889980,reason=SuccessfulCreate count=1 msg=Created pod: eval-conflicts-rho010-r3-008-lkbq4
0.0754,Event,ADDED,eval-conflicts-rho010-r3-008.18d4669e07c17c45,reason=Completed count=1 msg=Job completed
0.0755,Event,ADDED,eval-conflicts-rho010-r3-009-2jzch.18d4669aeeacac5d,reason=Scheduled count=None msg=Successfully assigned compute/eval-conflicts-rho010-r3-009-2jzch to kind-worker3
0.0757,Event,ADDED,eval-conflicts-rho010-r3-009-2jzch.18d4669b06fcb740,"reason=Pulled count=1 msg=Container image ""busybox:musl"" already present on machine"
0.0759,Event,ADDED,eval-conflicts-rho010-r3-009-2jzch.18d4669b0807886e,reason=Created count=1 msg=Created container: task
0.0762,Event,ADDED,eval-conflicts-rho010-r3-009-2jzch.18d4669b09e073bd,reason=Started count=1 msg=Started container task
0.0764,Event,ADDED,eval-conflicts-rho010-r3-009.18d4669aee07bf49,reason=SuccessfulCreate count=1 msg=Created pod: eval-conflicts-rho010-r3-009-2jzch
0.0766,Event,ADDED,eval-conflicts-rho010-r3-009.18d4669e37b2abbb,reason=Completed count=1 msg=Job completed
0.0767,Event,ADDED,eval-conflicts-rho010-r3-010-rchzl.18d4669b2b3e97a7,reason=Scheduled count=None msg=Successfully assigned compute/eval-conflicts-rho010-r3-010-rchzl to kind-worker3
0.0769,Event,ADDED,eval-conflicts-rho010-r3-010-rchzl.18d4669b461fe644,"reason=Pulled count=1 msg=Container image ""busybox:musl"" already present on machine"
0.0771,Event,ADDED,eval-conflicts-rho010-r3-010-rchzl.18d4669b475253c0,reason=Created count=1 msg=Created container: task
0.0772,Event,ADDED,eval-conflicts-rho010-r3-010-rchzl.18d4669b4ad99f64,reason=Started count=1 msg=Started container task
0.0774,Event,ADDED,eval-conflicts-rho010-r3-010.18d4669b2ab54c83,reason=SuccessfulCreate count=1 msg=Created pod: eval-conflicts-rho010-r3-010-rchzl
0.0776,Event,ADDED,eval-conflicts-rho010-r3-010.18d4669e7365be57,reason=Completed count=1 msg=Job completed
0.0777,Event,ADDED,eval-conflicts-rho010-r3-011-s9jnk.18d4669b65a90048,"reason=FailedScheduling count=None msg=0/6 nodes are available: 1 c_wall violated: 1 conflicting context pair(s) with node memory, 5 node(s) had untolerated taint(s). no new claims to deallocate, preemption: 0/6 nodes are available: 1 No preemption victims found for incoming pod, 5 Preemption is not helpful for scheduling."
0.0779,Event,ADDED,eval-conflicts-rho010-r3-011-s9jnk.18d4669b6643fc1e,"reason=FailedScheduling count=None msg=0/6 nodes are available: 1 c_wall violated: 1 conflicting context pair(s) with node memory, 5 node(s) had untolerated taint(s). no new claims to deallocate, preemption: 0/6 nodes are available: 1 No preemption victims found for incoming pod, 5 Preemption is not helpful for scheduling."
0.0781,Event,ADDED,eval-conflicts-rho010-r3-011-s9jnk.18d4669cd5c1bbe8,reason=Scheduled count=None msg=Successfully assigned compute/eval-conflicts-rho010-r3-011-s9jnk to kind-worker2
0.0782,Event,ADDED,eval-conflicts-rho010-r3-011-s9jnk.18d4669cf023e16f,"reason=Pulled count=1 msg=Container image ""busybox:musl"" already present on machine"
0.0784,Event,ADDED,eval-conflicts-rho010-r3-011-s9jnk.18d4669cf1f05521,reason=Created count=1 msg=Created container: task
0.0786,Event,ADDED,eval-conflicts-rho010-r3-011-s9jnk.18d4669cf598a120,reason=Started count=1 msg=Started container task
0.0787,Event,ADDED,eval-conflicts-rho010-r3-011.18d4669b6560f099,reason=SuccessfulCreate count=1 msg=Created pod: eval-conflicts-rho010-r3-011-s9jnk
0.0789,Event,ADDED,eval-conflicts-rho010-r3-011.18d466a024caf17a,reason=Completed count=1 msg=Job completed
0.0791,Event,ADDED,eval-conflicts-rho010-r3-012-ngxcr.18d4669ba1d994d6,reason=Scheduled count=None msg=Successfully assigned compute/eval-conflicts-rho010-r3-012-ngxcr to kind-worker3
0.0792,Event,ADDED,eval-conflicts-rho010-r3-012-ngxcr.18d4669bbc89b57b,"reason=Pulled count=1 msg=Container image ""busybox:musl"" already present on machine"
0.0794,Event,ADDED,eval-conflicts-rho010-r3-012-ngxcr.18d4669bbdcaa35d,reason=Created count=1 msg=Created container: task
0.0796,Event,ADDED,eval-conflicts-rho010-r3-012-ngxcr.18d4669bbfe66d2b,reason=Started count=1 msg=Started container task
0.0798,Event,ADDED,eval-conflicts-rho010-r3-012.18d4669ba147aaa7,reason=SuccessfulCreate count=1 msg=Created pod: eval-conflicts-rho010-r3-012-ngxcr
0.08,Event,ADDED,eval-conflicts-rho010-r3-012.18d4669eeba18c23,reason=Completed count=1 msg=Job completed
0.0804,Event,ADDED,eval-conflicts-rho010-r3-013-qzs78.18d4669bdd541612,"reason=FailedScheduling count=None msg=0/6 nodes are available: 1 c_wall violated: 1 conflicting context pair(s) with node memory, 5 node(s) had untolerated taint(s). no new claims to deallocate, preemption: 0/6 nodes are available: 1 No preemption victims found for incoming pod, 5 Preemption is not helpful for scheduling."
0.081,Event,ADDED,eval-conflicts-rho010-r3-013-qzs78.18d4669bddda5089,"reason=FailedScheduling count=None msg=0/6 nodes are available: 1 c_wall violated: 1 conflicting context pair(s) with node memory, 5 node(s) had untolerated taint(s). no new claims to deallocate, preemption: 0/6 nodes are available: 1 No preemption victims found for incoming pod, 5 Preemption is not helpful for scheduling."
0.0815,Event,ADDED,eval-conflicts-rho010-r3-013-qzs78.18d4669cd59078af,reason=Scheduled count=None msg=Successfully assigned compute/eval-conflicts-rho010-r3-013-qzs78 to kind-worker2
0.0819,Event,ADDED,eval-conflicts-rho010-r3-013-qzs78.18d4669cefbef8fd,"reason=Pulled count=1 msg=Container image ""busybox:musl"" already present on machine"
0.0822,Event,ADDED,eval-conflicts-rho010-r3-013-qzs78.18d4669cf15e6597,reason=Created count=1 msg=Created container: task
0.0825,Event,ADDED,eval-conflicts-rho010-r3-013-qzs78.18d4669cf53726f1,reason=Started count=1 msg=Started container task
0.0829,Event,ADDED,eval-conflicts-rho010-r3-013.18d4669bdd0bdca0,reason=SuccessfulCreate count=1 msg=Created pod: eval-conflicts-rho010-r3-013-qzs78
0.0831,Event,ADDED,eval-conflicts-rho010-r3-013.18d466a0246d9cf6,reason=Completed count=1 msg=Job completed
0.0832,Event,ADDED,eval-conflicts-rho010-r3-014-m7k2d.18d4669c18ddfd1e,reason=Scheduled count=None msg=Successfully assigned compute/eval-conflicts-rho010-r3-014-m7k2d to kind-worker3
0.0834,Event,ADDED,eval-conflicts-rho010-r3-014-m7k2d.18d4669c31c23f13,"reason=Pulled count=1 msg=Container image ""busybox:musl"" already present on machine"
0.0836,Event,ADDED,eval-conflicts-rho010-r3-014-m7k2d.18d4669c32d288cf,reason=Created count=1 msg=Created container: task
0.0838,Event,ADDED,eval-conflicts-rho010-r3-014-m7k2d.18d4669c34cc25e2,reason=Started count=1 msg=Started container task
0.0841,Event,ADDED,eval-conflicts-rho010-r3-014.18d4669c182f7770,reason=SuccessfulCreate count=1 msg=Created pod: eval-conflicts-rho010-r3-014-m7k2d
0.0843,Event,ADDED,eval-conflicts-rho010-r3-014.18d4669f63adf0b0,reason=Completed count=1 msg=Job completed
0.0845,Event,ADDED,eval-conflicts-rho010-r3-015-9r4mv.18d4669c54d7be43,reason=Scheduled count=None msg=Successfully assigned compute/eval-conflicts-rho010-r3-015-9r4mv to kind-worker3
0.0848,Event,ADDED,eval-conflicts-rho010-r3-015-9r4mv.18d4669c6eb39961,"reason=Pulled count=1 msg=Container image ""busybox:musl"" already present on machine"
0.085,Event,ADDED,eval-conflicts-rho010-r3-015-9r4mv.18d4669c6fc5230a,reason=Created count=1 msg=Created container: task
0.0852,Event,ADDED,eval-conflicts-rho010-r3-015-9r4mv.18d4669c71f5f7ee,reason=Started count=1 msg=Started container task
0.0855,Event,ADDED,eval-conflicts-rho010-r3-015.18d4669c5437e624,reason=SuccessfulCreate count=1 msg=Created pod: eval-conflicts-rho010-r3-015-9r4mv
0.0858,Event,ADDED,eval-conflicts-rho010-r3-015.18d4669f9fd8b767,reason=Completed count=1 msg=Job completed
0.086,Event,ADDED,eval-conflicts-rho010-r3-016-jd2cf.18d4669c90e4d131,reason=Scheduled count=None msg=Successfully assigned compute/eval-conflicts-rho010-r3-016-jd2cf to kind-worker3
0.0863,Event,ADDED,eval-conflicts-rho010-r3-016-jd2cf.18d4669caa12d84a,"reason=Pulled count=1 msg=Container image ""busybox:musl"" already present on machine"
0.0866,Event,ADDED,eval-conflicts-rho010-r3-016-jd2cf.18d4669cab25bc1b,reason=Created count=1 msg=Created container: task
0.0868,Event,ADDED,eval-conflicts-rho010-r3-016-jd2cf.18d4669caf5936be,reason=Started count=1 msg=Started container task
0.087,Event,ADDED,eval-conflicts-rho010-r3-016.18d4669c9050c787,reason=SuccessfulCreate count=1 msg=Created pod: eval-conflicts-rho010-r3-016-jd2cf
0.0872,Event,ADDED,eval-conflicts-rho010-r3-016.18d4669fdcbef3a1,reason=Completed count=1 msg=Job completed
0.0873,Event,ADDED,eval-conflicts-rho010-r3-017-cv6n2.18d4669ccaf7356b,"reason=FailedScheduling count=None msg=0/6 nodes are available: 6 node(s) had untolerated taint(s). no new claims to deallocate, preemption: 0/6 nodes are available: 6 Preemption is not helpful for scheduling."
0.0875,Event,ADDED,eval-conflicts-rho010-r3-017-cv6n2.18d4669cd60706ea,reason=Scheduled count=None msg=Successfully assigned compute/eval-conflicts-rho010-r3-017-cv6n2 to kind-worker2
0.0877,Event,ADDED,eval-conflicts-rho010-r3-017-cv6n2.18d4669cf0601def,"reason=Pulled count=1 msg=Container image ""busybox:musl"" already present on machine"
0.0878,Event,ADDED,eval-conflicts-rho010-r3-017-cv6n2.18d4669cf258edef,reason=Created count=1 msg=Created container: task
0.0882,Event,ADDED,eval-conflicts-rho010-r3-017-cv6n2.18d4669cf598cd13,reason=Started count=1 msg=Started container task
0.0884,Event,ADDED,eval-conflicts-rho010-r3-017.18d4669ccaede1c0,reason=SuccessfulCreate count=1 msg=Created pod: eval-conflicts-rho010-r3-017-cv6n2
0.0888,Event,ADDED,eval-conflicts-rho010-r3-017.18d466a0265aef4e,reason=Completed count=1 msg=Job completed
0.0893,Event,ADDED,eval-conflicts-rho010-r3-018-cwtxb.18d4669d07d2daff,"reason=FailedScheduling count=None msg=0/6 nodes are available: 1 c_wall violated: 1 conflicting context pair(s) with node memory, 5 node(s) had untolerated taint(s). no new claims to deallocate, preemption: 0/6 nodes are available: 1 No preemption victims found for incoming pod, 5 Preemption is not helpful for scheduling."
0.0898,Event,ADDED,eval-conflicts-rho010-r3-018-cwtxb.18d4669d08597ab1,"reason=FailedScheduling count=None msg=0/6 nodes are available: 1 c_wall violated: 1 conflicting context pair(s) with node memory, 5 node(s) had untolerated taint(s). no new claims to deallocate, preemption: 0/6 nodes are available: 1 No preemption victims found for incoming pod, 5 Preemption is not helpful for scheduling."
0.09,Event,ADDED,eval-conflicts-rho010-r3-018-cwtxb.18d4669ed55a6d4f,reason=Scheduled count=None msg=Successfully assigned compute/eval-conflicts-rho010-r3-018-cwtxb to kind-worker
0.0902,Event,ADDED,eval-conflicts-rho010-r3-018-cwtxb.18d4669eece1d8ce,"reason=Pulled count=1 msg=Container image ""busybox:musl"" already present on machine"
0.0903,Event,ADDED,eval-conflicts-rho010-r3-018-cwtxb.18d4669eef090ad7,reason=Created count=1 msg=Created container: task
0.0906,Event,ADDED,eval-conflicts-rho010-r3-018-cwtxb.18d4669ef39fbaf5,reason=Started count=1 msg=Started container task
0.0908,Event,ADDED,eval-conflicts-rho010-r3-018.18d4669d078def12,reason=SuccessfulCreate count=1 msg=Created pod: eval-conflicts-rho010-r3-018-cwtxb
0.0909,Event,ADDED,eval-conflicts-rho010-r3-018.18d466a233374a5c,reason=Completed count=1 msg=Job completed
0.0911,Event,ADDED,eval-conflicts-rho010-r3-019-mftww.18d4669d43558550,reason=Scheduled count=None msg=Successfully assigned compute/eval-conflicts-rho010-r3-019-mftww to kind-worker2
0.0913,Event,ADDED,eval-conflicts-rho010-r3-019-mftww.18d4669d5c991f26,"reason=Pulled count=1 msg=Container image ""busybox:musl"" already present on machine"
0.0914,Event,ADDED,eval-conflicts-rho010-r3-019-mftww.18d4669d5daae190,reason=Created count=1 msg=Created container: task
0.0917,Event,ADDED,eval-conflicts-rho010-r3-019-mftww.18d4669d6440237f,reason=Started count=1 msg=Started container task
0.0921,Event,ADDED,eval-conflicts-rho010-r3-019.18d4669d42d39955,reason=SuccessfulCreate count=1 msg=Created pod: eval-conflicts-rho010-r3-019-mftww
0.0923,Event,ADDED,eval-conflicts-rho010-r3-019.18d466a09bf2d74e,reason=Completed count=1 msg=Job completed
0.0925,Event,ADDED,eval-conflicts-rho010-r3-020-b94m7.18d4669d7f201b01,reason=Scheduled count=None msg=Successfully assigned compute/eval-conflicts-rho010-r3-020-b94m7 to kind-worker2
0.0927,Event,ADDED,eval-conflicts-rho010-r3-020-b94m7.18d4669d975d7891,"reason=Pulled count=1 msg=Container image ""busybox:musl"" already present on machine"
0.0929,Event,ADDED,eval-conflicts-rho010-r3-020-b94m7.18d4669d987eae13,reason=Created count=1 msg=Created container: task
0.0931,Event,ADDED,eval-conflicts-rho010-r3-020-b94m7.18d4669d9ab3bb6b,reason=Started count=1 msg=Started container task
0.0933,Event,ADDED,eval-conflicts-rho010-r3-020.18d4669d7e7eb535,reason=SuccessfulCreate count=1 msg=Created pod: eval-conflicts-rho010-r3-020-b94m7
0.0934,Event,ADDED,eval-conflicts-rho010-r3-020.18d466a0d7d81c61,reason=Completed count=1 msg=Job completed
0.0936,Event,ADDED,eval-conflicts-rho010-r3-021-p86bx.18d4669db9ab7b6c,"reason=FailedScheduling count=None msg=0/6 nodes are available: 1 c_wall violated: 1 conflicting context pair(s) with node memory, 5 node(s) had untolerated taint(s). no new claims to deallocate, preemption: 0/6 nodes are available: 1 No preemption victims found for incoming pod, 5 Preemption is not helpful for scheduling."
0.0938,Event,ADDED,eval-conflicts-rho010-r3-021-p86bx.18d4669dba36f2ad,"reason=FailedScheduling count=None msg=0/6 nodes are available: 1 c_wall violated: 1 conflicting context pair(s) with node memory, 5 node(s) had untolerated taint(s). no new claims to deallocate, preemption: 0/6 nodes are available: 1 No preemption victims found for incoming pod, 5 Preemption is not helpful for scheduling."
0.094,Event,ADDED,eval-conflicts-rho010-r3-021-p86bx.18d4669edbae0c10,"reason=FailedScheduling count=None msg=0/6 nodes are available: 2 c_wall violated: 1 conflicting context pair(s) with node memory, 4 node(s) had untolerated taint(s). no new claims to deallocate, preemption: 0/6 nodes are available: 2 No preemption victims found for incoming pod, 4 Preemption is not helpful for scheduling."
0.0942,Event,ADDED,eval-conflicts-rho010-r3-021-p86bx.18d4669f32743af2,"reason=FailedScheduling count=None msg=0/6 nodes are available: 1 c_wall violated: 1 conflicting context pair(s) with node memory, 5 node(s) had untolerated taint(s). no new claims to deallocate, preemption: 0/6 nodes are available: 1 No preemption victims found for incoming pod, 5 Preemption is not helpful for scheduling."
0.0943,Event,ADDED,eval-conflicts-rho010-r3-021-p86bx.18d4669f4829c80e,reason=Scheduled count=None msg=Successfully assigned compute/eval-conflicts-rho010-r3-021-p86bx to kind-worker4
0.0945,Event,ADDED,eval-conflicts-rho010-r3-021-p86bx.18d4669f62d5df18,"reason=Pulled count=1 msg=Container image ""busybox:musl"" already present on machine"
0.0947,Event,ADDED,eval-conflicts-rho010-r3-021-p86bx.18d4669f6537487b,reason=Created count=1 msg=Created container: task
0.0948,Event,ADDED,eval-conflicts-rho010-r3-021-p86bx.18d4669f6942d030,reason=Started count=1 msg=Started container task
0.095,Event,ADDED,eval-conflicts-rho010-r3-021.18d4669db967b1fb,reason=SuccessfulCreate count=1 msg=Created pod: eval-conflicts-rho010-r3-021-p86bx
0.0952,Event,ADDED,eval-conflicts-rho010-r3-021.18d466a2863ed683,reason=Completed count=1 msg=Job completed
0.0953,Event,ADDED,eval-conflicts-rho010-r3-022-g4swg.18d4669df5cd4571,reason=Scheduled count=None msg=Successfully assigned compute/eval-conflicts-rho010-r3-022-g4swg to kind-worker2
0.0955,Event,ADDED,eval-conflicts-rho010-r3-022-g4swg.18d4669e0fd9b433,"reason=Pulled count=1 msg=Container image ""busybox:musl"" already present on machine"
0.0957,Event,ADDED,eval-conflicts-rho010-r3-022-g4swg.18d4669e10eb68cf,reason=Created count=1 msg=Created container: task
0.0958,Event,ADDED,eval-conflicts-rho010-r3-022-g4swg.18d4669e149b1796,reason=Started count=1 msg=Started container task
0.0961,Event,ADDED,eval-conflicts-rho010-r3-022.18d4669df5432789,reason=SuccessfulCreate count=1 msg=Created pod: eval-conflicts-rho010-r3-022-g4swg
0.0963,Event,ADDED,eval-conflicts-rho010-r3-022.18d466a14fca06b1,reason=Completed count=1 msg=Job completed
0.0965,Event,ADDED,eval-conflicts-rho010-r3-023-gxwbw.18d4669e31f0f3d5,"reason=FailedScheduling count=None msg=0/6 nodes are available: 1 c_wall violated: 1 conflicting context pair(s) with node memory, 5 node(s) had untolerated taint(s). no new claims to deallocate, preemption: 0/6 nodes are available: 1 No preemption victims found for incoming pod, 5 Preemption is not helpful for scheduling."
0.0966,Event,ADDED,eval-conflicts-rho010-r3-023-gxwbw.18d4669e3272d941,"reason=FailedScheduling count=None msg=0/6 nodes are available: 1 c_wall violated: 1 conflicting context pair(s) with node memory, 5 node(s) had untolerated taint(s). no new claims to deallocate, preemption: 0/6 nodes are available: 1 No preemption victims found for incoming pod, 5 Preemption is not helpful for scheduling."
0.0968,Event,ADDED,eval-conflicts-rho010-r3-023-gxwbw.18d4669edb9f93f4,reason=Scheduled count=None msg=Successfully assigned compute/eval-conflicts-rho010-r3-023-gxwbw to kind-worker
0.097,Event,ADDED,eval-conflicts-rho010-r3-023-gxwbw.18d4669ef5cfcceb,"reason=Pulled count=1 msg=Container image ""busybox:musl"" already present on machine"
0.0972,Event,ADDED,eval-conflicts-rho010-r3-023-gxwbw.18d4669ef6fa2637,reason=Created count=1 msg=Created container: task
0.0973,Event,ADDED,eval-conflicts-rho010-r3-023-gxwbw.18d4669efa25011b,reason=Started count=1 msg=Started container task
0.0975,Event,ADDED,eval-conflicts-rho010-r3-023.18d4669e31ac5e7a,reason=SuccessfulCreate count=1 msg=Created pod: eval-conflicts-rho010-r3-023-gxwbw
0.0977,Event,ADDED,eval-conflicts-rho010-r3-023.18d466a23363fd29,reason=Completed count=1 msg=Job completed
0.0978,Event,ADDED,eval-conflicts-rho010-r3-024-c4bpr.18d4669e6cbadfae,reason=Scheduled count=None msg=Successfully assigned compute/eval-conflicts-rho010-r3-024-c4bpr to kind-worker2
0.098,Event,ADDED,eval-conflicts-rho010-r3-024-c4bpr.18d4669e86553cbd,"reason=Pulled count=1 msg=Container image ""busybox:musl"" already present on machine"
0.0982,Event,ADDED,eval-conflicts-rho010-r3-024-c4bpr.18d4669e876d5a18,reason=Created count=1 msg=Created container: task
0.0984,Event,ADDED,eval-conflicts-rho010-r3-024-c4bpr.18d4669e8985cf8a,reason=Started count=1 msg=Started container task
0.0986,Event,ADDED,eval-conflicts-rho010-r3-024.18d4669e6c2e0c0f,reason=SuccessfulCreate count=1 msg=Created pod: eval-conflicts-rho010-r3-024-c4bpr
0.0987,Event,ADDED,eval-conflicts-rho010-r3-024.18d466a1c8403084,reason=Completed count=1 msg=Job completed
0.0989,Event,ADDED,eval-conflicts-rho010-r3-025-vsnb7.18d4669ea880426a,"reason=FailedScheduling count=None msg=0/6 nodes are available: 1 c_wall violated: 1 conflicting context pair(s) with node memory, 5 node(s) had untolerated taint(s). no new claims to deallocate, preemption: 0/6 nodes are available: 1 No preemption victims found for incoming pod, 5 Preemption is not helpful for scheduling."
0.0991,Event,ADDED,eval-conflicts-rho010-r3-025-vsnb7.18d4669ea90898b1,"reason=FailedScheduling count=None msg=0/6 nodes are available: 1 c_wall violated: 1 conflicting context pair(s) with node memory, 5 node(s) had untolerated taint(s). no new claims to deallocate, preemption: 0/6 nodes are available: 1 No preemption victims found for incoming pod, 5 Preemption is not helpful for scheduling."
0.0992,Event,ADDED,eval-conflicts-rho010-r3-025-vsnb7.18d4669ed1b40b49,reason=Scheduled count=None msg=Successfully assigned compute/eval-conflicts-rho010-r3-025-vsnb7 to kind-worker
0.0995,Event,ADDED,eval-conflicts-rho010-r3-025-vsnb7.18d4669eecb31ed3,"reason=Pulled count=1 msg=Container image ""busybox:musl"" already present on machine"
0.0997,Event,ADDED,eval-conflicts-rho010-r3-025-vsnb7.18d4669eeebeb1a6,reason=Created count=1 msg=Created container: task
0.1001,Event,ADDED,eval-conflicts-rho010-r3-025-vsnb7.18d4669ef35a70b9,reason=Started count=1 msg=Started container task
0.1004,Event,ADDED,eval-conflicts-rho010-r3-025.18d4669ea83f3c21,reason=SuccessfulCreate count=1 msg=Created pod: eval-conflicts-rho010-r3-025-vsnb7
0.1006,Event,ADDED,eval-conflicts-rho010-r3-025.18d466a23365f2eb,reason=Completed count=1 msg=Job completed
0.1007,Event,ADDED,eval-conflicts-rho010-r3-026-cpnh9.18d4669ee45c8a71,reason=Scheduled count=None msg=Successfully assigned compute/eval-conflicts-rho010-r3-026-cpnh9 to kind-worker
0.1009,Event,ADDED,eval-conflicts-rho010-r3-026-cpnh9.18d4669eff3c43ea,"reason=Pulled count=1 msg=Container image ""busybox:musl"" already present on machine"
0.1011,Event,ADDED,eval-conflicts-rho010-r3-026-cpnh9.18d4669f005916d7,reason=Created count=1 msg=Created container: task
0.1013,Event,ADDED,eval-conflicts-rho010-r3-026-cpnh9.18d4669f035e298f,reason=Started count=1 msg=Started container task
0.1015,Event,ADDED,eval-conflicts-rho010-r3-026.18d4669ee35a1614,reason=SuccessfulCreate count=1 msg=Created pod: eval-conflicts-rho010-r3-026-cpnh9
0.1016,Event,ADDED,eval-conflicts-rho010-r3-026.18d466a23365766b,reason=Completed count=1 msg=Job completed
0.1018,Event,ADDED,eval-conflicts-rho010-r3-027-h9v2k.18d4669f20bdfdca,"reason=FailedScheduling count=None msg=0/6 nodes are available: 2 c_wall violated: 1 conflicting context pair(s) with node memory, 4 node(s) had untolerated taint(s). no new claims to deallocate, preemption: 0/6 nodes are available: 2 No preemption victims found for incoming pod, 4 Preemption is not helpful for scheduling."
0.102,Event,ADDED,eval-conflicts-rho010-r3-027-h9v2k.18d4669f220c844d,"reason=FailedScheduling count=None msg=0/6 nodes are available: 2 c_wall violated: 1 conflicting context pair(s) with node memory, 4 node(s) had untolerated taint(s). no new claims to deallocate, preemption: 0/6 nodes are available: 2 No preemption victims found for incoming pod, 4 Preemption is not helpful for scheduling."
0.1022,Event,ADDED,eval-conflicts-rho010-r3-027-h9v2k.18d4669f329cf9e1,"reason=FailedScheduling count=None msg=0/6 nodes are available: 1 c_wall violated: 1 conflicting context pair(s) with node memory, 5 node(s) had untolerated taint(s). no new claims to deallocate, preemption: 0/6 nodes are available: 1 No preemption victims found for incoming pod, 5 Preemption is not helpful for scheduling."
0.1024,Event,ADDED,eval-conflicts-rho010-r3-027-h9v2k.18d4669f48990b80,reason=Scheduled count=None msg=Successfully assigned compute/eval-conflicts-rho010-r3-027-h9v2k to kind-worker4
0.1025,Event,ADDED,eval-conflicts-rho010-r3-027-h9v2k.18d4669f62f31b90,"reason=Pulled count=1 msg=Container image ""busybox:musl"" already present on machine"
0.1027,Event,ADDED,eval-conflicts-rho010-r3-027-h9v2k.18d4669f655306a9,reason=Created count=1 msg=Created container: task
0.1029,Event,ADDED,eval-conflicts-rho010-r3-027-h9v2k.18d4669f69463539,reason=Started count=1 msg=Started container task
0.1031,Event,ADDED,eval-conflicts-rho010-r3-027.18d4669f204dd03e,reason=SuccessfulCreate count=1 msg=Created pod: eval-conflicts-rho010-r3-027-h9v2k
0.1032,Event,ADDED,eval-conflicts-rho010-r3-027.18d466a2866c3e3d,reason=Completed count=1 msg=Job completed
0.1034,Event,ADDED,eval-conflicts-rho010-r3-028-x4gn6.18d4669f5d21f307,reason=Scheduled count=None msg=Successfully assigned compute/eval-conflicts-rho010-r3-028-x4gn6 to kind-worker4
0.1035,Event,ADDED,eval-conflicts-rho010-r3-028-x4gn6.18d4669f76babfd1,"reason=Pulled count=1 msg=Container image ""busybox:musl"" already present on machine"
0.1037,Event,ADDED,eval-conflicts-rho010-r3-028-x4gn6.18d4669f77f96e8f,reason=Created count=1 msg=Created container: task
0.1039,Event,ADDED,eval-conflicts-rho010-r3-028-x4gn6.18d4669f7a216f3b,reason=Started count=1 msg=Started container task
0.1043,Event,ADDED,eval-conflicts-rho010-r3-028.18d4669f5b8bf610,reason=SuccessfulCreate count=1 msg=Created pod: eval-conflicts-rho010-r3-028-x4gn6
0.1045,Event,ADDED,eval-conflicts-rho010-r3-028.18d466a2c1f136be,reason=Completed count=1 msg=Job completed
0.1047,Event,ADDED,eval-conflicts-rho010-r3-029-gbc55.18d4669f97452179,reason=Scheduled count=None msg=Successfully assigned compute/eval-conflicts-rho010-r3-029-gbc55 to kind-worker5
0.1049,Event,ADDED,eval-conflicts-rho010-r3-029-gbc55.18d4669fb152222b,"reason=Pulled count=1 msg=Container image ""busybox:musl"" already present on machine"
0.1052,Event,ADDED,eval-conflicts-rho010-r3-029-gbc55.18d4669fb296b8ea,reason=Created count=1 msg=Created container: task
0.1053,Event,ADDED,eval-conflicts-rho010-r3-029-gbc55.18d4669fb7ad126a,reason=Started count=1 msg=Started container task
0.1055,Event,ADDED,eval-conflicts-rho010-r3-029.18d4669f966eb861,reason=SuccessfulCreate count=1 msg=Created pod: eval-conflicts-rho010-r3-029-gbc55
0.1057,Event,ADDED,eval-conflicts-rho010-r3-029.18d466a2eebfa78d,reason=Completed count=1 msg=Job completed
0.1058,Event,ADDED,eval-conflicts-rho010-r3-030-qhxnn.18d4669fd36ee286,reason=Scheduled count=None msg=Successfully assigned compute/eval-conflicts-rho010-r3-030-qhxnn to kind-worker5
0.106,Event,ADDED,eval-conflicts-rho010-r3-030-qhxnn.18d4669febd13422,"reason=Pulled count=1 msg=Container image ""busybox:musl"" already present on machine"
0.1062,Event,ADDED,eval-conflicts-rho010-r3-030-qhxnn.18d4669fece82582,reason=Created count=1 msg=Created container: task
0.1063,Event,ADDED,eval-conflicts-rho010-r3-030-qhxnn.18d4669ff192a9b9,reason=Started count=1 msg=Started container task
0.1066,Event,ADDED,eval-conflicts-rho010-r3-030.18d4669fd262a8e8,reason=SuccessfulCreate count=1 msg=Created pod: eval-conflicts-rho010-r3-030-qhxnn
0.1068,Event,ADDED,eval-conflicts-rho010-r3-030.18d466a32a5e09dc,reason=Completed count=1 msg=Job completed
0.1069,Event,ADDED,eval-conflicts-rho010-r3-031-47kv6.18d466a00e4b4615,reason=Scheduled count=None msg=Successfully assigned compute/eval-conflicts-rho010-r3-031-47kv6 to kind-worker
0.1071,Event,ADDED,eval-conflicts-rho010-r3-031-47kv6.18d466a02e0ee8d7,"reason=Pulled count=1 msg=Container image ""busybox:musl"" already present on machine"
0.1073,Event,ADDED,eval-conflicts-rho010-r3-031-47kv6.18d466a02f2124e0,reason=Created count=1 msg=Created container: task
0.1074,Event,ADDED,eval-conflicts-rho010-r3-031-47kv6.18d466a032eb0613,reason=Started count=1 msg=Started container task
0.1077,Event,ADDED,eval-conflicts-rho010-r3-031.18d466a00d3b5eb8,reason=SuccessfulCreate count=1 msg=Created pod: eval-conflicts-rho010-r3-031-47kv6
0.1081,Event,ADDED,eval-conflicts-rho010-r3-031.18d466a35da48dfa,reason=Completed count=1 msg=Job completed
0.1083,Event,ADDED,eval-conflicts-rho010-r3-032-86fdk.18d466a04a3cce13,reason=Scheduled count=None msg=Successfully assigned compute/eval-conflicts-rho010-r3-032-86fdk to kind-worker5
0.1086,Event,ADDED,eval-conflicts-rho010-r3-032-86fdk.18d466a0670c0a97,"reason=Pulled count=1 msg=Container image ""busybox:musl"" already present on machine"
0.1088,TaskRequest,ADDED,eval-conflicts-rho030-r9-000,phase=None job=None
0.1094,Event,ADDED,eval-conflicts-rho010-r3-032-86fdk.18d466a06817e298,reason=Created count=1 msg=Created container: task
0.1096,Event,ADDED,eval-conflicts-rho010-r3-032-86fdk.18d466a0715f7e46,reason=Started count=1 msg=Started container task
0.1097,Event,ADDED,eval-conflicts-rho010-r3-032.18d466a0490c1e2f,reason=SuccessfulCreate count=1 msg=Created pod: eval-conflicts-rho010-r3-032-86fdk
0.1099,Event,ADDED,eval-conflicts-rho010-r3-032.18d466a3a1de85c3,reason=Completed count=1 msg=Job completed
0.1102,Event,ADDED,eval-conflicts-rho010-r3-033-cn24m.18d466a085efa35b,reason=Scheduled count=None msg=Successfully assigned compute/eval-conflicts-rho010-r3-033-cn24m to kind-worker
0.1105,Event,ADDED,eval-conflicts-rho010-r3-033-cn24m.18d466a0a10fe9b6,"reason=Pulled count=1 msg=Container image ""busybox:musl"" already present on machine"
0.1106,Event,ADDED,eval-conflicts-rho010-r3-033-cn24m.18d466a0a22f32a2,reason=Created count=1 msg=Created container: task
0.1111,Event,ADDED,eval-conflicts-rho010-r3-033-cn24m.18d466a0a594fcaa,reason=Started count=1 msg=Started container task
0.1113,Event,ADDED,eval-conflicts-rho010-r3-033.18d466a084974150,reason=SuccessfulCreate count=1 msg=Created pod: eval-conflicts-rho010-r3-033-cn24m
0.1115,Event,ADDED,eval-conflicts-rho010-r3-033.18d466a3d530042a,reason=Completed count=1 msg=Job completed
0.1117,Event,ADDED,eval-conflicts-rho010-r3-034-z9zfk.18d466a0c26a54ea,reason=Scheduled count=None msg=Successfully assigned compute/eval-conflicts-rho010-r3-034-z9zfk to kind-worker5
0.1119,TaskRequest,MODIFIED,eval-conflicts-rho030-r9-000,phase=Pending job=None
0.1123,Event,ADDED,eval-conflicts-rho010-r3-034-z9zfk.18d466a0dfa7a269,"reason=Pulled count=1 msg=Container image ""busybox:musl"" already present on machine"
0.1125,Event,ADDED,eval-conflicts-rho010-r3-034-z9zfk.18d466a0e0be7e4f,reason=Created count=1 msg=Created container: task
0.1127,Event,ADDED,eval-conflicts-rho010-r3-034-z9zfk.18d466a0e45241ee,reason=Started count=1 msg=Started container task
0.1128,Event,ADDED,eval-conflicts-rho010-r3-034.18d466a0c10c7e75,reason=SuccessfulCreate count=1 msg=Created pod: eval-conflicts-rho010-r3-034-z9zfk
0.1132,Event,ADDED,eval-conflicts-rho010-r3-034.18d466a41995c85a,reason=Completed count=1 msg=Job completed
0.1133,Event,ADDED,eval-conflicts-rho010-r3-035-4bvpr.18d466a0fd03aad4,reason=Scheduled count=None msg=Successfully assigned compute/eval-conflicts-rho010-r3-035-4bvpr to kind-worker4
0.1135,Event,ADDED,eval-conflicts-rho010-r3-035-4bvpr.18d466a116259da7,"reason=Pulled count=1 msg=Container image ""busybox:musl"" already present on machine"
0.1142,Event,ADDED,eval-conflicts-rho010-r3-035-4bvpr.18d466a11762e52f,reason=Created count=1 msg=Created container: task
0.1144,Event,ADDED,eval-conflicts-rho010-r3-035-4bvpr.18d466a1194922a1,reason=Started count=1 msg=Started container task
0.1146,Event,ADDED,eval-conflicts-rho010-r3-035.18d466a0fbcce01c,reason=SuccessfulCreate count=1 msg=Created pod: eval-conflicts-rho010-r3-035-4bvpr
0.1148,Event,ADDED,eval-conflicts-rho010-r3-035.18d466a428bf99f9,reason=Completed count=1 msg=Job completed
0.1151,Event,ADDED,eval-conflicts-rho010-r3-036-jrzlb.18d466a1383db7e2,reason=Scheduled count=None msg=Successfully assigned compute/eval-conflicts-rho010-r3-036-jrzlb to kind-worker5
0.1153,Event,ADDED,eval-conflicts-rho010-r3-036-jrzlb.18d466a157456ed4,"reason=Pulled count=1 msg=Container image ""busybox:musl"" already present on machine"
0.1155,Event,ADDED,eval-conflicts-rho010-r3-036-jrzlb.18d466a1587501bc,reason=Created count=1 msg=Created container: task
0.1159,Event,ADDED,eval-conflicts-rho010-r3-036-jrzlb.18d466a15bdb6ded,reason=Started count=1 msg=Started container task
0.1162,Event,ADDED,eval-conflicts-rho010-r3-036.18d466a1377677c3,reason=SuccessfulCreate count=1 msg=Created pod: eval-conflicts-rho010-r3-036-jrzlb
0.1164,Event,ADDED,eval-conflicts-rho010-r3-036.18d466a491dcd78d,reason=Completed count=1 msg=Job completed
0.1166,Event,ADDED,eval-conflicts-rho010-r3-037-q4lgv.18d466a173d9054e,reason=Scheduled count=None msg=Successfully assigned compute/eval-conflicts-rho010-r3-037-q4lgv to kind-worker5
0.117,Event,ADDED,eval-conflicts-rho010-r3-037-q4lgv.18d466a19222720f,"reason=Pulled count=1 msg=Container image ""busybox:musl"" already present on machine"
0.1172,Event,ADDED,eval-conflicts-rho010-r3-037-q4lgv.18d466a19343f687,reason=Created count=1 msg=Created container: task
0.1174,Event,ADDED,eval-conflicts-rho010-r3-037-q4lgv.18d466a1971e6d98,reason=Started count=1 msg=Started container task
0.1176,Event,ADDED,eval-conflicts-rho010-r3-037.18d466a173304600,reason=SuccessfulCreate count=1 msg=Created pod: eval-conflicts-rho010-r3-037-q4lgv
0.1179,Event,ADDED,eval-conflicts-rho010-r3-037.18d466a4cddad53e,reason=Completed count=1 msg=Job completed
0.118,Event,ADDED,eval-conflicts-rho010-r3-038-44xcl.18d466a1b005501a,reason=Scheduled count=None msg=Successfully assigned compute/eval-conflicts-rho010-r3-038-44xcl to kind-worker2
0.1182,Event,ADDED,eval-conflicts-rho010-r3-038-44xcl.18d466a1c912e19e,"reason=Pulled count=1 msg=Container image ""busybox:musl"" already present on machine"
0.1186,Event,ADDED,eval-conflicts-rho010-r3-038-44xcl.18d466a1ca404e33,reason=Created count=1 msg=Created container: task
0.1188,Event,ADDED,eval-conflicts-rho010-r3-038-44xcl.18d466a1cecd44b1,reason=Started count=1 msg=Started container task
0.1191,Event,ADDED,eval-conflicts-rho010-r3-038.18d466a1af5159f0,reason=SuccessfulCreate count=1 msg=Created pod: eval-conflicts-rho010-r3-038-44xcl
0.1193,Event,ADDED,eval-conflicts-rho010-r3-038.18d466a50da1e66e,reason=Completed count=1 msg=Job completed
0.1196,Event,ADDED,eval-conflicts-rho010-r3-039-tn8b2.18d466a1eaa93fff,reason=Scheduled count=None msg=Successfully assigned compute/eval-conflicts-rho010-r3-039-tn8b2 to kind-worker2
0.1198,Event,ADDED,eval-conflicts-rho010-r3-039-tn8b2.18d466a2041b40e3,"reason=Pulled count=1 msg=Container image ""busybox:musl"" already present on machine"
0.1201,Event,ADDED,eval-conflicts-rho010-r3-039-tn8b2.18d466a2055bdab5,reason=Created count=1 msg=Created container: task
0.1204,Event,ADDED,eval-conflicts-rho010-r3-039-tn8b2.18d466a20753e8b3,reason=Started count=1 msg=Started container task
0.1206,Event,ADDED,eval-conflicts-rho010-r3-039.18d466a1e9f4d5a2,reason=SuccessfulCreate count=1 msg=Created pod: eval-conflicts-rho010-r3-039-tn8b2
0.1208,Event,ADDED,eval-conflicts-rho010-r3-039.18d466a548c7b194,reason=Completed count=1 msg=Job completed
0.1209,Event,ADDED,eval-conflicts-rho010-r3-040-clgcg.18d466a226ec925c,reason=Scheduled count=None msg=Successfully assigned compute/eval-conflicts-rho010-r3-040-clgcg to kind-worker2
0.1213,Event,ADDED,eval-conflicts-rho010-r3-040-clgcg.18d466a2413d8f8b,"reason=Pulled count=1 msg=Container image ""busybox:musl"" already present on machine"
0.1215,Event,ADDED,eval-conflicts-rho010-r3-040-clgcg.18d466a24256d1d3,reason=Created count=1 msg=Created container: task
0.1219,Event,ADDED,eval-conflicts-rho010-r3-040-clgcg.18d466a2446ffd62,reason=Started count=1 msg=Started container task
0.1221,Event,ADDED,eval-conflicts-rho010-r3-040.18d466a2261c2431,reason=SuccessfulCreate count=1 msg=Created pod: eval-conflicts-rho010-r3-040-clgcg
0.1224,Event,ADDED,eval-conflicts-rho010-r3-040.18d466a585390db4,reason=Completed count=1 msg=Job completed
0.1226,Event,ADDED,eval-conflicts-rho010-r3-041-4fv76.18d466a261d256d3,reason=Scheduled count=None msg=Successfully assigned compute/eval-conflicts-rho010-r3-041-4fv76 to kind-worker3
0.1228,Event,ADDED,eval-conflicts-rho010-r3-041-4fv76.18d466a27ccbde31,"reason=Pulled count=1 msg=Container image ""busybox:musl"" already present on machine"
0.1232,Event,ADDED,eval-conflicts-rho010-r3-041-4fv76.18d466a27ddface4,reason=Created count=1 msg=Created container: task
0.1235,Event,ADDED,eval-conflicts-rho010-r3-041-4fv76.18d466a280eddfc0,reason=Started count=1 msg=Started container task
0.1237,Event,ADDED,eval-conflicts-rho010-r3-041.18d466a261411e28,reason=SuccessfulCreate count=1 msg=Created pod: eval-conflicts-rho010-r3-041-4fv76
0.1239,Event,ADDED,eval-conflicts-rho010-r3-041.18d466a5b048bd48,reason=Completed count=1 msg=Job completed
0.1243,Event,ADDED,eval-conflicts-rho010-r3-042-jcg89.18d466a29dbaf166,reason=Scheduled count=None msg=Successfully assigned compute/eval-conflicts-rho010-r3-042-jcg89 to kind-worker2
0.1245,Event,ADDED,eval-conflicts-rho010-r3-042-jcg89.18d466a2b8638011,"reason=Pulled count=1 msg=Container image ""busybox:musl"" already present on machine"
0.1246,Event,ADDED,eval-conflicts-rho010-r3-042-jcg89.18d466a2b97ef0eb,reason=Created count=1 msg=Created container: task
0.1248,Event,ADDED,eval-conflicts-rho010-r3-042-jcg89.18d466a2bdff058e,reason=Started count=1 msg=Started container task
0.1251,Event,ADDED,eval-conflicts-rho010-r3-042.18d466a29d15cd28,reason=SuccessfulCreate count=1 msg=Created pod: eval-conflicts-rho010-r3-042-jcg89
0.1253,Event,ADDED,eval-conflicts-rho010-r3-042.18d466a5fcc039a8,reason=Completed count=1 msg=Job completed
0.1254,Event,ADDED,eval-conflicts-rho010-r3-043-mjzv9.18d466a2d95b0b94,reason=Scheduled count=None msg=Successfully assigned compute/eval-conflicts-rho010-r3-043-mjzv9 to kind-worker2
0.1256,Event,ADDED,eval-conflicts-rho010-r3-043-mjzv9.18d466a2f412e1e4,"reason=Pulled count=1 msg=Container image ""busybox:musl"" already present on machine"
0.1258,Event,ADDED,eval-conflicts-rho010-r3-043-mjzv9.18d466a2f545beae,reason=Created count=1 msg=Created container: task
0.1259,Event,ADDED,eval-conflicts-rho010-r3-043-mjzv9.18d466a2f9f41c11,reason=Started count=1 msg=Started container task
0.1261,Event,ADDED,eval-conflicts-rho010-r3-043.18d466a2d88fa752,reason=SuccessfulCreate count=1 msg=Created pod: eval-conflicts-rho010-r3-043-mjzv9
0.1265,Event,ADDED,eval-conflicts-rho010-r3-043.18d466a638332152,reason=Completed count=1 msg=Job completed
0.1267,Event,ADDED,eval-conflicts-rho010-r3-044-qvjxn.18d466a3154ae228,reason=Scheduled count=None msg=Successfully assigned compute/eval-conflicts-rho010-r3-044-qvjxn to kind-worker2
0.1269,Event,ADDED,eval-conflicts-rho010-r3-044-qvjxn.18d466a32e943125,"reason=Pulled count=1 msg=Container image ""busybox:musl"" already present on machine"
0.1273,Event,ADDED,eval-conflicts-rho010-r3-044-qvjxn.18d466a32f9785fd,reason=Created count=1 msg=Created container: task
0.1275,Event,ADDED,eval-conflicts-rho010-r3-044-qvjxn.18d466a3321e4cd6,reason=Started count=1 msg=Started container task
0.1277,Event,ADDED,eval-conflicts-rho010-r3-044.18d466a314415296,reason=SuccessfulCreate count=1 msg=Created pod: eval-conflicts-rho010-r3-044-qvjxn
0.1279,Event,ADDED,eval-conflicts-rho010-r3-044.18d466a674151802,reason=Completed count=1 msg=Job completed
0.1282,Event,ADDED,eval-conflicts-rho010-r3-045-l2fxj.18d466a350a21b3a,reason=Scheduled count=None msg=Successfully assigned compute/eval-conflicts-rho010-r3-045-l2fxj to kind-worker3
0.1284,Event,ADDED,eval-conflicts-rho010-r3-045-l2fxj.18d466a36bc0a899,"reason=Pulled count=1 msg=Container image ""busybox:musl"" already present on machine"
0.1286,Event,ADDED,eval-conflicts-rho010-r3-045-l2fxj.18d466a36cc708e4,reason=Created count=1 msg=Created container: task
0.1288,Event,ADDED,eval-conflicts-rho010-r3-045-l2fxj.18d466a370051e3e,reason=Started count=1 msg=Started container task
0.1292,Event,ADDED,eval-conflicts-rho010-r3-045.18d466a34fd46427,reason=SuccessfulCreate count=1 msg=Created pod: eval-conflicts-rho010-r3-045-l2fxj
0.1294,Event,ADDED,eval-conflicts-rho010-r3-045.18d466a69ee85bdc,reason=Completed count=1 msg=Job completed
0.1295,Event,ADDED,eval-conflicts-rho010-r3-046-h7d8x.18d466a38beb670f,reason=Scheduled count=None msg=Successfully assigned compute/eval-conflicts-rho010-r3-046-h7d8x to kind-worker
0.1302,Job,ADDED,eval-conflicts-rho030-r9-000,
0.1305,Event,ADDED,eval-conflicts-rho010-r3-046-h7d8x.18d466a3aa46e134,"reason=Pulled count=1 msg=Container image ""busybox:musl"" already present on machine"
0.1307,Event,ADDED,eval-conflicts-rho010-r3-046-h7d8x.18d466a3ab4e2279,reason=Created count=1 msg=Created container: task
0.1309,Event,ADDED,eval-conflicts-rho010-r3-046-h7d8x.18d466a3af17faec,reason=Started count=1 msg=Started container task
0.131,Event,ADDED,eval-conflicts-rho010-r3-046.18d466a38b4e02f5,reason=SuccessfulCreate count=1 msg=Created pod: eval-conflicts-rho010-r3-046-h7d8x
0.1315,Event,ADDED,eval-conflicts-rho010-r3-046.18d466a6dddf2b62,reason=Completed count=1 msg=Job completed
0.1319,Event,ADDED,eval-conflicts-rho010-r3-047-wm7ns.18d466a3c83bcaed,reason=Scheduled count=None msg=Successfully assigned compute/eval-conflicts-rho010-r3-047-wm7ns to kind-worker
0.1322,Event,ADDED,eval-conflicts-rho010-r3-047-wm7ns.18d466a3e2d7c7c4,"reason=Pulled count=1 msg=Container image ""busybox:musl"" already present on machine"
0.1324,Event,ADDED,eval-conflicts-rho010-r3-047-wm7ns.18d466a3e42a12ae,reason=Created count=1 msg=Created container: task
0.1328,Event,ADDED,eval-conflicts-rho010-r3-047-wm7ns.18d466a3e83d89cd,reason=Started count=1 msg=Started container task
0.133,Event,ADDED,eval-conflicts-rho010-r3-047.18d466a3c7019c12,reason=SuccessfulCreate count=1 msg=Created pod: eval-conflicts-rho010-r3-047-wm7ns
0.1332,Event,ADDED,eval-conflicts-rho010-r3-047.18d466a719ca0291,reason=Completed count=1 msg=Job completed
0.1336,Event,ADDED,eval-conflicts-rho010-r3-048-j6zc7.18d466a403143d65,reason=Scheduled count=None msg=Successfully assigned compute/eval-conflicts-rho010-r3-048-j6zc7 to kind-worker4
0.1339,Event,ADDED,eval-conflicts-rho010-r3-048-j6zc7.18d466a41c90f7ae,"reason=Pulled count=1 msg=Container image ""busybox:musl"" already present on machine"
0.1341,Event,ADDED,eval-conflicts-rho010-r3-048-j6zc7.18d466a41da664cd,reason=Created count=1 msg=Created container: task
0.1343,Event,ADDED,eval-conflicts-rho010-r3-048-j6zc7.18d466a422633af3,reason=Started count=1 msg=Started container task
0.1346,Event,ADDED,eval-conflicts-rho010-r3-048.18d466a402954e67,reason=SuccessfulCreate count=1 msg=Created pod: eval-conflicts-rho010-r3-048-j6zc7
0.1348,Event,ADDED,eval-conflicts-rho010-r3-048.18d466a73176c3c8,reason=Completed count=1 msg=Job completed
0.135,Event,ADDED,eval-conflicts-rho010-r3-049-zn9kh.18d466a43f1e521c,reason=Scheduled count=None msg=Successfully assigned compute/eval-conflicts-rho010-r3-049-zn9kh to kind-worker
0.1352,Event,ADDED,eval-conflicts-rho010-r3-049-zn9kh.18d466a45b558018,"reason=Pulled count=1 msg=Container image ""busybox:musl"" already present on machine"
0.1353,TaskRequest,MODIFIED,eval-conflicts-rho030-r9-000,phase=Scheduled job=None
0.1357,Event,ADDED,eval-conflicts-rho010-r3-049-zn9kh.18d466a45c7707e2,reason=Created count=1 msg=Created container: task
0.1359,Event,ADDED,eval-conflicts-rho010-r3-049-zn9kh.18d466a462c89f98,reason=Started count=1 msg=Started container task
0.1362,Event,ADDED,eval-conflicts-rho010-r3-049.18d466a43e242428,reason=SuccessfulCreate count=1 msg=Created pod: eval-conflicts-rho010-r3-049-zn9kh
0.1365,Event,ADDED,eval-conflicts-rho010-r3-049.18d466a791eecf8f,reason=Completed count=1 msg=Job completed
0.1367,Event,ADDED,eval-conflicts-rho010-r3-050-xpdpl.18d466a47aff1c4c,reason=Scheduled count=None msg=Successfully assigned compute/eval-conflicts-rho010-r3-050-xpdpl to kind-worker
0.1371,Event,ADDED,eval-conflicts-rho010-r3-050-xpdpl.18d466a49398f512,"reason=Pulled count=1 msg=Container image ""busybox:musl"" already present on machine"
0.1373,Event,ADDED,eval-conflicts-rho010-r3-050-xpdpl.18d466a494ce03f1,reason=Created count=1 msg=Created container: task
0.1376,Event,ADDED,eval-conflicts-rho010-r3-050-xpdpl.18d466a49cd74cad,reason=Started count=1 msg=Started container task
0.1381,Event,ADDED,eval-conflicts-rho010-r3-050.18d466a479f3bccc,reason=SuccessfulCreate count=1 msg=Created pod: eval-conflicts-rho010-r3-050-xpdpl
0.1387,Event,ADDED,eval-conflicts-rho010-r3-050.18d466a7ce0b9bfc,reason=Completed count=1 msg=Job completed
0.1393,Event,ADDED,eval-conflicts-rho010-r3-051-6ddms.18d466a4b66e244c,reason=Scheduled count=None msg=Successfully assigned compute/eval-conflicts-rho010-r3-051-6ddms to kind-worker
0.1396,Event,ADDED,eval-conflicts-rho010-r3-051-6ddms.18d466a4d0411f8a,"reason=Pulled count=1 msg=Container image ""busybox:musl"" already present on machine"
0.1401,Event,ADDED,eval-conflicts-rho010-r3-051-6ddms.18d466a4d21b0cb4,reason=Created count=1 msg=Created container: task
0.1404,Event,ADDED,eval-conflicts-rho010-r3-051-6ddms.18d466a4d65ada43,reason=Started count=1 msg=Started container task
0.1408,Event,ADDED,eval-conflicts-rho010-r3-051.18d466a4b595d784,reason=SuccessfulCreate count=1 msg=Created pod: eval-conflicts-rho010-r3-051-6ddms
0.141,Event,ADDED,eval-conflicts-rho010-r3-051.18d466a809e13b9d,reason=Completed count=1 msg=Job completed
0.1412,Event,ADDED,eval-conflicts-rho010-r3-052-zlszf.18d466a4f23b4561,reason=Scheduled count=None msg=Successfully assigned compute/eval-conflicts-rho010-r3-052-zlszf to kind-worker4
0.1415,Event,ADDED,eval-conflicts-rho010-r3-052-zlszf.18d466a50b5979ad,"reason=Pulled count=1 msg=Container image ""busybox:musl"" already present on machine"
0.1428,Pod,ADDED,eval-conflicts-rho030-r9-000-9fw4p,phase=Pending node=None
0.1431,Event,ADDED,eval-conflicts-rho010-r3-052-zlszf.18d466a50cb984ad,reason=Created count=1 msg=Created container: task
0.1433,Event,ADDED,eval-conflicts-rho010-r3-052-zlszf.18d466a51ac3b024,reason=Started count=1 msg=Started container task
0.1434,Event,ADDED,eval-conflicts-rho010-r3-052.18d466a4f1350759,reason=SuccessfulCreate count=1 msg=Created pod: eval-conflicts-rho010-r3-052-zlszf
0.1439,Event,ADDED,eval-conflicts-rho010-r3-052.18d466a85ca9f455,reason=Completed count=1 msg=Job completed
0.1441,Event,ADDED,eval-conflicts-rho010-r3-053-5ngpv.18d466a52d651b6f,"reason=FailedScheduling count=None msg=0/6 nodes are available: 2 c_wall violated: 1 conflicting context pair(s) with node memory, 4 node(s) had untolerated taint(s). no new claims to deallocate, preemption: 0/6 nodes are available: 2 No preemption victims found for incoming pod, 4 Preemption is not helpful for scheduling."
0.1444,Event,ADDED,eval-conflicts-rho010-r3-053-5ngpv.18d466a52e2c4e42,"reason=FailedScheduling count=None msg=0/6 nodes are available: 2 c_wall violated: 1 conflicting context pair(s) with node memory, 4 node(s) had untolerated taint(s). no new claims to deallocate, preemption: 0/6 nodes are available: 2 No preemption victims found for incoming pod, 4 Preemption is not helpful for scheduling."
0.145,Job,MODIFIED,eval-conflicts-rho030-r9-000,
0.1454,Event,ADDED,eval-conflicts-rho010-r3-053-5ngpv.18d466a5def6384f,"reason=FailedScheduling count=None msg=0/6 nodes are available: 1 c_wall violated: 1 conflicting context pair(s) with node memory, 5 node(s) had untolerated taint(s). no new claims to deallocate, preemption: 0/6 nodes are available: 1 No preemption victims found for incoming pod, 5 Preemption is not helpful for scheduling."
0.1455,Event,ADDED,eval-conflicts-rho010-r3-053-5ngpv.18d466a648a1769a,reason=Scheduled count=None msg=Successfully assigned compute/eval-conflicts-rho010-r3-053-5ngpv to kind-worker2
0.1457,Event,ADDED,eval-conflicts-rho010-r3-053-5ngpv.18d466a65f0c8613,"reason=Pulled count=1 msg=Container image ""busybox:musl"" already present on machine"
0.1459,Event,ADDED,eval-conflicts-rho010-r3-053-5ngpv.18d466a6605868a0,reason=Created count=1 msg=Created container: task
0.1463,Event,ADDED,eval-conflicts-rho010-r3-053-5ngpv.18d466a665aae72f,reason=Started count=1 msg=Started container task
0.1465,Event,ADDED,eval-conflicts-rho010-r3-053.18d466a52ceac261,reason=SuccessfulCreate count=1 msg=Created pod: eval-conflicts-rho010-r3-053-5ngpv
0.1466,Event,ADDED,eval-conflicts-rho010-r3-053.18d466a97d9c2d4a,reason=Completed count=1 msg=Job completed
0.147,Event,ADDED,eval-conflicts-rho010-r3-054-66qhb.18d466a56904f9c3,reason=Scheduled count=None msg=Successfully assigned compute/eval-conflicts-rho010-r3-054-66qhb to kind-worker
0.1472,Event,ADDED,eval-conflicts-rho010-r3-054-66qhb.18d466a581f4a490,"reason=Pulled count=1 msg=Container image ""busybox:musl"" already present on machine"
0.1475,Event,ADDED,eval-conflicts-rho010-r3-054-66qhb.18d466a58304ad9d,reason=Created count=1 msg=Created container: task
0.1477,Event,ADDED,eval-conflicts-rho010-r3-054-66qhb.18d466a587d328f7,reason=Started count=1 msg=Started container task
0.1481,Event,ADDED,eval-conflicts-rho010-r3-054.18d466a56847c240,reason=SuccessfulCreate count=1 msg=Created pod: eval-conflicts-rho010-r3-054-66qhb
0.1483,Event,ADDED,eval-conflicts-rho010-r3-054.18d466a8bcddd1ae,reason=Completed count=1 msg=Job completed
0.1485,Event,ADDED,eval-conflicts-rho010-r3-055-j66g6.18d466a5a4f53bf9,reason=Scheduled count=None msg=Successfully assigned compute/eval-conflicts-rho010-r3-055-j66g6 to kind-worker4
0.1486,Event,ADDED,eval-conflicts-rho010-r3-055-j66g6.18d466a5be9984d5,"reason=Pulled count=1 msg=Container image ""busybox:musl"" already present on machine"
0.1488,TaskRequest,MODIFIED,eval-conflicts-rho030-r9-000,phase=Scheduled job=None
0.1493,Event,ADDED,eval-conflicts-rho010-r3-055-j66g6.18d466a5bff0ab0a,reason=Created count=1 msg=Created container: task
0.1496,Event,ADDED,eval-conflicts-rho010-r3-055-j66g6.18d466a5c4b2753a,reason=Started count=1 msg=Started container task
0.15,Event,ADDED,eval-conflicts-rho010-r3-055.18d466a5a3e8e299,reason=SuccessfulCreate count=1 msg=Created pod: eval-conflicts-rho010-r3-055-j66g6
0.1504,Event,ADDED,eval-conflicts-rho010-r3-055.18d466a8d44f4c55,reason=Completed count=1 msg=Job completed
0.1505,Event,ADDED,eval-conflicts-rho010-r3-056-j5wdn.18d466a5dfefdbc2,"reason=FailedScheduling count=None msg=0/6 nodes are available: 1 c_wall violated: 1 conflicting context pair(s) with node memory, 5 node(s) had untolerated taint(s). no new claims to deallocate, preemption: 0/6 nodes are available: 1 No preemption victims found for incoming pod, 5 Preemption is not helpful for scheduling."
0.1508,Event,ADDED,eval-conflicts-rho010-r3-056-j5wdn.18d466a5e09435df,"reason=FailedScheduling count=None msg=0/6 nodes are available: 1 c_wall violated: 1 conflicting context pair(s) with node memory, 5 node(s) had untolerated taint(s). no new claims to deallocate, preemption: 0/6 nodes are available: 1 No preemption victims found for incoming pod, 5 Preemption is not helpful for scheduling."
0.1512,Event,ADDED,eval-conflicts-rho010-r3-056-j5wdn.18d466a64a498ba5,"reason=FailedScheduling count=None msg=0/6 nodes are available: 2 c_wall violated: 1 conflicting context pair(s) with node memory, 4 node(s) had untolerated taint(s). no new claims to deallocate, preemption: 0/6 nodes are available: 2 No preemption victims found for incoming pod, 4 Preemption is not helpful for scheduling."
0.1514,Event,ADDED,eval-conflicts-rho010-r3-056-j5wdn.18d466a651c2f09f,"reason=FailedScheduling count=None msg=0/6 nodes are available: 1 c_wall violated: 1 conflicting context pair(s) with node memory, 5 node(s) had untolerated taint(s). no new claims to deallocate, preemption: 0/6 nodes are available: 1 No preemption victims found for incoming pod, 5 Preemption is not helpful for scheduling."
0.1516,Event,ADDED,eval-conflicts-rho010-r3-056-j5wdn.18d466a6af629302,"reason=FailedScheduling count=None msg=0/6 nodes are available: 2 c_wall violated: 1 conflicting context pair(s) with node memory, 4 node(s) had untolerated taint(s). no new claims to deallocate, preemption: 0/6 nodes are available: 2 No preemption victims found for incoming pod, 4 Preemption is not helpful for scheduling."
0.152,Event,ADDED,eval-conflicts-rho010-r3-056-j5wdn.18d466a88d4e7a8b,reason=Scheduled count=None msg=Successfully assigned compute/eval-conflicts-rho010-r3-056-j5wdn to kind-worker3
0.1523,Event,ADDED,eval-conflicts-rho010-r3-056-j5wdn.18d466a8a735ebaa,"reason=Pulled count=1 msg=Container image ""busybox:musl"" already present on machine"
0.1525,Event,ADDED,eval-conflicts-rho010-r3-056-j5wdn.18d466a8a85421d8,reason=Created count=1 msg=Created container: task
0.1532,Event,ADDED,eval-conflicts-rho010-r3-056-j5wdn.18d466a8aac6fc0b,reason=Started count=1 msg=Started container task
0.1537,Event,ADDED,eval-conflicts-rho010-r3-056.18d466a5dfb45524,reason=SuccessfulCreate count=1 msg=Created pod: eval-conflicts-rho010-r3-056-j5wdn
0.1539,Event,ADDED,eval-conflicts-rho010-r3-056.18d466abc15e523a,reason=Completed count=1 msg=Job completed
0.1541,Event,ADDED,eval-conflicts-rho010-r3-057-nxw9s.18d466a61b8ccfdf,"reason=FailedScheduling count=None msg=0/6 nodes are available: 1 c_wall violated: 1 conflicting context pair(s) with node memory, 5 node(s) had untolerated taint(s). no new claims to deallocate, preemption: 0/6 nodes are available: 1 No preemption victims found for incoming pod, 5 Preemption is not helpful for scheduling."
0.1545,Event,ADDED,eval-conflicts-rho010-r3-057-nxw9s.18d466a61c2d9a7b,"reason=FailedScheduling count=None msg=0/6 nodes are available: 1 c_wall violated: 1 conflicting context pair(s) with node memory, 5 node(s) had untolerated taint(s). no new claims to deallocate, preemption: 0/6 nodes are available: 1 No preemption victims found for incoming pod, 5 Preemption is not helpful for scheduling."
0.1547,Event,ADDED,eval-conflicts-rho010-r3-057-nxw9s.18d466a64a31dc6e,reason=Scheduled count=None msg=Successfully assigned compute/eval-conflicts-rho010-r3-057-nxw9s to kind-worker2
0.1549,Event,ADDED,eval-conflicts-rho010-r3-057-nxw9s.18d466a665b108be,"reason=Pulled count=1 msg=Container image ""busybox:musl"" already present on machine"
0.1551,Event,ADDED,eval-conflicts-rho010-r3-057-nxw9s.18d466a667246f13,reason=Created count=1 msg=Created container: task
0.1553,Event,ADDED,eval-conflicts-rho010-r3-057-nxw9s.18d466a66acf692d,reason=Started count=1 msg=Started container task
0.1555,Event,ADDED,eval-conflicts-rho010-r3-057.18d466a61b48c6e7,reason=SuccessfulCreate count=1 msg=Created pod: eval-conflicts-rho010-r3-057-nxw9s
0.1557,Event,ADDED,eval-conflicts-rho010-r3-057.18d466a97d726932,reason=Completed count=1 msg=Job completed
0.1559,Event,ADDED,eval-conflicts-rho010-r3-058-vw2gd.18d466a656ecd7d7,"reason=FailedScheduling count=None msg=0/6 nodes are available: 1 c_wall violated: 1 conflicting context pair(s) with node memory, 5 node(s) had untolerated taint(s). no new claims to deallocate, preemption: 0/6 nodes are available: 1 No preemption victims found for incoming pod, 5 Preemption is not helpful for scheduling."
0.1561,Event,ADDED,eval-conflicts-rho010-r3-058-vw2gd.18d466a65763615b,"reason=FailedScheduling count=None msg=0/6 nodes are available: 1 c_wall violated: 1 conflicting context pair(s) with node memory, 5 node(s) had untolerated taint(s). no new claims to deallocate, preemption: 0/6 nodes are available: 1 No preemption victims found for incoming pod, 5 Preemption is not helpful for scheduling."
0.1563,Event,ADDED,eval-conflicts-rho010-r3-058-vw2gd.18d466a6aa3a5a8c,reason=Scheduled count=None msg=Successfully assigned compute/eval-conflicts-rho010-r3-058-vw2gd to kind-worker5
0.1572,Pod,MODIFIED,eval-conflicts-rho030-r9-000-9fw4p,phase=Pending node=kind-worker
0.1575,Event,ADDED,eval-conflicts-rho010-r3-058-vw2gd.18d466a6c3796c0d,"reason=Pulled count=1 msg=Container image ""busybox:musl"" already present on machine"
0.1577,Event,ADDED,eval-conflicts-rho010-r3-058-vw2gd.18d466a6c4ae2102,reason=Created count=1 msg=Created container: task
0.1579,Event,ADDED,eval-conflicts-rho010-r3-058-vw2gd.18d466a6c925f801,reason=Started count=1 msg=Started container task
0.158,Event,ADDED,eval-conflicts-rho010-r3-058.18d466a656afcb3c,reason=SuccessfulCreate count=1 msg=Created pod: eval-conflicts-rho010-r3-058-vw2gd
0.1586,Event,ADDED,eval-conflicts-rho010-r3-058.18d466a9f03d92dc,reason=Completed count=1 msg=Job completed
0.1588,Event,ADDED,eval-conflicts-rho010-r3-059-rmwmh.18d466a693052e9e,reason=Scheduled count=None msg=Successfully assigned compute/eval-conflicts-rho010-r3-059-rmwmh to kind-worker2
0.1589,Event,ADDED,eval-conflicts-rho010-r3-059-rmwmh.18d466a6ae15a40f,"reason=Pulled count=1 msg=Container image ""busybox:musl"" already present on machine"
0.1591,Event,ADDED,eval-conflicts-rho010-r3-059-rmwmh.18d466a6af3cf4da,reason=Created count=1 msg=Created container: task
0.1595,Event,ADDED,eval-conflicts-rho010-r3-059-rmwmh.18d466a6b32fb81b,reason=Started count=1 msg=Started container task
0.1597,Event,ADDED,eval-conflicts-rho010-r3-059.18d466a69284a571,reason=SuccessfulCreate count=1 msg=Created pod: eval-conflicts-rho010-r3-059-rmwmh
0.1599,Event,ADDED,eval-conflicts-rho010-r3-059.18d466a9f532595c,reason=Completed count=1 msg=Job completed
0.1603,Event,ADDED,eval-conflicts-rho010-r3-060-hslc4.18d466a6ceee8d9e,reason=Scheduled count=None msg=Successfully assigned compute/eval-conflicts-rho010-r3-060-hslc4 to kind-worker2
0.1607,Event,ADDED,eval-conflicts-rho010-r3-060-hslc4.18d466a6e8604c72,"reason=Pulled count=1 msg=Container image ""busybox:musl"" already present on machine"
0.161,Event,ADDED,eval-conflicts-rho010-r3-060-hslc4.18d466a6e96cbf37,reason=Created count=1 msg=Created container: task
0.1612,Event,ADDED,eval-conflicts-rho010-r3-060-hslc4.18d466a6eda0c0da,reason=Started count=1 msg=Started container task
0.1615,Event,ADDED,eval-conflicts-rho010-r3-060.18d466a6ce2e2b25,reason=SuccessfulCreate count=1 msg=Created pod: eval-conflicts-rho010-r3-060-hslc4
0.1617,Event,ADDED,eval-conflicts-rho010-r3-060.18d466aa3125fe5d,reason=Completed count=1 msg=Job completed
0.1618,Event,ADDED,eval-conflicts-rho010-r3-061-8xccw.18d466a70b0610f9,reason=Scheduled count=None msg=Successfully assigned compute/eval-conflicts-rho010-r3-061-8xccw to kind-worker5
0.162,Event,ADDED,eval-conflicts-rho010-r3-061-8xccw.18d466a724649d09,"reason=Pulled count=1 msg=Container image ""busybox:musl"" already present on machine"
0.1622,Event,ADDED,eval-conflicts-rho010-r3-061-8xccw.18d466a72581c5c9,reason=Created count=1 msg=Created container: task
0.1624,Event,ADDED,eval-conflicts-rho010-r3-061-8xccw.18d466a727a9d14f,reason=Started count=1 msg=Started container task
0.1626,Event,ADDED,eval-conflicts-rho010-r3-061.18d466a709e13c03,reason=SuccessfulCreate count=1 msg=Created pod: eval-conflicts-rho010-r3-061-8xccw
0.163,Event,ADDED,eval-conflicts-rho010-r3-061.18d466aa682236ff,reason=Completed count=1 msg=Job completed
0.1633,Event,ADDED,eval-conflicts-rho010-r3-062-szc75.18d466a7461bfdc3,reason=Scheduled count=None msg=Successfully assigned compute/eval-conflicts-rho010-r3-062-szc75 to kind-worker5
0.1641,Event,ADDED,eval-conflicts-rho010-r3-062-szc75.18d466a75fdfadcd,"reason=Pulled count=1 msg=Container image ""busybox:musl"" already present on machine"
0.1644,Event,ADDED,eval-conflicts-rho010-r3-062-szc75.18d466a760fcaa68,reason=Created count=1 msg=Created container: task
0.1647,Event,ADDED,eval-conflicts-rho010-r3-062-szc75.18d466a766703432,reason=Started count=1 msg=Started container task
0.1649,Event,ADDED,eval-conflicts-rho010-r3-062.18d466a7455776a6,reason=SuccessfulCreate count=1 msg=Created pod: eval-conflicts-rho010-r3-062-szc75
0.1651,Event,ADDED,eval-conflicts-rho010-r3-062.18d466aaa449de33,reason=Completed count=1 msg=Job completed
0.1663,Pod,MODIFIED,eval-conflicts-rho030-r9-000-9fw4p,phase=Pending node=kind-worker
0.1666,Event,ADDED,eval-conflicts-rho010-r3-063-fmjj6.18d466a7825ea153,reason=Scheduled count=None msg=Successfully assigned compute/eval-conflicts-rho010-r3-063-fmjj6 to kind-worker5
0.1668,Event,ADDED,eval-conflicts-rho010-r3-063-fmjj6.18d466a79b1cc340,"reason=Pulled count=1 msg=Container image ""busybox:musl"" already present on machine"
0.1672,Event,ADDED,eval-conflicts-rho010-r3-063-fmjj6.18d466a79c2ebafc,reason=Created count=1 msg=Created container: task
0.1673,Event,ADDED,eval-conflicts-rho010-r3-063-fmjj6.18d466a7a054a2bb,reason=Started count=1 msg=Started container task
0.1687,Node,MODIFIED,kind-worker,taints=0
0.169,Event,ADDED,eval-conflicts-rho010-r3-063.18d466a7815f2be5,reason=SuccessfulCreate count=1 msg=Created pod: eval-conflicts-rho010-r3-063-fmjj6
0.1692,Event,ADDED,eval-conflicts-rho010-r3-063.18d466aae042122b,reason=Completed count=1 msg=Job completed
0.1694,Event,ADDED,eval-conflicts-rho010-r3-064-n2pzm.18d466a7bd8139c3,reason=Scheduled count=None msg=Successfully assigned compute/eval-conflicts-rho010-r3-064-n2pzm to kind-worker5
0.1696,Event,ADDED,eval-conflicts-rho010-r3-064-n2pzm.18d466a7d722cc3e,"reason=Pulled count=1 msg=Container image ""busybox:musl"" already present on machine"
0.1699,Event,ADDED,eval-conflicts-rho010-r3-064-n2pzm.18d466a7d836dbbc,reason=Created count=1 msg=Created container: task
0.17,Event,ADDED,eval-conflicts-rho010-r3-064-n2pzm.18d466a7da880eff,reason=Started count=1 msg=Started container task
0.1702,Event,ADDED,eval-conflicts-rho010-r3-064.18d466a7bcc9ae65,reason=SuccessfulCreate count=1 msg=Created pod: eval-conflicts-rho010-r3-064-n2pzm
0.1704,Event,ADDED,eval-conflicts-rho010-r3-064.18d466ab1c22e826,reason=Completed count=1 msg=Job completed
0.1706,Event,ADDED,eval-conflicts-rho010-r3-065-5skks.18d466a7f985e011,reason=Scheduled count=None msg=Successfully assigned compute/eval-conflicts-rho010-r3-065-5skks to kind-worker5
0.1707,Event,ADDED,eval-conflicts-rho010-r3-065-5skks.18d466a812b0e230,"reason=Pulled count=1 msg=Container image ""busybox:musl"" already present on machine"
0.1709,Event,ADDED,eval-conflicts-rho010-r3-065-5skks.18d466a813c667c3,reason=Created count=1 msg=Created container: task
0.1711,Event,ADDED,eval-conflicts-rho010-r3-065-5skks.18d466a8178555cd,reason=Started count=1 msg=Started container task
0.1713,Event,ADDED,eval-conflicts-rho010-r3-065.18d466a7f8c93f11,reason=SuccessfulCreate count=1 msg=Created pod: eval-conflicts-rho010-r3-065-5skks
0.1716,Event,ADDED,eval-conflicts-rho010-r3-065.18d466ab570f54db,reason=Completed count=1 msg=Job completed
0.1719,Event,ADDED,eval-conflicts-rho010-r3-066-f6hgd.18d466a8340fb498,reason=Scheduled count=None msg=Successfully assigned compute/eval-conflicts-rho010-r3-066-f6hgd to kind-worker5
0.1722,Event,ADDED,eval-conflicts-rho010-r3-066-f6hgd.18d466a84da257dc,"reason=Pulled count=1 msg=Container image ""busybox:musl"" already present on machine"
0.1724,Event,ADDED,eval-conflicts-rho010-r3-066-f6hgd.18d466a84ec6899f,reason=Created count=1 msg=Created container: task
0.1726,Event,ADDED,eval-conflicts-rho010-r3-066-f6hgd.18d466a853218978,reason=Started count=1 msg=Started container task
0.1729,Event,ADDED,eval-conflicts-rho010-r3-066.18d466a833701b64,reason=SuccessfulCreate count=1 msg=Created pod: eval-conflicts-rho010-r3-066-f6hgd
0.1731,Event,ADDED,eval-conflicts-rho010-r3-066.18d466ab92bdb6e9,reason=Completed count=1 msg=Job completed
0.1732,Event,ADDED,eval-conflicts-rho010-r3-067-mxfm5.18d466a86fb26f8e,reason=Scheduled count=None msg=Successfully assigned compute/eval-conflicts-rho010-r3-067-mxfm5 to kind-worker5
0.1734,Event,ADDED,eval-conflicts-rho010-r3-067-mxfm5.18d466a888bb685e,"reason=Pulled count=1 msg=Container image ""busybox:musl"" already present on machine"
0.1736,Event,ADDED,eval-conflicts-rho010-r3-067-mxfm5.18d466a889cca634,reason=Created count=1 msg=Created container: task
0.1738,Event,ADDED,eval-conflicts-rho010-r3-067-mxfm5.18d466a88f2cf597,reason=Started count=1 msg=Started container task
0.174,Event,ADDED,eval-conflicts-rho010-r3-067.18d466a86f0b4409,reason=SuccessfulCreate count=1 msg=Created pod: eval-conflicts-rho010-r3-067-mxfm5
0.1742,Event,ADDED,eval-conflicts-rho010-r3-067.18d466abce739137,reason=Completed count=1 msg=Job completed
0.1743,Event,ADDED,eval-conflicts-rho010-r3-068-2h8r8.18d466a8abfe2d9a,reason=Scheduled count=None msg=Successfully assigned compute/eval-conflicts-rho010-r3-068-2h8r8 to kind-worker3
0.1745,Event,ADDED,eval-conflicts-rho010-r3-068-2h8r8.18d466a8c554bf47,"reason=Pulled count=1 msg=Container image ""busybox:musl"" already present on machine"
0.1747,Event,ADDED,eval-conflicts-rho010-r3-068-2h8r8.18d466a8c65f17c4,reason=Created count=1 msg=Created container: task
0.1748,Event,ADDED,eval-conflicts-rho010-r3-068-2h8r8.18d466a8c8847205,reason=Started count=1 msg=Started container task
0.175,Event,ADDED,eval-conflicts-rho010-r3-068.18d466a8ab11f2b9,reason=SuccessfulCreate count=1 msg=Created pod: eval-conflicts-rho010-r3-068-2h8r8
0.1752,Event,ADDED,eval-conflicts-rho010-r3-068.18d466abfdef036c,reason=Completed count=1 msg=Job completed
0.1754,Event,ADDED,eval-conflicts-rho010-r3-069-cfvsb.18d466a8e7431865,reason=Scheduled count=None msg=Successfully assigned compute/eval-conflicts-rho010-r3-069-cfvsb to kind-worker4
0.1757,Event,ADDED,eval-conflicts-rho010-r3-069-cfvsb.18d466a900fb9bdd,"reason=Pulled count=1 msg=Container image ""busybox:musl"" already present on machine"
0.1759,Event,ADDED,eval-conflicts-rho010-r3-069-cfvsb.18d466a90212b542,reason=Created count=1 msg=Created container: task
0.176,Event,ADDED,eval-conflicts-rho010-r3-069-cfvsb.18d466a9062d5915,reason=Started count=1 msg=Started container task
0.1762,Event,ADDED,eval-conflicts-rho010-r3-069.18d466a8e6554c96,reason=SuccessfulCreate count=1 msg=Created pod: eval-conflicts-rho010-r3-069-cfvsb
0.1764,Event,ADDED,eval-conflicts-rho010-r3-069.18d466ac18ffef95,reason=Completed count=1 msg=Job completed
0.1765,Event,ADDED,eval-conflicts-rho010-r3-070-q4wr7.18d466a92298a6ea,reason=Scheduled count=None msg=Successfully assigned compute/eval-conflicts-rho010-r3-070-q4wr7 to kind-worker4
0.1767,Event,ADDED,eval-conflicts-rho010-r3-070-q4wr7.18d466a93c1ff775,"reason=Pulled count=1 msg=Container image ""busybox:musl"" already present on machine"
0.1773,Event,ADDED,eval-conflicts-rho010-r3-070-q4wr7.18d466a93d3c4205,reason=Created count=1 msg=Created container: task
0.1779,Event,ADDED,eval-conflicts-rho010-r3-070-q4wr7.18d466a93f3a43fa,reason=Started count=1 msg=Started container task
0.1782,Event,ADDED,eval-conflicts-rho010-r3-070.18d466a921e98b02,reason=SuccessfulCreate count=1 msg=Created pod: eval-conflicts-rho010-r3-070-q4wr7
0.1792,Event,ADDED,eval-conflicts-rho010-r3-070.18d466ac54d016c8,reason=Completed count=1 msg=Job completed
0.1794,Event,ADDED,eval-conflicts-rho010-r3-071-jmvzv.18d466a95e9221c4,reason=Scheduled count=None msg=Successfully assigned compute/eval-conflicts-rho010-r3-071-jmvzv to kind-worker4
0.1796,Event,ADDED,eval-conflicts-rho010-r3-071-jmvzv.18d466a979798051,"reason=Pulled count=1 msg=Container image ""busybox:musl"" already present on machine"
0.1797,Event,ADDED,eval-conflicts-rho010-r3-071-jmvzv.18d466a97a8a65fd,reason=Created count=1 msg=Created container: task
0.1802,Event,ADDED,eval-conflicts-rho010-r3-071-jmvzv.18d466a97f0e2878,reason=Started count=1 msg=Started container task
0.1804,Event,ADDED,eval-conflicts-rho010-r3-071.18d466a95d994ace,reason=SuccessfulCreate count=1 msg=Created pod: eval-conflicts-rho010-r3-071-jmvzv
0.1806,Event,ADDED,eval-conflicts-rho010-r3-071.18d466ac91061125,reason=Completed count=1 msg=Job completed
0.1807,Event,ADDED,eval-conflicts-rho010-r3-072-27h97.18d466a99ab77010,reason=Scheduled count=None msg=Successfully assigned compute/eval-conflicts-rho010-r3-072-27h97 to kind-worker4
0.182,Node,MODIFIED,kind-worker,taints=0
0.1823,Event,ADDED,eval-conflicts-rho010-r3-072-27h97.18d466a9b3d7fc00,"reason=Pulled count=1 msg=Container image ""busybox:musl"" already present on machine"
0.1825,Event,ADDED,eval-conflicts-rho010-r3-072-27h97.18d466a9b521540f,reason=Created count=1 msg=Created container: task
0.1827,Event,ADDED,eval-conflicts-rho010-r3-072-27h97.18d466a9ba61d5f8,reason=Started count=1 msg=Started container task
0.1835,Event,ADDED,eval-conflicts-rho010-r3-072.18d466a999ec5b22,reason=SuccessfulCreate count=1 msg=Created pod: eval-conflicts-rho010-r3-072-27h97
0.1837,Event,ADDED,eval-conflicts-rho010-r3-072.18d466accd17eb0e,reason=Completed count=1 msg=Job completed
0.1839,Event,ADDED,eval-conflicts-rho010-r3-073-zk8j5.18d466a9d60b8cd0,reason=Scheduled count=None msg=Successfully assigned compute/eval-conflicts-rho010-r3-073-zk8j5 to kind-worker4
0.1841,Event,ADDED,eval-conflicts-rho010-r3-073-zk8j5.18d466a9ef6605eb,"reason=Pulled count=1 msg=Container image ""busybox:musl"" already present on machine"
0.1844,Event,ADDED,eval-conflicts-rho010-r3-073-zk8j5.18d466a9f0f81193,reason=Created count=1 msg=Created container: task
0.1846,Event,ADDED,eval-conflicts-rho010-r3-073-zk8j5.18d466a9f4596311,reason=Started count=1 msg=Started container task
0.185,Event,ADDED,eval-conflicts-rho010-r3-073.18d466a9d5395e39,reason=SuccessfulCreate count=1 msg=Created pod: eval-conflicts-rho010-r3-073-zk8j5
0.1852,Event,ADDED,eval-conflicts-rho010-r3-073.18d466ad08f6cc41,reason=Completed count=1 msg=Job completed
0.1853,Event,ADDED,eval-conflicts-rho010-r3-074-p497j.18d466aa114c9375,reason=Scheduled count=None msg=Successfully assigned compute/eval-conflicts-rho010-r3-074-p497j to kind-worker3
0.1857,Event,ADDED,eval-conflicts-rho010-r3-074-p497j.18d466aa2b6d0e80,"reason=Pulled count=1 msg=Container image ""busybox:musl"" already present on machine"
0.1859,Event,ADDED,eval-conflicts-rho010-r3-074-p497j.18d466aa2ce13ff0,reason=Created count=1 msg=Created container: task
0.1862,Event,ADDED,eval-conflicts-rho010-r3-074-p497j.18d466aa30aa3b17,reason=Started count=1 msg=Started container task
0.1864,Event,ADDED,eval-conflicts-rho010-r3-074.18d466aa1073812e,reason=SuccessfulCreate count=1 msg=Created pod: eval-conflicts-rho010-r3-074-p497j
0.1868,Event,ADDED,eval-conflicts-rho010-r3-074.18d466ad641ef89b,reason=Completed count=1 msg=Job completed
0.187,Event,ADDED,eval-conflicts-rho010-r3-075-stnp9.18d466aa4dca7300,reason=Scheduled count=None msg=Successfully assigned compute/eval-conflicts-rho010-r3-075-stnp9 to kind-worker3
0.1872,Event,ADDED,eval-conflicts-rho010-r3-075-stnp9.18d466aa672bd476,"reason=Pulled count=1 msg=Container image ""busybox:musl"" already present on machine"
0.1873,Event,ADDED,eval-conflicts-rho010-r3-075-stnp9.18d466aa68b50da6,reason=Created count=1 msg=Created container: task
0.1877,Event,ADDED,eval-conflicts-rho010-r3-075-stnp9.18d466aa6d5f4673,reason=Started count=1 msg=Started container task
0.1878,Event,ADDED,eval-conflicts-rho010-r3-075.18d466aa4ca4682c,reason=SuccessfulCreate count=1 msg=Created pod: eval-conflicts-rho010-r3-075-stnp9
0.1881,Event,ADDED,eval-conflicts-rho010-r3-075.18d466ad9fef33b3,reason=Completed count=1 msg=Job completed
0.1883,Event,ADDED,eval-conflicts-rho010-r3-076-99fpd.18d466aa88804e29,"reason=FailedScheduling count=None msg=0/6 nodes are available: 2 c_wall violated: 1 conflicting context pair(s) with node memory, 4 node(s) had untolerated taint(s). no new claims to deallocate, preemption: 0/6 nodes are available: 2 No preemption victims found for incoming pod, 4 Preemption is not helpful for scheduling."
0.1885,Event,ADDED,eval-conflicts-rho010-r3-076-99fpd.18d466aa8917bfb7,"reason=FailedScheduling count=None msg=0/6 nodes are available: 2 c_wall violated: 1 conflicting context pair(s) with node memory, 4 node(s) had untolerated taint(s). no new claims to deallocate, preemption: 0/6 nodes are available: 2 No preemption victims found for incoming pod, 4 Preemption is not helpful for scheduling."
0.1887,Event,ADDED,eval-conflicts-rho010-r3-076-99fpd.18d466aa9b134588,reason=Scheduled count=None msg=Successfully assigned compute/eval-conflicts-rho010-r3-076-99fpd to kind-worker
0.189,Event,ADDED,eval-conflicts-rho010-r3-076-99fpd.18d466aab3b8ff9c,"reason=Pulled count=1 msg=Container image ""busybox:musl"" already present on machine"
0.1892,Event,ADDED,eval-conflicts-rho010-r3-076-99fpd.18d466aab4d37b32,reason=Created count=1 msg=Created container: task
0.1894,Event,ADDED,eval-conflicts-rho010-r3-076-99fpd.18d466aab6eecec7,reason=Started count=1 msg=Started container task
0.1895,Event,ADDED,eval-conflicts-rho010-r3-076.18d466aa880acd9c,reason=SuccessfulCreate count=1 msg=Created pod: eval-conflicts-rho010-r3-076-99fpd
0.1898,Event,ADDED,eval-conflicts-rho010-r3-076.18d466addeed524f,reason=Completed count=1 msg=Job completed
0.1899,Event,ADDED,eval-conflicts-rho010-r3-077-snpmx.18d466aac4111fac,reason=Scheduled count=None msg=Successfully assigned compute/eval-conflicts-rho010-r3-077-snpmx to kind-worker4
0.1901,Event,ADDED,eval-conflicts-rho010-r3-077-snpmx.18d466aadd27e0e3,"reason=Pulled count=1 msg=Container image ""busybox:musl"" already present on machine"
0.1903,Event,ADDED,eval-conflicts-rho010-r3-077-snpmx.18d466aade595d06,reason=Created count=1 msg=Created container: task
0.1905,Event,ADDED,eval-conflicts-rho010-r3-077-snpmx.18d466aae86121ea,reason=Started count=1 msg=Started container task
0.1906,Event,ADDED,eval-conflicts-rho010-r3-077.18d466aac321e433,reason=SuccessfulCreate count=1 msg=Created pod: eval-conflicts-rho010-r3-077-snpmx
0.1911,Event,ADDED,eval-conflicts-rho010-r3-077.18d466adf7c50051,reason=Completed count=1 msg=Job completed
0.1913,Event,ADDED,eval-conflicts-rho010-r3-078-slb9t.18d466aaffac954e,reason=Scheduled count=None msg=Successfully assigned compute/eval-conflicts-rho010-r3-078-slb9t to kind-worker4
0.1914,Event,ADDED,eval-conflicts-rho010-r3-078-slb9t.18d466ab19169e64,"reason=Pulled count=1 msg=Container image ""busybox:musl"" already present on machine"
0.1916,Event,ADDED,eval-conflicts-rho010-r3-078-slb9t.18d466ab1a3b2241,reason=Created count=1 msg=Created container: task
0.1918,Event,ADDED,eval-conflicts-rho010-r3-078-slb9t.18d466ab216a51f9,reason=Started count=1 msg=Started container task
0.1922,Event,ADDED,eval-conflicts-rho010-r3-078.18d466aafeef7d4f,reason=SuccessfulCreate count=1 msg=Created pod: eval-conflicts-rho010-r3-078-slb9t
0.1924,Event,ADDED,eval-conflicts-rho010-r3-078.18d466ae33de1796,reason=Completed count=1 msg=Job completed
0.1925,Event,ADDED,eval-conflicts-rho010-r3-079-4pm7n.18d466ab3b49fa36,reason=Scheduled count=None msg=Successfully assigned compute/eval-conflicts-rho010-r3-079-4pm7n to kind-worker2
0.1927,Event,ADDED,eval-conflicts-rho010-r3-079-4pm7n.18d466ab5485237a,"reason=Pulled count=1 msg=Container image ""busybox:musl"" already present on machine"
0.1929,Event,ADDED,eval-conflicts-rho010-r3-079-4pm7n.18d466ab55998ee5,reason=Created count=1 msg=Created container: task
0.1931,Event,ADDED,eval-conflicts-rho010-r3-079-4pm7n.18d466ab5adfe53c,reason=Started count=1 msg=Started container task
0.1933,Event,ADDED,eval-conflicts-rho010-r3-079.18d466ab3acb4774,reason=SuccessfulCreate count=1 msg=Created pod: eval-conflicts-rho010-r3-079-4pm7n
0.1935,Event,ADDED,eval-conflicts-rho010-r3-079.18d466aea0a557a8,reason=Completed count=1 msg=Job completed
0.1937,Event,ADDED,eval-conflicts-rho010-r3-080-9gkgk.18d466ab77140b4f,reason=Scheduled count=None msg=Successfully assigned compute/eval-conflicts-rho010-r3-080-9gkgk to kind-worker5
0.1939,Event,ADDED,eval-conflicts-rho010-r3-080-9gkgk.18d466ab8fa558e4,"reason=Pulled count=1 msg=Container image ""busybox:musl"" already present on machine"
0.194,Event,ADDED,eval-conflicts-rho010-r3-080-9gkgk.18d466ab90d25e81,reason=Created count=1 msg=Created container: task
0.1943,Event,ADDED,eval-conflicts-rho010-r3-080-9gkgk.18d466ab92ff4126,reason=Started count=1 msg=Started container task
0.1945,Event,ADDED,eval-conflicts-rho010-r3-080.18d466ab75d8ace7,reason=SuccessfulCreate count=1 msg=Created pod: eval-conflicts-rho010-r3-080-9gkgk
0.1947,Event,ADDED,eval-conflicts-rho010-r3-080.18d466aeda4880c7,reason=Completed count=1 msg=Job completed
0.1951,Event,ADDED,eval-conflicts-rho010-r3-081-frdsl.18d466abb2d9e88d,reason=Scheduled count=None msg=Successfully assigned compute/eval-conflicts-rho010-r3-081-frdsl to kind-worker
0.1952,Event,ADDED,eval-conflicts-rho010-r3-081-frdsl.18d466abcbc61fbc,"reason=Pulled count=1 msg=Container image ""busybox:musl"" already present on machine"
0.1954,Event,ADDED,eval-conflicts-rho010-r3-081-frdsl.18d466abcce3c08e,reason=Created count=1 msg=Created container: task
0.1956,Event,ADDED,eval-conflicts-rho010-r3-081-frdsl.18d466abcef3e875,reason=Started count=1 msg=Started container task
0.1958,Event,ADDED,eval-conflicts-rho010-r3-081.18d466abb1b9c95e,reason=SuccessfulCreate count=1 msg=Created pod: eval-conflicts-rho010-r3-081-frdsl
0.1961,Event,ADDED,eval-conflicts-rho010-r3-081.18d466af0994dbe3,reason=Completed count=1 msg=Job completed
0.1963,Event,ADDED,eval-conflicts-rho010-r3-082-8fxpc.18d466abee33a620,reason=Scheduled count=None msg=Successfully assigned compute/eval-conflicts-rho010-r3-082-8fxpc to kind-worker2
0.1964,Event,ADDED,eval-conflicts-rho010-r3-082-8fxpc.18d466ac06f6fb30,"reason=Pulled count=1 msg=Container image ""busybox:musl"" already present on machine"
0.1967,Event,ADDED,eval-conflicts-rho010-r3-082-8fxpc.18d466ac0811dff7,reason=Created count=1 msg=Created container: task
0.1969,Event,ADDED,eval-conflicts-rho010-r3-082-8fxpc.18d466ac0b03163e,reason=Started count=1 msg=Started container task
0.1971,Event,ADDED,eval-conflicts-rho010-r3-082.18d466abed4ae386,reason=SuccessfulCreate count=1 msg=Created pod: eval-conflicts-rho010-r3-082-8fxpc
0.1973,Event,ADDED,eval-conflicts-rho010-r3-082.18d466af185142ed,reason=Completed count=1 msg=Job completed
0.1975,Event,ADDED,eval-conflicts-rho010-r3-083-qwmxl.18d466ac2a1845cb,reason=Scheduled count=None msg=Successfully assigned compute/eval-conflicts-rho010-r3-083-qwmxl to kind-worker5
0.1977,Event,ADDED,eval-conflicts-rho010-r3-083-qwmxl.18d466ac44a857cf,"reason=Pulled count=1 msg=Container image ""busybox:musl"" already present on machine"
0.1978,Event,ADDED,eval-conflicts-rho010-r3-083-qwmxl.18d466ac45cb267f,reason=Created count=1 msg=Created container: task
0.198,Event,ADDED,eval-conflicts-rho010-r3-083-qwmxl.18d466ac496f0785,reason=Started count=1 msg=Started container task
0.1982,Event,ADDED,eval-conflicts-rho010-r3-083.18d466ac28dcec9b,reason=SuccessfulCreate count=1 msg=Created pod: eval-conflicts-rho010-r3-083-qwmxl
0.1983,Event,ADDED,eval-conflicts-rho010-r3-083.18d466af8c0d16ae,reason=Completed count=1 msg=Job completed
0.1985,Event,ADDED,eval-conflicts-rho010-r3-084-klnc7.18d466ac660197b0,reason=Scheduled count=None msg=Successfully assigned compute/eval-conflicts-rho010-r3-084-klnc7 to kind-worker5
0.1987,Event,ADDED,eval-conflicts-rho010-r3-084-klnc7.18d466ac7e89496f,"reason=Pulled count=1 msg=Container image ""busybox:musl"" already present on machine"
0.1988,Event,ADDED,eval-conflicts-rho010-r3-084-klnc7.18d466ac7f8ede65,reason=Created count=1 msg=Created container: task
0.1991,Event,ADDED,eval-conflicts-rho010-r3-084-klnc7.18d466ac83a31107,reason=Started count=1 msg=Started container task
0.1993,Event,ADDED,eval-conflicts-rho010-r3-084.18d466ac64a731f7,reason=SuccessfulCreate count=1 msg=Created pod: eval-conflicts-rho010-r3-084-klnc7
0.1995,Event,ADDED,eval-conflicts-rho010-r3-084.18d466afc7fe8bc0,reason=Completed count=1 msg=Job completed
0.1997,Event,ADDED,eval-conflicts-rho010-r3-085-h8sn2.18d466aca212c0b4,reason=Scheduled count=None msg=Successfully assigned compute/eval-conflicts-rho010-r3-085-h8sn2 to kind-worker2
0.1998,Event,ADDED,eval-conflicts-rho010-r3-085-h8sn2.18d466acbc3a2e47,"reason=Pulled count=1 msg=Container image ""busybox:musl"" already present on machine"
0.2001,Event,ADDED,eval-conflicts-rho010-r3-085-h8sn2.18d466acbd71ba71,reason=Created count=1 msg=Created container: task
0.2003,Event,ADDED,eval-conflicts-rho010-r3-085-h8sn2.18d466acc1f0e805,reason=Started count=1 msg=Started container task
0.2005,Event,ADDED,eval-conflicts-rho010-r3-085.18d466aca0da34f7,reason=SuccessfulCreate count=1 msg=Created pod: eval-conflicts-rho010-r3-085-h8sn2
0.2007,Event,ADDED,eval-conflicts-rho010-r3-085.18d466b0077a8448,reason=Completed count=1 msg=Job completed
0.2009,Event,ADDED,eval-conflicts-rho010-r3-086-dh67j.18d466acdcfd31b2,reason=Scheduled count=None msg=Successfully assigned compute/eval-conflicts-rho010-r3-086-dh67j to kind-worker5
0.2011,Event,ADDED,eval-conflicts-rho010-r3-086-dh67j.18d466acf5f98d08,"reason=Pulled count=1 msg=Container image ""busybox:musl"" already present on machine"
0.2012,Event,ADDED,eval-conflicts-rho010-r3-086-dh67j.18d466acf72a68b5,reason=Created count=1 msg=Created container: task
0.2014,Event,ADDED,eval-conflicts-rho010-r3-086-dh67j.18d466acfaf8e995,reason=Started count=1 msg=Started container task
0.2038,Event,ADDED,eval-conflicts-rho010-r3-086.18d466acdbc9d920,reason=SuccessfulCreate count=1 msg=Created pod: eval-conflicts-rho010-r3-086-dh67j
0.2041,Event,ADDED,eval-conflicts-rho010-r3-086.18d466b03f09a85a,reason=Completed count=1 msg=Job completed
0.2043,Event,ADDED,eval-conflicts-rho010-r3-087-d6qkc.18d466ad18dd8c41,reason=Scheduled count=None msg=Successfully assigned compute/eval-conflicts-rho010-r3-087-d6qkc to kind-worker5
0.2045,Event,ADDED,eval-conflicts-rho010-r3-087-d6qkc.18d466ad319c1a76,"reason=Pulled count=1 msg=Container image ""busybox:musl"" already present on machine"
0.2047,Event,ADDED,eval-conflicts-rho010-r3-087-d6qkc.18d466ad32c7c633,reason=Created count=1 msg=Created container: task
0.2049,Event,ADDED,eval-conflicts-rho010-r3-087-d6qkc.18d466ad3734e419,reason=Started count=1 msg=Started container task
0.205,Event,ADDED,eval-conflicts-rho010-r3-087.18d466ad1838e49e,reason=SuccessfulCreate count=1 msg=Created pod: eval-conflicts-rho010-r3-087-d6qkc
0.2052,Event,ADDED,eval-conflicts-rho010-r3-087.18d466b07b0a9c24,reason=Completed count=1 msg=Job completed
0.2054,Event,ADDED,eval-conflicts-rho010-r3-088-gxpd6.18d466ad54037243,reason=Scheduled count=None msg=Successfully assigned compute/eval-conflicts-rho010-r3-088-gxpd6 to kind-worker2
0.2055,Event,ADDED,eval-conflicts-rho010-r3-088-gxpd6.18d466ad6e596112,"reason=Pulled count=1 msg=Container image ""busybox:musl"" already present on machine"
0.2061,Event,ADDED,eval-conflicts-rho010-r3-088-gxpd6.18d466ad702996d7,reason=Created count=1 msg=Created container: task
0.2065,Event,ADDED,eval-conflicts-rho010-r3-088-gxpd6.18d466ad7548aab1,reason=Started count=1 msg=Started container task
0.2067,Event,ADDED,eval-conflicts-rho010-r3-088.18d466ad531b53ff,reason=SuccessfulCreate count=1 msg=Created pod: eval-conflicts-rho010-r3-088-gxpd6
0.2068,Event,ADDED,eval-conflicts-rho010-r3-088.18d466b0baddc715,reason=Completed count=1 msg=Job completed
0.2071,Event,ADDED,eval-conflicts-rho010-r3-089-r4smx.18d466ad8f4bb159,reason=Scheduled count=None msg=Successfully assigned compute/eval-conflicts-rho010-r3-089-r4smx to kind-worker5
0.2073,Event,ADDED,eval-conflicts-rho010-r3-089-r4smx.18d466adac167bf2,"reason=Pulled count=1 msg=Container image ""busybox:musl"" already present on machine"
0.2075,Event,ADDED,eval-conflicts-rho010-r3-089-r4smx.18d466adad389375,reason=Created count=1 msg=Created container: task
0.2078,Event,ADDED,eval-conflicts-rho010-r3-089-r4smx.18d466adb400aa46,reason=Started count=1 msg=Started container task
0.2081,Event,ADDED,eval-conflicts-rho010-r3-089.18d466ad8e4a56a7,reason=SuccessfulCreate count=1 msg=Created pod: eval-conflicts-rho010-r3-089-r4smx
0.2083,Event,ADDED,eval-conflicts-rho010-r3-089.18d466b0f2ed0c11,reason=Completed count=1 msg=Job completed
0.2084,Event,ADDED,eval-conflicts-rho010-r3-090-7l9ch.18d466adcad04c52,reason=Scheduled count=None msg=Successfully assigned compute/eval-conflicts-rho010-r3-090-7l9ch to kind-worker3
0.2088,Event,ADDED,eval-conflicts-rho010-r3-090-7l9ch.18d466ade534197c,"reason=Pulled count=1 msg=Container image ""busybox:musl"" already present on machine"
0.209,Event,ADDED,eval-conflicts-rho010-r3-090-7l9ch.18d466ade65823e5,reason=Created count=1 msg=Created container: task
0.2092,Event,ADDED,eval-conflicts-rho010-r3-090-7l9ch.18d466adec240a22,reason=Started count=1 msg=Started container task
0.2095,Event,ADDED,eval-conflicts-rho010-r3-090.18d466adca635335,reason=SuccessfulCreate count=1 msg=Created pod: eval-conflicts-rho010-r3-090-7l9ch
0.2096,Event,ADDED,eval-conflicts-rho010-r3-090.18d466b0e5236190,reason=Completed count=1 msg=Job completed
0.2098,Event,ADDED,eval-conflicts-rho010-r3-091-9nmcb.18d466ae082ac906,reason=Scheduled count=None msg=Successfully assigned compute/eval-conflicts-rho010-r3-091-9nmcb to kind-worker3
0.21,Event,ADDED,eval-conflicts-rho010-r3-091-9nmcb.18d466ae20e1e838,"reason=Pulled count=1 msg=Container image ""busybox:musl"" already present on machine"
0.2102,Event,ADDED,eval-conflicts-rho010-r3-091-9nmcb.18d466ae21e6ebe9,reason=Created count=1 msg=Created container: task
0.2103,Event,ADDED,eval-conflicts-rho010-r3-091-9nmcb.18d466ae25d2578a,reason=Started count=1 msg=Started container task
0.2105,Event,ADDED,eval-conflicts-rho010-r3-091.18d466ae07baf554,reason=SuccessfulCreate count=1 msg=Created pod: eval-conflicts-rho010-r3-091-9nmcb
0.2107,Event,ADDED,eval-conflicts-rho010-r3-091.18d466b15ca5115d,reason=Completed count=1 msg=Job completed
0.2109,Event,ADDED,eval-conflicts-rho010-r3-092-k74l6.18d466ae418c462b,reason=Scheduled count=None msg=Successfully assigned compute/eval-conflicts-rho010-r3-092-k74l6 to kind-worker3
0.2111,Event,ADDED,eval-conflicts-rho010-r3-092-k74l6.18d466ae5a2b0b59,"reason=Pulled count=1 msg=Container image ""busybox:musl"" already present on machine"
0.2114,Event,ADDED,eval-conflicts-rho010-r3-092-k74l6.18d466ae5b473827,reason=Created count=1 msg=Created container: task
0.2117,Event,ADDED,eval-conflicts-rho010-r3-092-k74l6.18d466ae5fb96d0b,reason=Started count=1 msg=Started container task
0.2118,Event,ADDED,eval-conflicts-rho010-r3-092.18d466ae412194a9,reason=SuccessfulCreate count=1 msg=Created pod: eval-conflicts-rho010-r3-092-k74l6
0.2121,Event,ADDED,eval-conflicts-rho010-r3-092.18d466b198a6d4ef,reason=Completed count=1 msg=Job completed
0.2123,Event,ADDED,eval-conflicts-rho010-r3-093-vfftc.18d466ae7d75c56a,reason=Scheduled count=None msg=Successfully assigned compute/eval-conflicts-rho010-r3-093-vfftc to kind-worker3
0.2127,Event,ADDED,eval-conflicts-rho010-r3-093-vfftc.18d466ae96575481,"reason=Pulled count=1 msg=Container image ""busybox:musl"" already present on machine"
0.2129,Event,ADDED,eval-conflicts-rho010-r3-093-vfftc.18d466ae976dbc5f,reason=Created count=1 msg=Created container: task
0.213,Event,ADDED,eval-conflicts-rho010-r3-093-vfftc.18d466ae995dcc10,reason=Started count=1 msg=Started container task
0.2132,Event,ADDED,eval-conflicts-rho010-r3-093.18d466ae7ceb1349,reason=SuccessfulCreate count=1 msg=Created pod: eval-conflicts-rho010-r3-093-vfftc
0.2135,Event,ADDED,eval-conflicts-rho010-r3-093.18d466b1d4532a38,reason=Completed count=1 msg=Job completed
0.2137,Event,ADDED,eval-conflicts-rho010-r3-094-9rvwr.18d466aeb91d7c33,reason=Scheduled count=None msg=Successfully assigned compute/eval-conflicts-rho010-r3-094-9rvwr to kind-worker3
0.2139,Event,ADDED,eval-conflicts-rho010-r3-094-9rvwr.18d466aed1c00f5a,"reason=Pulled count=1 msg=Container image ""busybox:musl"" already present on machine"
0.2142,Event,ADDED,eval-conflicts-rho010-r3-094-9rvwr.18d466aed2d632db,reason=Created count=1 msg=Created container: task
0.2144,Event,ADDED,eval-conflicts-rho010-r3-094-9rvwr.18d466aed4ce7ddf,reason=Started count=1 msg=Started container task
0.2146,Event,ADDED,eval-conflicts-rho010-r3-094.18d466aeb86b1095,reason=SuccessfulCreate count=1 msg=Created pod: eval-conflicts-rho010-r3-094-9rvwr
0.2147,Event,ADDED,eval-conflicts-rho010-r3-094.18d466b2108180c7,reason=Completed count=1 msg=Job completed
0.215,Event,ADDED,eval-conflicts-rho010-r3-095-x9qt2.18d466aef4a2c36e,reason=Scheduled count=None msg=Successfully assigned compute/eval-conflicts-rho010-r3-095-x9qt2 to kind-worker3
0.2151,Event,ADDED,eval-conflicts-rho010-r3-095-x9qt2.18d466af0de886b5,"reason=Pulled count=1 msg=Container image ""busybox:musl"" already present on machine"
0.2153,Event,ADDED,eval-conflicts-rho010-r3-095-x9qt2.18d466af0ef5f8b7,reason=Created count=1 msg=Created container: task
0.2155,Event,ADDED,eval-conflicts-rho010-r3-095-x9qt2.18d466af1111d05a,reason=Started count=1 msg=Started container task
0.2156,Event,ADDED,eval-conflicts-rho010-r3-095.18d466aef417f662,reason=SuccessfulCreate count=1 msg=Created pod: eval-conflicts-rho010-r3-095-x9qt2
0.2158,Event,ADDED,eval-conflicts-rho010-r3-095.18d466b24c3b8dba,reason=Completed count=1 msg=Job completed
0.216,Event,ADDED,eval-conflicts-rho010-r3-096-25tc5.18d466af3073e5bb,reason=Scheduled count=None msg=Successfully assigned compute/eval-conflicts-rho010-r3-096-25tc5 to kind-worker3
0.2162,Event,ADDED,eval-conflicts-rho010-r3-096-25tc5.18d466af499df652,"reason=Pulled count=1 msg=Container image ""busybox:musl"" already present on machine"
0.2164,Event,ADDED,eval-conflicts-rho010-r3-096-25tc5.18d466af4abe6bb7,reason=Created count=1 msg=Created container: task
0.2166,Event,ADDED,eval-conflicts-rho010-r3-096-25tc5.18d466af4d0fed10,reason=Started count=1 msg=Started container task
0.2168,Event,ADDED,eval-conflicts-rho010-r3-096.18d466af2fd721db,reason=SuccessfulCreate count=1 msg=Created pod: eval-conflicts-rho010-r3-096-25tc5
0.2171,Event,ADDED,eval-conflicts-rho010-r3-096.18d466b2884df5c4,reason=Completed count=1 msg=Job completed
0.2173,Event,ADDED,eval-conflicts-rho010-r3-097-zxg7v.18d466af6ce69000,reason=Scheduled count=None msg=Successfully assigned compute/eval-conflicts-rho010-r3-097-zxg7v to kind-worker
0.2175,Event,ADDED,eval-conflicts-rho010-r3-097-zxg7v.18d466af853c2c61,"reason=Pulled count=1 msg=Container image ""busybox:musl"" already present on machine"
0.2179,Event,ADDED,eval-conflicts-rho010-r3-097-zxg7v.18d466af864c67a4,reason=Created count=1 msg=Created container: task
0.2181,Event,ADDED,eval-conflicts-rho010-r3-097-zxg7v.18d466af8835bf5c,reason=Started count=1 msg=Started container task
0.2183,Event,ADDED,eval-conflicts-rho010-r3-097.18d466af6be4ad0c,reason=SuccessfulCreate count=1 msg=Created pod: eval-conflicts-rho010-r3-097-zxg7v
0.2185,Event,ADDED,eval-conflicts-rho010-r3-097.18d466b28a859ede,reason=Completed count=1 msg=Job completed
0.2187,Event,ADDED,eval-conflicts-rho010-r3-098-8zs7d.18d466afa737e7c0,reason=Scheduled count=None msg=Successfully assigned compute/eval-conflicts-rho010-r3-098-8zs7d to kind-worker
0.2189,Event,ADDED,eval-conflicts-rho010-r3-098-8zs7d.18d466afc06a419b,"reason=Pulled count=1 msg=Container image ""busybox:musl"" already present on machine"
0.2191,Event,ADDED,eval-conflicts-rho010-r3-098-8zs7d.18d466afc176f75d,reason=Created count=1 msg=Created container: task
0.2197,Event,ADDED,eval-conflicts-rho010-r3-098-8zs7d.18d466afc355897c,reason=Started count=1 msg=Started container task
0.2201,Event,ADDED,eval-conflicts-rho010-r3-098.18d466afa6be835b,reason=SuccessfulCreate count=1 msg=Created pod: eval-conflicts-rho010-r3-098-8zs7d
0.2204,Event,ADDED,eval-conflicts-rho010-r3-098.18d466b301dd838c,reason=Completed count=1 msg=Job completed
0.2207,Event,ADDED,eval-conflicts-rho010-r3-099-l9lvt.18d466afe305f493,reason=Scheduled count=None msg=Successfully assigned compute/eval-conflicts-rho010-r3-099-l9lvt to kind-worker
0.221,Event,ADDED,eval-conflicts-rho010-r3-099-l9lvt.18d466affc07fc67,"reason=Pulled count=1 msg=Container image ""busybox:musl"" already present on machine"
0.2211,Event,ADDED,eval-conflicts-rho010-r3-099-l9lvt.18d466affd208e38,reason=Created count=1 msg=Created container: task
0.2213,Event,ADDED,eval-conflicts-rho010-r3-099-l9lvt.18d466b001350b66,reason=Started count=1 msg=Started container task
0.2215,Event,ADDED,eval-conflicts-rho010-r3-099.18d466afe24fc834,reason=SuccessfulCreate count=1 msg=Created pod: eval-conflicts-rho010-r3-099-l9lvt
0.2218,Event,ADDED,eval-conflicts-rho010-r3-099.18d466b33db6ef45,reason=Completed count=1 msg=Job completed
0.222,Event,ADDED,eval-conflicts-rho010-r4-000-vcpkp.18d466b865177534,reason=Scheduled count=None msg=Successfully assigned compute/eval-conflicts-rho010-r4-000-vcpkp to kind-worker2
0.2221,Event,ADDED,eval-conflicts-rho010-r4-000-vcpkp.18d466b87e34f133,"reason=Pulled count=1 msg=Container image ""busybox:musl"" already present on machine"
0.2224,Event,ADDED,eval-conflicts-rho010-r4-000-vcpkp.18d466b87f47c928,reason=Created count=1 msg=Created container: task
0.2226,Event,ADDED,eval-conflicts-rho010-r4-000-vcpkp.18d466b8819192c8,reason=Started count=1 msg=Started container task
0.2227,Event,ADDED,eval-conflicts-rho010-r4-000.18d466b864345855,reason=SuccessfulCreate count=1 msg=Created pod: eval-conflicts-rho010-r4-000-vcpkp
0.2229,Event,ADDED,eval-conflicts-rho010-r4-000.18d466bbb32a2f4e,reason=Completed count=1 msg=Job completed
0.2231,Event,ADDED,eval-conflicts-rho010-r4-001-rtggb.18d466b89f3b69fe,reason=Scheduled count=None msg=Successfully assigned compute/eval-conflicts-rho010-r4-001-rtggb to kind-worker
0.2232,Event,ADDED,eval-conflicts-rho010-r4-001-rtggb.18d466b8b7aabd7a,"reason=Pulled count=1 msg=Container image ""busybox:musl"" already present on machine"
0.2234,Event,ADDED,eval-conflicts-rho010-r4-001-rtggb.18d466b8b8caaf01,reason=Created count=1 msg=Created container: task
0.2236,Event,ADDED,eval-conflicts-rho010-r4-001-rtggb.18d466b8bc86792a,reason=Started count=1 msg=Started container task
0.2237,Event,ADDED,eval-conflicts-rho010-r4-001.18d466b89e30688b,reason=SuccessfulCreate count=1 msg=Created pod: eval-conflicts-rho010-r4-001-rtggb
0.2239,Event,ADDED,eval-conflicts-rho010-r4-001.18d466bba47c889f,reason=Completed count=1 msg=Job completed
0.2241,Event,ADDED,eval-conflicts-rho010-r4-002-7z68v.18d466b8db4293b0,reason=Scheduled count=None msg=Successfully assigned compute/eval-conflicts-rho010-r4-002-7z68v to kind-worker5
0.2244,Event,ADDED,eval-conflicts-rho010-r4-002-7z68v.18d466b8f45cb681,"reason=Pulled count=1 msg=Container image ""busybox:musl"" already present on machine"
0.2246,Event,ADDED,eval-conflicts-rho010-r4-002-7z68v.18d466b8f56c7d60,reason=Created count=1 msg=Created container: task
0.2248,Event,ADDED,eval-conflicts-rho010-r4-002-7z68v.18d466b8f8b17746,reason=Started count=1 msg=Started container task
0.225,Event,ADDED,eval-conflicts-rho010-r4-002.18d466b8da9a1e38,reason=SuccessfulCreate count=1 msg=Created pod: eval-conflicts-rho010-r4-002-7z68v
0.2253,Event,ADDED,eval-conflicts-rho010-r4-002.18d466bc27728ec3,reason=Completed count=1 msg=Job completed
0.2255,Event,ADDED,eval-conflicts-rho010-r4-003-vg5zs.18d466b916671192,reason=Scheduled count=None msg=Successfully assigned compute/eval-conflicts-rho010-r4-003-vg5zs to kind-worker5
0.2257,Event,ADDED,eval-conflicts-rho010-r4-003-vg5zs.18d466b930288230,"reason=Pulled count=1 msg=Container image ""busybox:musl"" already present on machine"
0.2259,Event,ADDED,eval-conflicts-rho010-r4-003-vg5zs.18d466b93149a9e9,reason=Created count=1 msg=Created container: task
0.2262,Event,ADDED,eval-conflicts-rho010-r4-003-vg5zs.18d466b93361d8c6,reason=Started count=1 msg=Started container task
0.2264,Event,ADDED,eval-conflicts-rho010-r4-003.18d466b91572320b,reason=SuccessfulCreate count=1 msg=Created pod: eval-conflicts-rho010-r4-003-vg5zs
0.2266,Event,ADDED,eval-conflicts-rho010-r4-003.18d466bc62eb864c,reason=Completed count=1 msg=Job completed
0.2269,Event,ADDED,eval-conflicts-rho010-r4-004-xrs9h.18d466b951d5fe99,reason=Scheduled count=None msg=Successfully assigned compute/eval-conflicts-rho010-r4-004-xrs9h to kind-worker5
0.227,Event,ADDED,eval-conflicts-rho010-r4-004-xrs9h.18d466b96a442579,"reason=Pulled count=1 msg=Container image ""busybox:musl"" already present on machine"
0.2272,Event,ADDED,eval-conflicts-rho010-r4-004-xrs9h.18d466b96b4bda73,reason=Created count=1 msg=Created container: task
0.2274,Event,ADDED,eval-conflicts-rho010-r4-004-xrs9h.18d466b96ec6c7f1,reason=Started count=1 msg=Started container task
0.2276,Event,ADDED,eval-conflicts-rho010-r4-004.18d466b95121503e,reason=SuccessfulCreate count=1 msg=Created pod: eval-conflicts-rho010-r4-004-xrs9h
0.2278,Event,ADDED,eval-conflicts-rho010-r4-004.18d466bc9ea2ba19,reason=Completed count=1 msg=Job completed
0.228,Event,ADDED,eval-conflicts-rho010-r4-005-wvlxt.18d466b98dbf0df0,reason=Scheduled count=None msg=Successfully assigned compute/eval-conflicts-rho010-r4-005-wvlxt to kind-worker5
0.2283,Event,ADDED,eval-conflicts-rho010-r4-005-wvlxt.18d466b9a603d0bf,"reason=Pulled count=1 msg=Container image ""busybox:musl"" already present on machine"
0.2285,Event,ADDED,eval-conflicts-rho010-r4-005-wvlxt.18d466b9a70f9707,reason=Created count=1 msg=Created container: task
0.2286,Event,ADDED,eval-conflicts-rho010-r4-005-wvlxt.18d466b9a92318e6,reason=Started count=1 msg=Started container task
0.2288,Event,ADDED,eval-conflicts-rho010-r4-005.18d466b98cfcfbe4,reason=SuccessfulCreate count=1 msg=Created pod: eval-conflicts-rho010-r4-005-wvlxt
0.229,Event,ADDED,eval-conflicts-rho010-r4-005.18d466bcda78670b,reason=Completed count=1 msg=Job completed
0.2292,Event,ADDED,eval-conflicts-rho010-r4-006-sdjdk.18d466b9c88ca5a0,reason=Scheduled count=None msg=Successfully assigned compute/eval-conflicts-rho010-r4-006-sdjdk to kind-worker4
0.2293,Event,ADDED,eval-conflicts-rho010-r4-006-sdjdk.18d466b9e23e8b66,"reason=Pulled count=1 msg=Container image ""busybox:musl"" already present on machine"
0.2296,Event,ADDED,eval-conflicts-rho010-r4-006-sdjdk.18d466b9e3c20c33,reason=Created count=1 msg=Created container: task
0.2298,Event,ADDED,eval-conflicts-rho010-r4-006-sdjdk.18d466b9e5c787c5,reason=Started count=1 msg=Started container task
0.2299,Event,ADDED,eval-conflicts-rho010-r4-006.18d466b9c7f1776a,reason=SuccessfulCreate count=1 msg=Created pod: eval-conflicts-rho010-r4-006-sdjdk
0.2301,Event,ADDED,eval-conflicts-rho010-r4-006.18d466bd22a3c231,reason=Completed count=1 msg=Job completed
0.2303,Event,ADDED,eval-conflicts-rho010-r4-007-ndf8w.18d466ba045eb897,reason=Scheduled count=None msg=Successfully assigned compute/eval-conflicts-rho010-r4-007-ndf8w to kind-worker4
0.2304,Event,ADDED,eval-conflicts-rho010-r4-007-ndf8w.18d466ba1df65adb,"reason=Pulled count=1 msg=Container image ""busybox:musl"" already present on machine"
0.2306,Event,ADDED,eval-conflicts-rho010-r4-007-ndf8w.18d466ba1f1bf409,reason=Created count=1 msg=Created container: task
0.2308,Event,ADDED,eval-conflicts-rho010-r4-007-ndf8w.18d466ba214734b1,reason=Started count=1 msg=Started container task
0.231,Event,ADDED,eval-conflicts-rho010-r4-007.18d466ba038c2a1e,reason=SuccessfulCreate count=1 msg=Created pod: eval-conflicts-rho010-r4-007-ndf8w
0.2312,Event,ADDED,eval-conflicts-rho010-r4-007.18d466bd5ea1dc8b,reason=Completed count=1 msg=Job completed
0.2313,Event,ADDED,eval-conflicts-rho010-r4-008-h9bnn.18d466ba3fa5bd81,reason=Scheduled count=None msg=Successfully assigned compute/eval-conflicts-rho010-r4-008-h9bnn to kind-worker3
0.2315,Event,ADDED,eval-conflicts-rho010-r4-008-h9bnn.18d466ba58e2a1c0,"reason=Pulled count=1 msg=Container image ""busybox:musl"" already present on machine"
0.2317,Event,ADDED,eval-conflicts-rho010-r4-008-h9bnn.18d466ba5a15b4db,reason=Created count=1 msg=Created container: task
0.2318,Event,ADDED,eval-conflicts-rho010-r4-008-h9bnn.18d466ba5dc3145b,reason=Started count=1 msg=Started container task
0.2321,Event,ADDED,eval-conflicts-rho010-r4-008.18d466ba3f024a81,reason=SuccessfulCreate count=1 msg=Created pod: eval-conflicts-rho010-r4-008-h9bnn
0.2324,Event,ADDED,eval-conflicts-rho010-r4-008.18d466bd7f865ca9,reason=Completed count=1 msg=Job completed
0.2325,Event,ADDED,eval-conflicts-rho010-r4-009-rsgsr.18d466ba7b8baa45,reason=Scheduled count=None msg=Successfully assigned compute/eval-conflicts-rho010-r4-009-rsgsr to kind-worker4
0.2327,Event,ADDED,eval-conflicts-rho010-r4-009-rsgsr.18d466ba94598788,"reason=Pulled count=1 msg=Container image ""busybox:musl"" already present on machine"
0.2329,Event,ADDED,eval-conflicts-rho010-r4-009-rsgsr.18d466ba9575f120,reason=Created count=1 msg=Created container: task
0.2332,Event,ADDED,eval-conflicts-rho010-r4-009-rsgsr.18d466ba97f3ae52,reason=Started count=1 msg=Started container task
0.2334,Event,ADDED,eval-conflicts-rho010-r4-009.18d466ba7a95b91f,reason=SuccessfulCreate count=1 msg=Created pod: eval-conflicts-rho010-r4-009-rsgsr
0.2336,Event,ADDED,eval-conflicts-rho010-r4-009.18d466bdd5e49c07,reason=Completed count=1 msg=Job completed
0.2338,Event,ADDED,eval-conflicts-rho010-r4-010-k9tnq.18d466bab6eb6370,reason=Scheduled count=None msg=Successfully assigned compute/eval-conflicts-rho010-r4-010-k9tnq to kind-worker3
0.234,Event,ADDED,eval-conflicts-rho010-r4-010-k9tnq.18d466bacfc898db,"reason=Pulled count=1 msg=Container image ""busybox:musl"" already present on machine"
0.2341,Event,ADDED,eval-conflicts-rho010-r4-010-k9tnq.18d466bad0e68a12,reason=Created count=1 msg=Created container: task
0.2343,Event,ADDED,eval-conflicts-rho010-r4-010-k9tnq.18d466bad36f65cd,reason=Started count=1 msg=Started container task
0.2345,Event,ADDED,eval-conflicts-rho010-r4-010.18d466bab640de8e,reason=SuccessfulCreate count=1 msg=Created pod: eval-conflicts-rho010-r4-010-k9tnq
0.2346,Event,ADDED,eval-conflicts-rho010-r4-010.18d466bdf77f4cbc,reason=Completed count=1 msg=Job completed
0.2348,Event,ADDED,eval-conflicts-rho010-r4-011-55cqs.18d466baf37e4e13,reason=Scheduled count=None msg=Successfully assigned compute/eval-conflicts-rho010-r4-011-55cqs to kind-worker4
0.2349,Event,ADDED,eval-conflicts-rho010-r4-011-55cqs.18d466bb0c80b97e,"reason=Pulled count=1 msg=Container image ""busybox:musl"" already present on machine"
0.2352,Event,ADDED,eval-conflicts-rho010-r4-011-55cqs.18d466bb0d9978d2,reason=Created count=1 msg=Created container: task
0.2354,Event,ADDED,eval-conflicts-rho010-r4-011-55cqs.18d466bb0fdaaeaf,reason=Started count=1 msg=Started container task
0.2356,Event,ADDED,eval-conflicts-rho010-r4-011.18d466baf28bfc87,reason=SuccessfulCreate count=1 msg=Created pod: eval-conflicts-rho010-r4-011-55cqs
0.2358,Event,ADDED,eval-conflicts-rho010-r4-011.18d466be4dfa1bb7,reason=Completed count=1 msg=Job completed
0.236,Event,ADDED,eval-conflicts-rho010-r4-012-gbm46.18d466bb2e5b5912,reason=Scheduled count=None msg=Successfully assigned compute/eval-conflicts-rho010-r4-012-gbm46 to kind-worker4
0.2362,Event,ADDED,eval-conflicts-rho010-r4-012-gbm46.18d466bb472c419f,"reason=Pulled count=1 msg=Container image ""busybox:musl"" already present on machine"
0.2364,Event,ADDED,eval-conflicts-rho010-r4-012-gbm46.18d466bb484c1ca0,reason=Created count=1 msg=Created container: task
0.2367,Event,ADDED,eval-conflicts-rho010-r4-012-gbm46.18d466bb4a46853d,reason=Started count=1 msg=Started container task
0.2369,Event,ADDED,eval-conflicts-rho010-r4-012.18d466bb2d7acc2a,reason=SuccessfulCreate count=1 msg=Created pod: eval-conflicts-rho010-r4-012-gbm46
0.2371,Event,ADDED,eval-conflicts-rho010-r4-012.18d466be89cabc72,reason=Completed count=1 msg=Job completed
0.2372,Event,ADDED,eval-conflicts-rho010-r4-013-nhzjr.18d466bb6ae1d17d,reason=Scheduled count=None msg=Successfully assigned compute/eval-conflicts-rho010-r4-013-nhzjr to kind-worker4
0.2375,Event,ADDED,eval-conflicts-rho010-r4-013-nhzjr.18d466bb866a9457,"reason=Pulled count=1 msg=Container image ""busybox:musl"" already present on machine"
0.2376,Event,ADDED,eval-conflicts-rho010-r4-013-nhzjr.18d466bb87b1af2f,reason=Created count=1 msg=Created container: task
0.2378,Event,ADDED,eval-conflicts-rho010-r4-013-nhzjr.18d466bb8efd06a6,reason=Started count=1 msg=Started container task
0.238,Event,ADDED,eval-conflicts-rho010-r4-013.18d466bb6a2e9a4f,reason=SuccessfulCreate count=1 msg=Created pod: eval-conflicts-rho010-r4-013-nhzjr
0.2381,Event,ADDED,eval-conflicts-rho010-r4-013.18d466bec5da8219,reason=Completed count=1 msg=Job completed
0.2383,Event,ADDED,eval-conflicts-rho010-r4-014-cmgz9.18d466bba530ab26,reason=Scheduled count=None msg=Successfully assigned compute/eval-conflicts-rho010-r4-014-cmgz9 to kind-worker2
0.2385,Event,ADDED,eval-conflicts-rho010-r4-014-cmgz9.18d466bbc30994a6,"reason=Pulled count=1 msg=Container image ""busybox:musl"" already present on machine"
0.2386,Event,ADDED,eval-conflicts-rho010-r4-014-cmgz9.18d466bbc49649ec,reason=Created count=1 msg=Created container: task
0.2388,Event,ADDED,eval-conflicts-rho010-r4-014-cmgz9.18d466bbc9e59992,reason=Started count=1 msg=Started container task
0.239,Event,ADDED,eval-conflicts-rho010-r4-014.18d466bba4c06ea5,reason=SuccessfulCreate count=1 msg=Created pod: eval-conflicts-rho010-r4-014-cmgz9
0.2392,Event,ADDED,eval-conflicts-rho010-r4-014.18d466bef7d12640,reason=Completed count=1 msg=Job completed
0.2394,Event,ADDED,eval-conflicts-rho010-r4-015-nbj5d.18d466bbe25f121c,reason=Scheduled count=None msg=Successfully assigned compute/eval-conflicts-rho010-r4-015-nbj5d to kind-worker2
0.2395,Event,ADDED,eval-conflicts-rho010-r4-015-nbj5d.18d466bbfb241dc5,"reason=Pulled count=1 msg=Container image ""busybox:musl"" already present on machine"
0.2397,Event,ADDED,eval-conflicts-rho010-r4-015-nbj5d.18d466bbfc33f643,reason=Created count=1 msg=Created container: task
0.2399,Event,ADDED,eval-conflicts-rho010-r4-015-nbj5d.18d466bbfe8f680e,reason=Started count=1 msg=Started container task
0.2402,Event,ADDED,eval-conflicts-rho010-r4-015.18d466bbe196e194,reason=SuccessfulCreate count=1 msg=Created pod: eval-conflicts-rho010-r4-015-nbj5d
0.2404,Event,ADDED,eval-conflicts-rho010-r4-015.18d466bf33d51260,reason=Completed count=1 msg=Job completed
0.2406,Event,ADDED,eval-conflicts-rho010-r4-016-59wmd.18d466bc1c539177,reason=Scheduled count=None msg=Successfully assigned compute/eval-conflicts-rho010-r4-016-59wmd to kind-worker2
0.2409,Event,ADDED,eval-conflicts-rho010-r4-016-59wmd.18d466bc35e5b09b,"reason=Pulled count=1 msg=Container image ""busybox:musl"" already present on machine"
0.2411,Event,ADDED,eval-conflicts-rho010-r4-016-59wmd.18d466bc370c1de6,reason=Created count=1 msg=Created container: task
0.2412,Event,ADDED,eval-conflicts-rho010-r4-016-59wmd.18d466bc3a80ec39,reason=Started count=1 msg=Started container task
0.2415,Event,ADDED,eval-conflicts-rho010-r4-016.18d466bc1bd7dfc0,reason=SuccessfulCreate count=1 msg=Created pod: eval-conflicts-rho010-r4-016-59wmd
0.2417,Event,ADDED,eval-conflicts-rho010-r4-016.18d466bf6fe68046,reason=Completed count=1 msg=Job completed
0.2419,Event,ADDED,eval-conflicts-rho010-r4-017-zsvqq.18d466bc582acdc7,reason=Scheduled count=None msg=Successfully assigned compute/eval-conflicts-rho010-r4-017-zsvqq to kind-worker2
0.242,Event,ADDED,eval-conflicts-rho010-r4-017-zsvqq.18d466bc713b2501,"reason=Pulled count=1 msg=Container image ""busybox:musl"" already present on machine"
0.2425,Event,ADDED,eval-conflicts-rho010-r4-017-zsvqq.18d466bc7255a45b,reason=Created count=1 msg=Created container: task
0.2429,Event,ADDED,eval-conflicts-rho010-r4-017-zsvqq.18d466bc747e0a9e,reason=Started count=1 msg=Started container task
0.2433,Event,ADDED,eval-conflicts-rho010-r4-017.18d466bc579d59e9,reason=SuccessfulCreate count=1 msg=Created pod: eval-conflicts-rho010-r4-017-zsvqq
0.2435,Event,ADDED,eval-conflicts-rho010-r4-017.18d466bf704d151b,reason=Completed count=1 msg=Job completed
0.2438,Event,ADDED,eval-conflicts-rho010-r4-018-dv4cp.18d466bc93e2364c,reason=Scheduled count=None msg=Successfully assigned compute/eval-conflicts-rho010-r4-018-dv4cp to kind-worker2
0.2441,Event,ADDED,eval-conflicts-rho010-r4-018-dv4cp.18d466bcacf1fe30,"reason=Pulled count=1 msg=Container image ""busybox:musl"" already present on machine"
0.2443,Event,ADDED,eval-conflicts-rho010-r4-018-dv4cp.18d466bcae2ea383,reason=Created count=1 msg=Created container: task
0.2446,Event,ADDED,eval-conflicts-rho010-r4-018-dv4cp.18d466bcb027f5ee,reason=Started count=1 msg=Started container task
0.2448,Event,ADDED,eval-conflicts-rho010-r4-018.18d466bc935b3ac5,reason=SuccessfulCreate count=1 msg=Created pod: eval-conflicts-rho010-r4-018-dv4cp
0.245,Event,ADDED,eval-conflicts-rho010-r4-018.18d466bfe88780b9,reason=Completed count=1 msg=Job completed
0.2451,Event,ADDED,eval-conflicts-rho010-r4-019-pzxrw.18d466bccf0fa09b,reason=Scheduled count=None msg=Successfully assigned compute/eval-conflicts-rho010-r4-019-pzxrw to kind-worker2
0.2454,Event,ADDED,eval-conflicts-rho010-r4-019-pzxrw.18d466bceea0dde0,"reason=Pulled count=1 msg=Container image ""busybox:musl"" already present on machine"
0.2455,Event,ADDED,eval-conflicts-rho010-r4-019-pzxrw.18d466bcefc6c540,reason=Created count=1 msg=Created container: task
0.2457,Event,ADDED,eval-conflicts-rho010-r4-019-pzxrw.18d466bcf38d013c,reason=Started count=1 msg=Started container task
0.2459,Event,ADDED,eval-conflicts-rho010-r4-019.18d466bcce9e435a,reason=SuccessfulCreate count=1 msg=Created pod: eval-conflicts-rho010-r4-019-pzxrw
0.246,Event,ADDED,eval-conflicts-rho010-r4-019.18d466c02499680a,reason=Completed count=1 msg=Job completed
0.2462,Event,ADDED,eval-conflicts-rho010-r4-020-sb77t.18d466bd0ac7c7a0,reason=Scheduled count=None msg=Successfully assigned compute/eval-conflicts-rho010-r4-020-sb77t to kind-worker2
0.2463,Event,ADDED,eval-conflicts-rho010-r4-020-sb77t.18d466bd2589444d,"reason=Pulled count=1 msg=Container image ""busybox:musl"" already present on machine"
0.2465,Event,ADDED,eval-conflicts-rho010-r4-020-sb77t.18d466bd2700a086,reason=Created count=1 msg=Created container: task
0.2467,Event,ADDED,eval-conflicts-rho010-r4-020-sb77t.18d466bd2fe72c33,reason=Started count=1 msg=Started container task
0.2468,Event,ADDED,eval-conflicts-rho010-r4-020.18d466bd0a1c1d8c,reason=SuccessfulCreate count=1 msg=Created pod: eval-conflicts-rho010-r4-020-sb77t
0.2471,Event,ADDED,eval-conflicts-rho010-r4-020.18d466c0603b7e98,reason=Completed count=1 msg=Job completed
0.2473,Event,ADDED,eval-conflicts-rho010-r4-021-xqpsn.18d466bd463a761e,"reason=FailedScheduling count=None msg=0/6 nodes are available: 1 c_wall violated: 1 conflicting context pair(s) with node memory, 5 node(s) had untolerated taint(s). no new claims to deallocate, preemption: 0/6 nodes are available: 1 No preemption victims found for incoming pod, 5 Preemption is not helpful for scheduling."
0.2475,Event,ADDED,eval-conflicts-rho010-r4-021-xqpsn.18d466bd46d8ddcc,"reason=FailedScheduling count=None msg=0/6 nodes are available: 1 c_wall violated: 1 conflicting context pair(s) with node memory, 5 node(s) had untolerated taint(s). no new claims to deallocate, preemption: 0/6 nodes are available: 1 No preemption victims found for incoming pod, 5 Preemption is not helpful for scheduling."
0.2477,Event,ADDED,eval-conflicts-rho010-r4-021-xqpsn.18d466bd7a4ddb16,reason=Scheduled count=None msg=Successfully assigned compute/eval-conflicts-rho010-r4-021-xqpsn to kind-worker
0.2479,Event,ADDED,eval-conflicts-rho010-r4-021-xqpsn.18d466bd9309a4af,"reason=Pulled count=1 msg=Container image ""busybox:musl"" already present on machine"
0.2481,Event,ADDED,eval-conflicts-rho010-r4-021-xqpsn.18d466bd9414b2f5,reason=Created count=1 msg=Created container: task
0.2483,Event,ADDED,eval-conflicts-rho010-r4-021-xqpsn.18d466bd95e5a67e,reason=Started count=1 msg=Started container task
0.2486,Event,ADDED,eval-conflicts-rho010-r4-021.18d466bd45f8dc9b,reason=SuccessfulCreate count=1 msg=Created pod: eval-conflicts-rho010-r4-021-xqpsn
0.2487,Event,ADDED,eval-conflicts-rho010-r4-021.18d466c08c36b388,reason=Completed count=1 msg=Job completed
0.2489,Event,ADDED,eval-conflicts-rho010-r4-022-clmdt.18d466bd82ee6d3e,reason=Scheduled count=None msg=Successfully assigned compute/eval-conflicts-rho010-r4-022-clmdt to kind-worker
0.2491,Event,ADDED,eval-conflicts-rho010-r4-022-clmdt.18d466bd9c49f7cf,"reason=Pulled count=1 msg=Container image ""busybox:musl"" already present on machine"
0.2493,Event,ADDED,eval-conflicts-rho010-r4-022-clmdt.18d466bd9d68b6c4,reason=Created count=1 msg=Created container: task
0.2494,Event,ADDED,eval-conflicts-rho010-r4-022-clmdt.18d466bda0a35bcf,reason=Started count=1 msg=Started container task
0.2496,Event,ADDED,eval-conflicts-rho010-r4-022.18d466bd821fe92e,reason=SuccessfulCreate count=1 msg=Created pod: eval-conflicts-rho010-r4-022-clmdt
0.2498,Event,ADDED,eval-conflicts-rho010-r4-022.18d466c08c546332,reason=Completed count=1 msg=Job completed
0.2499,Event,ADDED,eval-conflicts-rho010-r4-023-zr2zf.18d466bdbe3d09eb,reason=Scheduled count=None msg=Successfully assigned compute/eval-conflicts-rho010-r4-023-zr2zf to kind-worker
0.2502,Event,ADDED,eval-conflicts-rho010-r4-023-zr2zf.18d466bdd79f413a,"reason=Pulled count=1 msg=Container image ""busybox:musl"" already present on machine"
0.2504,Event,ADDED,eval-conflicts-rho010-r4-023-zr2zf.18d466bdd8b429cc,reason=Created count=1 msg=Created container: task
0.2505,Event,ADDED,eval-conflicts-rho010-r4-023-zr2zf.18d466bddbf70760,reason=Started count=1 msg=Started container task
0.2507,Event,ADDED,eval-conflicts-rho010-r4-023.18d466bdbcf6be43,reason=SuccessfulCreate count=1 msg=Created pod: eval-conflicts-rho010-r4-023-zr2zf
0.2509,Event,ADDED,eval-conflicts-rho010-r4-023.18d466c0c771acbc,reason=Completed count=1 msg=Job completed
0.251,Event,ADDED,eval-conflicts-rho010-r4-024-ghmj9.18d466bdf91563f3,reason=Scheduled count=None msg=Successfully assigned compute/eval-conflicts-rho010-r4-024-ghmj9 to kind-worker3
0.2512,Event,ADDED,eval-conflicts-rho010-r4-024-ghmj9.18d466be135a6d49,"reason=Pulled count=1 msg=Container image ""busybox:musl"" already present on machine"
0.2514,Event,ADDED,eval-conflicts-rho010-r4-024-ghmj9.18d466be14640a59,reason=Created count=1 msg=Created container: task
0.2516,Event,ADDED,eval-conflicts-rho010-r4-024-ghmj9.18d466be1bafebed,reason=Started count=1 msg=Started container task
0.2518,Event,ADDED,eval-conflicts-rho010-r4-024.18d466bdf896f1f5,reason=SuccessfulCreate count=1 msg=Created pod: eval-conflicts-rho010-r4-024-ghmj9
0.2521,Event,ADDED,eval-conflicts-rho010-r4-024.18d466c100255b2f,reason=Completed count=1 msg=Job completed
0.2523,Event,ADDED,eval-conflicts-rho010-r4-025-gcbdp.18d466be34f264d7,reason=Scheduled count=None msg=Successfully assigned compute/eval-conflicts-rho010-r4-025-gcbdp to kind-worker
0.2524,Event,ADDED,eval-conflicts-rho010-r4-025-gcbdp.18d466be4f32cf63,"reason=Pulled count=1 msg=Container image ""busybox:musl"" already present on machine"
0.2527,Event,ADDED,eval-conflicts-rho010-r4-025-gcbdp.18d466be505eb6ac,reason=Created count=1 msg=Created container: task
0.2528,Event,ADDED,eval-conflicts-rho010-r4-025-gcbdp.18d466be5390bc36,reason=Started count=1 msg=Started container task
0.253,Event,ADDED,eval-conflicts-rho010-r4-025.18d466be341c8e38,reason=SuccessfulCreate count=1 msg=Created pod: eval-conflicts-rho010-r4-025-gcbdp
0.2532,Event,ADDED,eval-conflicts-rho010-r4-025.18d466c17a7d0176,reason=Completed count=1 msg=Job completed
0.2533,Event,ADDED,eval-conflicts-rho010-r4-026-dq6n6.18d466be711559b5,reason=Scheduled count=None msg=Successfully assigned compute/eval-conflicts-rho010-r4-026-dq6n6 to kind-worker5
0.2535,Event,ADDED,eval-conflicts-rho010-r4-026-dq6n6.18d466be8d7745cd,"reason=Pulled count=1 msg=Container image ""busybox:musl"" already present on machine"
0.2537,Event,ADDED,eval-conflicts-rho010-r4-026-dq6n6.18d466be8e8983c0,reason=Created count=1 msg=Created container: task
0.2539,Event,ADDED,eval-conflicts-rho010-r4-026-dq6n6.18d466be94ba5186,reason=Started count=1 msg=Started container task
0.2541,Event,ADDED,eval-conflicts-rho010-r4-026.18d466be70280f7c,reason=SuccessfulCreate count=1 msg=Created pod: eval-conflicts-rho010-r4-026-dq6n6
0.2543,Event,ADDED,eval-conflicts-rho010-r4-026.18d466c1c988a7b8,reason=Completed count=1 msg=Job completed
0.2544,Event,ADDED,eval-conflicts-rho010-r4-027-wtwr4.18d466beacc7ba5e,reason=Scheduled count=None msg=Successfully assigned compute/eval-conflicts-rho010-r4-027-wtwr4 to kind-worker5
0.2546,Event,ADDED,eval-conflicts-rho010-r4-027-wtwr4.18d466bec585f8fe,"reason=Pulled count=1 msg=Container image ""busybox:musl"" already present on machine"
0.2548,Event,ADDED,eval-conflicts-rho010-r4-027-wtwr4.18d466bec6bbf710,reason=Created count=1 msg=Created container: task
0.255,Event,ADDED,eval-conflicts-rho010-r4-027-wtwr4.18d466beca9d49a3,reason=Started count=1 msg=Started container task
0.2552,Event,ADDED,eval-conflicts-rho010-r4-027.18d466beab858c72,reason=SuccessfulCreate count=1 msg=Created pod: eval-conflicts-rho010-r4-027-wtwr4
0.2554,Event,ADDED,eval-conflicts-rho010-r4-027.18d466c206a4b067,reason=Completed count=1 msg=Job completed
0.2555,Event,ADDED,eval-conflicts-rho010-r4-028-48hk2.18d466bee82cd8f0,reason=Scheduled count=None msg=Successfully assigned compute/eval-conflicts-rho010-r4-028-48hk2 to kind-worker5
0.2557,Event,ADDED,eval-conflicts-rho010-r4-028-48hk2.18d466bf019ab282,"reason=Pulled count=1 msg=Container image ""busybox:musl"" already present on machine"
0.2559,Event,ADDED,eval-conflicts-rho010-r4-028-48hk2.18d466bf02b07f73,reason=Created count=1 msg=Created container: task
0.2561,Event,ADDED,eval-conflicts-rho010-r4-028-48hk2.18d466bf070ba4aa,reason=Started count=1 msg=Started container task
0.2562,Event,ADDED,eval-conflicts-rho010-r4-028.18d466bee7051e29,reason=SuccessfulCreate count=1 msg=Created pod: eval-conflicts-rho010-r4-028-48hk2
0.2564,Event,ADDED,eval-conflicts-rho010-r4-028.18d466c23b340ba7,reason=Completed count=1 msg=Job completed
0.2565,Event,ADDED,eval-conflicts-rho010-r4-029-swghr.18d466bf247e6cdd,reason=Scheduled count=None msg=Successfully assigned compute/eval-conflicts-rho010-r4-029-swghr to kind-worker5
0.2567,Event,ADDED,eval-conflicts-rho010-r4-029-swghr.18d466bf3eb95112,"reason=Pulled count=1 msg=Container image ""busybox:musl"" already present on machine"
0.2569,Event,ADDED,eval-conflicts-rho010-r4-029-swghr.18d466bf3fcc53fb,reason=Created count=1 msg=Created container: task
0.257,Event,ADDED,eval-conflicts-rho010-r4-029-swghr.18d466bf41eb46f3,reason=Started count=1 msg=Started container task
0.2572,Event,ADDED,eval-conflicts-rho010-r4-029.18d466bf23454dae,reason=SuccessfulCreate count=1 msg=Created pod: eval-conflicts-rho010-r4-029-swghr
0.2574,Event,ADDED,eval-conflicts-rho010-r4-029.18d466c2789414e2,reason=Completed count=1 msg=Job completed
0.2575,Event,ADDED,eval-conflicts-rho010-r4-030-498hd.18d466bf5f7b0c19,reason=Scheduled count=None msg=Successfully assigned compute/eval-conflicts-rho010-r4-030-498hd to kind-worker
0.2577,Event,ADDED,eval-conflicts-rho010-r4-030-498hd.18d466bf787f34c2,"reason=Pulled count=1 msg=Container image ""busybox:musl"" already present on machine"
0.2579,Event,ADDED,eval-conflicts-rho010-r4-030-498hd.18d466bf7991d1f5,reason=Created count=1 msg=Created container: task
0.258,Event,ADDED,eval-conflicts-rho010-r4-030-498hd.18d466bf7c61182e,reason=Started count=1 msg=Started container task
0.2583,Event,ADDED,eval-conflicts-rho010-r4-030.18d466bf5e5a5327,reason=SuccessfulCreate count=1 msg=Created pod: eval-conflicts-rho010-r4-030-498hd
0.2586,Event,ADDED,eval-conflicts-rho010-r4-030.18d466c2aa6ad5d1,reason=Completed count=1 msg=Job completed
0.2587,Event,ADDED,eval-conflicts-rho010-r4-031-knxj7.18d466bf9c6c398d,reason=Scheduled count=None msg=Successfully assigned compute/eval-conflicts-rho010-r4-031-knxj7 to kind-worker5
0.2589,Event,ADDED,eval-conflicts-rho010-r4-031-knxj7.18d466bfb65eba9f,"reason=Pulled count=1 msg=Container image ""busybox:musl"" already present on machine"
0.2592,Event,ADDED,eval-conflicts-rho010-r4-031-knxj7.18d466bfb77b4148,reason=Created count=1 msg=Created container: task
0.2595,Event,ADDED,eval-conflicts-rho010-r4-031-knxj7.18d466bfba777af0,reason=Started count=1 msg=Started container task
0.2597,Event,ADDED,eval-conflicts-rho010-r4-031.18d466bf9b3a1e96,reason=SuccessfulCreate count=1 msg=Created pod: eval-conflicts-rho010-r4-031-knxj7
0.2599,Event,ADDED,eval-conflicts-rho010-r4-031.18d466c2f09d011b,reason=Completed count=1 msg=Job completed
0.2601,Event,ADDED,eval-conflicts-rho010-r4-032-wrfgl.18d466bfd62366df,reason=Scheduled count=None msg=Successfully assigned compute/eval-conflicts-rho010-r4-032-wrfgl to kind-worker3
0.2603,Event,ADDED,eval-conflicts-rho010-r4-032-wrfgl.18d466bff01a6e23,"reason=Pulled count=1 msg=Container image ""busybox:musl"" already present on machine"
0.2604,Event,ADDED,eval-conflicts-rho010-r4-032-wrfgl.18d466bff1335730,reason=Created count=1 msg=Created container: task
0.2606,Event,ADDED,eval-conflicts-rho010-r4-032-wrfgl.18d466bff3299820,reason=Started count=1 msg=Started container task
0.2608,Event,ADDED,eval-conflicts-rho010-r4-032.18d466bfd555d179,reason=SuccessfulCreate count=1 msg=Created pod: eval-conflicts-rho010-r4-032-wrfgl
0.2609,Event,ADDED,eval-conflicts-rho010-r4-032.18d466c31988be66,reason=Completed count=1 msg=Job completed
0.2611,Event,ADDED,eval-conflicts-rho010-r4-033-nss6m.18d466c0121ca05b,reason=Scheduled count=None msg=Successfully assigned compute/eval-conflicts-rho010-r4-033-nss6m to kind-worker5
0.2613,Event,ADDED,eval-conflicts-rho010-r4-033-nss6m.18d466c02a81757c,"reason=Pulled count=1 msg=Container image ""busybox:musl"" already present on machine"
0.2614,Event,ADDED,eval-conflicts-rho010-r4-033-nss6m.18d466c02b8c8ac4,reason=Created count=1 msg=Created container: task
0.2616,Event,ADDED,eval-conflicts-rho010-r4-033-nss6m.18d466c02d893311,reason=Started count=1 msg=Started container task
0.2617,Event,ADDED,eval-conflicts-rho010-r4-033.18d466c0111ed070,reason=SuccessfulCreate count=1 msg=Created pod: eval-conflicts-rho010-r4-033-nss6m
0.2619,Event,ADDED,eval-conflicts-rho010-r4-033.18d466c366e40510,reason=Completed count=1 msg=Job completed
0.2621,Event,ADDED,eval-conflicts-rho010-r4-034-8cqls.18d466c04d6221ea,reason=Scheduled count=None msg=Successfully assigned compute/eval-conflicts-rho010-r4-034-8cqls to kind-worker4
0.2622,Event,ADDED,eval-conflicts-rho010-r4-034-8cqls.18d466c065ef085d,"reason=Pulled count=1 msg=Container image ""busybox:musl"" already present on machine"
0.2624,Event,ADDED,eval-conflicts-rho010-r4-034-8cqls.18d466c06742bc0b,reason=Created count=1 msg=Created container: task
0.2626,Event,ADDED,eval-conflicts-rho010-r4-034-8cqls.18d466c0697cf84a,reason=Started count=1 msg=Started container task
0.2627,Event,ADDED,eval-conflicts-rho010-r4-034.18d466c04ca05e23,reason=SuccessfulCreate count=1 msg=Created pod: eval-conflicts-rho010-r4-034-8cqls
0.2629,Event,ADDED,eval-conflicts-rho010-r4-034.18d466c3b2c79dd0,reason=Completed count=1 msg=Job completed
0.263,Event,ADDED,eval-conflicts-rho010-r4-035-sh9vm.18d466c089aa7edd,reason=Scheduled count=None msg=Successfully assigned compute/eval-conflicts-rho010-r4-035-sh9vm to kind-worker2
0.2632,Event,ADDED,eval-conflicts-rho010-r4-035-sh9vm.18d466c0a1eeafdf,"reason=Pulled count=1 msg=Container image ""busybox:musl"" already present on machine"
0.2634,Event,ADDED,eval-conflicts-rho010-r4-035-sh9vm.18d466c0a31d43b8,reason=Created count=1 msg=Created container: task
0.2635,Event,ADDED,eval-conflicts-rho010-r4-035-sh9vm.18d466c0a6f4b752,reason=Started count=1 msg=Started container task
0.2637,Event,ADDED,eval-conflicts-rho010-r4-035.18d466c088b9f078,reason=SuccessfulCreate count=1 msg=Created pod: eval-conflicts-rho010-r4-035-sh9vm
0.2638,Event,ADDED,eval-conflicts-rho010-r4-035.18d466c3e4b4aba1,reason=Completed count=1 msg=Job completed
0.264,Event,ADDED,eval-conflicts-rho010-r4-036-fc292.18d466c0c5830935,reason=Scheduled count=None msg=Successfully assigned compute/eval-conflicts-rho010-r4-036-fc292 to kind-worker2
0.2644,Event,ADDED,eval-conflicts-rho010-r4-036-fc292.18d466c0df37bdb3,"reason=Pulled count=1 msg=Container image ""busybox:musl"" already present on machine"
0.2646,Event,ADDED,eval-conflicts-rho010-r4-036-fc292.18d466c0e04690a9,reason=Created count=1 msg=Created container: task
0.2647,Event,ADDED,eval-conflicts-rho010-r4-036-fc292.18d466c0e41554b0,reason=Started count=1 msg=Started container task
0.2649,Event,ADDED,eval-conflicts-rho010-r4-036.18d466c0c4c04516,reason=SuccessfulCreate count=1 msg=Created pod: eval-conflicts-rho010-r4-036-fc292
0.2651,Event,ADDED,eval-conflicts-rho010-r4-036.18d466c424976ed6,reason=Completed count=1 msg=Job completed
0.2653,Event,ADDED,eval-conflicts-rho010-r4-037-5tgss.18d466c100ccacc6,reason=Scheduled count=None msg=Successfully assigned compute/eval-conflicts-rho010-r4-037-5tgss to kind-worker2
0.2654,Event,ADDED,eval-conflicts-rho010-r4-037-5tgss.18d466c119a64316,"reason=Pulled count=1 msg=Container image ""busybox:musl"" already present on machine"
0.2656,Event,ADDED,eval-conflicts-rho010-r4-037-5tgss.18d466c11ac11650,reason=Created count=1 msg=Created container: task
0.2658,Event,ADDED,eval-conflicts-rho010-r4-037-5tgss.18d466c11cda16ca,reason=Started count=1 msg=Started container task
0.266,Event,ADDED,eval-conflicts-rho010-r4-037.18d466c0ff9e91d5,reason=SuccessfulCreate count=1 msg=Created pod: eval-conflicts-rho010-r4-037-5tgss
0.2661,Event,ADDED,eval-conflicts-rho010-r4-037.18d466c460c7ad4a,reason=Completed count=1 msg=Job completed
0.2663,Event,ADDED,eval-conflicts-rho010-r4-038-mms8t.18d466c13cdbd217,reason=Scheduled count=None msg=Successfully assigned compute/eval-conflicts-rho010-r4-038-mms8t to kind-worker2
0.2665,Event,ADDED,eval-conflicts-rho010-r4-038-mms8t.18d466c1574dcefc,"reason=Pulled count=1 msg=Container image ""busybox:musl"" already present on machine"
0.2666,Event,ADDED,eval-conflicts-rho010-r4-038-mms8t.18d466c15877a5f2,reason=Created count=1 msg=Created container: task
0.2668,Event,ADDED,eval-conflicts-rho010-r4-038-mms8t.18d466c160abb1e5,reason=Started count=1 msg=Started container task
0.267,Event,ADDED,eval-conflicts-rho010-r4-038.18d466c13c01f751,reason=SuccessfulCreate count=1 msg=Created pod: eval-conflicts-rho010-r4-038-mms8t
0.2671,Event,ADDED,eval-conflicts-rho010-r4-038.18d466c49c818823,reason=Completed count=1 msg=Job completed
0.2673,Event,ADDED,eval-conflicts-rho010-r4-039-7rl9l.18d466c178b876ab,reason=Scheduled count=None msg=Successfully assigned compute/eval-conflicts-rho010-r4-039-7rl9l to kind-worker4
0.2674,Event,ADDED,eval-conflicts-rho010-r4-039-7rl9l.18d466c193b825bc,"reason=Pulled count=1 msg=Container image ""busybox:musl"" already present on machine"
0.2676,Event,ADDED,eval-conflicts-rho010-r4-039-7rl9l.18d466c194c39f89,reason=Created count=1 msg=Created container: task
0.2678,Event,ADDED,eval-conflicts-rho010-r4-039-7rl9l.18d466c19b72ef09,reason=Started count=1 msg=Started container task
0.268,Event,ADDED,eval-conflicts-rho010-r4-039.18d466c177c75251,reason=SuccessfulCreate count=1 msg=Created pod: eval-conflicts-rho010-r4-039-7rl9l
0.2682,Event,ADDED,eval-conflicts-rho010-r4-039.18d466c4da0234fd,reason=Completed count=1 msg=Job completed
0.2684,Event,ADDED,eval-conflicts-rho010-r4-040-bwzg4.18d466c1b31cee2c,reason=Scheduled count=None msg=Successfully assigned compute/eval-conflicts-rho010-r4-040-bwzg4 to kind-worker2
0.2685,Event,ADDED,eval-conflicts-rho010-r4-040-bwzg4.18d466c1d18791cf,"reason=Pulled count=1 msg=Container image ""busybox:musl"" already present on machine"
0.2687,Event,ADDED,eval-conflicts-rho010-r4-040-bwzg4.18d466c1d2b13d4a,reason=Created count=1 msg=Created container: task
0.2689,Event,ADDED,eval-conflicts-rho010-r4-040-bwzg4.18d466c1d9bd89d2,reason=Started count=1 msg=Started container task
0.2691,Event,ADDED,eval-conflicts-rho010-r4-040.18d466c1b2336f9b,reason=SuccessfulCreate count=1 msg=Created pod: eval-conflicts-rho010-r4-040-bwzg4
0.2692,Event,ADDED,eval-conflicts-rho010-r4-040.18d466c50c0e69a8,reason=Completed count=1 msg=Job completed
0.2694,Event,ADDED,eval-conflicts-rho010-r4-041-47gwj.18d466c1eef6f070,reason=Scheduled count=None msg=Successfully assigned compute/eval-conflicts-rho010-r4-041-47gwj to kind-worker4
0.2696,Event,ADDED,eval-conflicts-rho010-r4-041-47gwj.18d466c20cec58bb,"reason=Pulled count=1 msg=Container image ""busybox:musl"" already present on machine"
0.2698,Event,ADDED,eval-conflicts-rho010-r4-041-47gwj.18d466c20e06a6f2,reason=Created count=1 msg=Created container: task
0.2699,Event,ADDED,eval-conflicts-rho010-r4-041-47gwj.18d466c21580b084,reason=Started count=1 msg=Started container task
0.2701,Event,ADDED,eval-conflicts-rho010-r4-041.18d466c1ee07718b,reason=SuccessfulCreate count=1 msg=Created pod: eval-conflicts-rho010-r4-041-47gwj
0.2703,Event,ADDED,eval-conflicts-rho010-r4-041.18d466c557f64024,reason=Completed count=1 msg=Job completed
0.2704,Event,ADDED,eval-conflicts-rho010-r4-042-s5tzc.18d466c22a6d31f2,reason=Scheduled count=None msg=Successfully assigned compute/eval-conflicts-rho010-r4-042-s5tzc to kind-worker4
0.2706,Event,ADDED,eval-conflicts-rho010-r4-042-s5tzc.18d466c24886920b,"reason=Pulled count=1 msg=Container image ""busybox:musl"" already present on machine"
0.2708,Event,ADDED,eval-conflicts-rho010-r4-042-s5tzc.18d466c249bc9d8a,reason=Created count=1 msg=Created container: task
0.2709,Event,ADDED,eval-conflicts-rho010-r4-042-s5tzc.18d466c24caafa22,reason=Started count=1 msg=Started container task
0.2711,Event,ADDED,eval-conflicts-rho010-r4-042.18d466c2298d0307,reason=SuccessfulCreate count=1 msg=Created pod: eval-conflicts-rho010-r4-042-s5tzc
0.2712,Event,ADDED,eval-conflicts-rho010-r4-042.18d466c593eda8f6,reason=Completed count=1 msg=Job completed
0.2714,Event,ADDED,eval-conflicts-rho010-r4-043-f8trd.18d466c26647cc18,reason=Scheduled count=None msg=Successfully assigned compute/eval-conflicts-rho010-r4-043-f8trd to kind-worker2
0.2716,Event,ADDED,eval-conflicts-rho010-r4-043-f8trd.18d466c282f74378,"reason=Pulled count=1 msg=Container image ""busybox:musl"" already present on machine"
0.2718,Event,ADDED,eval-conflicts-rho010-r4-043-f8trd.18d466c2842d92fb,reason=Created count=1 msg=Created container: task
0.2719,Event,ADDED,eval-conflicts-rho010-r4-043-f8trd.18d466c287b96f18,reason=Started count=1 msg=Started container task
0.2721,Event,ADDED,eval-conflicts-rho010-r4-043.18d466c2656067c4,reason=SuccessfulCreate count=1 msg=Created pod: eval-conflicts-rho010-r4-043-f8trd
0.2723,Event,ADDED,eval-conflicts-rho010-r4-043.18d466c5c02aeaed,reason=Completed count=1 msg=Job completed
0.2724,Event,ADDED,eval-conflicts-rho010-r4-044-w9d85.18d466c2a1043d4e,"reason=FailedScheduling count=None msg=0/6 nodes are available: 1 c_wall violated: 1 conflicting context pair(s) with node memory, 5 node(s) had untolerated taint(s). no new claims to deallocate, preemption: 0/6 nodes are available: 1 No preemption victims found for incoming pod, 5 Preemption is not helpful for scheduling."
0.2726,Event,ADDED,eval-conflicts-rho010-r4-044-w9d85.18d466c2a187c574,"reason=FailedScheduling count=None msg=0/6 nodes are available: 1 c_wall violated: 1 conflicting context pair(s) with node memory, 5 node(s) had untolerated taint(s). no new claims to deallocate, preemption: 0/6 nodes are available: 1 No preemption victims found for incoming pod, 5 Preemption is not helpful for scheduling."
0.2728,Event,ADDED,eval-conflicts-rho010-r4-044-w9d85.18d466c3053440ed,reason=Scheduled count=None msg=Successfully assigned compute/eval-conflicts-rho010-r4-044-w9d85 to kind-worker5
0.2729,Event,ADDED,eval-conflicts-rho010-r4-044-w9d85.18d466c3222b9bf4,"reason=Pulled count=1 msg=Container image ""busybox:musl"" already present on machine"
0.2731,Event,ADDED,eval-conflicts-rho010-r4-044-w9d85.18d466c3239b689f,reason=Created count=1 msg=Created container: task
0.2733,Event,ADDED,eval-conflicts-rho010-r4-044-w9d85.18d466c32a92f715,reason=Started count=1 msg=Started container task
0.2734,Event,ADDED,eval-conflicts-rho010-r4-044.18d466c2a0c61a82,reason=SuccessfulCreate count=1 msg=Created pod: eval-conflicts-rho010-r4-044-w9d85
0.2736,Event,ADDED,eval-conflicts-rho010-r4-044.18d466c637fd72cc,reason=Completed count=1 msg=Job completed
0.2738,Event,ADDED,eval-conflicts-rho010-r4-045-ml7lt.18d466c2dcbf0cfe,"reason=FailedScheduling count=None msg=0/6 nodes are available: 6 node(s) had untolerated taint(s). no new claims to deallocate, preemption: 0/6 nodes are available: 6 Preemption is not helpful for scheduling."
0.2739,Event,ADDED,eval-conflicts-rho010-r4-045-ml7lt.18d466c305509613,reason=Scheduled count=None msg=Successfully assigned compute/eval-conflicts-rho010-r4-045-ml7lt to kind-worker5
0.2744,Event,ADDED,eval-conflicts-rho010-r4-045-ml7lt.18d466c3224ec692,"reason=Pulled count=1 msg=Container image ""busybox:musl"" already present on machine"
0.2747,Event,ADDED,eval-conflicts-rho010-r4-045-ml7lt.18d466c323f0825c,reason=Created count=1 msg=Created container: task
0.2749,Event,ADDED,eval-conflicts-rho010-r4-045-ml7lt.18d466c32a8eacd9,reason=Started count=1 msg=Started container task
0.2751,Event,ADDED,eval-conflicts-rho010-r4-045.18d466c2dcb5a9e0,reason=SuccessfulCreate count=1 msg=Created pod: eval-conflicts-rho010-r4-045-ml7lt
0.2753,Event,ADDED,eval-conflicts-rho010-r4-045.18d466c6388c0b5a,reason=Completed count=1 msg=Job completed
0.2756,Event,ADDED,eval-conflicts-rho010-r4-046-f4lcp.18d466c318564c20,reason=Scheduled count=None msg=Successfully assigned compute/eval-conflicts-rho010-r4-046-f4lcp to kind-worker5
0.2758,Event,ADDED,eval-conflicts-rho010-r4-046-f4lcp.18d466c331ad1fd6,"reason=Pulled count=1 msg=Container image ""busybox:musl"" already present on machine"
0.276,Event,ADDED,eval-conflicts-rho010-r4-046-f4lcp.18d466c332ba30d5,reason=Created count=1 msg=Created container: task
0.2763,Event,ADDED,eval-conflicts-rho010-r4-046-f4lcp.18d466c334b54eaf,reason=Started count=1 msg=Started container task
0.2765,Event,ADDED,eval-conflicts-rho010-r4-046.18d466c317a59c8f,reason=SuccessfulCreate count=1 msg=Created pod: eval-conflicts-rho010-r4-046-f4lcp
0.2767,Event,ADDED,eval-conflicts-rho010-r4-046.18d466c6739de303,reason=Completed count=1 msg=Job completed
0.2769,Event,ADDED,eval-conflicts-rho010-r4-047-rgsrt.18d466c353d56f78,"reason=FailedScheduling count=None msg=0/6 nodes are available: 1 c_wall violated: 1 conflicting context pair(s) with node memory, 5 node(s) had untolerated taint(s). no new claims to deallocate, preemption: 0/6 nodes are available: 1 No preemption victims found for incoming pod, 5 Preemption is not helpful for scheduling."
0.2772,Event,ADDED,eval-conflicts-rho010-r4-047-rgsrt.18d466c354585c49,"reason=FailedScheduling count=None msg=0/6 nodes are available: 1 c_wall violated: 1 conflicting context pair(s) with node memory, 5 node(s) had untolerated taint(s). no new claims to deallocate, preemption: 0/6 nodes are available: 1 No preemption victims found for incoming pod, 5 Preemption is not helpful for scheduling."
0.2773,Event,ADDED,eval-conflicts-rho010-r4-047-rgsrt.18d466c49240a17e,"reason=FailedScheduling count=None msg=0/6 nodes are available: 2 c_wall violated: 1 conflicting context pair(s) with node memory, 4 node(s) had untolerated taint(s). no new claims to deallocate, preemption: 0/6 nodes are available: 2 No preemption victims found for incoming pod, 4 Preemption is not helpful for scheduling."
0.2775,Event,ADDED,eval-conflicts-rho010-r4-047-rgsrt.18d466c4dd35bc2e,reason=Scheduled count=None msg=Successfully assigned compute/eval-conflicts-rho010-r4-047-rgsrt to kind-worker3
0.2777,Event,ADDED,eval-conflicts-rho010-r4-047-rgsrt.18d466c4f8524c93,"reason=Pulled count=1 msg=Container image ""busybox:musl"" already present on machine"
0.2778,Event,ADDED,eval-conflicts-rho010-r4-047-rgsrt.18d466c4f977f6c8,reason=Created count=1 msg=Created container: task
0.278,Event,ADDED,eval-conflicts-rho010-r4-047-rgsrt.18d466c5026da981,reason=Started count=1 msg=Started container task
0.2782,Event,ADDED,eval-conflicts-rho010-r4-047.18d466c35398bca0,reason=SuccessfulCreate count=1 msg=Created pod: eval-conflicts-rho010-r4-047-rgsrt
0.2783,Event,ADDED,eval-conflicts-rho010-r4-047.18d466c843c0251d,reason=Completed count=1 msg=Job completed
0.2785,Event,ADDED,eval-conflicts-rho010-r4-048-5xbn2.18d466c390a97202,reason=Scheduled count=None msg=Successfully assigned compute/eval-conflicts-rho010-r4-048-5xbn2 to kind-worker5
0.2787,Event,ADDED,eval-conflicts-rho010-r4-048-5xbn2.18d466c3b18b0cea,"reason=Pulled count=1 msg=Container image ""busybox:musl"" already present on machine"
0.2789,Event,ADDED,eval-conflicts-rho010-r4-048-5xbn2.18d466c3b2fff587,reason=Created count=1 msg=Created container: task
0.2791,Event,ADDED,eval-conflicts-rho010-r4-048-5xbn2.18d466c3b9fc5c57,reason=Started count=1 msg=Started container task
0.2793,Event,ADDED,eval-conflicts-rho010-r4-048.18d466c3901843bb,reason=SuccessfulCreate count=1 msg=Created pod: eval-conflicts-rho010-r4-048-5xbn2
0.2794,Event,ADDED,eval-conflicts-rho010-r4-048.18d466c6eb75758a,reason=Completed count=1 msg=Job completed
0.2798,Event,ADDED,eval-conflicts-rho010-r4-049-l2gdc.18d466c3cb3192d5,reason=Scheduled count=None msg=Successfully assigned compute/eval-conflicts-rho010-r4-049-l2gdc to kind-worker5
0.28,Event,ADDED,eval-conflicts-rho010-r4-049-l2gdc.18d466c3ef4ddf5d,"reason=Pulled count=1 msg=Container image ""busybox:musl"" already present on machine"
0.2802,Event,ADDED,eval-conflicts-rho010-r4-049-l2gdc.18d466c3f089d484,reason=Created count=1 msg=Created container: task
0.2805,Event,ADDED,eval-conflicts-rho010-r4-049-l2gdc.18d466c3f464671f,reason=Started count=1 msg=Started container task
0.2807,Event,ADDED,eval-conflicts-rho010-r4-049.18d466c3caafb0bf,reason=SuccessfulCreate count=1 msg=Created pod: eval-conflicts-rho010-r4-049-l2gdc
0.2809,Event,ADDED,eval-conflicts-rho010-r4-049.18d466c72936dc91,reason=Completed count=1 msg=Job completed
0.281,Event,ADDED,eval-conflicts-rho010-r4-050-z2jkk.18d466c406e04eb3,"reason=FailedScheduling count=None msg=0/6 nodes are available: 1 c_wall violated: 1 conflicting context pair(s) with node memory, 5 node(s) had untolerated taint(s). no new claims to deallocate, preemption: 0/6 nodes are available: 1 No preemption victims found for incoming pod, 5 Preemption is not helpful for scheduling."
0.2813,Event,ADDED,eval-conflicts-rho010-r4-050-z2jkk.18d466c407631159,"reason=FailedScheduling count=None msg=0/6 nodes are available: 1 c_wall violated: 1 conflicting context pair(s) with node memory, 5 node(s) had untolerated taint(s). no new claims to deallocate, preemption: 0/6 nodes are available: 1 No preemption victims found for incoming pod, 5 Preemption is not helpful for scheduling."
0.2814,Event,ADDED,eval-conflicts-rho010-r4-050-z2jkk.18d466c48a49a756,reason=Scheduled count=None msg=Successfully assigned compute/eval-conflicts-rho010-r4-050-z2jkk to kind-worker
0.2816,Event,ADDED,eval-conflicts-rho010-r4-050-z2jkk.18d466c4a2dd3d53,"reason=Pulled count=1 msg=Container image ""busybox:musl"" already present on machine"
0.2818,Event,ADDED,eval-conflicts-rho010-r4-050-z2jkk.18d466c4a3ecb3ea,reason=Created count=1 msg=Created container: task
0.282,Event,ADDED,eval-conflicts-rho010-r4-050-z2jkk.18d466c4aa8e9f83,reason=Started count=1 msg=Started container task
0.2822,Event,ADDED,eval-conflicts-rho010-r4-050.18d466c406999be3,reason=SuccessfulCreate count=1 msg=Created pod: eval-conflicts-rho010-r4-050-z2jkk
0.2824,Event,ADDED,eval-conflicts-rho010-r4-050.18d466c7c9184b98,reason=Completed count=1 msg=Job completed
0.2827,Event,ADDED,eval-conflicts-rho010-r4-051-cp9j7.18d466c442936e54,"reason=FailedScheduling count=None msg=0/6 nodes are available: 1 c_wall violated: 1 conflicting context pair(s) with node memory, 5 node(s) had untolerated taint(s). no new claims to deallocate, preemption: 0/6 nodes are available: 1 No preemption victims found for incoming pod, 5 Preemption is not helpful for scheduling."
0.2834,Event,ADDED,eval-conflicts-rho010-r4-051-cp9j7.18d466c443252862,"reason=FailedScheduling count=None msg=0/6 nodes are available: 1 c_wall violated: 1 conflicting context pair(s) with node memory, 5 node(s) had untolerated taint(s). no new claims to deallocate, preemption: 0/6 nodes are available: 1 No preemption victims found for incoming pod, 5 Preemption is not helpful for scheduling."
0.2838,Event,ADDED,eval-conflicts-rho010-r4-051-cp9j7.18d466c4928e62a7,"reason=FailedScheduling count=None msg=0/6 nodes are available: 2 c_wall violated: 1 conflicting context pair(s) with node memory, 4 node(s) had untolerated taint(s). no new claims to deallocate, preemption: 0/6 nodes are available: 2 No preemption victims found for incoming pod, 4 Preemption is not helpful for scheduling."
0.2839,Event,ADDED,eval-conflicts-rho010-r4-051-cp9j7.18d466c4e587c2a8,reason=Scheduled count=None msg=Successfully assigned compute/eval-conflicts-rho010-r4-051-cp9j7 to kind-worker3
0.2841,Event,ADDED,eval-conflicts-rho010-r4-051-cp9j7.18d466c502793d71,"reason=Pulled count=1 msg=Container image ""busybox:musl"" already present on machine"
0.2843,Event,ADDED,eval-conflicts-rho010-r4-051-cp9j7.18d466c5039e2181,reason=Created count=1 msg=Created container: task
0.2846,Event,ADDED,eval-conflicts-rho010-r4-051-cp9j7.18d466c50836f7ed,reason=Started count=1 msg=Started container task
0.2848,Event,ADDED,eval-conflicts-rho010-r4-051.18d466c442500ea5,reason=SuccessfulCreate count=1 msg=Created pod: eval-conflicts-rho010-r4-051-cp9j7
0.2849,Event,ADDED,eval-conflicts-rho010-r4-051.18d466c843944de5,reason=Completed count=1 msg=Job completed
0.2851,Event,ADDED,eval-conflicts-rho010-r4-052-ltl58.18d466c47e70cb20,reason=Scheduled count=None msg=Successfully assigned compute/eval-conflicts-rho010-r4-052-ltl58 to kind-worker5
0.2854,Event,ADDED,eval-conflicts-rho010-r4-052-ltl58.18d466c49cb9e849,"reason=Pulled count=1 msg=Container image ""busybox:musl"" already present on machine"
0.2856,Event,ADDED,eval-conflicts-rho010-r4-052-ltl58.18d466c49e293453,reason=Created count=1 msg=Created container: task
0.2857,Event,ADDED,eval-conflicts-rho010-r4-052-ltl58.18d466c4a21b21c7,reason=Started count=1 msg=Started container task
0.2862,Event,ADDED,eval-conflicts-rho010-r4-052.18d466c47de158cb,reason=SuccessfulCreate count=1 msg=Created pod: eval-conflicts-rho010-r4-052-ltl58
0.2863,Event,ADDED,eval-conflicts-rho010-r4-052.18d466c7e20449ab,reason=Completed count=1 msg=Job completed
0.2865,Event,ADDED,eval-conflicts-rho010-r4-053-85b24.18d466c4badc31a4,reason=Scheduled count=None msg=Successfully assigned compute/eval-conflicts-rho010-r4-053-85b24 to kind-worker
0.2867,Event,ADDED,eval-conflicts-rho010-r4-053-85b24.18d466c4d92d1546,"reason=Pulled count=1 msg=Container image ""busybox:musl"" already present on machine"
0.287,Event,ADDED,eval-conflicts-rho010-r4-053-85b24.18d466c4da9e66cf,reason=Created count=1 msg=Created container: task
0.2872,Event,ADDED,eval-conflicts-rho010-r4-053-85b24.18d466c4de34836b,reason=Started count=1 msg=Started container task
0.2873,Event,ADDED,eval-conflicts-rho010-r4-053.18d466c4b9af5bf5,reason=SuccessfulCreate count=1 msg=Created pod: eval-conflicts-rho010-r4-053-85b24
0.2875,Event,ADDED,eval-conflicts-rho010-r4-053.18d466c807377188,reason=Completed count=1 msg=Job completed
0.2877,Event,ADDED,eval-conflicts-rho010-r4-054-k4sxr.18d466c4f695350c,reason=Scheduled count=None msg=Successfully assigned compute/eval-conflicts-rho010-r4-054-k4sxr to kind-worker3
0.2879,Event,ADDED,eval-conflicts-rho010-r4-054-k4sxr.18d466c50fe63611,"reason=Pulled count=1 msg=Container image ""busybox:musl"" already present on machine"
0.2881,Event,ADDED,eval-conflicts-rho010-r4-054-k4sxr.18d466c511007aef,reason=Created count=1 msg=Created container: task
0.2884,Event,ADDED,eval-conflicts-rho010-r4-054-k4sxr.18d466c518d934ca,reason=Started count=1 msg=Started container task
0.2886,Event,ADDED,eval-conflicts-rho010-r4-054.18d466c4f59115a3,reason=SuccessfulCreate count=1 msg=Created pod: eval-conflicts-rho010-r4-054-k4sxr
0.2887,Event,ADDED,eval-conflicts-rho010-r4-054.18d466c84367a8dd,reason=Completed count=1 msg=Job completed
0.2889,Event,ADDED,eval-conflicts-rho010-r4-055-f4hhp.18d466c531058a40,reason=Scheduled count=None msg=Successfully assigned compute/eval-conflicts-rho010-r4-055-f4hhp to kind-worker
0.2892,Event,ADDED,eval-conflicts-rho010-r4-055-f4hhp.18d466c54fdd14e2,"reason=Pulled count=1 msg=Container image ""busybox:musl"" already present on machine"
0.2894,Event,ADDED,eval-conflicts-rho010-r4-055-f4hhp.18d466c551057640,reason=Created count=1 msg=Created container: task
0.2896,Event,ADDED,eval-conflicts-rho010-r4-055-f4hhp.18d466c557b0fccb,reason=Started count=1 msg=Started container task
0.2899,Event,ADDED,eval-conflicts-rho010-r4-055.18d466c53030d747,reason=SuccessfulCreate count=1 msg=Created pod: eval-conflicts-rho010-r4-055-f4hhp
0.2902,Event,ADDED,eval-conflicts-rho010-r4-055.18d466c84442dba2,reason=Completed count=1 msg=Job completed
0.2903,Event,ADDED,eval-conflicts-rho010-r4-056-4bpg2.18d466c57196804c,reason=Scheduled count=None msg=Successfully assigned compute/eval-conflicts-rho010-r4-056-4bpg2 to kind-worker
0.2905,Event,ADDED,eval-conflicts-rho010-r4-056-4bpg2.18d466c58d833f14,"reason=Pulled count=1 msg=Container image ""busybox:musl"" already present on machine"
0.2908,Event,ADDED,eval-conflicts-rho010-r4-056-4bpg2.18d466c58ebe225e,reason=Created count=1 msg=Created container: task
0.291,Event,ADDED,eval-conflicts-rho010-r4-056-4bpg2.18d466c592d7f191,reason=Started count=1 msg=Started container task
0.2912,Event,ADDED,eval-conflicts-rho010-r4-056.18d466c5709819d4,reason=SuccessfulCreate count=1 msg=Created pod: eval-conflicts-rho010-r4-056-4bpg2
0.2914,Event,ADDED,eval-conflicts-rho010-r4-056.18d466c8bbf7aac8,reason=Completed count=1 msg=Job completed
0.2917,Event,ADDED,eval-conflicts-rho010-r4-057-2fxpb.18d466c5a85e67dc,reason=Scheduled count=None msg=Successfully assigned compute/eval-conflicts-rho010-r4-057-2fxpb to kind-worker
0.2919,Event,ADDED,eval-conflicts-rho010-r4-057-2fxpb.18d466c5cb0474fa,"reason=Pulled count=1 msg=Container image ""busybox:musl"" already present on machine"
0.2921,Event,ADDED,eval-conflicts-rho010-r4-057-2fxpb.18d466c5cc53c209,reason=Created count=1 msg=Created container: task
0.2925,Event,ADDED,eval-conflicts-rho010-r4-057-2fxpb.18d466c5d0a99601,reason=Started count=1 msg=Started container task
0.2927,Event,ADDED,eval-conflicts-rho010-r4-057.18d466c5a7c81547,reason=SuccessfulCreate count=1 msg=Created pod: eval-conflicts-rho010-r4-057-2fxpb
0.2929,Event,ADDED,eval-conflicts-rho010-r4-057.18d466c8f75e7d82,reason=Completed count=1 msg=Job completed
0.293,Event,ADDED,eval-conflicts-rho010-r4-058-8xqrj.18d466c5e8e259cc,reason=Scheduled count=None msg=Successfully assigned compute/eval-conflicts-rho010-r4-058-8xqrj to kind-worker
0.2934,Event,ADDED,eval-conflicts-rho010-r4-058-8xqrj.18d466c603e18853,"reason=Pulled count=1 msg=Container image ""busybox:musl"" already present on machine"
0.2936,Event,ADDED,eval-conflicts-rho010-r4-058-8xqrj.18d466c604fd4491,reason=Created count=1 msg=Created container: task
0.2938,Event,ADDED,eval-conflicts-rho010-r4-058-8xqrj.18d466c608a4386f,reason=Started count=1 msg=Started container task
0.294,Event,ADDED,eval-conflicts-rho010-r4-058.18d466c5e7eaf853,reason=SuccessfulCreate count=1 msg=Created pod: eval-conflicts-rho010-r4-058-8xqrj
0.2943,Event,ADDED,eval-conflicts-rho010-r4-058.18d466c9343f7f52,reason=Completed count=1 msg=Job completed
0.2946,Event,ADDED,eval-conflicts-rho010-r4-059-5kg5w.18d466c61fbb6955,reason=Scheduled count=None msg=Successfully assigned compute/eval-conflicts-rho010-r4-059-5kg5w to kind-worker
0.2948,Event,ADDED,eval-conflicts-rho010-r4-059-5kg5w.18d466c640c141f8,"reason=Pulled count=1 msg=Container image ""busybox:musl"" already present on machine"
0.295,Event,ADDED,eval-conflicts-rho010-r4-059-5kg5w.18d466c641dfcd1b,reason=Created count=1 msg=Created container: task
0.2951,Event,ADDED,eval-conflicts-rho010-r4-059-5kg5w.18d466c6487d2443,reason=Started count=1 msg=Started container task
0.2955,Event,ADDED,eval-conflicts-rho010-r4-059.18d466c61ee693e2,reason=SuccessfulCreate count=1 msg=Created pod: eval-conflicts-rho010-r4-059-5kg5w
0.2956,Event,ADDED,eval-conflicts-rho010-r4-059.18d466c970415e50,reason=Completed count=1 msg=Job completed
0.2958,Event,ADDED,eval-conflicts-rho010-r4-060-4h7zd.18d466c65b77a4dc,reason=Scheduled count=None msg=Successfully assigned compute/eval-conflicts-rho010-r4-060-4h7zd to kind-worker
0.296,Event,ADDED,eval-conflicts-rho010-r4-060-4h7zd.18d466c67bb0fa1c,"reason=Pulled count=1 msg=Container image ""busybox:musl"" already present on machine"
0.2963,Event,ADDED,eval-conflicts-rho010-r4-060-4h7zd.18d466c67d0077d8,reason=Created count=1 msg=Created container: task
0.2965,Event,ADDED,eval-conflicts-rho010-r4-060-4h7zd.18d466c683ab795c,reason=Started count=1 msg=Started container task
0.2967,Event,ADDED,eval-conflicts-rho010-r4-060.18d466c65a8bd616,reason=SuccessfulCreate count=1 msg=Created pod: eval-conflicts-rho010-r4-060-4h7zd
0.297,Event,ADDED,eval-conflicts-rho010-r4-060.18d466c9a882a8f7,reason=Completed count=1 msg=Job completed
0.2971,Event,ADDED,eval-conflicts-rho010-r4-061-52n5n.18d466c6995bb3ed,reason=Scheduled count=None msg=Successfully assigned compute/eval-conflicts-rho010-r4-061-52n5n to kind-worker
0.2973,Event,ADDED,eval-conflicts-rho010-r4-061-52n5n.18d466c6bc9c6ec6,"reason=Pulled count=1 msg=Container image ""busybox:musl"" already present on machine"
0.2975,Event,ADDED,eval-conflicts-rho010-r4-061-52n5n.18d466c6bdc6565f,reason=Created count=1 msg=Created container: task
0.2978,Event,ADDED,eval-conflicts-rho010-r4-061-52n5n.18d466c6c6ee0e53,reason=Started count=1 msg=Started container task
0.298,Event,ADDED,eval-conflicts-rho010-r4-061.18d466c698a6c54e,reason=SuccessfulCreate count=1 msg=Created pod: eval-conflicts-rho010-r4-061-52n5n
0.2982,Event,ADDED,eval-conflicts-rho010-r4-061.18d466c9e443910c,reason=Completed count=1 msg=Job completed
0.2983,Event,ADDED,eval-conflicts-rho010-r4-062-dhmrx.18d466c6d25d7983,reason=Scheduled count=None msg=Successfully assigned compute/eval-conflicts-rho010-r4-062-dhmrx to kind-worker
0.2987,Event,ADDED,eval-conflicts-rho010-r4-062-dhmrx.18d466c6fd1cbca2,"reason=Pulled count=1 msg=Container image ""busybox:musl"" already present on machine"
0.2989,Event,ADDED,eval-conflicts-rho010-r4-062-dhmrx.18d466c6fe3da03e,reason=Created count=1 msg=Created container: task
0.299,Event,ADDED,eval-conflicts-rho010-r4-062-dhmrx.18d466c705a49429,reason=Started count=1 msg=Started container task
0.2993,Event,ADDED,eval-conflicts-rho010-r4-062.18d466c6d1af1e75,reason=SuccessfulCreate count=1 msg=Created pod: eval-conflicts-rho010-r4-062-dhmrx
0.2995,Event,ADDED,eval-conflicts-rho010-r4-062.18d466ca20aa787a,reason=Completed count=1 msg=Job completed
0.2997,Event,ADDED,eval-conflicts-rho010-r4-063-9fzpp.18d466c7153aa232,reason=Scheduled count=None msg=Successfully assigned compute/eval-conflicts-rho010-r4-063-9fzpp to kind-worker3
0.2999,Event,ADDED,eval-conflicts-rho010-r4-063-9fzpp.18d466c74f9a09c3,"reason=Pulled count=1 msg=Container image ""busybox:musl"" already present on machine"
0.3002,Event,ADDED,eval-conflicts-rho010-r4-063-9fzpp.18d466c750fda9d8,reason=Created count=1 msg=Created container: task
0.3004,Event,ADDED,eval-conflicts-rho010-r4-063-9fzpp.18d466c75a184ac8,reason=Started count=1 msg=Started container task
0.3006,Event,ADDED,eval-conflicts-rho010-r4-063.18d466c714c93081,reason=SuccessfulCreate count=1 msg=Created pod: eval-conflicts-rho010-r4-063-9fzpp
0.301,Event,ADDED,eval-conflicts-rho010-r4-063.18d466ca927fd3db,reason=Completed count=1 msg=Job completed
0.3013,Event,ADDED,eval-conflicts-rho010-r4-064-75fts.18d466c748eabd02,"reason=FailedScheduling count=None msg=0/6 nodes are available: 6 node(s) had untolerated taint(s). no new claims to deallocate, preemption: 0/6 nodes are available: 6 Preemption is not helpful for scheduling."
0.3015,Event,ADDED,eval-conflicts-rho010-r4-064-75fts.18d466c75950c069,reason=Scheduled count=None msg=Successfully assigned compute/eval-conflicts-rho010-r4-064-75fts to kind-worker4
0.3017,Event,ADDED,eval-conflicts-rho010-r4-064-75fts.18d466c77988823b,"reason=Pulled count=1 msg=Container image ""busybox:musl"" already present on machine"
0.302,Event,ADDED,eval-conflicts-rho010-r4-064-75fts.18d466c77abca989,reason=Created count=1 msg=Created container: task
0.3022,Event,ADDED,eval-conflicts-rho010-r4-064-75fts.18d466c77f82b9b4,reason=Started count=1 msg=Started container task
0.3024,Event,ADDED,eval-conflicts-rho010-r4-064.18d466c748de55c3,reason=SuccessfulCreate count=1 msg=Created pod: eval-conflicts-rho010-r4-064-75fts
0.3026,Event,ADDED,eval-conflicts-rho010-r4-064.18d466caae25e07e,reason=Completed count=1 msg=Job completed
0.3029,Event,ADDED,eval-conflicts-rho010-r4-065-b2t4l.18d466c78abd2053,reason=Scheduled count=None msg=Successfully assigned compute/eval-conflicts-rho010-r4-065-b2t4l to kind-worker2
0.3031,Event,ADDED,eval-conflicts-rho010-r4-065-b2t4l.18d466c7ab9fac6c,"reason=Pulled count=1 msg=Container image ""busybox:musl"" already present on machine"
0.3033,Event,ADDED,eval-conflicts-rho010-r4-065-b2t4l.18d466c7acdcca88,reason=Created count=1 msg=Created container: task
0.3036,Event,ADDED,eval-conflicts-rho010-r4-065-b2t4l.18d466c7b5e1e800,reason=Started count=1 msg=Started container task
0.3038,Event,ADDED,eval-conflicts-rho010-r4-065.18d466c789c65504,reason=SuccessfulCreate count=1 msg=Created pod: eval-conflicts-rho010-r4-065-b2t4l
0.3041,Event,ADDED,eval-conflicts-rho010-r4-065.18d466cae1dca204,reason=Completed count=1 msg=Job completed
0.3043,Event,ADDED,eval-conflicts-rho010-r4-066-5j998.18d466c7c0b16468,reason=Scheduled count=None msg=Successfully assigned compute/eval-conflicts-rho010-r4-066-5j998 to kind-worker5
0.3046,Event,ADDED,eval-conflicts-rho010-r4-066-5j998.18d466c7da3a5669,"reason=Pulled count=1 msg=Container image ""busybox:musl"" already present on machine"
0.3048,Event,ADDED,eval-conflicts-rho010-r4-066-5j998.18d466c7db49222d,reason=Created count=1 msg=Created container: task
0.305,Event,ADDED,eval-conflicts-rho010-r4-066-5j998.18d466c7e281e2c6,reason=Started count=1 msg=Started container task
0.3053,Event,ADDED,eval-conflicts-rho010-r4-066.18d466c7bfddadcb,reason=SuccessfulCreate count=1 msg=Created pod: eval-conflicts-rho010-r4-066-5j998
0.3054,Event,ADDED,eval-conflicts-rho010-r4-066.18d466cb1d73e431,reason=Completed count=1 msg=Job completed
0.3056,Event,ADDED,eval-conflicts-rho010-r4-067-8jn26.18d466c7fd2a2d52,reason=Scheduled count=None msg=Successfully assigned compute/eval-conflicts-rho010-r4-067-8jn26 to kind-worker5
0.3058,Event,ADDED,eval-conflicts-rho010-r4-067-8jn26.18d466c81c3070dd,"reason=Pulled count=1 msg=Container image ""busybox:musl"" already present on machine"
0.3059,Event,ADDED,eval-conflicts-rho010-r4-067-8jn26.18d466c81d480aa5,reason=Created count=1 msg=Created container: task
0.3061,Event,ADDED,eval-conflicts-rho010-r4-067-8jn26.18d466c824e6baee,reason=Started count=1 msg=Started container task
0.3063,Event,ADDED,eval-conflicts-rho010-r4-067.18d466c7fc1c0623,reason=SuccessfulCreate count=1 msg=Created pod: eval-conflicts-rho010-r4-067-8jn26
0.3064,Event,ADDED,eval-conflicts-rho010-r4-067.18d466cb59017d74,reason=Completed count=1 msg=Job completed
0.3066,Event,ADDED,eval-conflicts-rho010-r4-068-7592l.18d466c83fd8a5e2,reason=Scheduled count=None msg=Successfully assigned compute/eval-conflicts-rho010-r4-068-7592l to kind-worker5
0.3068,Event,ADDED,eval-conflicts-rho010-r4-068-7592l.18d466c85c1a8414,"reason=Pulled count=1 msg=Container image ""busybox:musl"" already present on machine"
0.3069,Event,ADDED,eval-conflicts-rho010-r4-068-7592l.18d466c85d422838,reason=Created count=1 msg=Created container: task
0.3071,Event,ADDED,eval-conflicts-rho010-r4-068-7592l.18d466c8676ee2ca,reason=Started count=1 msg=Started container task
0.3073,Event,ADDED,eval-conflicts-rho010-r4-068.18d466c83e978e06,reason=SuccessfulCreate count=1 msg=Created pod: eval-conflicts-rho010-r4-068-7592l
0.3074,Event,ADDED,eval-conflicts-rho010-r4-068.18d466cb94e65d42,reason=Completed count=1 msg=Job completed
0.3076,Event,ADDED,eval-conflicts-rho010-r4-069-n9wpr.18d466c8748f07c9,reason=Scheduled count=None msg=Successfully assigned compute/eval-conflicts-rho010-r4-069-n9wpr to kind-worker2
0.3078,Event,ADDED,eval-conflicts-rho010-r4-069-n9wpr.18d466c8a58c8d9d,"reason=Pulled count=1 msg=Container image ""busybox:musl"" already present on machine"
0.3079,Event,ADDED,eval-conflicts-rho010-r4-069-n9wpr.18d466c8a6ac681f,reason=Created count=1 msg=Created container: task
0.3082,Event,ADDED,eval-conflicts-rho010-r4-069-n9wpr.18d466c8ab363552,reason=Started count=1 msg=Started container task
0.3083,Event,ADDED,eval-conflicts-rho010-r4-069.18d466c873503a15,reason=SuccessfulCreate count=1 msg=Created pod: eval-conflicts-rho010-r4-069-n9wpr
0.3087,Event,ADDED,eval-conflicts-rho010-r4-069.18d466cbd146e55d,reason=Completed count=1 msg=Job completed
0.3089,Event,ADDED,eval-conflicts-rho010-r4-070-2xcl4.18d466c8b00dba2c,reason=Scheduled count=None msg=Successfully assigned compute/eval-conflicts-rho010-r4-070-2xcl4 to kind-worker5
0.3091,Event,ADDED,eval-conflicts-rho010-r4-070-2xcl4.18d466c8cee7d592,"reason=Pulled count=1 msg=Container image ""busybox:musl"" already present on machine"
0.3094,Event,ADDED,eval-conflicts-rho010-r4-070-2xcl4.18d466c8d02934e4,reason=Created count=1 msg=Created container: task
0.3096,Event,ADDED,eval-conflicts-rho010-r4-070-2xcl4.18d466c8d5b26bb9,reason=Started count=1 msg=Started container task
0.3098,Event,ADDED,eval-conflicts-rho010-r4-070.18d466c8aee9ff71,reason=SuccessfulCreate count=1 msg=Created pod: eval-conflicts-rho010-r4-070-2xcl4
0.3099,Event,ADDED,eval-conflicts-rho010-r4-070.18d466cc0ca7a4ce,reason=Completed count=1 msg=Job completed
0.3103,Event,ADDED,eval-conflicts-rho010-r4-071-7kbbg.18d466c8eb906b04,reason=Scheduled count=None msg=Successfully assigned compute/eval-conflicts-rho010-r4-071-7kbbg to kind-worker2
0.3105,Event,ADDED,eval-conflicts-rho010-r4-071-7kbbg.18d466c906647a31,"reason=Pulled count=1 msg=Container image ""busybox:musl"" already present on machine"
0.3107,Event,ADDED,eval-conflicts-rho010-r4-071-7kbbg.18d466c9078fff48,reason=Created count=1 msg=Created container: task
0.311,Event,ADDED,eval-conflicts-rho010-r4-071-7kbbg.18d466c90ae6a45a,reason=Started count=1 msg=Started container task
0.3112,Event,ADDED,eval-conflicts-rho010-r4-071.18d466c8ea57a9bc,reason=SuccessfulCreate count=1 msg=Created pod: eval-conflicts-rho010-r4-071-7kbbg
0.3114,Event,ADDED,eval-conflicts-rho010-r4-071.18d466cc489c7c50,reason=Completed count=1 msg=Job completed
0.3115,Event,ADDED,eval-conflicts-rho010-r4-072-mfc4b.18d466c927621257,reason=Scheduled count=None msg=Successfully assigned compute/eval-conflicts-rho010-r4-072-mfc4b to kind-worker5
0.3117,Event,ADDED,eval-conflicts-rho010-r4-072-mfc4b.18d466c940460bfd,"reason=Pulled count=1 msg=Container image ""busybox:musl"" already present on machine"
0.3119,Event,ADDED,eval-conflicts-rho010-r4-072-mfc4b.18d466c9417485ee,reason=Created count=1 msg=Created container: task
0.3122,Event,ADDED,eval-conflicts-rho010-r4-072-mfc4b.18d466c943ec8339,reason=Started count=1 msg=Started container task
0.3124,Event,ADDED,eval-conflicts-rho010-r4-072.18d466c9261c2424,reason=SuccessfulCreate count=1 msg=Created pod: eval-conflicts-rho010-r4-072-mfc4b
0.3128,Event,ADDED,eval-conflicts-rho010-r4-072.18d466cc847683ca,reason=Completed count=1 msg=Job completed
0.313,Event,ADDED,eval-conflicts-rho010-r4-073-b4ngc.18d466c9627a4e76,reason=Scheduled count=None msg=Successfully assigned compute/eval-conflicts-rho010-r4-073-b4ngc to kind-worker2
0.3132,Event,ADDED,eval-conflicts-rho010-r4-073-b4ngc.18d466c97b95323f,"reason=Pulled count=1 msg=Container image ""busybox:musl"" already present on machine"
0.3134,Event,ADDED,eval-conflicts-rho010-r4-073-b4ngc.18d466c97cd06e1a,reason=Created count=1 msg=Created container: task
0.3137,Event,ADDED,eval-conflicts-rho010-r4-073-b4ngc.18d466c9816568b5,reason=Started count=1 msg=Started container task
0.3139,Event,ADDED,eval-conflicts-rho010-r4-073.18d466c96132bfdf,reason=SuccessfulCreate count=1 msg=Created pod: eval-conflicts-rho010-r4-073-b4ngc
0.314,Event,ADDED,eval-conflicts-rho010-r4-073.18d466ccc05df3cc,reason=Completed count=1 msg=Job completed
0.3144,Event,ADDED,eval-conflicts-rho010-r4-074-wdlvj.18d466c99e586bee,reason=Scheduled count=None msg=Successfully assigned compute/eval-conflicts-rho010-r4-074-wdlvj to kind-worker2
0.3145,Event,ADDED,eval-conflicts-rho010-r4-074-wdlvj.18d466c9b9833e64,"reason=Pulled count=1 msg=Container image ""busybox:musl"" already present on machine"
0.3147,Event,ADDED,eval-conflicts-rho010-r4-074-wdlvj.18d466c9bac5a3ff,reason=Created count=1 msg=Created container: task
0.3151,Event,ADDED,eval-conflicts-rho010-r4-074-wdlvj.18d466c9bd2969e2,reason=Started count=1 msg=Started container task
0.3153,Event,ADDED,eval-conflicts-rho010-r4-074.18d466c99d28b3a8,reason=SuccessfulCreate count=1 msg=Created pod: eval-conflicts-rho010-r4-074-wdlvj
0.3155,Event,ADDED,eval-conflicts-rho010-r4-074.18d466ccfc2c5668,reason=Completed count=1 msg=Job completed
0.3156,Event,ADDED,eval-conflicts-rho010-r4-075-97tpz.18d466c9d9c46cbd,reason=Scheduled count=None msg=Successfully assigned compute/eval-conflicts-rho010-r4-075-97tpz to kind-worker5
0.3161,Event,ADDED,eval-conflicts-rho010-r4-075-97tpz.18d466c9f49f56e1,"reason=Pulled count=1 msg=Container image ""busybox:musl"" already present on machine"
0.3163,Event,ADDED,eval-conflicts-rho010-r4-075-97tpz.18d466c9f5bdfb01,reason=Created count=1 msg=Created container: task
0.3165,Event,ADDED,eval-conflicts-rho010-r4-075-97tpz.18d466c9f7c92976,reason=Started count=1 msg=Started container task
0.3167,Event,ADDED,eval-conflicts-rho010-r4-075.18d466c9d936cbda,reason=SuccessfulCreate count=1 msg=Created pod: eval-conflicts-rho010-r4-075-97tpz
0.3169,Event,ADDED,eval-conflicts-rho010-r4-075.18d466cd3843f22f,reason=Completed count=1 msg=Job completed
0.3171,Event,ADDED,eval-conflicts-rho010-r4-076-pv75k.18d466ca147e1a16,"reason=FailedScheduling count=None msg=0/6 nodes are available: 6 node(s) had untolerated taint(s). no new claims to deallocate, preemption: 0/6 nodes are available: 6 Preemption is not helpful for scheduling."
0.3172,Event,ADDED,eval-conflicts-rho010-r4-076-pv75k.18d466cba8572f1c,reason=Scheduled count=None msg=Successfully assigned compute/eval-conflicts-rho010-r4-076-pv75k to kind-worker
0.3174,Event,ADDED,eval-conflicts-rho010-r4-076-pv75k.18d466cbc2aa3986,"reason=Pulled count=1 msg=Container image ""busybox:musl"" already present on machine"
0.3176,Event,ADDED,eval-conflicts-rho010-r4-076-pv75k.18d466cbc4a41576,reason=Created count=1 msg=Created container: task
0.3177,Event,ADDED,eval-conflicts-rho010-r4-076-pv75k.18d466cbc6aeab1b,reason=Started count=1 msg=Started container task
0.3179,Event,ADDED,eval-conflicts-rho010-r4-076.18d466ca1475bad4,reason=SuccessfulCreate count=1 msg=Created pod: eval-conflicts-rho010-r4-076-pv75k
0.3181,Event,ADDED,eval-conflicts-rho010-r4-076.18d466cf0812d732,reason=Completed count=1 msg=Job completed
0.3182,Event,ADDED,eval-conflicts-rho010-r4-077-9h742.18d466ca50b89864,"reason=FailedScheduling count=None msg=0/6 nodes are available: 6 node(s) had untolerated taint(s). no new claims to deallocate, preemption: 0/6 nodes are available: 6 Preemption is not helpful for scheduling."
0.3184,Event,ADDED,eval-conflicts-rho010-r4-077-9h742.18d466cba88b7fd0,"reason=FailedScheduling count=None msg=0/6 nodes are available: 1 c_wall violated: 1 conflicting context pair(s) with node memory, 5 node(s) had untolerated taint(s). no new claims to deallocate, preemption: 0/6 nodes are available: 1 No preemption victims found for incoming pod, 5 Preemption is not helpful for scheduling."
0.3187,Event,ADDED,eval-conflicts-rho010-r4-077-9h742.18d466cbb2bc7cdd,"reason=FailedScheduling count=None msg=0/6 nodes are available: 1 c_wall violated: 1 conflicting context pair(s) with node memory, 5 node(s) had untolerated taint(s). no new claims to deallocate, preemption: 0/6 nodes are available: 1 No preemption victims found for incoming pod, 5 Preemption is not helpful for scheduling."
0.3189,Event,ADDED,eval-conflicts-rho010-r4-077-9h742.18d466cbeaf2dfc9,reason=Scheduled count=None msg=Successfully assigned compute/eval-conflicts-rho010-r4-077-9h742 to kind-worker3
0.319,Event,ADDED,eval-conflicts-rho010-r4-077-9h742.18d466cc041798a4,"reason=Pulled count=1 msg=Container image ""busybox:musl"" already present on machine"
0.3192,Event,ADDED,eval-conflicts-rho010-r4-077-9h742.18d466cc05772ff8,reason=Created count=1 msg=Created container: task
0.3194,Event,ADDED,eval-conflicts-rho010-r4-077-9h742.18d466cc07650700,reason=Started count=1 msg=Started container task
0.3195,Event,ADDED,eval-conflicts-rho010-r4-077.18d466ca50b00fc1,reason=SuccessfulCreate count=1 msg=Created pod: eval-conflicts-rho010-r4-077-9h742
0.3198,Event,ADDED,eval-conflicts-rho010-r4-077.18d466cf3c5a0d00,reason=Completed count=1 msg=Job completed
0.3202,Event,ADDED,eval-conflicts-rho010-r4-078-mwhvj.18d466ca8bb834ae,"reason=FailedScheduling count=None msg=0/6 nodes are available: 6 node(s) had untolerated taint(s). no new claims to deallocate, preemption: 0/6 nodes are available: 6 Preemption is not helpful for scheduling."
0.3204,Event,ADDED,eval-conflicts-rho010-r4-078-mwhvj.18d466cba9757595,reason=Scheduled count=None msg=Successfully assigned compute/eval-conflicts-rho010-r4-078-mwhvj to kind-worker
0.3205,Event,ADDED,eval-conflicts-rho010-r4-078-mwhvj.18d466cbc3ef400b,"reason=Pulled count=1 msg=Container image ""busybox:musl"" already present on machine"
0.3208,Event,ADDED,eval-conflicts-rho010-r4-078-mwhvj.18d466cbc73b27c6,reason=Created count=1 msg=Created container: task
0.3211,Event,ADDED,eval-conflicts-rho010-r4-078-mwhvj.18d466cbc9ed4b3d,reason=Started count=1 msg=Started container task
0.3213,Event,ADDED,eval-conflicts-rho010-r4-078.18d466ca8baa225a,reason=SuccessfulCreate count=1 msg=Created pod: eval-conflicts-rho010-r4-078-mwhvj
0.3215,Event,ADDED,eval-conflicts-rho010-r4-078.18d466cf07ab09b3,reason=Completed count=1 msg=Job completed
0.3218,Event,ADDED,eval-conflicts-rho010-r4-079-6wtsn.18d466cac755225f,"reason=FailedScheduling count=None msg=0/6 nodes are available: 6 node(s) had untolerated taint(s). no new claims to deallocate, preemption: 0/6 nodes are available: 6 Preemption is not helpful for scheduling."
0.3219,Event,ADDED,eval-conflicts-rho010-r4-079-6wtsn.18d466cba99e873f,reason=Scheduled count=None msg=Successfully assigned compute/eval-conflicts-rho010-r4-079-6wtsn to kind-worker
0.3221,Event,ADDED,eval-conflicts-rho010-r4-079-6wtsn.18d466cbc4102b27,"reason=Pulled count=1 msg=Container image ""busybox:musl"" already present on machine"
0.3223,Event,ADDED,eval-conflicts-rho010-r4-079-6wtsn.18d466cbc7c94fb2,reason=Created count=1 msg=Created container: task
0.3225,Event,ADDED,eval-conflicts-rho010-r4-079-6wtsn.18d466cbca7443a2,reason=Started count=1 msg=Started container task
0.3227,Event,ADDED,eval-conflicts-rho010-r4-079.18d466cac74bf939,reason=SuccessfulCreate count=1 msg=Created pod: eval-conflicts-rho010-r4-079-6wtsn
0.3228,Event,ADDED,eval-conflicts-rho010-r4-079.18d466cf088626a6,reason=Completed count=1 msg=Job completed
0.323,Event,ADDED,eval-conflicts-rho010-r4-080-77kmd.18d466cb029ff80c,"reason=FailedScheduling count=None msg=0/6 nodes are available: 6 node(s) had untolerated taint(s). no new claims to deallocate, preemption: 0/6 nodes are available: 6 Preemption is not helpful for scheduling."
0.3234,Event,ADDED,eval-conflicts-rho010-r4-080-77kmd.18d466cbacccd813,reason=Scheduled count=None msg=Successfully assigned compute/eval-conflicts-rho010-r4-080-77kmd to kind-worker
0.3237,Event,ADDED,eval-conflicts-rho010-r4-080-77kmd.18d466cbc4acfacc,"reason=Pulled count=1 msg=Container image ""busybox:musl"" already present on machine"
0.3239,Event,ADDED,eval-conflicts-rho010-r4-080-77kmd.18d466cbc787ef2b,reason=Created count=1 msg=Created container: task
0.3243,Event,ADDED,eval-conflicts-rho010-r4-080-77kmd.18d466cbc9ed89ec,reason=Started count=1 msg=Started container task
0.3244,Event,ADDED,eval-conflicts-rho010-r4-080.18d466cb0296f912,reason=SuccessfulCreate count=1 msg=Created pod: eval-conflicts-rho010-r4-080-77kmd
0.3246,Event,ADDED,eval-conflicts-rho010-r4-080.18d466cf0781a264,reason=Completed count=1 msg=Job completed
0.3248,Event,ADDED,eval-conflicts-rho010-r4-081-b5xbp.18d466cb3e408d9b,"reason=FailedScheduling count=None msg=0/6 nodes are available: 6 node(s) had untolerated taint(s). no new claims to deallocate, preemption: 0/6 nodes are available: 6 Preemption is not helpful for scheduling."
0.3254,Event,ADDED,eval-conflicts-rho010-r4-081-b5xbp.18d466cbacd7d63d,reason=Scheduled count=None msg=Successfully assigned compute/eval-conflicts-rho010-r4-081-b5xbp to kind-worker
0.3256,Event,ADDED,eval-conflicts-rho010-r4-081-b5xbp.18d466cbc4c9b100,"reason=Pulled count=1 msg=Container image ""busybox:musl"" already present on machine"
0.3257,Event,ADDED,eval-conflicts-rho010-r4-081-b5xbp.18d466cbc859d4df,reason=Created count=1 msg=Created container: task
0.3261,Event,ADDED,eval-conflicts-rho010-r4-081-b5xbp.18d466cbcb475b9a,reason=Started count=1 msg=Started container task
0.3262,Event,ADDED,eval-conflicts-rho010-r4-081.18d466cb3e336403,reason=SuccessfulCreate count=1 msg=Created pod: eval-conflicts-rho010-r4-081-b5xbp
0.3264,Event,ADDED,eval-conflicts-rho010-r4-081.18d466cf08ebea8c,reason=Completed count=1 msg=Job completed
0.3266,Event,ADDED,eval-conflicts-rho010-r4-082-2svnh.18d466cb79e597a3,"reason=FailedScheduling count=None msg=0/6 nodes are available: 6 node(s) had untolerated taint(s). no new claims to deallocate, preemption: 0/6 nodes are available: 6 Preemption is not helpful for scheduling."
0.3268,Event,ADDED,eval-conflicts-rho010-r4-082-2svnh.18d466cbad1c2b49,reason=Scheduled count=None msg=Successfully assigned compute/eval-conflicts-rho010-r4-082-2svnh to kind-worker
0.327,Event,ADDED,eval-conflicts-rho010-r4-082-2svnh.18d466cbc5e0623b,"reason=Pulled count=1 msg=Container image ""busybox:musl"" already present on machine"
0.3272,Event,ADDED,eval-conflicts-rho010-r4-082-2svnh.18d466cbc89c534f,reason=Created count=1 msg=Created container: task
0.3275,Event,ADDED,eval-conflicts-rho010-r4-082-2svnh.18d466cbcb475b90,reason=Started count=1 msg=Started container task
0.3277,Event,ADDED,eval-conflicts-rho010-r4-082.18d466cb79db14bd,reason=SuccessfulCreate count=1 msg=Created pod: eval-conflicts-rho010-r4-082-2svnh
0.3279,Event,ADDED,eval-conflicts-rho010-r4-082.18d466cecdeec81b,reason=Completed count=1 msg=Job completed
0.328,Event,ADDED,eval-conflicts-rho010-r4-083-8txvg.18d466cbb68a0ba4,reason=Scheduled count=None msg=Successfully assigned compute/eval-conflicts-rho010-r4-083-8txvg to kind-worker
0.3283,Event,ADDED,eval-conflicts-rho010-r4-083-8txvg.18d466cbd0179ce1,"reason=Pulled count=1 msg=Container image ""busybox:musl"" already present on machine"
0.3284,Event,ADDED,eval-conflicts-rho010-r4-083-8txvg.18d466cbd1b5aa0a,reason=Created count=1 msg=Created container: task
0.3286,Event,ADDED,eval-conflicts-rho010-r4-083-8txvg.18d466cbd5e4c96e,reason=Started count=1 msg=Started container task
0.3288,Event,ADDED,eval-conflicts-rho010-r4-083.18d466cbb6077d21,reason=SuccessfulCreate count=1 msg=Created pod: eval-conflicts-rho010-r4-083-8txvg
0.329,Event,ADDED,eval-conflicts-rho010-r4-083.18d466cf07c7a222,reason=Completed count=1 msg=Job completed
0.3291,Event,ADDED,eval-conflicts-rho010-r4-084-z9zq2.18d466cbf16be6ee,reason=Scheduled count=None msg=Successfully assigned compute/eval-conflicts-rho010-r4-084-z9zq2 to kind-worker3
0.3293,Event,ADDED,eval-conflicts-rho010-r4-084-z9zq2.18d466cc0899e714,"reason=Pulled count=1 msg=Container image ""busybox:musl"" already present on machine"
0.3295,Event,ADDED,eval-conflicts-rho010-r4-084-z9zq2.18d466cc09a1f76b,reason=Created count=1 msg=Created container: task
0.3297,Event,ADDED,eval-conflicts-rho010-r4-084-z9zq2.18d466cc0d3d3a0e,reason=Started count=1 msg=Started container task
0.3299,Event,ADDED,eval-conflicts-rho010-r4-084.18d466cbf0aab96f,reason=SuccessfulCreate count=1 msg=Created pod: eval-conflicts-rho010-r4-084-z9zq2
0.33,Event,ADDED,eval-conflicts-rho010-r4-084.18d466cf3c36c6a7,reason=Completed count=1 msg=Job completed
0.3303,Event,ADDED,eval-conflicts-rho010-r4-085-vglh2.18d466cc2e3c7ee2,reason=Scheduled count=None msg=Successfully assigned compute/eval-conflicts-rho010-r4-085-vglh2 to kind-worker4
0.3304,Event,ADDED,eval-conflicts-rho010-r4-085-vglh2.18d466cc472cd3a4,"reason=Pulled count=1 msg=Container image ""busybox:musl"" already present on machine"
0.3306,Event,ADDED,eval-conflicts-rho010-r4-085-vglh2.18d466cc48bdce7e,reason=Created count=1 msg=Created container: task
0.3308,Event,ADDED,eval-conflicts-rho010-r4-085-vglh2.18d466cc4cd5cc17,reason=Started count=1 msg=Started container task
0.331,Event,ADDED,eval-conflicts-rho010-r4-085.18d466cc2cf7e55f,reason=SuccessfulCreate count=1 msg=Created pod: eval-conflicts-rho010-r4-085-vglh2
0.3312,Event,ADDED,eval-conflicts-rho010-r4-085.18d466cf931769cf,reason=Completed count=1 msg=Job completed
0.3313,Event,ADDED,eval-conflicts-rho010-r4-086-b9xrt.18d466cc695bbf2e,reason=Scheduled count=None msg=Successfully assigned compute/eval-conflicts-rho010-r4-086-b9xrt to kind-worker4
0.3315,Event,ADDED,eval-conflicts-rho010-r4-086-b9xrt.18d466cc827dfe63,"reason=Pulled count=1 msg=Container image ""busybox:musl"" already present on machine"
0.3317,Event,ADDED,eval-conflicts-rho010-r4-086-b9xrt.18d466cc83ceed36,reason=Created count=1 msg=Created container: task
0.3318,Event,ADDED,eval-conflicts-rho010-r4-086-b9xrt.18d466cc8bf01612,reason=Started count=1 msg=Started container task
0.3321,Event,ADDED,eval-conflicts-rho010-r4-086.18d466cc68320f37,reason=SuccessfulCreate count=1 msg=Created pod: eval-conflicts-rho010-r4-086-b9xrt
0.3324,Event,ADDED,eval-conflicts-rho010-r4-086.18d466cfcf30fc18,reason=Completed count=1 msg=Job completed
0.3325,Event,ADDED,eval-conflicts-rho010-r4-087-trdn4.18d466cca590fc57,reason=Scheduled count=None msg=Successfully assigned compute/eval-conflicts-rho010-r4-087-trdn4 to kind-worker3
0.3327,Event,ADDED,eval-conflicts-rho010-r4-087-trdn4.18d466ccbec1f17f,"reason=Pulled count=1 msg=Container image ""busybox:musl"" already present on machine"
0.3329,Event,ADDED,eval-conflicts-rho010-r4-087-trdn4.18d466ccc0c18004,reason=Created count=1 msg=Created container: task
0.3331,Event,ADDED,eval-conflicts-rho010-r4-087-trdn4.18d466ccc7167a3a,reason=Started count=1 msg=Started container task
0.3333,Event,ADDED,eval-conflicts-rho010-r4-087.18d466cca4b2b434,reason=SuccessfulCreate count=1 msg=Created pod: eval-conflicts-rho010-r4-087-trdn4
0.3334,Event,ADDED,eval-conflicts-rho010-r4-087.18d466cfefc860ff,reason=Completed count=1 msg=Job completed
0.3336,Event,ADDED,eval-conflicts-rho010-r4-088-44xkz.18d466cce08dccec,reason=Scheduled count=None msg=Successfully assigned compute/eval-conflicts-rho010-r4-088-44xkz to kind-worker4
0.3338,Event,ADDED,eval-conflicts-rho010-r4-088-44xkz.18d466ccfa1081f2,"reason=Pulled count=1 msg=Container image ""busybox:musl"" already present on machine"
0.3339,Event,ADDED,eval-conflicts-rho010-r4-088-44xkz.18d466ccfb40bc21,reason=Created count=1 msg=Created container: task
0.3341,Event,ADDED,eval-conflicts-rho010-r4-088-44xkz.18d466cd014e8a8b,reason=Started count=1 msg=Started container task
0.3343,Event,ADDED,eval-conflicts-rho010-r4-088.18d466ccdf67a617,reason=SuccessfulCreate count=1 msg=Created pod: eval-conflicts-rho010-r4-088-44xkz
0.3344,Event,ADDED,eval-conflicts-rho010-r4-088.18d466d046f5ad52,reason=Completed count=1 msg=Job completed
0.3346,Event,ADDED,eval-conflicts-rho010-r4-089-599rf.18d466cd1c81a313,reason=Scheduled count=None msg=Successfully assigned compute/eval-conflicts-rho010-r4-089-599rf to kind-worker4
0.3352,Event,ADDED,eval-conflicts-rho010-r4-089-599rf.18d466cd3631e82f,"reason=Pulled count=1 msg=Container image ""busybox:musl"" already present on machine"
0.3356,Event,ADDED,eval-conflicts-rho010-r4-089-599rf.18d466cd374117f5,reason=Created count=1 msg=Created container: task
0.3358,Event,ADDED,eval-conflicts-rho010-r4-089-599rf.18d466cd3940c591,reason=Started count=1 msg=Started container task
0.336,Event,ADDED,eval-conflicts-rho010-r4-089.18d466cd1b1863b6,reason=SuccessfulCreate count=1 msg=Created pod: eval-conflicts-rho010-r4-089-599rf
0.3364,Event,ADDED,eval-conflicts-rho010-r4-089.18d466d047bb47e9,reason=Completed count=1 msg=Job completed
0.3367,Event,ADDED,eval-conflicts-rho010-r4-090-x84fj.18d466cd5811d859,reason=Scheduled count=None msg=Successfully assigned compute/eval-conflicts-rho010-r4-090-x84fj to kind-worker4
0.3369,Event,ADDED,eval-conflicts-rho010-r4-090-x84fj.18d466cd70661bb9,"reason=Pulled count=1 msg=Container image ""busybox:musl"" already present on machine"
0.3371,Event,ADDED,eval-conflicts-rho010-r4-090-x84fj.18d466cd7184a92e,reason=Created count=1 msg=Created container: task
0.3373,Event,ADDED,eval-conflicts-rho010-r4-090-x84fj.18d466cd739131ce,reason=Started count=1 msg=Started container task
0.3375,Event,ADDED,eval-conflicts-rho010-r4-090.18d466cd56a0cb2d,reason=SuccessfulCreate count=1 msg=Created pod: eval-conflicts-rho010-r4-090-x84fj
0.3377,Event,ADDED,eval-conflicts-rho010-r4-090.18d466d0835ba4c8,reason=Completed count=1 msg=Job completed
0.338,Event,ADDED,eval-conflicts-rho010-r4-091-vc9t7.18d466cd93a1e9b4,reason=Scheduled count=None msg=Successfully assigned compute/eval-conflicts-rho010-r4-091-vc9t7 to kind-worker
0.3382,Event,ADDED,eval-conflicts-rho010-r4-091-vc9t7.18d466cdadb5cea0,"reason=Pulled count=1 msg=Container image ""busybox:musl"" already present on machine"
0.3384,Event,ADDED,eval-conflicts-rho010-r4-091-vc9t7.18d466cdaedded28,reason=Created count=1 msg=Created container: task
0.3386,Event,ADDED,eval-conflicts-rho010-r4-091-vc9t7.18d466cdb0e37e89,reason=Started count=1 msg=Started container task
0.339,Event,ADDED,eval-conflicts-rho010-r4-091.18d466cd925cf0a2,reason=SuccessfulCreate count=1 msg=Created pod: eval-conflicts-rho010-r4-091-vc9t7
0.3392,Event,ADDED,eval-conflicts-rho010-r4-091.18d466d0e5c5d308,reason=Completed count=1 msg=Job completed
0.3393,Event,ADDED,eval-conflicts-rho010-r4-092-j7mvc.18d466cdcf320946,reason=Scheduled count=None msg=Successfully assigned compute/eval-conflicts-rho010-r4-092-j7mvc to kind-worker4
0.3396,Event,ADDED,eval-conflicts-rho010-r4-092-j7mvc.18d466cde947bbe7,"reason=Pulled count=1 msg=Container image ""busybox:musl"" already present on machine"
0.3398,Event,ADDED,eval-conflicts-rho010-r4-092-j7mvc.18d466cdea75ef5d,reason=Created count=1 msg=Created container: task
0.3401,Event,ADDED,eval-conflicts-rho010-r4-092-j7mvc.18d466cdecfad227,reason=Started count=1 msg=Started container task
0.3403,Event,ADDED,eval-conflicts-rho010-r4-092.18d466cdcde36572,reason=SuccessfulCreate count=1 msg=Created pod: eval-conflicts-rho010-r4-092-j7mvc
0.3407,Event,ADDED,eval-conflicts-rho010-r4-092.18d466d0faa86bc8,reason=Completed count=1 msg=Job completed
0.3409,Event,ADDED,eval-conflicts-rho010-r4-093-cxvvz.18d466ce09fb392e,"reason=FailedScheduling count=None msg=0/6 nodes are available: 2 c_wall violated: 1 conflicting context pair(s) with node memory, 4 node(s) had untolerated taint(s). no new claims to deallocate, preemption: 0/6 nodes are available: 2 No preemption victims found for incoming pod, 4 Preemption is not helpful for scheduling."
0.3411,Event,ADDED,eval-conflicts-rho010-r4-093-cxvvz.18d466ce0aba81bf,"reason=FailedScheduling count=None msg=0/6 nodes are available: 2 c_wall violated: 1 conflicting context pair(s) with node memory, 4 node(s) had untolerated taint(s). no new claims to deallocate, preemption: 0/6 nodes are available: 2 No preemption victims found for incoming pod, 4 Preemption is not helpful for scheduling."
0.3415,Event,ADDED,eval-conflicts-rho010-r4-093-cxvvz.18d466ce4066f960,"reason=FailedScheduling count=None msg=0/6 nodes are available: 1 c_wall violated: 1 conflicting context pair(s) with node memory, 5 node(s) had untolerated taint(s). no new claims to deallocate, preemption: 0/6 nodes are available: 1 No preemption victims found for incoming pod, 5 Preemption is not helpful for scheduling."
0.3416,Event,ADDED,eval-conflicts-rho010-r4-093-cxvvz.18d466ce8b7362a5,reason=Scheduled count=None msg=Successfully assigned compute/eval-conflicts-rho010-r4-093-cxvvz to kind-worker2
0.3418,Event,ADDED,eval-conflicts-rho010-r4-093-cxvvz.18d466cea40d3195,"reason=Pulled count=1 msg=Container image ""busybox:musl"" already present on machine"
0.342,Event,ADDED,eval-conflicts-rho010-r4-093-cxvvz.18d466cea534cb99,reason=Created count=1 msg=Created container: task
0.3423,Event,ADDED,eval-conflicts-rho010-r4-093-cxvvz.18d466cea8d2e6c5,reason=Started count=1 msg=Started container task
0.3425,Event,ADDED,eval-conflicts-rho010-r4-093.18d466ce098f9b60,reason=SuccessfulCreate count=1 msg=Created pod: eval-conflicts-rho010-r4-093-cxvvz
0.3426,Event,ADDED,eval-conflicts-rho010-r4-093.18d466d1e2c4c624,reason=Completed count=1 msg=Job completed
0.3428,Event,ADDED,eval-conflicts-rho010-r4-094-dcn45.18d466ce45c826df,reason=Scheduled count=None msg=Successfully assigned compute/eval-conflicts-rho010-r4-094-dcn45 to kind-worker4
0.343,Event,ADDED,eval-conflicts-rho010-r4-094-dcn45.18d466ce5f80cf26,"reason=Pulled count=1 msg=Container image ""busybox:musl"" already present on machine"
0.3431,Event,ADDED,eval-conflicts-rho010-r4-094-dcn45.18d466ce60983861,reason=Created count=1 msg=Created container: task
0.3433,Event,ADDED,eval-conflicts-rho010-r4-094-dcn45.18d466ce62854bd3,reason=Started count=1 msg=Started container task
0.3435,Event,ADDED,eval-conflicts-rho010-r4-094.18d466ce4554027a,reason=SuccessfulCreate count=1 msg=Created pod: eval-conflicts-rho010-r4-094-dcn45
0.3436,Event,ADDED,eval-conflicts-rho010-r4-094.18d466d1725817c5,reason=Completed count=1 msg=Job completed
0.3438,Event,ADDED,eval-conflicts-rho010-r4-095-xhspn.18d466ce80999bd9,"reason=FailedScheduling count=None msg=0/6 nodes are available: 6 node(s) had untolerated taint(s). no new claims to deallocate, preemption: 0/6 nodes are available: 6 Preemption is not helpful for scheduling."
0.344,Event,ADDED,eval-conflicts-rho010-r4-095-xhspn.18d466ce8b57d332,"reason=FailedScheduling count=None msg=0/6 nodes are available: 1 c_wall violated: 1 conflicting context pair(s) with node memory, 5 node(s) had untolerated taint(s). no new claims to deallocate, preemption: 0/6 nodes are available: 1 No preemption victims found for incoming pod, 5 Preemption is not helpful for scheduling."
0.3442,Event,ADDED,eval-conflicts-rho010-r4-095-xhspn.18d466ce8c3fdb3e,"reason=FailedScheduling count=None msg=0/6 nodes are available: 1 c_wall violated: 1 conflicting context pair(s) with node memory, 5 node(s) had untolerated taint(s). no new claims to deallocate, preemption: 0/6 nodes are available: 1 No preemption victims found for incoming pod, 5 Preemption is not helpful for scheduling."
0.3444,Event,ADDED,eval-conflicts-rho010-r4-095-xhspn.18d466ced9cb2820,reason=Scheduled count=None msg=Successfully assigned compute/eval-conflicts-rho010-r4-095-xhspn to kind-worker5
0.3447,Event,ADDED,eval-conflicts-rho010-r4-095-xhspn.18d466cef26b5d54,"reason=Pulled count=1 msg=Container image ""busybox:musl"" already present on machine"
0.3448,Event,ADDED,eval-conflicts-rho010-r4-095-xhspn.18d466cef3a086d1,reason=Created count=1 msg=Created container: task
0.345,Event,ADDED,eval-conflicts-rho010-r4-095-xhspn.18d466cef8131ebd,reason=Started count=1 msg=Started container task
0.3452,Event,ADDED,eval-conflicts-rho010-r4-095.18d466ce808dbe45,reason=SuccessfulCreate count=1 msg=Created pod: eval-conflicts-rho010-r4-095-xhspn
0.3454,Event,ADDED,eval-conflicts-rho010-r4-095.18d466d21eecdc35,reason=Completed count=1 msg=Job completed
0.3455,Event,ADDED,eval-conflicts-rho010-r4-096-p8kpq.18d466cebcab9f30,reason=Scheduled count=None msg=Successfully assigned compute/eval-conflicts-rho010-r4-096-p8kpq to kind-worker2
0.3457,Event,ADDED,eval-conflicts-rho010-r4-096-p8kpq.18d466ced564bfe2,"reason=Pulled count=1 msg=Container image ""busybox:musl"" already present on machine"
0.3458,Event,ADDED,eval-conflicts-rho010-r4-096-p8kpq.18d466ced6cecee8,reason=Created count=1 msg=Created container: task
0.346,Event,ADDED,eval-conflicts-rho010-r4-096-p8kpq.18d466cedd7b2c15,reason=Started count=1 msg=Started container task
0.3462,Event,ADDED,eval-conflicts-rho010-r4-096.18d466cebc1f5707,reason=SuccessfulCreate count=1 msg=Created pod: eval-conflicts-rho010-r4-096-p8kpq
0.3464,Event,ADDED,eval-conflicts-rho010-r4-096.18d466d21ec8d192,reason=Completed count=1 msg=Job completed
0.3466,Event,ADDED,eval-conflicts-rho010-r4-097-7g6j8.18d466cef858f3c1,"reason=FailedScheduling count=None msg=0/6 nodes are available: 2 c_wall violated: 1 conflicting context pair(s) with node memory, 4 node(s) had untolerated taint(s). no new claims to deallocate, preemption: 0/6 nodes are available: 2 No preemption victims found for incoming pod, 4 Preemption is not helpful for scheduling."
0.3468,Event,ADDED,eval-conflicts-rho010-r4-097-7g6j8.18d466cef901fa24,"reason=FailedScheduling count=None msg=0/6 nodes are available: 2 c_wall violated: 1 conflicting context pair(s) with node memory, 4 node(s) had untolerated taint(s). no new claims to deallocate, preemption: 0/6 nodes are available: 2 No preemption victims found for incoming pod, 4 Preemption is not helpful for scheduling."
0.3469,Event,ADDED,eval-conflicts-rho010-r4-097-7g6j8.18d466d0a5889699,reason=Scheduled count=None msg=Successfully assigned compute/eval-conflicts-rho010-r4-097-7g6j8 to kind-worker3
0.3472,Event,ADDED,eval-conflicts-rho010-r4-097-7g6j8.18d466d0be0858e4,"reason=Pulled count=1 msg=Container image ""busybox:musl"" already present on machine"
0.3473,Event,ADDED,eval-conflicts-rho010-r4-097-7g6j8.18d466d0bf594a61,reason=Created count=1 msg=Created container: task
0.3475,Event,ADDED,eval-conflicts-rho010-r4-097-7g6j8.18d466d0c14275da,reason=Started count=1 msg=Started container task
0.3477,Event,ADDED,eval-conflicts-rho010-r4-097.18d466cef7ef2eca,reason=SuccessfulCreate count=1 msg=Created pod: eval-conflicts-rho010-r4-097-7g6j8
0.3478,Event,ADDED,eval-conflicts-rho010-r4-097.18d466d3e74a38c5,reason=Completed count=1 msg=Job completed
0.3521,Event,ADDED,eval-conflicts-rho010-r4-098-484d2.18d466cf34fec2fb,reason=Scheduled count=None msg=Successfully assigned compute/eval-conflicts-rho010-r4-098-484d2 to kind-worker5
0.3523,Event,ADDED,eval-conflicts-rho010-r4-098-484d2.18d466cf4d974bbd,"reason=Pulled count=1 msg=Container image ""busybox:musl"" already present on machine"
0.3525,Event,ADDED,eval-conflicts-rho010-r4-098-484d2.18d466cf4ec2ae80,reason=Created count=1 msg=Created container: task
0.3529,Event,ADDED,eval-conflicts-rho010-r4-098-484d2.18d466cf53c1e16d,reason=Started count=1 msg=Started container task
0.353,Event,ADDED,eval-conflicts-rho010-r4-098.18d466cf33c28674,reason=SuccessfulCreate count=1 msg=Created pod: eval-conflicts-rho010-r4-098-484d2
0.3532,Event,ADDED,eval-conflicts-rho010-r4-098.18d466d29631915a,reason=Completed count=1 msg=Job completed
0.3535,Event,ADDED,eval-conflicts-rho010-r4-099-r9tph.18d466cf6fd35972,reason=Scheduled count=None msg=Successfully assigned compute/eval-conflicts-rho010-r4-099-r9tph to kind-worker5
0.3537,Event,ADDED,eval-conflicts-rho010-r4-099-r9tph.18d466cf88b96476,"reason=Pulled count=1 msg=Container image ""busybox:musl"" already present on machine"
0.3539,Event,ADDED,eval-conflicts-rho010-r4-099-r9tph.18d466cf89e10f87,reason=Created count=1 msg=Created container: task
0.3541,Event,ADDED,eval-conflicts-rho010-r4-099-r9tph.18d466cf8c64c286,reason=Started count=1 msg=Started container task
0.3545,Event,ADDED,eval-conflicts-rho010-r4-099.18d466cf6efc7622,reason=SuccessfulCreate count=1 msg=Created pod: eval-conflicts-rho010-r4-099-r9tph
0.3547,Event,ADDED,eval-conflicts-rho010-r4-099.18d466d2d20236b4,reason=Completed count=1 msg=Job completed
0.3549,Event,ADDED,eval-conflicts-rho010-r5-000-pl8k2.18d466d9326363e7,reason=Scheduled count=None msg=Successfully assigned compute/eval-conflicts-rho010-r5-000-pl8k2 to kind-worker2
0.3551,Event,ADDED,eval-conflicts-rho010-r5-000-pl8k2.18d466d94b9e12b3,"reason=Pulled count=1 msg=Container image ""busybox:musl"" already present on machine"
0.3554,Event,ADDED,eval-conflicts-rho010-r5-000-pl8k2.18d466d94cdb475c,reason=Created count=1 msg=Created container: task
0.3561,Event,ADDED,eval-conflicts-rho010-r5-000-pl8k2.18d466d94fdf8d09,reason=Started count=1 msg=Started container task
0.3563,Event,ADDED,eval-conflicts-rho010-r5-000.18d466d9315d784d,reason=SuccessfulCreate count=1 msg=Created pod: eval-conflicts-rho010-r5-000-pl8k2
0.3567,Event,ADDED,eval-conflicts-rho010-r5-000.18d466dc62c66c9f,reason=Completed count=1 msg=Job completed
0.3568,Event,ADDED,eval-conflicts-rho010-r5-001-rxrgl.18d466d96d5e0583,reason=Scheduled count=None msg=Successfully assigned compute/eval-conflicts-rho010-r5-001-rxrgl to kind-worker5
0.357,Event,ADDED,eval-conflicts-rho010-r5-001-rxrgl.18d466d9866cb2c4,"reason=Pulled count=1 msg=Container image ""busybox:musl"" already present on machine"
0.3572,Event,ADDED,eval-conflicts-rho010-r5-001-rxrgl.18d466d9878427e1,reason=Created count=1 msg=Created container: task
0.3574,Event,ADDED,eval-conflicts-rho010-r5-001-rxrgl.18d466d9898d48c7,reason=Started count=1 msg=Started container task
0.3575,Event,ADDED,eval-conflicts-rho010-r5-001.18d466d96c54a0de,reason=SuccessfulCreate count=1 msg=Created pod: eval-conflicts-rho010-r5-001-rxrgl
0.3577,Event,ADDED,eval-conflicts-rho010-r5-001.18d466dc9f78d7b3,reason=Completed count=1 msg=Job completed
0.3579,Event,ADDED,eval-conflicts-rho010-r5-002-tfvg2.18d466d9a9b9685f,reason=Scheduled count=None msg=Successfully assigned compute/eval-conflicts-rho010-r5-002-tfvg2 to kind-worker
0.358,Event,ADDED,eval-conflicts-rho010-r5-002-tfvg2.18d466d9c31816de,"reason=Pulled count=1 msg=Container image ""busybox:musl"" already present on machine"
0.3582,Event,ADDED,eval-conflicts-rho010-r5-002-tfvg2.18d466d9c429c0bf,reason=Created count=1 msg=Created container: task
0.3584,Event,ADDED,eval-conflicts-rho010-r5-002-tfvg2.18d466d9c7ed69c9,reason=Started count=1 msg=Started container task
0.3586,Event,ADDED,eval-conflicts-rho010-r5-002.18d466d9a8ac399b,reason=SuccessfulCreate count=1 msg=Created pod: eval-conflicts-rho010-r5-002-tfvg2
0.3587,Event,ADDED,eval-conflicts-rho010-r5-002.18d466dd090d77f6,reason=Completed count=1 msg=Job completed
0.3589,Event,ADDED,eval-conflicts-rho010-r5-003-8j7hc.18d466d9e44acf16,reason=Scheduled count=None msg=Successfully assigned compute/eval-conflicts-rho010-r5-003-8j7hc to kind-worker5
0.359,Event,ADDED,eval-conflicts-rho010-r5-003-8j7hc.18d466d9fd618d84,"reason=Pulled count=1 msg=Container image ""busybox:musl"" already present on machine"
0.3592,Event,ADDED,eval-conflicts-rho010-r5-003-8j7hc.18d466d9fe9acb6e,reason=Created count=1 msg=Created container: task
0.3594,Event,ADDED,eval-conflicts-rho010-r5-003-8j7hc.18d466da00bfdb65,reason=Started count=1 msg=Started container task
0.3596,Event,ADDED,eval-conflicts-rho010-r5-003.18d466d9e35df7df,reason=SuccessfulCreate count=1 msg=Created pod: eval-conflicts-rho010-r5-003-8j7hc
0.361,Node,MODIFIED,kind-worker,taints=1
0.3613,Event,ADDED,eval-conflicts-rho010-r5-003.18d466dd1761cb1b,reason=Completed count=1 msg=Job completed
0.3615,Event,ADDED,eval-conflicts-rho010-r5-004-s5nst.18d466da1f9feb66,reason=Scheduled count=None msg=Successfully assigned compute/eval-conflicts-rho010-r5-004-s5nst to kind-worker2
0.3617,Event,ADDED,eval-conflicts-rho010-r5-004-s5nst.18d466da37d52343,"reason=Pulled count=1 msg=Container image ""busybox:musl"" already present on machine"
0.3618,Event,ADDED,eval-conflicts-rho010-r5-004-s5nst.18d466da38f1136a,reason=Created count=1 msg=Created container: task
0.3622,Event,ADDED,eval-conflicts-rho010-r5-004-s5nst.18d466da3aebbdb3,reason=Started count=1 msg=Started container task
0.3625,Event,ADDED,eval-conflicts-rho010-r5-004.18d466da1eba70be,reason=SuccessfulCreate count=1 msg=Created pod: eval-conflicts-rho010-r5-004-s5nst
0.3627,Event,ADDED,eval-conflicts-rho010-r5-004.18d466dd526fb948,reason=Completed count=1 msg=Job completed
0.3628,Event,ADDED,eval-conflicts-rho010-r5-005-rqk55.18d466da5b0c34eb,reason=Scheduled count=None msg=Successfully assigned compute/eval-conflicts-rho010-r5-005-rqk55 to kind-worker5
0.3632,Event,ADDED,eval-conflicts-rho010-r5-005-rqk55.18d466da741d503f,"reason=Pulled count=1 msg=Container image ""busybox:musl"" already present on machine"
0.3634,Event,ADDED,eval-conflicts-rho010-r5-005-rqk55.18d466da7525341d,reason=Created count=1 msg=Created container: task
0.3636,Event,ADDED,eval-conflicts-rho010-r5-005-rqk55.18d466da7715d7ad,reason=Started count=1 msg=Started container task
0.3639,Event,ADDED,eval-conflicts-rho010-r5-005.18d466da5a3ffbcf,reason=SuccessfulCreate count=1 msg=Created pod: eval-conflicts-rho010-r5-005-rqk55
0.3641,Event,ADDED,eval-conflicts-rho010-r5-005.18d466dd8f0c7f2d,reason=Completed count=1 msg=Job completed
0.3643,Event,ADDED,eval-conflicts-rho010-r5-006-7j56n.18d466da96ebcd94,reason=Scheduled count=None msg=Successfully assigned compute/eval-conflicts-rho010-r5-006-7j56n to kind-worker4
0.3645,Event,ADDED,eval-conflicts-rho010-r5-006-7j56n.18d466dab0424229,"reason=Pulled count=1 msg=Container image ""busybox:musl"" already present on machine"
0.3657,Event,ADDED,eval-conflicts-rho010-r5-006-7j56n.18d466dab15c7e2f,reason=Created count=1 msg=Created container: task
0.3659,Event,ADDED,eval-conflicts-rho010-r5-006-7j56n.18d466dab3903fc0,reason=Started count=1 msg=Started container task
0.3661,Event,ADDED,eval-conflicts-rho010-r5-006.18d466da9621d3d2,reason=SuccessfulCreate count=1 msg=Created pod: eval-conflicts-rho010-r5-006-7j56n
0.3664,Event,ADDED,eval-conflicts-rho010-r5-006.18d466ddd0b32fc1,reason=Completed count=1 msg=Job completed
0.3665,Event,ADDED,eval-conflicts-rho010-r5-007-mrcnp.18d466dad2519277,reason=Scheduled count=None msg=Successfully assigned compute/eval-conflicts-rho010-r5-007-mrcnp to kind-worker4
0.3667,Event,ADDED,eval-conflicts-rho010-r5-007-mrcnp.18d466daeb39f6de,"reason=Pulled count=1 msg=Container image ""busybox:musl"" already present on machine"
0.3669,Event,ADDED,eval-conflicts-rho010-r5-007-mrcnp.18d466daec5a14b3,reason=Created count=1 msg=Created container: task
0.3671,Event,ADDED,eval-conflicts-rho010-r5-007-mrcnp.18d466daefeb274e,reason=Started count=1 msg=Started container task
0.3673,Event,ADDED,eval-conflicts-rho010-r5-007.18d466dad18e3385,reason=SuccessfulCreate count=1 msg=Created pod: eval-conflicts-rho010-r5-007-mrcnp
0.3674,Event,ADDED,eval-conflicts-rho010-r5-007.18d466de0c9c7fe2,reason=Completed count=1 msg=Job completed
0.3676,Event,ADDED,eval-conflicts-rho010-r5-008-45jpp.18d466db0dfff10f,reason=Scheduled count=None msg=Successfully assigned compute/eval-conflicts-rho010-r5-008-45jpp to kind-worker4
0.3678,Event,ADDED,eval-conflicts-rho010-r5-008-45jpp.18d466db269b1f3f,"reason=Pulled count=1 msg=Container image ""busybox:musl"" already present on machine"
0.368,Event,ADDED,eval-conflicts-rho010-r5-008-45jpp.18d466db27be58ff,reason=Created count=1 msg=Created container: task
0.3682,Event,ADDED,eval-conflicts-rho010-r5-008-45jpp.18d466db2c3e0e79,reason=Started count=1 msg=Started container task
0.3685,Event,ADDED,eval-conflicts-rho010-r5-008.18d466db0d35cfa8,reason=SuccessfulCreate count=1 msg=Created pod: eval-conflicts-rho010-r5-008-45jpp
0.3687,Event,ADDED,eval-conflicts-rho010-r5-008.18d466de47f85c53,reason=Completed count=1 msg=Job completed
0.3689,Event,ADDED,eval-conflicts-rho010-r5-009-jf85t.18d466db4b267d96,reason=Scheduled count=None msg=Successfully assigned compute/eval-conflicts-rho010-r5-009-jf85t to kind-worker4
0.369,Event,ADDED,eval-conflicts-rho010-r5-009-jf85t.18d466db64571633,"reason=Pulled count=1 msg=Container image ""busybox:musl"" already present on machine"
0.3694,Event,ADDED,eval-conflicts-rho010-r5-009-jf85t.18d466db6589b764,reason=Created count=1 msg=Created container: task
0.3701,Event,ADDED,eval-conflicts-rho010-r5-009-jf85t.18d466db67aa382b,reason=Started count=1 msg=Started container task
0.3705,Event,ADDED,eval-conflicts-rho010-r5-009.18d466db498e6085,reason=SuccessfulCreate count=1 msg=Created pod: eval-conflicts-rho010-r5-009-jf85t
0.3707,Event,ADDED,eval-conflicts-rho010-r5-009.18d466de83e0f13c,reason=Completed count=1 msg=Job completed
0.3711,Event,ADDED,eval-conflicts-rho010-r5-010-n7m4m.18d466db8552adf3,reason=Scheduled count=None msg=Successfully assigned compute/eval-conflicts-rho010-r5-010-n7m4m to kind-worker3
0.3713,Event,ADDED,eval-conflicts-rho010-r5-010-n7m4m.18d466db9e0e0af2,"reason=Pulled count=1 msg=Container image ""busybox:musl"" already present on machine"
0.3714,Event,ADDED,eval-conflicts-rho010-r5-010-n7m4m.18d466db9f794190,reason=Created count=1 msg=Created container: task
0.3718,Event,ADDED,eval-conflicts-rho010-r5-010-n7m4m.18d466dba41a5fe2,reason=Started count=1 msg=Started container task
0.372,Event,ADDED,eval-conflicts-rho010-r5-010.18d466db849984ff,reason=SuccessfulCreate count=1 msg=Created pod: eval-conflicts-rho010-r5-010-n7m4m
0.3723,Event,ADDED,eval-conflicts-rho010-r5-010.18d466dede4049e6,reason=Completed count=1 msg=Job completed
0.3724,Event,ADDED,eval-conflicts-rho010-r5-011-bpzt6.18d466dbc17c904c,reason=Scheduled count=None msg=Successfully assigned compute/eval-conflicts-rho010-r5-011-bpzt6 to kind-worker3
0.3738,Node,MODIFIED,kind-worker,taints=1
0.3741,Event,ADDED,eval-conflicts-rho010-r5-011-bpzt6.18d466dbdb331e17,"reason=Pulled count=1 msg=Container image ""busybox:musl"" already present on machine"
0.3743,Event,ADDED,eval-conflicts-rho010-r5-011-bpzt6.18d466dbdc56c358,reason=Created count=1 msg=Created container: task
0.3745,Event,ADDED,eval-conflicts-rho010-r5-011-bpzt6.18d466dbe111a084,reason=Started count=1 msg=Started container task
0.3749,Event,ADDED,eval-conflicts-rho010-r5-011.18d466dbc06a74c5,reason=SuccessfulCreate count=1 msg=Created pod: eval-conflicts-rho010-r5-011-bpzt6
0.3751,Event,ADDED,eval-conflicts-rho010-r5-011.18d466df1a2b7bbc,reason=Completed count=1 msg=Job completed
0.3753,Event,ADDED,eval-conflicts-rho010-r5-012-nwrqd.18d466dbfc8c7c8b,reason=Scheduled count=None msg=Successfully assigned compute/eval-conflicts-rho010-r5-012-nwrqd to kind-worker3
0.3755,Event,ADDED,eval-conflicts-rho010-r5-012-nwrqd.18d466dc155ad5fd,"reason=Pulled count=1 msg=Container image ""busybox:musl"" already present on machine"
0.3759,Event,ADDED,eval-conflicts-rho010-r5-012-nwrqd.18d466dc16b6635c,reason=Created count=1 msg=Created container: task
0.3762,Event,ADDED,eval-conflicts-rho010-r5-012-nwrqd.18d466dc1b911af1,reason=Started count=1 msg=Started container task
0.3764,Event,ADDED,eval-conflicts-rho010-r5-012.18d466dbfb91a5be,reason=SuccessfulCreate count=1 msg=Created pod: eval-conflicts-rho010-r5-012-nwrqd
0.3765,Event,ADDED,eval-conflicts-rho010-r5-012.18d466df55facd99,reason=Completed count=1 msg=Job completed
0.3769,Event,ADDED,eval-conflicts-rho010-r5-013-szwpk.18d466dc38894668,reason=Scheduled count=None msg=Successfully assigned compute/eval-conflicts-rho010-r5-013-szwpk to kind-worker3
0.3771,Event,ADDED,eval-conflicts-rho010-r5-013-szwpk.18d466dc517c7c1a,"reason=Pulled count=1 msg=Container image ""busybox:musl"" already present on machine"
0.3773,Event,ADDED,eval-conflicts-rho010-r5-013-szwpk.18d466dc528525b7,reason=Created count=1 msg=Created container: task
0.3777,Event,ADDED,eval-conflicts-rho010-r5-013-szwpk.18d466dc546ead59,reason=Started count=1 msg=Started container task
0.3778,Event,ADDED,eval-conflicts-rho010-r5-013.18d466dc37c38dd8,reason=SuccessfulCreate count=1 msg=Created pod: eval-conflicts-rho010-r5-013-szwpk
0.378,Event,ADDED,eval-conflicts-rho010-r5-013.18d466df91e13746,reason=Completed count=1 msg=Job completed
0.3782,Event,ADDED,eval-conflicts-rho010-r5-014-skrqs.18d466dc733ebe0c,reason=Scheduled count=None msg=Successfully assigned compute/eval-conflicts-rho010-r5-014-skrqs to kind-worker4
0.3785,Event,ADDED,eval-conflicts-rho010-r5-014-skrqs.18d466dc8cec3fbb,"reason=Pulled count=1 msg=Container image ""busybox:musl"" already present on machine"
0.3787,Event,ADDED,eval-conflicts-rho010-r5-014-skrqs.18d466dc8e1c048c,reason=Created count=1 msg=Created container: task
0.3789,Event,ADDED,eval-conflicts-rho010-r5-014-skrqs.18d466dc917b9dab,reason=Started count=1 msg=Started container task
0.3793,Event,ADDED,eval-conflicts-rho010-r5-014.18d466dc72b04676,reason=SuccessfulCreate count=1 msg=Created pod: eval-conflicts-rho010-r5-014-skrqs
0.3797,Event,ADDED,eval-conflicts-rho010-r5-014.18d466dfaee658ea,reason=Completed count=1 msg=Job completed
0.3798,Event,ADDED,eval-conflicts-rho010-r5-015-7fnkt.18d466dcaf0de65c,"reason=FailedScheduling count=None msg=0/6 nodes are available: 6 node(s) had untolerated taint(s). no new claims to deallocate, preemption: 0/6 nodes are available: 6 Preemption is not helpful for scheduling."
0.3801,Event,ADDED,eval-conflicts-rho010-r5-015-7fnkt.18d466de7df220a4,reason=Scheduled count=None msg=Successfully assigned compute/eval-conflicts-rho010-r5-015-7fnkt to kind-worker
0.3804,Event,ADDED,eval-conflicts-rho010-r5-015-7fnkt.18d466de9700b933,"reason=Pulled count=1 msg=Container image ""busybox:musl"" already present on machine"
0.3806,Event,ADDED,eval-conflicts-rho010-r5-015-7fnkt.18d466de986d49f8,reason=Created count=1 msg=Created container: task
0.3808,Event,ADDED,eval-conflicts-rho010-r5-015-7fnkt.18d466de9d1e2ce2,reason=Started count=1 msg=Started container task
0.3809,Event,ADDED,eval-conflicts-rho010-r5-015.18d466dcaeff54d0,reason=SuccessfulCreate count=1 msg=Created pod: eval-conflicts-rho010-r5-015-7fnkt
0.3815,Event,ADDED,eval-conflicts-rho010-r5-015.18d466e1b81531c9,reason=Completed count=1 msg=Job completed
0.3817,Event,ADDED,eval-conflicts-rho010-r5-016-n99rg.18d466dcea2f707c,"reason=FailedScheduling count=None msg=0/6 nodes are available: 6 node(s) had untolerated taint(s). no new claims to deallocate, preemption: 0/6 nodes are available: 6 Preemption is not helpful for scheduling."
0.3819,Event,ADDED,eval-conflicts-rho010-r5-016-n99rg.18d466de7ea29842,reason=Scheduled count=None msg=Successfully assigned compute/eval-conflicts-rho010-r5-016-n99rg to kind-worker
0.3821,Event,ADDED,eval-conflicts-rho010-r5-016-n99rg.18d466de9825faf9,"reason=Pulled count=1 msg=Container image ""busybox:musl"" already present on machine"
0.3823,Event,ADDED,eval-conflicts-rho010-r5-016-n99rg.18d466de99ca1890,reason=Created count=1 msg=Created container: task
0.3825,Event,ADDED,eval-conflicts-rho010-r5-016-n99rg.18d466de9dc7680d,reason=Started count=1 msg=Started container task
0.3826,Event,ADDED,eval-conflicts-rho010-r5-016.18d466dcea246465,reason=SuccessfulCreate count=1 msg=Created pod: eval-conflicts-rho010-r5-016-n99rg
0.3828,Event,ADDED,eval-conflicts-rho010-r5-016.18d466e1b813849e,reason=Completed count=1 msg=Job completed
0.383,Event,ADDED,eval-conflicts-rho010-r5-017-nzkqc.18d466dd25e6f590,"reason=FailedScheduling count=None msg=0/6 nodes are available: 6 node(s) had untolerated taint(s). no new claims to deallocate, preemption: 0/6 nodes are available: 6 Preemption is not helpful for scheduling."
0.3831,Event,ADDED,eval-conflicts-rho010-r5-017-nzkqc.18d466de7ec77045,reason=Scheduled count=None msg=Successfully assigned compute/eval-conflicts-rho010-r5-017-nzkqc to kind-worker
0.3833,Event,ADDED,eval-conflicts-rho010-r5-017-nzkqc.18d466de980d7452,"reason=Pulled count=1 msg=Container image ""busybox:musl"" already present on machine"
0.3835,Event,ADDED,eval-conflicts-rho010-r5-017-nzkqc.18d466de99977725,reason=Created count=1 msg=Created container: task
0.3837,Event,ADDED,eval-conflicts-rho010-r5-017-nzkqc.18d466de9dc65261,reason=Started count=1 msg=Started container task
0.3838,Event,ADDED,eval-conflicts-rho010-r5-017.18d466dd25d908e0,reason=SuccessfulCreate count=1 msg=Created pod: eval-conflicts-rho010-r5-017-nzkqc
0.3841,Event,ADDED,eval-conflicts-rho010-r5-017.18d466e1b81711be,reason=Completed count=1 msg=Job completed
0.3843,Event,ADDED,eval-conflicts-rho010-r5-018-rs8fj.18d466dd6137bf73,"reason=FailedScheduling count=None msg=0/6 nodes are available: 6 node(s) had untolerated taint(s). no new claims to deallocate, preemption: 0/6 nodes are available: 6 Preemption is not helpful for scheduling."
0.3844,Event,ADDED,eval-conflicts-rho010-r5-018-rs8fj.18d466de7eb0abc0,"reason=FailedScheduling count=None msg=0/6 nodes are available: 1 c_wall violated: 1 conflicting context pair(s) with node memory, 5 node(s) had untolerated taint(s). no new claims to deallocate, preemption: 0/6 nodes are available: 1 No preemption victims found for incoming pod, 5 Preemption is not helpful for scheduling."
0.3848,Event,ADDED,eval-conflicts-rho010-r5-018-rs8fj.18d466de8519c19b,"reason=FailedScheduling count=None msg=0/6 nodes are available: 1 c_wall violated: 1 conflicting context pair(s) with node memory, 5 node(s) had untolerated taint(s). no new claims to deallocate, preemption: 0/6 nodes are available: 1 No preemption victims found for incoming pod, 5 Preemption is not helpful for scheduling."
0.385,Event,ADDED,eval-conflicts-rho010-r5-018-rs8fj.18d466df0e1b4630,reason=Scheduled count=None msg=Successfully assigned compute/eval-conflicts-rho010-r5-018-rs8fj to kind-worker2
0.3852,Event,ADDED,eval-conflicts-rho010-r5-018-rs8fj.18d466df2a22320c,"reason=Pulled count=1 msg=Container image ""busybox:musl"" already present on machine"
0.3854,Event,ADDED,eval-conflicts-rho010-r5-018-rs8fj.18d466df2b8af07c,reason=Created count=1 msg=Created container: task
0.3857,Event,ADDED,eval-conflicts-rho010-r5-018-rs8fj.18d466df2dfad52e,reason=Started count=1 msg=Started container task
0.3859,Event,ADDED,eval-conflicts-rho010-r5-018.18d466dd612825de,reason=SuccessfulCreate count=1 msg=Created pod: eval-conflicts-rho010-r5-018-rs8fj
0.3861,Event,ADDED,eval-conflicts-rho010-r5-018.18d466e23d489f70,reason=Completed count=1 msg=Job completed
0.3864,Event,ADDED,eval-conflicts-rho010-r5-019-qrl5b.18d466dd9d32e12e,"reason=FailedScheduling count=None msg=0/6 nodes are available: 6 node(s) had untolerated taint(s). no new claims to deallocate, preemption: 0/6 nodes are available: 6 Preemption is not helpful for scheduling."
0.3866,Event,ADDED,eval-conflicts-rho010-r5-019-qrl5b.18d466de7f7e2176,"reason=FailedScheduling count=None msg=0/6 nodes are available: 1 c_wall violated: 1 conflicting context pair(s) with node memory, 5 node(s) had untolerated taint(s). no new claims to deallocate, preemption: 0/6 nodes are available: 1 No preemption victims found for incoming pod, 5 Preemption is not helpful for scheduling."
0.3868,Event,ADDED,eval-conflicts-rho010-r5-019-qrl5b.18d466de85429810,"reason=FailedScheduling count=None msg=0/6 nodes are available: 1 c_wall violated: 1 conflicting context pair(s) with node memory, 5 node(s) had untolerated taint(s). no new claims to deallocate, preemption: 0/6 nodes are available: 1 No preemption victims found for incoming pod, 5 Preemption is not helpful for scheduling."
0.3871,Event,ADDED,eval-conflicts-rho010-r5-019-qrl5b.18d466df020511ac,reason=Scheduled count=None msg=Successfully assigned compute/eval-conflicts-rho010-r5-019-qrl5b to kind-worker2
0.3872,Event,ADDED,eval-conflicts-rho010-r5-019-qrl5b.18d466df1bb674b0,"reason=Pulled count=1 msg=Container image ""busybox:musl"" already present on machine"
0.3874,Event,ADDED,eval-conflicts-rho010-r5-019-qrl5b.18d466df1e84b8fb,reason=Created count=1 msg=Created container: task
0.3876,Event,ADDED,eval-conflicts-rho010-r5-019-qrl5b.18d466df2142e660,reason=Started count=1 msg=Started container task
0.388,Event,ADDED,eval-conflicts-rho010-r5-019.18d466dd9d2916c5,reason=SuccessfulCreate count=1 msg=Created pod: eval-conflicts-rho010-r5-019-qrl5b
0.3882,Event,ADDED,eval-conflicts-rho010-r5-019.18d466e23b5dbd0e,reason=Completed count=1 msg=Job completed
0.3884,Event,ADDED,eval-conflicts-rho010-r5-020-xmct7.18d466ddd89cca2a,"reason=FailedScheduling count=None msg=0/6 nodes are available: 6 node(s) had untolerated taint(s). no new claims to deallocate, preemption: 0/6 nodes are available: 6 Preemption is not helpful for scheduling."
0.3886,Event,ADDED,eval-conflicts-rho010-r5-020-xmct7.18d466de82885f33,"reason=FailedScheduling count=None msg=0/6 nodes are available: 1 c_wall violated: 1 conflicting context pair(s) with node memory, 5 node(s) had untolerated taint(s). no new claims to deallocate, preemption: 0/6 nodes are available: 1 No preemption victims found for incoming pod, 5 Preemption is not helpful for scheduling."
0.3888,Event,ADDED,eval-conflicts-rho010-r5-020-xmct7.18d466de8567d27c,"reason=FailedScheduling count=None msg=0/6 nodes are available: 1 c_wall violated: 1 conflicting context pair(s) with node memory, 5 node(s) had untolerated taint(s). no new claims to deallocate, preemption: 0/6 nodes are available: 1 No preemption victims found for incoming pod, 5 Preemption is not helpful for scheduling."
0.3889,Event,ADDED,eval-conflicts-rho010-r5-020-xmct7.18d466df0757b567,reason=Scheduled count=None msg=Successfully assigned compute/eval-conflicts-rho010-r5-020-xmct7 to kind-worker2
0.3891,Event,ADDED,eval-conflicts-rho010-r5-020-xmct7.18d466df20f2d998,"reason=Pulled count=1 msg=Container image ""busybox:musl"" already present on machine"
0.3893,Event,ADDED,eval-conflicts-rho010-r5-020-xmct7.18d466df245a77c7,reason=Created count=1 msg=Created container: task
0.3895,Event,ADDED,eval-conflicts-rho010-r5-020-xmct7.18d466df29b674de,reason=Started count=1 msg=Started container task
0.3897,Event,ADDED,eval-conflicts-rho010-r5-020.18d466ddd893eb33,reason=SuccessfulCreate count=1 msg=Created pod: eval-conflicts-rho010-r5-020-xmct7
0.3899,Event,ADDED,eval-conflicts-rho010-r5-020.18d466e277891b16,reason=Completed count=1 msg=Job completed
0.39,Event,ADDED,eval-conflicts-rho010-r5-021-kpdpd.18d466de140da2ef,"reason=FailedScheduling count=None msg=0/6 nodes are available: 6 node(s) had untolerated taint(s). no new claims to deallocate, preemption: 0/6 nodes are available: 6 Preemption is not helpful for scheduling."
0.3902,Event,ADDED,eval-conflicts-rho010-r5-021-kpdpd.18d466de83ee6928,"reason=FailedScheduling count=None msg=0/6 nodes are available: 1 c_wall violated: 1 conflicting context pair(s) with node memory, 5 node(s) had untolerated taint(s). no new claims to deallocate, preemption: 0/6 nodes are available: 1 No preemption victims found for incoming pod, 5 Preemption is not helpful for scheduling."
0.3904,Event,ADDED,eval-conflicts-rho010-r5-021-kpdpd.18d466de859588cd,"reason=FailedScheduling count=None msg=0/6 nodes are available: 1 c_wall violated: 1 conflicting context pair(s) with node memory, 5 node(s) had untolerated taint(s). no new claims to deallocate, preemption: 0/6 nodes are available: 1 No preemption victims found for incoming pod, 5 Preemption is not helpful for scheduling."
0.3906,Event,ADDED,eval-conflicts-rho010-r5-021-kpdpd.18d466df085aa477,reason=Scheduled count=None msg=Successfully assigned compute/eval-conflicts-rho010-r5-021-kpdpd to kind-worker2
0.3907,Event,ADDED,eval-conflicts-rho010-r5-021-kpdpd.18d466df22b076b9,"reason=Pulled count=1 msg=Container image ""busybox:musl"" already present on machine"
0.3909,Event,ADDED,eval-conflicts-rho010-r5-021-kpdpd.18d466df25c4770a,reason=Created count=1 msg=Created container: task
0.3911,Event,ADDED,eval-conflicts-rho010-r5-021-kpdpd.18d466df29b6e7ba,reason=Started count=1 msg=Started container task
0.3914,Event,ADDED,eval-conflicts-rho010-r5-021.18d466de14015e4d,reason=SuccessfulCreate count=1 msg=Created pod: eval-conflicts-rho010-r5-021-kpdpd
0.3916,Event,ADDED,eval-conflicts-rho010-r5-021.18d466e2783987a4,reason=Completed count=1 msg=Job completed
0.3917,Event,ADDED,eval-conflicts-rho010-r5-022-mhvbz.18d466de4fd072f0,"reason=FailedScheduling count=None msg=0/6 nodes are available: 6 node(s) had untolerated taint(s). no new claims to deallocate, preemption: 0/6 nodes are available: 6 Preemption is not helpful for scheduling."
0.3919,Event,ADDED,eval-conflicts-rho010-r5-022-mhvbz.18d466de84900322,"reason=FailedScheduling count=None msg=0/6 nodes are available: 1 c_wall violated: 1 conflicting context pair(s) with node memory, 5 node(s) had untolerated taint(s). no new claims to deallocate, preemption: 0/6 nodes are available: 1 No preemption victims found for incoming pod, 5 Preemption is not helpful for scheduling."
0.3922,Event,ADDED,eval-conflicts-rho010-r5-022-mhvbz.18d466de85bdedc7,"reason=FailedScheduling count=None msg=0/6 nodes are available: 1 c_wall violated: 1 conflicting context pair(s) with node memory, 5 node(s) had untolerated taint(s). no new claims to deallocate, preemption: 0/6 nodes are available: 1 No preemption victims found for incoming pod, 5 Preemption is not helpful for scheduling."
0.3924,Event,ADDED,eval-conflicts-rho010-r5-022-mhvbz.18d466df0d45a16d,reason=Scheduled count=None msg=Successfully assigned compute/eval-conflicts-rho010-r5-022-mhvbz to kind-worker2
0.3927,Event,ADDED,eval-conflicts-rho010-r5-022-mhvbz.18d466df28745b5e,"reason=Pulled count=1 msg=Container image ""busybox:musl"" already present on machine"
0.3928,Event,ADDED,eval-conflicts-rho010-r5-022-mhvbz.18d466df29c98989,reason=Created count=1 msg=Created container: task
0.393,Event,ADDED,eval-conflicts-rho010-r5-022-mhvbz.18d466df2d467fea,reason=Started count=1 msg=Started container task
0.3932,Event,ADDED,eval-conflicts-rho010-r5-022.18d466de4fc5c066,reason=SuccessfulCreate count=1 msg=Created pod: eval-conflicts-rho010-r5-022-mhvbz
0.3933,Event,ADDED,eval-conflicts-rho010-r5-022.18d466e277b2e6e5,reason=Completed count=1 msg=Job completed
0.3935,Event,ADDED,eval-conflicts-rho010-r5-023-l2ksk.18d466de8b4d589b,"reason=FailedScheduling count=None msg=0/6 nodes are available: 1 c_wall violated: 1 conflicting context pair(s) with node memory, 5 node(s) had untolerated taint(s). no new claims to deallocate, preemption: 0/6 nodes are available: 1 No preemption victims found for incoming pod, 5 Preemption is not helpful for scheduling."
0.3937,Event,ADDED,eval-conflicts-rho010-r5-023-l2ksk.18d466de8bcf0b9f,"reason=FailedScheduling count=None msg=0/6 nodes are available: 1 c_wall violated: 1 conflicting context pair(s) with node memory, 5 node(s) had untolerated taint(s). no new claims to deallocate, preemption: 0/6 nodes are available: 1 No preemption victims found for incoming pod, 5 Preemption is not helpful for scheduling."
0.3938,Event,ADDED,eval-conflicts-rho010-r5-023-l2ksk.18d466df0d9379d1,reason=Scheduled count=None msg=Successfully assigned compute/eval-conflicts-rho010-r5-023-l2ksk to kind-worker2
0.394,Event,ADDED,eval-conflicts-rho010-r5-023-l2ksk.18d466df2a40aa7c,"reason=Pulled count=1 msg=Container image ""busybox:musl"" already present on machine"
0.3942,Event,ADDED,eval-conflicts-rho010-r5-023-l2ksk.18d466df2bf48df6,reason=Created count=1 msg=Created container: task
0.3944,Event,ADDED,eval-conflicts-rho010-r5-023-l2ksk.18d466df2e539b9a,reason=Started count=1 msg=Started container task
0.3945,Event,ADDED,eval-conflicts-rho010-r5-023.18d466de8b0fc45b,reason=SuccessfulCreate count=1 msg=Created pod: eval-conflicts-rho010-r5-023-l2ksk
0.3947,Event,ADDED,eval-conflicts-rho010-r5-023.18d466e27728ce5b,reason=Completed count=1 msg=Job completed
0.3948,Event,ADDED,eval-conflicts-rho010-r5-024-rdk7z.18d466dec73fbe01,reason=Scheduled count=None msg=Successfully assigned compute/eval-conflicts-rho010-r5-024-rdk7z to kind-worker
0.395,Event,ADDED,eval-conflicts-rho010-r5-024-rdk7z.18d466dee346e5a9,"reason=Pulled count=1 msg=Container image ""busybox:musl"" already present on machine"
0.3952,Event,ADDED,eval-conflicts-rho010-r5-024-rdk7z.18d466dee450e6ce,reason=Created count=1 msg=Created container: task
0.3953,Event,ADDED,eval-conflicts-rho010-r5-024-rdk7z.18d466dee7e52a38,reason=Started count=1 msg=Started container task
0.3955,Event,ADDED,eval-conflicts-rho010-r5-024.18d466dec6bdf6d1,reason=SuccessfulCreate count=1 msg=Created pod: eval-conflicts-rho010-r5-024-rdk7z
0.3957,Event,ADDED,eval-conflicts-rho010-r5-024.18d466e22f91374f,reason=Completed count=1 msg=Job completed
0.3958,Event,ADDED,eval-conflicts-rho010-r5-025-6x6vv.18d466df0823a98b,reason=Scheduled count=None msg=Successfully assigned compute/eval-conflicts-rho010-r5-025-6x6vv to kind-worker2
0.396,Event,ADDED,eval-conflicts-rho010-r5-025-6x6vv.18d466df2273d30c,"reason=Pulled count=1 msg=Container image ""busybox:musl"" already present on machine"
0.3964,Event,ADDED,eval-conflicts-rho010-r5-025-6x6vv.18d466df25aa7ced,reason=Created count=1 msg=Created container: task
0.3966,Event,ADDED,eval-conflicts-rho010-r5-025-6x6vv.18d466df2990693b,reason=Started count=1 msg=Started container task
0.3968,Event,ADDED,eval-conflicts-rho010-r5-025.18d466df04451f0a,reason=SuccessfulCreate count=1 msg=Created pod: eval-conflicts-rho010-r5-025-6x6vv
0.397,Event,ADDED,eval-conflicts-rho010-r5-025.18d466e27749a9da,reason=Completed count=1 msg=Job completed
0.3973,Event,ADDED,eval-conflicts-rho010-r5-026-h24qq.18d466df3edf16c7,reason=Scheduled count=None msg=Successfully assigned compute/eval-conflicts-rho010-r5-026-h24qq to kind-worker
0.3975,Event,ADDED,eval-conflicts-rho010-r5-026-h24qq.18d466df5795cdf6,"reason=Pulled count=1 msg=Container image ""busybox:musl"" already present on machine"
0.3977,Event,ADDED,eval-conflicts-rho010-r5-026-h24qq.18d466df58c4465a,reason=Created count=1 msg=Created container: task
0.398,Event,ADDED,eval-conflicts-rho010-r5-026-h24qq.18d466df5ca4b291,reason=Started count=1 msg=Started container task
0.3982,Event,ADDED,eval-conflicts-rho010-r5-026.18d466df3e2f443c,reason=SuccessfulCreate count=1 msg=Created pod: eval-conflicts-rho010-r5-026-h24qq
0.3984,Event,ADDED,eval-conflicts-rho010-r5-026.18d466e2af9cf4ce,reason=Completed count=1 msg=Job completed
0.3986,Event,ADDED,eval-conflicts-rho010-r5-027-75vxm.18d466df7a8601d1,reason=Scheduled count=None msg=Successfully assigned compute/eval-conflicts-rho010-r5-027-75vxm to kind-worker5
0.399,Event,ADDED,eval-conflicts-rho010-r5-027-75vxm.18d466df94021367,"reason=Pulled count=1 msg=Container image ""busybox:musl"" already present on machine"
0.3992,Event,ADDED,eval-conflicts-rho010-r5-027-75vxm.18d466df9516bd71,reason=Created count=1 msg=Created container: task
0.3994,Event,ADDED,eval-conflicts-rho010-r5-027-75vxm.18d466df97394688,reason=Started count=1 msg=Started container task
0.3997,Event,ADDED,eval-conflicts-rho010-r5-027.18d466df798b4909,reason=SuccessfulCreate count=1 msg=Created pod: eval-conflicts-rho010-r5-027-75vxm
0.3999,Event,ADDED,eval-conflicts-rho010-r5-027.18d466e2b2bad899,reason=Completed count=1 msg=Job completed
0.4001,Event,ADDED,eval-conflicts-rho010-r5-028-w7kxq.18d466dfb76d2202,reason=Scheduled count=None msg=Successfully assigned compute/eval-conflicts-rho010-r5-028-w7kxq to kind-worker5
0.4003,Event,ADDED,eval-conflicts-rho010-r5-028-w7kxq.18d466dfcfe77eb3,"reason=Pulled count=1 msg=Container image ""busybox:musl"" already present on machine"
0.4007,Event,ADDED,eval-conflicts-rho010-r5-028-w7kxq.18d466dfd0f754f3,reason=Created count=1 msg=Created container: task
0.4009,Event,ADDED,eval-conflicts-rho010-r5-028-w7kxq.18d466dfd2f3c361,reason=Started count=1 msg=Started container task
0.401,Event,ADDED,eval-conflicts-rho010-r5-028.18d466dfb623ddcc,reason=SuccessfulCreate count=1 msg=Created pod: eval-conflicts-rho010-r5-028-w7kxq
0.4012,Event,ADDED,eval-conflicts-rho010-r5-028.18d466e2ed34fafe,reason=Completed count=1 msg=Job completed
0.4017,Event,ADDED,eval-conflicts-rho010-r5-029-txcm9.18d466dff213af7a,reason=Scheduled count=None msg=Successfully assigned compute/eval-conflicts-rho010-r5-029-txcm9 to kind-worker5
0.4019,Event,ADDED,eval-conflicts-rho010-r5-029-txcm9.18d466e00aebdf84,"reason=Pulled count=1 msg=Container image ""busybox:musl"" already present on machine"
0.4021,Event,ADDED,eval-conflicts-rho010-r5-029-txcm9.18d466e00c07216d,reason=Created count=1 msg=Created container: task
0.4033,Event,ADDED,eval-conflicts-rho010-r5-029-txcm9.18d466e01081c62f,reason=Started count=1 msg=Started container task
0.4035,Event,ADDED,eval-conflicts-rho010-r5-029.18d466dff0dc1c6b,reason=SuccessfulCreate count=1 msg=Created pod: eval-conflicts-rho010-r5-029-txcm9
0.4037,Event,ADDED,eval-conflicts-rho010-r5-029.18d466e328eda94a,reason=Completed count=1 msg=Job completed
0.4038,Event,ADDED,eval-conflicts-rho010-r5-030-jfxft.18d466e02d8ab1f2,reason=Scheduled count=None msg=Successfully assigned compute/eval-conflicts-rho010-r5-030-jfxft to kind-worker
0.4042,Event,ADDED,eval-conflicts-rho010-r5-030-jfxft.18d466e04685a868,"reason=Pulled count=1 msg=Container image ""busybox:musl"" already present on machine"
0.4044,Event,ADDED,eval-conflicts-rho010-r5-030-jfxft.18d466e047a13e7d,reason=Created count=1 msg=Created container: task
0.4046,Event,ADDED,eval-conflicts-rho010-r5-030-jfxft.18d466e04b825492,reason=Started count=1 msg=Started container task
0.4048,Event,ADDED,eval-conflicts-rho010-r5-030.18d466e02c7c8a14,reason=SuccessfulCreate count=1 msg=Created pod: eval-conflicts-rho010-r5-030-jfxft
0.4051,Event,ADDED,eval-conflicts-rho010-r5-030.18d466e395541476,reason=Completed count=1 msg=Job completed
0.4053,Event,ADDED,eval-conflicts-rho010-r5-031-d6mkg.18d466e069b9210a,reason=Scheduled count=None msg=Successfully assigned compute/eval-conflicts-rho010-r5-031-d6mkg to kind-worker5
0.4055,Event,ADDED,eval-conflicts-rho010-r5-031-d6mkg.18d466e082e0e667,"reason=Pulled count=1 msg=Container image ""busybox:musl"" already present on machine"
0.4058,Event,ADDED,eval-conflicts-rho010-r5-031-d6mkg.18d466e083f47946,reason=Created count=1 msg=Created container: task
0.406,Event,ADDED,eval-conflicts-rho010-r5-031-d6mkg.18d466e086080b15,reason=Started count=1 msg=Started container task
0.4062,Event,ADDED,eval-conflicts-rho010-r5-031.18d466e068913ef3,reason=SuccessfulCreate count=1 msg=Created pod: eval-conflicts-rho010-r5-031-d6mkg
0.4064,Event,ADDED,eval-conflicts-rho010-r5-031.18d466e3a5cbd037,reason=Completed count=1 msg=Job completed
0.4065,Event,ADDED,eval-conflicts-rho010-r5-032-lsr4c.18d466e0a5bfdd17,reason=Scheduled count=None msg=Successfully assigned compute/eval-conflicts-rho010-r5-032-lsr4c to kind-worker5
0.4067,Event,ADDED,eval-conflicts-rho010-r5-032-lsr4c.18d466e0be293f54,"reason=Pulled count=1 msg=Container image ""busybox:musl"" already present on machine"
0.4069,Event,ADDED,eval-conflicts-rho010-r5-032-lsr4c.18d466e0bf4478f6,reason=Created count=1 msg=Created container: task
0.4071,Event,ADDED,eval-conflicts-rho010-r5-032-lsr4c.18d466e0c427220e,reason=Started count=1 msg=Started container task
0.4073,Event,ADDED,eval-conflicts-rho010-r5-032.18d466e0a49531ff,reason=SuccessfulCreate count=1 msg=Created pod: eval-conflicts-rho010-r5-032-lsr4c
0.4074,Event,ADDED,eval-conflicts-rho010-r5-032.18d466e3e1aa2238,reason=Completed count=1 msg=Job completed
0.4076,Event,ADDED,eval-conflicts-rho010-r5-033-w2zrx.18d466e0e072c696,reason=Scheduled count=None msg=Successfully assigned compute/eval-conflicts-rho010-r5-033-w2zrx to kind-worker5
0.4078,Event,ADDED,eval-conflicts-rho010-r5-033-w2zrx.18d466e0fc33b5a5,"reason=Pulled count=1 msg=Container image ""busybox:musl"" already present on machine"
0.4081,Event,ADDED,eval-conflicts-rho010-r5-033-w2zrx.18d466e0fd4eff60,reason=Created count=1 msg=Created container: task
0.4088,Event,ADDED,eval-conflicts-rho010-r5-033-w2zrx.18d466e1060d99ed,reason=Started count=1 msg=Started container task
0.4093,Event,ADDED,eval-conflicts-rho010-r5-033.18d466e0df9547ab,reason=SuccessfulCreate count=1 msg=Created pod: eval-conflicts-rho010-r5-033-w2zrx
0.4096,Event,ADDED,eval-conflicts-rho010-r5-033.18d466e41f5e52e6,reason=Completed count=1 msg=Job completed
0.4098,Event,ADDED,eval-conflicts-rho010-r5-034-5jzfh.18d466e11bab66e1,reason=Scheduled count=None msg=Successfully assigned compute/eval-conflicts-rho010-r5-034-5jzfh to kind-worker5
0.4101,Event,ADDED,eval-conflicts-rho010-r5-034-5jzfh.18d466e133ff792f,"reason=Pulled count=1 msg=Container image ""busybox:musl"" already present on machine"
0.4104,Event,ADDED,eval-conflicts-rho010-r5-034-5jzfh.18d466e1352c8ad4,reason=Created count=1 msg=Created container: task
0.4106,Event,ADDED,eval-conflicts-rho010-r5-034-5jzfh.18d466e13b6c27fd,reason=Started count=1 msg=Started container task
0.4108,Event,ADDED,eval-conflicts-rho010-r5-034.18d466e11ab2c5d7,reason=SuccessfulCreate count=1 msg=Created pod: eval-conflicts-rho010-r5-034-5jzfh
0.4109,Event,ADDED,eval-conflicts-rho010-r5-034.18d466e4547d249e,reason=Completed count=1 msg=Job completed
0.4112,Event,ADDED,eval-conflicts-rho010-r5-035-clwnl.18d466e1572862ac,reason=Scheduled count=None msg=Successfully assigned compute/eval-conflicts-rho010-r5-035-clwnl to kind-worker4
0.4114,Event,ADDED,eval-conflicts-rho010-r5-035-clwnl.18d466e1719d8c2f,"reason=Pulled count=1 msg=Container image ""busybox:musl"" already present on machine"
0.4116,Event,ADDED,eval-conflicts-rho010-r5-035-clwnl.18d466e172ac51a3,reason=Created count=1 msg=Created container: task
0.4118,Event,ADDED,eval-conflicts-rho010-r5-035-clwnl.18d466e17667ff2e,reason=Started count=1 msg=Started container task
0.4122,Event,ADDED,eval-conflicts-rho010-r5-035.18d466e1566f4e46,reason=SuccessfulCreate count=1 msg=Created pod: eval-conflicts-rho010-r5-035-clwnl
0.4124,Event,ADDED,eval-conflicts-rho010-r5-035.18d466e49ba7e907,reason=Completed count=1 msg=Job completed
0.4125,Event,ADDED,eval-conflicts-rho010-r5-036-zswxt.18d466e192ad8eac,reason=Scheduled count=None msg=Successfully assigned compute/eval-conflicts-rho010-r5-036-zswxt to kind-worker4
0.4128,Event,ADDED,eval-conflicts-rho010-r5-036-zswxt.18d466e1adb39bcf,"reason=Pulled count=1 msg=Container image ""busybox:musl"" already present on machine"
0.413,Event,ADDED,eval-conflicts-rho010-r5-036-zswxt.18d466e1aedaa2c4,reason=Created count=1 msg=Created container: task
0.4132,Event,ADDED,eval-conflicts-rho010-r5-036-zswxt.18d466e1b79c0c24,reason=Started count=1 msg=Started container task
0.4134,Event,ADDED,eval-conflicts-rho010-r5-036.18d466e191dd2246,reason=SuccessfulCreate count=1 msg=Created pod: eval-conflicts-rho010-r5-036-zswxt
0.4137,Event,ADDED,eval-conflicts-rho010-r5-036.18d466e4d752e75a,reason=Completed count=1 msg=Job completed
0.4138,Event,ADDED,eval-conflicts-rho010-r5-037-qrr52.18d466e1ce49d478,reason=Scheduled count=None msg=Successfully assigned compute/eval-conflicts-rho010-r5-037-qrr52 to kind-worker4
0.414,Event,ADDED,eval-conflicts-rho010-r5-037-qrr52.18d466e1eb36d6b6,"reason=Pulled count=1 msg=Container image ""busybox:musl"" already present on machine"
0.4143,Event,ADDED,eval-conflicts-rho010-r5-037-qrr52.18d466e1ec72f982,reason=Created count=1 msg=Created container: task
0.4145,Event,ADDED,eval-conflicts-rho010-r5-037-qrr52.18d466e1f2bb6a38,reason=Started count=1 msg=Started container task
0.4147,Event,ADDED,eval-conflicts-rho010-r5-037.18d466e1cd7774c0,reason=SuccessfulCreate count=1 msg=Created pod: eval-conflicts-rho010-r5-037-qrr52
0.4148,Event,ADDED,eval-conflicts-rho010-r5-037.18d466e50d9522b1,reason=Completed count=1 msg=Job completed
0.4151,Event,ADDED,eval-conflicts-rho010-r5-038-62t4d.18d466e20a4d4a9a,reason=Scheduled count=None msg=Successfully assigned compute/eval-conflicts-rho010-r5-038-62t4d to kind-worker4
0.4153,Event,ADDED,eval-conflicts-rho010-r5-038-62t4d.18d466e223c5e1b7,"reason=Pulled count=1 msg=Container image ""busybox:musl"" already present on machine"
0.4155,Event,ADDED,eval-conflicts-rho010-r5-038-62t4d.18d466e224ddb018,reason=Created count=1 msg=Created container: task
0.4157,Event,ADDED,eval-conflicts-rho010-r5-038-62t4d.18d466e226ad006e,reason=Started count=1 msg=Started container task
0.416,Event,ADDED,eval-conflicts-rho010-r5-038.18d466e2097640c7,reason=SuccessfulCreate count=1 msg=Created pod: eval-conflicts-rho010-r5-038-62t4d
0.4162,Event,ADDED,eval-conflicts-rho010-r5-038.18d466e549a54fbc,reason=Completed count=1 msg=Job completed
0.4164,Event,ADDED,eval-conflicts-rho010-r5-039-q9psz.18d466e24818e5ea,reason=Scheduled count=None msg=Successfully assigned compute/eval-conflicts-rho010-r5-039-q9psz to kind-worker3
0.4166,Event,ADDED,eval-conflicts-rho010-r5-039-q9psz.18d466e263c65a07,"reason=Pulled count=1 msg=Container image ""busybox:musl"" already present on machine"
0.4168,Event,ADDED,eval-conflicts-rho010-r5-039-q9psz.18d466e264e8704c,reason=Created count=1 msg=Created container: task
0.417,Event,ADDED,eval-conflicts-rho010-r5-039-q9psz.18d466e268c44546,reason=Started count=1 msg=Started container task
0.4172,Event,ADDED,eval-conflicts-rho010-r5-039.18d466e247676813,reason=SuccessfulCreate count=1 msg=Created pod: eval-conflicts-rho010-r5-039-q9psz
0.4174,Event,ADDED,eval-conflicts-rho010-r5-039.18d466e5a3b81b8f,reason=Completed count=1 msg=Job completed
0.4175,Event,ADDED,eval-conflicts-rho010-r5-040-tdfbc.18d466e2834a7e06,reason=Scheduled count=None msg=Successfully assigned compute/eval-conflicts-rho010-r5-040-tdfbc to kind-worker3
0.4178,Event,ADDED,eval-conflicts-rho010-r5-040-tdfbc.18d466e29d2f0214,"reason=Pulled count=1 msg=Container image ""busybox:musl"" already present on machine"
0.4179,Event,ADDED,eval-conflicts-rho010-r5-040-tdfbc.18d466e29e52b3dc,reason=Created count=1 msg=Created container: task
0.4181,Event,ADDED,eval-conflicts-rho010-r5-040-tdfbc.18d466e2a49d9769,reason=Started count=1 msg=Started container task
0.4184,Event,ADDED,eval-conflicts-rho010-r5-040.18d466e2828cd48d,reason=SuccessfulCreate count=1 msg=Created pod: eval-conflicts-rho010-r5-040-tdfbc
0.4185,Event,ADDED,eval-conflicts-rho010-r5-040.18d466e5dfbaf6eb,reason=Completed count=1 msg=Job completed
0.4187,Event,ADDED,eval-conflicts-rho010-r5-041-nlptv.18d466e2bcc0f6fd,reason=Scheduled count=None msg=Successfully assigned compute/eval-conflicts-rho010-r5-041-nlptv to kind-worker4
0.4189,Event,ADDED,eval-conflicts-rho010-r5-041-nlptv.18d466e2d7ed7a38,"reason=Pulled count=1 msg=Container image ""busybox:musl"" already present on machine"
0.419,Event,ADDED,eval-conflicts-rho010-r5-041-nlptv.18d466e2d919a348,reason=Created count=1 msg=Created container: task
0.4192,Event,ADDED,eval-conflicts-rho010-r5-041-nlptv.18d466e2de3f591c,reason=Started count=1 msg=Started container task
0.4194,Event,ADDED,eval-conflicts-rho010-r5-041.18d466e2bbe07ec0,reason=SuccessfulCreate count=1 msg=Created pod: eval-conflicts-rho010-r5-041-nlptv
0.4196,Event,ADDED,eval-conflicts-rho010-r5-041.18d466e5fd955272,reason=Completed count=1 msg=Job completed
0.4197,Event,ADDED,eval-conflicts-rho010-r5-042-726fh.18d466e2f8aafe47,reason=Scheduled count=None msg=Successfully assigned compute/eval-conflicts-rho010-r5-042-726fh to kind-worker3
0.4199,Event,ADDED,eval-conflicts-rho010-r5-042-726fh.18d466e31332ddd4,"reason=Pulled count=1 msg=Container image ""busybox:musl"" already present on machine"
0.4202,Event,ADDED,eval-conflicts-rho010-r5-042-726fh.18d466e3144da923,reason=Created count=1 msg=Created container: task
0.4205,Event,ADDED,eval-conflicts-rho010-r5-042-726fh.18d466e3166b8dd8,reason=Started count=1 msg=Started container task
0.4207,Event,ADDED,eval-conflicts-rho010-r5-042.18d466e2f7de3ebd,reason=SuccessfulCreate count=1 msg=Created pod: eval-conflicts-rho010-r5-042-726fh
0.4209,Event,ADDED,eval-conflicts-rho010-r5-042.18d466e656bd9379,reason=Completed count=1 msg=Job completed
0.421,Event,ADDED,eval-conflicts-rho010-r5-043-dc4f8.18d466e33767f935,reason=Scheduled count=None msg=Successfully assigned compute/eval-conflicts-rho010-r5-043-dc4f8 to kind-worker3
0.4219,Event,ADDED,eval-conflicts-rho010-r5-043-dc4f8.18d466e35313c7e0,"reason=Pulled count=1 msg=Container image ""busybox:musl"" already present on machine"
0.4222,Event,ADDED,eval-conflicts-rho010-r5-043-dc4f8.18d466e3541e306a,reason=Created count=1 msg=Created container: task
0.4224,Event,ADDED,eval-conflicts-rho010-r5-043-dc4f8.18d466e358b33132,reason=Started count=1 msg=Started container task
0.4226,Event,ADDED,eval-conflicts-rho010-r5-043.18d466e336616137,reason=SuccessfulCreate count=1 msg=Created pod: eval-conflicts-rho010-r5-043-dc4f8
0.4229,Event,ADDED,eval-conflicts-rho010-r5-043.18d466e692926b92,reason=Completed count=1 msg=Job completed
0.4231,Event,ADDED,eval-conflicts-rho010-r5-044-vj7gs.18d466e36f87ac55,reason=Scheduled count=None msg=Successfully assigned compute/eval-conflicts-rho010-r5-044-vj7gs to kind-worker
0.4233,Event,ADDED,eval-conflicts-rho010-r5-044-vj7gs.18d466e389fa806a,"reason=Pulled count=1 msg=Container image ""busybox:musl"" already present on machine"
0.4236,Event,ADDED,eval-conflicts-rho010-r5-044-vj7gs.18d466e38b133d2a,reason=Created count=1 msg=Created container: task
0.4238,Event,ADDED,eval-conflicts-rho010-r5-044-vj7gs.18d466e3926b9257,reason=Started count=1 msg=Started container task
0.4239,Event,ADDED,eval-conflicts-rho010-r5-044.18d466e36ed27f90,reason=SuccessfulCreate count=1 msg=Created pod: eval-conflicts-rho010-r5-044-vj7gs
0.4242,Event,ADDED,eval-conflicts-rho010-r5-044.18d466e6d8fce104,reason=Completed count=1 msg=Job completed
0.4244,Event,ADDED,eval-conflicts-rho010-r5-045-wvfds.18d466e3ab687fd5,reason=Scheduled count=None msg=Successfully assigned compute/eval-conflicts-rho010-r5-045-wvfds to kind-worker
0.4246,Event,ADDED,eval-conflicts-rho010-r5-045-wvfds.18d466e3c57e1e3e,"reason=Pulled count=1 msg=Container image ""busybox:musl"" already present on machine"
0.4248,Event,ADDED,eval-conflicts-rho010-r5-045-wvfds.18d466e3c6b64091,reason=Created count=1 msg=Created container: task
0.4251,Event,ADDED,eval-conflicts-rho010-r5-045-wvfds.18d466e3ce582ea7,reason=Started count=1 msg=Started container task
0.4253,Event,ADDED,eval-conflicts-rho010-r5-045.18d466e3aac0fa02,reason=SuccessfulCreate count=1 msg=Created pod: eval-conflicts-rho010-r5-045-wvfds
0.4254,Event,ADDED,eval-conflicts-rho010-r5-045.18d466e6d91a28ab,reason=Completed count=1 msg=Job completed
0.4256,Event,ADDED,eval-conflicts-rho010-r5-046-gqpzq.18d466e3eb1b946f,reason=Scheduled count=None msg=Successfully assigned compute/eval-conflicts-rho010-r5-046-gqpzq to kind-worker2
0.4259,Event,ADDED,eval-conflicts-rho010-r5-046-gqpzq.18d466e40348b9a2,"reason=Pulled count=1 msg=Container image ""busybox:musl"" already present on machine"
0.4261,Event,ADDED,eval-conflicts-rho010-r5-046-gqpzq.18d466e40459f43f,reason=Created count=1 msg=Created container: task
0.4263,Event,ADDED,eval-conflicts-rho010-r5-046-gqpzq.18d466e40ab8b652,reason=Started count=1 msg=Started container task
0.4264,Event,ADDED,eval-conflicts-rho010-r5-046.18d466e3ea688acb,reason=SuccessfulCreate count=1 msg=Created pod: eval-conflicts-rho010-r5-046-gqpzq
0.4267,Event,ADDED,eval-conflicts-rho010-r5-046.18d466e7213188a0,reason=Completed count=1 msg=Job completed
0.4268,Event,ADDED,eval-conflicts-rho010-r5-047-g69mj.18d466e4228b6635,reason=Scheduled count=None msg=Successfully assigned compute/eval-conflicts-rho010-r5-047-g69mj to kind-worker5
0.427,Event,ADDED,eval-conflicts-rho010-r5-047-g69mj.18d466e4408b20f9,"reason=Pulled count=1 msg=Container image ""busybox:musl"" already present on machine"
0.4272,Event,ADDED,eval-conflicts-rho010-r5-047-g69mj.18d466e441aa2bac,reason=Created count=1 msg=Created container: task
0.4273,Event,ADDED,eval-conflicts-rho010-r5-047-g69mj.18d466e447f79c89,reason=Started count=1 msg=Started container task
0.4275,Event,ADDED,eval-conflicts-rho010-r5-047.18d466e421931d86,reason=SuccessfulCreate count=1 msg=Created pod: eval-conflicts-rho010-r5-047-g69mj
0.4277,Event,ADDED,eval-conflicts-rho010-r5-047.18d466e75dada61b,reason=Completed count=1 msg=Job completed
0.4278,Event,ADDED,eval-conflicts-rho010-r5-048-ftm2t.18d466e45e9097e5,reason=Scheduled count=None msg=Successfully assigned compute/eval-conflicts-rho010-r5-048-ftm2t to kind-worker5
0.4281,Event,ADDED,eval-conflicts-rho010-r5-048-ftm2t.18d466e47c0777d9,"reason=Pulled count=1 msg=Container image ""busybox:musl"" already present on machine"
0.4283,Event,ADDED,eval-conflicts-rho010-r5-048-ftm2t.18d466e47d2b9499,reason=Created count=1 msg=Created container: task
0.4284,Event,ADDED,eval-conflicts-rho010-r5-048-ftm2t.18d466e484740dbf,reason=Started count=1 msg=Started container task
0.4288,Event,ADDED,eval-conflicts-rho010-r5-048.18d466e45d792d36,reason=SuccessfulCreate count=1 msg=Created pod: eval-conflicts-rho010-r5-048-ftm2t
0.429,Event,ADDED,eval-conflicts-rho010-r5-048.18d466e7992473d7,reason=Completed count=1 msg=Job completed
0.4292,Event,ADDED,eval-conflicts-rho010-r5-049-tk8dk.18d466e49ea721a1,reason=Scheduled count=None msg=Successfully assigned compute/eval-conflicts-rho010-r5-049-tk8dk to kind-worker2
0.4295,Event,ADDED,eval-conflicts-rho010-r5-049-tk8dk.18d466e4bb2b6fba,"reason=Pulled count=1 msg=Container image ""busybox:musl"" already present on machine"
0.4297,Event,ADDED,eval-conflicts-rho010-r5-049-tk8dk.18d466e4bc52a165,reason=Created count=1 msg=Created container: task
0.4299,Event,ADDED,eval-conflicts-rho010-r5-049-tk8dk.18d466e4cd3809fb,reason=Started count=1 msg=Started container task
0.4301,Event,ADDED,eval-conflicts-rho010-r5-049.18d466e49d95568e,reason=SuccessfulCreate count=1 msg=Created pod: eval-conflicts-rho010-r5-049-tk8dk
0.4304,Event,ADDED,eval-conflicts-rho010-r5-049.18d466e80ffecb5f,reason=Completed count=1 msg=Job completed
0.4305,Event,ADDED,eval-conflicts-rho010-r5-050-2qh4f.18d466e4d55cb794,reason=Scheduled count=None msg=Successfully assigned compute/eval-conflicts-rho010-r5-050-2qh4f to kind-worker2
0.4307,Event,ADDED,eval-conflicts-rho010-r5-050-2qh4f.18d466e4ef5928f8,"reason=Pulled count=1 msg=Container image ""busybox:musl"" already present on machine"
0.4314,Event,ADDED,eval-conflicts-rho010-r5-050-2qh4f.18d466e4f078f333,reason=Created count=1 msg=Created container: task
0.4315,Event,ADDED,eval-conflicts-rho010-r5-050-2qh4f.18d466e4f57fe679,reason=Started count=1 msg=Started container task
0.4317,Event,ADDED,eval-conflicts-rho010-r5-050.18d466e4d4590092,reason=SuccessfulCreate count=1 msg=Created pod: eval-conflicts-rho010-r5-050-2qh4f
0.4319,Event,ADDED,eval-conflicts-rho010-r5-050.18d466e80fe25c5e,reason=Completed count=1 msg=Job completed
0.4322,Event,ADDED,eval-conflicts-rho010-r5-051-s5rbt.18d466e5117a5671,reason=Scheduled count=None msg=Successfully assigned compute/eval-conflicts-rho010-r5-051-s5rbt to kind-worker5
0.4325,Event,ADDED,eval-conflicts-rho010-r5-051-s5rbt.18d466e52a628de8,"reason=Pulled count=1 msg=Container image ""busybox:musl"" already present on machine"
0.4326,Event,ADDED,eval-conflicts-rho010-r5-051-s5rbt.18d466e52bd6e43e,reason=Created count=1 msg=Created container: task
0.4328,Event,ADDED,eval-conflicts-rho010-r5-051-s5rbt.18d466e53283d8cf,reason=Started count=1 msg=Started container task
0.4332,Event,ADDED,eval-conflicts-rho010-r5-051.18d466e51051c6cb,reason=SuccessfulCreate count=1 msg=Created pod: eval-conflicts-rho010-r5-051-s5rbt
0.4333,Event,ADDED,eval-conflicts-rho010-r5-051.18d466e84d70c74a,reason=Completed count=1 msg=Job completed
0.4335,Event,ADDED,eval-conflicts-rho010-r5-052-zqmbp.18d466e54c5d23b9,"reason=FailedScheduling count=None msg=0/6 nodes are available: 3 c_wall violated: 1 conflicting context pair(s) with node memory, 3 node(s) had untolerated taint(s). no new claims to deallocate, preemption: 0/6 nodes are available: 3 No preemption victims found for incoming pod, 3 Preemption is not helpful for scheduling."
0.4339,Event,ADDED,eval-conflicts-rho010-r5-052-zqmbp.18d466e5510f9ebb,"reason=FailedScheduling count=None msg=0/6 nodes are available: 3 c_wall violated: 1 conflicting context pair(s) with node memory, 3 node(s) had untolerated taint(s). no new claims to deallocate, preemption: 0/6 nodes are available: 3 No preemption victims found for incoming pod, 3 Preemption is not helpful for scheduling."
0.4341,Event,ADDED,eval-conflicts-rho010-r5-052-zqmbp.18d466e59432c6e6,"reason=FailedScheduling count=None msg=0/6 nodes are available: 2 c_wall violated: 1 conflicting context pair(s) with node memory, 4 node(s) had untolerated taint(s). no new claims to deallocate, preemption: 0/6 nodes are available: 2 No preemption victims found for incoming pod, 4 Preemption is not helpful for scheduling."
0.4343,Event,ADDED,eval-conflicts-rho010-r5-052-zqmbp.18d466e5f26f880d,reason=Scheduled count=None msg=Successfully assigned compute/eval-conflicts-rho010-r5-052-zqmbp to kind-worker4
0.4348,Event,ADDED,eval-conflicts-rho010-r5-052-zqmbp.18d466e60af4c8e1,"reason=Pulled count=1 msg=Container image ""busybox:musl"" already present on machine"
0.435,Event,ADDED,eval-conflicts-rho010-r5-052-zqmbp.18d466e60c01721e,reason=Created count=1 msg=Created container: task
0.4351,Event,ADDED,eval-conflicts-rho010-r5-052-zqmbp.18d466e60dec9fb6,reason=Started count=1 msg=Started container task
0.4353,Event,ADDED,eval-conflicts-rho010-r5-052.18d466e54badf6b3,reason=SuccessfulCreate count=1 msg=Created pod: eval-conflicts-rho010-r5-052-zqmbp
0.4356,Event,ADDED,eval-conflicts-rho010-r5-052.18d466e941b3c01d,reason=Completed count=1 msg=Job completed
0.4358,Event,ADDED,eval-conflicts-rho010-r5-053-wrcv2.18d466e58890edaf,reason=Scheduled count=None msg=Successfully assigned compute/eval-conflicts-rho010-r5-053-wrcv2 to kind-worker5
0.436,Event,ADDED,eval-conflicts-rho010-r5-053-wrcv2.18d466e5a11ca9fa,"reason=Pulled count=1 msg=Container image ""busybox:musl"" already present on machine"
0.4363,Event,ADDED,eval-conflicts-rho010-r5-053-wrcv2.18d466e5a255a165,reason=Created count=1 msg=Created container: task
0.4365,Event,ADDED,eval-conflicts-rho010-r5-053-wrcv2.18d466e5a9fa18b2,reason=Started count=1 msg=Started container task
0.4366,Event,ADDED,eval-conflicts-rho010-r5-053.18d466e5875d91f9,reason=SuccessfulCreate count=1 msg=Created pod: eval-conflicts-rho010-r5-053-wrcv2
0.4368,Event,ADDED,eval-conflicts-rho010-r5-053.18d466e8c4506a90,reason=Completed count=1 msg=Job completed
0.4371,Event,ADDED,eval-conflicts-rho010-r5-054-6fqzt.18d466e5c4074519,reason=Scheduled count=None msg=Successfully assigned compute/eval-conflicts-rho010-r5-054-6fqzt to kind-worker2
0.4374,Event,ADDED,eval-conflicts-rho010-r5-054-6fqzt.18d466e5dd8f1b42,"reason=Pulled count=1 msg=Container image ""busybox:musl"" already present on machine"
0.4376,Event,ADDED,eval-conflicts-rho010-r5-054-6fqzt.18d466e5ded18737,reason=Created count=1 msg=Created container: task
0.4377,Event,ADDED,eval-conflicts-rho010-r5-054-6fqzt.18d466e5e9815b86,reason=Started count=1 msg=Started container task
0.4383,Event,ADDED,eval-conflicts-rho010-r5-054.18d466e5c3231a30,reason=SuccessfulCreate count=1 msg=Created pod: eval-conflicts-rho010-r5-054-6fqzt
0.4387,Event,ADDED,eval-conflicts-rho010-r5-054.18d466e8ff5ea3f7,reason=Completed count=1 msg=Job completed
0.4389,Event,ADDED,eval-conflicts-rho010-r5-055-8bhff.18d466e5ffb017a9,reason=Scheduled count=None msg=Successfully assigned compute/eval-conflicts-rho010-r5-055-8bhff to kind-worker4
0.4392,Event,ADDED,eval-conflicts-rho010-r5-055-8bhff.18d466e618cea4ef,"reason=Pulled count=1 msg=Container image ""busybox:musl"" already present on machine"
0.4394,Event,ADDED,eval-conflicts-rho010-r5-055-8bhff.18d466e619ea3fa6,reason=Created count=1 msg=Created container: task
0.4396,Event,ADDED,eval-conflicts-rho010-r5-055-8bhff.18d466e6279e8b57,reason=Started count=1 msg=Started container task
0.4397,Event,ADDED,eval-conflicts-rho010-r5-055.18d466e5fe8e9f2a,reason=SuccessfulCreate count=1 msg=Created pod: eval-conflicts-rho010-r5-055-8bhff
0.4401,Event,ADDED,eval-conflicts-rho010-r5-055.18d466e905cc40bf,reason=Completed count=1 msg=Job completed
0.4403,Event,ADDED,eval-conflicts-rho010-r5-056-snhrg.18d466e63ae537cc,reason=Scheduled count=None msg=Successfully assigned compute/eval-conflicts-rho010-r5-056-snhrg to kind-worker5
0.4405,Event,ADDED,eval-conflicts-rho010-r5-056-snhrg.18d466e65436582c,"reason=Pulled count=1 msg=Container image ""busybox:musl"" already present on machine"
0.4407,Event,ADDED,eval-conflicts-rho010-r5-056-snhrg.18d466e6554848a1,reason=Created count=1 msg=Created container: task
0.4409,Event,ADDED,eval-conflicts-rho010-r5-056-snhrg.18d466e6575c01ec,reason=Started count=1 msg=Started container task
0.4411,Event,ADDED,eval-conflicts-rho010-r5-056.18d466e639fce970,reason=SuccessfulCreate count=1 msg=Created pod: eval-conflicts-rho010-r5-056-snhrg
0.4413,Event,ADDED,eval-conflicts-rho010-r5-056.18d466e977ba4c45,reason=Completed count=1 msg=Job completed
0.4414,Event,ADDED,eval-conflicts-rho010-r5-057-9bd5q.18d466e676259165,reason=Scheduled count=None msg=Successfully assigned compute/eval-conflicts-rho010-r5-057-9bd5q to kind-worker4
0.4416,Event,ADDED,eval-conflicts-rho010-r5-057-9bd5q.18d466e68f2775e7,"reason=Pulled count=1 msg=Container image ""busybox:musl"" already present on machine"
0.4418,Event,ADDED,eval-conflicts-rho010-r5-057-9bd5q.18d466e690355cda,reason=Created count=1 msg=Created container: task
0.4419,Event,ADDED,eval-conflicts-rho010-r5-057-9bd5q.18d466e6924dbbfd,reason=Started count=1 msg=Started container task
0.4421,Event,ADDED,eval-conflicts-rho010-r5-057.18d466e67586742a,reason=SuccessfulCreate count=1 msg=Created pod: eval-conflicts-rho010-r5-057-9bd5q
0.4423,Event,ADDED,eval-conflicts-rho010-r5-057.18d466e97da0f102,reason=Completed count=1 msg=Job completed
0.4425,Event,ADDED,eval-conflicts-rho010-r5-058-h2tb8.18d466e6b1a3cd35,reason=Scheduled count=None msg=Successfully assigned compute/eval-conflicts-rho010-r5-058-h2tb8 to kind-worker4
0.4427,Event,ADDED,eval-conflicts-rho010-r5-058-h2tb8.18d466e6cb3fe213,"reason=Pulled count=1 msg=Container image ""busybox:musl"" already present on machine"
0.4429,Event,ADDED,eval-conflicts-rho010-r5-058-h2tb8.18d466e6cc56625c,reason=Created count=1 msg=Created container: task
0.4431,Event,ADDED,eval-conflicts-rho010-r5-058-h2tb8.18d466e6ce52905d,reason=Started count=1 msg=Started container task
0.4433,Event,ADDED,eval-conflicts-rho010-r5-058.18d466e6b1267f2e,reason=SuccessfulCreate count=1 msg=Created pod: eval-conflicts-rho010-r5-058-h2tb8
0.4437,Event,ADDED,eval-conflicts-rho010-r5-058.18d466e9f50864f8,reason=Completed count=1 msg=Job completed
0.4439,Event,ADDED,eval-conflicts-rho010-r5-059-wljc6.18d466e6ed5dcf98,reason=Scheduled count=None msg=Successfully assigned compute/eval-conflicts-rho010-r5-059-wljc6 to kind-worker4
0.4442,Event,ADDED,eval-conflicts-rho010-r5-059-wljc6.18d466e70681613f,"reason=Pulled count=1 msg=Container image ""busybox:musl"" already present on machine"
0.4444,Event,ADDED,eval-conflicts-rho010-r5-059-wljc6.18d466e707a101d6,reason=Created count=1 msg=Created container: task
0.4447,Event,ADDED,eval-conflicts-rho010-r5-059-wljc6.18d466e70b6b0360,reason=Started count=1 msg=Started container task
0.4449,Event,ADDED,eval-conflicts-rho010-r5-059.18d466e6ecd2554c,reason=SuccessfulCreate count=1 msg=Created pod: eval-conflicts-rho010-r5-059-wljc6
0.4451,Event,ADDED,eval-conflicts-rho010-r5-059.18d466e9f590596d,reason=Completed count=1 msg=Job completed
0.4455,Event,ADDED,eval-conflicts-rho010-r5-060-hj8dg.18d466e7294dfb26,reason=Scheduled count=None msg=Successfully assigned compute/eval-conflicts-rho010-r5-060-hj8dg to kind-worker4
0.4457,Event,ADDED,eval-conflicts-rho010-r5-060-hj8dg.18d466e742283786,"reason=Pulled count=1 msg=Container image ""busybox:musl"" already present on machine"
0.4459,Event,ADDED,eval-conflicts-rho010-r5-060-hj8dg.18d466e7433cdd96,reason=Created count=1 msg=Created container: task
0.4461,Event,ADDED,eval-conflicts-rho010-r5-060-hj8dg.18d466e74549c3a7,reason=Started count=1 msg=Started container task
0.4464,Event,ADDED,eval-conflicts-rho010-r5-060.18d466e728b3dd16,reason=SuccessfulCreate count=1 msg=Created pod: eval-conflicts-rho010-r5-060-hj8dg
0.4469,Event,ADDED,eval-conflicts-rho010-r5-060.18d466ea6cc869f4,reason=Completed count=1 msg=Job completed
0.4471,Event,ADDED,eval-conflicts-rho010-r5-061-svjzz.18d466e7648d561c,"reason=FailedScheduling count=None msg=0/6 nodes are available: 1 c_wall violated: 1 conflicting context pair(s) with node memory, 5 node(s) had untolerated taint(s). no new claims to deallocate, preemption: 0/6 nodes are available: 1 No preemption victims found for incoming pod, 5 Preemption is not helpful for scheduling."
0.4475,Event,ADDED,eval-conflicts-rho010-r5-061-svjzz.18d466e764f8138e,"reason=FailedScheduling count=None msg=0/6 nodes are available: 1 c_wall violated: 1 conflicting context pair(s) with node memory, 5 node(s) had untolerated taint(s). no new claims to deallocate, preemption: 0/6 nodes are available: 1 No preemption victims found for incoming pod, 5 Preemption is not helpful for scheduling."
0.4476,Event,ADDED,eval-conflicts-rho010-r5-061-svjzz.18d466e7ec7ad4ec,reason=Scheduled count=None msg=Successfully assigned compute/eval-conflicts-rho010-r5-061-svjzz to kind-worker
0.4478,Event,ADDED,eval-conflicts-rho010-r5-061-svjzz.18d466e805d937f5,"reason=Pulled count=1 msg=Container image ""busybox:musl"" already present on machine"
0.4481,Event,ADDED,eval-conflicts-rho010-r5-061-svjzz.18d466e806fbf88f,reason=Created count=1 msg=Created container: task
0.4484,Event,ADDED,eval-conflicts-rho010-r5-061-svjzz.18d466e808e7293f,reason=Started count=1 msg=Started container task
0.4486,Event,ADDED,eval-conflicts-rho010-r5-061.18d466e7643c6de8,reason=SuccessfulCreate count=1 msg=Created pod: eval-conflicts-rho010-r5-061-svjzz
0.4487,Event,ADDED,eval-conflicts-rho010-r5-061.18d466eb49525b90,reason=Completed count=1 msg=Job completed
0.449,Event,ADDED,eval-conflicts-rho010-r5-062-9cxpr.18d466e7a07a2d98,reason=Scheduled count=None msg=Successfully assigned compute/eval-conflicts-rho010-r5-062-9cxpr to kind-worker4
0.4492,Event,ADDED,eval-conflicts-rho010-r5-062-9cxpr.18d466e7b90e64fd,"reason=Pulled count=1 msg=Container image ""busybox:musl"" already present on machine"
0.4494,Event,ADDED,eval-conflicts-rho010-r5-062-9cxpr.18d466e7ba2077b3,reason=Created count=1 msg=Created container: task
0.4495,Event,ADDED,eval-conflicts-rho010-r5-062-9cxpr.18d466e7bc0b28af,reason=Started count=1 msg=Started container task
0.4498,Event,ADDED,eval-conflicts-rho010-r5-062.18d466e7a00630c0,reason=SuccessfulCreate count=1 msg=Created pod: eval-conflicts-rho010-r5-062-9cxpr
0.45,Event,ADDED,eval-conflicts-rho010-r5-062.18d466eae4a4c9dd,reason=Completed count=1 msg=Job completed
0.4502,Event,ADDED,eval-conflicts-rho010-r5-063-cljs2.18d466e7dc75178a,reason=Scheduled count=None msg=Successfully assigned compute/eval-conflicts-rho010-r5-063-cljs2 to kind-worker4
0.4504,Event,ADDED,eval-conflicts-rho010-r5-063-cljs2.18d466e7f54867fc,"reason=Pulled count=1 msg=Container image ""busybox:musl"" already present on machine"
0.4506,Event,ADDED,eval-conflicts-rho010-r5-063-cljs2.18d466e7f666c1be,reason=Created count=1 msg=Created container: task
0.4508,Event,ADDED,eval-conflicts-rho010-r5-063-cljs2.18d466e7f89de5e1,reason=Started count=1 msg=Started container task
0.4509,Event,ADDED,eval-conflicts-rho010-r5-063.18d466e7dbdd7b4b,reason=SuccessfulCreate count=1 msg=Created pod: eval-conflicts-rho010-r5-063-cljs2
0.4511,Event,ADDED,eval-conflicts-rho010-r5-063.18d466eb201a3aae,reason=Completed count=1 msg=Job completed
0.4513,Event,ADDED,eval-conflicts-rho010-r5-064-rpdk4.18d466e817aed28a,reason=Scheduled count=None msg=Successfully assigned compute/eval-conflicts-rho010-r5-064-rpdk4 to kind-worker
0.4514,Event,ADDED,eval-conflicts-rho010-r5-064-rpdk4.18d466e8302d0f90,"reason=Pulled count=1 msg=Container image ""busybox:musl"" already present on machine"
0.4517,Event,ADDED,eval-conflicts-rho010-r5-064-rpdk4.18d466e83133b611,reason=Created count=1 msg=Created container: task
0.4519,Event,ADDED,eval-conflicts-rho010-r5-064-rpdk4.18d466e8331d0a0b,reason=Started count=1 msg=Started container task
0.4521,Event,ADDED,eval-conflicts-rho010-r5-064.18d466e816f01789,reason=SuccessfulCreate count=1 msg=Created pod: eval-conflicts-rho010-r5-064-rpdk4
0.4523,Event,ADDED,eval-conflicts-rho010-r5-064.18d466eb493314f7,reason=Completed count=1 msg=Job completed
0.4526,Event,ADDED,eval-conflicts-rho010-r5-065-d4gmr.18d466e8532d8c07,reason=Scheduled count=None msg=Successfully assigned compute/eval-conflicts-rho010-r5-065-d4gmr to kind-worker3
0.4528,Event,ADDED,eval-conflicts-rho010-r5-065-d4gmr.18d466e86bfc4d14,"reason=Pulled count=1 msg=Container image ""busybox:musl"" already present on machine"
0.453,Event,ADDED,eval-conflicts-rho010-r5-065-d4gmr.18d466e86d0eb27e,reason=Created count=1 msg=Created container: task
0.4531,Event,ADDED,eval-conflicts-rho010-r5-065-d4gmr.18d466e86f029160,reason=Started count=1 msg=Started container task
0.4534,Event,ADDED,eval-conflicts-rho010-r5-065.18d466e8529e5579,reason=SuccessfulCreate count=1 msg=Created pod: eval-conflicts-rho010-r5-065-d4gmr
0.4536,Event,ADDED,eval-conflicts-rho010-r5-065.18d466ebb6224284,reason=Completed count=1 msg=Job completed
0.4538,Event,ADDED,eval-conflicts-rho010-r5-066-j57cn.18d466e8904194c6,reason=Scheduled count=None msg=Successfully assigned compute/eval-conflicts-rho010-r5-066-j57cn to kind-worker
0.4539,Event,ADDED,eval-conflicts-rho010-r5-066-j57cn.18d466e8a9491201,"reason=Pulled count=1 msg=Container image ""busybox:musl"" already present on machine"
0.4542,Event,ADDED,eval-conflicts-rho010-r5-066-j57cn.18d466e8aa6e703f,reason=Created count=1 msg=Created container: task
0.4544,Event,ADDED,eval-conflicts-rho010-r5-066-j57cn.18d466e8ac62d050,reason=Started count=1 msg=Started container task
0.4546,Event,ADDED,eval-conflicts-rho010-r5-066.18d466e88f02cae8,reason=SuccessfulCreate count=1 msg=Created pod: eval-conflicts-rho010-r5-066-j57cn
0.4548,Event,ADDED,eval-conflicts-rho010-r5-066.18d466ebc14343fc,reason=Completed count=1 msg=Job completed
0.455,Event,ADDED,eval-conflicts-rho010-r5-067-kz6nt.18d466e8cb11df7d,reason=Scheduled count=None msg=Successfully assigned compute/eval-conflicts-rho010-r5-067-kz6nt to kind-worker
0.4552,Event,ADDED,eval-conflicts-rho010-r5-067-kz6nt.18d466e8e3f94554,"reason=Pulled count=1 msg=Container image ""busybox:musl"" already present on machine"
0.4553,Event,ADDED,eval-conflicts-rho010-r5-067-kz6nt.18d466e8e513c41f,reason=Created count=1 msg=Created container: task
0.4555,Event,ADDED,eval-conflicts-rho010-r5-067-kz6nt.18d466e8ed28d742,reason=Started count=1 msg=Started container task
0.4557,Event,ADDED,eval-conflicts-rho010-r5-067.18d466e8ca2a4484,reason=SuccessfulCreate count=1 msg=Created pod: eval-conflicts-rho010-r5-067-kz6nt
0.4558,Event,ADDED,eval-conflicts-rho010-r5-067.18d466ebfcd6de2e,reason=Completed count=1 msg=Job completed
0.4561,Event,ADDED,eval-conflicts-rho010-r5-068-vkkjw.18d466e9065ab33b,reason=Scheduled count=None msg=Successfully assigned compute/eval-conflicts-rho010-r5-068-vkkjw to kind-worker
0.4565,Event,ADDED,eval-conflicts-rho010-r5-068-vkkjw.18d466e92036a2e8,"reason=Pulled count=1 msg=Container image ""busybox:musl"" already present on machine"
0.4567,Event,ADDED,eval-conflicts-rho010-r5-068-vkkjw.18d466e9215c9831,reason=Created count=1 msg=Created container: task
0.4568,Event,ADDED,eval-conflicts-rho010-r5-068-vkkjw.18d466e924b3d636,reason=Started count=1 msg=Started container task
0.457,Event,ADDED,eval-conflicts-rho010-r5-068.18d466e90553b4b7,reason=SuccessfulCreate count=1 msg=Created pod: eval-conflicts-rho010-r5-068-vkkjw
0.4572,Event,ADDED,eval-conflicts-rho010-r5-068.18d466ec3881b86c,reason=Completed count=1 msg=Job completed
0.4573,Event,ADDED,eval-conflicts-rho010-r5-069-pk2lm.18d466e9423a5768,reason=Scheduled count=None msg=Successfully assigned compute/eval-conflicts-rho010-r5-069-pk2lm to kind-worker
0.4575,Event,ADDED,eval-conflicts-rho010-r5-069-pk2lm.18d466e95b4b6d06,"reason=Pulled count=1 msg=Container image ""busybox:musl"" already present on machine"
0.4577,Event,ADDED,eval-conflicts-rho010-r5-069-pk2lm.18d466e95c660f70,reason=Created count=1 msg=Created container: task
0.4579,Event,ADDED,eval-conflicts-rho010-r5-069-pk2lm.18d466e96453ab53,reason=Started count=1 msg=Started container task
0.4581,Event,ADDED,eval-conflicts-rho010-r5-069.18d466e941373a84,reason=SuccessfulCreate count=1 msg=Created pod: eval-conflicts-rho010-r5-069-pk2lm
0.4583,Event,ADDED,eval-conflicts-rho010-r5-069.18d466ec7410a714,reason=Completed count=1 msg=Job completed
0.4586,Event,ADDED,eval-conflicts-rho010-r5-070-vb5mc.18d466e97dedb217,reason=Scheduled count=None msg=Successfully assigned compute/eval-conflicts-rho010-r5-070-vb5mc to kind-worker3
0.4588,Event,ADDED,eval-conflicts-rho010-r5-070-vb5mc.18d466e9972be44f,"reason=Pulled count=1 msg=Container image ""busybox:musl"" already present on machine"
0.4589,Event,ADDED,eval-conflicts-rho010-r5-070-vb5mc.18d466e9983bb8f6,reason=Created count=1 msg=Created container: task
0.4592,Event,ADDED,eval-conflicts-rho010-r5-070-vb5mc.18d466e99a37688c,reason=Started count=1 msg=Started container task
0.4593,Event,ADDED,eval-conflicts-rho010-r5-070.18d466e97cd7feb8,reason=SuccessfulCreate count=1 msg=Created pod: eval-conflicts-rho010-r5-070-vb5mc
0.4595,Event,ADDED,eval-conflicts-rho010-r5-070.18d466ecdfae2718,reason=Completed count=1 msg=Job completed
0.4596,Event,ADDED,eval-conflicts-rho010-r5-071-wp4hm.18d466e9b93c519b,reason=Scheduled count=None msg=Successfully assigned compute/eval-conflicts-rho010-r5-071-wp4hm to kind-worker
0.46,Event,ADDED,eval-conflicts-rho010-r5-071-wp4hm.18d466e9d3748de8,"reason=Pulled count=1 msg=Container image ""busybox:musl"" already present on machine"
0.4603,Event,ADDED,eval-conflicts-rho010-r5-071-wp4hm.18d466e9d496a04e,reason=Created count=1 msg=Created container: task
0.4606,Event,ADDED,eval-conflicts-rho010-r5-071-wp4hm.18d466e9d92505ae,reason=Started count=1 msg=Started container task
0.4609,Event,ADDED,eval-conflicts-rho010-r5-071.18d466e9b86bbb26,reason=SuccessfulCreate count=1 msg=Created pod: eval-conflicts-rho010-r5-071-wp4hm
0.4612,Event,ADDED,eval-conflicts-rho010-r5-071.18d466ecebde298d,reason=Completed count=1 msg=Job completed
0.4614,Event,ADDED,eval-conflicts-rho010-r5-072-hbxnt.18d466e9f509a426,reason=Scheduled count=None msg=Successfully assigned compute/eval-conflicts-rho010-r5-072-hbxnt to kind-worker
0.4615,Event,ADDED,eval-conflicts-rho010-r5-072-hbxnt.18d466ea0e925444,"reason=Pulled count=1 msg=Container image ""busybox:musl"" already present on machine"
0.4617,Event,ADDED,eval-conflicts-rho010-r5-072-hbxnt.18d466ea0faebc80,reason=Created count=1 msg=Created container: task
0.4619,Event,ADDED,eval-conflicts-rho010-r5-072-hbxnt.18d466ea11a163fd,reason=Started count=1 msg=Started container task
0.4621,Event,ADDED,eval-conflicts-rho010-r5-072.18d466e9f4234910,reason=SuccessfulCreate count=1 msg=Created pod: eval-conflicts-rho010-r5-072-hbxnt
0.4622,Event,ADDED,eval-conflicts-rho010-r5-072.18d466ed27b47d01,reason=Completed count=1 msg=Job completed
0.4625,Event,ADDED,eval-conflicts-rho010-r5-073-ftx5v.18d466ea3064868e,reason=Scheduled count=None msg=Successfully assigned compute/eval-conflicts-rho010-r5-073-ftx5v to kind-worker3
0.4627,Event,ADDED,eval-conflicts-rho010-r5-073-ftx5v.18d466ea48e91157,"reason=Pulled count=1 msg=Container image ""busybox:musl"" already present on machine"
0.4629,Event,ADDED,eval-conflicts-rho010-r5-073-ftx5v.18d466ea49fd26a5,reason=Created count=1 msg=Created container: task
0.4632,Event,ADDED,eval-conflicts-rho010-r5-073-ftx5v.18d466ea4be86cb8,reason=Started count=1 msg=Started container task
0.4634,Event,ADDED,eval-conflicts-rho010-r5-073.18d466ea2fa1c61a,reason=SuccessfulCreate count=1 msg=Created pod: eval-conflicts-rho010-r5-073-ftx5v
0.4635,Event,ADDED,eval-conflicts-rho010-r5-073.18d466ed5778b108,reason=Completed count=1 msg=Job completed
0.4637,Event,ADDED,eval-conflicts-rho010-r5-074-w22h5.18d466ea6bd0664c,reason=Scheduled count=None msg=Successfully assigned compute/eval-conflicts-rho010-r5-074-w22h5 to kind-worker3
0.464,Event,ADDED,eval-conflicts-rho010-r5-074-w22h5.18d466ea85b45138,"reason=Pulled count=1 msg=Container image ""busybox:musl"" already present on machine"
0.4642,Event,ADDED,eval-conflicts-rho010-r5-074-w22h5.18d466ea86d30561,reason=Created count=1 msg=Created container: task
0.4644,Event,ADDED,eval-conflicts-rho010-r5-074-w22h5.18d466ea88c3d51e,reason=Started count=1 msg=Started container task
0.4646,Event,ADDED,eval-conflicts-rho010-r5-074.18d466ea6b32e59a,reason=SuccessfulCreate count=1 msg=Created pod: eval-conflicts-rho010-r5-074-w22h5
0.4648,Event,ADDED,eval-conflicts-rho010-r5-074.18d466ed9340849b,reason=Completed count=1 msg=Job completed
0.465,Event,ADDED,eval-conflicts-rho010-r5-075-c9q22.18d466eaa6a4511c,"reason=FailedScheduling count=None msg=0/6 nodes are available: 6 node(s) had untolerated taint(s). no new claims to deallocate, preemption: 0/6 nodes are available: 6 Preemption is not helpful for scheduling."
0.4651,Event,ADDED,eval-conflicts-rho010-r5-075-c9q22.18d466eac98762c3,reason=Scheduled count=None msg=Successfully assigned compute/eval-conflicts-rho010-r5-075-c9q22 to kind-worker2
0.4653,Event,ADDED,eval-conflicts-rho010-r5-075-c9q22.18d466eae262a57a,"reason=Pulled count=1 msg=Container image ""busybox:musl"" already present on machine"
0.4655,Event,ADDED,eval-conflicts-rho010-r5-075-c9q22.18d466eae3e5cb05,reason=Created count=1 msg=Created container: task
0.4657,Event,ADDED,eval-conflicts-rho010-r5-075-c9q22.18d466eae628987a,reason=Started count=1 msg=Started container task
0.4658,Event,ADDED,eval-conflicts-rho010-r5-075.18d466eaa69ad74b,reason=SuccessfulCreate count=1 msg=Created pod: eval-conflicts-rho010-r5-075-c9q22
0.466,Event,ADDED,eval-conflicts-rho010-r5-075.18d466ee2193fb6d,reason=Completed count=1 msg=Job completed
0.4662,Event,ADDED,eval-conflicts-rho010-r5-076-g456n.18d466eae369eb06,reason=Scheduled count=None msg=Successfully assigned compute/eval-conflicts-rho010-r5-076-g456n to kind-worker2
0.4663,Event,ADDED,eval-conflicts-rho010-r5-076-g456n.18d466eafb94652a,"reason=Pulled count=1 msg=Container image ""busybox:musl"" already present on machine"
0.4665,Event,ADDED,eval-conflicts-rho010-r5-076-g456n.18d466eafca1cbe4,reason=Created count=1 msg=Created container: task
0.4667,Event,ADDED,eval-conflicts-rho010-r5-076-g456n.18d466eb005c5fa1,reason=Started count=1 msg=Started container task
0.4668,Event,ADDED,eval-conflicts-rho010-r5-076.18d466eae2cc5b12,reason=SuccessfulCreate count=1 msg=Created pod: eval-conflicts-rho010-r5-076-g456n
0.467,Event,ADDED,eval-conflicts-rho010-r5-076.18d466ee216735de,reason=Completed count=1 msg=Job completed
0.4672,Event,ADDED,eval-conflicts-rho010-r5-077-knxkq.18d466eb1ec50858,reason=Scheduled count=None msg=Successfully assigned compute/eval-conflicts-rho010-r5-077-knxkq to kind-worker5
0.4673,Event,ADDED,eval-conflicts-rho010-r5-077-knxkq.18d466eb393e1a48,"reason=Pulled count=1 msg=Container image ""busybox:musl"" already present on machine"
0.4675,Event,ADDED,eval-conflicts-rho010-r5-077-knxkq.18d466eb3a59a1a2,reason=Created count=1 msg=Created container: task
0.4682,Event,ADDED,eval-conflicts-rho010-r5-077-knxkq.18d466eb3c6b4fb2,reason=Started count=1 msg=Started container task
0.4684,Event,ADDED,eval-conflicts-rho010-r5-077.18d466eb1e2cafa4,reason=SuccessfulCreate count=1 msg=Created pod: eval-conflicts-rho010-r5-077-knxkq
0.4686,Event,ADDED,eval-conflicts-rho010-r5-077.18d466ee235e2298,reason=Completed count=1 msg=Job completed
0.4687,Event,ADDED,eval-conflicts-rho010-r5-078-cc75b.18d466eb5b355f00,reason=Scheduled count=None msg=Successfully assigned compute/eval-conflicts-rho010-r5-078-cc75b to kind-worker5
0.469,Event,ADDED,eval-conflicts-rho010-r5-078-cc75b.18d466eb7526d2ba,"reason=Pulled count=1 msg=Container image ""busybox:musl"" already present on machine"
0.4691,Event,ADDED,eval-conflicts-rho010-r5-078-cc75b.18d466eb764f02f4,reason=Created count=1 msg=Created container: task
0.4693,Event,ADDED,eval-conflicts-rho010-r5-078-cc75b.18d466eb7a24315b,reason=Started count=1 msg=Started container task
0.4695,Event,ADDED,eval-conflicts-rho010-r5-078.18d466eb59ac7159,reason=SuccessfulCreate count=1 msg=Created pod: eval-conflicts-rho010-r5-078-cc75b
0.4698,Event,ADDED,eval-conflicts-rho010-r5-078.18d466ee5fd199cc,reason=Completed count=1 msg=Job completed
0.4699,Event,ADDED,eval-conflicts-rho010-r5-079-rfblz.18d466eb963f1da4,reason=Scheduled count=None msg=Successfully assigned compute/eval-conflicts-rho010-r5-079-rfblz to kind-worker5
0.4702,Event,ADDED,eval-conflicts-rho010-r5-079-rfblz.18d466ebaff9c353,"reason=Pulled count=1 msg=Container image ""busybox:musl"" already present on machine"
0.4704,Event,ADDED,eval-conflicts-rho010-r5-079-rfblz.18d466ebb1131128,reason=Created count=1 msg=Created container: task
0.4706,Event,ADDED,eval-conflicts-rho010-r5-079-rfblz.18d466ebb2fba56c,reason=Started count=1 msg=Started container task
0.4708,Event,ADDED,eval-conflicts-rho010-r5-079.18d466eb954bdeb5,reason=SuccessfulCreate count=1 msg=Created pod: eval-conflicts-rho010-r5-079-rfblz
0.4709,Event,ADDED,eval-conflicts-rho010-r5-079.18d466ee9b12ee54,reason=Completed count=1 msg=Job completed
0.4711,Event,ADDED,eval-conflicts-rho010-r5-080-dxm2g.18d466ebd12b7f29,"reason=FailedScheduling count=None msg=0/6 nodes are available: 2 c_wall violated: 1 conflicting context pair(s) with node memory, 4 node(s) had untolerated taint(s). no new claims to deallocate, preemption: 0/6 nodes are available: 2 No preemption victims found for incoming pod, 4 Preemption is not helpful for scheduling."
0.4713,Event,ADDED,eval-conflicts-rho010-r5-080-dxm2g.18d466ebd1f64d9f,"reason=FailedScheduling count=None msg=0/6 nodes are available: 2 c_wall violated: 1 conflicting context pair(s) with node memory, 4 node(s) had untolerated taint(s). no new claims to deallocate, preemption: 0/6 nodes are available: 2 No preemption victims found for incoming pod, 4 Preemption is not helpful for scheduling."
0.4714,Event,ADDED,eval-conflicts-rho010-r5-080-dxm2g.18d466ed0634b01b,reason=Scheduled count=None msg=Successfully assigned compute/eval-conflicts-rho010-r5-080-dxm2g to kind-worker4
0.4716,Event,ADDED,eval-conflicts-rho010-r5-080-dxm2g.18d466ed229ebd96,"reason=Pulled count=1 msg=Container image ""busybox:musl"" already present on machine"
0.4718,Event,ADDED,eval-conflicts-rho010-r5-080-dxm2g.18d466ed23de9dee,reason=Created count=1 msg=Created container: task
0.472,Event,ADDED,eval-conflicts-rho010-r5-080-dxm2g.18d466ed27e371fd,reason=Started count=1 msg=Started container task
0.4722,Event,ADDED,eval-conflicts-rho010-r5-080.18d466ebd0c6d951,reason=SuccessfulCreate count=1 msg=Created pod: eval-conflicts-rho010-r5-080-dxm2g
0.4725,Event,ADDED,eval-conflicts-rho010-r5-080.18d466f0439b6b7b,reason=Completed count=1 msg=Job completed
0.4727,Event,ADDED,eval-conflicts-rho010-r5-081-knr5j.18d466ec0cffc1dc,reason=Scheduled count=None msg=Successfully assigned compute/eval-conflicts-rho010-r5-081-knr5j to kind-worker5
0.4729,Event,ADDED,eval-conflicts-rho010-r5-081-knr5j.18d466ec26458c85,"reason=Pulled count=1 msg=Container image ""busybox:musl"" already present on machine"
0.4732,Event,ADDED,eval-conflicts-rho010-r5-081-knr5j.18d466ec2776ba23,reason=Created count=1 msg=Created container: task
0.4734,Event,ADDED,eval-conflicts-rho010-r5-081-knr5j.18d466ec299617d2,reason=Started count=1 msg=Started container task
0.4736,Event,ADDED,eval-conflicts-rho010-r5-081.18d466ec0c24bc8c,reason=SuccessfulCreate count=1 msg=Created pod: eval-conflicts-rho010-r5-081-knr5j
0.4737,Event,ADDED,eval-conflicts-rho010-r5-081.18d466ef1318dc4c,reason=Completed count=1 msg=Job completed
0.474,Event,ADDED,eval-conflicts-rho010-r5-082-4vdjl.18d466ec48540fd9,"reason=FailedScheduling count=None msg=0/6 nodes are available: 2 c_wall violated: 1 conflicting context pair(s) with node memory, 4 node(s) had untolerated taint(s). no new claims to deallocate, preemption: 0/6 nodes are available: 2 No preemption victims found for incoming pod, 4 Preemption is not helpful for scheduling."
0.4743,Event,ADDED,eval-conflicts-rho010-r5-082-4vdjl.18d466ec4904c5bc,"reason=FailedScheduling count=None msg=0/6 nodes are available: 2 c_wall violated: 1 conflicting context pair(s) with node memory, 4 node(s) had untolerated taint(s). no new claims to deallocate, preemption: 0/6 nodes are available: 2 No preemption victims found for incoming pod, 4 Preemption is not helpful for scheduling."
0.4745,Event,ADDED,eval-conflicts-rho010-r5-082-4vdjl.18d466ed0bfaaaa6,"reason=FailedScheduling count=None msg=0/6 nodes are available: 3 c_wall violated: 1 conflicting context pair(s) with node memory, 3 node(s) had untolerated taint(s). no new claims to deallocate, preemption: 0/6 nodes are available: 3 No preemption victims found for incoming pod, 3 Preemption is not helpful for scheduling."
0.4748,Event,ADDED,eval-conflicts-rho010-r5-082-4vdjl.18d466ed2373ef4c,"reason=FailedScheduling count=None msg=0/6 nodes are available: 2 c_wall violated: 1 conflicting context pair(s) with node memory, 4 node(s) had untolerated taint(s). no new claims to deallocate, preemption: 0/6 nodes are available: 2 No preemption victims found for incoming pod, 4 Preemption is not helpful for scheduling."
0.4751,Event,ADDED,eval-conflicts-rho010-r5-082-4vdjl.18d466ed6a939d48,"reason=FailedScheduling count=None msg=0/6 nodes are available: 1 c_wall violated: 1 conflicting context pair(s) with node memory, 5 node(s) had untolerated taint(s). no new claims to deallocate, preemption: 0/6 nodes are available: 1 No preemption victims found for incoming pod, 5 Preemption is not helpful for scheduling."
0.4752,Event,ADDED,eval-conflicts-rho010-r5-082-4vdjl.18d466ef0bd6efb8,reason=Scheduled count=None msg=Successfully assigned compute/eval-conflicts-rho010-r5-082-4vdjl to kind-worker
0.4755,Event,ADDED,eval-conflicts-rho010-r5-082-4vdjl.18d466ef248694c4,"reason=Pulled count=1 msg=Container image ""busybox:musl"" already present on machine"
0.4756,Event,ADDED,eval-conflicts-rho010-r5-082-4vdjl.18d466ef258daf08,reason=Created count=1 msg=Created container: task
0.4758,Event,ADDED,eval-conflicts-rho010-r5-082-4vdjl.18d466ef2763a49c,reason=Started count=1 msg=Started container task
0.476,Event,ADDED,eval-conflicts-rho010-r5-082.18d466ec47d9e331,reason=SuccessfulCreate count=1 msg=Created pod: eval-conflicts-rho010-r5-082-4vdjl
0.4762,Event,ADDED,eval-conflicts-rho010-r5-082.18d466f24ac3e7a0,reason=Completed count=1 msg=Job completed
0.4763,Event,ADDED,eval-conflicts-rho010-r5-083-bmsc8.18d466ec856c964b,reason=Scheduled count=None msg=Successfully assigned compute/eval-conflicts-rho010-r5-083-bmsc8 to kind-worker2
0.4765,Event,ADDED,eval-conflicts-rho010-r5-083-bmsc8.18d466ec9f3bb424,"reason=Pulled count=1 msg=Container image ""busybox:musl"" already present on machine"
0.4767,Event,ADDED,eval-conflicts-rho010-r5-083-bmsc8.18d466eca064fa0f,reason=Created count=1 msg=Created container: task
0.4768,Event,ADDED,eval-conflicts-rho010-r5-083-bmsc8.18d466eca528cba2,reason=Started count=1 msg=Started container task
0.477,Event,ADDED,eval-conflicts-rho010-r5-083.18d466ec8463f4f1,reason=SuccessfulCreate count=1 msg=Created pod: eval-conflicts-rho010-r5-083-bmsc8
0.4772,Event,ADDED,eval-conflicts-rho010-r5-083.18d466efc400cb82,reason=Completed count=1 msg=Job completed
0.4773,Event,ADDED,eval-conflicts-rho010-r5-084-ltswm.18d466ecc0007ba8,reason=Scheduled count=None msg=Successfully assigned compute/eval-conflicts-rho010-r5-084-ltswm to kind-worker5
0.4775,Event,ADDED,eval-conflicts-rho010-r5-084-ltswm.18d466ecd8afa371,"reason=Pulled count=1 msg=Container image ""busybox:musl"" already present on machine"
0.4777,Event,ADDED,eval-conflicts-rho010-r5-084-ltswm.18d466ecd9c5be28,reason=Created count=1 msg=Created container: task
0.4778,Event,ADDED,eval-conflicts-rho010-r5-084-ltswm.18d466ecdbd45955,reason=Started count=1 msg=Started container task
0.478,Event,ADDED,eval-conflicts-rho010-r5-084.18d466ecbf05db4e,reason=SuccessfulCreate count=1 msg=Created pod: eval-conflicts-rho010-r5-084-ltswm
0.4782,Event,ADDED,eval-conflicts-rho010-r5-084.18d466efc5f7d9fe,reason=Completed count=1 msg=Job completed
0.4783,Event,ADDED,eval-conflicts-rho010-r5-085-gc8vw.18d466ecfbb2d2ec,reason=Scheduled count=None msg=Successfully assigned compute/eval-conflicts-rho010-r5-085-gc8vw to kind-worker2
0.4785,Event,ADDED,eval-conflicts-rho010-r5-085-gc8vw.18d466ed15262147,"reason=Pulled count=1 msg=Container image ""busybox:musl"" already present on machine"
0.4787,Event,ADDED,eval-conflicts-rho010-r5-085-gc8vw.18d466ed16415f41,reason=Created count=1 msg=Created container: task
0.4788,Event,ADDED,eval-conflicts-rho010-r5-085-gc8vw.18d466ed184289af,reason=Started count=1 msg=Started container task
0.479,Event,ADDED,eval-conflicts-rho010-r5-085.18d466ecfb0bcb22,reason=SuccessfulCreate count=1 msg=Created pod: eval-conflicts-rho010-r5-085-gc8vw
0.4793,Event,ADDED,eval-conflicts-rho010-r5-085.18d466f03c0e9fb7,reason=Completed count=1 msg=Job completed
0.4794,Event,ADDED,eval-conflicts-rho010-r5-086-jtvws.18d466ed36e2a8e2,reason=Scheduled count=None msg=Successfully assigned compute/eval-conflicts-rho010-r5-086-jtvws to kind-worker4
0.4796,Event,ADDED,eval-conflicts-rho010-r5-086-jtvws.18d466ed4fd8babd,"reason=Pulled count=1 msg=Container image ""busybox:musl"" already present on machine"
0.4798,Event,ADDED,eval-conflicts-rho010-r5-086-jtvws.18d466ed50e2d30e,reason=Created count=1 msg=Created container: task
0.48,Event,ADDED,eval-conflicts-rho010-r5-086-jtvws.18d466ed5303ad4d,reason=Started count=1 msg=Started container task
0.4802,Event,ADDED,eval-conflicts-rho010-r5-086.18d466ed36285f3e,reason=SuccessfulCreate count=1 msg=Created pod: eval-conflicts-rho010-r5-086-jtvws
0.4804,Event,ADDED,eval-conflicts-rho010-r5-086.18d466f07f6a7f1f,reason=Completed count=1 msg=Job completed
0.4806,Event,ADDED,eval-conflicts-rho010-r5-087-r8l2v.18d466ed72bf5d15,reason=Scheduled count=None msg=Successfully assigned compute/eval-conflicts-rho010-r5-087-r8l2v to kind-worker4
0.4808,Event,ADDED,eval-conflicts-rho010-r5-087-r8l2v.18d466ed8b56743c,"reason=Pulled count=1 msg=Container image ""busybox:musl"" already present on machine"
0.4809,Event,ADDED,eval-conflicts-rho010-r5-087-r8l2v.18d466ed8c6f5e97,reason=Created count=1 msg=Created container: task
0.4811,Event,ADDED,eval-conflicts-rho010-r5-087-r8l2v.18d466ed8fa961b2,reason=Started count=1 msg=Started container task
0.4813,Event,ADDED,eval-conflicts-rho010-r5-087.18d466ed72316280,reason=SuccessfulCreate count=1 msg=Created pod: eval-conflicts-rho010-r5-087-r8l2v
0.4815,Event,ADDED,eval-conflicts-rho010-r5-087.18d466f0802d38a4,reason=Completed count=1 msg=Job completed
0.4816,Event,ADDED,eval-conflicts-rho010-r5-088-6mmmt.18d466edae1de065,reason=Scheduled count=None msg=Successfully assigned compute/eval-conflicts-rho010-r5-088-6mmmt to kind-worker4
0.4818,Event,ADDED,eval-conflicts-rho010-r5-088-6mmmt.18d466edc7bcc3b0,"reason=Pulled count=1 msg=Container image ""busybox:musl"" already present on machine"
0.4819,Event,ADDED,eval-conflicts-rho010-r5-088-6mmmt.18d466edc8eb7782,reason=Created count=1 msg=Created container: task
0.4821,Event,ADDED,eval-conflicts-rho010-r5-088-6mmmt.18d466edcb33b54e,reason=Started count=1 msg=Started container task
0.4823,Event,ADDED,eval-conflicts-rho010-r5-088.18d466edad78d274,reason=SuccessfulCreate count=1 msg=Created pod: eval-conflicts-rho010-r5-088-6mmmt
0.4824,Event,ADDED,eval-conflicts-rho010-r5-088.18d466f0f744ccae,reason=Completed count=1 msg=Job completed
0.4826,Event,ADDED,eval-conflicts-rho010-r5-089-gdw2g.18d466ede9402d3b,reason=Scheduled count=None msg=Successfully assigned compute/eval-conflicts-rho010-r5-089-gdw2g to kind-worker4
0.4828,Event,ADDED,eval-conflicts-rho010-r5-089-gdw2g.18d466ee031ce4de,"reason=Pulled count=1 msg=Container image ""busybox:musl"" already present on machine"
0.483,Event,ADDED,eval-conflicts-rho010-r5-089-gdw2g.18d466ee043108cc,reason=Created count=1 msg=Created container: task
0.4832,Event,ADDED,eval-conflicts-rho010-r5-089-gdw2g.18d466ee0644fcfd,reason=Started count=1 msg=Started container task
0.4833,Event,ADDED,eval-conflicts-rho010-r5-089.18d466ede8c17193,reason=SuccessfulCreate count=1 msg=Created pod: eval-conflicts-rho010-r5-089-gdw2g
0.4835,Event,ADDED,eval-conflicts-rho010-r5-089.18d466f13343a79e,reason=Completed count=1 msg=Job completed
0.4837,Event,ADDED,eval-conflicts-rho010-r5-090-dkx8s.18d466ee259fa65e,reason=Scheduled count=None msg=Successfully assigned compute/eval-conflicts-rho010-r5-090-dkx8s to kind-worker4
0.4838,Event,ADDED,eval-conflicts-rho010-r5-090-dkx8s.18d466ee4072e6d6,"reason=Pulled count=1 msg=Container image ""busybox:musl"" already present on machine"
0.484,Event,ADDED,eval-conflicts-rho010-r5-090-dkx8s.18d466ee41ba0892,reason=Created count=1 msg=Created container: task
0.4842,Event,ADDED,eval-conflicts-rho010-r5-090-dkx8s.18d466ee448dde32,reason=Started count=1 msg=Started container task
0.4843,Event,ADDED,eval-conflicts-rho010-r5-090.18d466ee2507f58a,reason=SuccessfulCreate count=1 msg=Created pod: eval-conflicts-rho010-r5-090-dkx8s
0.4845,Event,ADDED,eval-conflicts-rho010-r5-090.18d466f16f580149,reason=Completed count=1 msg=Job completed
0.4846,Event,ADDED,eval-conflicts-rho010-r5-091-vmf29.18d466ee6239e496,reason=Scheduled count=None msg=Successfully assigned compute/eval-conflicts-rho010-r5-091-vmf29 to kind-worker4
0.4848,Event,ADDED,eval-conflicts-rho010-r5-091-vmf29.18d466ee7b5d1835,"reason=Pulled count=1 msg=Container image ""busybox:musl"" already present on machine"
0.485,Event,ADDED,eval-conflicts-rho010-r5-091-vmf29.18d466ee7c6c1254,reason=Created count=1 msg=Created container: task
0.4851,Event,ADDED,eval-conflicts-rho010-r5-091-vmf29.18d466ee7ea333eb,reason=Started count=1 msg=Started container task
0.4853,Event,ADDED,eval-conflicts-rho010-r5-091.18d466ee61997c88,reason=SuccessfulCreate count=1 msg=Created pod: eval-conflicts-rho010-r5-091-vmf29
0.4854,Event,ADDED,eval-conflicts-rho010-r5-091.18d466f1ab206a72,reason=Completed count=1 msg=Job completed
0.4856,Event,ADDED,eval-conflicts-rho010-r5-092-886pk.18d466ee9c545bf1,reason=Scheduled count=None msg=Successfully assigned compute/eval-conflicts-rho010-r5-092-886pk to kind-worker4
0.4858,Event,ADDED,eval-conflicts-rho010-r5-092-886pk.18d466eeb560c213,"reason=Pulled count=1 msg=Container image ""busybox:musl"" already present on machine"
0.4859,Event,ADDED,eval-conflicts-rho010-r5-092-886pk.18d466eeb65e8e9a,reason=Created count=1 msg=Created container: task
0.4861,Event,ADDED,eval-conflicts-rho010-r5-092-886pk.18d466eeb847902b,reason=Started count=1 msg=Started container task
0.4862,Event,ADDED,eval-conflicts-rho010-r5-092.18d466ee9bcd9703,reason=SuccessfulCreate count=1 msg=Created pod: eval-conflicts-rho010-r5-092-886pk
0.4864,Event,ADDED,eval-conflicts-rho010-r5-092.18d466f1e6f5499c,reason=Completed count=1 msg=Job completed
0.4866,Event,ADDED,eval-conflicts-rho010-r5-093-grh8w.18d466eed835178e,"reason=FailedScheduling count=None msg=0/6 nodes are available: 1 c_wall violated: 1 conflicting context pair(s) with node memory, 5 node(s) had untolerated taint(s). no new claims to deallocate, preemption: 0/6 nodes are available: 1 No preemption victims found for incoming pod, 5 Preemption is not helpful for scheduling."
0.4867,Event,ADDED,eval-conflicts-rho010-r5-093-grh8w.18d466eed8c1e891,"reason=FailedScheduling count=None msg=0/6 nodes are available: 1 c_wall violated: 1 conflicting context pair(s) with node memory, 5 node(s) had untolerated taint(s). no new claims to deallocate, preemption: 0/6 nodes are available: 1 No preemption victims found for incoming pod, 5 Preemption is not helpful for scheduling."
0.4869,Event,ADDED,eval-conflicts-rho010-r5-093-grh8w.18d466ef0d33257d,"reason=FailedScheduling count=None msg=0/6 nodes are available: 2 c_wall violated: 1 conflicting context pair(s) with node memory, 4 node(s) had untolerated taint(s). no new claims to deallocate, preemption: 0/6 nodes are available: 2 No preemption victims found for incoming pod, 4 Preemption is not helpful for scheduling."
0.4871,Event,ADDED,eval-conflicts-rho010-r5-093-grh8w.18d466ef53e4b2e8,reason=Scheduled count=None msg=Successfully assigned compute/eval-conflicts-rho010-r5-093-grh8w to kind-worker3
0.4872,Event,ADDED,eval-conflicts-rho010-r5-093-grh8w.18d466ef6e92c463,"reason=Pulled count=1 msg=Container image ""busybox:musl"" already present on machine"
0.4874,Event,ADDED,eval-conflicts-rho010-r5-093-grh8w.18d466ef6fff92b3,reason=Created count=1 msg=Created container: task
0.4876,Event,ADDED,eval-conflicts-rho010-r5-093-grh8w.18d466ef79756d7e,reason=Started count=1 msg=Started container task
0.4878,Event,ADDED,eval-conflicts-rho010-r5-093.18d466eed7f5e94b,reason=SuccessfulCreate count=1 msg=Created pod: eval-conflicts-rho010-r5-093-grh8w
0.4879,Event,ADDED,eval-conflicts-rho010-r5-093.18d466f2b55642f2,reason=Completed count=1 msg=Job completed
0.4881,Event,ADDED,eval-conflicts-rho010-r5-094-gxl8t.18d466ef141c0ea1,reason=Scheduled count=None msg=Successfully assigned compute/eval-conflicts-rho010-r5-094-gxl8t to kind-worker
0.4883,Event,ADDED,eval-conflicts-rho010-r5-094-gxl8t.18d466ef2d5a14b3,"reason=Pulled count=1 msg=Container image ""busybox:musl"" already present on machine"
0.4884,Event,ADDED,eval-conflicts-rho010-r5-094-gxl8t.18d466ef2e63ebe0,reason=Created count=1 msg=Created container: task
0.4886,Event,ADDED,eval-conflicts-rho010-r5-094-gxl8t.18d466ef303fffd1,reason=Started count=1 msg=Started container task
0.4887,Event,ADDED,eval-conflicts-rho010-r5-094.18d466ef12e7e47c,reason=SuccessfulCreate count=1 msg=Created pod: eval-conflicts-rho010-r5-094-gxl8t
0.4894,Event,ADDED,eval-conflicts-rho010-r5-094.18d466f24a77e828,reason=Completed count=1 msg=Job completed
0.4896,Event,ADDED,eval-conflicts-rho010-r5-095-9fc64.18d466ef53a9cec6,reason=Scheduled count=None msg=Successfully assigned compute/eval-conflicts-rho010-r5-095-9fc64 to kind-worker4
0.4898,Event,ADDED,eval-conflicts-rho010-r5-095-9fc64.18d466ef6e8dc114,"reason=Pulled count=1 msg=Container image ""busybox:musl"" already present on machine"
0.4901,Event,ADDED,eval-conflicts-rho010-r5-095-9fc64.18d466ef6fd54f21,reason=Created count=1 msg=Created container: task
0.4903,Event,ADDED,eval-conflicts-rho010-r5-095-9fc64.18d466ef759cc200,reason=Started count=1 msg=Started container task
0.4905,Event,ADDED,eval-conflicts-rho010-r5-095.18d466ef4fc6515b,reason=SuccessfulCreate count=1 msg=Created pod: eval-conflicts-rho010-r5-095-9fc64
0.4907,Event,ADDED,eval-conflicts-rho010-r5-095.18d466f299c70c33,reason=Completed count=1 msg=Job completed
0.4911,Event,ADDED,eval-conflicts-rho010-r5-096-ttl59.18d466ef8b4ce8ce,reason=Scheduled count=None msg=Successfully assigned compute/eval-conflicts-rho010-r5-096-ttl59 to kind-worker
0.4913,Event,ADDED,eval-conflicts-rho010-r5-096-ttl59.18d466efa5c6366a,"reason=Pulled count=1 msg=Container image ""busybox:musl"" already present on machine"
0.4915,Event,ADDED,eval-conflicts-rho010-r5-096-ttl59.18d466efa6c75904,reason=Created count=1 msg=Created container: task
0.4916,Event,ADDED,eval-conflicts-rho010-r5-096-ttl59.18d466efa8a5ebe8,reason=Started count=1 msg=Started container task
0.4918,Event,ADDED,eval-conflicts-rho010-r5-096.18d466ef8aa1a60e,reason=SuccessfulCreate count=1 msg=Created pod: eval-conflicts-rho010-r5-096-ttl59
0.492,Event,ADDED,eval-conflicts-rho010-r5-096.18d466f2c2a258a0,reason=Completed count=1 msg=Job completed
0.4921,Event,ADDED,eval-conflicts-rho010-r5-097-ts9km.18d466efc707fede,reason=Scheduled count=None msg=Successfully assigned compute/eval-conflicts-rho010-r5-097-ts9km to kind-worker3
0.4923,Event,ADDED,eval-conflicts-rho010-r5-097-ts9km.18d466efdff63dab,"reason=Pulled count=1 msg=Container image ""busybox:musl"" already present on machine"
0.4926,Event,ADDED,eval-conflicts-rho010-r5-097-ts9km.18d466efe0f5fc2c,reason=Created count=1 msg=Created container: task
0.4928,Event,ADDED,eval-conflicts-rho010-r5-097-ts9km.18d466efe2cc9dae,reason=Started count=1 msg=Started container task
0.4929,Event,ADDED,eval-conflicts-rho010-r5-097.18d466efc656c4b0,reason=SuccessfulCreate count=1 msg=Created pod: eval-conflicts-rho010-r5-097-ts9km
0.4931,Event,ADDED,eval-conflicts-rho010-r5-097.18d466f32d37b49b,reason=Completed count=1 msg=Job completed
0.4933,Event,ADDED,eval-conflicts-rho010-r5-098-h6z6j.18d466f0021018d0,reason=Scheduled count=None msg=Successfully assigned compute/eval-conflicts-rho010-r5-098-h6z6j to kind-worker5
0.4934,Event,ADDED,eval-conflicts-rho010-r5-098-h6z6j.18d466f01b60a6dd,"reason=Pulled count=1 msg=Container image ""busybox:musl"" already present on machine"
0.4936,Event,ADDED,eval-conflicts-rho010-r5-098-h6z6j.18d466f01c6b42a8,reason=Created count=1 msg=Created container: task
0.4938,Event,ADDED,eval-conflicts-rho010-r5-098-h6z6j.18d466f01e4dd07b,reason=Started count=1 msg=Started container task
0.4939,Event,ADDED,eval-conflicts-rho010-r5-098.18d466f001443c4c,reason=SuccessfulCreate count=1 msg=Created pod: eval-conflicts-rho010-r5-098-h6z6j
0.4941,Event,ADDED,eval-conflicts-rho010-r5-098.18d466f3478316f9,reason=Completed count=1 msg=Job completed
0.4942,Event,ADDED,eval-conflicts-rho010-r5-099-sbrcf.18d466f03e65d4f0,reason=Scheduled count=None msg=Successfully assigned compute/eval-conflicts-rho010-r5-099-sbrcf to kind-worker5
0.4944,Event,ADDED,eval-conflicts-rho010-r5-099-sbrcf.18d466f05643b770,"reason=Pulled count=1 msg=Container image ""busybox:musl"" already present on machine"
0.4946,Event,ADDED,eval-conflicts-rho010-r5-099-sbrcf.18d466f0574d7056,reason=Created count=1 msg=Created container: task
0.4948,Event,ADDED,eval-conflicts-rho010-r5-099-sbrcf.18d466f05926d745,reason=Started count=1 msg=Started container task
0.4949,Event,ADDED,eval-conflicts-rho010-r5-099.18d466f03d4f56e2,reason=SuccessfulCreate count=1 msg=Created pod: eval-conflicts-rho010-r5-099-sbrcf
0.4951,Event,ADDED,eval-conflicts-rho010-r5-099.18d466f383f4e8c7,reason=Completed count=1 msg=Job completed
0.4952,Event,ADDED,eval-conflicts-rho010-r6-000-8xxh7.18d466f8d094f0bc,reason=Scheduled count=None msg=Successfully assigned compute/eval-conflicts-rho010-r6-000-8xxh7 to kind-worker2
0.4954,Event,ADDED,eval-conflicts-rho010-r6-000-8xxh7.18d466f8eb8aad7b,"reason=Pulled count=1 msg=Container image ""busybox:musl"" already present on machine"
0.4956,Event,ADDED,eval-conflicts-rho010-r6-000-8xxh7.18d466f8ecbac792,reason=Created count=1 msg=Created container: task
0.4958,Event,ADDED,eval-conflicts-rho010-r6-000-8xxh7.18d466f8eec5e46d,reason=Started count=1 msg=Started container task
0.4959,Event,ADDED,eval-conflicts-rho010-r6-000.18d466f8cf5bdd5b,reason=SuccessfulCreate count=1 msg=Created pod: eval-conflicts-rho010-r6-000-8xxh7
0.4961,Event,ADDED,eval-conflicts-rho010-r6-000.18d466fc20903efa,reason=Completed count=1 msg=Job completed
0.4962,Event,ADDED,eval-conflicts-rho010-r6-001-bqjhx.18d466f9095bd9a4,reason=Scheduled count=None msg=Successfully assigned compute/eval-conflicts-rho010-r6-001-bqjhx to kind-worker5
0.4964,Event,ADDED,eval-conflicts-rho010-r6-001-bqjhx.18d466f921900afa,"reason=Pulled count=1 msg=Container image ""busybox:musl"" already present on machine"
0.4966,Event,ADDED,eval-conflicts-rho010-r6-001-bqjhx.18d466f922a8eb12,reason=Created count=1 msg=Created container: task
0.4968,Event,ADDED,eval-conflicts-rho010-r6-001-bqjhx.18d466f924a0f932,reason=Started count=1 msg=Started container task
0.4969,Event,ADDED,eval-conflicts-rho010-r6-001.18d466f908e4b53a,reason=SuccessfulCreate count=1 msg=Created pod: eval-conflicts-rho010-r6-001-bqjhx
0.4971,Event,ADDED,eval-conflicts-rho010-r6-001.18d466fc608d0a4f,reason=Completed count=1 msg=Job completed
0.4972,Event,ADDED,eval-conflicts-rho010-r6-002-8bz8s.18d466f9456bb69e,reason=Scheduled count=None msg=Successfully assigned compute/eval-conflicts-rho010-r6-002-8bz8s to kind-worker
0.4974,Event,ADDED,eval-conflicts-rho010-r6-002-8bz8s.18d466f95e8c6584,"reason=Pulled count=1 msg=Container image ""busybox:musl"" already present on machine"
0.4976,Event,ADDED,eval-conflicts-rho010-r6-002-8bz8s.18d466f95fa00327,reason=Created count=1 msg=Created container: task
0.4978,Event,ADDED,eval-conflicts-rho010-r6-002-8bz8s.18d466f961ac753b,reason=Started count=1 msg=Started container task
0.4979,Event,ADDED,eval-conflicts-rho010-r6-002.18d466f9443f447a,reason=SuccessfulCreate count=1 msg=Created pod: eval-conflicts-rho010-r6-002-8bz8s
0.4981,Event,ADDED,eval-conflicts-rho010-r6-002.18d466fc90fa3127,reason=Completed count=1 msg=Job completed
0.4983,Event,ADDED,eval-conflicts-rho010-r6-003-b2n7v.18d466f98090bed0,reason=Scheduled count=None msg=Successfully assigned compute/eval-conflicts-rho010-r6-003-b2n7v to kind-worker4
0.4984,Event,ADDED,eval-conflicts-rho010-r6-003-b2n7v.18d466f999e2f747,"reason=Pulled count=1 msg=Container image ""busybox:musl"" already present on machine"
0.4986,Event,ADDED,eval-conflicts-rho010-r6-003-b2n7v.18d466f99b01c8f4,reason=Created count=1 msg=Created container: task
0.4988,Event,ADDED,eval-conflicts-rho010-r6-003-b2n7v.18d466f99d2de9c0,reason=Started count=1 msg=Started container task
0.4989,Event,ADDED,eval-conflicts-rho010-r6-003.18d466f97fd589f2,reason=SuccessfulCreate count=1 msg=Created pod: eval-conflicts-rho010-r6-003-b2n7v
0.4991,Event,ADDED,eval-conflicts-rho010-r6-003.18d466fcdee3e55f,reason=Completed count=1 msg=Job completed
0.4993,Event,ADDED,eval-conflicts-rho010-r6-004-zchk5.18d466f9bbfdb584,reason=Scheduled count=None msg=Successfully assigned compute/eval-conflicts-rho010-r6-004-zchk5 to kind-worker
0.4995,Event,ADDED,eval-conflicts-rho010-r6-004-zchk5.18d466f9d4933b2b,"reason=Pulled count=1 msg=Container image ""busybox:musl"" already present on machine"
0.4996,Event,ADDED,eval-conflicts-rho010-r6-004-zchk5.18d466f9d5c8ab6d,reason=Created count=1 msg=Created container: task
0.5,Event,ADDED,eval-conflicts-rho010-r6-004-zchk5.18d466f9d7dbb485,reason=Started count=1 msg=Started container task
0.5002,Event,ADDED,eval-conflicts-rho010-r6-004.18d466f9bb0d2d7e,reason=SuccessfulCreate count=1 msg=Created pod: eval-conflicts-rho010-r6-004-zchk5
0.5004,Event,ADDED,eval-conflicts-rho010-r6-004.18d466fd0d08e9ff,reason=Completed count=1 msg=Job completed
0.5005,Event,ADDED,eval-conflicts-rho010-r6-005-6dxtg.18d466f9f802236c,reason=Scheduled count=None msg=Successfully assigned compute/eval-conflicts-rho010-r6-005-6dxtg to kind-worker4
0.5008,Event,ADDED,eval-conflicts-rho010-r6-005-6dxtg.18d466fa10c05048,"reason=Pulled count=1 msg=Container image ""busybox:musl"" already present on machine"
0.5009,Event,ADDED,eval-conflicts-rho010-r6-005-6dxtg.18d466fa11c4d7f0,reason=Created count=1 msg=Created container: task
0.5011,Event,ADDED,eval-conflicts-rho010-r6-005-6dxtg.18d466fa15d6b485,reason=Started count=1 msg=Started container task
0.5013,Event,ADDED,eval-conflicts-rho010-r6-005.18d466f9f71d3185,reason=SuccessfulCreate count=1 msg=Created pod: eval-conflicts-rho010-r6-005-6dxtg
0.5014,Event,ADDED,eval-conflicts-rho010-r6-005.18d466fd56631947,reason=Completed count=1 msg=Job completed
0.5016,Event,ADDED,eval-conflicts-rho010-r6-006-xf7jw.18d466fa33983510,reason=Scheduled count=None msg=Successfully assigned compute/eval-conflicts-rho010-r6-006-xf7jw to kind-worker
0.5018,Event,ADDED,eval-conflicts-rho010-r6-006-xf7jw.18d466fa4cf49286,"reason=Pulled count=1 msg=Container image ""busybox:musl"" already present on machine"
0.5019,Event,ADDED,eval-conflicts-rho010-r6-006-xf7jw.18d466fa4dffaf82,reason=Created count=1 msg=Created container: task
0.5021,Event,ADDED,eval-conflicts-rho010-r6-006-xf7jw.18d466fa4fdaf7f5,reason=Started count=1 msg=Started container task
0.5023,Event,ADDED,eval-conflicts-rho010-r6-006.18d466fa32ad291b,reason=SuccessfulCreate count=1 msg=Created pod: eval-conflicts-rho010-r6-006-xf7jw
0.5025,Event,ADDED,eval-conflicts-rho010-r6-006.18d466fd814bb8dc,reason=Completed count=1 msg=Job completed
0.5026,Event,ADDED,eval-conflicts-rho010-r6-007-877pn.18d466fa6fab5ec9,reason=Scheduled count=None msg=Successfully assigned compute/eval-conflicts-rho010-r6-007-877pn to kind-worker
0.5028,Event,ADDED,eval-conflicts-rho010-r6-007-877pn.18d466fa896cc9ae,"reason=Pulled count=1 msg=Container image ""busybox:musl"" already present on machine"
0.5029,Event,ADDED,eval-conflicts-rho010-r6-007-877pn.18d466fa8a9092d0,reason=Created count=1 msg=Created container: task
0.5031,Event,ADDED,eval-conflicts-rho010-r6-007-877pn.18d466fa8c721989,reason=Started count=1 msg=Started container task
0.5033,Event,ADDED,eval-conflicts-rho010-r6-007.18d466fa6eaeb019,reason=SuccessfulCreate count=1 msg=Created pod: eval-conflicts-rho010-r6-007-877pn
0.5034,Event,ADDED,eval-conflicts-rho010-r6-007.18d466fdbf95fb6e,reason=Completed count=1 msg=Job completed
0.5036,Event,ADDED,eval-conflicts-rho010-r6-008-7wc6b.18d466faaadbd6ff,reason=Scheduled count=None msg=Successfully assigned compute/eval-conflicts-rho010-r6-008-7wc6b to kind-worker
0.5038,Event,ADDED,eval-conflicts-rho010-r6-008-7wc6b.18d466fac391dbe9,"reason=Pulled count=1 msg=Container image ""busybox:musl"" already present on machine"
0.5039,Event,ADDED,eval-conflicts-rho010-r6-008-7wc6b.18d466fac4ae83c1,reason=Created count=1 msg=Created container: task
0.5041,Event,ADDED,eval-conflicts-rho010-r6-008-7wc6b.18d466fac6a02820,reason=Started count=1 msg=Started container task
0.5043,Event,ADDED,eval-conflicts-rho010-r6-008.18d466faa9fd3153,reason=SuccessfulCreate count=1 msg=Created pod: eval-conflicts-rho010-r6-008-7wc6b
0.5044,Event,ADDED,eval-conflicts-rho010-r6-008.18d466fdfc2c9845,reason=Completed count=1 msg=Job completed
0.5046,Event,ADDED,eval-conflicts-rho010-r6-009-t2l2l.18d466fae62348a5,reason=Scheduled count=None msg=Successfully assigned compute/eval-conflicts-rho010-r6-009-t2l2l to kind-worker4
0.5047,Event,ADDED,eval-conflicts-rho010-r6-009-t2l2l.18d466faff26e5fe,"reason=Pulled count=1 msg=Container image ""busybox:musl"" already present on machine"
0.5049,Event,ADDED,eval-conflicts-rho010-r6-009-t2l2l.18d466fb004406dc,reason=Created count=1 msg=Created container: task
0.5051,Event,ADDED,eval-conflicts-rho010-r6-009-t2l2l.18d466fb0238bac9,reason=Started count=1 msg=Started container task
0.5052,Event,ADDED,eval-conflicts-rho010-r6-009.18d466fae55f599b,reason=SuccessfulCreate count=1 msg=Created pod: eval-conflicts-rho010-r6-009-t2l2l
0.5054,Event,ADDED,eval-conflicts-rho010-r6-009.18d466fe486ac740,reason=Completed count=1 msg=Job completed
0.5056,Event,ADDED,eval-conflicts-rho010-r6-010-p644f.18d466fb22199d16,reason=Scheduled count=None msg=Successfully assigned compute/eval-conflicts-rho010-r6-010-p644f to kind-worker4
0.5057,Event,ADDED,eval-conflicts-rho010-r6-010-p644f.18d466fb3b18f566,"reason=Pulled count=1 msg=Container image ""busybox:musl"" already present on machine"
0.5059,Event,ADDED,eval-conflicts-rho010-r6-010-p644f.18d466fb3c3d678e,reason=Created count=1 msg=Created container: task
0.5061,Event,ADDED,eval-conflicts-rho010-r6-010-p644f.18d466fb4134774a,reason=Started count=1 msg=Started container task
0.5062,Event,ADDED,eval-conflicts-rho010-r6-010.18d466fb2110ed69,reason=SuccessfulCreate count=1 msg=Created pod: eval-conflicts-rho010-r6-010-p644f
0.5064,Event,ADDED,eval-conflicts-rho010-r6-010.18d466fe82df14ef,reason=Completed count=1 msg=Job completed
0.5065,Event,ADDED,eval-conflicts-rho010-r6-011-9d6xb.18d466fb5cfc27f4,reason=Scheduled count=None msg=Successfully assigned compute/eval-conflicts-rho010-r6-011-9d6xb to kind-worker3
0.5067,Event,ADDED,eval-conflicts-rho010-r6-011-9d6xb.18d466fb75bf698a,"reason=Pulled count=1 msg=Container image ""busybox:musl"" already present on machine"
0.5069,Event,ADDED,eval-conflicts-rho010-r6-011-9d6xb.18d466fb76d1b311,reason=Created count=1 msg=Created container: task
0.5104,Event,ADDED,eval-conflicts-rho010-r6-011-9d6xb.18d466fb78f8a6f9,reason=Started count=1 msg=Started container task
0.5107,Event,ADDED,eval-conflicts-rho010-r6-011.18d466fb5c995488,reason=SuccessfulCreate count=1 msg=Created pod: eval-conflicts-rho010-r6-011-9d6xb
0.5108,Event,ADDED,eval-conflicts-rho010-r6-011.18d466fe9c36f196,reason=Completed count=1 msg=Job completed
0.511,Event,ADDED,eval-conflicts-rho010-r6-012-7glsc.18d466fb98bba4aa,reason=Scheduled count=None msg=Successfully assigned compute/eval-conflicts-rho010-r6-012-7glsc to kind-worker3
0.5112,Event,ADDED,eval-conflicts-rho010-r6-012-7glsc.18d466fbb31b5556,"reason=Pulled count=1 msg=Container image ""busybox:musl"" already present on machine"
0.5114,Event,ADDED,eval-conflicts-rho010-r6-012-7glsc.18d466fbb4270e75,reason=Created count=1 msg=Created container: task
0.5115,Event,ADDED,eval-conflicts-rho010-r6-012-7glsc.18d466fbb8844cee,reason=Started count=1 msg=Started container task
0.5117,Event,ADDED,eval-conflicts-rho010-r6-012.18d466fb9831a59f,reason=SuccessfulCreate count=1 msg=Created pod: eval-conflicts-rho010-r6-012-7glsc
0.5119,Event,ADDED,eval-conflicts-rho010-r6-012.18d466fed8132040,reason=Completed count=1 msg=Job completed
0.5121,Event,ADDED,eval-conflicts-rho010-r6-013-tltsh.18d466fbd48c67c8,reason=Scheduled count=None msg=Successfully assigned compute/eval-conflicts-rho010-r6-013-tltsh to kind-worker3
0.5122,Event,ADDED,eval-conflicts-rho010-r6-013-tltsh.18d466fbf25d12ab,"reason=Pulled count=1 msg=Container image ""busybox:musl"" already present on machine"
0.5124,Event,ADDED,eval-conflicts-rho010-r6-013-tltsh.18d466fbf3be6367,reason=Created count=1 msg=Created container: task
0.5126,Event,ADDED,eval-conflicts-rho010-r6-013-tltsh.18d466fbf7422cbc,reason=Started count=1 msg=Started container task
0.5128,Event,ADDED,eval-conflicts-rho010-r6-013.18d466fbd4058f8f,reason=SuccessfulCreate count=1 msg=Created pod: eval-conflicts-rho010-r6-013-tltsh
0.5129,Event,ADDED,eval-conflicts-rho010-r6-013.18d466ff1478e8a1,reason=Completed count=1 msg=Job completed
0.5131,Event,ADDED,eval-conflicts-rho010-r6-014-8wfvc.18d466fc1002726c,reason=Scheduled count=None msg=Successfully assigned compute/eval-conflicts-rho010-r6-014-8wfvc to kind-worker3
0.5133,Event,ADDED,eval-conflicts-rho010-r6-014-8wfvc.18d466fc29960ae5,"reason=Pulled count=1 msg=Container image ""busybox:musl"" already present on machine"
0.5135,Event,ADDED,eval-conflicts-rho010-r6-014-8wfvc.18d466fc2abb99c9,reason=Created count=1 msg=Created container: task
0.5137,Event,ADDED,eval-conflicts-rho010-r6-014-8wfvc.18d466fc31a48f3f,reason=Started count=1 msg=Started container task
0.5138,Event,ADDED,eval-conflicts-rho010-r6-014.18d466fc0f704b3a,reason=SuccessfulCreate count=1 msg=Created pod: eval-conflicts-rho010-r6-014-8wfvc
0.514,Event,ADDED,eval-conflicts-rho010-r6-014.18d466ff5088f7f4,reason=Completed count=1 msg=Job completed
0.5142,Event,ADDED,eval-conflicts-rho010-r6-015-2qps6.18d466fc4ba0bd96,reason=Scheduled count=None msg=Successfully assigned compute/eval-conflicts-rho010-r6-015-2qps6 to kind-worker3
0.5143,Event,ADDED,eval-conflicts-rho010-r6-015-2qps6.18d466fc64720f97,"reason=Pulled count=1 msg=Container image ""busybox:musl"" already present on machine"
0.5145,Event,ADDED,eval-conflicts-rho010-r6-015-2qps6.18d466fc658e328d,reason=Created count=1 msg=Created container: task
0.5147,Event,ADDED,eval-conflicts-rho010-r6-015-2qps6.18d466fc67a1dcd4,reason=Started count=1 msg=Started container task
0.5148,Event,ADDED,eval-conflicts-rho010-r6-015.18d466fc4b10258f,reason=SuccessfulCreate count=1 msg=Created pod: eval-conflicts-rho010-r6-015-2qps6
0.515,Event,ADDED,eval-conflicts-rho010-r6-015.18d466ff8ef55365,reason=Completed count=1 msg=Job completed
0.5151,Event,ADDED,eval-conflicts-rho010-r6-016-bktsp.18d466fc87d0e6a8,"reason=FailedScheduling count=None msg=0/6 nodes are available: 1 c_wall violated: 1 conflicting context pair(s) with node memory, 5 node(s) had untolerated taint(s). no new claims to deallocate, preemption: 0/6 nodes are available: 1 No preemption victims found for incoming pod, 5 Preemption is not helpful for scheduling."
0.5153,Event,ADDED,eval-conflicts-rho010-r6-016-bktsp.18d466fc884dce97,"reason=FailedScheduling count=None msg=0/6 nodes are available: 1 c_wall violated: 1 conflicting context pair(s) with node memory, 5 node(s) had untolerated taint(s). no new claims to deallocate, preemption: 0/6 nodes are available: 1 No preemption victims found for incoming pod, 5 Preemption is not helpful for scheduling."
0.5155,Event,ADDED,eval-conflicts-rho010-r6-016-bktsp.18d466fd97ee8a5e,reason=Scheduled count=None msg=Successfully assigned compute/eval-conflicts-rho010-r6-016-bktsp to kind-worker2
0.5156,Event,ADDED,eval-conflicts-rho010-r6-016-bktsp.18d466fdb57b69fb,"reason=Pulled count=1 msg=Container image ""busybox:musl"" already present on machine"
0.5158,Event,ADDED,eval-conflicts-rho010-r6-016-bktsp.18d466fdb6fca591,reason=Created count=1 msg=Created container: task
0.516,Event,ADDED,eval-conflicts-rho010-r6-016-bktsp.18d466fdbf30219c,reason=Started count=1 msg=Started container task
0.5161,Event,ADDED,eval-conflicts-rho010-r6-016.18d466fc87885582,reason=SuccessfulCreate count=1 msg=Created pod: eval-conflicts-rho010-r6-016-bktsp
0.5163,Event,ADDED,eval-conflicts-rho010-r6-016.18d46700cd233001,reason=Completed count=1 msg=Job completed
0.5164,Event,ADDED,eval-conflicts-rho010-r6-017-ncgg9.18d466fcc795224f,reason=Scheduled count=None msg=Successfully assigned compute/eval-conflicts-rho010-r6-017-ncgg9 to kind-worker3
0.5166,Event,ADDED,eval-conflicts-rho010-r6-017-ncgg9.18d466fce31e08b8,"reason=Pulled count=1 msg=Container image ""busybox:musl"" already present on machine"
0.5168,Event,ADDED,eval-conflicts-rho010-r6-017-ncgg9.18d466fce444f580,reason=Created count=1 msg=Created container: task
0.5169,Event,ADDED,eval-conflicts-rho010-r6-017-ncgg9.18d466fceaee2d41,reason=Started count=1 msg=Started container task
0.5171,Event,ADDED,eval-conflicts-rho010-r6-017.18d466fcc709f5a6,reason=SuccessfulCreate count=1 msg=Created pod: eval-conflicts-rho010-r6-017-ncgg9
0.5173,Event,ADDED,eval-conflicts-rho010-r6-017.18d46700071e8959,reason=Completed count=1 msg=Job completed
0.5174,Event,ADDED,eval-conflicts-rho010-r6-018-b46nt.18d466fd0003bf06,reason=Scheduled count=None msg=Successfully assigned compute/eval-conflicts-rho010-r6-018-b46nt to kind-worker3
0.5176,Event,ADDED,eval-conflicts-rho010-r6-018-b46nt.18d466fd1a35257f,"reason=Pulled count=1 msg=Container image ""busybox:musl"" already present on machine"
0.5178,Event,ADDED,eval-conflicts-rho010-r6-018-b46nt.18d466fd1b759819,reason=Created count=1 msg=Created container: task
0.5179,Event,ADDED,eval-conflicts-rho010-r6-018-b46nt.18d466fd2196c26f,reason=Started count=1 msg=Started container task
0.5181,Event,ADDED,eval-conflicts-rho010-r6-018.18d466fcff76d691,reason=SuccessfulCreate count=1 msg=Created pod: eval-conflicts-rho010-r6-018-b46nt
0.5183,Event,ADDED,eval-conflicts-rho010-r6-018.18d4670042dbbe20,reason=Completed count=1 msg=Job completed
0.5185,Event,ADDED,eval-conflicts-rho010-r6-019-r5zfj.18d466fd3a68c03a,reason=Scheduled count=None msg=Successfully assigned compute/eval-conflicts-rho010-r6-019-r5zfj to kind-worker3
0.5186,Event,ADDED,eval-conflicts-rho010-r6-019-r5zfj.18d466fd56d47fc4,"reason=Pulled count=1 msg=Container image ""busybox:musl"" already present on machine"
0.5188,Event,ADDED,eval-conflicts-rho010-r6-019-r5zfj.18d466fd5839f150,reason=Created count=1 msg=Created container: task
0.519,Event,ADDED,eval-conflicts-rho010-r6-019-r5zfj.18d466fd5e542977,reason=Started count=1 msg=Started container task
0.5191,Event,ADDED,eval-conflicts-rho010-r6-019.18d466fd39e4795f,reason=SuccessfulCreate count=1 msg=Created pod: eval-conflicts-rho010-r6-019-r5zfj
0.5193,Event,ADDED,eval-conflicts-rho010-r6-019.18d46700405a90f6,reason=Completed count=1 msg=Job completed
0.5195,Event,ADDED,eval-conflicts-rho010-r6-020-tvclm.18d466fd74f5b4ba,"reason=FailedScheduling count=None msg=0/6 nodes are available: 6 node(s) had untolerated taint(s). no new claims to deallocate, preemption: 0/6 nodes are available: 6 Preemption is not helpful for scheduling."
0.5196,Event,ADDED,eval-conflicts-rho010-r6-020-tvclm.18d466fd9823ca19,reason=Scheduled count=None msg=Successfully assigned compute/eval-conflicts-rho010-r6-020-tvclm to kind-worker2
0.5198,Event,ADDED,eval-conflicts-rho010-r6-020-tvclm.18d466fdb5c4bcfb,"reason=Pulled count=1 msg=Container image ""busybox:musl"" already present on machine"
0.5199,Event,ADDED,eval-conflicts-rho010-r6-020-tvclm.18d466fdb72d9ed3,reason=Created count=1 msg=Created container: task
0.5201,Event,ADDED,eval-conflicts-rho010-r6-020-tvclm.18d466fdbf316fe4,reason=Started count=1 msg=Started container task
0.5203,Event,ADDED,eval-conflicts-rho010-r6-020.18d466fd74ef5494,reason=SuccessfulCreate count=1 msg=Created pod: eval-conflicts-rho010-r6-020-tvclm
0.5205,Event,ADDED,eval-conflicts-rho010-r6-020.18d46700cce5775d,reason=Completed count=1 msg=Job completed
0.5206,Event,ADDED,eval-conflicts-rho010-r6-021-7zsc5.18d466fdb192d00f,reason=Scheduled count=None msg=Successfully assigned compute/eval-conflicts-rho010-r6-021-7zsc5 to kind-worker2
0.5208,Event,ADDED,eval-conflicts-rho010-r6-021-7zsc5.18d466fdce7bdf1f,"reason=Pulled count=1 msg=Container image ""busybox:musl"" already present on machine"
0.521,Event,ADDED,eval-conflicts-rho010-r6-021-7zsc5.18d466fdcfa989fe,reason=Created count=1 msg=Created container: task
0.5211,Event,ADDED,eval-conflicts-rho010-r6-021-7zsc5.18d466fdd5ce7c80,reason=Started count=1 msg=Started container task
0.5213,Event,ADDED,eval-conflicts-rho010-r6-021.18d466fdb0f30740,reason=SuccessfulCreate count=1 msg=Created pod: eval-conflicts-rho010-r6-021-7zsc5
0.5214,Event,ADDED,eval-conflicts-rho010-r6-021.18d46701092cf116,reason=Completed count=1 msg=Job completed
0.5216,Event,ADDED,eval-conflicts-rho010-r6-022-5nnkk.18d466fdef71ec69,"reason=FailedScheduling count=None msg=0/6 nodes are available: 1 c_wall violated: 1 conflicting context pair(s) with node memory, 5 node(s) had untolerated taint(s). no new claims to deallocate, preemption: 0/6 nodes are available: 1 No preemption victims found for incoming pod, 5 Preemption is not helpful for scheduling."
0.5218,Event,ADDED,eval-conflicts-rho010-r6-022-5nnkk.18d466fdeff1c369,"reason=FailedScheduling count=None msg=0/6 nodes are available: 1 c_wall violated: 1 conflicting context pair(s) with node memory, 5 node(s) had untolerated taint(s). no new claims to deallocate, preemption: 0/6 nodes are available: 1 No preemption victims found for incoming pod, 5 Preemption is not helpful for scheduling."
0.522,Event,ADDED,eval-conflicts-rho010-r6-022-5nnkk.18d466fe0759d212,reason=Scheduled count=None msg=Successfully assigned compute/eval-conflicts-rho010-r6-022-5nnkk to kind-worker5
0.5222,Event,ADDED,eval-conflicts-rho010-r6-022-5nnkk.18d466fe2415491b,"reason=Pulled count=1 msg=Container image ""busybox:musl"" already present on machine"
0.5224,Event,ADDED,eval-conflicts-rho010-r6-022-5nnkk.18d466fe255ef209,reason=Created count=1 msg=Created container: task
0.5225,Event,ADDED,eval-conflicts-rho010-r6-022-5nnkk.18d466fe293c5333,reason=Started count=1 msg=Started container task
0.5227,Event,ADDED,eval-conflicts-rho010-r6-022.18d466fdef355e2c,reason=SuccessfulCreate count=1 msg=Created pod: eval-conflicts-rho010-r6-022-5nnkk
0.5229,Event,ADDED,eval-conflicts-rho010-r6-022.18d4670146764d21,reason=Completed count=1 msg=Job completed
0.5233,Event,ADDED,eval-conflicts-rho010-r6-023-j6hhh.18d466fe2955c02e,reason=Scheduled count=None msg=Successfully assigned compute/eval-conflicts-rho010-r6-023-j6hhh to kind-worker5
0.5237,Event,ADDED,eval-conflicts-rho010-r6-023-j6hhh.18d466fe45fd96ff,"reason=Pulled count=1 msg=Container image ""busybox:musl"" already present on machine"
0.5241,Event,ADDED,eval-conflicts-rho010-r6-023-j6hhh.18d466fe475d2afe,reason=Created count=1 msg=Created container: task
0.5243,Event,ADDED,eval-conflicts-rho010-r6-023-j6hhh.18d466fe4b6507a9,reason=Started count=1 msg=Started container task
0.5246,Event,ADDED,eval-conflicts-rho010-r6-023.18d466fe27717ebd,reason=SuccessfulCreate count=1 msg=Created pod: eval-conflicts-rho010-r6-023-j6hhh
0.5248,Event,ADDED,eval-conflicts-rho010-r6-023.18d4670182ab2057,reason=Completed count=1 msg=Job completed
0.5251,Event,ADDED,eval-conflicts-rho010-r6-024-4wslc.18d466fe63d0e34f,reason=Scheduled count=None msg=Successfully assigned compute/eval-conflicts-rho010-r6-024-4wslc to kind-worker2
0.5253,Event,ADDED,eval-conflicts-rho010-r6-024-4wslc.18d466fe7e255666,"reason=Pulled count=1 msg=Container image ""busybox:musl"" already present on machine"
0.5257,Event,ADDED,eval-conflicts-rho010-r6-024-4wslc.18d466fe7f375166,reason=Created count=1 msg=Created container: task
0.5258,Event,ADDED,eval-conflicts-rho010-r6-024-4wslc.18d466fe83337817,reason=Started count=1 msg=Started container task
0.526,Event,ADDED,eval-conflicts-rho010-r6-024.18d466fe63266a38,reason=SuccessfulCreate count=1 msg=Created pod: eval-conflicts-rho010-r6-024-4wslc
0.5262,Event,ADDED,eval-conflicts-rho010-r6-024.18d46701baf4071f,reason=Completed count=1 msg=Job completed
0.5264,Event,ADDED,eval-conflicts-rho010-r6-025-pg7hl.18d466fea0b1ea8d,reason=Scheduled count=None msg=Successfully assigned compute/eval-conflicts-rho010-r6-025-pg7hl to kind-worker5
0.5266,Event,ADDED,eval-conflicts-rho010-r6-025-pg7hl.18d466febd6afa93,"reason=Pulled count=1 msg=Container image ""busybox:musl"" already present on machine"
0.5268,Event,ADDED,eval-conflicts-rho010-r6-025-pg7hl.18d466febe851cbd,reason=Created count=1 msg=Created container: task
0.527,Event,ADDED,eval-conflicts-rho010-r6-025-pg7hl.18d466fec4a4e3e2,reason=Started count=1 msg=Started container task
0.5272,Event,ADDED,eval-conflicts-rho010-r6-025.18d466fe9fc1f45f,reason=SuccessfulCreate count=1 msg=Created pod: eval-conflicts-rho010-r6-025-pg7hl
0.5274,Event,ADDED,eval-conflicts-rho010-r6-025.18d46701fa874e27,reason=Completed count=1 msg=Job completed
0.5275,Event,ADDED,eval-conflicts-rho010-r6-026-ltq8k.18d466fedbcb5ad7,reason=Scheduled count=None msg=Successfully assigned compute/eval-conflicts-rho010-r6-026-ltq8k to kind-worker5
0.5278,Event,ADDED,eval-conflicts-rho010-r6-026-ltq8k.18d466fef83e0860,"reason=Pulled count=1 msg=Container image ""busybox:musl"" already present on machine"
0.5281,Event,ADDED,eval-conflicts-rho010-r6-026-ltq8k.18d466fef9481d0f,reason=Created count=1 msg=Created container: task
0.5283,Event,ADDED,eval-conflicts-rho010-r6-026-ltq8k.18d466fefd5557bb,reason=Started count=1 msg=Started container task
0.5286,Event,ADDED,eval-conflicts-rho010-r6-026.18d466fedaf9f990,reason=SuccessfulCreate count=1 msg=Created pod: eval-conflicts-rho010-r6-026-ltq8k
0.5288,Event,ADDED,eval-conflicts-rho010-r6-026.18d467023669d0cc,reason=Completed count=1 msg=Job completed
0.529,Event,ADDED,eval-conflicts-rho010-r6-027-qfvnc.18d466ff16bfd50e,"reason=FailedScheduling count=None msg=0/6 nodes are available: 2 c_wall violated: 1 conflicting context pair(s) with node memory, 4 node(s) had untolerated taint(s). no new claims to deallocate, preemption: 0/6 nodes are available: 2 No preemption victims found for incoming pod, 4 Preemption is not helpful for scheduling."
0.5292,Event,ADDED,eval-conflicts-rho010-r6-027-qfvnc.18d466ff17557735,"reason=FailedScheduling count=None msg=0/6 nodes are available: 2 c_wall violated: 1 conflicting context pair(s) with node memory, 4 node(s) had untolerated taint(s). no new claims to deallocate, preemption: 0/6 nodes are available: 2 No preemption victims found for incoming pod, 4 Preemption is not helpful for scheduling."
0.5294,Event,ADDED,eval-conflicts-rho010-r6-027-qfvnc.18d466ff874a615c,reason=Scheduled count=None msg=Successfully assigned compute/eval-conflicts-rho010-r6-027-qfvnc to kind-worker
0.5296,Event,ADDED,eval-conflicts-rho010-r6-027-qfvnc.18d466ffa4222067,"reason=Pulled count=1 msg=Container image ""busybox:musl"" already present on machine"
0.5297,Event,ADDED,eval-conflicts-rho010-r6-027-qfvnc.18d466ffa5a28045,reason=Created count=1 msg=Created container: task
0.5299,Event,ADDED,eval-conflicts-rho010-r6-027-qfvnc.18d466ffad7d1dba,reason=Started count=1 msg=Started container task
0.5301,Event,ADDED,eval-conflicts-rho010-r6-027.18d466ff165ac524,reason=SuccessfulCreate count=1 msg=Created pod: eval-conflicts-rho010-r6-027-qfvnc
0.5305,Event,ADDED,eval-conflicts-rho010-r6-027.18d46702ddac283e,reason=Completed count=1 msg=Job completed
0.5307,Event,ADDED,eval-conflicts-rho010-r6-028-t2t7n.18d466ff52053716,"reason=FailedScheduling count=None msg=0/6 nodes are available: 2 c_wall violated: 1 conflicting context pair(s) with node memory, 4 node(s) had untolerated taint(s). no new claims to deallocate, preemption: 0/6 nodes are available: 2 No preemption victims found for incoming pod, 4 Preemption is not helpful for scheduling."
0.5312,Event,ADDED,eval-conflicts-rho010-r6-028-t2t7n.18d466ff52a249ee,"reason=FailedScheduling count=None msg=0/6 nodes are available: 2 c_wall violated: 1 conflicting context pair(s) with node memory, 4 node(s) had untolerated taint(s). no new claims to deallocate, preemption: 0/6 nodes are available: 2 No preemption victims found for incoming pod, 4 Preemption is not helpful for scheduling."
0.5314,Event,ADDED,eval-conflicts-rho010-r6-028-t2t7n.18d466ff8820ae8f,reason=Scheduled count=None msg=Successfully assigned compute/eval-conflicts-rho010-r6-028-t2t7n to kind-worker
0.5316,Event,ADDED,eval-conflicts-rho010-r6-028-t2t7n.18d466ffa43ecd29,"reason=Pulled count=1 msg=Container image ""busybox:musl"" already present on machine"
0.5321,Event,ADDED,eval-conflicts-rho010-r6-028-t2t7n.18d466ffa63161d2,reason=Created count=1 msg=Created container: task
0.5324,Event,ADDED,eval-conflicts-rho010-r6-028-t2t7n.18d466ffad7fc764,reason=Started count=1 msg=Started container task
0.5328,Event,ADDED,eval-conflicts-rho010-r6-028.18d466ff51a023ab,reason=SuccessfulCreate count=1 msg=Created pod: eval-conflicts-rho010-r6-028-t2t7n
0.533,Event,ADDED,eval-conflicts-rho010-r6-028.18d46702dd37493c,reason=Completed count=1 msg=Job completed
0.5333,Event,ADDED,eval-conflicts-rho010-r6-029-l8zmh.18d466ff918d4e70,reason=Scheduled count=None msg=Successfully assigned compute/eval-conflicts-rho010-r6-029-l8zmh to kind-worker
0.5336,Event,ADDED,eval-conflicts-rho010-r6-029-l8zmh.18d466ffad84c811,"reason=Pulled count=1 msg=Container image ""busybox:musl"" already present on machine"
0.5337,Event,ADDED,eval-conflicts-rho010-r6-029-l8zmh.18d466ffaead0248,reason=Created count=1 msg=Created container: task
0.5344,Event,ADDED,eval-conflicts-rho010-r6-029-l8zmh.18d466ffb2ceaf90,reason=Started count=1 msg=Started container task
0.5349,Event,ADDED,eval-conflicts-rho010-r6-029.18d466ff907d9c3e,reason=SuccessfulCreate count=1 msg=Created pod: eval-conflicts-rho010-r6-029-l8zmh
0.5355,Event,ADDED,eval-conflicts-rho010-r6-029.18d46702dc533f8b,reason=Completed count=1 msg=Job completed
0.5359,Event,ADDED,eval-conflicts-rho010-r6-030-hhmgc.18d466ffc9cdb6ef,reason=Scheduled count=None msg=Successfully assigned compute/eval-conflicts-rho010-r6-030-hhmgc to kind-worker5
0.5366,Event,ADDED,eval-conflicts-rho010-r6-030-hhmgc.18d466ffe6767d66,"reason=Pulled count=1 msg=Container image ""busybox:musl"" already present on machine"
0.5368,Event,ADDED,eval-conflicts-rho010-r6-030-hhmgc.18d466ffe835f312,reason=Created count=1 msg=Created container: task
0.537,Event,ADDED,eval-conflicts-rho010-r6-030-hhmgc.18d466ffebf6d807,reason=Started count=1 msg=Started container task
0.5373,Event,ADDED,eval-conflicts-rho010-r6-030.18d466ffc8f40f72,reason=SuccessfulCreate count=1 msg=Created pod: eval-conflicts-rho010-r6-030-hhmgc
0.5375,Event,ADDED,eval-conflicts-rho010-r6-030.18d4670324b494fe,reason=Completed count=1 msg=Job completed
0.5377,Event,ADDED,eval-conflicts-rho010-r6-031-hs44b.18d46700060aab5d,reason=Scheduled count=None msg=Successfully assigned compute/eval-conflicts-rho010-r6-031-hs44b to kind-worker
0.538,Event,ADDED,eval-conflicts-rho010-r6-031-hs44b.18d4670023cf4baf,"reason=Pulled count=1 msg=Container image ""busybox:musl"" already present on machine"
0.5384,Event,ADDED,eval-conflicts-rho010-r6-031-hs44b.18d4670024e480c9,reason=Created count=1 msg=Created container: task
0.5386,Event,ADDED,eval-conflicts-rho010-r6-031-hs44b.18d4670030065856,reason=Started count=1 msg=Started container task
0.5388,Event,ADDED,eval-conflicts-rho010-r6-031.18d46700052c082e,reason=SuccessfulCreate count=1 msg=Created pod: eval-conflicts-rho010-r6-031-hs44b
0.5389,Event,ADDED,eval-conflicts-rho010-r6-031.18d467035407f5c4,reason=Completed count=1 msg=Job completed
0.5393,Event,ADDED,eval-conflicts-rho010-r6-032-hbxmg.18d467004182cdda,reason=Scheduled count=None msg=Successfully assigned compute/eval-conflicts-rho010-r6-032-hbxmg to kind-worker4
0.5395,Event,ADDED,eval-conflicts-rho010-r6-032-hbxmg.18d467005e9d89a3,"reason=Pulled count=1 msg=Container image ""busybox:musl"" already present on machine"
0.5399,Event,ADDED,eval-conflicts-rho010-r6-032-hbxmg.18d467005ff1d578,reason=Created count=1 msg=Created container: task
0.5403,Event,ADDED,eval-conflicts-rho010-r6-032-hbxmg.18d46700645c8feb,reason=Started count=1 msg=Started container task
0.5405,Event,ADDED,eval-conflicts-rho010-r6-032.18d4670040a1591a,reason=SuccessfulCreate count=1 msg=Created pod: eval-conflicts-rho010-r6-032-hbxmg
0.5407,Event,ADDED,eval-conflicts-rho010-r6-032.18d46703a4ca143a,reason=Completed count=1 msg=Job completed
0.5408,Event,ADDED,eval-conflicts-rho010-r6-033-vdxmq.18d467007d3ba00e,reason=Scheduled count=None msg=Successfully assigned compute/eval-conflicts-rho010-r6-033-vdxmq to kind-worker4
0.5412,Event,ADDED,eval-conflicts-rho010-r6-033-vdxmq.18d467009831963e,"reason=Pulled count=1 msg=Container image ""busybox:musl"" already present on machine"
0.5414,Event,ADDED,eval-conflicts-rho010-r6-033-vdxmq.18d467009957538f,reason=Created count=1 msg=Created container: task
0.5415,Event,ADDED,eval-conflicts-rho010-r6-033-vdxmq.18d467009dcc816b,reason=Started count=1 msg=Started container task
0.5417,Event,ADDED,eval-conflicts-rho010-r6-033.18d467007c52d6c0,reason=SuccessfulCreate count=1 msg=Created pod: eval-conflicts-rho010-r6-033-vdxmq
0.542,Event,ADDED,eval-conflicts-rho010-r6-033.18d46703e0ae35df,reason=Completed count=1 msg=Job completed
0.5422,Event,ADDED,eval-conflicts-rho010-r6-034-8s5kc.18d46700b89e2386,reason=Scheduled count=None msg=Successfully assigned compute/eval-conflicts-rho010-r6-034-8s5kc to kind-worker4
0.5424,Event,ADDED,eval-conflicts-rho010-r6-034-8s5kc.18d46700d53323b5,"reason=Pulled count=1 msg=Container image ""busybox:musl"" already present on machine"
0.5428,Event,ADDED,eval-conflicts-rho010-r6-034-8s5kc.18d46700d66f65ab,reason=Created count=1 msg=Created container: task
0.543,Event,ADDED,eval-conflicts-rho010-r6-034-8s5kc.18d46700e0b7224a,reason=Started count=1 msg=Started container task
0.5432,Event,ADDED,eval-conflicts-rho010-r6-034.18d46700b7d781f7,reason=SuccessfulCreate count=1 msg=Created pod: eval-conflicts-rho010-r6-034-8s5kc
0.5433,Event,ADDED,eval-conflicts-rho010-r6-034.18d467041c89249b,reason=Completed count=1 msg=Job completed
0.5436,Event,ADDED,eval-conflicts-rho010-r6-035-7hxhx.18d46700f399f152,"reason=FailedScheduling count=None msg=0/6 nodes are available: 2 c_wall violated: 1 conflicting context pair(s) with node memory, 4 node(s) had untolerated taint(s). no new claims to deallocate, preemption: 0/6 nodes are available: 2 No preemption victims found for incoming pod, 4 Preemption is not helpful for scheduling."
0.5439,Event,ADDED,eval-conflicts-rho010-r6-035-7hxhx.18d46700f47a97f3,"reason=FailedScheduling count=None msg=0/6 nodes are available: 2 c_wall violated: 1 conflicting context pair(s) with node memory, 4 node(s) had untolerated taint(s). no new claims to deallocate, preemption: 0/6 nodes are available: 2 No preemption victims found for incoming pod, 4 Preemption is not helpful for scheduling."
0.5442,Event,ADDED,eval-conflicts-rho010-r6-035-7hxhx.18d46701dbb7e7b3,"reason=FailedScheduling count=None msg=0/6 nodes are available: 1 c_wall violated: 1 conflicting context pair(s) with node memory, 5 node(s) had untolerated taint(s). no new claims to deallocate, preemption: 0/6 nodes are available: 1 No preemption victims found for incoming pod, 5 Preemption is not helpful for scheduling."
0.5445,Event,ADDED,eval-conflicts-rho010-r6-035-7hxhx.18d467022879b1f5,reason=Scheduled count=None msg=Successfully assigned compute/eval-conflicts-rho010-r6-035-7hxhx to kind-worker3
0.5446,Event,ADDED,eval-conflicts-rho010-r6-035-7hxhx.18d4670243f4d8d7,"reason=Pulled count=1 msg=Container image ""busybox:musl"" already present on machine"
0.5448,Event,ADDED,eval-conflicts-rho010-r6-035-7hxhx.18d4670245016d0b,reason=Created count=1 msg=Created container: task
0.545,Event,ADDED,eval-conflicts-rho010-r6-035-7hxhx.18d46702489f2818,reason=Started count=1 msg=Started container task
0.5452,Event,ADDED,eval-conflicts-rho010-r6-035.18d46700f32eff3f,reason=SuccessfulCreate count=1 msg=Created pod: eval-conflicts-rho010-r6-035-7hxhx
0.5453,Event,ADDED,eval-conflicts-rho010-r6-035.18d46705296e1492,reason=Completed count=1 msg=Job completed
0.5455,Event,ADDED,eval-conflicts-rho010-r6-036-85dgh.18d4670130aa464b,reason=Scheduled count=None msg=Successfully assigned compute/eval-conflicts-rho010-r6-036-85dgh to kind-worker
0.5457,Event,ADDED,eval-conflicts-rho010-r6-036-85dgh.18d467014a7a65c1,"reason=Pulled count=1 msg=Container image ""busybox:musl"" already present on machine"
0.5458,Event,ADDED,eval-conflicts-rho010-r6-036-85dgh.18d467014b963176,reason=Created count=1 msg=Created container: task
0.546,Event,ADDED,eval-conflicts-rho010-r6-036-85dgh.18d46701508f894c,reason=Started count=1 msg=Started container task
0.5462,Event,ADDED,eval-conflicts-rho010-r6-036.18d467012fba9713,reason=SuccessfulCreate count=1 msg=Created pod: eval-conflicts-rho010-r6-036-85dgh
0.5466,Event,ADDED,eval-conflicts-rho010-r6-036.18d467047ef33d5f,reason=Completed count=1 msg=Job completed
0.5468,Event,ADDED,eval-conflicts-rho010-r6-037-55n46.18d467016b2e2fd2,reason=Scheduled count=None msg=Successfully assigned compute/eval-conflicts-rho010-r6-037-55n46 to kind-worker4
0.547,Event,ADDED,eval-conflicts-rho010-r6-037-55n46.18d46701864bf5cb,"reason=Pulled count=1 msg=Container image ""busybox:musl"" already present on machine"
0.5473,Event,ADDED,eval-conflicts-rho010-r6-037-55n46.18d4670187f11b0e,reason=Created count=1 msg=Created container: task
0.5475,Event,ADDED,eval-conflicts-rho010-r6-037-55n46.18d467018d0e4639,reason=Started count=1 msg=Started container task
0.5477,Event,ADDED,eval-conflicts-rho010-r6-037.18d467016a5871ce,reason=SuccessfulCreate count=1 msg=Created pod: eval-conflicts-rho010-r6-037-55n46
0.5479,Event,ADDED,eval-conflicts-rho010-r6-037.18d46704d2f3d90f,reason=Completed count=1 msg=Job completed
0.5482,Event,ADDED,eval-conflicts-rho010-r6-038-vlpv9.18d46701a76a9351,reason=Scheduled count=None msg=Successfully assigned compute/eval-conflicts-rho010-r6-038-vlpv9 to kind-worker
0.5484,Event,ADDED,eval-conflicts-rho010-r6-038-vlpv9.18d46701c56c113a,"reason=Pulled count=1 msg=Container image ""busybox:musl"" already present on machine"
0.5487,Event,ADDED,eval-conflicts-rho010-r6-038-vlpv9.18d46701c6bd11fb,reason=Created count=1 msg=Created container: task
0.549,Event,ADDED,eval-conflicts-rho010-r6-038-vlpv9.18d46701cb295543,reason=Started count=1 msg=Started container task
0.5492,Event,ADDED,eval-conflicts-rho010-r6-038.18d46701a6a7c2d1,reason=SuccessfulCreate count=1 msg=Created pod: eval-conflicts-rho010-r6-038-vlpv9
0.5493,Event,ADDED,eval-conflicts-rho010-r6-038.18d46704f777be88,reason=Completed count=1 msg=Job completed
0.5495,Event,ADDED,eval-conflicts-rho010-r6-039-bbb6n.18d46701e269e1c3,"reason=FailedScheduling count=None msg=0/6 nodes are available: 1 c_wall violated: 1 conflicting context pair(s) with node memory, 5 node(s) had untolerated taint(s). no new claims to deallocate, preemption: 0/6 nodes are available: 1 No preemption victims found for incoming pod, 5 Preemption is not helpful for scheduling."
0.5497,Event,ADDED,eval-conflicts-rho010-r6-039-bbb6n.18d46701e2ea6b2b,"reason=FailedScheduling count=None msg=0/6 nodes are available: 1 c_wall violated: 1 conflicting context pair(s) with node memory, 5 node(s) had untolerated taint(s). no new claims to deallocate, preemption: 0/6 nodes are available: 1 No preemption victims found for incoming pod, 5 Preemption is not helpful for scheduling."
0.5499,Event,ADDED,eval-conflicts-rho010-r6-039-bbb6n.18d467022896276b,reason=Scheduled count=None msg=Successfully assigned compute/eval-conflicts-rho010-r6-039-bbb6n to kind-worker3
0.5501,Event,ADDED,eval-conflicts-rho010-r6-039-bbb6n.18d4670247c83c9f,"reason=Pulled count=1 msg=Container image ""busybox:musl"" already present on machine"
0.5508,Event,ADDED,eval-conflicts-rho010-r6-039-bbb6n.18d4670248e29e18,reason=Created count=1 msg=Created container: task
0.5513,Event,ADDED,eval-conflicts-rho010-r6-039-bbb6n.18d467024c3c2e1c,reason=Started count=1 msg=Started container task
0.5515,Event,ADDED,eval-conflicts-rho010-r6-039.18d46701e22c08a2,reason=SuccessfulCreate count=1 msg=Created pod: eval-conflicts-rho010-r6-039-bbb6n
0.5516,Event,ADDED,eval-conflicts-rho010-r6-039.18d46705296efb10,reason=Completed count=1 msg=Job completed
0.552,Event,ADDED,eval-conflicts-rho010-r6-040-qvlwd.18d467021e3afc7b,reason=Scheduled count=None msg=Successfully assigned compute/eval-conflicts-rho010-r6-040-qvlwd to kind-worker4
0.5522,Event,ADDED,eval-conflicts-rho010-r6-040-qvlwd.18d46702379e532a,"reason=Pulled count=1 msg=Container image ""busybox:musl"" already present on machine"
0.5524,Event,ADDED,eval-conflicts-rho010-r6-040-qvlwd.18d4670238b35dde,reason=Created count=1 msg=Created container: task
0.5527,Event,ADDED,eval-conflicts-rho010-r6-040-qvlwd.18d467023ab11a64,reason=Started count=1 msg=Started container task
0.5529,Event,ADDED,eval-conflicts-rho010-r6-040.18d467021d9e241e,reason=SuccessfulCreate count=1 msg=Created pod: eval-conflicts-rho010-r6-040-qvlwd
0.5531,Event,ADDED,eval-conflicts-rho010-r6-040.18d467054b1d0fa2,reason=Completed count=1 msg=Job completed
0.5532,Event,ADDED,eval-conflicts-rho010-r6-041-hl5cc.18d467025a4eafb1,reason=Scheduled count=None msg=Successfully assigned compute/eval-conflicts-rho010-r6-041-hl5cc to kind-worker2
0.5536,Event,ADDED,eval-conflicts-rho010-r6-041-hl5cc.18d46702733943ea,"reason=Pulled count=1 msg=Container image ""busybox:musl"" already present on machine"
0.5539,Event,ADDED,eval-conflicts-rho010-r6-041-hl5cc.18d467027442454b,reason=Created count=1 msg=Created container: task
0.5541,Event,ADDED,eval-conflicts-rho010-r6-041-hl5cc.18d467027622c5a3,reason=Started count=1 msg=Started container task
0.5543,Event,ADDED,eval-conflicts-rho010-r6-041.18d4670259818a22,reason=SuccessfulCreate count=1 msg=Created pod: eval-conflicts-rho010-r6-041-hl5cc
0.5546,Event,ADDED,eval-conflicts-rho010-r6-041.18d46705b4e63016,reason=Completed count=1 msg=Job completed
0.5548,Event,ADDED,eval-conflicts-rho010-r6-042-jhdkt.18d46702951498cc,reason=Scheduled count=None msg=Successfully assigned compute/eval-conflicts-rho010-r6-042-jhdkt to kind-worker2
0.555,Event,ADDED,eval-conflicts-rho010-r6-042-jhdkt.18d46702add83c71,"reason=Pulled count=1 msg=Container image ""busybox:musl"" already present on machine"
0.5554,Event,ADDED,eval-conflicts-rho010-r6-042-jhdkt.18d46702af0c0bfe,reason=Created count=1 msg=Created container: task
0.5555,Event,ADDED,eval-conflicts-rho010-r6-042-jhdkt.18d46702b2e23c36,reason=Started count=1 msg=Started container task
0.5557,Event,ADDED,eval-conflicts-rho010-r6-042.18d467029441ed1c,reason=SuccessfulCreate count=1 msg=Created pod: eval-conflicts-rho010-r6-042-jhdkt
0.5559,Event,ADDED,eval-conflicts-rho010-r6-042.18d46705f118773d,reason=Completed count=1 msg=Job completed
0.5562,Event,ADDED,eval-conflicts-rho010-r6-043-rfg9c.18d46702d09d7ece,reason=Scheduled count=None msg=Successfully assigned compute/eval-conflicts-rho010-r6-043-rfg9c to kind-worker5
0.5564,Event,ADDED,eval-conflicts-rho010-r6-043-rfg9c.18d46702e8956487,"reason=Pulled count=1 msg=Container image ""busybox:musl"" already present on machine"
0.5566,Event,ADDED,eval-conflicts-rho010-r6-043-rfg9c.18d46702e9dd8a6a,reason=Created count=1 msg=Created container: task
0.5568,Event,ADDED,eval-conflicts-rho010-r6-043-rfg9c.18d46702f02cfe8f,reason=Started count=1 msg=Started container task
0.557,Event,ADDED,eval-conflicts-rho010-r6-043.18d46702cfbb7595,reason=SuccessfulCreate count=1 msg=Created pod: eval-conflicts-rho010-r6-043-rfg9c
0.5571,Event,ADDED,eval-conflicts-rho010-r6-043.18d467062d9f00b0,reason=Completed count=1 msg=Job completed
0.5573,Event,ADDED,eval-conflicts-rho010-r6-044-g79vz.18d467030cc84bfe,reason=Scheduled count=None msg=Successfully assigned compute/eval-conflicts-rho010-r6-044-g79vz to kind-worker5
0.5576,Event,ADDED,eval-conflicts-rho010-r6-044-g79vz.18d46703264476f9,"reason=Pulled count=1 msg=Container image ""busybox:musl"" already present on machine"
0.5578,Event,ADDED,eval-conflicts-rho010-r6-044-g79vz.18d467032764d4a9,reason=Created count=1 msg=Created container: task
0.558,Event,ADDED,eval-conflicts-rho010-r6-044-g79vz.18d4670329563a88,reason=Started count=1 msg=Started container task
0.5582,Event,ADDED,eval-conflicts-rho010-r6-044.18d467030b8e2b56,reason=SuccessfulCreate count=1 msg=Created pod: eval-conflicts-rho010-r6-044-g79vz
0.5585,Event,ADDED,eval-conflicts-rho010-r6-044.18d467062e15e103,reason=Completed count=1 msg=Job completed
0.5587,Event,ADDED,eval-conflicts-rho010-r6-045-dckzn.18d467034847e361,reason=Scheduled count=None msg=Successfully assigned compute/eval-conflicts-rho010-r6-045-dckzn to kind-worker5
0.5588,Event,ADDED,eval-conflicts-rho010-r6-045-dckzn.18d4670360f91a62,"reason=Pulled count=1 msg=Container image ""busybox:musl"" already present on machine"
0.5592,Event,ADDED,eval-conflicts-rho010-r6-045-dckzn.18d4670362061180,reason=Created count=1 msg=Created container: task
0.5594,Event,ADDED,eval-conflicts-rho010-r6-045-dckzn.18d4670365eebc9b,reason=Started count=1 msg=Started container task
0.5596,Event,ADDED,eval-conflicts-rho010-r6-045.18d46703472b0d54,reason=SuccessfulCreate count=1 msg=Created pod: eval-conflicts-rho010-r6-045-dckzn
0.5597,Event,ADDED,eval-conflicts-rho010-r6-045.18d46706a58dd445,reason=Completed count=1 msg=Job completed
0.56,Event,ADDED,eval-conflicts-rho010-r6-046-swp2q.18d4670383d36044,reason=Scheduled count=None msg=Successfully assigned compute/eval-conflicts-rho010-r6-046-swp2q to kind-worker5
0.5603,Event,ADDED,eval-conflicts-rho010-r6-046-swp2q.18d467039d7aef24,"reason=Pulled count=1 msg=Container image ""busybox:musl"" already present on machine"
0.5605,Event,ADDED,eval-conflicts-rho010-r6-046-swp2q.18d467039ef010b3,reason=Created count=1 msg=Created container: task
0.5607,Event,ADDED,eval-conflicts-rho010-r6-046-swp2q.18d46703a2b8439e,reason=Started count=1 msg=Started container task
0.561,Event,ADDED,eval-conflicts-rho010-r6-046.18d4670382aa6626,reason=SuccessfulCreate count=1 msg=Created pod: eval-conflicts-rho010-r6-046-swp2q
0.5612,Event,ADDED,eval-conflicts-rho010-r6-046.18d46706e495da85,reason=Completed count=1 msg=Job completed
0.5613,Event,ADDED,eval-conflicts-rho010-r6-047-prqx9.18d46703c0393b01,reason=Scheduled count=None msg=Successfully assigned compute/eval-conflicts-rho010-r6-047-prqx9 to kind-worker2
0.5616,Event,ADDED,eval-conflicts-rho010-r6-047-prqx9.18d46703d99b0923,"reason=Pulled count=1 msg=Container image ""busybox:musl"" already present on machine"
0.5618,Event,ADDED,eval-conflicts-rho010-r6-047-prqx9.18d46703dabce850,reason=Created count=1 msg=Created container: task
0.562,Event,ADDED,eval-conflicts-rho010-r6-047-prqx9.18d46703dd088c38,reason=Started count=1 msg=Started container task
0.5622,Event,ADDED,eval-conflicts-rho010-r6-047.18d46703bf18a0f8,reason=SuccessfulCreate count=1 msg=Created pod: eval-conflicts-rho010-r6-047-prqx9
0.5625,Event,ADDED,eval-conflicts-rho010-r6-047.18d467071aa43965,reason=Completed count=1 msg=Job completed
0.5627,Event,ADDED,eval-conflicts-rho010-r6-048-hgr9h.18d46703fb1d563f,reason=Scheduled count=None msg=Successfully assigned compute/eval-conflicts-rho010-r6-048-hgr9h to kind-worker2
0.5629,Event,ADDED,eval-conflicts-rho010-r6-048-hgr9h.18d4670414f5832a,"reason=Pulled count=1 msg=Container image ""busybox:musl"" already present on machine"
0.563,Event,ADDED,eval-conflicts-rho010-r6-048-hgr9h.18d46704160b1de2,reason=Created count=1 msg=Created container: task
0.5633,Event,ADDED,eval-conflicts-rho010-r6-048-hgr9h.18d4670418086ad2,reason=Started count=1 msg=Started container task
0.5635,Event,ADDED,eval-conflicts-rho010-r6-048.18d46703f9e76a8e,reason=SuccessfulCreate count=1 msg=Created pod: eval-conflicts-rho010-r6-048-hgr9h
0.5643,Event,ADDED,eval-conflicts-rho010-r6-048.18d46707563475e0,reason=Completed count=1 msg=Job completed
0.5647,Event,ADDED,eval-conflicts-rho010-r6-049-rn2wf.18d467043700d3b8,reason=Scheduled count=None msg=Successfully assigned compute/eval-conflicts-rho010-r6-049-rn2wf to kind-worker2
0.5649,Event,ADDED,eval-conflicts-rho010-r6-049-rn2wf.18d467044fce4b2c,"reason=Pulled count=1 msg=Container image ""busybox:musl"" already present on machine"
0.565,Event,ADDED,eval-conflicts-rho010-r6-049-rn2wf.18d4670450d31572,reason=Created count=1 msg=Created container: task
0.5652,Event,ADDED,eval-conflicts-rho010-r6-049-rn2wf.18d4670453d38bdf,reason=Started count=1 msg=Started container task
0.5654,Event,ADDED,eval-conflicts-rho010-r6-049.18d46704359ee1d5,reason=SuccessfulCreate count=1 msg=Created pod: eval-conflicts-rho010-r6-049-rn2wf
0.5656,Event,ADDED,eval-conflicts-rho010-r6-049.18d46707925ef13c,reason=Completed count=1 msg=Job completed
0.5658,Event,ADDED,eval-conflicts-rho010-r6-050-fdnpm.18d467047264c652,reason=Scheduled count=None msg=Successfully assigned compute/eval-conflicts-rho010-r6-050-fdnpm to kind-worker5
0.566,Event,ADDED,eval-conflicts-rho010-r6-050-fdnpm.18d467048bc034ba,"reason=Pulled count=1 msg=Container image ""busybox:musl"" already present on machine"
0.5661,Event,ADDED,eval-conflicts-rho010-r6-050-fdnpm.18d467048cf59f0d,reason=Created count=1 msg=Created container: task
0.5663,Event,ADDED,eval-conflicts-rho010-r6-050-fdnpm.18d4670490f001ff,reason=Started count=1 msg=Started container task
0.5665,Event,ADDED,eval-conflicts-rho010-r6-050.18d46704711f6378,reason=SuccessfulCreate count=1 msg=Created pod: eval-conflicts-rho010-r6-050-fdnpm
0.5666,Event,ADDED,eval-conflicts-rho010-r6-050.18d46707d070d84f,reason=Completed count=1 msg=Job completed
0.5668,Event,ADDED,eval-conflicts-rho010-r6-051-ptspn.18d46704ad2d726a,reason=Scheduled count=None msg=Successfully assigned compute/eval-conflicts-rho010-r6-051-ptspn to kind-worker5
0.567,Event,ADDED,eval-conflicts-rho010-r6-051-ptspn.18d46704cba55feb,"reason=Pulled count=1 msg=Container image ""busybox:musl"" already present on machine"
0.5671,Event,ADDED,eval-conflicts-rho010-r6-051-ptspn.18d46704cce44f93,reason=Created count=1 msg=Created container: task
0.5675,Event,ADDED,eval-conflicts-rho010-r6-051-ptspn.18d46704d2aaa912,reason=Started count=1 msg=Started container task
0.5676,Event,ADDED,eval-conflicts-rho010-r6-051.18d46704ac9b5ced,reason=SuccessfulCreate count=1 msg=Created pod: eval-conflicts-rho010-r6-051-ptspn
0.5678,Event,ADDED,eval-conflicts-rho010-r6-051.18d467080c284e30,reason=Completed count=1 msg=Job completed
0.5682,Event,ADDED,eval-conflicts-rho010-r6-052-lbxrs.18d46704e89a889c,"reason=FailedScheduling count=None msg=0/6 nodes are available: 1 c_wall violated: 1 conflicting context pair(s) with node memory, 5 node(s) had untolerated taint(s). no new claims to deallocate, preemption: 0/6 nodes are available: 1 No preemption victims found for incoming pod, 5 Preemption is not helpful for scheduling."
0.5684,Event,ADDED,eval-conflicts-rho010-r6-052-lbxrs.18d46704e92ebf0b,"reason=FailedScheduling count=None msg=0/6 nodes are available: 1 c_wall violated: 1 conflicting context pair(s) with node memory, 5 node(s) had untolerated taint(s). no new claims to deallocate, preemption: 0/6 nodes are available: 1 No preemption victims found for incoming pod, 5 Preemption is not helpful for scheduling."
0.5686,Event,ADDED,eval-conflicts-rho010-r6-052-lbxrs.18d467069589dbf9,reason=Scheduled count=None msg=Successfully assigned compute/eval-conflicts-rho010-r6-052-lbxrs to kind-worker
0.569,Event,ADDED,eval-conflicts-rho010-r6-052-lbxrs.18d46706ae549561,"reason=Pulled count=1 msg=Container image ""busybox:musl"" already present on machine"
0.5692,Event,ADDED,eval-conflicts-rho010-r6-052-lbxrs.18d46706aff640f2,reason=Created count=1 msg=Created container: task
0.5694,Event,ADDED,eval-conflicts-rho010-r6-052-lbxrs.18d46706b208a726,reason=Started count=1 msg=Started container task
0.5695,Event,ADDED,eval-conflicts-rho010-r6-052.18d46704e85b123a,reason=SuccessfulCreate count=1 msg=Created pod: eval-conflicts-rho010-r6-052-lbxrs
0.5699,Event,ADDED,eval-conflicts-rho010-r6-052.18d46709e2aeb248,reason=Completed count=1 msg=Job completed
0.5701,Event,ADDED,eval-conflicts-rho010-r6-053-cfrjn.18d4670528b5c932,"reason=FailedScheduling count=None msg=0/6 nodes are available: 6 node(s) had untolerated taint(s). no new claims to deallocate, preemption: 0/6 nodes are available: 6 Preemption is not helpful for scheduling."
0.5703,Event,ADDED,eval-conflicts-rho010-r6-053-cfrjn.18d4670695bd6743,"reason=FailedScheduling count=None msg=0/6 nodes are available: 1 c_wall violated: 1 conflicting context pair(s) with node memory, 5 node(s) had untolerated taint(s). no new claims to deallocate, preemption: 0/6 nodes are available: 1 No preemption victims found for incoming pod, 5 Preemption is not helpful for scheduling."
0.5707,Event,ADDED,eval-conflicts-rho010-r6-053-cfrjn.18d467069ba048d9,"reason=FailedScheduling count=None msg=0/6 nodes are available: 1 c_wall violated: 1 conflicting context pair(s) with node memory, 5 node(s) had untolerated taint(s). no new claims to deallocate, preemption: 0/6 nodes are available: 1 No preemption victims found for incoming pod, 5 Preemption is not helpful for scheduling."
0.5709,Event,ADDED,eval-conflicts-rho010-r6-053-cfrjn.18d46706e4569ef3,reason=Scheduled count=None msg=Successfully assigned compute/eval-conflicts-rho010-r6-053-cfrjn to kind-worker3
0.5711,Event,ADDED,eval-conflicts-rho010-r6-053-cfrjn.18d46706feaf2676,"reason=Pulled count=1 msg=Container image ""busybox:musl"" already present on machine"
0.5713,Event,ADDED,eval-conflicts-rho010-r6-053-cfrjn.18d46707003ce1c5,reason=Created count=1 msg=Created container: task
0.5717,Event,ADDED,eval-conflicts-rho010-r6-053-cfrjn.18d46707045f89ff,reason=Started count=1 msg=Started container task
0.5719,Event,ADDED,eval-conflicts-rho010-r6-053.18d4670528a8a801,reason=SuccessfulCreate count=1 msg=Created pod: eval-conflicts-rho010-r6-053-cfrjn
0.5722,Event,ADDED,eval-conflicts-rho010-r6-053.18d4670a0e40055b,reason=Completed count=1 msg=Job completed
0.5725,Event,ADDED,eval-conflicts-rho010-r6-054-hltfl.18d467055faf0776,"reason=FailedScheduling count=None msg=0/6 nodes are available: 6 node(s) had untolerated taint(s). no new claims to deallocate, preemption: 0/6 nodes are available: 6 Preemption is not helpful for scheduling."
0.5727,Event,ADDED,eval-conflicts-rho010-r6-054-hltfl.18d46706963865d4,"reason=FailedScheduling count=None msg=0/6 nodes are available: 1 c_wall violated: 1 conflicting context pair(s) with node memory, 5 node(s) had untolerated taint(s). no new claims to deallocate, preemption: 0/6 nodes are available: 1 No preemption victims found for incoming pod, 5 Preemption is not helpful for scheduling."
0.5729,Event,ADDED,eval-conflicts-rho010-r6-054-hltfl.18d467069bcdd398,"reason=FailedScheduling count=None msg=0/6 nodes are available: 1 c_wall violated: 1 conflicting context pair(s) with node memory, 5 node(s) had untolerated taint(s). no new claims to deallocate, preemption: 0/6 nodes are available: 1 No preemption victims found for incoming pod, 5 Preemption is not helpful for scheduling."
0.5732,Event,ADDED,eval-conflicts-rho010-r6-054-hltfl.18d46706eb22c862,"reason=FailedScheduling count=None msg=0/6 nodes are available: 2 c_wall violated: 1 conflicting context pair(s) with node memory, 4 node(s) had untolerated taint(s). no new claims to deallocate, preemption: 0/6 nodes are available: 2 No preemption victims found for incoming pod, 4 Preemption is not helpful for scheduling."
0.5734,Event,ADDED,eval-conflicts-rho010-r6-054-hltfl.18d46706f5e67869,reason=Scheduled count=None msg=Successfully assigned compute/eval-conflicts-rho010-r6-054-hltfl to kind-worker4
0.5736,Event,ADDED,eval-conflicts-rho010-r6-054-hltfl.18d467070fbf64f0,"reason=Pulled count=1 msg=Container image ""busybox:musl"" already present on machine"
0.5737,Event,ADDED,eval-conflicts-rho010-r6-054-hltfl.18d467071192f955,reason=Created count=1 msg=Created container: task
0.5741,Event,ADDED,eval-conflicts-rho010-r6-054-hltfl.18d46707163c67c5,reason=Started count=1 msg=Started container task
0.5743,Event,ADDED,eval-conflicts-rho010-r6-054.18d467055faa3b2a,reason=SuccessfulCreate count=1 msg=Created pod: eval-conflicts-rho010-r6-054-hltfl
0.5746,Event,ADDED,eval-conflicts-rho010-r6-054.18d4670a3054ad18,reason=Completed count=1 msg=Job completed
0.5749,Event,ADDED,eval-conflicts-rho010-r6-055-tmpl4.18d46705a029e2eb,"reason=FailedScheduling count=None msg=0/6 nodes are available: 6 node(s) had untolerated taint(s). no new claims to deallocate, preemption: 0/6 nodes are available: 6 Preemption is not helpful for scheduling."
0.5751,Event,ADDED,eval-conflicts-rho010-r6-055-tmpl4.18d4670696a9221a,"reason=FailedScheduling count=None msg=0/6 nodes are available: 1 c_wall violated: 1 conflicting context pair(s) with node memory, 5 node(s) had untolerated taint(s). no new claims to deallocate, preemption: 0/6 nodes are available: 1 No preemption victims found for incoming pod, 5 Preemption is not helpful for scheduling."
0.5753,Event,ADDED,eval-conflicts-rho010-r6-055-tmpl4.18d467069c04858f,"reason=FailedScheduling count=None msg=0/6 nodes are available: 1 c_wall violated: 1 conflicting context pair(s) with node memory, 5 node(s) had untolerated taint(s). no new claims to deallocate, preemption: 0/6 nodes are available: 1 No preemption victims found for incoming pod, 5 Preemption is not helpful for scheduling."
0.5757,Event,ADDED,eval-conflicts-rho010-r6-055-tmpl4.18d46706eb608507,"reason=FailedScheduling count=None msg=0/6 nodes are available: 2 c_wall violated: 1 conflicting context pair(s) with node memory, 4 node(s) had untolerated taint(s). no new claims to deallocate, preemption: 0/6 nodes are available: 2 No preemption victims found for incoming pod, 4 Preemption is not helpful for scheduling."
0.5759,Event,ADDED,eval-conflicts-rho010-r6-055-tmpl4.18d46706fb6ffbd6,reason=Scheduled count=None msg=Successfully assigned compute/eval-conflicts-rho010-r6-055-tmpl4 to kind-worker4
0.5763,Event,ADDED,eval-conflicts-rho010-r6-055-tmpl4.18d4670716e74508,"reason=Pulled count=1 msg=Container image ""busybox:musl"" already present on machine"
0.5765,Event,ADDED,eval-conflicts-rho010-r6-055-tmpl4.18d467071826c54b,reason=Created count=1 msg=Created container: task
0.5769,Event,ADDED,eval-conflicts-rho010-r6-055-tmpl4.18d467071ca8b710,reason=Started count=1 msg=Started container task
0.577,Event,ADDED,eval-conflicts-rho010-r6-055.18d46705a022a499,reason=SuccessfulCreate count=1 msg=Created pod: eval-conflicts-rho010-r6-055-tmpl4
0.5774,Event,ADDED,eval-conflicts-rho010-r6-055.18d4670a307d979c,reason=Completed count=1 msg=Job completed
0.5777,Event,ADDED,eval-conflicts-rho010-r6-056-b4n7k.18d46705dc146536,"reason=FailedScheduling count=None msg=0/6 nodes are available: 6 node(s) had untolerated taint(s). no new claims to deallocate, preemption: 0/6 nodes are available: 6 Preemption is not helpful for scheduling."
0.5779,Event,ADDED,eval-conflicts-rho010-r6-056-b4n7k.18d4670697667e38,reason=Scheduled count=None msg=Successfully assigned compute/eval-conflicts-rho010-r6-056-b4n7k to kind-worker
0.5781,Event,ADDED,eval-conflicts-rho010-r6-056-b4n7k.18d46706af331e24,"reason=Pulled count=1 msg=Container image ""busybox:musl"" already present on machine"
0.5782,Event,ADDED,eval-conflicts-rho010-r6-056-b4n7k.18d46706b1664011,reason=Created count=1 msg=Created container: task
0.5786,Event,ADDED,eval-conflicts-rho010-r6-056-b4n7k.18d46706b3b9359f,reason=Started count=1 msg=Started container task
0.5788,Event,ADDED,eval-conflicts-rho010-r6-056.18d46705dc0c1343,reason=SuccessfulCreate count=1 msg=Created pod: eval-conflicts-rho010-r6-056-b4n7k
0.5789,Event,ADDED,eval-conflicts-rho010-r6-056.18d46709e26d5dda,reason=Completed count=1 msg=Job completed
0.5791,Event,ADDED,eval-conflicts-rho010-r6-057-k4kk5.18d46706124a1e74,"reason=FailedScheduling count=None msg=0/6 nodes are available: 6 node(s) had untolerated taint(s). no new claims to deallocate, preemption: 0/6 nodes are available: 6 Preemption is not helpful for scheduling."
0.5794,Event,ADDED,eval-conflicts-rho010-r6-057-k4kk5.18d467069782c311,reason=Scheduled count=None msg=Successfully assigned compute/eval-conflicts-rho010-r6-057-k4kk5 to kind-worker
0.5796,Event,ADDED,eval-conflicts-rho010-r6-057-k4kk5.18d46706b07e24a1,"reason=Pulled count=1 msg=Container image ""busybox:musl"" already present on machine"
0.5798,Event,ADDED,eval-conflicts-rho010-r6-057-k4kk5.18d46706b282848d,reason=Created count=1 msg=Created container: task
0.5801,Event,ADDED,eval-conflicts-rho010-r6-057-k4kk5.18d46706b4dbbbc3,reason=Started count=1 msg=Started container task
0.5803,Event,ADDED,eval-conflicts-rho010-r6-057.18d467061240a835,reason=SuccessfulCreate count=1 msg=Created pod: eval-conflicts-rho010-r6-057-k4kk5
0.5805,Event,ADDED,eval-conflicts-rho010-r6-057.18d46709e289e90d,reason=Completed count=1 msg=Job completed
0.5807,Event,ADDED,eval-conflicts-rho010-r6-058-96ftv.18d467064dee4dca,"reason=FailedScheduling count=None msg=0/6 nodes are available: 6 node(s) had untolerated taint(s). no new claims to deallocate, preemption: 0/6 nodes are available: 6 Preemption is not helpful for scheduling."
0.5809,Event,ADDED,eval-conflicts-rho010-r6-058-96ftv.18d4670697ffda08,reason=Scheduled count=None msg=Successfully assigned compute/eval-conflicts-rho010-r6-058-96ftv to kind-worker
0.5811,Event,ADDED,eval-conflicts-rho010-r6-058-96ftv.18d46706b1898a5b,"reason=Pulled count=1 msg=Container image ""busybox:musl"" already present on machine"
0.5813,Event,ADDED,eval-conflicts-rho010-r6-058-96ftv.18d46706b3287a16,reason=Created count=1 msg=Created container: task
0.5816,Event,ADDED,eval-conflicts-rho010-r6-058-96ftv.18d46706b567ee38,reason=Started count=1 msg=Started container task
0.5818,Event,ADDED,eval-conflicts-rho010-r6-058.18d467064de64583,reason=SuccessfulCreate count=1 msg=Created pod: eval-conflicts-rho010-r6-058-96ftv
0.582,Event,ADDED,eval-conflicts-rho010-r6-058.18d46709e2ab7022,reason=Completed count=1 msg=Job completed
0.5821,Event,ADDED,eval-conflicts-rho010-r6-059-n6pv5.18d4670689710ab4,"reason=FailedScheduling count=None msg=0/6 nodes are available: 6 node(s) had untolerated taint(s). no new claims to deallocate, preemption: 0/6 nodes are available: 6 Preemption is not helpful for scheduling."
0.5824,Event,ADDED,eval-conflicts-rho010-r6-059-n6pv5.18d467069b25be20,reason=Scheduled count=None msg=Successfully assigned compute/eval-conflicts-rho010-r6-059-n6pv5 to kind-worker
0.5826,Event,ADDED,eval-conflicts-rho010-r6-059-n6pv5.18d46706b411997c,"reason=Pulled count=1 msg=Container image ""busybox:musl"" already present on machine"
0.5828,Event,ADDED,eval-conflicts-rho010-r6-059-n6pv5.18d46706b59c4840,reason=Created count=1 msg=Created container: task
0.5831,Event,ADDED,eval-conflicts-rho010-r6-059-n6pv5.18d46706b9ab6b1c,reason=Started count=1 msg=Started container task
0.5833,Event,ADDED,eval-conflicts-rho010-r6-059.18d46706896b753e,reason=SuccessfulCreate count=1 msg=Created pod: eval-conflicts-rho010-r6-059-n6pv5
0.5835,Event,ADDED,eval-conflicts-rho010-r6-059.18d46709e2af60bd,reason=Completed count=1 msg=Job completed
0.5836,Event,ADDED,eval-conflicts-rho010-r6-060-9ddgt.18d46706c68af105,"reason=FailedScheduling count=None msg=0/6 nodes are available: 1 c_wall violated: 1 conflicting context pair(s) with node memory, 5 node(s) had untolerated taint(s). no new claims to deallocate, preemption: 0/6 nodes are available: 1 No preemption victims found for incoming pod, 5 Preemption is not helpful for scheduling."
0.584,Event,ADDED,eval-conflicts-rho010-r6-060-9ddgt.18d46706c73d0c3e,"reason=FailedScheduling count=None msg=0/6 nodes are available: 1 c_wall violated: 1 conflicting context pair(s) with node memory, 5 node(s) had untolerated taint(s). no new claims to deallocate, preemption: 0/6 nodes are available: 1 No preemption victims found for incoming pod, 5 Preemption is not helpful for scheduling."
0.5843,Event,ADDED,eval-conflicts-rho010-r6-060-9ddgt.18d46706e45901a9,reason=Scheduled count=None msg=Successfully assigned compute/eval-conflicts-rho010-r6-060-9ddgt to kind-worker3
0.5844,Event,ADDED,eval-conflicts-rho010-r6-060-9ddgt.18d46706fe5ff1e6,"reason=Pulled count=1 msg=Container image ""busybox:musl"" already present on machine"
0.5847,Event,ADDED,eval-conflicts-rho010-r6-060-9ddgt.18d46706ffdc8bfe,reason=Created count=1 msg=Created container: task
0.5849,Event,ADDED,eval-conflicts-rho010-r6-060-9ddgt.18d46707042bd762,reason=Started count=1 msg=Started container task
0.5851,Event,ADDED,eval-conflicts-rho010-r6-060.18d46706c645737d,reason=SuccessfulCreate count=1 msg=Created pod: eval-conflicts-rho010-r6-060-9ddgt
0.5853,Event,ADDED,eval-conflicts-rho010-r6-060.18d4670a0e85e0b1,reason=Completed count=1 msg=Job completed
0.5855,Event,ADDED,eval-conflicts-rho010-r6-061-2srcl.18d4670702051c67,reason=Scheduled count=None msg=Successfully assigned compute/eval-conflicts-rho010-r6-061-2srcl to kind-worker
0.5857,Event,ADDED,eval-conflicts-rho010-r6-061-2srcl.18d467071fb4b03f,"reason=Pulled count=1 msg=Container image ""busybox:musl"" already present on machine"
0.5859,Event,ADDED,eval-conflicts-rho010-r6-061-2srcl.18d4670720dc21e0,reason=Created count=1 msg=Created container: task
0.5861,Event,ADDED,eval-conflicts-rho010-r6-061-2srcl.18d4670724f6b82c,reason=Started count=1 msg=Started container task
0.5862,Event,ADDED,eval-conflicts-rho010-r6-061.18d4670700fa7122,reason=SuccessfulCreate count=1 msg=Created pod: eval-conflicts-rho010-r6-061-2srcl
0.5864,Event,ADDED,eval-conflicts-rho010-r6-061.18d4670a60834fb4,reason=Completed count=1 msg=Job completed
0.5865,Event,ADDED,eval-conflicts-rho010-r6-062-sbxbt.18d467073eae0305,reason=Scheduled count=None msg=Successfully assigned compute/eval-conflicts-rho010-r6-062-sbxbt to kind-worker4
0.5867,Event,ADDED,eval-conflicts-rho010-r6-062-sbxbt.18d4670758676ffd,"reason=Pulled count=1 msg=Container image ""busybox:musl"" already present on machine"
0.5869,Event,ADDED,eval-conflicts-rho010-r6-062-sbxbt.18d4670759b28767,reason=Created count=1 msg=Created container: task
0.587,Event,ADDED,eval-conflicts-rho010-r6-062-sbxbt.18d467075e4e7a71,reason=Started count=1 msg=Started container task
0.5873,Event,ADDED,eval-conflicts-rho010-r6-062.18d467073d420c8a,reason=SuccessfulCreate count=1 msg=Created pod: eval-conflicts-rho010-r6-062-sbxbt
0.5875,Event,ADDED,eval-conflicts-rho010-r6-062.18d4670aa8d3c5cf,reason=Completed count=1 msg=Job completed
0.5877,Event,ADDED,eval-conflicts-rho010-r6-063-5ds48.18d4670779206bf5,reason=Scheduled count=None msg=Successfully assigned compute/eval-conflicts-rho010-r6-063-5ds48 to kind-worker
0.5879,Event,ADDED,eval-conflicts-rho010-r6-063-5ds48.18d46707946b4145,"reason=Pulled count=1 msg=Container image ""busybox:musl"" already present on machine"
0.5882,Event,ADDED,eval-conflicts-rho010-r6-063-5ds48.18d4670795caf04b,reason=Created count=1 msg=Created container: task
0.5885,Event,ADDED,eval-conflicts-rho010-r6-063-5ds48.18d4670799f471fb,reason=Started count=1 msg=Started container task
0.5887,Event,ADDED,eval-conflicts-rho010-r6-063.18d4670778311286,reason=SuccessfulCreate count=1 msg=Created pod: eval-conflicts-rho010-r6-063-5ds48
0.5889,Event,ADDED,eval-conflicts-rho010-r6-063.18d4670acf66ac33,reason=Completed count=1 msg=Job completed
0.5891,Event,ADDED,eval-conflicts-rho010-r6-064-xj942.18d46707b4831e65,reason=Scheduled count=None msg=Successfully assigned compute/eval-conflicts-rho010-r6-064-xj942 to kind-worker
0.5893,Event,ADDED,eval-conflicts-rho010-r6-064-xj942.18d46707cef3e767,"reason=Pulled count=1 msg=Container image ""busybox:musl"" already present on machine"
0.5895,Event,ADDED,eval-conflicts-rho010-r6-064-xj942.18d46707d037b0b8,reason=Created count=1 msg=Created container: task
0.5897,Event,ADDED,eval-conflicts-rho010-r6-064-xj942.18d46707d4874c01,reason=Started count=1 msg=Started container task
0.59,Event,ADDED,eval-conflicts-rho010-r6-064.18d46707b389c614,reason=SuccessfulCreate count=1 msg=Created pod: eval-conflicts-rho010-r6-064-xj942
0.5902,Event,ADDED,eval-conflicts-rho010-r6-064.18d4670b0b28e051,reason=Completed count=1 msg=Job completed
0.5904,Event,ADDED,eval-conflicts-rho010-r6-065-ckqqc.18d46707f3a84742,reason=Scheduled count=None msg=Successfully assigned compute/eval-conflicts-rho010-r6-065-ckqqc to kind-worker4
0.5907,Event,ADDED,eval-conflicts-rho010-r6-065-ckqqc.18d467080cf7c54c,"reason=Pulled count=1 msg=Container image ""busybox:musl"" already present on machine"
0.5909,Event,ADDED,eval-conflicts-rho010-r6-065-ckqqc.18d467080e1e0794,reason=Created count=1 msg=Created container: task
0.5911,Event,ADDED,eval-conflicts-rho010-r6-065-ckqqc.18d4670813170bd5,reason=Started count=1 msg=Started container task
0.5913,Event,ADDED,eval-conflicts-rho010-r6-065.18d46707f278224d,reason=SuccessfulCreate count=1 msg=Created pod: eval-conflicts-rho010-r6-065-ckqqc
0.5915,Event,ADDED,eval-conflicts-rho010-r6-065.18d4670b59a9b20f,reason=Completed count=1 msg=Job completed
0.5917,Event,ADDED,eval-conflicts-rho010-r6-066-ms4r5.18d467082b74dd99,reason=Scheduled count=None msg=Successfully assigned compute/eval-conflicts-rho010-r6-066-ms4r5 to kind-worker
0.5918,Event,ADDED,eval-conflicts-rho010-r6-066-ms4r5.18d4670843f01697,"reason=Pulled count=1 msg=Container image ""busybox:musl"" already present on machine"
0.5921,Event,ADDED,eval-conflicts-rho010-r6-066-ms4r5.18d467084519150a,reason=Created count=1 msg=Created container: task
0.5924,Event,ADDED,eval-conflicts-rho010-r6-066-ms4r5.18d46708470532f0,reason=Started count=1 msg=Started container task
0.5926,Event,ADDED,eval-conflicts-rho010-r6-066.18d467082a9ca4d1,reason=SuccessfulCreate count=1 msg=Created pod: eval-conflicts-rho010-r6-066-ms4r5
0.5927,Event,ADDED,eval-conflicts-rho010-r6-066.18d4670b81ec3bb9,reason=Completed count=1 msg=Job completed
0.593,Event,ADDED,eval-conflicts-rho010-r6-067-qfsqh.18d467086b806eae,reason=Scheduled count=None msg=Successfully assigned compute/eval-conflicts-rho010-r6-067-qfsqh to kind-worker3
0.5932,Event,ADDED,eval-conflicts-rho010-r6-067-qfsqh.18d4670884547ec9,"reason=Pulled count=1 msg=Container image ""busybox:musl"" already present on machine"
0.5934,Event,ADDED,eval-conflicts-rho010-r6-067-qfsqh.18d467088564e383,reason=Created count=1 msg=Created container: task
0.5936,Event,ADDED,eval-conflicts-rho010-r6-067-qfsqh.18d467088bde4f4e,reason=Started count=1 msg=Started container task
0.5939,Event,ADDED,eval-conflicts-rho010-r6-067.18d467086a4cf6bf,reason=SuccessfulCreate count=1 msg=Created pod: eval-conflicts-rho010-r6-067-qfsqh
0.5941,Event,ADDED,eval-conflicts-rho010-r6-067.18d4670bb00f57ba,reason=Completed count=1 msg=Job completed
0.5942,Event,ADDED,eval-conflicts-rho010-r6-068-t85hb.18d46708a3732a5b,reason=Scheduled count=None msg=Successfully assigned compute/eval-conflicts-rho010-r6-068-t85hb to kind-worker
0.5944,Event,ADDED,eval-conflicts-rho010-r6-068-t85hb.18d46708bd99ca77,"reason=Pulled count=1 msg=Container image ""busybox:musl"" already present on machine"
0.5946,Event,ADDED,eval-conflicts-rho010-r6-068-t85hb.18d46708beb1065d,reason=Created count=1 msg=Created container: task
0.5948,Event,ADDED,eval-conflicts-rho010-r6-068-t85hb.18d46708c09562de,reason=Started count=1 msg=Started container task
0.5949,Event,ADDED,eval-conflicts-rho010-r6-068.18d46708a293f9ff,reason=SuccessfulCreate count=1 msg=Created pod: eval-conflicts-rho010-r6-068-t85hb
0.5951,Event,ADDED,eval-conflicts-rho010-r6-068.18d4670bf93f6539,reason=Completed count=1 msg=Job completed
0.5953,Event,ADDED,eval-conflicts-rho010-r6-069-fmzch.18d46708debc06a4,reason=Scheduled count=None msg=Successfully assigned compute/eval-conflicts-rho010-r6-069-fmzch to kind-worker4
0.5954,Event,ADDED,eval-conflicts-rho010-r6-069-fmzch.18d46708fdea4516,"reason=Pulled count=1 msg=Container image ""busybox:musl"" already present on machine"
0.5956,Event,ADDED,eval-conflicts-rho010-r6-069-fmzch.18d46708fefb3cd3,reason=Created count=1 msg=Created container: task
0.5958,Event,ADDED,eval-conflicts-rho010-r6-069-fmzch.18d46709010afa24,reason=Started count=1 msg=Started container task
0.596,Event,ADDED,eval-conflicts-rho010-r6-069.18d46708dd92299e,reason=SuccessfulCreate count=1 msg=Created pod: eval-conflicts-rho010-r6-069-fmzch
0.5963,Event,ADDED,eval-conflicts-rho010-r6-069.18d4670c0cbc5b06,reason=Completed count=1 msg=Job completed
0.5965,Event,ADDED,eval-conflicts-rho010-r6-070-9tgbq.18d467091a4afe6a,reason=Scheduled count=None msg=Successfully assigned compute/eval-conflicts-rho010-r6-070-9tgbq to kind-worker3
0.5967,Event,ADDED,eval-conflicts-rho010-r6-070-9tgbq.18d46709330f3aae,"reason=Pulled count=1 msg=Container image ""busybox:musl"" already present on machine"
0.5969,Event,ADDED,eval-conflicts-rho010-r6-070-9tgbq.18d4670934268662,reason=Created count=1 msg=Created container: task
0.597,Event,ADDED,eval-conflicts-rho010-r6-070-9tgbq.18d4670937a8eca2,reason=Started count=1 msg=Started container task
0.5973,Event,ADDED,eval-conflicts-rho010-r6-070.18d46709196f59ee,reason=SuccessfulCreate count=1 msg=Created pod: eval-conflicts-rho010-r6-070-9tgbq
0.5974,Event,ADDED,eval-conflicts-rho010-r6-070.18d4670c641331ee,reason=Completed count=1 msg=Job completed
0.5976,Event,ADDED,eval-conflicts-rho010-r6-071-72586.18d4670954cf97b0,"reason=FailedScheduling count=None msg=0/6 nodes are available: 6 node(s) had untolerated taint(s). no new claims to deallocate, preemption: 0/6 nodes are available: 6 Preemption is not helpful for scheduling."
0.5978,Event,ADDED,eval-conflicts-rho010-r6-071-72586.18d4670966417ef9,reason=Scheduled count=None msg=Successfully assigned compute/eval-conflicts-rho010-r6-071-72586 to kind-worker2
0.598,Event,ADDED,eval-conflicts-rho010-r6-071-72586.18d46709812936d0,"reason=Pulled count=1 msg=Container image ""busybox:musl"" already present on machine"
0.5981,Event,ADDED,eval-conflicts-rho010-r6-071-72586.18d4670982b26966,reason=Created count=1 msg=Created container: task
0.5983,Event,ADDED,eval-conflicts-rho010-r6-071-72586.18d467098a6bf20a,reason=Started count=1 msg=Started container task
0.5985,Event,ADDED,eval-conflicts-rho010-r6-071.18d4670954c6f1c2,reason=SuccessfulCreate count=1 msg=Created pod: eval-conflicts-rho010-r6-071-72586
0.5987,Event,ADDED,eval-conflicts-rho010-r6-071.18d4670cb3344334,reason=Completed count=1 msg=Job completed
0.5988,Event,ADDED,eval-conflicts-rho010-r6-072-rj89l.18d4670993933e4f,reason=Scheduled count=None msg=Successfully assigned compute/eval-conflicts-rho010-r6-072-rj89l to kind-worker2
0.599,Event,ADDED,eval-conflicts-rho010-r6-072-rj89l.18d46709b527650a,"reason=Pulled count=1 msg=Container image ""busybox:musl"" already present on machine"
0.5992,Event,ADDED,eval-conflicts-rho010-r6-072-rj89l.18d46709b64d20a1,reason=Created count=1 msg=Created container: task
0.5994,Event,ADDED,eval-conflicts-rho010-r6-072-rj89l.18d46709be160e16,reason=Started count=1 msg=Started container task
0.5996,Event,ADDED,eval-conflicts-rho010-r6-072.18d4670992f5bcc6,reason=SuccessfulCreate count=1 msg=Created pod: eval-conflicts-rho010-r6-072-rj89l
0.5998,Event,ADDED,eval-conflicts-rho010-r6-072.18d4670ceeff5101,reason=Completed count=1 msg=Job completed
0.6,Event,ADDED,eval-conflicts-rho010-r6-073-kp8bn.18d46709cfc36a3b,"reason=FailedScheduling count=None msg=0/6 nodes are available: 1 c_wall violated: 1 conflicting context pair(s) with node memory, 5 node(s) had untolerated taint(s). no new claims to deallocate, preemption: 0/6 nodes are available: 1 No preemption victims found for incoming pod, 5 Preemption is not helpful for scheduling."
0.6004,Event,ADDED,eval-conflicts-rho010-r6-073-kp8bn.18d46709d0509eb8,"reason=FailedScheduling count=None msg=0/6 nodes are available: 1 c_wall violated: 1 conflicting context pair(s) with node memory, 5 node(s) had untolerated taint(s). no new claims to deallocate, preemption: 0/6 nodes are available: 1 No preemption victims found for incoming pod, 5 Preemption is not helpful for scheduling."
0.6005,Event,ADDED,eval-conflicts-rho010-r6-073-kp8bn.18d46709d905490d,reason=Scheduled count=None msg=Successfully assigned compute/eval-conflicts-rho010-r6-073-kp8bn to kind-worker5
0.6008,Event,ADDED,eval-conflicts-rho010-r6-073-kp8bn.18d4670a0ce153e3,"reason=Pulled count=1 msg=Container image ""busybox:musl"" already present on machine"
0.6009,Event,ADDED,eval-conflicts-rho010-r6-073-kp8bn.18d4670a0e6e39a5,reason=Created count=1 msg=Created container: task
0.6011,Event,ADDED,eval-conflicts-rho010-r6-073-kp8bn.18d4670a137d94fe,reason=Started count=1 msg=Started container task
0.6016,Event,ADDED,eval-conflicts-rho010-r6-073.18d46709cf7327b5,reason=SuccessfulCreate count=1 msg=Created pod: eval-conflicts-rho010-r6-073-kp8bn
0.6017,Event,ADDED,eval-conflicts-rho010-r6-073.18d4670d2fc2ed84,reason=Completed count=1 msg=Job completed
0.6019,Event,ADDED,eval-conflicts-rho010-r6-074-l76tz.18d4670a0f9f2e27,reason=Scheduled count=None msg=Successfully assigned compute/eval-conflicts-rho010-r6-074-l76tz to kind-worker5
0.6021,Event,ADDED,eval-conflicts-rho010-r6-074-l76tz.18d4670a3e0fb581,"reason=Pulled count=1 msg=Container image ""busybox:musl"" already present on machine"
0.6023,Event,ADDED,eval-conflicts-rho010-r6-074-l76tz.18d4670a3f4321d9,reason=Created count=1 msg=Created container: task
0.6025,Event,ADDED,eval-conflicts-rho010-r6-074-l76tz.18d4670a42725b37,reason=Started count=1 msg=Started container task
0.6026,Event,ADDED,eval-conflicts-rho010-r6-074.18d4670a0ea986bd,reason=SuccessfulCreate count=1 msg=Created pod: eval-conflicts-rho010-r6-074-l76tz
0.6028,Event,ADDED,eval-conflicts-rho010-r6-074.18d4670d6b23c96f,reason=Completed count=1 msg=Job completed
0.603,Event,ADDED,eval-conflicts-rho010-r6-075-gkpnp.18d4670a446d163a,reason=Scheduled count=None msg=Successfully assigned compute/eval-conflicts-rho010-r6-075-gkpnp to kind-worker2
0.6031,Event,ADDED,eval-conflicts-rho010-r6-075-gkpnp.18d4670a5f6912eb,"reason=Pulled count=1 msg=Container image ""busybox:musl"" already present on machine"
0.6033,Event,ADDED,eval-conflicts-rho010-r6-075-gkpnp.18d4670a60c26870,reason=Created count=1 msg=Created container: task
0.6035,Event,ADDED,eval-conflicts-rho010-r6-075-gkpnp.18d4670a671fa31c,reason=Started count=1 msg=Started container task
0.6036,Event,ADDED,eval-conflicts-rho010-r6-075.18d4670a43cff4c7,reason=SuccessfulCreate count=1 msg=Created pod: eval-conflicts-rho010-r6-075-gkpnp
0.6038,Event,ADDED,eval-conflicts-rho010-r6-075.18d4670da201a974,reason=Completed count=1 msg=Job completed
0.604,Event,ADDED,eval-conflicts-rho010-r6-076-k4fbt.18d4670a829dea56,reason=Scheduled count=None msg=Successfully assigned compute/eval-conflicts-rho010-r6-076-k4fbt to kind-worker5
0.6043,Event,ADDED,eval-conflicts-rho010-r6-076-k4fbt.18d4670a9c66c14f,"reason=Pulled count=1 msg=Container image ""busybox:musl"" already present on machine"
0.6045,Event,ADDED,eval-conflicts-rho010-r6-076-k4fbt.18d4670a9d777131,reason=Created count=1 msg=Created container: task
0.6046,Event,ADDED,eval-conflicts-rho010-r6-076-k4fbt.18d4670aa2684f51,reason=Started count=1 msg=Started container task
0.6048,Event,ADDED,eval-conflicts-rho010-r6-076.18d4670a81e53241,reason=SuccessfulCreate count=1 msg=Created pod: eval-conflicts-rho010-r6-076-k4fbt
0.605,Event,ADDED,eval-conflicts-rho010-r6-076.18d4670de2a713b6,reason=Completed count=1 msg=Job completed
0.6051,Event,ADDED,eval-conflicts-rho010-r6-077-qdmd5.18d4670abb643798,reason=Scheduled count=None msg=Successfully assigned compute/eval-conflicts-rho010-r6-077-qdmd5 to kind-worker5
0.6053,Event,ADDED,eval-conflicts-rho010-r6-077-qdmd5.18d4670ad442ff49,"reason=Pulled count=1 msg=Container image ""busybox:musl"" already present on machine"
0.6055,Event,ADDED,eval-conflicts-rho010-r6-077-qdmd5.18d4670ad5596be0,reason=Created count=1 msg=Created container: task
0.6057,Event,ADDED,eval-conflicts-rho010-r6-077-qdmd5.18d4670ada30d855,reason=Started count=1 msg=Started container task
0.6058,Event,ADDED,eval-conflicts-rho010-r6-077.18d4670aba8e93e3,reason=SuccessfulCreate count=1 msg=Created pod: eval-conflicts-rho010-r6-077-qdmd5
0.606,Event,ADDED,eval-conflicts-rho010-r6-077.18d4670e1e62e3c5,reason=Completed count=1 msg=Job completed
0.6061,Event,ADDED,eval-conflicts-rho010-r6-078-r67jl.18d4670af7359cc7,reason=Scheduled count=None msg=Successfully assigned compute/eval-conflicts-rho010-r6-078-r67jl to kind-worker5
0.6063,Event,ADDED,eval-conflicts-rho010-r6-078-r67jl.18d4670b1152c532,"reason=Pulled count=1 msg=Container image ""busybox:musl"" already present on machine"
0.6065,Event,ADDED,eval-conflicts-rho010-r6-078-r67jl.18d4670b126300ce,reason=Created count=1 msg=Created container: task
0.6066,Event,ADDED,eval-conflicts-rho010-r6-078-r67jl.18d4670b1618cfc8,reason=Started count=1 msg=Started container task
0.6068,Event,ADDED,eval-conflicts-rho010-r6-078.18d4670af64eee8d,reason=SuccessfulCreate count=1 msg=Created pod: eval-conflicts-rho010-r6-078-r67jl
0.607,Event,ADDED,eval-conflicts-rho010-r6-078.18d4670e5a067683,reason=Completed count=1 msg=Job completed
0.6071,Event,ADDED,eval-conflicts-rho010-r6-079-7wsbw.18d4670b32f52560,reason=Scheduled count=None msg=Successfully assigned compute/eval-conflicts-rho010-r6-079-7wsbw to kind-worker2
0.6073,Event,ADDED,eval-conflicts-rho010-r6-079-7wsbw.18d4670b4cce67c1,"reason=Pulled count=1 msg=Container image ""busybox:musl"" already present on machine"
0.6074,Event,ADDED,eval-conflicts-rho010-r6-079-7wsbw.18d4670b4df1d138,reason=Created count=1 msg=Created container: task
0.6076,Event,ADDED,eval-conflicts-rho010-r6-079-7wsbw.18d4670b4feeff6b,reason=Started count=1 msg=Started container task
0.6078,Event,ADDED,eval-conflicts-rho010-r6-079.18d4670b320ba8fa,reason=SuccessfulCreate count=1 msg=Created pod: eval-conflicts-rho010-r6-079-7wsbw
0.6081,Event,ADDED,eval-conflicts-rho010-r6-079.18d4670e911dc5a2,reason=Completed count=1 msg=Job completed
0.6083,Event,ADDED,eval-conflicts-rho010-r6-080-k284m.18d4670b6ec0f8f0,reason=Scheduled count=None msg=Successfully assigned compute/eval-conflicts-rho010-r6-080-k284m to kind-worker2
0.6085,Event,ADDED,eval-conflicts-rho010-r6-080-k284m.18d4670b888e3445,"reason=Pulled count=1 msg=Container image ""busybox:musl"" already present on machine"
0.6088,Event,ADDED,eval-conflicts-rho010-r6-080-k284m.18d4670b899fd5a3,reason=Created count=1 msg=Created container: task
0.609,Event,ADDED,eval-conflicts-rho010-r6-080-k284m.18d4670b8b989443,reason=Started count=1 msg=Started container task
0.6091,Event,ADDED,eval-conflicts-rho010-r6-080.18d4670b6e07d268,reason=SuccessfulCreate count=1 msg=Created pod: eval-conflicts-rho010-r6-080-k284m
0.6093,Event,ADDED,eval-conflicts-rho010-r6-080.18d4670eccc02d44,reason=Completed count=1 msg=Job completed
0.6096,Event,ADDED,eval-conflicts-rho010-r6-081-l4cc4.18d4670ba99090fd,reason=Scheduled count=None msg=Successfully assigned compute/eval-conflicts-rho010-r6-081-l4cc4 to kind-worker5
0.6098,Event,ADDED,eval-conflicts-rho010-r6-081-l4cc4.18d4670bc283763b,"reason=Pulled count=1 msg=Container image ""busybox:musl"" already present on machine"
0.61,Event,ADDED,eval-conflicts-rho010-r6-081-l4cc4.18d4670bc39804f0,reason=Created count=1 msg=Created container: task
0.6103,Event,ADDED,eval-conflicts-rho010-r6-081-l4cc4.18d4670bc595ea8a,reason=Started count=1 msg=Started container task
0.6104,Event,ADDED,eval-conflicts-rho010-r6-081.18d4670ba8ca1435,reason=SuccessfulCreate count=1 msg=Created pod: eval-conflicts-rho010-r6-081-l4cc4
0.6106,Event,ADDED,eval-conflicts-rho010-r6-081.18d4670f0d84adb3,reason=Completed count=1 msg=Job completed
0.6108,Event,ADDED,eval-conflicts-rho010-r6-082-hpvds.18d4670be4fb3290,reason=Scheduled count=None msg=Successfully assigned compute/eval-conflicts-rho010-r6-082-hpvds to kind-worker4
0.6109,Event,ADDED,eval-conflicts-rho010-r6-082-hpvds.18d4670bfe410bb8,"reason=Pulled count=1 msg=Container image ""busybox:musl"" already present on machine"
0.6111,Event,ADDED,eval-conflicts-rho010-r6-082-hpvds.18d4670bff6770f0,reason=Created count=1 msg=Created container: task
0.6113,Event,ADDED,eval-conflicts-rho010-r6-082-hpvds.18d4670c015ea890,reason=Started count=1 msg=Started container task
0.6115,Event,ADDED,eval-conflicts-rho010-r6-082.18d4670be447fac3,reason=SuccessfulCreate count=1 msg=Created pod: eval-conflicts-rho010-r6-082-hpvds
0.6117,Event,ADDED,eval-conflicts-rho010-r6-082.18d4670f15fcb64d,reason=Completed count=1 msg=Job completed
0.6118,Event,ADDED,eval-conflicts-rho010-r6-083-glgsd.18d4670c2120f7d9,reason=Scheduled count=None msg=Successfully assigned compute/eval-conflicts-rho010-r6-083-glgsd to kind-worker4
0.6121,Event,ADDED,eval-conflicts-rho010-r6-083-glgsd.18d4670c39ea3631,"reason=Pulled count=1 msg=Container image ""busybox:musl"" already present on machine"
0.6126,Event,ADDED,eval-conflicts-rho010-r6-083-glgsd.18d4670c3b1f06cc,reason=Created count=1 msg=Created container: task
0.6128,Event,ADDED,eval-conflicts-rho010-r6-083-glgsd.18d4670c42e5284b,reason=Started count=1 msg=Started container task
0.613,Event,ADDED,eval-conflicts-rho010-r6-083.18d4670c205ce503,reason=SuccessfulCreate count=1 msg=Created pod: eval-conflicts-rho010-r6-083-glgsd
0.6132,Event,ADDED,eval-conflicts-rho010-r6-083.18d4670f5241efb1,reason=Completed count=1 msg=Job completed
0.6135,Event,ADDED,eval-conflicts-rho010-r6-084-6bz6b.18d4670c5cf8c24c,reason=Scheduled count=None msg=Successfully assigned compute/eval-conflicts-rho010-r6-084-6bz6b to kind-worker4
0.6137,Event,ADDED,eval-conflicts-rho010-r6-084-6bz6b.18d4670c76abdefb,"reason=Pulled count=1 msg=Container image ""busybox:musl"" already present on machine"
0.6143,Event,ADDED,eval-conflicts-rho010-r6-084-6bz6b.18d4670c78169569,reason=Created count=1 msg=Created container: task
0.6147,Event,ADDED,eval-conflicts-rho010-r6-084-6bz6b.18d4670c7c32fa98,reason=Started count=1 msg=Started container task
0.615,Event,ADDED,eval-conflicts-rho010-r6-084.18d4670c5c688d32,reason=SuccessfulCreate count=1 msg=Created pod: eval-conflicts-rho010-r6-084-6bz6b
0.6152,Event,ADDED,eval-conflicts-rho010-r6-084.18d4670fca2ac2b4,reason=Completed count=1 msg=Job completed
0.6153,Event,ADDED,eval-conflicts-rho010-r6-085-82gpl.18d4670c99aa2242,reason=Scheduled count=None msg=Successfully assigned compute/eval-conflicts-rho010-r6-085-82gpl to kind-worker4
0.6157,Event,ADDED,eval-conflicts-rho010-r6-085-82gpl.18d4670cb3b968e1,"reason=Pulled count=1 msg=Container image ""busybox:musl"" already present on machine"
0.6158,Event,ADDED,eval-conflicts-rho010-r6-085-82gpl.18d4670cb5091fdf,reason=Created count=1 msg=Created container: task
0.6161,Event,ADDED,eval-conflicts-rho010-r6-085-82gpl.18d4670cbc6aaaef,reason=Started count=1 msg=Started container task
0.6163,Event,ADDED,eval-conflicts-rho010-r6-085.18d4670c99124b79,reason=SuccessfulCreate count=1 msg=Created pod: eval-conflicts-rho010-r6-085-82gpl
0.6167,Event,ADDED,eval-conflicts-rho010-r6-085.18d4671005d1d15f,reason=Completed count=1 msg=Job completed
0.6169,Event,ADDED,eval-conflicts-rho010-r6-086-tr457.18d4670cd381a1ee,reason=Scheduled count=None msg=Successfully assigned compute/eval-conflicts-rho010-r6-086-tr457 to kind-worker4
0.6171,Event,ADDED,eval-conflicts-rho010-r6-086-tr457.18d4670cecbe8679,"reason=Pulled count=1 msg=Container image ""busybox:musl"" already present on machine"
0.6176,Event,ADDED,eval-conflicts-rho010-r6-086-tr457.18d4670cedf39fc7,reason=Created count=1 msg=Created container: task
0.6177,Event,ADDED,eval-conflicts-rho010-r6-086-tr457.18d4670cf1f8fb40,reason=Started count=1 msg=Started container task
0.6179,Event,ADDED,eval-conflicts-rho010-r6-086.18d4670cd2fb5d31,reason=SuccessfulCreate count=1 msg=Created pod: eval-conflicts-rho010-r6-086-tr457
0.6181,Event,ADDED,eval-conflicts-rho010-r6-086.18d46710068ac5cb,reason=Completed count=1 msg=Job completed
0.6185,Event,ADDED,eval-conflicts-rho010-r6-087-9fpkf.18d4670d0f38f9c0,reason=Scheduled count=None msg=Successfully assigned compute/eval-conflicts-rho010-r6-087-9fpkf to kind-worker4
0.6187,Event,ADDED,eval-conflicts-rho010-r6-087-9fpkf.18d4670d289e43a9,"reason=Pulled count=1 msg=Container image ""busybox:musl"" already present on machine"
0.6189,Event,ADDED,eval-conflicts-rho010-r6-087-9fpkf.18d4670d29bf488e,reason=Created count=1 msg=Created container: task
0.6192,Event,ADDED,eval-conflicts-rho010-r6-087-9fpkf.18d4670d2bc1dc0f,reason=Started count=1 msg=Started container task
0.6194,Event,ADDED,eval-conflicts-rho010-r6-087.18d4670d0ea4d295,reason=SuccessfulCreate count=1 msg=Created pod: eval-conflicts-rho010-r6-087-9fpkf
0.6196,Event,ADDED,eval-conflicts-rho010-r6-087.18d4671042163abe,reason=Completed count=1 msg=Job completed
0.6198,Event,ADDED,eval-conflicts-rho010-r6-088-7pt2q.18d4670d4a9800ea,reason=Scheduled count=None msg=Successfully assigned compute/eval-conflicts-rho010-r6-088-7pt2q to kind-worker4
0.6202,Event,ADDED,eval-conflicts-rho010-r6-088-7pt2q.18d4670d63b42f7f,"reason=Pulled count=1 msg=Container image ""busybox:musl"" already present on machine"
0.6205,Event,ADDED,eval-conflicts-rho010-r6-088-7pt2q.18d4670d64d52624,reason=Created count=1 msg=Created container: task
0.6208,Event,ADDED,eval-conflicts-rho010-r6-088-7pt2q.18d4670d66d1728e,reason=Started count=1 msg=Started container task
0.6211,Event,ADDED,eval-conflicts-rho010-r6-088.18d4670d4a11f860,reason=SuccessfulCreate count=1 msg=Created pod: eval-conflicts-rho010-r6-088-7pt2q
0.6215,Event,ADDED,eval-conflicts-rho010-r6-088.18d467107de97fa6,reason=Completed count=1 msg=Job completed
0.6217,Event,ADDED,eval-conflicts-rho010-r6-089-849bt.18d4670d86411f84,reason=Scheduled count=None msg=Successfully assigned compute/eval-conflicts-rho010-r6-089-849bt to kind-worker4
0.6219,Event,ADDED,eval-conflicts-rho010-r6-089-849bt.18d4670d9eb2d812,"reason=Pulled count=1 msg=Container image ""busybox:musl"" already present on machine"
0.6223,Event,ADDED,eval-conflicts-rho010-r6-089-849bt.18d4670d9fd40f82,reason=Created count=1 msg=Created container: task
0.6225,Event,ADDED,eval-conflicts-rho010-r6-089-849bt.18d4670da38ad8a2,reason=Started count=1 msg=Started container task
0.6227,Event,ADDED,eval-conflicts-rho010-r6-089.18d4670d85ac7272,reason=SuccessfulCreate count=1 msg=Created pod: eval-conflicts-rho010-r6-089-849bt
0.6229,Event,ADDED,eval-conflicts-rho010-r6-089.18d46710b9d1b3b5,reason=Completed count=1 msg=Job completed
0.6232,Event,ADDED,eval-conflicts-rho010-r6-090-zp2zm.18d4670dc21cb137,reason=Scheduled count=None msg=Successfully assigned compute/eval-conflicts-rho010-r6-090-zp2zm to kind-worker
0.6234,Event,ADDED,eval-conflicts-rho010-r6-090-zp2zm.18d4670ddb1f14ff,"reason=Pulled count=1 msg=Container image ""busybox:musl"" already present on machine"
0.6235,Event,ADDED,eval-conflicts-rho010-r6-090-zp2zm.18d4670ddc29d515,reason=Created count=1 msg=Created container: task
0.6237,Event,ADDED,eval-conflicts-rho010-r6-090-zp2zm.18d4670dde16bbb1,reason=Started count=1 msg=Started container task
0.6241,Event,ADDED,eval-conflicts-rho010-r6-090.18d4670dc11d9aff,reason=SuccessfulCreate count=1 msg=Created pod: eval-conflicts-rho010-r6-090-zp2zm
0.6243,Event,ADDED,eval-conflicts-rho010-r6-090.18d467111c8e82f2,reason=Completed count=1 msg=Job completed
0.6245,Event,ADDED,eval-conflicts-rho010-r6-091-p44sq.18d4670dfe02e221,reason=Scheduled count=None msg=Successfully assigned compute/eval-conflicts-rho010-r6-091-p44sq to kind-worker
0.6248,Event,ADDED,eval-conflicts-rho010-r6-091-p44sq.18d4670e17509e26,"reason=Pulled count=1 msg=Container image ""busybox:musl"" already present on machine"
0.6249,Event,ADDED,eval-conflicts-rho010-r6-091-p44sq.18d4670e189285aa,reason=Created count=1 msg=Created container: task
0.6251,Event,ADDED,eval-conflicts-rho010-r6-091-p44sq.18d4670e24331259,reason=Started count=1 msg=Started container task
0.6253,Event,ADDED,eval-conflicts-rho010-r6-091.18d4670dfcfa5300,reason=SuccessfulCreate count=1 msg=Created pod: eval-conflicts-rho010-r6-091-p44sq
0.6257,Event,ADDED,eval-conflicts-rho010-r6-091.18d4671158724e35,reason=Completed count=1 msg=Job completed
0.6258,Event,ADDED,eval-conflicts-rho010-r6-092-wktdc.18d4670e390e9060,reason=Scheduled count=None msg=Successfully assigned compute/eval-conflicts-rho010-r6-092-wktdc to kind-worker
0.626,Event,ADDED,eval-conflicts-rho010-r6-092-wktdc.18d4670e52824105,"reason=Pulled count=1 msg=Container image ""busybox:musl"" already present on machine"
0.6265,Event,ADDED,eval-conflicts-rho010-r6-092-wktdc.18d4670e539d47cf,reason=Created count=1 msg=Created container: task
0.6266,Event,ADDED,eval-conflicts-rho010-r6-092-wktdc.18d4670e5a6b862e,reason=Started count=1 msg=Started container task
0.6268,Event,ADDED,eval-conflicts-rho010-r6-092.18d4670e385a5c9f,reason=SuccessfulCreate count=1 msg=Created pod: eval-conflicts-rho010-r6-092-wktdc
0.627,Event,ADDED,eval-conflicts-rho010-r6-092.18d46711942730d1,reason=Completed count=1 msg=Job completed
0.6273,Event,ADDED,eval-conflicts-rho010-r6-093-7vh5l.18d4670e750d0bed,reason=Scheduled count=None msg=Successfully assigned compute/eval-conflicts-rho010-r6-093-7vh5l to kind-worker
0.6275,Event,ADDED,eval-conflicts-rho010-r6-093-7vh5l.18d4670e8f3d942b,"reason=Pulled count=1 msg=Container image ""busybox:musl"" already present on machine"
0.6276,Event,ADDED,eval-conflicts-rho010-r6-093-7vh5l.18d4670e908d51ad,reason=Created count=1 msg=Created container: task
0.6278,Event,ADDED,eval-conflicts-rho010-r6-093-7vh5l.18d4670e9d1b071e,reason=Started count=1 msg=Started container task
0.6282,Event,ADDED,eval-conflicts-rho010-r6-093.18d4670e74495323,reason=SuccessfulCreate count=1 msg=Created pod: eval-conflicts-rho010-r6-093-7vh5l
0.6284,Event,ADDED,eval-conflicts-rho010-r6-093.18d46711d06662a1,reason=Completed count=1 msg=Job completed
0.6285,Event,ADDED,eval-conflicts-rho010-r6-094-jcjqs.18d4670eb1095881,reason=Scheduled count=None msg=Successfully assigned compute/eval-conflicts-rho010-r6-094-jcjqs to kind-worker3
0.6288,Event,ADDED,eval-conflicts-rho010-r6-094-jcjqs.18d4670ece31c455,"reason=Pulled count=1 msg=Container image ""busybox:musl"" already present on machine"
0.629,Event,ADDED,eval-conflicts-rho010-r6-094-jcjqs.18d4670ecf61d380,reason=Created count=1 msg=Created container: task
0.6294,Event,ADDED,eval-conflicts-rho010-r6-094-jcjqs.18d4670ed92a8422,reason=Started count=1 msg=Started container task
0.6297,Event,ADDED,eval-conflicts-rho010-r6-094.18d4670eb0566c6c,reason=SuccessfulCreate count=1 msg=Created pod: eval-conflicts-rho010-r6-094-jcjqs
0.63,Event,ADDED,eval-conflicts-rho010-r6-094.18d46711fdd7df57,reason=Completed count=1 msg=Job completed
0.6302,Event,ADDED,eval-conflicts-rho010-r6-095-gkljn.18d4670eeccc3b28,reason=Scheduled count=None msg=Successfully assigned compute/eval-conflicts-rho010-r6-095-gkljn to kind-worker
0.6304,Event,ADDED,eval-conflicts-rho010-r6-095-gkljn.18d4670f06b613aa,"reason=Pulled count=1 msg=Container image ""busybox:musl"" already present on machine"
0.6306,Event,ADDED,eval-conflicts-rho010-r6-095-gkljn.18d4670f08031423,reason=Created count=1 msg=Created container: task
