t_recv,kind,type,name,detail
0.0218,Node,ADDED,kind-control-plane,taints=1
0.0253,Node,ADDED,kind-worker,taints=0
0.0267,Node,ADDED,kind-worker2,taints=0
0.027,TaskRequest,ADDED,eval-conflicts-rho030-r1-000,phase=None job=None
0.0284,Node,ADDED,kind-worker3,taints=0
0.0297,Node,ADDED,kind-worker4,taints=0
0.031,Node,ADDED,kind-worker5,taints=0
0.0531,Event,ADDED,eval-conflicts-rho005-r0-019-4hkwr.18d464fe7e22dffc,"reason=FailedScheduling count=None msg=0/6 nodes are available: 1 c_wall violated: 1 conflicting context pair(s) with node memory, 5 node(s) had untolerated taint(s). no new claims to deallocate, preemption: 0/6 nodes are available: 1 No preemption victims found for incoming pod, 5 Preemption is not helpful for scheduling."
0.0536,Event,ADDED,eval-conflicts-rho005-r0-023-fjlcb.18d464ff709d92ad,"reason=FailedScheduling count=None msg=0/6 nodes are available: 1 c_wall violated: 1 conflicting context pair(s) with node memory, 5 node(s) had untolerated taint(s). no new claims to deallocate, preemption: 0/6 nodes are available: 1 No preemption victims found for incoming pod, 5 Preemption is not helpful for scheduling."
0.0538,Event,ADDED,eval-conflicts-rho005-r0-027-ds6bj.18d4650060790d9c,"reason=FailedScheduling count=None msg=0/6 nodes are available: 1 c_wall violated: 1 conflicting context pair(s) with node memory, 5 node(s) had untolerated taint(s). no new claims to deallocate, preemption: 0/6 nodes are available: 1 No preemption victims found for incoming pod, 5 Preemption is not helpful for scheduling."
0.054,Event,ADDED,eval-conflicts-rho005-r0-027-ds6bj.18d4650097d065c8,"reason=FailedScheduling count=None msg=0/6 nodes are available: 1 c_wall violated: 2 conflicting context pair(s) with node memory, 5 node(s) had untolerated taint(s). no new claims to deallocate, preemption: 0/6 nodes are available: 1 No preemption victims found for incoming pod, 5 Preemption is not helpful for scheduling."
0.0542,Event,ADDED,eval-conflicts-rho005-r0-077-jdd6h.18d4650bfe9e23e5,"reason=FailedScheduling count=None msg=0/6 nodes are available: 1 c_wall violated: 1 conflicting context pair(s) with node memory, 5 node(s) had untolerated taint(s). no new claims to deallocate, preemption: 0/6 nodes are available: 1 No preemption victims found for incoming pod, 5 Preemption is not helpful for scheduling."
0.0544,Event,ADDED,eval-conflicts-rho005-r0-080-6nt5s.18d4650cb1847a32,"reason=FailedScheduling count=None msg=0/6 nodes are available: 1 c_wall violated: 1 conflicting context pair(s) with node memory, 5 node(s) had untolerated taint(s). no new claims to deallocate, preemption: 0/6 nodes are available: 1 No preemption victims found for incoming pod, 5 Preemption is not helpful for scheduling."
0.0546,Event,ADDED,eval-conflicts-rho005-r0-091-czqms.18d4650f411bd9bc,"reason=FailedScheduling count=None msg=0/6 nodes are available: 1 c_wall violated: 2 conflicting context pair(s) with node memory, 5 node(s) had untolerated taint(s). no new claims to deallocate, preemption: 0/6 nodes are available: 1 No preemption victims found for incoming pod, 5 Preemption is not helpful for scheduling."
0.0548,Event,ADDED,eval-conflicts-rho005-r0-094-24qhz.18d465101d004dbe,"reason=FailedScheduling count=None msg=0/6 nodes are available: 1 c_wall violated: 1 conflicting context pair(s) with node memory, 5 node(s) had untolerated taint(s). no new claims to deallocate, preemption: 0/6 nodes are available: 1 No preemption victims found for incoming pod, 5 Preemption is not helpful for scheduling."
0.0551,Event,ADDED,eval-conflicts-rho005-r0-095-5q8h6.18d465102fdee5c6,"reason=FailedScheduling count=None msg=0/6 nodes are available: 1 c_wall violated: 1 conflicting context pair(s) with node memory, 5 node(s) had untolerated taint(s). no new claims to deallocate, preemption: 0/6 nodes are available: 1 No preemption victims found for incoming pod, 5 Preemption is not helpful for scheduling."
0.0554,Event,ADDED,eval-conflicts-rho005-r1-013-sqxsc.18d4651ced1c9355,"reason=FailedScheduling count=None msg=0/6 nodes are available: 1 c_wall violated: 2 conflicting context pair(s) with node memory, 5 node(s) had untolerated taint(s). no new claims to deallocate, preemption: 0/6 nodes are available: 1 No preemption victims found for incoming pod, 5 Preemption is not helpful for scheduling."
0.0556,Event,ADDED,eval-conflicts-rho005-r1-023-lpr7p.18d4651f01272de5,"reason=FailedScheduling count=None msg=0/6 nodes are available: 1 c_wall violated: 1 conflicting context pair(s) with node memory, 5 node(s) had untolerated taint(s). no new claims to deallocate, preemption: 0/6 nodes are available: 1 No preemption victims found for incoming pod, 5 Preemption is not helpful for scheduling."
0.0558,Event,ADDED,eval-conflicts-rho005-r1-082-2glzb.18d4652cbf68e63a,"reason=FailedScheduling count=None msg=0/6 nodes are available: 2 c_wall violated: 1 conflicting context pair(s) with node memory, 4 node(s) had untolerated taint(s). no new claims to deallocate, preemption: 0/6 nodes are available: 2 No preemption victims found for incoming pod, 4 Preemption is not helpful for scheduling."
0.056,Event,ADDED,eval-conflicts-rho005-r1-082-2glzb.18d4652cef51ad4f,"reason=FailedScheduling count=None msg=0/6 nodes are available: 1 c_wall violated: 1 conflicting context pair(s) with node memory, 5 node(s) had untolerated taint(s). no new claims to deallocate, preemption: 0/6 nodes are available: 1 No preemption victims found for incoming pod, 5 Preemption is not helpful for scheduling."
0.0562,Event,ADDED,eval-conflicts-rho005-r2-017-pzs87.18d4653d040bc466,"reason=FailedScheduling count=None msg=0/6 nodes are available: 1 c_wall violated: 1 conflicting context pair(s) with node memory, 5 node(s) had untolerated taint(s). no new claims to deallocate, preemption: 0/6 nodes are available: 1 No preemption victims found for incoming pod, 5 Preemption is not helpful for scheduling."
0.0564,Event,ADDED,eval-conflicts-rho005-r2-065-c77cv.18d4654835a3f952,"reason=FailedScheduling count=None msg=0/6 nodes are available: 2 c_wall violated: 1 conflicting context pair(s) with node memory, 4 node(s) had untolerated taint(s). no new claims to deallocate, preemption: 0/6 nodes are available: 2 No preemption victims found for incoming pod, 4 Preemption is not helpful for scheduling."
0.0565,Event,ADDED,eval-conflicts-rho005-r3-021-zjnpj.18d4655d373b5512,"reason=FailedScheduling count=None msg=0/6 nodes are available: 1 c_wall violated: 2 conflicting context pair(s) with node memory, 5 node(s) had untolerated taint(s). no new claims to deallocate, preemption: 0/6 nodes are available: 1 No preemption victims found for incoming pod, 5 Preemption is not helpful for scheduling."
0.0567,Event,ADDED,eval-conflicts-rho005-r3-025-gfltv.18d4655dd57e298f,"reason=FailedScheduling count=None msg=0/6 nodes are available: 1 c_wall violated: 1 conflicting context pair(s) with node memory, 5 node(s) had untolerated taint(s). no new claims to deallocate, preemption: 0/6 nodes are available: 1 No preemption victims found for incoming pod, 5 Preemption is not helpful for scheduling."
0.0569,Event,ADDED,eval-conflicts-rho005-r3-041-76kch.18d465618ebbf5cf,"reason=FailedScheduling count=None msg=0/6 nodes are available: 1 c_wall violated: 1 conflicting context pair(s) with node memory, 5 node(s) had untolerated taint(s). no new claims to deallocate, preemption: 0/6 nodes are available: 1 No preemption victims found for incoming pod, 5 Preemption is not helpful for scheduling."
0.0571,Event,ADDED,eval-conflicts-rho005-r3-053-dtc6p.18d4656459896248,"reason=FailedScheduling count=None msg=0/6 nodes are available: 1 c_wall violated: 1 conflicting context pair(s) with node memory, 1 c_wall violated: 2 conflicting context pair(s) with node memory, 4 node(s) had untolerated taint(s). no new claims to deallocate, preemption: 0/6 nodes are available: 2 No preemption victims found for incoming pod, 4 Preemption is not helpful for scheduling."
0.0574,Event,ADDED,eval-conflicts-rho005-r3-070-5q8nk.18d465684ecee5c7,"reason=FailedScheduling count=None msg=0/6 nodes are available: 1 c_wall violated: 1 conflicting context pair(s) with node memory, 5 node(s) had untolerated taint(s). no new claims to deallocate, preemption: 0/6 nodes are available: 1 No preemption victims found for incoming pod, 5 Preemption is not helpful for scheduling."
0.0578,Event,ADDED,eval-conflicts-rho005-r3-071-qtz8z.18d465688b0e45c1,"reason=FailedScheduling count=None msg=0/6 nodes are available: 1 c_wall violated: 1 conflicting context pair(s) with node memory, 5 node(s) had untolerated taint(s). no new claims to deallocate, preemption: 0/6 nodes are available: 1 No preemption victims found for incoming pod, 5 Preemption is not helpful for scheduling."
0.0581,Event,ADDED,eval-conflicts-rho005-r3-076-4wlnv.18d46569b7d7cb38,"reason=FailedScheduling count=None msg=0/6 nodes are available: 1 c_wall violated: 1 conflicting context pair(s) with node memory, 5 node(s) had untolerated taint(s). no new claims to deallocate, preemption: 0/6 nodes are available: 1 No preemption victims found for incoming pod, 5 Preemption is not helpful for scheduling."
0.0583,Event,ADDED,eval-conflicts-rho005-r4-097-f7hx7.18d4658e7a96f91e,"reason=FailedScheduling count=None msg=0/6 nodes are available: 1 c_wall violated: 2 conflicting context pair(s) with node memory, 5 node(s) had untolerated taint(s). no new claims to deallocate, preemption: 0/6 nodes are available: 1 No preemption victims found for incoming pod, 5 Preemption is not helpful for scheduling."
0.0586,Event,ADDED,eval-conflicts-rho005-r5-000-s8nwz.18d4659723eb690d,reason=Scheduled count=None msg=Successfully assigned compute/eval-conflicts-rho005-r5-000-s8nwz to kind-worker
0.0588,Event,ADDED,eval-conflicts-rho005-r5-000-s8nwz.18d465973dabc813,"reason=Pulled count=1 msg=Container image ""busybox:musl"" already present on machine"
0.059,Event,ADDED,eval-conflicts-rho005-r5-000-s8nwz.18d465973ef9c235,reason=Created count=1 msg=Created container: task
0.0592,Event,ADDED,eval-conflicts-rho005-r5-000-s8nwz.18d4659741649a7e,reason=Started count=1 msg=Started container task
0.0594,Event,ADDED,eval-conflicts-rho005-r5-000.18d46597230b4d9e,reason=SuccessfulCreate count=1 msg=Created pod: eval-conflicts-rho005-r5-000-s8nwz
0.0595,Event,ADDED,eval-conflicts-rho005-r5-000.18d4659a7f77243f,reason=Completed count=1 msg=Job completed
0.0597,Event,ADDED,eval-conflicts-rho005-r5-001-l94ms.18d465975e6aaa00,reason=Scheduled count=None msg=Successfully assigned compute/eval-conflicts-rho005-r5-001-l94ms to kind-worker
0.06,Event,ADDED,eval-conflicts-rho005-r5-001-l94ms.18d46597792b2889,"reason=Pulled count=1 msg=Container image ""busybox:musl"" already present on machine"
0.0602,Event,ADDED,eval-conflicts-rho005-r5-001-l94ms.18d465977a50ec19,reason=Created count=1 msg=Created container: task
0.0604,Event,ADDED,eval-conflicts-rho005-r5-001-l94ms.18d465977c60200b,reason=Started count=1 msg=Started container task
0.0605,Event,ADDED,eval-conflicts-rho005-r5-001.18d465975d67dfa3,reason=SuccessfulCreate count=1 msg=Created pod: eval-conflicts-rho005-r5-001-l94ms
0.0607,Event,ADDED,eval-conflicts-rho005-r5-001.18d4659abb0667e4,reason=Completed count=1 msg=Job completed
0.0609,Event,ADDED,eval-conflicts-rho005-r5-002-vlbqs.18d465979950ae70,reason=Scheduled count=None msg=Successfully assigned compute/eval-conflicts-rho005-r5-002-vlbqs to kind-worker2
0.0612,Event,ADDED,eval-conflicts-rho005-r5-002-vlbqs.18d46597b1f88552,"reason=Pulled count=1 msg=Container image ""busybox:musl"" already present on machine"
0.0614,Event,ADDED,eval-conflicts-rho005-r5-002-vlbqs.18d46597b310d00c,reason=Created count=1 msg=Created container: task
0.0615,Event,ADDED,eval-conflicts-rho005-r5-002-vlbqs.18d46597b71317dc,reason=Started count=1 msg=Started container task
0.0617,Event,ADDED,eval-conflicts-rho005-r5-002.18d46597989d3cd2,reason=SuccessfulCreate count=1 msg=Created pod: eval-conflicts-rho005-r5-002-vlbqs
0.0619,Event,ADDED,eval-conflicts-rho005-r5-002.18d4659ae227d042,reason=Completed count=1 msg=Job completed
0.062,Event,ADDED,eval-conflicts-rho005-r5-003-68946.18d46597d642c3b3,reason=Scheduled count=None msg=Successfully assigned compute/eval-conflicts-rho005-r5-003-68946 to kind-worker5
0.0622,Event,ADDED,eval-conflicts-rho005-r5-003-68946.18d46597ef6e41d5,"reason=Pulled count=1 msg=Container image ""busybox:musl"" already present on machine"
0.0624,Event,ADDED,eval-conflicts-rho005-r5-003-68946.18d46597f0880207,reason=Created count=1 msg=Created container: task
0.0625,Event,ADDED,eval-conflicts-rho005-r5-003-68946.18d46597f2940d67,reason=Started count=1 msg=Started container task
0.0627,Event,ADDED,eval-conflicts-rho005-r5-003.18d46597d517dd48,reason=SuccessfulCreate count=1 msg=Created pod: eval-conflicts-rho005-r5-003-68946
0.063,Event,ADDED,eval-conflicts-rho005-r5-003.18d4659b00e713ae,reason=Completed count=1 msg=Job completed
0.0632,Event,ADDED,eval-conflicts-rho005-r5-004-wqhkq.18d4659810688fff,reason=Scheduled count=None msg=Successfully assigned compute/eval-conflicts-rho005-r5-004-wqhkq to kind-worker5
0.0633,Event,ADDED,eval-conflicts-rho005-r5-004-wqhkq.18d465982a1e7747,"reason=Pulled count=1 msg=Container image ""busybox:musl"" already present on machine"
0.0635,Event,ADDED,eval-conflicts-rho005-r5-004-wqhkq.18d465982b2eab99,reason=Created count=1 msg=Created container: task
0.0637,Event,ADDED,eval-conflicts-rho005-r5-004-wqhkq.18d465982d2c0824,reason=Started count=1 msg=Started container task
0.0639,Event,ADDED,eval-conflicts-rho005-r5-004.18d465980f699136,reason=SuccessfulCreate count=1 msg=Created pod: eval-conflicts-rho005-r5-004-wqhkq
0.0641,Event,ADDED,eval-conflicts-rho005-r5-004.18d4659b3cb7bdd5,reason=Completed count=1 msg=Job completed
0.0642,Event,ADDED,eval-conflicts-rho005-r5-005-85vvr.18d465984c5126fc,reason=Scheduled count=None msg=Successfully assigned compute/eval-conflicts-rho005-r5-005-85vvr to kind-worker5
0.0644,Event,ADDED,eval-conflicts-rho005-r5-005-85vvr.18d4659865b882d9,"reason=Pulled count=1 msg=Container image ""busybox:musl"" already present on machine"
0.0646,Event,ADDED,eval-conflicts-rho005-r5-005-85vvr.18d4659866d2cd0a,reason=Created count=1 msg=Created container: task
0.0647,Event,ADDED,eval-conflicts-rho005-r5-005-85vvr.18d465986aa7424b,reason=Started count=1 msg=Started container task
0.0649,Event,ADDED,eval-conflicts-rho005-r5-005.18d465984b86865b,reason=SuccessfulCreate count=1 msg=Created pod: eval-conflicts-rho005-r5-005-85vvr
0.0651,Event,ADDED,eval-conflicts-rho005-r5-005.18d4659b788afa93,reason=Completed count=1 msg=Job completed
0.0652,Event,ADDED,eval-conflicts-rho005-r5-006-hnzhd.18d465988731a9ae,reason=Scheduled count=None msg=Successfully assigned compute/eval-conflicts-rho005-r5-006-hnzhd to kind-worker5
0.0654,Event,ADDED,eval-conflicts-rho005-r5-006-hnzhd.18d465989fc5dc81,"reason=Pulled count=1 msg=Container image ""busybox:musl"" already present on machine"
0.0656,Event,ADDED,eval-conflicts-rho005-r5-006-hnzhd.18d46598a0eb0962,reason=Created count=1 msg=Created container: task
0.0657,Event,ADDED,eval-conflicts-rho005-r5-006-hnzhd.18d46598a30c4159,reason=Started count=1 msg=Started container task
0.0659,Event,ADDED,eval-conflicts-rho005-r5-006.18d465988673a9bd,reason=SuccessfulCreate count=1 msg=Created pod: eval-conflicts-rho005-r5-006-hnzhd
0.0661,Event,ADDED,eval-conflicts-rho005-r5-006.18d4659bb44bd17c,reason=Completed count=1 msg=Job completed
0.0662,Event,ADDED,eval-conflicts-rho005-r5-007-jrvr4.18d46598c3c5d30a,reason=Scheduled count=None msg=Successfully assigned compute/eval-conflicts-rho005-r5-007-jrvr4 to kind-worker4
0.0664,Event,ADDED,eval-conflicts-rho005-r5-007-jrvr4.18d46598dcc50b89,"reason=Pulled count=1 msg=Container image ""busybox:musl"" already present on machine"
0.0665,Event,ADDED,eval-conflicts-rho005-r5-007-jrvr4.18d46598de592801,reason=Created count=1 msg=Created container: task
0.0667,Event,ADDED,eval-conflicts-rho005-r5-007-jrvr4.18d46598e074f227,reason=Started count=1 msg=Started container task
0.0669,Event,ADDED,eval-conflicts-rho005-r5-007.18d46598c24ce715,reason=SuccessfulCreate count=1 msg=Created pod: eval-conflicts-rho005-r5-007-jrvr4
0.067,Event,ADDED,eval-conflicts-rho005-r5-007.18d4659c1bbf85e3,reason=Completed count=1 msg=Job completed
0.0672,Event,ADDED,eval-conflicts-rho005-r5-008-2c2bn.18d46598ff12862a,reason=Scheduled count=None msg=Successfully assigned compute/eval-conflicts-rho005-r5-008-2c2bn to kind-worker4
0.0674,Event,ADDED,eval-conflicts-rho005-r5-008-2c2bn.18d465991851b80f,"reason=Pulled count=1 msg=Container image ""busybox:musl"" already present on machine"
0.0675,Event,ADDED,eval-conflicts-rho005-r5-008-2c2bn.18d46599198a0cb4,reason=Created count=1 msg=Created container: task
0.0678,Event,ADDED,eval-conflicts-rho005-r5-008-2c2bn.18d465991cfa6a45,reason=Started count=1 msg=Started container task
0.068,Event,ADDED,eval-conflicts-rho005-r5-008.18d46598fe3329ed,reason=SuccessfulCreate count=1 msg=Created pod: eval-conflicts-rho005-r5-008-2c2bn
0.0681,Event,ADDED,eval-conflicts-rho005-r5-008.18d4659c57a4fd7a,reason=Completed count=1 msg=Job completed
0.0683,Event,ADDED,eval-conflicts-rho005-r5-009-srgwg.18d465993a93ac77,reason=Scheduled count=None msg=Successfully assigned compute/eval-conflicts-rho005-r5-009-srgwg to kind-worker4
0.0685,Event,ADDED,eval-conflicts-rho005-r5-009-srgwg.18d46599543b6378,"reason=Pulled count=1 msg=Container image ""busybox:musl"" already present on machine"
0.0687,Event,ADDED,eval-conflicts-rho005-r5-009-srgwg.18d46599555d922a,reason=Created count=1 msg=Created container: task
0.0688,Event,ADDED,eval-conflicts-rho005-r5-009-srgwg.18d465995767d6b4,reason=Started count=1 msg=Started container task
0.069,Event,ADDED,eval-conflicts-rho005-r5-009.18d4659939d2f5fe,reason=SuccessfulCreate count=1 msg=Created pod: eval-conflicts-rho005-r5-009-srgwg
0.0692,Event,ADDED,eval-conflicts-rho005-r5-009.18d4659c93c0509b,reason=Completed count=1 msg=Job completed
0.0693,Event,ADDED,eval-conflicts-rho005-r5-010-kcfbr.18d4659975dc6e0b,reason=Scheduled count=None msg=Successfully assigned compute/eval-conflicts-rho005-r5-010-kcfbr to kind-worker3
0.0695,Event,ADDED,eval-conflicts-rho005-r5-010-kcfbr.18d465998f9949f1,"reason=Pulled count=1 msg=Container image ""busybox:musl"" already present on machine"
0.0696,Event,ADDED,eval-conflicts-rho005-r5-010-kcfbr.18d4659990c6529f,reason=Created count=1 msg=Created container: task
0.0698,Event,ADDED,eval-conflicts-rho005-r5-010-kcfbr.18d4659992e910d8,reason=Started count=1 msg=Started container task
0.07,Event,ADDED,eval-conflicts-rho005-r5-010.18d4659974decfd7,reason=SuccessfulCreate count=1 msg=Created pod: eval-conflicts-rho005-r5-010-kcfbr
0.0701,Event,ADDED,eval-conflicts-rho005-r5-010.18d4659cc83d1b5c,reason=Completed count=1 msg=Job completed
0.0703,Event,ADDED,eval-conflicts-rho005-r5-011-dth2t.18d46599b26929ff,reason=Scheduled count=None msg=Successfully assigned compute/eval-conflicts-rho005-r5-011-dth2t to kind-worker4
0.0704,Event,ADDED,eval-conflicts-rho005-r5-011-dth2t.18d46599cb9429e9,"reason=Pulled count=1 msg=Container image ""busybox:musl"" already present on machine"
0.0706,Event,ADDED,eval-conflicts-rho005-r5-011-dth2t.18d46599ccabb0d8,reason=Created count=1 msg=Created container: task
0.0708,Event,ADDED,eval-conflicts-rho005-r5-011-dth2t.18d46599d04e05ae,reason=Started count=1 msg=Started container task
0.0709,Event,ADDED,eval-conflicts-rho005-r5-011.18d46599b12aa9fd,reason=SuccessfulCreate count=1 msg=Created pod: eval-conflicts-rho005-r5-011-dth2t
0.0711,Event,ADDED,eval-conflicts-rho005-r5-011.18d4659d0b99b490,reason=Completed count=1 msg=Job completed
0.0713,Event,ADDED,eval-conflicts-rho005-r5-012-5g62s.18d46599ed376f09,reason=Scheduled count=None msg=Successfully assigned compute/eval-conflicts-rho005-r5-012-5g62s to kind-worker3
0.0714,Event,ADDED,eval-conflicts-rho005-r5-012-5g62s.18d4659a0580ad66,"reason=Pulled count=1 msg=Container image ""busybox:musl"" already present on machine"
0.0716,Event,ADDED,eval-conflicts-rho005-r5-012-5g62s.18d4659a069f2f62,reason=Created count=1 msg=Created container: task
0.0718,Event,ADDED,eval-conflicts-rho005-r5-012-5g62s.18d4659a08ad46aa,reason=Started count=1 msg=Started container task
0.0719,Event,ADDED,eval-conflicts-rho005-r5-012.18d46599ec358226,reason=SuccessfulCreate count=1 msg=Created pod: eval-conflicts-rho005-r5-012-5g62s
0.0721,Event,ADDED,eval-conflicts-rho005-r5-012.18d4659d4022ca58,reason=Completed count=1 msg=Job completed
0.0722,Event,ADDED,eval-conflicts-rho005-r5-013-wdttc.18d4659a2925d1da,reason=Scheduled count=None msg=Successfully assigned compute/eval-conflicts-rho005-r5-013-wdttc to kind-worker3
0.0724,Event,ADDED,eval-conflicts-rho005-r5-013-wdttc.18d4659a42b71077,"reason=Pulled count=1 msg=Container image ""busybox:musl"" already present on machine"
0.0726,Event,ADDED,eval-conflicts-rho005-r5-013-wdttc.18d4659a443531a0,reason=Created count=1 msg=Created container: task
0.0727,Event,ADDED,eval-conflicts-rho005-r5-013-wdttc.18d4659a4e57e1a3,reason=Started count=1 msg=Started container task
0.0729,Event,ADDED,eval-conflicts-rho005-r5-013.18d4659a28407818,reason=SuccessfulCreate count=1 msg=Created pod: eval-conflicts-rho005-r5-013-wdttc
0.0731,Event,ADDED,eval-conflicts-rho005-r5-013.18d4659d7c0d5182,reason=Completed count=1 msg=Job completed
0.0732,Event,ADDED,eval-conflicts-rho005-r5-014-vtv75.18d4659a63c1d533,reason=Scheduled count=None msg=Successfully assigned compute/eval-conflicts-rho005-r5-014-vtv75 to kind-worker3
0.0734,Event,ADDED,eval-conflicts-rho005-r5-014-vtv75.18d4659a7ca76708,"reason=Pulled count=1 msg=Container image ""busybox:musl"" already present on machine"
0.0736,Event,ADDED,eval-conflicts-rho005-r5-014-vtv75.18d4659a7daa6bd9,reason=Created count=1 msg=Created container: task
0.0737,Event,ADDED,eval-conflicts-rho005-r5-014-vtv75.18d4659a7fba7584,reason=Started count=1 msg=Started container task
0.0739,Event,ADDED,eval-conflicts-rho005-r5-014.18d4659a631d3f86,reason=SuccessfulCreate count=1 msg=Created pod: eval-conflicts-rho005-r5-014-vtv75
0.074,Event,ADDED,eval-conflicts-rho005-r5-014.18d4659db7dea73c,reason=Completed count=1 msg=Job completed
0.0742,Event,ADDED,eval-conflicts-rho005-r5-015-8tjr2.18d4659a9fde06c3,reason=Scheduled count=None msg=Successfully assigned compute/eval-conflicts-rho005-r5-015-8tjr2 to kind-worker2
0.0744,Event,ADDED,eval-conflicts-rho005-r5-015-8tjr2.18d4659ab921e76c,"reason=Pulled count=1 msg=Container image ""busybox:musl"" already present on machine"
0.0745,Event,ADDED,eval-conflicts-rho005-r5-015-8tjr2.18d4659aba555207,reason=Created count=1 msg=Created container: task
0.0747,Event,ADDED,eval-conflicts-rho005-r5-015-8tjr2.18d4659abea25747,reason=Started count=1 msg=Started container task
0.0749,Event,ADDED,eval-conflicts-rho005-r5-015.18d4659a9f41387c,reason=SuccessfulCreate count=1 msg=Created pod: eval-conflicts-rho005-r5-015-8tjr2
0.075,Event,ADDED,eval-conflicts-rho005-r5-015.18d4659deafa5eb4,reason=Completed count=1 msg=Job completed
0.0752,Event,ADDED,eval-conflicts-rho005-r5-016-xkcq8.18d4659adc237a7a,reason=Scheduled count=None msg=Successfully assigned compute/eval-conflicts-rho005-r5-016-xkcq8 to kind-worker2
0.0754,Event,ADDED,eval-conflicts-rho005-r5-016-xkcq8.18d4659af4f904e7,"reason=Pulled count=1 msg=Container image ""busybox:musl"" already present on machine"
0.0756,Event,ADDED,eval-conflicts-rho005-r5-016-xkcq8.18d4659af617a8c1,reason=Created count=1 msg=Created container: task
0.0757,Event,ADDED,eval-conflicts-rho005-r5-016-xkcq8.18d4659af8001ed8,reason=Started count=1 msg=Started container task
0.0759,Event,ADDED,eval-conflicts-rho005-r5-016.18d4659adb4cc6ec,reason=SuccessfulCreate count=1 msg=Created pod: eval-conflicts-rho005-r5-016-xkcq8
0.0761,Event,ADDED,eval-conflicts-rho005-r5-016.18d4659e26b4901e,reason=Completed count=1 msg=Job completed
0.0762,Event,ADDED,eval-conflicts-rho005-r5-017-zgfsm.18d4659b175937fc,reason=Scheduled count=None msg=Successfully assigned compute/eval-conflicts-rho005-r5-017-zgfsm to kind-worker2
0.0764,Event,ADDED,eval-conflicts-rho005-r5-017-zgfsm.18d4659b3016f391,"reason=Pulled count=1 msg=Container image ""busybox:musl"" already present on machine"
0.0765,Event,ADDED,eval-conflicts-rho005-r5-017-zgfsm.18d4659b312a3be4,reason=Created count=1 msg=Created container: task
0.0768,Event,ADDED,eval-conflicts-rho005-r5-017-zgfsm.18d4659b33901a1e,reason=Started count=1 msg=Started container task
0.0769,Event,ADDED,eval-conflicts-rho005-r5-017.18d4659b168320c7,reason=SuccessfulCreate count=1 msg=Created pod: eval-conflicts-rho005-r5-017-zgfsm
0.0771,Event,ADDED,eval-conflicts-rho005-r5-017.18d4659e62f6e464,reason=Completed count=1 msg=Job completed
0.0773,Event,ADDED,eval-conflicts-rho005-r5-018-pbvpl.18d4659b523e626b,reason=Scheduled count=None msg=Successfully assigned compute/eval-conflicts-rho005-r5-018-pbvpl to kind-worker5
0.0774,Event,ADDED,eval-conflicts-rho005-r5-018-pbvpl.18d4659b6ad85086,"reason=Pulled count=1 msg=Container image ""busybox:musl"" already present on machine"
0.0776,Event,ADDED,eval-conflicts-rho005-r5-018-pbvpl.18d4659b6be90c55,reason=Created count=1 msg=Created container: task
0.0778,Event,ADDED,eval-conflicts-rho005-r5-018-pbvpl.18d4659b6dd5090d,reason=Started count=1 msg=Started container task
0.0779,Event,ADDED,eval-conflicts-rho005-r5-018.18d4659b519e4777,reason=SuccessfulCreate count=1 msg=Created pod: eval-conflicts-rho005-r5-018-pbvpl
0.0781,Event,ADDED,eval-conflicts-rho005-r5-018.18d4659e815c21fd,reason=Completed count=1 msg=Job completed
0.0783,Event,ADDED,eval-conflicts-rho005-r5-019-z2x2f.18d4659b8f1ca233,reason=Scheduled count=None msg=Successfully assigned compute/eval-conflicts-rho005-r5-019-z2x2f to kind-worker5
0.0784,Event,ADDED,eval-conflicts-rho005-r5-019-z2x2f.18d4659bacb0e2c4,"reason=Pulled count=1 msg=Container image ""busybox:musl"" already present on machine"
0.0786,Event,ADDED,eval-conflicts-rho005-r5-019-z2x2f.18d4659badb79cdb,reason=Created count=1 msg=Created container: task
0.0788,Event,ADDED,eval-conflicts-rho005-r5-019-z2x2f.18d4659bb25cdcf0,reason=Started count=1 msg=Started container task
0.0789,Event,ADDED,eval-conflicts-rho005-r5-019.18d4659b8de379ca,reason=SuccessfulCreate count=1 msg=Created pod: eval-conflicts-rho005-r5-019-z2x2f
0.0791,Event,ADDED,eval-conflicts-rho005-r5-019.18d4659ebd5dcb82,reason=Completed count=1 msg=Job completed
0.0795,Event,ADDED,eval-conflicts-rho005-r5-020-425jj.18d4659bc9e806fd,reason=Scheduled count=None msg=Successfully assigned compute/eval-conflicts-rho005-r5-020-425jj to kind-worker5
0.0797,Event,ADDED,eval-conflicts-rho005-r5-020-425jj.18d4659be7bf5310,"reason=Pulled count=1 msg=Container image ""busybox:musl"" already present on machine"
0.0798,Event,ADDED,eval-conflicts-rho005-r5-020-425jj.18d4659be8fb0357,reason=Created count=1 msg=Created container: task
0.08,Event,ADDED,eval-conflicts-rho005-r5-020-425jj.18d4659becffdf9c,reason=Started count=1 msg=Started container task
0.0802,TaskRequest,MODIFIED,eval-conflicts-rho030-r1-000,phase=Pending job=None
0.0804,Event,ADDED,eval-conflicts-rho005-r5-020.18d4659bc8cc36a7,reason=SuccessfulCreate count=1 msg=Created pod: eval-conflicts-rho005-r5-020-425jj
0.0806,Event,ADDED,eval-conflicts-rho005-r5-020.18d4659efd4557c4,reason=Completed count=1 msg=Job completed
0.0808,Event,ADDED,eval-conflicts-rho005-r5-021-fxpvl.18d4659c05471aaf,reason=Scheduled count=None msg=Successfully assigned compute/eval-conflicts-rho005-r5-021-fxpvl to kind-worker5
0.081,Event,ADDED,eval-conflicts-rho005-r5-021-fxpvl.18d4659c1e799aff,"reason=Pulled count=1 msg=Container image ""busybox:musl"" already present on machine"
0.0812,Event,ADDED,eval-conflicts-rho005-r5-021-fxpvl.18d4659c1fb2a1ff,reason=Created count=1 msg=Created container: task
0.0814,Event,ADDED,eval-conflicts-rho005-r5-021-fxpvl.18d4659c21ea9d0d,reason=Started count=1 msg=Started container task
0.0816,Event,ADDED,eval-conflicts-rho005-r5-021.18d4659c048a919b,reason=SuccessfulCreate count=1 msg=Created pod: eval-conflicts-rho005-r5-021-fxpvl
0.0818,Event,ADDED,eval-conflicts-rho005-r5-021.18d4659f398db5af,reason=Completed count=1 msg=Job completed
0.0819,Event,ADDED,eval-conflicts-rho005-r5-022-j6fbl.18d4659c40d85f3e,reason=Scheduled count=None msg=Successfully assigned compute/eval-conflicts-rho005-r5-022-j6fbl to kind-worker5
0.0821,Event,ADDED,eval-conflicts-rho005-r5-022-j6fbl.18d4659c59cb850a,"reason=Pulled count=1 msg=Container image ""busybox:musl"" already present on machine"
0.0823,Event,ADDED,eval-conflicts-rho005-r5-022-j6fbl.18d4659c5acc0e58,reason=Created count=1 msg=Created container: task
0.0824,Event,ADDED,eval-conflicts-rho005-r5-022-j6fbl.18d4659c5ce30e8c,reason=Started count=1 msg=Started container task
0.0826,Event,ADDED,eval-conflicts-rho005-r5-022.18d4659c4002eefc,reason=SuccessfulCreate count=1 msg=Created pod: eval-conflicts-rho005-r5-022-j6fbl
0.0828,Event,ADDED,eval-conflicts-rho005-r5-022.18d4659f75843a3a,reason=Completed count=1 msg=Job completed
0.0829,Event,ADDED,eval-conflicts-rho005-r5-023-45kcl.18d4659c7d14fe3e,reason=Scheduled count=None msg=Successfully assigned compute/eval-conflicts-rho005-r5-023-45kcl to kind-worker2
0.0831,Event,ADDED,eval-conflicts-rho005-r5-023-45kcl.18d4659c989dab2e,"reason=Pulled count=1 msg=Container image ""busybox:musl"" already present on machine"
0.0833,Event,ADDED,eval-conflicts-rho005-r5-023-45kcl.18d4659c99cd0538,reason=Created count=1 msg=Created container: task
0.0835,Event,ADDED,eval-conflicts-rho005-r5-023-45kcl.18d4659c9e79a26a,reason=Started count=1 msg=Started container task
0.0837,Event,ADDED,eval-conflicts-rho005-r5-023.18d4659c7c1d8d81,reason=SuccessfulCreate count=1 msg=Created pod: eval-conflicts-rho005-r5-023-45kcl
0.0839,Event,ADDED,eval-conflicts-rho005-r5-023.18d4659fcdceb575,reason=Completed count=1 msg=Job completed
0.084,Event,ADDED,eval-conflicts-rho005-r5-024-r9jnf.18d4659cb8133a8a,reason=Scheduled count=None msg=Successfully assigned compute/eval-conflicts-rho005-r5-024-r9jnf to kind-worker
0.0842,Event,ADDED,eval-conflicts-rho005-r5-024-r9jnf.18d4659cd51bf68a,"reason=Pulled count=1 msg=Container image ""busybox:musl"" already present on machine"
0.0844,Event,ADDED,eval-conflicts-rho005-r5-024-r9jnf.18d4659cd62b3e23,reason=Created count=1 msg=Created container: task
0.0845,Event,ADDED,eval-conflicts-rho005-r5-024-r9jnf.18d4659cda9ed5ca,reason=Started count=1 msg=Started container task
0.0848,Event,ADDED,eval-conflicts-rho005-r5-024.18d4659cb70d1811,reason=SuccessfulCreate count=1 msg=Created pod: eval-conflicts-rho005-r5-024-r9jnf
0.0851,Event,ADDED,eval-conflicts-rho005-r5-024.18d465a023d31b97,reason=Completed count=1 msg=Job completed
0.0853,Event,ADDED,eval-conflicts-rho005-r5-025-nrqtz.18d4659cf4fb19e4,reason=Scheduled count=None msg=Successfully assigned compute/eval-conflicts-rho005-r5-025-nrqtz to kind-worker
0.0855,Event,ADDED,eval-conflicts-rho005-r5-025-nrqtz.18d4659d0e792c5e,"reason=Pulled count=1 msg=Container image ""busybox:musl"" already present on machine"
0.0857,Event,ADDED,eval-conflicts-rho005-r5-025-nrqtz.18d4659d0f94b2d9,reason=Created count=1 msg=Created container: task
0.086,Event,ADDED,eval-conflicts-rho005-r5-025-nrqtz.18d4659d1467f7c8,reason=Started count=1 msg=Started container task
0.0863,Event,ADDED,eval-conflicts-rho005-r5-025.18d4659cf41fbfcb,reason=SuccessfulCreate count=1 msg=Created pod: eval-conflicts-rho005-r5-025-nrqtz
0.0865,Event,ADDED,eval-conflicts-rho005-r5-025.18d465a05586a962,reason=Completed count=1 msg=Job completed
0.0868,Event,ADDED,eval-conflicts-rho005-r5-026-rgvcl.18d4659d2fe2e702,reason=Scheduled count=None msg=Successfully assigned compute/eval-conflicts-rho005-r5-026-rgvcl to kind-worker
0.087,Event,ADDED,eval-conflicts-rho005-r5-026-rgvcl.18d4659d494a68a6,"reason=Pulled count=1 msg=Container image ""busybox:musl"" already present on machine"
0.0872,Event,ADDED,eval-conflicts-rho005-r5-026-rgvcl.18d4659d4a5a3da2,reason=Created count=1 msg=Created container: task
0.0873,Event,ADDED,eval-conflicts-rho005-r5-026-rgvcl.18d4659d4c7895cd,reason=Started count=1 msg=Started container task
0.0876,Event,ADDED,eval-conflicts-rho005-r5-026.18d4659d2ef479d0,reason=SuccessfulCreate count=1 msg=Created pod: eval-conflicts-rho005-r5-026-rgvcl
0.0878,Event,ADDED,eval-conflicts-rho005-r5-026.18d465a091f329bf,reason=Completed count=1 msg=Job completed
0.0879,Event,ADDED,eval-conflicts-rho005-r5-027-2s2fx.18d4659d6b06ef1b,reason=Scheduled count=None msg=Successfully assigned compute/eval-conflicts-rho005-r5-027-2s2fx to kind-worker
0.0882,Event,ADDED,eval-conflicts-rho005-r5-027-2s2fx.18d4659d83c9599c,"reason=Pulled count=1 msg=Container image ""busybox:musl"" already present on machine"
0.0884,Event,ADDED,eval-conflicts-rho005-r5-027-2s2fx.18d4659d84d511b1,reason=Created count=1 msg=Created container: task
0.0885,Event,ADDED,eval-conflicts-rho005-r5-027-2s2fx.18d4659d86aa2c0a,reason=Started count=1 msg=Started container task
0.0887,Event,ADDED,eval-conflicts-rho005-r5-027.18d4659d6a2e8dfb,reason=SuccessfulCreate count=1 msg=Created pod: eval-conflicts-rho005-r5-027-2s2fx
0.0889,Event,ADDED,eval-conflicts-rho005-r5-027.18d465a0916f4eb2,reason=Completed count=1 msg=Job completed
0.089,Event,ADDED,eval-conflicts-rho005-r5-028-8h4n9.18d4659da73bfae0,reason=Scheduled count=None msg=Successfully assigned compute/eval-conflicts-rho005-r5-028-8h4n9 to kind-worker4
0.0892,Event,ADDED,eval-conflicts-rho005-r5-028-8h4n9.18d4659dc00f0895,"reason=Pulled count=1 msg=Container image ""busybox:musl"" already present on machine"
0.0894,Event,ADDED,eval-conflicts-rho005-r5-028-8h4n9.18d4659dc1236b44,reason=Created count=1 msg=Created container: task
0.0895,Event,ADDED,eval-conflicts-rho005-r5-028-8h4n9.18d4659dc35940b4,reason=Started count=1 msg=Started container task
0.0897,Event,ADDED,eval-conflicts-rho005-r5-028.18d4659da679950e,reason=SuccessfulCreate count=1 msg=Created pod: eval-conflicts-rho005-r5-028-8h4n9
0.0899,Event,ADDED,eval-conflicts-rho005-r5-028.18d465a103abe5fa,reason=Completed count=1 msg=Job completed
0.09,Event,ADDED,eval-conflicts-rho005-r5-029-f4j77.18d4659de28f5952,reason=Scheduled count=None msg=Successfully assigned compute/eval-conflicts-rho005-r5-029-f4j77 to kind-worker4
0.0902,Event,ADDED,eval-conflicts-rho005-r5-029-f4j77.18d4659dfbd7f08a,"reason=Pulled count=1 msg=Container image ""busybox:musl"" already present on machine"
0.0904,Event,ADDED,eval-conflicts-rho005-r5-029-f4j77.18d4659dfce5eb82,reason=Created count=1 msg=Created container: task
0.0905,Event,ADDED,eval-conflicts-rho005-r5-029-f4j77.18d4659dfef9e7ab,reason=Started count=1 msg=Started container task
0.0907,Event,ADDED,eval-conflicts-rho005-r5-029.18d4659de165b52d,reason=SuccessfulCreate count=1 msg=Created pod: eval-conflicts-rho005-r5-029-f4j77
0.0909,Event,ADDED,eval-conflicts-rho005-r5-029.18d465a140b87a75,reason=Completed count=1 msg=Job completed
0.091,Event,ADDED,eval-conflicts-rho005-r5-030-86vcn.18d4659e1e002f96,reason=Scheduled count=None msg=Successfully assigned compute/eval-conflicts-rho005-r5-030-86vcn to kind-worker
0.0912,Event,ADDED,eval-conflicts-rho005-r5-030-86vcn.18d4659e370db5cb,"reason=Pulled count=1 msg=Container image ""busybox:musl"" already present on machine"
0.0913,Event,ADDED,eval-conflicts-rho005-r5-030-86vcn.18d4659e389842ba,reason=Created count=1 msg=Created container: task
0.0915,Event,ADDED,eval-conflicts-rho005-r5-030-86vcn.18d4659e3dcc23f3,reason=Started count=1 msg=Started container task
0.0917,Event,ADDED,eval-conflicts-rho005-r5-030.18d4659e1ced45dd,reason=SuccessfulCreate count=1 msg=Created pod: eval-conflicts-rho005-r5-030-86vcn
0.0918,Event,ADDED,eval-conflicts-rho005-r5-030.18d465a183479257,reason=Completed count=1 msg=Job completed
0.092,Event,ADDED,eval-conflicts-rho005-r5-031-5w2hc.18d4659e59d8dc50,reason=Scheduled count=None msg=Successfully assigned compute/eval-conflicts-rho005-r5-031-5w2hc to kind-worker4
0.0922,Event,ADDED,eval-conflicts-rho005-r5-031-5w2hc.18d4659e72e3129a,"reason=Pulled count=1 msg=Container image ""busybox:musl"" already present on machine"
0.0924,Event,ADDED,eval-conflicts-rho005-r5-031-5w2hc.18d4659e73f21574,reason=Created count=1 msg=Created container: task
0.0926,Event,ADDED,eval-conflicts-rho005-r5-031-5w2hc.18d4659e76b8c76a,reason=Started count=1 msg=Started container task
0.0927,Event,ADDED,eval-conflicts-rho005-r5-031.18d4659e58f192f0,reason=SuccessfulCreate count=1 msg=Created pod: eval-conflicts-rho005-r5-031-5w2hc
0.0929,Event,ADDED,eval-conflicts-rho005-r5-031.18d465a1b865070f,reason=Completed count=1 msg=Job completed
0.093,Event,ADDED,eval-conflicts-rho005-r5-032-6bdrh.18d4659e958f9f9a,reason=Scheduled count=None msg=Successfully assigned compute/eval-conflicts-rho005-r5-032-6bdrh to kind-worker3
0.0932,Event,ADDED,eval-conflicts-rho005-r5-032-6bdrh.18d4659eaf328ee6,"reason=Pulled count=1 msg=Container image ""busybox:musl"" already present on machine"
0.0934,Event,ADDED,eval-conflicts-rho005-r5-032-6bdrh.18d4659eb04e6f83,reason=Created count=1 msg=Created container: task
0.0936,Event,ADDED,eval-conflicts-rho005-r5-032-6bdrh.18d4659eb8ba0f23,reason=Started count=1 msg=Started container task
0.0938,Event,ADDED,eval-conflicts-rho005-r5-032.18d4659e945c9cd7,reason=SuccessfulCreate count=1 msg=Created pod: eval-conflicts-rho005-r5-032-6bdrh
0.094,Event,ADDED,eval-conflicts-rho005-r5-032.18d465a1ec3aa2be,reason=Completed count=1 msg=Job completed
0.0941,Event,ADDED,eval-conflicts-rho005-r5-033-dzswk.18d4659ed1970b4f,reason=Scheduled count=None msg=Successfully assigned compute/eval-conflicts-rho005-r5-033-dzswk to kind-worker3
0.0943,Event,ADDED,eval-conflicts-rho005-r5-033-dzswk.18d4659eeba82003,"reason=Pulled count=1 msg=Container image ""busybox:musl"" already present on machine"
0.0945,Event,ADDED,eval-conflicts-rho005-r5-033-dzswk.18d4659eeccb5fb4,reason=Created count=1 msg=Created container: task
0.0947,Event,ADDED,eval-conflicts-rho005-r5-033-dzswk.18d4659ef0bd247b,reason=Started count=1 msg=Started container task
0.095,Event,ADDED,eval-conflicts-rho005-r5-033.18d4659ed05d1fe5,reason=SuccessfulCreate count=1 msg=Created pod: eval-conflicts-rho005-r5-033-dzswk
0.0955,Event,ADDED,eval-conflicts-rho005-r5-033.18d465a22825ac0c,reason=Completed count=1 msg=Job completed
0.0957,Event,ADDED,eval-conflicts-rho005-r5-034-5fdb7.18d4659f0d548dcc,reason=Scheduled count=None msg=Successfully assigned compute/eval-conflicts-rho005-r5-034-5fdb7 to kind-worker4
0.0959,Event,ADDED,eval-conflicts-rho005-r5-034-5fdb7.18d4659f28c0eb41,"reason=Pulled count=1 msg=Container image ""busybox:musl"" already present on machine"
0.0961,Event,ADDED,eval-conflicts-rho005-r5-034-5fdb7.18d4659f29d09787,reason=Created count=1 msg=Created container: task
0.0967,Job,ADDED,eval-conflicts-rho030-r1-000,
0.0971,Event,ADDED,eval-conflicts-rho005-r5-034-5fdb7.18d4659f2dd77faa,reason=Started count=1 msg=Started container task
0.0973,Event,ADDED,eval-conflicts-rho005-r5-034.18d4659f0c7a7c25,reason=SuccessfulCreate count=1 msg=Created pod: eval-conflicts-rho005-r5-034-5fdb7
0.0975,Event,ADDED,eval-conflicts-rho005-r5-034.18d465a26acb8c50,reason=Completed count=1 msg=Job completed
0.0977,Event,ADDED,eval-conflicts-rho005-r5-035-8lv92.18d4659f47eacfeb,reason=Scheduled count=None msg=Successfully assigned compute/eval-conflicts-rho005-r5-035-8lv92 to kind-worker3
0.098,Event,ADDED,eval-conflicts-rho005-r5-035-8lv92.18d4659f6238af34,"reason=Pulled count=1 msg=Container image ""busybox:musl"" already present on machine"
0.0982,Event,ADDED,eval-conflicts-rho005-r5-035-8lv92.18d4659f634a1c8e,reason=Created count=1 msg=Created container: task
0.0983,Event,ADDED,eval-conflicts-rho005-r5-035-8lv92.18d4659f6a387257,reason=Started count=1 msg=Started container task
0.0987,Event,ADDED,eval-conflicts-rho005-r5-035.18d4659f47621514,reason=SuccessfulCreate count=1 msg=Created pod: eval-conflicts-rho005-r5-035-8lv92
0.0989,Event,ADDED,eval-conflicts-rho005-r5-035.18d465a2a05d109b,reason=Completed count=1 msg=Job completed
0.099,Event,ADDED,eval-conflicts-rho005-r5-036-hsbbm.18d4659f875ca675,reason=Scheduled count=None msg=Successfully assigned compute/eval-conflicts-rho005-r5-036-hsbbm to kind-worker3
0.0992,Event,ADDED,eval-conflicts-rho005-r5-036-hsbbm.18d4659fab3cec97,"reason=Pulled count=1 msg=Container image ""busybox:musl"" already present on machine"
0.0996,Event,ADDED,eval-conflicts-rho005-r5-036-hsbbm.18d4659fac8d14bb,reason=Created count=1 msg=Created container: task
0.0998,Event,ADDED,eval-conflicts-rho005-r5-036-hsbbm.18d4659fb14c86d4,reason=Started count=1 msg=Started container task
0.1,Event,ADDED,eval-conflicts-rho005-r5-036.18d4659f86cfb1c5,reason=SuccessfulCreate count=1 msg=Created pod: eval-conflicts-rho005-r5-036-hsbbm
0.1002,Event,ADDED,eval-conflicts-rho005-r5-036.18d465a2dc16f115,reason=Completed count=1 msg=Job completed
0.1006,Event,ADDED,eval-conflicts-rho005-r5-037-725k2.18d4659fbf6c3dda,reason=Scheduled count=None msg=Successfully assigned compute/eval-conflicts-rho005-r5-037-725k2 to kind-worker3
0.1008,Event,ADDED,eval-conflicts-rho005-r5-037-725k2.18d4659fd9c7f451,"reason=Pulled count=1 msg=Container image ""busybox:musl"" already present on machine"
0.1011,Event,ADDED,eval-conflicts-rho005-r5-037-725k2.18d4659fdb1e09f6,reason=Created count=1 msg=Created container: task
0.1015,Event,ADDED,eval-conflicts-rho005-r5-037-725k2.18d4659feace6877,reason=Started count=1 msg=Started container task
0.1016,Event,ADDED,eval-conflicts-rho005-r5-037.18d4659fbeba33b4,reason=SuccessfulCreate count=1 msg=Created pod: eval-conflicts-rho005-r5-037-725k2
0.1018,Event,ADDED,eval-conflicts-rho005-r5-037.18d465a3168d3b22,reason=Completed count=1 msg=Job completed
0.102,Event,ADDED,eval-conflicts-rho005-r5-038-clsb2.18d4659ffad72c3c,"reason=FailedScheduling count=None msg=0/6 nodes are available: 6 node(s) had untolerated taint(s). no new claims to deallocate, preemption: 0/6 nodes are available: 6 Preemption is not helpful for scheduling."
0.1021,TaskRequest,MODIFIED,eval-conflicts-rho030-r1-000,phase=Scheduled job=None
0.1024,Event,ADDED,eval-conflicts-rho005-r5-038-clsb2.18d465a00b469e57,reason=Scheduled count=None msg=Successfully assigned compute/eval-conflicts-rho005-r5-038-clsb2 to kind-worker5
0.1026,Event,ADDED,eval-conflicts-rho005-r5-038-clsb2.18d465a0245e322b,"reason=Pulled count=1 msg=Container image ""busybox:musl"" already present on machine"
0.1028,Event,ADDED,eval-conflicts-rho005-r5-038-clsb2.18d465a025b5f34d,reason=Created count=1 msg=Created container: task
0.1032,Event,ADDED,eval-conflicts-rho005-r5-038-clsb2.18d465a027ff9809,reason=Started count=1 msg=Started container task
0.1036,Event,ADDED,eval-conflicts-rho005-r5-038.18d4659ffacd2391,reason=SuccessfulCreate count=1 msg=Created pod: eval-conflicts-rho005-r5-038-clsb2
0.104,Event,ADDED,eval-conflicts-rho005-r5-038.18d465a369562aac,reason=Completed count=1 msg=Job completed
0.1043,Event,ADDED,eval-conflicts-rho005-r5-039-jz87s.18d465a0360c8676,reason=Scheduled count=None msg=Successfully assigned compute/eval-conflicts-rho005-r5-039-jz87s to kind-worker5
0.1049,Event,ADDED,eval-conflicts-rho005-r5-039-jz87s.18d465a04fffdc56,"reason=Pulled count=1 msg=Container image ""busybox:musl"" already present on machine"
0.1052,Event,ADDED,eval-conflicts-rho005-r5-039-jz87s.18d465a0512b7c3a,reason=Created count=1 msg=Created container: task
0.1054,Event,ADDED,eval-conflicts-rho005-r5-039-jz87s.18d465a054e74045,reason=Started count=1 msg=Started container task
0.1058,Event,ADDED,eval-conflicts-rho005-r5-039.18d465a0355c0e38,reason=SuccessfulCreate count=1 msg=Created pod: eval-conflicts-rho005-r5-039-jz87s
0.1067,Pod,ADDED,eval-conflicts-rho030-r1-000-mvt9p,phase=Pending node=None
0.1071,Event,ADDED,eval-conflicts-rho005-r5-039.18d465a3696bc310,reason=Completed count=1 msg=Job completed
0.1072,Event,ADDED,eval-conflicts-rho005-r5-040-5l56w.18d465a073f1d958,"reason=FailedScheduling count=None msg=0/6 nodes are available: 1 c_wall violated: 1 conflicting context pair(s) with node memory, 5 node(s) had untolerated taint(s). no new claims to deallocate, preemption: 0/6 nodes are available: 1 No preemption victims found for incoming pod, 5 Preemption is not helpful for scheduling."
0.1075,Event,ADDED,eval-conflicts-rho005-r5-040-5l56w.18d465a074767091,"reason=FailedScheduling count=None msg=0/6 nodes are available: 1 c_wall violated: 1 conflicting context pair(s) with node memory, 5 node(s) had untolerated taint(s). no new claims to deallocate, preemption: 0/6 nodes are available: 1 No preemption victims found for incoming pod, 5 Preemption is not helpful for scheduling."
0.1079,Event,ADDED,eval-conflicts-rho005-r5-040-5l56w.18d465a15ec2ace7,reason=Scheduled count=None msg=Successfully assigned compute/eval-conflicts-rho005-r5-040-5l56w to kind-worker
0.1081,Event,ADDED,eval-conflicts-rho005-r5-040-5l56w.18d465a179daface,"reason=Pulled count=1 msg=Container image ""busybox:musl"" already present on machine"
0.1083,Event,ADDED,eval-conflicts-rho005-r5-040-5l56w.18d465a17afff46d,reason=Created count=1 msg=Created container: task
0.1089,Job,MODIFIED,eval-conflicts-rho030-r1-000,
0.1093,Event,ADDED,eval-conflicts-rho005-r5-040-5l56w.18d465a17f57edf8,reason=Started count=1 msg=Started container task
0.1095,Event,ADDED,eval-conflicts-rho005-r5-040.18d465a073ac0759,reason=SuccessfulCreate count=1 msg=Created pod: eval-conflicts-rho005-r5-040-5l56w
0.1097,Event,ADDED,eval-conflicts-rho005-r5-040.18d465a4c6bc8a78,reason=Completed count=1 msg=Job completed
0.1098,Event,ADDED,eval-conflicts-rho005-r5-041-lj9p5.18d465a0afae65d0,reason=Scheduled count=None msg=Successfully assigned compute/eval-conflicts-rho005-r5-041-lj9p5 to kind-worker5
0.1102,Event,ADDED,eval-conflicts-rho005-r5-041-lj9p5.18d465a0d148f6e9,"reason=Pulled count=1 msg=Container image ""busybox:musl"" already present on machine"
0.1105,Event,ADDED,eval-conflicts-rho005-r5-041-lj9p5.18d465a0d2751d4c,reason=Created count=1 msg=Created container: task
0.1107,Event,ADDED,eval-conflicts-rho005-r5-041-lj9p5.18d465a0d67fe718,reason=Started count=1 msg=Started container task
0.1108,Event,ADDED,eval-conflicts-rho005-r5-041.18d465a0af09a50b,reason=SuccessfulCreate count=1 msg=Created pod: eval-conflicts-rho005-r5-041-lj9p5
0.111,TaskRequest,MODIFIED,eval-conflicts-rho030-r1-000,phase=Scheduled job=None
0.1113,Event,ADDED,eval-conflicts-rho005-r5-041.18d465a41d63f019,reason=Completed count=1 msg=Job completed
0.1114,Event,ADDED,eval-conflicts-rho005-r5-042-2h72f.18d465a0e919c5ee,reason=Scheduled count=None msg=Successfully assigned compute/eval-conflicts-rho005-r5-042-2h72f to kind-worker5
0.1116,Event,ADDED,eval-conflicts-rho005-r5-042-2h72f.18d465a10371f6fd,"reason=Pulled count=1 msg=Container image ""busybox:musl"" already present on machine"
0.112,Event,ADDED,eval-conflicts-rho005-r5-042-2h72f.18d465a104e61b1f,reason=Created count=1 msg=Created container: task
0.1121,Event,ADDED,eval-conflicts-rho005-r5-042-2h72f.18d465a107290dba,reason=Started count=1 msg=Started container task
0.1123,Event,ADDED,eval-conflicts-rho005-r5-042.18d465a0e8971af6,reason=SuccessfulCreate count=1 msg=Created pod: eval-conflicts-rho005-r5-042-2h72f
0.1125,Event,ADDED,eval-conflicts-rho005-r5-042.18d465a41d3df17b,reason=Completed count=1 msg=Job completed
0.1127,Event,ADDED,eval-conflicts-rho005-r5-043-q869r.18d465a12569f2e5,reason=Scheduled count=None msg=Successfully assigned compute/eval-conflicts-rho005-r5-043-q869r to kind-worker5
0.1129,Event,ADDED,eval-conflicts-rho005-r5-043-q869r.18d465a1402af5de,"reason=Pulled count=1 msg=Container image ""busybox:musl"" already present on machine"
0.113,Event,ADDED,eval-conflicts-rho005-r5-043-q869r.18d465a141a9436d,reason=Created count=1 msg=Created container: task
0.1132,Event,ADDED,eval-conflicts-rho005-r5-043-q869r.18d465a147199c18,reason=Started count=1 msg=Started container task
0.1134,Event,ADDED,eval-conflicts-rho005-r5-043.18d465a124b24f56,reason=SuccessfulCreate count=1 msg=Created pod: eval-conflicts-rho005-r5-043-q869r
0.1136,Event,ADDED,eval-conflicts-rho005-r5-043.18d465a494f0de1d,reason=Completed count=1 msg=Job completed
0.1137,Event,ADDED,eval-conflicts-rho005-r5-044-vk2x8.18d465a1614a8389,reason=Scheduled count=None msg=Successfully assigned compute/eval-conflicts-rho005-r5-044-vk2x8 to kind-worker
0.114,Event,ADDED,eval-conflicts-rho005-r5-044-vk2x8.18d465a17d2187f7,"reason=Pulled count=1 msg=Container image ""busybox:musl"" already present on machine"
0.1142,Event,ADDED,eval-conflicts-rho005-r5-044-vk2x8.18d465a17e46c856,reason=Created count=1 msg=Created container: task
0.1143,Event,ADDED,eval-conflicts-rho005-r5-044-vk2x8.18d465a18059a730,reason=Started count=1 msg=Started container task
0.1145,Event,ADDED,eval-conflicts-rho005-r5-044.18d465a15fca95ef,reason=SuccessfulCreate count=1 msg=Created pod: eval-conflicts-rho005-r5-044-vk2x8
0.1147,Event,ADDED,eval-conflicts-rho005-r5-044.18d465a4c656279f,reason=Completed count=1 msg=Job completed
0.1149,Event,ADDED,eval-conflicts-rho005-r5-045-k9ch6.18d465a19beef4c0,reason=Scheduled count=None msg=Successfully assigned compute/eval-conflicts-rho005-r5-045-k9ch6 to kind-worker2
0.1152,Event,ADDED,eval-conflicts-rho005-r5-045-k9ch6.18d465a1b5c93f55,"reason=Pulled count=1 msg=Container image ""busybox:musl"" already present on machine"
0.1155,Event,ADDED,eval-conflicts-rho005-r5-045-k9ch6.18d465a1b711a147,reason=Created count=1 msg=Created container: task
0.1157,Event,ADDED,eval-conflicts-rho005-r5-045-k9ch6.18d465a1ba981e67,reason=Started count=1 msg=Started container task
0.1158,Event,ADDED,eval-conflicts-rho005-r5-045.18d465a19ae4205f,reason=SuccessfulCreate count=1 msg=Created pod: eval-conflicts-rho005-r5-045-k9ch6
0.116,Event,ADDED,eval-conflicts-rho005-r5-045.18d465a4ec5c8e88,reason=Completed count=1 msg=Job completed
0.1164,Event,ADDED,eval-conflicts-rho005-r5-046-5c8qf.18d465a1d85e2659,reason=Scheduled count=None msg=Successfully assigned compute/eval-conflicts-rho005-r5-046-5c8qf to kind-worker2
0.1166,Event,ADDED,eval-conflicts-rho005-r5-046-5c8qf.18d465a1f256d635,"reason=Pulled count=1 msg=Container image ""busybox:musl"" already present on machine"
0.1168,Event,ADDED,eval-conflicts-rho005-r5-046-5c8qf.18d465a1f3a2f108,reason=Created count=1 msg=Created container: task
0.1169,Event,ADDED,eval-conflicts-rho005-r5-046-5c8qf.18d465a1f806c5a6,reason=Started count=1 msg=Started container task
0.1172,Event,ADDED,eval-conflicts-rho005-r5-046.18d465a1d70666a2,reason=SuccessfulCreate count=1 msg=Created pod: eval-conflicts-rho005-r5-046-5c8qf
0.1173,Event,ADDED,eval-conflicts-rho005-r5-046.18d465a5279fdfbf,reason=Completed count=1 msg=Job completed
0.1175,Event,ADDED,eval-conflicts-rho005-r5-047-45gpb.18d465a2144bef1b,reason=Scheduled count=None msg=Successfully assigned compute/eval-conflicts-rho005-r5-047-45gpb to kind-worker2
0.1177,Event,ADDED,eval-conflicts-rho005-r5-047-45gpb.18d465a22fb599fe,"reason=Pulled count=1 msg=Container image ""busybox:musl"" already present on machine"
0.1178,Event,ADDED,eval-conflicts-rho005-r5-047-45gpb.18d465a231054992,reason=Created count=1 msg=Created container: task
0.118,Event,ADDED,eval-conflicts-rho005-r5-047-45gpb.18d465a23574f733,reason=Started count=1 msg=Started container task
0.1182,Event,ADDED,eval-conflicts-rho005-r5-047.18d465a212fb0c13,reason=SuccessfulCreate count=1 msg=Created pod: eval-conflicts-rho005-r5-047-45gpb
0.1183,Event,ADDED,eval-conflicts-rho005-r5-047.18d465a5638d4628,reason=Completed count=1 msg=Job completed
0.1185,Event,ADDED,eval-conflicts-rho005-r5-048-zxzh9.18d465a250202713,reason=Scheduled count=None msg=Successfully assigned compute/eval-conflicts-rho005-r5-048-zxzh9 to kind-worker
0.1187,Event,ADDED,eval-conflicts-rho005-r5-048-zxzh9.18d465a269ce9d44,"reason=Pulled count=1 msg=Container image ""busybox:musl"" already present on machine"
0.1188,Event,ADDED,eval-conflicts-rho005-r5-048-zxzh9.18d465a26b030b46,reason=Created count=1 msg=Created container: task
0.119,Event,ADDED,eval-conflicts-rho005-r5-048-zxzh9.18d465a26d1f9322,reason=Started count=1 msg=Started container task
0.1192,Event,ADDED,eval-conflicts-rho005-r5-048.18d465a24e51d50f,reason=SuccessfulCreate count=1 msg=Created pod: eval-conflicts-rho005-r5-048-zxzh9
0.1193,Event,ADDED,eval-conflicts-rho005-r5-048.18d465a5793983df,reason=Completed count=1 msg=Job completed
0.1195,Event,ADDED,eval-conflicts-rho005-r5-049-5v2wd.18d465a28a701290,reason=Scheduled count=None msg=Successfully assigned compute/eval-conflicts-rho005-r5-049-5v2wd to kind-worker
0.1198,Event,ADDED,eval-conflicts-rho005-r5-049-5v2wd.18d465a2a8a18196,"reason=Pulled count=1 msg=Container image ""busybox:musl"" already present on machine"
0.1203,Event,ADDED,eval-conflicts-rho005-r5-049-5v2wd.18d465a2a9d4f7ea,reason=Created count=1 msg=Created container: task
0.1206,Event,ADDED,eval-conflicts-rho005-r5-049-5v2wd.18d465a2ad74723e,reason=Started count=1 msg=Started container task
0.121,Event,ADDED,eval-conflicts-rho005-r5-049.18d465a2894384af,reason=SuccessfulCreate count=1 msg=Created pod: eval-conflicts-rho005-r5-049-5v2wd
0.1211,Event,ADDED,eval-conflicts-rho005-r5-049.18d465a5f1678182,reason=Completed count=1 msg=Job completed
0.1213,Event,ADDED,eval-conflicts-rho005-r5-050-vrxc7.18d465a2c7241bdc,reason=Scheduled count=None msg=Successfully assigned compute/eval-conflicts-rho005-r5-050-vrxc7 to kind-worker
0.1221,Pod,MODIFIED,eval-conflicts-rho030-r1-000-mvt9p,phase=Pending node=kind-worker5
0.1224,Event,ADDED,eval-conflicts-rho005-r5-050-vrxc7.18d465a2e17c71e1,"reason=Pulled count=1 msg=Container image ""busybox:musl"" already present on machine"
0.1226,Event,ADDED,eval-conflicts-rho005-r5-050-vrxc7.18d465a2e2886058,reason=Created count=1 msg=Created container: task
0.1227,Event,ADDED,eval-conflicts-rho005-r5-050-vrxc7.18d465a2e5c095e6,reason=Started count=1 msg=Started container task
0.1229,Event,ADDED,eval-conflicts-rho005-r5-050.18d465a2c636ed24,reason=SuccessfulCreate count=1 msg=Created pod: eval-conflicts-rho005-r5-050-vrxc7
0.1232,Event,ADDED,eval-conflicts-rho005-r5-050.18d465a5f12f7638,reason=Completed count=1 msg=Job completed
0.1235,Event,ADDED,eval-conflicts-rho005-r5-051-8ssdj.18d465a301b1ba66,reason=Scheduled count=None msg=Successfully assigned compute/eval-conflicts-rho005-r5-051-8ssdj to kind-worker2
0.1239,Event,ADDED,eval-conflicts-rho005-r5-051-8ssdj.18d465a31a8730e9,"reason=Pulled count=1 msg=Container image ""busybox:musl"" already present on machine"
0.1242,Event,ADDED,eval-conflicts-rho005-r5-051-8ssdj.18d465a31b999ccf,reason=Created count=1 msg=Created container: task
0.1247,Event,ADDED,eval-conflicts-rho005-r5-051-8ssdj.18d465a31db463ad,reason=Started count=1 msg=Started container task
0.1249,Event,ADDED,eval-conflicts-rho005-r5-051.18d465a300d0db9e,reason=SuccessfulCreate count=1 msg=Created pod: eval-conflicts-rho005-r5-051-8ssdj
0.125,Event,ADDED,eval-conflicts-rho005-r5-051.18d465a652b7e57b,reason=Completed count=1 msg=Job completed
0.1254,Event,ADDED,eval-conflicts-rho005-r5-052-ktc4v.18d465a33cfa660e,"reason=FailedScheduling count=None msg=0/6 nodes are available: 2 c_wall violated: 1 conflicting context pair(s) with node memory, 4 node(s) had untolerated taint(s). no new claims to deallocate, preemption: 0/6 nodes are available: 2 No preemption victims found for incoming pod, 4 Preemption is not helpful for scheduling."
0.1256,Event,ADDED,eval-conflicts-rho005-r5-052-ktc4v.18d465a33d9ae64a,"reason=FailedScheduling count=None msg=0/6 nodes are available: 2 c_wall violated: 1 conflicting context pair(s) with node memory, 4 node(s) had untolerated taint(s). no new claims to deallocate, preemption: 0/6 nodes are available: 2 No preemption victims found for incoming pod, 4 Preemption is not helpful for scheduling."
0.1258,Event,ADDED,eval-conflicts-rho005-r5-052-ktc4v.18d465a3b924bec2,"reason=FailedScheduling count=None msg=0/6 nodes are available: 1 c_wall violated: 1 conflicting context pair(s) with node memory, 5 node(s) had untolerated taint(s). no new claims to deallocate, preemption: 0/6 nodes are available: 1 No preemption victims found for incoming pod, 5 Preemption is not helpful for scheduling."
0.1262,Event,ADDED,eval-conflicts-rho005-r5-052-ktc4v.18d465a3d64b251e,reason=Scheduled count=None msg=Successfully assigned compute/eval-conflicts-rho005-r5-052-ktc4v to kind-worker4
0.1264,Event,ADDED,eval-conflicts-rho005-r5-052-ktc4v.18d465a3f12e0f35,"reason=Pulled count=1 msg=Container image ""busybox:musl"" already present on machine"
0.1266,Event,ADDED,eval-conflicts-rho005-r5-052-ktc4v.18d465a3f27fd5d0,reason=Created count=1 msg=Created container: task
0.1267,Event,ADDED,eval-conflicts-rho005-r5-052-ktc4v.18d465a3f68cefa7,reason=Started count=1 msg=Started container task
0.1272,Event,ADDED,eval-conflicts-rho005-r5-052.18d465a33c793d26,reason=SuccessfulCreate count=1 msg=Created pod: eval-conflicts-rho005-r5-052-ktc4v
0.1274,Event,ADDED,eval-conflicts-rho005-r5-052.18d465a714bb5df8,reason=Completed count=1 msg=Job completed
0.1276,Event,ADDED,eval-conflicts-rho005-r5-053-frkgt.18d465a379008400,reason=Scheduled count=None msg=Successfully assigned compute/eval-conflicts-rho005-r5-053-frkgt to kind-worker2
0.1279,Event,ADDED,eval-conflicts-rho005-r5-053-frkgt.18d465a3957bb33d,"reason=Pulled count=1 msg=Container image ""busybox:musl"" already present on machine"
0.1281,Event,ADDED,eval-conflicts-rho005-r5-053-frkgt.18d465a3969790c0,reason=Created count=1 msg=Created container: task
0.1287,Event,ADDED,eval-conflicts-rho005-r5-053-frkgt.18d465a3a202baf2,reason=Started count=1 msg=Started container task
0.1289,Event,ADDED,eval-conflicts-rho005-r5-053.18d465a3782ddb2b,reason=SuccessfulCreate count=1 msg=Created pod: eval-conflicts-rho005-r5-053-frkgt
0.1292,Event,ADDED,eval-conflicts-rho005-r5-053.18d465a6ca2c0d4d,reason=Completed count=1 msg=Job completed
0.1294,Event,ADDED,eval-conflicts-rho005-r5-054-2fgmv.18d465a3b524a52e,reason=Scheduled count=None msg=Successfully assigned compute/eval-conflicts-rho005-r5-054-2fgmv to kind-worker2
0.1295,Event,ADDED,eval-conflicts-rho005-r5-054-2fgmv.18d465a3cf666d3a,"reason=Pulled count=1 msg=Container image ""busybox:musl"" already present on machine"
0.1297,Event,ADDED,eval-conflicts-rho005-r5-054-2fgmv.18d465a3d0829d97,reason=Created count=1 msg=Created container: task
0.1312,Pod,MODIFIED,eval-conflicts-rho030-r1-000-mvt9p,phase=Pending node=kind-worker5
0.1315,Event,ADDED,eval-conflicts-rho005-r5-054-2fgmv.18d465a3da2ab33c,reason=Started count=1 msg=Started container task
0.1317,Event,ADDED,eval-conflicts-rho005-r5-054.18d465a3b386f2ba,reason=SuccessfulCreate count=1 msg=Created pod: eval-conflicts-rho005-r5-054-2fgmv
0.132,Event,ADDED,eval-conflicts-rho005-r5-054.18d465a705f33d47,reason=Completed count=1 msg=Job completed
0.1325,Event,ADDED,eval-conflicts-rho005-r5-055-qbc2q.18d465a3f020c2c3,reason=Scheduled count=None msg=Successfully assigned compute/eval-conflicts-rho005-r5-055-qbc2q to kind-worker4
0.1327,Event,ADDED,eval-conflicts-rho005-r5-055-qbc2q.18d465a40b210d2f,"reason=Pulled count=1 msg=Container image ""busybox:musl"" already present on machine"
0.1328,Event,ADDED,eval-conflicts-rho005-r5-055-qbc2q.18d465a40c46c672,reason=Created count=1 msg=Created container: task
0.133,Event,ADDED,eval-conflicts-rho005-r5-055-qbc2q.18d465a411965001,reason=Started count=1 msg=Started container task
0.1333,Event,ADDED,eval-conflicts-rho005-r5-055.18d465a3ef7a51f3,reason=SuccessfulCreate count=1 msg=Created pod: eval-conflicts-rho005-r5-055-qbc2q
0.1335,Event,ADDED,eval-conflicts-rho005-r5-055.18d465a750b4324b,reason=Completed count=1 msg=Job completed
0.1337,Event,ADDED,eval-conflicts-rho005-r5-056-v7m2g.18d465a42be1c4d9,reason=Scheduled count=None msg=Successfully assigned compute/eval-conflicts-rho005-r5-056-v7m2g to kind-worker4
0.1351,Node,MODIFIED,kind-worker5,taints=0
0.1354,Event,ADDED,eval-conflicts-rho005-r5-056-v7m2g.18d465a4453f07e0,"reason=Pulled count=1 msg=Container image ""busybox:musl"" already present on machine"
0.1356,Event,ADDED,eval-conflicts-rho005-r5-056-v7m2g.18d465a44668f129,reason=Created count=1 msg=Created container: task
0.1359,Event,ADDED,eval-conflicts-rho005-r5-056-v7m2g.18d465a44b670ddf,reason=Started count=1 msg=Started container task
0.1361,Event,ADDED,eval-conflicts-rho005-r5-056.18d465a42b128ae0,reason=SuccessfulCreate count=1 msg=Created pod: eval-conflicts-rho005-r5-056-v7m2g
0.1363,Event,ADDED,eval-conflicts-rho005-r5-056.18d465a78c526988,reason=Completed count=1 msg=Job completed
0.1365,Event,ADDED,eval-conflicts-rho005-r5-057-pzdr5.18d465a467398247,reason=Scheduled count=None msg=Successfully assigned compute/eval-conflicts-rho005-r5-057-pzdr5 to kind-worker4
0.1366,Event,ADDED,eval-conflicts-rho005-r5-057-pzdr5.18d465a4804451ca,"reason=Pulled count=1 msg=Container image ""busybox:musl"" already present on machine"
0.1368,Event,ADDED,eval-conflicts-rho005-r5-057-pzdr5.18d465a4819d1435,reason=Created count=1 msg=Created container: task
0.137,Event,ADDED,eval-conflicts-rho005-r5-057-pzdr5.18d465a483aea8fb,reason=Started count=1 msg=Started container task
0.1372,Event,ADDED,eval-conflicts-rho005-r5-057.18d465a466930348,reason=SuccessfulCreate count=1 msg=Created pod: eval-conflicts-rho005-r5-057-pzdr5
0.1374,Event,ADDED,eval-conflicts-rho005-r5-057.18d465a7c85a809d,reason=Completed count=1 msg=Job completed
0.1375,Event,ADDED,eval-conflicts-rho005-r5-058-lcwj4.18d465a4a2af507b,reason=Scheduled count=None msg=Successfully assigned compute/eval-conflicts-rho005-r5-058-lcwj4 to kind-worker3
0.1377,Event,ADDED,eval-conflicts-rho005-r5-058-lcwj4.18d465a4bc5f4fda,"reason=Pulled count=1 msg=Container image ""busybox:musl"" already present on machine"
0.1379,Event,ADDED,eval-conflicts-rho005-r5-058-lcwj4.18d465a4bd8f733f,reason=Created count=1 msg=Created container: task
0.138,Event,ADDED,eval-conflicts-rho005-r5-058-lcwj4.18d465a4bfbb0f11,reason=Started count=1 msg=Started container task
0.1382,Event,ADDED,eval-conflicts-rho005-r5-058.18d465a4a1e2c6ac,reason=SuccessfulCreate count=1 msg=Created pod: eval-conflicts-rho005-r5-058-lcwj4
0.1384,Event,ADDED,eval-conflicts-rho005-r5-058.18d465a7fd3eb7a4,reason=Completed count=1 msg=Job completed
0.1385,Event,ADDED,eval-conflicts-rho005-r5-059-mwp5j.18d465a4de8c1a44,reason=Scheduled count=None msg=Successfully assigned compute/eval-conflicts-rho005-r5-059-mwp5j to kind-worker5
0.1388,Event,ADDED,eval-conflicts-rho005-r5-059-mwp5j.18d465a4f6f0ff08,"reason=Pulled count=1 msg=Container image ""busybox:musl"" already present on machine"
0.139,Event,ADDED,eval-conflicts-rho005-r5-059-mwp5j.18d465a4f80bdef4,reason=Created count=1 msg=Created container: task
0.1392,Event,ADDED,eval-conflicts-rho005-r5-059-mwp5j.18d465a4fa180d88,reason=Started count=1 msg=Started container task
0.1394,Event,ADDED,eval-conflicts-rho005-r5-059.18d465a4dd75310a,reason=SuccessfulCreate count=1 msg=Created pod: eval-conflicts-rho005-r5-059-mwp5j
0.1396,Event,ADDED,eval-conflicts-rho005-r5-059.18d465a814bd9077,reason=Completed count=1 msg=Job completed
0.1397,Event,ADDED,eval-conflicts-rho005-r5-060-n4nsg.18d465a51aa89f8e,reason=Scheduled count=None msg=Successfully assigned compute/eval-conflicts-rho005-r5-060-n4nsg to kind-worker5
0.14,Event,ADDED,eval-conflicts-rho005-r5-060-n4nsg.18d465a53494f56a,"reason=Pulled count=1 msg=Container image ""busybox:musl"" already present on machine"
0.1401,Event,ADDED,eval-conflicts-rho005-r5-060-n4nsg.18d465a535beea2d,reason=Created count=1 msg=Created container: task
0.1405,Event,ADDED,eval-conflicts-rho005-r5-060-n4nsg.18d465a537eafb81,reason=Started count=1 msg=Started container task
0.1406,Event,ADDED,eval-conflicts-rho005-r5-060.18d465a5193c02be,reason=SuccessfulCreate count=1 msg=Created pod: eval-conflicts-rho005-r5-060-n4nsg
0.1409,Event,ADDED,eval-conflicts-rho005-r5-060.18d465a8507b925e,reason=Completed count=1 msg=Job completed
0.1412,Event,ADDED,eval-conflicts-rho005-r5-061-ljc59.18d465a555eb5c31,reason=Scheduled count=None msg=Successfully assigned compute/eval-conflicts-rho005-r5-061-ljc59 to kind-worker3
0.1415,Event,ADDED,eval-conflicts-rho005-r5-061-ljc59.18d465a56f403411,"reason=Pulled count=1 msg=Container image ""busybox:musl"" already present on machine"
0.1417,Event,ADDED,eval-conflicts-rho005-r5-061-ljc59.18d465a5708685b7,reason=Created count=1 msg=Created container: task
0.1419,Event,ADDED,eval-conflicts-rho005-r5-061-ljc59.18d465a5729b673b,reason=Started count=1 msg=Started container task
0.1423,Event,ADDED,eval-conflicts-rho005-r5-061.18d465a554c899e2,reason=SuccessfulCreate count=1 msg=Created pod: eval-conflicts-rho005-r5-061-ljc59
0.1429,Event,ADDED,eval-conflicts-rho005-r5-061.18d465a87533d04e,reason=Completed count=1 msg=Job completed
0.1431,Event,ADDED,eval-conflicts-rho005-r5-062-8b9tz.18d465a591bd4a8b,reason=Scheduled count=None msg=Successfully assigned compute/eval-conflicts-rho005-r5-062-8b9tz to kind-worker5
0.1433,Event,ADDED,eval-conflicts-rho005-r5-062-8b9tz.18d465a5ab85406d,"reason=Pulled count=1 msg=Container image ""busybox:musl"" already present on machine"
0.1437,Event,ADDED,eval-conflicts-rho005-r5-062-8b9tz.18d465a5aca1701d,reason=Created count=1 msg=Created container: task
0.1439,Event,ADDED,eval-conflicts-rho005-r5-062-8b9tz.18d465a5b1b70b15,reason=Started count=1 msg=Started container task
0.1441,Event,ADDED,eval-conflicts-rho005-r5-062.18d465a59081ad30,reason=SuccessfulCreate count=1 msg=Created pod: eval-conflicts-rho005-r5-062-8b9tz
0.1455,Node,MODIFIED,kind-worker5,taints=0
0.1458,Event,ADDED,eval-conflicts-rho005-r5-062.18d465a88cda8603,reason=Completed count=1 msg=Job completed
0.1459,Event,ADDED,eval-conflicts-rho005-r5-063-75zfp.18d465a5ce30406a,reason=Scheduled count=None msg=Successfully assigned compute/eval-conflicts-rho005-r5-063-75zfp to kind-worker5
0.1461,Event,ADDED,eval-conflicts-rho005-r5-063-75zfp.18d465a5e737e1d9,"reason=Pulled count=1 msg=Container image ""busybox:musl"" already present on machine"
0.1463,Event,ADDED,eval-conflicts-rho005-r5-063-75zfp.18d465a5e8557df4,reason=Created count=1 msg=Created container: task
0.1466,Event,ADDED,eval-conflicts-rho005-r5-063-75zfp.18d465a5ea66607d,reason=Started count=1 msg=Started container task
0.1468,Event,ADDED,eval-conflicts-rho005-r5-063.18d465a5cd0f717b,reason=SuccessfulCreate count=1 msg=Created pod: eval-conflicts-rho005-r5-063-75zfp
0.147,Event,ADDED,eval-conflicts-rho005-r5-063.18d465a90442c941,reason=Completed count=1 msg=Job completed
0.1471,Event,ADDED,eval-conflicts-rho005-r5-064-6f24d.18d465a609acc66f,reason=Scheduled count=None msg=Successfully assigned compute/eval-conflicts-rho005-r5-064-6f24d to kind-worker5
0.1477,Event,ADDED,eval-conflicts-rho005-r5-064-6f24d.18d465a622bec354,"reason=Pulled count=1 msg=Container image ""busybox:musl"" already present on machine"
0.148,Event,ADDED,eval-conflicts-rho005-r5-064-6f24d.18d465a623fc4c1b,reason=Created count=1 msg=Created container: task
0.1482,Event,ADDED,eval-conflicts-rho005-r5-064-6f24d.18d465a626780a25,reason=Started count=1 msg=Started container task
0.1484,Event,ADDED,eval-conflicts-rho005-r5-064.18d465a60848c186,reason=SuccessfulCreate count=1 msg=Created pod: eval-conflicts-rho005-r5-064-6f24d
0.1486,Event,ADDED,eval-conflicts-rho005-r5-064.18d465a940459f3f,reason=Completed count=1 msg=Job completed
0.1488,Event,ADDED,eval-conflicts-rho005-r5-065-cbcq2.18d465a6442568a5,reason=Scheduled count=None msg=Successfully assigned compute/eval-conflicts-rho005-r5-065-cbcq2 to kind-worker
0.1489,Event,ADDED,eval-conflicts-rho005-r5-065-cbcq2.18d465a65da10889,"reason=Pulled count=1 msg=Container image ""busybox:musl"" already present on machine"
0.1493,Event,ADDED,eval-conflicts-rho005-r5-065-cbcq2.18d465a65eb3579f,reason=Created count=1 msg=Created container: task
0.1494,Event,ADDED,eval-conflicts-rho005-r5-065-cbcq2.18d465a660e64d8d,reason=Started count=1 msg=Started container task
0.1496,Event,ADDED,eval-conflicts-rho005-r5-065.18d465a6431bbef5,reason=SuccessfulCreate count=1 msg=Created pod: eval-conflicts-rho005-r5-065-cbcq2
0.1499,Event,ADDED,eval-conflicts-rho005-r5-065.18d465a972593236,reason=Completed count=1 msg=Job completed
0.15,Event,ADDED,eval-conflicts-rho005-r5-066-b49fn.18d465a680a291e0,reason=Scheduled count=None msg=Successfully assigned compute/eval-conflicts-rho005-r5-066-b49fn to kind-worker
0.1502,Event,ADDED,eval-conflicts-rho005-r5-066-b49fn.18d465a699b6b8f8,"reason=Pulled count=1 msg=Container image ""busybox:musl"" already present on machine"
0.1504,Event,ADDED,eval-conflicts-rho005-r5-066-b49fn.18d465a69acb8b4f,reason=Created count=1 msg=Created container: task
0.1507,Event,ADDED,eval-conflicts-rho005-r5-066-b49fn.18d465a69cf783e4,reason=Started count=1 msg=Started container task
0.1508,Event,ADDED,eval-conflicts-rho005-r5-066.18d465a67f5c9991,reason=SuccessfulCreate count=1 msg=Created pod: eval-conflicts-rho005-r5-066-b49fn
0.151,Event,ADDED,eval-conflicts-rho005-r5-066.18d465a9ae8766ea,reason=Completed count=1 msg=Job completed
0.1512,Event,ADDED,eval-conflicts-rho005-r5-067-hqr6h.18d465a6bb753bbf,reason=Scheduled count=None msg=Successfully assigned compute/eval-conflicts-rho005-r5-067-hqr6h to kind-worker
0.1514,Event,ADDED,eval-conflicts-rho005-r5-067-hqr6h.18d465a6d4d97edc,"reason=Pulled count=1 msg=Container image ""busybox:musl"" already present on machine"
0.1518,Event,ADDED,eval-conflicts-rho005-r5-067-hqr6h.18d465a6d5ed6c84,reason=Created count=1 msg=Created container: task
0.1521,Event,ADDED,eval-conflicts-rho005-r5-067-hqr6h.18d465a6d7edd689,reason=Started count=1 msg=Started container task
0.1523,Event,ADDED,eval-conflicts-rho005-r5-067.18d465a6ba320916,reason=SuccessfulCreate count=1 msg=Created pod: eval-conflicts-rho005-r5-067-hqr6h
0.1524,Event,ADDED,eval-conflicts-rho005-r5-067.18d465a9ea515b5a,reason=Completed count=1 msg=Job completed
0.1526,Event,ADDED,eval-conflicts-rho005-r5-068-t9ml8.18d465a6f73feaf4,reason=Scheduled count=None msg=Successfully assigned compute/eval-conflicts-rho005-r5-068-t9ml8 to kind-worker
0.1528,Event,ADDED,eval-conflicts-rho005-r5-068-t9ml8.18d465a71046d13d,"reason=Pulled count=1 msg=Container image ""busybox:musl"" already present on machine"
0.1531,Event,ADDED,eval-conflicts-rho005-r5-068-t9ml8.18d465a71169f7a5,reason=Created count=1 msg=Created container: task
0.1532,Event,ADDED,eval-conflicts-rho005-r5-068-t9ml8.18d465a713662704,reason=Started count=1 msg=Started container task
0.1534,Event,ADDED,eval-conflicts-rho005-r5-068.18d465a6f664d4ad,reason=SuccessfulCreate count=1 msg=Created pod: eval-conflicts-rho005-r5-068-t9ml8
0.1536,Event,ADDED,eval-conflicts-rho005-r5-068.18d465aa25eac0aa,reason=Completed count=1 msg=Job completed
0.1539,Event,ADDED,eval-conflicts-rho005-r5-069-l9dlg.18d465a73251d5f6,reason=Scheduled count=None msg=Successfully assigned compute/eval-conflicts-rho005-r5-069-l9dlg to kind-worker
0.154,Event,ADDED,eval-conflicts-rho005-r5-069-l9dlg.18d465a74b5bc019,"reason=Pulled count=1 msg=Container image ""busybox:musl"" already present on machine"
0.1542,Event,ADDED,eval-conflicts-rho005-r5-069-l9dlg.18d465a74c748eab,reason=Created count=1 msg=Created container: task
0.1545,Event,ADDED,eval-conflicts-rho005-r5-069-l9dlg.18d465a74eb502ca,reason=Started count=1 msg=Started container task
0.1547,Event,ADDED,eval-conflicts-rho005-r5-069.18d465a731a79586,reason=SuccessfulCreate count=1 msg=Created pod: eval-conflicts-rho005-r5-069-l9dlg
0.1549,Event,ADDED,eval-conflicts-rho005-r5-069.18d465aa61f5e16f,reason=Completed count=1 msg=Job completed
0.1551,Event,ADDED,eval-conflicts-rho005-r5-070-8xgs6.18d465a76dbca052,reason=Scheduled count=None msg=Successfully assigned compute/eval-conflicts-rho005-r5-070-8xgs6 to kind-worker
0.1555,Event,ADDED,eval-conflicts-rho005-r5-070-8xgs6.18d465a78771ac5e,"reason=Pulled count=1 msg=Container image ""busybox:musl"" already present on machine"
0.1557,Event,ADDED,eval-conflicts-rho005-r5-070-8xgs6.18d465a78894b147,reason=Created count=1 msg=Created container: task
0.1559,Event,ADDED,eval-conflicts-rho005-r5-070-8xgs6.18d465a7901ecd19,reason=Started count=1 msg=Started container task
0.1562,Event,ADDED,eval-conflicts-rho005-r5-070.18d465a76d09e5ab,reason=SuccessfulCreate count=1 msg=Created pod: eval-conflicts-rho005-r5-070-8xgs6
0.1563,Event,ADDED,eval-conflicts-rho005-r5-070.18d465aa9de6c402,reason=Completed count=1 msg=Job completed
0.1565,Event,ADDED,eval-conflicts-rho005-r5-071-9zrwq.18d465a7a93723ed,reason=Scheduled count=None msg=Successfully assigned compute/eval-conflicts-rho005-r5-071-9zrwq to kind-worker
0.1567,Event,ADDED,eval-conflicts-rho005-r5-071-9zrwq.18d465a7c3238d25,"reason=Pulled count=1 msg=Container image ""busybox:musl"" already present on machine"
0.157,Event,ADDED,eval-conflicts-rho005-r5-071-9zrwq.18d465a7c43febe0,reason=Created count=1 msg=Created container: task
0.1571,Event,ADDED,eval-conflicts-rho005-r5-071-9zrwq.18d465a7c6575423,reason=Started count=1 msg=Started container task
0.1573,Event,ADDED,eval-conflicts-rho005-r5-071.18d465a7a8a5a1ba,reason=SuccessfulCreate count=1 msg=Created pod: eval-conflicts-rho005-r5-071-9zrwq
0.1575,Event,ADDED,eval-conflicts-rho005-r5-071.18d465aada437055,reason=Completed count=1 msg=Job completed
0.1577,Event,ADDED,eval-conflicts-rho005-r5-072-lwmfk.18d465a7e5277029,reason=Scheduled count=None msg=Successfully assigned compute/eval-conflicts-rho005-r5-072-lwmfk to kind-worker
0.1579,Event,ADDED,eval-conflicts-rho005-r5-072-lwmfk.18d465a7ff31ac4a,"reason=Pulled count=1 msg=Container image ""busybox:musl"" already present on machine"
0.158,Event,ADDED,eval-conflicts-rho005-r5-072-lwmfk.18d465a800467380,reason=Created count=1 msg=Created container: task
0.1582,Event,ADDED,eval-conflicts-rho005-r5-072-lwmfk.18d465a802371e66,reason=Started count=1 msg=Started container task
0.1584,Event,ADDED,eval-conflicts-rho005-r5-072.18d465a7e493a015,reason=SuccessfulCreate count=1 msg=Created pod: eval-conflicts-rho005-r5-072-lwmfk
0.1585,Event,ADDED,eval-conflicts-rho005-r5-072.18d465ab163e0fb9,reason=Completed count=1 msg=Job completed
0.1587,Event,ADDED,eval-conflicts-rho005-r5-073-h77wp.18d465a82186fb92,reason=Scheduled count=None msg=Successfully assigned compute/eval-conflicts-rho005-r5-073-h77wp to kind-worker
0.1589,Event,ADDED,eval-conflicts-rho005-r5-073-h77wp.18d465a83a7e2a6b,"reason=Pulled count=1 msg=Container image ""busybox:musl"" already present on machine"
0.159,Event,ADDED,eval-conflicts-rho005-r5-073-h77wp.18d465a83b926ba4,reason=Created count=1 msg=Created container: task
0.1592,Event,ADDED,eval-conflicts-rho005-r5-073-h77wp.18d465a83f43c3a1,reason=Started count=1 msg=Started container task
0.1594,Event,ADDED,eval-conflicts-rho005-r5-073.18d465a82103c70c,reason=SuccessfulCreate count=1 msg=Created pod: eval-conflicts-rho005-r5-073-h77wp
0.1597,Event,ADDED,eval-conflicts-rho005-r5-073.18d465ab5216f89a,reason=Completed count=1 msg=Job completed
0.16,Event,ADDED,eval-conflicts-rho005-r5-074-qhwcw.18d465a897c83f9c,"reason=FailedScheduling count=None msg=0/6 nodes are available: 6 node(s) had untolerated taint(s). no new claims to deallocate, preemption: 0/6 nodes are available: 6 Preemption is not helpful for scheduling."
0.1603,Event,ADDED,eval-conflicts-rho005-r5-074-qhwcw.18d465a89c6aeda4,reason=Scheduled count=None msg=Successfully assigned compute/eval-conflicts-rho005-r5-074-qhwcw to kind-worker4
0.1614,Event,ADDED,eval-conflicts-rho005-r5-074-qhwcw.18d465a8b5c34b9c,"reason=Pulled count=1 msg=Container image ""busybox:musl"" already present on machine"
0.1618,Event,ADDED,eval-conflicts-rho005-r5-074-qhwcw.18d465a8b7420143,reason=Created count=1 msg=Created container: task
0.1621,Event,ADDED,eval-conflicts-rho005-r5-074-qhwcw.18d465a8bab6902b,reason=Started count=1 msg=Started container task
0.1624,Event,ADDED,eval-conflicts-rho005-r5-074.18d465a897bd15a3,reason=SuccessfulCreate count=1 msg=Created pod: eval-conflicts-rho005-r5-074-qhwcw
0.1627,Event,ADDED,eval-conflicts-rho005-r5-074.18d465abfbe2a690,reason=Completed count=1 msg=Job completed
0.163,Event,ADDED,eval-conflicts-rho005-r5-075-n5n4r.18d465a89d09ee3e,"reason=FailedScheduling count=None msg=0/6 nodes are available: 1 c_wall violated: 1 conflicting context pair(s) with node memory, 5 node(s) had untolerated taint(s). no new claims to deallocate, preemption: 0/6 nodes are available: 1 No preemption victims found for incoming pod, 5 Preemption is not helpful for scheduling."
0.1633,Event,ADDED,eval-conflicts-rho005-r5-075-n5n4r.18d465a89df13b15,"reason=FailedScheduling count=None msg=0/6 nodes are available: 1 c_wall violated: 1 conflicting context pair(s) with node memory, 5 node(s) had untolerated taint(s). no new claims to deallocate, preemption: 0/6 nodes are available: 1 No preemption victims found for incoming pod, 5 Preemption is not helpful for scheduling."
0.1636,Event,ADDED,eval-conflicts-rho005-r5-075-n5n4r.18d465a8a1fbed28,reason=Scheduled count=None msg=Successfully assigned compute/eval-conflicts-rho005-r5-075-n5n4r to kind-worker2
0.1639,Event,ADDED,eval-conflicts-rho005-r5-075-n5n4r.18d465a8baf296e3,"reason=Pulled count=1 msg=Container image ""busybox:musl"" already present on machine"
0.1642,Event,ADDED,eval-conflicts-rho005-r5-075-n5n4r.18d465a8bc0a3db0,reason=Created count=1 msg=Created container: task
0.1645,Event,ADDED,eval-conflicts-rho005-r5-075-n5n4r.18d465a8bdf29bc6,reason=Started count=1 msg=Started container task
0.1647,Event,ADDED,eval-conflicts-rho005-r5-075.18d465a89cc702b3,reason=SuccessfulCreate count=1 msg=Created pod: eval-conflicts-rho005-r5-075-n5n4r
0.165,Event,ADDED,eval-conflicts-rho005-r5-075.18d465abec6d2580,reason=Completed count=1 msg=Job completed
0.1652,Event,ADDED,eval-conflicts-rho005-r5-076-n97gv.18d465a8d4b15b6b,reason=Scheduled count=None msg=Successfully assigned compute/eval-conflicts-rho005-r5-076-n97gv to kind-worker2
0.1655,Event,ADDED,eval-conflicts-rho005-r5-076-n97gv.18d465a8ee1f21fc,"reason=Pulled count=1 msg=Container image ""busybox:musl"" already present on machine"
0.1658,Event,ADDED,eval-conflicts-rho005-r5-076-n97gv.18d465a8ef2e9e33,reason=Created count=1 msg=Created container: task
0.1663,Event,ADDED,eval-conflicts-rho005-r5-076-n97gv.18d465a8f13744ab,reason=Started count=1 msg=Started container task
0.1666,Event,ADDED,eval-conflicts-rho005-r5-076.18d465a8d376efae,reason=SuccessfulCreate count=1 msg=Created pod: eval-conflicts-rho005-r5-076-n97gv
0.1672,Event,ADDED,eval-conflicts-rho005-r5-076.18d465ac282be548,reason=Completed count=1 msg=Job completed
0.1676,Event,ADDED,eval-conflicts-rho005-r5-077-6bnc4.18d465a90f919827,reason=Scheduled count=None msg=Successfully assigned compute/eval-conflicts-rho005-r5-077-6bnc4 to kind-worker4
0.1679,Event,ADDED,eval-conflicts-rho005-r5-077-6bnc4.18d465a928c729b9,"reason=Pulled count=1 msg=Container image ""busybox:musl"" already present on machine"
0.1683,Event,ADDED,eval-conflicts-rho005-r5-077-6bnc4.18d465a929e1e002,reason=Created count=1 msg=Created container: task
0.1686,Event,ADDED,eval-conflicts-rho005-r5-077-6bnc4.18d465a92d6eb392,reason=Started count=1 msg=Started container task
0.169,Event,ADDED,eval-conflicts-rho005-r5-077.18d465a90eca58ed,reason=SuccessfulCreate count=1 msg=Created pod: eval-conflicts-rho005-r5-077-6bnc4
0.1692,Event,ADDED,eval-conflicts-rho005-r5-077.18d465ac37a2f8f3,reason=Completed count=1 msg=Job completed
0.1695,Event,ADDED,eval-conflicts-rho005-r5-078-snxsc.18d465a94b1e747e,reason=Scheduled count=None msg=Successfully assigned compute/eval-conflicts-rho005-r5-078-snxsc to kind-worker2
0.1698,Event,ADDED,eval-conflicts-rho005-r5-078-snxsc.18d465a964712dfc,"reason=Pulled count=1 msg=Container image ""busybox:musl"" already present on machine"
0.17,Event,ADDED,eval-conflicts-rho005-r5-078-snxsc.18d465a9657f8ab2,reason=Created count=1 msg=Created container: task
0.1703,Event,ADDED,eval-conflicts-rho005-r5-078-snxsc.18d465a967b0fcd3,reason=Started count=1 msg=Started container task
0.1706,Event,ADDED,eval-conflicts-rho005-r5-078.18d465a94a2c7cd5,reason=SuccessfulCreate count=1 msg=Created pod: eval-conflicts-rho005-r5-078-snxsc
0.171,Event,ADDED,eval-conflicts-rho005-r5-078.18d465aca01f0385,reason=Completed count=1 msg=Job completed
0.1712,Event,ADDED,eval-conflicts-rho005-r5-079-ftkg7.18d465a98680b3db,reason=Scheduled count=None msg=Successfully assigned compute/eval-conflicts-rho005-r5-079-ftkg7 to kind-worker2
0.1717,Event,ADDED,eval-conflicts-rho005-r5-079-ftkg7.18d465a99eb2caf5,"reason=Pulled count=1 msg=Container image ""busybox:musl"" already present on machine"
0.172,Event,ADDED,eval-conflicts-rho005-r5-079-ftkg7.18d465a99fbe03ef,reason=Created count=1 msg=Created container: task
0.1723,Event,ADDED,eval-conflicts-rho005-r5-079-ftkg7.18d465a9a1ee17f3,reason=Started count=1 msg=Started container task
0.1725,Event,ADDED,eval-conflicts-rho005-r5-079.18d465a985894d94,reason=SuccessfulCreate count=1 msg=Created pod: eval-conflicts-rho005-r5-079-ftkg7
0.1728,Event,ADDED,eval-conflicts-rho005-r5-079.18d465acdbb6bdd3,reason=Completed count=1 msg=Job completed
0.173,Event,ADDED,eval-conflicts-rho005-r5-080-qg5mm.18d465a9c2a8f538,reason=Scheduled count=None msg=Successfully assigned compute/eval-conflicts-rho005-r5-080-qg5mm to kind-worker5
0.1732,Event,ADDED,eval-conflicts-rho005-r5-080-qg5mm.18d465a9dc34ee48,"reason=Pulled count=1 msg=Container image ""busybox:musl"" already present on machine"
0.1735,Event,ADDED,eval-conflicts-rho005-r5-080-qg5mm.18d465a9dd4aa9a5,reason=Created count=1 msg=Created container: task
0.1737,Event,ADDED,eval-conflicts-rho005-r5-080-qg5mm.18d465a9e1817b29,reason=Started count=1 msg=Started container task
0.1738,Event,ADDED,eval-conflicts-rho005-r5-080.18d465a9c1bb948d,reason=SuccessfulCreate count=1 msg=Created pod: eval-conflicts-rho005-r5-080-qg5mm
0.174,Event,ADDED,eval-conflicts-rho005-r5-080.18d465acfc741586,reason=Completed count=1 msg=Job completed
0.1743,Event,ADDED,eval-conflicts-rho005-r5-081-5bdgl.18d465a9fdea2911,reason=Scheduled count=None msg=Successfully assigned compute/eval-conflicts-rho005-r5-081-5bdgl to kind-worker2
0.1745,Event,ADDED,eval-conflicts-rho005-r5-081-5bdgl.18d465aa182853ca,"reason=Pulled count=1 msg=Container image ""busybox:musl"" already present on machine"
0.1748,Event,ADDED,eval-conflicts-rho005-r5-081-5bdgl.18d465aa1940b318,reason=Created count=1 msg=Created container: task
0.175,Event,ADDED,eval-conflicts-rho005-r5-081-5bdgl.18d465aa1da0a265,reason=Started count=1 msg=Started container task
0.1752,Event,ADDED,eval-conflicts-rho005-r5-081.18d465a9fca65e0e,reason=SuccessfulCreate count=1 msg=Created pod: eval-conflicts-rho005-r5-081-5bdgl
0.1753,Event,ADDED,eval-conflicts-rho005-r5-081.18d465ad53f0b8f3,reason=Completed count=1 msg=Job completed
0.1757,Event,ADDED,eval-conflicts-rho005-r5-082-5dsfb.18d465aa3a2cdc42,reason=Scheduled count=None msg=Successfully assigned compute/eval-conflicts-rho005-r5-082-5dsfb to kind-worker5
0.1759,Event,ADDED,eval-conflicts-rho005-r5-082-5dsfb.18d465aa54b85286,"reason=Pulled count=1 msg=Container image ""busybox:musl"" already present on machine"
0.1761,Event,ADDED,eval-conflicts-rho005-r5-082-5dsfb.18d465aa55effbb4,reason=Created count=1 msg=Created container: task
0.1765,Event,ADDED,eval-conflicts-rho005-r5-082-5dsfb.18d465aa60d94d13,reason=Started count=1 msg=Started container task
0.1766,Event,ADDED,eval-conflicts-rho005-r5-082.18d465aa38eebb6f,reason=SuccessfulCreate count=1 msg=Created pod: eval-conflicts-rho005-r5-082-5dsfb
0.1768,Event,ADDED,eval-conflicts-rho005-r5-082.18d465ad74e9ce23,reason=Completed count=1 msg=Job completed
0.177,Event,ADDED,eval-conflicts-rho005-r5-083-dwpps.18d465aa75a1ac50,reason=Scheduled count=None msg=Successfully assigned compute/eval-conflicts-rho005-r5-083-dwpps to kind-worker5
0.1772,Event,ADDED,eval-conflicts-rho005-r5-083-dwpps.18d465aa8fe54029,"reason=Pulled count=1 msg=Container image ""busybox:musl"" already present on machine"
0.1774,Event,ADDED,eval-conflicts-rho005-r5-083-dwpps.18d465aa91011ea0,reason=Created count=1 msg=Created container: task
0.1776,Event,ADDED,eval-conflicts-rho005-r5-083-dwpps.18d465aa9310c20a,reason=Started count=1 msg=Started container task
0.1779,Event,ADDED,eval-conflicts-rho005-r5-083.18d465aa74761da2,reason=SuccessfulCreate count=1 msg=Created pod: eval-conflicts-rho005-r5-083-dwpps
0.1781,Event,ADDED,eval-conflicts-rho005-r5-083.18d465adb01550ec,reason=Completed count=1 msg=Job completed
0.1782,Event,ADDED,eval-conflicts-rho005-r5-084-gjjkd.18d465aab18f4041,reason=Scheduled count=None msg=Successfully assigned compute/eval-conflicts-rho005-r5-084-gjjkd to kind-worker4
0.1784,Event,ADDED,eval-conflicts-rho005-r5-084-gjjkd.18d465aacb504113,"reason=Pulled count=1 msg=Container image ""busybox:musl"" already present on machine"
0.1787,Event,ADDED,eval-conflicts-rho005-r5-084-gjjkd.18d465aacc6945f7,reason=Created count=1 msg=Created container: task
0.1789,Event,ADDED,eval-conflicts-rho005-r5-084-gjjkd.18d465aace669643,reason=Started count=1 msg=Started container task
0.1791,Event,ADDED,eval-conflicts-rho005-r5-084.18d465aab04d5732,reason=SuccessfulCreate count=1 msg=Created pod: eval-conflicts-rho005-r5-084-gjjkd
0.1792,Event,ADDED,eval-conflicts-rho005-r5-084.18d465addadb376e,reason=Completed count=1 msg=Job completed
0.1795,Event,ADDED,eval-conflicts-rho005-r5-085-dd2jk.18d465aaec7bf2c2,reason=Scheduled count=None msg=Successfully assigned compute/eval-conflicts-rho005-r5-085-dd2jk to kind-worker5
0.1797,Event,ADDED,eval-conflicts-rho005-r5-085-dd2jk.18d465ab04f2e018,"reason=Pulled count=1 msg=Container image ""busybox:musl"" already present on machine"
0.1799,Event,ADDED,eval-conflicts-rho005-r5-085-dd2jk.18d465ab062a17de,reason=Created count=1 msg=Created container: task
0.1804,Event,ADDED,eval-conflicts-rho005-r5-085-dd2jk.18d465ab08589605,reason=Started count=1 msg=Started container task
0.1806,Event,ADDED,eval-conflicts-rho005-r5-085.18d465aaeb2bda1a,reason=SuccessfulCreate count=1 msg=Created pod: eval-conflicts-rho005-r5-085-dd2jk
0.1808,Event,ADDED,eval-conflicts-rho005-r5-085.18d465ae283e943f,reason=Completed count=1 msg=Job completed
0.1809,Event,ADDED,eval-conflicts-rho005-r5-086-wxtwd.18d465ab27de3277,reason=Scheduled count=None msg=Successfully assigned compute/eval-conflicts-rho005-r5-086-wxtwd to kind-worker5
0.1813,Event,ADDED,eval-conflicts-rho005-r5-086-wxtwd.18d465ab40bd1164,"reason=Pulled count=1 msg=Container image ""busybox:musl"" already present on machine"
0.1815,Event,ADDED,eval-conflicts-rho005-r5-086-wxtwd.18d465ab41d8fd9d,reason=Created count=1 msg=Created container: task
0.1817,Event,ADDED,eval-conflicts-rho005-r5-086-wxtwd.18d465ab43d227ce,reason=Started count=1 msg=Started container task
0.1822,Event,ADDED,eval-conflicts-rho005-r5-086.18d465ab26ee5819,reason=SuccessfulCreate count=1 msg=Created pod: eval-conflicts-rho005-r5-086-wxtwd
0.1824,Event,ADDED,eval-conflicts-rho005-r5-086.18d465ae64107e52,reason=Completed count=1 msg=Job completed
0.1825,Event,ADDED,eval-conflicts-rho005-r5-087-98wcw.18d465ab642c154d,reason=Scheduled count=None msg=Successfully assigned compute/eval-conflicts-rho005-r5-087-98wcw to kind-worker3
0.1827,Event,ADDED,eval-conflicts-rho005-r5-087-98wcw.18d465ab7dcd05c0,"reason=Pulled count=1 msg=Container image ""busybox:musl"" already present on machine"
0.1831,Event,ADDED,eval-conflicts-rho005-r5-087-98wcw.18d465ab7edd983d,reason=Created count=1 msg=Created container: task
0.1833,Event,ADDED,eval-conflicts-rho005-r5-087-98wcw.18d465ab80b16bf0,reason=Started count=1 msg=Started container task
0.1835,Event,ADDED,eval-conflicts-rho005-r5-087.18d465ab6358da67,reason=SuccessfulCreate count=1 msg=Created pod: eval-conflicts-rho005-r5-087-98wcw
0.1838,Event,ADDED,eval-conflicts-rho005-r5-087.18d465aec2d7ca15,reason=Completed count=1 msg=Job completed
0.1841,Event,ADDED,eval-conflicts-rho005-r5-088-xd7hw.18d465ab9efc8331,reason=Scheduled count=None msg=Successfully assigned compute/eval-conflicts-rho005-r5-088-xd7hw to kind-worker3
0.1842,Event,ADDED,eval-conflicts-rho005-r5-088-xd7hw.18d465abb8be3963,"reason=Pulled count=1 msg=Container image ""busybox:musl"" already present on machine"
0.1844,Event,ADDED,eval-conflicts-rho005-r5-088-xd7hw.18d465abb9f8f431,reason=Created count=1 msg=Created container: task
0.1848,Event,ADDED,eval-conflicts-rho005-r5-088-xd7hw.18d465abbe1083b9,reason=Started count=1 msg=Started container task
0.1852,Event,ADDED,eval-conflicts-rho005-r5-088.18d465ab9e0852ff,reason=SuccessfulCreate count=1 msg=Created pod: eval-conflicts-rho005-r5-088-xd7hw
0.1854,Event,ADDED,eval-conflicts-rho005-r5-088.18d465aeff2817a7,reason=Completed count=1 msg=Job completed
0.1855,Event,ADDED,eval-conflicts-rho005-r5-089-vtc54.18d465abda497812,reason=Scheduled count=None msg=Successfully assigned compute/eval-conflicts-rho005-r5-089-vtc54 to kind-worker5
0.1859,Event,ADDED,eval-conflicts-rho005-r5-089-vtc54.18d465abf41f532f,"reason=Pulled count=1 msg=Container image ""busybox:musl"" already present on machine"
0.1861,Event,ADDED,eval-conflicts-rho005-r5-089-vtc54.18d465abf54747cc,reason=Created count=1 msg=Created container: task
0.1862,Event,ADDED,eval-conflicts-rho005-r5-089-vtc54.18d465abf77a958d,reason=Started count=1 msg=Started container task
0.1864,Event,ADDED,eval-conflicts-rho005-r5-089.18d465abd9a0aa74,reason=SuccessfulCreate count=1 msg=Created pod: eval-conflicts-rho005-r5-089-vtc54
0.1867,Event,ADDED,eval-conflicts-rho005-r5-089.18d465af17be7cea,reason=Completed count=1 msg=Job completed
0.1869,Event,ADDED,eval-conflicts-rho005-r5-090-znrkt.18d465ac14f9d372,"reason=FailedScheduling count=None msg=0/6 nodes are available: 6 node(s) had untolerated taint(s). no new claims to deallocate, preemption: 0/6 nodes are available: 6 Preemption is not helpful for scheduling."
0.187,Event,ADDED,eval-conflicts-rho005-r5-090-znrkt.18d465ad49d6065b,reason=Scheduled count=None msg=Successfully assigned compute/eval-conflicts-rho005-r5-090-znrkt to kind-worker
0.1872,Event,ADDED,eval-conflicts-rho005-r5-090-znrkt.18d465ad67030b81,"reason=Pulled count=1 msg=Container image ""busybox:musl"" already present on machine"
0.1874,Event,ADDED,eval-conflicts-rho005-r5-090-znrkt.18d465ad68cabc65,reason=Created count=1 msg=Created container: task
0.1876,Event,ADDED,eval-conflicts-rho005-r5-090-znrkt.18d465ad6c460550,reason=Started count=1 msg=Started container task
0.1877,Event,ADDED,eval-conflicts-rho005-r5-090.18d465ac14f08664,reason=SuccessfulCreate count=1 msg=Created pod: eval-conflicts-rho005-r5-090-znrkt
0.1879,Event,ADDED,eval-conflicts-rho005-r5-090.18d465b0b1bf89e4,reason=Completed count=1 msg=Job completed
0.188,Event,ADDED,eval-conflicts-rho005-r5-091-5sgpf.18d465ac50bf2c9d,"reason=FailedScheduling count=None msg=0/6 nodes are available: 6 node(s) had untolerated taint(s). no new claims to deallocate, preemption: 0/6 nodes are available: 6 Preemption is not helpful for scheduling."
0.1883,Event,ADDED,eval-conflicts-rho005-r5-091-5sgpf.18d465ad4ab86645,reason=Scheduled count=None msg=Successfully assigned compute/eval-conflicts-rho005-r5-091-5sgpf to kind-worker
0.1889,Event,ADDED,eval-conflicts-rho005-r5-091-5sgpf.18d465ad6722c03c,"reason=Pulled count=1 msg=Container image ""busybox:musl"" already present on machine"
0.1891,Event,ADDED,eval-conflicts-rho005-r5-091-5sgpf.18d465ad6956fb4d,reason=Created count=1 msg=Created container: task
0.1893,Event,ADDED,eval-conflicts-rho005-r5-091-5sgpf.18d465ad6d2199b7,reason=Started count=1 msg=Started container task
0.1895,Event,ADDED,eval-conflicts-rho005-r5-091.18d465ac50b17f75,reason=SuccessfulCreate count=1 msg=Created pod: eval-conflicts-rho005-r5-091-5sgpf
0.1899,Event,ADDED,eval-conflicts-rho005-r5-091.18d465b0b0e248fe,reason=Completed count=1 msg=Job completed
0.1901,Event,ADDED,eval-conflicts-rho005-r5-092-zl7bb.18d465ac8d6caa15,"reason=FailedScheduling count=None msg=0/6 nodes are available: 6 node(s) had untolerated taint(s). no new claims to deallocate, preemption: 0/6 nodes are available: 6 Preemption is not helpful for scheduling."
0.1902,Event,ADDED,eval-conflicts-rho005-r5-092-zl7bb.18d465ad4acd067a,reason=Scheduled count=None msg=Successfully assigned compute/eval-conflicts-rho005-r5-092-zl7bb to kind-worker
0.1906,Event,ADDED,eval-conflicts-rho005-r5-092-zl7bb.18d465ad697f7ad1,"reason=Pulled count=1 msg=Container image ""busybox:musl"" already present on machine"
0.1908,Event,ADDED,eval-conflicts-rho005-r5-092-zl7bb.18d465ad6b238ec9,reason=Created count=1 msg=Created container: task
0.191,Event,ADDED,eval-conflicts-rho005-r5-092-zl7bb.18d465ad6dc4f5da,reason=Started count=1 msg=Started container task
0.1911,Event,ADDED,eval-conflicts-rho005-r5-092.18d465ac8d600300,reason=SuccessfulCreate count=1 msg=Created pod: eval-conflicts-rho005-r5-092-zl7bb
0.1914,Event,ADDED,eval-conflicts-rho005-r5-092.18d465b0b0bfced6,reason=Completed count=1 msg=Job completed
0.1917,Event,ADDED,eval-conflicts-rho005-r5-093-pn6rt.18d465acc82d4ed2,"reason=FailedScheduling count=None msg=0/6 nodes are available: 6 node(s) had untolerated taint(s). no new claims to deallocate, preemption: 0/6 nodes are available: 6 Preemption is not helpful for scheduling."
0.1919,Event,ADDED,eval-conflicts-rho005-r5-093-pn6rt.18d465ad4a8b9fc7,"reason=FailedScheduling count=None msg=0/6 nodes are available: 1 c_wall violated: 1 conflicting context pair(s) with node memory, 5 node(s) had untolerated taint(s). no new claims to deallocate, preemption: 0/6 nodes are available: 1 No preemption victims found for incoming pod, 5 Preemption is not helpful for scheduling."
0.1922,Event,ADDED,eval-conflicts-rho005-r5-093-pn6rt.18d465ad4deece1f,"reason=FailedScheduling count=None msg=0/6 nodes are available: 1 c_wall violated: 1 conflicting context pair(s) with node memory, 5 node(s) had untolerated taint(s). no new claims to deallocate, preemption: 0/6 nodes are available: 1 No preemption victims found for incoming pod, 5 Preemption is not helpful for scheduling."
0.1924,Event,ADDED,eval-conflicts-rho005-r5-093-pn6rt.18d465ad791758f7,reason=Scheduled count=None msg=Successfully assigned compute/eval-conflicts-rho005-r5-093-pn6rt to kind-worker2
0.1925,Event,ADDED,eval-conflicts-rho005-r5-093-pn6rt.18d465ad92a9ae3e,"reason=Pulled count=1 msg=Container image ""busybox:musl"" already present on machine"
0.1927,Event,ADDED,eval-conflicts-rho005-r5-093-pn6rt.18d465ad93e702d8,reason=Created count=1 msg=Created container: task
0.193,Event,ADDED,eval-conflicts-rho005-r5-093-pn6rt.18d465ad985bec1a,reason=Started count=1 msg=Started container task
0.1932,Event,ADDED,eval-conflicts-rho005-r5-093.18d465acc8240e0e,reason=SuccessfulCreate count=1 msg=Created pod: eval-conflicts-rho005-r5-093-pn6rt
0.1934,Event,ADDED,eval-conflicts-rho005-r5-093.18d465b0d4366a29,reason=Completed count=1 msg=Job completed
0.1936,Event,ADDED,eval-conflicts-rho005-r5-094-csfd4.18d465ad044eb787,"reason=FailedScheduling count=None msg=0/6 nodes are available: 6 node(s) had untolerated taint(s). no new claims to deallocate, preemption: 0/6 nodes are available: 6 Preemption is not helpful for scheduling."
0.1937,Event,ADDED,eval-conflicts-rho005-r5-094-csfd4.18d465ad4df24efa,reason=Scheduled count=None msg=Successfully assigned compute/eval-conflicts-rho005-r5-094-csfd4 to kind-worker
0.1939,Event,ADDED,eval-conflicts-rho005-r5-094-csfd4.18d465ad695bf69e,"reason=Pulled count=1 msg=Container image ""busybox:musl"" already present on machine"
0.1941,Event,ADDED,eval-conflicts-rho005-r5-094-csfd4.18d465ad6ac2ace9,reason=Created count=1 msg=Created container: task
0.1943,Event,ADDED,eval-conflicts-rho005-r5-094-csfd4.18d465ad6d715f73,reason=Started count=1 msg=Started container task
0.1944,Event,ADDED,eval-conflicts-rho005-r5-094.18d465ad044095d6,reason=SuccessfulCreate count=1 msg=Created pod: eval-conflicts-rho005-r5-094-csfd4
0.1946,Event,ADDED,eval-conflicts-rho005-r5-094.18d465b0b2e377a6,reason=Completed count=1 msg=Job completed
0.1947,Event,ADDED,eval-conflicts-rho005-r5-095-s54sg.18d465ad3fce3209,"reason=FailedScheduling count=None msg=0/6 nodes are available: 6 node(s) had untolerated taint(s). no new claims to deallocate, preemption: 0/6 nodes are available: 6 Preemption is not helpful for scheduling."
0.1949,Event,ADDED,eval-conflicts-rho005-r5-095-s54sg.18d465ad4df26643,reason=Scheduled count=None msg=Successfully assigned compute/eval-conflicts-rho005-r5-095-s54sg to kind-worker
0.1951,Event,ADDED,eval-conflicts-rho005-r5-095-s54sg.18d465ad66eaefa3,"reason=Pulled count=1 msg=Container image ""busybox:musl"" already present on machine"
0.1953,Event,ADDED,eval-conflicts-rho005-r5-095-s54sg.18d465ad690d0a0f,reason=Created count=1 msg=Created container: task
0.1955,Event,ADDED,eval-conflicts-rho005-r5-095-s54sg.18d465ad6ccdbfbb,reason=Started count=1 msg=Started container task
0.1956,Event,ADDED,eval-conflicts-rho005-r5-095.18d465ad3fc2fa87,reason=SuccessfulCreate count=1 msg=Created pod: eval-conflicts-rho005-r5-095-s54sg
0.1958,Event,ADDED,eval-conflicts-rho005-r5-095.18d465b0b2968602,reason=Completed count=1 msg=Job completed
0.196,Event,ADDED,eval-conflicts-rho005-r5-096-cddq7.18d465ad7bcd4934,reason=Scheduled count=None msg=Successfully assigned compute/eval-conflicts-rho005-r5-096-cddq7 to kind-worker
0.1961,Event,ADDED,eval-conflicts-rho005-r5-096-cddq7.18d465ad98b02048,"reason=Pulled count=1 msg=Container image ""busybox:musl"" already present on machine"
0.1988,Event,ADDED,eval-conflicts-rho005-r5-096-cddq7.18d465ad99ebcb8c,reason=Created count=1 msg=Created container: task
0.199,Event,ADDED,eval-conflicts-rho005-r5-096-cddq7.18d465ad9dc317bd,reason=Started count=1 msg=Started container task
0.1992,Event,ADDED,eval-conflicts-rho005-r5-096.18d465ad7ad2ac6e,reason=SuccessfulCreate count=1 msg=Created pod: eval-conflicts-rho005-r5-096-cddq7
0.1994,Event,ADDED,eval-conflicts-rho005-r5-096.18d465b0b2ac9ba4,reason=Completed count=1 msg=Job completed
0.1995,Event,ADDED,eval-conflicts-rho005-r5-097-qt76d.18d465adb7bec02e,reason=Scheduled count=None msg=Successfully assigned compute/eval-conflicts-rho005-r5-097-qt76d to kind-worker2
0.1997,Event,ADDED,eval-conflicts-rho005-r5-097-qt76d.18d465add137cc90,"reason=Pulled count=1 msg=Container image ""busybox:musl"" already present on machine"
0.2001,Event,ADDED,eval-conflicts-rho005-r5-097-qt76d.18d465add26ba65a,reason=Created count=1 msg=Created container: task
0.2003,Event,ADDED,eval-conflicts-rho005-r5-097-qt76d.18d465add47d2747,reason=Started count=1 msg=Started container task
0.2005,Event,ADDED,eval-conflicts-rho005-r5-097.18d465adb6fd3e66,reason=SuccessfulCreate count=1 msg=Created pod: eval-conflicts-rho005-r5-097-qt76d
0.2006,Event,ADDED,eval-conflicts-rho005-r5-097.18d465b10fd07afc,reason=Completed count=1 msg=Job completed
0.201,Event,ADDED,eval-conflicts-rho005-r5-098-dm6cg.18d465adf4111996,reason=Scheduled count=None msg=Successfully assigned compute/eval-conflicts-rho005-r5-098-dm6cg to kind-worker2
0.2012,Event,ADDED,eval-conflicts-rho005-r5-098-dm6cg.18d465ae0db4a969,"reason=Pulled count=1 msg=Container image ""busybox:musl"" already present on machine"
0.2013,Event,ADDED,eval-conflicts-rho005-r5-098-dm6cg.18d465ae0ed5a236,reason=Created count=1 msg=Created container: task
0.2018,Event,ADDED,eval-conflicts-rho005-r5-098-dm6cg.18d465ae1398ac80,reason=Started count=1 msg=Started container task
0.202,Event,ADDED,eval-conflicts-rho005-r5-098.18d465adf2de31d7,reason=SuccessfulCreate count=1 msg=Created pod: eval-conflicts-rho005-r5-098-dm6cg
0.2021,Event,ADDED,eval-conflicts-rho005-r5-098.18d465b14bf7a20b,reason=Completed count=1 msg=Job completed
0.2023,Event,ADDED,eval-conflicts-rho005-r5-099-rwprb.18d465ae2e9d7c4a,reason=Scheduled count=None msg=Successfully assigned compute/eval-conflicts-rho005-r5-099-rwprb to kind-worker2
0.2025,Event,ADDED,eval-conflicts-rho005-r5-099-rwprb.18d465ae48ee12d9,"reason=Pulled count=1 msg=Container image ""busybox:musl"" already present on machine"
0.2027,Event,ADDED,eval-conflicts-rho005-r5-099-rwprb.18d465ae4a4b040e,reason=Created count=1 msg=Created container: task
0.2028,Event,ADDED,eval-conflicts-rho005-r5-099-rwprb.18d465ae532e4a2f,reason=Started count=1 msg=Started container task
0.203,Event,ADDED,eval-conflicts-rho005-r5-099.18d465ae2ddb3224,reason=SuccessfulCreate count=1 msg=Created pod: eval-conflicts-rho005-r5-099-rwprb
0.2032,Event,ADDED,eval-conflicts-rho005-r5-099.18d465b188a3ff56,reason=Completed count=1 msg=Job completed
0.2033,Event,ADDED,eval-conflicts-rho005-r6-000-cxd4s.18d465b6b1e6e738,reason=Scheduled count=None msg=Successfully assigned compute/eval-conflicts-rho005-r6-000-cxd4s to kind-worker
0.2035,Event,ADDED,eval-conflicts-rho005-r6-000-cxd4s.18d465b6ca3fa19a,"reason=Pulled count=1 msg=Container image ""busybox:musl"" already present on machine"
0.204,Event,ADDED,eval-conflicts-rho005-r6-000-cxd4s.18d465b6cb6d26ea,reason=Created count=1 msg=Created container: task
0.2043,Event,ADDED,eval-conflicts-rho005-r6-000-cxd4s.18d465b6cd98bcde,reason=Started count=1 msg=Started container task
0.2046,Event,ADDED,eval-conflicts-rho005-r6-000.18d465b6b107fedd,reason=SuccessfulCreate count=1 msg=Created pod: eval-conflicts-rho005-r6-000-cxd4s
0.2049,Event,ADDED,eval-conflicts-rho005-r6-000.18d465ba0786d3f0,reason=Completed count=1 msg=Job completed
0.2052,Event,ADDED,eval-conflicts-rho005-r6-001-zjp94.18d465b6ecb94876,reason=Scheduled count=None msg=Successfully assigned compute/eval-conflicts-rho005-r6-001-zjp94 to kind-worker5
0.2054,Event,ADDED,eval-conflicts-rho005-r6-001-zjp94.18d465b706a6b30d,"reason=Pulled count=1 msg=Container image ""busybox:musl"" already present on machine"
0.2056,Event,ADDED,eval-conflicts-rho005-r6-001-zjp94.18d465b707d0b5a3,reason=Created count=1 msg=Created container: task
0.2058,Event,ADDED,eval-conflicts-rho005-r6-001-zjp94.18d465b70bd8206f,reason=Started count=1 msg=Started container task
0.206,Event,ADDED,eval-conflicts-rho005-r6-001.18d465b6ec3c33be,reason=SuccessfulCreate count=1 msg=Created pod: eval-conflicts-rho005-r6-001-zjp94
0.2062,Event,ADDED,eval-conflicts-rho005-r6-001.18d465ba4aa42bad,reason=Completed count=1 msg=Job completed
0.2063,Event,ADDED,eval-conflicts-rho005-r6-002-v4jzl.18d465b727e2c572,reason=Scheduled count=None msg=Successfully assigned compute/eval-conflicts-rho005-r6-002-v4jzl to kind-worker5
0.2065,Event,ADDED,eval-conflicts-rho005-r6-002-v4jzl.18d465b7416bff8e,"reason=Pulled count=1 msg=Container image ""busybox:musl"" already present on machine"
0.2067,Event,ADDED,eval-conflicts-rho005-r6-002-v4jzl.18d465b74299a892,reason=Created count=1 msg=Created container: task
0.2069,Event,ADDED,eval-conflicts-rho005-r6-002-v4jzl.18d465b746aa7f7c,reason=Started count=1 msg=Started container task
0.207,Event,ADDED,eval-conflicts-rho005-r6-002.18d465b726dab341,reason=SuccessfulCreate count=1 msg=Created pod: eval-conflicts-rho005-r6-002-v4jzl
0.2072,Event,ADDED,eval-conflicts-rho005-r6-002.18d465ba86a0a6e5,reason=Completed count=1 msg=Job completed
0.2074,Event,ADDED,eval-conflicts-rho005-r6-003-dqvqj.18d465b763819d30,reason=Scheduled count=None msg=Successfully assigned compute/eval-conflicts-rho005-r6-003-dqvqj to kind-worker2
0.2077,Event,ADDED,eval-conflicts-rho005-r6-003-dqvqj.18d465b77ca7f293,"reason=Pulled count=1 msg=Container image ""busybox:musl"" already present on machine"
0.208,Event,ADDED,eval-conflicts-rho005-r6-003-dqvqj.18d465b77de45a61,reason=Created count=1 msg=Created container: task
0.2082,Event,ADDED,eval-conflicts-rho005-r6-003-dqvqj.18d465b782a58bfd,reason=Started count=1 msg=Started container task
0.2084,Event,ADDED,eval-conflicts-rho005-r6-003.18d465b762a4ac8e,reason=SuccessfulCreate count=1 msg=Created pod: eval-conflicts-rho005-r6-003-dqvqj
0.2086,Event,ADDED,eval-conflicts-rho005-r6-003.18d465baa20e430f,reason=Completed count=1 msg=Job completed
0.2091,Event,ADDED,eval-conflicts-rho005-r6-004-snvxn.18d465b79f186922,reason=Scheduled count=None msg=Successfully assigned compute/eval-conflicts-rho005-r6-004-snvxn to kind-worker2
0.2092,Event,ADDED,eval-conflicts-rho005-r6-004-snvxn.18d465b7b7e69822,"reason=Pulled count=1 msg=Container image ""busybox:musl"" already present on machine"
0.2094,Event,ADDED,eval-conflicts-rho005-r6-004-snvxn.18d465b7b8f7920d,reason=Created count=1 msg=Created container: task
0.2097,Event,ADDED,eval-conflicts-rho005-r6-004-snvxn.18d465b7bd005df1,reason=Started count=1 msg=Started container task
0.2099,Event,ADDED,eval-conflicts-rho005-r6-004.18d465b79e1a14c7,reason=SuccessfulCreate count=1 msg=Created pod: eval-conflicts-rho005-r6-004-snvxn
0.2101,Event,ADDED,eval-conflicts-rho005-r6-004.18d465baddcf9e33,reason=Completed count=1 msg=Job completed
0.2103,Event,ADDED,eval-conflicts-rho005-r6-005-89xx4.18d465b7da6a03bb,reason=Scheduled count=None msg=Successfully assigned compute/eval-conflicts-rho005-r6-005-89xx4 to kind-worker4
0.2105,Event,ADDED,eval-conflicts-rho005-r6-005-89xx4.18d465b7f43b3c78,"reason=Pulled count=1 msg=Container image ""busybox:musl"" already present on machine"
0.2107,Event,ADDED,eval-conflicts-rho005-r6-005-89xx4.18d465b7f5623367,reason=Created count=1 msg=Created container: task
0.2108,Event,ADDED,eval-conflicts-rho005-r6-005-89xx4.18d465b7f9d826f5,reason=Started count=1 msg=Started container task
0.211,Event,ADDED,eval-conflicts-rho005-r6-005.18d465b7d9b5443b,reason=SuccessfulCreate count=1 msg=Created pod: eval-conflicts-rho005-r6-005-89xx4
0.2112,Event,ADDED,eval-conflicts-rho005-r6-005.18d465bb26ce1e81,reason=Completed count=1 msg=Job completed
0.2113,Event,ADDED,eval-conflicts-rho005-r6-006-kjc2m.18d465b8161daf18,reason=Scheduled count=None msg=Successfully assigned compute/eval-conflicts-rho005-r6-006-kjc2m to kind-worker4
0.2115,Event,ADDED,eval-conflicts-rho005-r6-006-kjc2m.18d465b8301b9aa1,"reason=Pulled count=1 msg=Container image ""busybox:musl"" already present on machine"
0.2117,Event,ADDED,eval-conflicts-rho005-r6-006-kjc2m.18d465b8315fb344,reason=Created count=1 msg=Created container: task
0.2118,Event,ADDED,eval-conflicts-rho005-r6-006-kjc2m.18d465b83603579e,reason=Started count=1 msg=Started container task
0.212,Event,ADDED,eval-conflicts-rho005-r6-006.18d465b81517c0e7,reason=SuccessfulCreate count=1 msg=Created pod: eval-conflicts-rho005-r6-006-kjc2m
0.2122,Event,ADDED,eval-conflicts-rho005-r6-006.18d465bb632977f9,reason=Completed count=1 msg=Job completed
0.2123,Event,ADDED,eval-conflicts-rho005-r6-007-lt86t.18d465b851b71637,reason=Scheduled count=None msg=Successfully assigned compute/eval-conflicts-rho005-r6-007-lt86t to kind-worker2
0.2125,Event,ADDED,eval-conflicts-rho005-r6-007-lt86t.18d465b86c3c8eb2,"reason=Pulled count=1 msg=Container image ""busybox:musl"" already present on machine"
0.2127,Event,ADDED,eval-conflicts-rho005-r6-007-lt86t.18d465b86d71a8e2,reason=Created count=1 msg=Created container: task
0.2128,Event,ADDED,eval-conflicts-rho005-r6-007-lt86t.18d465b86fb8200a,reason=Started count=1 msg=Started container task
0.213,Event,ADDED,eval-conflicts-rho005-r6-007.18d465b850b0e032,reason=SuccessfulCreate count=1 msg=Created pod: eval-conflicts-rho005-r6-007-lt86t
0.2132,Event,ADDED,eval-conflicts-rho005-r6-007.18d465bb916db0d1,reason=Completed count=1 msg=Job completed
0.2135,Event,ADDED,eval-conflicts-rho005-r6-008-pj5z2.18d465b88d5ef845,reason=Scheduled count=None msg=Successfully assigned compute/eval-conflicts-rho005-r6-008-pj5z2 to kind-worker2
0.2136,Event,ADDED,eval-conflicts-rho005-r6-008-pj5z2.18d465b8a6278510,"reason=Pulled count=1 msg=Container image ""busybox:musl"" already present on machine"
0.2138,Event,ADDED,eval-conflicts-rho005-r6-008-pj5z2.18d465b8a7412bed,reason=Created count=1 msg=Created container: task
0.214,Event,ADDED,eval-conflicts-rho005-r6-008-pj5z2.18d465b8a9806806,reason=Started count=1 msg=Started container task
0.2141,Event,ADDED,eval-conflicts-rho005-r6-008.18d465b88c61985b,reason=SuccessfulCreate count=1 msg=Created pod: eval-conflicts-rho005-r6-008-pj5z2
0.2143,Event,ADDED,eval-conflicts-rho005-r6-008.18d465bbcd5212e3,reason=Completed count=1 msg=Job completed
0.2145,Event,ADDED,eval-conflicts-rho005-r6-009-cng4v.18d465b8c8dc1920,reason=Scheduled count=None msg=Successfully assigned compute/eval-conflicts-rho005-r6-009-cng4v to kind-worker2
0.2146,Event,ADDED,eval-conflicts-rho005-r6-009-cng4v.18d465b8e2156cea,"reason=Pulled count=1 msg=Container image ""busybox:musl"" already present on machine"
0.2148,Event,ADDED,eval-conflicts-rho005-r6-009-cng4v.18d465b8e34bb06d,reason=Created count=1 msg=Created container: task
0.215,Event,ADDED,eval-conflicts-rho005-r6-009-cng4v.18d465b8e56d524e,reason=Started count=1 msg=Started container task
0.2151,Event,ADDED,eval-conflicts-rho005-r6-009.18d465b8c800d391,reason=SuccessfulCreate count=1 msg=Created pod: eval-conflicts-rho005-r6-009-cng4v
0.2153,Event,ADDED,eval-conflicts-rho005-r6-009.18d465bc099c403c,reason=Completed count=1 msg=Job completed
0.2155,Event,ADDED,eval-conflicts-rho005-r6-010-62tkf.18d465b9047cb69a,reason=Scheduled count=None msg=Successfully assigned compute/eval-conflicts-rho005-r6-010-62tkf to kind-worker4
0.2157,Event,ADDED,eval-conflicts-rho005-r6-010-62tkf.18d465b91d8113e4,"reason=Pulled count=1 msg=Container image ""busybox:musl"" already present on machine"
0.2158,Event,ADDED,eval-conflicts-rho005-r6-010-62tkf.18d465b91e9c21b7,reason=Created count=1 msg=Created container: task
0.216,Event,ADDED,eval-conflicts-rho005-r6-010-62tkf.18d465b9221920ad,reason=Started count=1 msg=Started container task
0.2162,Event,ADDED,eval-conflicts-rho005-r6-010.18d465b9038772d4,reason=SuccessfulCreate count=1 msg=Created pod: eval-conflicts-rho005-r6-010-62tkf
0.2163,Event,ADDED,eval-conflicts-rho005-r6-010.18d465bc52881e81,reason=Completed count=1 msg=Job completed
0.2165,Event,ADDED,eval-conflicts-rho005-r6-011-hlrqm.18d465b9403ebb6e,reason=Scheduled count=None msg=Successfully assigned compute/eval-conflicts-rho005-r6-011-hlrqm to kind-worker3
0.2167,Event,ADDED,eval-conflicts-rho005-r6-011-hlrqm.18d465b95aec53d7,"reason=Pulled count=1 msg=Container image ""busybox:musl"" already present on machine"
0.2168,Event,ADDED,eval-conflicts-rho005-r6-011-hlrqm.18d465b95c074d3e,reason=Created count=1 msg=Created container: task
0.217,Event,ADDED,eval-conflicts-rho005-r6-011-hlrqm.18d465b960201f27,reason=Started count=1 msg=Started container task
0.2172,Event,ADDED,eval-conflicts-rho005-r6-011.18d465b93ff000a6,reason=SuccessfulCreate count=1 msg=Created pod: eval-conflicts-rho005-r6-011-hlrqm
0.2174,Event,ADDED,eval-conflicts-rho005-r6-011.18d465bc86ef4ed2,reason=Completed count=1 msg=Job completed
0.2175,Event,ADDED,eval-conflicts-rho005-r6-012-49ftg.18d465b97e2d4cb1,reason=Scheduled count=None msg=Successfully assigned compute/eval-conflicts-rho005-r6-012-49ftg to kind-worker3
0.2177,Event,ADDED,eval-conflicts-rho005-r6-012-49ftg.18d465b996f86a02,"reason=Pulled count=1 msg=Container image ""busybox:musl"" already present on machine"
0.2178,Event,ADDED,eval-conflicts-rho005-r6-012-49ftg.18d465b99813b387,reason=Created count=1 msg=Created container: task
0.2181,Event,ADDED,eval-conflicts-rho005-r6-012-49ftg.18d465b99c8adeff,reason=Started count=1 msg=Started container task
0.2183,Event,ADDED,eval-conflicts-rho005-r6-012.18d465b97d41d459,reason=SuccessfulCreate count=1 msg=Created pod: eval-conflicts-rho005-r6-012-49ftg
0.2185,Event,ADDED,eval-conflicts-rho005-r6-012.18d465bcc2d81903,reason=Completed count=1 msg=Job completed
0.2186,Event,ADDED,eval-conflicts-rho005-r6-013-5g77b.18d465b9b718743c,reason=Scheduled count=None msg=Successfully assigned compute/eval-conflicts-rho005-r6-013-5g77b to kind-worker3
0.2188,Event,ADDED,eval-conflicts-rho005-r6-013-5g77b.18d465b9d006984e,"reason=Pulled count=1 msg=Container image ""busybox:musl"" already present on machine"
0.2189,Event,ADDED,eval-conflicts-rho005-r6-013-5g77b.18d465b9d118d5c8,reason=Created count=1 msg=Created container: task
0.2191,Event,ADDED,eval-conflicts-rho005-r6-013-5g77b.18d465b9d719dc3c,reason=Started count=1 msg=Started container task
0.2193,Event,ADDED,eval-conflicts-rho005-r6-013.18d465b9b6778413,reason=SuccessfulCreate count=1 msg=Created pod: eval-conflicts-rho005-r6-013-5g77b
0.2194,Event,ADDED,eval-conflicts-rho005-r6-013.18d465bcfec56061,reason=Completed count=1 msg=Job completed
0.2196,Event,ADDED,eval-conflicts-rho005-r6-014-8srfc.18d465b9f3b67361,"reason=FailedScheduling count=None msg=0/6 nodes are available: 6 node(s) had untolerated taint(s). no new claims to deallocate, preemption: 0/6 nodes are available: 6 Preemption is not helpful for scheduling."
0.2197,Event,ADDED,eval-conflicts-rho005-r6-014-8srfc.18d465bb77a6ee2d,reason=Scheduled count=None msg=Successfully assigned compute/eval-conflicts-rho005-r6-014-8srfc to kind-worker
0.2199,Event,ADDED,eval-conflicts-rho005-r6-014-8srfc.18d465bb98d1796d,"reason=Pulled count=1 msg=Container image ""busybox:musl"" already present on machine"
0.2201,Event,ADDED,eval-conflicts-rho005-r6-014-8srfc.18d465bb9cd627ad,reason=Created count=1 msg=Created container: task
0.2202,Event,ADDED,eval-conflicts-rho005-r6-014-8srfc.18d465bba01cbe90,reason=Started count=1 msg=Started container task
0.2204,Event,ADDED,eval-conflicts-rho005-r6-014.18d465b9f3abbf9c,reason=SuccessfulCreate count=1 msg=Created pod: eval-conflicts-rho005-r6-014-8srfc
0.2206,Event,ADDED,eval-conflicts-rho005-r6-014.18d465beb500d579,reason=Completed count=1 msg=Job completed
0.2207,Event,ADDED,eval-conflicts-rho005-r6-015-nh52d.18d465ba2de87bb9,"reason=FailedScheduling count=None msg=0/6 nodes are available: 6 node(s) had untolerated taint(s). no new claims to deallocate, preemption: 0/6 nodes are available: 6 Preemption is not helpful for scheduling."
0.2209,Event,ADDED,eval-conflicts-rho005-r6-015-nh52d.18d465bb782322d3,reason=Scheduled count=None msg=Successfully assigned compute/eval-conflicts-rho005-r6-015-nh52d to kind-worker
0.221,Event,ADDED,eval-conflicts-rho005-r6-015-nh52d.18d465bb98ec678b,"reason=Pulled count=1 msg=Container image ""busybox:musl"" already present on machine"
0.2212,Event,ADDED,eval-conflicts-rho005-r6-015-nh52d.18d465bb9cede9a6,reason=Created count=1 msg=Created container: task
0.2213,Event,ADDED,eval-conflicts-rho005-r6-015-nh52d.18d465bba01b1313,reason=Started count=1 msg=Started container task
0.2215,Event,ADDED,eval-conflicts-rho005-r6-015.18d465ba2dd52792,reason=SuccessfulCreate count=1 msg=Created pod: eval-conflicts-rho005-r6-015-nh52d
0.2217,Event,ADDED,eval-conflicts-rho005-r6-015.18d465beb3540598,reason=Completed count=1 msg=Job completed
0.2218,Event,ADDED,eval-conflicts-rho005-r6-016-tl8fx.18d465ba69f63ea4,"reason=FailedScheduling count=None msg=0/6 nodes are available: 6 node(s) had untolerated taint(s). no new claims to deallocate, preemption: 0/6 nodes are available: 6 Preemption is not helpful for scheduling."
0.222,Event,ADDED,eval-conflicts-rho005-r6-016-tl8fx.18d465bb788a999c,reason=Scheduled count=None msg=Successfully assigned compute/eval-conflicts-rho005-r6-016-tl8fx to kind-worker
0.2222,Event,ADDED,eval-conflicts-rho005-r6-016-tl8fx.18d465bb975f3a74,"reason=Pulled count=1 msg=Container image ""busybox:musl"" already present on machine"
0.2223,Event,ADDED,eval-conflicts-rho005-r6-016-tl8fx.18d465bb9c16be4e,reason=Created count=1 msg=Created container: task
0.2225,Event,ADDED,eval-conflicts-rho005-r6-016-tl8fx.18d465bb9ecfe7cd,reason=Started count=1 msg=Started container task
0.2227,Event,ADDED,eval-conflicts-rho005-r6-016.18d465ba69ebfabd,reason=SuccessfulCreate count=1 msg=Created pod: eval-conflicts-rho005-r6-016-tl8fx
0.2229,Event,ADDED,eval-conflicts-rho005-r6-016.18d465be78c0ce39,reason=Completed count=1 msg=Job completed
0.2231,Event,ADDED,eval-conflicts-rho005-r6-017-fbkjw.18d465baa4fb139d,"reason=FailedScheduling count=None msg=0/6 nodes are available: 6 node(s) had untolerated taint(s). no new claims to deallocate, preemption: 0/6 nodes are available: 6 Preemption is not helpful for scheduling."
0.2232,Event,ADDED,eval-conflicts-rho005-r6-017-fbkjw.18d465bb78aec93b,reason=Scheduled count=None msg=Successfully assigned compute/eval-conflicts-rho005-r6-017-fbkjw to kind-worker
0.2234,Event,ADDED,eval-conflicts-rho005-r6-017-fbkjw.18d465bb973e8334,"reason=Pulled count=1 msg=Container image ""busybox:musl"" already present on machine"
0.2235,Event,ADDED,eval-conflicts-rho005-r6-017-fbkjw.18d465bb9aeb08f2,reason=Created count=1 msg=Created container: task
0.2237,Event,ADDED,eval-conflicts-rho005-r6-017-fbkjw.18d465bb9e971f26,reason=Started count=1 msg=Started container task
0.2239,Event,ADDED,eval-conflicts-rho005-r6-017.18d465baa4ed8e60,reason=SuccessfulCreate count=1 msg=Created pod: eval-conflicts-rho005-r6-017-fbkjw
0.224,Event,ADDED,eval-conflicts-rho005-r6-017.18d465be78edde79,reason=Completed count=1 msg=Job completed
0.2242,Event,ADDED,eval-conflicts-rho005-r6-018-trzzd.18d465bae08db744,"reason=FailedScheduling count=None msg=0/6 nodes are available: 6 node(s) had untolerated taint(s). no new claims to deallocate, preemption: 0/6 nodes are available: 6 Preemption is not helpful for scheduling."
0.2243,Event,ADDED,eval-conflicts-rho005-r6-018-trzzd.18d465bb78b02213,reason=Scheduled count=None msg=Successfully assigned compute/eval-conflicts-rho005-r6-018-trzzd to kind-worker
0.2245,Event,ADDED,eval-conflicts-rho005-r6-018-trzzd.18d465bb97bb446a,"reason=Pulled count=1 msg=Container image ""busybox:musl"" already present on machine"
0.2247,Event,ADDED,eval-conflicts-rho005-r6-018-trzzd.18d465bb9ca1c1c9,reason=Created count=1 msg=Created container: task
0.2248,Event,ADDED,eval-conflicts-rho005-r6-018-trzzd.18d465bba01d06c1,reason=Started count=1 msg=Started container task
0.225,Event,ADDED,eval-conflicts-rho005-r6-018.18d465bae082edf0,reason=SuccessfulCreate count=1 msg=Created pod: eval-conflicts-rho005-r6-018-trzzd
0.2252,Event,ADDED,eval-conflicts-rho005-r6-018.18d465beeeb5657f,reason=Completed count=1 msg=Job completed
0.2253,Event,ADDED,eval-conflicts-rho005-r6-019-hlgdt.18d465bb1bd4fe1f,"reason=FailedScheduling count=None msg=0/6 nodes are available: 6 node(s) had untolerated taint(s). no new claims to deallocate, preemption: 0/6 nodes are available: 6 Preemption is not helpful for scheduling."
0.2255,Event,ADDED,eval-conflicts-rho005-r6-019-hlgdt.18d465bb7bc018fe,reason=Scheduled count=None msg=Successfully assigned compute/eval-conflicts-rho005-r6-019-hlgdt to kind-worker
0.2257,Event,ADDED,eval-conflicts-rho005-r6-019-hlgdt.18d465bb97959b0d,"reason=Pulled count=1 msg=Container image ""busybox:musl"" already present on machine"
0.2258,Event,ADDED,eval-conflicts-rho005-r6-019-hlgdt.18d465bb9c58eb33,reason=Created count=1 msg=Created container: task
0.226,Event,ADDED,eval-conflicts-rho005-r6-019-hlgdt.18d465bba01e5ca2,reason=Started count=1 msg=Started container task
0.2262,Event,ADDED,eval-conflicts-rho005-r6-019.18d465bb1bcbe718,reason=SuccessfulCreate count=1 msg=Created pod: eval-conflicts-rho005-r6-019-hlgdt
0.2263,Event,ADDED,eval-conflicts-rho005-r6-019.18d465beb48b2aaf,reason=Completed count=1 msg=Job completed
0.2265,Event,ADDED,eval-conflicts-rho005-r6-020-k9sdf.18d465bb57aad79a,"reason=FailedScheduling count=None msg=0/6 nodes are available: 6 node(s) had untolerated taint(s). no new claims to deallocate, preemption: 0/6 nodes are available: 6 Preemption is not helpful for scheduling."
0.2266,Event,ADDED,eval-conflicts-rho005-r6-020-k9sdf.18d465bb7bbbc505,reason=Scheduled count=None msg=Successfully assigned compute/eval-conflicts-rho005-r6-020-k9sdf to kind-worker
0.2268,Event,ADDED,eval-conflicts-rho005-r6-020-k9sdf.18d465bb970401df,"reason=Pulled count=1 msg=Container image ""busybox:musl"" already present on machine"
0.227,Event,ADDED,eval-conflicts-rho005-r6-020-k9sdf.18d465bb997ee428,reason=Created count=1 msg=Created container: task
0.2271,Event,ADDED,eval-conflicts-rho005-r6-020-k9sdf.18d465bb9dddc8fd,reason=Started count=1 msg=Started container task
0.2273,Event,ADDED,eval-conflicts-rho005-r6-020.18d465bb579f08f3,reason=SuccessfulCreate count=1 msg=Created pod: eval-conflicts-rho005-r6-020-k9sdf
0.2275,Event,ADDED,eval-conflicts-rho005-r6-020.18d465beb3065189,reason=Completed count=1 msg=Job completed
0.2276,Event,ADDED,eval-conflicts-rho005-r6-021-bxtcs.18d465bb978d4439,reason=Scheduled count=None msg=Successfully assigned compute/eval-conflicts-rho005-r6-021-bxtcs to kind-worker
0.2278,Event,ADDED,eval-conflicts-rho005-r6-021-bxtcs.18d465bbb0fb6459,"reason=Pulled count=1 msg=Container image ""busybox:musl"" already present on machine"
0.2279,Event,ADDED,eval-conflicts-rho005-r6-021-bxtcs.18d465bbb20b8ae9,reason=Created count=1 msg=Created container: task
0.2281,Event,ADDED,eval-conflicts-rho005-r6-021-bxtcs.18d465bbbc121c69,reason=Started count=1 msg=Started container task
0.2283,Event,ADDED,eval-conflicts-rho005-r6-021.18d465bb9691b0fc,reason=SuccessfulCreate count=1 msg=Created pod: eval-conflicts-rho005-r6-021-bxtcs
0.2284,Event,ADDED,eval-conflicts-rho005-r6-021.18d465beef7f2f91,reason=Completed count=1 msg=Job completed
0.2288,Event,ADDED,eval-conflicts-rho005-r6-022-k2s7h.18d465bbcf35afea,reason=Scheduled count=None msg=Successfully assigned compute/eval-conflicts-rho005-r6-022-k2s7h to kind-worker
0.2291,Event,ADDED,eval-conflicts-rho005-r6-022-k2s7h.18d465bbe7d6ba58,"reason=Pulled count=1 msg=Container image ""busybox:musl"" already present on machine"
0.2293,Event,ADDED,eval-conflicts-rho005-r6-022-k2s7h.18d465bbe8f9f251,reason=Created count=1 msg=Created container: task
0.2294,Event,ADDED,eval-conflicts-rho005-r6-022-k2s7h.18d465bbebf9fb29,reason=Started count=1 msg=Started container task
0.2296,Event,ADDED,eval-conflicts-rho005-r6-022.18d465bbceabc702,reason=SuccessfulCreate count=1 msg=Created pod: eval-conflicts-rho005-r6-022-k2s7h
0.2298,Event,ADDED,eval-conflicts-rho005-r6-022.18d465bf2bf0e86d,reason=Completed count=1 msg=Job completed
0.23,Event,ADDED,eval-conflicts-rho005-r6-023-6xlfd.18d465bc0b571749,reason=Scheduled count=None msg=Successfully assigned compute/eval-conflicts-rho005-r6-023-6xlfd to kind-worker
0.2302,Event,ADDED,eval-conflicts-rho005-r6-023-6xlfd.18d465bc25824311,"reason=Pulled count=1 msg=Container image ""busybox:musl"" already present on machine"
0.2304,Event,ADDED,eval-conflicts-rho005-r6-023-6xlfd.18d465bc26b83790,reason=Created count=1 msg=Created container: task
0.2306,Event,ADDED,eval-conflicts-rho005-r6-023-6xlfd.18d465bc2b72e8f8,reason=Started count=1 msg=Started container task
0.2307,Event,ADDED,eval-conflicts-rho005-r6-023.18d465bc0abeed89,reason=SuccessfulCreate count=1 msg=Created pod: eval-conflicts-rho005-r6-023-6xlfd
0.2309,Event,ADDED,eval-conflicts-rho005-r6-023.18d465bf67548dae,reason=Completed count=1 msg=Job completed
0.231,Event,ADDED,eval-conflicts-rho005-r6-024-924pf.18d465bc465e2a7c,reason=Scheduled count=None msg=Successfully assigned compute/eval-conflicts-rho005-r6-024-924pf to kind-worker
0.2312,Event,ADDED,eval-conflicts-rho005-r6-024-924pf.18d465bc5f6f6743,"reason=Pulled count=1 msg=Container image ""busybox:musl"" already present on machine"
0.2314,Event,ADDED,eval-conflicts-rho005-r6-024-924pf.18d465bc607f4f2d,reason=Created count=1 msg=Created container: task
0.2315,Event,ADDED,eval-conflicts-rho005-r6-024-924pf.18d465bc645eb32a,reason=Started count=1 msg=Started container task
0.2317,Event,ADDED,eval-conflicts-rho005-r6-024.18d465bc45df1e40,reason=SuccessfulCreate count=1 msg=Created pod: eval-conflicts-rho005-r6-024-924pf
0.2319,Event,ADDED,eval-conflicts-rho005-r6-024.18d465bfa367ca42,reason=Completed count=1 msg=Job completed
0.232,Event,ADDED,eval-conflicts-rho005-r6-025-pkzlc.18d465bc8340470b,reason=Scheduled count=None msg=Successfully assigned compute/eval-conflicts-rho005-r6-025-pkzlc to kind-worker5
0.2322,Event,ADDED,eval-conflicts-rho005-r6-025-pkzlc.18d465bc9be8a1b3,"reason=Pulled count=1 msg=Container image ""busybox:musl"" already present on machine"
0.2324,Event,ADDED,eval-conflicts-rho005-r6-025-pkzlc.18d465bc9d0b3cf3,reason=Created count=1 msg=Created container: task
0.2325,Event,ADDED,eval-conflicts-rho005-r6-025-pkzlc.18d465bc9fd91910,reason=Started count=1 msg=Started container task
0.2327,Event,ADDED,eval-conflicts-rho005-r6-025.18d465bc82379f9e,reason=SuccessfulCreate count=1 msg=Created pod: eval-conflicts-rho005-r6-025-pkzlc
0.2329,Event,ADDED,eval-conflicts-rho005-r6-025.18d465bfe55cf6ab,reason=Completed count=1 msg=Job completed
0.233,Event,ADDED,eval-conflicts-rho005-r6-026-49spt.18d465bcbe8402fc,reason=Scheduled count=None msg=Successfully assigned compute/eval-conflicts-rho005-r6-026-49spt to kind-worker5
0.2332,Event,ADDED,eval-conflicts-rho005-r6-026-49spt.18d465bcd7feec6b,"reason=Pulled count=1 msg=Container image ""busybox:musl"" already present on machine"
0.2334,Event,ADDED,eval-conflicts-rho005-r6-026-49spt.18d465bcd93f7f54,reason=Created count=1 msg=Created container: task
0.2335,Event,ADDED,eval-conflicts-rho005-r6-026-49spt.18d465bcdb735b14,reason=Started count=1 msg=Started container task
0.2337,Event,ADDED,eval-conflicts-rho005-r6-026.18d465bcbd516743,reason=SuccessfulCreate count=1 msg=Created pod: eval-conflicts-rho005-r6-026-49spt
0.2338,Event,ADDED,eval-conflicts-rho005-r6-026.18d465c0210d1748,reason=Completed count=1 msg=Job completed
0.234,Event,ADDED,eval-conflicts-rho005-r6-027-f9vb6.18d465bcf9e068ee,reason=Scheduled count=None msg=Successfully assigned compute/eval-conflicts-rho005-r6-027-f9vb6 to kind-worker5
0.2342,Event,ADDED,eval-conflicts-rho005-r6-027-f9vb6.18d465bd131d0e37,"reason=Pulled count=1 msg=Container image ""busybox:musl"" already present on machine"
0.2343,Event,ADDED,eval-conflicts-rho005-r6-027-f9vb6.18d465bd144ac6b7,reason=Created count=1 msg=Created container: task
0.2345,Event,ADDED,eval-conflicts-rho005-r6-027-f9vb6.18d465bd1669c81b,reason=Started count=1 msg=Started container task
0.2347,Event,ADDED,eval-conflicts-rho005-r6-027.18d465bcf924c812,reason=SuccessfulCreate count=1 msg=Created pod: eval-conflicts-rho005-r6-027-f9vb6
0.2349,Event,ADDED,eval-conflicts-rho005-r6-027.18d465c05e9ece51,reason=Completed count=1 msg=Job completed
0.235,Event,ADDED,eval-conflicts-rho005-r6-028-2mpvz.18d465bd357fe4e2,reason=Scheduled count=None msg=Successfully assigned compute/eval-conflicts-rho005-r6-028-2mpvz to kind-worker5
0.2352,Event,ADDED,eval-conflicts-rho005-r6-028-2mpvz.18d465bd4f7823c0,"reason=Pulled count=1 msg=Container image ""busybox:musl"" already present on machine"
0.2354,Event,ADDED,eval-conflicts-rho005-r6-028-2mpvz.18d465bd50c7bb13,reason=Created count=1 msg=Created container: task
0.2355,Event,ADDED,eval-conflicts-rho005-r6-028-2mpvz.18d465bd551581b3,reason=Started count=1 msg=Started container task
0.2357,Event,ADDED,eval-conflicts-rho005-r6-028.18d465bd34bfeb78,reason=SuccessfulCreate count=1 msg=Created pod: eval-conflicts-rho005-r6-028-2mpvz
0.2359,Event,ADDED,eval-conflicts-rho005-r6-028.18d465c09a41dde2,reason=Completed count=1 msg=Job completed
0.236,Event,ADDED,eval-conflicts-rho005-r6-029-2jcnj.18d465bd7135a74d,reason=Scheduled count=None msg=Successfully assigned compute/eval-conflicts-rho005-r6-029-2jcnj to kind-worker5
0.2362,Event,ADDED,eval-conflicts-rho005-r6-029-2jcnj.18d465bd8ab1fce5,"reason=Pulled count=1 msg=Container image ""busybox:musl"" already present on machine"
0.2364,Event,ADDED,eval-conflicts-rho005-r6-029-2jcnj.18d465bd8bf36d7c,reason=Created count=1 msg=Created container: task
0.2365,Event,ADDED,eval-conflicts-rho005-r6-029-2jcnj.18d465bd90e814c8,reason=Started count=1 msg=Started container task
0.2367,Event,ADDED,eval-conflicts-rho005-r6-029.18d465bd702eb884,reason=SuccessfulCreate count=1 msg=Created pod: eval-conflicts-rho005-r6-029-2jcnj
0.2369,Event,ADDED,eval-conflicts-rho005-r6-029.18d465c0d6559412,reason=Completed count=1 msg=Job completed
0.237,Event,ADDED,eval-conflicts-rho005-r6-030-2h87w.18d465bdad8fec0c,reason=Scheduled count=None msg=Successfully assigned compute/eval-conflicts-rho005-r6-030-2h87w to kind-worker
0.2373,Event,ADDED,eval-conflicts-rho005-r6-030-2h87w.18d465bdc87aa7bf,"reason=Pulled count=1 msg=Container image ""busybox:musl"" already present on machine"
0.2374,Event,ADDED,eval-conflicts-rho005-r6-030-2h87w.18d465bdc9b2de78,reason=Created count=1 msg=Created container: task
0.2376,Event,ADDED,eval-conflicts-rho005-r6-030-2h87w.18d465bdcbd23348,reason=Started count=1 msg=Started container task
0.2378,Event,ADDED,eval-conflicts-rho005-r6-030.18d465bdacdd25ff,reason=SuccessfulCreate count=1 msg=Created pod: eval-conflicts-rho005-r6-030-2h87w
0.2379,Event,ADDED,eval-conflicts-rho005-r6-030.18d465c10aa2d06c,reason=Completed count=1 msg=Job completed
0.2381,Event,ADDED,eval-conflicts-rho005-r6-031-tcmnj.18d465bde81c5d71,reason=Scheduled count=None msg=Successfully assigned compute/eval-conflicts-rho005-r6-031-tcmnj to kind-worker4
0.2383,Event,ADDED,eval-conflicts-rho005-r6-031-tcmnj.18d465be008c6353,"reason=Pulled count=1 msg=Container image ""busybox:musl"" already present on machine"
0.2385,Event,ADDED,eval-conflicts-rho005-r6-031-tcmnj.18d465be019a3197,reason=Created count=1 msg=Created container: task
0.2386,Event,ADDED,eval-conflicts-rho005-r6-031-tcmnj.18d465be069f39d8,reason=Started count=1 msg=Started container task
0.2388,Event,ADDED,eval-conflicts-rho005-r6-031.18d465bde77a3f5e,reason=SuccessfulCreate count=1 msg=Created pod: eval-conflicts-rho005-r6-031-tcmnj
0.239,Event,ADDED,eval-conflicts-rho005-r6-031.18d465c138d79227,reason=Completed count=1 msg=Job completed
0.2391,Event,ADDED,eval-conflicts-rho005-r6-032-d878g.18d465be23c7e0b1,reason=Scheduled count=None msg=Successfully assigned compute/eval-conflicts-rho005-r6-032-d878g to kind-worker2
0.2393,Event,ADDED,eval-conflicts-rho005-r6-032-d878g.18d465be40e8619a,"reason=Pulled count=1 msg=Container image ""busybox:musl"" already present on machine"
0.2397,Event,ADDED,eval-conflicts-rho005-r6-032-d878g.18d465be41ffd665,reason=Created count=1 msg=Created container: task
0.2399,Event,ADDED,eval-conflicts-rho005-r6-032-d878g.18d465be46840fd8,reason=Started count=1 msg=Started container task
0.24,Event,ADDED,eval-conflicts-rho005-r6-032.18d465be22dafa8c,reason=SuccessfulCreate count=1 msg=Created pod: eval-conflicts-rho005-r6-032-d878g
0.2402,Event,ADDED,eval-conflicts-rho005-r6-032.18d465c16708d6a8,reason=Completed count=1 msg=Job completed
0.2405,Event,ADDED,eval-conflicts-rho005-r6-033-qzths.18d465be5f8ddbd0,reason=Scheduled count=None msg=Successfully assigned compute/eval-conflicts-rho005-r6-033-qzths to kind-worker2
0.2407,Event,ADDED,eval-conflicts-rho005-r6-033-qzths.18d465be7d5b836b,"reason=Pulled count=1 msg=Container image ""busybox:musl"" already present on machine"
0.2409,Event,ADDED,eval-conflicts-rho005-r6-033-qzths.18d465be7edf194b,reason=Created count=1 msg=Created container: task
0.2411,Event,ADDED,eval-conflicts-rho005-r6-033-qzths.18d465be838b789f,reason=Started count=1 msg=Started container task
0.2413,Event,ADDED,eval-conflicts-rho005-r6-033.18d465be5e713433,reason=SuccessfulCreate count=1 msg=Created pod: eval-conflicts-rho005-r6-033-qzths
0.2415,Event,ADDED,eval-conflicts-rho005-r6-033.18d465c167a2f3af,reason=Completed count=1 msg=Job completed
0.2416,Event,ADDED,eval-conflicts-rho005-r6-034-trhkc.18d465be9b407aea,reason=Scheduled count=None msg=Successfully assigned compute/eval-conflicts-rho005-r6-034-trhkc to kind-worker2
0.2418,Event,ADDED,eval-conflicts-rho005-r6-034-trhkc.18d465beb9468502,"reason=Pulled count=1 msg=Container image ""busybox:musl"" already present on machine"
0.242,Event,ADDED,eval-conflicts-rho005-r6-034-trhkc.18d465bebaba916d,reason=Created count=1 msg=Created container: task
0.2421,Event,ADDED,eval-conflicts-rho005-r6-034-trhkc.18d465bebe413db8,reason=Started count=1 msg=Started container task
0.2423,Event,ADDED,eval-conflicts-rho005-r6-034.18d465be99fe2010,reason=SuccessfulCreate count=1 msg=Created pod: eval-conflicts-rho005-r6-034-trhkc
0.2425,Event,ADDED,eval-conflicts-rho005-r6-034.18d465c1dee4a6ce,reason=Completed count=1 msg=Job completed
0.2426,Event,ADDED,eval-conflicts-rho005-r6-035-nk9n9.18d465bed6aa4839,reason=Scheduled count=None msg=Successfully assigned compute/eval-conflicts-rho005-r6-035-nk9n9 to kind-worker4
0.2429,Event,ADDED,eval-conflicts-rho005-r6-035-nk9n9.18d465bef4cdf1ac,"reason=Pulled count=1 msg=Container image ""busybox:musl"" already present on machine"
0.2431,Event,ADDED,eval-conflicts-rho005-r6-035-nk9n9.18d465bef60fe215,reason=Created count=1 msg=Created container: task
0.2433,Event,ADDED,eval-conflicts-rho005-r6-035-nk9n9.18d465befa9c208f,reason=Started count=1 msg=Started container task
0.2434,Event,ADDED,eval-conflicts-rho005-r6-035.18d465bed5c13fc2,reason=SuccessfulCreate count=1 msg=Created pod: eval-conflicts-rho005-r6-035-nk9n9
0.2436,Event,ADDED,eval-conflicts-rho005-r6-035.18d465c228fe1e35,reason=Completed count=1 msg=Job completed
0.2438,Event,ADDED,eval-conflicts-rho005-r6-036-mhg92.18d465bf12d4953c,reason=Scheduled count=None msg=Successfully assigned compute/eval-conflicts-rho005-r6-036-mhg92 to kind-worker2
0.244,Event,ADDED,eval-conflicts-rho005-r6-036-mhg92.18d465bf30fcb924,"reason=Pulled count=1 msg=Container image ""busybox:musl"" already present on machine"
0.2442,Event,ADDED,eval-conflicts-rho005-r6-036-mhg92.18d465bf325b5d43,reason=Created count=1 msg=Created container: task
0.2443,Event,ADDED,eval-conflicts-rho005-r6-036-mhg92.18d465bf36d82dda,reason=Started count=1 msg=Started container task
0.2445,Event,ADDED,eval-conflicts-rho005-r6-036.18d465bf11eda1f8,reason=SuccessfulCreate count=1 msg=Created pod: eval-conflicts-rho005-r6-036-mhg92
0.2447,Event,ADDED,eval-conflicts-rho005-r6-036.18d465c2566cbf11,reason=Completed count=1 msg=Job completed
0.2448,Event,ADDED,eval-conflicts-rho005-r6-037-lwd7p.18d465bf4dca54e7,reason=Scheduled count=None msg=Successfully assigned compute/eval-conflicts-rho005-r6-037-lwd7p to kind-worker2
0.2452,Event,ADDED,eval-conflicts-rho005-r6-037-lwd7p.18d465bf6853333c,"reason=Pulled count=1 msg=Container image ""busybox:musl"" already present on machine"
0.2454,Event,ADDED,eval-conflicts-rho005-r6-037-lwd7p.18d465bf699d27f5,reason=Created count=1 msg=Created container: task
0.2456,Event,ADDED,eval-conflicts-rho005-r6-037-lwd7p.18d465bf6eaaea6a,reason=Started count=1 msg=Started container task
0.2457,Event,ADDED,eval-conflicts-rho005-r6-037.18d465bf4ce1ecb3,reason=SuccessfulCreate count=1 msg=Created pod: eval-conflicts-rho005-r6-037-lwd7p
0.2461,Event,ADDED,eval-conflicts-rho005-r6-037.18d465c291f585a3,reason=Completed count=1 msg=Job completed
0.2462,Event,ADDED,eval-conflicts-rho005-r6-038-srjzn.18d465bf8aa064a3,reason=Scheduled count=None msg=Successfully assigned compute/eval-conflicts-rho005-r6-038-srjzn to kind-worker4
0.2464,Event,ADDED,eval-conflicts-rho005-r6-038-srjzn.18d465bfa7fe3645,"reason=Pulled count=1 msg=Container image ""busybox:musl"" already present on machine"
0.2468,Event,ADDED,eval-conflicts-rho005-r6-038-srjzn.18d465bfa94960f2,reason=Created count=1 msg=Created container: task
0.247,Event,ADDED,eval-conflicts-rho005-r6-038-srjzn.18d465bfaf08ba8e,reason=Started count=1 msg=Started container task
0.2472,Event,ADDED,eval-conflicts-rho005-r6-038.18d465bf89c8a979,reason=SuccessfulCreate count=1 msg=Created pod: eval-conflicts-rho005-r6-038-srjzn
0.2473,Event,ADDED,eval-conflicts-rho005-r6-038.18d465c2dbfc3399,reason=Completed count=1 msg=Job completed
0.2477,Event,ADDED,eval-conflicts-rho005-r6-039-897g2.18d465bfc6741a5a,reason=Scheduled count=None msg=Successfully assigned compute/eval-conflicts-rho005-r6-039-897g2 to kind-worker4
0.248,Event,ADDED,eval-conflicts-rho005-r6-039-897g2.18d465bfe1cc5a4a,"reason=Pulled count=1 msg=Container image ""busybox:musl"" already present on machine"
0.2483,Event,ADDED,eval-conflicts-rho005-r6-039-897g2.18d465bfe30a0500,reason=Created count=1 msg=Created container: task
0.2485,Event,ADDED,eval-conflicts-rho005-r6-039-897g2.18d465bfe77e886d,reason=Started count=1 msg=Started container task
0.2487,Event,ADDED,eval-conflicts-rho005-r6-039.18d465bfc558b8c4,reason=SuccessfulCreate count=1 msg=Created pod: eval-conflicts-rho005-r6-039-897g2
0.2488,Event,ADDED,eval-conflicts-rho005-r6-039.18d465c31822bd81,reason=Completed count=1 msg=Job completed
0.249,Event,ADDED,eval-conflicts-rho005-r6-040-5l877.18d465c00215373a,reason=Scheduled count=None msg=Successfully assigned compute/eval-conflicts-rho005-r6-040-5l877 to kind-worker3
0.2492,Event,ADDED,eval-conflicts-rho005-r6-040-5l877.18d465c01bb1617b,"reason=Pulled count=1 msg=Container image ""busybox:musl"" already present on machine"
0.2494,Event,ADDED,eval-conflicts-rho005-r6-040-5l877.18d465c01ccb6a50,reason=Created count=1 msg=Created container: task
0.2496,Event,ADDED,eval-conflicts-rho005-r6-040-5l877.18d465c0227bcfe6,reason=Started count=1 msg=Started container task
0.2497,Event,ADDED,eval-conflicts-rho005-r6-040.18d465c0012819c5,reason=SuccessfulCreate count=1 msg=Created pod: eval-conflicts-rho005-r6-040-5l877
0.25,Event,ADDED,eval-conflicts-rho005-r6-040.18d465c34b93055e,reason=Completed count=1 msg=Job completed
0.2501,Event,ADDED,eval-conflicts-rho005-r6-041-qdj9z.18d465c03cd2c357,reason=Scheduled count=None msg=Successfully assigned compute/eval-conflicts-rho005-r6-041-qdj9z to kind-worker2
0.2503,Event,ADDED,eval-conflicts-rho005-r6-041-qdj9z.18d465c05729326c,"reason=Pulled count=1 msg=Container image ""busybox:musl"" already present on machine"
0.2505,Event,ADDED,eval-conflicts-rho005-r6-041-qdj9z.18d465c058540631,reason=Created count=1 msg=Created container: task
0.2506,Event,ADDED,eval-conflicts-rho005-r6-041-qdj9z.18d465c05e46f96e,reason=Started count=1 msg=Started container task
0.2508,Event,ADDED,eval-conflicts-rho005-r6-041.18d465c03b6de4b5,reason=SuccessfulCreate count=1 msg=Created pod: eval-conflicts-rho005-r6-041-qdj9z
0.2509,Event,ADDED,eval-conflicts-rho005-r6-041.18d465c3811af286,reason=Completed count=1 msg=Job completed
0.2511,Event,ADDED,eval-conflicts-rho005-r6-042-x47c9.18d465c077fb312b,reason=Scheduled count=None msg=Successfully assigned compute/eval-conflicts-rho005-r6-042-x47c9 to kind-worker3
0.2513,Event,ADDED,eval-conflicts-rho005-r6-042-x47c9.18d465c0920e5415,"reason=Pulled count=1 msg=Container image ""busybox:musl"" already present on machine"
0.2514,Event,ADDED,eval-conflicts-rho005-r6-042-x47c9.18d465c093582299,reason=Created count=1 msg=Created container: task
0.2516,Event,ADDED,eval-conflicts-rho005-r6-042-x47c9.18d465c0964c733b,reason=Started count=1 msg=Started container task
0.2518,Event,ADDED,eval-conflicts-rho005-r6-042.18d465c0778a378d,reason=SuccessfulCreate count=1 msg=Created pod: eval-conflicts-rho005-r6-042-x47c9
0.252,Event,ADDED,eval-conflicts-rho005-r6-042.18d465c3c38b0ac6,reason=Completed count=1 msg=Job completed
0.2521,Event,ADDED,eval-conflicts-rho005-r6-043-b7msb.18d465c0b342d73e,reason=Scheduled count=None msg=Successfully assigned compute/eval-conflicts-rho005-r6-043-b7msb to kind-worker3
0.2523,Event,ADDED,eval-conflicts-rho005-r6-043-b7msb.18d465c0cdd9daa9,"reason=Pulled count=1 msg=Container image ""busybox:musl"" already present on machine"
0.2524,Event,ADDED,eval-conflicts-rho005-r6-043-b7msb.18d465c0cf5a20c2,reason=Created count=1 msg=Created container: task
0.2526,Event,ADDED,eval-conflicts-rho005-r6-043-b7msb.18d465c0d3b1910d,reason=Started count=1 msg=Started container task
0.2528,Event,ADDED,eval-conflicts-rho005-r6-043.18d465c0b2d0a735,reason=SuccessfulCreate count=1 msg=Created pod: eval-conflicts-rho005-r6-043-b7msb
0.2531,Event,ADDED,eval-conflicts-rho005-r6-043.18d465c3ff77cf3b,reason=Completed count=1 msg=Job completed
0.2532,Event,ADDED,eval-conflicts-rho005-r6-044-sn7wt.18d465c0ee66a504,"reason=FailedScheduling count=None msg=0/6 nodes are available: 6 node(s) had untolerated taint(s). no new claims to deallocate, preemption: 0/6 nodes are available: 6 Preemption is not helpful for scheduling."
0.2533,Event,ADDED,eval-conflicts-rho005-r6-044-sn7wt.18d465c11fe569b9,reason=Scheduled count=None msg=Successfully assigned compute/eval-conflicts-rho005-r6-044-sn7wt to kind-worker5
0.2535,Event,ADDED,eval-conflicts-rho005-r6-044-sn7wt.18d465c1394e9ca2,"reason=Pulled count=1 msg=Container image ""busybox:musl"" already present on machine"
0.2537,Event,ADDED,eval-conflicts-rho005-r6-044-sn7wt.18d465c13aa734a0,reason=Created count=1 msg=Created container: task
0.2539,Event,ADDED,eval-conflicts-rho005-r6-044-sn7wt.18d465c13cca3aca,reason=Started count=1 msg=Started container task
0.254,Event,ADDED,eval-conflicts-rho005-r6-044.18d465c0ee5bcca0,reason=SuccessfulCreate count=1 msg=Created pod: eval-conflicts-rho005-r6-044-sn7wt
0.2542,Event,ADDED,eval-conflicts-rho005-r6-044.18d465c4566240a4,reason=Completed count=1 msg=Job completed
0.2544,Event,ADDED,eval-conflicts-rho005-r6-045-9pprb.18d465c12a0e3559,reason=Scheduled count=None msg=Successfully assigned compute/eval-conflicts-rho005-r6-045-9pprb to kind-worker5
0.2545,Event,ADDED,eval-conflicts-rho005-r6-045-9pprb.18d465c1432327f9,"reason=Pulled count=1 msg=Container image ""busybox:musl"" already present on machine"
0.2547,Event,ADDED,eval-conflicts-rho005-r6-045-9pprb.18d465c1445685c3,reason=Created count=1 msg=Created container: task
0.2555,Event,ADDED,eval-conflicts-rho005-r6-045-9pprb.18d465c148af8047,reason=Started count=1 msg=Started container task
0.2559,Event,ADDED,eval-conflicts-rho005-r6-045.18d465c129855d9e,reason=SuccessfulCreate count=1 msg=Created pod: eval-conflicts-rho005-r6-045-9pprb
0.2562,Event,ADDED,eval-conflicts-rho005-r6-045.18d465c456a6081a,reason=Completed count=1 msg=Job completed
0.2565,Event,ADDED,eval-conflicts-rho005-r6-046-69wzq.18d465c1663ff13d,reason=Scheduled count=None msg=Successfully assigned compute/eval-conflicts-rho005-r6-046-69wzq to kind-worker5
0.2567,Event,ADDED,eval-conflicts-rho005-r6-046-69wzq.18d465c181489301,"reason=Pulled count=1 msg=Container image ""busybox:musl"" already present on machine"
0.2569,Event,ADDED,eval-conflicts-rho005-r6-046-69wzq.18d465c1825997cb,reason=Created count=1 msg=Created container: task
0.257,Event,ADDED,eval-conflicts-rho005-r6-046-69wzq.18d465c184586c71,reason=Started count=1 msg=Started container task
0.2573,Event,ADDED,eval-conflicts-rho005-r6-046.18d465c1658db88d,reason=SuccessfulCreate count=1 msg=Created pod: eval-conflicts-rho005-r6-046-69wzq
0.2575,Event,ADDED,eval-conflicts-rho005-r6-046.18d465c492436e41,reason=Completed count=1 msg=Job completed
0.2577,Event,ADDED,eval-conflicts-rho005-r6-047-bk6gw.18d465c1a2bc0170,reason=Scheduled count=None msg=Successfully assigned compute/eval-conflicts-rho005-r6-047-bk6gw to kind-worker5
0.2578,Event,ADDED,eval-conflicts-rho005-r6-047-bk6gw.18d465c1bbd40548,"reason=Pulled count=1 msg=Container image ""busybox:musl"" already present on machine"
0.2582,Event,ADDED,eval-conflicts-rho005-r6-047-bk6gw.18d465c1bd0fa5ad,reason=Created count=1 msg=Created container: task
0.2584,Event,ADDED,eval-conflicts-rho005-r6-047-bk6gw.18d465c1c1a8506b,reason=Started count=1 msg=Started container task
0.2586,Event,ADDED,eval-conflicts-rho005-r6-047.18d465c1a22080d6,reason=SuccessfulCreate count=1 msg=Created pod: eval-conflicts-rho005-r6-047-bk6gw
0.2589,Event,ADDED,eval-conflicts-rho005-r6-047.18d465c4ce363d29,reason=Completed count=1 msg=Job completed
0.2591,Event,ADDED,eval-conflicts-rho005-r6-048-xrkrg.18d465c1de44d8ca,reason=Scheduled count=None msg=Successfully assigned compute/eval-conflicts-rho005-r6-048-xrkrg to kind-worker5
0.2593,Event,ADDED,eval-conflicts-rho005-r6-048-xrkrg.18d465c1f7a06d1d,"reason=Pulled count=1 msg=Container image ""busybox:musl"" already present on machine"
0.2595,Event,ADDED,eval-conflicts-rho005-r6-048-xrkrg.18d465c1f8e9a9c1,reason=Created count=1 msg=Created container: task
0.2597,Event,ADDED,eval-conflicts-rho005-r6-048-xrkrg.18d465c1fdfb168a,reason=Started count=1 msg=Started container task
0.2599,Event,ADDED,eval-conflicts-rho005-r6-048.18d465c1dd95bb2b,reason=SuccessfulCreate count=1 msg=Created pod: eval-conflicts-rho005-r6-048-xrkrg
0.26,Event,ADDED,eval-conflicts-rho005-r6-048.18d465c509c45462,reason=Completed count=1 msg=Job completed
0.2602,Event,ADDED,eval-conflicts-rho005-r6-049-4cwvc.18d465c2195bb6c1,reason=Scheduled count=None msg=Successfully assigned compute/eval-conflicts-rho005-r6-049-4cwvc to kind-worker5
0.2603,Event,ADDED,eval-conflicts-rho005-r6-049-4cwvc.18d465c2329fbb63,"reason=Pulled count=1 msg=Container image ""busybox:musl"" already present on machine"
0.2605,Event,ADDED,eval-conflicts-rho005-r6-049-4cwvc.18d465c233cba12d,reason=Created count=1 msg=Created container: task
0.2607,Event,ADDED,eval-conflicts-rho005-r6-049-4cwvc.18d465c235c50f47,reason=Started count=1 msg=Started container task
0.2608,Event,ADDED,eval-conflicts-rho005-r6-049.18d465c218d20f97,reason=SuccessfulCreate count=1 msg=Created pod: eval-conflicts-rho005-r6-049-4cwvc
0.261,Event,ADDED,eval-conflicts-rho005-r6-049.18d465c545880883,reason=Completed count=1 msg=Job completed
0.2611,Event,ADDED,eval-conflicts-rho005-r6-050-gvtpj.18d465c254872532,reason=Scheduled count=None msg=Successfully assigned compute/eval-conflicts-rho005-r6-050-gvtpj to kind-worker5
0.2613,Event,ADDED,eval-conflicts-rho005-r6-050-gvtpj.18d465c26d1421ba,"reason=Pulled count=1 msg=Container image ""busybox:musl"" already present on machine"
0.2615,Event,ADDED,eval-conflicts-rho005-r6-050-gvtpj.18d465c26e2b1d0e,reason=Created count=1 msg=Created container: task
0.2617,Event,ADDED,eval-conflicts-rho005-r6-050-gvtpj.18d465c2724c13a6,reason=Started count=1 msg=Started container task
0.2618,Event,ADDED,eval-conflicts-rho005-r6-050.18d465c253f11ef4,reason=SuccessfulCreate count=1 msg=Created pod: eval-conflicts-rho005-r6-050-gvtpj
0.262,Event,ADDED,eval-conflicts-rho005-r6-050.18d465c5815c8120,reason=Completed count=1 msg=Job completed
0.2621,Event,ADDED,eval-conflicts-rho005-r6-051-rqsjj.18d465c29040ad1f,reason=Scheduled count=None msg=Successfully assigned compute/eval-conflicts-rho005-r6-051-rqsjj to kind-worker5
0.2623,Event,ADDED,eval-conflicts-rho005-r6-051-rqsjj.18d465c2aac704cd,"reason=Pulled count=1 msg=Container image ""busybox:musl"" already present on machine"
0.2625,Event,ADDED,eval-conflicts-rho005-r6-051-rqsjj.18d465c2abfc6ba3,reason=Created count=1 msg=Created container: task
0.2626,Event,ADDED,eval-conflicts-rho005-r6-051-rqsjj.18d465c2ae204027,reason=Started count=1 msg=Started container task
0.2628,Event,ADDED,eval-conflicts-rho005-r6-051.18d465c28fb63e5d,reason=SuccessfulCreate count=1 msg=Created pod: eval-conflicts-rho005-r6-051-rqsjj
0.263,Event,ADDED,eval-conflicts-rho005-r6-051.18d465c5bd22b103,reason=Completed count=1 msg=Job completed
0.2631,Event,ADDED,eval-conflicts-rho005-r6-052-5gp2n.18d465c2cb98bbb4,"reason=FailedScheduling count=None msg=0/6 nodes are available: 1 c_wall violated: 1 conflicting context pair(s) with node memory, 5 node(s) had untolerated taint(s). no new claims to deallocate, preemption: 0/6 nodes are available: 1 No preemption victims found for incoming pod, 5 Preemption is not helpful for scheduling."
0.2633,Event,ADDED,eval-conflicts-rho005-r6-052-5gp2n.18d465c2cc21a18f,"reason=FailedScheduling count=None msg=0/6 nodes are available: 1 c_wall violated: 1 conflicting context pair(s) with node memory, 5 node(s) had untolerated taint(s). no new claims to deallocate, preemption: 0/6 nodes are available: 1 No preemption victims found for incoming pod, 5 Preemption is not helpful for scheduling."
0.2635,Event,ADDED,eval-conflicts-rho005-r6-052-5gp2n.18d465c2d8833141,reason=Scheduled count=None msg=Successfully assigned compute/eval-conflicts-rho005-r6-052-5gp2n to kind-worker
0.2636,Event,ADDED,eval-conflicts-rho005-r6-052-5gp2n.18d465c2f2ece13c,"reason=Pulled count=1 msg=Container image ""busybox:musl"" already present on machine"
0.2638,Event,ADDED,eval-conflicts-rho005-r6-052-5gp2n.18d465c2f40f440f,reason=Created count=1 msg=Created container: task
0.264,Event,ADDED,eval-conflicts-rho005-r6-052-5gp2n.18d465c2f887efad,reason=Started count=1 msg=Started container task
0.2641,Event,ADDED,eval-conflicts-rho005-r6-052.18d465c2cb53bb8a,reason=SuccessfulCreate count=1 msg=Created pod: eval-conflicts-rho005-r6-052-5gp2n
0.2643,Event,ADDED,eval-conflicts-rho005-r6-052.18d465c62cbe7bcf,reason=Completed count=1 msg=Job completed
0.2645,Event,ADDED,eval-conflicts-rho005-r6-053-7jmpb.18d465c3086cf078,reason=Scheduled count=None msg=Successfully assigned compute/eval-conflicts-rho005-r6-053-7jmpb to kind-worker4
0.2646,Event,ADDED,eval-conflicts-rho005-r6-053-7jmpb.18d465c3334c34ad,"reason=Pulled count=1 msg=Container image ""busybox:musl"" already present on machine"
0.2649,Event,ADDED,eval-conflicts-rho005-r6-053-7jmpb.18d465c3346ad9dd,reason=Created count=1 msg=Created container: task
0.2651,Event,ADDED,eval-conflicts-rho005-r6-053-7jmpb.18d465c33683c7fc,reason=Started count=1 msg=Started container task
0.2652,Event,ADDED,eval-conflicts-rho005-r6-053.18d465c3071bbdf3,reason=SuccessfulCreate count=1 msg=Created pod: eval-conflicts-rho005-r6-053-7jmpb
0.2654,Event,ADDED,eval-conflicts-rho005-r6-053.18d465c65b590543,reason=Completed count=1 msg=Job completed
0.2655,Event,ADDED,eval-conflicts-rho005-r6-054-zwkvf.18d465c34376ccad,reason=Scheduled count=None msg=Successfully assigned compute/eval-conflicts-rho005-r6-054-zwkvf to kind-worker4
0.2658,Event,ADDED,eval-conflicts-rho005-r6-054-zwkvf.18d465c35e1c359f,"reason=Pulled count=1 msg=Container image ""busybox:musl"" already present on machine"
0.2659,Event,ADDED,eval-conflicts-rho005-r6-054-zwkvf.18d465c35f38989f,reason=Created count=1 msg=Created container: task
0.2661,Event,ADDED,eval-conflicts-rho005-r6-054-zwkvf.18d465c363a3adc4,reason=Started count=1 msg=Started container task
0.2664,Event,ADDED,eval-conflicts-rho005-r6-054.18d465c34250af8e,reason=SuccessfulCreate count=1 msg=Created pod: eval-conflicts-rho005-r6-054-zwkvf
0.2666,Event,ADDED,eval-conflicts-rho005-r6-054.18d465c697857f68,reason=Completed count=1 msg=Job completed
0.2667,Event,ADDED,eval-conflicts-rho005-r6-055-6wrgg.18d465c37f886e6b,reason=Scheduled count=None msg=Successfully assigned compute/eval-conflicts-rho005-r6-055-6wrgg to kind-worker4
0.2669,Event,ADDED,eval-conflicts-rho005-r6-055-6wrgg.18d465c398e2a1a7,"reason=Pulled count=1 msg=Container image ""busybox:musl"" already present on machine"
0.2671,Event,ADDED,eval-conflicts-rho005-r6-055-6wrgg.18d465c39a0e8995,reason=Created count=1 msg=Created container: task
0.2673,Event,ADDED,eval-conflicts-rho005-r6-055-6wrgg.18d465c39e0277ec,reason=Started count=1 msg=Started container task
0.2675,Event,ADDED,eval-conflicts-rho005-r6-055.18d465c37ed47371,reason=SuccessfulCreate count=1 msg=Created pod: eval-conflicts-rho005-r6-055-6wrgg
0.2676,Event,ADDED,eval-conflicts-rho005-r6-055.18d465c6d43aac9c,reason=Completed count=1 msg=Job completed
0.2678,Event,ADDED,eval-conflicts-rho005-r6-056-tgsw4.18d465c3bae98d4a,reason=Scheduled count=None msg=Successfully assigned compute/eval-conflicts-rho005-r6-056-tgsw4 to kind-worker
0.268,Event,ADDED,eval-conflicts-rho005-r6-056-tgsw4.18d465c3d59bb42d,"reason=Pulled count=1 msg=Container image ""busybox:musl"" already present on machine"
0.2682,Event,ADDED,eval-conflicts-rho005-r6-056-tgsw4.18d465c3d6ab6fee,reason=Created count=1 msg=Created container: task
0.2683,Event,ADDED,eval-conflicts-rho005-r6-056-tgsw4.18d465c3da02d6b7,reason=Started count=1 msg=Started container task
0.2685,Event,ADDED,eval-conflicts-rho005-r6-056.18d465c3b9f7ffb1,reason=SuccessfulCreate count=1 msg=Created pod: eval-conflicts-rho005-r6-056-tgsw4
0.2687,Event,ADDED,eval-conflicts-rho005-r6-056.18d465c71c87d4b4,reason=Completed count=1 msg=Job completed
0.2688,Event,ADDED,eval-conflicts-rho005-r6-057-62jkv.18d465c3f5f40ebd,reason=Scheduled count=None msg=Successfully assigned compute/eval-conflicts-rho005-r6-057-62jkv to kind-worker
0.269,Event,ADDED,eval-conflicts-rho005-r6-057-62jkv.18d465c40edb66a3,"reason=Pulled count=1 msg=Container image ""busybox:musl"" already present on machine"
0.2691,Event,ADDED,eval-conflicts-rho005-r6-057-62jkv.18d465c4101424d7,reason=Created count=1 msg=Created container: task
0.2693,Event,ADDED,eval-conflicts-rho005-r6-057-62jkv.18d465c412644c1e,reason=Started count=1 msg=Started container task
0.2695,Event,ADDED,eval-conflicts-rho005-r6-057.18d465c3f519d46e,reason=SuccessfulCreate count=1 msg=Created pod: eval-conflicts-rho005-r6-057-62jkv
0.2696,Event,ADDED,eval-conflicts-rho005-r6-057.18d465c7583785f9,reason=Completed count=1 msg=Job completed
0.2698,Event,ADDED,eval-conflicts-rho005-r6-058-ngtpz.18d465c43164eaec,reason=Scheduled count=None msg=Successfully assigned compute/eval-conflicts-rho005-r6-058-ngtpz to kind-worker
0.27,Event,ADDED,eval-conflicts-rho005-r6-058-ngtpz.18d465c44ac054d5,"reason=Pulled count=1 msg=Container image ""busybox:musl"" already present on machine"
0.2701,Event,ADDED,eval-conflicts-rho005-r6-058-ngtpz.18d465c44c1f5d23,reason=Created count=1 msg=Created container: task
0.2703,Event,ADDED,eval-conflicts-rho005-r6-058-ngtpz.18d465c44fab947d,reason=Started count=1 msg=Started container task
0.2705,Event,ADDED,eval-conflicts-rho005-r6-058.18d465c430883916,reason=SuccessfulCreate count=1 msg=Created pod: eval-conflicts-rho005-r6-058-ngtpz
0.2706,Event,ADDED,eval-conflicts-rho005-r6-058.18d465c79424ee52,reason=Completed count=1 msg=Job completed
0.2708,Event,ADDED,eval-conflicts-rho005-r6-059-vs9dc.18d465c46d0362b6,reason=Scheduled count=None msg=Successfully assigned compute/eval-conflicts-rho005-r6-059-vs9dc to kind-worker
0.2709,Event,ADDED,eval-conflicts-rho005-r6-059-vs9dc.18d465c4872c5ccd,"reason=Pulled count=1 msg=Container image ""busybox:musl"" already present on machine"
0.2711,Event,ADDED,eval-conflicts-rho005-r6-059-vs9dc.18d465c4886a295c,reason=Created count=1 msg=Created container: task
0.2713,Event,ADDED,eval-conflicts-rho005-r6-059-vs9dc.18d465c48c30bdb5,reason=Started count=1 msg=Started container task
0.2714,Event,ADDED,eval-conflicts-rho005-r6-059.18d465c46c01ce04,reason=SuccessfulCreate count=1 msg=Created pod: eval-conflicts-rho005-r6-059-vs9dc
0.2716,Event,ADDED,eval-conflicts-rho005-r6-059.18d465c7cf829a7b,reason=Completed count=1 msg=Job completed
0.2717,Event,ADDED,eval-conflicts-rho005-r6-060-lp6vg.18d465c4a933d565,reason=Scheduled count=None msg=Successfully assigned compute/eval-conflicts-rho005-r6-060-lp6vg to kind-worker4
0.2719,Event,ADDED,eval-conflicts-rho005-r6-060-lp6vg.18d465c4c22d54c3,"reason=Pulled count=1 msg=Container image ""busybox:musl"" already present on machine"
0.2721,Event,ADDED,eval-conflicts-rho005-r6-060-lp6vg.18d465c4c357a1e8,reason=Created count=1 msg=Created container: task
0.2722,Event,ADDED,eval-conflicts-rho005-r6-060-lp6vg.18d465c4c599524a,reason=Started count=1 msg=Started container task
0.2724,Event,ADDED,eval-conflicts-rho005-r6-060.18d465c4a84680d7,reason=SuccessfulCreate count=1 msg=Created pod: eval-conflicts-rho005-r6-060-lp6vg
0.2726,Event,ADDED,eval-conflicts-rho005-r6-060.18d465c7fe15a481,reason=Completed count=1 msg=Job completed
0.2727,Event,ADDED,eval-conflicts-rho005-r6-061-n96lf.18d465c4e510d504,reason=Scheduled count=None msg=Successfully assigned compute/eval-conflicts-rho005-r6-061-n96lf to kind-worker
0.2729,Event,ADDED,eval-conflicts-rho005-r6-061-n96lf.18d465c4fe698de5,"reason=Pulled count=1 msg=Container image ""busybox:musl"" already present on machine"
0.2731,Event,ADDED,eval-conflicts-rho005-r6-061-n96lf.18d465c4ffaf9cf1,reason=Created count=1 msg=Created container: task
0.2733,Event,ADDED,eval-conflicts-rho005-r6-061-n96lf.18d465c504e674e9,reason=Started count=1 msg=Started container task
0.2734,Event,ADDED,eval-conflicts-rho005-r6-061.18d465c4e4566980,reason=SuccessfulCreate count=1 msg=Created pod: eval-conflicts-rho005-r6-061-n96lf
0.2736,Event,ADDED,eval-conflicts-rho005-r6-061.18d465c84763e09b,reason=Completed count=1 msg=Job completed
0.2738,Event,ADDED,eval-conflicts-rho005-r6-062-wkwc2.18d465c51fe9ca08,reason=Scheduled count=None msg=Successfully assigned compute/eval-conflicts-rho005-r6-062-wkwc2 to kind-worker
0.2739,Event,ADDED,eval-conflicts-rho005-r6-062-wkwc2.18d465c53a2ab2cb,"reason=Pulled count=1 msg=Container image ""busybox:musl"" already present on machine"
0.2741,Event,ADDED,eval-conflicts-rho005-r6-062-wkwc2.18d465c53b5f8daa,reason=Created count=1 msg=Created container: task
0.2743,Event,ADDED,eval-conflicts-rho005-r6-062-wkwc2.18d465c53f39e6fa,reason=Started count=1 msg=Started container task
0.2744,Event,ADDED,eval-conflicts-rho005-r6-062.18d465c51f0ac46c,reason=SuccessfulCreate count=1 msg=Created pod: eval-conflicts-rho005-r6-062-wkwc2
0.2746,Event,ADDED,eval-conflicts-rho005-r6-062.18d465c8863f24ed,reason=Completed count=1 msg=Job completed
0.2747,Event,ADDED,eval-conflicts-rho005-r6-063-pfk57.18d465c55af34a4c,reason=Scheduled count=None msg=Successfully assigned compute/eval-conflicts-rho005-r6-063-pfk57 to kind-worker2
0.2749,Event,ADDED,eval-conflicts-rho005-r6-063-pfk57.18d465c573d6d2d7,"reason=Pulled count=1 msg=Container image ""busybox:musl"" already present on machine"
0.2751,Event,ADDED,eval-conflicts-rho005-r6-063-pfk57.18d465c574e85ee7,reason=Created count=1 msg=Created container: task
0.2752,Event,ADDED,eval-conflicts-rho005-r6-063-pfk57.18d465c576ff7e39,reason=Started count=1 msg=Started container task
0.2754,Event,ADDED,eval-conflicts-rho005-r6-063.18d465c55a9e98b2,reason=SuccessfulCreate count=1 msg=Created pod: eval-conflicts-rho005-r6-063-pfk57
0.2756,Event,ADDED,eval-conflicts-rho005-r6-063.18d465c8a5a97edf,reason=Completed count=1 msg=Job completed
0.2757,Event,ADDED,eval-conflicts-rho005-r6-064-kcnsm.18d465c596fcc0cd,reason=Scheduled count=None msg=Successfully assigned compute/eval-conflicts-rho005-r6-064-kcnsm to kind-worker2
0.2759,Event,ADDED,eval-conflicts-rho005-r6-064-kcnsm.18d465c5b10c7679,"reason=Pulled count=1 msg=Container image ""busybox:musl"" already present on machine"
0.2761,Event,ADDED,eval-conflicts-rho005-r6-064-kcnsm.18d465c5b236037f,reason=Created count=1 msg=Created container: task
0.2762,Event,ADDED,eval-conflicts-rho005-r6-064-kcnsm.18d465c5b4330c26,reason=Started count=1 msg=Started container task
0.2764,Event,ADDED,eval-conflicts-rho005-r6-064.18d465c596265f5a,reason=SuccessfulCreate count=1 msg=Created pod: eval-conflicts-rho005-r6-064-kcnsm
0.2765,Event,ADDED,eval-conflicts-rho005-r6-064.18d465c8e3c497f9,reason=Completed count=1 msg=Job completed
0.2767,Event,ADDED,eval-conflicts-rho005-r6-065-v8fqb.18d465c5d27359e7,reason=Scheduled count=None msg=Successfully assigned compute/eval-conflicts-rho005-r6-065-v8fqb to kind-worker2
0.2769,Event,ADDED,eval-conflicts-rho005-r6-065-v8fqb.18d465c5ec0d2108,"reason=Pulled count=1 msg=Container image ""busybox:musl"" already present on machine"
0.277,Event,ADDED,eval-conflicts-rho005-r6-065-v8fqb.18d465c5ed3330e2,reason=Created count=1 msg=Created container: task
0.2772,Event,ADDED,eval-conflicts-rho005-r6-065-v8fqb.18d465c5f121ff12,reason=Started count=1 msg=Started container task
0.2774,Event,ADDED,eval-conflicts-rho005-r6-065.18d465c5d1b5cb2b,reason=SuccessfulCreate count=1 msg=Created pod: eval-conflicts-rho005-r6-065-v8fqb
0.2776,Event,ADDED,eval-conflicts-rho005-r6-065.18d465c9246a073c,reason=Completed count=1 msg=Job completed
0.2777,Event,ADDED,eval-conflicts-rho005-r6-066-59vts.18d465c60e17e71f,reason=Scheduled count=None msg=Successfully assigned compute/eval-conflicts-rho005-r6-066-59vts to kind-worker5
0.2779,Event,ADDED,eval-conflicts-rho005-r6-066-59vts.18d465c6276f48a2,"reason=Pulled count=1 msg=Container image ""busybox:musl"" already present on machine"
0.2781,Event,ADDED,eval-conflicts-rho005-r6-066-59vts.18d465c62887084c,reason=Created count=1 msg=Created container: task
0.2782,Event,ADDED,eval-conflicts-rho005-r6-066-59vts.18d465c62a955207,reason=Started count=1 msg=Started container task
0.2784,Event,ADDED,eval-conflicts-rho005-r6-066.18d465c60d61b854,reason=SuccessfulCreate count=1 msg=Created pod: eval-conflicts-rho005-r6-066-59vts
0.2786,Event,ADDED,eval-conflicts-rho005-r6-066.18d465c944449a7b,reason=Completed count=1 msg=Job completed
0.2787,Event,ADDED,eval-conflicts-rho005-r6-067-lncbg.18d465c649e927ff,reason=Scheduled count=None msg=Successfully assigned compute/eval-conflicts-rho005-r6-067-lncbg to kind-worker5
0.2789,Event,ADDED,eval-conflicts-rho005-r6-067-lncbg.18d465c662ff8a5d,"reason=Pulled count=1 msg=Container image ""busybox:musl"" already present on machine"
0.279,Event,ADDED,eval-conflicts-rho005-r6-067-lncbg.18d465c66413d035,reason=Created count=1 msg=Created container: task
0.2792,Event,ADDED,eval-conflicts-rho005-r6-067-lncbg.18d465c6662eae12,reason=Started count=1 msg=Started container task
0.2794,Event,ADDED,eval-conflicts-rho005-r6-067.18d465c64901c7d7,reason=SuccessfulCreate count=1 msg=Created pod: eval-conflicts-rho005-r6-067-lncbg
0.2795,Event,ADDED,eval-conflicts-rho005-r6-067.18d465c9805b3b64,reason=Completed count=1 msg=Job completed
0.2797,Event,ADDED,eval-conflicts-rho005-r6-068-lrnlv.18d465c6857648a5,reason=Scheduled count=None msg=Successfully assigned compute/eval-conflicts-rho005-r6-068-lrnlv to kind-worker5
0.2799,Event,ADDED,eval-conflicts-rho005-r6-068-lrnlv.18d465c69e314f01,"reason=Pulled count=1 msg=Container image ""busybox:musl"" already present on machine"
0.2801,Event,ADDED,eval-conflicts-rho005-r6-068-lrnlv.18d465c69f446e6e,reason=Created count=1 msg=Created container: task
0.2802,Event,ADDED,eval-conflicts-rho005-r6-068-lrnlv.18d465c6a1e3c6bf,reason=Started count=1 msg=Started container task
0.2804,Event,ADDED,eval-conflicts-rho005-r6-068.18d465c684873443,reason=SuccessfulCreate count=1 msg=Created pod: eval-conflicts-rho005-r6-068-lrnlv
0.2806,Event,ADDED,eval-conflicts-rho005-r6-068.18d465c9bc09a3a5,reason=Completed count=1 msg=Job completed
0.2807,Event,ADDED,eval-conflicts-rho005-r6-069-n2hr8.18d465c6c1e823cf,reason=Scheduled count=None msg=Successfully assigned compute/eval-conflicts-rho005-r6-069-n2hr8 to kind-worker5
0.2809,Event,ADDED,eval-conflicts-rho005-r6-069-n2hr8.18d465c6db9a6bd5,"reason=Pulled count=1 msg=Container image ""busybox:musl"" already present on machine"
0.281,Event,ADDED,eval-conflicts-rho005-r6-069-n2hr8.18d465c6dcd1eafa,reason=Created count=1 msg=Created container: task
0.2812,Event,ADDED,eval-conflicts-rho005-r6-069-n2hr8.18d465c6e182b962,reason=Started count=1 msg=Started container task
0.2814,Event,ADDED,eval-conflicts-rho005-r6-069.18d465c6c11003a9,reason=SuccessfulCreate count=1 msg=Created pod: eval-conflicts-rho005-r6-069-n2hr8
0.2815,Event,ADDED,eval-conflicts-rho005-r6-069.18d465c9f818a64e,reason=Completed count=1 msg=Job completed
0.2817,Event,ADDED,eval-conflicts-rho005-r6-070-hfqt9.18d465c6fd07a26b,reason=Scheduled count=None msg=Successfully assigned compute/eval-conflicts-rho005-r6-070-hfqt9 to kind-worker5
0.2819,Event,ADDED,eval-conflicts-rho005-r6-070-hfqt9.18d465c716c935ff,"reason=Pulled count=1 msg=Container image ""busybox:musl"" already present on machine"
0.2821,Event,ADDED,eval-conflicts-rho005-r6-070-hfqt9.18d465c71812594b,reason=Created count=1 msg=Created container: task
0.2823,Event,ADDED,eval-conflicts-rho005-r6-070-hfqt9.18d465c71bfbd711,reason=Started count=1 msg=Started container task
0.2825,Event,ADDED,eval-conflicts-rho005-r6-070.18d465c6fc2e4a65,reason=SuccessfulCreate count=1 msg=Created pod: eval-conflicts-rho005-r6-070-hfqt9
0.2827,Event,ADDED,eval-conflicts-rho005-r6-070.18d465ca37b9e140,reason=Completed count=1 msg=Job completed
0.2828,Event,ADDED,eval-conflicts-rho005-r6-071-k7m9h.18d465c7383b62fa,reason=Scheduled count=None msg=Successfully assigned compute/eval-conflicts-rho005-r6-071-k7m9h to kind-worker2
0.283,Event,ADDED,eval-conflicts-rho005-r6-071-k7m9h.18d465c7515baa79,"reason=Pulled count=1 msg=Container image ""busybox:musl"" already present on machine"
0.2832,Event,ADDED,eval-conflicts-rho005-r6-071-k7m9h.18d465c7528f3b37,reason=Created count=1 msg=Created container: task
0.2833,Event,ADDED,eval-conflicts-rho005-r6-071-k7m9h.18d465c754bb3e88,reason=Started count=1 msg=Started container task
0.2835,Event,ADDED,eval-conflicts-rho005-r6-071.18d465c7376df539,reason=SuccessfulCreate count=1 msg=Created pod: eval-conflicts-rho005-r6-071-k7m9h
0.2837,Event,ADDED,eval-conflicts-rho005-r6-071.18d465ca85a41e68,reason=Completed count=1 msg=Job completed
0.2838,Event,ADDED,eval-conflicts-rho005-r6-072-p6nx2.18d465c77416087c,reason=Scheduled count=None msg=Successfully assigned compute/eval-conflicts-rho005-r6-072-p6nx2 to kind-worker2
0.284,Event,ADDED,eval-conflicts-rho005-r6-072-p6nx2.18d465c78d7c20ac,"reason=Pulled count=1 msg=Container image ""busybox:musl"" already present on machine"
0.2842,Event,ADDED,eval-conflicts-rho005-r6-072-p6nx2.18d465c78e9b8113,reason=Created count=1 msg=Created container: task
0.2843,Event,ADDED,eval-conflicts-rho005-r6-072-p6nx2.18d465c792b7e034,reason=Started count=1 msg=Started container task
0.2845,Event,ADDED,eval-conflicts-rho005-r6-072.18d465c77325cac8,reason=SuccessfulCreate count=1 msg=Created pod: eval-conflicts-rho005-r6-072-p6nx2
0.2847,Event,ADDED,eval-conflicts-rho005-r6-072.18d465ca8638dd5c,reason=Completed count=1 msg=Job completed
0.2848,Event,ADDED,eval-conflicts-rho005-r6-073-w8hkr.18d465c7aee3bfcc,reason=Scheduled count=None msg=Successfully assigned compute/eval-conflicts-rho005-r6-073-w8hkr to kind-worker3
0.285,Event,ADDED,eval-conflicts-rho005-r6-073-w8hkr.18d465c7c86fea5a,"reason=Pulled count=1 msg=Container image ""busybox:musl"" already present on machine"
0.2851,Event,ADDED,eval-conflicts-rho005-r6-073-w8hkr.18d465c7c9800037,reason=Created count=1 msg=Created container: task
0.2853,Event,ADDED,eval-conflicts-rho005-r6-073-w8hkr.18d465c7cbaad297,reason=Started count=1 msg=Started container task
0.2855,Event,ADDED,eval-conflicts-rho005-r6-073.18d465c7ae5c48b2,reason=SuccessfulCreate count=1 msg=Created pod: eval-conflicts-rho005-r6-073-w8hkr
0.2856,Event,ADDED,eval-conflicts-rho005-r6-073.18d465cb024dac01,reason=Completed count=1 msg=Job completed
0.2858,Event,ADDED,eval-conflicts-rho005-r6-074-xjvjx.18d465c7eaff85c3,reason=Scheduled count=None msg=Successfully assigned compute/eval-conflicts-rho005-r6-074-xjvjx to kind-worker4
0.2859,Event,ADDED,eval-conflicts-rho005-r6-074-xjvjx.18d465c8040661d3,"reason=Pulled count=1 msg=Container image ""busybox:musl"" already present on machine"
0.2861,Event,ADDED,eval-conflicts-rho005-r6-074-xjvjx.18d465c8051801ef,reason=Created count=1 msg=Created container: task
0.2863,Event,ADDED,eval-conflicts-rho005-r6-074-xjvjx.18d465c8072cd2f2,reason=Started count=1 msg=Started container task
0.2864,Event,ADDED,eval-conflicts-rho005-r6-074.18d465c7ea015606,reason=SuccessfulCreate count=1 msg=Created pod: eval-conflicts-rho005-r6-074-xjvjx
0.2866,Event,ADDED,eval-conflicts-rho005-r6-074.18d465cb4dcf093b,reason=Completed count=1 msg=Job completed
0.2868,Event,ADDED,eval-conflicts-rho005-r6-075-7fg46.18d465c827dd07b6,reason=Scheduled count=None msg=Successfully assigned compute/eval-conflicts-rho005-r6-075-7fg46 to kind-worker4
0.287,Event,ADDED,eval-conflicts-rho005-r6-075-7fg46.18d465c840871489,"reason=Pulled count=1 msg=Container image ""busybox:musl"" already present on machine"
0.2872,Event,ADDED,eval-conflicts-rho005-r6-075-7fg46.18d465c841be2a3f,reason=Created count=1 msg=Created container: task
0.2874,Event,ADDED,eval-conflicts-rho005-r6-075-7fg46.18d465c84614199c,reason=Started count=1 msg=Started container task
0.2876,Event,ADDED,eval-conflicts-rho005-r6-075.18d465c827005de8,reason=SuccessfulCreate count=1 msg=Created pod: eval-conflicts-rho005-r6-075-7fg46
0.2877,Event,ADDED,eval-conflicts-rho005-r6-075.18d465cb7f61707c,reason=Completed count=1 msg=Job completed
0.2879,Event,ADDED,eval-conflicts-rho005-r6-076-f5bcr.18d465c862057fec,"reason=FailedScheduling count=None msg=0/6 nodes are available: 1 c_wall violated: 1 conflicting context pair(s) with node memory, 5 node(s) had untolerated taint(s). no new claims to deallocate, preemption: 0/6 nodes are available: 1 No preemption victims found for incoming pod, 5 Preemption is not helpful for scheduling."
0.2881,Event,ADDED,eval-conflicts-rho005-r6-076-f5bcr.18d465c862829883,"reason=FailedScheduling count=None msg=0/6 nodes are available: 1 c_wall violated: 1 conflicting context pair(s) with node memory, 5 node(s) had untolerated taint(s). no new claims to deallocate, preemption: 0/6 nodes are available: 1 No preemption victims found for incoming pod, 5 Preemption is not helpful for scheduling."
0.2882,Event,ADDED,eval-conflicts-rho005-r6-076-f5bcr.18d465c9f9880dd2,reason=Scheduled count=None msg=Successfully assigned compute/eval-conflicts-rho005-r6-076-f5bcr to kind-worker
0.2884,Event,ADDED,eval-conflicts-rho005-r6-076-f5bcr.18d465ca16cde6ae,"reason=Pulled count=1 msg=Container image ""busybox:musl"" already present on machine"
0.2886,Event,ADDED,eval-conflicts-rho005-r6-076-f5bcr.18d465ca18435c17,reason=Created count=1 msg=Created container: task
0.2887,Event,ADDED,eval-conflicts-rho005-r6-076-f5bcr.18d465ca1c6ae6a6,reason=Started count=1 msg=Started container task
0.2889,Event,ADDED,eval-conflicts-rho005-r6-076.18d465c861bbe455,reason=SuccessfulCreate count=1 msg=Created pod: eval-conflicts-rho005-r6-076-f5bcr
0.289,Event,ADDED,eval-conflicts-rho005-r6-076.18d465cd2ffe3887,reason=Completed count=1 msg=Job completed
0.2892,Event,ADDED,eval-conflicts-rho005-r6-077-l7l62.18d465c89dc6bb81,reason=Scheduled count=None msg=Successfully assigned compute/eval-conflicts-rho005-r6-077-l7l62 to kind-worker4
0.2894,Event,ADDED,eval-conflicts-rho005-r6-077-l7l62.18d465c8b7cb27f2,"reason=Pulled count=1 msg=Container image ""busybox:musl"" already present on machine"
0.2895,Event,ADDED,eval-conflicts-rho005-r6-077-l7l62.18d465c8b8fffc29,reason=Created count=1 msg=Created container: task
0.2897,Event,ADDED,eval-conflicts-rho005-r6-077-l7l62.18d465c8c4c4e888,reason=Started count=1 msg=Started container task
0.2899,Event,ADDED,eval-conflicts-rho005-r6-077.18d465c89d271b8c,reason=SuccessfulCreate count=1 msg=Created pod: eval-conflicts-rho005-r6-077-l7l62
0.29,Event,ADDED,eval-conflicts-rho005-r6-077.18d465cbf6f3418b,reason=Completed count=1 msg=Job completed
0.2902,Event,ADDED,eval-conflicts-rho005-r6-078-jcz5v.18d465c8d9712744,reason=Scheduled count=None msg=Successfully assigned compute/eval-conflicts-rho005-r6-078-jcz5v to kind-worker4
0.2903,Event,ADDED,eval-conflicts-rho005-r6-078-jcz5v.18d465c8f77f5d37,"reason=Pulled count=1 msg=Container image ""busybox:musl"" already present on machine"
0.2905,Event,ADDED,eval-conflicts-rho005-r6-078-jcz5v.18d465c8f8a1150b,reason=Created count=1 msg=Created container: task
0.2907,Event,ADDED,eval-conflicts-rho005-r6-078-jcz5v.18d465c8ff9cb9e8,reason=Started count=1 msg=Started container task
0.2908,Event,ADDED,eval-conflicts-rho005-r6-078.18d465c8d8de0d64,reason=SuccessfulCreate count=1 msg=Created pod: eval-conflicts-rho005-r6-078-jcz5v
0.291,Event,ADDED,eval-conflicts-rho005-r6-078.18d465cc32bd8399,reason=Completed count=1 msg=Job completed
0.2911,Event,ADDED,eval-conflicts-rho005-r6-079-6p2c9.18d465c915873537,reason=Scheduled count=None msg=Successfully assigned compute/eval-conflicts-rho005-r6-079-6p2c9 to kind-worker4
0.2913,Event,ADDED,eval-conflicts-rho005-r6-079-6p2c9.18d465c92fa69332,"reason=Pulled count=1 msg=Container image ""busybox:musl"" already present on machine"
0.2915,Event,ADDED,eval-conflicts-rho005-r6-079-6p2c9.18d465c930db3ed8,reason=Created count=1 msg=Created container: task
0.2916,Event,ADDED,eval-conflicts-rho005-r6-079-6p2c9.18d465c9391114b9,reason=Started count=1 msg=Started container task
0.2918,Event,ADDED,eval-conflicts-rho005-r6-079.18d465c914e5181e,reason=SuccessfulCreate count=1 msg=Created pod: eval-conflicts-rho005-r6-079-6p2c9
0.292,Event,ADDED,eval-conflicts-rho005-r6-079.18d465cc6eeecd21,reason=Completed count=1 msg=Job completed
0.2921,Event,ADDED,eval-conflicts-rho005-r6-080-7s9qw.18d465c9524479d8,reason=Scheduled count=None msg=Successfully assigned compute/eval-conflicts-rho005-r6-080-7s9qw to kind-worker4
0.2923,Event,ADDED,eval-conflicts-rho005-r6-080-7s9qw.18d465c9712d73ce,"reason=Pulled count=1 msg=Container image ""busybox:musl"" already present on machine"
0.2925,Event,ADDED,eval-conflicts-rho005-r6-080-7s9qw.18d465c972753bc6,reason=Created count=1 msg=Created container: task
0.2926,Event,ADDED,eval-conflicts-rho005-r6-080-7s9qw.18d465c97cd888cb,reason=Started count=1 msg=Started container task
0.2928,Event,ADDED,eval-conflicts-rho005-r6-080.18d465c951bebb9e,reason=SuccessfulCreate count=1 msg=Created pod: eval-conflicts-rho005-r6-080-7s9qw
0.293,Event,ADDED,eval-conflicts-rho005-r6-080.18d465ccaae5c327,reason=Completed count=1 msg=Job completed
0.2931,Event,ADDED,eval-conflicts-rho005-r6-081-lz85h.18d465c99173a9ff,reason=Scheduled count=None msg=Successfully assigned compute/eval-conflicts-rho005-r6-081-lz85h to kind-worker4
0.2933,Event,ADDED,eval-conflicts-rho005-r6-081-lz85h.18d465c9b5472824,"reason=Pulled count=1 msg=Container image ""busybox:musl"" already present on machine"
0.2935,Event,ADDED,eval-conflicts-rho005-r6-081-lz85h.18d465c9b69c8964,reason=Created count=1 msg=Created container: task
0.2936,Event,ADDED,eval-conflicts-rho005-r6-081-lz85h.18d465c9babed34c,reason=Started count=1 msg=Started container task
0.2938,Event,ADDED,eval-conflicts-rho005-r6-081.18d465c990db764b,reason=SuccessfulCreate count=1 msg=Created pod: eval-conflicts-rho005-r6-081-lz85h
0.2941,Event,ADDED,eval-conflicts-rho005-r6-081.18d465cce729de50,reason=Completed count=1 msg=Job completed
0.2943,Event,ADDED,eval-conflicts-rho005-r6-082-m24lt.18d465c9c72e90f4,"reason=FailedScheduling count=None msg=0/6 nodes are available: 1 c_wall violated: 1 conflicting context pair(s) with node memory, 5 node(s) had untolerated taint(s). no new claims to deallocate, preemption: 0/6 nodes are available: 1 No preemption victims found for incoming pod, 5 Preemption is not helpful for scheduling."
0.2945,Event,ADDED,eval-conflicts-rho005-r6-082-m24lt.18d465c9c7a73b18,"reason=FailedScheduling count=None msg=0/6 nodes are available: 1 c_wall violated: 1 conflicting context pair(s) with node memory, 5 node(s) had untolerated taint(s). no new claims to deallocate, preemption: 0/6 nodes are available: 1 No preemption victims found for incoming pod, 5 Preemption is not helpful for scheduling."
0.2948,Event,ADDED,eval-conflicts-rho005-r6-082-m24lt.18d465c9fa03c916,reason=Scheduled count=None msg=Successfully assigned compute/eval-conflicts-rho005-r6-082-m24lt to kind-worker
0.2949,Event,ADDED,eval-conflicts-rho005-r6-082-m24lt.18d465ca16ecb12f,"reason=Pulled count=1 msg=Container image ""busybox:musl"" already present on machine"
0.2951,Event,ADDED,eval-conflicts-rho005-r6-082-m24lt.18d465ca18bab052,reason=Created count=1 msg=Created container: task
0.2954,Event,ADDED,eval-conflicts-rho005-r6-082-m24lt.18d465ca1c6d404f,reason=Started count=1 msg=Started container task
0.2956,Event,ADDED,eval-conflicts-rho005-r6-082.18d465c9c6ed34c6,reason=SuccessfulCreate count=1 msg=Created pod: eval-conflicts-rho005-r6-082-m24lt
0.2958,Event,ADDED,eval-conflicts-rho005-r6-082.18d465cd2f7ada36,reason=Completed count=1 msg=Job completed
0.2959,Event,ADDED,eval-conflicts-rho005-r6-083-jqwb5.18d465ca09c4cd01,reason=Scheduled count=None msg=Successfully assigned compute/eval-conflicts-rho005-r6-083-jqwb5 to kind-worker
0.2964,Event,ADDED,eval-conflicts-rho005-r6-083-jqwb5.18d465ca27267dc6,"reason=Pulled count=1 msg=Container image ""busybox:musl"" already present on machine"
0.2965,Event,ADDED,eval-conflicts-rho005-r6-083-jqwb5.18d465ca28678d62,reason=Created count=1 msg=Created container: task
0.2967,Event,ADDED,eval-conflicts-rho005-r6-083-jqwb5.18d465ca2ccc0318,reason=Started count=1 msg=Started container task
0.2969,Event,ADDED,eval-conflicts-rho005-r6-083.18d465ca08930dd7,reason=SuccessfulCreate count=1 msg=Created pod: eval-conflicts-rho005-r6-083-jqwb5
0.2973,Event,ADDED,eval-conflicts-rho005-r6-083.18d465cd6b5c94cc,reason=Completed count=1 msg=Job completed
0.2975,Event,ADDED,eval-conflicts-rho005-r6-084-kkd5p.18d465ca3ea4f908,reason=Scheduled count=None msg=Successfully assigned compute/eval-conflicts-rho005-r6-084-kkd5p to kind-worker
0.2977,Event,ADDED,eval-conflicts-rho005-r6-084-kkd5p.18d465ca613cf865,"reason=Pulled count=1 msg=Container image ""busybox:musl"" already present on machine"
0.2979,Event,ADDED,eval-conflicts-rho005-r6-084-kkd5p.18d465ca626e4474,reason=Created count=1 msg=Created container: task
0.298,Event,ADDED,eval-conflicts-rho005-r6-084-kkd5p.18d465ca6bc725c1,reason=Started count=1 msg=Started container task
0.2982,Event,ADDED,eval-conflicts-rho005-r6-084.18d465ca3e36dd44,reason=SuccessfulCreate count=1 msg=Created pod: eval-conflicts-rho005-r6-084-kkd5p
0.2984,Event,ADDED,eval-conflicts-rho005-r6-084.18d465cda718a0ef,reason=Completed count=1 msg=Job completed
0.2986,Event,ADDED,eval-conflicts-rho005-r6-085-b2sgd.18d465ca7a5c07ba,reason=Scheduled count=None msg=Successfully assigned compute/eval-conflicts-rho005-r6-085-b2sgd to kind-worker
0.2988,Event,ADDED,eval-conflicts-rho005-r6-085-b2sgd.18d465ca9b1258e9,"reason=Pulled count=1 msg=Container image ""busybox:musl"" already present on machine"
0.299,Event,ADDED,eval-conflicts-rho005-r6-085-b2sgd.18d465ca9f313fd0,reason=Created count=1 msg=Created container: task
0.2991,Event,ADDED,eval-conflicts-rho005-r6-085-b2sgd.18d465caa3b135af,reason=Started count=1 msg=Started container task
0.2994,Event,ADDED,eval-conflicts-rho005-r6-085.18d465ca79d20b71,reason=SuccessfulCreate count=1 msg=Created pod: eval-conflicts-rho005-r6-085-b2sgd
0.2996,Event,ADDED,eval-conflicts-rho005-r6-085.18d465cde32ddae1,reason=Completed count=1 msg=Job completed
0.2997,Event,ADDED,eval-conflicts-rho005-r6-086-dwqbf.18d465cab71eff1b,reason=Scheduled count=None msg=Successfully assigned compute/eval-conflicts-rho005-r6-086-dwqbf to kind-worker5
0.2999,Event,ADDED,eval-conflicts-rho005-r6-086-dwqbf.18d465cad3c4ea3c,"reason=Pulled count=1 msg=Container image ""busybox:musl"" already present on machine"
0.3,Event,ADDED,eval-conflicts-rho005-r6-086-dwqbf.18d465cad4f8e9c4,reason=Created count=1 msg=Created container: task
0.3002,Event,ADDED,eval-conflicts-rho005-r6-086-dwqbf.18d465cade5816c1,reason=Started count=1 msg=Started container task
0.3004,Event,ADDED,eval-conflicts-rho005-r6-086.18d465cab65bec25,reason=SuccessfulCreate count=1 msg=Created pod: eval-conflicts-rho005-r6-086-dwqbf
0.3005,Event,ADDED,eval-conflicts-rho005-r6-086.18d465cdec45340e,reason=Completed count=1 msg=Job completed
0.3007,Event,ADDED,eval-conflicts-rho005-r6-087-6t78s.18d465caf20a86e0,reason=Scheduled count=None msg=Successfully assigned compute/eval-conflicts-rho005-r6-087-6t78s to kind-worker5
0.3009,Event,ADDED,eval-conflicts-rho005-r6-087-6t78s.18d465cb1195705a,"reason=Pulled count=1 msg=Container image ""busybox:musl"" already present on machine"
0.3011,Event,ADDED,eval-conflicts-rho005-r6-087-6t78s.18d465cb12dd08f5,reason=Created count=1 msg=Created container: task
0.3013,Event,ADDED,eval-conflicts-rho005-r6-087-6t78s.18d465cb1b357cc7,reason=Started count=1 msg=Started container task
0.3015,Event,ADDED,eval-conflicts-rho005-r6-087.18d465caf121349c,reason=SuccessfulCreate count=1 msg=Created pod: eval-conflicts-rho005-r6-087-6t78s
0.3016,Event,ADDED,eval-conflicts-rho005-r6-087.18d465ce63fa740c,reason=Completed count=1 msg=Job completed
0.3019,Event,ADDED,eval-conflicts-rho005-r6-088-6gmzg.18d465cb2dadd9ea,reason=Scheduled count=None msg=Successfully assigned compute/eval-conflicts-rho005-r6-088-6gmzg to kind-worker5
0.302,Event,ADDED,eval-conflicts-rho005-r6-088-6gmzg.18d465cb4b1caa7d,"reason=Pulled count=1 msg=Container image ""busybox:musl"" already present on machine"
0.3022,Event,ADDED,eval-conflicts-rho005-r6-088-6gmzg.18d465cb4c3e5d3a,reason=Created count=1 msg=Created container: task
0.3024,Event,ADDED,eval-conflicts-rho005-r6-088-6gmzg.18d465cb509503f0,reason=Started count=1 msg=Started container task
0.3026,Event,ADDED,eval-conflicts-rho005-r6-088.18d465cb2cbc4515,reason=SuccessfulCreate count=1 msg=Created pod: eval-conflicts-rho005-r6-088-6gmzg
0.3027,Event,ADDED,eval-conflicts-rho005-r6-088.18d465ce64618163,reason=Completed count=1 msg=Job completed
0.3029,Event,ADDED,eval-conflicts-rho005-r6-089-sjsc6.18d465cb69463611,reason=Scheduled count=None msg=Successfully assigned compute/eval-conflicts-rho005-r6-089-sjsc6 to kind-worker5
0.303,Event,ADDED,eval-conflicts-rho005-r6-089-sjsc6.18d465cb89612391,"reason=Pulled count=1 msg=Container image ""busybox:musl"" already present on machine"
0.3032,Event,ADDED,eval-conflicts-rho005-r6-089-sjsc6.18d465cb8ac40179,reason=Created count=1 msg=Created container: task
0.3034,Event,ADDED,eval-conflicts-rho005-r6-089-sjsc6.18d465cb94341c87,reason=Started count=1 msg=Started container task
0.3035,Event,ADDED,eval-conflicts-rho005-r6-089.18d465cb68404f9d,reason=SuccessfulCreate count=1 msg=Created pod: eval-conflicts-rho005-r6-089-sjsc6
0.3038,Event,ADDED,eval-conflicts-rho005-r6-089.18d465cedc6bc1dc,reason=Completed count=1 msg=Job completed
0.3039,Event,ADDED,eval-conflicts-rho005-r6-090-sd6km.18d465cba5089936,reason=Scheduled count=None msg=Successfully assigned compute/eval-conflicts-rho005-r6-090-sd6km to kind-worker5
0.3041,Event,ADDED,eval-conflicts-rho005-r6-090-sd6km.18d465cbc376c1b6,"reason=Pulled count=1 msg=Container image ""busybox:musl"" already present on machine"
0.3042,Event,ADDED,eval-conflicts-rho005-r6-090-sd6km.18d465cbc48e2e4c,reason=Created count=1 msg=Created container: task
0.3045,Event,ADDED,eval-conflicts-rho005-r6-090-sd6km.18d465cbc822b6cf,reason=Started count=1 msg=Started container task
0.3046,Event,ADDED,eval-conflicts-rho005-r6-090.18d465cba41dc401,reason=SuccessfulCreate count=1 msg=Created pod: eval-conflicts-rho005-r6-090-sd6km
0.3048,Event,ADDED,eval-conflicts-rho005-r6-090.18d465cedbbf023a,reason=Completed count=1 msg=Job completed
0.305,Event,ADDED,eval-conflicts-rho005-r6-091-vh9kl.18d465cbe10452d4,reason=Scheduled count=None msg=Successfully assigned compute/eval-conflicts-rho005-r6-091-vh9kl to kind-worker
0.3051,Event,ADDED,eval-conflicts-rho005-r6-091-vh9kl.18d465cc029e29bf,"reason=Pulled count=1 msg=Container image ""busybox:musl"" already present on machine"
0.3053,Event,ADDED,eval-conflicts-rho005-r6-091-vh9kl.18d465cc03c0b2df,reason=Created count=1 msg=Created container: task
0.3054,Event,ADDED,eval-conflicts-rho005-r6-091-vh9kl.18d465cc0733913a,reason=Started count=1 msg=Started container task
0.3057,Event,ADDED,eval-conflicts-rho005-r6-091.18d465cbe01a352a,reason=SuccessfulCreate count=1 msg=Created pod: eval-conflicts-rho005-r6-091-vh9kl
0.3058,Event,ADDED,eval-conflicts-rho005-r6-091.18d465cf49af8800,reason=Completed count=1 msg=Job completed
0.306,Event,ADDED,eval-conflicts-rho005-r6-092-hcjxn.18d465cc1c1bf089,reason=Scheduled count=None msg=Successfully assigned compute/eval-conflicts-rho005-r6-092-hcjxn to kind-worker5
0.3062,Event,ADDED,eval-conflicts-rho005-r6-092-hcjxn.18d465cc3c2bb61d,"reason=Pulled count=1 msg=Container image ""busybox:musl"" already present on machine"
0.3063,Event,ADDED,eval-conflicts-rho005-r6-092-hcjxn.18d465cc3dceb672,reason=Created count=1 msg=Created container: task
0.3065,Event,ADDED,eval-conflicts-rho005-r6-092-hcjxn.18d465cc46681d42,reason=Started count=1 msg=Started container task
0.3067,Event,ADDED,eval-conflicts-rho005-r6-092.18d465cc1b3a2a1f,reason=SuccessfulCreate count=1 msg=Created pod: eval-conflicts-rho005-r6-092-hcjxn
0.3069,Event,ADDED,eval-conflicts-rho005-r6-092.18d465cf52d690ae,reason=Completed count=1 msg=Job completed
0.307,Event,ADDED,eval-conflicts-rho005-r6-093-f2bv2.18d465cc5aaedf5c,reason=Scheduled count=None msg=Successfully assigned compute/eval-conflicts-rho005-r6-093-f2bv2 to kind-worker5
0.3072,Event,ADDED,eval-conflicts-rho005-r6-093-f2bv2.18d465cc75e45a78,"reason=Pulled count=1 msg=Container image ""busybox:musl"" already present on machine"
0.3074,Event,ADDED,eval-conflicts-rho005-r6-093-f2bv2.18d465cc7715f567,reason=Created count=1 msg=Created container: task
0.3078,Event,ADDED,eval-conflicts-rho005-r6-093-f2bv2.18d465cc7b5691ae,reason=Started count=1 msg=Started container task
0.3079,Event,ADDED,eval-conflicts-rho005-r6-093.18d465cc5a0a767e,reason=SuccessfulCreate count=1 msg=Created pod: eval-conflicts-rho005-r6-093-f2bv2
0.3082,Event,ADDED,eval-conflicts-rho005-r6-093.18d465cf8eb21f6b,reason=Completed count=1 msg=Job completed
0.3084,Event,ADDED,eval-conflicts-rho005-r6-094-r2x7g.18d465cc931e56d5,reason=Scheduled count=None msg=Successfully assigned compute/eval-conflicts-rho005-r6-094-r2x7g to kind-worker2
0.3086,Event,ADDED,eval-conflicts-rho005-r6-094-r2x7g.18d465ccb0a32bdf,"reason=Pulled count=1 msg=Container image ""busybox:musl"" already present on machine"
0.3088,Event,ADDED,eval-conflicts-rho005-r6-094-r2x7g.18d465ccb1c05321,reason=Created count=1 msg=Created container: task
0.309,Event,ADDED,eval-conflicts-rho005-r6-094-r2x7g.18d465ccb3b7b255,reason=Started count=1 msg=Started container task
0.3091,Event,ADDED,eval-conflicts-rho005-r6-094.18d465cc927a23bc,reason=SuccessfulCreate count=1 msg=Created pod: eval-conflicts-rho005-r6-094-r2x7g
0.3093,Event,ADDED,eval-conflicts-rho005-r6-094.18d465cfe132bb87,reason=Completed count=1 msg=Job completed
0.3095,Event,ADDED,eval-conflicts-rho005-r6-095-kkcwt.18d465cccefd79b1,reason=Scheduled count=None msg=Successfully assigned compute/eval-conflicts-rho005-r6-095-kkcwt to kind-worker2
0.3096,Event,ADDED,eval-conflicts-rho005-r6-095-kkcwt.18d465cce9ac25ab,"reason=Pulled count=1 msg=Container image ""busybox:musl"" already present on machine"
0.3098,Event,ADDED,eval-conflicts-rho005-r6-095-kkcwt.18d465cceacee648,reason=Created count=1 msg=Created container: task
0.31,Event,ADDED,eval-conflicts-rho005-r6-095-kkcwt.18d465ccecd3c019,reason=Started count=1 msg=Started container task
0.3102,Event,ADDED,eval-conflicts-rho005-r6-095.18d465ccce1eaaf2,reason=SuccessfulCreate count=1 msg=Created pod: eval-conflicts-rho005-r6-095-kkcwt
0.3103,Event,ADDED,eval-conflicts-rho005-r6-095.18d465cfe1d3aedb,reason=Completed count=1 msg=Job completed
0.3105,Event,ADDED,eval-conflicts-rho005-r6-096-xz8ww.18d465cd0b6044c0,reason=Scheduled count=None msg=Successfully assigned compute/eval-conflicts-rho005-r6-096-xz8ww to kind-worker2
0.3107,Event,ADDED,eval-conflicts-rho005-r6-096-xz8ww.18d465cd24cec640,"reason=Pulled count=1 msg=Container image ""busybox:musl"" already present on machine"
0.3108,Event,ADDED,eval-conflicts-rho005-r6-096-xz8ww.18d465cd260c7cd5,reason=Created count=1 msg=Created container: task
0.311,Event,ADDED,eval-conflicts-rho005-r6-096-xz8ww.18d465cd2a7757f3,reason=Started count=1 msg=Started container task
0.3111,Event,ADDED,eval-conflicts-rho005-r6-096.18d465cd0a8742b6,reason=SuccessfulCreate count=1 msg=Created pod: eval-conflicts-rho005-r6-096-xz8ww
0.3113,Event,ADDED,eval-conflicts-rho005-r6-096.18d465d0597873aa,reason=Completed count=1 msg=Job completed
0.3115,Event,ADDED,eval-conflicts-rho005-r6-097-6hvnl.18d465cd45ef9d4a,reason=Scheduled count=None msg=Successfully assigned compute/eval-conflicts-rho005-r6-097-6hvnl to kind-worker2
0.3117,Event,ADDED,eval-conflicts-rho005-r6-097-6hvnl.18d465cd5e6bb800,"reason=Pulled count=1 msg=Container image ""busybox:musl"" already present on machine"
0.3119,Event,ADDED,eval-conflicts-rho005-r6-097-6hvnl.18d465cd5fa4b112,reason=Created count=1 msg=Created container: task
0.3122,Event,ADDED,eval-conflicts-rho005-r6-097-6hvnl.18d465cd624188eb,reason=Started count=1 msg=Started container task
0.3125,Event,ADDED,eval-conflicts-rho005-r6-097.18d465cd45321509,reason=SuccessfulCreate count=1 msg=Created pod: eval-conflicts-rho005-r6-097-6hvnl
0.3127,Event,ADDED,eval-conflicts-rho005-r6-097.18d465d095580ebd,reason=Completed count=1 msg=Job completed
0.3128,Event,ADDED,eval-conflicts-rho005-r6-098-qlmqw.18d465cd8161b88d,reason=Scheduled count=None msg=Successfully assigned compute/eval-conflicts-rho005-r6-098-qlmqw to kind-worker2
0.313,Event,ADDED,eval-conflicts-rho005-r6-098-qlmqw.18d465cd9b27c593,"reason=Pulled count=1 msg=Container image ""busybox:musl"" already present on machine"
0.3132,Event,ADDED,eval-conflicts-rho005-r6-098-qlmqw.18d465cd9c674417,reason=Created count=1 msg=Created container: task
0.3134,Event,ADDED,eval-conflicts-rho005-r6-098-qlmqw.18d465cd9f4d08e5,reason=Started count=1 msg=Started container task
0.3136,Event,ADDED,eval-conflicts-rho005-r6-098.18d465cd80a26bca,reason=SuccessfulCreate count=1 msg=Created pod: eval-conflicts-rho005-r6-098-qlmqw
0.3138,Event,ADDED,eval-conflicts-rho005-r6-098.18d465d0d16e754d,reason=Completed count=1 msg=Job completed
0.3139,Event,ADDED,eval-conflicts-rho005-r6-099-4qh4z.18d465cdbd5e6004,reason=Scheduled count=None msg=Successfully assigned compute/eval-conflicts-rho005-r6-099-4qh4z to kind-worker3
0.3141,Event,ADDED,eval-conflicts-rho005-r6-099-4qh4z.18d465cdd7cfe1f7,"reason=Pulled count=1 msg=Container image ""busybox:musl"" already present on machine"
0.3143,Event,ADDED,eval-conflicts-rho005-r6-099-4qh4z.18d465cdd8fec55c,reason=Created count=1 msg=Created container: task
0.3144,Event,ADDED,eval-conflicts-rho005-r6-099-4qh4z.18d465cddb1b7b15,reason=Started count=1 msg=Started container task
0.3146,Event,ADDED,eval-conflicts-rho005-r6-099.18d465cdbc86f795,reason=SuccessfulCreate count=1 msg=Created pod: eval-conflicts-rho005-r6-099-4qh4z
0.3148,Event,ADDED,eval-conflicts-rho005-r6-099.18d465d110335ace,reason=Completed count=1 msg=Job completed
0.3149,Event,ADDED,eval-conflicts-rho005-r7-000-x48qj.18d465d60686e420,reason=Scheduled count=None msg=Successfully assigned compute/eval-conflicts-rho005-r7-000-x48qj to kind-worker2
0.3151,Event,ADDED,eval-conflicts-rho005-r7-000-x48qj.18d465d61f271e50,"reason=Pulled count=1 msg=Container image ""busybox:musl"" already present on machine"
0.3152,Event,ADDED,eval-conflicts-rho005-r7-000-x48qj.18d465d620513893,reason=Created count=1 msg=Created container: task
0.3154,Event,ADDED,eval-conflicts-rho005-r7-000-x48qj.18d465d6225087d4,reason=Started count=1 msg=Started container task
0.3156,Event,ADDED,eval-conflicts-rho005-r7-000.18d465d605b5bf5c,reason=SuccessfulCreate count=1 msg=Created pod: eval-conflicts-rho005-r7-000-x48qj
0.3157,Event,ADDED,eval-conflicts-rho005-r7-000.18d465d9379b537b,reason=Completed count=1 msg=Job completed
0.3159,Event,ADDED,eval-conflicts-rho005-r7-001-6pdqs.18d465d642c9dabb,reason=Scheduled count=None msg=Successfully assigned compute/eval-conflicts-rho005-r7-001-6pdqs to kind-worker5
0.3184,Event,ADDED,eval-conflicts-rho005-r7-001-6pdqs.18d465d65addb313,"reason=Pulled count=1 msg=Container image ""busybox:musl"" already present on machine"
0.3186,Event,ADDED,eval-conflicts-rho005-r7-001-6pdqs.18d465d65bf350e7,reason=Created count=1 msg=Created container: task
0.3187,Event,ADDED,eval-conflicts-rho005-r7-001-6pdqs.18d465d6618b7590,reason=Started count=1 msg=Started container task
0.3189,Event,ADDED,eval-conflicts-rho005-r7-001.18d465d641b979e5,reason=SuccessfulCreate count=1 msg=Created pod: eval-conflicts-rho005-r7-001-6pdqs
0.3191,Event,ADDED,eval-conflicts-rho005-r7-001.18d465d998075abc,reason=Completed count=1 msg=Job completed
0.3192,Event,ADDED,eval-conflicts-rho005-r7-002-64hpb.18d465d67d43d5ec,reason=Scheduled count=None msg=Successfully assigned compute/eval-conflicts-rho005-r7-002-64hpb to kind-worker
0.3194,Event,ADDED,eval-conflicts-rho005-r7-002-64hpb.18d465d698cf9651,"reason=Pulled count=1 msg=Container image ""busybox:musl"" already present on machine"
0.3196,Event,ADDED,eval-conflicts-rho005-r7-002-64hpb.18d465d69a079932,reason=Created count=1 msg=Created container: task
0.3199,Event,ADDED,eval-conflicts-rho005-r7-002-64hpb.18d465d69e3cc70a,reason=Started count=1 msg=Started container task
0.32,Event,ADDED,eval-conflicts-rho005-r7-002.18d465d67c87dc28,reason=SuccessfulCreate count=1 msg=Created pod: eval-conflicts-rho005-r7-002-64hpb
0.3202,Event,ADDED,eval-conflicts-rho005-r7-002.18d465d9cab80522,reason=Completed count=1 msg=Job completed
0.3203,Event,ADDED,eval-conflicts-rho005-r7-003-vfm42.18d465d6b92443e4,reason=Scheduled count=None msg=Successfully assigned compute/eval-conflicts-rho005-r7-003-vfm42 to kind-worker
0.3206,Event,ADDED,eval-conflicts-rho005-r7-003-vfm42.18d465d6d3319f25,"reason=Pulled count=1 msg=Container image ""busybox:musl"" already present on machine"
0.3207,Event,ADDED,eval-conflicts-rho005-r7-003-vfm42.18d465d6d451689e,reason=Created count=1 msg=Created container: task
0.3209,Event,ADDED,eval-conflicts-rho005-r7-003-vfm42.18d465d6d949ec5f,reason=Started count=1 msg=Started container task
0.3211,Event,ADDED,eval-conflicts-rho005-r7-003.18d465d6b823d935,reason=SuccessfulCreate count=1 msg=Created pod: eval-conflicts-rho005-r7-003-vfm42
0.3212,Event,ADDED,eval-conflicts-rho005-r7-003.18d465da0658a7dd,reason=Completed count=1 msg=Job completed
0.3214,Event,ADDED,eval-conflicts-rho005-r7-004-tpwvb.18d465d6f6283a60,reason=Scheduled count=None msg=Successfully assigned compute/eval-conflicts-rho005-r7-004-tpwvb to kind-worker2
0.3215,Event,ADDED,eval-conflicts-rho005-r7-004-tpwvb.18d465d71124fa15,"reason=Pulled count=1 msg=Container image ""busybox:musl"" already present on machine"
0.3217,Event,ADDED,eval-conflicts-rho005-r7-004-tpwvb.18d465d7123af410,reason=Created count=1 msg=Created container: task
0.3219,Event,ADDED,eval-conflicts-rho005-r7-004-tpwvb.18d465d7162b30d1,reason=Started count=1 msg=Started container task
0.322,Event,ADDED,eval-conflicts-rho005-r7-004.18d465d6f5325e98,reason=SuccessfulCreate count=1 msg=Created pod: eval-conflicts-rho005-r7-004-tpwvb
0.3222,Event,ADDED,eval-conflicts-rho005-r7-004.18d465da272b3b99,reason=Completed count=1 msg=Job completed
0.3223,Event,ADDED,eval-conflicts-rho005-r7-005-dvcl4.18d465d7302b1b66,reason=Scheduled count=None msg=Successfully assigned compute/eval-conflicts-rho005-r7-005-dvcl4 to kind-worker4
0.3225,Event,ADDED,eval-conflicts-rho005-r7-005-dvcl4.18d465d74a421892,"reason=Pulled count=1 msg=Container image ""busybox:musl"" already present on machine"
0.3227,Event,ADDED,eval-conflicts-rho005-r7-005-dvcl4.18d465d74b724dab,reason=Created count=1 msg=Created container: task
0.3228,Event,ADDED,eval-conflicts-rho005-r7-005-dvcl4.18d465d74f9d73ef,reason=Started count=1 msg=Started container task
0.323,Event,ADDED,eval-conflicts-rho005-r7-005.18d465d72f2ff188,reason=SuccessfulCreate count=1 msg=Created pod: eval-conflicts-rho005-r7-005-dvcl4
0.3232,Event,ADDED,eval-conflicts-rho005-r7-005.18d465da6faac456,reason=Completed count=1 msg=Job completed
0.3233,Event,ADDED,eval-conflicts-rho005-r7-006-c2bbc.18d465d76e1b2adc,reason=Scheduled count=None msg=Successfully assigned compute/eval-conflicts-rho005-r7-006-c2bbc to kind-worker
0.3235,Event,ADDED,eval-conflicts-rho005-r7-006-c2bbc.18d465d7873748f5,"reason=Pulled count=1 msg=Container image ""busybox:musl"" already present on machine"
0.3236,Event,ADDED,eval-conflicts-rho005-r7-006-c2bbc.18d465d7885019f9,reason=Created count=1 msg=Created container: task
0.3238,Event,ADDED,eval-conflicts-rho005-r7-006-c2bbc.18d465d78a4717f8,reason=Started count=1 msg=Started container task
0.324,Event,ADDED,eval-conflicts-rho005-r7-006.18d465d76cf3c741,reason=SuccessfulCreate count=1 msg=Created pod: eval-conflicts-rho005-r7-006-c2bbc
0.3241,Event,ADDED,eval-conflicts-rho005-r7-006.18d465daba69eba6,reason=Completed count=1 msg=Job completed
0.3243,Event,ADDED,eval-conflicts-rho005-r7-007-qbkjw.18d465d7a94d524a,reason=Scheduled count=None msg=Successfully assigned compute/eval-conflicts-rho005-r7-007-qbkjw to kind-worker
0.3244,Event,ADDED,eval-conflicts-rho005-r7-007-qbkjw.18d465d7c448a822,"reason=Pulled count=1 msg=Container image ""busybox:musl"" already present on machine"
0.3247,Event,ADDED,eval-conflicts-rho005-r7-007-qbkjw.18d465d7c55ee4c1,reason=Created count=1 msg=Created container: task
0.3248,Event,ADDED,eval-conflicts-rho005-r7-007-qbkjw.18d465d7c90f6013,reason=Started count=1 msg=Started container task
0.325,Event,ADDED,eval-conflicts-rho005-r7-007.18d465d7a81da6aa,reason=SuccessfulCreate count=1 msg=Created pod: eval-conflicts-rho005-r7-007-qbkjw
0.3251,Event,ADDED,eval-conflicts-rho005-r7-007.18d465daf60dceb4,reason=Completed count=1 msg=Job completed
0.3253,Event,ADDED,eval-conflicts-rho005-r7-008-dfzct.18d465d7e328be63,reason=Scheduled count=None msg=Successfully assigned compute/eval-conflicts-rho005-r7-008-dfzct to kind-worker2
0.3255,Event,ADDED,eval-conflicts-rho005-r7-008-dfzct.18d465d7ff4a9d13,"reason=Pulled count=1 msg=Container image ""busybox:musl"" already present on machine"
0.3257,Event,ADDED,eval-conflicts-rho005-r7-008-dfzct.18d465d80069f343,reason=Created count=1 msg=Created container: task
0.3259,Event,ADDED,eval-conflicts-rho005-r7-008-dfzct.18d465d804dae911,reason=Started count=1 msg=Started container task
0.326,Event,ADDED,eval-conflicts-rho005-r7-008.18d465d7e1f277f9,reason=SuccessfulCreate count=1 msg=Created pod: eval-conflicts-rho005-r7-008-dfzct
0.3262,Event,ADDED,eval-conflicts-rho005-r7-008.18d465db15fbd887,reason=Completed count=1 msg=Job completed
0.3263,Event,ADDED,eval-conflicts-rho005-r7-009-tbnf7.18d465d81f0046b7,reason=Scheduled count=None msg=Successfully assigned compute/eval-conflicts-rho005-r7-009-tbnf7 to kind-worker
0.3265,Event,ADDED,eval-conflicts-rho005-r7-009-tbnf7.18d465d8391100a7,"reason=Pulled count=1 msg=Container image ""busybox:musl"" already present on machine"
0.3267,Event,ADDED,eval-conflicts-rho005-r7-009-tbnf7.18d465d83a37ccb0,reason=Created count=1 msg=Created container: task
0.3268,Event,ADDED,eval-conflicts-rho005-r7-009-tbnf7.18d465d83e371609,reason=Started count=1 msg=Started container task
0.327,Event,ADDED,eval-conflicts-rho005-r7-009.18d465d81db43605,reason=SuccessfulCreate count=1 msg=Created pod: eval-conflicts-rho005-r7-009-tbnf7
0.3272,Event,ADDED,eval-conflicts-rho005-r7-009.18d465db6e160ef9,reason=Completed count=1 msg=Job completed
0.3273,Event,ADDED,eval-conflicts-rho005-r7-010-brbwk.18d465d859242848,reason=Scheduled count=None msg=Successfully assigned compute/eval-conflicts-rho005-r7-010-brbwk to kind-worker3
0.3275,Event,ADDED,eval-conflicts-rho005-r7-010-brbwk.18d465d8739138b7,"reason=Pulled count=1 msg=Container image ""busybox:musl"" already present on machine"
0.3276,Event,ADDED,eval-conflicts-rho005-r7-010-brbwk.18d465d874d05fe4,reason=Created count=1 msg=Created container: task
0.3278,Event,ADDED,eval-conflicts-rho005-r7-010-brbwk.18d465d878428e06,reason=Started count=1 msg=Started container task
0.328,Event,ADDED,eval-conflicts-rho005-r7-010.18d465d858d0db01,reason=SuccessfulCreate count=1 msg=Created pod: eval-conflicts-rho005-r7-010-brbwk
0.3281,Event,ADDED,eval-conflicts-rho005-r7-010.18d465db8fe33356,reason=Completed count=1 msg=Job completed
0.3283,Event,ADDED,eval-conflicts-rho005-r7-011-5phhp.18d465d895531ddc,"reason=FailedScheduling count=None msg=0/6 nodes are available: 6 node(s) had untolerated taint(s). no new claims to deallocate, preemption: 0/6 nodes are available: 6 Preemption is not helpful for scheduling."
0.3285,Event,ADDED,eval-conflicts-rho005-r7-011-5phhp.18d465daa465217a,reason=Scheduled count=None msg=Successfully assigned compute/eval-conflicts-rho005-r7-011-5phhp to kind-worker4
0.3287,Event,ADDED,eval-conflicts-rho005-r7-011-5phhp.18d465dac0526aca,"reason=Pulled count=1 msg=Container image ""busybox:musl"" already present on machine"
0.3289,Event,ADDED,eval-conflicts-rho005-r7-011-5phhp.18d465dac4772741,reason=Created count=1 msg=Created container: task
0.3291,Event,ADDED,eval-conflicts-rho005-r7-011-5phhp.18d465dac6f9ee2c,reason=Started count=1 msg=Started container task
0.3293,Event,ADDED,eval-conflicts-rho005-r7-011.18d465d8954536fb,reason=SuccessfulCreate count=1 msg=Created pod: eval-conflicts-rho005-r7-011-5phhp
0.3294,Event,ADDED,eval-conflicts-rho005-r7-011.18d465ddcf57d193,reason=Completed count=1 msg=Job completed
0.33,Event,ADDED,eval-conflicts-rho005-r7-012-l6k72.18d465d8d05dff80,"reason=FailedScheduling count=None msg=0/6 nodes are available: 6 node(s) had untolerated taint(s). no new claims to deallocate, preemption: 0/6 nodes are available: 6 Preemption is not helpful for scheduling."
0.3301,Event,ADDED,eval-conflicts-rho005-r7-012-l6k72.18d465daa4e2236d,reason=Scheduled count=None msg=Successfully assigned compute/eval-conflicts-rho005-r7-012-l6k72 to kind-worker4
0.3304,Event,ADDED,eval-conflicts-rho005-r7-012-l6k72.18d465dac0ffc0c3,"reason=Pulled count=1 msg=Container image ""busybox:musl"" already present on machine"
0.3306,Event,ADDED,eval-conflicts-rho005-r7-012-l6k72.18d465dac53a8690,reason=Created count=1 msg=Created container: task
0.3308,Event,ADDED,eval-conflicts-rho005-r7-012-l6k72.18d465dac7845b96,reason=Started count=1 msg=Started container task
0.331,Event,ADDED,eval-conflicts-rho005-r7-012.18d465d8d053cb08,reason=SuccessfulCreate count=1 msg=Created pod: eval-conflicts-rho005-r7-012-l6k72
0.3311,Event,ADDED,eval-conflicts-rho005-r7-012.18d465ddb7e06f40,reason=Completed count=1 msg=Job completed
0.3313,Event,ADDED,eval-conflicts-rho005-r7-013-7czrr.18d465d90bea4391,"reason=FailedScheduling count=None msg=0/6 nodes are available: 6 node(s) had untolerated taint(s). no new claims to deallocate, preemption: 0/6 nodes are available: 6 Preemption is not helpful for scheduling."
0.3315,Event,ADDED,eval-conflicts-rho005-r7-013-7czrr.18d465daa5498803,reason=Scheduled count=None msg=Successfully assigned compute/eval-conflicts-rho005-r7-013-7czrr to kind-worker4
0.3316,Event,ADDED,eval-conflicts-rho005-r7-013-7czrr.18d465dac122c908,"reason=Pulled count=1 msg=Container image ""busybox:musl"" already present on machine"
0.3318,Event,ADDED,eval-conflicts-rho005-r7-013-7czrr.18d465dac5d6c033,reason=Created count=1 msg=Created container: task
0.332,Event,ADDED,eval-conflicts-rho005-r7-013-7czrr.18d465dac82c33e8,reason=Started count=1 msg=Started container task
0.3321,Event,ADDED,eval-conflicts-rho005-r7-013.18d465d90bdb44e4,reason=SuccessfulCreate count=1 msg=Created pod: eval-conflicts-rho005-r7-013-7czrr
0.3323,Event,ADDED,eval-conflicts-rho005-r7-013.18d465ddf1469949,reason=Completed count=1 msg=Job completed
0.3326,Event,ADDED,eval-conflicts-rho005-r7-014-cb5px.18d465d947bc03d0,"reason=FailedScheduling count=None msg=0/6 nodes are available: 6 node(s) had untolerated taint(s). no new claims to deallocate, preemption: 0/6 nodes are available: 6 Preemption is not helpful for scheduling."
0.3327,Event,ADDED,eval-conflicts-rho005-r7-014-cb5px.18d465daa57cf133,reason=Scheduled count=None msg=Successfully assigned compute/eval-conflicts-rho005-r7-014-cb5px to kind-worker4
0.3329,Event,ADDED,eval-conflicts-rho005-r7-014-cb5px.18d465dac1c903fa,"reason=Pulled count=1 msg=Container image ""busybox:musl"" already present on machine"
0.3331,Event,ADDED,eval-conflicts-rho005-r7-014-cb5px.18d465dac6fabe14,reason=Created count=1 msg=Created container: task
0.3333,Event,ADDED,eval-conflicts-rho005-r7-014-cb5px.18d465dac91b237c,reason=Started count=1 msg=Started container task
0.3335,Event,ADDED,eval-conflicts-rho005-r7-014.18d465d947b0c7f8,reason=SuccessfulCreate count=1 msg=Created pod: eval-conflicts-rho005-r7-014-cb5px
0.3337,Event,ADDED,eval-conflicts-rho005-r7-014.18d465ddfcf68119,reason=Completed count=1 msg=Job completed
0.3338,Event,ADDED,eval-conflicts-rho005-r7-015-pgzc9.18d465d982fab140,"reason=FailedScheduling count=None msg=0/6 nodes are available: 6 node(s) had untolerated taint(s). no new claims to deallocate, preemption: 0/6 nodes are available: 6 Preemption is not helpful for scheduling."
0.3341,Event,ADDED,eval-conflicts-rho005-r7-015-pgzc9.18d465daa5352f0a,"reason=FailedScheduling count=None msg=0/6 nodes are available: 1 c_wall violated: 1 conflicting context pair(s) with node memory, 5 node(s) had untolerated taint(s). no new claims to deallocate, preemption: 0/6 nodes are available: 1 No preemption victims found for incoming pod, 5 Preemption is not helpful for scheduling."
0.3343,Event,ADDED,eval-conflicts-rho005-r7-015-pgzc9.18d465daaeb428c7,"reason=FailedScheduling count=None msg=0/6 nodes are available: 1 c_wall violated: 1 conflicting context pair(s) with node memory, 5 node(s) had untolerated taint(s). no new claims to deallocate, preemption: 0/6 nodes are available: 1 No preemption victims found for incoming pod, 5 Preemption is not helpful for scheduling."
0.3345,Event,ADDED,eval-conflicts-rho005-r7-015-pgzc9.18d465db1c68682c,reason=Scheduled count=None msg=Successfully assigned compute/eval-conflicts-rho005-r7-015-pgzc9 to kind-worker5
0.3347,Event,ADDED,eval-conflicts-rho005-r7-015-pgzc9.18d465db361a433c,"reason=Pulled count=1 msg=Container image ""busybox:musl"" already present on machine"
0.3349,Event,ADDED,eval-conflicts-rho005-r7-015-pgzc9.18d465db374d72a7,reason=Created count=1 msg=Created container: task
0.335,Event,ADDED,eval-conflicts-rho005-r7-015-pgzc9.18d465db394d4fcf,reason=Started count=1 msg=Started container task
0.3352,Event,ADDED,eval-conflicts-rho005-r7-015.18d465d982f113e8,reason=SuccessfulCreate count=1 msg=Created pod: eval-conflicts-rho005-r7-015-pgzc9
0.3354,Event,ADDED,eval-conflicts-rho005-r7-015.18d465de83e98102,reason=Completed count=1 msg=Job completed
0.3355,Event,ADDED,eval-conflicts-rho005-r7-016-4zvz9.18d465d9be89aa41,"reason=FailedScheduling count=None msg=0/6 nodes are available: 6 node(s) had untolerated taint(s). no new claims to deallocate, preemption: 0/6 nodes are available: 6 Preemption is not helpful for scheduling."
0.3357,Event,ADDED,eval-conflicts-rho005-r7-016-4zvz9.18d465daaa5e52cd,reason=Scheduled count=None msg=Successfully assigned compute/eval-conflicts-rho005-r7-016-4zvz9 to kind-worker4
0.3359,Event,ADDED,eval-conflicts-rho005-r7-016-4zvz9.18d465dac5dcfe21,"reason=Pulled count=1 msg=Container image ""busybox:musl"" already present on machine"
0.336,Event,ADDED,eval-conflicts-rho005-r7-016-4zvz9.18d465dac9a7b874,reason=Created count=1 msg=Created container: task
0.3362,Event,ADDED,eval-conflicts-rho005-r7-016-4zvz9.18d465dace08bef7,reason=Started count=1 msg=Started container task
0.3364,Event,ADDED,eval-conflicts-rho005-r7-016.18d465d9be805424,reason=SuccessfulCreate count=1 msg=Created pod: eval-conflicts-rho005-r7-016-4zvz9
0.3365,Event,ADDED,eval-conflicts-rho005-r7-016.18d465ddb9505590,reason=Completed count=1 msg=Job completed
0.3367,Event,ADDED,eval-conflicts-rho005-r7-017-t5d2w.18d465d9fa1f1914,"reason=FailedScheduling count=None msg=0/6 nodes are available: 6 node(s) had untolerated taint(s). no new claims to deallocate, preemption: 0/6 nodes are available: 6 Preemption is not helpful for scheduling."
0.3368,Event,ADDED,eval-conflicts-rho005-r7-017-t5d2w.18d465daae6d1295,reason=Scheduled count=None msg=Successfully assigned compute/eval-conflicts-rho005-r7-017-t5d2w to kind-worker4
0.337,Event,ADDED,eval-conflicts-rho005-r7-017-t5d2w.18d465dac3ea760d,"reason=Pulled count=1 msg=Container image ""busybox:musl"" already present on machine"
0.3372,Event,ADDED,eval-conflicts-rho005-r7-017-t5d2w.18d465dac8bcdf62,reason=Created count=1 msg=Created container: task
0.3373,Event,ADDED,eval-conflicts-rho005-r7-017-t5d2w.18d465dace0bec92,reason=Started count=1 msg=Started container task
0.3375,Event,ADDED,eval-conflicts-rho005-r7-017.18d465d9fa17249b,reason=SuccessfulCreate count=1 msg=Created pod: eval-conflicts-rho005-r7-017-t5d2w
0.3377,Event,ADDED,eval-conflicts-rho005-r7-017.18d465ddbd859b82,reason=Completed count=1 msg=Job completed
0.3378,Event,ADDED,eval-conflicts-rho005-r7-018-74djg.18d465da35b7ab1d,"reason=FailedScheduling count=None msg=0/6 nodes are available: 6 node(s) had untolerated taint(s). no new claims to deallocate, preemption: 0/6 nodes are available: 6 Preemption is not helpful for scheduling."
0.338,Event,ADDED,eval-conflicts-rho005-r7-018-74djg.18d465daae7486b7,reason=Scheduled count=None msg=Successfully assigned compute/eval-conflicts-rho005-r7-018-74djg to kind-worker4
0.3383,Event,ADDED,eval-conflicts-rho005-r7-018-74djg.18d465dac5075c8b,"reason=Pulled count=1 msg=Container image ""busybox:musl"" already present on machine"
0.3384,Event,ADDED,eval-conflicts-rho005-r7-018-74djg.18d465dac967cd3f,reason=Created count=1 msg=Created container: task
0.3386,Event,ADDED,eval-conflicts-rho005-r7-018-74djg.18d465dace0743f4,reason=Started count=1 msg=Started container task
0.3388,Event,ADDED,eval-conflicts-rho005-r7-018.18d465da35abaefe,reason=SuccessfulCreate count=1 msg=Created pod: eval-conflicts-rho005-r7-018-74djg
0.3389,Event,ADDED,eval-conflicts-rho005-r7-018.18d465ddbb0c069a,reason=Completed count=1 msg=Job completed
0.3391,Event,ADDED,eval-conflicts-rho005-r7-019-5vxlr.18d465da71653d8f,"reason=FailedScheduling count=None msg=0/6 nodes are available: 6 node(s) had untolerated taint(s). no new claims to deallocate, preemption: 0/6 nodes are available: 6 Preemption is not helpful for scheduling."
0.3392,Event,ADDED,eval-conflicts-rho005-r7-019-5vxlr.18d465daaec60a2e,reason=Scheduled count=None msg=Successfully assigned compute/eval-conflicts-rho005-r7-019-5vxlr to kind-worker4
0.3394,Event,ADDED,eval-conflicts-rho005-r7-019-5vxlr.18d465dace1055be,"reason=Pulled count=1 msg=Container image ""busybox:musl"" already present on machine"
0.3396,Event,ADDED,eval-conflicts-rho005-r7-019-5vxlr.18d465dacf3b73b8,reason=Created count=1 msg=Created container: task
0.3397,Event,ADDED,eval-conflicts-rho005-r7-019-5vxlr.18d465dad3ac2a69,reason=Started count=1 msg=Started container task
0.3399,Event,ADDED,eval-conflicts-rho005-r7-019.18d465da7159a94e,reason=SuccessfulCreate count=1 msg=Created pod: eval-conflicts-rho005-r7-019-5vxlr
0.3404,Event,ADDED,eval-conflicts-rho005-r7-019.18d465ddba60d6ad,reason=Completed count=1 msg=Job completed
0.3406,Event,ADDED,eval-conflicts-rho005-r7-020-4czrt.18d465daaf48127d,reason=Scheduled count=None msg=Successfully assigned compute/eval-conflicts-rho005-r7-020-4czrt to kind-worker4
0.3408,Event,ADDED,eval-conflicts-rho005-r7-020-4czrt.18d465dad3b33704,"reason=Pulled count=1 msg=Container image ""busybox:musl"" already present on machine"
0.341,Event,ADDED,eval-conflicts-rho005-r7-020-4czrt.18d465dad4e213dd,reason=Created count=1 msg=Created container: task
0.3413,Event,ADDED,eval-conflicts-rho005-r7-020-4czrt.18d465dad92bbeca,reason=Started count=1 msg=Started container task
0.3415,Event,ADDED,eval-conflicts-rho005-r7-020.18d465daacb9c9fc,reason=SuccessfulCreate count=1 msg=Created pod: eval-conflicts-rho005-r7-020-4czrt
0.3416,Event,ADDED,eval-conflicts-rho005-r7-020.18d465ddb9a790e2,reason=Completed count=1 msg=Job completed
0.3419,Event,ADDED,eval-conflicts-rho005-r7-021-rgpv6.18d465daec399ad9,reason=Scheduled count=None msg=Successfully assigned compute/eval-conflicts-rho005-r7-021-rgpv6 to kind-worker4
0.342,Event,ADDED,eval-conflicts-rho005-r7-021-rgpv6.18d465db068468a1,"reason=Pulled count=1 msg=Container image ""busybox:musl"" already present on machine"
0.3422,Event,ADDED,eval-conflicts-rho005-r7-021-rgpv6.18d465db07ba4c0b,reason=Created count=1 msg=Created container: task
0.3424,Event,ADDED,eval-conflicts-rho005-r7-021-rgpv6.18d465db09ba6ca9,reason=Started count=1 msg=Started container task
0.3425,Event,ADDED,eval-conflicts-rho005-r7-021.18d465dae8b6feee,reason=SuccessfulCreate count=1 msg=Created pod: eval-conflicts-rho005-r7-021-rgpv6
0.3427,Event,ADDED,eval-conflicts-rho005-r7-021.18d465ddf489967d,reason=Completed count=1 msg=Job completed
0.3429,Event,ADDED,eval-conflicts-rho005-r7-022-gxnvk.18d465db262731c7,reason=Scheduled count=None msg=Successfully assigned compute/eval-conflicts-rho005-r7-022-gxnvk to kind-worker5
0.3431,Event,ADDED,eval-conflicts-rho005-r7-022-gxnvk.18d465db3f000153,"reason=Pulled count=1 msg=Container image ""busybox:musl"" already present on machine"
0.3433,Event,ADDED,eval-conflicts-rho005-r7-022-gxnvk.18d465db40200c2e,reason=Created count=1 msg=Created container: task
0.3435,Event,ADDED,eval-conflicts-rho005-r7-022-gxnvk.18d465db424290dd,reason=Started count=1 msg=Started container task
0.3437,Event,ADDED,eval-conflicts-rho005-r7-022.18d465db24405a69,reason=SuccessfulCreate count=1 msg=Created pod: eval-conflicts-rho005-r7-022-gxnvk
0.3441,Event,ADDED,eval-conflicts-rho005-r7-022.18d465de851e62b9,reason=Completed count=1 msg=Job completed
0.3442,Event,ADDED,eval-conflicts-rho005-r7-023-4bq62.18d465db61068fd4,reason=Scheduled count=None msg=Successfully assigned compute/eval-conflicts-rho005-r7-023-4bq62 to kind-worker5
0.3444,Event,ADDED,eval-conflicts-rho005-r7-023-4bq62.18d465db7b3f5166,"reason=Pulled count=1 msg=Container image ""busybox:musl"" already present on machine"
0.3446,Event,ADDED,eval-conflicts-rho005-r7-023-4bq62.18d465db7cc0c21b,reason=Created count=1 msg=Created container: task
0.3448,Event,ADDED,eval-conflicts-rho005-r7-023-4bq62.18d465db82611df2,reason=Started count=1 msg=Started container task
0.345,Event,ADDED,eval-conflicts-rho005-r7-023.18d465db6008322d,reason=SuccessfulCreate count=1 msg=Created pod: eval-conflicts-rho005-r7-023-4bq62
0.3451,Event,ADDED,eval-conflicts-rho005-r7-023.18d465dec0493ad3,reason=Completed count=1 msg=Job completed
0.3456,Event,ADDED,eval-conflicts-rho005-r7-024-bzb9z.18d465db9c635e80,reason=Scheduled count=None msg=Successfully assigned compute/eval-conflicts-rho005-r7-024-bzb9z to kind-worker5
0.3459,Event,ADDED,eval-conflicts-rho005-r7-024-bzb9z.18d465dbb68686f0,"reason=Pulled count=1 msg=Container image ""busybox:musl"" already present on machine"
0.3462,Event,ADDED,eval-conflicts-rho005-r7-024-bzb9z.18d465dbb7cad914,reason=Created count=1 msg=Created container: task
0.3464,Event,ADDED,eval-conflicts-rho005-r7-024-bzb9z.18d465dbbba0642f,reason=Started count=1 msg=Started container task
0.3467,Event,ADDED,eval-conflicts-rho005-r7-024.18d465db9b6e0f42,reason=SuccessfulCreate count=1 msg=Created pod: eval-conflicts-rho005-r7-024-bzb9z
0.3469,Event,ADDED,eval-conflicts-rho005-r7-024.18d465defcb29002,reason=Completed count=1 msg=Job completed
0.347,Event,ADDED,eval-conflicts-rho005-r7-025-48cxv.18d465dbd8b7eba3,reason=Scheduled count=None msg=Successfully assigned compute/eval-conflicts-rho005-r7-025-48cxv to kind-worker5
0.3472,Event,ADDED,eval-conflicts-rho005-r7-025-48cxv.18d465dbf600df99,"reason=Pulled count=1 msg=Container image ""busybox:musl"" already present on machine"
0.3478,Event,ADDED,eval-conflicts-rho005-r7-025-48cxv.18d465dbf722f52a,reason=Created count=1 msg=Created container: task
0.3479,Event,ADDED,eval-conflicts-rho005-r7-025-48cxv.18d465dbfb48980f,reason=Started count=1 msg=Started container task
0.3481,Event,ADDED,eval-conflicts-rho005-r7-025.18d465dbd7c770af,reason=SuccessfulCreate count=1 msg=Created pod: eval-conflicts-rho005-r7-025-48cxv
0.3483,Event,ADDED,eval-conflicts-rho005-r7-025.18d465df37adec03,reason=Completed count=1 msg=Job completed
0.3484,Event,ADDED,eval-conflicts-rho005-r7-026-xk9xx.18d465dc133ab503,reason=Scheduled count=None msg=Successfully assigned compute/eval-conflicts-rho005-r7-026-xk9xx to kind-worker5
0.3486,Event,ADDED,eval-conflicts-rho005-r7-026-xk9xx.18d465dc2fa654f0,"reason=Pulled count=1 msg=Container image ""busybox:musl"" already present on machine"
0.3488,Event,ADDED,eval-conflicts-rho005-r7-026-xk9xx.18d465dc30e92a13,reason=Created count=1 msg=Created container: task
0.3489,Event,ADDED,eval-conflicts-rho005-r7-026-xk9xx.18d465dc358f955d,reason=Started count=1 msg=Started container task
0.3491,Event,ADDED,eval-conflicts-rho005-r7-026.18d465dc1276dd32,reason=SuccessfulCreate count=1 msg=Created pod: eval-conflicts-rho005-r7-026-xk9xx
0.3492,Event,ADDED,eval-conflicts-rho005-r7-026.18d465df7360df6b,reason=Completed count=1 msg=Job completed
0.3495,Event,ADDED,eval-conflicts-rho005-r7-027-7hscd.18d465dc50007bc6,reason=Scheduled count=None msg=Successfully assigned compute/eval-conflicts-rho005-r7-027-7hscd to kind-worker5
0.3497,Event,ADDED,eval-conflicts-rho005-r7-027-7hscd.18d465dc6da5d5cc,"reason=Pulled count=1 msg=Container image ""busybox:musl"" already present on machine"
0.3499,Event,ADDED,eval-conflicts-rho005-r7-027-7hscd.18d465dc6fdfd7f1,reason=Created count=1 msg=Created container: task
0.3501,Event,ADDED,eval-conflicts-rho005-r7-027-7hscd.18d465dc74e61c59,reason=Started count=1 msg=Started container task
0.3504,Event,ADDED,eval-conflicts-rho005-r7-027.18d465dc4ef7ad79,reason=SuccessfulCreate count=1 msg=Created pod: eval-conflicts-rho005-r7-027-7hscd
0.3506,Event,ADDED,eval-conflicts-rho005-r7-027.18d465dfaf1cbb61,reason=Completed count=1 msg=Job completed
0.3507,Event,ADDED,eval-conflicts-rho005-r7-028-9fkxw.18d465dc8d001444,reason=Scheduled count=None msg=Successfully assigned compute/eval-conflicts-rho005-r7-028-9fkxw to kind-worker5
0.3509,Event,ADDED,eval-conflicts-rho005-r7-028-9fkxw.18d465dca8fc68e4,"reason=Pulled count=1 msg=Container image ""busybox:musl"" already present on machine"
0.3511,Event,ADDED,eval-conflicts-rho005-r7-028-9fkxw.18d465dcab264f52,reason=Created count=1 msg=Created container: task
0.3513,Event,ADDED,eval-conflicts-rho005-r7-028-9fkxw.18d465dcb0310b2a,reason=Started count=1 msg=Started container task
0.3514,Event,ADDED,eval-conflicts-rho005-r7-028.18d465dc8b546d00,reason=SuccessfulCreate count=1 msg=Created pod: eval-conflicts-rho005-r7-028-9fkxw
0.3516,Event,ADDED,eval-conflicts-rho005-r7-028.18d465dfeebbc775,reason=Completed count=1 msg=Job completed
0.3518,Event,ADDED,eval-conflicts-rho005-r7-029-g6lqk.18d465dcc793e9ad,reason=Scheduled count=None msg=Successfully assigned compute/eval-conflicts-rho005-r7-029-g6lqk to kind-worker5
0.352,Event,ADDED,eval-conflicts-rho005-r7-029-g6lqk.18d465dce3d683b0,"reason=Pulled count=1 msg=Container image ""busybox:musl"" already present on machine"
0.3521,Event,ADDED,eval-conflicts-rho005-r7-029-g6lqk.18d465dce5da314a,reason=Created count=1 msg=Created container: task
0.3524,Event,ADDED,eval-conflicts-rho005-r7-029-g6lqk.18d465dceb40965f,reason=Started count=1 msg=Started container task
0.3526,Event,ADDED,eval-conflicts-rho005-r7-029.18d465dcc6496732,reason=SuccessfulCreate count=1 msg=Created pod: eval-conflicts-rho005-r7-029-g6lqk
0.3527,Event,ADDED,eval-conflicts-rho005-r7-029.18d465e0293324d3,reason=Completed count=1 msg=Job completed
0.3529,Event,ADDED,eval-conflicts-rho005-r7-030-qsp54.18d465dd029cb7f1,reason=Scheduled count=None msg=Successfully assigned compute/eval-conflicts-rho005-r7-030-qsp54 to kind-worker2
0.353,Event,ADDED,eval-conflicts-rho005-r7-030-qsp54.18d465dd28ff76c7,"reason=Pulled count=1 msg=Container image ""busybox:musl"" already present on machine"
0.3532,Event,ADDED,eval-conflicts-rho005-r7-030-qsp54.18d465dd2b431ce1,reason=Created count=1 msg=Created container: task
0.3534,Event,ADDED,eval-conflicts-rho005-r7-030-qsp54.18d465dd3343cfdb,reason=Started count=1 msg=Started container task
0.3536,Event,ADDED,eval-conflicts-rho005-r7-030.18d465dd0195fa9b,reason=SuccessfulCreate count=1 msg=Created pod: eval-conflicts-rho005-r7-030-qsp54
0.3537,Event,ADDED,eval-conflicts-rho005-r7-030.18d465e0786f0088,reason=Completed count=1 msg=Job completed
0.3539,Event,ADDED,eval-conflicts-rho005-r7-031-882b8.18d465dd3f12b3d4,reason=Scheduled count=None msg=Successfully assigned compute/eval-conflicts-rho005-r7-031-882b8 to kind-worker
0.354,Event,ADDED,eval-conflicts-rho005-r7-031-882b8.18d465dd5b5709e0,"reason=Pulled count=1 msg=Container image ""busybox:musl"" already present on machine"
0.3542,Event,ADDED,eval-conflicts-rho005-r7-031-882b8.18d465dd5d5a410d,reason=Created count=1 msg=Created container: task
0.3544,Event,ADDED,eval-conflicts-rho005-r7-031-882b8.18d465dd67e5a878,reason=Started count=1 msg=Started container task
0.3545,Event,ADDED,eval-conflicts-rho005-r7-031.18d465dd3da95b27,reason=SuccessfulCreate count=1 msg=Created pod: eval-conflicts-rho005-r7-031-882b8
0.3547,Event,ADDED,eval-conflicts-rho005-r7-031.18d465e09519ffe3,reason=Completed count=1 msg=Job completed
0.3548,Event,ADDED,eval-conflicts-rho005-r7-032-nlxvh.18d465dd7c63e6dd,reason=Scheduled count=None msg=Successfully assigned compute/eval-conflicts-rho005-r7-032-nlxvh to kind-worker
0.355,Event,ADDED,eval-conflicts-rho005-r7-032-nlxvh.18d465dd9fce8afc,"reason=Pulled count=1 msg=Container image ""busybox:musl"" already present on machine"
0.3552,Event,ADDED,eval-conflicts-rho005-r7-032-nlxvh.18d465dda1afbf1a,reason=Created count=1 msg=Created container: task
0.3553,Event,ADDED,eval-conflicts-rho005-r7-032-nlxvh.18d465dda6664692,reason=Started count=1 msg=Started container task
0.3555,Event,ADDED,eval-conflicts-rho005-r7-032.18d465dd7a9b6534,reason=SuccessfulCreate count=1 msg=Created pod: eval-conflicts-rho005-r7-032-nlxvh
0.3557,Event,ADDED,eval-conflicts-rho005-r7-032.18d465e0d0ce6dac,reason=Completed count=1 msg=Job completed
0.3558,Event,ADDED,eval-conflicts-rho005-r7-033-9ht85.18d465ddb69c25ca,reason=Scheduled count=None msg=Successfully assigned compute/eval-conflicts-rho005-r7-033-9ht85 to kind-worker2
0.3561,Event,ADDED,eval-conflicts-rho005-r7-033-9ht85.18d465ddd34644aa,"reason=Pulled count=1 msg=Container image ""busybox:musl"" already present on machine"
0.3563,Event,ADDED,eval-conflicts-rho005-r7-033-9ht85.18d465ddd56bb645,reason=Created count=1 msg=Created container: task
0.3566,Event,ADDED,eval-conflicts-rho005-r7-033-9ht85.18d465ddda7d21df,reason=Started count=1 msg=Started container task
0.3568,Event,ADDED,eval-conflicts-rho005-r7-033.18d465ddb4ca1775,reason=SuccessfulCreate count=1 msg=Created pod: eval-conflicts-rho005-r7-033-9ht85
0.3569,Event,ADDED,eval-conflicts-rho005-r7-033.18d465e0ef9a4712,reason=Completed count=1 msg=Job completed
0.3571,Event,ADDED,eval-conflicts-rho005-r7-034-89wrv.18d465ddf3235b36,reason=Scheduled count=None msg=Successfully assigned compute/eval-conflicts-rho005-r7-034-89wrv to kind-worker
0.3573,Event,ADDED,eval-conflicts-rho005-r7-034-89wrv.18d465de12b384a2,"reason=Pulled count=1 msg=Container image ""busybox:musl"" already present on machine"
0.3574,Event,ADDED,eval-conflicts-rho005-r7-034-89wrv.18d465de14bcf4cb,reason=Created count=1 msg=Created container: task
0.3576,Event,ADDED,eval-conflicts-rho005-r7-034-89wrv.18d465de1a031bb8,reason=Started count=1 msg=Started container task
0.3578,Event,ADDED,eval-conflicts-rho005-r7-034.18d465ddf1a25092,reason=SuccessfulCreate count=1 msg=Created pod: eval-conflicts-rho005-r7-034-89wrv
0.3579,Event,ADDED,eval-conflicts-rho005-r7-034.18d465e147e5942a,reason=Completed count=1 msg=Job completed
0.3581,Event,ADDED,eval-conflicts-rho005-r7-035-698cv.18d465de2df70212,reason=Scheduled count=None msg=Successfully assigned compute/eval-conflicts-rho005-r7-035-698cv to kind-worker
0.3582,Event,ADDED,eval-conflicts-rho005-r7-035-698cv.18d465de51b3b7de,"reason=Pulled count=1 msg=Container image ""busybox:musl"" already present on machine"
0.3584,Event,ADDED,eval-conflicts-rho005-r7-035-698cv.18d465de54630934,reason=Created count=1 msg=Created container: task
0.3586,Event,ADDED,eval-conflicts-rho005-r7-035-698cv.18d465de59f042f4,reason=Started count=1 msg=Started container task
0.3587,Event,ADDED,eval-conflicts-rho005-r7-035.18d465de2ca361d5,reason=SuccessfulCreate count=1 msg=Created pod: eval-conflicts-rho005-r7-035-698cv
0.3589,Event,ADDED,eval-conflicts-rho005-r7-035.18d465e1836143bb,reason=Completed count=1 msg=Job completed
0.359,Event,ADDED,eval-conflicts-rho005-r7-036-ctmrm.18d465de6997365e,reason=Scheduled count=None msg=Successfully assigned compute/eval-conflicts-rho005-r7-036-ctmrm to kind-worker2
0.3592,Event,ADDED,eval-conflicts-rho005-r7-036-ctmrm.18d465de8c0c1539,"reason=Pulled count=1 msg=Container image ""busybox:musl"" already present on machine"
0.3594,Event,ADDED,eval-conflicts-rho005-r7-036-ctmrm.18d465de8e0e8729,reason=Created count=1 msg=Created container: task
0.3596,Event,ADDED,eval-conflicts-rho005-r7-036-ctmrm.18d465de93e46f49,reason=Started count=1 msg=Started container task
0.3599,Event,ADDED,eval-conflicts-rho005-r7-036.18d465de6861f41f,reason=SuccessfulCreate count=1 msg=Created pod: eval-conflicts-rho005-r7-036-ctmrm
0.36,Event,ADDED,eval-conflicts-rho005-r7-036.18d465e1a25a0bba,reason=Completed count=1 msg=Job completed
0.3602,Event,ADDED,eval-conflicts-rho005-r7-037-grc79.18d465dea43ff604,reason=Scheduled count=None msg=Successfully assigned compute/eval-conflicts-rho005-r7-037-grc79 to kind-worker
0.3603,Event,ADDED,eval-conflicts-rho005-r7-037-grc79.18d465dec3148af3,"reason=Pulled count=1 msg=Container image ""busybox:musl"" already present on machine"
0.3606,Event,ADDED,eval-conflicts-rho005-r7-037-grc79.18d465dec525cf63,reason=Created count=1 msg=Created container: task
0.3607,Event,ADDED,eval-conflicts-rho005-r7-037-grc79.18d465decb1d0215,reason=Started count=1 msg=Started container task
0.3609,Event,ADDED,eval-conflicts-rho005-r7-037.18d465dea307a29f,reason=SuccessfulCreate count=1 msg=Created pod: eval-conflicts-rho005-r7-037-grc79
0.3611,Event,ADDED,eval-conflicts-rho005-r7-037.18d465e1fb59b30e,reason=Completed count=1 msg=Job completed
0.3612,Event,ADDED,eval-conflicts-rho005-r7-038-lxf28.18d465dee535ea75,reason=Scheduled count=None msg=Successfully assigned compute/eval-conflicts-rho005-r7-038-lxf28 to kind-worker2
0.3614,Event,ADDED,eval-conflicts-rho005-r7-038-lxf28.18d465df00c97407,"reason=Pulled count=1 msg=Container image ""busybox:musl"" already present on machine"
0.3615,Event,ADDED,eval-conflicts-rho005-r7-038-lxf28.18d465df041ada56,reason=Created count=1 msg=Created container: task
0.3617,Event,ADDED,eval-conflicts-rho005-r7-038-lxf28.18d465df0fd54afb,reason=Started count=1 msg=Started container task
0.3619,Event,ADDED,eval-conflicts-rho005-r7-038.18d465dededb0af9,reason=SuccessfulCreate count=1 msg=Created pod: eval-conflicts-rho005-r7-038-lxf28
0.362,Event,ADDED,eval-conflicts-rho005-r7-038.18d465e256a42578,reason=Completed count=1 msg=Job completed
0.3622,Event,ADDED,eval-conflicts-rho005-r7-039-xch8n.18d465df1d25abf0,reason=Scheduled count=None msg=Successfully assigned compute/eval-conflicts-rho005-r7-039-xch8n to kind-worker2
0.3625,Event,ADDED,eval-conflicts-rho005-r7-039-xch8n.18d465df453ab77d,"reason=Pulled count=1 msg=Container image ""busybox:musl"" already present on machine"
0.3627,Event,ADDED,eval-conflicts-rho005-r7-039-xch8n.18d465df48a7a6b0,reason=Created count=1 msg=Created container: task
0.3628,Event,ADDED,eval-conflicts-rho005-r7-039-xch8n.18d465df4fc03aff,reason=Started count=1 msg=Started container task
0.363,Event,ADDED,eval-conflicts-rho005-r7-039.18d465df1abde0a9,reason=SuccessfulCreate count=1 msg=Created pod: eval-conflicts-rho005-r7-039-xch8n
0.3632,Event,ADDED,eval-conflicts-rho005-r7-039.18d465e2928fd61f,reason=Completed count=1 msg=Job completed
0.3634,Event,ADDED,eval-conflicts-rho005-r7-040-g6gpr.18d465df583dea63,reason=Scheduled count=None msg=Successfully assigned compute/eval-conflicts-rho005-r7-040-g6gpr to kind-worker2
0.3635,Event,ADDED,eval-conflicts-rho005-r7-040-g6gpr.18d465df785676aa,"reason=Pulled count=1 msg=Container image ""busybox:musl"" already present on machine"
0.3637,Event,ADDED,eval-conflicts-rho005-r7-040-g6gpr.18d465df7a353384,reason=Created count=1 msg=Created container: task
0.3639,Event,ADDED,eval-conflicts-rho005-r7-040-g6gpr.18d465df8006c49a,reason=Started count=1 msg=Started container task
0.3641,Event,ADDED,eval-conflicts-rho005-r7-040.18d465df56b61427,reason=SuccessfulCreate count=1 msg=Created pod: eval-conflicts-rho005-r7-040-g6gpr
0.3642,Event,ADDED,eval-conflicts-rho005-r7-040.18d465e293ba1e21,reason=Completed count=1 msg=Job completed
0.3644,Event,ADDED,eval-conflicts-rho005-r7-041-j5h9w.18d465df926eaaac,reason=Scheduled count=None msg=Successfully assigned compute/eval-conflicts-rho005-r7-041-j5h9w to kind-worker4
0.3646,Event,ADDED,eval-conflicts-rho005-r7-041-j5h9w.18d465dfaec88090,"reason=Pulled count=1 msg=Container image ""busybox:musl"" already present on machine"
0.3647,Event,ADDED,eval-conflicts-rho005-r7-041-j5h9w.18d465dfb091d9e5,reason=Created count=1 msg=Created container: task
0.3649,Event,ADDED,eval-conflicts-rho005-r7-041-j5h9w.18d465dfb90d6f6b,reason=Started count=1 msg=Started container task
0.3651,Event,ADDED,eval-conflicts-rho005-r7-041.18d465df917258b2,reason=SuccessfulCreate count=1 msg=Created pod: eval-conflicts-rho005-r7-041-j5h9w
0.3652,Event,ADDED,eval-conflicts-rho005-r7-041.18d465e2dbc2e1ff,reason=Completed count=1 msg=Job completed
0.3655,Event,ADDED,eval-conflicts-rho005-r7-042-x8xzd.18d465dfcdcd3414,reason=Scheduled count=None msg=Successfully assigned compute/eval-conflicts-rho005-r7-042-x8xzd to kind-worker3
0.3656,Event,ADDED,eval-conflicts-rho005-r7-042-x8xzd.18d465dfea7db145,"reason=Pulled count=1 msg=Container image ""busybox:musl"" already present on machine"
0.3658,Event,ADDED,eval-conflicts-rho005-r7-042-x8xzd.18d465dfec731db3,reason=Created count=1 msg=Created container: task
0.366,Event,ADDED,eval-conflicts-rho005-r7-042-x8xzd.18d465dff47b46c5,reason=Started count=1 msg=Started container task
0.3661,Event,ADDED,eval-conflicts-rho005-r7-042.18d465dfcd0202a6,reason=SuccessfulCreate count=1 msg=Created pod: eval-conflicts-rho005-r7-042-x8xzd
0.3663,Event,ADDED,eval-conflicts-rho005-r7-042.18d465e30893b1eb,reason=Completed count=1 msg=Job completed
0.3664,Event,ADDED,eval-conflicts-rho005-r7-043-5hvmf.18d465e008d0239e,reason=Scheduled count=None msg=Successfully assigned compute/eval-conflicts-rho005-r7-043-5hvmf to kind-worker5
0.3666,Event,ADDED,eval-conflicts-rho005-r7-043-5hvmf.18d465e022de66bf,"reason=Pulled count=1 msg=Container image ""busybox:musl"" already present on machine"
0.3668,Event,ADDED,eval-conflicts-rho005-r7-043-5hvmf.18d465e024229591,reason=Created count=1 msg=Created container: task
0.3669,Event,ADDED,eval-conflicts-rho005-r7-043-5hvmf.18d465e02640d0eb,reason=Started count=1 msg=Started container task
0.3671,Event,ADDED,eval-conflicts-rho005-r7-043.18d465e007d6ad22,reason=SuccessfulCreate count=1 msg=Created pod: eval-conflicts-rho005-r7-043-5hvmf
0.3673,Event,ADDED,eval-conflicts-rho005-r7-043.18d465e36f3b1d58,reason=Completed count=1 msg=Job completed
0.3674,Event,ADDED,eval-conflicts-rho005-r7-044-hhfp7.18d465e0450ac7e7,reason=Scheduled count=None msg=Successfully assigned compute/eval-conflicts-rho005-r7-044-hhfp7 to kind-worker5
0.3676,Event,ADDED,eval-conflicts-rho005-r7-044-hhfp7.18d465e05f5aaa97,"reason=Pulled count=1 msg=Container image ""busybox:musl"" already present on machine"
0.3678,Event,ADDED,eval-conflicts-rho005-r7-044-hhfp7.18d465e060914715,reason=Created count=1 msg=Created container: task
0.3679,Event,ADDED,eval-conflicts-rho005-r7-044-hhfp7.18d465e064b3ca13,reason=Started count=1 msg=Started container task
0.3681,Event,ADDED,eval-conflicts-rho005-r7-044.18d465e043ed29a4,reason=SuccessfulCreate count=1 msg=Created pod: eval-conflicts-rho005-r7-044-hhfp7
0.3683,Event,ADDED,eval-conflicts-rho005-r7-044.18d465e3ac135932,reason=Completed count=1 msg=Job completed
0.3684,Event,ADDED,eval-conflicts-rho005-r7-045-vxbxp.18d465e0808dfb58,reason=Scheduled count=None msg=Successfully assigned compute/eval-conflicts-rho005-r7-045-vxbxp to kind-worker5
0.3686,Event,ADDED,eval-conflicts-rho005-r7-045-vxbxp.18d465e0999e9939,"reason=Pulled count=1 msg=Container image ""busybox:musl"" already present on machine"
0.3687,Event,ADDED,eval-conflicts-rho005-r7-045-vxbxp.18d465e09ab616a6,reason=Created count=1 msg=Created container: task
0.3689,Event,ADDED,eval-conflicts-rho005-r7-045-vxbxp.18d465e09ec4350b,reason=Started count=1 msg=Started container task
0.3691,Event,ADDED,eval-conflicts-rho005-r7-045.18d465e07f39e7a8,reason=SuccessfulCreate count=1 msg=Created pod: eval-conflicts-rho005-r7-045-vxbxp
0.3692,Event,ADDED,eval-conflicts-rho005-r7-045.18d465e3aac15450,reason=Completed count=1 msg=Job completed
0.3694,Event,ADDED,eval-conflicts-rho005-r7-046-s97zn.18d465e0bbfa9d20,reason=Scheduled count=None msg=Successfully assigned compute/eval-conflicts-rho005-r7-046-s97zn to kind-worker5
0.3695,Event,ADDED,eval-conflicts-rho005-r7-046-s97zn.18d465e0d5ff2621,"reason=Pulled count=1 msg=Container image ""busybox:musl"" already present on machine"
0.3697,Event,ADDED,eval-conflicts-rho005-r7-046-s97zn.18d465e0d719bb51,reason=Created count=1 msg=Created container: task
0.3699,Event,ADDED,eval-conflicts-rho005-r7-046-s97zn.18d465e0dae452bc,reason=Started count=1 msg=Started container task
0.37,Event,ADDED,eval-conflicts-rho005-r7-046.18d465e0bae6a35a,reason=SuccessfulCreate count=1 msg=Created pod: eval-conflicts-rho005-r7-046-s97zn
0.3702,Event,ADDED,eval-conflicts-rho005-r7-046.18d465e3e77e739b,reason=Completed count=1 msg=Job completed
0.3704,Event,ADDED,eval-conflicts-rho005-r7-047-5bhsk.18d465e0f77bc10d,reason=Scheduled count=None msg=Successfully assigned compute/eval-conflicts-rho005-r7-047-5bhsk to kind-worker4
0.3705,Event,ADDED,eval-conflicts-rho005-r7-047-5bhsk.18d465e110dacef1,"reason=Pulled count=1 msg=Container image ""busybox:musl"" already present on machine"
0.3707,Event,ADDED,eval-conflicts-rho005-r7-047-5bhsk.18d465e111eda7fd,reason=Created count=1 msg=Created container: task
0.3708,Event,ADDED,eval-conflicts-rho005-r7-047-5bhsk.18d465e115c794f2,reason=Started count=1 msg=Started container task
0.371,Event,ADDED,eval-conflicts-rho005-r7-047.18d465e0f641497f,reason=SuccessfulCreate count=1 msg=Created pod: eval-conflicts-rho005-r7-047-5bhsk
0.3712,Event,ADDED,eval-conflicts-rho005-r7-047.18d465e44250d4fa,reason=Completed count=1 msg=Job completed
0.3713,Event,ADDED,eval-conflicts-rho005-r7-048-nqbc8.18d465e133315d42,reason=Scheduled count=None msg=Successfully assigned compute/eval-conflicts-rho005-r7-048-nqbc8 to kind-worker5
0.3715,Event,ADDED,eval-conflicts-rho005-r7-048-nqbc8.18d465e14c783376,"reason=Pulled count=1 msg=Container image ""busybox:musl"" already present on machine"
0.3717,Event,ADDED,eval-conflicts-rho005-r7-048-nqbc8.18d465e14d8f8fc1,reason=Created count=1 msg=Created container: task
0.3719,Event,ADDED,eval-conflicts-rho005-r7-048-nqbc8.18d465e14fbbfdbd,reason=Started count=1 msg=Started container task
0.372,Event,ADDED,eval-conflicts-rho005-r7-048.18d465e131f222cc,reason=SuccessfulCreate count=1 msg=Created pod: eval-conflicts-rho005-r7-048-nqbc8
0.3723,Event,ADDED,eval-conflicts-rho005-r7-048.18d465e46104945c,reason=Completed count=1 msg=Job completed
0.3724,Event,ADDED,eval-conflicts-rho005-r7-049-crbwq.18d465e16f8ca560,reason=Scheduled count=None msg=Successfully assigned compute/eval-conflicts-rho005-r7-049-crbwq to kind-worker4
0.3726,Event,ADDED,eval-conflicts-rho005-r7-049-crbwq.18d465e188f75341,"reason=Pulled count=1 msg=Container image ""busybox:musl"" already present on machine"
0.3728,Event,ADDED,eval-conflicts-rho005-r7-049-crbwq.18d465e18a0ab209,reason=Created count=1 msg=Created container: task
0.373,Event,ADDED,eval-conflicts-rho005-r7-049-crbwq.18d465e18dcd8fdf,reason=Started count=1 msg=Started container task
0.3731,Event,ADDED,eval-conflicts-rho005-r7-049.18d465e16e0b6363,reason=SuccessfulCreate count=1 msg=Created pod: eval-conflicts-rho005-r7-049-crbwq
0.3733,Event,ADDED,eval-conflicts-rho005-r7-049.18d465e4baa271f6,reason=Completed count=1 msg=Job completed
0.3734,Event,ADDED,eval-conflicts-rho005-r7-050-hds9q.18d465e1aaee3d8e,reason=Scheduled count=None msg=Successfully assigned compute/eval-conflicts-rho005-r7-050-hds9q to kind-worker5
0.3736,Event,ADDED,eval-conflicts-rho005-r7-050-hds9q.18d465e1c71b9092,"reason=Pulled count=1 msg=Container image ""busybox:musl"" already present on machine"
0.3738,Event,ADDED,eval-conflicts-rho005-r7-050-hds9q.18d465e1c9378e1c,reason=Created count=1 msg=Created container: task
0.3739,Event,ADDED,eval-conflicts-rho005-r7-050-hds9q.18d465e1cd7ac2ce,reason=Started count=1 msg=Started container task
0.3741,Event,ADDED,eval-conflicts-rho005-r7-050.18d465e1a99dad12,reason=SuccessfulCreate count=1 msg=Created pod: eval-conflicts-rho005-r7-050-hds9q
0.3743,Event,ADDED,eval-conflicts-rho005-r7-050.18d465e51369373c,reason=Completed count=1 msg=Job completed
0.3744,Event,ADDED,eval-conflicts-rho005-r7-051-pnsjq.18d465e1e6b32e45,reason=Scheduled count=None msg=Successfully assigned compute/eval-conflicts-rho005-r7-051-pnsjq to kind-worker
0.3746,Event,ADDED,eval-conflicts-rho005-r7-051-pnsjq.18d465e2027faeac,"reason=Pulled count=1 msg=Container image ""busybox:musl"" already present on machine"
0.3747,Event,ADDED,eval-conflicts-rho005-r7-051-pnsjq.18d465e2045b412e,reason=Created count=1 msg=Created container: task
0.3749,Event,ADDED,eval-conflicts-rho005-r7-051-pnsjq.18d465e20a171201,reason=Started count=1 msg=Started container task
0.3751,Event,ADDED,eval-conflicts-rho005-r7-051.18d465e1e5686524,reason=SuccessfulCreate count=1 msg=Created pod: eval-conflicts-rho005-r7-051-pnsjq
0.3752,Event,ADDED,eval-conflicts-rho005-r7-051.18d465e542a093c6,reason=Completed count=1 msg=Job completed
0.3755,Event,ADDED,eval-conflicts-rho005-r7-052-7xfgm.18d465e2232f172b,reason=Scheduled count=None msg=Successfully assigned compute/eval-conflicts-rho005-r7-052-7xfgm to kind-worker
0.3758,Event,ADDED,eval-conflicts-rho005-r7-052-7xfgm.18d465e23f51c1c3,"reason=Pulled count=1 msg=Container image ""busybox:musl"" already present on machine"
0.376,Event,ADDED,eval-conflicts-rho005-r7-052-7xfgm.18d465e2410df3e8,reason=Created count=1 msg=Created container: task
0.3762,Event,ADDED,eval-conflicts-rho005-r7-052-7xfgm.18d465e2470a3de7,reason=Started count=1 msg=Started container task
0.3764,Event,ADDED,eval-conflicts-rho005-r7-052.18d465e221d0bab0,reason=SuccessfulCreate count=1 msg=Created pod: eval-conflicts-rho005-r7-052-7xfgm
0.3767,Event,ADDED,eval-conflicts-rho005-r7-052.18d465e57ec8f2f1,reason=Completed count=1 msg=Job completed
0.3769,Event,ADDED,eval-conflicts-rho005-r7-053-w5w4d.18d465e25d2bfa2a,reason=Scheduled count=None msg=Successfully assigned compute/eval-conflicts-rho005-r7-053-w5w4d to kind-worker
0.377,Event,ADDED,eval-conflicts-rho005-r7-053-w5w4d.18d465e279a7a05d,"reason=Pulled count=1 msg=Container image ""busybox:musl"" already present on machine"
0.3773,Event,ADDED,eval-conflicts-rho005-r7-053-w5w4d.18d465e27b3a55b0,reason=Created count=1 msg=Created container: task
0.3775,Event,ADDED,eval-conflicts-rho005-r7-053-w5w4d.18d465e2805b58d8,reason=Started count=1 msg=Started container task
0.3776,Event,ADDED,eval-conflicts-rho005-r7-053.18d465e25c847b54,reason=SuccessfulCreate count=1 msg=Created pod: eval-conflicts-rho005-r7-053-w5w4d
0.3778,Event,ADDED,eval-conflicts-rho005-r7-053.18d465e5bb211b3a,reason=Completed count=1 msg=Job completed
0.3781,Event,ADDED,eval-conflicts-rho005-r7-054-hwgrp.18d465e29ba0aebc,reason=Scheduled count=None msg=Successfully assigned compute/eval-conflicts-rho005-r7-054-hwgrp to kind-worker
0.3783,Event,ADDED,eval-conflicts-rho005-r7-054-hwgrp.18d465e2c97025e1,"reason=Pulled count=1 msg=Container image ""busybox:musl"" already present on machine"
0.3785,Event,ADDED,eval-conflicts-rho005-r7-054-hwgrp.18d465e2cb3d3a96,reason=Created count=1 msg=Created container: task
0.3788,Event,ADDED,eval-conflicts-rho005-r7-054-hwgrp.18d465e2cfe44522,reason=Started count=1 msg=Started container task
0.3789,Event,ADDED,eval-conflicts-rho005-r7-054.18d465e29abe8b29,reason=SuccessfulCreate count=1 msg=Created pod: eval-conflicts-rho005-r7-054-hwgrp
0.3791,Event,ADDED,eval-conflicts-rho005-r7-054.18d465e5f6d9a385,reason=Completed count=1 msg=Job completed
0.3792,Event,ADDED,eval-conflicts-rho005-r7-055-qbkfm.18d465e2d46a86df,reason=Scheduled count=None msg=Successfully assigned compute/eval-conflicts-rho005-r7-055-qbkfm to kind-worker
0.3795,Event,ADDED,eval-conflicts-rho005-r7-055-qbkfm.18d465e2f1225510,"reason=Pulled count=1 msg=Container image ""busybox:musl"" already present on machine"
0.3796,Event,ADDED,eval-conflicts-rho005-r7-055-qbkfm.18d465e2f31280ca,reason=Created count=1 msg=Created container: task
0.3798,Event,ADDED,eval-conflicts-rho005-r7-055-qbkfm.18d465e2fed2bd60,reason=Started count=1 msg=Started container task
0.38,Event,ADDED,eval-conflicts-rho005-r7-055.18d465e2d3ab1835,reason=SuccessfulCreate count=1 msg=Created pod: eval-conflicts-rho005-r7-055-qbkfm
0.3802,Event,ADDED,eval-conflicts-rho005-r7-055.18d465e632e0eab4,reason=Completed count=1 msg=Job completed
0.3803,Event,ADDED,eval-conflicts-rho005-r7-056-q4wwk.18d465e3104a7a3e,reason=Scheduled count=None msg=Successfully assigned compute/eval-conflicts-rho005-r7-056-q4wwk to kind-worker
0.3805,Event,ADDED,eval-conflicts-rho005-r7-056-q4wwk.18d465e32d9c5c5f,"reason=Pulled count=1 msg=Container image ""busybox:musl"" already present on machine"
0.3806,Event,ADDED,eval-conflicts-rho005-r7-056-q4wwk.18d465e32f55a625,reason=Created count=1 msg=Created container: task
0.3808,Event,ADDED,eval-conflicts-rho005-r7-056-q4wwk.18d465e33a9d5d6b,reason=Started count=1 msg=Started container task
0.381,Event,ADDED,eval-conflicts-rho005-r7-056.18d465e30f95f9cc,reason=SuccessfulCreate count=1 msg=Created pod: eval-conflicts-rho005-r7-056-q4wwk
0.3811,Event,ADDED,eval-conflicts-rho005-r7-056.18d465e66ea15b88,reason=Completed count=1 msg=Job completed
0.3813,Event,ADDED,eval-conflicts-rho005-r7-057-hhc5c.18d465e34bebf762,reason=Scheduled count=None msg=Successfully assigned compute/eval-conflicts-rho005-r7-057-hhc5c to kind-worker
0.3814,Event,ADDED,eval-conflicts-rho005-r7-057-hhc5c.18d465e3680104f2,"reason=Pulled count=1 msg=Container image ""busybox:musl"" already present on machine"
0.3816,Event,ADDED,eval-conflicts-rho005-r7-057-hhc5c.18d465e369b01ad3,reason=Created count=1 msg=Created container: task
0.3818,Event,ADDED,eval-conflicts-rho005-r7-057-hhc5c.18d465e37435b9ff,reason=Started count=1 msg=Started container task
0.3823,Event,ADDED,eval-conflicts-rho005-r7-057.18d465e34b270cac,reason=SuccessfulCreate count=1 msg=Created pod: eval-conflicts-rho005-r7-057-hhc5c
0.3825,Event,ADDED,eval-conflicts-rho005-r7-057.18d465e6aa6c4a98,reason=Completed count=1 msg=Job completed
0.3826,Event,ADDED,eval-conflicts-rho005-r7-058-kcr5v.18d465e38704295a,"reason=FailedScheduling count=None msg=0/6 nodes are available: 1 c_wall violated: 1 conflicting context pair(s) with node memory, 5 node(s) had untolerated taint(s). no new claims to deallocate, preemption: 0/6 nodes are available: 1 No preemption victims found for incoming pod, 5 Preemption is not helpful for scheduling."
0.3828,Event,ADDED,eval-conflicts-rho005-r7-058-kcr5v.18d465e387d39a97,"reason=FailedScheduling count=None msg=0/6 nodes are available: 1 c_wall violated: 1 conflicting context pair(s) with node memory, 5 node(s) had untolerated taint(s). no new claims to deallocate, preemption: 0/6 nodes are available: 1 No preemption victims found for incoming pod, 5 Preemption is not helpful for scheduling."
0.383,Event,ADDED,eval-conflicts-rho005-r7-058-kcr5v.18d465e449e4cb27,reason=Scheduled count=None msg=Successfully assigned compute/eval-conflicts-rho005-r7-058-kcr5v to kind-worker2
0.3831,Event,ADDED,eval-conflicts-rho005-r7-058-kcr5v.18d465e4688808ed,"reason=Pulled count=1 msg=Container image ""busybox:musl"" already present on machine"
0.3833,Event,ADDED,eval-conflicts-rho005-r7-058-kcr5v.18d465e46a706e04,reason=Created count=1 msg=Created container: task
0.3835,Event,ADDED,eval-conflicts-rho005-r7-058-kcr5v.18d465e470d1c19a,reason=Started count=1 msg=Started container task
0.3836,Event,ADDED,eval-conflicts-rho005-r7-058.18d465e386af86dc,reason=SuccessfulCreate count=1 msg=Created pod: eval-conflicts-rho005-r7-058-kcr5v
0.3838,Event,ADDED,eval-conflicts-rho005-r7-058.18d465e77dd8c277,reason=Completed count=1 msg=Job completed
0.384,Event,ADDED,eval-conflicts-rho005-r7-059-qqwjg.18d465e3c43c9b9a,reason=Scheduled count=None msg=Successfully assigned compute/eval-conflicts-rho005-r7-059-qqwjg to kind-worker
0.3841,Event,ADDED,eval-conflicts-rho005-r7-059-qqwjg.18d465e3e06652fc,"reason=Pulled count=1 msg=Container image ""busybox:musl"" already present on machine"
0.3843,Event,ADDED,eval-conflicts-rho005-r7-059-qqwjg.18d465e3e2b7366e,reason=Created count=1 msg=Created container: task
0.3844,Event,ADDED,eval-conflicts-rho005-r7-059-qqwjg.18d465e3ef2e3ee3,reason=Started count=1 msg=Started container task
0.3846,Event,ADDED,eval-conflicts-rho005-r7-059.18d465e3c37f68c6,reason=SuccessfulCreate count=1 msg=Created pod: eval-conflicts-rho005-r7-059-qqwjg
0.3848,Event,ADDED,eval-conflicts-rho005-r7-059.18d465e7223706cd,reason=Completed count=1 msg=Job completed
0.3849,Event,ADDED,eval-conflicts-rho005-r7-060-kljs4.18d465e3ff3ab0c9,reason=Scheduled count=None msg=Successfully assigned compute/eval-conflicts-rho005-r7-060-kljs4 to kind-worker
0.3851,Event,ADDED,eval-conflicts-rho005-r7-060-kljs4.18d465e41cc1883f,"reason=Pulled count=1 msg=Container image ""busybox:musl"" already present on machine"
0.3852,Event,ADDED,eval-conflicts-rho005-r7-060-kljs4.18d465e41ec6ed99,reason=Created count=1 msg=Created container: task
0.3854,Event,ADDED,eval-conflicts-rho005-r7-060-kljs4.18d465e429572171,reason=Started count=1 msg=Started container task
0.3856,Event,ADDED,eval-conflicts-rho005-r7-060.18d465e3fe3d42da,reason=SuccessfulCreate count=1 msg=Created pod: eval-conflicts-rho005-r7-060-kljs4
0.3857,Event,ADDED,eval-conflicts-rho005-r7-060.18d465e7607f83ad,reason=Completed count=1 msg=Job completed
0.3859,Event,ADDED,eval-conflicts-rho005-r7-061-mxntg.18d465e43a70e164,"reason=FailedScheduling count=None msg=0/6 nodes are available: 6 node(s) had untolerated taint(s). no new claims to deallocate, preemption: 0/6 nodes are available: 6 Preemption is not helpful for scheduling."
0.386,Event,ADDED,eval-conflicts-rho005-r7-061-mxntg.18d465e45dd411ed,reason=Scheduled count=None msg=Successfully assigned compute/eval-conflicts-rho005-r7-061-mxntg to kind-worker2
0.3862,Event,ADDED,eval-conflicts-rho005-r7-061-mxntg.18d465e469ad9efd,"reason=Pulled count=1 msg=Container image ""busybox:musl"" already present on machine"
0.3865,Event,ADDED,eval-conflicts-rho005-r7-061-mxntg.18d465e46b9eb085,reason=Created count=1 msg=Created container: task
0.3867,Event,ADDED,eval-conflicts-rho005-r7-061-mxntg.18d465e470d19111,reason=Started count=1 msg=Started container task
0.3868,Event,ADDED,eval-conflicts-rho005-r7-061.18d465e43a657650,reason=SuccessfulCreate count=1 msg=Created pod: eval-conflicts-rho005-r7-061-mxntg
0.387,Event,ADDED,eval-conflicts-rho005-r7-061.18d465e77da45e27,reason=Completed count=1 msg=Job completed
0.3871,Event,ADDED,eval-conflicts-rho005-r7-062-zmt24.18d465e478685c95,reason=Scheduled count=None msg=Successfully assigned compute/eval-conflicts-rho005-r7-062-zmt24 to kind-worker4
0.3873,Event,ADDED,eval-conflicts-rho005-r7-062-zmt24.18d465e494002ad1,"reason=Pulled count=1 msg=Container image ""busybox:musl"" already present on machine"
0.3875,Event,ADDED,eval-conflicts-rho005-r7-062-zmt24.18d465e495c72151,reason=Created count=1 msg=Created container: task
0.3876,Event,ADDED,eval-conflicts-rho005-r7-062-zmt24.18d465e49d0f585e,reason=Started count=1 msg=Started container task
0.3878,Event,ADDED,eval-conflicts-rho005-r7-062.18d465e476c84b6a,reason=SuccessfulCreate count=1 msg=Created pod: eval-conflicts-rho005-r7-062-zmt24
0.3879,Event,ADDED,eval-conflicts-rho005-r7-062.18d465e7c8d8fa80,reason=Completed count=1 msg=Job completed
0.3881,Event,ADDED,eval-conflicts-rho005-r7-063-7frzx.18d465e4b2a99698,reason=Scheduled count=None msg=Successfully assigned compute/eval-conflicts-rho005-r7-063-7frzx to kind-worker2
0.3883,Event,ADDED,eval-conflicts-rho005-r7-063-7frzx.18d465e4cf619a4f,"reason=Pulled count=1 msg=Container image ""busybox:musl"" already present on machine"
0.3884,Event,ADDED,eval-conflicts-rho005-r7-063-7frzx.18d465e4d148ee8d,reason=Created count=1 msg=Created container: task
0.3886,Event,ADDED,eval-conflicts-rho005-r7-063-7frzx.18d465e4db6ea822,reason=Started count=1 msg=Started container task
0.3888,Event,ADDED,eval-conflicts-rho005-r7-063.18d465e4b10cb1cd,reason=SuccessfulCreate count=1 msg=Created pod: eval-conflicts-rho005-r7-063-7frzx
0.3889,Event,ADDED,eval-conflicts-rho005-r7-063.18d465e7f52da4a7,reason=Completed count=1 msg=Job completed
0.3891,Event,ADDED,eval-conflicts-rho005-r7-064-gs79l.18d465e4edafa709,reason=Scheduled count=None msg=Successfully assigned compute/eval-conflicts-rho005-r7-064-gs79l to kind-worker5
0.3892,Event,ADDED,eval-conflicts-rho005-r7-064-gs79l.18d465e50e76220f,"reason=Pulled count=1 msg=Container image ""busybox:musl"" already present on machine"
0.3894,Event,ADDED,eval-conflicts-rho005-r7-064-gs79l.18d465e5102f0860,reason=Created count=1 msg=Created container: task
0.3896,Event,ADDED,eval-conflicts-rho005-r7-064-gs79l.18d465e519263f34,reason=Started count=1 msg=Started container task
0.3897,Event,ADDED,eval-conflicts-rho005-r7-064.18d465e4ec628293,reason=SuccessfulCreate count=1 msg=Created pod: eval-conflicts-rho005-r7-064-gs79l
0.3899,Event,ADDED,eval-conflicts-rho005-r7-064.18d465e85d30637b,reason=Completed count=1 msg=Job completed
0.39,Event,ADDED,eval-conflicts-rho005-r7-065-splfb.18d465e529df0aa8,reason=Scheduled count=None msg=Successfully assigned compute/eval-conflicts-rho005-r7-065-splfb to kind-worker5
0.3902,Event,ADDED,eval-conflicts-rho005-r7-065-splfb.18d465e54b37b82c,"reason=Pulled count=1 msg=Container image ""busybox:musl"" already present on machine"
0.3904,Event,ADDED,eval-conflicts-rho005-r7-065-splfb.18d465e54d233b23,reason=Created count=1 msg=Created container: task
0.3905,Event,ADDED,eval-conflicts-rho005-r7-065-splfb.18d465e5517162a8,reason=Started count=1 msg=Started container task
0.3907,Event,ADDED,eval-conflicts-rho005-r7-065.18d465e52832018a,reason=SuccessfulCreate count=1 msg=Created pod: eval-conflicts-rho005-r7-065-splfb
0.3908,Event,ADDED,eval-conflicts-rho005-r7-065.18d465e89be6313c,reason=Completed count=1 msg=Job completed
0.391,Event,ADDED,eval-conflicts-rho005-r7-066-mb4zj.18d465e565e1e5b9,reason=Scheduled count=None msg=Successfully assigned compute/eval-conflicts-rho005-r7-066-mb4zj to kind-worker5
0.3912,Event,ADDED,eval-conflicts-rho005-r7-066-mb4zj.18d465e584fb8cde,"reason=Pulled count=1 msg=Container image ""busybox:musl"" already present on machine"
0.3913,Event,ADDED,eval-conflicts-rho005-r7-066-mb4zj.18d465e586c2d5b4,reason=Created count=1 msg=Created container: task
0.3915,Event,ADDED,eval-conflicts-rho005-r7-066-mb4zj.18d465e58b9b4e20,reason=Started count=1 msg=Started container task
0.3918,Event,ADDED,eval-conflicts-rho005-r7-066.18d465e5642c9a75,reason=SuccessfulCreate count=1 msg=Created pod: eval-conflicts-rho005-r7-066-mb4zj
0.392,Event,ADDED,eval-conflicts-rho005-r7-066.18d465e8de20d454,reason=Completed count=1 msg=Job completed
0.3922,Event,ADDED,eval-conflicts-rho005-r7-067-c42d4.18d465e5a23b7d95,reason=Scheduled count=None msg=Successfully assigned compute/eval-conflicts-rho005-r7-067-c42d4 to kind-worker5
0.3924,Event,ADDED,eval-conflicts-rho005-r7-067-c42d4.18d465e5c273c1d8,"reason=Pulled count=1 msg=Container image ""busybox:musl"" already present on machine"
0.3927,Event,ADDED,eval-conflicts-rho005-r7-067-c42d4.18d465e5c456e261,reason=Created count=1 msg=Created container: task
0.3929,Event,ADDED,eval-conflicts-rho005-r7-067-c42d4.18d465e5c9b9feba,reason=Started count=1 msg=Started container task
0.3931,Event,ADDED,eval-conflicts-rho005-r7-067.18d465e5a06abeb6,reason=SuccessfulCreate count=1 msg=Created pod: eval-conflicts-rho005-r7-067-c42d4
0.3934,Event,ADDED,eval-conflicts-rho005-r7-067.18d465e91a2fca39,reason=Completed count=1 msg=Job completed
0.3935,Event,ADDED,eval-conflicts-rho005-r7-068-jj64g.18d465e5dd0fe6e4,reason=Scheduled count=None msg=Successfully assigned compute/eval-conflicts-rho005-r7-068-jj64g to kind-worker2
0.3937,Event,ADDED,eval-conflicts-rho005-r7-068-jj64g.18d465e5fe22a54d,"reason=Pulled count=1 msg=Container image ""busybox:musl"" already present on machine"
0.3939,Event,ADDED,eval-conflicts-rho005-r7-068-jj64g.18d465e5ffecb6f3,reason=Created count=1 msg=Created container: task
0.3942,Event,ADDED,eval-conflicts-rho005-r7-068-jj64g.18d465e60522bf97,reason=Started count=1 msg=Started container task
0.3944,Event,ADDED,eval-conflicts-rho005-r7-068.18d465e5db64cf1c,reason=SuccessfulCreate count=1 msg=Created pod: eval-conflicts-rho005-r7-068-jj64g
0.3946,Event,ADDED,eval-conflicts-rho005-r7-068.18d465e921a09b98,reason=Completed count=1 msg=Job completed
0.3948,Event,ADDED,eval-conflicts-rho005-r7-069-7bnl9.18d465e6184d09dc,reason=Scheduled count=None msg=Successfully assigned compute/eval-conflicts-rho005-r7-069-7bnl9 to kind-worker5
0.3951,Event,ADDED,eval-conflicts-rho005-r7-069-7bnl9.18d465e63590a0fe,"reason=Pulled count=1 msg=Container image ""busybox:musl"" already present on machine"
0.3952,Event,ADDED,eval-conflicts-rho005-r7-069-7bnl9.18d465e6374b11c2,reason=Created count=1 msg=Created container: task
0.3954,Event,ADDED,eval-conflicts-rho005-r7-069-7bnl9.18d465e63d41ee69,reason=Started count=1 msg=Started container task
0.3957,Event,ADDED,eval-conflicts-rho005-r7-069.18d465e616be2863,reason=SuccessfulCreate count=1 msg=Created pod: eval-conflicts-rho005-r7-069-7bnl9
0.3958,Event,ADDED,eval-conflicts-rho005-r7-069.18d465e955bb6d19,reason=Completed count=1 msg=Job completed
0.396,Event,ADDED,eval-conflicts-rho005-r7-070-mmtmw.18d465e6555552ad,reason=Scheduled count=None msg=Successfully assigned compute/eval-conflicts-rho005-r7-070-mmtmw to kind-worker4
0.3962,Event,ADDED,eval-conflicts-rho005-r7-070-mmtmw.18d465e67533ef95,"reason=Pulled count=1 msg=Container image ""busybox:musl"" already present on machine"
0.3963,Event,ADDED,eval-conflicts-rho005-r7-070-mmtmw.18d465e67772ecb6,reason=Created count=1 msg=Created container: task
0.3965,Event,ADDED,eval-conflicts-rho005-r7-070-mmtmw.18d465e682daae55,reason=Started count=1 msg=Started container task
0.3967,Event,ADDED,eval-conflicts-rho005-r7-070.18d465e653a4b923,reason=SuccessfulCreate count=1 msg=Created pod: eval-conflicts-rho005-r7-070-mmtmw
0.3968,Event,ADDED,eval-conflicts-rho005-r7-070.18d465e9a8c89b4f,reason=Completed count=1 msg=Job completed
0.397,Event,ADDED,eval-conflicts-rho005-r7-071-hk2x9.18d465e69f09f6d0,reason=Scheduled count=None msg=Successfully assigned compute/eval-conflicts-rho005-r7-071-hk2x9 to kind-worker4
0.3972,Event,ADDED,eval-conflicts-rho005-r7-071-hk2x9.18d465e6bc074a11,"reason=Pulled count=1 msg=Container image ""busybox:musl"" already present on machine"
0.3973,Event,ADDED,eval-conflicts-rho005-r7-071-hk2x9.18d465e6be23e309,reason=Created count=1 msg=Created container: task
0.3975,Event,ADDED,eval-conflicts-rho005-r7-071-hk2x9.18d465e6c3b81795,reason=Started count=1 msg=Started container task
0.3977,Event,ADDED,eval-conflicts-rho005-r7-071.18d465e68e511fa8,reason=SuccessfulCreate count=1 msg=Created pod: eval-conflicts-rho005-r7-071-hk2x9
0.3978,Event,ADDED,eval-conflicts-rho005-r7-071.18d465e9e89a5b90,reason=Completed count=1 msg=Job completed
0.398,Event,ADDED,eval-conflicts-rho005-r7-072-qpxl5.18d465e6cc78c792,reason=Scheduled count=None msg=Successfully assigned compute/eval-conflicts-rho005-r7-072-qpxl5 to kind-worker3
0.3981,Event,ADDED,eval-conflicts-rho005-r7-072-qpxl5.18d465e6ef4629ac,"reason=Pulled count=1 msg=Container image ""busybox:musl"" already present on machine"
0.3983,Event,ADDED,eval-conflicts-rho005-r7-072-qpxl5.18d465e6f0e7d5de,reason=Created count=1 msg=Created container: task
0.3985,Event,ADDED,eval-conflicts-rho005-r7-072-qpxl5.18d465e6faecf2d7,reason=Started count=1 msg=Started container task
0.3986,Event,ADDED,eval-conflicts-rho005-r7-072.18d465e6cb6fbac8,reason=SuccessfulCreate count=1 msg=Created pod: eval-conflicts-rho005-r7-072-qpxl5
0.3988,Event,ADDED,eval-conflicts-rho005-r7-072.18d465ea1124c12b,reason=Completed count=1 msg=Job completed
0.3989,Event,ADDED,eval-conflicts-rho005-r7-073-tqjzb.18d465e7069656de,reason=Scheduled count=None msg=Successfully assigned compute/eval-conflicts-rho005-r7-073-tqjzb to kind-worker5
0.3991,Event,ADDED,eval-conflicts-rho005-r7-073-tqjzb.18d465e7240fa3cc,"reason=Pulled count=1 msg=Container image ""busybox:musl"" already present on machine"
0.3993,Event,ADDED,eval-conflicts-rho005-r7-073-tqjzb.18d465e725e84ce6,reason=Created count=1 msg=Created container: task
0.3994,Event,ADDED,eval-conflicts-rho005-r7-073-tqjzb.18d465e72d9ca505,reason=Started count=1 msg=Started container task
0.3996,Event,ADDED,eval-conflicts-rho005-r7-073.18d465e705a91389,reason=SuccessfulCreate count=1 msg=Created pod: eval-conflicts-rho005-r7-073-tqjzb
0.3998,Event,ADDED,eval-conflicts-rho005-r7-073.18d465ea77e78996,reason=Completed count=1 msg=Job completed
0.3999,Event,ADDED,eval-conflicts-rho005-r7-074-zz9g8.18d465e740aa2df9,"reason=FailedScheduling count=None msg=0/6 nodes are available: 6 node(s) had untolerated taint(s). no new claims to deallocate, preemption: 0/6 nodes are available: 6 Preemption is not helpful for scheduling."
0.4001,Event,ADDED,eval-conflicts-rho005-r7-074-zz9g8.18d465e8fc316ed4,reason=Scheduled count=None msg=Successfully assigned compute/eval-conflicts-rho005-r7-074-zz9g8 to kind-worker
0.4002,Event,ADDED,eval-conflicts-rho005-r7-074-zz9g8.18d465e920618bc8,"reason=Pulled count=1 msg=Container image ""busybox:musl"" already present on machine"
0.4004,Event,ADDED,eval-conflicts-rho005-r7-074-zz9g8.18d465e92934937e,reason=Created count=1 msg=Created container: task
0.4006,Event,ADDED,eval-conflicts-rho005-r7-074-zz9g8.18d465e930bdbdf3,reason=Started count=1 msg=Started container task
0.4007,Event,ADDED,eval-conflicts-rho005-r7-074.18d465e74096c7cf,reason=SuccessfulCreate count=1 msg=Created pod: eval-conflicts-rho005-r7-074-zz9g8
0.4009,Event,ADDED,eval-conflicts-rho005-r7-074.18d465ec0cb2fb7d,reason=Completed count=1 msg=Job completed
0.4011,Event,ADDED,eval-conflicts-rho005-r7-075-26n2p.18d465e77ee378c5,"reason=FailedScheduling count=None msg=0/6 nodes are available: 6 node(s) had untolerated taint(s). no new claims to deallocate, preemption: 0/6 nodes are available: 6 Preemption is not helpful for scheduling."
0.4012,Event,ADDED,eval-conflicts-rho005-r7-075-26n2p.18d465e8fcf8b14c,reason=Scheduled count=None msg=Successfully assigned compute/eval-conflicts-rho005-r7-075-26n2p to kind-worker
0.4014,Event,ADDED,eval-conflicts-rho005-r7-075-26n2p.18d465e92050d62e,"reason=Pulled count=1 msg=Container image ""busybox:musl"" already present on machine"
0.4015,Event,ADDED,eval-conflicts-rho005-r7-075-26n2p.18d465e92804daea,reason=Created count=1 msg=Created container: task
0.4017,Event,ADDED,eval-conflicts-rho005-r7-075-26n2p.18d465e930bdad34,reason=Started count=1 msg=Started container task
0.4019,Event,ADDED,eval-conflicts-rho005-r7-075.18d465e77ed41e61,reason=SuccessfulCreate count=1 msg=Created pod: eval-conflicts-rho005-r7-075-26n2p
0.4021,Event,ADDED,eval-conflicts-rho005-r7-075.18d465ec831928c2,reason=Completed count=1 msg=Job completed
0.4025,Event,ADDED,eval-conflicts-rho005-r7-076-bbvkb.18d465e7b7d17d85,"reason=FailedScheduling count=None msg=0/6 nodes are available: 6 node(s) had untolerated taint(s). no new claims to deallocate, preemption: 0/6 nodes are available: 6 Preemption is not helpful for scheduling."
0.4027,Event,ADDED,eval-conflicts-rho005-r7-076-bbvkb.18d465e8fcfb4e14,reason=Scheduled count=None msg=Successfully assigned compute/eval-conflicts-rho005-r7-076-bbvkb to kind-worker
0.4029,Event,ADDED,eval-conflicts-rho005-r7-076-bbvkb.18d465e91ffc866f,"reason=Pulled count=1 msg=Container image ""busybox:musl"" already present on machine"
0.403,Event,ADDED,eval-conflicts-rho005-r7-076-bbvkb.18d465e9289b86bf,reason=Created count=1 msg=Created container: task
0.4032,Event,ADDED,eval-conflicts-rho005-r7-076-bbvkb.18d465e930beb675,reason=Started count=1 msg=Started container task
0.4034,Event,ADDED,eval-conflicts-rho005-r7-076.18d465e7b7c72f51,reason=SuccessfulCreate count=1 msg=Created pod: eval-conflicts-rho005-r7-076-bbvkb
0.4035,Event,ADDED,eval-conflicts-rho005-r7-076.18d465ec4638a791,reason=Completed count=1 msg=Job completed
0.4037,Event,ADDED,eval-conflicts-rho005-r7-077-x6cm2.18d465e7f36a0710,"reason=FailedScheduling count=None msg=0/6 nodes are available: 6 node(s) had untolerated taint(s). no new claims to deallocate, preemption: 0/6 nodes are available: 6 Preemption is not helpful for scheduling."
0.4038,Event,ADDED,eval-conflicts-rho005-r7-077-x6cm2.18d465e8fd1f95df,reason=Scheduled count=None msg=Successfully assigned compute/eval-conflicts-rho005-r7-077-x6cm2 to kind-worker
0.404,Event,ADDED,eval-conflicts-rho005-r7-077-x6cm2.18d465e91ec93575,"reason=Pulled count=1 msg=Container image ""busybox:musl"" already present on machine"
0.4041,Event,ADDED,eval-conflicts-rho005-r7-077-x6cm2.18d465e926df27e6,reason=Created count=1 msg=Created container: task
0.4043,Event,ADDED,eval-conflicts-rho005-r7-077-x6cm2.18d465e930b927ab,reason=Started count=1 msg=Started container task
0.4045,Event,ADDED,eval-conflicts-rho005-r7-077.18d465e7f361fb92,reason=SuccessfulCreate count=1 msg=Created pod: eval-conflicts-rho005-r7-077-x6cm2
0.4046,Event,ADDED,eval-conflicts-rho005-r7-077.18d465ec0c9662e2,reason=Completed count=1 msg=Job completed
0.4048,Event,ADDED,eval-conflicts-rho005-r7-078-wrbdj.18d465e82efe1b69,"reason=FailedScheduling count=None msg=0/6 nodes are available: 6 node(s) had untolerated taint(s). no new claims to deallocate, preemption: 0/6 nodes are available: 6 Preemption is not helpful for scheduling."
0.4049,Event,ADDED,eval-conflicts-rho005-r7-078-wrbdj.18d465e8fd6beda9,reason=Scheduled count=None msg=Successfully assigned compute/eval-conflicts-rho005-r7-078-wrbdj to kind-worker
0.4051,Event,ADDED,eval-conflicts-rho005-r7-078-wrbdj.18d465e91ed4215d,"reason=Pulled count=1 msg=Container image ""busybox:musl"" already present on machine"
0.4052,Event,ADDED,eval-conflicts-rho005-r7-078-wrbdj.18d465e926900503,reason=Created count=1 msg=Created container: task
0.4054,Event,ADDED,eval-conflicts-rho005-r7-078-wrbdj.18d465e930bf44df,reason=Started count=1 msg=Started container task
0.4056,Event,ADDED,eval-conflicts-rho005-r7-078.18d465e82ef3f62c,reason=SuccessfulCreate count=1 msg=Created pod: eval-conflicts-rho005-r7-078-wrbdj
0.4057,Event,ADDED,eval-conflicts-rho005-r7-078.18d465ec461a74f5,reason=Completed count=1 msg=Job completed
0.4059,Event,ADDED,eval-conflicts-rho005-r7-079-gbntl.18d465e86a7de01c,"reason=FailedScheduling count=None msg=0/6 nodes are available: 6 node(s) had untolerated taint(s). no new claims to deallocate, preemption: 0/6 nodes are available: 6 Preemption is not helpful for scheduling."
0.4061,Event,ADDED,eval-conflicts-rho005-r7-079-gbntl.18d465e8fdbd5148,reason=Scheduled count=None msg=Successfully assigned compute/eval-conflicts-rho005-r7-079-gbntl to kind-worker
0.4062,Event,ADDED,eval-conflicts-rho005-r7-079-gbntl.18d465e91f6dae4b,"reason=Pulled count=1 msg=Container image ""busybox:musl"" already present on machine"
0.4064,Event,ADDED,eval-conflicts-rho005-r7-079-gbntl.18d465e927b32a8a,reason=Created count=1 msg=Created container: task
0.4066,Event,ADDED,eval-conflicts-rho005-r7-079-gbntl.18d465e930be4cab,reason=Started count=1 msg=Started container task
0.4067,Event,ADDED,eval-conflicts-rho005-r7-079.18d465e86a725d25,reason=SuccessfulCreate count=1 msg=Created pod: eval-conflicts-rho005-r7-079-gbntl
0.4069,Event,ADDED,eval-conflicts-rho005-r7-079.18d465ec473bbc02,reason=Completed count=1 msg=Job completed
0.407,Event,ADDED,eval-conflicts-rho005-r7-080-5qfdh.18d465e8a8f45b8e,"reason=FailedScheduling count=None msg=0/6 nodes are available: 6 node(s) had untolerated taint(s). no new claims to deallocate, preemption: 0/6 nodes are available: 6 Preemption is not helpful for scheduling."
0.4072,Event,ADDED,eval-conflicts-rho005-r7-080-5qfdh.18d465e8fdfce8f9,reason=Scheduled count=None msg=Successfully assigned compute/eval-conflicts-rho005-r7-080-5qfdh to kind-worker
0.4074,Event,ADDED,eval-conflicts-rho005-r7-080-5qfdh.18d465e91e87f901,"reason=Pulled count=1 msg=Container image ""busybox:musl"" already present on machine"
0.4075,Event,ADDED,eval-conflicts-rho005-r7-080-5qfdh.18d465e9258b3eba,reason=Created count=1 msg=Created container: task
0.4077,Event,ADDED,eval-conflicts-rho005-r7-080-5qfdh.18d465e930484b02,reason=Started count=1 msg=Started container task
0.4079,Event,ADDED,eval-conflicts-rho005-r7-080.18d465e8a8eb02fe,reason=SuccessfulCreate count=1 msg=Created pod: eval-conflicts-rho005-r7-080-5qfdh
0.4081,Event,ADDED,eval-conflicts-rho005-r7-080.18d465ec46d61a89,reason=Completed count=1 msg=Job completed
0.4082,Event,ADDED,eval-conflicts-rho005-r7-081-tqpgk.18d465e8e0a2eb1f,"reason=FailedScheduling count=None msg=0/6 nodes are available: 6 node(s) had untolerated taint(s). no new claims to deallocate, preemption: 0/6 nodes are available: 6 Preemption is not helpful for scheduling."
0.4084,Event,ADDED,eval-conflicts-rho005-r7-081-tqpgk.18d465e902887cf2,reason=Scheduled count=None msg=Successfully assigned compute/eval-conflicts-rho005-r7-081-tqpgk to kind-worker
0.4086,Event,ADDED,eval-conflicts-rho005-r7-081-tqpgk.18d465e9210eb738,"reason=Pulled count=1 msg=Container image ""busybox:musl"" already present on machine"
0.4087,Event,ADDED,eval-conflicts-rho005-r7-081-tqpgk.18d465e92934939d,reason=Created count=1 msg=Created container: task
0.4089,Event,ADDED,eval-conflicts-rho005-r7-081-tqpgk.18d465e930baf134,reason=Started count=1 msg=Started container task
0.409,Event,ADDED,eval-conflicts-rho005-r7-081.18d465e8e0973818,reason=SuccessfulCreate count=1 msg=Created pod: eval-conflicts-rho005-r7-081-tqpgk
0.4092,Event,ADDED,eval-conflicts-rho005-r7-081.18d465ec46d5a089,reason=Completed count=1 msg=Job completed
0.4094,Event,ADDED,eval-conflicts-rho005-r7-082-qb5zh.18d465e91f2d0eeb,reason=Scheduled count=None msg=Successfully assigned compute/eval-conflicts-rho005-r7-082-qb5zh to kind-worker2
0.4096,Event,ADDED,eval-conflicts-rho005-r7-082-qb5zh.18d465e9388ff911,"reason=Pulled count=1 msg=Container image ""busybox:musl"" already present on machine"
0.4098,Event,ADDED,eval-conflicts-rho005-r7-082-qb5zh.18d465e939b00279,reason=Created count=1 msg=Created container: task
0.4099,Event,ADDED,eval-conflicts-rho005-r7-082-qb5zh.18d465e93e633862,reason=Started count=1 msg=Started container task
0.4101,Event,ADDED,eval-conflicts-rho005-r7-082.18d465e91d8eeb53,reason=SuccessfulCreate count=1 msg=Created pod: eval-conflicts-rho005-r7-082-qb5zh
0.4103,Event,ADDED,eval-conflicts-rho005-r7-082.18d465ec9ccff40e,reason=Completed count=1 msg=Job completed
0.4104,Event,ADDED,eval-conflicts-rho005-r7-083-6rzbl.18d465e959040769,reason=Scheduled count=None msg=Successfully assigned compute/eval-conflicts-rho005-r7-083-6rzbl to kind-worker2
0.4106,Event,ADDED,eval-conflicts-rho005-r7-083-6rzbl.18d465e97298cae8,"reason=Pulled count=1 msg=Container image ""busybox:musl"" already present on machine"
0.4108,Event,ADDED,eval-conflicts-rho005-r7-083-6rzbl.18d465e973bc03f8,reason=Created count=1 msg=Created container: task
0.4109,Event,ADDED,eval-conflicts-rho005-r7-083-6rzbl.18d465e9787645a2,reason=Started count=1 msg=Started container task
0.4111,Event,ADDED,eval-conflicts-rho005-r7-083.18d465e957e31cd9,reason=SuccessfulCreate count=1 msg=Created pod: eval-conflicts-rho005-r7-083-6rzbl
0.4112,Event,ADDED,eval-conflicts-rho005-r7-083.18d465eca300f5ad,reason=Completed count=1 msg=Job completed
0.4114,Event,ADDED,eval-conflicts-rho005-r7-084-7p2dq.18d465e9942113a1,reason=Scheduled count=None msg=Successfully assigned compute/eval-conflicts-rho005-r7-084-7p2dq to kind-worker2
0.4116,Event,ADDED,eval-conflicts-rho005-r7-084-7p2dq.18d465e9b18032c1,"reason=Pulled count=1 msg=Container image ""busybox:musl"" already present on machine"
0.4117,Event,ADDED,eval-conflicts-rho005-r7-084-7p2dq.18d465e9b2984616,reason=Created count=1 msg=Created container: task
0.412,Event,ADDED,eval-conflicts-rho005-r7-084-7p2dq.18d465e9bd00aab1,reason=Started count=1 msg=Started container task
0.4121,Event,ADDED,eval-conflicts-rho005-r7-084.18d465e993521215,reason=SuccessfulCreate count=1 msg=Created pod: eval-conflicts-rho005-r7-084-7p2dq
0.4123,Event,ADDED,eval-conflicts-rho005-r7-084.18d465ecdc88727a,reason=Completed count=1 msg=Job completed
0.4124,Event,ADDED,eval-conflicts-rho005-r7-085-blfs7.18d465e9d0a6346c,reason=Scheduled count=None msg=Successfully assigned compute/eval-conflicts-rho005-r7-085-blfs7 to kind-worker
0.4128,Event,ADDED,eval-conflicts-rho005-r7-085-blfs7.18d465e9f3feb495,"reason=Pulled count=1 msg=Container image ""busybox:musl"" already present on machine"
0.413,Event,ADDED,eval-conflicts-rho005-r7-085-blfs7.18d465e9f528be49,reason=Created count=1 msg=Created container: task
0.4132,Event,ADDED,eval-conflicts-rho005-r7-085-blfs7.18d465e9fea729ef,reason=Started count=1 msg=Started container task
0.4134,Event,ADDED,eval-conflicts-rho005-r7-085.18d465e9cfedbc19,reason=SuccessfulCreate count=1 msg=Created pod: eval-conflicts-rho005-r7-085-blfs7
0.4137,Event,ADDED,eval-conflicts-rho005-r7-085.18d465ed36936261,reason=Completed count=1 msg=Job completed
0.4139,Event,ADDED,eval-conflicts-rho005-r7-086-8hbvf.18d465ea13564a8c,reason=Scheduled count=None msg=Successfully assigned compute/eval-conflicts-rho005-r7-086-8hbvf to kind-worker2
0.4141,Event,ADDED,eval-conflicts-rho005-r7-086-8hbvf.18d465ea2e09ae4c,"reason=Pulled count=1 msg=Container image ""busybox:musl"" already present on machine"
0.4144,Event,ADDED,eval-conflicts-rho005-r7-086-8hbvf.18d465ea2f207749,reason=Created count=1 msg=Created container: task
0.4146,Event,ADDED,eval-conflicts-rho005-r7-086-8hbvf.18d465ea3125052e,reason=Started count=1 msg=Started container task
0.4148,Event,ADDED,eval-conflicts-rho005-r7-086.18d465ea124c5bf1,reason=SuccessfulCreate count=1 msg=Created pod: eval-conflicts-rho005-r7-086-8hbvf
0.4149,Event,ADDED,eval-conflicts-rho005-r7-086.18d465ed50f184c4,reason=Completed count=1 msg=Job completed
0.4151,Event,ADDED,eval-conflicts-rho005-r7-087-55ks7.18d465ea47d94036,reason=Scheduled count=None msg=Successfully assigned compute/eval-conflicts-rho005-r7-087-55ks7 to kind-worker2
0.4153,Event,ADDED,eval-conflicts-rho005-r7-087-55ks7.18d465ea619d5a1b,"reason=Pulled count=1 msg=Container image ""busybox:musl"" already present on machine"
0.4155,Event,ADDED,eval-conflicts-rho005-r7-087-55ks7.18d465ea62db1d5d,reason=Created count=1 msg=Created container: task
0.4157,Event,ADDED,eval-conflicts-rho005-r7-087-55ks7.18d465ea67eaf0c7,reason=Started count=1 msg=Started container task
0.4158,Event,ADDED,eval-conflicts-rho005-r7-087.18d465ea4707b6e1,reason=SuccessfulCreate count=1 msg=Created pod: eval-conflicts-rho005-r7-087-55ks7
0.4162,Event,ADDED,eval-conflicts-rho005-r7-087.18d465ed8ce799ef,reason=Completed count=1 msg=Job completed
0.4164,Event,ADDED,eval-conflicts-rho005-r7-088-77wmm.18d465ea83e10728,reason=Scheduled count=None msg=Successfully assigned compute/eval-conflicts-rho005-r7-088-77wmm to kind-worker2
0.4166,Event,ADDED,eval-conflicts-rho005-r7-088-77wmm.18d465ea9da96b1a,"reason=Pulled count=1 msg=Container image ""busybox:musl"" already present on machine"
0.4168,Event,ADDED,eval-conflicts-rho005-r7-088-77wmm.18d465ea9ecdd24b,reason=Created count=1 msg=Created container: task
0.4169,Event,ADDED,eval-conflicts-rho005-r7-088-77wmm.18d465eaa28815b0,reason=Started count=1 msg=Started container task
0.4171,Event,ADDED,eval-conflicts-rho005-r7-088.18d465ea82feeef7,reason=SuccessfulCreate count=1 msg=Created pod: eval-conflicts-rho005-r7-088-77wmm
0.4173,Event,ADDED,eval-conflicts-rho005-r7-088.18d465edc89cdd1e,reason=Completed count=1 msg=Job completed
0.4174,Event,ADDED,eval-conflicts-rho005-r7-089-trtnj.18d465eabf029149,reason=Scheduled count=None msg=Successfully assigned compute/eval-conflicts-rho005-r7-089-trtnj to kind-worker
0.4176,Event,ADDED,eval-conflicts-rho005-r7-089-trtnj.18d465ead7b7eca0,"reason=Pulled count=1 msg=Container image ""busybox:musl"" already present on machine"
0.4179,Event,ADDED,eval-conflicts-rho005-r7-089-trtnj.18d465ead8b8bf80,reason=Created count=1 msg=Created container: task
0.4181,Event,ADDED,eval-conflicts-rho005-r7-089-trtnj.18d465eadafa6645,reason=Started count=1 msg=Started container task
0.4183,Event,ADDED,eval-conflicts-rho005-r7-089.18d465eabe37cbc9,reason=SuccessfulCreate count=1 msg=Created pod: eval-conflicts-rho005-r7-089-trtnj
0.4184,Event,ADDED,eval-conflicts-rho005-r7-089.18d465edeaae2075,reason=Completed count=1 msg=Job completed
0.4186,Event,ADDED,eval-conflicts-rho005-r7-090-vcll4.18d465eafa0de538,reason=Scheduled count=None msg=Successfully assigned compute/eval-conflicts-rho005-r7-090-vcll4 to kind-worker
0.4189,Event,ADDED,eval-conflicts-rho005-r7-090-vcll4.18d465eb14430f98,"reason=Pulled count=1 msg=Container image ""busybox:musl"" already present on machine"
0.4191,Event,ADDED,eval-conflicts-rho005-r7-090-vcll4.18d465eb156bb861,reason=Created count=1 msg=Created container: task
0.4192,Event,ADDED,eval-conflicts-rho005-r7-090-vcll4.18d465eb1844dd7d,reason=Started count=1 msg=Started container task
0.4196,Event,ADDED,eval-conflicts-rho005-r7-090.18d465eaf9574758,reason=SuccessfulCreate count=1 msg=Created pod: eval-conflicts-rho005-r7-090-vcll4
0.4197,Event,ADDED,eval-conflicts-rho005-r7-090.18d465ee26872df6,reason=Completed count=1 msg=Job completed
0.4199,Event,ADDED,eval-conflicts-rho005-r7-091-5b7cp.18d465eb36565fb1,reason=Scheduled count=None msg=Successfully assigned compute/eval-conflicts-rho005-r7-091-5b7cp to kind-worker2
0.4201,Event,ADDED,eval-conflicts-rho005-r7-091-5b7cp.18d465eb4ffc9d3c,"reason=Pulled count=1 msg=Container image ""busybox:musl"" already present on machine"
0.4203,Event,ADDED,eval-conflicts-rho005-r7-091-5b7cp.18d465eb510dfd9a,reason=Created count=1 msg=Created container: task
0.4205,Event,ADDED,eval-conflicts-rho005-r7-091-5b7cp.18d465eb55602dd5,reason=Started count=1 msg=Started container task
0.4207,Event,ADDED,eval-conflicts-rho005-r7-091.18d465eb3565f049,reason=SuccessfulCreate count=1 msg=Created pod: eval-conflicts-rho005-r7-091-5b7cp
0.4209,Event,ADDED,eval-conflicts-rho005-r7-091.18d465ee7c819f25,reason=Completed count=1 msg=Job completed
0.421,Event,ADDED,eval-conflicts-rho005-r7-092-rpvvv.18d465eb705ca418,"reason=FailedScheduling count=None msg=0/6 nodes are available: 6 node(s) had untolerated taint(s). no new claims to deallocate, preemption: 0/6 nodes are available: 6 Preemption is not helpful for scheduling."
0.4212,Event,ADDED,eval-conflicts-rho005-r7-092-rpvvv.18d465ebae41a4ba,reason=Scheduled count=None msg=Successfully assigned compute/eval-conflicts-rho005-r7-092-rpvvv to kind-worker4
0.4214,Event,ADDED,eval-conflicts-rho005-r7-092-rpvvv.18d465ebc8de05d7,"reason=Pulled count=1 msg=Container image ""busybox:musl"" already present on machine"
0.4216,Event,ADDED,eval-conflicts-rho005-r7-092-rpvvv.18d465ebca318ffd,reason=Created count=1 msg=Created container: task
0.4217,Event,ADDED,eval-conflicts-rho005-r7-092-rpvvv.18d465ebcc13b176,reason=Started count=1 msg=Started container task
0.4219,Event,ADDED,eval-conflicts-rho005-r7-092.18d465eb705095a5,reason=SuccessfulCreate count=1 msg=Created pod: eval-conflicts-rho005-r7-092-rpvvv
0.4222,Event,ADDED,eval-conflicts-rho005-r7-092.18d465ef005fcbd1,reason=Completed count=1 msg=Job completed
0.4224,Event,ADDED,eval-conflicts-rho005-r7-093-74qs9.18d465ebabc433ab,"reason=FailedScheduling count=None msg=0/6 nodes are available: 6 node(s) had untolerated taint(s). no new claims to deallocate, preemption: 0/6 nodes are available: 6 Preemption is not helpful for scheduling."
0.4226,Event,ADDED,eval-conflicts-rho005-r7-093-74qs9.18d465ebae71ab30,reason=Scheduled count=None msg=Successfully assigned compute/eval-conflicts-rho005-r7-093-74qs9 to kind-worker4
0.4228,Event,ADDED,eval-conflicts-rho005-r7-093-74qs9.18d465ebc902955b,"reason=Pulled count=1 msg=Container image ""busybox:musl"" already present on machine"
0.4231,Event,ADDED,eval-conflicts-rho005-r7-093-74qs9.18d465ebca84644a,reason=Created count=1 msg=Created container: task
0.4233,Event,ADDED,eval-conflicts-rho005-r7-093-74qs9.18d465ebcc460c51,reason=Started count=1 msg=Started container task
0.4234,Event,ADDED,eval-conflicts-rho005-r7-093.18d465ebabb35b50,reason=SuccessfulCreate count=1 msg=Created pod: eval-conflicts-rho005-r7-093-74qs9
0.424,Event,ADDED,eval-conflicts-rho005-r7-093.18d465ef003dd2c4,reason=Completed count=1 msg=Job completed
0.4242,Event,ADDED,eval-conflicts-rho005-r7-094-8jv8j.18d465ebe88b577a,reason=Scheduled count=None msg=Successfully assigned compute/eval-conflicts-rho005-r7-094-8jv8j to kind-worker4
0.4243,Event,ADDED,eval-conflicts-rho005-r7-094-8jv8j.18d465ec01d403f2,"reason=Pulled count=1 msg=Container image ""busybox:musl"" already present on machine"
0.4245,Event,ADDED,eval-conflicts-rho005-r7-094-8jv8j.18d465ec02e5a144,reason=Created count=1 msg=Created container: task
0.4248,Event,ADDED,eval-conflicts-rho005-r7-094-8jv8j.18d465ec04df83d8,reason=Started count=1 msg=Started container task
0.425,Event,ADDED,eval-conflicts-rho005-r7-094.18d465ebe7d13b6b,reason=SuccessfulCreate count=1 msg=Created pod: eval-conflicts-rho005-r7-094-8jv8j
0.4251,Event,ADDED,eval-conflicts-rho005-r7-094.18d465ef3c3b4163,reason=Completed count=1 msg=Job completed
0.4253,Event,ADDED,eval-conflicts-rho005-r7-095-fvfmp.18d465ec24cfd19d,reason=Scheduled count=None msg=Successfully assigned compute/eval-conflicts-rho005-r7-095-fvfmp to kind-worker5
0.4255,Event,ADDED,eval-conflicts-rho005-r7-095-fvfmp.18d465ec3dd5845e,"reason=Pulled count=1 msg=Container image ""busybox:musl"" already present on machine"
0.4257,Event,ADDED,eval-conflicts-rho005-r7-095-fvfmp.18d465ec3ee104d1,reason=Created count=1 msg=Created container: task
0.4258,Event,ADDED,eval-conflicts-rho005-r7-095-fvfmp.18d465ec42ff7334,reason=Started count=1 msg=Started container task
0.426,Event,ADDED,eval-conflicts-rho005-r7-095.18d465ec24151b79,reason=SuccessfulCreate count=1 msg=Created pod: eval-conflicts-rho005-r7-095-fvfmp
0.4262,Event,ADDED,eval-conflicts-rho005-r7-095.18d465ef5c83dd28,reason=Completed count=1 msg=Job completed
0.4263,Event,ADDED,eval-conflicts-rho005-r7-096-xmmsh.18d465ec5f991a29,reason=Scheduled count=None msg=Successfully assigned compute/eval-conflicts-rho005-r7-096-xmmsh to kind-worker5
0.4265,Event,ADDED,eval-conflicts-rho005-r7-096-xmmsh.18d465ec7872d1d3,"reason=Pulled count=1 msg=Container image ""busybox:musl"" already present on machine"
0.4267,Event,ADDED,eval-conflicts-rho005-r7-096-xmmsh.18d465ec79840cdb,reason=Created count=1 msg=Created container: task
0.4268,Event,ADDED,eval-conflicts-rho005-r7-096-xmmsh.18d465ec7b4f4c3e,reason=Started count=1 msg=Started container task
0.427,Event,ADDED,eval-conflicts-rho005-r7-096.18d465ec5ea404c7,reason=SuccessfulCreate count=1 msg=Created pod: eval-conflicts-rho005-r7-096-xmmsh
0.4273,Event,ADDED,eval-conflicts-rho005-r7-096.18d465ef9819a134,reason=Completed count=1 msg=Job completed
0.4274,Event,ADDED,eval-conflicts-rho005-r7-097-rrctx.18d465ec9b8ce8c7,reason=Scheduled count=None msg=Successfully assigned compute/eval-conflicts-rho005-r7-097-rrctx to kind-worker5
0.4276,Event,ADDED,eval-conflicts-rho005-r7-097-rrctx.18d465ecb56882c3,"reason=Pulled count=1 msg=Container image ""busybox:musl"" already present on machine"
0.4278,Event,ADDED,eval-conflicts-rho005-r7-097-rrctx.18d465ecb68d98fb,reason=Created count=1 msg=Created container: task
0.4281,Event,ADDED,eval-conflicts-rho005-r7-097-rrctx.18d465ecb96dc5b6,reason=Started count=1 msg=Started container task
0.4283,Event,ADDED,eval-conflicts-rho005-r7-097.18d465ec9a92e814,reason=SuccessfulCreate count=1 msg=Created pod: eval-conflicts-rho005-r7-097-rrctx
0.4285,Event,ADDED,eval-conflicts-rho005-r7-097.18d465efd3219513,reason=Completed count=1 msg=Job completed
0.4287,Event,ADDED,eval-conflicts-rho005-r7-098-6c5n7.18d465ecd77a9442,reason=Scheduled count=None msg=Successfully assigned compute/eval-conflicts-rho005-r7-098-6c5n7 to kind-worker5
0.429,Event,ADDED,eval-conflicts-rho005-r7-098-6c5n7.18d465ecf0656c4d,"reason=Pulled count=1 msg=Container image ""busybox:musl"" already present on machine"
0.4292,Event,ADDED,eval-conflicts-rho005-r7-098-6c5n7.18d465ecf1785b2e,reason=Created count=1 msg=Created container: task
0.4294,Event,ADDED,eval-conflicts-rho005-r7-098-6c5n7.18d465ecf44a84c2,reason=Started count=1 msg=Started container task
0.4298,Event,ADDED,eval-conflicts-rho005-r7-098.18d465ecd699cf5d,reason=SuccessfulCreate count=1 msg=Created pod: eval-conflicts-rho005-r7-098-6c5n7
0.43,Event,ADDED,eval-conflicts-rho005-r7-098.18d465f00f49a13a,reason=Completed count=1 msg=Job completed
0.4303,Event,ADDED,eval-conflicts-rho005-r7-099-c7s9j.18d465ed12d9e2db,reason=Scheduled count=None msg=Successfully assigned compute/eval-conflicts-rho005-r7-099-c7s9j to kind-worker4
0.4306,Event,ADDED,eval-conflicts-rho005-r7-099-c7s9j.18d465ed2c8b69cf,"reason=Pulled count=1 msg=Container image ""busybox:musl"" already present on machine"
0.4309,Event,ADDED,eval-conflicts-rho005-r7-099-c7s9j.18d465ed2d9f6903,reason=Created count=1 msg=Created container: task
0.4311,Event,ADDED,eval-conflicts-rho005-r7-099-c7s9j.18d465ed2f7854dd,reason=Started count=1 msg=Started container task
0.4312,Event,ADDED,eval-conflicts-rho005-r7-099.18d465ed11f399a4,reason=SuccessfulCreate count=1 msg=Created pod: eval-conflicts-rho005-r7-099-c7s9j
0.4314,Event,ADDED,eval-conflicts-rho005-r7-099.18d465f0668f764a,reason=Completed count=1 msg=Job completed
0.4316,Event,ADDED,eval-conflicts-rho005-r8-000-2zkhp.18d465f54a699b1b,reason=Scheduled count=None msg=Successfully assigned compute/eval-conflicts-rho005-r8-000-2zkhp to kind-worker2
0.4318,Event,ADDED,eval-conflicts-rho005-r8-000-2zkhp.18d465f56649a2f0,"reason=Pulled count=1 msg=Container image ""busybox:musl"" already present on machine"
0.432,Event,ADDED,eval-conflicts-rho005-r8-000-2zkhp.18d465f56773a21b,reason=Created count=1 msg=Created container: task
0.4321,Event,ADDED,eval-conflicts-rho005-r8-000-2zkhp.18d465f569b44854,reason=Started count=1 msg=Started container task
0.4323,Event,ADDED,eval-conflicts-rho005-r8-000.18d465f5497a6522,reason=SuccessfulCreate count=1 msg=Created pod: eval-conflicts-rho005-r8-000-2zkhp
0.4325,Event,ADDED,eval-conflicts-rho005-r8-000.18d465f885663b09,reason=Completed count=1 msg=Job completed
0.4326,Event,ADDED,eval-conflicts-rho005-r8-001-mb9r7.18d465f58700c962,reason=Scheduled count=None msg=Successfully assigned compute/eval-conflicts-rho005-r8-001-mb9r7 to kind-worker
0.4328,Event,ADDED,eval-conflicts-rho005-r8-001-mb9r7.18d465f5a1c52013,"reason=Pulled count=1 msg=Container image ""busybox:musl"" already present on machine"
0.433,Event,ADDED,eval-conflicts-rho005-r8-001-mb9r7.18d465f5a303b53d,reason=Created count=1 msg=Created container: task
0.4331,Event,ADDED,eval-conflicts-rho005-r8-001-mb9r7.18d465f5a8193154,reason=Started count=1 msg=Started container task
0.4333,Event,ADDED,eval-conflicts-rho005-r8-001.18d465f585c2a4d5,reason=SuccessfulCreate count=1 msg=Created pod: eval-conflicts-rho005-r8-001-mb9r7
0.4335,Event,ADDED,eval-conflicts-rho005-r8-001.18d465f8e3c5e086,reason=Completed count=1 msg=Job completed
0.4336,Event,ADDED,eval-conflicts-rho005-r8-002-ckg5q.18d465f5c01af68c,reason=Scheduled count=None msg=Successfully assigned compute/eval-conflicts-rho005-r8-002-ckg5q to kind-worker5
0.4339,Event,ADDED,eval-conflicts-rho005-r8-002-ckg5q.18d465f5d8f94e9e,"reason=Pulled count=1 msg=Container image ""busybox:musl"" already present on machine"
0.4341,Event,ADDED,eval-conflicts-rho005-r8-002-ckg5q.18d465f5da187994,reason=Created count=1 msg=Created container: task
0.4343,Event,ADDED,eval-conflicts-rho005-r8-002-ckg5q.18d465f5dc952365,reason=Started count=1 msg=Started container task
0.4344,Event,ADDED,eval-conflicts-rho005-r8-002.18d465f5bf15d61a,reason=SuccessfulCreate count=1 msg=Created pod: eval-conflicts-rho005-r8-002-ckg5q
0.4346,Event,ADDED,eval-conflicts-rho005-r8-002.18d465f8edcba3d1,reason=Completed count=1 msg=Job completed
0.4348,Event,ADDED,eval-conflicts-rho005-r8-003-rscmz.18d465f5fbefa857,reason=Scheduled count=None msg=Successfully assigned compute/eval-conflicts-rho005-r8-003-rscmz to kind-worker
0.4349,Event,ADDED,eval-conflicts-rho005-r8-003-rscmz.18d465f615090854,"reason=Pulled count=1 msg=Container image ""busybox:musl"" already present on machine"
0.4351,Event,ADDED,eval-conflicts-rho005-r8-003-rscmz.18d465f6162a0d6f,reason=Created count=1 msg=Created container: task
0.4353,Event,ADDED,eval-conflicts-rho005-r8-003-rscmz.18d465f61a87d0fb,reason=Started count=1 msg=Started container task
0.4355,Event,ADDED,eval-conflicts-rho005-r8-003.18d465f5faa8bca4,reason=SuccessfulCreate count=1 msg=Created pod: eval-conflicts-rho005-r8-003-rscmz
0.4356,Event,ADDED,eval-conflicts-rho005-r8-003.18d465f95b8dd456,reason=Completed count=1 msg=Job completed
0.4358,Event,ADDED,eval-conflicts-rho005-r8-004-d9nqc.18d465f636eb2a5e,reason=Scheduled count=None msg=Successfully assigned compute/eval-conflicts-rho005-r8-004-d9nqc to kind-worker5
0.436,Event,ADDED,eval-conflicts-rho005-r8-004-d9nqc.18d465f64fc2eeb4,"reason=Pulled count=1 msg=Container image ""busybox:musl"" already present on machine"
0.4361,Event,ADDED,eval-conflicts-rho005-r8-004-d9nqc.18d465f651717adf,reason=Created count=1 msg=Created container: task
0.4363,Event,ADDED,eval-conflicts-rho005-r8-004-d9nqc.18d465f65795e41f,reason=Started count=1 msg=Started container task
0.4365,Event,ADDED,eval-conflicts-rho005-r8-004.18d465f635b8afee,reason=SuccessfulCreate count=1 msg=Created pod: eval-conflicts-rho005-r8-004-d9nqc
0.4366,Event,ADDED,eval-conflicts-rho005-r8-004.18d465f965f392cf,reason=Completed count=1 msg=Job completed
0.4368,Event,ADDED,eval-conflicts-rho005-r8-005-kqldq.18d465f673389052,reason=Scheduled count=None msg=Successfully assigned compute/eval-conflicts-rho005-r8-005-kqldq to kind-worker5
0.4369,Event,ADDED,eval-conflicts-rho005-r8-005-kqldq.18d465f68e7a9e9c,"reason=Pulled count=1 msg=Container image ""busybox:musl"" already present on machine"
0.4371,Event,ADDED,eval-conflicts-rho005-r8-005-kqldq.18d465f68f83565f,reason=Created count=1 msg=Created container: task
0.4373,Event,ADDED,eval-conflicts-rho005-r8-005-kqldq.18d465f693ae7ff9,reason=Started count=1 msg=Started container task
0.4374,Event,ADDED,eval-conflicts-rho005-r8-005.18d465f6720c59bb,reason=SuccessfulCreate count=1 msg=Created pod: eval-conflicts-rho005-r8-005-kqldq
0.4376,Event,ADDED,eval-conflicts-rho005-r8-005.18d465f9a21ac08e,reason=Completed count=1 msg=Job completed
0.4378,Event,ADDED,eval-conflicts-rho005-r8-006-bjhm6.18d465f6b03c95af,reason=Scheduled count=None msg=Successfully assigned compute/eval-conflicts-rho005-r8-006-bjhm6 to kind-worker4
0.4379,Event,ADDED,eval-conflicts-rho005-r8-006-bjhm6.18d465f6ca538747,"reason=Pulled count=1 msg=Container image ""busybox:musl"" already present on machine"
0.4381,Event,ADDED,eval-conflicts-rho005-r8-006-bjhm6.18d465f6cb7ad308,reason=Created count=1 msg=Created container: task
0.4383,Event,ADDED,eval-conflicts-rho005-r8-006-bjhm6.18d465f6cfd176b4,reason=Started count=1 msg=Started container task
0.4384,Event,ADDED,eval-conflicts-rho005-r8-006.18d465f6aec181dd,reason=SuccessfulCreate count=1 msg=Created pod: eval-conflicts-rho005-r8-006-bjhm6
0.4386,Event,ADDED,eval-conflicts-rho005-r8-006.18d465f9f8c45e60,reason=Completed count=1 msg=Job completed
0.4388,Event,ADDED,eval-conflicts-rho005-r8-007-2gwj2.18d465f6ea1fd0d8,reason=Scheduled count=None msg=Successfully assigned compute/eval-conflicts-rho005-r8-007-2gwj2 to kind-worker
0.4389,Event,ADDED,eval-conflicts-rho005-r8-007-2gwj2.18d465f705227e1c,"reason=Pulled count=1 msg=Container image ""busybox:musl"" already present on machine"
0.4391,Event,ADDED,eval-conflicts-rho005-r8-007-2gwj2.18d465f706604898,reason=Created count=1 msg=Created container: task
0.4393,Event,ADDED,eval-conflicts-rho005-r8-007-2gwj2.18d465f70a98a015,reason=Started count=1 msg=Started container task
0.4394,Event,ADDED,eval-conflicts-rho005-r8-007.18d465f6e8993c3c,reason=SuccessfulCreate count=1 msg=Created pod: eval-conflicts-rho005-r8-007-2gwj2
0.4396,Event,ADDED,eval-conflicts-rho005-r8-007.18d465fa49d14a15,reason=Completed count=1 msg=Job completed
0.4398,Event,ADDED,eval-conflicts-rho005-r8-008-w9l7t.18d465f7265fa470,reason=Scheduled count=None msg=Successfully assigned compute/eval-conflicts-rho005-r8-008-w9l7t to kind-worker2
0.44,Event,ADDED,eval-conflicts-rho005-r8-008-w9l7t.18d465f7403eb008,"reason=Pulled count=1 msg=Container image ""busybox:musl"" already present on machine"
0.4401,Event,ADDED,eval-conflicts-rho005-r8-008-w9l7t.18d465f7414eb0a4,reason=Created count=1 msg=Created container: task
0.4403,Event,ADDED,eval-conflicts-rho005-r8-008-w9l7t.18d465f743dfba9e,reason=Started count=1 msg=Started container task
0.4405,Event,ADDED,eval-conflicts-rho005-r8-008.18d465f724e7d81d,reason=SuccessfulCreate count=1 msg=Created pod: eval-conflicts-rho005-r8-008-w9l7t
0.4406,Event,ADDED,eval-conflicts-rho005-r8-008.18d465fa63764bfe,reason=Completed count=1 msg=Job completed
0.4408,Event,ADDED,eval-conflicts-rho005-r8-009-rjszd.18d465f760a33dec,reason=Scheduled count=None msg=Successfully assigned compute/eval-conflicts-rho005-r8-009-rjszd to kind-worker5
0.441,Event,ADDED,eval-conflicts-rho005-r8-009-rjszd.18d465f77b4a3917,"reason=Pulled count=1 msg=Container image ""busybox:musl"" already present on machine"
0.4436,Event,ADDED,eval-conflicts-rho005-r8-009-rjszd.18d465f77c79ef86,reason=Created count=1 msg=Created container: task
0.4438,Event,ADDED,eval-conflicts-rho005-r8-009-rjszd.18d465f78018ce56,reason=Started count=1 msg=Started container task
0.444,Event,ADDED,eval-conflicts-rho005-r8-009.18d465f75fb793b4,reason=SuccessfulCreate count=1 msg=Created pod: eval-conflicts-rho005-r8-009-rjszd
0.4441,Event,ADDED,eval-conflicts-rho005-r8-009.18d465fa912a15b6,reason=Completed count=1 msg=Job completed
0.4443,Event,ADDED,eval-conflicts-rho005-r8-010-rtsw6.18d465f79ce53493,reason=Scheduled count=None msg=Successfully assigned compute/eval-conflicts-rho005-r8-010-rtsw6 to kind-worker3
0.4445,Event,ADDED,eval-conflicts-rho005-r8-010-rtsw6.18d465f7b897d319,"reason=Pulled count=1 msg=Container image ""busybox:musl"" already present on machine"
0.4446,Event,ADDED,eval-conflicts-rho005-r8-010-rtsw6.18d465f7b9aa2799,reason=Created count=1 msg=Created container: task
0.4448,Event,ADDED,eval-conflicts-rho005-r8-010-rtsw6.18d465f7bc155355,reason=Started count=1 msg=Started container task
0.4449,Event,ADDED,eval-conflicts-rho005-r8-010.18d465f79c3af176,reason=SuccessfulCreate count=1 msg=Created pod: eval-conflicts-rho005-r8-010-rtsw6
0.4451,Event,ADDED,eval-conflicts-rho005-r8-010.18d465fad5a9604d,reason=Completed count=1 msg=Job completed
0.4453,Event,ADDED,eval-conflicts-rho005-r8-011-s4zql.18d465f7d6f41217,"reason=FailedScheduling count=None msg=0/6 nodes are available: 1 c_wall violated: 1 conflicting context pair(s) with node memory, 5 node(s) had untolerated taint(s). no new claims to deallocate, preemption: 0/6 nodes are available: 1 No preemption victims found for incoming pod, 5 Preemption is not helpful for scheduling."
0.4455,Event,ADDED,eval-conflicts-rho005-r8-011-s4zql.18d465f7d792dafe,"reason=FailedScheduling count=None msg=0/6 nodes are available: 1 c_wall violated: 1 conflicting context pair(s) with node memory, 5 node(s) had untolerated taint(s). no new claims to deallocate, preemption: 0/6 nodes are available: 1 No preemption victims found for incoming pod, 5 Preemption is not helpful for scheduling."
0.4457,Event,ADDED,eval-conflicts-rho005-r8-011-s4zql.18d465f97aa0b012,"reason=FailedScheduling count=None msg=0/6 nodes are available: 1 c_wall violated: 2 conflicting context pair(s) with node memory, 5 node(s) had untolerated taint(s). no new claims to deallocate, preemption: 0/6 nodes are available: 1 No preemption victims found for incoming pod, 5 Preemption is not helpful for scheduling."
0.4458,Event,ADDED,eval-conflicts-rho005-r8-011-s4zql.18d465f9d124b727,reason=Scheduled count=None msg=Successfully assigned compute/eval-conflicts-rho005-r8-011-s4zql to kind-worker4
0.446,Event,ADDED,eval-conflicts-rho005-r8-011-s4zql.18d465f9eafb1d55,"reason=Pulled count=1 msg=Container image ""busybox:musl"" already present on machine"
0.4461,Event,ADDED,eval-conflicts-rho005-r8-011-s4zql.18d465f9ec3683bc,reason=Created count=1 msg=Created container: task
0.4463,Event,ADDED,eval-conflicts-rho005-r8-011-s4zql.18d465f9f09e2ddd,reason=Started count=1 msg=Started container task
0.4465,Event,ADDED,eval-conflicts-rho005-r8-011.18d465f7d6b64081,reason=SuccessfulCreate count=1 msg=Created pod: eval-conflicts-rho005-r8-011-s4zql
0.4466,Event,ADDED,eval-conflicts-rho005-r8-011.18d465fd01dced61,reason=Completed count=1 msg=Job completed
0.4468,Event,ADDED,eval-conflicts-rho005-r8-012-22lv2.18d465f813de1615,reason=Scheduled count=None msg=Successfully assigned compute/eval-conflicts-rho005-r8-012-22lv2 to kind-worker3
0.447,Event,ADDED,eval-conflicts-rho005-r8-012-22lv2.18d465f82ed706a1,"reason=Pulled count=1 msg=Container image ""busybox:musl"" already present on machine"
0.4472,Event,ADDED,eval-conflicts-rho005-r8-012-22lv2.18d465f83068a3eb,reason=Created count=1 msg=Created container: task
0.4475,Event,ADDED,eval-conflicts-rho005-r8-012-22lv2.18d465f834e170f5,reason=Started count=1 msg=Started container task
0.4477,Event,ADDED,eval-conflicts-rho005-r8-012.18d465f8135a2cdf,reason=SuccessfulCreate count=1 msg=Created pod: eval-conflicts-rho005-r8-012-22lv2
0.4479,Event,ADDED,eval-conflicts-rho005-r8-012.18d465fb4de49ae8,reason=Completed count=1 msg=Job completed
0.4481,Event,ADDED,eval-conflicts-rho005-r8-013-pzr7b.18d465f84ebad0f7,reason=Scheduled count=None msg=Successfully assigned compute/eval-conflicts-rho005-r8-013-pzr7b to kind-worker3
0.4484,Event,ADDED,eval-conflicts-rho005-r8-013-pzr7b.18d465f868e2f20c,"reason=Pulled count=1 msg=Container image ""busybox:musl"" already present on machine"
0.4486,Event,ADDED,eval-conflicts-rho005-r8-013-pzr7b.18d465f869f20331,reason=Created count=1 msg=Created container: task
0.4488,Event,ADDED,eval-conflicts-rho005-r8-013-pzr7b.18d465f871db0fa4,reason=Started count=1 msg=Started container task
0.449,Event,ADDED,eval-conflicts-rho005-r8-013.18d465f84e2ed82c,reason=SuccessfulCreate count=1 msg=Created pod: eval-conflicts-rho005-r8-013-pzr7b
0.4493,Event,ADDED,eval-conflicts-rho005-r8-013.18d465fb898c1306,reason=Completed count=1 msg=Job completed
0.4494,Event,ADDED,eval-conflicts-rho005-r8-014-fcxzh.18d465f88b8cc5ec,reason=Scheduled count=None msg=Successfully assigned compute/eval-conflicts-rho005-r8-014-fcxzh to kind-worker3
0.4496,Event,ADDED,eval-conflicts-rho005-r8-014-fcxzh.18d465f8a3c8a1c0,"reason=Pulled count=1 msg=Container image ""busybox:musl"" already present on machine"
0.4499,Event,ADDED,eval-conflicts-rho005-r8-014-fcxzh.18d465f8a4dd9a8c,reason=Created count=1 msg=Created container: task
0.45,Event,ADDED,eval-conflicts-rho005-r8-014-fcxzh.18d465f8a9b36b9a,reason=Started count=1 msg=Started container task
0.4502,Event,ADDED,eval-conflicts-rho005-r8-014.18d465f88adcc39f,reason=SuccessfulCreate count=1 msg=Created pod: eval-conflicts-rho005-r8-014-fcxzh
0.4504,Event,ADDED,eval-conflicts-rho005-r8-014.18d465fbc4bb4f65,reason=Completed count=1 msg=Job completed
0.4506,Event,ADDED,eval-conflicts-rho005-r8-015-td7br.18d465f8c5aa85ce,reason=Scheduled count=None msg=Successfully assigned compute/eval-conflicts-rho005-r8-015-td7br to kind-worker3
0.4508,Event,ADDED,eval-conflicts-rho005-r8-015-td7br.18d465f8df93f03e,"reason=Pulled count=1 msg=Container image ""busybox:musl"" already present on machine"
0.4509,Event,ADDED,eval-conflicts-rho005-r8-015-td7br.18d465f8e0b96746,reason=Created count=1 msg=Created container: task
0.4511,Event,ADDED,eval-conflicts-rho005-r8-015-td7br.18d465f8e2b9c497,reason=Started count=1 msg=Started container task
0.4513,Event,ADDED,eval-conflicts-rho005-r8-015.18d465f8c52ea9fd,reason=SuccessfulCreate count=1 msg=Created pod: eval-conflicts-rho005-r8-015-td7br
0.4516,Event,ADDED,eval-conflicts-rho005-r8-015.18d465fc007b4c65,reason=Completed count=1 msg=Job completed
0.4519,Event,ADDED,eval-conflicts-rho005-r8-016-z6p9q.18d465f901d63707,reason=Scheduled count=None msg=Successfully assigned compute/eval-conflicts-rho005-r8-016-z6p9q to kind-worker3
0.4526,Event,ADDED,eval-conflicts-rho005-r8-016-z6p9q.18d465f91b635daf,"reason=Pulled count=1 msg=Container image ""busybox:musl"" already present on machine"
0.4529,Event,ADDED,eval-conflicts-rho005-r8-016-z6p9q.18d465f91c859996,reason=Created count=1 msg=Created container: task
0.4534,Event,ADDED,eval-conflicts-rho005-r8-016-z6p9q.18d465f91eeb62ff,reason=Started count=1 msg=Started container task
0.4536,Event,ADDED,eval-conflicts-rho005-r8-016.18d465f9013da75c,reason=SuccessfulCreate count=1 msg=Created pod: eval-conflicts-rho005-r8-016-z6p9q
0.454,Event,ADDED,eval-conflicts-rho005-r8-016.18d465fc3d25d09a,reason=Completed count=1 msg=Job completed
0.4542,Event,ADDED,eval-conflicts-rho005-r8-017-5fr57.18d465f93ddfe395,reason=Scheduled count=None msg=Successfully assigned compute/eval-conflicts-rho005-r8-017-5fr57 to kind-worker3
0.4544,Event,ADDED,eval-conflicts-rho005-r8-017-5fr57.18d465f957a1eb82,"reason=Pulled count=1 msg=Container image ""busybox:musl"" already present on machine"
0.4547,Event,ADDED,eval-conflicts-rho005-r8-017-5fr57.18d465f958bbb6d1,reason=Created count=1 msg=Created container: task
0.455,Event,ADDED,eval-conflicts-rho005-r8-017-5fr57.18d465f95b45828a,reason=Started count=1 msg=Started container task
0.4552,Event,ADDED,eval-conflicts-rho005-r8-017.18d465f93d58428b,reason=SuccessfulCreate count=1 msg=Created pod: eval-conflicts-rho005-r8-017-5fr57
0.4554,Event,ADDED,eval-conflicts-rho005-r8-017.18d465fc3dba5886,reason=Completed count=1 msg=Job completed
0.4557,Event,ADDED,eval-conflicts-rho005-r8-018-xk5gt.18d465f9797406f4,reason=Scheduled count=None msg=Successfully assigned compute/eval-conflicts-rho005-r8-018-xk5gt to kind-worker3
0.4559,Event,ADDED,eval-conflicts-rho005-r8-018-xk5gt.18d465f991f46057,"reason=Pulled count=1 msg=Container image ""busybox:musl"" already present on machine"
0.4561,Event,ADDED,eval-conflicts-rho005-r8-018-xk5gt.18d465f9933ed703,reason=Created count=1 msg=Created container: task
0.4562,Event,ADDED,eval-conflicts-rho005-r8-018-xk5gt.18d465f99539f491,reason=Started count=1 msg=Started container task
0.4565,Event,ADDED,eval-conflicts-rho005-r8-018.18d465f978f2b498,reason=SuccessfulCreate count=1 msg=Created pod: eval-conflicts-rho005-r8-018-xk5gt
0.4567,Event,ADDED,eval-conflicts-rho005-r8-018.18d465fcb5303954,reason=Completed count=1 msg=Job completed
0.4569,Event,ADDED,eval-conflicts-rho005-r8-019-qkxst.18d465f9b448ecf3,reason=Scheduled count=None msg=Successfully assigned compute/eval-conflicts-rho005-r8-019-qkxst to kind-worker3
0.4572,Event,ADDED,eval-conflicts-rho005-r8-019-qkxst.18d465f9ccee1b9d,"reason=Pulled count=1 msg=Container image ""busybox:musl"" already present on machine"
0.4574,Event,ADDED,eval-conflicts-rho005-r8-019-qkxst.18d465f9cdf7c51d,reason=Created count=1 msg=Created container: task
0.4576,Event,ADDED,eval-conflicts-rho005-r8-019-qkxst.18d465f9d0daa368,reason=Started count=1 msg=Started container task
0.4577,Event,ADDED,eval-conflicts-rho005-r8-019.18d465f9b3b8c191,reason=SuccessfulCreate count=1 msg=Created pod: eval-conflicts-rho005-r8-019-qkxst
0.4581,Event,ADDED,eval-conflicts-rho005-r8-019.18d465fcf11e8fd4,reason=Completed count=1 msg=Job completed
0.4582,Event,ADDED,eval-conflicts-rho005-r8-020-ckcgt.18d465f9ef7ba5ee,"reason=FailedScheduling count=None msg=0/6 nodes are available: 1 c_wall violated: 1 conflicting context pair(s) with node memory, 5 node(s) had untolerated taint(s). no new claims to deallocate, preemption: 0/6 nodes are available: 1 No preemption victims found for incoming pod, 5 Preemption is not helpful for scheduling."
0.4584,Event,ADDED,eval-conflicts-rho005-r8-020-ckcgt.18d465f9f00ffc3e,"reason=FailedScheduling count=None msg=0/6 nodes are available: 1 c_wall violated: 1 conflicting context pair(s) with node memory, 5 node(s) had untolerated taint(s). no new claims to deallocate, preemption: 0/6 nodes are available: 1 No preemption victims found for incoming pod, 5 Preemption is not helpful for scheduling."
0.4587,Event,ADDED,eval-conflicts-rho005-r8-020-ckcgt.18d465fa3110c402,reason=Scheduled count=None msg=Successfully assigned compute/eval-conflicts-rho005-r8-020-ckcgt to kind-worker5
0.4589,Event,ADDED,eval-conflicts-rho005-r8-020-ckcgt.18d465fa49b58771,"reason=Pulled count=1 msg=Container image ""busybox:musl"" already present on machine"
0.4592,Event,ADDED,eval-conflicts-rho005-r8-020-ckcgt.18d465fa4af8b42b,reason=Created count=1 msg=Created container: task
0.4594,Event,ADDED,eval-conflicts-rho005-r8-020-ckcgt.18d465fa4ed7a754,reason=Started count=1 msg=Started container task
0.4597,Event,ADDED,eval-conflicts-rho005-r8-020.18d465f9ef3b5344,reason=SuccessfulCreate count=1 msg=Created pod: eval-conflicts-rho005-r8-020-ckcgt
0.4599,Event,ADDED,eval-conflicts-rho005-r8-020.18d465fd5f1a4951,reason=Completed count=1 msg=Job completed
0.4601,Event,ADDED,eval-conflicts-rho005-r8-021-lrc5b.18d465fa2b6c3240,reason=Scheduled count=None msg=Successfully assigned compute/eval-conflicts-rho005-r8-021-lrc5b to kind-worker4
0.4608,Event,ADDED,eval-conflicts-rho005-r8-021-lrc5b.18d465fa447d397d,"reason=Pulled count=1 msg=Container image ""busybox:musl"" already present on machine"
0.461,Event,ADDED,eval-conflicts-rho005-r8-021-lrc5b.18d465fa45b93758,reason=Created count=1 msg=Created container: task
0.4612,Event,ADDED,eval-conflicts-rho005-r8-021-lrc5b.18d465fa48f6caf7,reason=Started count=1 msg=Started container task
0.4613,Event,ADDED,eval-conflicts-rho005-r8-021.18d465fa2aea689f,reason=SuccessfulCreate count=1 msg=Created pod: eval-conflicts-rho005-r8-021-lrc5b
0.4617,Event,ADDED,eval-conflicts-rho005-r8-021.18d465fd7f3bf7bb,reason=Completed count=1 msg=Job completed
0.4618,Event,ADDED,eval-conflicts-rho005-r8-022-fqdxp.18d465fa678a95af,reason=Scheduled count=None msg=Successfully assigned compute/eval-conflicts-rho005-r8-022-fqdxp to kind-worker5
0.462,Event,ADDED,eval-conflicts-rho005-r8-022-fqdxp.18d465fa8213d7c0,"reason=Pulled count=1 msg=Container image ""busybox:musl"" already present on machine"
0.4622,Event,ADDED,eval-conflicts-rho005-r8-022-fqdxp.18d465fa831f2c6c,reason=Created count=1 msg=Created container: task
0.4625,Event,ADDED,eval-conflicts-rho005-r8-022-fqdxp.18d465fa86d35562,reason=Started count=1 msg=Started container task
0.4627,Event,ADDED,eval-conflicts-rho005-r8-022.18d465fa665592b8,reason=SuccessfulCreate count=1 msg=Created pod: eval-conflicts-rho005-r8-022-fqdxp
0.4629,Event,ADDED,eval-conflicts-rho005-r8-022.18d465fd9ac1393f,reason=Completed count=1 msg=Job completed
0.4632,Event,ADDED,eval-conflicts-rho005-r8-023-2kq5v.18d465faa32e46e5,reason=Scheduled count=None msg=Successfully assigned compute/eval-conflicts-rho005-r8-023-2kq5v to kind-worker5
0.4634,Event,ADDED,eval-conflicts-rho005-r8-023-2kq5v.18d465fabd7b05e9,"reason=Pulled count=1 msg=Container image ""busybox:musl"" already present on machine"
0.4636,Event,ADDED,eval-conflicts-rho005-r8-023-2kq5v.18d465fabe945140,reason=Created count=1 msg=Created container: task
0.4638,Event,ADDED,eval-conflicts-rho005-r8-023-2kq5v.18d465fac2d1b522,reason=Started count=1 msg=Started container task
0.4641,Event,ADDED,eval-conflicts-rho005-r8-023.18d465faa25b0c92,reason=SuccessfulCreate count=1 msg=Created pod: eval-conflicts-rho005-r8-023-2kq5v
0.4643,Event,ADDED,eval-conflicts-rho005-r8-023.18d465fddacad5c3,reason=Completed count=1 msg=Job completed
0.4645,Event,ADDED,eval-conflicts-rho005-r8-024-vv2ml.18d465fadf66e810,reason=Scheduled count=None msg=Successfully assigned compute/eval-conflicts-rho005-r8-024-vv2ml to kind-worker5
0.4646,Event,ADDED,eval-conflicts-rho005-r8-024-vv2ml.18d465fafa140a2e,"reason=Pulled count=1 msg=Container image ""busybox:musl"" already present on machine"
0.465,Event,ADDED,eval-conflicts-rho005-r8-024-vv2ml.18d465fafb2c4b54,reason=Created count=1 msg=Created container: task
0.4652,Event,ADDED,eval-conflicts-rho005-r8-024-vv2ml.18d465faff711688,reason=Started count=1 msg=Started container task
0.4653,Event,ADDED,eval-conflicts-rho005-r8-024.18d465fade7ed895,reason=SuccessfulCreate count=1 msg=Created pod: eval-conflicts-rho005-r8-024-vv2ml
0.4657,Event,ADDED,eval-conflicts-rho005-r8-024.18d465fddb67a6b2,reason=Completed count=1 msg=Job completed
0.4659,Event,ADDED,eval-conflicts-rho005-r8-025-vtlfd.18d465fb1a832b85,reason=Scheduled count=None msg=Successfully assigned compute/eval-conflicts-rho005-r8-025-vtlfd to kind-worker5
0.466,Event,ADDED,eval-conflicts-rho005-r8-025-vtlfd.18d465fb3315947e,"reason=Pulled count=1 msg=Container image ""busybox:musl"" already present on machine"
0.4662,Event,ADDED,eval-conflicts-rho005-r8-025-vtlfd.18d465fb34ad9abb,reason=Created count=1 msg=Created container: task
0.4664,Event,ADDED,eval-conflicts-rho005-r8-025-vtlfd.18d465fb392dc117,reason=Started count=1 msg=Started container task
0.4666,Event,ADDED,eval-conflicts-rho005-r8-025.18d465fb19a98e9d,reason=SuccessfulCreate count=1 msg=Created pod: eval-conflicts-rho005-r8-025-vtlfd
0.4667,Event,ADDED,eval-conflicts-rho005-r8-025.18d465fe5284170f,reason=Completed count=1 msg=Job completed
0.4669,Event,ADDED,eval-conflicts-rho005-r8-026-xhq8x.18d465fb56353474,reason=Scheduled count=None msg=Successfully assigned compute/eval-conflicts-rho005-r8-026-xhq8x to kind-worker4
0.4671,Event,ADDED,eval-conflicts-rho005-r8-026-xhq8x.18d465fb6f645437,"reason=Pulled count=1 msg=Container image ""busybox:musl"" already present on machine"
0.4672,Event,ADDED,eval-conflicts-rho005-r8-026-xhq8x.18d465fb70d4a6cb,reason=Created count=1 msg=Created container: task
0.4674,Event,ADDED,eval-conflicts-rho005-r8-026-xhq8x.18d465fb74898f14,reason=Started count=1 msg=Started container task
0.4676,Event,ADDED,eval-conflicts-rho005-r8-026.18d465fb54f84a5a,reason=SuccessfulCreate count=1 msg=Created pod: eval-conflicts-rho005-r8-026-xhq8x
0.4678,Event,ADDED,eval-conflicts-rho005-r8-026.18d465feab9b1891,reason=Completed count=1 msg=Job completed
0.4679,Event,ADDED,eval-conflicts-rho005-r8-027-fqlxx.18d465fb91af2be5,reason=Scheduled count=None msg=Successfully assigned compute/eval-conflicts-rho005-r8-027-fqlxx to kind-worker4
0.4681,Event,ADDED,eval-conflicts-rho005-r8-027-fqlxx.18d465fbab98e3b3,"reason=Pulled count=1 msg=Container image ""busybox:musl"" already present on machine"
0.4683,Event,ADDED,eval-conflicts-rho005-r8-027-fqlxx.18d465fbad34832e,reason=Created count=1 msg=Created container: task
0.4684,Event,ADDED,eval-conflicts-rho005-r8-027-fqlxx.18d465fbaf2f0f8b,reason=Started count=1 msg=Started container task
0.4686,Event,ADDED,eval-conflicts-rho005-r8-027.18d465fb910e93ff,reason=SuccessfulCreate count=1 msg=Created pod: eval-conflicts-rho005-r8-027-fqlxx
0.4688,Event,ADDED,eval-conflicts-rho005-r8-027.18d465fee780494b,reason=Completed count=1 msg=Job completed
0.4689,Event,ADDED,eval-conflicts-rho005-r8-028-6pr5g.18d465fbcd5c7300,reason=Scheduled count=None msg=Successfully assigned compute/eval-conflicts-rho005-r8-028-6pr5g to kind-worker5
0.4691,Event,ADDED,eval-conflicts-rho005-r8-028-6pr5g.18d465fbe734f3e0,"reason=Pulled count=1 msg=Container image ""busybox:musl"" already present on machine"
0.4693,Event,ADDED,eval-conflicts-rho005-r8-028-6pr5g.18d465fbe8622374,reason=Created count=1 msg=Created container: task
0.4694,Event,ADDED,eval-conflicts-rho005-r8-028-6pr5g.18d465fbf0584117,reason=Started count=1 msg=Started container task
0.4696,Event,ADDED,eval-conflicts-rho005-r8-028.18d465fbcc44ac38,reason=SuccessfulCreate count=1 msg=Created pod: eval-conflicts-rho005-r8-028-6pr5g
0.4698,Event,ADDED,eval-conflicts-rho005-r8-028.18d465ff0327c31b,reason=Completed count=1 msg=Job completed
0.4699,Event,ADDED,eval-conflicts-rho005-r8-029-7sgsk.18d465fc0898c751,reason=Scheduled count=None msg=Successfully assigned compute/eval-conflicts-rho005-r8-029-7sgsk to kind-worker
0.4703,Event,ADDED,eval-conflicts-rho005-r8-029-7sgsk.18d465fc23e0e056,"reason=Pulled count=1 msg=Container image ""busybox:musl"" already present on machine"
0.4704,Event,ADDED,eval-conflicts-rho005-r8-029-7sgsk.18d465fc2515f77c,reason=Created count=1 msg=Created container: task
0.4706,Event,ADDED,eval-conflicts-rho005-r8-029-7sgsk.18d465fc290b9467,reason=Started count=1 msg=Started container task
0.4708,Event,ADDED,eval-conflicts-rho005-r8-029.18d465fc07c34dae,reason=SuccessfulCreate count=1 msg=Created pod: eval-conflicts-rho005-r8-029-7sgsk
0.4709,Event,ADDED,eval-conflicts-rho005-r8-029.18d465ff35c2955a,reason=Completed count=1 msg=Job completed
0.4711,Event,ADDED,eval-conflicts-rho005-r8-030-ncjhv.18d465fc4541838d,reason=Scheduled count=None msg=Successfully assigned compute/eval-conflicts-rho005-r8-030-ncjhv to kind-worker2
0.4713,Event,ADDED,eval-conflicts-rho005-r8-030-ncjhv.18d465fc620576df,"reason=Pulled count=1 msg=Container image ""busybox:musl"" already present on machine"
0.4715,Event,ADDED,eval-conflicts-rho005-r8-030-ncjhv.18d465fc6319977e,reason=Created count=1 msg=Created container: task
0.4716,Event,ADDED,eval-conflicts-rho005-r8-030-ncjhv.18d465fc67ca9ee2,reason=Started count=1 msg=Started container task
0.4718,Event,ADDED,eval-conflicts-rho005-r8-030.18d465fc444930a1,reason=SuccessfulCreate count=1 msg=Created pod: eval-conflicts-rho005-r8-030-ncjhv
0.4723,Event,ADDED,eval-conflicts-rho005-r8-030.18d465ff4ae3e497,reason=Completed count=1 msg=Job completed
0.4726,Event,ADDED,eval-conflicts-rho005-r8-031-d945n.18d465fc80c23e9f,reason=Scheduled count=None msg=Successfully assigned compute/eval-conflicts-rho005-r8-031-d945n to kind-worker
0.4729,Event,ADDED,eval-conflicts-rho005-r8-031-d945n.18d465fc99650c0c,"reason=Pulled count=1 msg=Container image ""busybox:musl"" already present on machine"
0.4732,Event,ADDED,eval-conflicts-rho005-r8-031-d945n.18d465fc9a6cc438,reason=Created count=1 msg=Created container: task
0.4735,Event,ADDED,eval-conflicts-rho005-r8-031-d945n.18d465fc9d04702d,reason=Started count=1 msg=Started container task
0.4737,Event,ADDED,eval-conflicts-rho005-r8-031.18d465fc7f9de68f,reason=SuccessfulCreate count=1 msg=Created pod: eval-conflicts-rho005-r8-031-d945n
0.474,Event,ADDED,eval-conflicts-rho005-r8-031.18d465ffad1f5dbc,reason=Completed count=1 msg=Job completed
0.4742,Event,ADDED,eval-conflicts-rho005-r8-032-hhtzl.18d465fcbba20717,reason=Scheduled count=None msg=Successfully assigned compute/eval-conflicts-rho005-r8-032-hhtzl to kind-worker2
0.4746,Event,ADDED,eval-conflicts-rho005-r8-032-hhtzl.18d465fcd4de5878,"reason=Pulled count=1 msg=Container image ""busybox:musl"" already present on machine"
0.4748,Event,ADDED,eval-conflicts-rho005-r8-032-hhtzl.18d465fcd5e323cb,reason=Created count=1 msg=Created container: task
0.4749,Event,ADDED,eval-conflicts-rho005-r8-032-hhtzl.18d465fcd7b590ae,reason=Started count=1 msg=Started container task
0.4752,Event,ADDED,eval-conflicts-rho005-r8-032.18d465fcbace52ad,reason=SuccessfulCreate count=1 msg=Created pod: eval-conflicts-rho005-r8-032-hhtzl
0.4754,Event,ADDED,eval-conflicts-rho005-r8-032.18d465fffde5e76b,reason=Completed count=1 msg=Job completed
0.4756,Event,ADDED,eval-conflicts-rho005-r8-033-g2q72.18d465fcf79d843d,reason=Scheduled count=None msg=Successfully assigned compute/eval-conflicts-rho005-r8-033-g2q72 to kind-worker
0.4758,Event,ADDED,eval-conflicts-rho005-r8-033-g2q72.18d465fd10e6959e,"reason=Pulled count=1 msg=Container image ""busybox:musl"" already present on machine"
0.4761,Event,ADDED,eval-conflicts-rho005-r8-033-g2q72.18d465fd11ee46f9,reason=Created count=1 msg=Created container: task
0.4763,Event,ADDED,eval-conflicts-rho005-r8-033-g2q72.18d465fd13cf44d1,reason=Started count=1 msg=Started container task
0.4765,Event,ADDED,eval-conflicts-rho005-r8-033.18d465fcf6db87fa,reason=SuccessfulCreate count=1 msg=Created pod: eval-conflicts-rho005-r8-033-g2q72
0.4767,Event,ADDED,eval-conflicts-rho005-r8-033.18d4660024bad829,reason=Completed count=1 msg=Job completed
0.477,Event,ADDED,eval-conflicts-rho005-r8-034-7v5lf.18d465fd329f600f,reason=Scheduled count=None msg=Successfully assigned compute/eval-conflicts-rho005-r8-034-7v5lf to kind-worker
0.4772,Event,ADDED,eval-conflicts-rho005-r8-034-7v5lf.18d465fd4bc2f4a9,"reason=Pulled count=1 msg=Container image ""busybox:musl"" already present on machine"
0.4774,Event,ADDED,eval-conflicts-rho005-r8-034-7v5lf.18d465fd4d4abf8e,reason=Created count=1 msg=Created container: task
0.4777,Event,ADDED,eval-conflicts-rho005-r8-034-7v5lf.18d465fd560ec9ee,reason=Started count=1 msg=Started container task
0.4779,Event,ADDED,eval-conflicts-rho005-r8-034.18d465fd31b9c96c,reason=SuccessfulCreate count=1 msg=Created pod: eval-conflicts-rho005-r8-034-7v5lf
0.4781,Event,ADDED,eval-conflicts-rho005-r8-034.18d466006121934b,reason=Completed count=1 msg=Job completed
0.4782,Event,ADDED,eval-conflicts-rho005-r8-035-h8xnz.18d465fd72c639d0,reason=Scheduled count=None msg=Successfully assigned compute/eval-conflicts-rho005-r8-035-h8xnz to kind-worker
0.4786,Event,ADDED,eval-conflicts-rho005-r8-035-h8xnz.18d465fda4bad26c,"reason=Pulled count=1 msg=Container image ""busybox:musl"" already present on machine"
0.4787,Event,ADDED,eval-conflicts-rho005-r8-035-h8xnz.18d465fda5e2c5b4,reason=Created count=1 msg=Created container: task
0.4789,Event,ADDED,eval-conflicts-rho005-r8-035-h8xnz.18d465fda9e4096d,reason=Started count=1 msg=Started container task
0.4792,Event,ADDED,eval-conflicts-rho005-r8-035.18d465fd717c8273,reason=SuccessfulCreate count=1 msg=Created pod: eval-conflicts-rho005-r8-035-h8xnz
0.4793,Event,ADDED,eval-conflicts-rho005-r8-035.18d46600d925e274,reason=Completed count=1 msg=Job completed
0.4795,Event,ADDED,eval-conflicts-rho005-r8-036-tf96x.18d465fdaa0fc315,reason=Scheduled count=None msg=Successfully assigned compute/eval-conflicts-rho005-r8-036-tf96x to kind-worker2
0.4796,Event,ADDED,eval-conflicts-rho005-r8-036-tf96x.18d465fdc58447e2,"reason=Pulled count=1 msg=Container image ""busybox:musl"" already present on machine"
0.4798,Event,ADDED,eval-conflicts-rho005-r8-036-tf96x.18d465fdc698abf7,reason=Created count=1 msg=Created container: task
0.48,Event,ADDED,eval-conflicts-rho005-r8-036-tf96x.18d465fdcb1bd885,reason=Started count=1 msg=Started container task
0.4802,Event,ADDED,eval-conflicts-rho005-r8-036.18d465fda91910c4,reason=SuccessfulCreate count=1 msg=Created pod: eval-conflicts-rho005-r8-036-tf96x
0.4803,Event,ADDED,eval-conflicts-rho005-r8-036.18d46600b1c6d09a,reason=Completed count=1 msg=Job completed
0.4806,Event,ADDED,eval-conflicts-rho005-r8-037-hp5xf.18d465fdea05b413,reason=Scheduled count=None msg=Successfully assigned compute/eval-conflicts-rho005-r8-037-hp5xf to kind-worker2
0.4809,Event,ADDED,eval-conflicts-rho005-r8-037-hp5xf.18d465fe0840701a,"reason=Pulled count=1 msg=Container image ""busybox:musl"" already present on machine"
0.4811,Event,ADDED,eval-conflicts-rho005-r8-037-hp5xf.18d465fe098dae5b,reason=Created count=1 msg=Created container: task
0.4813,Event,ADDED,eval-conflicts-rho005-r8-037-hp5xf.18d465fe0e395260,reason=Started count=1 msg=Started container task
0.4815,Event,ADDED,eval-conflicts-rho005-r8-037.18d465fde95d27bd,reason=SuccessfulCreate count=1 msg=Created pod: eval-conflicts-rho005-r8-037-hp5xf
0.4819,Event,ADDED,eval-conflicts-rho005-r8-037.18d4660128e68b8e,reason=Completed count=1 msg=Job completed
0.482,Event,ADDED,eval-conflicts-rho005-r8-038-6pzbj.18d465fe25943de1,reason=Scheduled count=None msg=Successfully assigned compute/eval-conflicts-rho005-r8-038-6pzbj to kind-worker2
0.4822,Event,ADDED,eval-conflicts-rho005-r8-038-6pzbj.18d465fe4437a997,"reason=Pulled count=1 msg=Container image ""busybox:musl"" already present on machine"
0.4824,Event,ADDED,eval-conflicts-rho005-r8-038-6pzbj.18d465fe4572fed9,reason=Created count=1 msg=Created container: task
0.4826,Event,ADDED,eval-conflicts-rho005-r8-038-6pzbj.18d465fe4debf282,reason=Started count=1 msg=Started container task
0.4828,Event,ADDED,eval-conflicts-rho005-r8-038.18d465fe24a1c6f1,reason=SuccessfulCreate count=1 msg=Created pod: eval-conflicts-rho005-r8-038-6pzbj
0.483,Event,ADDED,eval-conflicts-rho005-r8-038.18d4660164ee3f28,reason=Completed count=1 msg=Job completed
0.4833,Event,ADDED,eval-conflicts-rho005-r8-039-kr8q2.18d465fe5d717fe3,"reason=FailedScheduling count=None msg=0/6 nodes are available: 6 node(s) had untolerated taint(s). no new claims to deallocate, preemption: 0/6 nodes are available: 6 Preemption is not helpful for scheduling."
0.4835,Event,ADDED,eval-conflicts-rho005-r8-039-kr8q2.18d465fe6e178806,reason=Scheduled count=None msg=Successfully assigned compute/eval-conflicts-rho005-r8-039-kr8q2 to kind-worker3
0.4837,Event,ADDED,eval-conflicts-rho005-r8-039-kr8q2.18d465fe871b021d,"reason=Pulled count=1 msg=Container image ""busybox:musl"" already present on machine"
0.4838,Event,ADDED,eval-conflicts-rho005-r8-039-kr8q2.18d465fe8833e131,reason=Created count=1 msg=Created container: task
0.4842,Event,ADDED,eval-conflicts-rho005-r8-039-kr8q2.18d465fe8a5f8b3d,reason=Started count=1 msg=Started container task
0.4844,Event,ADDED,eval-conflicts-rho005-r8-039.18d465fe5d672f5d,reason=SuccessfulCreate count=1 msg=Created pod: eval-conflicts-rho005-r8-039-kr8q2
0.4846,Event,ADDED,eval-conflicts-rho005-r8-039.18d466019a870997,reason=Completed count=1 msg=Job completed
0.4848,Event,ADDED,eval-conflicts-rho005-r8-040-bvhwd.18d465fe9f6600c2,reason=Scheduled count=None msg=Successfully assigned compute/eval-conflicts-rho005-r8-040-bvhwd to kind-worker4
0.4852,Event,ADDED,eval-conflicts-rho005-r8-040-bvhwd.18d465feb7dd9ef6,"reason=Pulled count=1 msg=Container image ""busybox:musl"" already present on machine"
0.4853,Event,ADDED,eval-conflicts-rho005-r8-040-bvhwd.18d465feb8e0f555,reason=Created count=1 msg=Created container: task
0.4855,Event,ADDED,eval-conflicts-rho005-r8-040-bvhwd.18d465febad2c53a,reason=Started count=1 msg=Started container task
0.4857,Event,ADDED,eval-conflicts-rho005-r8-040.18d465fe9bb612aa,reason=SuccessfulCreate count=1 msg=Created pod: eval-conflicts-rho005-r8-040-bvhwd
0.4859,Event,ADDED,eval-conflicts-rho005-r8-040.18d46601e824bba0,reason=Completed count=1 msg=Job completed
0.4861,Event,ADDED,eval-conflicts-rho005-r8-041-q7cdd.18d465fed3c992d4,reason=Scheduled count=None msg=Successfully assigned compute/eval-conflicts-rho005-r8-041-q7cdd to kind-worker4
0.4863,Event,ADDED,eval-conflicts-rho005-r8-041-q7cdd.18d465feecfe7bfe,"reason=Pulled count=1 msg=Container image ""busybox:musl"" already present on machine"
0.4865,Event,ADDED,eval-conflicts-rho005-r8-041-q7cdd.18d465feee046a3b,reason=Created count=1 msg=Created container: task
0.4867,Event,ADDED,eval-conflicts-rho005-r8-041-q7cdd.18d465fef0193025,reason=Started count=1 msg=Started container task
0.4868,Event,ADDED,eval-conflicts-rho005-r8-041.18d465fed2f1c7ed,reason=SuccessfulCreate count=1 msg=Created pod: eval-conflicts-rho005-r8-041-q7cdd
0.487,Event,ADDED,eval-conflicts-rho005-r8-041.18d466022403548c,reason=Completed count=1 msg=Job completed
0.4872,Event,ADDED,eval-conflicts-rho005-r8-042-wvnxs.18d465ff0f62975b,reason=Scheduled count=None msg=Successfully assigned compute/eval-conflicts-rho005-r8-042-wvnxs to kind-worker5
0.4874,Event,ADDED,eval-conflicts-rho005-r8-042-wvnxs.18d465ff280903d6,"reason=Pulled count=1 msg=Container image ""busybox:musl"" already present on machine"
0.4876,Event,ADDED,eval-conflicts-rho005-r8-042-wvnxs.18d465ff2917b34b,reason=Created count=1 msg=Created container: task
0.4879,Event,ADDED,eval-conflicts-rho005-r8-042-wvnxs.18d465ff2d59bb66,reason=Started count=1 msg=Started container task
0.4882,Event,ADDED,eval-conflicts-rho005-r8-042.18d465ff0e6ffc62,reason=SuccessfulCreate count=1 msg=Created pod: eval-conflicts-rho005-r8-042-wvnxs
0.4884,Event,ADDED,eval-conflicts-rho005-r8-042.18d4660246bb7c32,reason=Completed count=1 msg=Job completed
0.4886,Event,ADDED,eval-conflicts-rho005-r8-043-58nxw.18d465ff4b8ad961,reason=Scheduled count=None msg=Successfully assigned compute/eval-conflicts-rho005-r8-043-58nxw to kind-worker5
0.489,Event,ADDED,eval-conflicts-rho005-r8-043-58nxw.18d465ff64509b64,"reason=Pulled count=1 msg=Container image ""busybox:musl"" already present on machine"
0.4892,Event,ADDED,eval-conflicts-rho005-r8-043-58nxw.18d465ff6563a2d9,reason=Created count=1 msg=Created container: task
0.4894,Event,ADDED,eval-conflicts-rho005-r8-043-58nxw.18d465ff694c5fd1,reason=Started count=1 msg=Started container task
0.4897,Event,ADDED,eval-conflicts-rho005-r8-043.18d465ff4a2de79e,reason=SuccessfulCreate count=1 msg=Created pod: eval-conflicts-rho005-r8-043-58nxw
0.4898,Event,ADDED,eval-conflicts-rho005-r8-043.18d46602826fff0b,reason=Completed count=1 msg=Job completed
0.49,Event,ADDED,eval-conflicts-rho005-r8-044-zxwcx.18d465ff874cf1fb,reason=Scheduled count=None msg=Successfully assigned compute/eval-conflicts-rho005-r8-044-zxwcx to kind-worker5
0.4901,Event,ADDED,eval-conflicts-rho005-r8-044-zxwcx.18d465ffa068aacf,"reason=Pulled count=1 msg=Container image ""busybox:musl"" already present on machine"
0.4904,Event,ADDED,eval-conflicts-rho005-r8-044-zxwcx.18d465ffa17d5f29,reason=Created count=1 msg=Created container: task
0.4906,Event,ADDED,eval-conflicts-rho005-r8-044-zxwcx.18d465ffa3ad7fb4,reason=Started count=1 msg=Started container task
0.4908,Event,ADDED,eval-conflicts-rho005-r8-044.18d465ff85e5a64e,reason=SuccessfulCreate count=1 msg=Created pod: eval-conflicts-rho005-r8-044-zxwcx
0.491,Event,ADDED,eval-conflicts-rho005-r8-044.18d46602be698792,reason=Completed count=1 msg=Job completed
0.4911,Event,ADDED,eval-conflicts-rho005-r8-045-kdkd8.18d465ffc2b80898,reason=Scheduled count=None msg=Successfully assigned compute/eval-conflicts-rho005-r8-045-kdkd8 to kind-worker5
0.4913,Event,ADDED,eval-conflicts-rho005-r8-045-kdkd8.18d465ffdba6e5b9,"reason=Pulled count=1 msg=Container image ""busybox:musl"" already present on machine"
0.4915,Event,ADDED,eval-conflicts-rho005-r8-045-kdkd8.18d465ffdcb5d468,reason=Created count=1 msg=Created container: task
0.4917,Event,ADDED,eval-conflicts-rho005-r8-045-kdkd8.18d465ffe1230133,reason=Started count=1 msg=Started container task
0.4918,Event,ADDED,eval-conflicts-rho005-r8-045.18d465ffc181a6b8,reason=SuccessfulCreate count=1 msg=Created pod: eval-conflicts-rho005-r8-045-kdkd8
0.492,Event,ADDED,eval-conflicts-rho005-r8-045.18d46602fa3a8045,reason=Completed count=1 msg=Job completed
0.4921,Event,ADDED,eval-conflicts-rho005-r8-046-xzqxp.18d465fffe5115d9,reason=Scheduled count=None msg=Successfully assigned compute/eval-conflicts-rho005-r8-046-xzqxp to kind-worker4
0.4923,Event,ADDED,eval-conflicts-rho005-r8-046-xzqxp.18d4660017e3da6b,"reason=Pulled count=1 msg=Container image ""busybox:musl"" already present on machine"
0.4925,Event,ADDED,eval-conflicts-rho005-r8-046-xzqxp.18d4660018f63d6e,reason=Created count=1 msg=Created container: task
0.4927,Event,ADDED,eval-conflicts-rho005-r8-046-xzqxp.18d466001d2563db,reason=Started count=1 msg=Started container task
0.4928,Event,ADDED,eval-conflicts-rho005-r8-046.18d465fffd0bfba7,reason=SuccessfulCreate count=1 msg=Created pod: eval-conflicts-rho005-r8-046-xzqxp
0.493,Event,ADDED,eval-conflicts-rho005-r8-046.18d466034eea0ab9,reason=Completed count=1 msg=Job completed
0.4931,Event,ADDED,eval-conflicts-rho005-r8-047-wdc5k.18d4660039b25422,reason=Scheduled count=None msg=Successfully assigned compute/eval-conflicts-rho005-r8-047-wdc5k to kind-worker5
0.4933,Event,ADDED,eval-conflicts-rho005-r8-047-wdc5k.18d4660052f390f6,"reason=Pulled count=1 msg=Container image ""busybox:musl"" already present on machine"
0.4935,Event,ADDED,eval-conflicts-rho005-r8-047-wdc5k.18d4660054059b2e,reason=Created count=1 msg=Created container: task
0.4936,Event,ADDED,eval-conflicts-rho005-r8-047-wdc5k.18d4660056247ffc,reason=Started count=1 msg=Started container task
0.4939,Event,ADDED,eval-conflicts-rho005-r8-047.18d466003895d12e,reason=SuccessfulCreate count=1 msg=Created pod: eval-conflicts-rho005-r8-047-wdc5k
0.4941,Event,ADDED,eval-conflicts-rho005-r8-047.18d4660372197677,reason=Completed count=1 msg=Job completed
0.4945,Event,ADDED,eval-conflicts-rho005-r8-048-28qvc.18d4660075367b54,reason=Scheduled count=None msg=Successfully assigned compute/eval-conflicts-rho005-r8-048-28qvc to kind-worker3
0.4947,Event,ADDED,eval-conflicts-rho005-r8-048-28qvc.18d4660094472335,"reason=Pulled count=1 msg=Container image ""busybox:musl"" already present on machine"
0.4948,Event,ADDED,eval-conflicts-rho005-r8-048-28qvc.18d466009557274a,reason=Created count=1 msg=Created container: task
0.4951,Event,ADDED,eval-conflicts-rho005-r8-048-28qvc.18d466009a1691c8,reason=Started count=1 msg=Started container task
0.4953,Event,ADDED,eval-conflicts-rho005-r8-048.18d46600742f7cd9,reason=SuccessfulCreate count=1 msg=Created pod: eval-conflicts-rho005-r8-048-28qvc
0.4955,Event,ADDED,eval-conflicts-rho005-r8-048.18d46603b44dac7b,reason=Completed count=1 msg=Job completed
0.4957,Event,ADDED,eval-conflicts-rho005-r8-049-xjc6t.18d46600b14673ed,reason=Scheduled count=None msg=Successfully assigned compute/eval-conflicts-rho005-r8-049-xjc6t to kind-worker
0.4961,Event,ADDED,eval-conflicts-rho005-r8-049-xjc6t.18d46600cb5fe4c0,"reason=Pulled count=1 msg=Container image ""busybox:musl"" already present on machine"
0.4963,Event,ADDED,eval-conflicts-rho005-r8-049-xjc6t.18d46600cc88e027,reason=Created count=1 msg=Created container: task
0.4964,Event,ADDED,eval-conflicts-rho005-r8-049-xjc6t.18d46600ceb50521,reason=Started count=1 msg=Started container task
0.4966,Event,ADDED,eval-conflicts-rho005-r8-049.18d46600affc4360,reason=SuccessfulCreate count=1 msg=Created pod: eval-conflicts-rho005-r8-049-xjc6t
0.4969,Event,ADDED,eval-conflicts-rho005-r8-049.18d46603e39b1ca2,reason=Completed count=1 msg=Job completed
0.4971,Event,ADDED,eval-conflicts-rho005-r8-050-zm5rv.18d46600ecc6cae5,reason=Scheduled count=None msg=Successfully assigned compute/eval-conflicts-rho005-r8-050-zm5rv to kind-worker
0.4973,Event,ADDED,eval-conflicts-rho005-r8-050-zm5rv.18d46601065e53c4,"reason=Pulled count=1 msg=Container image ""busybox:musl"" already present on machine"
0.4975,Event,ADDED,eval-conflicts-rho005-r8-050-zm5rv.18d46601076ed6dd,reason=Created count=1 msg=Created container: task
0.4977,Event,ADDED,eval-conflicts-rho005-r8-050-zm5rv.18d4660109789e8c,reason=Started count=1 msg=Started container task
0.4979,Event,ADDED,eval-conflicts-rho005-r8-050.18d46600ebd86c14,reason=SuccessfulCreate count=1 msg=Created pod: eval-conflicts-rho005-r8-050-zm5rv
0.4981,Event,ADDED,eval-conflicts-rho005-r8-050.18d466041fb48aed,reason=Completed count=1 msg=Job completed
0.4984,Event,ADDED,eval-conflicts-rho005-r8-051-7sh7d.18d4660128e731a7,reason=Scheduled count=None msg=Successfully assigned compute/eval-conflicts-rho005-r8-051-7sh7d to kind-worker
0.4986,Event,ADDED,eval-conflicts-rho005-r8-051-7sh7d.18d4660141a1da83,"reason=Pulled count=1 msg=Container image ""busybox:musl"" already present on machine"
0.4987,Event,ADDED,eval-conflicts-rho005-r8-051-7sh7d.18d4660142b3945f,reason=Created count=1 msg=Created container: task
0.499,Event,ADDED,eval-conflicts-rho005-r8-051-7sh7d.18d46601449b4090,reason=Started count=1 msg=Started container task
0.4992,Event,ADDED,eval-conflicts-rho005-r8-051.18d4660127e56ef6,reason=SuccessfulCreate count=1 msg=Created pod: eval-conflicts-rho005-r8-051-7sh7d
0.4994,Event,ADDED,eval-conflicts-rho005-r8-051.18d466045b3a8bd5,reason=Completed count=1 msg=Job completed
0.4996,Event,ADDED,eval-conflicts-rho005-r8-052-s8wcx.18d46601637327ac,"reason=FailedScheduling count=None msg=0/6 nodes are available: 1 c_wall violated: 1 conflicting context pair(s) with node memory, 5 node(s) had untolerated taint(s). no new claims to deallocate, preemption: 0/6 nodes are available: 1 No preemption victims found for incoming pod, 5 Preemption is not helpful for scheduling."
0.5,Event,ADDED,eval-conflicts-rho005-r8-052-s8wcx.18d4660163eb8b7f,"reason=FailedScheduling count=None msg=0/6 nodes are available: 1 c_wall violated: 1 conflicting context pair(s) with node memory, 5 node(s) had untolerated taint(s). no new claims to deallocate, preemption: 0/6 nodes are available: 1 No preemption victims found for incoming pod, 5 Preemption is not helpful for scheduling."
0.5002,Event,ADDED,eval-conflicts-rho005-r8-052-s8wcx.18d466030a9ddf64,reason=Scheduled count=None msg=Successfully assigned compute/eval-conflicts-rho005-r8-052-s8wcx to kind-worker2
0.5004,Event,ADDED,eval-conflicts-rho005-r8-052-s8wcx.18d4660323e1b709,"reason=Pulled count=1 msg=Container image ""busybox:musl"" already present on machine"
0.5008,Event,ADDED,eval-conflicts-rho005-r8-052-s8wcx.18d466032566a12f,reason=Created count=1 msg=Created container: task
0.5009,Event,ADDED,eval-conflicts-rho005-r8-052-s8wcx.18d466032aa85bd6,reason=Started count=1 msg=Started container task
0.5011,Event,ADDED,eval-conflicts-rho005-r8-052.18d466016333ea3f,reason=SuccessfulCreate count=1 msg=Created pod: eval-conflicts-rho005-r8-052-s8wcx
0.5013,Event,ADDED,eval-conflicts-rho005-r8-052.18d466064cea096f,reason=Completed count=1 msg=Job completed
0.5016,Event,ADDED,eval-conflicts-rho005-r8-053-hwgq2.18d466019e9e37fc,reason=Scheduled count=None msg=Successfully assigned compute/eval-conflicts-rho005-r8-053-hwgq2 to kind-worker
0.5018,Event,ADDED,eval-conflicts-rho005-r8-053-hwgq2.18d46601b761eb1c,"reason=Pulled count=1 msg=Container image ""busybox:musl"" already present on machine"
0.502,Event,ADDED,eval-conflicts-rho005-r8-053-hwgq2.18d46601b8692a91,reason=Created count=1 msg=Created container: task
0.5024,Event,ADDED,eval-conflicts-rho005-r8-053-hwgq2.18d46601ba7d9fe0,reason=Started count=1 msg=Started container task
0.5025,Event,ADDED,eval-conflicts-rho005-r8-053.18d466019e2740f8,reason=SuccessfulCreate count=1 msg=Created pod: eval-conflicts-rho005-r8-053-hwgq2
0.5027,Event,ADDED,eval-conflicts-rho005-r8-053.18d46604d2cb8377,reason=Completed count=1 msg=Job completed
0.5029,Event,ADDED,eval-conflicts-rho005-r8-054-kbpz7.18d46601da7e4d21,reason=Scheduled count=None msg=Successfully assigned compute/eval-conflicts-rho005-r8-054-kbpz7 to kind-worker
0.5031,Event,ADDED,eval-conflicts-rho005-r8-054-kbpz7.18d46601f2ec4988,"reason=Pulled count=1 msg=Container image ""busybox:musl"" already present on machine"
0.5033,Event,ADDED,eval-conflicts-rho005-r8-054-kbpz7.18d46601f4041acf,reason=Created count=1 msg=Created container: task
0.5035,Event,ADDED,eval-conflicts-rho005-r8-054-kbpz7.18d46601f7b014ae,reason=Started count=1 msg=Started container task
0.5036,Event,ADDED,eval-conflicts-rho005-r8-054.18d46601d9f922ea,reason=SuccessfulCreate count=1 msg=Created pod: eval-conflicts-rho005-r8-054-kbpz7
0.5039,Event,ADDED,eval-conflicts-rho005-r8-054.18d466050df3495c,reason=Completed count=1 msg=Job completed
0.504,Event,ADDED,eval-conflicts-rho005-r8-055-ltfbc.18d466021606dca6,reason=Scheduled count=None msg=Successfully assigned compute/eval-conflicts-rho005-r8-055-ltfbc to kind-worker
0.5042,Event,ADDED,eval-conflicts-rho005-r8-055-ltfbc.18d466022f608b91,"reason=Pulled count=1 msg=Container image ""busybox:musl"" already present on machine"
0.5046,Event,ADDED,eval-conflicts-rho005-r8-055-ltfbc.18d4660230649bdd,reason=Created count=1 msg=Created container: task
0.5047,Event,ADDED,eval-conflicts-rho005-r8-055-ltfbc.18d46602334a1517,reason=Started count=1 msg=Started container task
0.5049,Event,ADDED,eval-conflicts-rho005-r8-055.18d4660215717a6c,reason=SuccessfulCreate count=1 msg=Created pod: eval-conflicts-rho005-r8-055-ltfbc
0.5051,Event,ADDED,eval-conflicts-rho005-r8-055.18d46605499f139f,reason=Completed count=1 msg=Job completed
0.5053,Event,ADDED,eval-conflicts-rho005-r8-056-x9grw.18d4660251980907,reason=Scheduled count=None msg=Successfully assigned compute/eval-conflicts-rho005-r8-056-x9grw to kind-worker
0.5055,Event,ADDED,eval-conflicts-rho005-r8-056-x9grw.18d466026b89e847,"reason=Pulled count=1 msg=Container image ""busybox:musl"" already present on machine"
0.5057,Event,ADDED,eval-conflicts-rho005-r8-056-x9grw.18d466026c9b89a1,reason=Created count=1 msg=Created container: task
0.5058,Event,ADDED,eval-conflicts-rho005-r8-056-x9grw.18d4660271b13a2f,reason=Started count=1 msg=Started container task
0.5061,Event,ADDED,eval-conflicts-rho005-r8-056.18d46602510421ef,reason=SuccessfulCreate count=1 msg=Created pod: eval-conflicts-rho005-r8-056-x9grw
0.5063,Event,ADDED,eval-conflicts-rho005-r8-056.18d466058578892e,reason=Completed count=1 msg=Job completed
0.5066,Event,ADDED,eval-conflicts-rho005-r8-057-42fkc.18d466028d149243,reason=Scheduled count=None msg=Successfully assigned compute/eval-conflicts-rho005-r8-057-42fkc to kind-worker
0.5071,Event,ADDED,eval-conflicts-rho005-r8-057-42fkc.18d46602a6233c48,"reason=Pulled count=1 msg=Container image ""busybox:musl"" already present on machine"
0.5073,Event,ADDED,eval-conflicts-rho005-r8-057-42fkc.18d46602a766f035,reason=Created count=1 msg=Created container: task
0.5075,Event,ADDED,eval-conflicts-rho005-r8-057-42fkc.18d46602a964e5fb,reason=Started count=1 msg=Started container task
0.5076,Event,ADDED,eval-conflicts-rho005-r8-057.18d466028c8d4031,reason=SuccessfulCreate count=1 msg=Created pod: eval-conflicts-rho005-r8-057-42fkc
0.508,Event,ADDED,eval-conflicts-rho005-r8-057.18d46605c0e79893,reason=Completed count=1 msg=Job completed
0.5082,Event,ADDED,eval-conflicts-rho005-r8-058-qgkfd.18d46602c92275c5,reason=Scheduled count=None msg=Successfully assigned compute/eval-conflicts-rho005-r8-058-qgkfd to kind-worker
0.5084,Event,ADDED,eval-conflicts-rho005-r8-058-qgkfd.18d46602e1f27dbb,"reason=Pulled count=1 msg=Container image ""busybox:musl"" already present on machine"
0.509,Event,ADDED,eval-conflicts-rho005-r8-058-qgkfd.18d46602e31825e4,reason=Created count=1 msg=Created container: task
0.5092,Event,ADDED,eval-conflicts-rho005-r8-058-qgkfd.18d46602e661784d,reason=Started count=1 msg=Started container task
0.5094,Event,ADDED,eval-conflicts-rho005-r8-058.18d46602c8a3400c,reason=SuccessfulCreate count=1 msg=Created pod: eval-conflicts-rho005-r8-058-qgkfd
0.5096,Event,ADDED,eval-conflicts-rho005-r8-058.18d46605fd0aca44,reason=Completed count=1 msg=Job completed
0.5103,Event,ADDED,eval-conflicts-rho005-r8-059-7rlwl.18d466030440469b,"reason=FailedScheduling count=None msg=0/6 nodes are available: 6 node(s) had untolerated taint(s). no new claims to deallocate, preemption: 0/6 nodes are available: 6 Preemption is not helpful for scheduling."
0.5105,Event,ADDED,eval-conflicts-rho005-r8-059-7rlwl.18d466030af25011,reason=Scheduled count=None msg=Successfully assigned compute/eval-conflicts-rho005-r8-059-7rlwl to kind-worker2
0.5107,Event,ADDED,eval-conflicts-rho005-r8-059-7rlwl.18d4660324337598,"reason=Pulled count=1 msg=Container image ""busybox:musl"" already present on machine"
0.511,Event,ADDED,eval-conflicts-rho005-r8-059-7rlwl.18d4660325c20ff9,reason=Created count=1 msg=Created container: task
0.5114,Event,ADDED,eval-conflicts-rho005-r8-059-7rlwl.18d466032ae372a6,reason=Started count=1 msg=Started container task
0.5116,Event,ADDED,eval-conflicts-rho005-r8-059.18d466030435a5d9,reason=SuccessfulCreate count=1 msg=Created pod: eval-conflicts-rho005-r8-059-7rlwl
0.5119,Event,ADDED,eval-conflicts-rho005-r8-059.18d466064d0ba330,reason=Completed count=1 msg=Job completed
0.5122,Event,ADDED,eval-conflicts-rho005-r8-060-k7fkt.18d46603412e2861,reason=Scheduled count=None msg=Successfully assigned compute/eval-conflicts-rho005-r8-060-k7fkt to kind-worker4
0.5124,Event,ADDED,eval-conflicts-rho005-r8-060-k7fkt.18d466035b510623,"reason=Pulled count=1 msg=Container image ""busybox:musl"" already present on machine"
0.5126,Event,ADDED,eval-conflicts-rho005-r8-060-k7fkt.18d466035c6eeecd,reason=Created count=1 msg=Created container: task
0.5128,Event,ADDED,eval-conflicts-rho005-r8-060-k7fkt.18d466036573a9b0,reason=Started count=1 msg=Started container task
0.5131,Event,ADDED,eval-conflicts-rho005-r8-060.18d4660340139b71,reason=SuccessfulCreate count=1 msg=Created pod: eval-conflicts-rho005-r8-060-k7fkt
0.5133,Event,ADDED,eval-conflicts-rho005-r8-060.18d4660693efe2ab,reason=Completed count=1 msg=Job completed
0.5135,Event,ADDED,eval-conflicts-rho005-r8-061-nh9zj.18d466037c752eee,reason=Scheduled count=None msg=Successfully assigned compute/eval-conflicts-rho005-r8-061-nh9zj to kind-worker2
0.5136,Event,ADDED,eval-conflicts-rho005-r8-061-nh9zj.18d46603959a7867,"reason=Pulled count=1 msg=Container image ""busybox:musl"" already present on machine"
0.5139,Event,ADDED,eval-conflicts-rho005-r8-061-nh9zj.18d4660396ae2057,reason=Created count=1 msg=Created container: task
0.5141,Event,ADDED,eval-conflicts-rho005-r8-061-nh9zj.18d466039b1e9334,reason=Started count=1 msg=Started container task
0.5142,Event,ADDED,eval-conflicts-rho005-r8-061.18d466037b78b969,reason=SuccessfulCreate count=1 msg=Created pod: eval-conflicts-rho005-r8-061-nh9zj
0.5145,Event,ADDED,eval-conflicts-rho005-r8-061.18d46606c4dd4560,reason=Completed count=1 msg=Job completed
0.5147,Event,ADDED,eval-conflicts-rho005-r8-062-9qdzk.18d46603b8d68ef6,reason=Scheduled count=None msg=Successfully assigned compute/eval-conflicts-rho005-r8-062-9qdzk to kind-worker5
0.5148,Event,ADDED,eval-conflicts-rho005-r8-062-9qdzk.18d46603d41cdfef,"reason=Pulled count=1 msg=Container image ""busybox:musl"" already present on machine"
0.515,Event,ADDED,eval-conflicts-rho005-r8-062-9qdzk.18d46603d547072e,reason=Created count=1 msg=Created container: task
0.5152,Event,ADDED,eval-conflicts-rho005-r8-062-9qdzk.18d46603d9be2e92,reason=Started count=1 msg=Started container task
0.5154,Event,ADDED,eval-conflicts-rho005-r8-062.18d46603b7bee152,reason=SuccessfulCreate count=1 msg=Created pod: eval-conflicts-rho005-r8-062-9qdzk
0.5156,Event,ADDED,eval-conflicts-rho005-r8-062.18d46606f307783c,reason=Completed count=1 msg=Job completed
0.5158,Event,ADDED,eval-conflicts-rho005-r8-063-fqlw4.18d46603f78fad7c,reason=Scheduled count=None msg=Successfully assigned compute/eval-conflicts-rho005-r8-063-fqlw4 to kind-worker5
0.516,Event,ADDED,eval-conflicts-rho005-r8-063-fqlw4.18d4660410f02c27,"reason=Pulled count=1 msg=Container image ""busybox:musl"" already present on machine"
0.5162,Event,ADDED,eval-conflicts-rho005-r8-063-fqlw4.18d466041206f980,reason=Created count=1 msg=Created container: task
0.5164,Event,ADDED,eval-conflicts-rho005-r8-063-fqlw4.18d4660419211ec5,reason=Started count=1 msg=Started container task
0.5166,Event,ADDED,eval-conflicts-rho005-r8-063.18d46603f66042cf,reason=SuccessfulCreate count=1 msg=Created pod: eval-conflicts-rho005-r8-063-fqlw4
0.5167,Event,ADDED,eval-conflicts-rho005-r8-063.18d466072eedbddd,reason=Completed count=1 msg=Job completed
0.5169,Event,ADDED,eval-conflicts-rho005-r8-064-87mpc.18d466042f35c66e,reason=Scheduled count=None msg=Successfully assigned compute/eval-conflicts-rho005-r8-064-87mpc to kind-worker5
0.5171,Event,ADDED,eval-conflicts-rho005-r8-064-87mpc.18d466044a853203,"reason=Pulled count=1 msg=Container image ""busybox:musl"" already present on machine"
0.5174,Event,ADDED,eval-conflicts-rho005-r8-064-87mpc.18d466044bd3fc64,reason=Created count=1 msg=Created container: task
0.5176,Event,ADDED,eval-conflicts-rho005-r8-064-87mpc.18d4660452920ca0,reason=Started count=1 msg=Started container task
0.5177,Event,ADDED,eval-conflicts-rho005-r8-064.18d466042e19d2c1,reason=SuccessfulCreate count=1 msg=Created pod: eval-conflicts-rho005-r8-064-87mpc
0.518,Event,ADDED,eval-conflicts-rho005-r8-064.18d466076b85e71d,reason=Completed count=1 msg=Job completed
0.5181,Event,ADDED,eval-conflicts-rho005-r8-065-8fvbz.18d466046a601c34,reason=Scheduled count=None msg=Successfully assigned compute/eval-conflicts-rho005-r8-065-8fvbz to kind-worker5
0.5183,Event,ADDED,eval-conflicts-rho005-r8-065-8fvbz.18d4660482d95f29,"reason=Pulled count=1 msg=Container image ""busybox:musl"" already present on machine"
0.5185,Event,ADDED,eval-conflicts-rho005-r8-065-8fvbz.18d4660483def43b,reason=Created count=1 msg=Created container: task
0.5187,Event,ADDED,eval-conflicts-rho005-r8-065-8fvbz.18d4660485cbe35f,reason=Started count=1 msg=Started container task
0.5188,Event,ADDED,eval-conflicts-rho005-r8-065.18d466046983c02f,reason=SuccessfulCreate count=1 msg=Created pod: eval-conflicts-rho005-r8-065-8fvbz
0.519,Event,ADDED,eval-conflicts-rho005-r8-065.18d46607a74b9d17,reason=Completed count=1 msg=Job completed
0.5192,Event,ADDED,eval-conflicts-rho005-r8-066-lc7z7.18d46604a62d4071,reason=Scheduled count=None msg=Successfully assigned compute/eval-conflicts-rho005-r8-066-lc7z7 to kind-worker4
0.5193,Event,ADDED,eval-conflicts-rho005-r8-066-lc7z7.18d46604bfec6221,"reason=Pulled count=1 msg=Container image ""busybox:musl"" already present on machine"
0.5195,Event,ADDED,eval-conflicts-rho005-r8-066-lc7z7.18d46604c114c2e5,reason=Created count=1 msg=Created container: task
0.5197,Event,ADDED,eval-conflicts-rho005-r8-066-lc7z7.18d46604c326d3be,reason=Started count=1 msg=Started container task
0.5199,Event,ADDED,eval-conflicts-rho005-r8-066.18d46604a50b8cc4,reason=SuccessfulCreate count=1 msg=Created pod: eval-conflicts-rho005-r8-066-lc7z7
0.5201,Event,ADDED,eval-conflicts-rho005-r8-066.18d46607fa42932b,reason=Completed count=1 msg=Job completed
0.5203,Event,ADDED,eval-conflicts-rho005-r8-067-mv24s.18d46604e1be0dcc,reason=Scheduled count=None msg=Successfully assigned compute/eval-conflicts-rho005-r8-067-mv24s to kind-worker2
0.5204,Event,ADDED,eval-conflicts-rho005-r8-067-mv24s.18d46604fbcd8d32,"reason=Pulled count=1 msg=Container image ""busybox:musl"" already present on machine"
0.5207,Event,ADDED,eval-conflicts-rho005-r8-067-mv24s.18d46604fceb49b0,reason=Created count=1 msg=Created container: task
0.5211,Event,ADDED,eval-conflicts-rho005-r8-067-mv24s.18d4660500b8d112,reason=Started count=1 msg=Started container task
0.5212,Event,ADDED,eval-conflicts-rho005-r8-067.18d46604e0a0497e,reason=SuccessfulCreate count=1 msg=Created pod: eval-conflicts-rho005-r8-067-mv24s
0.5215,Event,ADDED,eval-conflicts-rho005-r8-067.18d466082ac8bf3e,reason=Completed count=1 msg=Job completed
0.5216,Event,ADDED,eval-conflicts-rho005-r8-068-9wjdk.18d466051d619e9e,reason=Scheduled count=None msg=Successfully assigned compute/eval-conflicts-rho005-r8-068-9wjdk to kind-worker5
0.5218,Event,ADDED,eval-conflicts-rho005-r8-068-9wjdk.18d4660536e0ac47,"reason=Pulled count=1 msg=Container image ""busybox:musl"" already present on machine"
0.522,Event,ADDED,eval-conflicts-rho005-r8-068-9wjdk.18d466053816db45,reason=Created count=1 msg=Created container: task
0.5222,Event,ADDED,eval-conflicts-rho005-r8-068-9wjdk.18d466053a31e17a,reason=Started count=1 msg=Started container task
0.5224,Event,ADDED,eval-conflicts-rho005-r8-068.18d466051c311a42,reason=SuccessfulCreate count=1 msg=Created pod: eval-conflicts-rho005-r8-068-9wjdk
0.5226,Event,ADDED,eval-conflicts-rho005-r8-068.18d466085a0a45ca,reason=Completed count=1 msg=Job completed
0.5227,Event,ADDED,eval-conflicts-rho005-r8-069-mcb48.18d466055a20290b,reason=Scheduled count=None msg=Successfully assigned compute/eval-conflicts-rho005-r8-069-mcb48 to kind-worker2
0.5229,Event,ADDED,eval-conflicts-rho005-r8-069-mcb48.18d4660574ab888d,"reason=Pulled count=1 msg=Container image ""busybox:musl"" already present on machine"
0.5231,Event,ADDED,eval-conflicts-rho005-r8-069-mcb48.18d4660575d4c5b9,reason=Created count=1 msg=Created container: task
0.5233,Event,ADDED,eval-conflicts-rho005-r8-069-mcb48.18d4660577ee1a5f,reason=Started count=1 msg=Started container task
0.5237,Event,ADDED,eval-conflicts-rho005-r8-069.18d4660558d0e2b6,reason=SuccessfulCreate count=1 msg=Created pod: eval-conflicts-rho005-r8-069-mcb48
0.5239,Event,ADDED,eval-conflicts-rho005-r8-069.18d46608a1fb4dca,reason=Completed count=1 msg=Job completed
0.5241,Event,ADDED,eval-conflicts-rho005-r8-070-xhhs8.18d4660594dd0656,reason=Scheduled count=None msg=Successfully assigned compute/eval-conflicts-rho005-r8-070-xhhs8 to kind-worker5
0.5242,Event,ADDED,eval-conflicts-rho005-r8-070-xhhs8.18d46605ae110047,"reason=Pulled count=1 msg=Container image ""busybox:musl"" already present on machine"
0.5246,Event,ADDED,eval-conflicts-rho005-r8-070-xhhs8.18d46605af301614,reason=Created count=1 msg=Created container: task
0.5248,Event,ADDED,eval-conflicts-rho005-r8-070-xhhs8.18d46605b2795687,reason=Started count=1 msg=Started container task
0.525,Event,ADDED,eval-conflicts-rho005-r8-070.18d46605940a905d,reason=SuccessfulCreate count=1 msg=Created pod: eval-conflicts-rho005-r8-070-xhhs8
0.5252,Event,ADDED,eval-conflicts-rho005-r8-070.18d46608d144cad8,reason=Completed count=1 msg=Job completed
0.5254,Event,ADDED,eval-conflicts-rho005-r8-071-m8drq.18d46605cfac0fd0,reason=Scheduled count=None msg=Successfully assigned compute/eval-conflicts-rho005-r8-071-m8drq to kind-worker3
0.5256,Event,ADDED,eval-conflicts-rho005-r8-071-m8drq.18d46605e9d993b7,"reason=Pulled count=1 msg=Container image ""busybox:musl"" already present on machine"
0.5257,Event,ADDED,eval-conflicts-rho005-r8-071-m8drq.18d46605eaf809c7,reason=Created count=1 msg=Created container: task
0.5259,Event,ADDED,eval-conflicts-rho005-r8-071-m8drq.18d46605ed14b692,reason=Started count=1 msg=Started container task
0.5261,Event,ADDED,eval-conflicts-rho005-r8-071.18d46605cf246640,reason=SuccessfulCreate count=1 msg=Created pod: eval-conflicts-rho005-r8-071-m8drq
0.5262,Event,ADDED,eval-conflicts-rho005-r8-071.18d4660912a31516,reason=Completed count=1 msg=Job completed
0.5264,Event,ADDED,eval-conflicts-rho005-r8-072-bxbvd.18d466060c09adc1,"reason=FailedScheduling count=None msg=0/6 nodes are available: 1 c_wall violated: 1 conflicting context pair(s) with node memory, 5 node(s) had untolerated taint(s). no new claims to deallocate, preemption: 0/6 nodes are available: 1 No preemption victims found for incoming pod, 5 Preemption is not helpful for scheduling."
0.5266,Event,ADDED,eval-conflicts-rho005-r8-072-bxbvd.18d466060c95578d,"reason=FailedScheduling count=None msg=0/6 nodes are available: 1 c_wall violated: 1 conflicting context pair(s) with node memory, 5 node(s) had untolerated taint(s). no new claims to deallocate, preemption: 0/6 nodes are available: 1 No preemption victims found for incoming pod, 5 Preemption is not helpful for scheduling."
0.5268,Event,ADDED,eval-conflicts-rho005-r8-072-bxbvd.18d46607bdf3d8b2,reason=Scheduled count=None msg=Successfully assigned compute/eval-conflicts-rho005-r8-072-bxbvd to kind-worker
0.5269,Event,ADDED,eval-conflicts-rho005-r8-072-bxbvd.18d46607d76656c2,"reason=Pulled count=1 msg=Container image ""busybox:musl"" already present on machine"
0.5271,Event,ADDED,eval-conflicts-rho005-r8-072-bxbvd.18d46607d90b4194,reason=Created count=1 msg=Created container: task
0.5273,Event,ADDED,eval-conflicts-rho005-r8-072-bxbvd.18d46607dd9a18a4,reason=Started count=1 msg=Started container task
0.5274,Event,ADDED,eval-conflicts-rho005-r8-072.18d466060bbe92f6,reason=SuccessfulCreate count=1 msg=Created pod: eval-conflicts-rho005-r8-072-bxbvd
0.5276,Event,ADDED,eval-conflicts-rho005-r8-072.18d4660b202a5a48,reason=Completed count=1 msg=Job completed
0.5278,Event,ADDED,eval-conflicts-rho005-r8-073-9rrjs.18d46606478ff323,reason=Scheduled count=None msg=Successfully assigned compute/eval-conflicts-rho005-r8-073-9rrjs to kind-worker3
0.528,Event,ADDED,eval-conflicts-rho005-r8-073-9rrjs.18d466066007b89f,"reason=Pulled count=1 msg=Container image ""busybox:musl"" already present on machine"
0.5282,Event,ADDED,eval-conflicts-rho005-r8-073-9rrjs.18d466066124513b,reason=Created count=1 msg=Created container: task
0.5284,Event,ADDED,eval-conflicts-rho005-r8-073-9rrjs.18d4660663164202,reason=Started count=1 msg=Started container task
0.5286,Event,ADDED,eval-conflicts-rho005-r8-073.18d4660646c7e0fa,reason=SuccessfulCreate count=1 msg=Created pod: eval-conflicts-rho005-r8-073-9rrjs
0.5287,Event,ADDED,eval-conflicts-rho005-r8-073.18d466094ee2fff7,reason=Completed count=1 msg=Job completed
0.5289,Event,ADDED,eval-conflicts-rho005-r8-074-sq6kh.18d4660681e691b5,"reason=FailedScheduling count=None msg=0/6 nodes are available: 1 c_wall violated: 1 conflicting context pair(s) with node memory, 5 node(s) had untolerated taint(s). no new claims to deallocate, preemption: 0/6 nodes are available: 1 No preemption victims found for incoming pod, 5 Preemption is not helpful for scheduling."
0.5291,Event,ADDED,eval-conflicts-rho005-r8-074-sq6kh.18d4660682617f10,"reason=FailedScheduling count=None msg=0/6 nodes are available: 1 c_wall violated: 1 conflicting context pair(s) with node memory, 5 node(s) had untolerated taint(s). no new claims to deallocate, preemption: 0/6 nodes are available: 1 No preemption victims found for incoming pod, 5 Preemption is not helpful for scheduling."
0.5292,Event,ADDED,eval-conflicts-rho005-r8-074-sq6kh.18d46607bd6c702d,reason=Scheduled count=None msg=Successfully assigned compute/eval-conflicts-rho005-r8-074-sq6kh to kind-worker
0.5294,Event,ADDED,eval-conflicts-rho005-r8-074-sq6kh.18d46607d74b97b3,"reason=Pulled count=1 msg=Container image ""busybox:musl"" already present on machine"
0.5298,Event,ADDED,eval-conflicts-rho005-r8-074-sq6kh.18d46607d8d27c9e,reason=Created count=1 msg=Created container: task
0.53,Event,ADDED,eval-conflicts-rho005-r8-074-sq6kh.18d46607dd9a18ae,reason=Started count=1 msg=Started container task
0.5301,Event,ADDED,eval-conflicts-rho005-r8-074.18d4660681abd042,reason=SuccessfulCreate count=1 msg=Created pod: eval-conflicts-rho005-r8-074-sq6kh
0.5303,Event,ADDED,eval-conflicts-rho005-r8-074.18d4660b1faffdc9,reason=Completed count=1 msg=Job completed
0.5307,Event,ADDED,eval-conflicts-rho005-r8-075-z6tbb.18d46606be2fb059,reason=Scheduled count=None msg=Successfully assigned compute/eval-conflicts-rho005-r8-075-z6tbb to kind-worker3
0.531,Event,ADDED,eval-conflicts-rho005-r8-075-z6tbb.18d46606d6857af7,"reason=Pulled count=1 msg=Container image ""busybox:musl"" already present on machine"
0.5312,Event,ADDED,eval-conflicts-rho005-r8-075-z6tbb.18d46606d7964581,reason=Created count=1 msg=Created container: task
0.5316,Event,ADDED,eval-conflicts-rho005-r8-075-z6tbb.18d46606d959cccc,reason=Started count=1 msg=Started container task
0.5321,Event,ADDED,eval-conflicts-rho005-r8-075.18d46606bdbd77b2,reason=SuccessfulCreate count=1 msg=Created pod: eval-conflicts-rho005-r8-075-z6tbb
0.5325,Event,ADDED,eval-conflicts-rho005-r8-075.18d46609c712f886,reason=Completed count=1 msg=Job completed
0.533,Event,ADDED,eval-conflicts-rho005-r8-076-pj9r7.18d46606f9f3a210,reason=Scheduled count=None msg=Successfully assigned compute/eval-conflicts-rho005-r8-076-pj9r7 to kind-worker3
0.5335,Event,ADDED,eval-conflicts-rho005-r8-076-pj9r7.18d46607139fd40e,"reason=Pulled count=1 msg=Container image ""busybox:musl"" already present on machine"
0.5337,Event,ADDED,eval-conflicts-rho005-r8-076-pj9r7.18d466071517232d,reason=Created count=1 msg=Created container: task
0.5339,Event,ADDED,eval-conflicts-rho005-r8-076-pj9r7.18d4660719f5fab8,reason=Started count=1 msg=Started container task
0.5343,Event,ADDED,eval-conflicts-rho005-r8-076.18d46606f97061d8,reason=SuccessfulCreate count=1 msg=Created pod: eval-conflicts-rho005-r8-076-pj9r7
0.5348,Event,ADDED,eval-conflicts-rho005-r8-076.18d4660a3e4d959c,reason=Completed count=1 msg=Job completed
0.5351,Event,ADDED,eval-conflicts-rho005-r8-077-m7xb7.18d46607365598c5,reason=Scheduled count=None msg=Successfully assigned compute/eval-conflicts-rho005-r8-077-m7xb7 to kind-worker3
0.5354,Event,ADDED,eval-conflicts-rho005-r8-077-m7xb7.18d466074fe69e89,"reason=Pulled count=1 msg=Container image ""busybox:musl"" already present on machine"
0.5358,Event,ADDED,eval-conflicts-rho005-r8-077-m7xb7.18d4660751102cf0,reason=Created count=1 msg=Created container: task
0.536,Event,ADDED,eval-conflicts-rho005-r8-077-m7xb7.18d4660755598a21,reason=Started count=1 msg=Started container task
0.5362,Event,ADDED,eval-conflicts-rho005-r8-077.18d4660735b9ed15,reason=SuccessfulCreate count=1 msg=Created pod: eval-conflicts-rho005-r8-077-m7xb7
0.5364,Event,ADDED,eval-conflicts-rho005-r8-077.18d4660a79a940ab,reason=Completed count=1 msg=Job completed
0.5368,Event,ADDED,eval-conflicts-rho005-r8-078-dphvz.18d4660771d32374,reason=Scheduled count=None msg=Successfully assigned compute/eval-conflicts-rho005-r8-078-dphvz to kind-worker3
0.537,Event,ADDED,eval-conflicts-rho005-r8-078-dphvz.18d466078bd57f59,"reason=Pulled count=1 msg=Container image ""busybox:musl"" already present on machine"
0.5373,Event,ADDED,eval-conflicts-rho005-r8-078-dphvz.18d466078ce5712a,reason=Created count=1 msg=Created container: task
0.5377,Event,ADDED,eval-conflicts-rho005-r8-078-dphvz.18d466078eeec974,reason=Started count=1 msg=Started container task
0.5379,Event,ADDED,eval-conflicts-rho005-r8-078.18d46607714311f5,reason=SuccessfulCreate count=1 msg=Created pod: eval-conflicts-rho005-r8-078-dphvz
0.5381,Event,ADDED,eval-conflicts-rho005-r8-078.18d4660a7acfd150,reason=Completed count=1 msg=Job completed
0.5383,Event,ADDED,eval-conflicts-rho005-r8-079-rlnr8.18d46607acbd5f74,reason=Scheduled count=None msg=Successfully assigned compute/eval-conflicts-rho005-r8-079-rlnr8 to kind-worker3
0.5386,Event,ADDED,eval-conflicts-rho005-r8-079-rlnr8.18d46607c5adac9a,"reason=Pulled count=1 msg=Container image ""busybox:musl"" already present on machine"
0.5389,Event,ADDED,eval-conflicts-rho005-r8-079-rlnr8.18d46607c6b975f4,reason=Created count=1 msg=Created container: task
0.5391,Event,ADDED,eval-conflicts-rho005-r8-079-rlnr8.18d46607c89e3503,reason=Started count=1 msg=Started container task
0.5393,Event,ADDED,eval-conflicts-rho005-r8-079.18d46607ac445bc1,reason=SuccessfulCreate count=1 msg=Created pod: eval-conflicts-rho005-r8-079-rlnr8
0.5397,Event,ADDED,eval-conflicts-rho005-r8-079.18d4660af1c134ed,reason=Completed count=1 msg=Job completed
0.5399,Event,ADDED,eval-conflicts-rho005-r8-080-5ffm8.18d46607e8aa9c77,reason=Scheduled count=None msg=Successfully assigned compute/eval-conflicts-rho005-r8-080-5ffm8 to kind-worker
0.5401,Event,ADDED,eval-conflicts-rho005-r8-080-5ffm8.18d46608021fd091,"reason=Pulled count=1 msg=Container image ""busybox:musl"" already present on machine"
0.5405,Event,ADDED,eval-conflicts-rho005-r8-080-5ffm8.18d46608032b4842,reason=Created count=1 msg=Created container: task
0.5407,Event,ADDED,eval-conflicts-rho005-r8-080-5ffm8.18d4660806c76596,reason=Started count=1 msg=Started container task
0.5409,Event,ADDED,eval-conflicts-rho005-r8-080.18d46607e8110d2f,reason=SuccessfulCreate count=1 msg=Created pod: eval-conflicts-rho005-r8-080-5ffm8
0.541,Event,ADDED,eval-conflicts-rho005-r8-080.18d4660b1f91218e,reason=Completed count=1 msg=Job completed
0.5413,Event,ADDED,eval-conflicts-rho005-r8-081-5sjt4.18d4660823f064a4,reason=Scheduled count=None msg=Successfully assigned compute/eval-conflicts-rho005-r8-081-5sjt4 to kind-worker
0.5414,Event,ADDED,eval-conflicts-rho005-r8-081-5sjt4.18d466083c945e7f,"reason=Pulled count=1 msg=Container image ""busybox:musl"" already present on machine"
0.5416,Event,ADDED,eval-conflicts-rho005-r8-081-5sjt4.18d466083da2254f,reason=Created count=1 msg=Created container: task
0.5418,Event,ADDED,eval-conflicts-rho005-r8-081-5sjt4.18d466083f82bfd7,reason=Started count=1 msg=Started container task
0.542,Event,ADDED,eval-conflicts-rho005-r8-081.18d4660822f8e879,reason=SuccessfulCreate count=1 msg=Created pod: eval-conflicts-rho005-r8-081-5sjt4
0.5421,Event,ADDED,eval-conflicts-rho005-r8-081.18d4660b5b7e3a84,reason=Completed count=1 msg=Job completed
0.5423,Event,ADDED,eval-conflicts-rho005-r8-082-7x2nq.18d466085f7907d8,reason=Scheduled count=None msg=Successfully assigned compute/eval-conflicts-rho005-r8-082-7x2nq to kind-worker4
0.5425,Event,ADDED,eval-conflicts-rho005-r8-082-7x2nq.18d466087be3ff50,"reason=Pulled count=1 msg=Container image ""busybox:musl"" already present on machine"
0.5426,Event,ADDED,eval-conflicts-rho005-r8-082-7x2nq.18d466087d0eeaaa,reason=Created count=1 msg=Created container: task
0.5428,Event,ADDED,eval-conflicts-rho005-r8-082-7x2nq.18d4660881a5ea7e,reason=Started count=1 msg=Started container task
0.5431,Event,ADDED,eval-conflicts-rho005-r8-082.18d466085eefe7b3,reason=SuccessfulCreate count=1 msg=Created pod: eval-conflicts-rho005-r8-082-7x2nq
0.5433,Event,ADDED,eval-conflicts-rho005-r8-082.18d4660bb527cae3,reason=Completed count=1 msg=Job completed
0.5435,Event,ADDED,eval-conflicts-rho005-r8-083-vlsf7.18d466089b5221f2,reason=Scheduled count=None msg=Successfully assigned compute/eval-conflicts-rho005-r8-083-vlsf7 to kind-worker5
0.5437,Event,ADDED,eval-conflicts-rho005-r8-083-vlsf7.18d46608b4d56abd,"reason=Pulled count=1 msg=Container image ""busybox:musl"" already present on machine"
0.544,Event,ADDED,eval-conflicts-rho005-r8-083-vlsf7.18d46608b5ead74d,reason=Created count=1 msg=Created container: task
0.5441,Event,ADDED,eval-conflicts-rho005-r8-083-vlsf7.18d46608b7e419f2,reason=Started count=1 msg=Started container task
0.5443,Event,ADDED,eval-conflicts-rho005-r8-083.18d466089a6696b8,reason=SuccessfulCreate count=1 msg=Created pod: eval-conflicts-rho005-r8-083-vlsf7
0.5445,Event,ADDED,eval-conflicts-rho005-r8-083.18d4660bda9086e7,reason=Completed count=1 msg=Job completed
0.5448,Event,ADDED,eval-conflicts-rho005-r8-084-jpwc7.18d46608d7703f29,reason=Scheduled count=None msg=Successfully assigned compute/eval-conflicts-rho005-r8-084-jpwc7 to kind-worker5
0.5451,Event,ADDED,eval-conflicts-rho005-r8-084-jpwc7.18d46608f0c40949,"reason=Pulled count=1 msg=Container image ""busybox:musl"" already present on machine"
0.5453,Event,ADDED,eval-conflicts-rho005-r8-084-jpwc7.18d46608f1ce8bf4,reason=Created count=1 msg=Created container: task
0.5455,Event,ADDED,eval-conflicts-rho005-r8-084-jpwc7.18d46608f5ea98b4,reason=Started count=1 msg=Started container task
0.5457,Event,ADDED,eval-conflicts-rho005-r8-084.18d46608d626cff7,reason=SuccessfulCreate count=1 msg=Created pod: eval-conflicts-rho005-r8-084-jpwc7
0.5459,Event,ADDED,eval-conflicts-rho005-r8-084.18d4660bdb455a0c,reason=Completed count=1 msg=Job completed
0.5461,Event,ADDED,eval-conflicts-rho005-r8-085-99cr5.18d4660912c268a3,reason=Scheduled count=None msg=Successfully assigned compute/eval-conflicts-rho005-r8-085-99cr5 to kind-worker5
0.5464,Event,ADDED,eval-conflicts-rho005-r8-085-99cr5.18d466092b5d4f57,"reason=Pulled count=1 msg=Container image ""busybox:musl"" already present on machine"
0.5466,Event,ADDED,eval-conflicts-rho005-r8-085-99cr5.18d466092c6c5e4e,reason=Created count=1 msg=Created container: task
0.5468,Event,ADDED,eval-conflicts-rho005-r8-085-99cr5.18d466092e6bfa19,reason=Started count=1 msg=Started container task
0.5469,Event,ADDED,eval-conflicts-rho005-r8-085.18d466091185106c,reason=SuccessfulCreate count=1 msg=Created pod: eval-conflicts-rho005-r8-085-99cr5
0.5472,Event,ADDED,eval-conflicts-rho005-r8-085.18d4660c526d72c5,reason=Completed count=1 msg=Job completed
0.5474,Event,ADDED,eval-conflicts-rho005-r8-086-8hqm7.18d466094fd68efe,reason=Scheduled count=None msg=Successfully assigned compute/eval-conflicts-rho005-r8-086-8hqm7 to kind-worker5
0.5476,Event,ADDED,eval-conflicts-rho005-r8-086-8hqm7.18d4660967fc0de9,"reason=Pulled count=1 msg=Container image ""busybox:musl"" already present on machine"
0.548,Event,ADDED,eval-conflicts-rho005-r8-086-8hqm7.18d46609691f0c37,reason=Created count=1 msg=Created container: task
0.5482,Event,ADDED,eval-conflicts-rho005-r8-086-8hqm7.18d466096b293e43,reason=Started count=1 msg=Started container task
0.5485,Event,ADDED,eval-conflicts-rho005-r8-086.18d466094e4eb6ad,reason=SuccessfulCreate count=1 msg=Created pod: eval-conflicts-rho005-r8-086-8hqm7
0.5488,Event,ADDED,eval-conflicts-rho005-r8-086.18d4660c8e48f051,reason=Completed count=1 msg=Job completed
0.5492,Event,ADDED,eval-conflicts-rho005-r8-087-x59xd.18d466098a575cca,reason=Scheduled count=None msg=Successfully assigned compute/eval-conflicts-rho005-r8-087-x59xd to kind-worker
0.5494,Event,ADDED,eval-conflicts-rho005-r8-087-x59xd.18d46609a49423cf,"reason=Pulled count=1 msg=Container image ""busybox:musl"" already present on machine"
0.5495,Event,ADDED,eval-conflicts-rho005-r8-087-x59xd.18d46609a5bff1ca,reason=Created count=1 msg=Created container: task
0.5497,Event,ADDED,eval-conflicts-rho005-r8-087-x59xd.18d46609a980fc4c,reason=Started count=1 msg=Started container task
0.5501,Event,ADDED,eval-conflicts-rho005-r8-087.18d4660988f9a44d,reason=SuccessfulCreate count=1 msg=Created pod: eval-conflicts-rho005-r8-087-x59xd
0.5504,Event,ADDED,eval-conflicts-rho005-r8-087.18d4660cc21a8a66,reason=Completed count=1 msg=Job completed
0.5506,Event,ADDED,eval-conflicts-rho005-r8-088-wttbk.18d46609c5f02ca3,reason=Scheduled count=None msg=Successfully assigned compute/eval-conflicts-rho005-r8-088-wttbk to kind-worker5
0.551,Event,ADDED,eval-conflicts-rho005-r8-088-wttbk.18d46609dee667fe,"reason=Pulled count=1 msg=Container image ""busybox:musl"" already present on machine"
0.5513,Event,ADDED,eval-conflicts-rho005-r8-088-wttbk.18d46609e005f88b,reason=Created count=1 msg=Created container: task
0.5517,Event,ADDED,eval-conflicts-rho005-r8-088-wttbk.18d46609e488078e,reason=Started count=1 msg=Started container task
0.5519,Event,ADDED,eval-conflicts-rho005-r8-088.18d46609c4773d57,reason=SuccessfulCreate count=1 msg=Created pod: eval-conflicts-rho005-r8-088-wttbk
0.5523,Event,ADDED,eval-conflicts-rho005-r8-088.18d4660d05f9cc64,reason=Completed count=1 msg=Job completed
0.5525,Event,ADDED,eval-conflicts-rho005-r8-089-mrf7f.18d4660a014f5c00,reason=Scheduled count=None msg=Successfully assigned compute/eval-conflicts-rho005-r8-089-mrf7f to kind-worker4
0.5528,Event,ADDED,eval-conflicts-rho005-r8-089-mrf7f.18d4660a1ab39313,"reason=Pulled count=1 msg=Container image ""busybox:musl"" already present on machine"
0.5531,Event,ADDED,eval-conflicts-rho005-r8-089-mrf7f.18d4660a1bc91283,reason=Created count=1 msg=Created container: task
0.5535,Event,ADDED,eval-conflicts-rho005-r8-089-mrf7f.18d4660a1dc71c7c,reason=Started count=1 msg=Started container task
0.5537,Event,ADDED,eval-conflicts-rho005-r8-089.18d46609fff55787,reason=SuccessfulCreate count=1 msg=Created pod: eval-conflicts-rho005-r8-089-mrf7f
0.5539,Event,ADDED,eval-conflicts-rho005-r8-089.18d4660d58a5fb9e,reason=Completed count=1 msg=Job completed
0.5543,Event,ADDED,eval-conflicts-rho005-r8-090-sdwdf.18d4660a3c8c2f7b,reason=Scheduled count=None msg=Successfully assigned compute/eval-conflicts-rho005-r8-090-sdwdf to kind-worker2
0.5545,Event,ADDED,eval-conflicts-rho005-r8-090-sdwdf.18d4660a550b8d75,"reason=Pulled count=1 msg=Container image ""busybox:musl"" already present on machine"
0.5547,Event,ADDED,eval-conflicts-rho005-r8-090-sdwdf.18d4660a561632de,reason=Created count=1 msg=Created container: task
0.5548,Event,ADDED,eval-conflicts-rho005-r8-090-sdwdf.18d4660a5e47d666,reason=Started count=1 msg=Started container task
0.5552,Event,ADDED,eval-conflicts-rho005-r8-090.18d4660a3ba2c4dc,reason=SuccessfulCreate count=1 msg=Created pod: eval-conflicts-rho005-r8-090-sdwdf
0.5554,Event,ADDED,eval-conflicts-rho005-r8-090.18d4660d89e07b87,reason=Completed count=1 msg=Job completed
0.5556,Event,ADDED,eval-conflicts-rho005-r8-091-pxm86.18d4660a780c07de,reason=Scheduled count=None msg=Successfully assigned compute/eval-conflicts-rho005-r8-091-pxm86 to kind-worker2
0.556,Event,ADDED,eval-conflicts-rho005-r8-091-pxm86.18d4660a90e1cd1b,"reason=Pulled count=1 msg=Container image ""busybox:musl"" already present on machine"
0.5562,Event,ADDED,eval-conflicts-rho005-r8-091-pxm86.18d4660a91f3e582,reason=Created count=1 msg=Created container: task
0.5564,Event,ADDED,eval-conflicts-rho005-r8-091-pxm86.18d4660a93deadcc,reason=Started count=1 msg=Started container task
0.5565,Event,ADDED,eval-conflicts-rho005-r8-091.18d4660a772f84b2,reason=SuccessfulCreate count=1 msg=Created pod: eval-conflicts-rho005-r8-091-pxm86
0.5569,Event,ADDED,eval-conflicts-rho005-r8-091.18d4660dc6155660,reason=Completed count=1 msg=Job completed
0.5571,Event,ADDED,eval-conflicts-rho005-r8-092-tspxb.18d4660ab36e433e,reason=Scheduled count=None msg=Successfully assigned compute/eval-conflicts-rho005-r8-092-tspxb to kind-worker2
0.5573,Event,ADDED,eval-conflicts-rho005-r8-092-tspxb.18d4660acc56183c,"reason=Pulled count=1 msg=Container image ""busybox:musl"" already present on machine"
0.5575,Event,ADDED,eval-conflicts-rho005-r8-092-tspxb.18d4660acd78168b,reason=Created count=1 msg=Created container: task
0.5578,Event,ADDED,eval-conflicts-rho005-r8-092-tspxb.18d4660ad0806548,reason=Started count=1 msg=Started container task
0.558,Event,ADDED,eval-conflicts-rho005-r8-092.18d4660ab2a7dacf,reason=SuccessfulCreate count=1 msg=Created pod: eval-conflicts-rho005-r8-092-tspxb
0.5582,Event,ADDED,eval-conflicts-rho005-r8-092.18d4660e01a8a7de,reason=Completed count=1 msg=Job completed
0.5585,Event,ADDED,eval-conflicts-rho005-r8-093-rqwmp.18d4660af001988e,reason=Scheduled count=None msg=Successfully assigned compute/eval-conflicts-rho005-r8-093-rqwmp to kind-worker2
0.5586,Event,ADDED,eval-conflicts-rho005-r8-093-rqwmp.18d4660b095a1b3a,"reason=Pulled count=1 msg=Container image ""busybox:musl"" already present on machine"
0.5588,Event,ADDED,eval-conflicts-rho005-r8-093-rqwmp.18d4660b0a698a25,reason=Created count=1 msg=Created container: task
0.559,Event,ADDED,eval-conflicts-rho005-r8-093-rqwmp.18d4660b0c3c7d1c,reason=Started count=1 msg=Started container task
0.5593,Event,ADDED,eval-conflicts-rho005-r8-093.18d4660aef673346,reason=SuccessfulCreate count=1 msg=Created pod: eval-conflicts-rho005-r8-093-rqwmp
0.5596,Event,ADDED,eval-conflicts-rho005-r8-093.18d4660e3cad00bb,reason=Completed count=1 msg=Job completed
0.5599,Event,ADDED,eval-conflicts-rho005-r8-094-bf5v7.18d4660b2a9c7f5c,reason=Scheduled count=None msg=Successfully assigned compute/eval-conflicts-rho005-r8-094-bf5v7 to kind-worker2
0.5601,Event,ADDED,eval-conflicts-rho005-r8-094-bf5v7.18d4660b443ebf69,"reason=Pulled count=1 msg=Container image ""busybox:musl"" already present on machine"
0.5603,Event,ADDED,eval-conflicts-rho005-r8-094-bf5v7.18d4660b460084e8,reason=Created count=1 msg=Created container: task
0.5605,Event,ADDED,eval-conflicts-rho005-r8-094-bf5v7.18d4660b4a6c1c3c,reason=Started count=1 msg=Started container task
0.5606,Event,ADDED,eval-conflicts-rho005-r8-094.18d4660b2a041627,reason=SuccessfulCreate count=1 msg=Created pod: eval-conflicts-rho005-r8-094-bf5v7
0.5608,Event,ADDED,eval-conflicts-rho005-r8-094.18d4660e788bf933,reason=Completed count=1 msg=Job completed
0.561,Event,ADDED,eval-conflicts-rho005-r8-095-bc75v.18d4660b66ab98f6,reason=Scheduled count=None msg=Successfully assigned compute/eval-conflicts-rho005-r8-095-bc75v to kind-worker2
0.5611,Event,ADDED,eval-conflicts-rho005-r8-095-bc75v.18d4660b7fec455f,"reason=Pulled count=1 msg=Container image ""busybox:musl"" already present on machine"
0.5613,Event,ADDED,eval-conflicts-rho005-r8-095-bc75v.18d4660b80f835c7,reason=Created count=1 msg=Created container: task
0.5615,Event,ADDED,eval-conflicts-rho005-r8-095-bc75v.18d4660b82ea34e9,reason=Started count=1 msg=Started container task
0.5616,Event,ADDED,eval-conflicts-rho005-r8-095.18d4660b65b423d7,reason=SuccessfulCreate count=1 msg=Created pod: eval-conflicts-rho005-r8-095-bc75v
0.5618,Event,ADDED,eval-conflicts-rho005-r8-095.18d4660eb44b44df,reason=Completed count=1 msg=Job completed
0.562,Event,ADDED,eval-conflicts-rho005-r8-096-8dwmd.18d4660ba382b81b,reason=Scheduled count=None msg=Successfully assigned compute/eval-conflicts-rho005-r8-096-8dwmd to kind-worker2
0.5622,Event,ADDED,eval-conflicts-rho005-r8-096-8dwmd.18d4660bbe933a70,"reason=Pulled count=1 msg=Container image ""busybox:musl"" already present on machine"
0.5624,Event,ADDED,eval-conflicts-rho005-r8-096-8dwmd.18d4660bbfb6a932,reason=Created count=1 msg=Created container: task
0.5626,Event,ADDED,eval-conflicts-rho005-r8-096-8dwmd.18d4660bc52c7f59,reason=Started count=1 msg=Started container task
0.5628,Event,ADDED,eval-conflicts-rho005-r8-096.18d4660ba2e9c93d,reason=SuccessfulCreate count=1 msg=Created pod: eval-conflicts-rho005-r8-096-8dwmd
0.5629,Event,ADDED,eval-conflicts-rho005-r8-096.18d4660ef040787b,reason=Completed count=1 msg=Job completed
0.5631,Event,ADDED,eval-conflicts-rho005-r8-097-ccx9s.18d4660be270dffa,reason=Scheduled count=None msg=Successfully assigned compute/eval-conflicts-rho005-r8-097-ccx9s to kind-worker2
0.5632,Event,ADDED,eval-conflicts-rho005-r8-097-ccx9s.18d4660bfce3274d,"reason=Pulled count=1 msg=Container image ""busybox:musl"" already present on machine"
0.5634,Event,ADDED,eval-conflicts-rho005-r8-097-ccx9s.18d4660bfe0f8a73,reason=Created count=1 msg=Created container: task
0.5636,Event,ADDED,eval-conflicts-rho005-r8-097-ccx9s.18d4660c004c640c,reason=Started count=1 msg=Started container task
0.5638,Event,ADDED,eval-conflicts-rho005-r8-097.18d4660be1d0f7ae,reason=SuccessfulCreate count=1 msg=Created pod: eval-conflicts-rho005-r8-097-ccx9s
0.5641,Event,ADDED,eval-conflicts-rho005-r8-097.18d4660f2bf6f230,reason=Completed count=1 msg=Job completed
0.5643,Event,ADDED,eval-conflicts-rho005-r8-098-6c2gc.18d4660c19084e62,"reason=FailedScheduling count=None msg=0/6 nodes are available: 1 c_wall violated: 1 conflicting context pair(s) with node memory, 5 node(s) had untolerated taint(s). no new claims to deallocate, preemption: 0/6 nodes are available: 1 No preemption victims found for incoming pod, 5 Preemption is not helpful for scheduling."
0.5645,Event,ADDED,eval-conflicts-rho005-r8-098-6c2gc.18d4660c1981a2ab,"reason=FailedScheduling count=None msg=0/6 nodes are available: 1 c_wall violated: 1 conflicting context pair(s) with node memory, 5 node(s) had untolerated taint(s). no new claims to deallocate, preemption: 0/6 nodes are available: 1 No preemption victims found for incoming pod, 5 Preemption is not helpful for scheduling."
0.5647,Event,ADDED,eval-conflicts-rho005-r8-098-6c2gc.18d4660c7d9438f0,reason=Scheduled count=None msg=Successfully assigned compute/eval-conflicts-rho005-r8-098-6c2gc to kind-worker
0.5651,Event,ADDED,eval-conflicts-rho005-r8-098-6c2gc.18d4660c960e541d,"reason=Pulled count=1 msg=Container image ""busybox:musl"" already present on machine"
0.5653,Event,ADDED,eval-conflicts-rho005-r8-098-6c2gc.18d4660c9719a2b7,reason=Created count=1 msg=Created container: task
0.5654,Event,ADDED,eval-conflicts-rho005-r8-098-6c2gc.18d4660c9c463dff,reason=Started count=1 msg=Started container task
0.5658,Event,ADDED,eval-conflicts-rho005-r8-098.18d4660c18c89ff8,reason=SuccessfulCreate count=1 msg=Created pod: eval-conflicts-rho005-r8-098-6c2gc
0.566,Event,ADDED,eval-conflicts-rho005-r8-098.18d4660fcad42f8a,reason=Completed count=1 msg=Job completed
0.5661,Event,ADDED,eval-conflicts-rho005-r8-099-d5qt9.18d4660c54dc9e7a,reason=Scheduled count=None msg=Successfully assigned compute/eval-conflicts-rho005-r8-099-d5qt9 to kind-worker2
0.5663,Event,ADDED,eval-conflicts-rho005-r8-099-d5qt9.18d4660c6f35ee02,"reason=Pulled count=1 msg=Container image ""busybox:musl"" already present on machine"
0.5665,Event,ADDED,eval-conflicts-rho005-r8-099-d5qt9.18d4660c705794c7,reason=Created count=1 msg=Created container: task
0.5667,Event,ADDED,eval-conflicts-rho005-r8-099-d5qt9.18d4660c7424e9ee,reason=Started count=1 msg=Started container task
0.5669,Event,ADDED,eval-conflicts-rho005-r8-099.18d4660c546924cb,reason=SuccessfulCreate count=1 msg=Created pod: eval-conflicts-rho005-r8-099-d5qt9
0.5671,Event,ADDED,eval-conflicts-rho005-r8-099.18d4660fa3c4b404,reason=Completed count=1 msg=Job completed
0.5672,Event,ADDED,eval-conflicts-rho005-r9-000-7dbm9.18d4661500902d71,reason=Scheduled count=None msg=Successfully assigned compute/eval-conflicts-rho005-r9-000-7dbm9 to kind-worker
0.5675,Event,ADDED,eval-conflicts-rho005-r9-000-7dbm9.18d466151a44481b,"reason=Pulled count=1 msg=Container image ""busybox:musl"" already present on machine"
0.5678,Event,ADDED,eval-conflicts-rho005-r9-000-7dbm9.18d466151b798536,reason=Created count=1 msg=Created container: task
0.5681,Event,ADDED,eval-conflicts-rho005-r9-000-7dbm9.18d466151d9ae0bf,reason=Started count=1 msg=Started container task
0.5682,Event,ADDED,eval-conflicts-rho005-r9-000.18d46614ff96a2a2,reason=SuccessfulCreate count=1 msg=Created pod: eval-conflicts-rho005-r9-000-7dbm9
0.5684,Event,ADDED,eval-conflicts-rho005-r9-000.18d4661831434bd7,reason=Completed count=1 msg=Job completed
0.5686,Event,ADDED,eval-conflicts-rho005-r9-001-bs46x.18d466153be5f025,reason=Scheduled count=None msg=Successfully assigned compute/eval-conflicts-rho005-r9-001-bs46x to kind-worker
0.5688,Event,ADDED,eval-conflicts-rho005-r9-001-bs46x.18d46615557dbc6d,"reason=Pulled count=1 msg=Container image ""busybox:musl"" already present on machine"
0.5689,Event,ADDED,eval-conflicts-rho005-r9-001-bs46x.18d4661556a6ed2d,reason=Created count=1 msg=Created container: task
0.5693,Event,ADDED,eval-conflicts-rho005-r9-001-bs46x.18d466155885f972,reason=Started count=1 msg=Started container task
0.5695,Event,ADDED,eval-conflicts-rho005-r9-001.18d466153ad7177a,reason=SuccessfulCreate count=1 msg=Created pod: eval-conflicts-rho005-r9-001-bs46x
0.5697,Event,ADDED,eval-conflicts-rho005-r9-001.18d466186dd6f766,reason=Completed count=1 msg=Job completed
0.5699,Event,ADDED,eval-conflicts-rho005-r9-002-4k8nz.18d46615773f1640,reason=Scheduled count=None msg=Successfully assigned compute/eval-conflicts-rho005-r9-002-4k8nz to kind-worker2
0.5701,Event,ADDED,eval-conflicts-rho005-r9-002-4k8nz.18d4661591b8dc19,"reason=Pulled count=1 msg=Container image ""busybox:musl"" already present on machine"
0.5703,Event,ADDED,eval-conflicts-rho005-r9-002-4k8nz.18d4661592d4b916,reason=Created count=1 msg=Created container: task
0.5704,Event,ADDED,eval-conflicts-rho005-r9-002-4k8nz.18d46615950276b1,reason=Started count=1 msg=Started container task
0.5706,Event,ADDED,eval-conflicts-rho005-r9-002.18d46615768d8f89,reason=SuccessfulCreate count=1 msg=Created pod: eval-conflicts-rho005-r9-002-4k8nz
0.5708,Event,ADDED,eval-conflicts-rho005-r9-002.18d46618bf5c7702,reason=Completed count=1 msg=Job completed
0.5709,Event,ADDED,eval-conflicts-rho005-r9-003-4ljhm.18d46615b3b6307e,reason=Scheduled count=None msg=Successfully assigned compute/eval-conflicts-rho005-r9-003-4ljhm to kind-worker5
0.5711,Event,ADDED,eval-conflicts-rho005-r9-003-4ljhm.18d46615ccabadbe,"reason=Pulled count=1 msg=Container image ""busybox:musl"" already present on machine"
0.5713,Event,ADDED,eval-conflicts-rho005-r9-003-4ljhm.18d46615cdc9b465,reason=Created count=1 msg=Created container: task
0.5714,Event,ADDED,eval-conflicts-rho005-r9-003-4ljhm.18d46615cfca6454,reason=Started count=1 msg=Started container task
0.5716,Event,ADDED,eval-conflicts-rho005-r9-003.18d46615b28f4550,reason=SuccessfulCreate count=1 msg=Created pod: eval-conflicts-rho005-r9-003-4ljhm
0.5718,Event,ADDED,eval-conflicts-rho005-r9-003.18d46618ee5b1562,reason=Completed count=1 msg=Job completed
0.572,Event,ADDED,eval-conflicts-rho005-r9-004-znrdg.18d46615f26448aa,reason=Scheduled count=None msg=Successfully assigned compute/eval-conflicts-rho005-r9-004-znrdg to kind-worker5
0.5722,Event,ADDED,eval-conflicts-rho005-r9-004-znrdg.18d466160b924157,"reason=Pulled count=1 msg=Container image ""busybox:musl"" already present on machine"
0.5724,Event,ADDED,eval-conflicts-rho005-r9-004-znrdg.18d466160cb250ba,reason=Created count=1 msg=Created container: task
0.5725,Event,ADDED,eval-conflicts-rho005-r9-004-znrdg.18d466160eb3b292,reason=Started count=1 msg=Started container task
0.5727,Event,ADDED,eval-conflicts-rho005-r9-004.18d46615ecd4d03e,reason=SuccessfulCreate count=1 msg=Created pod: eval-conflicts-rho005-r9-004-znrdg
0.573,Event,ADDED,eval-conflicts-rho005-r9-004.18d466192a9dba4b,reason=Completed count=1 msg=Job completed
0.5731,Event,ADDED,eval-conflicts-rho005-r9-005-nxwvv.18d4661629763bcd,reason=Scheduled count=None msg=Successfully assigned compute/eval-conflicts-rho005-r9-005-nxwvv to kind-worker5
0.5733,Event,ADDED,eval-conflicts-rho005-r9-005-nxwvv.18d4661642bcd10b,"reason=Pulled count=1 msg=Container image ""busybox:musl"" already present on machine"
0.5736,Event,ADDED,eval-conflicts-rho005-r9-005-nxwvv.18d4661643c7ba4e,reason=Created count=1 msg=Created container: task
0.5739,Event,ADDED,eval-conflicts-rho005-r9-005-nxwvv.18d4661645f58094,reason=Started count=1 msg=Started container task
0.5741,Event,ADDED,eval-conflicts-rho005-r9-005.18d4661628a3f45b,reason=SuccessfulCreate count=1 msg=Created pod: eval-conflicts-rho005-r9-005-nxwvv
0.5742,Event,ADDED,eval-conflicts-rho005-r9-005.18d4661966595881,reason=Completed count=1 msg=Job completed
0.5744,Event,ADDED,eval-conflicts-rho005-r9-006-jm2n5.18d4661664c5d5dd,reason=Scheduled count=None msg=Successfully assigned compute/eval-conflicts-rho005-r9-006-jm2n5 to kind-worker4
0.5746,Event,ADDED,eval-conflicts-rho005-r9-006-jm2n5.18d466167e76e6d2,"reason=Pulled count=1 msg=Container image ""busybox:musl"" already present on machine"
0.5748,Event,ADDED,eval-conflicts-rho005-r9-006-jm2n5.18d466167f8343b6,reason=Created count=1 msg=Created container: task
0.5749,Event,ADDED,eval-conflicts-rho005-r9-006-jm2n5.18d46616817a5da7,reason=Started count=1 msg=Started container task
0.5751,Event,ADDED,eval-conflicts-rho005-r9-006.18d4661664188eed,reason=SuccessfulCreate count=1 msg=Created pod: eval-conflicts-rho005-r9-006-jm2n5
0.5753,Event,ADDED,eval-conflicts-rho005-r9-006.18d46619b552ef1d,reason=Completed count=1 msg=Job completed
0.5754,Event,ADDED,eval-conflicts-rho005-r9-007-wghst.18d46616a02e876b,reason=Scheduled count=None msg=Successfully assigned compute/eval-conflicts-rho005-r9-007-wghst to kind-worker4
0.5756,Event,ADDED,eval-conflicts-rho005-r9-007-wghst.18d46616b9bad8fc,"reason=Pulled count=1 msg=Container image ""busybox:musl"" already present on machine"
0.5758,Event,ADDED,eval-conflicts-rho005-r9-007-wghst.18d46616badf1668,reason=Created count=1 msg=Created container: task
0.576,Event,ADDED,eval-conflicts-rho005-r9-007-wghst.18d46616bf15f2f9,reason=Started count=1 msg=Started container task
0.5762,Event,ADDED,eval-conflicts-rho005-r9-007.18d466169f725347,reason=SuccessfulCreate count=1 msg=Created pod: eval-conflicts-rho005-r9-007-wghst
0.5764,Event,ADDED,eval-conflicts-rho005-r9-007.18d46619f168ee50,reason=Completed count=1 msg=Job completed
0.5766,Event,ADDED,eval-conflicts-rho005-r9-008-x8qvh.18d46616dc019a02,reason=Scheduled count=None msg=Successfully assigned compute/eval-conflicts-rho005-r9-008-x8qvh to kind-worker4
0.5767,Event,ADDED,eval-conflicts-rho005-r9-008-x8qvh.18d46616f3f83e86,"reason=Pulled count=1 msg=Container image ""busybox:musl"" already present on machine"
0.577,Event,ADDED,eval-conflicts-rho005-r9-008-x8qvh.18d46616f51007ad,reason=Created count=1 msg=Created container: task
0.5771,Event,ADDED,eval-conflicts-rho005-r9-008-x8qvh.18d46616f711973b,reason=Started count=1 msg=Started container task
0.5773,Event,ADDED,eval-conflicts-rho005-r9-008.18d46616db3feda6,reason=SuccessfulCreate count=1 msg=Created pod: eval-conflicts-rho005-r9-008-x8qvh
0.5775,Event,ADDED,eval-conflicts-rho005-r9-008.18d4661a2d45eb0f,reason=Completed count=1 msg=Job completed
0.5776,Event,ADDED,eval-conflicts-rho005-r9-009-wsg5q.18d46617180d18c7,reason=Scheduled count=None msg=Successfully assigned compute/eval-conflicts-rho005-r9-009-wsg5q to kind-worker4
0.5778,Event,ADDED,eval-conflicts-rho005-r9-009-wsg5q.18d4661731a3e5a8,"reason=Pulled count=1 msg=Container image ""busybox:musl"" already present on machine"
0.578,Event,ADDED,eval-conflicts-rho005-r9-009-wsg5q.18d4661732b5be1e,reason=Created count=1 msg=Created container: task
0.5782,Event,ADDED,eval-conflicts-rho005-r9-009-wsg5q.18d46617371bc5dd,reason=Started count=1 msg=Started container task
0.5783,Event,ADDED,eval-conflicts-rho005-r9-009.18d4661717439c5a,reason=SuccessfulCreate count=1 msg=Created pod: eval-conflicts-rho005-r9-009-wsg5q
0.5785,Event,ADDED,eval-conflicts-rho005-r9-009.18d4661a69027e71,reason=Completed count=1 msg=Job completed
0.5786,Event,ADDED,eval-conflicts-rho005-r9-010-btfdq.18d4661753f0b461,reason=Scheduled count=None msg=Successfully assigned compute/eval-conflicts-rho005-r9-010-btfdq to kind-worker3
0.5788,Event,ADDED,eval-conflicts-rho005-r9-010-btfdq.18d466176d34e116,"reason=Pulled count=1 msg=Container image ""busybox:musl"" already present on machine"
0.579,Event,ADDED,eval-conflicts-rho005-r9-010-btfdq.18d466176e5eff35,reason=Created count=1 msg=Created container: task
0.5791,Event,ADDED,eval-conflicts-rho005-r9-010-btfdq.18d46617706afe55,reason=Started count=1 msg=Started container task
0.5793,Event,ADDED,eval-conflicts-rho005-r9-010.18d4661752f2856a,reason=SuccessfulCreate count=1 msg=Created pod: eval-conflicts-rho005-r9-010-btfdq
0.5798,Event,ADDED,eval-conflicts-rho005-r9-010.18d4661a58e49c2e,reason=Completed count=1 msg=Job completed
0.58,Event,ADDED,eval-conflicts-rho005-r9-011-4kwsx.18d4661790c9e2d8,reason=Scheduled count=None msg=Successfully assigned compute/eval-conflicts-rho005-r9-011-4kwsx to kind-worker3
0.5802,Event,ADDED,eval-conflicts-rho005-r9-011-4kwsx.18d46617a9ba3d0d,"reason=Pulled count=1 msg=Container image ""busybox:musl"" already present on machine"
0.5805,Event,ADDED,eval-conflicts-rho005-r9-011-4kwsx.18d46617ab1ff2b7,reason=Created count=1 msg=Created container: task
0.5807,Event,ADDED,eval-conflicts-rho005-r9-011-4kwsx.18d46617ad0170db,reason=Started count=1 msg=Started container task
0.5809,Event,ADDED,eval-conflicts-rho005-r9-011.18d466178de2f498,reason=SuccessfulCreate count=1 msg=Created pod: eval-conflicts-rho005-r9-011-4kwsx
0.581,Event,ADDED,eval-conflicts-rho005-r9-011.18d4661a94918f0c,reason=Completed count=1 msg=Job completed
0.5813,Event,ADDED,eval-conflicts-rho005-r9-012-6p8d7.18d46617cb4f6943,reason=Scheduled count=None msg=Successfully assigned compute/eval-conflicts-rho005-r9-012-6p8d7 to kind-worker4
0.5815,Event,ADDED,eval-conflicts-rho005-r9-012-6p8d7.18d46617e45d73f0,"reason=Pulled count=1 msg=Container image ""busybox:musl"" already present on machine"
0.5817,Event,ADDED,eval-conflicts-rho005-r9-012-6p8d7.18d46617e587a4da,reason=Created count=1 msg=Created container: task
0.5819,Event,ADDED,eval-conflicts-rho005-r9-012-6p8d7.18d46617e77268da,reason=Started count=1 msg=Started container task
0.5821,Event,ADDED,eval-conflicts-rho005-r9-012.18d46617ca6c28de,reason=SuccessfulCreate count=1 msg=Created pod: eval-conflicts-rho005-r9-012-6p8d7
0.5822,Event,ADDED,eval-conflicts-rho005-r9-012.18d4661b1c4798fa,reason=Completed count=1 msg=Job completed
0.5824,Event,ADDED,eval-conflicts-rho005-r9-013-vbrns.18d4661806420fcc,reason=Scheduled count=None msg=Successfully assigned compute/eval-conflicts-rho005-r9-013-vbrns to kind-worker3
0.5826,Event,ADDED,eval-conflicts-rho005-r9-013-vbrns.18d466181ffcca79,"reason=Pulled count=1 msg=Container image ""busybox:musl"" already present on machine"
0.5827,Event,ADDED,eval-conflicts-rho005-r9-013-vbrns.18d46618210a40e7,reason=Created count=1 msg=Created container: task
0.5829,Event,ADDED,eval-conflicts-rho005-r9-013-vbrns.18d46618231bf855,reason=Started count=1 msg=Started container task
0.5831,Event,ADDED,eval-conflicts-rho005-r9-013.18d4661805726513,reason=SuccessfulCreate count=1 msg=Created pod: eval-conflicts-rho005-r9-013-vbrns
0.5832,Event,ADDED,eval-conflicts-rho005-r9-013.18d4661b0c4d5ecb,reason=Completed count=1 msg=Job completed
0.5834,Event,ADDED,eval-conflicts-rho005-r9-014-nrwbd.18d466184293025f,reason=Scheduled count=None msg=Successfully assigned compute/eval-conflicts-rho005-r9-014-nrwbd to kind-worker3
0.5836,Event,ADDED,eval-conflicts-rho005-r9-014-nrwbd.18d466185bbd1e03,"reason=Pulled count=1 msg=Container image ""busybox:musl"" already present on machine"
0.5838,Event,ADDED,eval-conflicts-rho005-r9-014-nrwbd.18d466185d08570b,reason=Created count=1 msg=Created container: task
0.584,Event,ADDED,eval-conflicts-rho005-r9-014-nrwbd.18d46618612232d7,reason=Started count=1 msg=Started container task
0.5842,Event,ADDED,eval-conflicts-rho005-r9-014.18d4661841cd31fe,reason=SuccessfulCreate count=1 msg=Created pod: eval-conflicts-rho005-r9-014-nrwbd
0.5843,Event,ADDED,eval-conflicts-rho005-r9-014.18d4661b484ebc28,reason=Completed count=1 msg=Job completed
0.5846,Event,ADDED,eval-conflicts-rho005-r9-015-l99l6.18d466187cc22e47,reason=Scheduled count=None msg=Successfully assigned compute/eval-conflicts-rho005-r9-015-l99l6 to kind-worker
0.5848,Event,ADDED,eval-conflicts-rho005-r9-015-l99l6.18d4661895edaf7c,"reason=Pulled count=1 msg=Container image ""busybox:musl"" already present on machine"
0.5849,Event,ADDED,eval-conflicts-rho005-r9-015-l99l6.18d466189700e756,reason=Created count=1 msg=Created container: task
0.5851,Event,ADDED,eval-conflicts-rho005-r9-015-l99l6.18d4661899027fa8,reason=Started count=1 msg=Started container task
0.5853,Event,ADDED,eval-conflicts-rho005-r9-015.18d466187c4ea59a,reason=SuccessfulCreate count=1 msg=Created pod: eval-conflicts-rho005-r9-015-l99l6
0.5854,Event,ADDED,eval-conflicts-rho005-r9-015.18d4661bb218c54a,reason=Completed count=1 msg=Job completed
0.5856,Event,ADDED,eval-conflicts-rho005-r9-016-vckwn.18d46618b8af5a33,reason=Scheduled count=None msg=Successfully assigned compute/eval-conflicts-rho005-r9-016-vckwn to kind-worker2
0.5889,Event,ADDED,eval-conflicts-rho005-r9-016-vckwn.18d46618d26a2382,"reason=Pulled count=1 msg=Container image ""busybox:musl"" already present on machine"
0.5891,Event,ADDED,eval-conflicts-rho005-r9-016-vckwn.18d46618d37f5c25,reason=Created count=1 msg=Created container: task
0.5893,Event,ADDED,eval-conflicts-rho005-r9-016-vckwn.18d46618d7a31603,reason=Started count=1 msg=Started container task
0.5895,Event,ADDED,eval-conflicts-rho005-r9-016.18d46618b81efdf9,reason=SuccessfulCreate count=1 msg=Created pod: eval-conflicts-rho005-r9-016-vckwn
0.5897,Event,ADDED,eval-conflicts-rho005-r9-016.18d4661c020d30e1,reason=Completed count=1 msg=Job completed
0.5899,Event,ADDED,eval-conflicts-rho005-r9-017-5lfj4.18d46618f44c1d80,reason=Scheduled count=None msg=Successfully assigned compute/eval-conflicts-rho005-r9-017-5lfj4 to kind-worker
0.59,Event,ADDED,eval-conflicts-rho005-r9-017-5lfj4.18d466190e25787c,"reason=Pulled count=1 msg=Container image ""busybox:musl"" already present on machine"
0.5902,Event,ADDED,eval-conflicts-rho005-r9-017-5lfj4.18d466190f4eff45,reason=Created count=1 msg=Created container: task
0.5904,Event,ADDED,eval-conflicts-rho005-r9-017-5lfj4.18d4661912a22660,reason=Started count=1 msg=Started container task
0.5905,Event,ADDED,eval-conflicts-rho005-r9-017.18d46618f36ee4f8,reason=SuccessfulCreate count=1 msg=Created pod: eval-conflicts-rho005-r9-017-5lfj4
0.5907,Event,ADDED,eval-conflicts-rho005-r9-017.18d4661c29b8d3ae,reason=Completed count=1 msg=Job completed
0.5908,Event,ADDED,eval-conflicts-rho005-r9-018-f4nzd.18d4661930d2a9e9,reason=Scheduled count=None msg=Successfully assigned compute/eval-conflicts-rho005-r9-018-f4nzd to kind-worker5
0.591,Event,ADDED,eval-conflicts-rho005-r9-018-f4nzd.18d466194a6487ae,"reason=Pulled count=1 msg=Container image ""busybox:musl"" already present on machine"
0.5912,Event,ADDED,eval-conflicts-rho005-r9-018-f4nzd.18d466194b785d1a,reason=Created count=1 msg=Created container: task
0.5913,Event,ADDED,eval-conflicts-rho005-r9-018-f4nzd.18d4661952785d41,reason=Started count=1 msg=Started container task
0.5915,Event,ADDED,eval-conflicts-rho005-r9-018.18d4661930176f44,reason=SuccessfulCreate count=1 msg=Created pod: eval-conflicts-rho005-r9-018-f4nzd
0.5917,Event,ADDED,eval-conflicts-rho005-r9-018.18d4661c6e0fdfd1,reason=Completed count=1 msg=Job completed
0.5919,Event,ADDED,eval-conflicts-rho005-r9-019-79jlq.18d466196be22f15,reason=Scheduled count=None msg=Successfully assigned compute/eval-conflicts-rho005-r9-019-79jlq to kind-worker5
0.5921,Event,ADDED,eval-conflicts-rho005-r9-019-79jlq.18d46619852b3830,"reason=Pulled count=1 msg=Container image ""busybox:musl"" already present on machine"
0.5923,Event,ADDED,eval-conflicts-rho005-r9-019-79jlq.18d4661986356ef4,reason=Created count=1 msg=Created container: task
0.5925,Event,ADDED,eval-conflicts-rho005-r9-019-79jlq.18d466198b5fdca5,reason=Started count=1 msg=Started container task
0.5926,Event,ADDED,eval-conflicts-rho005-r9-019.18d466196abb9299,reason=SuccessfulCreate count=1 msg=Created pod: eval-conflicts-rho005-r9-019-79jlq
0.5928,Event,ADDED,eval-conflicts-rho005-r9-019.18d4661ca9f8f5c8,reason=Completed count=1 msg=Job completed
0.593,Event,ADDED,eval-conflicts-rho005-r9-020-h7452.18d46619a896baf6,reason=Scheduled count=None msg=Successfully assigned compute/eval-conflicts-rho005-r9-020-h7452 to kind-worker5
0.5931,Event,ADDED,eval-conflicts-rho005-r9-020-h7452.18d46619c1d17eb8,"reason=Pulled count=1 msg=Container image ""busybox:musl"" already present on machine"
0.5933,Event,ADDED,eval-conflicts-rho005-r9-020-h7452.18d46619c2e48e9c,reason=Created count=1 msg=Created container: task
0.5935,Event,ADDED,eval-conflicts-rho005-r9-020-h7452.18d46619c4fd7338,reason=Started count=1 msg=Started container task
0.5936,Event,ADDED,eval-conflicts-rho005-r9-020.18d46619a747cacd,reason=SuccessfulCreate count=1 msg=Created pod: eval-conflicts-rho005-r9-020-h7452
0.5938,Event,ADDED,eval-conflicts-rho005-r9-020.18d4661ce7c01bdb,reason=Completed count=1 msg=Job completed
0.5939,Event,ADDED,eval-conflicts-rho005-r9-021-mcjtk.18d46619e45d4e76,reason=Scheduled count=None msg=Successfully assigned compute/eval-conflicts-rho005-r9-021-mcjtk to kind-worker2
0.5941,Event,ADDED,eval-conflicts-rho005-r9-021-mcjtk.18d46619fd8305da,"reason=Pulled count=1 msg=Container image ""busybox:musl"" already present on machine"
0.5943,Event,ADDED,eval-conflicts-rho005-r9-021-mcjtk.18d46619fea9e151,reason=Created count=1 msg=Created container: task
0.5944,Event,ADDED,eval-conflicts-rho005-r9-021-mcjtk.18d4661a035c5c58,reason=Started count=1 msg=Started container task
0.5946,Event,ADDED,eval-conflicts-rho005-r9-021.18d46619e322315b,reason=SuccessfulCreate count=1 msg=Created pod: eval-conflicts-rho005-r9-021-mcjtk
0.5948,Event,ADDED,eval-conflicts-rho005-r9-021.18d4661d2c764209,reason=Completed count=1 msg=Job completed
0.5949,Event,ADDED,eval-conflicts-rho005-r9-022-452sx.18d4661a1f43a197,reason=Scheduled count=None msg=Successfully assigned compute/eval-conflicts-rho005-r9-022-452sx to kind-worker5
0.5951,Event,ADDED,eval-conflicts-rho005-r9-022-452sx.18d4661a387b28a1,"reason=Pulled count=1 msg=Container image ""busybox:musl"" already present on machine"
0.5952,Event,ADDED,eval-conflicts-rho005-r9-022-452sx.18d4661a39b9fb99,reason=Created count=1 msg=Created container: task
0.5954,Event,ADDED,eval-conflicts-rho005-r9-022-452sx.18d4661a3bdbc08c,reason=Started count=1 msg=Started container task
0.5956,Event,ADDED,eval-conflicts-rho005-r9-022.18d4661a1e329226,reason=SuccessfulCreate count=1 msg=Created pod: eval-conflicts-rho005-r9-022-452sx
0.5958,Event,ADDED,eval-conflicts-rho005-r9-022.18d4661d5d407575,reason=Completed count=1 msg=Job completed
0.596,Event,ADDED,eval-conflicts-rho005-r9-023-smrtr.18d4661a5adc211d,reason=Scheduled count=None msg=Successfully assigned compute/eval-conflicts-rho005-r9-023-smrtr to kind-worker
0.5962,Event,ADDED,eval-conflicts-rho005-r9-023-smrtr.18d4661a73cf621e,"reason=Pulled count=1 msg=Container image ""busybox:musl"" already present on machine"
0.5964,Event,ADDED,eval-conflicts-rho005-r9-023-smrtr.18d4661a74e77d76,reason=Created count=1 msg=Created container: task
0.5966,Event,ADDED,eval-conflicts-rho005-r9-023-smrtr.18d4661a76d9b9fc,reason=Started count=1 msg=Started container task
0.5968,Event,ADDED,eval-conflicts-rho005-r9-023.18d4661a5998a5f0,reason=SuccessfulCreate count=1 msg=Created pod: eval-conflicts-rho005-r9-023-smrtr
0.597,Event,ADDED,eval-conflicts-rho005-r9-023.18d4661d9065014a,reason=Completed count=1 msg=Job completed
0.5971,Event,ADDED,eval-conflicts-rho005-r9-024-9nhxl.18d4661a9692c7a4,reason=Scheduled count=None msg=Successfully assigned compute/eval-conflicts-rho005-r9-024-9nhxl to kind-worker2
0.5973,Event,ADDED,eval-conflicts-rho005-r9-024-9nhxl.18d4661aaf386fcf,"reason=Pulled count=1 msg=Container image ""busybox:musl"" already present on machine"
0.5976,Event,ADDED,eval-conflicts-rho005-r9-024-9nhxl.18d4661ab0444938,reason=Created count=1 msg=Created container: task
0.5977,Event,ADDED,eval-conflicts-rho005-r9-024-9nhxl.18d4661ab251e8ed,reason=Started count=1 msg=Started container task
0.5979,Event,ADDED,eval-conflicts-rho005-r9-024.18d4661a95540ff3,reason=SuccessfulCreate count=1 msg=Created pod: eval-conflicts-rho005-r9-024-9nhxl
0.5981,Event,ADDED,eval-conflicts-rho005-r9-024.18d4661de68b2fd8,reason=Completed count=1 msg=Job completed
0.5984,Event,ADDED,eval-conflicts-rho005-r9-025-m5vc8.18d4661ad158c347,reason=Scheduled count=None msg=Successfully assigned compute/eval-conflicts-rho005-r9-025-m5vc8 to kind-worker4
0.5986,Event,ADDED,eval-conflicts-rho005-r9-025-m5vc8.18d4661aeadf4b3e,"reason=Pulled count=1 msg=Container image ""busybox:musl"" already present on machine"
0.5988,Event,ADDED,eval-conflicts-rho005-r9-025-m5vc8.18d4661aebf4d132,reason=Created count=1 msg=Created container: task
0.5993,Event,ADDED,eval-conflicts-rho005-r9-025-m5vc8.18d4661aee66bccd,reason=Started count=1 msg=Started container task
0.5995,Event,ADDED,eval-conflicts-rho005-r9-025.18d4661ad09400cd,reason=SuccessfulCreate count=1 msg=Created pod: eval-conflicts-rho005-r9-025-m5vc8
0.5997,Event,ADDED,eval-conflicts-rho005-r9-025.18d4661e25c8284b,reason=Completed count=1 msg=Job completed
0.5999,Event,ADDED,eval-conflicts-rho005-r9-026-945d8.18d4661b0d28620a,reason=Scheduled count=None msg=Successfully assigned compute/eval-conflicts-rho005-r9-026-945d8 to kind-worker5
0.6003,Event,ADDED,eval-conflicts-rho005-r9-026-945d8.18d4661b25cae83f,"reason=Pulled count=1 msg=Container image ""busybox:musl"" already present on machine"
0.6005,Event,ADDED,eval-conflicts-rho005-r9-026-945d8.18d4661b26db9409,reason=Created count=1 msg=Created container: task
0.6007,Event,ADDED,eval-conflicts-rho005-r9-026-945d8.18d4661b2b6f878b,reason=Started count=1 msg=Started container task
0.6009,Event,ADDED,eval-conflicts-rho005-r9-026.18d4661b0c2bd08d,reason=SuccessfulCreate count=1 msg=Created pod: eval-conflicts-rho005-r9-026-945d8
0.6012,Event,ADDED,eval-conflicts-rho005-r9-026.18d4661e50eef10c,reason=Completed count=1 msg=Job completed
0.6013,Event,ADDED,eval-conflicts-rho005-r9-027-9c8sq.18d4661b48b2f700,reason=Scheduled count=None msg=Successfully assigned compute/eval-conflicts-rho005-r9-027-9c8sq to kind-worker4
0.6015,Event,ADDED,eval-conflicts-rho005-r9-027-9c8sq.18d4661b621d881a,"reason=Pulled count=1 msg=Container image ""busybox:musl"" already present on machine"
0.6017,Event,ADDED,eval-conflicts-rho005-r9-027-9c8sq.18d4661b6328221e,reason=Created count=1 msg=Created container: task
0.6019,Event,ADDED,eval-conflicts-rho005-r9-027-9c8sq.18d4661b65238a40,reason=Started count=1 msg=Started container task
0.602,Event,ADDED,eval-conflicts-rho005-r9-027.18d4661b47c51649,reason=SuccessfulCreate count=1 msg=Created pod: eval-conflicts-rho005-r9-027-9c8sq
0.6022,Event,ADDED,eval-conflicts-rho005-r9-027.18d4661e9d1927c9,reason=Completed count=1 msg=Job completed
0.6023,Event,ADDED,eval-conflicts-rho005-r9-028-ldmrf.18d4661b84af1958,reason=Scheduled count=None msg=Successfully assigned compute/eval-conflicts-rho005-r9-028-ldmrf to kind-worker4
0.6025,Event,ADDED,eval-conflicts-rho005-r9-028-ldmrf.18d4661b9da59af9,"reason=Pulled count=1 msg=Container image ""busybox:musl"" already present on machine"
0.6027,Event,ADDED,eval-conflicts-rho005-r9-028-ldmrf.18d4661b9eba8f27,reason=Created count=1 msg=Created container: task
0.6028,Event,ADDED,eval-conflicts-rho005-r9-028-ldmrf.18d4661ba2dc7eac,reason=Started count=1 msg=Started container task
0.603,Event,ADDED,eval-conflicts-rho005-r9-028.18d4661b8412c946,reason=SuccessfulCreate count=1 msg=Created pod: eval-conflicts-rho005-r9-028-ldmrf
0.6032,Event,ADDED,eval-conflicts-rho005-r9-028.18d4661edab1faea,reason=Completed count=1 msg=Job completed
0.6033,Event,ADDED,eval-conflicts-rho005-r9-029-fp8b4.18d4661bbf7ecc40,reason=Scheduled count=None msg=Successfully assigned compute/eval-conflicts-rho005-r9-029-fp8b4 to kind-worker4
0.6035,Event,ADDED,eval-conflicts-rho005-r9-029-fp8b4.18d4661bd8a641f7,"reason=Pulled count=1 msg=Container image ""busybox:musl"" already present on machine"
0.6037,Event,ADDED,eval-conflicts-rho005-r9-029-fp8b4.18d4661bd9b798ef,reason=Created count=1 msg=Created container: task
0.6039,Event,ADDED,eval-conflicts-rho005-r9-029-fp8b4.18d4661bdb8c505f,reason=Started count=1 msg=Started container task
0.6041,Event,ADDED,eval-conflicts-rho005-r9-029.18d4661bbf073982,reason=SuccessfulCreate count=1 msg=Created pod: eval-conflicts-rho005-r9-029-fp8b4
0.6044,Event,ADDED,eval-conflicts-rho005-r9-029.18d4661f16cf93fa,reason=Completed count=1 msg=Job completed
0.6045,Event,ADDED,eval-conflicts-rho005-r9-030-dvnpp.18d4661bfb718721,reason=Scheduled count=None msg=Successfully assigned compute/eval-conflicts-rho005-r9-030-dvnpp to kind-worker4
0.6047,Event,ADDED,eval-conflicts-rho005-r9-030-dvnpp.18d4661c13ff84e0,"reason=Pulled count=1 msg=Container image ""busybox:musl"" already present on machine"
0.6052,Event,ADDED,eval-conflicts-rho005-r9-030-dvnpp.18d4661c1512f92b,reason=Created count=1 msg=Created container: task
0.6053,Event,ADDED,eval-conflicts-rho005-r9-030-dvnpp.18d4661c1925e2dd,reason=Started count=1 msg=Started container task
0.6055,Event,ADDED,eval-conflicts-rho005-r9-030.18d4661bfaef0188,reason=SuccessfulCreate count=1 msg=Created pod: eval-conflicts-rho005-r9-030-dvnpp
0.6057,Event,ADDED,eval-conflicts-rho005-r9-030.18d4661f529d17d1,reason=Completed count=1 msg=Job completed
0.6058,Event,ADDED,eval-conflicts-rho005-r9-031-hhbsj.18d4661c36ad98ce,reason=Scheduled count=None msg=Successfully assigned compute/eval-conflicts-rho005-r9-031-hhbsj to kind-worker4
0.606,Event,ADDED,eval-conflicts-rho005-r9-031-hhbsj.18d4661c4ebd7e1a,"reason=Pulled count=1 msg=Container image ""busybox:musl"" already present on machine"
0.6061,Event,ADDED,eval-conflicts-rho005-r9-031-hhbsj.18d4661c4fc5f067,reason=Created count=1 msg=Created container: task
0.6063,Event,ADDED,eval-conflicts-rho005-r9-031-hhbsj.18d4661c5443d4ab,reason=Started count=1 msg=Started container task
0.6065,Event,ADDED,eval-conflicts-rho005-r9-031.18d4661c362a37f5,reason=SuccessfulCreate count=1 msg=Created pod: eval-conflicts-rho005-r9-031-hhbsj
0.6066,Event,ADDED,eval-conflicts-rho005-r9-031.18d4661f8e45cdac,reason=Completed count=1 msg=Job completed
0.6068,Event,ADDED,eval-conflicts-rho005-r9-032-8txmn.18d4661c72197fb8,reason=Scheduled count=None msg=Successfully assigned compute/eval-conflicts-rho005-r9-032-8txmn to kind-worker4
0.6069,Event,ADDED,eval-conflicts-rho005-r9-032-8txmn.18d4661c8bfd44a5,"reason=Pulled count=1 msg=Container image ""busybox:musl"" already present on machine"
0.6071,Event,ADDED,eval-conflicts-rho005-r9-032-8txmn.18d4661c8d0d3974,reason=Created count=1 msg=Created container: task
0.6073,Event,ADDED,eval-conflicts-rho005-r9-032-8txmn.18d4661c9180b84c,reason=Started count=1 msg=Started container task
0.6074,Event,ADDED,eval-conflicts-rho005-r9-032.18d4661c71846222,reason=SuccessfulCreate count=1 msg=Created pod: eval-conflicts-rho005-r9-032-8txmn
0.6076,Event,ADDED,eval-conflicts-rho005-r9-032.18d4661fcb0dbc09,reason=Completed count=1 msg=Job completed
0.6078,Event,ADDED,eval-conflicts-rho005-r9-033-xw9jh.18d4661cada6c07b,reason=Scheduled count=None msg=Successfully assigned compute/eval-conflicts-rho005-r9-033-xw9jh to kind-worker4
0.608,Event,ADDED,eval-conflicts-rho005-r9-033-xw9jh.18d4661cc85625d5,"reason=Pulled count=1 msg=Container image ""busybox:musl"" already present on machine"
0.6082,Event,ADDED,eval-conflicts-rho005-r9-033-xw9jh.18d4661cc970a87d,reason=Created count=1 msg=Created container: task
0.6085,Event,ADDED,eval-conflicts-rho005-r9-033-xw9jh.18d4661cce234d4b,reason=Started count=1 msg=Started container task
0.6086,Event,ADDED,eval-conflicts-rho005-r9-033.18d4661cad1cb0fa,reason=SuccessfulCreate count=1 msg=Created pod: eval-conflicts-rho005-r9-033-xw9jh
0.6088,Event,ADDED,eval-conflicts-rho005-r9-033.18d466200775ede4,reason=Completed count=1 msg=Job completed
0.6092,Event,ADDED,eval-conflicts-rho005-r9-034-7glbv.18d4661cea48ca89,reason=Scheduled count=None msg=Successfully assigned compute/eval-conflicts-rho005-r9-034-7glbv to kind-worker4
0.6094,Event,ADDED,eval-conflicts-rho005-r9-034-7glbv.18d4661d06b2690c,"reason=Pulled count=1 msg=Container image ""busybox:musl"" already present on machine"
0.6096,Event,ADDED,eval-conflicts-rho005-r9-034-7glbv.18d4661d08036a91,reason=Created count=1 msg=Created container: task
0.6098,Event,ADDED,eval-conflicts-rho005-r9-034-7glbv.18d4661d0d1e974c,reason=Started count=1 msg=Started container task
0.61,Event,ADDED,eval-conflicts-rho005-r9-034.18d4661ce9a88f06,reason=SuccessfulCreate count=1 msg=Created pod: eval-conflicts-rho005-r9-034-7glbv
