t_recv,kind,type,name,detail
0.02,Node,ADDED,kind-control-plane,taints=1
0.0214,Node,ADDED,kind-worker,taints=0
0.0226,Node,ADDED,kind-worker2,taints=0
0.0239,Node,ADDED,kind-worker3,taints=0
0.025,Node,ADDED,kind-worker4,taints=0
0.0266,Node,ADDED,kind-worker5,taints=0
0.0392,TaskRequest,ADDED,eval-conflicts-rho060-r3-000,phase=None job=None
0.0431,TaskRequest,MODIFIED,eval-conflicts-rho060-r3-000,phase=Pending job=None
0.0516,Event,ADDED,eval-conflicts-rho040-r0-018-67fqd.18d52f2ac14f61ce,"reason=FailedScheduling count=None msg=0/6 nodes are available: 3 c_wall violated: 1 conflicting context pair(s) with node memory, 3 node(s) had untolerated taint(s). no new claims to deallocate, preemption: 0/6 nodes are available: 3 No preemption victims found for incoming pod, 3 Preemption is not helpful for scheduling."
0.0525,Event,ADDED,eval-conflicts-rho040-r0-018-67fqd.18d52f2ba3994628,"reason=FailedScheduling count=None msg=0/6 nodes are available: 2 c_wall violated: 1 conflicting context pair(s) with node memory, 4 node(s) had untolerated taint(s). no new claims to deallocate, preemption: 0/6 nodes are available: 2 No preemption victims found for incoming pod, 4 Preemption is not helpful for scheduling."
0.0531,Event,ADDED,eval-conflicts-rho040-r0-018-67fqd.18d52f2bbfc0e743,"reason=FailedScheduling count=None msg=0/6 nodes are available: 1 c_wall violated: 1 conflicting context pair(s) with node memory, 5 node(s) had untolerated taint(s). no new claims to deallocate, preemption: 0/6 nodes are available: 1 No preemption victims found for incoming pod, 5 Preemption is not helpful for scheduling."
0.0535,Event,ADDED,eval-conflicts-rho040-r0-022-lwdfj.18d52f2baf663e1b,"reason=FailedScheduling count=None msg=0/6 nodes are available: 1 c_wall violated: 1 conflicting context pair(s) with node memory, 1 c_wall violated: 2 conflicting context pair(s) with node memory, 4 node(s) had untolerated taint(s). no new claims to deallocate, preemption: 0/6 nodes are available: 2 No preemption victims found for incoming pod, 4 Preemption is not helpful for scheduling."
0.0541,Event,ADDED,eval-conflicts-rho040-r0-022-lwdfj.18d52f2bbff2100c,"reason=FailedScheduling count=None msg=0/6 nodes are available: 1 c_wall violated: 1 conflicting context pair(s) with node memory, 5 node(s) had untolerated taint(s). no new claims to deallocate, preemption: 0/6 nodes are available: 1 No preemption victims found for incoming pod, 5 Preemption is not helpful for scheduling."
0.0543,Event,ADDED,eval-conflicts-rho040-r0-023-dzxw6.18d52f2d310db7f2,"reason=FailedScheduling count=None msg=0/6 nodes are available: 1 c_wall violated: 3 conflicting context pair(s) with node memory, 5 node(s) had untolerated taint(s). no new claims to deallocate, preemption: 0/6 nodes are available: 1 No preemption victims found for incoming pod, 5 Preemption is not helpful for scheduling."
0.0548,Event,ADDED,eval-conflicts-rho040-r0-027-pd82v.18d52f2d2dfea16a,"reason=FailedScheduling count=None msg=0/6 nodes are available: 1 c_wall violated: 1 conflicting context pair(s) with node memory, 5 node(s) had untolerated taint(s). no new claims to deallocate, preemption: 0/6 nodes are available: 1 No preemption victims found for incoming pod, 5 Preemption is not helpful for scheduling."
0.055,Event,ADDED,eval-conflicts-rho040-r0-028-qmxft.18d52f2d2e31ecf5,"reason=FailedScheduling count=None msg=0/6 nodes are available: 1 c_wall violated: 3 conflicting context pair(s) with node memory, 5 node(s) had untolerated taint(s). no new claims to deallocate, preemption: 0/6 nodes are available: 1 No preemption victims found for incoming pod, 5 Preemption is not helpful for scheduling."
0.0552,Event,ADDED,eval-conflicts-rho040-r0-032-fd9md.18d52f2e00d5bc26,"reason=FailedScheduling count=None msg=0/6 nodes are available: 1 c_wall violated: 3 conflicting context pair(s) with node memory, 5 node(s) had untolerated taint(s). no new claims to deallocate, preemption: 0/6 nodes are available: 1 No preemption victims found for incoming pod, 5 Preemption is not helpful for scheduling."
0.0556,Event,ADDED,eval-conflicts-rho040-r0-033-x2jf4.18d52f2e414f639a,"reason=FailedScheduling count=None msg=0/6 nodes are available: 1 c_wall violated: 3 conflicting context pair(s) with node memory, 5 node(s) had untolerated taint(s). no new claims to deallocate, preemption: 0/6 nodes are available: 1 No preemption victims found for incoming pod, 5 Preemption is not helpful for scheduling."
0.0558,Event,ADDED,eval-conflicts-rho040-r0-035-vfln2.18d52f2eba1657b6,"reason=FailedScheduling count=None msg=0/6 nodes are available: 1 c_wall violated: 1 conflicting context pair(s) with node memory, 5 node(s) had untolerated taint(s). no new claims to deallocate, preemption: 0/6 nodes are available: 1 No preemption victims found for incoming pod, 5 Preemption is not helpful for scheduling."
0.056,Event,ADDED,eval-conflicts-rho040-r0-037-hjmnr.18d52f2f2df0a103,"reason=FailedScheduling count=None msg=0/6 nodes are available: 1 c_wall violated: 3 conflicting context pair(s) with node memory, 5 node(s) had untolerated taint(s). no new claims to deallocate, preemption: 0/6 nodes are available: 1 No preemption victims found for incoming pod, 5 Preemption is not helpful for scheduling."
0.0564,Event,ADDED,eval-conflicts-rho040-r0-038-hvgrx.18d52f2f6680caf2,"reason=FailedScheduling count=None msg=0/6 nodes are available: 1 c_wall violated: 3 conflicting context pair(s) with node memory, 5 node(s) had untolerated taint(s). no new claims to deallocate, preemption: 0/6 nodes are available: 1 No preemption victims found for incoming pod, 5 Preemption is not helpful for scheduling."
0.0566,Event,ADDED,eval-conflicts-rho040-r0-039-hz7gr.18d52f2fa5018ebe,"reason=FailedScheduling count=None msg=0/6 nodes are available: 1 c_wall violated: 1 conflicting context pair(s) with node memory, 5 node(s) had untolerated taint(s). no new claims to deallocate, preemption: 0/6 nodes are available: 1 No preemption victims found for incoming pod, 5 Preemption is not helpful for scheduling."
0.0568,Event,ADDED,eval-conflicts-rho040-r0-040-k8vlb.18d52f2fe1022999,"reason=FailedScheduling count=None msg=0/6 nodes are available: 1 c_wall violated: 3 conflicting context pair(s) with node memory, 5 node(s) had untolerated taint(s). no new claims to deallocate, preemption: 0/6 nodes are available: 1 No preemption victims found for incoming pod, 5 Preemption is not helpful for scheduling."
0.0572,Event,ADDED,eval-conflicts-rho040-r0-055.18d52f38f58d4fef,reason=Completed count=1 msg=Job completed
0.0574,Event,ADDED,eval-conflicts-rho040-r0-056.18d52f39604c1589,reason=Completed count=1 msg=Job completed
0.0576,Event,ADDED,eval-conflicts-rho040-r0-057.18d52f396e90f4f9,reason=Completed count=1 msg=Job completed
0.0578,Event,ADDED,eval-conflicts-rho040-r0-058.18d52f39aa53a6ec,reason=Completed count=1 msg=Job completed
0.0582,Event,ADDED,eval-conflicts-rho040-r0-059.18d52f39ffe08bda,reason=Completed count=1 msg=Job completed
0.0584,Event,ADDED,eval-conflicts-rho040-r0-060-hjjsl.18d52f348f03bd60,reason=Scheduled count=None msg=Successfully assigned compute/eval-conflicts-rho040-r0-060-hjjsl to kind-worker3
0.0586,Event,ADDED,eval-conflicts-rho040-r0-060.18d52f3a3cdf6b59,reason=Completed count=1 msg=Job completed
0.059,Event,ADDED,eval-conflicts-rho040-r0-061-qxjj7.18d52f34c1c43604,reason=Scheduled count=None msg=Successfully assigned compute/eval-conflicts-rho040-r0-061-qxjj7 to kind-worker5
0.0592,Event,ADDED,eval-conflicts-rho040-r0-061.18d52f3a5e29aad0,reason=Completed count=1 msg=Job completed
0.0593,Event,ADDED,eval-conflicts-rho040-r0-062-xxcnk.18d52f34fe4f52e8,reason=Scheduled count=None msg=Successfully assigned compute/eval-conflicts-rho040-r0-062-xxcnk to kind-worker3
0.0595,Event,ADDED,eval-conflicts-rho040-r0-062.18d52f3ab9ee351f,reason=Completed count=1 msg=Job completed
0.0598,Event,ADDED,eval-conflicts-rho040-r0-063-9pfw4.18d52f3539e3be88,"reason=FailedScheduling count=None msg=0/6 nodes are available: 1 c_wall violated: 1 conflicting context pair(s) with node memory, 1 c_wall violated: 2 conflicting context pair(s) with node memory, 4 node(s) had untolerated taint(s). no new claims to deallocate, preemption: 0/6 nodes are available: 2 No preemption victims found for incoming pod, 4 Preemption is not helpful for scheduling."
0.06,Event,ADDED,eval-conflicts-rho040-r0-063-9pfw4.18d52f353a91d5ef,"reason=FailedScheduling count=None msg=0/6 nodes are available: 1 c_wall violated: 1 conflicting context pair(s) with node memory, 1 c_wall violated: 2 conflicting context pair(s) with node memory, 4 node(s) had untolerated taint(s). no new claims to deallocate, preemption: 0/6 nodes are available: 2 No preemption victims found for incoming pod, 4 Preemption is not helpful for scheduling."
0.0602,Event,ADDED,eval-conflicts-rho040-r0-063-9pfw4.18d52f354fe50fc9,"reason=FailedScheduling count=None msg=0/6 nodes are available: 1 c_wall violated: 2 conflicting context pair(s) with node memory, 5 node(s) had untolerated taint(s). no new claims to deallocate, preemption: 0/6 nodes are available: 1 No preemption victims found for incoming pod, 5 Preemption is not helpful for scheduling."
0.0606,Event,ADDED,eval-conflicts-rho040-r0-063-9pfw4.18d52f357aa779fc,"reason=FailedScheduling count=None msg=0/6 nodes are available: 1 c_wall violated: 3 conflicting context pair(s) with node memory, 5 node(s) had untolerated taint(s). no new claims to deallocate, preemption: 0/6 nodes are available: 1 No preemption victims found for incoming pod, 5 Preemption is not helpful for scheduling."
0.0608,Event,ADDED,eval-conflicts-rho040-r0-063-9pfw4.18d52f369d87b669,"reason=FailedScheduling count=None msg=0/6 nodes are available: 1 c_wall violated: 1 conflicting context pair(s) with node memory, 1 c_wall violated: 3 conflicting context pair(s) with node memory, 4 node(s) had untolerated taint(s). no new claims to deallocate, preemption: 0/6 nodes are available: 2 No preemption victims found for incoming pod, 4 Preemption is not helpful for scheduling."
0.061,Event,ADDED,eval-conflicts-rho040-r0-063-9pfw4.18d52f36b7eff528,"reason=FailedScheduling count=None msg=0/6 nodes are available: 1 c_wall violated: 1 conflicting context pair(s) with node memory, 5 node(s) had untolerated taint(s). no new claims to deallocate, preemption: 0/6 nodes are available: 1 No preemption victims found for incoming pod, 5 Preemption is not helpful for scheduling."
0.0614,Event,ADDED,eval-conflicts-rho040-r0-063-9pfw4.18d52f371b36b584,"reason=FailedScheduling count=None msg=0/6 nodes are available: 1 c_wall violated: 2 conflicting context pair(s) with node memory, 5 node(s) had untolerated taint(s). no new claims to deallocate, preemption: 0/6 nodes are available: 1 No preemption victims found for incoming pod, 5 Preemption is not helpful for scheduling."
0.0616,Event,ADDED,eval-conflicts-rho040-r0-063-9pfw4.18d52f3881fb2f81,"reason=FailedScheduling count=None msg=0/6 nodes are available: 1 c_wall violated: 3 conflicting context pair(s) with node memory, 5 node(s) had untolerated taint(s). no new claims to deallocate, preemption: 0/6 nodes are available: 1 No preemption victims found for incoming pod, 5 Preemption is not helpful for scheduling."
0.0618,Event,ADDED,eval-conflicts-rho040-r0-063-9pfw4.18d52f39dd043431,"reason=FailedScheduling count=None msg=0/6 nodes are available: 1 c_wall violated: 1 conflicting context pair(s) with node memory, 1 c_wall violated: 3 conflicting context pair(s) with node memory, 4 node(s) had untolerated taint(s). no new claims to deallocate, preemption: 0/6 nodes are available: 2 No preemption victims found for incoming pod, 4 Preemption is not helpful for scheduling."
0.062,Event,ADDED,eval-conflicts-rho040-r0-063-9pfw4.18d52f39f5e035fc,reason=Scheduled count=None msg=Successfully assigned compute/eval-conflicts-rho040-r0-063-9pfw4 to kind-worker
0.0622,Event,ADDED,eval-conflicts-rho040-r0-063-9pfw4.18d52f3a1190c936,"reason=Pulled count=1 msg=Container image ""busybox:musl"" already present on machine"
0.0625,Event,ADDED,eval-conflicts-rho040-r0-063-9pfw4.18d52f3a129ebd1c,reason=Created count=1 msg=Created container: task
0.0635,Job,ADDED,eval-conflicts-rho060-r3-000,
0.0638,Event,ADDED,eval-conflicts-rho040-r0-063-9pfw4.18d52f3a1b168716,reason=Started count=1 msg=Started container task
0.064,Event,ADDED,eval-conflicts-rho040-r0-063.18d52f3f864bf7a2,reason=Completed count=1 msg=Job completed
0.0641,Event,ADDED,eval-conflicts-rho040-r0-064-9kvzt.18d52f35771a4ffc,reason=Scheduled count=None msg=Successfully assigned compute/eval-conflicts-rho040-r0-064-9kvzt to kind-worker3
0.0643,Event,ADDED,eval-conflicts-rho040-r0-064.18d52f3b375a8a60,reason=Completed count=1 msg=Job completed
0.0646,Event,ADDED,eval-conflicts-rho040-r0-065-fsc2f.18d52f35aed7c0b0,"reason=FailedScheduling count=None msg=0/6 nodes are available: 1 c_wall violated: 2 conflicting context pair(s) with node memory, 5 node(s) had untolerated taint(s). no new claims to deallocate, preemption: 0/6 nodes are available: 1 No preemption victims found for incoming pod, 5 Preemption is not helpful for scheduling."
0.0648,Event,ADDED,eval-conflicts-rho040-r0-065-fsc2f.18d52f35af57155c,"reason=FailedScheduling count=None msg=0/6 nodes are available: 1 c_wall violated: 2 conflicting context pair(s) with node memory, 5 node(s) had untolerated taint(s). no new claims to deallocate, preemption: 0/6 nodes are available: 1 No preemption victims found for incoming pod, 5 Preemption is not helpful for scheduling."
0.0652,Event,ADDED,eval-conflicts-rho040-r0-065-fsc2f.18d52f36a0ef83b2,"reason=FailedScheduling count=None msg=0/6 nodes are available: 1 c_wall violated: 1 conflicting context pair(s) with node memory, 1 c_wall violated: 2 conflicting context pair(s) with node memory, 4 node(s) had untolerated taint(s). no new claims to deallocate, preemption: 0/6 nodes are available: 2 No preemption victims found for incoming pod, 4 Preemption is not helpful for scheduling."
0.0654,Event,ADDED,eval-conflicts-rho040-r0-065-fsc2f.18d52f36b78324c4,"reason=FailedScheduling count=None msg=0/6 nodes are available: 1 c_wall violated: 1 conflicting context pair(s) with node memory, 5 node(s) had untolerated taint(s). no new claims to deallocate, preemption: 0/6 nodes are available: 1 No preemption victims found for incoming pod, 5 Preemption is not helpful for scheduling."
0.0656,Event,ADDED,eval-conflicts-rho040-r0-065-fsc2f.18d52f371b6afde3,"reason=FailedScheduling count=None msg=0/6 nodes are available: 1 c_wall violated: 2 conflicting context pair(s) with node memory, 5 node(s) had untolerated taint(s). no new claims to deallocate, preemption: 0/6 nodes are available: 1 No preemption victims found for incoming pod, 5 Preemption is not helpful for scheduling."
0.066,Event,ADDED,eval-conflicts-rho040-r0-065-fsc2f.18d52f39e7fd9178,"reason=FailedScheduling count=None msg=0/6 nodes are available: 1 c_wall violated: 1 conflicting context pair(s) with node memory, 1 c_wall violated: 2 conflicting context pair(s) with node memory, 4 node(s) had untolerated taint(s). no new claims to deallocate, preemption: 0/6 nodes are available: 2 No preemption victims found for incoming pod, 4 Preemption is not helpful for scheduling."
0.0662,Event,ADDED,eval-conflicts-rho040-r0-065-fsc2f.18d52f3a09a2ea11,reason=Scheduled count=None msg=Successfully assigned compute/eval-conflicts-rho040-r0-065-fsc2f to kind-worker
0.0664,Event,ADDED,eval-conflicts-rho040-r0-065-fsc2f.18d52f3a2a96d0d0,"reason=Pulled count=1 msg=Container image ""busybox:musl"" already present on machine"
0.0666,Event,ADDED,eval-conflicts-rho040-r0-065-fsc2f.18d52f3a2c33c032,reason=Created count=1 msg=Created container: task
0.067,Event,ADDED,eval-conflicts-rho040-r0-065-fsc2f.18d52f3a35369c9c,reason=Started count=1 msg=Started container task
0.0672,Event,ADDED,eval-conflicts-rho040-r0-065.18d52f40347497a1,reason=Completed count=1 msg=Job completed
0.0674,Event,ADDED,eval-conflicts-rho040-r0-066-8zm6t.18d52f35eda6c83b,"reason=FailedScheduling count=None msg=0/6 nodes are available: 1 c_wall violated: 2 conflicting context pair(s) with node memory, 5 node(s) had untolerated taint(s). no new claims to deallocate, preemption: 0/6 nodes are available: 1 No preemption victims found for incoming pod, 5 Preemption is not helpful for scheduling."
0.0677,Event,ADDED,eval-conflicts-rho040-r0-066-8zm6t.18d52f35ee574d02,"reason=FailedScheduling count=None msg=0/6 nodes are available: 1 c_wall violated: 2 conflicting context pair(s) with node memory, 5 node(s) had untolerated taint(s). no new claims to deallocate, preemption: 0/6 nodes are available: 1 No preemption victims found for incoming pod, 5 Preemption is not helpful for scheduling."
0.0679,Event,ADDED,eval-conflicts-rho040-r0-066-8zm6t.18d52f369223986b,reason=Scheduled count=None msg=Successfully assigned compute/eval-conflicts-rho040-r0-066-8zm6t to kind-worker2
0.0681,Event,ADDED,eval-conflicts-rho040-r0-066.18d52f3c47727c70,reason=Completed count=1 msg=Job completed
0.0684,Event,ADDED,eval-conflicts-rho040-r0-067-djmqr.18d52f362695b7b1,"reason=FailedScheduling count=None msg=0/6 nodes are available: 1 c_wall violated: 3 conflicting context pair(s) with node memory, 5 node(s) had untolerated taint(s). no new claims to deallocate, preemption: 0/6 nodes are available: 1 No preemption victims found for incoming pod, 5 Preemption is not helpful for scheduling."
0.0686,Event,ADDED,eval-conflicts-rho040-r0-067-djmqr.18d52f3627422066,"reason=FailedScheduling count=None msg=0/6 nodes are available: 1 c_wall violated: 3 conflicting context pair(s) with node memory, 5 node(s) had untolerated taint(s). no new claims to deallocate, preemption: 0/6 nodes are available: 1 No preemption victims found for incoming pod, 5 Preemption is not helpful for scheduling."
0.0688,Event,ADDED,eval-conflicts-rho040-r0-067-djmqr.18d52f369d2987fb,"reason=FailedScheduling count=None msg=0/6 nodes are available: 1 c_wall violated: 1 conflicting context pair(s) with node memory, 1 c_wall violated: 3 conflicting context pair(s) with node memory, 4 node(s) had untolerated taint(s). no new claims to deallocate, preemption: 0/6 nodes are available: 2 No preemption victims found for incoming pod, 4 Preemption is not helpful for scheduling."
0.0692,Event,ADDED,eval-conflicts-rho040-r0-067-djmqr.18d52f36b7b26549,"reason=FailedScheduling count=None msg=0/6 nodes are available: 1 c_wall violated: 1 conflicting context pair(s) with node memory, 5 node(s) had untolerated taint(s). no new claims to deallocate, preemption: 0/6 nodes are available: 1 No preemption victims found for incoming pod, 5 Preemption is not helpful for scheduling."
0.0694,Event,ADDED,eval-conflicts-rho040-r0-067-djmqr.18d52f371b98b2b3,"reason=FailedScheduling count=None msg=0/6 nodes are available: 1 c_wall violated: 2 conflicting context pair(s) with node memory, 5 node(s) had untolerated taint(s). no new claims to deallocate, preemption: 0/6 nodes are available: 1 No preemption victims found for incoming pod, 5 Preemption is not helpful for scheduling."
0.0696,Event,ADDED,eval-conflicts-rho040-r0-067-djmqr.18d52f3881912797,"reason=FailedScheduling count=None msg=0/6 nodes are available: 1 c_wall violated: 3 conflicting context pair(s) with node memory, 5 node(s) had untolerated taint(s). no new claims to deallocate, preemption: 0/6 nodes are available: 1 No preemption victims found for incoming pod, 5 Preemption is not helpful for scheduling."
0.0699,Event,ADDED,eval-conflicts-rho040-r0-067-djmqr.18d52f39ed27aaca,"reason=FailedScheduling count=None msg=0/6 nodes are available: 1 c_wall violated: 1 conflicting context pair(s) with node memory, 1 c_wall violated: 3 conflicting context pair(s) with node memory, 4 node(s) had untolerated taint(s). no new claims to deallocate, preemption: 0/6 nodes are available: 2 No preemption victims found for incoming pod, 4 Preemption is not helpful for scheduling."
0.0701,Event,ADDED,eval-conflicts-rho040-r0-067-djmqr.18d52f3a0a0e59a8,reason=Scheduled count=None msg=Successfully assigned compute/eval-conflicts-rho040-r0-067-djmqr to kind-worker
0.0704,Event,ADDED,eval-conflicts-rho040-r0-067-djmqr.18d52f3a2ab36c1d,"reason=Pulled count=1 msg=Container image ""busybox:musl"" already present on machine"
0.0708,Event,ADDED,eval-conflicts-rho040-r0-067-djmqr.18d52f3a2ca1585f,reason=Created count=1 msg=Created container: task
0.0713,Event,ADDED,eval-conflicts-rho040-r0-067-djmqr.18d52f3a35c376d2,reason=Started count=1 msg=Started container task
0.0716,Event,ADDED,eval-conflicts-rho040-r0-067.18d52f4012d9c193,reason=Completed count=1 msg=Job completed
0.072,Event,ADDED,eval-conflicts-rho040-r0-068-dqgvl.18d52f3663f0894f,reason=Scheduled count=None msg=Successfully assigned compute/eval-conflicts-rho040-r0-068-dqgvl to kind-worker3
0.0721,TaskRequest,MODIFIED,eval-conflicts-rho060-r3-000,phase=Scheduled job=None
0.0726,Event,ADDED,eval-conflicts-rho040-r0-068.18d52f3c15bbd108,reason=Completed count=1 msg=Job completed
0.0728,Event,ADDED,eval-conflicts-rho040-r0-069-lp68l.18d52f36a1bce031,reason=Scheduled count=None msg=Successfully assigned compute/eval-conflicts-rho040-r0-069-lp68l to kind-worker3
0.073,Event,ADDED,eval-conflicts-rho040-r0-069.18d52f3c527e513c,reason=Completed count=1 msg=Job completed
0.0732,Event,ADDED,eval-conflicts-rho040-r0-070-j2cxz.18d52f36e04ab17b,reason=Scheduled count=None msg=Successfully assigned compute/eval-conflicts-rho040-r0-070-j2cxz to kind-worker2
0.0736,Event,ADDED,eval-conflicts-rho040-r0-070.18d52f3c83eefc3e,reason=Completed count=1 msg=Job completed
0.0738,Event,ADDED,eval-conflicts-rho040-r0-071-6wxbq.18d52f37191fb3be,reason=Scheduled count=None msg=Successfully assigned compute/eval-conflicts-rho040-r0-071-6wxbq to kind-worker2
0.074,Event,ADDED,eval-conflicts-rho040-r0-071.18d52f3cc16660f3,reason=Completed count=1 msg=Job completed
0.0749,Pod,ADDED,eval-conflicts-rho060-r3-000-sklq6,phase=Pending node=None
0.0757,Job,MODIFIED,eval-conflicts-rho060-r3-000,
0.0761,Event,ADDED,eval-conflicts-rho040-r0-072-jhh8j.18d52f3752a14a4c,"reason=FailedScheduling count=None msg=0/6 nodes are available: 1 c_wall violated: 2 conflicting context pair(s) with node memory, 5 node(s) had untolerated taint(s). no new claims to deallocate, preemption: 0/6 nodes are available: 1 No preemption victims found for incoming pod, 5 Preemption is not helpful for scheduling."
0.0763,Event,ADDED,eval-conflicts-rho040-r0-072-jhh8j.18d52f37532a52e1,"reason=FailedScheduling count=None msg=0/6 nodes are available: 1 c_wall violated: 2 conflicting context pair(s) with node memory, 5 node(s) had untolerated taint(s). no new claims to deallocate, preemption: 0/6 nodes are available: 1 No preemption victims found for incoming pod, 5 Preemption is not helpful for scheduling."
0.0765,Event,ADDED,eval-conflicts-rho040-r0-072-jhh8j.18d52f39c759f35d,reason=Scheduled count=None msg=Successfully assigned compute/eval-conflicts-rho040-r0-072-jhh8j to kind-worker4
0.0767,Event,ADDED,eval-conflicts-rho040-r0-072-jhh8j.18d52f39e1acd7ae,"reason=Pulled count=1 msg=Container image ""busybox:musl"" already present on machine"
0.077,Event,ADDED,eval-conflicts-rho040-r0-072-jhh8j.18d52f39e3bb39c4,reason=Created count=1 msg=Created container: task
0.0772,Event,ADDED,eval-conflicts-rho040-r0-072-jhh8j.18d52f39ec417e00,reason=Started count=1 msg=Started container task
0.0774,Event,ADDED,eval-conflicts-rho040-r0-072.18d52f3f73d11126,reason=Completed count=1 msg=Job completed
0.0777,Event,ADDED,eval-conflicts-rho040-r0-073-s66r9.18d52f378ca60bbf,"reason=FailedScheduling count=None msg=0/6 nodes are available: 1 c_wall violated: 2 conflicting context pair(s) with node memory, 5 node(s) had untolerated taint(s). no new claims to deallocate, preemption: 0/6 nodes are available: 1 No preemption victims found for incoming pod, 5 Preemption is not helpful for scheduling."
0.0779,Event,ADDED,eval-conflicts-rho040-r0-073-s66r9.18d52f378d4a8eec,"reason=FailedScheduling count=None msg=0/6 nodes are available: 1 c_wall violated: 2 conflicting context pair(s) with node memory, 5 node(s) had untolerated taint(s). no new claims to deallocate, preemption: 0/6 nodes are available: 1 No preemption victims found for incoming pod, 5 Preemption is not helpful for scheduling."
0.0781,Event,ADDED,eval-conflicts-rho040-r0-073-s66r9.18d52f39edd5cd8b,reason=Scheduled count=None msg=Successfully assigned compute/eval-conflicts-rho040-r0-073-s66r9 to kind-worker
0.0783,Event,ADDED,eval-conflicts-rho040-r0-073-s66r9.18d52f3a0975273d,"reason=Pulled count=1 msg=Container image ""busybox:musl"" already present on machine"
0.0786,Event,ADDED,eval-conflicts-rho040-r0-073-s66r9.18d52f3a0bb183fd,reason=Created count=1 msg=Created container: task
0.0788,Event,ADDED,eval-conflicts-rho040-r0-073-s66r9.18d52f3a10560129,reason=Started count=1 msg=Started container task
0.0789,Event,ADDED,eval-conflicts-rho040-r0-073.18d52f3fd1673e89,reason=Completed count=1 msg=Job completed
0.0792,Event,ADDED,eval-conflicts-rho040-r0-074-6wfkb.18d52f37c7f6b968,reason=Scheduled count=None msg=Successfully assigned compute/eval-conflicts-rho040-r0-074-6wfkb to kind-worker2
0.0794,Event,ADDED,eval-conflicts-rho040-r0-074.18d52f3d6efa957b,reason=Completed count=1 msg=Job completed
0.0796,Event,ADDED,eval-conflicts-rho040-r0-075-4gwrq.18d52f38059f3da2,"reason=FailedScheduling count=None msg=0/6 nodes are available: 1 c_wall violated: 1 conflicting context pair(s) with node memory, 5 node(s) had untolerated taint(s). no new claims to deallocate, preemption: 0/6 nodes are available: 1 No preemption victims found for incoming pod, 5 Preemption is not helpful for scheduling."
0.0797,TaskRequest,MODIFIED,eval-conflicts-rho060-r3-000,phase=Scheduled job=None
0.0802,Event,ADDED,eval-conflicts-rho040-r0-075-4gwrq.18d52f3806111199,"reason=FailedScheduling count=None msg=0/6 nodes are available: 1 c_wall violated: 1 conflicting context pair(s) with node memory, 5 node(s) had untolerated taint(s). no new claims to deallocate, preemption: 0/6 nodes are available: 1 No preemption victims found for incoming pod, 5 Preemption is not helpful for scheduling."
0.0804,Event,ADDED,eval-conflicts-rho040-r0-075-4gwrq.18d52f38821d5325,"reason=FailedScheduling count=None msg=0/6 nodes are available: 1 c_wall violated: 2 conflicting context pair(s) with node memory, 5 node(s) had untolerated taint(s). no new claims to deallocate, preemption: 0/6 nodes are available: 1 No preemption victims found for incoming pod, 5 Preemption is not helpful for scheduling."
0.0806,Event,ADDED,eval-conflicts-rho040-r0-075-4gwrq.18d52f39e157310b,"reason=FailedScheduling count=None msg=0/6 nodes are available: 1 c_wall violated: 1 conflicting context pair(s) with node memory, 1 c_wall violated: 2 conflicting context pair(s) with node memory, 4 node(s) had untolerated taint(s). no new claims to deallocate, preemption: 0/6 nodes are available: 2 No preemption victims found for incoming pod, 4 Preemption is not helpful for scheduling."
0.081,Event,ADDED,eval-conflicts-rho040-r0-075-4gwrq.18d52f3a0b0795a1,"reason=FailedScheduling count=None msg=0/6 nodes are available: 1 c_wall violated: 2 conflicting context pair(s) with node memory, 2 c_wall violated: 1 conflicting context pair(s) with node memory, 3 node(s) had untolerated taint(s). no new claims to deallocate, preemption: 0/6 nodes are available: 3 No preemption victims found for incoming pod, 3 Preemption is not helpful for scheduling."
0.0812,Event,ADDED,eval-conflicts-rho040-r0-075-4gwrq.18d52f3a1b0ddb12,reason=Scheduled count=None msg=Successfully assigned compute/eval-conflicts-rho040-r0-075-4gwrq to kind-worker5
0.0814,Event,ADDED,eval-conflicts-rho040-r0-075-4gwrq.18d52f3a3c6c32eb,"reason=Pulled count=1 msg=Container image ""busybox:musl"" already present on machine"
0.0815,Event,ADDED,eval-conflicts-rho040-r0-075-4gwrq.18d52f3a3e429865,reason=Created count=1 msg=Created container: task
0.0819,Event,ADDED,eval-conflicts-rho040-r0-075-4gwrq.18d52f3a47af5c47,reason=Started count=1 msg=Started container task
0.0822,Event,ADDED,eval-conflicts-rho040-r0-075.18d52f40365e0ff7,reason=Completed count=1 msg=Job completed
0.0823,Event,ADDED,eval-conflicts-rho040-r0-076-7ktk6.18d52f383ea439f9,"reason=FailedScheduling count=None msg=0/6 nodes are available: 1 c_wall violated: 2 conflicting context pair(s) with node memory, 5 node(s) had untolerated taint(s). no new claims to deallocate, preemption: 0/6 nodes are available: 1 No preemption victims found for incoming pod, 5 Preemption is not helpful for scheduling."
0.0827,Event,ADDED,eval-conflicts-rho040-r0-076-7ktk6.18d52f383f131300,"reason=FailedScheduling count=None msg=0/6 nodes are available: 1 c_wall violated: 2 conflicting context pair(s) with node memory, 5 node(s) had untolerated taint(s). no new claims to deallocate, preemption: 0/6 nodes are available: 1 No preemption victims found for incoming pod, 5 Preemption is not helpful for scheduling."
0.0828,Event,ADDED,eval-conflicts-rho040-r0-076-7ktk6.18d52f39d2516bc0,reason=Scheduled count=None msg=Successfully assigned compute/eval-conflicts-rho040-r0-076-7ktk6 to kind-worker4
0.083,Event,ADDED,eval-conflicts-rho040-r0-076-7ktk6.18d52f39edb2efd0,"reason=Pulled count=1 msg=Container image ""busybox:musl"" already present on machine"
0.0834,Event,ADDED,eval-conflicts-rho040-r0-076-7ktk6.18d52f39ef64c88f,reason=Created count=1 msg=Created container: task
0.0836,Event,ADDED,eval-conflicts-rho040-r0-076-7ktk6.18d52f39f5f4ffd2,reason=Started count=1 msg=Started container task
0.0837,Event,ADDED,eval-conflicts-rho040-r0-076.18d52f3f739e9b2a,reason=Completed count=1 msg=Job completed
0.0839,Event,ADDED,eval-conflicts-rho040-r0-077-dgtdx.18d52f387baceddd,reason=Scheduled count=None msg=Successfully assigned compute/eval-conflicts-rho040-r0-077-dgtdx to kind-worker2
0.0842,Event,ADDED,eval-conflicts-rho040-r0-077.18d52f3e2f172066,reason=Completed count=1 msg=Job completed
0.0843,Event,ADDED,eval-conflicts-rho040-r0-078-z5s6q.18d52f38b700b60b,"reason=FailedScheduling count=None msg=0/6 nodes are available: 1 c_wall violated: 1 conflicting context pair(s) with node memory, 5 node(s) had untolerated taint(s). no new claims to deallocate, preemption: 0/6 nodes are available: 1 No preemption victims found for incoming pod, 5 Preemption is not helpful for scheduling."
0.0845,Event,ADDED,eval-conflicts-rho040-r0-078-z5s6q.18d52f38b7820828,"reason=FailedScheduling count=None msg=0/6 nodes are available: 1 c_wall violated: 1 conflicting context pair(s) with node memory, 5 node(s) had untolerated taint(s). no new claims to deallocate, preemption: 0/6 nodes are available: 1 No preemption victims found for incoming pod, 5 Preemption is not helpful for scheduling."
0.085,Event,ADDED,eval-conflicts-rho040-r0-078-z5s6q.18d52f39e72286ba,"reason=FailedScheduling count=None msg=0/6 nodes are available: 2 c_wall violated: 1 conflicting context pair(s) with node memory, 4 node(s) had untolerated taint(s). no new claims to deallocate, preemption: 0/6 nodes are available: 2 No preemption victims found for incoming pod, 4 Preemption is not helpful for scheduling."
0.0858,Event,ADDED,eval-conflicts-rho040-r0-078-z5s6q.18d52f3a134d072b,reason=Scheduled count=None msg=Successfully assigned compute/eval-conflicts-rho040-r0-078-z5s6q to kind-worker5
0.0861,Event,ADDED,eval-conflicts-rho040-r0-078-z5s6q.18d52f3a36b5b313,"reason=Pulled count=1 msg=Container image ""busybox:musl"" already present on machine"
0.0863,Event,ADDED,eval-conflicts-rho040-r0-078-z5s6q.18d52f3a38c2b796,reason=Created count=1 msg=Created container: task
0.0871,Pod,MODIFIED,eval-conflicts-rho060-r3-000-sklq6,phase=Pending node=kind-worker2
0.0875,Event,ADDED,eval-conflicts-rho040-r0-078-z5s6q.18d52f3a3c637021,reason=Started count=1 msg=Started container task
0.0876,Event,ADDED,eval-conflicts-rho040-r0-078.18d52f4044f33f82,reason=Completed count=1 msg=Job completed
0.0878,Event,ADDED,eval-conflicts-rho040-r0-079-8ktk6.18d52f38f24d9ea7,"reason=FailedScheduling count=None msg=0/6 nodes are available: 1 c_wall violated: 2 conflicting context pair(s) with node memory, 5 node(s) had untolerated taint(s). no new claims to deallocate, preemption: 0/6 nodes are available: 1 No preemption victims found for incoming pod, 5 Preemption is not helpful for scheduling."
0.0883,Event,ADDED,eval-conflicts-rho040-r0-079-8ktk6.18d52f38f2d6dc02,"reason=FailedScheduling count=None msg=0/6 nodes are available: 1 c_wall violated: 2 conflicting context pair(s) with node memory, 5 node(s) had untolerated taint(s). no new claims to deallocate, preemption: 0/6 nodes are available: 1 No preemption victims found for incoming pod, 5 Preemption is not helpful for scheduling."
0.0886,Event,ADDED,eval-conflicts-rho040-r0-079-8ktk6.18d52f39e1c7ebdf,"reason=FailedScheduling count=None msg=0/6 nodes are available: 1 c_wall violated: 1 conflicting context pair(s) with node memory, 1 c_wall violated: 2 conflicting context pair(s) with node memory, 4 node(s) had untolerated taint(s). no new claims to deallocate, preemption: 0/6 nodes are available: 2 No preemption victims found for incoming pod, 4 Preemption is not helpful for scheduling."
0.0889,Event,ADDED,eval-conflicts-rho040-r0-079-8ktk6.18d52f3a10b3d84e,"reason=FailedScheduling count=None msg=0/6 nodes are available: 1 c_wall violated: 2 conflicting context pair(s) with node memory, 2 c_wall violated: 1 conflicting context pair(s) with node memory, 3 node(s) had untolerated taint(s). no new claims to deallocate, preemption: 0/6 nodes are available: 3 No preemption victims found for incoming pod, 3 Preemption is not helpful for scheduling."
0.0894,Event,ADDED,eval-conflicts-rho040-r0-079-8ktk6.18d52f3a1d1a69de,reason=Scheduled count=None msg=Successfully assigned compute/eval-conflicts-rho040-r0-079-8ktk6 to kind-worker5
0.0903,Event,ADDED,eval-conflicts-rho040-r0-079-8ktk6.18d52f3a3d2045fb,"reason=Pulled count=1 msg=Container image ""busybox:musl"" already present on machine"
0.0906,Event,ADDED,eval-conflicts-rho040-r0-079-8ktk6.18d52f3a3f53eca7,reason=Created count=1 msg=Created container: task
0.0912,Event,ADDED,eval-conflicts-rho040-r0-079-8ktk6.18d52f3a47b22a7b,reason=Started count=1 msg=Started container task
0.0916,Event,ADDED,eval-conflicts-rho040-r0-079.18d52f402781135b,reason=Completed count=1 msg=Job completed
0.0919,Event,ADDED,eval-conflicts-rho040-r0-080-hrljm.18d52f392d815f8a,"reason=FailedScheduling count=None msg=0/6 nodes are available: 1 c_wall violated: 2 conflicting context pair(s) with node memory, 5 node(s) had untolerated taint(s). no new claims to deallocate, preemption: 0/6 nodes are available: 1 No preemption victims found for incoming pod, 5 Preemption is not helpful for scheduling."
0.0923,Event,ADDED,eval-conflicts-rho040-r0-080-hrljm.18d52f392e0c3a59,"reason=FailedScheduling count=None msg=0/6 nodes are available: 1 c_wall violated: 2 conflicting context pair(s) with node memory, 5 node(s) had untolerated taint(s). no new claims to deallocate, preemption: 0/6 nodes are available: 1 No preemption victims found for incoming pod, 5 Preemption is not helpful for scheduling."
0.0925,Event,ADDED,eval-conflicts-rho040-r0-080-hrljm.18d52f39cf73028f,reason=Scheduled count=None msg=Successfully assigned compute/eval-conflicts-rho040-r0-080-hrljm to kind-worker4
0.0927,Event,ADDED,eval-conflicts-rho040-r0-080-hrljm.18d52f39e9aae5ea,"reason=Pulled count=1 msg=Container image ""busybox:musl"" already present on machine"
0.0929,Event,ADDED,eval-conflicts-rho040-r0-080-hrljm.18d52f39eb050904,reason=Created count=1 msg=Created container: task
0.0933,Event,ADDED,eval-conflicts-rho040-r0-080-hrljm.18d52f39ee370b2f,reason=Started count=1 msg=Started container task
0.0935,Event,ADDED,eval-conflicts-rho040-r0-080.18d52f392d384409,reason=SuccessfulCreate count=1 msg=Created pod: eval-conflicts-rho040-r0-080-hrljm
0.0937,Event,ADDED,eval-conflicts-rho040-r0-080.18d52f3f73d15e1e,reason=Completed count=1 msg=Job completed
0.0941,Event,ADDED,eval-conflicts-rho040-r0-081-w4fs2.18d52f3968a911c5,"reason=FailedScheduling count=None msg=0/6 nodes are available: 1 c_wall violated: 2 conflicting context pair(s) with node memory, 5 node(s) had untolerated taint(s). no new claims to deallocate, preemption: 0/6 nodes are available: 1 No preemption victims found for incoming pod, 5 Preemption is not helpful for scheduling."
0.0943,Event,ADDED,eval-conflicts-rho040-r0-081-w4fs2.18d52f39692ce50a,"reason=FailedScheduling count=None msg=0/6 nodes are available: 1 c_wall violated: 2 conflicting context pair(s) with node memory, 5 node(s) had untolerated taint(s). no new claims to deallocate, preemption: 0/6 nodes are available: 1 No preemption victims found for incoming pod, 5 Preemption is not helpful for scheduling."
0.0945,Event,ADDED,eval-conflicts-rho040-r0-081-w4fs2.18d52f39cfca74a9,reason=Scheduled count=None msg=Successfully assigned compute/eval-conflicts-rho040-r0-081-w4fs2 to kind-worker4
0.0946,Event,ADDED,eval-conflicts-rho040-r0-081-w4fs2.18d52f39e9dc71e7,"reason=Pulled count=1 msg=Container image ""busybox:musl"" already present on machine"
0.095,Event,ADDED,eval-conflicts-rho040-r0-081-w4fs2.18d52f39eb63579a,reason=Created count=1 msg=Created container: task
0.0951,Event,ADDED,eval-conflicts-rho040-r0-081-w4fs2.18d52f39ee370b3e,reason=Started count=1 msg=Started container task
0.0953,Event,ADDED,eval-conflicts-rho040-r0-081.18d52f3968640077,reason=SuccessfulCreate count=1 msg=Created pod: eval-conflicts-rho040-r0-081-w4fs2
0.0963,Event,ADDED,eval-conflicts-rho040-r0-081.18d52f3f73d0d577,reason=Completed count=1 msg=Job completed
0.0966,Event,ADDED,eval-conflicts-rho040-r0-082-vlbwg.18d52f39a50abfcd,reason=Scheduled count=None msg=Successfully assigned compute/eval-conflicts-rho040-r0-082-vlbwg to kind-worker2
0.097,Event,ADDED,eval-conflicts-rho040-r0-082-vlbwg.18d52f39bdf80b71,"reason=Pulled count=1 msg=Container image ""busybox:musl"" already present on machine"
0.0975,Event,ADDED,eval-conflicts-rho040-r0-082-vlbwg.18d52f39bf96a0f3,reason=Created count=1 msg=Created container: task
0.0982,Event,ADDED,eval-conflicts-rho040-r0-082-vlbwg.18d52f39c6afc4a8,reason=Started count=1 msg=Started container task
0.0985,Event,ADDED,eval-conflicts-rho040-r0-082.18d52f39a4699f1c,reason=SuccessfulCreate count=1 msg=Created pod: eval-conflicts-rho040-r0-082-vlbwg
0.0989,Event,ADDED,eval-conflicts-rho040-r0-082.18d52f3f4fe9a279,reason=Completed count=1 msg=Job completed
0.0991,Event,ADDED,eval-conflicts-rho040-r0-083-r45p8.18d52f39e81e0768,reason=Scheduled count=None msg=Successfully assigned compute/eval-conflicts-rho040-r0-083-r45p8 to kind-worker4
0.0995,Event,ADDED,eval-conflicts-rho040-r0-083-r45p8.18d52f3a097e7749,"reason=Pulled count=1 msg=Container image ""busybox:musl"" already present on machine"
0.0997,Event,ADDED,eval-conflicts-rho040-r0-083-r45p8.18d52f3a0b501d95,reason=Created count=1 msg=Created container: task
0.0999,Event,ADDED,eval-conflicts-rho040-r0-083-r45p8.18d52f3a107e493f,reason=Started count=1 msg=Started container task
0.1013,Node,MODIFIED,kind-worker2,taints=0
0.1018,Event,ADDED,eval-conflicts-rho040-r0-083.18d52f39e3346aba,reason=SuccessfulCreate count=1 msg=Created pod: eval-conflicts-rho040-r0-083-r45p8
0.1021,Event,ADDED,eval-conflicts-rho040-r0-083.18d52f4000a06157,reason=Completed count=1 msg=Job completed
0.1023,Event,ADDED,eval-conflicts-rho040-r0-084-dpm79.18d52f3a232c63b5,reason=Scheduled count=None msg=Successfully assigned compute/eval-conflicts-rho040-r0-084-dpm79 to kind-worker5
0.1025,Event,ADDED,eval-conflicts-rho040-r0-084-dpm79.18d52f3a3d38bf2d,"reason=Pulled count=1 msg=Container image ""busybox:musl"" already present on machine"
0.1028,Event,ADDED,eval-conflicts-rho040-r0-084-dpm79.18d52f3a3f80b7ed,reason=Created count=1 msg=Created container: task
0.103,Event,ADDED,eval-conflicts-rho040-r0-084-dpm79.18d52f3a47af5c33,reason=Started count=1 msg=Started container task
0.1032,Event,ADDED,eval-conflicts-rho040-r0-084.18d52f3a1ce54318,reason=SuccessfulCreate count=1 msg=Created pod: eval-conflicts-rho040-r0-084-dpm79
0.1034,Event,ADDED,eval-conflicts-rho040-r0-084.18d52f40189b6d73,reason=Completed count=1 msg=Job completed
0.1045,Pod,MODIFIED,eval-conflicts-rho060-r3-000-sklq6,phase=Pending node=kind-worker2
0.1048,Event,ADDED,eval-conflicts-rho040-r0-085-w42zh.18d52f3a5ff69e12,reason=Scheduled count=None msg=Successfully assigned compute/eval-conflicts-rho040-r0-085-w42zh to kind-worker2
0.105,Event,ADDED,eval-conflicts-rho040-r0-085-w42zh.18d52f3a7ac88b80,"reason=Pulled count=1 msg=Container image ""busybox:musl"" already present on machine"
0.1051,Event,ADDED,eval-conflicts-rho040-r0-085-w42zh.18d52f3a7c0056bf,reason=Created count=1 msg=Created container: task
0.1056,Event,ADDED,eval-conflicts-rho040-r0-085-w42zh.18d52f3a816579b9,reason=Started count=1 msg=Started container task
0.1058,Event,ADDED,eval-conflicts-rho040-r0-085.18d52f3a5d82cbe4,reason=SuccessfulCreate count=1 msg=Created pod: eval-conflicts-rho040-r0-085-w42zh
0.1061,Event,ADDED,eval-conflicts-rho040-r0-085.18d52f4065e778df,reason=Completed count=1 msg=Job completed
0.1063,Event,ADDED,eval-conflicts-rho040-r0-086-8st2v.18d52f3a97153f74,reason=Scheduled count=None msg=Successfully assigned compute/eval-conflicts-rho040-r0-086-8st2v to kind-worker2
0.1069,Event,ADDED,eval-conflicts-rho040-r0-086-8st2v.18d52f3ab986e8b4,"reason=Pulled count=1 msg=Container image ""busybox:musl"" already present on machine"
0.1071,Event,ADDED,eval-conflicts-rho040-r0-086-8st2v.18d52f3abaddfa87,reason=Created count=1 msg=Created container: task
0.1073,Event,ADDED,eval-conflicts-rho040-r0-086-8st2v.18d52f3ac35f70fd,reason=Started count=1 msg=Started container task
0.1076,Event,ADDED,eval-conflicts-rho040-r0-086.18d52f3a93395607,reason=SuccessfulCreate count=1 msg=Created pod: eval-conflicts-rho040-r0-086-8st2v
0.1078,Event,ADDED,eval-conflicts-rho040-r0-086.18d52f40a462029a,reason=Completed count=1 msg=Job completed
0.108,Event,ADDED,eval-conflicts-rho040-r0-087-8vmgq.18d52f3acfef5f3f,reason=Scheduled count=None msg=Successfully assigned compute/eval-conflicts-rho040-r0-087-8vmgq to kind-worker
0.1082,Event,ADDED,eval-conflicts-rho040-r0-087-8vmgq.18d52f3af089db2e,"reason=Pulled count=1 msg=Container image ""busybox:musl"" already present on machine"
0.1084,Event,ADDED,eval-conflicts-rho040-r0-087-8vmgq.18d52f3af1d99cdc,reason=Created count=1 msg=Created container: task
0.1086,Event,ADDED,eval-conflicts-rho040-r0-087-8vmgq.18d52f3af544eff0,reason=Started count=1 msg=Started container task
0.1087,Event,ADDED,eval-conflicts-rho040-r0-087.18d52f3ace8db2d0,reason=SuccessfulCreate count=1 msg=Created pod: eval-conflicts-rho040-r0-087-8vmgq
0.1089,Event,ADDED,eval-conflicts-rho040-r0-087.18d52f40cfff02df,reason=Completed count=1 msg=Job completed
0.1092,Event,ADDED,eval-conflicts-rho040-r0-088-m6bc6.18d52f3b0be000a8,reason=Scheduled count=None msg=Successfully assigned compute/eval-conflicts-rho040-r0-088-m6bc6 to kind-worker4
0.1096,Event,ADDED,eval-conflicts-rho040-r0-088-m6bc6.18d52f3b287e55c3,"reason=Pulled count=1 msg=Container image ""busybox:musl"" already present on machine"
0.1098,Event,ADDED,eval-conflicts-rho040-r0-088-m6bc6.18d52f3b2a014f4d,reason=Created count=1 msg=Created container: task
0.1102,Event,ADDED,eval-conflicts-rho040-r0-088-m6bc6.18d52f3b36e420d4,reason=Started count=1 msg=Started container task
0.1104,Event,ADDED,eval-conflicts-rho040-r0-088.18d52f3b0a5f94d7,reason=SuccessfulCreate count=1 msg=Created pod: eval-conflicts-rho040-r0-088-m6bc6
0.1106,Event,ADDED,eval-conflicts-rho040-r0-088.18d52f40ec2a384d,reason=Completed count=1 msg=Job completed
0.1107,Event,ADDED,eval-conflicts-rho040-r0-089-s9xr8.18d52f3b493420b0,reason=Scheduled count=None msg=Successfully assigned compute/eval-conflicts-rho040-r0-089-s9xr8 to kind-worker5
0.111,Event,ADDED,eval-conflicts-rho040-r0-089-s9xr8.18d52f3b679407d5,"reason=Pulled count=1 msg=Container image ""busybox:musl"" already present on machine"
0.1112,Event,ADDED,eval-conflicts-rho040-r0-089-s9xr8.18d52f3b68b2e35d,reason=Created count=1 msg=Created container: task
0.1114,Event,ADDED,eval-conflicts-rho040-r0-089-s9xr8.18d52f3b6cd73bb1,reason=Started count=1 msg=Started container task
0.1115,Event,ADDED,eval-conflicts-rho040-r0-089.18d52f3b48464f11,reason=SuccessfulCreate count=1 msg=Created pod: eval-conflicts-rho040-r0-089-s9xr8
0.1129,Node,MODIFIED,kind-worker2,taints=0
0.1133,Event,ADDED,eval-conflicts-rho040-r0-089.18d52f40fa694550,reason=Completed count=1 msg=Job completed
0.1134,Event,ADDED,eval-conflicts-rho040-r0-090-rmrfc.18d52f3b831534f8,reason=Scheduled count=None msg=Successfully assigned compute/eval-conflicts-rho040-r0-090-rmrfc to kind-worker
0.1136,Event,ADDED,eval-conflicts-rho040-r0-090-rmrfc.18d52f3b9c4e7bae,"reason=Pulled count=1 msg=Container image ""busybox:musl"" already present on machine"
0.1141,Event,ADDED,eval-conflicts-rho040-r0-090-rmrfc.18d52f3b9dc963af,reason=Created count=1 msg=Created container: task
0.1143,Event,ADDED,eval-conflicts-rho040-r0-090-rmrfc.18d52f3ba39142fb,reason=Started count=1 msg=Started container task
0.1145,Event,ADDED,eval-conflicts-rho040-r0-090.18d52f3b8233c285,reason=SuccessfulCreate count=1 msg=Created pod: eval-conflicts-rho040-r0-090-rmrfc
0.1147,Event,ADDED,eval-conflicts-rho040-r0-090.18d52f40ed6bad65,reason=Completed count=1 msg=Job completed
0.115,Event,ADDED,eval-conflicts-rho040-r0-091-lncmp.18d52f3bbd3f9c3e,reason=Scheduled count=None msg=Successfully assigned compute/eval-conflicts-rho040-r0-091-lncmp to kind-worker5
0.1151,Event,ADDED,eval-conflicts-rho040-r0-091-lncmp.18d52f3bd9144cc2,"reason=Pulled count=1 msg=Container image ""busybox:musl"" already present on machine"
0.1153,Event,ADDED,eval-conflicts-rho040-r0-091-lncmp.18d52f3bdabb04e7,reason=Created count=1 msg=Created container: task
0.1156,Event,ADDED,eval-conflicts-rho040-r0-091-lncmp.18d52f3be3c1cf36,reason=Started count=1 msg=Started container task
0.1158,Event,ADDED,eval-conflicts-rho040-r0-091.18d52f3bbc53623c,reason=SuccessfulCreate count=1 msg=Created pod: eval-conflicts-rho040-r0-091-lncmp
0.116,Event,ADDED,eval-conflicts-rho040-r0-091.18d52f416d65125a,reason=Completed count=1 msg=Job completed
0.1161,Event,ADDED,eval-conflicts-rho040-r0-092-wdtth.18d52f3bf99a5bc6,reason=Scheduled count=None msg=Successfully assigned compute/eval-conflicts-rho040-r0-092-wdtth to kind-worker
0.1163,Event,ADDED,eval-conflicts-rho040-r0-092-wdtth.18d52f3c1914f29e,"reason=Pulled count=1 msg=Container image ""busybox:musl"" already present on machine"
0.1165,Event,ADDED,eval-conflicts-rho040-r0-092-wdtth.18d52f3c1a281a5c,reason=Created count=1 msg=Created container: task
0.1167,Event,ADDED,eval-conflicts-rho040-r0-092-wdtth.18d52f3c21be7cfd,reason=Started count=1 msg=Started container task
0.1168,Event,ADDED,eval-conflicts-rho040-r0-092.18d52f3bf8a4fde4,reason=SuccessfulCreate count=1 msg=Created pod: eval-conflicts-rho040-r0-092-wdtth
0.1171,Event,ADDED,eval-conflicts-rho040-r0-092.18d52f41a9ced705,reason=Completed count=1 msg=Job completed
0.1172,Event,ADDED,eval-conflicts-rho040-r0-093-snjmj.18d52f3c3aff7d20,reason=Scheduled count=None msg=Successfully assigned compute/eval-conflicts-rho040-r0-093-snjmj to kind-worker
0.1174,Event,ADDED,eval-conflicts-rho040-r0-093-snjmj.18d52f3c5d40ff0c,"reason=Pulled count=1 msg=Container image ""busybox:musl"" already present on machine"
0.1176,Event,ADDED,eval-conflicts-rho040-r0-093-snjmj.18d52f3c5e5ca23a,reason=Created count=1 msg=Created container: task
0.1177,Event,ADDED,eval-conflicts-rho040-r0-093-snjmj.18d52f3c64054216,reason=Started count=1 msg=Started container task
0.118,Event,ADDED,eval-conflicts-rho040-r0-093.18d52f3c39e7d4f7,reason=SuccessfulCreate count=1 msg=Created pod: eval-conflicts-rho040-r0-093-snjmj
0.1182,Event,ADDED,eval-conflicts-rho040-r0-093.18d52f41dae856ef,reason=Completed count=1 msg=Job completed
0.1188,Event,ADDED,eval-conflicts-rho040-r0-094-7z5km.18d52f3c72141d99,reason=Scheduled count=None msg=Successfully assigned compute/eval-conflicts-rho040-r0-094-7z5km to kind-worker
0.1191,Event,ADDED,eval-conflicts-rho040-r0-094-7z5km.18d52f3c8b885f7c,"reason=Pulled count=1 msg=Container image ""busybox:musl"" already present on machine"
0.1193,Event,ADDED,eval-conflicts-rho040-r0-094-7z5km.18d52f3c8cba04d9,reason=Created count=1 msg=Created container: task
0.1195,Event,ADDED,eval-conflicts-rho040-r0-094-7z5km.18d52f3c9417490d,reason=Started count=1 msg=Started container task
0.1198,Event,ADDED,eval-conflicts-rho040-r0-094.18d52f3c71245eec,reason=SuccessfulCreate count=1 msg=Created pod: eval-conflicts-rho040-r0-094-7z5km
0.12,Event,ADDED,eval-conflicts-rho040-r0-094.18d52f4216d44182,reason=Completed count=1 msg=Job completed
0.1202,Event,ADDED,eval-conflicts-rho040-r0-095-w7xzp.18d52f3cac3e75e8,reason=Scheduled count=None msg=Successfully assigned compute/eval-conflicts-rho040-r0-095-w7xzp to kind-worker
0.1205,Event,ADDED,eval-conflicts-rho040-r0-095-w7xzp.18d52f3cc7b05426,"reason=Pulled count=1 msg=Container image ""busybox:musl"" already present on machine"
0.1207,Event,ADDED,eval-conflicts-rho040-r0-095-w7xzp.18d52f3cc8e10838,reason=Created count=1 msg=Created container: task
0.1209,Event,ADDED,eval-conflicts-rho040-r0-095-w7xzp.18d52f3cd105a78d,reason=Started count=1 msg=Started container task
0.121,Event,ADDED,eval-conflicts-rho040-r0-095.18d52f3cab3e32f1,reason=SuccessfulCreate count=1 msg=Created pod: eval-conflicts-rho040-r0-095-w7xzp
0.1213,Event,ADDED,eval-conflicts-rho040-r0-095.18d52f4254895c93,reason=Completed count=1 msg=Job completed
0.1214,Event,ADDED,eval-conflicts-rho040-r0-096-z6gsq.18d52f3cee11243d,reason=Scheduled count=None msg=Successfully assigned compute/eval-conflicts-rho040-r0-096-z6gsq to kind-worker
0.1216,Event,ADDED,eval-conflicts-rho040-r0-096-z6gsq.18d52f3d0cc69a55,"reason=Pulled count=1 msg=Container image ""busybox:musl"" already present on machine"
0.1218,Event,ADDED,eval-conflicts-rho040-r0-096-z6gsq.18d52f3d0e013bb8,reason=Created count=1 msg=Created container: task
0.122,Event,ADDED,eval-conflicts-rho040-r0-096-z6gsq.18d52f3d132dc469,reason=Started count=1 msg=Started container task
0.1221,Event,ADDED,eval-conflicts-rho040-r0-096.18d52f3ced152703,reason=SuccessfulCreate count=1 msg=Created pod: eval-conflicts-rho040-r0-096-z6gsq
0.1223,Event,ADDED,eval-conflicts-rho040-r0-096.18d52f4291b6ad90,reason=Completed count=1 msg=Job completed
0.1225,Event,ADDED,eval-conflicts-rho040-r0-097-v4bbv.18d52f3d26c8b26e,reason=Scheduled count=None msg=Successfully assigned compute/eval-conflicts-rho040-r0-097-v4bbv to kind-worker
0.1226,Event,ADDED,eval-conflicts-rho040-r0-097-v4bbv.18d52f3d44a1d5f3,"reason=Pulled count=1 msg=Container image ""busybox:musl"" already present on machine"
0.1228,Event,ADDED,eval-conflicts-rho040-r0-097-v4bbv.18d52f3d46052341,reason=Created count=1 msg=Created container: task
0.123,Event,ADDED,eval-conflicts-rho040-r0-097-v4bbv.18d52f3d4ed0dd11,reason=Started count=1 msg=Started container task
0.1233,Event,ADDED,eval-conflicts-rho040-r0-097.18d52f3d25c5145b,reason=SuccessfulCreate count=1 msg=Created pod: eval-conflicts-rho040-r0-097-v4bbv
0.1235,Event,ADDED,eval-conflicts-rho040-r0-097.18d52f42cdaa978c,reason=Completed count=1 msg=Job completed
0.1237,Event,ADDED,eval-conflicts-rho040-r0-098-624vc.18d52f3d5efa0c24,reason=Scheduled count=None msg=Successfully assigned compute/eval-conflicts-rho040-r0-098-624vc to kind-worker4
0.1239,Event,ADDED,eval-conflicts-rho040-r0-098-624vc.18d52f3d7bd71e7a,"reason=Pulled count=1 msg=Container image ""busybox:musl"" already present on machine"
0.1242,Event,ADDED,eval-conflicts-rho040-r0-098-624vc.18d52f3d7d0ddfb5,reason=Created count=1 msg=Created container: task
0.1243,Event,ADDED,eval-conflicts-rho040-r0-098-624vc.18d52f3d85133912,reason=Started count=1 msg=Started container task
0.1245,Event,ADDED,eval-conflicts-rho040-r0-098.18d52f3d5e03ea61,reason=SuccessfulCreate count=1 msg=Created pod: eval-conflicts-rho040-r0-098-624vc
0.1248,Event,ADDED,eval-conflicts-rho040-r0-098.18d52f42b9759849,reason=Completed count=1 msg=Job completed
0.125,Event,ADDED,eval-conflicts-rho040-r0-099-7blkj.18d52f3d9d32413d,reason=Scheduled count=None msg=Successfully assigned compute/eval-conflicts-rho040-r0-099-7blkj to kind-worker
0.1251,Event,ADDED,eval-conflicts-rho040-r0-099-7blkj.18d52f3dc481dad0,"reason=Pulled count=1 msg=Container image ""busybox:musl"" already present on machine"
0.1253,Event,ADDED,eval-conflicts-rho040-r0-099-7blkj.18d52f3dc5c1370d,reason=Created count=1 msg=Created container: task
0.1255,Event,ADDED,eval-conflicts-rho040-r0-099-7blkj.18d52f3dcf7cd8ca,reason=Started count=1 msg=Started container task
0.1257,Event,ADDED,eval-conflicts-rho040-r0-099.18d52f3d9c23fb66,reason=SuccessfulCreate count=1 msg=Created pod: eval-conflicts-rho040-r0-099-7blkj
0.1259,Event,ADDED,eval-conflicts-rho040-r0-099.18d52f434befda56,reason=Completed count=1 msg=Job completed
0.126,Event,ADDED,eval-conflicts-rho040-r0-100-8w6x2.18d52f3ddadf1e28,reason=Scheduled count=None msg=Successfully assigned compute/eval-conflicts-rho040-r0-100-8w6x2 to kind-worker4
0.1262,Event,ADDED,eval-conflicts-rho040-r0-100-8w6x2.18d52f3e086d03a3,"reason=Pulled count=1 msg=Container image ""busybox:musl"" already present on machine"
0.1264,Event,ADDED,eval-conflicts-rho040-r0-100-8w6x2.18d52f3e09a06583,reason=Created count=1 msg=Created container: task
0.1265,Event,ADDED,eval-conflicts-rho040-r0-100-8w6x2.18d52f3e1a8eb718,reason=Started count=1 msg=Started container task
0.1268,Event,ADDED,eval-conflicts-rho040-r0-100.18d52f3dd9d57c34,reason=SuccessfulCreate count=1 msg=Created pod: eval-conflicts-rho040-r0-100-8w6x2
0.127,Event,ADDED,eval-conflicts-rho040-r0-100.18d52f43a3dfcf11,reason=Completed count=1 msg=Job completed
0.1272,Event,ADDED,eval-conflicts-rho040-r0-101-lhjhx.18d52f3e1d4420da,reason=Scheduled count=None msg=Successfully assigned compute/eval-conflicts-rho040-r0-101-lhjhx to kind-worker4
0.1278,Event,ADDED,eval-conflicts-rho040-r0-101-lhjhx.18d52f3e3ce91ffd,"reason=Pulled count=1 msg=Container image ""busybox:musl"" already present on machine"
0.128,Event,ADDED,eval-conflicts-rho040-r0-101-lhjhx.18d52f3e3e07b408,reason=Created count=1 msg=Created container: task
0.1282,Event,ADDED,eval-conflicts-rho040-r0-101-lhjhx.18d52f3e422db544,reason=Started count=1 msg=Started container task
0.1284,Event,ADDED,eval-conflicts-rho040-r0-101.18d52f3e1c466a66,reason=SuccessfulCreate count=1 msg=Created pod: eval-conflicts-rho040-r0-101-lhjhx
0.1288,Event,ADDED,eval-conflicts-rho040-r0-101.18d52f43e09a1c80,reason=Completed count=1 msg=Job completed
0.1289,Event,ADDED,eval-conflicts-rho040-r0-102-d9cjb.18d52f3e50bf3fe8,reason=Scheduled count=None msg=Successfully assigned compute/eval-conflicts-rho040-r0-102-d9cjb to kind-worker
0.1291,Event,ADDED,eval-conflicts-rho040-r0-102-d9cjb.18d52f3e72547898,"reason=Pulled count=1 msg=Container image ""busybox:musl"" already present on machine"
0.1293,Event,ADDED,eval-conflicts-rho040-r0-102-d9cjb.18d52f3e738d4a82,reason=Created count=1 msg=Created container: task
0.1295,Event,ADDED,eval-conflicts-rho040-r0-102-d9cjb.18d52f3e7d3f8722,reason=Started count=1 msg=Started container task
0.1297,Event,ADDED,eval-conflicts-rho040-r0-102.18d52f3e4fca8394,reason=SuccessfulCreate count=1 msg=Created pod: eval-conflicts-rho040-r0-102-d9cjb
0.1299,Event,ADDED,eval-conflicts-rho040-r0-102.18d52f43f6d2fa17,reason=Completed count=1 msg=Job completed
0.13,Event,ADDED,eval-conflicts-rho040-r0-103-bbh2r.18d52f3e8864019e,reason=Scheduled count=None msg=Successfully assigned compute/eval-conflicts-rho040-r0-103-bbh2r to kind-worker
0.1302,Event,ADDED,eval-conflicts-rho040-r0-103-bbh2r.18d52f3ea90f089a,"reason=Pulled count=1 msg=Container image ""busybox:musl"" already present on machine"
0.1304,Event,ADDED,eval-conflicts-rho040-r0-103-bbh2r.18d52f3eaa2627b8,reason=Created count=1 msg=Created container: task
0.1306,Event,ADDED,eval-conflicts-rho040-r0-103-bbh2r.18d52f3eb01fe4f4,reason=Started count=1 msg=Started container task
0.1308,Event,ADDED,eval-conflicts-rho040-r0-103.18d52f3e87adf9d0,reason=SuccessfulCreate count=1 msg=Created pod: eval-conflicts-rho040-r0-103-bbh2r
0.1309,Event,ADDED,eval-conflicts-rho040-r0-103.18d52f4437d1a31a,reason=Completed count=1 msg=Job completed
0.1311,Event,ADDED,eval-conflicts-rho040-r0-104-dp8xq.18d52f3ec33cac10,"reason=FailedScheduling count=None msg=0/6 nodes are available: 6 node(s) had untolerated taint(s). no new claims to deallocate, preemption: 0/6 nodes are available: 6 Preemption is not helpful for scheduling."
0.1312,Event,ADDED,eval-conflicts-rho040-r0-104-dp8xq.18d52f400263f147,reason=Scheduled count=None msg=Successfully assigned compute/eval-conflicts-rho040-r0-104-dp8xq to kind-worker2
0.1314,Event,ADDED,eval-conflicts-rho040-r0-104-dp8xq.18d52f401cc9ade0,"reason=Pulled count=1 msg=Container image ""busybox:musl"" already present on machine"
0.1316,Event,ADDED,eval-conflicts-rho040-r0-104-dp8xq.18d52f401ec5ad1b,reason=Created count=1 msg=Created container: task
0.1318,Event,ADDED,eval-conflicts-rho040-r0-104-dp8xq.18d52f402691bb76,reason=Started count=1 msg=Started container task
0.132,Event,ADDED,eval-conflicts-rho040-r0-104.18d52f3ec334ca16,reason=SuccessfulCreate count=1 msg=Created pod: eval-conflicts-rho040-r0-104-dp8xq
0.1321,Event,ADDED,eval-conflicts-rho040-r0-104.18d52f459ca8039e,reason=Completed count=1 msg=Job completed
0.1324,Event,ADDED,eval-conflicts-rho040-r0-105-7plvx.18d52f3f0048d520,"reason=FailedScheduling count=None msg=0/6 nodes are available: 6 node(s) had untolerated taint(s). no new claims to deallocate, preemption: 0/6 nodes are available: 6 Preemption is not helpful for scheduling."
0.1326,Event,ADDED,eval-conflicts-rho040-r0-105-7plvx.18d52f4002e9b016,reason=Scheduled count=None msg=Successfully assigned compute/eval-conflicts-rho040-r0-105-7plvx to kind-worker2
0.1329,Event,ADDED,eval-conflicts-rho040-r0-105-7plvx.18d52f401ec8148b,"reason=Pulled count=1 msg=Container image ""busybox:musl"" already present on machine"
0.133,Event,ADDED,eval-conflicts-rho040-r0-105-7plvx.18d52f4021b9afb9,reason=Created count=1 msg=Created container: task
0.1332,Event,ADDED,eval-conflicts-rho040-r0-105-7plvx.18d52f40264ec7f6,reason=Started count=1 msg=Started container task
0.1335,Event,ADDED,eval-conflicts-rho040-r0-105.18d52f3f003ddd08,reason=SuccessfulCreate count=1 msg=Created pod: eval-conflicts-rho040-r0-105-7plvx
0.1336,Event,ADDED,eval-conflicts-rho040-r0-105.18d52f459d40fe18,reason=Completed count=1 msg=Job completed
0.1338,Event,ADDED,eval-conflicts-rho040-r0-106-d9f9j.18d52f3f3c6fe7b2,"reason=FailedScheduling count=None msg=0/6 nodes are available: 6 node(s) had untolerated taint(s). no new claims to deallocate, preemption: 0/6 nodes are available: 6 Preemption is not helpful for scheduling."
0.1339,Event,ADDED,eval-conflicts-rho040-r0-106-d9f9j.18d52f4003532a39,reason=Scheduled count=None msg=Successfully assigned compute/eval-conflicts-rho040-r0-106-d9f9j to kind-worker2
0.1341,Event,ADDED,eval-conflicts-rho040-r0-106-d9f9j.18d52f401e43786d,"reason=Pulled count=1 msg=Container image ""busybox:musl"" already present on machine"
0.1343,Event,ADDED,eval-conflicts-rho040-r0-106-d9f9j.18d52f4020a0a5a1,reason=Created count=1 msg=Created container: task
0.1344,Event,ADDED,eval-conflicts-rho040-r0-106-d9f9j.18d52f40264a0cb7,reason=Started count=1 msg=Started container task
0.1346,Event,ADDED,eval-conflicts-rho040-r0-106.18d52f3f3c60caf2,reason=SuccessfulCreate count=1 msg=Created pod: eval-conflicts-rho040-r0-106-d9f9j
0.1348,Event,ADDED,eval-conflicts-rho040-r0-106.18d52f459d1224bf,reason=Completed count=1 msg=Job completed
0.1349,Event,ADDED,eval-conflicts-rho040-r0-107-zhl4z.18d52f3f7b33e8d0,"reason=FailedScheduling count=None msg=0/6 nodes are available: 6 node(s) had untolerated taint(s). no new claims to deallocate, preemption: 0/6 nodes are available: 6 Preemption is not helpful for scheduling."
0.1351,Event,ADDED,eval-conflicts-rho040-r0-107-zhl4z.18d52f40030583e9,"reason=FailedScheduling count=None msg=0/6 nodes are available: 1 c_wall violated: 2 conflicting context pair(s) with node memory, 5 node(s) had untolerated taint(s). no new claims to deallocate, preemption: 0/6 nodes are available: 1 No preemption victims found for incoming pod, 5 Preemption is not helpful for scheduling."
0.1353,Event,ADDED,eval-conflicts-rho040-r0-107-zhl4z.18d52f400415e433,"reason=FailedScheduling count=None msg=0/6 nodes are available: 1 c_wall violated: 2 conflicting context pair(s) with node memory, 5 node(s) had untolerated taint(s). no new claims to deallocate, preemption: 0/6 nodes are available: 1 No preemption victims found for incoming pod, 5 Preemption is not helpful for scheduling."
0.1354,Event,ADDED,eval-conflicts-rho040-r0-107-zhl4z.18d52f401cf8d27a,reason=Scheduled count=None msg=Successfully assigned compute/eval-conflicts-rho040-r0-107-zhl4z to kind-worker3
0.1356,Event,ADDED,eval-conflicts-rho040-r0-107-zhl4z.18d52f403caa2e68,"reason=Pulled count=1 msg=Container image ""busybox:musl"" already present on machine"
0.1358,Event,ADDED,eval-conflicts-rho040-r0-107-zhl4z.18d52f403e2e3cce,reason=Created count=1 msg=Created container: task
0.136,Event,ADDED,eval-conflicts-rho040-r0-107-zhl4z.18d52f4044ee0162,reason=Started count=1 msg=Started container task
0.1363,Event,ADDED,eval-conflicts-rho040-r0-107.18d52f3f7b2a0a9e,reason=SuccessfulCreate count=1 msg=Created pod: eval-conflicts-rho040-r0-107-zhl4z
0.1364,Event,ADDED,eval-conflicts-rho040-r0-107.18d52f45a98cfbfd,reason=Completed count=1 msg=Job completed
0.1366,Event,ADDED,eval-conflicts-rho040-r0-108-v7rtw.18d52f3fbc5e983f,"reason=FailedScheduling count=None msg=0/6 nodes are available: 6 node(s) had untolerated taint(s). no new claims to deallocate, preemption: 0/6 nodes are available: 6 Preemption is not helpful for scheduling."
0.1367,Event,ADDED,eval-conflicts-rho040-r0-108-v7rtw.18d52f40080b1b43,reason=Scheduled count=None msg=Successfully assigned compute/eval-conflicts-rho040-r0-108-v7rtw to kind-worker2
0.1369,Event,ADDED,eval-conflicts-rho040-r0-108-v7rtw.18d52f401e9a16f9,"reason=Pulled count=1 msg=Container image ""busybox:musl"" already present on machine"
0.1371,Event,ADDED,eval-conflicts-rho040-r0-108-v7rtw.18d52f40212ea207,reason=Created count=1 msg=Created container: task
0.1373,Event,ADDED,eval-conflicts-rho040-r0-108-v7rtw.18d52f40264d2004,reason=Started count=1 msg=Started container task
0.1374,Event,ADDED,eval-conflicts-rho040-r0-108.18d52f3fbc551afd,reason=SuccessfulCreate count=1 msg=Created pod: eval-conflicts-rho040-r0-108-v7rtw
0.1376,Event,ADDED,eval-conflicts-rho040-r0-108.18d52f459d3f2aff,reason=Completed count=1 msg=Job completed
0.1377,Event,ADDED,eval-conflicts-rho040-r0-109-45hl8.18d52f3ffae87d12,"reason=FailedScheduling count=None msg=0/6 nodes are available: 6 node(s) had untolerated taint(s). no new claims to deallocate, preemption: 0/6 nodes are available: 6 Preemption is not helpful for scheduling."
0.1379,Event,ADDED,eval-conflicts-rho040-r0-109-45hl8.18d52f4008126a06,reason=Scheduled count=None msg=Successfully assigned compute/eval-conflicts-rho040-r0-109-45hl8 to kind-worker2
0.1381,Event,ADDED,eval-conflicts-rho040-r0-109-45hl8.18d52f401f10ded7,"reason=Pulled count=1 msg=Container image ""busybox:musl"" already present on machine"
0.1385,Event,ADDED,eval-conflicts-rho040-r0-109-45hl8.18d52f402227a259,reason=Created count=1 msg=Created container: task
0.1387,Event,ADDED,eval-conflicts-rho040-r0-109-45hl8.18d52f40264e82d6,reason=Started count=1 msg=Started container task
0.1389,Event,ADDED,eval-conflicts-rho040-r0-109.18d52f3ffad4cad0,reason=SuccessfulCreate count=1 msg=Created pod: eval-conflicts-rho040-r0-109-45hl8
0.139,Event,ADDED,eval-conflicts-rho040-r0-109.18d52f459d3f0162,reason=Completed count=1 msg=Job completed
0.1392,Event,ADDED,eval-conflicts-rho040-r0-110-p9pmx.18d52f403dfef1a6,reason=Scheduled count=None msg=Successfully assigned compute/eval-conflicts-rho040-r0-110-p9pmx to kind-worker3
0.1393,Event,ADDED,eval-conflicts-rho040-r0-110-p9pmx.18d52f40572a0ffa,"reason=Pulled count=1 msg=Container image ""busybox:musl"" already present on machine"
0.1395,Event,ADDED,eval-conflicts-rho040-r0-110-p9pmx.18d52f405859a154,reason=Created count=1 msg=Created container: task
0.1397,Event,ADDED,eval-conflicts-rho040-r0-110-p9pmx.18d52f405d349645,reason=Started count=1 msg=Started container task
0.1399,Event,ADDED,eval-conflicts-rho040-r0-110.18d52f403cbc8886,reason=SuccessfulCreate count=1 msg=Created pod: eval-conflicts-rho040-r0-110-p9pmx
0.14,Event,ADDED,eval-conflicts-rho040-r0-110.18d52f45a935404b,reason=Completed count=1 msg=Job completed
0.1402,Event,ADDED,eval-conflicts-rho040-r0-111-r86jl.18d52f4078942ba0,reason=Scheduled count=None msg=Successfully assigned compute/eval-conflicts-rho040-r0-111-r86jl to kind-worker3
0.1404,Event,ADDED,eval-conflicts-rho040-r0-111-r86jl.18d52f409ae77835,"reason=Pulled count=1 msg=Container image ""busybox:musl"" already present on machine"
0.1405,Event,ADDED,eval-conflicts-rho040-r0-111-r86jl.18d52f409c059617,reason=Created count=1 msg=Created container: task
0.1407,Event,ADDED,eval-conflicts-rho040-r0-111-r86jl.18d52f40a448cac7,reason=Started count=1 msg=Started container task
0.1409,Event,ADDED,eval-conflicts-rho040-r0-111.18d52f4077d401ef,reason=SuccessfulCreate count=1 msg=Created pod: eval-conflicts-rho040-r0-111-r86jl
0.1411,Event,ADDED,eval-conflicts-rho040-r0-111.18d52f46222a77de,reason=Completed count=1 msg=Job completed
0.1412,Event,ADDED,eval-conflicts-rho040-r0-112-2snf6.18d52f40a66d991a,reason=Scheduled count=None msg=Successfully assigned compute/eval-conflicts-rho040-r0-112-2snf6 to kind-worker3
0.1414,Event,ADDED,eval-conflicts-rho040-r0-112-2snf6.18d52f40c17967e7,"reason=Pulled count=1 msg=Container image ""busybox:musl"" already present on machine"
0.1416,Event,ADDED,eval-conflicts-rho040-r0-112-2snf6.18d52f40c2a1bbc3,reason=Created count=1 msg=Created container: task
0.1417,Event,ADDED,eval-conflicts-rho040-r0-112-2snf6.18d52f40d00bf06e,reason=Started count=1 msg=Started container task
0.1419,Event,ADDED,eval-conflicts-rho040-r0-112.18d52f40a5c8d0a2,reason=SuccessfulCreate count=1 msg=Created pod: eval-conflicts-rho040-r0-112-2snf6
0.1421,Event,ADDED,eval-conflicts-rho040-r0-112.18d52f465e0b6ed9,reason=Completed count=1 msg=Job completed
0.1422,Event,ADDED,eval-conflicts-rho040-r0-113-r9lvx.18d52f40e17ee572,"reason=FailedScheduling count=None msg=0/6 nodes are available: 1 c_wall violated: 2 conflicting context pair(s) with node memory, 1 c_wall violated: 3 conflicting context pair(s) with node memory, 4 node(s) had untolerated taint(s). no new claims to deallocate, preemption: 0/6 nodes are available: 2 No preemption victims found for incoming pod, 4 Preemption is not helpful for scheduling."
0.1424,Event,ADDED,eval-conflicts-rho040-r0-113-r9lvx.18d52f40e51d9c28,"reason=FailedScheduling count=None msg=0/6 nodes are available: 1 c_wall violated: 2 conflicting context pair(s) with node memory, 1 c_wall violated: 3 conflicting context pair(s) with node memory, 4 node(s) had untolerated taint(s). no new claims to deallocate, preemption: 0/6 nodes are available: 2 No preemption victims found for incoming pod, 4 Preemption is not helpful for scheduling."
0.1426,Event,ADDED,eval-conflicts-rho040-r0-113-r9lvx.18d52f438f77743c,reason=Scheduled count=None msg=Successfully assigned compute/eval-conflicts-rho040-r0-113-r9lvx to kind-worker5
0.1427,Event,ADDED,eval-conflicts-rho040-r0-113-r9lvx.18d52f43a9ada60e,"reason=Pulled count=1 msg=Container image ""busybox:musl"" already present on machine"
0.1429,Event,ADDED,eval-conflicts-rho040-r0-113-r9lvx.18d52f43ab9b4b9a,reason=Created count=1 msg=Created container: task
0.1431,Event,ADDED,eval-conflicts-rho040-r0-113-r9lvx.18d52f43aed958d5,reason=Started count=1 msg=Started container task
0.1432,Event,ADDED,eval-conflicts-rho040-r0-113.18d52f40e0f7be15,reason=SuccessfulCreate count=1 msg=Created pod: eval-conflicts-rho040-r0-113-r9lvx
0.1434,Event,ADDED,eval-conflicts-rho040-r0-113.18d52f491f907f3c,reason=Completed count=1 msg=Job completed
0.1436,Event,ADDED,eval-conflicts-rho040-r0-114-qcrv5.18d52f41185ab90e,reason=Scheduled count=None msg=Successfully assigned compute/eval-conflicts-rho040-r0-114-qcrv5 to kind-worker3
0.1437,Event,ADDED,eval-conflicts-rho040-r0-114-qcrv5.18d52f413a8ebf73,"reason=Pulled count=1 msg=Container image ""busybox:musl"" already present on machine"
0.1439,Event,ADDED,eval-conflicts-rho040-r0-114-qcrv5.18d52f413bc533b4,reason=Created count=1 msg=Created container: task
0.1441,Event,ADDED,eval-conflicts-rho040-r0-114-qcrv5.18d52f4146ebaf85,reason=Started count=1 msg=Started container task
0.1443,Event,ADDED,eval-conflicts-rho040-r0-114.18d52f4117bafcdb,reason=SuccessfulCreate count=1 msg=Created pod: eval-conflicts-rho040-r0-114-qcrv5
0.1444,Event,ADDED,eval-conflicts-rho040-r0-114.18d52f46d62b2c7e,reason=Completed count=1 msg=Job completed
0.1446,Event,ADDED,eval-conflicts-rho040-r0-115-wrxj4.18d52f41536d90c9,"reason=FailedScheduling count=None msg=0/6 nodes are available: 1 c_wall violated: 1 conflicting context pair(s) with node memory, 1 c_wall violated: 2 conflicting context pair(s) with node memory, 4 node(s) had untolerated taint(s). no new claims to deallocate, preemption: 0/6 nodes are available: 2 No preemption victims found for incoming pod, 4 Preemption is not helpful for scheduling."
0.1448,Event,ADDED,eval-conflicts-rho040-r0-115-wrxj4.18d52f415415c335,"reason=FailedScheduling count=None msg=0/6 nodes are available: 1 c_wall violated: 1 conflicting context pair(s) with node memory, 1 c_wall violated: 2 conflicting context pair(s) with node memory, 4 node(s) had untolerated taint(s). no new claims to deallocate, preemption: 0/6 nodes are available: 2 No preemption victims found for incoming pod, 4 Preemption is not helpful for scheduling."
0.1449,Event,ADDED,eval-conflicts-rho040-r0-115-wrxj4.18d52f4395ca0c7a,reason=Scheduled count=None msg=Successfully assigned compute/eval-conflicts-rho040-r0-115-wrxj4 to kind-worker5
0.1451,Event,ADDED,eval-conflicts-rho040-r0-115-wrxj4.18d52f43af604e7c,"reason=Pulled count=1 msg=Container image ""busybox:musl"" already present on machine"
0.1452,Event,ADDED,eval-conflicts-rho040-r0-115-wrxj4.18d52f43b07eca03,reason=Created count=1 msg=Created container: task
0.1455,Event,ADDED,eval-conflicts-rho040-r0-115-wrxj4.18d52f43ba4ec680,reason=Started count=1 msg=Started container task
0.1457,Event,ADDED,eval-conflicts-rho040-r0-115.18d52f41530d7071,reason=SuccessfulCreate count=1 msg=Created pod: eval-conflicts-rho040-r0-115-wrxj4
0.1458,Event,ADDED,eval-conflicts-rho040-r0-115.18d52f495f32e736,reason=Completed count=1 msg=Job completed
0.146,Event,ADDED,eval-conflicts-rho040-r0-116-rrjf9.18d52f4198a7b877,reason=Scheduled count=None msg=Successfully assigned compute/eval-conflicts-rho040-r0-116-rrjf9 to kind-worker3
0.1462,Event,ADDED,eval-conflicts-rho040-r0-116-rrjf9.18d52f41b6390426,"reason=Pulled count=1 msg=Container image ""busybox:musl"" already present on machine"
0.1463,Event,ADDED,eval-conflicts-rho040-r0-116-rrjf9.18d52f41b889699b,reason=Created count=1 msg=Created container: task
0.1465,Event,ADDED,eval-conflicts-rho040-r0-116-rrjf9.18d52f41c01f7aa3,reason=Started count=1 msg=Started container task
0.1467,Event,ADDED,eval-conflicts-rho040-r0-116.18d52f4197eca593,reason=SuccessfulCreate count=1 msg=Created pod: eval-conflicts-rho040-r0-116-rrjf9
0.1468,Event,ADDED,eval-conflicts-rho040-r0-116.18d52f474a7c07c9,reason=Completed count=1 msg=Job completed
0.147,Event,ADDED,eval-conflicts-rho040-r0-117-6rgw5.18d52f41cce8b727,reason=Scheduled count=None msg=Successfully assigned compute/eval-conflicts-rho040-r0-117-6rgw5 to kind-worker3
0.1471,Event,ADDED,eval-conflicts-rho040-r0-117-6rgw5.18d52f41ed775a7e,"reason=Pulled count=1 msg=Container image ""busybox:musl"" already present on machine"
0.1473,Event,ADDED,eval-conflicts-rho040-r0-117-6rgw5.18d52f41eead6e58,reason=Created count=1 msg=Created container: task
0.1475,Event,ADDED,eval-conflicts-rho040-r0-117-6rgw5.18d52f41f447bbd1,reason=Started count=1 msg=Started container task
0.1476,Event,ADDED,eval-conflicts-rho040-r0-117.18d52f41cc29da87,reason=SuccessfulCreate count=1 msg=Created pod: eval-conflicts-rho040-r0-117-6rgw5
0.1478,Event,ADDED,eval-conflicts-rho040-r0-117.18d52f47872756e6,reason=Completed count=1 msg=Job completed
0.148,Event,ADDED,eval-conflicts-rho040-r0-118-g7wbc.18d52f4207c571a1,reason=Scheduled count=None msg=Successfully assigned compute/eval-conflicts-rho040-r0-118-g7wbc to kind-worker3
0.1482,Event,ADDED,eval-conflicts-rho040-r0-118-g7wbc.18d52f4225b17d86,"reason=Pulled count=1 msg=Container image ""busybox:musl"" already present on machine"
0.1484,Event,ADDED,eval-conflicts-rho040-r0-118-g7wbc.18d52f4226ee7bea,reason=Created count=1 msg=Created container: task
0.1486,Event,ADDED,eval-conflicts-rho040-r0-118-g7wbc.18d52f422c494b35,reason=Started count=1 msg=Started container task
0.1487,Event,ADDED,eval-conflicts-rho040-r0-118.18d52f4207019fc5,reason=SuccessfulCreate count=1 msg=Created pod: eval-conflicts-rho040-r0-118-g7wbc
0.1492,Event,ADDED,eval-conflicts-rho040-r0-118.18d52f47c4928039,reason=Completed count=1 msg=Job completed
0.1494,Event,ADDED,eval-conflicts-rho040-r0-119-flrjp.18d52f4242909f64,reason=Scheduled count=None msg=Successfully assigned compute/eval-conflicts-rho040-r0-119-flrjp to kind-worker2
0.1496,Event,ADDED,eval-conflicts-rho040-r0-119-flrjp.18d52f42602f68c6,"reason=Pulled count=1 msg=Container image ""busybox:musl"" already present on machine"
0.1497,Event,ADDED,eval-conflicts-rho040-r0-119-flrjp.18d52f426156c186,reason=Created count=1 msg=Created container: task
0.1501,Event,ADDED,eval-conflicts-rho040-r0-119-flrjp.18d52f426dc253ca,reason=Started count=1 msg=Started container task
0.1503,Event,ADDED,eval-conflicts-rho040-r0-119.18d52f4241603664,reason=SuccessfulCreate count=1 msg=Created pod: eval-conflicts-rho040-r0-119-flrjp
0.1505,Event,ADDED,eval-conflicts-rho040-r0-119.18d52f47ed9a46ac,reason=Completed count=1 msg=Job completed
0.1508,Event,ADDED,eval-conflicts-rho040-r0-120-c7cbn.18d52f4280375d4c,reason=Scheduled count=None msg=Successfully assigned compute/eval-conflicts-rho040-r0-120-c7cbn to kind-worker2
0.151,Event,ADDED,eval-conflicts-rho040-r0-120-c7cbn.18d52f429c603379,"reason=Pulled count=1 msg=Container image ""busybox:musl"" already present on machine"
0.1512,Event,ADDED,eval-conflicts-rho040-r0-120-c7cbn.18d52f429d749377,reason=Created count=1 msg=Created container: task
0.1513,Event,ADDED,eval-conflicts-rho040-r0-120-c7cbn.18d52f42a6a101d1,reason=Started count=1 msg=Started container task
0.1517,Event,ADDED,eval-conflicts-rho040-r0-120.18d52f427ec38db0,reason=SuccessfulCreate count=1 msg=Created pod: eval-conflicts-rho040-r0-120-c7cbn
0.1519,Event,ADDED,eval-conflicts-rho040-r0-120.18d52f4829d8c526,reason=Completed count=1 msg=Job completed
0.1521,Event,ADDED,eval-conflicts-rho040-r0-121-2g5t9.18d52f42ba1d3bbb,"reason=FailedScheduling count=None msg=0/6 nodes are available: 1 c_wall violated: 1 conflicting context pair(s) with node memory, 1 c_wall violated: 2 conflicting context pair(s) with node memory, 4 node(s) had untolerated taint(s). no new claims to deallocate, preemption: 0/6 nodes are available: 2 No preemption victims found for incoming pod, 4 Preemption is not helpful for scheduling."
0.1524,Event,ADDED,eval-conflicts-rho040-r0-121-2g5t9.18d52f42bac14671,"reason=FailedScheduling count=None msg=0/6 nodes are available: 1 c_wall violated: 1 conflicting context pair(s) with node memory, 1 c_wall violated: 2 conflicting context pair(s) with node memory, 4 node(s) had untolerated taint(s). no new claims to deallocate, preemption: 0/6 nodes are available: 2 No preemption victims found for incoming pod, 4 Preemption is not helpful for scheduling."
0.1526,Event,ADDED,eval-conflicts-rho040-r0-121-2g5t9.18d52f438f8931f8,reason=Scheduled count=None msg=Successfully assigned compute/eval-conflicts-rho040-r0-121-2g5t9 to kind-worker5
0.1528,Event,ADDED,eval-conflicts-rho040-r0-121-2g5t9.18d52f43a9d04fbb,"reason=Pulled count=1 msg=Container image ""busybox:musl"" already present on machine"
0.1531,Event,ADDED,eval-conflicts-rho040-r0-121-2g5t9.18d52f43ac1c4f55,reason=Created count=1 msg=Created container: task
0.1533,Event,ADDED,eval-conflicts-rho040-r0-121-2g5t9.18d52f43af594e14,reason=Started count=1 msg=Started container task
0.1535,Event,ADDED,eval-conflicts-rho040-r0-121.18d52f42b9af77b6,reason=SuccessfulCreate count=1 msg=Created pod: eval-conflicts-rho040-r0-121-2g5t9
0.1536,Event,ADDED,eval-conflicts-rho040-r0-121.18d52f491fc175b3,reason=Completed count=1 msg=Job completed
0.1539,Event,ADDED,eval-conflicts-rho040-r0-122-2f8gl.18d52f42f82ac949,reason=Scheduled count=None msg=Successfully assigned compute/eval-conflicts-rho040-r0-122-2f8gl to kind-worker2
0.1541,Event,ADDED,eval-conflicts-rho040-r0-122-2f8gl.18d52f431bb7b2d0,"reason=Pulled count=1 msg=Container image ""busybox:musl"" already present on machine"
0.1543,Event,ADDED,eval-conflicts-rho040-r0-122-2f8gl.18d52f431ccd793b,reason=Created count=1 msg=Created container: task
0.1544,Event,ADDED,eval-conflicts-rho040-r0-122-2f8gl.18d52f432664824c,reason=Started count=1 msg=Started container task
0.1548,Event,ADDED,eval-conflicts-rho040-r0-122.18d52f42f7466483,reason=SuccessfulCreate count=1 msg=Created pod: eval-conflicts-rho040-r0-122-2f8gl
0.155,Event,ADDED,eval-conflicts-rho040-r0-122.18d52f48a559ca16,reason=Completed count=1 msg=Job completed
0.1552,Event,ADDED,eval-conflicts-rho040-r0-123-g8zfw.18d52f433cc4b473,reason=Scheduled count=None msg=Successfully assigned compute/eval-conflicts-rho040-r0-123-g8zfw to kind-worker3
0.1555,Event,ADDED,eval-conflicts-rho040-r0-123-g8zfw.18d52f435e702ce4,"reason=Pulled count=1 msg=Container image ""busybox:musl"" already present on machine"
0.1557,Event,ADDED,eval-conflicts-rho040-r0-123-g8zfw.18d52f435f828ba2,reason=Created count=1 msg=Created container: task
0.1559,Event,ADDED,eval-conflicts-rho040-r0-123-g8zfw.18d52f43672740ee,reason=Started count=1 msg=Started container task
0.156,Event,ADDED,eval-conflicts-rho040-r0-123.18d52f4333531de3,reason=SuccessfulCreate count=1 msg=Created pod: eval-conflicts-rho040-r0-123-g8zfw
0.1563,Event,ADDED,eval-conflicts-rho040-r0-123.18d52f48f3d7ad25,reason=Completed count=1 msg=Job completed
0.1565,Event,ADDED,eval-conflicts-rho040-r0-124-t8dsp.18d52f4374e035a7,"reason=FailedScheduling count=None msg=0/6 nodes are available: 1 c_wall violated: 1 conflicting context pair(s) with node memory, 1 c_wall violated: 2 conflicting context pair(s) with node memory, 4 node(s) had untolerated taint(s). no new claims to deallocate, preemption: 0/6 nodes are available: 2 No preemption victims found for incoming pod, 4 Preemption is not helpful for scheduling."
0.1568,Event,ADDED,eval-conflicts-rho040-r0-124-t8dsp.18d52f437bfb33ae,"reason=FailedScheduling count=None msg=0/6 nodes are available: 1 c_wall violated: 1 conflicting context pair(s) with node memory, 1 c_wall violated: 2 conflicting context pair(s) with node memory, 4 node(s) had untolerated taint(s). no new claims to deallocate, preemption: 0/6 nodes are available: 2 No preemption victims found for incoming pod, 4 Preemption is not helpful for scheduling."
0.1571,Event,ADDED,eval-conflicts-rho040-r0-124-t8dsp.18d52f43819604dd,reason=Scheduled count=None msg=Successfully assigned compute/eval-conflicts-rho040-r0-124-t8dsp to kind-worker5
0.1572,Event,ADDED,eval-conflicts-rho040-r0-124-t8dsp.18d52f43a1ebfaa4,"reason=Pulled count=1 msg=Container image ""busybox:musl"" already present on machine"
0.1574,Event,ADDED,eval-conflicts-rho040-r0-124-t8dsp.18d52f43a42502ae,reason=Created count=1 msg=Created container: task
0.1576,Event,ADDED,eval-conflicts-rho040-r0-124-t8dsp.18d52f43a87753eb,reason=Started count=1 msg=Started container task
0.1578,Event,ADDED,eval-conflicts-rho040-r0-124.18d52f437192c048,reason=SuccessfulCreate count=1 msg=Created pod: eval-conflicts-rho040-r0-124-t8dsp
0.158,Event,ADDED,eval-conflicts-rho040-r0-124.18d52f48e470f123,reason=Completed count=1 msg=Job completed
0.1581,Event,ADDED,eval-conflicts-rho040-r0-125-xzl5c.18d52f43a83ca035,reason=Scheduled count=None msg=Successfully assigned compute/eval-conflicts-rho040-r0-125-xzl5c to kind-worker2
0.1583,Event,ADDED,eval-conflicts-rho040-r0-125-xzl5c.18d52f43c8f5c64f,"reason=Pulled count=1 msg=Container image ""busybox:musl"" already present on machine"
0.1585,Event,ADDED,eval-conflicts-rho040-r0-125-xzl5c.18d52f43ca1ae690,reason=Created count=1 msg=Created container: task
0.1587,Event,ADDED,eval-conflicts-rho040-r0-125-xzl5c.18d52f43d5a58b66,reason=Started count=1 msg=Started container task
0.1588,Event,ADDED,eval-conflicts-rho040-r0-125.18d52f43a6e6e89b,reason=SuccessfulCreate count=1 msg=Created pod: eval-conflicts-rho040-r0-125-xzl5c
0.159,Event,ADDED,eval-conflicts-rho040-r0-125.18d52f4957074431,reason=Completed count=1 msg=Job completed
0.1592,Event,ADDED,eval-conflicts-rho040-r0-126-sdsj9.18d52f43e39988ef,reason=Scheduled count=None msg=Successfully assigned compute/eval-conflicts-rho040-r0-126-sdsj9 to kind-worker2
0.1593,Event,ADDED,eval-conflicts-rho040-r0-126-sdsj9.18d52f43fdd4da0b,"reason=Pulled count=1 msg=Container image ""busybox:musl"" already present on machine"
0.1596,Event,ADDED,eval-conflicts-rho040-r0-126-sdsj9.18d52f43fef191a9,reason=Created count=1 msg=Created container: task
0.1599,Event,ADDED,eval-conflicts-rho040-r0-126-sdsj9.18d52f4409be84c3,reason=Started count=1 msg=Started container task
0.1601,Event,ADDED,eval-conflicts-rho040-r0-126.18d52f43e285818e,reason=SuccessfulCreate count=1 msg=Created pod: eval-conflicts-rho040-r0-126-sdsj9
0.1603,Event,ADDED,eval-conflicts-rho040-r0-126.18d52f499316e60d,reason=Completed count=1 msg=Job completed
0.1607,Event,ADDED,eval-conflicts-rho040-r0-127-krqbh.18d52f442329ca2b,reason=Scheduled count=None msg=Successfully assigned compute/eval-conflicts-rho040-r0-127-krqbh to kind-worker3
0.1609,Event,ADDED,eval-conflicts-rho040-r0-127-krqbh.18d52f4446133ff9,"reason=Pulled count=1 msg=Container image ""busybox:musl"" already present on machine"
0.161,Event,ADDED,eval-conflicts-rho040-r0-127-krqbh.18d52f44473a9c7f,reason=Created count=1 msg=Created container: task
0.1612,Event,ADDED,eval-conflicts-rho040-r0-127-krqbh.18d52f444e2b7673,reason=Started count=1 msg=Started container task
0.1615,Event,ADDED,eval-conflicts-rho040-r0-127.18d52f442227e161,reason=SuccessfulCreate count=1 msg=Created pod: eval-conflicts-rho040-r0-127-krqbh
0.1616,Event,ADDED,eval-conflicts-rho040-r0-127.18d52f49e19a398b,reason=Completed count=1 msg=Job completed
0.1618,Event,ADDED,eval-conflicts-rho040-r0-128-6jw8l.18d52f445d8389ac,reason=Scheduled count=None msg=Successfully assigned compute/eval-conflicts-rho040-r0-128-6jw8l to kind-worker5
0.1623,Event,ADDED,eval-conflicts-rho040-r0-128-6jw8l.18d52f4484556b3f,"reason=Pulled count=1 msg=Container image ""busybox:musl"" already present on machine"
0.1625,Event,ADDED,eval-conflicts-rho040-r0-128-6jw8l.18d52f448639c8f4,reason=Created count=1 msg=Created container: task
0.1627,Event,ADDED,eval-conflicts-rho040-r0-128-6jw8l.18d52f4489eb1bf7,reason=Started count=1 msg=Started container task
0.1629,Event,ADDED,eval-conflicts-rho040-r0-128.18d52f445c3c7c1f,reason=SuccessfulCreate count=1 msg=Created pod: eval-conflicts-rho040-r0-128-6jw8l
0.1631,Event,ADDED,eval-conflicts-rho040-r0-128.18d52f4a0b7de9ad,reason=Completed count=1 msg=Job completed
0.1632,Event,ADDED,eval-conflicts-rho040-r0-129-fj86b.18d52f449eb3e7fd,"reason=FailedScheduling count=None msg=0/6 nodes are available: 1 c_wall violated: 1 conflicting context pair(s) with node memory, 1 c_wall violated: 2 conflicting context pair(s) with node memory, 1 c_wall violated: 3 conflicting context pair(s) with node memory, 3 node(s) had untolerated taint(s). no new claims to deallocate, preemption: 0/6 nodes are available: 3 No preemption victims found for incoming pod, 3 Preemption is not helpful for scheduling."
0.1634,Event,ADDED,eval-conflicts-rho040-r0-129-fj86b.18d52f44a2b6f000,"reason=FailedScheduling count=None msg=0/6 nodes are available: 1 c_wall violated: 1 conflicting context pair(s) with node memory, 1 c_wall violated: 2 conflicting context pair(s) with node memory, 1 c_wall violated: 3 conflicting context pair(s) with node memory, 3 node(s) had untolerated taint(s). no new claims to deallocate, preemption: 0/6 nodes are available: 3 No preemption victims found for incoming pod, 3 Preemption is not helpful for scheduling."
0.1636,Event,ADDED,eval-conflicts-rho040-r0-129-fj86b.18d52f44b6c63ebe,"reason=FailedScheduling count=None msg=0/6 nodes are available: 1 c_wall violated: 1 conflicting context pair(s) with node memory, 1 c_wall violated: 2 conflicting context pair(s) with node memory, 4 node(s) had untolerated taint(s). no new claims to deallocate, preemption: 0/6 nodes are available: 2 No preemption victims found for incoming pod, 4 Preemption is not helpful for scheduling."
0.1638,Event,ADDED,eval-conflicts-rho040-r0-129-fj86b.18d52f44cd3bca11,"reason=FailedScheduling count=None msg=0/6 nodes are available: 1 c_wall violated: 1 conflicting context pair(s) with node memory, 5 node(s) had untolerated taint(s). no new claims to deallocate, preemption: 0/6 nodes are available: 1 No preemption victims found for incoming pod, 5 Preemption is not helpful for scheduling."
0.1639,Event,ADDED,eval-conflicts-rho040-r0-129-fj86b.18d52f4805ac0694,reason=Scheduled count=None msg=Successfully assigned compute/eval-conflicts-rho040-r0-129-fj86b to kind-worker4
0.1641,Event,ADDED,eval-conflicts-rho040-r0-129-fj86b.18d52f4822b2b863,"reason=Pulled count=1 msg=Container image ""busybox:musl"" already present on machine"
0.1643,Event,ADDED,eval-conflicts-rho040-r0-129-fj86b.18d52f48245dfc8e,reason=Created count=1 msg=Created container: task
0.1645,Event,ADDED,eval-conflicts-rho040-r0-129-fj86b.18d52f482b094966,reason=Started count=1 msg=Started container task
0.1646,Event,ADDED,eval-conflicts-rho040-r0-129.18d52f449dec2617,reason=SuccessfulCreate count=1 msg=Created pod: eval-conflicts-rho040-r0-129-fj86b
0.1648,Event,ADDED,eval-conflicts-rho040-r0-129.18d52f4e09722969,reason=Completed count=1 msg=Job completed
0.165,Event,ADDED,eval-conflicts-rho040-r0-130-q4zkb.18d52f44d5f648ab,"reason=FailedScheduling count=None msg=0/6 nodes are available: 1 c_wall violated: 1 conflicting context pair(s) with node memory, 5 node(s) had untolerated taint(s). no new claims to deallocate, preemption: 0/6 nodes are available: 1 No preemption victims found for incoming pod, 5 Preemption is not helpful for scheduling."
0.1652,Event,ADDED,eval-conflicts-rho040-r0-130-q4zkb.18d52f44d680825b,"reason=FailedScheduling count=None msg=0/6 nodes are available: 1 c_wall violated: 1 conflicting context pair(s) with node memory, 5 node(s) had untolerated taint(s). no new claims to deallocate, preemption: 0/6 nodes are available: 1 No preemption victims found for incoming pod, 5 Preemption is not helpful for scheduling."
0.1653,Event,ADDED,eval-conflicts-rho040-r0-130-q4zkb.18d52f482fa6f142,reason=Scheduled count=None msg=Successfully assigned compute/eval-conflicts-rho040-r0-130-q4zkb to kind-worker
0.1655,Event,ADDED,eval-conflicts-rho040-r0-130-q4zkb.18d52f484d9964c6,"reason=Pulled count=1 msg=Container image ""busybox:musl"" already present on machine"
0.1657,Event,ADDED,eval-conflicts-rho040-r0-130-q4zkb.18d52f485289061a,reason=Created count=1 msg=Created container: task
0.1659,Event,ADDED,eval-conflicts-rho040-r0-130-q4zkb.18d52f485a87cfb4,reason=Started count=1 msg=Started container task
0.166,Event,ADDED,eval-conflicts-rho040-r0-130.18d52f44d5b27342,reason=SuccessfulCreate count=1 msg=Created pod: eval-conflicts-rho040-r0-130-q4zkb
0.1662,Event,ADDED,eval-conflicts-rho040-r0-130.18d52f4d92d17183,reason=Completed count=1 msg=Job completed
0.1664,Event,ADDED,eval-conflicts-rho040-r0-131-2t2nv.18d52f450d426b66,reason=Scheduled count=None msg=Successfully assigned compute/eval-conflicts-rho040-r0-131-2t2nv to kind-worker5
0.1665,Event,ADDED,eval-conflicts-rho040-r0-131-2t2nv.18d52f452bab7f16,"reason=Pulled count=1 msg=Container image ""busybox:musl"" already present on machine"
0.1667,Event,ADDED,eval-conflicts-rho040-r0-131-2t2nv.18d52f452cf5cbd5,reason=Created count=1 msg=Created container: task
0.1669,Event,ADDED,eval-conflicts-rho040-r0-131-2t2nv.18d52f45313cfe87,reason=Started count=1 msg=Started container task
0.167,Event,ADDED,eval-conflicts-rho040-r0-131.18d52f450cbac646,reason=SuccessfulCreate count=1 msg=Created pod: eval-conflicts-rho040-r0-131-2t2nv
0.1672,Event,ADDED,eval-conflicts-rho040-r0-131.18d52f4ac791fe96,reason=Completed count=1 msg=Job completed
0.1674,Event,ADDED,eval-conflicts-rho040-r0-132-zgtlp.18d52f454ddbb369,"reason=FailedScheduling count=None msg=0/6 nodes are available: 1 c_wall violated: 2 conflicting context pair(s) with node memory, 5 node(s) had untolerated taint(s). no new claims to deallocate, preemption: 0/6 nodes are available: 1 No preemption victims found for incoming pod, 5 Preemption is not helpful for scheduling."
0.1675,Event,ADDED,eval-conflicts-rho040-r0-132-zgtlp.18d52f454e542590,"reason=FailedScheduling count=None msg=0/6 nodes are available: 1 c_wall violated: 2 conflicting context pair(s) with node memory, 5 node(s) had untolerated taint(s). no new claims to deallocate, preemption: 0/6 nodes are available: 1 No preemption victims found for incoming pod, 5 Preemption is not helpful for scheduling."
0.1677,Event,ADDED,eval-conflicts-rho040-r0-132-zgtlp.18d52f4806cf62cd,reason=Scheduled count=None msg=Successfully assigned compute/eval-conflicts-rho040-r0-132-zgtlp to kind-worker4
0.1679,Event,ADDED,eval-conflicts-rho040-r0-132-zgtlp.18d52f4822af5b04,"reason=Pulled count=1 msg=Container image ""busybox:musl"" already present on machine"
0.168,Event,ADDED,eval-conflicts-rho040-r0-132-zgtlp.18d52f48248fad4a,reason=Created count=1 msg=Created container: task
0.1682,Event,ADDED,eval-conflicts-rho040-r0-132-zgtlp.18d52f4827fd66c1,reason=Started count=1 msg=Started container task
0.1684,Event,ADDED,eval-conflicts-rho040-r0-132.18d52f454d9a44c2,reason=SuccessfulCreate count=1 msg=Created pod: eval-conflicts-rho040-r0-132-zgtlp
0.1685,Event,ADDED,eval-conflicts-rho040-r0-132.18d52f4dbb0ac94f,reason=Completed count=1 msg=Job completed
0.1687,Event,ADDED,eval-conflicts-rho040-r0-133-7vbmn.18d52f4584b236b4,"reason=FailedScheduling count=None msg=0/6 nodes are available: 1 c_wall violated: 1 conflicting context pair(s) with node memory, 5 node(s) had untolerated taint(s). no new claims to deallocate, preemption: 0/6 nodes are available: 1 No preemption victims found for incoming pod, 5 Preemption is not helpful for scheduling."
0.1691,Event,ADDED,eval-conflicts-rho040-r0-133-7vbmn.18d52f45852df9c5,"reason=FailedScheduling count=None msg=0/6 nodes are available: 1 c_wall violated: 1 conflicting context pair(s) with node memory, 5 node(s) had untolerated taint(s). no new claims to deallocate, preemption: 0/6 nodes are available: 1 No preemption victims found for incoming pod, 5 Preemption is not helpful for scheduling."
0.1695,Event,ADDED,eval-conflicts-rho040-r0-133-7vbmn.18d52f482fd6de7f,reason=Scheduled count=None msg=Successfully assigned compute/eval-conflicts-rho040-r0-133-7vbmn to kind-worker
0.1698,Event,ADDED,eval-conflicts-rho040-r0-133-7vbmn.18d52f484dba3fda,"reason=Pulled count=1 msg=Container image ""busybox:musl"" already present on machine"
0.1703,Event,ADDED,eval-conflicts-rho040-r0-133-7vbmn.18d52f48517af1e2,reason=Created count=1 msg=Created container: task
0.1705,Event,ADDED,eval-conflicts-rho040-r0-133-7vbmn.18d52f4866e37c01,reason=Started count=1 msg=Started container task
0.1709,Event,ADDED,eval-conflicts-rho040-r0-133.18d52f458477401f,reason=SuccessfulCreate count=1 msg=Created pod: eval-conflicts-rho040-r0-133-7vbmn
0.1711,Event,ADDED,eval-conflicts-rho040-r0-133.18d52f4e2d6b6427,reason=Completed count=1 msg=Job completed
0.1715,Event,ADDED,eval-conflicts-rho040-r0-134-5j2bj.18d52f45bfaf55ed,"reason=FailedScheduling count=None msg=0/6 nodes are available: 1 c_wall violated: 2 conflicting context pair(s) with node memory, 5 node(s) had untolerated taint(s). no new claims to deallocate, preemption: 0/6 nodes are available: 1 No preemption victims found for incoming pod, 5 Preemption is not helpful for scheduling."
0.1717,Event,ADDED,eval-conflicts-rho040-r0-134-5j2bj.18d52f45c0405ca7,"reason=FailedScheduling count=None msg=0/6 nodes are available: 1 c_wall violated: 2 conflicting context pair(s) with node memory, 5 node(s) had untolerated taint(s). no new claims to deallocate, preemption: 0/6 nodes are available: 1 No preemption victims found for incoming pod, 5 Preemption is not helpful for scheduling."
0.1719,Event,ADDED,eval-conflicts-rho040-r0-134-5j2bj.18d52f48155b1415,reason=Scheduled count=None msg=Successfully assigned compute/eval-conflicts-rho040-r0-134-5j2bj to kind-worker4
0.1726,Event,ADDED,eval-conflicts-rho040-r0-134-5j2bj.18d52f482fa0dfeb,"reason=Pulled count=1 msg=Container image ""busybox:musl"" already present on machine"
0.173,Event,ADDED,eval-conflicts-rho040-r0-134-5j2bj.18d52f4831299b13,reason=Created count=1 msg=Created container: task
0.1732,Event,ADDED,eval-conflicts-rho040-r0-134-5j2bj.18d52f4839ff85bb,reason=Started count=1 msg=Started container task
0.1735,Event,ADDED,eval-conflicts-rho040-r0-134.18d52f45bf71a2fd,reason=SuccessfulCreate count=1 msg=Created pod: eval-conflicts-rho040-r0-134-5j2bj
0.1737,Event,ADDED,eval-conflicts-rho040-r0-134.18d52f4d7b8fa298,reason=Completed count=1 msg=Job completed
0.1739,Event,ADDED,eval-conflicts-rho040-r0-135-nt4zg.18d52f45fcd2ec32,"reason=FailedScheduling count=None msg=0/6 nodes are available: 1 c_wall violated: 1 conflicting context pair(s) with node memory, 5 node(s) had untolerated taint(s). no new claims to deallocate, preemption: 0/6 nodes are available: 1 No preemption victims found for incoming pod, 5 Preemption is not helpful for scheduling."
0.1741,Event,ADDED,eval-conflicts-rho040-r0-135-nt4zg.18d52f45fdb62936,"reason=FailedScheduling count=None msg=0/6 nodes are available: 1 c_wall violated: 1 conflicting context pair(s) with node memory, 5 node(s) had untolerated taint(s). no new claims to deallocate, preemption: 0/6 nodes are available: 1 No preemption victims found for incoming pod, 5 Preemption is not helpful for scheduling."
0.1744,Event,ADDED,eval-conflicts-rho040-r0-135-nt4zg.18d52f482fd6ba93,reason=Scheduled count=None msg=Successfully assigned compute/eval-conflicts-rho040-r0-135-nt4zg to kind-worker
0.1746,Event,ADDED,eval-conflicts-rho040-r0-135-nt4zg.18d52f484de33a32,"reason=Pulled count=1 msg=Container image ""busybox:musl"" already present on machine"
0.1748,Event,ADDED,eval-conflicts-rho040-r0-135-nt4zg.18d52f4852b02f9a,reason=Created count=1 msg=Created container: task
0.1752,Event,ADDED,eval-conflicts-rho040-r0-135-nt4zg.18d52f485a8eba4a,reason=Started count=1 msg=Started container task
0.1754,Event,ADDED,eval-conflicts-rho040-r0-135.18d52f45fc930699,reason=SuccessfulCreate count=1 msg=Created pod: eval-conflicts-rho040-r0-135-nt4zg
0.1756,Event,ADDED,eval-conflicts-rho040-r0-135.18d52f4e1249de41,reason=Completed count=1 msg=Job completed
0.1757,Event,ADDED,eval-conflicts-rho040-r0-136-bhg94.18d52f46385c4900,"reason=FailedScheduling count=None msg=0/6 nodes are available: 1 c_wall violated: 2 conflicting context pair(s) with node memory, 5 node(s) had untolerated taint(s). no new claims to deallocate, preemption: 0/6 nodes are available: 1 No preemption victims found for incoming pod, 5 Preemption is not helpful for scheduling."
0.1761,Event,ADDED,eval-conflicts-rho040-r0-136-bhg94.18d52f4639081893,"reason=FailedScheduling count=None msg=0/6 nodes are available: 1 c_wall violated: 2 conflicting context pair(s) with node memory, 5 node(s) had untolerated taint(s). no new claims to deallocate, preemption: 0/6 nodes are available: 1 No preemption victims found for incoming pod, 5 Preemption is not helpful for scheduling."
0.1763,Event,ADDED,eval-conflicts-rho040-r0-136-bhg94.18d52f47f32b1252,reason=Scheduled count=None msg=Successfully assigned compute/eval-conflicts-rho040-r0-136-bhg94 to kind-worker4
0.1765,Event,ADDED,eval-conflicts-rho040-r0-136-bhg94.18d52f481499b298,"reason=Pulled count=1 msg=Container image ""busybox:musl"" already present on machine"
0.1768,Event,ADDED,eval-conflicts-rho040-r0-136-bhg94.18d52f48170170df,reason=Created count=1 msg=Created container: task
0.177,Event,ADDED,eval-conflicts-rho040-r0-136-bhg94.18d52f481b522fbb,reason=Started count=1 msg=Started container task
0.1772,Event,ADDED,eval-conflicts-rho040-r0-136.18d52f46381e05e0,reason=SuccessfulCreate count=1 msg=Created pod: eval-conflicts-rho040-r0-136-bhg94
0.1774,Event,ADDED,eval-conflicts-rho040-r0-136.18d52f4e06802bb4,reason=Completed count=1 msg=Job completed
0.1776,Event,ADDED,eval-conflicts-rho040-r0-137-7lt2c.18d52f46755bb9d0,"reason=FailedScheduling count=None msg=0/6 nodes are available: 1 c_wall violated: 1 conflicting context pair(s) with node memory, 5 node(s) had untolerated taint(s). no new claims to deallocate, preemption: 0/6 nodes are available: 1 No preemption victims found for incoming pod, 5 Preemption is not helpful for scheduling."
0.1778,Event,ADDED,eval-conflicts-rho040-r0-137-7lt2c.18d52f4675eb65c3,"reason=FailedScheduling count=None msg=0/6 nodes are available: 1 c_wall violated: 1 conflicting context pair(s) with node memory, 5 node(s) had untolerated taint(s). no new claims to deallocate, preemption: 0/6 nodes are available: 1 No preemption victims found for incoming pod, 5 Preemption is not helpful for scheduling."
0.1779,Event,ADDED,eval-conflicts-rho040-r0-137-7lt2c.18d52f4816563f7c,"reason=FailedScheduling count=None msg=0/6 nodes are available: 1 c_wall violated: 1 conflicting context pair(s) with node memory, 1 c_wall violated: 2 conflicting context pair(s) with node memory, 4 node(s) had untolerated taint(s). no new claims to deallocate, preemption: 0/6 nodes are available: 2 No preemption victims found for incoming pod, 4 Preemption is not helpful for scheduling."
0.1781,Event,ADDED,eval-conflicts-rho040-r0-137-7lt2c.18d52f4839fb67dd,reason=Scheduled count=None msg=Successfully assigned compute/eval-conflicts-rho040-r0-137-7lt2c to kind-worker
0.1783,Event,ADDED,eval-conflicts-rho040-r0-137-7lt2c.18d52f485a8f58a4,"reason=Pulled count=1 msg=Container image ""busybox:musl"" already present on machine"
0.1785,Event,ADDED,eval-conflicts-rho040-r0-137-7lt2c.18d52f485badaa01,reason=Created count=1 msg=Created container: task
0.1786,Event,ADDED,eval-conflicts-rho040-r0-137-7lt2c.18d52f4866e37ee1,reason=Started count=1 msg=Started container task
0.1789,Event,ADDED,eval-conflicts-rho040-r0-137.18d52f46751d2604,reason=SuccessfulCreate count=1 msg=Created pod: eval-conflicts-rho040-r0-137-7lt2c
0.1792,Event,ADDED,eval-conflicts-rho040-r0-137.18d52f4e1ff30ad3,reason=Completed count=1 msg=Job completed
0.1793,Event,ADDED,eval-conflicts-rho040-r0-138-7xkbt.18d52f46af18c2ae,"reason=FailedScheduling count=None msg=0/6 nodes are available: 1 c_wall violated: 3 conflicting context pair(s) with node memory, 5 node(s) had untolerated taint(s). no new claims to deallocate, preemption: 0/6 nodes are available: 1 No preemption victims found for incoming pod, 5 Preemption is not helpful for scheduling."
0.1795,Event,ADDED,eval-conflicts-rho040-r0-138-7xkbt.18d52f46af8c1462,"reason=FailedScheduling count=None msg=0/6 nodes are available: 1 c_wall violated: 3 conflicting context pair(s) with node memory, 5 node(s) had untolerated taint(s). no new claims to deallocate, preemption: 0/6 nodes are available: 1 No preemption victims found for incoming pod, 5 Preemption is not helpful for scheduling."
0.1797,Event,ADDED,eval-conflicts-rho040-r0-138-7xkbt.18d52f481aa9e8de,"reason=FailedScheduling count=None msg=0/6 nodes are available: 1 c_wall violated: 2 conflicting context pair(s) with node memory, 1 c_wall violated: 3 conflicting context pair(s) with node memory, 4 node(s) had untolerated taint(s). no new claims to deallocate, preemption: 0/6 nodes are available: 2 No preemption victims found for incoming pod, 4 Preemption is not helpful for scheduling."
0.18,Event,ADDED,eval-conflicts-rho040-r0-138-7xkbt.18d52f48345c53e2,"reason=FailedScheduling count=None msg=0/6 nodes are available: 1 c_wall violated: 1 conflicting context pair(s) with node memory, 1 c_wall violated: 2 conflicting context pair(s) with node memory, 4 node(s) had untolerated taint(s). no new claims to deallocate, preemption: 0/6 nodes are available: 2 No preemption victims found for incoming pod, 4 Preemption is not helpful for scheduling."
0.1802,Event,ADDED,eval-conflicts-rho040-r0-138-7xkbt.18d52f483e613985,"reason=FailedScheduling count=None msg=0/6 nodes are available: 1 c_wall violated: 1 conflicting context pair(s) with node memory, 1 c_wall violated: 2 conflicting context pair(s) with node memory, 4 node(s) had untolerated taint(s). no new claims to deallocate, preemption: 0/6 nodes are available: 2 No preemption victims found for incoming pod, 4 Preemption is not helpful for scheduling."
0.1805,Event,ADDED,eval-conflicts-rho040-r0-138-7xkbt.18d52f48cfa1b5f0,"reason=FailedScheduling count=None msg=0/6 nodes are available: 2 c_wall violated: 2 conflicting context pair(s) with node memory, 4 node(s) had untolerated taint(s). no new claims to deallocate, preemption: 0/6 nodes are available: 2 No preemption victims found for incoming pod, 4 Preemption is not helpful for scheduling."
0.1807,Event,ADDED,eval-conflicts-rho040-r0-138-7xkbt.18d52f49811400bb,reason=Scheduled count=None msg=Successfully assigned compute/eval-conflicts-rho040-r0-138-7xkbt to kind-worker2
0.1809,Event,ADDED,eval-conflicts-rho040-r0-138-7xkbt.18d52f499e02c37d,"reason=Pulled count=1 msg=Container image ""busybox:musl"" already present on machine"
0.1812,Event,ADDED,eval-conflicts-rho040-r0-138-7xkbt.18d52f49a10662ee,reason=Created count=1 msg=Created container: task
0.1814,Event,ADDED,eval-conflicts-rho040-r0-138-7xkbt.18d52f49affe47b1,reason=Started count=1 msg=Started container task
0.1816,Event,ADDED,eval-conflicts-rho040-r0-138.18d52f46aed78efe,reason=SuccessfulCreate count=1 msg=Created pod: eval-conflicts-rho040-r0-138-7xkbt
0.1818,Event,ADDED,eval-conflicts-rho040-r0-138.18d52f4f37e2fd08,reason=Completed count=1 msg=Job completed
0.1822,Event,ADDED,eval-conflicts-rho040-r0-139-985vx.18d52f46eb1ee139,"reason=FailedScheduling count=None msg=0/6 nodes are available: 1 c_wall violated: 2 conflicting context pair(s) with node memory, 5 node(s) had untolerated taint(s). no new claims to deallocate, preemption: 0/6 nodes are available: 1 No preemption victims found for incoming pod, 5 Preemption is not helpful for scheduling."
0.1827,Event,ADDED,eval-conflicts-rho040-r0-139-985vx.18d52f46ebb3cb0d,"reason=FailedScheduling count=None msg=0/6 nodes are available: 1 c_wall violated: 2 conflicting context pair(s) with node memory, 5 node(s) had untolerated taint(s). no new claims to deallocate, preemption: 0/6 nodes are available: 1 No preemption victims found for incoming pod, 5 Preemption is not helpful for scheduling."
0.183,Event,ADDED,eval-conflicts-rho040-r0-139-985vx.18d52f47fab116b5,reason=Scheduled count=None msg=Successfully assigned compute/eval-conflicts-rho040-r0-139-985vx to kind-worker4
0.1834,Event,ADDED,eval-conflicts-rho040-r0-139-985vx.18d52f481cd77e7c,"reason=Pulled count=1 msg=Container image ""busybox:musl"" already present on machine"
0.1836,Event,ADDED,eval-conflicts-rho040-r0-139-985vx.18d52f481e974880,reason=Created count=1 msg=Created container: task
0.1838,Event,ADDED,eval-conflicts-rho040-r0-139-985vx.18d52f4822ac4dbd,reason=Started count=1 msg=Started container task
0.184,Event,ADDED,eval-conflicts-rho040-r0-139.18d52f46eadb17e0,reason=SuccessfulCreate count=1 msg=Created pod: eval-conflicts-rho040-r0-139-985vx
0.1843,Event,ADDED,eval-conflicts-rho040-r0-139.18d52f4e05212b1d,reason=Completed count=1 msg=Job completed
0.1844,Event,ADDED,eval-conflicts-rho040-r0-140-dxbkm.18d52f4725d4f16e,"reason=FailedScheduling count=None msg=0/6 nodes are available: 1 c_wall violated: 2 conflicting context pair(s) with node memory, 5 node(s) had untolerated taint(s). no new claims to deallocate, preemption: 0/6 nodes are available: 1 No preemption victims found for incoming pod, 5 Preemption is not helpful for scheduling."
0.1846,Event,ADDED,eval-conflicts-rho040-r0-140-dxbkm.18d52f472668b940,"reason=FailedScheduling count=None msg=0/6 nodes are available: 1 c_wall violated: 2 conflicting context pair(s) with node memory, 5 node(s) had untolerated taint(s). no new claims to deallocate, preemption: 0/6 nodes are available: 1 No preemption victims found for incoming pod, 5 Preemption is not helpful for scheduling."
0.1848,Event,ADDED,eval-conflicts-rho040-r0-140-dxbkm.18d52f47fabbe852,reason=Scheduled count=None msg=Successfully assigned compute/eval-conflicts-rho040-r0-140-dxbkm to kind-worker4
0.1851,Event,ADDED,eval-conflicts-rho040-r0-140-dxbkm.18d52f481c9ede45,"reason=Pulled count=1 msg=Container image ""busybox:musl"" already present on machine"
0.1853,Event,ADDED,eval-conflicts-rho040-r0-140-dxbkm.18d52f481e3e6de9,reason=Created count=1 msg=Created container: task
0.1855,Event,ADDED,eval-conflicts-rho040-r0-140-dxbkm.18d52f4822adca72,reason=Started count=1 msg=Started container task
0.1857,Event,ADDED,eval-conflicts-rho040-r0-140.18d52f47258e21c7,reason=SuccessfulCreate count=1 msg=Created pod: eval-conflicts-rho040-r0-140-dxbkm
0.1859,Event,ADDED,eval-conflicts-rho040-r0-140.18d52f4e05212b09,reason=Completed count=1 msg=Job completed
0.1862,Event,ADDED,eval-conflicts-rho040-r0-141-jxjvj.18d52f4761a5b074,"reason=FailedScheduling count=None msg=0/6 nodes are available: 1 c_wall violated: 1 conflicting context pair(s) with node memory, 5 node(s) had untolerated taint(s). no new claims to deallocate, preemption: 0/6 nodes are available: 1 No preemption victims found for incoming pod, 5 Preemption is not helpful for scheduling."
0.1864,Event,ADDED,eval-conflicts-rho040-r0-141-jxjvj.18d52f47623a951d,"reason=FailedScheduling count=None msg=0/6 nodes are available: 1 c_wall violated: 1 conflicting context pair(s) with node memory, 5 node(s) had untolerated taint(s). no new claims to deallocate, preemption: 0/6 nodes are available: 1 No preemption victims found for incoming pod, 5 Preemption is not helpful for scheduling."
0.1865,Event,ADDED,eval-conflicts-rho040-r0-141-jxjvj.18d52f4820f22ef8,"reason=FailedScheduling count=None msg=0/6 nodes are available: 1 c_wall violated: 2 conflicting context pair(s) with node memory, 2 c_wall violated: 1 conflicting context pair(s) with node memory, 3 node(s) had untolerated taint(s). no new claims to deallocate, preemption: 0/6 nodes are available: 3 No preemption victims found for incoming pod, 3 Preemption is not helpful for scheduling."
0.1867,Event,ADDED,eval-conflicts-rho040-r0-141-jxjvj.18d52f483aa6ecbf,"reason=FailedScheduling count=None msg=0/6 nodes are available: 1 c_wall violated: 1 conflicting context pair(s) with node memory, 1 c_wall violated: 2 conflicting context pair(s) with node memory, 4 node(s) had untolerated taint(s). no new claims to deallocate, preemption: 0/6 nodes are available: 2 No preemption victims found for incoming pod, 4 Preemption is not helpful for scheduling."
0.1869,Event,ADDED,eval-conflicts-rho040-r0-141-jxjvj.18d52f4840901fa1,"reason=FailedScheduling count=None msg=0/6 nodes are available: 1 c_wall violated: 1 conflicting context pair(s) with node memory, 1 c_wall violated: 2 conflicting context pair(s) with node memory, 4 node(s) had untolerated taint(s). no new claims to deallocate, preemption: 0/6 nodes are available: 2 No preemption victims found for incoming pod, 4 Preemption is not helpful for scheduling."
0.187,Event,ADDED,eval-conflicts-rho040-r0-141-jxjvj.18d52f49829e271d,reason=Scheduled count=None msg=Successfully assigned compute/eval-conflicts-rho040-r0-141-jxjvj to kind-worker2
0.1872,Event,ADDED,eval-conflicts-rho040-r0-141-jxjvj.18d52f499e1b115a,"reason=Pulled count=1 msg=Container image ""busybox:musl"" already present on machine"
0.1874,Event,ADDED,eval-conflicts-rho040-r0-141-jxjvj.18d52f49a1e3319f,reason=Created count=1 msg=Created container: task
0.1876,Event,ADDED,eval-conflicts-rho040-r0-141-jxjvj.18d52f49affcbfe1,reason=Started count=1 msg=Started container task
0.1877,Event,ADDED,eval-conflicts-rho040-r0-141.18d52f47616d904d,reason=SuccessfulCreate count=1 msg=Created pod: eval-conflicts-rho040-r0-141-jxjvj
0.1879,Event,ADDED,eval-conflicts-rho040-r0-141.18d52f4f37c3e23a,reason=Completed count=1 msg=Job completed
0.1881,Event,ADDED,eval-conflicts-rho040-r0-142-q2wj5.18d52f479d250a11,"reason=FailedScheduling count=None msg=0/6 nodes are available: 1 c_wall violated: 3 conflicting context pair(s) with node memory, 5 node(s) had untolerated taint(s). no new claims to deallocate, preemption: 0/6 nodes are available: 1 No preemption victims found for incoming pod, 5 Preemption is not helpful for scheduling."
0.1883,Event,ADDED,eval-conflicts-rho040-r0-142-q2wj5.18d52f479da92c5d,"reason=FailedScheduling count=None msg=0/6 nodes are available: 1 c_wall violated: 3 conflicting context pair(s) with node memory, 5 node(s) had untolerated taint(s). no new claims to deallocate, preemption: 0/6 nodes are available: 1 No preemption victims found for incoming pod, 5 Preemption is not helpful for scheduling."
0.1884,Event,ADDED,eval-conflicts-rho040-r0-142-q2wj5.18d52f482328fdda,"reason=FailedScheduling count=None msg=0/6 nodes are available: 1 c_wall violated: 1 conflicting context pair(s) with node memory, 1 c_wall violated: 2 conflicting context pair(s) with node memory, 1 c_wall violated: 3 conflicting context pair(s) with node memory, 3 node(s) had untolerated taint(s). no new claims to deallocate, preemption: 0/6 nodes are available: 3 No preemption victims found for incoming pod, 3 Preemption is not helpful for scheduling."
0.1886,Event,ADDED,eval-conflicts-rho040-r0-142-q2wj5.18d52f483b5193f2,"reason=FailedScheduling count=None msg=0/6 nodes are available: 1 c_wall violated: 1 conflicting context pair(s) with node memory, 1 c_wall violated: 2 conflicting context pair(s) with node memory, 4 node(s) had untolerated taint(s). no new claims to deallocate, preemption: 0/6 nodes are available: 2 No preemption victims found for incoming pod, 4 Preemption is not helpful for scheduling."
0.1887,Event,ADDED,eval-conflicts-rho040-r0-142-q2wj5.18d52f4840f8aac4,"reason=FailedScheduling count=None msg=0/6 nodes are available: 1 c_wall violated: 1 conflicting context pair(s) with node memory, 1 c_wall violated: 2 conflicting context pair(s) with node memory, 4 node(s) had untolerated taint(s). no new claims to deallocate, preemption: 0/6 nodes are available: 2 No preemption victims found for incoming pod, 4 Preemption is not helpful for scheduling."
0.1889,Event,ADDED,eval-conflicts-rho040-r0-142-q2wj5.18d52f48ce069c16,"reason=FailedScheduling count=None msg=0/6 nodes are available: 2 c_wall violated: 2 conflicting context pair(s) with node memory, 4 node(s) had untolerated taint(s). no new claims to deallocate, preemption: 0/6 nodes are available: 2 No preemption victims found for incoming pod, 4 Preemption is not helpful for scheduling."
0.1891,Event,ADDED,eval-conflicts-rho040-r0-142-q2wj5.18d52f498a4d307e,reason=Scheduled count=None msg=Successfully assigned compute/eval-conflicts-rho040-r0-142-q2wj5 to kind-worker2
0.1893,Event,ADDED,eval-conflicts-rho040-r0-142-q2wj5.18d52f49a871684a,"reason=Pulled count=1 msg=Container image ""busybox:musl"" already present on machine"
0.1894,Event,ADDED,eval-conflicts-rho040-r0-142-q2wj5.18d52f49a98c099b,reason=Created count=1 msg=Created container: task
0.1896,Event,ADDED,eval-conflicts-rho040-r0-142-q2wj5.18d52f49affcbfea,reason=Started count=1 msg=Started container task
0.1898,Event,ADDED,eval-conflicts-rho040-r0-142.18d52f479ce2a327,reason=SuccessfulCreate count=1 msg=Created pod: eval-conflicts-rho040-r0-142-q2wj5
0.1899,Event,ADDED,eval-conflicts-rho040-r0-142.18d52f4f37e17d18,reason=Completed count=1 msg=Job completed
0.1901,Event,ADDED,eval-conflicts-rho040-r0-143-5vsjn.18d52f47d8a5ced6,"reason=FailedScheduling count=None msg=0/6 nodes are available: 1 c_wall violated: 1 conflicting context pair(s) with node memory, 5 node(s) had untolerated taint(s). no new claims to deallocate, preemption: 0/6 nodes are available: 1 No preemption victims found for incoming pod, 5 Preemption is not helpful for scheduling."
0.1903,Event,ADDED,eval-conflicts-rho040-r0-143-5vsjn.18d52f47d92fe9a9,"reason=FailedScheduling count=None msg=0/6 nodes are available: 1 c_wall violated: 1 conflicting context pair(s) with node memory, 5 node(s) had untolerated taint(s). no new claims to deallocate, preemption: 0/6 nodes are available: 1 No preemption victims found for incoming pod, 5 Preemption is not helpful for scheduling."
0.1904,Event,ADDED,eval-conflicts-rho040-r0-143-5vsjn.18d52f482914aba0,reason=Scheduled count=None msg=Successfully assigned compute/eval-conflicts-rho040-r0-143-5vsjn to kind-worker
0.1906,Event,ADDED,eval-conflicts-rho040-r0-143-5vsjn.18d52f484d7218cf,"reason=Pulled count=1 msg=Container image ""busybox:musl"" already present on machine"
0.1908,Event,ADDED,eval-conflicts-rho040-r0-143-5vsjn.18d52f48515632b8,reason=Created count=1 msg=Created container: task
0.1909,Event,ADDED,eval-conflicts-rho040-r0-143-5vsjn.18d52f485a8dc3df,reason=Started count=1 msg=Started container task
0.1912,Event,ADDED,eval-conflicts-rho040-r0-143.18d52f47d8660c54,reason=SuccessfulCreate count=1 msg=Created pod: eval-conflicts-rho040-r0-143-5vsjn
0.1915,Event,ADDED,eval-conflicts-rho040-r0-143.18d52f4d9255fa74,reason=Completed count=1 msg=Job completed
0.1916,Event,ADDED,eval-conflicts-rho040-r0-144-j9cmv.18d52f481c76f0f5,reason=Scheduled count=None msg=Successfully assigned compute/eval-conflicts-rho040-r0-144-j9cmv to kind-worker
0.1918,Event,ADDED,eval-conflicts-rho040-r0-144-j9cmv.18d52f4839f02b8b,"reason=Pulled count=1 msg=Container image ""busybox:musl"" already present on machine"
0.192,Event,ADDED,eval-conflicts-rho040-r0-144-j9cmv.18d52f483b77e593,reason=Created count=1 msg=Created container: task
0.1923,Event,ADDED,eval-conflicts-rho040-r0-144-j9cmv.18d52f48401af366,reason=Started count=1 msg=Started container task
0.1925,Event,ADDED,eval-conflicts-rho040-r0-144.18d52f4817307768,reason=SuccessfulCreate count=1 msg=Created pod: eval-conflicts-rho040-r0-144-j9cmv
0.1927,Event,ADDED,eval-conflicts-rho040-r0-144.18d52f4e2d496323,reason=Completed count=1 msg=Job completed
0.193,Event,ADDED,eval-conflicts-rho040-r0-145-jrplm.18d52f48534498b9,reason=Scheduled count=None msg=Successfully assigned compute/eval-conflicts-rho040-r0-145-jrplm to kind-worker
0.1932,Event,ADDED,eval-conflicts-rho040-r0-145-jrplm.18d52f486e5f407f,"reason=Pulled count=1 msg=Container image ""busybox:musl"" already present on machine"
0.1934,Event,ADDED,eval-conflicts-rho040-r0-145-jrplm.18d52f486f72e7c6,reason=Created count=1 msg=Created container: task
0.1936,Event,ADDED,eval-conflicts-rho040-r0-145-jrplm.18d52f487a81b046,reason=Started count=1 msg=Started container task
0.1938,Event,ADDED,eval-conflicts-rho040-r0-145.18d52f48510b9b8e,reason=SuccessfulCreate count=1 msg=Created pod: eval-conflicts-rho040-r0-145-jrplm
0.194,Event,ADDED,eval-conflicts-rho040-r0-145.18d52f4e62fbc3d5,reason=Completed count=1 msg=Job completed
0.1941,Event,ADDED,eval-conflicts-rho040-r0-146-4qsw2.18d52f48937146c8,reason=Scheduled count=None msg=Successfully assigned compute/eval-conflicts-rho040-r0-146-4qsw2 to kind-worker
0.1944,Event,ADDED,eval-conflicts-rho040-r0-146-4qsw2.18d52f48aec554a7,"reason=Pulled count=1 msg=Container image ""busybox:musl"" already present on machine"
0.1947,Event,ADDED,eval-conflicts-rho040-r0-146-4qsw2.18d52f48b030539f,reason=Created count=1 msg=Created container: task
0.1949,Event,ADDED,eval-conflicts-rho040-r0-146-4qsw2.18d52f48bd50a226,reason=Started count=1 msg=Started container task
0.195,Event,ADDED,eval-conflicts-rho040-r0-146.18d52f4891fee6b1,reason=SuccessfulCreate count=1 msg=Created pod: eval-conflicts-rho040-r0-146-4qsw2
0.1952,Event,ADDED,eval-conflicts-rho040-r0-146.18d52f4e6346c027,reason=Completed count=1 msg=Job completed
0.1954,Event,ADDED,eval-conflicts-rho040-r0-147-kq8vv.18d52f48c7071763,reason=Scheduled count=None msg=Successfully assigned compute/eval-conflicts-rho040-r0-147-kq8vv to kind-worker
0.1955,Event,ADDED,eval-conflicts-rho040-r0-147-kq8vv.18d52f48e3334b23,"reason=Pulled count=1 msg=Container image ""busybox:musl"" already present on machine"
0.1958,Event,ADDED,eval-conflicts-rho040-r0-147-kq8vv.18d52f48e4b10458,reason=Created count=1 msg=Created container: task
0.196,Event,ADDED,eval-conflicts-rho040-r0-147-kq8vv.18d52f48ed5fa5fa,reason=Started count=1 msg=Started container task
0.1961,Event,ADDED,eval-conflicts-rho040-r0-147.18d52f48c66037eb,reason=SuccessfulCreate count=1 msg=Created pod: eval-conflicts-rho040-r0-147-kq8vv
0.1963,Event,ADDED,eval-conflicts-rho040-r0-147.18d52f4e8c1d22f1,reason=Completed count=1 msg=Job completed
0.1965,Event,ADDED,eval-conflicts-rho040-r0-148-p8p82.18d52f49048a25c4,reason=Scheduled count=None msg=Successfully assigned compute/eval-conflicts-rho040-r0-148-p8p82 to kind-worker4
0.1966,Event,ADDED,eval-conflicts-rho040-r0-148-p8p82.18d52f491eed8d80,"reason=Pulled count=1 msg=Container image ""busybox:musl"" already present on machine"
0.1968,Event,ADDED,eval-conflicts-rho040-r0-148-p8p82.18d52f4920690ef6,reason=Created count=1 msg=Created container: task
0.197,Event,ADDED,eval-conflicts-rho040-r0-148-p8p82.18d52f49274f0a94,reason=Started count=1 msg=Started container task
0.1971,Event,ADDED,eval-conflicts-rho040-r0-148.18d52f4903cada5e,reason=SuccessfulCreate count=1 msg=Created pod: eval-conflicts-rho040-r0-148-p8p82
0.1973,Event,ADDED,eval-conflicts-rho040-r0-148.18d52f4eabfbdc48,reason=Completed count=1 msg=Job completed
0.1975,Event,ADDED,eval-conflicts-rho040-r0-149-tr8xf.18d52f494150d747,reason=Scheduled count=None msg=Successfully assigned compute/eval-conflicts-rho040-r0-149-tr8xf to kind-worker
0.1976,Event,ADDED,eval-conflicts-rho040-r0-149-tr8xf.18d52f495ed337b1,"reason=Pulled count=1 msg=Container image ""busybox:musl"" already present on machine"
0.1978,Event,ADDED,eval-conflicts-rho040-r0-149-tr8xf.18d52f496024f0c0,reason=Created count=1 msg=Created container: task
0.198,Event,ADDED,eval-conflicts-rho040-r0-149-tr8xf.18d52f4965bab6f7,reason=Started count=1 msg=Started container task
0.1981,Event,ADDED,eval-conflicts-rho040-r0-149.18d52f493e7482d3,reason=SuccessfulCreate count=1 msg=Created pod: eval-conflicts-rho040-r0-149-tr8xf
0.1983,Event,ADDED,eval-conflicts-rho040-r0-149.18d52f4f0524ebc4,reason=Completed count=1 msg=Job completed
0.1985,Event,ADDED,eval-conflicts-rho040-r0-150-cjjrj.18d52f4980a1ba20,reason=Scheduled count=None msg=Successfully assigned compute/eval-conflicts-rho040-r0-150-cjjrj to kind-worker
0.1986,Event,ADDED,eval-conflicts-rho040-r0-150-cjjrj.18d52f499df6fde8,"reason=Pulled count=1 msg=Container image ""busybox:musl"" already present on machine"
0.1988,Event,ADDED,eval-conflicts-rho040-r0-150-cjjrj.18d52f49a0c9ca25,reason=Created count=1 msg=Created container: task
0.199,Event,ADDED,eval-conflicts-rho040-r0-150-cjjrj.18d52f49a887b477,reason=Started count=1 msg=Started container task
0.1991,Event,ADDED,eval-conflicts-rho040-r0-150.18d52f497c2c4b86,reason=SuccessfulCreate count=1 msg=Created pod: eval-conflicts-rho040-r0-150-cjjrj
0.1993,Event,ADDED,eval-conflicts-rho040-r0-150.18d52f4f061ad70f,reason=Completed count=1 msg=Job completed
0.1994,Event,ADDED,eval-conflicts-rho040-r0-151-dz962.18d52f49bad90863,reason=Scheduled count=None msg=Successfully assigned compute/eval-conflicts-rho040-r0-151-dz962 to kind-worker3
0.1996,Event,ADDED,eval-conflicts-rho040-r0-151-dz962.18d52f49d944f9fe,"reason=Pulled count=1 msg=Container image ""busybox:musl"" already present on machine"
0.1998,Event,ADDED,eval-conflicts-rho040-r0-151-dz962.18d52f49da641251,reason=Created count=1 msg=Created container: task
0.1999,Event,ADDED,eval-conflicts-rho040-r0-151-dz962.18d52f49e1fb5f71,reason=Started count=1 msg=Started container task
0.2001,Event,ADDED,eval-conflicts-rho040-r0-151.18d52f49b965fc46,reason=SuccessfulCreate count=1 msg=Created pod: eval-conflicts-rho040-r0-151-dz962
0.2003,Event,ADDED,eval-conflicts-rho040-r0-151.18d52f4f05c6d19f,reason=Completed count=1 msg=Job completed
0.2004,Event,ADDED,eval-conflicts-rho040-r0-152-g8btk.18d52f49f28ba111,reason=Scheduled count=None msg=Successfully assigned compute/eval-conflicts-rho040-r0-152-g8btk to kind-worker3
0.2006,Event,ADDED,eval-conflicts-rho040-r0-152-g8btk.18d52f4a0e2da541,"reason=Pulled count=1 msg=Container image ""busybox:musl"" already present on machine"
0.2008,Event,ADDED,eval-conflicts-rho040-r0-152-g8btk.18d52f4a0f527523,reason=Created count=1 msg=Created container: task
0.2009,Event,ADDED,eval-conflicts-rho040-r0-152-g8btk.18d52f4a170b77a3,reason=Started count=1 msg=Started container task
0.2011,Event,ADDED,eval-conflicts-rho040-r0-152.18d52f49f139e8ba,reason=SuccessfulCreate count=1 msg=Created pod: eval-conflicts-rho040-r0-152-g8btk
0.2013,Event,ADDED,eval-conflicts-rho040-r0-152.18d52f4f8014d679,reason=Completed count=1 msg=Job completed
0.2014,Event,ADDED,eval-conflicts-rho040-r0-153-6btdn.18d52f4a2ece5b85,reason=Scheduled count=None msg=Successfully assigned compute/eval-conflicts-rho040-r0-153-6btdn to kind-worker
0.2016,Event,ADDED,eval-conflicts-rho040-r0-153-6btdn.18d52f4a4deac597,"reason=Pulled count=1 msg=Container image ""busybox:musl"" already present on machine"
0.2034,Event,ADDED,eval-conflicts-rho040-r0-153-6btdn.18d52f4a4f27dd75,reason=Created count=1 msg=Created container: task
0.2036,Event,ADDED,eval-conflicts-rho040-r0-153-6btdn.18d52f4a5a0c32f8,reason=Started count=1 msg=Started container task
0.2038,Event,ADDED,eval-conflicts-rho040-r0-153.18d52f4a2d8f6f43,reason=SuccessfulCreate count=1 msg=Created pod: eval-conflicts-rho040-r0-153-6btdn
0.204,Event,ADDED,eval-conflicts-rho040-r0-153.18d52f4fe56f1e69,reason=Completed count=1 msg=Job completed
0.2041,Event,ADDED,eval-conflicts-rho040-r0-154-cf2d2.18d52f4a6d662a5d,reason=Scheduled count=None msg=Successfully assigned compute/eval-conflicts-rho040-r0-154-cf2d2 to kind-worker3
0.2043,Event,ADDED,eval-conflicts-rho040-r0-154-cf2d2.18d52f4a94aac523,"reason=Pulled count=1 msg=Container image ""busybox:musl"" already present on machine"
0.2045,Event,ADDED,eval-conflicts-rho040-r0-154-cf2d2.18d52f4a95c83076,reason=Created count=1 msg=Created container: task
0.2046,Event,ADDED,eval-conflicts-rho040-r0-154-cf2d2.18d52f4a9dd5bee0,reason=Started count=1 msg=Started container task
0.2048,Event,ADDED,eval-conflicts-rho040-r0-154.18d52f4a6c0014ff,reason=SuccessfulCreate count=1 msg=Created pod: eval-conflicts-rho040-r0-154-cf2d2
0.205,Event,ADDED,eval-conflicts-rho040-r0-154.18d52f5031609dd4,reason=Completed count=1 msg=Job completed
0.2051,Event,ADDED,eval-conflicts-rho040-r0-155-dnh94.18d52f4aac71756b,reason=Scheduled count=None msg=Successfully assigned compute/eval-conflicts-rho040-r0-155-dnh94 to kind-worker
0.2053,Event,ADDED,eval-conflicts-rho040-r0-155-dnh94.18d52f4ad0d7e45b,"reason=Pulled count=1 msg=Container image ""busybox:musl"" already present on machine"
0.2055,Event,ADDED,eval-conflicts-rho040-r0-155-dnh94.18d52f4ad1fe9eb3,reason=Created count=1 msg=Created container: task
0.2056,Event,ADDED,eval-conflicts-rho040-r0-155-dnh94.18d52f4ad92e870f,reason=Started count=1 msg=Started container task
0.2058,Event,ADDED,eval-conflicts-rho040-r0-155.18d52f4aab36a8fe,reason=SuccessfulCreate count=1 msg=Created pod: eval-conflicts-rho040-r0-155-dnh94
0.2059,Event,ADDED,eval-conflicts-rho040-r0-155.18d52f5061c471a6,reason=Completed count=1 msg=Job completed
0.2062,Event,ADDED,eval-conflicts-rho040-r0-156-ksxsp.18d52f4ae4bb79cf,reason=Scheduled count=None msg=Successfully assigned compute/eval-conflicts-rho040-r0-156-ksxsp to kind-worker2
0.2063,Event,ADDED,eval-conflicts-rho040-r0-156-ksxsp.18d52f4b0429a066,"reason=Pulled count=1 msg=Container image ""busybox:musl"" already present on machine"
0.2065,Event,ADDED,eval-conflicts-rho040-r0-156-ksxsp.18d52f4b0557781b,reason=Created count=1 msg=Created container: task
0.2068,Event,ADDED,eval-conflicts-rho040-r0-156-ksxsp.18d52f4b0e15818e,reason=Started count=1 msg=Started container task
0.207,Event,ADDED,eval-conflicts-rho040-r0-156.18d52f4ae36e789a,reason=SuccessfulCreate count=1 msg=Created pod: eval-conflicts-rho040-r0-156-ksxsp
0.2071,Event,ADDED,eval-conflicts-rho040-r0-156.18d52f50907559ef,reason=Completed count=1 msg=Job completed
0.2073,Event,ADDED,eval-conflicts-rho040-r0-157-q6bsv.18d52f4b1dae3a0c,reason=Scheduled count=None msg=Successfully assigned compute/eval-conflicts-rho040-r0-157-q6bsv to kind-worker3
0.2076,Event,ADDED,eval-conflicts-rho040-r0-157-q6bsv.18d52f4b3bd3d71c,"reason=Pulled count=1 msg=Container image ""busybox:musl"" already present on machine"
0.2078,Event,ADDED,eval-conflicts-rho040-r0-157-q6bsv.18d52f4b3d6db721,reason=Created count=1 msg=Created container: task
0.208,Event,ADDED,eval-conflicts-rho040-r0-157-q6bsv.18d52f4b479b0ebb,reason=Started count=1 msg=Started container task
0.2082,Event,ADDED,eval-conflicts-rho040-r0-157.18d52f4b1c4aeae3,reason=SuccessfulCreate count=1 msg=Created pod: eval-conflicts-rho040-r0-157-q6bsv
0.2084,Event,ADDED,eval-conflicts-rho040-r0-157.18d52f50ab7ab09a,reason=Completed count=1 msg=Job completed
0.2085,Event,ADDED,eval-conflicts-rho040-r0-158-sjcsp.18d52f4b5881e269,"reason=FailedScheduling count=None msg=0/6 nodes are available: 1 c_wall violated: 2 conflicting context pair(s) with node memory, 2 node(s) had untolerated taint(s), 3 c_wall violated: 1 conflicting context pair(s) with node memory. no new claims to deallocate, preemption: 0/6 nodes are available: 2 Preemption is not helpful for scheduling, 4 No preemption victims found for incoming pod."
0.2087,Event,ADDED,eval-conflicts-rho040-r0-158-sjcsp.18d52f4b5dbcfaa4,"reason=FailedScheduling count=None msg=0/6 nodes are available: 1 c_wall violated: 2 conflicting context pair(s) with node memory, 2 node(s) had untolerated taint(s), 3 c_wall violated: 1 conflicting context pair(s) with node memory. no new claims to deallocate, preemption: 0/6 nodes are available: 2 Preemption is not helpful for scheduling, 4 No preemption victims found for incoming pod."
0.209,Event,ADDED,eval-conflicts-rho040-r0-158-sjcsp.18d52f4bad46c074,"reason=FailedScheduling count=None msg=0/6 nodes are available: 2 c_wall violated: 1 conflicting context pair(s) with node memory, 2 c_wall violated: 2 conflicting context pair(s) with node memory, 2 node(s) had untolerated taint(s). no new claims to deallocate, preemption: 0/6 nodes are available: 2 Preemption is not helpful for scheduling, 4 No preemption victims found for incoming pod."
0.2092,Event,ADDED,eval-conflicts-rho040-r0-158-sjcsp.18d52f4c123ce09f,"reason=FailedScheduling count=None msg=0/6 nodes are available: 1 c_wall violated: 2 conflicting context pair(s) with node memory, 1 c_wall violated: 3 conflicting context pair(s) with node memory, 2 c_wall violated: 1 conflicting context pair(s) with node memory, 2 node(s) had untolerated taint(s). no new claims to deallocate, preemption: 0/6 nodes are available: 2 Preemption is not helpful for scheduling, 4 No preemption victims found for incoming pod."
0.2094,Event,ADDED,eval-conflicts-rho040-r0-158-sjcsp.18d52f4c9f153d18,"reason=FailedScheduling count=None msg=0/6 nodes are available: 1 c_wall violated: 1 conflicting context pair(s) with node memory, 1 c_wall violated: 2 conflicting context pair(s) with node memory, 1 c_wall violated: 3 conflicting context pair(s) with node memory, 3 node(s) had untolerated taint(s). no new claims to deallocate, preemption: 0/6 nodes are available: 3 No preemption victims found for incoming pod, 3 Preemption is not helpful for scheduling."
0.2096,Event,ADDED,eval-conflicts-rho040-r0-158-sjcsp.18d52f4ccaacd596,"reason=FailedScheduling count=None msg=0/6 nodes are available: 1 c_wall violated: 1 conflicting context pair(s) with node memory, 1 c_wall violated: 3 conflicting context pair(s) with node memory, 4 node(s) had untolerated taint(s). no new claims to deallocate, preemption: 0/6 nodes are available: 2 No preemption victims found for incoming pod, 4 Preemption is not helpful for scheduling."
0.2098,Event,ADDED,eval-conflicts-rho040-r0-158-sjcsp.18d52f4cf10241d5,reason=Scheduled count=None msg=Successfully assigned compute/eval-conflicts-rho040-r0-158-sjcsp to kind-worker5
0.2099,Event,ADDED,eval-conflicts-rho040-r0-158-sjcsp.18d52f4d1fbeba07,"reason=Pulled count=1 msg=Container image ""busybox:musl"" already present on machine"
0.2101,Event,ADDED,eval-conflicts-rho040-r0-158-sjcsp.18d52f4d20d24a46,reason=Created count=1 msg=Created container: task
0.2103,Event,ADDED,eval-conflicts-rho040-r0-158-sjcsp.18d52f4d2a8b1194,reason=Started count=1 msg=Started container task
0.2104,Event,ADDED,eval-conflicts-rho040-r0-158.18d52f4b5784dfd6,reason=SuccessfulCreate count=1 msg=Created pod: eval-conflicts-rho040-r0-158-sjcsp
0.2106,Event,ADDED,eval-conflicts-rho040-r0-158.18d52f52b227f09e,reason=Completed count=1 msg=Job completed
0.2108,Event,ADDED,eval-conflicts-rho040-r0-159-mh5z7.18d52f4b9a29f534,reason=Scheduled count=None msg=Successfully assigned compute/eval-conflicts-rho040-r0-159-mh5z7 to kind-worker2
0.211,Event,ADDED,eval-conflicts-rho040-r0-159-mh5z7.18d52f4bc035f513,"reason=Pulled count=1 msg=Container image ""busybox:musl"" already present on machine"
0.2113,Event,ADDED,eval-conflicts-rho040-r0-159-mh5z7.18d52f4bc1628f50,reason=Created count=1 msg=Created container: task
0.2115,Event,ADDED,eval-conflicts-rho040-r0-159-mh5z7.18d52f4bcf86381e,reason=Started count=1 msg=Started container task
0.2117,Event,ADDED,eval-conflicts-rho040-r0-159.18d52f4b9897eca7,reason=SuccessfulCreate count=1 msg=Created pod: eval-conflicts-rho040-r0-159-mh5z7
0.2118,Event,ADDED,eval-conflicts-rho040-r0-159.18d52f514cdaafb0,reason=Completed count=1 msg=Job completed
0.2121,Event,ADDED,eval-conflicts-rho040-r0-160-k2ttj.18d52f4bd2b1b867,reason=Scheduled count=None msg=Successfully assigned compute/eval-conflicts-rho040-r0-160-k2ttj to kind-worker2
0.2122,Event,ADDED,eval-conflicts-rho040-r0-160-k2ttj.18d52f4bf1d4fd98,"reason=Pulled count=1 msg=Container image ""busybox:musl"" already present on machine"
0.2124,Event,ADDED,eval-conflicts-rho040-r0-160-k2ttj.18d52f4bf3171966,reason=Created count=1 msg=Created container: task
0.2127,Event,ADDED,eval-conflicts-rho040-r0-160-k2ttj.18d52f4bfa0d1c18,reason=Started count=1 msg=Started container task
0.2128,Event,ADDED,eval-conflicts-rho040-r0-160.18d52f4bd12822a0,reason=SuccessfulCreate count=1 msg=Created pod: eval-conflicts-rho040-r0-160-k2ttj
0.213,Event,ADDED,eval-conflicts-rho040-r0-160.18d52f5189c7b2c3,reason=Completed count=1 msg=Job completed
0.2132,Event,ADDED,eval-conflicts-rho040-r0-161-jgmkx.18d52f4c0a7a0178,reason=Scheduled count=None msg=Successfully assigned compute/eval-conflicts-rho040-r0-161-jgmkx to kind-worker2
0.2133,Event,ADDED,eval-conflicts-rho040-r0-161-jgmkx.18d52f4c2a2c7b41,"reason=Pulled count=1 msg=Container image ""busybox:musl"" already present on machine"
0.2135,Event,ADDED,eval-conflicts-rho040-r0-161-jgmkx.18d52f4c2b4084a1,reason=Created count=1 msg=Created container: task
0.2137,Event,ADDED,eval-conflicts-rho040-r0-161-jgmkx.18d52f4c33f5f53e,reason=Started count=1 msg=Started container task
0.214,Event,ADDED,eval-conflicts-rho040-r0-161.18d52f4c093c683d,reason=SuccessfulCreate count=1 msg=Created pod: eval-conflicts-rho040-r0-161-jgmkx
0.2142,Event,ADDED,eval-conflicts-rho040-r0-161.18d52f51bb88245a,reason=Completed count=1 msg=Job completed
0.2144,Event,ADDED,eval-conflicts-rho040-r0-162-nwmp7.18d52f4c4df1c94f,reason=Scheduled count=None msg=Successfully assigned compute/eval-conflicts-rho040-r0-162-nwmp7 to kind-worker3
0.2145,Event,ADDED,eval-conflicts-rho040-r0-162-nwmp7.18d52f4c739223eb,"reason=Pulled count=1 msg=Container image ""busybox:musl"" already present on machine"
0.2147,Event,ADDED,eval-conflicts-rho040-r0-162-nwmp7.18d52f4c74c4e247,reason=Created count=1 msg=Created container: task
0.2149,Event,ADDED,eval-conflicts-rho040-r0-162-nwmp7.18d52f4c836ccea9,reason=Started count=1 msg=Started container task
0.2151,Event,ADDED,eval-conflicts-rho040-r0-162.18d52f4c4c837c63,reason=SuccessfulCreate count=1 msg=Created pod: eval-conflicts-rho040-r0-162-nwmp7
0.2152,Event,ADDED,eval-conflicts-rho040-r0-162.18d52f521395869a,reason=Completed count=1 msg=Job completed
0.2154,Event,ADDED,eval-conflicts-rho040-r0-163-nklpl.18d52f4c864838a1,reason=Scheduled count=None msg=Successfully assigned compute/eval-conflicts-rho040-r0-163-nklpl to kind-worker3
0.2156,Event,ADDED,eval-conflicts-rho040-r0-163-nklpl.18d52f4ca3c9ecd4,"reason=Pulled count=1 msg=Container image ""busybox:musl"" already present on machine"
0.2158,Event,ADDED,eval-conflicts-rho040-r0-163-nklpl.18d52f4ca4e7d4de,reason=Created count=1 msg=Created container: task
0.2159,Event,ADDED,eval-conflicts-rho040-r0-163-nklpl.18d52f4caacd4cde,reason=Started count=1 msg=Started container task
0.2161,Event,ADDED,eval-conflicts-rho040-r0-163.18d52f4c84ccba8b,reason=SuccessfulCreate count=1 msg=Created pod: eval-conflicts-rho040-r0-163-nklpl
0.2163,Event,ADDED,eval-conflicts-rho040-r0-163.18d52f5213b24806,reason=Completed count=1 msg=Job completed
0.2164,Event,ADDED,eval-conflicts-rho040-r0-164-cqn8s.18d52f4cbfb17c53,reason=Scheduled count=None msg=Successfully assigned compute/eval-conflicts-rho040-r0-164-cqn8s to kind-worker2
0.2167,Event,ADDED,eval-conflicts-rho040-r0-164-cqn8s.18d52f4cda9bb3a7,"reason=Pulled count=1 msg=Container image ""busybox:musl"" already present on machine"
0.2168,Event,ADDED,eval-conflicts-rho040-r0-164-cqn8s.18d52f4cdba86a7e,reason=Created count=1 msg=Created container: task
0.217,Event,ADDED,eval-conflicts-rho040-r0-164-cqn8s.18d52f4cef2ce1d8,reason=Started count=1 msg=Started container task
0.2172,Event,ADDED,eval-conflicts-rho040-r0-164.18d52f4cbe721df2,reason=SuccessfulCreate count=1 msg=Created pod: eval-conflicts-rho040-r0-164-cqn8s
0.2174,Event,ADDED,eval-conflicts-rho040-r0-164.18d52f526e91d416,reason=Completed count=1 msg=Job completed
0.2175,Event,ADDED,eval-conflicts-rho040-r0-165-db5z8.18d52f4cfb5e465f,reason=Scheduled count=None msg=Successfully assigned compute/eval-conflicts-rho040-r0-165-db5z8 to kind-worker5
0.2177,Event,ADDED,eval-conflicts-rho040-r0-165-db5z8.18d52f4d17275a22,"reason=Pulled count=1 msg=Container image ""busybox:musl"" already present on machine"
0.2178,Event,ADDED,eval-conflicts-rho040-r0-165-db5z8.18d52f4d1856966b,reason=Created count=1 msg=Created container: task
0.218,Event,ADDED,eval-conflicts-rho040-r0-165-db5z8.18d52f4d1fb63ae3,reason=Started count=1 msg=Started container task
0.2182,Event,ADDED,eval-conflicts-rho040-r0-165.18d52f4cfa37ce59,reason=SuccessfulCreate count=1 msg=Created pod: eval-conflicts-rho040-r0-165-db5z8
0.2183,Event,ADDED,eval-conflicts-rho040-r0-165.18d52f52b1d95880,reason=Completed count=1 msg=Job completed
0.2185,Event,ADDED,eval-conflicts-rho040-r0-166-df4zn.18d52f4d3a71014d,reason=Scheduled count=None msg=Successfully assigned compute/eval-conflicts-rho040-r0-166-df4zn to kind-worker5
0.2187,Event,ADDED,eval-conflicts-rho040-r0-166-df4zn.18d52f4d5cb4a77f,"reason=Pulled count=1 msg=Container image ""busybox:musl"" already present on machine"
0.2188,Event,ADDED,eval-conflicts-rho040-r0-166-df4zn.18d52f4d5dd49bd7,reason=Created count=1 msg=Created container: task
0.219,Event,ADDED,eval-conflicts-rho040-r0-166-df4zn.18d52f4d688a2457,reason=Started count=1 msg=Started container task
0.2192,Event,ADDED,eval-conflicts-rho040-r0-166.18d52f4d39701508,reason=SuccessfulCreate count=1 msg=Created pod: eval-conflicts-rho040-r0-166-df4zn
0.2193,Event,ADDED,eval-conflicts-rho040-r0-166.18d52f52ef385ae3,reason=Completed count=1 msg=Job completed
0.2195,Event,ADDED,eval-conflicts-rho040-r0-167-62wlc.18d52f4d6f9eb6d9,reason=Scheduled count=None msg=Successfully assigned compute/eval-conflicts-rho040-r0-167-62wlc to kind-worker5
0.2196,Event,ADDED,eval-conflicts-rho040-r0-167-62wlc.18d52f4d930cd716,"reason=Pulled count=1 msg=Container image ""busybox:musl"" already present on machine"
0.2198,Event,ADDED,eval-conflicts-rho040-r0-167-62wlc.18d52f4d945ce13d,reason=Created count=1 msg=Created container: task
0.22,Event,ADDED,eval-conflicts-rho040-r0-167-62wlc.18d52f4d9e09b006,reason=Started count=1 msg=Started container task
0.2201,Event,ADDED,eval-conflicts-rho040-r0-167.18d52f4d6e956e14,reason=SuccessfulCreate count=1 msg=Created pod: eval-conflicts-rho040-r0-167-62wlc
0.2203,Event,ADDED,eval-conflicts-rho040-r0-167.18d52f532ae42d9a,reason=Completed count=1 msg=Job completed
0.2205,Event,ADDED,eval-conflicts-rho040-r0-168-swdmg.18d52f4daf57bfc7,"reason=FailedScheduling count=None msg=0/6 nodes are available: 1 c_wall violated: 1 conflicting context pair(s) with node memory, 1 c_wall violated: 2 conflicting context pair(s) with node memory, 1 c_wall violated: 3 conflicting context pair(s) with node memory, 3 node(s) had untolerated taint(s). no new claims to deallocate, preemption: 0/6 nodes are available: 3 No preemption victims found for incoming pod, 3 Preemption is not helpful for scheduling."
0.2207,Event,ADDED,eval-conflicts-rho040-r0-168-swdmg.18d52f4db370e71c,"reason=FailedScheduling count=None msg=0/6 nodes are available: 1 c_wall violated: 1 conflicting context pair(s) with node memory, 1 c_wall violated: 2 conflicting context pair(s) with node memory, 1 c_wall violated: 3 conflicting context pair(s) with node memory, 3 node(s) had untolerated taint(s). no new claims to deallocate, preemption: 0/6 nodes are available: 3 No preemption victims found for incoming pod, 3 Preemption is not helpful for scheduling."
0.221,Event,ADDED,eval-conflicts-rho040-r0-168-swdmg.18d52f4e347ec3d7,"reason=FailedScheduling count=None msg=0/6 nodes are available: 1 c_wall violated: 2 conflicting context pair(s) with node memory, 1 c_wall violated: 3 conflicting context pair(s) with node memory, 4 node(s) had untolerated taint(s). no new claims to deallocate, preemption: 0/6 nodes are available: 2 No preemption victims found for incoming pod, 4 Preemption is not helpful for scheduling."
0.2211,Event,ADDED,eval-conflicts-rho040-r0-168-swdmg.18d52f4e4a808c10,"reason=FailedScheduling count=None msg=0/6 nodes are available: 1 c_wall violated: 2 conflicting context pair(s) with node memory, 5 node(s) had untolerated taint(s). no new claims to deallocate, preemption: 0/6 nodes are available: 1 No preemption victims found for incoming pod, 5 Preemption is not helpful for scheduling."
0.2213,Event,ADDED,eval-conflicts-rho040-r0-168-swdmg.18d52f5176395437,reason=Scheduled count=None msg=Successfully assigned compute/eval-conflicts-rho040-r0-168-swdmg to kind-worker4
0.2215,Event,ADDED,eval-conflicts-rho040-r0-168-swdmg.18d52f5192b7c8cc,"reason=Pulled count=1 msg=Container image ""busybox:musl"" already present on machine"
0.2216,Event,ADDED,eval-conflicts-rho040-r0-168-swdmg.18d52f5193e66351,reason=Created count=1 msg=Created container: task
0.2218,Event,ADDED,eval-conflicts-rho040-r0-168-swdmg.18d52f5195fc0b41,reason=Started count=1 msg=Started container task
0.222,Event,ADDED,eval-conflicts-rho040-r0-168.18d52f4daea6ed81,reason=SuccessfulCreate count=1 msg=Created pod: eval-conflicts-rho040-r0-168-swdmg
0.2221,Event,ADDED,eval-conflicts-rho040-r0-168.18d52f56ca393ef7,reason=Completed count=1 msg=Job completed
0.2223,Event,ADDED,eval-conflicts-rho040-r0-169-pspzq.18d52f4df4a4d791,reason=Scheduled count=None msg=Successfully assigned compute/eval-conflicts-rho040-r0-169-pspzq to kind-worker2
0.2225,Event,ADDED,eval-conflicts-rho040-r0-169-pspzq.18d52f4e0e1dd4cb,"reason=Pulled count=1 msg=Container image ""busybox:musl"" already present on machine"
0.2226,Event,ADDED,eval-conflicts-rho040-r0-169-pspzq.18d52f4e0f23e344,reason=Created count=1 msg=Created container: task
0.2228,Event,ADDED,eval-conflicts-rho040-r0-169-pspzq.18d52f4e14331b4e,reason=Started count=1 msg=Started container task
0.223,Event,ADDED,eval-conflicts-rho040-r0-169.18d52f4df3a40b9b,reason=SuccessfulCreate count=1 msg=Created pod: eval-conflicts-rho040-r0-169-pspzq
0.2231,Event,ADDED,eval-conflicts-rho040-r0-169.18d52f539d8e314d,reason=Completed count=1 msg=Job completed
0.2233,Event,ADDED,eval-conflicts-rho040-r0-170-2k6j5.18d52f4e3983f2ea,"reason=FailedScheduling count=None msg=0/6 nodes are available: 2 c_wall violated: 1 conflicting context pair(s) with node memory, 4 node(s) had untolerated taint(s). no new claims to deallocate, preemption: 0/6 nodes are available: 2 No preemption victims found for incoming pod, 4 Preemption is not helpful for scheduling."
0.2235,Event,ADDED,eval-conflicts-rho040-r0-170-2k6j5.18d52f4e3a74f8a7,"reason=FailedScheduling count=None msg=0/6 nodes are available: 2 c_wall violated: 1 conflicting context pair(s) with node memory, 4 node(s) had untolerated taint(s). no new claims to deallocate, preemption: 0/6 nodes are available: 2 No preemption victims found for incoming pod, 4 Preemption is not helpful for scheduling."
0.2237,Event,ADDED,eval-conflicts-rho040-r0-170-2k6j5.18d52f4e4e49025a,"reason=FailedScheduling count=None msg=0/6 nodes are available: 1 c_wall violated: 1 conflicting context pair(s) with node memory, 5 node(s) had untolerated taint(s). no new claims to deallocate, preemption: 0/6 nodes are available: 1 No preemption victims found for incoming pod, 5 Preemption is not helpful for scheduling."
0.2238,Event,ADDED,eval-conflicts-rho040-r0-170-2k6j5.18d52f5184dd1d18,"reason=FailedScheduling count=None msg=0/6 nodes are available: 2 c_wall violated: 1 conflicting context pair(s) with node memory, 4 node(s) had untolerated taint(s). no new claims to deallocate, preemption: 0/6 nodes are available: 2 No preemption victims found for incoming pod, 4 Preemption is not helpful for scheduling."
0.224,Event,ADDED,eval-conflicts-rho040-r0-170-2k6j5.18d52f51b294ff83,reason=Scheduled count=None msg=Successfully assigned compute/eval-conflicts-rho040-r0-170-2k6j5 to kind-worker
0.2242,Event,ADDED,eval-conflicts-rho040-r0-170-2k6j5.18d52f51cc5124a5,"reason=Pulled count=1 msg=Container image ""busybox:musl"" already present on machine"
0.2243,Event,ADDED,eval-conflicts-rho040-r0-170-2k6j5.18d52f51ce0d18a5,reason=Created count=1 msg=Created container: task
0.2245,Event,ADDED,eval-conflicts-rho040-r0-170-2k6j5.18d52f51d7611bc2,reason=Started count=1 msg=Started container task
0.2247,Event,ADDED,eval-conflicts-rho040-r0-170.18d52f4e392bfc06,reason=SuccessfulCreate count=1 msg=Created pod: eval-conflicts-rho040-r0-170-2k6j5
0.2248,Event,ADDED,eval-conflicts-rho040-r0-170.18d52f576fb430f1,reason=Completed count=1 msg=Job completed
0.225,Event,ADDED,eval-conflicts-rho040-r0-171-dxq9l.18d52f4e6c3cb9b3,"reason=FailedScheduling count=None msg=0/6 nodes are available: 1 c_wall violated: 1 conflicting context pair(s) with node memory, 5 node(s) had untolerated taint(s). no new claims to deallocate, preemption: 0/6 nodes are available: 1 No preemption victims found for incoming pod, 5 Preemption is not helpful for scheduling."
0.2252,Event,ADDED,eval-conflicts-rho040-r0-171-dxq9l.18d52f4e6cb3153e,"reason=FailedScheduling count=None msg=0/6 nodes are available: 1 c_wall violated: 1 conflicting context pair(s) with node memory, 5 node(s) had untolerated taint(s). no new claims to deallocate, preemption: 0/6 nodes are available: 1 No preemption victims found for incoming pod, 5 Preemption is not helpful for scheduling."
0.2253,Event,ADDED,eval-conflicts-rho040-r0-171-dxq9l.18d52f5185327121,"reason=FailedScheduling count=None msg=0/6 nodes are available: 1 c_wall violated: 1 conflicting context pair(s) with node memory, 1 c_wall violated: 2 conflicting context pair(s) with node memory, 4 node(s) had untolerated taint(s). no new claims to deallocate, preemption: 0/6 nodes are available: 2 No preemption victims found for incoming pod, 4 Preemption is not helpful for scheduling."
0.2255,Event,ADDED,eval-conflicts-rho040-r0-171-dxq9l.18d52f51b2b5ec32,"reason=FailedScheduling count=None msg=0/6 nodes are available: 2 c_wall violated: 2 conflicting context pair(s) with node memory, 4 node(s) had untolerated taint(s). no new claims to deallocate, preemption: 0/6 nodes are available: 2 No preemption victims found for incoming pod, 4 Preemption is not helpful for scheduling."
0.2257,Event,ADDED,eval-conflicts-rho040-r0-171-dxq9l.18d52f51b9087490,"reason=FailedScheduling count=None msg=0/6 nodes are available: 2 c_wall violated: 2 conflicting context pair(s) with node memory, 4 node(s) had untolerated taint(s). no new claims to deallocate, preemption: 0/6 nodes are available: 2 No preemption victims found for incoming pod, 4 Preemption is not helpful for scheduling."
0.2258,Event,ADDED,eval-conflicts-rho040-r0-171-dxq9l.18d52f53201ca839,reason=Scheduled count=None msg=Successfully assigned compute/eval-conflicts-rho040-r0-171-dxq9l to kind-worker3
0.226,Event,ADDED,eval-conflicts-rho040-r0-171-dxq9l.18d52f5351118868,"reason=Pulled count=1 msg=Container image ""busybox:musl"" already present on machine"
0.2262,Event,ADDED,eval-conflicts-rho040-r0-171-dxq9l.18d52f5352a3a811,reason=Created count=1 msg=Created container: task
0.2264,Event,ADDED,eval-conflicts-rho040-r0-171-dxq9l.18d52f53579e2689,reason=Started count=1 msg=Started container task
0.2266,Event,ADDED,eval-conflicts-rho040-r0-171.18d52f4e6c097c63,reason=SuccessfulCreate count=1 msg=Created pod: eval-conflicts-rho040-r0-171-dxq9l
0.2267,Event,ADDED,eval-conflicts-rho040-r0-171.18d52f58dcab265e,reason=Completed count=1 msg=Job completed
0.2269,Event,ADDED,eval-conflicts-rho040-r0-172-jxpjr.18d52f4ea10dc6f8,"reason=FailedScheduling count=None msg=0/6 nodes are available: 1 c_wall violated: 1 conflicting context pair(s) with node memory, 5 node(s) had untolerated taint(s). no new claims to deallocate, preemption: 0/6 nodes are available: 1 No preemption victims found for incoming pod, 5 Preemption is not helpful for scheduling."
0.2273,Event,ADDED,eval-conflicts-rho040-r0-172-jxpjr.18d52f4ea1883b38,"reason=FailedScheduling count=None msg=0/6 nodes are available: 1 c_wall violated: 1 conflicting context pair(s) with node memory, 5 node(s) had untolerated taint(s). no new claims to deallocate, preemption: 0/6 nodes are available: 1 No preemption victims found for incoming pod, 5 Preemption is not helpful for scheduling."
0.2275,Event,ADDED,eval-conflicts-rho040-r0-172-jxpjr.18d52f517bb9f547,reason=Scheduled count=None msg=Successfully assigned compute/eval-conflicts-rho040-r0-172-jxpjr to kind-worker4
0.2277,Event,ADDED,eval-conflicts-rho040-r0-172-jxpjr.18d52f51943ac502,"reason=Pulled count=1 msg=Container image ""busybox:musl"" already present on machine"
0.2278,Event,ADDED,eval-conflicts-rho040-r0-172-jxpjr.18d52f5195f51989,reason=Created count=1 msg=Created container: task
0.2282,Event,ADDED,eval-conflicts-rho040-r0-172-jxpjr.18d52f51a0697f21,reason=Started count=1 msg=Started container task
0.2285,Event,ADDED,eval-conflicts-rho040-r0-172.18d52f4ea0cd8175,reason=SuccessfulCreate count=1 msg=Created pod: eval-conflicts-rho040-r0-172-jxpjr
0.2287,Event,ADDED,eval-conflicts-rho040-r0-172.18d52f5704416694,reason=Completed count=1 msg=Job completed
0.2288,Event,ADDED,eval-conflicts-rho040-r0-173-hdfdw.18d52f4ed5eb53fb,reason=Scheduled count=None msg=Successfully assigned compute/eval-conflicts-rho040-r0-173-hdfdw to kind-worker5
0.2292,Event,ADDED,eval-conflicts-rho040-r0-173-hdfdw.18d52f4f0351b28c,"reason=Pulled count=1 msg=Container image ""busybox:musl"" already present on machine"
0.2296,Event,ADDED,eval-conflicts-rho040-r0-173-hdfdw.18d52f4f05c76c15,reason=Created count=1 msg=Created container: task
0.23,Event,ADDED,eval-conflicts-rho040-r0-173-hdfdw.18d52f4f0bf004f4,reason=Started count=1 msg=Started container task
0.2303,Event,ADDED,eval-conflicts-rho040-r0-173.18d52f4ed56a8e78,reason=SuccessfulCreate count=1 msg=Created pod: eval-conflicts-rho040-r0-173-hdfdw
0.2305,Event,ADDED,eval-conflicts-rho040-r0-173.18d52f549bf092cb,reason=Completed count=1 msg=Job completed
0.2307,Event,ADDED,eval-conflicts-rho040-r0-174-6ndpv.18d52f4f0fbfce90,"reason=FailedScheduling count=None msg=0/6 nodes are available: 1 c_wall violated: 1 conflicting context pair(s) with node memory, 5 node(s) had untolerated taint(s). no new claims to deallocate, preemption: 0/6 nodes are available: 1 No preemption victims found for incoming pod, 5 Preemption is not helpful for scheduling."
0.231,Event,ADDED,eval-conflicts-rho040-r0-174-6ndpv.18d52f4f102bb0f5,"reason=FailedScheduling count=None msg=0/6 nodes are available: 1 c_wall violated: 1 conflicting context pair(s) with node memory, 5 node(s) had untolerated taint(s). no new claims to deallocate, preemption: 0/6 nodes are available: 1 No preemption victims found for incoming pod, 5 Preemption is not helpful for scheduling."
0.2311,Event,ADDED,eval-conflicts-rho040-r0-174-6ndpv.18d52f516807f281,reason=Scheduled count=None msg=Successfully assigned compute/eval-conflicts-rho040-r0-174-6ndpv to kind-worker4
0.2313,Event,ADDED,eval-conflicts-rho040-r0-174-6ndpv.18d52f51895a17b4,"reason=Pulled count=1 msg=Container image ""busybox:musl"" already present on machine"
0.2315,Event,ADDED,eval-conflicts-rho040-r0-174-6ndpv.18d52f518d81fc81,reason=Created count=1 msg=Created container: task
0.2318,Event,ADDED,eval-conflicts-rho040-r0-174-6ndpv.18d52f519250cdb4,reason=Started count=1 msg=Started container task
0.232,Event,ADDED,eval-conflicts-rho040-r0-174.18d52f4f0f806c6e,reason=SuccessfulCreate count=1 msg=Created pod: eval-conflicts-rho040-r0-174-6ndpv
0.2321,Event,ADDED,eval-conflicts-rho040-r0-174.18d52f56ca17196b,reason=Completed count=1 msg=Job completed
0.2323,Event,ADDED,eval-conflicts-rho040-r0-175-87pqx.18d52f4f4b69a3be,"reason=FailedScheduling count=None msg=0/6 nodes are available: 1 c_wall violated: 1 conflicting context pair(s) with node memory, 5 node(s) had untolerated taint(s). no new claims to deallocate, preemption: 0/6 nodes are available: 1 No preemption victims found for incoming pod, 5 Preemption is not helpful for scheduling."
0.2325,Event,ADDED,eval-conflicts-rho040-r0-175-87pqx.18d52f4f4c09e468,"reason=FailedScheduling count=None msg=0/6 nodes are available: 1 c_wall violated: 1 conflicting context pair(s) with node memory, 5 node(s) had untolerated taint(s). no new claims to deallocate, preemption: 0/6 nodes are available: 1 No preemption victims found for incoming pod, 5 Preemption is not helpful for scheduling."
0.2327,Event,ADDED,eval-conflicts-rho040-r0-175-87pqx.18d52f516d2d17d1,reason=Scheduled count=None msg=Successfully assigned compute/eval-conflicts-rho040-r0-175-87pqx to kind-worker4
0.2329,Event,ADDED,eval-conflicts-rho040-r0-175-87pqx.18d52f518a055e98,"reason=Pulled count=1 msg=Container image ""busybox:musl"" already present on machine"
0.233,Event,ADDED,eval-conflicts-rho040-r0-175-87pqx.18d52f518e13eed4,reason=Created count=1 msg=Created container: task
0.2332,Event,ADDED,eval-conflicts-rho040-r0-175-87pqx.18d52f51924f3a4c,reason=Started count=1 msg=Started container task
0.2334,Event,ADDED,eval-conflicts-rho040-r0-175.18d52f4f4b269c1e,reason=SuccessfulCreate count=1 msg=Created pod: eval-conflicts-rho040-r0-175-87pqx
0.2336,Event,ADDED,eval-conflicts-rho040-r0-175.18d52f56c90de8c0,reason=Completed count=1 msg=Job completed
0.2337,Event,ADDED,eval-conflicts-rho040-r0-176-2xg9h.18d52f4f88683849,"reason=FailedScheduling count=None msg=0/6 nodes are available: 1 c_wall violated: 1 conflicting context pair(s) with node memory, 5 node(s) had untolerated taint(s). no new claims to deallocate, preemption: 0/6 nodes are available: 1 No preemption victims found for incoming pod, 5 Preemption is not helpful for scheduling."
0.234,Event,ADDED,eval-conflicts-rho040-r0-176-2xg9h.18d52f4f88de942a,"reason=FailedScheduling count=None msg=0/6 nodes are available: 1 c_wall violated: 1 conflicting context pair(s) with node memory, 5 node(s) had untolerated taint(s). no new claims to deallocate, preemption: 0/6 nodes are available: 1 No preemption victims found for incoming pod, 5 Preemption is not helpful for scheduling."
0.2342,Event,ADDED,eval-conflicts-rho040-r0-176-2xg9h.18d52f516e5a6571,reason=Scheduled count=None msg=Successfully assigned compute/eval-conflicts-rho040-r0-176-2xg9h to kind-worker4
0.2345,Event,ADDED,eval-conflicts-rho040-r0-176-2xg9h.18d52f518a28e04a,"reason=Pulled count=1 msg=Container image ""busybox:musl"" already present on machine"
0.2347,Event,ADDED,eval-conflicts-rho040-r0-176-2xg9h.18d52f518e35fbc3,reason=Created count=1 msg=Created container: task
0.2349,Event,ADDED,eval-conflicts-rho040-r0-176-2xg9h.18d52f51924f162e,reason=Started count=1 msg=Started container task
0.2351,Event,ADDED,eval-conflicts-rho040-r0-176.18d52f4f88263dc3,reason=SuccessfulCreate count=1 msg=Created pod: eval-conflicts-rho040-r0-176-2xg9h
0.2353,Event,ADDED,eval-conflicts-rho040-r0-176.18d52f56ca39ad8c,reason=Completed count=1 msg=Job completed
0.2355,Event,ADDED,eval-conflicts-rho040-r0-177-vqqx7.18d52f4fc5cebdf6,"reason=FailedScheduling count=None msg=0/6 nodes are available: 1 c_wall violated: 1 conflicting context pair(s) with node memory, 5 node(s) had untolerated taint(s). no new claims to deallocate, preemption: 0/6 nodes are available: 1 No preemption victims found for incoming pod, 5 Preemption is not helpful for scheduling."
0.2357,Event,ADDED,eval-conflicts-rho040-r0-177-vqqx7.18d52f4fc690bb91,"reason=FailedScheduling count=None msg=0/6 nodes are available: 1 c_wall violated: 1 conflicting context pair(s) with node memory, 5 node(s) had untolerated taint(s). no new claims to deallocate, preemption: 0/6 nodes are available: 1 No preemption victims found for incoming pod, 5 Preemption is not helpful for scheduling."
0.2358,Event,ADDED,eval-conflicts-rho040-r0-177-vqqx7.18d52f517fb567bd,"reason=FailedScheduling count=None msg=0/6 nodes are available: 1 c_wall violated: 1 conflicting context pair(s) with node memory, 1 c_wall violated: 2 conflicting context pair(s) with node memory, 4 node(s) had untolerated taint(s). no new claims to deallocate, preemption: 0/6 nodes are available: 2 No preemption victims found for incoming pod, 4 Preemption is not helpful for scheduling."
0.236,Event,ADDED,eval-conflicts-rho040-r0-177-vqqx7.18d52f518abe568f,"reason=FailedScheduling count=None msg=0/6 nodes are available: 1 c_wall violated: 1 conflicting context pair(s) with node memory, 1 c_wall violated: 2 conflicting context pair(s) with node memory, 4 node(s) had untolerated taint(s). no new claims to deallocate, preemption: 0/6 nodes are available: 2 No preemption victims found for incoming pod, 4 Preemption is not helpful for scheduling."
0.2362,Event,ADDED,eval-conflicts-rho040-r0-177-vqqx7.18d52f51acbf9575,"reason=FailedScheduling count=None msg=0/6 nodes are available: 1 c_wall violated: 1 conflicting context pair(s) with node memory, 1 c_wall violated: 2 conflicting context pair(s) with node memory, 4 node(s) had untolerated taint(s). no new claims to deallocate, preemption: 0/6 nodes are available: 2 No preemption victims found for incoming pod, 4 Preemption is not helpful for scheduling."
0.2363,Event,ADDED,eval-conflicts-rho040-r0-177-vqqx7.18d52f51b84f4295,"reason=FailedScheduling count=None msg=0/6 nodes are available: 2 c_wall violated: 2 conflicting context pair(s) with node memory, 4 node(s) had untolerated taint(s). no new claims to deallocate, preemption: 0/6 nodes are available: 2 No preemption victims found for incoming pod, 4 Preemption is not helpful for scheduling."
0.2365,Event,ADDED,eval-conflicts-rho040-r0-177-vqqx7.18d52f51be32d810,"reason=FailedScheduling count=None msg=0/6 nodes are available: 2 c_wall violated: 2 conflicting context pair(s) with node memory, 4 node(s) had untolerated taint(s). no new claims to deallocate, preemption: 0/6 nodes are available: 2 No preemption victims found for incoming pod, 4 Preemption is not helpful for scheduling."
0.2367,Event,ADDED,eval-conflicts-rho040-r0-177-vqqx7.18d52f531ff39a06,reason=Scheduled count=None msg=Successfully assigned compute/eval-conflicts-rho040-r0-177-vqqx7 to kind-worker3
0.2368,Event,ADDED,eval-conflicts-rho040-r0-177-vqqx7.18d52f533ea452e5,"reason=Pulled count=1 msg=Container image ""busybox:musl"" already present on machine"
0.237,Event,ADDED,eval-conflicts-rho040-r0-177-vqqx7.18d52f533fe1ac21,reason=Created count=1 msg=Created container: task
0.2372,Event,ADDED,eval-conflicts-rho040-r0-177-vqqx7.18d52f5349615691,reason=Started count=1 msg=Started container task
0.2375,Event,ADDED,eval-conflicts-rho040-r0-177.18d52f4fc2ced0bc,reason=SuccessfulCreate count=1 msg=Created pod: eval-conflicts-rho040-r0-177-vqqx7
0.2376,Event,ADDED,eval-conflicts-rho040-r0-177.18d52f58dcab785d,reason=Completed count=1 msg=Job completed
0.2378,Event,ADDED,eval-conflicts-rho040-r0-178-zhf65.18d52f4ffe8372f1,reason=Scheduled count=None msg=Successfully assigned compute/eval-conflicts-rho040-r0-178-zhf65 to kind-worker5
0.238,Event,ADDED,eval-conflicts-rho040-r0-178-zhf65.18d52f5018b0f5b4,"reason=Pulled count=1 msg=Container image ""busybox:musl"" already present on machine"
0.2381,Event,ADDED,eval-conflicts-rho040-r0-178-zhf65.18d52f5019da7b60,reason=Created count=1 msg=Created container: task
0.2383,Event,ADDED,eval-conflicts-rho040-r0-178-zhf65.18d52f501de92472,reason=Started count=1 msg=Started container task
0.2385,Event,ADDED,eval-conflicts-rho040-r0-178.18d52f4ffdf18a71,reason=SuccessfulCreate count=1 msg=Created pod: eval-conflicts-rho040-r0-178-zhf65
0.2388,Event,ADDED,eval-conflicts-rho040-r0-178.18d52f55bf6783ba,reason=Completed count=1 msg=Job completed
0.2389,Event,ADDED,eval-conflicts-rho040-r0-179-76vzs.18d52f503b8742c8,"reason=FailedScheduling count=None msg=0/6 nodes are available: 1 c_wall violated: 1 conflicting context pair(s) with node memory, 5 node(s) had untolerated taint(s). no new claims to deallocate, preemption: 0/6 nodes are available: 1 No preemption victims found for incoming pod, 5 Preemption is not helpful for scheduling."
0.2391,Event,ADDED,eval-conflicts-rho040-r0-179-76vzs.18d52f503c00db2a,"reason=FailedScheduling count=None msg=0/6 nodes are available: 1 c_wall violated: 1 conflicting context pair(s) with node memory, 5 node(s) had untolerated taint(s). no new claims to deallocate, preemption: 0/6 nodes are available: 1 No preemption victims found for incoming pod, 5 Preemption is not helpful for scheduling."
0.2393,Event,ADDED,eval-conflicts-rho040-r0-179-76vzs.18d52f517c9a3a6a,reason=Scheduled count=None msg=Successfully assigned compute/eval-conflicts-rho040-r0-179-76vzs to kind-worker4
0.2394,Event,ADDED,eval-conflicts-rho040-r0-179-76vzs.18d52f5194a2d7e8,"reason=Pulled count=1 msg=Container image ""busybox:musl"" already present on machine"
0.2396,Event,ADDED,eval-conflicts-rho040-r0-179-76vzs.18d52f5196401ad0,reason=Created count=1 msg=Created container: task
0.2398,Event,ADDED,eval-conflicts-rho040-r0-179-76vzs.18d52f519a3b8373,reason=Started count=1 msg=Started container task
0.2401,Event,ADDED,eval-conflicts-rho040-r0-179.18d52f503b486e9b,reason=SuccessfulCreate count=1 msg=Created pod: eval-conflicts-rho040-r0-179-76vzs
0.2403,Event,ADDED,eval-conflicts-rho040-r0-179.18d52f56c9193bcc,reason=Completed count=1 msg=Job completed
0.2404,Event,ADDED,eval-conflicts-rho040-r0-180-r9zx7.18d52f5076e1b999,"reason=FailedScheduling count=None msg=0/6 nodes are available: 1 c_wall violated: 2 conflicting context pair(s) with node memory, 5 node(s) had untolerated taint(s). no new claims to deallocate, preemption: 0/6 nodes are available: 1 No preemption victims found for incoming pod, 5 Preemption is not helpful for scheduling."
0.241,Event,ADDED,eval-conflicts-rho040-r0-180-r9zx7.18d52f5077720b97,"reason=FailedScheduling count=None msg=0/6 nodes are available: 1 c_wall violated: 2 conflicting context pair(s) with node memory, 5 node(s) had untolerated taint(s). no new claims to deallocate, preemption: 0/6 nodes are available: 1 No preemption victims found for incoming pod, 5 Preemption is not helpful for scheduling."
0.2412,Event,ADDED,eval-conflicts-rho040-r0-180-r9zx7.18d52f51858830d5,"reason=FailedScheduling count=None msg=0/6 nodes are available: 1 c_wall violated: 2 conflicting context pair(s) with node memory, 1 c_wall violated: 3 conflicting context pair(s) with node memory, 4 node(s) had untolerated taint(s). no new claims to deallocate, preemption: 0/6 nodes are available: 2 No preemption victims found for incoming pod, 4 Preemption is not helpful for scheduling."
0.2414,Event,ADDED,eval-conflicts-rho040-r0-180-r9zx7.18d52f51af055c66,reason=Scheduled count=None msg=Successfully assigned compute/eval-conflicts-rho040-r0-180-r9zx7 to kind-worker
0.2417,Event,ADDED,eval-conflicts-rho040-r0-180-r9zx7.18d52f51cb65d4b0,"reason=Pulled count=1 msg=Container image ""busybox:musl"" already present on machine"
0.2419,Event,ADDED,eval-conflicts-rho040-r0-180-r9zx7.18d52f51cd103555,reason=Created count=1 msg=Created container: task
0.2421,Event,ADDED,eval-conflicts-rho040-r0-180-r9zx7.18d52f51d7611bae,reason=Started count=1 msg=Started container task
0.2422,Event,ADDED,eval-conflicts-rho040-r0-180.18d52f5076a7d815,reason=SuccessfulCreate count=1 msg=Created pod: eval-conflicts-rho040-r0-180-r9zx7
0.2425,Event,ADDED,eval-conflicts-rho040-r0-180.18d52f576f957fac,reason=Completed count=1 msg=Job completed
0.2426,Event,ADDED,eval-conflicts-rho040-r0-181-b774k.18d52f50b7f0d501,"reason=FailedScheduling count=None msg=0/6 nodes are available: 1 c_wall violated: 1 conflicting context pair(s) with node memory, 5 node(s) had untolerated taint(s). no new claims to deallocate, preemption: 0/6 nodes are available: 1 No preemption victims found for incoming pod, 5 Preemption is not helpful for scheduling."
0.2428,Event,ADDED,eval-conflicts-rho040-r0-181-b774k.18d52f50b86f8f70,"reason=FailedScheduling count=None msg=0/6 nodes are available: 1 c_wall violated: 1 conflicting context pair(s) with node memory, 5 node(s) had untolerated taint(s). no new claims to deallocate, preemption: 0/6 nodes are available: 1 No preemption victims found for incoming pod, 5 Preemption is not helpful for scheduling."
0.243,Event,ADDED,eval-conflicts-rho040-r0-181-b774k.18d52f51679f47f0,reason=Scheduled count=None msg=Successfully assigned compute/eval-conflicts-rho040-r0-181-b774k to kind-worker4
0.2431,Event,ADDED,eval-conflicts-rho040-r0-181-b774k.18d52f518446e0db,"reason=Pulled count=1 msg=Container image ""busybox:musl"" already present on machine"
0.2433,Event,ADDED,eval-conflicts-rho040-r0-181-b774k.18d52f51857f837e,reason=Created count=1 msg=Created container: task
0.2434,Event,ADDED,eval-conflicts-rho040-r0-181-b774k.18d52f518955db08,reason=Started count=1 msg=Started container task
0.2437,Event,ADDED,eval-conflicts-rho040-r0-181.18d52f50b7b2fa2b,reason=SuccessfulCreate count=1 msg=Created pod: eval-conflicts-rho040-r0-181-b774k
0.2438,Event,ADDED,eval-conflicts-rho040-r0-181.18d52f56c920749c,reason=Completed count=1 msg=Job completed
0.244,Event,ADDED,eval-conflicts-rho040-r0-182-8nn2b.18d52f50f6390bda,reason=Scheduled count=None msg=Successfully assigned compute/eval-conflicts-rho040-r0-182-8nn2b to kind-worker5
0.2442,Event,ADDED,eval-conflicts-rho040-r0-182-8nn2b.18d52f5117bc58f0,"reason=Pulled count=1 msg=Container image ""busybox:musl"" already present on machine"
0.2443,Event,ADDED,eval-conflicts-rho040-r0-182-8nn2b.18d52f511905fe18,reason=Created count=1 msg=Created container: task
0.2445,Event,ADDED,eval-conflicts-rho040-r0-182-8nn2b.18d52f511afa856b,reason=Started count=1 msg=Started container task
0.2447,Event,ADDED,eval-conflicts-rho040-r0-182.18d52f50f5a4c9d5,reason=SuccessfulCreate count=1 msg=Created pod: eval-conflicts-rho040-r0-182-8nn2b
0.2448,Event,ADDED,eval-conflicts-rho040-r0-182.18d52f56aea1daa8,reason=Completed count=1 msg=Job completed
0.245,Event,ADDED,eval-conflicts-rho040-r0-183-dmck5.18d52f512a4bd29f,"reason=FailedScheduling count=None msg=0/6 nodes are available: 1 c_wall violated: 2 conflicting context pair(s) with node memory, 5 node(s) had untolerated taint(s). no new claims to deallocate, preemption: 0/6 nodes are available: 1 No preemption victims found for incoming pod, 5 Preemption is not helpful for scheduling."
0.2452,Event,ADDED,eval-conflicts-rho040-r0-183-dmck5.18d52f512aca81fb,"reason=FailedScheduling count=None msg=0/6 nodes are available: 1 c_wall violated: 2 conflicting context pair(s) with node memory, 5 node(s) had untolerated taint(s). no new claims to deallocate, preemption: 0/6 nodes are available: 1 No preemption victims found for incoming pod, 5 Preemption is not helpful for scheduling."
0.2455,Event,ADDED,eval-conflicts-rho040-r0-183-dmck5.18d52f518081e18b,"reason=FailedScheduling count=None msg=0/6 nodes are available: 1 c_wall violated: 1 conflicting context pair(s) with node memory, 1 c_wall violated: 2 conflicting context pair(s) with node memory, 4 node(s) had untolerated taint(s). no new claims to deallocate, preemption: 0/6 nodes are available: 2 No preemption victims found for incoming pod, 4 Preemption is not helpful for scheduling."
0.2457,Event,ADDED,eval-conflicts-rho040-r0-183-dmck5.18d52f51afdc1078,reason=Scheduled count=None msg=Successfully assigned compute/eval-conflicts-rho040-r0-183-dmck5 to kind-worker
0.2459,Event,ADDED,eval-conflicts-rho040-r0-183-dmck5.18d52f51cb938747,"reason=Pulled count=1 msg=Container image ""busybox:musl"" already present on machine"
0.2462,Event,ADDED,eval-conflicts-rho040-r0-183-dmck5.18d52f51cd4df396,reason=Created count=1 msg=Created container: task
0.2463,Event,ADDED,eval-conflicts-rho040-r0-183-dmck5.18d52f51d95da0e5,reason=Started count=1 msg=Started container task
0.2465,Event,ADDED,eval-conflicts-rho040-r0-183.18d52f512a0bc95b,reason=SuccessfulCreate count=1 msg=Created pod: eval-conflicts-rho040-r0-183-dmck5
0.2467,Event,ADDED,eval-conflicts-rho040-r0-183.18d52f572bd4f105,reason=Completed count=1 msg=Job completed
0.247,Event,ADDED,eval-conflicts-rho040-r0-184-ksr7s.18d52f516defb129,reason=Scheduled count=None msg=Successfully assigned compute/eval-conflicts-rho040-r0-184-ksr7s to kind-worker4
0.2471,Event,ADDED,eval-conflicts-rho040-r0-184-ksr7s.18d52f5189dc08e4,"reason=Pulled count=1 msg=Container image ""busybox:musl"" already present on machine"
0.2473,Event,ADDED,eval-conflicts-rho040-r0-184-ksr7s.18d52f518c9477ac,reason=Created count=1 msg=Created container: task
0.2475,Event,ADDED,eval-conflicts-rho040-r0-184-ksr7s.18d52f51912a9a5b,reason=Started count=1 msg=Started container task
0.2477,Event,ADDED,eval-conflicts-rho040-r0-184.18d52f5168f62dee,reason=SuccessfulCreate count=1 msg=Created pod: eval-conflicts-rho040-r0-184-ksr7s
0.2479,Event,ADDED,eval-conflicts-rho040-r0-184.18d52f56c9219823,reason=Completed count=1 msg=Job completed
0.248,Event,ADDED,eval-conflicts-rho040-r0-185-nflw9.18d52f51a682e0fa,"reason=FailedScheduling count=None msg=0/6 nodes are available: 1 c_wall violated: 2 conflicting context pair(s) with node memory, 5 node(s) had untolerated taint(s). no new claims to deallocate, preemption: 0/6 nodes are available: 1 No preemption victims found for incoming pod, 5 Preemption is not helpful for scheduling."
0.2485,Event,ADDED,eval-conflicts-rho040-r0-185-nflw9.18d52f51ac48091c,"reason=FailedScheduling count=None msg=0/6 nodes are available: 1 c_wall violated: 2 conflicting context pair(s) with node memory, 5 node(s) had untolerated taint(s). no new claims to deallocate, preemption: 0/6 nodes are available: 1 No preemption victims found for incoming pod, 5 Preemption is not helpful for scheduling."
0.2487,Event,ADDED,eval-conflicts-rho040-r0-185-nflw9.18d52f51ba72c2aa,"reason=FailedScheduling count=None msg=0/6 nodes are available: 1 c_wall violated: 1 conflicting context pair(s) with node memory, 1 c_wall violated: 2 conflicting context pair(s) with node memory, 4 node(s) had untolerated taint(s). no new claims to deallocate, preemption: 0/6 nodes are available: 2 No preemption victims found for incoming pod, 4 Preemption is not helpful for scheduling."
0.2489,Event,ADDED,eval-conflicts-rho040-r0-185-nflw9.18d52f5313d7e225,reason=Scheduled count=None msg=Successfully assigned compute/eval-conflicts-rho040-r0-185-nflw9 to kind-worker3
0.2491,Event,ADDED,eval-conflicts-rho040-r0-185-nflw9.18d52f5337620ca2,"reason=Pulled count=1 msg=Container image ""busybox:musl"" already present on machine"
0.2493,Event,ADDED,eval-conflicts-rho040-r0-185-nflw9.18d52f5338d74c12,reason=Created count=1 msg=Created container: task
0.2494,Event,ADDED,eval-conflicts-rho040-r0-185-nflw9.18d52f533e7de794,reason=Started count=1 msg=Started container task
0.2496,Event,ADDED,eval-conflicts-rho040-r0-185.18d52f51a2329ead,reason=SuccessfulCreate count=1 msg=Created pod: eval-conflicts-rho040-r0-185-nflw9
0.2498,Event,ADDED,eval-conflicts-rho040-r0-185.18d52f58dcace4f0,reason=Completed count=1 msg=Job completed
0.2499,Event,ADDED,eval-conflicts-rho040-r0-186-mhddk.18d52f51db674c19,reason=Scheduled count=None msg=Successfully assigned compute/eval-conflicts-rho040-r0-186-mhddk to kind-worker
0.2501,Event,ADDED,eval-conflicts-rho040-r0-186-mhddk.18d52f51fc26ab16,"reason=Pulled count=1 msg=Container image ""busybox:musl"" already present on machine"
0.2503,Event,ADDED,eval-conflicts-rho040-r0-186-mhddk.18d52f51fd88e601,reason=Created count=1 msg=Created container: task
0.2505,Event,ADDED,eval-conflicts-rho040-r0-186-mhddk.18d52f52020f8c9a,reason=Started count=1 msg=Started container task
0.2506,Event,ADDED,eval-conflicts-rho040-r0-186.18d52f51dabd771a,reason=SuccessfulCreate count=1 msg=Created pod: eval-conflicts-rho040-r0-186-mhddk
0.2508,Event,ADDED,eval-conflicts-rho040-r0-186.18d52f57a05eee2b,reason=Completed count=1 msg=Job completed
0.2511,Event,ADDED,eval-conflicts-rho040-r0-187-92fc9.18d52f5216e3c3fd,reason=Scheduled count=None msg=Successfully assigned compute/eval-conflicts-rho040-r0-187-92fc9 to kind-worker4
0.2513,Event,ADDED,eval-conflicts-rho040-r0-187-92fc9.18d52f5231f1541d,"reason=Pulled count=1 msg=Container image ""busybox:musl"" already present on machine"
0.2515,Event,ADDED,eval-conflicts-rho040-r0-187-92fc9.18d52f52333d3a28,reason=Created count=1 msg=Created container: task
0.2516,Event,ADDED,eval-conflicts-rho040-r0-187-92fc9.18d52f5235463c65,reason=Started count=1 msg=Started container task
0.2518,Event,ADDED,eval-conflicts-rho040-r0-187.18d52f521643d5e4,reason=SuccessfulCreate count=1 msg=Created pod: eval-conflicts-rho040-r0-187-92fc9
0.252,Event,ADDED,eval-conflicts-rho040-r0-187.18d52f57bee4424b,reason=Completed count=1 msg=Job completed
0.2521,Event,ADDED,eval-conflicts-rho040-r0-188-4jj7s.18d52f5254ed3d3e,reason=Scheduled count=None msg=Successfully assigned compute/eval-conflicts-rho040-r0-188-4jj7s to kind-worker4
0.2523,Event,ADDED,eval-conflicts-rho040-r0-188-4jj7s.18d52f5270d78238,"reason=Pulled count=1 msg=Container image ""busybox:musl"" already present on machine"
0.2524,Event,ADDED,eval-conflicts-rho040-r0-188-4jj7s.18d52f5271ef84a2,reason=Created count=1 msg=Created container: task
0.2526,Event,ADDED,eval-conflicts-rho040-r0-188-4jj7s.18d52f527a7a2c68,reason=Started count=1 msg=Started container task
0.2528,Event,ADDED,eval-conflicts-rho040-r0-188.18d52f525440b4dc,reason=SuccessfulCreate count=1 msg=Created pod: eval-conflicts-rho040-r0-188-4jj7s
0.2529,Event,ADDED,eval-conflicts-rho040-r0-188.18d52f57fdc98ca3,reason=Completed count=1 msg=Job completed
0.2531,Event,ADDED,eval-conflicts-rho040-r0-189-2pxpv.18d52f528f0e9848,reason=Scheduled count=None msg=Successfully assigned compute/eval-conflicts-rho040-r0-189-2pxpv to kind-worker
0.2533,Event,ADDED,eval-conflicts-rho040-r0-189-2pxpv.18d52f52aad750af,"reason=Pulled count=1 msg=Container image ""busybox:musl"" already present on machine"
0.2534,Event,ADDED,eval-conflicts-rho040-r0-189-2pxpv.18d52f52ac326cad,reason=Created count=1 msg=Created container: task
0.2536,Event,ADDED,eval-conflicts-rho040-r0-189-2pxpv.18d52f52bd776af5,reason=Started count=1 msg=Started container task
0.2538,Event,ADDED,eval-conflicts-rho040-r0-189.18d52f528e6c20cf,reason=SuccessfulCreate count=1 msg=Created pod: eval-conflicts-rho040-r0-189-2pxpv
0.2539,Event,ADDED,eval-conflicts-rho040-r0-189.18d52f585408138f,reason=Completed count=1 msg=Job completed
0.2541,Event,ADDED,eval-conflicts-rho040-r0-190-fjcbx.18d52f52ca3339dc,reason=Scheduled count=None msg=Successfully assigned compute/eval-conflicts-rho040-r0-190-fjcbx to kind-worker
0.2542,Event,ADDED,eval-conflicts-rho040-r0-190-fjcbx.18d52f52e836da29,"reason=Pulled count=1 msg=Container image ""busybox:musl"" already present on machine"
0.2544,Event,ADDED,eval-conflicts-rho040-r0-190-fjcbx.18d52f52e9d4c266,reason=Created count=1 msg=Created container: task
0.2546,Event,ADDED,eval-conflicts-rho040-r0-190-fjcbx.18d52f52f02848d5,reason=Started count=1 msg=Started container task
0.2547,Event,ADDED,eval-conflicts-rho040-r0-190.18d52f52c97efc11,reason=SuccessfulCreate count=1 msg=Created pod: eval-conflicts-rho040-r0-190-fjcbx
0.2549,Event,ADDED,eval-conflicts-rho040-r0-190.18d52f588fbea93b,reason=Completed count=1 msg=Job completed
0.255,Event,ADDED,eval-conflicts-rho040-r0-191-r9prs.18d52f53069bce8d,"reason=FailedScheduling count=None msg=0/6 nodes are available: 1 c_wall violated: 1 conflicting context pair(s) with node memory, 1 c_wall violated: 2 conflicting context pair(s) with node memory, 4 node(s) had untolerated taint(s). no new claims to deallocate, preemption: 0/6 nodes are available: 2 No preemption victims found for incoming pod, 4 Preemption is not helpful for scheduling."
0.2552,Event,ADDED,eval-conflicts-rho040-r0-191-r9prs.18d52f53074b8b9a,"reason=FailedScheduling count=None msg=0/6 nodes are available: 1 c_wall violated: 1 conflicting context pair(s) with node memory, 1 c_wall violated: 2 conflicting context pair(s) with node memory, 4 node(s) had untolerated taint(s). no new claims to deallocate, preemption: 0/6 nodes are available: 2 No preemption victims found for incoming pod, 4 Preemption is not helpful for scheduling."
0.2554,Event,ADDED,eval-conflicts-rho040-r0-191-r9prs.18d52f53201d2393,reason=Scheduled count=None msg=Successfully assigned compute/eval-conflicts-rho040-r0-191-r9prs to kind-worker3
0.2555,Event,ADDED,eval-conflicts-rho040-r0-191-r9prs.18d52f5350df8707,"reason=Pulled count=1 msg=Container image ""busybox:musl"" already present on machine"
0.2557,Event,ADDED,eval-conflicts-rho040-r0-191-r9prs.18d52f535237b0ce,reason=Created count=1 msg=Created container: task
0.2559,Event,ADDED,eval-conflicts-rho040-r0-191-r9prs.18d52f53579ec18c,reason=Started count=1 msg=Started container task
0.256,Event,ADDED,eval-conflicts-rho040-r0-191.18d52f5306269273,reason=SuccessfulCreate count=1 msg=Created pod: eval-conflicts-rho040-r0-191-r9prs
0.2562,Event,ADDED,eval-conflicts-rho040-r0-191.18d52f58dc63ab43,reason=Completed count=1 msg=Job completed
0.2564,Event,ADDED,eval-conflicts-rho040-r0-192-kqhwx.18d52f53418ef1cf,reason=Scheduled count=None msg=Successfully assigned compute/eval-conflicts-rho040-r0-192-kqhwx to kind-worker4
0.2565,Event,ADDED,eval-conflicts-rho040-r0-192-kqhwx.18d52f535e9df91d,"reason=Pulled count=1 msg=Container image ""busybox:musl"" already present on machine"
0.2567,Event,ADDED,eval-conflicts-rho040-r0-192-kqhwx.18d52f53600dd5c4,reason=Created count=1 msg=Created container: task
0.2569,Event,ADDED,eval-conflicts-rho040-r0-192-kqhwx.18d52f5366017e7e,reason=Started count=1 msg=Started container task
0.257,Event,ADDED,eval-conflicts-rho040-r0-192.18d52f53409ad881,reason=SuccessfulCreate count=1 msg=Created pod: eval-conflicts-rho040-r0-192-kqhwx
0.2572,Event,ADDED,eval-conflicts-rho040-r0-192.18d52f58ecad7196,reason=Completed count=1 msg=Job completed
0.2573,Event,ADDED,eval-conflicts-rho040-r0-193-h5vlt.18d52f537f57f488,reason=Scheduled count=None msg=Successfully assigned compute/eval-conflicts-rho040-r0-193-h5vlt to kind-worker
0.2577,Event,ADDED,eval-conflicts-rho040-r0-193-h5vlt.18d52f539d72a502,"reason=Pulled count=1 msg=Container image ""busybox:musl"" already present on machine"
0.2578,Event,ADDED,eval-conflicts-rho040-r0-193-h5vlt.18d52f539ef9efce,reason=Created count=1 msg=Created container: task
0.258,Event,ADDED,eval-conflicts-rho040-r0-193-h5vlt.18d52f53a62b6093,reason=Started count=1 msg=Started container task
0.2582,Event,ADDED,eval-conflicts-rho040-r0-193.18d52f537e6e8aab,reason=SuccessfulCreate count=1 msg=Created pod: eval-conflicts-rho040-r0-193-h5vlt
0.2586,Event,ADDED,eval-conflicts-rho040-r0-193.18d52f5949f94555,reason=Completed count=1 msg=Job completed
0.2587,Event,ADDED,eval-conflicts-rho040-r0-194-chpnr.18d52f53b96ef405,reason=Scheduled count=None msg=Successfully assigned compute/eval-conflicts-rho040-r0-194-chpnr to kind-worker
0.2589,Event,ADDED,eval-conflicts-rho040-r0-194-chpnr.18d52f53d7c088be,"reason=Pulled count=1 msg=Container image ""busybox:musl"" already present on machine"
0.2592,Event,ADDED,eval-conflicts-rho040-r0-194-chpnr.18d52f53d8f0466d,reason=Created count=1 msg=Created container: task
0.2594,Event,ADDED,eval-conflicts-rho040-r0-194-chpnr.18d52f53dc5a6c63,reason=Started count=1 msg=Started container task
0.2596,Event,ADDED,eval-conflicts-rho040-r0-194.18d52f53b87a98a2,reason=SuccessfulCreate count=1 msg=Created pod: eval-conflicts-rho040-r0-194-chpnr
0.2598,Event,ADDED,eval-conflicts-rho040-r0-194.18d52f5985c6c0ef,reason=Completed count=1 msg=Job completed
0.2601,Event,ADDED,eval-conflicts-rho040-r0-195-sd4fm.18d52f53f56339c1,reason=Scheduled count=None msg=Successfully assigned compute/eval-conflicts-rho040-r0-195-sd4fm to kind-worker4
0.2603,Event,ADDED,eval-conflicts-rho040-r0-195-sd4fm.18d52f54100a0fb1,"reason=Pulled count=1 msg=Container image ""busybox:musl"" already present on machine"
0.2604,Event,ADDED,eval-conflicts-rho040-r0-195-sd4fm.18d52f54125a75ce,reason=Created count=1 msg=Created container: task
0.2606,Event,ADDED,eval-conflicts-rho040-r0-195-sd4fm.18d52f541578f33d,reason=Started count=1 msg=Started container task
0.2609,Event,ADDED,eval-conflicts-rho040-r0-195.18d52f53f45770a2,reason=SuccessfulCreate count=1 msg=Created pod: eval-conflicts-rho040-r0-195-sd4fm
0.2611,Event,ADDED,eval-conflicts-rho040-r0-195.18d52f59a3f647d0,reason=Completed count=1 msg=Job completed
0.2612,Event,ADDED,eval-conflicts-rho040-r0-196-k9jlf.18d52f5435f62456,reason=Scheduled count=None msg=Successfully assigned compute/eval-conflicts-rho040-r0-196-k9jlf to kind-worker
0.2616,Event,ADDED,eval-conflicts-rho040-r0-196-k9jlf.18d52f54596ef1f8,"reason=Pulled count=1 msg=Container image ""busybox:musl"" already present on machine"
0.2617,Event,ADDED,eval-conflicts-rho040-r0-196-k9jlf.18d52f545ac619c2,reason=Created count=1 msg=Created container: task
0.2619,Event,ADDED,eval-conflicts-rho040-r0-196-k9jlf.18d52f5465ea3ae7,reason=Started count=1 msg=Started container task
0.2621,Event,ADDED,eval-conflicts-rho040-r0-196.18d52f543501dfad,reason=SuccessfulCreate count=1 msg=Created pod: eval-conflicts-rho040-r0-196-k9jlf
0.2624,Event,ADDED,eval-conflicts-rho040-r0-196.18d52f59fbe3082a,reason=Completed count=1 msg=Job completed
0.2626,Event,ADDED,eval-conflicts-rho040-r0-197-zs2x4.18d52f5475c64df1,reason=Scheduled count=None msg=Successfully assigned compute/eval-conflicts-rho040-r0-197-zs2x4 to kind-worker
0.2627,Event,ADDED,eval-conflicts-rho040-r0-197-zs2x4.18d52f549b8fcdc5,"reason=Pulled count=1 msg=Container image ""busybox:musl"" already present on machine"
0.2629,Event,ADDED,eval-conflicts-rho040-r0-197-zs2x4.18d52f549cece031,reason=Created count=1 msg=Created container: task
0.2631,Event,ADDED,eval-conflicts-rho040-r0-197-zs2x4.18d52f54a71c83db,reason=Started count=1 msg=Started container task
0.2633,Event,ADDED,eval-conflicts-rho040-r0-197.18d52f5474cd3b79,reason=SuccessfulCreate count=1 msg=Created pod: eval-conflicts-rho040-r0-197-zs2x4
0.2635,Event,ADDED,eval-conflicts-rho040-r0-197.18d52f5a38d706a9,reason=Completed count=1 msg=Job completed
0.2637,Event,ADDED,eval-conflicts-rho040-r0-198-8jjkr.18d52f54a95fd449,reason=Scheduled count=None msg=Successfully assigned compute/eval-conflicts-rho040-r0-198-8jjkr to kind-worker4
0.2639,Event,ADDED,eval-conflicts-rho040-r0-198-8jjkr.18d52f54cc6e9722,"reason=Pulled count=1 msg=Container image ""busybox:musl"" already present on machine"
0.264,Event,ADDED,eval-conflicts-rho040-r0-198-8jjkr.18d52f54cdb7a5f4,reason=Created count=1 msg=Created container: task
0.2642,Event,ADDED,eval-conflicts-rho040-r0-198-8jjkr.18d52f54d20d24ea,reason=Started count=1 msg=Started container task
0.2644,Event,ADDED,eval-conflicts-rho040-r0-198.18d52f54a8760634,reason=SuccessfulCreate count=1 msg=Created pod: eval-conflicts-rho040-r0-198-8jjkr
0.2645,Event,ADDED,eval-conflicts-rho040-r0-198.18d52f5a4b08dc3a,reason=Completed count=1 msg=Job completed
0.2647,Event,ADDED,eval-conflicts-rho040-r0-199-tmjvr.18d52f54e59241c0,reason=Scheduled count=None msg=Successfully assigned compute/eval-conflicts-rho040-r0-199-tmjvr to kind-worker
0.2649,Event,ADDED,eval-conflicts-rho040-r0-199-tmjvr.18d52f550283cb3a,"reason=Pulled count=1 msg=Container image ""busybox:musl"" already present on machine"
0.265,Event,ADDED,eval-conflicts-rho040-r0-199-tmjvr.18d52f5503b8d88c,reason=Created count=1 msg=Created container: task
0.2652,Event,ADDED,eval-conflicts-rho040-r0-199-tmjvr.18d52f550ebaabe1,reason=Started count=1 msg=Started container task
0.2654,Event,ADDED,eval-conflicts-rho040-r0-199.18d52f54e4a30b80,reason=SuccessfulCreate count=1 msg=Created pod: eval-conflicts-rho040-r0-199-tmjvr
0.2655,Event,ADDED,eval-conflicts-rho040-r0-199.18d52f5a747700c0,reason=Completed count=1 msg=Job completed
0.2657,Event,ADDED,eval-conflicts-rho040-r1-000-c82xs.18d52f6453db74a1,reason=Scheduled count=None msg=Successfully assigned compute/eval-conflicts-rho040-r1-000-c82xs to kind-worker2
0.2659,Event,ADDED,eval-conflicts-rho040-r1-000-c82xs.18d52f646f6d6111,"reason=Pulled count=1 msg=Container image ""busybox:musl"" already present on machine"
0.266,Event,ADDED,eval-conflicts-rho040-r1-000-c82xs.18d52f64709c88bd,reason=Created count=1 msg=Created container: task
0.2662,Event,ADDED,eval-conflicts-rho040-r1-000-c82xs.18d52f6472a04d69,reason=Started count=1 msg=Started container task
0.2664,Event,ADDED,eval-conflicts-rho040-r1-000.18d52f6452f2a2ca,reason=SuccessfulCreate count=1 msg=Created pod: eval-conflicts-rho040-r1-000-c82xs
0.2665,Event,ADDED,eval-conflicts-rho040-r1-000.18d52f6a04bf4a3d,reason=Completed count=1 msg=Job completed
0.2667,Event,ADDED,eval-conflicts-rho040-r1-001-mrggq.18d52f64919f3a09,reason=Scheduled count=None msg=Successfully assigned compute/eval-conflicts-rho040-r1-001-mrggq to kind-worker2
0.2669,Event,ADDED,eval-conflicts-rho040-r1-001-mrggq.18d52f64aa11680c,"reason=Pulled count=1 msg=Container image ""busybox:musl"" already present on machine"
0.267,Event,ADDED,eval-conflicts-rho040-r1-001-mrggq.18d52f64ab2605fc,reason=Created count=1 msg=Created container: task
0.2672,Event,ADDED,eval-conflicts-rho040-r1-001-mrggq.18d52f64af1de8c9,reason=Started count=1 msg=Started container task
0.2674,Event,ADDED,eval-conflicts-rho040-r1-001.18d52f64908efad3,reason=SuccessfulCreate count=1 msg=Created pod: eval-conflicts-rho040-r1-001-mrggq
0.2676,Event,ADDED,eval-conflicts-rho040-r1-001.18d52f6a41a1ce0f,reason=Completed count=1 msg=Job completed
0.2678,Event,ADDED,eval-conflicts-rho040-r1-002-mz5dl.18d52f64c8e4c9d3,reason=Scheduled count=None msg=Successfully assigned compute/eval-conflicts-rho040-r1-002-mz5dl to kind-worker3
0.2679,Event,ADDED,eval-conflicts-rho040-r1-002-mz5dl.18d52f64e2d014aa,"reason=Pulled count=1 msg=Container image ""busybox:musl"" already present on machine"
0.2681,Event,ADDED,eval-conflicts-rho040-r1-002-mz5dl.18d52f64e3d828f4,reason=Created count=1 msg=Created container: task
0.2683,Event,ADDED,eval-conflicts-rho040-r1-002-mz5dl.18d52f64e7b733eb,reason=Started count=1 msg=Started container task
0.2684,Event,ADDED,eval-conflicts-rho040-r1-002.18d52f64c84087cb,reason=SuccessfulCreate count=1 msg=Created pod: eval-conflicts-rho040-r1-002-mz5dl
0.2689,Event,ADDED,eval-conflicts-rho040-r1-002.18d52f6a28916434,reason=Completed count=1 msg=Job completed
0.2691,Event,ADDED,eval-conflicts-rho040-r1-003-dk7n6.18d52f6504963f73,reason=Scheduled count=None msg=Successfully assigned compute/eval-conflicts-rho040-r1-003-dk7n6 to kind-worker4
0.2692,Event,ADDED,eval-conflicts-rho040-r1-003-dk7n6.18d52f651dee6516,"reason=Pulled count=1 msg=Container image ""busybox:musl"" already present on machine"
0.2694,Event,ADDED,eval-conflicts-rho040-r1-003-dk7n6.18d52f651f09c242,reason=Created count=1 msg=Created container: task
0.2698,Event,ADDED,eval-conflicts-rho040-r1-003-dk7n6.18d52f6523106406,reason=Started count=1 msg=Started container task
0.2699,Event,ADDED,eval-conflicts-rho040-r1-003.18d52f65039826b6,reason=SuccessfulCreate count=1 msg=Created pod: eval-conflicts-rho040-r1-003-dk7n6
0.2701,Event,ADDED,eval-conflicts-rho040-r1-003.18d52f6aa21a51d1,reason=Completed count=1 msg=Job completed
0.2703,Event,ADDED,eval-conflicts-rho040-r1-004-nlzlb.18d52f6542357506,reason=Scheduled count=None msg=Successfully assigned compute/eval-conflicts-rho040-r1-004-nlzlb to kind-worker2
0.2706,Event,ADDED,eval-conflicts-rho040-r1-004-nlzlb.18d52f655b59ba05,"reason=Pulled count=1 msg=Container image ""busybox:musl"" already present on machine"
0.2708,Event,ADDED,eval-conflicts-rho040-r1-004-nlzlb.18d52f655c611f12,reason=Created count=1 msg=Created container: task
0.271,Event,ADDED,eval-conflicts-rho040-r1-004-nlzlb.18d52f655e4ac6b3,reason=Started count=1 msg=Started container task
0.2713,Event,ADDED,eval-conflicts-rho040-r1-004.18d52f6540d734cf,reason=SuccessfulCreate count=1 msg=Created pod: eval-conflicts-rho040-r1-004-nlzlb
0.2715,Event,ADDED,eval-conflicts-rho040-r1-004.18d52f6b015e2a63,reason=Completed count=1 msg=Job completed
0.2717,Event,ADDED,eval-conflicts-rho040-r1-005-wrnxd.18d52f657c62f73a,reason=Scheduled count=None msg=Successfully assigned compute/eval-conflicts-rho040-r1-005-wrnxd to kind-worker3
0.2719,Event,ADDED,eval-conflicts-rho040-r1-005-wrnxd.18d52f659b84e0b0,"reason=Pulled count=1 msg=Container image ""busybox:musl"" already present on machine"
0.2721,Event,ADDED,eval-conflicts-rho040-r1-005-wrnxd.18d52f659cba41da,reason=Created count=1 msg=Created container: task
0.2723,Event,ADDED,eval-conflicts-rho040-r1-005-wrnxd.18d52f65a08e4e30,reason=Started count=1 msg=Started container task
0.2725,Event,ADDED,eval-conflicts-rho040-r1-005.18d52f657b4bb6aa,reason=SuccessfulCreate count=1 msg=Created pod: eval-conflicts-rho040-r1-005-wrnxd
0.2728,Event,ADDED,eval-conflicts-rho040-r1-005.18d52f6b1297ddc7,reason=Completed count=1 msg=Job completed
0.2729,Event,ADDED,eval-conflicts-rho040-r1-006-vwzwv.18d52f65b6c58eb6,reason=Scheduled count=None msg=Successfully assigned compute/eval-conflicts-rho040-r1-006-vwzwv to kind-worker3
0.2731,Event,ADDED,eval-conflicts-rho040-r1-006-vwzwv.18d52f65cf8df306,"reason=Pulled count=1 msg=Container image ""busybox:musl"" already present on machine"
0.2733,Event,ADDED,eval-conflicts-rho040-r1-006-vwzwv.18d52f65d0c59818,reason=Created count=1 msg=Created container: task
0.2735,Event,ADDED,eval-conflicts-rho040-r1-006-vwzwv.18d52f65d4826968,reason=Started count=1 msg=Started container task
0.2737,Event,ADDED,eval-conflicts-rho040-r1-006.18d52f65b5f3da9f,reason=SuccessfulCreate count=1 msg=Created pod: eval-conflicts-rho040-r1-006-vwzwv
0.2739,Event,ADDED,eval-conflicts-rho040-r1-006.18d52f6b501e5c20,reason=Completed count=1 msg=Job completed
0.274,Event,ADDED,eval-conflicts-rho040-r1-007-z4twp.18d52f65f9220254,reason=Scheduled count=None msg=Successfully assigned compute/eval-conflicts-rho040-r1-007-z4twp to kind-worker4
0.2742,Event,ADDED,eval-conflicts-rho040-r1-007-z4twp.18d52f661214eac3,"reason=Pulled count=1 msg=Container image ""busybox:musl"" already present on machine"
0.2744,Event,ADDED,eval-conflicts-rho040-r1-007-z4twp.18d52f6613b558e1,reason=Created count=1 msg=Created container: task
0.2746,Event,ADDED,eval-conflicts-rho040-r1-007-z4twp.18d52f66171d0176,reason=Started count=1 msg=Started container task
0.2749,Event,ADDED,eval-conflicts-rho040-r1-007.18d52f65f84b0a73,reason=SuccessfulCreate count=1 msg=Created pod: eval-conflicts-rho040-r1-007-z4twp
0.275,Event,ADDED,eval-conflicts-rho040-r1-007.18d52f6b96fc0104,reason=Completed count=1 msg=Job completed
0.2752,Event,ADDED,eval-conflicts-rho040-r1-008-76w7z.18d52f662e95eaae,reason=Scheduled count=None msg=Successfully assigned compute/eval-conflicts-rho040-r1-008-76w7z to kind-worker5
0.2754,Event,ADDED,eval-conflicts-rho040-r1-008-76w7z.18d52f66496944ec,"reason=Pulled count=1 msg=Container image ""busybox:musl"" already present on machine"
0.2756,Event,ADDED,eval-conflicts-rho040-r1-008-76w7z.18d52f664d775749,reason=Created count=1 msg=Created container: task
0.2758,Event,ADDED,eval-conflicts-rho040-r1-008-76w7z.18d52f6652344567,reason=Started count=1 msg=Started container task
0.2759,Event,ADDED,eval-conflicts-rho040-r1-008.18d52f662dda6655,reason=SuccessfulCreate count=1 msg=Created pod: eval-conflicts-rho040-r1-008-76w7z
0.2761,Event,ADDED,eval-conflicts-rho040-r1-008.18d52f6bebd3e404,reason=Completed count=1 msg=Job completed
0.2766,Event,ADDED,eval-conflicts-rho040-r1-009-h5zb2.18d52f666a297391,reason=Scheduled count=None msg=Successfully assigned compute/eval-conflicts-rho040-r1-009-h5zb2 to kind-worker4
0.2769,Event,ADDED,eval-conflicts-rho040-r1-009-h5zb2.18d52f668380302d,"reason=Pulled count=1 msg=Container image ""busybox:musl"" already present on machine"
0.2771,Event,ADDED,eval-conflicts-rho040-r1-009-h5zb2.18d52f6684933244,reason=Created count=1 msg=Created container: task
0.2772,Event,ADDED,eval-conflicts-rho040-r1-009-h5zb2.18d52f6688556499,reason=Started count=1 msg=Started container task
0.2774,Event,ADDED,eval-conflicts-rho040-r1-009.18d52f666956c513,reason=SuccessfulCreate count=1 msg=Created pod: eval-conflicts-rho040-r1-009-h5zb2
0.2776,Event,ADDED,eval-conflicts-rho040-r1-009.18d52f6bd4fcd679,reason=Completed count=1 msg=Job completed
0.2777,Event,ADDED,eval-conflicts-rho040-r1-010-zsp6m.18d52f66a644b0c0,reason=Scheduled count=None msg=Successfully assigned compute/eval-conflicts-rho040-r1-010-zsp6m to kind-worker4
0.2779,Event,ADDED,eval-conflicts-rho040-r1-010-zsp6m.18d52f66c0123da2,"reason=Pulled count=1 msg=Container image ""busybox:musl"" already present on machine"
0.2781,Event,ADDED,eval-conflicts-rho040-r1-010-zsp6m.18d52f66c13bac00,reason=Created count=1 msg=Created container: task
0.2782,Event,ADDED,eval-conflicts-rho040-r1-010-zsp6m.18d52f66c4e60165,reason=Started count=1 msg=Started container task
0.2784,Event,ADDED,eval-conflicts-rho040-r1-010.18d52f66a563afc2,reason=SuccessfulCreate count=1 msg=Created pod: eval-conflicts-rho040-r1-010-zsp6m
0.2785,Event,ADDED,eval-conflicts-rho040-r1-010.18d52f6c480a0e6b,reason=Completed count=1 msg=Job completed
0.2788,Event,ADDED,eval-conflicts-rho040-r1-011-j8dcz.18d52f66e1a98ad7,reason=Scheduled count=None msg=Successfully assigned compute/eval-conflicts-rho040-r1-011-j8dcz to kind-worker5
0.2789,Event,ADDED,eval-conflicts-rho040-r1-011-j8dcz.18d52f66fb7a3c72,"reason=Pulled count=1 msg=Container image ""busybox:musl"" already present on machine"
0.2791,Event,ADDED,eval-conflicts-rho040-r1-011-j8dcz.18d52f66fc96f9a5,reason=Created count=1 msg=Created container: task
0.2793,Event,ADDED,eval-conflicts-rho040-r1-011-j8dcz.18d52f66feaaa63a,reason=Started count=1 msg=Started container task
0.2795,Event,ADDED,eval-conflicts-rho040-r1-011.18d52f66e0cb877a,reason=SuccessfulCreate count=1 msg=Created pod: eval-conflicts-rho040-r1-011-j8dcz
0.2797,Event,ADDED,eval-conflicts-rho040-r1-011.18d52f6c9ae4efda,reason=Completed count=1 msg=Job completed
0.2798,Event,ADDED,eval-conflicts-rho040-r1-012-sq2bf.18d52f671db3ea01,reason=Scheduled count=None msg=Successfully assigned compute/eval-conflicts-rho040-r1-012-sq2bf to kind-worker
0.2801,Event,ADDED,eval-conflicts-rho040-r1-012-sq2bf.18d52f6736e1d046,"reason=Pulled count=1 msg=Container image ""busybox:musl"" already present on machine"
0.2802,Event,ADDED,eval-conflicts-rho040-r1-012-sq2bf.18d52f6737fb0d60,reason=Created count=1 msg=Created container: task
0.2805,Event,ADDED,eval-conflicts-rho040-r1-012-sq2bf.18d52f673a026774,reason=Started count=1 msg=Started container task
0.2807,Event,ADDED,eval-conflicts-rho040-r1-012.18d52f671c9af262,reason=SuccessfulCreate count=1 msg=Created pod: eval-conflicts-rho040-r1-012-sq2bf
0.281,Event,ADDED,eval-conflicts-rho040-r1-012.18d52f6ca1aea6fd,reason=Completed count=1 msg=Job completed
0.2812,Event,ADDED,eval-conflicts-rho040-r1-013-s5lfq.18d52f67597cdcd2,reason=Scheduled count=None msg=Successfully assigned compute/eval-conflicts-rho040-r1-013-s5lfq to kind-worker
0.2813,Event,ADDED,eval-conflicts-rho040-r1-013-s5lfq.18d52f6772e3b7fc,"reason=Pulled count=1 msg=Container image ""busybox:musl"" already present on machine"
0.2815,Event,ADDED,eval-conflicts-rho040-r1-013-s5lfq.18d52f67748e674d,reason=Created count=1 msg=Created container: task
0.2818,Event,ADDED,eval-conflicts-rho040-r1-013-s5lfq.18d52f6777f86ad7,reason=Started count=1 msg=Started container task
0.282,Event,ADDED,eval-conflicts-rho040-r1-013.18d52f6758469b77,reason=SuccessfulCreate count=1 msg=Created pod: eval-conflicts-rho040-r1-013-s5lfq
0.2822,Event,ADDED,eval-conflicts-rho040-r1-013.18d52f6cdd9fcffe,reason=Completed count=1 msg=Job completed
0.2825,Event,ADDED,eval-conflicts-rho040-r1-014-hhdvg.18d52f67984fec38,reason=Scheduled count=None msg=Successfully assigned compute/eval-conflicts-rho040-r1-014-hhdvg to kind-worker5
0.2827,Event,ADDED,eval-conflicts-rho040-r1-014-hhdvg.18d52f67b229c0c7,"reason=Pulled count=1 msg=Container image ""busybox:musl"" already present on machine"
0.2828,Event,ADDED,eval-conflicts-rho040-r1-014-hhdvg.18d52f67b38fd630,reason=Created count=1 msg=Created container: task
0.283,Event,ADDED,eval-conflicts-rho040-r1-014-hhdvg.18d52f67b7a01b86,reason=Started count=1 msg=Started container task
0.2832,Event,ADDED,eval-conflicts-rho040-r1-014.18d52f67939acf72,reason=SuccessfulCreate count=1 msg=Created pod: eval-conflicts-rho040-r1-014-hhdvg
0.2834,Event,ADDED,eval-conflicts-rho040-r1-014.18d52f6d55412cc3,reason=Completed count=1 msg=Job completed
0.2836,Event,ADDED,eval-conflicts-rho040-r1-015-4qkx6.18d52f67d027453a,reason=Scheduled count=None msg=Successfully assigned compute/eval-conflicts-rho040-r1-015-4qkx6 to kind-worker
0.2837,Event,ADDED,eval-conflicts-rho040-r1-015-4qkx6.18d52f67ea70b6e0,"reason=Pulled count=1 msg=Container image ""busybox:musl"" already present on machine"
0.284,Event,ADDED,eval-conflicts-rho040-r1-015-4qkx6.18d52f67eb76985a,reason=Created count=1 msg=Created container: task
0.2842,Event,ADDED,eval-conflicts-rho040-r1-015-4qkx6.18d52f67ed7259e1,reason=Started count=1 msg=Started container task
0.2844,Event,ADDED,eval-conflicts-rho040-r1-015.18d52f67cee9f94f,reason=SuccessfulCreate count=1 msg=Created pod: eval-conflicts-rho040-r1-015-4qkx6
0.2846,Event,ADDED,eval-conflicts-rho040-r1-015.18d52f6d5561f25d,reason=Completed count=1 msg=Job completed
0.2847,Event,ADDED,eval-conflicts-rho040-r1-016-lvz7m.18d52f680c9e9b84,reason=Scheduled count=None msg=Successfully assigned compute/eval-conflicts-rho040-r1-016-lvz7m to kind-worker4
0.2849,Event,ADDED,eval-conflicts-rho040-r1-016-lvz7m.18d52f6825beb42a,"reason=Pulled count=1 msg=Container image ""busybox:musl"" already present on machine"
0.285,Event,ADDED,eval-conflicts-rho040-r1-016-lvz7m.18d52f6826f2cdaa,reason=Created count=1 msg=Created container: task
0.2854,Event,ADDED,eval-conflicts-rho040-r1-016-lvz7m.18d52f682b89bc9c,reason=Started count=1 msg=Started container task
0.2855,Event,ADDED,eval-conflicts-rho040-r1-016.18d52f680b697b66,reason=SuccessfulCreate count=1 msg=Created pod: eval-conflicts-rho040-r1-016-lvz7m
0.2857,Event,ADDED,eval-conflicts-rho040-r1-016.18d52f6dafb69fcb,reason=Completed count=1 msg=Job completed
0.286,Event,ADDED,eval-conflicts-rho040-r1-017-d2xp6.18d52f684784b80d,"reason=FailedScheduling count=None msg=0/6 nodes are available: 1 c_wall violated: 2 conflicting context pair(s) with node memory, 2 c_wall violated: 1 conflicting context pair(s) with node memory, 3 node(s) had untolerated taint(s). no new claims to deallocate, preemption: 0/6 nodes are available: 3 No preemption victims found for incoming pod, 3 Preemption is not helpful for scheduling."
0.2862,Event,ADDED,eval-conflicts-rho040-r1-017-d2xp6.18d52f684a020748,"reason=FailedScheduling count=None msg=0/6 nodes are available: 1 c_wall violated: 2 conflicting context pair(s) with node memory, 2 c_wall violated: 1 conflicting context pair(s) with node memory, 3 node(s) had untolerated taint(s). no new claims to deallocate, preemption: 0/6 nodes are available: 3 No preemption victims found for incoming pod, 3 Preemption is not helpful for scheduling."
0.2864,Event,ADDED,eval-conflicts-rho040-r1-017-d2xp6.18d52f68eecab2aa,"reason=FailedScheduling count=None msg=0/6 nodes are available: 1 c_wall violated: 1 conflicting context pair(s) with node memory, 1 c_wall violated: 2 conflicting context pair(s) with node memory, 4 node(s) had untolerated taint(s). no new claims to deallocate, preemption: 0/6 nodes are available: 2 No preemption victims found for incoming pod, 4 Preemption is not helpful for scheduling."
0.2867,Event,ADDED,eval-conflicts-rho040-r1-017-d2xp6.18d52f6944834ab4,"reason=FailedScheduling count=None msg=0/6 nodes are available: 1 c_wall violated: 1 conflicting context pair(s) with node memory, 5 node(s) had untolerated taint(s). no new claims to deallocate, preemption: 0/6 nodes are available: 1 No preemption victims found for incoming pod, 5 Preemption is not helpful for scheduling."
0.2869,Event,ADDED,eval-conflicts-rho040-r1-017-d2xp6.18d52f6da757c68a,reason=Scheduled count=None msg=Successfully assigned compute/eval-conflicts-rho040-r1-017-d2xp6 to kind-worker4
0.2871,Event,ADDED,eval-conflicts-rho040-r1-017-d2xp6.18d52f6dc413d5e2,"reason=Pulled count=1 msg=Container image ""busybox:musl"" already present on machine"
0.2873,Event,ADDED,eval-conflicts-rho040-r1-017-d2xp6.18d52f6dc62ee258,reason=Created count=1 msg=Created container: task
0.2875,Event,ADDED,eval-conflicts-rho040-r1-017-d2xp6.18d52f6dccd14690,reason=Started count=1 msg=Started container task
0.2877,Event,ADDED,eval-conflicts-rho040-r1-017.18d52f6846b003a9,reason=SuccessfulCreate count=1 msg=Created pod: eval-conflicts-rho040-r1-017-d2xp6
0.2878,Event,ADDED,eval-conflicts-rho040-r1-017.18d52f734cfb2987,reason=Completed count=1 msg=Job completed
0.288,Event,ADDED,eval-conflicts-rho040-r1-018-pgf6f.18d52f6883769440,reason=Scheduled count=None msg=Successfully assigned compute/eval-conflicts-rho040-r1-018-pgf6f to kind-worker5
0.2882,Event,ADDED,eval-conflicts-rho040-r1-018-pgf6f.18d52f689eb4d250,"reason=Pulled count=1 msg=Container image ""busybox:musl"" already present on machine"
0.2883,Event,ADDED,eval-conflicts-rho040-r1-018-pgf6f.18d52f689fd53e27,reason=Created count=1 msg=Created container: task
0.2885,Event,ADDED,eval-conflicts-rho040-r1-018-pgf6f.18d52f68a4984816,reason=Started count=1 msg=Started container task
0.2887,Event,ADDED,eval-conflicts-rho040-r1-018.18d52f6882334195,reason=SuccessfulCreate count=1 msg=Created pod: eval-conflicts-rho040-r1-018-pgf6f
0.2888,Event,ADDED,eval-conflicts-rho040-r1-018.18d52f6e3de8544e,reason=Completed count=1 msg=Job completed
0.2891,Event,ADDED,eval-conflicts-rho040-r1-019-jcs2b.18d52f68c0c2864c,reason=Scheduled count=None msg=Successfully assigned compute/eval-conflicts-rho040-r1-019-jcs2b to kind-worker5
0.2894,Event,ADDED,eval-conflicts-rho040-r1-019-jcs2b.18d52f68e23949c1,"reason=Pulled count=1 msg=Container image ""busybox:musl"" already present on machine"
0.2895,Event,ADDED,eval-conflicts-rho040-r1-019-jcs2b.18d52f68e3600bd1,reason=Created count=1 msg=Created container: task
0.2897,Event,ADDED,eval-conflicts-rho040-r1-019-jcs2b.18d52f68edcd8774,reason=Started count=1 msg=Started container task
0.2899,Event,ADDED,eval-conflicts-rho040-r1-019.18d52f68bf749a2a,reason=SuccessfulCreate count=1 msg=Created pod: eval-conflicts-rho040-r1-019-jcs2b
0.2901,Event,ADDED,eval-conflicts-rho040-r1-019.18d52f6e79ae0269,reason=Completed count=1 msg=Job completed
0.2903,Event,ADDED,eval-conflicts-rho040-r1-020-5l8fj.18d52f68fc984a2a,reason=Scheduled count=None msg=Successfully assigned compute/eval-conflicts-rho040-r1-020-5l8fj to kind-worker5
0.2904,Event,ADDED,eval-conflicts-rho040-r1-020-5l8fj.18d52f692301ca47,"reason=Pulled count=1 msg=Container image ""busybox:musl"" already present on machine"
0.2906,Event,ADDED,eval-conflicts-rho040-r1-020-5l8fj.18d52f69240d4d38,reason=Created count=1 msg=Created container: task
0.2908,Event,ADDED,eval-conflicts-rho040-r1-020-5l8fj.18d52f692ce8d83c,reason=Started count=1 msg=Started container task
0.291,Event,ADDED,eval-conflicts-rho040-r1-020.18d52f68fbdab538,reason=SuccessfulCreate count=1 msg=Created pod: eval-conflicts-rho040-r1-020-5l8fj
0.2911,Event,ADDED,eval-conflicts-rho040-r1-020.18d52f6e7a295e23,reason=Completed count=1 msg=Job completed
0.2915,Event,ADDED,eval-conflicts-rho040-r1-021-59rdt.18d52f6936c1a2eb,reason=Scheduled count=None msg=Successfully assigned compute/eval-conflicts-rho040-r1-021-59rdt to kind-worker5
0.2917,Event,ADDED,eval-conflicts-rho040-r1-021-59rdt.18d52f6950c4debf,"reason=Pulled count=1 msg=Container image ""busybox:musl"" already present on machine"
0.2919,Event,ADDED,eval-conflicts-rho040-r1-021-59rdt.18d52f6951cc49ad,reason=Created count=1 msg=Created container: task
0.2921,Event,ADDED,eval-conflicts-rho040-r1-021-59rdt.18d52f69565fc579,reason=Started count=1 msg=Started container task
0.2924,Event,ADDED,eval-conflicts-rho040-r1-021.18d52f6936117ac6,reason=SuccessfulCreate count=1 msg=Created pod: eval-conflicts-rho040-r1-021-59rdt
0.2925,Event,ADDED,eval-conflicts-rho040-r1-021.18d52f6ef45a12ac,reason=Completed count=1 msg=Job completed
0.2927,Event,ADDED,eval-conflicts-rho040-r1-022-gkbnl.18d52f69792c998c,"reason=FailedScheduling count=None msg=0/6 nodes are available: 6 node(s) had untolerated taint(s). no new claims to deallocate, preemption: 0/6 nodes are available: 6 Preemption is not helpful for scheduling."
0.2929,Event,ADDED,eval-conflicts-rho040-r1-022-gkbnl.18d52f6da7310708,"reason=FailedScheduling count=None msg=0/6 nodes are available: 1 c_wall violated: 1 conflicting context pair(s) with node memory, 5 node(s) had untolerated taint(s). no new claims to deallocate, preemption: 0/6 nodes are available: 1 No preemption victims found for incoming pod, 5 Preemption is not helpful for scheduling."
0.293,Event,ADDED,eval-conflicts-rho040-r1-022-gkbnl.18d52f6dbaca3fe2,"reason=FailedScheduling count=None msg=0/6 nodes are available: 1 c_wall violated: 2 conflicting context pair(s) with node memory, 5 node(s) had untolerated taint(s). no new claims to deallocate, preemption: 0/6 nodes are available: 1 No preemption victims found for incoming pod, 5 Preemption is not helpful for scheduling."
0.2932,Event,ADDED,eval-conflicts-rho040-r1-022-gkbnl.18d52f6dc8479685,"reason=FailedScheduling count=None msg=0/6 nodes are available: 1 c_wall violated: 2 conflicting context pair(s) with node memory, 5 node(s) had untolerated taint(s). no new claims to deallocate, preemption: 0/6 nodes are available: 1 No preemption victims found for incoming pod, 5 Preemption is not helpful for scheduling."
0.2934,Event,ADDED,eval-conflicts-rho040-r1-022-gkbnl.18d52f6e10ad7aa6,reason=Scheduled count=None msg=Successfully assigned compute/eval-conflicts-rho040-r1-022-gkbnl to kind-worker
0.2936,Event,ADDED,eval-conflicts-rho040-r1-022-gkbnl.18d52f6e2e89d7ea,"reason=Pulled count=1 msg=Container image ""busybox:musl"" already present on machine"
0.2938,Event,ADDED,eval-conflicts-rho040-r1-022-gkbnl.18d52f6e32037706,reason=Created count=1 msg=Created container: task
0.2939,Event,ADDED,eval-conflicts-rho040-r1-022-gkbnl.18d52f6e36a6def6,reason=Started count=1 msg=Started container task
0.2941,Event,ADDED,eval-conflicts-rho040-r1-022.18d52f6979233945,reason=SuccessfulCreate count=1 msg=Created pod: eval-conflicts-rho040-r1-022-gkbnl
0.2943,Event,ADDED,eval-conflicts-rho040-r1-022.18d52f7452cd061f,reason=Completed count=1 msg=Job completed
0.2944,Event,ADDED,eval-conflicts-rho040-r1-023-9nvl6.18d52f69b0a5e4f9,"reason=FailedScheduling count=None msg=0/6 nodes are available: 6 node(s) had untolerated taint(s). no new claims to deallocate, preemption: 0/6 nodes are available: 6 Preemption is not helpful for scheduling."
0.2946,Event,ADDED,eval-conflicts-rho040-r1-023-9nvl6.18d52f6da7dc50b6,"reason=FailedScheduling count=None msg=0/6 nodes are available: 1 c_wall violated: 1 conflicting context pair(s) with node memory, 5 node(s) had untolerated taint(s). no new claims to deallocate, preemption: 0/6 nodes are available: 1 No preemption victims found for incoming pod, 5 Preemption is not helpful for scheduling."
0.2947,Event,ADDED,eval-conflicts-rho040-r1-023-9nvl6.18d52f6dbd0a50a6,"reason=FailedScheduling count=None msg=0/6 nodes are available: 1 c_wall violated: 2 conflicting context pair(s) with node memory, 5 node(s) had untolerated taint(s). no new claims to deallocate, preemption: 0/6 nodes are available: 1 No preemption victims found for incoming pod, 5 Preemption is not helpful for scheduling."
0.2949,Event,ADDED,eval-conflicts-rho040-r1-023-9nvl6.18d52f6dc87eeac5,"reason=FailedScheduling count=None msg=0/6 nodes are available: 1 c_wall violated: 2 conflicting context pair(s) with node memory, 5 node(s) had untolerated taint(s). no new claims to deallocate, preemption: 0/6 nodes are available: 1 No preemption victims found for incoming pod, 5 Preemption is not helpful for scheduling."
0.2951,Event,ADDED,eval-conflicts-rho040-r1-023-9nvl6.18d52f6e10d172ff,reason=Scheduled count=None msg=Successfully assigned compute/eval-conflicts-rho040-r1-023-9nvl6 to kind-worker
0.2953,Event,ADDED,eval-conflicts-rho040-r1-023-9nvl6.18d52f6e2ed6dc3e,"reason=Pulled count=1 msg=Container image ""busybox:musl"" already present on machine"
0.2955,Event,ADDED,eval-conflicts-rho040-r1-023-9nvl6.18d52f6e32a93198,reason=Created count=1 msg=Created container: task
0.2957,Event,ADDED,eval-conflicts-rho040-r1-023-9nvl6.18d52f6e367ede73,reason=Started count=1 msg=Started container task
0.2959,Event,ADDED,eval-conflicts-rho040-r1-023.18d52f69b09b689c,reason=SuccessfulCreate count=1 msg=Created pod: eval-conflicts-rho040-r1-023-9nvl6
0.2961,Event,ADDED,eval-conflicts-rho040-r1-023.18d52f73a807ea3e,reason=Completed count=1 msg=Job completed
0.2962,Event,ADDED,eval-conflicts-rho040-r1-024-2rd9v.18d52f69ec8cd864,"reason=FailedScheduling count=None msg=0/6 nodes are available: 6 node(s) had untolerated taint(s). no new claims to deallocate, preemption: 0/6 nodes are available: 6 Preemption is not helpful for scheduling."
0.2963,Event,ADDED,eval-conflicts-rho040-r1-024-2rd9v.18d52f6da9f0943e,reason=Scheduled count=None msg=Successfully assigned compute/eval-conflicts-rho040-r1-024-2rd9v to kind-worker4
0.2968,Event,ADDED,eval-conflicts-rho040-r1-024-2rd9v.18d52f6dc434c46f,"reason=Pulled count=1 msg=Container image ""busybox:musl"" already present on machine"
0.2971,Event,ADDED,eval-conflicts-rho040-r1-024-2rd9v.18d52f6dc6d38da1,reason=Created count=1 msg=Created container: task
0.2973,Event,ADDED,eval-conflicts-rho040-r1-024-2rd9v.18d52f6dccd121be,reason=Started count=1 msg=Started container task
0.2976,Event,ADDED,eval-conflicts-rho040-r1-024.18d52f69ec83ac25,reason=SuccessfulCreate count=1 msg=Created pod: eval-conflicts-rho040-r1-024-2rd9v
0.2978,Event,ADDED,eval-conflicts-rho040-r1-024.18d52f734bff0dd0,reason=Completed count=1 msg=Job completed
0.298,Event,ADDED,eval-conflicts-rho040-r1-025-njhxl.18d52f6a290f70b6,"reason=FailedScheduling count=None msg=0/6 nodes are available: 6 node(s) had untolerated taint(s). no new claims to deallocate, preemption: 0/6 nodes are available: 6 Preemption is not helpful for scheduling."
0.2981,Event,ADDED,eval-conflicts-rho040-r1-025-njhxl.18d52f6da9e33921,"reason=FailedScheduling count=None msg=0/6 nodes are available: 1 c_wall violated: 1 conflicting context pair(s) with node memory, 5 node(s) had untolerated taint(s). no new claims to deallocate, preemption: 0/6 nodes are available: 1 No preemption victims found for incoming pod, 5 Preemption is not helpful for scheduling."
0.2983,Event,ADDED,eval-conflicts-rho040-r1-025-njhxl.18d52f6dbdaa1c3f,"reason=FailedScheduling count=None msg=0/6 nodes are available: 1 c_wall violated: 2 conflicting context pair(s) with node memory, 5 node(s) had untolerated taint(s). no new claims to deallocate, preemption: 0/6 nodes are available: 1 No preemption victims found for incoming pod, 5 Preemption is not helpful for scheduling."
0.2985,Event,ADDED,eval-conflicts-rho040-r1-025-njhxl.18d52f6dc8a5ea8b,"reason=FailedScheduling count=None msg=0/6 nodes are available: 1 c_wall violated: 2 conflicting context pair(s) with node memory, 5 node(s) had untolerated taint(s). no new claims to deallocate, preemption: 0/6 nodes are available: 1 No preemption victims found for incoming pod, 5 Preemption is not helpful for scheduling."
0.2987,Event,ADDED,eval-conflicts-rho040-r1-025-njhxl.18d52f6e10d049e6,reason=Scheduled count=None msg=Successfully assigned compute/eval-conflicts-rho040-r1-025-njhxl to kind-worker
0.2989,Event,ADDED,eval-conflicts-rho040-r1-025-njhxl.18d52f6e2eaafacf,"reason=Pulled count=1 msg=Container image ""busybox:musl"" already present on machine"
0.299,Event,ADDED,eval-conflicts-rho040-r1-025-njhxl.18d52f6e325862a1,reason=Created count=1 msg=Created container: task
0.2992,Event,ADDED,eval-conflicts-rho040-r1-025-njhxl.18d52f6e36aa99fe,reason=Started count=1 msg=Started container task
0.2994,Event,ADDED,eval-conflicts-rho040-r1-025.18d52f6a29028a04,reason=SuccessfulCreate count=1 msg=Created pod: eval-conflicts-rho040-r1-025-njhxl
0.2995,Event,ADDED,eval-conflicts-rho040-r1-025.18d52f747caa3a14,reason=Completed count=1 msg=Job completed
0.2997,Event,ADDED,eval-conflicts-rho040-r1-026-4m4vn.18d52f6a642f01cc,"reason=FailedScheduling count=None msg=0/6 nodes are available: 6 node(s) had untolerated taint(s). no new claims to deallocate, preemption: 0/6 nodes are available: 6 Preemption is not helpful for scheduling."
0.2998,Event,ADDED,eval-conflicts-rho040-r1-026-4m4vn.18d52f6daa6853c7,"reason=FailedScheduling count=None msg=0/6 nodes are available: 1 c_wall violated: 1 conflicting context pair(s) with node memory, 5 node(s) had untolerated taint(s). no new claims to deallocate, preemption: 0/6 nodes are available: 1 No preemption victims found for incoming pod, 5 Preemption is not helpful for scheduling."
0.3,Event,ADDED,eval-conflicts-rho040-r1-026-4m4vn.18d52f6dbe2a7d44,"reason=FailedScheduling count=None msg=0/6 nodes are available: 1 c_wall violated: 1 conflicting context pair(s) with node memory, 5 node(s) had untolerated taint(s). no new claims to deallocate, preemption: 0/6 nodes are available: 1 No preemption victims found for incoming pod, 5 Preemption is not helpful for scheduling."
0.3002,Event,ADDED,eval-conflicts-rho040-r1-026-4m4vn.18d52f6e27b317dd,"reason=FailedScheduling count=None msg=0/6 nodes are available: 1 c_wall violated: 1 conflicting context pair(s) with node memory, 1 c_wall violated: 2 conflicting context pair(s) with node memory, 4 node(s) had untolerated taint(s). no new claims to deallocate, preemption: 0/6 nodes are available: 2 No preemption victims found for incoming pod, 4 Preemption is not helpful for scheduling."
0.3004,Event,ADDED,eval-conflicts-rho040-r1-026-4m4vn.18d52f6f265a2d39,reason=Scheduled count=None msg=Successfully assigned compute/eval-conflicts-rho040-r1-026-4m4vn to kind-worker2
0.3005,Event,ADDED,eval-conflicts-rho040-r1-026-4m4vn.18d52f6f412d35bd,"reason=Pulled count=1 msg=Container image ""busybox:musl"" already present on machine"
0.3007,Event,ADDED,eval-conflicts-rho040-r1-026-4m4vn.18d52f6f42c0733d,reason=Created count=1 msg=Created container: task
0.3009,Event,ADDED,eval-conflicts-rho040-r1-026-4m4vn.18d52f6f4738b057,reason=Started count=1 msg=Started container task
0.301,Event,ADDED,eval-conflicts-rho040-r1-026.18d52f6a64222647,reason=SuccessfulCreate count=1 msg=Created pod: eval-conflicts-rho040-r1-026-4m4vn
0.3012,Event,ADDED,eval-conflicts-rho040-r1-026.18d52f758bd532dd,reason=Completed count=1 msg=Job completed
0.3013,Event,ADDED,eval-conflicts-rho040-r1-027-98xwk.18d52f6aa1c883d3,"reason=FailedScheduling count=None msg=0/6 nodes are available: 6 node(s) had untolerated taint(s). no new claims to deallocate, preemption: 0/6 nodes are available: 6 Preemption is not helpful for scheduling."
0.3015,Event,ADDED,eval-conflicts-rho040-r1-027-98xwk.18d52f6daafdadd8,"reason=FailedScheduling count=None msg=0/6 nodes are available: 1 c_wall violated: 1 conflicting context pair(s) with node memory, 5 node(s) had untolerated taint(s). no new claims to deallocate, preemption: 0/6 nodes are available: 1 No preemption victims found for incoming pod, 5 Preemption is not helpful for scheduling."
0.3018,Event,ADDED,eval-conflicts-rho040-r1-027-98xwk.18d52f6dbe53835b,"reason=FailedScheduling count=None msg=0/6 nodes are available: 1 c_wall violated: 2 conflicting context pair(s) with node memory, 5 node(s) had untolerated taint(s). no new claims to deallocate, preemption: 0/6 nodes are available: 1 No preemption victims found for incoming pod, 5 Preemption is not helpful for scheduling."
0.3021,Event,ADDED,eval-conflicts-rho040-r1-027-98xwk.18d52f6dc8f768f3,"reason=FailedScheduling count=None msg=0/6 nodes are available: 1 c_wall violated: 2 conflicting context pair(s) with node memory, 5 node(s) had untolerated taint(s). no new claims to deallocate, preemption: 0/6 nodes are available: 1 No preemption victims found for incoming pod, 5 Preemption is not helpful for scheduling."
0.3022,Event,ADDED,eval-conflicts-rho040-r1-027-98xwk.18d52f6e167ce736,reason=Scheduled count=None msg=Successfully assigned compute/eval-conflicts-rho040-r1-027-98xwk to kind-worker
0.3025,Event,ADDED,eval-conflicts-rho040-r1-027-98xwk.18d52f6e3572a532,"reason=Pulled count=1 msg=Container image ""busybox:musl"" already present on machine"
0.3027,Event,ADDED,eval-conflicts-rho040-r1-027-98xwk.18d52f6e371b243d,reason=Created count=1 msg=Created container: task
0.3029,Event,ADDED,eval-conflicts-rho040-r1-027-98xwk.18d52f6e3974c799,reason=Started count=1 msg=Started container task
0.3032,Event,ADDED,eval-conflicts-rho040-r1-027.18d52f6aa1bd470a,reason=SuccessfulCreate count=1 msg=Created pod: eval-conflicts-rho040-r1-027-98xwk
0.3034,Event,ADDED,eval-conflicts-rho040-r1-027.18d52f74468f777d,reason=Completed count=1 msg=Job completed
0.3036,Event,ADDED,eval-conflicts-rho040-r1-028-t7jc7.18d52f6adfebe1ce,"reason=FailedScheduling count=None msg=0/6 nodes are available: 6 node(s) had untolerated taint(s). no new claims to deallocate, preemption: 0/6 nodes are available: 6 Preemption is not helpful for scheduling."
0.3037,Event,ADDED,eval-conflicts-rho040-r1-028-t7jc7.18d52f6dafd4d735,"reason=FailedScheduling count=None msg=0/6 nodes are available: 1 c_wall violated: 1 conflicting context pair(s) with node memory, 5 node(s) had untolerated taint(s). no new claims to deallocate, preemption: 0/6 nodes are available: 1 No preemption victims found for incoming pod, 5 Preemption is not helpful for scheduling."
0.304,Event,ADDED,eval-conflicts-rho040-r1-028-t7jc7.18d52f6dbedf3814,"reason=FailedScheduling count=None msg=0/6 nodes are available: 1 c_wall violated: 2 conflicting context pair(s) with node memory, 5 node(s) had untolerated taint(s). no new claims to deallocate, preemption: 0/6 nodes are available: 1 No preemption victims found for incoming pod, 5 Preemption is not helpful for scheduling."
0.3042,Event,ADDED,eval-conflicts-rho040-r1-028-t7jc7.18d52f6dc9182cf9,"reason=FailedScheduling count=None msg=0/6 nodes are available: 1 c_wall violated: 2 conflicting context pair(s) with node memory, 5 node(s) had untolerated taint(s). no new claims to deallocate, preemption: 0/6 nodes are available: 1 No preemption victims found for incoming pod, 5 Preemption is not helpful for scheduling."
0.3044,Event,ADDED,eval-conflicts-rho040-r1-028-t7jc7.18d52f6e16d3af02,reason=Scheduled count=None msg=Successfully assigned compute/eval-conflicts-rho040-r1-028-t7jc7 to kind-worker
0.3046,Event,ADDED,eval-conflicts-rho040-r1-028-t7jc7.18d52f6e35944f28,"reason=Pulled count=1 msg=Container image ""busybox:musl"" already present on machine"
0.3048,Event,ADDED,eval-conflicts-rho040-r1-028-t7jc7.18d52f6e37aaa1f6,reason=Created count=1 msg=Created container: task
0.305,Event,ADDED,eval-conflicts-rho040-r1-028-t7jc7.18d52f6e39d04540,reason=Started count=1 msg=Started container task
0.3051,Event,ADDED,eval-conflicts-rho040-r1-028.18d52f6adfdea0ee,reason=SuccessfulCreate count=1 msg=Created pod: eval-conflicts-rho040-r1-028-t7jc7
0.3053,Event,ADDED,eval-conflicts-rho040-r1-028.18d52f7446657303,reason=Completed count=1 msg=Job completed
0.3055,Event,ADDED,eval-conflicts-rho040-r1-029-x5fcl.18d52f6b1453eec0,"reason=FailedScheduling count=None msg=0/6 nodes are available: 6 node(s) had untolerated taint(s). no new claims to deallocate, preemption: 0/6 nodes are available: 6 Preemption is not helpful for scheduling."
0.3056,Event,ADDED,eval-conflicts-rho040-r1-029-x5fcl.18d52f6db0b1b740,reason=Scheduled count=None msg=Successfully assigned compute/eval-conflicts-rho040-r1-029-x5fcl to kind-worker4
0.3058,Event,ADDED,eval-conflicts-rho040-r1-029-x5fcl.18d52f6dccd59864,"reason=Pulled count=1 msg=Container image ""busybox:musl"" already present on machine"
0.3061,Event,ADDED,eval-conflicts-rho040-r1-029-x5fcl.18d52f6dceb3b32c,reason=Created count=1 msg=Created container: task
0.3062,Event,ADDED,eval-conflicts-rho040-r1-029-x5fcl.18d52f6dd3563954,reason=Started count=1 msg=Started container task
0.3064,Event,ADDED,eval-conflicts-rho040-r1-029.18d52f6b1449dc08,reason=SuccessfulCreate count=1 msg=Created pod: eval-conflicts-rho040-r1-029-x5fcl
0.3066,Event,ADDED,eval-conflicts-rho040-r1-029.18d52f734c349349,reason=Completed count=1 msg=Job completed
0.3067,Event,ADDED,eval-conflicts-rho040-r1-030-gp7v8.18d52f6b517706c1,"reason=FailedScheduling count=None msg=0/6 nodes are available: 6 node(s) had untolerated taint(s). no new claims to deallocate, preemption: 0/6 nodes are available: 6 Preemption is not helpful for scheduling."
0.3069,Event,ADDED,eval-conflicts-rho040-r1-030-gp7v8.18d52f6db092ac0b,"reason=FailedScheduling count=None msg=0/6 nodes are available: 1 c_wall violated: 1 conflicting context pair(s) with node memory, 5 node(s) had untolerated taint(s). no new claims to deallocate, preemption: 0/6 nodes are available: 1 No preemption victims found for incoming pod, 5 Preemption is not helpful for scheduling."
0.3071,Event,ADDED,eval-conflicts-rho040-r1-030-gp7v8.18d52f6dc0987f0d,"reason=FailedScheduling count=None msg=0/6 nodes are available: 1 c_wall violated: 1 conflicting context pair(s) with node memory, 5 node(s) had untolerated taint(s). no new claims to deallocate, preemption: 0/6 nodes are available: 1 No preemption victims found for incoming pod, 5 Preemption is not helpful for scheduling."
0.3073,Event,ADDED,eval-conflicts-rho040-r1-030-gp7v8.18d52f6e281fca7a,"reason=FailedScheduling count=None msg=0/6 nodes are available: 1 c_wall violated: 1 conflicting context pair(s) with node memory, 1 c_wall violated: 2 conflicting context pair(s) with node memory, 4 node(s) had untolerated taint(s). no new claims to deallocate, preemption: 0/6 nodes are available: 2 No preemption victims found for incoming pod, 4 Preemption is not helpful for scheduling."
0.3074,Event,ADDED,eval-conflicts-rho040-r1-030-gp7v8.18d52f6f29b7239a,reason=Scheduled count=None msg=Successfully assigned compute/eval-conflicts-rho040-r1-030-gp7v8 to kind-worker2
0.3076,Event,ADDED,eval-conflicts-rho040-r1-030-gp7v8.18d52f6f47414fee,"reason=Pulled count=1 msg=Container image ""busybox:musl"" already present on machine"
0.3077,Event,ADDED,eval-conflicts-rho040-r1-030-gp7v8.18d52f6f48b32ccd,reason=Created count=1 msg=Created container: task
0.3079,Event,ADDED,eval-conflicts-rho040-r1-030-gp7v8.18d52f6f4f552fc1,reason=Started count=1 msg=Started container task
0.3081,Event,ADDED,eval-conflicts-rho040-r1-030.18d52f6b516ce9fd,reason=SuccessfulCreate count=1 msg=Created pod: eval-conflicts-rho040-r1-030-gp7v8
0.3083,Event,ADDED,eval-conflicts-rho040-r1-030.18d52f757b856875,reason=Completed count=1 msg=Job completed
0.3084,Event,ADDED,eval-conflicts-rho040-r1-031-j6zlt.18d52f6b88c4138c,"reason=FailedScheduling count=None msg=0/6 nodes are available: 6 node(s) had untolerated taint(s). no new claims to deallocate, preemption: 0/6 nodes are available: 6 Preemption is not helpful for scheduling."
0.3086,Event,ADDED,eval-conflicts-rho040-r1-031-j6zlt.18d52f6db13c8c1a,"reason=FailedScheduling count=None msg=0/6 nodes are available: 1 c_wall violated: 1 conflicting context pair(s) with node memory, 5 node(s) had untolerated taint(s). no new claims to deallocate, preemption: 0/6 nodes are available: 1 No preemption victims found for incoming pod, 5 Preemption is not helpful for scheduling."
0.3087,Event,ADDED,eval-conflicts-rho040-r1-031-j6zlt.18d52f6dc0c54b09,"reason=FailedScheduling count=None msg=0/6 nodes are available: 1 c_wall violated: 2 conflicting context pair(s) with node memory, 5 node(s) had untolerated taint(s). no new claims to deallocate, preemption: 0/6 nodes are available: 1 No preemption victims found for incoming pod, 5 Preemption is not helpful for scheduling."
0.3089,Event,ADDED,eval-conflicts-rho040-r1-031-j6zlt.18d52f6dcc7387a9,"reason=FailedScheduling count=None msg=0/6 nodes are available: 1 c_wall violated: 2 conflicting context pair(s) with node memory, 5 node(s) had untolerated taint(s). no new claims to deallocate, preemption: 0/6 nodes are available: 1 No preemption victims found for incoming pod, 5 Preemption is not helpful for scheduling."
0.3091,Event,ADDED,eval-conflicts-rho040-r1-031-j6zlt.18d52f6e2bb81480,"reason=FailedScheduling count=None msg=0/6 nodes are available: 1 c_wall violated: 1 conflicting context pair(s) with node memory, 1 c_wall violated: 2 conflicting context pair(s) with node memory, 4 node(s) had untolerated taint(s). no new claims to deallocate, preemption: 0/6 nodes are available: 2 No preemption victims found for incoming pod, 4 Preemption is not helpful for scheduling."
0.3093,Event,ADDED,eval-conflicts-rho040-r1-031-j6zlt.18d52f6f37b92634,"reason=FailedScheduling count=None msg=0/6 nodes are available: 1 c_wall violated: 2 conflicting context pair(s) with node memory, 2 c_wall violated: 1 conflicting context pair(s) with node memory, 3 node(s) had untolerated taint(s). no new claims to deallocate, preemption: 0/6 nodes are available: 3 No preemption victims found for incoming pod, 3 Preemption is not helpful for scheduling."
0.3094,Event,ADDED,eval-conflicts-rho040-r1-031-j6zlt.18d52f6f44ab3f63,reason=Scheduled count=None msg=Successfully assigned compute/eval-conflicts-rho040-r1-031-j6zlt to kind-worker3
0.3096,Event,ADDED,eval-conflicts-rho040-r1-031-j6zlt.18d52f6f6087d5f1,"reason=Pulled count=1 msg=Container image ""busybox:musl"" already present on machine"
0.3098,Event,ADDED,eval-conflicts-rho040-r1-031-j6zlt.18d52f6f6221e0ec,reason=Created count=1 msg=Created container: task
0.31,Event,ADDED,eval-conflicts-rho040-r1-031-j6zlt.18d52f6f672d4958,reason=Started count=1 msg=Started container task
0.3101,Event,ADDED,eval-conflicts-rho040-r1-031.18d52f6b88b55421,reason=SuccessfulCreate count=1 msg=Created pod: eval-conflicts-rho040-r1-031-j6zlt
0.3103,Event,ADDED,eval-conflicts-rho040-r1-031.18d52f7598b4eaf4,reason=Completed count=1 msg=Job completed
0.3104,Event,ADDED,eval-conflicts-rho040-r1-032-pcpbf.18d52f6bc6251b5f,"reason=FailedScheduling count=None msg=0/6 nodes are available: 6 node(s) had untolerated taint(s). no new claims to deallocate, preemption: 0/6 nodes are available: 6 Preemption is not helpful for scheduling."
0.3106,Event,ADDED,eval-conflicts-rho040-r1-032-pcpbf.18d52f6db1aa6c21,"reason=FailedScheduling count=None msg=0/6 nodes are available: 1 c_wall violated: 1 conflicting context pair(s) with node memory, 5 node(s) had untolerated taint(s). no new claims to deallocate, preemption: 0/6 nodes are available: 1 No preemption victims found for incoming pod, 5 Preemption is not helpful for scheduling."
0.3107,Event,ADDED,eval-conflicts-rho040-r1-032-pcpbf.18d52f6dc26f0ebb,"reason=FailedScheduling count=None msg=0/6 nodes are available: 1 c_wall violated: 2 conflicting context pair(s) with node memory, 5 node(s) had untolerated taint(s). no new claims to deallocate, preemption: 0/6 nodes are available: 1 No preemption victims found for incoming pod, 5 Preemption is not helpful for scheduling."
0.3109,Event,ADDED,eval-conflicts-rho040-r1-032-pcpbf.18d52f6dce5629c0,"reason=FailedScheduling count=None msg=0/6 nodes are available: 1 c_wall violated: 2 conflicting context pair(s) with node memory, 5 node(s) had untolerated taint(s). no new claims to deallocate, preemption: 0/6 nodes are available: 1 No preemption victims found for incoming pod, 5 Preemption is not helpful for scheduling."
0.3111,Event,ADDED,eval-conflicts-rho040-r1-032-pcpbf.18d52f6e1c6d0033,reason=Scheduled count=None msg=Successfully assigned compute/eval-conflicts-rho040-r1-032-pcpbf to kind-worker
0.3112,Event,ADDED,eval-conflicts-rho040-r1-032-pcpbf.18d52f6e3747e5ca,"reason=Pulled count=1 msg=Container image ""busybox:musl"" already present on machine"
0.3115,Event,ADDED,eval-conflicts-rho040-r1-032-pcpbf.18d52f6e38bd48fb,reason=Created count=1 msg=Created container: task
0.3116,Event,ADDED,eval-conflicts-rho040-r1-032-pcpbf.18d52f6e3ae068f7,reason=Started count=1 msg=Started container task
0.3118,Event,ADDED,eval-conflicts-rho040-r1-032.18d52f6bc61a9e27,reason=SuccessfulCreate count=1 msg=Created pod: eval-conflicts-rho040-r1-032-pcpbf
0.312,Event,ADDED,eval-conflicts-rho040-r1-032.18d52f746d3dea68,reason=Completed count=1 msg=Job completed
0.3124,Event,ADDED,eval-conflicts-rho040-r1-033-mrbkb.18d52f6bffc0235d,"reason=FailedScheduling count=None msg=0/6 nodes are available: 6 node(s) had untolerated taint(s). no new claims to deallocate, preemption: 0/6 nodes are available: 6 Preemption is not helpful for scheduling."
0.3126,Event,ADDED,eval-conflicts-rho040-r1-033-mrbkb.18d52f6db576c91b,"reason=FailedScheduling count=None msg=0/6 nodes are available: 1 c_wall violated: 1 conflicting context pair(s) with node memory, 5 node(s) had untolerated taint(s). no new claims to deallocate, preemption: 0/6 nodes are available: 1 No preemption victims found for incoming pod, 5 Preemption is not helpful for scheduling."
0.3128,Event,ADDED,eval-conflicts-rho040-r1-033-mrbkb.18d52f6dc30c1c9c,"reason=FailedScheduling count=None msg=0/6 nodes are available: 1 c_wall violated: 1 conflicting context pair(s) with node memory, 5 node(s) had untolerated taint(s). no new claims to deallocate, preemption: 0/6 nodes are available: 1 No preemption victims found for incoming pod, 5 Preemption is not helpful for scheduling."
0.3131,Event,ADDED,eval-conflicts-rho040-r1-033-mrbkb.18d52f6e2e23999d,"reason=FailedScheduling count=None msg=0/6 nodes are available: 1 c_wall violated: 1 conflicting context pair(s) with node memory, 1 c_wall violated: 2 conflicting context pair(s) with node memory, 4 node(s) had untolerated taint(s). no new claims to deallocate, preemption: 0/6 nodes are available: 2 No preemption victims found for incoming pod, 4 Preemption is not helpful for scheduling."
0.3132,Event,ADDED,eval-conflicts-rho040-r1-033-mrbkb.18d52f6f1c8fcaa6,reason=Scheduled count=None msg=Successfully assigned compute/eval-conflicts-rho040-r1-033-mrbkb to kind-worker2
0.3134,Event,ADDED,eval-conflicts-rho040-r1-033-mrbkb.18d52f6f350bf7e3,"reason=Pulled count=1 msg=Container image ""busybox:musl"" already present on machine"
0.3137,Event,ADDED,eval-conflicts-rho040-r1-033-mrbkb.18d52f6f369260c9,reason=Created count=1 msg=Created container: task
0.3139,Event,ADDED,eval-conflicts-rho040-r1-033-mrbkb.18d52f6f3a0b8cff,reason=Started count=1 msg=Started container task
0.3142,Event,ADDED,eval-conflicts-rho040-r1-033.18d52f6bffb13aa8,reason=SuccessfulCreate count=1 msg=Created pod: eval-conflicts-rho040-r1-033-mrbkb
0.3144,Event,ADDED,eval-conflicts-rho040-r1-033.18d52f75665c6738,reason=Completed count=1 msg=Job completed
0.3146,Event,ADDED,eval-conflicts-rho040-r1-034-n22mj.18d52f6c3c7a4744,"reason=FailedScheduling count=None msg=0/6 nodes are available: 6 node(s) had untolerated taint(s). no new claims to deallocate, preemption: 0/6 nodes are available: 6 Preemption is not helpful for scheduling."
0.3147,Event,ADDED,eval-conflicts-rho040-r1-034-n22mj.18d52f6db5f98502,"reason=FailedScheduling count=None msg=0/6 nodes are available: 1 c_wall violated: 1 conflicting context pair(s) with node memory, 5 node(s) had untolerated taint(s). no new claims to deallocate, preemption: 0/6 nodes are available: 1 No preemption victims found for incoming pod, 5 Preemption is not helpful for scheduling."
0.3149,Event,ADDED,eval-conflicts-rho040-r1-034-n22mj.18d52f6dc3392179,"reason=FailedScheduling count=None msg=0/6 nodes are available: 1 c_wall violated: 2 conflicting context pair(s) with node memory, 5 node(s) had untolerated taint(s). no new claims to deallocate, preemption: 0/6 nodes are available: 1 No preemption victims found for incoming pod, 5 Preemption is not helpful for scheduling."
0.3152,Event,ADDED,eval-conflicts-rho040-r1-034-n22mj.18d52f6dceae4425,"reason=FailedScheduling count=None msg=0/6 nodes are available: 1 c_wall violated: 2 conflicting context pair(s) with node memory, 5 node(s) had untolerated taint(s). no new claims to deallocate, preemption: 0/6 nodes are available: 1 No preemption victims found for incoming pod, 5 Preemption is not helpful for scheduling."
0.3154,Event,ADDED,eval-conflicts-rho040-r1-034-n22mj.18d52f6e047d273d,reason=Scheduled count=None msg=Successfully assigned compute/eval-conflicts-rho040-r1-034-n22mj to kind-worker
0.3156,Event,ADDED,eval-conflicts-rho040-r1-034-n22mj.18d52f6e1de305e3,"reason=Pulled count=1 msg=Container image ""busybox:musl"" already present on machine"
0.3159,Event,ADDED,eval-conflicts-rho040-r1-034-n22mj.18d52f6e1f6e2301,reason=Created count=1 msg=Created container: task
0.316,Event,ADDED,eval-conflicts-rho040-r1-034-n22mj.18d52f6e22387601,reason=Started count=1 msg=Started container task
0.3162,Event,ADDED,eval-conflicts-rho040-r1-034.18d52f6c3c73cfde,reason=SuccessfulCreate count=1 msg=Created pod: eval-conflicts-rho040-r1-034-n22mj
0.3164,Event,ADDED,eval-conflicts-rho040-r1-034.18d52f73fae8cbef,reason=Completed count=1 msg=Job completed
0.3165,Event,ADDED,eval-conflicts-rho040-r1-035-zhl9z.18d52f6c76fd2a38,"reason=FailedScheduling count=None msg=0/6 nodes are available: 6 node(s) had untolerated taint(s). no new claims to deallocate, preemption: 0/6 nodes are available: 6 Preemption is not helpful for scheduling."
0.3167,Event,ADDED,eval-conflicts-rho040-r1-035-zhl9z.18d52f6db6bba16e,reason=Scheduled count=None msg=Successfully assigned compute/eval-conflicts-rho040-r1-035-zhl9z to kind-worker4
0.3168,Event,ADDED,eval-conflicts-rho040-r1-035-zhl9z.18d52f6dd8efd1d0,"reason=Pulled count=1 msg=Container image ""busybox:musl"" already present on machine"
0.317,Event,ADDED,eval-conflicts-rho040-r1-035-zhl9z.18d52f6dda8fdad0,reason=Created count=1 msg=Created container: task
0.3172,Event,ADDED,eval-conflicts-rho040-r1-035-zhl9z.18d52f6de150db95,reason=Started count=1 msg=Started container task
0.3174,Event,ADDED,eval-conflicts-rho040-r1-035.18d52f6c76f1f572,reason=SuccessfulCreate count=1 msg=Created pod: eval-conflicts-rho040-r1-035-zhl9z
0.3176,Event,ADDED,eval-conflicts-rho040-r1-035.18d52f731060c83f,reason=Completed count=1 msg=Job completed
0.3178,Event,ADDED,eval-conflicts-rho040-r1-036-kkl9q.18d52f6cb500cb2d,"reason=FailedScheduling count=None msg=0/6 nodes are available: 6 node(s) had untolerated taint(s). no new claims to deallocate, preemption: 0/6 nodes are available: 6 Preemption is not helpful for scheduling."
0.318,Event,ADDED,eval-conflicts-rho040-r1-036-kkl9q.18d52f6db68f4d4d,"reason=FailedScheduling count=None msg=0/6 nodes are available: 1 c_wall violated: 1 conflicting context pair(s) with node memory, 5 node(s) had untolerated taint(s). no new claims to deallocate, preemption: 0/6 nodes are available: 1 No preemption victims found for incoming pod, 5 Preemption is not helpful for scheduling."
0.3182,Event,ADDED,eval-conflicts-rho040-r1-036-kkl9q.18d52f6dc3dfd66c,"reason=FailedScheduling count=None msg=0/6 nodes are available: 1 c_wall violated: 1 conflicting context pair(s) with node memory, 5 node(s) had untolerated taint(s). no new claims to deallocate, preemption: 0/6 nodes are available: 1 No preemption victims found for incoming pod, 5 Preemption is not helpful for scheduling."
0.3184,Event,ADDED,eval-conflicts-rho040-r1-036-kkl9q.18d52f6e25c1859f,"reason=FailedScheduling count=None msg=0/6 nodes are available: 1 c_wall violated: 1 conflicting context pair(s) with node memory, 1 c_wall violated: 2 conflicting context pair(s) with node memory, 4 node(s) had untolerated taint(s). no new claims to deallocate, preemption: 0/6 nodes are available: 2 No preemption victims found for incoming pod, 4 Preemption is not helpful for scheduling."
0.3186,Event,ADDED,eval-conflicts-rho040-r1-036-kkl9q.18d52f6e31a1e629,"reason=FailedScheduling count=None msg=0/6 nodes are available: 1 c_wall violated: 1 conflicting context pair(s) with node memory, 1 c_wall violated: 2 conflicting context pair(s) with node memory, 4 node(s) had untolerated taint(s). no new claims to deallocate, preemption: 0/6 nodes are available: 2 No preemption victims found for incoming pod, 4 Preemption is not helpful for scheduling."
0.3187,Event,ADDED,eval-conflicts-rho040-r1-036-kkl9q.18d52f6f2106f5e1,reason=Scheduled count=None msg=Successfully assigned compute/eval-conflicts-rho040-r1-036-kkl9q to kind-worker2
0.3189,Event,ADDED,eval-conflicts-rho040-r1-036-kkl9q.18d52f6f3a0f03fb,"reason=Pulled count=1 msg=Container image ""busybox:musl"" already present on machine"
0.3191,Event,ADDED,eval-conflicts-rho040-r1-036-kkl9q.18d52f6f3bdf6a8e,reason=Created count=1 msg=Created container: task
0.3193,Event,ADDED,eval-conflicts-rho040-r1-036-kkl9q.18d52f6f4113e9d1,reason=Started count=1 msg=Started container task
0.3194,Event,ADDED,eval-conflicts-rho040-r1-036.18d52f6cb4f5811d,reason=SuccessfulCreate count=1 msg=Created pod: eval-conflicts-rho040-r1-036-kkl9q
0.3196,Event,ADDED,eval-conflicts-rho040-r1-036.18d52f757cfb543a,reason=Completed count=1 msg=Job completed
0.3197,Event,ADDED,eval-conflicts-rho040-r1-037-x7vst.18d52f6cf03cb153,"reason=FailedScheduling count=None msg=0/6 nodes are available: 6 node(s) had untolerated taint(s). no new claims to deallocate, preemption: 0/6 nodes are available: 6 Preemption is not helpful for scheduling."
0.3199,Event,ADDED,eval-conflicts-rho040-r1-037-x7vst.18d52f6db77b33dd,reason=Scheduled count=None msg=Successfully assigned compute/eval-conflicts-rho040-r1-037-x7vst to kind-worker4
0.3201,Event,ADDED,eval-conflicts-rho040-r1-037-x7vst.18d52f6dd921f2dc,"reason=Pulled count=1 msg=Container image ""busybox:musl"" already present on machine"
0.3202,Event,ADDED,eval-conflicts-rho040-r1-037-x7vst.18d52f6ddadab07c,reason=Created count=1 msg=Created container: task
0.3204,Event,ADDED,eval-conflicts-rho040-r1-037-x7vst.18d52f6de1519516,reason=Started count=1 msg=Started container task
0.3206,Event,ADDED,eval-conflicts-rho040-r1-037.18d52f6cf0319bf0,reason=SuccessfulCreate count=1 msg=Created pod: eval-conflicts-rho040-r1-037-x7vst
0.3207,Event,ADDED,eval-conflicts-rho040-r1-037.18d52f734c3476e3,reason=Completed count=1 msg=Job completed
0.3209,Event,ADDED,eval-conflicts-rho040-r1-038-lvxxr.18d52f6d29dfc8ed,"reason=FailedScheduling count=None msg=0/6 nodes are available: 6 node(s) had untolerated taint(s). no new claims to deallocate, preemption: 0/6 nodes are available: 6 Preemption is not helpful for scheduling."
0.321,Event,ADDED,eval-conflicts-rho040-r1-038-lvxxr.18d52f6db740bd0a,"reason=FailedScheduling count=None msg=0/6 nodes are available: 1 c_wall violated: 2 conflicting context pair(s) with node memory, 5 node(s) had untolerated taint(s). no new claims to deallocate, preemption: 0/6 nodes are available: 1 No preemption victims found for incoming pod, 5 Preemption is not helpful for scheduling."
0.3213,Event,ADDED,eval-conflicts-rho040-r1-038-lvxxr.18d52f6dc6497c60,"reason=FailedScheduling count=None msg=0/6 nodes are available: 1 c_wall violated: 2 conflicting context pair(s) with node memory, 5 node(s) had untolerated taint(s). no new claims to deallocate, preemption: 0/6 nodes are available: 1 No preemption victims found for incoming pod, 5 Preemption is not helpful for scheduling."
0.3215,Event,ADDED,eval-conflicts-rho040-r1-038-lvxxr.18d52f6e08e1553a,reason=Scheduled count=None msg=Successfully assigned compute/eval-conflicts-rho040-r1-038-lvxxr to kind-worker
0.3216,Event,ADDED,eval-conflicts-rho040-r1-038-lvxxr.18d52f6e21e6d125,"reason=Pulled count=1 msg=Container image ""busybox:musl"" already present on machine"
0.3219,Event,ADDED,eval-conflicts-rho040-r1-038-lvxxr.18d52f6e2354ea89,reason=Created count=1 msg=Created container: task
0.3221,Event,ADDED,eval-conflicts-rho040-r1-038-lvxxr.18d52f6e276fd030,reason=Started count=1 msg=Started container task
0.3222,Event,ADDED,eval-conflicts-rho040-r1-038.18d52f6d29cef244,reason=SuccessfulCreate count=1 msg=Created pod: eval-conflicts-rho040-r1-038-lvxxr
0.3224,Event,ADDED,eval-conflicts-rho040-r1-038.18d52f73a82afe07,reason=Completed count=1 msg=Job completed
0.3225,Event,ADDED,eval-conflicts-rho040-r1-039-tpvmn.18d52f6d65f5fde6,"reason=FailedScheduling count=None msg=0/6 nodes are available: 6 node(s) had untolerated taint(s). no new claims to deallocate, preemption: 0/6 nodes are available: 6 Preemption is not helpful for scheduling."
0.3227,Event,ADDED,eval-conflicts-rho040-r1-039-tpvmn.18d52f6db7cf6b84,"reason=FailedScheduling count=None msg=0/6 nodes are available: 1 c_wall violated: 2 conflicting context pair(s) with node memory, 5 node(s) had untolerated taint(s). no new claims to deallocate, preemption: 0/6 nodes are available: 1 No preemption victims found for incoming pod, 5 Preemption is not helpful for scheduling."
0.3229,Event,ADDED,eval-conflicts-rho040-r1-039-tpvmn.18d52f6dc675df96,"reason=FailedScheduling count=None msg=0/6 nodes are available: 1 c_wall violated: 2 conflicting context pair(s) with node memory, 5 node(s) had untolerated taint(s). no new claims to deallocate, preemption: 0/6 nodes are available: 1 No preemption victims found for incoming pod, 5 Preemption is not helpful for scheduling."
0.3231,Event,ADDED,eval-conflicts-rho040-r1-039-tpvmn.18d52f6e0a6862da,reason=Scheduled count=None msg=Successfully assigned compute/eval-conflicts-rho040-r1-039-tpvmn to kind-worker
0.3263,Event,ADDED,eval-conflicts-rho040-r1-039-tpvmn.18d52f6e22f0d3ef,"reason=Pulled count=1 msg=Container image ""busybox:musl"" already present on machine"
0.3265,Event,ADDED,eval-conflicts-rho040-r1-039-tpvmn.18d52f6e25110f19,reason=Created count=1 msg=Created container: task
0.3266,Event,ADDED,eval-conflicts-rho040-r1-039-tpvmn.18d52f6e27f9b5e2,reason=Started count=1 msg=Started container task
0.3268,Event,ADDED,eval-conflicts-rho040-r1-039.18d52f6d65ea22cc,reason=SuccessfulCreate count=1 msg=Created pod: eval-conflicts-rho040-r1-039-tpvmn
0.327,Event,ADDED,eval-conflicts-rho040-r1-039.18d52f73a82d8e22,reason=Completed count=1 msg=Job completed
0.3272,Event,ADDED,eval-conflicts-rho040-r1-040-tgbjb.18d52f6da2d1e693,"reason=FailedScheduling count=None msg=0/6 nodes are available: 6 node(s) had untolerated taint(s). no new claims to deallocate, preemption: 0/6 nodes are available: 6 Preemption is not helpful for scheduling."
0.3273,Event,ADDED,eval-conflicts-rho040-r1-040-tgbjb.18d52f6dbcbf11a3,reason=Scheduled count=None msg=Successfully assigned compute/eval-conflicts-rho040-r1-040-tgbjb to kind-worker4
0.3275,Event,ADDED,eval-conflicts-rho040-r1-040-tgbjb.18d52f6ddadc1dc8,"reason=Pulled count=1 msg=Container image ""busybox:musl"" already present on machine"
0.3277,Event,ADDED,eval-conflicts-rho040-r1-040-tgbjb.18d52f6ddc0d32f5,reason=Created count=1 msg=Created container: task
0.3278,Event,ADDED,eval-conflicts-rho040-r1-040-tgbjb.18d52f6de150ea05,reason=Started count=1 msg=Started container task
0.328,Event,ADDED,eval-conflicts-rho040-r1-040.18d52f6da2c2830f,reason=SuccessfulCreate count=1 msg=Created pod: eval-conflicts-rho040-r1-040-tgbjb
0.3282,Event,ADDED,eval-conflicts-rho040-r1-040.18d52f734c3165fc,reason=Completed count=1 msg=Job completed
0.3283,Event,ADDED,eval-conflicts-rho040-r1-041-r8vmp.18d52f6ddc9f0f61,"reason=FailedScheduling count=None msg=0/6 nodes are available: 1 c_wall violated: 1 conflicting context pair(s) with node memory, 5 node(s) had untolerated taint(s). no new claims to deallocate, preemption: 0/6 nodes are available: 1 No preemption victims found for incoming pod, 5 Preemption is not helpful for scheduling."
0.3286,Event,ADDED,eval-conflicts-rho040-r1-041-r8vmp.18d52f6ddd1b58df,"reason=FailedScheduling count=None msg=0/6 nodes are available: 1 c_wall violated: 1 conflicting context pair(s) with node memory, 5 node(s) had untolerated taint(s). no new claims to deallocate, preemption: 0/6 nodes are available: 1 No preemption victims found for incoming pod, 5 Preemption is not helpful for scheduling."
0.3287,Event,ADDED,eval-conflicts-rho040-r1-041-r8vmp.18d52f6e2dcd73e7,"reason=FailedScheduling count=None msg=0/6 nodes are available: 1 c_wall violated: 1 conflicting context pair(s) with node memory, 1 c_wall violated: 2 conflicting context pair(s) with node memory, 4 node(s) had untolerated taint(s). no new claims to deallocate, preemption: 0/6 nodes are available: 2 No preemption victims found for incoming pod, 4 Preemption is not helpful for scheduling."
0.3289,Event,ADDED,eval-conflicts-rho040-r1-041-r8vmp.18d52f6f32175a96,reason=Scheduled count=None msg=Successfully assigned compute/eval-conflicts-rho040-r1-041-r8vmp to kind-worker2
0.3291,Event,ADDED,eval-conflicts-rho040-r1-041-r8vmp.18d52f6f4f63dbcb,"reason=Pulled count=1 msg=Container image ""busybox:musl"" already present on machine"
0.3292,Event,ADDED,eval-conflicts-rho040-r1-041-r8vmp.18d52f6f5093f601,reason=Created count=1 msg=Created container: task
0.3294,Event,ADDED,eval-conflicts-rho040-r1-041-r8vmp.18d52f6f553d046d,reason=Started count=1 msg=Started container task
0.3296,Event,ADDED,eval-conflicts-rho040-r1-041.18d52f6ddc611d46,reason=SuccessfulCreate count=1 msg=Created pod: eval-conflicts-rho040-r1-041-r8vmp
0.3297,Event,ADDED,eval-conflicts-rho040-r1-041.18d52f75682031d6,reason=Completed count=1 msg=Job completed
0.33,Event,ADDED,eval-conflicts-rho040-r1-042-8n7dq.18d52f6e2013b417,reason=Scheduled count=None msg=Successfully assigned compute/eval-conflicts-rho040-r1-042-8n7dq to kind-worker4
0.3302,Event,ADDED,eval-conflicts-rho040-r1-042-8n7dq.18d52f6e38029f3b,"reason=Pulled count=1 msg=Container image ""busybox:musl"" already present on machine"
0.3304,Event,ADDED,eval-conflicts-rho040-r1-042-8n7dq.18d52f6e395aa0d1,reason=Created count=1 msg=Created container: task
0.3306,Event,ADDED,eval-conflicts-rho040-r1-042-8n7dq.18d52f6e3b4eb1b4,reason=Started count=1 msg=Started container task
0.3308,Event,ADDED,eval-conflicts-rho040-r1-042.18d52f6e1be0e584,reason=SuccessfulCreate count=1 msg=Created pod: eval-conflicts-rho040-r1-042-8n7dq
0.3309,Event,ADDED,eval-conflicts-rho040-r1-042.18d52f743228318b,reason=Completed count=1 msg=Job completed
0.3311,Event,ADDED,eval-conflicts-rho040-r1-043-bqmj8.18d52f6e581f4b51,reason=Scheduled count=None msg=Successfully assigned compute/eval-conflicts-rho040-r1-043-bqmj8 to kind-worker
0.3313,Event,ADDED,eval-conflicts-rho040-r1-043-bqmj8.18d52f6e70f3afb2,"reason=Pulled count=1 msg=Container image ""busybox:musl"" already present on machine"
0.3314,Event,ADDED,eval-conflicts-rho040-r1-043-bqmj8.18d52f6e72321531,reason=Created count=1 msg=Created container: task
0.3316,Event,ADDED,eval-conflicts-rho040-r1-043-bqmj8.18d52f6e76e601a4,reason=Started count=1 msg=Started container task
0.3318,Event,ADDED,eval-conflicts-rho040-r1-043.18d52f6e53ab30f5,reason=SuccessfulCreate count=1 msg=Created pod: eval-conflicts-rho040-r1-043-bqmj8
0.3319,Event,ADDED,eval-conflicts-rho040-r1-043.18d52f745300ba73,reason=Completed count=1 msg=Job completed
0.3321,Event,ADDED,eval-conflicts-rho040-r1-044-kn7zn.18d52f6e92a2c950,reason=Scheduled count=None msg=Successfully assigned compute/eval-conflicts-rho040-r1-044-kn7zn to kind-worker4
0.3323,Event,ADDED,eval-conflicts-rho040-r1-044-kn7zn.18d52f6eb0288038,"reason=Pulled count=1 msg=Container image ""busybox:musl"" already present on machine"
0.3324,Event,ADDED,eval-conflicts-rho040-r1-044-kn7zn.18d52f6eb16b8f4c,reason=Created count=1 msg=Created container: task
0.3326,Event,ADDED,eval-conflicts-rho040-r1-044-kn7zn.18d52f6eb81612c8,reason=Started count=1 msg=Started container task
0.3328,Event,ADDED,eval-conflicts-rho040-r1-044.18d52f6e91ab514b,reason=SuccessfulCreate count=1 msg=Created pod: eval-conflicts-rho040-r1-044-kn7zn
0.3329,Event,ADDED,eval-conflicts-rho040-r1-044.18d52f748736c519,reason=Completed count=1 msg=Job completed
0.3331,Event,ADDED,eval-conflicts-rho040-r1-045-glt5n.18d52f6ecbc86fe8,reason=Scheduled count=None msg=Successfully assigned compute/eval-conflicts-rho040-r1-045-glt5n to kind-worker4
0.3333,Event,ADDED,eval-conflicts-rho040-r1-045-glt5n.18d52f6ee5121286,"reason=Pulled count=1 msg=Container image ""busybox:musl"" already present on machine"
0.3334,Event,ADDED,eval-conflicts-rho040-r1-045-glt5n.18d52f6ee62c1197,reason=Created count=1 msg=Created container: task
0.3336,Event,ADDED,eval-conflicts-rho040-r1-045-glt5n.18d52f6ee8d3499a,reason=Started count=1 msg=Started container task
0.3338,Event,ADDED,eval-conflicts-rho040-r1-045.18d52f6ecb1ae48c,reason=SuccessfulCreate count=1 msg=Created pod: eval-conflicts-rho040-r1-045-glt5n
0.334,Event,ADDED,eval-conflicts-rho040-r1-045.18d52f74fd544b88,reason=Completed count=1 msg=Job completed
0.3343,Event,ADDED,eval-conflicts-rho040-r1-046-8gk9c.18d52f6f07db782d,reason=Scheduled count=None msg=Successfully assigned compute/eval-conflicts-rho040-r1-046-8gk9c to kind-worker
0.3345,Event,ADDED,eval-conflicts-rho040-r1-046-8gk9c.18d52f6f21a2962b,"reason=Pulled count=1 msg=Container image ""busybox:musl"" already present on machine"
0.3347,Event,ADDED,eval-conflicts-rho040-r1-046-8gk9c.18d52f6f2301ff93,reason=Created count=1 msg=Created container: task
0.3349,Event,ADDED,eval-conflicts-rho040-r1-046-8gk9c.18d52f6f2670bc64,reason=Started count=1 msg=Started container task
0.3352,Event,ADDED,eval-conflicts-rho040-r1-046.18d52f6f0727e903,reason=SuccessfulCreate count=1 msg=Created pod: eval-conflicts-rho040-r1-046-8gk9c
0.3354,Event,ADDED,eval-conflicts-rho040-r1-046.18d52f75475af732,reason=Completed count=1 msg=Job completed
0.3357,Event,ADDED,eval-conflicts-rho040-r1-047-jr78x.18d52f6f4a341bf3,reason=Scheduled count=None msg=Successfully assigned compute/eval-conflicts-rho040-r1-047-jr78x to kind-worker2
0.3358,Event,ADDED,eval-conflicts-rho040-r1-047-jr78x.18d52f6f67347810,"reason=Pulled count=1 msg=Container image ""busybox:musl"" already present on machine"
0.3361,Event,ADDED,eval-conflicts-rho040-r1-047-jr78x.18d52f6f68787b9d,reason=Created count=1 msg=Created container: task
0.3363,Event,ADDED,eval-conflicts-rho040-r1-047-jr78x.18d52f6f6d136280,reason=Started count=1 msg=Started container task
0.3365,Event,ADDED,eval-conflicts-rho040-r1-047.18d52f6f42a62b54,reason=SuccessfulCreate count=1 msg=Created pod: eval-conflicts-rho040-r1-047-jr78x
0.3367,Event,ADDED,eval-conflicts-rho040-r1-047.18d52f75a88faab4,reason=Completed count=1 msg=Job completed
0.3369,Event,ADDED,eval-conflicts-rho040-r1-048-blvjn.18d52f6f7f49eaeb,reason=Scheduled count=None msg=Successfully assigned compute/eval-conflicts-rho040-r1-048-blvjn to kind-worker3
0.337,Event,ADDED,eval-conflicts-rho040-r1-048-blvjn.18d52f6f9b559bc0,"reason=Pulled count=1 msg=Container image ""busybox:musl"" already present on machine"
0.3372,Event,ADDED,eval-conflicts-rho040-r1-048-blvjn.18d52f6f9c95a168,reason=Created count=1 msg=Created container: task
0.3375,Event,ADDED,eval-conflicts-rho040-r1-048-blvjn.18d52f6fa0e39b63,reason=Started count=1 msg=Started container task
0.3377,Event,ADDED,eval-conflicts-rho040-r1-048.18d52f6f7da03520,reason=SuccessfulCreate count=1 msg=Created pod: eval-conflicts-rho040-r1-048-blvjn
0.3379,Event,ADDED,eval-conflicts-rho040-r1-048.18d52f7573982022,reason=Completed count=1 msg=Job completed
0.338,Event,ADDED,eval-conflicts-rho040-r1-049-l2c85.18d52f6fbc8509bf,reason=Scheduled count=None msg=Successfully assigned compute/eval-conflicts-rho040-r1-049-l2c85 to kind-worker3
0.3383,Event,ADDED,eval-conflicts-rho040-r1-049-l2c85.18d52f6fd6c4cde0,"reason=Pulled count=1 msg=Container image ""busybox:musl"" already present on machine"
0.3385,Event,ADDED,eval-conflicts-rho040-r1-049-l2c85.18d52f6fd7f453c6,reason=Created count=1 msg=Created container: task
0.3387,Event,ADDED,eval-conflicts-rho040-r1-049-l2c85.18d52f6fe0f62588,reason=Started count=1 msg=Started container task
0.339,Event,ADDED,eval-conflicts-rho040-r1-049.18d52f6fbb1a556c,reason=SuccessfulCreate count=1 msg=Created pod: eval-conflicts-rho040-r1-049-l2c85
0.3391,Event,ADDED,eval-conflicts-rho040-r1-049.18d52f7586bb10f1,reason=Completed count=1 msg=Job completed
0.3393,Event,ADDED,eval-conflicts-rho040-r1-050-cfh87.18d52f6ff6517e44,reason=Scheduled count=None msg=Successfully assigned compute/eval-conflicts-rho040-r1-050-cfh87 to kind-worker
0.3395,Event,ADDED,eval-conflicts-rho040-r1-050-cfh87.18d52f7010405420,"reason=Pulled count=1 msg=Container image ""busybox:musl"" already present on machine"
0.3398,Event,ADDED,eval-conflicts-rho040-r1-050-cfh87.18d52f70114f8e3e,reason=Created count=1 msg=Created container: task
0.34,Event,ADDED,eval-conflicts-rho040-r1-050-cfh87.18d52f70179f0d02,reason=Started count=1 msg=Started container task
0.3401,Event,ADDED,eval-conflicts-rho040-r1-050.18d52f6ff524e67c,reason=SuccessfulCreate count=1 msg=Created pod: eval-conflicts-rho040-r1-050-cfh87
0.3404,Event,ADDED,eval-conflicts-rho040-r1-050.18d52f75a8ae40ac,reason=Completed count=1 msg=Job completed
0.3406,Event,ADDED,eval-conflicts-rho040-r1-051-sxtwf.18d52f7031880e8c,reason=Scheduled count=None msg=Successfully assigned compute/eval-conflicts-rho040-r1-051-sxtwf to kind-worker2
0.3408,Event,ADDED,eval-conflicts-rho040-r1-051-sxtwf.18d52f704e830aea,"reason=Pulled count=1 msg=Container image ""busybox:musl"" already present on machine"
0.3411,Event,ADDED,eval-conflicts-rho040-r1-051-sxtwf.18d52f704f97f0cf,reason=Created count=1 msg=Created container: task
0.3414,Event,ADDED,eval-conflicts-rho040-r1-051-sxtwf.18d52f7053192909,reason=Started count=1 msg=Started container task
0.3416,Event,ADDED,eval-conflicts-rho040-r1-051.18d52f70305c7597,reason=SuccessfulCreate count=1 msg=Created pod: eval-conflicts-rho040-r1-051-sxtwf
0.3418,Event,ADDED,eval-conflicts-rho040-r1-051.18d52f76050432e0,reason=Completed count=1 msg=Job completed
0.3419,Event,ADDED,eval-conflicts-rho040-r1-052-w2vm4.18d52f706d87c384,reason=Scheduled count=None msg=Successfully assigned compute/eval-conflicts-rho040-r1-052-w2vm4 to kind-worker2
0.3422,Event,ADDED,eval-conflicts-rho040-r1-052-w2vm4.18d52f7086e5caf0,"reason=Pulled count=1 msg=Container image ""busybox:musl"" already present on machine"
0.3424,Event,ADDED,eval-conflicts-rho040-r1-052-w2vm4.18d52f7087ffdd09,reason=Created count=1 msg=Created container: task
0.3426,Event,ADDED,eval-conflicts-rho040-r1-052-w2vm4.18d52f708e04bd51,reason=Started count=1 msg=Started container task
0.3428,Event,ADDED,eval-conflicts-rho040-r1-052.18d52f706c11c115,reason=SuccessfulCreate count=1 msg=Created pod: eval-conflicts-rho040-r1-052-w2vm4
0.343,Event,ADDED,eval-conflicts-rho040-r1-052.18d52f76056dd86f,reason=Completed count=1 msg=Job completed
0.3431,Event,ADDED,eval-conflicts-rho040-r1-053-z986k.18d52f70ab480874,reason=Scheduled count=None msg=Successfully assigned compute/eval-conflicts-rho040-r1-053-z986k to kind-worker3
0.3433,Event,ADDED,eval-conflicts-rho040-r1-053-z986k.18d52f70caad627d,"reason=Pulled count=1 msg=Container image ""busybox:musl"" already present on machine"
0.3436,Event,ADDED,eval-conflicts-rho040-r1-053-z986k.18d52f70cbefb92f,reason=Created count=1 msg=Created container: task
0.3438,Event,ADDED,eval-conflicts-rho040-r1-053-z986k.18d52f70d1c0d782,reason=Started count=1 msg=Started container task
0.344,Event,ADDED,eval-conflicts-rho040-r1-053.18d52f70a9ce9fa0,reason=SuccessfulCreate count=1 msg=Created pod: eval-conflicts-rho040-r1-053-z986k
0.3441,Event,ADDED,eval-conflicts-rho040-r1-053.18d52f760a23ff25,reason=Completed count=1 msg=Job completed
0.3444,Event,ADDED,eval-conflicts-rho040-r1-054-7qpmg.18d52f70eed6fda8,reason=Scheduled count=None msg=Successfully assigned compute/eval-conflicts-rho040-r1-054-7qpmg to kind-worker3
0.3446,Event,ADDED,eval-conflicts-rho040-r1-054-7qpmg.18d52f710c364830,"reason=Pulled count=1 msg=Container image ""busybox:musl"" already present on machine"
0.3448,Event,ADDED,eval-conflicts-rho040-r1-054-7qpmg.18d52f710d681fc5,reason=Created count=1 msg=Created container: task
0.3451,Event,ADDED,eval-conflicts-rho040-r1-054-7qpmg.18d52f71172716f9,reason=Started count=1 msg=Started container task
0.3453,Event,ADDED,eval-conflicts-rho040-r1-054.18d52f70e7c12d20,reason=SuccessfulCreate count=1 msg=Created pod: eval-conflicts-rho040-r1-054-7qpmg
0.3455,Event,ADDED,eval-conflicts-rho040-r1-054.18d52f7687c4bde5,reason=Completed count=1 msg=Job completed
0.3457,Event,ADDED,eval-conflicts-rho040-r1-055-ng6st.18d52f712309ed58,reason=Scheduled count=None msg=Successfully assigned compute/eval-conflicts-rho040-r1-055-ng6st to kind-worker2
0.346,Event,ADDED,eval-conflicts-rho040-r1-055-ng6st.18d52f713efaddea,"reason=Pulled count=1 msg=Container image ""busybox:musl"" already present on machine"
0.3462,Event,ADDED,eval-conflicts-rho040-r1-055-ng6st.18d52f71401a895e,reason=Created count=1 msg=Created container: task
0.3463,Event,ADDED,eval-conflicts-rho040-r1-055-ng6st.18d52f7145f45017,reason=Started count=1 msg=Started container task
0.3466,Event,ADDED,eval-conflicts-rho040-r1-055.18d52f7121a7f950,reason=SuccessfulCreate count=1 msg=Created pod: eval-conflicts-rho040-r1-055-ng6st
0.3468,Event,ADDED,eval-conflicts-rho040-r1-055.18d52f76e584522e,reason=Completed count=1 msg=Job completed
0.3469,Event,ADDED,eval-conflicts-rho040-r1-056-8mpx5.18d52f715c03f161,reason=Scheduled count=None msg=Successfully assigned compute/eval-conflicts-rho040-r1-056-8mpx5 to kind-worker3
0.3471,Event,ADDED,eval-conflicts-rho040-r1-056-8mpx5.18d52f7179f45857,"reason=Pulled count=1 msg=Container image ""busybox:musl"" already present on machine"
0.3473,Event,ADDED,eval-conflicts-rho040-r1-056-8mpx5.18d52f717b0ff539,reason=Created count=1 msg=Created container: task
0.3474,Event,ADDED,eval-conflicts-rho040-r1-056-8mpx5.18d52f717ee5f843,reason=Started count=1 msg=Started container task
0.3477,Event,ADDED,eval-conflicts-rho040-r1-056.18d52f715aa7512b,reason=SuccessfulCreate count=1 msg=Created pod: eval-conflicts-rho040-r1-056-8mpx5
0.3479,Event,ADDED,eval-conflicts-rho040-r1-056.18d52f76bb8760a4,reason=Completed count=1 msg=Job completed
0.3481,Event,ADDED,eval-conflicts-rho040-r1-057-p2vnf.18d52f71972e72cb,reason=Scheduled count=None msg=Successfully assigned compute/eval-conflicts-rho040-r1-057-p2vnf to kind-worker4
0.3483,Event,ADDED,eval-conflicts-rho040-r1-057-p2vnf.18d52f71b97644bf,"reason=Pulled count=1 msg=Container image ""busybox:musl"" already present on machine"
0.3486,Event,ADDED,eval-conflicts-rho040-r1-057-p2vnf.18d52f71bac39837,reason=Created count=1 msg=Created container: task
0.3488,Event,ADDED,eval-conflicts-rho040-r1-057-p2vnf.18d52f71c4f78ecf,reason=Started count=1 msg=Started container task
0.3489,Event,ADDED,eval-conflicts-rho040-r1-057.18d52f7195dad06b,reason=SuccessfulCreate count=1 msg=Created pod: eval-conflicts-rho040-r1-057-p2vnf
0.3491,Event,ADDED,eval-conflicts-rho040-r1-057.18d52f773ee72fb3,reason=Completed count=1 msg=Job completed
0.3492,Event,ADDED,eval-conflicts-rho040-r1-058-7nn2z.18d52f71d938f790,reason=Scheduled count=None msg=Successfully assigned compute/eval-conflicts-rho040-r1-058-7nn2z to kind-worker4
0.3494,Event,ADDED,eval-conflicts-rho040-r1-058-7nn2z.18d52f7201ac9897,"reason=Pulled count=1 msg=Container image ""busybox:musl"" already present on machine"
0.3496,Event,ADDED,eval-conflicts-rho040-r1-058-7nn2z.18d52f7202f358ac,reason=Created count=1 msg=Created container: task
0.3498,Event,ADDED,eval-conflicts-rho040-r1-058-7nn2z.18d52f720cccb111,reason=Started count=1 msg=Started container task
0.3499,Event,ADDED,eval-conflicts-rho040-r1-058.18d52f71d8026710,reason=SuccessfulCreate count=1 msg=Created pod: eval-conflicts-rho040-r1-058-7nn2z
0.3501,Event,ADDED,eval-conflicts-rho040-r1-058.18d52f777b69c8ba,reason=Completed count=1 msg=Job completed
0.3503,Event,ADDED,eval-conflicts-rho040-r1-059-q5txv.18d52f72102aa2bf,reason=Scheduled count=None msg=Successfully assigned compute/eval-conflicts-rho040-r1-059-q5txv to kind-worker2
0.3504,Event,ADDED,eval-conflicts-rho040-r1-059-q5txv.18d52f72312c0bb1,"reason=Pulled count=1 msg=Container image ""busybox:musl"" already present on machine"
0.3506,Event,ADDED,eval-conflicts-rho040-r1-059-q5txv.18d52f723251c2ba,reason=Created count=1 msg=Created container: task
0.3508,Event,ADDED,eval-conflicts-rho040-r1-059-q5txv.18d52f723adb58d6,reason=Started count=1 msg=Started container task
0.3509,Event,ADDED,eval-conflicts-rho040-r1-059.18d52f720eadaa4a,reason=SuccessfulCreate count=1 msg=Created pod: eval-conflicts-rho040-r1-059-q5txv
0.3511,Event,ADDED,eval-conflicts-rho040-r1-059.18d52f77c9b2ab73,reason=Completed count=1 msg=Job completed
0.3512,Event,ADDED,eval-conflicts-rho040-r1-060-rhz9h.18d52f724a0e0131,reason=Scheduled count=None msg=Successfully assigned compute/eval-conflicts-rho040-r1-060-rhz9h to kind-worker
0.3514,Event,ADDED,eval-conflicts-rho040-r1-060-rhz9h.18d52f726a19d5a2,"reason=Pulled count=1 msg=Container image ""busybox:musl"" already present on machine"
0.3516,Event,ADDED,eval-conflicts-rho040-r1-060-rhz9h.18d52f726b46de86,reason=Created count=1 msg=Created container: task
0.3518,Event,ADDED,eval-conflicts-rho040-r1-060-rhz9h.18d52f7271e4ceb4,reason=Started count=1 msg=Started container task
0.3519,Event,ADDED,eval-conflicts-rho040-r1-060.18d52f7248cc688e,reason=SuccessfulCreate count=1 msg=Created pod: eval-conflicts-rho040-r1-060-rhz9h
0.3521,Event,ADDED,eval-conflicts-rho040-r1-060.18d52f77d7cbb1e5,reason=Completed count=1 msg=Job completed
0.3522,Event,ADDED,eval-conflicts-rho040-r1-061-wb4n5.18d52f72878471d3,reason=Scheduled count=None msg=Successfully assigned compute/eval-conflicts-rho040-r1-061-wb4n5 to kind-worker2
0.3525,Event,ADDED,eval-conflicts-rho040-r1-061-wb4n5.18d52f72a292f0ee,"reason=Pulled count=1 msg=Container image ""busybox:musl"" already present on machine"
0.3526,Event,ADDED,eval-conflicts-rho040-r1-061-wb4n5.18d52f72a3a619d8,reason=Created count=1 msg=Created container: task
0.3528,Event,ADDED,eval-conflicts-rho040-r1-061-wb4n5.18d52f72ab4f2629,reason=Started count=1 msg=Started container task
0.353,Event,ADDED,eval-conflicts-rho040-r1-061.18d52f7286980ae6,reason=SuccessfulCreate count=1 msg=Created pod: eval-conflicts-rho040-r1-061-wb4n5
0.3531,Event,ADDED,eval-conflicts-rho040-r1-061.18d52f7847921fa8,reason=Completed count=1 msg=Job completed
0.3533,Event,ADDED,eval-conflicts-rho040-r1-062-csvnr.18d52f72c5022586,reason=Scheduled count=None msg=Successfully assigned compute/eval-conflicts-rho040-r1-062-csvnr to kind-worker5
0.3534,Event,ADDED,eval-conflicts-rho040-r1-062-csvnr.18d52f72e1d68fa5,"reason=Pulled count=1 msg=Container image ""busybox:musl"" already present on machine"
0.3536,Event,ADDED,eval-conflicts-rho040-r1-062-csvnr.18d52f72e3551d2c,reason=Created count=1 msg=Created container: task
0.3538,Event,ADDED,eval-conflicts-rho040-r1-062-csvnr.18d52f72f48df7eb,reason=Started count=1 msg=Started container task
0.354,Event,ADDED,eval-conflicts-rho040-r1-062.18d52f72c4409388,reason=SuccessfulCreate count=1 msg=Created pod: eval-conflicts-rho040-r1-062-csvnr
0.3541,Event,ADDED,eval-conflicts-rho040-r1-062.18d52f7885c0ee08,reason=Completed count=1 msg=Job completed
0.3543,Event,ADDED,eval-conflicts-rho040-r1-063-25ntn.18d52f72fd05e97e,reason=Scheduled count=None msg=Successfully assigned compute/eval-conflicts-rho040-r1-063-25ntn to kind-worker3
0.3545,Event,ADDED,eval-conflicts-rho040-r1-063-25ntn.18d52f7319c9e912,"reason=Pulled count=1 msg=Container image ""busybox:musl"" already present on machine"
0.3547,Event,ADDED,eval-conflicts-rho040-r1-063-25ntn.18d52f731ad41d24,reason=Created count=1 msg=Created container: task
0.3548,Event,ADDED,eval-conflicts-rho040-r1-063-25ntn.18d52f73215e21cd,reason=Started count=1 msg=Started container task
0.355,Event,ADDED,eval-conflicts-rho040-r1-063.18d52f72fbf4e87f,reason=SuccessfulCreate count=1 msg=Created pod: eval-conflicts-rho040-r1-063-25ntn
0.3552,Event,ADDED,eval-conflicts-rho040-r1-063.18d52f7899e38ac6,reason=Completed count=1 msg=Job completed
0.3554,Event,ADDED,eval-conflicts-rho040-r1-064-m25fg.18d52f73387afb5d,reason=Scheduled count=None msg=Successfully assigned compute/eval-conflicts-rho040-r1-064-m25fg to kind-worker5
0.3555,Event,ADDED,eval-conflicts-rho040-r1-064-m25fg.18d52f7357e28bc4,"reason=Pulled count=1 msg=Container image ""busybox:musl"" already present on machine"
0.3557,Event,ADDED,eval-conflicts-rho040-r1-064-m25fg.18d52f73598f13dd,reason=Created count=1 msg=Created container: task
0.3559,Event,ADDED,eval-conflicts-rho040-r1-064-m25fg.18d52f7361911f98,reason=Started count=1 msg=Started container task
0.3561,Event,ADDED,eval-conflicts-rho040-r1-064.18d52f73375afe08,reason=SuccessfulCreate count=1 msg=Created pod: eval-conflicts-rho040-r1-064-m25fg
0.3563,Event,ADDED,eval-conflicts-rho040-r1-064.18d52f78c1b1dd75,reason=Completed count=1 msg=Job completed
0.3565,Event,ADDED,eval-conflicts-rho040-r1-065-wq6zh.18d52f73781d1447,reason=Scheduled count=None msg=Successfully assigned compute/eval-conflicts-rho040-r1-065-wq6zh to kind-worker5
0.3566,Event,ADDED,eval-conflicts-rho040-r1-065-wq6zh.18d52f73a0956bde,"reason=Pulled count=1 msg=Container image ""busybox:musl"" already present on machine"
0.3572,Event,ADDED,eval-conflicts-rho040-r1-065-wq6zh.18d52f73a1b34640,reason=Created count=1 msg=Created container: task
0.3573,Event,ADDED,eval-conflicts-rho040-r1-065-wq6zh.18d52f73a7b12b86,reason=Started count=1 msg=Started container task
0.3575,Event,ADDED,eval-conflicts-rho040-r1-065.18d52f737706417c,reason=SuccessfulCreate count=1 msg=Created pod: eval-conflicts-rho040-r1-065-wq6zh
0.3577,Event,ADDED,eval-conflicts-rho040-r1-065.18d52f793bbad487,reason=Completed count=1 msg=Job completed
0.358,Event,ADDED,eval-conflicts-rho040-r1-066-zjr8x.18d52f73da18abc3,reason=Scheduled count=None msg=Successfully assigned compute/eval-conflicts-rho040-r1-066-zjr8x to kind-worker5
0.3581,Event,ADDED,eval-conflicts-rho040-r1-066-zjr8x.18d52f73fae2c3bd,"reason=Pulled count=1 msg=Container image ""busybox:musl"" already present on machine"
0.3583,Event,ADDED,eval-conflicts-rho040-r1-066-zjr8x.18d52f73fc1c0db6,reason=Created count=1 msg=Created container: task
0.3585,Event,ADDED,eval-conflicts-rho040-r1-066-zjr8x.18d52f7405a4c381,reason=Started count=1 msg=Started container task
0.3588,Event,ADDED,eval-conflicts-rho040-r1-066.18d52f73d9710764,reason=SuccessfulCreate count=1 msg=Created pod: eval-conflicts-rho040-r1-066-zjr8x
0.3589,Event,ADDED,eval-conflicts-rho040-r1-066.18d52f79778aaaeb,reason=Completed count=1 msg=Job completed
0.3591,Event,ADDED,eval-conflicts-rho040-r1-067-xcxq2.18d52f740edeba48,"reason=FailedScheduling count=None msg=0/6 nodes are available: 1 c_wall violated: 2 conflicting context pair(s) with node memory, 5 node(s) had untolerated taint(s). no new claims to deallocate, preemption: 0/6 nodes are available: 1 No preemption victims found for incoming pod, 5 Preemption is not helpful for scheduling."
0.3594,Event,ADDED,eval-conflicts-rho040-r1-067-xcxq2.18d52f740fb7f0a8,"reason=FailedScheduling count=None msg=0/6 nodes are available: 1 c_wall violated: 2 conflicting context pair(s) with node memory, 5 node(s) had untolerated taint(s). no new claims to deallocate, preemption: 0/6 nodes are available: 1 No preemption victims found for incoming pod, 5 Preemption is not helpful for scheduling."
0.3596,Event,ADDED,eval-conflicts-rho040-r1-067-xcxq2.18d52f787fc5370e,reason=Scheduled count=None msg=Successfully assigned compute/eval-conflicts-rho040-r1-067-xcxq2 to kind-worker2
0.3597,Event,ADDED,eval-conflicts-rho040-r1-067-xcxq2.18d52f789d793c23,"reason=Pulled count=1 msg=Container image ""busybox:musl"" already present on machine"
0.3599,Event,ADDED,eval-conflicts-rho040-r1-067-xcxq2.18d52f78a2c8eba7,reason=Created count=1 msg=Created container: task
0.3601,Event,ADDED,eval-conflicts-rho040-r1-067-xcxq2.18d52f78a60da8b6,reason=Started count=1 msg=Started container task
0.3603,Event,ADDED,eval-conflicts-rho040-r1-067.18d52f740e9ef11e,reason=SuccessfulCreate count=1 msg=Created pod: eval-conflicts-rho040-r1-067-xcxq2
0.3604,Event,ADDED,eval-conflicts-rho040-r1-067.18d52f7e2725262a,reason=Completed count=1 msg=Job completed
0.3606,Event,ADDED,eval-conflicts-rho040-r1-068-fkg86.18d52f743b6464fb,"reason=FailedScheduling count=None msg=0/6 nodes are available: 1 c_wall violated: 2 conflicting context pair(s) with node memory, 5 node(s) had untolerated taint(s). no new claims to deallocate, preemption: 0/6 nodes are available: 1 No preemption victims found for incoming pod, 5 Preemption is not helpful for scheduling."
0.3608,Event,ADDED,eval-conflicts-rho040-r1-068-fkg86.18d52f743bd889c5,"reason=FailedScheduling count=None msg=0/6 nodes are available: 1 c_wall violated: 2 conflicting context pair(s) with node memory, 5 node(s) had untolerated taint(s). no new claims to deallocate, preemption: 0/6 nodes are available: 1 No preemption victims found for incoming pod, 5 Preemption is not helpful for scheduling."
0.3609,Event,ADDED,eval-conflicts-rho040-r1-068-fkg86.18d52f787f35cd0d,reason=Scheduled count=None msg=Successfully assigned compute/eval-conflicts-rho040-r1-068-fkg86 to kind-worker2
0.3612,Event,ADDED,eval-conflicts-rho040-r1-068-fkg86.18d52f789c062e2d,"reason=Pulled count=1 msg=Container image ""busybox:musl"" already present on machine"
0.3613,Event,ADDED,eval-conflicts-rho040-r1-068-fkg86.18d52f78a17a9e24,reason=Created count=1 msg=Created container: task
0.3615,Event,ADDED,eval-conflicts-rho040-r1-068-fkg86.18d52f78a4798d05,reason=Started count=1 msg=Started container task
0.3617,Event,ADDED,eval-conflicts-rho040-r1-068.18d52f743b2ae6a6,reason=SuccessfulCreate count=1 msg=Created pod: eval-conflicts-rho040-r1-068-fkg86
0.3619,Event,ADDED,eval-conflicts-rho040-r1-068.18d52f7e2745f69a,reason=Completed count=1 msg=Job completed
0.362,Event,ADDED,eval-conflicts-rho040-r1-069-4j2cn.18d52f747cff1895,reason=Scheduled count=None msg=Successfully assigned compute/eval-conflicts-rho040-r1-069-4j2cn to kind-worker5
0.3622,Event,ADDED,eval-conflicts-rho040-r1-069-4j2cn.18d52f74a11a6020,"reason=Pulled count=1 msg=Container image ""busybox:musl"" already present on machine"
0.3624,Event,ADDED,eval-conflicts-rho040-r1-069-4j2cn.18d52f74a2723f00,reason=Created count=1 msg=Created container: task
0.3625,Event,ADDED,eval-conflicts-rho040-r1-069-4j2cn.18d52f74a59e9841,reason=Started count=1 msg=Started container task
0.3627,Event,ADDED,eval-conflicts-rho040-r1-069.18d52f747c6e6c3b,reason=SuccessfulCreate count=1 msg=Created pod: eval-conflicts-rho040-r1-069-4j2cn
0.3629,Event,ADDED,eval-conflicts-rho040-r1-069.18d52f7a2c225aba,reason=Completed count=1 msg=Job completed
0.363,Event,ADDED,eval-conflicts-rho040-r1-070-gm4zh.18d52f74dc15ed83,"reason=FailedScheduling count=None msg=0/6 nodes are available: 1 c_wall violated: 2 conflicting context pair(s) with node memory, 5 node(s) had untolerated taint(s). no new claims to deallocate, preemption: 0/6 nodes are available: 1 No preemption victims found for incoming pod, 5 Preemption is not helpful for scheduling."
0.3632,Event,ADDED,eval-conflicts-rho040-r1-070-gm4zh.18d52f74dc9d92c5,"reason=FailedScheduling count=None msg=0/6 nodes are available: 1 c_wall violated: 2 conflicting context pair(s) with node memory, 5 node(s) had untolerated taint(s). no new claims to deallocate, preemption: 0/6 nodes are available: 1 No preemption victims found for incoming pod, 5 Preemption is not helpful for scheduling."
0.3634,Event,ADDED,eval-conflicts-rho040-r1-070-gm4zh.18d52f773a4aa2e0,"reason=FailedScheduling count=None msg=0/6 nodes are available: 1 c_wall violated: 3 conflicting context pair(s) with node memory, 5 node(s) had untolerated taint(s). no new claims to deallocate, preemption: 0/6 nodes are available: 1 No preemption victims found for incoming pod, 5 Preemption is not helpful for scheduling."
0.3635,Event,ADDED,eval-conflicts-rho040-r1-070-gm4zh.18d52f7884b12264,reason=Scheduled count=None msg=Successfully assigned compute/eval-conflicts-rho040-r1-070-gm4zh to kind-worker2
0.3637,Event,ADDED,eval-conflicts-rho040-r1-070-gm4zh.18d52f78a2dc8de4,"reason=Pulled count=1 msg=Container image ""busybox:musl"" already present on machine"
0.3639,Event,ADDED,eval-conflicts-rho040-r1-070-gm4zh.18d52f78a7540ecf,reason=Created count=1 msg=Created container: task
0.364,Event,ADDED,eval-conflicts-rho040-r1-070-gm4zh.18d52f78af814c38,reason=Started count=1 msg=Started container task
0.3642,Event,ADDED,eval-conflicts-rho040-r1-070.18d52f74dbcc35cb,reason=SuccessfulCreate count=1 msg=Created pod: eval-conflicts-rho040-r1-070-gm4zh
0.3644,Event,ADDED,eval-conflicts-rho040-r1-070.18d52f7dea5390ff,reason=Completed count=1 msg=Job completed
0.3645,Event,ADDED,eval-conflicts-rho040-r1-071-5hkng.18d52f7507a20452,"reason=FailedScheduling count=None msg=0/6 nodes are available: 1 c_wall violated: 2 conflicting context pair(s) with node memory, 5 node(s) had untolerated taint(s). no new claims to deallocate, preemption: 0/6 nodes are available: 1 No preemption victims found for incoming pod, 5 Preemption is not helpful for scheduling."
0.3647,Event,ADDED,eval-conflicts-rho040-r1-071-5hkng.18d52f7508280131,"reason=FailedScheduling count=None msg=0/6 nodes are available: 1 c_wall violated: 2 conflicting context pair(s) with node memory, 5 node(s) had untolerated taint(s). no new claims to deallocate, preemption: 0/6 nodes are available: 1 No preemption victims found for incoming pod, 5 Preemption is not helpful for scheduling."
0.3649,Event,ADDED,eval-conflicts-rho040-r1-071-5hkng.18d52f773a6ec831,"reason=FailedScheduling count=None msg=0/6 nodes are available: 1 c_wall violated: 3 conflicting context pair(s) with node memory, 5 node(s) had untolerated taint(s). no new claims to deallocate, preemption: 0/6 nodes are available: 1 No preemption victims found for incoming pod, 5 Preemption is not helpful for scheduling."
0.3651,Event,ADDED,eval-conflicts-rho040-r1-071-5hkng.18d52f7889524c1b,reason=Scheduled count=None msg=Successfully assigned compute/eval-conflicts-rho040-r1-071-5hkng to kind-worker2
0.3654,Event,ADDED,eval-conflicts-rho040-r1-071-5hkng.18d52f78a34e5e93,"reason=Pulled count=1 msg=Container image ""busybox:musl"" already present on machine"
0.3656,Event,ADDED,eval-conflicts-rho040-r1-071-5hkng.18d52f78a78e3643,reason=Created count=1 msg=Created container: task
0.3657,Event,ADDED,eval-conflicts-rho040-r1-071-5hkng.18d52f78af82073a,reason=Started count=1 msg=Started container task
0.366,Event,ADDED,eval-conflicts-rho040-r1-071.18d52f75076a6863,reason=SuccessfulCreate count=1 msg=Created pod: eval-conflicts-rho040-r1-071-5hkng
0.3662,Event,ADDED,eval-conflicts-rho040-r1-071.18d52f7eb45de3a0,reason=Completed count=1 msg=Job completed
0.3663,Event,ADDED,eval-conflicts-rho040-r1-072-prb9n.18d52f7541e47e7b,"reason=FailedScheduling count=None msg=0/6 nodes are available: 1 c_wall violated: 2 conflicting context pair(s) with node memory, 5 node(s) had untolerated taint(s). no new claims to deallocate, preemption: 0/6 nodes are available: 1 No preemption victims found for incoming pod, 5 Preemption is not helpful for scheduling."
0.3665,Event,ADDED,eval-conflicts-rho040-r1-072-prb9n.18d52f7542871e37,"reason=FailedScheduling count=None msg=0/6 nodes are available: 1 c_wall violated: 2 conflicting context pair(s) with node memory, 5 node(s) had untolerated taint(s). no new claims to deallocate, preemption: 0/6 nodes are available: 1 No preemption victims found for incoming pod, 5 Preemption is not helpful for scheduling."
0.3667,Event,ADDED,eval-conflicts-rho040-r1-072-prb9n.18d52f7736a8f271,"reason=FailedScheduling count=None msg=0/6 nodes are available: 1 c_wall violated: 3 conflicting context pair(s) with node memory, 5 node(s) had untolerated taint(s). no new claims to deallocate, preemption: 0/6 nodes are available: 1 No preemption victims found for incoming pod, 5 Preemption is not helpful for scheduling."
0.3669,Event,ADDED,eval-conflicts-rho040-r1-072-prb9n.18d52f788344d7be,reason=Scheduled count=None msg=Successfully assigned compute/eval-conflicts-rho040-r1-072-prb9n to kind-worker2
0.367,Event,ADDED,eval-conflicts-rho040-r1-072-prb9n.18d52f789edaa49b,"reason=Pulled count=1 msg=Container image ""busybox:musl"" already present on machine"
0.3673,Event,ADDED,eval-conflicts-rho040-r1-072-prb9n.18d52f78a46f3874,reason=Created count=1 msg=Created container: task
0.3675,Event,ADDED,eval-conflicts-rho040-r1-072-prb9n.18d52f78a753c054,reason=Started count=1 msg=Started container task
0.3677,Event,ADDED,eval-conflicts-rho040-r1-072.18d52f7541aa43d4,reason=SuccessfulCreate count=1 msg=Created pod: eval-conflicts-rho040-r1-072-prb9n
0.3679,Event,ADDED,eval-conflicts-rho040-r1-072.18d52f7e27657932,reason=Completed count=1 msg=Job completed
0.3681,Event,ADDED,eval-conflicts-rho040-r1-073-dnfzd.18d52f757415cb69,"reason=FailedScheduling count=None msg=0/6 nodes are available: 1 c_wall violated: 2 conflicting context pair(s) with node memory, 5 node(s) had untolerated taint(s). no new claims to deallocate, preemption: 0/6 nodes are available: 1 No preemption victims found for incoming pod, 5 Preemption is not helpful for scheduling."
0.3684,Event,ADDED,eval-conflicts-rho040-r1-073-dnfzd.18d52f7574b9debc,"reason=FailedScheduling count=None msg=0/6 nodes are available: 1 c_wall violated: 2 conflicting context pair(s) with node memory, 5 node(s) had untolerated taint(s). no new claims to deallocate, preemption: 0/6 nodes are available: 1 No preemption victims found for incoming pod, 5 Preemption is not helpful for scheduling."
0.369,Event,ADDED,eval-conflicts-rho040-r1-073-dnfzd.18d52f7736f59345,"reason=FailedScheduling count=None msg=0/6 nodes are available: 1 c_wall violated: 3 conflicting context pair(s) with node memory, 5 node(s) had untolerated taint(s). no new claims to deallocate, preemption: 0/6 nodes are available: 1 No preemption victims found for incoming pod, 5 Preemption is not helpful for scheduling."
0.3692,Event,ADDED,eval-conflicts-rho040-r1-073-dnfzd.18d52f78839ac8d5,reason=Scheduled count=None msg=Successfully assigned compute/eval-conflicts-rho040-r1-073-dnfzd to kind-worker2
0.3694,Event,ADDED,eval-conflicts-rho040-r1-073-dnfzd.18d52f78a18134a5,"reason=Pulled count=1 msg=Container image ""busybox:musl"" already present on machine"
0.3695,Event,ADDED,eval-conflicts-rho040-r1-073-dnfzd.18d52f78a686380c,reason=Created count=1 msg=Created container: task
0.3699,Event,ADDED,eval-conflicts-rho040-r1-073-dnfzd.18d52f78aa7dd2a5,reason=Started count=1 msg=Started container task
0.37,Event,ADDED,eval-conflicts-rho040-r1-073.18d52f7573d24129,reason=SuccessfulCreate count=1 msg=Created pod: eval-conflicts-rho040-r1-073-dnfzd
0.3702,Event,ADDED,eval-conflicts-rho040-r1-073.18d52f7ed16417e9,reason=Completed count=1 msg=Job completed
0.3704,Event,ADDED,eval-conflicts-rho040-r1-074-jg645.18d52f759b027a74,"reason=FailedScheduling count=None msg=0/6 nodes are available: 1 c_wall violated: 2 conflicting context pair(s) with node memory, 5 node(s) had untolerated taint(s). no new claims to deallocate, preemption: 0/6 nodes are available: 1 No preemption victims found for incoming pod, 5 Preemption is not helpful for scheduling."
0.3706,Event,ADDED,eval-conflicts-rho040-r1-074-jg645.18d52f759b7f58b6,"reason=FailedScheduling count=None msg=0/6 nodes are available: 1 c_wall violated: 2 conflicting context pair(s) with node memory, 5 node(s) had untolerated taint(s). no new claims to deallocate, preemption: 0/6 nodes are available: 1 No preemption victims found for incoming pod, 5 Preemption is not helpful for scheduling."
0.3708,Event,ADDED,eval-conflicts-rho040-r1-074-jg645.18d52f773a26845c,"reason=FailedScheduling count=None msg=0/6 nodes are available: 1 c_wall violated: 3 conflicting context pair(s) with node memory, 5 node(s) had untolerated taint(s). no new claims to deallocate, preemption: 0/6 nodes are available: 1 No preemption victims found for incoming pod, 5 Preemption is not helpful for scheduling."
0.3709,Event,ADDED,eval-conflicts-rho040-r1-074-jg645.18d52f788482fd26,reason=Scheduled count=None msg=Successfully assigned compute/eval-conflicts-rho040-r1-074-jg645 to kind-worker2
0.3711,Event,ADDED,eval-conflicts-rho040-r1-074-jg645.18d52f78a24dfd87,"reason=Pulled count=1 msg=Container image ""busybox:musl"" already present on machine"
0.3713,Event,ADDED,eval-conflicts-rho040-r1-074-jg645.18d52f78a6ddf16a,reason=Created count=1 msg=Created container: task
0.3715,Event,ADDED,eval-conflicts-rho040-r1-074-jg645.18d52f78af82180c,reason=Started count=1 msg=Started container task
0.3716,Event,ADDED,eval-conflicts-rho040-r1-074.18d52f759ac63932,reason=SuccessfulCreate count=1 msg=Created pod: eval-conflicts-rho040-r1-074-jg645
0.3718,Event,ADDED,eval-conflicts-rho040-r1-074.18d52f7ec5146d42,reason=Completed count=1 msg=Job completed
0.3719,Event,ADDED,eval-conflicts-rho040-r1-075-k6mtz.18d52f75e1aaaf31,reason=Scheduled count=None msg=Successfully assigned compute/eval-conflicts-rho040-r1-075-k6mtz to kind-worker5
0.3721,Event,ADDED,eval-conflicts-rho040-r1-075-k6mtz.18d52f7605039990,"reason=Pulled count=1 msg=Container image ""busybox:musl"" already present on machine"
0.3723,Event,ADDED,eval-conflicts-rho040-r1-075-k6mtz.18d52f76069ac1b1,reason=Created count=1 msg=Created container: task
0.3725,Event,ADDED,eval-conflicts-rho040-r1-075-k6mtz.18d52f760ad58c13,reason=Started count=1 msg=Started container task
0.3726,Event,ADDED,eval-conflicts-rho040-r1-075.18d52f75e115bcd1,reason=SuccessfulCreate count=1 msg=Created pod: eval-conflicts-rho040-r1-075-k6mtz
0.3728,Event,ADDED,eval-conflicts-rho040-r1-075.18d52f7b8ece0139,reason=Completed count=1 msg=Job completed
0.3729,Event,ADDED,eval-conflicts-rho040-r1-076-sz68c.18d52f7607f628cc,"reason=FailedScheduling count=None msg=0/6 nodes are available: 1 c_wall violated: 2 conflicting context pair(s) with node memory, 5 node(s) had untolerated taint(s). no new claims to deallocate, preemption: 0/6 nodes are available: 1 No preemption victims found for incoming pod, 5 Preemption is not helpful for scheduling."
0.3731,Event,ADDED,eval-conflicts-rho040-r1-076-sz68c.18d52f76086cf84a,"reason=FailedScheduling count=None msg=0/6 nodes are available: 1 c_wall violated: 2 conflicting context pair(s) with node memory, 5 node(s) had untolerated taint(s). no new claims to deallocate, preemption: 0/6 nodes are available: 1 No preemption victims found for incoming pod, 5 Preemption is not helpful for scheduling."
0.3733,Event,ADDED,eval-conflicts-rho040-r1-076-sz68c.18d52f77366213c5,"reason=FailedScheduling count=None msg=0/6 nodes are available: 1 c_wall violated: 3 conflicting context pair(s) with node memory, 5 node(s) had untolerated taint(s). no new claims to deallocate, preemption: 0/6 nodes are available: 1 No preemption victims found for incoming pod, 5 Preemption is not helpful for scheduling."
0.3735,Event,ADDED,eval-conflicts-rho040-r1-076-sz68c.18d52f787feea1fe,reason=Scheduled count=None msg=Successfully assigned compute/eval-conflicts-rho040-r1-076-sz68c to kind-worker2
0.3737,Event,ADDED,eval-conflicts-rho040-r1-076-sz68c.18d52f789e33e84a,"reason=Pulled count=1 msg=Container image ""busybox:musl"" already present on machine"
0.3738,Event,ADDED,eval-conflicts-rho040-r1-076-sz68c.18d52f78a3c14a95,reason=Created count=1 msg=Created container: task
0.3741,Event,ADDED,eval-conflicts-rho040-r1-076-sz68c.18d52f78a685db03,reason=Started count=1 msg=Started container task
0.3742,Event,ADDED,eval-conflicts-rho040-r1-076.18d52f7607bab5c6,reason=SuccessfulCreate count=1 msg=Created pod: eval-conflicts-rho040-r1-076-sz68c
0.3744,Event,ADDED,eval-conflicts-rho040-r1-076.18d52f7eb7594988,reason=Completed count=1 msg=Job completed
0.3746,Event,ADDED,eval-conflicts-rho040-r1-077-4t666.18d52f7641e863f5,"reason=FailedScheduling count=None msg=0/6 nodes are available: 1 c_wall violated: 2 conflicting context pair(s) with node memory, 5 node(s) had untolerated taint(s). no new claims to deallocate, preemption: 0/6 nodes are available: 1 No preemption victims found for incoming pod, 5 Preemption is not helpful for scheduling."
0.3748,Event,ADDED,eval-conflicts-rho040-r1-077-4t666.18d52f76496dc4de,"reason=FailedScheduling count=None msg=0/6 nodes are available: 1 c_wall violated: 2 conflicting context pair(s) with node memory, 5 node(s) had untolerated taint(s). no new claims to deallocate, preemption: 0/6 nodes are available: 1 No preemption victims found for incoming pod, 5 Preemption is not helpful for scheduling."
0.3749,Event,ADDED,eval-conflicts-rho040-r1-077-4t666.18d52f773685dd55,"reason=FailedScheduling count=None msg=0/6 nodes are available: 1 c_wall violated: 3 conflicting context pair(s) with node memory, 5 node(s) had untolerated taint(s). no new claims to deallocate, preemption: 0/6 nodes are available: 1 No preemption victims found for incoming pod, 5 Preemption is not helpful for scheduling."
0.3751,Event,ADDED,eval-conflicts-rho040-r1-077-4t666.18d52f7880268c31,reason=Scheduled count=None msg=Successfully assigned compute/eval-conflicts-rho040-r1-077-4t666 to kind-worker2
0.3754,Event,ADDED,eval-conflicts-rho040-r1-077-4t666.18d52f789d979bd2,"reason=Pulled count=1 msg=Container image ""busybox:musl"" already present on machine"
0.3756,Event,ADDED,eval-conflicts-rho040-r1-077-4t666.18d52f78a2f704a4,reason=Created count=1 msg=Created container: task
0.3757,Event,ADDED,eval-conflicts-rho040-r1-077-4t666.18d52f78a60de41c,reason=Started count=1 msg=Started container task
0.376,Event,ADDED,eval-conflicts-rho040-r1-077.18d52f763ef029d5,reason=SuccessfulCreate count=1 msg=Created pod: eval-conflicts-rho040-r1-077-4t666
0.3762,Event,ADDED,eval-conflicts-rho040-r1-077.18d52f7e27667bfa,reason=Completed count=1 msg=Job completed
0.3764,Event,ADDED,eval-conflicts-rho040-r1-078-4zvg2.18d52f767df1e45b,reason=Scheduled count=None msg=Successfully assigned compute/eval-conflicts-rho040-r1-078-4zvg2 to kind-worker5
0.3766,Event,ADDED,eval-conflicts-rho040-r1-078-4zvg2.18d52f76a7ff50de,"reason=Pulled count=1 msg=Container image ""busybox:musl"" already present on machine"
0.3768,Event,ADDED,eval-conflicts-rho040-r1-078-4zvg2.18d52f76a95067e6,reason=Created count=1 msg=Created container: task
0.377,Event,ADDED,eval-conflicts-rho040-r1-078-4zvg2.18d52f76aeaf3334,reason=Started count=1 msg=Started container task
0.3772,Event,ADDED,eval-conflicts-rho040-r1-078.18d52f767d70bd55,reason=SuccessfulCreate count=1 msg=Created pod: eval-conflicts-rho040-r1-078-4zvg2
0.3773,Event,ADDED,eval-conflicts-rho040-r1-078.18d52f7c4523aabd,reason=Completed count=1 msg=Job completed
0.3775,Event,ADDED,eval-conflicts-rho040-r1-079-99p55.18d52f76bc96b57b,"reason=FailedScheduling count=None msg=0/6 nodes are available: 1 c_wall violated: 2 conflicting context pair(s) with node memory, 5 node(s) had untolerated taint(s). no new claims to deallocate, preemption: 0/6 nodes are available: 1 No preemption victims found for incoming pod, 5 Preemption is not helpful for scheduling."
0.3779,Event,ADDED,eval-conflicts-rho040-r1-079-99p55.18d52f76bd0f0a67,"reason=FailedScheduling count=None msg=0/6 nodes are available: 1 c_wall violated: 2 conflicting context pair(s) with node memory, 5 node(s) had untolerated taint(s). no new claims to deallocate, preemption: 0/6 nodes are available: 1 No preemption victims found for incoming pod, 5 Preemption is not helpful for scheduling."
0.3781,Event,ADDED,eval-conflicts-rho040-r1-079-99p55.18d52f7736ceaa99,"reason=FailedScheduling count=None msg=0/6 nodes are available: 1 c_wall violated: 3 conflicting context pair(s) with node memory, 5 node(s) had untolerated taint(s). no new claims to deallocate, preemption: 0/6 nodes are available: 1 No preemption victims found for incoming pod, 5 Preemption is not helpful for scheduling."
0.3783,Event,ADDED,eval-conflicts-rho040-r1-079-99p55.18d52f788351f7d4,reason=Scheduled count=None msg=Successfully assigned compute/eval-conflicts-rho040-r1-079-99p55 to kind-worker2
0.3786,Event,ADDED,eval-conflicts-rho040-r1-079-99p55.18d52f789ef25585,"reason=Pulled count=1 msg=Container image ""busybox:musl"" already present on machine"
0.3788,Event,ADDED,eval-conflicts-rho040-r1-079-99p55.18d52f78a46c8261,reason=Created count=1 msg=Created container: task
0.379,Event,ADDED,eval-conflicts-rho040-r1-079-99p55.18d52f78a791be30,reason=Started count=1 msg=Started container task
0.3793,Event,ADDED,eval-conflicts-rho040-r1-079.18d52f76bc50a201,reason=SuccessfulCreate count=1 msg=Created pod: eval-conflicts-rho040-r1-079-99p55
0.3795,Event,ADDED,eval-conflicts-rho040-r1-079.18d52f7e276934a2,reason=Completed count=1 msg=Job completed
0.3797,Event,ADDED,eval-conflicts-rho040-r1-080-rkxj7.18d52f76f1bba8d7,reason=Scheduled count=None msg=Successfully assigned compute/eval-conflicts-rho040-r1-080-rkxj7 to kind-worker5
0.3798,Event,ADDED,eval-conflicts-rho040-r1-080-rkxj7.18d52f770bcfd1b9,"reason=Pulled count=1 msg=Container image ""busybox:musl"" already present on machine"
0.3801,Event,ADDED,eval-conflicts-rho040-r1-080-rkxj7.18d52f770d60646a,reason=Created count=1 msg=Created container: task
0.3802,Event,ADDED,eval-conflicts-rho040-r1-080-rkxj7.18d52f77133ffe12,reason=Started count=1 msg=Started container task
0.3804,Event,ADDED,eval-conflicts-rho040-r1-080.18d52f76f14df663,reason=SuccessfulCreate count=1 msg=Created pod: eval-conflicts-rho040-r1-080-rkxj7
0.3806,Event,ADDED,eval-conflicts-rho040-r1-080.18d52f7c8142797b,reason=Completed count=1 msg=Job completed
0.3807,Event,ADDED,eval-conflicts-rho040-r1-081-8bmdv.18d52f772ddacd73,reason=Scheduled count=None msg=Successfully assigned compute/eval-conflicts-rho040-r1-081-8bmdv to kind-worker5
0.3809,Event,ADDED,eval-conflicts-rho040-r1-081-8bmdv.18d52f7746a56f9f,"reason=Pulled count=1 msg=Container image ""busybox:musl"" already present on machine"
0.3811,Event,ADDED,eval-conflicts-rho040-r1-081-8bmdv.18d52f7747c06cbe,reason=Created count=1 msg=Created container: task
0.3812,Event,ADDED,eval-conflicts-rho040-r1-081-8bmdv.18d52f7749dd9438,reason=Started count=1 msg=Started container task
0.3814,Event,ADDED,eval-conflicts-rho040-r1-081.18d52f772d52cfd6,reason=SuccessfulCreate count=1 msg=Created pod: eval-conflicts-rho040-r1-081-8bmdv
0.3816,Event,ADDED,eval-conflicts-rho040-r1-081.18d52f7cbababe4c,reason=Completed count=1 msg=Job completed
0.3818,Event,ADDED,eval-conflicts-rho040-r1-082-8rvfz.18d52f776df997aa,"reason=FailedScheduling count=None msg=0/6 nodes are available: 6 node(s) had untolerated taint(s). no new claims to deallocate, preemption: 0/6 nodes are available: 6 Preemption is not helpful for scheduling."
0.3821,Event,ADDED,eval-conflicts-rho040-r1-082-8rvfz.18d52f78847e7d4d,"reason=FailedScheduling count=None msg=0/6 nodes are available: 1 c_wall violated: 1 conflicting context pair(s) with node memory, 5 node(s) had untolerated taint(s). no new claims to deallocate, preemption: 0/6 nodes are available: 1 No preemption victims found for incoming pod, 5 Preemption is not helpful for scheduling."
0.3823,Event,ADDED,eval-conflicts-rho040-r1-082-8rvfz.18d52f78922091ea,"reason=FailedScheduling count=None msg=0/6 nodes are available: 1 c_wall violated: 1 conflicting context pair(s) with node memory, 5 node(s) had untolerated taint(s). no new claims to deallocate, preemption: 0/6 nodes are available: 1 No preemption victims found for incoming pod, 5 Preemption is not helpful for scheduling."
0.3824,Event,ADDED,eval-conflicts-rho040-r1-082-8rvfz.18d52f78a2520a30,reason=Scheduled count=None msg=Successfully assigned compute/eval-conflicts-rho040-r1-082-8rvfz to kind-worker3
0.3826,Event,ADDED,eval-conflicts-rho040-r1-082-8rvfz.18d52f78be049e3f,"reason=Pulled count=1 msg=Container image ""busybox:musl"" already present on machine"
0.3828,Event,ADDED,eval-conflicts-rho040-r1-082-8rvfz.18d52f78bf57cd64,reason=Created count=1 msg=Created container: task
0.383,Event,ADDED,eval-conflicts-rho040-r1-082-8rvfz.18d52f78caa5caaf,reason=Started count=1 msg=Started container task
0.3831,Event,ADDED,eval-conflicts-rho040-r1-082.18d52f776df0e517,reason=SuccessfulCreate count=1 msg=Created pod: eval-conflicts-rho040-r1-082-8rvfz
0.3833,Event,ADDED,eval-conflicts-rho040-r1-082.18d52f7df73dc640,reason=Completed count=1 msg=Job completed
0.3835,Event,ADDED,eval-conflicts-rho040-r1-083-78ghx.18d52f77a4837ad9,"reason=FailedScheduling count=None msg=0/6 nodes are available: 6 node(s) had untolerated taint(s). no new claims to deallocate, preemption: 0/6 nodes are available: 6 Preemption is not helpful for scheduling."
0.3836,Event,ADDED,eval-conflicts-rho040-r1-083-78ghx.18d52f788f30c006,"reason=FailedScheduling count=None msg=0/6 nodes are available: 1 c_wall violated: 2 conflicting context pair(s) with node memory, 5 node(s) had untolerated taint(s). no new claims to deallocate, preemption: 0/6 nodes are available: 1 No preemption victims found for incoming pod, 5 Preemption is not helpful for scheduling."
0.3838,Event,ADDED,eval-conflicts-rho040-r1-083-78ghx.18d52f7892557515,"reason=FailedScheduling count=None msg=0/6 nodes are available: 1 c_wall violated: 2 conflicting context pair(s) with node memory, 5 node(s) had untolerated taint(s). no new claims to deallocate, preemption: 0/6 nodes are available: 1 No preemption victims found for incoming pod, 5 Preemption is not helpful for scheduling."
0.384,Event,ADDED,eval-conflicts-rho040-r1-083-78ghx.18d52f78a33888e6,reason=Scheduled count=None msg=Successfully assigned compute/eval-conflicts-rho040-r1-083-78ghx to kind-worker3
0.3842,Event,ADDED,eval-conflicts-rho040-r1-083-78ghx.18d52f78be37aef2,"reason=Pulled count=1 msg=Container image ""busybox:musl"" already present on machine"
0.3843,Event,ADDED,eval-conflicts-rho040-r1-083-78ghx.18d52f78bfb90c4f,reason=Created count=1 msg=Created container: task
0.3845,Event,ADDED,eval-conflicts-rho040-r1-083-78ghx.18d52f78caa5f647,reason=Started count=1 msg=Started container task
0.3847,Event,ADDED,eval-conflicts-rho040-r1-083.18d52f77a4765a5d,reason=SuccessfulCreate count=1 msg=Created pod: eval-conflicts-rho040-r1-083-78ghx
0.3849,Event,ADDED,eval-conflicts-rho040-r1-083.18d52f7eed88e100,reason=Completed count=1 msg=Job completed
0.3851,Event,ADDED,eval-conflicts-rho040-r1-084-fqvqt.18d52f77e0af4229,"reason=FailedScheduling count=None msg=0/6 nodes are available: 6 node(s) had untolerated taint(s). no new claims to deallocate, preemption: 0/6 nodes are available: 6 Preemption is not helpful for scheduling."
0.3852,Event,ADDED,eval-conflicts-rho040-r1-084-fqvqt.18d52f7890c70e7a,"reason=FailedScheduling count=None msg=0/6 nodes are available: 1 c_wall violated: 1 conflicting context pair(s) with node memory, 5 node(s) had untolerated taint(s). no new claims to deallocate, preemption: 0/6 nodes are available: 1 No preemption victims found for incoming pod, 5 Preemption is not helpful for scheduling."
0.3854,Event,ADDED,eval-conflicts-rho040-r1-084-fqvqt.18d52f7895c06090,"reason=FailedScheduling count=None msg=0/6 nodes are available: 1 c_wall violated: 1 conflicting context pair(s) with node memory, 5 node(s) had untolerated taint(s). no new claims to deallocate, preemption: 0/6 nodes are available: 1 No preemption victims found for incoming pod, 5 Preemption is not helpful for scheduling."
0.3856,Event,ADDED,eval-conflicts-rho040-r1-084-fqvqt.18d52f78ada1ee4a,"reason=FailedScheduling count=None msg=0/6 nodes are available: 2 c_wall violated: 1 conflicting context pair(s) with node memory, 4 node(s) had untolerated taint(s). no new claims to deallocate, preemption: 0/6 nodes are available: 2 No preemption victims found for incoming pod, 4 Preemption is not helpful for scheduling."
0.3858,Event,ADDED,eval-conflicts-rho040-r1-084-fqvqt.18d52f7bdf95d816,reason=Scheduled count=None msg=Successfully assigned compute/eval-conflicts-rho040-r1-084-fqvqt to kind-worker4
0.3859,Event,ADDED,eval-conflicts-rho040-r1-084-fqvqt.18d52f7c06186f75,"reason=Pulled count=1 msg=Container image ""busybox:musl"" already present on machine"
0.3861,Event,ADDED,eval-conflicts-rho040-r1-084-fqvqt.18d52f7c0b2f2528,reason=Created count=1 msg=Created container: task
0.3863,Event,ADDED,eval-conflicts-rho040-r1-084-fqvqt.18d52f7c0f2156ea,reason=Started count=1 msg=Started container task
0.3864,Event,ADDED,eval-conflicts-rho040-r1-084.18d52f77e0a4a5b6,reason=SuccessfulCreate count=1 msg=Created pod: eval-conflicts-rho040-r1-084-fqvqt
0.3866,Event,ADDED,eval-conflicts-rho040-r1-084.18d52f8208b22cfd,reason=Completed count=1 msg=Job completed
0.3868,Event,ADDED,eval-conflicts-rho040-r1-085-g76zg.18d52f7822ac421a,"reason=FailedScheduling count=None msg=0/6 nodes are available: 6 node(s) had untolerated taint(s). no new claims to deallocate, preemption: 0/6 nodes are available: 6 Preemption is not helpful for scheduling."
0.3869,Event,ADDED,eval-conflicts-rho040-r1-085-g76zg.18d52f78916ec324,"reason=FailedScheduling count=None msg=0/6 nodes are available: 1 c_wall violated: 1 conflicting context pair(s) with node memory, 5 node(s) had untolerated taint(s). no new claims to deallocate, preemption: 0/6 nodes are available: 1 No preemption victims found for incoming pod, 5 Preemption is not helpful for scheduling."
0.3871,Event,ADDED,eval-conflicts-rho040-r1-085-g76zg.18d52f7896aa2cd4,"reason=FailedScheduling count=None msg=0/6 nodes are available: 1 c_wall violated: 1 conflicting context pair(s) with node memory, 5 node(s) had untolerated taint(s). no new claims to deallocate, preemption: 0/6 nodes are available: 1 No preemption victims found for incoming pod, 5 Preemption is not helpful for scheduling."
0.3873,Event,ADDED,eval-conflicts-rho040-r1-085-g76zg.18d52f78ae38231f,"reason=FailedScheduling count=None msg=0/6 nodes are available: 2 c_wall violated: 1 conflicting context pair(s) with node memory, 4 node(s) had untolerated taint(s). no new claims to deallocate, preemption: 0/6 nodes are available: 2 No preemption victims found for incoming pod, 4 Preemption is not helpful for scheduling."
0.3874,Event,ADDED,eval-conflicts-rho040-r1-085-g76zg.18d52f7bc728576b,reason=Scheduled count=None msg=Successfully assigned compute/eval-conflicts-rho040-r1-085-g76zg to kind-worker4
0.3876,Event,ADDED,eval-conflicts-rho040-r1-085-g76zg.18d52f7be77bc335,"reason=Pulled count=1 msg=Container image ""busybox:musl"" already present on machine"
0.3882,Event,ADDED,eval-conflicts-rho040-r1-085-g76zg.18d52f7be940b0cb,reason=Created count=1 msg=Created container: task
0.3884,Event,ADDED,eval-conflicts-rho040-r1-085-g76zg.18d52f7bed45f5a7,reason=Started count=1 msg=Started container task
0.3885,Event,ADDED,eval-conflicts-rho040-r1-085.18d52f7822a3b434,reason=SuccessfulCreate count=1 msg=Created pod: eval-conflicts-rho040-r1-085-g76zg
0.3887,Event,ADDED,eval-conflicts-rho040-r1-085.18d52f815947e4af,reason=Completed count=1 msg=Job completed
0.389,Event,ADDED,eval-conflicts-rho040-r1-086-4fqhs.18d52f7856700854,"reason=FailedScheduling count=None msg=0/6 nodes are available: 6 node(s) had untolerated taint(s). no new claims to deallocate, preemption: 0/6 nodes are available: 6 Preemption is not helpful for scheduling."
0.3891,Event,ADDED,eval-conflicts-rho040-r1-086-4fqhs.18d52f789256f18b,reason=Scheduled count=None msg=Successfully assigned compute/eval-conflicts-rho040-r1-086-4fqhs to kind-worker2
0.3893,Event,ADDED,eval-conflicts-rho040-r1-086-4fqhs.18d52f78b018cc80,"reason=Pulled count=1 msg=Container image ""busybox:musl"" already present on machine"
0.3895,Event,ADDED,eval-conflicts-rho040-r1-086-4fqhs.18d52f78b142c6b3,reason=Created count=1 msg=Created container: task
0.3897,Event,ADDED,eval-conflicts-rho040-r1-086-4fqhs.18d52f78b6b1c665,reason=Started count=1 msg=Started container task
0.3898,Event,ADDED,eval-conflicts-rho040-r1-086.18d52f7856663454,reason=SuccessfulCreate count=1 msg=Created pod: eval-conflicts-rho040-r1-086-4fqhs
0.39,Event,ADDED,eval-conflicts-rho040-r1-086.18d52f7ec637920a,reason=Completed count=1 msg=Job completed
0.3902,Event,ADDED,eval-conflicts-rho040-r1-087-xbmfv.18d52f7895f86895,"reason=FailedScheduling count=None msg=0/6 nodes are available: 1 c_wall violated: 1 conflicting context pair(s) with node memory, 5 node(s) had untolerated taint(s). no new claims to deallocate, preemption: 0/6 nodes are available: 1 No preemption victims found for incoming pod, 5 Preemption is not helpful for scheduling."
0.3903,Event,ADDED,eval-conflicts-rho040-r1-087-xbmfv.18d52f789749f1f3,"reason=FailedScheduling count=None msg=0/6 nodes are available: 1 c_wall violated: 1 conflicting context pair(s) with node memory, 5 node(s) had untolerated taint(s). no new claims to deallocate, preemption: 0/6 nodes are available: 1 No preemption victims found for incoming pod, 5 Preemption is not helpful for scheduling."
0.3905,Event,ADDED,eval-conflicts-rho040-r1-087-xbmfv.18d52f78adf3a4da,"reason=FailedScheduling count=None msg=0/6 nodes are available: 2 c_wall violated: 1 conflicting context pair(s) with node memory, 4 node(s) had untolerated taint(s). no new claims to deallocate, preemption: 0/6 nodes are available: 2 No preemption victims found for incoming pod, 4 Preemption is not helpful for scheduling."
0.3907,Event,ADDED,eval-conflicts-rho040-r1-087-xbmfv.18d52f7be766ecfb,reason=Scheduled count=None msg=Successfully assigned compute/eval-conflicts-rho040-r1-087-xbmfv to kind-worker4
0.3909,Event,ADDED,eval-conflicts-rho040-r1-087-xbmfv.18d52f7c0e3cd5bb,"reason=Pulled count=1 msg=Container image ""busybox:musl"" already present on machine"
0.391,Event,ADDED,eval-conflicts-rho040-r1-087-xbmfv.18d52f7c0faea14f,reason=Created count=1 msg=Created container: task
0.3912,Event,ADDED,eval-conflicts-rho040-r1-087-xbmfv.18d52f7c1346b0f9,reason=Started count=1 msg=Started container task
0.3914,Event,ADDED,eval-conflicts-rho040-r1-087.18d52f7893679ec0,reason=SuccessfulCreate count=1 msg=Created pod: eval-conflicts-rho040-r1-087-xbmfv
0.3915,Event,ADDED,eval-conflicts-rho040-r1-087.18d52f81594dbc12,reason=Completed count=1 msg=Job completed
0.3917,Event,ADDED,eval-conflicts-rho040-r1-088-mhpks.18d52f78d1b366c2,reason=Scheduled count=None msg=Successfully assigned compute/eval-conflicts-rho040-r1-088-mhpks to kind-worker2
0.3919,Event,ADDED,eval-conflicts-rho040-r1-088-mhpks.18d52f78e9c2be0f,"reason=Pulled count=1 msg=Container image ""busybox:musl"" already present on machine"
0.392,Event,ADDED,eval-conflicts-rho040-r1-088-mhpks.18d52f78eadaef68,reason=Created count=1 msg=Created container: task
0.3922,Event,ADDED,eval-conflicts-rho040-r1-088-mhpks.18d52f78eebafdf9,reason=Started count=1 msg=Started container task
0.3924,Event,ADDED,eval-conflicts-rho040-r1-088.18d52f78cd75f62f,reason=SuccessfulCreate count=1 msg=Created pod: eval-conflicts-rho040-r1-088-mhpks
0.3925,Event,ADDED,eval-conflicts-rho040-r1-088.18d52f7edb1f72d8,reason=Completed count=1 msg=Job completed
0.3927,Event,ADDED,eval-conflicts-rho040-r1-089-qhq8j.18d52f790aaff1d4,"reason=FailedScheduling count=None msg=0/6 nodes are available: 1 c_wall violated: 1 conflicting context pair(s) with node memory, 1 c_wall violated: 2 conflicting context pair(s) with node memory, 4 node(s) had untolerated taint(s). no new claims to deallocate, preemption: 0/6 nodes are available: 2 No preemption victims found for incoming pod, 4 Preemption is not helpful for scheduling."
0.3929,Event,ADDED,eval-conflicts-rho040-r1-089-qhq8j.18d52f790b4e7b4b,"reason=FailedScheduling count=None msg=0/6 nodes are available: 1 c_wall violated: 1 conflicting context pair(s) with node memory, 1 c_wall violated: 2 conflicting context pair(s) with node memory, 4 node(s) had untolerated taint(s). no new claims to deallocate, preemption: 0/6 nodes are available: 2 No preemption victims found for incoming pod, 4 Preemption is not helpful for scheduling."
0.393,Event,ADDED,eval-conflicts-rho040-r1-089-qhq8j.18d52f7bccd7632d,reason=Scheduled count=None msg=Successfully assigned compute/eval-conflicts-rho040-r1-089-qhq8j to kind-worker4
0.3932,Event,ADDED,eval-conflicts-rho040-r1-089-qhq8j.18d52f7be7943390,"reason=Pulled count=1 msg=Container image ""busybox:musl"" already present on machine"
0.3934,Event,ADDED,eval-conflicts-rho040-r1-089-qhq8j.18d52f7be9f2348f,reason=Created count=1 msg=Created container: task
0.3936,Event,ADDED,eval-conflicts-rho040-r1-089-qhq8j.18d52f7bee4cb306,reason=Started count=1 msg=Started container task
0.3937,Event,ADDED,eval-conflicts-rho040-r1-089.18d52f790a1ea332,reason=SuccessfulCreate count=1 msg=Created pod: eval-conflicts-rho040-r1-089-qhq8j
0.3939,Event,ADDED,eval-conflicts-rho040-r1-089.18d52f82073c4a1a,reason=Completed count=1 msg=Job completed
0.394,Event,ADDED,eval-conflicts-rho040-r1-090-jwzqf.18d52f7945aee419,reason=Scheduled count=None msg=Successfully assigned compute/eval-conflicts-rho040-r1-090-jwzqf to kind-worker3
0.3942,Event,ADDED,eval-conflicts-rho040-r1-090-jwzqf.18d52f795fde0854,"reason=Pulled count=1 msg=Container image ""busybox:musl"" already present on machine"
0.3944,Event,ADDED,eval-conflicts-rho040-r1-090-jwzqf.18d52f7963052c24,reason=Created count=1 msg=Created container: task
0.3945,Event,ADDED,eval-conflicts-rho040-r1-090-jwzqf.18d52f796803ab26,reason=Started count=1 msg=Started container task
0.3947,Event,ADDED,eval-conflicts-rho040-r1-090.18d52f7944f7fe3e,reason=SuccessfulCreate count=1 msg=Created pod: eval-conflicts-rho040-r1-090-jwzqf
0.395,Event,ADDED,eval-conflicts-rho040-r1-090.18d52f7eff7ed4cf,reason=Completed count=1 msg=Job completed
0.3952,Event,ADDED,eval-conflicts-rho040-r1-091-7bcpv.18d52f79819d8ee0,reason=Scheduled count=None msg=Successfully assigned compute/eval-conflicts-rho040-r1-091-7bcpv to kind-worker2
0.3954,Event,ADDED,eval-conflicts-rho040-r1-091-7bcpv.18d52f799fea4143,"reason=Pulled count=1 msg=Container image ""busybox:musl"" already present on machine"
0.3957,Event,ADDED,eval-conflicts-rho040-r1-091-7bcpv.18d52f79a1018f95,reason=Created count=1 msg=Created container: task
0.3959,Event,ADDED,eval-conflicts-rho040-r1-091-7bcpv.18d52f79a4eae984,reason=Started count=1 msg=Started container task
0.3962,Event,ADDED,eval-conflicts-rho040-r1-091.18d52f7980d8093a,reason=SuccessfulCreate count=1 msg=Created pod: eval-conflicts-rho040-r1-091-7bcpv
0.3964,Event,ADDED,eval-conflicts-rho040-r1-091.18d52f7f24200fbe,reason=Completed count=1 msg=Job completed
0.3966,Event,ADDED,eval-conflicts-rho040-r1-092-n2rw7.18d52f79c38322b6,reason=Scheduled count=None msg=Successfully assigned compute/eval-conflicts-rho040-r1-092-n2rw7 to kind-worker2
0.3968,Event,ADDED,eval-conflicts-rho040-r1-092-n2rw7.18d52f79dcfad47d,"reason=Pulled count=1 msg=Container image ""busybox:musl"" already present on machine"
0.397,Event,ADDED,eval-conflicts-rho040-r1-092-n2rw7.18d52f79de16193e,reason=Created count=1 msg=Created container: task
0.3972,Event,ADDED,eval-conflicts-rho040-r1-092-n2rw7.18d52f79e031ed17,reason=Started count=1 msg=Started container task
0.3975,Event,ADDED,eval-conflicts-rho040-r1-092.18d52f79bc3b28f8,reason=SuccessfulCreate count=1 msg=Created pod: eval-conflicts-rho040-r1-092-n2rw7
0.3977,Event,ADDED,eval-conflicts-rho040-r1-092.18d52f7f51bc5413,reason=Completed count=1 msg=Job completed
0.3979,Event,ADDED,eval-conflicts-rho040-r1-093-8r24c.18d52f79f8366857,"reason=FailedScheduling count=None msg=0/6 nodes are available: 2 c_wall violated: 1 conflicting context pair(s) with node memory, 4 node(s) had untolerated taint(s). no new claims to deallocate, preemption: 0/6 nodes are available: 2 No preemption victims found for incoming pod, 4 Preemption is not helpful for scheduling."
0.3984,Event,ADDED,eval-conflicts-rho040-r1-093-8r24c.18d52f79f8e35959,"reason=FailedScheduling count=None msg=0/6 nodes are available: 2 c_wall violated: 1 conflicting context pair(s) with node memory, 4 node(s) had untolerated taint(s). no new claims to deallocate, preemption: 0/6 nodes are available: 2 No preemption victims found for incoming pod, 4 Preemption is not helpful for scheduling."
0.3985,Event,ADDED,eval-conflicts-rho040-r1-093-8r24c.18d52f7bea8611fb,reason=Scheduled count=None msg=Successfully assigned compute/eval-conflicts-rho040-r1-093-8r24c to kind-worker4
0.3987,Event,ADDED,eval-conflicts-rho040-r1-093-8r24c.18d52f7c1036cb51,"reason=Pulled count=1 msg=Container image ""busybox:musl"" already present on machine"
0.399,Event,ADDED,eval-conflicts-rho040-r1-093-8r24c.18d52f7c125f692f,reason=Created count=1 msg=Created container: task
0.3992,Event,ADDED,eval-conflicts-rho040-r1-093-8r24c.18d52f7c1639762e,reason=Started count=1 msg=Started container task
0.3994,Event,ADDED,eval-conflicts-rho040-r1-093.18d52f79f7c5bc79,reason=SuccessfulCreate count=1 msg=Created pod: eval-conflicts-rho040-r1-093-8r24c
0.3996,Event,ADDED,eval-conflicts-rho040-r1-093.18d52f821465f16f,reason=Completed count=1 msg=Job completed
0.3999,Event,ADDED,eval-conflicts-rho040-r1-094-kbp8z.18d52f7a33a40592,"reason=FailedScheduling count=None msg=0/6 nodes are available: 2 c_wall violated: 1 conflicting context pair(s) with node memory, 4 node(s) had untolerated taint(s). no new claims to deallocate, preemption: 0/6 nodes are available: 2 No preemption victims found for incoming pod, 4 Preemption is not helpful for scheduling."
0.4001,Event,ADDED,eval-conflicts-rho040-r1-094-kbp8z.18d52f7a344d6a64,"reason=FailedScheduling count=None msg=0/6 nodes are available: 2 c_wall violated: 1 conflicting context pair(s) with node memory, 4 node(s) had untolerated taint(s). no new claims to deallocate, preemption: 0/6 nodes are available: 2 No preemption victims found for incoming pod, 4 Preemption is not helpful for scheduling."
0.4002,Event,ADDED,eval-conflicts-rho040-r1-094-kbp8z.18d52f7beb1942e6,reason=Scheduled count=None msg=Successfully assigned compute/eval-conflicts-rho040-r1-094-kbp8z to kind-worker4
0.4006,Event,ADDED,eval-conflicts-rho040-r1-094-kbp8z.18d52f7c1052748f,"reason=Pulled count=1 msg=Container image ""busybox:musl"" already present on machine"
0.4007,Event,ADDED,eval-conflicts-rho040-r1-094-kbp8z.18d52f7c1343eb8a,reason=Created count=1 msg=Created container: task
0.4009,Event,ADDED,eval-conflicts-rho040-r1-094-kbp8z.18d52f7c16b6867c,reason=Started count=1 msg=Started container task
0.4011,Event,ADDED,eval-conflicts-rho040-r1-094.18d52f7a333b5a70,reason=SuccessfulCreate count=1 msg=Created pod: eval-conflicts-rho040-r1-094-kbp8z
0.4013,Event,ADDED,eval-conflicts-rho040-r1-094.18d52f8159486fb3,reason=Completed count=1 msg=Job completed
0.4015,Event,ADDED,eval-conflicts-rho040-r1-095-2ddq4.18d52f7a709a7370,"reason=FailedScheduling count=None msg=0/6 nodes are available: 1 c_wall violated: 1 conflicting context pair(s) with node memory, 1 c_wall violated: 3 conflicting context pair(s) with node memory, 4 node(s) had untolerated taint(s). no new claims to deallocate, preemption: 0/6 nodes are available: 2 No preemption victims found for incoming pod, 4 Preemption is not helpful for scheduling."
0.4017,Event,ADDED,eval-conflicts-rho040-r1-095-2ddq4.18d52f7a729a72e7,"reason=FailedScheduling count=None msg=0/6 nodes are available: 1 c_wall violated: 1 conflicting context pair(s) with node memory, 1 c_wall violated: 3 conflicting context pair(s) with node memory, 4 node(s) had untolerated taint(s). no new claims to deallocate, preemption: 0/6 nodes are available: 2 No preemption victims found for incoming pod, 4 Preemption is not helpful for scheduling."
0.4018,Event,ADDED,eval-conflicts-rho040-r1-095-2ddq4.18d52f7bf0bc73ee,reason=Scheduled count=None msg=Successfully assigned compute/eval-conflicts-rho040-r1-095-2ddq4 to kind-worker4
0.402,Event,ADDED,eval-conflicts-rho040-r1-095-2ddq4.18d52f7c108aaa37,"reason=Pulled count=1 msg=Container image ""busybox:musl"" already present on machine"
0.4022,Event,ADDED,eval-conflicts-rho040-r1-095-2ddq4.18d52f7c13438ba9,reason=Created count=1 msg=Created container: task
0.4026,Event,ADDED,eval-conflicts-rho040-r1-095-2ddq4.18d52f7c16b6be19,reason=Started count=1 msg=Started container task
0.4028,Event,ADDED,eval-conflicts-rho040-r1-095.18d52f7a70254b2e,reason=SuccessfulCreate count=1 msg=Created pod: eval-conflicts-rho040-r1-095-2ddq4
0.403,Event,ADDED,eval-conflicts-rho040-r1-095.18d52f82073af45a,reason=Completed count=1 msg=Job completed
0.4031,Event,ADDED,eval-conflicts-rho040-r1-096-kn8f8.18d52f7aab68cbbd,reason=Scheduled count=None msg=Successfully assigned compute/eval-conflicts-rho040-r1-096-kn8f8 to kind-worker2
0.4035,Event,ADDED,eval-conflicts-rho040-r1-096-kn8f8.18d52f7ac5c398cf,"reason=Pulled count=1 msg=Container image ""busybox:musl"" already present on machine"
0.4036,Event,ADDED,eval-conflicts-rho040-r1-096-kn8f8.18d52f7ac6e3a3cf,reason=Created count=1 msg=Created container: task
0.4038,Event,ADDED,eval-conflicts-rho040-r1-096-kn8f8.18d52f7aca866e9a,reason=Started count=1 msg=Started container task
0.404,Event,ADDED,eval-conflicts-rho040-r1-096.18d52f7aaac5c5be,reason=SuccessfulCreate count=1 msg=Created pod: eval-conflicts-rho040-r1-096-kn8f8
0.4043,Event,ADDED,eval-conflicts-rho040-r1-096.18d52f803b2722be,reason=Completed count=1 msg=Job completed
0.4045,Event,ADDED,eval-conflicts-rho040-r1-097-q5s8r.18d52f7ae9cbf25f,"reason=FailedScheduling count=None msg=0/6 nodes are available: 2 c_wall violated: 1 conflicting context pair(s) with node memory, 4 node(s) had untolerated taint(s). no new claims to deallocate, preemption: 0/6 nodes are available: 2 No preemption victims found for incoming pod, 4 Preemption is not helpful for scheduling."
0.4047,Event,ADDED,eval-conflicts-rho040-r1-097-q5s8r.18d52f7aec3c091d,"reason=FailedScheduling count=None msg=0/6 nodes are available: 2 c_wall violated: 1 conflicting context pair(s) with node memory, 4 node(s) had untolerated taint(s). no new claims to deallocate, preemption: 0/6 nodes are available: 2 No preemption victims found for incoming pod, 4 Preemption is not helpful for scheduling."
0.4049,Event,ADDED,eval-conflicts-rho040-r1-097-q5s8r.18d52f7bcd42c0b1,reason=Scheduled count=None msg=Successfully assigned compute/eval-conflicts-rho040-r1-097-q5s8r to kind-worker4
0.4051,Event,ADDED,eval-conflicts-rho040-r1-097-q5s8r.18d52f7be7e96106,"reason=Pulled count=1 msg=Container image ""busybox:musl"" already present on machine"
0.4053,Event,ADDED,eval-conflicts-rho040-r1-097-q5s8r.18d52f7bea839616,reason=Created count=1 msg=Created container: task
0.4055,Event,ADDED,eval-conflicts-rho040-r1-097-q5s8r.18d52f7bee4cab73,reason=Started count=1 msg=Started container task
0.4056,Event,ADDED,eval-conflicts-rho040-r1-097.18d52f7ae6525d1e,reason=SuccessfulCreate count=1 msg=Created pod: eval-conflicts-rho040-r1-097-q5s8r
0.4058,Event,ADDED,eval-conflicts-rho040-r1-097.18d52f8163ef7c93,reason=Completed count=1 msg=Job completed
0.4059,Event,ADDED,eval-conflicts-rho040-r1-098-nb2f8.18d52f7b27581ee3,"reason=FailedScheduling count=None msg=0/6 nodes are available: 2 c_wall violated: 1 conflicting context pair(s) with node memory, 4 node(s) had untolerated taint(s). no new claims to deallocate, preemption: 0/6 nodes are available: 2 No preemption victims found for incoming pod, 4 Preemption is not helpful for scheduling."
0.4063,Event,ADDED,eval-conflicts-rho040-r1-098-nb2f8.18d52f7b2b6ffe61,"reason=FailedScheduling count=None msg=0/6 nodes are available: 2 c_wall violated: 1 conflicting context pair(s) with node memory, 4 node(s) had untolerated taint(s). no new claims to deallocate, preemption: 0/6 nodes are available: 2 No preemption victims found for incoming pod, 4 Preemption is not helpful for scheduling."
0.4065,Event,ADDED,eval-conflicts-rho040-r1-098-nb2f8.18d52f7bf6058070,"reason=FailedScheduling count=None msg=0/6 nodes are available: 1 c_wall violated: 2 conflicting context pair(s) with node memory, 2 c_wall violated: 1 conflicting context pair(s) with node memory, 3 node(s) had untolerated taint(s). no new claims to deallocate, preemption: 0/6 nodes are available: 3 No preemption victims found for incoming pod, 3 Preemption is not helpful for scheduling."
0.4068,Event,ADDED,eval-conflicts-rho040-r1-098-nb2f8.18d52f7bfc386cfc,"reason=FailedScheduling count=None msg=0/6 nodes are available: 1 c_wall violated: 2 conflicting context pair(s) with node memory, 2 c_wall violated: 1 conflicting context pair(s) with node memory, 3 node(s) had untolerated taint(s). no new claims to deallocate, preemption: 0/6 nodes are available: 3 No preemption victims found for incoming pod, 3 Preemption is not helpful for scheduling."
0.407,Event,ADDED,eval-conflicts-rho040-r1-098-nb2f8.18d52f7c2c60dee7,reason=Scheduled count=None msg=Successfully assigned compute/eval-conflicts-rho040-r1-098-nb2f8 to kind-worker
0.4072,Event,ADDED,eval-conflicts-rho040-r1-098-nb2f8.18d52f7c4a239a14,"reason=Pulled count=1 msg=Container image ""busybox:musl"" already present on machine"
0.4073,Event,ADDED,eval-conflicts-rho040-r1-098-nb2f8.18d52f7c4b5710fc,reason=Created count=1 msg=Created container: task
0.4078,Event,ADDED,eval-conflicts-rho040-r1-098-nb2f8.18d52f7c4faf23d3,reason=Started count=1 msg=Started container task
0.408,Event,ADDED,eval-conflicts-rho040-r1-098.18d52f7b26fa16f2,reason=SuccessfulCreate count=1 msg=Created pod: eval-conflicts-rho040-r1-098-nb2f8
0.4082,Event,ADDED,eval-conflicts-rho040-r1-098.18d52f8225c08408,reason=Completed count=1 msg=Job completed
0.4083,Event,ADDED,eval-conflicts-rho040-r1-099-gplln.18d52f7b5f0fd797,"reason=FailedScheduling count=None msg=0/6 nodes are available: 1 c_wall violated: 1 conflicting context pair(s) with node memory, 1 c_wall violated: 2 conflicting context pair(s) with node memory, 4 node(s) had untolerated taint(s). no new claims to deallocate, preemption: 0/6 nodes are available: 2 No preemption victims found for incoming pod, 4 Preemption is not helpful for scheduling."
0.4087,Event,ADDED,eval-conflicts-rho040-r1-099-gplln.18d52f7b5fc3b255,"reason=FailedScheduling count=None msg=0/6 nodes are available: 1 c_wall violated: 1 conflicting context pair(s) with node memory, 1 c_wall violated: 2 conflicting context pair(s) with node memory, 4 node(s) had untolerated taint(s). no new claims to deallocate, preemption: 0/6 nodes are available: 2 No preemption victims found for incoming pod, 4 Preemption is not helpful for scheduling."
0.4089,Event,ADDED,eval-conflicts-rho040-r1-099-gplln.18d52f7bd67c5272,reason=Scheduled count=None msg=Successfully assigned compute/eval-conflicts-rho040-r1-099-gplln to kind-worker4
0.4091,Event,ADDED,eval-conflicts-rho040-r1-099-gplln.18d52f7bf015c217,"reason=Pulled count=1 msg=Container image ""busybox:musl"" already present on machine"
0.4093,Event,ADDED,eval-conflicts-rho040-r1-099-gplln.18d52f7bf15cf813,reason=Created count=1 msg=Created container: task
0.4095,Event,ADDED,eval-conflicts-rho040-r1-099-gplln.18d52f7bf918633b,reason=Started count=1 msg=Started container task
0.4097,Event,ADDED,eval-conflicts-rho040-r1-099.18d52f7b5ea9cd62,reason=SuccessfulCreate count=1 msg=Created pod: eval-conflicts-rho040-r1-099-gplln
0.41,Event,ADDED,eval-conflicts-rho040-r1-099.18d52f81f7c4ce48,reason=Completed count=1 msg=Job completed
0.4102,Event,ADDED,eval-conflicts-rho040-r1-100-jd5xr.18d52f7ba0dcec9c,"reason=FailedScheduling count=None msg=0/6 nodes are available: 1 c_wall violated: 1 conflicting context pair(s) with node memory, 1 c_wall violated: 3 conflicting context pair(s) with node memory, 4 node(s) had untolerated taint(s). no new claims to deallocate, preemption: 0/6 nodes are available: 2 No preemption victims found for incoming pod, 4 Preemption is not helpful for scheduling."
0.4104,Event,ADDED,eval-conflicts-rho040-r1-100-jd5xr.18d52f7ba2914b16,"reason=FailedScheduling count=None msg=0/6 nodes are available: 1 c_wall violated: 1 conflicting context pair(s) with node memory, 1 c_wall violated: 3 conflicting context pair(s) with node memory, 4 node(s) had untolerated taint(s). no new claims to deallocate, preemption: 0/6 nodes are available: 2 No preemption victims found for incoming pod, 4 Preemption is not helpful for scheduling."
0.4105,Event,ADDED,eval-conflicts-rho040-r1-100-jd5xr.18d52f7bdeba143d,reason=Scheduled count=None msg=Successfully assigned compute/eval-conflicts-rho040-r1-100-jd5xr to kind-worker4
0.4108,Event,ADDED,eval-conflicts-rho040-r1-100-jd5xr.18d52f7c05f4f3d1,"reason=Pulled count=1 msg=Container image ""busybox:musl"" already present on machine"
0.411,Event,ADDED,eval-conflicts-rho040-r1-100-jd5xr.18d52f7c0ac2787f,reason=Created count=1 msg=Created container: task
0.4113,Event,ADDED,eval-conflicts-rho040-r1-100-jd5xr.18d52f7c0f211aa3,reason=Started count=1 msg=Started container task
0.4116,Event,ADDED,eval-conflicts-rho040-r1-100.18d52f7b9fb5a252,reason=SuccessfulCreate count=1 msg=Created pod: eval-conflicts-rho040-r1-100-jd5xr
0.4118,Event,ADDED,eval-conflicts-rho040-r1-100.18d52f815ab3dd5f,reason=Completed count=1 msg=Job completed
0.412,Event,ADDED,eval-conflicts-rho040-r1-101-ksntl.18d52f7bdefbfd8a,reason=Scheduled count=None msg=Successfully assigned compute/eval-conflicts-rho040-r1-101-ksntl to kind-worker4
0.4122,Event,ADDED,eval-conflicts-rho040-r1-101-ksntl.18d52f7c0642e074,"reason=Pulled count=1 msg=Container image ""busybox:musl"" already present on machine"
0.4125,Event,ADDED,eval-conflicts-rho040-r1-101-ksntl.18d52f7c0b4f5cea,reason=Created count=1 msg=Created container: task
0.4127,Event,ADDED,eval-conflicts-rho040-r1-101-ksntl.18d52f7c0f211ab2,reason=Started count=1 msg=Started container task
0.4128,Event,ADDED,eval-conflicts-rho040-r1-101.18d52f7bd6a13173,reason=SuccessfulCreate count=1 msg=Created pod: eval-conflicts-rho040-r1-101-ksntl
0.4131,Event,ADDED,eval-conflicts-rho040-r1-101.18d52f81f7ebff95,reason=Completed count=1 msg=Job completed
0.4133,Event,ADDED,eval-conflicts-rho040-r1-102-f9w4g.18d52f7c12375688,reason=Scheduled count=None msg=Successfully assigned compute/eval-conflicts-rho040-r1-102-f9w4g to kind-worker4
0.4135,Event,ADDED,eval-conflicts-rho040-r1-102-f9w4g.18d52f7c2c506e55,"reason=Pulled count=1 msg=Container image ""busybox:musl"" already present on machine"
0.4137,Event,ADDED,eval-conflicts-rho040-r1-102-f9w4g.18d52f7c2d9ea978,reason=Created count=1 msg=Created container: task
0.4142,Event,ADDED,eval-conflicts-rho040-r1-102-f9w4g.18d52f7c33fa36b8,reason=Started count=1 msg=Started container task
0.4144,Event,ADDED,eval-conflicts-rho040-r1-102.18d52f7c10e01041,reason=SuccessfulCreate count=1 msg=Created pod: eval-conflicts-rho040-r1-102-f9w4g
0.4148,Event,ADDED,eval-conflicts-rho040-r1-102.18d52f81f7e9fe6b,reason=Completed count=1 msg=Job completed
0.415,Event,ADDED,eval-conflicts-rho040-r1-103-lfrwh.18d52f7c4d85bcf0,reason=Scheduled count=None msg=Successfully assigned compute/eval-conflicts-rho040-r1-103-lfrwh to kind-worker3
0.4153,Event,ADDED,eval-conflicts-rho040-r1-103-lfrwh.18d52f7c67a99b88,"reason=Pulled count=1 msg=Container image ""busybox:musl"" already present on machine"
0.4156,Event,ADDED,eval-conflicts-rho040-r1-103-lfrwh.18d52f7c68bd99d6,reason=Created count=1 msg=Created container: task
0.4158,Event,ADDED,eval-conflicts-rho040-r1-103-lfrwh.18d52f7c6d6f349b,reason=Started count=1 msg=Started container task
0.4161,Event,ADDED,eval-conflicts-rho040-r1-103.18d52f7c4bce3c3b,reason=SuccessfulCreate count=1 msg=Created pod: eval-conflicts-rho040-r1-103-lfrwh
0.4163,Event,ADDED,eval-conflicts-rho040-r1-103.18d52f8225c110b1,reason=Completed count=1 msg=Job completed
0.4165,Event,ADDED,eval-conflicts-rho040-r1-104-kzkhb.18d52f7c88ec5d30,reason=Scheduled count=None msg=Successfully assigned compute/eval-conflicts-rho040-r1-104-kzkhb to kind-worker
0.4166,Event,ADDED,eval-conflicts-rho040-r1-104-kzkhb.18d52f7ca3e1fc39,"reason=Pulled count=1 msg=Container image ""busybox:musl"" already present on machine"
0.4169,Event,ADDED,eval-conflicts-rho040-r1-104-kzkhb.18d52f7ca53fa836,reason=Created count=1 msg=Created container: task
0.417,Event,ADDED,eval-conflicts-rho040-r1-104-kzkhb.18d52f7ca8ee12aa,reason=Started count=1 msg=Started container task
0.4172,Event,ADDED,eval-conflicts-rho040-r1-104.18d52f7c8790bb5a,reason=SuccessfulCreate count=1 msg=Created pod: eval-conflicts-rho040-r1-104-kzkhb
0.4174,Event,ADDED,eval-conflicts-rho040-r1-104.18d52f822608b62b,reason=Completed count=1 msg=Job completed
0.4175,Event,ADDED,eval-conflicts-rho040-r1-105-zpm89.18d52f7cc74dd5df,reason=Scheduled count=None msg=Successfully assigned compute/eval-conflicts-rho040-r1-105-zpm89 to kind-worker
0.4177,Event,ADDED,eval-conflicts-rho040-r1-105-zpm89.18d52f7ce07b01f1,"reason=Pulled count=1 msg=Container image ""busybox:musl"" already present on machine"
0.4179,Event,ADDED,eval-conflicts-rho040-r1-105-zpm89.18d52f7ce1ae4546,reason=Created count=1 msg=Created container: task
0.4182,Event,ADDED,eval-conflicts-rho040-r1-105-zpm89.18d52f7ce718ed19,reason=Started count=1 msg=Started container task
0.4184,Event,ADDED,eval-conflicts-rho040-r1-105.18d52f7cc365f460,reason=SuccessfulCreate count=1 msg=Created pod: eval-conflicts-rho040-r1-105-zpm89
0.4186,Event,ADDED,eval-conflicts-rho040-r1-105.18d52f827263c6f8,reason=Completed count=1 msg=Job completed
0.4188,Event,ADDED,eval-conflicts-rho040-r1-106-jbxcn.18d52f7cffde47df,reason=Scheduled count=None msg=Successfully assigned compute/eval-conflicts-rho040-r1-106-jbxcn to kind-worker3
0.4191,Event,ADDED,eval-conflicts-rho040-r1-106-jbxcn.18d52f7d18cd8f49,"reason=Pulled count=1 msg=Container image ""busybox:musl"" already present on machine"
0.4193,Event,ADDED,eval-conflicts-rho040-r1-106-jbxcn.18d52f7d19fc5b20,reason=Created count=1 msg=Created container: task
0.4195,Event,ADDED,eval-conflicts-rho040-r1-106-jbxcn.18d52f7d1eb4f3ae,reason=Started count=1 msg=Started container task
0.4197,Event,ADDED,eval-conflicts-rho040-r1-106.18d52f7cfe9df1b6,reason=SuccessfulCreate count=1 msg=Created pod: eval-conflicts-rho040-r1-106-jbxcn
0.4199,Event,ADDED,eval-conflicts-rho040-r1-106.18d52f82a529a664,reason=Completed count=1 msg=Job completed
0.42,Event,ADDED,eval-conflicts-rho040-r1-107-lwtm5.18d52f7d3be121e7,reason=Scheduled count=None msg=Successfully assigned compute/eval-conflicts-rho040-r1-107-lwtm5 to kind-worker4
0.4202,Event,ADDED,eval-conflicts-rho040-r1-107-lwtm5.18d52f7d5a57f714,"reason=Pulled count=1 msg=Container image ""busybox:musl"" already present on machine"
0.4204,Event,ADDED,eval-conflicts-rho040-r1-107-lwtm5.18d52f7d5b9c7829,reason=Created count=1 msg=Created container: task
0.4205,Event,ADDED,eval-conflicts-rho040-r1-107-lwtm5.18d52f7d6b935292,reason=Started count=1 msg=Started container task
0.4207,Event,ADDED,eval-conflicts-rho040-r1-107.18d52f7d3accf46c,reason=SuccessfulCreate count=1 msg=Created pod: eval-conflicts-rho040-r1-107-lwtm5
0.4209,Event,ADDED,eval-conflicts-rho040-r1-107.18d52f82fdb6fe9f,reason=Completed count=1 msg=Job completed
0.421,Event,ADDED,eval-conflicts-rho040-r1-108-dmldc.18d52f7d767d6855,"reason=FailedScheduling count=None msg=0/6 nodes are available: 2 c_wall violated: 1 conflicting context pair(s) with node memory, 4 node(s) had untolerated taint(s). no new claims to deallocate, preemption: 0/6 nodes are available: 2 No preemption victims found for incoming pod, 4 Preemption is not helpful for scheduling."
0.4212,Event,ADDED,eval-conflicts-rho040-r1-108-dmldc.18d52f7d778ee3c1,"reason=FailedScheduling count=None msg=0/6 nodes are available: 2 c_wall violated: 1 conflicting context pair(s) with node memory, 4 node(s) had untolerated taint(s). no new claims to deallocate, preemption: 0/6 nodes are available: 2 No preemption victims found for incoming pod, 4 Preemption is not helpful for scheduling."
0.4214,Event,ADDED,eval-conflicts-rho040-r1-108-dmldc.18d52f80744db81a,"reason=FailedScheduling count=None msg=0/6 nodes are available: 1 c_wall violated: 1 conflicting context pair(s) with node memory, 5 node(s) had untolerated taint(s). no new claims to deallocate, preemption: 0/6 nodes are available: 1 No preemption victims found for incoming pod, 5 Preemption is not helpful for scheduling."
0.4216,Event,ADDED,eval-conflicts-rho040-r1-108-dmldc.18d52f80cecbcfea,reason=Scheduled count=None msg=Successfully assigned compute/eval-conflicts-rho040-r1-108-dmldc to kind-worker5
0.4217,Event,ADDED,eval-conflicts-rho040-r1-108-dmldc.18d52f80ecd7be75,"reason=Pulled count=1 msg=Container image ""busybox:musl"" already present on machine"
0.422,Event,ADDED,eval-conflicts-rho040-r1-108-dmldc.18d52f80f0dd5c3b,reason=Created count=1 msg=Created container: task
0.4223,Event,ADDED,eval-conflicts-rho040-r1-108-dmldc.18d52f80f59ac1a7,reason=Started count=1 msg=Started container task
0.4225,Event,ADDED,eval-conflicts-rho040-r1-108.18d52f7d76135542,reason=SuccessfulCreate count=1 msg=Created pod: eval-conflicts-rho040-r1-108-dmldc
0.4227,Event,ADDED,eval-conflicts-rho040-r1-108.18d52f8651e5ad2d,reason=Completed count=1 msg=Job completed
0.4229,Event,ADDED,eval-conflicts-rho040-r1-109-dddnv.18d52f7db8c04dd2,reason=Scheduled count=None msg=Successfully assigned compute/eval-conflicts-rho040-r1-109-dddnv to kind-worker4
0.4231,Event,ADDED,eval-conflicts-rho040-r1-109-dddnv.18d52f7dd7d14ef2,"reason=Pulled count=1 msg=Container image ""busybox:musl"" already present on machine"
0.4233,Event,ADDED,eval-conflicts-rho040-r1-109-dddnv.18d52f7dd9054373,reason=Created count=1 msg=Created container: task
0.4234,Event,ADDED,eval-conflicts-rho040-r1-109-dddnv.18d52f7ddd124759,reason=Started count=1 msg=Started container task
0.4236,Event,ADDED,eval-conflicts-rho040-r1-109.18d52f7db1a96bdc,reason=SuccessfulCreate count=1 msg=Created pod: eval-conflicts-rho040-r1-109-dddnv
0.4238,Event,ADDED,eval-conflicts-rho040-r1-109.18d52f837a59beb9,reason=Completed count=1 msg=Job completed
0.4239,Event,ADDED,eval-conflicts-rho040-r1-110-8xrwt.18d52f7deeb8d9d9,reason=Scheduled count=None msg=Successfully assigned compute/eval-conflicts-rho040-r1-110-8xrwt to kind-worker4
0.4241,Event,ADDED,eval-conflicts-rho040-r1-110-8xrwt.18d52f7e09633975,"reason=Pulled count=1 msg=Container image ""busybox:musl"" already present on machine"
0.4243,Event,ADDED,eval-conflicts-rho040-r1-110-8xrwt.18d52f7e0a8126fd,reason=Created count=1 msg=Created container: task
0.4244,Event,ADDED,eval-conflicts-rho040-r1-110-8xrwt.18d52f7e0eefaade,reason=Started count=1 msg=Started container task
0.4246,Event,ADDED,eval-conflicts-rho040-r1-110.18d52f7dee0eba9c,reason=SuccessfulCreate count=1 msg=Created pod: eval-conflicts-rho040-r1-110-8xrwt
0.4248,Event,ADDED,eval-conflicts-rho040-r1-110.18d52f83a57eb1d8,reason=Completed count=1 msg=Job completed
0.425,Event,ADDED,eval-conflicts-rho040-r1-111-gghxx.18d52f7e55a6a046,reason=Scheduled count=None msg=Successfully assigned compute/eval-conflicts-rho040-r1-111-gghxx to kind-worker4
0.4252,Event,ADDED,eval-conflicts-rho040-r1-111-gghxx.18d52f7e70d6ed43,"reason=Pulled count=1 msg=Container image ""busybox:musl"" already present on machine"
0.4254,Event,ADDED,eval-conflicts-rho040-r1-111-gghxx.18d52f7e727f86b7,reason=Created count=1 msg=Created container: task
0.4255,Event,ADDED,eval-conflicts-rho040-r1-111-gghxx.18d52f7e7a1a3d6c,reason=Started count=1 msg=Started container task
0.4257,Event,ADDED,eval-conflicts-rho040-r1-111.18d52f7e55155e7a,reason=SuccessfulCreate count=1 msg=Created pod: eval-conflicts-rho040-r1-111-gghxx
0.4259,Event,ADDED,eval-conflicts-rho040-r1-111.18d52f83e3b6a8bc,reason=Completed count=1 msg=Job completed
0.426,Event,ADDED,eval-conflicts-rho040-r1-112-rg5sq.18d52f7e8b4c75c4,reason=Scheduled count=None msg=Successfully assigned compute/eval-conflicts-rho040-r1-112-rg5sq to kind-worker4
0.4262,Event,ADDED,eval-conflicts-rho040-r1-112-rg5sq.18d52f7ea5b5f4bf,"reason=Pulled count=1 msg=Container image ""busybox:musl"" already present on machine"
0.4264,Event,ADDED,eval-conflicts-rho040-r1-112-rg5sq.18d52f7ea6f13e8e,reason=Created count=1 msg=Created container: task
0.4266,Event,ADDED,eval-conflicts-rho040-r1-112-rg5sq.18d52f7eac6cb953,reason=Started count=1 msg=Started container task
0.4269,Event,ADDED,eval-conflicts-rho040-r1-112.18d52f7e8abbc11f,reason=SuccessfulCreate count=1 msg=Created pod: eval-conflicts-rho040-r1-112-rg5sq
0.4272,Event,ADDED,eval-conflicts-rho040-r1-112.18d52f8423a00991,reason=Completed count=1 msg=Job completed
0.4274,Event,ADDED,eval-conflicts-rho040-r1-113-2qg6w.18d52f7eb2371655,"reason=FailedScheduling count=None msg=0/6 nodes are available: 1 c_wall violated: 2 conflicting context pair(s) with node memory, 1 c_wall violated: 3 conflicting context pair(s) with node memory, 4 node(s) had untolerated taint(s). no new claims to deallocate, preemption: 0/6 nodes are available: 2 No preemption victims found for incoming pod, 4 Preemption is not helpful for scheduling."
0.4277,Event,ADDED,eval-conflicts-rho040-r1-113-2qg6w.18d52f7eb2f565f0,"reason=FailedScheduling count=None msg=0/6 nodes are available: 1 c_wall violated: 2 conflicting context pair(s) with node memory, 1 c_wall violated: 3 conflicting context pair(s) with node memory, 4 node(s) had untolerated taint(s). no new claims to deallocate, preemption: 0/6 nodes are available: 2 No preemption victims found for incoming pod, 4 Preemption is not helpful for scheduling."
0.4279,Event,ADDED,eval-conflicts-rho040-r1-113-2qg6w.18d52f80747b87a8,"reason=FailedScheduling count=None msg=0/6 nodes are available: 1 c_wall violated: 2 conflicting context pair(s) with node memory, 5 node(s) had untolerated taint(s). no new claims to deallocate, preemption: 0/6 nodes are available: 1 No preemption victims found for incoming pod, 5 Preemption is not helpful for scheduling."
0.428,Event,ADDED,eval-conflicts-rho040-r1-113-2qg6w.18d52f80cf313e9b,reason=Scheduled count=None msg=Successfully assigned compute/eval-conflicts-rho040-r1-113-2qg6w to kind-worker5
0.4282,Event,ADDED,eval-conflicts-rho040-r1-113-2qg6w.18d52f80ecfe6158,"reason=Pulled count=1 msg=Container image ""busybox:musl"" already present on machine"
0.4284,Event,ADDED,eval-conflicts-rho040-r1-113-2qg6w.18d52f80f119ccb6,reason=Created count=1 msg=Created container: task
0.4286,Event,ADDED,eval-conflicts-rho040-r1-113-2qg6w.18d52f80f5b9baa9,reason=Started count=1 msg=Started container task
0.4288,Event,ADDED,eval-conflicts-rho040-r1-113.18d52f7eb1d61ed0,reason=SuccessfulCreate count=1 msg=Created pod: eval-conflicts-rho040-r1-113-2qg6w
0.429,Event,ADDED,eval-conflicts-rho040-r1-113.18d52f865166feee,reason=Completed count=1 msg=Job completed
0.4291,Event,ADDED,eval-conflicts-rho040-r1-114-pcqdf.18d52f7ee5fffdd5,reason=Scheduled count=None msg=Successfully assigned compute/eval-conflicts-rho040-r1-114-pcqdf to kind-worker4
0.4293,Event,ADDED,eval-conflicts-rho040-r1-114-pcqdf.18d52f7f01331b78,"reason=Pulled count=1 msg=Container image ""busybox:musl"" already present on machine"
0.4294,Event,ADDED,eval-conflicts-rho040-r1-114-pcqdf.18d52f7f02511528,reason=Created count=1 msg=Created container: task
0.4296,Event,ADDED,eval-conflicts-rho040-r1-114-pcqdf.18d52f7f08bd2d58,reason=Started count=1 msg=Started container task
0.4298,Event,ADDED,eval-conflicts-rho040-r1-114.18d52f7ee5482522,reason=SuccessfulCreate count=1 msg=Created pod: eval-conflicts-rho040-r1-114-pcqdf
0.4301,Event,ADDED,eval-conflicts-rho040-r1-114.18d52f84938df162,reason=Completed count=1 msg=Job completed
0.4302,Event,ADDED,eval-conflicts-rho040-r1-115-gzzzb.18d52f7f17f46f2a,reason=Scheduled count=None msg=Successfully assigned compute/eval-conflicts-rho040-r1-115-gzzzb to kind-worker
0.4305,Event,ADDED,eval-conflicts-rho040-r1-115-gzzzb.18d52f7f3320af9f,"reason=Pulled count=1 msg=Container image ""busybox:musl"" already present on machine"
0.4307,Event,ADDED,eval-conflicts-rho040-r1-115-gzzzb.18d52f7f3440500e,reason=Created count=1 msg=Created container: task
0.4309,Event,ADDED,eval-conflicts-rho040-r1-115-gzzzb.18d52f7f37abbc76,reason=Started count=1 msg=Started container task
0.4313,Event,ADDED,eval-conflicts-rho040-r1-115.18d52f7f174182bc,reason=SuccessfulCreate count=1 msg=Created pod: eval-conflicts-rho040-r1-115-gzzzb
0.4314,Event,ADDED,eval-conflicts-rho040-r1-115.18d52f84b8158c4b,reason=Completed count=1 msg=Job completed
0.4316,Event,ADDED,eval-conflicts-rho040-r1-116-46gxv.18d52f7f53b7c310,"reason=FailedScheduling count=None msg=0/6 nodes are available: 1 c_wall violated: 2 conflicting context pair(s) with node memory, 1 c_wall violated: 3 conflicting context pair(s) with node memory, 4 node(s) had untolerated taint(s). no new claims to deallocate, preemption: 0/6 nodes are available: 2 No preemption victims found for incoming pod, 4 Preemption is not helpful for scheduling."
0.4318,Event,ADDED,eval-conflicts-rho040-r1-116-46gxv.18d52f7f5480875c,"reason=FailedScheduling count=None msg=0/6 nodes are available: 1 c_wall violated: 2 conflicting context pair(s) with node memory, 1 c_wall violated: 3 conflicting context pair(s) with node memory, 4 node(s) had untolerated taint(s). no new claims to deallocate, preemption: 0/6 nodes are available: 2 No preemption victims found for incoming pod, 4 Preemption is not helpful for scheduling."
0.432,Event,ADDED,eval-conflicts-rho040-r1-116-46gxv.18d52f80729c24c8,"reason=FailedScheduling count=None msg=0/6 nodes are available: 1 c_wall violated: 2 conflicting context pair(s) with node memory, 5 node(s) had untolerated taint(s). no new claims to deallocate, preemption: 0/6 nodes are available: 1 No preemption victims found for incoming pod, 5 Preemption is not helpful for scheduling."
0.4322,Event,ADDED,eval-conflicts-rho040-r1-116-46gxv.18d52f80ce5ad625,reason=Scheduled count=None msg=Successfully assigned compute/eval-conflicts-rho040-r1-116-46gxv to kind-worker5
0.4324,Event,ADDED,eval-conflicts-rho040-r1-116-46gxv.18d52f80ecb97f65,"reason=Pulled count=1 msg=Container image ""busybox:musl"" already present on machine"
0.4325,Event,ADDED,eval-conflicts-rho040-r1-116-46gxv.18d52f80efe5e621,reason=Created count=1 msg=Created container: task
0.4327,Event,ADDED,eval-conflicts-rho040-r1-116-46gxv.18d52f80f50895dd,reason=Started count=1 msg=Started container task
0.4329,Event,ADDED,eval-conflicts-rho040-r1-116.18d52f7f5338e394,reason=SuccessfulCreate count=1 msg=Created pod: eval-conflicts-rho040-r1-116-46gxv
0.4333,Event,ADDED,eval-conflicts-rho040-r1-116.18d52f86519a39e1,reason=Completed count=1 msg=Job completed
0.4335,Event,ADDED,eval-conflicts-rho040-r1-117-qktfn.18d52f7f8f6accf5,reason=Scheduled count=None msg=Successfully assigned compute/eval-conflicts-rho040-r1-117-qktfn to kind-worker4
0.4337,Event,ADDED,eval-conflicts-rho040-r1-117-qktfn.18d52f7fac987f78,"reason=Pulled count=1 msg=Container image ""busybox:musl"" already present on machine"
0.4339,Event,ADDED,eval-conflicts-rho040-r1-117-qktfn.18d52f7fadb535ed,reason=Created count=1 msg=Created container: task
0.4343,Event,ADDED,eval-conflicts-rho040-r1-117-qktfn.18d52f7fb1ab6898,reason=Started count=1 msg=Started container task
0.4344,Event,ADDED,eval-conflicts-rho040-r1-117.18d52f7f8e9c84f7,reason=SuccessfulCreate count=1 msg=Created pod: eval-conflicts-rho040-r1-117-qktfn
0.4346,Event,ADDED,eval-conflicts-rho040-r1-117.18d52f8550ee569c,reason=Completed count=1 msg=Job completed
0.435,Event,ADDED,eval-conflicts-rho040-r1-118-l5ptq.18d52f7fcd873a79,"reason=FailedScheduling count=None msg=0/6 nodes are available: 2 c_wall violated: 1 conflicting context pair(s) with node memory, 4 node(s) had untolerated taint(s). no new claims to deallocate, preemption: 0/6 nodes are available: 2 No preemption victims found for incoming pod, 4 Preemption is not helpful for scheduling."
0.4353,Event,ADDED,eval-conflicts-rho040-r1-118-l5ptq.18d52f7fce77126e,"reason=FailedScheduling count=None msg=0/6 nodes are available: 2 c_wall violated: 1 conflicting context pair(s) with node memory, 4 node(s) had untolerated taint(s). no new claims to deallocate, preemption: 0/6 nodes are available: 2 No preemption victims found for incoming pod, 4 Preemption is not helpful for scheduling."
0.4355,Event,ADDED,eval-conflicts-rho040-r1-118-l5ptq.18d52f8074af147b,"reason=FailedScheduling count=None msg=0/6 nodes are available: 1 c_wall violated: 1 conflicting context pair(s) with node memory, 5 node(s) had untolerated taint(s). no new claims to deallocate, preemption: 0/6 nodes are available: 1 No preemption victims found for incoming pod, 5 Preemption is not helpful for scheduling."
0.4358,Event,ADDED,eval-conflicts-rho040-r1-118-l5ptq.18d52f80d42537f8,reason=Scheduled count=None msg=Successfully assigned compute/eval-conflicts-rho040-r1-118-l5ptq to kind-worker5
0.436,Event,ADDED,eval-conflicts-rho040-r1-118-l5ptq.18d52f80f6c8427f,"reason=Pulled count=1 msg=Container image ""busybox:musl"" already present on machine"
0.4362,Event,ADDED,eval-conflicts-rho040-r1-118-l5ptq.18d52f80f8d7ec5f,reason=Created count=1 msg=Created container: task
0.4364,Event,ADDED,eval-conflicts-rho040-r1-118-l5ptq.18d52f81072708ba,reason=Started count=1 msg=Started container task
0.4366,Event,ADDED,eval-conflicts-rho040-r1-118.18d52f7fc9ec3486,reason=SuccessfulCreate count=1 msg=Created pod: eval-conflicts-rho040-r1-118-l5ptq
0.4368,Event,ADDED,eval-conflicts-rho040-r1-118.18d52f865187c43c,reason=Completed count=1 msg=Job completed
0.437,Event,ADDED,eval-conflicts-rho040-r1-119-47c9n.18d52f80061ef2fc,"reason=FailedScheduling count=None msg=0/6 nodes are available: 2 c_wall violated: 1 conflicting context pair(s) with node memory, 4 node(s) had untolerated taint(s). no new claims to deallocate, preemption: 0/6 nodes are available: 2 No preemption victims found for incoming pod, 4 Preemption is not helpful for scheduling."
0.4372,Event,ADDED,eval-conflicts-rho040-r1-119-47c9n.18d52f8006dd1655,"reason=FailedScheduling count=None msg=0/6 nodes are available: 2 c_wall violated: 1 conflicting context pair(s) with node memory, 4 node(s) had untolerated taint(s). no new claims to deallocate, preemption: 0/6 nodes are available: 2 No preemption victims found for incoming pod, 4 Preemption is not helpful for scheduling."
0.4374,Event,ADDED,eval-conflicts-rho040-r1-119-47c9n.18d52f8074d35081,"reason=FailedScheduling count=None msg=0/6 nodes are available: 1 c_wall violated: 1 conflicting context pair(s) with node memory, 5 node(s) had untolerated taint(s). no new claims to deallocate, preemption: 0/6 nodes are available: 1 No preemption victims found for incoming pod, 5 Preemption is not helpful for scheduling."
0.4375,Event,ADDED,eval-conflicts-rho040-r1-119-47c9n.18d52f80d4a920aa,reason=Scheduled count=None msg=Successfully assigned compute/eval-conflicts-rho040-r1-119-47c9n to kind-worker5
0.4377,Event,ADDED,eval-conflicts-rho040-r1-119-47c9n.18d52f80f6e5ecc5,"reason=Pulled count=1 msg=Container image ""busybox:musl"" already present on machine"
0.438,Event,ADDED,eval-conflicts-rho040-r1-119-47c9n.18d52f80f91d4a4f,reason=Created count=1 msg=Created container: task
0.4383,Event,ADDED,eval-conflicts-rho040-r1-119-47c9n.18d52f81072764dc,reason=Started count=1 msg=Started container task
0.4385,Event,ADDED,eval-conflicts-rho040-r1-119.18d52f8005b5de2d,reason=SuccessfulCreate count=1 msg=Created pod: eval-conflicts-rho040-r1-119-47c9n
0.4388,Event,ADDED,eval-conflicts-rho040-r1-119.18d52f86524d536f,reason=Completed count=1 msg=Job completed
0.439,Event,ADDED,eval-conflicts-rho040-r1-120-bz758.18d52f80444c79e5,"reason=FailedScheduling count=None msg=0/6 nodes are available: 1 c_wall violated: 2 conflicting context pair(s) with node memory, 1 c_wall violated: 3 conflicting context pair(s) with node memory, 4 node(s) had untolerated taint(s). no new claims to deallocate, preemption: 0/6 nodes are available: 2 No preemption victims found for incoming pod, 4 Preemption is not helpful for scheduling."
0.4392,Event,ADDED,eval-conflicts-rho040-r1-120-bz758.18d52f80456459a8,"reason=FailedScheduling count=None msg=0/6 nodes are available: 1 c_wall violated: 2 conflicting context pair(s) with node memory, 1 c_wall violated: 3 conflicting context pair(s) with node memory, 4 node(s) had untolerated taint(s). no new claims to deallocate, preemption: 0/6 nodes are available: 2 No preemption victims found for incoming pod, 4 Preemption is not helpful for scheduling."
0.4395,Event,ADDED,eval-conflicts-rho040-r1-120-bz758.18d52f8074f6b67f,"reason=FailedScheduling count=None msg=0/6 nodes are available: 1 c_wall violated: 2 conflicting context pair(s) with node memory, 5 node(s) had untolerated taint(s). no new claims to deallocate, preemption: 0/6 nodes are available: 1 No preemption victims found for incoming pod, 5 Preemption is not helpful for scheduling."
0.4397,Event,ADDED,eval-conflicts-rho040-r1-120-bz758.18d52f80d4c9d515,reason=Scheduled count=None msg=Successfully assigned compute/eval-conflicts-rho040-r1-120-bz758 to kind-worker5
0.4399,Event,ADDED,eval-conflicts-rho040-r1-120-bz758.18d52f80f6a62672,"reason=Pulled count=1 msg=Container image ""busybox:musl"" already present on machine"
0.4402,Event,ADDED,eval-conflicts-rho040-r1-120-bz758.18d52f80f874eae8,reason=Created count=1 msg=Created container: task
0.4404,Event,ADDED,eval-conflicts-rho040-r1-120-bz758.18d52f810727bdf3,reason=Started count=1 msg=Started container task
0.4406,Event,ADDED,eval-conflicts-rho040-r1-120.18d52f8043cd9737,reason=SuccessfulCreate count=1 msg=Created pod: eval-conflicts-rho040-r1-120-bz758
0.4411,Event,ADDED,eval-conflicts-rho040-r1-120.18d52f8651102a11,reason=Completed count=1 msg=Job completed
0.4414,Event,ADDED,eval-conflicts-rho040-r1-121-svzbn.18d52f8086fa0bba,"reason=FailedScheduling count=None msg=0/6 nodes are available: 1 c_wall violated: 1 conflicting context pair(s) with node memory, 5 node(s) had untolerated taint(s). no new claims to deallocate, preemption: 0/6 nodes are available: 1 No preemption victims found for incoming pod, 5 Preemption is not helpful for scheduling."
0.4416,Event,ADDED,eval-conflicts-rho040-r1-121-svzbn.18d52f8087787ed6,"reason=FailedScheduling count=None msg=0/6 nodes are available: 1 c_wall violated: 1 conflicting context pair(s) with node memory, 5 node(s) had untolerated taint(s). no new claims to deallocate, preemption: 0/6 nodes are available: 1 No preemption victims found for incoming pod, 5 Preemption is not helpful for scheduling."
0.4418,Event,ADDED,eval-conflicts-rho040-r1-121-svzbn.18d52f8213063b37,reason=Scheduled count=None msg=Successfully assigned compute/eval-conflicts-rho040-r1-121-svzbn to kind-worker2
0.4421,Event,ADDED,eval-conflicts-rho040-r1-121-svzbn.18d52f82480ea199,"reason=Pulled count=1 msg=Container image ""busybox:musl"" already present on machine"
0.4423,Event,ADDED,eval-conflicts-rho040-r1-121-svzbn.18d52f82496530c2,reason=Created count=1 msg=Created container: task
0.4425,Event,ADDED,eval-conflicts-rho040-r1-121-svzbn.18d52f825846b9f2,reason=Started count=1 msg=Started container task
0.4426,Event,ADDED,eval-conflicts-rho040-r1-121.18d52f8086b87107,reason=SuccessfulCreate count=1 msg=Created pod: eval-conflicts-rho040-r1-121-svzbn
0.4429,Event,ADDED,eval-conflicts-rho040-r1-121.18d52f87bab337bf,reason=Completed count=1 msg=Job completed
0.4431,Event,ADDED,eval-conflicts-rho040-r1-122-4d7nt.18d52f80baf2c5ba,"reason=FailedScheduling count=None msg=0/6 nodes are available: 1 c_wall violated: 1 conflicting context pair(s) with node memory, 5 node(s) had untolerated taint(s). no new claims to deallocate, preemption: 0/6 nodes are available: 1 No preemption victims found for incoming pod, 5 Preemption is not helpful for scheduling."
0.4433,Event,ADDED,eval-conflicts-rho040-r1-122-4d7nt.18d52f80bb6beb99,"reason=FailedScheduling count=None msg=0/6 nodes are available: 1 c_wall violated: 1 conflicting context pair(s) with node memory, 5 node(s) had untolerated taint(s). no new claims to deallocate, preemption: 0/6 nodes are available: 1 No preemption victims found for incoming pod, 5 Preemption is not helpful for scheduling."
0.4435,Event,ADDED,eval-conflicts-rho040-r1-122-4d7nt.18d52f82133e9f37,reason=Scheduled count=None msg=Successfully assigned compute/eval-conflicts-rho040-r1-122-4d7nt to kind-worker2
0.4437,Event,ADDED,eval-conflicts-rho040-r1-122-4d7nt.18d52f824829de75,"reason=Pulled count=1 msg=Container image ""busybox:musl"" already present on machine"
0.4439,Event,ADDED,eval-conflicts-rho040-r1-122-4d7nt.18d52f8249d3f9c4,reason=Created count=1 msg=Created container: task
0.444,Event,ADDED,eval-conflicts-rho040-r1-122-4d7nt.18d52f8258467203,reason=Started count=1 msg=Started container task
0.4442,Event,ADDED,eval-conflicts-rho040-r1-122.18d52f80bab0de38,reason=SuccessfulCreate count=1 msg=Created pod: eval-conflicts-rho040-r1-122-4d7nt
0.4444,Event,ADDED,eval-conflicts-rho040-r1-122.18d52f87b9777601,reason=Completed count=1 msg=Job completed
0.4447,Event,ADDED,eval-conflicts-rho040-r1-123-hlzs5.18d52f80f49982fa,"reason=FailedScheduling count=None msg=0/6 nodes are available: 1 c_wall violated: 1 conflicting context pair(s) with node memory, 5 node(s) had untolerated taint(s). no new claims to deallocate, preemption: 0/6 nodes are available: 1 No preemption victims found for incoming pod, 5 Preemption is not helpful for scheduling."
0.4449,Event,ADDED,eval-conflicts-rho040-r1-123-hlzs5.18d52f80f5683eab,"reason=FailedScheduling count=None msg=0/6 nodes are available: 1 c_wall violated: 1 conflicting context pair(s) with node memory, 5 node(s) had untolerated taint(s). no new claims to deallocate, preemption: 0/6 nodes are available: 1 No preemption victims found for incoming pod, 5 Preemption is not helpful for scheduling."
0.445,Event,ADDED,eval-conflicts-rho040-r1-123-hlzs5.18d52f8215cdec23,"reason=FailedScheduling count=None msg=0/6 nodes are available: 1 c_wall violated: 1 conflicting context pair(s) with node memory, 1 c_wall violated: 2 conflicting context pair(s) with node memory, 4 node(s) had untolerated taint(s). no new claims to deallocate, preemption: 0/6 nodes are available: 2 No preemption victims found for incoming pod, 4 Preemption is not helpful for scheduling."
0.4452,Event,ADDED,eval-conflicts-rho040-r1-123-hlzs5.18d52f8216ac6729,"reason=FailedScheduling count=None msg=0/6 nodes are available: 1 c_wall violated: 1 conflicting context pair(s) with node memory, 1 c_wall violated: 2 conflicting context pair(s) with node memory, 4 node(s) had untolerated taint(s). no new claims to deallocate, preemption: 0/6 nodes are available: 2 No preemption victims found for incoming pod, 4 Preemption is not helpful for scheduling."
0.4457,Event,ADDED,eval-conflicts-rho040-r1-123-hlzs5.18d52f8550773257,reason=Scheduled count=None msg=Successfully assigned compute/eval-conflicts-rho040-r1-123-hlzs5 to kind-worker4
0.4459,Event,ADDED,eval-conflicts-rho040-r1-123-hlzs5.18d52f857411efc8,"reason=Pulled count=1 msg=Container image ""busybox:musl"" already present on machine"
0.4462,Event,ADDED,eval-conflicts-rho040-r1-123-hlzs5.18d52f85764971f0,reason=Created count=1 msg=Created container: task
0.4465,Event,ADDED,eval-conflicts-rho040-r1-123-hlzs5.18d52f857fae3b9b,reason=Started count=1 msg=Started container task
0.4467,Event,ADDED,eval-conflicts-rho040-r1-123.18d52f80f46408e5,reason=SuccessfulCreate count=1 msg=Created pod: eval-conflicts-rho040-r1-123-hlzs5
0.4469,Event,ADDED,eval-conflicts-rho040-r1-123.18d52f8ae3ed4d6a,reason=Completed count=1 msg=Job completed
0.4471,Event,ADDED,eval-conflicts-rho040-r1-124-n6b5f.18d52f8135eebc04,"reason=FailedScheduling count=None msg=0/6 nodes are available: 1 c_wall violated: 1 conflicting context pair(s) with node memory, 5 node(s) had untolerated taint(s). no new claims to deallocate, preemption: 0/6 nodes are available: 1 No preemption victims found for incoming pod, 5 Preemption is not helpful for scheduling."
0.4474,Event,ADDED,eval-conflicts-rho040-r1-124-n6b5f.18d52f8136776467,"reason=FailedScheduling count=None msg=0/6 nodes are available: 1 c_wall violated: 1 conflicting context pair(s) with node memory, 5 node(s) had untolerated taint(s). no new claims to deallocate, preemption: 0/6 nodes are available: 1 No preemption victims found for incoming pod, 5 Preemption is not helpful for scheduling."
0.4476,Event,ADDED,eval-conflicts-rho040-r1-124-n6b5f.18d52f821664f23e,"reason=FailedScheduling count=None msg=0/6 nodes are available: 1 c_wall violated: 1 conflicting context pair(s) with node memory, 1 c_wall violated: 2 conflicting context pair(s) with node memory, 4 node(s) had untolerated taint(s). no new claims to deallocate, preemption: 0/6 nodes are available: 2 No preemption victims found for incoming pod, 4 Preemption is not helpful for scheduling."
0.4477,Event,ADDED,eval-conflicts-rho040-r1-124-n6b5f.18d52f855042f8de,reason=Scheduled count=None msg=Successfully assigned compute/eval-conflicts-rho040-r1-124-n6b5f to kind-worker4
0.448,Event,ADDED,eval-conflicts-rho040-r1-124-n6b5f.18d52f8573f32499,"reason=Pulled count=1 msg=Container image ""busybox:musl"" already present on machine"
0.4482,Event,ADDED,eval-conflicts-rho040-r1-124-n6b5f.18d52f8576cfaa31,reason=Created count=1 msg=Created container: task
0.4484,Event,ADDED,eval-conflicts-rho040-r1-124-n6b5f.18d52f857fa9e7fc,reason=Started count=1 msg=Started container task
0.4486,Event,ADDED,eval-conflicts-rho040-r1-124.18d52f8135b00a52,reason=SuccessfulCreate count=1 msg=Created pod: eval-conflicts-rho040-r1-124-n6b5f
0.4488,Event,ADDED,eval-conflicts-rho040-r1-124.18d52f8ae3cb1d8d,reason=Completed count=1 msg=Job completed
0.449,Event,ADDED,eval-conflicts-rho040-r1-125-8fp54.18d52f818e58243b,"reason=FailedScheduling count=None msg=0/6 nodes are available: 1 c_wall violated: 1 conflicting context pair(s) with node memory, 5 node(s) had untolerated taint(s). no new claims to deallocate, preemption: 0/6 nodes are available: 1 No preemption victims found for incoming pod, 5 Preemption is not helpful for scheduling."
0.4492,Event,ADDED,eval-conflicts-rho040-r1-125-8fp54.18d52f818edcf5c3,"reason=FailedScheduling count=None msg=0/6 nodes are available: 1 c_wall violated: 1 conflicting context pair(s) with node memory, 5 node(s) had untolerated taint(s). no new claims to deallocate, preemption: 0/6 nodes are available: 1 No preemption victims found for incoming pod, 5 Preemption is not helpful for scheduling."
0.4493,Event,ADDED,eval-conflicts-rho040-r1-125-8fp54.18d52f8207cb6db8,reason=Scheduled count=None msg=Successfully assigned compute/eval-conflicts-rho040-r1-125-8fp54 to kind-worker2
0.4495,Event,ADDED,eval-conflicts-rho040-r1-125-8fp54.18d52f8234e804b9,"reason=Pulled count=1 msg=Container image ""busybox:musl"" already present on machine"
0.4496,Event,ADDED,eval-conflicts-rho040-r1-125-8fp54.18d52f823708bc43,reason=Created count=1 msg=Created container: task
0.4498,Event,ADDED,eval-conflicts-rho040-r1-125-8fp54.18d52f823f0bcdd2,reason=Started count=1 msg=Started container task
0.4501,Event,ADDED,eval-conflicts-rho040-r1-125.18d52f818e16f46b,reason=SuccessfulCreate count=1 msg=Created pod: eval-conflicts-rho040-r1-125-8fp54
0.4503,Event,ADDED,eval-conflicts-rho040-r1-125.18d52f87bb1602af,reason=Completed count=1 msg=Job completed
0.4504,Event,ADDED,eval-conflicts-rho040-r1-126-6bbbv.18d52f81d6bc03f7,"reason=FailedScheduling count=None msg=0/6 nodes are available: 1 c_wall violated: 1 conflicting context pair(s) with node memory, 5 node(s) had untolerated taint(s). no new claims to deallocate, preemption: 0/6 nodes are available: 1 No preemption victims found for incoming pod, 5 Preemption is not helpful for scheduling."
0.4507,Event,ADDED,eval-conflicts-rho040-r1-126-6bbbv.18d52f81d7316523,"reason=FailedScheduling count=None msg=0/6 nodes are available: 1 c_wall violated: 1 conflicting context pair(s) with node memory, 5 node(s) had untolerated taint(s). no new claims to deallocate, preemption: 0/6 nodes are available: 1 No preemption victims found for incoming pod, 5 Preemption is not helpful for scheduling."
0.4508,Event,ADDED,eval-conflicts-rho040-r1-126-6bbbv.18d52f8208b1bb5b,reason=Scheduled count=None msg=Successfully assigned compute/eval-conflicts-rho040-r1-126-6bbbv to kind-worker2
0.451,Event,ADDED,eval-conflicts-rho040-r1-126-6bbbv.18d52f8234febf73,"reason=Pulled count=1 msg=Container image ""busybox:musl"" already present on machine"
0.4512,Event,ADDED,eval-conflicts-rho040-r1-126-6bbbv.18d52f8237288f1d,reason=Created count=1 msg=Created container: task
0.4514,Event,ADDED,eval-conflicts-rho040-r1-126-6bbbv.18d52f823f088681,reason=Started count=1 msg=Started container task
0.4516,Event,ADDED,eval-conflicts-rho040-r1-126.18d52f81d67ceb51,reason=SuccessfulCreate count=1 msg=Created pod: eval-conflicts-rho040-r1-126-6bbbv
0.4517,Event,ADDED,eval-conflicts-rho040-r1-126.18d52f87ba67b90d,reason=Completed count=1 msg=Job completed
0.4519,Event,ADDED,eval-conflicts-rho040-r1-127-rvvzl.18d52f8208319156,reason=Scheduled count=None msg=Successfully assigned compute/eval-conflicts-rho040-r1-127-rvvzl to kind-worker2
0.4522,Event,ADDED,eval-conflicts-rho040-r1-127-rvvzl.18d52f823528b37c,"reason=Pulled count=1 msg=Container image ""busybox:musl"" already present on machine"
0.4524,Event,ADDED,eval-conflicts-rho040-r1-127-rvvzl.18d52f8237abc983,reason=Created count=1 msg=Created container: task
0.4528,Event,ADDED,eval-conflicts-rho040-r1-127-rvvzl.18d52f823f0b0432,reason=Started count=1 msg=Started container task
0.453,Event,ADDED,eval-conflicts-rho040-r1-127.18d52f820739cec8,reason=SuccessfulCreate count=1 msg=Created pod: eval-conflicts-rho040-r1-127-rvvzl
0.4532,Event,ADDED,eval-conflicts-rho040-r1-127.18d52f87bb8bbad8,reason=Completed count=1 msg=Job completed
0.4533,Event,ADDED,eval-conflicts-rho040-r1-128-l8956.18d52f8235b98fdf,"reason=FailedScheduling count=None msg=0/6 nodes are available: 1 c_wall violated: 1 conflicting context pair(s) with node memory, 1 c_wall violated: 2 conflicting context pair(s) with node memory, 4 node(s) had untolerated taint(s). no new claims to deallocate, preemption: 0/6 nodes are available: 2 No preemption victims found for incoming pod, 4 Preemption is not helpful for scheduling."
0.4536,Event,ADDED,eval-conflicts-rho040-r1-128-l8956.18d52f82395ca1a9,"reason=FailedScheduling count=None msg=0/6 nodes are available: 1 c_wall violated: 1 conflicting context pair(s) with node memory, 1 c_wall violated: 2 conflicting context pair(s) with node memory, 4 node(s) had untolerated taint(s). no new claims to deallocate, preemption: 0/6 nodes are available: 2 No preemption victims found for incoming pod, 4 Preemption is not helpful for scheduling."
0.4538,Event,ADDED,eval-conflicts-rho040-r1-128-l8956.18d52f856368dc83,reason=Scheduled count=None msg=Successfully assigned compute/eval-conflicts-rho040-r1-128-l8956 to kind-worker4
0.454,Event,ADDED,eval-conflicts-rho040-r1-128-l8956.18d52f858a990f5b,"reason=Pulled count=1 msg=Container image ""busybox:musl"" already present on machine"
0.4543,Event,ADDED,eval-conflicts-rho040-r1-128-l8956.18d52f858bef1fe6,reason=Created count=1 msg=Created container: task
0.4545,Event,ADDED,eval-conflicts-rho040-r1-128-l8956.18d52f85958983d9,reason=Started count=1 msg=Started container task
0.4546,Event,ADDED,eval-conflicts-rho040-r1-128.18d52f82354ee6d7,reason=SuccessfulCreate count=1 msg=Created pod: eval-conflicts-rho040-r1-128-l8956
0.4549,Event,ADDED,eval-conflicts-rho040-r1-128.18d52f8ae5a9d52c,reason=Completed count=1 msg=Job completed
0.455,Event,ADDED,eval-conflicts-rho040-r1-129-5tww4.18d52f82631f4953,reason=Scheduled count=None msg=Successfully assigned compute/eval-conflicts-rho040-r1-129-5tww4 to kind-worker2
0.4552,Event,ADDED,eval-conflicts-rho040-r1-129-5tww4.18d52f82865fe38e,"reason=Pulled count=1 msg=Container image ""busybox:musl"" already present on machine"
0.4554,Event,ADDED,eval-conflicts-rho040-r1-129-5tww4.18d52f8287f76488,reason=Created count=1 msg=Created container: task
0.4556,Event,ADDED,eval-conflicts-rho040-r1-129-5tww4.18d52f829231a6a7,reason=Started count=1 msg=Started container task
0.4557,Event,ADDED,eval-conflicts-rho040-r1-129.18d52f8259d10237,reason=SuccessfulCreate count=1 msg=Created pod: eval-conflicts-rho040-r1-129-5tww4
0.4559,Event,ADDED,eval-conflicts-rho040-r1-129.18d52f87f983667c,reason=Completed count=1 msg=Job completed
0.456,Event,ADDED,eval-conflicts-rho040-r1-130-g62x5.18d52f8295cdeef2,reason=Scheduled count=None msg=Successfully assigned compute/eval-conflicts-rho040-r1-130-g62x5 to kind-worker2
0.4613,Event,ADDED,eval-conflicts-rho040-r1-130-g62x5.18d52f82b518a9bc,"reason=Pulled count=1 msg=Container image ""busybox:musl"" already present on machine"
0.4615,Event,ADDED,eval-conflicts-rho040-r1-130-g62x5.18d52f82b6e4ea7f,reason=Created count=1 msg=Created container: task
0.4617,Event,ADDED,eval-conflicts-rho040-r1-130-g62x5.18d52f82bfc16f95,reason=Started count=1 msg=Started container task
0.462,Event,ADDED,eval-conflicts-rho040-r1-130.18d52f8294f86d03,reason=SuccessfulCreate count=1 msg=Created pod: eval-conflicts-rho040-r1-130-g62x5
0.4623,Event,ADDED,eval-conflicts-rho040-r1-130.18d52f883974c026,reason=Completed count=1 msg=Job completed
0.4625,Event,ADDED,eval-conflicts-rho040-r1-131-n7xjt.18d52f82e8604742,reason=Scheduled count=None msg=Successfully assigned compute/eval-conflicts-rho040-r1-131-n7xjt to kind-worker2
0.4628,Event,ADDED,eval-conflicts-rho040-r1-131-n7xjt.18d52f830b470e02,"reason=Pulled count=1 msg=Container image ""busybox:musl"" already present on machine"
0.4631,Event,ADDED,eval-conflicts-rho040-r1-131-n7xjt.18d52f830c83a590,reason=Created count=1 msg=Created container: task
0.4634,Event,ADDED,eval-conflicts-rho040-r1-131-n7xjt.18d52f831bed6f54,reason=Started count=1 msg=Started container task
0.4636,Event,ADDED,eval-conflicts-rho040-r1-131.18d52f82da1a81fd,reason=SuccessfulCreate count=1 msg=Created pod: eval-conflicts-rho040-r1-131-n7xjt
0.4638,Event,ADDED,eval-conflicts-rho040-r1-131.18d52f88b351a1ce,reason=Completed count=1 msg=Job completed
0.464,Event,ADDED,eval-conflicts-rho040-r1-132-txdd7.18d52f830d54746d,"reason=FailedScheduling count=None msg=0/6 nodes are available: 1 c_wall violated: 1 conflicting context pair(s) with node memory, 1 c_wall violated: 2 conflicting context pair(s) with node memory, 4 node(s) had untolerated taint(s). no new claims to deallocate, preemption: 0/6 nodes are available: 2 No preemption victims found for incoming pod, 4 Preemption is not helpful for scheduling."
0.4642,Event,ADDED,eval-conflicts-rho040-r1-132-txdd7.18d52f830dfe7e28,"reason=FailedScheduling count=None msg=0/6 nodes are available: 1 c_wall violated: 1 conflicting context pair(s) with node memory, 1 c_wall violated: 2 conflicting context pair(s) with node memory, 4 node(s) had untolerated taint(s). no new claims to deallocate, preemption: 0/6 nodes are available: 2 No preemption victims found for incoming pod, 4 Preemption is not helpful for scheduling."
0.4644,Event,ADDED,eval-conflicts-rho040-r1-132-txdd7.18d52f8559d76649,reason=Scheduled count=None msg=Successfully assigned compute/eval-conflicts-rho040-r1-132-txdd7 to kind-worker4
0.4646,Event,ADDED,eval-conflicts-rho040-r1-132-txdd7.18d52f857fb1ef4f,"reason=Pulled count=1 msg=Container image ""busybox:musl"" already present on machine"
0.4647,Event,ADDED,eval-conflicts-rho040-r1-132-txdd7.18d52f8581e5fc1f,reason=Created count=1 msg=Created container: task
0.4649,Event,ADDED,eval-conflicts-rho040-r1-132-txdd7.18d52f858a91b7a6,reason=Started count=1 msg=Started container task
0.4651,Event,ADDED,eval-conflicts-rho040-r1-132.18d52f830cd86a04,reason=SuccessfulCreate count=1 msg=Created pod: eval-conflicts-rho040-r1-132-txdd7
0.4653,Event,ADDED,eval-conflicts-rho040-r1-132.18d52f8b201a7cbb,reason=Completed count=1 msg=Job completed
0.4655,Event,ADDED,eval-conflicts-rho040-r1-133-qs9ms.18d52f834c062664,reason=Scheduled count=None msg=Successfully assigned compute/eval-conflicts-rho040-r1-133-qs9ms to kind-worker2
0.4656,Event,ADDED,eval-conflicts-rho040-r1-133-qs9ms.18d52f837140631b,"reason=Pulled count=1 msg=Container image ""busybox:musl"" already present on machine"
0.4658,Event,ADDED,eval-conflicts-rho040-r1-133-qs9ms.18d52f83727c307f,reason=Created count=1 msg=Created container: task
0.4661,Event,ADDED,eval-conflicts-rho040-r1-133-qs9ms.18d52f837a0dfc55,reason=Started count=1 msg=Started container task
0.4662,Event,ADDED,eval-conflicts-rho040-r1-133.18d52f834973bc0a,reason=SuccessfulCreate count=1 msg=Created pod: eval-conflicts-rho040-r1-133-qs9ms
0.4665,Event,ADDED,eval-conflicts-rho040-r1-133.18d52f88efbfc5a1,reason=Completed count=1 msg=Job completed
0.4666,Event,ADDED,eval-conflicts-rho040-r1-134-22dh7.18d52f8390160fd3,reason=Scheduled count=None msg=Successfully assigned compute/eval-conflicts-rho040-r1-134-22dh7 to kind-worker2
0.4668,Event,ADDED,eval-conflicts-rho040-r1-134-22dh7.18d52f83be9e7542,"reason=Pulled count=1 msg=Container image ""busybox:musl"" already present on machine"
0.467,Event,ADDED,eval-conflicts-rho040-r1-134-22dh7.18d52f83bfd83282,reason=Created count=1 msg=Created container: task
0.4672,Event,ADDED,eval-conflicts-rho040-r1-134-22dh7.18d52f83cf8376fe,reason=Started count=1 msg=Started container task
0.4673,Event,ADDED,eval-conflicts-rho040-r1-134.18d52f83857df609,reason=SuccessfulCreate count=1 msg=Created pod: eval-conflicts-rho040-r1-134-22dh7
0.4675,Event,ADDED,eval-conflicts-rho040-r1-134.18d52f895ea31f93,reason=Completed count=1 msg=Job completed
0.4676,Event,ADDED,eval-conflicts-rho040-r1-135-tvjzx.18d52f83c116f854,reason=Scheduled count=None msg=Successfully assigned compute/eval-conflicts-rho040-r1-135-tvjzx to kind-worker5
0.4678,Event,ADDED,eval-conflicts-rho040-r1-135-tvjzx.18d52f83e338145a,"reason=Pulled count=1 msg=Container image ""busybox:musl"" already present on machine"
0.468,Event,ADDED,eval-conflicts-rho040-r1-135-tvjzx.18d52f83e4bc3946,reason=Created count=1 msg=Created container: task
0.4682,Event,ADDED,eval-conflicts-rho040-r1-135-tvjzx.18d52f83eba33e67,reason=Started count=1 msg=Started container task
0.4683,Event,ADDED,eval-conflicts-rho040-r1-135.18d52f83c06e8cc6,reason=SuccessfulCreate count=1 msg=Created pod: eval-conflicts-rho040-r1-135-tvjzx
0.4685,Event,ADDED,eval-conflicts-rho040-r1-135.18d52f8919f23bcd,reason=Completed count=1 msg=Job completed
0.4687,Event,ADDED,eval-conflicts-rho040-r1-136-6spmb.18d52f83fef359b5,reason=Scheduled count=None msg=Successfully assigned compute/eval-conflicts-rho040-r1-136-6spmb to kind-worker2
0.4689,Event,ADDED,eval-conflicts-rho040-r1-136-6spmb.18d52f841b4545c7,"reason=Pulled count=1 msg=Container image ""busybox:musl"" already present on machine"
0.4692,Event,ADDED,eval-conflicts-rho040-r1-136-6spmb.18d52f841c7d993e,reason=Created count=1 msg=Created container: task
0.4694,Event,ADDED,eval-conflicts-rho040-r1-136-6spmb.18d52f84237a9357,reason=Started count=1 msg=Started container task
0.4696,Event,ADDED,eval-conflicts-rho040-r1-136.18d52f83fab35d36,reason=SuccessfulCreate count=1 msg=Created pod: eval-conflicts-rho040-r1-136-6spmb
0.4698,Event,ADDED,eval-conflicts-rho040-r1-136.18d52f899a736b7f,reason=Completed count=1 msg=Job completed
0.4702,Event,ADDED,eval-conflicts-rho040-r1-137-j5ljk.18d52f8440c0c66f,reason=Scheduled count=None msg=Successfully assigned compute/eval-conflicts-rho040-r1-137-j5ljk to kind-worker5
0.4704,Event,ADDED,eval-conflicts-rho040-r1-137-j5ljk.18d52f8461749e51,"reason=Pulled count=1 msg=Container image ""busybox:musl"" already present on machine"
0.4706,Event,ADDED,eval-conflicts-rho040-r1-137-j5ljk.18d52f8462a4eafe,reason=Created count=1 msg=Created container: task
0.4709,Event,ADDED,eval-conflicts-rho040-r1-137-j5ljk.18d52f8469fc386d,reason=Started count=1 msg=Started container task
0.4711,Event,ADDED,eval-conflicts-rho040-r1-137.18d52f843d4f4143,reason=SuccessfulCreate count=1 msg=Created pod: eval-conflicts-rho040-r1-137-j5ljk
0.4713,Event,ADDED,eval-conflicts-rho040-r1-137.18d52f89933a4cc7,reason=Completed count=1 msg=Job completed
0.4714,Event,ADDED,eval-conflicts-rho040-r1-138-n4vn2.18d52f847380ebd4,"reason=FailedScheduling count=None msg=0/6 nodes are available: 1 c_wall violated: 1 conflicting context pair(s) with node memory, 1 c_wall violated: 2 conflicting context pair(s) with node memory, 4 node(s) had untolerated taint(s). no new claims to deallocate, preemption: 0/6 nodes are available: 2 No preemption victims found for incoming pod, 4 Preemption is not helpful for scheduling."
0.4718,Event,ADDED,eval-conflicts-rho040-r1-138-n4vn2.18d52f847429d038,"reason=FailedScheduling count=None msg=0/6 nodes are available: 1 c_wall violated: 1 conflicting context pair(s) with node memory, 1 c_wall violated: 2 conflicting context pair(s) with node memory, 4 node(s) had untolerated taint(s). no new claims to deallocate, preemption: 0/6 nodes are available: 2 No preemption victims found for incoming pod, 4 Preemption is not helpful for scheduling."
0.472,Event,ADDED,eval-conflicts-rho040-r1-138-n4vn2.18d52f856357dc95,"reason=FailedScheduling count=None msg=0/6 nodes are available: 1 c_wall violated: 2 conflicting context pair(s) with node memory, 2 c_wall violated: 1 conflicting context pair(s) with node memory, 3 node(s) had untolerated taint(s). no new claims to deallocate, preemption: 0/6 nodes are available: 3 No preemption victims found for incoming pod, 3 Preemption is not helpful for scheduling."
0.4725,Event,ADDED,eval-conflicts-rho040-r1-138-n4vn2.18d52f857ff32b3b,"reason=FailedScheduling count=None msg=0/6 nodes are available: 1 c_wall violated: 1 conflicting context pair(s) with node memory, 1 c_wall violated: 2 conflicting context pair(s) with node memory, 4 node(s) had untolerated taint(s). no new claims to deallocate, preemption: 0/6 nodes are available: 2 No preemption victims found for incoming pod, 4 Preemption is not helpful for scheduling."
0.4727,Event,ADDED,eval-conflicts-rho040-r1-138-n4vn2.18d52f859705740f,reason=Scheduled count=None msg=Successfully assigned compute/eval-conflicts-rho040-r1-138-n4vn2 to kind-worker
0.4729,Event,ADDED,eval-conflicts-rho040-r1-138-n4vn2.18d52f85b5e46482,"reason=Pulled count=1 msg=Container image ""busybox:musl"" already present on machine"
0.4731,Event,ADDED,eval-conflicts-rho040-r1-138-n4vn2.18d52f85b700d8fd,reason=Created count=1 msg=Created container: task
0.4734,Event,ADDED,eval-conflicts-rho040-r1-138-n4vn2.18d52f85bd2c6a61,reason=Started count=1 msg=Started container task
0.4736,Event,ADDED,eval-conflicts-rho040-r1-138.18d52f84730abdf0,reason=SuccessfulCreate count=1 msg=Created pod: eval-conflicts-rho040-r1-138-n4vn2
0.4738,Event,ADDED,eval-conflicts-rho040-r1-138.18d52f8b35c7adf3,reason=Completed count=1 msg=Job completed
0.4746,Event,ADDED,eval-conflicts-rho040-r1-139-dkwt9.18d52f84b018f7c3,"reason=FailedScheduling count=None msg=0/6 nodes are available: 1 c_wall violated: 1 conflicting context pair(s) with node memory, 1 c_wall violated: 2 conflicting context pair(s) with node memory, 4 node(s) had untolerated taint(s). no new claims to deallocate, preemption: 0/6 nodes are available: 2 No preemption victims found for incoming pod, 4 Preemption is not helpful for scheduling."
0.475,Event,ADDED,eval-conflicts-rho040-r1-139-dkwt9.18d52f84b0b7d325,"reason=FailedScheduling count=None msg=0/6 nodes are available: 1 c_wall violated: 1 conflicting context pair(s) with node memory, 1 c_wall violated: 2 conflicting context pair(s) with node memory, 4 node(s) had untolerated taint(s). no new claims to deallocate, preemption: 0/6 nodes are available: 2 No preemption victims found for incoming pod, 4 Preemption is not helpful for scheduling."
0.4754,Event,ADDED,eval-conflicts-rho040-r1-139-dkwt9.18d52f8559b44f3c,reason=Scheduled count=None msg=Successfully assigned compute/eval-conflicts-rho040-r1-139-dkwt9 to kind-worker4
0.4758,Event,ADDED,eval-conflicts-rho040-r1-139-dkwt9.18d52f857fad8eb8,"reason=Pulled count=1 msg=Container image ""busybox:musl"" already present on machine"
0.476,Event,ADDED,eval-conflicts-rho040-r1-139-dkwt9.18d52f8581b37aca,reason=Created count=1 msg=Created container: task
0.4762,Event,ADDED,eval-conflicts-rho040-r1-139-dkwt9.18d52f858a91eab0,reason=Started count=1 msg=Started container task
0.4763,Event,ADDED,eval-conflicts-rho040-r1-139.18d52f84af9c4976,reason=SuccessfulCreate count=1 msg=Created pod: eval-conflicts-rho040-r1-139-dkwt9
0.4767,Event,ADDED,eval-conflicts-rho040-r1-139.18d52f8b1ff05bdd,reason=Completed count=1 msg=Job completed
0.4768,Event,ADDED,eval-conflicts-rho040-r1-140-gskgx.18d52f84ece2ef4c,reason=Scheduled count=None msg=Successfully assigned compute/eval-conflicts-rho040-r1-140-gskgx to kind-worker2
0.477,Event,ADDED,eval-conflicts-rho040-r1-140-gskgx.18d52f851165f81a,"reason=Pulled count=1 msg=Container image ""busybox:musl"" already present on machine"
0.4772,Event,ADDED,eval-conflicts-rho040-r1-140-gskgx.18d52f8512a3eddd,reason=Created count=1 msg=Created container: task
0.4774,Event,ADDED,eval-conflicts-rho040-r1-140-gskgx.18d52f851be58d4d,reason=Started count=1 msg=Started container task
0.4776,Event,ADDED,eval-conflicts-rho040-r1-140.18d52f84ec3288d3,reason=SuccessfulCreate count=1 msg=Created pod: eval-conflicts-rho040-r1-140-gskgx
0.4778,Event,ADDED,eval-conflicts-rho040-r1-140.18d52f8a89ca225b,reason=Completed count=1 msg=Job completed
0.4782,Event,ADDED,eval-conflicts-rho040-r1-141-752cf.18d52f8525742b65,reason=Scheduled count=None msg=Successfully assigned compute/eval-conflicts-rho040-r1-141-752cf to kind-worker5
0.4784,Event,ADDED,eval-conflicts-rho040-r1-141-752cf.18d52f8545e608b2,"reason=Pulled count=1 msg=Container image ""busybox:musl"" already present on machine"
0.4786,Event,ADDED,eval-conflicts-rho040-r1-141-752cf.18d52f85473eb9e5,reason=Created count=1 msg=Created container: task
0.4788,Event,ADDED,eval-conflicts-rho040-r1-141-752cf.18d52f85501e7ba1,reason=Started count=1 msg=Started container task
0.4791,Event,ADDED,eval-conflicts-rho040-r1-141.18d52f8524d9ec50,reason=SuccessfulCreate count=1 msg=Created pod: eval-conflicts-rho040-r1-141-752cf
0.4793,Event,ADDED,eval-conflicts-rho040-r1-141.18d52f8a80423bc4,reason=Completed count=1 msg=Job completed
0.4795,Event,ADDED,eval-conflicts-rho040-r1-142-8vqrp.18d52f8573e3c6cb,reason=Scheduled count=None msg=Successfully assigned compute/eval-conflicts-rho040-r1-142-8vqrp to kind-worker4
0.4797,Event,ADDED,eval-conflicts-rho040-r1-142-8vqrp.18d52f85958efa8f,"reason=Pulled count=1 msg=Container image ""busybox:musl"" already present on machine"
0.48,Event,ADDED,eval-conflicts-rho040-r1-142-8vqrp.18d52f8596ec1e7d,reason=Created count=1 msg=Created container: task
0.4802,Event,ADDED,eval-conflicts-rho040-r1-142-8vqrp.18d52f85a27cd60c,reason=Started count=1 msg=Started container task
0.4804,Event,ADDED,eval-conflicts-rho040-r1-142.18d52f85655f3290,reason=SuccessfulCreate count=1 msg=Created pod: eval-conflicts-rho040-r1-142-8vqrp
0.4808,Event,ADDED,eval-conflicts-rho040-r1-142.18d52f8b20a6fde5,reason=Completed count=1 msg=Job completed
0.4809,Event,ADDED,eval-conflicts-rho040-r1-143-jl7mq.18d52f85a51322d9,reason=Scheduled count=None msg=Successfully assigned compute/eval-conflicts-rho040-r1-143-jl7mq to kind-worker
0.4811,Event,ADDED,eval-conflicts-rho040-r1-143-jl7mq.18d52f85c4f124d1,"reason=Pulled count=1 msg=Container image ""busybox:musl"" already present on machine"
0.4813,Event,ADDED,eval-conflicts-rho040-r1-143-jl7mq.18d52f85c619962c,reason=Created count=1 msg=Created container: task
0.4817,Event,ADDED,eval-conflicts-rho040-r1-143-jl7mq.18d52f85cb206b39,reason=Started count=1 msg=Started container task
0.4819,Event,ADDED,eval-conflicts-rho040-r1-143.18d52f85a3bd4404,reason=SuccessfulCreate count=1 msg=Created pod: eval-conflicts-rho040-r1-143-jl7mq
0.4821,Event,ADDED,eval-conflicts-rho040-r1-143.18d52f8afb0f07f8,reason=Completed count=1 msg=Job completed
0.4823,Event,ADDED,eval-conflicts-rho040-r1-144-274zb.18d52f85d9614117,reason=Scheduled count=None msg=Successfully assigned compute/eval-conflicts-rho040-r1-144-274zb to kind-worker
0.4826,Event,ADDED,eval-conflicts-rho040-r1-144-274zb.18d52f85f9b0e031,"reason=Pulled count=1 msg=Container image ""busybox:musl"" already present on machine"
0.4828,Event,ADDED,eval-conflicts-rho040-r1-144-274zb.18d52f85fb1fbad5,reason=Created count=1 msg=Created container: task
0.4829,Event,ADDED,eval-conflicts-rho040-r1-144-274zb.18d52f8600e57c71,reason=Started count=1 msg=Started container task
0.4833,Event,ADDED,eval-conflicts-rho040-r1-144.18d52f85d83e5989,reason=SuccessfulCreate count=1 msg=Created pod: eval-conflicts-rho040-r1-144-274zb
0.4835,Event,ADDED,eval-conflicts-rho040-r1-144.18d52f8b717487ca,reason=Completed count=1 msg=Job completed
0.4836,Event,ADDED,eval-conflicts-rho040-r1-145-s64d8.18d52f8617dff1cf,reason=Scheduled count=None msg=Successfully assigned compute/eval-conflicts-rho040-r1-145-s64d8 to kind-worker
0.4838,Event,ADDED,eval-conflicts-rho040-r1-145-s64d8.18d52f8636732a07,"reason=Pulled count=1 msg=Container image ""busybox:musl"" already present on machine"
0.4841,Event,ADDED,eval-conflicts-rho040-r1-145-s64d8.18d52f863785a42b,reason=Created count=1 msg=Created container: task
0.4844,Event,ADDED,eval-conflicts-rho040-r1-145-s64d8.18d52f863ff2f07d,reason=Started count=1 msg=Started container task
0.4845,Event,ADDED,eval-conflicts-rho040-r1-145.18d52f8616ad3fdd,reason=SuccessfulCreate count=1 msg=Created pod: eval-conflicts-rho040-r1-145-s64d8
0.4849,Event,ADDED,eval-conflicts-rho040-r1-145.18d52f8b720b5efc,reason=Completed count=1 msg=Job completed
0.4851,Event,ADDED,eval-conflicts-rho040-r1-146-flf4s.18d52f86531dfde5,reason=Scheduled count=None msg=Successfully assigned compute/eval-conflicts-rho040-r1-146-flf4s to kind-worker4
0.4853,Event,ADDED,eval-conflicts-rho040-r1-146-flf4s.18d52f8670c19fea,"reason=Pulled count=1 msg=Container image ""busybox:musl"" already present on machine"
0.4854,Event,ADDED,eval-conflicts-rho040-r1-146-flf4s.18d52f8671ef1cd3,reason=Created count=1 msg=Created container: task
0.4859,Event,ADDED,eval-conflicts-rho040-r1-146-flf4s.18d52f8676ea7126,reason=Started count=1 msg=Started container task
0.4863,Event,ADDED,eval-conflicts-rho040-r1-146.18d52f8651e416f3,reason=SuccessfulCreate count=1 msg=Created pod: eval-conflicts-rho040-r1-146-flf4s
0.4865,Event,ADDED,eval-conflicts-rho040-r1-146.18d52f8c107d076c,reason=Completed count=1 msg=Job completed
0.4866,Event,ADDED,eval-conflicts-rho040-r1-147-vfb86.18d52f868bab5c96,reason=Scheduled count=None msg=Successfully assigned compute/eval-conflicts-rho040-r1-147-vfb86 to kind-worker
0.487,Event,ADDED,eval-conflicts-rho040-r1-147-vfb86.18d52f86a7ae03e4,"reason=Pulled count=1 msg=Container image ""busybox:musl"" already present on machine"
0.4872,Event,ADDED,eval-conflicts-rho040-r1-147-vfb86.18d52f86a8cc91b2,reason=Created count=1 msg=Created container: task
0.4875,Event,ADDED,eval-conflicts-rho040-r1-147-vfb86.18d52f86b1329fb4,reason=Started count=1 msg=Started container task
0.4881,Event,ADDED,eval-conflicts-rho040-r1-147.18d52f868a996711,reason=SuccessfulCreate count=1 msg=Created pod: eval-conflicts-rho040-r1-147-vfb86
0.4885,Event,ADDED,eval-conflicts-rho040-r1-147.18d52f8bea0174cc,reason=Completed count=1 msg=Job completed
0.4887,Event,ADDED,eval-conflicts-rho040-r1-148-zn7ck.18d52f86c75da6fc,"reason=FailedScheduling count=None msg=0/6 nodes are available: 1 c_wall violated: 1 conflicting context pair(s) with node memory, 1 c_wall violated: 2 conflicting context pair(s) with node memory, 4 node(s) had untolerated taint(s). no new claims to deallocate, preemption: 0/6 nodes are available: 2 No preemption victims found for incoming pod, 4 Preemption is not helpful for scheduling."
0.489,Event,ADDED,eval-conflicts-rho040-r1-148-zn7ck.18d52f86c8043d89,"reason=FailedScheduling count=None msg=0/6 nodes are available: 1 c_wall violated: 1 conflicting context pair(s) with node memory, 1 c_wall violated: 2 conflicting context pair(s) with node memory, 4 node(s) had untolerated taint(s). no new claims to deallocate, preemption: 0/6 nodes are available: 2 No preemption victims found for incoming pod, 4 Preemption is not helpful for scheduling."
0.4891,Event,ADDED,eval-conflicts-rho040-r1-148-zn7ck.18d52f86d6966b51,reason=Scheduled count=None msg=Successfully assigned compute/eval-conflicts-rho040-r1-148-zn7ck to kind-worker3
0.4893,Event,ADDED,eval-conflicts-rho040-r1-148-zn7ck.18d52f86f38fd532,"reason=Pulled count=1 msg=Container image ""busybox:musl"" already present on machine"
0.4895,Event,ADDED,eval-conflicts-rho040-r1-148-zn7ck.18d52f86f4ac0ffb,reason=Created count=1 msg=Created container: task
0.4897,Event,ADDED,eval-conflicts-rho040-r1-148-zn7ck.18d52f86f6bd31b3,reason=Started count=1 msg=Started container task
0.4899,Event,ADDED,eval-conflicts-rho040-r1-148.18d52f86c6f46138,reason=SuccessfulCreate count=1 msg=Created pod: eval-conflicts-rho040-r1-148-zn7ck
0.4902,Event,ADDED,eval-conflicts-rho040-r1-148.18d52f8c6c509d6e,reason=Completed count=1 msg=Job completed
0.4905,Event,ADDED,eval-conflicts-rho040-r1-149-46h7t.18d52f8705b85560,"reason=FailedScheduling count=None msg=0/6 nodes are available: 1 c_wall violated: 2 conflicting context pair(s) with node memory, 2 c_wall violated: 1 conflicting context pair(s) with node memory, 3 node(s) had untolerated taint(s). no new claims to deallocate, preemption: 0/6 nodes are available: 3 No preemption victims found for incoming pod, 3 Preemption is not helpful for scheduling."
0.4907,Event,ADDED,eval-conflicts-rho040-r1-149-46h7t.18d52f870b3ff538,"reason=FailedScheduling count=None msg=0/6 nodes are available: 1 c_wall violated: 2 conflicting context pair(s) with node memory, 2 c_wall violated: 1 conflicting context pair(s) with node memory, 3 node(s) had untolerated taint(s). no new claims to deallocate, preemption: 0/6 nodes are available: 3 No preemption victims found for incoming pod, 3 Preemption is not helpful for scheduling."
0.4911,Event,ADDED,eval-conflicts-rho040-r1-149-46h7t.18d52f87812ced15,"reason=FailedScheduling count=None msg=0/6 nodes are available: 1 c_wall violated: 1 conflicting context pair(s) with node memory, 2 c_wall violated: 2 conflicting context pair(s) with node memory, 3 node(s) had untolerated taint(s). no new claims to deallocate, preemption: 0/6 nodes are available: 3 No preemption victims found for incoming pod, 3 Preemption is not helpful for scheduling."
0.4914,Event,ADDED,eval-conflicts-rho040-r1-149-46h7t.18d52f8a00103b29,"reason=FailedScheduling count=None msg=0/6 nodes are available: 1 c_wall violated: 1 conflicting context pair(s) with node memory, 1 c_wall violated: 2 conflicting context pair(s) with node memory, 4 node(s) had untolerated taint(s). no new claims to deallocate, preemption: 0/6 nodes are available: 2 No preemption victims found for incoming pod, 4 Preemption is not helpful for scheduling."
0.4918,Event,ADDED,eval-conflicts-rho040-r1-149-46h7t.18d52f8a46f1217c,"reason=FailedScheduling count=None msg=0/6 nodes are available: 1 c_wall violated: 2 conflicting context pair(s) with node memory, 5 node(s) had untolerated taint(s). no new claims to deallocate, preemption: 0/6 nodes are available: 1 No preemption victims found for incoming pod, 5 Preemption is not helpful for scheduling."
0.4919,Event,ADDED,eval-conflicts-rho040-r1-149-46h7t.18d52f8b8efe36dc,reason=Scheduled count=None msg=Successfully assigned compute/eval-conflicts-rho040-r1-149-46h7t to kind-worker2
0.4921,Event,ADDED,eval-conflicts-rho040-r1-149-46h7t.18d52f8bad654157,"reason=Pulled count=1 msg=Container image ""busybox:musl"" already present on machine"
0.4923,Event,ADDED,eval-conflicts-rho040-r1-149-46h7t.18d52f8bafc8ca65,reason=Created count=1 msg=Created container: task
0.4927,Event,ADDED,eval-conflicts-rho040-r1-149-46h7t.18d52f8bb2273bd1,reason=Started count=1 msg=Started container task
0.4929,Event,ADDED,eval-conflicts-rho040-r1-149.18d52f8704d568dd,reason=SuccessfulCreate count=1 msg=Created pod: eval-conflicts-rho040-r1-149-46h7t
0.4931,Event,ADDED,eval-conflicts-rho040-r1-149.18d52f9158349b4e,reason=Completed count=1 msg=Job completed
0.4932,Event,ADDED,eval-conflicts-rho040-r1-150-92g8q.18d52f873f58317f,reason=Scheduled count=None msg=Successfully assigned compute/eval-conflicts-rho040-r1-150-92g8q to kind-worker3
0.4936,Event,ADDED,eval-conflicts-rho040-r1-150-92g8q.18d52f875ef336d2,"reason=Pulled count=1 msg=Container image ""busybox:musl"" already present on machine"
0.4938,Event,ADDED,eval-conflicts-rho040-r1-150-92g8q.18d52f876008e582,reason=Created count=1 msg=Created container: task
0.494,Event,ADDED,eval-conflicts-rho040-r1-150-92g8q.18d52f876ac95b0f,reason=Started count=1 msg=Started container task
0.4943,Event,ADDED,eval-conflicts-rho040-r1-150.18d52f873e36c5d7,reason=SuccessfulCreate count=1 msg=Created pod: eval-conflicts-rho040-r1-150-92g8q
0.4945,Event,ADDED,eval-conflicts-rho040-r1-150.18d52f8ce6ad76c3,reason=Completed count=1 msg=Job completed
0.4947,Event,ADDED,eval-conflicts-rho040-r1-151-hkkzl.18d52f877b15acb8,reason=Scheduled count=None msg=Successfully assigned compute/eval-conflicts-rho040-r1-151-hkkzl to kind-worker3
0.4949,Event,ADDED,eval-conflicts-rho040-r1-151-hkkzl.18d52f8794430f51,"reason=Pulled count=1 msg=Container image ""busybox:musl"" already present on machine"
0.4953,Event,ADDED,eval-conflicts-rho040-r1-151-hkkzl.18d52f87955ab732,reason=Created count=1 msg=Created container: task
0.4955,Event,ADDED,eval-conflicts-rho040-r1-151-hkkzl.18d52f879c0de8e1,reason=Started count=1 msg=Started container task
0.4956,Event,ADDED,eval-conflicts-rho040-r1-151.18d52f8779eece31,reason=SuccessfulCreate count=1 msg=Created pod: eval-conflicts-rho040-r1-151-hkkzl
0.4959,Event,ADDED,eval-conflicts-rho040-r1-151.18d52f8d22aa5b8c,reason=Completed count=1 msg=Job completed
0.496,Event,ADDED,eval-conflicts-rho040-r1-152-zj6rp.18d52f87b7e898e0,reason=Scheduled count=None msg=Successfully assigned compute/eval-conflicts-rho040-r1-152-zj6rp to kind-worker4
0.4962,Event,ADDED,eval-conflicts-rho040-r1-152-zj6rp.18d52f87d14e3e10,"reason=Pulled count=1 msg=Container image ""busybox:musl"" already present on machine"
0.4964,Event,ADDED,eval-conflicts-rho040-r1-152-zj6rp.18d52f87d25b350e,reason=Created count=1 msg=Created container: task
0.4967,Event,ADDED,eval-conflicts-rho040-r1-152-zj6rp.18d52f87d434fdd2,reason=Started count=1 msg=Started container task
0.4969,Event,ADDED,eval-conflicts-rho040-r1-152.18d52f87b6c0fc9e,reason=SuccessfulCreate count=1 msg=Created pod: eval-conflicts-rho040-r1-152-zj6rp
0.4971,Event,ADDED,eval-conflicts-rho040-r1-152.18d52f8d3fd9b557,reason=Completed count=1 msg=Job completed
0.4972,Event,ADDED,eval-conflicts-rho040-r1-153-f9hq8.18d52f87f2dd4406,reason=Scheduled count=None msg=Successfully assigned compute/eval-conflicts-rho040-r1-153-f9hq8 to kind-worker3
0.4975,Event,ADDED,eval-conflicts-rho040-r1-153-f9hq8.18d52f880f3a8b7d,"reason=Pulled count=1 msg=Container image ""busybox:musl"" already present on machine"
0.4977,Event,ADDED,eval-conflicts-rho040-r1-153-f9hq8.18d52f881057dec3,reason=Created count=1 msg=Created container: task
0.498,Event,ADDED,eval-conflicts-rho040-r1-153-f9hq8.18d52f88172b66b8,reason=Started count=1 msg=Started container task
0.4983,Event,ADDED,eval-conflicts-rho040-r1-153.18d52f87f19ff6df,reason=SuccessfulCreate count=1 msg=Created pod: eval-conflicts-rho040-r1-153-f9hq8
0.4986,Event,ADDED,eval-conflicts-rho040-r1-153.18d52f8d9beb0118,reason=Completed count=1 msg=Job completed
0.4988,Event,ADDED,eval-conflicts-rho040-r1-154-pj5f2.18d52f88312e04b0,reason=Scheduled count=None msg=Successfully assigned compute/eval-conflicts-rho040-r1-154-pj5f2 to kind-worker
0.499,Event,ADDED,eval-conflicts-rho040-r1-154-pj5f2.18d52f88632d8c96,"reason=Pulled count=1 msg=Container image ""busybox:musl"" already present on machine"
0.4993,Event,ADDED,eval-conflicts-rho040-r1-154-pj5f2.18d52f886452632d,reason=Created count=1 msg=Created container: task
0.4994,Event,ADDED,eval-conflicts-rho040-r1-154-pj5f2.18d52f8868c2deea,reason=Started count=1 msg=Started container task
0.4997,Event,ADDED,eval-conflicts-rho040-r1-154.18d52f882fe14337,reason=SuccessfulCreate count=1 msg=Created pod: eval-conflicts-rho040-r1-154-pj5f2
0.4999,Event,ADDED,eval-conflicts-rho040-r1-154.18d52f8dd287fd51,reason=Completed count=1 msg=Job completed
0.5,Event,ADDED,eval-conflicts-rho040-r1-155-8r9fz.18d52f8868316c9b,reason=Scheduled count=None msg=Successfully assigned compute/eval-conflicts-rho040-r1-155-8r9fz to kind-worker3
0.5002,Event,ADDED,eval-conflicts-rho040-r1-155-8r9fz.18d52f888a0c8376,"reason=Pulled count=1 msg=Container image ""busybox:musl"" already present on machine"
0.5005,Event,ADDED,eval-conflicts-rho040-r1-155-8r9fz.18d52f888b1d85bb,reason=Created count=1 msg=Created container: task
0.501,Event,ADDED,eval-conflicts-rho040-r1-155-8r9fz.18d52f88979f3c60,reason=Started count=1 msg=Started container task
0.5012,Event,ADDED,eval-conflicts-rho040-r1-155.18d52f8867340ad1,reason=SuccessfulCreate count=1 msg=Created pod: eval-conflicts-rho040-r1-155-8r9fz
0.5013,Event,ADDED,eval-conflicts-rho040-r1-155.18d52f8e174f067f,reason=Completed count=1 msg=Job completed
0.5015,Event,ADDED,eval-conflicts-rho040-r1-156-6xc6s.18d52f88a9b77f31,reason=Scheduled count=None msg=Successfully assigned compute/eval-conflicts-rho040-r1-156-6xc6s to kind-worker3
0.5019,Event,ADDED,eval-conflicts-rho040-r1-156-6xc6s.18d52f88ca280557,"reason=Pulled count=1 msg=Container image ""busybox:musl"" already present on machine"
0.5021,Event,ADDED,eval-conflicts-rho040-r1-156-6xc6s.18d52f88cb5f56b1,reason=Created count=1 msg=Created container: task
0.5023,Event,ADDED,eval-conflicts-rho040-r1-156-6xc6s.18d52f88dbab1771,reason=Started count=1 msg=Started container task
0.5026,Event,ADDED,eval-conflicts-rho040-r1-156.18d52f88a2fd7e2e,reason=SuccessfulCreate count=1 msg=Created pod: eval-conflicts-rho040-r1-156-6xc6s
0.5028,Event,ADDED,eval-conflicts-rho040-r1-156.18d52f8e542d425a,reason=Completed count=1 msg=Job completed
0.503,Event,ADDED,eval-conflicts-rho040-r1-157-dwdfh.18d52f88df6fcfd8,"reason=FailedScheduling count=None msg=0/6 nodes are available: 3 c_wall violated: 2 conflicting context pair(s) with node memory, 3 node(s) had untolerated taint(s). no new claims to deallocate, preemption: 0/6 nodes are available: 3 No preemption victims found for incoming pod, 3 Preemption is not helpful for scheduling."
0.5032,Event,ADDED,eval-conflicts-rho040-r1-157-dwdfh.18d52f88e21de13f,"reason=FailedScheduling count=None msg=0/6 nodes are available: 3 c_wall violated: 2 conflicting context pair(s) with node memory, 3 node(s) had untolerated taint(s). no new claims to deallocate, preemption: 0/6 nodes are available: 3 No preemption victims found for incoming pod, 3 Preemption is not helpful for scheduling."
0.5035,Event,ADDED,eval-conflicts-rho040-r1-157-dwdfh.18d52f89e187d694,"reason=FailedScheduling count=None msg=0/6 nodes are available: 1 c_wall violated: 3 conflicting context pair(s) with node memory, 2 c_wall violated: 2 conflicting context pair(s) with node memory, 3 node(s) had untolerated taint(s). no new claims to deallocate, preemption: 0/6 nodes are available: 3 No preemption victims found for incoming pod, 3 Preemption is not helpful for scheduling."
0.5038,Event,ADDED,eval-conflicts-rho040-r1-157-dwdfh.18d52f8a0432334d,"reason=FailedScheduling count=None msg=0/6 nodes are available: 2 c_wall violated: 2 conflicting context pair(s) with node memory, 4 node(s) had untolerated taint(s). no new claims to deallocate, preemption: 0/6 nodes are available: 2 No preemption victims found for incoming pod, 4 Preemption is not helpful for scheduling."
0.5042,Event,ADDED,eval-conflicts-rho040-r1-157-dwdfh.18d52f8a42a051f6,"reason=FailedScheduling count=None msg=0/6 nodes are available: 1 c_wall violated: 2 conflicting context pair(s) with node memory, 5 node(s) had untolerated taint(s). no new claims to deallocate, preemption: 0/6 nodes are available: 1 No preemption victims found for incoming pod, 5 Preemption is not helpful for scheduling."
0.5046,Event,ADDED,eval-conflicts-rho040-r1-157-dwdfh.18d52f8b8e2dc976,reason=Scheduled count=None msg=Successfully assigned compute/eval-conflicts-rho040-r1-157-dwdfh to kind-worker2
0.5048,Event,ADDED,eval-conflicts-rho040-r1-157-dwdfh.18d52f8bad87582f,"reason=Pulled count=1 msg=Container image ""busybox:musl"" already present on machine"
0.5049,Event,ADDED,eval-conflicts-rho040-r1-157-dwdfh.18d52f8bb01d441d,reason=Created count=1 msg=Created container: task
0.5053,Event,ADDED,eval-conflicts-rho040-r1-157-dwdfh.18d52f8bb25f6bd3,reason=Started count=1 msg=Started container task
0.5055,Event,ADDED,eval-conflicts-rho040-r1-157.18d52f88de8e066e,reason=SuccessfulCreate count=1 msg=Created pod: eval-conflicts-rho040-r1-157-dwdfh
0.5057,Event,ADDED,eval-conflicts-rho040-r1-157.18d52f915885d189,reason=Completed count=1 msg=Job completed
0.5061,Event,ADDED,eval-conflicts-rho040-r1-158-wq8cz.18d52f891e2bc20e,"reason=FailedScheduling count=None msg=0/6 nodes are available: 3 c_wall violated: 2 conflicting context pair(s) with node memory, 3 node(s) had untolerated taint(s). no new claims to deallocate, preemption: 0/6 nodes are available: 3 No preemption victims found for incoming pod, 3 Preemption is not helpful for scheduling."
0.5063,Event,ADDED,eval-conflicts-rho040-r1-158-wq8cz.18d52f8923bf991b,"reason=FailedScheduling count=None msg=0/6 nodes are available: 3 c_wall violated: 2 conflicting context pair(s) with node memory, 3 node(s) had untolerated taint(s). no new claims to deallocate, preemption: 0/6 nodes are available: 3 No preemption victims found for incoming pod, 3 Preemption is not helpful for scheduling."
0.5065,Event,ADDED,eval-conflicts-rho040-r1-158-wq8cz.18d52f89e82718e7,"reason=FailedScheduling count=None msg=0/6 nodes are available: 1 c_wall violated: 3 conflicting context pair(s) with node memory, 2 c_wall violated: 2 conflicting context pair(s) with node memory, 3 node(s) had untolerated taint(s). no new claims to deallocate, preemption: 0/6 nodes are available: 3 No preemption victims found for incoming pod, 3 Preemption is not helpful for scheduling."
0.507,Event,ADDED,eval-conflicts-rho040-r1-158-wq8cz.18d52f8a004fc1c9,"reason=FailedScheduling count=None msg=0/6 nodes are available: 2 c_wall violated: 2 conflicting context pair(s) with node memory, 4 node(s) had untolerated taint(s). no new claims to deallocate, preemption: 0/6 nodes are available: 2 No preemption victims found for incoming pod, 4 Preemption is not helpful for scheduling."
0.5073,Event,ADDED,eval-conflicts-rho040-r1-158-wq8cz.18d52f8a47418710,"reason=FailedScheduling count=None msg=0/6 nodes are available: 1 c_wall violated: 2 conflicting context pair(s) with node memory, 5 node(s) had untolerated taint(s). no new claims to deallocate, preemption: 0/6 nodes are available: 1 No preemption victims found for incoming pod, 5 Preemption is not helpful for scheduling."
0.5075,Event,ADDED,eval-conflicts-rho040-r1-158-wq8cz.18d52f8b95d12b49,reason=Scheduled count=None msg=Successfully assigned compute/eval-conflicts-rho040-r1-158-wq8cz to kind-worker2
0.5079,Event,ADDED,eval-conflicts-rho040-r1-158-wq8cz.18d52f8bb2639cad,"reason=Pulled count=1 msg=Container image ""busybox:musl"" already present on machine"
0.5081,Event,ADDED,eval-conflicts-rho040-r1-158-wq8cz.18d52f8bb3c7dd41,reason=Created count=1 msg=Created container: task
0.5083,Event,ADDED,eval-conflicts-rho040-r1-158-wq8cz.18d52f8bb771fc45,reason=Started count=1 msg=Started container task
0.5085,Event,ADDED,eval-conflicts-rho040-r1-158.18d52f891ae7388c,reason=SuccessfulCreate count=1 msg=Created pod: eval-conflicts-rho040-r1-158-wq8cz
0.5088,Event,ADDED,eval-conflicts-rho040-r1-158.18d52f9158881e7d,reason=Completed count=1 msg=Job completed
0.509,Event,ADDED,eval-conflicts-rho040-r1-159-shzww.18d52f89570a1cc3,reason=Scheduled count=None msg=Successfully assigned compute/eval-conflicts-rho040-r1-159-shzww to kind-worker3
0.5092,Event,ADDED,eval-conflicts-rho040-r1-159-shzww.18d52f89744d3220,"reason=Pulled count=1 msg=Container image ""busybox:musl"" already present on machine"
0.5096,Event,ADDED,eval-conflicts-rho040-r1-159-shzww.18d52f8975757742,reason=Created count=1 msg=Created container: task
0.5099,Event,ADDED,eval-conflicts-rho040-r1-159-shzww.18d52f897c3ed191,reason=Started count=1 msg=Started container task
0.5101,Event,ADDED,eval-conflicts-rho040-r1-159.18d52f8955b9ec14,reason=SuccessfulCreate count=1 msg=Created pod: eval-conflicts-rho040-r1-159-shzww
0.5103,Event,ADDED,eval-conflicts-rho040-r1-159.18d52f8f08e236d4,reason=Completed count=1 msg=Job completed
0.5106,Event,ADDED,eval-conflicts-rho040-r1-160-46cbb.18d52f8994f1352e,"reason=FailedScheduling count=None msg=0/6 nodes are available: 3 c_wall violated: 2 conflicting context pair(s) with node memory, 3 node(s) had untolerated taint(s). no new claims to deallocate, preemption: 0/6 nodes are available: 3 No preemption victims found for incoming pod, 3 Preemption is not helpful for scheduling."
0.5109,Event,ADDED,eval-conflicts-rho040-r1-160-46cbb.18d52f8998c8a5f1,"reason=FailedScheduling count=None msg=0/6 nodes are available: 3 c_wall violated: 2 conflicting context pair(s) with node memory, 3 node(s) had untolerated taint(s). no new claims to deallocate, preemption: 0/6 nodes are available: 3 No preemption victims found for incoming pod, 3 Preemption is not helpful for scheduling."
0.5111,Event,ADDED,eval-conflicts-rho040-r1-160-46cbb.18d52f89ec478e7b,"reason=FailedScheduling count=None msg=0/6 nodes are available: 1 c_wall violated: 3 conflicting context pair(s) with node memory, 2 c_wall violated: 2 conflicting context pair(s) with node memory, 3 node(s) had untolerated taint(s). no new claims to deallocate, preemption: 0/6 nodes are available: 3 No preemption victims found for incoming pod, 3 Preemption is not helpful for scheduling."
0.5114,Event,ADDED,eval-conflicts-rho040-r1-160-46cbb.18d52f8a03f0ba69,"reason=FailedScheduling count=None msg=0/6 nodes are available: 2 c_wall violated: 2 conflicting context pair(s) with node memory, 4 node(s) had untolerated taint(s). no new claims to deallocate, preemption: 0/6 nodes are available: 2 No preemption victims found for incoming pod, 4 Preemption is not helpful for scheduling."
0.5117,Event,ADDED,eval-conflicts-rho040-r1-160-46cbb.18d52f8a4275fb16,"reason=FailedScheduling count=None msg=0/6 nodes are available: 1 c_wall violated: 2 conflicting context pair(s) with node memory, 5 node(s) had untolerated taint(s). no new claims to deallocate, preemption: 0/6 nodes are available: 1 No preemption victims found for incoming pod, 5 Preemption is not helpful for scheduling."
0.5118,Event,ADDED,eval-conflicts-rho040-r1-160-46cbb.18d52f8b8dc1a968,reason=Scheduled count=None msg=Successfully assigned compute/eval-conflicts-rho040-r1-160-46cbb to kind-worker2
0.5122,Event,ADDED,eval-conflicts-rho040-r1-160-46cbb.18d52f8bac8777f8,"reason=Pulled count=1 msg=Container image ""busybox:musl"" already present on machine"
0.5124,Event,ADDED,eval-conflicts-rho040-r1-160-46cbb.18d52f8bae6da561,reason=Created count=1 msg=Created container: task
0.5126,Event,ADDED,eval-conflicts-rho040-r1-160-46cbb.18d52f8bb0a804fe,reason=Started count=1 msg=Started container task
0.5128,Event,ADDED,eval-conflicts-rho040-r1-160.18d52f89942519d6,reason=SuccessfulCreate count=1 msg=Created pod: eval-conflicts-rho040-r1-160-46cbb
0.5136,Event,ADDED,eval-conflicts-rho040-r1-160.18d52f911948ed58,reason=Completed count=1 msg=Job completed
0.5138,Event,ADDED,eval-conflicts-rho040-r1-161-nj2tz.18d52f89cede593b,reason=Scheduled count=None msg=Successfully assigned compute/eval-conflicts-rho040-r1-161-nj2tz to kind-worker4
0.5141,Event,ADDED,eval-conflicts-rho040-r1-161-nj2tz.18d52f89e8c8cf2f,"reason=Pulled count=1 msg=Container image ""busybox:musl"" already present on machine"
0.5145,Event,ADDED,eval-conflicts-rho040-r1-161-nj2tz.18d52f89e9dc6d5f,reason=Created count=1 msg=Created container: task
0.5147,Event,ADDED,eval-conflicts-rho040-r1-161-nj2tz.18d52f89ebd48b2b,reason=Started count=1 msg=Started container task
0.5149,Event,ADDED,eval-conflicts-rho040-r1-161.18d52f89cddaec1e,reason=SuccessfulCreate count=1 msg=Created pod: eval-conflicts-rho040-r1-161-nj2tz
0.5151,Event,ADDED,eval-conflicts-rho040-r1-161.18d52f8f51c2526b,reason=Completed count=1 msg=Job completed
0.5154,Event,ADDED,eval-conflicts-rho040-r1-162-5pztq.18d52f8a0bfc67ed,"reason=FailedScheduling count=None msg=0/6 nodes are available: 1 c_wall violated: 1 conflicting context pair(s) with node memory, 1 c_wall violated: 2 conflicting context pair(s) with node memory, 4 node(s) had untolerated taint(s). no new claims to deallocate, preemption: 0/6 nodes are available: 2 No preemption victims found for incoming pod, 4 Preemption is not helpful for scheduling."
0.5156,Event,ADDED,eval-conflicts-rho040-r1-162-5pztq.18d52f8a10010a20,"reason=FailedScheduling count=None msg=0/6 nodes are available: 1 c_wall violated: 1 conflicting context pair(s) with node memory, 1 c_wall violated: 2 conflicting context pair(s) with node memory, 4 node(s) had untolerated taint(s). no new claims to deallocate, preemption: 0/6 nodes are available: 2 No preemption victims found for incoming pod, 4 Preemption is not helpful for scheduling."
0.5159,Event,ADDED,eval-conflicts-rho040-r1-162-5pztq.18d52f8a42ca2e4f,"reason=FailedScheduling count=None msg=0/6 nodes are available: 1 c_wall violated: 1 conflicting context pair(s) with node memory, 5 node(s) had untolerated taint(s). no new claims to deallocate, preemption: 0/6 nodes are available: 1 No preemption victims found for incoming pod, 5 Preemption is not helpful for scheduling."
0.5163,Event,ADDED,eval-conflicts-rho040-r1-162-5pztq.18d52f8b8dde8ef8,"reason=FailedScheduling count=None msg=0/6 nodes are available: 1 c_wall violated: 1 conflicting context pair(s) with node memory, 5 node(s) had untolerated taint(s). no new claims to deallocate, preemption: 0/6 nodes are available: 1 No preemption victims found for incoming pod, 5 Preemption is not helpful for scheduling."
