t_recv,kind,type,name,detail
0.0255,Node,ADDED,kind-control-plane,taints=1
0.0273,Node,ADDED,kind-worker,taints=0
0.0296,Node,ADDED,kind-worker2,taints=0
0.0317,Node,ADDED,kind-worker3,taints=0
0.0331,Node,ADDED,kind-worker4,taints=0
0.0351,Node,ADDED,kind-worker5,taints=0
0.0486,TaskRequest,ADDED,eval-sanitize-50-r3-000,phase=None job=None
0.055,TaskRequest,MODIFIED,eval-sanitize-50-r3-000,phase=Pending job=None
0.0727,Event,ADDED,eval-sanitize-30-r0-017-gzrg7.18d4f7781e8da3fc,"reason=FailedScheduling count=None msg=0/6 nodes are available: 1 node(s) had untolerated taint(s), 2 c_wall violated: 2 conflicting context pair(s) with node memory, 3 c_wall violated: 1 conflicting context pair(s) with node memory. no new claims to deallocate, preemption: 0/6 nodes are available: 1 Preemption is not helpful for scheduling, 5 No preemption victims found for incoming pod."
0.0733,Event,ADDED,eval-sanitize-30-r0-019-dtq8t.18d4f7788fe8a465,"reason=FailedScheduling count=None msg=0/6 nodes are available: 1 c_wall violated: 1 conflicting context pair(s) with node memory, 1 node(s) had untolerated taint(s), 4 c_wall violated: 2 conflicting context pair(s) with node memory. no new claims to deallocate, preemption: 0/6 nodes are available: 1 Preemption is not helpful for scheduling, 5 No preemption victims found for incoming pod."
0.074,Event,ADDED,eval-sanitize-30-r0-020-lk5cb.18d4f778d14c840a,"reason=FailedScheduling count=None msg=0/6 nodes are available: 1 c_wall violated: 2 conflicting context pair(s) with node memory, 1 c_wall violated: 3 conflicting context pair(s) with node memory, 1 node(s) had untolerated taint(s), 3 c_wall violated: 1 conflicting context pair(s) with node memory. no new claims to deallocate, preemption: 0/6 nodes are available: 1 Preemption is not helpful for scheduling, 5 No preemption victims found for incoming pod."
0.076,Event,ADDED,eval-sanitize-30-r0-022-c28vw.18d4f7796b987ea1,"reason=FailedScheduling count=None msg=0/6 nodes are available: 1 node(s) had untolerated taint(s), 2 c_wall violated: 2 conflicting context pair(s) with node memory, 3 c_wall violated: 1 conflicting context pair(s) with node memory. no new claims to deallocate, preemption: 0/6 nodes are available: 1 Preemption is not helpful for scheduling, 5 No preemption victims found for incoming pod."
0.0765,Event,ADDED,eval-sanitize-30-r0-023-g56qt.18d4f779cacc5595,"reason=FailedScheduling count=None msg=0/6 nodes are available: 1 c_wall violated: 1 conflicting context pair(s) with node memory, 1 node(s) had untolerated taint(s), 4 c_wall violated: 2 conflicting context pair(s) with node memory. no new claims to deallocate, preemption: 0/6 nodes are available: 1 Preemption is not helpful for scheduling, 5 No preemption victims found for incoming pod."
0.0768,Event,ADDED,eval-sanitize-30-r0-086-5m2jb.18d4f788ffd90381,"reason=FailedScheduling count=None msg=0/6 nodes are available: 1 c_wall violated: 1 conflicting context pair(s) with node memory, 1 c_wall violated: 2 conflicting context pair(s) with node memory, 1 c_wall violated: 3 conflicting context pair(s) with node memory, 3 node(s) had untolerated taint(s). no new claims to deallocate, preemption: 0/6 nodes are available: 3 No preemption victims found for incoming pod, 3 Preemption is not helpful for scheduling."
0.078,Event,ADDED,eval-sanitize-30-r0-086-5m2jb.18d4f78910cd3741,"reason=FailedScheduling count=None msg=0/6 nodes are available: 1 c_wall violated: 1 conflicting context pair(s) with node memory, 1 c_wall violated: 2 conflicting context pair(s) with node memory, 4 node(s) had untolerated taint(s). no new claims to deallocate, preemption: 0/6 nodes are available: 2 No preemption victims found for incoming pod, 4 Preemption is not helpful for scheduling."
0.0788,Event,ADDED,eval-sanitize-30-r0-092-xmsjg.18d4f78fcdf3e2de,"reason=FailedScheduling count=None msg=0/6 nodes are available: 1 c_wall violated: 1 conflicting context pair(s) with node memory, 5 node(s) had untolerated taint(s). no new claims to deallocate, preemption: 0/6 nodes are available: 1 No preemption victims found for incoming pod, 5 Preemption is not helpful for scheduling."
0.0791,Event,ADDED,eval-sanitize-30-r0-094-xwx95.18d4f78fd2c8ec49,"reason=FailedScheduling count=None msg=0/6 nodes are available: 1 c_wall violated: 1 conflicting context pair(s) with node memory, 5 node(s) had untolerated taint(s). no new claims to deallocate, preemption: 0/6 nodes are available: 1 No preemption victims found for incoming pod, 5 Preemption is not helpful for scheduling."
0.0809,Job,ADDED,eval-sanitize-50-r3-000,
0.0831,Event,ADDED,eval-sanitize-30-r0-147-6pl7z.18d4f79721babd83,"reason=FailedScheduling count=None msg=0/6 nodes are available: 3 c_wall violated: 1 conflicting context pair(s) with node memory, 3 node(s) had untolerated taint(s). no new claims to deallocate, preemption: 0/6 nodes are available: 3 No preemption victims found for incoming pod, 3 Preemption is not helpful for scheduling."
0.0835,Event,ADDED,eval-sanitize-30-r0-147-6pl7z.18d4f79737a4ade6,"reason=FailedScheduling count=None msg=0/6 nodes are available: 2 c_wall violated: 1 conflicting context pair(s) with node memory, 4 node(s) had untolerated taint(s). no new claims to deallocate, preemption: 0/6 nodes are available: 2 No preemption victims found for incoming pod, 4 Preemption is not helpful for scheduling."
0.0841,Event,ADDED,eval-sanitize-30-r0-147.18d4f7a4568ed8c5,reason=Completed count=1 msg=Job completed
0.0854,Event,ADDED,eval-sanitize-30-r0-148.18d4f7a34fb62359,reason=Completed count=1 msg=Job completed
0.0858,Event,ADDED,eval-sanitize-30-r0-149-bsxtg.18d4f79e10bc6551,"reason=FailedScheduling count=None msg=0/6 nodes are available: 1 c_wall violated: 2 conflicting context pair(s) with node memory, 5 node(s) had untolerated taint(s). no new claims to deallocate, preemption: 0/6 nodes are available: 1 No preemption victims found for incoming pod, 5 Preemption is not helpful for scheduling."
0.0862,Event,ADDED,eval-sanitize-30-r0-149-bsxtg.18d4f79e976171e8,reason=Scheduled count=None msg=Successfully assigned compute/eval-sanitize-30-r0-149-bsxtg to kind-worker3
0.0865,Event,ADDED,eval-sanitize-30-r0-149-bsxtg.18d4f79ebc13ea6e,"reason=Pulled count=1 msg=Container image ""busybox:musl"" already present on machine"
0.087,Event,ADDED,eval-sanitize-30-r0-149-bsxtg.18d4f79ebe22a50f,reason=Created count=1 msg=Created container: task
0.0875,Event,ADDED,eval-sanitize-30-r0-149-bsxtg.18d4f79ec454f609,reason=Started count=1 msg=Started container task
0.0878,Event,ADDED,eval-sanitize-30-r0-149.18d4f7a5dec0cc12,reason=Completed count=1 msg=Job completed
0.0881,Event,ADDED,eval-sanitize-30-r0-150-5wnxz.18d4f79df3dd7730,"reason=FailedScheduling count=None msg=0/6 nodes are available: 1 c_wall violated: 1 conflicting context pair(s) with node memory, 5 node(s) had untolerated taint(s). no new claims to deallocate, preemption: 0/6 nodes are available: 1 No preemption victims found for incoming pod, 5 Preemption is not helpful for scheduling."
0.0885,Event,ADDED,eval-sanitize-30-r0-150-5wnxz.18d4f79ea74bb7c2,reason=Scheduled count=None msg=Successfully assigned compute/eval-sanitize-30-r0-150-5wnxz to kind-worker5
0.0888,Event,ADDED,eval-sanitize-30-r0-150-5wnxz.18d4f79ec42e8829,"reason=Pulled count=1 msg=Container image ""busybox:musl"" already present on machine"
0.0892,Event,ADDED,eval-sanitize-30-r0-150-5wnxz.18d4f79ec5b4f315,reason=Created count=1 msg=Created container: task
0.0898,Event,ADDED,eval-sanitize-30-r0-150-5wnxz.18d4f79ecb965931,reason=Started count=1 msg=Started container task
0.0901,Event,ADDED,eval-sanitize-30-r0-150.18d4f7a60b7b86ee,reason=Completed count=1 msg=Job completed
0.0904,Event,ADDED,eval-sanitize-30-r0-151-dbdnz.18d4f79df514f437,"reason=FailedScheduling count=None msg=0/6 nodes are available: 1 c_wall violated: 1 conflicting context pair(s) with node memory, 5 node(s) had untolerated taint(s). no new claims to deallocate, preemption: 0/6 nodes are available: 1 No preemption victims found for incoming pod, 5 Preemption is not helpful for scheduling."
0.0915,Event,ADDED,eval-sanitize-30-r0-151-dbdnz.18d4f79e5aed3c62,reason=Scheduled count=None msg=Successfully assigned compute/eval-sanitize-30-r0-151-dbdnz to kind-worker3
0.0922,Event,ADDED,eval-sanitize-30-r0-151-dbdnz.18d4f79e77c0916d,"reason=Pulled count=1 msg=Container image ""busybox:musl"" already present on machine"
0.0931,Event,ADDED,eval-sanitize-30-r0-151-dbdnz.18d4f79e79663045,reason=Created count=1 msg=Created container: task
0.0936,Event,ADDED,eval-sanitize-30-r0-151-dbdnz.18d4f79e7e2668d1,reason=Started count=1 msg=Started container task
0.094,Event,ADDED,eval-sanitize-30-r0-151.18d4f7a5f6cb65b6,reason=Completed count=1 msg=Job completed
0.0943,Event,ADDED,eval-sanitize-30-r0-152-9k2gz.18d4f79e11c0cc09,"reason=FailedScheduling count=None msg=0/6 nodes are available: 1 c_wall violated: 2 conflicting context pair(s) with node memory, 5 node(s) had untolerated taint(s). no new claims to deallocate, preemption: 0/6 nodes are available: 1 No preemption victims found for incoming pod, 5 Preemption is not helpful for scheduling."
0.0947,Event,ADDED,eval-sanitize-30-r0-152-9k2gz.18d4f79e9b71b244,reason=Scheduled count=None msg=Successfully assigned compute/eval-sanitize-30-r0-152-9k2gz to kind-worker3
0.0965,Event,ADDED,eval-sanitize-30-r0-152-9k2gz.18d4f79ebc86ba18,"reason=Pulled count=1 msg=Container image ""busybox:musl"" already present on machine"
0.0972,Event,ADDED,eval-sanitize-30-r0-152-9k2gz.18d4f79ebe7781ca,reason=Created count=1 msg=Created container: task
0.0978,Event,ADDED,eval-sanitize-30-r0-152-9k2gz.18d4f79ec454f636,reason=Started count=1 msg=Started container task
0.0983,Event,ADDED,eval-sanitize-30-r0-152.18d4f7a5d2cb5173,reason=Completed count=1 msg=Job completed
0.0984,TaskRequest,MODIFIED,eval-sanitize-50-r3-000,phase=Scheduled job=None
0.0994,Event,ADDED,eval-sanitize-30-r0-153.18d4f7a34e87a698,reason=Completed count=1 msg=Job completed
0.1001,Event,ADDED,eval-sanitize-30-r0-154.18d4f7a34fb3ecee,reason=Completed count=1 msg=Job completed
0.1005,Event,ADDED,eval-sanitize-30-r0-155.18d4f7a4c260c4f5,reason=Completed count=1 msg=Job completed
0.1029,Pod,ADDED,eval-sanitize-50-r3-000-p74fk,phase=Pending node=None
0.1035,Event,ADDED,eval-sanitize-30-r0-156.18d4f7a353cb572e,reason=Completed count=1 msg=Job completed
0.104,Event,ADDED,eval-sanitize-30-r0-157-7n5v2.18d4f79df629385e,"reason=FailedScheduling count=None msg=0/6 nodes are available: 1 c_wall violated: 2 conflicting context pair(s) with node memory, 5 node(s) had untolerated taint(s). no new claims to deallocate, preemption: 0/6 nodes are available: 1 No preemption victims found for incoming pod, 5 Preemption is not helpful for scheduling."
0.1045,Event,ADDED,eval-sanitize-30-r0-157-7n5v2.18d4f79e65a9c58e,reason=Scheduled count=None msg=Successfully assigned compute/eval-sanitize-30-r0-157-7n5v2 to kind-worker3
0.1048,Event,ADDED,eval-sanitize-30-r0-157-7n5v2.18d4f79e8535068c,"reason=Pulled count=1 msg=Container image ""busybox:musl"" already present on machine"
0.1058,Event,ADDED,eval-sanitize-30-r0-157-7n5v2.18d4f79e88646a39,reason=Created count=1 msg=Created container: task
0.1064,Event,ADDED,eval-sanitize-30-r0-157-7n5v2.18d4f79e8dfcc404,reason=Started count=1 msg=Started container task
0.1067,Event,ADDED,eval-sanitize-30-r0-157.18d4f7a5f080ec05,reason=Completed count=1 msg=Job completed
0.108,Job,MODIFIED,eval-sanitize-50-r3-000,
0.1087,Event,ADDED,eval-sanitize-30-r0-158-ch7zc.18d4f79e1f59361d,reason=Scheduled count=None msg=Successfully assigned compute/eval-sanitize-30-r0-158-ch7zc to kind-worker4
0.1091,Event,ADDED,eval-sanitize-30-r0-158-ch7zc.18d4f79e3f37b491,"reason=Pulled count=1 msg=Container image ""busybox:musl"" already present on machine"
0.1096,Event,ADDED,eval-sanitize-30-r0-158-ch7zc.18d4f79e42504bf2,reason=Created count=1 msg=Created container: task
0.11,Event,ADDED,eval-sanitize-30-r0-158-ch7zc.18d4f79e481ba8aa,reason=Started count=1 msg=Started container task
0.1106,Event,ADDED,eval-sanitize-30-r0-158.18d4f7a5878043cf,reason=Completed count=1 msg=Job completed
0.1109,Event,ADDED,eval-sanitize-30-r0-159-x7bw4.18d4f79e1f5bd511,reason=Scheduled count=None msg=Successfully assigned compute/eval-sanitize-30-r0-159-x7bw4 to kind-worker4
0.1112,Event,ADDED,eval-sanitize-30-r0-159-x7bw4.18d4f79e3f08131a,"reason=Pulled count=1 msg=Container image ""busybox:musl"" already present on machine"
0.1116,Event,ADDED,eval-sanitize-30-r0-159-x7bw4.18d4f79e41f8a73f,reason=Created count=1 msg=Created container: task
0.1123,Event,ADDED,eval-sanitize-30-r0-159-x7bw4.18d4f79e481bd974,reason=Started count=1 msg=Started container task
0.1128,Event,ADDED,eval-sanitize-30-r0-159.18d4f7a5616d7ccd,reason=Completed count=1 msg=Job completed
0.1132,Event,ADDED,eval-sanitize-30-r0-160.18d4f7a503be146b,reason=Completed count=1 msg=Job completed
0.1138,Event,ADDED,eval-sanitize-30-r0-161.18d4f7a4aeb59af1,reason=Completed count=1 msg=Job completed
0.1142,Event,ADDED,eval-sanitize-30-r0-162-v246g.18d4f79dfa8441b1,"reason=FailedScheduling count=None msg=0/6 nodes are available: 1 c_wall violated: 1 conflicting context pair(s) with node memory, 5 node(s) had untolerated taint(s). no new claims to deallocate, preemption: 0/6 nodes are available: 1 No preemption victims found for incoming pod, 5 Preemption is not helpful for scheduling."
0.1146,Event,ADDED,eval-sanitize-30-r0-162-v246g.18d4f79e6c04d691,reason=Scheduled count=None msg=Successfully assigned compute/eval-sanitize-30-r0-162-v246g to kind-worker3
0.1151,Event,ADDED,eval-sanitize-30-r0-162-v246g.18d4f79e8dfb64f0,"reason=Pulled count=1 msg=Container image ""busybox:musl"" already present on machine"
0.1156,Event,ADDED,eval-sanitize-30-r0-162-v246g.18d4f79e90527df4,reason=Created count=1 msg=Created container: task
0.1159,Event,ADDED,eval-sanitize-30-r0-162-v246g.18d4f79e9cbf567f,reason=Started count=1 msg=Started container task
0.1162,Event,ADDED,eval-sanitize-30-r0-162.18d4f7a5e49b3459,reason=Completed count=1 msg=Job completed
0.1166,Event,ADDED,eval-sanitize-30-r0-163-xwzlm.18d4f79dfec23411,"reason=FailedScheduling count=None msg=0/6 nodes are available: 1 c_wall violated: 1 conflicting context pair(s) with node memory, 5 node(s) had untolerated taint(s). no new claims to deallocate, preemption: 0/6 nodes are available: 1 No preemption victims found for incoming pod, 5 Preemption is not helpful for scheduling."
0.1168,Event,ADDED,eval-sanitize-30-r0-163-xwzlm.18d4f79e6c4b33c0,reason=Scheduled count=None msg=Successfully assigned compute/eval-sanitize-30-r0-163-xwzlm to kind-worker3
0.1171,Event,ADDED,eval-sanitize-30-r0-163-xwzlm.18d4f79e8e15b7c9,"reason=Pulled count=1 msg=Container image ""busybox:musl"" already present on machine"
0.1174,Event,ADDED,eval-sanitize-30-r0-163-xwzlm.18d4f79e902b99e7,reason=Created count=1 msg=Created container: task
0.1178,Event,ADDED,eval-sanitize-30-r0-163-xwzlm.18d4f79e9cb9992e,reason=Started count=1 msg=Started container task
0.118,Event,ADDED,eval-sanitize-30-r0-163.18d4f7a5c10959b6,reason=Completed count=1 msg=Job completed
0.1182,Event,ADDED,eval-sanitize-30-r0-164-7bldl.18d4f79e25688df2,reason=Scheduled count=None msg=Successfully assigned compute/eval-sanitize-30-r0-164-7bldl to kind-worker4
0.1187,Event,ADDED,eval-sanitize-30-r0-164-7bldl.18d4f79e43d16d3a,"reason=Pulled count=1 msg=Container image ""busybox:musl"" already present on machine"
0.119,Event,ADDED,eval-sanitize-30-r0-164-7bldl.18d4f79e451b5e99,reason=Created count=1 msg=Created container: task
0.1193,Event,ADDED,eval-sanitize-30-r0-164-7bldl.18d4f79e49361d4a,reason=Started count=1 msg=Started container task
0.1199,Event,ADDED,eval-sanitize-30-r0-164.18d4f7a574f3611f,reason=Completed count=1 msg=Job completed
0.1206,Event,ADDED,eval-sanitize-30-r0-165-7w7jb.18d4f79e00e9b9e0,"reason=FailedScheduling count=None msg=0/6 nodes are available: 1 c_wall violated: 1 conflicting context pair(s) with node memory, 5 node(s) had untolerated taint(s). no new claims to deallocate, preemption: 0/6 nodes are available: 1 No preemption victims found for incoming pod, 5 Preemption is not helpful for scheduling."
0.1209,Event,ADDED,eval-sanitize-30-r0-165-7w7jb.18d4f79e725725e8,reason=Scheduled count=None msg=Successfully assigned compute/eval-sanitize-30-r0-165-7w7jb to kind-worker3
0.1213,Event,ADDED,eval-sanitize-30-r0-165-7w7jb.18d4f79e8f0d8595,"reason=Pulled count=1 msg=Container image ""busybox:musl"" already present on machine"
0.122,Event,ADDED,eval-sanitize-30-r0-165-7w7jb.18d4f79e91957c14,reason=Created count=1 msg=Created container: task
0.1224,Event,ADDED,eval-sanitize-30-r0-165-7w7jb.18d4f79e9f8007d8,reason=Started count=1 msg=Started container task
0.1228,Event,ADDED,eval-sanitize-30-r0-165.18d4f7a5cfe1d8b8,reason=Completed count=1 msg=Job completed
0.1231,Event,ADDED,eval-sanitize-30-r0-166.18d4f7a42f2b0c5f,reason=Completed count=1 msg=Job completed
0.1235,Event,ADDED,eval-sanitize-30-r0-167-m5z9d.18d4f79e2a0181fe,reason=Scheduled count=None msg=Successfully assigned compute/eval-sanitize-30-r0-167-m5z9d to kind-worker4
0.1238,Event,ADDED,eval-sanitize-30-r0-167-m5z9d.18d4f79e4826ec8e,"reason=Pulled count=1 msg=Container image ""busybox:musl"" already present on machine"
0.1242,Event,ADDED,eval-sanitize-30-r0-167-m5z9d.18d4f79e4a43bb36,reason=Created count=1 msg=Created container: task
0.1246,Event,ADDED,eval-sanitize-30-r0-167-m5z9d.18d4f79e51bb338b,reason=Started count=1 msg=Started container task
0.1252,Event,ADDED,eval-sanitize-30-r0-167.18d4f7a55e7f934c,reason=Completed count=1 msg=Job completed
0.1255,Event,ADDED,eval-sanitize-30-r0-168.18d4f7a34db0d967,reason=Completed count=1 msg=Job completed
0.1259,Event,ADDED,eval-sanitize-30-r0-169-m96qr.18d4f79e06029769,"reason=FailedScheduling count=None msg=0/6 nodes are available: 1 c_wall violated: 2 conflicting context pair(s) with node memory, 5 node(s) had untolerated taint(s). no new claims to deallocate, preemption: 0/6 nodes are available: 1 No preemption victims found for incoming pod, 5 Preemption is not helpful for scheduling."
0.1262,Event,ADDED,eval-sanitize-30-r0-169-m96qr.18d4f79e77c7d82b,reason=Scheduled count=None msg=Successfully assigned compute/eval-sanitize-30-r0-169-m96qr to kind-worker3
0.1264,Event,ADDED,eval-sanitize-30-r0-169-m96qr.18d4f79e99ed5509,"reason=Pulled count=1 msg=Container image ""busybox:musl"" already present on machine"
0.1266,Event,ADDED,eval-sanitize-30-r0-169-m96qr.18d4f79e9cf0eda4,reason=Created count=1 msg=Created container: task
0.1269,Event,ADDED,eval-sanitize-30-r0-169-m96qr.18d4f79ea21bbc7c,reason=Started count=1 msg=Started container task
0.1272,Event,ADDED,eval-sanitize-30-r0-169.18d4f7a5af600418,reason=Completed count=1 msg=Job completed
0.1274,Event,ADDED,eval-sanitize-30-r0-170-gtc7d.18d4f79e06415de7,"reason=FailedScheduling count=None msg=0/6 nodes are available: 1 c_wall violated: 2 conflicting context pair(s) with node memory, 5 node(s) had untolerated taint(s). no new claims to deallocate, preemption: 0/6 nodes are available: 1 No preemption victims found for incoming pod, 5 Preemption is not helpful for scheduling."
0.1276,Event,ADDED,eval-sanitize-30-r0-170-gtc7d.18d4f79e84ea0c00,reason=Scheduled count=None msg=Successfully assigned compute/eval-sanitize-30-r0-170-gtc7d to kind-worker3
0.1281,Event,ADDED,eval-sanitize-30-r0-170-gtc7d.18d4f79ea2295a49,"reason=Pulled count=1 msg=Container image ""busybox:musl"" already present on machine"
0.1283,Event,ADDED,eval-sanitize-30-r0-170-gtc7d.18d4f79ea756a933,reason=Created count=1 msg=Created container: task
0.1286,Event,ADDED,eval-sanitize-30-r0-170-gtc7d.18d4f79eaf98561c,reason=Started count=1 msg=Started container task
0.1289,Event,ADDED,eval-sanitize-30-r0-170.18d4f7a5cccdfe10,reason=Completed count=1 msg=Job completed
0.1292,Event,ADDED,eval-sanitize-30-r0-171-dvztt.18d4f79e068a5e9c,"reason=FailedScheduling count=None msg=0/6 nodes are available: 1 c_wall violated: 2 conflicting context pair(s) with node memory, 5 node(s) had untolerated taint(s). no new claims to deallocate, preemption: 0/6 nodes are available: 1 No preemption victims found for incoming pod, 5 Preemption is not helpful for scheduling."
0.1294,Event,ADDED,eval-sanitize-30-r0-171-dvztt.18d4f79e353cea48,reason=Scheduled count=None msg=Successfully assigned compute/eval-sanitize-30-r0-171-dvztt to kind-worker4
0.1298,Event,ADDED,eval-sanitize-30-r0-171-dvztt.18d4f79e5395cea6,"reason=Pulled count=1 msg=Container image ""busybox:musl"" already present on machine"
0.1304,Event,ADDED,eval-sanitize-30-r0-171-dvztt.18d4f79e5583c78c,reason=Created count=1 msg=Created container: task
0.1309,Event,ADDED,eval-sanitize-30-r0-171-dvztt.18d4f79e5ad96316,reason=Started count=1 msg=Started container task
0.1313,Event,ADDED,eval-sanitize-30-r0-171.18d4f7a59116b1fc,reason=Completed count=1 msg=Job completed
0.1317,Event,ADDED,eval-sanitize-30-r0-172-9mbhk.18d4f79e06cd42ea,"reason=FailedScheduling count=None msg=0/6 nodes are available: 1 c_wall violated: 1 conflicting context pair(s) with node memory, 5 node(s) had untolerated taint(s). no new claims to deallocate, preemption: 0/6 nodes are available: 1 No preemption victims found for incoming pod, 5 Preemption is not helpful for scheduling."
0.1326,Event,ADDED,eval-sanitize-30-r0-172-9mbhk.18d4f79e36332780,reason=Scheduled count=None msg=Successfully assigned compute/eval-sanitize-30-r0-172-9mbhk to kind-worker4
0.1331,Event,ADDED,eval-sanitize-30-r0-172-9mbhk.18d4f79e53b19797,"reason=Pulled count=1 msg=Container image ""busybox:musl"" already present on machine"
0.1334,Event,ADDED,eval-sanitize-30-r0-172-9mbhk.18d4f79e56437d4d,reason=Created count=1 msg=Created container: task
0.1339,Event,ADDED,eval-sanitize-30-r0-172-9mbhk.18d4f79e5ad962db,reason=Started count=1 msg=Started container task
0.1344,Event,ADDED,eval-sanitize-30-r0-172.18d4f7a5a31e0f43,reason=Completed count=1 msg=Job completed
0.1347,Event,ADDED,eval-sanitize-30-r0-173-s2x6t.18d4f79e0baa77cf,"reason=FailedScheduling count=None msg=0/6 nodes are available: 1 c_wall violated: 1 conflicting context pair(s) with node memory, 5 node(s) had untolerated taint(s). no new claims to deallocate, preemption: 0/6 nodes are available: 1 No preemption victims found for incoming pod, 5 Preemption is not helpful for scheduling."
0.135,Event,ADDED,eval-sanitize-30-r0-173-s2x6t.18d4f79e3bf0cbc9,reason=Scheduled count=None msg=Successfully assigned compute/eval-sanitize-30-r0-173-s2x6t to kind-worker4
0.1357,Event,ADDED,eval-sanitize-30-r0-173-s2x6t.18d4f79e59d76e34,"reason=Pulled count=1 msg=Container image ""busybox:musl"" already present on machine"
0.1362,Event,ADDED,eval-sanitize-30-r0-173-s2x6t.18d4f79e5c321a57,reason=Created count=1 msg=Created container: task
0.1365,Event,ADDED,eval-sanitize-30-r0-173-s2x6t.18d4f79e60773be6,reason=Started count=1 msg=Started container task
0.1368,Event,ADDED,eval-sanitize-30-r0-173.18d4f7a59d11dbc0,reason=Completed count=1 msg=Job completed
0.1374,Event,ADDED,eval-sanitize-30-r0-174-vcgn2.18d4f79e0bef4752,"reason=FailedScheduling count=None msg=0/6 nodes are available: 1 c_wall violated: 2 conflicting context pair(s) with node memory, 5 node(s) had untolerated taint(s). no new claims to deallocate, preemption: 0/6 nodes are available: 1 No preemption victims found for incoming pod, 5 Preemption is not helpful for scheduling."
0.1379,Event,ADDED,eval-sanitize-30-r0-174-vcgn2.18d4f79e414d6525,reason=Scheduled count=None msg=Successfully assigned compute/eval-sanitize-30-r0-174-vcgn2 to kind-worker4
0.1382,Event,ADDED,eval-sanitize-30-r0-174-vcgn2.18d4f79e5e7cacee,"reason=Pulled count=1 msg=Container image ""busybox:musl"" already present on machine"
0.1388,Event,ADDED,eval-sanitize-30-r0-174-vcgn2.18d4f79e61556373,reason=Created count=1 msg=Created container: task
0.1391,Event,ADDED,eval-sanitize-30-r0-174-vcgn2.18d4f79e65e9b3fe,reason=Started count=1 msg=Started container task
0.1393,Event,ADDED,eval-sanitize-30-r0-174.18d4f7a5f96944a0,reason=Completed count=1 msg=Job completed
0.1395,Event,ADDED,eval-sanitize-30-r0-175-m79rw.18d4f79e117b719e,reason=Started count=1 msg=Started container task
0.1399,Event,ADDED,eval-sanitize-30-r0-175.18d4f7a4612df8c3,reason=Completed count=1 msg=Job completed
0.14,Event,ADDED,eval-sanitize-30-r0-176-h8zd7.18d4f79e0c29f8a3,"reason=FailedScheduling count=None msg=0/6 nodes are available: 1 c_wall violated: 2 conflicting context pair(s) with node memory, 5 node(s) had untolerated taint(s). no new claims to deallocate, preemption: 0/6 nodes are available: 1 No preemption victims found for incoming pod, 5 Preemption is not helpful for scheduling."
0.1402,Event,ADDED,eval-sanitize-30-r0-176-h8zd7.18d4f79e46e90074,reason=Scheduled count=None msg=Successfully assigned compute/eval-sanitize-30-r0-176-h8zd7 to kind-worker4
0.1406,Event,ADDED,eval-sanitize-30-r0-176-h8zd7.18d4f79e61cd601a,"reason=Pulled count=1 msg=Container image ""busybox:musl"" already present on machine"
0.1409,Event,ADDED,eval-sanitize-30-r0-176-h8zd7.18d4f79e63716a77,reason=Created count=1 msg=Created container: task
0.1413,Event,ADDED,eval-sanitize-30-r0-176-h8zd7.18d4f79e6bc44333,reason=Started count=1 msg=Started container task
0.1416,Event,ADDED,eval-sanitize-30-r0-176.18d4f7a6026bba4a,reason=Completed count=1 msg=Job completed
0.142,Event,ADDED,eval-sanitize-30-r0-177-d8zwr.18d4f79e13c15acf,reason=Started count=1 msg=Started container task
0.1422,Event,ADDED,eval-sanitize-30-r0-177.18d4f7a49fcb5f3d,reason=Completed count=1 msg=Job completed
0.1426,Event,ADDED,eval-sanitize-30-r0-178-qzjxn.18d4f79e0ca2f3c4,"reason=FailedScheduling count=None msg=0/6 nodes are available: 1 c_wall violated: 1 conflicting context pair(s) with node memory, 5 node(s) had untolerated taint(s). no new claims to deallocate, preemption: 0/6 nodes are available: 1 No preemption victims found for incoming pod, 5 Preemption is not helpful for scheduling."
0.1429,Event,ADDED,eval-sanitize-30-r0-178-qzjxn.18d4f79e8f100319,"reason=FailedScheduling count=None msg=0/6 nodes are available: 3 c_wall violated: 1 conflicting context pair(s) with node memory, 3 node(s) had untolerated taint(s). no new claims to deallocate, preemption: 0/6 nodes are available: 3 No preemption victims found for incoming pod, 3 Preemption is not helpful for scheduling."
0.1431,Event,ADDED,eval-sanitize-30-r0-178-qzjxn.18d4f79eb2e546d5,"reason=FailedScheduling count=None msg=0/6 nodes are available: 2 node(s) had untolerated taint(s), 4 c_wall violated: 1 conflicting context pair(s) with node memory. no new claims to deallocate, preemption: 0/6 nodes are available: 2 Preemption is not helpful for scheduling, 4 No preemption victims found for incoming pod."
0.1436,Event,ADDED,eval-sanitize-30-r0-178-qzjxn.18d4f79ed02abdd4,reason=Scheduled count=None msg=Successfully assigned compute/eval-sanitize-30-r0-178-qzjxn to kind-worker2
0.1439,Event,ADDED,eval-sanitize-30-r0-178-qzjxn.18d4f79eeed42aee,"reason=Pulled count=1 msg=Container image ""busybox:musl"" already present on machine"
0.1441,Event,ADDED,eval-sanitize-30-r0-178-qzjxn.18d4f79ef08fa487,reason=Created count=1 msg=Created container: task
0.1443,Event,ADDED,eval-sanitize-30-r0-178-qzjxn.18d4f79ef53c642a,reason=Started count=1 msg=Started container task
0.1445,Event,ADDED,eval-sanitize-30-r0-178.18d4f7a6265adaa3,reason=Completed count=1 msg=Job completed
0.1449,Event,ADDED,eval-sanitize-30-r0-179-vqss5.18d4f79e0c6ae4ad,"reason=FailedScheduling count=None msg=0/6 nodes are available: 1 c_wall violated: 3 conflicting context pair(s) with node memory, 5 node(s) had untolerated taint(s). no new claims to deallocate, preemption: 0/6 nodes are available: 1 No preemption victims found for incoming pod, 5 Preemption is not helpful for scheduling."
0.145,Event,ADDED,eval-sanitize-30-r0-179-vqss5.18d4f79e8950bc92,"reason=FailedScheduling count=None msg=0/6 nodes are available: 1 c_wall violated: 4 conflicting context pair(s) with node memory, 2 c_wall violated: 1 conflicting context pair(s) with node memory, 3 node(s) had untolerated taint(s). no new claims to deallocate, preemption: 0/6 nodes are available: 3 No preemption victims found for incoming pod, 3 Preemption is not helpful for scheduling."
0.1452,Event,ADDED,eval-sanitize-30-r0-179-vqss5.18d4f79eacb079b6,"reason=FailedScheduling count=None msg=0/6 nodes are available: 1 c_wall violated: 4 conflicting context pair(s) with node memory, 2 node(s) had untolerated taint(s), 3 c_wall violated: 1 conflicting context pair(s) with node memory. no new claims to deallocate, preemption: 0/6 nodes are available: 2 Preemption is not helpful for scheduling, 4 No preemption victims found for incoming pod."
0.1455,Event,ADDED,eval-sanitize-30-r0-179-vqss5.18d4f79ebe7d87c0,"reason=FailedScheduling count=None msg=0/6 nodes are available: 1 c_wall violated: 4 conflicting context pair(s) with node memory, 2 node(s) had untolerated taint(s), 3 c_wall violated: 1 conflicting context pair(s) with node memory. no new claims to deallocate, preemption: 0/6 nodes are available: 2 Preemption is not helpful for scheduling, 4 No preemption victims found for incoming pod."
0.1457,Event,ADDED,eval-sanitize-30-r0-179-vqss5.18d4f79edb9d4729,reason=Scheduled count=None msg=Successfully assigned compute/eval-sanitize-30-r0-179-vqss5 to kind-worker2
0.1459,Event,ADDED,eval-sanitize-30-r0-179-vqss5.18d4f79ef68a7b07,"reason=Pulled count=1 msg=Container image ""busybox:musl"" already present on machine"
0.1465,Event,ADDED,eval-sanitize-30-r0-179-vqss5.18d4f79ef7d39ea7,reason=Created count=1 msg=Created container: task
0.1469,Event,ADDED,eval-sanitize-30-r0-179-vqss5.18d4f79efc8d1c88,reason=Started count=1 msg=Started container task
0.1474,Event,ADDED,eval-sanitize-30-r0-179.18d4f7a6204906c0,reason=Completed count=1 msg=Job completed
0.1479,Event,ADDED,eval-sanitize-30-r0-180-v7pfv.18d4f79e1217f344,"reason=FailedScheduling count=None msg=0/6 nodes are available: 1 c_wall violated: 1 conflicting context pair(s) with node memory, 5 node(s) had untolerated taint(s). no new claims to deallocate, preemption: 0/6 nodes are available: 1 No preemption victims found for incoming pod, 5 Preemption is not helpful for scheduling."
0.1493,Event,ADDED,eval-sanitize-30-r0-180-v7pfv.18d4f79ea10e8b15,reason=Scheduled count=None msg=Successfully assigned compute/eval-sanitize-30-r0-180-v7pfv to kind-worker3
0.1497,Event,ADDED,eval-sanitize-30-r0-180-v7pfv.18d4f79ed2cae593,"reason=Pulled count=1 msg=Container image ""busybox:musl"" already present on machine"
0.1501,Event,ADDED,eval-sanitize-30-r0-180-v7pfv.18d4f79ed41e329b,reason=Created count=1 msg=Created container: task
0.1508,Event,ADDED,eval-sanitize-30-r0-180-v7pfv.18d4f79eda78779c,reason=Started count=1 msg=Started container task
0.1512,Event,ADDED,eval-sanitize-30-r0-180.18d4f7a5bade9d2f,reason=Completed count=1 msg=Job completed
0.1515,Event,ADDED,eval-sanitize-30-r0-181-9sj5d.18d4f79e421c528b,reason=Scheduled count=None msg=Successfully assigned compute/eval-sanitize-30-r0-181-9sj5d to kind-worker
0.1518,Event,ADDED,eval-sanitize-30-r0-181-9sj5d.18d4f79e5e7f4277,"reason=Pulled count=1 msg=Container image ""busybox:musl"" already present on machine"
0.1525,Event,ADDED,eval-sanitize-30-r0-181-9sj5d.18d4f79e613987ff,reason=Created count=1 msg=Created container: task
0.153,Event,ADDED,eval-sanitize-30-r0-181-9sj5d.18d4f79e6612f94f,reason=Started count=1 msg=Started container task
0.1535,Event,ADDED,eval-sanitize-30-r0-181.18d4f79e3e6b2bf1,reason=SuccessfulCreate count=1 msg=Created pod: eval-sanitize-30-r0-181-9sj5d
0.154,Event,ADDED,eval-sanitize-30-r0-181.18d4f7a5bdd2f1c7,reason=Completed count=1 msg=Job completed
0.1543,Event,ADDED,eval-sanitize-30-r0-182-j656l.18d4f79e7dc6e063,reason=Scheduled count=None msg=Successfully assigned compute/eval-sanitize-30-r0-182-j656l to kind-worker
0.1547,Event,ADDED,eval-sanitize-30-r0-182-j656l.18d4f79ea1657661,"reason=Pulled count=1 msg=Container image ""busybox:musl"" already present on machine"
0.1551,Event,ADDED,eval-sanitize-30-r0-182-j656l.18d4f79ea32f5dc9,reason=Created count=1 msg=Created container: task
0.1581,Event,ADDED,eval-sanitize-30-r0-182-j656l.18d4f79ea858a728,reason=Started count=1 msg=Started container task
0.1599,Event,ADDED,eval-sanitize-30-r0-182.18d4f79e74ea4f6f,reason=SuccessfulCreate count=1 msg=Created pod: eval-sanitize-30-r0-182-j656l
0.1602,Event,ADDED,eval-sanitize-30-r0-182.18d4f7a5b50badbe,reason=Completed count=1 msg=Job completed
0.1608,Event,ADDED,eval-sanitize-30-r0-183-d7bpl.18d4f79ecbb8887b,reason=Scheduled count=None msg=Successfully assigned compute/eval-sanitize-30-r0-183-d7bpl to kind-worker5
0.1614,Event,ADDED,eval-sanitize-30-r0-183-d7bpl.18d4f79ee6bf52ef,"reason=Pulled count=1 msg=Container image ""busybox:musl"" already present on machine"
0.1624,Event,ADDED,eval-sanitize-30-r0-183-d7bpl.18d4f79ee84767ff,reason=Created count=1 msg=Created container: task
0.1628,Event,ADDED,eval-sanitize-30-r0-183-d7bpl.18d4f79eeda60134,reason=Started count=1 msg=Started container task
0.1632,Event,ADDED,eval-sanitize-30-r0-183.18d4f79eb6500ab4,reason=SuccessfulCreate count=1 msg=Created pod: eval-sanitize-30-r0-183-d7bpl
0.1642,Event,ADDED,eval-sanitize-30-r0-183.18d4f7a60e57016a,reason=Completed count=1 msg=Job completed
0.1647,Event,ADDED,eval-sanitize-30-r0-184-cr2dc.18d4f79eef0bac5b,reason=Scheduled count=None msg=Successfully assigned compute/eval-sanitize-30-r0-184-cr2dc to kind-worker4
0.1651,Event,ADDED,eval-sanitize-30-r0-184-cr2dc.18d4f79f0d373227,"reason=Pulled count=1 msg=Container image ""busybox:musl"" already present on machine"
0.1664,Pod,MODIFIED,eval-sanitize-50-r3-000-p74fk,phase=Pending node=kind-worker5
0.1669,Event,ADDED,eval-sanitize-30-r0-184-cr2dc.18d4f79f0e95c10d,reason=Created count=1 msg=Created container: task
0.1671,Event,ADDED,eval-sanitize-30-r0-184-cr2dc.18d4f79f14aa0b89,reason=Started count=1 msg=Started container task
0.1673,Event,ADDED,eval-sanitize-30-r0-184.18d4f79eeafde6b3,reason=SuccessfulCreate count=1 msg=Created pod: eval-sanitize-30-r0-184-cr2dc
0.1674,Event,ADDED,eval-sanitize-30-r0-184.18d4f7a614613c0f,reason=Completed count=1 msg=Job completed
0.168,Event,ADDED,eval-sanitize-30-r0-185-mc7fg.18d4f79f2fd6cd07,reason=Scheduled count=None msg=Successfully assigned compute/eval-sanitize-30-r0-185-mc7fg to kind-worker5
0.1685,Event,ADDED,eval-sanitize-30-r0-185-mc7fg.18d4f79f4cac70cd,"reason=Pulled count=1 msg=Container image ""busybox:musl"" already present on machine"
0.169,Event,ADDED,eval-sanitize-30-r0-185-mc7fg.18d4f79f4eb015f0,reason=Created count=1 msg=Created container: task
0.1699,Event,ADDED,eval-sanitize-30-r0-185-mc7fg.18d4f79f539d3593,reason=Started count=1 msg=Started container task
0.1704,Event,ADDED,eval-sanitize-30-r0-185.18d4f79f289b2f76,reason=SuccessfulCreate count=1 msg=Created pod: eval-sanitize-30-r0-185-mc7fg
0.1707,Event,ADDED,eval-sanitize-30-r0-185.18d4f7a63812d2e1,reason=Completed count=1 msg=Job completed
0.1711,Event,ADDED,eval-sanitize-30-r0-186-2x7vr.18d4f79f6e6cd662,reason=Scheduled count=None msg=Successfully assigned compute/eval-sanitize-30-r0-186-2x7vr to kind-worker5
0.1718,Event,ADDED,eval-sanitize-30-r0-186-2x7vr.18d4f79f8f15be72,"reason=Pulled count=1 msg=Container image ""busybox:musl"" already present on machine"
0.1722,Event,ADDED,eval-sanitize-30-r0-186-2x7vr.18d4f79f906a9f7e,reason=Created count=1 msg=Created container: task
0.1726,Event,ADDED,eval-sanitize-30-r0-186-2x7vr.18d4f79f9a9abcae,reason=Started count=1 msg=Started container task
0.1731,Event,ADDED,eval-sanitize-30-r0-186.18d4f79f670794a7,reason=SuccessfulCreate count=1 msg=Created pod: eval-sanitize-30-r0-186-2x7vr
0.1738,Event,ADDED,eval-sanitize-30-r0-186.18d4f7a64d187637,reason=Completed count=1 msg=Job completed
0.1741,Event,ADDED,eval-sanitize-30-r0-187-82fx9.18d4f79fa1d3dbc4,reason=Scheduled count=None msg=Successfully assigned compute/eval-sanitize-30-r0-187-82fx9 to kind-worker5
0.1747,Event,ADDED,eval-sanitize-30-r0-187-82fx9.18d4f79fc0145660,"reason=Pulled count=1 msg=Container image ""busybox:musl"" already present on machine"
0.1753,Event,ADDED,eval-sanitize-30-r0-187-82fx9.18d4f79fc16f8a61,reason=Created count=1 msg=Created container: task
0.1787,Event,ADDED,eval-sanitize-30-r0-187-82fx9.18d4f79fc80a187c,reason=Started count=1 msg=Started container task
0.1797,Event,ADDED,eval-sanitize-30-r0-187.18d4f79f9de3ae30,reason=SuccessfulCreate count=1 msg=Created pod: eval-sanitize-30-r0-187-82fx9
0.1806,Event,ADDED,eval-sanitize-30-r0-187.18d4f7a65ec02c37,reason=Completed count=1 msg=Job completed
0.1819,Event,ADDED,eval-sanitize-30-r0-188-k97qd.18d4f79fe328026f,reason=Scheduled count=None msg=Successfully assigned compute/eval-sanitize-30-r0-188-k97qd to kind-worker2
0.1826,Event,ADDED,eval-sanitize-30-r0-188-k97qd.18d4f79ffe2a2f61,"reason=Pulled count=1 msg=Container image ""busybox:musl"" already present on machine"
0.1832,Event,ADDED,eval-sanitize-30-r0-188-k97qd.18d4f79fffa4f436,reason=Created count=1 msg=Created container: task
0.1835,Event,ADDED,eval-sanitize-30-r0-188-k97qd.18d4f7a00a3b1f56,reason=Started count=1 msg=Started container task
0.1841,Event,ADDED,eval-sanitize-30-r0-188.18d4f79fda9d1b69,reason=SuccessfulCreate count=1 msg=Created pod: eval-sanitize-30-r0-188-k97qd
0.1845,Event,ADDED,eval-sanitize-30-r0-188.18d4f7a66ab88563,reason=Completed count=1 msg=Job completed
0.1849,Event,ADDED,eval-sanitize-30-r0-189-nf795.18d4f7a01eb936c1,reason=Scheduled count=None msg=Successfully assigned compute/eval-sanitize-30-r0-189-nf795 to kind-worker5
0.1853,Event,ADDED,eval-sanitize-30-r0-189-nf795.18d4f7a03d062b3d,"reason=Pulled count=1 msg=Container image ""busybox:musl"" already present on machine"
0.1862,Event,ADDED,eval-sanitize-30-r0-189-nf795.18d4f7a03e55fb6e,reason=Created count=1 msg=Created container: task
0.1867,Event,ADDED,eval-sanitize-30-r0-189-nf795.18d4f7a042ef0fc1,reason=Started count=1 msg=Started container task
0.1871,Event,ADDED,eval-sanitize-30-r0-189.18d4f7a017726a6d,reason=SuccessfulCreate count=1 msg=Created pod: eval-sanitize-30-r0-189-nf795
0.1877,Event,ADDED,eval-sanitize-30-r0-189.18d4f7a67ca137e3,reason=Completed count=1 msg=Job completed
0.188,Event,ADDED,eval-sanitize-30-r0-190-htn94.18d4f7a05936b92e,reason=Scheduled count=None msg=Successfully assigned compute/eval-sanitize-30-r0-190-htn94 to kind-worker4
0.1883,Event,ADDED,eval-sanitize-30-r0-190-htn94.18d4f7a0734de565,"reason=Pulled count=1 msg=Container image ""busybox:musl"" already present on machine"
0.1887,Event,ADDED,eval-sanitize-30-r0-190-htn94.18d4f7a074b5f2c5,reason=Created count=1 msg=Created container: task
0.1893,Event,ADDED,eval-sanitize-30-r0-190-htn94.18d4f7a07c8d5601,reason=Started count=1 msg=Started container task
0.1897,Event,ADDED,eval-sanitize-30-r0-190.18d4f7a0523571c4,reason=SuccessfulCreate count=1 msg=Created pod: eval-sanitize-30-r0-190-htn94
0.19,Event,ADDED,eval-sanitize-30-r0-190.18d4f7a68bb0ae21,reason=Completed count=1 msg=Job completed
0.1903,Event,ADDED,eval-sanitize-30-r0-191-qnctg.18d4f7a09607a49d,reason=Scheduled count=None msg=Successfully assigned compute/eval-sanitize-30-r0-191-qnctg to kind-worker5
0.191,Event,ADDED,eval-sanitize-30-r0-191-qnctg.18d4f7a0b3713a50,"reason=Pulled count=1 msg=Container image ""busybox:musl"" already present on machine"
0.1913,Event,ADDED,eval-sanitize-30-r0-191-qnctg.18d4f7a0b4d32c73,reason=Created count=1 msg=Created container: task
0.192,Event,ADDED,eval-sanitize-30-r0-191-qnctg.18d4f7a0bdc4246d,reason=Started count=1 msg=Started container task
0.1926,Event,ADDED,eval-sanitize-30-r0-191.18d4f7a090c59234,reason=SuccessfulCreate count=1 msg=Created pod: eval-sanitize-30-r0-191-qnctg
0.1939,Event,ADDED,eval-sanitize-30-r0-191.18d4f7a673c8abc0,reason=Completed count=1 msg=Job completed
0.1943,Event,ADDED,eval-sanitize-30-r0-192-5bjnr.18d4f7a0d820a6f1,reason=Scheduled count=None msg=Successfully assigned compute/eval-sanitize-30-r0-192-5bjnr to kind-worker2
0.1946,Event,ADDED,eval-sanitize-30-r0-192-5bjnr.18d4f7a0fc7410a3,"reason=Pulled count=1 msg=Container image ""busybox:musl"" already present on machine"
0.1951,Event,ADDED,eval-sanitize-30-r0-192-5bjnr.18d4f7a0fdca3b50,reason=Created count=1 msg=Created container: task
0.1954,Event,ADDED,eval-sanitize-30-r0-192-5bjnr.18d4f7a105440c2b,reason=Started count=1 msg=Started container task
0.1956,Event,ADDED,eval-sanitize-30-r0-192.18d4f7a0caf8a49e,reason=SuccessfulCreate count=1 msg=Created pod: eval-sanitize-30-r0-192-5bjnr
0.1959,Event,ADDED,eval-sanitize-30-r0-192.18d4f7a68877bb65,reason=Completed count=1 msg=Job completed
0.1966,Event,ADDED,eval-sanitize-30-r0-193-xwqh8.18d4f7a110211868,reason=Scheduled count=None msg=Successfully assigned compute/eval-sanitize-30-r0-193-xwqh8 to kind-worker4
0.197,Event,ADDED,eval-sanitize-30-r0-193-xwqh8.18d4f7a12cfc14c6,"reason=Pulled count=1 msg=Container image ""busybox:musl"" already present on machine"
0.1974,Event,ADDED,eval-sanitize-30-r0-193-xwqh8.18d4f7a12e5dfe6f,reason=Created count=1 msg=Created container: task
0.1982,Event,ADDED,eval-sanitize-30-r0-193-xwqh8.18d4f7a13720acca,reason=Started count=1 msg=Started container task
0.1987,Event,ADDED,eval-sanitize-30-r0-193.18d4f7a1072aea91,reason=SuccessfulCreate count=1 msg=Created pod: eval-sanitize-30-r0-193-xwqh8
0.1992,Event,ADDED,eval-sanitize-30-r0-193.18d4f7a6ac51f4ef,reason=Completed count=1 msg=Job completed
0.1997,Event,ADDED,eval-sanitize-30-r0-194-6bvpb.18d4f7a14b919ac4,reason=Scheduled count=None msg=Successfully assigned compute/eval-sanitize-30-r0-194-6bvpb to kind-worker5
0.2005,Event,ADDED,eval-sanitize-30-r0-194-6bvpb.18d4f7a16a1b3dc2,"reason=Pulled count=1 msg=Container image ""busybox:musl"" already present on machine"
0.2009,Event,ADDED,eval-sanitize-30-r0-194-6bvpb.18d4f7a16bf636bd,reason=Created count=1 msg=Created container: task
0.2012,Event,ADDED,eval-sanitize-30-r0-194-6bvpb.18d4f7a171ce7389,reason=Started count=1 msg=Started container task
0.2016,Event,ADDED,eval-sanitize-30-r0-194.18d4f7a140a2dc78,reason=SuccessfulCreate count=1 msg=Created pod: eval-sanitize-30-r0-194-6bvpb
0.2019,Event,ADDED,eval-sanitize-30-r0-194.18d4f7a6f7a960f1,reason=Completed count=1 msg=Job completed
0.2021,Event,ADDED,eval-sanitize-30-r0-195-msm6b.18d4f7a18356e593,reason=Scheduled count=None msg=Successfully assigned compute/eval-sanitize-30-r0-195-msm6b to kind-worker4
0.2023,Event,ADDED,eval-sanitize-30-r0-195-msm6b.18d4f7a1a26d3096,"reason=Pulled count=1 msg=Container image ""busybox:musl"" already present on machine"
0.2025,Event,ADDED,eval-sanitize-30-r0-195-msm6b.18d4f7a1a40bff93,reason=Created count=1 msg=Created container: task
0.2027,Event,ADDED,eval-sanitize-30-r0-195-msm6b.18d4f7a1a9d2e8e3,reason=Started count=1 msg=Started container task
0.2029,Event,ADDED,eval-sanitize-30-r0-195.18d4f7a17c86da3c,reason=SuccessfulCreate count=1 msg=Created pod: eval-sanitize-30-r0-195-msm6b
0.2032,Event,ADDED,eval-sanitize-30-r0-195.18d4f7a7131c968e,reason=Completed count=1 msg=Job completed
0.2037,Event,ADDED,eval-sanitize-30-r0-196-4vp8l.18d4f7a1b9e7138e,reason=Scheduled count=None msg=Successfully assigned compute/eval-sanitize-30-r0-196-4vp8l to kind-worker
0.204,Event,ADDED,eval-sanitize-30-r0-196-4vp8l.18d4f7a1d66d5b60,"reason=Pulled count=1 msg=Container image ""busybox:musl"" already present on machine"
0.2046,Event,ADDED,eval-sanitize-30-r0-196-4vp8l.18d4f7a1d807c8d4,reason=Created count=1 msg=Created container: task
0.2051,Event,ADDED,eval-sanitize-30-r0-196-4vp8l.18d4f7a1e0c67ffe,reason=Started count=1 msg=Started container task
0.206,Event,ADDED,eval-sanitize-30-r0-196.18d4f7a1b744a65c,reason=SuccessfulCreate count=1 msg=Created pod: eval-sanitize-30-r0-196-4vp8l
0.2066,Event,ADDED,eval-sanitize-30-r0-196.18d4f7a74900ee1a,reason=Completed count=1 msg=Job completed
0.2071,Event,ADDED,eval-sanitize-30-r0-197-srpnv.18d4f7a1fb77d663,reason=Scheduled count=None msg=Successfully assigned compute/eval-sanitize-30-r0-197-srpnv to kind-worker
0.2078,Event,ADDED,eval-sanitize-30-r0-197-srpnv.18d4f7a219261643,"reason=Pulled count=1 msg=Container image ""busybox:musl"" already present on machine"
0.2083,Event,ADDED,eval-sanitize-30-r0-197-srpnv.18d4f7a21af7f175,reason=Created count=1 msg=Created container: task
0.2088,Event,ADDED,eval-sanitize-30-r0-197-srpnv.18d4f7a220346746,reason=Started count=1 msg=Started container task
0.2092,Event,ADDED,eval-sanitize-30-r0-197.18d4f7a1f4731558,reason=SuccessfulCreate count=1 msg=Created pod: eval-sanitize-30-r0-197-srpnv
0.2098,Event,ADDED,eval-sanitize-30-r0-197.18d4f7a7bcf392f3,reason=Completed count=1 msg=Job completed
0.2104,Event,ADDED,eval-sanitize-30-r0-198-kn8vs.18d4f7a231a98285,reason=Scheduled count=None msg=Successfully assigned compute/eval-sanitize-30-r0-198-kn8vs to kind-worker2
0.2109,Event,ADDED,eval-sanitize-30-r0-198-kn8vs.18d4f7a24c23efe5,"reason=Pulled count=1 msg=Container image ""busybox:musl"" already present on machine"
0.2114,Event,ADDED,eval-sanitize-30-r0-198-kn8vs.18d4f7a24da2f7e3,reason=Created count=1 msg=Created container: task
0.2115,TaskRequest,MODIFIED,eval-sanitize-50-r3-000,phase=Scheduled job=None
0.2121,Event,ADDED,eval-sanitize-30-r0-198-kn8vs.18d4f7a250be656e,reason=Started count=1 msg=Started container task
0.2124,Event,ADDED,eval-sanitize-30-r0-198.18d4f7a22d5c683f,reason=SuccessfulCreate count=1 msg=Created pod: eval-sanitize-30-r0-198-kn8vs
0.2127,Event,ADDED,eval-sanitize-30-r0-198.18d4f7a7cd0cedb9,reason=Completed count=1 msg=Job completed
0.2137,Event,ADDED,eval-sanitize-30-r0-199-pchwm.18d4f7a26d04ce44,reason=Scheduled count=None msg=Successfully assigned compute/eval-sanitize-30-r0-199-pchwm to kind-worker5
0.2142,Event,ADDED,eval-sanitize-30-r0-199-pchwm.18d4f7a288ad2bb8,"reason=Pulled count=1 msg=Container image ""busybox:musl"" already present on machine"
0.2146,Event,ADDED,eval-sanitize-30-r0-199-pchwm.18d4f7a28a2826ca,reason=Created count=1 msg=Created container: task
0.2152,Event,ADDED,eval-sanitize-30-r0-199-pchwm.18d4f7a292278227,reason=Started count=1 msg=Started container task
0.2172,Node,MODIFIED,kind-worker5,taints=0
0.2177,Event,ADDED,eval-sanitize-30-r0-199.18d4f7a2696d0df1,reason=SuccessfulCreate count=1 msg=Created pod: eval-sanitize-30-r0-199-pchwm
0.2181,Event,ADDED,eval-sanitize-30-r0-199.18d4f7a8186b3266,reason=Completed count=1 msg=Job completed
0.2184,Event,ADDED,eval-sanitize-30-r1-000-fj7gj.18d4f7b289fcc432,reason=Scheduled count=None msg=Successfully assigned compute/eval-sanitize-30-r1-000-fj7gj to kind-worker
0.2188,Event,ADDED,eval-sanitize-30-r1-000-fj7gj.18d4f7b2a618ffb0,"reason=Pulled count=1 msg=Container image ""busybox:musl"" already present on machine"
0.2193,Event,ADDED,eval-sanitize-30-r1-000-fj7gj.18d4f7b2a7441ace,reason=Created count=1 msg=Created container: task
0.2198,Event,ADDED,eval-sanitize-30-r1-000-fj7gj.18d4f7b2b0264201,reason=Started count=1 msg=Started container task
0.2202,Event,ADDED,eval-sanitize-30-r1-000.18d4f7b288a5c80d,reason=SuccessfulCreate count=1 msg=Created pod: eval-sanitize-30-r1-000-fj7gj
0.2222,Pod,MODIFIED,eval-sanitize-50-r3-000-p74fk,phase=Pending node=kind-worker5
0.2227,Event,ADDED,eval-sanitize-30-r1-000.18d4f7b819901fde,reason=Completed count=1 msg=Job completed
0.2231,Event,ADDED,eval-sanitize-30-r1-001-4cvv9.18d4f7b2ccf50edc,reason=Scheduled count=None msg=Successfully assigned compute/eval-sanitize-30-r1-001-4cvv9 to kind-worker5
0.2234,Event,ADDED,eval-sanitize-30-r1-001-4cvv9.18d4f7b2e653df24,"reason=Pulled count=1 msg=Container image ""busybox:musl"" already present on machine"
0.2238,Event,ADDED,eval-sanitize-30-r1-001-4cvv9.18d4f7b2e81fa147,reason=Created count=1 msg=Created container: task
0.2245,Event,ADDED,eval-sanitize-30-r1-001-4cvv9.18d4f7b2f679a12e,reason=Started count=1 msg=Started container task
0.2248,Event,ADDED,eval-sanitize-30-r1-001.18d4f7b2c1fa6c5f,reason=SuccessfulCreate count=1 msg=Created pod: eval-sanitize-30-r1-001-4cvv9
0.2256,Event,ADDED,eval-sanitize-30-r1-001.18d4f7b86dc35013,reason=Completed count=1 msg=Job completed
0.2261,Event,ADDED,eval-sanitize-30-r1-002-pd7x8.18d4f7b302f5ae70,reason=Scheduled count=None msg=Successfully assigned compute/eval-sanitize-30-r1-002-pd7x8 to kind-worker4
0.2267,Event,ADDED,eval-sanitize-30-r1-002-pd7x8.18d4f7b32ce42d20,"reason=Pulled count=1 msg=Container image ""busybox:musl"" already present on machine"
0.2271,Event,ADDED,eval-sanitize-30-r1-002-pd7x8.18d4f7b32f87adb8,reason=Created count=1 msg=Created container: task
0.2274,Event,ADDED,eval-sanitize-30-r1-002-pd7x8.18d4f7b33ae920fc,reason=Started count=1 msg=Started container task
0.2278,Event,ADDED,eval-sanitize-30-r1-002.18d4f7b30216a51f,reason=SuccessfulCreate count=1 msg=Created pod: eval-sanitize-30-r1-002-pd7x8
0.228,Event,ADDED,eval-sanitize-30-r1-002.18d4f7b8d07df36a,reason=Completed count=1 msg=Job completed
0.2282,Event,ADDED,eval-sanitize-30-r1-003-4hxfp.18d4f7b33dbea6f9,reason=Scheduled count=None msg=Successfully assigned compute/eval-sanitize-30-r1-003-4hxfp to kind-worker2
0.2284,Event,ADDED,eval-sanitize-30-r1-003-4hxfp.18d4f7b3607b1e79,"reason=Pulled count=1 msg=Container image ""busybox:musl"" already present on machine"
0.2287,Event,ADDED,eval-sanitize-30-r1-003-4hxfp.18d4f7b361c08144,reason=Created count=1 msg=Created container: task
0.2289,Event,ADDED,eval-sanitize-30-r1-003-4hxfp.18d4f7b36743f2e3,reason=Started count=1 msg=Started container task
0.229,Event,ADDED,eval-sanitize-30-r1-003.18d4f7b33cd8491b,reason=SuccessfulCreate count=1 msg=Created pod: eval-sanitize-30-r1-003-4hxfp
0.2292,Event,ADDED,eval-sanitize-30-r1-003.18d4f7b8d4575e94,reason=Completed count=1 msg=Job completed
0.2294,Event,ADDED,eval-sanitize-30-r1-004-cctrr.18d4f7b37751133e,reason=Scheduled count=None msg=Successfully assigned compute/eval-sanitize-30-r1-004-cctrr to kind-worker3
0.2297,Event,ADDED,eval-sanitize-30-r1-004-cctrr.18d4f7b39716bf57,"reason=Pulled count=1 msg=Container image ""busybox:musl"" already present on machine"
0.2298,Event,ADDED,eval-sanitize-30-r1-004-cctrr.18d4f7b398408360,reason=Created count=1 msg=Created container: task
0.2303,Event,ADDED,eval-sanitize-30-r1-004-cctrr.18d4f7b3a05548cc,reason=Started count=1 msg=Started container task
0.2315,Event,ADDED,eval-sanitize-30-r1-004.18d4f7b376585125,reason=SuccessfulCreate count=1 msg=Created pod: eval-sanitize-30-r1-004-cctrr
0.2321,Event,ADDED,eval-sanitize-30-r1-004.18d4f7b91fd4fbbd,reason=Completed count=1 msg=Job completed
0.2325,Event,ADDED,eval-sanitize-30-r1-005-mjm2t.18d4f7b3b203b324,reason=Scheduled count=None msg=Successfully assigned compute/eval-sanitize-30-r1-005-mjm2t to kind-worker3
0.2329,Event,ADDED,eval-sanitize-30-r1-005-mjm2t.18d4f7b3d27f4b02,"reason=Pulled count=1 msg=Container image ""busybox:musl"" already present on machine"
0.2331,Event,ADDED,eval-sanitize-30-r1-005-mjm2t.18d4f7b3d3c06bbe,reason=Created count=1 msg=Created container: task
0.2333,Event,ADDED,eval-sanitize-30-r1-005-mjm2t.18d4f7b3d61d56e4,reason=Started count=1 msg=Started container task
0.2336,Event,ADDED,eval-sanitize-30-r1-005.18d4f7b3b147cd08,reason=SuccessfulCreate count=1 msg=Created pod: eval-sanitize-30-r1-005-mjm2t
0.2353,Node,MODIFIED,kind-worker5,taints=0
0.2358,Event,ADDED,eval-sanitize-30-r1-005.18d4f7b95b99235f,reason=Completed count=1 msg=Job completed
0.2361,Event,ADDED,eval-sanitize-30-r1-006-wh4fw.18d4f7b3f1aba633,reason=Scheduled count=None msg=Successfully assigned compute/eval-sanitize-30-r1-006-wh4fw to kind-worker3
0.2364,Event,ADDED,eval-sanitize-30-r1-006-wh4fw.18d4f7b40d9edfb8,"reason=Pulled count=1 msg=Container image ""busybox:musl"" already present on machine"
0.2369,Event,ADDED,eval-sanitize-30-r1-006-wh4fw.18d4f7b40ed44cc8,reason=Created count=1 msg=Created container: task
0.2372,Event,ADDED,eval-sanitize-30-r1-006-wh4fw.18d4f7b419fb33a7,reason=Started count=1 msg=Started container task
0.2376,Event,ADDED,eval-sanitize-30-r1-006.18d4f7b3f0d3b239,reason=SuccessfulCreate count=1 msg=Created pod: eval-sanitize-30-r1-006-wh4fw
0.2379,Event,ADDED,eval-sanitize-30-r1-006.18d4f7b955af72a7,reason=Completed count=1 msg=Job completed
0.2383,Event,ADDED,eval-sanitize-30-r1-007-st92s.18d4f7b4283e4694,reason=Scheduled count=None msg=Successfully assigned compute/eval-sanitize-30-r1-007-st92s to kind-worker3
0.2387,Event,ADDED,eval-sanitize-30-r1-007-st92s.18d4f7b44ec28755,"reason=Pulled count=1 msg=Container image ""busybox:musl"" already present on machine"
0.2391,Event,ADDED,eval-sanitize-30-r1-007-st92s.18d4f7b44ff9b965,reason=Created count=1 msg=Created container: task
0.2394,Event,ADDED,eval-sanitize-30-r1-007-st92s.18d4f7b45b32614e,reason=Started count=1 msg=Started container task
0.2396,Event,ADDED,eval-sanitize-30-r1-007.18d4f7b427a5433d,reason=SuccessfulCreate count=1 msg=Created pod: eval-sanitize-30-r1-007-st92s
0.2398,Event,ADDED,eval-sanitize-30-r1-007.18d4f7b9d0a79ae1,reason=Completed count=1 msg=Job completed
0.2399,Event,ADDED,eval-sanitize-30-r1-008-bnzvc.18d4f7b46ec9f884,reason=Scheduled count=None msg=Successfully assigned compute/eval-sanitize-30-r1-008-bnzvc to kind-worker3
0.2402,Event,ADDED,eval-sanitize-30-r1-008-bnzvc.18d4f7b490c7df0c,"reason=Pulled count=1 msg=Container image ""busybox:musl"" already present on machine"
0.2404,Event,ADDED,eval-sanitize-30-r1-008-bnzvc.18d4f7b49209dff8,reason=Created count=1 msg=Created container: task
0.2406,Event,ADDED,eval-sanitize-30-r1-008-bnzvc.18d4f7b4a1ebc0f4,reason=Started count=1 msg=Started container task
0.2407,Event,ADDED,eval-sanitize-30-r1-008.18d4f7b46e2e82b8,reason=SuccessfulCreate count=1 msg=Created pod: eval-sanitize-30-r1-008-bnzvc
0.2409,Event,ADDED,eval-sanitize-30-r1-008.18d4f7ba0c801039,reason=Completed count=1 msg=Job completed
0.2411,Event,ADDED,eval-sanitize-30-r1-009-xl4wc.18d4f7b4a4291762,"reason=FailedScheduling count=None msg=0/6 nodes are available: 1 c_wall violated: 1 conflicting context pair(s) with node memory, 5 node(s) had untolerated taint(s). no new claims to deallocate, preemption: 0/6 nodes are available: 1 No preemption victims found for incoming pod, 5 Preemption is not helpful for scheduling."
0.2413,Event,ADDED,eval-sanitize-30-r1-009-xl4wc.18d4f7b4a4df4ff8,"reason=FailedScheduling count=None msg=0/6 nodes are available: 1 c_wall violated: 1 conflicting context pair(s) with node memory, 5 node(s) had untolerated taint(s). no new claims to deallocate, preemption: 0/6 nodes are available: 1 No preemption victims found for incoming pod, 5 Preemption is not helpful for scheduling."
0.2419,Event,ADDED,eval-sanitize-30-r1-009-xl4wc.18d4f7ba07c954b9,"reason=FailedScheduling count=None msg=0/6 nodes are available: 2 c_wall violated: 1 conflicting context pair(s) with node memory, 4 node(s) had untolerated taint(s). no new claims to deallocate, preemption: 0/6 nodes are available: 2 No preemption victims found for incoming pod, 4 Preemption is not helpful for scheduling."
0.2423,Event,ADDED,eval-sanitize-30-r1-009-xl4wc.18d4f7ba56cf7127,reason=Scheduled count=None msg=Successfully assigned compute/eval-sanitize-30-r1-009-xl4wc to kind-worker4
0.2428,Event,ADDED,eval-sanitize-30-r1-009-xl4wc.18d4f7ba747feaee,"reason=Pulled count=1 msg=Container image ""busybox:musl"" already present on machine"
0.2432,Event,ADDED,eval-sanitize-30-r1-009-xl4wc.18d4f7ba762c2244,reason=Created count=1 msg=Created container: task
0.2434,Event,ADDED,eval-sanitize-30-r1-009-xl4wc.18d4f7ba79338d56,reason=Started count=1 msg=Started container task
0.2436,Event,ADDED,eval-sanitize-30-r1-009.18d4f7b4a3cffadf,reason=SuccessfulCreate count=1 msg=Created pod: eval-sanitize-30-r1-009-xl4wc
0.2438,Event,ADDED,eval-sanitize-30-r1-009.18d4f7bfcffba726,reason=Completed count=1 msg=Job completed
0.2441,Event,ADDED,eval-sanitize-30-r1-010-fbtrj.18d4f7b4dc008cea,"reason=FailedScheduling count=None msg=0/6 nodes are available: 1 c_wall violated: 3 conflicting context pair(s) with node memory, 5 node(s) had untolerated taint(s). no new claims to deallocate, preemption: 0/6 nodes are available: 1 No preemption victims found for incoming pod, 5 Preemption is not helpful for scheduling."
0.2444,Event,ADDED,eval-sanitize-30-r1-010-fbtrj.18d4f7b4dc9a8f27,"reason=FailedScheduling count=None msg=0/6 nodes are available: 1 c_wall violated: 3 conflicting context pair(s) with node memory, 5 node(s) had untolerated taint(s). no new claims to deallocate, preemption: 0/6 nodes are available: 1 No preemption victims found for incoming pod, 5 Preemption is not helpful for scheduling."
0.2445,Event,ADDED,eval-sanitize-30-r1-010-fbtrj.18d4f7b9eecd024d,reason=Scheduled count=None msg=Successfully assigned compute/eval-sanitize-30-r1-010-fbtrj to kind-worker
0.2449,Event,ADDED,eval-sanitize-30-r1-010-fbtrj.18d4f7ba10738f1b,"reason=Pulled count=1 msg=Container image ""busybox:musl"" already present on machine"
0.2451,Event,ADDED,eval-sanitize-30-r1-010-fbtrj.18d4f7ba1252017a,reason=Created count=1 msg=Created container: task
0.2452,Event,ADDED,eval-sanitize-30-r1-010-fbtrj.18d4f7ba15d8251e,reason=Started count=1 msg=Started container task
0.2459,Event,ADDED,eval-sanitize-30-r1-010.18d4f7b4dbb0696b,reason=SuccessfulCreate count=1 msg=Created pod: eval-sanitize-30-r1-010-fbtrj
0.2463,Event,ADDED,eval-sanitize-30-r1-010.18d4f7bf57862744,reason=Completed count=1 msg=Job completed
0.2464,Event,ADDED,eval-sanitize-30-r1-011-65nl4.18d4f7b51a193d8d,reason=Scheduled count=None msg=Successfully assigned compute/eval-sanitize-30-r1-011-65nl4 to kind-worker3
0.2466,Event,ADDED,eval-sanitize-30-r1-011-65nl4.18d4f7b536faa360,"reason=Pulled count=1 msg=Container image ""busybox:musl"" already present on machine"
0.2468,Event,ADDED,eval-sanitize-30-r1-011-65nl4.18d4f7b538386788,reason=Created count=1 msg=Created container: task
0.2472,Event,ADDED,eval-sanitize-30-r1-011-65nl4.18d4f7b53c572f9c,reason=Started count=1 msg=Started container task
0.2473,Event,ADDED,eval-sanitize-30-r1-011.18d4f7b5196cc9f4,reason=SuccessfulCreate count=1 msg=Created pod: eval-sanitize-30-r1-011-65nl4
0.2475,Event,ADDED,eval-sanitize-30-r1-011.18d4f7bac1cab283,reason=Completed count=1 msg=Job completed
0.248,Event,ADDED,eval-sanitize-30-r1-012-db7nz.18d4f7b5524ed0c6,"reason=FailedScheduling count=None msg=0/6 nodes are available: 1 c_wall violated: 3 conflicting context pair(s) with node memory, 5 node(s) had untolerated taint(s). no new claims to deallocate, preemption: 0/6 nodes are available: 1 No preemption victims found for incoming pod, 5 Preemption is not helpful for scheduling."
0.2483,Event,ADDED,eval-sanitize-30-r1-012-db7nz.18d4f7b552fd1209,"reason=FailedScheduling count=None msg=0/6 nodes are available: 1 c_wall violated: 3 conflicting context pair(s) with node memory, 5 node(s) had untolerated taint(s). no new claims to deallocate, preemption: 0/6 nodes are available: 1 No preemption victims found for incoming pod, 5 Preemption is not helpful for scheduling."
0.2485,Event,ADDED,eval-sanitize-30-r1-012-db7nz.18d4f7b9f61f3d4f,reason=Scheduled count=None msg=Successfully assigned compute/eval-sanitize-30-r1-012-db7nz to kind-worker
0.2489,Event,ADDED,eval-sanitize-30-r1-012-db7nz.18d4f7ba147e4f78,"reason=Pulled count=1 msg=Container image ""busybox:musl"" already present on machine"
0.2491,Event,ADDED,eval-sanitize-30-r1-012-db7nz.18d4f7ba15f6d2eb,reason=Created count=1 msg=Created container: task
0.2493,Event,ADDED,eval-sanitize-30-r1-012-db7nz.18d4f7ba1a436cbe,reason=Started count=1 msg=Started container task
0.2495,Event,ADDED,eval-sanitize-30-r1-012.18d4f7b551f9036e,reason=SuccessfulCreate count=1 msg=Created pod: eval-sanitize-30-r1-012-db7nz
0.2499,Event,ADDED,eval-sanitize-30-r1-012.18d4f7bf58c218cf,reason=Completed count=1 msg=Job completed
0.2501,Event,ADDED,eval-sanitize-30-r1-013-6dvdk.18d4f7b58dd7fc54,"reason=FailedScheduling count=None msg=0/6 nodes are available: 1 c_wall violated: 2 conflicting context pair(s) with node memory, 5 node(s) had untolerated taint(s). no new claims to deallocate, preemption: 0/6 nodes are available: 1 No preemption victims found for incoming pod, 5 Preemption is not helpful for scheduling."
0.2503,Event,ADDED,eval-sanitize-30-r1-013-6dvdk.18d4f7b58e90efe6,"reason=FailedScheduling count=None msg=0/6 nodes are available: 1 c_wall violated: 2 conflicting context pair(s) with node memory, 5 node(s) had untolerated taint(s). no new claims to deallocate, preemption: 0/6 nodes are available: 1 No preemption victims found for incoming pod, 5 Preemption is not helpful for scheduling."
0.2507,Event,ADDED,eval-sanitize-30-r1-013-6dvdk.18d4f7b9deec8eb3,reason=Scheduled count=None msg=Successfully assigned compute/eval-sanitize-30-r1-013-6dvdk to kind-worker
0.251,Event,ADDED,eval-sanitize-30-r1-013-6dvdk.18d4f7b9fabef8a5,"reason=Pulled count=1 msg=Container image ""busybox:musl"" already present on machine"
0.2512,Event,ADDED,eval-sanitize-30-r1-013-6dvdk.18d4f7b9fc85ce8c,reason=Created count=1 msg=Created container: task
0.2514,Event,ADDED,eval-sanitize-30-r1-013-6dvdk.18d4f7b9ff3e977d,reason=Started count=1 msg=Started container task
0.2518,Event,ADDED,eval-sanitize-30-r1-013.18d4f7b58d857f7e,reason=SuccessfulCreate count=1 msg=Created pod: eval-sanitize-30-r1-013-6dvdk
0.252,Event,ADDED,eval-sanitize-30-r1-013.18d4f7bf59736762,reason=Completed count=1 msg=Job completed
0.2522,Event,ADDED,eval-sanitize-30-r1-014-vsj6m.18d4f7b5cc2e5723,"reason=FailedScheduling count=None msg=0/6 nodes are available: 1 c_wall violated: 1 conflicting context pair(s) with node memory, 5 node(s) had untolerated taint(s). no new claims to deallocate, preemption: 0/6 nodes are available: 1 No preemption victims found for incoming pod, 5 Preemption is not helpful for scheduling."
0.2525,Event,ADDED,eval-sanitize-30-r1-014-vsj6m.18d4f7b5cccf0b9f,"reason=FailedScheduling count=None msg=0/6 nodes are available: 1 c_wall violated: 1 conflicting context pair(s) with node memory, 5 node(s) had untolerated taint(s). no new claims to deallocate, preemption: 0/6 nodes are available: 1 No preemption victims found for incoming pod, 5 Preemption is not helpful for scheduling."
0.2527,Event,ADDED,eval-sanitize-30-r1-014-vsj6m.18d4f7ba0287c8b8,"reason=FailedScheduling count=None msg=0/6 nodes are available: 1 c_wall violated: 1 conflicting context pair(s) with node memory, 1 c_wall violated: 2 conflicting context pair(s) with node memory, 4 node(s) had untolerated taint(s). no new claims to deallocate, preemption: 0/6 nodes are available: 2 No preemption victims found for incoming pod, 4 Preemption is not helpful for scheduling."
0.2528,Event,ADDED,eval-sanitize-30-r1-014-vsj6m.18d4f7ba4b86bfa8,reason=Scheduled count=None msg=Successfully assigned compute/eval-sanitize-30-r1-014-vsj6m to kind-worker4
0.2531,Event,ADDED,eval-sanitize-30-r1-014-vsj6m.18d4f7ba6ed52f18,"reason=Pulled count=1 msg=Container image ""busybox:musl"" already present on machine"
0.2533,Event,ADDED,eval-sanitize-30-r1-014-vsj6m.18d4f7ba71160f34,reason=Created count=1 msg=Created container: task
0.2536,Event,ADDED,eval-sanitize-30-r1-014-vsj6m.18d4f7ba74a9ccbd,reason=Started count=1 msg=Started container task
0.2539,Event,ADDED,eval-sanitize-30-r1-014.18d4f7b5c8da8953,reason=SuccessfulCreate count=1 msg=Created pod: eval-sanitize-30-r1-014-vsj6m
0.2543,Event,ADDED,eval-sanitize-30-r1-014.18d4f7bfd08ddc95,reason=Completed count=1 msg=Job completed
0.2545,Event,ADDED,eval-sanitize-30-r1-015-d2jch.18d4f7b604cf04c6,reason=Scheduled count=None msg=Successfully assigned compute/eval-sanitize-30-r1-015-d2jch to kind-worker3
0.2546,Event,ADDED,eval-sanitize-30-r1-015-d2jch.18d4f7b62042aecd,"reason=Pulled count=1 msg=Container image ""busybox:musl"" already present on machine"
0.2548,Event,ADDED,eval-sanitize-30-r1-015-d2jch.18d4f7b621659937,reason=Created count=1 msg=Created container: task
0.2552,Event,ADDED,eval-sanitize-30-r1-015-d2jch.18d4f7b629e9cc34,reason=Started count=1 msg=Started container task
0.2554,Event,ADDED,eval-sanitize-30-r1-015.18d4f7b604211271,reason=SuccessfulCreate count=1 msg=Created pod: eval-sanitize-30-r1-015-d2jch
0.2556,Event,ADDED,eval-sanitize-30-r1-015.18d4f7bba73d332a,reason=Completed count=1 msg=Job completed
0.256,Event,ADDED,eval-sanitize-30-r1-016-kwgh4.18d4f7b641b92fac,"reason=FailedScheduling count=None msg=0/6 nodes are available: 1 c_wall violated: 3 conflicting context pair(s) with node memory, 5 node(s) had untolerated taint(s). no new claims to deallocate, preemption: 0/6 nodes are available: 1 No preemption victims found for incoming pod, 5 Preemption is not helpful for scheduling."
0.2562,Event,ADDED,eval-sanitize-30-r1-016-kwgh4.18d4f7b64267c363,"reason=FailedScheduling count=None msg=0/6 nodes are available: 1 c_wall violated: 3 conflicting context pair(s) with node memory, 5 node(s) had untolerated taint(s). no new claims to deallocate, preemption: 0/6 nodes are available: 1 No preemption victims found for incoming pod, 5 Preemption is not helpful for scheduling."
0.2564,Event,ADDED,eval-sanitize-30-r1-016-kwgh4.18d4f7b9d9cbdb06,reason=Scheduled count=None msg=Successfully assigned compute/eval-sanitize-30-r1-016-kwgh4 to kind-worker
0.2565,Event,ADDED,eval-sanitize-30-r1-016-kwgh4.18d4f7b9f627911e,"reason=Pulled count=1 msg=Container image ""busybox:musl"" already present on machine"
0.2571,Event,ADDED,eval-sanitize-30-r1-016-kwgh4.18d4f7b9f81976e9,reason=Created count=1 msg=Created container: task
0.2575,Event,ADDED,eval-sanitize-30-r1-016-kwgh4.18d4f7b9fb4d83ac,reason=Started count=1 msg=Started container task
0.2578,Event,ADDED,eval-sanitize-30-r1-016.18d4f7b64165238d,reason=SuccessfulCreate count=1 msg=Created pod: eval-sanitize-30-r1-016-kwgh4
0.2582,Event,ADDED,eval-sanitize-30-r1-016.18d4f7bf5a068cfe,reason=Completed count=1 msg=Job completed
0.2584,Event,ADDED,eval-sanitize-30-r1-017-4njv5.18d4f7b67be0df89,"reason=FailedScheduling count=None msg=0/6 nodes are available: 1 c_wall violated: 2 conflicting context pair(s) with node memory, 5 node(s) had untolerated taint(s). no new claims to deallocate, preemption: 0/6 nodes are available: 1 No preemption victims found for incoming pod, 5 Preemption is not helpful for scheduling."
0.2587,Event,ADDED,eval-sanitize-30-r1-017-4njv5.18d4f7b67cb6bf54,"reason=FailedScheduling count=None msg=0/6 nodes are available: 1 c_wall violated: 2 conflicting context pair(s) with node memory, 5 node(s) had untolerated taint(s). no new claims to deallocate, preemption: 0/6 nodes are available: 1 No preemption victims found for incoming pod, 5 Preemption is not helpful for scheduling."
0.259,Event,ADDED,eval-sanitize-30-r1-017-4njv5.18d4f7b9deaa21ad,reason=Scheduled count=None msg=Successfully assigned compute/eval-sanitize-30-r1-017-4njv5 to kind-worker
0.2592,Event,ADDED,eval-sanitize-30-r1-017-4njv5.18d4f7b9f9c8702e,"reason=Pulled count=1 msg=Container image ""busybox:musl"" already present on machine"
0.2594,Event,ADDED,eval-sanitize-30-r1-017-4njv5.18d4f7b9fbd4ccf1,reason=Created count=1 msg=Created container: task
0.2596,Event,ADDED,eval-sanitize-30-r1-017-4njv5.18d4f7b9fea010e1,reason=Started count=1 msg=Started container task
0.26,Event,ADDED,eval-sanitize-30-r1-017.18d4f7b67b8a9a2f,reason=SuccessfulCreate count=1 msg=Created pod: eval-sanitize-30-r1-017-4njv5
0.2601,Event,ADDED,eval-sanitize-30-r1-017.18d4f7bf56b7962d,reason=Completed count=1 msg=Job completed
0.2603,Event,ADDED,eval-sanitize-30-r1-018-zw6r6.18d4f7b6bb56d512,reason=Scheduled count=None msg=Successfully assigned compute/eval-sanitize-30-r1-018-zw6r6 to kind-worker3
0.2605,Event,ADDED,eval-sanitize-30-r1-018-zw6r6.18d4f7b6d7aee355,"reason=Pulled count=1 msg=Container image ""busybox:musl"" already present on machine"
0.2608,Event,ADDED,eval-sanitize-30-r1-018-zw6r6.18d4f7b6d8e3b6e1,reason=Created count=1 msg=Created container: task
0.261,Event,ADDED,eval-sanitize-30-r1-018-zw6r6.18d4f7b6e3bb5eb5,reason=Started count=1 msg=Started container task
0.2612,Event,ADDED,eval-sanitize-30-r1-018.18d4f7b6bab2233e,reason=SuccessfulCreate count=1 msg=Created pod: eval-sanitize-30-r1-018-zw6r6
0.2614,Event,ADDED,eval-sanitize-30-r1-018.18d4f7bc61188a44,reason=Completed count=1 msg=Job completed
0.2616,Event,ADDED,eval-sanitize-30-r1-019-hnqzk.18d4f7b6f4725a8d,"reason=FailedScheduling count=None msg=0/6 nodes are available: 1 c_wall violated: 1 conflicting context pair(s) with node memory, 5 node(s) had untolerated taint(s). no new claims to deallocate, preemption: 0/6 nodes are available: 1 No preemption victims found for incoming pod, 5 Preemption is not helpful for scheduling."
0.2619,Event,ADDED,eval-sanitize-30-r1-019-hnqzk.18d4f7b6f518d837,"reason=FailedScheduling count=None msg=0/6 nodes are available: 1 c_wall violated: 1 conflicting context pair(s) with node memory, 5 node(s) had untolerated taint(s). no new claims to deallocate, preemption: 0/6 nodes are available: 1 No preemption victims found for incoming pod, 5 Preemption is not helpful for scheduling."
0.2623,Event,ADDED,eval-sanitize-30-r1-019-hnqzk.18d4f7ba082a7263,"reason=FailedScheduling count=None msg=0/6 nodes are available: 2 c_wall violated: 1 conflicting context pair(s) with node memory, 4 node(s) had untolerated taint(s). no new claims to deallocate, preemption: 0/6 nodes are available: 2 No preemption victims found for incoming pod, 4 Preemption is not helpful for scheduling."
0.2626,Event,ADDED,eval-sanitize-30-r1-019-hnqzk.18d4f7ba6cf04a8a,"reason=FailedScheduling count=None msg=0/6 nodes are available: 1 c_wall violated: 1 conflicting context pair(s) with node memory, 1 c_wall violated: 2 conflicting context pair(s) with node memory, 4 node(s) had untolerated taint(s). no new claims to deallocate, preemption: 0/6 nodes are available: 2 No preemption victims found for incoming pod, 4 Preemption is not helpful for scheduling."
0.2629,Event,ADDED,eval-sanitize-30-r1-019-hnqzk.18d4f7ba7dff7762,"reason=FailedScheduling count=None msg=0/6 nodes are available: 1 c_wall violated: 1 conflicting context pair(s) with node memory, 1 c_wall violated: 2 conflicting context pair(s) with node memory, 4 node(s) had untolerated taint(s). no new claims to deallocate, preemption: 0/6 nodes are available: 2 No preemption victims found for incoming pod, 4 Preemption is not helpful for scheduling."
0.2631,Event,ADDED,eval-sanitize-30-r1-019-hnqzk.18d4f7bad94030c9,reason=Scheduled count=None msg=Successfully assigned compute/eval-sanitize-30-r1-019-hnqzk to kind-worker2
0.2633,Event,ADDED,eval-sanitize-30-r1-019-hnqzk.18d4f7baf9e3d5d8,"reason=Pulled count=1 msg=Container image ""busybox:musl"" already present on machine"
0.2634,Event,ADDED,eval-sanitize-30-r1-019-hnqzk.18d4f7bafba30ef0,reason=Created count=1 msg=Created container: task
0.2636,Event,ADDED,eval-sanitize-30-r1-019-hnqzk.18d4f7bb026aad5d,reason=Started count=1 msg=Started container task
0.2638,Event,ADDED,eval-sanitize-30-r1-019.18d4f7b6f4255d9a,reason=SuccessfulCreate count=1 msg=Created pod: eval-sanitize-30-r1-019-hnqzk
0.264,Event,ADDED,eval-sanitize-30-r1-019.18d4f7c0eb514a5f,reason=Completed count=1 msg=Job completed
0.2641,Event,ADDED,eval-sanitize-30-r1-020-6m9rn.18d4f7b731f97cca,"reason=FailedScheduling count=None msg=0/6 nodes are available: 1 c_wall violated: 2 conflicting context pair(s) with node memory, 5 node(s) had untolerated taint(s). no new claims to deallocate, preemption: 0/6 nodes are available: 1 No preemption victims found for incoming pod, 5 Preemption is not helpful for scheduling."
0.2643,Event,ADDED,eval-sanitize-30-r1-020-6m9rn.18d4f7b73298a8ed,"reason=FailedScheduling count=None msg=0/6 nodes are available: 1 c_wall violated: 2 conflicting context pair(s) with node memory, 5 node(s) had untolerated taint(s). no new claims to deallocate, preemption: 0/6 nodes are available: 1 No preemption victims found for incoming pod, 5 Preemption is not helpful for scheduling."
0.2645,Event,ADDED,eval-sanitize-30-r1-020-6m9rn.18d4f7b9ee8f9809,reason=Scheduled count=None msg=Successfully assigned compute/eval-sanitize-30-r1-020-6m9rn to kind-worker
0.2647,Event,ADDED,eval-sanitize-30-r1-020-6m9rn.18d4f7ba0f9248cf,"reason=Pulled count=1 msg=Container image ""busybox:musl"" already present on machine"
0.2649,Event,ADDED,eval-sanitize-30-r1-020-6m9rn.18d4f7ba11287faa,reason=Created count=1 msg=Created container: task
0.2654,Event,ADDED,eval-sanitize-30-r1-020-6m9rn.18d4f7ba14f67b8e,reason=Started count=1 msg=Started container task
0.2657,Event,ADDED,eval-sanitize-30-r1-020.18d4f7b731af0482,reason=SuccessfulCreate count=1 msg=Created pod: eval-sanitize-30-r1-020-6m9rn
0.2661,Event,ADDED,eval-sanitize-30-r1-020.18d4f7bf56615acd,reason=Completed count=1 msg=Job completed
0.2665,Event,ADDED,eval-sanitize-30-r1-021-5xl5r.18d4f7b76a7afa0b,reason=Scheduled count=None msg=Successfully assigned compute/eval-sanitize-30-r1-021-5xl5r to kind-worker3
0.2667,Event,ADDED,eval-sanitize-30-r1-021-5xl5r.18d4f7b79b31e1f7,"reason=Pulled count=1 msg=Container image ""busybox:musl"" already present on machine"
0.2669,Event,ADDED,eval-sanitize-30-r1-021-5xl5r.18d4f7b79c764fdc,reason=Created count=1 msg=Created container: task
0.267,Event,ADDED,eval-sanitize-30-r1-021-5xl5r.18d4f7b7a1b40297,reason=Started count=1 msg=Started container task
0.2674,Event,ADDED,eval-sanitize-30-r1-021.18d4f7b769cfdd27,reason=SuccessfulCreate count=1 msg=Created pod: eval-sanitize-30-r1-021-5xl5r
0.2676,Event,ADDED,eval-sanitize-30-r1-021.18d4f7bd1351d48a,reason=Completed count=1 msg=Job completed
0.2678,Event,ADDED,eval-sanitize-30-r1-022-jd2rp.18d4f7b7a5cc17e0,"reason=FailedScheduling count=None msg=0/6 nodes are available: 1 c_wall violated: 1 conflicting context pair(s) with node memory, 5 node(s) had untolerated taint(s). no new claims to deallocate, preemption: 0/6 nodes are available: 1 No preemption victims found for incoming pod, 5 Preemption is not helpful for scheduling."
0.268,Event,ADDED,eval-sanitize-30-r1-022-jd2rp.18d4f7b7acb663a7,"reason=FailedScheduling count=None msg=0/6 nodes are available: 1 c_wall violated: 1 conflicting context pair(s) with node memory, 5 node(s) had untolerated taint(s). no new claims to deallocate, preemption: 0/6 nodes are available: 1 No preemption victims found for incoming pod, 5 Preemption is not helpful for scheduling."
0.2682,Event,ADDED,eval-sanitize-30-r1-022-jd2rp.18d4f7ba0e860b76,"reason=FailedScheduling count=None msg=0/6 nodes are available: 2 c_wall violated: 1 conflicting context pair(s) with node memory, 4 node(s) had untolerated taint(s). no new claims to deallocate, preemption: 0/6 nodes are available: 2 No preemption victims found for incoming pod, 4 Preemption is not helpful for scheduling."
0.2684,Event,ADDED,eval-sanitize-30-r1-022-jd2rp.18d4f7ba7306aa44,"reason=FailedScheduling count=None msg=0/6 nodes are available: 1 c_wall violated: 1 conflicting context pair(s) with node memory, 1 c_wall violated: 2 conflicting context pair(s) with node memory, 4 node(s) had untolerated taint(s). no new claims to deallocate, preemption: 0/6 nodes are available: 2 No preemption victims found for incoming pod, 4 Preemption is not helpful for scheduling."
0.2687,Event,ADDED,eval-sanitize-30-r1-022-jd2rp.18d4f7bad2b0924b,"reason=FailedScheduling count=None msg=0/6 nodes are available: 1 c_wall violated: 2 conflicting context pair(s) with node memory, 2 c_wall violated: 1 conflicting context pair(s) with node memory, 3 node(s) had untolerated taint(s). no new claims to deallocate, preemption: 0/6 nodes are available: 3 No preemption victims found for incoming pod, 3 Preemption is not helpful for scheduling."
0.2689,Event,ADDED,eval-sanitize-30-r1-022-jd2rp.18d4f7bae30b805c,reason=Scheduled count=None msg=Successfully assigned compute/eval-sanitize-30-r1-022-jd2rp to kind-worker2
0.2691,Event,ADDED,eval-sanitize-30-r1-022-jd2rp.18d4f7bb02748889,"reason=Pulled count=1 msg=Container image ""busybox:musl"" already present on machine"
0.2693,Event,ADDED,eval-sanitize-30-r1-022-jd2rp.18d4f7bb03dedd09,reason=Created count=1 msg=Created container: task
0.2698,Event,ADDED,eval-sanitize-30-r1-022-jd2rp.18d4f7bb0a91f80b,reason=Started count=1 msg=Started container task
0.2699,Event,ADDED,eval-sanitize-30-r1-022.18d4f7b7a57d6c46,reason=SuccessfulCreate count=1 msg=Created pod: eval-sanitize-30-r1-022-jd2rp
0.2701,Event,ADDED,eval-sanitize-30-r1-022.18d4f7c0ef08d128,reason=Completed count=1 msg=Job completed
0.2705,Event,ADDED,eval-sanitize-30-r1-023-dhxd2.18d4f7b7e6652e10,"reason=FailedScheduling count=None msg=0/6 nodes are available: 1 c_wall violated: 2 conflicting context pair(s) with node memory, 5 node(s) had untolerated taint(s). no new claims to deallocate, preemption: 0/6 nodes are available: 1 No preemption victims found for incoming pod, 5 Preemption is not helpful for scheduling."
0.2707,Event,ADDED,eval-sanitize-30-r1-023-dhxd2.18d4f7b7e712c69e,"reason=FailedScheduling count=None msg=0/6 nodes are available: 1 c_wall violated: 2 conflicting context pair(s) with node memory, 5 node(s) had untolerated taint(s). no new claims to deallocate, preemption: 0/6 nodes are available: 1 No preemption victims found for incoming pod, 5 Preemption is not helpful for scheduling."
0.2709,Event,ADDED,eval-sanitize-30-r1-023-dhxd2.18d4f7ba13a6d876,"reason=FailedScheduling count=None msg=0/6 nodes are available: 1 c_wall violated: 1 conflicting context pair(s) with node memory, 1 c_wall violated: 2 conflicting context pair(s) with node memory, 4 node(s) had untolerated taint(s). no new claims to deallocate, preemption: 0/6 nodes are available: 2 No preemption victims found for incoming pod, 4 Preemption is not helpful for scheduling."
0.2713,Event,ADDED,eval-sanitize-30-r1-023-dhxd2.18d4f7ba678e3eb6,reason=Scheduled count=None msg=Successfully assigned compute/eval-sanitize-30-r1-023-dhxd2 to kind-worker4
0.2715,Event,ADDED,eval-sanitize-30-r1-023-dhxd2.18d4f7ba8240cc12,"reason=Pulled count=1 msg=Container image ""busybox:musl"" already present on machine"
0.2717,Event,ADDED,eval-sanitize-30-r1-023-dhxd2.18d4f7ba8407ae9c,reason=Created count=1 msg=Created container: task
0.2719,Event,ADDED,eval-sanitize-30-r1-023-dhxd2.18d4f7ba8835d38d,reason=Started count=1 msg=Started container task
0.2722,Event,ADDED,eval-sanitize-30-r1-023.18d4f7b7e6114f3a,reason=SuccessfulCreate count=1 msg=Created pod: eval-sanitize-30-r1-023-dhxd2
0.2724,Event,ADDED,eval-sanitize-30-r1-023.18d4f7c070da9533,reason=Completed count=1 msg=Job completed
0.2726,Event,ADDED,eval-sanitize-30-r1-024-cb488.18d4f7b81ee6cfb4,"reason=FailedScheduling count=None msg=0/6 nodes are available: 1 c_wall violated: 2 conflicting context pair(s) with node memory, 5 node(s) had untolerated taint(s). no new claims to deallocate, preemption: 0/6 nodes are available: 1 No preemption victims found for incoming pod, 5 Preemption is not helpful for scheduling."
0.273,Event,ADDED,eval-sanitize-30-r1-024-cb488.18d4f7b829e2a2f7,"reason=FailedScheduling count=None msg=0/6 nodes are available: 1 c_wall violated: 2 conflicting context pair(s) with node memory, 5 node(s) had untolerated taint(s). no new claims to deallocate, preemption: 0/6 nodes are available: 1 No preemption victims found for incoming pod, 5 Preemption is not helpful for scheduling."
0.2732,Event,ADDED,eval-sanitize-30-r1-024-cb488.18d4f7ba0e0f209f,"reason=FailedScheduling count=None msg=0/6 nodes are available: 1 c_wall violated: 1 conflicting context pair(s) with node memory, 1 c_wall violated: 2 conflicting context pair(s) with node memory, 4 node(s) had untolerated taint(s). no new claims to deallocate, preemption: 0/6 nodes are available: 2 No preemption victims found for incoming pod, 4 Preemption is not helpful for scheduling."
0.2734,Event,ADDED,eval-sanitize-30-r1-024-cb488.18d4f7ba6dedea42,"reason=FailedScheduling count=None msg=0/6 nodes are available: 1 c_wall violated: 1 conflicting context pair(s) with node memory, 1 c_wall violated: 2 conflicting context pair(s) with node memory, 4 node(s) had untolerated taint(s). no new claims to deallocate, preemption: 0/6 nodes are available: 2 No preemption victims found for incoming pod, 4 Preemption is not helpful for scheduling."
0.2738,Event,ADDED,eval-sanitize-30-r1-024-cb488.18d4f7ba7eee4289,"reason=FailedScheduling count=None msg=0/6 nodes are available: 1 c_wall violated: 1 conflicting context pair(s) with node memory, 1 c_wall violated: 2 conflicting context pair(s) with node memory, 4 node(s) had untolerated taint(s). no new claims to deallocate, preemption: 0/6 nodes are available: 2 No preemption victims found for incoming pod, 4 Preemption is not helpful for scheduling."
0.2739,Event,ADDED,eval-sanitize-30-r1-024-cb488.18d4f7bac07ed246,reason=Scheduled count=None msg=Successfully assigned compute/eval-sanitize-30-r1-024-cb488 to kind-worker5
0.2741,Event,ADDED,eval-sanitize-30-r1-024-cb488.18d4f7bae352c9d1,"reason=Pulled count=1 msg=Container image ""busybox:musl"" already present on machine"
0.2745,Event,ADDED,eval-sanitize-30-r1-024-cb488.18d4f7bae5ce2da9,reason=Created count=1 msg=Created container: task
0.2747,Event,ADDED,eval-sanitize-30-r1-024-cb488.18d4f7baef0bde61,reason=Started count=1 msg=Started container task
0.2749,Event,ADDED,eval-sanitize-30-r1-024.18d4f7b81cd36340,reason=SuccessfulCreate count=1 msg=Created pod: eval-sanitize-30-r1-024-cb488
0.2751,Event,ADDED,eval-sanitize-30-r1-024.18d4f7c0c1a35f3c,reason=Completed count=1 msg=Job completed
0.2753,Event,ADDED,eval-sanitize-30-r1-025-d2f7x.18d4f7b858b292b4,"reason=FailedScheduling count=None msg=0/6 nodes are available: 1 c_wall violated: 1 conflicting context pair(s) with node memory, 5 node(s) had untolerated taint(s). no new claims to deallocate, preemption: 0/6 nodes are available: 1 No preemption victims found for incoming pod, 5 Preemption is not helpful for scheduling."
0.2755,Event,ADDED,eval-sanitize-30-r1-025-d2f7x.18d4f7b8598a34c9,"reason=FailedScheduling count=None msg=0/6 nodes are available: 1 c_wall violated: 1 conflicting context pair(s) with node memory, 5 node(s) had untolerated taint(s). no new claims to deallocate, preemption: 0/6 nodes are available: 1 No preemption victims found for incoming pod, 5 Preemption is not helpful for scheduling."
0.2757,Event,ADDED,eval-sanitize-30-r1-025-d2f7x.18d4f7ba19b92e28,"reason=FailedScheduling count=None msg=0/6 nodes are available: 1 c_wall violated: 1 conflicting context pair(s) with node memory, 1 c_wall violated: 2 conflicting context pair(s) with node memory, 4 node(s) had untolerated taint(s). no new claims to deallocate, preemption: 0/6 nodes are available: 2 No preemption victims found for incoming pod, 4 Preemption is not helpful for scheduling."
0.2758,Event,ADDED,eval-sanitize-30-r1-025-d2f7x.18d4f7ba43f17da1,reason=Scheduled count=None msg=Successfully assigned compute/eval-sanitize-30-r1-025-d2f7x to kind-worker4
0.276,Event,ADDED,eval-sanitize-30-r1-025-d2f7x.18d4f7ba73baeee2,"reason=Pulled count=1 msg=Container image ""busybox:musl"" already present on machine"
0.2762,Event,ADDED,eval-sanitize-30-r1-025-d2f7x.18d4f7ba757692d5,reason=Created count=1 msg=Created container: task
0.2764,Event,ADDED,eval-sanitize-30-r1-025-d2f7x.18d4f7ba78775806,reason=Started count=1 msg=Started container task
0.2767,Event,ADDED,eval-sanitize-30-r1-025.18d4f7b85865ea85,reason=SuccessfulCreate count=1 msg=Created pod: eval-sanitize-30-r1-025-d2f7x
0.2769,Event,ADDED,eval-sanitize-30-r1-025.18d4f7c05c4354e2,reason=Completed count=1 msg=Job completed
0.2771,Event,ADDED,eval-sanitize-30-r1-026-txmv6.18d4f7b8943f7a98,"reason=FailedScheduling count=None msg=0/6 nodes are available: 1 c_wall violated: 2 conflicting context pair(s) with node memory, 5 node(s) had untolerated taint(s). no new claims to deallocate, preemption: 0/6 nodes are available: 1 No preemption victims found for incoming pod, 5 Preemption is not helpful for scheduling."
0.2773,Event,ADDED,eval-sanitize-30-r1-026-txmv6.18d4f7b894dad96a,"reason=FailedScheduling count=None msg=0/6 nodes are available: 1 c_wall violated: 2 conflicting context pair(s) with node memory, 5 node(s) had untolerated taint(s). no new claims to deallocate, preemption: 0/6 nodes are available: 1 No preemption victims found for incoming pod, 5 Preemption is not helpful for scheduling."
0.2774,Event,ADDED,eval-sanitize-30-r1-026-txmv6.18d4f7ba05a6d53a,reason=Scheduled count=None msg=Successfully assigned compute/eval-sanitize-30-r1-026-txmv6 to kind-worker
0.2777,Event,ADDED,eval-sanitize-30-r1-026-txmv6.18d4f7ba222a18aa,"reason=Pulled count=1 msg=Container image ""busybox:musl"" already present on machine"
0.2781,Event,ADDED,eval-sanitize-30-r1-026-txmv6.18d4f7ba238f355a,reason=Created count=1 msg=Created container: task
0.2783,Event,ADDED,eval-sanitize-30-r1-026-txmv6.18d4f7ba2d2dc229,reason=Started count=1 msg=Started container task
0.2784,Event,ADDED,eval-sanitize-30-r1-026.18d4f7b893e724a3,reason=SuccessfulCreate count=1 msg=Created pod: eval-sanitize-30-r1-026-txmv6
0.2786,Event,ADDED,eval-sanitize-30-r1-026.18d4f7bf57c60364,reason=Completed count=1 msg=Job completed
0.2789,Event,ADDED,eval-sanitize-30-r1-027-gb5gr.18d4f7b8d2998293,reason=Scheduled count=None msg=Successfully assigned compute/eval-sanitize-30-r1-027-gb5gr to kind-worker3
0.279,Event,ADDED,eval-sanitize-30-r1-027-gb5gr.18d4f7b8f03df77b,"reason=Pulled count=1 msg=Container image ""busybox:musl"" already present on machine"
0.2792,Event,ADDED,eval-sanitize-30-r1-027-gb5gr.18d4f7b8f17acf29,reason=Created count=1 msg=Created container: task
0.2794,Event,ADDED,eval-sanitize-30-r1-027-gb5gr.18d4f7b8f6eebcc3,reason=Started count=1 msg=Started container task
0.2796,Event,ADDED,eval-sanitize-30-r1-027.18d4f7b8d2094297,reason=SuccessfulCreate count=1 msg=Created pod: eval-sanitize-30-r1-027-gb5gr
0.2797,Event,ADDED,eval-sanitize-30-r1-027.18d4f7be754e2e8c,reason=Completed count=1 msg=Job completed
0.2799,Event,ADDED,eval-sanitize-30-r1-028-x9tsd.18d4f7b90eb309fa,"reason=FailedScheduling count=None msg=0/6 nodes are available: 1 c_wall violated: 1 conflicting context pair(s) with node memory, 5 node(s) had untolerated taint(s). no new claims to deallocate, preemption: 0/6 nodes are available: 1 No preemption victims found for incoming pod, 5 Preemption is not helpful for scheduling."
0.2801,Event,ADDED,eval-sanitize-30-r1-028-x9tsd.18d4f7b90f66ab9d,"reason=FailedScheduling count=None msg=0/6 nodes are available: 1 c_wall violated: 1 conflicting context pair(s) with node memory, 5 node(s) had untolerated taint(s). no new claims to deallocate, preemption: 0/6 nodes are available: 1 No preemption victims found for incoming pod, 5 Preemption is not helpful for scheduling."
0.2803,Event,ADDED,eval-sanitize-30-r1-028-x9tsd.18d4f7ba022cfed3,"reason=FailedScheduling count=None msg=0/6 nodes are available: 2 c_wall violated: 1 conflicting context pair(s) with node memory, 4 node(s) had untolerated taint(s). no new claims to deallocate, preemption: 0/6 nodes are available: 2 No preemption victims found for incoming pod, 4 Preemption is not helpful for scheduling."
0.2805,Event,ADDED,eval-sanitize-30-r1-028-x9tsd.18d4f7ba4b556eaf,reason=Scheduled count=None msg=Successfully assigned compute/eval-sanitize-30-r1-028-x9tsd to kind-worker4
0.2809,Event,ADDED,eval-sanitize-30-r1-028-x9tsd.18d4f7ba6eb697a5,"reason=Pulled count=1 msg=Container image ""busybox:musl"" already present on machine"
0.2812,Event,ADDED,eval-sanitize-30-r1-028-x9tsd.18d4f7ba707e4239,reason=Created count=1 msg=Created container: task
0.2816,Event,ADDED,eval-sanitize-30-r1-028-x9tsd.18d4f7ba747b2e77,reason=Started count=1 msg=Started container task
0.2819,Event,ADDED,eval-sanitize-30-r1-028.18d4f7b90e6eb2ea,reason=SuccessfulCreate count=1 msg=Created pod: eval-sanitize-30-r1-028-x9tsd
0.2825,Event,ADDED,eval-sanitize-30-r1-028.18d4f7c064a8892c,reason=Completed count=1 msg=Job completed
0.2828,Event,ADDED,eval-sanitize-30-r1-029-6wv7z.18d4f7b94932e1a5,reason=Scheduled count=None msg=Successfully assigned compute/eval-sanitize-30-r1-029-6wv7z to kind-worker3
0.2831,Event,ADDED,eval-sanitize-30-r1-029-6wv7z.18d4f7b96f8bd012,"reason=Pulled count=1 msg=Container image ""busybox:musl"" already present on machine"
0.2834,Event,ADDED,eval-sanitize-30-r1-029-6wv7z.18d4f7b970b75e1d,reason=Created count=1 msg=Created container: task
0.2838,Event,ADDED,eval-sanitize-30-r1-029-6wv7z.18d4f7b978c26be5,reason=Started count=1 msg=Started container task
0.284,Event,ADDED,eval-sanitize-30-r1-029.18d4f7b948b144e6,reason=SuccessfulCreate count=1 msg=Created pod: eval-sanitize-30-r1-029-6wv7z
0.2842,Event,ADDED,eval-sanitize-30-r1-029.18d4f7beedbabb8e,reason=Completed count=1 msg=Job completed
0.2844,Event,ADDED,eval-sanitize-30-r1-030-v5n6w.18d4f7b988e088b1,"reason=FailedScheduling count=None msg=0/6 nodes are available: 1 c_wall violated: 2 conflicting context pair(s) with node memory, 5 node(s) had untolerated taint(s). no new claims to deallocate, preemption: 0/6 nodes are available: 1 No preemption victims found for incoming pod, 5 Preemption is not helpful for scheduling."
0.2846,Event,ADDED,eval-sanitize-30-r1-030-v5n6w.18d4f7b98974196b,"reason=FailedScheduling count=None msg=0/6 nodes are available: 1 c_wall violated: 2 conflicting context pair(s) with node memory, 5 node(s) had untolerated taint(s). no new claims to deallocate, preemption: 0/6 nodes are available: 1 No preemption victims found for incoming pod, 5 Preemption is not helpful for scheduling."
0.2848,Event,ADDED,eval-sanitize-30-r1-030-v5n6w.18d4f7b9eecac0cb,reason=Scheduled count=None msg=Successfully assigned compute/eval-sanitize-30-r1-030-v5n6w to kind-worker
0.2852,Event,ADDED,eval-sanitize-30-r1-030-v5n6w.18d4f7ba1091f0d6,"reason=Pulled count=1 msg=Container image ""busybox:musl"" already present on machine"
0.2854,Event,ADDED,eval-sanitize-30-r1-030-v5n6w.18d4f7ba12a28456,reason=Created count=1 msg=Created container: task
0.2858,Event,ADDED,eval-sanitize-30-r1-030-v5n6w.18d4f7ba15d83433,reason=Started count=1 msg=Started container task
0.2861,Event,ADDED,eval-sanitize-30-r1-030.18d4f7b988910ffb,reason=SuccessfulCreate count=1 msg=Created pod: eval-sanitize-30-r1-030-v5n6w
0.2864,Event,ADDED,eval-sanitize-30-r1-030.18d4f7bf573f6307,reason=Completed count=1 msg=Job completed
0.2867,Event,ADDED,eval-sanitize-30-r1-031-66t5k.18d4f7b9c55aa425,"reason=FailedScheduling count=None msg=0/6 nodes are available: 1 c_wall violated: 2 conflicting context pair(s) with node memory, 5 node(s) had untolerated taint(s). no new claims to deallocate, preemption: 0/6 nodes are available: 1 No preemption victims found for incoming pod, 5 Preemption is not helpful for scheduling."
0.287,Event,ADDED,eval-sanitize-30-r1-031-66t5k.18d4f7b9c60ee651,"reason=FailedScheduling count=None msg=0/6 nodes are available: 1 c_wall violated: 2 conflicting context pair(s) with node memory, 5 node(s) had untolerated taint(s). no new claims to deallocate, preemption: 0/6 nodes are available: 1 No preemption victims found for incoming pod, 5 Preemption is not helpful for scheduling."
0.2875,Event,ADDED,eval-sanitize-30-r1-031-66t5k.18d4f7ba0d90d6e6,"reason=FailedScheduling count=None msg=0/6 nodes are available: 1 c_wall violated: 1 conflicting context pair(s) with node memory, 1 c_wall violated: 2 conflicting context pair(s) with node memory, 4 node(s) had untolerated taint(s). no new claims to deallocate, preemption: 0/6 nodes are available: 2 No preemption victims found for incoming pod, 4 Preemption is not helpful for scheduling."
0.2876,Event,ADDED,eval-sanitize-30-r1-031-66t5k.18d4f7ba5badff72,reason=Scheduled count=None msg=Successfully assigned compute/eval-sanitize-30-r1-031-66t5k to kind-worker4
0.2878,Event,ADDED,eval-sanitize-30-r1-031-66t5k.18d4f7ba76e47c8a,"reason=Pulled count=1 msg=Container image ""busybox:musl"" already present on machine"
0.288,Event,ADDED,eval-sanitize-30-r1-031-66t5k.18d4f7ba78b26042,reason=Created count=1 msg=Created container: task
0.2884,Event,ADDED,eval-sanitize-30-r1-031-66t5k.18d4f7ba8232e9f5,reason=Started count=1 msg=Started container task
0.2888,Event,ADDED,eval-sanitize-30-r1-031.18d4f7b9c509fdbd,reason=SuccessfulCreate count=1 msg=Created pod: eval-sanitize-30-r1-031-66t5k
0.289,Event,ADDED,eval-sanitize-30-r1-031.18d4f7bfceb9ee95,reason=Completed count=1 msg=Job completed
0.2892,Event,ADDED,eval-sanitize-30-r1-032-jgbm7.18d4f7b9fc91136d,"reason=FailedScheduling count=None msg=0/6 nodes are available: 1 c_wall violated: 1 conflicting context pair(s) with node memory, 1 c_wall violated: 2 conflicting context pair(s) with node memory, 4 node(s) had untolerated taint(s). no new claims to deallocate, preemption: 0/6 nodes are available: 2 No preemption victims found for incoming pod, 4 Preemption is not helpful for scheduling."
0.2897,Event,ADDED,eval-sanitize-30-r1-032-jgbm7.18d4f7ba14349550,"reason=FailedScheduling count=None msg=0/6 nodes are available: 1 c_wall violated: 1 conflicting context pair(s) with node memory, 1 c_wall violated: 2 conflicting context pair(s) with node memory, 4 node(s) had untolerated taint(s). no new claims to deallocate, preemption: 0/6 nodes are available: 2 No preemption victims found for incoming pod, 4 Preemption is not helpful for scheduling."
0.2899,Event,ADDED,eval-sanitize-30-r1-032-jgbm7.18d4f7ba678dd473,"reason=FailedScheduling count=None msg=0/6 nodes are available: 1 c_wall violated: 1 conflicting context pair(s) with node memory, 1 c_wall violated: 2 conflicting context pair(s) with node memory, 4 node(s) had untolerated taint(s). no new claims to deallocate, preemption: 0/6 nodes are available: 2 No preemption victims found for incoming pod, 4 Preemption is not helpful for scheduling."
0.2901,Event,ADDED,eval-sanitize-30-r1-032-jgbm7.18d4f7ba738dc192,"reason=FailedScheduling count=None msg=0/6 nodes are available: 1 c_wall violated: 1 conflicting context pair(s) with node memory, 1 c_wall violated: 2 conflicting context pair(s) with node memory, 4 node(s) had untolerated taint(s). no new claims to deallocate, preemption: 0/6 nodes are available: 2 No preemption victims found for incoming pod, 4 Preemption is not helpful for scheduling."
0.2903,Event,ADDED,eval-sanitize-30-r1-032-jgbm7.18d4f7bac6ea994a,reason=Scheduled count=None msg=Successfully assigned compute/eval-sanitize-30-r1-032-jgbm7 to kind-worker5
0.2906,Event,ADDED,eval-sanitize-30-r1-032-jgbm7.18d4f7bae32d9f38,"reason=Pulled count=1 msg=Container image ""busybox:musl"" already present on machine"
0.2908,Event,ADDED,eval-sanitize-30-r1-032-jgbm7.18d4f7bae4f1fd69,reason=Created count=1 msg=Created container: task
0.291,Event,ADDED,eval-sanitize-30-r1-032-jgbm7.18d4f7baef0bde57,reason=Started count=1 msg=Started container task
0.2913,Event,ADDED,eval-sanitize-30-r1-032.18d4f7b9fa885558,reason=SuccessfulCreate count=1 msg=Created pod: eval-sanitize-30-r1-032-jgbm7
0.2915,Event,ADDED,eval-sanitize-30-r1-032.18d4f7c0c4e70db3,reason=Completed count=1 msg=Job completed
0.2917,Event,ADDED,eval-sanitize-30-r1-033-rq6k2.18d4f7ba3823f28c,reason=Scheduled count=None msg=Successfully assigned compute/eval-sanitize-30-r1-033-rq6k2 to kind-worker4
0.2919,Event,ADDED,eval-sanitize-30-r1-033-rq6k2.18d4f7ba56c3db36,"reason=Pulled count=1 msg=Container image ""busybox:musl"" already present on machine"
0.2922,Event,ADDED,eval-sanitize-30-r1-033-rq6k2.18d4f7ba5947238d,reason=Created count=1 msg=Created container: task
0.2924,Event,ADDED,eval-sanitize-30-r1-033-rq6k2.18d4f7ba654784e5,reason=Started count=1 msg=Started container task
0.2926,Event,ADDED,eval-sanitize-30-r1-033.18d4f7ba358ab5c1,reason=SuccessfulCreate count=1 msg=Created pod: eval-sanitize-30-r1-033-rq6k2
0.2928,Event,ADDED,eval-sanitize-30-r1-033.18d4f7bfce1313a4,reason=Completed count=1 msg=Job completed
0.2932,Event,ADDED,eval-sanitize-30-r1-034-9dgqc.18d4f7ba79758c8d,reason=Scheduled count=None msg=Successfully assigned compute/eval-sanitize-30-r1-034-9dgqc to kind-worker
0.2936,Event,ADDED,eval-sanitize-30-r1-034-9dgqc.18d4f7ba95c69345,"reason=Pulled count=1 msg=Container image ""busybox:musl"" already present on machine"
0.2939,Event,ADDED,eval-sanitize-30-r1-034-9dgqc.18d4f7ba971c2b04,reason=Created count=1 msg=Created container: task
0.2941,Event,ADDED,eval-sanitize-30-r1-034-9dgqc.18d4f7ba9e877e7a,reason=Started count=1 msg=Started container task
0.2943,Event,ADDED,eval-sanitize-30-r1-034.18d4f7ba738da00f,reason=SuccessfulCreate count=1 msg=Created pod: eval-sanitize-30-r1-034-9dgqc
0.2945,Event,ADDED,eval-sanitize-30-r1-034.18d4f7bfd01bb62f,reason=Completed count=1 msg=Job completed
0.2947,Event,ADDED,eval-sanitize-30-r1-035-pljn4.18d4f7bab3bb4c15,reason=Scheduled count=None msg=Successfully assigned compute/eval-sanitize-30-r1-035-pljn4 to kind-worker4
0.2948,Event,ADDED,eval-sanitize-30-r1-035-pljn4.18d4f7bad1fab655,"reason=Pulled count=1 msg=Container image ""busybox:musl"" already present on machine"
0.295,Event,ADDED,eval-sanitize-30-r1-035-pljn4.18d4f7bad3c25800,reason=Created count=1 msg=Created container: task
0.2953,Event,ADDED,eval-sanitize-30-r1-035-pljn4.18d4f7bad9435e90,reason=Started count=1 msg=Started container task
0.2957,Event,ADDED,eval-sanitize-30-r1-035.18d4f7baacbe1503,reason=SuccessfulCreate count=1 msg=Created pod: eval-sanitize-30-r1-035-pljn4
0.296,Event,ADDED,eval-sanitize-30-r1-035.18d4f7c09b61812d,reason=Completed count=1 msg=Job completed
0.2963,Event,ADDED,eval-sanitize-30-r1-036-95bfb.18d4f7baf9f114e9,reason=Scheduled count=None msg=Successfully assigned compute/eval-sanitize-30-r1-036-95bfb to kind-worker5
0.2966,Event,ADDED,eval-sanitize-30-r1-036-95bfb.18d4f7bb1c276bc1,"reason=Pulled count=1 msg=Container image ""busybox:musl"" already present on machine"
0.2973,Event,ADDED,eval-sanitize-30-r1-036-95bfb.18d4f7bb1d94026a,reason=Created count=1 msg=Created container: task
0.2976,Event,ADDED,eval-sanitize-30-r1-036-95bfb.18d4f7bb23ffd8c9,reason=Started count=1 msg=Started container task
0.2982,Event,ADDED,eval-sanitize-30-r1-036.18d4f7baf0196b9a,reason=SuccessfulCreate count=1 msg=Created pod: eval-sanitize-30-r1-036-95bfb
0.2985,Event,ADDED,eval-sanitize-30-r1-036.18d4f7c101ecfe26,reason=Completed count=1 msg=Job completed
0.2989,Event,ADDED,eval-sanitize-30-r1-037-8rxpd.18d4f7bb2ea9133f,reason=Scheduled count=None msg=Successfully assigned compute/eval-sanitize-30-r1-037-8rxpd to kind-worker
0.2991,Event,ADDED,eval-sanitize-30-r1-037-8rxpd.18d4f7bb5383394f,"reason=Pulled count=1 msg=Container image ""busybox:musl"" already present on machine"
0.2993,Event,ADDED,eval-sanitize-30-r1-037-8rxpd.18d4f7bb54ca7e14,reason=Created count=1 msg=Created container: task
0.2995,Event,ADDED,eval-sanitize-30-r1-037-8rxpd.18d4f7bb5fa71318,reason=Started count=1 msg=Started container task
0.2997,Event,ADDED,eval-sanitize-30-r1-037.18d4f7bb25eaf35e,reason=SuccessfulCreate count=1 msg=Created pod: eval-sanitize-30-r1-037-8rxpd
0.2999,Event,ADDED,eval-sanitize-30-r1-037.18d4f7c12489ac2c,reason=Completed count=1 msg=Job completed
0.3,Event,ADDED,eval-sanitize-30-r1-038-8lfsz.18d4f7bb68c2e268,reason=Scheduled count=None msg=Successfully assigned compute/eval-sanitize-30-r1-038-8lfsz to kind-worker
0.3002,Event,ADDED,eval-sanitize-30-r1-038-8lfsz.18d4f7bb834fc71b,"reason=Pulled count=1 msg=Container image ""busybox:musl"" already present on machine"
0.3005,Event,ADDED,eval-sanitize-30-r1-038-8lfsz.18d4f7bb848ff890,reason=Created count=1 msg=Created container: task
0.3007,Event,ADDED,eval-sanitize-30-r1-038-8lfsz.18d4f7bb8c458c26,reason=Started count=1 msg=Started container task
0.3009,Event,ADDED,eval-sanitize-30-r1-038.18d4f7bb61b739aa,reason=SuccessfulCreate count=1 msg=Created pod: eval-sanitize-30-r1-038-8lfsz
0.3012,Event,ADDED,eval-sanitize-30-r1-038.18d4f7c1557738a2,reason=Completed count=1 msg=Job completed
0.3014,Event,ADDED,eval-sanitize-30-r1-039-59nfq.18d4f7bba33c5083,reason=Scheduled count=None msg=Successfully assigned compute/eval-sanitize-30-r1-039-59nfq to kind-worker2
0.3017,Event,ADDED,eval-sanitize-30-r1-039-59nfq.18d4f7bbc311ebd7,"reason=Pulled count=1 msg=Container image ""busybox:musl"" already present on machine"
0.302,Event,ADDED,eval-sanitize-30-r1-039-59nfq.18d4f7bbc47a8238,reason=Created count=1 msg=Created container: task
0.3021,Event,ADDED,eval-sanitize-30-r1-039-59nfq.18d4f7bbca36d0c1,reason=Started count=1 msg=Started container task
0.3023,Event,ADDED,eval-sanitize-30-r1-039.18d4f7bb9d78953c,reason=SuccessfulCreate count=1 msg=Created pod: eval-sanitize-30-r1-039-59nfq
0.3025,Event,ADDED,eval-sanitize-30-r1-039.18d4f7c14c6119dd,reason=Completed count=1 msg=Job completed
0.3027,Event,ADDED,eval-sanitize-30-r1-040-mddtw.18d4f7bbd916c9e9,reason=Scheduled count=None msg=Successfully assigned compute/eval-sanitize-30-r1-040-mddtw to kind-worker2
0.3028,Event,ADDED,eval-sanitize-30-r1-040-mddtw.18d4f7bbfb1b29b5,"reason=Pulled count=1 msg=Container image ""busybox:musl"" already present on machine"
0.303,Event,ADDED,eval-sanitize-30-r1-040-mddtw.18d4f7bbfc5309b6,reason=Created count=1 msg=Created container: task
0.3032,Event,ADDED,eval-sanitize-30-r1-040-mddtw.18d4f7bc0102d5de,reason=Started count=1 msg=Started container task
0.3036,Event,ADDED,eval-sanitize-30-r1-040.18d4f7bbd6f5fff5,reason=SuccessfulCreate count=1 msg=Created pod: eval-sanitize-30-r1-040-mddtw
0.3038,Event,ADDED,eval-sanitize-30-r1-040.18d4f7c18319cfd1,reason=Completed count=1 msg=Job completed
0.304,Event,ADDED,eval-sanitize-30-r1-041-g9ctf.18d4f7bc199bd51a,reason=Scheduled count=None msg=Successfully assigned compute/eval-sanitize-30-r1-041-g9ctf to kind-worker4
0.3043,Event,ADDED,eval-sanitize-30-r1-041-g9ctf.18d4f7bc3711ebbb,"reason=Pulled count=1 msg=Container image ""busybox:musl"" already present on machine"
0.3045,Event,ADDED,eval-sanitize-30-r1-041-g9ctf.18d4f7bc3861a3aa,reason=Created count=1 msg=Created container: task
0.3047,Event,ADDED,eval-sanitize-30-r1-041-g9ctf.18d4f7bc3e93eb22,reason=Started count=1 msg=Started container task
0.3049,Event,ADDED,eval-sanitize-30-r1-041.18d4f7bc13a8dcda,reason=SuccessfulCreate count=1 msg=Created pod: eval-sanitize-30-r1-041-g9ctf
0.3053,Event,ADDED,eval-sanitize-30-r1-041.18d4f7c17127d43a,reason=Completed count=1 msg=Job completed
0.3055,Event,ADDED,eval-sanitize-30-r1-042-j9plb.18d4f7bc5018ebd9,reason=Scheduled count=None msg=Successfully assigned compute/eval-sanitize-30-r1-042-j9plb to kind-worker4
0.3057,Event,ADDED,eval-sanitize-30-r1-042-j9plb.18d4f7bc6d247c55,"reason=Pulled count=1 msg=Container image ""busybox:musl"" already present on machine"
0.3059,Event,ADDED,eval-sanitize-30-r1-042-j9plb.18d4f7bc6e773258,reason=Created count=1 msg=Created container: task
0.3062,Event,ADDED,eval-sanitize-30-r1-042-j9plb.18d4f7bc75e1bd65,reason=Started count=1 msg=Started container task
0.3064,Event,ADDED,eval-sanitize-30-r1-042.18d4f7bc4e014516,reason=SuccessfulCreate count=1 msg=Created pod: eval-sanitize-30-r1-042-j9plb
0.3066,Event,ADDED,eval-sanitize-30-r1-042.18d4f7c1ad4c968a,reason=Completed count=1 msg=Job completed
0.3068,Event,ADDED,eval-sanitize-30-r1-043-t58j8.18d4f7bc8ba0649d,reason=Scheduled count=None msg=Successfully assigned compute/eval-sanitize-30-r1-043-t58j8 to kind-worker4
0.307,Event,ADDED,eval-sanitize-30-r1-043-t58j8.18d4f7bca897c157,"reason=Pulled count=1 msg=Container image ""busybox:musl"" already present on machine"
0.3072,Event,ADDED,eval-sanitize-30-r1-043-t58j8.18d4f7bca9e1db02,reason=Created count=1 msg=Created container: task
0.3074,Event,ADDED,eval-sanitize-30-r1-043-t58j8.18d4f7bcb13240bf,reason=Started count=1 msg=Started container task
0.3076,Event,ADDED,eval-sanitize-30-r1-043.18d4f7bc898d21c5,reason=SuccessfulCreate count=1 msg=Created pod: eval-sanitize-30-r1-043-t58j8
0.3077,Event,ADDED,eval-sanitize-30-r1-043.18d4f7c1e945b91a,reason=Completed count=1 msg=Job completed
0.3079,Event,ADDED,eval-sanitize-30-r1-044-ggtpd.18d4f7bcc71bbfb3,reason=Scheduled count=None msg=Successfully assigned compute/eval-sanitize-30-r1-044-ggtpd to kind-worker2
0.3081,Event,ADDED,eval-sanitize-30-r1-044-ggtpd.18d4f7bce1d191aa,"reason=Pulled count=1 msg=Container image ""busybox:musl"" already present on machine"
0.3083,Event,ADDED,eval-sanitize-30-r1-044-ggtpd.18d4f7bce3171087,reason=Created count=1 msg=Created container: task
0.3084,Event,ADDED,eval-sanitize-30-r1-044-ggtpd.18d4f7bceb8bd87b,reason=Started count=1 msg=Started container task
0.3087,Event,ADDED,eval-sanitize-30-r1-044.18d4f7bcc558c578,reason=SuccessfulCreate count=1 msg=Created pod: eval-sanitize-30-r1-044-ggtpd
0.3092,Event,ADDED,eval-sanitize-30-r1-044.18d4f7c26f566df9,reason=Completed count=1 msg=Job completed
0.3096,Event,ADDED,eval-sanitize-30-r1-045-5fst9.18d4f7bd02a022f1,reason=Scheduled count=None msg=Successfully assigned compute/eval-sanitize-30-r1-045-5fst9 to kind-worker2
0.3099,Event,ADDED,eval-sanitize-30-r1-045-5fst9.18d4f7bd202f68ea,"reason=Pulled count=1 msg=Container image ""busybox:musl"" already present on machine"
0.3101,Event,ADDED,eval-sanitize-30-r1-045-5fst9.18d4f7bd217b6ce2,reason=Created count=1 msg=Created container: task
0.3104,Event,ADDED,eval-sanitize-30-r1-045-5fst9.18d4f7bd2a5d0223,reason=Started count=1 msg=Started container task
0.3106,Event,ADDED,eval-sanitize-30-r1-045.18d4f7bd00a0d971,reason=SuccessfulCreate count=1 msg=Created pod: eval-sanitize-30-r1-045-5fst9
0.3108,Event,ADDED,eval-sanitize-30-r1-045.18d4f7c2ab932bd4,reason=Completed count=1 msg=Job completed
0.3109,Event,ADDED,eval-sanitize-30-r1-046-gkm6v.18d4f7bd498d0c65,reason=Scheduled count=None msg=Successfully assigned compute/eval-sanitize-30-r1-046-gkm6v to kind-worker2
0.3112,Event,ADDED,eval-sanitize-30-r1-046-gkm6v.18d4f7bd65bfe35d,"reason=Pulled count=1 msg=Container image ""busybox:musl"" already present on machine"
0.3114,Event,ADDED,eval-sanitize-30-r1-046-gkm6v.18d4f7bd670681ec,reason=Created count=1 msg=Created container: task
0.3116,Event,ADDED,eval-sanitize-30-r1-046-gkm6v.18d4f7bd6c779fd3,reason=Started count=1 msg=Started container task
0.3118,Event,ADDED,eval-sanitize-30-r1-046.18d4f7bd3f901753,reason=SuccessfulCreate count=1 msg=Created pod: eval-sanitize-30-r1-046-gkm6v
0.312,Event,ADDED,eval-sanitize-30-r1-046.18d4f7c2e7f0f3ff,reason=Completed count=1 msg=Job completed
0.3121,Event,ADDED,eval-sanitize-30-r1-047-5k787.18d4f7bd7a387e46,reason=Scheduled count=None msg=Successfully assigned compute/eval-sanitize-30-r1-047-5k787 to kind-worker2
0.3123,Event,ADDED,eval-sanitize-30-r1-047-5k787.18d4f7bd9dea7a37,"reason=Pulled count=1 msg=Container image ""busybox:musl"" already present on machine"
0.3125,Event,ADDED,eval-sanitize-30-r1-047-5k787.18d4f7bd9f60c7e5,reason=Created count=1 msg=Created container: task
0.3127,Event,ADDED,eval-sanitize-30-r1-047-5k787.18d4f7bdab67ec34,reason=Started count=1 msg=Started container task
0.3128,Event,ADDED,eval-sanitize-30-r1-047.18d4f7bd782a25c0,reason=SuccessfulCreate count=1 msg=Created pod: eval-sanitize-30-r1-047-5k787
0.3133,Event,ADDED,eval-sanitize-30-r1-047.18d4f7c31e3584ff,reason=Completed count=1 msg=Job completed
0.3134,Event,ADDED,eval-sanitize-30-r1-048-6k62m.18d4f7bdbafb6b32,reason=Scheduled count=None msg=Successfully assigned compute/eval-sanitize-30-r1-048-6k62m to kind-worker4
0.3136,Event,ADDED,eval-sanitize-30-r1-048-6k62m.18d4f7bdd7b81235,"reason=Pulled count=1 msg=Container image ""busybox:musl"" already present on machine"
0.3138,Event,ADDED,eval-sanitize-30-r1-048-6k62m.18d4f7bdd91a5721,reason=Created count=1 msg=Created container: task
0.314,Event,ADDED,eval-sanitize-30-r1-048-6k62m.18d4f7bddec57261,reason=Started count=1 msg=Started container task
0.3142,Event,ADDED,eval-sanitize-30-r1-048.18d4f7bdb480c27a,reason=SuccessfulCreate count=1 msg=Created pod: eval-sanitize-30-r1-048-6k62m
0.3144,Event,ADDED,eval-sanitize-30-r1-048.18d4f7c34f390df2,reason=Completed count=1 msg=Job completed
0.3145,Event,ADDED,eval-sanitize-30-r1-049-88fbm.18d4f7bdf15862fc,reason=Scheduled count=None msg=Successfully assigned compute/eval-sanitize-30-r1-049-88fbm to kind-worker5
0.3149,Event,ADDED,eval-sanitize-30-r1-049-88fbm.18d4f7be0f18b87a,"reason=Pulled count=1 msg=Container image ""busybox:musl"" already present on machine"
0.3151,Event,ADDED,eval-sanitize-30-r1-049-88fbm.18d4f7be1081e0f9,reason=Created count=1 msg=Created container: task
0.3153,Event,ADDED,eval-sanitize-30-r1-049-88fbm.18d4f7be1573d220,reason=Started count=1 msg=Started container task
0.3154,Event,ADDED,eval-sanitize-30-r1-049.18d4f7bdef62a6c8,reason=SuccessfulCreate count=1 msg=Created pod: eval-sanitize-30-r1-049-88fbm
0.3157,Event,ADDED,eval-sanitize-30-r1-049.18d4f7c3a3b14d64,reason=Completed count=1 msg=Job completed
0.3159,Event,ADDED,eval-sanitize-30-r1-050-sxjnd.18d4f7be31fb6d96,reason=Scheduled count=None msg=Successfully assigned compute/eval-sanitize-30-r1-050-sxjnd to kind-worker5
0.316,Event,ADDED,eval-sanitize-30-r1-050-sxjnd.18d4f7be4f0e6dfb,"reason=Pulled count=1 msg=Container image ""busybox:musl"" already present on machine"
0.3162,Event,ADDED,eval-sanitize-30-r1-050-sxjnd.18d4f7be50673f57,reason=Created count=1 msg=Created container: task
0.3164,Event,ADDED,eval-sanitize-30-r1-050-sxjnd.18d4f7be587a118a,reason=Started count=1 msg=Started container task
0.3166,Event,ADDED,eval-sanitize-30-r1-050.18d4f7be2b7140e6,reason=SuccessfulCreate count=1 msg=Created pod: eval-sanitize-30-r1-050-sxjnd
0.3167,Event,ADDED,eval-sanitize-30-r1-050.18d4f7c3df9c1c6d,reason=Completed count=1 msg=Job completed
0.3169,Event,ADDED,eval-sanitize-30-r1-051-lk22c.18d4f7be71d73fa8,reason=Scheduled count=None msg=Successfully assigned compute/eval-sanitize-30-r1-051-lk22c to kind-worker2
0.3171,Event,ADDED,eval-sanitize-30-r1-051-lk22c.18d4f7be9712c77f,"reason=Pulled count=1 msg=Container image ""busybox:musl"" already present on machine"
0.3172,Event,ADDED,eval-sanitize-30-r1-051-lk22c.18d4f7be98b3028c,reason=Created count=1 msg=Created container: task
0.3174,Event,ADDED,eval-sanitize-30-r1-051-lk22c.18d4f7be9ee50a24,reason=Started count=1 msg=Started container task
0.3177,Event,ADDED,eval-sanitize-30-r1-051.18d4f7be687394f1,reason=SuccessfulCreate count=1 msg=Created pod: eval-sanitize-30-r1-051-lk22c
0.3179,Event,ADDED,eval-sanitize-30-r1-051.18d4f7c410176d9f,reason=Completed count=1 msg=Job completed
0.318,Event,ADDED,eval-sanitize-30-r1-052-rz2fc.18d4f7bea42c99fe,reason=Scheduled count=None msg=Successfully assigned compute/eval-sanitize-30-r1-052-rz2fc to kind-worker
0.3183,Event,ADDED,eval-sanitize-30-r1-052-rz2fc.18d4f7bec51bcbe1,"reason=Pulled count=1 msg=Container image ""busybox:musl"" already present on machine"
0.3184,Event,ADDED,eval-sanitize-30-r1-052-rz2fc.18d4f7bec66b2ead,reason=Created count=1 msg=Created container: task
0.3186,Event,ADDED,eval-sanitize-30-r1-052-rz2fc.18d4f7bed1311add,reason=Started count=1 msg=Started container task
0.3188,Event,ADDED,eval-sanitize-30-r1-052.18d4f7bea25d4482,reason=SuccessfulCreate count=1 msg=Created pod: eval-sanitize-30-r1-052-rz2fc
0.319,Event,ADDED,eval-sanitize-30-r1-052.18d4f7c44ef6e377,reason=Completed count=1 msg=Job completed
0.3191,Event,ADDED,eval-sanitize-30-r1-053-c2g2m.18d4f7bedf9e3564,reason=Scheduled count=None msg=Successfully assigned compute/eval-sanitize-30-r1-053-c2g2m to kind-worker4
0.3193,Event,ADDED,eval-sanitize-30-r1-053-c2g2m.18d4f7bf069ead12,"reason=Pulled count=1 msg=Container image ""busybox:musl"" already present on machine"
0.3194,Event,ADDED,eval-sanitize-30-r1-053-c2g2m.18d4f7bf087b1650,reason=Created count=1 msg=Created container: task
0.3196,Event,ADDED,eval-sanitize-30-r1-053-c2g2m.18d4f7bf0db37421,reason=Started count=1 msg=Started container task
0.3198,Event,ADDED,eval-sanitize-30-r1-053.18d4f7beddd8cbdd,reason=SuccessfulCreate count=1 msg=Created pod: eval-sanitize-30-r1-053-c2g2m
0.32,Event,ADDED,eval-sanitize-30-r1-053.18d4f7c4817acb79,reason=Completed count=1 msg=Job completed
0.3204,Event,ADDED,eval-sanitize-30-r1-054-2669c.18d4f7bf253aa369,reason=Scheduled count=None msg=Successfully assigned compute/eval-sanitize-30-r1-054-2669c to kind-worker2
0.3207,Event,ADDED,eval-sanitize-30-r1-054-2669c.18d4f7bf5423e39e,"reason=Pulled count=1 msg=Container image ""busybox:musl"" already present on machine"
0.3209,Event,ADDED,eval-sanitize-30-r1-054-2669c.18d4f7bf575b9fa6,reason=Created count=1 msg=Created container: task
0.321,Event,ADDED,eval-sanitize-30-r1-054-2669c.18d4f7bf5dcf265f,reason=Started count=1 msg=Started container task
0.3214,Event,ADDED,eval-sanitize-30-r1-054.18d4f7bf1b10fb69,reason=SuccessfulCreate count=1 msg=Created pod: eval-sanitize-30-r1-054-2669c
0.3217,Event,ADDED,eval-sanitize-30-r1-054.18d4f7c4c76eb055,reason=Completed count=1 msg=Job completed
0.3219,Event,ADDED,eval-sanitize-30-r1-055-8trl4.18d4f7bf607a09b7,reason=Scheduled count=None msg=Successfully assigned compute/eval-sanitize-30-r1-055-8trl4 to kind-worker
0.322,Event,ADDED,eval-sanitize-30-r1-055-8trl4.18d4f7bf7a952793,"reason=Pulled count=1 msg=Container image ""busybox:musl"" already present on machine"
0.3223,Event,ADDED,eval-sanitize-30-r1-055-8trl4.18d4f7bf7be31db4,reason=Created count=1 msg=Created container: task
0.3225,Event,ADDED,eval-sanitize-30-r1-055-8trl4.18d4f7bf821896cc,reason=Started count=1 msg=Started container task
0.3226,Event,ADDED,eval-sanitize-30-r1-055.18d4f7bf5f2274d7,reason=SuccessfulCreate count=1 msg=Created pod: eval-sanitize-30-r1-055-8trl4
0.3231,Event,ADDED,eval-sanitize-30-r1-055.18d4f7c4f68487b7,reason=Completed count=1 msg=Job completed
0.3233,Event,ADDED,eval-sanitize-30-r1-056-sz8r5.18d4f7bf99094471,reason=Scheduled count=None msg=Successfully assigned compute/eval-sanitize-30-r1-056-sz8r5 to kind-worker2
0.3234,Event,ADDED,eval-sanitize-30-r1-056-sz8r5.18d4f7bfb48cc6d3,"reason=Pulled count=1 msg=Container image ""busybox:musl"" already present on machine"
0.3236,Event,ADDED,eval-sanitize-30-r1-056-sz8r5.18d4f7bfb5c5608f,reason=Created count=1 msg=Created container: task
0.324,Event,ADDED,eval-sanitize-30-r1-056-sz8r5.18d4f7bfb9e4bba7,reason=Started count=1 msg=Started container task
0.3243,Event,ADDED,eval-sanitize-30-r1-056.18d4f7bf91f5946d,reason=SuccessfulCreate count=1 msg=Created pod: eval-sanitize-30-r1-056-sz8r5
0.3245,Event,ADDED,eval-sanitize-30-r1-056.18d4f7c4fcf5d2b0,reason=Completed count=1 msg=Job completed
0.3247,Event,ADDED,eval-sanitize-30-r1-057-8vw49.18d4f7bfd59154e8,reason=Scheduled count=None msg=Successfully assigned compute/eval-sanitize-30-r1-057-8vw49 to kind-worker5
0.325,Event,ADDED,eval-sanitize-30-r1-057-8vw49.18d4f7bff13ae60c,"reason=Pulled count=1 msg=Container image ""busybox:musl"" already present on machine"
0.3251,Event,ADDED,eval-sanitize-30-r1-057-8vw49.18d4f7bff2ce357f,reason=Created count=1 msg=Created container: task
0.3253,Event,ADDED,eval-sanitize-30-r1-057-8vw49.18d4f7bff8597a5c,reason=Started count=1 msg=Started container task
0.3256,Event,ADDED,eval-sanitize-30-r1-057.18d4f7bfce438b6c,reason=SuccessfulCreate count=1 msg=Created pod: eval-sanitize-30-r1-057-8vw49
0.3258,Event,ADDED,eval-sanitize-30-r1-057.18d4f7c5877ed677,reason=Completed count=1 msg=Job completed
0.3259,Event,ADDED,eval-sanitize-30-r1-058-2wr5s.18d4f7c009d74ed9,reason=Scheduled count=None msg=Successfully assigned compute/eval-sanitize-30-r1-058-2wr5s to kind-worker4
0.3261,Event,ADDED,eval-sanitize-30-r1-058-2wr5s.18d4f7c02912d663,"reason=Pulled count=1 msg=Container image ""busybox:musl"" already present on machine"
0.3264,Event,ADDED,eval-sanitize-30-r1-058-2wr5s.18d4f7c02a8a6b52,reason=Created count=1 msg=Created container: task
0.3266,Event,ADDED,eval-sanitize-30-r1-058-2wr5s.18d4f7c031778989,reason=Started count=1 msg=Started container task
0.3268,Event,ADDED,eval-sanitize-30-r1-058.18d4f7c0079e1396,reason=SuccessfulCreate count=1 msg=Created pod: eval-sanitize-30-r1-058-2wr5s
0.3269,Event,ADDED,eval-sanitize-30-r1-058.18d4f7c5b4327489,reason=Completed count=1 msg=Job completed
0.3272,Event,ADDED,eval-sanitize-30-r1-059-9wkjk.18d4f7c04fc4952f,reason=Scheduled count=None msg=Successfully assigned compute/eval-sanitize-30-r1-059-9wkjk to kind-worker
0.3274,Event,ADDED,eval-sanitize-30-r1-059-9wkjk.18d4f7c070f2301e,"reason=Pulled count=1 msg=Container image ""busybox:musl"" already present on machine"
0.3276,Event,ADDED,eval-sanitize-30-r1-059-9wkjk.18d4f7c07288c98c,reason=Created count=1 msg=Created container: task
0.3279,Event,ADDED,eval-sanitize-30-r1-059-9wkjk.18d4f7c07db60d65,reason=Started count=1 msg=Started container task
0.3281,Event,ADDED,eval-sanitize-30-r1-059.18d4f7c04e4d12ca,reason=SuccessfulCreate count=1 msg=Created pod: eval-sanitize-30-r1-059-9wkjk
0.3282,Event,ADDED,eval-sanitize-30-r1-059.18d4f7c5e61d3062,reason=Completed count=1 msg=Job completed
0.3284,Event,ADDED,eval-sanitize-30-r1-060-7f6zw.18d4f7c092be5a40,reason=Scheduled count=None msg=Successfully assigned compute/eval-sanitize-30-r1-060-7f6zw to kind-worker4
0.3287,Event,ADDED,eval-sanitize-30-r1-060-7f6zw.18d4f7c0b1dd1963,"reason=Pulled count=1 msg=Container image ""busybox:musl"" already present on machine"
0.3289,Event,ADDED,eval-sanitize-30-r1-060-7f6zw.18d4f7c0b33865ac,reason=Created count=1 msg=Created container: task
0.3291,Event,ADDED,eval-sanitize-30-r1-060-7f6zw.18d4f7c0b86dc804,reason=Started count=1 msg=Started container task
0.3293,Event,ADDED,eval-sanitize-30-r1-060.18d4f7c090d7eb45,reason=SuccessfulCreate count=1 msg=Created pod: eval-sanitize-30-r1-060-7f6zw
0.3295,Event,ADDED,eval-sanitize-30-r1-060.18d4f7c622020b4f,reason=Completed count=1 msg=Job completed
0.3296,Event,ADDED,eval-sanitize-30-r1-061-l4s2l.18d4f7c0ce6e3fee,reason=Scheduled count=None msg=Successfully assigned compute/eval-sanitize-30-r1-061-l4s2l to kind-worker2
0.3298,Event,ADDED,eval-sanitize-30-r1-061-l4s2l.18d4f7c0eaa6da66,"reason=Pulled count=1 msg=Container image ""busybox:musl"" already present on machine"
0.33,Event,ADDED,eval-sanitize-30-r1-061-l4s2l.18d4f7c0ec16bb88,reason=Created count=1 msg=Created container: task
0.3302,Event,ADDED,eval-sanitize-30-r1-061-l4s2l.18d4f7c0f15dc442,reason=Started count=1 msg=Started container task
0.3303,Event,ADDED,eval-sanitize-30-r1-061.18d4f7c0c7b47af6,reason=SuccessfulCreate count=1 msg=Created pod: eval-sanitize-30-r1-061-l4s2l
0.3305,Event,ADDED,eval-sanitize-30-r1-061.18d4f7c6692acda3,reason=Completed count=1 msg=Job completed
0.3307,Event,ADDED,eval-sanitize-30-r1-062-bp9xl.18d4f7c0fc243369,reason=Scheduled count=None msg=Successfully assigned compute/eval-sanitize-30-r1-062-bp9xl to kind-worker4
0.3308,Event,ADDED,eval-sanitize-30-r1-062-bp9xl.18d4f7c1195d1371,"reason=Pulled count=1 msg=Container image ""busybox:musl"" already present on machine"
0.331,Event,ADDED,eval-sanitize-30-r1-062-bp9xl.18d4f7c11ac0e7f8,reason=Created count=1 msg=Created container: task
0.3312,Event,ADDED,eval-sanitize-30-r1-062-bp9xl.18d4f7c123fd3461,reason=Started count=1 msg=Started container task
0.3315,Event,ADDED,eval-sanitize-30-r1-062.18d4f7c0fac7e932,reason=SuccessfulCreate count=1 msg=Created pod: eval-sanitize-30-r1-062-bp9xl
0.3317,Event,ADDED,eval-sanitize-30-r1-062.18d4f7c694fc846a,reason=Completed count=1 msg=Job completed
0.3319,Event,ADDED,eval-sanitize-30-r1-063-dl924.18d4f7c1355d8730,reason=Scheduled count=None msg=Successfully assigned compute/eval-sanitize-30-r1-063-dl924 to kind-worker2
0.3321,Event,ADDED,eval-sanitize-30-r1-063-dl924.18d4f7c152c98d04,"reason=Pulled count=1 msg=Container image ""busybox:musl"" already present on machine"
0.3323,Event,ADDED,eval-sanitize-30-r1-063-dl924.18d4f7c1540f2d53,reason=Created count=1 msg=Created container: task
0.3324,Event,ADDED,eval-sanitize-30-r1-063-dl924.18d4f7c15c5e60f7,reason=Started count=1 msg=Started container task
0.3326,Event,ADDED,eval-sanitize-30-r1-063.18d4f7c13404524e,reason=SuccessfulCreate count=1 msg=Created pod: eval-sanitize-30-r1-063-dl924
0.3328,Event,ADDED,eval-sanitize-30-r1-063.18d4f7c6dc37834f,reason=Completed count=1 msg=Job completed
0.3329,Event,ADDED,eval-sanitize-30-r1-064-z7b6m.18d4f7c16fd0c632,reason=Scheduled count=None msg=Successfully assigned compute/eval-sanitize-30-r1-064-z7b6m to kind-worker3
0.3331,Event,ADDED,eval-sanitize-30-r1-064-z7b6m.18d4f7c18a72fd00,"reason=Pulled count=1 msg=Container image ""busybox:musl"" already present on machine"
0.3333,Event,ADDED,eval-sanitize-30-r1-064-z7b6m.18d4f7c18bb92535,reason=Created count=1 msg=Created container: task
0.3335,Event,ADDED,eval-sanitize-30-r1-064-z7b6m.18d4f7c1914d789e,reason=Started count=1 msg=Started container task
0.3336,Event,ADDED,eval-sanitize-30-r1-064.18d4f7c16ea8331f,reason=SuccessfulCreate count=1 msg=Created pod: eval-sanitize-30-r1-064-z7b6m
0.3339,Event,ADDED,eval-sanitize-30-r1-064.18d4f7c719fb7ac4,reason=Completed count=1 msg=Job completed
0.3341,Event,ADDED,eval-sanitize-30-r1-065-qmwjc.18d4f7c1b0c7aff0,reason=Scheduled count=None msg=Successfully assigned compute/eval-sanitize-30-r1-065-qmwjc to kind-worker5
0.3361,Event,ADDED,eval-sanitize-30-r1-065-qmwjc.18d4f7c1cbb6f236,"reason=Pulled count=1 msg=Container image ""busybox:musl"" already present on machine"
0.3363,Event,ADDED,eval-sanitize-30-r1-065-qmwjc.18d4f7c1cd207fea,reason=Created count=1 msg=Created container: task
0.3365,Event,ADDED,eval-sanitize-30-r1-065-qmwjc.18d4f7c1d56785f3,reason=Started count=1 msg=Started container task
0.3371,Event,ADDED,eval-sanitize-30-r1-065.18d4f7c1ae6b4b0d,reason=SuccessfulCreate count=1 msg=Created pod: eval-sanitize-30-r1-065-qmwjc
0.3373,Event,ADDED,eval-sanitize-30-r1-065.18d4f7c75dd9a0b2,reason=Completed count=1 msg=Job completed
0.3374,Event,ADDED,eval-sanitize-30-r1-066-x52xq.18d4f7c1e977f7fe,reason=Scheduled count=None msg=Successfully assigned compute/eval-sanitize-30-r1-066-x52xq to kind-worker3
0.3376,Event,ADDED,eval-sanitize-30-r1-066-x52xq.18d4f7c2097f36da,"reason=Pulled count=1 msg=Container image ""busybox:musl"" already present on machine"
0.338,Event,ADDED,eval-sanitize-30-r1-066-x52xq.18d4f7c20acf0254,reason=Created count=1 msg=Created container: task
0.3383,Event,ADDED,eval-sanitize-30-r1-066-x52xq.18d4f7c214264c99,reason=Started count=1 msg=Started container task
0.3385,Event,ADDED,eval-sanitize-30-r1-066.18d4f7c1e8a3a46c,reason=SuccessfulCreate count=1 msg=Created pod: eval-sanitize-30-r1-066-x52xq
0.3388,Event,ADDED,eval-sanitize-30-r1-066.18d4f7c79173fae7,reason=Completed count=1 msg=Job completed
0.339,Event,ADDED,eval-sanitize-30-r1-067-4l2v6.18d4f7c2274a50ba,"reason=FailedScheduling count=None msg=0/6 nodes are available: 1 c_wall violated: 2 conflicting context pair(s) with node memory, 5 node(s) had untolerated taint(s). no new claims to deallocate, preemption: 0/6 nodes are available: 1 No preemption victims found for incoming pod, 5 Preemption is not helpful for scheduling."
0.3392,Event,ADDED,eval-sanitize-30-r1-067-4l2v6.18d4f7c22801f78c,"reason=FailedScheduling count=None msg=0/6 nodes are available: 1 c_wall violated: 2 conflicting context pair(s) with node memory, 5 node(s) had untolerated taint(s). no new claims to deallocate, preemption: 0/6 nodes are available: 1 No preemption victims found for incoming pod, 5 Preemption is not helpful for scheduling."
0.3396,Event,ADDED,eval-sanitize-30-r1-067-4l2v6.18d4f7c3160bf416,"reason=FailedScheduling count=None msg=0/6 nodes are available: 1 c_wall violated: 3 conflicting context pair(s) with node memory, 5 node(s) had untolerated taint(s). no new claims to deallocate, preemption: 0/6 nodes are available: 1 No preemption victims found for incoming pod, 5 Preemption is not helpful for scheduling."
0.3398,Event,ADDED,eval-sanitize-30-r1-067-4l2v6.18d4f7c504d1a7ae,"reason=FailedScheduling count=None msg=0/6 nodes are available: 1 c_wall violated: 4 conflicting context pair(s) with node memory, 5 node(s) had untolerated taint(s). no new claims to deallocate, preemption: 0/6 nodes are available: 1 No preemption victims found for incoming pod, 5 Preemption is not helpful for scheduling."
0.34,Event,ADDED,eval-sanitize-30-r1-067-4l2v6.18d4f7c8289c7cda,"reason=FailedScheduling count=None msg=0/6 nodes are available: 1 c_wall violated: 1 conflicting context pair(s) with node memory, 1 c_wall violated: 4 conflicting context pair(s) with node memory, 4 node(s) had untolerated taint(s). no new claims to deallocate, preemption: 0/6 nodes are available: 2 No preemption victims found for incoming pod, 4 Preemption is not helpful for scheduling."
0.3403,Event,ADDED,eval-sanitize-30-r1-067-4l2v6.18d4f7c87dc6e653,"reason=FailedScheduling count=None msg=0/6 nodes are available: 2 c_wall violated: 1 conflicting context pair(s) with node memory, 4 node(s) had untolerated taint(s). no new claims to deallocate, preemption: 0/6 nodes are available: 2 No preemption victims found for incoming pod, 4 Preemption is not helpful for scheduling."
0.3405,Event,ADDED,eval-sanitize-30-r1-067-4l2v6.18d4f7c889293e8e,"reason=FailedScheduling count=None msg=0/6 nodes are available: 2 c_wall violated: 1 conflicting context pair(s) with node memory, 4 node(s) had untolerated taint(s). no new claims to deallocate, preemption: 0/6 nodes are available: 2 No preemption victims found for incoming pod, 4 Preemption is not helpful for scheduling."
0.3406,Event,ADDED,eval-sanitize-30-r1-067-4l2v6.18d4f7c8d1762dff,reason=Scheduled count=None msg=Successfully assigned compute/eval-sanitize-30-r1-067-4l2v6 to kind-worker5
0.3409,Event,ADDED,eval-sanitize-30-r1-067-4l2v6.18d4f7c8ec96e11d,"reason=Pulled count=1 msg=Container image ""busybox:musl"" already present on machine"
0.341,Event,ADDED,eval-sanitize-30-r1-067-4l2v6.18d4f7c8ee096a6d,reason=Created count=1 msg=Created container: task
0.3412,Event,ADDED,eval-sanitize-30-r1-067-4l2v6.18d4f7c8f0b04eba,reason=Started count=1 msg=Started container task
0.3414,Event,ADDED,eval-sanitize-30-r1-067.18d4f7c226ef6268,reason=SuccessfulCreate count=1 msg=Created pod: eval-sanitize-30-r1-067-4l2v6
0.3417,Event,ADDED,eval-sanitize-30-r1-067.18d4f7ce2a5b3cdb,reason=Completed count=1 msg=Job completed
0.3419,Event,ADDED,eval-sanitize-30-r1-068-8f9gb.18d4f7c264b8a528,"reason=FailedScheduling count=None msg=0/6 nodes are available: 1 c_wall violated: 1 conflicting context pair(s) with node memory, 5 node(s) had untolerated taint(s). no new claims to deallocate, preemption: 0/6 nodes are available: 1 No preemption victims found for incoming pod, 5 Preemption is not helpful for scheduling."
0.3421,Event,ADDED,eval-sanitize-30-r1-068-8f9gb.18d4f7c265624ecc,"reason=FailedScheduling count=None msg=0/6 nodes are available: 1 c_wall violated: 1 conflicting context pair(s) with node memory, 5 node(s) had untolerated taint(s). no new claims to deallocate, preemption: 0/6 nodes are available: 1 No preemption victims found for incoming pod, 5 Preemption is not helpful for scheduling."
0.3425,Event,ADDED,eval-sanitize-30-r1-068-8f9gb.18d4f7c31648365a,"reason=FailedScheduling count=None msg=0/6 nodes are available: 1 c_wall violated: 2 conflicting context pair(s) with node memory, 5 node(s) had untolerated taint(s). no new claims to deallocate, preemption: 0/6 nodes are available: 1 No preemption victims found for incoming pod, 5 Preemption is not helpful for scheduling."
0.3427,Event,ADDED,eval-sanitize-30-r1-068-8f9gb.18d4f7c829b796ec,"reason=FailedScheduling count=None msg=0/6 nodes are available: 2 c_wall violated: 2 conflicting context pair(s) with node memory, 4 node(s) had untolerated taint(s). no new claims to deallocate, preemption: 0/6 nodes are available: 2 No preemption victims found for incoming pod, 4 Preemption is not helpful for scheduling."
0.3429,Event,ADDED,eval-sanitize-30-r1-068-8f9gb.18d4f7c853f4fa01,reason=Scheduled count=None msg=Successfully assigned compute/eval-sanitize-30-r1-068-8f9gb to kind-worker4
0.3431,Event,ADDED,eval-sanitize-30-r1-068-8f9gb.18d4f7c86f990db2,"reason=Pulled count=1 msg=Container image ""busybox:musl"" already present on machine"
0.3434,Event,ADDED,eval-sanitize-30-r1-068-8f9gb.18d4f7c870e3640a,reason=Created count=1 msg=Created container: task
0.3437,Event,ADDED,eval-sanitize-30-r1-068-8f9gb.18d4f7c875b7ff48,reason=Started count=1 msg=Started container task
0.3439,Event,ADDED,eval-sanitize-30-r1-068.18d4f7c26469b8aa,reason=SuccessfulCreate count=1 msg=Created pod: eval-sanitize-30-r1-068-8f9gb
0.3443,Event,ADDED,eval-sanitize-30-r1-068.18d4f7ce1bb7270c,reason=Completed count=1 msg=Job completed
0.3444,Event,ADDED,eval-sanitize-30-r1-069-x8bxc.18d4f7c29798f408,"reason=FailedScheduling count=None msg=0/6 nodes are available: 1 c_wall violated: 2 conflicting context pair(s) with node memory, 5 node(s) had untolerated taint(s). no new claims to deallocate, preemption: 0/6 nodes are available: 1 No preemption victims found for incoming pod, 5 Preemption is not helpful for scheduling."
0.3446,Event,ADDED,eval-sanitize-30-r1-069-x8bxc.18d4f7c2985abf60,"reason=FailedScheduling count=None msg=0/6 nodes are available: 1 c_wall violated: 2 conflicting context pair(s) with node memory, 5 node(s) had untolerated taint(s). no new claims to deallocate, preemption: 0/6 nodes are available: 1 No preemption victims found for incoming pod, 5 Preemption is not helpful for scheduling."
0.345,Event,ADDED,eval-sanitize-30-r1-069-x8bxc.18d4f7c31688d176,"reason=FailedScheduling count=None msg=0/6 nodes are available: 1 c_wall violated: 3 conflicting context pair(s) with node memory, 5 node(s) had untolerated taint(s). no new claims to deallocate, preemption: 0/6 nodes are available: 1 No preemption victims found for incoming pod, 5 Preemption is not helpful for scheduling."
0.3453,Event,ADDED,eval-sanitize-30-r1-069-x8bxc.18d4f7c83b3c7bfb,"reason=FailedScheduling count=None msg=0/6 nodes are available: 1 c_wall violated: 2 conflicting context pair(s) with node memory, 1 c_wall violated: 3 conflicting context pair(s) with node memory, 4 node(s) had untolerated taint(s). no new claims to deallocate, preemption: 0/6 nodes are available: 2 No preemption victims found for incoming pod, 4 Preemption is not helpful for scheduling."
0.3454,Event,ADDED,eval-sanitize-30-r1-069-x8bxc.18d4f7c865c7d3fd,reason=Scheduled count=None msg=Successfully assigned compute/eval-sanitize-30-r1-069-x8bxc to kind-worker4
0.3457,Event,ADDED,eval-sanitize-30-r1-069-x8bxc.18d4f7c880245bf6,"reason=Pulled count=1 msg=Container image ""busybox:musl"" already present on machine"
0.3459,Event,ADDED,eval-sanitize-30-r1-069-x8bxc.18d4f7c882079c0b,reason=Created count=1 msg=Created container: task
0.3461,Event,ADDED,eval-sanitize-30-r1-069-x8bxc.18d4f7c886df1007,reason=Started count=1 msg=Started container task
0.3462,Event,ADDED,eval-sanitize-30-r1-069.18d4f7c29742ffd4,reason=SuccessfulCreate count=1 msg=Created pod: eval-sanitize-30-r1-069-x8bxc
0.3465,Event,ADDED,eval-sanitize-30-r1-069.18d4f7ce1bb4b808,reason=Completed count=1 msg=Job completed
0.3467,Event,ADDED,eval-sanitize-30-r1-070-g26h5.18d4f7c2d3bdf5e0,"reason=FailedScheduling count=None msg=0/6 nodes are available: 1 c_wall violated: 2 conflicting context pair(s) with node memory, 5 node(s) had untolerated taint(s). no new claims to deallocate, preemption: 0/6 nodes are available: 1 No preemption victims found for incoming pod, 5 Preemption is not helpful for scheduling."
0.3469,Event,ADDED,eval-sanitize-30-r1-070-g26h5.18d4f7c2d49e72ae,"reason=FailedScheduling count=None msg=0/6 nodes are available: 1 c_wall violated: 2 conflicting context pair(s) with node memory, 5 node(s) had untolerated taint(s). no new claims to deallocate, preemption: 0/6 nodes are available: 1 No preemption victims found for incoming pod, 5 Preemption is not helpful for scheduling."
0.3471,Event,ADDED,eval-sanitize-30-r1-070-g26h5.18d4f7c31a42c2d4,"reason=FailedScheduling count=None msg=0/6 nodes are available: 1 c_wall violated: 3 conflicting context pair(s) with node memory, 5 node(s) had untolerated taint(s). no new claims to deallocate, preemption: 0/6 nodes are available: 1 No preemption victims found for incoming pod, 5 Preemption is not helpful for scheduling."
0.3473,Event,ADDED,eval-sanitize-30-r1-070-g26h5.18d4f7c5053c45ee,"reason=FailedScheduling count=None msg=0/6 nodes are available: 1 c_wall violated: 4 conflicting context pair(s) with node memory, 5 node(s) had untolerated taint(s). no new claims to deallocate, preemption: 0/6 nodes are available: 1 No preemption victims found for incoming pod, 5 Preemption is not helpful for scheduling."
0.3475,Event,ADDED,eval-sanitize-30-r1-070-g26h5.18d4f7c82ea5038a,"reason=FailedScheduling count=None msg=0/6 nodes are available: 1 c_wall violated: 1 conflicting context pair(s) with node memory, 1 c_wall violated: 4 conflicting context pair(s) with node memory, 4 node(s) had untolerated taint(s). no new claims to deallocate, preemption: 0/6 nodes are available: 2 No preemption victims found for incoming pod, 4 Preemption is not helpful for scheduling."
0.3479,Event,ADDED,eval-sanitize-30-r1-070-g26h5.18d4f7c87826b6f2,"reason=FailedScheduling count=None msg=0/6 nodes are available: 2 c_wall violated: 1 conflicting context pair(s) with node memory, 4 node(s) had untolerated taint(s). no new claims to deallocate, preemption: 0/6 nodes are available: 2 No preemption victims found for incoming pod, 4 Preemption is not helpful for scheduling."
0.3482,Event,ADDED,eval-sanitize-30-r1-070-g26h5.18d4f7c8833177cb,"reason=FailedScheduling count=None msg=0/6 nodes are available: 2 c_wall violated: 1 conflicting context pair(s) with node memory, 4 node(s) had untolerated taint(s). no new claims to deallocate, preemption: 0/6 nodes are available: 2 No preemption victims found for incoming pod, 4 Preemption is not helpful for scheduling."
0.3484,Event,ADDED,eval-sanitize-30-r1-070-g26h5.18d4f7c8dcdc62e3,reason=Scheduled count=None msg=Successfully assigned compute/eval-sanitize-30-r1-070-g26h5 to kind-worker5
0.3487,Event,ADDED,eval-sanitize-30-r1-070-g26h5.18d4f7c8fb290fac,"reason=Pulled count=1 msg=Container image ""busybox:musl"" already present on machine"
0.3489,Event,ADDED,eval-sanitize-30-r1-070-g26h5.18d4f7c8fcf81dfa,reason=Created count=1 msg=Created container: task
0.3491,Event,ADDED,eval-sanitize-30-r1-070-g26h5.18d4f7c900df8363,reason=Started count=1 msg=Started container task
0.3496,Event,ADDED,eval-sanitize-30-r1-070.18d4f7c2d36952a8,reason=SuccessfulCreate count=1 msg=Created pod: eval-sanitize-30-r1-070-g26h5
0.3498,Event,ADDED,eval-sanitize-30-r1-070.18d4f7cea7e3f10a,reason=Completed count=1 msg=Job completed
0.35,Event,ADDED,eval-sanitize-30-r1-071-sph7b.18d4f7c30f4bb1e3,reason=Scheduled count=None msg=Successfully assigned compute/eval-sanitize-30-r1-071-sph7b to kind-worker3
0.3502,Event,ADDED,eval-sanitize-30-r1-071-sph7b.18d4f7c3312473ab,"reason=Pulled count=1 msg=Container image ""busybox:musl"" already present on machine"
0.3505,Event,ADDED,eval-sanitize-30-r1-071-sph7b.18d4f7c332781f3d,reason=Created count=1 msg=Created container: task
0.3507,Event,ADDED,eval-sanitize-30-r1-071-sph7b.18d4f7c337f72e52,reason=Started count=1 msg=Started container task
0.3508,Event,ADDED,eval-sanitize-30-r1-071.18d4f7c30e8aa672,reason=SuccessfulCreate count=1 msg=Created pod: eval-sanitize-30-r1-071-sph7b
0.351,Event,ADDED,eval-sanitize-30-r1-071.18d4f7c8bd951913,reason=Completed count=1 msg=Job completed
0.3514,Event,ADDED,eval-sanitize-30-r1-072-62htx.18d4f7c34b85740d,reason=Scheduled count=None msg=Successfully assigned compute/eval-sanitize-30-r1-072-62htx to kind-worker3
0.3516,Event,ADDED,eval-sanitize-30-r1-072-62htx.18d4f7c366ffda8e,"reason=Pulled count=1 msg=Container image ""busybox:musl"" already present on machine"
0.3518,Event,ADDED,eval-sanitize-30-r1-072-62htx.18d4f7c368b7560b,reason=Created count=1 msg=Created container: task
0.352,Event,ADDED,eval-sanitize-30-r1-072-62htx.18d4f7c36de098c5,reason=Started count=1 msg=Started container task
0.3522,Event,ADDED,eval-sanitize-30-r1-072.18d4f7c34aa4e9a7,reason=SuccessfulCreate count=1 msg=Created pod: eval-sanitize-30-r1-072-62htx
0.3524,Event,ADDED,eval-sanitize-30-r1-072.18d4f7c8f9e233ed,reason=Completed count=1 msg=Job completed
0.3528,Event,ADDED,eval-sanitize-30-r1-073-88phz.18d4f7c386027f3b,"reason=FailedScheduling count=None msg=0/6 nodes are available: 1 c_wall violated: 2 conflicting context pair(s) with node memory, 5 node(s) had untolerated taint(s). no new claims to deallocate, preemption: 0/6 nodes are available: 1 No preemption victims found for incoming pod, 5 Preemption is not helpful for scheduling."
0.353,Event,ADDED,eval-sanitize-30-r1-073-88phz.18d4f7c386ceb5ec,"reason=FailedScheduling count=None msg=0/6 nodes are available: 1 c_wall violated: 2 conflicting context pair(s) with node memory, 5 node(s) had untolerated taint(s). no new claims to deallocate, preemption: 0/6 nodes are available: 1 No preemption victims found for incoming pod, 5 Preemption is not helpful for scheduling."
0.3532,Event,ADDED,eval-sanitize-30-r1-073-88phz.18d4f7c823989d85,"reason=FailedScheduling count=None msg=0/6 nodes are available: 2 c_wall violated: 2 conflicting context pair(s) with node memory, 4 node(s) had untolerated taint(s). no new claims to deallocate, preemption: 0/6 nodes are available: 2 No preemption victims found for incoming pod, 4 Preemption is not helpful for scheduling."
0.3533,Event,ADDED,eval-sanitize-30-r1-073-88phz.18d4f7c83ba3c9fc,"reason=FailedScheduling count=None msg=0/6 nodes are available: 2 c_wall violated: 2 conflicting context pair(s) with node memory, 4 node(s) had untolerated taint(s). no new claims to deallocate, preemption: 0/6 nodes are available: 2 No preemption victims found for incoming pod, 4 Preemption is not helpful for scheduling."
0.3535,Event,ADDED,eval-sanitize-30-r1-073-88phz.18d4f7c86bd95d3a,reason=Scheduled count=None msg=Successfully assigned compute/eval-sanitize-30-r1-073-88phz to kind-worker4
0.3537,Event,ADDED,eval-sanitize-30-r1-073-88phz.18d4f7c8882da1fb,"reason=Pulled count=1 msg=Container image ""busybox:musl"" already present on machine"
0.3539,Event,ADDED,eval-sanitize-30-r1-073-88phz.18d4f7c889d85435,reason=Created count=1 msg=Created container: task
0.3541,Event,ADDED,eval-sanitize-30-r1-073-88phz.18d4f7c88eca1895,reason=Started count=1 msg=Started container task
0.3542,Event,ADDED,eval-sanitize-30-r1-073.18d4f7c385b1639f,reason=SuccessfulCreate count=1 msg=Created pod: eval-sanitize-30-r1-073-88phz
0.3544,Event,ADDED,eval-sanitize-30-r1-073.18d4f7ce1bb80871,reason=Completed count=1 msg=Job completed
0.3546,Event,ADDED,eval-sanitize-30-r1-074-9bcjv.18d4f7c3c2081be5,"reason=FailedScheduling count=None msg=0/6 nodes are available: 1 c_wall violated: 3 conflicting context pair(s) with node memory, 5 node(s) had untolerated taint(s). no new claims to deallocate, preemption: 0/6 nodes are available: 1 No preemption victims found for incoming pod, 5 Preemption is not helpful for scheduling."
0.3548,Event,ADDED,eval-sanitize-30-r1-074-9bcjv.18d4f7c3c2b5887d,"reason=FailedScheduling count=None msg=0/6 nodes are available: 1 c_wall violated: 3 conflicting context pair(s) with node memory, 5 node(s) had untolerated taint(s). no new claims to deallocate, preemption: 0/6 nodes are available: 1 No preemption victims found for incoming pod, 5 Preemption is not helpful for scheduling."
0.3549,Event,ADDED,eval-sanitize-30-r1-074-9bcjv.18d4f7c806e55449,reason=Scheduled count=None msg=Successfully assigned compute/eval-sanitize-30-r1-074-9bcjv to kind-worker
0.3551,Event,ADDED,eval-sanitize-30-r1-074-9bcjv.18d4f7c821a6e305,"reason=Pulled count=1 msg=Container image ""busybox:musl"" already present on machine"
0.3553,Event,ADDED,eval-sanitize-30-r1-074-9bcjv.18d4f7c823989d48,reason=Created count=1 msg=Created container: task
0.3554,Event,ADDED,eval-sanitize-30-r1-074-9bcjv.18d4f7c82787a39c,reason=Started count=1 msg=Started container task
0.3557,Event,ADDED,eval-sanitize-30-r1-074.18d4f7c3c1aca440,reason=SuccessfulCreate count=1 msg=Created pod: eval-sanitize-30-r1-074-9bcjv
0.3559,Event,ADDED,eval-sanitize-30-r1-074.18d4f7cd5e9ebde1,reason=Completed count=1 msg=Job completed
0.3562,Event,ADDED,eval-sanitize-30-r1-075-pq8zv.18d4f7c3fe05ba38,reason=Scheduled count=None msg=Successfully assigned compute/eval-sanitize-30-r1-075-pq8zv to kind-worker3
0.3563,Event,ADDED,eval-sanitize-30-r1-075-pq8zv.18d4f7c4199791a7,"reason=Pulled count=1 msg=Container image ""busybox:musl"" already present on machine"
0.3566,Event,ADDED,eval-sanitize-30-r1-075-pq8zv.18d4f7c41b01c0cc,reason=Created count=1 msg=Created container: task
0.3568,Event,ADDED,eval-sanitize-30-r1-075-pq8zv.18d4f7c422c3ee42,reason=Started count=1 msg=Started container task
0.3571,Event,ADDED,eval-sanitize-30-r1-075.18d4f7c3fd54ee4d,reason=SuccessfulCreate count=1 msg=Created pod: eval-sanitize-30-r1-075-pq8zv
0.3573,Event,ADDED,eval-sanitize-30-r1-075.18d4f7c9ae20b46b,reason=Completed count=1 msg=Job completed
0.3575,Event,ADDED,eval-sanitize-30-r1-076-jwq4m.18d4f7c439e7dfe1,reason=Scheduled count=None msg=Successfully assigned compute/eval-sanitize-30-r1-076-jwq4m to kind-worker3
0.3578,Event,ADDED,eval-sanitize-30-r1-076-jwq4m.18d4f7c45dc7b757,"reason=Pulled count=1 msg=Container image ""busybox:musl"" already present on machine"
0.358,Event,ADDED,eval-sanitize-30-r1-076-jwq4m.18d4f7c45f23f616,reason=Created count=1 msg=Created container: task
0.3582,Event,ADDED,eval-sanitize-30-r1-076-jwq4m.18d4f7c4686333b8,reason=Started count=1 msg=Started container task
0.3584,Event,ADDED,eval-sanitize-30-r1-076.18d4f7c43924adc4,reason=SuccessfulCreate count=1 msg=Created pod: eval-sanitize-30-r1-076-jwq4m
0.3587,Event,ADDED,eval-sanitize-30-r1-076.18d4f7c9ea7df597,reason=Completed count=1 msg=Job completed
0.3595,Event,ADDED,eval-sanitize-30-r1-077-j9c5b.18d4f7c476066130,"reason=FailedScheduling count=None msg=0/6 nodes are available: 1 c_wall violated: 3 conflicting context pair(s) with node memory, 5 node(s) had untolerated taint(s). no new claims to deallocate, preemption: 0/6 nodes are available: 1 No preemption victims found for incoming pod, 5 Preemption is not helpful for scheduling."
0.3604,Event,ADDED,eval-sanitize-30-r1-077-j9c5b.18d4f7c476d137b2,"reason=FailedScheduling count=None msg=0/6 nodes are available: 1 c_wall violated: 3 conflicting context pair(s) with node memory, 5 node(s) had untolerated taint(s). no new claims to deallocate, preemption: 0/6 nodes are available: 1 No preemption victims found for incoming pod, 5 Preemption is not helpful for scheduling."
0.3609,Event,ADDED,eval-sanitize-30-r1-077-j9c5b.18d4f7c7ff947d7e,reason=Scheduled count=None msg=Successfully assigned compute/eval-sanitize-30-r1-077-j9c5b to kind-worker
0.3612,Event,ADDED,eval-sanitize-30-r1-077-j9c5b.18d4f7c81c056ae7,"reason=Pulled count=1 msg=Container image ""busybox:musl"" already present on machine"
0.3615,Event,ADDED,eval-sanitize-30-r1-077-j9c5b.18d4f7c81d6d114c,reason=Created count=1 msg=Created container: task
0.3617,Event,ADDED,eval-sanitize-30-r1-077-j9c5b.18d4f7c82115b061,reason=Started count=1 msg=Started container task
0.3621,Event,ADDED,eval-sanitize-30-r1-077.18d4f7c475af65d4,reason=SuccessfulCreate count=1 msg=Created pod: eval-sanitize-30-r1-077-j9c5b
0.3624,Event,ADDED,eval-sanitize-30-r1-077.18d4f7cd99260326,reason=Completed count=1 msg=Job completed
0.3626,Event,ADDED,eval-sanitize-30-r1-078-ghftg.18d4f7c4b08b2fee,reason=Scheduled count=None msg=Successfully assigned compute/eval-sanitize-30-r1-078-ghftg to kind-worker3
0.3633,Event,ADDED,eval-sanitize-30-r1-078-ghftg.18d4f7c4d3c8ee64,"reason=Pulled count=1 msg=Container image ""busybox:musl"" already present on machine"
0.3635,Event,ADDED,eval-sanitize-30-r1-078-ghftg.18d4f7c4d52432f9,reason=Created count=1 msg=Created container: task
0.3637,Event,ADDED,eval-sanitize-30-r1-078-ghftg.18d4f7c4deba8a7a,reason=Started count=1 msg=Started container task
0.3638,Event,ADDED,eval-sanitize-30-r1-078.18d4f7c4afcedddc,reason=SuccessfulCreate count=1 msg=Created pod: eval-sanitize-30-r1-078-ghftg
0.3641,Event,ADDED,eval-sanitize-30-r1-078.18d4f7ca6106d561,reason=Completed count=1 msg=Job completed
0.3643,Event,ADDED,eval-sanitize-30-r1-079-9qcjp.18d4f7c4f9fc79be,reason=Scheduled count=None msg=Successfully assigned compute/eval-sanitize-30-r1-079-9qcjp to kind-worker3
0.3646,Event,ADDED,eval-sanitize-30-r1-079-9qcjp.18d4f7c516b1b169,"reason=Pulled count=1 msg=Container image ""busybox:musl"" already present on machine"
0.3651,Event,ADDED,eval-sanitize-30-r1-079-9qcjp.18d4f7c517f13721,reason=Created count=1 msg=Created container: task
0.3654,Event,ADDED,eval-sanitize-30-r1-079-9qcjp.18d4f7c51c71eafb,reason=Started count=1 msg=Started container task
0.3657,Event,ADDED,eval-sanitize-30-r1-079.18d4f7c4f87df951,reason=SuccessfulCreate count=1 msg=Created pod: eval-sanitize-30-r1-079-9qcjp
0.3659,Event,ADDED,eval-sanitize-30-r1-079.18d4f7ca9d3c3496,reason=Completed count=1 msg=Job completed
0.3663,Event,ADDED,eval-sanitize-30-r1-080-8rqsm.18d4f7c5270d78aa,"reason=FailedScheduling count=None msg=0/6 nodes are available: 1 c_wall violated: 1 conflicting context pair(s) with node memory, 5 node(s) had untolerated taint(s). no new claims to deallocate, preemption: 0/6 nodes are available: 1 No preemption victims found for incoming pod, 5 Preemption is not helpful for scheduling."
0.3666,Event,ADDED,eval-sanitize-30-r1-080-8rqsm.18d4f7c527b15e2d,"reason=FailedScheduling count=None msg=0/6 nodes are available: 1 c_wall violated: 1 conflicting context pair(s) with node memory, 5 node(s) had untolerated taint(s). no new claims to deallocate, preemption: 0/6 nodes are available: 1 No preemption victims found for incoming pod, 5 Preemption is not helpful for scheduling."
0.367,Event,ADDED,eval-sanitize-30-r1-080-8rqsm.18d4f7c834b72df1,"reason=FailedScheduling count=None msg=0/6 nodes are available: 2 c_wall violated: 1 conflicting context pair(s) with node memory, 4 node(s) had untolerated taint(s). no new claims to deallocate, preemption: 0/6 nodes are available: 2 No preemption victims found for incoming pod, 4 Preemption is not helpful for scheduling."
0.3673,Event,ADDED,eval-sanitize-30-r1-080-8rqsm.18d4f7c87cd90057,"reason=FailedScheduling count=None msg=0/6 nodes are available: 2 c_wall violated: 1 conflicting context pair(s) with node memory, 4 node(s) had untolerated taint(s). no new claims to deallocate, preemption: 0/6 nodes are available: 2 No preemption victims found for incoming pod, 4 Preemption is not helpful for scheduling."
0.3676,Event,ADDED,eval-sanitize-30-r1-080-8rqsm.18d4f7c888b637ef,"reason=FailedScheduling count=None msg=0/6 nodes are available: 2 c_wall violated: 1 conflicting context pair(s) with node memory, 4 node(s) had untolerated taint(s). no new claims to deallocate, preemption: 0/6 nodes are available: 2 No preemption victims found for incoming pod, 4 Preemption is not helpful for scheduling."
0.3678,Event,ADDED,eval-sanitize-30-r1-080-8rqsm.18d4f7c8e2a13ea5,reason=Scheduled count=None msg=Successfully assigned compute/eval-sanitize-30-r1-080-8rqsm to kind-worker5
0.3681,Event,ADDED,eval-sanitize-30-r1-080-8rqsm.18d4f7c900ebdb73,"reason=Pulled count=1 msg=Container image ""busybox:musl"" already present on machine"
0.3683,Event,ADDED,eval-sanitize-30-r1-080-8rqsm.18d4f7c902a7ed0d,reason=Created count=1 msg=Created container: task
0.3685,Event,ADDED,eval-sanitize-30-r1-080-8rqsm.18d4f7c907aba7ce,reason=Started count=1 msg=Started container task
0.3687,Event,ADDED,eval-sanitize-30-r1-080.18d4f7c526bb8afc,reason=SuccessfulCreate count=1 msg=Created pod: eval-sanitize-30-r1-080-8rqsm
0.369,Event,ADDED,eval-sanitize-30-r1-080.18d4f7cea7e3f091,reason=Completed count=1 msg=Job completed
0.3692,Event,ADDED,eval-sanitize-30-r1-081-lw2fm.18d4f7c5694d3a87,reason=Scheduled count=None msg=Successfully assigned compute/eval-sanitize-30-r1-081-lw2fm to kind-worker3
0.3694,Event,ADDED,eval-sanitize-30-r1-081-lw2fm.18d4f7c5871625ec,"reason=Pulled count=1 msg=Container image ""busybox:musl"" already present on machine"
0.3696,Event,ADDED,eval-sanitize-30-r1-081-lw2fm.18d4f7c588d0b825,reason=Created count=1 msg=Created container: task
0.3698,Event,ADDED,eval-sanitize-30-r1-081-lw2fm.18d4f7c59204a31d,reason=Started count=1 msg=Started container task
0.3702,Event,ADDED,eval-sanitize-30-r1-081.18d4f7c568545e61,reason=SuccessfulCreate count=1 msg=Created pod: eval-sanitize-30-r1-081-lw2fm
0.3705,Event,ADDED,eval-sanitize-30-r1-081.18d4f7cb14f2669b,reason=Completed count=1 msg=Job completed
0.3709,Event,ADDED,eval-sanitize-30-r1-082-wppn2.18d4f7c59ef0197f,"reason=FailedScheduling count=None msg=0/6 nodes are available: 1 c_wall violated: 2 conflicting context pair(s) with node memory, 5 node(s) had untolerated taint(s). no new claims to deallocate, preemption: 0/6 nodes are available: 1 No preemption victims found for incoming pod, 5 Preemption is not helpful for scheduling."
0.3715,Event,ADDED,eval-sanitize-30-r1-082-wppn2.18d4f7c59f9543c3,"reason=FailedScheduling count=None msg=0/6 nodes are available: 1 c_wall violated: 2 conflicting context pair(s) with node memory, 5 node(s) had untolerated taint(s). no new claims to deallocate, preemption: 0/6 nodes are available: 1 No preemption victims found for incoming pod, 5 Preemption is not helpful for scheduling."
0.3718,Event,ADDED,eval-sanitize-30-r1-082-wppn2.18d4f7c80b618ac9,reason=Scheduled count=None msg=Successfully assigned compute/eval-sanitize-30-r1-082-wppn2 to kind-worker
0.372,Event,ADDED,eval-sanitize-30-r1-082-wppn2.18d4f7c826cffa24,"reason=Pulled count=1 msg=Container image ""busybox:musl"" already present on machine"
0.3726,Event,ADDED,eval-sanitize-30-r1-082-wppn2.18d4f7c828cd8f4a,reason=Created count=1 msg=Created container: task
0.3728,Event,ADDED,eval-sanitize-30-r1-082-wppn2.18d4f7c82de92eaf,reason=Started count=1 msg=Started container task
0.373,Event,ADDED,eval-sanitize-30-r1-082.18d4f7c59e8c251e,reason=SuccessfulCreate count=1 msg=Created pod: eval-sanitize-30-r1-082-wppn2
0.3734,Event,ADDED,eval-sanitize-30-r1-082.18d4f7cd5eec8d97,reason=Completed count=1 msg=Job completed
0.3735,Event,ADDED,eval-sanitize-30-r1-083-g97l5.18d4f7c5daea30f0,"reason=FailedScheduling count=None msg=0/6 nodes are available: 1 c_wall violated: 3 conflicting context pair(s) with node memory, 5 node(s) had untolerated taint(s). no new claims to deallocate, preemption: 0/6 nodes are available: 1 No preemption victims found for incoming pod, 5 Preemption is not helpful for scheduling."
0.3737,Event,ADDED,eval-sanitize-30-r1-083-g97l5.18d4f7c5db9a53ca,"reason=FailedScheduling count=None msg=0/6 nodes are available: 1 c_wall violated: 3 conflicting context pair(s) with node memory, 5 node(s) had untolerated taint(s). no new claims to deallocate, preemption: 0/6 nodes are available: 1 No preemption victims found for incoming pod, 5 Preemption is not helpful for scheduling."
0.3739,Event,ADDED,eval-sanitize-30-r1-083-g97l5.18d4f7c812078a1e,reason=Scheduled count=None msg=Successfully assigned compute/eval-sanitize-30-r1-083-g97l5 to kind-worker
0.3743,Event,ADDED,eval-sanitize-30-r1-083-g97l5.18d4f7c82f56ea4e,"reason=Pulled count=1 msg=Container image ""busybox:musl"" already present on machine"
0.3745,Event,ADDED,eval-sanitize-30-r1-083-g97l5.18d4f7c830d56340,reason=Created count=1 msg=Created container: task
0.3746,Event,ADDED,eval-sanitize-30-r1-083-g97l5.18d4f7c83676ffc2,reason=Started count=1 msg=Started container task
0.3751,Event,ADDED,eval-sanitize-30-r1-083.18d4f7c5da9a0e65,reason=SuccessfulCreate count=1 msg=Created pod: eval-sanitize-30-r1-083-g97l5
0.3754,Event,ADDED,eval-sanitize-30-r1-083.18d4f7cd98dad2b4,reason=Completed count=1 msg=Job completed
0.3756,Event,ADDED,eval-sanitize-30-r1-084-tvscm.18d4f7c6160d552e,reason=Scheduled count=None msg=Successfully assigned compute/eval-sanitize-30-r1-084-tvscm to kind-worker3
0.3758,Event,ADDED,eval-sanitize-30-r1-084-tvscm.18d4f7c634057563,"reason=Pulled count=1 msg=Container image ""busybox:musl"" already present on machine"
0.3761,Event,ADDED,eval-sanitize-30-r1-084-tvscm.18d4f7c635631997,reason=Created count=1 msg=Created container: task
0.3764,Event,ADDED,eval-sanitize-30-r1-084-tvscm.18d4f7c63b288d1e,reason=Started count=1 msg=Started container task
0.3767,Event,ADDED,eval-sanitize-30-r1-084.18d4f7c61548cac1,reason=SuccessfulCreate count=1 msg=Created pod: eval-sanitize-30-r1-084-tvscm
0.3771,Event,ADDED,eval-sanitize-30-r1-084.18d4f7cbcb00407b,reason=Completed count=1 msg=Job completed
0.3774,Event,ADDED,eval-sanitize-30-r1-085-dqbz8.18d4f7c652aab771,reason=Scheduled count=None msg=Successfully assigned compute/eval-sanitize-30-r1-085-dqbz8 to kind-worker3
0.3777,Event,ADDED,eval-sanitize-30-r1-085-dqbz8.18d4f7c66db832a7,"reason=Pulled count=1 msg=Container image ""busybox:musl"" already present on machine"
0.3779,Event,ADDED,eval-sanitize-30-r1-085-dqbz8.18d4f7c66f096010,reason=Created count=1 msg=Created container: task
0.3782,Event,ADDED,eval-sanitize-30-r1-085-dqbz8.18d4f7c674f50707,reason=Started count=1 msg=Started container task
0.3785,Event,ADDED,eval-sanitize-30-r1-085.18d4f7c651e67554,reason=SuccessfulCreate count=1 msg=Created pod: eval-sanitize-30-r1-085-dqbz8
0.3787,Event,ADDED,eval-sanitize-30-r1-085.18d4f7cc062c7fb3,reason=Completed count=1 msg=Job completed
0.3789,Event,ADDED,eval-sanitize-30-r1-086-h6dmn.18d4f7c68d6068d5,reason=Scheduled count=None msg=Successfully assigned compute/eval-sanitize-30-r1-086-h6dmn to kind-worker3
0.3793,Event,ADDED,eval-sanitize-30-r1-086-h6dmn.18d4f7c6aa58ecc4,"reason=Pulled count=1 msg=Container image ""busybox:musl"" already present on machine"
0.3795,Event,ADDED,eval-sanitize-30-r1-086-h6dmn.18d4f7c6abe804aa,reason=Created count=1 msg=Created container: task
0.3798,Event,ADDED,eval-sanitize-30-r1-086-h6dmn.18d4f7c6b10f661a,reason=Started count=1 msg=Started container task
0.3801,Event,ADDED,eval-sanitize-30-r1-086.18d4f7c68c96100b,reason=SuccessfulCreate count=1 msg=Created pod: eval-sanitize-30-r1-086-h6dmn
0.3803,Event,ADDED,eval-sanitize-30-r1-086.18d4f7cc40687d07,reason=Completed count=1 msg=Job completed
0.3804,Event,ADDED,eval-sanitize-30-r1-087-n8l2p.18d4f7c6c8f53bac,"reason=FailedScheduling count=None msg=0/6 nodes are available: 1 c_wall violated: 3 conflicting context pair(s) with node memory, 5 node(s) had untolerated taint(s). no new claims to deallocate, preemption: 0/6 nodes are available: 1 No preemption victims found for incoming pod, 5 Preemption is not helpful for scheduling."
0.3806,Event,ADDED,eval-sanitize-30-r1-087-n8l2p.18d4f7c6c9a110fb,"reason=FailedScheduling count=None msg=0/6 nodes are available: 1 c_wall violated: 3 conflicting context pair(s) with node memory, 5 node(s) had untolerated taint(s). no new claims to deallocate, preemption: 0/6 nodes are available: 1 No preemption victims found for incoming pod, 5 Preemption is not helpful for scheduling."
0.381,Event,ADDED,eval-sanitize-30-r1-087-n8l2p.18d4f7c835c6e6d3,"reason=FailedScheduling count=None msg=0/6 nodes are available: 1 c_wall violated: 2 conflicting context pair(s) with node memory, 1 c_wall violated: 3 conflicting context pair(s) with node memory, 4 node(s) had untolerated taint(s). no new claims to deallocate, preemption: 0/6 nodes are available: 2 No preemption victims found for incoming pod, 4 Preemption is not helpful for scheduling."
0.3813,Event,ADDED,eval-sanitize-30-r1-087-n8l2p.18d4f7c86041b037,reason=Scheduled count=None msg=Successfully assigned compute/eval-sanitize-30-r1-087-n8l2p to kind-worker4
0.3816,Event,ADDED,eval-sanitize-30-r1-087-n8l2p.18d4f7c87b3ed189,"reason=Pulled count=1 msg=Container image ""busybox:musl"" already present on machine"
0.3821,Event,ADDED,eval-sanitize-30-r1-087-n8l2p.18d4f7c87ccfeb82,reason=Created count=1 msg=Created container: task
0.3824,Event,ADDED,eval-sanitize-30-r1-087-n8l2p.18d4f7c8840e3d18,reason=Started count=1 msg=Started container task
0.3828,Event,ADDED,eval-sanitize-30-r1-087.18d4f7c6c8a31b78,reason=SuccessfulCreate count=1 msg=Created pod: eval-sanitize-30-r1-087-n8l2p
0.3831,Event,ADDED,eval-sanitize-30-r1-087.18d4f7ce1bb1848c,reason=Completed count=1 msg=Job completed
0.3834,Event,ADDED,eval-sanitize-30-r1-088-z9jkk.18d4f7c7056b2496,"reason=FailedScheduling count=None msg=0/6 nodes are available: 1 c_wall violated: 3 conflicting context pair(s) with node memory, 5 node(s) had untolerated taint(s). no new claims to deallocate, preemption: 0/6 nodes are available: 1 No preemption victims found for incoming pod, 5 Preemption is not helpful for scheduling."
0.3836,Event,ADDED,eval-sanitize-30-r1-088-z9jkk.18d4f7c70669e862,"reason=FailedScheduling count=None msg=0/6 nodes are available: 1 c_wall violated: 3 conflicting context pair(s) with node memory, 5 node(s) had untolerated taint(s). no new claims to deallocate, preemption: 0/6 nodes are available: 1 No preemption victims found for incoming pod, 5 Preemption is not helpful for scheduling."
0.3838,Event,ADDED,eval-sanitize-30-r1-088-z9jkk.18d4f7c80580da73,reason=Scheduled count=None msg=Successfully assigned compute/eval-sanitize-30-r1-088-z9jkk to kind-worker
0.3841,Event,ADDED,eval-sanitize-30-r1-088-z9jkk.18d4f7c8211bca97,"reason=Pulled count=1 msg=Container image ""busybox:musl"" already present on machine"
0.3843,Event,ADDED,eval-sanitize-30-r1-088-z9jkk.18d4f7c8235302f7,reason=Created count=1 msg=Created container: task
0.3845,Event,ADDED,eval-sanitize-30-r1-088-z9jkk.18d4f7c8278ac514,reason=Started count=1 msg=Started container task
0.3848,Event,ADDED,eval-sanitize-30-r1-088.18d4f7c7050c5c28,reason=SuccessfulCreate count=1 msg=Created pod: eval-sanitize-30-r1-088-z9jkk
0.385,Event,ADDED,eval-sanitize-30-r1-088.18d4f7cd98d875c4,reason=Completed count=1 msg=Job completed
0.3852,Event,ADDED,eval-sanitize-30-r1-089-84z8g.18d4f7c740ef1148,reason=Scheduled count=None msg=Successfully assigned compute/eval-sanitize-30-r1-089-84z8g to kind-worker3
0.3854,Event,ADDED,eval-sanitize-30-r1-089-84z8g.18d4f7c75c236e13,"reason=Pulled count=1 msg=Container image ""busybox:musl"" already present on machine"
0.3857,Event,ADDED,eval-sanitize-30-r1-089-84z8g.18d4f7c75d71f3cf,reason=Created count=1 msg=Created container: task
0.3859,Event,ADDED,eval-sanitize-30-r1-089-84z8g.18d4f7c7627e25e7,reason=Started count=1 msg=Started container task
0.3861,Event,ADDED,eval-sanitize-30-r1-089.18d4f7c740426cff,reason=SuccessfulCreate count=1 msg=Created pod: eval-sanitize-30-r1-089-84z8g
0.3864,Event,ADDED,eval-sanitize-30-r1-089.18d4f7ccf887b48f,reason=Completed count=1 msg=Job completed
0.3868,Event,ADDED,eval-sanitize-30-r1-090-pmkr5.18d4f7c77c1514bb,reason=Scheduled count=None msg=Successfully assigned compute/eval-sanitize-30-r1-090-pmkr5 to kind-worker3
0.3872,Event,ADDED,eval-sanitize-30-r1-090-pmkr5.18d4f7c798f81abd,"reason=Pulled count=1 msg=Container image ""busybox:musl"" already present on machine"
0.3876,Event,ADDED,eval-sanitize-30-r1-090-pmkr5.18d4f7c79a52d177,reason=Created count=1 msg=Created container: task
0.3879,Event,ADDED,eval-sanitize-30-r1-090-pmkr5.18d4f7c79d1f0c36,reason=Started count=1 msg=Started container task
0.3881,Event,ADDED,eval-sanitize-30-r1-090.18d4f7c77b5ce5d2,reason=SuccessfulCreate count=1 msg=Created pod: eval-sanitize-30-r1-090-pmkr5
0.3886,Event,ADDED,eval-sanitize-30-r1-090.18d4f7cd3401128b,reason=Completed count=1 msg=Job completed
0.389,Event,ADDED,eval-sanitize-30-r1-091-jwvs2.18d4f7c7b780b7ec,reason=Scheduled count=None msg=Successfully assigned compute/eval-sanitize-30-r1-091-jwvs2 to kind-worker3
0.3893,Event,ADDED,eval-sanitize-30-r1-091-jwvs2.18d4f7c7d1c9d0aa,"reason=Pulled count=1 msg=Container image ""busybox:musl"" already present on machine"
0.3896,Event,ADDED,eval-sanitize-30-r1-091-jwvs2.18d4f7c7d3163e11,reason=Created count=1 msg=Created container: task
0.3899,Event,ADDED,eval-sanitize-30-r1-091-jwvs2.18d4f7c7d8230739,reason=Started count=1 msg=Started container task
0.3901,Event,ADDED,eval-sanitize-30-r1-091.18d4f7c7b6bfcb4c,reason=SuccessfulCreate count=1 msg=Created pod: eval-sanitize-30-r1-091-jwvs2
0.3904,Event,ADDED,eval-sanitize-30-r1-091.18d4f7cd6f7f4e94,reason=Completed count=1 msg=Job completed
0.3905,Event,ADDED,eval-sanitize-30-r1-092-rfngt.18d4f7c7f31bc463,reason=Scheduled count=None msg=Successfully assigned compute/eval-sanitize-30-r1-092-rfngt to kind-worker3
0.3907,Event,ADDED,eval-sanitize-30-r1-092-rfngt.18d4f7c80e9cee45,"reason=Pulled count=1 msg=Container image ""busybox:musl"" already present on machine"
0.391,Event,ADDED,eval-sanitize-30-r1-092-rfngt.18d4f7c80fdede44,reason=Created count=1 msg=Created container: task
0.3912,Event,ADDED,eval-sanitize-30-r1-092-rfngt.18d4f7c8157eebb5,reason=Started count=1 msg=Started container task
0.3914,Event,ADDED,eval-sanitize-30-r1-092.18d4f7c7f235c87f,reason=SuccessfulCreate count=1 msg=Created pod: eval-sanitize-30-r1-092-rfngt
0.3916,Event,ADDED,eval-sanitize-30-r1-092.18d4f7cda9f1f394,reason=Completed count=1 msg=Job completed
0.3919,Event,ADDED,eval-sanitize-30-r1-093-4swcl.18d4f7c82ffe2ca6,reason=Scheduled count=None msg=Successfully assigned compute/eval-sanitize-30-r1-093-4swcl to kind-worker3
0.3921,Event,ADDED,eval-sanitize-30-r1-093-4swcl.18d4f7c84c44b568,"reason=Pulled count=1 msg=Container image ""busybox:musl"" already present on machine"
0.3923,Event,ADDED,eval-sanitize-30-r1-093-4swcl.18d4f7c84de32661,reason=Created count=1 msg=Created container: task
0.3925,Event,ADDED,eval-sanitize-30-r1-093-4swcl.18d4f7c8530404b9,reason=Started count=1 msg=Started container task
0.393,Event,ADDED,eval-sanitize-30-r1-093.18d4f7c82e3e8536,reason=SuccessfulCreate count=1 msg=Created pod: eval-sanitize-30-r1-093-4swcl
0.3932,Event,ADDED,eval-sanitize-30-r1-093.18d4f7cde6117847,reason=Completed count=1 msg=Job completed
0.3935,Event,ADDED,eval-sanitize-30-r1-094-xsdwg.18d4f7c876dd4d85,"reason=FailedScheduling count=None msg=0/6 nodes are available: 2 c_wall violated: 1 conflicting context pair(s) with node memory, 4 node(s) had untolerated taint(s). no new claims to deallocate, preemption: 0/6 nodes are available: 2 No preemption victims found for incoming pod, 4 Preemption is not helpful for scheduling."
0.3938,Event,ADDED,eval-sanitize-30-r1-094-xsdwg.18d4f7c88214a20f,"reason=FailedScheduling count=None msg=0/6 nodes are available: 2 c_wall violated: 1 conflicting context pair(s) with node memory, 4 node(s) had untolerated taint(s). no new claims to deallocate, preemption: 0/6 nodes are available: 2 No preemption victims found for incoming pod, 4 Preemption is not helpful for scheduling."
0.394,Event,ADDED,eval-sanitize-30-r1-094-xsdwg.18d4f7c8d71bdc05,reason=Scheduled count=None msg=Successfully assigned compute/eval-sanitize-30-r1-094-xsdwg to kind-worker5
0.3942,Event,ADDED,eval-sanitize-30-r1-094-xsdwg.18d4f7c8efb0abb0,"reason=Pulled count=1 msg=Container image ""busybox:musl"" already present on machine"
0.3944,Event,ADDED,eval-sanitize-30-r1-094-xsdwg.18d4f7c8f13f0c66,reason=Created count=1 msg=Created container: task
0.3947,Event,ADDED,eval-sanitize-30-r1-094-xsdwg.18d4f7c8f879929c,reason=Started count=1 msg=Started container task
0.395,Event,ADDED,eval-sanitize-30-r1-094.18d4f7c86d9fe9e2,reason=SuccessfulCreate count=1 msg=Created pod: eval-sanitize-30-r1-094-xsdwg
0.3952,Event,ADDED,eval-sanitize-30-r1-094.18d4f7ce6621081c,reason=Completed count=1 msg=Job completed
0.3955,Event,ADDED,eval-sanitize-30-r1-095-vfskn.18d4f7c8a5f2866e,reason=Scheduled count=None msg=Successfully assigned compute/eval-sanitize-30-r1-095-vfskn to kind-worker4
0.3957,Event,ADDED,eval-sanitize-30-r1-095-vfskn.18d4f7c8c34de242,"reason=Pulled count=1 msg=Container image ""busybox:musl"" already present on machine"
0.3959,Event,ADDED,eval-sanitize-30-r1-095-vfskn.18d4f7c8c4a13631,reason=Created count=1 msg=Created container: task
0.3961,Event,ADDED,eval-sanitize-30-r1-095-vfskn.18d4f7c8c9cb5c15,reason=Started count=1 msg=Started container task
0.3964,Event,ADDED,eval-sanitize-30-r1-095.18d4f7c8a5028aa2,reason=SuccessfulCreate count=1 msg=Created pod: eval-sanitize-30-r1-095-vfskn
0.3967,Event,ADDED,eval-sanitize-30-r1-095.18d4f7ce5608d885,reason=Completed count=1 msg=Job completed
0.3969,Event,ADDED,eval-sanitize-30-r1-096-mccdd.18d4f7c8e367cd8a,reason=Scheduled count=None msg=Successfully assigned compute/eval-sanitize-30-r1-096-mccdd to kind-worker
0.3971,Event,ADDED,eval-sanitize-30-r1-096-mccdd.18d4f7c900d09772,"reason=Pulled count=1 msg=Container image ""busybox:musl"" already present on machine"
0.3974,Event,ADDED,eval-sanitize-30-r1-096-mccdd.18d4f7c9028bd49e,reason=Created count=1 msg=Created container: task
0.3976,Event,ADDED,eval-sanitize-30-r1-096-mccdd.18d4f7c907974e2c,reason=Started count=1 msg=Started container task
0.3979,Event,ADDED,eval-sanitize-30-r1-096.18d4f7c8e120d161,reason=SuccessfulCreate count=1 msg=Created pod: eval-sanitize-30-r1-096-mccdd
0.3985,Event,ADDED,eval-sanitize-30-r1-096.18d4f7ce958f6177,reason=Completed count=1 msg=Job completed
0.3987,Event,ADDED,eval-sanitize-30-r1-097-2fqbl.18d4f7c91db448b0,reason=Scheduled count=None msg=Successfully assigned compute/eval-sanitize-30-r1-097-2fqbl to kind-worker2
0.3989,Event,ADDED,eval-sanitize-30-r1-097-2fqbl.18d4f7c93b114efc,"reason=Pulled count=1 msg=Container image ""busybox:musl"" already present on machine"
0.3991,Event,ADDED,eval-sanitize-30-r1-097-2fqbl.18d4f7c93cada409,reason=Created count=1 msg=Created container: task
0.3994,Event,ADDED,eval-sanitize-30-r1-097-2fqbl.18d4f7c9409d1f70,reason=Started count=1 msg=Started container task
0.3999,Event,ADDED,eval-sanitize-30-r1-097.18d4f7c91c677062,reason=SuccessfulCreate count=1 msg=Created pod: eval-sanitize-30-r1-097-2fqbl
0.4001,Event,ADDED,eval-sanitize-30-r1-097.18d4f7ced0f76e01,reason=Completed count=1 msg=Job completed
0.4003,Event,ADDED,eval-sanitize-30-r1-098-7q5hz.18d4f7c95a8a6b1a,reason=Scheduled count=None msg=Successfully assigned compute/eval-sanitize-30-r1-098-7q5hz to kind-worker2
0.4005,Event,ADDED,eval-sanitize-30-r1-098-7q5hz.18d4f7c97497a0d3,"reason=Pulled count=1 msg=Container image ""busybox:musl"" already present on machine"
0.4007,Event,ADDED,eval-sanitize-30-r1-098-7q5hz.18d4f7c975e576c9,reason=Created count=1 msg=Created container: task
0.4009,Event,ADDED,eval-sanitize-30-r1-098-7q5hz.18d4f7c97b891d97,reason=Started count=1 msg=Started container task
0.4013,Event,ADDED,eval-sanitize-30-r1-098.18d4f7c957bc0b8e,reason=SuccessfulCreate count=1 msg=Created pod: eval-sanitize-30-r1-098-7q5hz
0.4015,Event,ADDED,eval-sanitize-30-r1-098.18d4f7cf15927b2f,reason=Completed count=1 msg=Job completed
0.4017,Event,ADDED,eval-sanitize-30-r1-099-hmt84.18d4f7c99a9b74ea,reason=Scheduled count=None msg=Successfully assigned compute/eval-sanitize-30-r1-099-hmt84 to kind-worker
0.4019,Event,ADDED,eval-sanitize-30-r1-099-hmt84.18d4f7c9b55132e0,"reason=Pulled count=1 msg=Container image ""busybox:musl"" already present on machine"
0.4022,Event,ADDED,eval-sanitize-30-r1-099-hmt84.18d4f7c9b6955616,reason=Created count=1 msg=Created container: task
0.4024,Event,ADDED,eval-sanitize-30-r1-099-hmt84.18d4f7c9ba91cbf4,reason=Started count=1 msg=Started container task
0.4025,Event,ADDED,eval-sanitize-30-r1-099.18d4f7c993bd7b4e,reason=SuccessfulCreate count=1 msg=Created pod: eval-sanitize-30-r1-099-hmt84
0.4027,Event,ADDED,eval-sanitize-30-r1-099.18d4f7cf43ea0fc9,reason=Completed count=1 msg=Job completed
0.4029,Event,ADDED,eval-sanitize-30-r1-100-bnwdb.18d4f7c9d11f7f18,reason=Scheduled count=None msg=Successfully assigned compute/eval-sanitize-30-r1-100-bnwdb to kind-worker
0.4031,Event,ADDED,eval-sanitize-30-r1-100-bnwdb.18d4f7c9efbdf0cf,"reason=Pulled count=1 msg=Container image ""busybox:musl"" already present on machine"
0.4037,Event,ADDED,eval-sanitize-30-r1-100-bnwdb.18d4f7c9f1134494,reason=Created count=1 msg=Created container: task
0.4041,Event,ADDED,eval-sanitize-30-r1-100-bnwdb.18d4f7c9f59407ce,reason=Started count=1 msg=Started container task
0.4043,Event,ADDED,eval-sanitize-30-r1-100.18d4f7c9cf23126d,reason=SuccessfulCreate count=1 msg=Created pod: eval-sanitize-30-r1-100-bnwdb
0.4045,Event,ADDED,eval-sanitize-30-r1-100.18d4f7cf800f1a43,reason=Completed count=1 msg=Job completed
0.4047,Event,ADDED,eval-sanitize-30-r1-101-xg9zh.18d4f7ca11e35342,reason=Scheduled count=None msg=Successfully assigned compute/eval-sanitize-30-r1-101-xg9zh to kind-worker2
0.4051,Event,ADDED,eval-sanitize-30-r1-101-xg9zh.18d4f7ca2e1a026e,"reason=Pulled count=1 msg=Container image ""busybox:musl"" already present on machine"
0.4053,Event,ADDED,eval-sanitize-30-r1-101-xg9zh.18d4f7ca2f6d0952,reason=Created count=1 msg=Created container: task
0.4055,Event,ADDED,eval-sanitize-30-r1-101-xg9zh.18d4f7ca3412f2f1,reason=Started count=1 msg=Started container task
0.4057,Event,ADDED,eval-sanitize-30-r1-101.18d4f7ca0ab6462c,reason=SuccessfulCreate count=1 msg=Created pod: eval-sanitize-30-r1-101-xg9zh
0.406,Event,ADDED,eval-sanitize-30-r1-101.18d4f7cfc0dbf3dd,reason=Completed count=1 msg=Job completed
0.4062,Event,ADDED,eval-sanitize-30-r1-102-g9jcq.18d4f7ca48761d53,reason=Scheduled count=None msg=Successfully assigned compute/eval-sanitize-30-r1-102-g9jcq to kind-worker4
0.4064,Event,ADDED,eval-sanitize-30-r1-102-g9jcq.18d4f7ca63cda9e6,"reason=Pulled count=1 msg=Container image ""busybox:musl"" already present on machine"
0.4066,Event,ADDED,eval-sanitize-30-r1-102-g9jcq.18d4f7ca650ed897,reason=Created count=1 msg=Created container: task
0.4068,Event,ADDED,eval-sanitize-30-r1-102-g9jcq.18d4f7ca695c5a0f,reason=Started count=1 msg=Started container task
0.407,Event,ADDED,eval-sanitize-30-r1-102.18d4f7ca4686703b,reason=SuccessfulCreate count=1 msg=Created pod: eval-sanitize-30-r1-102-g9jcq
0.4072,Event,ADDED,eval-sanitize-30-r1-102.18d4f7cff2392483,reason=Completed count=1 msg=Job completed
0.4075,Event,ADDED,eval-sanitize-30-r1-103-7489c.18d4f7ca83c018f7,reason=Scheduled count=None msg=Successfully assigned compute/eval-sanitize-30-r1-103-7489c to kind-worker2
0.4077,Event,ADDED,eval-sanitize-30-r1-103-7489c.18d4f7caa3b060ed,"reason=Pulled count=1 msg=Container image ""busybox:musl"" already present on machine"
0.4079,Event,ADDED,eval-sanitize-30-r1-103-7489c.18d4f7caa4f83803,reason=Created count=1 msg=Created container: task
0.4081,Event,ADDED,eval-sanitize-30-r1-103-7489c.18d4f7caa9fc9065,reason=Started count=1 msg=Started container task
0.4083,Event,ADDED,eval-sanitize-30-r1-103.18d4f7ca81c779d4,reason=SuccessfulCreate count=1 msg=Created pod: eval-sanitize-30-r1-103-7489c
0.4085,Event,ADDED,eval-sanitize-30-r1-103.18d4f7d0461d9f15,reason=Completed count=1 msg=Job completed
0.4087,Event,ADDED,eval-sanitize-30-r1-104-lfth6.18d4f7cabf5d1fba,reason=Scheduled count=None msg=Successfully assigned compute/eval-sanitize-30-r1-104-lfth6 to kind-worker4
0.4092,Event,ADDED,eval-sanitize-30-r1-104-lfth6.18d4f7cadac22917,"reason=Pulled count=1 msg=Container image ""busybox:musl"" already present on machine"
0.4095,Event,ADDED,eval-sanitize-30-r1-104-lfth6.18d4f7cadc1abe56,reason=Created count=1 msg=Created container: task
0.4098,Event,ADDED,eval-sanitize-30-r1-104-lfth6.18d4f7cae0c6ffd8,reason=Started count=1 msg=Started container task
0.4101,Event,ADDED,eval-sanitize-30-r1-104.18d4f7cabd59d252,reason=SuccessfulCreate count=1 msg=Created pod: eval-sanitize-30-r1-104-lfth6
0.4104,Event,ADDED,eval-sanitize-30-r1-104.18d4f7d073ed95f3,reason=Completed count=1 msg=Job completed
0.4106,Event,ADDED,eval-sanitize-30-r1-105-qf6sr.18d4f7cafb06b0e7,reason=Scheduled count=None msg=Successfully assigned compute/eval-sanitize-30-r1-105-qf6sr to kind-worker2
0.4108,Event,ADDED,eval-sanitize-30-r1-105-qf6sr.18d4f7cb15b02ca8,"reason=Pulled count=1 msg=Container image ""busybox:musl"" already present on machine"
0.411,Event,ADDED,eval-sanitize-30-r1-105-qf6sr.18d4f7cb17401eee,reason=Created count=1 msg=Created container: task
0.4113,Event,ADDED,eval-sanitize-30-r1-105-qf6sr.18d4f7cb20297bf0,reason=Started count=1 msg=Started container task
0.4115,Event,ADDED,eval-sanitize-30-r1-105.18d4f7caf92a224d,reason=SuccessfulCreate count=1 msg=Created pod: eval-sanitize-30-r1-105-qf6sr
0.4117,Event,ADDED,eval-sanitize-30-r1-105.18d4f7d081e4c3bc,reason=Completed count=1 msg=Job completed
0.4119,Event,ADDED,eval-sanitize-30-r1-106-wqnfm.18d4f7cb36887015,reason=Scheduled count=None msg=Successfully assigned compute/eval-sanitize-30-r1-106-wqnfm to kind-worker
0.4121,Event,ADDED,eval-sanitize-30-r1-106-wqnfm.18d4f7cb53c257a5,"reason=Pulled count=1 msg=Container image ""busybox:musl"" already present on machine"
0.4123,Event,ADDED,eval-sanitize-30-r1-106-wqnfm.18d4f7cb552f55fa,reason=Created count=1 msg=Created container: task
0.4124,Event,ADDED,eval-sanitize-30-r1-106-wqnfm.18d4f7cb59fe45fc,reason=Started count=1 msg=Started container task
0.4126,Event,ADDED,eval-sanitize-30-r1-106.18d4f7cb349ecdd3,reason=SuccessfulCreate count=1 msg=Created pod: eval-sanitize-30-r1-106-wqnfm
0.4128,Event,ADDED,eval-sanitize-30-r1-106.18d4f7d0ecac65eb,reason=Completed count=1 msg=Job completed
0.413,Event,ADDED,eval-sanitize-30-r1-107-jxksh.18d4f7cb7753e3e6,reason=Scheduled count=None msg=Successfully assigned compute/eval-sanitize-30-r1-107-jxksh to kind-worker5
0.4131,Event,ADDED,eval-sanitize-30-r1-107-jxksh.18d4f7cb93720c1f,"reason=Pulled count=1 msg=Container image ""busybox:musl"" already present on machine"
0.4133,Event,ADDED,eval-sanitize-30-r1-107-jxksh.18d4f7cb94ffe2ce,reason=Created count=1 msg=Created container: task
0.4136,Event,ADDED,eval-sanitize-30-r1-107-jxksh.18d4f7cb9b2d49bf,reason=Started count=1 msg=Started container task
0.4138,Event,ADDED,eval-sanitize-30-r1-107.18d4f7cb70a9a097,reason=SuccessfulCreate count=1 msg=Created pod: eval-sanitize-30-r1-107-jxksh
0.4141,Event,ADDED,eval-sanitize-30-r1-107.18d4f7d13a6507f2,reason=Completed count=1 msg=Job completed
0.4142,Event,ADDED,eval-sanitize-30-r1-108-pbnc4.18d4f7cbb2eb3bac,reason=Scheduled count=None msg=Successfully assigned compute/eval-sanitize-30-r1-108-pbnc4 to kind-worker2
0.4145,Event,ADDED,eval-sanitize-30-r1-108-pbnc4.18d4f7cbcf74cef2,"reason=Pulled count=1 msg=Container image ""busybox:musl"" already present on machine"
0.4147,Event,ADDED,eval-sanitize-30-r1-108-pbnc4.18d4f7cbd12eec80,reason=Created count=1 msg=Created container: task
0.4152,Event,ADDED,eval-sanitize-30-r1-108-pbnc4.18d4f7cbd6cf3679,reason=Started count=1 msg=Started container task
0.4154,Event,ADDED,eval-sanitize-30-r1-108.18d4f7cbabef28af,reason=SuccessfulCreate count=1 msg=Created pod: eval-sanitize-30-r1-108-pbnc4
0.4156,Event,ADDED,eval-sanitize-30-r1-108.18d4f7d165635470,reason=Completed count=1 msg=Job completed
0.4158,Event,ADDED,eval-sanitize-30-r1-109-4s2vp.18d4f7cbef262d37,reason=Scheduled count=None msg=Successfully assigned compute/eval-sanitize-30-r1-109-4s2vp to kind-worker5
0.4161,Event,ADDED,eval-sanitize-30-r1-109-4s2vp.18d4f7cc0be566a0,"reason=Pulled count=1 msg=Container image ""busybox:musl"" already present on machine"
0.4166,Event,ADDED,eval-sanitize-30-r1-109-4s2vp.18d4f7cc0d3a0113,reason=Created count=1 msg=Created container: task
0.4168,Event,ADDED,eval-sanitize-30-r1-109-4s2vp.18d4f7cc13e6869d,reason=Started count=1 msg=Started container task
0.4172,Event,ADDED,eval-sanitize-30-r1-109.18d4f7cbe7c43ff4,reason=SuccessfulCreate count=1 msg=Created pod: eval-sanitize-30-r1-109-4s2vp
0.4173,Event,ADDED,eval-sanitize-30-r1-109.18d4f7d1b370baf5,reason=Completed count=1 msg=Job completed
0.4175,Event,ADDED,eval-sanitize-30-r1-110-7t6dw.18d4f7cc2aed772c,reason=Scheduled count=None msg=Successfully assigned compute/eval-sanitize-30-r1-110-7t6dw to kind-worker4
0.4177,Event,ADDED,eval-sanitize-30-r1-110-7t6dw.18d4f7cc4963acab,"reason=Pulled count=1 msg=Container image ""busybox:musl"" already present on machine"
0.418,Event,ADDED,eval-sanitize-30-r1-110-7t6dw.18d4f7cc4ad5c397,reason=Created count=1 msg=Created container: task
0.4181,Event,ADDED,eval-sanitize-30-r1-110-7t6dw.18d4f7cc4fe09377,reason=Started count=1 msg=Started container task
0.4185,Event,ADDED,eval-sanitize-30-r1-110.18d4f7cc244d314a,reason=SuccessfulCreate count=1 msg=Created pod: eval-sanitize-30-r1-110-7t6dw
0.4187,Event,ADDED,eval-sanitize-30-r1-110.18d4f7d1ce82bbb8,reason=Completed count=1 msg=Job completed
0.4188,Event,ADDED,eval-sanitize-30-r1-111-mbj7n.18d4f7cc6b15a8af,reason=Scheduled count=None msg=Successfully assigned compute/eval-sanitize-30-r1-111-mbj7n to kind-worker5
0.419,Event,ADDED,eval-sanitize-30-r1-111-mbj7n.18d4f7cc8858b430,"reason=Pulled count=1 msg=Container image ""busybox:musl"" already present on machine"
0.4192,Event,ADDED,eval-sanitize-30-r1-111-mbj7n.18d4f7cc89eeeb63,reason=Created count=1 msg=Created container: task
0.4194,Event,ADDED,eval-sanitize-30-r1-111-mbj7n.18d4f7cc926a58c7,reason=Started count=1 msg=Started container task
0.4196,Event,ADDED,eval-sanitize-30-r1-111.18d4f7cc61802478,reason=SuccessfulCreate count=1 msg=Created pod: eval-sanitize-30-r1-111-mbj7n
0.4198,Event,ADDED,eval-sanitize-30-r1-111.18d4f7d22a85f0d1,reason=Completed count=1 msg=Job completed
0.4201,Event,ADDED,eval-sanitize-30-r1-112-npgrt.18d4f7cca66dc983,reason=Scheduled count=None msg=Successfully assigned compute/eval-sanitize-30-r1-112-npgrt to kind-worker
0.4203,Event,ADDED,eval-sanitize-30-r1-112-npgrt.18d4f7cccbf1494b,"reason=Pulled count=1 msg=Container image ""busybox:musl"" already present on machine"
0.4206,Event,ADDED,eval-sanitize-30-r1-112-npgrt.18d4f7cccde267e5,reason=Created count=1 msg=Created container: task
0.4211,Event,ADDED,eval-sanitize-30-r1-112-npgrt.18d4f7ccd58b735d,reason=Started count=1 msg=Started container task
0.4216,Event,ADDED,eval-sanitize-30-r1-112.18d4f7cc9aabc88f,reason=SuccessfulCreate count=1 msg=Created pod: eval-sanitize-30-r1-112-npgrt
0.4218,Event,ADDED,eval-sanitize-30-r1-112.18d4f7d246a3d2d1,reason=Completed count=1 msg=Job completed
0.4222,Event,ADDED,eval-sanitize-30-r1-113-msgfs.18d4f7ccdd42b8f0,reason=Scheduled count=None msg=Successfully assigned compute/eval-sanitize-30-r1-113-msgfs to kind-worker2
0.4225,Event,ADDED,eval-sanitize-30-r1-113-msgfs.18d4f7ccfa92b15a,"reason=Pulled count=1 msg=Container image ""busybox:musl"" already present on machine"
0.4228,Event,ADDED,eval-sanitize-30-r1-113-msgfs.18d4f7ccfc51786a,reason=Created count=1 msg=Created container: task
0.423,Event,ADDED,eval-sanitize-30-r1-113-msgfs.18d4f7cd035f5c26,reason=Started count=1 msg=Started container task
0.4238,Event,ADDED,eval-sanitize-30-r1-113.18d4f7ccd689b589,reason=SuccessfulCreate count=1 msg=Created pod: eval-sanitize-30-r1-113-msgfs
0.4242,Event,ADDED,eval-sanitize-30-r1-113.18d4f7d28fd5d076,reason=Completed count=1 msg=Job completed
0.4244,Event,ADDED,eval-sanitize-30-r1-114-2jsbf.18d4f7cd15d45f96,reason=Scheduled count=None msg=Successfully assigned compute/eval-sanitize-30-r1-114-2jsbf to kind-worker5
0.4247,Event,ADDED,eval-sanitize-30-r1-114-2jsbf.18d4f7cd367f2ea9,"reason=Pulled count=1 msg=Container image ""busybox:musl"" already present on machine"
0.425,Event,ADDED,eval-sanitize-30-r1-114-2jsbf.18d4f7cd3815fb7b,reason=Created count=1 msg=Created container: task
0.4253,Event,ADDED,eval-sanitize-30-r1-114-2jsbf.18d4f7cd3f07ce95,reason=Started count=1 msg=Started container task
0.4257,Event,ADDED,eval-sanitize-30-r1-114.18d4f7cd1447fc9a,reason=SuccessfulCreate count=1 msg=Created pod: eval-sanitize-30-r1-114-2jsbf
0.4261,Event,ADDED,eval-sanitize-30-r1-114.18d4f7d2d8af2437,reason=Completed count=1 msg=Job completed
0.4266,Event,ADDED,eval-sanitize-30-r1-115-8s45d.18d4f7cd4efad161,reason=Scheduled count=None msg=Successfully assigned compute/eval-sanitize-30-r1-115-8s45d to kind-worker
0.427,Event,ADDED,eval-sanitize-30-r1-115-8s45d.18d4f7cd6d7ce9ef,"reason=Pulled count=1 msg=Container image ""busybox:musl"" already present on machine"
0.4273,Event,ADDED,eval-sanitize-30-r1-115-8s45d.18d4f7cd6f41f9ea,reason=Created count=1 msg=Created container: task
0.4277,Event,ADDED,eval-sanitize-30-r1-115-8s45d.18d4f7cd7468866e,reason=Started count=1 msg=Started container task
0.428,Event,ADDED,eval-sanitize-30-r1-115.18d4f7cd4d5c570e,reason=SuccessfulCreate count=1 msg=Created pod: eval-sanitize-30-r1-115-8s45d
0.4282,Event,ADDED,eval-sanitize-30-r1-115.18d4f7d2fd08f493,reason=Completed count=1 msg=Job completed
0.4284,Event,ADDED,eval-sanitize-30-r1-116-qddsp.18d4f7cd92710e93,reason=Scheduled count=None msg=Successfully assigned compute/eval-sanitize-30-r1-116-qddsp to kind-worker5
0.4288,Event,ADDED,eval-sanitize-30-r1-116-qddsp.18d4f7cdb7bfaf73,"reason=Pulled count=1 msg=Container image ""busybox:musl"" already present on machine"
0.4291,Event,ADDED,eval-sanitize-30-r1-116-qddsp.18d4f7cdb9204faa,reason=Created count=1 msg=Created container: task
0.4294,Event,ADDED,eval-sanitize-30-r1-116-qddsp.18d4f7cdc347895b,reason=Started count=1 msg=Started container task
0.4299,Event,ADDED,eval-sanitize-30-r1-116.18d4f7cd8c39ff7b,reason=SuccessfulCreate count=1 msg=Created pod: eval-sanitize-30-r1-116-qddsp
0.4302,Event,ADDED,eval-sanitize-30-r1-116.18d4f7d34c943637,reason=Completed count=1 msg=Job completed
0.4304,Event,ADDED,eval-sanitize-30-r1-117-8swmh.18d4f7cdcdbf1e33,reason=Scheduled count=None msg=Successfully assigned compute/eval-sanitize-30-r1-117-8swmh to kind-worker4
0.4306,Event,ADDED,eval-sanitize-30-r1-117-8swmh.18d4f7cdf200f8f4,"reason=Pulled count=1 msg=Container image ""busybox:musl"" already present on machine"
0.4309,Event,ADDED,eval-sanitize-30-r1-117-8swmh.18d4f7cdf3ce15d9,reason=Created count=1 msg=Created container: task
0.4312,Event,ADDED,eval-sanitize-30-r1-117-8swmh.18d4f7cdf83a8aad,reason=Started count=1 msg=Started container task
0.4314,Event,ADDED,eval-sanitize-30-r1-117.18d4f7cdc55b445e,reason=SuccessfulCreate count=1 msg=Created pod: eval-sanitize-30-r1-117-8swmh
0.4316,Event,ADDED,eval-sanitize-30-r1-117.18d4f7d37493c979,reason=Completed count=1 msg=Job completed
0.4319,Event,ADDED,eval-sanitize-30-r1-118-mblqp.18d4f7ce02d47197,reason=Scheduled count=None msg=Successfully assigned compute/eval-sanitize-30-r1-118-mblqp to kind-worker5
0.4321,Event,ADDED,eval-sanitize-30-r1-118-mblqp.18d4f7ce21f1345a,"reason=Pulled count=1 msg=Container image ""busybox:musl"" already present on machine"
0.4323,Event,ADDED,eval-sanitize-30-r1-118-mblqp.18d4f7ce23885ebf,reason=Created count=1 msg=Created container: task
0.4326,Event,ADDED,eval-sanitize-30-r1-118-mblqp.18d4f7ce2b1f1b4d,reason=Started count=1 msg=Started container task
0.4329,Event,ADDED,eval-sanitize-30-r1-118.18d4f7ce00be828d,reason=SuccessfulCreate count=1 msg=Created pod: eval-sanitize-30-r1-118-mblqp
0.4331,Event,ADDED,eval-sanitize-30-r1-118.18d4f7d3c8d46ae1,reason=Completed count=1 msg=Job completed
0.4333,Event,ADDED,eval-sanitize-30-r1-119-cf7sx.18d4f7ce437c2624,reason=Scheduled count=None msg=Successfully assigned compute/eval-sanitize-30-r1-119-cf7sx to kind-worker4
0.4336,Event,ADDED,eval-sanitize-30-r1-119-cf7sx.18d4f7ce64d70866,"reason=Pulled count=1 msg=Container image ""busybox:musl"" already present on machine"
0.4338,Event,ADDED,eval-sanitize-30-r1-119-cf7sx.18d4f7ce671fc972,reason=Created count=1 msg=Created container: task
0.434,Event,ADDED,eval-sanitize-30-r1-119-cf7sx.18d4f7ce732461fc,reason=Started count=1 msg=Started container task
0.4342,Event,ADDED,eval-sanitize-30-r1-119.18d4f7ce3f4cb613,reason=SuccessfulCreate count=1 msg=Created pod: eval-sanitize-30-r1-119-cf7sx
0.4345,Event,ADDED,eval-sanitize-30-r1-119.18d4f7d3ed5d7170,reason=Completed count=1 msg=Job completed
0.4347,Event,ADDED,eval-sanitize-30-r1-120-mkcck.18d4f7ce80c7ec5d,reason=Scheduled count=None msg=Successfully assigned compute/eval-sanitize-30-r1-120-mkcck to kind-worker
0.4351,Event,ADDED,eval-sanitize-30-r1-120-mkcck.18d4f7cea6e40a1d,"reason=Pulled count=1 msg=Container image ""busybox:musl"" already present on machine"
0.4355,Event,ADDED,eval-sanitize-30-r1-120-mkcck.18d4f7cea91baed1,reason=Created count=1 msg=Created container: task
0.4357,Event,ADDED,eval-sanitize-30-r1-120-mkcck.18d4f7ceb0d6de00,reason=Started count=1 msg=Started container task
0.4361,Event,ADDED,eval-sanitize-30-r1-120.18d4f7ce7775bb4b,reason=SuccessfulCreate count=1 msg=Created pod: eval-sanitize-30-r1-120-mkcck
0.4363,Event,ADDED,eval-sanitize-30-r1-120.18d4f7d42c6501f1,reason=Completed count=1 msg=Job completed
0.4367,Event,ADDED,eval-sanitize-30-r1-121-5vldj.18d4f7cec095e173,reason=Scheduled count=None msg=Successfully assigned compute/eval-sanitize-30-r1-121-5vldj to kind-worker4
0.4369,Event,ADDED,eval-sanitize-30-r1-121-5vldj.18d4f7cefbbc0deb,"reason=Pulled count=1 msg=Container image ""busybox:musl"" already present on machine"
0.4371,Event,ADDED,eval-sanitize-30-r1-121-5vldj.18d4f7cefd4cd475,reason=Created count=1 msg=Created container: task
0.4373,Event,ADDED,eval-sanitize-30-r1-121-5vldj.18d4f7cf07886f55,reason=Started count=1 msg=Started container task
0.4377,Event,ADDED,eval-sanitize-30-r1-121.18d4f7ceb31d2475,reason=SuccessfulCreate count=1 msg=Created pod: eval-sanitize-30-r1-121-5vldj
0.4379,Event,ADDED,eval-sanitize-30-r1-121.18d4f7d49bdf52c5,reason=Completed count=1 msg=Job completed
0.4381,Event,ADDED,eval-sanitize-30-r1-122-sk6b4.18d4f7cefb9f0446,reason=Scheduled count=None msg=Successfully assigned compute/eval-sanitize-30-r1-122-sk6b4 to kind-worker2
0.4384,Event,ADDED,eval-sanitize-30-r1-122-sk6b4.18d4f7cf26bcd123,"reason=Pulled count=1 msg=Container image ""busybox:musl"" already present on machine"
0.4386,Event,ADDED,eval-sanitize-30-r1-122-sk6b4.18d4f7cf282288e7,reason=Created count=1 msg=Created container: task
0.4388,Event,ADDED,eval-sanitize-30-r1-122-sk6b4.18d4f7cf2e3677cc,reason=Started count=1 msg=Started container task
0.4389,Event,ADDED,eval-sanitize-30-r1-122.18d4f7cef562b760,reason=SuccessfulCreate count=1 msg=Created pod: eval-sanitize-30-r1-122-sk6b4
0.4392,Event,ADDED,eval-sanitize-30-r1-122.18d4f7d4a9d8066f,reason=Completed count=1 msg=Job completed
0.4396,Event,ADDED,eval-sanitize-30-r1-123-xqtvd.18d4f7cf2d267364,reason=Scheduled count=None msg=Successfully assigned compute/eval-sanitize-30-r1-123-xqtvd to kind-worker5
0.4398,Event,ADDED,eval-sanitize-30-r1-123-xqtvd.18d4f7cf4d1c3ff8,"reason=Pulled count=1 msg=Container image ""busybox:musl"" already present on machine"
0.4399,Event,ADDED,eval-sanitize-30-r1-123-xqtvd.18d4f7cf4e8bafb5,reason=Created count=1 msg=Created container: task
0.4406,Event,ADDED,eval-sanitize-30-r1-123-xqtvd.18d4f7cf583e86e9,reason=Started count=1 msg=Started container task
0.441,Event,ADDED,eval-sanitize-30-r1-123.18d4f7cf2b8c82c5,reason=SuccessfulCreate count=1 msg=Created pod: eval-sanitize-30-r1-123-xqtvd
0.4413,Event,ADDED,eval-sanitize-30-r1-123.18d4f7d4f36dcfdf,reason=Completed count=1 msg=Job completed
0.4417,Event,ADDED,eval-sanitize-30-r1-124-ssqdc.18d4f7cf6b839b30,reason=Scheduled count=None msg=Successfully assigned compute/eval-sanitize-30-r1-124-ssqdc to kind-worker5
0.442,Event,ADDED,eval-sanitize-30-r1-124-ssqdc.18d4f7cf8c52abe2,"reason=Pulled count=1 msg=Container image ""busybox:musl"" already present on machine"
0.4422,Event,ADDED,eval-sanitize-30-r1-124-ssqdc.18d4f7cf8e5d2d9c,reason=Created count=1 msg=Created container: task
0.4425,Event,ADDED,eval-sanitize-30-r1-124-ssqdc.18d4f7cf965ea561,reason=Started count=1 msg=Started container task
0.4428,Event,ADDED,eval-sanitize-30-r1-124.18d4f7cf6a68a91e,reason=SuccessfulCreate count=1 msg=Created pod: eval-sanitize-30-r1-124-ssqdc
0.443,Event,ADDED,eval-sanitize-30-r1-124.18d4f7d52e89141d,reason=Completed count=1 msg=Job completed
0.4432,Event,ADDED,eval-sanitize-30-r1-125-kxbpj.18d4f7cfa268dc20,reason=Scheduled count=None msg=Successfully assigned compute/eval-sanitize-30-r1-125-kxbpj to kind-worker3
0.4433,Event,ADDED,eval-sanitize-30-r1-125-kxbpj.18d4f7cfc1ea2f43,"reason=Pulled count=1 msg=Container image ""busybox:musl"" already present on machine"
0.4436,Event,ADDED,eval-sanitize-30-r1-125-kxbpj.18d4f7cfc351146e,reason=Created count=1 msg=Created container: task
0.4438,Event,ADDED,eval-sanitize-30-r1-125-kxbpj.18d4f7cfc8676c06,reason=Started count=1 msg=Started container task
0.444,Event,ADDED,eval-sanitize-30-r1-125.18d4f7cfa183ea67,reason=SuccessfulCreate count=1 msg=Created pod: eval-sanitize-30-r1-125-kxbpj
0.4442,Event,ADDED,eval-sanitize-30-r1-125.18d4f7d561f7675d,reason=Completed count=1 msg=Job completed
0.4444,Event,ADDED,eval-sanitize-30-r1-126-kll2b.18d4f7cfde1b01ab,reason=Scheduled count=None msg=Successfully assigned compute/eval-sanitize-30-r1-126-kll2b to kind-worker3
0.4446,Event,ADDED,eval-sanitize-30-r1-126-kll2b.18d4f7d00e581fc6,"reason=Pulled count=1 msg=Container image ""busybox:musl"" already present on machine"
0.4448,Event,ADDED,eval-sanitize-30-r1-126-kll2b.18d4f7d00fa0f464,reason=Created count=1 msg=Created container: task
0.445,Event,ADDED,eval-sanitize-30-r1-126-kll2b.18d4f7d01af3b506,reason=Started count=1 msg=Started container task
0.4452,Event,ADDED,eval-sanitize-30-r1-126.18d4f7cfdd27507c,reason=SuccessfulCreate count=1 msg=Created pod: eval-sanitize-30-r1-126-kll2b
0.4454,Event,ADDED,eval-sanitize-30-r1-126.18d4f7d5a1ce9031,reason=Completed count=1 msg=Job completed
0.4457,Event,ADDED,eval-sanitize-30-r1-127-8vq9b.18d4f7d01d631480,"reason=FailedScheduling count=None msg=0/6 nodes are available: 1 c_wall violated: 2 conflicting context pair(s) with node memory, 5 node(s) had untolerated taint(s). no new claims to deallocate, preemption: 0/6 nodes are available: 1 No preemption victims found for incoming pod, 5 Preemption is not helpful for scheduling."
0.4459,Event,ADDED,eval-sanitize-30-r1-127-8vq9b.18d4f7d01e390b19,"reason=FailedScheduling count=None msg=0/6 nodes are available: 1 c_wall violated: 2 conflicting context pair(s) with node memory, 5 node(s) had untolerated taint(s). no new claims to deallocate, preemption: 0/6 nodes are available: 1 No preemption victims found for incoming pod, 5 Preemption is not helpful for scheduling."
0.4461,Event,ADDED,eval-sanitize-30-r1-127-8vq9b.18d4f7d6b2767859,reason=Scheduled count=None msg=Successfully assigned compute/eval-sanitize-30-r1-127-8vq9b to kind-worker4
0.4463,Event,ADDED,eval-sanitize-30-r1-127-8vq9b.18d4f7d6d481621c,"reason=Pulled count=1 msg=Container image ""busybox:musl"" already present on machine"
0.4468,Event,ADDED,eval-sanitize-30-r1-127-8vq9b.18d4f7d6d8f37032,reason=Created count=1 msg=Created container: task
0.447,Event,ADDED,eval-sanitize-30-r1-127-8vq9b.18d4f7d6e46ed9b7,reason=Started count=1 msg=Started container task
0.4472,Event,ADDED,eval-sanitize-30-r1-127.18d4f7d01d123d9c,reason=SuccessfulCreate count=1 msg=Created pod: eval-sanitize-30-r1-127-8vq9b
0.4479,Event,ADDED,eval-sanitize-30-r1-127.18d4f7dd4943248d,reason=Completed count=1 msg=Job completed
0.4482,Event,ADDED,eval-sanitize-30-r1-128-g4mr4.18d4f7d0560c6ca4,"reason=FailedScheduling count=None msg=0/6 nodes are available: 1 c_wall violated: 2 conflicting context pair(s) with node memory, 5 node(s) had untolerated taint(s). no new claims to deallocate, preemption: 0/6 nodes are available: 1 No preemption victims found for incoming pod, 5 Preemption is not helpful for scheduling."
0.4485,Event,ADDED,eval-sanitize-30-r1-128-g4mr4.18d4f7d056bf7bca,"reason=FailedScheduling count=None msg=0/6 nodes are available: 1 c_wall violated: 2 conflicting context pair(s) with node memory, 5 node(s) had untolerated taint(s). no new claims to deallocate, preemption: 0/6 nodes are available: 1 No preemption victims found for incoming pod, 5 Preemption is not helpful for scheduling."
0.4488,Event,ADDED,eval-sanitize-30-r1-128-g4mr4.18d4f7d674d98531,reason=Scheduled count=None msg=Successfully assigned compute/eval-sanitize-30-r1-128-g4mr4 to kind-worker
0.4491,Event,ADDED,eval-sanitize-30-r1-128-g4mr4.18d4f7d68ee03439,"reason=Pulled count=1 msg=Container image ""busybox:musl"" already present on machine"
0.4492,Event,ADDED,eval-sanitize-30-r1-128-g4mr4.18d4f7d690be6261,reason=Created count=1 msg=Created container: task
0.4495,Event,ADDED,eval-sanitize-30-r1-128-g4mr4.18d4f7d6960e3d13,reason=Started count=1 msg=Started container task
0.4499,Event,ADDED,eval-sanitize-30-r1-128.18d4f7d055a3403c,reason=SuccessfulCreate count=1 msg=Created pod: eval-sanitize-30-r1-128-g4mr4
0.4502,Event,ADDED,eval-sanitize-30-r1-128.18d4f7dcf7cf0f51,reason=Completed count=1 msg=Job completed
0.4505,Event,ADDED,eval-sanitize-30-r1-129-pz5vs.18d4f7d094e1752f,"reason=FailedScheduling count=None msg=0/6 nodes are available: 1 c_wall violated: 2 conflicting context pair(s) with node memory, 5 node(s) had untolerated taint(s). no new claims to deallocate, preemption: 0/6 nodes are available: 1 No preemption victims found for incoming pod, 5 Preemption is not helpful for scheduling."
0.4508,Event,ADDED,eval-sanitize-30-r1-129-pz5vs.18d4f7d095a67522,"reason=FailedScheduling count=None msg=0/6 nodes are available: 1 c_wall violated: 2 conflicting context pair(s) with node memory, 5 node(s) had untolerated taint(s). no new claims to deallocate, preemption: 0/6 nodes are available: 1 No preemption victims found for incoming pod, 5 Preemption is not helpful for scheduling."
0.4511,Event,ADDED,eval-sanitize-30-r1-129-pz5vs.18d4f7d62e03a7fe,reason=Scheduled count=None msg=Successfully assigned compute/eval-sanitize-30-r1-129-pz5vs to kind-worker
0.4513,Event,ADDED,eval-sanitize-30-r1-129-pz5vs.18d4f7d64e0d1b67,"reason=Pulled count=1 msg=Container image ""busybox:musl"" already present on machine"
0.4514,Event,ADDED,eval-sanitize-30-r1-129-pz5vs.18d4f7d64f8d7b0e,reason=Created count=1 msg=Created container: task
0.4517,Event,ADDED,eval-sanitize-30-r1-129-pz5vs.18d4f7d656119221,reason=Started count=1 msg=Started container task
0.4519,Event,ADDED,eval-sanitize-30-r1-129.18d4f7d0948e6d4b,reason=SuccessfulCreate count=1 msg=Created pod: eval-sanitize-30-r1-129-pz5vs
0.4521,Event,ADDED,eval-sanitize-30-r1-129.18d4f7dbdc923d03,reason=Completed count=1 msg=Job completed
0.4524,Event,ADDED,eval-sanitize-30-r1-130-48f5x.18d4f7d0d2c33925,"reason=FailedScheduling count=None msg=0/6 nodes are available: 1 c_wall violated: 1 conflicting context pair(s) with node memory, 5 node(s) had untolerated taint(s). no new claims to deallocate, preemption: 0/6 nodes are available: 1 No preemption victims found for incoming pod, 5 Preemption is not helpful for scheduling."
0.453,Event,ADDED,eval-sanitize-30-r1-130-48f5x.18d4f7d0d3b202f4,"reason=FailedScheduling count=None msg=0/6 nodes are available: 1 c_wall violated: 1 conflicting context pair(s) with node memory, 5 node(s) had untolerated taint(s). no new claims to deallocate, preemption: 0/6 nodes are available: 1 No preemption victims found for incoming pod, 5 Preemption is not helpful for scheduling."
0.4533,Event,ADDED,eval-sanitize-30-r1-130-48f5x.18d4f7d6ae6cd93d,reason=Scheduled count=None msg=Successfully assigned compute/eval-sanitize-30-r1-130-48f5x to kind-worker4
0.4536,Event,ADDED,eval-sanitize-30-r1-130-48f5x.18d4f7d6d3f8df21,"reason=Pulled count=1 msg=Container image ""busybox:musl"" already present on machine"
0.4539,Event,ADDED,eval-sanitize-30-r1-130-48f5x.18d4f7d6d7eb6645,reason=Created count=1 msg=Created container: task
0.4541,Event,ADDED,eval-sanitize-30-r1-130-48f5x.18d4f7d6e46ed98a,reason=Started count=1 msg=Started container task
0.4543,Event,ADDED,eval-sanitize-30-r1-130.18d4f7d0d25e17cc,reason=SuccessfulCreate count=1 msg=Created pod: eval-sanitize-30-r1-130-48f5x
0.4545,Event,ADDED,eval-sanitize-30-r1-130.18d4f7dd31c0a6bf,reason=Completed count=1 msg=Job completed
0.4547,Event,ADDED,eval-sanitize-30-r1-131-429ph.18d4f7d10c7f00a7,"reason=FailedScheduling count=None msg=0/6 nodes are available: 1 c_wall violated: 2 conflicting context pair(s) with node memory, 5 node(s) had untolerated taint(s). no new claims to deallocate, preemption: 0/6 nodes are available: 1 No preemption victims found for incoming pod, 5 Preemption is not helpful for scheduling."
0.4549,Event,ADDED,eval-sanitize-30-r1-131-429ph.18d4f7d10d45822c,"reason=FailedScheduling count=None msg=0/6 nodes are available: 1 c_wall violated: 2 conflicting context pair(s) with node memory, 5 node(s) had untolerated taint(s). no new claims to deallocate, preemption: 0/6 nodes are available: 1 No preemption victims found for incoming pod, 5 Preemption is not helpful for scheduling."
0.4551,Event,ADDED,eval-sanitize-30-r1-131-429ph.18d4f7d691e6431f,"reason=FailedScheduling count=None msg=0/6 nodes are available: 2 c_wall violated: 2 conflicting context pair(s) with node memory, 4 node(s) had untolerated taint(s). no new claims to deallocate, preemption: 0/6 nodes are available: 2 No preemption victims found for incoming pod, 4 Preemption is not helpful for scheduling."
0.4554,Event,ADDED,eval-sanitize-30-r1-131-429ph.18d4f7d6bcafb1a1,"reason=FailedScheduling count=None msg=0/6 nodes are available: 2 c_wall violated: 2 conflicting context pair(s) with node memory, 4 node(s) had untolerated taint(s). no new claims to deallocate, preemption: 0/6 nodes are available: 2 No preemption victims found for incoming pod, 4 Preemption is not helpful for scheduling."
0.4555,Event,ADDED,eval-sanitize-30-r1-131-429ph.18d4f7d6fbd80ece,reason=Scheduled count=None msg=Successfully assigned compute/eval-sanitize-30-r1-131-429ph to kind-worker5
0.4557,Event,ADDED,eval-sanitize-30-r1-131-429ph.18d4f7d7209b5123,"reason=Pulled count=1 msg=Container image ""busybox:musl"" already present on machine"
0.4559,Event,ADDED,eval-sanitize-30-r1-131-429ph.18d4f7d722afb618,reason=Created count=1 msg=Created container: task
0.4561,Event,ADDED,eval-sanitize-30-r1-131-429ph.18d4f7d7294d7508,reason=Started count=1 msg=Started container task
0.4563,Event,ADDED,eval-sanitize-30-r1-131.18d4f7d10c25c9a5,reason=SuccessfulCreate count=1 msg=Created pod: eval-sanitize-30-r1-131-429ph
0.4565,Event,ADDED,eval-sanitize-30-r1-131.18d4f7ddaf8427a9,reason=Completed count=1 msg=Job completed
0.4568,Event,ADDED,eval-sanitize-30-r1-132-d4rwp.18d4f7d148ea2162,"reason=FailedScheduling count=None msg=0/6 nodes are available: 1 c_wall violated: 2 conflicting context pair(s) with node memory, 5 node(s) had untolerated taint(s). no new claims to deallocate, preemption: 0/6 nodes are available: 1 No preemption victims found for incoming pod, 5 Preemption is not helpful for scheduling."
0.457,Event,ADDED,eval-sanitize-30-r1-132-d4rwp.18d4f7d1499fc218,"reason=FailedScheduling count=None msg=0/6 nodes are available: 1 c_wall violated: 2 conflicting context pair(s) with node memory, 5 node(s) had untolerated taint(s). no new claims to deallocate, preemption: 0/6 nodes are available: 1 No preemption victims found for incoming pod, 5 Preemption is not helpful for scheduling."
0.4571,Event,ADDED,eval-sanitize-30-r1-132-d4rwp.18d4f7d693cbb237,reason=Scheduled count=None msg=Successfully assigned compute/eval-sanitize-30-r1-132-d4rwp to kind-worker4
0.4573,Event,ADDED,eval-sanitize-30-r1-132-d4rwp.18d4f7d6bdb6b029,"reason=Pulled count=1 msg=Container image ""busybox:musl"" already present on machine"
0.4576,Event,ADDED,eval-sanitize-30-r1-132-d4rwp.18d4f7d6bf4852fe,reason=Created count=1 msg=Created container: task
0.4579,Event,ADDED,eval-sanitize-30-r1-132-d4rwp.18d4f7d6c44cdf3c,reason=Started count=1 msg=Started container task
0.4583,Event,ADDED,eval-sanitize-30-r1-132.18d4f7d14888287b,reason=SuccessfulCreate count=1 msg=Created pod: eval-sanitize-30-r1-132-d4rwp
0.4586,Event,ADDED,eval-sanitize-30-r1-132.18d4f7dd6d6ed33f,reason=Completed count=1 msg=Job completed
0.4588,Event,ADDED,eval-sanitize-30-r1-133-92v5f.18d4f7d17ec744df,"reason=FailedScheduling count=None msg=0/6 nodes are available: 1 c_wall violated: 1 conflicting context pair(s) with node memory, 5 node(s) had untolerated taint(s). no new claims to deallocate, preemption: 0/6 nodes are available: 1 No preemption victims found for incoming pod, 5 Preemption is not helpful for scheduling."
0.4591,Event,ADDED,eval-sanitize-30-r1-133-92v5f.18d4f7d17f89c993,"reason=FailedScheduling count=None msg=0/6 nodes are available: 1 c_wall violated: 1 conflicting context pair(s) with node memory, 5 node(s) had untolerated taint(s). no new claims to deallocate, preemption: 0/6 nodes are available: 1 No preemption victims found for incoming pod, 5 Preemption is not helpful for scheduling."
0.4593,Event,ADDED,eval-sanitize-30-r1-133-92v5f.18d4f7d69939f876,reason=Scheduled count=None msg=Successfully assigned compute/eval-sanitize-30-r1-133-92v5f to kind-worker4
0.4596,Event,ADDED,eval-sanitize-30-r1-133-92v5f.18d4f7d6bed10ac6,"reason=Pulled count=1 msg=Container image ""busybox:musl"" already present on machine"
0.4599,Event,ADDED,eval-sanitize-30-r1-133-92v5f.18d4f7d6c0b97ab5,reason=Created count=1 msg=Created container: task
0.4603,Event,ADDED,eval-sanitize-30-r1-133-92v5f.18d4f7d6c57c073e,reason=Started count=1 msg=Started container task
0.4606,Event,ADDED,eval-sanitize-30-r1-133.18d4f7d17e73dbfc,reason=SuccessfulCreate count=1 msg=Created pod: eval-sanitize-30-r1-133-92v5f
0.4609,Event,ADDED,eval-sanitize-30-r1-133.18d4f7ddba9f3bde,reason=Completed count=1 msg=Job completed
0.4612,Event,ADDED,eval-sanitize-30-r1-134-64jzf.18d4f7d1bb8cd7f2,"reason=FailedScheduling count=None msg=0/6 nodes are available: 1 c_wall violated: 2 conflicting context pair(s) with node memory, 5 node(s) had untolerated taint(s). no new claims to deallocate, preemption: 0/6 nodes are available: 1 No preemption victims found for incoming pod, 5 Preemption is not helpful for scheduling."
0.4615,Event,ADDED,eval-sanitize-30-r1-134-64jzf.18d4f7d1bc4e656f,"reason=FailedScheduling count=None msg=0/6 nodes are available: 1 c_wall violated: 2 conflicting context pair(s) with node memory, 5 node(s) had untolerated taint(s). no new claims to deallocate, preemption: 0/6 nodes are available: 1 No preemption victims found for incoming pod, 5 Preemption is not helpful for scheduling."
0.4617,Event,ADDED,eval-sanitize-30-r1-134-64jzf.18d4f7d6a5598396,"reason=FailedScheduling count=None msg=0/6 nodes are available: 2 c_wall violated: 2 conflicting context pair(s) with node memory, 4 node(s) had untolerated taint(s). no new claims to deallocate, preemption: 0/6 nodes are available: 2 No preemption victims found for incoming pod, 4 Preemption is not helpful for scheduling."
0.4619,Event,ADDED,eval-sanitize-30-r1-134-64jzf.18d4f7d70b42103f,reason=Scheduled count=None msg=Successfully assigned compute/eval-sanitize-30-r1-134-64jzf to kind-worker2
0.4622,Event,ADDED,eval-sanitize-30-r1-134-64jzf.18d4f7d72a57f57b,"reason=Pulled count=1 msg=Container image ""busybox:musl"" already present on machine"
0.4624,Event,ADDED,eval-sanitize-30-r1-134-64jzf.18d4f7d72be90057,reason=Created count=1 msg=Created container: task
0.4626,Event,ADDED,eval-sanitize-30-r1-134-64jzf.18d4f7d7308d3466,reason=Started count=1 msg=Started container task
0.4629,Event,ADDED,eval-sanitize-30-r1-134.18d4f7d1bb3f5e33,reason=SuccessfulCreate count=1 msg=Created pod: eval-sanitize-30-r1-134-64jzf
0.4631,Event,ADDED,eval-sanitize-30-r1-134.18d4f7ddd597ec71,reason=Completed count=1 msg=Job completed
0.4633,Event,ADDED,eval-sanitize-30-r1-135-vljhq.18d4f7d1f5547819,"reason=FailedScheduling count=None msg=0/6 nodes are available: 1 c_wall violated: 1 conflicting context pair(s) with node memory, 5 node(s) had untolerated taint(s). no new claims to deallocate, preemption: 0/6 nodes are available: 1 No preemption victims found for incoming pod, 5 Preemption is not helpful for scheduling."
0.4637,Event,ADDED,eval-sanitize-30-r1-135-vljhq.18d4f7d1f5fc7167,"reason=FailedScheduling count=None msg=0/6 nodes are available: 1 c_wall violated: 1 conflicting context pair(s) with node memory, 5 node(s) had untolerated taint(s). no new claims to deallocate, preemption: 0/6 nodes are available: 1 No preemption victims found for incoming pod, 5 Preemption is not helpful for scheduling."
0.4641,Event,ADDED,eval-sanitize-30-r1-135-vljhq.18d4f7d6aecb98aa,reason=Scheduled count=None msg=Successfully assigned compute/eval-sanitize-30-r1-135-vljhq to kind-worker4
0.4643,Event,ADDED,eval-sanitize-30-r1-135-vljhq.18d4f7d6d41d55e9,"reason=Pulled count=1 msg=Container image ""busybox:musl"" already present on machine"
0.4645,Event,ADDED,eval-sanitize-30-r1-135-vljhq.18d4f7d6d829c0d4,reason=Created count=1 msg=Created container: task
0.4649,Event,ADDED,eval-sanitize-30-r1-135-vljhq.18d4f7d6e46f4ff4,reason=Started count=1 msg=Started container task
0.4651,Event,ADDED,eval-sanitize-30-r1-135.18d4f7d1f501fbed,reason=SuccessfulCreate count=1 msg=Created pod: eval-sanitize-30-r1-135-vljhq
0.4652,Event,ADDED,eval-sanitize-30-r1-135.18d4f7dd2e8055b3,reason=Completed count=1 msg=Job completed
0.4654,Event,ADDED,eval-sanitize-30-r1-136-vhtsc.18d4f7d238f672ed,reason=Scheduled count=None msg=Successfully assigned compute/eval-sanitize-30-r1-136-vhtsc to kind-worker3
0.4658,Event,ADDED,eval-sanitize-30-r1-136-vhtsc.18d4f7d2601f4155,"reason=Pulled count=1 msg=Container image ""busybox:musl"" already present on machine"
0.4661,Event,ADDED,eval-sanitize-30-r1-136-vhtsc.18d4f7d261fee216,reason=Created count=1 msg=Created container: task
0.4664,Event,ADDED,eval-sanitize-30-r1-136-vhtsc.18d4f7d268dedb82,reason=Started count=1 msg=Started container task
0.4667,Event,ADDED,eval-sanitize-30-r1-136.18d4f7d2383dd84a,reason=SuccessfulCreate count=1 msg=Created pod: eval-sanitize-30-r1-136-vhtsc
0.467,Event,ADDED,eval-sanitize-30-r1-136.18d4f7d7f23e5aee,reason=Completed count=1 msg=Job completed
0.4672,Event,ADDED,eval-sanitize-30-r1-137-sgc2s.18d4f7d26e46e1f6,reason=Scheduled count=None msg=Successfully assigned compute/eval-sanitize-30-r1-137-sgc2s to kind-worker3
0.4674,Event,ADDED,eval-sanitize-30-r1-137-sgc2s.18d4f7d28d2ad7f9,"reason=Pulled count=1 msg=Container image ""busybox:musl"" already present on machine"
0.4676,Event,ADDED,eval-sanitize-30-r1-137-sgc2s.18d4f7d28ec099b2,reason=Created count=1 msg=Created container: task
0.4678,Event,ADDED,eval-sanitize-30-r1-137-sgc2s.18d4f7d294280860,reason=Started count=1 msg=Started container task
0.468,Event,ADDED,eval-sanitize-30-r1-137.18d4f7d26c632d9b,reason=SuccessfulCreate count=1 msg=Created pod: eval-sanitize-30-r1-137-sgc2s
0.4682,Event,ADDED,eval-sanitize-30-r1-137.18d4f7d82f04e953,reason=Completed count=1 msg=Job completed
0.4688,Event,ADDED,eval-sanitize-30-r1-138-94lsw.18d4f7d2a88d0e90,"reason=FailedScheduling count=None msg=0/6 nodes are available: 1 c_wall violated: 2 conflicting context pair(s) with node memory, 5 node(s) had untolerated taint(s). no new claims to deallocate, preemption: 0/6 nodes are available: 1 No preemption victims found for incoming pod, 5 Preemption is not helpful for scheduling."
0.4694,Event,ADDED,eval-sanitize-30-r1-138-94lsw.18d4f7d2a93dd87f,"reason=FailedScheduling count=None msg=0/6 nodes are available: 1 c_wall violated: 2 conflicting context pair(s) with node memory, 5 node(s) had untolerated taint(s). no new claims to deallocate, preemption: 0/6 nodes are available: 1 No preemption victims found for incoming pod, 5 Preemption is not helpful for scheduling."
0.4698,Event,ADDED,eval-sanitize-30-r1-138-94lsw.18d4f7d699c7af56,reason=Scheduled count=None msg=Successfully assigned compute/eval-sanitize-30-r1-138-94lsw to kind-worker4
0.4702,Event,ADDED,eval-sanitize-30-r1-138-94lsw.18d4f7d6c9e97ef1,"reason=Pulled count=1 msg=Container image ""busybox:musl"" already present on machine"
0.4705,Event,ADDED,eval-sanitize-30-r1-138-94lsw.18d4f7d6cc5dfafb,reason=Created count=1 msg=Created container: task
0.4709,Event,ADDED,eval-sanitize-30-r1-138-94lsw.18d4f7d6d3d77914,reason=Started count=1 msg=Started container task
0.4711,Event,ADDED,eval-sanitize-30-r1-138.18d4f7d2a830449a,reason=SuccessfulCreate count=1 msg=Created pod: eval-sanitize-30-r1-138-94lsw
0.4717,Event,ADDED,eval-sanitize-30-r1-138.18d4f7dd79123213,reason=Completed count=1 msg=Job completed
0.472,Event,ADDED,eval-sanitize-30-r1-139-75tz8.18d4f7d2e75ebcd0,"reason=FailedScheduling count=None msg=0/6 nodes are available: 1 c_wall violated: 1 conflicting context pair(s) with node memory, 5 node(s) had untolerated taint(s). no new claims to deallocate, preemption: 0/6 nodes are available: 1 No preemption victims found for incoming pod, 5 Preemption is not helpful for scheduling."
0.4722,Event,ADDED,eval-sanitize-30-r1-139-75tz8.18d4f7d2e7f172e1,"reason=FailedScheduling count=None msg=0/6 nodes are available: 1 c_wall violated: 1 conflicting context pair(s) with node memory, 5 node(s) had untolerated taint(s). no new claims to deallocate, preemption: 0/6 nodes are available: 1 No preemption victims found for incoming pod, 5 Preemption is not helpful for scheduling."
0.4725,Event,ADDED,eval-sanitize-30-r1-139-75tz8.18d4f7d647715086,reason=Scheduled count=None msg=Successfully assigned compute/eval-sanitize-30-r1-139-75tz8 to kind-worker
0.4727,Event,ADDED,eval-sanitize-30-r1-139-75tz8.18d4f7d666723cdc,"reason=Pulled count=1 msg=Container image ""busybox:musl"" already present on machine"
0.473,Event,ADDED,eval-sanitize-30-r1-139-75tz8.18d4f7d667fc2dee,reason=Created count=1 msg=Created container: task
0.4732,Event,ADDED,eval-sanitize-30-r1-139-75tz8.18d4f7d66b5f669d,reason=Started count=1 msg=Started container task
0.4734,Event,ADDED,eval-sanitize-30-r1-139.18d4f7d2e70b5e55,reason=SuccessfulCreate count=1 msg=Created pod: eval-sanitize-30-r1-139-75tz8
0.4736,Event,ADDED,eval-sanitize-30-r1-139.18d4f7dba1c4b818,reason=Completed count=1 msg=Job completed
0.4739,Event,ADDED,eval-sanitize-30-r1-140-mqfhq.18d4f7d3249a63f7,"reason=FailedScheduling count=None msg=0/6 nodes are available: 1 c_wall violated: 1 conflicting context pair(s) with node memory, 5 node(s) had untolerated taint(s). no new claims to deallocate, preemption: 0/6 nodes are available: 1 No preemption victims found for incoming pod, 5 Preemption is not helpful for scheduling."
0.4741,Event,ADDED,eval-sanitize-30-r1-140-mqfhq.18d4f7d3254f2ce9,"reason=FailedScheduling count=None msg=0/6 nodes are available: 1 c_wall violated: 1 conflicting context pair(s) with node memory, 5 node(s) had untolerated taint(s). no new claims to deallocate, preemption: 0/6 nodes are available: 1 No preemption victims found for incoming pod, 5 Preemption is not helpful for scheduling."
0.4743,Event,ADDED,eval-sanitize-30-r1-140-mqfhq.18d4f7d69f8e0314,reason=Scheduled count=None msg=Successfully assigned compute/eval-sanitize-30-r1-140-mqfhq to kind-worker4
0.4745,Event,ADDED,eval-sanitize-30-r1-140-mqfhq.18d4f7d6bf35ffdf,"reason=Pulled count=1 msg=Container image ""busybox:musl"" already present on machine"
0.4749,Event,ADDED,eval-sanitize-30-r1-140-mqfhq.18d4f7d6c1a1ba36,reason=Created count=1 msg=Created container: task
0.4752,Event,ADDED,eval-sanitize-30-r1-140-mqfhq.18d4f7d6c579cc7f,reason=Started count=1 msg=Started container task
0.4757,Event,ADDED,eval-sanitize-30-r1-140.18d4f7d32443c668,reason=SuccessfulCreate count=1 msg=Created pod: eval-sanitize-30-r1-140-mqfhq
0.476,Event,ADDED,eval-sanitize-30-r1-140.18d4f7dd3481e7d9,reason=Completed count=1 msg=Job completed
0.4763,Event,ADDED,eval-sanitize-30-r1-141-fcnzv.18d4f7d35c497570,"reason=FailedScheduling count=None msg=0/6 nodes are available: 1 c_wall violated: 1 conflicting context pair(s) with node memory, 5 node(s) had untolerated taint(s). no new claims to deallocate, preemption: 0/6 nodes are available: 1 No preemption victims found for incoming pod, 5 Preemption is not helpful for scheduling."
0.4766,Event,ADDED,eval-sanitize-30-r1-141-fcnzv.18d4f7d35d06b104,"reason=FailedScheduling count=None msg=0/6 nodes are available: 1 c_wall violated: 1 conflicting context pair(s) with node memory, 5 node(s) had untolerated taint(s). no new claims to deallocate, preemption: 0/6 nodes are available: 1 No preemption victims found for incoming pod, 5 Preemption is not helpful for scheduling."
0.4767,Event,ADDED,eval-sanitize-30-r1-141-fcnzv.18d4f7d64ebd4d86,reason=Scheduled count=None msg=Successfully assigned compute/eval-sanitize-30-r1-141-fcnzv to kind-worker
0.4771,Event,ADDED,eval-sanitize-30-r1-141-fcnzv.18d4f7d66b01121f,"reason=Pulled count=1 msg=Container image ""busybox:musl"" already present on machine"
0.4773,Event,ADDED,eval-sanitize-30-r1-141-fcnzv.18d4f7d66c974e55,reason=Created count=1 msg=Created container: task
0.4776,Event,ADDED,eval-sanitize-30-r1-141-fcnzv.18d4f7d673426f67,reason=Started count=1 msg=Started container task
0.4778,Event,ADDED,eval-sanitize-30-r1-141.18d4f7d35be8b34d,reason=SuccessfulCreate count=1 msg=Created pod: eval-sanitize-30-r1-141-fcnzv
0.4782,Event,ADDED,eval-sanitize-30-r1-141.18d4f7dbdcb96ad0,reason=Completed count=1 msg=Job completed
0.4784,Event,ADDED,eval-sanitize-30-r1-142-fbn8g.18d4f7d397f4023e,"reason=FailedScheduling count=None msg=0/6 nodes are available: 1 c_wall violated: 1 conflicting context pair(s) with node memory, 5 node(s) had untolerated taint(s). no new claims to deallocate, preemption: 0/6 nodes are available: 1 No preemption victims found for incoming pod, 5 Preemption is not helpful for scheduling."
0.4787,Event,ADDED,eval-sanitize-30-r1-142-fbn8g.18d4f7d39900fd50,"reason=FailedScheduling count=None msg=0/6 nodes are available: 1 c_wall violated: 1 conflicting context pair(s) with node memory, 5 node(s) had untolerated taint(s). no new claims to deallocate, preemption: 0/6 nodes are available: 1 No preemption victims found for incoming pod, 5 Preemption is not helpful for scheduling."
0.479,Event,ADDED,eval-sanitize-30-r1-142-fbn8g.18d4f7d67b00e387,reason=Scheduled count=None msg=Successfully assigned compute/eval-sanitize-30-r1-142-fbn8g to kind-worker
0.4792,Event,ADDED,eval-sanitize-30-r1-142-fbn8g.18d4f7d696b107e3,"reason=Pulled count=1 msg=Container image ""busybox:musl"" already present on machine"
0.4795,Event,ADDED,eval-sanitize-30-r1-142-fbn8g.18d4f7d698265a19,reason=Created count=1 msg=Created container: task
0.4797,Event,ADDED,eval-sanitize-30-r1-142-fbn8g.18d4f7d69d61856a,reason=Started count=1 msg=Started container task
0.4802,Event,ADDED,eval-sanitize-30-r1-142.18d4f7d3979d750d,reason=SuccessfulCreate count=1 msg=Created pod: eval-sanitize-30-r1-142-fbn8g
0.4808,Event,ADDED,eval-sanitize-30-r1-142.18d4f7dbe3c1341e,reason=Completed count=1 msg=Job completed
0.4811,Event,ADDED,eval-sanitize-30-r1-143-hzk2w.18d4f7d3d791b49c,"reason=FailedScheduling count=None msg=0/6 nodes are available: 1 c_wall violated: 1 conflicting context pair(s) with node memory, 5 node(s) had untolerated taint(s). no new claims to deallocate, preemption: 0/6 nodes are available: 1 No preemption victims found for incoming pod, 5 Preemption is not helpful for scheduling."
0.4816,Event,ADDED,eval-sanitize-30-r1-143-hzk2w.18d4f7d3d86e4bcc,"reason=FailedScheduling count=None msg=0/6 nodes are available: 1 c_wall violated: 1 conflicting context pair(s) with node memory, 5 node(s) had untolerated taint(s). no new claims to deallocate, preemption: 0/6 nodes are available: 1 No preemption victims found for incoming pod, 5 Preemption is not helpful for scheduling."
0.4819,Event,ADDED,eval-sanitize-30-r1-143-hzk2w.18d4f7d68dd60711,reason=Scheduled count=None msg=Successfully assigned compute/eval-sanitize-30-r1-143-hzk2w to kind-worker4
0.4823,Event,ADDED,eval-sanitize-30-r1-143-hzk2w.18d4f7d6aecf323c,"reason=Pulled count=1 msg=Container image ""busybox:musl"" already present on machine"
0.4826,Event,ADDED,eval-sanitize-30-r1-143-hzk2w.18d4f7d6b6ec1601,reason=Created count=1 msg=Created container: task
0.4834,Event,ADDED,eval-sanitize-30-r1-143-hzk2w.18d4f7d6bcc1d5b7,reason=Started count=1 msg=Started container task
0.4836,Event,ADDED,eval-sanitize-30-r1-143.18d4f7d3d73db130,reason=SuccessfulCreate count=1 msg=Created pod: eval-sanitize-30-r1-143-hzk2w
0.484,Event,ADDED,eval-sanitize-30-r1-143.18d4f7dd8b9cfee5,reason=Completed count=1 msg=Job completed
0.4844,Event,ADDED,eval-sanitize-30-r1-144-wb4ff.18d4f7d40f1ad1fc,"reason=FailedScheduling count=None msg=0/6 nodes are available: 1 c_wall violated: 1 conflicting context pair(s) with node memory, 5 node(s) had untolerated taint(s). no new claims to deallocate, preemption: 0/6 nodes are available: 1 No preemption victims found for incoming pod, 5 Preemption is not helpful for scheduling."
0.4847,Event,ADDED,eval-sanitize-30-r1-144-wb4ff.18d4f7d40fb707d1,"reason=FailedScheduling count=None msg=0/6 nodes are available: 1 c_wall violated: 1 conflicting context pair(s) with node memory, 5 node(s) had untolerated taint(s). no new claims to deallocate, preemption: 0/6 nodes are available: 1 No preemption victims found for incoming pod, 5 Preemption is not helpful for scheduling."
0.485,Event,ADDED,eval-sanitize-30-r1-144-wb4ff.18d4f7d628414063,reason=Scheduled count=None msg=Successfully assigned compute/eval-sanitize-30-r1-144-wb4ff to kind-worker
0.4854,Event,ADDED,eval-sanitize-30-r1-144-wb4ff.18d4f7d645c431c2,"reason=Pulled count=1 msg=Container image ""busybox:musl"" already present on machine"
0.4857,Event,ADDED,eval-sanitize-30-r1-144-wb4ff.18d4f7d64755a599,reason=Created count=1 msg=Created container: task
0.486,Event,ADDED,eval-sanitize-30-r1-144-wb4ff.18d4f7d64e044757,reason=Started count=1 msg=Started container task
0.4864,Event,ADDED,eval-sanitize-30-r1-144.18d4f7d40ebe314c,reason=SuccessfulCreate count=1 msg=Created pod: eval-sanitize-30-r1-144-wb4ff
0.4868,Event,ADDED,eval-sanitize-30-r1-144.18d4f7dbdcbd0ed2,reason=Completed count=1 msg=Job completed
0.4872,Event,ADDED,eval-sanitize-30-r1-145-4bdst.18d4f7d44aaabfe4,"reason=FailedScheduling count=None msg=0/6 nodes are available: 1 c_wall violated: 1 conflicting context pair(s) with node memory, 5 node(s) had untolerated taint(s). no new claims to deallocate, preemption: 0/6 nodes are available: 1 No preemption victims found for incoming pod, 5 Preemption is not helpful for scheduling."
0.4875,Event,ADDED,eval-sanitize-30-r1-145-4bdst.18d4f7d44b4bc65d,"reason=FailedScheduling count=None msg=0/6 nodes are available: 1 c_wall violated: 1 conflicting context pair(s) with node memory, 5 node(s) had untolerated taint(s). no new claims to deallocate, preemption: 0/6 nodes are available: 1 No preemption victims found for incoming pod, 5 Preemption is not helpful for scheduling."
0.4879,Event,ADDED,eval-sanitize-30-r1-145-4bdst.18d4f7d683575674,reason=Scheduled count=None msg=Successfully assigned compute/eval-sanitize-30-r1-145-4bdst to kind-worker4
0.4882,Event,ADDED,eval-sanitize-30-r1-145-4bdst.18d4f7d69f41a071,"reason=Pulled count=1 msg=Container image ""busybox:musl"" already present on machine"
0.4885,Event,ADDED,eval-sanitize-30-r1-145-4bdst.18d4f7d6a185e140,reason=Created count=1 msg=Created container: task
0.4888,Event,ADDED,eval-sanitize-30-r1-145-4bdst.18d4f7d6a5de529c,reason=Started count=1 msg=Started container task
0.4891,Event,ADDED,eval-sanitize-30-r1-145.18d4f7d449927160,reason=SuccessfulCreate count=1 msg=Created pod: eval-sanitize-30-r1-145-4bdst
0.4893,Event,ADDED,eval-sanitize-30-r1-145.18d4f7dd04d87e27,reason=Completed count=1 msg=Job completed
0.4895,Event,ADDED,eval-sanitize-30-r1-146-zt7cn.18d4f7d48c5c9d79,"reason=FailedScheduling count=None msg=0/6 nodes are available: 1 c_wall violated: 1 conflicting context pair(s) with node memory, 5 node(s) had untolerated taint(s). no new claims to deallocate, preemption: 0/6 nodes are available: 1 No preemption victims found for incoming pod, 5 Preemption is not helpful for scheduling."
0.4899,Event,ADDED,eval-sanitize-30-r1-146-zt7cn.18d4f7d49862b30d,"reason=FailedScheduling count=None msg=0/6 nodes are available: 1 c_wall violated: 1 conflicting context pair(s) with node memory, 5 node(s) had untolerated taint(s). no new claims to deallocate, preemption: 0/6 nodes are available: 1 No preemption victims found for incoming pod, 5 Preemption is not helpful for scheduling."
0.4901,Event,ADDED,eval-sanitize-30-r1-146-zt7cn.18d4f7d6836ab566,reason=Scheduled count=None msg=Successfully assigned compute/eval-sanitize-30-r1-146-zt7cn to kind-worker4
0.4903,Event,ADDED,eval-sanitize-30-r1-146-zt7cn.18d4f7d69ed4fe25,"reason=Pulled count=1 msg=Container image ""busybox:musl"" already present on machine"
0.4905,Event,ADDED,eval-sanitize-30-r1-146-zt7cn.18d4f7d6a0c9c68d,reason=Created count=1 msg=Created container: task
0.4907,Event,ADDED,eval-sanitize-30-r1-146-zt7cn.18d4f7d6a52182f7,reason=Started count=1 msg=Started container task
0.4909,Event,ADDED,eval-sanitize-30-r1-146.18d4f7d4893d8472,reason=SuccessfulCreate count=1 msg=Created pod: eval-sanitize-30-r1-146-zt7cn
0.4911,Event,ADDED,eval-sanitize-30-r1-146.18d4f7dd20482c0c,reason=Completed count=1 msg=Job completed
0.4916,Event,ADDED,eval-sanitize-30-r1-147-k8846.18d4f7d4c1ff019d,"reason=FailedScheduling count=None msg=0/6 nodes are available: 1 c_wall violated: 1 conflicting context pair(s) with node memory, 5 node(s) had untolerated taint(s). no new claims to deallocate, preemption: 0/6 nodes are available: 1 No preemption victims found for incoming pod, 5 Preemption is not helpful for scheduling."
0.492,Event,ADDED,eval-sanitize-30-r1-147-k8846.18d4f7d4ce7f515e,"reason=FailedScheduling count=None msg=0/6 nodes are available: 1 c_wall violated: 1 conflicting context pair(s) with node memory, 5 node(s) had untolerated taint(s). no new claims to deallocate, preemption: 0/6 nodes are available: 1 No preemption victims found for incoming pod, 5 Preemption is not helpful for scheduling."
0.4923,Event,ADDED,eval-sanitize-30-r1-147-k8846.18d4f7d6873a64fd,reason=Scheduled count=None msg=Successfully assigned compute/eval-sanitize-30-r1-147-k8846 to kind-worker4
0.4927,Event,ADDED,eval-sanitize-30-r1-147-k8846.18d4f7d6a1a9bee1,"reason=Pulled count=1 msg=Container image ""busybox:musl"" already present on machine"
0.4934,Event,ADDED,eval-sanitize-30-r1-147-k8846.18d4f7d6a2fe1037,reason=Created count=1 msg=Created container: task
0.4936,Event,ADDED,eval-sanitize-30-r1-147-k8846.18d4f7d6a6603d63,reason=Started count=1 msg=Started container task
0.4938,Event,ADDED,eval-sanitize-30-r1-147.18d4f7d4c08c38dc,reason=SuccessfulCreate count=1 msg=Created pod: eval-sanitize-30-r1-147-k8846
0.494,Event,ADDED,eval-sanitize-30-r1-147.18d4f7dd182a43c5,reason=Completed count=1 msg=Job completed
0.4942,Event,ADDED,eval-sanitize-30-r1-148-v84p7.18d4f7d503a68f4d,reason=Scheduled count=None msg=Successfully assigned compute/eval-sanitize-30-r1-148-v84p7 to kind-worker3
0.4944,Event,ADDED,eval-sanitize-30-r1-148-v84p7.18d4f7d5237db85e,"reason=Pulled count=1 msg=Container image ""busybox:musl"" already present on machine"
0.4946,Event,ADDED,eval-sanitize-30-r1-148-v84p7.18d4f7d525516b72,reason=Created count=1 msg=Created container: task
0.4948,Event,ADDED,eval-sanitize-30-r1-148-v84p7.18d4f7d52cfdf690,reason=Started count=1 msg=Started container task
0.495,Event,ADDED,eval-sanitize-30-r1-148.18d4f7d502c3081d,reason=SuccessfulCreate count=1 msg=Created pod: eval-sanitize-30-r1-148-v84p7
0.4951,Event,ADDED,eval-sanitize-30-r1-148.18d4f7dabdba23e9,reason=Completed count=1 msg=Job completed
0.4954,Event,ADDED,eval-sanitize-30-r1-149-6rvq5.18d4f7d53f3b2fb6,"reason=FailedScheduling count=None msg=0/6 nodes are available: 1 c_wall violated: 1 conflicting context pair(s) with node memory, 5 node(s) had untolerated taint(s). no new claims to deallocate, preemption: 0/6 nodes are available: 1 No preemption victims found for incoming pod, 5 Preemption is not helpful for scheduling."
0.4956,Event,ADDED,eval-sanitize-30-r1-149-6rvq5.18d4f7d540597d62,"reason=FailedScheduling count=None msg=0/6 nodes are available: 1 c_wall violated: 1 conflicting context pair(s) with node memory, 5 node(s) had untolerated taint(s). no new claims to deallocate, preemption: 0/6 nodes are available: 1 No preemption victims found for incoming pod, 5 Preemption is not helpful for scheduling."
0.4957,Event,ADDED,eval-sanitize-30-r1-149-6rvq5.18d4f7d6b27873b9,reason=Scheduled count=None msg=Successfully assigned compute/eval-sanitize-30-r1-149-6rvq5 to kind-worker4
0.496,Event,ADDED,eval-sanitize-30-r1-149-6rvq5.18d4f7d6d442579d,"reason=Pulled count=1 msg=Container image ""busybox:musl"" already present on machine"
0.4964,Event,ADDED,eval-sanitize-30-r1-149-6rvq5.18d4f7d6d8ba600b,reason=Created count=1 msg=Created container: task
0.4969,Event,ADDED,eval-sanitize-30-r1-149-6rvq5.18d4f7d6e46f3f82,reason=Started count=1 msg=Started container task
0.4975,Event,ADDED,eval-sanitize-30-r1-149.18d4f7d53d5fa965,reason=SuccessfulCreate count=1 msg=Created pod: eval-sanitize-30-r1-149-6rvq5
0.4978,Event,ADDED,eval-sanitize-30-r1-149.18d4f7dd850c8c7f,reason=Completed count=1 msg=Job completed
0.4985,Event,ADDED,eval-sanitize-30-r1-150-b729n.18d4f7d5741c054d,"reason=FailedScheduling count=None msg=0/6 nodes are available: 1 c_wall violated: 2 conflicting context pair(s) with node memory, 5 node(s) had untolerated taint(s). no new claims to deallocate, preemption: 0/6 nodes are available: 1 No preemption victims found for incoming pod, 5 Preemption is not helpful for scheduling."
0.4989,Event,ADDED,eval-sanitize-30-r1-150-b729n.18d4f7d574b3b4a0,"reason=FailedScheduling count=None msg=0/6 nodes are available: 1 c_wall violated: 2 conflicting context pair(s) with node memory, 5 node(s) had untolerated taint(s). no new claims to deallocate, preemption: 0/6 nodes are available: 1 No preemption victims found for incoming pod, 5 Preemption is not helpful for scheduling."
0.4991,Event,ADDED,eval-sanitize-30-r1-150-b729n.18d4f7d663624441,reason=Scheduled count=None msg=Successfully assigned compute/eval-sanitize-30-r1-150-b729n to kind-worker
0.4996,Event,ADDED,eval-sanitize-30-r1-150-b729n.18d4f7d6834da0bb,"reason=Pulled count=1 msg=Container image ""busybox:musl"" already present on machine"
0.4998,Event,ADDED,eval-sanitize-30-r1-150-b729n.18d4f7d6854cf075,reason=Created count=1 msg=Created container: task
0.5001,Event,ADDED,eval-sanitize-30-r1-150-b729n.18d4f7d689e083f7,reason=Started count=1 msg=Started container task
0.5004,Event,ADDED,eval-sanitize-30-r1-150.18d4f7d573a738a8,reason=SuccessfulCreate count=1 msg=Created pod: eval-sanitize-30-r1-150-b729n
0.5007,Event,ADDED,eval-sanitize-30-r1-150.18d4f7dbdd8a7691,reason=Completed count=1 msg=Job completed
0.5009,Event,ADDED,eval-sanitize-30-r1-151-v5wtd.18d4f7d5b285b6c5,"reason=FailedScheduling count=None msg=0/6 nodes are available: 1 c_wall violated: 2 conflicting context pair(s) with node memory, 5 node(s) had untolerated taint(s). no new claims to deallocate, preemption: 0/6 nodes are available: 1 No preemption victims found for incoming pod, 5 Preemption is not helpful for scheduling."
0.5011,Event,ADDED,eval-sanitize-30-r1-151-v5wtd.18d4f7d5b3470dc2,"reason=FailedScheduling count=None msg=0/6 nodes are available: 1 c_wall violated: 2 conflicting context pair(s) with node memory, 5 node(s) had untolerated taint(s). no new claims to deallocate, preemption: 0/6 nodes are available: 1 No preemption victims found for incoming pod, 5 Preemption is not helpful for scheduling."
0.5016,Event,ADDED,eval-sanitize-30-r1-151-v5wtd.18d4f7d6b5d18690,"reason=FailedScheduling count=None msg=0/6 nodes are available: 2 c_wall violated: 2 conflicting context pair(s) with node memory, 4 node(s) had untolerated taint(s). no new claims to deallocate, preemption: 0/6 nodes are available: 2 No preemption victims found for incoming pod, 4 Preemption is not helpful for scheduling."
0.5019,Event,ADDED,eval-sanitize-30-r1-151-v5wtd.18d4f7d6fb9657ca,reason=Scheduled count=None msg=Successfully assigned compute/eval-sanitize-30-r1-151-v5wtd to kind-worker5
0.5022,Event,ADDED,eval-sanitize-30-r1-151-v5wtd.18d4f7d720c0001e,"reason=Pulled count=1 msg=Container image ""busybox:musl"" already present on machine"
0.5025,Event,ADDED,eval-sanitize-30-r1-151-v5wtd.18d4f7d723d50ea5,reason=Created count=1 msg=Created container: task
0.5028,Event,ADDED,eval-sanitize-30-r1-151-v5wtd.18d4f7d729d988fb,reason=Started count=1 msg=Started container task
0.5032,Event,ADDED,eval-sanitize-30-r1-151.18d4f7d5b2313bf0,reason=SuccessfulCreate count=1 msg=Created pod: eval-sanitize-30-r1-151-v5wtd
0.5036,Event,ADDED,eval-sanitize-30-r1-151.18d4f7dd99d16e2d,reason=Completed count=1 msg=Job completed
0.5043,Event,ADDED,eval-sanitize-30-r1-152-6fc6k.18d4f7d5ec91f4eb,"reason=FailedScheduling count=None msg=0/6 nodes are available: 1 c_wall violated: 2 conflicting context pair(s) with node memory, 5 node(s) had untolerated taint(s). no new claims to deallocate, preemption: 0/6 nodes are available: 1 No preemption victims found for incoming pod, 5 Preemption is not helpful for scheduling."
0.5047,Event,ADDED,eval-sanitize-30-r1-152-6fc6k.18d4f7d5ed3a5f79,"reason=FailedScheduling count=None msg=0/6 nodes are available: 1 c_wall violated: 2 conflicting context pair(s) with node memory, 5 node(s) had untolerated taint(s). no new claims to deallocate, preemption: 0/6 nodes are available: 1 No preemption victims found for incoming pod, 5 Preemption is not helpful for scheduling."
0.505,Event,ADDED,eval-sanitize-30-r1-152-6fc6k.18d4f7d67339a59e,reason=Scheduled count=None msg=Successfully assigned compute/eval-sanitize-30-r1-152-6fc6k to kind-worker4
0.5054,Event,ADDED,eval-sanitize-30-r1-152-6fc6k.18d4f7d68d2e703d,"reason=Pulled count=1 msg=Container image ""busybox:musl"" already present on machine"
0.5057,Event,ADDED,eval-sanitize-30-r1-152-6fc6k.18d4f7d68f797894,reason=Created count=1 msg=Created container: task
0.5059,Event,ADDED,eval-sanitize-30-r1-152-6fc6k.18d4f7d695238a0a,reason=Started count=1 msg=Started container task
0.5061,Event,ADDED,eval-sanitize-30-r1-152.18d4f7d5ec42bdbb,reason=SuccessfulCreate count=1 msg=Created pod: eval-sanitize-30-r1-152-6fc6k
0.5064,Event,ADDED,eval-sanitize-30-r1-152.18d4f7dbdd8a09eb,reason=Completed count=1 msg=Job completed
0.5068,Event,ADDED,eval-sanitize-30-r1-153-fp7d2.18d4f7d668312cac,"reason=FailedScheduling count=None msg=0/6 nodes are available: 2 c_wall violated: 2 conflicting context pair(s) with node memory, 4 node(s) had untolerated taint(s). no new claims to deallocate, preemption: 0/6 nodes are available: 2 No preemption victims found for incoming pod, 4 Preemption is not helpful for scheduling."
0.5071,Event,ADDED,eval-sanitize-30-r1-153-fp7d2.18d4f7d6b822cebe,reason=Scheduled count=None msg=Successfully assigned compute/eval-sanitize-30-r1-153-fp7d2 to kind-worker4
0.5076,Event,ADDED,eval-sanitize-30-r1-153-fp7d2.18d4f7d6e476ce6c,"reason=Pulled count=1 msg=Container image ""busybox:musl"" already present on machine"
0.5079,Event,ADDED,eval-sanitize-30-r1-153-fp7d2.18d4f7d6e5cd20b1,reason=Created count=1 msg=Created container: task
0.5084,Event,ADDED,eval-sanitize-30-r1-153-fp7d2.18d4f7d6ee0dcf7d,reason=Started count=1 msg=Started container task
0.5089,Event,ADDED,eval-sanitize-30-r1-153.18d4f7d62841cf86,reason=SuccessfulCreate count=1 msg=Created pod: eval-sanitize-30-r1-153-fp7d2
0.5092,Event,ADDED,eval-sanitize-30-r1-153.18d4f7dd9ce05564,reason=Completed count=1 msg=Job completed
0.51,Event,ADDED,eval-sanitize-30-r1-154-sp6gl.18d4f7d669bea1f3,reason=Scheduled count=None msg=Successfully assigned compute/eval-sanitize-30-r1-154-sp6gl to kind-worker4
0.5104,Event,ADDED,eval-sanitize-30-r1-154-sp6gl.18d4f7d689c65bb2,"reason=Pulled count=1 msg=Container image ""busybox:musl"" already present on machine"
0.5107,Event,ADDED,eval-sanitize-30-r1-154-sp6gl.18d4f7d68b5ab2ef,reason=Created count=1 msg=Created container: task
0.511,Event,ADDED,eval-sanitize-30-r1-154-sp6gl.18d4f7d68ebc5291,reason=Started count=1 msg=Started container task
0.5112,Event,ADDED,eval-sanitize-30-r1-154.18d4f7d661ce14d0,reason=SuccessfulCreate count=1 msg=Created pod: eval-sanitize-30-r1-154-sp6gl
0.5114,Event,ADDED,eval-sanitize-30-r1-154.18d4f7dd4f69a6af,reason=Completed count=1 msg=Job completed
0.5119,Event,ADDED,eval-sanitize-30-r1-155-snjzp.18d4f7d6a3d8bae1,"reason=FailedScheduling count=None msg=0/6 nodes are available: 2 c_wall violated: 2 conflicting context pair(s) with node memory, 4 node(s) had untolerated taint(s). no new claims to deallocate, preemption: 0/6 nodes are available: 2 No preemption victims found for incoming pod, 4 Preemption is not helpful for scheduling."
0.5122,Event,ADDED,eval-sanitize-30-r1-155-snjzp.18d4f7d6c26c759c,"reason=FailedScheduling count=None msg=0/6 nodes are available: 2 c_wall violated: 2 conflicting context pair(s) with node memory, 4 node(s) had untolerated taint(s). no new claims to deallocate, preemption: 0/6 nodes are available: 2 No preemption victims found for incoming pod, 4 Preemption is not helpful for scheduling."
0.5124,Event,ADDED,eval-sanitize-30-r1-155-snjzp.18d4f7d71c12ff8c,"reason=FailedScheduling count=None msg=0/6 nodes are available: 2 c_wall violated: 1 conflicting context pair(s) with node memory, 2 c_wall violated: 2 conflicting context pair(s) with node memory, 2 node(s) had untolerated taint(s). no new claims to deallocate, preemption: 0/6 nodes are available: 2 Preemption is not helpful for scheduling, 4 No preemption victims found for incoming pod."
0.5129,Event,ADDED,eval-sanitize-30-r1-155-snjzp.18d4f7d734005b79,"reason=FailedScheduling count=None msg=0/6 nodes are available: 2 c_wall violated: 1 conflicting context pair(s) with node memory, 2 c_wall violated: 2 conflicting context pair(s) with node memory, 2 node(s) had untolerated taint(s). no new claims to deallocate, preemption: 0/6 nodes are available: 2 Preemption is not helpful for scheduling, 4 No preemption victims found for incoming pod."
0.5132,Event,ADDED,eval-sanitize-30-r1-155-snjzp.18d4f7d77573345f,"reason=FailedScheduling count=None msg=0/6 nodes are available: 1 c_wall violated: 1 conflicting context pair(s) with node memory, 2 node(s) had untolerated taint(s), 3 c_wall violated: 2 conflicting context pair(s) with node memory. no new claims to deallocate, preemption: 0/6 nodes are available: 2 Preemption is not helpful for scheduling, 4 No preemption victims found for incoming pod."
0.5134,Event,ADDED,eval-sanitize-30-r1-155-snjzp.18d4f7da2ec30e0f,"reason=FailedScheduling count=None msg=0/6 nodes are available: 1 c_wall violated: 3 conflicting context pair(s) with node memory, 2 node(s) had untolerated taint(s), 3 c_wall violated: 2 conflicting context pair(s) with node memory. no new claims to deallocate, preemption: 0/6 nodes are available: 2 Preemption is not helpful for scheduling, 4 No preemption victims found for incoming pod."
0.5139,Event,ADDED,eval-sanitize-30-r1-155-snjzp.18d4f7da575492dc,"reason=FailedScheduling count=None msg=0/6 nodes are available: 1 c_wall violated: 3 conflicting context pair(s) with node memory, 2 node(s) had untolerated taint(s), 3 c_wall violated: 2 conflicting context pair(s) with node memory. no new claims to deallocate, preemption: 0/6 nodes are available: 2 Preemption is not helpful for scheduling, 4 No preemption victims found for incoming pod."
0.5145,Event,ADDED,eval-sanitize-30-r1-155-snjzp.18d4f7dd6bb166cc,"reason=FailedScheduling count=None msg=0/6 nodes are available: 1 c_wall violated: 3 conflicting context pair(s) with node memory, 2 c_wall violated: 2 conflicting context pair(s) with node memory, 3 node(s) had untolerated taint(s). no new claims to deallocate, preemption: 0/6 nodes are available: 3 No preemption victims found for incoming pod, 3 Preemption is not helpful for scheduling."
0.5149,Event,ADDED,eval-sanitize-30-r1-155-snjzp.18d4f7dda777d0ec,reason=Scheduled count=None msg=Successfully assigned compute/eval-sanitize-30-r1-155-snjzp to kind-worker3
0.5155,Event,ADDED,eval-sanitize-30-r1-155-snjzp.18d4f7ddc32c9231,"reason=Pulled count=1 msg=Container image ""busybox:musl"" already present on machine"
0.516,Event,ADDED,eval-sanitize-30-r1-155-snjzp.18d4f7ddc4d984f9,reason=Created count=1 msg=Created container: task
0.5164,Event,ADDED,eval-sanitize-30-r1-155-snjzp.18d4f7ddcc62763f,reason=Started count=1 msg=Started container task
0.5168,Event,ADDED,eval-sanitize-30-r1-155.18d4f7d69e613a83,reason=SuccessfulCreate count=1 msg=Created pod: eval-sanitize-30-r1-155-snjzp
0.517,Event,ADDED,eval-sanitize-30-r1-155.18d4f7e32ea9ab3b,reason=Completed count=1 msg=Job completed
0.5172,Event,ADDED,eval-sanitize-30-r1-156-bk9kg.18d4f7d6d9e5c743,"reason=FailedScheduling count=None msg=0/6 nodes are available: 1 c_wall violated: 2 conflicting context pair(s) with node memory, 1 c_wall violated: 3 conflicting context pair(s) with node memory, 4 node(s) had untolerated taint(s). no new claims to deallocate, preemption: 0/6 nodes are available: 2 No preemption victims found for incoming pod, 4 Preemption is not helpful for scheduling."
0.5177,Event,ADDED,eval-sanitize-30-r1-156-bk9kg.18d4f7d6df59ed3e,"reason=FailedScheduling count=None msg=0/6 nodes are available: 1 c_wall violated: 2 conflicting context pair(s) with node memory, 1 c_wall violated: 3 conflicting context pair(s) with node memory, 4 node(s) had untolerated taint(s). no new claims to deallocate, preemption: 0/6 nodes are available: 2 No preemption victims found for incoming pod, 4 Preemption is not helpful for scheduling."
0.5179,Event,ADDED,eval-sanitize-30-r1-156-bk9kg.18d4f7d714fa8441,"reason=FailedScheduling count=None msg=0/6 nodes are available: 1 c_wall violated: 2 conflicting context pair(s) with node memory, 1 c_wall violated: 3 conflicting context pair(s) with node memory, 2 c_wall violated: 1 conflicting context pair(s) with node memory, 2 node(s) had untolerated taint(s). no new claims to deallocate, preemption: 0/6 nodes are available: 2 Preemption is not helpful for scheduling, 4 No preemption victims found for incoming pod."
0.5182,Event,ADDED,eval-sanitize-30-r1-156-bk9kg.18d4f7d72db34b51,"reason=FailedScheduling count=None msg=0/6 nodes are available: 1 c_wall violated: 2 conflicting context pair(s) with node memory, 1 c_wall violated: 3 conflicting context pair(s) with node memory, 2 c_wall violated: 1 conflicting context pair(s) with node memory, 2 node(s) had untolerated taint(s). no new claims to deallocate, preemption: 0/6 nodes are available: 2 Preemption is not helpful for scheduling, 4 No preemption victims found for incoming pod."
0.5186,Event,ADDED,eval-sanitize-30-r1-156-bk9kg.18d4f7da4cc5926d,"reason=FailedScheduling count=None msg=0/6 nodes are available: 1 c_wall violated: 1 conflicting context pair(s) with node memory, 1 c_wall violated: 3 conflicting context pair(s) with node memory, 2 c_wall violated: 2 conflicting context pair(s) with node memory, 2 node(s) had untolerated taint(s). no new claims to deallocate, preemption: 0/6 nodes are available: 2 Preemption is not helpful for scheduling, 4 No preemption victims found for incoming pod."
0.5192,Event,ADDED,eval-sanitize-30-r1-156-bk9kg.18d4f7dacfef2bd3,"reason=FailedScheduling count=None msg=0/6 nodes are available: 1 c_wall violated: 3 conflicting context pair(s) with node memory, 2 node(s) had untolerated taint(s), 3 c_wall violated: 2 conflicting context pair(s) with node memory. no new claims to deallocate, preemption: 0/6 nodes are available: 2 Preemption is not helpful for scheduling, 4 No preemption victims found for incoming pod."
0.5195,Event,ADDED,eval-sanitize-30-r1-156-bk9kg.18d4f7dd71d84828,"reason=FailedScheduling count=None msg=0/6 nodes are available: 2 c_wall violated: 2 conflicting context pair(s) with node memory, 4 node(s) had untolerated taint(s). no new claims to deallocate, preemption: 0/6 nodes are available: 2 No preemption victims found for incoming pod, 4 Preemption is not helpful for scheduling."
0.5206,Event,ADDED,eval-sanitize-30-r1-156-bk9kg.18d4f7dd8ee36b14,"reason=FailedScheduling count=None msg=0/6 nodes are available: 2 c_wall violated: 2 conflicting context pair(s) with node memory, 4 node(s) had untolerated taint(s). no new claims to deallocate, preemption: 0/6 nodes are available: 2 No preemption victims found for incoming pod, 4 Preemption is not helpful for scheduling."
0.5208,Event,ADDED,eval-sanitize-30-r1-156-bk9kg.18d4f7ddb3167d26,reason=Scheduled count=None msg=Successfully assigned compute/eval-sanitize-30-r1-156-bk9kg to kind-worker3
0.5214,Event,ADDED,eval-sanitize-30-r1-156-bk9kg.18d4f7ddd4f38a08,"reason=Pulled count=1 msg=Container image ""busybox:musl"" already present on machine"
0.5219,Event,ADDED,eval-sanitize-30-r1-156-bk9kg.18d4f7ddd72c8954,reason=Created count=1 msg=Created container: task
0.5222,Event,ADDED,eval-sanitize-30-r1-156-bk9kg.18d4f7dddba7deba,reason=Started count=1 msg=Started container task
0.5227,Event,ADDED,eval-sanitize-30-r1-156.18d4f7d6d9517055,reason=SuccessfulCreate count=1 msg=Created pod: eval-sanitize-30-r1-156-bk9kg
0.5232,Event,ADDED,eval-sanitize-30-r1-156.18d4f7e36c7a87be,reason=Completed count=1 msg=Job completed
0.5237,Event,ADDED,eval-sanitize-30-r1-157-c8lhc.18d4f7d7276fe59e,reason=Scheduled count=None msg=Successfully assigned compute/eval-sanitize-30-r1-157-c8lhc to kind-worker
0.5243,Event,ADDED,eval-sanitize-30-r1-157-c8lhc.18d4f7d746af041e,"reason=Pulled count=1 msg=Container image ""busybox:musl"" already present on machine"
0.525,Event,ADDED,eval-sanitize-30-r1-157-c8lhc.18d4f7d748366d9c,reason=Created count=1 msg=Created container: task
0.526,Event,ADDED,eval-sanitize-30-r1-157-c8lhc.18d4f7d74efd4c19,reason=Started count=1 msg=Started container task
0.5267,Event,ADDED,eval-sanitize-30-r1-157.18d4f7d717e58d83,reason=SuccessfulCreate count=1 msg=Created pod: eval-sanitize-30-r1-157-c8lhc
0.5271,Event,ADDED,eval-sanitize-30-r1-157.18d4f7ddcf7e0ead,reason=Completed count=1 msg=Job completed
0.5274,Event,ADDED,eval-sanitize-30-r1-158-js294.18d4f7d75cd1ecdd,reason=Scheduled count=None msg=Successfully assigned compute/eval-sanitize-30-r1-158-js294 to kind-worker2
0.5279,Event,ADDED,eval-sanitize-30-r1-158-js294.18d4f7d7795c5eaa,"reason=Pulled count=1 msg=Container image ""busybox:musl"" already present on machine"
0.5282,Event,ADDED,eval-sanitize-30-r1-158-js294.18d4f7d77af89504,reason=Created count=1 msg=Created container: task
0.5284,Event,ADDED,eval-sanitize-30-r1-158-js294.18d4f7d784a0d896,reason=Started count=1 msg=Started container task
0.5288,Event,ADDED,eval-sanitize-30-r1-158.18d4f7d75141b758,reason=SuccessfulCreate count=1 msg=Created pod: eval-sanitize-30-r1-158-js294
0.5293,Event,ADDED,eval-sanitize-30-r1-158.18d4f7ddeb501459,reason=Completed count=1 msg=Job completed
0.5295,Event,ADDED,eval-sanitize-30-r1-159-xx4wz.18d4f7d7999271c3,reason=Scheduled count=None msg=Successfully assigned compute/eval-sanitize-30-r1-159-xx4wz to kind-worker5
0.5298,Event,ADDED,eval-sanitize-30-r1-159-xx4wz.18d4f7d7c08065bb,"reason=Pulled count=1 msg=Container image ""busybox:musl"" already present on machine"
0.5301,Event,ADDED,eval-sanitize-30-r1-159-xx4wz.18d4f7d7c24e2b3f,reason=Created count=1 msg=Created container: task
0.5315,Event,ADDED,eval-sanitize-30-r1-159-xx4wz.18d4f7d7c7bab860,reason=Started count=1 msg=Started container task
0.5322,Event,ADDED,eval-sanitize-30-r1-159.18d4f7d78f8c7c08,reason=SuccessfulCreate count=1 msg=Created pod: eval-sanitize-30-r1-159-xx4wz
0.5331,Event,ADDED,eval-sanitize-30-r1-159.18d4f7ddff2d2a06,reason=Completed count=1 msg=Job completed
0.5335,Event,ADDED,eval-sanitize-30-r1-160-tr66g.18d4f7d7cfc188c3,reason=Scheduled count=None msg=Successfully assigned compute/eval-sanitize-30-r1-160-tr66g to kind-worker2
0.5338,Event,ADDED,eval-sanitize-30-r1-160-tr66g.18d4f7d7f19ad18c,"reason=Pulled count=1 msg=Container image ""busybox:musl"" already present on machine"
0.5341,Event,ADDED,eval-sanitize-30-r1-160-tr66g.18d4f7d7f37bceac,reason=Created count=1 msg=Created container: task
0.5343,Event,ADDED,eval-sanitize-30-r1-160-tr66g.18d4f7d7f8ed4b42,reason=Started count=1 msg=Started container task
0.5345,Event,ADDED,eval-sanitize-30-r1-160.18d4f7d7c78e5ada,reason=SuccessfulCreate count=1 msg=Created pod: eval-sanitize-30-r1-160-tr66g
0.5347,Event,ADDED,eval-sanitize-30-r1-160.18d4f7de1d2ea68d,reason=Completed count=1 msg=Job completed
0.5348,Event,ADDED,eval-sanitize-30-r1-161-qgsf6.18d4f7d8058b95b0,reason=Scheduled count=None msg=Successfully assigned compute/eval-sanitize-30-r1-161-qgsf6 to kind-worker5
0.5351,Event,ADDED,eval-sanitize-30-r1-161-qgsf6.18d4f7d821abb186,"reason=Pulled count=1 msg=Container image ""busybox:musl"" already present on machine"
0.5358,Event,ADDED,eval-sanitize-30-r1-161-qgsf6.18d4f7d823160a88,reason=Created count=1 msg=Created container: task
0.5362,Event,ADDED,eval-sanitize-30-r1-161-qgsf6.18d4f7d828710c2d,reason=Started count=1 msg=Started container task
0.5366,Event,ADDED,eval-sanitize-30-r1-161.18d4f7d803a969c7,reason=SuccessfulCreate count=1 msg=Created pod: eval-sanitize-30-r1-161-qgsf6
0.5373,Event,ADDED,eval-sanitize-30-r1-161.18d4f7de31c9c7b2,reason=Completed count=1 msg=Job completed
0.5377,Event,ADDED,eval-sanitize-30-r1-162-vczjg.18d4f7d849b9ffc2,reason=Scheduled count=None msg=Successfully assigned compute/eval-sanitize-30-r1-162-vczjg to kind-worker
0.5381,Event,ADDED,eval-sanitize-30-r1-162-vczjg.18d4f7d866d67192,"reason=Pulled count=1 msg=Container image ""busybox:musl"" already present on machine"
0.5383,Event,ADDED,eval-sanitize-30-r1-162-vczjg.18d4f7d86833db9d,reason=Created count=1 msg=Created container: task
0.5389,Event,ADDED,eval-sanitize-30-r1-162-vczjg.18d4f7d86db9cd9e,reason=Started count=1 msg=Started container task
0.5392,Event,ADDED,eval-sanitize-30-r1-162.18d4f7d83e55f8a2,reason=SuccessfulCreate count=1 msg=Created pod: eval-sanitize-30-r1-162-vczjg
0.5395,Event,ADDED,eval-sanitize-30-r1-162.18d4f7de1114d415,reason=Completed count=1 msg=Job completed
0.5398,Event,ADDED,eval-sanitize-30-r1-163-cn9gd.18d4f7d880ccbd09,reason=Scheduled count=None msg=Successfully assigned compute/eval-sanitize-30-r1-163-cn9gd to kind-worker4
0.5402,Event,ADDED,eval-sanitize-30-r1-163-cn9gd.18d4f7d89c594047,"reason=Pulled count=1 msg=Container image ""busybox:musl"" already present on machine"
0.5405,Event,ADDED,eval-sanitize-30-r1-163-cn9gd.18d4f7d89db1c22c,reason=Created count=1 msg=Created container: task
0.5407,Event,ADDED,eval-sanitize-30-r1-163-cn9gd.18d4f7d8a3e33ff5,reason=Started count=1 msg=Started container task
0.5411,Event,ADDED,eval-sanitize-30-r1-163.18d4f7d87a56ddb6,reason=SuccessfulCreate count=1 msg=Created pod: eval-sanitize-30-r1-163-cn9gd
0.5412,Event,ADDED,eval-sanitize-30-r1-163.18d4f7de4e1e7ff0,reason=Completed count=1 msg=Job completed
0.5415,Event,ADDED,eval-sanitize-30-r1-164-w5lgb.18d4f7d8bce40051,"reason=FailedScheduling count=None msg=0/6 nodes are available: 1 c_wall violated: 2 conflicting context pair(s) with node memory, 1 c_wall violated: 3 conflicting context pair(s) with node memory, 2 c_wall violated: 1 conflicting context pair(s) with node memory, 2 node(s) had untolerated taint(s). no new claims to deallocate, preemption: 0/6 nodes are available: 2 Preemption is not helpful for scheduling, 4 No preemption victims found for incoming pod."
0.5421,Event,ADDED,eval-sanitize-30-r1-164-w5lgb.18d4f7d8c2d69d9f,"reason=FailedScheduling count=None msg=0/6 nodes are available: 1 c_wall violated: 2 conflicting context pair(s) with node memory, 1 c_wall violated: 3 conflicting context pair(s) with node memory, 2 c_wall violated: 1 conflicting context pair(s) with node memory, 2 node(s) had untolerated taint(s). no new claims to deallocate, preemption: 0/6 nodes are available: 2 Preemption is not helpful for scheduling, 4 No preemption victims found for incoming pod."
0.5425,Event,ADDED,eval-sanitize-30-r1-164-w5lgb.18d4f7da648d42ca,"reason=FailedScheduling count=None msg=0/6 nodes are available: 1 c_wall violated: 1 conflicting context pair(s) with node memory, 1 c_wall violated: 3 conflicting context pair(s) with node memory, 2 c_wall violated: 2 conflicting context pair(s) with node memory, 2 node(s) had untolerated taint(s). no new claims to deallocate, preemption: 0/6 nodes are available: 2 Preemption is not helpful for scheduling, 4 No preemption victims found for incoming pod."
0.5429,Event,ADDED,eval-sanitize-30-r1-164-w5lgb.18d4f7dac9f52f9a,"reason=FailedScheduling count=None msg=0/6 nodes are available: 1 c_wall violated: 3 conflicting context pair(s) with node memory, 2 node(s) had untolerated taint(s), 3 c_wall violated: 2 conflicting context pair(s) with node memory. no new claims to deallocate, preemption: 0/6 nodes are available: 2 Preemption is not helpful for scheduling, 4 No preemption victims found for incoming pod."
0.5432,Event,ADDED,eval-sanitize-30-r1-164-w5lgb.18d4f7dd71073ecb,"reason=FailedScheduling count=None msg=0/6 nodes are available: 2 c_wall violated: 2 conflicting context pair(s) with node memory, 4 node(s) had untolerated taint(s). no new claims to deallocate, preemption: 0/6 nodes are available: 2 No preemption victims found for incoming pod, 4 Preemption is not helpful for scheduling."
0.5435,Event,ADDED,eval-sanitize-30-r1-164-w5lgb.18d4f7dd8cb482f7,"reason=FailedScheduling count=None msg=0/6 nodes are available: 2 c_wall violated: 2 conflicting context pair(s) with node memory, 4 node(s) had untolerated taint(s). no new claims to deallocate, preemption: 0/6 nodes are available: 2 No preemption victims found for incoming pod, 4 Preemption is not helpful for scheduling."
0.5438,Event,ADDED,eval-sanitize-30-r1-164-w5lgb.18d4f7ddaf8353dd,reason=Scheduled count=None msg=Successfully assigned compute/eval-sanitize-30-r1-164-w5lgb to kind-worker3
0.5442,Event,ADDED,eval-sanitize-30-r1-164-w5lgb.18d4f7ddcc7d915e,"reason=Pulled count=1 msg=Container image ""busybox:musl"" already present on machine"
0.5444,Event,ADDED,eval-sanitize-30-r1-164-w5lgb.18d4f7ddceb1a8cf,reason=Created count=1 msg=Created container: task
0.5446,Event,ADDED,eval-sanitize-30-r1-164-w5lgb.18d4f7ddd4e5ad94,reason=Started count=1 msg=Started container task
0.5447,Event,ADDED,eval-sanitize-30-r1-164.18d4f7d8b6a5d682,reason=SuccessfulCreate count=1 msg=Created pod: eval-sanitize-30-r1-164-w5lgb
0.545,Event,ADDED,eval-sanitize-30-r1-164.18d4f7e3311b736d,reason=Completed count=1 msg=Job completed
0.5451,Event,ADDED,eval-sanitize-30-r1-165-7h78f.18d4f7d8f8a82369,"reason=FailedScheduling count=None msg=0/6 nodes are available: 1 c_wall violated: 1 conflicting context pair(s) with node memory, 2 node(s) had untolerated taint(s), 3 c_wall violated: 2 conflicting context pair(s) with node memory. no new claims to deallocate, preemption: 0/6 nodes are available: 2 Preemption is not helpful for scheduling, 4 No preemption victims found for incoming pod."
0.5454,Event,ADDED,eval-sanitize-30-r1-165-7h78f.18d4f7d8fee46ce9,"reason=FailedScheduling count=None msg=0/6 nodes are available: 1 c_wall violated: 1 conflicting context pair(s) with node memory, 2 node(s) had untolerated taint(s), 3 c_wall violated: 2 conflicting context pair(s) with node memory. no new claims to deallocate, preemption: 0/6 nodes are available: 2 Preemption is not helpful for scheduling, 4 No preemption victims found for incoming pod."
0.5458,Event,ADDED,eval-sanitize-30-r1-165-7h78f.18d4f7da1140aa89,"reason=FailedScheduling count=None msg=0/6 nodes are available: 2 node(s) had untolerated taint(s), 4 c_wall violated: 2 conflicting context pair(s) with node memory. no new claims to deallocate, preemption: 0/6 nodes are available: 2 Preemption is not helpful for scheduling, 4 No preemption victims found for incoming pod."
0.5462,Event,ADDED,eval-sanitize-30-r1-165-7h78f.18d4f7da6a943650,"reason=FailedScheduling count=None msg=0/6 nodes are available: 1 c_wall violated: 3 conflicting context pair(s) with node memory, 2 node(s) had untolerated taint(s), 3 c_wall violated: 2 conflicting context pair(s) with node memory. no new claims to deallocate, preemption: 0/6 nodes are available: 2 Preemption is not helpful for scheduling, 4 No preemption victims found for incoming pod."
0.5469,Event,ADDED,eval-sanitize-30-r1-165-7h78f.18d4f7dd82e46367,"reason=FailedScheduling count=None msg=0/6 nodes are available: 1 c_wall violated: 2 conflicting context pair(s) with node memory, 1 c_wall violated: 3 conflicting context pair(s) with node memory, 4 node(s) had untolerated taint(s). no new claims to deallocate, preemption: 0/6 nodes are available: 2 No preemption victims found for incoming pod, 4 Preemption is not helpful for scheduling."
0.5473,Event,ADDED,eval-sanitize-30-r1-165-7h78f.18d4f7dda0b5408d,"reason=FailedScheduling count=None msg=0/6 nodes are available: 1 c_wall violated: 2 conflicting context pair(s) with node memory, 1 c_wall violated: 3 conflicting context pair(s) with node memory, 4 node(s) had untolerated taint(s). no new claims to deallocate, preemption: 0/6 nodes are available: 2 No preemption victims found for incoming pod, 4 Preemption is not helpful for scheduling."
0.5476,Event,ADDED,eval-sanitize-30-r1-165-7h78f.18d4f7ddd74d55fe,reason=Scheduled count=None msg=Successfully assigned compute/eval-sanitize-30-r1-165-7h78f to kind-worker3
0.5479,Event,ADDED,eval-sanitize-30-r1-165-7h78f.18d4f7ddf669308f,"reason=Pulled count=1 msg=Container image ""busybox:musl"" already present on machine"
0.5483,Event,ADDED,eval-sanitize-30-r1-165-7h78f.18d4f7ddf818eb8f,reason=Created count=1 msg=Created container: task
0.5486,Event,ADDED,eval-sanitize-30-r1-165-7h78f.18d4f7ddfc145adc,reason=Started count=1 msg=Started container task
0.5488,Event,ADDED,eval-sanitize-30-r1-165.18d4f7d8f65f259c,reason=SuccessfulCreate count=1 msg=Created pod: eval-sanitize-30-r1-165-7h78f
0.549,Event,ADDED,eval-sanitize-30-r1-165.18d4f7e36e4cfe58,reason=Completed count=1 msg=Job completed
0.5496,Event,ADDED,eval-sanitize-30-r1-166-sbjdj.18d4f7d93415f299,"reason=FailedScheduling count=None msg=0/6 nodes are available: 1 c_wall violated: 1 conflicting context pair(s) with node memory, 2 node(s) had untolerated taint(s), 3 c_wall violated: 2 conflicting context pair(s) with node memory. no new claims to deallocate, preemption: 0/6 nodes are available: 2 Preemption is not helpful for scheduling, 4 No preemption victims found for incoming pod."
0.5499,Event,ADDED,eval-sanitize-30-r1-166-sbjdj.18d4f7d93a12d8b0,"reason=FailedScheduling count=None msg=0/6 nodes are available: 1 c_wall violated: 1 conflicting context pair(s) with node memory, 2 node(s) had untolerated taint(s), 3 c_wall violated: 2 conflicting context pair(s) with node memory. no new claims to deallocate, preemption: 0/6 nodes are available: 2 Preemption is not helpful for scheduling, 4 No preemption victims found for incoming pod."
0.5502,Event,ADDED,eval-sanitize-30-r1-166-sbjdj.18d4f7da1bbd179d,"reason=FailedScheduling count=None msg=0/6 nodes are available: 2 node(s) had untolerated taint(s), 4 c_wall violated: 2 conflicting context pair(s) with node memory. no new claims to deallocate, preemption: 0/6 nodes are available: 2 Preemption is not helpful for scheduling, 4 No preemption victims found for incoming pod."
0.5507,Event,ADDED,eval-sanitize-30-r1-166-sbjdj.18d4f7da75f7629b,"reason=FailedScheduling count=None msg=0/6 nodes are available: 1 c_wall violated: 3 conflicting context pair(s) with node memory, 2 node(s) had untolerated taint(s), 3 c_wall violated: 2 conflicting context pair(s) with node memory. no new claims to deallocate, preemption: 0/6 nodes are available: 2 Preemption is not helpful for scheduling, 4 No preemption victims found for incoming pod."
0.5509,Event,ADDED,eval-sanitize-30-r1-166-sbjdj.18d4f7dd88c42d08,"reason=FailedScheduling count=None msg=0/6 nodes are available: 1 c_wall violated: 2 conflicting context pair(s) with node memory, 1 c_wall violated: 3 conflicting context pair(s) with node memory, 4 node(s) had untolerated taint(s). no new claims to deallocate, preemption: 0/6 nodes are available: 2 No preemption victims found for incoming pod, 4 Preemption is not helpful for scheduling."
0.551,Event,ADDED,eval-sanitize-30-r1-166-sbjdj.18d4f7dda69cdc49,"reason=FailedScheduling count=None msg=0/6 nodes are available: 1 c_wall violated: 2 conflicting context pair(s) with node memory, 1 c_wall violated: 3 conflicting context pair(s) with node memory, 4 node(s) had untolerated taint(s). no new claims to deallocate, preemption: 0/6 nodes are available: 2 No preemption victims found for incoming pod, 4 Preemption is not helpful for scheduling."
0.5514,Event,ADDED,eval-sanitize-30-r1-166-sbjdj.18d4f7ddeb520d0b,reason=Scheduled count=None msg=Successfully assigned compute/eval-sanitize-30-r1-166-sbjdj to kind-worker3
0.5516,Event,ADDED,eval-sanitize-30-r1-166-sbjdj.18d4f7de055c1858,"reason=Pulled count=1 msg=Container image ""busybox:musl"" already present on machine"
0.5518,Event,ADDED,eval-sanitize-30-r1-166-sbjdj.18d4f7de06d0b74e,reason=Created count=1 msg=Created container: task
0.5524,Event,ADDED,eval-sanitize-30-r1-166-sbjdj.18d4f7de0d228efd,reason=Started count=1 msg=Started container task
0.5527,Event,ADDED,eval-sanitize-30-r1-166.18d4f7d930c5cfa8,reason=SuccessfulCreate count=1 msg=Created pod: eval-sanitize-30-r1-166-sbjdj
0.5531,Event,ADDED,eval-sanitize-30-r1-166.18d4f7e36daba803,reason=Completed count=1 msg=Job completed
0.5534,Event,ADDED,eval-sanitize-30-r1-167-wptfb.18d4f7d96b8bfa4f,reason=Scheduled count=None msg=Successfully assigned compute/eval-sanitize-30-r1-167-wptfb to kind-worker2
0.5539,Event,ADDED,eval-sanitize-30-r1-167-wptfb.18d4f7d986426787,"reason=Pulled count=1 msg=Container image ""busybox:musl"" already present on machine"
0.5542,Event,ADDED,eval-sanitize-30-r1-167-wptfb.18d4f7d987cf4e8e,reason=Created count=1 msg=Created container: task
0.5546,Event,ADDED,eval-sanitize-30-r1-167-wptfb.18d4f7d98dc761e9,reason=Started count=1 msg=Started container task
0.555,Event,ADDED,eval-sanitize-30-r1-167.18d4f7d968c3b594,reason=SuccessfulCreate count=1 msg=Created pod: eval-sanitize-30-r1-167-wptfb
0.5553,Event,ADDED,eval-sanitize-30-r1-167.18d4f7df3817a8f2,reason=Completed count=1 msg=Job completed
0.5557,Event,ADDED,eval-sanitize-30-r1-168-9xbhw.18d4f7d9abf155f3,reason=Scheduled count=None msg=Successfully assigned compute/eval-sanitize-30-r1-168-9xbhw to kind-worker
0.5561,Event,ADDED,eval-sanitize-30-r1-168-9xbhw.18d4f7d9c749fac7,"reason=Pulled count=1 msg=Container image ""busybox:musl"" already present on machine"
0.5564,Event,ADDED,eval-sanitize-30-r1-168-9xbhw.18d4f7d9c8cfe6c9,reason=Created count=1 msg=Created container: task
0.5568,Event,ADDED,eval-sanitize-30-r1-168-9xbhw.18d4f7d9cf3fee16,reason=Started count=1 msg=Started container task
0.5572,Event,ADDED,eval-sanitize-30-r1-168.18d4f7d9a63b0ed9,reason=SuccessfulCreate count=1 msg=Created pod: eval-sanitize-30-r1-168-9xbhw
0.5576,Event,ADDED,eval-sanitize-30-r1-168.18d4f7df6bcb3836,reason=Completed count=1 msg=Job completed
0.5579,Event,ADDED,eval-sanitize-30-r1-169-zg6p7.18d4f7d9edb08517,reason=Scheduled count=None msg=Successfully assigned compute/eval-sanitize-30-r1-169-zg6p7 to kind-worker5
0.5583,Event,ADDED,eval-sanitize-30-r1-169-zg6p7.18d4f7da0ea51e51,"reason=Pulled count=1 msg=Container image ""busybox:musl"" already present on machine"
0.5592,Event,ADDED,eval-sanitize-30-r1-169-zg6p7.18d4f7da102b8e69,reason=Created count=1 msg=Created container: task
0.5599,Event,ADDED,eval-sanitize-30-r1-169-zg6p7.18d4f7da191723e3,reason=Started count=1 msg=Started container task
0.5604,Event,ADDED,eval-sanitize-30-r1-169.18d4f7d9dff4d4bd,reason=SuccessfulCreate count=1 msg=Created pod: eval-sanitize-30-r1-169-zg6p7
0.5612,Event,ADDED,eval-sanitize-30-r1-169.18d4f7df78d9166e,reason=Completed count=1 msg=Job completed
0.5615,Event,ADDED,eval-sanitize-30-r1-170-bhnns.18d4f7da234bf2d9,reason=Scheduled count=None msg=Successfully assigned compute/eval-sanitize-30-r1-170-bhnns to kind-worker5
0.562,Event,ADDED,eval-sanitize-30-r1-170-bhnns.18d4f7da3e7dbb80,"reason=Pulled count=1 msg=Container image ""busybox:musl"" already present on machine"
0.5624,Event,ADDED,eval-sanitize-30-r1-170-bhnns.18d4f7da3ffda15d,reason=Created count=1 msg=Created container: task
0.5627,Event,ADDED,eval-sanitize-30-r1-170-bhnns.18d4f7da45b7c0e4,reason=Started count=1 msg=Started container task
0.563,Event,ADDED,eval-sanitize-30-r1-170.18d4f7da1b5c0e93,reason=SuccessfulCreate count=1 msg=Created pod: eval-sanitize-30-r1-170-bhnns
0.5636,Event,ADDED,eval-sanitize-30-r1-170.18d4f7dff012c64d,reason=Completed count=1 msg=Job completed
0.5646,Event,ADDED,eval-sanitize-30-r1-171-dv9dl.18d4f7da5e3f2daf,"reason=FailedScheduling count=None msg=0/6 nodes are available: 1 c_wall violated: 1 conflicting context pair(s) with node memory, 1 c_wall violated: 3 conflicting context pair(s) with node memory, 2 c_wall violated: 2 conflicting context pair(s) with node memory, 2 node(s) had untolerated taint(s). no new claims to deallocate, preemption: 0/6 nodes are available: 2 Preemption is not helpful for scheduling, 4 No preemption victims found for incoming pod."
0.5652,Event,ADDED,eval-sanitize-30-r1-171-dv9dl.18d4f7da885ea671,"reason=FailedScheduling count=None msg=0/6 nodes are available: 1 c_wall violated: 1 conflicting context pair(s) with node memory, 1 c_wall violated: 3 conflicting context pair(s) with node memory, 2 c_wall violated: 2 conflicting context pair(s) with node memory, 2 node(s) had untolerated taint(s). no new claims to deallocate, preemption: 0/6 nodes are available: 2 Preemption is not helpful for scheduling, 4 No preemption victims found for incoming pod."
0.5658,Event,ADDED,eval-sanitize-30-r1-171-dv9dl.18d4f7dae075b0f1,"reason=FailedScheduling count=None msg=0/6 nodes are available: 1 c_wall violated: 3 conflicting context pair(s) with node memory, 2 node(s) had untolerated taint(s), 3 c_wall violated: 2 conflicting context pair(s) with node memory. no new claims to deallocate, preemption: 0/6 nodes are available: 2 Preemption is not helpful for scheduling, 4 No preemption victims found for incoming pod."
0.5662,Event,ADDED,eval-sanitize-30-r1-171-dv9dl.18d4f7dd7cff7219,"reason=FailedScheduling count=None msg=0/6 nodes are available: 2 c_wall violated: 2 conflicting context pair(s) with node memory, 4 node(s) had untolerated taint(s). no new claims to deallocate, preemption: 0/6 nodes are available: 2 No preemption victims found for incoming pod, 4 Preemption is not helpful for scheduling."
0.5666,Event,ADDED,eval-sanitize-30-r1-171-dv9dl.18d4f7dd9a9bf83c,"reason=FailedScheduling count=None msg=0/6 nodes are available: 2 c_wall violated: 2 conflicting context pair(s) with node memory, 4 node(s) had untolerated taint(s). no new claims to deallocate, preemption: 0/6 nodes are available: 2 No preemption victims found for incoming pod, 4 Preemption is not helpful for scheduling."
0.5671,Event,ADDED,eval-sanitize-30-r1-171-dv9dl.18d4f7ddcc82da5f,reason=Scheduled count=None msg=Successfully assigned compute/eval-sanitize-30-r1-171-dv9dl to kind-worker3
0.5676,Event,ADDED,eval-sanitize-30-r1-171-dv9dl.18d4f7ddeb1a3033,"reason=Pulled count=1 msg=Container image ""busybox:musl"" already present on machine"
0.568,Event,ADDED,eval-sanitize-30-r1-171-dv9dl.18d4f7dded95cd4a,reason=Created count=1 msg=Created container: task
0.5684,Event,ADDED,eval-sanitize-30-r1-171-dv9dl.18d4f7ddf668fa2e,reason=Started count=1 msg=Started container task
0.5689,Event,ADDED,eval-sanitize-30-r1-171.18d4f7da56e76876,reason=SuccessfulCreate count=1 msg=Created pod: eval-sanitize-30-r1-171-dv9dl
0.5696,Event,ADDED,eval-sanitize-30-r1-171.18d4f7e32eaa4c07,reason=Completed count=1 msg=Job completed
0.57,Event,ADDED,eval-sanitize-30-r1-172-2lmpn.18d4f7da9495bcb2,reason=Scheduled count=None msg=Successfully assigned compute/eval-sanitize-30-r1-172-2lmpn to kind-worker2
0.5708,Event,ADDED,eval-sanitize-30-r1-172-2lmpn.18d4f7daaf8df4ae,"reason=Pulled count=1 msg=Container image ""busybox:musl"" already present on machine"
0.5712,Event,ADDED,eval-sanitize-30-r1-172-2lmpn.18d4f7dab106341b,reason=Created count=1 msg=Created container: task
0.5716,Event,ADDED,eval-sanitize-30-r1-172-2lmpn.18d4f7dab647b9aa,reason=Started count=1 msg=Started container task
0.5719,Event,ADDED,eval-sanitize-30-r1-172.18d4f7da9299de10,reason=SuccessfulCreate count=1 msg=Created pod: eval-sanitize-30-r1-172-2lmpn
0.5723,Event,ADDED,eval-sanitize-30-r1-172.18d4f7e05867ecae,reason=Completed count=1 msg=Job completed
0.5725,Event,ADDED,eval-sanitize-30-r1-173-rr45p.18d4f7dad5d07af6,"reason=FailedScheduling count=None msg=0/6 nodes are available: 1 c_wall violated: 3 conflicting context pair(s) with node memory, 2 node(s) had untolerated taint(s), 3 c_wall violated: 2 conflicting context pair(s) with node memory. no new claims to deallocate, preemption: 0/6 nodes are available: 2 Preemption is not helpful for scheduling, 4 No preemption victims found for incoming pod."
0.5729,Event,ADDED,eval-sanitize-30-r1-173-rr45p.18d4f7dae75b5673,"reason=FailedScheduling count=None msg=0/6 nodes are available: 1 c_wall violated: 3 conflicting context pair(s) with node memory, 2 node(s) had untolerated taint(s), 3 c_wall violated: 2 conflicting context pair(s) with node memory. no new claims to deallocate, preemption: 0/6 nodes are available: 2 Preemption is not helpful for scheduling, 4 No preemption victims found for incoming pod."
0.5733,Event,ADDED,eval-sanitize-30-r1-173-rr45p.18d4f7dd7e6af8d3,"reason=FailedScheduling count=None msg=0/6 nodes are available: 1 c_wall violated: 2 conflicting context pair(s) with node memory, 1 c_wall violated: 3 conflicting context pair(s) with node memory, 4 node(s) had untolerated taint(s). no new claims to deallocate, preemption: 0/6 nodes are available: 2 No preemption victims found for incoming pod, 4 Preemption is not helpful for scheduling."
0.5735,Event,ADDED,eval-sanitize-30-r1-173-rr45p.18d4f7dd9b24220f,"reason=FailedScheduling count=None msg=0/6 nodes are available: 1 c_wall violated: 2 conflicting context pair(s) with node memory, 1 c_wall violated: 3 conflicting context pair(s) with node memory, 4 node(s) had untolerated taint(s). no new claims to deallocate, preemption: 0/6 nodes are available: 2 No preemption victims found for incoming pod, 4 Preemption is not helpful for scheduling."
0.5738,Event,ADDED,eval-sanitize-30-r1-173-rr45p.18d4f7ddd12a4474,reason=Scheduled count=None msg=Successfully assigned compute/eval-sanitize-30-r1-173-rr45p to kind-worker3
0.5743,Event,ADDED,eval-sanitize-30-r1-173-rr45p.18d4f7ddf3ba931f,"reason=Pulled count=1 msg=Container image ""busybox:musl"" already present on machine"
0.5746,Event,ADDED,eval-sanitize-30-r1-173-rr45p.18d4f7ddf50a7a28,reason=Created count=1 msg=Created container: task
0.575,Event,ADDED,eval-sanitize-30-r1-173-rr45p.18d4f7ddf8903e71,reason=Started count=1 msg=Started container task
0.5752,Event,ADDED,eval-sanitize-30-r1-173.18d4f7dace1801c4,reason=SuccessfulCreate count=1 msg=Created pod: eval-sanitize-30-r1-173-rr45p
0.5756,Event,ADDED,eval-sanitize-30-r1-173.18d4f7e3309057be,reason=Completed count=1 msg=Job completed
0.5759,Event,ADDED,eval-sanitize-30-r1-174-v8c5b.18d4f7db13be48f4,reason=Scheduled count=None msg=Successfully assigned compute/eval-sanitize-30-r1-174-v8c5b to kind-worker2
0.5763,Event,ADDED,eval-sanitize-30-r1-174-v8c5b.18d4f7db336d83cf,"reason=Pulled count=1 msg=Container image ""busybox:musl"" already present on machine"
0.5766,Event,ADDED,eval-sanitize-30-r1-174-v8c5b.18d4f7db3544e080,reason=Created count=1 msg=Created container: task
0.5772,Event,ADDED,eval-sanitize-30-r1-174-v8c5b.18d4f7db3e0da59f,reason=Started count=1 msg=Started container task
0.5777,Event,ADDED,eval-sanitize-30-r1-174.18d4f7db0a176055,reason=SuccessfulCreate count=1 msg=Created pod: eval-sanitize-30-r1-174-v8c5b
0.5779,Event,ADDED,eval-sanitize-30-r1-174.18d4f7e0ca60f076,reason=Completed count=1 msg=Job completed
0.5782,Event,ADDED,eval-sanitize-30-r1-175-s6wwj.18d4f7db52758eca,"reason=FailedScheduling count=None msg=0/6 nodes are available: 1 c_wall violated: 3 conflicting context pair(s) with node memory, 2 node(s) had untolerated taint(s), 3 c_wall violated: 2 conflicting context pair(s) with node memory. no new claims to deallocate, preemption: 0/6 nodes are available: 2 Preemption is not helpful for scheduling, 4 No preemption victims found for incoming pod."
0.5784,Event,ADDED,eval-sanitize-30-r1-175-s6wwj.18d4f7db941127ea,"reason=FailedScheduling count=None msg=0/6 nodes are available: 1 c_wall violated: 3 conflicting context pair(s) with node memory, 2 node(s) had untolerated taint(s), 3 c_wall violated: 2 conflicting context pair(s) with node memory. no new claims to deallocate, preemption: 0/6 nodes are available: 2 Preemption is not helpful for scheduling, 4 No preemption victims found for incoming pod."
0.5785,Event,ADDED,eval-sanitize-30-r1-175-s6wwj.18d4f7dd78b1413c,"reason=FailedScheduling count=None msg=0/6 nodes are available: 1 c_wall violated: 2 conflicting context pair(s) with node memory, 1 c_wall violated: 3 conflicting context pair(s) with node memory, 4 node(s) had untolerated taint(s). no new claims to deallocate, preemption: 0/6 nodes are available: 2 No preemption victims found for incoming pod, 4 Preemption is not helpful for scheduling."
0.5787,Event,ADDED,eval-sanitize-30-r1-175-s6wwj.18d4f7dd952b7395,"reason=FailedScheduling count=None msg=0/6 nodes are available: 1 c_wall violated: 2 conflicting context pair(s) with node memory, 1 c_wall violated: 3 conflicting context pair(s) with node memory, 4 node(s) had untolerated taint(s). no new claims to deallocate, preemption: 0/6 nodes are available: 2 No preemption victims found for incoming pod, 4 Preemption is not helpful for scheduling."
0.5789,Event,ADDED,eval-sanitize-30-r1-175-s6wwj.18d4f7ddc5ac812c,reason=Scheduled count=None msg=Successfully assigned compute/eval-sanitize-30-r1-175-s6wwj to kind-worker3
0.5791,Event,ADDED,eval-sanitize-30-r1-175-s6wwj.18d4f7dde1a6aa64,"reason=Pulled count=1 msg=Container image ""busybox:musl"" already present on machine"
0.5795,Event,ADDED,eval-sanitize-30-r1-175-s6wwj.18d4f7dde350798a,reason=Created count=1 msg=Created container: task
0.5797,Event,ADDED,eval-sanitize-30-r1-175-s6wwj.18d4f7ddeafa019b,reason=Started count=1 msg=Started container task
0.5799,Event,ADDED,eval-sanitize-30-r1-175.18d4f7db45312c29,reason=SuccessfulCreate count=1 msg=Created pod: eval-sanitize-30-r1-175-s6wwj
0.5801,Event,ADDED,eval-sanitize-30-r1-175.18d4f7e3306029a8,reason=Completed count=1 msg=Job completed
0.5805,Event,ADDED,eval-sanitize-30-r1-176-l76lp.18d4f7db8d54e10a,"reason=FailedScheduling count=None msg=0/6 nodes are available: 1 c_wall violated: 3 conflicting context pair(s) with node memory, 2 node(s) had untolerated taint(s), 3 c_wall violated: 2 conflicting context pair(s) with node memory. no new claims to deallocate, preemption: 0/6 nodes are available: 2 Preemption is not helpful for scheduling, 4 No preemption victims found for incoming pod."
0.5808,Event,ADDED,eval-sanitize-30-r1-176-l76lp.18d4f7dbd61d8dbd,"reason=FailedScheduling count=None msg=0/6 nodes are available: 1 c_wall violated: 3 conflicting context pair(s) with node memory, 2 node(s) had untolerated taint(s), 3 c_wall violated: 2 conflicting context pair(s) with node memory. no new claims to deallocate, preemption: 0/6 nodes are available: 2 Preemption is not helpful for scheduling, 4 No preemption victims found for incoming pod."
0.581,Event,ADDED,eval-sanitize-30-r1-176-l76lp.18d4f7dd7294fd70,"reason=FailedScheduling count=None msg=0/6 nodes are available: 2 c_wall violated: 2 conflicting context pair(s) with node memory, 4 node(s) had untolerated taint(s). no new claims to deallocate, preemption: 0/6 nodes are available: 2 No preemption victims found for incoming pod, 4 Preemption is not helpful for scheduling."
0.5815,Event,ADDED,eval-sanitize-30-r1-176-l76lp.18d4f7dd8f55ff65,"reason=FailedScheduling count=None msg=0/6 nodes are available: 2 c_wall violated: 2 conflicting context pair(s) with node memory, 4 node(s) had untolerated taint(s). no new claims to deallocate, preemption: 0/6 nodes are available: 2 No preemption victims found for incoming pod, 4 Preemption is not helpful for scheduling."
0.5819,Event,ADDED,eval-sanitize-30-r1-176-l76lp.18d4f7ddb9deef8c,reason=Scheduled count=None msg=Successfully assigned compute/eval-sanitize-30-r1-176-l76lp to kind-worker3
0.5821,Event,ADDED,eval-sanitize-30-r1-176-l76lp.18d4f7ddd6781bb2,"reason=Pulled count=1 msg=Container image ""busybox:musl"" already present on machine"
0.5826,Event,ADDED,eval-sanitize-30-r1-176-l76lp.18d4f7ddd8852dcf,reason=Created count=1 msg=Created container: task
0.5829,Event,ADDED,eval-sanitize-30-r1-176-l76lp.18d4f7dddc8b37dd,reason=Started count=1 msg=Started container task
0.5831,Event,ADDED,eval-sanitize-30-r1-176.18d4f7db823c5fe6,reason=SuccessfulCreate count=1 msg=Created pod: eval-sanitize-30-r1-176-l76lp
0.5833,Event,ADDED,eval-sanitize-30-r1-176.18d4f7e331643b71,reason=Completed count=1 msg=Job completed
0.5836,Event,ADDED,eval-sanitize-30-r1-177-jgkfp.18d4f7dbc4902430,reason=Scheduled count=None msg=Successfully assigned compute/eval-sanitize-30-r1-177-jgkfp to kind-worker4
0.5837,Event,ADDED,eval-sanitize-30-r1-177-jgkfp.18d4f7dbe61b6cec,"reason=Pulled count=1 msg=Container image ""busybox:musl"" already present on machine"
0.5839,Event,ADDED,eval-sanitize-30-r1-177-jgkfp.18d4f7dbe7d76473,reason=Created count=1 msg=Created container: task
0.5842,Event,ADDED,eval-sanitize-30-r1-177-jgkfp.18d4f7dbefb2c0b8,reason=Started count=1 msg=Started container task
0.5843,Event,ADDED,eval-sanitize-30-r1-177.18d4f7dbbc7bf81d,reason=SuccessfulCreate count=1 msg=Created pod: eval-sanitize-30-r1-177-jgkfp
0.5845,Event,ADDED,eval-sanitize-30-r1-177.18d4f7e179a4e726,reason=Completed count=1 msg=Job completed
0.5847,Event,ADDED,eval-sanitize-30-r1-178-knk4t.18d4f7dc3bfcc759,reason=Scheduled count=None msg=Successfully assigned compute/eval-sanitize-30-r1-178-knk4t to kind-worker
0.5849,Event,ADDED,eval-sanitize-30-r1-178-knk4t.18d4f7dc5830df56,"reason=Pulled count=1 msg=Container image ""busybox:musl"" already present on machine"
0.5851,Event,ADDED,eval-sanitize-30-r1-178-knk4t.18d4f7dc5a25b9bd,reason=Created count=1 msg=Created container: task
0.5854,Event,ADDED,eval-sanitize-30-r1-178-knk4t.18d4f7dc6223ca05,reason=Started count=1 msg=Started container task
0.5857,Event,ADDED,eval-sanitize-30-r1-178.18d4f7dc345bb798,reason=SuccessfulCreate count=1 msg=Created pod: eval-sanitize-30-r1-178-knk4t
0.5859,Event,ADDED,eval-sanitize-30-r1-178.18d4f7e1ed4ff8c6,reason=Completed count=1 msg=Job completed
0.5862,Event,ADDED,eval-sanitize-30-r1-179-fp4p2.18d4f7dcb2723055,"reason=FailedScheduling count=None msg=0/6 nodes are available: 1 c_wall violated: 3 conflicting context pair(s) with node memory, 2 node(s) had untolerated taint(s), 3 c_wall violated: 2 conflicting context pair(s) with node memory. no new claims to deallocate, preemption: 0/6 nodes are available: 2 Preemption is not helpful for scheduling, 4 No preemption victims found for incoming pod."
0.5865,Event,ADDED,eval-sanitize-30-r1-179-fp4p2.18d4f7dd005ec8e0,"reason=FailedScheduling count=None msg=0/6 nodes are available: 1 c_wall violated: 3 conflicting context pair(s) with node memory, 2 node(s) had untolerated taint(s), 3 c_wall violated: 2 conflicting context pair(s) with node memory. no new claims to deallocate, preemption: 0/6 nodes are available: 2 Preemption is not helpful for scheduling, 4 No preemption victims found for incoming pod."
0.5869,Event,ADDED,eval-sanitize-30-r1-179-fp4p2.18d4f7dd773091a0,"reason=FailedScheduling count=None msg=0/6 nodes are available: 1 c_wall violated: 2 conflicting context pair(s) with node memory, 1 c_wall violated: 3 conflicting context pair(s) with node memory, 4 node(s) had untolerated taint(s). no new claims to deallocate, preemption: 0/6 nodes are available: 2 No preemption victims found for incoming pod, 4 Preemption is not helpful for scheduling."
0.5873,Event,ADDED,eval-sanitize-30-r1-179-fp4p2.18d4f7dd94b0afa6,"reason=FailedScheduling count=None msg=0/6 nodes are available: 1 c_wall violated: 2 conflicting context pair(s) with node memory, 1 c_wall violated: 3 conflicting context pair(s) with node memory, 4 node(s) had untolerated taint(s). no new claims to deallocate, preemption: 0/6 nodes are available: 2 No preemption victims found for incoming pod, 4 Preemption is not helpful for scheduling."
0.5875,Event,ADDED,eval-sanitize-30-r1-179-fp4p2.18d4f7ddbfa2f7cd,reason=Scheduled count=None msg=Successfully assigned compute/eval-sanitize-30-r1-179-fp4p2 to kind-worker3
0.5877,Event,ADDED,eval-sanitize-30-r1-179-fp4p2.18d4f7dddccf8af7,"reason=Pulled count=1 msg=Container image ""busybox:musl"" already present on machine"
0.5879,Event,ADDED,eval-sanitize-30-r1-179-fp4p2.18d4f7ddde896f9a,reason=Created count=1 msg=Created container: task
0.5881,Event,ADDED,eval-sanitize-30-r1-179-fp4p2.18d4f7dde1933618,reason=Started count=1 msg=Started container task
0.5883,Event,ADDED,eval-sanitize-30-r1-179.18d4f7dcab81519f,reason=SuccessfulCreate count=1 msg=Created pod: eval-sanitize-30-r1-179-fp4p2
0.5884,Event,ADDED,eval-sanitize-30-r1-179.18d4f7e32ea98005,reason=Completed count=1 msg=Job completed
0.5888,Event,ADDED,eval-sanitize-30-r1-180-hbgzd.18d4f7dcd68ce05b,reason=Scheduled count=None msg=Successfully assigned compute/eval-sanitize-30-r1-180-hbgzd to kind-worker4
0.589,Event,ADDED,eval-sanitize-30-r1-180-hbgzd.18d4f7dcf7d60979,"reason=Pulled count=1 msg=Container image ""busybox:musl"" already present on machine"
0.5892,Event,ADDED,eval-sanitize-30-r1-180-hbgzd.18d4f7dcf972ac0c,reason=Created count=1 msg=Created container: task
0.5894,Event,ADDED,eval-sanitize-30-r1-180-hbgzd.18d4f7dd006232d5,reason=Started count=1 msg=Started container task
0.5898,Event,ADDED,eval-sanitize-30-r1-180.18d4f7dccfcd4859,reason=SuccessfulCreate count=1 msg=Created pod: eval-sanitize-30-r1-180-hbgzd
0.59,Event,ADDED,eval-sanitize-30-r1-180.18d4f7e268db3281,reason=Completed count=1 msg=Job completed
0.5902,Event,ADDED,eval-sanitize-30-r1-181-t4crs.18d4f7dd201e6a4e,reason=Scheduled count=None msg=Successfully assigned compute/eval-sanitize-30-r1-181-t4crs to kind-worker4
0.5904,Event,ADDED,eval-sanitize-30-r1-181-t4crs.18d4f7dd3ad796fa,"reason=Pulled count=1 msg=Container image ""busybox:musl"" already present on machine"
0.5908,Event,ADDED,eval-sanitize-30-r1-181-t4crs.18d4f7dd3ce5b602,reason=Created count=1 msg=Created container: task
0.5911,Event,ADDED,eval-sanitize-30-r1-181-t4crs.18d4f7dd4200b552,reason=Started count=1 msg=Started container task
0.5915,Event,ADDED,eval-sanitize-30-r1-181.18d4f7dd17f15a33,reason=SuccessfulCreate count=1 msg=Created pod: eval-sanitize-30-r1-181-t4crs
0.5918,Event,ADDED,eval-sanitize-30-r1-181.18d4f7e2a4ceeb2e,reason=Completed count=1 msg=Job completed
0.5921,Event,ADDED,eval-sanitize-30-r1-182-9nxd4.18d4f7dd4df59c59,reason=Scheduled count=None msg=Successfully assigned compute/eval-sanitize-30-r1-182-9nxd4 to kind-worker5
0.5923,Event,ADDED,eval-sanitize-30-r1-182-9nxd4.18d4f7dd6860de8d,"reason=Pulled count=1 msg=Container image ""busybox:musl"" already present on machine"
0.5926,Event,ADDED,eval-sanitize-30-r1-182-9nxd4.18d4f7dd69d2316a,reason=Created count=1 msg=Created container: task
0.5931,Event,ADDED,eval-sanitize-30-r1-182-9nxd4.18d4f7dd6ef4c690,reason=Started count=1 msg=Started container task
0.5934,Event,ADDED,eval-sanitize-30-r1-182.18d4f7dd437e9d62,reason=SuccessfulCreate count=1 msg=Created pod: eval-sanitize-30-r1-182-9nxd4
0.5937,Event,ADDED,eval-sanitize-30-r1-182.18d4f7e2f7ea7ed2,reason=Completed count=1 msg=Job completed
0.5939,Event,ADDED,eval-sanitize-30-r1-183-fflr6.18d4f7dd83b929a0,"reason=FailedScheduling count=None msg=0/6 nodes are available: 1 c_wall violated: 2 conflicting context pair(s) with node memory, 1 c_wall violated: 3 conflicting context pair(s) with node memory, 4 node(s) had untolerated taint(s). no new claims to deallocate, preemption: 0/6 nodes are available: 2 No preemption victims found for incoming pod, 4 Preemption is not helpful for scheduling."
0.5942,Event,ADDED,eval-sanitize-30-r1-183-fflr6.18d4f7dda141272b,"reason=FailedScheduling count=None msg=0/6 nodes are available: 1 c_wall violated: 2 conflicting context pair(s) with node memory, 1 c_wall violated: 3 conflicting context pair(s) with node memory, 4 node(s) had untolerated taint(s). no new claims to deallocate, preemption: 0/6 nodes are available: 2 No preemption victims found for incoming pod, 4 Preemption is not helpful for scheduling."
0.5944,Event,ADDED,eval-sanitize-30-r1-183-fflr6.18d4f7dde2d68afd,reason=Scheduled count=None msg=Successfully assigned compute/eval-sanitize-30-r1-183-fflr6 to kind-worker3
0.5945,Event,ADDED,eval-sanitize-30-r1-183-fflr6.18d4f7ddfe61c56b,"reason=Pulled count=1 msg=Container image ""busybox:musl"" already present on machine"
0.601,Event,ADDED,eval-sanitize-30-r1-183-fflr6.18d4f7ddffebaec9,reason=Created count=1 msg=Created container: task
0.6012,Event,ADDED,eval-sanitize-30-r1-183-fflr6.18d4f7de03b888a3,reason=Started count=1 msg=Started container task
0.6015,Event,ADDED,eval-sanitize-30-r1-183.18d4f7dd7f06a867,reason=SuccessfulCreate count=1 msg=Created pod: eval-sanitize-30-r1-183-fflr6
0.6017,Event,ADDED,eval-sanitize-30-r1-183.18d4f7e36d73b4b1,reason=Completed count=1 msg=Job completed
0.602,Event,ADDED,eval-sanitize-30-r1-184-44lrx.18d4f7ddb79a4b4b,"reason=FailedScheduling count=None msg=0/6 nodes are available: 1 c_wall violated: 1 conflicting context pair(s) with node memory, 2 c_wall violated: 2 conflicting context pair(s) with node memory, 3 node(s) had untolerated taint(s). no new claims to deallocate, preemption: 0/6 nodes are available: 3 No preemption victims found for incoming pod, 3 Preemption is not helpful for scheduling."
0.6023,Event,ADDED,eval-sanitize-30-r1-184-44lrx.18d4f7dde91d5356,"reason=FailedScheduling count=None msg=0/6 nodes are available: 1 c_wall violated: 1 conflicting context pair(s) with node memory, 2 c_wall violated: 2 conflicting context pair(s) with node memory, 3 node(s) had untolerated taint(s). no new claims to deallocate, preemption: 0/6 nodes are available: 3 No preemption victims found for incoming pod, 3 Preemption is not helpful for scheduling."
0.6028,Event,ADDED,eval-sanitize-30-r1-184-44lrx.18d4f7ddfa5ae1c5,"reason=FailedScheduling count=None msg=0/6 nodes are available: 1 c_wall violated: 1 conflicting context pair(s) with node memory, 1 c_wall violated: 2 conflicting context pair(s) with node memory, 4 node(s) had untolerated taint(s). no new claims to deallocate, preemption: 0/6 nodes are available: 2 No preemption victims found for incoming pod, 4 Preemption is not helpful for scheduling."
0.603,Event,ADDED,eval-sanitize-30-r1-184-44lrx.18d4f7de0e2bb016,"reason=FailedScheduling count=None msg=0/6 nodes are available: 1 c_wall violated: 2 conflicting context pair(s) with node memory, 5 node(s) had untolerated taint(s). no new claims to deallocate, preemption: 0/6 nodes are available: 1 No preemption victims found for incoming pod, 5 Preemption is not helpful for scheduling."
0.6032,Event,ADDED,eval-sanitize-30-r1-184-44lrx.18d4f7e46843fa95,reason=Scheduled count=None msg=Successfully assigned compute/eval-sanitize-30-r1-184-44lrx to kind-worker
0.6034,Event,ADDED,eval-sanitize-30-r1-184-44lrx.18d4f7e4846020fd,"reason=Pulled count=1 msg=Container image ""busybox:musl"" already present on machine"
0.6038,Event,ADDED,eval-sanitize-30-r1-184-44lrx.18d4f7e485ec4c7a,reason=Created count=1 msg=Created container: task
0.6041,Event,ADDED,eval-sanitize-30-r1-184-44lrx.18d4f7e48aba4985,reason=Started count=1 msg=Started container task
0.6043,Event,ADDED,eval-sanitize-30-r1-184.18d4f7ddaf5c5d39,reason=SuccessfulCreate count=1 msg=Created pod: eval-sanitize-30-r1-184-44lrx
0.6047,Event,ADDED,eval-sanitize-30-r1-184.18d4f7ea221f8296,reason=Completed count=1 msg=Job completed
0.6048,Event,ADDED,eval-sanitize-30-r1-185-dpzck.18d4f7dddd246aa3,reason=Scheduled count=None msg=Successfully assigned compute/eval-sanitize-30-r1-185-dpzck to kind-worker3
0.605,Event,ADDED,eval-sanitize-30-r1-185-dpzck.18d4f7ddf802abda,"reason=Pulled count=1 msg=Container image ""busybox:musl"" already present on machine"
0.6052,Event,ADDED,eval-sanitize-30-r1-185-dpzck.18d4f7ddf9ae87dc,reason=Created count=1 msg=Created container: task
0.6056,Event,ADDED,eval-sanitize-30-r1-185-dpzck.18d4f7ddfd0a729c,reason=Started count=1 msg=Started container task
0.6058,Event,ADDED,eval-sanitize-30-r1-185.18d4f7ddd2c0087d,reason=SuccessfulCreate count=1 msg=Created pod: eval-sanitize-30-r1-185-dpzck
0.606,Event,ADDED,eval-sanitize-30-r1-185.18d4f7e3a8640ade,reason=Completed count=1 msg=Job completed
0.6065,Event,ADDED,eval-sanitize-30-r1-186-fwphb.18d4f7ddf54a0859,"reason=FailedScheduling count=None msg=0/6 nodes are available: 1 c_wall violated: 1 conflicting context pair(s) with node memory, 1 c_wall violated: 3 conflicting context pair(s) with node memory, 4 node(s) had untolerated taint(s). no new claims to deallocate, preemption: 0/6 nodes are available: 2 No preemption victims found for incoming pod, 4 Preemption is not helpful for scheduling."
0.6069,Event,ADDED,eval-sanitize-30-r1-186-fwphb.18d4f7ddfae74d53,"reason=FailedScheduling count=None msg=0/6 nodes are available: 1 c_wall violated: 1 conflicting context pair(s) with node memory, 1 c_wall violated: 3 conflicting context pair(s) with node memory, 4 node(s) had untolerated taint(s). no new claims to deallocate, preemption: 0/6 nodes are available: 2 No preemption victims found for incoming pod, 4 Preemption is not helpful for scheduling."
0.6072,Event,ADDED,eval-sanitize-30-r1-186-fwphb.18d4f7de0e6cefc7,"reason=FailedScheduling count=None msg=0/6 nodes are available: 1 c_wall violated: 1 conflicting context pair(s) with node memory, 5 node(s) had untolerated taint(s). no new claims to deallocate, preemption: 0/6 nodes are available: 1 No preemption victims found for incoming pod, 5 Preemption is not helpful for scheduling."
0.6076,Event,ADDED,eval-sanitize-30-r1-186-fwphb.18d4f7e472585017,"reason=FailedScheduling count=None msg=0/6 nodes are available: 1 c_wall violated: 1 conflicting context pair(s) with node memory, 1 c_wall violated: 3 conflicting context pair(s) with node memory, 4 node(s) had untolerated taint(s). no new claims to deallocate, preemption: 0/6 nodes are available: 2 No preemption victims found for incoming pod, 4 Preemption is not helpful for scheduling."
0.6079,Event,ADDED,eval-sanitize-30-r1-186-fwphb.18d4f7e47ede200b,"reason=FailedScheduling count=None msg=0/6 nodes are available: 1 c_wall violated: 1 conflicting context pair(s) with node memory, 1 c_wall violated: 3 conflicting context pair(s) with node memory, 4 node(s) had untolerated taint(s). no new claims to deallocate, preemption: 0/6 nodes are available: 2 No preemption victims found for incoming pod, 4 Preemption is not helpful for scheduling."
0.6082,Event,ADDED,eval-sanitize-30-r1-186-fwphb.18d4f7e49d31c196,"reason=FailedScheduling count=None msg=0/6 nodes are available: 1 c_wall violated: 3 conflicting context pair(s) with node memory, 2 c_wall violated: 1 conflicting context pair(s) with node memory, 3 node(s) had untolerated taint(s). no new claims to deallocate, preemption: 0/6 nodes are available: 3 No preemption victims found for incoming pod, 3 Preemption is not helpful for scheduling."
0.6086,Event,ADDED,eval-sanitize-30-r1-186-fwphb.18d4f7e4b3ae0935,"reason=FailedScheduling count=None msg=0/6 nodes are available: 1 c_wall violated: 1 conflicting context pair(s) with node memory, 1 c_wall violated: 3 conflicting context pair(s) with node memory, 4 node(s) had untolerated taint(s). no new claims to deallocate, preemption: 0/6 nodes are available: 2 No preemption victims found for incoming pod, 4 Preemption is not helpful for scheduling."
0.6088,Event,ADDED,eval-sanitize-30-r1-186-fwphb.18d4f7e515089345,reason=Scheduled count=None msg=Successfully assigned compute/eval-sanitize-30-r1-186-fwphb to kind-worker5
0.6091,Event,ADDED,eval-sanitize-30-r1-186-fwphb.18d4f7e53175453c,"reason=Pulled count=1 msg=Container image ""busybox:musl"" already present on machine"
0.6096,Event,ADDED,eval-sanitize-30-r1-186-fwphb.18d4f7e532e8f87d,reason=Created count=1 msg=Created container: task
0.6101,Event,ADDED,eval-sanitize-30-r1-186-fwphb.18d4f7e539696d6f,reason=Started count=1 msg=Started container task
0.6106,Event,ADDED,eval-sanitize-30-r1-186.18d4f7ddf065ff51,reason=SuccessfulCreate count=1 msg=Created pod: eval-sanitize-30-r1-186-fwphb
0.611,Event,ADDED,eval-sanitize-30-r1-186.18d4f7eaaad88f6f,reason=Completed count=1 msg=Job completed
0.6113,Event,ADDED,eval-sanitize-30-r1-187-7gwbz.18d4f7de2845c78e,reason=Scheduled count=None msg=Successfully assigned compute/eval-sanitize-30-r1-187-7gwbz to kind-worker3
0.6116,Event,ADDED,eval-sanitize-30-r1-187-7gwbz.18d4f7de5eb914d7,"reason=Pulled count=1 msg=Container image ""busybox:musl"" already present on machine"
0.6119,Event,ADDED,eval-sanitize-30-r1-187-7gwbz.18d4f7de606e865d,reason=Created count=1 msg=Created container: task
0.6121,Event,ADDED,eval-sanitize-30-r1-187-7gwbz.18d4f7de68fd63fa,reason=Started count=1 msg=Started container task
0.6124,Event,ADDED,eval-sanitize-30-r1-187.18d4f7de2798e883,reason=SuccessfulCreate count=1 msg=Created pod: eval-sanitize-30-r1-187-7gwbz
0.6126,Event,ADDED,eval-sanitize-30-r1-187.18d4f7e3e562ed73,reason=Completed count=1 msg=Job completed
0.6129,Event,ADDED,eval-sanitize-30-r1-188-tmz9x.18d4f7de5f047d6f,"reason=FailedScheduling count=None msg=0/6 nodes are available: 1 c_wall violated: 1 conflicting context pair(s) with node memory, 5 node(s) had untolerated taint(s). no new claims to deallocate, preemption: 0/6 nodes are available: 1 No preemption victims found for incoming pod, 5 Preemption is not helpful for scheduling."
0.6133,Event,ADDED,eval-sanitize-30-r1-188-tmz9x.18d4f7de5fb707c2,"reason=FailedScheduling count=None msg=0/6 nodes are available: 1 c_wall violated: 1 conflicting context pair(s) with node memory, 5 node(s) had untolerated taint(s). no new claims to deallocate, preemption: 0/6 nodes are available: 1 No preemption victims found for incoming pod, 5 Preemption is not helpful for scheduling."
0.6137,Event,ADDED,eval-sanitize-30-r1-188-tmz9x.18d4f7e45ca4f8e3,reason=Scheduled count=None msg=Successfully assigned compute/eval-sanitize-30-r1-188-tmz9x to kind-worker
0.614,Event,ADDED,eval-sanitize-30-r1-188-tmz9x.18d4f7e4787f64a0,"reason=Pulled count=1 msg=Container image ""busybox:musl"" already present on machine"
0.6144,Event,ADDED,eval-sanitize-30-r1-188-tmz9x.18d4f7e47a2f525c,reason=Created count=1 msg=Created container: task
0.6149,Event,ADDED,eval-sanitize-30-r1-188-tmz9x.18d4f7e47ebf91c5,reason=Started count=1 msg=Started container task
0.6153,Event,ADDED,eval-sanitize-30-r1-188.18d4f7de5eb7aa14,reason=SuccessfulCreate count=1 msg=Created pod: eval-sanitize-30-r1-188-tmz9x
0.6156,Event,ADDED,eval-sanitize-30-r1-188.18d4f7e9a7bfed99,reason=Completed count=1 msg=Job completed
0.6159,Event,ADDED,eval-sanitize-30-r1-189-lhpdw.18d4f7de88472bb8,"reason=FailedScheduling count=None msg=0/6 nodes are available: 1 c_wall violated: 1 conflicting context pair(s) with node memory, 5 node(s) had untolerated taint(s). no new claims to deallocate, preemption: 0/6 nodes are available: 1 No preemption victims found for incoming pod, 5 Preemption is not helpful for scheduling."
0.6163,Event,ADDED,eval-sanitize-30-r1-189-lhpdw.18d4f7de8a3ca0ef,"reason=FailedScheduling count=None msg=0/6 nodes are available: 1 c_wall violated: 1 conflicting context pair(s) with node memory, 5 node(s) had untolerated taint(s). no new claims to deallocate, preemption: 0/6 nodes are available: 1 No preemption victims found for incoming pod, 5 Preemption is not helpful for scheduling."
0.6165,Event,ADDED,eval-sanitize-30-r1-189-lhpdw.18d4f7e473946ddc,"reason=FailedScheduling count=None msg=0/6 nodes are available: 1 c_wall violated: 1 conflicting context pair(s) with node memory, 1 c_wall violated: 3 conflicting context pair(s) with node memory, 4 node(s) had untolerated taint(s). no new claims to deallocate, preemption: 0/6 nodes are available: 2 No preemption victims found for incoming pod, 4 Preemption is not helpful for scheduling."
0.6169,Event,ADDED,eval-sanitize-30-r1-189-lhpdw.18d4f7e47f6e2a40,"reason=FailedScheduling count=None msg=0/6 nodes are available: 1 c_wall violated: 1 conflicting context pair(s) with node memory, 1 c_wall violated: 3 conflicting context pair(s) with node memory, 4 node(s) had untolerated taint(s). no new claims to deallocate, preemption: 0/6 nodes are available: 2 No preemption victims found for incoming pod, 4 Preemption is not helpful for scheduling."
0.6172,Event,ADDED,eval-sanitize-30-r1-189-lhpdw.18d4f7e4a3081936,"reason=FailedScheduling count=None msg=0/6 nodes are available: 1 c_wall violated: 3 conflicting context pair(s) with node memory, 2 c_wall violated: 1 conflicting context pair(s) with node memory, 3 node(s) had untolerated taint(s). no new claims to deallocate, preemption: 0/6 nodes are available: 3 No preemption victims found for incoming pod, 3 Preemption is not helpful for scheduling."
0.6174,Event,ADDED,eval-sanitize-30-r1-189-lhpdw.18d4f7e4b49bb45d,"reason=FailedScheduling count=None msg=0/6 nodes are available: 1 c_wall violated: 1 conflicting context pair(s) with node memory, 1 c_wall violated: 3 conflicting context pair(s) with node memory, 4 node(s) had untolerated taint(s). no new claims to deallocate, preemption: 0/6 nodes are available: 2 No preemption victims found for incoming pod, 4 Preemption is not helpful for scheduling."
0.6178,Event,ADDED,eval-sanitize-30-r1-189-lhpdw.18d4f7e508dc83fa,reason=Scheduled count=None msg=Successfully assigned compute/eval-sanitize-30-r1-189-lhpdw to kind-worker5
0.618,Event,ADDED,eval-sanitize-30-r1-189-lhpdw.18d4f7e5245ee4c7,"reason=Pulled count=1 msg=Container image ""busybox:musl"" already present on machine"
0.6182,Event,ADDED,eval-sanitize-30-r1-189-lhpdw.18d4f7e52624635a,reason=Created count=1 msg=Created container: task
0.6186,Event,ADDED,eval-sanitize-30-r1-189-lhpdw.18d4f7e52b5486b8,reason=Started count=1 msg=Started container task
0.6188,Event,ADDED,eval-sanitize-30-r1-189.18d4f7de87f9ac2d,reason=SuccessfulCreate count=1 msg=Created pod: eval-sanitize-30-r1-189-lhpdw
0.619,Event,ADDED,eval-sanitize-30-r1-189.18d4f7eaab21dde6,reason=Completed count=1 msg=Job completed
0.6192,Event,ADDED,eval-sanitize-30-r1-190-hcs5z.18d4f7dec49ff9e3,"reason=FailedScheduling count=None msg=0/6 nodes are available: 1 c_wall violated: 1 conflicting context pair(s) with node memory, 5 node(s) had untolerated taint(s). no new claims to deallocate, preemption: 0/6 nodes are available: 1 No preemption victims found for incoming pod, 5 Preemption is not helpful for scheduling."
0.6197,Event,ADDED,eval-sanitize-30-r1-190-hcs5z.18d4f7dec556200c,"reason=FailedScheduling count=None msg=0/6 nodes are available: 1 c_wall violated: 1 conflicting context pair(s) with node memory, 5 node(s) had untolerated taint(s). no new claims to deallocate, preemption: 0/6 nodes are available: 1 No preemption victims found for incoming pod, 5 Preemption is not helpful for scheduling."
0.6201,Event,ADDED,eval-sanitize-30-r1-190-hcs5z.18d4f7e478f04a0d,"reason=FailedScheduling count=None msg=0/6 nodes are available: 1 c_wall violated: 1 conflicting context pair(s) with node memory, 1 c_wall violated: 3 conflicting context pair(s) with node memory, 4 node(s) had untolerated taint(s). no new claims to deallocate, preemption: 0/6 nodes are available: 2 No preemption victims found for incoming pod, 4 Preemption is not helpful for scheduling."
0.6207,Event,ADDED,eval-sanitize-30-r1-190-hcs5z.18d4f7e48425951e,"reason=FailedScheduling count=None msg=0/6 nodes are available: 1 c_wall violated: 1 conflicting context pair(s) with node memory, 1 c_wall violated: 3 conflicting context pair(s) with node memory, 4 node(s) had untolerated taint(s). no new claims to deallocate, preemption: 0/6 nodes are available: 2 No preemption victims found for incoming pod, 4 Preemption is not helpful for scheduling."
0.6211,Event,ADDED,eval-sanitize-30-r1-190-hcs5z.18d4f7e4a7f54405,"reason=FailedScheduling count=None msg=0/6 nodes are available: 1 c_wall violated: 1 conflicting context pair(s) with node memory, 1 c_wall violated: 3 conflicting context pair(s) with node memory, 4 node(s) had untolerated taint(s). no new claims to deallocate, preemption: 0/6 nodes are available: 2 No preemption victims found for incoming pod, 4 Preemption is not helpful for scheduling."
0.6216,Event,ADDED,eval-sanitize-30-r1-190-hcs5z.18d4f7e4aef7047b,"reason=FailedScheduling count=None msg=0/6 nodes are available: 1 c_wall violated: 1 conflicting context pair(s) with node memory, 1 c_wall violated: 3 conflicting context pair(s) with node memory, 4 node(s) had untolerated taint(s). no new claims to deallocate, preemption: 0/6 nodes are available: 2 No preemption victims found for incoming pod, 4 Preemption is not helpful for scheduling."
0.622,Event,ADDED,eval-sanitize-30-r1-190-hcs5z.18d4f7e5104ef137,reason=Scheduled count=None msg=Successfully assigned compute/eval-sanitize-30-r1-190-hcs5z to kind-worker5
0.6225,Event,ADDED,eval-sanitize-30-r1-190-hcs5z.18d4f7e52c36dd1d,"reason=Pulled count=1 msg=Container image ""busybox:musl"" already present on machine"
0.6231,Event,ADDED,eval-sanitize-30-r1-190-hcs5z.18d4f7e52d8179a6,reason=Created count=1 msg=Created container: task
0.6234,Event,ADDED,eval-sanitize-30-r1-190-hcs5z.18d4f7e531a20c3f,reason=Started count=1 msg=Started container task
0.6238,Event,ADDED,eval-sanitize-30-r1-190.18d4f7dec3ead37e,reason=SuccessfulCreate count=1 msg=Created pod: eval-sanitize-30-r1-190-hcs5z
0.624,Event,ADDED,eval-sanitize-30-r1-190.18d4f7eaab4e2556,reason=Completed count=1 msg=Job completed
0.6241,Event,ADDED,eval-sanitize-30-r1-191-p5dz6.18d4f7df008079ae,"reason=FailedScheduling count=None msg=0/6 nodes are available: 1 c_wall violated: 2 conflicting context pair(s) with node memory, 5 node(s) had untolerated taint(s). no new claims to deallocate, preemption: 0/6 nodes are available: 1 No preemption victims found for incoming pod, 5 Preemption is not helpful for scheduling."
0.6245,Event,ADDED,eval-sanitize-30-r1-191-p5dz6.18d4f7df01385c10,"reason=FailedScheduling count=None msg=0/6 nodes are available: 1 c_wall violated: 2 conflicting context pair(s) with node memory, 5 node(s) had untolerated taint(s). no new claims to deallocate, preemption: 0/6 nodes are available: 1 No preemption victims found for incoming pod, 5 Preemption is not helpful for scheduling."
0.6246,Event,ADDED,eval-sanitize-30-r1-191-p5dz6.18d4f7e46ca2256a,reason=Scheduled count=None msg=Successfully assigned compute/eval-sanitize-30-r1-191-p5dz6 to kind-worker
0.6248,Event,ADDED,eval-sanitize-30-r1-191-p5dz6.18d4f7e48b9648e0,"reason=Pulled count=1 msg=Container image ""busybox:musl"" already present on machine"
0.625,Event,ADDED,eval-sanitize-30-r1-191-p5dz6.18d4f7e48d0c5585,reason=Created count=1 msg=Created container: task
0.6252,Event,ADDED,eval-sanitize-30-r1-191-p5dz6.18d4f7e49586eb55,reason=Started count=1 msg=Started container task
0.6256,Event,ADDED,eval-sanitize-30-r1-191.18d4f7deff7a8493,reason=SuccessfulCreate count=1 msg=Created pod: eval-sanitize-30-r1-191-p5dz6
0.6259,Event,ADDED,eval-sanitize-30-r1-191.18d4f7ea222246f7,reason=Completed count=1 msg=Job completed
0.6262,Event,ADDED,eval-sanitize-30-r1-192-2d6r4.18d4f7df4b58a4b1,reason=Scheduled count=None msg=Successfully assigned compute/eval-sanitize-30-r1-192-2d6r4 to kind-worker3
0.6265,Event,ADDED,eval-sanitize-30-r1-192-2d6r4.18d4f7df6b280a38,"reason=Pulled count=1 msg=Container image ""busybox:musl"" already present on machine"
0.6268,Event,ADDED,eval-sanitize-30-r1-192-2d6r4.18d4f7df6d35ecd6,reason=Created count=1 msg=Created container: task
0.627,Event,ADDED,eval-sanitize-30-r1-192-2d6r4.18d4f7df77600827,reason=Started count=1 msg=Started container task
0.6274,Event,ADDED,eval-sanitize-30-r1-192.18d4f7df3ab9de02,reason=SuccessfulCreate count=1 msg=Created pod: eval-sanitize-30-r1-192-2d6r4
0.6276,Event,ADDED,eval-sanitize-30-r1-192.18d4f7e50add81ed,reason=Completed count=1 msg=Job completed
0.6278,Event,ADDED,eval-sanitize-30-r1-193-4rrcg.18d4f7df7a7a30d6,"reason=FailedScheduling count=None msg=0/6 nodes are available: 1 c_wall violated: 2 conflicting context pair(s) with node memory, 5 node(s) had untolerated taint(s). no new claims to deallocate, preemption: 0/6 nodes are available: 1 No preemption victims found for incoming pod, 5 Preemption is not helpful for scheduling."
0.628,Event,ADDED,eval-sanitize-30-r1-193-4rrcg.18d4f7df7b19f249,"reason=FailedScheduling count=None msg=0/6 nodes are available: 1 c_wall violated: 2 conflicting context pair(s) with node memory, 5 node(s) had untolerated taint(s). no new claims to deallocate, preemption: 0/6 nodes are available: 1 No preemption victims found for incoming pod, 5 Preemption is not helpful for scheduling."
0.6283,Event,ADDED,eval-sanitize-30-r1-193-4rrcg.18d4f7e479e65a04,"reason=FailedScheduling count=None msg=0/6 nodes are available: 2 c_wall violated: 2 conflicting context pair(s) with node memory, 4 node(s) had untolerated taint(s). no new claims to deallocate, preemption: 0/6 nodes are available: 2 No preemption victims found for incoming pod, 4 Preemption is not helpful for scheduling."
0.6285,Event,ADDED,eval-sanitize-30-r1-193-4rrcg.18d4f7e485c02b9b,reason=Scheduled count=None msg=Successfully assigned compute/eval-sanitize-30-r1-193-4rrcg to kind-worker4
0.6287,Event,ADDED,eval-sanitize-30-r1-193-4rrcg.18d4f7e4a46f6496,"reason=Pulled count=1 msg=Container image ""busybox:musl"" already present on machine"
0.629,Event,ADDED,eval-sanitize-30-r1-193-4rrcg.18d4f7e4a634148f,reason=Created count=1 msg=Created container: task
0.6292,Event,ADDED,eval-sanitize-30-r1-193-4rrcg.18d4f7e4abc6fc0e,reason=Started count=1 msg=Started container task
0.6294,Event,ADDED,eval-sanitize-30-r1-193.18d4f7df7a2e84c4,reason=SuccessfulCreate count=1 msg=Created pod: eval-sanitize-30-r1-193-4rrcg
0.6296,Event,ADDED,eval-sanitize-30-r1-193.18d4f7ea22862ede,reason=Completed count=1 msg=Job completed
0.6299,Event,ADDED,eval-sanitize-30-r1-194-d4zc7.18d4f7dfb2547261,"reason=FailedScheduling count=None msg=0/6 nodes are available: 1 c_wall violated: 1 conflicting context pair(s) with node memory, 5 node(s) had untolerated taint(s). no new claims to deallocate, preemption: 0/6 nodes are available: 1 No preemption victims found for incoming pod, 5 Preemption is not helpful for scheduling."
0.6301,Event,ADDED,eval-sanitize-30-r1-194-d4zc7.18d4f7dfb3056ae1,"reason=FailedScheduling count=None msg=0/6 nodes are available: 1 c_wall violated: 1 conflicting context pair(s) with node memory, 5 node(s) had untolerated taint(s). no new claims to deallocate, preemption: 0/6 nodes are available: 1 No preemption victims found for incoming pod, 5 Preemption is not helpful for scheduling."
0.6302,Event,ADDED,eval-sanitize-30-r1-194-d4zc7.18d4f7e461a08e54,reason=Scheduled count=None msg=Successfully assigned compute/eval-sanitize-30-r1-194-d4zc7 to kind-worker
0.6306,Event,ADDED,eval-sanitize-30-r1-194-d4zc7.18d4f7e47aa40dca,"reason=Pulled count=1 msg=Container image ""busybox:musl"" already present on machine"
0.6308,Event,ADDED,eval-sanitize-30-r1-194-d4zc7.18d4f7e47c2476d1,reason=Created count=1 msg=Created container: task
0.6312,Event,ADDED,eval-sanitize-30-r1-194-d4zc7.18d4f7e47f4d46e4,reason=Started count=1 msg=Started container task
0.6317,Event,ADDED,eval-sanitize-30-r1-194.18d4f7dfb1f7c8cc,reason=SuccessfulCreate count=1 msg=Created pod: eval-sanitize-30-r1-194-d4zc7
0.6323,Event,ADDED,eval-sanitize-30-r1-194.18d4f7ea2286d9e0,reason=Completed count=1 msg=Job completed
0.6325,Event,ADDED,eval-sanitize-30-r1-195-f889f.18d4f7dfee4f6b41,reason=Scheduled count=None msg=Successfully assigned compute/eval-sanitize-30-r1-195-f889f to kind-worker3
0.6327,Event,ADDED,eval-sanitize-30-r1-195-f889f.18d4f7e0099dd6ef,"reason=Pulled count=1 msg=Container image ""busybox:musl"" already present on machine"
0.633,Event,ADDED,eval-sanitize-30-r1-195-f889f.18d4f7e00af2d1c3,reason=Created count=1 msg=Created container: task
0.6333,Event,ADDED,eval-sanitize-30-r1-195-f889f.18d4f7e010c9ac1e,reason=Started count=1 msg=Started container task
0.6336,Event,ADDED,eval-sanitize-30-r1-195.18d4f7dfed905fc9,reason=SuccessfulCreate count=1 msg=Created pod: eval-sanitize-30-r1-195-f889f
0.6338,Event,ADDED,eval-sanitize-30-r1-195.18d4f7e585b452ca,reason=Completed count=1 msg=Job completed
0.6342,Event,ADDED,eval-sanitize-30-r1-196-8mgv6.18d4f7e029f046a2,"reason=FailedScheduling count=None msg=0/6 nodes are available: 1 c_wall violated: 2 conflicting context pair(s) with node memory, 5 node(s) had untolerated taint(s). no new claims to deallocate, preemption: 0/6 nodes are available: 1 No preemption victims found for incoming pod, 5 Preemption is not helpful for scheduling."
0.6346,Event,ADDED,eval-sanitize-30-r1-196-8mgv6.18d4f7e02a93296d,"reason=FailedScheduling count=None msg=0/6 nodes are available: 1 c_wall violated: 2 conflicting context pair(s) with node memory, 5 node(s) had untolerated taint(s). no new claims to deallocate, preemption: 0/6 nodes are available: 1 No preemption victims found for incoming pod, 5 Preemption is not helpful for scheduling."
0.635,Event,ADDED,eval-sanitize-30-r1-196-8mgv6.18d4f7e46daeeaf2,reason=Scheduled count=None msg=Successfully assigned compute/eval-sanitize-30-r1-196-8mgv6 to kind-worker
0.6353,Event,ADDED,eval-sanitize-30-r1-196-8mgv6.18d4f7e48a6f8889,"reason=Pulled count=1 msg=Container image ""busybox:musl"" already present on machine"
0.6357,Event,ADDED,eval-sanitize-30-r1-196-8mgv6.18d4f7e48c484e7d,reason=Created count=1 msg=Created container: task
0.6359,Event,ADDED,eval-sanitize-30-r1-196-8mgv6.18d4f7e4985c6e10,reason=Started count=1 msg=Started container task
0.6361,Event,ADDED,eval-sanitize-30-r1-196.18d4f7e0299a1f0c,reason=SuccessfulCreate count=1 msg=Created pod: eval-sanitize-30-r1-196-8mgv6
0.6364,Event,ADDED,eval-sanitize-30-r1-196.18d4f7ea222348c2,reason=Completed count=1 msg=Job completed
0.6366,Event,ADDED,eval-sanitize-30-r1-197-rbs5j.18d4f7e06560e8c7,"reason=FailedScheduling count=None msg=0/6 nodes are available: 1 c_wall violated: 1 conflicting context pair(s) with node memory, 5 node(s) had untolerated taint(s). no new claims to deallocate, preemption: 0/6 nodes are available: 1 No preemption victims found for incoming pod, 5 Preemption is not helpful for scheduling."
0.6369,Event,ADDED,eval-sanitize-30-r1-197-rbs5j.18d4f7e0664dc487,"reason=FailedScheduling count=None msg=0/6 nodes are available: 1 c_wall violated: 1 conflicting context pair(s) with node memory, 5 node(s) had untolerated taint(s). no new claims to deallocate, preemption: 0/6 nodes are available: 1 No preemption victims found for incoming pod, 5 Preemption is not helpful for scheduling."
0.6374,Event,ADDED,eval-sanitize-30-r1-197-rbs5j.18d4f7e45510ed76,reason=Scheduled count=None msg=Successfully assigned compute/eval-sanitize-30-r1-197-rbs5j to kind-worker
0.6379,Event,ADDED,eval-sanitize-30-r1-197-rbs5j.18d4f7e470168edc,"reason=Pulled count=1 msg=Container image ""busybox:musl"" already present on machine"
0.6384,Event,ADDED,eval-sanitize-30-r1-197-rbs5j.18d4f7e4725b67bc,reason=Created count=1 msg=Created container: task
0.6389,Event,ADDED,eval-sanitize-30-r1-197-rbs5j.18d4f7e476b718ad,reason=Started count=1 msg=Started container task
0.6394,Event,ADDED,eval-sanitize-30-r1-197.18d4f7e06504e847,reason=SuccessfulCreate count=1 msg=Created pod: eval-sanitize-30-r1-197-rbs5j
0.6397,Event,ADDED,eval-sanitize-30-r1-197.18d4f7e9e3fa6db0,reason=Completed count=1 msg=Job completed
0.64,Event,ADDED,eval-sanitize-30-r1-198-l9s2l.18d4f7e0a16cd572,"reason=FailedScheduling count=None msg=0/6 nodes are available: 1 c_wall violated: 1 conflicting context pair(s) with node memory, 5 node(s) had untolerated taint(s). no new claims to deallocate, preemption: 0/6 nodes are available: 1 No preemption victims found for incoming pod, 5 Preemption is not helpful for scheduling."
0.6404,Event,ADDED,eval-sanitize-30-r1-198-l9s2l.18d4f7e0a22667a8,"reason=FailedScheduling count=None msg=0/6 nodes are available: 1 c_wall violated: 1 conflicting context pair(s) with node memory, 5 node(s) had untolerated taint(s). no new claims to deallocate, preemption: 0/6 nodes are available: 1 No preemption victims found for incoming pod, 5 Preemption is not helpful for scheduling."
0.6406,Event,ADDED,eval-sanitize-30-r1-198-l9s2l.18d4f7e45684382b,reason=Scheduled count=None msg=Successfully assigned compute/eval-sanitize-30-r1-198-l9s2l to kind-worker
0.6409,Event,ADDED,eval-sanitize-30-r1-198-l9s2l.18d4f7e470fc1e38,"reason=Pulled count=1 msg=Container image ""busybox:musl"" already present on machine"
0.6418,Event,ADDED,eval-sanitize-30-r1-198-l9s2l.18d4f7e473c4548e,reason=Created count=1 msg=Created container: task
0.6429,Event,ADDED,eval-sanitize-30-r1-198-l9s2l.18d4f7e4775eaa1b,reason=Started count=1 msg=Started container task
0.6434,Event,ADDED,eval-sanitize-30-r1-198.18d4f7e0a120464e,reason=SuccessfulCreate count=1 msg=Created pod: eval-sanitize-30-r1-198-l9s2l
0.6437,Event,ADDED,eval-sanitize-30-r1-198.18d4f7e9a7c01ca6,reason=Completed count=1 msg=Job completed
0.6443,Event,ADDED,eval-sanitize-30-r1-199-5fktr.18d4f7e0dcd2f95e,reason=Scheduled count=None msg=Successfully assigned compute/eval-sanitize-30-r1-199-5fktr to kind-worker3
0.6447,Event,ADDED,eval-sanitize-30-r1-199-5fktr.18d4f7e0fb604a84,"reason=Pulled count=1 msg=Container image ""busybox:musl"" already present on machine"
0.6452,Event,ADDED,eval-sanitize-30-r1-199-5fktr.18d4f7e0fcbedaa1,reason=Created count=1 msg=Created container: task
0.6456,Event,ADDED,eval-sanitize-30-r1-199-5fktr.18d4f7e108a3db17,reason=Started count=1 msg=Started container task
0.6461,Event,ADDED,eval-sanitize-30-r1-199.18d4f7e0dc2114c0,reason=SuccessfulCreate count=1 msg=Created pod: eval-sanitize-30-r1-199-5fktr
0.6463,Event,ADDED,eval-sanitize-30-r1-199.18d4f7e66f453b6e,reason=Completed count=1 msg=Job completed
0.6465,Event,ADDED,eval-sanitize-30-r2-000-kthq8.18d4f7f4a30ea566,reason=Scheduled count=None msg=Successfully assigned compute/eval-sanitize-30-r2-000-kthq8 to kind-worker5
0.6471,Event,ADDED,eval-sanitize-30-r2-000-kthq8.18d4f7f4c05ed4c8,"reason=Pulled count=1 msg=Container image ""busybox:musl"" already present on machine"
0.6476,Event,ADDED,eval-sanitize-30-r2-000-kthq8.18d4f7f4c18a37a0,reason=Created count=1 msg=Created container: task
0.6482,Event,ADDED,eval-sanitize-30-r2-000-kthq8.18d4f7f4c7323b51,reason=Started count=1 msg=Started container task
0.6488,Event,ADDED,eval-sanitize-30-r2-000.18d4f7f4a223192b,reason=SuccessfulCreate count=1 msg=Created pod: eval-sanitize-30-r2-000-kthq8
0.6496,Event,ADDED,eval-sanitize-30-r2-000.18d4f7fa4c18f75a,reason=Completed count=1 msg=Job completed
0.6499,Event,ADDED,eval-sanitize-30-r2-001-hgwdx.18d4f7f4dca57680,reason=Scheduled count=None msg=Successfully assigned compute/eval-sanitize-30-r2-001-hgwdx to kind-worker
0.6501,Event,ADDED,eval-sanitize-30-r2-001-hgwdx.18d4f7f4fb4c9c66,"reason=Pulled count=1 msg=Container image ""busybox:musl"" already present on machine"
0.6503,Event,ADDED,eval-sanitize-30-r2-001-hgwdx.18d4f7f4fc6c0791,reason=Created count=1 msg=Created container: task
0.6506,Event,ADDED,eval-sanitize-30-r2-001-hgwdx.18d4f7f4ff4f7af2,reason=Started count=1 msg=Started container task
0.6508,Event,ADDED,eval-sanitize-30-r2-001.18d4f7f4db8fa8e4,reason=SuccessfulCreate count=1 msg=Created pod: eval-sanitize-30-r2-001-hgwdx
0.651,Event,ADDED,eval-sanitize-30-r2-001.18d4f7fa3b60641d,reason=Completed count=1 msg=Job completed
0.6513,Event,ADDED,eval-sanitize-30-r2-002-mx55q.18d4f7f51bdc25d2,reason=Scheduled count=None msg=Successfully assigned compute/eval-sanitize-30-r2-002-mx55q to kind-worker2
0.6515,Event,ADDED,eval-sanitize-30-r2-002-mx55q.18d4f7f538e3940a,"reason=Pulled count=1 msg=Container image ""busybox:musl"" already present on machine"
0.6518,Event,ADDED,eval-sanitize-30-r2-002-mx55q.18d4f7f53a12af5c,reason=Created count=1 msg=Created container: task
0.652,Event,ADDED,eval-sanitize-30-r2-002-mx55q.18d4f7f53d5b65b5,reason=Started count=1 msg=Started container task
0.6523,Event,ADDED,eval-sanitize-30-r2-002.18d4f7f5170a1f66,reason=SuccessfulCreate count=1 msg=Created pod: eval-sanitize-30-r2-002-mx55q
0.6525,Event,ADDED,eval-sanitize-30-r2-002.18d4f7fab765f3d6,reason=Completed count=1 msg=Job completed
0.6526,Event,ADDED,eval-sanitize-30-r2-003-6khzh.18d4f7f553cfec33,reason=Scheduled count=None msg=Successfully assigned compute/eval-sanitize-30-r2-003-6khzh to kind-worker4
0.6528,Event,ADDED,eval-sanitize-30-r2-003-6khzh.18d4f7f56edd2b53,"reason=Pulled count=1 msg=Container image ""busybox:musl"" already present on machine"
0.6531,Event,ADDED,eval-sanitize-30-r2-003-6khzh.18d4f7f57010e5e4,reason=Created count=1 msg=Created container: task
0.6536,Event,ADDED,eval-sanitize-30-r2-003-6khzh.18d4f7f5725934b0,reason=Started count=1 msg=Started container task
0.654,Event,ADDED,eval-sanitize-30-r2-003.18d4f7f55274aaee,reason=SuccessfulCreate count=1 msg=Created pod: eval-sanitize-30-r2-003-6khzh
0.6545,Event,ADDED,eval-sanitize-30-r2-003.18d4f7faf8899099,reason=Completed count=1 msg=Job completed
0.6547,Event,ADDED,eval-sanitize-30-r2-004-qg5fn.18d4f7f590063870,reason=Scheduled count=None msg=Successfully assigned compute/eval-sanitize-30-r2-004-qg5fn to kind-worker5
0.655,Event,ADDED,eval-sanitize-30-r2-004-qg5fn.18d4f7f5ac259b55,"reason=Pulled count=1 msg=Container image ""busybox:musl"" already present on machine"
0.6552,Event,ADDED,eval-sanitize-30-r2-004-qg5fn.18d4f7f5ad69ab60,reason=Created count=1 msg=Created container: task
0.6557,Event,ADDED,eval-sanitize-30-r2-004-qg5fn.18d4f7f5b28290db,reason=Started count=1 msg=Started container task
0.6559,Event,ADDED,eval-sanitize-30-r2-004.18d4f7f58e84c0fc,reason=SuccessfulCreate count=1 msg=Created pod: eval-sanitize-30-r2-004-qg5fn
0.6561,Event,ADDED,eval-sanitize-30-r2-004.18d4f7fb37d757a2,reason=Completed count=1 msg=Job completed
0.6563,Event,ADDED,eval-sanitize-30-r2-005-ddln6.18d4f7f5cc7e7853,reason=Scheduled count=None msg=Successfully assigned compute/eval-sanitize-30-r2-005-ddln6 to kind-worker
0.6568,Event,ADDED,eval-sanitize-30-r2-005-ddln6.18d4f7f5e6b45e3d,"reason=Pulled count=1 msg=Container image ""busybox:musl"" already present on machine"
0.6571,Event,ADDED,eval-sanitize-30-r2-005-ddln6.18d4f7f5e8009bf0,reason=Created count=1 msg=Created container: task
0.6573,Event,ADDED,eval-sanitize-30-r2-005-ddln6.18d4f7f5ebf8c7fc,reason=Started count=1 msg=Started container task
0.6576,Event,ADDED,eval-sanitize-30-r2-005.18d4f7f5caeb93ad,reason=SuccessfulCreate count=1 msg=Created pod: eval-sanitize-30-r2-005-ddln6
0.6579,Event,ADDED,eval-sanitize-30-r2-005.18d4f7fb62db3f76,reason=Completed count=1 msg=Job completed
0.6581,Event,ADDED,eval-sanitize-30-r2-006-lg2nh.18d4f7f60b792d47,reason=Scheduled count=None msg=Successfully assigned compute/eval-sanitize-30-r2-006-lg2nh to kind-worker3
0.6584,Event,ADDED,eval-sanitize-30-r2-006-lg2nh.18d4f7f62614d939,"reason=Pulled count=1 msg=Container image ""busybox:musl"" already present on machine"
0.6589,Event,ADDED,eval-sanitize-30-r2-006-lg2nh.18d4f7f6274792a8,reason=Created count=1 msg=Created container: task
0.6594,Event,ADDED,eval-sanitize-30-r2-006-lg2nh.18d4f7f6297c48c6,reason=Started count=1 msg=Started container task
0.6597,Event,ADDED,eval-sanitize-30-r2-006.18d4f7f605d68f23,reason=SuccessfulCreate count=1 msg=Created pod: eval-sanitize-30-r2-006-lg2nh
0.6599,Event,ADDED,eval-sanitize-30-r2-006.18d4f7fbb33a5b2f,reason=Completed count=1 msg=Job completed
0.6603,Event,ADDED,eval-sanitize-30-r2-007-fc2wz.18d4f7f642db7906,reason=Scheduled count=None msg=Successfully assigned compute/eval-sanitize-30-r2-007-fc2wz to kind-worker3
0.6606,Event,ADDED,eval-sanitize-30-r2-007-fc2wz.18d4f7f6766e4660,"reason=Pulled count=1 msg=Container image ""busybox:musl"" already present on machine"
0.6609,Event,ADDED,eval-sanitize-30-r2-007-fc2wz.18d4f7f6778b030d,reason=Created count=1 msg=Created container: task
0.6612,Event,ADDED,eval-sanitize-30-r2-007-fc2wz.18d4f7f67efe23e7,reason=Started count=1 msg=Started container task
0.6614,Event,ADDED,eval-sanitize-30-r2-007.18d4f7f641000481,reason=SuccessfulCreate count=1 msg=Created pod: eval-sanitize-30-r2-007-fc2wz
0.6617,Event,ADDED,eval-sanitize-30-r2-007.18d4f7fbf1426588,reason=Completed count=1 msg=Job completed
0.6619,Event,ADDED,eval-sanitize-30-r2-008-x9gqp.18d4f7f68ab99dd8,reason=Scheduled count=None msg=Successfully assigned compute/eval-sanitize-30-r2-008-x9gqp to kind-worker2
0.6623,Event,ADDED,eval-sanitize-30-r2-008-x9gqp.18d4f7f6b9cb9453,"reason=Pulled count=1 msg=Container image ""busybox:musl"" already present on machine"
0.6628,Event,ADDED,eval-sanitize-30-r2-008-x9gqp.18d4f7f6bb3f249c,reason=Created count=1 msg=Created container: task
0.6632,Event,ADDED,eval-sanitize-30-r2-008-x9gqp.18d4f7f6bf1adedb,reason=Started count=1 msg=Started container task
0.6634,Event,ADDED,eval-sanitize-30-r2-008.18d4f7f6809dbd43,reason=SuccessfulCreate count=1 msg=Created pod: eval-sanitize-30-r2-008-x9gqp
0.6638,Event,ADDED,eval-sanitize-30-r2-008.18d4f7fc1bd9c7bc,reason=Completed count=1 msg=Job completed
0.6639,Event,ADDED,eval-sanitize-30-r2-009-c76tr.18d4f7f6bf9e2754,"reason=FailedScheduling count=None msg=0/6 nodes are available: 1 node(s) had untolerated taint(s), 2 c_wall violated: 2 conflicting context pair(s) with node memory, 3 c_wall violated: 1 conflicting context pair(s) with node memory. no new claims to deallocate, preemption: 0/6 nodes are available: 1 Preemption is not helpful for scheduling, 5 No preemption victims found for incoming pod."
0.6642,Event,ADDED,eval-sanitize-30-r2-009-c76tr.18d4f7f6ca9d1aea,"reason=FailedScheduling count=None msg=0/6 nodes are available: 1 node(s) had untolerated taint(s), 2 c_wall violated: 2 conflicting context pair(s) with node memory, 3 c_wall violated: 1 conflicting context pair(s) with node memory. no new claims to deallocate, preemption: 0/6 nodes are available: 1 Preemption is not helpful for scheduling, 5 No preemption victims found for incoming pod."
0.6646,Event,ADDED,eval-sanitize-30-r2-009-c76tr.18d4f7f7cbfa27b1,"reason=FailedScheduling count=None msg=0/6 nodes are available: 1 node(s) had untolerated taint(s), 2 c_wall violated: 1 conflicting context pair(s) with node memory, 3 c_wall violated: 2 conflicting context pair(s) with node memory. no new claims to deallocate, preemption: 0/6 nodes are available: 1 Preemption is not helpful for scheduling, 5 No preemption victims found for incoming pod."
0.6653,Event,ADDED,eval-sanitize-30-r2-009-c76tr.18d4f7f97685d0fc,"reason=FailedScheduling count=None msg=0/6 nodes are available: 1 c_wall violated: 1 conflicting context pair(s) with node memory, 2 node(s) had untolerated taint(s), 3 c_wall violated: 2 conflicting context pair(s) with node memory. no new claims to deallocate, preemption: 0/6 nodes are available: 2 Preemption is not helpful for scheduling, 4 No preemption victims found for incoming pod."
0.666,Event,ADDED,eval-sanitize-30-r2-009-c76tr.18d4f7f98b30010c,"reason=FailedScheduling count=None msg=0/6 nodes are available: 1 c_wall violated: 1 conflicting context pair(s) with node memory, 2 c_wall violated: 2 conflicting context pair(s) with node memory, 3 node(s) had untolerated taint(s). no new claims to deallocate, preemption: 0/6 nodes are available: 3 No preemption victims found for incoming pod, 3 Preemption is not helpful for scheduling."
0.6666,Event,ADDED,eval-sanitize-30-r2-009-c76tr.18d4f7f9d261658d,"reason=FailedScheduling count=None msg=0/6 nodes are available: 1 c_wall violated: 1 conflicting context pair(s) with node memory, 1 c_wall violated: 2 conflicting context pair(s) with node memory, 4 node(s) had untolerated taint(s). no new claims to deallocate, preemption: 0/6 nodes are available: 2 No preemption victims found for incoming pod, 4 Preemption is not helpful for scheduling."
0.6669,Event,ADDED,eval-sanitize-30-r2-009-c76tr.18d4f7fa096ffc4f,"reason=FailedScheduling count=None msg=0/6 nodes are available: 1 c_wall violated: 1 conflicting context pair(s) with node memory, 5 node(s) had untolerated taint(s). no new claims to deallocate, preemption: 0/6 nodes are available: 1 No preemption victims found for incoming pod, 5 Preemption is not helpful for scheduling."
0.6677,Event,ADDED,eval-sanitize-30-r2-009-c76tr.18d4f800754397a0,reason=Scheduled count=None msg=Successfully assigned compute/eval-sanitize-30-r2-009-c76tr to kind-worker
0.6682,Event,ADDED,eval-sanitize-30-r2-009-c76tr.18d4f80096729073,"reason=Pulled count=1 msg=Container image ""busybox:musl"" already present on machine"
0.6687,Event,ADDED,eval-sanitize-30-r2-009-c76tr.18d4f8009ba0f8bb,reason=Created count=1 msg=Created container: task
0.6698,Event,ADDED,eval-sanitize-30-r2-009-c76tr.18d4f800a2981f0b,reason=Started count=1 msg=Started container task
0.6705,Event,ADDED,eval-sanitize-30-r2-009.18d4f7f6be078572,reason=SuccessfulCreate count=1 msg=Created pod: eval-sanitize-30-r2-009-c76tr
0.6721,Event,ADDED,eval-sanitize-30-r2-009.18d4f806d62f4272,reason=Completed count=1 msg=Job completed
0.6725,Event,ADDED,eval-sanitize-30-r2-010-7rq26.18d4f7f70b624d72,reason=Scheduled count=None msg=Successfully assigned compute/eval-sanitize-30-r2-010-7rq26 to kind-worker
0.6728,Event,ADDED,eval-sanitize-30-r2-010-7rq26.18d4f7f727e605df,"reason=Pulled count=1 msg=Container image ""busybox:musl"" already present on machine"
0.6732,Event,ADDED,eval-sanitize-30-r2-010-7rq26.18d4f7f7292ae36a,reason=Created count=1 msg=Created container: task
0.6736,Event,ADDED,eval-sanitize-30-r2-010-7rq26.18d4f7f72e159012,reason=Started count=1 msg=Started container task
0.674,Event,ADDED,eval-sanitize-30-r2-010.18d4f7f6f3c9af51,reason=SuccessfulCreate count=1 msg=Created pod: eval-sanitize-30-r2-010-7rq26
0.6744,Event,ADDED,eval-sanitize-30-r2-010.18d4f7fcd862457e,reason=Completed count=1 msg=Job completed
0.6747,Event,ADDED,eval-sanitize-30-r2-011-2zcvq.18d4f7f739bec5e8,reason=Scheduled count=None msg=Successfully assigned compute/eval-sanitize-30-r2-011-2zcvq to kind-worker3
0.6751,Event,ADDED,eval-sanitize-30-r2-011-2zcvq.18d4f7f755d386c1,"reason=Pulled count=1 msg=Container image ""busybox:musl"" already present on machine"
0.6754,Event,ADDED,eval-sanitize-30-r2-011-2zcvq.18d4f7f757167461,reason=Created count=1 msg=Created container: task
0.6762,Event,ADDED,eval-sanitize-30-r2-011-2zcvq.18d4f7f75fde04d3,reason=Started count=1 msg=Started container task
0.6767,Event,ADDED,eval-sanitize-30-r2-011.18d4f7f72fe80794,reason=SuccessfulCreate count=1 msg=Created pod: eval-sanitize-30-r2-011-2zcvq
0.6771,Event,ADDED,eval-sanitize-30-r2-011.18d4f7fcd895da12,reason=Completed count=1 msg=Job completed
0.6773,Event,ADDED,eval-sanitize-30-r2-012-n4xjr.18d4f7f773519a16,reason=Scheduled count=None msg=Successfully assigned compute/eval-sanitize-30-r2-012-n4xjr to kind-worker2
0.6777,Event,ADDED,eval-sanitize-30-r2-012-n4xjr.18d4f7f790edc0ee,"reason=Pulled count=1 msg=Container image ""busybox:musl"" already present on machine"
0.678,Event,ADDED,eval-sanitize-30-r2-012-n4xjr.18d4f7f792697c61,reason=Created count=1 msg=Created container: task
0.6783,Event,ADDED,eval-sanitize-30-r2-012-n4xjr.18d4f7f79b0ef1f9,reason=Started count=1 msg=Started container task
0.6787,Event,ADDED,eval-sanitize-30-r2-012.18d4f7f76c2a01c4,reason=SuccessfulCreate count=1 msg=Created pod: eval-sanitize-30-r2-012-n4xjr
0.6791,Event,ADDED,eval-sanitize-30-r2-012.18d4f7fd0abfa743,reason=Completed count=1 msg=Job completed
0.6795,Event,ADDED,eval-sanitize-30-r2-013-9t9qq.18d4f7f7b636ad18,reason=Scheduled count=None msg=Successfully assigned compute/eval-sanitize-30-r2-013-9t9qq to kind-worker4
0.6799,Event,ADDED,eval-sanitize-30-r2-013-9t9qq.18d4f7f7d4b54cdc,"reason=Pulled count=1 msg=Container image ""busybox:musl"" already present on machine"
0.6806,Event,ADDED,eval-sanitize-30-r2-013-9t9qq.18d4f7f7db162c9e,reason=Created count=1 msg=Created container: task
0.681,Event,ADDED,eval-sanitize-30-r2-013-9t9qq.18d4f7f7e3bc8ba0,reason=Started count=1 msg=Started container task
0.6812,Event,ADDED,eval-sanitize-30-r2-013.18d4f7f7ae3b55c3,reason=SuccessfulCreate count=1 msg=Created pod: eval-sanitize-30-r2-013-9t9qq
0.6817,Event,ADDED,eval-sanitize-30-r2-013.18d4f7fd8631f4f8,reason=Completed count=1 msg=Job completed
0.682,Event,ADDED,eval-sanitize-30-r2-014-d752n.18d4f7f7ee04c967,reason=Scheduled count=None msg=Successfully assigned compute/eval-sanitize-30-r2-014-d752n to kind-worker4
0.6825,Event,ADDED,eval-sanitize-30-r2-014-d752n.18d4f7f810cbaf2b,"reason=Pulled count=1 msg=Container image ""busybox:musl"" already present on machine"
0.6827,Event,ADDED,eval-sanitize-30-r2-014-d752n.18d4f7f81204da77,reason=Created count=1 msg=Created container: task
0.683,Event,ADDED,eval-sanitize-30-r2-014-d752n.18d4f7f8171c9c24,reason=Started count=1 msg=Started container task
0.6833,Event,ADDED,eval-sanitize-30-r2-014.18d4f7f7e54d1259,reason=SuccessfulCreate count=1 msg=Created pod: eval-sanitize-30-r2-014-d752n
0.6836,Event,ADDED,eval-sanitize-30-r2-014.18d4f7fd860ba7df,reason=Completed count=1 msg=Job completed
0.6838,Event,ADDED,eval-sanitize-30-r2-015-99vlx.18d4f7f82d92238f,reason=Scheduled count=None msg=Successfully assigned compute/eval-sanitize-30-r2-015-99vlx to kind-worker2
0.6841,Event,ADDED,eval-sanitize-30-r2-015-99vlx.18d4f7f84d3451cd,"reason=Pulled count=1 msg=Container image ""busybox:musl"" already present on machine"
0.6844,Event,ADDED,eval-sanitize-30-r2-015-99vlx.18d4f7f84e56088f,reason=Created count=1 msg=Created container: task
0.6848,Event,ADDED,eval-sanitize-30-r2-015-99vlx.18d4f7f852eeea63,reason=Started count=1 msg=Started container task
0.685,Event,ADDED,eval-sanitize-30-r2-015.18d4f7f8222f0f0c,reason=SuccessfulCreate count=1 msg=Created pod: eval-sanitize-30-r2-015-99vlx
0.6853,Event,ADDED,eval-sanitize-30-r2-015.18d4f7fdb7d81244,reason=Completed count=1 msg=Job completed
0.6855,Event,ADDED,eval-sanitize-30-r2-016-f9m2l.18d4f7f863301cd8,reason=Scheduled count=None msg=Successfully assigned compute/eval-sanitize-30-r2-016-f9m2l to kind-worker2
0.6858,Event,ADDED,eval-sanitize-30-r2-016-f9m2l.18d4f7f87d6a8ee9,"reason=Pulled count=1 msg=Container image ""busybox:musl"" already present on machine"
0.6866,Event,ADDED,eval-sanitize-30-r2-016-f9m2l.18d4f7f87ea196ab,reason=Created count=1 msg=Created container: task
0.6868,Event,ADDED,eval-sanitize-30-r2-016-f9m2l.18d4f7f8849f2730,reason=Started count=1 msg=Started container task
0.6872,Event,ADDED,eval-sanitize-30-r2-016.18d4f7f8598949b7,reason=SuccessfulCreate count=1 msg=Created pod: eval-sanitize-30-r2-016-f9m2l
0.6876,Event,ADDED,eval-sanitize-30-r2-016.18d4f7fdf33950ec,reason=Completed count=1 msg=Job completed
0.6879,Event,ADDED,eval-sanitize-30-r2-017-gxf98.18d4f7f8a38768fe,reason=Scheduled count=None msg=Successfully assigned compute/eval-sanitize-30-r2-017-gxf98 to kind-worker5
0.6881,Event,ADDED,eval-sanitize-30-r2-017-gxf98.18d4f7f8c177280c,"reason=Pulled count=1 msg=Container image ""busybox:musl"" already present on machine"
0.6883,Event,ADDED,eval-sanitize-30-r2-017-gxf98.18d4f7f8c2b0bb79,reason=Created count=1 msg=Created container: task
0.6885,Event,ADDED,eval-sanitize-30-r2-017-gxf98.18d4f7f8c7a7b5e3,reason=Started count=1 msg=Started container task
0.6889,Event,ADDED,eval-sanitize-30-r2-017.18d4f7f896f692e7,reason=SuccessfulCreate count=1 msg=Created pod: eval-sanitize-30-r2-017-gxf98
0.6892,Event,ADDED,eval-sanitize-30-r2-017.18d4f7fe3ee3fb93,reason=Completed count=1 msg=Job completed
0.6895,Event,ADDED,eval-sanitize-30-r2-018-fjh4c.18d4f7f8d88160ed,reason=Scheduled count=None msg=Successfully assigned compute/eval-sanitize-30-r2-018-fjh4c to kind-worker
0.6898,Event,ADDED,eval-sanitize-30-r2-018-fjh4c.18d4f7f8f1ea609c,"reason=Pulled count=1 msg=Container image ""busybox:musl"" already present on machine"
0.69,Event,ADDED,eval-sanitize-30-r2-018-fjh4c.18d4f7f8f32e8f15,reason=Created count=1 msg=Created container: task
0.6902,Event,ADDED,eval-sanitize-30-r2-018-fjh4c.18d4f7f8fb06c02c,reason=Started count=1 msg=Started container task
0.6904,Event,ADDED,eval-sanitize-30-r2-018.18d4f7f8d57512b0,reason=SuccessfulCreate count=1 msg=Created pod: eval-sanitize-30-r2-018-fjh4c
0.6907,Event,ADDED,eval-sanitize-30-r2-018.18d4f7fe6a53bd4e,reason=Completed count=1 msg=Job completed
0.6908,Event,ADDED,eval-sanitize-30-r2-019-lmtm4.18d4f7f91c1ccd38,reason=Scheduled count=None msg=Successfully assigned compute/eval-sanitize-30-r2-019-lmtm4 to kind-worker3
0.691,Event,ADDED,eval-sanitize-30-r2-019-lmtm4.18d4f7f937da6aec,"reason=Pulled count=1 msg=Container image ""busybox:musl"" already present on machine"
0.6912,Event,ADDED,eval-sanitize-30-r2-019-lmtm4.18d4f7f9391da885,reason=Created count=1 msg=Created container: task
0.6915,Event,ADDED,eval-sanitize-30-r2-019-lmtm4.18d4f7f941f4d249,reason=Started count=1 msg=Started container task
0.6918,Event,ADDED,eval-sanitize-30-r2-019.18d4f7f912792a10,reason=SuccessfulCreate count=1 msg=Created pod: eval-sanitize-30-r2-019-lmtm4
0.692,Event,ADDED,eval-sanitize-30-r2-019.18d4f7feb8f196d0,reason=Completed count=1 msg=Job completed
0.6923,Event,ADDED,eval-sanitize-30-r2-020-gdw4l.18d4f7f963309159,reason=Scheduled count=None msg=Successfully assigned compute/eval-sanitize-30-r2-020-gdw4l to kind-worker2
0.6926,Event,ADDED,eval-sanitize-30-r2-020-gdw4l.18d4f7f97e52f271,"reason=Pulled count=1 msg=Container image ""busybox:musl"" already present on machine"
0.693,Event,ADDED,eval-sanitize-30-r2-020-gdw4l.18d4f7f97f83e1ab,reason=Created count=1 msg=Created container: task
0.6934,Event,ADDED,eval-sanitize-30-r2-020-gdw4l.18d4f7f985f89d04,reason=Started count=1 msg=Started container task
0.6938,Event,ADDED,eval-sanitize-30-r2-020.18d4f7f94eb06e31,reason=SuccessfulCreate count=1 msg=Created pod: eval-sanitize-30-r2-020-gdw4l
0.6939,Event,ADDED,eval-sanitize-30-r2-020.18d4f7ff22c8c5bb,reason=Completed count=1 msg=Job completed
0.6941,Event,ADDED,eval-sanitize-30-r2-021-gx724.18d4f7f98a95c732,reason=Scheduled count=None msg=Successfully assigned compute/eval-sanitize-30-r2-021-gx724 to kind-worker5
0.6943,Event,ADDED,eval-sanitize-30-r2-021-gx724.18d4f7f9a4b43cc0,"reason=Pulled count=1 msg=Container image ""busybox:musl"" already present on machine"
0.6945,Event,ADDED,eval-sanitize-30-r2-021-gx724.18d4f7f9a60b571c,reason=Created count=1 msg=Created container: task
0.6947,Event,ADDED,eval-sanitize-30-r2-021-gx724.18d4f7f9abf219ea,reason=Started count=1 msg=Started container task
0.6949,Event,ADDED,eval-sanitize-30-r2-021.18d4f7f9848be571,reason=SuccessfulCreate count=1 msg=Created pod: eval-sanitize-30-r2-021-gx724
0.6954,Event,ADDED,eval-sanitize-30-r2-021.18d4f7ff30ffb8e5,reason=Completed count=1 msg=Job completed
0.6956,Event,ADDED,eval-sanitize-30-r2-022-c896k.18d4f7f9c8a55a93,reason=Scheduled count=None msg=Successfully assigned compute/eval-sanitize-30-r2-022-c896k to kind-worker5
0.6957,Event,ADDED,eval-sanitize-30-r2-022-c896k.18d4f7f9e33ab0d0,"reason=Pulled count=1 msg=Container image ""busybox:musl"" already present on machine"
0.6959,Event,ADDED,eval-sanitize-30-r2-022-c896k.18d4f7f9e473dcf6,reason=Created count=1 msg=Created container: task
0.6961,Event,ADDED,eval-sanitize-30-r2-022-c896k.18d4f7f9ed4c8290,reason=Started count=1 msg=Started container task
0.6963,Event,ADDED,eval-sanitize-30-r2-022.18d4f7f9c2af9a3f,reason=SuccessfulCreate count=1 msg=Created pod: eval-sanitize-30-r2-022-c896k
0.6965,Event,ADDED,eval-sanitize-30-r2-022.18d4f7ff69899eb6,reason=Completed count=1 msg=Job completed
0.697,Event,ADDED,eval-sanitize-30-r2-023-67kfr.18d4f7fa01409d40,"reason=FailedScheduling count=None msg=0/6 nodes are available: 2 c_wall violated: 1 conflicting context pair(s) with node memory, 4 node(s) had untolerated taint(s). no new claims to deallocate, preemption: 0/6 nodes are available: 2 No preemption victims found for incoming pod, 4 Preemption is not helpful for scheduling."
0.6972,Event,ADDED,eval-sanitize-30-r2-023-67kfr.18d4f7fa024a3de5,"reason=FailedScheduling count=None msg=0/6 nodes are available: 2 c_wall violated: 1 conflicting context pair(s) with node memory, 4 node(s) had untolerated taint(s). no new claims to deallocate, preemption: 0/6 nodes are available: 2 No preemption victims found for incoming pod, 4 Preemption is not helpful for scheduling."
0.6974,Event,ADDED,eval-sanitize-30-r2-023-67kfr.18d4f7fa09a97318,"reason=FailedScheduling count=None msg=0/6 nodes are available: 1 c_wall violated: 1 conflicting context pair(s) with node memory, 5 node(s) had untolerated taint(s). no new claims to deallocate, preemption: 0/6 nodes are available: 1 No preemption victims found for incoming pod, 5 Preemption is not helpful for scheduling."
0.6976,Event,ADDED,eval-sanitize-30-r2-023-67kfr.18d4f800778a7aec,reason=Scheduled count=None msg=Successfully assigned compute/eval-sanitize-30-r2-023-67kfr to kind-worker
0.698,Event,ADDED,eval-sanitize-30-r2-023-67kfr.18d4f8009692f2fb,"reason=Pulled count=1 msg=Container image ""busybox:musl"" already present on machine"
0.6984,Event,ADDED,eval-sanitize-30-r2-023-67kfr.18d4f8009c0d0b8d,reason=Created count=1 msg=Created container: task
0.6985,Event,ADDED,eval-sanitize-30-r2-023-67kfr.18d4f800a1cc3728,reason=Started count=1 msg=Started container task
0.6988,Event,ADDED,eval-sanitize-30-r2-023.18d4f7fa00a986a1,reason=SuccessfulCreate count=1 msg=Created pod: eval-sanitize-30-r2-023-67kfr
0.699,Event,ADDED,eval-sanitize-30-r2-023.18d4f805e8606f6c,reason=Completed count=1 msg=Job completed
0.6993,Event,ADDED,eval-sanitize-30-r2-024-vbwl5.18d4f7fa3adfb46c,"reason=FailedScheduling count=None msg=0/6 nodes are available: 6 node(s) had untolerated taint(s). no new claims to deallocate, preemption: 0/6 nodes are available: 6 Preemption is not helpful for scheduling."
0.6996,Event,ADDED,eval-sanitize-30-r2-024-vbwl5.18d4f80075c6b151,"reason=FailedScheduling count=None msg=0/6 nodes are available: 1 c_wall violated: 1 conflicting context pair(s) with node memory, 5 node(s) had untolerated taint(s). no new claims to deallocate, preemption: 0/6 nodes are available: 1 No preemption victims found for incoming pod, 5 Preemption is not helpful for scheduling."
0.6999,Event,ADDED,eval-sanitize-30-r2-024-vbwl5.18d4f800a9dedb9b,"reason=FailedScheduling count=None msg=0/6 nodes are available: 1 c_wall violated: 1 conflicting context pair(s) with node memory, 1 c_wall violated: 2 conflicting context pair(s) with node memory, 4 node(s) had untolerated taint(s). no new claims to deallocate, preemption: 0/6 nodes are available: 2 No preemption victims found for incoming pod, 4 Preemption is not helpful for scheduling."
0.7,Event,ADDED,eval-sanitize-30-r2-024-vbwl5.18d4f800e0ace91a,"reason=FailedScheduling count=None msg=0/6 nodes are available: 1 c_wall violated: 2 conflicting context pair(s) with node memory, 2 c_wall violated: 1 conflicting context pair(s) with node memory, 3 node(s) had untolerated taint(s). no new claims to deallocate, preemption: 0/6 nodes are available: 3 No preemption victims found for incoming pod, 3 Preemption is not helpful for scheduling."
0.7002,Event,ADDED,eval-sanitize-30-r2-024-vbwl5.18d4f80126024707,reason=Scheduled count=None msg=Successfully assigned compute/eval-sanitize-30-r2-024-vbwl5 to kind-worker5
0.7005,Event,ADDED,eval-sanitize-30-r2-024-vbwl5.18d4f80142380b27,"reason=Pulled count=1 msg=Container image ""busybox:musl"" already present on machine"
0.7007,Event,ADDED,eval-sanitize-30-r2-024-vbwl5.18d4f80143d0c5d8,reason=Created count=1 msg=Created container: task
0.7009,Event,ADDED,eval-sanitize-30-r2-024-vbwl5.18d4f8014c641be1,reason=Started count=1 msg=Started container task
0.7012,Event,ADDED,eval-sanitize-30-r2-024.18d4f7fa3ad277b8,reason=SuccessfulCreate count=1 msg=Created pod: eval-sanitize-30-r2-024-vbwl5
0.7013,Event,ADDED,eval-sanitize-30-r2-024.18d4f808b301000e,reason=Completed count=1 msg=Job completed
0.7017,Event,ADDED,eval-sanitize-30-r2-025-nht27.18d4f7fa75ff45f7,"reason=FailedScheduling count=None msg=0/6 nodes are available: 6 node(s) had untolerated taint(s). no new claims to deallocate, preemption: 0/6 nodes are available: 6 Preemption is not helpful for scheduling."
0.7019,Event,ADDED,eval-sanitize-30-r2-025-nht27.18d4f8007891128b,reason=Scheduled count=None msg=Successfully assigned compute/eval-sanitize-30-r2-025-nht27 to kind-worker
0.7022,Event,ADDED,eval-sanitize-30-r2-025-nht27.18d4f80096c08747,"reason=Pulled count=1 msg=Container image ""busybox:musl"" already present on machine"
0.7024,Event,ADDED,eval-sanitize-30-r2-025-nht27.18d4f8009c34d451,reason=Created count=1 msg=Created container: task
0.7026,Event,ADDED,eval-sanitize-30-r2-025-nht27.18d4f800a2512e8a,reason=Started count=1 msg=Started container task
0.7027,Event,ADDED,eval-sanitize-30-r2-025.18d4f7fa75f53d8e,reason=SuccessfulCreate count=1 msg=Created pod: eval-sanitize-30-r2-025-nht27
0.7031,Event,ADDED,eval-sanitize-30-r2-025.18d4f8070400fe10,reason=Completed count=1 msg=Job completed
0.7032,Event,ADDED,eval-sanitize-30-r2-026-4scv9.18d4f7faafa1ebdd,"reason=FailedScheduling count=None msg=0/6 nodes are available: 6 node(s) had untolerated taint(s). no new claims to deallocate, preemption: 0/6 nodes are available: 6 Preemption is not helpful for scheduling."
0.7035,Event,ADDED,eval-sanitize-30-r2-026-4scv9.18d4f8007aded212,"reason=FailedScheduling count=None msg=0/6 nodes are available: 1 c_wall violated: 1 conflicting context pair(s) with node memory, 5 node(s) had untolerated taint(s). no new claims to deallocate, preemption: 0/6 nodes are available: 1 No preemption victims found for incoming pod, 5 Preemption is not helpful for scheduling."
0.7039,Event,ADDED,eval-sanitize-30-r2-026-4scv9.18d4f800aaf24b93,"reason=FailedScheduling count=None msg=0/6 nodes are available: 1 c_wall violated: 1 conflicting context pair(s) with node memory, 1 c_wall violated: 2 conflicting context pair(s) with node memory, 4 node(s) had untolerated taint(s). no new claims to deallocate, preemption: 0/6 nodes are available: 2 No preemption victims found for incoming pod, 4 Preemption is not helpful for scheduling."
0.7041,Event,ADDED,eval-sanitize-30-r2-026-4scv9.18d4f800e695941b,"reason=FailedScheduling count=None msg=0/6 nodes are available: 1 c_wall violated: 1 conflicting context pair(s) with node memory, 2 c_wall violated: 2 conflicting context pair(s) with node memory, 3 node(s) had untolerated taint(s). no new claims to deallocate, preemption: 0/6 nodes are available: 3 No preemption victims found for incoming pod, 3 Preemption is not helpful for scheduling."
0.7043,Event,ADDED,eval-sanitize-30-r2-026-4scv9.18d4f8012894523a,"reason=FailedScheduling count=None msg=0/6 nodes are available: 2 c_wall violated: 1 conflicting context pair(s) with node memory, 2 c_wall violated: 2 conflicting context pair(s) with node memory, 2 node(s) had untolerated taint(s). no new claims to deallocate, preemption: 0/6 nodes are available: 2 Preemption is not helpful for scheduling, 4 No preemption victims found for incoming pod."
0.7045,Event,ADDED,eval-sanitize-30-r2-026-4scv9.18d4f801728b339b,reason=Scheduled count=None msg=Successfully assigned compute/eval-sanitize-30-r2-026-4scv9 to kind-worker2
0.7047,Event,ADDED,eval-sanitize-30-r2-026-4scv9.18d4f8018f2d235a,"reason=Pulled count=1 msg=Container image ""busybox:musl"" already present on machine"
0.7048,Event,ADDED,eval-sanitize-30-r2-026-4scv9.18d4f80190f11884,reason=Created count=1 msg=Created container: task
0.705,Event,ADDED,eval-sanitize-30-r2-026-4scv9.18d4f80196bd5e65,reason=Started count=1 msg=Started container task
0.7053,Event,ADDED,eval-sanitize-30-r2-026.18d4f7faaf821e5b,reason=SuccessfulCreate count=1 msg=Created pod: eval-sanitize-30-r2-026-4scv9
0.7056,Event,ADDED,eval-sanitize-30-r2-026.18d4f808cad5895b,reason=Completed count=1 msg=Job completed
0.7059,Event,ADDED,eval-sanitize-30-r2-027-b2v9b.18d4f7fae94c84bc,"reason=FailedScheduling count=None msg=0/6 nodes are available: 6 node(s) had untolerated taint(s). no new claims to deallocate, preemption: 0/6 nodes are available: 6 Preemption is not helpful for scheduling."
0.7064,Event,ADDED,eval-sanitize-30-r2-027-b2v9b.18d4f8007b720e01,"reason=FailedScheduling count=None msg=0/6 nodes are available: 1 c_wall violated: 1 conflicting context pair(s) with node memory, 5 node(s) had untolerated taint(s). no new claims to deallocate, preemption: 0/6 nodes are available: 1 No preemption victims found for incoming pod, 5 Preemption is not helpful for scheduling."
0.7067,Event,ADDED,eval-sanitize-30-r2-027-b2v9b.18d4f800b0924c88,"reason=FailedScheduling count=None msg=0/6 nodes are available: 1 c_wall violated: 1 conflicting context pair(s) with node memory, 1 c_wall violated: 2 conflicting context pair(s) with node memory, 4 node(s) had untolerated taint(s). no new claims to deallocate, preemption: 0/6 nodes are available: 2 No preemption victims found for incoming pod, 4 Preemption is not helpful for scheduling."
0.7069,Event,ADDED,eval-sanitize-30-r2-027-b2v9b.18d4f800f3de504e,"reason=FailedScheduling count=None msg=0/6 nodes are available: 1 c_wall violated: 2 conflicting context pair(s) with node memory, 2 c_wall violated: 1 conflicting context pair(s) with node memory, 3 node(s) had untolerated taint(s). no new claims to deallocate, preemption: 0/6 nodes are available: 3 No preemption victims found for incoming pod, 3 Preemption is not helpful for scheduling."
0.7073,Event,ADDED,eval-sanitize-30-r2-027-b2v9b.18d4f80136f2a7c7,reason=Scheduled count=None msg=Successfully assigned compute/eval-sanitize-30-r2-027-b2v9b to kind-worker5
0.7076,Event,ADDED,eval-sanitize-30-r2-027-b2v9b.18d4f8015ba41e22,"reason=Pulled count=1 msg=Container image ""busybox:musl"" already present on machine"
0.7079,Event,ADDED,eval-sanitize-30-r2-027-b2v9b.18d4f8015d91954c,reason=Created count=1 msg=Created container: task
0.7082,Event,ADDED,eval-sanitize-30-r2-027-b2v9b.18d4f801625c69fb,reason=Started count=1 msg=Started container task
0.7086,Event,ADDED,eval-sanitize-30-r2-027.18d4f7fae93d2163,reason=SuccessfulCreate count=1 msg=Created pod: eval-sanitize-30-r2-027-b2v9b
0.7088,Event,ADDED,eval-sanitize-30-r2-027.18d4f808b5f4a4fa,reason=Completed count=1 msg=Job completed
0.7091,Event,ADDED,eval-sanitize-30-r2-028-7xdwq.18d4f7fb262bf3c5,"reason=FailedScheduling count=None msg=0/6 nodes are available: 6 node(s) had untolerated taint(s). no new claims to deallocate, preemption: 0/6 nodes are available: 6 Preemption is not helpful for scheduling."
0.7094,Event,ADDED,eval-sanitize-30-r2-028-7xdwq.18d4f8007c84db7e,"reason=FailedScheduling count=None msg=0/6 nodes are available: 1 c_wall violated: 1 conflicting context pair(s) with node memory, 5 node(s) had untolerated taint(s). no new claims to deallocate, preemption: 0/6 nodes are available: 1 No preemption victims found for incoming pod, 5 Preemption is not helpful for scheduling."
0.7098,Event,ADDED,eval-sanitize-30-r2-028-7xdwq.18d4f800b1e630c6,"reason=FailedScheduling count=None msg=0/6 nodes are available: 2 c_wall violated: 2 conflicting context pair(s) with node memory, 4 node(s) had untolerated taint(s). no new claims to deallocate, preemption: 0/6 nodes are available: 2 No preemption victims found for incoming pod, 4 Preemption is not helpful for scheduling."
0.7108,Event,ADDED,eval-sanitize-30-r2-028-7xdwq.18d4f800fa05dc30,reason=Scheduled count=None msg=Successfully assigned compute/eval-sanitize-30-r2-028-7xdwq to kind-worker3
0.7118,Event,ADDED,eval-sanitize-30-r2-028-7xdwq.18d4f801159fcea9,"reason=Pulled count=1 msg=Container image ""busybox:musl"" already present on machine"
0.7124,Event,ADDED,eval-sanitize-30-r2-028-7xdwq.18d4f801197467fc,reason=Created count=1 msg=Created container: task
0.7127,Event,ADDED,eval-sanitize-30-r2-028-7xdwq.18d4f80125fa66f0,reason=Started count=1 msg=Started container task
0.713,Event,ADDED,eval-sanitize-30-r2-028.18d4f7fb261d78bf,reason=SuccessfulCreate count=1 msg=Created pod: eval-sanitize-30-r2-028-7xdwq
0.7136,Event,ADDED,eval-sanitize-30-r2-028.18d4f808271cdc29,reason=Completed count=1 msg=Job completed
0.7139,Event,ADDED,eval-sanitize-30-r2-029-sj672.18d4f7fb603aee45,"reason=FailedScheduling count=None msg=0/6 nodes are available: 6 node(s) had untolerated taint(s). no new claims to deallocate, preemption: 0/6 nodes are available: 6 Preemption is not helpful for scheduling."
0.7141,Event,ADDED,eval-sanitize-30-r2-029-sj672.18d4f8007d69612f,reason=Scheduled count=None msg=Successfully assigned compute/eval-sanitize-30-r2-029-sj672 to kind-worker
0.7144,Event,ADDED,eval-sanitize-30-r2-029-sj672.18d4f800a079d954,"reason=Pulled count=1 msg=Container image ""busybox:musl"" already present on machine"
0.7148,Event,ADDED,eval-sanitize-30-r2-029-sj672.18d4f800a24e5089,reason=Created count=1 msg=Created container: task
0.7152,Event,ADDED,eval-sanitize-30-r2-029-sj672.18d4f800a67a31be,reason=Started count=1 msg=Started container task
0.7159,Event,ADDED,eval-sanitize-30-r2-029.18d4f7fb602eedf0,reason=SuccessfulCreate count=1 msg=Created pod: eval-sanitize-30-r2-029-sj672
0.7165,Event,ADDED,eval-sanitize-30-r2-029.18d4f805e860f26a,reason=Completed count=1 msg=Job completed
0.7171,Event,ADDED,eval-sanitize-30-r2-030-r2mdq.18d4f7fb9f78a734,"reason=FailedScheduling count=None msg=0/6 nodes are available: 6 node(s) had untolerated taint(s). no new claims to deallocate, preemption: 0/6 nodes are available: 6 Preemption is not helpful for scheduling."
0.7173,Event,ADDED,eval-sanitize-30-r2-030-r2mdq.18d4f8007d42ea50,"reason=FailedScheduling count=None msg=0/6 nodes are available: 1 c_wall violated: 2 conflicting context pair(s) with node memory, 5 node(s) had untolerated taint(s). no new claims to deallocate, preemption: 0/6 nodes are available: 1 No preemption victims found for incoming pod, 5 Preemption is not helpful for scheduling."
0.7176,Event,ADDED,eval-sanitize-30-r2-030-r2mdq.18d4f800b6e6b8dc,reason=Scheduled count=None msg=Successfully assigned compute/eval-sanitize-30-r2-030-r2mdq to kind-worker4
0.7182,Event,ADDED,eval-sanitize-30-r2-030-r2mdq.18d4f800d4ff1efe,"reason=Pulled count=1 msg=Container image ""busybox:musl"" already present on machine"
0.7185,Event,ADDED,eval-sanitize-30-r2-030-r2mdq.18d4f800d69d2cb2,reason=Created count=1 msg=Created container: task
0.7189,Event,ADDED,eval-sanitize-30-r2-030-r2mdq.18d4f800dac191f2,reason=Started count=1 msg=Started container task
0.7192,Event,ADDED,eval-sanitize-30-r2-030.18d4f7fb9f6f18ee,reason=SuccessfulCreate count=1 msg=Created pod: eval-sanitize-30-r2-030-r2mdq
0.7198,Event,ADDED,eval-sanitize-30-r2-030.18d4f8086b6af8ec,reason=Completed count=1 msg=Job completed
0.7201,Event,ADDED,eval-sanitize-30-r2-031-bbj7f.18d4f7fbdb3851de,"reason=FailedScheduling count=None msg=0/6 nodes are available: 6 node(s) had untolerated taint(s). no new claims to deallocate, preemption: 0/6 nodes are available: 6 Preemption is not helpful for scheduling."
0.7206,Event,ADDED,eval-sanitize-30-r2-031-bbj7f.18d4f8007f54dd80,"reason=FailedScheduling count=None msg=0/6 nodes are available: 1 c_wall violated: 2 conflicting context pair(s) with node memory, 5 node(s) had untolerated taint(s). no new claims to deallocate, preemption: 0/6 nodes are available: 1 No preemption victims found for incoming pod, 5 Preemption is not helpful for scheduling."
0.7212,Event,ADDED,eval-sanitize-30-r2-031-bbj7f.18d4f800b6e87e9e,"reason=FailedScheduling count=None msg=0/6 nodes are available: 2 c_wall violated: 2 conflicting context pair(s) with node memory, 4 node(s) had untolerated taint(s). no new claims to deallocate, preemption: 0/6 nodes are available: 2 No preemption victims found for incoming pod, 4 Preemption is not helpful for scheduling."
0.7215,Event,ADDED,eval-sanitize-30-r2-031-bbj7f.18d4f80101ec72ca,reason=Scheduled count=None msg=Successfully assigned compute/eval-sanitize-30-r2-031-bbj7f to kind-worker3
0.7219,Event,ADDED,eval-sanitize-30-r2-031-bbj7f.18d4f80126039016,"reason=Pulled count=1 msg=Container image ""busybox:musl"" already present on machine"
0.7224,Event,ADDED,eval-sanitize-30-r2-031-bbj7f.18d4f80127fbf404,reason=Created count=1 msg=Created container: task
0.7229,Event,ADDED,eval-sanitize-30-r2-031-bbj7f.18d4f8012c40708f,reason=Started count=1 msg=Started container task
0.7232,Event,ADDED,eval-sanitize-30-r2-031.18d4f7fbdb2ffd05,reason=SuccessfulCreate count=1 msg=Created pod: eval-sanitize-30-r2-031-bbj7f
0.7235,Event,ADDED,eval-sanitize-30-r2-031.18d4f80838d08bd8,reason=Completed count=1 msg=Job completed
0.7239,Event,ADDED,eval-sanitize-30-r2-032-x4hl7.18d4f7fc1c833c91,"reason=FailedScheduling count=None msg=0/6 nodes are available: 6 node(s) had untolerated taint(s). no new claims to deallocate, preemption: 0/6 nodes are available: 6 Preemption is not helpful for scheduling."
0.7242,Event,ADDED,eval-sanitize-30-r2-032-x4hl7.18d4f80080f14574,"reason=FailedScheduling count=None msg=0/6 nodes are available: 1 c_wall violated: 1 conflicting context pair(s) with node memory, 5 node(s) had untolerated taint(s). no new claims to deallocate, preemption: 0/6 nodes are available: 1 No preemption victims found for incoming pod, 5 Preemption is not helpful for scheduling."
0.7245,Event,ADDED,eval-sanitize-30-r2-032-x4hl7.18d4f800bbc02896,"reason=FailedScheduling count=None msg=0/6 nodes are available: 1 c_wall violated: 1 conflicting context pair(s) with node memory, 1 c_wall violated: 2 conflicting context pair(s) with node memory, 4 node(s) had untolerated taint(s). no new claims to deallocate, preemption: 0/6 nodes are available: 2 No preemption victims found for incoming pod, 4 Preemption is not helpful for scheduling."
0.7249,Event,ADDED,eval-sanitize-30-r2-032-x4hl7.18d4f80104520efa,"reason=FailedScheduling count=None msg=0/6 nodes are available: 1 c_wall violated: 1 conflicting context pair(s) with node memory, 2 c_wall violated: 2 conflicting context pair(s) with node memory, 3 node(s) had untolerated taint(s). no new claims to deallocate, preemption: 0/6 nodes are available: 3 No preemption victims found for incoming pod, 3 Preemption is not helpful for scheduling."
0.7251,Event,ADDED,eval-sanitize-30-r2-032-x4hl7.18d4f8013a99479d,reason=Scheduled count=None msg=Successfully assigned compute/eval-sanitize-30-r2-032-x4hl7 to kind-worker2
0.7255,Event,ADDED,eval-sanitize-30-r2-032-x4hl7.18d4f8015b879ec1,"reason=Pulled count=1 msg=Container image ""busybox:musl"" already present on machine"
0.726,Event,ADDED,eval-sanitize-30-r2-032-x4hl7.18d4f8015ddc95ca,reason=Created count=1 msg=Created container: task
0.7265,Event,ADDED,eval-sanitize-30-r2-032-x4hl7.18d4f801625dab1b,reason=Started count=1 msg=Started container task
0.7269,Event,ADDED,eval-sanitize-30-r2-032.18d4f7fc1c7811a6,reason=SuccessfulCreate count=1 msg=Created pod: eval-sanitize-30-r2-032-x4hl7
0.7272,Event,ADDED,eval-sanitize-30-r2-032.18d4f808a4cb3a2a,reason=Completed count=1 msg=Job completed
0.7275,Event,ADDED,eval-sanitize-30-r2-033-2x9qh.18d4f7fc52b75e40,"reason=FailedScheduling count=None msg=0/6 nodes are available: 6 node(s) had untolerated taint(s). no new claims to deallocate, preemption: 0/6 nodes are available: 6 Preemption is not helpful for scheduling."
0.7278,Event,ADDED,eval-sanitize-30-r2-033-2x9qh.18d4f80082a38f43,reason=Scheduled count=None msg=Successfully assigned compute/eval-sanitize-30-r2-033-2x9qh to kind-worker
0.7283,Event,ADDED,eval-sanitize-30-r2-033-2x9qh.18d4f800a35fdcdc,"reason=Pulled count=1 msg=Container image ""busybox:musl"" already present on machine"
0.7287,Event,ADDED,eval-sanitize-30-r2-033-2x9qh.18d4f800a59bf160,reason=Created count=1 msg=Created container: task
0.7291,Event,ADDED,eval-sanitize-30-r2-033-2x9qh.18d4f800ac41fa64,reason=Started count=1 msg=Started container task
0.7294,Event,ADDED,eval-sanitize-30-r2-033.18d4f7fc52abd6f1,reason=SuccessfulCreate count=1 msg=Created pod: eval-sanitize-30-r2-033-2x9qh
0.7299,Event,ADDED,eval-sanitize-30-r2-033.18d4f806dc284bb4,reason=Completed count=1 msg=Job completed
0.7304,Event,ADDED,eval-sanitize-30-r2-034-zv7xs.18d4f7fc93e31109,"reason=FailedScheduling count=None msg=0/6 nodes are available: 6 node(s) had untolerated taint(s). no new claims to deallocate, preemption: 0/6 nodes are available: 6 Preemption is not helpful for scheduling."
0.7309,Event,ADDED,eval-sanitize-30-r2-034-zv7xs.18d4f800827788bb,"reason=FailedScheduling count=None msg=0/6 nodes are available: 1 c_wall violated: 1 conflicting context pair(s) with node memory, 5 node(s) had untolerated taint(s). no new claims to deallocate, preemption: 0/6 nodes are available: 1 No preemption victims found for incoming pod, 5 Preemption is not helpful for scheduling."
0.7317,Event,ADDED,eval-sanitize-30-r2-034-zv7xs.18d4f800bd813b92,"reason=FailedScheduling count=None msg=0/6 nodes are available: 1 c_wall violated: 1 conflicting context pair(s) with node memory, 1 c_wall violated: 2 conflicting context pair(s) with node memory, 4 node(s) had untolerated taint(s). no new claims to deallocate, preemption: 0/6 nodes are available: 2 No preemption victims found for incoming pod, 4 Preemption is not helpful for scheduling."
0.7325,Event,ADDED,eval-sanitize-30-r2-034-zv7xs.18d4f8010a3323ad,"reason=FailedScheduling count=None msg=0/6 nodes are available: 1 c_wall violated: 1 conflicting context pair(s) with node memory, 2 c_wall violated: 2 conflicting context pair(s) with node memory, 3 node(s) had untolerated taint(s). no new claims to deallocate, preemption: 0/6 nodes are available: 3 No preemption victims found for incoming pod, 3 Preemption is not helpful for scheduling."
0.7328,Event,ADDED,eval-sanitize-30-r2-034-zv7xs.18d4f80145164cd4,reason=Scheduled count=None msg=Successfully assigned compute/eval-sanitize-30-r2-034-zv7xs to kind-worker2
0.7331,Event,ADDED,eval-sanitize-30-r2-034-zv7xs.18d4f801641f3839,"reason=Pulled count=1 msg=Container image ""busybox:musl"" already present on machine"
0.7334,Event,ADDED,eval-sanitize-30-r2-034-zv7xs.18d4f8016562ecfa,reason=Created count=1 msg=Created container: task
0.7338,Event,ADDED,eval-sanitize-30-r2-034-zv7xs.18d4f80172451010,reason=Started count=1 msg=Started container task
0.7341,Event,ADDED,eval-sanitize-30-r2-034.18d4f7fc93dbd65d,reason=SuccessfulCreate count=1 msg=Created pod: eval-sanitize-30-r2-034-zv7xs
0.7343,Event,ADDED,eval-sanitize-30-r2-034.18d4f8089e2f165a,reason=Completed count=1 msg=Job completed
0.7346,Event,ADDED,eval-sanitize-30-r2-035-8fjqz.18d4f7fcc7dee18e,"reason=FailedScheduling count=None msg=0/6 nodes are available: 6 node(s) had untolerated taint(s). no new claims to deallocate, preemption: 0/6 nodes are available: 6 Preemption is not helpful for scheduling."
0.735,Event,ADDED,eval-sanitize-30-r2-035-8fjqz.18d4f80083a4ae12,reason=Scheduled count=None msg=Successfully assigned compute/eval-sanitize-30-r2-035-8fjqz to kind-worker
0.7353,Event,ADDED,eval-sanitize-30-r2-035-8fjqz.18d4f800a381024b,"reason=Pulled count=1 msg=Container image ""busybox:musl"" already present on machine"
0.7356,Event,ADDED,eval-sanitize-30-r2-035-8fjqz.18d4f800a5e238ac,reason=Created count=1 msg=Created container: task
0.7364,Event,ADDED,eval-sanitize-30-r2-035-8fjqz.18d4f800ac415fa6,reason=Started count=1 msg=Started container task
0.7369,Event,ADDED,eval-sanitize-30-r2-035.18d4f7fcc7d2289f,reason=SuccessfulCreate count=1 msg=Created pod: eval-sanitize-30-r2-035-8fjqz
0.7372,Event,ADDED,eval-sanitize-30-r2-035.18d4f80705cdcd8f,reason=Completed count=1 msg=Job completed
0.7377,Event,ADDED,eval-sanitize-30-r2-036-597dz.18d4f7fd03d0dcd7,"reason=FailedScheduling count=None msg=0/6 nodes are available: 6 node(s) had untolerated taint(s). no new claims to deallocate, preemption: 0/6 nodes are available: 6 Preemption is not helpful for scheduling."
0.7381,Event,ADDED,eval-sanitize-30-r2-036-597dz.18d4f8008604c0f2,"reason=FailedScheduling count=None msg=0/6 nodes are available: 1 c_wall violated: 3 conflicting context pair(s) with node memory, 5 node(s) had untolerated taint(s). no new claims to deallocate, preemption: 0/6 nodes are available: 1 No preemption victims found for incoming pod, 5 Preemption is not helpful for scheduling."
0.7384,Event,ADDED,eval-sanitize-30-r2-036-597dz.18d4f800cc909ca1,reason=Scheduled count=None msg=Successfully assigned compute/eval-sanitize-30-r2-036-597dz to kind-worker4
0.7387,Event,ADDED,eval-sanitize-30-r2-036-597dz.18d4f800e96605a0,"reason=Pulled count=1 msg=Container image ""busybox:musl"" already present on machine"
0.7391,Event,ADDED,eval-sanitize-30-r2-036-597dz.18d4f800eb6e6359,reason=Created count=1 msg=Created container: task
0.7394,Event,ADDED,eval-sanitize-30-r2-036-597dz.18d4f800f55e0967,reason=Started count=1 msg=Started container task
0.7397,Event,ADDED,eval-sanitize-30-r2-036.18d4f7fd03ca30e5,reason=SuccessfulCreate count=1 msg=Created pod: eval-sanitize-30-r2-036-597dz
0.74,Event,ADDED,eval-sanitize-30-r2-036.18d4f8089009b320,reason=Completed count=1 msg=Job completed
0.7404,Event,ADDED,eval-sanitize-30-r2-037-2xptq.18d4f7fd4056f67e,"reason=FailedScheduling count=None msg=0/6 nodes are available: 6 node(s) had untolerated taint(s). no new claims to deallocate, preemption: 0/6 nodes are available: 6 Preemption is not helpful for scheduling."
0.7409,Event,ADDED,eval-sanitize-30-r2-037-2xptq.18d4f8008af68764,"reason=FailedScheduling count=None msg=0/6 nodes are available: 1 c_wall violated: 1 conflicting context pair(s) with node memory, 5 node(s) had untolerated taint(s). no new claims to deallocate, preemption: 0/6 nodes are available: 1 No preemption victims found for incoming pod, 5 Preemption is not helpful for scheduling."
0.7412,Event,ADDED,eval-sanitize-30-r2-037-2xptq.18d4f800cd0628d3,reason=Scheduled count=None msg=Successfully assigned compute/eval-sanitize-30-r2-037-2xptq to kind-worker4
0.7417,Event,ADDED,eval-sanitize-30-r2-037-2xptq.18d4f800eaab6e5e,"reason=Pulled count=1 msg=Container image ""busybox:musl"" already present on machine"
0.7421,Event,ADDED,eval-sanitize-30-r2-037-2xptq.18d4f800ecfebd3d,reason=Created count=1 msg=Created container: task
0.7426,Event,ADDED,eval-sanitize-30-r2-037-2xptq.18d4f800f55fef16,reason=Started count=1 msg=Started container task
0.7433,Event,ADDED,eval-sanitize-30-r2-037.18d4f7fd404e7c7c,reason=SuccessfulCreate count=1 msg=Created pod: eval-sanitize-30-r2-037-2xptq
0.7439,Event,ADDED,eval-sanitize-30-r2-037.18d4f808810bfd3b,reason=Completed count=1 msg=Job completed
0.7441,Event,ADDED,eval-sanitize-30-r2-038-mmdbm.18d4f7fd7b5925bf,"reason=FailedScheduling count=None msg=0/6 nodes are available: 6 node(s) had untolerated taint(s). no new claims to deallocate, preemption: 0/6 nodes are available: 6 Preemption is not helpful for scheduling."
0.7445,Event,ADDED,eval-sanitize-30-r2-038-mmdbm.18d4f8008bc0a7ac,"reason=FailedScheduling count=None msg=0/6 nodes are available: 1 c_wall violated: 1 conflicting context pair(s) with node memory, 5 node(s) had untolerated taint(s). no new claims to deallocate, preemption: 0/6 nodes are available: 1 No preemption victims found for incoming pod, 5 Preemption is not helpful for scheduling."
0.7449,Event,ADDED,eval-sanitize-30-r2-038-mmdbm.18d4f800c8ef6c73,"reason=FailedScheduling count=None msg=0/6 nodes are available: 1 c_wall violated: 1 conflicting context pair(s) with node memory, 1 c_wall violated: 2 conflicting context pair(s) with node memory, 4 node(s) had untolerated taint(s). no new claims to deallocate, preemption: 0/6 nodes are available: 2 No preemption victims found for incoming pod, 4 Preemption is not helpful for scheduling."
0.7452,Event,ADDED,eval-sanitize-30-r2-038-mmdbm.18d4f80110a367a1,"reason=FailedScheduling count=None msg=0/6 nodes are available: 1 c_wall violated: 2 conflicting context pair(s) with node memory, 2 c_wall violated: 1 conflicting context pair(s) with node memory, 3 node(s) had untolerated taint(s). no new claims to deallocate, preemption: 0/6 nodes are available: 3 No preemption victims found for incoming pod, 3 Preemption is not helpful for scheduling."
0.7457,Event,ADDED,eval-sanitize-30-r2-038-mmdbm.18d4f8015ee42912,reason=Scheduled count=None msg=Successfully assigned compute/eval-sanitize-30-r2-038-mmdbm to kind-worker5
0.7466,Event,ADDED,eval-sanitize-30-r2-038-mmdbm.18d4f8018d0064b0,"reason=Pulled count=1 msg=Container image ""busybox:musl"" already present on machine"
0.7471,Event,ADDED,eval-sanitize-30-r2-038-mmdbm.18d4f8018ef20eb1,reason=Created count=1 msg=Created container: task
0.7474,Event,ADDED,eval-sanitize-30-r2-038-mmdbm.18d4f80196e791ef,reason=Started count=1 msg=Started container task
0.7477,Event,ADDED,eval-sanitize-30-r2-038.18d4f7fd7b52df5f,reason=SuccessfulCreate count=1 msg=Created pod: eval-sanitize-30-r2-038-mmdbm
0.7482,Event,ADDED,eval-sanitize-30-r2-038.18d4f809065f4ff1,reason=Completed count=1 msg=Job completed
0.7485,Event,ADDED,eval-sanitize-30-r2-039-w494g.18d4f7fdb41a77f0,"reason=FailedScheduling count=None msg=0/6 nodes are available: 6 node(s) had untolerated taint(s). no new claims to deallocate, preemption: 0/6 nodes are available: 6 Preemption is not helpful for scheduling."
0.7489,Event,ADDED,eval-sanitize-30-r2-039-w494g.18d4f8008ce0f270,"reason=FailedScheduling count=None msg=0/6 nodes are available: 1 c_wall violated: 3 conflicting context pair(s) with node memory, 5 node(s) had untolerated taint(s). no new claims to deallocate, preemption: 0/6 nodes are available: 1 No preemption victims found for incoming pod, 5 Preemption is not helpful for scheduling."
0.7491,Event,ADDED,eval-sanitize-30-r2-039-w494g.18d4f800cee3c674,reason=Scheduled count=None msg=Successfully assigned compute/eval-sanitize-30-r2-039-w494g to kind-worker4
0.7494,Event,ADDED,eval-sanitize-30-r2-039-w494g.18d4f800eb742dba,"reason=Pulled count=1 msg=Container image ""busybox:musl"" already present on machine"
0.7498,Event,ADDED,eval-sanitize-30-r2-039-w494g.18d4f800ed667acc,reason=Created count=1 msg=Created container: task
0.75,Event,ADDED,eval-sanitize-30-r2-039-w494g.18d4f800f55fa85b,reason=Started count=1 msg=Started container task
0.7503,Event,ADDED,eval-sanitize-30-r2-039.18d4f7fdb416a027,reason=SuccessfulCreate count=1 msg=Created pod: eval-sanitize-30-r2-039-w494g
0.7505,Event,ADDED,eval-sanitize-30-r2-039.18d4f8080c099f8a,reason=Completed count=1 msg=Job completed
0.7507,Event,ADDED,eval-sanitize-30-r2-040-zjnhx.18d4f7fdefce4a64,"reason=FailedScheduling count=None msg=0/6 nodes are available: 6 node(s) had untolerated taint(s). no new claims to deallocate, preemption: 0/6 nodes are available: 6 Preemption is not helpful for scheduling."
0.7509,Event,ADDED,eval-sanitize-30-r2-040-zjnhx.18d4f8008dfd0a07,reason=Scheduled count=None msg=Successfully assigned compute/eval-sanitize-30-r2-040-zjnhx to kind-worker
0.7511,Event,ADDED,eval-sanitize-30-r2-040-zjnhx.18d4f800aca2d1a9,"reason=Pulled count=1 msg=Container image ""busybox:musl"" already present on machine"
0.7513,Event,ADDED,eval-sanitize-30-r2-040-zjnhx.18d4f800ae86bf30,reason=Created count=1 msg=Created container: task
0.7516,Event,ADDED,eval-sanitize-30-r2-040-zjnhx.18d4f800b17e8138,reason=Started count=1 msg=Started container task
0.7519,Event,ADDED,eval-sanitize-30-r2-040.18d4f7fdefc244bb,reason=SuccessfulCreate count=1 msg=Created pod: eval-sanitize-30-r2-040-zjnhx
0.7522,Event,ADDED,eval-sanitize-30-r2-040.18d4f805e8f55637,reason=Completed count=1 msg=Job completed
0.7524,Event,ADDED,eval-sanitize-30-r2-041-2xr4p.18d4f7fe2b870794,"reason=FailedScheduling count=None msg=0/6 nodes are available: 6 node(s) had untolerated taint(s). no new claims to deallocate, preemption: 0/6 nodes are available: 6 Preemption is not helpful for scheduling."
0.7526,Event,ADDED,eval-sanitize-30-r2-041-2xr4p.18d4f8008dd8e6c3,"reason=FailedScheduling count=None msg=0/6 nodes are available: 1 c_wall violated: 1 conflicting context pair(s) with node memory, 5 node(s) had untolerated taint(s). no new claims to deallocate, preemption: 0/6 nodes are available: 1 No preemption victims found for incoming pod, 5 Preemption is not helpful for scheduling."
0.7529,Event,ADDED,eval-sanitize-30-r2-041-2xr4p.18d4f800ceed454f,"reason=FailedScheduling count=None msg=0/6 nodes are available: 1 c_wall violated: 1 conflicting context pair(s) with node memory, 1 c_wall violated: 2 conflicting context pair(s) with node memory, 4 node(s) had untolerated taint(s). no new claims to deallocate, preemption: 0/6 nodes are available: 2 No preemption victims found for incoming pod, 4 Preemption is not helpful for scheduling."
0.7531,Event,ADDED,eval-sanitize-30-r2-041-2xr4p.18d4f80116543eb2,"reason=FailedScheduling count=None msg=0/6 nodes are available: 1 c_wall violated: 2 conflicting context pair(s) with node memory, 2 c_wall violated: 1 conflicting context pair(s) with node memory, 3 node(s) had untolerated taint(s). no new claims to deallocate, preemption: 0/6 nodes are available: 3 No preemption victims found for incoming pod, 3 Preemption is not helpful for scheduling."
0.7532,Event,ADDED,eval-sanitize-30-r2-041-2xr4p.18d4f80171fe0b8b,reason=Scheduled count=None msg=Successfully assigned compute/eval-sanitize-30-r2-041-2xr4p to kind-worker2
0.7537,Event,ADDED,eval-sanitize-30-r2-041-2xr4p.18d4f8018dfda09c,"reason=Pulled count=1 msg=Container image ""busybox:musl"" already present on machine"
0.7539,Event,ADDED,eval-sanitize-30-r2-041-2xr4p.18d4f8018fefcea9,reason=Created count=1 msg=Created container: task
0.7543,Event,ADDED,eval-sanitize-30-r2-041-2xr4p.18d4f80196bd5e51,reason=Started count=1 msg=Started container task
0.7546,Event,ADDED,eval-sanitize-30-r2-041.18d4f7fe2b7b79d9,reason=SuccessfulCreate count=1 msg=Created pod: eval-sanitize-30-r2-041-2xr4p
0.7549,Event,ADDED,eval-sanitize-30-r2-041.18d4f808fe41b639,reason=Completed count=1 msg=Job completed
0.7551,Event,ADDED,eval-sanitize-30-r2-042-mqrsk.18d4f7fe6aabb54b,"reason=FailedScheduling count=None msg=0/6 nodes are available: 6 node(s) had untolerated taint(s). no new claims to deallocate, preemption: 0/6 nodes are available: 6 Preemption is not helpful for scheduling."
0.7553,Event,ADDED,eval-sanitize-30-r2-042-mqrsk.18d4f80091008a87,"reason=FailedScheduling count=None msg=0/6 nodes are available: 1 c_wall violated: 2 conflicting context pair(s) with node memory, 5 node(s) had untolerated taint(s). no new claims to deallocate, preemption: 0/6 nodes are available: 1 No preemption victims found for incoming pod, 5 Preemption is not helpful for scheduling."
0.7556,Event,ADDED,eval-sanitize-30-r2-042-mqrsk.18d4f800d46a147a,"reason=FailedScheduling count=None msg=0/6 nodes are available: 2 c_wall violated: 2 conflicting context pair(s) with node memory, 4 node(s) had untolerated taint(s). no new claims to deallocate, preemption: 0/6 nodes are available: 2 No preemption victims found for incoming pod, 4 Preemption is not helpful for scheduling."
0.7557,Event,ADDED,eval-sanitize-30-r2-042-mqrsk.18d4f8011daa4776,reason=Scheduled count=None msg=Successfully assigned compute/eval-sanitize-30-r2-042-mqrsk to kind-worker5
0.756,Event,ADDED,eval-sanitize-30-r2-042-mqrsk.18d4f8014159c146,"reason=Pulled count=1 msg=Container image ""busybox:musl"" already present on machine"
0.7562,Event,ADDED,eval-sanitize-30-r2-042-mqrsk.18d4f80142caed46,reason=Created count=1 msg=Created container: task
0.7567,Event,ADDED,eval-sanitize-30-r2-042-mqrsk.18d4f8014c641beb,reason=Started count=1 msg=Started container task
0.757,Event,ADDED,eval-sanitize-30-r2-042.18d4f7fe6aa1d94f,reason=SuccessfulCreate count=1 msg=Created pod: eval-sanitize-30-r2-042-mqrsk
0.7573,Event,ADDED,eval-sanitize-30-r2-042.18d4f808b2cbf5e2,reason=Completed count=1 msg=Job completed
0.7578,Event,ADDED,eval-sanitize-30-r2-043-kfd48.18d4f7fea28c46e0,"reason=FailedScheduling count=None msg=0/6 nodes are available: 6 node(s) had untolerated taint(s). no new claims to deallocate, preemption: 0/6 nodes are available: 6 Preemption is not helpful for scheduling."
0.7581,Event,ADDED,eval-sanitize-30-r2-043-kfd48.18d4f80096e6f2cc,reason=Scheduled count=None msg=Successfully assigned compute/eval-sanitize-30-r2-043-kfd48 to kind-worker4
0.7586,Event,ADDED,eval-sanitize-30-r2-043-kfd48.18d4f800b0adf5c2,"reason=Pulled count=1 msg=Container image ""busybox:musl"" already present on machine"
0.7588,Event,ADDED,eval-sanitize-30-r2-043-kfd48.18d4f800b44f9efa,reason=Created count=1 msg=Created container: task
0.7591,Event,ADDED,eval-sanitize-30-r2-043-kfd48.18d4f800b9eb7e87,reason=Started count=1 msg=Started container task
0.7594,Event,ADDED,eval-sanitize-30-r2-043.18d4f7fea289ba7a,reason=SuccessfulCreate count=1 msg=Created pod: eval-sanitize-30-r2-043-kfd48
0.7598,Event,ADDED,eval-sanitize-30-r2-043.18d4f807302542ba,reason=Completed count=1 msg=Job completed
0.76,Event,ADDED,eval-sanitize-30-r2-044-n2c7g.18d4f7feded9e3ee,"reason=FailedScheduling count=None msg=0/6 nodes are available: 6 node(s) had untolerated taint(s). no new claims to deallocate, preemption: 0/6 nodes are available: 6 Preemption is not helpful for scheduling."
0.7605,Event,ADDED,eval-sanitize-30-r2-044-n2c7g.18d4f80097af307b,reason=Scheduled count=None msg=Successfully assigned compute/eval-sanitize-30-r2-044-n2c7g to kind-worker4
0.7608,Event,ADDED,eval-sanitize-30-r2-044-n2c7g.18d4f800b2289fee,"reason=Pulled count=1 msg=Container image ""busybox:musl"" already present on machine"
0.7612,Event,ADDED,eval-sanitize-30-r2-044-n2c7g.18d4f800b59439ec,reason=Created count=1 msg=Created container: task
0.7617,Event,ADDED,eval-sanitize-30-r2-044-n2c7g.18d4f800ba7bb86f,reason=Started count=1 msg=Started container task
0.7619,Event,ADDED,eval-sanitize-30-r2-044.18d4f7feded19e5c,reason=SuccessfulCreate count=1 msg=Created pod: eval-sanitize-30-r2-044-n2c7g
0.7621,Event,ADDED,eval-sanitize-30-r2-044.18d4f8073e377d3e,reason=Completed count=1 msg=Job completed
0.7622,Event,ADDED,eval-sanitize-30-r2-045-ncmlk.18d4f7ff19dc5c4e,"reason=FailedScheduling count=None msg=0/6 nodes are available: 6 node(s) had untolerated taint(s). no new claims to deallocate, preemption: 0/6 nodes are available: 6 Preemption is not helpful for scheduling."
0.7626,Event,ADDED,eval-sanitize-30-r2-045-ncmlk.18d4f80097f0b370,reason=Scheduled count=None msg=Successfully assigned compute/eval-sanitize-30-r2-045-ncmlk to kind-worker
0.7628,Event,ADDED,eval-sanitize-30-r2-045-ncmlk.18d4f800b2044f30,"reason=Pulled count=1 msg=Container image ""busybox:musl"" already present on machine"
0.7631,Event,ADDED,eval-sanitize-30-r2-045-ncmlk.18d4f800b41ba9f0,reason=Created count=1 msg=Created container: task
0.7634,Event,ADDED,eval-sanitize-30-r2-045-ncmlk.18d4f800b96880f8,reason=Started count=1 msg=Started container task
0.7637,Event,ADDED,eval-sanitize-30-r2-045.18d4f7ff19cc67f6,reason=SuccessfulCreate count=1 msg=Created pod: eval-sanitize-30-r2-045-ncmlk
0.764,Event,ADDED,eval-sanitize-30-r2-045.18d4f808048a4c17,reason=Completed count=1 msg=Job completed
0.7642,Event,ADDED,eval-sanitize-30-r2-046-bv2xj.18d4f7ff5559d644,"reason=FailedScheduling count=None msg=0/6 nodes are available: 6 node(s) had untolerated taint(s). no new claims to deallocate, preemption: 0/6 nodes are available: 6 Preemption is not helpful for scheduling."
0.7643,Event,ADDED,eval-sanitize-30-r2-046-bv2xj.18d4f8009a1ce51c,"reason=FailedScheduling count=None msg=0/6 nodes are available: 2 c_wall violated: 2 conflicting context pair(s) with node memory, 4 node(s) had untolerated taint(s). no new claims to deallocate, preemption: 0/6 nodes are available: 2 No preemption victims found for incoming pod, 4 Preemption is not helpful for scheduling."
0.7645,Event,ADDED,eval-sanitize-30-r2-046-bv2xj.18d4f800d5d770e2,reason=Scheduled count=None msg=Successfully assigned compute/eval-sanitize-30-r2-046-bv2xj to kind-worker3
0.7649,Event,ADDED,eval-sanitize-30-r2-046-bv2xj.18d4f800f58a9845,"reason=Pulled count=1 msg=Container image ""busybox:musl"" already present on machine"
0.7653,Event,ADDED,eval-sanitize-30-r2-046-bv2xj.18d4f800f77aafef,reason=Created count=1 msg=Created container: task
0.7657,Event,ADDED,eval-sanitize-30-r2-046-bv2xj.18d4f800fc01be51,reason=Started count=1 msg=Started container task
0.766,Event,ADDED,eval-sanitize-30-r2-046.18d4f7ff554dc857,reason=SuccessfulCreate count=1 msg=Created pod: eval-sanitize-30-r2-046-bv2xj
0.7662,Event,ADDED,eval-sanitize-30-r2-046.18d4f807a8a30058,reason=Completed count=1 msg=Job completed
0.7664,Event,ADDED,eval-sanitize-30-r2-047-4xqwx.18d4f7ff91053691,"reason=FailedScheduling count=None msg=0/6 nodes are available: 6 node(s) had untolerated taint(s). no new claims to deallocate, preemption: 0/6 nodes are available: 6 Preemption is not helpful for scheduling."
0.7667,Event,ADDED,eval-sanitize-30-r2-047-4xqwx.18d4f8009ead1682,reason=Scheduled count=None msg=Successfully assigned compute/eval-sanitize-30-r2-047-4xqwx to kind-worker4
0.767,Event,ADDED,eval-sanitize-30-r2-047-4xqwx.18d4f800bb843f2d,"reason=Pulled count=1 msg=Container image ""busybox:musl"" already present on machine"
0.7673,Event,ADDED,eval-sanitize-30-r2-047-4xqwx.18d4f800bdcd6205,reason=Created count=1 msg=Created container: task
0.7675,Event,ADDED,eval-sanitize-30-r2-047-4xqwx.18d4f800c2549a5e,reason=Started count=1 msg=Started container task
0.7677,Event,ADDED,eval-sanitize-30-r2-047.18d4f7ff90fa2d58,reason=SuccessfulCreate count=1 msg=Created pod: eval-sanitize-30-r2-047-4xqwx
0.768,Event,ADDED,eval-sanitize-30-r2-047.18d4f8079dc5e614,reason=Completed count=1 msg=Job completed
0.7683,Event,ADDED,eval-sanitize-30-r2-048-bqn89.18d4f7ffce29fd28,"reason=FailedScheduling count=None msg=0/6 nodes are available: 6 node(s) had untolerated taint(s). no new claims to deallocate, preemption: 0/6 nodes are available: 6 Preemption is not helpful for scheduling."
0.7685,Event,ADDED,eval-sanitize-30-r2-048-bqn89.18d4f8009f7f625d,reason=Scheduled count=None msg=Successfully assigned compute/eval-sanitize-30-r2-048-bqn89 to kind-worker4
0.769,Event,ADDED,eval-sanitize-30-r2-048-bqn89.18d4f800bbf333b1,"reason=Pulled count=1 msg=Container image ""busybox:musl"" already present on machine"
0.7693,Event,ADDED,eval-sanitize-30-r2-048-bqn89.18d4f800be872b44,reason=Created count=1 msg=Created container: task
0.7697,Event,ADDED,eval-sanitize-30-r2-048-bqn89.18d4f800c29a895a,reason=Started count=1 msg=Started container task
0.7699,Event,ADDED,eval-sanitize-30-r2-048.18d4f7ffce1e110b,reason=SuccessfulCreate count=1 msg=Created pod: eval-sanitize-30-r2-048-bqn89
0.7702,Event,ADDED,eval-sanitize-30-r2-048.18d4f80883413498,reason=Completed count=1 msg=Job completed
0.7705,Event,ADDED,eval-sanitize-30-r2-049-r4tbw.18d4f800082a6363,"reason=FailedScheduling count=None msg=0/6 nodes are available: 6 node(s) had untolerated taint(s). no new claims to deallocate, preemption: 0/6 nodes are available: 6 Preemption is not helpful for scheduling."
0.7708,Event,ADDED,eval-sanitize-30-r2-049-r4tbw.18d4f800a2d427d4,reason=Scheduled count=None msg=Successfully assigned compute/eval-sanitize-30-r2-049-r4tbw to kind-worker
0.7712,Event,ADDED,eval-sanitize-30-r2-049-r4tbw.18d4f800bd3a7b86,"reason=Pulled count=1 msg=Container image ""busybox:musl"" already present on machine"
0.7714,Event,ADDED,eval-sanitize-30-r2-049-r4tbw.18d4f800bf34fc86,reason=Created count=1 msg=Created container: task
0.7716,Event,ADDED,eval-sanitize-30-r2-049-r4tbw.18d4f800c43da7d3,reason=Started count=1 msg=Started container task
0.7718,Event,ADDED,eval-sanitize-30-r2-049.18d4f8000825e6dc,reason=SuccessfulCreate count=1 msg=Created pod: eval-sanitize-30-r2-049-r4tbw
0.772,Event,ADDED,eval-sanitize-30-r2-049.18d4f8080653a7be,reason=Completed count=1 msg=Job completed
0.7722,Event,ADDED,eval-sanitize-30-r2-050-2d8ms.18d4f800451a6309,"reason=FailedScheduling count=None msg=0/6 nodes are available: 6 node(s) had untolerated taint(s). no new claims to deallocate, preemption: 0/6 nodes are available: 6 Preemption is not helpful for scheduling."
0.7724,Event,ADDED,eval-sanitize-30-r2-050-2d8ms.18d4f800a50f4416,"reason=FailedScheduling count=None msg=0/6 nodes are available: 2 c_wall violated: 2 conflicting context pair(s) with node memory, 4 node(s) had untolerated taint(s). no new claims to deallocate, preemption: 0/6 nodes are available: 2 No preemption victims found for incoming pod, 4 Preemption is not helpful for scheduling."
0.7725,Event,ADDED,eval-sanitize-30-r2-050-2d8ms.18d4f800db5aced6,reason=Scheduled count=None msg=Successfully assigned compute/eval-sanitize-30-r2-050-2d8ms to kind-worker3
0.7727,Event,ADDED,eval-sanitize-30-r2-050-2d8ms.18d4f800fc07d121,"reason=Pulled count=1 msg=Container image ""busybox:musl"" already present on machine"
0.7729,Event,ADDED,eval-sanitize-30-r2-050-2d8ms.18d4f8010177faff,reason=Created count=1 msg=Created container: task
0.773,Event,ADDED,eval-sanitize-30-r2-050-2d8ms.18d4f801061b2766,reason=Started count=1 msg=Started container task
0.7732,Event,ADDED,eval-sanitize-30-r2-050.18d4f80045112ade,reason=SuccessfulCreate count=1 msg=Created pod: eval-sanitize-30-r2-050-2d8ms
0.7734,Event,ADDED,eval-sanitize-30-r2-050.18d4f80841eac43d,reason=Completed count=1 msg=Job completed
0.7737,Event,ADDED,eval-sanitize-30-r2-051-sl2v5.18d4f800a519853a,reason=Scheduled count=None msg=Successfully assigned compute/eval-sanitize-30-r2-051-sl2v5 to kind-worker
0.7739,Event,ADDED,eval-sanitize-30-r2-051-sl2v5.18d4f800c1b04f10,"reason=Pulled count=1 msg=Container image ""busybox:musl"" already present on machine"
0.7742,Event,ADDED,eval-sanitize-30-r2-051-sl2v5.18d4f800c3b4e327,reason=Created count=1 msg=Created container: task
0.7744,Event,ADDED,eval-sanitize-30-r2-051-sl2v5.18d4f800cc9afb5c,reason=Started count=1 msg=Started container task
0.7746,Event,ADDED,eval-sanitize-30-r2-051.18d4f80080194131,reason=SuccessfulCreate count=1 msg=Created pod: eval-sanitize-30-r2-051-sl2v5
0.7752,Event,ADDED,eval-sanitize-30-r2-051.18d4f807d690587f,reason=Completed count=1 msg=Job completed
0.7754,Event,ADDED,eval-sanitize-30-r2-052-5r55g.18d4f800c2b84d3e,"reason=FailedScheduling count=None msg=0/6 nodes are available: 1 c_wall violated: 1 conflicting context pair(s) with node memory, 1 c_wall violated: 2 conflicting context pair(s) with node memory, 4 node(s) had untolerated taint(s). no new claims to deallocate, preemption: 0/6 nodes are available: 2 No preemption victims found for incoming pod, 4 Preemption is not helpful for scheduling."
0.7755,Event,ADDED,eval-sanitize-30-r2-052-5r55g.18d4f8010b5c55ba,"reason=FailedScheduling count=None msg=0/6 nodes are available: 1 c_wall violated: 2 conflicting context pair(s) with node memory, 2 c_wall violated: 1 conflicting context pair(s) with node memory, 3 node(s) had untolerated taint(s). no new claims to deallocate, preemption: 0/6 nodes are available: 3 No preemption victims found for incoming pod, 3 Preemption is not helpful for scheduling."
0.7757,Event,ADDED,eval-sanitize-30-r2-052-5r55g.18d4f8015bbbd336,reason=Scheduled count=None msg=Successfully assigned compute/eval-sanitize-30-r2-052-5r55g to kind-worker2
0.776,Event,ADDED,eval-sanitize-30-r2-052-5r55g.18d4f8017aca56d0,"reason=Pulled count=1 msg=Container image ""busybox:musl"" already present on machine"
0.7764,Event,ADDED,eval-sanitize-30-r2-052-5r55g.18d4f8017c5b219c,reason=Created count=1 msg=Created container: task
0.7766,Event,ADDED,eval-sanitize-30-r2-052-5r55g.18d4f80181c9610e,reason=Started count=1 msg=Started container task
0.777,Event,ADDED,eval-sanitize-30-r2-052.18d4f800bcb88a77,reason=SuccessfulCreate count=1 msg=Created pod: eval-sanitize-30-r2-052-5r55g
0.7773,Event,ADDED,eval-sanitize-30-r2-052.18d4f808eecea96d,reason=Completed count=1 msg=Job completed
0.7777,Event,ADDED,eval-sanitize-30-r2-053-c69tt.18d4f8010199d840,reason=Scheduled count=None msg=Successfully assigned compute/eval-sanitize-30-r2-053-c69tt to kind-worker4
0.7779,Event,ADDED,eval-sanitize-30-r2-053-c69tt.18d4f8012d966a0b,"reason=Pulled count=1 msg=Container image ""busybox:musl"" already present on machine"
0.7781,Event,ADDED,eval-sanitize-30-r2-053-c69tt.18d4f8012ec7df05,reason=Created count=1 msg=Created container: task
0.7783,Event,ADDED,eval-sanitize-30-r2-053-c69tt.18d4f80136af8488,reason=Started count=1 msg=Started container task
0.7785,Event,ADDED,eval-sanitize-30-r2-053.18d4f800f7c4e776,reason=SuccessfulCreate count=1 msg=Created pod: eval-sanitize-30-r2-053-c69tt
0.7787,Event,ADDED,eval-sanitize-30-r2-053.18d4f808121f0c6a,reason=Completed count=1 msg=Job completed
0.779,Event,ADDED,eval-sanitize-30-r2-054-wztsh.18d4f8014fb1c805,reason=Scheduled count=None msg=Successfully assigned compute/eval-sanitize-30-r2-054-wztsh to kind-worker3
0.7794,Event,ADDED,eval-sanitize-30-r2-054-wztsh.18d4f80171f16c82,"reason=Pulled count=1 msg=Container image ""busybox:musl"" already present on machine"
0.7796,Event,ADDED,eval-sanitize-30-r2-054-wztsh.18d4f801749d76fb,reason=Created count=1 msg=Created container: task
0.7799,Event,ADDED,eval-sanitize-30-r2-054-wztsh.18d4f801797f65ee,reason=Started count=1 msg=Started container task
0.7801,Event,ADDED,eval-sanitize-30-r2-054.18d4f8013a7a0529,reason=SuccessfulCreate count=1 msg=Created pod: eval-sanitize-30-r2-054-wztsh
0.7804,Event,ADDED,eval-sanitize-30-r2-054.18d4f809007d6e57,reason=Completed count=1 msg=Job completed
0.7806,Event,ADDED,eval-sanitize-30-r2-055-mbxnk.18d4f8017be9536c,reason=Scheduled count=None msg=Successfully assigned compute/eval-sanitize-30-r2-055-mbxnk to kind-worker2
0.781,Event,ADDED,eval-sanitize-30-r2-055-mbxnk.18d4f8019df722e0,"reason=Pulled count=1 msg=Container image ""busybox:musl"" already present on machine"
0.7812,Event,ADDED,eval-sanitize-30-r2-055-mbxnk.18d4f8019f3a8541,reason=Created count=1 msg=Created container: task
0.7815,Event,ADDED,eval-sanitize-30-r2-055-mbxnk.18d4f801a4f5d014,reason=Started count=1 msg=Started container task
0.7818,Event,ADDED,eval-sanitize-30-r2-055.18d4f801760cd2a5,reason=SuccessfulCreate count=1 msg=Created pod: eval-sanitize-30-r2-055-mbxnk
0.7822,Event,ADDED,eval-sanitize-30-r2-055.18d4f808d1bbd064,reason=Completed count=1 msg=Job completed
0.7825,Event,ADDED,eval-sanitize-30-r2-056-8mt2t.18d4f801b2445b7a,reason=Scheduled count=None msg=Successfully assigned compute/eval-sanitize-30-r2-056-8mt2t to kind-worker2
0.7827,Event,ADDED,eval-sanitize-30-r2-056-8mt2t.18d4f801cf1fe5c3,"reason=Pulled count=1 msg=Container image ""busybox:musl"" already present on machine"
0.783,Event,ADDED,eval-sanitize-30-r2-056-8mt2t.18d4f801d06d3092,reason=Created count=1 msg=Created container: task
0.7832,Event,ADDED,eval-sanitize-30-r2-056-8mt2t.18d4f801d7b25c85,reason=Started count=1 msg=Started container task
0.7834,Event,ADDED,eval-sanitize-30-r2-056.18d4f801a9cecfd7,reason=SuccessfulCreate count=1 msg=Created pod: eval-sanitize-30-r2-056-8mt2t
0.7836,Event,ADDED,eval-sanitize-30-r2-056.18d4f809124e80c5,reason=Completed count=1 msg=Job completed
0.7838,Event,ADDED,eval-sanitize-30-r2-057-zsq42.18d4f801eda35b39,reason=Scheduled count=None msg=Successfully assigned compute/eval-sanitize-30-r2-057-zsq42 to kind-worker2
0.7841,Event,ADDED,eval-sanitize-30-r2-057-zsq42.18d4f802095223bf,"reason=Pulled count=1 msg=Container image ""busybox:musl"" already present on machine"
0.7842,Event,ADDED,eval-sanitize-30-r2-057-zsq42.18d4f8020ab2c02e,reason=Created count=1 msg=Created container: task
0.7844,Event,ADDED,eval-sanitize-30-r2-057-zsq42.18d4f80212935d89,reason=Started count=1 msg=Started container task
0.7849,Event,ADDED,eval-sanitize-30-r2-057.18d4f801e9cd11b8,reason=SuccessfulCreate count=1 msg=Created pod: eval-sanitize-30-r2-057-zsq42
0.7852,Event,ADDED,eval-sanitize-30-r2-057.18d4f8092d23d347,reason=Completed count=1 msg=Job completed
0.7855,Event,ADDED,eval-sanitize-30-r2-058-84b4k.18d4f80229220762,reason=Scheduled count=None msg=Successfully assigned compute/eval-sanitize-30-r2-058-84b4k to kind-worker5
0.7858,Event,ADDED,eval-sanitize-30-r2-058-84b4k.18d4f8024b2893f8,"reason=Pulled count=1 msg=Container image ""busybox:musl"" already present on machine"
0.7862,Event,ADDED,eval-sanitize-30-r2-058-84b4k.18d4f8024c66af2b,reason=Created count=1 msg=Created container: task
0.7864,Event,ADDED,eval-sanitize-30-r2-058-84b4k.18d4f8025371e334,reason=Started count=1 msg=Started container task
0.7866,Event,ADDED,eval-sanitize-30-r2-058.18d4f8022231ad5b,reason=SuccessfulCreate count=1 msg=Created pod: eval-sanitize-30-r2-058-84b4k
0.7868,Event,ADDED,eval-sanitize-30-r2-058.18d4f8094b2a2125,reason=Completed count=1 msg=Job completed
0.7871,Event,ADDED,eval-sanitize-30-r2-059-wfkb5.18d4f802646b6cff,reason=Scheduled count=None msg=Successfully assigned compute/eval-sanitize-30-r2-059-wfkb5 to kind-worker4
0.7873,Event,ADDED,eval-sanitize-30-r2-059-wfkb5.18d4f80284a6b64b,"reason=Pulled count=1 msg=Container image ""busybox:musl"" already present on machine"
0.7876,Event,ADDED,eval-sanitize-30-r2-059-wfkb5.18d4f80285eea401,reason=Created count=1 msg=Created container: task
0.788,Event,ADDED,eval-sanitize-30-r2-059-wfkb5.18d4f8028f1e19d3,reason=Started count=1 msg=Started container task
0.7882,Event,ADDED,eval-sanitize-30-r2-059.18d4f80261c8d2bd,reason=SuccessfulCreate count=1 msg=Created pod: eval-sanitize-30-r2-059-wfkb5
0.7884,Event,ADDED,eval-sanitize-30-r2-059.18d4f8094e07148d,reason=Completed count=1 msg=Job completed
0.7888,Event,ADDED,eval-sanitize-30-r2-060-g4wdf.18d4f802ac35b58c,reason=Scheduled count=None msg=Successfully assigned compute/eval-sanitize-30-r2-060-g4wdf to kind-worker4
0.789,Event,ADDED,eval-sanitize-30-r2-060-g4wdf.18d4f802c8e0d2fd,"reason=Pulled count=1 msg=Container image ""busybox:musl"" already present on machine"
0.7892,Event,ADDED,eval-sanitize-30-r2-060-g4wdf.18d4f802ca2eedff,reason=Created count=1 msg=Created container: task
0.7893,Event,ADDED,eval-sanitize-30-r2-060-g4wdf.18d4f802cd1f8e08,reason=Started count=1 msg=Started container task
0.7898,Event,ADDED,eval-sanitize-30-r2-060.18d4f802a1a925b3,reason=SuccessfulCreate count=1 msg=Created pod: eval-sanitize-30-r2-060-g4wdf
0.7901,Event,ADDED,eval-sanitize-30-r2-060.18d4f80965f066d1,reason=Completed count=1 msg=Job completed
0.7903,Event,ADDED,eval-sanitize-30-r2-061-rknmq.18d4f802dba37c75,reason=Scheduled count=None msg=Successfully assigned compute/eval-sanitize-30-r2-061-rknmq to kind-worker4
0.7904,Event,ADDED,eval-sanitize-30-r2-061-rknmq.18d4f8030117cb56,"reason=Pulled count=1 msg=Container image ""busybox:musl"" already present on machine"
0.791,Event,ADDED,eval-sanitize-30-r2-061-rknmq.18d4f8030275f205,reason=Created count=1 msg=Created container: task
0.7913,Event,ADDED,eval-sanitize-30-r2-061-rknmq.18d4f80307b47567,reason=Started count=1 msg=Started container task
0.7916,Event,ADDED,eval-sanitize-30-r2-061.18d4f802d6893afb,reason=SuccessfulCreate count=1 msg=Created pod: eval-sanitize-30-r2-061-rknmq
0.792,Event,ADDED,eval-sanitize-30-r2-061.18d4f8097a8b2177,reason=Completed count=1 msg=Job completed
0.7922,Event,ADDED,eval-sanitize-30-r2-062-gqr2f.18d4f8031a05f590,reason=Scheduled count=None msg=Successfully assigned compute/eval-sanitize-30-r2-062-gqr2f to kind-worker4
0.7924,Event,ADDED,eval-sanitize-30-r2-062-gqr2f.18d4f803362b44a4,"reason=Pulled count=1 msg=Container image ""busybox:musl"" already present on machine"
0.7926,Event,ADDED,eval-sanitize-30-r2-062-gqr2f.18d4f8033773bb16,reason=Created count=1 msg=Created container: task
0.7931,Event,ADDED,eval-sanitize-30-r2-062-gqr2f.18d4f8033cd2c248,reason=Started count=1 msg=Started container task
0.7935,Event,ADDED,eval-sanitize-30-r2-062.18d4f80312d2f527,reason=SuccessfulCreate count=1 msg=Created pod: eval-sanitize-30-r2-062-gqr2f
0.7939,Event,ADDED,eval-sanitize-30-r2-062.18d4f80990606f84,reason=Completed count=1 msg=Job completed
0.7942,Event,ADDED,eval-sanitize-30-r2-063-dtz2v.18d4f8035697f0d5,reason=Scheduled count=None msg=Successfully assigned compute/eval-sanitize-30-r2-063-dtz2v to kind-worker4
0.7945,Event,ADDED,eval-sanitize-30-r2-063-dtz2v.18d4f8037e37442d,"reason=Pulled count=1 msg=Container image ""busybox:musl"" already present on machine"
0.7948,Event,ADDED,eval-sanitize-30-r2-063-dtz2v.18d4f8037fedd167,reason=Created count=1 msg=Created container: task
0.795,Event,ADDED,eval-sanitize-30-r2-063-dtz2v.18d4f8038919e505,reason=Started count=1 msg=Started container task
0.7952,Event,ADDED,eval-sanitize-30-r2-063.18d4f8034c2032ac,reason=SuccessfulCreate count=1 msg=Created pod: eval-sanitize-30-r2-063-dtz2v
0.7954,Event,ADDED,eval-sanitize-30-r2-063.18d4f8099b56cea4,reason=Completed count=1 msg=Job completed
0.7956,Event,ADDED,eval-sanitize-30-r2-064-g9mkh.18d4f8038f72bde8,reason=Scheduled count=None msg=Successfully assigned compute/eval-sanitize-30-r2-064-g9mkh to kind-worker5
0.7958,Event,ADDED,eval-sanitize-30-r2-064-g9mkh.18d4f803b7a63fb4,"reason=Pulled count=1 msg=Container image ""busybox:musl"" already present on machine"
0.796,Event,ADDED,eval-sanitize-30-r2-064-g9mkh.18d4f803b9396c5f,reason=Created count=1 msg=Created container: task
0.7961,Event,ADDED,eval-sanitize-30-r2-064-g9mkh.18d4f803c2cb488f,reason=Started count=1 msg=Started container task
0.7963,Event,ADDED,eval-sanitize-30-r2-064.18d4f8038b0616fa,reason=SuccessfulCreate count=1 msg=Created pod: eval-sanitize-30-r2-064-g9mkh
0.7965,Event,ADDED,eval-sanitize-30-r2-064.18d4f809bce13d29,reason=Completed count=1 msg=Job completed
0.7967,Event,ADDED,eval-sanitize-30-r2-065-ljqsn.18d4f803ca12092a,reason=Scheduled count=None msg=Successfully assigned compute/eval-sanitize-30-r2-065-ljqsn to kind-worker2
0.7968,Event,ADDED,eval-sanitize-30-r2-065-ljqsn.18d4f803ecc7c54d,"reason=Pulled count=1 msg=Container image ""busybox:musl"" already present on machine"
0.797,Event,ADDED,eval-sanitize-30-r2-065-ljqsn.18d4f803ee3d8b14,reason=Created count=1 msg=Created container: task
0.7972,Event,ADDED,eval-sanitize-30-r2-065-ljqsn.18d4f803f2a12bf8,reason=Started count=1 msg=Started container task
0.7974,Event,ADDED,eval-sanitize-30-r2-065.18d4f803c631bd84,reason=SuccessfulCreate count=1 msg=Created pod: eval-sanitize-30-r2-065-ljqsn
0.7977,Event,ADDED,eval-sanitize-30-r2-065.18d4f809925a29fd,reason=Completed count=1 msg=Job completed
0.7979,Event,ADDED,eval-sanitize-30-r2-066-2mq9h.18d4f80406edd483,reason=Scheduled count=None msg=Successfully assigned compute/eval-sanitize-30-r2-066-2mq9h to kind-worker
0.7983,Event,ADDED,eval-sanitize-30-r2-066-2mq9h.18d4f80429a47973,"reason=Pulled count=1 msg=Container image ""busybox:musl"" already present on machine"
0.7985,Event,ADDED,eval-sanitize-30-r2-066-2mq9h.18d4f8042b42289d,reason=Created count=1 msg=Created container: task
0.799,Event,ADDED,eval-sanitize-30-r2-066-2mq9h.18d4f804323c32f8,reason=Started count=1 msg=Started container task
0.7993,Event,ADDED,eval-sanitize-30-r2-066.18d4f803fe837501,reason=SuccessfulCreate count=1 msg=Created pod: eval-sanitize-30-r2-066-2mq9h
0.7995,Event,ADDED,eval-sanitize-30-r2-066.18d4f809b9a60852,reason=Completed count=1 msg=Job completed
0.8,Event,ADDED,eval-sanitize-30-r2-067-6rrxz.18d4f8044522026a,reason=Scheduled count=None msg=Successfully assigned compute/eval-sanitize-30-r2-067-6rrxz to kind-worker4
0.8002,Event,ADDED,eval-sanitize-30-r2-067-6rrxz.18d4f804654186f4,"reason=Pulled count=1 msg=Container image ""busybox:musl"" already present on machine"
0.8005,Event,ADDED,eval-sanitize-30-r2-067-6rrxz.18d4f80466aff0e4,reason=Created count=1 msg=Created container: task
0.8007,Event,ADDED,eval-sanitize-30-r2-067-6rrxz.18d4f8046e9c7dad,reason=Started count=1 msg=Started container task
0.8009,Event,ADDED,eval-sanitize-30-r2-067.18d4f8043e024748,reason=SuccessfulCreate count=1 msg=Created pod: eval-sanitize-30-r2-067-6rrxz
0.8011,Event,ADDED,eval-sanitize-30-r2-067.18d4f80a3caeb246,reason=Completed count=1 msg=Job completed
0.8014,Event,ADDED,eval-sanitize-30-r2-068-sc8lt.18d4f8047ce0e3f9,reason=Scheduled count=None msg=Successfully assigned compute/eval-sanitize-30-r2-068-sc8lt to kind-worker4
0.8017,Event,ADDED,eval-sanitize-30-r2-068-sc8lt.18d4f80498438117,"reason=Pulled count=1 msg=Container image ""busybox:musl"" already present on machine"
0.8019,Event,ADDED,eval-sanitize-30-r2-068-sc8lt.18d4f80499953724,reason=Created count=1 msg=Created container: task
0.8023,Event,ADDED,eval-sanitize-30-r2-068-sc8lt.18d4f804a0b2d675,reason=Started count=1 msg=Started container task
0.8026,Event,ADDED,eval-sanitize-30-r2-068.18d4f80477251ad7,reason=SuccessfulCreate count=1 msg=Created pod: eval-sanitize-30-r2-068-sc8lt
0.803,Event,ADDED,eval-sanitize-30-r2-068.18d4f80a2e26b967,reason=Completed count=1 msg=Job completed
0.8032,Event,ADDED,eval-sanitize-30-r2-069-8h6qc.18d4f804bad2bed7,reason=Scheduled count=None msg=Successfully assigned compute/eval-sanitize-30-r2-069-8h6qc to kind-worker4
0.8035,Event,ADDED,eval-sanitize-30-r2-069-8h6qc.18d4f804e2ce21ed,"reason=Pulled count=1 msg=Container image ""busybox:musl"" already present on machine"
0.8037,Event,ADDED,eval-sanitize-30-r2-069-8h6qc.18d4f804e4338d40,reason=Created count=1 msg=Created container: task
0.8039,Event,ADDED,eval-sanitize-30-r2-069-8h6qc.18d4f804eb872ba7,reason=Started count=1 msg=Started container task
0.8042,Event,ADDED,eval-sanitize-30-r2-069.18d4f804b0b4e2fa,reason=SuccessfulCreate count=1 msg=Created pod: eval-sanitize-30-r2-069-8h6qc
0.8045,Event,ADDED,eval-sanitize-30-r2-069.18d4f80a62ca1efc,reason=Completed count=1 msg=Job completed
0.8047,Event,ADDED,eval-sanitize-30-r2-070-g29w2.18d4f804fc8580f5,reason=Scheduled count=None msg=Successfully assigned compute/eval-sanitize-30-r2-070-g29w2 to kind-worker2
0.8051,Event,ADDED,eval-sanitize-30-r2-070-g29w2.18d4f805237ff918,"reason=Pulled count=1 msg=Container image ""busybox:musl"" already present on machine"
0.8054,Event,ADDED,eval-sanitize-30-r2-070-g29w2.18d4f80524dbdf25,reason=Created count=1 msg=Created container: task
0.8057,Event,ADDED,eval-sanitize-30-r2-070-g29w2.18d4f8052a6b94a8,reason=Started count=1 msg=Started container task
0.8059,Event,ADDED,eval-sanitize-30-r2-070.18d4f804edd80acb,reason=SuccessfulCreate count=1 msg=Created pod: eval-sanitize-30-r2-070-g29w2
0.8061,Event,ADDED,eval-sanitize-30-r2-070.18d4f80aa06b9421,reason=Completed count=1 msg=Job completed
0.8066,Event,ADDED,eval-sanitize-30-r2-071-6lrvb.18d4f8052f1c86f8,reason=Scheduled count=None msg=Successfully assigned compute/eval-sanitize-30-r2-071-6lrvb to kind-worker5
0.8069,Event,ADDED,eval-sanitize-30-r2-071-6lrvb.18d4f8054da2e4f0,"reason=Pulled count=1 msg=Container image ""busybox:musl"" already present on machine"
0.8071,Event,ADDED,eval-sanitize-30-r2-071-6lrvb.18d4f8054efa2f76,reason=Created count=1 msg=Created container: task
0.8073,Event,ADDED,eval-sanitize-30-r2-071-6lrvb.18d4f8055aef239a,reason=Started count=1 msg=Started container task
0.8075,Event,ADDED,eval-sanitize-30-r2-071.18d4f80527f6b9f6,reason=SuccessfulCreate count=1 msg=Created pod: eval-sanitize-30-r2-071-6lrvb
0.8077,Event,ADDED,eval-sanitize-30-r2-071.18d4f80adf836a2b,reason=Completed count=1 msg=Job completed
0.8078,Event,ADDED,eval-sanitize-30-r2-072-z444l.18d4f8057130df1c,reason=Scheduled count=None msg=Successfully assigned compute/eval-sanitize-30-r2-072-z444l to kind-worker5
0.808,Event,ADDED,eval-sanitize-30-r2-072-z444l.18d4f8058da89a2c,"reason=Pulled count=1 msg=Container image ""busybox:musl"" already present on machine"
0.8082,Event,ADDED,eval-sanitize-30-r2-072-z444l.18d4f8058ef57b5d,reason=Created count=1 msg=Created container: task
0.8086,Event,ADDED,eval-sanitize-30-r2-072-z444l.18d4f80595925e22,reason=Started count=1 msg=Started container task
0.8088,Event,ADDED,eval-sanitize-30-r2-072.18d4f80568031898,reason=SuccessfulCreate count=1 msg=Created pod: eval-sanitize-30-r2-072-z444l
0.8091,Event,ADDED,eval-sanitize-30-r2-072.18d4f80b1b821160,reason=Completed count=1 msg=Job completed
0.8093,Event,ADDED,eval-sanitize-30-r2-073-jzmv5.18d4f805a74b1849,reason=Scheduled count=None msg=Successfully assigned compute/eval-sanitize-30-r2-073-jzmv5 to kind-worker3
0.8098,Event,ADDED,eval-sanitize-30-r2-073-jzmv5.18d4f805cae62921,"reason=Pulled count=1 msg=Container image ""busybox:musl"" already present on machine"
0.8101,Event,ADDED,eval-sanitize-30-r2-073-jzmv5.18d4f805cc9ed769,reason=Created count=1 msg=Created container: task
0.8105,Event,ADDED,eval-sanitize-30-r2-073-jzmv5.18d4f805d32aaa99,reason=Started count=1 msg=Started container task
0.8107,Event,ADDED,eval-sanitize-30-r2-073.18d4f8059fcf3558,reason=SuccessfulCreate count=1 msg=Created pod: eval-sanitize-30-r2-073-jzmv5
0.8109,Event,ADDED,eval-sanitize-30-r2-073.18d4f80b5e198439,reason=Completed count=1 msg=Job completed
0.8111,Event,ADDED,eval-sanitize-30-r2-074-fxhh9.18d4f805e2c4b226,reason=Scheduled count=None msg=Successfully assigned compute/eval-sanitize-30-r2-074-fxhh9 to kind-worker
0.8114,Event,ADDED,eval-sanitize-30-r2-074-fxhh9.18d4f805feba6815,"reason=Pulled count=1 msg=Container image ""busybox:musl"" already present on machine"
0.8117,Event,ADDED,eval-sanitize-30-r2-074-fxhh9.18d4f806003ba4b6,reason=Created count=1 msg=Created container: task
0.8118,Event,ADDED,eval-sanitize-30-r2-074-fxhh9.18d4f80604a0c26e,reason=Started count=1 msg=Started container task
0.8121,Event,ADDED,eval-sanitize-30-r2-074.18d4f805dc11771e,reason=SuccessfulCreate count=1 msg=Created pod: eval-sanitize-30-r2-074-fxhh9
0.8123,Event,ADDED,eval-sanitize-30-r2-074.18d4f80b8343a54e,reason=Completed count=1 msg=Job completed
0.8125,Event,ADDED,eval-sanitize-30-r2-075-jz5sr.18d4f806243c6ccb,reason=Scheduled count=None msg=Successfully assigned compute/eval-sanitize-30-r2-075-jz5sr to kind-worker
0.8126,Event,ADDED,eval-sanitize-30-r2-075-jz5sr.18d4f806401decb8,"reason=Pulled count=1 msg=Container image ""busybox:musl"" already present on machine"
0.8129,Event,ADDED,eval-sanitize-30-r2-075-jz5sr.18d4f80641d3178c,reason=Created count=1 msg=Created container: task
0.813,Event,ADDED,eval-sanitize-30-r2-075-jz5sr.18d4f8064b40d456,reason=Started count=1 msg=Started container task
0.8132,Event,ADDED,eval-sanitize-30-r2-075.18d4f8061d676eb1,reason=SuccessfulCreate count=1 msg=Created pod: eval-sanitize-30-r2-075-jz5sr
0.8137,Event,ADDED,eval-sanitize-30-r2-075.18d4f80bbf6f886c,reason=Completed count=1 msg=Job completed
0.814,Event,ADDED,eval-sanitize-30-r2-076-vhhk6.18d4f806bf25b7ed,reason=Scheduled count=None msg=Successfully assigned compute/eval-sanitize-30-r2-076-vhhk6 to kind-worker3
0.8141,Event,ADDED,eval-sanitize-30-r2-076-vhhk6.18d4f806dc991fcc,"reason=Pulled count=1 msg=Container image ""busybox:musl"" already present on machine"
0.8143,Event,ADDED,eval-sanitize-30-r2-076-vhhk6.18d4f806de115fc0,reason=Created count=1 msg=Created container: task
0.8145,Event,ADDED,eval-sanitize-30-r2-076-vhhk6.18d4f806e7feef13,reason=Started count=1 msg=Started container task
0.8147,Event,ADDED,eval-sanitize-30-r2-076.18d4f806bb51b664,reason=SuccessfulCreate count=1 msg=Created pod: eval-sanitize-30-r2-076-vhhk6
0.815,Event,ADDED,eval-sanitize-30-r2-076.18d4f80c7bf2acc1,reason=Completed count=1 msg=Job completed
0.8153,Event,ADDED,eval-sanitize-30-r2-077-7h78k.18d4f8073e679110,reason=Scheduled count=None msg=Successfully assigned compute/eval-sanitize-30-r2-077-7h78k to kind-worker4
0.8157,Event,ADDED,eval-sanitize-30-r2-077-7h78k.18d4f8075a093933,"reason=Pulled count=1 msg=Container image ""busybox:musl"" already present on machine"
0.816,Event,ADDED,eval-sanitize-30-r2-077-7h78k.18d4f8075b821cca,reason=Created count=1 msg=Created container: task
0.8163,Event,ADDED,eval-sanitize-30-r2-077-7h78k.18d4f80761b75556,reason=Started count=1 msg=Started container task
0.8166,Event,ADDED,eval-sanitize-30-r2-077.18d4f80735bc18c0,reason=SuccessfulCreate count=1 msg=Created pod: eval-sanitize-30-r2-077-7h78k
0.8168,Event,ADDED,eval-sanitize-30-r2-077.18d4f80cf2b31765,reason=Completed count=1 msg=Job completed
0.8169,Event,ADDED,eval-sanitize-30-r2-078-9q8xm.18d4f8079ba05661,reason=Scheduled count=None msg=Successfully assigned compute/eval-sanitize-30-r2-078-9q8xm to kind-worker2
0.8171,Event,ADDED,eval-sanitize-30-r2-078-9q8xm.18d4f807bd9a7d80,"reason=Pulled count=1 msg=Container image ""busybox:musl"" already present on machine"
0.8174,Event,ADDED,eval-sanitize-30-r2-078-9q8xm.18d4f807bf0b282a,reason=Created count=1 msg=Created container: task
0.8177,Event,ADDED,eval-sanitize-30-r2-078-9q8xm.18d4f807c8041571,reason=Started count=1 msg=Started container task
0.818,Event,ADDED,eval-sanitize-30-r2-078.18d4f8079a01afb9,reason=SuccessfulCreate count=1 msg=Created pod: eval-sanitize-30-r2-078-9q8xm
0.8182,Event,ADDED,eval-sanitize-30-r2-078.18d4f80d2bf49aba,reason=Completed count=1 msg=Job completed
0.8184,Event,ADDED,eval-sanitize-30-r2-079-bhl5b.18d4f807c01679c9,reason=Scheduled count=None msg=Successfully assigned compute/eval-sanitize-30-r2-079-bhl5b to kind-worker2
0.8186,Event,ADDED,eval-sanitize-30-r2-079-bhl5b.18d4f807e3668ebb,"reason=Pulled count=1 msg=Container image ""busybox:musl"" already present on machine"
