t_recv,kind,type,name,detail
0.02,Node,ADDED,kind-control-plane,taints=1
0.0218,Node,ADDED,kind-worker,taints=0
0.0234,Node,ADDED,kind-worker2,taints=0
0.0236,TaskRequest,ADDED,eval-conflicts-rho010-r7-000,phase=None job=None
0.025,Node,ADDED,kind-worker3,taints=0
0.0268,Node,ADDED,kind-worker4,taints=0
0.0284,Node,ADDED,kind-worker5,taints=0
0.0286,TaskRequest,MODIFIED,eval-conflicts-rho010-r7-000,phase=Pending job=None
0.0436,Job,ADDED,eval-conflicts-rho010-r7-000,
0.0482,TaskRequest,MODIFIED,eval-conflicts-rho010-r7-000,phase=Scheduled job=None
0.0532,Pod,ADDED,eval-conflicts-rho010-r7-000-kpdwk,phase=Pending node=None
0.0536,Event,ADDED,eval-conflicts-rho000-r0-061-ncqz8.18d463c8954fb74f,reason=Scheduled count=None msg=Successfully assigned compute/eval-conflicts-rho000-r0-061-ncqz8 to kind-worker5
0.0544,Event,ADDED,eval-conflicts-rho000-r0-062-msmgc.18d463c8ce235b09,reason=Scheduled count=None msg=Successfully assigned compute/eval-conflicts-rho000-r0-062-msmgc to kind-worker
0.0547,Event,ADDED,eval-conflicts-rho000-r0-063-mzc4t.18d463c90957cf7a,reason=Scheduled count=None msg=Successfully assigned compute/eval-conflicts-rho000-r0-063-mzc4t to kind-worker5
0.0551,Event,ADDED,eval-conflicts-rho000-r0-064-8kwqb.18d463c945313c54,reason=Scheduled count=None msg=Successfully assigned compute/eval-conflicts-rho000-r0-064-8kwqb to kind-worker
0.0554,Event,ADDED,eval-conflicts-rho000-r0-065-cb4jq.18d463c982aff9c6,reason=Scheduled count=None msg=Successfully assigned compute/eval-conflicts-rho000-r0-065-cb4jq to kind-worker
0.0559,Event,ADDED,eval-conflicts-rho000-r0-066-v7w7c.18d463c9bc013b1d,reason=Scheduled count=None msg=Successfully assigned compute/eval-conflicts-rho000-r0-066-v7w7c to kind-worker3
0.0562,Event,ADDED,eval-conflicts-rho000-r0-067-c6gzs.18d463c9fb9092f2,reason=Scheduled count=None msg=Successfully assigned compute/eval-conflicts-rho000-r0-067-c6gzs to kind-worker3
0.0567,Event,ADDED,eval-conflicts-rho000-r0-067.18d463cd456352d8,reason=Completed count=1 msg=Job completed
0.0572,Event,ADDED,eval-conflicts-rho000-r0-068-6lk79.18d463ca342f11aa,"reason=FailedScheduling count=None msg=0/6 nodes are available: 6 node(s) had untolerated taint(s). no new claims to deallocate, preemption: 0/6 nodes are available: 6 Preemption is not helpful for scheduling."
0.0576,Event,ADDED,eval-conflicts-rho000-r0-068-6lk79.18d463caff1a6a9a,reason=Scheduled count=None msg=Successfully assigned compute/eval-conflicts-rho000-r0-068-6lk79 to kind-worker2
0.0579,Event,ADDED,eval-conflicts-rho000-r0-068.18d463ce63bfe7c5,reason=Completed count=1 msg=Job completed
0.0581,Event,ADDED,eval-conflicts-rho000-r0-069-7hj8x.18d463ca71401f4a,"reason=FailedScheduling count=None msg=0/6 nodes are available: 6 node(s) had untolerated taint(s). no new claims to deallocate, preemption: 0/6 nodes are available: 6 Preemption is not helpful for scheduling."
0.059,Job,MODIFIED,eval-conflicts-rho010-r7-000,
0.0596,Event,ADDED,eval-conflicts-rho000-r0-069-7hj8x.18d463caff515918,reason=Scheduled count=None msg=Successfully assigned compute/eval-conflicts-rho000-r0-069-7hj8x to kind-worker2
0.0598,Event,ADDED,eval-conflicts-rho000-r0-069.18d463ce6374f91b,reason=Completed count=1 msg=Job completed
0.0601,Event,ADDED,eval-conflicts-rho000-r0-070-cq4jt.18d463caafea5116,"reason=FailedScheduling count=None msg=0/6 nodes are available: 6 node(s) had untolerated taint(s). no new claims to deallocate, preemption: 0/6 nodes are available: 6 Preemption is not helpful for scheduling."
0.0604,Event,ADDED,eval-conflicts-rho000-r0-070-cq4jt.18d463caff93f54f,reason=Scheduled count=None msg=Successfully assigned compute/eval-conflicts-rho000-r0-070-cq4jt to kind-worker2
0.0605,TaskRequest,MODIFIED,eval-conflicts-rho010-r7-000,phase=Scheduled job=None
0.0609,Event,ADDED,eval-conflicts-rho000-r0-070.18d463ce6267266f,reason=Completed count=1 msg=Job completed
0.0611,Event,ADDED,eval-conflicts-rho000-r0-071-nlkrr.18d463cae77d0442,"reason=FailedScheduling count=None msg=0/6 nodes are available: 6 node(s) had untolerated taint(s). no new claims to deallocate, preemption: 0/6 nodes are available: 6 Preemption is not helpful for scheduling."
0.0612,Event,ADDED,eval-conflicts-rho000-r0-071-nlkrr.18d463caffcd6ed7,reason=Scheduled count=None msg=Successfully assigned compute/eval-conflicts-rho000-r0-071-nlkrr to kind-worker2
0.0617,Event,ADDED,eval-conflicts-rho000-r0-071.18d463ce624819e2,reason=Completed count=1 msg=Job completed
0.0619,Event,ADDED,eval-conflicts-rho000-r0-072-mn79f.18d463cb21de6898,reason=Scheduled count=None msg=Successfully assigned compute/eval-conflicts-rho000-r0-072-mn79f to kind-worker2
0.0622,Event,ADDED,eval-conflicts-rho000-r0-072.18d463ce62d1be9a,reason=Completed count=1 msg=Job completed
0.0624,Event,ADDED,eval-conflicts-rho000-r0-073-q54t4.18d463cb5d9b093a,reason=Scheduled count=None msg=Successfully assigned compute/eval-conflicts-rho000-r0-073-q54t4 to kind-worker4
0.0627,Event,ADDED,eval-conflicts-rho000-r0-073.18d463ce98848fc6,reason=Completed count=1 msg=Job completed
0.0628,Event,ADDED,eval-conflicts-rho000-r0-074-kd4x8.18d463cb9d663e15,reason=Scheduled count=None msg=Successfully assigned compute/eval-conflicts-rho000-r0-074-kd4x8 to kind-worker4
0.063,Event,ADDED,eval-conflicts-rho000-r0-074.18d463ced46f6ecf,reason=Completed count=1 msg=Job completed
0.0632,Event,ADDED,eval-conflicts-rho000-r0-075-s2zmx.18d463cbd64cecef,reason=Scheduled count=None msg=Successfully assigned compute/eval-conflicts-rho000-r0-075-s2zmx to kind-worker4
0.0636,Event,ADDED,eval-conflicts-rho000-r0-075.18d463cf4aaf316c,reason=Completed count=1 msg=Job completed
0.0638,Event,ADDED,eval-conflicts-rho000-r0-076-5t4mw.18d463cc142e8aeb,reason=Scheduled count=None msg=Successfully assigned compute/eval-conflicts-rho000-r0-076-5t4mw to kind-worker2
0.0639,Event,ADDED,eval-conflicts-rho000-r0-076.18d463cf18dfe877,reason=Completed count=1 msg=Job completed
0.0641,Event,ADDED,eval-conflicts-rho000-r0-077-tffr4.18d463cc52c0a078,reason=Scheduled count=None msg=Successfully assigned compute/eval-conflicts-rho000-r0-077-tffr4 to kind-worker4
0.0644,Event,ADDED,eval-conflicts-rho000-r0-077.18d463cf84a57648,reason=Completed count=1 msg=Job completed
0.0646,Event,ADDED,eval-conflicts-rho000-r0-078-52w2w.18d463cc87c93291,reason=Scheduled count=None msg=Successfully assigned compute/eval-conflicts-rho000-r0-078-52w2w to kind-worker2
0.0647,Event,ADDED,eval-conflicts-rho000-r0-078.18d463cfcc1c0763,reason=Completed count=1 msg=Job completed
0.0651,Event,ADDED,eval-conflicts-rho000-r0-079-wv2h6.18d463ccc3acde6f,reason=Scheduled count=None msg=Successfully assigned compute/eval-conflicts-rho000-r0-079-wv2h6 to kind-worker4
0.0653,Event,ADDED,eval-conflicts-rho000-r0-079.18d463cffc5792f9,reason=Completed count=1 msg=Job completed
0.0655,Event,ADDED,eval-conflicts-rho000-r0-080-jd8lb.18d463ccff0d835a,reason=Scheduled count=None msg=Successfully assigned compute/eval-conflicts-rho000-r0-080-jd8lb to kind-worker4
0.0658,Event,ADDED,eval-conflicts-rho000-r0-080-jd8lb.18d463cd19bee0a9,"reason=Pulled count=1 msg=Container image ""busybox:musl"" already present on machine"
0.0663,Event,ADDED,eval-conflicts-rho000-r0-080-jd8lb.18d463cd1ae1a202,reason=Created count=1 msg=Created container: task
0.0665,Event,ADDED,eval-conflicts-rho000-r0-080-jd8lb.18d463cd203556c2,reason=Started count=1 msg=Started container task
0.0667,Event,ADDED,eval-conflicts-rho000-r0-080.18d463d038432360,reason=Completed count=1 msg=Job completed
0.0668,Event,ADDED,eval-conflicts-rho000-r0-081-42pmc.18d463cd3ae79097,reason=Scheduled count=None msg=Successfully assigned compute/eval-conflicts-rho000-r0-081-42pmc to kind-worker2
0.0676,Event,ADDED,eval-conflicts-rho000-r0-081-42pmc.18d463cd54666d4f,"reason=Pulled count=1 msg=Container image ""busybox:musl"" already present on machine"
0.0678,Event,ADDED,eval-conflicts-rho000-r0-081-42pmc.18d463cd559cbe0d,reason=Created count=1 msg=Created container: task
0.068,Event,ADDED,eval-conflicts-rho000-r0-081-42pmc.18d463cd5af7f9fe,reason=Started count=1 msg=Started container task
0.0684,Event,ADDED,eval-conflicts-rho000-r0-081.18d463cd3a1d8909,reason=SuccessfulCreate count=1 msg=Created pod: eval-conflicts-rho000-r0-081-42pmc
0.0687,Event,ADDED,eval-conflicts-rho000-r0-081.18d463d040d61cea,reason=Completed count=1 msg=Job completed
0.0689,Event,ADDED,eval-conflicts-rho000-r0-082-rgnqk.18d463cd75fbad8f,reason=Scheduled count=None msg=Successfully assigned compute/eval-conflicts-rho000-r0-082-rgnqk to kind-worker4
0.0691,Event,ADDED,eval-conflicts-rho000-r0-082-rgnqk.18d463cd925af27d,"reason=Pulled count=1 msg=Container image ""busybox:musl"" already present on machine"
0.07,Pod,MODIFIED,eval-conflicts-rho010-r7-000-kpdwk,phase=Pending node=kind-worker2
0.0704,Event,ADDED,eval-conflicts-rho000-r0-082-rgnqk.18d463cd936eaede,reason=Created count=1 msg=Created container: task
0.0706,Event,ADDED,eval-conflicts-rho000-r0-082-rgnqk.18d463cd9e9974b0,reason=Started count=1 msg=Started container task
0.0708,Event,ADDED,eval-conflicts-rho000-r0-082.18d463cd7578311d,reason=SuccessfulCreate count=1 msg=Created pod: eval-conflicts-rho000-r0-082-rgnqk
0.0709,Event,ADDED,eval-conflicts-rho000-r0-082.18d463d0b01b99da,reason=Completed count=1 msg=Job completed
0.0713,Event,ADDED,eval-conflicts-rho000-r0-083-pjmb6.18d463cdb186009f,"reason=FailedScheduling count=None msg=0/6 nodes are available: 6 node(s) had untolerated taint(s). no new claims to deallocate, preemption: 0/6 nodes are available: 6 Preemption is not helpful for scheduling."
0.0714,Event,ADDED,eval-conflicts-rho000-r0-083-pjmb6.18d463ce36ae5cd4,reason=Scheduled count=None msg=Successfully assigned compute/eval-conflicts-rho000-r0-083-pjmb6 to kind-worker5
0.0716,Event,ADDED,eval-conflicts-rho000-r0-083-pjmb6.18d463ce51961525,"reason=Pulled count=1 msg=Container image ""busybox:musl"" already present on machine"
0.0718,Event,ADDED,eval-conflicts-rho000-r0-083-pjmb6.18d463ce5315dca6,reason=Created count=1 msg=Created container: task
0.072,Event,ADDED,eval-conflicts-rho000-r0-083-pjmb6.18d463ce5a503267,reason=Started count=1 msg=Started container task
0.0722,Event,ADDED,eval-conflicts-rho000-r0-083.18d463cdb17a23c8,reason=SuccessfulCreate count=1 msg=Created pod: eval-conflicts-rho000-r0-083-pjmb6
0.0724,Event,ADDED,eval-conflicts-rho000-r0-083.18d463d1785203eb,reason=Completed count=1 msg=Job completed
0.0726,Event,ADDED,eval-conflicts-rho000-r0-084-t4wc6.18d463cdececd139,"reason=FailedScheduling count=None msg=0/6 nodes are available: 6 node(s) had untolerated taint(s). no new claims to deallocate, preemption: 0/6 nodes are available: 6 Preemption is not helpful for scheduling."
0.0728,Event,ADDED,eval-conflicts-rho000-r0-084-t4wc6.18d463ce371809ec,reason=Scheduled count=None msg=Successfully assigned compute/eval-conflicts-rho000-r0-084-t4wc6 to kind-worker5
0.073,Event,ADDED,eval-conflicts-rho000-r0-084-t4wc6.18d463ce52017a5c,"reason=Pulled count=1 msg=Container image ""busybox:musl"" already present on machine"
0.0733,Event,ADDED,eval-conflicts-rho000-r0-084-t4wc6.18d463ce53ed1541,reason=Created count=1 msg=Created container: task
0.0735,Event,ADDED,eval-conflicts-rho000-r0-084-t4wc6.18d463ce5a4ef1b3,reason=Started count=1 msg=Started container task
0.0737,Event,ADDED,eval-conflicts-rho000-r0-084.18d463cdece253d1,reason=SuccessfulCreate count=1 msg=Created pod: eval-conflicts-rho000-r0-084-t4wc6
0.0742,Event,ADDED,eval-conflicts-rho000-r0-084.18d463d1787feeff,reason=Completed count=1 msg=Job completed
0.0745,Event,ADDED,eval-conflicts-rho000-r0-085-g9j29.18d463ce2e61ac55,"reason=FailedScheduling count=None msg=0/6 nodes are available: 6 node(s) had untolerated taint(s). no new claims to deallocate, preemption: 0/6 nodes are available: 6 Preemption is not helpful for scheduling."
0.0749,Event,ADDED,eval-conflicts-rho000-r0-085-g9j29.18d463ce3735b176,reason=Scheduled count=None msg=Successfully assigned compute/eval-conflicts-rho000-r0-085-g9j29 to kind-worker5
0.0751,Event,ADDED,eval-conflicts-rho000-r0-085-g9j29.18d463ce527d2a61,"reason=Pulled count=1 msg=Container image ""busybox:musl"" already present on machine"
0.0753,Event,ADDED,eval-conflicts-rho000-r0-085-g9j29.18d463ce54553736,reason=Created count=1 msg=Created container: task
0.0757,Event,ADDED,eval-conflicts-rho000-r0-085-g9j29.18d463ce5a4ef181,reason=Started count=1 msg=Started container task
0.0759,Event,ADDED,eval-conflicts-rho000-r0-085.18d463ce2e5a905f,reason=SuccessfulCreate count=1 msg=Created pod: eval-conflicts-rho000-r0-085-g9j29
0.0761,Event,ADDED,eval-conflicts-rho000-r0-085.18d463d1791d2a06,reason=Completed count=1 msg=Job completed
0.0764,Event,ADDED,eval-conflicts-rho000-r0-086-bn7v4.18d463ce64161060,reason=Scheduled count=None msg=Successfully assigned compute/eval-conflicts-rho000-r0-086-bn7v4 to kind-worker5
0.0768,Event,ADDED,eval-conflicts-rho000-r0-086-bn7v4.18d463ce7cdaf298,"reason=Pulled count=1 msg=Container image ""busybox:musl"" already present on machine"
0.0772,Event,ADDED,eval-conflicts-rho000-r0-086-bn7v4.18d463ce7df29c6d,reason=Created count=1 msg=Created container: task
0.0774,Event,ADDED,eval-conflicts-rho000-r0-086-bn7v4.18d463ce834e4341,reason=Started count=1 msg=Started container task
0.0778,Event,ADDED,eval-conflicts-rho000-r0-086.18d463ce6392b77a,reason=SuccessfulCreate count=1 msg=Created pod: eval-conflicts-rho000-r0-086-bn7v4
0.078,Event,ADDED,eval-conflicts-rho000-r0-086.18d463d1b46de487,reason=Completed count=1 msg=Job completed
0.0782,Event,ADDED,eval-conflicts-rho000-r0-087-5jwcd.18d463ce9f717636,reason=Scheduled count=None msg=Successfully assigned compute/eval-conflicts-rho000-r0-087-5jwcd to kind-worker5
0.0795,Pod,MODIFIED,eval-conflicts-rho010-r7-000-kpdwk,phase=Pending node=kind-worker2
0.0803,Event,ADDED,eval-conflicts-rho000-r0-087-5jwcd.18d463ceb8fc77b4,"reason=Pulled count=1 msg=Container image ""busybox:musl"" already present on machine"
0.0805,Event,ADDED,eval-conflicts-rho000-r0-087-5jwcd.18d463ceba2100d8,reason=Created count=1 msg=Created container: task
0.0808,Event,ADDED,eval-conflicts-rho000-r0-087-5jwcd.18d463cebe3fd213,reason=Started count=1 msg=Started container task
0.0809,Event,ADDED,eval-conflicts-rho000-r0-087.18d463ce9ee8e602,reason=SuccessfulCreate count=1 msg=Created pod: eval-conflicts-rho000-r0-087-5jwcd
0.0813,Event,ADDED,eval-conflicts-rho000-r0-087.18d463d1f020c5db,reason=Completed count=1 msg=Job completed
0.0815,Event,ADDED,eval-conflicts-rho000-r0-088-wtx24.18d463cedc9362aa,reason=Scheduled count=None msg=Successfully assigned compute/eval-conflicts-rho000-r0-088-wtx24 to kind-worker
0.0817,Event,ADDED,eval-conflicts-rho000-r0-088-wtx24.18d463cef5f7afff,"reason=Pulled count=1 msg=Container image ""busybox:musl"" already present on machine"
0.0819,Event,ADDED,eval-conflicts-rho000-r0-088-wtx24.18d463cef6f9eaca,reason=Created count=1 msg=Created container: task
0.0824,Event,ADDED,eval-conflicts-rho000-r0-088-wtx24.18d463cef8d8a031,reason=Started count=1 msg=Started container task
0.0826,Event,ADDED,eval-conflicts-rho000-r0-088.18d463cedb97202c,reason=SuccessfulCreate count=1 msg=Created pod: eval-conflicts-rho000-r0-088-wtx24
0.0828,Event,ADDED,eval-conflicts-rho000-r0-088.18d463d232b18094,reason=Completed count=1 msg=Job completed
0.084,Node,MODIFIED,kind-worker2,taints=0
0.0843,Event,ADDED,eval-conflicts-rho000-r0-089-bpm42.18d463cf1ab9b331,reason=Scheduled count=None msg=Successfully assigned compute/eval-conflicts-rho000-r0-089-bpm42 to kind-worker
0.0845,Event,ADDED,eval-conflicts-rho000-r0-089-bpm42.18d463cf36030b2a,"reason=Pulled count=1 msg=Container image ""busybox:musl"" already present on machine"
0.0846,Event,ADDED,eval-conflicts-rho000-r0-089-bpm42.18d463cf37322e02,reason=Created count=1 msg=Created container: task
0.0848,Event,ADDED,eval-conflicts-rho000-r0-089-bpm42.18d463cf3e823f4f,reason=Started count=1 msg=Started container task
0.0851,Event,ADDED,eval-conflicts-rho000-r0-089.18d463cf19c0cc4d,reason=SuccessfulCreate count=1 msg=Created pod: eval-conflicts-rho000-r0-089-bpm42
0.0853,Event,ADDED,eval-conflicts-rho000-r0-089.18d463d26ea23bc8,reason=Completed count=1 msg=Job completed
0.0855,Event,ADDED,eval-conflicts-rho000-r0-090-hqgzt.18d463cf538f1908,reason=Scheduled count=None msg=Successfully assigned compute/eval-conflicts-rho000-r0-090-hqgzt to kind-worker
0.0857,Event,ADDED,eval-conflicts-rho000-r0-090-hqgzt.18d463cf7039d8f6,"reason=Pulled count=1 msg=Container image ""busybox:musl"" already present on machine"
0.086,Event,ADDED,eval-conflicts-rho000-r0-090-hqgzt.18d463cf71fcb87c,reason=Created count=1 msg=Created container: task
0.0862,Event,ADDED,eval-conflicts-rho000-r0-090-hqgzt.18d463cf779085fd,reason=Started count=1 msg=Started container task
0.0864,Event,ADDED,eval-conflicts-rho000-r0-090.18d463cf52b0b9ec,reason=SuccessfulCreate count=1 msg=Created pod: eval-conflicts-rho000-r0-090-hqgzt
0.0868,Event,ADDED,eval-conflicts-rho000-r0-090.18d463d2aa5fd388,reason=Completed count=1 msg=Job completed
0.087,Event,ADDED,eval-conflicts-rho000-r0-091-s8zj2.18d463cf8e46ee24,reason=Scheduled count=None msg=Successfully assigned compute/eval-conflicts-rho000-r0-091-s8zj2 to kind-worker
0.0872,Event,ADDED,eval-conflicts-rho000-r0-091-s8zj2.18d463cfa8c63655,"reason=Pulled count=1 msg=Container image ""busybox:musl"" already present on machine"
0.0874,Event,ADDED,eval-conflicts-rho000-r0-091-s8zj2.18d463cfa9d0b7b6,reason=Created count=1 msg=Created container: task
0.088,Event,ADDED,eval-conflicts-rho000-r0-091-s8zj2.18d463cfae187fa7,reason=Started count=1 msg=Started container task
0.0882,Event,ADDED,eval-conflicts-rho000-r0-091.18d463cf8d64ec14,reason=SuccessfulCreate count=1 msg=Created pod: eval-conflicts-rho000-r0-091-s8zj2
0.0883,Event,ADDED,eval-conflicts-rho000-r0-091.18d463d2e69a2d1f,reason=Completed count=1 msg=Job completed
0.0885,Event,ADDED,eval-conflicts-rho000-r0-092-jdgnq.18d463cfc9c4ad18,reason=Scheduled count=None msg=Successfully assigned compute/eval-conflicts-rho000-r0-092-jdgnq to kind-worker
0.0889,Event,ADDED,eval-conflicts-rho000-r0-092-jdgnq.18d463cfe23d0090,"reason=Pulled count=1 msg=Container image ""busybox:musl"" already present on machine"
0.0891,Event,ADDED,eval-conflicts-rho000-r0-092-jdgnq.18d463cfe34d7e3a,reason=Created count=1 msg=Created container: task
0.0892,Event,ADDED,eval-conflicts-rho000-r0-092-jdgnq.18d463cfe5577af9,reason=Started count=1 msg=Started container task
0.0895,Event,ADDED,eval-conflicts-rho000-r0-092.18d463cfc8fbb572,reason=SuccessfulCreate count=1 msg=Created pod: eval-conflicts-rho000-r0-092-jdgnq
0.0896,Event,ADDED,eval-conflicts-rho000-r0-092.18d463d3221a4ce8,reason=Completed count=1 msg=Job completed
0.0898,Event,ADDED,eval-conflicts-rho000-r0-093-8pf82.18d463d00590a4da,reason=Scheduled count=None msg=Successfully assigned compute/eval-conflicts-rho000-r0-093-8pf82 to kind-worker5
0.09,Event,ADDED,eval-conflicts-rho000-r0-093-8pf82.18d463d01ddf0e4f,"reason=Pulled count=1 msg=Container image ""busybox:musl"" already present on machine"
0.0903,Event,ADDED,eval-conflicts-rho000-r0-093-8pf82.18d463d01ee58e20,reason=Created count=1 msg=Created container: task
0.0905,Event,ADDED,eval-conflicts-rho000-r0-093-8pf82.18d463d021092d50,reason=Started count=1 msg=Started container task
0.0907,Event,ADDED,eval-conflicts-rho000-r0-093.18d463d00489f711,reason=SuccessfulCreate count=1 msg=Created pod: eval-conflicts-rho000-r0-093-8pf82
0.091,Event,ADDED,eval-conflicts-rho000-r0-093.18d463d357476a6e,reason=Completed count=1 msg=Job completed
0.0912,Event,ADDED,eval-conflicts-rho000-r0-094-nx8nt.18d463d041a26b3d,reason=Scheduled count=None msg=Successfully assigned compute/eval-conflicts-rho000-r0-094-nx8nt to kind-worker5
0.0914,Event,ADDED,eval-conflicts-rho000-r0-094-nx8nt.18d463d05adae4ca,"reason=Pulled count=1 msg=Container image ""busybox:musl"" already present on machine"
0.0915,Event,ADDED,eval-conflicts-rho000-r0-094-nx8nt.18d463d05bf8c1ae,reason=Created count=1 msg=Created container: task
0.092,Event,ADDED,eval-conflicts-rho000-r0-094-nx8nt.18d463d05dfb7e60,reason=Started count=1 msg=Started container task
0.0921,Event,ADDED,eval-conflicts-rho000-r0-094.18d463d040a91203,reason=SuccessfulCreate count=1 msg=Created pod: eval-conflicts-rho000-r0-094-nx8nt
0.0923,Event,ADDED,eval-conflicts-rho000-r0-094.18d463d3931dd782,reason=Completed count=1 msg=Job completed
0.0925,Event,ADDED,eval-conflicts-rho000-r0-095-c5rxn.18d463d07c8076ce,reason=Scheduled count=None msg=Successfully assigned compute/eval-conflicts-rho000-r0-095-c5rxn to kind-worker
0.0929,Event,ADDED,eval-conflicts-rho000-r0-095-c5rxn.18d463d0952afec2,"reason=Pulled count=1 msg=Container image ""busybox:musl"" already present on machine"
0.0936,Event,ADDED,eval-conflicts-rho000-r0-095-c5rxn.18d463d0963ae7ab,reason=Created count=1 msg=Created container: task
0.0938,Event,ADDED,eval-conflicts-rho000-r0-095-c5rxn.18d463d098309d9e,reason=Started count=1 msg=Started container task
0.0943,Event,ADDED,eval-conflicts-rho000-r0-095.18d463d07ba84424,reason=SuccessfulCreate count=1 msg=Created pod: eval-conflicts-rho000-r0-095-c5rxn
0.0945,Event,ADDED,eval-conflicts-rho000-r0-095.18d463d3d60535d2,reason=Completed count=1 msg=Job completed
0.0947,Event,ADDED,eval-conflicts-rho000-r0-096-vh95q.18d463d0b8727239,reason=Scheduled count=None msg=Successfully assigned compute/eval-conflicts-rho000-r0-096-vh95q to kind-worker3
0.0949,Event,ADDED,eval-conflicts-rho000-r0-096-vh95q.18d463d0d1be2529,"reason=Pulled count=1 msg=Container image ""busybox:musl"" already present on machine"
0.0952,Event,ADDED,eval-conflicts-rho000-r0-096-vh95q.18d463d0d2d44325,reason=Created count=1 msg=Created container: task
0.0954,Event,ADDED,eval-conflicts-rho000-r0-096-vh95q.18d463d0d4fd5a51,reason=Started count=1 msg=Started container task
0.0956,Event,ADDED,eval-conflicts-rho000-r0-096.18d463d0b77ea2e1,reason=SuccessfulCreate count=1 msg=Created pod: eval-conflicts-rho000-r0-096-vh95q
0.0957,Event,ADDED,eval-conflicts-rho000-r0-096.18d463d405ce43cd,reason=Completed count=1 msg=Job completed
0.0975,Node,MODIFIED,kind-worker2,taints=0
0.0977,Event,ADDED,eval-conflicts-rho000-r0-097-mb5cp.18d463d0f4506338,reason=Scheduled count=None msg=Successfully assigned compute/eval-conflicts-rho000-r0-097-mb5cp to kind-worker3
0.0979,Event,ADDED,eval-conflicts-rho000-r0-097-mb5cp.18d463d10c55baf3,"reason=Pulled count=1 msg=Container image ""busybox:musl"" already present on machine"
0.0982,Event,ADDED,eval-conflicts-rho000-r0-097-mb5cp.18d463d10d63270b,reason=Created count=1 msg=Created container: task
0.0985,Event,ADDED,eval-conflicts-rho000-r0-097-mb5cp.18d463d1123f4992,reason=Started count=1 msg=Started container task
0.0987,Event,ADDED,eval-conflicts-rho000-r0-097.18d463d0f362f27a,reason=SuccessfulCreate count=1 msg=Created pod: eval-conflicts-rho000-r0-097-mb5cp
0.0989,Event,ADDED,eval-conflicts-rho000-r0-097.18d463d441c223bd,reason=Completed count=1 msg=Job completed
0.099,Event,ADDED,eval-conflicts-rho000-r0-098-pg44m.18d463d1302154c1,reason=Scheduled count=None msg=Successfully assigned compute/eval-conflicts-rho000-r0-098-pg44m to kind-worker3
0.0993,Event,ADDED,eval-conflicts-rho000-r0-098-pg44m.18d463d148d5fa4b,"reason=Pulled count=1 msg=Container image ""busybox:musl"" already present on machine"
0.0997,Event,ADDED,eval-conflicts-rho000-r0-098-pg44m.18d463d149fcc28a,reason=Created count=1 msg=Created container: task
0.0999,Event,ADDED,eval-conflicts-rho000-r0-098-pg44m.18d463d14bf19980,reason=Started count=1 msg=Started container task
0.1001,Event,ADDED,eval-conflicts-rho000-r0-098.18d463d12fae4d3c,reason=SuccessfulCreate count=1 msg=Created pod: eval-conflicts-rho000-r0-098-pg44m
0.1003,Event,ADDED,eval-conflicts-rho000-r0-098.18d463d47da6aa9e,reason=Completed count=1 msg=Job completed
0.1005,Event,ADDED,eval-conflicts-rho000-r0-099-6l7k4.18d463d16a8bd323,"reason=FailedScheduling count=None msg=0/6 nodes are available: 6 node(s) had untolerated taint(s). no new claims to deallocate, preemption: 0/6 nodes are available: 6 Preemption is not helpful for scheduling."
0.1006,Event,ADDED,eval-conflicts-rho000-r0-099-6l7k4.18d463d2201c954d,reason=Scheduled count=None msg=Successfully assigned compute/eval-conflicts-rho000-r0-099-6l7k4 to kind-worker2
0.1009,Event,ADDED,eval-conflicts-rho000-r0-099-6l7k4.18d463d23a0977f4,"reason=Pulled count=1 msg=Container image ""busybox:musl"" already present on machine"
0.101,Event,ADDED,eval-conflicts-rho000-r0-099-6l7k4.18d463d23b4ee0a5,reason=Created count=1 msg=Created container: task
0.1012,Event,ADDED,eval-conflicts-rho000-r0-099-6l7k4.18d463d2403c159b,reason=Started count=1 msg=Started container task
0.1014,Event,ADDED,eval-conflicts-rho000-r0-099.18d463d16a81470e,reason=SuccessfulCreate count=1 msg=Created pod: eval-conflicts-rho000-r0-099-6l7k4
0.1017,Event,ADDED,eval-conflicts-rho000-r0-099.18d463d563a8586a,reason=Completed count=1 msg=Job completed
0.1019,Event,ADDED,eval-conflicts-rho000-r1-000-xz9vc.18d463daa0a781b8,reason=Scheduled count=None msg=Successfully assigned compute/eval-conflicts-rho000-r1-000-xz9vc to kind-worker
0.1021,Event,ADDED,eval-conflicts-rho000-r1-000-xz9vc.18d463dab90c3d59,"reason=Pulled count=1 msg=Container image ""busybox:musl"" already present on machine"
0.1024,Event,ADDED,eval-conflicts-rho000-r1-000-xz9vc.18d463daba3171a7,reason=Created count=1 msg=Created container: task
0.1026,Event,ADDED,eval-conflicts-rho000-r1-000-xz9vc.18d463dabc3e1fc8,reason=Started count=1 msg=Started container task
0.1027,Event,ADDED,eval-conflicts-rho000-r1-000.18d463da9fad148b,reason=SuccessfulCreate count=1 msg=Created pod: eval-conflicts-rho000-r1-000-xz9vc
0.1029,Event,ADDED,eval-conflicts-rho000-r1-000.18d463ddde9d0296,reason=Completed count=1 msg=Job completed
0.1033,Event,ADDED,eval-conflicts-rho000-r1-001-d8rsw.18d463dada62aa07,reason=Scheduled count=None msg=Successfully assigned compute/eval-conflicts-rho000-r1-001-d8rsw to kind-worker
0.1035,Event,ADDED,eval-conflicts-rho000-r1-001-d8rsw.18d463daf3451efc,"reason=Pulled count=1 msg=Container image ""busybox:musl"" already present on machine"
0.1037,Event,ADDED,eval-conflicts-rho000-r1-001-d8rsw.18d463daf46f36a7,reason=Created count=1 msg=Created container: task
0.1039,Event,ADDED,eval-conflicts-rho000-r1-001-d8rsw.18d463daf6e231f7,reason=Started count=1 msg=Started container task
0.1041,Event,ADDED,eval-conflicts-rho000-r1-001.18d463dad950ca9f,reason=SuccessfulCreate count=1 msg=Created pod: eval-conflicts-rho000-r1-001-d8rsw
0.1042,Event,ADDED,eval-conflicts-rho000-r1-001.18d463de1a75dbd7,reason=Completed count=1 msg=Job completed
0.1044,Event,ADDED,eval-conflicts-rho000-r1-002-lvlj7.18d463db15908149,reason=Scheduled count=None msg=Successfully assigned compute/eval-conflicts-rho000-r1-002-lvlj7 to kind-worker2
0.1046,Event,ADDED,eval-conflicts-rho000-r1-002-lvlj7.18d463db2fc07e5b,"reason=Pulled count=1 msg=Container image ""busybox:musl"" already present on machine"
0.1047,Event,ADDED,eval-conflicts-rho000-r1-002-lvlj7.18d463db30ca395e,reason=Created count=1 msg=Created container: task
0.1049,Event,ADDED,eval-conflicts-rho000-r1-002-lvlj7.18d463db355f9f17,reason=Started count=1 msg=Started container task
0.1051,Event,ADDED,eval-conflicts-rho000-r1-002.18d463db14d680ff,reason=SuccessfulCreate count=1 msg=Created pod: eval-conflicts-rho000-r1-002-lvlj7
0.1052,Event,ADDED,eval-conflicts-rho000-r1-002.18d463de41303eeb,reason=Completed count=1 msg=Job completed
0.1054,Event,ADDED,eval-conflicts-rho000-r1-003-9hfrz.18d463db51896f9b,reason=Scheduled count=None msg=Successfully assigned compute/eval-conflicts-rho000-r1-003-9hfrz to kind-worker5
0.1056,Event,ADDED,eval-conflicts-rho000-r1-003-9hfrz.18d463db6b3bae65,"reason=Pulled count=1 msg=Container image ""busybox:musl"" already present on machine"
0.1058,Event,ADDED,eval-conflicts-rho000-r1-003-9hfrz.18d463db6c5a7739,reason=Created count=1 msg=Created container: task
0.106,Event,ADDED,eval-conflicts-rho000-r1-003-9hfrz.18d463db6f1100c6,reason=Started count=1 msg=Started container task
0.1062,Event,ADDED,eval-conflicts-rho000-r1-003.18d463db50879f72,reason=SuccessfulCreate count=1 msg=Created pod: eval-conflicts-rho000-r1-003-9hfrz
0.1064,Event,ADDED,eval-conflicts-rho000-r1-003.18d463de8b801744,reason=Completed count=1 msg=Job completed
0.1066,Event,ADDED,eval-conflicts-rho000-r1-004-xcdjl.18d463db8cdd9ad6,reason=Scheduled count=None msg=Successfully assigned compute/eval-conflicts-rho000-r1-004-xcdjl to kind-worker5
0.1068,Event,ADDED,eval-conflicts-rho000-r1-004-xcdjl.18d463dba63cf775,"reason=Pulled count=1 msg=Container image ""busybox:musl"" already present on machine"
0.107,Event,ADDED,eval-conflicts-rho000-r1-004-xcdjl.18d463dba765e601,reason=Created count=1 msg=Created container: task
0.1071,Event,ADDED,eval-conflicts-rho000-r1-004-xcdjl.18d463dbaad77efb,reason=Started count=1 msg=Started container task
0.1073,Event,ADDED,eval-conflicts-rho000-r1-004.18d463db8bdb2d60,reason=SuccessfulCreate count=1 msg=Created pod: eval-conflicts-rho000-r1-004-xcdjl
0.1075,Event,ADDED,eval-conflicts-rho000-r1-004.18d463dec73875eb,reason=Completed count=1 msg=Job completed
0.1077,Event,ADDED,eval-conflicts-rho000-r1-005-fm48c.18d463dbc88db918,reason=Scheduled count=None msg=Successfully assigned compute/eval-conflicts-rho000-r1-005-fm48c to kind-worker5
0.108,Event,ADDED,eval-conflicts-rho000-r1-005-fm48c.18d463dbe25f9fe8,"reason=Pulled count=1 msg=Container image ""busybox:musl"" already present on machine"
0.1083,Event,ADDED,eval-conflicts-rho000-r1-005-fm48c.18d463dbe3861f9f,reason=Created count=1 msg=Created container: task
0.1085,Event,ADDED,eval-conflicts-rho000-r1-005-fm48c.18d463dbe7914628,reason=Started count=1 msg=Started container task
0.1087,Event,ADDED,eval-conflicts-rho000-r1-005.18d463dbc7a46a8f,reason=SuccessfulCreate count=1 msg=Created pod: eval-conflicts-rho000-r1-005-fm48c
0.1089,Event,ADDED,eval-conflicts-rho000-r1-005.18d463df02e4f031,reason=Completed count=1 msg=Job completed
0.1091,Event,ADDED,eval-conflicts-rho000-r1-006-45zsq.18d463dc04c8040f,reason=Scheduled count=None msg=Successfully assigned compute/eval-conflicts-rho000-r1-006-45zsq to kind-worker5
0.1093,Event,ADDED,eval-conflicts-rho000-r1-006-45zsq.18d463dc1d7aae36,"reason=Pulled count=1 msg=Container image ""busybox:musl"" already present on machine"
0.1095,Event,ADDED,eval-conflicts-rho000-r1-006-45zsq.18d463dc1e9ef286,reason=Created count=1 msg=Created container: task
0.1097,Event,ADDED,eval-conflicts-rho000-r1-006-45zsq.18d463dc21031ba9,reason=Started count=1 msg=Started container task
0.1099,Event,ADDED,eval-conflicts-rho000-r1-006.18d463dc03ea4f74,reason=SuccessfulCreate count=1 msg=Created pod: eval-conflicts-rho000-r1-006-45zsq
0.11,Event,ADDED,eval-conflicts-rho000-r1-006.18d463df3e70dcd6,reason=Completed count=1 msg=Job completed
0.1102,Event,ADDED,eval-conflicts-rho000-r1-007-nqmk6.18d463dc3f757108,reason=Scheduled count=None msg=Successfully assigned compute/eval-conflicts-rho000-r1-007-nqmk6 to kind-worker
0.1104,Event,ADDED,eval-conflicts-rho000-r1-007-nqmk6.18d463dc591e1c67,"reason=Pulled count=1 msg=Container image ""busybox:musl"" already present on machine"
0.1106,Event,ADDED,eval-conflicts-rho000-r1-007-nqmk6.18d463dc5a4ed87b,reason=Created count=1 msg=Created container: task
0.1107,Event,ADDED,eval-conflicts-rho000-r1-007-nqmk6.18d463dc5c85231e,reason=Started count=1 msg=Started container task
0.1109,Event,ADDED,eval-conflicts-rho000-r1-007.18d463dc3e91daf4,reason=SuccessfulCreate count=1 msg=Created pod: eval-conflicts-rho000-r1-007-nqmk6
0.1111,Event,ADDED,eval-conflicts-rho000-r1-007.18d463df80f94eb5,reason=Completed count=1 msg=Job completed
0.1112,Event,ADDED,eval-conflicts-rho000-r1-008-lktgf.18d463dc7b6f3211,reason=Scheduled count=None msg=Successfully assigned compute/eval-conflicts-rho000-r1-008-lktgf to kind-worker
0.1114,Event,ADDED,eval-conflicts-rho000-r1-008-lktgf.18d463dc947996b4,"reason=Pulled count=1 msg=Container image ""busybox:musl"" already present on machine"
0.1115,Event,ADDED,eval-conflicts-rho000-r1-008-lktgf.18d463dc959e0098,reason=Created count=1 msg=Created container: task
0.1118,Event,ADDED,eval-conflicts-rho000-r1-008-lktgf.18d463dc982eaddd,reason=Started count=1 msg=Started container task
0.112,Event,ADDED,eval-conflicts-rho000-r1-008.18d463dc7aa2b1d7,reason=SuccessfulCreate count=1 msg=Created pod: eval-conflicts-rho000-r1-008-lktgf
0.1122,Event,ADDED,eval-conflicts-rho000-r1-008.18d463df8165c8cd,reason=Completed count=1 msg=Job completed
0.1123,Event,ADDED,eval-conflicts-rho000-r1-009-4zmgx.18d463dcb68468bf,reason=Scheduled count=None msg=Successfully assigned compute/eval-conflicts-rho000-r1-009-4zmgx to kind-worker4
0.1125,Event,ADDED,eval-conflicts-rho000-r1-009-4zmgx.18d463dccfba3a0d,"reason=Pulled count=1 msg=Container image ""busybox:musl"" already present on machine"
0.1127,Event,ADDED,eval-conflicts-rho000-r1-009-4zmgx.18d463dcd0ec08cc,reason=Created count=1 msg=Created container: task
0.1128,Event,ADDED,eval-conflicts-rho000-r1-009-4zmgx.18d463dcd4b2a8fd,reason=Started count=1 msg=Started container task
0.113,Event,ADDED,eval-conflicts-rho000-r1-009.18d463dcb5cdc4b7,reason=SuccessfulCreate count=1 msg=Created pod: eval-conflicts-rho000-r1-009-4zmgx
0.1132,Event,ADDED,eval-conflicts-rho000-r1-009.18d463e01652eb7b,reason=Completed count=1 msg=Job completed
0.1133,Event,ADDED,eval-conflicts-rho000-r1-010-xkh9r.18d463dcf35fd465,reason=Scheduled count=None msg=Successfully assigned compute/eval-conflicts-rho000-r1-010-xkh9r to kind-worker4
0.1135,Event,ADDED,eval-conflicts-rho000-r1-010-xkh9r.18d463dd0d15682e,"reason=Pulled count=1 msg=Container image ""busybox:musl"" already present on machine"
0.1136,Event,ADDED,eval-conflicts-rho000-r1-010-xkh9r.18d463dd0e4e8083,reason=Created count=1 msg=Created container: task
0.1138,Event,ADDED,eval-conflicts-rho000-r1-010-xkh9r.18d463dd12031bcc,reason=Started count=1 msg=Started container task
0.1141,Event,ADDED,eval-conflicts-rho000-r1-010.18d463dcf29edbaa,reason=SuccessfulCreate count=1 msg=Created pod: eval-conflicts-rho000-r1-010-xkh9r
0.1142,Event,ADDED,eval-conflicts-rho000-r1-010.18d463e0520efc3c,reason=Completed count=1 msg=Job completed
0.1144,Event,ADDED,eval-conflicts-rho000-r1-011-jl56d.18d463dd2eb246c8,reason=Scheduled count=None msg=Successfully assigned compute/eval-conflicts-rho000-r1-011-jl56d to kind-worker4
0.1145,Event,ADDED,eval-conflicts-rho000-r1-011-jl56d.18d463dd486b9264,"reason=Pulled count=1 msg=Container image ""busybox:musl"" already present on machine"
0.1147,Event,ADDED,eval-conflicts-rho000-r1-011-jl56d.18d463dd4989a108,reason=Created count=1 msg=Created container: task
0.1149,Event,ADDED,eval-conflicts-rho000-r1-011-jl56d.18d463dd4be2053f,reason=Started count=1 msg=Started container task
0.115,Event,ADDED,eval-conflicts-rho000-r1-011.18d463dd2df00ae9,reason=SuccessfulCreate count=1 msg=Created pod: eval-conflicts-rho000-r1-011-jl56d
0.1152,Event,ADDED,eval-conflicts-rho000-r1-011.18d463e08e5870ed,reason=Completed count=1 msg=Job completed
0.1154,Event,ADDED,eval-conflicts-rho000-r1-012-ggs82.18d463dd69bf838d,reason=Scheduled count=None msg=Successfully assigned compute/eval-conflicts-rho000-r1-012-ggs82 to kind-worker3
0.1155,Event,ADDED,eval-conflicts-rho000-r1-012-ggs82.18d463dd847785d9,"reason=Pulled count=1 msg=Container image ""busybox:musl"" already present on machine"
0.1157,Event,ADDED,eval-conflicts-rho000-r1-012-ggs82.18d463dd858f8ef0,reason=Created count=1 msg=Created container: task
0.116,Event,ADDED,eval-conflicts-rho000-r1-012-ggs82.18d463dd87c3b7e1,reason=Started count=1 msg=Started container task
0.1162,Event,ADDED,eval-conflicts-rho000-r1-012.18d463dd68e826ff,reason=SuccessfulCreate count=1 msg=Created pod: eval-conflicts-rho000-r1-012-ggs82
0.1164,Event,ADDED,eval-conflicts-rho000-r1-012.18d463e0a0c1ca34,reason=Completed count=1 msg=Job completed
0.1165,Event,ADDED,eval-conflicts-rho000-r1-013-ngqb6.18d463dda5681a2f,reason=Scheduled count=None msg=Successfully assigned compute/eval-conflicts-rho000-r1-013-ngqb6 to kind-worker3
0.1169,Event,ADDED,eval-conflicts-rho000-r1-013-ngqb6.18d463ddbeefdaa7,"reason=Pulled count=1 msg=Container image ""busybox:musl"" already present on machine"
0.1171,Event,ADDED,eval-conflicts-rho000-r1-013-ngqb6.18d463ddc003f381,reason=Created count=1 msg=Created container: task
0.1173,Event,ADDED,eval-conflicts-rho000-r1-013-ngqb6.18d463ddc214507a,reason=Started count=1 msg=Started container task
0.1175,Event,ADDED,eval-conflicts-rho000-r1-013.18d463dda458ca20,reason=SuccessfulCreate count=1 msg=Created pod: eval-conflicts-rho000-r1-013-ngqb6
0.1177,Event,ADDED,eval-conflicts-rho000-r1-013.18d463e0db88576e,reason=Completed count=1 msg=Job completed
0.1179,Event,ADDED,eval-conflicts-rho000-r1-014-fkm9m.18d463dde1761f96,reason=Scheduled count=None msg=Successfully assigned compute/eval-conflicts-rho000-r1-014-fkm9m to kind-worker4
0.118,Event,ADDED,eval-conflicts-rho000-r1-014-fkm9m.18d463ddfa6c498f,"reason=Pulled count=1 msg=Container image ""busybox:musl"" already present on machine"
0.1187,Event,ADDED,eval-conflicts-rho000-r1-014-fkm9m.18d463ddfb89f223,reason=Created count=1 msg=Created container: task
0.1191,Event,ADDED,eval-conflicts-rho000-r1-014-fkm9m.18d463ddfdf6ddf4,reason=Started count=1 msg=Started container task
0.1194,Event,ADDED,eval-conflicts-rho000-r1-014.18d463dde08f5eaa,reason=SuccessfulCreate count=1 msg=Created pod: eval-conflicts-rho000-r1-014-fkm9m
0.1196,Event,ADDED,eval-conflicts-rho000-r1-014.18d463e142785946,reason=Completed count=1 msg=Job completed
0.1199,Event,ADDED,eval-conflicts-rho000-r1-015-wsvpm.18d463de1d63eec5,reason=Scheduled count=None msg=Successfully assigned compute/eval-conflicts-rho000-r1-015-wsvpm to kind-worker2
0.1201,Event,ADDED,eval-conflicts-rho000-r1-015-wsvpm.18d463de35a6b09e,"reason=Pulled count=1 msg=Container image ""busybox:musl"" already present on machine"
0.1203,Event,ADDED,eval-conflicts-rho000-r1-015-wsvpm.18d463de36ed536a,reason=Created count=1 msg=Created container: task
0.1205,Event,ADDED,eval-conflicts-rho000-r1-015-wsvpm.18d463de396030a2,reason=Started count=1 msg=Started container task
0.1207,Event,ADDED,eval-conflicts-rho000-r1-015.18d463de1c11a2f6,reason=SuccessfulCreate count=1 msg=Created pod: eval-conflicts-rho000-r1-015-wsvpm
0.1208,Event,ADDED,eval-conflicts-rho000-r1-015.18d463e14b4e6a22,reason=Completed count=1 msg=Job completed
0.121,Event,ADDED,eval-conflicts-rho000-r1-016-gnhtc.18d463de587a600c,reason=Scheduled count=None msg=Successfully assigned compute/eval-conflicts-rho000-r1-016-gnhtc to kind-worker2
0.1212,Event,ADDED,eval-conflicts-rho000-r1-016-gnhtc.18d463de72491c7f,"reason=Pulled count=1 msg=Container image ""busybox:musl"" already present on machine"
0.1214,Event,ADDED,eval-conflicts-rho000-r1-016-gnhtc.18d463de735d6926,reason=Created count=1 msg=Created container: task
0.1215,Event,ADDED,eval-conflicts-rho000-r1-016-gnhtc.18d463de76477bdf,reason=Started count=1 msg=Started container task
0.1217,Event,ADDED,eval-conflicts-rho000-r1-016.18d463de57a2ae47,reason=SuccessfulCreate count=1 msg=Created pod: eval-conflicts-rho000-r1-016-gnhtc
0.1219,Event,ADDED,eval-conflicts-rho000-r1-016.18d463e14bd9922e,reason=Completed count=1 msg=Job completed
0.122,Event,ADDED,eval-conflicts-rho000-r1-017-zxrxr.18d463de93541648,reason=Scheduled count=None msg=Successfully assigned compute/eval-conflicts-rho000-r1-017-zxrxr to kind-worker2
0.1222,Event,ADDED,eval-conflicts-rho000-r1-017-zxrxr.18d463dead69867c,"reason=Pulled count=1 msg=Container image ""busybox:musl"" already present on machine"
0.1225,Event,ADDED,eval-conflicts-rho000-r1-017-zxrxr.18d463deae99b731,reason=Created count=1 msg=Created container: task
0.1226,Event,ADDED,eval-conflicts-rho000-r1-017-zxrxr.18d463deb1e53774,reason=Started count=1 msg=Started container task
0.1228,Event,ADDED,eval-conflicts-rho000-r1-017.18d463de926e6285,reason=SuccessfulCreate count=1 msg=Created pod: eval-conflicts-rho000-r1-017-zxrxr
0.123,Event,ADDED,eval-conflicts-rho000-r1-017.18d463e1c31e9131,reason=Completed count=1 msg=Job completed
0.1231,Event,ADDED,eval-conflicts-rho000-r1-018-xvxhk.18d463ded0398d6f,reason=Scheduled count=None msg=Successfully assigned compute/eval-conflicts-rho000-r1-018-xvxhk to kind-worker2
0.1233,Event,ADDED,eval-conflicts-rho000-r1-018-xvxhk.18d463deea08f9bc,"reason=Pulled count=1 msg=Container image ""busybox:musl"" already present on machine"
0.1235,Event,ADDED,eval-conflicts-rho000-r1-018-xvxhk.18d463deeb2258aa,reason=Created count=1 msg=Created container: task
0.1236,Event,ADDED,eval-conflicts-rho000-r1-018-xvxhk.18d463deed1ba038,reason=Started count=1 msg=Started container task
0.1238,Event,ADDED,eval-conflicts-rho000-r1-018.18d463decf4a3c28,reason=SuccessfulCreate count=1 msg=Created pod: eval-conflicts-rho000-r1-018-xvxhk
0.124,Event,ADDED,eval-conflicts-rho000-r1-018.18d463e1ff2d108c,reason=Completed count=1 msg=Job completed
0.1241,Event,ADDED,eval-conflicts-rho000-r1-019-7lzsk.18d463df0ad99986,reason=Scheduled count=None msg=Successfully assigned compute/eval-conflicts-rho000-r1-019-7lzsk to kind-worker2
0.1244,Event,ADDED,eval-conflicts-rho000-r1-019-7lzsk.18d463df23c99521,"reason=Pulled count=1 msg=Container image ""busybox:musl"" already present on machine"
0.1246,Event,ADDED,eval-conflicts-rho000-r1-019-7lzsk.18d463df24e6f6ce,reason=Created count=1 msg=Created container: task
0.1248,Event,ADDED,eval-conflicts-rho000-r1-019-7lzsk.18d463df2723e3f2,reason=Started count=1 msg=Started container task
0.125,Event,ADDED,eval-conflicts-rho000-r1-019.18d463df09c451e5,reason=SuccessfulCreate count=1 msg=Created pod: eval-conflicts-rho000-r1-019-7lzsk
0.1253,Event,ADDED,eval-conflicts-rho000-r1-019.18d463e23c2613cb,reason=Completed count=1 msg=Job completed
0.1254,Event,ADDED,eval-conflicts-rho000-r1-020-lrnj4.18d463df47989c46,reason=Scheduled count=None msg=Successfully assigned compute/eval-conflicts-rho000-r1-020-lrnj4 to kind-worker2
0.1256,Event,ADDED,eval-conflicts-rho000-r1-020-lrnj4.18d463df6150f439,"reason=Pulled count=1 msg=Container image ""busybox:musl"" already present on machine"
0.1261,Event,ADDED,eval-conflicts-rho000-r1-020-lrnj4.18d463df62975574,reason=Created count=1 msg=Created container: task
0.1262,Event,ADDED,eval-conflicts-rho000-r1-020-lrnj4.18d463df64eadd7c,reason=Started count=1 msg=Started container task
0.1264,Event,ADDED,eval-conflicts-rho000-r1-020.18d463df4690e599,reason=SuccessfulCreate count=1 msg=Created pod: eval-conflicts-rho000-r1-020-lrnj4
0.1266,Event,ADDED,eval-conflicts-rho000-r1-020.18d463e2787a9614,reason=Completed count=1 msg=Job completed
0.1269,Event,ADDED,eval-conflicts-rho000-r1-021-z4tzk.18d463df8221ce16,reason=Scheduled count=None msg=Successfully assigned compute/eval-conflicts-rho000-r1-021-z4tzk to kind-worker2
0.1271,Event,ADDED,eval-conflicts-rho000-r1-021-z4tzk.18d463df9cc3921b,"reason=Pulled count=1 msg=Container image ""busybox:musl"" already present on machine"
0.1272,Event,ADDED,eval-conflicts-rho000-r1-021-z4tzk.18d463df9e16ec05,reason=Created count=1 msg=Created container: task
0.1275,Event,ADDED,eval-conflicts-rho000-r1-021-z4tzk.18d463dfa4aff41c,reason=Started count=1 msg=Started container task
0.1276,Event,ADDED,eval-conflicts-rho000-r1-021.18d463df817bd1b1,reason=SuccessfulCreate count=1 msg=Created pod: eval-conflicts-rho000-r1-021-z4tzk
0.1278,Event,ADDED,eval-conflicts-rho000-r1-021.18d463e2f1da0a1e,reason=Completed count=1 msg=Job completed
0.128,Event,ADDED,eval-conflicts-rho000-r1-022-kkc9g.18d463dfbd438f96,reason=Scheduled count=None msg=Successfully assigned compute/eval-conflicts-rho000-r1-022-kkc9g to kind-worker2
0.1281,Event,ADDED,eval-conflicts-rho000-r1-022-kkc9g.18d463dfd6a20f87,"reason=Pulled count=1 msg=Container image ""busybox:musl"" already present on machine"
0.1283,Event,ADDED,eval-conflicts-rho000-r1-022-kkc9g.18d463dfd7e6fa83,reason=Created count=1 msg=Created container: task
0.1285,Event,ADDED,eval-conflicts-rho000-r1-022-kkc9g.18d463dfe1932be2,reason=Started count=1 msg=Started container task
0.1286,Event,ADDED,eval-conflicts-rho000-r1-022.18d463dfbcbf323d,reason=SuccessfulCreate count=1 msg=Created pod: eval-conflicts-rho000-r1-022-kkc9g
0.1288,Event,ADDED,eval-conflicts-rho000-r1-022.18d463e2f13e47fc,reason=Completed count=1 msg=Job completed
0.129,Event,ADDED,eval-conflicts-rho000-r1-023-jwjwv.18d463dff90f95d2,reason=Scheduled count=None msg=Successfully assigned compute/eval-conflicts-rho000-r1-023-jwjwv to kind-worker2
0.1291,Event,ADDED,eval-conflicts-rho000-r1-023-jwjwv.18d463e0127491f1,"reason=Pulled count=1 msg=Container image ""busybox:musl"" already present on machine"
0.1293,Event,ADDED,eval-conflicts-rho000-r1-023-jwjwv.18d463e013a5c358,reason=Created count=1 msg=Created container: task
0.1295,Event,ADDED,eval-conflicts-rho000-r1-023-jwjwv.18d463e0162b276e,reason=Started count=1 msg=Started container task
0.1297,Event,ADDED,eval-conflicts-rho000-r1-023.18d463dff88a1ab8,reason=SuccessfulCreate count=1 msg=Created pod: eval-conflicts-rho000-r1-023-jwjwv
0.1298,Event,ADDED,eval-conflicts-rho000-r1-023.18d463e32d417e80,reason=Completed count=1 msg=Job completed
0.13,Event,ADDED,eval-conflicts-rho000-r1-024-wdntf.18d463e0345a9a46,reason=Scheduled count=None msg=Successfully assigned compute/eval-conflicts-rho000-r1-024-wdntf to kind-worker2
0.1301,Event,ADDED,eval-conflicts-rho000-r1-024-wdntf.18d463e04f363972,"reason=Pulled count=1 msg=Container image ""busybox:musl"" already present on machine"
0.1303,Event,ADDED,eval-conflicts-rho000-r1-024-wdntf.18d463e050669eb0,reason=Created count=1 msg=Created container: task
0.1305,Event,ADDED,eval-conflicts-rho000-r1-024-wdntf.18d463e05419f80b,reason=Started count=1 msg=Started container task
0.1306,Event,ADDED,eval-conflicts-rho000-r1-024.18d463e033d7bfa8,reason=SuccessfulCreate count=1 msg=Created pod: eval-conflicts-rho000-r1-024-wdntf
0.1308,Event,ADDED,eval-conflicts-rho000-r1-024.18d463e36803fc82,reason=Completed count=1 msg=Job completed
0.1309,Event,ADDED,eval-conflicts-rho000-r1-025-lxds7.18d463e06fae4924,"reason=FailedScheduling count=None msg=0/6 nodes are available: 6 node(s) had untolerated taint(s). no new claims to deallocate, preemption: 0/6 nodes are available: 6 Preemption is not helpful for scheduling."
0.1311,Event,ADDED,eval-conflicts-rho000-r1-025-lxds7.18d463e107270937,reason=Scheduled count=None msg=Successfully assigned compute/eval-conflicts-rho000-r1-025-lxds7 to kind-worker5
0.1313,Event,ADDED,eval-conflicts-rho000-r1-025-lxds7.18d463e12181f175,"reason=Pulled count=1 msg=Container image ""busybox:musl"" already present on machine"
0.1315,Event,ADDED,eval-conflicts-rho000-r1-025-lxds7.18d463e123d65e12,reason=Created count=1 msg=Created container: task
0.1316,Event,ADDED,eval-conflicts-rho000-r1-025-lxds7.18d463e127a9617d,reason=Started count=1 msg=Started container task
0.1319,Event,ADDED,eval-conflicts-rho000-r1-025.18d463e06fa43f6a,reason=SuccessfulCreate count=1 msg=Created pod: eval-conflicts-rho000-r1-025-lxds7
0.1321,Event,ADDED,eval-conflicts-rho000-r1-025.18d463e46aa24505,reason=Completed count=1 msg=Job completed
0.1323,Event,ADDED,eval-conflicts-rho000-r1-026-tfjmv.18d463e0ab6ddb17,"reason=FailedScheduling count=None msg=0/6 nodes are available: 6 node(s) had untolerated taint(s). no new claims to deallocate, preemption: 0/6 nodes are available: 6 Preemption is not helpful for scheduling."
0.1326,Event,ADDED,eval-conflicts-rho000-r1-026-tfjmv.18d463e107689f6a,reason=Scheduled count=None msg=Successfully assigned compute/eval-conflicts-rho000-r1-026-tfjmv to kind-worker5
0.1327,Event,ADDED,eval-conflicts-rho000-r1-026-tfjmv.18d463e121e11ecc,"reason=Pulled count=1 msg=Container image ""busybox:musl"" already present on machine"
0.1329,Event,ADDED,eval-conflicts-rho000-r1-026-tfjmv.18d463e1242679a4,reason=Created count=1 msg=Created container: task
0.1331,Event,ADDED,eval-conflicts-rho000-r1-026-tfjmv.18d463e127a8edb2,reason=Started count=1 msg=Started container task
0.1334,Event,ADDED,eval-conflicts-rho000-r1-026.18d463e0ab6411a7,reason=SuccessfulCreate count=1 msg=Created pod: eval-conflicts-rho000-r1-026-tfjmv
0.1336,Event,ADDED,eval-conflicts-rho000-r1-026.18d463e46a088a5c,reason=Completed count=1 msg=Job completed
0.1337,Event,ADDED,eval-conflicts-rho000-r1-027-tbn28.18d463e0e74ff5f8,"reason=FailedScheduling count=None msg=0/6 nodes are available: 6 node(s) had untolerated taint(s). no new claims to deallocate, preemption: 0/6 nodes are available: 6 Preemption is not helpful for scheduling."
0.1339,Event,ADDED,eval-conflicts-rho000-r1-027-tbn28.18d463e107b44d57,reason=Scheduled count=None msg=Successfully assigned compute/eval-conflicts-rho000-r1-027-tbn28 to kind-worker5
0.1343,Event,ADDED,eval-conflicts-rho000-r1-027-tbn28.18d463e1222856ca,"reason=Pulled count=1 msg=Container image ""busybox:musl"" already present on machine"
0.1345,Event,ADDED,eval-conflicts-rho000-r1-027-tbn28.18d463e1248deaf4,reason=Created count=1 msg=Created container: task
0.1347,Event,ADDED,eval-conflicts-rho000-r1-027-tbn28.18d463e127e3421b,reason=Started count=1 msg=Started container task
0.1353,Event,ADDED,eval-conflicts-rho000-r1-027.18d463e0e7413952,reason=SuccessfulCreate count=1 msg=Created pod: eval-conflicts-rho000-r1-027-tbn28
0.1355,Event,ADDED,eval-conflicts-rho000-r1-027.18d463e42f15c6c7,reason=Completed count=1 msg=Job completed
0.1357,Event,ADDED,eval-conflicts-rho000-r1-028-rnqnq.18d463e12355e7c4,reason=Scheduled count=None msg=Successfully assigned compute/eval-conflicts-rho000-r1-028-rnqnq to kind-worker5
0.1358,Event,ADDED,eval-conflicts-rho000-r1-028-rnqnq.18d463e13d27d332,"reason=Pulled count=1 msg=Container image ""busybox:musl"" already present on machine"
0.1362,Event,ADDED,eval-conflicts-rho000-r1-028-rnqnq.18d463e13e431570,reason=Created count=1 msg=Created container: task
0.1364,Event,ADDED,eval-conflicts-rho000-r1-028-rnqnq.18d463e14237f741,reason=Started count=1 msg=Started container task
0.1366,Event,ADDED,eval-conflicts-rho000-r1-028.18d463e122abdc7f,reason=SuccessfulCreate count=1 msg=Created pod: eval-conflicts-rho000-r1-028-rnqnq
0.1369,Event,ADDED,eval-conflicts-rho000-r1-028.18d463e42ef3fada,reason=Completed count=1 msg=Job completed
0.1371,Event,ADDED,eval-conflicts-rho000-r1-029-4xm8f.18d463e15edc6bea,reason=Scheduled count=None msg=Successfully assigned compute/eval-conflicts-rho000-r1-029-4xm8f to kind-worker5
0.1373,Event,ADDED,eval-conflicts-rho000-r1-029-4xm8f.18d463e178b5edff,"reason=Pulled count=1 msg=Container image ""busybox:musl"" already present on machine"
0.1375,Event,ADDED,eval-conflicts-rho000-r1-029-4xm8f.18d463e179dedab6,reason=Created count=1 msg=Created container: task
0.1382,Event,ADDED,eval-conflicts-rho000-r1-029-4xm8f.18d463e17e2d662e,reason=Started count=1 msg=Started container task
0.1385,Event,ADDED,eval-conflicts-rho000-r1-029.18d463e15e4a47cb,reason=SuccessfulCreate count=1 msg=Created pod: eval-conflicts-rho000-r1-029-4xm8f
0.1387,Event,ADDED,eval-conflicts-rho000-r1-029.18d463e46afec727,reason=Completed count=1 msg=Job completed
0.1388,Event,ADDED,eval-conflicts-rho000-r1-030-rbbrl.18d463e19a9fc460,reason=Scheduled count=None msg=Successfully assigned compute/eval-conflicts-rho000-r1-030-rbbrl to kind-worker
0.1392,Event,ADDED,eval-conflicts-rho000-r1-030-rbbrl.18d463e1b4c0c608,"reason=Pulled count=1 msg=Container image ""busybox:musl"" already present on machine"
0.1394,Event,ADDED,eval-conflicts-rho000-r1-030-rbbrl.18d463e1b5d4ca00,reason=Created count=1 msg=Created container: task
0.1396,Event,ADDED,eval-conflicts-rho000-r1-030-rbbrl.18d463e1b7e867c0,reason=Started count=1 msg=Started container task
0.1399,Event,ADDED,eval-conflicts-rho000-r1-030.18d463e199a6cf9e,reason=SuccessfulCreate count=1 msg=Created pod: eval-conflicts-rho000-r1-030-rbbrl
0.1401,Event,ADDED,eval-conflicts-rho000-r1-030.18d463e4e2027bbf,reason=Completed count=1 msg=Job completed
0.1403,Event,ADDED,eval-conflicts-rho000-r1-031-m4bbl.18d463e1d66e4bde,reason=Scheduled count=None msg=Successfully assigned compute/eval-conflicts-rho000-r1-031-m4bbl to kind-worker
0.1405,Event,ADDED,eval-conflicts-rho000-r1-031-m4bbl.18d463e1f0d3bc7d,"reason=Pulled count=1 msg=Container image ""busybox:musl"" already present on machine"
0.1407,Event,ADDED,eval-conflicts-rho000-r1-031-m4bbl.18d463e1f1fd3931,reason=Created count=1 msg=Created container: task
0.1409,Event,ADDED,eval-conflicts-rho000-r1-031-m4bbl.18d463e1f7dbe8ac,reason=Started count=1 msg=Started container task
0.1411,Event,ADDED,eval-conflicts-rho000-r1-031.18d463e1d56b6d86,reason=SuccessfulCreate count=1 msg=Created pod: eval-conflicts-rho000-r1-031-m4bbl
0.1412,Event,ADDED,eval-conflicts-rho000-r1-031.18d463e51e4ada14,reason=Completed count=1 msg=Job completed
0.1415,Event,ADDED,eval-conflicts-rho000-r1-032-rjq79.18d463e211aff152,reason=Scheduled count=None msg=Successfully assigned compute/eval-conflicts-rho000-r1-032-rjq79 to kind-worker
0.1418,Event,ADDED,eval-conflicts-rho000-r1-032-rjq79.18d463e22b383e1d,"reason=Pulled count=1 msg=Container image ""busybox:musl"" already present on machine"
0.142,Event,ADDED,eval-conflicts-rho000-r1-032-rjq79.18d463e22c534c52,reason=Created count=1 msg=Created container: task
0.1423,Event,ADDED,eval-conflicts-rho000-r1-032-rjq79.18d463e22fc6e67a,reason=Started count=1 msg=Started container task
0.1425,Event,ADDED,eval-conflicts-rho000-r1-032.18d463e210b19310,reason=SuccessfulCreate count=1 msg=Created pod: eval-conflicts-rho000-r1-032-rjq79
0.1427,Event,ADDED,eval-conflicts-rho000-r1-032.18d463e55bab29b8,reason=Completed count=1 msg=Job completed
0.1429,Event,ADDED,eval-conflicts-rho000-r1-033-8nkpf.18d463e24ee81c68,reason=Scheduled count=None msg=Successfully assigned compute/eval-conflicts-rho000-r1-033-8nkpf to kind-worker
0.1432,Event,ADDED,eval-conflicts-rho000-r1-033-8nkpf.18d463e26938ec94,"reason=Pulled count=1 msg=Container image ""busybox:musl"" already present on machine"
0.1434,Event,ADDED,eval-conflicts-rho000-r1-033-8nkpf.18d463e26a67c440,reason=Created count=1 msg=Created container: task
0.1436,Event,ADDED,eval-conflicts-rho000-r1-033-8nkpf.18d463e27059bb07,reason=Started count=1 msg=Started container task
0.1439,Event,ADDED,eval-conflicts-rho000-r1-033.18d463e24dd1c472,reason=SuccessfulCreate count=1 msg=Created pod: eval-conflicts-rho000-r1-033-8nkpf
0.1441,Event,ADDED,eval-conflicts-rho000-r1-033.18d463e598d4a94b,reason=Completed count=1 msg=Job completed
0.1443,Event,ADDED,eval-conflicts-rho000-r1-034-9f78x.18d463e289077128,reason=Scheduled count=None msg=Successfully assigned compute/eval-conflicts-rho000-r1-034-9f78x to kind-worker
0.1445,Event,ADDED,eval-conflicts-rho000-r1-034-9f78x.18d463e2a269acb3,"reason=Pulled count=1 msg=Container image ""busybox:musl"" already present on machine"
0.1448,Event,ADDED,eval-conflicts-rho000-r1-034-9f78x.18d463e2a375d786,reason=Created count=1 msg=Created container: task
0.1449,Event,ADDED,eval-conflicts-rho000-r1-034-9f78x.18d463e2a82fc51b,reason=Started count=1 msg=Started container task
0.1454,Event,ADDED,eval-conflicts-rho000-r1-034.18d463e2882f312b,reason=SuccessfulCreate count=1 msg=Created pod: eval-conflicts-rho000-r1-034-9f78x
0.1456,Event,ADDED,eval-conflicts-rho000-r1-034.18d463e5d79a5284,reason=Completed count=1 msg=Job completed
0.1458,Event,ADDED,eval-conflicts-rho000-r1-035-mdczm.18d463e2c45bb50f,reason=Scheduled count=None msg=Successfully assigned compute/eval-conflicts-rho000-r1-035-mdczm to kind-worker4
0.146,Event,ADDED,eval-conflicts-rho000-r1-035-mdczm.18d463e2de5030cc,"reason=Pulled count=1 msg=Container image ""busybox:musl"" already present on machine"
0.1461,Event,ADDED,eval-conflicts-rho000-r1-035-mdczm.18d463e2df6f4d6e,reason=Created count=1 msg=Created container: task
0.1464,Event,ADDED,eval-conflicts-rho000-r1-035-mdczm.18d463e2e5fefd02,reason=Started count=1 msg=Started container task
0.1466,Event,ADDED,eval-conflicts-rho000-r1-035.18d463e2c3874c54,reason=SuccessfulCreate count=1 msg=Created pod: eval-conflicts-rho000-r1-035-mdczm
0.1468,Event,ADDED,eval-conflicts-rho000-r1-035.18d463e6054f8448,reason=Completed count=1 msg=Job completed
0.147,Event,ADDED,eval-conflicts-rho000-r1-036-gb5k5.18d463e300d96f7a,reason=Scheduled count=None msg=Successfully assigned compute/eval-conflicts-rho000-r1-036-gb5k5 to kind-worker4
0.1474,Event,ADDED,eval-conflicts-rho000-r1-036-gb5k5.18d463e31c394783,"reason=Pulled count=1 msg=Container image ""busybox:musl"" already present on machine"
0.1476,Event,ADDED,eval-conflicts-rho000-r1-036-gb5k5.18d463e31d5bd8df,reason=Created count=1 msg=Created container: task
0.1477,Event,ADDED,eval-conflicts-rho000-r1-036-gb5k5.18d463e32637499c,reason=Started count=1 msg=Started container task
0.1479,Event,ADDED,eval-conflicts-rho000-r1-036.18d463e2ff97ebd1,reason=SuccessfulCreate count=1 msg=Created pod: eval-conflicts-rho000-r1-036-gb5k5
0.1483,Event,ADDED,eval-conflicts-rho000-r1-036.18d463e642db69fe,reason=Completed count=1 msg=Job completed
0.1484,Event,ADDED,eval-conflicts-rho000-r1-037-k67lg.18d463e33c651967,reason=Scheduled count=None msg=Successfully assigned compute/eval-conflicts-rho000-r1-037-k67lg to kind-worker4
0.1486,Event,ADDED,eval-conflicts-rho000-r1-037-k67lg.18d463e3589a74b8,"reason=Pulled count=1 msg=Container image ""busybox:musl"" already present on machine"
0.149,Event,ADDED,eval-conflicts-rho000-r1-037-k67lg.18d463e359baced3,reason=Created count=1 msg=Created container: task
0.1491,Event,ADDED,eval-conflicts-rho000-r1-037-k67lg.18d463e362a28dbd,reason=Started count=1 msg=Started container task
0.1493,Event,ADDED,eval-conflicts-rho000-r1-037.18d463e33b2e7889,reason=SuccessfulCreate count=1 msg=Created pod: eval-conflicts-rho000-r1-037-k67lg
0.1495,Event,ADDED,eval-conflicts-rho000-r1-037.18d463e671622b07,reason=Completed count=1 msg=Job completed
0.1498,Event,ADDED,eval-conflicts-rho000-r1-038-p7645.18d463e378139931,reason=Scheduled count=None msg=Successfully assigned compute/eval-conflicts-rho000-r1-038-p7645 to kind-worker
0.15,Event,ADDED,eval-conflicts-rho000-r1-038-p7645.18d463e39d1a4efb,"reason=Pulled count=1 msg=Container image ""busybox:musl"" already present on machine"
0.1502,Event,ADDED,eval-conflicts-rho000-r1-038-p7645.18d463e39e70b8e1,reason=Created count=1 msg=Created container: task
0.1504,Event,ADDED,eval-conflicts-rho000-r1-038-p7645.18d463e3a9ce6233,reason=Started count=1 msg=Started container task
0.1507,Event,ADDED,eval-conflicts-rho000-r1-038.18d463e37722d166,reason=SuccessfulCreate count=1 msg=Created pod: eval-conflicts-rho000-r1-038-p7645
0.1509,Event,ADDED,eval-conflicts-rho000-r1-038.18d463e6c19b9105,reason=Completed count=1 msg=Job completed
0.151,Event,ADDED,eval-conflicts-rho000-r1-039-tvfvm.18d463e3b8286b8d,reason=Scheduled count=None msg=Successfully assigned compute/eval-conflicts-rho000-r1-039-tvfvm to kind-worker3
0.1513,Event,ADDED,eval-conflicts-rho000-r1-039-tvfvm.18d463e3d48d54b9,"reason=Pulled count=1 msg=Container image ""busybox:musl"" already present on machine"
0.1515,Event,ADDED,eval-conflicts-rho000-r1-039-tvfvm.18d463e3d5b2d3be,reason=Created count=1 msg=Created container: task
0.1517,Event,ADDED,eval-conflicts-rho000-r1-039-tvfvm.18d463e3de39ef3d,reason=Started count=1 msg=Started container task
0.1518,Event,ADDED,eval-conflicts-rho000-r1-039.18d463e3b74c7e83,reason=SuccessfulCreate count=1 msg=Created pod: eval-conflicts-rho000-r1-039-tvfvm
0.152,Event,ADDED,eval-conflicts-rho000-r1-039.18d463e72f68feb4,reason=Completed count=1 msg=Job completed
0.1522,Event,ADDED,eval-conflicts-rho000-r1-040-vx8vp.18d463e3ee8017aa,reason=Scheduled count=None msg=Successfully assigned compute/eval-conflicts-rho000-r1-040-vx8vp to kind-worker3
0.1524,Event,ADDED,eval-conflicts-rho000-r1-040-vx8vp.18d463e407825b1f,"reason=Pulled count=1 msg=Container image ""busybox:musl"" already present on machine"
0.1526,Event,ADDED,eval-conflicts-rho000-r1-040-vx8vp.18d463e40912a31a,reason=Created count=1 msg=Created container: task
0.1527,Event,ADDED,eval-conflicts-rho000-r1-040-vx8vp.18d463e412b9b78d,reason=Started count=1 msg=Started container task
0.1529,Event,ADDED,eval-conflicts-rho000-r1-040.18d463e3ed971b53,reason=SuccessfulCreate count=1 msg=Created pod: eval-conflicts-rho000-r1-040-vx8vp
0.1531,Event,ADDED,eval-conflicts-rho000-r1-040.18d463e72f88a0d8,reason=Completed count=1 msg=Job completed
0.1532,Event,ADDED,eval-conflicts-rho000-r1-041-mx45n.18d463e42a56bbb6,reason=Scheduled count=None msg=Successfully assigned compute/eval-conflicts-rho000-r1-041-mx45n to kind-worker4
0.1534,Event,ADDED,eval-conflicts-rho000-r1-041-mx45n.18d463e44962bc6f,"reason=Pulled count=1 msg=Container image ""busybox:musl"" already present on machine"
0.1536,Event,ADDED,eval-conflicts-rho000-r1-041-mx45n.18d463e44a7bb483,reason=Created count=1 msg=Created container: task
0.1537,Event,ADDED,eval-conflicts-rho000-r1-041-mx45n.18d463e4548be979,reason=Started count=1 msg=Started container task
0.1539,Event,ADDED,eval-conflicts-rho000-r1-041.18d463e429d54a30,reason=SuccessfulCreate count=1 msg=Created pod: eval-conflicts-rho000-r1-041-mx45n
0.1541,Event,ADDED,eval-conflicts-rho000-r1-041.18d463e766fbc172,reason=Completed count=1 msg=Job completed
0.1542,Event,ADDED,eval-conflicts-rho000-r1-042-qhqp2.18d463e46be3e10e,reason=Scheduled count=None msg=Successfully assigned compute/eval-conflicts-rho000-r1-042-qhqp2 to kind-worker4
0.1544,Event,ADDED,eval-conflicts-rho000-r1-042-qhqp2.18d463e488224702,"reason=Pulled count=1 msg=Container image ""busybox:musl"" already present on machine"
0.1546,Event,ADDED,eval-conflicts-rho000-r1-042-qhqp2.18d463e48986931b,reason=Created count=1 msg=Created container: task
0.1547,Event,ADDED,eval-conflicts-rho000-r1-042-qhqp2.18d463e48dbc5b50,reason=Started count=1 msg=Started container task
0.1549,Event,ADDED,eval-conflicts-rho000-r1-042.18d463e46b65bb65,reason=SuccessfulCreate count=1 msg=Created pod: eval-conflicts-rho000-r1-042-qhqp2
0.1552,Event,ADDED,eval-conflicts-rho000-r1-042.18d463e7ac3f93e8,reason=Completed count=1 msg=Job completed
0.1553,Event,ADDED,eval-conflicts-rho000-r1-043-tjdv9.18d463e4a182f019,reason=Scheduled count=None msg=Successfully assigned compute/eval-conflicts-rho000-r1-043-tjdv9 to kind-worker4
0.1555,Event,ADDED,eval-conflicts-rho000-r1-043-tjdv9.18d463e4bb60c2be,"reason=Pulled count=1 msg=Container image ""busybox:musl"" already present on machine"
0.1556,Event,ADDED,eval-conflicts-rho000-r1-043-tjdv9.18d463e4bc92f87b,reason=Created count=1 msg=Created container: task
0.1558,Event,ADDED,eval-conflicts-rho000-r1-043-tjdv9.18d463e4c0de8672,reason=Started count=1 msg=Started container task
0.156,Event,ADDED,eval-conflicts-rho000-r1-043.18d463e4a098fb86,reason=SuccessfulCreate count=1 msg=Created pod: eval-conflicts-rho000-r1-043-tjdv9
0.1562,Event,ADDED,eval-conflicts-rho000-r1-043.18d463e7ac2047a2,reason=Completed count=1 msg=Job completed
0.1563,Event,ADDED,eval-conflicts-rho000-r1-044-82w9w.18d463e4de0bf414,reason=Scheduled count=None msg=Successfully assigned compute/eval-conflicts-rho000-r1-044-82w9w to kind-worker4
0.1565,Event,ADDED,eval-conflicts-rho000-r1-044-82w9w.18d463e4f7aea098,"reason=Pulled count=1 msg=Container image ""busybox:musl"" already present on machine"
0.1567,Event,ADDED,eval-conflicts-rho000-r1-044-82w9w.18d463e4f905c752,reason=Created count=1 msg=Created container: task
0.1568,Event,ADDED,eval-conflicts-rho000-r1-044-82w9w.18d463e500afffd0,reason=Started count=1 msg=Started container task
0.157,Event,ADDED,eval-conflicts-rho000-r1-044.18d463e4dd83d215,reason=SuccessfulCreate count=1 msg=Created pod: eval-conflicts-rho000-r1-044-82w9w
0.1571,Event,ADDED,eval-conflicts-rho000-r1-044.18d463e822d94151,reason=Completed count=1 msg=Job completed
0.1573,Event,ADDED,eval-conflicts-rho000-r1-045-vzwq2.18d463e517df0248,reason=Scheduled count=None msg=Successfully assigned compute/eval-conflicts-rho000-r1-045-vzwq2 to kind-worker2
0.1575,Event,ADDED,eval-conflicts-rho000-r1-045-vzwq2.18d463e5346d63c9,"reason=Pulled count=1 msg=Container image ""busybox:musl"" already present on machine"
0.1576,Event,ADDED,eval-conflicts-rho000-r1-045-vzwq2.18d463e5358972d0,reason=Created count=1 msg=Created container: task
0.1578,Event,ADDED,eval-conflicts-rho000-r1-045-vzwq2.18d463e537743cd6,reason=Started count=1 msg=Started container task
0.158,Event,ADDED,eval-conflicts-rho000-r1-045.18d463e5178481e7,reason=SuccessfulCreate count=1 msg=Created pod: eval-conflicts-rho000-r1-045-vzwq2
0.1581,Event,ADDED,eval-conflicts-rho000-r1-045.18d463e84ffafc3f,reason=Completed count=1 msg=Job completed
0.1583,Event,ADDED,eval-conflicts-rho000-r1-046-jkz6n.18d463e555e9d23c,reason=Scheduled count=None msg=Successfully assigned compute/eval-conflicts-rho000-r1-046-jkz6n to kind-worker2
0.1585,Event,ADDED,eval-conflicts-rho000-r1-046-jkz6n.18d463e56f34b99e,"reason=Pulled count=1 msg=Container image ""busybox:musl"" already present on machine"
0.1586,Event,ADDED,eval-conflicts-rho000-r1-046-jkz6n.18d463e5706da19c,reason=Created count=1 msg=Created container: task
0.1588,Event,ADDED,eval-conflicts-rho000-r1-046-jkz6n.18d463e5781b2441,reason=Started count=1 msg=Started container task
0.159,Event,ADDED,eval-conflicts-rho000-r1-046.18d463e55572db87,reason=SuccessfulCreate count=1 msg=Created pod: eval-conflicts-rho000-r1-046-jkz6n
0.1591,Event,ADDED,eval-conflicts-rho000-r1-046.18d463e89007e5e1,reason=Completed count=1 msg=Job completed
0.1593,Event,ADDED,eval-conflicts-rho000-r1-047-hqr4b.18d463e5902086ea,reason=Scheduled count=None msg=Successfully assigned compute/eval-conflicts-rho000-r1-047-hqr4b to kind-worker2
0.1595,Event,ADDED,eval-conflicts-rho000-r1-047-hqr4b.18d463e5aea20c04,"reason=Pulled count=1 msg=Container image ""busybox:musl"" already present on machine"
0.1596,Event,ADDED,eval-conflicts-rho000-r1-047-hqr4b.18d463e5b0310aec,reason=Created count=1 msg=Created container: task
0.1598,Event,ADDED,eval-conflicts-rho000-r1-047-hqr4b.18d463e5ba75bef8,reason=Started count=1 msg=Started container task
0.16,Event,ADDED,eval-conflicts-rho000-r1-047.18d463e58f9c0a7f,reason=SuccessfulCreate count=1 msg=Created pod: eval-conflicts-rho000-r1-047-hqr4b
0.1602,Event,ADDED,eval-conflicts-rho000-r1-047.18d463e8ce8103ce,reason=Completed count=1 msg=Job completed
0.1603,Event,ADDED,eval-conflicts-rho000-r1-048-h5djt.18d463e5cb09ab1a,reason=Scheduled count=None msg=Successfully assigned compute/eval-conflicts-rho000-r1-048-h5djt to kind-worker5
0.1605,Event,ADDED,eval-conflicts-rho000-r1-048-h5djt.18d463e5eb930bf3,"reason=Pulled count=1 msg=Container image ""busybox:musl"" already present on machine"
0.1607,Event,ADDED,eval-conflicts-rho000-r1-048-h5djt.18d463e5ecbfeeb2,reason=Created count=1 msg=Created container: task
0.1609,Event,ADDED,eval-conflicts-rho000-r1-048-h5djt.18d463e5f83fa753,reason=Started count=1 msg=Started container task
0.161,Event,ADDED,eval-conflicts-rho000-r1-048.18d463e5ca1058fe,reason=SuccessfulCreate count=1 msg=Created pod: eval-conflicts-rho000-r1-048-h5djt
0.1617,Event,ADDED,eval-conflicts-rho000-r1-048.18d463e917d434d9,reason=Completed count=1 msg=Job completed
0.1619,Event,ADDED,eval-conflicts-rho000-r1-049-prrtt.18d463e607937d5e,reason=Scheduled count=None msg=Successfully assigned compute/eval-conflicts-rho000-r1-049-prrtt to kind-worker5
0.162,Event,ADDED,eval-conflicts-rho000-r1-049-prrtt.18d463e621cfd0d8,"reason=Pulled count=1 msg=Container image ""busybox:musl"" already present on machine"
0.1622,Event,ADDED,eval-conflicts-rho000-r1-049-prrtt.18d463e623960ed6,reason=Created count=1 msg=Created container: task
0.1624,Event,ADDED,eval-conflicts-rho000-r1-049-prrtt.18d463e63045560c,reason=Started count=1 msg=Started container task
0.1626,Event,ADDED,eval-conflicts-rho000-r1-049.18d463e6069428d7,reason=SuccessfulCreate count=1 msg=Created pod: eval-conflicts-rho000-r1-049-prrtt
0.1628,Event,ADDED,eval-conflicts-rho000-r1-049.18d463e953a71ade,reason=Completed count=1 msg=Job completed
0.1629,Event,ADDED,eval-conflicts-rho000-r1-050-pnks8.18d463e6456b071f,reason=Scheduled count=None msg=Successfully assigned compute/eval-conflicts-rho000-r1-050-pnks8 to kind-worker5
0.1631,Event,ADDED,eval-conflicts-rho000-r1-050-pnks8.18d463e65fad535f,"reason=Pulled count=1 msg=Container image ""busybox:musl"" already present on machine"
0.1632,Event,ADDED,eval-conflicts-rho000-r1-050-pnks8.18d463e660bdec52,reason=Created count=1 msg=Created container: task
0.1634,Event,ADDED,eval-conflicts-rho000-r1-050-pnks8.18d463e6665151c9,reason=Started count=1 msg=Started container task
0.1636,Event,ADDED,eval-conflicts-rho000-r1-050.18d463e6446914d6,reason=SuccessfulCreate count=1 msg=Created pod: eval-conflicts-rho000-r1-050-pnks8
0.1637,Event,ADDED,eval-conflicts-rho000-r1-050.18d463e98f639840,reason=Completed count=1 msg=Job completed
0.1639,Event,ADDED,eval-conflicts-rho000-r1-051-68jk5.18d463e67df88c80,reason=Scheduled count=None msg=Successfully assigned compute/eval-conflicts-rho000-r1-051-68jk5 to kind-worker5
0.164,Event,ADDED,eval-conflicts-rho000-r1-051-68jk5.18d463e697dd147f,"reason=Pulled count=1 msg=Container image ""busybox:musl"" already present on machine"
0.1642,Event,ADDED,eval-conflicts-rho000-r1-051-68jk5.18d463e69901f292,reason=Created count=1 msg=Created container: task
0.1644,Event,ADDED,eval-conflicts-rho000-r1-051-68jk5.18d463e6a08c8dd4,reason=Started count=1 msg=Started container task
0.1645,Event,ADDED,eval-conflicts-rho000-r1-051.18d463e67d178804,reason=SuccessfulCreate count=1 msg=Created pod: eval-conflicts-rho000-r1-051-68jk5
0.1647,Event,ADDED,eval-conflicts-rho000-r1-051.18d463e9cb2141b6,reason=Completed count=1 msg=Job completed
0.1649,Event,ADDED,eval-conflicts-rho000-r1-052-wlzp8.18d463e6b9c3016a,reason=Scheduled count=None msg=Successfully assigned compute/eval-conflicts-rho000-r1-052-wlzp8 to kind-worker5
0.165,Event,ADDED,eval-conflicts-rho000-r1-052-wlzp8.18d463e6d28ce589,"reason=Pulled count=1 msg=Container image ""busybox:musl"" already present on machine"
0.1652,Event,ADDED,eval-conflicts-rho000-r1-052-wlzp8.18d463e6d39f257b,reason=Created count=1 msg=Created container: task
0.1654,Event,ADDED,eval-conflicts-rho000-r1-052-wlzp8.18d463e6dda1514f,reason=Started count=1 msg=Started container task
0.1655,Event,ADDED,eval-conflicts-rho000-r1-052.18d463e6b8c4709d,reason=SuccessfulCreate count=1 msg=Created pod: eval-conflicts-rho000-r1-052-wlzp8
0.1657,Event,ADDED,eval-conflicts-rho000-r1-052.18d463ea058f108c,reason=Completed count=1 msg=Job completed
0.1658,Event,ADDED,eval-conflicts-rho000-r1-053-gts44.18d463e6f5eb0c83,reason=Scheduled count=None msg=Successfully assigned compute/eval-conflicts-rho000-r1-053-gts44 to kind-worker2
0.166,Event,ADDED,eval-conflicts-rho000-r1-053-gts44.18d463e710dc4edb,"reason=Pulled count=1 msg=Container image ""busybox:musl"" already present on machine"
0.1662,Event,ADDED,eval-conflicts-rho000-r1-053-gts44.18d463e7120b89f2,reason=Created count=1 msg=Created container: task
0.1664,Event,ADDED,eval-conflicts-rho000-r1-053-gts44.18d463e718f44174,reason=Started count=1 msg=Started container task
0.1665,Event,ADDED,eval-conflicts-rho000-r1-053.18d463e6f517fd83,reason=SuccessfulCreate count=1 msg=Created pod: eval-conflicts-rho000-r1-053-gts44
0.1667,Event,ADDED,eval-conflicts-rho000-r1-053.18d463ea2f2875f7,reason=Completed count=1 msg=Job completed
0.1668,Event,ADDED,eval-conflicts-rho000-r1-054-tl4jh.18d463e730e65abb,reason=Scheduled count=None msg=Successfully assigned compute/eval-conflicts-rho000-r1-054-tl4jh to kind-worker2
0.167,Event,ADDED,eval-conflicts-rho000-r1-054-tl4jh.18d463e74ca2c1a8,"reason=Pulled count=1 msg=Container image ""busybox:musl"" already present on machine"
0.1672,Event,ADDED,eval-conflicts-rho000-r1-054-tl4jh.18d463e74dd1ceba,reason=Created count=1 msg=Created container: task
0.1673,Event,ADDED,eval-conflicts-rho000-r1-054-tl4jh.18d463e755ae133b,reason=Started count=1 msg=Started container task
0.1675,Event,ADDED,eval-conflicts-rho000-r1-054.18d463e73005907e,reason=SuccessfulCreate count=1 msg=Created pod: eval-conflicts-rho000-r1-054-tl4jh
0.1677,Event,ADDED,eval-conflicts-rho000-r1-054.18d463ea6ae17618,reason=Completed count=1 msg=Job completed
0.168,Event,ADDED,eval-conflicts-rho000-r1-055-5q95s.18d463e777940d90,reason=Scheduled count=None msg=Successfully assigned compute/eval-conflicts-rho000-r1-055-5q95s to kind-worker5
0.1681,Event,ADDED,eval-conflicts-rho000-r1-055-5q95s.18d463e799cf89f8,"reason=Pulled count=1 msg=Container image ""busybox:musl"" already present on machine"
0.1683,Event,ADDED,eval-conflicts-rho000-r1-055-5q95s.18d463e79b01ef1d,reason=Created count=1 msg=Created container: task
0.1685,Event,ADDED,eval-conflicts-rho000-r1-055-5q95s.18d463e7aae06ad0,reason=Started count=1 msg=Started container task
0.1686,Event,ADDED,eval-conflicts-rho000-r1-055.18d463e7770e6252,reason=SuccessfulCreate count=1 msg=Created pod: eval-conflicts-rho000-r1-055-5q95s
0.1688,Event,ADDED,eval-conflicts-rho000-r1-055.18d463eab7be0817,reason=Completed count=1 msg=Job completed
0.1689,Event,ADDED,eval-conflicts-rho000-r1-056-jwbmc.18d463e7ad7a11fa,reason=Scheduled count=None msg=Successfully assigned compute/eval-conflicts-rho000-r1-056-jwbmc to kind-worker5
0.1691,Event,ADDED,eval-conflicts-rho000-r1-056-jwbmc.18d463e7d3827102,"reason=Pulled count=1 msg=Container image ""busybox:musl"" already present on machine"
0.1693,Event,ADDED,eval-conflicts-rho000-r1-056-jwbmc.18d463e7d4b096b3,reason=Created count=1 msg=Created container: task
0.1694,Event,ADDED,eval-conflicts-rho000-r1-056-jwbmc.18d463e7d8edde91,reason=Started count=1 msg=Started container task
0.1696,Event,ADDED,eval-conflicts-rho000-r1-056.18d463e7acee423a,reason=SuccessfulCreate count=1 msg=Created pod: eval-conflicts-rho000-r1-056-jwbmc
0.1698,Event,ADDED,eval-conflicts-rho000-r1-056.18d463eaf53d838f,reason=Completed count=1 msg=Job completed
0.1699,Event,ADDED,eval-conflicts-rho000-r1-057-r5h44.18d463e7e565de80,reason=Scheduled count=None msg=Successfully assigned compute/eval-conflicts-rho000-r1-057-r5h44 to kind-worker5
0.1701,Event,ADDED,eval-conflicts-rho000-r1-057-r5h44.18d463e800acae1f,"reason=Pulled count=1 msg=Container image ""busybox:musl"" already present on machine"
0.1703,Event,ADDED,eval-conflicts-rho000-r1-057-r5h44.18d463e801cdbe75,reason=Created count=1 msg=Created container: task
0.1704,Event,ADDED,eval-conflicts-rho000-r1-057-r5h44.18d463e8057fe357,reason=Started count=1 msg=Started container task
0.1706,Event,ADDED,eval-conflicts-rho000-r1-057.18d463e7e4dd6a15,reason=SuccessfulCreate count=1 msg=Created pod: eval-conflicts-rho000-r1-057-r5h44
0.1708,Event,ADDED,eval-conflicts-rho000-r1-057.18d463eb31ab3ff5,reason=Completed count=1 msg=Job completed
0.171,Event,ADDED,eval-conflicts-rho000-r1-058-v57qp.18d463e81eac5d22,"reason=FailedScheduling count=None msg=0/6 nodes are available: 6 node(s) had untolerated taint(s). no new claims to deallocate, preemption: 0/6 nodes are available: 6 Preemption is not helpful for scheduling."
0.1711,Event,ADDED,eval-conflicts-rho000-r1-058-v57qp.18d463e8ba7e54bd,reason=Scheduled count=None msg=Successfully assigned compute/eval-conflicts-rho000-r1-058-v57qp to kind-worker
0.1713,Event,ADDED,eval-conflicts-rho000-r1-058-v57qp.18d463e8daed7959,"reason=Pulled count=1 msg=Container image ""busybox:musl"" already present on machine"
0.1715,Event,ADDED,eval-conflicts-rho000-r1-058-v57qp.18d463e8dd51374a,reason=Created count=1 msg=Created container: task
0.1717,Event,ADDED,eval-conflicts-rho000-r1-058-v57qp.18d463e8e6206c50,reason=Started count=1 msg=Started container task
0.1718,Event,ADDED,eval-conflicts-rho000-r1-058.18d463e81ea25e68,reason=SuccessfulCreate count=1 msg=Created pod: eval-conflicts-rho000-r1-058-v57qp
0.172,Event,ADDED,eval-conflicts-rho000-r1-058.18d463ebe5116c41,reason=Completed count=1 msg=Job completed
0.1722,Event,ADDED,eval-conflicts-rho000-r1-059-gsszw.18d463e85e197715,"reason=FailedScheduling count=None msg=0/6 nodes are available: 6 node(s) had untolerated taint(s). no new claims to deallocate, preemption: 0/6 nodes are available: 6 Preemption is not helpful for scheduling."
0.1723,Event,ADDED,eval-conflicts-rho000-r1-059-gsszw.18d463e8bab02b62,reason=Scheduled count=None msg=Successfully assigned compute/eval-conflicts-rho000-r1-059-gsszw to kind-worker
0.1725,Event,ADDED,eval-conflicts-rho000-r1-059-gsszw.18d463e8db33b37d,"reason=Pulled count=1 msg=Container image ""busybox:musl"" already present on machine"
0.1726,Event,ADDED,eval-conflicts-rho000-r1-059-gsszw.18d463e8dde0ae64,reason=Created count=1 msg=Created container: task
0.1728,Event,ADDED,eval-conflicts-rho000-r1-059-gsszw.18d463e8e621841c,reason=Started count=1 msg=Started container task
0.173,Event,ADDED,eval-conflicts-rho000-r1-059.18d463e85e0e8475,reason=SuccessfulCreate count=1 msg=Created pod: eval-conflicts-rho000-r1-059-gsszw
0.1731,Event,ADDED,eval-conflicts-rho000-r1-059.18d463ec207cf2b9,reason=Completed count=1 msg=Job completed
0.1733,Event,ADDED,eval-conflicts-rho000-r1-060-hcbx9.18d463e8964daf30,"reason=FailedScheduling count=None msg=0/6 nodes are available: 6 node(s) had untolerated taint(s). no new claims to deallocate, preemption: 0/6 nodes are available: 6 Preemption is not helpful for scheduling."
0.1734,Event,ADDED,eval-conflicts-rho000-r1-060-hcbx9.18d463e8baf01090,reason=Scheduled count=None msg=Successfully assigned compute/eval-conflicts-rho000-r1-060-hcbx9 to kind-worker
0.1736,Event,ADDED,eval-conflicts-rho000-r1-060-hcbx9.18d463e8db5b306c,"reason=Pulled count=1 msg=Container image ""busybox:musl"" already present on machine"
0.1737,Event,ADDED,eval-conflicts-rho000-r1-060-hcbx9.18d463e8de339920,reason=Created count=1 msg=Created container: task
0.1739,Event,ADDED,eval-conflicts-rho000-r1-060-hcbx9.18d463e8e6206c5e,reason=Started count=1 msg=Started container task
0.1741,Event,ADDED,eval-conflicts-rho000-r1-060.18d463e896482fb7,reason=SuccessfulCreate count=1 msg=Created pod: eval-conflicts-rho000-r1-060-hcbx9
0.1743,Event,ADDED,eval-conflicts-rho000-r1-060.18d463ec207afa28,reason=Completed count=1 msg=Job completed
0.1744,Event,ADDED,eval-conflicts-rho000-r1-061-2rxnx.18d463e8d2d59f7b,reason=Scheduled count=None msg=Successfully assigned compute/eval-conflicts-rho000-r1-061-2rxnx to kind-worker
0.1746,Event,ADDED,eval-conflicts-rho000-r1-061-2rxnx.18d463e8f16ba7b7,"reason=Pulled count=1 msg=Container image ""busybox:musl"" already present on machine"
0.1747,Event,ADDED,eval-conflicts-rho000-r1-061-2rxnx.18d463e8f289453a,reason=Created count=1 msg=Created container: task
0.1749,Event,ADDED,eval-conflicts-rho000-r1-061-2rxnx.18d463e8fb84bc44,reason=Started count=1 msg=Started container task
0.1751,Event,ADDED,eval-conflicts-rho000-r1-061.18d463e8d1b5ec15,reason=SuccessfulCreate count=1 msg=Created pod: eval-conflicts-rho000-r1-061-2rxnx
0.1753,Event,ADDED,eval-conflicts-rho000-r1-061.18d463ec2052194f,reason=Completed count=1 msg=Job completed
0.1754,Event,ADDED,eval-conflicts-rho000-r1-062-gn6ml.18d463e90d9f25c8,reason=Scheduled count=None msg=Successfully assigned compute/eval-conflicts-rho000-r1-062-gn6ml to kind-worker
0.1756,Event,ADDED,eval-conflicts-rho000-r1-062-gn6ml.18d463e92b942003,"reason=Pulled count=1 msg=Container image ""busybox:musl"" already present on machine"
0.1758,Event,ADDED,eval-conflicts-rho000-r1-062-gn6ml.18d463e92ca4c9c0,reason=Created count=1 msg=Created container: task
0.1759,Event,ADDED,eval-conflicts-rho000-r1-062-gn6ml.18d463e93920d05a,reason=Started count=1 msg=Started container task
0.1761,Event,ADDED,eval-conflicts-rho000-r1-062.18d463e90ce97e22,reason=SuccessfulCreate count=1 msg=Created pod: eval-conflicts-rho000-r1-062-gn6ml
0.1763,Event,ADDED,eval-conflicts-rho000-r1-062.18d463ec5c99f5f4,reason=Completed count=1 msg=Job completed
0.1764,Event,ADDED,eval-conflicts-rho000-r1-063-5fshh.18d463e94903e3c6,reason=Scheduled count=None msg=Successfully assigned compute/eval-conflicts-rho000-r1-063-5fshh to kind-worker3
0.1766,Event,ADDED,eval-conflicts-rho000-r1-063-5fshh.18d463e9745c748e,"reason=Pulled count=1 msg=Container image ""busybox:musl"" already present on machine"
0.1768,Event,ADDED,eval-conflicts-rho000-r1-063-5fshh.18d463e97565c4e4,reason=Created count=1 msg=Created container: task
0.1769,Event,ADDED,eval-conflicts-rho000-r1-063-5fshh.18d463e978806b11,reason=Started count=1 msg=Started container task
0.1771,Event,ADDED,eval-conflicts-rho000-r1-063.18d463e948466097,reason=SuccessfulCreate count=1 msg=Created pod: eval-conflicts-rho000-r1-063-5fshh
0.1773,Event,ADDED,eval-conflicts-rho000-r1-063.18d463ec879fce21,reason=Completed count=1 msg=Job completed
0.1774,Event,ADDED,eval-conflicts-rho000-r1-064-z8qpf.18d463e984fde529,reason=Scheduled count=None msg=Successfully assigned compute/eval-conflicts-rho000-r1-064-z8qpf to kind-worker
0.1776,Event,ADDED,eval-conflicts-rho000-r1-064-z8qpf.18d463e99daba652,"reason=Pulled count=1 msg=Container image ""busybox:musl"" already present on machine"
0.1778,Event,ADDED,eval-conflicts-rho000-r1-064-z8qpf.18d463e99f89f25c,reason=Created count=1 msg=Created container: task
0.1779,Event,ADDED,eval-conflicts-rho000-r1-064-z8qpf.18d463e9a4239f8a,reason=Started count=1 msg=Started container task
0.1781,Event,ADDED,eval-conflicts-rho000-r1-064.18d463e983dea8b3,reason=SuccessfulCreate count=1 msg=Created pod: eval-conflicts-rho000-r1-064-z8qpf
0.1782,Event,ADDED,eval-conflicts-rho000-r1-064.18d463ecd6d74dd3,reason=Completed count=1 msg=Job completed
0.1784,Event,ADDED,eval-conflicts-rho000-r1-065-vr47c.18d463e9c08cbfb5,reason=Scheduled count=None msg=Successfully assigned compute/eval-conflicts-rho000-r1-065-vr47c to kind-worker3
0.1786,Event,ADDED,eval-conflicts-rho000-r1-065-vr47c.18d463e9dc0e8a54,"reason=Pulled count=1 msg=Container image ""busybox:musl"" already present on machine"
0.1787,Event,ADDED,eval-conflicts-rho000-r1-065-vr47c.18d463e9dd2a3608,reason=Created count=1 msg=Created container: task
0.1789,Event,ADDED,eval-conflicts-rho000-r1-065-vr47c.18d463e9df238afb,reason=Started count=1 msg=Started container task
0.1791,Event,ADDED,eval-conflicts-rho000-r1-065.18d463e9bf8cf536,reason=SuccessfulCreate count=1 msg=Created pod: eval-conflicts-rho000-r1-065-vr47c
0.1792,Event,ADDED,eval-conflicts-rho000-r1-065.18d463ed002e7160,reason=Completed count=1 msg=Job completed
0.1794,Event,ADDED,eval-conflicts-rho000-r1-066-zrhk5.18d463e9feb61dd8,reason=Scheduled count=None msg=Successfully assigned compute/eval-conflicts-rho000-r1-066-zrhk5 to kind-worker4
0.1796,Event,ADDED,eval-conflicts-rho000-r1-066-zrhk5.18d463ea19fca8eb,"reason=Pulled count=1 msg=Container image ""busybox:musl"" already present on machine"
0.1797,Event,ADDED,eval-conflicts-rho000-r1-066-zrhk5.18d463ea1b1cdaae,reason=Created count=1 msg=Created container: task
0.1799,Event,ADDED,eval-conflicts-rho000-r1-066-zrhk5.18d463ea21ac5eed,reason=Started count=1 msg=Started container task
0.18,Event,ADDED,eval-conflicts-rho000-r1-066.18d463e9fb2e958a,reason=SuccessfulCreate count=1 msg=Created pod: eval-conflicts-rho000-r1-066-zrhk5
0.1803,Event,ADDED,eval-conflicts-rho000-r1-066.18d463ed3d87a7ad,reason=Completed count=1 msg=Job completed
0.1804,Event,ADDED,eval-conflicts-rho000-r1-067-q95zr.18d463ea3844bec3,reason=Scheduled count=None msg=Successfully assigned compute/eval-conflicts-rho000-r1-067-q95zr to kind-worker4
0.1806,Event,ADDED,eval-conflicts-rho000-r1-067-q95zr.18d463ea517b8eb3,"reason=Pulled count=1 msg=Container image ""busybox:musl"" already present on machine"
0.1808,Event,ADDED,eval-conflicts-rho000-r1-067-q95zr.18d463ea52985dde,reason=Created count=1 msg=Created container: task
0.1809,Event,ADDED,eval-conflicts-rho000-r1-067-q95zr.18d463ea56ad2f56,reason=Started count=1 msg=Started container task
0.1811,Event,ADDED,eval-conflicts-rho000-r1-067.18d463ea36fdd2d0,reason=SuccessfulCreate count=1 msg=Created pod: eval-conflicts-rho000-r1-067-q95zr
0.1812,Event,ADDED,eval-conflicts-rho000-r1-067.18d463ed752cdc07,reason=Completed count=1 msg=Job completed
0.1814,Event,ADDED,eval-conflicts-rho000-r1-068-xqtch.18d463ea74f00f80,reason=Scheduled count=None msg=Successfully assigned compute/eval-conflicts-rho000-r1-068-xqtch to kind-worker4
0.1816,Event,ADDED,eval-conflicts-rho000-r1-068-xqtch.18d463eaa06bfdb5,"reason=Pulled count=1 msg=Container image ""busybox:musl"" already present on machine"
0.1817,Event,ADDED,eval-conflicts-rho000-r1-068-xqtch.18d463eaa181f9e4,reason=Created count=1 msg=Created container: task
0.1819,Event,ADDED,eval-conflicts-rho000-r1-068-xqtch.18d463eaa539d1c9,reason=Started count=1 msg=Started container task
0.1821,Event,ADDED,eval-conflicts-rho000-r1-068.18d463ea73b6840a,reason=SuccessfulCreate count=1 msg=Created pod: eval-conflicts-rho000-r1-068-xqtch
0.1823,Event,ADDED,eval-conflicts-rho000-r1-068.18d463edb0781dc4,reason=Completed count=1 msg=Job completed
0.1825,Event,ADDED,eval-conflicts-rho000-r1-069-tht8q.18d463eaaf73b178,reason=Scheduled count=None msg=Successfully assigned compute/eval-conflicts-rho000-r1-069-tht8q to kind-worker4
0.1826,Event,ADDED,eval-conflicts-rho000-r1-069-tht8q.18d463eacabfff08,"reason=Pulled count=1 msg=Container image ""busybox:musl"" already present on machine"
0.1828,Event,ADDED,eval-conflicts-rho000-r1-069-tht8q.18d463eacbe6fa8e,reason=Created count=1 msg=Created container: task
0.183,Event,ADDED,eval-conflicts-rho000-r1-069-tht8q.18d463ead1bab8ce,reason=Started count=1 msg=Started container task
0.1831,Event,ADDED,eval-conflicts-rho000-r1-069.18d463eaae5484c2,reason=SuccessfulCreate count=1 msg=Created pod: eval-conflicts-rho000-r1-069-tht8q
0.1833,Event,ADDED,eval-conflicts-rho000-r1-069.18d463edec555800,reason=Completed count=1 msg=Job completed
0.1834,Event,ADDED,eval-conflicts-rho000-r1-070-xhws4.18d463eaeaf32377,reason=Scheduled count=None msg=Successfully assigned compute/eval-conflicts-rho000-r1-070-xhws4 to kind-worker4
0.1836,Event,ADDED,eval-conflicts-rho000-r1-070-xhws4.18d463eb0381db7d,"reason=Pulled count=1 msg=Container image ""busybox:musl"" already present on machine"
0.1838,Event,ADDED,eval-conflicts-rho000-r1-070-xhws4.18d463eb063bd39f,reason=Created count=1 msg=Created container: task
0.1839,Event,ADDED,eval-conflicts-rho000-r1-070-xhws4.18d463eb09c7f360,reason=Started count=1 msg=Started container task
0.1841,Event,ADDED,eval-conflicts-rho000-r1-070.18d463eae9bb7640,reason=SuccessfulCreate count=1 msg=Created pod: eval-conflicts-rho000-r1-070-xhws4
0.1843,Event,ADDED,eval-conflicts-rho000-r1-070.18d463ee288cf7cb,reason=Completed count=1 msg=Job completed
0.1844,Event,ADDED,eval-conflicts-rho000-r1-071-9rt6j.18d463eb2765bfeb,reason=Scheduled count=None msg=Successfully assigned compute/eval-conflicts-rho000-r1-071-9rt6j to kind-worker4
0.1846,Event,ADDED,eval-conflicts-rho000-r1-071-9rt6j.18d463eb41f2b928,"reason=Pulled count=1 msg=Container image ""busybox:musl"" already present on machine"
0.1848,Event,ADDED,eval-conflicts-rho000-r1-071-9rt6j.18d463eb43065877,reason=Created count=1 msg=Created container: task
0.1849,Event,ADDED,eval-conflicts-rho000-r1-071-9rt6j.18d463eb473e3d92,reason=Started count=1 msg=Started container task
0.1851,Event,ADDED,eval-conflicts-rho000-r1-071.18d463eb26d7f189,reason=SuccessfulCreate count=1 msg=Created pod: eval-conflicts-rho000-r1-071-9rt6j
0.1853,Event,ADDED,eval-conflicts-rho000-r1-071.18d463ee641d2549,reason=Completed count=1 msg=Job completed
0.1854,Event,ADDED,eval-conflicts-rho000-r1-072-kltv6.18d463eb615af36d,reason=Scheduled count=None msg=Successfully assigned compute/eval-conflicts-rho000-r1-072-kltv6 to kind-worker4
0.1856,Event,ADDED,eval-conflicts-rho000-r1-072-kltv6.18d463eb7b0aa974,"reason=Pulled count=1 msg=Container image ""busybox:musl"" already present on machine"
0.1857,Event,ADDED,eval-conflicts-rho000-r1-072-kltv6.18d463eb7c2704a1,reason=Created count=1 msg=Created container: task
0.1859,Event,ADDED,eval-conflicts-rho000-r1-072-kltv6.18d463eb7e41f641,reason=Started count=1 msg=Started container task
0.1863,Event,ADDED,eval-conflicts-rho000-r1-072.18d463eb60cd2daf,reason=SuccessfulCreate count=1 msg=Created pod: eval-conflicts-rho000-r1-072-kltv6
0.1866,Event,ADDED,eval-conflicts-rho000-r1-072.18d463ee9fa87584,reason=Completed count=1 msg=Job completed
0.1868,Event,ADDED,eval-conflicts-rho000-r1-073-s975j.18d463eb9fb52802,reason=Scheduled count=None msg=Successfully assigned compute/eval-conflicts-rho000-r1-073-s975j to kind-worker4
0.187,Event,ADDED,eval-conflicts-rho000-r1-073-s975j.18d463ebbae36557,"reason=Pulled count=1 msg=Container image ""busybox:musl"" already present on machine"
0.1872,Event,ADDED,eval-conflicts-rho000-r1-073-s975j.18d463ebbc15f82f,reason=Created count=1 msg=Created container: task
0.1875,Event,ADDED,eval-conflicts-rho000-r1-073-s975j.18d463ebbff84c59,reason=Started count=1 msg=Started container task
0.1877,Event,ADDED,eval-conflicts-rho000-r1-073.18d463eb9d9ad663,reason=SuccessfulCreate count=1 msg=Created pod: eval-conflicts-rho000-r1-073-s975j
0.1879,Event,ADDED,eval-conflicts-rho000-r1-073.18d463eedba24cf8,reason=Completed count=1 msg=Job completed
0.1881,Event,ADDED,eval-conflicts-rho000-r1-074-t6rp9.18d463ebd8cf68d9,reason=Scheduled count=None msg=Successfully assigned compute/eval-conflicts-rho000-r1-074-t6rp9 to kind-worker4
0.1885,Event,ADDED,eval-conflicts-rho000-r1-074-t6rp9.18d463ebf1fdcac5,"reason=Pulled count=1 msg=Container image ""busybox:musl"" already present on machine"
0.1887,Event,ADDED,eval-conflicts-rho000-r1-074-t6rp9.18d463ebf3171bf0,reason=Created count=1 msg=Created container: task
0.1889,Event,ADDED,eval-conflicts-rho000-r1-074-t6rp9.18d463ebf531a291,reason=Started count=1 msg=Started container task
0.1892,Event,ADDED,eval-conflicts-rho000-r1-074.18d463ebd84af552,reason=SuccessfulCreate count=1 msg=Created pod: eval-conflicts-rho000-r1-074-t6rp9
0.1894,Event,ADDED,eval-conflicts-rho000-r1-074.18d463ef17c2cb98,reason=Completed count=1 msg=Job completed
0.1896,Event,ADDED,eval-conflicts-rho000-r1-075-rr9kx.18d463ec14dd8ef4,reason=Scheduled count=None msg=Successfully assigned compute/eval-conflicts-rho000-r1-075-rr9kx to kind-worker2
0.1898,Event,ADDED,eval-conflicts-rho000-r1-075-rr9kx.18d463ec2ced9d97,"reason=Pulled count=1 msg=Container image ""busybox:musl"" already present on machine"
0.1901,Event,ADDED,eval-conflicts-rho000-r1-075-rr9kx.18d463ec2dff56cc,reason=Created count=1 msg=Created container: task
0.1903,Event,ADDED,eval-conflicts-rho000-r1-075-rr9kx.18d463ec3030046b,reason=Started count=1 msg=Started container task
0.1905,Event,ADDED,eval-conflicts-rho000-r1-075.18d463ec141049b9,reason=SuccessfulCreate count=1 msg=Created pod: eval-conflicts-rho000-r1-075-rr9kx
0.1908,Event,ADDED,eval-conflicts-rho000-r1-075.18d463ef50b5c62e,reason=Completed count=1 msg=Job completed
0.191,Event,ADDED,eval-conflicts-rho000-r1-076-7khv6.18d463ec4fa1210c,reason=Scheduled count=None msg=Successfully assigned compute/eval-conflicts-rho000-r1-076-7khv6 to kind-worker2
0.1912,Event,ADDED,eval-conflicts-rho000-r1-076-7khv6.18d463ec685a7a45,"reason=Pulled count=1 msg=Container image ""busybox:musl"" already present on machine"
0.1914,Event,ADDED,eval-conflicts-rho000-r1-076-7khv6.18d463ec6982f5a1,reason=Created count=1 msg=Created container: task
0.1918,Event,ADDED,eval-conflicts-rho000-r1-076-7khv6.18d463ec6b598b1c,reason=Started count=1 msg=Started container task
0.192,Event,ADDED,eval-conflicts-rho000-r1-076.18d463ec4f0351f8,reason=SuccessfulCreate count=1 msg=Created pod: eval-conflicts-rho000-r1-076-7khv6
0.1922,Event,ADDED,eval-conflicts-rho000-r1-076.18d463ef8c9f43a7,reason=Completed count=1 msg=Job completed
0.1924,Event,ADDED,eval-conflicts-rho000-r1-077-xk9fv.18d463ec8b264d86,reason=Scheduled count=None msg=Successfully assigned compute/eval-conflicts-rho000-r1-077-xk9fv to kind-worker2
0.1928,Event,ADDED,eval-conflicts-rho000-r1-077-xk9fv.18d463eca59e7424,"reason=Pulled count=1 msg=Container image ""busybox:musl"" already present on machine"
0.193,Event,ADDED,eval-conflicts-rho000-r1-077-xk9fv.18d463eca7eac17b,reason=Created count=1 msg=Created container: task
0.1932,Event,ADDED,eval-conflicts-rho000-r1-077-xk9fv.18d463ecaa7209d8,reason=Started count=1 msg=Started container task
0.1936,Event,ADDED,eval-conflicts-rho000-r1-077.18d463ec8a9eb483,reason=SuccessfulCreate count=1 msg=Created pod: eval-conflicts-rho000-r1-077-xk9fv
0.1938,Event,ADDED,eval-conflicts-rho000-r1-077.18d463efc86c9c67,reason=Completed count=1 msg=Job completed
0.194,Event,ADDED,eval-conflicts-rho000-r1-078-jzd2j.18d463ecc76eb9dd,reason=Scheduled count=None msg=Successfully assigned compute/eval-conflicts-rho000-r1-078-jzd2j to kind-worker2
0.1943,Event,ADDED,eval-conflicts-rho000-r1-078-jzd2j.18d463ece0698f52,"reason=Pulled count=1 msg=Container image ""busybox:musl"" already present on machine"
0.1946,Event,ADDED,eval-conflicts-rho000-r1-078-jzd2j.18d463ece1c03964,reason=Created count=1 msg=Created container: task
0.1948,Event,ADDED,eval-conflicts-rho000-r1-078-jzd2j.18d463ece59ee7ae,reason=Started count=1 msg=Started container task
0.195,Event,ADDED,eval-conflicts-rho000-r1-078.18d463ecc6e2fedd,reason=SuccessfulCreate count=1 msg=Created pod: eval-conflicts-rho000-r1-078-jzd2j
0.1952,Event,ADDED,eval-conflicts-rho000-r1-078.18d463f003936bde,reason=Completed count=1 msg=Job completed
0.1955,Event,ADDED,eval-conflicts-rho000-r1-079-cb4sq.18d463ed038071f4,reason=Scheduled count=None msg=Successfully assigned compute/eval-conflicts-rho000-r1-079-cb4sq to kind-worker5
0.1957,Event,ADDED,eval-conflicts-rho000-r1-079-cb4sq.18d463ed1d121965,"reason=Pulled count=1 msg=Container image ""busybox:musl"" already present on machine"
0.1959,Event,ADDED,eval-conflicts-rho000-r1-079-cb4sq.18d463ed1e39fde0,reason=Created count=1 msg=Created container: task
0.1962,Event,ADDED,eval-conflicts-rho000-r1-079-cb4sq.18d463ed22c8580e,reason=Started count=1 msg=Started container task
0.1964,Event,ADDED,eval-conflicts-rho000-r1-079.18d463ed02db9395,reason=SuccessfulCreate count=1 msg=Created pod: eval-conflicts-rho000-r1-079-cb4sq
0.1966,Event,ADDED,eval-conflicts-rho000-r1-079.18d463f051620895,reason=Completed count=1 msg=Job completed
0.1967,Event,ADDED,eval-conflicts-rho000-r1-080-45lh5.18d463ed40131159,reason=Scheduled count=None msg=Successfully assigned compute/eval-conflicts-rho000-r1-080-45lh5 to kind-worker5
0.1971,Event,ADDED,eval-conflicts-rho000-r1-080-45lh5.18d463ed5a728ada,"reason=Pulled count=1 msg=Container image ""busybox:musl"" already present on machine"
0.1973,Event,ADDED,eval-conflicts-rho000-r1-080-45lh5.18d463ed5be777bf,reason=Created count=1 msg=Created container: task
0.1975,Event,ADDED,eval-conflicts-rho000-r1-080-45lh5.18d463ed608d30f2,reason=Started count=1 msg=Started container task
0.1979,Event,ADDED,eval-conflicts-rho000-r1-080.18d463ed3ef055a8,reason=SuccessfulCreate count=1 msg=Created pod: eval-conflicts-rho000-r1-080-45lh5
0.1981,Event,ADDED,eval-conflicts-rho000-r1-080.18d463f08d1f72d3,reason=Completed count=1 msg=Job completed
0.1983,Event,ADDED,eval-conflicts-rho000-r1-081-ftc8n.18d463ed7b2c9b06,reason=Scheduled count=None msg=Successfully assigned compute/eval-conflicts-rho000-r1-081-ftc8n to kind-worker5
0.1985,Event,ADDED,eval-conflicts-rho000-r1-081-ftc8n.18d463ed94d5f36b,"reason=Pulled count=1 msg=Container image ""busybox:musl"" already present on machine"
0.1988,Event,ADDED,eval-conflicts-rho000-r1-081-ftc8n.18d463ed95e9b789,reason=Created count=1 msg=Created container: task
0.199,Event,ADDED,eval-conflicts-rho000-r1-081-ftc8n.18d463ed97c7b157,reason=Started count=1 msg=Started container task
0.1992,Event,ADDED,eval-conflicts-rho000-r1-081.18d463ed7a5686db,reason=SuccessfulCreate count=1 msg=Created pod: eval-conflicts-rho000-r1-081-ftc8n
0.1994,Event,ADDED,eval-conflicts-rho000-r1-081.18d463f0c84f1c3f,reason=Completed count=1 msg=Job completed
0.1997,Event,ADDED,eval-conflicts-rho000-r1-082-msbx7.18d463edb768e589,reason=Scheduled count=None msg=Successfully assigned compute/eval-conflicts-rho000-r1-082-msbx7 to kind-worker
0.1999,Event,ADDED,eval-conflicts-rho000-r1-082-msbx7.18d463edd043bd1b,"reason=Pulled count=1 msg=Container image ""busybox:musl"" already present on machine"
0.2001,Event,ADDED,eval-conflicts-rho000-r1-082-msbx7.18d463edd16db942,reason=Created count=1 msg=Created container: task
0.2005,Event,ADDED,eval-conflicts-rho000-r1-082-msbx7.18d463edd53619ec,reason=Started count=1 msg=Started container task
0.2007,Event,ADDED,eval-conflicts-rho000-r1-082.18d463edb66c34a2,reason=SuccessfulCreate count=1 msg=Created pod: eval-conflicts-rho000-r1-082-msbx7
0.2009,Event,ADDED,eval-conflicts-rho000-r1-082.18d463f1063a6e84,reason=Completed count=1 msg=Job completed
0.201,Event,ADDED,eval-conflicts-rho000-r1-083-x2xtf.18d463edf17b62f4,reason=Scheduled count=None msg=Successfully assigned compute/eval-conflicts-rho000-r1-083-x2xtf to kind-worker
0.2013,Event,ADDED,eval-conflicts-rho000-r1-083-x2xtf.18d463ee0a34e632,"reason=Pulled count=1 msg=Container image ""busybox:musl"" already present on machine"
0.2015,Event,ADDED,eval-conflicts-rho000-r1-083-x2xtf.18d463ee0b52debf,reason=Created count=1 msg=Created container: task
0.2017,Event,ADDED,eval-conflicts-rho000-r1-083-x2xtf.18d463ee0e6c7fb6,reason=Started count=1 msg=Started container task
0.2018,Event,ADDED,eval-conflicts-rho000-r1-083.18d463edf063fc9f,reason=SuccessfulCreate count=1 msg=Created pod: eval-conflicts-rho000-r1-083-x2xtf
0.2022,Event,ADDED,eval-conflicts-rho000-r1-083.18d463f142f01c78,reason=Completed count=1 msg=Job completed
0.2024,Event,ADDED,eval-conflicts-rho000-r1-084-brmgr.18d463ee333508c4,reason=Scheduled count=None msg=Successfully assigned compute/eval-conflicts-rho000-r1-084-brmgr to kind-worker
0.2026,Event,ADDED,eval-conflicts-rho000-r1-084-brmgr.18d463ee47fd061b,"reason=Pulled count=1 msg=Container image ""busybox:musl"" already present on machine"
0.2029,Event,ADDED,eval-conflicts-rho000-r1-084-brmgr.18d463ee490fd52f,reason=Created count=1 msg=Created container: task
0.2031,Event,ADDED,eval-conflicts-rho000-r1-084-brmgr.18d463ee4e6adfa8,reason=Started count=1 msg=Started container task
0.2033,Event,ADDED,eval-conflicts-rho000-r1-084.18d463ee2d673782,reason=SuccessfulCreate count=1 msg=Created pod: eval-conflicts-rho000-r1-084-brmgr
0.2034,Event,ADDED,eval-conflicts-rho000-r1-084.18d463f17f14d9b6,reason=Completed count=1 msg=Job completed
0.2037,Event,ADDED,eval-conflicts-rho000-r1-085-cm9h4.18d463ee6970c461,reason=Scheduled count=None msg=Successfully assigned compute/eval-conflicts-rho000-r1-085-cm9h4 to kind-worker5
0.2039,Event,ADDED,eval-conflicts-rho000-r1-085-cm9h4.18d463ee83ced235,"reason=Pulled count=1 msg=Container image ""busybox:musl"" already present on machine"
0.2041,Event,ADDED,eval-conflicts-rho000-r1-085-cm9h4.18d463ee84e4dc8a,reason=Created count=1 msg=Created container: task
0.2043,Event,ADDED,eval-conflicts-rho000-r1-085-cm9h4.18d463ee8c1a442c,reason=Started count=1 msg=Started container task
0.2045,Event,ADDED,eval-conflicts-rho000-r1-085.18d463ee68857299,reason=SuccessfulCreate count=1 msg=Created pod: eval-conflicts-rho000-r1-085-cm9h4
0.2047,Event,ADDED,eval-conflicts-rho000-r1-085.18d463f1b792a583,reason=Completed count=1 msg=Job completed
0.2048,Event,ADDED,eval-conflicts-rho000-r1-086-4wd89.18d463eea3fbd798,reason=Scheduled count=None msg=Successfully assigned compute/eval-conflicts-rho000-r1-086-4wd89 to kind-worker
0.2054,Event,ADDED,eval-conflicts-rho000-r1-086-4wd89.18d463eebd1eeb8c,"reason=Pulled count=1 msg=Container image ""busybox:musl"" already present on machine"
0.2055,Event,ADDED,eval-conflicts-rho000-r1-086-4wd89.18d463eebf00423e,reason=Created count=1 msg=Created container: task
0.2057,Event,ADDED,eval-conflicts-rho000-r1-086-4wd89.18d463eec7be783f,reason=Started count=1 msg=Started container task
0.2059,Event,ADDED,eval-conflicts-rho000-r1-086.18d463eea31fc1ed,reason=SuccessfulCreate count=1 msg=Created pod: eval-conflicts-rho000-r1-086-4wd89
0.2063,Event,ADDED,eval-conflicts-rho000-r1-086.18d463f1f6d3a043,reason=Completed count=1 msg=Job completed
0.2066,Event,ADDED,eval-conflicts-rho000-r1-087-k8szd.18d463eee017332d,reason=Scheduled count=None msg=Successfully assigned compute/eval-conflicts-rho000-r1-087-k8szd to kind-worker
0.2069,Event,ADDED,eval-conflicts-rho000-r1-087-k8szd.18d463eefa76a1d6,"reason=Pulled count=1 msg=Container image ""busybox:musl"" already present on machine"
0.2072,Event,ADDED,eval-conflicts-rho000-r1-087-k8szd.18d463eefb92c554,reason=Created count=1 msg=Created container: task
0.2075,Event,ADDED,eval-conflicts-rho000-r1-087-k8szd.18d463eeff1dd870,reason=Started count=1 msg=Started container task
0.2077,Event,ADDED,eval-conflicts-rho000-r1-087.18d463eedf210e3c,reason=SuccessfulCreate count=1 msg=Created pod: eval-conflicts-rho000-r1-087-k8szd
0.2079,Event,ADDED,eval-conflicts-rho000-r1-087.18d463f2325f2d14,reason=Completed count=1 msg=Job completed
0.2082,Event,ADDED,eval-conflicts-rho000-r1-088-d84hz.18d463ef1b62c345,reason=Scheduled count=None msg=Successfully assigned compute/eval-conflicts-rho000-r1-088-d84hz to kind-worker5
0.2083,Event,ADDED,eval-conflicts-rho000-r1-088-d84hz.18d463ef35fa2853,"reason=Pulled count=1 msg=Container image ""busybox:musl"" already present on machine"
0.2085,Event,ADDED,eval-conflicts-rho000-r1-088-d84hz.18d463ef37158b4f,reason=Created count=1 msg=Created container: task
0.2087,Event,ADDED,eval-conflicts-rho000-r1-088-d84hz.18d463ef3b55a7bb,reason=Started count=1 msg=Started container task
0.209,Event,ADDED,eval-conflicts-rho000-r1-088.18d463ef1a66bf97,reason=SuccessfulCreate count=1 msg=Created pod: eval-conflicts-rho000-r1-088-d84hz
0.2092,Event,ADDED,eval-conflicts-rho000-r1-088.18d463f26b076f7b,reason=Completed count=1 msg=Job completed
0.2094,Event,ADDED,eval-conflicts-rho000-r1-089-sfnt4.18d463ef56df784b,reason=Scheduled count=None msg=Successfully assigned compute/eval-conflicts-rho000-r1-089-sfnt4 to kind-worker
0.2097,Event,ADDED,eval-conflicts-rho000-r1-089-sfnt4.18d463ef702bd036,"reason=Pulled count=1 msg=Container image ""busybox:musl"" already present on machine"
0.2099,Event,ADDED,eval-conflicts-rho000-r1-089-sfnt4.18d463ef715b0a5a,reason=Created count=1 msg=Created container: task
0.21,Event,ADDED,eval-conflicts-rho000-r1-089-sfnt4.18d463ef73589d86,reason=Started count=1 msg=Started container task
0.2103,Event,ADDED,eval-conflicts-rho000-r1-089.18d463ef56343cd4,reason=SuccessfulCreate count=1 msg=Created pod: eval-conflicts-rho000-r1-089-sfnt4
0.2106,Event,ADDED,eval-conflicts-rho000-r1-089.18d463f2aac12675,reason=Completed count=1 msg=Job completed
0.2107,Event,ADDED,eval-conflicts-rho000-r1-090-2rlk6.18d463ef9336e3c1,reason=Scheduled count=None msg=Successfully assigned compute/eval-conflicts-rho000-r1-090-2rlk6 to kind-worker3
0.2109,Event,ADDED,eval-conflicts-rho000-r1-090-2rlk6.18d463efabe21e4c,"reason=Pulled count=1 msg=Container image ""busybox:musl"" already present on machine"
0.2111,Event,ADDED,eval-conflicts-rho000-r1-090-2rlk6.18d463efad039af1,reason=Created count=1 msg=Created container: task
0.2113,Event,ADDED,eval-conflicts-rho000-r1-090-2rlk6.18d463efb11da0d8,reason=Started count=1 msg=Started container task
0.2115,Event,ADDED,eval-conflicts-rho000-r1-090.18d463ef92714e03,reason=SuccessfulCreate count=1 msg=Created pod: eval-conflicts-rho000-r1-090-2rlk6
0.2117,Event,ADDED,eval-conflicts-rho000-r1-090.18d463f2d4bad31f,reason=Completed count=1 msg=Job completed
0.2118,Event,ADDED,eval-conflicts-rho000-r1-091-fwnb8.18d463efce609dd6,reason=Scheduled count=None msg=Successfully assigned compute/eval-conflicts-rho000-r1-091-fwnb8 to kind-worker3
0.212,Event,ADDED,eval-conflicts-rho000-r1-091-fwnb8.18d463efe7046610,"reason=Pulled count=1 msg=Container image ""busybox:musl"" already present on machine"
0.2122,Event,ADDED,eval-conflicts-rho000-r1-091-fwnb8.18d463efe8b2ff7f,reason=Created count=1 msg=Created container: task
0.2123,Event,ADDED,eval-conflicts-rho000-r1-091-fwnb8.18d463efec5e37b1,reason=Started count=1 msg=Started container task
0.2125,Event,ADDED,eval-conflicts-rho000-r1-091.18d463efcd9352f9,reason=SuccessfulCreate count=1 msg=Created pod: eval-conflicts-rho000-r1-091-fwnb8
0.2127,Event,ADDED,eval-conflicts-rho000-r1-091.18d463f31060202a,reason=Completed count=1 msg=Job completed
0.2128,Event,ADDED,eval-conflicts-rho000-r1-092-kwpkq.18d463f009d07bc5,"reason=FailedScheduling count=None msg=0/6 nodes are available: 6 node(s) had untolerated taint(s). no new claims to deallocate, preemption: 0/6 nodes are available: 6 Preemption is not helpful for scheduling."
0.213,Event,ADDED,eval-conflicts-rho000-r1-092-kwpkq.18d463f0cf084ba6,reason=Scheduled count=None msg=Successfully assigned compute/eval-conflicts-rho000-r1-092-kwpkq to kind-worker2
0.2158,Event,ADDED,eval-conflicts-rho000-r1-092-kwpkq.18d463f0eaf2e400,"reason=Pulled count=1 msg=Container image ""busybox:musl"" already present on machine"
0.216,Event,ADDED,eval-conflicts-rho000-r1-092-kwpkq.18d463f0ecf2c6a8,reason=Created count=1 msg=Created container: task
0.2161,Event,ADDED,eval-conflicts-rho000-r1-092-kwpkq.18d463f0f0cf9eb5,reason=Started count=1 msg=Started container task
0.2164,Event,ADDED,eval-conflicts-rho000-r1-092.18d463f009c6e816,reason=SuccessfulCreate count=1 msg=Created pod: eval-conflicts-rho000-r1-092-kwpkq
0.2165,Event,ADDED,eval-conflicts-rho000-r1-092.18d463f439d18fdc,reason=Completed count=1 msg=Job completed
0.2167,Event,ADDED,eval-conflicts-rho000-r1-093-bpfws.18d463f045803259,"reason=FailedScheduling count=None msg=0/6 nodes are available: 6 node(s) had untolerated taint(s). no new claims to deallocate, preemption: 0/6 nodes are available: 6 Preemption is not helpful for scheduling."
0.2168,Event,ADDED,eval-conflicts-rho000-r1-093-bpfws.18d463f0cf503347,reason=Scheduled count=None msg=Successfully assigned compute/eval-conflicts-rho000-r1-093-bpfws to kind-worker2
0.2172,Event,ADDED,eval-conflicts-rho000-r1-093-bpfws.18d463f0eb615c0d,"reason=Pulled count=1 msg=Container image ""busybox:musl"" already present on machine"
0.2174,Event,ADDED,eval-conflicts-rho000-r1-093-bpfws.18d463f0ed876eb2,reason=Created count=1 msg=Created container: task
0.2176,Event,ADDED,eval-conflicts-rho000-r1-093-bpfws.18d463f0f1bfb9ba,reason=Started count=1 msg=Started container task
0.2178,Event,ADDED,eval-conflicts-rho000-r1-093.18d463f04575526f,reason=SuccessfulCreate count=1 msg=Created pod: eval-conflicts-rho000-r1-093-bpfws
0.218,Event,ADDED,eval-conflicts-rho000-r1-093.18d463f439cfec89,reason=Completed count=1 msg=Job completed
0.2182,Event,ADDED,eval-conflicts-rho000-r1-094-xh2kw.18d463f080337608,"reason=FailedScheduling count=None msg=0/6 nodes are available: 6 node(s) had untolerated taint(s). no new claims to deallocate, preemption: 0/6 nodes are available: 6 Preemption is not helpful for scheduling."
0.2184,Event,ADDED,eval-conflicts-rho000-r1-094-xh2kw.18d463f0cfb57d6e,reason=Scheduled count=None msg=Successfully assigned compute/eval-conflicts-rho000-r1-094-xh2kw to kind-worker2
0.2187,Event,ADDED,eval-conflicts-rho000-r1-094-xh2kw.18d463f0ec083e68,"reason=Pulled count=1 msg=Container image ""busybox:musl"" already present on machine"
0.2188,Event,ADDED,eval-conflicts-rho000-r1-094-xh2kw.18d463f0ee595f0f,reason=Created count=1 msg=Created container: task
0.219,Event,ADDED,eval-conflicts-rho000-r1-094-xh2kw.18d463f0f1bedcbd,reason=Started count=1 msg=Started container task
0.2192,Event,ADDED,eval-conflicts-rho000-r1-094.18d463f080289676,reason=SuccessfulCreate count=1 msg=Created pod: eval-conflicts-rho000-r1-094-xh2kw
0.2194,Event,ADDED,eval-conflicts-rho000-r1-094.18d463f4398597b1,reason=Completed count=1 msg=Job completed
0.2195,Event,ADDED,eval-conflicts-rho000-r1-095-6pshg.18d463f0bcbe4606,"reason=FailedScheduling count=None msg=0/6 nodes are available: 6 node(s) had untolerated taint(s). no new claims to deallocate, preemption: 0/6 nodes are available: 6 Preemption is not helpful for scheduling."
0.2197,Event,ADDED,eval-conflicts-rho000-r1-095-6pshg.18d463f0cfd82d83,reason=Scheduled count=None msg=Successfully assigned compute/eval-conflicts-rho000-r1-095-6pshg to kind-worker2
0.2201,Event,ADDED,eval-conflicts-rho000-r1-095-6pshg.18d463f0ec3dccea,"reason=Pulled count=1 msg=Container image ""busybox:musl"" already present on machine"
0.2203,Event,ADDED,eval-conflicts-rho000-r1-095-6pshg.18d463f0ee8c01ba,reason=Created count=1 msg=Created container: task
0.2205,Event,ADDED,eval-conflicts-rho000-r1-095-6pshg.18d463f0f1c74ca4,reason=Started count=1 msg=Started container task
0.2206,Event,ADDED,eval-conflicts-rho000-r1-095.18d463f0bcb0089d,reason=SuccessfulCreate count=1 msg=Created pod: eval-conflicts-rho000-r1-095-6pshg
0.2209,Event,ADDED,eval-conflicts-rho000-r1-095.18d463f43aae9c00,reason=Completed count=1 msg=Job completed
0.221,Event,ADDED,eval-conflicts-rho000-r1-096-5fk7m.18d463f0f7e15d82,reason=Scheduled count=None msg=Successfully assigned compute/eval-conflicts-rho000-r1-096-5fk7m to kind-worker4
0.2212,Event,ADDED,eval-conflicts-rho000-r1-096-5fk7m.18d463f111c6ea25,"reason=Pulled count=1 msg=Container image ""busybox:musl"" already present on machine"
0.2215,Event,ADDED,eval-conflicts-rho000-r1-096-5fk7m.18d463f112cbfc41,reason=Created count=1 msg=Created container: task
0.2216,Event,ADDED,eval-conflicts-rho000-r1-096-5fk7m.18d463f114bf46ea,reason=Started count=1 msg=Started container task
0.2218,Event,ADDED,eval-conflicts-rho000-r1-096.18d463f0f73397cb,reason=SuccessfulCreate count=1 msg=Created pod: eval-conflicts-rho000-r1-096-5fk7m
0.222,Event,ADDED,eval-conflicts-rho000-r1-096.18d463f43a5cda21,reason=Completed count=1 msg=Job completed
0.2222,Event,ADDED,eval-conflicts-rho000-r1-097-dj78d.18d463f1340b5fe9,reason=Scheduled count=None msg=Successfully assigned compute/eval-conflicts-rho000-r1-097-dj78d to kind-worker2
0.2224,Event,ADDED,eval-conflicts-rho000-r1-097-dj78d.18d463f14e07c79f,"reason=Pulled count=1 msg=Container image ""busybox:musl"" already present on machine"
0.2226,Event,ADDED,eval-conflicts-rho000-r1-097-dj78d.18d463f14f2aaec9,reason=Created count=1 msg=Created container: task
0.2229,Event,ADDED,eval-conflicts-rho000-r1-097-dj78d.18d463f152a5a615,reason=Started count=1 msg=Started container task
0.2231,Event,ADDED,eval-conflicts-rho000-r1-097.18d463f1330daac3,reason=SuccessfulCreate count=1 msg=Created pod: eval-conflicts-rho000-r1-097-dj78d
0.2233,Event,ADDED,eval-conflicts-rho000-r1-097.18d463f475a71642,reason=Completed count=1 msg=Job completed
0.2235,Event,ADDED,eval-conflicts-rho000-r1-098-s7wx8.18d463f171276081,reason=Scheduled count=None msg=Successfully assigned compute/eval-conflicts-rho000-r1-098-s7wx8 to kind-worker4
0.2237,Event,ADDED,eval-conflicts-rho000-r1-098-s7wx8.18d463f189aad12b,"reason=Pulled count=1 msg=Container image ""busybox:musl"" already present on machine"
0.2239,Event,ADDED,eval-conflicts-rho000-r1-098-s7wx8.18d463f18abb6a01,reason=Created count=1 msg=Created container: task
0.224,Event,ADDED,eval-conflicts-rho000-r1-098-s7wx8.18d463f18dffb2f2,reason=Started count=1 msg=Started container task
0.2242,Event,ADDED,eval-conflicts-rho000-r1-098.18d463f17039980e,reason=SuccessfulCreate count=1 msg=Created pod: eval-conflicts-rho000-r1-098-s7wx8
0.2245,Event,ADDED,eval-conflicts-rho000-r1-098.18d463f4b1e1ec66,reason=Completed count=1 msg=Job completed
0.2247,Event,ADDED,eval-conflicts-rho000-r1-099-p9psb.18d463f1aaeabd09,reason=Scheduled count=None msg=Successfully assigned compute/eval-conflicts-rho000-r1-099-p9psb to kind-worker4
0.2248,Event,ADDED,eval-conflicts-rho000-r1-099-p9psb.18d463f1c3a6b560,"reason=Pulled count=1 msg=Container image ""busybox:musl"" already present on machine"
0.2251,Event,ADDED,eval-conflicts-rho000-r1-099-p9psb.18d463f1c4be0821,reason=Created count=1 msg=Created container: task
0.2253,Event,ADDED,eval-conflicts-rho000-r1-099-p9psb.18d463f1c69e6a16,reason=Started count=1 msg=Started container task
0.2255,Event,ADDED,eval-conflicts-rho000-r1-099.18d463f1aa0f47fc,reason=SuccessfulCreate count=1 msg=Created pod: eval-conflicts-rho000-r1-099-p9psb
0.2257,Event,ADDED,eval-conflicts-rho000-r1-099.18d463f4ede3b807,reason=Completed count=1 msg=Job completed
0.226,Event,ADDED,eval-conflicts-rho000-r2-000-d8n6t.18d463fa2bbcca8f,reason=Scheduled count=None msg=Successfully assigned compute/eval-conflicts-rho000-r2-000-d8n6t to kind-worker5
0.2262,Event,ADDED,eval-conflicts-rho000-r2-000-d8n6t.18d463fa46611ecf,"reason=Pulled count=1 msg=Container image ""busybox:musl"" already present on machine"
0.2263,Event,ADDED,eval-conflicts-rho000-r2-000-d8n6t.18d463fa477398e6,reason=Created count=1 msg=Created container: task
0.2265,Event,ADDED,eval-conflicts-rho000-r2-000-d8n6t.18d463fa4c4950c5,reason=Started count=1 msg=Started container task
0.2267,Event,ADDED,eval-conflicts-rho000-r2-000.18d463fa2ad7d0c2,reason=SuccessfulCreate count=1 msg=Created pod: eval-conflicts-rho000-r2-000-d8n6t
0.2269,Event,ADDED,eval-conflicts-rho000-r2-000.18d463fd652cac55,reason=Completed count=1 msg=Job completed
0.227,Event,ADDED,eval-conflicts-rho000-r2-001-mn6cm.18d463fa66a5d4ae,reason=Scheduled count=None msg=Successfully assigned compute/eval-conflicts-rho000-r2-001-mn6cm to kind-worker
0.2272,Event,ADDED,eval-conflicts-rho000-r2-001-mn6cm.18d463fa80398402,"reason=Pulled count=1 msg=Container image ""busybox:musl"" already present on machine"
0.2274,Event,ADDED,eval-conflicts-rho000-r2-001-mn6cm.18d463fa81544caf,reason=Created count=1 msg=Created container: task
0.2276,Event,ADDED,eval-conflicts-rho000-r2-001-mn6cm.18d463fa83532548,reason=Started count=1 msg=Started container task
0.2277,Event,ADDED,eval-conflicts-rho000-r2-001.18d463fa659143c4,reason=SuccessfulCreate count=1 msg=Created pod: eval-conflicts-rho000-r2-001-mn6cm
0.2279,Event,ADDED,eval-conflicts-rho000-r2-001.18d463fda1f48392,reason=Completed count=1 msg=Job completed
0.2281,Event,ADDED,eval-conflicts-rho000-r2-002-m6qnc.18d463faa21554d1,reason=Scheduled count=None msg=Successfully assigned compute/eval-conflicts-rho000-r2-002-m6qnc to kind-worker
0.2282,Event,ADDED,eval-conflicts-rho000-r2-002-m6qnc.18d463faba03e622,"reason=Pulled count=1 msg=Container image ""busybox:musl"" already present on machine"
0.2284,Event,ADDED,eval-conflicts-rho000-r2-002-m6qnc.18d463fabb18ad3f,reason=Created count=1 msg=Created container: task
0.2286,Event,ADDED,eval-conflicts-rho000-r2-002-m6qnc.18d463fabfaf5ef2,reason=Started count=1 msg=Started container task
0.2287,Event,ADDED,eval-conflicts-rho000-r2-002.18d463faa0f0a19a,reason=SuccessfulCreate count=1 msg=Created pod: eval-conflicts-rho000-r2-002-m6qnc
0.2289,Event,ADDED,eval-conflicts-rho000-r2-002.18d463fddd392acc,reason=Completed count=1 msg=Job completed
0.229,Event,ADDED,eval-conflicts-rho000-r2-003-4kcqn.18d463fade26b804,reason=Scheduled count=None msg=Successfully assigned compute/eval-conflicts-rho000-r2-003-4kcqn to kind-worker2
0.2292,Event,ADDED,eval-conflicts-rho000-r2-003-4kcqn.18d463faf774b73d,"reason=Pulled count=1 msg=Container image ""busybox:musl"" already present on machine"
0.2295,Event,ADDED,eval-conflicts-rho000-r2-003-4kcqn.18d463faf8941154,reason=Created count=1 msg=Created container: task
0.2296,Event,ADDED,eval-conflicts-rho000-r2-003-4kcqn.18d463fafa6ccb09,reason=Started count=1 msg=Started container task
0.2298,Event,ADDED,eval-conflicts-rho000-r2-003.18d463fadd3eafd1,reason=SuccessfulCreate count=1 msg=Created pod: eval-conflicts-rho000-r2-003-4kcqn
0.2299,Event,ADDED,eval-conflicts-rho000-r2-003.18d463fe06f28e17,reason=Completed count=1 msg=Job completed
0.2301,Event,ADDED,eval-conflicts-rho000-r2-004-zx9n6.18d463fb19bed2e7,reason=Scheduled count=None msg=Successfully assigned compute/eval-conflicts-rho000-r2-004-zx9n6 to kind-worker2
0.2303,Event,ADDED,eval-conflicts-rho000-r2-004-zx9n6.18d463fb32dc1995,"reason=Pulled count=1 msg=Container image ""busybox:musl"" already present on machine"
0.2304,Event,ADDED,eval-conflicts-rho000-r2-004-zx9n6.18d463fb33fdc383,reason=Created count=1 msg=Created container: task
0.2306,Event,ADDED,eval-conflicts-rho000-r2-004-zx9n6.18d463fb36d52cf1,reason=Started count=1 msg=Started container task
0.2307,Event,ADDED,eval-conflicts-rho000-r2-004.18d463fb18aedaf3,reason=SuccessfulCreate count=1 msg=Created pod: eval-conflicts-rho000-r2-004-zx9n6
0.231,Event,ADDED,eval-conflicts-rho000-r2-004.18d463fe42415aa8,reason=Completed count=1 msg=Job completed
0.2311,Event,ADDED,eval-conflicts-rho000-r2-005-zlbrq.18d463fb5516915c,reason=Scheduled count=None msg=Successfully assigned compute/eval-conflicts-rho000-r2-005-zlbrq to kind-worker2
0.2313,Event,ADDED,eval-conflicts-rho000-r2-005-zlbrq.18d463fb6f25d293,"reason=Pulled count=1 msg=Container image ""busybox:musl"" already present on machine"
0.2315,Event,ADDED,eval-conflicts-rho000-r2-005-zlbrq.18d463fb704d65f6,reason=Created count=1 msg=Created container: task
0.2316,Event,ADDED,eval-conflicts-rho000-r2-005-zlbrq.18d463fb74893b29,reason=Started count=1 msg=Started container task
0.2318,Event,ADDED,eval-conflicts-rho000-r2-005.18d463fb5408c6db,reason=SuccessfulCreate count=1 msg=Created pod: eval-conflicts-rho000-r2-005-zlbrq
0.232,Event,ADDED,eval-conflicts-rho000-r2-005.18d463feba1fc9da,reason=Completed count=1 msg=Job completed
0.2321,Event,ADDED,eval-conflicts-rho000-r2-006-c5vnw.18d463fb9086a697,reason=Scheduled count=None msg=Successfully assigned compute/eval-conflicts-rho000-r2-006-c5vnw to kind-worker
0.2323,Event,ADDED,eval-conflicts-rho000-r2-006-c5vnw.18d463fba8ecefa3,"reason=Pulled count=1 msg=Container image ""busybox:musl"" already present on machine"
0.2325,Event,ADDED,eval-conflicts-rho000-r2-006-c5vnw.18d463fbaa0ce078,reason=Created count=1 msg=Created container: task
0.2326,Event,ADDED,eval-conflicts-rho000-r2-006-c5vnw.18d463fbae43d196,reason=Started count=1 msg=Started container task
0.2328,Event,ADDED,eval-conflicts-rho000-r2-006.18d463fb8f91a83d,reason=SuccessfulCreate count=1 msg=Created pod: eval-conflicts-rho000-r2-006-c5vnw
0.233,Event,ADDED,eval-conflicts-rho000-r2-006.18d463fecd0b057d,reason=Completed count=1 msg=Job completed
0.2331,Event,ADDED,eval-conflicts-rho000-r2-007-7nfjd.18d463fbcc085db1,reason=Scheduled count=None msg=Successfully assigned compute/eval-conflicts-rho000-r2-007-7nfjd to kind-worker4
0.2333,Event,ADDED,eval-conflicts-rho000-r2-007-7nfjd.18d463fbe5fc9415,"reason=Pulled count=1 msg=Container image ""busybox:musl"" already present on machine"
0.2334,Event,ADDED,eval-conflicts-rho000-r2-007-7nfjd.18d463fbe712b652,reason=Created count=1 msg=Created container: task
0.2336,Event,ADDED,eval-conflicts-rho000-r2-007-7nfjd.18d463fbe9283459,reason=Started count=1 msg=Started container task
0.2338,Event,ADDED,eval-conflicts-rho000-r2-007.18d463fbcb067896,reason=SuccessfulCreate count=1 msg=Created pod: eval-conflicts-rho000-r2-007-7nfjd
0.2339,Event,ADDED,eval-conflicts-rho000-r2-007.18d463fef64450ac,reason=Completed count=1 msg=Job completed
0.2341,Event,ADDED,eval-conflicts-rho000-r2-008-dd4s5.18d463fc07c5c77d,reason=Scheduled count=None msg=Successfully assigned compute/eval-conflicts-rho000-r2-008-dd4s5 to kind-worker4
0.2342,Event,ADDED,eval-conflicts-rho000-r2-008-dd4s5.18d463fc219bf61b,"reason=Pulled count=1 msg=Container image ""busybox:musl"" already present on machine"
0.2344,Event,ADDED,eval-conflicts-rho000-r2-008-dd4s5.18d463fc22b691a2,reason=Created count=1 msg=Created container: task
0.2346,Event,ADDED,eval-conflicts-rho000-r2-008-dd4s5.18d463fc26696023,reason=Started count=1 msg=Started container task
0.2347,Event,ADDED,eval-conflicts-rho000-r2-008.18d463fc06d7eccc,reason=SuccessfulCreate count=1 msg=Created pod: eval-conflicts-rho000-r2-008-dd4s5
0.2349,Event,ADDED,eval-conflicts-rho000-r2-008.18d463ff32686e4f,reason=Completed count=1 msg=Job completed
0.235,Event,ADDED,eval-conflicts-rho000-r2-009-9ncn7.18d463fc44167b92,reason=Scheduled count=None msg=Successfully assigned compute/eval-conflicts-rho000-r2-009-9ncn7 to kind-worker2
0.2352,Event,ADDED,eval-conflicts-rho000-r2-009-9ncn7.18d463fc5de44c34,"reason=Pulled count=1 msg=Container image ""busybox:musl"" already present on machine"
0.2354,Event,ADDED,eval-conflicts-rho000-r2-009-9ncn7.18d463fc5ef44e78,reason=Created count=1 msg=Created container: task
0.2355,Event,ADDED,eval-conflicts-rho000-r2-009-9ncn7.18d463fc63220a66,reason=Started count=1 msg=Started container task
0.2357,Event,ADDED,eval-conflicts-rho000-r2-009.18d463fc433037d6,reason=SuccessfulCreate count=1 msg=Created pod: eval-conflicts-rho000-r2-009-9ncn7
0.2359,Event,ADDED,eval-conflicts-rho000-r2-009.18d463ff6dde2d61,reason=Completed count=1 msg=Job completed
0.236,Event,ADDED,eval-conflicts-rho000-r2-010-vr7tg.18d463fc7edcce9c,reason=Scheduled count=None msg=Successfully assigned compute/eval-conflicts-rho000-r2-010-vr7tg to kind-worker2
0.2362,Event,ADDED,eval-conflicts-rho000-r2-010-vr7tg.18d463fc98f51f63,"reason=Pulled count=1 msg=Container image ""busybox:musl"" already present on machine"
0.2363,Event,ADDED,eval-conflicts-rho000-r2-010-vr7tg.18d463fc9a0a3968,reason=Created count=1 msg=Created container: task
0.2366,Event,ADDED,eval-conflicts-rho000-r2-010-vr7tg.18d463fc9dad8857,reason=Started count=1 msg=Started container task
0.2367,Event,ADDED,eval-conflicts-rho000-r2-010.18d463fc7deebfbd,reason=SuccessfulCreate count=1 msg=Created pod: eval-conflicts-rho000-r2-010-vr7tg
0.2369,Event,ADDED,eval-conflicts-rho000-r2-010.18d463ffe511525c,reason=Completed count=1 msg=Job completed
0.237,Event,ADDED,eval-conflicts-rho000-r2-011-pqpnx.18d463fcbaa6ab5e,reason=Scheduled count=None msg=Successfully assigned compute/eval-conflicts-rho000-r2-011-pqpnx to kind-worker3
0.2372,Event,ADDED,eval-conflicts-rho000-r2-011-pqpnx.18d463fcd3b28e6f,"reason=Pulled count=1 msg=Container image ""busybox:musl"" already present on machine"
0.2374,Event,ADDED,eval-conflicts-rho000-r2-011-pqpnx.18d463fcd4f28797,reason=Created count=1 msg=Created container: task
0.2375,Event,ADDED,eval-conflicts-rho000-r2-011-pqpnx.18d463fcd6f640d7,reason=Started count=1 msg=Started container task
0.2377,Event,ADDED,eval-conflicts-rho000-r2-011.18d463fcba3db19c,reason=SuccessfulCreate count=1 msg=Created pod: eval-conflicts-rho000-r2-011-pqpnx
0.2379,Event,ADDED,eval-conflicts-rho000-r2-011.18d463ffe410b022,reason=Completed count=1 msg=Job completed
0.238,Event,ADDED,eval-conflicts-rho000-r2-012-qw98h.18d463fcf59eb308,reason=Scheduled count=None msg=Successfully assigned compute/eval-conflicts-rho000-r2-012-qw98h to kind-worker3
0.2382,Event,ADDED,eval-conflicts-rho000-r2-012-qw98h.18d463fd10595042,"reason=Pulled count=1 msg=Container image ""busybox:musl"" already present on machine"
0.2383,Event,ADDED,eval-conflicts-rho000-r2-012-qw98h.18d463fd11674eb4,reason=Created count=1 msg=Created container: task
0.2385,Event,ADDED,eval-conflicts-rho000-r2-012-qw98h.18d463fd1a81f999,reason=Started count=1 msg=Started container task
0.2387,Event,ADDED,eval-conflicts-rho000-r2-012.18d463fcf50f722c,reason=SuccessfulCreate count=1 msg=Created pod: eval-conflicts-rho000-r2-012-qw98h
0.2388,Event,ADDED,eval-conflicts-rho000-r2-012.18d464005be1c02a,reason=Completed count=1 msg=Job completed
0.239,Event,ADDED,eval-conflicts-rho000-r2-013-hl28n.18d463fd3125280e,reason=Scheduled count=None msg=Successfully assigned compute/eval-conflicts-rho000-r2-013-hl28n to kind-worker3
0.2391,Event,ADDED,eval-conflicts-rho000-r2-013-hl28n.18d463fd4a8b69ca,"reason=Pulled count=1 msg=Container image ""busybox:musl"" already present on machine"
0.2393,Event,ADDED,eval-conflicts-rho000-r2-013-hl28n.18d463fd4b965423,reason=Created count=1 msg=Created container: task
0.2395,Event,ADDED,eval-conflicts-rho000-r2-013-hl28n.18d463fd4d9e426f,reason=Started count=1 msg=Started container task
0.2396,Event,ADDED,eval-conflicts-rho000-r2-013.18d463fd30a13c3e,reason=SuccessfulCreate count=1 msg=Created pod: eval-conflicts-rho000-r2-013-hl28n
0.2398,Event,ADDED,eval-conflicts-rho000-r2-013.18d464005c0287f5,reason=Completed count=1 msg=Job completed
0.2399,Event,ADDED,eval-conflicts-rho000-r2-014-826rj.18d463fd6d9d64ec,reason=Scheduled count=None msg=Successfully assigned compute/eval-conflicts-rho000-r2-014-826rj to kind-worker5
0.2401,Event,ADDED,eval-conflicts-rho000-r2-014-826rj.18d463fd8743f5ae,"reason=Pulled count=1 msg=Container image ""busybox:musl"" already present on machine"
0.2403,Event,ADDED,eval-conflicts-rho000-r2-014-826rj.18d463fd88627076,reason=Created count=1 msg=Created container: task
0.2405,Event,ADDED,eval-conflicts-rho000-r2-014-826rj.18d463fd8c68bc74,reason=Started count=1 msg=Started container task
0.2406,Event,ADDED,eval-conflicts-rho000-r2-014.18d463fd6ce8e81b,reason=SuccessfulCreate count=1 msg=Created pod: eval-conflicts-rho000-r2-014-826rj
0.2408,Event,ADDED,eval-conflicts-rho000-r2-014.18d46400a81d2208,reason=Completed count=1 msg=Job completed
0.2409,Event,ADDED,eval-conflicts-rho000-r2-015-8psxs.18d463fda8dbb818,reason=Scheduled count=None msg=Successfully assigned compute/eval-conflicts-rho000-r2-015-8psxs to kind-worker5
0.2411,Event,ADDED,eval-conflicts-rho000-r2-015-8psxs.18d463fdc2704ef9,"reason=Pulled count=1 msg=Container image ""busybox:musl"" already present on machine"
0.2413,Event,ADDED,eval-conflicts-rho000-r2-015-8psxs.18d463fdc3b2632b,reason=Created count=1 msg=Created container: task
0.2414,Event,ADDED,eval-conflicts-rho000-r2-015-8psxs.18d463fdc72ecd13,reason=Started count=1 msg=Started container task
0.2416,Event,ADDED,eval-conflicts-rho000-r2-015.18d463fda7ed0690,reason=SuccessfulCreate count=1 msg=Created pod: eval-conflicts-rho000-r2-015-8psxs
0.2418,Event,ADDED,eval-conflicts-rho000-r2-015.18d46400e4338290,reason=Completed count=1 msg=Job completed
0.2419,Event,ADDED,eval-conflicts-rho000-r2-016-wstwk.18d463fde4d39a35,reason=Scheduled count=None msg=Successfully assigned compute/eval-conflicts-rho000-r2-016-wstwk to kind-worker5
0.2421,Event,ADDED,eval-conflicts-rho000-r2-016-wstwk.18d463fdfdc65404,"reason=Pulled count=1 msg=Container image ""busybox:musl"" already present on machine"
0.2428,Event,ADDED,eval-conflicts-rho000-r2-016-wstwk.18d463fdfee61887,reason=Created count=1 msg=Created container: task
0.2432,Event,ADDED,eval-conflicts-rho000-r2-016-wstwk.18d463fe011eb276,reason=Started count=1 msg=Started container task
0.2434,Event,ADDED,eval-conflicts-rho000-r2-016.18d463fde3f42b8e,reason=SuccessfulCreate count=1 msg=Created pod: eval-conflicts-rho000-r2-016-wstwk
0.2436,Event,ADDED,eval-conflicts-rho000-r2-016.18d4640120a44028,reason=Completed count=1 msg=Job completed
0.2439,Event,ADDED,eval-conflicts-rho000-r2-017-jrxdn.18d463fe2054f9d2,reason=Scheduled count=None msg=Successfully assigned compute/eval-conflicts-rho000-r2-017-jrxdn to kind-worker5
0.2441,Event,ADDED,eval-conflicts-rho000-r2-017-jrxdn.18d463fe3acdca87,"reason=Pulled count=1 msg=Container image ""busybox:musl"" already present on machine"
0.2443,Event,ADDED,eval-conflicts-rho000-r2-017-jrxdn.18d463fe3bf124d7,reason=Created count=1 msg=Created container: task
0.2446,Event,ADDED,eval-conflicts-rho000-r2-017-jrxdn.18d463fe3e18ec22,reason=Started count=1 msg=Started container task
0.2448,Event,ADDED,eval-conflicts-rho000-r2-017.18d463fe1f6ef1d8,reason=SuccessfulCreate count=1 msg=Created pod: eval-conflicts-rho000-r2-017-jrxdn
0.245,Event,ADDED,eval-conflicts-rho000-r2-017.18d464015d322006,reason=Completed count=1 msg=Job completed
0.2452,Event,ADDED,eval-conflicts-rho000-r2-018-8scfj.18d463fe5bc2cfe6,reason=Scheduled count=None msg=Successfully assigned compute/eval-conflicts-rho000-r2-018-8scfj to kind-worker5
0.2455,Event,ADDED,eval-conflicts-rho000-r2-018-8scfj.18d463fe758dfb4a,"reason=Pulled count=1 msg=Container image ""busybox:musl"" already present on machine"
0.2457,Event,ADDED,eval-conflicts-rho000-r2-018-8scfj.18d463fe76af0541,reason=Created count=1 msg=Created container: task
0.2459,Event,ADDED,eval-conflicts-rho000-r2-018-8scfj.18d463fe78d32305,reason=Started count=1 msg=Started container task
0.2461,Event,ADDED,eval-conflicts-rho000-r2-018.18d463fe5b31f289,reason=SuccessfulCreate count=1 msg=Created pod: eval-conflicts-rho000-r2-018-8scfj
0.2464,Event,ADDED,eval-conflicts-rho000-r2-018.18d4640198c676a9,reason=Completed count=1 msg=Job completed
0.2466,Event,ADDED,eval-conflicts-rho000-r2-019-2sr5m.18d463fe96d0afc4,reason=Scheduled count=None msg=Successfully assigned compute/eval-conflicts-rho000-r2-019-2sr5m to kind-worker5
0.2468,Event,ADDED,eval-conflicts-rho000-r2-019-2sr5m.18d463feb018c682,"reason=Pulled count=1 msg=Container image ""busybox:musl"" already present on machine"
0.2471,Event,ADDED,eval-conflicts-rho000-r2-019-2sr5m.18d463feb1583741,reason=Created count=1 msg=Created container: task
0.2473,Event,ADDED,eval-conflicts-rho000-r2-019-2sr5m.18d463feb34495a6,reason=Started count=1 msg=Started container task
0.2475,Event,ADDED,eval-conflicts-rho000-r2-019.18d463fe96437925,reason=SuccessfulCreate count=1 msg=Created pod: eval-conflicts-rho000-r2-019-2sr5m
0.2476,Event,ADDED,eval-conflicts-rho000-r2-019.18d46401d53687c0,reason=Completed count=1 msg=Job completed
0.2479,Event,ADDED,eval-conflicts-rho000-r2-020-rlj4d.18d463fed2e0465e,reason=Scheduled count=None msg=Successfully assigned compute/eval-conflicts-rho000-r2-020-rlj4d to kind-worker5
0.2481,Event,ADDED,eval-conflicts-rho000-r2-020-rlj4d.18d463feec0b20f3,"reason=Pulled count=1 msg=Container image ""busybox:musl"" already present on machine"
0.2483,Event,ADDED,eval-conflicts-rho000-r2-020-rlj4d.18d463feed1dc493,reason=Created count=1 msg=Created container: task
0.2486,Event,ADDED,eval-conflicts-rho000-r2-020-rlj4d.18d463feef2e7cf6,reason=Started count=1 msg=Started container task
0.249,Event,ADDED,eval-conflicts-rho000-r2-020.18d463fed25cfe93,reason=SuccessfulCreate count=1 msg=Created pod: eval-conflicts-rho000-r2-020-rlj4d
0.2492,Event,ADDED,eval-conflicts-rho000-r2-020.18d4640210852d1f,reason=Completed count=1 msg=Job completed
0.2493,Event,ADDED,eval-conflicts-rho000-r2-021-8zzbf.18d463ff0e6cb5dc,reason=Scheduled count=None msg=Successfully assigned compute/eval-conflicts-rho000-r2-021-8zzbf to kind-worker5
0.2496,Event,ADDED,eval-conflicts-rho000-r2-021-8zzbf.18d463ff27bdbbbc,"reason=Pulled count=1 msg=Container image ""busybox:musl"" already present on machine"
0.2498,Event,ADDED,eval-conflicts-rho000-r2-021-8zzbf.18d463ff28f843a4,reason=Created count=1 msg=Created container: task
0.25,Event,ADDED,eval-conflicts-rho000-r2-021-8zzbf.18d463ff2cb04220,reason=Started count=1 msg=Started container task
0.2502,Event,ADDED,eval-conflicts-rho000-r2-021.18d463ff0dd89dc5,reason=SuccessfulCreate count=1 msg=Created pod: eval-conflicts-rho000-r2-021-8zzbf
0.2505,Event,ADDED,eval-conflicts-rho000-r2-021.18d464024c18119b,reason=Completed count=1 msg=Job completed
0.2506,Event,ADDED,eval-conflicts-rho000-r2-022-q98jz.18d463ff49fd2ef0,reason=Scheduled count=None msg=Successfully assigned compute/eval-conflicts-rho000-r2-022-q98jz to kind-worker4
0.2508,Event,ADDED,eval-conflicts-rho000-r2-022-q98jz.18d463ff62de97ff,"reason=Pulled count=1 msg=Container image ""busybox:musl"" already present on machine"
0.251,Event,ADDED,eval-conflicts-rho000-r2-022-q98jz.18d463ff6422ea4a,reason=Created count=1 msg=Created container: task
0.2512,Event,ADDED,eval-conflicts-rho000-r2-022-q98jz.18d463ff66638bd9,reason=Started count=1 msg=Started container task
0.2514,Event,ADDED,eval-conflicts-rho000-r2-022.18d463ff4919b417,reason=SuccessfulCreate count=1 msg=Created pod: eval-conflicts-rho000-r2-022-q98jz
0.2515,Event,ADDED,eval-conflicts-rho000-r2-022.18d4640277ca52a4,reason=Completed count=1 msg=Job completed
0.2517,Event,ADDED,eval-conflicts-rho000-r2-023-h46qv.18d463ff85c13033,reason=Scheduled count=None msg=Successfully assigned compute/eval-conflicts-rho000-r2-023-h46qv to kind-worker4
0.2519,Event,ADDED,eval-conflicts-rho000-r2-023-h46qv.18d463ff9e640f97,"reason=Pulled count=1 msg=Container image ""busybox:musl"" already present on machine"
0.2521,Event,ADDED,eval-conflicts-rho000-r2-023-h46qv.18d463ff9fcd01ea,reason=Created count=1 msg=Created container: task
0.2522,Event,ADDED,eval-conflicts-rho000-r2-023-h46qv.18d463ffa3f11852,reason=Started count=1 msg=Started container task
0.2526,Event,ADDED,eval-conflicts-rho000-r2-023.18d463ff84b0884f,reason=SuccessfulCreate count=1 msg=Created pod: eval-conflicts-rho000-r2-023-h46qv
0.2528,Event,ADDED,eval-conflicts-rho000-r2-023.18d46402b3c2fd2a,reason=Completed count=1 msg=Job completed
0.2529,Event,ADDED,eval-conflicts-rho000-r2-024-s9vqs.18d463ffc173027d,reason=Scheduled count=None msg=Successfully assigned compute/eval-conflicts-rho000-r2-024-s9vqs to kind-worker4
0.2532,Event,ADDED,eval-conflicts-rho000-r2-024-s9vqs.18d463ffdafb3455,"reason=Pulled count=1 msg=Container image ""busybox:musl"" already present on machine"
0.2534,Event,ADDED,eval-conflicts-rho000-r2-024-s9vqs.18d463ffdc241d0a,reason=Created count=1 msg=Created container: task
0.2536,Event,ADDED,eval-conflicts-rho000-r2-024-s9vqs.18d463ffde3df962,reason=Started count=1 msg=Started container task
0.2538,Event,ADDED,eval-conflicts-rho000-r2-024.18d463ffc0d3e904,reason=SuccessfulCreate count=1 msg=Created pod: eval-conflicts-rho000-r2-024-s9vqs
0.2541,Event,ADDED,eval-conflicts-rho000-r2-024.18d46402efdf4231,reason=Completed count=1 msg=Job completed
0.2542,Event,ADDED,eval-conflicts-rho000-r2-025-w58zh.18d463fffd409712,reason=Scheduled count=None msg=Successfully assigned compute/eval-conflicts-rho000-r2-025-w58zh to kind-worker4
0.2544,Event,ADDED,eval-conflicts-rho000-r2-025-w58zh.18d4640015d57ce8,"reason=Pulled count=1 msg=Container image ""busybox:musl"" already present on machine"
0.2546,Event,ADDED,eval-conflicts-rho000-r2-025-w58zh.18d4640016f050c6,reason=Created count=1 msg=Created container: task
0.2548,Event,ADDED,eval-conflicts-rho000-r2-025-w58zh.18d4640018e679ad,reason=Started count=1 msg=Started container task
0.255,Event,ADDED,eval-conflicts-rho000-r2-025.18d463fffcb13573,reason=SuccessfulCreate count=1 msg=Created pod: eval-conflicts-rho000-r2-025-w58zh
0.2551,Event,ADDED,eval-conflicts-rho000-r2-025.18d464032b78f07d,reason=Completed count=1 msg=Job completed
0.2563,Event,ADDED,eval-conflicts-rho000-r2-026-j9vhl.18d464003a9b3a64,reason=Scheduled count=None msg=Successfully assigned compute/eval-conflicts-rho000-r2-026-j9vhl to kind-worker4
0.2565,Event,ADDED,eval-conflicts-rho000-r2-026-j9vhl.18d46400578ad7f0,"reason=Pulled count=1 msg=Container image ""busybox:musl"" already present on machine"
0.2567,Event,ADDED,eval-conflicts-rho000-r2-026-j9vhl.18d4640058e50d2e,reason=Created count=1 msg=Created container: task
0.2568,Event,ADDED,eval-conflicts-rho000-r2-026-j9vhl.18d464005f561e7c,reason=Started count=1 msg=Started container task
0.2571,Event,ADDED,eval-conflicts-rho000-r2-026.18d4640039eaee4b,reason=SuccessfulCreate count=1 msg=Created pod: eval-conflicts-rho000-r2-026-j9vhl
0.2572,Event,ADDED,eval-conflicts-rho000-r2-026.18d46403a324f6ca,reason=Completed count=1 msg=Job completed
0.2574,Event,ADDED,eval-conflicts-rho000-r2-027-55228.18d4640074b26f95,reason=Scheduled count=None msg=Successfully assigned compute/eval-conflicts-rho000-r2-027-55228 to kind-worker
0.2576,Event,ADDED,eval-conflicts-rho000-r2-027-55228.18d464008f791773,"reason=Pulled count=1 msg=Container image ""busybox:musl"" already present on machine"
0.2577,Event,ADDED,eval-conflicts-rho000-r2-027-55228.18d4640090976baa,reason=Created count=1 msg=Created container: task
0.2579,Event,ADDED,eval-conflicts-rho000-r2-027-55228.18d4640092cfbd96,reason=Started count=1 msg=Started container task
0.2581,Event,ADDED,eval-conflicts-rho000-r2-027.18d4640073e6fbd9,reason=SuccessfulCreate count=1 msg=Created pod: eval-conflicts-rho000-r2-027-55228
0.2582,Event,ADDED,eval-conflicts-rho000-r2-027.18d46403b44d6088,reason=Completed count=1 msg=Job completed
0.2584,Event,ADDED,eval-conflicts-rho000-r2-028-jdcmj.18d46400b0731fb9,reason=Scheduled count=None msg=Successfully assigned compute/eval-conflicts-rho000-r2-028-jdcmj to kind-worker
0.2585,Event,ADDED,eval-conflicts-rho000-r2-028-jdcmj.18d46400ca6e73c9,"reason=Pulled count=1 msg=Container image ""busybox:musl"" already present on machine"
0.2587,Event,ADDED,eval-conflicts-rho000-r2-028-jdcmj.18d46400cd039a20,reason=Created count=1 msg=Created container: task
0.2589,Event,ADDED,eval-conflicts-rho000-r2-028-jdcmj.18d46400d5f0f8df,reason=Started count=1 msg=Started container task
0.2591,Event,ADDED,eval-conflicts-rho000-r2-028.18d46400af86a4ca,reason=SuccessfulCreate count=1 msg=Created pod: eval-conflicts-rho000-r2-028-jdcmj
0.2592,Event,ADDED,eval-conflicts-rho000-r2-028.18d46403f0a77f04,reason=Completed count=1 msg=Job completed
0.2594,Event,ADDED,eval-conflicts-rho000-r2-029-j8z2p.18d46400ebabd6ef,reason=Scheduled count=None msg=Successfully assigned compute/eval-conflicts-rho000-r2-029-j8z2p to kind-worker
0.2595,Event,ADDED,eval-conflicts-rho000-r2-029-j8z2p.18d4640105a67abc,"reason=Pulled count=1 msg=Container image ""busybox:musl"" already present on machine"
0.2597,Event,ADDED,eval-conflicts-rho000-r2-029-j8z2p.18d4640106bec507,reason=Created count=1 msg=Created container: task
0.2599,Event,ADDED,eval-conflicts-rho000-r2-029-j8z2p.18d4640108c151a4,reason=Started count=1 msg=Started container task
0.26,Event,ADDED,eval-conflicts-rho000-r2-029.18d46400ea77ff6b,reason=SuccessfulCreate count=1 msg=Created pod: eval-conflicts-rho000-r2-029-j8z2p
0.2602,Event,ADDED,eval-conflicts-rho000-r2-029.18d46403f10d30ce,reason=Completed count=1 msg=Job completed
0.2603,Event,ADDED,eval-conflicts-rho000-r2-030-rhphj.18d4640127655e98,reason=Scheduled count=None msg=Successfully assigned compute/eval-conflicts-rho000-r2-030-rhphj to kind-worker
0.2605,Event,ADDED,eval-conflicts-rho000-r2-030-rhphj.18d46401415ed470,"reason=Pulled count=1 msg=Container image ""busybox:musl"" already present on machine"
0.2607,Event,ADDED,eval-conflicts-rho000-r2-030-rhphj.18d4640142809379,reason=Created count=1 msg=Created container: task
0.2608,Event,ADDED,eval-conflicts-rho000-r2-030-rhphj.18d4640144b79386,reason=Started count=1 msg=Started container task
0.261,Event,ADDED,eval-conflicts-rho000-r2-030.18d464012689f334,reason=SuccessfulCreate count=1 msg=Created pod: eval-conflicts-rho000-r2-030-rhphj
0.2612,Event,ADDED,eval-conflicts-rho000-r2-030.18d464042cc33160,reason=Completed count=1 msg=Job completed
0.2613,Event,ADDED,eval-conflicts-rho000-r2-031-x77d4.18d46401628eccba,reason=Scheduled count=None msg=Successfully assigned compute/eval-conflicts-rho000-r2-031-x77d4 to kind-worker2
0.2615,Event,ADDED,eval-conflicts-rho000-r2-031-x77d4.18d464017c1d1d5e,"reason=Pulled count=1 msg=Container image ""busybox:musl"" already present on machine"
0.2616,Event,ADDED,eval-conflicts-rho000-r2-031-x77d4.18d464017d3653c8,reason=Created count=1 msg=Created container: task
0.2619,Event,ADDED,eval-conflicts-rho000-r2-031-x77d4.18d46401813866eb,reason=Started count=1 msg=Started container task
0.262,Event,ADDED,eval-conflicts-rho000-r2-031.18d46401619bae39,reason=SuccessfulCreate count=1 msg=Created pod: eval-conflicts-rho000-r2-031-x77d4
0.2622,Event,ADDED,eval-conflicts-rho000-r2-031.18d4640490c4ee2d,reason=Completed count=1 msg=Job completed
0.2623,Event,ADDED,eval-conflicts-rho000-r2-032-vn2c8.18d464019dd3c8dd,reason=Scheduled count=None msg=Successfully assigned compute/eval-conflicts-rho000-r2-032-vn2c8 to kind-worker2
0.2625,Event,ADDED,eval-conflicts-rho000-r2-032-vn2c8.18d46401b6c17e77,"reason=Pulled count=1 msg=Container image ""busybox:musl"" already present on machine"
0.2627,Event,ADDED,eval-conflicts-rho000-r2-032-vn2c8.18d46401b7db0a75,reason=Created count=1 msg=Created container: task
0.2628,Event,ADDED,eval-conflicts-rho000-r2-032-vn2c8.18d46401ba02d125,reason=Started count=1 msg=Started container task
0.263,Event,ADDED,eval-conflicts-rho000-r2-032.18d464019cf6b328,reason=SuccessfulCreate count=1 msg=Created pod: eval-conflicts-rho000-r2-032-vn2c8
0.2632,Event,ADDED,eval-conflicts-rho000-r2-032.18d46404ccfd8745,reason=Completed count=1 msg=Job completed
0.2633,Event,ADDED,eval-conflicts-rho000-r2-033-4k6q8.18d46401dad1b4b7,reason=Scheduled count=None msg=Successfully assigned compute/eval-conflicts-rho000-r2-033-4k6q8 to kind-worker2
0.2635,Event,ADDED,eval-conflicts-rho000-r2-033-4k6q8.18d46401f4813f1b,"reason=Pulled count=1 msg=Container image ""busybox:musl"" already present on machine"
0.2639,Event,ADDED,eval-conflicts-rho000-r2-033-4k6q8.18d46401f5a6f978,reason=Created count=1 msg=Created container: task
0.264,Event,ADDED,eval-conflicts-rho000-r2-033-4k6q8.18d46401f96700f0,reason=Started count=1 msg=Started container task
0.2642,Event,ADDED,eval-conflicts-rho000-r2-033.18d46401d9e4197a,reason=SuccessfulCreate count=1 msg=Created pod: eval-conflicts-rho000-r2-033-4k6q8
0.2644,Event,ADDED,eval-conflicts-rho000-r2-033.18d4640508c1a39e,reason=Completed count=1 msg=Job completed
0.2646,Event,ADDED,eval-conflicts-rho000-r2-034-vnbnq.18d464021624d83c,reason=Scheduled count=None msg=Successfully assigned compute/eval-conflicts-rho000-r2-034-vnbnq to kind-worker5
0.2648,Event,ADDED,eval-conflicts-rho000-r2-034-vnbnq.18d464022fd50aea,"reason=Pulled count=1 msg=Container image ""busybox:musl"" already present on machine"
0.2649,Event,ADDED,eval-conflicts-rho000-r2-034-vnbnq.18d4640230f6d836,reason=Created count=1 msg=Created container: task
0.2653,Event,ADDED,eval-conflicts-rho000-r2-034-vnbnq.18d4640232ef8733,reason=Started count=1 msg=Started container task
0.2654,Event,ADDED,eval-conflicts-rho000-r2-034.18d46402154f6a1f,reason=SuccessfulCreate count=1 msg=Created pod: eval-conflicts-rho000-r2-034-vnbnq
0.2656,Event,ADDED,eval-conflicts-rho000-r2-034.18d4640555a245d7,reason=Completed count=1 msg=Job completed
0.2658,Event,ADDED,eval-conflicts-rho000-r2-035-8nqfh.18d46402511fd1ea,reason=Scheduled count=None msg=Successfully assigned compute/eval-conflicts-rho000-r2-035-8nqfh to kind-worker5
0.2659,Event,ADDED,eval-conflicts-rho000-r2-035-8nqfh.18d464026b04b269,"reason=Pulled count=1 msg=Container image ""busybox:musl"" already present on machine"
0.2661,Event,ADDED,eval-conflicts-rho000-r2-035-8nqfh.18d464026c2da852,reason=Created count=1 msg=Created container: task
0.2663,Event,ADDED,eval-conflicts-rho000-r2-035-8nqfh.18d464026f3d3a0d,reason=Started count=1 msg=Started container task
0.2664,Event,ADDED,eval-conflicts-rho000-r2-035.18d464024ffda5be,reason=SuccessfulCreate count=1 msg=Created pod: eval-conflicts-rho000-r2-035-8nqfh
0.2666,Event,ADDED,eval-conflicts-rho000-r2-035.18d4640591a063f8,reason=Completed count=1 msg=Job completed
0.2668,Event,ADDED,eval-conflicts-rho000-r2-036-29bh7.18d464028cb21fa3,reason=Scheduled count=None msg=Successfully assigned compute/eval-conflicts-rho000-r2-036-29bh7 to kind-worker5
0.2669,Event,ADDED,eval-conflicts-rho000-r2-036-29bh7.18d46402a5ee2b59,"reason=Pulled count=1 msg=Container image ""busybox:musl"" already present on machine"
0.2671,Event,ADDED,eval-conflicts-rho000-r2-036-29bh7.18d46402a710e0fd,reason=Created count=1 msg=Created container: task
0.2673,Event,ADDED,eval-conflicts-rho000-r2-036-29bh7.18d46402a90ed7eb,reason=Started count=1 msg=Started container task
0.2674,Event,ADDED,eval-conflicts-rho000-r2-036.18d464028b7f5fe3,reason=SuccessfulCreate count=1 msg=Created pod: eval-conflicts-rho000-r2-036-29bh7
0.2676,Event,ADDED,eval-conflicts-rho000-r2-036.18d464059269dfc6,reason=Completed count=1 msg=Job completed
0.2677,Event,ADDED,eval-conflicts-rho000-r2-037-2n2n6.18d46402c7dd56cc,reason=Scheduled count=None msg=Successfully assigned compute/eval-conflicts-rho000-r2-037-2n2n6 to kind-worker5
0.2679,Event,ADDED,eval-conflicts-rho000-r2-037-2n2n6.18d46402e1716ab5,"reason=Pulled count=1 msg=Container image ""busybox:musl"" already present on machine"
0.2681,Event,ADDED,eval-conflicts-rho000-r2-037-2n2n6.18d46402e28f306a,reason=Created count=1 msg=Created container: task
0.2682,Event,ADDED,eval-conflicts-rho000-r2-037-2n2n6.18d46402e4975be1,reason=Started count=1 msg=Started container task
0.2684,Event,ADDED,eval-conflicts-rho000-r2-037.18d46402c6fb3300,reason=SuccessfulCreate count=1 msg=Created pod: eval-conflicts-rho000-r2-037-2n2n6
0.2686,Event,ADDED,eval-conflicts-rho000-r2-037.18d46405ce16a556,reason=Completed count=1 msg=Job completed
0.2687,Event,ADDED,eval-conflicts-rho000-r2-038-fj9mh.18d4640304364da1,reason=Scheduled count=None msg=Successfully assigned compute/eval-conflicts-rho000-r2-038-fj9mh to kind-worker2
0.2689,Event,ADDED,eval-conflicts-rho000-r2-038-fj9mh.18d464031d0d77f6,"reason=Pulled count=1 msg=Container image ""busybox:musl"" already present on machine"
0.269,Event,ADDED,eval-conflicts-rho000-r2-038-fj9mh.18d464031e353cad,reason=Created count=1 msg=Created container: task
0.2692,Event,ADDED,eval-conflicts-rho000-r2-038-fj9mh.18d46403222b2892,reason=Started count=1 msg=Started container task
0.2697,Event,ADDED,eval-conflicts-rho000-r2-038.18d464030353f464,reason=SuccessfulCreate count=1 msg=Created pod: eval-conflicts-rho000-r2-038-fj9mh
0.2699,Event,ADDED,eval-conflicts-rho000-r2-038.18d4640633771413,reason=Completed count=1 msg=Job completed
0.2701,Event,ADDED,eval-conflicts-rho000-r2-039-hrkq9.18d464033f746ffb,reason=Scheduled count=None msg=Successfully assigned compute/eval-conflicts-rho000-r2-039-hrkq9 to kind-worker2
0.2703,Event,ADDED,eval-conflicts-rho000-r2-039-hrkq9.18d464035855696a,"reason=Pulled count=1 msg=Container image ""busybox:musl"" already present on machine"
0.2705,Event,ADDED,eval-conflicts-rho000-r2-039-hrkq9.18d46403596cb6cf,reason=Created count=1 msg=Created container: task
0.2707,Event,ADDED,eval-conflicts-rho000-r2-039-hrkq9.18d464035bc0a848,reason=Started count=1 msg=Started container task
0.2709,Event,ADDED,eval-conflicts-rho000-r2-039.18d464033e9217b8,reason=SuccessfulCreate count=1 msg=Created pod: eval-conflicts-rho000-r2-039-hrkq9
0.2711,Event,ADDED,eval-conflicts-rho000-r2-039.18d464066f676c1b,reason=Completed count=1 msg=Job completed
0.2712,Event,ADDED,eval-conflicts-rho000-r2-040-zthcn.18d464037b2504e5,reason=Scheduled count=None msg=Successfully assigned compute/eval-conflicts-rho000-r2-040-zthcn to kind-worker5
0.2714,Event,ADDED,eval-conflicts-rho000-r2-040-zthcn.18d4640394ac43f7,"reason=Pulled count=1 msg=Container image ""busybox:musl"" already present on machine"
0.2716,Event,ADDED,eval-conflicts-rho000-r2-040-zthcn.18d4640395c4341b,reason=Created count=1 msg=Created container: task
0.2717,Event,ADDED,eval-conflicts-rho000-r2-040-zthcn.18d4640397ddc618,reason=Started count=1 msg=Started container task
0.2719,Event,ADDED,eval-conflicts-rho000-r2-040.18d464037a332965,reason=SuccessfulCreate count=1 msg=Created pod: eval-conflicts-rho000-r2-040-zthcn
0.2721,Event,ADDED,eval-conflicts-rho000-r2-040.18d4640681402b85,reason=Completed count=1 msg=Job completed
0.2722,Event,ADDED,eval-conflicts-rho000-r2-041-h7tnh.18d46403b6f28d7f,reason=Scheduled count=None msg=Successfully assigned compute/eval-conflicts-rho000-r2-041-h7tnh to kind-worker5
0.2724,Event,ADDED,eval-conflicts-rho000-r2-041-h7tnh.18d46403d015c65c,"reason=Pulled count=1 msg=Container image ""busybox:musl"" already present on machine"
0.2726,Event,ADDED,eval-conflicts-rho000-r2-041-h7tnh.18d46403d138b7ae,reason=Created count=1 msg=Created container: task
0.2727,Event,ADDED,eval-conflicts-rho000-r2-041-h7tnh.18d46403d45164c1,reason=Started count=1 msg=Started container task
0.2729,Event,ADDED,eval-conflicts-rho000-r2-041.18d46403b63f62b4,reason=SuccessfulCreate count=1 msg=Created pod: eval-conflicts-rho000-r2-041-h7tnh
0.2731,Event,ADDED,eval-conflicts-rho000-r2-041.18d46406bcec92cf,reason=Completed count=1 msg=Job completed
0.2732,Event,ADDED,eval-conflicts-rho000-r2-042-sfbrg.18d46403f2eac11d,reason=Scheduled count=None msg=Successfully assigned compute/eval-conflicts-rho000-r2-042-sfbrg to kind-worker4
0.2734,Event,ADDED,eval-conflicts-rho000-r2-042-sfbrg.18d464040c5696f9,"reason=Pulled count=1 msg=Container image ""busybox:musl"" already present on machine"
0.2735,Event,ADDED,eval-conflicts-rho000-r2-042-sfbrg.18d464040d7a8303,reason=Created count=1 msg=Created container: task
0.2737,Event,ADDED,eval-conflicts-rho000-r2-042-sfbrg.18d464040fcfe55f,reason=Started count=1 msg=Started container task
0.2739,Event,ADDED,eval-conflicts-rho000-r2-042.18d46403f20b4c7a,reason=SuccessfulCreate count=1 msg=Created pod: eval-conflicts-rho000-r2-042-sfbrg
0.2741,Event,ADDED,eval-conflicts-rho000-r2-042.18d4640723afd5a6,reason=Completed count=1 msg=Job completed
0.2744,Event,ADDED,eval-conflicts-rho000-r2-043-8sm6x.18d464042e046e1b,reason=Scheduled count=None msg=Successfully assigned compute/eval-conflicts-rho000-r2-043-8sm6x to kind-worker4
0.2745,Event,ADDED,eval-conflicts-rho000-r2-043-8sm6x.18d4640446d23202,"reason=Pulled count=1 msg=Container image ""busybox:musl"" already present on machine"
0.2747,Event,ADDED,eval-conflicts-rho000-r2-043-8sm6x.18d4640447ee9ed2,reason=Created count=1 msg=Created container: task
0.2749,Event,ADDED,eval-conflicts-rho000-r2-043-8sm6x.18d464044cd43bf7,reason=Started count=1 msg=Started container task
0.2751,Event,ADDED,eval-conflicts-rho000-r2-043.18d464042d048908,reason=SuccessfulCreate count=1 msg=Created pod: eval-conflicts-rho000-r2-043-8sm6x
0.2753,Event,ADDED,eval-conflicts-rho000-r2-043.18d464075f810145,reason=Completed count=1 msg=Job completed
0.2754,Event,ADDED,eval-conflicts-rho000-r2-044-7m5vw.18d464046936d970,reason=Scheduled count=None msg=Successfully assigned compute/eval-conflicts-rho000-r2-044-7m5vw to kind-worker4
0.2756,Event,ADDED,eval-conflicts-rho000-r2-044-7m5vw.18d4640482d9e08c,"reason=Pulled count=1 msg=Container image ""busybox:musl"" already present on machine"
0.2757,Event,ADDED,eval-conflicts-rho000-r2-044-7m5vw.18d464048403d010,reason=Created count=1 msg=Created container: task
0.2759,Event,ADDED,eval-conflicts-rho000-r2-044-7m5vw.18d46404879f7078,reason=Started count=1 msg=Started container task
0.2761,Event,ADDED,eval-conflicts-rho000-r2-044.18d46404686f3166,reason=SuccessfulCreate count=1 msg=Created pod: eval-conflicts-rho000-r2-044-7m5vw
0.2762,Event,ADDED,eval-conflicts-rho000-r2-044.18d464079b1e8d69,reason=Completed count=1 msg=Job completed
0.2764,Event,ADDED,eval-conflicts-rho000-r2-045-zvtw6.18d46404a52f9357,reason=Scheduled count=None msg=Successfully assigned compute/eval-conflicts-rho000-r2-045-zvtw6 to kind-worker4
0.2765,Event,ADDED,eval-conflicts-rho000-r2-045-zvtw6.18d46404bedd52a5,"reason=Pulled count=1 msg=Container image ""busybox:musl"" already present on machine"
0.2767,Event,ADDED,eval-conflicts-rho000-r2-045-zvtw6.18d46404c0079676,reason=Created count=1 msg=Created container: task
0.2769,Event,ADDED,eval-conflicts-rho000-r2-045-zvtw6.18d46404c24f46cf,reason=Started count=1 msg=Started container task
0.277,Event,ADDED,eval-conflicts-rho000-r2-045.18d46404a469395e,reason=SuccessfulCreate count=1 msg=Created pod: eval-conflicts-rho000-r2-045-zvtw6
0.2772,Event,ADDED,eval-conflicts-rho000-r2-045.18d46407d7061468,reason=Completed count=1 msg=Job completed
0.2774,Event,ADDED,eval-conflicts-rho000-r2-046-6qm4h.18d46404e122000f,reason=Scheduled count=None msg=Successfully assigned compute/eval-conflicts-rho000-r2-046-6qm4h to kind-worker3
0.2775,Event,ADDED,eval-conflicts-rho000-r2-046-6qm4h.18d46404fb4a70e3,"reason=Pulled count=1 msg=Container image ""busybox:musl"" already present on machine"
0.2777,Event,ADDED,eval-conflicts-rho000-r2-046-6qm4h.18d46404fc6a54bb,reason=Created count=1 msg=Created container: task
0.2778,Event,ADDED,eval-conflicts-rho000-r2-046-6qm4h.18d46404feaa548a,reason=Started count=1 msg=Started container task
0.278,Event,ADDED,eval-conflicts-rho000-r2-046.18d46404e06d3e06,reason=SuccessfulCreate count=1 msg=Created pod: eval-conflicts-rho000-r2-046-6qm4h
0.2782,Event,ADDED,eval-conflicts-rho000-r2-046.18d464080e6e4b92,reason=Completed count=1 msg=Job completed
0.2783,Event,ADDED,eval-conflicts-rho000-r2-047-frsjv.18d464051ce9fb6a,reason=Scheduled count=None msg=Successfully assigned compute/eval-conflicts-rho000-r2-047-frsjv to kind-worker3
0.2785,Event,ADDED,eval-conflicts-rho000-r2-047-frsjv.18d464053549e82d,"reason=Pulled count=1 msg=Container image ""busybox:musl"" already present on machine"
0.2786,Event,ADDED,eval-conflicts-rho000-r2-047-frsjv.18d46405365a521f,reason=Created count=1 msg=Created container: task
0.2788,Event,ADDED,eval-conflicts-rho000-r2-047-frsjv.18d464053864b2af,reason=Started count=1 msg=Started container task
0.279,Event,ADDED,eval-conflicts-rho000-r2-047.18d464051bb77b80,reason=SuccessfulCreate count=1 msg=Created pod: eval-conflicts-rho000-r2-047-frsjv
0.2791,Event,ADDED,eval-conflicts-rho000-r2-047.18d464084a78129b,reason=Completed count=1 msg=Job completed
0.2793,Event,ADDED,eval-conflicts-rho000-r2-048-s8fzw.18d464055846d36b,reason=Scheduled count=None msg=Successfully assigned compute/eval-conflicts-rho000-r2-048-s8fzw to kind-worker
0.2794,Event,ADDED,eval-conflicts-rho000-r2-048-s8fzw.18d4640570f1cce6,"reason=Pulled count=1 msg=Container image ""busybox:musl"" already present on machine"
0.2796,Event,ADDED,eval-conflicts-rho000-r2-048-s8fzw.18d46405721c6d72,reason=Created count=1 msg=Created container: task
0.2798,Event,ADDED,eval-conflicts-rho000-r2-048-s8fzw.18d4640574207edd,reason=Started count=1 msg=Started container task
0.2799,Event,ADDED,eval-conflicts-rho000-r2-048.18d46405579823a3,reason=SuccessfulCreate count=1 msg=Created pod: eval-conflicts-rho000-r2-048-s8fzw
0.2801,Event,ADDED,eval-conflicts-rho000-r2-048.18d464089c5dead6,reason=Completed count=1 msg=Job completed
0.2802,Event,ADDED,eval-conflicts-rho000-r2-049-dtcbn.18d4640593f7d74d,reason=Scheduled count=None msg=Successfully assigned compute/eval-conflicts-rho000-r2-049-dtcbn to kind-worker
0.2804,Event,ADDED,eval-conflicts-rho000-r2-049-dtcbn.18d46405ac5257e0,"reason=Pulled count=1 msg=Container image ""busybox:musl"" already present on machine"
0.2806,Event,ADDED,eval-conflicts-rho000-r2-049-dtcbn.18d46405ad721abf,reason=Created count=1 msg=Created container: task
0.2807,Event,ADDED,eval-conflicts-rho000-r2-049-dtcbn.18d46405af4e518c,reason=Started count=1 msg=Started container task
0.2809,Event,ADDED,eval-conflicts-rho000-r2-049.18d4640592ff4f3e,reason=SuccessfulCreate count=1 msg=Created pod: eval-conflicts-rho000-r2-049-dtcbn
0.2811,Event,ADDED,eval-conflicts-rho000-r2-049.18d46408d8b00eb0,reason=Completed count=1 msg=Job completed
0.2812,Event,ADDED,eval-conflicts-rho000-r2-050-wk98v.18d46405cf39b3b4,reason=Scheduled count=None msg=Successfully assigned compute/eval-conflicts-rho000-r2-050-wk98v to kind-worker
0.2814,Event,ADDED,eval-conflicts-rho000-r2-050-wk98v.18d46405e820bad6,"reason=Pulled count=1 msg=Container image ""busybox:musl"" already present on machine"
0.2816,Event,ADDED,eval-conflicts-rho000-r2-050-wk98v.18d46405e955d982,reason=Created count=1 msg=Created container: task
0.2818,Event,ADDED,eval-conflicts-rho000-r2-050-wk98v.18d46405ecb89690,reason=Started count=1 msg=Started container task
0.282,Event,ADDED,eval-conflicts-rho000-r2-050.18d46405ce348108,reason=SuccessfulCreate count=1 msg=Created pod: eval-conflicts-rho000-r2-050-wk98v
0.2821,Event,ADDED,eval-conflicts-rho000-r2-050.18d46409143020c7,reason=Completed count=1 msg=Job completed
0.2823,Event,ADDED,eval-conflicts-rho000-r2-051-w5kf7.18d464060a80f045,reason=Scheduled count=None msg=Successfully assigned compute/eval-conflicts-rho000-r2-051-w5kf7 to kind-worker
0.2824,Event,ADDED,eval-conflicts-rho000-r2-051-w5kf7.18d464062394c98e,"reason=Pulled count=1 msg=Container image ""busybox:musl"" already present on machine"
0.2826,Event,ADDED,eval-conflicts-rho000-r2-051-w5kf7.18d4640624a5decd,reason=Created count=1 msg=Created container: task
0.2828,Event,ADDED,eval-conflicts-rho000-r2-051-w5kf7.18d4640626907c99,reason=Started count=1 msg=Started container task
0.2829,Event,ADDED,eval-conflicts-rho000-r2-051.18d4640609bfda87,reason=SuccessfulCreate count=1 msg=Created pod: eval-conflicts-rho000-r2-051-w5kf7
0.2831,Event,ADDED,eval-conflicts-rho000-r2-051.18d464094fcf4920,reason=Completed count=1 msg=Job completed
0.2833,Event,ADDED,eval-conflicts-rho000-r2-052-tgw6q.18d464064672608d,reason=Scheduled count=None msg=Successfully assigned compute/eval-conflicts-rho000-r2-052-tgw6q to kind-worker
0.2834,Event,ADDED,eval-conflicts-rho000-r2-052-tgw6q.18d464066007f8a9,"reason=Pulled count=1 msg=Container image ""busybox:musl"" already present on machine"
0.2836,Event,ADDED,eval-conflicts-rho000-r2-052-tgw6q.18d4640661307897,reason=Created count=1 msg=Created container: task
0.2838,Event,ADDED,eval-conflicts-rho000-r2-052-tgw6q.18d46406656aacaa,reason=Started count=1 msg=Started container task
0.284,Event,ADDED,eval-conflicts-rho000-r2-052.18d4640645d8260f,reason=SuccessfulCreate count=1 msg=Created pod: eval-conflicts-rho000-r2-052-tgw6q
0.2841,Event,ADDED,eval-conflicts-rho000-r2-052.18d464098ba218e4,reason=Completed count=1 msg=Job completed
0.2843,Event,ADDED,eval-conflicts-rho000-r2-053-2c57v.18d46406822e6c62,reason=Scheduled count=None msg=Successfully assigned compute/eval-conflicts-rho000-r2-053-2c57v to kind-worker
0.2844,Event,ADDED,eval-conflicts-rho000-r2-053-2c57v.18d464069b49ddca,"reason=Pulled count=1 msg=Container image ""busybox:musl"" already present on machine"
0.2846,Event,ADDED,eval-conflicts-rho000-r2-053-2c57v.18d464069c60626b,reason=Created count=1 msg=Created container: task
0.2848,Event,ADDED,eval-conflicts-rho000-r2-053-2c57v.18d464069e5088b8,reason=Started count=1 msg=Started container task
0.2849,Event,ADDED,eval-conflicts-rho000-r2-053.18d46406818d8834,reason=SuccessfulCreate count=1 msg=Created pod: eval-conflicts-rho000-r2-053-2c57v
0.2851,Event,ADDED,eval-conflicts-rho000-r2-053.18d46409c7c5afc7,reason=Completed count=1 msg=Job completed
0.2852,Event,ADDED,eval-conflicts-rho000-r2-054-4wkqw.18d46406bd1312c0,reason=Scheduled count=None msg=Successfully assigned compute/eval-conflicts-rho000-r2-054-4wkqw to kind-worker
0.2854,Event,ADDED,eval-conflicts-rho000-r2-054-4wkqw.18d46406d495313a,"reason=Pulled count=1 msg=Container image ""busybox:musl"" already present on machine"
0.2856,Event,ADDED,eval-conflicts-rho000-r2-054-4wkqw.18d46406d5a04a20,reason=Created count=1 msg=Created container: task
0.2857,Event,ADDED,eval-conflicts-rho000-r2-054-4wkqw.18d46406d796ccd7,reason=Started count=1 msg=Started container task
0.2859,Event,ADDED,eval-conflicts-rho000-r2-054.18d46406bc7ad531,reason=SuccessfulCreate count=1 msg=Created pod: eval-conflicts-rho000-r2-054-4wkqw
0.2861,Event,ADDED,eval-conflicts-rho000-r2-054.18d4640a039e7603,reason=Completed count=1 msg=Job completed
0.2862,Event,ADDED,eval-conflicts-rho000-r2-055-x2wgr.18d46406f99f75a7,reason=Scheduled count=None msg=Successfully assigned compute/eval-conflicts-rho000-r2-055-x2wgr to kind-worker5
0.2864,Event,ADDED,eval-conflicts-rho000-r2-055-x2wgr.18d4640713f6c80b,"reason=Pulled count=1 msg=Container image ""busybox:musl"" already present on machine"
0.2865,Event,ADDED,eval-conflicts-rho000-r2-055-x2wgr.18d46407151584d8,reason=Created count=1 msg=Created container: task
0.2867,Event,ADDED,eval-conflicts-rho000-r2-055-x2wgr.18d4640719c467fd,reason=Started count=1 msg=Started container task
0.2869,Event,ADDED,eval-conflicts-rho000-r2-055.18d46406f8edb838,reason=SuccessfulCreate count=1 msg=Created pod: eval-conflicts-rho000-r2-055-x2wgr
0.287,Event,ADDED,eval-conflicts-rho000-r2-055.18d4640a3dcb87e5,reason=Completed count=1 msg=Job completed
0.2872,Event,ADDED,eval-conflicts-rho000-r2-056-zt4r2.18d46407347198b2,reason=Scheduled count=None msg=Successfully assigned compute/eval-conflicts-rho000-r2-056-zt4r2 to kind-worker5
0.2873,Event,ADDED,eval-conflicts-rho000-r2-056-zt4r2.18d464074dc88c11,"reason=Pulled count=1 msg=Container image ""busybox:musl"" already present on machine"
0.2875,Event,ADDED,eval-conflicts-rho000-r2-056-zt4r2.18d464074ef27a3f,reason=Created count=1 msg=Created container: task
0.2877,Event,ADDED,eval-conflicts-rho000-r2-056-zt4r2.18d46407534cdf7e,reason=Started count=1 msg=Started container task
0.2878,Event,ADDED,eval-conflicts-rho000-r2-056.18d4640733a15b88,reason=SuccessfulCreate count=1 msg=Created pod: eval-conflicts-rho000-r2-056-zt4r2
0.288,Event,ADDED,eval-conflicts-rho000-r2-056.18d4640a79ad4149,reason=Completed count=1 msg=Job completed
0.2881,Event,ADDED,eval-conflicts-rho000-r2-057-cjh6q.18d464077045f640,reason=Scheduled count=None msg=Successfully assigned compute/eval-conflicts-rho000-r2-057-cjh6q to kind-worker5
0.2884,Event,ADDED,eval-conflicts-rho000-r2-057-cjh6q.18d4640789902e48,"reason=Pulled count=1 msg=Container image ""busybox:musl"" already present on machine"
0.2885,Event,ADDED,eval-conflicts-rho000-r2-057-cjh6q.18d464078a9c458f,reason=Created count=1 msg=Created container: task
0.2887,Event,ADDED,eval-conflicts-rho000-r2-057-cjh6q.18d464078cdda384,reason=Started count=1 msg=Started container task
0.2889,Event,ADDED,eval-conflicts-rho000-r2-057.18d464076f5d136f,reason=SuccessfulCreate count=1 msg=Created pod: eval-conflicts-rho000-r2-057-cjh6q
0.289,Event,ADDED,eval-conflicts-rho000-r2-057.18d4640ab5a66055,reason=Completed count=1 msg=Job completed
0.2892,Event,ADDED,eval-conflicts-rho000-r2-058-77zm8.18d46407abb1c8b4,reason=Scheduled count=None msg=Successfully assigned compute/eval-conflicts-rho000-r2-058-77zm8 to kind-worker5
0.2893,Event,ADDED,eval-conflicts-rho000-r2-058-77zm8.18d46407c602314d,"reason=Pulled count=1 msg=Container image ""busybox:musl"" already present on machine"
0.2895,Event,ADDED,eval-conflicts-rho000-r2-058-77zm8.18d46407c7299072,reason=Created count=1 msg=Created container: task
0.2897,Event,ADDED,eval-conflicts-rho000-r2-058-77zm8.18d46407cb42cf1f,reason=Started count=1 msg=Started container task
0.2898,Event,ADDED,eval-conflicts-rho000-r2-058.18d46407ab25e6b3,reason=SuccessfulCreate count=1 msg=Created pod: eval-conflicts-rho000-r2-058-77zm8
0.29,Event,ADDED,eval-conflicts-rho000-r2-058.18d4640af345ab7c,reason=Completed count=1 msg=Job completed
0.2902,Event,ADDED,eval-conflicts-rho000-r2-059-7qb4c.18d46407e7313b0d,reason=Scheduled count=None msg=Successfully assigned compute/eval-conflicts-rho000-r2-059-7qb4c to kind-worker5
0.2903,Event,ADDED,eval-conflicts-rho000-r2-059-7qb4c.18d4640801533917,"reason=Pulled count=1 msg=Container image ""busybox:musl"" already present on machine"
0.2905,Event,ADDED,eval-conflicts-rho000-r2-059-7qb4c.18d46408029e7154,reason=Created count=1 msg=Created container: task
0.2907,Event,ADDED,eval-conflicts-rho000-r2-059-7qb4c.18d46408065122e8,reason=Started count=1 msg=Started container task
0.2908,Event,ADDED,eval-conflicts-rho000-r2-059.18d46407e689d592,reason=SuccessfulCreate count=1 msg=Created pod: eval-conflicts-rho000-r2-059-7qb4c
0.291,Event,ADDED,eval-conflicts-rho000-r2-059.18d4640b2f1b9c0e,reason=Completed count=1 msg=Job completed
0.2911,Event,ADDED,eval-conflicts-rho000-r2-060-clq2v.18d4640822b25773,reason=Scheduled count=None msg=Successfully assigned compute/eval-conflicts-rho000-r2-060-clq2v to kind-worker5
0.2913,Event,ADDED,eval-conflicts-rho000-r2-060-clq2v.18d464083b8143d8,"reason=Pulled count=1 msg=Container image ""busybox:musl"" already present on machine"
0.2915,Event,ADDED,eval-conflicts-rho000-r2-060-clq2v.18d464083ca4ad71,reason=Created count=1 msg=Created container: task
0.2916,Event,ADDED,eval-conflicts-rho000-r2-060-clq2v.18d46408402d56b3,reason=Started count=1 msg=Started container task
0.2918,Event,ADDED,eval-conflicts-rho000-r2-060.18d46408222affe4,reason=SuccessfulCreate count=1 msg=Created pod: eval-conflicts-rho000-r2-060-clq2v
0.292,Event,ADDED,eval-conflicts-rho000-r2-060.18d4640b6ad35333,reason=Completed count=1 msg=Job completed
0.2921,Event,ADDED,eval-conflicts-rho000-r2-061-rb6gs.18d464085ea22722,reason=Scheduled count=None msg=Successfully assigned compute/eval-conflicts-rho000-r2-061-rb6gs to kind-worker2
0.2923,Event,ADDED,eval-conflicts-rho000-r2-061-rb6gs.18d46408784688f0,"reason=Pulled count=1 msg=Container image ""busybox:musl"" already present on machine"
0.2924,Event,ADDED,eval-conflicts-rho000-r2-061-rb6gs.18d46408796296a2,reason=Created count=1 msg=Created container: task
0.2926,Event,ADDED,eval-conflicts-rho000-r2-061-rb6gs.18d464087b507274,reason=Started count=1 msg=Started container task
0.2928,Event,ADDED,eval-conflicts-rho000-r2-061.18d464085dc72679,reason=SuccessfulCreate count=1 msg=Created pod: eval-conflicts-rho000-r2-061-rb6gs
0.2929,Event,ADDED,eval-conflicts-rho000-r2-061.18d4640b928028f3,reason=Completed count=1 msg=Job completed
0.2932,Event,ADDED,eval-conflicts-rho000-r2-062-5dzwd.18d464089b130bec,reason=Scheduled count=None msg=Successfully assigned compute/eval-conflicts-rho000-r2-062-5dzwd to kind-worker2
0.2933,Event,ADDED,eval-conflicts-rho000-r2-062-5dzwd.18d46408b5b38601,"reason=Pulled count=1 msg=Container image ""busybox:musl"" already present on machine"
0.2935,Event,ADDED,eval-conflicts-rho000-r2-062-5dzwd.18d46408b6bc8963,reason=Created count=1 msg=Created container: task
0.2937,Event,ADDED,eval-conflicts-rho000-r2-062-5dzwd.18d46408b8e165d9,reason=Started count=1 msg=Started container task
0.2938,Event,ADDED,eval-conflicts-rho000-r2-062.18d4640899d1ac84,reason=SuccessfulCreate count=1 msg=Created pod: eval-conflicts-rho000-r2-062-5dzwd
0.294,Event,ADDED,eval-conflicts-rho000-r2-062.18d4640bce44e9e8,reason=Completed count=1 msg=Job completed
0.2941,Event,ADDED,eval-conflicts-rho000-r2-063-897mh.18d46408d60ec684,reason=Scheduled count=None msg=Successfully assigned compute/eval-conflicts-rho000-r2-063-897mh to kind-worker4
0.2943,Event,ADDED,eval-conflicts-rho000-r2-063-897mh.18d46408ef3a389f,"reason=Pulled count=1 msg=Container image ""busybox:musl"" already present on machine"
0.2945,Event,ADDED,eval-conflicts-rho000-r2-063-897mh.18d46408f045ee85,reason=Created count=1 msg=Created container: task
0.2946,Event,ADDED,eval-conflicts-rho000-r2-063-897mh.18d46408f2740394,reason=Started count=1 msg=Started container task
0.2948,Event,ADDED,eval-conflicts-rho000-r2-063.18d46408d533bd3e,reason=SuccessfulCreate count=1 msg=Created pod: eval-conflicts-rho000-r2-063-897mh
0.295,Event,ADDED,eval-conflicts-rho000-r2-063.18d4640c0a8e6da6,reason=Completed count=1 msg=Job completed
0.2951,Event,ADDED,eval-conflicts-rho000-r2-064-xgsqp.18d4640911e2d85c,reason=Scheduled count=None msg=Successfully assigned compute/eval-conflicts-rho000-r2-064-xgsqp to kind-worker2
0.2953,Event,ADDED,eval-conflicts-rho000-r2-064-xgsqp.18d464092a922331,"reason=Pulled count=1 msg=Container image ""busybox:musl"" already present on machine"
0.2955,Event,ADDED,eval-conflicts-rho000-r2-064-xgsqp.18d464092bc14fb0,reason=Created count=1 msg=Created container: task
0.2957,Event,ADDED,eval-conflicts-rho000-r2-064-xgsqp.18d4640933604e4b,reason=Started count=1 msg=Started container task
0.2958,Event,ADDED,eval-conflicts-rho000-r2-064.18d4640910b5f13e,reason=SuccessfulCreate count=1 msg=Created pod: eval-conflicts-rho000-r2-064-xgsqp
0.296,Event,ADDED,eval-conflicts-rho000-r2-064.18d4640c44efa75c,reason=Completed count=1 msg=Job completed
0.2961,Event,ADDED,eval-conflicts-rho000-r2-065-7vh8p.18d464094d292941,reason=Scheduled count=None msg=Successfully assigned compute/eval-conflicts-rho000-r2-065-7vh8p to kind-worker4
0.2963,Event,ADDED,eval-conflicts-rho000-r2-065-7vh8p.18d4640966047c9c,"reason=Pulled count=1 msg=Container image ""busybox:musl"" already present on machine"
0.2965,Event,ADDED,eval-conflicts-rho000-r2-065-7vh8p.18d464096716b933,reason=Created count=1 msg=Created container: task
0.2966,Event,ADDED,eval-conflicts-rho000-r2-065-7vh8p.18d464096b61a583,reason=Started count=1 msg=Started container task
0.2968,Event,ADDED,eval-conflicts-rho000-r2-065.18d464094c3a5f77,reason=SuccessfulCreate count=1 msg=Created pod: eval-conflicts-rho000-r2-065-7vh8p
0.297,Event,ADDED,eval-conflicts-rho000-r2-065.18d4640c820db583,reason=Completed count=1 msg=Job completed
0.2971,Event,ADDED,eval-conflicts-rho000-r2-066-b7rxn.18d4640988c636e8,reason=Scheduled count=None msg=Successfully assigned compute/eval-conflicts-rho000-r2-066-b7rxn to kind-worker2
0.2973,Event,ADDED,eval-conflicts-rho000-r2-066-b7rxn.18d46409a24f41a5,"reason=Pulled count=1 msg=Container image ""busybox:musl"" already present on machine"
0.2975,Event,ADDED,eval-conflicts-rho000-r2-066-b7rxn.18d46409a3840195,reason=Created count=1 msg=Created container: task
0.2976,Event,ADDED,eval-conflicts-rho000-r2-066-b7rxn.18d46409a67fa000,reason=Started count=1 msg=Started container task
0.2978,Event,ADDED,eval-conflicts-rho000-r2-066.18d4640987debf00,reason=SuccessfulCreate count=1 msg=Created pod: eval-conflicts-rho000-r2-066-b7rxn
0.2979,Event,ADDED,eval-conflicts-rho000-r2-066.18d4640cbcf3633c,reason=Completed count=1 msg=Job completed
0.2981,Event,ADDED,eval-conflicts-rho000-r2-067-5x6nx.18d46409c41b192e,reason=Scheduled count=None msg=Successfully assigned compute/eval-conflicts-rho000-r2-067-5x6nx to kind-worker4
0.2983,Event,ADDED,eval-conflicts-rho000-r2-067-5x6nx.18d46409dc32c80c,"reason=Pulled count=1 msg=Container image ""busybox:musl"" already present on machine"
0.2984,Event,ADDED,eval-conflicts-rho000-r2-067-5x6nx.18d46409dd74309f,reason=Created count=1 msg=Created container: task
0.2986,Event,ADDED,eval-conflicts-rho000-r2-067-5x6nx.18d46409df9c1ffe,reason=Started count=1 msg=Started container task
0.2987,Event,ADDED,eval-conflicts-rho000-r2-067.18d46409c340d8d6,reason=SuccessfulCreate count=1 msg=Created pod: eval-conflicts-rho000-r2-067-5x6nx
0.2989,Event,ADDED,eval-conflicts-rho000-r2-067.18d4640cf9d05ab4,reason=Completed count=1 msg=Job completed
0.2991,Event,ADDED,eval-conflicts-rho000-r2-068-9qrch.18d46409ffefeed5,reason=Scheduled count=None msg=Successfully assigned compute/eval-conflicts-rho000-r2-068-9qrch to kind-worker
0.2992,Event,ADDED,eval-conflicts-rho000-r2-068-9qrch.18d4640a190c3ec7,"reason=Pulled count=1 msg=Container image ""busybox:musl"" already present on machine"
0.2994,Event,ADDED,eval-conflicts-rho000-r2-068-9qrch.18d4640a1a2d22ca,reason=Created count=1 msg=Created container: task
0.2995,Event,ADDED,eval-conflicts-rho000-r2-068-9qrch.18d4640a1dc7bffb,reason=Started count=1 msg=Started container task
0.2997,Event,ADDED,eval-conflicts-rho000-r2-068.18d46409fef5b369,reason=SuccessfulCreate count=1 msg=Created pod: eval-conflicts-rho000-r2-068-9qrch
0.2999,Event,ADDED,eval-conflicts-rho000-r2-068.18d4640d4a5e1ce4,reason=Completed count=1 msg=Job completed
0.3,Event,ADDED,eval-conflicts-rho000-r2-069-xrtnc.18d4640a3c2c628d,reason=Scheduled count=None msg=Successfully assigned compute/eval-conflicts-rho000-r2-069-xrtnc to kind-worker
0.3002,Event,ADDED,eval-conflicts-rho000-r2-069-xrtnc.18d4640a559769fa,"reason=Pulled count=1 msg=Container image ""busybox:musl"" already present on machine"
0.3003,Event,ADDED,eval-conflicts-rho000-r2-069-xrtnc.18d4640a56aac66f,reason=Created count=1 msg=Created container: task
0.3005,Event,ADDED,eval-conflicts-rho000-r2-069-xrtnc.18d4640a58cab910,reason=Started count=1 msg=Started container task
0.3007,Event,ADDED,eval-conflicts-rho000-r2-069.18d4640a3aa58aee,reason=SuccessfulCreate count=1 msg=Created pod: eval-conflicts-rho000-r2-069-xrtnc
0.3008,Event,ADDED,eval-conflicts-rho000-r2-069.18d4640d84702253,reason=Completed count=1 msg=Job completed
0.301,Event,ADDED,eval-conflicts-rho000-r2-070-psfvd.18d4640a77a77854,reason=Scheduled count=None msg=Successfully assigned compute/eval-conflicts-rho000-r2-070-psfvd to kind-worker
0.3012,Event,ADDED,eval-conflicts-rho000-r2-070-psfvd.18d4640a90ce8c4e,"reason=Pulled count=1 msg=Container image ""busybox:musl"" already present on machine"
0.3013,Event,ADDED,eval-conflicts-rho000-r2-070-psfvd.18d4640a91eb157f,reason=Created count=1 msg=Created container: task
0.3015,Event,ADDED,eval-conflicts-rho000-r2-070-psfvd.18d4640a963e762c,reason=Started count=1 msg=Started container task
0.3016,Event,ADDED,eval-conflicts-rho000-r2-070.18d4640a7661fd15,reason=SuccessfulCreate count=1 msg=Created pod: eval-conflicts-rho000-r2-070-psfvd
0.3018,Event,ADDED,eval-conflicts-rho000-r2-070.18d4640dc11935f9,reason=Completed count=1 msg=Job completed
0.302,Event,ADDED,eval-conflicts-rho000-r2-071-m9sck.18d4640ab2b3a6de,reason=Scheduled count=None msg=Successfully assigned compute/eval-conflicts-rho000-r2-071-m9sck to kind-worker
0.3022,Event,ADDED,eval-conflicts-rho000-r2-071-m9sck.18d4640acb429350,"reason=Pulled count=1 msg=Container image ""busybox:musl"" already present on machine"
0.3023,Event,ADDED,eval-conflicts-rho000-r2-071-m9sck.18d4640acc731864,reason=Created count=1 msg=Created container: task
0.3025,Event,ADDED,eval-conflicts-rho000-r2-071-m9sck.18d4640ace831d0a,reason=Started count=1 msg=Started container task
0.3027,Event,ADDED,eval-conflicts-rho000-r2-071.18d4640ab1cee681,reason=SuccessfulCreate count=1 msg=Created pod: eval-conflicts-rho000-r2-071-m9sck
0.3029,Event,ADDED,eval-conflicts-rho000-r2-071.18d4640dfcacb41d,reason=Completed count=1 msg=Job completed
0.3031,Event,ADDED,eval-conflicts-rho000-r2-072-29xmk.18d4640aee69826c,reason=Scheduled count=None msg=Successfully assigned compute/eval-conflicts-rho000-r2-072-29xmk to kind-worker
0.3032,Event,ADDED,eval-conflicts-rho000-r2-072-29xmk.18d4640b07b8ed18,"reason=Pulled count=1 msg=Container image ""busybox:musl"" already present on machine"
0.3034,Event,ADDED,eval-conflicts-rho000-r2-072-29xmk.18d4640b08d21f76,reason=Created count=1 msg=Created container: task
0.3035,Event,ADDED,eval-conflicts-rho000-r2-072-29xmk.18d4640b0c9f4ec1,reason=Started count=1 msg=Started container task
0.3037,Event,ADDED,eval-conflicts-rho000-r2-072.18d4640aed97d193,reason=SuccessfulCreate count=1 msg=Created pod: eval-conflicts-rho000-r2-072-29xmk
0.3039,Event,ADDED,eval-conflicts-rho000-r2-072.18d4640e38c4fbc9,reason=Completed count=1 msg=Job completed
0.304,Event,ADDED,eval-conflicts-rho000-r2-073-ntlmg.18d4640b29cdf108,reason=Scheduled count=None msg=Successfully assigned compute/eval-conflicts-rho000-r2-073-ntlmg to kind-worker3
0.3042,Event,ADDED,eval-conflicts-rho000-r2-073-ntlmg.18d4640b42082ad2,"reason=Pulled count=1 msg=Container image ""busybox:musl"" already present on machine"
0.3044,Event,ADDED,eval-conflicts-rho000-r2-073-ntlmg.18d4640b430e2084,reason=Created count=1 msg=Created container: task
0.3045,Event,ADDED,eval-conflicts-rho000-r2-073-ntlmg.18d4640b4641218a,reason=Started count=1 msg=Started container task
0.3047,Event,ADDED,eval-conflicts-rho000-r2-073.18d4640b28f313cd,reason=SuccessfulCreate count=1 msg=Created pod: eval-conflicts-rho000-r2-073-ntlmg
0.3049,Event,ADDED,eval-conflicts-rho000-r2-073.18d4640e5b91c31b,reason=Completed count=1 msg=Job completed
0.305,Event,ADDED,eval-conflicts-rho000-r2-074-9jtb7.18d4640b682473ea,reason=Scheduled count=None msg=Successfully assigned compute/eval-conflicts-rho000-r2-074-9jtb7 to kind-worker3
0.3052,Event,ADDED,eval-conflicts-rho000-r2-074-9jtb7.18d4640b828a44ce,"reason=Pulled count=1 msg=Container image ""busybox:musl"" already present on machine"
0.3053,Event,ADDED,eval-conflicts-rho000-r2-074-9jtb7.18d4640b83bf6f04,reason=Created count=1 msg=Created container: task
0.3055,Event,ADDED,eval-conflicts-rho000-r2-074-9jtb7.18d4640b87ae74f1,reason=Started count=1 msg=Started container task
0.3057,Event,ADDED,eval-conflicts-rho000-r2-074.18d4640b672ad51e,reason=SuccessfulCreate count=1 msg=Created pod: eval-conflicts-rho000-r2-074-9jtb7
0.3058,Event,ADDED,eval-conflicts-rho000-r2-074.18d4640ed4f32ac7,reason=Completed count=1 msg=Job completed
0.306,Event,ADDED,eval-conflicts-rho000-r2-075-5jzrs.18d4640ba11cdded,reason=Scheduled count=None msg=Successfully assigned compute/eval-conflicts-rho000-r2-075-5jzrs to kind-worker5
0.3061,Event,ADDED,eval-conflicts-rho000-r2-075-5jzrs.18d4640bba4a68e6,"reason=Pulled count=1 msg=Container image ""busybox:musl"" already present on machine"
0.3063,Event,ADDED,eval-conflicts-rho000-r2-075-5jzrs.18d4640bbb579a35,reason=Created count=1 msg=Created container: task
0.3065,Event,ADDED,eval-conflicts-rho000-r2-075-5jzrs.18d4640bc070a6f1,reason=Started count=1 msg=Started container task
0.3066,Event,ADDED,eval-conflicts-rho000-r2-075.18d4640ba0459ecc,reason=SuccessfulCreate count=1 msg=Created pod: eval-conflicts-rho000-r2-075-5jzrs
0.3068,Event,ADDED,eval-conflicts-rho000-r2-075.18d4640eec6ae770,reason=Completed count=1 msg=Job completed
0.3069,Event,ADDED,eval-conflicts-rho000-r2-076-mln2n.18d4640bdd273670,reason=Scheduled count=None msg=Successfully assigned compute/eval-conflicts-rho000-r2-076-mln2n to kind-worker5
0.3071,Event,ADDED,eval-conflicts-rho000-r2-076-mln2n.18d4640bf9007749,"reason=Pulled count=1 msg=Container image ""busybox:musl"" already present on machine"
0.3073,Event,ADDED,eval-conflicts-rho000-r2-076-mln2n.18d4640bfa21535d,reason=Created count=1 msg=Created container: task
0.3074,Event,ADDED,eval-conflicts-rho000-r2-076-mln2n.18d4640bfe005834,reason=Started count=1 msg=Started container task
0.3076,Event,ADDED,eval-conflicts-rho000-r2-076.18d4640bdc195ac4,reason=SuccessfulCreate count=1 msg=Created pod: eval-conflicts-rho000-r2-076-mln2n
0.3078,Event,ADDED,eval-conflicts-rho000-r2-076.18d4640f284727aa,reason=Completed count=1 msg=Job completed
0.3079,Event,ADDED,eval-conflicts-rho000-r2-077-kmp8j.18d4640c1905c71b,reason=Scheduled count=None msg=Successfully assigned compute/eval-conflicts-rho000-r2-077-kmp8j to kind-worker5
0.3081,Event,ADDED,eval-conflicts-rho000-r2-077-kmp8j.18d4640c343cd007,"reason=Pulled count=1 msg=Container image ""busybox:musl"" already present on machine"
0.3083,Event,ADDED,eval-conflicts-rho000-r2-077-kmp8j.18d4640c35a2c14e,reason=Created count=1 msg=Created container: task
0.3084,Event,ADDED,eval-conflicts-rho000-r2-077-kmp8j.18d4640c3ac17f51,reason=Started count=1 msg=Started container task
0.3086,Event,ADDED,eval-conflicts-rho000-r2-077.18d4640c17ce6a59,reason=SuccessfulCreate count=1 msg=Created pod: eval-conflicts-rho000-r2-077-kmp8j
0.3087,Event,ADDED,eval-conflicts-rho000-r2-077.18d4640f637c46cb,reason=Completed count=1 msg=Job completed
0.309,Event,ADDED,eval-conflicts-rho000-r2-078-s99d7.18d4640c5376cb37,reason=Scheduled count=None msg=Successfully assigned compute/eval-conflicts-rho000-r2-078-s99d7 to kind-worker5
0.3091,Event,ADDED,eval-conflicts-rho000-r2-078-s99d7.18d4640c6d68f0be,"reason=Pulled count=1 msg=Container image ""busybox:musl"" already present on machine"
0.3093,Event,ADDED,eval-conflicts-rho000-r2-078-s99d7.18d4640c6e780b82,reason=Created count=1 msg=Created container: task
0.3095,Event,ADDED,eval-conflicts-rho000-r2-078-s99d7.18d4640c73319bd5,reason=Started count=1 msg=Started container task
0.3096,Event,ADDED,eval-conflicts-rho000-r2-078.18d4640c52ced0a4,reason=SuccessfulCreate count=1 msg=Created pod: eval-conflicts-rho000-r2-078-s99d7
0.3098,Event,ADDED,eval-conflicts-rho000-r2-078.18d4640f9f6669f0,reason=Completed count=1 msg=Job completed
0.3099,Event,ADDED,eval-conflicts-rho000-r2-079-6fq28.18d4640c8f2d524d,reason=Scheduled count=None msg=Successfully assigned compute/eval-conflicts-rho000-r2-079-6fq28 to kind-worker5
0.3101,Event,ADDED,eval-conflicts-rho000-r2-079-6fq28.18d4640ca88cdb90,"reason=Pulled count=1 msg=Container image ""busybox:musl"" already present on machine"
0.3103,Event,ADDED,eval-conflicts-rho000-r2-079-6fq28.18d4640ca9b1b1f4,reason=Created count=1 msg=Created container: task
0.3105,Event,ADDED,eval-conflicts-rho000-r2-079-6fq28.18d4640cabb22b63,reason=Started count=1 msg=Started container task
0.3106,Event,ADDED,eval-conflicts-rho000-r2-079.18d4640c8e9a8467,reason=SuccessfulCreate count=1 msg=Created pod: eval-conflicts-rho000-r2-079-6fq28
0.3108,Event,ADDED,eval-conflicts-rho000-r2-079.18d4640fdb7b1eb5,reason=Completed count=1 msg=Job completed
0.3109,Event,ADDED,eval-conflicts-rho000-r2-080-ck6nh.18d4640ccadf35eb,reason=Scheduled count=None msg=Successfully assigned compute/eval-conflicts-rho000-r2-080-ck6nh to kind-worker5
0.3111,Event,ADDED,eval-conflicts-rho000-r2-080-ck6nh.18d4640ce41ed77d,"reason=Pulled count=1 msg=Container image ""busybox:musl"" already present on machine"
0.3113,Event,ADDED,eval-conflicts-rho000-r2-080-ck6nh.18d4640ce55330c0,reason=Created count=1 msg=Created container: task
0.3114,Event,ADDED,eval-conflicts-rho000-r2-080-ck6nh.18d4640ce9089c21,reason=Started count=1 msg=Started container task
0.3117,Event,ADDED,eval-conflicts-rho000-r2-080.18d4640cca60cf8b,reason=SuccessfulCreate count=1 msg=Created pod: eval-conflicts-rho000-r2-080-ck6nh
0.3118,Event,ADDED,eval-conflicts-rho000-r2-080.18d4641015c8e399,reason=Completed count=1 msg=Job completed
0.312,Event,ADDED,eval-conflicts-rho000-r2-081-8vz96.18d4640d067100a8,reason=Scheduled count=None msg=Successfully assigned compute/eval-conflicts-rho000-r2-081-8vz96 to kind-worker5
0.3121,Event,ADDED,eval-conflicts-rho000-r2-081-8vz96.18d4640d2144d64f,"reason=Pulled count=1 msg=Container image ""busybox:musl"" already present on machine"
0.3123,Event,ADDED,eval-conflicts-rho000-r2-081-8vz96.18d4640d225a59ec,reason=Created count=1 msg=Created container: task
0.3125,Event,ADDED,eval-conflicts-rho000-r2-081-8vz96.18d4640d2b928775,reason=Started count=1 msg=Started container task
0.3126,Event,ADDED,eval-conflicts-rho000-r2-081.18d4640d05cd71f1,reason=SuccessfulCreate count=1 msg=Created pod: eval-conflicts-rho000-r2-081-8vz96
0.3128,Event,ADDED,eval-conflicts-rho000-r2-081.18d4641051a4914e,reason=Completed count=1 msg=Job completed
0.313,Event,ADDED,eval-conflicts-rho000-r2-082-24wwj.18d4640d431e9dff,reason=Scheduled count=None msg=Successfully assigned compute/eval-conflicts-rho000-r2-082-24wwj to kind-worker2
0.3131,Event,ADDED,eval-conflicts-rho000-r2-082-24wwj.18d4640d5d2c082a,"reason=Pulled count=1 msg=Container image ""busybox:musl"" already present on machine"
0.3133,Event,ADDED,eval-conflicts-rho000-r2-082-24wwj.18d4640d5e3f8a9f,reason=Created count=1 msg=Created container: task
0.3134,Event,ADDED,eval-conflicts-rho000-r2-082-24wwj.18d4640d6236961e,reason=Started count=1 msg=Started container task
0.3136,Event,ADDED,eval-conflicts-rho000-r2-082.18d4640d424e853e,reason=SuccessfulCreate count=1 msg=Created pod: eval-conflicts-rho000-r2-082-24wwj
0.3138,Event,ADDED,eval-conflicts-rho000-r2-082.18d46410790479a6,reason=Completed count=1 msg=Job completed
0.3139,Event,ADDED,eval-conflicts-rho000-r2-083-lnkzc.18d4640d7eaf79f5,reason=Scheduled count=None msg=Successfully assigned compute/eval-conflicts-rho000-r2-083-lnkzc to kind-worker2
0.3141,Event,ADDED,eval-conflicts-rho000-r2-083-lnkzc.18d4640d983e5e81,"reason=Pulled count=1 msg=Container image ""busybox:musl"" already present on machine"
0.3143,Event,ADDED,eval-conflicts-rho000-r2-083-lnkzc.18d4640d9943274e,reason=Created count=1 msg=Created container: task
0.3144,Event,ADDED,eval-conflicts-rho000-r2-083-lnkzc.18d4640d9d083669,reason=Started count=1 msg=Started container task
0.3146,Event,ADDED,eval-conflicts-rho000-r2-083.18d4640d7d80513f,reason=SuccessfulCreate count=1 msg=Created pod: eval-conflicts-rho000-r2-083-lnkzc
0.3147,Event,ADDED,eval-conflicts-rho000-r2-083.18d46410b49c6a03,reason=Completed count=1 msg=Job completed
0.3149,Event,ADDED,eval-conflicts-rho000-r2-084-krn2p.18d4640dbb85d881,reason=Scheduled count=None msg=Successfully assigned compute/eval-conflicts-rho000-r2-084-krn2p to kind-worker4
0.3151,Event,ADDED,eval-conflicts-rho000-r2-084-krn2p.18d4640dd6c5e040,"reason=Pulled count=1 msg=Container image ""busybox:musl"" already present on machine"
0.3152,Event,ADDED,eval-conflicts-rho000-r2-084-krn2p.18d4640dd7f6e3a0,reason=Created count=1 msg=Created container: task
0.3154,Event,ADDED,eval-conflicts-rho000-r2-084-krn2p.18d4640de16d889a,reason=Started count=1 msg=Started container task
0.3155,Event,ADDED,eval-conflicts-rho000-r2-084.18d4640dbaa58f2a,reason=SuccessfulCreate count=1 msg=Created pod: eval-conflicts-rho000-r2-084-krn2p
0.3157,Event,ADDED,eval-conflicts-rho000-r2-084.18d46410f14f8250,reason=Completed count=1 msg=Job completed
0.3159,Event,ADDED,eval-conflicts-rho000-r2-085-w57qr.18d4640df531bb12,reason=Scheduled count=None msg=Successfully assigned compute/eval-conflicts-rho000-r2-085-w57qr to kind-worker2
0.3161,Event,ADDED,eval-conflicts-rho000-r2-085-w57qr.18d4640e1025ff88,"reason=Pulled count=1 msg=Container image ""busybox:musl"" already present on machine"
0.3162,Event,ADDED,eval-conflicts-rho000-r2-085-w57qr.18d4640e112fe0a1,reason=Created count=1 msg=Created container: task
0.3164,Event,ADDED,eval-conflicts-rho000-r2-085-w57qr.18d4640e1465a320,reason=Started count=1 msg=Started container task
0.3166,Event,ADDED,eval-conflicts-rho000-r2-085.18d4640df4551c70,reason=SuccessfulCreate count=1 msg=Created pod: eval-conflicts-rho000-r2-085-w57qr
0.3167,Event,ADDED,eval-conflicts-rho000-r2-085.18d464112c61b2b8,reason=Completed count=1 msg=Job completed
0.3169,Event,ADDED,eval-conflicts-rho000-r2-086-vzrfc.18d4640e30bc1d76,reason=Scheduled count=None msg=Successfully assigned compute/eval-conflicts-rho000-r2-086-vzrfc to kind-worker2
0.317,Event,ADDED,eval-conflicts-rho000-r2-086-vzrfc.18d4640e4d12994d,"reason=Pulled count=1 msg=Container image ""busybox:musl"" already present on machine"
0.3172,Event,ADDED,eval-conflicts-rho000-r2-086-vzrfc.18d4640e4e39c3b3,reason=Created count=1 msg=Created container: task
0.3174,Event,ADDED,eval-conflicts-rho000-r2-086-vzrfc.18d4640e5283e209,reason=Started count=1 msg=Started container task
0.3175,Event,ADDED,eval-conflicts-rho000-r2-086.18d4640e2fe4ec81,reason=SuccessfulCreate count=1 msg=Created pod: eval-conflicts-rho000-r2-086-vzrfc
0.3177,Event,ADDED,eval-conflicts-rho000-r2-086.18d464116874f45d,reason=Completed count=1 msg=Job completed
0.3178,Event,ADDED,eval-conflicts-rho000-r2-087-4vbqn.18d4640e6c7082e9,reason=Scheduled count=None msg=Successfully assigned compute/eval-conflicts-rho000-r2-087-4vbqn to kind-worker2
0.318,Event,ADDED,eval-conflicts-rho000-r2-087-4vbqn.18d4640e874fff59,"reason=Pulled count=1 msg=Container image ""busybox:musl"" already present on machine"
0.3182,Event,ADDED,eval-conflicts-rho000-r2-087-4vbqn.18d4640e888ab8d6,reason=Created count=1 msg=Created container: task
0.3183,Event,ADDED,eval-conflicts-rho000-r2-087-4vbqn.18d4640e8aa96833,reason=Started count=1 msg=Started container task
0.3185,Event,ADDED,eval-conflicts-rho000-r2-087.18d4640e6b7d31e0,reason=SuccessfulCreate count=1 msg=Created pod: eval-conflicts-rho000-r2-087-4vbqn
0.3187,Event,ADDED,eval-conflicts-rho000-r2-087.18d46411a45e858b,reason=Completed count=1 msg=Job completed
0.3188,Event,ADDED,eval-conflicts-rho000-r2-088-pjb6m.18d4640ea8560ab0,reason=Scheduled count=None msg=Successfully assigned compute/eval-conflicts-rho000-r2-088-pjb6m to kind-worker
0.319,Event,ADDED,eval-conflicts-rho000-r2-088-pjb6m.18d4640ec3d9bd88,"reason=Pulled count=1 msg=Container image ""busybox:musl"" already present on machine"
0.3191,Event,ADDED,eval-conflicts-rho000-r2-088-pjb6m.18d4640ec50d7dc4,reason=Created count=1 msg=Created container: task
0.3193,Event,ADDED,eval-conflicts-rho000-r2-088-pjb6m.18d4640ecea03de3,reason=Started count=1 msg=Started container task
0.3195,Event,ADDED,eval-conflicts-rho000-r2-088.18d4640ea78284f8,reason=SuccessfulCreate count=1 msg=Created pod: eval-conflicts-rho000-r2-088-pjb6m
0.3196,Event,ADDED,eval-conflicts-rho000-r2-088.18d46411b96d5c2e,reason=Completed count=1 msg=Job completed
0.3198,Event,ADDED,eval-conflicts-rho000-r2-089-ffqrl.18d4640ee5d67d5d,reason=Scheduled count=None msg=Successfully assigned compute/eval-conflicts-rho000-r2-089-ffqrl to kind-worker
0.32,Event,ADDED,eval-conflicts-rho000-r2-089-ffqrl.18d4640f0102b796,"reason=Pulled count=1 msg=Container image ""busybox:musl"" already present on machine"
0.3201,Event,ADDED,eval-conflicts-rho000-r2-089-ffqrl.18d4640f0230e2ce,reason=Created count=1 msg=Created container: task
0.3203,Event,ADDED,eval-conflicts-rho000-r2-089-ffqrl.18d4640f06758cf4,reason=Started count=1 msg=Started container task
0.3204,Event,ADDED,eval-conflicts-rho000-r2-089.18d4640ee49644ca,reason=SuccessfulCreate count=1 msg=Created pod: eval-conflicts-rho000-r2-089-ffqrl
0.3206,Event,ADDED,eval-conflicts-rho000-r2-089.18d4641230ca8b82,reason=Completed count=1 msg=Job completed
0.3208,Event,ADDED,eval-conflicts-rho000-r2-090-7b765.18d4640f1f681bd2,reason=Scheduled count=None msg=Successfully assigned compute/eval-conflicts-rho000-r2-090-7b765 to kind-worker
0.3209,Event,ADDED,eval-conflicts-rho000-r2-090-7b765.18d4640f37988d6e,"reason=Pulled count=1 msg=Container image ""busybox:musl"" already present on machine"
0.3211,Event,ADDED,eval-conflicts-rho000-r2-090-7b765.18d4640f39220c88,reason=Created count=1 msg=Created container: task
0.3214,Event,ADDED,eval-conflicts-rho000-r2-090-7b765.18d4640f3b3b675a,reason=Started count=1 msg=Started container task
0.3216,Event,ADDED,eval-conflicts-rho000-r2-090.18d4640f1e4a2290,reason=SuccessfulCreate count=1 msg=Created pod: eval-conflicts-rho000-r2-090-7b765
0.3218,Event,ADDED,eval-conflicts-rho000-r2-090.18d464126cd0026f,reason=Completed count=1 msg=Job completed
0.3221,Event,ADDED,eval-conflicts-rho000-r2-091-4hjgt.18d4640f5aee96e3,reason=Scheduled count=None msg=Successfully assigned compute/eval-conflicts-rho000-r2-091-4hjgt to kind-worker
0.3222,Event,ADDED,eval-conflicts-rho000-r2-091-4hjgt.18d4640f74d30214,"reason=Pulled count=1 msg=Container image ""busybox:musl"" already present on machine"
0.3224,Event,ADDED,eval-conflicts-rho000-r2-091-4hjgt.18d4640f75ef2463,reason=Created count=1 msg=Created container: task
0.3226,Event,ADDED,eval-conflicts-rho000-r2-091-4hjgt.18d4640f780f233e,reason=Started count=1 msg=Started container task
0.3228,Event,ADDED,eval-conflicts-rho000-r2-091.18d4640f59a875f5,reason=SuccessfulCreate count=1 msg=Created pod: eval-conflicts-rho000-r2-091-4hjgt
0.323,Event,ADDED,eval-conflicts-rho000-r2-091.18d46412a8aa54c7,reason=Completed count=1 msg=Job completed
0.3231,Event,ADDED,eval-conflicts-rho000-r2-092-9cpbr.18d4640f96b4bad7,reason=Scheduled count=None msg=Successfully assigned compute/eval-conflicts-rho000-r2-092-9cpbr to kind-worker
0.3233,Event,ADDED,eval-conflicts-rho000-r2-092-9cpbr.18d4640fb1b7ca82,"reason=Pulled count=1 msg=Container image ""busybox:musl"" already present on machine"
0.3257,Event,ADDED,eval-conflicts-rho000-r2-092-9cpbr.18d4640fb2c6b49c,reason=Created count=1 msg=Created container: task
0.3258,Event,ADDED,eval-conflicts-rho000-r2-092-9cpbr.18d4640fb4b67db0,reason=Started count=1 msg=Started container task
0.326,Event,ADDED,eval-conflicts-rho000-r2-092.18d4640f95ee3ab4,reason=SuccessfulCreate count=1 msg=Created pod: eval-conflicts-rho000-r2-092-9cpbr
0.3262,Event,ADDED,eval-conflicts-rho000-r2-092.18d46412e4ae1d37,reason=Completed count=1 msg=Job completed
0.3263,Event,ADDED,eval-conflicts-rho000-r2-093-75nc6.18d4640fd1c4c433,reason=Scheduled count=None msg=Successfully assigned compute/eval-conflicts-rho000-r2-093-75nc6 to kind-worker3
0.3265,Event,ADDED,eval-conflicts-rho000-r2-093-75nc6.18d4640fea9a81b9,"reason=Pulled count=1 msg=Container image ""busybox:musl"" already present on machine"
0.3266,Event,ADDED,eval-conflicts-rho000-r2-093-75nc6.18d4640febb2f843,reason=Created count=1 msg=Created container: task
0.3268,Event,ADDED,eval-conflicts-rho000-r2-093-75nc6.18d4640fed83c1d5,reason=Started count=1 msg=Started container task
0.327,Event,ADDED,eval-conflicts-rho000-r2-093.18d4640fd108425f,reason=SuccessfulCreate count=1 msg=Created pod: eval-conflicts-rho000-r2-093-75nc6
0.3272,Event,ADDED,eval-conflicts-rho000-r2-093.18d4641306ae5b56,reason=Completed count=1 msg=Job completed
0.3273,Event,ADDED,eval-conflicts-rho000-r2-094-lpqrj.18d464100e61a8ba,reason=Scheduled count=None msg=Successfully assigned compute/eval-conflicts-rho000-r2-094-lpqrj to kind-worker3
0.3275,Event,ADDED,eval-conflicts-rho000-r2-094-lpqrj.18d464102735c57e,"reason=Pulled count=1 msg=Container image ""busybox:musl"" already present on machine"
0.3277,Event,ADDED,eval-conflicts-rho000-r2-094-lpqrj.18d46410284e7fdb,reason=Created count=1 msg=Created container: task
0.3278,Event,ADDED,eval-conflicts-rho000-r2-094-lpqrj.18d464102a6ac249,reason=Started count=1 msg=Started container task
0.328,Event,ADDED,eval-conflicts-rho000-r2-094.18d464100d73a211,reason=SuccessfulCreate count=1 msg=Created pod: eval-conflicts-rho000-r2-094-lpqrj
0.3281,Event,ADDED,eval-conflicts-rho000-r2-094.18d46413426ec4a0,reason=Completed count=1 msg=Job completed
0.3283,Event,ADDED,eval-conflicts-rho000-r2-095-mwfbb.18d46410491321cc,reason=Scheduled count=None msg=Successfully assigned compute/eval-conflicts-rho000-r2-095-mwfbb to kind-worker
0.3284,Event,ADDED,eval-conflicts-rho000-r2-095-mwfbb.18d464106205ae02,"reason=Pulled count=1 msg=Container image ""busybox:musl"" already present on machine"
0.3286,Event,ADDED,eval-conflicts-rho000-r2-095-mwfbb.18d464106313788b,reason=Created count=1 msg=Created container: task
0.3288,Event,ADDED,eval-conflicts-rho000-r2-095-mwfbb.18d464106507f1e1,reason=Started count=1 msg=Started container task
0.3289,Event,ADDED,eval-conflicts-rho000-r2-095.18d46410483f88a8,reason=SuccessfulCreate count=1 msg=Created pod: eval-conflicts-rho000-r2-095-mwfbb
0.3291,Event,ADDED,eval-conflicts-rho000-r2-095.18d464139823b4a7,reason=Completed count=1 msg=Job completed
0.3293,Event,ADDED,eval-conflicts-rho000-r2-096-c6zcb.18d46410853c1805,reason=Scheduled count=None msg=Successfully assigned compute/eval-conflicts-rho000-r2-096-c6zcb to kind-worker5
0.3294,Event,ADDED,eval-conflicts-rho000-r2-096-c6zcb.18d464109dedb0eb,"reason=Pulled count=1 msg=Container image ""busybox:musl"" already present on machine"
0.3296,Event,ADDED,eval-conflicts-rho000-r2-096-c6zcb.18d464109f29029e,reason=Created count=1 msg=Created container: task
0.3297,Event,ADDED,eval-conflicts-rho000-r2-096-c6zcb.18d46410a1537bb4,reason=Started count=1 msg=Started container task
0.3299,Event,ADDED,eval-conflicts-rho000-r2-096.18d46410846a22fc,reason=SuccessfulCreate count=1 msg=Created pod: eval-conflicts-rho000-r2-096-c6zcb
0.3301,Event,ADDED,eval-conflicts-rho000-r2-096.18d46413d2f34bc7,reason=Completed count=1 msg=Job completed
0.3302,Event,ADDED,eval-conflicts-rho000-r2-097-pczf7.18d46410c1e4ad00,reason=Scheduled count=None msg=Successfully assigned compute/eval-conflicts-rho000-r2-097-pczf7 to kind-worker5
0.3304,Event,ADDED,eval-conflicts-rho000-r2-097-pczf7.18d46410db4749af,"reason=Pulled count=1 msg=Container image ""busybox:musl"" already present on machine"
0.3305,Event,ADDED,eval-conflicts-rho000-r2-097-pczf7.18d46410dc76d4fa,reason=Created count=1 msg=Created container: task
0.3307,Event,ADDED,eval-conflicts-rho000-r2-097-pczf7.18d46410e0c3de2d,reason=Started count=1 msg=Started container task
0.3309,Event,ADDED,eval-conflicts-rho000-r2-097.18d46410c0a7cfaa,reason=SuccessfulCreate count=1 msg=Created pod: eval-conflicts-rho000-r2-097-pczf7
0.331,Event,ADDED,eval-conflicts-rho000-r2-097.18d464140f24c5b4,reason=Completed count=1 msg=Job completed
0.3312,Event,ADDED,eval-conflicts-rho000-r2-098-xq9rn.18d46410fc71d84f,reason=Scheduled count=None msg=Successfully assigned compute/eval-conflicts-rho000-r2-098-xq9rn to kind-worker5
0.3314,Event,ADDED,eval-conflicts-rho000-r2-098-xq9rn.18d4641114f82f85,"reason=Pulled count=1 msg=Container image ""busybox:musl"" already present on machine"
0.3315,Event,ADDED,eval-conflicts-rho000-r2-098-xq9rn.18d46411160c32c6,reason=Created count=1 msg=Created container: task
0.3317,Event,ADDED,eval-conflicts-rho000-r2-098-xq9rn.18d464111804950b,reason=Started count=1 msg=Started container task
0.3319,Event,ADDED,eval-conflicts-rho000-r2-098.18d46410fb42eb15,reason=SuccessfulCreate count=1 msg=Created pod: eval-conflicts-rho000-r2-098-xq9rn
0.332,Event,ADDED,eval-conflicts-rho000-r2-098.18d464144b1e7358,reason=Completed count=1 msg=Job completed
0.3322,Event,ADDED,eval-conflicts-rho000-r2-099-w2nkv.18d46411376fc738,reason=Scheduled count=None msg=Successfully assigned compute/eval-conflicts-rho000-r2-099-w2nkv to kind-worker5
0.3324,Event,ADDED,eval-conflicts-rho000-r2-099-w2nkv.18d46411506d08b7,"reason=Pulled count=1 msg=Container image ""busybox:musl"" already present on machine"
0.3326,Event,ADDED,eval-conflicts-rho000-r2-099-w2nkv.18d464115193d6c1,reason=Created count=1 msg=Created container: task
0.3327,Event,ADDED,eval-conflicts-rho000-r2-099-w2nkv.18d46411537dec6d,reason=Started count=1 msg=Started container task
0.3329,Event,ADDED,eval-conflicts-rho000-r2-099.18d4641136e75a92,reason=SuccessfulCreate count=1 msg=Created pod: eval-conflicts-rho000-r2-099-w2nkv
0.3331,Event,ADDED,eval-conflicts-rho000-r2-099.18d464148706a61c,reason=Completed count=1 msg=Job completed
0.3332,Event,ADDED,eval-conflicts-rho000-r3-000-vsbc6.18d4641937ed46a7,reason=Scheduled count=None msg=Successfully assigned compute/eval-conflicts-rho000-r3-000-vsbc6 to kind-worker2
0.3334,Event,ADDED,eval-conflicts-rho000-r3-000-vsbc6.18d4641951b2e3a8,"reason=Pulled count=1 msg=Container image ""busybox:musl"" already present on machine"
0.3336,Event,ADDED,eval-conflicts-rho000-r3-000-vsbc6.18d4641952d24cbe,reason=Created count=1 msg=Created container: task
0.3338,Event,ADDED,eval-conflicts-rho000-r3-000-vsbc6.18d4641954f3ed94,reason=Started count=1 msg=Started container task
0.334,Event,ADDED,eval-conflicts-rho000-r3-000.18d464193707dd72,reason=SuccessfulCreate count=1 msg=Created pod: eval-conflicts-rho000-r3-000-vsbc6
0.3342,Event,ADDED,eval-conflicts-rho000-r3-000.18d4641c9c39d198,reason=Completed count=1 msg=Job completed
0.3344,Event,ADDED,eval-conflicts-rho000-r3-001-n4sv7.18d464197305c8b9,reason=Scheduled count=None msg=Successfully assigned compute/eval-conflicts-rho000-r3-001-n4sv7 to kind-worker
0.3346,Event,ADDED,eval-conflicts-rho000-r3-001-n4sv7.18d464198afa31df,"reason=Pulled count=1 msg=Container image ""busybox:musl"" already present on machine"
0.3348,Event,ADDED,eval-conflicts-rho000-r3-001-n4sv7.18d464198c1c2e4c,reason=Created count=1 msg=Created container: task
0.335,Event,ADDED,eval-conflicts-rho000-r3-001-n4sv7.18d464198e28e7a3,reason=Started count=1 msg=Started container task
0.3351,Event,ADDED,eval-conflicts-rho000-r3-001.18d4641971e4a6ae,reason=SuccessfulCreate count=1 msg=Created pod: eval-conflicts-rho000-r3-001-n4sv7
0.3353,Event,ADDED,eval-conflicts-rho000-r3-001.18d4641cb40549e6,reason=Completed count=1 msg=Job completed
0.3354,Event,ADDED,eval-conflicts-rho000-r3-002-vn95z.18d46419afb10984,reason=Scheduled count=None msg=Successfully assigned compute/eval-conflicts-rho000-r3-002-vn95z to kind-worker5
0.3356,Event,ADDED,eval-conflicts-rho000-r3-002-vn95z.18d46419ca76da04,"reason=Pulled count=1 msg=Container image ""busybox:musl"" already present on machine"
0.3358,Event,ADDED,eval-conflicts-rho000-r3-002-vn95z.18d46419cbbe82a0,reason=Created count=1 msg=Created container: task
0.336,Event,ADDED,eval-conflicts-rho000-r3-002-vn95z.18d46419cdc539c6,reason=Started count=1 msg=Started container task
0.3361,Event,ADDED,eval-conflicts-rho000-r3-002.18d46419adee6fde,reason=SuccessfulCreate count=1 msg=Created pod: eval-conflicts-rho000-r3-002-vn95z
0.3363,Event,ADDED,eval-conflicts-rho000-r3-002.18d4641cefadf144,reason=Completed count=1 msg=Job completed
0.3364,Event,ADDED,eval-conflicts-rho000-r3-003-ntnrn.18d46419e99b913a,reason=Scheduled count=None msg=Successfully assigned compute/eval-conflicts-rho000-r3-003-ntnrn to kind-worker
0.3366,Event,ADDED,eval-conflicts-rho000-r3-003-ntnrn.18d4641a02c5807e,"reason=Pulled count=1 msg=Container image ""busybox:musl"" already present on machine"
0.3368,Event,ADDED,eval-conflicts-rho000-r3-003-ntnrn.18d4641a03f255f0,reason=Created count=1 msg=Created container: task
0.3369,Event,ADDED,eval-conflicts-rho000-r3-003-ntnrn.18d4641a05fbc472,reason=Started count=1 msg=Started container task
0.3371,Event,ADDED,eval-conflicts-rho000-r3-003.18d46419e8a1c361,reason=SuccessfulCreate count=1 msg=Created pod: eval-conflicts-rho000-r3-003-ntnrn
0.3373,Event,ADDED,eval-conflicts-rho000-r3-003.18d4641cf09d5043,reason=Completed count=1 msg=Job completed
0.3374,Event,ADDED,eval-conflicts-rho000-r3-004-mkg6r.18d4641a262ad2de,reason=Scheduled count=None msg=Successfully assigned compute/eval-conflicts-rho000-r3-004-mkg6r to kind-worker2
0.3376,Event,ADDED,eval-conflicts-rho000-r3-004-mkg6r.18d4641a3efc1ea4,"reason=Pulled count=1 msg=Container image ""busybox:musl"" already present on machine"
0.3378,Event,ADDED,eval-conflicts-rho000-r3-004-mkg6r.18d4641a400db5a9,reason=Created count=1 msg=Created container: task
0.3379,Event,ADDED,eval-conflicts-rho000-r3-004-mkg6r.18d4641a450f4c16,reason=Started count=1 msg=Started container task
0.3381,Event,ADDED,eval-conflicts-rho000-r3-004.18d4641a25445055,reason=SuccessfulCreate count=1 msg=Created pod: eval-conflicts-rho000-r3-004-mkg6r
0.3382,Event,ADDED,eval-conflicts-rho000-r3-004.18d4641d8ae62c94,reason=Completed count=1 msg=Job completed
0.3384,Event,ADDED,eval-conflicts-rho000-r3-005-9v8ng.18d4641a61248466,reason=Scheduled count=None msg=Successfully assigned compute/eval-conflicts-rho000-r3-005-9v8ng to kind-worker
0.3386,Event,ADDED,eval-conflicts-rho000-r3-005-9v8ng.18d4641a7af9dbd3,"reason=Pulled count=1 msg=Container image ""busybox:musl"" already present on machine"
0.3387,Event,ADDED,eval-conflicts-rho000-r3-005-9v8ng.18d4641a7c25c621,reason=Created count=1 msg=Created container: task
0.3389,Event,ADDED,eval-conflicts-rho000-r3-005-9v8ng.18d4641a7e5a7245,reason=Started count=1 msg=Started container task
0.3391,Event,ADDED,eval-conflicts-rho000-r3-005.18d4641a60343e6a,reason=SuccessfulCreate count=1 msg=Created pod: eval-conflicts-rho000-r3-005-9v8ng
0.3392,Event,ADDED,eval-conflicts-rho000-r3-005.18d4641d667f00a6,reason=Completed count=1 msg=Job completed
0.3394,Event,ADDED,eval-conflicts-rho000-r3-006-pgj47.18d4641a9c7019cb,reason=Scheduled count=None msg=Successfully assigned compute/eval-conflicts-rho000-r3-006-pgj47 to kind-worker4
0.3395,Event,ADDED,eval-conflicts-rho000-r3-006-pgj47.18d4641ab55aab38,"reason=Pulled count=1 msg=Container image ""busybox:musl"" already present on machine"
0.3397,Event,ADDED,eval-conflicts-rho000-r3-006-pgj47.18d4641ab6739da8,reason=Created count=1 msg=Created container: task
0.3399,Event,ADDED,eval-conflicts-rho000-r3-006-pgj47.18d4641ab8769272,reason=Started count=1 msg=Started container task
0.3401,Event,ADDED,eval-conflicts-rho000-r3-006.18d4641a9bb808e5,reason=SuccessfulCreate count=1 msg=Created pod: eval-conflicts-rho000-r3-006-pgj47
0.3403,Event,ADDED,eval-conflicts-rho000-r3-006.18d4641dc6bfd1f5,reason=Completed count=1 msg=Job completed
0.3404,Event,ADDED,eval-conflicts-rho000-r3-007-rvkxn.18d4641ad81a4ae1,reason=Scheduled count=None msg=Successfully assigned compute/eval-conflicts-rho000-r3-007-rvkxn to kind-worker2
0.3406,Event,ADDED,eval-conflicts-rho000-r3-007-rvkxn.18d4641af13111af,"reason=Pulled count=1 msg=Container image ""busybox:musl"" already present on machine"
0.3408,Event,ADDED,eval-conflicts-rho000-r3-007-rvkxn.18d4641af2558dd6,reason=Created count=1 msg=Created container: task
0.3409,Event,ADDED,eval-conflicts-rho000-r3-007-rvkxn.18d4641af4921610,reason=Started count=1 msg=Started container task
0.3411,Event,ADDED,eval-conflicts-rho000-r3-007.18d4641ad730a42f,reason=SuccessfulCreate count=1 msg=Created pod: eval-conflicts-rho000-r3-007-rvkxn
0.3412,Event,ADDED,eval-conflicts-rho000-r3-007.18d4641e02f8beaa,reason=Completed count=1 msg=Job completed
0.3414,Event,ADDED,eval-conflicts-rho000-r3-008-pj8gx.18d4641b14feeb08,reason=Scheduled count=None msg=Successfully assigned compute/eval-conflicts-rho000-r3-008-pj8gx to kind-worker4
0.3416,Event,ADDED,eval-conflicts-rho000-r3-008-pj8gx.18d4641b2e5767ff,"reason=Pulled count=1 msg=Container image ""busybox:musl"" already present on machine"
0.3417,Event,ADDED,eval-conflicts-rho000-r3-008-pj8gx.18d4641b2f8458f0,reason=Created count=1 msg=Created container: task
0.3419,Event,ADDED,eval-conflicts-rho000-r3-008-pj8gx.18d4641b31b231cc,reason=Started count=1 msg=Started container task
0.3421,Event,ADDED,eval-conflicts-rho000-r3-008.18d4641b1426c182,reason=SuccessfulCreate count=1 msg=Created pod: eval-conflicts-rho000-r3-008-pj8gx
0.3422,Event,ADDED,eval-conflicts-rho000-r3-008.18d4641e3e8bfcb2,reason=Completed count=1 msg=Job completed
0.3424,Event,ADDED,eval-conflicts-rho000-r3-009-nmpbk.18d4641b4f408d86,reason=Scheduled count=None msg=Successfully assigned compute/eval-conflicts-rho000-r3-009-nmpbk to kind-worker3
0.3426,Event,ADDED,eval-conflicts-rho000-r3-009-nmpbk.18d4641b68457555,"reason=Pulled count=1 msg=Container image ""busybox:musl"" already present on machine"
0.3427,Event,ADDED,eval-conflicts-rho000-r3-009-nmpbk.18d4641b697c754a,reason=Created count=1 msg=Created container: task
0.3429,Event,ADDED,eval-conflicts-rho000-r3-009-nmpbk.18d4641b6e45a9f7,reason=Started count=1 msg=Started container task
0.343,Event,ADDED,eval-conflicts-rho000-r3-009.18d4641b4ed18355,reason=SuccessfulCreate count=1 msg=Created pod: eval-conflicts-rho000-r3-009-nmpbk
0.3433,Event,ADDED,eval-conflicts-rho000-r3-009.18d4641eb1cc0a7c,reason=Completed count=1 msg=Job completed
0.3435,Event,ADDED,eval-conflicts-rho000-r3-010-s4s47.18d4641b8b035d9c,reason=Scheduled count=None msg=Successfully assigned compute/eval-conflicts-rho000-r3-010-s4s47 to kind-worker3
0.3437,Event,ADDED,eval-conflicts-rho000-r3-010-s4s47.18d4641ba4958c39,"reason=Pulled count=1 msg=Container image ""busybox:musl"" already present on machine"
0.3438,Event,ADDED,eval-conflicts-rho000-r3-010-s4s47.18d4641ba5aff60e,reason=Created count=1 msg=Created container: task
0.344,Event,ADDED,eval-conflicts-rho000-r3-010-s4s47.18d4641baa5ca5e0,reason=Started count=1 msg=Started container task
0.3442,Event,ADDED,eval-conflicts-rho000-r3-010.18d4641b8a725462,reason=SuccessfulCreate count=1 msg=Created pod: eval-conflicts-rho000-r3-010-s4s47
0.3443,Event,ADDED,eval-conflicts-rho000-r3-010.18d4641eed4a9e67,reason=Completed count=1 msg=Job completed
0.3445,Event,ADDED,eval-conflicts-rho000-r3-011-5nw29.18d4641bc61afd77,reason=Scheduled count=None msg=Successfully assigned compute/eval-conflicts-rho000-r3-011-5nw29 to kind-worker3
0.3446,Event,ADDED,eval-conflicts-rho000-r3-011-5nw29.18d4641bdf86b19c,"reason=Pulled count=1 msg=Container image ""busybox:musl"" already present on machine"
0.3448,Event,ADDED,eval-conflicts-rho000-r3-011-5nw29.18d4641be0b25374,reason=Created count=1 msg=Created container: task
0.345,Event,ADDED,eval-conflicts-rho000-r3-011-5nw29.18d4641be3808ae5,reason=Started count=1 msg=Started container task
0.3451,Event,ADDED,eval-conflicts-rho000-r3-011.18d4641bc5854370,reason=SuccessfulCreate count=1 msg=Created pod: eval-conflicts-rho000-r3-011-5nw29
0.3453,Event,ADDED,eval-conflicts-rho000-r3-011.18d4641f296a3f07,reason=Completed count=1 msg=Job completed
0.3454,Event,ADDED,eval-conflicts-rho000-r3-012-xcnxt.18d4641c01fb099c,reason=Scheduled count=None msg=Successfully assigned compute/eval-conflicts-rho000-r3-012-xcnxt to kind-worker3
0.3456,Event,ADDED,eval-conflicts-rho000-r3-012-xcnxt.18d4641c1b4e6444,"reason=Pulled count=1 msg=Container image ""busybox:musl"" already present on machine"
0.3458,Event,ADDED,eval-conflicts-rho000-r3-012-xcnxt.18d4641c1c70e3b3,reason=Created count=1 msg=Created container: task
0.3459,Event,ADDED,eval-conflicts-rho000-r3-012-xcnxt.18d4641c21958474,reason=Started count=1 msg=Started container task
0.3461,Event,ADDED,eval-conflicts-rho000-r3-012.18d4641c014429b4,reason=SuccessfulCreate count=1 msg=Created pod: eval-conflicts-rho000-r3-012-xcnxt
0.3463,Event,ADDED,eval-conflicts-rho000-r3-012.18d4641f6552bddc,reason=Completed count=1 msg=Job completed
0.3464,Event,ADDED,eval-conflicts-rho000-r3-013-qtxgb.18d4641c3e3ecf77,reason=Scheduled count=None msg=Successfully assigned compute/eval-conflicts-rho000-r3-013-qtxgb to kind-worker3
0.3466,Event,ADDED,eval-conflicts-rho000-r3-013-qtxgb.18d4641c5862cddb,"reason=Pulled count=1 msg=Container image ""busybox:musl"" already present on machine"
0.3468,Event,ADDED,eval-conflicts-rho000-r3-013-qtxgb.18d4641c5994660c,reason=Created count=1 msg=Created container: task
0.3469,Event,ADDED,eval-conflicts-rho000-r3-013-qtxgb.18d4641c5e68820a,reason=Started count=1 msg=Started container task
0.3471,Event,ADDED,eval-conflicts-rho000-r3-013.18d4641c3d25d6a6,reason=SuccessfulCreate count=1 msg=Created pod: eval-conflicts-rho000-r3-013-qtxgb
0.3472,Event,ADDED,eval-conflicts-rho000-r3-013.18d4641fa16f5448,reason=Completed count=1 msg=Job completed
0.3474,Event,ADDED,eval-conflicts-rho000-r3-014-rh9m6.18d4641c795c7b60,reason=Scheduled count=None msg=Successfully assigned compute/eval-conflicts-rho000-r3-014-rh9m6 to kind-worker3
0.3476,Event,ADDED,eval-conflicts-rho000-r3-014-rh9m6.18d4641c9380979d,"reason=Pulled count=1 msg=Container image ""busybox:musl"" already present on machine"
0.3478,Event,ADDED,eval-conflicts-rho000-r3-014-rh9m6.18d4641c94a7a185,reason=Created count=1 msg=Created container: task
0.348,Event,ADDED,eval-conflicts-rho000-r3-014-rh9m6.18d4641c96bc937c,reason=Started count=1 msg=Started container task
0.3481,Event,ADDED,eval-conflicts-rho000-r3-014.18d4641c78ba0587,reason=SuccessfulCreate count=1 msg=Created pod: eval-conflicts-rho000-r3-014-rh9m6
0.3483,Event,ADDED,eval-conflicts-rho000-r3-014.18d4641fdcd2f038,reason=Completed count=1 msg=Job completed
0.3484,Event,ADDED,eval-conflicts-rho000-r3-015-tppbj.18d4641cb5c607d3,reason=Scheduled count=None msg=Successfully assigned compute/eval-conflicts-rho000-r3-015-tppbj to kind-worker3
0.3486,Event,ADDED,eval-conflicts-rho000-r3-015-tppbj.18d4641ccf94722f,"reason=Pulled count=1 msg=Container image ""busybox:musl"" already present on machine"
0.3488,Event,ADDED,eval-conflicts-rho000-r3-015-tppbj.18d4641cd0ee4768,reason=Created count=1 msg=Created container: task
0.3489,Event,ADDED,eval-conflicts-rho000-r3-015-tppbj.18d4641cd3502405,reason=Started count=1 msg=Started container task
0.3491,Event,ADDED,eval-conflicts-rho000-r3-015.18d4641cb537293f,reason=SuccessfulCreate count=1 msg=Created pod: eval-conflicts-rho000-r3-015-tppbj
0.3493,Event,ADDED,eval-conflicts-rho000-r3-015.18d4642018b9dc9e,reason=Completed count=1 msg=Job completed
0.3494,Event,ADDED,eval-conflicts-rho000-r3-016-f8s62.18d4641cf06d8146,"reason=FailedScheduling count=None msg=0/6 nodes are available: 6 node(s) had untolerated taint(s). no new claims to deallocate, preemption: 0/6 nodes are available: 6 Preemption is not helpful for scheduling."
0.3496,Event,ADDED,eval-conflicts-rho000-r3-016-f8s62.18d4641e825110a8,reason=Scheduled count=None msg=Successfully assigned compute/eval-conflicts-rho000-r3-016-f8s62 to kind-worker5
0.3497,Event,ADDED,eval-conflicts-rho000-r3-016-f8s62.18d4641e9e2290c1,"reason=Pulled count=1 msg=Container image ""busybox:musl"" already present on machine"
0.3499,Event,ADDED,eval-conflicts-rho000-r3-016-f8s62.18d4641e9f94c523,reason=Created count=1 msg=Created container: task
0.3501,Event,ADDED,eval-conflicts-rho000-r3-016-f8s62.18d4641ea1abaf74,reason=Started count=1 msg=Started container task
0.3502,Event,ADDED,eval-conflicts-rho000-r3-016.18d4641cf0694db9,reason=SuccessfulCreate count=1 msg=Created pod: eval-conflicts-rho000-r3-016-f8s62
0.3504,Event,ADDED,eval-conflicts-rho000-r3-016.18d46421d88a9f5c,reason=Completed count=1 msg=Job completed
0.3505,Event,ADDED,eval-conflicts-rho000-r3-017-s24b9.18d4641d2bb10395,"reason=FailedScheduling count=None msg=0/6 nodes are available: 6 node(s) had untolerated taint(s). no new claims to deallocate, preemption: 0/6 nodes are available: 6 Preemption is not helpful for scheduling."
0.3507,Event,ADDED,eval-conflicts-rho000-r3-017-s24b9.18d4641e82e70695,reason=Scheduled count=None msg=Successfully assigned compute/eval-conflicts-rho000-r3-017-s24b9 to kind-worker5
0.3508,Event,ADDED,eval-conflicts-rho000-r3-017-s24b9.18d4641ea495f6ea,"reason=Pulled count=1 msg=Container image ""busybox:musl"" already present on machine"
0.351,Event,ADDED,eval-conflicts-rho000-r3-017-s24b9.18d4641ea7788d3d,reason=Created count=1 msg=Created container: task
0.3512,Event,ADDED,eval-conflicts-rho000-r3-017-s24b9.18d4641ea9fab9a2,reason=Started count=1 msg=Started container task
0.3513,Event,ADDED,eval-conflicts-rho000-r3-017.18d4641d2ba7a1d4,reason=SuccessfulCreate count=1 msg=Created pod: eval-conflicts-rho000-r3-017-s24b9
0.3516,Event,ADDED,eval-conflicts-rho000-r3-017.18d464219bbcaf2e,reason=Completed count=1 msg=Job completed
0.3517,Event,ADDED,eval-conflicts-rho000-r3-018-r7lqt.18d4641d671be3dc,"reason=FailedScheduling count=None msg=0/6 nodes are available: 6 node(s) had untolerated taint(s). no new claims to deallocate, preemption: 0/6 nodes are available: 6 Preemption is not helpful for scheduling."
0.3519,Event,ADDED,eval-conflicts-rho000-r3-018-r7lqt.18d4641e834ebb1d,reason=Scheduled count=None msg=Successfully assigned compute/eval-conflicts-rho000-r3-018-r7lqt to kind-worker5
0.352,Event,ADDED,eval-conflicts-rho000-r3-018-r7lqt.18d4641ea45de181,"reason=Pulled count=1 msg=Container image ""busybox:musl"" already present on machine"
0.3522,Event,ADDED,eval-conflicts-rho000-r3-018-r7lqt.18d4641ea5f34ecc,reason=Created count=1 msg=Created container: task
0.3524,Event,ADDED,eval-conflicts-rho000-r3-018-r7lqt.18d4641ea870b956,reason=Started count=1 msg=Started container task
0.3525,Event,ADDED,eval-conflicts-rho000-r3-018.18d4641d670e92bd,reason=SuccessfulCreate count=1 msg=Created pod: eval-conflicts-rho000-r3-018-r7lqt
0.353,Event,ADDED,eval-conflicts-rho000-r3-018.18d46421d64bfb6d,reason=Completed count=1 msg=Job completed
0.3532,Event,ADDED,eval-conflicts-rho000-r3-019-p9ccc.18d4641da2d544e6,"reason=FailedScheduling count=None msg=0/6 nodes are available: 6 node(s) had untolerated taint(s). no new claims to deallocate, preemption: 0/6 nodes are available: 6 Preemption is not helpful for scheduling."
0.3533,Event,ADDED,eval-conflicts-rho000-r3-019-p9ccc.18d4641e83731ae6,reason=Scheduled count=None msg=Successfully assigned compute/eval-conflicts-rho000-r3-019-p9ccc to kind-worker5
0.3535,Event,ADDED,eval-conflicts-rho000-r3-019-p9ccc.18d4641ea473b1f3,"reason=Pulled count=1 msg=Container image ""busybox:musl"" already present on machine"
0.3538,Event,ADDED,eval-conflicts-rho000-r3-019-p9ccc.18d4641ea69b1e5a,reason=Created count=1 msg=Created container: task
0.354,Event,ADDED,eval-conflicts-rho000-r3-019-p9ccc.18d4641ea9322f97,reason=Started count=1 msg=Started container task
0.3542,Event,ADDED,eval-conflicts-rho000-r3-019.18d4641da2c94267,reason=SuccessfulCreate count=1 msg=Created pod: eval-conflicts-rho000-r3-019-p9ccc
0.3544,Event,ADDED,eval-conflicts-rho000-r3-019.18d464219c4b617f,reason=Completed count=1 msg=Job completed
0.3546,Event,ADDED,eval-conflicts-rho000-r3-020-6tz59.18d4641dddc95fb5,"reason=FailedScheduling count=None msg=0/6 nodes are available: 6 node(s) had untolerated taint(s). no new claims to deallocate, preemption: 0/6 nodes are available: 6 Preemption is not helpful for scheduling."
0.3547,Event,ADDED,eval-conflicts-rho000-r3-020-6tz59.18d4641e83b17515,reason=Scheduled count=None msg=Successfully assigned compute/eval-conflicts-rho000-r3-020-6tz59 to kind-worker5
0.3549,Event,ADDED,eval-conflicts-rho000-r3-020-6tz59.18d4641ea6a8e408,"reason=Pulled count=1 msg=Container image ""busybox:musl"" already present on machine"
0.3551,Event,ADDED,eval-conflicts-rho000-r3-020-6tz59.18d4641ea9322fa0,reason=Created count=1 msg=Created container: task
0.3552,Event,ADDED,eval-conflicts-rho000-r3-020-6tz59.18d4641eabbb4eef,reason=Started count=1 msg=Started container task
0.3554,Event,ADDED,eval-conflicts-rho000-r3-020.18d4641dddb9aea7,reason=SuccessfulCreate count=1 msg=Created pod: eval-conflicts-rho000-r3-020-6tz59
0.3556,Event,ADDED,eval-conflicts-rho000-r3-020.18d46421a3f318e3,reason=Completed count=1 msg=Job completed
0.3557,Event,ADDED,eval-conflicts-rho000-r3-021-bphhn.18d4641e1a8adb7c,"reason=FailedScheduling count=None msg=0/6 nodes are available: 6 node(s) had untolerated taint(s). no new claims to deallocate, preemption: 0/6 nodes are available: 6 Preemption is not helpful for scheduling."
0.3559,Event,ADDED,eval-conflicts-rho000-r3-021-bphhn.18d4641e856517f4,reason=Scheduled count=None msg=Successfully assigned compute/eval-conflicts-rho000-r3-021-bphhn to kind-worker5
0.3561,Event,ADDED,eval-conflicts-rho000-r3-021-bphhn.18d4641ea6c15edb,"reason=Pulled count=1 msg=Container image ""busybox:musl"" already present on machine"
0.3562,Event,ADDED,eval-conflicts-rho000-r3-021-bphhn.18d4641ea97430d1,reason=Created count=1 msg=Created container: task
0.3564,Event,ADDED,eval-conflicts-rho000-r3-021-bphhn.18d4641eabb8d70f,reason=Started count=1 msg=Started container task
0.3566,Event,ADDED,eval-conflicts-rho000-r3-021.18d4641e1a7d23a2,reason=SuccessfulCreate count=1 msg=Created pod: eval-conflicts-rho000-r3-021-bphhn
0.3567,Event,ADDED,eval-conflicts-rho000-r3-021.18d464219c6be944,reason=Completed count=1 msg=Job completed
0.3569,Event,ADDED,eval-conflicts-rho000-r3-022-76pbs.18d4641e552bd10f,"reason=FailedScheduling count=None msg=0/6 nodes are available: 6 node(s) had untolerated taint(s). no new claims to deallocate, preemption: 0/6 nodes are available: 6 Preemption is not helpful for scheduling."
0.3571,Event,ADDED,eval-conflicts-rho000-r3-022-76pbs.18d4641e8568b8ff,reason=Scheduled count=None msg=Successfully assigned compute/eval-conflicts-rho000-r3-022-76pbs to kind-worker5
0.3573,Event,ADDED,eval-conflicts-rho000-r3-022-76pbs.18d4641ea25988c2,"reason=Pulled count=1 msg=Container image ""busybox:musl"" already present on machine"
0.3575,Event,ADDED,eval-conflicts-rho000-r3-022-76pbs.18d4641ea371e01b,reason=Created count=1 msg=Created container: task
0.3578,Event,ADDED,eval-conflicts-rho000-r3-022-76pbs.18d4641ea7551f81,reason=Started count=1 msg=Started container task
0.3579,Event,ADDED,eval-conflicts-rho000-r3-022.18d4641e55205a82,reason=SuccessfulCreate count=1 msg=Created pod: eval-conflicts-rho000-r3-022-76pbs
0.3581,Event,ADDED,eval-conflicts-rho000-r3-022.18d464219cc1c753,reason=Completed count=1 msg=Job completed
0.3584,Event,ADDED,eval-conflicts-rho000-r3-023-n6xf8.18d4641e912dc218,reason=Scheduled count=None msg=Successfully assigned compute/eval-conflicts-rho000-r3-023-n6xf8 to kind-worker5
0.3586,Event,ADDED,eval-conflicts-rho000-r3-023-n6xf8.18d4641eab38bcc0,"reason=Pulled count=1 msg=Container image ""busybox:musl"" already present on machine"
0.3589,Event,ADDED,eval-conflicts-rho000-r3-023-n6xf8.18d4641eac6c23e6,reason=Created count=1 msg=Created container: task
0.359,Event,ADDED,eval-conflicts-rho000-r3-023-n6xf8.18d4641eb156262a,reason=Started count=1 msg=Started container task
0.3593,Event,ADDED,eval-conflicts-rho000-r3-023.18d4641e908a9451,reason=SuccessfulCreate count=1 msg=Created pod: eval-conflicts-rho000-r3-023-n6xf8
0.3594,Event,ADDED,eval-conflicts-rho000-r3-023.18d464219da76b25,reason=Completed count=1 msg=Job completed
0.3596,Event,ADDED,eval-conflicts-rho000-r3-024-lqhm4.18d4641ecd1c117f,reason=Scheduled count=None msg=Successfully assigned compute/eval-conflicts-rho000-r3-024-lqhm4 to kind-worker5
0.3598,Event,ADDED,eval-conflicts-rho000-r3-024-lqhm4.18d4641ee70eaf20,"reason=Pulled count=1 msg=Container image ""busybox:musl"" already present on machine"
0.3599,Event,ADDED,eval-conflicts-rho000-r3-024-lqhm4.18d4641ee82acfdf,reason=Created count=1 msg=Created container: task
0.3601,Event,ADDED,eval-conflicts-rho000-r3-024-lqhm4.18d4641eea2642e6,reason=Started count=1 msg=Started container task
0.3603,Event,ADDED,eval-conflicts-rho000-r3-024.18d4641ecc90f8b4,reason=SuccessfulCreate count=1 msg=Created pod: eval-conflicts-rho000-r3-024-lqhm4
0.3604,Event,ADDED,eval-conflicts-rho000-r3-024.18d46421d7d070c3,reason=Completed count=1 msg=Job completed
0.3606,Event,ADDED,eval-conflicts-rho000-r3-025-2t9wn.18d4641f0890ac80,reason=Scheduled count=None msg=Successfully assigned compute/eval-conflicts-rho000-r3-025-2t9wn to kind-worker5
0.3608,Event,ADDED,eval-conflicts-rho000-r3-025-2t9wn.18d4641f21e7866b,"reason=Pulled count=1 msg=Container image ""busybox:musl"" already present on machine"
0.3609,Event,ADDED,eval-conflicts-rho000-r3-025-2t9wn.18d4641f23002157,reason=Created count=1 msg=Created container: task
0.3611,Event,ADDED,eval-conflicts-rho000-r3-025-2t9wn.18d4641f26741f62,reason=Started count=1 msg=Started container task
0.3613,Event,ADDED,eval-conflicts-rho000-r3-025.18d4641f07e3bd23,reason=SuccessfulCreate count=1 msg=Created pod: eval-conflicts-rho000-r3-025-2t9wn
0.3614,Event,ADDED,eval-conflicts-rho000-r3-025.18d464224e7f232f,reason=Completed count=1 msg=Job completed
0.3616,Event,ADDED,eval-conflicts-rho000-r3-026-kczdr.18d4641f44b2f82c,reason=Scheduled count=None msg=Successfully assigned compute/eval-conflicts-rho000-r3-026-kczdr to kind-worker5
0.3617,Event,ADDED,eval-conflicts-rho000-r3-026-kczdr.18d4641f5cc91667,"reason=Pulled count=1 msg=Container image ""busybox:musl"" already present on machine"
0.3619,Event,ADDED,eval-conflicts-rho000-r3-026-kczdr.18d4641f5ddcf359,reason=Created count=1 msg=Created container: task
0.3621,Event,ADDED,eval-conflicts-rho000-r3-026-kczdr.18d4641f62d6e3b3,reason=Started count=1 msg=Started container task
0.3622,Event,ADDED,eval-conflicts-rho000-r3-026.18d4641f43f3dc30,reason=SuccessfulCreate count=1 msg=Created pod: eval-conflicts-rho000-r3-026-kczdr
0.3624,Event,ADDED,eval-conflicts-rho000-r3-026.18d464224fcc39e6,reason=Completed count=1 msg=Job completed
0.3626,Event,ADDED,eval-conflicts-rho000-r3-027-9fxnd.18d4641f813064a4,reason=Scheduled count=None msg=Successfully assigned compute/eval-conflicts-rho000-r3-027-9fxnd to kind-worker
0.3627,Event,ADDED,eval-conflicts-rho000-r3-027-9fxnd.18d4641f9a2490fa,"reason=Pulled count=1 msg=Container image ""busybox:musl"" already present on machine"
0.3629,Event,ADDED,eval-conflicts-rho000-r3-027-9fxnd.18d4641f9b3f6032,reason=Created count=1 msg=Created container: task
0.3631,Event,ADDED,eval-conflicts-rho000-r3-027-9fxnd.18d4641f9d7afc37,reason=Started count=1 msg=Started container task
0.3632,Event,ADDED,eval-conflicts-rho000-r3-027.18d4641f801b4a9a,reason=SuccessfulCreate count=1 msg=Created pod: eval-conflicts-rho000-r3-027-9fxnd
0.3635,Event,ADDED,eval-conflicts-rho000-r3-027.18d46422c461dd4b,reason=Completed count=1 msg=Job completed
0.3636,Event,ADDED,eval-conflicts-rho000-r3-028-dvqkh.18d4641fbbeafe9b,reason=Scheduled count=None msg=Successfully assigned compute/eval-conflicts-rho000-r3-028-dvqkh to kind-worker
0.3638,Event,ADDED,eval-conflicts-rho000-r3-028-dvqkh.18d4641fd4b58aeb,"reason=Pulled count=1 msg=Container image ""busybox:musl"" already present on machine"
0.364,Event,ADDED,eval-conflicts-rho000-r3-028-dvqkh.18d4641fd67230f2,reason=Created count=1 msg=Created container: task
0.3641,Event,ADDED,eval-conflicts-rho000-r3-028-dvqkh.18d4641fd8d5add4,reason=Started count=1 msg=Started container task
0.3643,Event,ADDED,eval-conflicts-rho000-r3-028.18d4641fbaf4e47a,reason=SuccessfulCreate count=1 msg=Created pod: eval-conflicts-rho000-r3-028-dvqkh
0.3645,Event,ADDED,eval-conflicts-rho000-r3-028.18d46422ffea82c1,reason=Completed count=1 msg=Job completed
0.3646,Event,ADDED,eval-conflicts-rho000-r3-029-bz95c.18d4641ff6cb9434,reason=Scheduled count=None msg=Successfully assigned compute/eval-conflicts-rho000-r3-029-bz95c to kind-worker2
0.3648,Event,ADDED,eval-conflicts-rho000-r3-029-bz95c.18d46420103c05cf,"reason=Pulled count=1 msg=Container image ""busybox:musl"" already present on machine"
0.3649,Event,ADDED,eval-conflicts-rho000-r3-029-bz95c.18d464201146e3c0,reason=Created count=1 msg=Created container: task
0.3651,Event,ADDED,eval-conflicts-rho000-r3-029-bz95c.18d464201337270e,reason=Started count=1 msg=Started container task
0.3653,Event,ADDED,eval-conflicts-rho000-r3-029.18d4641ff5ed5b35,reason=SuccessfulCreate count=1 msg=Created pod: eval-conflicts-rho000-r3-029-bz95c
0.3654,Event,ADDED,eval-conflicts-rho000-r3-029.18d46423257b755a,reason=Completed count=1 msg=Job completed
0.3656,Event,ADDED,eval-conflicts-rho000-r3-030-wpqdh.18d4642033340c4c,reason=Scheduled count=None msg=Successfully assigned compute/eval-conflicts-rho000-r3-030-wpqdh to kind-worker2
0.3657,Event,ADDED,eval-conflicts-rho000-r3-030-wpqdh.18d464204c8ea91d,"reason=Pulled count=1 msg=Container image ""busybox:musl"" already present on machine"
0.3659,Event,ADDED,eval-conflicts-rho000-r3-030-wpqdh.18d464204da7f5b5,reason=Created count=1 msg=Created container: task
0.3661,Event,ADDED,eval-conflicts-rho000-r3-030-wpqdh.18d464204faa68a0,reason=Started count=1 msg=Started container task
0.3663,Event,ADDED,eval-conflicts-rho000-r3-030.18d4642031f8add6,reason=SuccessfulCreate count=1 msg=Created pod: eval-conflicts-rho000-r3-030-wpqdh
0.3665,Event,ADDED,eval-conflicts-rho000-r3-030.18d464236121febc,reason=Completed count=1 msg=Job completed
0.3666,Event,ADDED,eval-conflicts-rho000-r3-031-8kt9w.18d464206f50b777,reason=Scheduled count=None msg=Successfully assigned compute/eval-conflicts-rho000-r3-031-8kt9w to kind-worker2
0.3668,Event,ADDED,eval-conflicts-rho000-r3-031-8kt9w.18d4642088478ee5,"reason=Pulled count=1 msg=Container image ""busybox:musl"" already present on machine"
0.3669,Event,ADDED,eval-conflicts-rho000-r3-031-8kt9w.18d4642089657183,reason=Created count=1 msg=Created container: task
0.3671,Event,ADDED,eval-conflicts-rho000-r3-031-8kt9w.18d464208e1af02e,reason=Started count=1 msg=Started container task
0.3673,Event,ADDED,eval-conflicts-rho000-r3-031.18d464206e30426a,reason=SuccessfulCreate count=1 msg=Created pod: eval-conflicts-rho000-r3-031-8kt9w
0.3674,Event,ADDED,eval-conflicts-rho000-r3-031.18d464239ce80646,reason=Completed count=1 msg=Job completed
0.3676,Event,ADDED,eval-conflicts-rho000-r3-032-vvvld.18d46420aa58fd9d,reason=Scheduled count=None msg=Successfully assigned compute/eval-conflicts-rho000-r3-032-vvvld to kind-worker
0.3677,Event,ADDED,eval-conflicts-rho000-r3-032-vvvld.18d46420c2d4f7ac,"reason=Pulled count=1 msg=Container image ""busybox:musl"" already present on machine"
0.3679,Event,ADDED,eval-conflicts-rho000-r3-032-vvvld.18d46420c3e87041,reason=Created count=1 msg=Created container: task
0.3681,Event,ADDED,eval-conflicts-rho000-r3-032-vvvld.18d46420c7c31d05,reason=Started count=1 msg=Started container task
0.3682,Event,ADDED,eval-conflicts-rho000-r3-032.18d46420a92f0b3c,reason=SuccessfulCreate count=1 msg=Created pod: eval-conflicts-rho000-r3-032-vvvld
0.3684,Event,ADDED,eval-conflicts-rho000-r3-032.18d46423b3b3b28c,reason=Completed count=1 msg=Job completed
0.3685,Event,ADDED,eval-conflicts-rho000-r3-033-8dksl.18d46420e5a9453b,reason=Scheduled count=None msg=Successfully assigned compute/eval-conflicts-rho000-r3-033-8dksl to kind-worker
0.3687,Event,ADDED,eval-conflicts-rho000-r3-033-8dksl.18d4642106b0b8ad,"reason=Pulled count=1 msg=Container image ""busybox:musl"" already present on machine"
0.3689,Event,ADDED,eval-conflicts-rho000-r3-033-8dksl.18d4642107c9493e,reason=Created count=1 msg=Created container: task
0.3691,Event,ADDED,eval-conflicts-rho000-r3-033-8dksl.18d464210bc1c212,reason=Started count=1 msg=Started container task
0.3692,Event,ADDED,eval-conflicts-rho000-r3-033.18d46420e4b3da02,reason=SuccessfulCreate count=1 msg=Created pod: eval-conflicts-rho000-r3-033-8dksl
0.3694,Event,ADDED,eval-conflicts-rho000-r3-033.18d46423ef5e20a7,reason=Completed count=1 msg=Job completed
0.3695,Event,ADDED,eval-conflicts-rho000-r3-034-6pc2w.18d4642121530219,reason=Scheduled count=None msg=Successfully assigned compute/eval-conflicts-rho000-r3-034-6pc2w to kind-worker4
0.3697,Event,ADDED,eval-conflicts-rho000-r3-034-6pc2w.18d464213a2067d2,"reason=Pulled count=1 msg=Container image ""busybox:musl"" already present on machine"
0.3699,Event,ADDED,eval-conflicts-rho000-r3-034-6pc2w.18d464213b54a03a,reason=Created count=1 msg=Created container: task
0.37,Event,ADDED,eval-conflicts-rho000-r3-034-6pc2w.18d464213d4ebae8,reason=Started count=1 msg=Started container task
0.3702,Event,ADDED,eval-conflicts-rho000-r3-034.18d464212052fb75,reason=SuccessfulCreate count=1 msg=Created pod: eval-conflicts-rho000-r3-034-6pc2w
0.3704,Event,ADDED,eval-conflicts-rho000-r3-034.18d464244f2cad57,reason=Completed count=1 msg=Job completed
0.3705,Event,ADDED,eval-conflicts-rho000-r3-035-ftd5w.18d464215d56417b,reason=Scheduled count=None msg=Successfully assigned compute/eval-conflicts-rho000-r3-035-ftd5w to kind-worker
0.3707,Event,ADDED,eval-conflicts-rho000-r3-035-ftd5w.18d46421765fa8b3,"reason=Pulled count=1 msg=Container image ""busybox:musl"" already present on machine"
0.3708,Event,ADDED,eval-conflicts-rho000-r3-035-ftd5w.18d464217772a981,reason=Created count=1 msg=Created container: task
0.371,Event,ADDED,eval-conflicts-rho000-r3-035-ftd5w.18d46421795e755d,reason=Started count=1 msg=Started container task
0.3712,Event,ADDED,eval-conflicts-rho000-r3-035.18d464215c0f2661,reason=SuccessfulCreate count=1 msg=Created pod: eval-conflicts-rho000-r3-035-ftd5w
0.3713,Event,ADDED,eval-conflicts-rho000-r3-035.18d46424a44dd1d6,reason=Completed count=1 msg=Job completed
0.3715,Event,ADDED,eval-conflicts-rho000-r3-036-qc4tt.18d46421997505bc,reason=Scheduled count=None msg=Successfully assigned compute/eval-conflicts-rho000-r3-036-qc4tt to kind-worker2
0.3716,Event,ADDED,eval-conflicts-rho000-r3-036-qc4tt.18d46421b218950f,"reason=Pulled count=1 msg=Container image ""busybox:musl"" already present on machine"
0.3718,Event,ADDED,eval-conflicts-rho000-r3-036-qc4tt.18d46421b328ba64,reason=Created count=1 msg=Created container: task
0.372,Event,ADDED,eval-conflicts-rho000-r3-036-qc4tt.18d46421b54626fc,reason=Started count=1 msg=Started container task
0.3721,Event,ADDED,eval-conflicts-rho000-r3-036.18d464219851f0cd,reason=SuccessfulCreate count=1 msg=Created pod: eval-conflicts-rho000-r3-036-qc4tt
0.3723,Event,ADDED,eval-conflicts-rho000-r3-036.18d46424cbd05f5d,reason=Completed count=1 msg=Job completed
0.3724,Event,ADDED,eval-conflicts-rho000-r3-037-gmkvf.18d46421d49bacb3,reason=Scheduled count=None msg=Successfully assigned compute/eval-conflicts-rho000-r3-037-gmkvf to kind-worker2
0.3727,Event,ADDED,eval-conflicts-rho000-r3-037-gmkvf.18d46421ee323b54,"reason=Pulled count=1 msg=Container image ""busybox:musl"" already present on machine"
0.3728,Event,ADDED,eval-conflicts-rho000-r3-037-gmkvf.18d46421ef433432,reason=Created count=1 msg=Created container: task
0.373,Event,ADDED,eval-conflicts-rho000-r3-037-gmkvf.18d46421f1574821,reason=Started count=1 msg=Started container task
0.3732,Event,ADDED,eval-conflicts-rho000-r3-037.18d46421d3bdc386,reason=SuccessfulCreate count=1 msg=Created pod: eval-conflicts-rho000-r3-037-gmkvf
0.3734,Event,ADDED,eval-conflicts-rho000-r3-037.18d46425080042b7,reason=Completed count=1 msg=Job completed
0.3735,Event,ADDED,eval-conflicts-rho000-r3-038-lgl8g.18d464220f734dae,reason=Scheduled count=None msg=Successfully assigned compute/eval-conflicts-rho000-r3-038-lgl8g to kind-worker4
0.3737,Event,ADDED,eval-conflicts-rho000-r3-038-lgl8g.18d4642228b4930f,"reason=Pulled count=1 msg=Container image ""busybox:musl"" already present on machine"
0.3739,Event,ADDED,eval-conflicts-rho000-r3-038-lgl8g.18d4642229c80f40,reason=Created count=1 msg=Created container: task
0.374,Event,ADDED,eval-conflicts-rho000-r3-038-lgl8g.18d464222d746d6b,reason=Started count=1 msg=Started container task
0.3742,Event,ADDED,eval-conflicts-rho000-r3-038.18d464220e960991,reason=SuccessfulCreate count=1 msg=Created pod: eval-conflicts-rho000-r3-038-lgl8g
0.3744,Event,ADDED,eval-conflicts-rho000-r3-038.18d464253f204a25,reason=Completed count=1 msg=Job completed
0.3745,Event,ADDED,eval-conflicts-rho000-r3-039-bfn8l.18d464224b2e0f12,reason=Scheduled count=None msg=Successfully assigned compute/eval-conflicts-rho000-r3-039-bfn8l to kind-worker3
0.3747,Event,ADDED,eval-conflicts-rho000-r3-039-bfn8l.18d4642263d2f7dd,"reason=Pulled count=1 msg=Container image ""busybox:musl"" already present on machine"
0.3748,Event,ADDED,eval-conflicts-rho000-r3-039-bfn8l.18d4642264e3e315,reason=Created count=1 msg=Created container: task
0.375,Event,ADDED,eval-conflicts-rho000-r3-039-bfn8l.18d4642266cfa2fc,reason=Started count=1 msg=Started container task
0.3752,Event,ADDED,eval-conflicts-rho000-r3-039.18d464224a9abd62,reason=SuccessfulCreate count=1 msg=Created pod: eval-conflicts-rho000-r3-039-bfn8l
0.3753,Event,ADDED,eval-conflicts-rho000-r3-039.18d4642577ed00f4,reason=Completed count=1 msg=Job completed
0.3755,Event,ADDED,eval-conflicts-rho000-r3-040-tzztl.18d4642286bde00d,reason=Scheduled count=None msg=Successfully assigned compute/eval-conflicts-rho000-r3-040-tzztl to kind-worker3
0.3757,Event,ADDED,eval-conflicts-rho000-r3-040-tzztl.18d46422a05d4926,"reason=Pulled count=1 msg=Container image ""busybox:musl"" already present on machine"
0.3758,Event,ADDED,eval-conflicts-rho000-r3-040-tzztl.18d46422a1769b49,reason=Created count=1 msg=Created container: task
0.376,Event,ADDED,eval-conflicts-rho000-r3-040-tzztl.18d46422a57bd798,reason=Started count=1 msg=Started container task
0.3761,Event,ADDED,eval-conflicts-rho000-r3-040.18d464228626c00a,reason=SuccessfulCreate count=1 msg=Created pod: eval-conflicts-rho000-r3-040-tzztl
0.3763,Event,ADDED,eval-conflicts-rho000-r3-040.18d46425b487cd33,reason=Completed count=1 msg=Job completed
0.3764,Event,ADDED,eval-conflicts-rho000-r3-041-r7l4c.18d46422c250e654,reason=Scheduled count=None msg=Successfully assigned compute/eval-conflicts-rho000-r3-041-r7l4c to kind-worker3
0.3766,Event,ADDED,eval-conflicts-rho000-r3-041-r7l4c.18d46422db797d02,"reason=Pulled count=1 msg=Container image ""busybox:musl"" already present on machine"
0.3768,Event,ADDED,eval-conflicts-rho000-r3-041-r7l4c.18d46422dc9ee470,reason=Created count=1 msg=Created container: task
0.3769,Event,ADDED,eval-conflicts-rho000-r3-041-r7l4c.18d46422e1dbd820,reason=Started count=1 msg=Started container task
0.3772,Event,ADDED,eval-conflicts-rho000-r3-041.18d46422c1b6adb8,reason=SuccessfulCreate count=1 msg=Created pod: eval-conflicts-rho000-r3-041-r7l4c
0.3773,Event,ADDED,eval-conflicts-rho000-r3-041.18d46425f092822a,reason=Completed count=1 msg=Job completed
0.3775,Event,ADDED,eval-conflicts-rho000-r3-042-8g2h9.18d46422fde9edd3,reason=Scheduled count=None msg=Successfully assigned compute/eval-conflicts-rho000-r3-042-8g2h9 to kind-worker3
0.3777,Event,ADDED,eval-conflicts-rho000-r3-042-8g2h9.18d464231762d9c1,"reason=Pulled count=1 msg=Container image ""busybox:musl"" already present on machine"
0.3779,Event,ADDED,eval-conflicts-rho000-r3-042-8g2h9.18d46423187deb9e,reason=Created count=1 msg=Created container: task
0.3781,Event,ADDED,eval-conflicts-rho000-r3-042-8g2h9.18d464231aa266d9,reason=Started count=1 msg=Started container task
0.3787,Event,ADDED,eval-conflicts-rho000-r3-042.18d46422fd52d727,reason=SuccessfulCreate count=1 msg=Created pod: eval-conflicts-rho000-r3-042-8g2h9
0.3791,Event,ADDED,eval-conflicts-rho000-r3-042.18d464262c6c5c66,reason=Completed count=1 msg=Job completed
0.3794,Event,ADDED,eval-conflicts-rho000-r3-043-624fl.18d46423397ae621,reason=Scheduled count=None msg=Successfully assigned compute/eval-conflicts-rho000-r3-043-624fl to kind-worker3
0.3796,Event,ADDED,eval-conflicts-rho000-r3-043-624fl.18d46423534f0516,"reason=Pulled count=1 msg=Container image ""busybox:musl"" already present on machine"
0.3799,Event,ADDED,eval-conflicts-rho000-r3-043-624fl.18d46423547c0fc6,reason=Created count=1 msg=Created container: task
0.3801,Event,ADDED,eval-conflicts-rho000-r3-043-624fl.18d46423567cb14b,reason=Started count=1 msg=Started container task
0.3803,Event,ADDED,eval-conflicts-rho000-r3-043.18d4642338ee2d4e,reason=SuccessfulCreate count=1 msg=Created pod: eval-conflicts-rho000-r3-043-624fl
0.3806,Event,ADDED,eval-conflicts-rho000-r3-043.18d46426688798c7,reason=Completed count=1 msg=Job completed
0.3808,Event,ADDED,eval-conflicts-rho000-r3-044-c82wl.18d46423758a8c1b,reason=Scheduled count=None msg=Successfully assigned compute/eval-conflicts-rho000-r3-044-c82wl to kind-worker5
0.381,Event,ADDED,eval-conflicts-rho000-r3-044-c82wl.18d464238e80f21b,"reason=Pulled count=1 msg=Container image ""busybox:musl"" already present on machine"
0.3812,Event,ADDED,eval-conflicts-rho000-r3-044-c82wl.18d464238fa2d8af,reason=Created count=1 msg=Created container: task
0.3816,Event,ADDED,eval-conflicts-rho000-r3-044-c82wl.18d4642391e52f63,reason=Started count=1 msg=Started container task
0.3818,Event,ADDED,eval-conflicts-rho000-r3-044.18d46423746fadc4,reason=SuccessfulCreate count=1 msg=Created pod: eval-conflicts-rho000-r3-044-c82wl
0.3821,Event,ADDED,eval-conflicts-rho000-r3-044.18d46426c1ecc4c9,reason=Completed count=1 msg=Job completed
0.3826,Event,ADDED,eval-conflicts-rho000-r3-045-qtkt5.18d46423b149e6dd,reason=Scheduled count=None msg=Successfully assigned compute/eval-conflicts-rho000-r3-045-qtkt5 to kind-worker5
0.383,Event,ADDED,eval-conflicts-rho000-r3-045-qtkt5.18d46423c99e2346,"reason=Pulled count=1 msg=Container image ""busybox:musl"" already present on machine"
0.3834,Event,ADDED,eval-conflicts-rho000-r3-045-qtkt5.18d46423cab1c2dc,reason=Created count=1 msg=Created container: task
0.3838,Event,ADDED,eval-conflicts-rho000-r3-045-qtkt5.18d46423ccda59fa,reason=Started count=1 msg=Started container task
0.3842,Event,ADDED,eval-conflicts-rho000-r3-045.18d46423b039c03e,reason=SuccessfulCreate count=1 msg=Created pod: eval-conflicts-rho000-r3-045-qtkt5
0.3844,Event,ADDED,eval-conflicts-rho000-r3-045.18d46426fdacbcc7,reason=Completed count=1 msg=Job completed
0.3846,Event,ADDED,eval-conflicts-rho000-r3-046-4ts79.18d46423ecb697e7,reason=Scheduled count=None msg=Successfully assigned compute/eval-conflicts-rho000-r3-046-4ts79 to kind-worker5
0.3848,Event,ADDED,eval-conflicts-rho000-r3-046-4ts79.18d46424054dfda4,"reason=Pulled count=1 msg=Container image ""busybox:musl"" already present on machine"
0.3854,Event,ADDED,eval-conflicts-rho000-r3-046-4ts79.18d46424066c2386,reason=Created count=1 msg=Created container: task
0.3859,Event,ADDED,eval-conflicts-rho000-r3-046-4ts79.18d464240af006e9,reason=Started count=1 msg=Started container task
0.3864,Event,ADDED,eval-conflicts-rho000-r3-046.18d46423ebbdb912,reason=SuccessfulCreate count=1 msg=Created pod: eval-conflicts-rho000-r3-046-4ts79
0.3872,Event,ADDED,eval-conflicts-rho000-r3-046.18d4642739121dfb,reason=Completed count=1 msg=Job completed
0.3878,Event,ADDED,eval-conflicts-rho000-r3-047-f6cgv.18d4642427c733ed,reason=Scheduled count=None msg=Successfully assigned compute/eval-conflicts-rho000-r3-047-f6cgv to kind-worker5
0.3882,Event,ADDED,eval-conflicts-rho000-r3-047-f6cgv.18d46424422197a5,"reason=Pulled count=1 msg=Container image ""busybox:musl"" already present on machine"
0.3887,Event,ADDED,eval-conflicts-rho000-r3-047-f6cgv.18d46424433d8cd8,reason=Created count=1 msg=Created container: task
0.3891,Event,ADDED,eval-conflicts-rho000-r3-047-f6cgv.18d4642448488f5b,reason=Started count=1 msg=Started container task
0.3893,Event,ADDED,eval-conflicts-rho000-r3-047.18d4642427379e36,reason=SuccessfulCreate count=1 msg=Created pod: eval-conflicts-rho000-r3-047-f6cgv
0.3895,Event,ADDED,eval-conflicts-rho000-r3-047.18d4642774f4210c,reason=Completed count=1 msg=Job completed
0.3896,Event,ADDED,eval-conflicts-rho000-r3-048-b2r7b.18d464246361dc27,reason=Scheduled count=None msg=Successfully assigned compute/eval-conflicts-rho000-r3-048-b2r7b to kind-worker5
0.39,Event,ADDED,eval-conflicts-rho000-r3-048-b2r7b.18d464247d919c55,"reason=Pulled count=1 msg=Container image ""busybox:musl"" already present on machine"
0.3903,Event,ADDED,eval-conflicts-rho000-r3-048-b2r7b.18d464247eacc87b,reason=Created count=1 msg=Created container: task
0.3905,Event,ADDED,eval-conflicts-rho000-r3-048-b2r7b.18d4642484438d36,reason=Started count=1 msg=Started container task
0.3908,Event,ADDED,eval-conflicts-rho000-r3-048.18d4642462daa49e,reason=SuccessfulCreate count=1 msg=Created pod: eval-conflicts-rho000-r3-048-b2r7b
0.391,Event,ADDED,eval-conflicts-rho000-r3-048.18d4642775724d7e,reason=Completed count=1 msg=Job completed
0.3912,Event,ADDED,eval-conflicts-rho000-r3-049-v2ddc.18d464249f17216d,reason=Scheduled count=None msg=Successfully assigned compute/eval-conflicts-rho000-r3-049-v2ddc to kind-worker5
0.3914,Event,ADDED,eval-conflicts-rho000-r3-049-v2ddc.18d46424bb2a83b5,"reason=Pulled count=1 msg=Container image ""busybox:musl"" already present on machine"
0.3917,Event,ADDED,eval-conflicts-rho000-r3-049-v2ddc.18d46424bca3853c,reason=Created count=1 msg=Created container: task
0.3919,Event,ADDED,eval-conflicts-rho000-r3-049-v2ddc.18d46424c1141d9b,reason=Started count=1 msg=Started container task
0.3921,Event,ADDED,eval-conflicts-rho000-r3-049.18d464249e929ac9,reason=SuccessfulCreate count=1 msg=Created pod: eval-conflicts-rho000-r3-049-v2ddc
0.3924,Event,ADDED,eval-conflicts-rho000-r3-049.18d46427ee46df4b,reason=Completed count=1 msg=Job completed
0.3926,Event,ADDED,eval-conflicts-rho000-r3-050-nh4qx.18d46424dafd3d33,reason=Scheduled count=None msg=Successfully assigned compute/eval-conflicts-rho000-r3-050-nh4qx to kind-worker5
0.3928,Event,ADDED,eval-conflicts-rho000-r3-050-nh4qx.18d46424f3c755ac,"reason=Pulled count=1 msg=Container image ""busybox:musl"" already present on machine"
0.393,Event,ADDED,eval-conflicts-rho000-r3-050-nh4qx.18d46424f4e4d22a,reason=Created count=1 msg=Created container: task
0.3933,Event,ADDED,eval-conflicts-rho000-r3-050-nh4qx.18d46424f6e1829e,reason=Started count=1 msg=Started container task
0.3935,Event,ADDED,eval-conflicts-rho000-r3-050.18d46424da6fa489,reason=SuccessfulCreate count=1 msg=Created pod: eval-conflicts-rho000-r3-050-nh4qx
0.3937,Event,ADDED,eval-conflicts-rho000-r3-050.18d46427eee725bd,reason=Completed count=1 msg=Job completed
0.3939,Event,ADDED,eval-conflicts-rho000-r3-051-tpmg9.18d464251673ea2c,reason=Scheduled count=None msg=Successfully assigned compute/eval-conflicts-rho000-r3-051-tpmg9 to kind-worker5
0.3942,Event,ADDED,eval-conflicts-rho000-r3-051-tpmg9.18d4642532194634,"reason=Pulled count=1 msg=Container image ""busybox:musl"" already present on machine"
0.3945,Event,ADDED,eval-conflicts-rho000-r3-051-tpmg9.18d4642533437985,reason=Created count=1 msg=Created container: task
0.3947,Event,ADDED,eval-conflicts-rho000-r3-051-tpmg9.18d464253726c110,reason=Started count=1 msg=Started container task
0.395,Event,ADDED,eval-conflicts-rho000-r3-051.18d4642515c6e660,reason=SuccessfulCreate count=1 msg=Created pod: eval-conflicts-rho000-r3-051-tpmg9
0.3952,Event,ADDED,eval-conflicts-rho000-r3-051.18d4642868c91904,reason=Completed count=1 msg=Job completed
0.3953,Event,ADDED,eval-conflicts-rho000-r3-052-zsthm.18d4642551f35ca3,reason=Scheduled count=None msg=Successfully assigned compute/eval-conflicts-rho000-r3-052-zsthm to kind-worker5
0.3956,Event,ADDED,eval-conflicts-rho000-r3-052-zsthm.18d464256b30ad06,"reason=Pulled count=1 msg=Container image ""busybox:musl"" already present on machine"
0.396,Event,ADDED,eval-conflicts-rho000-r3-052-zsthm.18d464256c509a5c,reason=Created count=1 msg=Created container: task
0.3962,Event,ADDED,eval-conflicts-rho000-r3-052-zsthm.18d464256e681832,reason=Started count=1 msg=Started container task
0.3964,Event,ADDED,eval-conflicts-rho000-r3-052.18d464255159e657,reason=SuccessfulCreate count=1 msg=Created pod: eval-conflicts-rho000-r3-052-zsthm
0.3965,Event,ADDED,eval-conflicts-rho000-r3-052.18d46428a640505e,reason=Completed count=1 msg=Job completed
0.3969,Event,ADDED,eval-conflicts-rho000-r3-053-4njtv.18d464258e65adbf,reason=Scheduled count=None msg=Successfully assigned compute/eval-conflicts-rho000-r3-053-4njtv to kind-worker5
0.3971,Event,ADDED,eval-conflicts-rho000-r3-053-4njtv.18d46425a6c5de3f,"reason=Pulled count=1 msg=Container image ""busybox:musl"" already present on machine"
0.3973,Event,ADDED,eval-conflicts-rho000-r3-053-4njtv.18d46425a7da1d8a,reason=Created count=1 msg=Created container: task
0.3976,Event,ADDED,eval-conflicts-rho000-r3-053-4njtv.18d46425a9c81e41,reason=Started count=1 msg=Started container task
0.3978,Event,ADDED,eval-conflicts-rho000-r3-053.18d464258dd78e26,reason=SuccessfulCreate count=1 msg=Created pod: eval-conflicts-rho000-r3-053-4njtv
0.398,Event,ADDED,eval-conflicts-rho000-r3-053.18d46428e454d348,reason=Completed count=1 msg=Job completed
0.3983,Event,ADDED,eval-conflicts-rho000-r3-054-j2rgg.18d46425c8c56b62,"reason=FailedScheduling count=None msg=0/6 nodes are available: 6 node(s) had untolerated taint(s). no new claims to deallocate, preemption: 0/6 nodes are available: 6 Preemption is not helpful for scheduling."
0.3986,Event,ADDED,eval-conflicts-rho000-r3-054-j2rgg.18d464266f30652e,reason=Scheduled count=None msg=Successfully assigned compute/eval-conflicts-rho000-r3-054-j2rgg to kind-worker
0.3988,Event,ADDED,eval-conflicts-rho000-r3-054-j2rgg.18d464268c035e47,"reason=Pulled count=1 msg=Container image ""busybox:musl"" already present on machine"
0.399,Event,ADDED,eval-conflicts-rho000-r3-054-j2rgg.18d464268e3eed99,reason=Created count=1 msg=Created container: task
0.3993,Event,ADDED,eval-conflicts-rho000-r3-054-j2rgg.18d46426923dc25f,reason=Started count=1 msg=Started container task
0.3994,Event,ADDED,eval-conflicts-rho000-r3-054.18d46425c8ba2cb8,reason=SuccessfulCreate count=1 msg=Created pod: eval-conflicts-rho000-r3-054-j2rgg
0.3996,Event,ADDED,eval-conflicts-rho000-r3-054.18d46429cb794f6f,reason=Completed count=1 msg=Job completed
0.3998,Event,ADDED,eval-conflicts-rho000-r3-055-f6nfj.18d46426043c669e,"reason=FailedScheduling count=None msg=0/6 nodes are available: 6 node(s) had untolerated taint(s). no new claims to deallocate, preemption: 0/6 nodes are available: 6 Preemption is not helpful for scheduling."
0.4001,Event,ADDED,eval-conflicts-rho000-r3-055-f6nfj.18d464266f8e0e76,reason=Scheduled count=None msg=Successfully assigned compute/eval-conflicts-rho000-r3-055-f6nfj to kind-worker
0.4002,Event,ADDED,eval-conflicts-rho000-r3-055-f6nfj.18d464268c2310d5,"reason=Pulled count=1 msg=Container image ""busybox:musl"" already present on machine"
0.4004,Event,ADDED,eval-conflicts-rho000-r3-055-f6nfj.18d464268e866d94,reason=Created count=1 msg=Created container: task
0.4008,Event,ADDED,eval-conflicts-rho000-r3-055-f6nfj.18d464269267e0e7,reason=Started count=1 msg=Started container task
0.401,Event,ADDED,eval-conflicts-rho000-r3-055.18d46426042f22ed,reason=SuccessfulCreate count=1 msg=Created pod: eval-conflicts-rho000-r3-055-f6nfj
0.4012,Event,ADDED,eval-conflicts-rho000-r3-055.18d46429cb3df94c,reason=Completed count=1 msg=Job completed
0.4013,Event,ADDED,eval-conflicts-rho000-r3-056-85cjc.18d464263fa6d9fd,"reason=FailedScheduling count=None msg=0/6 nodes are available: 6 node(s) had untolerated taint(s). no new claims to deallocate, preemption: 0/6 nodes are available: 6 Preemption is not helpful for scheduling."
0.4015,Event,ADDED,eval-conflicts-rho000-r3-056-85cjc.18d464266fc56595,reason=Scheduled count=None msg=Successfully assigned compute/eval-conflicts-rho000-r3-056-85cjc to kind-worker
0.4017,Event,ADDED,eval-conflicts-rho000-r3-056-85cjc.18d464268c460b79,"reason=Pulled count=1 msg=Container image ""busybox:musl"" already present on machine"
0.4018,Event,ADDED,eval-conflicts-rho000-r3-056-85cjc.18d464268f4d9994,reason=Created count=1 msg=Created container: task
0.4022,Event,ADDED,eval-conflicts-rho000-r3-056-85cjc.18d4642692eb14f9,reason=Started count=1 msg=Started container task
0.4026,Event,ADDED,eval-conflicts-rho000-r3-056.18d464263fa048d8,reason=SuccessfulCreate count=1 msg=Created pod: eval-conflicts-rho000-r3-056-85cjc
0.4027,Event,ADDED,eval-conflicts-rho000-r3-056.18d46429cb5c0f58,reason=Completed count=1 msg=Job completed
0.4029,Event,ADDED,eval-conflicts-rho000-r3-057-62s7z.18d464267c27ca1e,reason=Scheduled count=None msg=Successfully assigned compute/eval-conflicts-rho000-r3-057-62s7z to kind-worker
0.4032,Event,ADDED,eval-conflicts-rho000-r3-057-62s7z.18d4642697571431,"reason=Pulled count=1 msg=Container image ""busybox:musl"" already present on machine"
0.4034,Event,ADDED,eval-conflicts-rho000-r3-057-62s7z.18d46426985e33a5,reason=Created count=1 msg=Created container: task
0.4036,Event,ADDED,eval-conflicts-rho000-r3-057-62s7z.18d464269f0f2ed9,reason=Started count=1 msg=Started container task
0.4037,Event,ADDED,eval-conflicts-rho000-r3-057.18d464267ba1e870,reason=SuccessfulCreate count=1 msg=Created pod: eval-conflicts-rho000-r3-057-62s7z
0.404,Event,ADDED,eval-conflicts-rho000-r3-057.18d46429cb79ef90,reason=Completed count=1 msg=Job completed
0.4042,Event,ADDED,eval-conflicts-rho000-r3-058-g9g6n.18d46426b8123d20,reason=Scheduled count=None msg=Successfully assigned compute/eval-conflicts-rho000-r3-058-g9g6n to kind-worker
0.4044,Event,ADDED,eval-conflicts-rho000-r3-058-g9g6n.18d46426cff3f8c4,"reason=Pulled count=1 msg=Container image ""busybox:musl"" already present on machine"
0.4046,Event,ADDED,eval-conflicts-rho000-r3-058-g9g6n.18d46426d0f6778d,reason=Created count=1 msg=Created container: task
0.4048,Event,ADDED,eval-conflicts-rho000-r3-058-g9g6n.18d46426d2d0069d,reason=Started count=1 msg=Started container task
0.405,Event,ADDED,eval-conflicts-rho000-r3-058.18d46426b702e0e0,reason=SuccessfulCreate count=1 msg=Created pod: eval-conflicts-rho000-r3-058-g9g6n
0.4052,Event,ADDED,eval-conflicts-rho000-r3-058.18d4642a01fcf1ae,reason=Completed count=1 msg=Job completed
0.4054,Event,ADDED,eval-conflicts-rho000-r3-059-chxpx.18d46426f33aef2b,reason=Scheduled count=None msg=Successfully assigned compute/eval-conflicts-rho000-r3-059-chxpx to kind-worker2
0.4055,Event,ADDED,eval-conflicts-rho000-r3-059-chxpx.18d464270cd3abc9,"reason=Pulled count=1 msg=Container image ""busybox:musl"" already present on machine"
0.4057,Event,ADDED,eval-conflicts-rho000-r3-059-chxpx.18d464270de38a28,reason=Created count=1 msg=Created container: task
0.4059,Event,ADDED,eval-conflicts-rho000-r3-059-chxpx.18d4642713e53069,reason=Started count=1 msg=Started container task
0.4061,Event,ADDED,eval-conflicts-rho000-r3-059.18d46426f26f06bd,reason=SuccessfulCreate count=1 msg=Created pod: eval-conflicts-rho000-r3-059-chxpx
0.4063,Event,ADDED,eval-conflicts-rho000-r3-059.18d4642a27aaa506,reason=Completed count=1 msg=Job completed
0.4065,Event,ADDED,eval-conflicts-rho000-r3-060-75c7n.18d464272f976229,reason=Scheduled count=None msg=Successfully assigned compute/eval-conflicts-rho000-r3-060-75c7n to kind-worker2
0.4068,Event,ADDED,eval-conflicts-rho000-r3-060-75c7n.18d4642747d7468e,"reason=Pulled count=1 msg=Container image ""busybox:musl"" already present on machine"
0.407,Event,ADDED,eval-conflicts-rho000-r3-060-75c7n.18d4642748f2716c,reason=Created count=1 msg=Created container: task
0.4072,Event,ADDED,eval-conflicts-rho000-r3-060-75c7n.18d464274d8434b3,reason=Started count=1 msg=Started container task
0.4074,Event,ADDED,eval-conflicts-rho000-r3-060.18d464272e73d7a9,reason=SuccessfulCreate count=1 msg=Created pod: eval-conflicts-rho000-r3-060-75c7n
0.4078,Event,ADDED,eval-conflicts-rho000-r3-060.18d4642a635d4196,reason=Completed count=1 msg=Job completed
0.408,Event,ADDED,eval-conflicts-rho000-r3-061-qf655.18d464276b23e746,reason=Scheduled count=None msg=Successfully assigned compute/eval-conflicts-rho000-r3-061-qf655 to kind-worker2
0.4082,Event,ADDED,eval-conflicts-rho000-r3-061-qf655.18d464278814d8ca,"reason=Pulled count=1 msg=Container image ""busybox:musl"" already present on machine"
0.4084,Event,ADDED,eval-conflicts-rho000-r3-061-qf655.18d4642789401387,reason=Created count=1 msg=Created container: task
0.4087,Event,ADDED,eval-conflicts-rho000-r3-061-qf655.18d464279386e6f8,reason=Started count=1 msg=Started container task
0.4089,Event,ADDED,eval-conflicts-rho000-r3-061.18d464276a2df702,reason=SuccessfulCreate count=1 msg=Created pod: eval-conflicts-rho000-r3-061-qf655
0.4091,Event,ADDED,eval-conflicts-rho000-r3-061.18d4642a9e72c265,reason=Completed count=1 msg=Job completed
0.4094,Event,ADDED,eval-conflicts-rho000-r3-062-qq6t8.18d46427a6cccfe8,reason=Scheduled count=None msg=Successfully assigned compute/eval-conflicts-rho000-r3-062-qq6t8 to kind-worker4
0.4096,Event,ADDED,eval-conflicts-rho000-r3-062-qq6t8.18d46427c3cb4222,"reason=Pulled count=1 msg=Container image ""busybox:musl"" already present on machine"
0.4097,Event,ADDED,eval-conflicts-rho000-r3-062-qq6t8.18d46427c4e8b8d0,reason=Created count=1 msg=Created container: task
0.4099,Event,ADDED,eval-conflicts-rho000-r3-062-qq6t8.18d46427cb940fe5,reason=Started count=1 msg=Started container task
0.4103,Event,ADDED,eval-conflicts-rho000-r3-062.18d46427a5f56eeb,reason=SuccessfulCreate count=1 msg=Created pod: eval-conflicts-rho000-r3-062-qq6t8
0.4105,Event,ADDED,eval-conflicts-rho000-r3-062.18d4642ad7c1b836,reason=Completed count=1 msg=Job completed
0.4107,Event,ADDED,eval-conflicts-rho000-r3-063-jtwpd.18d46427e4510abf,reason=Scheduled count=None msg=Successfully assigned compute/eval-conflicts-rho000-r3-063-jtwpd to kind-worker4
0.4108,Event,ADDED,eval-conflicts-rho000-r3-063-jtwpd.18d46427ffd38a79,"reason=Pulled count=1 msg=Container image ""busybox:musl"" already present on machine"
0.4111,Event,ADDED,eval-conflicts-rho000-r3-063-jtwpd.18d46428034d52f7,reason=Created count=1 msg=Created container: task
0.4113,Event,ADDED,eval-conflicts-rho000-r3-063-jtwpd.18d4642808dbde89,reason=Started count=1 msg=Started container task
0.4115,Event,ADDED,eval-conflicts-rho000-r3-063.18d46427e31eb9e8,reason=SuccessfulCreate count=1 msg=Created pod: eval-conflicts-rho000-r3-063-jtwpd
0.4117,Event,ADDED,eval-conflicts-rho000-r3-063.18d4642b4f612dbe,reason=Completed count=1 msg=Job completed
0.4119,Event,ADDED,eval-conflicts-rho000-r3-064-hvcjr.18d464281e69e43a,reason=Scheduled count=None msg=Successfully assigned compute/eval-conflicts-rho000-r3-064-hvcjr to kind-worker2
0.412,Event,ADDED,eval-conflicts-rho000-r3-064-hvcjr.18d4642837b25c3e,"reason=Pulled count=1 msg=Container image ""busybox:musl"" already present on machine"
0.4122,Event,ADDED,eval-conflicts-rho000-r3-064-hvcjr.18d4642838c79180,reason=Created count=1 msg=Created container: task
0.4124,Event,ADDED,eval-conflicts-rho000-r3-064-hvcjr.18d464283d12c162,reason=Started count=1 msg=Started container task
0.4126,Event,ADDED,eval-conflicts-rho000-r3-064.18d464281d49270f,reason=SuccessfulCreate count=1 msg=Created pod: eval-conflicts-rho000-r3-064-hvcjr
0.4127,Event,ADDED,eval-conflicts-rho000-r3-064.18d4642b51280f22,reason=Completed count=1 msg=Job completed
0.4129,Event,ADDED,eval-conflicts-rho000-r3-065-djsbq.18d4642859a6da00,reason=Scheduled count=None msg=Successfully assigned compute/eval-conflicts-rho000-r3-065-djsbq to kind-worker2
0.4134,Event,ADDED,eval-conflicts-rho000-r3-065-djsbq.18d4642873dc8ac6,"reason=Pulled count=1 msg=Container image ""busybox:musl"" already present on machine"
0.4136,Event,ADDED,eval-conflicts-rho000-r3-065-djsbq.18d46428750e0124,reason=Created count=1 msg=Created container: task
0.4138,Event,ADDED,eval-conflicts-rho000-r3-065-djsbq.18d464287aa20055,reason=Started count=1 msg=Started container task
0.4142,Event,ADDED,eval-conflicts-rho000-r3-065.18d46428589dd5a6,reason=SuccessfulCreate count=1 msg=Created pod: eval-conflicts-rho000-r3-065-djsbq
0.4144,Event,ADDED,eval-conflicts-rho000-r3-065.18d4642b8cf2617e,reason=Completed count=1 msg=Job completed
0.4146,Event,ADDED,eval-conflicts-rho000-r3-066-g7nmk.18d4642896802a87,reason=Scheduled count=None msg=Successfully assigned compute/eval-conflicts-rho000-r3-066-g7nmk to kind-worker4
0.4148,Event,ADDED,eval-conflicts-rho000-r3-066-g7nmk.18d46428b0369cc0,"reason=Pulled count=1 msg=Container image ""busybox:musl"" already present on machine"
0.4151,Event,ADDED,eval-conflicts-rho000-r3-066-g7nmk.18d46428b15e0661,reason=Created count=1 msg=Created container: task
0.4153,Event,ADDED,eval-conflicts-rho000-r3-066-g7nmk.18d46428b5df0f8e,reason=Started count=1 msg=Started container task
0.4154,Event,ADDED,eval-conflicts-rho000-r3-066.18d46428953e63ee,reason=SuccessfulCreate count=1 msg=Created pod: eval-conflicts-rho000-r3-066-g7nmk
0.4158,Event,ADDED,eval-conflicts-rho000-r3-066.18d4642bc66c2bbc,reason=Completed count=1 msg=Job completed
0.4159,Event,ADDED,eval-conflicts-rho000-r3-067-h5zqp.18d46428d3814d29,reason=Scheduled count=None msg=Successfully assigned compute/eval-conflicts-rho000-r3-067-h5zqp to kind-worker4
0.4161,Event,ADDED,eval-conflicts-rho000-r3-067-h5zqp.18d46428ed8d4f79,"reason=Pulled count=1 msg=Container image ""busybox:musl"" already present on machine"
0.4164,Event,ADDED,eval-conflicts-rho000-r3-067-h5zqp.18d46428eea2839d,reason=Created count=1 msg=Created container: task
0.4167,Event,ADDED,eval-conflicts-rho000-r3-067-h5zqp.18d46428f09ea903,reason=Started count=1 msg=Started container task
0.4169,Event,ADDED,eval-conflicts-rho000-r3-067.18d46428d2b0f648,reason=SuccessfulCreate count=1 msg=Created pod: eval-conflicts-rho000-r3-067-h5zqp
0.4171,Event,ADDED,eval-conflicts-rho000-r3-067.18d4642c025b0038,reason=Completed count=1 msg=Job completed
0.4173,Event,ADDED,eval-conflicts-rho000-r3-068-pcwtb.18d464290c1b7b2c,reason=Scheduled count=None msg=Successfully assigned compute/eval-conflicts-rho000-r3-068-pcwtb to kind-worker2
0.4177,Event,ADDED,eval-conflicts-rho000-r3-068-pcwtb.18d46429253277c1,"reason=Pulled count=1 msg=Container image ""busybox:musl"" already present on machine"
0.4179,Event,ADDED,eval-conflicts-rho000-r3-068-pcwtb.18d4642926b9036f,reason=Created count=1 msg=Created container: task
0.4181,Event,ADDED,eval-conflicts-rho000-r3-068-pcwtb.18d4642932b79887,reason=Started count=1 msg=Started container task
0.4184,Event,ADDED,eval-conflicts-rho000-r3-068.18d464290b3948f6,reason=SuccessfulCreate count=1 msg=Created pod: eval-conflicts-rho000-r3-068-pcwtb
0.4188,Event,ADDED,eval-conflicts-rho000-r3-068.18d4642c4102b8ef,reason=Completed count=1 msg=Job completed
0.419,Event,ADDED,eval-conflicts-rho000-r3-069-s7bk8.18d464294764d99a,reason=Scheduled count=None msg=Successfully assigned compute/eval-conflicts-rho000-r3-069-s7bk8 to kind-worker3
0.4192,Event,ADDED,eval-conflicts-rho000-r3-069-s7bk8.18d46429629b2ca6,"reason=Pulled count=1 msg=Container image ""busybox:musl"" already present on machine"
0.4195,Event,ADDED,eval-conflicts-rho000-r3-069-s7bk8.18d4642963b100e0,reason=Created count=1 msg=Created container: task
0.4196,Event,ADDED,eval-conflicts-rho000-r3-069-s7bk8.18d464296c41688d,reason=Started count=1 msg=Started container task
0.4198,Event,ADDED,eval-conflicts-rho000-r3-069.18d4642946a276e9,reason=SuccessfulCreate count=1 msg=Created pod: eval-conflicts-rho000-r3-069-s7bk8
0.42,Event,ADDED,eval-conflicts-rho000-r3-069.18d4642c7a1b6e89,reason=Completed count=1 msg=Job completed
0.4206,Event,ADDED,eval-conflicts-rho000-r3-070-dwl28.18d464298342993c,reason=Scheduled count=None msg=Successfully assigned compute/eval-conflicts-rho000-r3-070-dwl28 to kind-worker3
0.4207,Event,ADDED,eval-conflicts-rho000-r3-070-dwl28.18d464299dd17d60,"reason=Pulled count=1 msg=Container image ""busybox:musl"" already present on machine"
0.4209,Event,ADDED,eval-conflicts-rho000-r3-070-dwl28.18d464299ee82cf3,reason=Created count=1 msg=Created container: task
0.4212,Event,ADDED,eval-conflicts-rho000-r3-070-dwl28.18d46429a0c1f158,reason=Started count=1 msg=Started container task
0.4214,Event,ADDED,eval-conflicts-rho000-r3-070.18d4642982a7a6e8,reason=SuccessfulCreate count=1 msg=Created pod: eval-conflicts-rho000-r3-070-dwl28
0.4216,Event,ADDED,eval-conflicts-rho000-r3-070.18d4642c7aad0864,reason=Completed count=1 msg=Job completed
0.4217,Event,ADDED,eval-conflicts-rho000-r3-071-h7n26.18d46429be37b42b,reason=Scheduled count=None msg=Successfully assigned compute/eval-conflicts-rho000-r3-071-h7n26 to kind-worker3
0.422,Event,ADDED,eval-conflicts-rho000-r3-071-h7n26.18d46429d86df4ed,"reason=Pulled count=1 msg=Container image ""busybox:musl"" already present on machine"
0.4223,Event,ADDED,eval-conflicts-rho000-r3-071-h7n26.18d46429d9789d66,reason=Created count=1 msg=Created container: task
0.4225,Event,ADDED,eval-conflicts-rho000-r3-071-h7n26.18d46429deaec8c5,reason=Started count=1 msg=Started container task
0.4229,Event,ADDED,eval-conflicts-rho000-r3-071.18d46429bdc87bd5,reason=SuccessfulCreate count=1 msg=Created pod: eval-conflicts-rho000-r3-071-h7n26
0.4231,Event,ADDED,eval-conflicts-rho000-r3-071.18d4642cf20851b7,reason=Completed count=1 msg=Job completed
0.4232,Event,ADDED,eval-conflicts-rho000-r3-072-z6kqf.18d46429fb3fddb7,reason=Scheduled count=None msg=Successfully assigned compute/eval-conflicts-rho000-r3-072-z6kqf to kind-worker3
0.4234,Event,ADDED,eval-conflicts-rho000-r3-072-z6kqf.18d4642a13e13485,"reason=Pulled count=1 msg=Container image ""busybox:musl"" already present on machine"
0.4238,Event,ADDED,eval-conflicts-rho000-r3-072-z6kqf.18d4642a14fe4d8a,reason=Created count=1 msg=Created container: task
0.4239,Event,ADDED,eval-conflicts-rho000-r3-072-z6kqf.18d4642a170ef06e,reason=Started count=1 msg=Started container task
0.4241,Event,ADDED,eval-conflicts-rho000-r3-072.18d46429faaed71b,reason=SuccessfulCreate count=1 msg=Created pod: eval-conflicts-rho000-r3-072-z6kqf
0.4243,Event,ADDED,eval-conflicts-rho000-r3-072.18d4642d2dad6226,reason=Completed count=1 msg=Job completed
0.4246,Event,ADDED,eval-conflicts-rho000-r3-073-rzmf7.18d4642a360bfcfc,reason=Scheduled count=None msg=Successfully assigned compute/eval-conflicts-rho000-r3-073-rzmf7 to kind-worker3
0.4248,Event,ADDED,eval-conflicts-rho000-r3-073-rzmf7.18d4642a5238b41f,"reason=Pulled count=1 msg=Container image ""busybox:musl"" already present on machine"
0.425,Event,ADDED,eval-conflicts-rho000-r3-073-rzmf7.18d4642a5475ca4b,reason=Created count=1 msg=Created container: task
0.4254,Event,ADDED,eval-conflicts-rho000-r3-073-rzmf7.18d4642a591ddbc0,reason=Started count=1 msg=Started container task
0.4256,Event,ADDED,eval-conflicts-rho000-r3-073.18d4642a356a36ec,reason=SuccessfulCreate count=1 msg=Created pod: eval-conflicts-rho000-r3-073-rzmf7
0.4258,Event,ADDED,eval-conflicts-rho000-r3-073.18d4642d69115a0f,reason=Completed count=1 msg=Job completed
0.4259,Event,ADDED,eval-conflicts-rho000-r3-074-j6b5p.18d4642a729548a4,reason=Scheduled count=None msg=Successfully assigned compute/eval-conflicts-rho000-r3-074-j6b5p to kind-worker5
0.4262,Event,ADDED,eval-conflicts-rho000-r3-074-j6b5p.18d4642a8cb78967,"reason=Pulled count=1 msg=Container image ""busybox:musl"" already present on machine"
0.4264,Event,ADDED,eval-conflicts-rho000-r3-074-j6b5p.18d4642a8dd8ccdc,reason=Created count=1 msg=Created container: task
0.4266,Event,ADDED,eval-conflicts-rho000-r3-074-j6b5p.18d4642a92f97092,reason=Started count=1 msg=Started container task
0.4271,Event,ADDED,eval-conflicts-rho000-r3-074.18d4642a7175038a,reason=SuccessfulCreate count=1 msg=Created pod: eval-conflicts-rho000-r3-074-j6b5p
0.4272,Event,ADDED,eval-conflicts-rho000-r3-074.18d4642dc1c8b1b6,reason=Completed count=1 msg=Job completed
0.4274,Event,ADDED,eval-conflicts-rho000-r3-075-j27vh.18d4642aaeadbc68,reason=Scheduled count=None msg=Successfully assigned compute/eval-conflicts-rho000-r3-075-j27vh to kind-worker5
0.4276,Event,ADDED,eval-conflicts-rho000-r3-075-j27vh.18d4642ac8da6409,"reason=Pulled count=1 msg=Container image ""busybox:musl"" already present on machine"
0.4279,Event,ADDED,eval-conflicts-rho000-r3-075-j27vh.18d4642aca012b94,reason=Created count=1 msg=Created container: task
0.4281,Event,ADDED,eval-conflicts-rho000-r3-075-j27vh.18d4642acc230486,reason=Started count=1 msg=Started container task
0.4283,Event,ADDED,eval-conflicts-rho000-r3-075.18d4642aad8582f1,reason=SuccessfulCreate count=1 msg=Created pod: eval-conflicts-rho000-r3-075-j27vh
0.4285,Event,ADDED,eval-conflicts-rho000-r3-075.18d4642dfdd51f94,reason=Completed count=1 msg=Job completed
0.4287,Event,ADDED,eval-conflicts-rho000-r3-076-vw4sp.18d4642ae9b4597d,reason=Scheduled count=None msg=Successfully assigned compute/eval-conflicts-rho000-r3-076-vw4sp to kind-worker5
0.4288,Event,ADDED,eval-conflicts-rho000-r3-076-vw4sp.18d4642b029a4259,"reason=Pulled count=1 msg=Container image ""busybox:musl"" already present on machine"
0.429,Event,ADDED,eval-conflicts-rho000-r3-076-vw4sp.18d4642b03bfe588,reason=Created count=1 msg=Created container: task
0.4292,Event,ADDED,eval-conflicts-rho000-r3-076-vw4sp.18d4642b07bd166c,reason=Started count=1 msg=Started container task
0.4294,Event,ADDED,eval-conflicts-rho000-r3-076.18d4642ae8d9204c,reason=SuccessfulCreate count=1 msg=Created pod: eval-conflicts-rho000-r3-076-vw4sp
0.4295,Event,ADDED,eval-conflicts-rho000-r3-076.18d4642e398f4938,reason=Completed count=1 msg=Job completed
0.4297,Event,ADDED,eval-conflicts-rho000-r3-077-dqzrx.18d4642b247aa1af,reason=Scheduled count=None msg=Successfully assigned compute/eval-conflicts-rho000-r3-077-dqzrx to kind-worker5
0.4299,Event,ADDED,eval-conflicts-rho000-r3-077-dqzrx.18d4642b3df4565d,"reason=Pulled count=1 msg=Container image ""busybox:musl"" already present on machine"
0.43,Event,ADDED,eval-conflicts-rho000-r3-077-dqzrx.18d4642b3f064955,reason=Created count=1 msg=Created container: task
0.4303,Event,ADDED,eval-conflicts-rho000-r3-077-dqzrx.18d4642b40f655f2,reason=Started count=1 msg=Started container task
0.4306,Event,ADDED,eval-conflicts-rho000-r3-077.18d4642b239e6ca5,reason=SuccessfulCreate count=1 msg=Created pod: eval-conflicts-rho000-r3-077-dqzrx
0.4309,Event,ADDED,eval-conflicts-rho000-r3-077.18d4642e7566e2fb,reason=Completed count=1 msg=Job completed
0.431,Event,ADDED,eval-conflicts-rho000-r3-078-65j22.18d4642b5faf4a04,reason=Scheduled count=None msg=Successfully assigned compute/eval-conflicts-rho000-r3-078-65j22 to kind-worker
0.4312,Event,ADDED,eval-conflicts-rho000-r3-078-65j22.18d4642b78754f06,"reason=Pulled count=1 msg=Container image ""busybox:musl"" already present on machine"
0.4315,Event,ADDED,eval-conflicts-rho000-r3-078-65j22.18d4642b797d02f9,reason=Created count=1 msg=Created container: task
0.4317,Event,ADDED,eval-conflicts-rho000-r3-078-65j22.18d4642b7b5cd96d,reason=Started count=1 msg=Started container task
0.4319,Event,ADDED,eval-conflicts-rho000-r3-078.18d4642b5f033267,reason=SuccessfulCreate count=1 msg=Created pod: eval-conflicts-rho000-r3-078-65j22
0.4321,Event,ADDED,eval-conflicts-rho000-r3-078.18d4642eacc141a8,reason=Completed count=1 msg=Job completed
0.4323,Event,ADDED,eval-conflicts-rho000-r3-079-qn2zn.18d4642b9bcccb76,reason=Scheduled count=None msg=Successfully assigned compute/eval-conflicts-rho000-r3-079-qn2zn to kind-worker
0.4325,Event,ADDED,eval-conflicts-rho000-r3-079-qn2zn.18d4642bb50def6e,"reason=Pulled count=1 msg=Container image ""busybox:musl"" already present on machine"
0.4327,Event,ADDED,eval-conflicts-rho000-r3-079-qn2zn.18d4642bb62ba09c,reason=Created count=1 msg=Created container: task
0.433,Event,ADDED,eval-conflicts-rho000-r3-079-qn2zn.18d4642bb839ade1,reason=Started count=1 msg=Started container task
0.4332,Event,ADDED,eval-conflicts-rho000-r3-079.18d4642b9ae9c55e,reason=SuccessfulCreate count=1 msg=Created pod: eval-conflicts-rho000-r3-079-qn2zn
0.4333,Event,ADDED,eval-conflicts-rho000-r3-079.18d4642ee87c5b2e,reason=Completed count=1 msg=Job completed
0.4335,Event,ADDED,eval-conflicts-rho000-r3-080-zpz8r.18d4642bd724a5f7,reason=Scheduled count=None msg=Successfully assigned compute/eval-conflicts-rho000-r3-080-zpz8r to kind-worker
0.4338,Event,ADDED,eval-conflicts-rho000-r3-080-zpz8r.18d4642bf0a0646b,"reason=Pulled count=1 msg=Container image ""busybox:musl"" already present on machine"
0.434,Event,ADDED,eval-conflicts-rho000-r3-080-zpz8r.18d4642bf1acac1f,reason=Created count=1 msg=Created container: task
0.4342,Event,ADDED,eval-conflicts-rho000-r3-080-zpz8r.18d4642bf6cb4ecd,reason=Started count=1 msg=Started container task
0.4344,Event,ADDED,eval-conflicts-rho000-r3-080.18d4642bd6261ef0,reason=SuccessfulCreate count=1 msg=Created pod: eval-conflicts-rho000-r3-080-zpz8r
0.4346,Event,ADDED,eval-conflicts-rho000-r3-080.18d4642f246a0ecb,reason=Completed count=1 msg=Job completed
0.4348,Event,ADDED,eval-conflicts-rho000-r3-081-bwpjj.18d4642c12edec5f,reason=Scheduled count=None msg=Successfully assigned compute/eval-conflicts-rho000-r3-081-bwpjj to kind-worker4
0.435,Event,ADDED,eval-conflicts-rho000-r3-081-bwpjj.18d4642c2cfed6fa,"reason=Pulled count=1 msg=Container image ""busybox:musl"" already present on machine"
0.4354,Event,ADDED,eval-conflicts-rho000-r3-081-bwpjj.18d4642c2e28f9c8,reason=Created count=1 msg=Created container: task
0.4355,Event,ADDED,eval-conflicts-rho000-r3-081-bwpjj.18d4642c304d062e,reason=Started count=1 msg=Started container task
0.4357,Event,ADDED,eval-conflicts-rho000-r3-081.18d4642c11ecec7f,reason=SuccessfulCreate count=1 msg=Created pod: eval-conflicts-rho000-r3-081-bwpjj
0.4359,Event,ADDED,eval-conflicts-rho000-r3-081.18d4642f471273ba,reason=Completed count=1 msg=Job completed
0.4361,Event,ADDED,eval-conflicts-rho000-r3-082-4fhbc.18d4642c4ea7a0dc,reason=Scheduled count=None msg=Successfully assigned compute/eval-conflicts-rho000-r3-082-4fhbc to kind-worker
0.4363,Event,ADDED,eval-conflicts-rho000-r3-082-4fhbc.18d4642c68769f2d,"reason=Pulled count=1 msg=Container image ""busybox:musl"" already present on machine"
0.4365,Event,ADDED,eval-conflicts-rho000-r3-082-4fhbc.18d4642c699d8f6a,reason=Created count=1 msg=Created container: task
0.4366,Event,ADDED,eval-conflicts-rho000-r3-082-4fhbc.18d4642c6bb85cc6,reason=Started count=1 msg=Started container task
0.4369,Event,ADDED,eval-conflicts-rho000-r3-082.18d4642c4d9db2f3,reason=SuccessfulCreate count=1 msg=Created pod: eval-conflicts-rho000-r3-082-4fhbc
0.4371,Event,ADDED,eval-conflicts-rho000-r3-082.18d4642f9c37a7a7,reason=Completed count=1 msg=Job completed
0.4373,Event,ADDED,eval-conflicts-rho000-r3-083-5546s.18d4642c8b1de137,reason=Scheduled count=None msg=Successfully assigned compute/eval-conflicts-rho000-r3-083-5546s to kind-worker
0.4375,Event,ADDED,eval-conflicts-rho000-r3-083-5546s.18d4642ca41b96b1,"reason=Pulled count=1 msg=Container image ""busybox:musl"" already present on machine"
0.4377,Event,ADDED,eval-conflicts-rho000-r3-083-5546s.18d4642ca52a1f51,reason=Created count=1 msg=Created container: task
0.4378,Event,ADDED,eval-conflicts-rho000-r3-083-5546s.18d4642ca7314048,reason=Started count=1 msg=Started container task
0.438,Event,ADDED,eval-conflicts-rho000-r3-083.18d4642c8a020488,reason=SuccessfulCreate count=1 msg=Created pod: eval-conflicts-rho000-r3-083-5546s
0.4383,Event,ADDED,eval-conflicts-rho000-r3-083.18d4642fd829ae92,reason=Completed count=1 msg=Job completed
0.4385,Event,ADDED,eval-conflicts-rho000-r3-084-2scws.18d4642cc628d5d5,reason=Scheduled count=None msg=Successfully assigned compute/eval-conflicts-rho000-r3-084-2scws to kind-worker4
0.4386,Event,ADDED,eval-conflicts-rho000-r3-084-2scws.18d4642cdf8144df,"reason=Pulled count=1 msg=Container image ""busybox:musl"" already present on machine"
0.4391,Event,ADDED,eval-conflicts-rho000-r3-084-2scws.18d4642ce0975bce,reason=Created count=1 msg=Created container: task
0.4392,Event,ADDED,eval-conflicts-rho000-r3-084-2scws.18d4642ce412f3ab,reason=Started count=1 msg=Started container task
0.4394,Event,ADDED,eval-conflicts-rho000-r3-084.18d4642cc5448680,reason=SuccessfulCreate count=1 msg=Created pod: eval-conflicts-rho000-r3-084-2scws
0.4396,Event,ADDED,eval-conflicts-rho000-r3-084.18d4642ffaaa4109,reason=Completed count=1 msg=Job completed
0.4399,Event,ADDED,eval-conflicts-rho000-r3-085-wwzwb.18d4642d0159a66a,reason=Scheduled count=None msg=Successfully assigned compute/eval-conflicts-rho000-r3-085-wwzwb to kind-worker4
0.44,Event,ADDED,eval-conflicts-rho000-r3-085-wwzwb.18d4642d19cde7a4,"reason=Pulled count=1 msg=Container image ""busybox:musl"" already present on machine"
0.4402,Event,ADDED,eval-conflicts-rho000-r3-085-wwzwb.18d4642d1ae9adc5,reason=Created count=1 msg=Created container: task
0.4404,Event,ADDED,eval-conflicts-rho000-r3-085-wwzwb.18d4642d1ecb6e63,reason=Started count=1 msg=Started container task
0.4406,Event,ADDED,eval-conflicts-rho000-r3-085.18d4642d00779c79,reason=SuccessfulCreate count=1 msg=Created pod: eval-conflicts-rho000-r3-085-wwzwb
0.4408,Event,ADDED,eval-conflicts-rho000-r3-085.18d4643036a2ec3a,reason=Completed count=1 msg=Job completed
0.4409,Event,ADDED,eval-conflicts-rho000-r3-086-n2txb.18d4642d3d3e8358,reason=Scheduled count=None msg=Successfully assigned compute/eval-conflicts-rho000-r3-086-n2txb to kind-worker4
0.4412,Event,ADDED,eval-conflicts-rho000-r3-086-n2txb.18d4642d55b71ef1,"reason=Pulled count=1 msg=Container image ""busybox:musl"" already present on machine"
0.4414,Event,ADDED,eval-conflicts-rho000-r3-086-n2txb.18d4642d56c90328,reason=Created count=1 msg=Created container: task
0.4416,Event,ADDED,eval-conflicts-rho000-r3-086-n2txb.18d4642d58baa55d,reason=Started count=1 msg=Started container task
0.4418,Event,ADDED,eval-conflicts-rho000-r3-086.18d4642d3c3bd338,reason=SuccessfulCreate count=1 msg=Created pod: eval-conflicts-rho000-r3-086-n2txb
0.4421,Event,ADDED,eval-conflicts-rho000-r3-086.18d464307253e490,reason=Completed count=1 msg=Job completed
0.4422,Event,ADDED,eval-conflicts-rho000-r3-087-s5jdj.18d4642d7859235e,reason=Scheduled count=None msg=Successfully assigned compute/eval-conflicts-rho000-r3-087-s5jdj to kind-worker
0.4424,Event,ADDED,eval-conflicts-rho000-r3-087-s5jdj.18d4642d90f1c1c7,"reason=Pulled count=1 msg=Container image ""busybox:musl"" already present on machine"
0.4426,Event,ADDED,eval-conflicts-rho000-r3-087-s5jdj.18d4642d92052506,reason=Created count=1 msg=Created container: task
0.4429,Event,ADDED,eval-conflicts-rho000-r3-087-s5jdj.18d4642d941c5a40,reason=Started count=1 msg=Started container task
0.4431,Event,ADDED,eval-conflicts-rho000-r3-087.18d4642d776d7792,reason=SuccessfulCreate count=1 msg=Created pod: eval-conflicts-rho000-r3-087-s5jdj
0.4433,Event,ADDED,eval-conflicts-rho000-r3-087.18d46430c72950e9,reason=Completed count=1 msg=Job completed
0.4435,Event,ADDED,eval-conflicts-rho000-r3-088-jhcm6.18d4642db4556945,reason=Scheduled count=None msg=Successfully assigned compute/eval-conflicts-rho000-r3-088-jhcm6 to kind-worker3
0.4437,Event,ADDED,eval-conflicts-rho000-r3-088-jhcm6.18d4642dcdb13a9e,"reason=Pulled count=1 msg=Container image ""busybox:musl"" already present on machine"
0.4439,Event,ADDED,eval-conflicts-rho000-r3-088-jhcm6.18d4642dcec2430b,reason=Created count=1 msg=Created container: task
0.4441,Event,ADDED,eval-conflicts-rho000-r3-088-jhcm6.18d4642dd0c29368,reason=Started count=1 msg=Started container task
0.4443,Event,ADDED,eval-conflicts-rho000-r3-088.18d4642db3821bb5,reason=SuccessfulCreate count=1 msg=Created pod: eval-conflicts-rho000-r3-088-jhcm6
0.4445,Event,ADDED,eval-conflicts-rho000-r3-088.18d46430e9c29f87,reason=Completed count=1 msg=Job completed
0.4446,Event,ADDED,eval-conflicts-rho000-r3-089-4j9zb.18d4642defb7136b,reason=Scheduled count=None msg=Successfully assigned compute/eval-conflicts-rho000-r3-089-4j9zb to kind-worker3
0.4448,Event,ADDED,eval-conflicts-rho000-r3-089-4j9zb.18d4642e0910aaea,"reason=Pulled count=1 msg=Container image ""busybox:musl"" already present on machine"
0.4451,Event,ADDED,eval-conflicts-rho000-r3-089-4j9zb.18d4642e0a19c952,reason=Created count=1 msg=Created container: task
0.4453,Event,ADDED,eval-conflicts-rho000-r3-089-4j9zb.18d4642e0d01f313,reason=Started count=1 msg=Started container task
0.4455,Event,ADDED,eval-conflicts-rho000-r3-089.18d4642deec5fd8f,reason=SuccessfulCreate count=1 msg=Created pod: eval-conflicts-rho000-r3-089-4j9zb
0.4457,Event,ADDED,eval-conflicts-rho000-r3-089.18d4643125ace385,reason=Completed count=1 msg=Job completed
0.4459,Event,ADDED,eval-conflicts-rho000-r3-090-shw8g.18d4642e2b0f83f7,reason=Scheduled count=None msg=Successfully assigned compute/eval-conflicts-rho000-r3-090-shw8g to kind-worker2
0.4461,Event,ADDED,eval-conflicts-rho000-r3-090-shw8g.18d4642e44c108b2,"reason=Pulled count=1 msg=Container image ""busybox:musl"" already present on machine"
0.4463,Event,ADDED,eval-conflicts-rho000-r3-090-shw8g.18d4642e45cc812d,reason=Created count=1 msg=Created container: task
0.4466,Event,ADDED,eval-conflicts-rho000-r3-090-shw8g.18d4642e47c1ca04,reason=Started count=1 msg=Started container task
0.4468,Event,ADDED,eval-conflicts-rho000-r3-090.18d4642e2a5dd7d0,reason=SuccessfulCreate count=1 msg=Created pod: eval-conflicts-rho000-r3-090-shw8g
0.447,Event,ADDED,eval-conflicts-rho000-r3-090.18d4643127abcf47,reason=Completed count=1 msg=Job completed
0.4472,Event,ADDED,eval-conflicts-rho000-r3-091-s6h46.18d4642e67069ae6,reason=Scheduled count=None msg=Successfully assigned compute/eval-conflicts-rho000-r3-091-s6h46 to kind-worker2
0.4474,Event,ADDED,eval-conflicts-rho000-r3-091-s6h46.18d4642e803f8e25,"reason=Pulled count=1 msg=Container image ""busybox:musl"" already present on machine"
0.4475,Event,ADDED,eval-conflicts-rho000-r3-091-s6h46.18d4642e8154f554,reason=Created count=1 msg=Created container: task
0.4477,Event,ADDED,eval-conflicts-rho000-r3-091-s6h46.18d4642e83431795,reason=Started count=1 msg=Started container task
0.448,Event,ADDED,eval-conflicts-rho000-r3-091.18d4642e660c5459,reason=SuccessfulCreate count=1 msg=Created pod: eval-conflicts-rho000-r3-091-s6h46
0.4482,Event,ADDED,eval-conflicts-rho000-r3-091.18d464319f1dcfbd,reason=Completed count=1 msg=Job completed
0.4483,Event,ADDED,eval-conflicts-rho000-r3-092-dj5xk.18d4642ea2886092,reason=Scheduled count=None msg=Successfully assigned compute/eval-conflicts-rho000-r3-092-dj5xk to kind-worker2
0.4485,Event,ADDED,eval-conflicts-rho000-r3-092-dj5xk.18d4642ebb8e5b97,"reason=Pulled count=1 msg=Container image ""busybox:musl"" already present on machine"
0.4488,Event,ADDED,eval-conflicts-rho000-r3-092-dj5xk.18d4642ebc96d52d,reason=Created count=1 msg=Created container: task
0.449,Event,ADDED,eval-conflicts-rho000-r3-092-dj5xk.18d4642ebe9a4095,reason=Started count=1 msg=Started container task
0.4491,Event,ADDED,eval-conflicts-rho000-r3-092.18d4642ea197ac35,reason=SuccessfulCreate count=1 msg=Created pod: eval-conflicts-rho000-r3-092-dj5xk
0.4494,Event,ADDED,eval-conflicts-rho000-r3-092.18d46431dafd416c,reason=Completed count=1 msg=Job completed
0.4495,Event,ADDED,eval-conflicts-rho000-r3-093-4mzxj.18d4642ede8a5253,reason=Scheduled count=None msg=Successfully assigned compute/eval-conflicts-rho000-r3-093-4mzxj to kind-worker2
0.4497,Event,ADDED,eval-conflicts-rho000-r3-093-4mzxj.18d4642ef6b7e29d,"reason=Pulled count=1 msg=Container image ""busybox:musl"" already present on machine"
0.4498,Event,ADDED,eval-conflicts-rho000-r3-093-4mzxj.18d4642ef7f551b3,reason=Created count=1 msg=Created container: task
0.4501,Event,ADDED,eval-conflicts-rho000-r3-093-4mzxj.18d4642efc574d63,reason=Started count=1 msg=Started container task
0.4503,Event,ADDED,eval-conflicts-rho000-r3-093.18d4642eddbb1c99,reason=SuccessfulCreate count=1 msg=Created pod: eval-conflicts-rho000-r3-093-4mzxj
0.4506,Event,ADDED,eval-conflicts-rho000-r3-093.18d464321716bc1f,reason=Completed count=1 msg=Job completed
0.4508,Event,ADDED,eval-conflicts-rho000-r3-094-hh9nl.18d4642f19965484,reason=Scheduled count=None msg=Successfully assigned compute/eval-conflicts-rho000-r3-094-hh9nl to kind-worker2
0.4512,Event,ADDED,eval-conflicts-rho000-r3-094-hh9nl.18d4642f3254936d,"reason=Pulled count=1 msg=Container image ""busybox:musl"" already present on machine"
0.4514,Event,ADDED,eval-conflicts-rho000-r3-094-hh9nl.18d4642f3397c25c,reason=Created count=1 msg=Created container: task
0.4515,Event,ADDED,eval-conflicts-rho000-r3-094-hh9nl.18d4642f3573f359,reason=Started count=1 msg=Started container task
0.4519,Event,ADDED,eval-conflicts-rho000-r3-094.18d4642f18b8b6dc,reason=SuccessfulCreate count=1 msg=Created pod: eval-conflicts-rho000-r3-094-hh9nl
0.4522,Event,ADDED,eval-conflicts-rho000-r3-094.18d4643252cf5ceb,reason=Completed count=1 msg=Job completed
0.4524,Event,ADDED,eval-conflicts-rho000-r3-095-nfz9b.18d4642f553d6ed0,reason=Scheduled count=None msg=Successfully assigned compute/eval-conflicts-rho000-r3-095-nfz9b to kind-worker5
0.4527,Event,ADDED,eval-conflicts-rho000-r3-095-nfz9b.18d4642f6ed4c8a6,"reason=Pulled count=1 msg=Container image ""busybox:musl"" already present on machine"
0.4531,Event,ADDED,eval-conflicts-rho000-r3-095-nfz9b.18d4642f701decb2,reason=Created count=1 msg=Created container: task
0.4533,Event,ADDED,eval-conflicts-rho000-r3-095-nfz9b.18d4642f721d0c38,reason=Started count=1 msg=Started container task
0.4534,Event,ADDED,eval-conflicts-rho000-r3-095.18d4642f5466a943,reason=SuccessfulCreate count=1 msg=Created pod: eval-conflicts-rho000-r3-095-nfz9b
0.4537,Event,ADDED,eval-conflicts-rho000-r3-095.18d46432a9d1e80d,reason=Completed count=1 msg=Job completed
0.4539,Event,ADDED,eval-conflicts-rho000-r3-096-h7js5.18d4642f91183f17,reason=Scheduled count=None msg=Successfully assigned compute/eval-conflicts-rho000-r3-096-h7js5 to kind-worker5
0.4541,Event,ADDED,eval-conflicts-rho000-r3-096-h7js5.18d4642faa01311b,"reason=Pulled count=1 msg=Container image ""busybox:musl"" already present on machine"
0.4543,Event,ADDED,eval-conflicts-rho000-r3-096-h7js5.18d4642fab19632d,reason=Created count=1 msg=Created container: task
0.4545,Event,ADDED,eval-conflicts-rho000-r3-096-h7js5.18d4642fad179f62,reason=Started count=1 msg=Started container task
0.4547,Event,ADDED,eval-conflicts-rho000-r3-096.18d4642f901315cc,reason=SuccessfulCreate count=1 msg=Created pod: eval-conflicts-rho000-r3-096-h7js5
0.4548,Event,ADDED,eval-conflicts-rho000-r3-096.18d46432e5a387d4,reason=Completed count=1 msg=Job completed
0.455,Event,ADDED,eval-conflicts-rho000-r3-097-zgd7h.18d4642fcce6bb16,reason=Scheduled count=None msg=Successfully assigned compute/eval-conflicts-rho000-r3-097-zgd7h to kind-worker5
0.4552,Event,ADDED,eval-conflicts-rho000-r3-097-zgd7h.18d4642fe5e0d329,"reason=Pulled count=1 msg=Container image ""busybox:musl"" already present on machine"
0.4553,Event,ADDED,eval-conflicts-rho000-r3-097-zgd7h.18d4642fe6fe5d5b,reason=Created count=1 msg=Created container: task
0.4555,Event,ADDED,eval-conflicts-rho000-r3-097-zgd7h.18d4642fe93a52fc,reason=Started count=1 msg=Started container task
0.4557,Event,ADDED,eval-conflicts-rho000-r3-097.18d4642fcb97eaa3,reason=SuccessfulCreate count=1 msg=Created pod: eval-conflicts-rho000-r3-097-zgd7h
0.4558,Event,ADDED,eval-conflicts-rho000-r3-097.18d4643321846252,reason=Completed count=1 msg=Job completed
0.456,Event,ADDED,eval-conflicts-rho000-r3-098-kfcj6.18d4643007fad3d6,reason=Scheduled count=None msg=Successfully assigned compute/eval-conflicts-rho000-r3-098-kfcj6 to kind-worker5
0.4562,Event,ADDED,eval-conflicts-rho000-r3-098-kfcj6.18d46430208a7bbe,"reason=Pulled count=1 msg=Container image ""busybox:musl"" already present on machine"
0.4566,Event,ADDED,eval-conflicts-rho000-r3-098-kfcj6.18d4643021b32378,reason=Created count=1 msg=Created container: task
0.4567,Event,ADDED,eval-conflicts-rho000-r3-098-kfcj6.18d4643025a34d90,reason=Started count=1 msg=Started container task
0.4569,Event,ADDED,eval-conflicts-rho000-r3-098.18d4643007282106,reason=SuccessfulCreate count=1 msg=Created pod: eval-conflicts-rho000-r3-098-kfcj6
0.4571,Event,ADDED,eval-conflicts-rho000-r3-098.18d464335d718d97,reason=Completed count=1 msg=Job completed
0.4574,Event,ADDED,eval-conflicts-rho000-r3-099-vqxk2.18d4643043eb6091,reason=Scheduled count=None msg=Successfully assigned compute/eval-conflicts-rho000-r3-099-vqxk2 to kind-worker5
0.4576,Event,ADDED,eval-conflicts-rho000-r3-099-vqxk2.18d464305d07d3e0,"reason=Pulled count=1 msg=Container image ""busybox:musl"" already present on machine"
0.4578,Event,ADDED,eval-conflicts-rho000-r3-099-vqxk2.18d464305e1ad202,reason=Created count=1 msg=Created container: task
0.4581,Event,ADDED,eval-conflicts-rho000-r3-099-vqxk2.18d46430608985ef,reason=Started count=1 msg=Started container task
0.4584,Event,ADDED,eval-conflicts-rho000-r3-099.18d4643043022221,reason=SuccessfulCreate count=1 msg=Created pod: eval-conflicts-rho000-r3-099-vqxk2
0.4586,Event,ADDED,eval-conflicts-rho000-r3-099.18d4643399b1ac67,reason=Completed count=1 msg=Job completed
0.4587,Event,ADDED,eval-conflicts-rho000-r4-000-cf4rm.18d46438c7e3eacc,reason=Scheduled count=None msg=Successfully assigned compute/eval-conflicts-rho000-r4-000-cf4rm to kind-worker2
0.459,Event,ADDED,eval-conflicts-rho000-r4-000-cf4rm.18d46438e09a23ce,"reason=Pulled count=1 msg=Container image ""busybox:musl"" already present on machine"
0.4592,Event,ADDED,eval-conflicts-rho000-r4-000-cf4rm.18d46438e1faaeb8,reason=Created count=1 msg=Created container: task
0.4594,Event,ADDED,eval-conflicts-rho000-r4-000-cf4rm.18d46438e4048dc8,reason=Started count=1 msg=Started container task
0.4596,Event,ADDED,eval-conflicts-rho000-r4-000.18d46438c6dfb13b,reason=SuccessfulCreate count=1 msg=Created pod: eval-conflicts-rho000-r4-000-cf4rm
0.4598,Event,ADDED,eval-conflicts-rho000-r4-000.18d4643c20813f9b,reason=Completed count=1 msg=Job completed
0.46,Event,ADDED,eval-conflicts-rho000-r4-001-p6pc6.18d46439013e85e0,reason=Scheduled count=None msg=Successfully assigned compute/eval-conflicts-rho000-r4-001-p6pc6 to kind-worker
0.4601,Event,ADDED,eval-conflicts-rho000-r4-001-p6pc6.18d464391a3e7653,"reason=Pulled count=1 msg=Container image ""busybox:musl"" already present on machine"
0.4603,Event,ADDED,eval-conflicts-rho000-r4-001-p6pc6.18d464391cfd218d,reason=Created count=1 msg=Created container: task
0.4605,Event,ADDED,eval-conflicts-rho000-r4-001-p6pc6.18d46439212ec4c7,reason=Started count=1 msg=Started container task
0.4607,Event,ADDED,eval-conflicts-rho000-r4-001.18d4643900267408,reason=SuccessfulCreate count=1 msg=Created pod: eval-conflicts-rho000-r4-001-p6pc6
0.4608,Event,ADDED,eval-conflicts-rho000-r4-001.18d4643c36e27ab5,reason=Completed count=1 msg=Job completed
0.461,Event,ADDED,eval-conflicts-rho000-r4-002-9snmd.18d464393d823273,reason=Scheduled count=None msg=Successfully assigned compute/eval-conflicts-rho000-r4-002-9snmd to kind-worker
0.4612,Event,ADDED,eval-conflicts-rho000-r4-002-9snmd.18d4643956d705ed,"reason=Pulled count=1 msg=Container image ""busybox:musl"" already present on machine"
0.4613,Event,ADDED,eval-conflicts-rho000-r4-002-9snmd.18d4643957ef87e5,reason=Created count=1 msg=Created container: task
0.4652,Event,ADDED,eval-conflicts-rho000-r4-002-9snmd.18d4643959f55657,reason=Started count=1 msg=Started container task
0.4655,Event,ADDED,eval-conflicts-rho000-r4-002.18d464393c59d83c,reason=SuccessfulCreate count=1 msg=Created pod: eval-conflicts-rho000-r4-002-9snmd
0.4657,Event,ADDED,eval-conflicts-rho000-r4-002.18d4643c72d2791c,reason=Completed count=1 msg=Job completed
0.4658,Event,ADDED,eval-conflicts-rho000-r4-003-lvlql.18d4643978894ec6,reason=Scheduled count=None msg=Successfully assigned compute/eval-conflicts-rho000-r4-003-lvlql to kind-worker5
0.4662,Event,ADDED,eval-conflicts-rho000-r4-003-lvlql.18d464399224916c,"reason=Pulled count=1 msg=Container image ""busybox:musl"" already present on machine"
0.4664,Event,ADDED,eval-conflicts-rho000-r4-003-lvlql.18d46439932bb6e3,reason=Created count=1 msg=Created container: task
0.4666,Event,ADDED,eval-conflicts-rho000-r4-003-lvlql.18d4643995688101,reason=Started count=1 msg=Started container task
0.4668,Event,ADDED,eval-conflicts-rho000-r4-003.18d4643977c22a3e,reason=SuccessfulCreate count=1 msg=Created pod: eval-conflicts-rho000-r4-003-lvlql
0.4672,Event,ADDED,eval-conflicts-rho000-r4-003.18d4643cb5ad7071,reason=Completed count=1 msg=Job completed
0.4674,Event,ADDED,eval-conflicts-rho000-r4-004-rzjrd.18d46439b4d34e71,reason=Scheduled count=None msg=Successfully assigned compute/eval-conflicts-rho000-r4-004-rzjrd to kind-worker5
0.4676,Event,ADDED,eval-conflicts-rho000-r4-004-rzjrd.18d46439ce5e9b36,"reason=Pulled count=1 msg=Container image ""busybox:musl"" already present on machine"
0.4678,Event,ADDED,eval-conflicts-rho000-r4-004-rzjrd.18d46439cf693722,reason=Created count=1 msg=Created container: task
0.4679,Event,ADDED,eval-conflicts-rho000-r4-004-rzjrd.18d46439d1339168,reason=Started count=1 msg=Started container task
0.4681,Event,ADDED,eval-conflicts-rho000-r4-004.18d46439b3da31ae,reason=SuccessfulCreate count=1 msg=Created pod: eval-conflicts-rho000-r4-004-rzjrd
0.4684,Event,ADDED,eval-conflicts-rho000-r4-004.18d4643cf0bf71d4,reason=Completed count=1 msg=Job completed
0.4686,Event,ADDED,eval-conflicts-rho000-r4-005-5vnxw.18d46439efd5bf9a,reason=Scheduled count=None msg=Successfully assigned compute/eval-conflicts-rho000-r4-005-5vnxw to kind-worker5
0.4688,Event,ADDED,eval-conflicts-rho000-r4-005-5vnxw.18d4643a0a29f836,"reason=Pulled count=1 msg=Container image ""busybox:musl"" already present on machine"
0.469,Event,ADDED,eval-conflicts-rho000-r4-005-5vnxw.18d4643a0b3fadb0,reason=Created count=1 msg=Created container: task
0.4691,Event,ADDED,eval-conflicts-rho000-r4-005-5vnxw.18d4643a0fb02aa1,reason=Started count=1 msg=Started container task
0.4693,Event,ADDED,eval-conflicts-rho000-r4-005.18d46439eefd646e,reason=SuccessfulCreate count=1 msg=Created pod: eval-conflicts-rho000-r4-005-5vnxw
0.4695,Event,ADDED,eval-conflicts-rho000-r4-005.18d4643d2ce118f2,reason=Completed count=1 msg=Job completed
0.4696,Event,ADDED,eval-conflicts-rho000-r4-006-65gwg.18d4643a2b6f042a,reason=Scheduled count=None msg=Successfully assigned compute/eval-conflicts-rho000-r4-006-65gwg to kind-worker4
0.4698,Event,ADDED,eval-conflicts-rho000-r4-006-65gwg.18d4643a461f5e8a,"reason=Pulled count=1 msg=Container image ""busybox:musl"" already present on machine"
0.4701,Event,ADDED,eval-conflicts-rho000-r4-006-65gwg.18d4643a47370bc4,reason=Created count=1 msg=Created container: task
0.4705,Event,ADDED,eval-conflicts-rho000-r4-006-65gwg.18d4643a4c36d7b2,reason=Started count=1 msg=Started container task
0.4709,Event,ADDED,eval-conflicts-rho000-r4-006.18d4643a2abd1907,reason=SuccessfulCreate count=1 msg=Created pod: eval-conflicts-rho000-r4-006-65gwg
0.4713,Event,ADDED,eval-conflicts-rho000-r4-006.18d4643d837dbfbd,reason=Completed count=1 msg=Job completed
0.4714,Event,ADDED,eval-conflicts-rho000-r4-007-47ps5.18d4643a66a184aa,reason=Scheduled count=None msg=Successfully assigned compute/eval-conflicts-rho000-r4-007-47ps5 to kind-worker5
0.4716,Event,ADDED,eval-conflicts-rho000-r4-007-47ps5.18d4643a803c7232,"reason=Pulled count=1 msg=Container image ""busybox:musl"" already present on machine"
0.4719,Event,ADDED,eval-conflicts-rho000-r4-007-47ps5.18d4643a81574807,reason=Created count=1 msg=Created container: task
0.472,Event,ADDED,eval-conflicts-rho000-r4-007-47ps5.18d4643a8369ebb8,reason=Started count=1 msg=Started container task
0.4722,Event,ADDED,eval-conflicts-rho000-r4-007.18d4643a65bb4f7f,reason=SuccessfulCreate count=1 msg=Created pod: eval-conflicts-rho000-r4-007-47ps5
0.4724,Event,ADDED,eval-conflicts-rho000-r4-007.18d4643da4978e4a,reason=Completed count=1 msg=Job completed
0.4725,Event,ADDED,eval-conflicts-rho000-r4-008-24zqn.18d4643aa2e09307,reason=Scheduled count=None msg=Successfully assigned compute/eval-conflicts-rho000-r4-008-24zqn to kind-worker4
0.4727,Event,ADDED,eval-conflicts-rho000-r4-008-24zqn.18d4643abc8230a9,"reason=Pulled count=1 msg=Container image ""busybox:musl"" already present on machine"
0.4729,Event,ADDED,eval-conflicts-rho000-r4-008-24zqn.18d4643abd9a6aab,reason=Created count=1 msg=Created container: task
0.473,Event,ADDED,eval-conflicts-rho000-r4-008-24zqn.18d4643abfae0d89,reason=Started count=1 msg=Started container task
0.4732,Event,ADDED,eval-conflicts-rho000-r4-008.18d4643aa1f034ab,reason=SuccessfulCreate count=1 msg=Created pod: eval-conflicts-rho000-r4-008-24zqn
0.4734,Event,ADDED,eval-conflicts-rho000-r4-008.18d4643dfae20c00,reason=Completed count=1 msg=Job completed
0.4736,Event,ADDED,eval-conflicts-rho000-r4-009-k2hhq.18d4643addf6c2c8,reason=Scheduled count=None msg=Successfully assigned compute/eval-conflicts-rho000-r4-009-k2hhq to kind-worker4
0.4739,Event,ADDED,eval-conflicts-rho000-r4-009-k2hhq.18d4643af84a27b1,"reason=Pulled count=1 msg=Container image ""busybox:musl"" already present on machine"
0.474,Event,ADDED,eval-conflicts-rho000-r4-009-k2hhq.18d4643afa1ad5ef,reason=Created count=1 msg=Created container: task
0.4743,Event,ADDED,eval-conflicts-rho000-r4-009-k2hhq.18d4643afd9e13d8,reason=Started count=1 msg=Started container task
0.4745,Event,ADDED,eval-conflicts-rho000-r4-009.18d4643adcf25c9c,reason=SuccessfulCreate count=1 msg=Created pod: eval-conflicts-rho000-r4-009-k2hhq
0.475,Event,ADDED,eval-conflicts-rho000-r4-009.18d4643e36af234e,reason=Completed count=1 msg=Job completed
0.4752,Event,ADDED,eval-conflicts-rho000-r4-010-w6skr.18d4643b198e0fd6,reason=Scheduled count=None msg=Successfully assigned compute/eval-conflicts-rho000-r4-010-w6skr to kind-worker4
0.4754,Event,ADDED,eval-conflicts-rho000-r4-010-w6skr.18d4643b32a87e8e,"reason=Pulled count=1 msg=Container image ""busybox:musl"" already present on machine"
0.4757,Event,ADDED,eval-conflicts-rho000-r4-010-w6skr.18d4643b33bf3f6d,reason=Created count=1 msg=Created container: task
0.4758,Event,ADDED,eval-conflicts-rho000-r4-010-w6skr.18d4643b35e38a06,reason=Started count=1 msg=Started container task
0.476,Event,ADDED,eval-conflicts-rho000-r4-010.18d4643b18e51403,reason=SuccessfulCreate count=1 msg=Created pod: eval-conflicts-rho000-r4-010-w6skr
0.4762,Event,ADDED,eval-conflicts-rho000-r4-010.18d4643e7378b86a,reason=Completed count=1 msg=Job completed
0.4765,Event,ADDED,eval-conflicts-rho000-r4-011-sstpd.18d4643b555c5f2e,reason=Scheduled count=None msg=Successfully assigned compute/eval-conflicts-rho000-r4-011-sstpd to kind-worker3
0.4767,Event,ADDED,eval-conflicts-rho000-r4-011-sstpd.18d4643b6f4fed2e,"reason=Pulled count=1 msg=Container image ""busybox:musl"" already present on machine"
0.4769,Event,ADDED,eval-conflicts-rho000-r4-011-sstpd.18d4643b7071d9bf,reason=Created count=1 msg=Created container: task
0.477,Event,ADDED,eval-conflicts-rho000-r4-011-sstpd.18d4643b75a99a55,reason=Started count=1 msg=Started container task
0.4773,Event,ADDED,eval-conflicts-rho000-r4-011.18d4643b54944815,reason=SuccessfulCreate count=1 msg=Created pod: eval-conflicts-rho000-r4-011-sstpd
0.4775,Event,ADDED,eval-conflicts-rho000-r4-011.18d4643eae61731e,reason=Completed count=1 msg=Job completed
0.4777,Event,ADDED,eval-conflicts-rho000-r4-012-ctxhh.18d4643b90e404b5,reason=Scheduled count=None msg=Successfully assigned compute/eval-conflicts-rho000-r4-012-ctxhh to kind-worker3
0.478,Event,ADDED,eval-conflicts-rho000-r4-012-ctxhh.18d4643bae6fede4,"reason=Pulled count=1 msg=Container image ""busybox:musl"" already present on machine"
0.4783,Event,ADDED,eval-conflicts-rho000-r4-012-ctxhh.18d4643bafc33666,reason=Created count=1 msg=Created container: task
0.4785,Event,ADDED,eval-conflicts-rho000-r4-012-ctxhh.18d4643bb328d167,reason=Started count=1 msg=Started container task
0.4786,Event,ADDED,eval-conflicts-rho000-r4-012.18d4643b8fe86286,reason=SuccessfulCreate count=1 msg=Created pod: eval-conflicts-rho000-r4-012-ctxhh
0.4789,Event,ADDED,eval-conflicts-rho000-r4-012.18d4643ee9c76440,reason=Completed count=1 msg=Job completed
0.4791,Event,ADDED,eval-conflicts-rho000-r4-013-vlcpw.18d4643bcbe0895b,reason=Scheduled count=None msg=Successfully assigned compute/eval-conflicts-rho000-r4-013-vlcpw to kind-worker4
0.4793,Event,ADDED,eval-conflicts-rho000-r4-013-vlcpw.18d4643be58ba509,"reason=Pulled count=1 msg=Container image ""busybox:musl"" already present on machine"
0.4794,Event,ADDED,eval-conflicts-rho000-r4-013-vlcpw.18d4643be69c7475,reason=Created count=1 msg=Created container: task
0.4799,Event,ADDED,eval-conflicts-rho000-r4-013-vlcpw.18d4643beb127cad,reason=Started count=1 msg=Started container task
0.4801,Event,ADDED,eval-conflicts-rho000-r4-013.18d4643bcb5b9871,reason=SuccessfulCreate count=1 msg=Created pod: eval-conflicts-rho000-r4-013-vlcpw
0.4803,Event,ADDED,eval-conflicts-rho000-r4-013.18d4643f25f70944,reason=Completed count=1 msg=Job completed
0.4806,Event,ADDED,eval-conflicts-rho000-r4-014-xtmnx.18d4643c079515e2,reason=Scheduled count=None msg=Successfully assigned compute/eval-conflicts-rho000-r4-014-xtmnx to kind-worker4
0.4808,Event,ADDED,eval-conflicts-rho000-r4-014-xtmnx.18d4643c2147e769,"reason=Pulled count=1 msg=Container image ""busybox:musl"" already present on machine"
0.481,Event,ADDED,eval-conflicts-rho000-r4-014-xtmnx.18d4643c2265a517,reason=Created count=1 msg=Created container: task
0.4812,Event,ADDED,eval-conflicts-rho000-r4-014-xtmnx.18d4643c2475e8ae,reason=Started count=1 msg=Started container task
0.4816,Event,ADDED,eval-conflicts-rho000-r4-014.18d4643c07011de4,reason=SuccessfulCreate count=1 msg=Created pod: eval-conflicts-rho000-r4-014-xtmnx
0.4818,Event,ADDED,eval-conflicts-rho000-r4-014.18d4643f61f4e606,reason=Completed count=1 msg=Job completed
0.4819,Event,ADDED,eval-conflicts-rho000-r4-015-xzr6c.18d4643c437bf535,reason=Scheduled count=None msg=Successfully assigned compute/eval-conflicts-rho000-r4-015-xzr6c to kind-worker2
0.4823,Event,ADDED,eval-conflicts-rho000-r4-015-xzr6c.18d4643c5d158a0a,"reason=Pulled count=1 msg=Container image ""busybox:musl"" already present on machine"
0.4825,Event,ADDED,eval-conflicts-rho000-r4-015-xzr6c.18d4643c5e349fc5,reason=Created count=1 msg=Created container: task
0.4827,Event,ADDED,eval-conflicts-rho000-r4-015-xzr6c.18d4643c6069ffbe,reason=Started count=1 msg=Started container task
0.4829,Event,ADDED,eval-conflicts-rho000-r4-015.18d4643c430b7d6a,reason=SuccessfulCreate count=1 msg=Created pod: eval-conflicts-rho000-r4-015-xzr6c
0.4832,Event,ADDED,eval-conflicts-rho000-r4-015.18d4643f9fbee7b7,reason=Completed count=1 msg=Job completed
0.4834,Event,ADDED,eval-conflicts-rho000-r4-016-7cs7h.18d4643c7f026ee3,reason=Scheduled count=None msg=Successfully assigned compute/eval-conflicts-rho000-r4-016-7cs7h to kind-worker2
0.4835,Event,ADDED,eval-conflicts-rho000-r4-016-7cs7h.18d4643c982fa76f,"reason=Pulled count=1 msg=Container image ""busybox:musl"" already present on machine"
0.4837,Event,ADDED,eval-conflicts-rho000-r4-016-7cs7h.18d4643c9956a88e,reason=Created count=1 msg=Created container: task
0.484,Event,ADDED,eval-conflicts-rho000-r4-016-7cs7h.18d4643c9b5c9083,reason=Started count=1 msg=Started container task
0.4842,Event,ADDED,eval-conflicts-rho000-r4-016.18d4643c7e9516c1,reason=SuccessfulCreate count=1 msg=Created pod: eval-conflicts-rho000-r4-016-7cs7h
0.4844,Event,ADDED,eval-conflicts-rho000-r4-016.18d4643fdbb94d49,reason=Completed count=1 msg=Job completed
0.4847,Event,ADDED,eval-conflicts-rho000-r4-017-tbnbl.18d4643cba1de06c,reason=Scheduled count=None msg=Successfully assigned compute/eval-conflicts-rho000-r4-017-tbnbl to kind-worker2
0.4849,Event,ADDED,eval-conflicts-rho000-r4-017-tbnbl.18d4643cd3e1edd7,"reason=Pulled count=1 msg=Container image ""busybox:musl"" already present on machine"
0.485,Event,ADDED,eval-conflicts-rho000-r4-017-tbnbl.18d4643cd4f28503,reason=Created count=1 msg=Created container: task
0.4852,Event,ADDED,eval-conflicts-rho000-r4-017-tbnbl.18d4643cd6fbc75c,reason=Started count=1 msg=Started container task
0.4855,Event,ADDED,eval-conflicts-rho000-r4-017.18d4643cb999b834,reason=SuccessfulCreate count=1 msg=Created pod: eval-conflicts-rho000-r4-017-tbnbl
0.4857,Event,ADDED,eval-conflicts-rho000-r4-017.18d4644017a890fe,reason=Completed count=1 msg=Job completed
0.4859,Event,ADDED,eval-conflicts-rho000-r4-018-zwbth.18d4643cf5d94367,reason=Scheduled count=None msg=Successfully assigned compute/eval-conflicts-rho000-r4-018-zwbth to kind-worker2
0.486,Event,ADDED,eval-conflicts-rho000-r4-018-zwbth.18d4643d1411d5bd,"reason=Pulled count=1 msg=Container image ""busybox:musl"" already present on machine"
0.4864,Event,ADDED,eval-conflicts-rho000-r4-018-zwbth.18d4643d15578c6d,reason=Created count=1 msg=Created container: task
0.4866,Event,ADDED,eval-conflicts-rho000-r4-018-zwbth.18d4643d194c2e1f,reason=Started count=1 msg=Started container task
0.4867,Event,ADDED,eval-conflicts-rho000-r4-018.18d4643cf554f9c3,reason=SuccessfulCreate count=1 msg=Created pod: eval-conflicts-rho000-r4-018-zwbth
0.487,Event,ADDED,eval-conflicts-rho000-r4-018.18d464405377f944,reason=Completed count=1 msg=Job completed
0.4872,Event,ADDED,eval-conflicts-rho000-r4-019-h9nmh.18d4643d31ba3015,reason=Scheduled count=None msg=Successfully assigned compute/eval-conflicts-rho000-r4-019-h9nmh to kind-worker2
0.4874,Event,ADDED,eval-conflicts-rho000-r4-019-h9nmh.18d4643d4e162ce8,"reason=Pulled count=1 msg=Container image ""busybox:musl"" already present on machine"
0.4876,Event,ADDED,eval-conflicts-rho000-r4-019-h9nmh.18d4643d4f2ea3c2,reason=Created count=1 msg=Created container: task
0.4879,Event,ADDED,eval-conflicts-rho000-r4-019-h9nmh.18d4643d53674562,reason=Started count=1 msg=Started container task
0.4881,Event,ADDED,eval-conflicts-rho000-r4-019.18d4643d3116bfb5,reason=SuccessfulCreate count=1 msg=Created pod: eval-conflicts-rho000-r4-019-h9nmh
0.4883,Event,ADDED,eval-conflicts-rho000-r4-019.18d464408f5774b8,reason=Completed count=1 msg=Job completed
0.4885,Event,ADDED,eval-conflicts-rho000-r4-020-8gf4c.18d4643d6e0f8f19,reason=Scheduled count=None msg=Successfully assigned compute/eval-conflicts-rho000-r4-020-8gf4c to kind-worker5
0.4888,Event,ADDED,eval-conflicts-rho000-r4-020-8gf4c.18d4643d87cb6e3b,"reason=Pulled count=1 msg=Container image ""busybox:musl"" already present on machine"
0.489,Event,ADDED,eval-conflicts-rho000-r4-020-8gf4c.18d4643d88d2b165,reason=Created count=1 msg=Created container: task
0.4892,Event,ADDED,eval-conflicts-rho000-r4-020-8gf4c.18d4643d8b0da91b,reason=Started count=1 msg=Started container task
0.4895,Event,ADDED,eval-conflicts-rho000-r4-020.18d4643d6ce792b9,reason=SuccessfulCreate count=1 msg=Created pod: eval-conflicts-rho000-r4-020-8gf4c
0.4897,Event,ADDED,eval-conflicts-rho000-r4-020.18d46440ad1da162,reason=Completed count=1 msg=Job completed
0.4899,Event,ADDED,eval-conflicts-rho000-r4-021-swbtz.18d4643da9ca5831,reason=Scheduled count=None msg=Successfully assigned compute/eval-conflicts-rho000-r4-021-swbtz to kind-worker5
0.4901,Event,ADDED,eval-conflicts-rho000-r4-021-swbtz.18d4643dc88f78f2,"reason=Pulled count=1 msg=Container image ""busybox:musl"" already present on machine"
0.4904,Event,ADDED,eval-conflicts-rho000-r4-021-swbtz.18d4643dc99ffad4,reason=Created count=1 msg=Created container: task
0.4908,Event,ADDED,eval-conflicts-rho000-r4-021-swbtz.18d4643dd2e5efad,reason=Started count=1 msg=Started container task
0.491,Event,ADDED,eval-conflicts-rho000-r4-021.18d4643da889301a,reason=SuccessfulCreate count=1 msg=Created pod: eval-conflicts-rho000-r4-021-swbtz
0.4914,Event,ADDED,eval-conflicts-rho000-r4-021.18d46440e96063d7,reason=Completed count=1 msg=Job completed
0.4916,Event,ADDED,eval-conflicts-rho000-r4-022-xpzhk.18d4643de4797960,reason=Scheduled count=None msg=Successfully assigned compute/eval-conflicts-rho000-r4-022-xpzhk to kind-worker5
0.4918,Event,ADDED,eval-conflicts-rho000-r4-022-xpzhk.18d4643e02e796ab,"reason=Pulled count=1 msg=Container image ""busybox:musl"" already present on machine"
0.492,Event,ADDED,eval-conflicts-rho000-r4-022-xpzhk.18d4643e03f14e46,reason=Created count=1 msg=Created container: task
0.4925,Event,ADDED,eval-conflicts-rho000-r4-022-xpzhk.18d4643e076b33e2,reason=Started count=1 msg=Started container task
0.4927,Event,ADDED,eval-conflicts-rho000-r4-022.18d4643de3b2b08f,reason=SuccessfulCreate count=1 msg=Created pod: eval-conflicts-rho000-r4-022-xpzhk
0.4929,Event,ADDED,eval-conflicts-rho000-r4-022.18d4644125172166,reason=Completed count=1 msg=Job completed
0.493,Event,ADDED,eval-conflicts-rho000-r4-023-2q4mx.18d4643e20490a8c,reason=Scheduled count=None msg=Successfully assigned compute/eval-conflicts-rho000-r4-023-2q4mx to kind-worker
0.4933,Event,ADDED,eval-conflicts-rho000-r4-023-2q4mx.18d4643e3f35bf8b,"reason=Pulled count=1 msg=Container image ""busybox:musl"" already present on machine"
0.4935,Event,ADDED,eval-conflicts-rho000-r4-023-2q4mx.18d4643e4068b441,reason=Created count=1 msg=Created container: task
0.4936,Event,ADDED,eval-conflicts-rho000-r4-023-2q4mx.18d4643e450345fb,reason=Started count=1 msg=Started container task
0.4938,Event,ADDED,eval-conflicts-rho000-r4-023.18d4643e1f5933a2,reason=SuccessfulCreate count=1 msg=Created pod: eval-conflicts-rho000-r4-023-2q4mx
0.494,Event,ADDED,eval-conflicts-rho000-r4-023.18d4644158eb5dc1,reason=Completed count=1 msg=Job completed
0.4943,Event,ADDED,eval-conflicts-rho000-r4-024-xt9s9.18d4643e5caf5e03,reason=Scheduled count=None msg=Successfully assigned compute/eval-conflicts-rho000-r4-024-xt9s9 to kind-worker
0.4945,Event,ADDED,eval-conflicts-rho000-r4-024-xt9s9.18d4643e7e6cb682,"reason=Pulled count=1 msg=Container image ""busybox:musl"" already present on machine"
0.4946,Event,ADDED,eval-conflicts-rho000-r4-024-xt9s9.18d4643e7f8634bc,reason=Created count=1 msg=Created container: task
0.4948,Event,ADDED,eval-conflicts-rho000-r4-024-xt9s9.18d4643e832b5ec3,reason=Started count=1 msg=Started container task
0.4951,Event,ADDED,eval-conflicts-rho000-r4-024.18d4643e5b627e31,reason=SuccessfulCreate count=1 msg=Created pod: eval-conflicts-rho000-r4-024-xt9s9
0.4953,Event,ADDED,eval-conflicts-rho000-r4-024.18d4644194c27a38,reason=Completed count=1 msg=Job completed
0.4956,Event,ADDED,eval-conflicts-rho000-r4-025-ffd25.18d4643e97eda130,reason=Scheduled count=None msg=Successfully assigned compute/eval-conflicts-rho000-r4-025-ffd25 to kind-worker5
0.4958,Event,ADDED,eval-conflicts-rho000-r4-025-ffd25.18d4643eb97af387,"reason=Pulled count=1 msg=Container image ""busybox:musl"" already present on machine"
0.496,Event,ADDED,eval-conflicts-rho000-r4-025-ffd25.18d4643ebaa8c246,reason=Created count=1 msg=Created container: task
0.4965,Event,ADDED,eval-conflicts-rho000-r4-025-ffd25.18d4643ebf229b8b,reason=Started count=1 msg=Started container task
0.4969,Event,ADDED,eval-conflicts-rho000-r4-025.18d4643e97178e2b,reason=SuccessfulCreate count=1 msg=Created pod: eval-conflicts-rho000-r4-025-ffd25
0.4972,Event,ADDED,eval-conflicts-rho000-r4-025.18d46441d818f16e,reason=Completed count=1 msg=Job completed
0.4974,Event,ADDED,eval-conflicts-rho000-r4-026-dn2dr.18d4643ed3ee32f9,reason=Scheduled count=None msg=Successfully assigned compute/eval-conflicts-rho000-r4-026-dn2dr to kind-worker
0.4976,Event,ADDED,eval-conflicts-rho000-r4-026-dn2dr.18d4643ef5988644,"reason=Pulled count=1 msg=Container image ""busybox:musl"" already present on machine"
0.4977,Event,ADDED,eval-conflicts-rho000-r4-026-dn2dr.18d4643ef6a8fa71,reason=Created count=1 msg=Created container: task
0.498,Event,ADDED,eval-conflicts-rho000-r4-026-dn2dr.18d4643efaa50c75,reason=Started count=1 msg=Started container task
0.4983,Event,ADDED,eval-conflicts-rho000-r4-026.18d4643ed30cfcc9,reason=SuccessfulCreate count=1 msg=Created pod: eval-conflicts-rho000-r4-026-dn2dr
0.4985,Event,ADDED,eval-conflicts-rho000-r4-026.18d464420dcab386,reason=Completed count=1 msg=Job completed
0.4988,Event,ADDED,eval-conflicts-rho000-r4-027-42h69.18d4643f0f4b0ef1,reason=Scheduled count=None msg=Successfully assigned compute/eval-conflicts-rho000-r4-027-42h69 to kind-worker
0.499,Event,ADDED,eval-conflicts-rho000-r4-027-42h69.18d4643f32449fc6,"reason=Pulled count=1 msg=Container image ""busybox:musl"" already present on machine"
0.4991,Event,ADDED,eval-conflicts-rho000-r4-027-42h69.18d4643f337b680c,reason=Created count=1 msg=Created container: task
0.4993,Event,ADDED,eval-conflicts-rho000-r4-027-42h69.18d4643f3782fc80,reason=Started count=1 msg=Started container task
0.4996,Event,ADDED,eval-conflicts-rho000-r4-027.18d4643f0e313773,reason=SuccessfulCreate count=1 msg=Created pod: eval-conflicts-rho000-r4-027-42h69
0.4998,Event,ADDED,eval-conflicts-rho000-r4-027.18d4644249aa842f,reason=Completed count=1 msg=Job completed
0.4999,Event,ADDED,eval-conflicts-rho000-r4-028-qvb7r.18d4643f4a7c7308,reason=Scheduled count=None msg=Successfully assigned compute/eval-conflicts-rho000-r4-028-qvb7r to kind-worker5
0.5002,Event,ADDED,eval-conflicts-rho000-r4-028-qvb7r.18d4643f63d06963,"reason=Pulled count=1 msg=Container image ""busybox:musl"" already present on machine"
0.5004,Event,ADDED,eval-conflicts-rho000-r4-028-qvb7r.18d4643f653bb3b5,reason=Created count=1 msg=Created container: task
0.5006,Event,ADDED,eval-conflicts-rho000-r4-028-qvb7r.18d4643f68bcb137,reason=Started count=1 msg=Started container task
0.5008,Event,ADDED,eval-conflicts-rho000-r4-028.18d4643f498a4e7a,reason=SuccessfulCreate count=1 msg=Created pod: eval-conflicts-rho000-r4-028-qvb7r
0.5012,Event,ADDED,eval-conflicts-rho000-r4-028.18d464425240e6de,reason=Completed count=1 msg=Job completed
0.5013,Event,ADDED,eval-conflicts-rho000-r4-029-bkz2c.18d4643f86814a4c,reason=Scheduled count=None msg=Successfully assigned compute/eval-conflicts-rho000-r4-029-bkz2c to kind-worker
0.5015,Event,ADDED,eval-conflicts-rho000-r4-029-bkz2c.18d4643f9fbcd811,"reason=Pulled count=1 msg=Container image ""busybox:musl"" already present on machine"
0.5017,Event,ADDED,eval-conflicts-rho000-r4-029-bkz2c.18d4643fa12b6573,reason=Created count=1 msg=Created container: task
0.5021,Event,ADDED,eval-conflicts-rho000-r4-029-bkz2c.18d4643fa51e6dd2,reason=Started count=1 msg=Started container task
0.5024,Event,ADDED,eval-conflicts-rho000-r4-029.18d4643f85932616,reason=SuccessfulCreate count=1 msg=Created pod: eval-conflicts-rho000-r4-029-bkz2c
0.5025,Event,ADDED,eval-conflicts-rho000-r4-029.18d46442c1692374,reason=Completed count=1 msg=Job completed
0.5029,Event,ADDED,eval-conflicts-rho000-r4-030-lj6kw.18d4643fc15c877a,reason=Scheduled count=None msg=Successfully assigned compute/eval-conflicts-rho000-r4-030-lj6kw to kind-worker
0.5031,Event,ADDED,eval-conflicts-rho000-r4-030-lj6kw.18d4643fdb3ff75a,"reason=Pulled count=1 msg=Container image ""busybox:musl"" already present on machine"
0.5033,Event,ADDED,eval-conflicts-rho000-r4-030-lj6kw.18d4643fdcc94105,reason=Created count=1 msg=Created container: task
0.5035,Event,ADDED,eval-conflicts-rho000-r4-030-lj6kw.18d4643fe440bc36,reason=Started count=1 msg=Started container task
0.5038,Event,ADDED,eval-conflicts-rho000-r4-030.18d4643fc0c204b9,reason=SuccessfulCreate count=1 msg=Created pod: eval-conflicts-rho000-r4-030-lj6kw
0.504,Event,ADDED,eval-conflicts-rho000-r4-030.18d46442fc527091,reason=Completed count=1 msg=Job completed
0.5042,Event,ADDED,eval-conflicts-rho000-r4-031-h8n2h.18d4643ffcd67776,reason=Scheduled count=None msg=Successfully assigned compute/eval-conflicts-rho000-r4-031-h8n2h to kind-worker
0.5044,Event,ADDED,eval-conflicts-rho000-r4-031-h8n2h.18d46440158cb723,"reason=Pulled count=1 msg=Container image ""busybox:musl"" already present on machine"
0.5047,Event,ADDED,eval-conflicts-rho000-r4-031-h8n2h.18d4644016a651e9,reason=Created count=1 msg=Created container: task
0.5049,Event,ADDED,eval-conflicts-rho000-r4-031-h8n2h.18d46440200694cd,reason=Started count=1 msg=Started container task
0.5053,Event,ADDED,eval-conflicts-rho000-r4-031.18d4643ffc51f7e3,reason=SuccessfulCreate count=1 msg=Created pod: eval-conflicts-rho000-r4-031-h8n2h
0.5057,Event,ADDED,eval-conflicts-rho000-r4-031.18d4644338100409,reason=Completed count=1 msg=Job completed
0.5059,Event,ADDED,eval-conflicts-rho000-r4-032-r2z7v.18d4644038384108,reason=Scheduled count=None msg=Successfully assigned compute/eval-conflicts-rho000-r4-032-r2z7v to kind-worker
0.5061,Event,ADDED,eval-conflicts-rho000-r4-032-r2z7v.18d46440519824d0,"reason=Pulled count=1 msg=Container image ""busybox:musl"" already present on machine"
0.5064,Event,ADDED,eval-conflicts-rho000-r4-032-r2z7v.18d4644052ab6e81,reason=Created count=1 msg=Created container: task
0.5067,Event,ADDED,eval-conflicts-rho000-r4-032-r2z7v.18d46440578f2ee8,reason=Started count=1 msg=Started container task
0.5069,Event,ADDED,eval-conflicts-rho000-r4-032.18d4644037aac2df,reason=SuccessfulCreate count=1 msg=Created pod: eval-conflicts-rho000-r4-032-r2z7v
0.5071,Event,ADDED,eval-conflicts-rho000-r4-032.18d4644373ed26e3,reason=Completed count=1 msg=Job completed
0.5077,Event,ADDED,eval-conflicts-rho000-r4-033-wdblh.18d464407354051d,"reason=FailedScheduling count=None msg=0/6 nodes are available: 6 node(s) had untolerated taint(s). no new claims to deallocate, preemption: 0/6 nodes are available: 6 Preemption is not helpful for scheduling."
0.5079,Event,ADDED,eval-conflicts-rho000-r4-033-wdblh.18d464407b6351f9,reason=Scheduled count=None msg=Successfully assigned compute/eval-conflicts-rho000-r4-033-wdblh to kind-worker3
0.5081,Event,ADDED,eval-conflicts-rho000-r4-033-wdblh.18d4644095831a45,"reason=Pulled count=1 msg=Container image ""busybox:musl"" already present on machine"
0.5084,Event,ADDED,eval-conflicts-rho000-r4-033-wdblh.18d4644096992d57,reason=Created count=1 msg=Created container: task
0.5087,Event,ADDED,eval-conflicts-rho000-r4-033-wdblh.18d4644098d1efd2,reason=Started count=1 msg=Started container task
0.5089,Event,ADDED,eval-conflicts-rho000-r4-033.18d464407344dd7b,reason=SuccessfulCreate count=1 msg=Created pod: eval-conflicts-rho000-r4-033-wdblh
0.5091,Event,ADDED,eval-conflicts-rho000-r4-033.18d46443d62dcb79,reason=Completed count=1 msg=Job completed
0.5092,Event,ADDED,eval-conflicts-rho000-r4-034-znrsq.18d46440affabfc5,reason=Scheduled count=None msg=Successfully assigned compute/eval-conflicts-rho000-r4-034-znrsq to kind-worker3
0.5096,Event,ADDED,eval-conflicts-rho000-r4-034-znrsq.18d46440c93fd6ba,"reason=Pulled count=1 msg=Container image ""busybox:musl"" already present on machine"
0.5098,Event,ADDED,eval-conflicts-rho000-r4-034-znrsq.18d46440ca47f2af,reason=Created count=1 msg=Created container: task
0.51,Event,ADDED,eval-conflicts-rho000-r4-034-znrsq.18d46440cc898a67,reason=Started count=1 msg=Started container task
0.5104,Event,ADDED,eval-conflicts-rho000-r4-034.18d46440af4ebdf7,reason=SuccessfulCreate count=1 msg=Created pod: eval-conflicts-rho000-r4-034-znrsq
0.5106,Event,ADDED,eval-conflicts-rho000-r4-034.18d4644411f601b7,reason=Completed count=1 msg=Job completed
0.5107,Event,ADDED,eval-conflicts-rho000-r4-035-vxrwq.18d46440ec2da49b,reason=Scheduled count=None msg=Successfully assigned compute/eval-conflicts-rho000-r4-035-vxrwq to kind-worker2
0.5109,Event,ADDED,eval-conflicts-rho000-r4-035-vxrwq.18d4644105637551,"reason=Pulled count=1 msg=Container image ""busybox:musl"" already present on machine"
0.5112,Event,ADDED,eval-conflicts-rho000-r4-035-vxrwq.18d46441067f3442,reason=Created count=1 msg=Created container: task
0.5114,Event,ADDED,eval-conflicts-rho000-r4-035-vxrwq.18d464410879206d,reason=Started count=1 msg=Started container task
0.5116,Event,ADDED,eval-conflicts-rho000-r4-035.18d46440eb1db655,reason=SuccessfulCreate count=1 msg=Created pod: eval-conflicts-rho000-r4-035-vxrwq
0.5118,Event,ADDED,eval-conflicts-rho000-r4-035.18d464444dceee17,reason=Completed count=1 msg=Job completed
0.5121,Event,ADDED,eval-conflicts-rho000-r4-036-wrfdc.18d464412783308c,reason=Scheduled count=None msg=Successfully assigned compute/eval-conflicts-rho000-r4-036-wrfdc to kind-worker2
0.5123,Event,ADDED,eval-conflicts-rho000-r4-036-wrfdc.18d46441407eb313,"reason=Pulled count=1 msg=Container image ""busybox:musl"" already present on machine"
0.5125,Event,ADDED,eval-conflicts-rho000-r4-036-wrfdc.18d4644141b4e4ec,reason=Created count=1 msg=Created container: task
0.5127,Event,ADDED,eval-conflicts-rho000-r4-036-wrfdc.18d464414675fe72,reason=Started count=1 msg=Started container task
0.5129,Event,ADDED,eval-conflicts-rho000-r4-036.18d4644126716152,reason=SuccessfulCreate count=1 msg=Created pod: eval-conflicts-rho000-r4-036-wrfdc
0.5131,Event,ADDED,eval-conflicts-rho000-r4-036.18d464444e4a9e87,reason=Completed count=1 msg=Job completed
0.5132,Event,ADDED,eval-conflicts-rho000-r4-037-894j5.18d46441633f79f1,reason=Scheduled count=None msg=Successfully assigned compute/eval-conflicts-rho000-r4-037-894j5 to kind-worker2
0.5134,Event,ADDED,eval-conflicts-rho000-r4-037-894j5.18d464417c86ad5e,"reason=Pulled count=1 msg=Container image ""busybox:musl"" already present on machine"
0.5136,Event,ADDED,eval-conflicts-rho000-r4-037-894j5.18d464417dbb87fe,reason=Created count=1 msg=Created container: task
0.5138,Event,ADDED,eval-conflicts-rho000-r4-037-894j5.18d4644182238bc9,reason=Started count=1 msg=Started container task
0.5139,Event,ADDED,eval-conflicts-rho000-r4-037.18d46441623fe4af,reason=SuccessfulCreate count=1 msg=Created pod: eval-conflicts-rho000-r4-037-894j5
0.5142,Event,ADDED,eval-conflicts-rho000-r4-037.18d46444c5d7c876,reason=Completed count=1 msg=Job completed
0.5145,Event,ADDED,eval-conflicts-rho000-r4-038-cctc2.18d464419e984ef6,reason=Scheduled count=None msg=Successfully assigned compute/eval-conflicts-rho000-r4-038-cctc2 to kind-worker4
0.5147,Event,ADDED,eval-conflicts-rho000-r4-038-cctc2.18d46441b7de3378,"reason=Pulled count=1 msg=Container image ""busybox:musl"" already present on machine"
0.515,Event,ADDED,eval-conflicts-rho000-r4-038-cctc2.18d46441b917ba53,reason=Created count=1 msg=Created container: task
0.5152,Event,ADDED,eval-conflicts-rho000-r4-038-cctc2.18d46441bb41a088,reason=Started count=1 msg=Started container task
0.5153,Event,ADDED,eval-conflicts-rho000-r4-038.18d464419dc206f7,reason=SuccessfulCreate count=1 msg=Created pod: eval-conflicts-rho000-r4-038-cctc2
0.5155,Event,ADDED,eval-conflicts-rho000-r4-038.18d4644506c815b9,reason=Completed count=1 msg=Job completed
0.5157,Event,ADDED,eval-conflicts-rho000-r4-039-75l5l.18d46441da95066b,reason=Scheduled count=None msg=Successfully assigned compute/eval-conflicts-rho000-r4-039-75l5l to kind-worker4
0.5159,Event,ADDED,eval-conflicts-rho000-r4-039-75l5l.18d46441f3dda77e,"reason=Pulled count=1 msg=Container image ""busybox:musl"" already present on machine"
0.5161,Event,ADDED,eval-conflicts-rho000-r4-039-75l5l.18d46441f5018229,reason=Created count=1 msg=Created container: task
0.5162,Event,ADDED,eval-conflicts-rho000-r4-039-75l5l.18d46441f74634d0,reason=Started count=1 msg=Started container task
0.5164,Event,ADDED,eval-conflicts-rho000-r4-039.18d46441d9455712,reason=SuccessfulCreate count=1 msg=Created pod: eval-conflicts-rho000-r4-039-75l5l
0.5166,Event,ADDED,eval-conflicts-rho000-r4-039.18d4644542d195e3,reason=Completed count=1 msg=Job completed
0.5168,Event,ADDED,eval-conflicts-rho000-r4-040-4hp9s.18d4644215d4a58e,reason=Scheduled count=None msg=Successfully assigned compute/eval-conflicts-rho000-r4-040-4hp9s to kind-worker4
0.5171,Event,ADDED,eval-conflicts-rho000-r4-040-4hp9s.18d464422e8e6f08,"reason=Pulled count=1 msg=Container image ""busybox:musl"" already present on machine"
0.5174,Event,ADDED,eval-conflicts-rho000-r4-040-4hp9s.18d464422f9ef3a6,reason=Created count=1 msg=Created container: task
0.5176,Event,ADDED,eval-conflicts-rho000-r4-040-4hp9s.18d4644231831394,reason=Started count=1 msg=Started container task
0.5178,Event,ADDED,eval-conflicts-rho000-r4-040.18d4644214b1f460,reason=SuccessfulCreate count=1 msg=Created pod: eval-conflicts-rho000-r4-040-4hp9s
0.518,Event,ADDED,eval-conflicts-rho000-r4-040.18d4644580f47488,reason=Completed count=1 msg=Job completed
0.5182,Event,ADDED,eval-conflicts-rho000-r4-041-hjjkg.18d46442546f9850,reason=Scheduled count=None msg=Successfully assigned compute/eval-conflicts-rho000-r4-041-hjjkg to kind-worker2
0.5184,Event,ADDED,eval-conflicts-rho000-r4-041-hjjkg.18d46442714ba7d4,"reason=Pulled count=1 msg=Container image ""busybox:musl"" already present on machine"
0.5189,Event,ADDED,eval-conflicts-rho000-r4-041-hjjkg.18d46442726e745c,reason=Created count=1 msg=Created container: task
0.5191,Event,ADDED,eval-conflicts-rho000-r4-041-hjjkg.18d464427680cda0,reason=Started count=1 msg=Started container task
0.5193,Event,ADDED,eval-conflicts-rho000-r4-041.18d4644253082d94,reason=SuccessfulCreate count=1 msg=Created pod: eval-conflicts-rho000-r4-041-hjjkg
0.5194,Event,ADDED,eval-conflicts-rho000-r4-041.18d46445c318424f,reason=Completed count=1 msg=Job completed
0.5197,Event,ADDED,eval-conflicts-rho000-r4-042-7g9dp.18d464428d14f7ab,reason=Scheduled count=None msg=Successfully assigned compute/eval-conflicts-rho000-r4-042-7g9dp to kind-worker2
0.5199,Event,ADDED,eval-conflicts-rho000-r4-042-7g9dp.18d46442a6d82f16,"reason=Pulled count=1 msg=Container image ""busybox:musl"" already present on machine"
0.5201,Event,ADDED,eval-conflicts-rho000-r4-042-7g9dp.18d46442a81fe3b9,reason=Created count=1 msg=Created container: task
0.5204,Event,ADDED,eval-conflicts-rho000-r4-042-7g9dp.18d46442ad2ca8ba,reason=Started count=1 msg=Started container task
0.5206,Event,ADDED,eval-conflicts-rho000-r4-042.18d464428be8ca7a,reason=SuccessfulCreate count=1 msg=Created pod: eval-conflicts-rho000-r4-042-7g9dp
0.5208,Event,ADDED,eval-conflicts-rho000-r4-042.18d46445fbc14a54,reason=Completed count=1 msg=Job completed
0.521,Event,ADDED,eval-conflicts-rho000-r4-043-snq77.18d46442c8ae21bc,reason=Scheduled count=None msg=Successfully assigned compute/eval-conflicts-rho000-r4-043-snq77 to kind-worker2
0.5213,Event,ADDED,eval-conflicts-rho000-r4-043-snq77.18d46442e426f59f,"reason=Pulled count=1 msg=Container image ""busybox:musl"" already present on machine"
0.5215,Event,ADDED,eval-conflicts-rho000-r4-043-snq77.18d46442e53f367d,reason=Created count=1 msg=Created container: task
0.5217,Event,ADDED,eval-conflicts-rho000-r4-043-snq77.18d46442edaa70ac,reason=Started count=1 msg=Started container task
0.5219,Event,ADDED,eval-conflicts-rho000-r4-043.18d46442c7699481,reason=SuccessfulCreate count=1 msg=Created pod: eval-conflicts-rho000-r4-043-snq77
0.5223,Event,ADDED,eval-conflicts-rho000-r4-043.18d46446302b145e,reason=Completed count=1 msg=Job completed
0.5225,Event,ADDED,eval-conflicts-rho000-r4-044-56xwx.18d464430c2a0f80,reason=Scheduled count=None msg=Successfully assigned compute/eval-conflicts-rho000-r4-044-56xwx to kind-worker4
0.5227,Event,ADDED,eval-conflicts-rho000-r4-044-56xwx.18d4644329ecd07b,"reason=Pulled count=1 msg=Container image ""busybox:musl"" already present on machine"
0.5231,Event,ADDED,eval-conflicts-rho000-r4-044-56xwx.18d464432b0f5c38,reason=Created count=1 msg=Created container: task
0.5232,Event,ADDED,eval-conflicts-rho000-r4-044-56xwx.18d46443331e1a86,reason=Started count=1 msg=Started container task
0.5234,Event,ADDED,eval-conflicts-rho000-r4-044.18d464430b23d241,reason=SuccessfulCreate count=1 msg=Created pod: eval-conflicts-rho000-r4-044-56xwx
0.5236,Event,ADDED,eval-conflicts-rho000-r4-044.18d46446621d2166,reason=Completed count=1 msg=Job completed
0.5239,Event,ADDED,eval-conflicts-rho000-r4-045-dbvb7.18d4644343cb8215,"reason=FailedScheduling count=None msg=0/6 nodes are available: 6 node(s) had untolerated taint(s). no new claims to deallocate, preemption: 0/6 nodes are available: 6 Preemption is not helpful for scheduling."
0.5241,Event,ADDED,eval-conflicts-rho000-r4-045-dbvb7.18d4644464f773ff,reason=Scheduled count=None msg=Successfully assigned compute/eval-conflicts-rho000-r4-045-dbvb7 to kind-worker5
0.5243,Event,ADDED,eval-conflicts-rho000-r4-045-dbvb7.18d464447fbac7e4,"reason=Pulled count=1 msg=Container image ""busybox:musl"" already present on machine"
0.5245,Event,ADDED,eval-conflicts-rho000-r4-045-dbvb7.18d4644481664f6b,reason=Created count=1 msg=Created container: task
0.5247,Event,ADDED,eval-conflicts-rho000-r4-045-dbvb7.18d4644483a5c871,reason=Started count=1 msg=Started container task
0.5249,Event,ADDED,eval-conflicts-rho000-r4-045.18d4644343c67d2f,reason=SuccessfulCreate count=1 msg=Created pod: eval-conflicts-rho000-r4-045-dbvb7
0.525,Event,ADDED,eval-conflicts-rho000-r4-045.18d46447af40d1d0,reason=Completed count=1 msg=Job completed
0.5252,Event,ADDED,eval-conflicts-rho000-r4-046-tfnwq.18d464437a7be33d,"reason=FailedScheduling count=None msg=0/6 nodes are available: 6 node(s) had untolerated taint(s). no new claims to deallocate, preemption: 0/6 nodes are available: 6 Preemption is not helpful for scheduling."
0.5253,Event,ADDED,eval-conflicts-rho000-r4-046-tfnwq.18d46444658f2e0c,reason=Scheduled count=None msg=Successfully assigned compute/eval-conflicts-rho000-r4-046-tfnwq to kind-worker5
0.5255,Event,ADDED,eval-conflicts-rho000-r4-046-tfnwq.18d46444805b4632,"reason=Pulled count=1 msg=Container image ""busybox:musl"" already present on machine"
0.5257,Event,ADDED,eval-conflicts-rho000-r4-046-tfnwq.18d4644483023ce2,reason=Created count=1 msg=Created container: task
0.5259,Event,ADDED,eval-conflicts-rho000-r4-046-tfnwq.18d4644499c814c5,reason=Started count=1 msg=Started container task
0.526,Event,ADDED,eval-conflicts-rho000-r4-046.18d464437a7a824f,reason=SuccessfulCreate count=1 msg=Created pod: eval-conflicts-rho000-r4-046-tfnwq
0.5263,Event,ADDED,eval-conflicts-rho000-r4-046.18d46447aedbbf45,reason=Completed count=1 msg=Job completed
0.5265,Event,ADDED,eval-conflicts-rho000-r4-047-67bjm.18d46443b68829f3,"reason=FailedScheduling count=None msg=0/6 nodes are available: 6 node(s) had untolerated taint(s). no new claims to deallocate, preemption: 0/6 nodes are available: 6 Preemption is not helpful for scheduling."
0.5267,Event,ADDED,eval-conflicts-rho000-r4-047-67bjm.18d4644465ef8f04,reason=Scheduled count=None msg=Successfully assigned compute/eval-conflicts-rho000-r4-047-67bjm to kind-worker5
0.5268,Event,ADDED,eval-conflicts-rho000-r4-047-67bjm.18d46444817d7db0,"reason=Pulled count=1 msg=Container image ""busybox:musl"" already present on machine"
0.527,Event,ADDED,eval-conflicts-rho000-r4-047-67bjm.18d464448478c903,reason=Created count=1 msg=Created container: task
0.5273,Event,ADDED,eval-conflicts-rho000-r4-047-67bjm.18d464448747bf06,reason=Started count=1 msg=Started container task
0.5275,Event,ADDED,eval-conflicts-rho000-r4-047.18d46443b67feb3c,reason=SuccessfulCreate count=1 msg=Created pod: eval-conflicts-rho000-r4-047-67bjm
0.5277,Event,ADDED,eval-conflicts-rho000-r4-047.18d4644774e4bfc8,reason=Completed count=1 msg=Job completed
0.528,Event,ADDED,eval-conflicts-rho000-r4-048-xmgxw.18d46443f205149a,"reason=FailedScheduling count=None msg=0/6 nodes are available: 6 node(s) had untolerated taint(s). no new claims to deallocate, preemption: 0/6 nodes are available: 6 Preemption is not helpful for scheduling."
0.5281,Event,ADDED,eval-conflicts-rho000-r4-048-xmgxw.18d46444660bbc77,reason=Scheduled count=None msg=Successfully assigned compute/eval-conflicts-rho000-r4-048-xmgxw to kind-worker5
0.5283,Event,ADDED,eval-conflicts-rho000-r4-048-xmgxw.18d4644481b0a22d,"reason=Pulled count=1 msg=Container image ""busybox:musl"" already present on machine"
0.5285,Event,ADDED,eval-conflicts-rho000-r4-048-xmgxw.18d4644484f80dd3,reason=Created count=1 msg=Created container: task
0.5288,Event,ADDED,eval-conflicts-rho000-r4-048-xmgxw.18d464448aeeed61,reason=Started count=1 msg=Started container task
0.529,Event,ADDED,eval-conflicts-rho000-r4-048.18d46443f1fb472f,reason=SuccessfulCreate count=1 msg=Created pod: eval-conflicts-rho000-r4-048-xmgxw
0.5292,Event,ADDED,eval-conflicts-rho000-r4-048.18d464477545c0b3,reason=Completed count=1 msg=Job completed
0.5293,Event,ADDED,eval-conflicts-rho000-r4-049-v8xlq.18d464442d6ce851,"reason=FailedScheduling count=None msg=0/6 nodes are available: 6 node(s) had untolerated taint(s). no new claims to deallocate, preemption: 0/6 nodes are available: 6 Preemption is not helpful for scheduling."
0.5296,Event,ADDED,eval-conflicts-rho000-r4-049-v8xlq.18d464446650a8d0,reason=Scheduled count=None msg=Successfully assigned compute/eval-conflicts-rho000-r4-049-v8xlq to kind-worker5
0.5298,Event,ADDED,eval-conflicts-rho000-r4-049-v8xlq.18d464448167f4cf,"reason=Pulled count=1 msg=Container image ""busybox:musl"" already present on machine"
0.5303,Event,ADDED,eval-conflicts-rho000-r4-049-v8xlq.18d4644484563e01,reason=Created count=1 msg=Created container: task
0.5306,Event,ADDED,eval-conflicts-rho000-r4-049-v8xlq.18d46444874787af,reason=Started count=1 msg=Started container task
0.5308,Event,ADDED,eval-conflicts-rho000-r4-049.18d464442d621f52,reason=SuccessfulCreate count=1 msg=Created pod: eval-conflicts-rho000-r4-049-v8xlq
0.531,Event,ADDED,eval-conflicts-rho000-r4-049.18d4644774424de4,reason=Completed count=1 msg=Job completed
0.5312,Event,ADDED,eval-conflicts-rho000-r4-050-pqjzk.18d464446b45056c,reason=Scheduled count=None msg=Successfully assigned compute/eval-conflicts-rho000-r4-050-pqjzk to kind-worker5
0.5315,Event,ADDED,eval-conflicts-rho000-r4-050-pqjzk.18d464448367e84f,"reason=Pulled count=1 msg=Container image ""busybox:musl"" already present on machine"
0.5317,Event,ADDED,eval-conflicts-rho000-r4-050-pqjzk.18d46444859a6a9c,reason=Created count=1 msg=Created container: task
0.532,Event,ADDED,eval-conflicts-rho000-r4-050-pqjzk.18d464448b4fbc80,reason=Started count=1 msg=Started container task
0.5324,Event,ADDED,eval-conflicts-rho000-r4-050.18d46444697d94f4,reason=SuccessfulCreate count=1 msg=Created pod: eval-conflicts-rho000-r4-050-pqjzk
0.5326,Event,ADDED,eval-conflicts-rho000-r4-050.18d4644774c6b945,reason=Completed count=1 msg=Job completed
0.5327,Event,ADDED,eval-conflicts-rho000-r4-051-xgm2n.18d46444aac38e0e,reason=Scheduled count=None msg=Successfully assigned compute/eval-conflicts-rho000-r4-051-xgm2n to kind-worker5
0.5329,Event,ADDED,eval-conflicts-rho000-r4-051-xgm2n.18d46444c9c56969,"reason=Pulled count=1 msg=Container image ""busybox:musl"" already present on machine"
0.5333,Event,ADDED,eval-conflicts-rho000-r4-051-xgm2n.18d46444cadc1287,reason=Created count=1 msg=Created container: task
0.5335,Event,ADDED,eval-conflicts-rho000-r4-051-xgm2n.18d46444d40bd540,reason=Started count=1 msg=Started container task
0.5336,Event,ADDED,eval-conflicts-rho000-r4-051.18d46444aa2178c9,reason=SuccessfulCreate count=1 msg=Created pod: eval-conflicts-rho000-r4-051-xgm2n
0.5338,Event,ADDED,eval-conflicts-rho000-r4-051.18d46447b01ead2c,reason=Completed count=1 msg=Job completed
0.5342,Event,ADDED,eval-conflicts-rho000-r4-052-4z89d.18d46444e0853aca,reason=Scheduled count=None msg=Successfully assigned compute/eval-conflicts-rho000-r4-052-4z89d to kind-worker5
0.5345,Event,ADDED,eval-conflicts-rho000-r4-052-4z89d.18d464450612659b,"reason=Pulled count=1 msg=Container image ""busybox:musl"" already present on machine"
0.5347,Event,ADDED,eval-conflicts-rho000-r4-052-4z89d.18d4644507ac340e,reason=Created count=1 msg=Created container: task
0.535,Event,ADDED,eval-conflicts-rho000-r4-052-4z89d.18d464450b8cc2df,reason=Started count=1 msg=Started container task
0.5352,Event,ADDED,eval-conflicts-rho000-r4-052.18d46444dff64674,reason=SuccessfulCreate count=1 msg=Created pod: eval-conflicts-rho000-r4-052-4z89d
0.5354,Event,ADDED,eval-conflicts-rho000-r4-052.18d464482887249d,reason=Completed count=1 msg=Job completed
0.5356,Event,ADDED,eval-conflicts-rho000-r4-053-99c8j.18d464451c866add,reason=Scheduled count=None msg=Successfully assigned compute/eval-conflicts-rho000-r4-053-99c8j to kind-worker
0.5359,Event,ADDED,eval-conflicts-rho000-r4-053-99c8j.18d464453605b68f,"reason=Pulled count=1 msg=Container image ""busybox:musl"" already present on machine"
0.5361,Event,ADDED,eval-conflicts-rho000-r4-053-99c8j.18d464453720a366,reason=Created count=1 msg=Created container: task
0.5363,Event,ADDED,eval-conflicts-rho000-r4-053-99c8j.18d464454768e06c,reason=Started count=1 msg=Started container task
0.5366,Event,ADDED,eval-conflicts-rho000-r4-053.18d464451b6f66f1,reason=SuccessfulCreate count=1 msg=Created pod: eval-conflicts-rho000-r4-053-99c8j
0.5368,Event,ADDED,eval-conflicts-rho000-r4-053.18d464485c4ca9da,reason=Completed count=1 msg=Job completed
0.5369,Event,ADDED,eval-conflicts-rho000-r4-054-2qszk.18d464455ebd1324,reason=Scheduled count=None msg=Successfully assigned compute/eval-conflicts-rho000-r4-054-2qszk to kind-worker
0.5371,Event,ADDED,eval-conflicts-rho000-r4-054-2qszk.18d464458057c7fc,"reason=Pulled count=1 msg=Container image ""busybox:musl"" already present on machine"
0.5374,Event,ADDED,eval-conflicts-rho000-r4-054-2qszk.18d4644581e0f4aa,reason=Created count=1 msg=Created container: task
0.5376,Event,ADDED,eval-conflicts-rho000-r4-054-2qszk.18d464458d3b7172,reason=Started count=1 msg=Started container task
0.5377,Event,ADDED,eval-conflicts-rho000-r4-054.18d464455d9c36cc,reason=SuccessfulCreate count=1 msg=Created pod: eval-conflicts-rho000-r4-054-2qszk
0.5379,Event,ADDED,eval-conflicts-rho000-r4-054.18d4644899d3f499,reason=Completed count=1 msg=Job completed
0.5382,Event,ADDED,eval-conflicts-rho000-r4-055-flbwz.18d4644599ecf192,reason=Scheduled count=None msg=Successfully assigned compute/eval-conflicts-rho000-r4-055-flbwz to kind-worker
0.5384,Event,ADDED,eval-conflicts-rho000-r4-055-flbwz.18d46445b81bb625,"reason=Pulled count=1 msg=Container image ""busybox:musl"" already present on machine"
0.5386,Event,ADDED,eval-conflicts-rho000-r4-055-flbwz.18d46445b94cf240,reason=Created count=1 msg=Created container: task
0.5389,Event,ADDED,eval-conflicts-rho000-r4-055-flbwz.18d46445c2ac4e5b,reason=Started count=1 msg=Started container task
0.539,Event,ADDED,eval-conflicts-rho000-r4-055.18d4644598f358f0,reason=SuccessfulCreate count=1 msg=Created pod: eval-conflicts-rho000-r4-055-flbwz
0.5392,Event,ADDED,eval-conflicts-rho000-r4-055.18d464489a6d211c,reason=Completed count=1 msg=Job completed
0.5394,Event,ADDED,eval-conflicts-rho000-r4-056-vmn54.18d46445cf31d89c,reason=Scheduled count=None msg=Successfully assigned compute/eval-conflicts-rho000-r4-056-vmn54 to kind-worker
0.5396,Event,ADDED,eval-conflicts-rho000-r4-056-vmn54.18d46445e9428a63,"reason=Pulled count=1 msg=Container image ""busybox:musl"" already present on machine"
0.5397,Event,ADDED,eval-conflicts-rho000-r4-056-vmn54.18d46445eade74bf,reason=Created count=1 msg=Created container: task
0.5399,Event,ADDED,eval-conflicts-rho000-r4-056-vmn54.18d46445ef7d76b9,reason=Started count=1 msg=Started container task
0.5401,Event,ADDED,eval-conflicts-rho000-r4-056.18d46445ce59fd1c,reason=SuccessfulCreate count=1 msg=Created pod: eval-conflicts-rho000-r4-056-vmn54
0.5404,Event,ADDED,eval-conflicts-rho000-r4-056.18d4644911f21689,reason=Completed count=1 msg=Job completed
0.5405,Event,ADDED,eval-conflicts-rho000-r4-057-99qf9.18d464460ab4c585,reason=Scheduled count=None msg=Successfully assigned compute/eval-conflicts-rho000-r4-057-99qf9 to kind-worker
0.5407,Event,ADDED,eval-conflicts-rho000-r4-057-99qf9.18d46446253e31b2,"reason=Pulled count=1 msg=Container image ""busybox:musl"" already present on machine"
0.541,Event,ADDED,eval-conflicts-rho000-r4-057-99qf9.18d46446271ef4ed,reason=Created count=1 msg=Created container: task
0.5412,Event,ADDED,eval-conflicts-rho000-r4-057-99qf9.18d464462c7b4593,reason=Started count=1 msg=Started container task
0.5414,Event,ADDED,eval-conflicts-rho000-r4-057.18d4644609ca7719,reason=SuccessfulCreate count=1 msg=Created pod: eval-conflicts-rho000-r4-057-99qf9
0.5416,Event,ADDED,eval-conflicts-rho000-r4-057.18d46449121687f3,reason=Completed count=1 msg=Job completed
0.5419,Event,ADDED,eval-conflicts-rho000-r4-058-tbk4f.18d46446468a4e93,reason=Scheduled count=None msg=Successfully assigned compute/eval-conflicts-rho000-r4-058-tbk4f to kind-worker
0.5421,Event,ADDED,eval-conflicts-rho000-r4-058-tbk4f.18d464466062ff63,"reason=Pulled count=1 msg=Container image ""busybox:musl"" already present on machine"
0.5423,Event,ADDED,eval-conflicts-rho000-r4-058-tbk4f.18d4644661e4bd58,reason=Created count=1 msg=Created container: task
0.5426,Event,ADDED,eval-conflicts-rho000-r4-058-tbk4f.18d4644665beb97c,reason=Started count=1 msg=Started container task
0.5428,Event,ADDED,eval-conflicts-rho000-r4-058.18d4644645833110,reason=SuccessfulCreate count=1 msg=Created pod: eval-conflicts-rho000-r4-058-tbk4f
0.5429,Event,ADDED,eval-conflicts-rho000-r4-058.18d4644987a80a45,reason=Completed count=1 msg=Job completed
0.5431,Event,ADDED,eval-conflicts-rho000-r4-059-nfl95.18d4644681dac195,reason=Scheduled count=None msg=Successfully assigned compute/eval-conflicts-rho000-r4-059-nfl95 to kind-worker3
0.5433,Event,ADDED,eval-conflicts-rho000-r4-059-nfl95.18d464469b3ff153,"reason=Pulled count=1 msg=Container image ""busybox:musl"" already present on machine"
0.5436,Event,ADDED,eval-conflicts-rho000-r4-059-nfl95.18d464469c8d66cf,reason=Created count=1 msg=Created container: task
0.5438,Event,ADDED,eval-conflicts-rho000-r4-059-nfl95.18d46446a346505e,reason=Started count=1 msg=Started container task
0.5439,Event,ADDED,eval-conflicts-rho000-r4-059.18d46446810130d7,reason=SuccessfulCreate count=1 msg=Created pod: eval-conflicts-rho000-r4-059-nfl95
0.5446,Event,ADDED,eval-conflicts-rho000-r4-059.18d46449e1a89a53,reason=Completed count=1 msg=Job completed
0.5448,Event,ADDED,eval-conflicts-rho000-r4-060-gbrjk.18d46446be5e7f7c,reason=Scheduled count=None msg=Successfully assigned compute/eval-conflicts-rho000-r4-060-gbrjk to kind-worker3
0.5449,Event,ADDED,eval-conflicts-rho000-r4-060-gbrjk.18d46446dd18b5b3,"reason=Pulled count=1 msg=Container image ""busybox:musl"" already present on machine"
0.5453,Event,ADDED,eval-conflicts-rho000-r4-060-gbrjk.18d46446de78d97f,reason=Created count=1 msg=Created container: task
0.5455,Event,ADDED,eval-conflicts-rho000-r4-060-gbrjk.18d46446e62a8bf9,reason=Started count=1 msg=Started container task
0.5457,Event,ADDED,eval-conflicts-rho000-r4-060.18d46446bd101741,reason=SuccessfulCreate count=1 msg=Created pod: eval-conflicts-rho000-r4-060-gbrjk
0.5459,Event,ADDED,eval-conflicts-rho000-r4-060.18d4644a1dd3e238,reason=Completed count=1 msg=Job completed
0.5463,Event,ADDED,eval-conflicts-rho000-r4-061-zbvlt.18d46446f9da8640,reason=Scheduled count=None msg=Successfully assigned compute/eval-conflicts-rho000-r4-061-zbvlt to kind-worker
0.5465,Event,ADDED,eval-conflicts-rho000-r4-061-zbvlt.18d4644712eee637,"reason=Pulled count=1 msg=Container image ""busybox:musl"" already present on machine"
0.5467,Event,ADDED,eval-conflicts-rho000-r4-061-zbvlt.18d4644714295da3,reason=Created count=1 msg=Created container: task
0.5468,Event,ADDED,eval-conflicts-rho000-r4-061-zbvlt.18d464471938aaae,reason=Started count=1 msg=Started container task
0.5472,Event,ADDED,eval-conflicts-rho000-r4-061.18d46446f89156ba,reason=SuccessfulCreate count=1 msg=Created pod: eval-conflicts-rho000-r4-061-zbvlt
0.5474,Event,ADDED,eval-conflicts-rho000-r4-061.18d46449ffa9841c,reason=Completed count=1 msg=Job completed
0.5476,Event,ADDED,eval-conflicts-rho000-r4-062-8gcmb.18d464473519d651,reason=Scheduled count=None msg=Successfully assigned compute/eval-conflicts-rho000-r4-062-8gcmb to kind-worker3
0.5479,Event,ADDED,eval-conflicts-rho000-r4-062-8gcmb.18d464474de23594,"reason=Pulled count=1 msg=Container image ""busybox:musl"" already present on machine"
0.548,Event,ADDED,eval-conflicts-rho000-r4-062-8gcmb.18d464474f7f3c80,reason=Created count=1 msg=Created container: task
0.5482,Event,ADDED,eval-conflicts-rho000-r4-062-8gcmb.18d46447518f2af2,reason=Started count=1 msg=Started container task
0.5484,Event,ADDED,eval-conflicts-rho000-r4-062.18d46447342a3a37,reason=SuccessfulCreate count=1 msg=Created pod: eval-conflicts-rho000-r4-062-8gcmb
0.5486,Event,ADDED,eval-conflicts-rho000-r4-062.18d4644a974d5db5,reason=Completed count=1 msg=Job completed
0.5488,Event,ADDED,eval-conflicts-rho000-r4-063-kzlmt.18d464477137c2ad,reason=Scheduled count=None msg=Successfully assigned compute/eval-conflicts-rho000-r4-063-kzlmt to kind-worker
0.5489,Event,ADDED,eval-conflicts-rho000-r4-063-kzlmt.18d464478b03736f,"reason=Pulled count=1 msg=Container image ""busybox:musl"" already present on machine"
0.5491,Event,ADDED,eval-conflicts-rho000-r4-063-kzlmt.18d464478c1a4d2b,reason=Created count=1 msg=Created container: task
0.5494,Event,ADDED,eval-conflicts-rho000-r4-063-kzlmt.18d4644790b63bbe,reason=Started count=1 msg=Started container task
0.5495,Event,ADDED,eval-conflicts-rho000-r4-063.18d46447704c8967,reason=SuccessfulCreate count=1 msg=Created pod: eval-conflicts-rho000-r4-063-kzlmt
0.5497,Event,ADDED,eval-conflicts-rho000-r4-063.18d4644a77b0c323,reason=Completed count=1 msg=Job completed
0.5501,Event,ADDED,eval-conflicts-rho000-r4-064-hn8m2.18d46447ad1bac27,"reason=FailedScheduling count=None msg=0/6 nodes are available: 6 node(s) had untolerated taint(s). no new claims to deallocate, preemption: 0/6 nodes are available: 6 Preemption is not helpful for scheduling."
0.5503,Event,ADDED,eval-conflicts-rho000-r4-064-hn8m2.18d46447fa103a69,reason=Scheduled count=None msg=Successfully assigned compute/eval-conflicts-rho000-r4-064-hn8m2 to kind-worker2
0.5505,Event,ADDED,eval-conflicts-rho000-r4-064-hn8m2.18d464481bbe4b6b,"reason=Pulled count=1 msg=Container image ""busybox:musl"" already present on machine"
0.5507,Event,ADDED,eval-conflicts-rho000-r4-064-hn8m2.18d464481cfc1cd3,reason=Created count=1 msg=Created container: task
0.551,Event,ADDED,eval-conflicts-rho000-r4-064-hn8m2.18d4644821ce3f99,reason=Started count=1 msg=Started container task
0.5512,Event,ADDED,eval-conflicts-rho000-r4-064.18d46447ad13c249,reason=SuccessfulCreate count=1 msg=Created pod: eval-conflicts-rho000-r4-064-hn8m2
0.5514,Event,ADDED,eval-conflicts-rho000-r4-064.18d4644b4dce8a64,reason=Completed count=1 msg=Job completed
0.5516,Event,ADDED,eval-conflicts-rho000-r4-065-wwzlr.18d46447e6862207,"reason=FailedScheduling count=None msg=0/6 nodes are available: 6 node(s) had untolerated taint(s). no new claims to deallocate, preemption: 0/6 nodes are available: 6 Preemption is not helpful for scheduling."
0.5518,Event,ADDED,eval-conflicts-rho000-r4-065-wwzlr.18d46447fa46274d,reason=Scheduled count=None msg=Successfully assigned compute/eval-conflicts-rho000-r4-065-wwzlr to kind-worker2
0.552,Event,ADDED,eval-conflicts-rho000-r4-065-wwzlr.18d4644816fb5713,"reason=Pulled count=1 msg=Container image ""busybox:musl"" already present on machine"
0.5522,Event,ADDED,eval-conflicts-rho000-r4-065-wwzlr.18d4644818089540,reason=Created count=1 msg=Created container: task
0.5525,Event,ADDED,eval-conflicts-rho000-r4-065-wwzlr.18d464481d00bf8a,reason=Started count=1 msg=Started container task
0.5526,Event,ADDED,eval-conflicts-rho000-r4-065.18d46447e67a30f8,reason=SuccessfulCreate count=1 msg=Created pod: eval-conflicts-rho000-r4-065-wwzlr
0.5528,Event,ADDED,eval-conflicts-rho000-r4-065.18d4644b4dcfd4cc,reason=Completed count=1 msg=Job completed
0.553,Event,ADDED,eval-conflicts-rho000-r4-066-h8p4h.18d46448231a9594,reason=Scheduled count=None msg=Successfully assigned compute/eval-conflicts-rho000-r4-066-h8p4h to kind-worker2
0.5533,Event,ADDED,eval-conflicts-rho000-r4-066-h8p4h.18d464483dbee102,"reason=Pulled count=1 msg=Container image ""busybox:musl"" already present on machine"
0.5534,Event,ADDED,eval-conflicts-rho000-r4-066-h8p4h.18d464483ec81553,reason=Created count=1 msg=Created container: task
0.5536,Event,ADDED,eval-conflicts-rho000-r4-066-h8p4h.18d4644841b29a42,reason=Started count=1 msg=Started container task
0.5538,Event,ADDED,eval-conflicts-rho000-r4-066.18d464482261acf2,reason=SuccessfulCreate count=1 msg=Created pod: eval-conflicts-rho000-r4-066-h8p4h
0.554,Event,ADDED,eval-conflicts-rho000-r4-066.18d4644b8b6be6c5,reason=Completed count=1 msg=Job completed
0.5543,Event,ADDED,eval-conflicts-rho000-r4-067-gm6lk.18d464485f0473bc,reason=Scheduled count=None msg=Successfully assigned compute/eval-conflicts-rho000-r4-067-gm6lk to kind-worker4
0.5545,Event,ADDED,eval-conflicts-rho000-r4-067-gm6lk.18d464487940811b,"reason=Pulled count=1 msg=Container image ""busybox:musl"" already present on machine"
0.5547,Event,ADDED,eval-conflicts-rho000-r4-067-gm6lk.18d464487a5154e5,reason=Created count=1 msg=Created container: task
0.5549,Event,ADDED,eval-conflicts-rho000-r4-067-gm6lk.18d464487dd5bbb9,reason=Started count=1 msg=Started container task
0.555,Event,ADDED,eval-conflicts-rho000-r4-067.18d464485e37fdfd,reason=SuccessfulCreate count=1 msg=Created pod: eval-conflicts-rho000-r4-067-gm6lk
0.5552,Event,ADDED,eval-conflicts-rho000-r4-067.18d4644bc04f0bd9,reason=Completed count=1 msg=Job completed
0.5554,Event,ADDED,eval-conflicts-rho000-r4-068-t9tzc.18d464489c7b46a4,reason=Scheduled count=None msg=Successfully assigned compute/eval-conflicts-rho000-r4-068-t9tzc to kind-worker4
0.5556,Event,ADDED,eval-conflicts-rho000-r4-068-t9tzc.18d46448b83caf6d,"reason=Pulled count=1 msg=Container image ""busybox:musl"" already present on machine"
0.5557,Event,ADDED,eval-conflicts-rho000-r4-068-t9tzc.18d46448b975754c,reason=Created count=1 msg=Created container: task
0.5559,Event,ADDED,eval-conflicts-rho000-r4-068-t9tzc.18d46448c2b39680,reason=Started count=1 msg=Started container task
0.5561,Event,ADDED,eval-conflicts-rho000-r4-068.18d464489b89d498,reason=SuccessfulCreate count=1 msg=Created pod: eval-conflicts-rho000-r4-068-t9tzc
0.5562,Event,ADDED,eval-conflicts-rho000-r4-068.18d4644bfc278cf2,reason=Completed count=1 msg=Job completed
0.5564,Event,ADDED,eval-conflicts-rho000-r4-069-x8lzq.18d46448d64c1232,reason=Scheduled count=None msg=Successfully assigned compute/eval-conflicts-rho000-r4-069-x8lzq to kind-worker2
0.5571,Event,ADDED,eval-conflicts-rho000-r4-069-x8lzq.18d46448efdea9e9,"reason=Pulled count=1 msg=Container image ""busybox:musl"" already present on machine"
0.5573,Event,ADDED,eval-conflicts-rho000-r4-069-x8lzq.18d46448f102da99,reason=Created count=1 msg=Created container: task
0.5575,Event,ADDED,eval-conflicts-rho000-r4-069-x8lzq.18d46448f2fcf7d0,reason=Started count=1 msg=Started container task
0.5578,Event,ADDED,eval-conflicts-rho000-r4-069.18d46448d53af3ce,reason=SuccessfulCreate count=1 msg=Created pod: eval-conflicts-rho000-r4-069-x8lzq
0.558,Event,ADDED,eval-conflicts-rho000-r4-069.18d4644c0378f3b9,reason=Completed count=1 msg=Job completed
0.5582,Event,ADDED,eval-conflicts-rho000-r4-070-wqt7l.18d4644912822d8d,reason=Scheduled count=None msg=Successfully assigned compute/eval-conflicts-rho000-r4-070-wqt7l to kind-worker2
0.5584,Event,ADDED,eval-conflicts-rho000-r4-070-wqt7l.18d464492b648efd,"reason=Pulled count=1 msg=Container image ""busybox:musl"" already present on machine"
0.5587,Event,ADDED,eval-conflicts-rho000-r4-070-wqt7l.18d464492c93be8d,reason=Created count=1 msg=Created container: task
0.5589,Event,ADDED,eval-conflicts-rho000-r4-070-wqt7l.18d464493116a99e,reason=Started count=1 msg=Started container task
0.5591,Event,ADDED,eval-conflicts-rho000-r4-070.18d464491176c486,reason=SuccessfulCreate count=1 msg=Created pod: eval-conflicts-rho000-r4-070-wqt7l
0.5592,Event,ADDED,eval-conflicts-rho000-r4-070.18d4644c3f53e56e,reason=Completed count=1 msg=Job completed
0.5594,Event,ADDED,eval-conflicts-rho000-r4-071-6mnhx.18d464494e22b904,reason=Scheduled count=None msg=Successfully assigned compute/eval-conflicts-rho000-r4-071-6mnhx to kind-worker5
0.5596,Event,ADDED,eval-conflicts-rho000-r4-071-6mnhx.18d46449697548b6,"reason=Pulled count=1 msg=Container image ""busybox:musl"" already present on machine"
0.5598,Event,ADDED,eval-conflicts-rho000-r4-071-6mnhx.18d464496ae70469,reason=Created count=1 msg=Created container: task
0.5602,Event,ADDED,eval-conflicts-rho000-r4-071-6mnhx.18d464496f8933ab,reason=Started count=1 msg=Started container task
0.5604,Event,ADDED,eval-conflicts-rho000-r4-071.18d464494d2fbd4a,reason=SuccessfulCreate count=1 msg=Created pod: eval-conflicts-rho000-r4-071-6mnhx
0.5605,Event,ADDED,eval-conflicts-rho000-r4-071.18d4644c97b79c7f,reason=Completed count=1 msg=Job completed
0.5607,Event,ADDED,eval-conflicts-rho000-r4-072-r8xfj.18d4644989e054d6,reason=Scheduled count=None msg=Successfully assigned compute/eval-conflicts-rho000-r4-072-r8xfj to kind-worker5
0.561,Event,ADDED,eval-conflicts-rho000-r4-072-r8xfj.18d46449a4131225,"reason=Pulled count=1 msg=Container image ""busybox:musl"" already present on machine"
0.5612,Event,ADDED,eval-conflicts-rho000-r4-072-r8xfj.18d46449a55ddfe0,reason=Created count=1 msg=Created container: task
0.5613,Event,ADDED,eval-conflicts-rho000-r4-072-r8xfj.18d46449ad6d93ae,reason=Started count=1 msg=Started container task
0.5616,Event,ADDED,eval-conflicts-rho000-r4-072.18d4644988945495,reason=SuccessfulCreate count=1 msg=Created pod: eval-conflicts-rho000-r4-072-r8xfj
0.5618,Event,ADDED,eval-conflicts-rho000-r4-072.18d4644cd35fe5e3,reason=Completed count=1 msg=Job completed
0.562,Event,ADDED,eval-conflicts-rho000-r4-073-h4zg5.18d46449c678c7be,reason=Scheduled count=None msg=Successfully assigned compute/eval-conflicts-rho000-r4-073-h4zg5 to kind-worker5
0.5621,Event,ADDED,eval-conflicts-rho000-r4-073-h4zg5.18d46449e12b3d6a,"reason=Pulled count=1 msg=Container image ""busybox:musl"" already present on machine"
0.5624,Event,ADDED,eval-conflicts-rho000-r4-073-h4zg5.18d46449e29895ad,reason=Created count=1 msg=Created container: task
0.5625,Event,ADDED,eval-conflicts-rho000-r4-073-h4zg5.18d46449e7445e05,reason=Started count=1 msg=Started container task
0.5627,Event,ADDED,eval-conflicts-rho000-r4-073.18d46449c4828745,reason=SuccessfulCreate count=1 msg=Created pod: eval-conflicts-rho000-r4-073-h4zg5
0.5628,Event,ADDED,eval-conflicts-rho000-r4-073.18d4644d0efcfb19,reason=Completed count=1 msg=Job completed
0.5631,Event,ADDED,eval-conflicts-rho000-r4-074-s7td5.18d4644a00cbde1a,reason=Scheduled count=None msg=Successfully assigned compute/eval-conflicts-rho000-r4-074-s7td5 to kind-worker5
0.5633,Event,ADDED,eval-conflicts-rho000-r4-074-s7td5.18d4644a1c0b94f3,"reason=Pulled count=1 msg=Container image ""busybox:musl"" already present on machine"
0.5635,Event,ADDED,eval-conflicts-rho000-r4-074-s7td5.18d4644a1d389d2f,reason=Created count=1 msg=Created container: task
0.5638,Event,ADDED,eval-conflicts-rho000-r4-074-s7td5.18d4644a25b505f2,reason=Started count=1 msg=Started container task
0.5639,Event,ADDED,eval-conflicts-rho000-r4-074.18d46449ff84c1fc,reason=SuccessfulCreate count=1 msg=Created pod: eval-conflicts-rho000-r4-074-s7td5
0.5641,Event,ADDED,eval-conflicts-rho000-r4-074.18d4644d4b5f69e0,reason=Completed count=1 msg=Job completed
0.5643,Event,ADDED,eval-conflicts-rho000-r4-075-q72hc.18d4644a3ca26122,reason=Scheduled count=None msg=Successfully assigned compute/eval-conflicts-rho000-r4-075-q72hc to kind-worker5
0.5646,Event,ADDED,eval-conflicts-rho000-r4-075-q72hc.18d4644a558b5e40,"reason=Pulled count=1 msg=Container image ""busybox:musl"" already present on machine"
0.5648,Event,ADDED,eval-conflicts-rho000-r4-075-q72hc.18d4644a56b29c01,reason=Created count=1 msg=Created container: task
0.5649,Event,ADDED,eval-conflicts-rho000-r4-075-q72hc.18d4644a5da403ec,reason=Started count=1 msg=Started container task
0.5652,Event,ADDED,eval-conflicts-rho000-r4-075.18d4644a3b624412,reason=SuccessfulCreate count=1 msg=Created pod: eval-conflicts-rho000-r4-075-q72hc
0.5655,Event,ADDED,eval-conflicts-rho000-r4-075.18d4644d877e2b89,reason=Completed count=1 msg=Job completed
0.5656,Event,ADDED,eval-conflicts-rho000-r4-076-mgshc.18d4644a78a18738,reason=Scheduled count=None msg=Successfully assigned compute/eval-conflicts-rho000-r4-076-mgshc to kind-worker5
0.5658,Event,ADDED,eval-conflicts-rho000-r4-076-mgshc.18d4644a92291659,"reason=Pulled count=1 msg=Container image ""busybox:musl"" already present on machine"
0.5661,Event,ADDED,eval-conflicts-rho000-r4-076-mgshc.18d4644a933ab268,reason=Created count=1 msg=Created container: task
0.5663,Event,ADDED,eval-conflicts-rho000-r4-076-mgshc.18d4644a96fe07a6,reason=Started count=1 msg=Started container task
0.5664,Event,ADDED,eval-conflicts-rho000-r4-076.18d4644a7827f49d,reason=SuccessfulCreate count=1 msg=Created pod: eval-conflicts-rho000-r4-076-mgshc
0.5666,Event,ADDED,eval-conflicts-rho000-r4-076.18d4644d8825b45f,reason=Completed count=1 msg=Job completed
0.567,Event,ADDED,eval-conflicts-rho000-r4-077-xhdlt.18d4644ab4c5ac6a,reason=Scheduled count=None msg=Successfully assigned compute/eval-conflicts-rho000-r4-077-xhdlt to kind-worker5
0.5672,Event,ADDED,eval-conflicts-rho000-r4-077-xhdlt.18d4644acf6ceb53,"reason=Pulled count=1 msg=Container image ""busybox:musl"" already present on machine"
0.5673,Event,ADDED,eval-conflicts-rho000-r4-077-xhdlt.18d4644ad0856b17,reason=Created count=1 msg=Created container: task
0.5675,Event,ADDED,eval-conflicts-rho000-r4-077-xhdlt.18d4644ad7a5abdb,reason=Started count=1 msg=Started container task
0.5677,Event,ADDED,eval-conflicts-rho000-r4-077.18d4644ab421c223,reason=SuccessfulCreate count=1 msg=Created pod: eval-conflicts-rho000-r4-077-xhdlt
0.5679,Event,ADDED,eval-conflicts-rho000-r4-077.18d4644e05d34d72,reason=Completed count=1 msg=Job completed
0.568,Event,ADDED,eval-conflicts-rho000-r4-078-r9w7l.18d4644af01b35bf,reason=Scheduled count=None msg=Successfully assigned compute/eval-conflicts-rho000-r4-078-r9w7l to kind-worker5
0.5683,Event,ADDED,eval-conflicts-rho000-r4-078-r9w7l.18d4644b0c0a8b89,"reason=Pulled count=1 msg=Container image ""busybox:musl"" already present on machine"
0.5685,Event,ADDED,eval-conflicts-rho000-r4-078-r9w7l.18d4644b0d5b0686,reason=Created count=1 msg=Created container: task
0.5686,Event,ADDED,eval-conflicts-rho000-r4-078-r9w7l.18d4644b10aca886,reason=Started count=1 msg=Started container task
0.5688,Event,ADDED,eval-conflicts-rho000-r4-078.18d4644aef875782,reason=SuccessfulCreate count=1 msg=Created pod: eval-conflicts-rho000-r4-078-r9w7l
0.5689,Event,ADDED,eval-conflicts-rho000-r4-078.18d4644e063809a7,reason=Completed count=1 msg=Job completed
0.5691,Event,ADDED,eval-conflicts-rho000-r4-079-6v452.18d4644b29e88656,reason=Scheduled count=None msg=Successfully assigned compute/eval-conflicts-rho000-r4-079-6v452 to kind-worker5
0.5693,Event,ADDED,eval-conflicts-rho000-r4-079-6v452.18d4644b43bb8d75,"reason=Pulled count=1 msg=Container image ""busybox:musl"" already present on machine"
0.5694,Event,ADDED,eval-conflicts-rho000-r4-079-6v452.18d4644b44ee3d9c,reason=Created count=1 msg=Created container: task
0.5696,Event,ADDED,eval-conflicts-rho000-r4-079-6v452.18d4644b498015bb,reason=Started count=1 msg=Started container task
0.5698,Event,ADDED,eval-conflicts-rho000-r4-079.18d4644b295fbb56,reason=SuccessfulCreate count=1 msg=Created pod: eval-conflicts-rho000-r4-079-6v452
0.5699,Event,ADDED,eval-conflicts-rho000-r4-079.18d4644e7abb5ecf,reason=Completed count=1 msg=Job completed
0.5701,Event,ADDED,eval-conflicts-rho000-r4-080-kpxlt.18d4644b6564afcd,reason=Scheduled count=None msg=Successfully assigned compute/eval-conflicts-rho000-r4-080-kpxlt to kind-worker5
0.5703,Event,ADDED,eval-conflicts-rho000-r4-080-kpxlt.18d4644b815e589e,"reason=Pulled count=1 msg=Container image ""busybox:musl"" already present on machine"
0.5704,Event,ADDED,eval-conflicts-rho000-r4-080-kpxlt.18d4644b8279f509,reason=Created count=1 msg=Created container: task
0.5706,Event,ADDED,eval-conflicts-rho000-r4-080-kpxlt.18d4644b84ad29b8,reason=Started count=1 msg=Started container task
0.5708,Event,ADDED,eval-conflicts-rho000-r4-080.18d4644b64c32ff1,reason=SuccessfulCreate count=1 msg=Created pod: eval-conflicts-rho000-r4-080-kpxlt
0.5709,Event,ADDED,eval-conflicts-rho000-r4-080.18d4644e7e156b63,reason=Completed count=1 msg=Job completed
0.5711,Event,ADDED,eval-conflicts-rho000-r4-081-fbctb.18d4644ba054e8eb,"reason=FailedScheduling count=None msg=0/6 nodes are available: 6 node(s) had untolerated taint(s). no new claims to deallocate, preemption: 0/6 nodes are available: 6 Preemption is not helpful for scheduling."
0.5713,Event,ADDED,eval-conflicts-rho000-r4-081-fbctb.18d4644c3766eacb,reason=Scheduled count=None msg=Successfully assigned compute/eval-conflicts-rho000-r4-081-fbctb to kind-worker
0.5714,Event,ADDED,eval-conflicts-rho000-r4-081-fbctb.18d4644c52f5fb2a,"reason=Pulled count=1 msg=Container image ""busybox:musl"" already present on machine"
0.5716,Event,ADDED,eval-conflicts-rho000-r4-081-fbctb.18d4644c549ebeb6,reason=Created count=1 msg=Created container: task
0.5721,Event,ADDED,eval-conflicts-rho000-r4-081-fbctb.18d4644c596c0b67,reason=Started count=1 msg=Started container task
0.5723,Event,ADDED,eval-conflicts-rho000-r4-081.18d4644ba049b757,reason=SuccessfulCreate count=1 msg=Created pod: eval-conflicts-rho000-r4-081-fbctb
0.5725,Event,ADDED,eval-conflicts-rho000-r4-081.18d4644f9a9ea08c,reason=Completed count=1 msg=Job completed
0.5726,Event,ADDED,eval-conflicts-rho000-r4-082-krsxz.18d4644bdc53eb67,"reason=FailedScheduling count=None msg=0/6 nodes are available: 6 node(s) had untolerated taint(s). no new claims to deallocate, preemption: 0/6 nodes are available: 6 Preemption is not helpful for scheduling."
0.5728,Event,ADDED,eval-conflicts-rho000-r4-082-krsxz.18d4644c376be3ef,reason=Scheduled count=None msg=Successfully assigned compute/eval-conflicts-rho000-r4-082-krsxz to kind-worker
0.5729,Event,ADDED,eval-conflicts-rho000-r4-082-krsxz.18d4644c531a7756,"reason=Pulled count=1 msg=Container image ""busybox:musl"" already present on machine"
0.5731,Event,ADDED,eval-conflicts-rho000-r4-082-krsxz.18d4644c552f6bda,reason=Created count=1 msg=Created container: task
0.5733,Event,ADDED,eval-conflicts-rho000-r4-082-krsxz.18d4644c5a20fe0f,reason=Started count=1 msg=Started container task
0.5734,Event,ADDED,eval-conflicts-rho000-r4-082.18d4644bdc48283a,reason=SuccessfulCreate count=1 msg=Created pod: eval-conflicts-rho000-r4-082-krsxz
0.5736,Event,ADDED,eval-conflicts-rho000-r4-082.18d4644f9b013683,reason=Completed count=1 msg=Job completed
0.5737,Event,ADDED,eval-conflicts-rho000-r4-083-h8xpb.18d4644c17d20ff9,"reason=FailedScheduling count=None msg=0/6 nodes are available: 6 node(s) had untolerated taint(s). no new claims to deallocate, preemption: 0/6 nodes are available: 6 Preemption is not helpful for scheduling."
0.5739,Event,ADDED,eval-conflicts-rho000-r4-083-h8xpb.18d4644c37930ada,reason=Scheduled count=None msg=Successfully assigned compute/eval-conflicts-rho000-r4-083-h8xpb to kind-worker
0.5741,Event,ADDED,eval-conflicts-rho000-r4-083-h8xpb.18d4644c533ee81c,"reason=Pulled count=1 msg=Container image ""busybox:musl"" already present on machine"
0.5743,Event,ADDED,eval-conflicts-rho000-r4-083-h8xpb.18d4644c55a83616,reason=Created count=1 msg=Created container: task
0.5745,Event,ADDED,eval-conflicts-rho000-r4-083-h8xpb.18d4644c5a21359c,reason=Started count=1 msg=Started container task
0.5748,Event,ADDED,eval-conflicts-rho000-r4-083.18d4644c17c88345,reason=SuccessfulCreate count=1 msg=Created pod: eval-conflicts-rho000-r4-083-h8xpb
0.5749,Event,ADDED,eval-conflicts-rho000-r4-083.18d4644f615d83f1,reason=Completed count=1 msg=Job completed
0.5751,Event,ADDED,eval-conflicts-rho000-r4-084-f9qsd.18d4644c567bf578,reason=Scheduled count=None msg=Successfully assigned compute/eval-conflicts-rho000-r4-084-f9qsd to kind-worker
0.5753,Event,ADDED,eval-conflicts-rho000-r4-084-f9qsd.18d4644c71a03583,"reason=Pulled count=1 msg=Container image ""busybox:musl"" already present on machine"
0.5756,Event,ADDED,eval-conflicts-rho000-r4-084-f9qsd.18d4644c72bb2a9d,reason=Created count=1 msg=Created container: task
0.5758,Event,ADDED,eval-conflicts-rho000-r4-084-f9qsd.18d4644c74b40f6e,reason=Started count=1 msg=Started container task
0.5759,Event,ADDED,eval-conflicts-rho000-r4-084.18d4644c55644039,reason=SuccessfulCreate count=1 msg=Created pod: eval-conflicts-rho000-r4-084-f9qsd
0.5762,Event,ADDED,eval-conflicts-rho000-r4-084.18d4644f612f54df,reason=Completed count=1 msg=Job completed
0.5764,Event,ADDED,eval-conflicts-rho000-r4-085-zkrff.18d4644c9028bb0e,reason=Scheduled count=None msg=Successfully assigned compute/eval-conflicts-rho000-r4-085-zkrff to kind-worker
0.5766,Event,ADDED,eval-conflicts-rho000-r4-085-zkrff.18d4644caa1156c8,"reason=Pulled count=1 msg=Container image ""busybox:musl"" already present on machine"
0.5768,Event,ADDED,eval-conflicts-rho000-r4-085-zkrff.18d4644cab2e17a0,reason=Created count=1 msg=Created container: task
0.577,Event,ADDED,eval-conflicts-rho000-r4-085-zkrff.18d4644cad643dad,reason=Started count=1 msg=Started container task
0.5771,Event,ADDED,eval-conflicts-rho000-r4-085.18d4644c8f6209b9,reason=SuccessfulCreate count=1 msg=Created pod: eval-conflicts-rho000-r4-085-zkrff
0.5773,Event,ADDED,eval-conflicts-rho000-r4-085.18d4644fd71ced7b,reason=Completed count=1 msg=Job completed
0.5775,Event,ADDED,eval-conflicts-rho000-r4-086-l6zm8.18d4644ccbb3296b,reason=Scheduled count=None msg=Successfully assigned compute/eval-conflicts-rho000-r4-086-l6zm8 to kind-worker
0.5777,Event,ADDED,eval-conflicts-rho000-r4-086-l6zm8.18d4644ce6a88fbb,"reason=Pulled count=1 msg=Container image ""busybox:musl"" already present on machine"
0.5778,Event,ADDED,eval-conflicts-rho000-r4-086-l6zm8.18d4644ce7d453cf,reason=Created count=1 msg=Created container: task
0.578,Event,ADDED,eval-conflicts-rho000-r4-086-l6zm8.18d4644cec8a7627,reason=Started count=1 msg=Started container task
0.5782,Event,ADDED,eval-conflicts-rho000-r4-086.18d4644ccae8d8e7,reason=SuccessfulCreate count=1 msg=Created pod: eval-conflicts-rho000-r4-086-l6zm8
0.5784,Event,ADDED,eval-conflicts-rho000-r4-086.18d4645014030ffd,reason=Completed count=1 msg=Job completed
0.5785,Event,ADDED,eval-conflicts-rho000-r4-087-qxrq5.18d4644d0829aeca,reason=Scheduled count=None msg=Successfully assigned compute/eval-conflicts-rho000-r4-087-qxrq5 to kind-worker2
0.5787,Event,ADDED,eval-conflicts-rho000-r4-087-qxrq5.18d4644d21a4dd24,"reason=Pulled count=1 msg=Container image ""busybox:musl"" already present on machine"
0.579,Event,ADDED,eval-conflicts-rho000-r4-087-qxrq5.18d4644d22b24891,reason=Created count=1 msg=Created container: task
0.5791,Event,ADDED,eval-conflicts-rho000-r4-087-qxrq5.18d4644d28c42616,reason=Started count=1 msg=Started container task
0.5793,Event,ADDED,eval-conflicts-rho000-r4-087.18d4644d075e70d9,reason=SuccessfulCreate count=1 msg=Created pod: eval-conflicts-rho000-r4-087-qxrq5
0.5796,Event,ADDED,eval-conflicts-rho000-r4-087.18d46450345bb7f0,reason=Completed count=1 msg=Job completed
0.5797,Event,ADDED,eval-conflicts-rho000-r4-088-mc9rx.18d4644d4347095b,reason=Scheduled count=None msg=Successfully assigned compute/eval-conflicts-rho000-r4-088-mc9rx to kind-worker2
0.5799,Event,ADDED,eval-conflicts-rho000-r4-088-mc9rx.18d4644d5c8bc932,"reason=Pulled count=1 msg=Container image ""busybox:musl"" already present on machine"
0.5801,Event,ADDED,eval-conflicts-rho000-r4-088-mc9rx.18d4644d5dbec629,reason=Created count=1 msg=Created container: task
0.5805,Event,ADDED,eval-conflicts-rho000-r4-088-mc9rx.18d4644d618cad51,reason=Started count=1 msg=Started container task
0.5807,Event,ADDED,eval-conflicts-rho000-r4-088.18d4644d41db5805,reason=SuccessfulCreate count=1 msg=Created pod: eval-conflicts-rho000-r4-088-mc9rx
0.5809,Event,ADDED,eval-conflicts-rho000-r4-088.18d46450700b5740,reason=Completed count=1 msg=Job completed
0.581,Event,ADDED,eval-conflicts-rho000-r4-089-qpn44.18d4644d7efefd41,reason=Scheduled count=None msg=Successfully assigned compute/eval-conflicts-rho000-r4-089-qpn44 to kind-worker4
0.5814,Event,ADDED,eval-conflicts-rho000-r4-089-qpn44.18d4644d98017ac3,"reason=Pulled count=1 msg=Container image ""busybox:musl"" already present on machine"
0.5816,Event,ADDED,eval-conflicts-rho000-r4-089-qpn44.18d4644d993e2524,reason=Created count=1 msg=Created container: task
0.5818,Event,ADDED,eval-conflicts-rho000-r4-089-qpn44.18d4644d9cccf696,reason=Started count=1 msg=Started container task
0.5821,Event,ADDED,eval-conflicts-rho000-r4-089.18d4644d7e03dc79,reason=SuccessfulCreate count=1 msg=Created pod: eval-conflicts-rho000-r4-089-qpn44
0.5823,Event,ADDED,eval-conflicts-rho000-r4-089.18d46450a78ae7d7,reason=Completed count=1 msg=Job completed
0.5824,Event,ADDED,eval-conflicts-rho000-r4-090-c54xj.18d4644dba145f9c,reason=Scheduled count=None msg=Successfully assigned compute/eval-conflicts-rho000-r4-090-c54xj to kind-worker2
0.5826,Event,ADDED,eval-conflicts-rho000-r4-090-c54xj.18d4644dd507b4f8,"reason=Pulled count=1 msg=Container image ""busybox:musl"" already present on machine"
0.5828,Event,ADDED,eval-conflicts-rho000-r4-090-c54xj.18d4644dd636462a,reason=Created count=1 msg=Created container: task
0.5831,Event,ADDED,eval-conflicts-rho000-r4-090-c54xj.18d4644dd88b8320,reason=Started count=1 msg=Started container task
0.5832,Event,ADDED,eval-conflicts-rho000-r4-090.18d4644db8d69365,reason=SuccessfulCreate count=1 msg=Created pod: eval-conflicts-rho000-r4-090-c54xj
0.5834,Event,ADDED,eval-conflicts-rho000-r4-090.18d46450e86f129d,reason=Completed count=1 msg=Job completed
0.5836,Event,ADDED,eval-conflicts-rho000-r4-091-kn7br.18d4644e0901475d,reason=Scheduled count=None msg=Successfully assigned compute/eval-conflicts-rho000-r4-091-kn7br to kind-worker4
0.5837,Event,ADDED,eval-conflicts-rho000-r4-091-kn7br.18d4644e2337bd08,"reason=Pulled count=1 msg=Container image ""busybox:musl"" already present on machine"
0.5839,Event,ADDED,eval-conflicts-rho000-r4-091-kn7br.18d4644e24833ac5,reason=Created count=1 msg=Created container: task
0.5842,Event,ADDED,eval-conflicts-rho000-r4-091-kn7br.18d4644e2919e45e,reason=Started count=1 msg=Started container task
0.5844,Event,ADDED,eval-conflicts-rho000-r4-091.18d4644e077cef9e,reason=SuccessfulCreate count=1 msg=Created pod: eval-conflicts-rho000-r4-091-kn7br
0.5846,Event,ADDED,eval-conflicts-rho000-r4-091.18d464515ab81323,reason=Completed count=1 msg=Job completed
0.5847,Event,ADDED,eval-conflicts-rho000-r4-092-8q5m9.18d4644e31995a7f,reason=Scheduled count=None msg=Successfully assigned compute/eval-conflicts-rho000-r4-092-8q5m9 to kind-worker2
0.585,Event,ADDED,eval-conflicts-rho000-r4-092-8q5m9.18d4644e4bc8dd42,"reason=Pulled count=1 msg=Container image ""busybox:musl"" already present on machine"
0.5852,Event,ADDED,eval-conflicts-rho000-r4-092-8q5m9.18d4644e4cfe608e,reason=Created count=1 msg=Created container: task
0.5854,Event,ADDED,eval-conflicts-rho000-r4-092-8q5m9.18d4644e4f4101f7,reason=Started count=1 msg=Started container task
0.5857,Event,ADDED,eval-conflicts-rho000-r4-092.18d4644e3043ee82,reason=SuccessfulCreate count=1 msg=Created pod: eval-conflicts-rho000-r4-092-8q5m9
0.5858,Event,ADDED,eval-conflicts-rho000-r4-092.18d46451603d9636,reason=Completed count=1 msg=Job completed
0.586,Event,ADDED,eval-conflicts-rho000-r4-093-7k2vw.18d4644e6d9c27aa,reason=Scheduled count=None msg=Successfully assigned compute/eval-conflicts-rho000-r4-093-7k2vw to kind-worker4
0.5862,Event,ADDED,eval-conflicts-rho000-r4-093-7k2vw.18d4644e875ae2c3,"reason=Pulled count=1 msg=Container image ""busybox:musl"" already present on machine"
0.5864,Event,ADDED,eval-conflicts-rho000-r4-093-7k2vw.18d4644e88834377,reason=Created count=1 msg=Created container: task
0.5865,Event,ADDED,eval-conflicts-rho000-r4-093-7k2vw.18d4644e8a9023c5,reason=Started count=1 msg=Started container task
0.5867,Event,ADDED,eval-conflicts-rho000-r4-093.18d4644e6c3a4f05,reason=SuccessfulCreate count=1 msg=Created pod: eval-conflicts-rho000-r4-093-7k2vw
0.5869,Event,ADDED,eval-conflicts-rho000-r4-093.18d46451d2a557dc,reason=Completed count=1 msg=Job completed
0.587,Event,ADDED,eval-conflicts-rho000-r4-094-n58dn.18d4644ea85cc871,reason=Scheduled count=None msg=Successfully assigned compute/eval-conflicts-rho000-r4-094-n58dn to kind-worker2
0.5872,Event,ADDED,eval-conflicts-rho000-r4-094-n58dn.18d4644ec18e526c,"reason=Pulled count=1 msg=Container image ""busybox:musl"" already present on machine"
0.5874,Event,ADDED,eval-conflicts-rho000-r4-094-n58dn.18d4644ec2a96399,reason=Created count=1 msg=Created container: task
0.5876,Event,ADDED,eval-conflicts-rho000-r4-094-n58dn.18d4644ec4c1ed04,reason=Started count=1 msg=Started container task
0.5877,Event,ADDED,eval-conflicts-rho000-r4-094.18d4644ea763f057,reason=SuccessfulCreate count=1 msg=Created pod: eval-conflicts-rho000-r4-094-n58dn
0.5879,Event,ADDED,eval-conflicts-rho000-r4-094.18d46451d7516165,reason=Completed count=1 msg=Job completed
0.5881,Event,ADDED,eval-conflicts-rho000-r4-095-fllnt.18d4644ee3de97cb,reason=Scheduled count=None msg=Successfully assigned compute/eval-conflicts-rho000-r4-095-fllnt to kind-worker4
0.5882,Event,ADDED,eval-conflicts-rho000-r4-095-fllnt.18d4644efd8e774e,"reason=Pulled count=1 msg=Container image ""busybox:musl"" already present on machine"
0.5884,Event,ADDED,eval-conflicts-rho000-r4-095-fllnt.18d4644efeb661eb,reason=Created count=1 msg=Created container: task
0.5886,Event,ADDED,eval-conflicts-rho000-r4-095-fllnt.18d4644f00ddb96d,reason=Started count=1 msg=Started container task
0.5887,Event,ADDED,eval-conflicts-rho000-r4-095.18d4644ee2ead6ab,reason=SuccessfulCreate count=1 msg=Created pod: eval-conflicts-rho000-r4-095-fllnt
0.589,Event,ADDED,eval-conflicts-rho000-r4-095.18d464520e7be5f7,reason=Completed count=1 msg=Job completed
0.5891,Event,ADDED,eval-conflicts-rho000-r4-096-4zvn2.18d4644f21a6751b,reason=Scheduled count=None msg=Successfully assigned compute/eval-conflicts-rho000-r4-096-4zvn2 to kind-worker2
0.5893,Event,ADDED,eval-conflicts-rho000-r4-096-4zvn2.18d4644f6028143c,"reason=Pulled count=1 msg=Container image ""busybox:musl"" already present on machine"
0.5895,Event,ADDED,eval-conflicts-rho000-r4-096-4zvn2.18d4644f61c2bcbe,reason=Created count=1 msg=Created container: task
0.5897,Event,ADDED,eval-conflicts-rho000-r4-096-4zvn2.18d4644f65782bb8,reason=Started count=1 msg=Started container task
0.5898,Event,ADDED,eval-conflicts-rho000-r4-096.18d4644f1e9d7e4d,reason=SuccessfulCreate count=1 msg=Created pod: eval-conflicts-rho000-r4-096-4zvn2
0.59,Event,ADDED,eval-conflicts-rho000-r4-096.18d464528ab821e7,reason=Completed count=1 msg=Job completed
0.5903,Event,ADDED,eval-conflicts-rho000-r4-097-cb9sj.18d4644f5ad12eb1,reason=Scheduled count=None msg=Successfully assigned compute/eval-conflicts-rho000-r4-097-cb9sj to kind-worker3
0.5904,Event,ADDED,eval-conflicts-rho000-r4-097-cb9sj.18d4644f74061f04,"reason=Pulled count=1 msg=Container image ""busybox:musl"" already present on machine"
0.5906,Event,ADDED,eval-conflicts-rho000-r4-097-cb9sj.18d4644f751cec8c,reason=Created count=1 msg=Created container: task
0.5908,Event,ADDED,eval-conflicts-rho000-r4-097-cb9sj.18d4644f771bc222,reason=Started count=1 msg=Started container task
0.591,Event,ADDED,eval-conflicts-rho000-r4-097.18d4644f5a72edf4,reason=SuccessfulCreate count=1 msg=Created pod: eval-conflicts-rho000-r4-097-cb9sj
0.5911,Event,ADDED,eval-conflicts-rho000-r4-097.18d4645284170f9e,reason=Completed count=1 msg=Job completed
0.5913,Event,ADDED,eval-conflicts-rho000-r4-098-hr82q.18d4644f9652c7ae,reason=Scheduled count=None msg=Successfully assigned compute/eval-conflicts-rho000-r4-098-hr82q to kind-worker3
0.5915,Event,ADDED,eval-conflicts-rho000-r4-098-hr82q.18d4644faf9beba1,"reason=Pulled count=1 msg=Container image ""busybox:musl"" already present on machine"
0.5916,Event,ADDED,eval-conflicts-rho000-r4-098-hr82q.18d4644fb0bc6820,reason=Created count=1 msg=Created container: task
0.5918,Event,ADDED,eval-conflicts-rho000-r4-098-hr82q.18d4644fb2e7c815,reason=Started count=1 msg=Started container task
0.592,Event,ADDED,eval-conflicts-rho000-r4-098.18d4644f95c7f7fe,reason=SuccessfulCreate count=1 msg=Created pod: eval-conflicts-rho000-r4-098-hr82q
0.5922,Event,ADDED,eval-conflicts-rho000-r4-098.18d46452bfb72d7b,reason=Completed count=1 msg=Job completed
0.5923,Event,ADDED,eval-conflicts-rho000-r4-099-4m7d6.18d4644fd31357ec,reason=Scheduled count=None msg=Successfully assigned compute/eval-conflicts-rho000-r4-099-4m7d6 to kind-worker3
0.5925,Event,ADDED,eval-conflicts-rho000-r4-099-4m7d6.18d4644fec33e5f8,"reason=Pulled count=1 msg=Container image ""busybox:musl"" already present on machine"
0.5927,Event,ADDED,eval-conflicts-rho000-r4-099-4m7d6.18d4644fed6515ae,reason=Created count=1 msg=Created container: task
0.5928,Event,ADDED,eval-conflicts-rho000-r4-099-4m7d6.18d4644ff1cead12,reason=Started count=1 msg=Started container task
0.593,Event,ADDED,eval-conflicts-rho000-r4-099.18d4644fd250692f,reason=SuccessfulCreate count=1 msg=Created pod: eval-conflicts-rho000-r4-099-4m7d6
0.5932,Event,ADDED,eval-conflicts-rho000-r4-099.18d4645337eb96cb,reason=Completed count=1 msg=Job completed
0.5933,Event,ADDED,eval-conflicts-rho000-r5-000-rxvrg.18d4645864967f39,reason=Scheduled count=None msg=Successfully assigned compute/eval-conflicts-rho000-r5-000-rxvrg to kind-worker2
0.5935,Event,ADDED,eval-conflicts-rho000-r5-000-rxvrg.18d464587ec30d51,"reason=Pulled count=1 msg=Container image ""busybox:musl"" already present on machine"
0.5936,Event,ADDED,eval-conflicts-rho000-r5-000-rxvrg.18d464587fdc7d2b,reason=Created count=1 msg=Created container: task
0.5938,Event,ADDED,eval-conflicts-rho000-r5-000-rxvrg.18d46458824b9235,reason=Started count=1 msg=Started container task
0.594,Event,ADDED,eval-conflicts-rho000-r5-000.18d4645863a714d9,reason=SuccessfulCreate count=1 msg=Created pod: eval-conflicts-rho000-r5-000-rxvrg
0.5941,Event,ADDED,eval-conflicts-rho000-r5-000.18d4645b6aefbb89,reason=Completed count=1 msg=Job completed
0.5943,Event,ADDED,eval-conflicts-rho000-r5-001-66rrx.18d464589eef7a5e,reason=Scheduled count=None msg=Successfully assigned compute/eval-conflicts-rho000-r5-001-66rrx to kind-worker
0.5944,Event,ADDED,eval-conflicts-rho000-r5-001-66rrx.18d46458b869c939,"reason=Pulled count=1 msg=Container image ""busybox:musl"" already present on machine"
0.5946,Event,ADDED,eval-conflicts-rho000-r5-001-66rrx.18d46458b9824fc8,reason=Created count=1 msg=Created container: task
0.5948,Event,ADDED,eval-conflicts-rho000-r5-001-66rrx.18d46458bdd64daf,reason=Started count=1 msg=Started container task
0.5949,Event,ADDED,eval-conflicts-rho000-r5-001.18d464589deb3fa7,reason=SuccessfulCreate count=1 msg=Created pod: eval-conflicts-rho000-r5-001-66rrx
0.5951,Event,ADDED,eval-conflicts-rho000-r5-001.18d4645bfb2ccb5d,reason=Completed count=1 msg=Job completed
0.5953,Event,ADDED,eval-conflicts-rho000-r5-002-2bgxl.18d46458da301c73,reason=Scheduled count=None msg=Successfully assigned compute/eval-conflicts-rho000-r5-002-2bgxl to kind-worker
0.5954,Event,ADDED,eval-conflicts-rho000-r5-002-2bgxl.18d46458f35196c1,"reason=Pulled count=1 msg=Container image ""busybox:musl"" already present on machine"
0.5957,Event,ADDED,eval-conflicts-rho000-r5-002-2bgxl.18d46458f47079b1,reason=Created count=1 msg=Created container: task
0.5958,Event,ADDED,eval-conflicts-rho000-r5-002-2bgxl.18d46458f69e80eb,reason=Started count=1 msg=Started container task
0.596,Event,ADDED,eval-conflicts-rho000-r5-002.18d46458d95391d7,reason=SuccessfulCreate count=1 msg=Created pod: eval-conflicts-rho000-r5-002-2bgxl
0.5961,Event,ADDED,eval-conflicts-rho000-r5-002.18d4645c36995c33,reason=Completed count=1 msg=Job completed
0.5963,Event,ADDED,eval-conflicts-rho000-r5-003-lj8gz.18d46459151b1b9a,reason=Scheduled count=None msg=Successfully assigned compute/eval-conflicts-rho000-r5-003-lj8gz to kind-worker5
0.5965,Event,ADDED,eval-conflicts-rho000-r5-003-lj8gz.18d464592ee6dcac,"reason=Pulled count=1 msg=Container image ""busybox:musl"" already present on machine"
0.5966,Event,ADDED,eval-conflicts-rho000-r5-003-lj8gz.18d464592ffc0a38,reason=Created count=1 msg=Created container: task
0.5968,Event,ADDED,eval-conflicts-rho000-r5-003-lj8gz.18d4645933d6ec6e,reason=Started count=1 msg=Started container task
0.597,Event,ADDED,eval-conflicts-rho000-r5-003.18d46459145f1e03,reason=SuccessfulCreate count=1 msg=Created pod: eval-conflicts-rho000-r5-003-lj8gz
0.5971,Event,ADDED,eval-conflicts-rho000-r5-003.18d4645c7866e2ae,reason=Completed count=1 msg=Job completed
0.5973,Event,ADDED,eval-conflicts-rho000-r5-004-mn877.18d46459516d2304,reason=Scheduled count=None msg=Successfully assigned compute/eval-conflicts-rho000-r5-004-mn877 to kind-worker5
0.5974,Event,ADDED,eval-conflicts-rho000-r5-004-mn877.18d464596accd712,"reason=Pulled count=1 msg=Container image ""busybox:musl"" already present on machine"
0.5976,Event,ADDED,eval-conflicts-rho000-r5-004-mn877.18d464596be2cca1,reason=Created count=1 msg=Created container: task
0.5978,Event,ADDED,eval-conflicts-rho000-r5-004-mn877.18d464596f4dc0d4,reason=Started count=1 msg=Started container task
0.5979,Event,ADDED,eval-conflicts-rho000-r5-004.18d4645950420edd,reason=SuccessfulCreate count=1 msg=Created pod: eval-conflicts-rho000-r5-004-mn877
0.5981,Event,ADDED,eval-conflicts-rho000-r5-004.18d4645cb461bf0c,reason=Completed count=1 msg=Job completed
0.5982,Event,ADDED,eval-conflicts-rho000-r5-005-4wnpp.18d464598ca569a2,reason=Scheduled count=None msg=Successfully assigned compute/eval-conflicts-rho000-r5-005-4wnpp to kind-worker5
0.5984,Event,ADDED,eval-conflicts-rho000-r5-005-4wnpp.18d46459a605fd80,"reason=Pulled count=1 msg=Container image ""busybox:musl"" already present on machine"
0.5986,Event,ADDED,eval-conflicts-rho000-r5-005-4wnpp.18d46459a7472016,reason=Created count=1 msg=Created container: task
0.5987,Event,ADDED,eval-conflicts-rho000-r5-005-4wnpp.18d46459a957dfdd,reason=Started count=1 msg=Started container task
0.599,Event,ADDED,eval-conflicts-rho000-r5-005.18d464598bbacaa3,reason=SuccessfulCreate count=1 msg=Created pod: eval-conflicts-rho000-r5-005-4wnpp
0.5991,Event,ADDED,eval-conflicts-rho000-r5-005.18d4645cb43d63b6,reason=Completed count=1 msg=Job completed
0.5993,Event,ADDED,eval-conflicts-rho000-r5-006-7sjf4.18d46459c851c106,reason=Scheduled count=None msg=Successfully assigned compute/eval-conflicts-rho000-r5-006-7sjf4 to kind-worker5
0.5994,Event,ADDED,eval-conflicts-rho000-r5-006-7sjf4.18d46459e2321402,"reason=Pulled count=1 msg=Container image ""busybox:musl"" already present on machine"
0.5996,Event,ADDED,eval-conflicts-rho000-r5-006-7sjf4.18d46459e34cf0ef,reason=Created count=1 msg=Created container: task
0.5998,Event,ADDED,eval-conflicts-rho000-r5-006-7sjf4.18d46459e573c15c,reason=Started count=1 msg=Started container task
0.6004,Event,ADDED,eval-conflicts-rho000-r5-006.18d46459c74f620d,reason=SuccessfulCreate count=1 msg=Created pod: eval-conflicts-rho000-r5-006-7sjf4
0.6006,Event,ADDED,eval-conflicts-rho000-r5-006.18d4645cf05c8edb,reason=Completed count=1 msg=Job completed
0.6007,Event,ADDED,eval-conflicts-rho000-r5-007-lsqzm.18d4645a03fc1d11,reason=Scheduled count=None msg=Successfully assigned compute/eval-conflicts-rho000-r5-007-lsqzm to kind-worker4
0.6011,Event,ADDED,eval-conflicts-rho000-r5-007-lsqzm.18d4645a1d9904a5,"reason=Pulled count=1 msg=Container image ""busybox:musl"" already present on machine"
0.6013,Event,ADDED,eval-conflicts-rho000-r5-007-lsqzm.18d4645a1ebf6d59,reason=Created count=1 msg=Created container: task
0.6015,Event,ADDED,eval-conflicts-rho000-r5-007-lsqzm.18d4645a21054403,reason=Started count=1 msg=Started container task
0.6016,Event,ADDED,eval-conflicts-rho000-r5-007.18d4645a03373263,reason=SuccessfulCreate count=1 msg=Created pod: eval-conflicts-rho000-r5-007-lsqzm
0.6022,Event,ADDED,eval-conflicts-rho000-r5-007.18d4645d4197f669,reason=Completed count=1 msg=Job completed
0.6024,Event,ADDED,eval-conflicts-rho000-r5-008-ppjh7.18d4645a3f7cee3b,reason=Scheduled count=None msg=Successfully assigned compute/eval-conflicts-rho000-r5-008-ppjh7 to kind-worker
0.6026,Event,ADDED,eval-conflicts-rho000-r5-008-ppjh7.18d4645a5902644d,"reason=Pulled count=1 msg=Container image ""busybox:musl"" already present on machine"
0.6029,Event,ADDED,eval-conflicts-rho000-r5-008-ppjh7.18d4645a5a0ae0cf,reason=Created count=1 msg=Created container: task
0.6032,Event,ADDED,eval-conflicts-rho000-r5-008-ppjh7.18d4645a5c081807,reason=Started count=1 msg=Started container task
0.6034,Event,ADDED,eval-conflicts-rho000-r5-008.18d4645a3e7e29cd,reason=SuccessfulCreate count=1 msg=Created pod: eval-conflicts-rho000-r5-008-ppjh7
0.6036,Event,ADDED,eval-conflicts-rho000-r5-008.18d4645d9d151475,reason=Completed count=1 msg=Job completed
0.6039,Event,ADDED,eval-conflicts-rho000-r5-009-2x479.18d4645a7bbef824,reason=Scheduled count=None msg=Successfully assigned compute/eval-conflicts-rho000-r5-009-2x479 to kind-worker4
0.6041,Event,ADDED,eval-conflicts-rho000-r5-009-2x479.18d4645a97142af5,"reason=Pulled count=1 msg=Container image ""busybox:musl"" already present on machine"
0.6043,Event,ADDED,eval-conflicts-rho000-r5-009-2x479.18d4645a983a6155,reason=Created count=1 msg=Created container: task
0.6044,Event,ADDED,eval-conflicts-rho000-r5-009-2x479.18d4645a9c442fbe,reason=Started count=1 msg=Started container task
0.6047,Event,ADDED,eval-conflicts-rho000-r5-009.18d4645a7afb7766,reason=SuccessfulCreate count=1 msg=Created pod: eval-conflicts-rho000-r5-009-2x479
0.6049,Event,ADDED,eval-conflicts-rho000-r5-009.18d4645db97fd431,reason=Completed count=1 msg=Job completed
0.6055,Event,ADDED,eval-conflicts-rho000-r5-010-87khk.18d4645ab69822d8,reason=Scheduled count=None msg=Successfully assigned compute/eval-conflicts-rho000-r5-010-87khk to kind-worker4
0.6057,Event,ADDED,eval-conflicts-rho000-r5-010-87khk.18d4645ad01f51ab,"reason=Pulled count=1 msg=Container image ""busybox:musl"" already present on machine"
0.6058,Event,ADDED,eval-conflicts-rho000-r5-010-87khk.18d4645ad12d2583,reason=Created count=1 msg=Created container: task
0.6061,Event,ADDED,eval-conflicts-rho000-r5-010-87khk.18d4645ad635eab1,reason=Started count=1 msg=Started container task
0.6063,Event,ADDED,eval-conflicts-rho000-r5-010.18d4645ab5cb7955,reason=SuccessfulCreate count=1 msg=Created pod: eval-conflicts-rho000-r5-010-87khk
0.6065,Event,ADDED,eval-conflicts-rho000-r5-010.18d4645df53279df,reason=Completed count=1 msg=Job completed
0.6067,Event,ADDED,eval-conflicts-rho000-r5-011-nxt5j.18d4645af2e65981,reason=Scheduled count=None msg=Successfully assigned compute/eval-conflicts-rho000-r5-011-nxt5j to kind-worker4
0.607,Event,ADDED,eval-conflicts-rho000-r5-011-nxt5j.18d4645b0e303fa0,"reason=Pulled count=1 msg=Container image ""busybox:musl"" already present on machine"
0.6071,Event,ADDED,eval-conflicts-rho000-r5-011-nxt5j.18d4645b0f60c88b,reason=Created count=1 msg=Created container: task
0.6073,Event,ADDED,eval-conflicts-rho000-r5-011-nxt5j.18d4645b11843305,reason=Started count=1 msg=Started container task
0.6075,Event,ADDED,eval-conflicts-rho000-r5-011.18d4645af207151c,reason=SuccessfulCreate count=1 msg=Created pod: eval-conflicts-rho000-r5-011-nxt5j
0.6078,Event,ADDED,eval-conflicts-rho000-r5-011.18d4645e30a30588,reason=Completed count=1 msg=Job completed
0.608,Event,ADDED,eval-conflicts-rho000-r5-012-hdkz7.18d4645b2ec2c2a4,reason=Scheduled count=None msg=Successfully assigned compute/eval-conflicts-rho000-r5-012-hdkz7 to kind-worker3
0.6082,Event,ADDED,eval-conflicts-rho000-r5-012-hdkz7.18d4645b48ae0464,"reason=Pulled count=1 msg=Container image ""busybox:musl"" already present on machine"
0.6084,Event,ADDED,eval-conflicts-rho000-r5-012-hdkz7.18d4645b49c3a7fe,reason=Created count=1 msg=Created container: task
0.6086,Event,ADDED,eval-conflicts-rho000-r5-012-hdkz7.18d4645b4c27b9b7,reason=Started count=1 msg=Started container task
0.6088,Event,ADDED,eval-conflicts-rho000-r5-012.18d4645b2dedc91e,reason=SuccessfulCreate count=1 msg=Created pod: eval-conflicts-rho000-r5-012-hdkz7
0.609,Event,ADDED,eval-conflicts-rho000-r5-012.18d4645e6c875778,reason=Completed count=1 msg=Job completed
0.6092,Event,ADDED,eval-conflicts-rho000-r5-013-2vkh7.18d4645b6af030d4,reason=Scheduled count=None msg=Successfully assigned compute/eval-conflicts-rho000-r5-013-2vkh7 to kind-worker3
0.6094,Event,ADDED,eval-conflicts-rho000-r5-013-2vkh7.18d4645b84990b50,"reason=Pulled count=1 msg=Container image ""busybox:musl"" already present on machine"
0.6096,Event,ADDED,eval-conflicts-rho000-r5-013-2vkh7.18d4645b85bf4af4,reason=Created count=1 msg=Created container: task
0.6098,Event,ADDED,eval-conflicts-rho000-r5-013-2vkh7.18d4645b8eb05123,reason=Started count=1 msg=Started container task
0.61,Event,ADDED,eval-conflicts-rho000-r5-013.18d4645b69bb1fec,reason=SuccessfulCreate count=1 msg=Created pod: eval-conflicts-rho000-r5-013-2vkh7
0.6102,Event,ADDED,eval-conflicts-rho000-r5-013.18d4645ea7f97fec,reason=Completed count=1 msg=Job completed
0.6104,Event,ADDED,eval-conflicts-rho000-r5-014-6gzgm.18d4645ba495e7ad,reason=Scheduled count=None msg=Successfully assigned compute/eval-conflicts-rho000-r5-014-6gzgm to kind-worker3
0.6105,Event,ADDED,eval-conflicts-rho000-r5-014-6gzgm.18d4645bbee323a3,"reason=Pulled count=1 msg=Container image ""busybox:musl"" already present on machine"
0.6107,Event,ADDED,eval-conflicts-rho000-r5-014-6gzgm.18d4645bc0316434,reason=Created count=1 msg=Created container: task
0.6109,Event,ADDED,eval-conflicts-rho000-r5-014-6gzgm.18d4645bc3700237,reason=Started count=1 msg=Started container task
0.611,Event,ADDED,eval-conflicts-rho000-r5-014.18d4645ba40b84d6,reason=SuccessfulCreate count=1 msg=Created pod: eval-conflicts-rho000-r5-014-6gzgm
0.6115,Event,ADDED,eval-conflicts-rho000-r5-014.18d4645ee3ddf965,reason=Completed count=1 msg=Job completed
0.6116,Event,ADDED,eval-conflicts-rho000-r5-015-mdksr.18d4645be0bd53e2,reason=Scheduled count=None msg=Successfully assigned compute/eval-conflicts-rho000-r5-015-mdksr to kind-worker3
0.6118,Event,ADDED,eval-conflicts-rho000-r5-015-mdksr.18d4645bfa51e5f3,"reason=Pulled count=1 msg=Container image ""busybox:musl"" already present on machine"
0.6122,Event,ADDED,eval-conflicts-rho000-r5-015-mdksr.18d4645bfbba5205,reason=Created count=1 msg=Created container: task
0.6124,Event,ADDED,eval-conflicts-rho000-r5-015-mdksr.18d4645bff635e3b,reason=Started count=1 msg=Started container task
0.6126,Event,ADDED,eval-conflicts-rho000-r5-015.18d4645be03d03e1,reason=SuccessfulCreate count=1 msg=Created pod: eval-conflicts-rho000-r5-015-mdksr
0.6128,Event,ADDED,eval-conflicts-rho000-r5-015.18d4645f200bc10c,reason=Completed count=1 msg=Job completed
0.6131,Event,ADDED,eval-conflicts-rho000-r5-016-twmpz.18d4645c1c32de0a,reason=Scheduled count=None msg=Successfully assigned compute/eval-conflicts-rho000-r5-016-twmpz to kind-worker3
0.6133,Event,ADDED,eval-conflicts-rho000-r5-016-twmpz.18d4645c35f74332,"reason=Pulled count=1 msg=Container image ""busybox:musl"" already present on machine"
0.6135,Event,ADDED,eval-conflicts-rho000-r5-016-twmpz.18d4645c373274f3,reason=Created count=1 msg=Created container: task
0.6138,Event,ADDED,eval-conflicts-rho000-r5-016-twmpz.18d4645c393532d2,reason=Started count=1 msg=Started container task
0.614,Event,ADDED,eval-conflicts-rho000-r5-016.18d4645c1b889de2,reason=SuccessfulCreate count=1 msg=Created pod: eval-conflicts-rho000-r5-016-twmpz
0.6142,Event,ADDED,eval-conflicts-rho000-r5-016.18d4645f5bdd83ed,reason=Completed count=1 msg=Job completed
0.6144,Event,ADDED,eval-conflicts-rho000-r5-017-f6n5x.18d4645c575b9198,reason=Scheduled count=None msg=Successfully assigned compute/eval-conflicts-rho000-r5-017-f6n5x to kind-worker3
0.6148,Event,ADDED,eval-conflicts-rho000-r5-017-f6n5x.18d4645c6ffd73ab,"reason=Pulled count=1 msg=Container image ""busybox:musl"" already present on machine"
0.6149,Event,ADDED,eval-conflicts-rho000-r5-017-f6n5x.18d4645c7114069f,reason=Created count=1 msg=Created container: task
0.6151,Event,ADDED,eval-conflicts-rho000-r5-017-f6n5x.18d4645c7401dc08,reason=Started count=1 msg=Started container task
0.6153,Event,ADDED,eval-conflicts-rho000-r5-017.18d4645c56d7cc6c,reason=SuccessfulCreate count=1 msg=Created pod: eval-conflicts-rho000-r5-017-f6n5x
0.6155,Event,ADDED,eval-conflicts-rho000-r5-017.18d4645f98033204,reason=Completed count=1 msg=Job completed
0.6156,Event,ADDED,eval-conflicts-rho000-r5-018-zwvqq.18d4645c92e437f1,reason=Scheduled count=None msg=Successfully assigned compute/eval-conflicts-rho000-r5-018-zwvqq to kind-worker3
0.6158,Event,ADDED,eval-conflicts-rho000-r5-018-zwvqq.18d4645cac714de6,"reason=Pulled count=1 msg=Container image ""busybox:musl"" already present on machine"
0.616,Event,ADDED,eval-conflicts-rho000-r5-018-zwvqq.18d4645cad991587,reason=Created count=1 msg=Created container: task
0.6161,Event,ADDED,eval-conflicts-rho000-r5-018-zwvqq.18d4645cafc1c5da,reason=Started count=1 msg=Started container task
0.6163,Event,ADDED,eval-conflicts-rho000-r5-018.18d4645c9254e573,reason=SuccessfulCreate count=1 msg=Created pod: eval-conflicts-rho000-r5-018-zwvqq
0.6165,Event,ADDED,eval-conflicts-rho000-r5-018.18d4645fd3a12d6d,reason=Completed count=1 msg=Job completed
0.6166,Event,ADDED,eval-conflicts-rho000-r5-019-hr64g.18d4645ccf310748,reason=Scheduled count=None msg=Successfully assigned compute/eval-conflicts-rho000-r5-019-hr64g to kind-worker3
0.617,Event,ADDED,eval-conflicts-rho000-r5-019-hr64g.18d4645ce8d01071,"reason=Pulled count=1 msg=Container image ""busybox:musl"" already present on machine"
0.6172,Event,ADDED,eval-conflicts-rho000-r5-019-hr64g.18d4645ce9e28851,reason=Created count=1 msg=Created container: task
0.6173,Event,ADDED,eval-conflicts-rho000-r5-019-hr64g.18d4645cebfc06dc,reason=Started count=1 msg=Started container task
0.6175,Event,ADDED,eval-conflicts-rho000-r5-019.18d4645cce8ef49c,reason=SuccessfulCreate count=1 msg=Created pod: eval-conflicts-rho000-r5-019-hr64g
0.6177,Event,ADDED,eval-conflicts-rho000-r5-019.18d464600fb49df3,reason=Completed count=1 msg=Job completed
0.6178,Event,ADDED,eval-conflicts-rho000-r5-020-dfxhp.18d4645d0a43c98e,"reason=FailedScheduling count=None msg=0/6 nodes are available: 6 node(s) had untolerated taint(s). no new claims to deallocate, preemption: 0/6 nodes are available: 6 Preemption is not helpful for scheduling."
0.618,Event,ADDED,eval-conflicts-rho000-r5-020-dfxhp.18d4645da1019e41,reason=Scheduled count=None msg=Successfully assigned compute/eval-conflicts-rho000-r5-020-dfxhp to kind-worker2
0.6182,Event,ADDED,eval-conflicts-rho000-r5-020-dfxhp.18d4645dc0226b7d,"reason=Pulled count=1 msg=Container image ""busybox:musl"" already present on machine"
0.6183,Event,ADDED,eval-conflicts-rho000-r5-020-dfxhp.18d4645dc22bdf3e,reason=Created count=1 msg=Created container: task
0.6185,Event,ADDED,eval-conflicts-rho000-r5-020-dfxhp.18d4645dc600535c,reason=Started count=1 msg=Started container task
0.6187,Event,ADDED,eval-conflicts-rho000-r5-020.18d4645d0a37afe6,reason=SuccessfulCreate count=1 msg=Created pod: eval-conflicts-rho000-r5-020-dfxhp
0.6188,Event,ADDED,eval-conflicts-rho000-r5-020.18d46460c8f2b6af,reason=Completed count=1 msg=Job completed
0.619,Event,ADDED,eval-conflicts-rho000-r5-021-ldqtk.18d4645d4543b539,"reason=FailedScheduling count=None msg=0/6 nodes are available: 6 node(s) had untolerated taint(s). no new claims to deallocate, preemption: 0/6 nodes are available: 6 Preemption is not helpful for scheduling."
0.6191,Event,ADDED,eval-conflicts-rho000-r5-021-ldqtk.18d4645da141aff2,reason=Scheduled count=None msg=Successfully assigned compute/eval-conflicts-rho000-r5-021-ldqtk to kind-worker2
0.6193,Event,ADDED,eval-conflicts-rho000-r5-021-ldqtk.18d4645dc068ce7d,"reason=Pulled count=1 msg=Container image ""busybox:musl"" already present on machine"
0.6195,Event,ADDED,eval-conflicts-rho000-r5-021-ldqtk.18d4645dc2c603d6,reason=Created count=1 msg=Created container: task
0.6196,Event,ADDED,eval-conflicts-rho000-r5-021-ldqtk.18d4645dc65297bb,reason=Started count=1 msg=Started container task
0.6198,Event,ADDED,eval-conflicts-rho000-r5-021.18d4645d45387113,reason=SuccessfulCreate count=1 msg=Created pod: eval-conflicts-rho000-r5-021-ldqtk
0.62,Event,ADDED,eval-conflicts-rho000-r5-021.18d4646103e10f48,reason=Completed count=1 msg=Job completed
0.6201,Event,ADDED,eval-conflicts-rho000-r5-022-lf8gl.18d4645d80d8986c,"reason=FailedScheduling count=None msg=0/6 nodes are available: 6 node(s) had untolerated taint(s). no new claims to deallocate, preemption: 0/6 nodes are available: 6 Preemption is not helpful for scheduling."
0.6203,Event,ADDED,eval-conflicts-rho000-r5-022-lf8gl.18d4645da1896d18,reason=Scheduled count=None msg=Successfully assigned compute/eval-conflicts-rho000-r5-022-lf8gl to kind-worker2
0.6204,Event,ADDED,eval-conflicts-rho000-r5-022-lf8gl.18d4645dc03fefad,"reason=Pulled count=1 msg=Container image ""busybox:musl"" already present on machine"
0.6206,Event,ADDED,eval-conflicts-rho000-r5-022-lf8gl.18d4645dc28b306f,reason=Created count=1 msg=Created container: task
0.6208,Event,ADDED,eval-conflicts-rho000-r5-022-lf8gl.18d4645dc65297b2,reason=Started count=1 msg=Started container task
0.6209,Event,ADDED,eval-conflicts-rho000-r5-022.18d4645d80ca5a2e,reason=SuccessfulCreate count=1 msg=Created pod: eval-conflicts-rho000-r5-022-lf8gl
0.6211,Event,ADDED,eval-conflicts-rho000-r5-022.18d4646103b9fe00,reason=Completed count=1 msg=Job completed
0.6212,Event,ADDED,eval-conflicts-rho000-r5-023-wrvfs.18d4645dbcf4b99a,reason=Scheduled count=None msg=Successfully assigned compute/eval-conflicts-rho000-r5-023-wrvfs to kind-worker2
0.6214,Event,ADDED,eval-conflicts-rho000-r5-023-wrvfs.18d4645dd5e1c543,"reason=Pulled count=1 msg=Container image ""busybox:musl"" already present on machine"
0.6216,Event,ADDED,eval-conflicts-rho000-r5-023-wrvfs.18d4645dd6f85c23,reason=Created count=1 msg=Created container: task
0.6217,Event,ADDED,eval-conflicts-rho000-r5-023-wrvfs.18d4645dd90b1f94,reason=Started count=1 msg=Started container task
0.6219,Event,ADDED,eval-conflicts-rho000-r5-023.18d4645dbc6e0a47,reason=SuccessfulCreate count=1 msg=Created pod: eval-conflicts-rho000-r5-023-wrvfs
0.6221,Event,ADDED,eval-conflicts-rho000-r5-023.18d4646102b0fef1,reason=Completed count=1 msg=Job completed
0.6222,Event,ADDED,eval-conflicts-rho000-r5-024-p8t58.18d4645df9c15780,reason=Scheduled count=None msg=Successfully assigned compute/eval-conflicts-rho000-r5-024-p8t58 to kind-worker2
0.6224,Event,ADDED,eval-conflicts-rho000-r5-024-p8t58.18d4645e13c7875c,"reason=Pulled count=1 msg=Container image ""busybox:musl"" already present on machine"
0.6225,Event,ADDED,eval-conflicts-rho000-r5-024-p8t58.18d4645e14de6707,reason=Created count=1 msg=Created container: task
0.6227,Event,ADDED,eval-conflicts-rho000-r5-024-p8t58.18d4645e17066b4a,reason=Started count=1 msg=Started container task
0.6229,Event,ADDED,eval-conflicts-rho000-r5-024.18d4645df92610f6,reason=SuccessfulCreate count=1 msg=Created pod: eval-conflicts-rho000-r5-024-p8t58
0.623,Event,ADDED,eval-conflicts-rho000-r5-024.18d464613fc64455,reason=Completed count=1 msg=Job completed
0.6232,Event,ADDED,eval-conflicts-rho000-r5-025-n7lwh.18d4645e343e505f,reason=Scheduled count=None msg=Successfully assigned compute/eval-conflicts-rho000-r5-025-n7lwh to kind-worker2
0.6234,Event,ADDED,eval-conflicts-rho000-r5-025-n7lwh.18d4645e4cfc3931,"reason=Pulled count=1 msg=Container image ""busybox:musl"" already present on machine"
0.6236,Event,ADDED,eval-conflicts-rho000-r5-025-n7lwh.18d4645e4e232384,reason=Created count=1 msg=Created container: task
0.6238,Event,ADDED,eval-conflicts-rho000-r5-025-n7lwh.18d4645e50959248,reason=Started count=1 msg=Started container task
0.6239,Event,ADDED,eval-conflicts-rho000-r5-025.18d4645e33c41a86,reason=SuccessfulCreate count=1 msg=Created pod: eval-conflicts-rho000-r5-025-n7lwh
0.6283,Event,ADDED,eval-conflicts-rho000-r5-025.18d464614136465a,reason=Completed count=1 msg=Job completed
0.6285,Event,ADDED,eval-conflicts-rho000-r5-026-9xzng.18d4645e6fbbf227,reason=Scheduled count=None msg=Successfully assigned compute/eval-conflicts-rho000-r5-026-9xzng to kind-worker2
0.6288,Event,ADDED,eval-conflicts-rho000-r5-026-9xzng.18d4645e8928ea5e,"reason=Pulled count=1 msg=Container image ""busybox:musl"" already present on machine"
0.6293,Event,ADDED,eval-conflicts-rho000-r5-026-9xzng.18d4645e8a546013,reason=Created count=1 msg=Created container: task
0.6295,Event,ADDED,eval-conflicts-rho000-r5-026-9xzng.18d4645e8c56b53f,reason=Started count=1 msg=Started container task
0.6296,Event,ADDED,eval-conflicts-rho000-r5-026.18d4645e6f32a609,reason=SuccessfulCreate count=1 msg=Created pod: eval-conflicts-rho000-r5-026-9xzng
0.6299,Event,ADDED,eval-conflicts-rho000-r5-026.18d46461b7321b20,reason=Completed count=1 msg=Job completed
0.6302,Event,ADDED,eval-conflicts-rho000-r5-027-www9f.18d4645eabbc4fa0,reason=Scheduled count=None msg=Successfully assigned compute/eval-conflicts-rho000-r5-027-www9f to kind-worker5
0.6303,Event,ADDED,eval-conflicts-rho000-r5-027-www9f.18d4645ec56c322e,"reason=Pulled count=1 msg=Container image ""busybox:musl"" already present on machine"
0.6305,Event,ADDED,eval-conflicts-rho000-r5-027-www9f.18d4645ec687d286,reason=Created count=1 msg=Created container: task
0.6307,Event,ADDED,eval-conflicts-rho000-r5-027-www9f.18d4645ec8e0db92,reason=Started count=1 msg=Started container task
0.6309,Event,ADDED,eval-conflicts-rho000-r5-027.18d4645eaa9afbca,reason=SuccessfulCreate count=1 msg=Created pod: eval-conflicts-rho000-r5-027-www9f
0.631,Event,ADDED,eval-conflicts-rho000-r5-027.18d46461dc729c57,reason=Completed count=1 msg=Job completed
0.6312,Event,ADDED,eval-conflicts-rho000-r5-028-jvbqg.18d4645ee813a91f,reason=Scheduled count=None msg=Successfully assigned compute/eval-conflicts-rho000-r5-028-jvbqg to kind-worker5
0.6314,Event,ADDED,eval-conflicts-rho000-r5-028-jvbqg.18d4645f01955d02,"reason=Pulled count=1 msg=Container image ""busybox:musl"" already present on machine"
0.6315,Event,ADDED,eval-conflicts-rho000-r5-028-jvbqg.18d4645f02ab06e7,reason=Created count=1 msg=Created container: task
0.6318,Event,ADDED,eval-conflicts-rho000-r5-028-jvbqg.18d4645f0608cb99,reason=Started count=1 msg=Started container task
0.632,Event,ADDED,eval-conflicts-rho000-r5-028.18d4645ee7232bca,reason=SuccessfulCreate count=1 msg=Created pod: eval-conflicts-rho000-r5-028-jvbqg
0.6323,Event,ADDED,eval-conflicts-rho000-r5-028.18d4646215e2cdbb,reason=Completed count=1 msg=Job completed
0.6325,Event,ADDED,eval-conflicts-rho000-r5-029-j7vxj.18d4645f2335c7b7,reason=Scheduled count=None msg=Successfully assigned compute/eval-conflicts-rho000-r5-029-j7vxj to kind-worker5
0.6327,Event,ADDED,eval-conflicts-rho000-r5-029-j7vxj.18d4645f3d9c6ac8,"reason=Pulled count=1 msg=Container image ""busybox:musl"" already present on machine"
0.6333,Event,ADDED,eval-conflicts-rho000-r5-029-j7vxj.18d4645f3ea962f4,reason=Created count=1 msg=Created container: task
0.6335,Event,ADDED,eval-conflicts-rho000-r5-029-j7vxj.18d4645f45d56b55,reason=Started count=1 msg=Started container task
0.6337,Event,ADDED,eval-conflicts-rho000-r5-029.18d4645f224cc023,reason=SuccessfulCreate count=1 msg=Created pod: eval-conflicts-rho000-r5-029-j7vxj
0.6339,Event,ADDED,eval-conflicts-rho000-r5-029.18d464628b817076,reason=Completed count=1 msg=Job completed
0.6342,Event,ADDED,eval-conflicts-rho000-r5-030-xhgvd.18d4645f5ecf8171,reason=Scheduled count=None msg=Successfully assigned compute/eval-conflicts-rho000-r5-030-xhgvd to kind-worker
0.6344,Event,ADDED,eval-conflicts-rho000-r5-030-xhgvd.18d4645f7a759757,"reason=Pulled count=1 msg=Container image ""busybox:musl"" already present on machine"
0.6346,Event,ADDED,eval-conflicts-rho000-r5-030-xhgvd.18d4645f7b85c552,reason=Created count=1 msg=Created container: task
0.6348,Event,ADDED,eval-conflicts-rho000-r5-030-xhgvd.18d4645f80072da0,reason=Started count=1 msg=Started container task
0.635,Event,ADDED,eval-conflicts-rho000-r5-030.18d4645f5dfdf466,reason=SuccessfulCreate count=1 msg=Created pod: eval-conflicts-rho000-r5-030-xhgvd
0.6357,Event,ADDED,eval-conflicts-rho000-r5-030.18d46462c2c648e5,reason=Completed count=1 msg=Job completed
0.6359,Event,ADDED,eval-conflicts-rho000-r5-031-ctqgn.18d4645f9abd72a4,reason=Scheduled count=None msg=Successfully assigned compute/eval-conflicts-rho000-r5-031-ctqgn to kind-worker
0.6362,Event,ADDED,eval-conflicts-rho000-r5-031-ctqgn.18d4645fb6682c98,"reason=Pulled count=1 msg=Container image ""busybox:musl"" already present on machine"
0.6364,Event,ADDED,eval-conflicts-rho000-r5-031-ctqgn.18d4645fb78a381b,reason=Created count=1 msg=Created container: task
0.6366,Event,ADDED,eval-conflicts-rho000-r5-031-ctqgn.18d4645fbb6f6fbb,reason=Started count=1 msg=Started container task
0.6368,Event,ADDED,eval-conflicts-rho000-r5-031.18d4645f999f2d83,reason=SuccessfulCreate count=1 msg=Created pod: eval-conflicts-rho000-r5-031-ctqgn
0.6371,Event,ADDED,eval-conflicts-rho000-r5-031.18d46462fb215072,reason=Completed count=1 msg=Job completed
0.6373,Event,ADDED,eval-conflicts-rho000-r5-032-kmfv6.18d4645fd68f3bf5,reason=Scheduled count=None msg=Successfully assigned compute/eval-conflicts-rho000-r5-032-kmfv6 to kind-worker5
0.6374,Event,ADDED,eval-conflicts-rho000-r5-032-kmfv6.18d4645fef5c6bc7,"reason=Pulled count=1 msg=Container image ""busybox:musl"" already present on machine"
0.6377,Event,ADDED,eval-conflicts-rho000-r5-032-kmfv6.18d4645ff0a93757,reason=Created count=1 msg=Created container: task
0.6379,Event,ADDED,eval-conflicts-rho000-r5-032-kmfv6.18d4645ff2a2390c,reason=Started count=1 msg=Started container task
0.6381,Event,ADDED,eval-conflicts-rho000-r5-032.18d4645fd56372bc,reason=SuccessfulCreate count=1 msg=Created pod: eval-conflicts-rho000-r5-032-kmfv6
0.6383,Event,ADDED,eval-conflicts-rho000-r5-032.18d464633e31a109,reason=Completed count=1 msg=Job completed
0.6386,Event,ADDED,eval-conflicts-rho000-r5-033-7cfjc.18d4646011943f00,reason=Scheduled count=None msg=Successfully assigned compute/eval-conflicts-rho000-r5-033-7cfjc to kind-worker4
0.6388,Event,ADDED,eval-conflicts-rho000-r5-033-7cfjc.18d464602bef0d80,"reason=Pulled count=1 msg=Container image ""busybox:musl"" already present on machine"
0.639,Event,ADDED,eval-conflicts-rho000-r5-033-7cfjc.18d464602d07fa64,reason=Created count=1 msg=Created container: task
0.6391,Event,ADDED,eval-conflicts-rho000-r5-033-7cfjc.18d464603564f988,reason=Started count=1 msg=Started container task
0.6395,Event,ADDED,eval-conflicts-rho000-r5-033.18d4646010a4da7d,reason=SuccessfulCreate count=1 msg=Created pod: eval-conflicts-rho000-r5-033-7cfjc
0.6397,Event,ADDED,eval-conflicts-rho000-r5-033.18d4646354a13df8,reason=Completed count=1 msg=Job completed
