t_recv,kind,type,name,detail
0.0244,Node,ADDED,kind-control-plane,taints=1
0.0285,Node,ADDED,kind-worker,taints=0
0.0301,Node,ADDED,kind-worker2,taints=0
0.0314,Node,ADDED,kind-worker3,taints=0
0.0325,Node,ADDED,kind-worker4,taints=0
0.0339,Node,ADDED,kind-worker5,taints=0
0.0424,TaskRequest,ADDED,eval-sanitize-2-r1-000,phase=None job=None
0.05,TaskRequest,MODIFIED,eval-sanitize-2-r1-000,phase=Pending job=None
0.0664,Job,ADDED,eval-sanitize-2-r1-000,
0.0716,TaskRequest,MODIFIED,eval-sanitize-2-r1-000,phase=Scheduled job=None
0.074,Pod,ADDED,eval-sanitize-2-r1-000-qsvxq,phase=Pending node=None
0.0772,Job,MODIFIED,eval-sanitize-2-r1-000,
0.0799,Event,ADDED,eval-sanitize-2-r1-000.18d420daa268cf0a,reason=SuccessfulCreate count=1 msg=Created pod: eval-sanitize-2-r1-000-qsvxq
0.0808,TaskRequest,MODIFIED,eval-sanitize-2-r1-000,phase=Scheduled job=None
0.0929,Pod,MODIFIED,eval-sanitize-2-r1-000-qsvxq,phase=Pending node=kind-worker5
0.0983,Event,ADDED,eval-sanitize-2-r1-000-qsvxq.18d420daa393d765,reason=Scheduled count=None msg=Successfully assigned compute/eval-sanitize-2-r1-000-qsvxq to kind-worker5
0.1027,Pod,MODIFIED,eval-sanitize-2-r1-000-qsvxq,phase=Pending node=kind-worker5
0.1049,Node,MODIFIED,kind-worker5,taints=0
0.1179,Node,MODIFIED,kind-worker5,taints=0
0.3041,Node,MODIFIED,kind-worker5,taints=1
0.3193,Node,MODIFIED,kind-worker5,taints=1
0.5112,Event,ADDED,eval-sanitize-2-r1-000-qsvxq.18d420dabc3f7bd4,"reason=Pulled count=1 msg=Container image ""busybox:musl"" already present on machine"
0.5297,Event,ADDED,eval-sanitize-2-r1-000-qsvxq.18d420dabd612dce,reason=Created count=1 msg=Created container: task
0.5632,Event,ADDED,eval-sanitize-2-r1-000-qsvxq.18d420dabf5cc73d,reason=Started count=1 msg=Started container task
1.0118,TaskRequest,ADDED,eval-sanitize-2-r1-001,phase=None job=None
1.0162,TaskRequest,MODIFIED,eval-sanitize-2-r1-001,phase=Pending job=None
1.0327,Job,ADDED,eval-sanitize-2-r1-001,
1.0368,TaskRequest,MODIFIED,eval-sanitize-2-r1-001,phase=Scheduled job=None
1.04,Pod,ADDED,eval-sanitize-2-r1-001-qffv8,phase=Pending node=None
1.0428,Job,MODIFIED,eval-sanitize-2-r1-001,
1.0451,Event,ADDED,eval-sanitize-2-r1-001.18d420dadc00cacf,reason=SuccessfulCreate count=1 msg=Created pod: eval-sanitize-2-r1-001-qffv8
1.0493,Pod,MODIFIED,eval-sanitize-2-r1-001-qffv8,phase=Pending node=kind-worker3
1.0532,Event,ADDED,eval-sanitize-2-r1-001-qffv8.18d420dadc8fb516,reason=Scheduled count=None msg=Successfully assigned compute/eval-sanitize-2-r1-001-qffv8 to kind-worker3
1.0593,Pod,MODIFIED,eval-sanitize-2-r1-001-qffv8,phase=Pending node=kind-worker3
1.0602,TaskRequest,MODIFIED,eval-sanitize-2-r1-001,phase=Scheduled job=None
1.0617,Node,MODIFIED,kind-worker3,taints=0
1.0722,Node,MODIFIED,kind-worker3,taints=0
1.0778,Job,MODIFIED,eval-sanitize-2-r1-000,
1.0867,Job,MODIFIED,eval-sanitize-2-r1-000,
1.2404,Pod,MODIFIED,eval-sanitize-2-r1-000-qsvxq,phase=Running node=kind-worker5
1.4627,Event,ADDED,eval-sanitize-2-r1-001-qffv8.18d420daf4f62777,"reason=Pulled count=1 msg=Container image ""busybox:musl"" already present on machine"
1.4793,Event,ADDED,eval-sanitize-2-r1-001-qffv8.18d420daf6044256,reason=Created count=1 msg=Created container: task
1.5401,Event,ADDED,eval-sanitize-2-r1-001-qffv8.18d420daf99c98ba,reason=Started count=1 msg=Started container task
1.6403,Pod,MODIFIED,eval-sanitize-2-r1-001-qffv8,phase=Running node=kind-worker3
2.0126,TaskRequest,ADDED,eval-sanitize-2-r1-002,phase=None job=None
2.0178,TaskRequest,MODIFIED,eval-sanitize-2-r1-002,phase=Pending job=None
2.0331,Job,ADDED,eval-sanitize-2-r1-002,
2.0373,TaskRequest,MODIFIED,eval-sanitize-2-r1-002,phase=Scheduled job=None
2.0413,Pod,ADDED,eval-sanitize-2-r1-002-94z5p,phase=Pending node=None
2.0434,Job,MODIFIED,eval-sanitize-2-r1-002,
2.0454,Job,MODIFIED,eval-sanitize-2-r1-001,
2.0468,Event,ADDED,eval-sanitize-2-r1-002.18d420db17afa5db,reason=SuccessfulCreate count=1 msg=Created pod: eval-sanitize-2-r1-002-94z5p
2.0469,TaskRequest,MODIFIED,eval-sanitize-2-r1-002,phase=Scheduled job=None
2.055,Job,MODIFIED,eval-sanitize-2-r1-001,
2.0574,Pod,MODIFIED,eval-sanitize-2-r1-002-94z5p,phase=Pending node=kind-worker
2.0607,Event,ADDED,eval-sanitize-2-r1-002-94z5p.18d420db18a5171b,reason=Scheduled count=None msg=Successfully assigned compute/eval-sanitize-2-r1-002-94z5p to kind-worker
2.0664,Pod,MODIFIED,eval-sanitize-2-r1-002-94z5p,phase=Pending node=kind-worker
2.0687,Node,MODIFIED,kind-worker,taints=0
2.0801,Node,MODIFIED,kind-worker,taints=0
2.0828,Job,MODIFIED,eval-sanitize-2-r1-000,
2.0917,Job,MODIFIED,eval-sanitize-2-r1-000,
2.4852,Event,ADDED,eval-sanitize-2-r1-002-94z5p.18d420db31e850c7,"reason=Pulled count=1 msg=Container image ""busybox:musl"" already present on machine"
2.5016,Event,ADDED,eval-sanitize-2-r1-002-94z5p.18d420db32ef35b4,reason=Created count=1 msg=Created container: task
2.5371,Event,ADDED,eval-sanitize-2-r1-002-94z5p.18d420db35008452,reason=Started count=1 msg=Started container task
2.6891,Node,MODIFIED,kind-worker3,taints=1
2.699,Node,MODIFIED,kind-worker,taints=1
2.7495,Node,MODIFIED,kind-worker3,taints=1
2.8489,Node,MODIFIED,kind-worker,taints=1
3.0118,TaskRequest,ADDED,eval-sanitize-2-r1-003,phase=None job=None
3.0163,TaskRequest,MODIFIED,eval-sanitize-2-r1-003,phase=Pending job=None
3.0303,Job,ADDED,eval-sanitize-2-r1-003,
3.0356,TaskRequest,MODIFIED,eval-sanitize-2-r1-003,phase=Scheduled job=None
3.0379,Pod,ADDED,eval-sanitize-2-r1-003-8q9hg,phase=Pending node=None
3.0398,Job,MODIFIED,eval-sanitize-2-r1-003,
3.0425,Event,ADDED,eval-sanitize-2-r1-003.18d420db5315c310,reason=SuccessfulCreate count=1 msg=Created pod: eval-sanitize-2-r1-003-8q9hg
3.0452,Job,MODIFIED,eval-sanitize-2-r1-002,
3.0479,Pod,MODIFIED,eval-sanitize-2-r1-003-8q9hg,phase=Pending node=kind-worker2
3.0494,TaskRequest,MODIFIED,eval-sanitize-2-r1-003,phase=Scheduled job=None
3.0513,Event,ADDED,eval-sanitize-2-r1-003-8q9hg.18d420db53b18b21,reason=Scheduled count=None msg=Successfully assigned compute/eval-sanitize-2-r1-003-8q9hg to kind-worker2
3.0544,Job,MODIFIED,eval-sanitize-2-r1-002,
3.0584,Node,MODIFIED,kind-worker2,taints=0
3.0601,Pod,MODIFIED,eval-sanitize-2-r1-003-8q9hg,phase=Pending node=kind-worker2
3.1518,Node,MODIFIED,kind-worker2,taints=0
3.3467,Pod,MODIFIED,eval-sanitize-2-r1-002-94z5p,phase=Running node=kind-worker
3.4628,Event,ADDED,eval-sanitize-2-r1-003-8q9hg.18d420db6c2fe28d,"reason=Pulled count=1 msg=Container image ""busybox:musl"" already present on machine"
3.4799,Event,ADDED,eval-sanitize-2-r1-003-8q9hg.18d420db6d3cb898,reason=Created count=1 msg=Created container: task
3.5141,Event,ADDED,eval-sanitize-2-r1-003-8q9hg.18d420db6f3cff71,reason=Started count=1 msg=Started container task
3.5753,Pod,MODIFIED,eval-sanitize-2-r1-003-8q9hg,phase=Running node=kind-worker2
4.0136,TaskRequest,ADDED,eval-sanitize-2-r1-004,phase=None job=None
4.017,TaskRequest,MODIFIED,eval-sanitize-2-r1-004,phase=Pending job=None
4.0327,Job,ADDED,eval-sanitize-2-r1-004,
4.0381,TaskRequest,MODIFIED,eval-sanitize-2-r1-004,phase=Scheduled job=None
4.0414,Pod,ADDED,eval-sanitize-2-r1-004-lxbfr,phase=Pending node=None
4.0434,Job,MODIFIED,eval-sanitize-2-r1-003,
4.046,Job,MODIFIED,eval-sanitize-2-r1-004,
4.047,Event,ADDED,eval-sanitize-2-r1-004.18d420db8ee83c46,reason=SuccessfulCreate count=1 msg=Created pod: eval-sanitize-2-r1-004-lxbfr
4.0471,TaskRequest,MODIFIED,eval-sanitize-2-r1-004,phase=Scheduled job=None
4.0528,Job,MODIFIED,eval-sanitize-2-r1-002,
4.0541,Pod,MODIFIED,eval-sanitize-2-r1-004-lxbfr,phase=Pending node=kind-worker4
4.0555,Job,MODIFIED,eval-sanitize-2-r1-003,
4.0589,Event,ADDED,eval-sanitize-2-r1-004-lxbfr.18d420db8fa9037c,reason=Scheduled count=None msg=Successfully assigned compute/eval-sanitize-2-r1-004-lxbfr to kind-worker4
4.0617,Job,MODIFIED,eval-sanitize-2-r1-002,
4.0653,Node,MODIFIED,kind-worker4,taints=0
4.0669,Pod,MODIFIED,eval-sanitize-2-r1-004-lxbfr,phase=Pending node=kind-worker4
4.0753,Node,MODIFIED,kind-worker4,taints=0
4.3304,Node,MODIFIED,kind-worker4,taints=1
4.3426,Node,MODIFIED,kind-worker4,taints=1
4.4587,Event,ADDED,eval-sanitize-2-r1-004-lxbfr.18d420dba78acd00,"reason=Pulled count=1 msg=Container image ""busybox:musl"" already present on machine"
4.478,Event,ADDED,eval-sanitize-2-r1-004-lxbfr.18d420dba89ec956,reason=Created count=1 msg=Created container: task
4.5094,Event,ADDED,eval-sanitize-2-r1-004-lxbfr.18d420dbaa92345b,reason=Started count=1 msg=Started container task
4.7014,Node,MODIFIED,kind-worker2,taints=1
4.7144,Node,MODIFIED,kind-worker2,taints=1
5.0117,TaskRequest,ADDED,eval-sanitize-2-r1-005,phase=None job=None
5.0155,TaskRequest,MODIFIED,eval-sanitize-2-r1-005,phase=Pending job=None
5.0326,Job,ADDED,eval-sanitize-2-r1-005,
5.039,TaskRequest,MODIFIED,eval-sanitize-2-r1-005,phase=Scheduled job=None
5.0403,Pod,ADDED,eval-sanitize-2-r1-005-rng6l,phase=Pending node=None
5.0423,Job,MODIFIED,eval-sanitize-2-r1-005,
5.0461,Event,ADDED,eval-sanitize-2-r1-005.18d420dbca68d397,reason=SuccessfulCreate count=1 msg=Created pod: eval-sanitize-2-r1-005-rng6l
5.0465,Event,ADDED,eval-sanitize-2-r1-005-rng6l.18d420dbca7be0b3,"reason=FailedScheduling count=None msg=0/6 nodes are available: 6 node(s) had untolerated taint(s). no new claims to deallocate, preemption: 0/6 nodes are available: 6 Preemption is not helpful for scheduling."
5.0475,Pod,MODIFIED,eval-sanitize-2-r1-005-rng6l,phase=Pending node=None
5.0481,Job,MODIFIED,eval-sanitize-2-r1-004,
5.0519,TaskRequest,MODIFIED,eval-sanitize-2-r1-005,phase=Scheduled job=None
5.0548,Job,MODIFIED,eval-sanitize-2-r1-004,
5.2486,Pod,MODIFIED,eval-sanitize-2-r1-004-lxbfr,phase=Running node=kind-worker4
6.0119,TaskRequest,ADDED,eval-sanitize-2-r1-006,phase=None job=None
6.017,TaskRequest,MODIFIED,eval-sanitize-2-r1-006,phase=Pending job=None
6.0313,Job,ADDED,eval-sanitize-2-r1-006,
6.0378,Pod,ADDED,eval-sanitize-2-r1-006-srhbl,phase=Pending node=None
6.038,TaskRequest,MODIFIED,eval-sanitize-2-r1-006,phase=Scheduled job=None
6.0415,Job,MODIFIED,eval-sanitize-2-r1-006,
6.0434,Event,ADDED,eval-sanitize-2-r1-006.18d420dc05eb1375,reason=SuccessfulCreate count=1 msg=Created pod: eval-sanitize-2-r1-006-srhbl
6.0436,Event,ADDED,eval-sanitize-2-r1-006-srhbl.18d420dc05f76998,"reason=FailedScheduling count=None msg=0/6 nodes are available: 6 node(s) had untolerated taint(s). no new claims to deallocate, preemption: 0/6 nodes are available: 6 Preemption is not helpful for scheduling."
6.0446,Pod,MODIFIED,eval-sanitize-2-r1-006-srhbl,phase=Pending node=None
6.0454,Job,MODIFIED,eval-sanitize-2-r1-005,
6.0455,TaskRequest,MODIFIED,eval-sanitize-2-r1-006,phase=Scheduled job=None
6.0512,Job,MODIFIED,eval-sanitize-2-r1-004,
6.053,Job,MODIFIED,eval-sanitize-2-r1-005,
6.0588,Job,MODIFIED,eval-sanitize-2-r1-004,
7.006,TaskRequest,ADDED,eval-sanitize-2-r1-007,phase=None job=None
7.0111,TaskRequest,MODIFIED,eval-sanitize-2-r1-007,phase=Pending job=None
7.0268,Job,ADDED,eval-sanitize-2-r1-007,
7.0299,TaskRequest,MODIFIED,eval-sanitize-2-r1-007,phase=Scheduled job=None
7.0416,Pod,ADDED,eval-sanitize-2-r1-007-z7mxg,phase=Pending node=None
7.0428,TaskRequest,MODIFIED,eval-sanitize-2-r1-007,phase=Scheduled job=None
7.0435,Job,MODIFIED,eval-sanitize-2-r1-007,
7.0445,Job,MODIFIED,eval-sanitize-2-r1-006,
7.047,Event,ADDED,eval-sanitize-2-r1-007.18d420dc41c0e229,reason=SuccessfulCreate count=1 msg=Created pod: eval-sanitize-2-r1-007-z7mxg
7.0473,Event,ADDED,eval-sanitize-2-r1-007-z7mxg.18d420dc41cd6d33,"reason=FailedScheduling count=None msg=0/6 nodes are available: 6 node(s) had untolerated taint(s). no new claims to deallocate, preemption: 0/6 nodes are available: 6 Preemption is not helpful for scheduling."
7.0483,Pod,MODIFIED,eval-sanitize-2-r1-007-z7mxg,phase=Pending node=None
7.0532,Job,MODIFIED,eval-sanitize-2-r1-006,
8.0069,TaskRequest,ADDED,eval-sanitize-2-r1-008,phase=None job=None
8.0101,TaskRequest,MODIFIED,eval-sanitize-2-r1-008,phase=Pending job=None
8.0268,Job,ADDED,eval-sanitize-2-r1-008,
8.0345,Pod,ADDED,eval-sanitize-2-r1-008-24xc5,phase=Pending node=None
8.0347,TaskRequest,MODIFIED,eval-sanitize-2-r1-008,phase=Scheduled job=None
8.0371,Job,MODIFIED,eval-sanitize-2-r1-008,
8.04,Event,ADDED,eval-sanitize-2-r1-008.18d420dc7ce4f9f2,reason=SuccessfulCreate count=1 msg=Created pod: eval-sanitize-2-r1-008-24xc5
8.0412,Pod,MODIFIED,eval-sanitize-2-r1-008-24xc5,phase=Pending node=None
8.0415,Event,ADDED,eval-sanitize-2-r1-008-24xc5.18d420dc7cf14e5f,"reason=FailedScheduling count=None msg=0/6 nodes are available: 6 node(s) had untolerated taint(s). no new claims to deallocate, preemption: 0/6 nodes are available: 6 Preemption is not helpful for scheduling."
8.0486,Job,MODIFIED,eval-sanitize-2-r1-007,
8.0487,TaskRequest,MODIFIED,eval-sanitize-2-r1-008,phase=Scheduled job=None
8.0598,Job,MODIFIED,eval-sanitize-2-r1-007,
9.0082,TaskRequest,ADDED,eval-sanitize-2-r1-009,phase=None job=None
9.0132,TaskRequest,MODIFIED,eval-sanitize-2-r1-009,phase=Pending job=None
9.027,Job,ADDED,eval-sanitize-2-r1-009,
9.0325,TaskRequest,MODIFIED,eval-sanitize-2-r1-009,phase=Scheduled job=None
9.0356,Job,MODIFIED,eval-sanitize-2-r1-009,
9.0365,Pod,ADDED,eval-sanitize-2-r1-009-rqs9m,phase=Pending node=None
9.0386,Job,MODIFIED,eval-sanitize-2-r1-008,
9.0402,Event,ADDED,eval-sanitize-2-r1-009.18d420dcb898069a,reason=SuccessfulCreate count=1 msg=Created pod: eval-sanitize-2-r1-009-rqs9m
9.0412,Pod,MODIFIED,eval-sanitize-2-r1-009-rqs9m,phase=Pending node=None
9.0422,Event,ADDED,eval-sanitize-2-r1-009-rqs9m.18d420dcb8a434c2,"reason=FailedScheduling count=None msg=0/6 nodes are available: 6 node(s) had untolerated taint(s). no new claims to deallocate, preemption: 0/6 nodes are available: 6 Preemption is not helpful for scheduling."
9.0423,TaskRequest,MODIFIED,eval-sanitize-2-r1-009,phase=Scheduled job=None
9.0474,Job,MODIFIED,eval-sanitize-2-r1-008,
10.0087,TaskRequest,ADDED,eval-sanitize-2-r1-010,phase=None job=None
10.0126,TaskRequest,MODIFIED,eval-sanitize-2-r1-010,phase=Pending job=None
10.0286,Job,ADDED,eval-sanitize-2-r1-010,
10.0318,TaskRequest,MODIFIED,eval-sanitize-2-r1-010,phase=Scheduled job=None
10.0347,Pod,ADDED,eval-sanitize-2-r1-010-cmhnq,phase=Pending node=None
10.0382,Job,MODIFIED,eval-sanitize-2-r1-010,
10.0401,Event,ADDED,eval-sanitize-2-r1-010.18d420dcf42ddd5d,reason=SuccessfulCreate count=1 msg=Created pod: eval-sanitize-2-r1-010-cmhnq
10.041,Job,MODIFIED,eval-sanitize-2-r1-009,
10.0425,Pod,MODIFIED,eval-sanitize-2-r1-010-cmhnq,phase=Pending node=None
10.0429,Event,ADDED,eval-sanitize-2-r1-010-cmhnq.18d420dcf43a9175,"reason=FailedScheduling count=None msg=0/6 nodes are available: 6 node(s) had untolerated taint(s). no new claims to deallocate, preemption: 0/6 nodes are available: 6 Preemption is not helpful for scheduling."
10.043,TaskRequest,MODIFIED,eval-sanitize-2-r1-010,phase=Scheduled job=None
10.0491,Job,MODIFIED,eval-sanitize-2-r1-009,
11.0134,TaskRequest,ADDED,eval-sanitize-2-r1-011,phase=None job=None
11.0172,TaskRequest,MODIFIED,eval-sanitize-2-r1-011,phase=Pending job=None
11.0339,Job,ADDED,eval-sanitize-2-r1-011,
11.0395,Job,MODIFIED,eval-sanitize-2-r1-010,
11.042,Pod,ADDED,eval-sanitize-2-r1-011-mbg8c,phase=Pending node=None
11.0421,TaskRequest,MODIFIED,eval-sanitize-2-r1-011,phase=Scheduled job=None
11.0431,Job,MODIFIED,eval-sanitize-2-r1-011,
11.0488,Pod,MODIFIED,eval-sanitize-2-r1-011-mbg8c,phase=Pending node=None
11.0498,Event,ADDED,eval-sanitize-2-r1-011.18d420dd3031867e,reason=SuccessfulCreate count=1 msg=Created pod: eval-sanitize-2-r1-011-mbg8c
11.05,Event,ADDED,eval-sanitize-2-r1-011-mbg8c.18d420dd303d65e9,"reason=FailedScheduling count=None msg=0/6 nodes are available: 6 node(s) had untolerated taint(s). no new claims to deallocate, preemption: 0/6 nodes are available: 6 Preemption is not helpful for scheduling."
11.0524,Job,MODIFIED,eval-sanitize-2-r1-010,
11.0633,TaskRequest,MODIFIED,eval-sanitize-2-r1-011,phase=Scheduled job=None
11.26,Pod,MODIFIED,eval-sanitize-2-r1-000-qsvxq,phase=Running node=kind-worker5
11.6597,Pod,MODIFIED,eval-sanitize-2-r1-001-qffv8,phase=Running node=kind-worker3
12.0141,TaskRequest,ADDED,eval-sanitize-2-r1-012,phase=None job=None
12.0175,TaskRequest,MODIFIED,eval-sanitize-2-r1-012,phase=Pending job=None
12.0336,Job,ADDED,eval-sanitize-2-r1-012,
12.0389,Pod,ADDED,eval-sanitize-2-r1-012-nfhdz,phase=Pending node=None
12.0405,TaskRequest,MODIFIED,eval-sanitize-2-r1-012,phase=Scheduled job=None
12.0434,Job,MODIFIED,eval-sanitize-2-r1-012,
12.0449,Event,ADDED,eval-sanitize-2-r1-012.18d420dd6ba05425,reason=SuccessfulCreate count=1 msg=Created pod: eval-sanitize-2-r1-012-nfhdz
12.0451,Event,ADDED,eval-sanitize-2-r1-012-nfhdz.18d420dd6bab74bc,"reason=FailedScheduling count=None msg=0/6 nodes are available: 6 node(s) had untolerated taint(s). no new claims to deallocate, preemption: 0/6 nodes are available: 6 Preemption is not helpful for scheduling."
12.0461,Pod,MODIFIED,eval-sanitize-2-r1-012-nfhdz,phase=Pending node=None
12.0486,Job,MODIFIED,eval-sanitize-2-r1-011,
12.0563,TaskRequest,MODIFIED,eval-sanitize-2-r1-012,phase=Scheduled job=None
12.0585,Job,MODIFIED,eval-sanitize-2-r1-011,
12.2654,Job,MODIFIED,eval-sanitize-2-r1-000,
12.2748,Job,MODIFIED,eval-sanitize-2-r1-000,
12.4394,Pod,MODIFIED,eval-sanitize-2-r1-000-qsvxq,phase=Succeeded node=kind-worker5
12.665,Job,MODIFIED,eval-sanitize-2-r1-001,
12.6756,Job,MODIFIED,eval-sanitize-2-r1-001,
12.7403,Pod,MODIFIED,eval-sanitize-2-r1-001-qffv8,phase=Succeeded node=kind-worker3
13.0085,TaskRequest,ADDED,eval-sanitize-2-r1-013,phase=None job=None
13.0127,TaskRequest,MODIFIED,eval-sanitize-2-r1-013,phase=Pending job=None
13.0273,Job,ADDED,eval-sanitize-2-r1-013,
13.0339,Pod,ADDED,eval-sanitize-2-r1-013-w4d7s,phase=Pending node=None
13.0341,TaskRequest,MODIFIED,eval-sanitize-2-r1-013,phase=Scheduled job=None
13.0367,Job,MODIFIED,eval-sanitize-2-r1-013,
13.0395,Pod,MODIFIED,eval-sanitize-2-r1-013-w4d7s,phase=Pending node=None
13.0399,Event,ADDED,eval-sanitize-2-r1-013.18d420dda6ef082b,reason=SuccessfulCreate count=1 msg=Created pod: eval-sanitize-2-r1-013-w4d7s
13.0401,Event,ADDED,eval-sanitize-2-r1-013-w4d7s.18d420dda6f82cde,"reason=FailedScheduling count=None msg=0/6 nodes are available: 6 node(s) had untolerated taint(s). no new claims to deallocate, preemption: 0/6 nodes are available: 6 Preemption is not helpful for scheduling."
13.0438,Job,MODIFIED,eval-sanitize-2-r1-012,
13.0476,TaskRequest,MODIFIED,eval-sanitize-2-r1-013,phase=Scheduled job=None
13.0519,Job,MODIFIED,eval-sanitize-2-r1-012,
13.0744,Node,MODIFIED,kind-worker5,taints=1
13.1502,Node,MODIFIED,kind-worker5,taints=1
13.1582,Node,MODIFIED,kind-worker5,taints=0
13.1641,Pod,MODIFIED,eval-sanitize-2-r1-005-rng6l,phase=Pending node=kind-worker5
13.168,Event,ADDED,eval-sanitize-2-r1-005-rng6l.18d420ddaea7d16c,reason=Scheduled count=None msg=Successfully assigned compute/eval-sanitize-2-r1-005-rng6l to kind-worker5
13.1726,Pod,MODIFIED,eval-sanitize-2-r1-006-srhbl,phase=Pending node=None
13.1739,Event,ADDED,eval-sanitize-2-r1-006-srhbl.18d420ddaeed4e66,"reason=FailedScheduling count=None msg=0/6 nodes are available: 1 c_wall violated: 1 conflicting context pair(s) with node memory, 5 node(s) had untolerated taint(s). no new claims to deallocate, preemption: 0/6 nodes are available: 1 No preemption victims found for incoming pod, 5 Preemption is not helpful for scheduling."
13.1752,Pod,MODIFIED,eval-sanitize-2-r1-005-rng6l,phase=Pending node=kind-worker5
13.1766,Node,MODIFIED,kind-worker5,taints=0
13.1809,Pod,MODIFIED,eval-sanitize-2-r1-007-z7mxg,phase=Pending node=kind-worker5
13.1858,Pod,MODIFIED,eval-sanitize-2-r1-008-24xc5,phase=Pending node=None
13.1862,Event,ADDED,eval-sanitize-2-r1-008-24xc5.18d420ddafa02d34,"reason=FailedScheduling count=None msg=0/6 nodes are available: 1 c_wall violated: 1 conflicting context pair(s) with node memory, 5 node(s) had untolerated taint(s). no new claims to deallocate, preemption: 0/6 nodes are available: 1 No preemption victims found for incoming pod, 5 Preemption is not helpful for scheduling."
13.1864,Event,ADDED,eval-sanitize-2-r1-007-z7mxg.18d420ddafb40865,reason=Scheduled count=None msg=Successfully assigned compute/eval-sanitize-2-r1-007-z7mxg to kind-worker5
13.1924,Pod,MODIFIED,eval-sanitize-2-r1-007-z7mxg,phase=Pending node=kind-worker5
13.1944,Pod,MODIFIED,eval-sanitize-2-r1-009-rqs9m,phase=Pending node=kind-worker5
13.1958,Node,MODIFIED,kind-worker5,taints=0
13.1976,Pod,MODIFIED,eval-sanitize-2-r1-010-cmhnq,phase=Pending node=None
13.2003,Event,ADDED,eval-sanitize-2-r1-010-cmhnq.18d420ddb05e8221,"reason=FailedScheduling count=None msg=0/6 nodes are available: 1 c_wall violated: 1 conflicting context pair(s) with node memory, 5 node(s) had untolerated taint(s). no new claims to deallocate, preemption: 0/6 nodes are available: 1 No preemption victims found for incoming pod, 5 Preemption is not helpful for scheduling."
13.2061,Pod,MODIFIED,eval-sanitize-2-r1-009-rqs9m,phase=Pending node=kind-worker5
13.2657,Node,MODIFIED,kind-worker5,taints=0
13.2718,Job,MODIFIED,eval-sanitize-2-r1-000,
13.2762,Node,MODIFIED,kind-worker5,taints=0
13.2799,Pod,MODIFIED,eval-sanitize-2-r1-000-qsvxq,phase=Succeeded node=kind-worker5
13.2815,Job,MODIFIED,eval-sanitize-2-r1-000,
13.2864,Event,ADDED,eval-sanitize-2-r1-009-rqs9m.18d420ddb08a565b,reason=Scheduled count=None msg=Successfully assigned compute/eval-sanitize-2-r1-009-rqs9m to kind-worker5
13.2932,Pod,MODIFIED,eval-sanitize-2-r1-011-mbg8c,phase=Pending node=None
13.2936,Event,ADDED,eval-sanitize-2-r1-011-mbg8c.18d420ddb61a186b,"reason=FailedScheduling count=None msg=0/6 nodes are available: 1 c_wall violated: 2 conflicting context pair(s) with node memory, 5 node(s) had untolerated taint(s). no new claims to deallocate, preemption: 0/6 nodes are available: 1 No preemption victims found for incoming pod, 5 Preemption is not helpful for scheduling."
13.3003,Pod,MODIFIED,eval-sanitize-2-r1-012-nfhdz,phase=Pending node=None
13.3025,Event,ADDED,eval-sanitize-2-r1-012-nfhdz.18d420ddb68ce06a,"reason=FailedScheduling count=None msg=0/6 nodes are available: 1 c_wall violated: 2 conflicting context pair(s) with node memory, 5 node(s) had untolerated taint(s). no new claims to deallocate, preemption: 0/6 nodes are available: 1 No preemption victims found for incoming pod, 5 Preemption is not helpful for scheduling."
13.3085,Pod,MODIFIED,eval-sanitize-2-r1-013-w4d7s,phase=Pending node=None
13.3088,Event,ADDED,eval-sanitize-2-r1-013-w4d7s.18d420ddb7044796,"reason=FailedScheduling count=None msg=0/6 nodes are available: 1 c_wall violated: 1 conflicting context pair(s) with node memory, 5 node(s) had untolerated taint(s). no new claims to deallocate, preemption: 0/6 nodes are available: 1 No preemption victims found for incoming pod, 5 Preemption is not helpful for scheduling."
13.312,Node,MODIFIED,kind-worker5,taints=0
13.3459,Pod,MODIFIED,eval-sanitize-2-r1-006-srhbl,phase=Pending node=None
13.3463,Event,ADDED,eval-sanitize-2-r1-006-srhbl.18d420ddb93669fc,"reason=FailedScheduling count=None msg=0/6 nodes are available: 1 c_wall violated: 2 conflicting context pair(s) with node memory, 5 node(s) had untolerated taint(s). no new claims to deallocate, preemption: 0/6 nodes are available: 1 No preemption victims found for incoming pod, 5 Preemption is not helpful for scheduling."
13.3488,Node,MODIFIED,kind-worker5,taints=0
13.3528,Event,ADDED,eval-sanitize-2-r1-008-24xc5.18d420ddb9b5d6cc,"reason=FailedScheduling count=None msg=0/6 nodes are available: 1 c_wall violated: 1 conflicting context pair(s) with node memory, 5 node(s) had untolerated taint(s). no new claims to deallocate, preemption: 0/6 nodes are available: 1 No preemption victims found for incoming pod, 5 Preemption is not helpful for scheduling."
13.3556,Event,ADDED,eval-sanitize-2-r1-010-cmhnq.18d420ddb9ed9017,"reason=FailedScheduling count=None msg=0/6 nodes are available: 1 c_wall violated: 1 conflicting context pair(s) with node memory, 5 node(s) had untolerated taint(s). no new claims to deallocate, preemption: 0/6 nodes are available: 1 No preemption victims found for incoming pod, 5 Preemption is not helpful for scheduling."
13.3653,Pod,MODIFIED,eval-sanitize-2-r1-002-94z5p,phase=Running node=kind-worker
13.3781,Event,ADDED,eval-sanitize-2-r1-011-mbg8c.18d420ddbb3ebdb5,"reason=FailedScheduling count=None msg=0/6 nodes are available: 1 c_wall violated: 2 conflicting context pair(s) with node memory, 5 node(s) had untolerated taint(s). no new claims to deallocate, preemption: 0/6 nodes are available: 1 No preemption victims found for incoming pod, 5 Preemption is not helpful for scheduling."
13.3802,Event,ADDED,eval-sanitize-2-r1-012-nfhdz.18d420ddbb691a36,"reason=FailedScheduling count=None msg=0/6 nodes are available: 1 c_wall violated: 2 conflicting context pair(s) with node memory, 5 node(s) had untolerated taint(s). no new claims to deallocate, preemption: 0/6 nodes are available: 1 No preemption victims found for incoming pod, 5 Preemption is not helpful for scheduling."
13.3845,Event,ADDED,eval-sanitize-2-r1-013-w4d7s.18d420ddbb8ed0a8,"reason=FailedScheduling count=None msg=0/6 nodes are available: 1 c_wall violated: 1 conflicting context pair(s) with node memory, 5 node(s) had untolerated taint(s). no new claims to deallocate, preemption: 0/6 nodes are available: 1 No preemption victims found for incoming pod, 5 Preemption is not helpful for scheduling."
13.3865,Event,ADDED,eval-sanitize-2-r1-006-srhbl.18d420ddbbc749f0,"reason=FailedScheduling count=None msg=0/6 nodes are available: 1 c_wall violated: 2 conflicting context pair(s) with node memory, 5 node(s) had untolerated taint(s). no new claims to deallocate, preemption: 0/6 nodes are available: 1 No preemption victims found for incoming pod, 5 Preemption is not helpful for scheduling."
13.39,Event,MODIFIED,eval-sanitize-2-r1-008-24xc5.18d420ddb9b5d6cc,"reason=FailedScheduling count=None msg=0/6 nodes are available: 1 c_wall violated: 1 conflicting context pair(s) with node memory, 5 node(s) had untolerated taint(s). no new claims to deallocate, preemption: 0/6 nodes are available: 1 No preemption victims found for incoming pod, 5 Preemption is not helpful for scheduling."
13.4463,Event,MODIFIED,eval-sanitize-2-r1-010-cmhnq.18d420ddb9ed9017,"reason=FailedScheduling count=None msg=0/6 nodes are available: 1 c_wall violated: 1 conflicting context pair(s) with node memory, 5 node(s) had untolerated taint(s). no new claims to deallocate, preemption: 0/6 nodes are available: 1 No preemption victims found for incoming pod, 5 Preemption is not helpful for scheduling."
13.4536,Event,MODIFIED,eval-sanitize-2-r1-011-mbg8c.18d420ddbb3ebdb5,"reason=FailedScheduling count=None msg=0/6 nodes are available: 1 c_wall violated: 2 conflicting context pair(s) with node memory, 5 node(s) had untolerated taint(s). no new claims to deallocate, preemption: 0/6 nodes are available: 1 No preemption victims found for incoming pod, 5 Preemption is not helpful for scheduling."
13.5516,Node,MODIFIED,kind-worker3,taints=1
13.5602,Event,MODIFIED,eval-sanitize-2-r1-012-nfhdz.18d420ddbb691a36,"reason=FailedScheduling count=None msg=0/6 nodes are available: 1 c_wall violated: 2 conflicting context pair(s) with node memory, 5 node(s) had untolerated taint(s). no new claims to deallocate, preemption: 0/6 nodes are available: 1 No preemption victims found for incoming pod, 5 Preemption is not helpful for scheduling."
13.5638,Event,MODIFIED,eval-sanitize-2-r1-013-w4d7s.18d420ddbb8ed0a8,"reason=FailedScheduling count=None msg=0/6 nodes are available: 1 c_wall violated: 1 conflicting context pair(s) with node memory, 5 node(s) had untolerated taint(s). no new claims to deallocate, preemption: 0/6 nodes are available: 1 No preemption victims found for incoming pod, 5 Preemption is not helpful for scheduling."
13.5675,Event,MODIFIED,eval-sanitize-2-r1-006-srhbl.18d420ddbbc749f0,"reason=FailedScheduling count=None msg=0/6 nodes are available: 1 c_wall violated: 2 conflicting context pair(s) with node memory, 5 node(s) had untolerated taint(s). no new claims to deallocate, preemption: 0/6 nodes are available: 1 No preemption victims found for incoming pod, 5 Preemption is not helpful for scheduling."
13.597,Pod,MODIFIED,eval-sanitize-2-r1-003-8q9hg,phase=Running node=kind-worker2
13.6251,Event,ADDED,eval-sanitize-2-r1-009-rqs9m.18d420ddc9e14998,"reason=Pulled count=1 msg=Container image ""busybox:musl"" already present on machine"
13.6294,Event,ADDED,eval-sanitize-2-r1-007-z7mxg.18d420ddc9f85b88,"reason=Pulled count=1 msg=Container image ""busybox:musl"" already present on machine"
13.6344,Event,ADDED,eval-sanitize-2-r1-005-rng6l.18d420ddca758ad5,"reason=Pulled count=1 msg=Container image ""busybox:musl"" already present on machine"
13.647,Node,MODIFIED,kind-worker3,taints=0
13.656,Pod,MODIFIED,eval-sanitize-2-r1-010-cmhnq,phase=Pending node=kind-worker3
13.6566,Event,ADDED,eval-sanitize-2-r1-009-rqs9m.18d420ddcbadf3b7,reason=Created count=1 msg=Created container: task
13.6606,Event,ADDED,eval-sanitize-2-r1-010-cmhnq.18d420ddcbfc10ea,reason=Scheduled count=None msg=Successfully assigned compute/eval-sanitize-2-r1-010-cmhnq to kind-worker3
13.6652,Pod,MODIFIED,eval-sanitize-2-r1-011-mbg8c,phase=Pending node=None
13.6673,Event,ADDED,eval-sanitize-2-r1-007-z7mxg.18d420ddcc2a1fb9,reason=Created count=1 msg=Created container: task
13.6709,Pod,MODIFIED,eval-sanitize-2-r1-010-cmhnq,phase=Pending node=kind-worker3
13.6727,Node,MODIFIED,kind-worker3,taints=0
13.6731,Event,ADDED,eval-sanitize-2-r1-005-rng6l.18d420ddcca3c65c,reason=Created count=1 msg=Created container: task
13.6741,Job,MODIFIED,eval-sanitize-2-r1-001,
13.6804,Pod,MODIFIED,eval-sanitize-2-r1-001-qffv8,phase=Succeeded node=kind-worker3
13.683,Job,MODIFIED,eval-sanitize-2-r1-001,
13.7481,Node,MODIFIED,kind-worker3,taints=0
13.7501,Pod,MODIFIED,eval-sanitize-2-r1-012-nfhdz,phase=Pending node=None
13.7628,Pod,MODIFIED,eval-sanitize-2-r1-013-w4d7s,phase=Pending node=None
13.7654,Node,MODIFIED,kind-worker3,taints=0
13.7657,Event,ADDED,eval-sanitize-2-r1-009-rqs9m.18d420ddd243c894,reason=Started count=1 msg=Started container task
13.7787,Pod,MODIFIED,eval-sanitize-2-r1-006-srhbl,phase=Pending node=kind-worker3
13.7817,Event,ADDED,eval-sanitize-2-r1-006-srhbl.18d420ddd353b6f8,reason=Scheduled count=None msg=Successfully assigned compute/eval-sanitize-2-r1-006-srhbl to kind-worker3
13.7883,Pod,MODIFIED,eval-sanitize-2-r1-006-srhbl,phase=Pending node=kind-worker3
13.7907,Node,MODIFIED,kind-worker3,taints=0
13.8002,Event,ADDED,eval-sanitize-2-r1-005-rng6l.18d420ddd467f86d,reason=Started count=1 msg=Started container task
13.8046,Event,ADDED,eval-sanitize-2-r1-007-z7mxg.18d420ddd467f887,reason=Started count=1 msg=Started container task
13.8494,Pod,MODIFIED,eval-sanitize-2-r1-008-24xc5,phase=Pending node=kind-worker3
13.8523,Node,MODIFIED,kind-worker3,taints=0
13.8526,Event,ADDED,eval-sanitize-2-r1-008-24xc5.18d420ddd7839f4e,reason=Scheduled count=None msg=Successfully assigned compute/eval-sanitize-2-r1-008-24xc5 to kind-worker3
13.8569,Pod,MODIFIED,eval-sanitize-2-r1-011-mbg8c,phase=Pending node=None
13.8576,Event,ADDED,eval-sanitize-2-r1-011-mbg8c.18d420ddd79fc92d,"reason=FailedScheduling count=None msg=0/6 nodes are available: 2 c_wall violated: 2 conflicting context pair(s) with node memory, 4 node(s) had untolerated taint(s). no new claims to deallocate, preemption: 0/6 nodes are available: 2 No preemption victims found for incoming pod, 4 Preemption is not helpful for scheduling."
13.8613,Pod,MODIFIED,eval-sanitize-2-r1-008-24xc5,phase=Pending node=kind-worker3
13.8769,Event,ADDED,eval-sanitize-2-r1-012-nfhdz.18d420ddd8fe9f45,"reason=FailedScheduling count=None msg=0/6 nodes are available: 1 c_wall violated: 1 conflicting context pair(s) with node memory, 1 c_wall violated: 2 conflicting context pair(s) with node memory, 4 node(s) had untolerated taint(s). no new claims to deallocate, preemption: 0/6 nodes are available: 2 No preemption victims found for incoming pod, 4 Preemption is not helpful for scheduling."
13.9484,Pod,MODIFIED,eval-sanitize-2-r1-013-w4d7s,phase=Pending node=None
13.9487,Event,ADDED,eval-sanitize-2-r1-013-w4d7s.18d420dddd1f5b1f,"reason=FailedScheduling count=None msg=0/6 nodes are available: 1 c_wall violated: 1 conflicting context pair(s) with node memory, 1 c_wall violated: 2 conflicting context pair(s) with node memory, 4 node(s) had untolerated taint(s). no new claims to deallocate, preemption: 0/6 nodes are available: 2 No preemption victims found for incoming pod, 4 Preemption is not helpful for scheduling."
13.9582,Event,ADDED,eval-sanitize-2-r1-011-mbg8c.18d420ddddbbeb8f,"reason=FailedScheduling count=None msg=0/6 nodes are available: 2 c_wall violated: 2 conflicting context pair(s) with node memory, 4 node(s) had untolerated taint(s). no new claims to deallocate, preemption: 0/6 nodes are available: 2 No preemption victims found for incoming pod, 4 Preemption is not helpful for scheduling."
13.9629,Event,MODIFIED,eval-sanitize-2-r1-012-nfhdz.18d420ddd8fe9f45,"reason=FailedScheduling count=None msg=0/6 nodes are available: 1 c_wall violated: 1 conflicting context pair(s) with node memory, 1 c_wall violated: 2 conflicting context pair(s) with node memory, 4 node(s) had untolerated taint(s). no new claims to deallocate, preemption: 0/6 nodes are available: 2 No preemption victims found for incoming pod, 4 Preemption is not helpful for scheduling."
14.0072,TaskRequest,ADDED,eval-sanitize-2-r1-014,phase=None job=None
14.0125,TaskRequest,MODIFIED,eval-sanitize-2-r1-014,phase=Pending job=None
14.0279,Job,ADDED,eval-sanitize-2-r1-014,
14.0337,TaskRequest,MODIFIED,eval-sanitize-2-r1-014,phase=Scheduled job=None
14.037,Pod,ADDED,eval-sanitize-2-r1-014-fphhf,phase=Pending node=None
14.0385,Job,MODIFIED,eval-sanitize-2-r1-014,
14.0399,Job,MODIFIED,eval-sanitize-2-r1-013,
14.0403,Event,ADDED,eval-sanitize-2-r1-014.18d420dde2b864f3,reason=SuccessfulCreate count=1 msg=Created pod: eval-sanitize-2-r1-014-fphhf
14.0434,TaskRequest,MODIFIED,eval-sanitize-2-r1-014,phase=Scheduled job=None
14.0457,Event,ADDED,eval-sanitize-2-r1-013-w4d7s.18d420dde3038aee,"reason=FailedScheduling count=None msg=0/6 nodes are available: 1 c_wall violated: 1 conflicting context pair(s) with node memory, 1 c_wall violated: 2 conflicting context pair(s) with node memory, 4 node(s) had untolerated taint(s). no new claims to deallocate, preemption: 0/6 nodes are available: 2 No preemption victims found for incoming pod, 4 Preemption is not helpful for scheduling."
14.0487,Job,MODIFIED,eval-sanitize-2-r1-013,
14.0539,Pod,MODIFIED,eval-sanitize-2-r1-014-fphhf,phase=Pending node=kind-worker3
14.0573,Event,ADDED,eval-sanitize-2-r1-014-fphhf.18d420dde3bb97de,reason=Scheduled count=None msg=Successfully assigned compute/eval-sanitize-2-r1-014-fphhf to kind-worker3
14.0636,Pod,MODIFIED,eval-sanitize-2-r1-014-fphhf,phase=Pending node=kind-worker3
14.067,Event,MODIFIED,eval-sanitize-2-r1-011-mbg8c.18d420ddddbbeb8f,"reason=FailedScheduling count=None msg=0/6 nodes are available: 2 c_wall violated: 2 conflicting context pair(s) with node memory, 4 node(s) had untolerated taint(s). no new claims to deallocate, preemption: 0/6 nodes are available: 2 No preemption victims found for incoming pod, 4 Preemption is not helpful for scheduling."
14.1093,Event,ADDED,eval-sanitize-2-r1-010-cmhnq.18d420dde6c853b8,"reason=Pulled count=1 msg=Container image ""busybox:musl"" already present on machine"
14.1351,Event,ADDED,eval-sanitize-2-r1-010-cmhnq.18d420dde8549a1a,reason=Created count=1 msg=Created container: task
14.1569,Event,MODIFIED,eval-sanitize-2-r1-013-w4d7s.18d420dde3038aee,"reason=FailedScheduling count=None msg=0/6 nodes are available: 1 c_wall violated: 1 conflicting context pair(s) with node memory, 1 c_wall violated: 2 conflicting context pair(s) with node memory, 4 node(s) had untolerated taint(s). no new claims to deallocate, preemption: 0/6 nodes are available: 2 No preemption victims found for incoming pod, 4 Preemption is not helpful for scheduling."
14.1729,Event,ADDED,eval-sanitize-2-r1-010-cmhnq.18d420ddea8a2396,reason=Started count=1 msg=Started container task
14.1769,Event,ADDED,eval-sanitize-2-r1-006-srhbl.18d420ddeaa4b62a,"reason=Pulled count=1 msg=Container image ""busybox:musl"" already present on machine"
14.197,Event,ADDED,eval-sanitize-2-r1-006-srhbl.18d420ddebdc1c81,reason=Created count=1 msg=Created container: task
14.264,Event,ADDED,eval-sanitize-2-r1-006-srhbl.18d420ddeffcd013,reason=Started count=1 msg=Started container task
14.2681,Pod,MODIFIED,eval-sanitize-2-r1-009-rqs9m,phase=Running node=kind-worker5
14.2757,Pod,MODIFIED,eval-sanitize-2-r1-005-rng6l,phase=Running node=kind-worker5
14.2781,Job,MODIFIED,eval-sanitize-2-r1-000,
14.2846,Job,MODIFIED,eval-sanitize-2-r1-000,
14.2867,Event,ADDED,eval-sanitize-2-r1-008-24xc5.18d420ddf11c0d1c,"reason=Pulled count=1 msg=Container image ""busybox:musl"" already present on machine"
14.2881,Pod,MODIFIED,eval-sanitize-2-r1-007-z7mxg,phase=Running node=kind-worker5
14.2911,Event,ADDED,eval-sanitize-2-r1-000.18d420ddf17beaf1,reason=Completed count=1 msg=Job completed
14.3003,Job,MODIFIED,eval-sanitize-2-r1-000,
14.3043,Event,ADDED,eval-sanitize-2-r1-008-24xc5.18d420ddf267d42f,reason=Created count=1 msg=Created container: task
14.3052,TaskRequest,MODIFIED,eval-sanitize-2-r1-000,phase=Complete job=None
14.3148,Job,MODIFIED,eval-sanitize-2-r1-000,
14.371,Job,MODIFIED,eval-sanitize-2-r1-002,
14.3733,Event,ADDED,eval-sanitize-2-r1-008-24xc5.18d420ddf68741a3,reason=Started count=1 msg=Started container task
14.3808,Job,MODIFIED,eval-sanitize-2-r1-002,
14.5005,Event,ADDED,eval-sanitize-2-r1-014-fphhf.18d420ddfe192290,"reason=Pulled count=1 msg=Container image ""busybox:musl"" already present on machine"
14.5192,Event,ADDED,eval-sanitize-2-r1-014-fphhf.18d420ddff3918a0,reason=Created count=1 msg=Created container: task
14.5371,Pod,MODIFIED,eval-sanitize-2-r1-002-94z5p,phase=Succeeded node=kind-worker
14.5936,Event,ADDED,eval-sanitize-2-r1-014-fphhf.18d420de0395ccde,reason=Started count=1 msg=Started container task
14.6011,Job,MODIFIED,eval-sanitize-2-r1-003,
14.6105,Job,MODIFIED,eval-sanitize-2-r1-003,
14.6715,Pod,MODIFIED,eval-sanitize-2-r1-008-24xc5,phase=Running node=kind-worker3
14.6784,Pod,MODIFIED,eval-sanitize-2-r1-014-fphhf,phase=Running node=kind-worker3
14.6809,Job,MODIFIED,eval-sanitize-2-r1-001,
14.6994,Pod,MODIFIED,eval-sanitize-2-r1-006-srhbl,phase=Running node=kind-worker3
14.7012,Job,MODIFIED,eval-sanitize-2-r1-001,
14.7068,Pod,MODIFIED,eval-sanitize-2-r1-010-cmhnq,phase=Running node=kind-worker3
14.7075,Event,ADDED,eval-sanitize-2-r1-001.18d420de0a58380b,reason=Completed count=1 msg=Job completed
14.7086,Job,MODIFIED,eval-sanitize-2-r1-001,
14.7136,TaskRequest,MODIFIED,eval-sanitize-2-r1-001,phase=Complete job=None
14.7231,Job,MODIFIED,eval-sanitize-2-r1-001,
14.7473,Pod,MODIFIED,eval-sanitize-2-r1-003-8q9hg,phase=Succeeded node=kind-worker2
15.0084,TaskRequest,ADDED,eval-sanitize-2-r1-015,phase=None job=None
15.0122,TaskRequest,MODIFIED,eval-sanitize-2-r1-015,phase=Pending job=None
15.0276,Job,ADDED,eval-sanitize-2-r1-015,
15.0337,Pod,ADDED,eval-sanitize-2-r1-015-2w6kl,phase=Pending node=None
15.0338,TaskRequest,MODIFIED,eval-sanitize-2-r1-015,phase=Scheduled job=None
15.0366,Job,MODIFIED,eval-sanitize-2-r1-015,
15.0403,Event,ADDED,eval-sanitize-2-r1-015.18d420de1e227396,reason=SuccessfulCreate count=1 msg=Created pod: eval-sanitize-2-r1-015-2w6kl
15.0415,Job,MODIFIED,eval-sanitize-2-r1-014,
15.0416,TaskRequest,MODIFIED,eval-sanitize-2-r1-015,phase=Scheduled job=None
15.0459,Pod,MODIFIED,eval-sanitize-2-r1-015-2w6kl,phase=Pending node=None
15.0464,Event,ADDED,eval-sanitize-2-r1-015-2w6kl.18d420de1e96dd30,"reason=FailedScheduling count=None msg=0/6 nodes are available: 2 c_wall violated: 2 conflicting context pair(s) with node memory, 4 node(s) had untolerated taint(s). no new claims to deallocate, preemption: 0/6 nodes are available: 2 No preemption victims found for incoming pod, 4 Preemption is not helpful for scheduling."
15.0503,Job,MODIFIED,eval-sanitize-2-r1-014,
15.0558,Event,ADDED,eval-sanitize-2-r1-015-2w6kl.18d420de1f443551,"reason=FailedScheduling count=None msg=0/6 nodes are available: 2 c_wall violated: 2 conflicting context pair(s) with node memory, 4 node(s) had untolerated taint(s). no new claims to deallocate, preemption: 0/6 nodes are available: 2 No preemption victims found for incoming pod, 4 Preemption is not helpful for scheduling."
15.2661,Pod,MODIFIED,eval-sanitize-2-r1-004-lxbfr,phase=Running node=kind-worker4
15.2703,Node,MODIFIED,kind-worker5,taints=1
15.2729,Job,MODIFIED,eval-sanitize-2-r1-009,
15.2811,Job,MODIFIED,eval-sanitize-2-r1-005,
15.2831,Job,MODIFIED,eval-sanitize-2-r1-009,
15.2842,Pod,MODIFIED,eval-sanitize-2-r1-011-mbg8c,phase=Pending node=None
15.2898,Job,MODIFIED,eval-sanitize-2-r1-005,
15.2919,Pod,MODIFIED,eval-sanitize-2-r1-012-nfhdz,phase=Pending node=None
15.2935,Job,MODIFIED,eval-sanitize-2-r1-007,
15.3007,Pod,MODIFIED,eval-sanitize-2-r1-015-2w6kl,phase=Pending node=None
15.3016,Event,MODIFIED,eval-sanitize-2-r1-015-2w6kl.18d420de1f443551,"reason=FailedScheduling count=None msg=0/6 nodes are available: 2 c_wall violated: 2 conflicting context pair(s) with node memory, 4 node(s) had untolerated taint(s). no new claims to deallocate, preemption: 0/6 nodes are available: 2 No preemption victims found for incoming pod, 4 Preemption is not helpful for scheduling."
15.3024,Job,MODIFIED,eval-sanitize-2-r1-007,
15.346,Pod,MODIFIED,eval-sanitize-2-r1-013-w4d7s,phase=Pending node=None
15.3558,Node,MODIFIED,kind-worker2,taints=1
15.3564,Event,ADDED,eval-sanitize-2-r1-011-mbg8c.18d420de30f5c46d,"reason=FailedScheduling count=None msg=0/6 nodes are available: 1 c_wall violated: 2 conflicting context pair(s) with node memory, 5 node(s) had untolerated taint(s). no new claims to deallocate, preemption: 0/6 nodes are available: 1 No preemption victims found for incoming pod, 5 Preemption is not helpful for scheduling."
15.358,Node,MODIFIED,kind-worker5,taints=1
15.3583,Event,ADDED,eval-sanitize-2-r1-012-nfhdz.18d420de312bceb6,"reason=FailedScheduling count=None msg=0/6 nodes are available: 1 c_wall violated: 1 conflicting context pair(s) with node memory, 5 node(s) had untolerated taint(s). no new claims to deallocate, preemption: 0/6 nodes are available: 1 No preemption victims found for incoming pod, 5 Preemption is not helpful for scheduling."
15.3845,Job,MODIFIED,eval-sanitize-2-r1-002,
15.3858,Event,ADDED,eval-sanitize-2-r1-015-2w6kl.18d420de3261d9d1,"reason=FailedScheduling count=None msg=0/6 nodes are available: 1 c_wall violated: 2 conflicting context pair(s) with node memory, 5 node(s) had untolerated taint(s). no new claims to deallocate, preemption: 0/6 nodes are available: 1 No preemption victims found for incoming pod, 5 Preemption is not helpful for scheduling."
15.386,Event,ADDED,eval-sanitize-2-r1-013-w4d7s.18d420de328ee9dc,"reason=FailedScheduling count=None msg=0/6 nodes are available: 1 c_wall violated: 2 conflicting context pair(s) with node memory, 5 node(s) had untolerated taint(s). no new claims to deallocate, preemption: 0/6 nodes are available: 1 No preemption victims found for incoming pod, 5 Preemption is not helpful for scheduling."
15.3865,Event,MODIFIED,eval-sanitize-2-r1-011-mbg8c.18d420de30f5c46d,"reason=FailedScheduling count=None msg=0/6 nodes are available: 1 c_wall violated: 2 conflicting context pair(s) with node memory, 5 node(s) had untolerated taint(s). no new claims to deallocate, preemption: 0/6 nodes are available: 1 No preemption victims found for incoming pod, 5 Preemption is not helpful for scheduling."
15.3887,Event,MODIFIED,eval-sanitize-2-r1-012-nfhdz.18d420de312bceb6,"reason=FailedScheduling count=None msg=0/6 nodes are available: 1 c_wall violated: 1 conflicting context pair(s) with node memory, 5 node(s) had untolerated taint(s). no new claims to deallocate, preemption: 0/6 nodes are available: 1 No preemption victims found for incoming pod, 5 Preemption is not helpful for scheduling."
15.391,Event,MODIFIED,eval-sanitize-2-r1-015-2w6kl.18d420de3261d9d1,"reason=FailedScheduling count=None msg=0/6 nodes are available: 1 c_wall violated: 2 conflicting context pair(s) with node memory, 5 node(s) had untolerated taint(s). no new claims to deallocate, preemption: 0/6 nodes are available: 1 No preemption victims found for incoming pod, 5 Preemption is not helpful for scheduling."
15.3925,Pod,MODIFIED,eval-sanitize-2-r1-002-94z5p,phase=Succeeded node=kind-worker
15.3934,Job,MODIFIED,eval-sanitize-2-r1-002,
15.5491,Node,MODIFIED,kind-worker2,taints=0
15.5579,Pod,MODIFIED,eval-sanitize-2-r1-013-w4d7s,phase=Pending node=kind-worker2
15.5597,Node,MODIFIED,kind-worker2,taints=0
15.5612,Event,ADDED,eval-sanitize-2-r1-013-w4d7s.18d420de3d56ba37,reason=Scheduled count=None msg=Successfully assigned compute/eval-sanitize-2-r1-013-w4d7s to kind-worker2
15.5646,Pod,MODIFIED,eval-sanitize-2-r1-011-mbg8c,phase=Pending node=kind-worker2
15.5709,Pod,MODIFIED,eval-sanitize-2-r1-013-w4d7s,phase=Pending node=kind-worker2
15.572,Event,ADDED,eval-sanitize-2-r1-011-mbg8c.18d420de3dc164ea,reason=Scheduled count=None msg=Successfully assigned compute/eval-sanitize-2-r1-011-mbg8c to kind-worker2
15.573,Pod,MODIFIED,eval-sanitize-2-r1-012-nfhdz,phase=Pending node=kind-worker2
15.5755,Node,MODIFIED,kind-worker2,taints=0
15.5797,Event,ADDED,eval-sanitize-2-r1-012-nfhdz.18d420de3e434161,reason=Scheduled count=None msg=Successfully assigned compute/eval-sanitize-2-r1-012-nfhdz to kind-worker2
15.581,Pod,MODIFIED,eval-sanitize-2-r1-011-mbg8c,phase=Pending node=kind-worker2
15.5869,Node,MODIFIED,kind-worker2,taints=0
15.5887,Pod,MODIFIED,eval-sanitize-2-r1-012-nfhdz,phase=Pending node=kind-worker2
15.5966,Node,MODIFIED,kind-worker2,taints=0
15.6062,Job,MODIFIED,eval-sanitize-2-r1-003,
15.6138,Pod,MODIFIED,eval-sanitize-2-r1-003-8q9hg,phase=Succeeded node=kind-worker2
15.6151,Job,MODIFIED,eval-sanitize-2-r1-003,
15.6482,Pod,MODIFIED,eval-sanitize-2-r1-015-2w6kl,phase=Pending node=kind-worker2
15.6523,Event,ADDED,eval-sanitize-2-r1-015-2w6kl.18d420de42bf6b4d,reason=Scheduled count=None msg=Successfully assigned compute/eval-sanitize-2-r1-015-2w6kl to kind-worker2
15.6587,Node,MODIFIED,kind-worker2,taints=0
15.66,Pod,MODIFIED,eval-sanitize-2-r1-015-2w6kl,phase=Pending node=kind-worker2
15.6673,Node,MODIFIED,kind-worker2,taints=0
15.6754,Job,MODIFIED,eval-sanitize-2-r1-008,
15.684,Job,MODIFIED,eval-sanitize-2-r1-008,
15.7039,Job,MODIFIED,eval-sanitize-2-r1-006,
15.7111,Job,MODIFIED,eval-sanitize-2-r1-010,
15.713,Job,MODIFIED,eval-sanitize-2-r1-006,
15.719,Job,MODIFIED,eval-sanitize-2-r1-010,
15.8704,Node,MODIFIED,kind-worker3,taints=1
15.9367,Node,MODIFIED,kind-worker2,taints=0
15.9558,Node,MODIFIED,kind-worker,taints=1
15.9575,Node,MODIFIED,kind-worker3,taints=1
15.9604,Node,MODIFIED,kind-worker2,taints=0
16.0066,Event,ADDED,eval-sanitize-2-r1-013-w4d7s.18d420de57d6569c,"reason=Pulled count=1 msg=Container image ""busybox:musl"" already present on machine"
16.0111,Event,ADDED,eval-sanitize-2-r1-011-mbg8c.18d420de58134e43,"reason=Pulled count=1 msg=Container image ""busybox:musl"" already present on machine"
16.0142,TaskRequest,ADDED,eval-sanitize-2-r1-016,phase=None job=None
16.0223,Event,ADDED,eval-sanitize-2-r1-012-nfhdz.18d420de5897c52c,"reason=Pulled count=1 msg=Container image ""busybox:musl"" already present on machine"
16.0237,TaskRequest,MODIFIED,eval-sanitize-2-r1-016,phase=Pending job=None
16.039,Event,ADDED,eval-sanitize-2-r1-013-w4d7s.18d420de59a5c3d3,reason=Created count=1 msg=Created container: task
16.0403,Job,MODIFIED,eval-sanitize-2-r1-015,
16.0458,Job,ADDED,eval-sanitize-2-r1-016,
16.0489,Event,ADDED,eval-sanitize-2-r1-011-mbg8c.18d420de5a4462b5,reason=Created count=1 msg=Created container: task
16.0519,Node,MODIFIED,kind-worker,taints=0
16.0542,TaskRequest,MODIFIED,eval-sanitize-2-r1-016,phase=Scheduled job=None
16.0574,Event,ADDED,eval-sanitize-2-r1-015-2w6kl.18d420de5aaf177c,"reason=Pulled count=1 msg=Container image ""busybox:musl"" already present on machine"
16.0587,Pod,ADDED,eval-sanitize-2-r1-016-kq9wb,phase=Pending node=None
16.064,Job,MODIFIED,eval-sanitize-2-r1-016,
16.0649,Event,ADDED,eval-sanitize-2-r1-016.18d420de5b332d75,reason=SuccessfulCreate count=1 msg=Created pod: eval-sanitize-2-r1-016-kq9wb
16.0651,Event,ADDED,eval-sanitize-2-r1-012-nfhdz.18d420de5aeed255,reason=Created count=1 msg=Created container: task
16.0674,TaskRequest,MODIFIED,eval-sanitize-2-r1-016,phase=Scheduled job=None
16.0691,Job,MODIFIED,eval-sanitize-2-r1-015,
16.0731,Pod,MODIFIED,eval-sanitize-2-r1-016-kq9wb,phase=Pending node=kind-worker
16.0752,Node,MODIFIED,kind-worker,taints=0
16.0773,Event,ADDED,eval-sanitize-2-r1-016-kq9wb.18d420de5c15b6f3,reason=Scheduled count=None msg=Successfully assigned compute/eval-sanitize-2-r1-016-kq9wb to kind-worker
16.085,Pod,MODIFIED,eval-sanitize-2-r1-016-kq9wb,phase=Pending node=kind-worker
16.0866,Event,ADDED,eval-sanitize-2-r1-015-2w6kl.18d420de5c7b225e,reason=Created count=1 msg=Created container: task
16.0882,Node,MODIFIED,kind-worker,taints=0
16.0913,Event,ADDED,eval-sanitize-2-r1-013-w4d7s.18d420de5c7f97a1,reason=Started count=1 msg=Started container task
16.0956,Event,ADDED,eval-sanitize-2-r1-011-mbg8c.18d420de5d35a297,reason=Started count=1 msg=Started container task
16.1027,Event,ADDED,eval-sanitize-2-r1-012-nfhdz.18d420de5da8beb0,reason=Started count=1 msg=Started container task
16.1207,Event,ADDED,eval-sanitize-2-r1-015-2w6kl.18d420de5eaf1011,reason=Started count=1 msg=Started container task
16.165,Node,MODIFIED,kind-worker,taints=0
16.2472,Node,MODIFIED,kind-worker,taints=0
16.2716,Job,MODIFIED,eval-sanitize-2-r1-004,
16.2809,Job,MODIFIED,eval-sanitize-2-r1-004,
16.3912,Job,MODIFIED,eval-sanitize-2-r1-002,
16.3952,Job,MODIFIED,eval-sanitize-2-r1-002,
16.4013,Event,ADDED,eval-sanitize-2-r1-002.18d420de6f4cccb7,reason=Completed count=1 msg=Job completed
16.4084,Job,MODIFIED,eval-sanitize-2-r1-002,
16.4135,TaskRequest,MODIFIED,eval-sanitize-2-r1-002,phase=Complete job=None
16.4233,Job,MODIFIED,eval-sanitize-2-r1-002,
16.4402,Pod,MODIFIED,eval-sanitize-2-r1-004-lxbfr,phase=Succeeded node=kind-worker4
16.5082,Event,ADDED,eval-sanitize-2-r1-016-kq9wb.18d420de75c96099,"reason=Pulled count=1 msg=Container image ""busybox:musl"" already present on machine"
16.5261,Event,ADDED,eval-sanitize-2-r1-016-kq9wb.18d420de76cf49df,reason=Created count=1 msg=Created container: task
16.5846,Event,ADDED,eval-sanitize-2-r1-016-kq9wb.18d420de7a59b3c6,reason=Started count=1 msg=Started container task
16.6024,Pod,MODIFIED,eval-sanitize-2-r1-012-nfhdz,phase=Running node=kind-worker2
16.6084,Pod,MODIFIED,eval-sanitize-2-r1-015-2w6kl,phase=Running node=kind-worker2
16.612,Job,MODIFIED,eval-sanitize-2-r1-003,
16.6145,Pod,MODIFIED,eval-sanitize-2-r1-013-w4d7s,phase=Running node=kind-worker2
16.6162,Job,MODIFIED,eval-sanitize-2-r1-003,
16.6216,Pod,MODIFIED,eval-sanitize-2-r1-011-mbg8c,phase=Running node=kind-worker2
16.6219,Event,ADDED,eval-sanitize-2-r1-003.18d420de7c7a8fd4,reason=Completed count=1 msg=Job completed
16.6287,Job,MODIFIED,eval-sanitize-2-r1-003,
16.6329,TaskRequest,MODIFIED,eval-sanitize-2-r1-003,phase=Complete job=None
16.6421,Job,MODIFIED,eval-sanitize-2-r1-003,
16.9956,Node,MODIFIED,kind-worker4,taints=1
17.007,TaskRequest,ADDED,eval-sanitize-2-r1-017,phase=None job=None
17.0104,TaskRequest,MODIFIED,eval-sanitize-2-r1-017,phase=Pending job=None
17.0251,Job,ADDED,eval-sanitize-2-r1-017,
17.0291,TaskRequest,MODIFIED,eval-sanitize-2-r1-017,phase=Scheduled job=None
17.0323,Pod,ADDED,eval-sanitize-2-r1-017-6455d,phase=Pending node=None
17.0348,Job,MODIFIED,eval-sanitize-2-r1-017,
17.0375,Event,ADDED,eval-sanitize-2-r1-017.18d420de95401a36,reason=SuccessfulCreate count=1 msg=Created pod: eval-sanitize-2-r1-017-6455d
17.0376,TaskRequest,MODIFIED,eval-sanitize-2-r1-017,phase=Scheduled job=None
17.0432,Pod,MODIFIED,eval-sanitize-2-r1-017-6455d,phase=Pending node=None
17.0444,Event,ADDED,eval-sanitize-2-r1-017-6455d.18d420de95a67d8a,"reason=FailedScheduling count=None msg=0/6 nodes are available: 1 c_wall violated: 1 conflicting context pair(s) with node memory, 1 c_wall violated: 3 conflicting context pair(s) with node memory, 4 node(s) had untolerated taint(s). no new claims to deallocate, preemption: 0/6 nodes are available: 2 No preemption victims found for incoming pod, 4 Preemption is not helpful for scheduling."
17.0474,Job,MODIFIED,eval-sanitize-2-r1-015,
17.0489,Node,MODIFIED,kind-worker4,taints=0
17.0556,Node,MODIFIED,kind-worker4,taints=0
17.0565,Event,ADDED,eval-sanitize-2-r1-017-6455d.18d420de964ab054,"reason=FailedScheduling count=None msg=0/6 nodes are available: 1 c_wall violated: 1 conflicting context pair(s) with node memory, 1 c_wall violated: 3 conflicting context pair(s) with node memory, 4 node(s) had untolerated taint(s). no new claims to deallocate, preemption: 0/6 nodes are available: 2 No preemption victims found for incoming pod, 4 Preemption is not helpful for scheduling."
17.0574,Job,MODIFIED,eval-sanitize-2-r1-015,
17.0596,Pod,MODIFIED,eval-sanitize-2-r1-017-6455d,phase=Pending node=kind-worker4
17.0641,Job,MODIFIED,eval-sanitize-2-r1-016,
17.0644,Event,ADDED,eval-sanitize-2-r1-017-6455d.18d420de96e2a559,reason=Scheduled count=None msg=Successfully assigned compute/eval-sanitize-2-r1-017-6455d to kind-worker4
17.068,Node,MODIFIED,kind-worker4,taints=0
17.0751,Pod,MODIFIED,eval-sanitize-2-r1-017-6455d,phase=Pending node=kind-worker4
17.0761,Job,MODIFIED,eval-sanitize-2-r1-016,
17.0964,Node,MODIFIED,kind-worker4,taints=0
17.1051,Node,MODIFIED,kind-worker4,taints=0
17.2772,Job,MODIFIED,eval-sanitize-2-r1-004,
17.2863,Pod,MODIFIED,eval-sanitize-2-r1-004-lxbfr,phase=Succeeded node=kind-worker4
17.2872,Job,MODIFIED,eval-sanitize-2-r1-004,
17.3758,Pod,MODIFIED,eval-sanitize-2-r1-016-kq9wb,phase=Running node=kind-worker
17.4854,Event,ADDED,eval-sanitize-2-r1-017-6455d.18d420deaff705fd,"reason=Pulled count=1 msg=Container image ""busybox:musl"" already present on machine"
17.5028,Event,ADDED,eval-sanitize-2-r1-017-6455d.18d420deb11094b4,reason=Created count=1 msg=Created container: task
17.5365,Event,ADDED,eval-sanitize-2-r1-017-6455d.18d420deb3193517,reason=Started count=1 msg=Started container task
17.6062,Job,MODIFIED,eval-sanitize-2-r1-012,
17.6152,Job,MODIFIED,eval-sanitize-2-r1-012,
17.6179,Job,MODIFIED,eval-sanitize-2-r1-013,
17.6249,Job,MODIFIED,eval-sanitize-2-r1-011,
17.6272,Job,MODIFIED,eval-sanitize-2-r1-013,
17.6331,Job,MODIFIED,eval-sanitize-2-r1-011,
17.6499,Node,MODIFIED,kind-worker2,taints=1
17.6668,Node,MODIFIED,kind-worker2,taints=1
18.0071,TaskRequest,ADDED,eval-sanitize-2-r1-018,phase=None job=None
18.0118,TaskRequest,MODIFIED,eval-sanitize-2-r1-018,phase=Pending job=None
18.026,Job,ADDED,eval-sanitize-2-r1-018,
18.032,Pod,ADDED,eval-sanitize-2-r1-018-tgv4l,phase=Pending node=None
18.0333,TaskRequest,MODIFIED,eval-sanitize-2-r1-018,phase=Scheduled job=None
18.0362,Job,MODIFIED,eval-sanitize-2-r1-018,
18.0383,Event,ADDED,eval-sanitize-2-r1-018.18d420ded0dc084b,reason=SuccessfulCreate count=1 msg=Created pod: eval-sanitize-2-r1-018-tgv4l
18.0392,Job,MODIFIED,eval-sanitize-2-r1-017,
18.0414,TaskRequest,MODIFIED,eval-sanitize-2-r1-018,phase=Scheduled job=None
18.0433,Pod,MODIFIED,eval-sanitize-2-r1-018-tgv4l,phase=Pending node=kind-worker
18.049,Job,MODIFIED,eval-sanitize-2-r1-017,
18.0493,Event,ADDED,eval-sanitize-2-r1-018-tgv4l.18d420ded1887112,reason=Scheduled count=None msg=Successfully assigned compute/eval-sanitize-2-r1-018-tgv4l to kind-worker
18.0536,Node,MODIFIED,kind-worker,taints=0
18.0552,Pod,MODIFIED,eval-sanitize-2-r1-018-tgv4l,phase=Pending node=kind-worker
18.0634,Node,MODIFIED,kind-worker,taints=0
18.0688,Job,MODIFIED,eval-sanitize-2-r1-016,
18.0776,Job,MODIFIED,eval-sanitize-2-r1-016,
18.1769,Node,MODIFIED,kind-worker,taints=1
18.2551,Node,MODIFIED,kind-worker,taints=1
18.2748,Pod,MODIFIED,eval-sanitize-2-r1-017-6455d,phase=Running node=kind-worker4
18.2823,Job,MODIFIED,eval-sanitize-2-r1-004,
18.2879,Job,MODIFIED,eval-sanitize-2-r1-004,
18.2908,Event,ADDED,eval-sanitize-2-r1-004.18d420dee01d4d08,reason=Completed count=1 msg=Job completed
18.2966,Job,MODIFIED,eval-sanitize-2-r1-004,
18.3016,TaskRequest,MODIFIED,eval-sanitize-2-r1-004,phase=Complete job=None
18.3106,Job,MODIFIED,eval-sanitize-2-r1-004,
18.453,Event,ADDED,eval-sanitize-2-r1-018-tgv4l.18d420dee9a6e1aa,"reason=Pulled count=1 msg=Container image ""busybox:musl"" already present on machine"
18.469,Event,ADDED,eval-sanitize-2-r1-018-tgv4l.18d420deeab7576c,reason=Created count=1 msg=Created container: task
18.5017,Event,ADDED,eval-sanitize-2-r1-018-tgv4l.18d420deeca1f0e6,reason=Started count=1 msg=Started container task
19.0077,TaskRequest,ADDED,eval-sanitize-2-r1-019,phase=None job=None
19.013,TaskRequest,MODIFIED,eval-sanitize-2-r1-019,phase=Pending job=None
19.026,Job,ADDED,eval-sanitize-2-r1-019,
19.0318,TaskRequest,MODIFIED,eval-sanitize-2-r1-019,phase=Scheduled job=None
19.0346,Pod,ADDED,eval-sanitize-2-r1-019-9fbj8,phase=Pending node=None
19.0363,Job,MODIFIED,eval-sanitize-2-r1-019,
19.0386,Job,MODIFIED,eval-sanitize-2-r1-018,
19.0399,Event,ADDED,eval-sanitize-2-r1-019.18d420df0c9cccc1,reason=SuccessfulCreate count=1 msg=Created pod: eval-sanitize-2-r1-019-9fbj8
19.0401,TaskRequest,MODIFIED,eval-sanitize-2-r1-019,phase=Scheduled job=None
19.0442,Pod,MODIFIED,eval-sanitize-2-r1-019-9fbj8,phase=Pending node=None
19.045,Event,ADDED,eval-sanitize-2-r1-019-9fbj8.18d420df0ce024c9,"reason=FailedScheduling count=None msg=0/6 nodes are available: 1 c_wall violated: 1 conflicting context pair(s) with node memory, 5 node(s) had untolerated taint(s). no new claims to deallocate, preemption: 0/6 nodes are available: 1 No preemption victims found for incoming pod, 5 Preemption is not helpful for scheduling."
19.0458,Job,MODIFIED,eval-sanitize-2-r1-017,
19.0474,Job,MODIFIED,eval-sanitize-2-r1-018,
19.0505,Event,ADDED,eval-sanitize-2-r1-019-9fbj8.18d420df0d65b4e5,"reason=FailedScheduling count=None msg=0/6 nodes are available: 1 c_wall violated: 1 conflicting context pair(s) with node memory, 5 node(s) had untolerated taint(s). no new claims to deallocate, preemption: 0/6 nodes are available: 1 No preemption victims found for incoming pod, 5 Preemption is not helpful for scheduling."
19.0533,Job,MODIFIED,eval-sanitize-2-r1-017,
19.0662,Node,MODIFIED,kind-worker4,taints=1
19.0704,Pod,MODIFIED,eval-sanitize-2-r1-019-9fbj8,phase=Pending node=None
19.0709,Event,MODIFIED,eval-sanitize-2-r1-019-9fbj8.18d420df0d65b4e5,"reason=FailedScheduling count=None msg=0/6 nodes are available: 1 c_wall violated: 1 conflicting context pair(s) with node memory, 5 node(s) had untolerated taint(s). no new claims to deallocate, preemption: 0/6 nodes are available: 1 No preemption victims found for incoming pod, 5 Preemption is not helpful for scheduling."
19.0783,Node,MODIFIED,kind-worker4,taints=1
19.3813,Pod,MODIFIED,eval-sanitize-2-r1-018-tgv4l,phase=Running node=kind-worker
20.0093,TaskRequest,ADDED,eval-sanitize-2-r1-020,phase=None job=None
20.0127,TaskRequest,MODIFIED,eval-sanitize-2-r1-020,phase=Pending job=None
20.0298,Job,ADDED,eval-sanitize-2-r1-020,
20.0343,TaskRequest,MODIFIED,eval-sanitize-2-r1-020,phase=Scheduled job=None
20.0384,Pod,ADDED,eval-sanitize-2-r1-020-jm8sr,phase=Pending node=None
20.0413,Job,MODIFIED,eval-sanitize-2-r1-019,
20.0425,Job,MODIFIED,eval-sanitize-2-r1-020,
20.0431,TaskRequest,MODIFIED,eval-sanitize-2-r1-020,phase=Scheduled job=None
20.044,Job,MODIFIED,eval-sanitize-2-r1-018,
20.0448,Pod,MODIFIED,eval-sanitize-2-r1-020-jm8sr,phase=Pending node=None
20.0453,Event,ADDED,eval-sanitize-2-r1-020.18d420df48772875,reason=SuccessfulCreate count=1 msg=Created pod: eval-sanitize-2-r1-020-jm8sr
20.0457,Event,ADDED,eval-sanitize-2-r1-020-jm8sr.18d420df487d854d,"reason=FailedScheduling count=None msg=0/6 nodes are available: 6 node(s) had untolerated taint(s). no new claims to deallocate, preemption: 0/6 nodes are available: 6 Preemption is not helpful for scheduling."
20.0536,Job,MODIFIED,eval-sanitize-2-r1-019,
20.0553,Job,MODIFIED,eval-sanitize-2-r1-018,
21.0074,TaskRequest,ADDED,eval-sanitize-2-r1-021,phase=None job=None
21.0121,TaskRequest,MODIFIED,eval-sanitize-2-r1-021,phase=Pending job=None
21.0258,Job,ADDED,eval-sanitize-2-r1-021,
21.0306,TaskRequest,MODIFIED,eval-sanitize-2-r1-021,phase=Scheduled job=None
21.0328,Pod,ADDED,eval-sanitize-2-r1-021-xwkkx,phase=Pending node=None
21.0345,Job,MODIFIED,eval-sanitize-2-r1-021,
21.0385,Event,ADDED,eval-sanitize-2-r1-021.18d420df83a8a19b,reason=SuccessfulCreate count=1 msg=Created pod: eval-sanitize-2-r1-021-xwkkx
21.039,Event,ADDED,eval-sanitize-2-r1-021-xwkkx.18d420df83b68cba,"reason=FailedScheduling count=None msg=0/6 nodes are available: 6 node(s) had untolerated taint(s). no new claims to deallocate, preemption: 0/6 nodes are available: 6 Preemption is not helpful for scheduling."
21.0399,Pod,MODIFIED,eval-sanitize-2-r1-021-xwkkx,phase=Pending node=None
21.0401,TaskRequest,MODIFIED,eval-sanitize-2-r1-021,phase=Scheduled job=None
21.0425,Job,MODIFIED,eval-sanitize-2-r1-020,
21.051,Job,MODIFIED,eval-sanitize-2-r1-020,
22.0089,TaskRequest,ADDED,eval-sanitize-2-r1-022,phase=None job=None
22.0128,TaskRequest,MODIFIED,eval-sanitize-2-r1-022,phase=Pending job=None
22.0272,Job,ADDED,eval-sanitize-2-r1-022,
22.031,TaskRequest,MODIFIED,eval-sanitize-2-r1-022,phase=Scheduled job=None
22.0347,Pod,ADDED,eval-sanitize-2-r1-022-44zg5,phase=Pending node=None
22.0367,Job,MODIFIED,eval-sanitize-2-r1-022,
22.0387,Job,MODIFIED,eval-sanitize-2-r1-021,
22.0404,Event,ADDED,eval-sanitize-2-r1-022.18d420dfbf64c12e,reason=SuccessfulCreate count=1 msg=Created pod: eval-sanitize-2-r1-022-44zg5
22.0406,Event,ADDED,eval-sanitize-2-r1-022-44zg5.18d420dfbf70c22c,"reason=FailedScheduling count=None msg=0/6 nodes are available: 6 node(s) had untolerated taint(s). no new claims to deallocate, preemption: 0/6 nodes are available: 6 Preemption is not helpful for scheduling."
22.0407,TaskRequest,MODIFIED,eval-sanitize-2-r1-022,phase=Scheduled job=None
22.0415,Pod,MODIFIED,eval-sanitize-2-r1-022-44zg5,phase=Pending node=None
22.0473,Job,MODIFIED,eval-sanitize-2-r1-021,
23.0092,TaskRequest,ADDED,eval-sanitize-2-r1-023,phase=None job=None
23.0132,TaskRequest,MODIFIED,eval-sanitize-2-r1-023,phase=Pending job=None
23.0296,Job,ADDED,eval-sanitize-2-r1-023,
23.0369,Pod,ADDED,eval-sanitize-2-r1-023-42sh8,phase=Pending node=None
23.0379,TaskRequest,MODIFIED,eval-sanitize-2-r1-023,phase=Scheduled job=None
23.0387,Job,MODIFIED,eval-sanitize-2-r1-023,
23.0403,Job,MODIFIED,eval-sanitize-2-r1-022,
23.0443,Event,ADDED,eval-sanitize-2-r1-023.18d420dffb1f49d5,reason=SuccessfulCreate count=1 msg=Created pod: eval-sanitize-2-r1-023-42sh8
23.0445,Event,ADDED,eval-sanitize-2-r1-023-42sh8.18d420dffb29d3c5,"reason=FailedScheduling count=None msg=0/6 nodes are available: 6 node(s) had untolerated taint(s). no new claims to deallocate, preemption: 0/6 nodes are available: 6 Preemption is not helpful for scheduling."
23.0454,Pod,MODIFIED,eval-sanitize-2-r1-023-42sh8,phase=Pending node=None
23.0456,TaskRequest,MODIFIED,eval-sanitize-2-r1-023,phase=Scheduled job=None
23.0499,Job,MODIFIED,eval-sanitize-2-r1-022,
24.0069,TaskRequest,ADDED,eval-sanitize-2-r1-024,phase=None job=None
24.0106,TaskRequest,MODIFIED,eval-sanitize-2-r1-024,phase=Pending job=None
24.0263,Job,ADDED,eval-sanitize-2-r1-024,
24.0312,TaskRequest,MODIFIED,eval-sanitize-2-r1-024,phase=Scheduled job=None
24.033,Pod,ADDED,eval-sanitize-2-r1-024-mfnr5,phase=Pending node=None
24.0347,Job,MODIFIED,eval-sanitize-2-r1-024,
24.0385,Event,ADDED,eval-sanitize-2-r1-024.18d420e03684d939,reason=SuccessfulCreate count=1 msg=Created pod: eval-sanitize-2-r1-024-mfnr5
24.0396,Pod,MODIFIED,eval-sanitize-2-r1-024-mfnr5,phase=Pending node=None
24.0401,Event,ADDED,eval-sanitize-2-r1-024-mfnr5.18d420e0368ee596,"reason=FailedScheduling count=None msg=0/6 nodes are available: 6 node(s) had untolerated taint(s). no new claims to deallocate, preemption: 0/6 nodes are available: 6 Preemption is not helpful for scheduling."
24.0403,TaskRequest,MODIFIED,eval-sanitize-2-r1-024,phase=Scheduled job=None
24.0428,Job,MODIFIED,eval-sanitize-2-r1-023,
24.0511,Job,MODIFIED,eval-sanitize-2-r1-023,
24.2884,Pod,MODIFIED,eval-sanitize-2-r1-009-rqs9m,phase=Running node=kind-worker5
24.2935,Pod,MODIFIED,eval-sanitize-2-r1-005-rng6l,phase=Running node=kind-worker5
24.2996,Pod,MODIFIED,eval-sanitize-2-r1-007-z7mxg,phase=Running node=kind-worker5
24.6918,Pod,MODIFIED,eval-sanitize-2-r1-006-srhbl,phase=Running node=kind-worker3
24.6981,Pod,MODIFIED,eval-sanitize-2-r1-010-cmhnq,phase=Running node=kind-worker3
24.7043,Pod,MODIFIED,eval-sanitize-2-r1-008-24xc5,phase=Running node=kind-worker3
24.7101,Pod,MODIFIED,eval-sanitize-2-r1-014-fphhf,phase=Running node=kind-worker3
25.0207,TaskRequest,ADDED,eval-sanitize-2-r1-025,phase=None job=None
25.0249,TaskRequest,MODIFIED,eval-sanitize-2-r1-025,phase=Pending job=None
25.0384,Job,MODIFIED,eval-sanitize-2-r1-024,
25.0392,Job,ADDED,eval-sanitize-2-r1-025,
25.0461,Pod,ADDED,eval-sanitize-2-r1-025-7m5rb,phase=Pending node=None
25.0463,TaskRequest,MODIFIED,eval-sanitize-2-r1-025,phase=Scheduled job=None
25.0485,Job,MODIFIED,eval-sanitize-2-r1-025,
25.0509,Pod,MODIFIED,eval-sanitize-2-r1-025-7m5rb,phase=Pending node=None
25.0521,Event,ADDED,eval-sanitize-2-r1-025.18d420e072e0bb5a,reason=SuccessfulCreate count=1 msg=Created pod: eval-sanitize-2-r1-025-7m5rb
25.0523,Event,ADDED,eval-sanitize-2-r1-025-7m5rb.18d420e072e9d695,"reason=FailedScheduling count=None msg=0/6 nodes are available: 6 node(s) had untolerated taint(s). no new claims to deallocate, preemption: 0/6 nodes are available: 6 Preemption is not helpful for scheduling."
25.0527,TaskRequest,MODIFIED,eval-sanitize-2-r1-025,phase=Scheduled job=None
25.0555,Job,MODIFIED,eval-sanitize-2-r1-024,
25.2937,Job,MODIFIED,eval-sanitize-2-r1-009,
25.2982,Job,MODIFIED,eval-sanitize-2-r1-005,
25.3042,Job,MODIFIED,eval-sanitize-2-r1-009,
25.3066,Job,MODIFIED,eval-sanitize-2-r1-007,
25.3092,Job,MODIFIED,eval-sanitize-2-r1-005,
25.3166,Job,MODIFIED,eval-sanitize-2-r1-007,
25.4251,Pod,MODIFIED,eval-sanitize-2-r1-007-z7mxg,phase=Succeeded node=kind-worker5
25.4309,Pod,MODIFIED,eval-sanitize-2-r1-005-rng6l,phase=Succeeded node=kind-worker5
25.4373,Pod,MODIFIED,eval-sanitize-2-r1-009-rqs9m,phase=Succeeded node=kind-worker5
25.6978,Job,MODIFIED,eval-sanitize-2-r1-006,
25.7041,Job,MODIFIED,eval-sanitize-2-r1-010,
25.7084,Job,MODIFIED,eval-sanitize-2-r1-006,
25.71,Job,MODIFIED,eval-sanitize-2-r1-008,
25.713,Job,MODIFIED,eval-sanitize-2-r1-010,
25.7157,Job,MODIFIED,eval-sanitize-2-r1-014,
25.7216,Job,MODIFIED,eval-sanitize-2-r1-008,
25.7247,Job,MODIFIED,eval-sanitize-2-r1-014,
25.8459,Node,MODIFIED,kind-worker5,taints=1
25.8559,Pod,MODIFIED,eval-sanitize-2-r1-014-fphhf,phase=Succeeded node=kind-worker3
25.8601,Node,MODIFIED,kind-worker5,taints=0
25.8662,Pod,MODIFIED,eval-sanitize-2-r1-019-9fbj8,phase=Pending node=kind-worker5
25.8689,Node,MODIFIED,kind-worker5,taints=0
25.8727,Event,ADDED,eval-sanitize-2-r1-019-9fbj8.18d420e0a3c0f28a,reason=Scheduled count=None msg=Successfully assigned compute/eval-sanitize-2-r1-019-9fbj8 to kind-worker5
25.877,Pod,MODIFIED,eval-sanitize-2-r1-020-jm8sr,phase=Pending node=kind-worker5
25.8779,Pod,MODIFIED,eval-sanitize-2-r1-021-xwkkx,phase=Pending node=kind-worker5
25.8826,Node,MODIFIED,kind-worker5,taints=0
25.8842,Event,ADDED,eval-sanitize-2-r1-020-jm8sr.18d420e0a458b5e9,reason=Scheduled count=None msg=Successfully assigned compute/eval-sanitize-2-r1-020-jm8sr to kind-worker5
25.8845,Event,ADDED,eval-sanitize-2-r1-021-xwkkx.18d420e0a46c5ecc,reason=Scheduled count=None msg=Successfully assigned compute/eval-sanitize-2-r1-021-xwkkx to kind-worker5
25.8858,Pod,MODIFIED,eval-sanitize-2-r1-019-9fbj8,phase=Pending node=kind-worker5
25.887,Pod,MODIFIED,eval-sanitize-2-r1-022-44zg5,phase=Pending node=kind-worker5
25.8877,Event,ADDED,eval-sanitize-2-r1-023-42sh8.18d420e0a49bef2a,"reason=FailedScheduling count=None msg=0/6 nodes are available: 1 c_wall violated: 3 conflicting context pair(s) with node memory, 5 node(s) had untolerated taint(s). no new claims to deallocate, preemption: 0/6 nodes are available: 1 No preemption victims found for incoming pod, 5 Preemption is not helpful for scheduling."
25.889,Pod,MODIFIED,eval-sanitize-2-r1-023-42sh8,phase=Pending node=None
25.8953,Pod,MODIFIED,eval-sanitize-2-r1-020-jm8sr,phase=Pending node=kind-worker5
25.9033,Pod,MODIFIED,eval-sanitize-2-r1-021-xwkkx,phase=Pending node=kind-worker5
25.9058,Pod,MODIFIED,eval-sanitize-2-r1-010-cmhnq,phase=Succeeded node=kind-worker3
25.9097,Pod,MODIFIED,eval-sanitize-2-r1-022-44zg5,phase=Pending node=kind-worker5
25.9119,Pod,MODIFIED,eval-sanitize-2-r1-006-srhbl,phase=Succeeded node=kind-worker3
25.9174,Pod,MODIFIED,eval-sanitize-2-r1-008-24xc5,phase=Succeeded node=kind-worker3
25.9438,Event,ADDED,eval-sanitize-2-r1-022-44zg5.18d420e0a82cdc42,reason=Scheduled count=None msg=Successfully assigned compute/eval-sanitize-2-r1-022-44zg5 to kind-worker5
25.9519,Pod,MODIFIED,eval-sanitize-2-r1-024-mfnr5,phase=Pending node=kind-worker5
25.9564,Node,MODIFIED,kind-worker5,taints=0
25.9657,Event,ADDED,eval-sanitize-2-r1-025-7m5rb.18d420e0a895b70d,"reason=FailedScheduling count=None msg=0/6 nodes are available: 1 c_wall violated: 3 conflicting context pair(s) with node memory, 5 node(s) had untolerated taint(s). no new claims to deallocate, preemption: 0/6 nodes are available: 1 No preemption victims found for incoming pod, 5 Preemption is not helpful for scheduling."
25.9667,Pod,MODIFIED,eval-sanitize-2-r1-025-7m5rb,phase=Pending node=None
25.9687,Event,ADDED,eval-sanitize-2-r1-024-mfnr5.18d420e0a8aab91f,reason=Scheduled count=None msg=Successfully assigned compute/eval-sanitize-2-r1-024-mfnr5 to kind-worker5
25.9703,Node,MODIFIED,kind-worker5,taints=0
25.9788,Pod,MODIFIED,eval-sanitize-2-r1-024-mfnr5,phase=Pending node=kind-worker5
25.9795,Event,ADDED,eval-sanitize-2-r1-023-42sh8.18d420e0aa0d6da5,"reason=FailedScheduling count=None msg=0/6 nodes are available: 1 c_wall violated: 3 conflicting context pair(s) with node memory, 5 node(s) had untolerated taint(s). no new claims to deallocate, preemption: 0/6 nodes are available: 1 No preemption victims found for incoming pod, 5 Preemption is not helpful for scheduling."
25.981,Node,MODIFIED,kind-worker5,taints=0
25.9834,Event,ADDED,eval-sanitize-2-r1-025-7m5rb.18d420e0aa4b4836,"reason=FailedScheduling count=None msg=0/6 nodes are available: 1 c_wall violated: 3 conflicting context pair(s) with node memory, 5 node(s) had untolerated taint(s). no new claims to deallocate, preemption: 0/6 nodes are available: 1 No preemption victims found for incoming pod, 5 Preemption is not helpful for scheduling."
25.9866,Event,MODIFIED,eval-sanitize-2-r1-023-42sh8.18d420e0aa0d6da5,"reason=FailedScheduling count=None msg=0/6 nodes are available: 1 c_wall violated: 3 conflicting context pair(s) with node memory, 5 node(s) had untolerated taint(s). no new claims to deallocate, preemption: 0/6 nodes are available: 1 No preemption victims found for incoming pod, 5 Preemption is not helpful for scheduling."
26.0065,TaskRequest,ADDED,eval-sanitize-2-r1-026,phase=None job=None
26.0098,TaskRequest,MODIFIED,eval-sanitize-2-r1-026,phase=Pending job=None
26.0258,Job,ADDED,eval-sanitize-2-r1-026,
26.0331,Pod,ADDED,eval-sanitize-2-r1-026-88m8g,phase=Pending node=None
26.0333,TaskRequest,MODIFIED,eval-sanitize-2-r1-026,phase=Scheduled job=None
26.0357,Job,MODIFIED,eval-sanitize-2-r1-026,
26.0379,Event,ADDED,eval-sanitize-2-r1-026.18d420e0adbb54ec,reason=SuccessfulCreate count=1 msg=Created pod: eval-sanitize-2-r1-026-88m8g
26.0392,TaskRequest,MODIFIED,eval-sanitize-2-r1-026,phase=Scheduled job=None
26.0447,Event,MODIFIED,eval-sanitize-2-r1-025-7m5rb.18d420e0aa4b4836,"reason=FailedScheduling count=None msg=0/6 nodes are available: 1 c_wall violated: 3 conflicting context pair(s) with node memory, 5 node(s) had untolerated taint(s). no new claims to deallocate, preemption: 0/6 nodes are available: 1 No preemption victims found for incoming pod, 5 Preemption is not helpful for scheduling."
26.0486,Pod,MODIFIED,eval-sanitize-2-r1-026-88m8g,phase=Pending node=None
26.0498,Event,ADDED,eval-sanitize-2-r1-026-88m8g.18d420e0ae60612a,"reason=FailedScheduling count=None msg=0/6 nodes are available: 1 c_wall violated: 1 conflicting context pair(s) with node memory, 5 node(s) had untolerated taint(s). no new claims to deallocate, preemption: 0/6 nodes are available: 1 No preemption victims found for incoming pod, 5 Preemption is not helpful for scheduling."
26.0525,Job,MODIFIED,eval-sanitize-2-r1-025,
26.0626,Job,MODIFIED,eval-sanitize-2-r1-025,
26.063,Event,ADDED,eval-sanitize-2-r1-026-88m8g.18d420e0af3bd3de,"reason=FailedScheduling count=None msg=0/6 nodes are available: 1 c_wall violated: 1 conflicting context pair(s) with node memory, 5 node(s) had untolerated taint(s). no new claims to deallocate, preemption: 0/6 nodes are available: 1 No preemption victims found for incoming pod, 5 Preemption is not helpful for scheduling."
26.1049,Node,MODIFIED,kind-worker5,taints=0
26.148,Event,MODIFIED,eval-sanitize-2-r1-026-88m8g.18d420e0af3bd3de,"reason=FailedScheduling count=None msg=0/6 nodes are available: 1 c_wall violated: 1 conflicting context pair(s) with node memory, 5 node(s) had untolerated taint(s). no new claims to deallocate, preemption: 0/6 nodes are available: 1 No preemption victims found for incoming pod, 5 Preemption is not helpful for scheduling."
26.2525,Node,MODIFIED,kind-worker5,taints=0
26.2668,Node,MODIFIED,kind-worker5,taints=0
26.3012,Job,MODIFIED,eval-sanitize-2-r1-009,
26.3048,Job,MODIFIED,eval-sanitize-2-r1-005,
26.3118,Pod,MODIFIED,eval-sanitize-2-r1-009-rqs9m,phase=Succeeded node=kind-worker5
26.3159,Job,MODIFIED,eval-sanitize-2-r1-009,
26.3186,Job,MODIFIED,eval-sanitize-2-r1-007,
26.3213,Pod,MODIFIED,eval-sanitize-2-r1-005-rng6l,phase=Succeeded node=kind-worker5
26.3229,Job,MODIFIED,eval-sanitize-2-r1-005,
26.3249,Event,ADDED,eval-sanitize-2-r1-020-jm8sr.18d420e0beb0cea4,"reason=Pulled count=1 msg=Container image ""busybox:musl"" already present on machine"
26.3296,Pod,MODIFIED,eval-sanitize-2-r1-007-z7mxg,phase=Succeeded node=kind-worker5
26.3312,Job,MODIFIED,eval-sanitize-2-r1-007,
26.3445,Event,ADDED,eval-sanitize-2-r1-020-jm8sr.18d420e0c012a63c,reason=Created count=1 msg=Created container: task
26.396,Event,ADDED,eval-sanitize-2-r1-020-jm8sr.18d420e0c2fc443a,reason=Started count=1 msg=Started container task
26.4012,Event,ADDED,eval-sanitize-2-r1-024-mfnr5.18d420e0c3048391,"reason=Pulled count=1 msg=Container image ""busybox:musl"" already present on machine"
26.412,Event,ADDED,eval-sanitize-2-r1-024-mfnr5.18d420e0c420b847,reason=Created count=1 msg=Created container: task
26.4288,Event,ADDED,eval-sanitize-2-r1-019-9fbj8.18d420e0c511cfe9,"reason=Pulled count=1 msg=Container image ""busybox:musl"" already present on machine"
26.4329,Event,ADDED,eval-sanitize-2-r1-021-xwkkx.18d420e0c52d9507,"reason=Pulled count=1 msg=Container image ""busybox:musl"" already present on machine"
26.4376,Event,ADDED,eval-sanitize-2-r1-022-44zg5.18d420e0c54fa306,"reason=Pulled count=1 msg=Container image ""busybox:musl"" already present on machine"
26.4497,Event,ADDED,eval-sanitize-2-r1-024-mfnr5.18d420e0c63aacc3,reason=Started count=1 msg=Started container task
26.4585,Event,ADDED,eval-sanitize-2-r1-019-9fbj8.18d420e0c6e4281d,reason=Created count=1 msg=Created container: task
26.4642,Event,ADDED,eval-sanitize-2-r1-021-xwkkx.18d420e0c7387034,reason=Created count=1 msg=Created container: task
26.4682,Event,ADDED,eval-sanitize-2-r1-022-44zg5.18d420e0c77b5a5e,reason=Created count=1 msg=Created container: task
26.5325,Event,ADDED,eval-sanitize-2-r1-019-9fbj8.18d420e0cb1bf3b2,reason=Started count=1 msg=Started container task
26.5363,Event,ADDED,eval-sanitize-2-r1-021-xwkkx.18d420e0cb6875c3,reason=Started count=1 msg=Started container task
26.5404,Event,ADDED,eval-sanitize-2-r1-022-44zg5.18d420e0cb6ec513,reason=Started count=1 msg=Started container task
26.6259,Pod,MODIFIED,eval-sanitize-2-r1-012-nfhdz,phase=Running node=kind-worker2
26.6325,Pod,MODIFIED,eval-sanitize-2-r1-013-w4d7s,phase=Running node=kind-worker2
26.6382,Pod,MODIFIED,eval-sanitize-2-r1-011-mbg8c,phase=Running node=kind-worker2
26.6446,Pod,MODIFIED,eval-sanitize-2-r1-015-2w6kl,phase=Running node=kind-worker2
26.7057,Job,MODIFIED,eval-sanitize-2-r1-006,
26.709,Job,MODIFIED,eval-sanitize-2-r1-010,
26.7156,Pod,MODIFIED,eval-sanitize-2-r1-006-srhbl,phase=Succeeded node=kind-worker3
26.7167,Job,MODIFIED,eval-sanitize-2-r1-006,
26.7183,Job,MODIFIED,eval-sanitize-2-r1-008,
26.7199,Pod,MODIFIED,eval-sanitize-2-r1-010-cmhnq,phase=Succeeded node=kind-worker3
26.7209,Job,MODIFIED,eval-sanitize-2-r1-010,
26.7228,Job,MODIFIED,eval-sanitize-2-r1-014,
26.7256,Pod,MODIFIED,eval-sanitize-2-r1-008-24xc5,phase=Succeeded node=kind-worker3
26.7274,Job,MODIFIED,eval-sanitize-2-r1-008,
26.7316,Pod,MODIFIED,eval-sanitize-2-r1-014-fphhf,phase=Succeeded node=kind-worker3
26.733,Job,MODIFIED,eval-sanitize-2-r1-014,
26.744,Node,MODIFIED,kind-worker3,taints=1
26.7584,Node,MODIFIED,kind-worker3,taints=0
26.7653,Pod,MODIFIED,eval-sanitize-2-r1-025-7m5rb,phase=Pending node=kind-worker3
26.7674,Node,MODIFIED,kind-worker3,taints=0
26.7762,Pod,MODIFIED,eval-sanitize-2-r1-025-7m5rb,phase=Pending node=kind-worker3
26.778,Node,MODIFIED,kind-worker3,taints=0
26.8447,Event,ADDED,eval-sanitize-2-r1-025-7m5rb.18d420e0ddd13756,reason=Scheduled count=None msg=Successfully assigned compute/eval-sanitize-2-r1-025-7m5rb to kind-worker3
26.8502,Pod,MODIFIED,eval-sanitize-2-r1-026-88m8g,phase=Pending node=None
26.8534,Node,MODIFIED,kind-worker3,taints=0
26.8615,Pod,MODIFIED,eval-sanitize-2-r1-023-42sh8,phase=Pending node=None
26.8651,Node,MODIFIED,kind-worker3,taints=0
26.8705,Event,ADDED,eval-sanitize-2-r1-026-88m8g.18d420e0df729478,"reason=FailedScheduling count=None msg=0/6 nodes are available: 2 c_wall violated: 1 conflicting context pair(s) with node memory, 4 node(s) had untolerated taint(s). no new claims to deallocate, preemption: 0/6 nodes are available: 2 No preemption victims found for incoming pod, 4 Preemption is not helpful for scheduling."
26.949,Event,ADDED,eval-sanitize-2-r1-023-42sh8.18d420e0e4057683,"reason=FailedScheduling count=None msg=0/6 nodes are available: 1 c_wall violated: 1 conflicting context pair(s) with node memory, 1 c_wall violated: 3 conflicting context pair(s) with node memory, 4 node(s) had untolerated taint(s). no new claims to deallocate, preemption: 0/6 nodes are available: 2 No preemption victims found for incoming pod, 4 Preemption is not helpful for scheduling."
26.9536,Event,MODIFIED,eval-sanitize-2-r1-026-88m8g.18d420e0df729478,"reason=FailedScheduling count=None msg=0/6 nodes are available: 2 c_wall violated: 1 conflicting context pair(s) with node memory, 4 node(s) had untolerated taint(s). no new claims to deallocate, preemption: 0/6 nodes are available: 2 No preemption victims found for incoming pod, 4 Preemption is not helpful for scheduling."
27.0071,TaskRequest,ADDED,eval-sanitize-2-r1-027,phase=None job=None
27.0131,TaskRequest,MODIFIED,eval-sanitize-2-r1-027,phase=Pending job=None
27.028,Job,ADDED,eval-sanitize-2-r1-027,
27.0346,Pod,ADDED,eval-sanitize-2-r1-027-622v9,phase=Pending node=None
27.036,TaskRequest,MODIFIED,eval-sanitize-2-r1-027,phase=Scheduled job=None
27.0368,Job,MODIFIED,eval-sanitize-2-r1-027,
27.0398,Job,MODIFIED,eval-sanitize-2-r1-026,
27.0415,Event,ADDED,eval-sanitize-2-r1-027.18d420e0e96a2f18,reason=SuccessfulCreate count=1 msg=Created pod: eval-sanitize-2-r1-027-622v9
27.0439,TaskRequest,MODIFIED,eval-sanitize-2-r1-027,phase=Scheduled job=None
27.0484,Job,MODIFIED,eval-sanitize-2-r1-026,
27.055,Pod,MODIFIED,eval-sanitize-2-r1-027-622v9,phase=Pending node=kind-worker3
27.0582,Event,ADDED,eval-sanitize-2-r1-027-622v9.18d420e0ea9cd894,reason=Scheduled count=None msg=Successfully assigned compute/eval-sanitize-2-r1-027-622v9 to kind-worker3
27.0645,Node,MODIFIED,kind-worker3,taints=0
27.0671,Pod,MODIFIED,eval-sanitize-2-r1-027-622v9,phase=Pending node=kind-worker3
27.0675,Event,MODIFIED,eval-sanitize-2-r1-023-42sh8.18d420e0e4057683,"reason=FailedScheduling count=None msg=0/6 nodes are available: 1 c_wall violated: 1 conflicting context pair(s) with node memory, 1 c_wall violated: 3 conflicting context pair(s) with node memory, 4 node(s) had untolerated taint(s). no new claims to deallocate, preemption: 0/6 nodes are available: 2 No preemption victims found for incoming pod, 4 Preemption is not helpful for scheduling."
27.0684,Pod,MODIFIED,eval-sanitize-2-r1-023-42sh8,phase=Pending node=None
27.0757,Node,MODIFIED,kind-worker3,taints=0
27.1456,Event,ADDED,eval-sanitize-2-r1-023-42sh8.18d420e0efc4d363,"reason=FailedScheduling count=None msg=0/6 nodes are available: 1 c_wall violated: 2 conflicting context pair(s) with node memory, 1 c_wall violated: 3 conflicting context pair(s) with node memory, 4 node(s) had untolerated taint(s). no new claims to deallocate, preemption: 0/6 nodes are available: 2 No preemption victims found for incoming pod, 4 Preemption is not helpful for scheduling."
27.1787,Event,MODIFIED,eval-sanitize-2-r1-023-42sh8.18d420e0efc4d363,"reason=FailedScheduling count=None msg=0/6 nodes are available: 1 c_wall violated: 2 conflicting context pair(s) with node memory, 1 c_wall violated: 3 conflicting context pair(s) with node memory, 4 node(s) had untolerated taint(s). no new claims to deallocate, preemption: 0/6 nodes are available: 2 No preemption victims found for incoming pod, 4 Preemption is not helpful for scheduling."
27.1954,Event,ADDED,eval-sanitize-2-r1-025-7m5rb.18d420e0f2c683a4,"reason=Pulled count=1 msg=Container image ""busybox:musl"" already present on machine"
27.2127,Event,ADDED,eval-sanitize-2-r1-025-7m5rb.18d420e0f3d36307,reason=Created count=1 msg=Created container: task
27.2846,Event,ADDED,eval-sanitize-2-r1-025-7m5rb.18d420e0f8164f2d,reason=Started count=1 msg=Started container task
27.3009,Pod,MODIFIED,eval-sanitize-2-r1-021-xwkkx,phase=Running node=kind-worker5
27.3045,Job,MODIFIED,eval-sanitize-2-r1-009,
27.3081,Pod,MODIFIED,eval-sanitize-2-r1-019-9fbj8,phase=Running node=kind-worker5
27.3095,Job,MODIFIED,eval-sanitize-2-r1-009,
27.3114,Job,MODIFIED,eval-sanitize-2-r1-005,
27.3164,Pod,MODIFIED,eval-sanitize-2-r1-020-jm8sr,phase=Running node=kind-worker5
27.3168,Event,ADDED,eval-sanitize-2-r1-009.18d420e0f9cf3029,reason=Completed count=1 msg=Job completed
27.3179,Job,MODIFIED,eval-sanitize-2-r1-005,
27.3213,Event,ADDED,eval-sanitize-2-r1-005.18d420e0fa388864,reason=Completed count=1 msg=Job completed
27.3257,Pod,MODIFIED,eval-sanitize-2-r1-024-mfnr5,phase=Running node=kind-worker5
27.3265,Job,MODIFIED,eval-sanitize-2-r1-007,
27.3276,Job,MODIFIED,eval-sanitize-2-r1-009,
27.3289,Job,MODIFIED,eval-sanitize-2-r1-007,
27.332,Pod,MODIFIED,eval-sanitize-2-r1-022-44zg5,phase=Running node=kind-worker5
27.3327,TaskRequest,MODIFIED,eval-sanitize-2-r1-009,phase=Complete job=None
27.3337,Job,MODIFIED,eval-sanitize-2-r1-005,
27.334,Event,ADDED,eval-sanitize-2-r1-007.18d420e0fafaf47f,reason=Completed count=1 msg=Job completed
27.3368,Job,MODIFIED,eval-sanitize-2-r1-007,
27.3388,TaskRequest,MODIFIED,eval-sanitize-2-r1-005,phase=Complete job=None
27.3443,Job,MODIFIED,eval-sanitize-2-r1-009,
27.3444,TaskRequest,MODIFIED,eval-sanitize-2-r1-007,phase=Complete job=None
27.3478,Job,MODIFIED,eval-sanitize-2-r1-005,
27.3646,Job,MODIFIED,eval-sanitize-2-r1-007,
27.3971,Pod,MODIFIED,eval-sanitize-2-r1-016-kq9wb,phase=Running node=kind-worker
27.4814,Event,ADDED,eval-sanitize-2-r1-027-622v9.18d420e103c9033d,"reason=Pulled count=1 msg=Container image ""busybox:musl"" already present on machine"
27.4982,Event,ADDED,eval-sanitize-2-r1-027-622v9.18d420e104d8b530,reason=Created count=1 msg=Created container: task
27.5326,Event,ADDED,eval-sanitize-2-r1-027-622v9.18d420e106e20ecc,reason=Started count=1 msg=Started container task
27.6321,Job,MODIFIED,eval-sanitize-2-r1-012,
27.6371,Job,MODIFIED,eval-sanitize-2-r1-013,
27.6422,Job,MODIFIED,eval-sanitize-2-r1-012,
27.6443,Job,MODIFIED,eval-sanitize-2-r1-011,
27.6468,Job,MODIFIED,eval-sanitize-2-r1-013,
27.6488,Job,MODIFIED,eval-sanitize-2-r1-015,
27.6538,Job,MODIFIED,eval-sanitize-2-r1-011,
27.6567,Job,MODIFIED,eval-sanitize-2-r1-015,
27.7095,Pod,MODIFIED,eval-sanitize-2-r1-027-622v9,phase=Running node=kind-worker3
27.7113,Job,MODIFIED,eval-sanitize-2-r1-006,
27.7167,Job,MODIFIED,eval-sanitize-2-r1-010,
27.7188,Job,MODIFIED,eval-sanitize-2-r1-006,
27.7203,Pod,MODIFIED,eval-sanitize-2-r1-025-7m5rb,phase=Running node=kind-worker3
27.7218,Job,MODIFIED,eval-sanitize-2-r1-010,
27.724,Job,MODIFIED,eval-sanitize-2-r1-008,
27.7253,Event,ADDED,eval-sanitize-2-r1-006.18d420e112368f76,reason=Completed count=1 msg=Job completed
27.7298,Job,MODIFIED,eval-sanitize-2-r1-014,
27.7339,Job,MODIFIED,eval-sanitize-2-r1-008,
27.7344,Event,ADDED,eval-sanitize-2-r1-010.18d420e11263a5dc,reason=Completed count=1 msg=Job completed
27.7356,Job,MODIFIED,eval-sanitize-2-r1-006,
27.7366,Job,MODIFIED,eval-sanitize-2-r1-010,
27.7376,Job,MODIFIED,eval-sanitize-2-r1-014,
27.738,Event,ADDED,eval-sanitize-2-r1-008.18d420e113151088,reason=Completed count=1 msg=Job completed
27.7393,TaskRequest,MODIFIED,eval-sanitize-2-r1-006,phase=Complete job=None
27.7422,Job,MODIFIED,eval-sanitize-2-r1-008,
27.7452,Event,ADDED,eval-sanitize-2-r1-014.18d420e113216483,reason=Completed count=1 msg=Job completed
27.7487,Job,MODIFIED,eval-sanitize-2-r1-014,
27.7489,TaskRequest,MODIFIED,eval-sanitize-2-r1-010,phase=Complete job=None
27.7667,Job,MODIFIED,eval-sanitize-2-r1-006,
27.7683,Job,MODIFIED,eval-sanitize-2-r1-010,
27.7684,TaskRequest,MODIFIED,eval-sanitize-2-r1-008,phase=Complete job=None
27.7739,TaskRequest,MODIFIED,eval-sanitize-2-r1-014,phase=Complete job=None
27.7826,Pod,MODIFIED,eval-sanitize-2-r1-011-mbg8c,phase=Succeeded node=kind-worker2
27.8126,Pod,MODIFIED,eval-sanitize-2-r1-013-w4d7s,phase=Succeeded node=kind-worker2
27.8194,Pod,MODIFIED,eval-sanitize-2-r1-015-2w6kl,phase=Succeeded node=kind-worker2
27.8256,Pod,MODIFIED,eval-sanitize-2-r1-012-nfhdz,phase=Succeeded node=kind-worker2
27.832,Job,MODIFIED,eval-sanitize-2-r1-008,
27.8356,Job,MODIFIED,eval-sanitize-2-r1-014,
27.8786,Node,MODIFIED,kind-worker5,taints=1
27.8889,Pod,MODIFIED,eval-sanitize-2-r1-023-42sh8,phase=Pending node=None
27.8914,Node,MODIFIED,kind-worker5,taints=1
27.8954,Pod,MODIFIED,eval-sanitize-2-r1-026-88m8g,phase=Pending node=None
27.9772,Event,ADDED,eval-sanitize-2-r1-023-42sh8.18d420e1215e27f0,"reason=FailedScheduling count=None msg=0/6 nodes are available: 1 c_wall violated: 2 conflicting context pair(s) with node memory, 5 node(s) had untolerated taint(s). no new claims to deallocate, preemption: 0/6 nodes are available: 1 No preemption victims found for incoming pod, 5 Preemption is not helpful for scheduling."
27.9795,Event,ADDED,eval-sanitize-2-r1-026-88m8g.18d420e121978414,"reason=FailedScheduling count=None msg=0/6 nodes are available: 1 c_wall violated: 1 conflicting context pair(s) with node memory, 5 node(s) had untolerated taint(s). no new claims to deallocate, preemption: 0/6 nodes are available: 1 No preemption victims found for incoming pod, 5 Preemption is not helpful for scheduling."
28.0065,TaskRequest,ADDED,eval-sanitize-2-r1-028,phase=None job=None
28.0109,TaskRequest,MODIFIED,eval-sanitize-2-r1-028,phase=Pending job=None
28.0244,Job,ADDED,eval-sanitize-2-r1-028,
28.0309,Pod,ADDED,eval-sanitize-2-r1-028-gjgkl,phase=Pending node=None
28.0323,TaskRequest,MODIFIED,eval-sanitize-2-r1-028,phase=Scheduled job=None
28.033,Job,MODIFIED,eval-sanitize-2-r1-028,
28.0351,Event,ADDED,eval-sanitize-2-r1-028.18d420e124d3153b,reason=SuccessfulCreate count=1 msg=Created pod: eval-sanitize-2-r1-028-gjgkl
28.0404,Pod,MODIFIED,eval-sanitize-2-r1-028-gjgkl,phase=Pending node=None
28.0419,Event,ADDED,eval-sanitize-2-r1-028-gjgkl.18d420e1250e1eb0,"reason=FailedScheduling count=None msg=0/6 nodes are available: 1 c_wall violated: 1 conflicting context pair(s) with node memory, 5 node(s) had untolerated taint(s). no new claims to deallocate, preemption: 0/6 nodes are available: 1 No preemption victims found for incoming pod, 5 Preemption is not helpful for scheduling."
28.0421,TaskRequest,MODIFIED,eval-sanitize-2-r1-028,phase=Scheduled job=None
28.0429,Job,MODIFIED,eval-sanitize-2-r1-027,
28.0484,Event,ADDED,eval-sanitize-2-r1-028-gjgkl.18d420e125a400b5,"reason=FailedScheduling count=None msg=0/6 nodes are available: 1 c_wall violated: 1 conflicting context pair(s) with node memory, 5 node(s) had untolerated taint(s). no new claims to deallocate, preemption: 0/6 nodes are available: 1 No preemption victims found for incoming pod, 5 Preemption is not helpful for scheduling."
28.0525,Job,MODIFIED,eval-sanitize-2-r1-027,
28.2923,Pod,MODIFIED,eval-sanitize-2-r1-017-6455d,phase=Running node=kind-worker4
28.3023,Event,MODIFIED,eval-sanitize-2-r1-023-42sh8.18d420e1215e27f0,"reason=FailedScheduling count=None msg=0/6 nodes are available: 1 c_wall violated: 2 conflicting context pair(s) with node memory, 5 node(s) had untolerated taint(s). no new claims to deallocate, preemption: 0/6 nodes are available: 1 No preemption victims found for incoming pod, 5 Preemption is not helpful for scheduling."
28.3063,Job,MODIFIED,eval-sanitize-2-r1-021,
28.3078,Event,MODIFIED,eval-sanitize-2-r1-026-88m8g.18d420e121978414,"reason=FailedScheduling count=None msg=0/6 nodes are available: 1 c_wall violated: 1 conflicting context pair(s) with node memory, 5 node(s) had untolerated taint(s). no new claims to deallocate, preemption: 0/6 nodes are available: 1 No preemption victims found for incoming pod, 5 Preemption is not helpful for scheduling."
28.308,Event,MODIFIED,eval-sanitize-2-r1-028-gjgkl.18d420e125a400b5,"reason=FailedScheduling count=None msg=0/6 nodes are available: 1 c_wall violated: 1 conflicting context pair(s) with node memory, 5 node(s) had untolerated taint(s). no new claims to deallocate, preemption: 0/6 nodes are available: 1 No preemption victims found for incoming pod, 5 Preemption is not helpful for scheduling."
28.3135,Job,MODIFIED,eval-sanitize-2-r1-019,
28.3161,Job,MODIFIED,eval-sanitize-2-r1-021,
28.3183,Job,MODIFIED,eval-sanitize-2-r1-020,
28.3212,Job,MODIFIED,eval-sanitize-2-r1-019,
28.3261,Job,MODIFIED,eval-sanitize-2-r1-020,
28.3292,Job,MODIFIED,eval-sanitize-2-r1-024,
28.3353,Job,MODIFIED,eval-sanitize-2-r1-022,
28.3374,Job,MODIFIED,eval-sanitize-2-r1-024,
28.3431,Job,MODIFIED,eval-sanitize-2-r1-022,
28.347,Node,MODIFIED,kind-worker2,taints=1
28.3604,Node,MODIFIED,kind-worker2,taints=0
28.3676,Pod,MODIFIED,eval-sanitize-2-r1-023-42sh8,phase=Pending node=kind-worker2
28.37,Node,MODIFIED,kind-worker2,taints=0
28.3712,Event,ADDED,eval-sanitize-2-r1-023-42sh8.18d420e138dffad3,reason=Scheduled count=None msg=Successfully assigned compute/eval-sanitize-2-r1-023-42sh8 to kind-worker2
28.3781,Pod,MODIFIED,eval-sanitize-2-r1-023-42sh8,phase=Pending node=kind-worker2
28.3804,Node,MODIFIED,kind-worker2,taints=0
28.3825,Pod,MODIFIED,eval-sanitize-2-r1-026-88m8g,phase=Pending node=kind-worker2
28.3856,Event,ADDED,eval-sanitize-2-r1-026-88m8g.18d420e139c1d8d7,reason=Scheduled count=None msg=Successfully assigned compute/eval-sanitize-2-r1-026-88m8g to kind-worker2
28.3922,Node,MODIFIED,kind-worker2,taints=0
28.3944,Pod,MODIFIED,eval-sanitize-2-r1-026-88m8g,phase=Pending node=kind-worker2
28.4014,Job,MODIFIED,eval-sanitize-2-r1-016,
28.412,Job,MODIFIED,eval-sanitize-2-r1-016,
28.446,Pod,MODIFIED,eval-sanitize-2-r1-028-gjgkl,phase=Pending node=kind-worker2
28.4501,Node,MODIFIED,kind-worker2,taints=0
28.4512,Event,ADDED,eval-sanitize-2-r1-028-gjgkl.18d420e13d88d5d8,reason=Scheduled count=None msg=Successfully assigned compute/eval-sanitize-2-r1-028-gjgkl to kind-worker2
28.4571,Pod,MODIFIED,eval-sanitize-2-r1-028-gjgkl,phase=Pending node=kind-worker2
28.4598,Node,MODIFIED,kind-worker2,taints=0
28.47,Node,MODIFIED,kind-worker2,taints=0
28.4832,Pod,MODIFIED,eval-sanitize-2-r1-016-kq9wb,phase=Succeeded node=kind-worker
28.5402,Node,MODIFIED,kind-worker2,taints=0
28.5492,Node,MODIFIED,kind-worker2,taints=0
28.6367,Job,MODIFIED,eval-sanitize-2-r1-012,
28.6423,Job,MODIFIED,eval-sanitize-2-r1-013,
28.6451,Pod,MODIFIED,eval-sanitize-2-r1-012-nfhdz,phase=Succeeded node=kind-worker2
28.6464,Job,MODIFIED,eval-sanitize-2-r1-012,
28.6493,Job,MODIFIED,eval-sanitize-2-r1-011,
28.6525,Pod,MODIFIED,eval-sanitize-2-r1-013-w4d7s,phase=Succeeded node=kind-worker2
28.655,Job,MODIFIED,eval-sanitize-2-r1-013,
28.656,Job,MODIFIED,eval-sanitize-2-r1-015,
28.6594,Job,MODIFIED,eval-sanitize-2-r1-011,
28.6608,Pod,MODIFIED,eval-sanitize-2-r1-011-mbg8c,phase=Succeeded node=kind-worker2
28.6626,Pod,MODIFIED,eval-sanitize-2-r1-015-2w6kl,phase=Succeeded node=kind-worker2
28.6645,Job,MODIFIED,eval-sanitize-2-r1-015,
28.7265,Job,MODIFIED,eval-sanitize-2-r1-025,
28.7367,Job,MODIFIED,eval-sanitize-2-r1-025,
28.7806,Node,MODIFIED,kind-worker3,taints=1
28.7937,Node,MODIFIED,kind-worker3,taints=1
28.7985,Event,ADDED,eval-sanitize-2-r1-023-42sh8.18d420e1524b70a6,"reason=Pulled count=1 msg=Container image ""busybox:musl"" already present on machine"
28.8034,Event,ADDED,eval-sanitize-2-r1-026-88m8g.18d420e152a19bc2,"reason=Pulled count=1 msg=Container image ""busybox:musl"" already present on machine"
28.8216,Event,ADDED,eval-sanitize-2-r1-023-42sh8.18d420e153b6a70c,reason=Created count=1 msg=Created container: task
28.8302,Event,ADDED,eval-sanitize-2-r1-026-88m8g.18d420e154184b26,reason=Created count=1 msg=Created container: task
28.8393,Event,ADDED,eval-sanitize-2-r1-028-gjgkl.18d420e154beea21,"reason=Pulled count=1 msg=Container image ""busybox:musl"" already present on machine"
28.8611,Event,ADDED,eval-sanitize-2-r1-028-gjgkl.18d420e155ffa74c,reason=Created count=1 msg=Created container: task
28.865,Event,ADDED,eval-sanitize-2-r1-023-42sh8.18d420e15603cc70,reason=Started count=1 msg=Started container task
28.8702,Event,ADDED,eval-sanitize-2-r1-026-88m8g.18d420e1565df69c,reason=Started count=1 msg=Started container task
28.9118,Event,ADDED,eval-sanitize-2-r1-028-gjgkl.18d420e15917e447,reason=Started count=1 msg=Started container task
29.0193,TaskRequest,ADDED,eval-sanitize-2-r1-029,phase=None job=None
29.0231,TaskRequest,MODIFIED,eval-sanitize-2-r1-029,phase=Pending job=None
29.0366,Job,MODIFIED,eval-sanitize-2-r1-028,
29.0372,Job,ADDED,eval-sanitize-2-r1-029,
29.0446,Pod,ADDED,eval-sanitize-2-r1-029-vwzxl,phase=Pending node=None
29.0451,TaskRequest,MODIFIED,eval-sanitize-2-r1-029,phase=Scheduled job=None
29.0458,Job,MODIFIED,eval-sanitize-2-r1-029,
29.0488,Event,ADDED,eval-sanitize-2-r1-029.18d420e1612b847e,reason=SuccessfulCreate count=1 msg=Created pod: eval-sanitize-2-r1-029-vwzxl
29.0531,Pod,MODIFIED,eval-sanitize-2-r1-029-vwzxl,phase=Pending node=None
29.0532,TaskRequest,MODIFIED,eval-sanitize-2-r1-029,phase=Scheduled job=None
29.0535,Event,ADDED,eval-sanitize-2-r1-029-vwzxl.18d420e1617c19b4,"reason=FailedScheduling count=None msg=0/6 nodes are available: 1 c_wall violated: 3 conflicting context pair(s) with node memory, 5 node(s) had untolerated taint(s). no new claims to deallocate, preemption: 0/6 nodes are available: 1 No preemption victims found for incoming pod, 5 Preemption is not helpful for scheduling."
29.0555,Job,MODIFIED,eval-sanitize-2-r1-028,
29.0602,Event,ADDED,eval-sanitize-2-r1-029-vwzxl.18d420e161f9251b,"reason=FailedScheduling count=None msg=0/6 nodes are available: 1 c_wall violated: 3 conflicting context pair(s) with node memory, 5 node(s) had untolerated taint(s). no new claims to deallocate, preemption: 0/6 nodes are available: 1 No preemption victims found for incoming pod, 5 Preemption is not helpful for scheduling."
29.297,Job,MODIFIED,eval-sanitize-2-r1-017,
29.3065,Job,MODIFIED,eval-sanitize-2-r1-017,
29.4032,Pod,MODIFIED,eval-sanitize-2-r1-018-tgv4l,phase=Running node=kind-worker
29.4072,Job,MODIFIED,eval-sanitize-2-r1-016,
29.411,Event,MODIFIED,eval-sanitize-2-r1-029-vwzxl.18d420e161f9251b,"reason=FailedScheduling count=None msg=0/6 nodes are available: 1 c_wall violated: 3 conflicting context pair(s) with node memory, 5 node(s) had untolerated taint(s). no new claims to deallocate, preemption: 0/6 nodes are available: 1 No preemption victims found for incoming pod, 5 Preemption is not helpful for scheduling."
29.4149,Pod,MODIFIED,eval-sanitize-2-r1-017-6455d,phase=Succeeded node=kind-worker4
29.4165,Job,MODIFIED,eval-sanitize-2-r1-016,
29.4181,Pod,MODIFIED,eval-sanitize-2-r1-016-kq9wb,phase=Succeeded node=kind-worker
29.6412,Pod,MODIFIED,eval-sanitize-2-r1-026-88m8g,phase=Running node=kind-worker2
29.6423,Job,MODIFIED,eval-sanitize-2-r1-012,
29.6468,Job,MODIFIED,eval-sanitize-2-r1-012,
29.6495,Job,MODIFIED,eval-sanitize-2-r1-013,
29.6516,Pod,MODIFIED,eval-sanitize-2-r1-028-gjgkl,phase=Running node=kind-worker2
29.6521,Event,ADDED,eval-sanitize-2-r1-012.18d420e185227399,reason=Completed count=1 msg=Job completed
29.6541,Job,MODIFIED,eval-sanitize-2-r1-013,
29.6559,Job,MODIFIED,eval-sanitize-2-r1-011,
29.6584,Pod,MODIFIED,eval-sanitize-2-r1-023-42sh8,phase=Running node=kind-worker2
29.6591,Event,ADDED,eval-sanitize-2-r1-013.18d420e1858d349a,reason=Completed count=1 msg=Job completed
29.6623,Job,MODIFIED,eval-sanitize-2-r1-015,
29.6637,Job,MODIFIED,eval-sanitize-2-r1-012,
29.6646,Job,MODIFIED,eval-sanitize-2-r1-011,
29.6664,Job,MODIFIED,eval-sanitize-2-r1-015,
29.6679,Event,ADDED,eval-sanitize-2-r1-011.18d420e1860bca6f,reason=Completed count=1 msg=Job completed
29.6691,Job,MODIFIED,eval-sanitize-2-r1-013,
29.6709,TaskRequest,MODIFIED,eval-sanitize-2-r1-012,phase=Complete job=None
29.6717,Event,ADDED,eval-sanitize-2-r1-015.18d420e186505df5,reason=Completed count=1 msg=Job completed
29.6762,Job,MODIFIED,eval-sanitize-2-r1-011,
29.677,TaskRequest,MODIFIED,eval-sanitize-2-r1-013,phase=Complete job=None
29.678,Job,MODIFIED,eval-sanitize-2-r1-015,
29.68,Job,MODIFIED,eval-sanitize-2-r1-012,
29.6801,TaskRequest,MODIFIED,eval-sanitize-2-r1-011,phase=Complete job=None
29.7343,Job,MODIFIED,eval-sanitize-2-r1-013,
29.7357,Job,MODIFIED,eval-sanitize-2-r1-011,
29.7604,TaskRequest,MODIFIED,eval-sanitize-2-r1-015,phase=Complete job=None
29.7702,Job,MODIFIED,eval-sanitize-2-r1-015,
30.0066,TaskRequest,ADDED,eval-sanitize-2-r1-030,phase=None job=None
30.0101,TaskRequest,MODIFIED,eval-sanitize-2-r1-030,phase=Pending job=None
30.0287,Job,ADDED,eval-sanitize-2-r1-030,
30.0363,Pod,ADDED,eval-sanitize-2-r1-030-2q542,phase=Pending node=None
30.0364,TaskRequest,MODIFIED,eval-sanitize-2-r1-030,phase=Scheduled job=None
30.0389,Job,MODIFIED,eval-sanitize-2-r1-030,
30.0434,Event,ADDED,eval-sanitize-2-r1-030.18d420e19c5192fb,reason=SuccessfulCreate count=1 msg=Created pod: eval-sanitize-2-r1-030-2q542
30.0443,Job,MODIFIED,eval-sanitize-2-r1-028,
30.0445,TaskRequest,MODIFIED,eval-sanitize-2-r1-030,phase=Scheduled job=None
30.047,Pod,MODIFIED,eval-sanitize-2-r1-030-2q542,phase=Pending node=None
30.0488,Job,MODIFIED,eval-sanitize-2-r1-029,
30.0492,Event,ADDED,eval-sanitize-2-r1-030-2q542.18d420e19caae83a,"reason=FailedScheduling count=None msg=0/6 nodes are available: 1 c_wall violated: 3 conflicting context pair(s) with node memory, 5 node(s) had untolerated taint(s). no new claims to deallocate, preemption: 0/6 nodes are available: 1 No preemption victims found for incoming pod, 5 Preemption is not helpful for scheduling."
30.0551,Job,MODIFIED,eval-sanitize-2-r1-028,
30.0555,Event,ADDED,eval-sanitize-2-r1-030-2q542.18d420e19d3b7afd,"reason=FailedScheduling count=None msg=0/6 nodes are available: 1 c_wall violated: 3 conflicting context pair(s) with node memory, 5 node(s) had untolerated taint(s). no new claims to deallocate, preemption: 0/6 nodes are available: 1 No preemption victims found for incoming pod, 5 Preemption is not helpful for scheduling."
30.058,Job,MODIFIED,eval-sanitize-2-r1-029,
30.3022,Job,MODIFIED,eval-sanitize-2-r1-017,
30.3106,Pod,MODIFIED,eval-sanitize-2-r1-017-6455d,phase=Succeeded node=kind-worker4
30.3118,Job,MODIFIED,eval-sanitize-2-r1-017,
30.3801,Node,MODIFIED,kind-worker2,taints=1
30.3868,Pod,MODIFIED,eval-sanitize-2-r1-029-vwzxl,phase=Pending node=None
30.3913,Pod,MODIFIED,eval-sanitize-2-r1-030-2q542,phase=Pending node=None
30.3926,Event,MODIFIED,eval-sanitize-2-r1-030-2q542.18d420e19d3b7afd,"reason=FailedScheduling count=None msg=0/6 nodes are available: 1 c_wall violated: 3 conflicting context pair(s) with node memory, 5 node(s) had untolerated taint(s). no new claims to deallocate, preemption: 0/6 nodes are available: 1 No preemption victims found for incoming pod, 5 Preemption is not helpful for scheduling."
30.394,Node,MODIFIED,kind-worker2,taints=1
30.4082,Job,MODIFIED,eval-sanitize-2-r1-018,
30.4118,Job,MODIFIED,eval-sanitize-2-r1-016,
30.4161,Job,MODIFIED,eval-sanitize-2-r1-016,
30.4179,Job,MODIFIED,eval-sanitize-2-r1-018,
30.4219,Event,ADDED,eval-sanitize-2-r1-016.18d420e1b2faa31f,reason=Completed count=1 msg=Job completed
30.4279,Job,MODIFIED,eval-sanitize-2-r1-016,
30.4327,TaskRequest,MODIFIED,eval-sanitize-2-r1-016,phase=Complete job=None
30.4428,Job,MODIFIED,eval-sanitize-2-r1-016,
30.4954,Pod,MODIFIED,eval-sanitize-2-r1-018-tgv4l,phase=Succeeded node=kind-worker
30.6459,Job,MODIFIED,eval-sanitize-2-r1-026,
30.6545,Job,MODIFIED,eval-sanitize-2-r1-026,
30.6627,Job,MODIFIED,eval-sanitize-2-r1-023,
30.6732,Job,MODIFIED,eval-sanitize-2-r1-023,
31.0069,TaskRequest,ADDED,eval-sanitize-2-r1-031,phase=None job=None
31.0115,TaskRequest,MODIFIED,eval-sanitize-2-r1-031,phase=Pending job=None
31.0273,Job,ADDED,eval-sanitize-2-r1-031,
31.0315,TaskRequest,MODIFIED,eval-sanitize-2-r1-031,phase=Scheduled job=None
31.0364,Pod,ADDED,eval-sanitize-2-r1-031-rq4sb,phase=Pending node=None
31.0389,Job,MODIFIED,eval-sanitize-2-r1-031,
31.0411,Job,MODIFIED,eval-sanitize-2-r1-030,
31.0413,TaskRequest,MODIFIED,eval-sanitize-2-r1-031,phase=Scheduled job=None
31.0428,Event,ADDED,eval-sanitize-2-r1-031.18d420e1d7ef1d33,reason=SuccessfulCreate count=1 msg=Created pod: eval-sanitize-2-r1-031-rq4sb
31.043,Event,ADDED,eval-sanitize-2-r1-031-rq4sb.18d420e1d7fe2353,"reason=FailedScheduling count=None msg=0/6 nodes are available: 6 node(s) had untolerated taint(s). no new claims to deallocate, preemption: 0/6 nodes are available: 6 Preemption is not helpful for scheduling."
31.044,Pod,MODIFIED,eval-sanitize-2-r1-031-rq4sb,phase=Pending node=None
31.0521,Job,MODIFIED,eval-sanitize-2-r1-030,
31.1466,Node,MODIFIED,kind-worker,taints=1
31.16,Node,MODIFIED,kind-worker,taints=1
31.1688,Node,MODIFIED,kind-worker,taints=0
31.1747,Pod,MODIFIED,eval-sanitize-2-r1-029-vwzxl,phase=Pending node=kind-worker
31.1784,Pod,MODIFIED,eval-sanitize-2-r1-030-2q542,phase=Pending node=None
31.1801,Event,ADDED,eval-sanitize-2-r1-030-2q542.18d420e1e0146a5a,"reason=FailedScheduling count=None msg=0/6 nodes are available: 1 c_wall violated: 1 conflicting context pair(s) with node memory, 5 node(s) had untolerated taint(s). no new claims to deallocate, preemption: 0/6 nodes are available: 1 No preemption victims found for incoming pod, 5 Preemption is not helpful for scheduling."
31.1803,Event,ADDED,eval-sanitize-2-r1-029-vwzxl.18d420e1e02a10d0,reason=Scheduled count=None msg=Successfully assigned compute/eval-sanitize-2-r1-029-vwzxl to kind-worker
31.1839,Node,MODIFIED,kind-worker,taints=0
31.1885,Pod,MODIFIED,eval-sanitize-2-r1-029-vwzxl,phase=Pending node=kind-worker
31.1893,Pod,MODIFIED,eval-sanitize-2-r1-031-rq4sb,phase=Pending node=None
31.1897,Event,ADDED,eval-sanitize-2-r1-031-rq4sb.18d420e1e0ada46f,"reason=FailedScheduling count=None msg=0/6 nodes are available: 1 c_wall violated: 1 conflicting context pair(s) with node memory, 5 node(s) had untolerated taint(s). no new claims to deallocate, preemption: 0/6 nodes are available: 1 No preemption victims found for incoming pod, 5 Preemption is not helpful for scheduling."
31.1954,Event,ADDED,eval-sanitize-2-r1-030-2q542.18d420e1e1341680,"reason=FailedScheduling count=None msg=0/6 nodes are available: 1 c_wall violated: 1 conflicting context pair(s) with node memory, 5 node(s) had untolerated taint(s). no new claims to deallocate, preemption: 0/6 nodes are available: 1 No preemption victims found for incoming pod, 5 Preemption is not helpful for scheduling."
31.1997,Event,ADDED,eval-sanitize-2-r1-031-rq4sb.18d420e1e1692c41,"reason=FailedScheduling count=None msg=0/6 nodes are available: 1 c_wall violated: 1 conflicting context pair(s) with node memory, 5 node(s) had untolerated taint(s). no new claims to deallocate, preemption: 0/6 nodes are available: 1 No preemption victims found for incoming pod, 5 Preemption is not helpful for scheduling."
31.2044,Event,MODIFIED,eval-sanitize-2-r1-030-2q542.18d420e1e1341680,"reason=FailedScheduling count=None msg=0/6 nodes are available: 1 c_wall violated: 1 conflicting context pair(s) with node memory, 5 node(s) had untolerated taint(s). no new claims to deallocate, preemption: 0/6 nodes are available: 1 No preemption victims found for incoming pod, 5 Preemption is not helpful for scheduling."
31.2086,Node,MODIFIED,kind-worker,taints=0
31.2179,Event,MODIFIED,eval-sanitize-2-r1-031-rq4sb.18d420e1e1692c41,"reason=FailedScheduling count=None msg=0/6 nodes are available: 1 c_wall violated: 1 conflicting context pair(s) with node memory, 5 node(s) had untolerated taint(s). no new claims to deallocate, preemption: 0/6 nodes are available: 1 No preemption victims found for incoming pod, 5 Preemption is not helpful for scheduling."
31.2459,Node,MODIFIED,kind-worker,taints=0
31.3077,Job,MODIFIED,eval-sanitize-2-r1-017,
31.3127,Job,MODIFIED,eval-sanitize-2-r1-017,
31.3169,Event,ADDED,eval-sanitize-2-r1-017.18d420e1e86e0bfc,reason=Completed count=1 msg=Job completed
31.3231,Job,MODIFIED,eval-sanitize-2-r1-017,
31.3273,TaskRequest,MODIFIED,eval-sanitize-2-r1-017,phase=Complete job=None
31.3371,Job,MODIFIED,eval-sanitize-2-r1-017,
31.4148,Job,MODIFIED,eval-sanitize-2-r1-018,
31.4252,Pod,MODIFIED,eval-sanitize-2-r1-018-tgv4l,phase=Succeeded node=kind-worker
31.4263,Job,MODIFIED,eval-sanitize-2-r1-018,
31.5499,Node,MODIFIED,kind-worker4,taints=1
31.5627,Node,MODIFIED,kind-worker4,taints=1
31.5724,Node,MODIFIED,kind-worker4,taints=0
31.5776,Event,ADDED,eval-sanitize-2-r1-029-vwzxl.18d420e1f7ff1462,"reason=Pulled count=1 msg=Container image ""busybox:musl"" already present on machine"
31.581,Pod,MODIFIED,eval-sanitize-2-r1-031-rq4sb,phase=Pending node=kind-worker4
31.5878,Pod,MODIFIED,eval-sanitize-2-r1-030-2q542,phase=Pending node=kind-worker4
31.5883,Event,ADDED,eval-sanitize-2-r1-031-rq4sb.18d420e1f8692c71,reason=Scheduled count=None msg=Successfully assigned compute/eval-sanitize-2-r1-031-rq4sb to kind-worker4
31.5915,Node,MODIFIED,kind-worker4,taints=0
31.5933,Event,ADDED,eval-sanitize-2-r1-030-2q542.18d420e1f8cd9f4e,reason=Scheduled count=None msg=Successfully assigned compute/eval-sanitize-2-r1-030-2q542 to kind-worker4
31.5947,Pod,MODIFIED,eval-sanitize-2-r1-031-rq4sb,phase=Pending node=kind-worker4
31.6009,Pod,MODIFIED,eval-sanitize-2-r1-030-2q542,phase=Pending node=kind-worker4
31.6015,Event,ADDED,eval-sanitize-2-r1-029-vwzxl.18d420e1f96b3c65,reason=Created count=1 msg=Created container: task
31.6362,Event,ADDED,eval-sanitize-2-r1-029-vwzxl.18d420e1fb76345d,reason=Started count=1 msg=Started container task
31.6455,Node,MODIFIED,kind-worker4,taints=0
31.6559,Node,MODIFIED,kind-worker4,taints=0
32.0084,TaskRequest,ADDED,eval-sanitize-2-r1-032,phase=None job=None
32.0128,TaskRequest,MODIFIED,eval-sanitize-2-r1-032,phase=Pending job=None
32.0173,Event,ADDED,eval-sanitize-2-r1-031-rq4sb.18d420e211ff2921,"reason=Pulled count=1 msg=Container image ""busybox:musl"" already present on machine"
32.0221,Event,ADDED,eval-sanitize-2-r1-030-2q542.18d420e2121d357d,"reason=Pulled count=1 msg=Container image ""busybox:musl"" already present on machine"
32.0293,Job,ADDED,eval-sanitize-2-r1-032,
32.035,Pod,ADDED,eval-sanitize-2-r1-032-cjptq,phase=Pending node=None
32.0404,TaskRequest,MODIFIED,eval-sanitize-2-r1-032,phase=Scheduled job=None
32.0554,Event,ADDED,eval-sanitize-2-r1-032.18d420e2137c9720,reason=SuccessfulCreate count=1 msg=Created pod: eval-sanitize-2-r1-032-cjptq
32.0572,Job,MODIFIED,eval-sanitize-2-r1-032,
32.0581,Event,ADDED,eval-sanitize-2-r1-031-rq4sb.18d420e2139819a9,reason=Created count=1 msg=Created container: task
32.0586,Event,ADDED,eval-sanitize-2-r1-032-cjptq.18d420e213ef8a0e,"reason=FailedScheduling count=None msg=0/6 nodes are available: 2 c_wall violated: 1 conflicting context pair(s) with node memory, 4 node(s) had untolerated taint(s). no new claims to deallocate, preemption: 0/6 nodes are available: 2 No preemption victims found for incoming pod, 4 Preemption is not helpful for scheduling."
32.0588,TaskRequest,MODIFIED,eval-sanitize-2-r1-032,phase=Scheduled job=None
32.06,Job,MODIFIED,eval-sanitize-2-r1-031,
32.0614,Pod,MODIFIED,eval-sanitize-2-r1-032-cjptq,phase=Pending node=None
32.0628,Event,ADDED,eval-sanitize-2-r1-030-2q542.18d420e2144d126d,reason=Created count=1 msg=Created container: task
32.0722,Job,MODIFIED,eval-sanitize-2-r1-031,
32.0726,Event,ADDED,eval-sanitize-2-r1-032-cjptq.18d420e215780e94,"reason=FailedScheduling count=None msg=0/6 nodes are available: 2 c_wall violated: 1 conflicting context pair(s) with node memory, 4 node(s) had untolerated taint(s). no new claims to deallocate, preemption: 0/6 nodes are available: 2 No preemption victims found for incoming pod, 4 Preemption is not helpful for scheduling."
32.0867,Event,ADDED,eval-sanitize-2-r1-031-rq4sb.18d420e216582ac8,reason=Started count=1 msg=Started container task
32.0932,Event,ADDED,eval-sanitize-2-r1-030-2q542.18d420e216b96329,reason=Started count=1 msg=Started container task
32.3017,Pod,MODIFIED,eval-sanitize-2-r1-031-rq4sb,phase=Running node=kind-worker4
32.3083,Pod,MODIFIED,eval-sanitize-2-r1-030-2q542,phase=Running node=kind-worker4
32.3124,Event,MODIFIED,eval-sanitize-2-r1-032-cjptq.18d420e215780e94,"reason=FailedScheduling count=None msg=0/6 nodes are available: 2 c_wall violated: 1 conflicting context pair(s) with node memory, 4 node(s) had untolerated taint(s). no new claims to deallocate, preemption: 0/6 nodes are available: 2 No preemption victims found for incoming pod, 4 Preemption is not helpful for scheduling."
32.4181,Pod,MODIFIED,eval-sanitize-2-r1-029-vwzxl,phase=Running node=kind-worker
32.4206,Job,MODIFIED,eval-sanitize-2-r1-018,
32.4265,Job,MODIFIED,eval-sanitize-2-r1-018,
32.4297,Event,ADDED,eval-sanitize-2-r1-018.18d420e22ad38f6f,reason=Completed count=1 msg=Job completed
32.4357,Job,MODIFIED,eval-sanitize-2-r1-018,
32.4397,TaskRequest,MODIFIED,eval-sanitize-2-r1-018,phase=Complete job=None
32.4479,Job,MODIFIED,eval-sanitize-2-r1-018,
33.007,TaskRequest,ADDED,eval-sanitize-2-r1-033,phase=None job=None
33.0106,TaskRequest,MODIFIED,eval-sanitize-2-r1-033,phase=Pending job=None
33.0252,Job,ADDED,eval-sanitize-2-r1-033,
33.0334,Pod,ADDED,eval-sanitize-2-r1-033-895m8,phase=Pending node=None
33.0336,TaskRequest,MODIFIED,eval-sanitize-2-r1-033,phase=Scheduled job=None
33.0344,Job,MODIFIED,eval-sanitize-2-r1-033,
33.0375,Event,ADDED,eval-sanitize-2-r1-033.18d420e24efe9332,reason=SuccessfulCreate count=1 msg=Created pod: eval-sanitize-2-r1-033-895m8
33.0406,Job,MODIFIED,eval-sanitize-2-r1-032,
33.0407,TaskRequest,MODIFIED,eval-sanitize-2-r1-033,phase=Scheduled job=None
33.0445,Pod,MODIFIED,eval-sanitize-2-r1-033-895m8,phase=Pending node=kind-worker4
33.0484,Event,ADDED,eval-sanitize-2-r1-033-895m8.18d420e24fa7a668,reason=Scheduled count=None msg=Successfully assigned compute/eval-sanitize-2-r1-033-895m8 to kind-worker4
33.0529,Job,MODIFIED,eval-sanitize-2-r1-032,
33.0565,Node,MODIFIED,kind-worker4,taints=0
33.0583,Pod,MODIFIED,eval-sanitize-2-r1-033-895m8,phase=Pending node=kind-worker4
33.0615,Job,MODIFIED,eval-sanitize-2-r1-031,
33.0667,Node,MODIFIED,kind-worker4,taints=0
33.0709,Job,MODIFIED,eval-sanitize-2-r1-031,
33.1877,Node,MODIFIED,kind-worker,taints=1
33.1971,Pod,MODIFIED,eval-sanitize-2-r1-032-cjptq,phase=Pending node=None
33.2009,Node,MODIFIED,kind-worker,taints=1
33.2034,Event,ADDED,eval-sanitize-2-r1-032-cjptq.18d420e258eaf3e4,"reason=FailedScheduling count=None msg=0/6 nodes are available: 1 c_wall violated: 1 conflicting context pair(s) with node memory, 5 node(s) had untolerated taint(s). no new claims to deallocate, preemption: 0/6 nodes are available: 1 No preemption victims found for incoming pod, 5 Preemption is not helpful for scheduling."
33.2072,Event,MODIFIED,eval-sanitize-2-r1-032-cjptq.18d420e258eaf3e4,"reason=FailedScheduling count=None msg=0/6 nodes are available: 1 c_wall violated: 1 conflicting context pair(s) with node memory, 5 node(s) had untolerated taint(s). no new claims to deallocate, preemption: 0/6 nodes are available: 1 No preemption victims found for incoming pod, 5 Preemption is not helpful for scheduling."
33.3129,Job,MODIFIED,eval-sanitize-2-r1-030,
33.322,Job,MODIFIED,eval-sanitize-2-r1-030,
33.4218,Job,MODIFIED,eval-sanitize-2-r1-029,
33.4304,Job,MODIFIED,eval-sanitize-2-r1-029,
33.4762,Event,ADDED,eval-sanitize-2-r1-033-895m8.18d420e26927548c,"reason=Pulled count=1 msg=Container image ""busybox:musl"" already present on machine"
33.4951,Event,ADDED,eval-sanitize-2-r1-033-895m8.18d420e26a291e20,reason=Created count=1 msg=Created container: task
33.5249,Event,ADDED,eval-sanitize-2-r1-033-895m8.18d420e26c11c99b,reason=Started count=1 msg=Started container task
33.5929,Node,MODIFIED,kind-worker4,taints=1
33.5977,Pod,MODIFIED,eval-sanitize-2-r1-032-cjptq,phase=Pending node=None
33.6065,Node,MODIFIED,kind-worker4,taints=1
34.0085,TaskRequest,ADDED,eval-sanitize-2-r1-034,phase=None job=None
34.0122,TaskRequest,MODIFIED,eval-sanitize-2-r1-034,phase=Pending job=None
34.027,Job,ADDED,eval-sanitize-2-r1-034,
34.0321,Pod,ADDED,eval-sanitize-2-r1-034-bkxtk,phase=Pending node=None
34.0338,TaskRequest,MODIFIED,eval-sanitize-2-r1-034,phase=Scheduled job=None
34.0363,Job,MODIFIED,eval-sanitize-2-r1-034,
34.0383,Event,ADDED,eval-sanitize-2-r1-034.18d420e28a84c161,reason=SuccessfulCreate count=1 msg=Created pod: eval-sanitize-2-r1-034-bkxtk
34.0386,Event,ADDED,eval-sanitize-2-r1-034-bkxtk.18d420e28a947202,"reason=FailedScheduling count=None msg=0/6 nodes are available: 6 node(s) had untolerated taint(s). no new claims to deallocate, preemption: 0/6 nodes are available: 6 Preemption is not helpful for scheduling."
34.0397,Job,MODIFIED,eval-sanitize-2-r1-033,
34.0406,Pod,MODIFIED,eval-sanitize-2-r1-034-bkxtk,phase=Pending node=None
34.0407,TaskRequest,MODIFIED,eval-sanitize-2-r1-034,phase=Scheduled job=None
34.0475,Job,MODIFIED,eval-sanitize-2-r1-033,
34.3072,Pod,MODIFIED,eval-sanitize-2-r1-033-895m8,phase=Running node=kind-worker4
35.0075,TaskRequest,ADDED,eval-sanitize-2-r1-035,phase=None job=None
35.0114,TaskRequest,MODIFIED,eval-sanitize-2-r1-035,phase=Pending job=None
35.0288,Job,ADDED,eval-sanitize-2-r1-035,
35.0328,TaskRequest,MODIFIED,eval-sanitize-2-r1-035,phase=Scheduled job=None
35.0361,Pod,ADDED,eval-sanitize-2-r1-035-7rwtd,phase=Pending node=None
35.0382,Job,MODIFIED,eval-sanitize-2-r1-034,
35.0388,Job,MODIFIED,eval-sanitize-2-r1-035,
35.0416,Event,ADDED,eval-sanitize-2-r1-035.18d420e2c65ac44d,reason=SuccessfulCreate count=1 msg=Created pod: eval-sanitize-2-r1-035-7rwtd
35.042,Event,ADDED,eval-sanitize-2-r1-035-7rwtd.18d420e2c667b4b5,"reason=FailedScheduling count=None msg=0/6 nodes are available: 6 node(s) had untolerated taint(s). no new claims to deallocate, preemption: 0/6 nodes are available: 6 Preemption is not helpful for scheduling."
35.0421,TaskRequest,MODIFIED,eval-sanitize-2-r1-035,phase=Scheduled job=None
35.0431,Pod,MODIFIED,eval-sanitize-2-r1-035-7rwtd,phase=Pending node=None
35.044,Job,MODIFIED,eval-sanitize-2-r1-033,
35.0473,Job,MODIFIED,eval-sanitize-2-r1-034,
35.0523,Job,MODIFIED,eval-sanitize-2-r1-033,
36.0071,TaskRequest,ADDED,eval-sanitize-2-r1-036,phase=None job=None
36.011,TaskRequest,MODIFIED,eval-sanitize-2-r1-036,phase=Pending job=None
36.0269,Job,ADDED,eval-sanitize-2-r1-036,
36.0336,Pod,ADDED,eval-sanitize-2-r1-036-qp2wz,phase=Pending node=None
36.0337,TaskRequest,MODIFIED,eval-sanitize-2-r1-036,phase=Scheduled job=None
36.0362,Job,MODIFIED,eval-sanitize-2-r1-036,
36.0404,Event,ADDED,eval-sanitize-2-r1-036.18d420e301ccb5a2,reason=SuccessfulCreate count=1 msg=Created pod: eval-sanitize-2-r1-036-qp2wz
36.0406,Event,ADDED,eval-sanitize-2-r1-036-qp2wz.18d420e301dae957,"reason=FailedScheduling count=None msg=0/6 nodes are available: 6 node(s) had untolerated taint(s). no new claims to deallocate, preemption: 0/6 nodes are available: 6 Preemption is not helpful for scheduling."
36.0408,TaskRequest,MODIFIED,eval-sanitize-2-r1-036,phase=Scheduled job=None
36.0416,Job,MODIFIED,eval-sanitize-2-r1-035,
36.0424,Pod,MODIFIED,eval-sanitize-2-r1-036-qp2wz,phase=Pending node=None
36.05,Job,MODIFIED,eval-sanitize-2-r1-035,
37.0074,TaskRequest,ADDED,eval-sanitize-2-r1-037,phase=None job=None
37.012,TaskRequest,MODIFIED,eval-sanitize-2-r1-037,phase=Pending job=None
37.0271,Job,ADDED,eval-sanitize-2-r1-037,
37.0335,Pod,ADDED,eval-sanitize-2-r1-037-7pl9w,phase=Pending node=None
37.0337,TaskRequest,MODIFIED,eval-sanitize-2-r1-037,phase=Scheduled job=None
37.0362,Job,MODIFIED,eval-sanitize-2-r1-037,
37.0383,Job,MODIFIED,eval-sanitize-2-r1-036,
37.0403,Event,ADDED,eval-sanitize-2-r1-037.18d420e33d6a751e,reason=SuccessfulCreate count=1 msg=Created pod: eval-sanitize-2-r1-037-7pl9w
37.0405,Event,ADDED,eval-sanitize-2-r1-037-7pl9w.18d420e33d753ffe,"reason=FailedScheduling count=None msg=0/6 nodes are available: 6 node(s) had untolerated taint(s). no new claims to deallocate, preemption: 0/6 nodes are available: 6 Preemption is not helpful for scheduling."
37.0419,Pod,MODIFIED,eval-sanitize-2-r1-037-7pl9w,phase=Pending node=None
37.042,TaskRequest,MODIFIED,eval-sanitize-2-r1-037,phase=Scheduled job=None
37.0467,Job,MODIFIED,eval-sanitize-2-r1-036,
37.3243,Pod,MODIFIED,eval-sanitize-2-r1-021-xwkkx,phase=Running node=kind-worker5
37.3301,Pod,MODIFIED,eval-sanitize-2-r1-020-jm8sr,phase=Running node=kind-worker5
37.3357,Pod,MODIFIED,eval-sanitize-2-r1-024-mfnr5,phase=Running node=kind-worker5
37.3417,Pod,MODIFIED,eval-sanitize-2-r1-022-44zg5,phase=Running node=kind-worker5
37.3472,Pod,MODIFIED,eval-sanitize-2-r1-019-9fbj8,phase=Running node=kind-worker5
37.7292,Pod,MODIFIED,eval-sanitize-2-r1-027-622v9,phase=Running node=kind-worker3
37.7358,Pod,MODIFIED,eval-sanitize-2-r1-025-7m5rb,phase=Running node=kind-worker3
38.0071,TaskRequest,ADDED,eval-sanitize-2-r1-038,phase=None job=None
38.0126,TaskRequest,MODIFIED,eval-sanitize-2-r1-038,phase=Pending job=None
38.0268,Job,ADDED,eval-sanitize-2-r1-038,
38.0324,Pod,ADDED,eval-sanitize-2-r1-038-f2884,phase=Pending node=None
38.0335,TaskRequest,MODIFIED,eval-sanitize-2-r1-038,phase=Scheduled job=None
38.0342,Job,MODIFIED,eval-sanitize-2-r1-038,
38.0383,Event,ADDED,eval-sanitize-2-r1-038.18d420e378fb76c6,reason=SuccessfulCreate count=1 msg=Created pod: eval-sanitize-2-r1-038-f2884
38.0385,Event,ADDED,eval-sanitize-2-r1-038-f2884.18d420e3790440de,"reason=FailedScheduling count=None msg=0/6 nodes are available: 6 node(s) had untolerated taint(s). no new claims to deallocate, preemption: 0/6 nodes are available: 6 Preemption is not helpful for scheduling."
38.0392,Job,MODIFIED,eval-sanitize-2-r1-037,
38.0402,Pod,MODIFIED,eval-sanitize-2-r1-038-f2884,phase=Pending node=None
38.042,TaskRequest,MODIFIED,eval-sanitize-2-r1-038,phase=Scheduled job=None
38.0467,Job,MODIFIED,eval-sanitize-2-r1-037,
38.3313,Job,MODIFIED,eval-sanitize-2-r1-021,
38.3364,Job,MODIFIED,eval-sanitize-2-r1-020,
38.3412,Job,MODIFIED,eval-sanitize-2-r1-024,
38.3435,Job,MODIFIED,eval-sanitize-2-r1-021,
38.3455,Job,MODIFIED,eval-sanitize-2-r1-022,
38.3485,Job,MODIFIED,eval-sanitize-2-r1-020,
38.3501,Job,MODIFIED,eval-sanitize-2-r1-024,
38.353,Job,MODIFIED,eval-sanitize-2-r1-019,
38.3557,Job,MODIFIED,eval-sanitize-2-r1-022,
38.361,Job,MODIFIED,eval-sanitize-2-r1-019,
38.499,Pod,MODIFIED,eval-sanitize-2-r1-019-9fbj8,phase=Succeeded node=kind-worker5
38.5548,Pod,MODIFIED,eval-sanitize-2-r1-021-xwkkx,phase=Succeeded node=kind-worker5
38.5616,Pod,MODIFIED,eval-sanitize-2-r1-022-44zg5,phase=Succeeded node=kind-worker5
38.5673,Pod,MODIFIED,eval-sanitize-2-r1-020-jm8sr,phase=Succeeded node=kind-worker5
38.574,Pod,MODIFIED,eval-sanitize-2-r1-024-mfnr5,phase=Succeeded node=kind-worker5
38.7356,Job,MODIFIED,eval-sanitize-2-r1-027,
38.7415,Job,MODIFIED,eval-sanitize-2-r1-025,
38.7448,Job,MODIFIED,eval-sanitize-2-r1-027,
38.7503,Job,MODIFIED,eval-sanitize-2-r1-025,
38.9141,Pod,MODIFIED,eval-sanitize-2-r1-025-7m5rb,phase=Succeeded node=kind-worker3
38.9589,Pod,MODIFIED,eval-sanitize-2-r1-027-622v9,phase=Succeeded node=kind-worker3
39.0082,TaskRequest,ADDED,eval-sanitize-2-r1-039,phase=None job=None
39.0141,TaskRequest,MODIFIED,eval-sanitize-2-r1-039,phase=Pending job=None
39.0286,Job,ADDED,eval-sanitize-2-r1-039,
39.036,Pod,ADDED,eval-sanitize-2-r1-039-thkjq,phase=Pending node=None
39.0363,TaskRequest,MODIFIED,eval-sanitize-2-r1-039,phase=Scheduled job=None
39.0385,Job,MODIFIED,eval-sanitize-2-r1-038,
39.0411,Job,MODIFIED,eval-sanitize-2-r1-039,
39.0435,Event,ADDED,eval-sanitize-2-r1-039.18d420e3b4cd03e3,reason=SuccessfulCreate count=1 msg=Created pod: eval-sanitize-2-r1-039-thkjq
39.0441,Event,ADDED,eval-sanitize-2-r1-039-thkjq.18d420e3b4d4571e,"reason=FailedScheduling count=None msg=0/6 nodes are available: 6 node(s) had untolerated taint(s). no new claims to deallocate, preemption: 0/6 nodes are available: 6 Preemption is not helpful for scheduling."
39.0443,TaskRequest,MODIFIED,eval-sanitize-2-r1-039,phase=Scheduled job=None
39.0452,Pod,MODIFIED,eval-sanitize-2-r1-039-thkjq,phase=Pending node=None
39.0477,Job,MODIFIED,eval-sanitize-2-r1-038,
39.1447,Node,MODIFIED,kind-worker3,taints=1
39.1561,Node,MODIFIED,kind-worker3,taints=1
39.1643,Node,MODIFIED,kind-worker3,taints=0
39.1701,Pod,MODIFIED,eval-sanitize-2-r1-032-cjptq,phase=Pending node=kind-worker3
39.1762,Event,ADDED,eval-sanitize-2-r1-032-cjptq.18d420e3bccb601e,reason=Scheduled count=None msg=Successfully assigned compute/eval-sanitize-2-r1-032-cjptq to kind-worker3
39.1783,Event,ADDED,eval-sanitize-2-r1-034-bkxtk.18d420e3bd0168fe,"reason=FailedScheduling count=None msg=0/6 nodes are available: 1 c_wall violated: 1 conflicting context pair(s) with node memory, 5 node(s) had untolerated taint(s). no new claims to deallocate, preemption: 0/6 nodes are available: 1 No preemption victims found for incoming pod, 5 Preemption is not helpful for scheduling."
39.1798,Node,MODIFIED,kind-worker3,taints=0
39.1807,Pod,MODIFIED,eval-sanitize-2-r1-034-bkxtk,phase=Pending node=None
39.1834,Pod,MODIFIED,eval-sanitize-2-r1-032-cjptq,phase=Pending node=kind-worker3
39.1878,Pod,MODIFIED,eval-sanitize-2-r1-035-7rwtd,phase=Pending node=kind-worker3
39.1902,Pod,MODIFIED,eval-sanitize-2-r1-036-qp2wz,phase=Pending node=None
39.1936,Event,ADDED,eval-sanitize-2-r1-036-qp2wz.18d420e3bdb9069c,"reason=FailedScheduling count=None msg=0/6 nodes are available: 1 c_wall violated: 1 conflicting context pair(s) with node memory, 5 node(s) had untolerated taint(s). no new claims to deallocate, preemption: 0/6 nodes are available: 1 No preemption victims found for incoming pod, 5 Preemption is not helpful for scheduling."
39.1942,Event,ADDED,eval-sanitize-2-r1-035-7rwtd.18d420e3bdd5fe36,reason=Scheduled count=None msg=Successfully assigned compute/eval-sanitize-2-r1-035-7rwtd to kind-worker3
39.1988,Node,MODIFIED,kind-worker3,taints=0
39.1999,Event,ADDED,eval-sanitize-2-r1-037-7pl9w.18d420e3be2ff648,"reason=FailedScheduling count=None msg=0/6 nodes are available: 1 c_wall violated: 2 conflicting context pair(s) with node memory, 5 node(s) had untolerated taint(s). no new claims to deallocate, preemption: 0/6 nodes are available: 1 No preemption victims found for incoming pod, 5 Preemption is not helpful for scheduling."
39.2008,Pod,MODIFIED,eval-sanitize-2-r1-037-7pl9w,phase=Pending node=None
39.2021,Pod,MODIFIED,eval-sanitize-2-r1-035-7rwtd,phase=Pending node=kind-worker3
39.2088,Node,MODIFIED,kind-worker3,taints=0
39.2102,Pod,MODIFIED,eval-sanitize-2-r1-038-f2884,phase=Pending node=kind-worker3
39.2126,Pod,MODIFIED,eval-sanitize-2-r1-039-thkjq,phase=Pending node=kind-worker3
39.2131,Event,ADDED,eval-sanitize-2-r1-038-f2884.18d420e3bf2d8df2,reason=Scheduled count=None msg=Successfully assigned compute/eval-sanitize-2-r1-038-f2884 to kind-worker3
39.2195,Event,ADDED,eval-sanitize-2-r1-039-thkjq.18d420e3bf4de1e2,reason=Scheduled count=None msg=Successfully assigned compute/eval-sanitize-2-r1-039-thkjq to kind-worker3
39.2252,Pod,MODIFIED,eval-sanitize-2-r1-038-f2884,phase=Pending node=kind-worker3
39.2305,Pod,MODIFIED,eval-sanitize-2-r1-039-thkjq,phase=Pending node=kind-worker3
39.2465,Pod,MODIFIED,eval-sanitize-2-r1-034-bkxtk,phase=Pending node=None
39.2483,Event,ADDED,eval-sanitize-2-r1-034-bkxtk.18d420e3c10fd132,"reason=FailedScheduling count=None msg=0/6 nodes are available: 1 c_wall violated: 3 conflicting context pair(s) with node memory, 5 node(s) had untolerated taint(s). no new claims to deallocate, preemption: 0/6 nodes are available: 1 No preemption victims found for incoming pod, 5 Preemption is not helpful for scheduling."
39.2512,Node,MODIFIED,kind-worker3,taints=0
39.2559,Pod,MODIFIED,eval-sanitize-2-r1-036-qp2wz,phase=Pending node=None
39.2563,Event,ADDED,eval-sanitize-2-r1-036-qp2wz.18d420e3c1925963,"reason=FailedScheduling count=None msg=0/6 nodes are available: 1 c_wall violated: 2 conflicting context pair(s) with node memory, 5 node(s) had untolerated taint(s). no new claims to deallocate, preemption: 0/6 nodes are available: 1 No preemption victims found for incoming pod, 5 Preemption is not helpful for scheduling."
39.2615,Node,MODIFIED,kind-worker3,taints=0
39.2876,Pod,MODIFIED,eval-sanitize-2-r1-037-7pl9w,phase=Pending node=None
39.2881,Event,ADDED,eval-sanitize-2-r1-037-7pl9w.18d420e3c37df05e,"reason=FailedScheduling count=None msg=0/6 nodes are available: 1 c_wall violated: 3 conflicting context pair(s) with node memory, 5 node(s) had untolerated taint(s). no new claims to deallocate, preemption: 0/6 nodes are available: 1 No preemption victims found for incoming pod, 5 Preemption is not helpful for scheduling."
39.2943,Event,ADDED,eval-sanitize-2-r1-034-bkxtk.18d420e3c3fc6bef,"reason=FailedScheduling count=None msg=0/6 nodes are available: 1 c_wall violated: 3 conflicting context pair(s) with node memory, 5 node(s) had untolerated taint(s). no new claims to deallocate, preemption: 0/6 nodes are available: 1 No preemption victims found for incoming pod, 5 Preemption is not helpful for scheduling."
39.2973,Event,ADDED,eval-sanitize-2-r1-036-qp2wz.18d420e3c424f213,"reason=FailedScheduling count=None msg=0/6 nodes are available: 1 c_wall violated: 2 conflicting context pair(s) with node memory, 5 node(s) had untolerated taint(s). no new claims to deallocate, preemption: 0/6 nodes are available: 1 No preemption victims found for incoming pod, 5 Preemption is not helpful for scheduling."
39.299,Event,ADDED,eval-sanitize-2-r1-037-7pl9w.18d420e3c44e39f7,"reason=FailedScheduling count=None msg=0/6 nodes are available: 1 c_wall violated: 3 conflicting context pair(s) with node memory, 5 node(s) had untolerated taint(s). no new claims to deallocate, preemption: 0/6 nodes are available: 1 No preemption victims found for incoming pod, 5 Preemption is not helpful for scheduling."
39.3363,Job,MODIFIED,eval-sanitize-2-r1-021,
39.3405,Job,MODIFIED,eval-sanitize-2-r1-020,
39.3442,Pod,MODIFIED,eval-sanitize-2-r1-021-xwkkx,phase=Succeeded node=kind-worker5
39.346,Job,MODIFIED,eval-sanitize-2-r1-021,
39.349,Job,MODIFIED,eval-sanitize-2-r1-024,
39.3503,Pod,MODIFIED,eval-sanitize-2-r1-020-jm8sr,phase=Succeeded node=kind-worker5
39.3513,Job,MODIFIED,eval-sanitize-2-r1-020,
39.3521,Job,MODIFIED,eval-sanitize-2-r1-022,
39.3572,Pod,MODIFIED,eval-sanitize-2-r1-024-mfnr5,phase=Succeeded node=kind-worker5
39.3589,Pod,MODIFIED,eval-sanitize-2-r1-022-44zg5,phase=Succeeded node=kind-worker5
39.3598,Job,MODIFIED,eval-sanitize-2-r1-019,
39.3608,Job,MODIFIED,eval-sanitize-2-r1-024,
39.3617,Job,MODIFIED,eval-sanitize-2-r1-022,
39.3664,Pod,MODIFIED,eval-sanitize-2-r1-019-9fbj8,phase=Succeeded node=kind-worker5
39.368,Job,MODIFIED,eval-sanitize-2-r1-019,
39.543,Node,MODIFIED,kind-worker3,taints=0
39.55,Event,MODIFIED,eval-sanitize-2-r1-034-bkxtk.18d420e3c3fc6bef,"reason=FailedScheduling count=None msg=0/6 nodes are available: 1 c_wall violated: 3 conflicting context pair(s) with node memory, 5 node(s) had untolerated taint(s). no new claims to deallocate, preemption: 0/6 nodes are available: 1 No preemption victims found for incoming pod, 5 Preemption is not helpful for scheduling."
39.5536,Node,MODIFIED,kind-worker3,taints=0
39.554,Event,MODIFIED,eval-sanitize-2-r1-036-qp2wz.18d420e3c424f213,"reason=FailedScheduling count=None msg=0/6 nodes are available: 1 c_wall violated: 2 conflicting context pair(s) with node memory, 5 node(s) had untolerated taint(s). no new claims to deallocate, preemption: 0/6 nodes are available: 1 No preemption victims found for incoming pod, 5 Preemption is not helpful for scheduling."
39.556,Event,MODIFIED,eval-sanitize-2-r1-037-7pl9w.18d420e3c44e39f7,"reason=FailedScheduling count=None msg=0/6 nodes are available: 1 c_wall violated: 3 conflicting context pair(s) with node memory, 5 node(s) had untolerated taint(s). no new claims to deallocate, preemption: 0/6 nodes are available: 1 No preemption victims found for incoming pod, 5 Preemption is not helpful for scheduling."
39.601,Event,ADDED,eval-sanitize-2-r1-032-cjptq.18d420e3d60c6656,"reason=Pulled count=1 msg=Container image ""busybox:musl"" already present on machine"
39.6127,Event,ADDED,eval-sanitize-2-r1-035-7rwtd.18d420e3d6e90674,"reason=Pulled count=1 msg=Container image ""busybox:musl"" already present on machine"
39.6244,Event,ADDED,eval-sanitize-2-r1-032-cjptq.18d420e3d7a26145,reason=Created count=1 msg=Created container: task
39.6352,Event,ADDED,eval-sanitize-2-r1-035-7rwtd.18d420e3d852d15a,reason=Created count=1 msg=Created container: task
39.6672,Pod,MODIFIED,eval-sanitize-2-r1-023-42sh8,phase=Running node=kind-worker2
39.6771,Pod,MODIFIED,eval-sanitize-2-r1-028-gjgkl,phase=Running node=kind-worker2
39.6795,Event,ADDED,eval-sanitize-2-r1-039-thkjq.18d420e3dac9b517,"reason=Pulled count=1 msg=Container image ""busybox:musl"" already present on machine"
39.687,Pod,MODIFIED,eval-sanitize-2-r1-026-88m8g,phase=Running node=kind-worker2
39.6917,Event,ADDED,eval-sanitize-2-r1-032-cjptq.18d420e3db72be37,reason=Started count=1 msg=Started container task
39.6958,Event,ADDED,eval-sanitize-2-r1-035-7rwtd.18d420e3dbbf4b61,reason=Started count=1 msg=Started container task
39.7006,Event,ADDED,eval-sanitize-2-r1-038-f2884.18d420e3dbd540fb,"reason=Pulled count=1 msg=Container image ""busybox:musl"" already present on machine"
39.7053,Event,ADDED,eval-sanitize-2-r1-039-thkjq.18d420e3dc6a92e0,reason=Created count=1 msg=Created container: task
39.7215,Event,ADDED,eval-sanitize-2-r1-038-f2884.18d420e3dd575544,reason=Created count=1 msg=Created container: task
39.7395,Pod,MODIFIED,eval-sanitize-2-r1-032-cjptq,phase=Running node=kind-worker3
39.7408,Job,MODIFIED,eval-sanitize-2-r1-027,
39.7463,Pod,MODIFIED,eval-sanitize-2-r1-035-7rwtd,phase=Running node=kind-worker3
39.7479,Job,MODIFIED,eval-sanitize-2-r1-025,
39.7514,Pod,MODIFIED,eval-sanitize-2-r1-027-622v9,phase=Succeeded node=kind-worker3
39.7534,Job,MODIFIED,eval-sanitize-2-r1-027,
39.7584,Pod,MODIFIED,eval-sanitize-2-r1-025-7m5rb,phase=Succeeded node=kind-worker3
39.7599,Job,MODIFIED,eval-sanitize-2-r1-025,
39.9249,Event,ADDED,eval-sanitize-2-r1-039-thkjq.18d420e3e981b3c5,reason=Started count=1 msg=Started container task
39.9319,Event,ADDED,eval-sanitize-2-r1-038-f2884.18d420e3e9f22c3d,reason=Started count=1 msg=Started container task
40.0088,TaskRequest,ADDED,eval-sanitize-2-r1-040,phase=None job=None
40.0127,TaskRequest,MODIFIED,eval-sanitize-2-r1-040,phase=Pending job=None
40.0287,Job,ADDED,eval-sanitize-2-r1-040,
40.032,TaskRequest,MODIFIED,eval-sanitize-2-r1-040,phase=Scheduled job=None
40.0351,Pod,ADDED,eval-sanitize-2-r1-040-8rcmf,phase=Pending node=None
40.0389,Job,MODIFIED,eval-sanitize-2-r1-040,
40.0403,Event,ADDED,eval-sanitize-2-r1-040.18d420e3f058ef4e,reason=SuccessfulCreate count=1 msg=Created pod: eval-sanitize-2-r1-040-8rcmf
40.0404,TaskRequest,MODIFIED,eval-sanitize-2-r1-040,phase=Scheduled job=None
40.0429,Job,MODIFIED,eval-sanitize-2-r1-039,
40.0451,Pod,MODIFIED,eval-sanitize-2-r1-040-8rcmf,phase=Pending node=kind-worker3
40.0489,Event,ADDED,eval-sanitize-2-r1-040-8rcmf.18d420e3f0f2c740,reason=Scheduled count=None msg=Successfully assigned compute/eval-sanitize-2-r1-040-8rcmf to kind-worker3
40.0522,Job,MODIFIED,eval-sanitize-2-r1-039,
40.0578,Pod,MODIFIED,eval-sanitize-2-r1-040-8rcmf,phase=Pending node=kind-worker3
40.1755,Job,MODIFIED,eval-sanitize-2-r1-032,
40.1857,Job,MODIFIED,eval-sanitize-2-r1-032,
40.1922,Job,MODIFIED,eval-sanitize-2-r1-035,
40.2005,Job,MODIFIED,eval-sanitize-2-r1-035,
40.3423,Job,MODIFIED,eval-sanitize-2-r1-021,
40.3466,Job,MODIFIED,eval-sanitize-2-r1-020,
40.348,Job,MODIFIED,eval-sanitize-2-r1-021,
40.3505,Job,MODIFIED,eval-sanitize-2-r1-020,
40.354,Event,ADDED,eval-sanitize-2-r1-021.18d420e402ffe307,reason=Completed count=1 msg=Job completed
40.355,Job,MODIFIED,eval-sanitize-2-r1-024,
40.3586,Job,MODIFIED,eval-sanitize-2-r1-022,
40.3609,Event,ADDED,eval-sanitize-2-r1-020.18d420e403275a57,reason=Completed count=1 msg=Job completed
40.3618,Job,MODIFIED,eval-sanitize-2-r1-021,
40.3627,Job,MODIFIED,eval-sanitize-2-r1-024,
40.3646,Job,MODIFIED,eval-sanitize-2-r1-022,
40.3657,Job,MODIFIED,eval-sanitize-2-r1-019,
40.3676,Job,MODIFIED,eval-sanitize-2-r1-020,
40.3691,Event,ADDED,eval-sanitize-2-r1-024.18d420e403d23859,reason=Completed count=1 msg=Job completed
40.3692,TaskRequest,MODIFIED,eval-sanitize-2-r1-021,phase=Complete job=None
40.3708,Job,MODIFIED,eval-sanitize-2-r1-019,
40.3719,Job,MODIFIED,eval-sanitize-2-r1-024,
40.373,Event,ADDED,eval-sanitize-2-r1-022.18d420e4040687c0,reason=Completed count=1 msg=Job completed
40.3776,Job,MODIFIED,eval-sanitize-2-r1-022,
40.379,Event,ADDED,eval-sanitize-2-r1-019.18d420e4044f0016,reason=Completed count=1 msg=Job completed
40.3791,TaskRequest,MODIFIED,eval-sanitize-2-r1-020,phase=Complete job=None
40.38,Job,MODIFIED,eval-sanitize-2-r1-021,
40.3819,Job,MODIFIED,eval-sanitize-2-r1-019,
40.4272,TaskRequest,MODIFIED,eval-sanitize-2-r1-024,phase=Complete job=None
40.431,TaskRequest,MODIFIED,eval-sanitize-2-r1-022,phase=Complete job=None
40.4339,Job,MODIFIED,eval-sanitize-2-r1-020,
40.4365,Job,MODIFIED,eval-sanitize-2-r1-024,
40.4614,TaskRequest,MODIFIED,eval-sanitize-2-r1-019,phase=Complete job=None
40.4689,Job,MODIFIED,eval-sanitize-2-r1-022,
40.4713,Job,MODIFIED,eval-sanitize-2-r1-019,
40.4748,Event,ADDED,eval-sanitize-2-r1-040-8rcmf.18d420e40a54a6f1,"reason=Pulled count=1 msg=Container image ""busybox:musl"" already present on machine"
40.4928,Event,ADDED,eval-sanitize-2-r1-040-8rcmf.18d420e40b6e74b5,reason=Created count=1 msg=Created container: task
40.5602,Event,ADDED,eval-sanitize-2-r1-040-8rcmf.18d420e40f6b3ce6,reason=Started count=1 msg=Started container task
40.6739,Job,MODIFIED,eval-sanitize-2-r1-023,
40.6799,Job,MODIFIED,eval-sanitize-2-r1-028,
40.6843,Job,MODIFIED,eval-sanitize-2-r1-023,
40.6888,Job,MODIFIED,eval-sanitize-2-r1-028,
40.6925,Job,MODIFIED,eval-sanitize-2-r1-026,
40.702,Job,MODIFIED,eval-sanitize-2-r1-026,
40.746,Pod,MODIFIED,eval-sanitize-2-r1-040-8rcmf,phase=Running node=kind-worker3
40.7471,Job,MODIFIED,eval-sanitize-2-r1-027,
40.7499,Node,MODIFIED,kind-worker5,taints=1
40.7538,Job,MODIFIED,eval-sanitize-2-r1-027,
40.7574,Job,MODIFIED,eval-sanitize-2-r1-025,
40.7592,Pod,MODIFIED,eval-sanitize-2-r1-038-f2884,phase=Running node=kind-worker3
40.7596,Event,ADDED,eval-sanitize-2-r1-027.18d420e41b2eed54,reason=Completed count=1 msg=Job completed
40.7629,Job,MODIFIED,eval-sanitize-2-r1-025,
40.7657,Pod,MODIFIED,eval-sanitize-2-r1-039-thkjq,phase=Running node=kind-worker3
40.7673,Node,MODIFIED,kind-worker5,taints=0
40.7676,Event,ADDED,eval-sanitize-2-r1-025.18d420e41bbd68c3,reason=Completed count=1 msg=Job completed
40.7687,Job,MODIFIED,eval-sanitize-2-r1-027,
40.7726,TaskRequest,MODIFIED,eval-sanitize-2-r1-027,phase=Complete job=None
40.7766,Job,MODIFIED,eval-sanitize-2-r1-025,
40.7781,Node,MODIFIED,kind-worker5,taints=0
40.7827,Job,MODIFIED,eval-sanitize-2-r1-027,
40.7828,TaskRequest,MODIFIED,eval-sanitize-2-r1-025,phase=Complete job=None
40.7919,Job,MODIFIED,eval-sanitize-2-r1-025,
40.8388,Pod,MODIFIED,eval-sanitize-2-r1-028-gjgkl,phase=Succeeded node=kind-worker2
40.8471,Node,MODIFIED,kind-worker5,taints=0
40.8485,Pod,MODIFIED,eval-sanitize-2-r1-037-7pl9w,phase=Pending node=kind-worker5
40.8521,Event,ADDED,eval-sanitize-2-r1-037-7pl9w.18d420e420d06c36,reason=Scheduled count=None msg=Successfully assigned compute/eval-sanitize-2-r1-037-7pl9w to kind-worker5
40.8568,Pod,MODIFIED,eval-sanitize-2-r1-034-bkxtk,phase=Pending node=kind-worker5
40.8625,Node,MODIFIED,kind-worker5,taints=0
40.8641,Pod,MODIFIED,eval-sanitize-2-r1-036-qp2wz,phase=Pending node=None
40.8646,Event,ADDED,eval-sanitize-2-r1-034-bkxtk.18d420e4214a035c,reason=Scheduled count=None msg=Successfully assigned compute/eval-sanitize-2-r1-034-bkxtk to kind-worker5
40.8658,Pod,MODIFIED,eval-sanitize-2-r1-037-7pl9w,phase=Pending node=kind-worker5
40.8704,Pod,MODIFIED,eval-sanitize-2-r1-034-bkxtk,phase=Pending node=kind-worker5
40.8725,Node,MODIFIED,kind-worker5,taints=0
40.8746,Pod,MODIFIED,eval-sanitize-2-r1-023-42sh8,phase=Succeeded node=kind-worker2
40.8814,Pod,MODIFIED,eval-sanitize-2-r1-026-88m8g,phase=Succeeded node=kind-worker2
40.9477,Event,ADDED,eval-sanitize-2-r1-036-qp2wz.18d420e4267d96ae,"reason=FailedScheduling count=None msg=0/6 nodes are available: 1 c_wall violated: 1 conflicting context pair(s) with node memory, 1 c_wall violated: 2 conflicting context pair(s) with node memory, 4 node(s) had untolerated taint(s). no new claims to deallocate, preemption: 0/6 nodes are available: 2 No preemption victims found for incoming pod, 4 Preemption is not helpful for scheduling."
40.9527,Event,MODIFIED,eval-sanitize-2-r1-036-qp2wz.18d420e4267d96ae,"reason=FailedScheduling count=None msg=0/6 nodes are available: 1 c_wall violated: 1 conflicting context pair(s) with node memory, 1 c_wall violated: 2 conflicting context pair(s) with node memory, 4 node(s) had untolerated taint(s). no new claims to deallocate, preemption: 0/6 nodes are available: 2 No preemption victims found for incoming pod, 4 Preemption is not helpful for scheduling."
41.0066,TaskRequest,ADDED,eval-sanitize-2-r1-041,phase=None job=None
41.0119,TaskRequest,MODIFIED,eval-sanitize-2-r1-041,phase=Pending job=None
41.0263,Job,ADDED,eval-sanitize-2-r1-041,
41.0306,TaskRequest,MODIFIED,eval-sanitize-2-r1-041,phase=Scheduled job=None
41.0334,Pod,ADDED,eval-sanitize-2-r1-041-2kf6h,phase=Pending node=None
41.036,Job,MODIFIED,eval-sanitize-2-r1-041,
41.0396,Event,ADDED,eval-sanitize-2-r1-041.18d420e42bd9f38f,reason=SuccessfulCreate count=1 msg=Created pod: eval-sanitize-2-r1-041-2kf6h
41.0398,TaskRequest,MODIFIED,eval-sanitize-2-r1-041,phase=Scheduled job=None
41.0409,Job,MODIFIED,eval-sanitize-2-r1-040,
41.0494,Job,MODIFIED,eval-sanitize-2-r1-039,
41.0527,Node,MODIFIED,kind-worker2,taints=1
41.0555,Job,MODIFIED,eval-sanitize-2-r1-040,
41.0571,Pod,MODIFIED,eval-sanitize-2-r1-041-2kf6h,phase=Pending node=kind-worker5
41.061,Job,MODIFIED,eval-sanitize-2-r1-039,
41.0613,Event,ADDED,eval-sanitize-2-r1-041-2kf6h.18d420e42d1e5c9e,reason=Scheduled count=None msg=Successfully assigned compute/eval-sanitize-2-r1-041-2kf6h to kind-worker5
41.0672,Node,MODIFIED,kind-worker5,taints=0
41.0696,Pod,MODIFIED,eval-sanitize-2-r1-041-2kf6h,phase=Pending node=kind-worker5
41.0714,Pod,MODIFIED,eval-sanitize-2-r1-036-qp2wz,phase=Pending node=None
41.0729,Node,MODIFIED,kind-worker2,taints=0
41.0793,Node,MODIFIED,kind-worker2,taints=0
41.0812,Node,MODIFIED,kind-worker5,taints=0
41.1476,Node,MODIFIED,kind-worker2,taints=0
41.1491,Pod,MODIFIED,eval-sanitize-2-r1-036-qp2wz,phase=Pending node=kind-worker2
41.1524,Event,ADDED,eval-sanitize-2-r1-036-qp2wz.18d420e432bf0986,reason=Scheduled count=None msg=Successfully assigned compute/eval-sanitize-2-r1-036-qp2wz to kind-worker2
41.1585,Pod,MODIFIED,eval-sanitize-2-r1-036-qp2wz,phase=Pending node=kind-worker2
41.1626,Node,MODIFIED,kind-worker2,taints=0
41.1732,Node,MODIFIED,kind-worker2,taints=0
41.1882,Node,MODIFIED,kind-worker3,taints=1
41.2022,Node,MODIFIED,kind-worker3,taints=1
41.2722,Event,ADDED,eval-sanitize-2-r1-037-7pl9w.18d420e439ae3918,"reason=Pulled count=1 msg=Container image ""busybox:musl"" already present on machine"
41.2851,Event,ADDED,eval-sanitize-2-r1-034-bkxtk.18d420e43a960e33,"reason=Pulled count=1 msg=Container image ""busybox:musl"" already present on machine"
41.2923,Event,ADDED,eval-sanitize-2-r1-037-7pl9w.18d420e43b13ecd8,reason=Created count=1 msg=Created container: task
41.3038,Event,ADDED,eval-sanitize-2-r1-034-bkxtk.18d420e43bc293ee,reason=Created count=1 msg=Created container: task
41.3695,Event,ADDED,eval-sanitize-2-r1-037-7pl9w.18d420e43f735a61,reason=Started count=1 msg=Started container task
41.3739,Event,ADDED,eval-sanitize-2-r1-034-bkxtk.18d420e43fb65c9b,reason=Started count=1 msg=Started container task
41.4802,Event,ADDED,eval-sanitize-2-r1-041-2kf6h.18d420e446376725,"reason=Pulled count=1 msg=Container image ""busybox:musl"" already present on machine"
41.5032,Event,ADDED,eval-sanitize-2-r1-041-2kf6h.18d420e447932a90,reason=Created count=1 msg=Created container: task
41.5573,Event,ADDED,eval-sanitize-2-r1-041-2kf6h.18d420e44ac2540e,reason=Started count=1 msg=Started container task
41.561,Event,ADDED,eval-sanitize-2-r1-036-qp2wz.18d420e44b15e15b,"reason=Pulled count=1 msg=Container image ""busybox:musl"" already present on machine"
41.5797,Event,ADDED,eval-sanitize-2-r1-036-qp2wz.18d420e44c332afd,reason=Created count=1 msg=Created container: task
41.6483,Event,ADDED,eval-sanitize-2-r1-036-qp2wz.18d420e45040a55d,reason=Started count=1 msg=Started container task
41.6751,Pod,MODIFIED,eval-sanitize-2-r1-036-qp2wz,phase=Running node=kind-worker2
41.6784,Job,MODIFIED,eval-sanitize-2-r1-023,
41.6845,Job,MODIFIED,eval-sanitize-2-r1-028,
41.6881,Pod,MODIFIED,eval-sanitize-2-r1-023-42sh8,phase=Succeeded node=kind-worker2
41.6914,Job,MODIFIED,eval-sanitize-2-r1-023,
41.6957,Pod,MODIFIED,eval-sanitize-2-r1-028-gjgkl,phase=Succeeded node=kind-worker2
41.6971,Job,MODIFIED,eval-sanitize-2-r1-028,
41.6995,Job,MODIFIED,eval-sanitize-2-r1-026,
41.707,Pod,MODIFIED,eval-sanitize-2-r1-026-88m8g,phase=Succeeded node=kind-worker2
41.7088,Job,MODIFIED,eval-sanitize-2-r1-026,
41.7615,Job,MODIFIED,eval-sanitize-2-r1-038,
41.77,Job,MODIFIED,eval-sanitize-2-r1-038,
41.867,Job,MODIFIED,eval-sanitize-2-r1-036,
41.8876,Job,MODIFIED,eval-sanitize-2-r1-036,
42.0078,TaskRequest,ADDED,eval-sanitize-2-r1-042,phase=None job=None
42.0114,TaskRequest,MODIFIED,eval-sanitize-2-r1-042,phase=Pending job=None
42.0277,Job,ADDED,eval-sanitize-2-r1-042,
42.0345,Pod,ADDED,eval-sanitize-2-r1-042-9wtgn,phase=Pending node=None
42.0346,TaskRequest,MODIFIED,eval-sanitize-2-r1-042,phase=Scheduled job=None
42.0375,Job,MODIFIED,eval-sanitize-2-r1-042,
42.039,Event,ADDED,eval-sanitize-2-r1-042.18d420e46780dd96,reason=SuccessfulCreate count=1 msg=Created pod: eval-sanitize-2-r1-042-9wtgn
42.0398,Job,MODIFIED,eval-sanitize-2-r1-041,
42.0404,TaskRequest,MODIFIED,eval-sanitize-2-r1-042,phase=Scheduled job=None
42.0466,Pod,MODIFIED,eval-sanitize-2-r1-042-9wtgn,phase=Pending node=None
42.0477,Event,ADDED,eval-sanitize-2-r1-042-9wtgn.18d420e467f38cdf,"reason=FailedScheduling count=None msg=0/6 nodes are available: 1 c_wall violated: 1 conflicting context pair(s) with node memory, 1 c_wall violated: 2 conflicting context pair(s) with node memory, 4 node(s) had untolerated taint(s). no new claims to deallocate, preemption: 0/6 nodes are available: 2 No preemption victims found for incoming pod, 4 Preemption is not helpful for scheduling."
42.0488,Job,MODIFIED,eval-sanitize-2-r1-041,
42.0571,Event,ADDED,eval-sanitize-2-r1-042-9wtgn.18d420e468a5d8d3,"reason=FailedScheduling count=None msg=0/6 nodes are available: 1 c_wall violated: 1 conflicting context pair(s) with node memory, 1 c_wall violated: 2 conflicting context pair(s) with node memory, 4 node(s) had untolerated taint(s). no new claims to deallocate, preemption: 0/6 nodes are available: 2 No preemption victims found for incoming pod, 4 Preemption is not helpful for scheduling."
42.3227,Pod,MODIFIED,eval-sanitize-2-r1-030-2q542,phase=Running node=kind-worker4
42.3294,Pod,MODIFIED,eval-sanitize-2-r1-031-rq4sb,phase=Running node=kind-worker4
42.3333,Event,MODIFIED,eval-sanitize-2-r1-042-9wtgn.18d420e468a5d8d3,"reason=FailedScheduling count=None msg=0/6 nodes are available: 1 c_wall violated: 1 conflicting context pair(s) with node memory, 1 c_wall violated: 2 conflicting context pair(s) with node memory, 4 node(s) had untolerated taint(s). no new claims to deallocate, preemption: 0/6 nodes are available: 2 No preemption victims found for incoming pod, 4 Preemption is not helpful for scheduling."
42.3482,Pod,MODIFIED,eval-sanitize-2-r1-034-bkxtk,phase=Running node=kind-worker5
42.3546,Pod,MODIFIED,eval-sanitize-2-r1-037-7pl9w,phase=Running node=kind-worker5
42.3605,Pod,MODIFIED,eval-sanitize-2-r1-041-2kf6h,phase=Running node=kind-worker5
42.4347,Pod,MODIFIED,eval-sanitize-2-r1-029-vwzxl,phase=Running node=kind-worker
42.6851,Job,MODIFIED,eval-sanitize-2-r1-023,
42.689,Job,MODIFIED,eval-sanitize-2-r1-028,
42.6915,Job,MODIFIED,eval-sanitize-2-r1-023,
42.6939,Job,MODIFIED,eval-sanitize-2-r1-028,
42.6971,Event,ADDED,eval-sanitize-2-r1-023.18d420e48eb27506,reason=Completed count=1 msg=Job completed
42.7015,Job,MODIFIED,eval-sanitize-2-r1-023,
42.7048,Job,MODIFIED,eval-sanitize-2-r1-028,
42.7051,Event,ADDED,eval-sanitize-2-r1-028.18d420e48ed95a5c,reason=Completed count=1 msg=Job completed
42.7063,Job,MODIFIED,eval-sanitize-2-r1-026,
42.7064,TaskRequest,MODIFIED,eval-sanitize-2-r1-023,phase=Complete job=None
42.7101,Job,MODIFIED,eval-sanitize-2-r1-026,
42.7121,TaskRequest,MODIFIED,eval-sanitize-2-r1-028,phase=Complete job=None
42.7131,Event,ADDED,eval-sanitize-2-r1-026.18d420e48fce6871,reason=Completed count=1 msg=Job completed
42.7173,Job,MODIFIED,eval-sanitize-2-r1-023,
42.7203,Job,MODIFIED,eval-sanitize-2-r1-028,
42.7225,Job,MODIFIED,eval-sanitize-2-r1-026,
42.7268,TaskRequest,MODIFIED,eval-sanitize-2-r1-026,phase=Complete job=None
42.7351,Job,MODIFIED,eval-sanitize-2-r1-026,
42.8534,Node,MODIFIED,kind-worker5,taints=1
42.8612,Pod,MODIFIED,eval-sanitize-2-r1-042-9wtgn,phase=Pending node=None
42.8662,Node,MODIFIED,kind-worker5,taints=1
42.8688,Event,ADDED,eval-sanitize-2-r1-042-9wtgn.18d420e498fc078b,"reason=FailedScheduling count=None msg=0/6 nodes are available: 1 c_wall violated: 1 conflicting context pair(s) with node memory, 5 node(s) had untolerated taint(s). no new claims to deallocate, preemption: 0/6 nodes are available: 1 No preemption victims found for incoming pod, 5 Preemption is not helpful for scheduling."
42.8719,Event,MODIFIED,eval-sanitize-2-r1-042-9wtgn.18d420e498fc078b,"reason=FailedScheduling count=None msg=0/6 nodes are available: 1 c_wall violated: 1 conflicting context pair(s) with node memory, 5 node(s) had untolerated taint(s). no new claims to deallocate, preemption: 0/6 nodes are available: 1 No preemption victims found for incoming pod, 5 Preemption is not helpful for scheduling."
43.007,TaskRequest,ADDED,eval-sanitize-2-r1-043,phase=None job=None
43.0121,TaskRequest,MODIFIED,eval-sanitize-2-r1-043,phase=Pending job=None
43.0259,Job,ADDED,eval-sanitize-2-r1-043,
43.0314,TaskRequest,MODIFIED,eval-sanitize-2-r1-043,phase=Scheduled job=None
43.0332,Pod,ADDED,eval-sanitize-2-r1-043-qdbxg,phase=Pending node=None
43.0349,Job,MODIFIED,eval-sanitize-2-r1-043,
43.0383,Event,ADDED,eval-sanitize-2-r1-043.18d420e4a30c0788,reason=SuccessfulCreate count=1 msg=Created pod: eval-sanitize-2-r1-043-qdbxg
43.0392,Job,MODIFIED,eval-sanitize-2-r1-042,
43.0394,TaskRequest,MODIFIED,eval-sanitize-2-r1-043,phase=Scheduled job=None
43.0423,Pod,MODIFIED,eval-sanitize-2-r1-043-qdbxg,phase=Pending node=None
43.043,Event,ADDED,eval-sanitize-2-r1-043-qdbxg.18d420e4a34f20fa,"reason=FailedScheduling count=None msg=0/6 nodes are available: 1 c_wall violated: 1 conflicting context pair(s) with node memory, 5 node(s) had untolerated taint(s). no new claims to deallocate, preemption: 0/6 nodes are available: 1 No preemption victims found for incoming pod, 5 Preemption is not helpful for scheduling."
43.0455,Job,MODIFIED,eval-sanitize-2-r1-041,
43.0479,Job,MODIFIED,eval-sanitize-2-r1-042,
43.0504,Event,ADDED,eval-sanitize-2-r1-043-qdbxg.18d420e4a3d5473c,"reason=FailedScheduling count=None msg=0/6 nodes are available: 1 c_wall violated: 1 conflicting context pair(s) with node memory, 5 node(s) had untolerated taint(s). no new claims to deallocate, preemption: 0/6 nodes are available: 1 No preemption victims found for incoming pod, 5 Preemption is not helpful for scheduling."
43.054,Job,MODIFIED,eval-sanitize-2-r1-041,
43.0937,Node,MODIFIED,kind-worker2,taints=1
43.0984,Pod,MODIFIED,eval-sanitize-2-r1-042-9wtgn,phase=Pending node=None
43.1037,Pod,MODIFIED,eval-sanitize-2-r1-043-qdbxg,phase=Pending node=None
43.1052,Event,MODIFIED,eval-sanitize-2-r1-043-qdbxg.18d420e4a3d5473c,"reason=FailedScheduling count=None msg=0/6 nodes are available: 1 c_wall violated: 1 conflicting context pair(s) with node memory, 5 node(s) had untolerated taint(s). no new claims to deallocate, preemption: 0/6 nodes are available: 1 No preemption victims found for incoming pod, 5 Preemption is not helpful for scheduling."
43.1068,Node,MODIFIED,kind-worker2,taints=1
43.3285,Job,MODIFIED,eval-sanitize-2-r1-030,
43.3332,Job,MODIFIED,eval-sanitize-2-r1-031,
43.3379,Job,MODIFIED,eval-sanitize-2-r1-030,
43.3426,Job,MODIFIED,eval-sanitize-2-r1-031,
43.3524,Job,MODIFIED,eval-sanitize-2-r1-034,
43.3588,Job,MODIFIED,eval-sanitize-2-r1-037,
43.3613,Job,MODIFIED,eval-sanitize-2-r1-034,
43.3666,Job,MODIFIED,eval-sanitize-2-r1-037,
43.4412,Job,MODIFIED,eval-sanitize-2-r1-029,
43.4503,Job,MODIFIED,eval-sanitize-2-r1-029,
43.4865,Pod,MODIFIED,eval-sanitize-2-r1-030-2q542,phase=Succeeded node=kind-worker4
43.5236,Pod,MODIFIED,eval-sanitize-2-r1-031-rq4sb,phase=Succeeded node=kind-worker4
43.579,Pod,MODIFIED,eval-sanitize-2-r1-029-vwzxl,phase=Succeeded node=kind-worker
43.7454,Node,MODIFIED,kind-worker,taints=1
43.7577,Node,MODIFIED,kind-worker,taints=0
43.7633,Pod,MODIFIED,eval-sanitize-2-r1-042-9wtgn,phase=Pending node=kind-worker
43.7659,Pod,MODIFIED,eval-sanitize-2-r1-043-qdbxg,phase=Pending node=kind-worker
43.77,Node,MODIFIED,kind-worker,taints=0
43.7704,Event,ADDED,eval-sanitize-2-r1-042-9wtgn.18d420e4ce8fdee1,reason=Scheduled count=None msg=Successfully assigned compute/eval-sanitize-2-r1-042-9wtgn to kind-worker
43.7706,Event,ADDED,eval-sanitize-2-r1-043-qdbxg.18d420e4ceba1671,reason=Scheduled count=None msg=Successfully assigned compute/eval-sanitize-2-r1-043-qdbxg to kind-worker
43.776,Pod,MODIFIED,eval-sanitize-2-r1-042-9wtgn,phase=Pending node=kind-worker
43.7803,Node,MODIFIED,kind-worker,taints=0
43.7818,Pod,MODIFIED,eval-sanitize-2-r1-043-qdbxg,phase=Pending node=kind-worker
43.7939,Node,MODIFIED,kind-worker,taints=0
43.8444,Node,MODIFIED,kind-worker,taints=0
43.8616,Node,MODIFIED,kind-worker,taints=0
43.8705,Node,MODIFIED,kind-worker,taints=0
43.9734,Node,MODIFIED,kind-worker,taints=0
44.0079,TaskRequest,ADDED,eval-sanitize-2-r1-044,phase=None job=None
44.0116,TaskRequest,MODIFIED,eval-sanitize-2-r1-044,phase=Pending job=None
44.0265,Job,ADDED,eval-sanitize-2-r1-044,
44.0327,Pod,ADDED,eval-sanitize-2-r1-044-nh4hg,phase=Pending node=None
44.0337,TaskRequest,MODIFIED,eval-sanitize-2-r1-044,phase=Scheduled job=None
44.0347,Job,MODIFIED,eval-sanitize-2-r1-044,
44.0379,Event,ADDED,eval-sanitize-2-r1-044.18d420e4dea15172,reason=SuccessfulCreate count=1 msg=Created pod: eval-sanitize-2-r1-044-nh4hg
44.0387,Job,MODIFIED,eval-sanitize-2-r1-043,
44.0411,Pod,MODIFIED,eval-sanitize-2-r1-044-nh4hg,phase=Pending node=None
44.0415,Event,ADDED,eval-sanitize-2-r1-044-nh4hg.18d420e4dedb78f4,"reason=FailedScheduling count=None msg=0/6 nodes are available: 1 c_wall violated: 1 conflicting context pair(s) with node memory, 5 node(s) had untolerated taint(s). no new claims to deallocate, preemption: 0/6 nodes are available: 1 No preemption victims found for incoming pod, 5 Preemption is not helpful for scheduling."
44.0417,TaskRequest,MODIFIED,eval-sanitize-2-r1-044,phase=Scheduled job=None
44.0469,Job,MODIFIED,eval-sanitize-2-r1-043,
44.0479,Event,ADDED,eval-sanitize-2-r1-044-nh4hg.18d420e4df5dd8a6,"reason=FailedScheduling count=None msg=0/6 nodes are available: 1 c_wall violated: 1 conflicting context pair(s) with node memory, 5 node(s) had untolerated taint(s). no new claims to deallocate, preemption: 0/6 nodes are available: 1 No preemption victims found for incoming pod, 5 Preemption is not helpful for scheduling."
44.205,Event,ADDED,eval-sanitize-2-r1-043-qdbxg.18d420e4e8a8c441,"reason=Pulled count=1 msg=Container image ""busybox:musl"" already present on machine"
44.2102,Event,ADDED,eval-sanitize-2-r1-042-9wtgn.18d420e4e8bff0be,"reason=Pulled count=1 msg=Container image ""busybox:musl"" already present on machine"
44.2263,Event,ADDED,eval-sanitize-2-r1-043-qdbxg.18d420e4e9f5c2d3,reason=Created count=1 msg=Created container: task
44.2341,Event,ADDED,eval-sanitize-2-r1-042-9wtgn.18d420e4ea5c4653,reason=Created count=1 msg=Created container: task
44.263,Event,ADDED,eval-sanitize-2-r1-043-qdbxg.18d420e4ec15a0bc,reason=Started count=1 msg=Started container task
44.2675,Event,ADDED,eval-sanitize-2-r1-042-9wtgn.18d420e4ec6c576b,reason=Started count=1 msg=Started container task
44.3328,Pod,MODIFIED,eval-sanitize-2-r1-033-895m8,phase=Running node=kind-worker4
44.3339,Job,MODIFIED,eval-sanitize-2-r1-030,
44.339,Job,MODIFIED,eval-sanitize-2-r1-031,
44.3433,Pod,MODIFIED,eval-sanitize-2-r1-030-2q542,phase=Succeeded node=kind-worker4
44.3436,Event,MODIFIED,eval-sanitize-2-r1-044-nh4hg.18d420e4df5dd8a6,"reason=FailedScheduling count=None msg=0/6 nodes are available: 1 c_wall violated: 1 conflicting context pair(s) with node memory, 5 node(s) had untolerated taint(s). no new claims to deallocate, preemption: 0/6 nodes are available: 1 No preemption victims found for incoming pod, 5 Preemption is not helpful for scheduling."
44.3444,Job,MODIFIED,eval-sanitize-2-r1-030,
44.3464,Pod,MODIFIED,eval-sanitize-2-r1-031-rq4sb,phase=Succeeded node=kind-worker4
44.3475,Job,MODIFIED,eval-sanitize-2-r1-031,
44.441,Pod,MODIFIED,eval-sanitize-2-r1-042-9wtgn,phase=Running node=kind-worker
44.4459,Job,MODIFIED,eval-sanitize-2-r1-029,
44.4488,Pod,MODIFIED,eval-sanitize-2-r1-043-qdbxg,phase=Running node=kind-worker
44.4544,Pod,MODIFIED,eval-sanitize-2-r1-029-vwzxl,phase=Succeeded node=kind-worker
44.4562,Job,MODIFIED,eval-sanitize-2-r1-029,
45.0073,TaskRequest,ADDED,eval-sanitize-2-r1-045,phase=None job=None
45.0118,TaskRequest,MODIFIED,eval-sanitize-2-r1-045,phase=Pending job=None
45.0257,Job,ADDED,eval-sanitize-2-r1-045,
45.0311,TaskRequest,MODIFIED,eval-sanitize-2-r1-045,phase=Scheduled job=None
45.0342,Job,MODIFIED,eval-sanitize-2-r1-045,
45.035,Pod,ADDED,eval-sanitize-2-r1-045-ph5q2,phase=Pending node=None
45.0413,Job,MODIFIED,eval-sanitize-2-r1-044,
45.0426,Event,ADDED,eval-sanitize-2-r1-045.18d420e51a4f2bc7,reason=SuccessfulCreate count=1 msg=Created pod: eval-sanitize-2-r1-045-ph5q2
45.0427,TaskRequest,MODIFIED,eval-sanitize-2-r1-045,phase=Scheduled job=None
45.0437,Pod,MODIFIED,eval-sanitize-2-r1-045-ph5q2,phase=Pending node=None
45.0464,Event,ADDED,eval-sanitize-2-r1-045-ph5q2.18d420e51a943f63,"reason=FailedScheduling count=None msg=0/6 nodes are available: 1 c_wall violated: 2 conflicting context pair(s) with node memory, 5 node(s) had untolerated taint(s). no new claims to deallocate, preemption: 0/6 nodes are available: 1 No preemption victims found for incoming pod, 5 Preemption is not helpful for scheduling."
45.0473,Job,MODIFIED,eval-sanitize-2-r1-043,
45.051,Job,MODIFIED,eval-sanitize-2-r1-044,
45.0513,Event,ADDED,eval-sanitize-2-r1-045-ph5q2.18d420e51b19bc75,"reason=FailedScheduling count=None msg=0/6 nodes are available: 1 c_wall violated: 2 conflicting context pair(s) with node memory, 5 node(s) had untolerated taint(s). no new claims to deallocate, preemption: 0/6 nodes are available: 1 No preemption victims found for incoming pod, 5 Preemption is not helpful for scheduling."
45.0556,Job,MODIFIED,eval-sanitize-2-r1-043,
45.3391,Job,MODIFIED,eval-sanitize-2-r1-033,
45.3401,Job,MODIFIED,eval-sanitize-2-r1-030,
45.3431,Job,MODIFIED,eval-sanitize-2-r1-030,
45.3454,Job,MODIFIED,eval-sanitize-2-r1-031,
45.3508,Event,ADDED,eval-sanitize-2-r1-030.18d420e52cbeccf3,reason=Completed count=1 msg=Job completed
45.353,Job,MODIFIED,eval-sanitize-2-r1-031,
45.3539,Job,MODIFIED,eval-sanitize-2-r1-033,
45.3549,Job,MODIFIED,eval-sanitize-2-r1-030,
45.3561,Event,ADDED,eval-sanitize-2-r1-031.18d420e52d590535,reason=Completed count=1 msg=Job completed
45.3591,TaskRequest,MODIFIED,eval-sanitize-2-r1-030,phase=Complete job=None
45.3653,Job,MODIFIED,eval-sanitize-2-r1-031,
45.3694,Job,MODIFIED,eval-sanitize-2-r1-030,
45.3696,TaskRequest,MODIFIED,eval-sanitize-2-r1-031,phase=Complete job=None
45.3812,Job,MODIFIED,eval-sanitize-2-r1-031,
45.4262,Pod,MODIFIED,eval-sanitize-2-r1-033-895m8,phase=Succeeded node=kind-worker4
45.439,Event,MODIFIED,eval-sanitize-2-r1-045-ph5q2.18d420e51b19bc75,"reason=FailedScheduling count=None msg=0/6 nodes are available: 1 c_wall violated: 2 conflicting context pair(s) with node memory, 5 node(s) had untolerated taint(s). no new claims to deallocate, preemption: 0/6 nodes are available: 1 No preemption victims found for incoming pod, 5 Preemption is not helpful for scheduling."
45.4448,Job,MODIFIED,eval-sanitize-2-r1-042,
45.4503,Job,MODIFIED,eval-sanitize-2-r1-029,
45.4543,Job,MODIFIED,eval-sanitize-2-r1-042,
45.4569,Job,MODIFIED,eval-sanitize-2-r1-029,
45.4593,Event,ADDED,eval-sanitize-2-r1-029.18d420e533861e79,reason=Completed count=1 msg=Job completed
45.4641,Job,MODIFIED,eval-sanitize-2-r1-029,
45.4688,TaskRequest,MODIFIED,eval-sanitize-2-r1-029,phase=Complete job=None
45.4776,Job,MODIFIED,eval-sanitize-2-r1-029,
45.7793,Node,MODIFIED,kind-worker,taints=1
45.7841,Pod,MODIFIED,eval-sanitize-2-r1-044-nh4hg,phase=Pending node=None
45.7888,Pod,MODIFIED,eval-sanitize-2-r1-045-ph5q2,phase=Pending node=None
45.7914,Node,MODIFIED,kind-worker,taints=1
46.0069,TaskRequest,ADDED,eval-sanitize-2-r1-046,phase=None job=None
46.0113,TaskRequest,MODIFIED,eval-sanitize-2-r1-046,phase=Pending job=None
46.026,Job,ADDED,eval-sanitize-2-r1-046,
46.0326,Pod,ADDED,eval-sanitize-2-r1-046-qpmdw,phase=Pending node=None
46.0341,TaskRequest,MODIFIED,eval-sanitize-2-r1-046,phase=Scheduled job=None
46.041,Job,MODIFIED,eval-sanitize-2-r1-046,
46.0427,Event,ADDED,eval-sanitize-2-r1-046.18d420e555d19325,reason=SuccessfulCreate count=1 msg=Created pod: eval-sanitize-2-r1-046-qpmdw
46.0429,Event,ADDED,eval-sanitize-2-r1-046-qpmdw.18d420e555dde073,"reason=FailedScheduling count=None msg=0/6 nodes are available: 6 node(s) had untolerated taint(s). no new claims to deallocate, preemption: 0/6 nodes are available: 6 Preemption is not helpful for scheduling."
46.0438,Job,MODIFIED,eval-sanitize-2-r1-045,
46.0447,Pod,MODIFIED,eval-sanitize-2-r1-046-qpmdw,phase=Pending node=None
46.0449,TaskRequest,MODIFIED,eval-sanitize-2-r1-046,phase=Scheduled job=None
46.0519,Job,MODIFIED,eval-sanitize-2-r1-045,
46.161,Node,MODIFIED,kind-worker4,taints=1
46.1745,Node,MODIFIED,kind-worker4,taints=1
46.2431,Node,MODIFIED,kind-worker4,taints=0
46.2495,Pod,MODIFIED,eval-sanitize-2-r1-044-nh4hg,phase=Pending node=kind-worker4
46.2558,Pod,MODIFIED,eval-sanitize-2-r1-045-ph5q2,phase=Pending node=kind-worker4
46.2575,Event,ADDED,eval-sanitize-2-r1-044-nh4hg.18d420e562b366d6,reason=Scheduled count=None msg=Successfully assigned compute/eval-sanitize-2-r1-044-nh4hg to kind-worker4
46.2589,Node,MODIFIED,kind-worker4,taints=0
46.2623,Event,ADDED,eval-sanitize-2-r1-046-qpmdw.18d420e562e30fb6,"reason=FailedScheduling count=None msg=0/6 nodes are available: 1 c_wall violated: 1 conflicting context pair(s) with node memory, 5 node(s) had untolerated taint(s). no new claims to deallocate, preemption: 0/6 nodes are available: 1 No preemption victims found for incoming pod, 5 Preemption is not helpful for scheduling."
46.2639,Pod,MODIFIED,eval-sanitize-2-r1-046-qpmdw,phase=Pending node=None
46.2643,Event,ADDED,eval-sanitize-2-r1-045-ph5q2.18d420e5630d076e,reason=Scheduled count=None msg=Successfully assigned compute/eval-sanitize-2-r1-045-ph5q2 to kind-worker4
46.2655,Pod,MODIFIED,eval-sanitize-2-r1-044-nh4hg,phase=Pending node=kind-worker4
46.2712,Pod,MODIFIED,eval-sanitize-2-r1-045-ph5q2,phase=Pending node=kind-worker4
46.2727,Event,ADDED,eval-sanitize-2-r1-046-qpmdw.18d420e563df1546,"reason=FailedScheduling count=None msg=0/6 nodes are available: 1 c_wall violated: 1 conflicting context pair(s) with node memory, 5 node(s) had untolerated taint(s). no new claims to deallocate, preemption: 0/6 nodes are available: 1 No preemption victims found for incoming pod, 5 Preemption is not helpful for scheduling."
46.2836,Node,MODIFIED,kind-worker4,taints=0
46.2933,Node,MODIFIED,kind-worker4,taints=0
46.345,Job,MODIFIED,eval-sanitize-2-r1-033,
46.3529,Pod,MODIFIED,eval-sanitize-2-r1-033-895m8,phase=Succeeded node=kind-worker4
46.3547,Job,MODIFIED,eval-sanitize-2-r1-033,
46.356,Node,MODIFIED,kind-worker4,taints=0
46.3657,Node,MODIFIED,kind-worker4,taints=0
46.6889,Event,ADDED,eval-sanitize-2-r1-044-nh4hg.18d420e57c978f57,"reason=Pulled count=1 msg=Container image ""busybox:musl"" already present on machine"
46.6934,Event,ADDED,eval-sanitize-2-r1-045-ph5q2.18d420e57cb06754,"reason=Pulled count=1 msg=Container image ""busybox:musl"" already present on machine"
46.708,Event,ADDED,eval-sanitize-2-r1-044-nh4hg.18d420e57de4ecd7,reason=Created count=1 msg=Created container: task
46.714,Event,ADDED,eval-sanitize-2-r1-045-ph5q2.18d420e57e3a3f2d,reason=Created count=1 msg=Created container: task
46.7424,Event,ADDED,eval-sanitize-2-r1-044-nh4hg.18d420e57fe90fbf,reason=Started count=1 msg=Started container task
46.7472,Event,ADDED,eval-sanitize-2-r1-045-ph5q2.18d420e58029b266,reason=Started count=1 msg=Started container task
47.0077,TaskRequest,ADDED,eval-sanitize-2-r1-047,phase=None job=None
47.0122,TaskRequest,MODIFIED,eval-sanitize-2-r1-047,phase=Pending job=None
47.0268,Job,ADDED,eval-sanitize-2-r1-047,
47.0319,TaskRequest,MODIFIED,eval-sanitize-2-r1-047,phase=Scheduled job=None
47.0332,Pod,ADDED,eval-sanitize-2-r1-047-v644x,phase=Pending node=None
47.0355,Job,MODIFIED,eval-sanitize-2-r1-047,
47.0376,Job,MODIFIED,eval-sanitize-2-r1-046,
47.039,Event,ADDED,eval-sanitize-2-r1-047.18d420e59177b027,reason=SuccessfulCreate count=1 msg=Created pod: eval-sanitize-2-r1-047-v644x
47.0413,TaskRequest,MODIFIED,eval-sanitize-2-r1-047,phase=Scheduled job=None
47.0426,Pod,MODIFIED,eval-sanitize-2-r1-047-v644x,phase=Pending node=kind-worker4
47.0461,Job,MODIFIED,eval-sanitize-2-r1-046,
47.0476,Event,ADDED,eval-sanitize-2-r1-047-v644x.18d420e59200715d,reason=Scheduled count=None msg=Successfully assigned compute/eval-sanitize-2-r1-047-v644x to kind-worker4
47.0535,Pod,MODIFIED,eval-sanitize-2-r1-047-v644x,phase=Pending node=kind-worker4
47.3403,Pod,MODIFIED,eval-sanitize-2-r1-044-nh4hg,phase=Running node=kind-worker4
47.3467,Pod,MODIFIED,eval-sanitize-2-r1-045-ph5q2,phase=Running node=kind-worker4
47.3505,Job,MODIFIED,eval-sanitize-2-r1-033,
47.3563,Job,MODIFIED,eval-sanitize-2-r1-033,
47.3612,Event,ADDED,eval-sanitize-2-r1-033.18d420e5a4be5d72,reason=Completed count=1 msg=Job completed
47.3674,Job,MODIFIED,eval-sanitize-2-r1-033,
47.3716,TaskRequest,MODIFIED,eval-sanitize-2-r1-033,phase=Complete job=None
47.3812,Job,MODIFIED,eval-sanitize-2-r1-033,
47.4511,Event,ADDED,eval-sanitize-2-r1-047-v644x.18d420e5aa28de5d,"reason=Pulled count=1 msg=Container image ""busybox:musl"" already present on machine"
47.4685,Event,ADDED,eval-sanitize-2-r1-047-v644x.18d420e5ab2eed72,reason=Created count=1 msg=Created container: task
47.501,Event,ADDED,eval-sanitize-2-r1-047-v644x.18d420e5ad102b58,reason=Started count=1 msg=Started container task
48.0066,TaskRequest,ADDED,eval-sanitize-2-r1-048,phase=None job=None
48.0098,TaskRequest,MODIFIED,eval-sanitize-2-r1-048,phase=Pending job=None
48.025,Job,ADDED,eval-sanitize-2-r1-048,
48.0314,Pod,ADDED,eval-sanitize-2-r1-048-6852f,phase=Pending node=None
48.0315,TaskRequest,MODIFIED,eval-sanitize-2-r1-048,phase=Scheduled job=None
48.034,Job,MODIFIED,eval-sanitize-2-r1-048,
48.039,Event,ADDED,eval-sanitize-2-r1-048.18d420e5ccfa213a,reason=SuccessfulCreate count=1 msg=Created pod: eval-sanitize-2-r1-048-6852f
48.0399,Job,MODIFIED,eval-sanitize-2-r1-047,
48.04,TaskRequest,MODIFIED,eval-sanitize-2-r1-048,phase=Scheduled job=None
48.0411,Event,ADDED,eval-sanitize-2-r1-048-6852f.18d420e5cd403db6,"reason=FailedScheduling count=None msg=0/6 nodes are available: 1 c_wall violated: 1 conflicting context pair(s) with node memory, 5 node(s) had untolerated taint(s). no new claims to deallocate, preemption: 0/6 nodes are available: 1 No preemption victims found for incoming pod, 5 Preemption is not helpful for scheduling."
48.042,Pod,MODIFIED,eval-sanitize-2-r1-048-6852f,phase=Pending node=None
48.0496,Job,MODIFIED,eval-sanitize-2-r1-047,
48.0501,Event,ADDED,eval-sanitize-2-r1-048-6852f.18d420e5cdd37761,"reason=FailedScheduling count=None msg=0/6 nodes are available: 1 c_wall violated: 1 conflicting context pair(s) with node memory, 5 node(s) had untolerated taint(s). no new claims to deallocate, preemption: 0/6 nodes are available: 1 No preemption victims found for incoming pod, 5 Preemption is not helpful for scheduling."
48.269,Node,MODIFIED,kind-worker4,taints=1
48.2735,Pod,MODIFIED,eval-sanitize-2-r1-046-qpmdw,phase=Pending node=None
48.2775,Pod,MODIFIED,eval-sanitize-2-r1-048-6852f,phase=Pending node=None
48.2797,Event,MODIFIED,eval-sanitize-2-r1-048-6852f.18d420e5cdd37761,"reason=FailedScheduling count=None msg=0/6 nodes are available: 1 c_wall violated: 1 conflicting context pair(s) with node memory, 5 node(s) had untolerated taint(s). no new claims to deallocate, preemption: 0/6 nodes are available: 1 No preemption victims found for incoming pod, 5 Preemption is not helpful for scheduling."
48.2835,Node,MODIFIED,kind-worker4,taints=1
48.3444,Pod,MODIFIED,eval-sanitize-2-r1-047-v644x,phase=Running node=kind-worker4
48.3456,Job,MODIFIED,eval-sanitize-2-r1-044,
48.3511,Job,MODIFIED,eval-sanitize-2-r1-045,
48.3558,Job,MODIFIED,eval-sanitize-2-r1-044,
48.3604,Job,MODIFIED,eval-sanitize-2-r1-045,
49.0074,TaskRequest,ADDED,eval-sanitize-2-r1-049,phase=None job=None
49.0108,TaskRequest,MODIFIED,eval-sanitize-2-r1-049,phase=Pending job=None
49.0257,Job,ADDED,eval-sanitize-2-r1-049,
49.0327,Pod,ADDED,eval-sanitize-2-r1-049-lmphz,phase=Pending node=None
49.0328,TaskRequest,MODIFIED,eval-sanitize-2-r1-049,phase=Scheduled job=None
49.035,Job,MODIFIED,eval-sanitize-2-r1-049,
49.0376,Job,MODIFIED,eval-sanitize-2-r1-048,
49.0387,Pod,MODIFIED,eval-sanitize-2-r1-049-lmphz,phase=Pending node=None
49.0391,Event,ADDED,eval-sanitize-2-r1-049.18d420e608a503ce,reason=SuccessfulCreate count=1 msg=Created pod: eval-sanitize-2-r1-049-lmphz
49.0393,Event,ADDED,eval-sanitize-2-r1-049-lmphz.18d420e608b12260,"reason=FailedScheduling count=None msg=0/6 nodes are available: 6 node(s) had untolerated taint(s). no new claims to deallocate, preemption: 0/6 nodes are available: 6 Preemption is not helpful for scheduling."
49.0394,TaskRequest,MODIFIED,eval-sanitize-2-r1-049,phase=Scheduled job=None
49.0438,Job,MODIFIED,eval-sanitize-2-r1-047,
49.0456,Job,MODIFIED,eval-sanitize-2-r1-048,
49.0514,Job,MODIFIED,eval-sanitize-2-r1-047,
49.7667,Pod,MODIFIED,eval-sanitize-2-r1-032-cjptq,phase=Running node=kind-worker3
49.774,Pod,MODIFIED,eval-sanitize-2-r1-035-7rwtd,phase=Running node=kind-worker3
49.9044,Node,MODIFIED,kind-worker5,taints=1
50.0074,TaskRequest,ADDED,eval-sanitize-2-r1-050,phase=None job=None
50.0125,TaskRequest,MODIFIED,eval-sanitize-2-r1-050,phase=Pending job=None
50.0266,Job,ADDED,eval-sanitize-2-r1-050,
50.0328,TaskRequest,MODIFIED,eval-sanitize-2-r1-050,phase=Scheduled job=None
50.0358,Job,MODIFIED,eval-sanitize-2-r1-050,
50.037,Pod,ADDED,eval-sanitize-2-r1-050-qkt2f,phase=Pending node=None
50.0379,Job,MODIFIED,eval-sanitize-2-r1-049,
50.0411,Pod,MODIFIED,eval-sanitize-2-r1-050-qkt2f,phase=Pending node=None
50.0422,Event,ADDED,eval-sanitize-2-r1-050.18d420e64476b68a,reason=SuccessfulCreate count=1 msg=Created pod: eval-sanitize-2-r1-050-qkt2f
50.0424,Event,ADDED,eval-sanitize-2-r1-050-qkt2f.18d420e644819f5e,"reason=FailedScheduling count=None msg=0/6 nodes are available: 6 node(s) had untolerated taint(s). no new claims to deallocate, preemption: 0/6 nodes are available: 6 Preemption is not helpful for scheduling."
50.0425,TaskRequest,MODIFIED,eval-sanitize-2-r1-050,phase=Scheduled job=None
50.0461,Job,MODIFIED,eval-sanitize-2-r1-049,
50.7728,Pod,MODIFIED,eval-sanitize-2-r1-039-thkjq,phase=Running node=kind-worker3
50.7737,Job,MODIFIED,eval-sanitize-2-r1-032,
50.7794,Pod,MODIFIED,eval-sanitize-2-r1-038-f2884,phase=Running node=kind-worker3
50.7802,Job,MODIFIED,eval-sanitize-2-r1-035,
50.7834,Job,MODIFIED,eval-sanitize-2-r1-032,
50.7868,Pod,MODIFIED,eval-sanitize-2-r1-040-8rcmf,phase=Running node=kind-worker3
50.7892,Job,MODIFIED,eval-sanitize-2-r1-035,
50.8654,Pod,MODIFIED,eval-sanitize-2-r1-035-7rwtd,phase=Succeeded node=kind-worker3
50.9131,Pod,MODIFIED,eval-sanitize-2-r1-032-cjptq,phase=Succeeded node=kind-worker3
51.0073,TaskRequest,ADDED,eval-sanitize-2-r1-051,phase=None job=None
51.0122,TaskRequest,MODIFIED,eval-sanitize-2-r1-051,phase=Pending job=None
51.0267,Job,ADDED,eval-sanitize-2-r1-051,
51.0307,TaskRequest,MODIFIED,eval-sanitize-2-r1-051,phase=Scheduled job=None
51.0325,Pod,ADDED,eval-sanitize-2-r1-051-2k9qx,phase=Pending node=None
51.0354,Job,MODIFIED,eval-sanitize-2-r1-051,
51.0376,Event,ADDED,eval-sanitize-2-r1-051.18d420e67fc59d58,reason=SuccessfulCreate count=1 msg=Created pod: eval-sanitize-2-r1-051-2k9qx
51.0385,Pod,MODIFIED,eval-sanitize-2-r1-051-2k9qx,phase=Pending node=None
51.0406,Event,ADDED,eval-sanitize-2-r1-051-2k9qx.18d420e67fcf051a,"reason=FailedScheduling count=None msg=0/6 nodes are available: 6 node(s) had untolerated taint(s). no new claims to deallocate, preemption: 0/6 nodes are available: 6 Preemption is not helpful for scheduling."
51.0408,TaskRequest,MODIFIED,eval-sanitize-2-r1-051,phase=Scheduled job=None
51.0415,Job,MODIFIED,eval-sanitize-2-r1-050,
51.0508,Job,MODIFIED,eval-sanitize-2-r1-050,
51.6993,Pod,MODIFIED,eval-sanitize-2-r1-036-qp2wz,phase=Running node=kind-worker2
51.7781,Job,MODIFIED,eval-sanitize-2-r1-039,
51.781,Job,MODIFIED,eval-sanitize-2-r1-032,
51.785,Job,MODIFIED,eval-sanitize-2-r1-038,
51.7879,Job,MODIFIED,eval-sanitize-2-r1-035,
51.7901,Job,MODIFIED,eval-sanitize-2-r1-039,
51.7924,Job,MODIFIED,eval-sanitize-2-r1-040,
51.794,Pod,MODIFIED,eval-sanitize-2-r1-032-cjptq,phase=Succeeded node=kind-worker3
51.7951,Job,MODIFIED,eval-sanitize-2-r1-032,
51.7959,Job,MODIFIED,eval-sanitize-2-r1-038,
51.7989,Pod,MODIFIED,eval-sanitize-2-r1-035-7rwtd,phase=Succeeded node=kind-worker3
51.8002,Job,MODIFIED,eval-sanitize-2-r1-035,
51.804,Job,MODIFIED,eval-sanitize-2-r1-040,
51.9336,Pod,MODIFIED,eval-sanitize-2-r1-038-f2884,phase=Succeeded node=kind-worker3
51.9782,Pod,MODIFIED,eval-sanitize-2-r1-040-8rcmf,phase=Succeeded node=kind-worker3
51.9839,Pod,MODIFIED,eval-sanitize-2-r1-039-thkjq,phase=Succeeded node=kind-worker3
52.0063,TaskRequest,ADDED,eval-sanitize-2-r1-052,phase=None job=None
52.011,TaskRequest,MODIFIED,eval-sanitize-2-r1-052,phase=Pending job=None
52.0246,Job,ADDED,eval-sanitize-2-r1-052,
52.0307,Pod,ADDED,eval-sanitize-2-r1-052-hlv5q,phase=Pending node=None
52.032,TaskRequest,MODIFIED,eval-sanitize-2-r1-052,phase=Scheduled job=None
52.0344,Job,MODIFIED,eval-sanitize-2-r1-052,
52.037,Pod,MODIFIED,eval-sanitize-2-r1-052-hlv5q,phase=Pending node=None
52.0374,Event,ADDED,eval-sanitize-2-r1-052.18d420e6bb4d1e3f,reason=SuccessfulCreate count=1 msg=Created pod: eval-sanitize-2-r1-052-hlv5q
52.0376,Event,ADDED,eval-sanitize-2-r1-052-hlv5q.18d420e6bb505216,"reason=FailedScheduling count=None msg=0/6 nodes are available: 6 node(s) had untolerated taint(s). no new claims to deallocate, preemption: 0/6 nodes are available: 6 Preemption is not helpful for scheduling."
52.0386,Job,MODIFIED,eval-sanitize-2-r1-051,
52.0399,TaskRequest,MODIFIED,eval-sanitize-2-r1-052,phase=Scheduled job=None
52.0469,Job,MODIFIED,eval-sanitize-2-r1-051,
52.3742,Pod,MODIFIED,eval-sanitize-2-r1-041-2kf6h,phase=Running node=kind-worker5
52.38,Pod,MODIFIED,eval-sanitize-2-r1-037-7pl9w,phase=Running node=kind-worker5
52.3857,Pod,MODIFIED,eval-sanitize-2-r1-034-bkxtk,phase=Running node=kind-worker5
52.7042,Job,MODIFIED,eval-sanitize-2-r1-036,
52.7129,Job,MODIFIED,eval-sanitize-2-r1-036,
52.7836,Job,MODIFIED,eval-sanitize-2-r1-039,
52.785,Job,MODIFIED,eval-sanitize-2-r1-032,
52.7894,Job,MODIFIED,eval-sanitize-2-r1-032,
52.7919,Job,MODIFIED,eval-sanitize-2-r1-038,
52.7935,Pod,MODIFIED,eval-sanitize-2-r1-039-thkjq,phase=Succeeded node=kind-worker3
52.7946,Job,MODIFIED,eval-sanitize-2-r1-035,
52.795,Event,ADDED,eval-sanitize-2-r1-032.18d420e6e87e9cf8,reason=Completed count=1 msg=Job completed
52.7957,Job,MODIFIED,eval-sanitize-2-r1-039,
52.7993,Job,MODIFIED,eval-sanitize-2-r1-035,
52.8006,Job,MODIFIED,eval-sanitize-2-r1-040,
52.8016,Job,MODIFIED,eval-sanitize-2-r1-038,
52.8035,Pod,MODIFIED,eval-sanitize-2-r1-038-f2884,phase=Succeeded node=kind-worker3
52.8039,Event,ADDED,eval-sanitize-2-r1-035.18d420e6e91b4f6f,reason=Completed count=1 msg=Job completed
52.8048,Job,MODIFIED,eval-sanitize-2-r1-032,
52.8074,Pod,MODIFIED,eval-sanitize-2-r1-040-8rcmf,phase=Succeeded node=kind-worker3
52.8086,Job,MODIFIED,eval-sanitize-2-r1-040,
52.8107,Job,MODIFIED,eval-sanitize-2-r1-035,
52.8108,TaskRequest,MODIFIED,eval-sanitize-2-r1-032,phase=Complete job=None
52.8572,Pod,MODIFIED,eval-sanitize-2-r1-036-qp2wz,phase=Succeeded node=kind-worker2
52.8589,TaskRequest,MODIFIED,eval-sanitize-2-r1-035,phase=Complete job=None
52.8646,Job,MODIFIED,eval-sanitize-2-r1-032,
52.869,Job,MODIFIED,eval-sanitize-2-r1-035,
53.0077,TaskRequest,ADDED,eval-sanitize-2-r1-053,phase=None job=None
53.011,TaskRequest,MODIFIED,eval-sanitize-2-r1-053,phase=Pending job=None
53.0258,Job,ADDED,eval-sanitize-2-r1-053,
53.0312,Pod,ADDED,eval-sanitize-2-r1-053-plshx,phase=Pending node=None
53.032,TaskRequest,MODIFIED,eval-sanitize-2-r1-053,phase=Scheduled job=None
53.0346,Job,MODIFIED,eval-sanitize-2-r1-053,
53.0365,Event,ADDED,eval-sanitize-2-r1-053.18d420e6f6e6195d,reason=SuccessfulCreate count=1 msg=Created pod: eval-sanitize-2-r1-053-plshx
53.0367,Event,ADDED,eval-sanitize-2-r1-053-plshx.18d420e6f6f167a8,"reason=FailedScheduling count=None msg=0/6 nodes are available: 6 node(s) had untolerated taint(s). no new claims to deallocate, preemption: 0/6 nodes are available: 6 Preemption is not helpful for scheduling."
53.0376,Job,MODIFIED,eval-sanitize-2-r1-052,
53.0384,Pod,MODIFIED,eval-sanitize-2-r1-053-plshx,phase=Pending node=None
53.0393,TaskRequest,MODIFIED,eval-sanitize-2-r1-053,phase=Scheduled job=None
53.0428,Job,MODIFIED,eval-sanitize-2-r1-053,
53.046,Job,MODIFIED,eval-sanitize-2-r1-052,
53.0514,Job,MODIFIED,eval-sanitize-2-r1-053,
53.3807,Job,MODIFIED,eval-sanitize-2-r1-041,
53.3842,Job,MODIFIED,eval-sanitize-2-r1-037,
53.3908,Job,MODIFIED,eval-sanitize-2-r1-034,
53.3936,Job,MODIFIED,eval-sanitize-2-r1-041,
53.3957,Job,MODIFIED,eval-sanitize-2-r1-037,
53.4033,Job,MODIFIED,eval-sanitize-2-r1-034,
53.5501,Pod,MODIFIED,eval-sanitize-2-r1-037-7pl9w,phase=Succeeded node=kind-worker5
53.593,Pod,MODIFIED,eval-sanitize-2-r1-041-2kf6h,phase=Succeeded node=kind-worker5
53.5988,Pod,MODIFIED,eval-sanitize-2-r1-034-bkxtk,phase=Succeeded node=kind-worker5
53.7101,Job,MODIFIED,eval-sanitize-2-r1-036,
53.7182,Pod,MODIFIED,eval-sanitize-2-r1-036-qp2wz,phase=Succeeded node=kind-worker2
53.7196,Job,MODIFIED,eval-sanitize-2-r1-036,
53.8002,Job,MODIFIED,eval-sanitize-2-r1-039,
53.8025,Job,MODIFIED,eval-sanitize-2-r1-038,
53.8049,Job,MODIFIED,eval-sanitize-2-r1-039,
53.8069,Job,MODIFIED,eval-sanitize-2-r1-040,
53.8088,Job,MODIFIED,eval-sanitize-2-r1-038,
53.8103,Event,ADDED,eval-sanitize-2-r1-039.18d420e72509e818,reason=Completed count=1 msg=Job completed
53.8129,Job,MODIFIED,eval-sanitize-2-r1-040,
53.8164,Event,ADDED,eval-sanitize-2-r1-038.18d420e72548324c,reason=Completed count=1 msg=Job completed
53.8172,Job,MODIFIED,eval-sanitize-2-r1-039,
53.8189,Job,MODIFIED,eval-sanitize-2-r1-038,
53.8217,Job,MODIFIED,eval-sanitize-2-r1-040,
53.822,Event,ADDED,eval-sanitize-2-r1-040.18d420e725829bcd,reason=Completed count=1 msg=Job completed
53.8221,TaskRequest,MODIFIED,eval-sanitize-2-r1-039,phase=Complete job=None
53.8274,TaskRequest,MODIFIED,eval-sanitize-2-r1-038,phase=Complete job=None
53.8321,Job,MODIFIED,eval-sanitize-2-r1-039,
53.8333,TaskRequest,MODIFIED,eval-sanitize-2-r1-040,phase=Complete job=None
53.8362,Job,MODIFIED,eval-sanitize-2-r1-038,
53.8415,Job,MODIFIED,eval-sanitize-2-r1-040,
53.8557,Node,MODIFIED,kind-worker2,taints=1
53.8683,Node,MODIFIED,kind-worker2,taints=0
53.8737,Pod,MODIFIED,eval-sanitize-2-r1-046-qpmdw,phase=Pending node=kind-worker2
53.8782,Node,MODIFIED,kind-worker2,taints=0
53.8786,Event,ADDED,eval-sanitize-2-r1-046-qpmdw.18d420e7291f3294,reason=Scheduled count=None msg=Successfully assigned compute/eval-sanitize-2-r1-046-qpmdw to kind-worker2
53.8834,Pod,MODIFIED,eval-sanitize-2-r1-048-6852f,phase=Pending node=kind-worker2
53.8858,Pod,MODIFIED,eval-sanitize-2-r1-049-lmphz,phase=Pending node=None
53.8861,Event,ADDED,eval-sanitize-2-r1-049-lmphz.18d420e7299352ee,"reason=FailedScheduling count=None msg=0/6 nodes are available: 1 c_wall violated: 1 conflicting context pair(s) with node memory, 5 node(s) had untolerated taint(s). no new claims to deallocate, preemption: 0/6 nodes are available: 1 No preemption victims found for incoming pod, 5 Preemption is not helpful for scheduling."
53.889,Event,ADDED,eval-sanitize-2-r1-048-6852f.18d420e729b2d0c0,reason=Scheduled count=None msg=Successfully assigned compute/eval-sanitize-2-r1-048-6852f to kind-worker2
53.8905,Pod,MODIFIED,eval-sanitize-2-r1-046-qpmdw,phase=Pending node=kind-worker2
53.8941,Pod,MODIFIED,eval-sanitize-2-r1-050-qkt2f,phase=Pending node=kind-worker2
53.8995,Pod,MODIFIED,eval-sanitize-2-r1-048-6852f,phase=Pending node=kind-worker2
53.9012,Node,MODIFIED,kind-worker2,taints=0
53.9023,Pod,MODIFIED,eval-sanitize-2-r1-051-2k9qx,phase=Pending node=kind-worker2
53.904,Event,ADDED,eval-sanitize-2-r1-050-qkt2f.18d420e72a5581b3,reason=Scheduled count=None msg=Successfully assigned compute/eval-sanitize-2-r1-050-qkt2f to kind-worker2
53.9049,Pod,MODIFIED,eval-sanitize-2-r1-052-hlv5q,phase=Pending node=kind-worker2
53.9107,Pod,MODIFIED,eval-sanitize-2-r1-050-qkt2f,phase=Pending node=kind-worker2
53.9164,Pod,MODIFIED,eval-sanitize-2-r1-051-2k9qx,phase=Pending node=kind-worker2
53.9219,Pod,MODIFIED,eval-sanitize-2-r1-052-hlv5q,phase=Pending node=kind-worker2
53.945,Pod,MODIFIED,eval-sanitize-2-r1-053-plshx,phase=Pending node=kind-worker2
53.9454,Event,ADDED,eval-sanitize-2-r1-051-2k9qx.18d420e72d052f94,reason=Scheduled count=None msg=Successfully assigned compute/eval-sanitize-2-r1-051-2k9qx to kind-worker2
53.9456,Event,ADDED,eval-sanitize-2-r1-052-hlv5q.18d420e72d023544,reason=Scheduled count=None msg=Successfully assigned compute/eval-sanitize-2-r1-052-hlv5q to kind-worker2
53.9481,Node,MODIFIED,kind-worker2,taints=0
53.9512,Event,ADDED,eval-sanitize-2-r1-053-plshx.18d420e72d5c79ff,reason=Scheduled count=None msg=Successfully assigned compute/eval-sanitize-2-r1-053-plshx to kind-worker2
53.9572,Pod,MODIFIED,eval-sanitize-2-r1-053-plshx,phase=Pending node=kind-worker2
53.9593,Node,MODIFIED,kind-worker2,taints=0
53.9697,Node,MODIFIED,kind-worker2,taints=0
53.9856,Pod,MODIFIED,eval-sanitize-2-r1-049-lmphz,phase=Pending node=None
53.9867,Event,ADDED,eval-sanitize-2-r1-049-lmphz.18d420e72f96ebc3,"reason=FailedScheduling count=None msg=0/6 nodes are available: 1 c_wall violated: 3 conflicting context pair(s) with node memory, 5 node(s) had untolerated taint(s). no new claims to deallocate, preemption: 0/6 nodes are available: 1 No preemption victims found for incoming pod, 5 Preemption is not helpful for scheduling."
53.9904,Node,MODIFIED,kind-worker2,taints=0
53.9942,Event,MODIFIED,eval-sanitize-2-r1-049-lmphz.18d420e72f96ebc3,"reason=FailedScheduling count=None msg=0/6 nodes are available: 1 c_wall violated: 3 conflicting context pair(s) with node memory, 5 node(s) had untolerated taint(s). no new claims to deallocate, preemption: 0/6 nodes are available: 1 No preemption victims found for incoming pod, 5 Preemption is not helpful for scheduling."
53.9971,Event,ADDED,eval-sanitize-2-r1-049-lmphz.18d420e73051aaa1,"reason=FailedScheduling count=None msg=0/6 nodes are available: 1 c_wall violated: 3 conflicting context pair(s) with node memory, 5 node(s) had untolerated taint(s). no new claims to deallocate, preemption: 0/6 nodes are available: 1 No preemption victims found for incoming pod, 5 Preemption is not helpful for scheduling."
54.0058,TaskRequest,ADDED,eval-sanitize-2-r1-054,phase=None job=None
54.0103,TaskRequest,MODIFIED,eval-sanitize-2-r1-054,phase=Pending job=None
54.0248,Job,ADDED,eval-sanitize-2-r1-054,
54.031,Pod,ADDED,eval-sanitize-2-r1-054-w4wn7,phase=Pending node=None
54.0312,TaskRequest,MODIFIED,eval-sanitize-2-r1-054,phase=Scheduled job=None
54.0333,Job,MODIFIED,eval-sanitize-2-r1-054,
54.0359,Event,ADDED,eval-sanitize-2-r1-054.18d420e7327d5f9e,reason=SuccessfulCreate count=1 msg=Created pod: eval-sanitize-2-r1-054-w4wn7
54.0391,Pod,MODIFIED,eval-sanitize-2-r1-054-w4wn7,phase=Pending node=None
54.0394,Event,ADDED,eval-sanitize-2-r1-054-w4wn7.18d420e732b7d092,"reason=FailedScheduling count=None msg=0/6 nodes are available: 1 c_wall violated: 2 conflicting context pair(s) with node memory, 5 node(s) had untolerated taint(s). no new claims to deallocate, preemption: 0/6 nodes are available: 1 No preemption victims found for incoming pod, 5 Preemption is not helpful for scheduling."
54.0395,TaskRequest,MODIFIED,eval-sanitize-2-r1-054,phase=Scheduled job=None
54.0463,Event,ADDED,eval-sanitize-2-r1-054-w4wn7.18d420e7332c02a3,"reason=FailedScheduling count=None msg=0/6 nodes are available: 1 c_wall violated: 2 conflicting context pair(s) with node memory, 5 node(s) had untolerated taint(s). no new claims to deallocate, preemption: 0/6 nodes are available: 1 No preemption victims found for incoming pod, 5 Preemption is not helpful for scheduling."
54.1514,Node,MODIFIED,kind-worker3,taints=1
54.1537,Node,MODIFIED,kind-worker2,taints=0
54.1613,Event,MODIFIED,eval-sanitize-2-r1-049-lmphz.18d420e73051aaa1,"reason=FailedScheduling count=None msg=0/6 nodes are available: 1 c_wall violated: 3 conflicting context pair(s) with node memory, 5 node(s) had untolerated taint(s). no new claims to deallocate, preemption: 0/6 nodes are available: 1 No preemption victims found for incoming pod, 5 Preemption is not helpful for scheduling."
54.1658,Event,MODIFIED,eval-sanitize-2-r1-054-w4wn7.18d420e7332c02a3,"reason=FailedScheduling count=None msg=0/6 nodes are available: 1 c_wall violated: 2 conflicting context pair(s) with node memory, 5 node(s) had untolerated taint(s). no new claims to deallocate, preemption: 0/6 nodes are available: 1 No preemption victims found for incoming pod, 5 Preemption is not helpful for scheduling."
54.2562,Node,MODIFIED,kind-worker3,taints=0
54.2578,Node,MODIFIED,kind-worker2,taints=0
54.2665,Node,MODIFIED,kind-worker3,taints=0
54.2695,Pod,MODIFIED,eval-sanitize-2-r1-054-w4wn7,phase=Pending node=kind-worker3
54.2744,Event,ADDED,eval-sanitize-2-r1-054-w4wn7.18d420e740abe13e,reason=Scheduled count=None msg=Successfully assigned compute/eval-sanitize-2-r1-054-w4wn7 to kind-worker3
54.2798,Pod,MODIFIED,eval-sanitize-2-r1-049-lmphz,phase=Pending node=None
54.2844,Node,MODIFIED,kind-worker3,taints=0
54.2867,Pod,MODIFIED,eval-sanitize-2-r1-054-w4wn7,phase=Pending node=kind-worker3
54.3551,Event,ADDED,eval-sanitize-2-r1-051-2k9qx.18d420e745873ca2,"reason=Pulled count=1 msg=Container image ""busybox:musl"" already present on machine"
54.3557,Event,ADDED,eval-sanitize-2-r1-049-lmphz.18d420e745a33cb4,"reason=FailedScheduling count=None msg=0/6 nodes are available: 1 c_wall violated: 1 conflicting context pair(s) with node memory, 1 c_wall violated: 3 conflicting context pair(s) with node memory, 4 node(s) had untolerated taint(s). no new claims to deallocate, preemption: 0/6 nodes are available: 2 No preemption victims found for incoming pod, 4 Preemption is not helpful for scheduling."
54.361,Event,ADDED,eval-sanitize-2-r1-052-hlv5q.18d420e745a04de1,"reason=Pulled count=1 msg=Container image ""busybox:musl"" already present on machine"
54.3721,Event,ADDED,eval-sanitize-2-r1-053-plshx.18d420e7468d13ff,"reason=Pulled count=1 msg=Container image ""busybox:musl"" already present on machine"
54.3917,Job,MODIFIED,eval-sanitize-2-r1-041,
54.397,Job,MODIFIED,eval-sanitize-2-r1-037,
54.3983,Event,ADDED,eval-sanitize-2-r1-051-2k9qx.18d420e747d2f5d1,reason=Created count=1 msg=Created container: task
54.4,Job,MODIFIED,eval-sanitize-2-r1-034,
54.4046,Pod,MODIFIED,eval-sanitize-2-r1-041-2kf6h,phase=Succeeded node=kind-worker5
54.4114,Event,ADDED,eval-sanitize-2-r1-052-hlv5q.18d420e7482404d0,reason=Created count=1 msg=Created container: task
54.4124,Job,MODIFIED,eval-sanitize-2-r1-041,
54.4161,Job,MODIFIED,eval-sanitize-2-r1-037,
54.4179,Pod,MODIFIED,eval-sanitize-2-r1-037-7pl9w,phase=Succeeded node=kind-worker5
54.4183,Event,ADDED,eval-sanitize-2-r1-046-qpmdw.18d420e748493950,"reason=Pulled count=1 msg=Container image ""busybox:musl"" already present on machine"
54.4193,Job,MODIFIED,eval-sanitize-2-r1-034,
54.4206,Pod,MODIFIED,eval-sanitize-2-r1-034-bkxtk,phase=Succeeded node=kind-worker5
54.4227,Event,ADDED,eval-sanitize-2-r1-048-6852f.18d420e748776f5f,"reason=Pulled count=1 msg=Container image ""busybox:musl"" already present on machine"
54.4268,Event,ADDED,eval-sanitize-2-r1-050-qkt2f.18d420e7489b6683,"reason=Pulled count=1 msg=Container image ""busybox:musl"" already present on machine"
54.4331,Event,ADDED,eval-sanitize-2-r1-053-plshx.18d420e74a49159e,reason=Created count=1 msg=Created container: task
54.4448,Event,ADDED,eval-sanitize-2-r1-046-qpmdw.18d420e74acd7452,reason=Created count=1 msg=Created container: task
54.4533,Event,ADDED,eval-sanitize-2-r1-048-6852f.18d420e74b65b5dd,reason=Created count=1 msg=Created container: task
54.4586,Event,ADDED,eval-sanitize-2-r1-050-qkt2f.18d420e74b99a428,reason=Created count=1 msg=Created container: task
54.4662,Pod,MODIFIED,eval-sanitize-2-r1-043-qdbxg,phase=Running node=kind-worker
54.4681,Node,MODIFIED,kind-worker3,taints=0
54.4818,Pod,MODIFIED,eval-sanitize-2-r1-042-9wtgn,phase=Running node=kind-worker
54.4857,Event,MODIFIED,eval-sanitize-2-r1-049-lmphz.18d420e745a33cb4,"reason=FailedScheduling count=None msg=0/6 nodes are available: 1 c_wall violated: 1 conflicting context pair(s) with node memory, 1 c_wall violated: 3 conflicting context pair(s) with node memory, 4 node(s) had untolerated taint(s). no new claims to deallocate, preemption: 0/6 nodes are available: 2 No preemption victims found for incoming pod, 4 Preemption is not helpful for scheduling."
54.4863,Event,ADDED,eval-sanitize-2-r1-052-hlv5q.18d420e74cfd6d26,reason=Started count=1 msg=Started container task
54.4914,Event,ADDED,eval-sanitize-2-r1-051-2k9qx.18d420e74cfdc2c7,reason=Started count=1 msg=Started container task
54.4956,Event,ADDED,eval-sanitize-2-r1-053-plshx.18d420e74dcc9bfc,reason=Started count=1 msg=Started container task
54.5006,Event,ADDED,eval-sanitize-2-r1-046-qpmdw.18d420e74dfb1136,reason=Started count=1 msg=Started container task
54.5043,Event,ADDED,eval-sanitize-2-r1-048-6852f.18d420e74e722149,reason=Started count=1 msg=Started container task
54.5076,Event,ADDED,eval-sanitize-2-r1-050-qkt2f.18d420e74eaca93a,reason=Started count=1 msg=Started container task
54.5472,Node,MODIFIED,kind-worker3,taints=0
54.7044,Event,ADDED,eval-sanitize-2-r1-054-w4wn7.18d420e75a635f59,"reason=Pulled count=1 msg=Container image ""busybox:musl"" already present on machine"
54.7083,Pod,MODIFIED,eval-sanitize-2-r1-048-6852f,phase=Running node=kind-worker2
54.7151,Pod,MODIFIED,eval-sanitize-2-r1-050-qkt2f,phase=Running node=kind-worker2
54.7196,Job,MODIFIED,eval-sanitize-2-r1-036,
54.7245,Job,MODIFIED,eval-sanitize-2-r1-036,
54.7296,Pod,MODIFIED,eval-sanitize-2-r1-046-qpmdw,phase=Running node=kind-worker2
54.73,Event,ADDED,eval-sanitize-2-r1-054-w4wn7.18d420e75bb51dc1,reason=Created count=1 msg=Created container: task
54.7303,Event,ADDED,eval-sanitize-2-r1-036.18d420e75bd9d38b,reason=Completed count=1 msg=Job completed
54.7367,Pod,MODIFIED,eval-sanitize-2-r1-051-2k9qx,phase=Running node=kind-worker2
54.7379,Job,MODIFIED,eval-sanitize-2-r1-036,
54.7433,Pod,MODIFIED,eval-sanitize-2-r1-052-hlv5q,phase=Running node=kind-worker2
54.7434,TaskRequest,MODIFIED,eval-sanitize-2-r1-036,phase=Complete job=None
54.7496,Pod,MODIFIED,eval-sanitize-2-r1-053-plshx,phase=Running node=kind-worker2
54.7523,Job,MODIFIED,eval-sanitize-2-r1-036,
54.8111,Event,ADDED,eval-sanitize-2-r1-054-w4wn7.18d420e760c4abb2,reason=Started count=1 msg=Started container task
54.8792,Job,MODIFIED,eval-sanitize-2-r1-046,
54.8886,Job,MODIFIED,eval-sanitize-2-r1-046,
54.89,Job,MODIFIED,eval-sanitize-2-r1-048,
54.8983,Job,MODIFIED,eval-sanitize-2-r1-050,
54.9001,Job,MODIFIED,eval-sanitize-2-r1-048,
54.905,Job,MODIFIED,eval-sanitize-2-r1-051,
54.9075,Job,MODIFIED,eval-sanitize-2-r1-050,
54.9128,Job,MODIFIED,eval-sanitize-2-r1-051,
55.0066,TaskRequest,ADDED,eval-sanitize-2-r1-055,phase=None job=None
55.0101,TaskRequest,MODIFIED,eval-sanitize-2-r1-055,phase=Pending job=None
55.0269,Job,ADDED,eval-sanitize-2-r1-055,
55.0312,TaskRequest,MODIFIED,eval-sanitize-2-r1-055,phase=Scheduled job=None
55.033,Pod,ADDED,eval-sanitize-2-r1-055-nz9p5,phase=Pending node=None
55.0352,Job,MODIFIED,eval-sanitize-2-r1-054,
55.0369,Job,MODIFIED,eval-sanitize-2-r1-055,
55.0373,Event,ADDED,eval-sanitize-2-r1-055.18d420e76e3bd087,reason=SuccessfulCreate count=1 msg=Created pod: eval-sanitize-2-r1-055-nz9p5
55.0382,TaskRequest,MODIFIED,eval-sanitize-2-r1-055,phase=Scheduled job=None
55.0436,Job,MODIFIED,eval-sanitize-2-r1-054,
55.0445,Pod,MODIFIED,eval-sanitize-2-r1-055-nz9p5,phase=Pending node=kind-worker3
55.0503,Event,ADDED,eval-sanitize-2-r1-055-nz9p5.18d420e76eeac9c3,reason=Scheduled count=None msg=Successfully assigned compute/eval-sanitize-2-r1-055-nz9p5 to kind-worker3
55.0561,Pod,MODIFIED,eval-sanitize-2-r1-055-nz9p5,phase=Pending node=kind-worker3
55.3979,Job,MODIFIED,eval-sanitize-2-r1-041,
55.4024,Job,MODIFIED,eval-sanitize-2-r1-041,
55.4049,Job,MODIFIED,eval-sanitize-2-r1-037,
55.4053,Event,ADDED,eval-sanitize-2-r1-041.18d420e7843cd616,reason=Completed count=1 msg=Job completed
55.406,Job,MODIFIED,eval-sanitize-2-r1-034,
55.4101,Job,MODIFIED,eval-sanitize-2-r1-034,
55.4111,Job,MODIFIED,eval-sanitize-2-r1-037,
55.4147,Job,MODIFIED,eval-sanitize-2-r1-041,
55.4155,Event,ADDED,eval-sanitize-2-r1-034.18d420e784bbc6be,reason=Completed count=1 msg=Job completed
55.4202,TaskRequest,MODIFIED,eval-sanitize-2-r1-041,phase=Complete job=None
55.4207,Event,ADDED,eval-sanitize-2-r1-037.18d420e784bc26d4,reason=Completed count=1 msg=Job completed
55.4236,Job,MODIFIED,eval-sanitize-2-r1-037,
55.4246,Job,MODIFIED,eval-sanitize-2-r1-034,
55.4301,Job,MODIFIED,eval-sanitize-2-r1-041,
55.4335,TaskRequest,MODIFIED,eval-sanitize-2-r1-037,phase=Complete job=None
55.4366,TaskRequest,MODIFIED,eval-sanitize-2-r1-034,phase=Complete job=None
55.4424,Job,MODIFIED,eval-sanitize-2-r1-037,
55.4448,Job,MODIFIED,eval-sanitize-2-r1-034,
55.4725,Job,MODIFIED,eval-sanitize-2-r1-043,
55.4741,Event,ADDED,eval-sanitize-2-r1-055-nz9p5.18d420e7883f8ab2,"reason=Pulled count=1 msg=Container image ""busybox:musl"" already present on machine"
55.4824,Job,MODIFIED,eval-sanitize-2-r1-043,
55.4888,Job,MODIFIED,eval-sanitize-2-r1-042,
55.4956,Event,ADDED,eval-sanitize-2-r1-055-nz9p5.18d420e7898dec08,reason=Created count=1 msg=Created container: task
55.5317,Job,MODIFIED,eval-sanitize-2-r1-042,
55.557,Event,ADDED,eval-sanitize-2-r1-055-nz9p5.18d420e78d2579d6,reason=Started count=1 msg=Started container task
55.6293,Pod,MODIFIED,eval-sanitize-2-r1-042-9wtgn,phase=Succeeded node=kind-worker
55.6651,Pod,MODIFIED,eval-sanitize-2-r1-043-qdbxg,phase=Succeeded node=kind-worker
55.7478,Job,MODIFIED,eval-sanitize-2-r1-052,
55.7542,Job,MODIFIED,eval-sanitize-2-r1-053,
55.7565,Job,MODIFIED,eval-sanitize-2-r1-052,
55.7624,Job,MODIFIED,eval-sanitize-2-r1-053,
55.794,Pod,MODIFIED,eval-sanitize-2-r1-054-w4wn7,phase=Running node=kind-worker3
55.8002,Pod,MODIFIED,eval-sanitize-2-r1-055-nz9p5,phase=Running node=kind-worker3
55.8486,Node,MODIFIED,kind-worker5,taints=1
55.8606,Node,MODIFIED,kind-worker5,taints=1
55.8695,Node,MODIFIED,kind-worker5,taints=0
55.8837,Pod,MODIFIED,eval-sanitize-2-r1-049-lmphz,phase=Pending node=kind-worker5
55.8872,Event,ADDED,eval-sanitize-2-r1-049-lmphz.18d420e7a0eb4cab,reason=Scheduled count=None msg=Successfully assigned compute/eval-sanitize-2-r1-049-lmphz to kind-worker5
55.8928,Node,MODIFIED,kind-worker5,taints=0
55.8945,Pod,MODIFIED,eval-sanitize-2-r1-049-lmphz,phase=Pending node=kind-worker5
55.944,Node,MODIFIED,kind-worker5,taints=0
55.955,Node,MODIFIED,kind-worker2,taints=1
55.9581,Node,MODIFIED,kind-worker5,taints=0
55.9683,Node,MODIFIED,kind-worker2,taints=1
56.0072,TaskRequest,ADDED,eval-sanitize-2-r1-056,phase=None job=None
56.011,TaskRequest,MODIFIED,eval-sanitize-2-r1-056,phase=Pending job=None
56.0383,Job,MODIFIED,eval-sanitize-2-r1-055,
56.04,Job,MODIFIED,eval-sanitize-2-r1-054,
56.1408,Job,ADDED,eval-sanitize-2-r1-056,
56.1469,Pod,ADDED,eval-sanitize-2-r1-056-kmcc9,phase=Pending node=None
56.1521,Job,MODIFIED,eval-sanitize-2-r1-056,
56.1525,Event,ADDED,eval-sanitize-2-r1-056.18d420e7b09e8a34,reason=SuccessfulCreate count=1 msg=Created pod: eval-sanitize-2-r1-056-kmcc9
56.1578,Pod,MODIFIED,eval-sanitize-2-r1-056-kmcc9,phase=Pending node=None
56.1589,Event,ADDED,eval-sanitize-2-r1-056-kmcc9.18d420e7b10626fe,"reason=FailedScheduling count=None msg=0/6 nodes are available: 2 c_wall violated: 1 conflicting context pair(s) with node memory, 4 node(s) had untolerated taint(s). no new claims to deallocate, preemption: 0/6 nodes are available: 2 No preemption victims found for incoming pod, 4 Preemption is not helpful for scheduling."
56.1601,TaskRequest,MODIFIED,eval-sanitize-2-r1-056,phase=Scheduled job=None
56.165,Job,MODIFIED,eval-sanitize-2-r1-056,
56.1686,Event,ADDED,eval-sanitize-2-r1-056-kmcc9.18d420e7b1a6c949,"reason=FailedScheduling count=None msg=0/6 nodes are available: 2 c_wall violated: 1 conflicting context pair(s) with node memory, 4 node(s) had untolerated taint(s). no new claims to deallocate, preemption: 0/6 nodes are available: 2 No preemption victims found for incoming pod, 4 Preemption is not helpful for scheduling."
56.2291,TaskRequest,MODIFIED,eval-sanitize-2-r1-056,phase=Scheduled job=None
56.2318,Job,MODIFIED,eval-sanitize-2-r1-054,
56.2327,Job,MODIFIED,eval-sanitize-2-r1-055,
56.2336,Job,MODIFIED,eval-sanitize-2-r1-056,
56.3111,Event,ADDED,eval-sanitize-2-r1-049-lmphz.18d420e7ba28a712,"reason=Pulled count=1 msg=Container image ""busybox:musl"" already present on machine"
56.3287,Event,ADDED,eval-sanitize-2-r1-049-lmphz.18d420e7bb2fda6c,reason=Created count=1 msg=Created container: task
56.3605,Event,ADDED,eval-sanitize-2-r1-049-lmphz.18d420e7bd1f8794,reason=Started count=1 msg=Started container task
56.3901,Pod,MODIFIED,eval-sanitize-2-r1-049-lmphz,phase=Running node=kind-worker5
56.4,Event,MODIFIED,eval-sanitize-2-r1-056-kmcc9.18d420e7b1a6c949,"reason=FailedScheduling count=None msg=0/6 nodes are available: 2 c_wall violated: 1 conflicting context pair(s) with node memory, 4 node(s) had untolerated taint(s). no new claims to deallocate, preemption: 0/6 nodes are available: 2 No preemption victims found for incoming pod, 4 Preemption is not helpful for scheduling."
56.4577,Node,MODIFIED,kind-worker3,taints=1
56.466,Pod,MODIFIED,eval-sanitize-2-r1-056-kmcc9,phase=Pending node=None
56.471,Node,MODIFIED,kind-worker3,taints=1
56.4725,Event,ADDED,eval-sanitize-2-r1-056-kmcc9.18d420e7c3cf84ca,"reason=FailedScheduling count=None msg=0/6 nodes are available: 1 c_wall violated: 1 conflicting context pair(s) with node memory, 5 node(s) had untolerated taint(s). no new claims to deallocate, preemption: 0/6 nodes are available: 1 No preemption victims found for incoming pod, 5 Preemption is not helpful for scheduling."
56.4768,Job,MODIFIED,eval-sanitize-2-r1-043,
56.4793,Event,MODIFIED,eval-sanitize-2-r1-056-kmcc9.18d420e7c3cf84ca,"reason=FailedScheduling count=None msg=0/6 nodes are available: 1 c_wall violated: 1 conflicting context pair(s) with node memory, 5 node(s) had untolerated taint(s). no new claims to deallocate, preemption: 0/6 nodes are available: 1 No preemption victims found for incoming pod, 5 Preemption is not helpful for scheduling."
56.4848,Pod,MODIFIED,eval-sanitize-2-r1-043-qdbxg,phase=Succeeded node=kind-worker
56.4862,Job,MODIFIED,eval-sanitize-2-r1-043,
56.4924,Job,MODIFIED,eval-sanitize-2-r1-042,
56.4999,Pod,MODIFIED,eval-sanitize-2-r1-042-9wtgn,phase=Succeeded node=kind-worker
56.5023,Job,MODIFIED,eval-sanitize-2-r1-042,
56.7588,Node,MODIFIED,kind-worker,taints=1
56.8889,Job,MODIFIED,eval-sanitize-2-r1-049,
56.8975,Job,MODIFIED,eval-sanitize-2-r1-049,
56.943,Node,MODIFIED,kind-worker,taints=0
56.9516,Pod,MODIFIED,eval-sanitize-2-r1-056-kmcc9,phase=Pending node=kind-worker
56.9575,Node,MODIFIED,kind-worker,taints=0
56.9584,Event,ADDED,eval-sanitize-2-r1-056-kmcc9.18d420e7e090ecd7,reason=Scheduled count=None msg=Successfully assigned compute/eval-sanitize-2-r1-056-kmcc9 to kind-worker
56.9634,Pod,MODIFIED,eval-sanitize-2-r1-056-kmcc9,phase=Pending node=kind-worker
56.9678,Node,MODIFIED,kind-worker,taints=0
56.9834,Node,MODIFIED,kind-worker,taints=0
56.993,Node,MODIFIED,kind-worker,taints=0
57.0059,TaskRequest,ADDED,eval-sanitize-2-r1-057,phase=None job=None
57.011,TaskRequest,MODIFIED,eval-sanitize-2-r1-057,phase=Pending job=None
57.0253,Job,ADDED,eval-sanitize-2-r1-057,
57.0304,TaskRequest,MODIFIED,eval-sanitize-2-r1-057,phase=Scheduled job=None
57.0324,Pod,ADDED,eval-sanitize-2-r1-057-n6fs2,phase=Pending node=None
57.0339,Job,MODIFIED,eval-sanitize-2-r1-057,
57.036,Event,ADDED,eval-sanitize-2-r1-057.18d420e7e5647bdc,reason=SuccessfulCreate count=1 msg=Created pod: eval-sanitize-2-r1-057-n6fs2
57.0369,TaskRequest,MODIFIED,eval-sanitize-2-r1-057,phase=Scheduled job=None
57.0442,Pod,MODIFIED,eval-sanitize-2-r1-057-n6fs2,phase=Pending node=kind-worker
57.0469,Event,ADDED,eval-sanitize-2-r1-057-n6fs2.18d420e7e6162999,reason=Scheduled count=None msg=Successfully assigned compute/eval-sanitize-2-r1-057-n6fs2 to kind-worker
57.0531,Node,MODIFIED,kind-worker,taints=0
57.0549,Pod,MODIFIED,eval-sanitize-2-r1-057-n6fs2,phase=Pending node=kind-worker
57.063,Node,MODIFIED,kind-worker,taints=0
57.3115,Event,MODIFIED,eval-sanitize-2-r1-046-qpmdw.18d420e563df1546,"reason=FailedScheduling count=None msg=0/6 nodes are available: 1 c_wall violated: 1 conflicting context pair(s) with node memory, 5 node(s) had untolerated taint(s). no new claims to deallocate, preemption: 0/6 nodes are available: 1 No preemption victims found for incoming pod, 5 Preemption is not helpful for scheduling."
57.3676,Pod,MODIFIED,eval-sanitize-2-r1-045-ph5q2,phase=Running node=kind-worker4
57.3745,Pod,MODIFIED,eval-sanitize-2-r1-044-nh4hg,phase=Running node=kind-worker4
57.3801,Event,ADDED,eval-sanitize-2-r1-056-kmcc9.18d420e7f9e7a31d,"reason=Pulled count=1 msg=Container image ""busybox:musl"" already present on machine"
57.403,Event,ADDED,eval-sanitize-2-r1-056-kmcc9.18d420e7fb32f221,reason=Created count=1 msg=Created container: task
57.4373,Event,ADDED,eval-sanitize-2-r1-056-kmcc9.18d420e7fd532156,reason=Started count=1 msg=Started container task
57.4524,Event,ADDED,eval-sanitize-2-r1-057-n6fs2.18d420e7fe3e1feb,"reason=Pulled count=1 msg=Container image ""busybox:musl"" already present on machine"
57.4709,Event,ADDED,eval-sanitize-2-r1-057-n6fs2.18d420e7ff401da9,reason=Created count=1 msg=Created container: task
57.477,Pod,MODIFIED,eval-sanitize-2-r1-056-kmcc9,phase=Running node=kind-worker
57.4821,Job,MODIFIED,eval-sanitize-2-r1-043,
57.4868,Job,MODIFIED,eval-sanitize-2-r1-043,
57.4923,Event,ADDED,eval-sanitize-2-r1-043.18d420e8008350af,reason=Completed count=1 msg=Job completed
57.4973,Job,MODIFIED,eval-sanitize-2-r1-042,
57.499,Job,MODIFIED,eval-sanitize-2-r1-043,
57.5012,Job,MODIFIED,eval-sanitize-2-r1-042,
57.503,TaskRequest,MODIFIED,eval-sanitize-2-r1-043,phase=Complete job=None
57.5057,Event,ADDED,eval-sanitize-2-r1-042.18d420e8015e2d02,reason=Completed count=1 msg=Job completed
57.5116,Job,MODIFIED,eval-sanitize-2-r1-042,
57.5135,Job,MODIFIED,eval-sanitize-2-r1-043,
57.5166,TaskRequest,MODIFIED,eval-sanitize-2-r1-042,phase=Complete job=None
57.5258,Job,MODIFIED,eval-sanitize-2-r1-042,
57.5588,Event,ADDED,eval-sanitize-2-r1-057-n6fs2.18d420e8048c66e1,reason=Started count=1 msg=Started container task
57.9524,Node,MODIFIED,kind-worker5,taints=1
57.9651,Node,MODIFIED,kind-worker5,taints=1
58.0076,TaskRequest,ADDED,eval-sanitize-2-r1-058,phase=None job=None
58.0123,TaskRequest,MODIFIED,eval-sanitize-2-r1-058,phase=Pending job=None
58.0279,Job,ADDED,eval-sanitize-2-r1-058,
58.0343,Pod,ADDED,eval-sanitize-2-r1-058-6nf7f,phase=Pending node=None
58.0359,TaskRequest,MODIFIED,eval-sanitize-2-r1-058,phase=Scheduled job=None
58.0367,Job,MODIFIED,eval-sanitize-2-r1-058,
58.0405,Job,MODIFIED,eval-sanitize-2-r1-057,
58.0408,Event,ADDED,eval-sanitize-2-r1-058.18d420e8211bd7a8,reason=SuccessfulCreate count=1 msg=Created pod: eval-sanitize-2-r1-058-6nf7f
58.044,Pod,MODIFIED,eval-sanitize-2-r1-058-6nf7f,phase=Pending node=kind-worker
58.0443,TaskRequest,MODIFIED,eval-sanitize-2-r1-058,phase=Scheduled job=None
58.0487,Event,ADDED,eval-sanitize-2-r1-058-6nf7f.18d420e821ae49ad,reason=Scheduled count=None msg=Successfully assigned compute/eval-sanitize-2-r1-058-6nf7f to kind-worker
58.0515,Job,MODIFIED,eval-sanitize-2-r1-057,
58.0556,Node,MODIFIED,kind-worker,taints=0
58.0569,Pod,MODIFIED,eval-sanitize-2-r1-058-6nf7f,phase=Pending node=kind-worker
58.1469,Node,MODIFIED,kind-worker,taints=0
58.3711,Pod,MODIFIED,eval-sanitize-2-r1-047-v644x,phase=Running node=kind-worker4
58.3739,Job,MODIFIED,eval-sanitize-2-r1-045,
58.3801,Job,MODIFIED,eval-sanitize-2-r1-044,
58.384,Job,MODIFIED,eval-sanitize-2-r1-045,
58.39,Job,MODIFIED,eval-sanitize-2-r1-044,
58.4833,Pod,MODIFIED,eval-sanitize-2-r1-057-n6fs2,phase=Running node=kind-worker
58.485,Job,MODIFIED,eval-sanitize-2-r1-056,
58.486,Event,ADDED,eval-sanitize-2-r1-058-6nf7f.18d420e83bd90139,"reason=Pulled count=1 msg=Container image ""busybox:musl"" already present on machine"
58.4951,Job,MODIFIED,eval-sanitize-2-r1-056,
58.5077,Event,ADDED,eval-sanitize-2-r1-058-6nf7f.18d420e83d0b9408,reason=Created count=1 msg=Created container: task
58.5177,Pod,MODIFIED,eval-sanitize-2-r1-044-nh4hg,phase=Succeeded node=kind-worker4
58.5644,Pod,MODIFIED,eval-sanitize-2-r1-045-ph5q2,phase=Succeeded node=kind-worker4
58.58,Event,ADDED,eval-sanitize-2-r1-058-6nf7f.18d420e841767da8,reason=Started count=1 msg=Started container task
58.9672,Node,MODIFIED,kind-worker,taints=1
59.022,TaskRequest,ADDED,eval-sanitize-2-r1-059,phase=None job=None
59.0253,TaskRequest,MODIFIED,eval-sanitize-2-r1-059,phase=Pending job=None
59.0394,Job,MODIFIED,eval-sanitize-2-r1-058,
59.0409,Job,ADDED,eval-sanitize-2-r1-059,
59.0452,Job,MODIFIED,eval-sanitize-2-r1-057,
59.0479,Pod,ADDED,eval-sanitize-2-r1-059-j7flz,phase=Pending node=None
59.0493,Job,MODIFIED,eval-sanitize-2-r1-059,
59.0494,TaskRequest,MODIFIED,eval-sanitize-2-r1-059,phase=Scheduled job=None
59.0536,Node,MODIFIED,kind-worker,taints=1
59.054,Event,ADDED,eval-sanitize-2-r1-059.18d420e85d88a940,reason=SuccessfulCreate count=1 msg=Created pod: eval-sanitize-2-r1-059-j7flz
59.0543,Event,ADDED,eval-sanitize-2-r1-059-j7flz.18d420e85d9395fb,"reason=FailedScheduling count=None msg=0/6 nodes are available: 6 node(s) had untolerated taint(s). no new claims to deallocate, preemption: 0/6 nodes are available: 6 Preemption is not helpful for scheduling."
59.0559,Pod,MODIFIED,eval-sanitize-2-r1-059-j7flz,phase=Pending node=None
59.0577,TaskRequest,MODIFIED,eval-sanitize-2-r1-059,phase=Scheduled job=None
59.0603,Job,MODIFIED,eval-sanitize-2-r1-058,
59.0622,Job,MODIFIED,eval-sanitize-2-r1-057,
59.3763,Job,MODIFIED,eval-sanitize-2-r1-047,
59.3794,Job,MODIFIED,eval-sanitize-2-r1-045,
59.3849,Job,MODIFIED,eval-sanitize-2-r1-044,
59.3872,Job,MODIFIED,eval-sanitize-2-r1-047,
59.3914,Job,MODIFIED,eval-sanitize-2-r1-045,
59.3933,Pod,MODIFIED,eval-sanitize-2-r1-045-ph5q2,phase=Succeeded node=kind-worker4
59.3947,Pod,MODIFIED,eval-sanitize-2-r1-044-nh4hg,phase=Succeeded node=kind-worker4
59.3967,Job,MODIFIED,eval-sanitize-2-r1-044,
59.4608,Pod,MODIFIED,eval-sanitize-2-r1-047-v644x,phase=Succeeded node=kind-worker4
59.4843,Pod,MODIFIED,eval-sanitize-2-r1-058-6nf7f,phase=Running node=kind-worker
60.0076,TaskRequest,ADDED,eval-sanitize-2-r1-060,phase=None job=None
60.0128,TaskRequest,MODIFIED,eval-sanitize-2-r1-060,phase=Pending job=None
60.0245,Job,ADDED,eval-sanitize-2-r1-000,
60.0247,TaskRequest,ADDED,eval-sanitize-2-r1-000,phase=Complete job=None
60.0279,Node,ADDED,kind-control-plane,taints=1
60.0295,Job,ADDED,eval-sanitize-2-r1-001,
60.03,Event,ADDED,eval-sanitize-2-r1-000-qsvxq.18d420daa393d765,reason=Scheduled count=None msg=Successfully assigned compute/eval-sanitize-2-r1-000-qsvxq to kind-worker5
60.0304,TaskRequest,ADDED,eval-sanitize-2-r1-001,phase=Complete job=None
60.0305,TaskRequest,ADDED,eval-sanitize-2-r1-002,phase=Complete job=None
60.0319,Job,ADDED,eval-sanitize-2-r1-002,
60.0326,Event,ADDED,eval-sanitize-2-r1-000-qsvxq.18d420dabc3f7bd4,"reason=Pulled count=1 msg=Container image ""busybox:musl"" already present on machine"
60.033,Event,ADDED,eval-sanitize-2-r1-000-qsvxq.18d420dabd612dce,reason=Created count=1 msg=Created container: task
60.0335,Event,ADDED,eval-sanitize-2-r1-000-qsvxq.18d420dabf5cc73d,reason=Started count=1 msg=Started container task
60.0339,Event,ADDED,eval-sanitize-2-r1-000.18d420daa268cf0a,reason=SuccessfulCreate count=1 msg=Created pod: eval-sanitize-2-r1-000-qsvxq
60.034,TaskRequest,ADDED,eval-sanitize-2-r1-003,phase=Complete job=None
60.0341,TaskRequest,ADDED,eval-sanitize-2-r1-004,phase=Complete job=None
60.0342,TaskRequest,ADDED,eval-sanitize-2-r1-005,phase=Complete job=None
60.0357,Node,ADDED,kind-worker,taints=1
60.0364,Event,ADDED,eval-sanitize-2-r1-000.18d420ddf17beaf1,reason=Completed count=1 msg=Job completed
60.0366,Event,ADDED,eval-sanitize-2-r1-001-qffv8.18d420dadc8fb516,reason=Scheduled count=None msg=Successfully assigned compute/eval-sanitize-2-r1-001-qffv8 to kind-worker3
60.0368,Event,ADDED,eval-sanitize-2-r1-001-qffv8.18d420daf4f62777,"reason=Pulled count=1 msg=Container image ""busybox:musl"" already present on machine"
60.0371,Event,ADDED,eval-sanitize-2-r1-001-qffv8.18d420daf6044256,reason=Created count=1 msg=Created container: task
60.0385,Pod,ADDED,eval-sanitize-2-r1-000-qsvxq,phase=Succeeded node=kind-worker5
60.0386,TaskRequest,ADDED,eval-sanitize-2-r1-006,phase=Complete job=None
60.0387,TaskRequest,ADDED,eval-sanitize-2-r1-007,phase=Complete job=None
60.0388,TaskRequest,ADDED,eval-sanitize-2-r1-008,phase=Complete job=None
60.0402,Node,ADDED,kind-worker2,taints=1
60.0412,Job,ADDED,eval-sanitize-2-r1-003,
60.0415,Event,ADDED,eval-sanitize-2-r1-001-qffv8.18d420daf99c98ba,reason=Started count=1 msg=Started container task
60.0417,Event,ADDED,eval-sanitize-2-r1-001.18d420dadc00cacf,reason=SuccessfulCreate count=1 msg=Created pod: eval-sanitize-2-r1-001-qffv8
60.0419,Event,ADDED,eval-sanitize-2-r1-001.18d420de0a58380b,reason=Completed count=1 msg=Job completed
60.0422,Event,ADDED,eval-sanitize-2-r1-002-94z5p.18d420db18a5171b,reason=Scheduled count=None msg=Successfully assigned compute/eval-sanitize-2-r1-002-94z5p to kind-worker
60.0425,Event,ADDED,eval-sanitize-2-r1-002-94z5p.18d420db31e850c7,"reason=Pulled count=1 msg=Container image ""busybox:musl"" already present on machine"
60.0429,Event,ADDED,eval-sanitize-2-r1-002-94z5p.18d420db32ef35b4,reason=Created count=1 msg=Created container: task
60.0434,Event,ADDED,eval-sanitize-2-r1-002-94z5p.18d420db35008452,reason=Started count=1 msg=Started container task
60.0435,TaskRequest,ADDED,eval-sanitize-2-r1-009,phase=Complete job=None
60.0437,TaskRequest,ADDED,eval-sanitize-2-r1-010,phase=Complete job=None
60.0438,TaskRequest,ADDED,eval-sanitize-2-r1-011,phase=Complete job=None
60.0438,TaskRequest,ADDED,eval-sanitize-2-r1-012,phase=Complete job=None
60.0438,TaskRequest,ADDED,eval-sanitize-2-r1-013,phase=Complete job=None
60.0453,Pod,ADDED,eval-sanitize-2-r1-001-qffv8,phase=Succeeded node=kind-worker3
60.0456,Event,ADDED,eval-sanitize-2-r1-002.18d420db17afa5db,reason=SuccessfulCreate count=1 msg=Created pod: eval-sanitize-2-r1-002-94z5p
60.0458,Event,ADDED,eval-sanitize-2-r1-002.18d420de6f4cccb7,reason=Completed count=1 msg=Job completed
60.046,Event,ADDED,eval-sanitize-2-r1-003-8q9hg.18d420db53b18b21,reason=Scheduled count=None msg=Successfully assigned compute/eval-sanitize-2-r1-003-8q9hg to kind-worker2
60.0463,Event,ADDED,eval-sanitize-2-r1-003-8q9hg.18d420db6c2fe28d,"reason=Pulled count=1 msg=Container image ""busybox:musl"" already present on machine"
60.0471,Job,ADDED,eval-sanitize-2-r1-004,
60.0483,Node,ADDED,kind-worker3,taints=1
60.0484,TaskRequest,ADDED,eval-sanitize-2-r1-014,phase=Complete job=None
60.0484,TaskRequest,ADDED,eval-sanitize-2-r1-015,phase=Complete job=None
60.0485,TaskRequest,ADDED,eval-sanitize-2-r1-016,phase=Complete job=None
60.0497,Pod,ADDED,eval-sanitize-2-r1-002-94z5p,phase=Succeeded node=kind-worker
60.0502,Event,ADDED,eval-sanitize-2-r1-003-8q9hg.18d420db6d3cb898,reason=Created count=1 msg=Created container: task
60.0504,Event,ADDED,eval-sanitize-2-r1-003-8q9hg.18d420db6f3cff71,reason=Started count=1 msg=Started container task
60.0506,Event,ADDED,eval-sanitize-2-r1-003.18d420db5315c310,reason=SuccessfulCreate count=1 msg=Created pod: eval-sanitize-2-r1-003-8q9hg
60.0508,TaskRequest,ADDED,eval-sanitize-2-r1-017,phase=Complete job=None
60.0508,TaskRequest,ADDED,eval-sanitize-2-r1-018,phase=Complete job=None
60.0513,Event,ADDED,eval-sanitize-2-r1-003.18d420de7c7a8fd4,reason=Completed count=1 msg=Job completed
60.0515,Event,ADDED,eval-sanitize-2-r1-004-lxbfr.18d420db8fa9037c,reason=Scheduled count=None msg=Successfully assigned compute/eval-sanitize-2-r1-004-lxbfr to kind-worker4
60.0516,Event,ADDED,eval-sanitize-2-r1-004-lxbfr.18d420dba78acd00,"reason=Pulled count=1 msg=Container image ""busybox:musl"" already present on machine"
60.0518,Event,ADDED,eval-sanitize-2-r1-004-lxbfr.18d420dba89ec956,reason=Created count=1 msg=Created container: task
60.0533,Node,ADDED,kind-worker4,taints=1
60.0534,TaskRequest,ADDED,eval-sanitize-2-r1-019,phase=Complete job=None
60.0535,TaskRequest,ADDED,eval-sanitize-2-r1-020,phase=Complete job=None
60.0535,TaskRequest,ADDED,eval-sanitize-2-r1-021,phase=Complete job=None
60.0548,Pod,ADDED,eval-sanitize-2-r1-003-8q9hg,phase=Succeeded node=kind-worker2
60.0557,Job,ADDED,eval-sanitize-2-r1-005,
60.0564,Job,ADDED,eval-sanitize-2-r1-006,
60.0565,TaskRequest,ADDED,eval-sanitize-2-r1-022,phase=Complete job=None
60.0565,TaskRequest,ADDED,eval-sanitize-2-r1-023,phase=Complete job=None
60.0577,Pod,ADDED,eval-sanitize-2-r1-004-lxbfr,phase=Succeeded node=kind-worker4
60.0582,Event,ADDED,eval-sanitize-2-r1-004-lxbfr.18d420dbaa92345b,reason=Started count=1 msg=Started container task
60.0585,Event,ADDED,eval-sanitize-2-r1-004.18d420db8ee83c46,reason=SuccessfulCreate count=1 msg=Created pod: eval-sanitize-2-r1-004-lxbfr
60.0587,Event,ADDED,eval-sanitize-2-r1-004.18d420dee01d4d08,reason=Completed count=1 msg=Job completed
60.059,Event,ADDED,eval-sanitize-2-r1-005-rng6l.18d420dbca7be0b3,"reason=FailedScheduling count=None msg=0/6 nodes are available: 6 node(s) had untolerated taint(s). no new claims to deallocate, preemption: 0/6 nodes are available: 6 Preemption is not helpful for scheduling."
60.0594,Event,ADDED,eval-sanitize-2-r1-005-rng6l.18d420ddaea7d16c,reason=Scheduled count=None msg=Successfully assigned compute/eval-sanitize-2-r1-005-rng6l to kind-worker5
60.0597,Event,ADDED,eval-sanitize-2-r1-005-rng6l.18d420ddca758ad5,"reason=Pulled count=1 msg=Container image ""busybox:musl"" already present on machine"
60.06,Event,ADDED,eval-sanitize-2-r1-005-rng6l.18d420ddcca3c65c,reason=Created count=1 msg=Created container: task
60.0601,TaskRequest,ADDED,eval-sanitize-2-r1-024,phase=Complete job=None
60.0602,TaskRequest,ADDED,eval-sanitize-2-r1-025,phase=Complete job=None
60.0602,TaskRequest,ADDED,eval-sanitize-2-r1-026,phase=Complete job=None
60.0614,Pod,ADDED,eval-sanitize-2-r1-005-rng6l,phase=Succeeded node=kind-worker5
60.0625,Pod,ADDED,eval-sanitize-2-r1-006-srhbl,phase=Succeeded node=kind-worker3
60.0628,Event,ADDED,eval-sanitize-2-r1-005-rng6l.18d420ddd467f86d,reason=Started count=1 msg=Started container task
60.063,Event,ADDED,eval-sanitize-2-r1-005.18d420dbca68d397,reason=SuccessfulCreate count=1 msg=Created pod: eval-sanitize-2-r1-005-rng6l
60.0632,Event,ADDED,eval-sanitize-2-r1-005.18d420e0fa388864,reason=Completed count=1 msg=Job completed
60.0634,Event,ADDED,eval-sanitize-2-r1-006-srhbl.18d420dc05f76998,"reason=FailedScheduling count=None msg=0/6 nodes are available: 6 node(s) had untolerated taint(s). no new claims to deallocate, preemption: 0/6 nodes are available: 6 Preemption is not helpful for scheduling."
60.0634,TaskRequest,ADDED,eval-sanitize-2-r1-027,phase=Complete job=None
60.0635,TaskRequest,ADDED,eval-sanitize-2-r1-028,phase=Complete job=None
60.0635,TaskRequest,ADDED,eval-sanitize-2-r1-029,phase=Complete job=None
60.0653,Node,ADDED,kind-worker5,taints=1
60.0656,Event,ADDED,eval-sanitize-2-r1-006-srhbl.18d420ddaeed4e66,"reason=FailedScheduling count=None msg=0/6 nodes are available: 1 c_wall violated: 1 conflicting context pair(s) with node memory, 5 node(s) had untolerated taint(s). no new claims to deallocate, preemption: 0/6 nodes are available: 1 No preemption victims found for incoming pod, 5 Preemption is not helpful for scheduling."
60.0658,Event,ADDED,eval-sanitize-2-r1-006-srhbl.18d420ddb93669fc,"reason=FailedScheduling count=None msg=0/6 nodes are available: 1 c_wall violated: 2 conflicting context pair(s) with node memory, 5 node(s) had untolerated taint(s). no new claims to deallocate, preemption: 0/6 nodes are available: 1 No preemption victims found for incoming pod, 5 Preemption is not helpful for scheduling."
60.0659,Event,ADDED,eval-sanitize-2-r1-006-srhbl.18d420ddbbc749f0,"reason=FailedScheduling count=None msg=0/6 nodes are available: 1 c_wall violated: 2 conflicting context pair(s) with node memory, 5 node(s) had untolerated taint(s). no new claims to deallocate, preemption: 0/6 nodes are available: 1 No preemption victims found for incoming pod, 5 Preemption is not helpful for scheduling."
60.0662,TaskRequest,ADDED,eval-sanitize-2-r1-030,phase=Complete job=None
60.0663,TaskRequest,ADDED,eval-sanitize-2-r1-031,phase=Complete job=None
60.0672,Job,ADDED,eval-sanitize-2-r1-007,
60.0687,Pod,ADDED,eval-sanitize-2-r1-007-z7mxg,phase=Succeeded node=kind-worker5
60.069,Event,ADDED,eval-sanitize-2-r1-006-srhbl.18d420ddd353b6f8,reason=Scheduled count=None msg=Successfully assigned compute/eval-sanitize-2-r1-006-srhbl to kind-worker3
60.0693,Event,ADDED,eval-sanitize-2-r1-006-srhbl.18d420ddeaa4b62a,"reason=Pulled count=1 msg=Container image ""busybox:musl"" already present on machine"
60.0695,Event,ADDED,eval-sanitize-2-r1-006-srhbl.18d420ddebdc1c81,reason=Created count=1 msg=Created container: task
60.0696,TaskRequest,ADDED,eval-sanitize-2-r1-032,phase=Complete job=None
60.0696,TaskRequest,ADDED,eval-sanitize-2-r1-033,phase=Complete job=None
60.0697,TaskRequest,ADDED,eval-sanitize-2-r1-034,phase=Complete job=None
60.0705,Job,ADDED,eval-sanitize-2-r1-008,
60.072,Pod,ADDED,eval-sanitize-2-r1-008-24xc5,phase=Succeeded node=kind-worker3
60.0725,Event,ADDED,eval-sanitize-2-r1-006-srhbl.18d420ddeffcd013,reason=Started count=1 msg=Started container task
60.0729,Event,ADDED,eval-sanitize-2-r1-006.18d420dc05eb1375,reason=SuccessfulCreate count=1 msg=Created pod: eval-sanitize-2-r1-006-srhbl
60.073,Event,ADDED,eval-sanitize-2-r1-006.18d420e112368f76,reason=Completed count=1 msg=Job completed
60.0732,Event,ADDED,eval-sanitize-2-r1-007-z7mxg.18d420dc41cd6d33,"reason=FailedScheduling count=None msg=0/6 nodes are available: 6 node(s) had untolerated taint(s). no new claims to deallocate, preemption: 0/6 nodes are available: 6 Preemption is not helpful for scheduling."
60.0733,TaskRequest,ADDED,eval-sanitize-2-r1-035,phase=Complete job=None
60.0733,TaskRequest,ADDED,eval-sanitize-2-r1-036,phase=Complete job=None
60.0734,TaskRequest,ADDED,eval-sanitize-2-r1-037,phase=Complete job=None
60.0734,TaskRequest,ADDED,eval-sanitize-2-r1-038,phase=Complete job=None
60.0736,TaskRequest,ADDED,eval-sanitize-2-r1-039,phase=Complete job=None
60.0748,Pod,ADDED,eval-sanitize-2-r1-009-rqs9m,phase=Succeeded node=kind-worker5
60.075,Event,ADDED,eval-sanitize-2-r1-007-z7mxg.18d420ddafb40865,reason=Scheduled count=None msg=Successfully assigned compute/eval-sanitize-2-r1-007-z7mxg to kind-worker5
60.0752,Event,ADDED,eval-sanitize-2-r1-007-z7mxg.18d420ddc9f85b88,"reason=Pulled count=1 msg=Container image ""busybox:musl"" already present on machine"
60.0754,Event,ADDED,eval-sanitize-2-r1-007-z7mxg.18d420ddcc2a1fb9,reason=Created count=1 msg=Created container: task
60.0756,Event,ADDED,eval-sanitize-2-r1-007-z7mxg.18d420ddd467f887,reason=Started count=1 msg=Started container task
60.0769,Job,ADDED,eval-sanitize-2-r1-009,
60.077,TaskRequest,ADDED,eval-sanitize-2-r1-040,phase=Complete job=None
60.0771,TaskRequest,ADDED,eval-sanitize-2-r1-041,phase=Complete job=None
60.0771,TaskRequest,ADDED,eval-sanitize-2-r1-042,phase=Complete job=None
60.0784,Pod,ADDED,eval-sanitize-2-r1-010-cmhnq,phase=Succeeded node=kind-worker3
60.0787,Event,ADDED,eval-sanitize-2-r1-007.18d420dc41c0e229,reason=SuccessfulCreate count=1 msg=Created pod: eval-sanitize-2-r1-007-z7mxg
60.0789,Event,ADDED,eval-sanitize-2-r1-007.18d420e0fafaf47f,reason=Completed count=1 msg=Job completed
60.079,Event,ADDED,eval-sanitize-2-r1-008-24xc5.18d420dc7cf14e5f,"reason=FailedScheduling count=None msg=0/6 nodes are available: 6 node(s) had untolerated taint(s). no new claims to deallocate, preemption: 0/6 nodes are available: 6 Preemption is not helpful for scheduling."
60.0801,Job,ADDED,eval-sanitize-2-r1-010,
60.0801,TaskRequest,ADDED,eval-sanitize-2-r1-043,phase=Complete job=None
60.0802,TaskRequest,ADDED,eval-sanitize-2-r1-044,phase=Scheduled job=None
60.0805,TaskRequest,ADDED,eval-sanitize-2-r1-045,phase=Scheduled job=None
60.0805,TaskRequest,ADDED,eval-sanitize-2-r1-046,phase=Scheduled job=None
60.0806,TaskRequest,ADDED,eval-sanitize-2-r1-047,phase=Scheduled job=None
60.0808,Event,ADDED,eval-sanitize-2-r1-008-24xc5.18d420ddafa02d34,"reason=FailedScheduling count=None msg=0/6 nodes are available: 1 c_wall violated: 1 conflicting context pair(s) with node memory, 5 node(s) had untolerated taint(s). no new claims to deallocate, preemption: 0/6 nodes are available: 1 No preemption victims found for incoming pod, 5 Preemption is not helpful for scheduling."
60.081,Event,ADDED,eval-sanitize-2-r1-008-24xc5.18d420ddb9b5d6cc,"reason=FailedScheduling count=None msg=0/6 nodes are available: 1 c_wall violated: 1 conflicting context pair(s) with node memory, 5 node(s) had untolerated taint(s). no new claims to deallocate, preemption: 0/6 nodes are available: 1 No preemption victims found for incoming pod, 5 Preemption is not helpful for scheduling."
60.0812,Event,ADDED,eval-sanitize-2-r1-008-24xc5.18d420ddd7839f4e,reason=Scheduled count=None msg=Successfully assigned compute/eval-sanitize-2-r1-008-24xc5 to kind-worker3
60.0824,Pod,ADDED,eval-sanitize-2-r1-011-mbg8c,phase=Succeeded node=kind-worker2
60.0837,Pod,ADDED,eval-sanitize-2-r1-012-nfhdz,phase=Succeeded node=kind-worker2
60.0845,Job,ADDED,eval-sanitize-2-r1-011,
60.0846,TaskRequest,ADDED,eval-sanitize-2-r1-048,phase=Scheduled job=None
60.0847,TaskRequest,ADDED,eval-sanitize-2-r1-049,phase=Scheduled job=None
60.0847,TaskRequest,ADDED,eval-sanitize-2-r1-050,phase=Scheduled job=None
60.0849,Event,ADDED,eval-sanitize-2-r1-008-24xc5.18d420ddf11c0d1c,"reason=Pulled count=1 msg=Container image ""busybox:musl"" already present on machine"
60.0851,Event,ADDED,eval-sanitize-2-r1-008-24xc5.18d420ddf267d42f,reason=Created count=1 msg=Created container: task
60.0853,Event,ADDED,eval-sanitize-2-r1-008-24xc5.18d420ddf68741a3,reason=Started count=1 msg=Started container task
60.0855,Event,ADDED,eval-sanitize-2-r1-008.18d420dc7ce4f9f2,reason=SuccessfulCreate count=1 msg=Created pod: eval-sanitize-2-r1-008-24xc5
60.0862,Event,ADDED,eval-sanitize-2-r1-008.18d420e113151088,reason=Completed count=1 msg=Job completed
60.0864,Event,ADDED,eval-sanitize-2-r1-009-rqs9m.18d420dcb8a434c2,"reason=FailedScheduling count=None msg=0/6 nodes are available: 6 node(s) had untolerated taint(s). no new claims to deallocate, preemption: 0/6 nodes are available: 6 Preemption is not helpful for scheduling."
60.0866,Event,ADDED,eval-sanitize-2-r1-009-rqs9m.18d420ddb08a565b,reason=Scheduled count=None msg=Successfully assigned compute/eval-sanitize-2-r1-009-rqs9m to kind-worker5
60.0867,Event,ADDED,eval-sanitize-2-r1-009-rqs9m.18d420ddc9e14998,"reason=Pulled count=1 msg=Container image ""busybox:musl"" already present on machine"
60.0878,Pod,ADDED,eval-sanitize-2-r1-013-w4d7s,phase=Succeeded node=kind-worker2
60.0885,Job,ADDED,eval-sanitize-2-r1-012,
60.0886,TaskRequest,ADDED,eval-sanitize-2-r1-051,phase=Scheduled job=None
60.0886,TaskRequest,ADDED,eval-sanitize-2-r1-052,phase=Scheduled job=None
60.0887,TaskRequest,ADDED,eval-sanitize-2-r1-053,phase=Scheduled job=None
60.089,TaskRequest,ADDED,eval-sanitize-2-r1-054,phase=Scheduled job=None
60.0891,TaskRequest,ADDED,eval-sanitize-2-r1-055,phase=Scheduled job=None
60.0894,Event,ADDED,eval-sanitize-2-r1-009-rqs9m.18d420ddcbadf3b7,reason=Created count=1 msg=Created container: task
60.0895,Event,ADDED,eval-sanitize-2-r1-009-rqs9m.18d420ddd243c894,reason=Started count=1 msg=Started container task
60.0897,Event,ADDED,eval-sanitize-2-r1-009.18d420dcb898069a,reason=SuccessfulCreate count=1 msg=Created pod: eval-sanitize-2-r1-009-rqs9m
60.0899,Event,ADDED,eval-sanitize-2-r1-009.18d420e0f9cf3029,reason=Completed count=1 msg=Job completed
60.0901,Event,ADDED,eval-sanitize-2-r1-010-cmhnq.18d420dcf43a9175,"reason=FailedScheduling count=None msg=0/6 nodes are available: 6 node(s) had untolerated taint(s). no new claims to deallocate, preemption: 0/6 nodes are available: 6 Preemption is not helpful for scheduling."
60.0902,Event,ADDED,eval-sanitize-2-r1-010-cmhnq.18d420ddb05e8221,"reason=FailedScheduling count=None msg=0/6 nodes are available: 1 c_wall violated: 1 conflicting context pair(s) with node memory, 5 node(s) had untolerated taint(s). no new claims to deallocate, preemption: 0/6 nodes are available: 1 No preemption victims found for incoming pod, 5 Preemption is not helpful for scheduling."
60.0904,Event,ADDED,eval-sanitize-2-r1-010-cmhnq.18d420ddb9ed9017,"reason=FailedScheduling count=None msg=0/6 nodes are available: 1 c_wall violated: 1 conflicting context pair(s) with node memory, 5 node(s) had untolerated taint(s). no new claims to deallocate, preemption: 0/6 nodes are available: 1 No preemption victims found for incoming pod, 5 Preemption is not helpful for scheduling."
60.0915,Pod,ADDED,eval-sanitize-2-r1-014-fphhf,phase=Succeeded node=kind-worker3
60.0917,TaskRequest,ADDED,eval-sanitize-2-r1-056,phase=Scheduled job=None
60.0917,TaskRequest,ADDED,eval-sanitize-2-r1-057,phase=Scheduled job=None
60.0917,TaskRequest,ADDED,eval-sanitize-2-r1-058,phase=Scheduled job=None
60.0925,Job,ADDED,eval-sanitize-2-r1-013,
60.0928,Event,ADDED,eval-sanitize-2-r1-010-cmhnq.18d420ddcbfc10ea,reason=Scheduled count=None msg=Successfully assigned compute/eval-sanitize-2-r1-010-cmhnq to kind-worker3
60.093,Event,ADDED,eval-sanitize-2-r1-010-cmhnq.18d420dde6c853b8,"reason=Pulled count=1 msg=Container image ""busybox:musl"" already present on machine"
60.0931,Event,ADDED,eval-sanitize-2-r1-010-cmhnq.18d420dde8549a1a,reason=Created count=1 msg=Created container: task
60.0936,TaskRequest,ADDED,eval-sanitize-2-r1-059,phase=Scheduled job=None
60.0936,TaskRequest,ADDED,eval-sanitize-2-r1-060,phase=Pending job=None
60.0943,Job,ADDED,eval-sanitize-2-r1-014,
60.0947,Event,ADDED,eval-sanitize-2-r1-010-cmhnq.18d420ddea8a2396,reason=Started count=1 msg=Started container task
60.0949,Event,ADDED,eval-sanitize-2-r1-010.18d420dcf42ddd5d,reason=SuccessfulCreate count=1 msg=Created pod: eval-sanitize-2-r1-010-cmhnq
60.0951,Event,ADDED,eval-sanitize-2-r1-010.18d420e11263a5dc,reason=Completed count=1 msg=Job completed
60.0953,Event,ADDED,eval-sanitize-2-r1-011-mbg8c.18d420dd303d65e9,"reason=FailedScheduling count=None msg=0/6 nodes are available: 6 node(s) had untolerated taint(s). no new claims to deallocate, preemption: 0/6 nodes are available: 6 Preemption is not helpful for scheduling."
60.0967,Pod,ADDED,eval-sanitize-2-r1-015-2w6kl,phase=Succeeded node=kind-worker2
60.0969,TaskRequest,MODIFIED,eval-sanitize-2-r1-060,phase=Scheduled job=None
60.0974,Event,ADDED,eval-sanitize-2-r1-011-mbg8c.18d420ddb61a186b,"reason=FailedScheduling count=None msg=0/6 nodes are available: 1 c_wall violated: 2 conflicting context pair(s) with node memory, 5 node(s) had untolerated taint(s). no new claims to deallocate, preemption: 0/6 nodes are available: 1 No preemption victims found for incoming pod, 5 Preemption is not helpful for scheduling."
60.0976,Event,ADDED,eval-sanitize-2-r1-011-mbg8c.18d420ddbb3ebdb5,"reason=FailedScheduling count=None msg=0/6 nodes are available: 1 c_wall violated: 2 conflicting context pair(s) with node memory, 5 node(s) had untolerated taint(s). no new claims to deallocate, preemption: 0/6 nodes are available: 1 No preemption victims found for incoming pod, 5 Preemption is not helpful for scheduling."
60.0977,Event,ADDED,eval-sanitize-2-r1-011-mbg8c.18d420ddd79fc92d,"reason=FailedScheduling count=None msg=0/6 nodes are available: 2 c_wall violated: 2 conflicting context pair(s) with node memory, 4 node(s) had untolerated taint(s). no new claims to deallocate, preemption: 0/6 nodes are available: 2 No preemption victims found for incoming pod, 4 Preemption is not helpful for scheduling."
60.0987,Pod,ADDED,eval-sanitize-2-r1-016-kq9wb,phase=Succeeded node=kind-worker
60.0995,Job,ADDED,eval-sanitize-2-r1-015,
60.0997,Event,ADDED,eval-sanitize-2-r1-011-mbg8c.18d420ddddbbeb8f,"reason=FailedScheduling count=None msg=0/6 nodes are available: 2 c_wall violated: 2 conflicting context pair(s) with node memory, 4 node(s) had untolerated taint(s). no new claims to deallocate, preemption: 0/6 nodes are available: 2 No preemption victims found for incoming pod, 4 Preemption is not helpful for scheduling."
60.0999,Event,ADDED,eval-sanitize-2-r1-011-mbg8c.18d420de30f5c46d,"reason=FailedScheduling count=None msg=0/6 nodes are available: 1 c_wall violated: 2 conflicting context pair(s) with node memory, 5 node(s) had untolerated taint(s). no new claims to deallocate, preemption: 0/6 nodes are available: 1 No preemption victims found for incoming pod, 5 Preemption is not helpful for scheduling."
60.1001,Event,ADDED,eval-sanitize-2-r1-011-mbg8c.18d420de3dc164ea,reason=Scheduled count=None msg=Successfully assigned compute/eval-sanitize-2-r1-011-mbg8c to kind-worker2
60.1011,Pod,ADDED,eval-sanitize-2-r1-017-6455d,phase=Succeeded node=kind-worker4
60.1012,TaskRequest,MODIFIED,eval-sanitize-2-r1-060,phase=Scheduled job=None
60.1019,Job,ADDED,eval-sanitize-2-r1-016,
60.103,Pod,ADDED,eval-sanitize-2-r1-018-tgv4l,phase=Succeeded node=kind-worker
60.1038,Job,ADDED,eval-sanitize-2-r1-017,
60.1041,Event,ADDED,eval-sanitize-2-r1-011-mbg8c.18d420de58134e43,"reason=Pulled count=1 msg=Container image ""busybox:musl"" already present on machine"
60.1042,Event,ADDED,eval-sanitize-2-r1-011-mbg8c.18d420de5a4462b5,reason=Created count=1 msg=Created container: task
60.1044,Event,ADDED,eval-sanitize-2-r1-011-mbg8c.18d420de5d35a297,reason=Started count=1 msg=Started container task
60.1053,Job,ADDED,eval-sanitize-2-r1-018,
60.1055,Event,ADDED,eval-sanitize-2-r1-011.18d420dd3031867e,reason=SuccessfulCreate count=1 msg=Created pod: eval-sanitize-2-r1-011-mbg8c
60.1057,Event,ADDED,eval-sanitize-2-r1-011.18d420e1860bca6f,reason=Completed count=1 msg=Job completed
60.1059,Event,ADDED,eval-sanitize-2-r1-012-nfhdz.18d420dd6bab74bc,"reason=FailedScheduling count=None msg=0/6 nodes are available: 6 node(s) had untolerated taint(s). no new claims to deallocate, preemption: 0/6 nodes are available: 6 Preemption is not helpful for scheduling."
60.106,Event,ADDED,eval-sanitize-2-r1-012-nfhdz.18d420ddb68ce06a,"reason=FailedScheduling count=None msg=0/6 nodes are available: 1 c_wall violated: 2 conflicting context pair(s) with node memory, 5 node(s) had untolerated taint(s). no new claims to deallocate, preemption: 0/6 nodes are available: 1 No preemption victims found for incoming pod, 5 Preemption is not helpful for scheduling."
60.1066,Event,ADDED,eval-sanitize-2-r1-012-nfhdz.18d420ddbb691a36,"reason=FailedScheduling count=None msg=0/6 nodes are available: 1 c_wall violated: 2 conflicting context pair(s) with node memory, 5 node(s) had untolerated taint(s). no new claims to deallocate, preemption: 0/6 nodes are available: 1 No preemption victims found for incoming pod, 5 Preemption is not helpful for scheduling."
60.1069,Event,ADDED,eval-sanitize-2-r1-012-nfhdz.18d420ddd8fe9f45,"reason=FailedScheduling count=None msg=0/6 nodes are available: 1 c_wall violated: 1 conflicting context pair(s) with node memory, 1 c_wall violated: 2 conflicting context pair(s) with node memory, 4 node(s) had untolerated taint(s). no new claims to deallocate, preemption: 0/6 nodes are available: 2 No preemption victims found for incoming pod, 4 Preemption is not helpful for scheduling."
60.1071,Event,ADDED,eval-sanitize-2-r1-012-nfhdz.18d420de312bceb6,"reason=FailedScheduling count=None msg=0/6 nodes are available: 1 c_wall violated: 1 conflicting context pair(s) with node memory, 5 node(s) had untolerated taint(s). no new claims to deallocate, preemption: 0/6 nodes are available: 1 No preemption victims found for incoming pod, 5 Preemption is not helpful for scheduling."
60.1082,Pod,ADDED,eval-sanitize-2-r1-019-9fbj8,phase=Succeeded node=kind-worker5
60.1085,Event,ADDED,eval-sanitize-2-r1-012-nfhdz.18d420de3e434161,reason=Scheduled count=None msg=Successfully assigned compute/eval-sanitize-2-r1-012-nfhdz to kind-worker2
60.1087,Event,ADDED,eval-sanitize-2-r1-012-nfhdz.18d420de5897c52c,"reason=Pulled count=1 msg=Container image ""busybox:musl"" already present on machine"
60.1089,Event,ADDED,eval-sanitize-2-r1-012-nfhdz.18d420de5aeed255,reason=Created count=1 msg=Created container: task
60.1099,Pod,ADDED,eval-sanitize-2-r1-020-jm8sr,phase=Succeeded node=kind-worker5
60.1107,Job,ADDED,eval-sanitize-2-r1-019,
60.111,Event,ADDED,eval-sanitize-2-r1-012-nfhdz.18d420de5da8beb0,reason=Started count=1 msg=Started container task
60.1113,Event,ADDED,eval-sanitize-2-r1-012.18d420dd6ba05425,reason=SuccessfulCreate count=1 msg=Created pod: eval-sanitize-2-r1-012-nfhdz
60.1115,Event,ADDED,eval-sanitize-2-r1-012.18d420e185227399,reason=Completed count=1 msg=Job completed
60.1117,Event,ADDED,eval-sanitize-2-r1-013-w4d7s.18d420dda6f82cde,"reason=FailedScheduling count=None msg=0/6 nodes are available: 6 node(s) had untolerated taint(s). no new claims to deallocate, preemption: 0/6 nodes are available: 6 Preemption is not helpful for scheduling."
60.1125,Job,ADDED,eval-sanitize-2-r1-020,
60.1129,Event,ADDED,eval-sanitize-2-r1-013-w4d7s.18d420ddb7044796,"reason=FailedScheduling count=None msg=0/6 nodes are available: 1 c_wall violated: 1 conflicting context pair(s) with node memory, 5 node(s) had untolerated taint(s). no new claims to deallocate, preemption: 0/6 nodes are available: 1 No preemption victims found for incoming pod, 5 Preemption is not helpful for scheduling."
60.1131,Event,ADDED,eval-sanitize-2-r1-013-w4d7s.18d420ddbb8ed0a8,"reason=FailedScheduling count=None msg=0/6 nodes are available: 1 c_wall violated: 1 conflicting context pair(s) with node memory, 5 node(s) had untolerated taint(s). no new claims to deallocate, preemption: 0/6 nodes are available: 1 No preemption victims found for incoming pod, 5 Preemption is not helpful for scheduling."
60.1133,Event,ADDED,eval-sanitize-2-r1-013-w4d7s.18d420dddd1f5b1f,"reason=FailedScheduling count=None msg=0/6 nodes are available: 1 c_wall violated: 1 conflicting context pair(s) with node memory, 1 c_wall violated: 2 conflicting context pair(s) with node memory, 4 node(s) had untolerated taint(s). no new claims to deallocate, preemption: 0/6 nodes are available: 2 No preemption victims found for incoming pod, 4 Preemption is not helpful for scheduling."
60.1136,Event,ADDED,eval-sanitize-2-r1-013-w4d7s.18d420dde3038aee,"reason=FailedScheduling count=None msg=0/6 nodes are available: 1 c_wall violated: 1 conflicting context pair(s) with node memory, 1 c_wall violated: 2 conflicting context pair(s) with node memory, 4 node(s) had untolerated taint(s). no new claims to deallocate, preemption: 0/6 nodes are available: 2 No preemption victims found for incoming pod, 4 Preemption is not helpful for scheduling."
60.1137,Event,ADDED,eval-sanitize-2-r1-013-w4d7s.18d420de328ee9dc,"reason=FailedScheduling count=None msg=0/6 nodes are available: 1 c_wall violated: 2 conflicting context pair(s) with node memory, 5 node(s) had untolerated taint(s). no new claims to deallocate, preemption: 0/6 nodes are available: 1 No preemption victims found for incoming pod, 5 Preemption is not helpful for scheduling."
60.1139,Event,ADDED,eval-sanitize-2-r1-013-w4d7s.18d420de3d56ba37,reason=Scheduled count=None msg=Successfully assigned compute/eval-sanitize-2-r1-013-w4d7s to kind-worker2
60.1142,Event,ADDED,eval-sanitize-2-r1-013-w4d7s.18d420de57d6569c,"reason=Pulled count=1 msg=Container image ""busybox:musl"" already present on machine"
60.1144,Event,ADDED,eval-sanitize-2-r1-013-w4d7s.18d420de59a5c3d3,reason=Created count=1 msg=Created container: task
60.1146,Event,ADDED,eval-sanitize-2-r1-013-w4d7s.18d420de5c7f97a1,reason=Started count=1 msg=Started container task
60.1159,Pod,ADDED,eval-sanitize-2-r1-021-xwkkx,phase=Succeeded node=kind-worker5
60.1169,Pod,ADDED,eval-sanitize-2-r1-022-44zg5,phase=Succeeded node=kind-worker5
60.1177,Job,ADDED,eval-sanitize-2-r1-021,
60.118,Event,ADDED,eval-sanitize-2-r1-013.18d420dda6ef082b,reason=SuccessfulCreate count=1 msg=Created pod: eval-sanitize-2-r1-013-w4d7s
60.1183,Event,ADDED,eval-sanitize-2-r1-013.18d420e1858d349a,reason=Completed count=1 msg=Job completed
60.1185,Event,ADDED,eval-sanitize-2-r1-014-fphhf.18d420dde3bb97de,reason=Scheduled count=None msg=Successfully assigned compute/eval-sanitize-2-r1-014-fphhf to kind-worker3
60.1187,Event,ADDED,eval-sanitize-2-r1-014-fphhf.18d420ddfe192290,"reason=Pulled count=1 msg=Container image ""busybox:musl"" already present on machine"
60.1195,Job,ADDED,eval-sanitize-2-r1-022,
60.1198,Event,ADDED,eval-sanitize-2-r1-014-fphhf.18d420ddff3918a0,reason=Created count=1 msg=Created container: task
60.12,Event,ADDED,eval-sanitize-2-r1-014-fphhf.18d420de0395ccde,reason=Started count=1 msg=Started container task
60.1202,Event,ADDED,eval-sanitize-2-r1-014.18d420dde2b864f3,reason=SuccessfulCreate count=1 msg=Created pod: eval-sanitize-2-r1-014-fphhf
60.1204,Event,ADDED,eval-sanitize-2-r1-014.18d420e113216483,reason=Completed count=1 msg=Job completed
60.1225,Pod,ADDED,eval-sanitize-2-r1-023-42sh8,phase=Succeeded node=kind-worker2
60.1228,Event,ADDED,eval-sanitize-2-r1-015-2w6kl.18d420de1e96dd30,"reason=FailedScheduling count=None msg=0/6 nodes are available: 2 c_wall violated: 2 conflicting context pair(s) with node memory, 4 node(s) had untolerated taint(s). no new claims to deallocate, preemption: 0/6 nodes are available: 2 No preemption victims found for incoming pod, 4 Preemption is not helpful for scheduling."
60.123,Event,ADDED,eval-sanitize-2-r1-015-2w6kl.18d420de1f443551,"reason=FailedScheduling count=None msg=0/6 nodes are available: 2 c_wall violated: 2 conflicting context pair(s) with node memory, 4 node(s) had untolerated taint(s). no new claims to deallocate, preemption: 0/6 nodes are available: 2 No preemption victims found for incoming pod, 4 Preemption is not helpful for scheduling."
60.1232,Event,ADDED,eval-sanitize-2-r1-015-2w6kl.18d420de3261d9d1,"reason=FailedScheduling count=None msg=0/6 nodes are available: 1 c_wall violated: 2 conflicting context pair(s) with node memory, 5 node(s) had untolerated taint(s). no new claims to deallocate, preemption: 0/6 nodes are available: 1 No preemption victims found for incoming pod, 5 Preemption is not helpful for scheduling."
60.1243,Pod,ADDED,eval-sanitize-2-r1-024-mfnr5,phase=Succeeded node=kind-worker5
60.1251,Job,ADDED,eval-sanitize-2-r1-023,
60.1258,Job,ADDED,eval-sanitize-2-r1-024,
60.1261,Event,ADDED,eval-sanitize-2-r1-015-2w6kl.18d420de42bf6b4d,reason=Scheduled count=None msg=Successfully assigned compute/eval-sanitize-2-r1-015-2w6kl to kind-worker2
60.1263,Event,ADDED,eval-sanitize-2-r1-015-2w6kl.18d420de5aaf177c,"reason=Pulled count=1 msg=Container image ""busybox:musl"" already present on machine"
60.1265,Event,ADDED,eval-sanitize-2-r1-015-2w6kl.18d420de5c7b225e,reason=Created count=1 msg=Created container: task
60.1272,Job,ADDED,eval-sanitize-2-r1-025,
60.1278,Event,ADDED,eval-sanitize-2-r1-015-2w6kl.18d420de5eaf1011,reason=Started count=1 msg=Started container task
60.128,Event,ADDED,eval-sanitize-2-r1-015.18d420de1e227396,reason=SuccessfulCreate count=1 msg=Created pod: eval-sanitize-2-r1-015-2w6kl
60.1282,Event,ADDED,eval-sanitize-2-r1-015.18d420e186505df5,reason=Completed count=1 msg=Job completed
60.1283,Event,ADDED,eval-sanitize-2-r1-016-kq9wb.18d420de5c15b6f3,reason=Scheduled count=None msg=Successfully assigned compute/eval-sanitize-2-r1-016-kq9wb to kind-worker
60.1291,Job,ADDED,eval-sanitize-2-r1-026,
60.1302,Pod,ADDED,eval-sanitize-2-r1-025-7m5rb,phase=Succeeded node=kind-worker3
60.1305,Event,ADDED,eval-sanitize-2-r1-016-kq9wb.18d420de75c96099,"reason=Pulled count=1 msg=Container image ""busybox:musl"" already present on machine"
60.1307,Event,ADDED,eval-sanitize-2-r1-016-kq9wb.18d420de76cf49df,reason=Created count=1 msg=Created container: task
60.1308,Event,ADDED,eval-sanitize-2-r1-016-kq9wb.18d420de7a59b3c6,reason=Started count=1 msg=Started container task
60.131,Event,ADDED,eval-sanitize-2-r1-016.18d420de5b332d75,reason=SuccessfulCreate count=1 msg=Created pod: eval-sanitize-2-r1-016-kq9wb
60.1321,Pod,ADDED,eval-sanitize-2-r1-026-88m8g,phase=Succeeded node=kind-worker2
60.1324,Event,ADDED,eval-sanitize-2-r1-016.18d420e1b2faa31f,reason=Completed count=1 msg=Job completed
60.1325,Event,ADDED,eval-sanitize-2-r1-017-6455d.18d420de95a67d8a,"reason=FailedScheduling count=None msg=0/6 nodes are available: 1 c_wall violated: 1 conflicting context pair(s) with node memory, 1 c_wall violated: 3 conflicting context pair(s) with node memory, 4 node(s) had untolerated taint(s). no new claims to deallocate, preemption: 0/6 nodes are available: 2 No preemption victims found for incoming pod, 4 Preemption is not helpful for scheduling."
60.1327,Event,ADDED,eval-sanitize-2-r1-017-6455d.18d420de964ab054,"reason=FailedScheduling count=None msg=0/6 nodes are available: 1 c_wall violated: 1 conflicting context pair(s) with node memory, 1 c_wall violated: 3 conflicting context pair(s) with node memory, 4 node(s) had untolerated taint(s). no new claims to deallocate, preemption: 0/6 nodes are available: 2 No preemption victims found for incoming pod, 4 Preemption is not helpful for scheduling."
60.1334,Job,ADDED,eval-sanitize-2-r1-027,
60.1346,Pod,ADDED,eval-sanitize-2-r1-027-622v9,phase=Succeeded node=kind-worker3
60.1355,Pod,ADDED,eval-sanitize-2-r1-028-gjgkl,phase=Succeeded node=kind-worker2
60.1362,Job,ADDED,eval-sanitize-2-r1-028,
60.1368,Job,ADDED,eval-sanitize-2-r1-029,
60.1375,Job,ADDED,eval-sanitize-2-r1-030,
60.1387,Pod,ADDED,eval-sanitize-2-r1-029-vwzxl,phase=Succeeded node=kind-worker
60.1394,Job,ADDED,eval-sanitize-2-r1-031,
60.1397,Event,ADDED,eval-sanitize-2-r1-017-6455d.18d420de96e2a559,reason=Scheduled count=None msg=Successfully assigned compute/eval-sanitize-2-r1-017-6455d to kind-worker4
60.1399,Event,ADDED,eval-sanitize-2-r1-017-6455d.18d420deaff705fd,"reason=Pulled count=1 msg=Container image ""busybox:musl"" already present on machine"
60.14,Event,ADDED,eval-sanitize-2-r1-017-6455d.18d420deb11094b4,reason=Created count=1 msg=Created container: task
60.1403,Event,ADDED,eval-sanitize-2-r1-017-6455d.18d420deb3193517,reason=Started count=1 msg=Started container task
60.1416,Pod,ADDED,eval-sanitize-2-r1-030-2q542,phase=Succeeded node=kind-worker4
60.1424,Job,ADDED,eval-sanitize-2-r1-032,
60.1427,Event,ADDED,eval-sanitize-2-r1-017.18d420de95401a36,reason=SuccessfulCreate count=1 msg=Created pod: eval-sanitize-2-r1-017-6455d
60.1429,Event,ADDED,eval-sanitize-2-r1-017.18d420e1e86e0bfc,reason=Completed count=1 msg=Job completed
60.1431,Event,ADDED,eval-sanitize-2-r1-018-tgv4l.18d420ded1887112,reason=Scheduled count=None msg=Successfully assigned compute/eval-sanitize-2-r1-018-tgv4l to kind-worker
60.1438,Event,ADDED,eval-sanitize-2-r1-018-tgv4l.18d420dee9a6e1aa,"reason=Pulled count=1 msg=Container image ""busybox:musl"" already present on machine"
60.144,Event,ADDED,eval-sanitize-2-r1-018-tgv4l.18d420deeab7576c,reason=Created count=1 msg=Created container: task
60.1442,Event,ADDED,eval-sanitize-2-r1-018-tgv4l.18d420deeca1f0e6,reason=Started count=1 msg=Started container task
60.1444,Event,ADDED,eval-sanitize-2-r1-018.18d420ded0dc084b,reason=SuccessfulCreate count=1 msg=Created pod: eval-sanitize-2-r1-018-tgv4l
60.1456,Pod,ADDED,eval-sanitize-2-r1-031-rq4sb,phase=Succeeded node=kind-worker4
60.1465,Job,ADDED,eval-sanitize-2-r1-033,
60.1468,Event,ADDED,eval-sanitize-2-r1-018.18d420e22ad38f6f,reason=Completed count=1 msg=Job completed
60.1469,Event,ADDED,eval-sanitize-2-r1-019-9fbj8.18d420df0ce024c9,"reason=FailedScheduling count=None msg=0/6 nodes are available: 1 c_wall violated: 1 conflicting context pair(s) with node memory, 5 node(s) had untolerated taint(s). no new claims to deallocate, preemption: 0/6 nodes are available: 1 No preemption victims found for incoming pod, 5 Preemption is not helpful for scheduling."
60.1472,Event,ADDED,eval-sanitize-2-r1-019-9fbj8.18d420df0d65b4e5,"reason=FailedScheduling count=None msg=0/6 nodes are available: 1 c_wall violated: 1 conflicting context pair(s) with node memory, 5 node(s) had untolerated taint(s). no new claims to deallocate, preemption: 0/6 nodes are available: 1 No preemption victims found for incoming pod, 5 Preemption is not helpful for scheduling."
60.1484,Pod,ADDED,eval-sanitize-2-r1-032-cjptq,phase=Succeeded node=kind-worker3
60.1492,Job,ADDED,eval-sanitize-2-r1-034,
60.1495,Event,ADDED,eval-sanitize-2-r1-019-9fbj8.18d420e0a3c0f28a,reason=Scheduled count=None msg=Successfully assigned compute/eval-sanitize-2-r1-019-9fbj8 to kind-worker5
60.1496,Event,ADDED,eval-sanitize-2-r1-019-9fbj8.18d420e0c511cfe9,"reason=Pulled count=1 msg=Container image ""busybox:musl"" already present on machine"
60.1498,Event,ADDED,eval-sanitize-2-r1-019-9fbj8.18d420e0c6e4281d,reason=Created count=1 msg=Created container: task
60.1501,Event,ADDED,eval-sanitize-2-r1-019-9fbj8.18d420e0cb1bf3b2,reason=Started count=1 msg=Started container task
60.1503,Event,ADDED,eval-sanitize-2-r1-019.18d420df0c9cccc1,reason=SuccessfulCreate count=1 msg=Created pod: eval-sanitize-2-r1-019-9fbj8
60.1505,Event,ADDED,eval-sanitize-2-r1-019.18d420e4044f0016,reason=Completed count=1 msg=Job completed
60.1506,Event,ADDED,eval-sanitize-2-r1-020-jm8sr.18d420df487d854d,"reason=FailedScheduling count=None msg=0/6 nodes are available: 6 node(s) had untolerated taint(s). no new claims to deallocate, preemption: 0/6 nodes are available: 6 Preemption is not helpful for scheduling."
60.1508,Event,ADDED,eval-sanitize-2-r1-020-jm8sr.18d420e0a458b5e9,reason=Scheduled count=None msg=Successfully assigned compute/eval-sanitize-2-r1-020-jm8sr to kind-worker5
60.151,Event,ADDED,eval-sanitize-2-r1-020-jm8sr.18d420e0beb0cea4,"reason=Pulled count=1 msg=Container image ""busybox:musl"" already present on machine"
60.1512,Event,ADDED,eval-sanitize-2-r1-020-jm8sr.18d420e0c012a63c,reason=Created count=1 msg=Created container: task
60.1513,Event,ADDED,eval-sanitize-2-r1-020-jm8sr.18d420e0c2fc443a,reason=Started count=1 msg=Started container task
60.1515,Event,ADDED,eval-sanitize-2-r1-020.18d420df48772875,reason=SuccessfulCreate count=1 msg=Created pod: eval-sanitize-2-r1-020-jm8sr
60.1517,Event,ADDED,eval-sanitize-2-r1-020.18d420e403275a57,reason=Completed count=1 msg=Job completed
60.1518,Event,ADDED,eval-sanitize-2-r1-021-xwkkx.18d420df83b68cba,"reason=FailedScheduling count=None msg=0/6 nodes are available: 6 node(s) had untolerated taint(s). no new claims to deallocate, preemption: 0/6 nodes are available: 6 Preemption is not helpful for scheduling."
60.152,Event,ADDED,eval-sanitize-2-r1-021-xwkkx.18d420e0a46c5ecc,reason=Scheduled count=None msg=Successfully assigned compute/eval-sanitize-2-r1-021-xwkkx to kind-worker5
60.1532,Pod,ADDED,eval-sanitize-2-r1-033-895m8,phase=Succeeded node=kind-worker4
60.1535,Event,ADDED,eval-sanitize-2-r1-021-xwkkx.18d420e0c52d9507,"reason=Pulled count=1 msg=Container image ""busybox:musl"" already present on machine"
60.1537,Event,ADDED,eval-sanitize-2-r1-021-xwkkx.18d420e0c7387034,reason=Created count=1 msg=Created container: task
60.1539,Event,ADDED,eval-sanitize-2-r1-021-xwkkx.18d420e0cb6875c3,reason=Started count=1 msg=Started container task
60.1546,Job,ADDED,eval-sanitize-2-r1-035,
60.1558,Pod,ADDED,eval-sanitize-2-r1-034-bkxtk,phase=Succeeded node=kind-worker5
60.1562,Event,ADDED,eval-sanitize-2-r1-021.18d420df83a8a19b,reason=SuccessfulCreate count=1 msg=Created pod: eval-sanitize-2-r1-021-xwkkx
60.1564,Event,ADDED,eval-sanitize-2-r1-021.18d420e402ffe307,reason=Completed count=1 msg=Job completed
60.1566,Event,ADDED,eval-sanitize-2-r1-022-44zg5.18d420dfbf70c22c,"reason=FailedScheduling count=None msg=0/6 nodes are available: 6 node(s) had untolerated taint(s). no new claims to deallocate, preemption: 0/6 nodes are available: 6 Preemption is not helpful for scheduling."
60.1567,Event,ADDED,eval-sanitize-2-r1-022-44zg5.18d420e0a82cdc42,reason=Scheduled count=None msg=Successfully assigned compute/eval-sanitize-2-r1-022-44zg5 to kind-worker5
60.1576,Job,ADDED,eval-sanitize-2-r1-036,
60.1593,Pod,ADDED,eval-sanitize-2-r1-035-7rwtd,phase=Succeeded node=kind-worker3
60.1597,Event,ADDED,eval-sanitize-2-r1-022-44zg5.18d420e0c54fa306,"reason=Pulled count=1 msg=Container image ""busybox:musl"" already present on machine"
60.1599,Event,ADDED,eval-sanitize-2-r1-022-44zg5.18d420e0c77b5a5e,reason=Created count=1 msg=Created container: task
60.16,Event,ADDED,eval-sanitize-2-r1-022-44zg5.18d420e0cb6ec513,reason=Started count=1 msg=Started container task
60.1602,Event,ADDED,eval-sanitize-2-r1-022.18d420dfbf64c12e,reason=SuccessfulCreate count=1 msg=Created pod: eval-sanitize-2-r1-022-44zg5
60.161,Job,ADDED,eval-sanitize-2-r1-037,
60.1622,Pod,ADDED,eval-sanitize-2-r1-036-qp2wz,phase=Succeeded node=kind-worker2
60.1626,Event,ADDED,eval-sanitize-2-r1-022.18d420e4040687c0,reason=Completed count=1 msg=Job completed
60.1628,Event,ADDED,eval-sanitize-2-r1-023-42sh8.18d420dffb29d3c5,"reason=FailedScheduling count=None msg=0/6 nodes are available: 6 node(s) had untolerated taint(s). no new claims to deallocate, preemption: 0/6 nodes are available: 6 Preemption is not helpful for scheduling."
60.1629,Event,ADDED,eval-sanitize-2-r1-023-42sh8.18d420e0a49bef2a,"reason=FailedScheduling count=None msg=0/6 nodes are available: 1 c_wall violated: 3 conflicting context pair(s) with node memory, 5 node(s) had untolerated taint(s). no new claims to deallocate, preemption: 0/6 nodes are available: 1 No preemption victims found for incoming pod, 5 Preemption is not helpful for scheduling."
60.1637,Job,ADDED,eval-sanitize-2-r1-038,
60.1641,Event,ADDED,eval-sanitize-2-r1-023-42sh8.18d420e0aa0d6da5,"reason=FailedScheduling count=None msg=0/6 nodes are available: 1 c_wall violated: 3 conflicting context pair(s) with node memory, 5 node(s) had untolerated taint(s). no new claims to deallocate, preemption: 0/6 nodes are available: 1 No preemption victims found for incoming pod, 5 Preemption is not helpful for scheduling."
60.1643,Event,ADDED,eval-sanitize-2-r1-023-42sh8.18d420e0e4057683,"reason=FailedScheduling count=None msg=0/6 nodes are available: 1 c_wall violated: 1 conflicting context pair(s) with node memory, 1 c_wall violated: 3 conflicting context pair(s) with node memory, 4 node(s) had untolerated taint(s). no new claims to deallocate, preemption: 0/6 nodes are available: 2 No preemption victims found for incoming pod, 4 Preemption is not helpful for scheduling."
60.1645,Event,ADDED,eval-sanitize-2-r1-023-42sh8.18d420e0efc4d363,"reason=FailedScheduling count=None msg=0/6 nodes are available: 1 c_wall violated: 2 conflicting context pair(s) with node memory, 1 c_wall violated: 3 conflicting context pair(s) with node memory, 4 node(s) had untolerated taint(s). no new claims to deallocate, preemption: 0/6 nodes are available: 2 No preemption victims found for incoming pod, 4 Preemption is not helpful for scheduling."
60.1659,Pod,ADDED,eval-sanitize-2-r1-037-7pl9w,phase=Succeeded node=kind-worker5
60.1662,Event,ADDED,eval-sanitize-2-r1-023-42sh8.18d420e1215e27f0,"reason=FailedScheduling count=None msg=0/6 nodes are available: 1 c_wall violated: 2 conflicting context pair(s) with node memory, 5 node(s) had untolerated taint(s). no new claims to deallocate, preemption: 0/6 nodes are available: 1 No preemption victims found for incoming pod, 5 Preemption is not helpful for scheduling."
60.1664,Event,ADDED,eval-sanitize-2-r1-023-42sh8.18d420e138dffad3,reason=Scheduled count=None msg=Successfully assigned compute/eval-sanitize-2-r1-023-42sh8 to kind-worker2
60.1666,Event,ADDED,eval-sanitize-2-r1-023-42sh8.18d420e1524b70a6,"reason=Pulled count=1 msg=Container image ""busybox:musl"" already present on machine"
60.1674,Job,ADDED,eval-sanitize-2-r1-039,
60.1686,Pod,ADDED,eval-sanitize-2-r1-038-f2884,phase=Succeeded node=kind-worker3
60.1689,Event,ADDED,eval-sanitize-2-r1-023-42sh8.18d420e153b6a70c,reason=Created count=1 msg=Created container: task
60.1691,Event,ADDED,eval-sanitize-2-r1-023-42sh8.18d420e15603cc70,reason=Started count=1 msg=Started container task
60.1693,Event,ADDED,eval-sanitize-2-r1-023.18d420dffb1f49d5,reason=SuccessfulCreate count=1 msg=Created pod: eval-sanitize-2-r1-023-42sh8
60.1694,Event,ADDED,eval-sanitize-2-r1-023.18d420e48eb27506,reason=Completed count=1 msg=Job completed
60.1703,Job,ADDED,eval-sanitize-2-r1-040,
60.1708,Event,ADDED,eval-sanitize-2-r1-024-mfnr5.18d420e0368ee596,"reason=FailedScheduling count=None msg=0/6 nodes are available: 6 node(s) had untolerated taint(s). no new claims to deallocate, preemption: 0/6 nodes are available: 6 Preemption is not helpful for scheduling."
60.171,Event,ADDED,eval-sanitize-2-r1-024-mfnr5.18d420e0a8aab91f,reason=Scheduled count=None msg=Successfully assigned compute/eval-sanitize-2-r1-024-mfnr5 to kind-worker5
60.1712,Event,ADDED,eval-sanitize-2-r1-024-mfnr5.18d420e0c3048391,"reason=Pulled count=1 msg=Container image ""busybox:musl"" already present on machine"
60.1715,Event,ADDED,eval-sanitize-2-r1-024-mfnr5.18d420e0c420b847,reason=Created count=1 msg=Created container: task
60.1717,Event,ADDED,eval-sanitize-2-r1-024-mfnr5.18d420e0c63aacc3,reason=Started count=1 msg=Started container task
60.1719,Event,ADDED,eval-sanitize-2-r1-024.18d420e03684d939,reason=SuccessfulCreate count=1 msg=Created pod: eval-sanitize-2-r1-024-mfnr5
60.1721,Event,ADDED,eval-sanitize-2-r1-024.18d420e403d23859,reason=Completed count=1 msg=Job completed
60.1733,Pod,ADDED,eval-sanitize-2-r1-039-thkjq,phase=Succeeded node=kind-worker3
60.1741,Event,ADDED,eval-sanitize-2-r1-025-7m5rb.18d420e072e9d695,"reason=FailedScheduling count=None msg=0/6 nodes are available: 6 node(s) had untolerated taint(s). no new claims to deallocate, preemption: 0/6 nodes are available: 6 Preemption is not helpful for scheduling."
60.1743,Event,ADDED,eval-sanitize-2-r1-025-7m5rb.18d420e0a895b70d,"reason=FailedScheduling count=None msg=0/6 nodes are available: 1 c_wall violated: 3 conflicting context pair(s) with node memory, 5 node(s) had untolerated taint(s). no new claims to deallocate, preemption: 0/6 nodes are available: 1 No preemption victims found for incoming pod, 5 Preemption is not helpful for scheduling."
60.1745,Event,ADDED,eval-sanitize-2-r1-025-7m5rb.18d420e0aa4b4836,"reason=FailedScheduling count=None msg=0/6 nodes are available: 1 c_wall violated: 3 conflicting context pair(s) with node memory, 5 node(s) had untolerated taint(s). no new claims to deallocate, preemption: 0/6 nodes are available: 1 No preemption victims found for incoming pod, 5 Preemption is not helpful for scheduling."
60.1758,Pod,ADDED,eval-sanitize-2-r1-040-8rcmf,phase=Succeeded node=kind-worker3
60.1762,Job,ADDED,eval-sanitize-2-r1-041,
60.1765,Event,ADDED,eval-sanitize-2-r1-025-7m5rb.18d420e0ddd13756,reason=Scheduled count=None msg=Successfully assigned compute/eval-sanitize-2-r1-025-7m5rb to kind-worker3
60.1767,Event,ADDED,eval-sanitize-2-r1-025-7m5rb.18d420e0f2c683a4,"reason=Pulled count=1 msg=Container image ""busybox:musl"" already present on machine"
60.1769,Event,ADDED,eval-sanitize-2-r1-025-7m5rb.18d420e0f3d36307,reason=Created count=1 msg=Created container: task
60.1771,Event,ADDED,eval-sanitize-2-r1-025-7m5rb.18d420e0f8164f2d,reason=Started count=1 msg=Started container task
60.178,Job,ADDED,eval-sanitize-2-r1-042,
60.1785,Event,ADDED,eval-sanitize-2-r1-025.18d420e072e0bb5a,reason=SuccessfulCreate count=1 msg=Created pod: eval-sanitize-2-r1-025-7m5rb
60.1789,Event,ADDED,eval-sanitize-2-r1-025.18d420e41bbd68c3,reason=Completed count=1 msg=Job completed
60.179,Event,ADDED,eval-sanitize-2-r1-026-88m8g.18d420e0ae60612a,"reason=FailedScheduling count=None msg=0/6 nodes are available: 1 c_wall violated: 1 conflicting context pair(s) with node memory, 5 node(s) had untolerated taint(s). no new claims to deallocate, preemption: 0/6 nodes are available: 1 No preemption victims found for incoming pod, 5 Preemption is not helpful for scheduling."
60.1801,Pod,ADDED,eval-sanitize-2-r1-041-2kf6h,phase=Succeeded node=kind-worker5
60.1816,Pod,ADDED,eval-sanitize-2-r1-042-9wtgn,phase=Succeeded node=kind-worker
60.1824,Job,ADDED,eval-sanitize-2-r1-043,
60.1827,Event,ADDED,eval-sanitize-2-r1-026-88m8g.18d420e0af3bd3de,"reason=FailedScheduling count=None msg=0/6 nodes are available: 1 c_wall violated: 1 conflicting context pair(s) with node memory, 5 node(s) had untolerated taint(s). no new claims to deallocate, preemption: 0/6 nodes are available: 1 No preemption victims found for incoming pod, 5 Preemption is not helpful for scheduling."
60.1829,Event,ADDED,eval-sanitize-2-r1-026-88m8g.18d420e0df729478,"reason=FailedScheduling count=None msg=0/6 nodes are available: 2 c_wall violated: 1 conflicting context pair(s) with node memory, 4 node(s) had untolerated taint(s). no new claims to deallocate, preemption: 0/6 nodes are available: 2 No preemption victims found for incoming pod, 4 Preemption is not helpful for scheduling."
60.1831,Event,ADDED,eval-sanitize-2-r1-026-88m8g.18d420e121978414,"reason=FailedScheduling count=None msg=0/6 nodes are available: 1 c_wall violated: 1 conflicting context pair(s) with node memory, 5 node(s) had untolerated taint(s). no new claims to deallocate, preemption: 0/6 nodes are available: 1 No preemption victims found for incoming pod, 5 Preemption is not helpful for scheduling."
60.1844,Job,ADDED,eval-sanitize-2-r1-044,
60.1858,Pod,ADDED,eval-sanitize-2-r1-043-qdbxg,phase=Succeeded node=kind-worker
60.186,Event,ADDED,eval-sanitize-2-r1-026-88m8g.18d420e139c1d8d7,reason=Scheduled count=None msg=Successfully assigned compute/eval-sanitize-2-r1-026-88m8g to kind-worker2
60.1862,Event,ADDED,eval-sanitize-2-r1-026-88m8g.18d420e152a19bc2,"reason=Pulled count=1 msg=Container image ""busybox:musl"" already present on machine"
60.1864,Event,ADDED,eval-sanitize-2-r1-026-88m8g.18d420e154184b26,reason=Created count=1 msg=Created container: task
60.1879,Pod,ADDED,eval-sanitize-2-r1-044-nh4hg,phase=Succeeded node=kind-worker4
60.1886,Job,ADDED,eval-sanitize-2-r1-045,
60.1889,Event,ADDED,eval-sanitize-2-r1-026-88m8g.18d420e1565df69c,reason=Started count=1 msg=Started container task
60.1891,Event,ADDED,eval-sanitize-2-r1-026.18d420e0adbb54ec,reason=SuccessfulCreate count=1 msg=Created pod: eval-sanitize-2-r1-026-88m8g
60.1893,Event,ADDED,eval-sanitize-2-r1-026.18d420e48fce6871,reason=Completed count=1 msg=Job completed
60.1894,Event,ADDED,eval-sanitize-2-r1-027-622v9.18d420e0ea9cd894,reason=Scheduled count=None msg=Successfully assigned compute/eval-sanitize-2-r1-027-622v9 to kind-worker3
60.19,Event,ADDED,eval-sanitize-2-r1-027-622v9.18d420e103c9033d,"reason=Pulled count=1 msg=Container image ""busybox:musl"" already present on machine"
60.1902,Event,ADDED,eval-sanitize-2-r1-027-622v9.18d420e104d8b530,reason=Created count=1 msg=Created container: task
60.1904,Event,ADDED,eval-sanitize-2-r1-027-622v9.18d420e106e20ecc,reason=Started count=1 msg=Started container task
60.1906,Event,ADDED,eval-sanitize-2-r1-027.18d420e0e96a2f18,reason=SuccessfulCreate count=1 msg=Created pod: eval-sanitize-2-r1-027-622v9
60.1913,Job,ADDED,eval-sanitize-2-r1-046,
60.1917,Event,ADDED,eval-sanitize-2-r1-027.18d420e41b2eed54,reason=Completed count=1 msg=Job completed
60.1919,Event,ADDED,eval-sanitize-2-r1-028-gjgkl.18d420e1250e1eb0,"reason=FailedScheduling count=None msg=0/6 nodes are available: 1 c_wall violated: 1 conflicting context pair(s) with node memory, 5 node(s) had untolerated taint(s). no new claims to deallocate, preemption: 0/6 nodes are available: 1 No preemption victims found for incoming pod, 5 Preemption is not helpful for scheduling."
60.1922,Event,ADDED,eval-sanitize-2-r1-028-gjgkl.18d420e125a400b5,"reason=FailedScheduling count=None msg=0/6 nodes are available: 1 c_wall violated: 1 conflicting context pair(s) with node memory, 5 node(s) had untolerated taint(s). no new claims to deallocate, preemption: 0/6 nodes are available: 1 No preemption victims found for incoming pod, 5 Preemption is not helpful for scheduling."
60.1932,Pod,ADDED,eval-sanitize-2-r1-045-ph5q2,phase=Succeeded node=kind-worker4
60.1936,Event,ADDED,eval-sanitize-2-r1-028-gjgkl.18d420e13d88d5d8,reason=Scheduled count=None msg=Successfully assigned compute/eval-sanitize-2-r1-028-gjgkl to kind-worker2
60.1938,Event,ADDED,eval-sanitize-2-r1-028-gjgkl.18d420e154beea21,"reason=Pulled count=1 msg=Container image ""busybox:musl"" already present on machine"
60.1939,Event,ADDED,eval-sanitize-2-r1-028-gjgkl.18d420e155ffa74c,reason=Created count=1 msg=Created container: task
60.1941,Event,ADDED,eval-sanitize-2-r1-028-gjgkl.18d420e15917e447,reason=Started count=1 msg=Started container task
60.1952,Pod,ADDED,eval-sanitize-2-r1-046-qpmdw,phase=Running node=kind-worker2
60.1958,Job,ADDED,eval-sanitize-2-r1-047,
60.1961,Event,ADDED,eval-sanitize-2-r1-028.18d420e124d3153b,reason=SuccessfulCreate count=1 msg=Created pod: eval-sanitize-2-r1-028-gjgkl
60.1963,Event,ADDED,eval-sanitize-2-r1-028.18d420e48ed95a5c,reason=Completed count=1 msg=Job completed
60.1965,Event,ADDED,eval-sanitize-2-r1-029-vwzxl.18d420e1617c19b4,"reason=FailedScheduling count=None msg=0/6 nodes are available: 1 c_wall violated: 3 conflicting context pair(s) with node memory, 5 node(s) had untolerated taint(s). no new claims to deallocate, preemption: 0/6 nodes are available: 1 No preemption victims found for incoming pod, 5 Preemption is not helpful for scheduling."
60.1976,Job,ADDED,eval-sanitize-2-r1-048,
60.1979,Event,ADDED,eval-sanitize-2-r1-029-vwzxl.18d420e161f9251b,"reason=FailedScheduling count=None msg=0/6 nodes are available: 1 c_wall violated: 3 conflicting context pair(s) with node memory, 5 node(s) had untolerated taint(s). no new claims to deallocate, preemption: 0/6 nodes are available: 1 No preemption victims found for incoming pod, 5 Preemption is not helpful for scheduling."
60.1981,Event,ADDED,eval-sanitize-2-r1-029-vwzxl.18d420e1e02a10d0,reason=Scheduled count=None msg=Successfully assigned compute/eval-sanitize-2-r1-029-vwzxl to kind-worker
60.1982,Event,ADDED,eval-sanitize-2-r1-029-vwzxl.18d420e1f7ff1462,"reason=Pulled count=1 msg=Container image ""busybox:musl"" already present on machine"
60.1993,Pod,ADDED,eval-sanitize-2-r1-047-v644x,phase=Succeeded node=kind-worker4
60.1996,Event,ADDED,eval-sanitize-2-r1-029-vwzxl.18d420e1f96b3c65,reason=Created count=1 msg=Created container: task
60.1997,Event,ADDED,eval-sanitize-2-r1-029-vwzxl.18d420e1fb76345d,reason=Started count=1 msg=Started container task
60.1999,Event,ADDED,eval-sanitize-2-r1-029.18d420e1612b847e,reason=SuccessfulCreate count=1 msg=Created pod: eval-sanitize-2-r1-029-vwzxl
60.2001,Event,ADDED,eval-sanitize-2-r1-029.18d420e533861e79,reason=Completed count=1 msg=Job completed
60.2002,Event,ADDED,eval-sanitize-2-r1-030-2q542.18d420e19caae83a,"reason=FailedScheduling count=None msg=0/6 nodes are available: 1 c_wall violated: 3 conflicting context pair(s) with node memory, 5 node(s) had untolerated taint(s). no new claims to deallocate, preemption: 0/6 nodes are available: 1 No preemption victims found for incoming pod, 5 Preemption is not helpful for scheduling."
60.2004,Event,ADDED,eval-sanitize-2-r1-030-2q542.18d420e19d3b7afd,"reason=FailedScheduling count=None msg=0/6 nodes are available: 1 c_wall violated: 3 conflicting context pair(s) with node memory, 5 node(s) had untolerated taint(s). no new claims to deallocate, preemption: 0/6 nodes are available: 1 No preemption victims found for incoming pod, 5 Preemption is not helpful for scheduling."
60.2006,Event,ADDED,eval-sanitize-2-r1-030-2q542.18d420e1e0146a5a,"reason=FailedScheduling count=None msg=0/6 nodes are available: 1 c_wall violated: 1 conflicting context pair(s) with node memory, 5 node(s) had untolerated taint(s). no new claims to deallocate, preemption: 0/6 nodes are available: 1 No preemption victims found for incoming pod, 5 Preemption is not helpful for scheduling."
60.2008,Event,ADDED,eval-sanitize-2-r1-030-2q542.18d420e1e1341680,"reason=FailedScheduling count=None msg=0/6 nodes are available: 1 c_wall violated: 1 conflicting context pair(s) with node memory, 5 node(s) had untolerated taint(s). no new claims to deallocate, preemption: 0/6 nodes are available: 1 No preemption victims found for incoming pod, 5 Preemption is not helpful for scheduling."
60.2009,Event,ADDED,eval-sanitize-2-r1-030-2q542.18d420e1f8cd9f4e,reason=Scheduled count=None msg=Successfully assigned compute/eval-sanitize-2-r1-030-2q542 to kind-worker4
60.2011,Event,ADDED,eval-sanitize-2-r1-030-2q542.18d420e2121d357d,"reason=Pulled count=1 msg=Container image ""busybox:musl"" already present on machine"
60.2014,Event,ADDED,eval-sanitize-2-r1-030-2q542.18d420e2144d126d,reason=Created count=1 msg=Created container: task
60.2025,Pod,ADDED,eval-sanitize-2-r1-048-6852f,phase=Running node=kind-worker2
60.203,Job,ADDED,eval-sanitize-2-r1-049,
60.2034,Event,ADDED,eval-sanitize-2-r1-030-2q542.18d420e216b96329,reason=Started count=1 msg=Started container task
60.2036,Event,ADDED,eval-sanitize-2-r1-030.18d420e19c5192fb,reason=SuccessfulCreate count=1 msg=Created pod: eval-sanitize-2-r1-030-2q542
60.2038,Event,ADDED,eval-sanitize-2-r1-030.18d420e52cbeccf3,reason=Completed count=1 msg=Job completed
60.2045,Job,ADDED,eval-sanitize-2-r1-050,
60.2048,Event,ADDED,eval-sanitize-2-r1-031-rq4sb.18d420e1d7fe2353,"reason=FailedScheduling count=None msg=0/6 nodes are available: 6 node(s) had untolerated taint(s). no new claims to deallocate, preemption: 0/6 nodes are available: 6 Preemption is not helpful for scheduling."
60.205,Event,ADDED,eval-sanitize-2-r1-031-rq4sb.18d420e1e0ada46f,"reason=FailedScheduling count=None msg=0/6 nodes are available: 1 c_wall violated: 1 conflicting context pair(s) with node memory, 5 node(s) had untolerated taint(s). no new claims to deallocate, preemption: 0/6 nodes are available: 1 No preemption victims found for incoming pod, 5 Preemption is not helpful for scheduling."
60.2055,Event,ADDED,eval-sanitize-2-r1-031-rq4sb.18d420e1e1692c41,"reason=FailedScheduling count=None msg=0/6 nodes are available: 1 c_wall violated: 1 conflicting context pair(s) with node memory, 5 node(s) had untolerated taint(s). no new claims to deallocate, preemption: 0/6 nodes are available: 1 No preemption victims found for incoming pod, 5 Preemption is not helpful for scheduling."
60.2065,Pod,ADDED,eval-sanitize-2-r1-049-lmphz,phase=Running node=kind-worker5
60.2068,Event,ADDED,eval-sanitize-2-r1-031-rq4sb.18d420e1f8692c71,reason=Scheduled count=None msg=Successfully assigned compute/eval-sanitize-2-r1-031-rq4sb to kind-worker4
60.207,Event,ADDED,eval-sanitize-2-r1-031-rq4sb.18d420e211ff2921,"reason=Pulled count=1 msg=Container image ""busybox:musl"" already present on machine"
60.2071,Event,ADDED,eval-sanitize-2-r1-031-rq4sb.18d420e2139819a9,reason=Created count=1 msg=Created container: task
60.2073,Event,ADDED,eval-sanitize-2-r1-031-rq4sb.18d420e216582ac8,reason=Started count=1 msg=Started container task
60.2084,Pod,ADDED,eval-sanitize-2-r1-050-qkt2f,phase=Running node=kind-worker2
60.2091,Job,ADDED,eval-sanitize-2-r1-051,
60.2093,Event,ADDED,eval-sanitize-2-r1-031.18d420e1d7ef1d33,reason=SuccessfulCreate count=1 msg=Created pod: eval-sanitize-2-r1-031-rq4sb
60.2095,Event,ADDED,eval-sanitize-2-r1-031.18d420e52d590535,reason=Completed count=1 msg=Job completed
60.2097,Event,ADDED,eval-sanitize-2-r1-032-cjptq.18d420e213ef8a0e,"reason=FailedScheduling count=None msg=0/6 nodes are available: 2 c_wall violated: 1 conflicting context pair(s) with node memory, 4 node(s) had untolerated taint(s). no new claims to deallocate, preemption: 0/6 nodes are available: 2 No preemption victims found for incoming pod, 4 Preemption is not helpful for scheduling."
60.2104,Job,ADDED,eval-sanitize-2-r1-052,
60.2106,Event,ADDED,eval-sanitize-2-r1-032-cjptq.18d420e215780e94,"reason=FailedScheduling count=None msg=0/6 nodes are available: 2 c_wall violated: 1 conflicting context pair(s) with node memory, 4 node(s) had untolerated taint(s). no new claims to deallocate, preemption: 0/6 nodes are available: 2 No preemption victims found for incoming pod, 4 Preemption is not helpful for scheduling."
60.2108,Event,ADDED,eval-sanitize-2-r1-032-cjptq.18d420e258eaf3e4,"reason=FailedScheduling count=None msg=0/6 nodes are available: 1 c_wall violated: 1 conflicting context pair(s) with node memory, 5 node(s) had untolerated taint(s). no new claims to deallocate, preemption: 0/6 nodes are available: 1 No preemption victims found for incoming pod, 5 Preemption is not helpful for scheduling."
60.211,Event,ADDED,eval-sanitize-2-r1-032-cjptq.18d420e3bccb601e,reason=Scheduled count=None msg=Successfully assigned compute/eval-sanitize-2-r1-032-cjptq to kind-worker3
60.2112,Event,ADDED,eval-sanitize-2-r1-032-cjptq.18d420e3d60c6656,"reason=Pulled count=1 msg=Container image ""busybox:musl"" already present on machine"
60.2124,Pod,ADDED,eval-sanitize-2-r1-051-2k9qx,phase=Running node=kind-worker2
60.2135,Pod,ADDED,eval-sanitize-2-r1-052-hlv5q,phase=Running node=kind-worker2
60.2138,Event,ADDED,eval-sanitize-2-r1-032-cjptq.18d420e3d7a26145,reason=Created count=1 msg=Created container: task
60.2141,Event,ADDED,eval-sanitize-2-r1-032-cjptq.18d420e3db72be37,reason=Started count=1 msg=Started container task
60.2143,Event,ADDED,eval-sanitize-2-r1-032.18d420e2137c9720,reason=SuccessfulCreate count=1 msg=Created pod: eval-sanitize-2-r1-032-cjptq
60.2149,Job,ADDED,eval-sanitize-2-r1-053,
60.2152,Event,ADDED,eval-sanitize-2-r1-032.18d420e6e87e9cf8,reason=Completed count=1 msg=Job completed
60.2154,Event,ADDED,eval-sanitize-2-r1-033-895m8.18d420e24fa7a668,reason=Scheduled count=None msg=Successfully assigned compute/eval-sanitize-2-r1-033-895m8 to kind-worker4
60.2157,Event,ADDED,eval-sanitize-2-r1-033-895m8.18d420e26927548c,"reason=Pulled count=1 msg=Container image ""busybox:musl"" already present on machine"
60.2159,Event,ADDED,eval-sanitize-2-r1-033-895m8.18d420e26a291e20,reason=Created count=1 msg=Created container: task
60.2165,Job,ADDED,eval-sanitize-2-r1-054,
60.2177,Pod,ADDED,eval-sanitize-2-r1-053-plshx,phase=Running node=kind-worker2
60.218,Event,ADDED,eval-sanitize-2-r1-033-895m8.18d420e26c11c99b,reason=Started count=1 msg=Started container task
60.2181,Event,ADDED,eval-sanitize-2-r1-033.18d420e24efe9332,reason=SuccessfulCreate count=1 msg=Created pod: eval-sanitize-2-r1-033-895m8
60.2183,Event,ADDED,eval-sanitize-2-r1-033.18d420e5a4be5d72,reason=Completed count=1 msg=Job completed
60.2194,Pod,ADDED,eval-sanitize-2-r1-054-w4wn7,phase=Running node=kind-worker3
60.2205,Pod,ADDED,eval-sanitize-2-r1-055-nz9p5,phase=Running node=kind-worker3
60.2211,Job,ADDED,eval-sanitize-2-r1-055,
60.2214,Event,ADDED,eval-sanitize-2-r1-034-bkxtk.18d420e28a947202,"reason=FailedScheduling count=None msg=0/6 nodes are available: 6 node(s) had untolerated taint(s). no new claims to deallocate, preemption: 0/6 nodes are available: 6 Preemption is not helpful for scheduling."
60.2216,Event,ADDED,eval-sanitize-2-r1-034-bkxtk.18d420e3bd0168fe,"reason=FailedScheduling count=None msg=0/6 nodes are available: 1 c_wall violated: 1 conflicting context pair(s) with node memory, 5 node(s) had untolerated taint(s). no new claims to deallocate, preemption: 0/6 nodes are available: 1 No preemption victims found for incoming pod, 5 Preemption is not helpful for scheduling."
60.2218,Event,ADDED,eval-sanitize-2-r1-034-bkxtk.18d420e3c10fd132,"reason=FailedScheduling count=None msg=0/6 nodes are available: 1 c_wall violated: 3 conflicting context pair(s) with node memory, 5 node(s) had untolerated taint(s). no new claims to deallocate, preemption: 0/6 nodes are available: 1 No preemption victims found for incoming pod, 5 Preemption is not helpful for scheduling."
60.223,Pod,ADDED,eval-sanitize-2-r1-056-kmcc9,phase=Running node=kind-worker
60.2236,Job,ADDED,eval-sanitize-2-r1-056,
60.224,Event,ADDED,eval-sanitize-2-r1-034-bkxtk.18d420e3c3fc6bef,"reason=FailedScheduling count=None msg=0/6 nodes are available: 1 c_wall violated: 3 conflicting context pair(s) with node memory, 5 node(s) had untolerated taint(s). no new claims to deallocate, preemption: 0/6 nodes are available: 1 No preemption victims found for incoming pod, 5 Preemption is not helpful for scheduling."
60.2242,Event,ADDED,eval-sanitize-2-r1-034-bkxtk.18d420e4214a035c,reason=Scheduled count=None msg=Successfully assigned compute/eval-sanitize-2-r1-034-bkxtk to kind-worker5
60.2245,Event,ADDED,eval-sanitize-2-r1-034-bkxtk.18d420e43a960e33,"reason=Pulled count=1 msg=Container image ""busybox:musl"" already present on machine"
60.2247,Event,ADDED,eval-sanitize-2-r1-034-bkxtk.18d420e43bc293ee,reason=Created count=1 msg=Created container: task
60.2258,Pod,ADDED,eval-sanitize-2-r1-057-n6fs2,phase=Running node=kind-worker
60.2261,Event,ADDED,eval-sanitize-2-r1-034-bkxtk.18d420e43fb65c9b,reason=Started count=1 msg=Started container task
60.2262,Event,ADDED,eval-sanitize-2-r1-034.18d420e28a84c161,reason=SuccessfulCreate count=1 msg=Created pod: eval-sanitize-2-r1-034-bkxtk
60.2264,Event,ADDED,eval-sanitize-2-r1-034.18d420e784bbc6be,reason=Completed count=1 msg=Job completed
60.2266,Event,ADDED,eval-sanitize-2-r1-035-7rwtd.18d420e2c667b4b5,"reason=FailedScheduling count=None msg=0/6 nodes are available: 6 node(s) had untolerated taint(s). no new claims to deallocate, preemption: 0/6 nodes are available: 6 Preemption is not helpful for scheduling."
60.2278,Pod,ADDED,eval-sanitize-2-r1-058-6nf7f,phase=Running node=kind-worker
60.2281,Event,ADDED,eval-sanitize-2-r1-035-7rwtd.18d420e3bdd5fe36,reason=Scheduled count=None msg=Successfully assigned compute/eval-sanitize-2-r1-035-7rwtd to kind-worker3
60.2282,Event,ADDED,eval-sanitize-2-r1-035-7rwtd.18d420e3d6e90674,"reason=Pulled count=1 msg=Container image ""busybox:musl"" already present on machine"
60.2284,Event,ADDED,eval-sanitize-2-r1-035-7rwtd.18d420e3d852d15a,reason=Created count=1 msg=Created container: task
60.229,Job,ADDED,eval-sanitize-2-r1-057,
60.2297,Pod,ADDED,eval-sanitize-2-r1-059-j7flz,phase=Pending node=None
60.23,Event,ADDED,eval-sanitize-2-r1-035-7rwtd.18d420e3dbbf4b61,reason=Started count=1 msg=Started container task
60.2303,Event,ADDED,eval-sanitize-2-r1-035.18d420e2c65ac44d,reason=SuccessfulCreate count=1 msg=Created pod: eval-sanitize-2-r1-035-7rwtd
60.2306,Event,ADDED,eval-sanitize-2-r1-035.18d420e6e91b4f6f,reason=Completed count=1 msg=Job completed
60.2307,Event,ADDED,eval-sanitize-2-r1-036-qp2wz.18d420e301dae957,"reason=FailedScheduling count=None msg=0/6 nodes are available: 6 node(s) had untolerated taint(s). no new claims to deallocate, preemption: 0/6 nodes are available: 6 Preemption is not helpful for scheduling."
60.2314,Job,ADDED,eval-sanitize-2-r1-058,
60.2317,Event,ADDED,eval-sanitize-2-r1-036-qp2wz.18d420e3bdb9069c,"reason=FailedScheduling count=None msg=0/6 nodes are available: 1 c_wall violated: 1 conflicting context pair(s) with node memory, 5 node(s) had untolerated taint(s). no new claims to deallocate, preemption: 0/6 nodes are available: 1 No preemption victims found for incoming pod, 5 Preemption is not helpful for scheduling."
60.2319,Event,ADDED,eval-sanitize-2-r1-036-qp2wz.18d420e3c1925963,"reason=FailedScheduling count=None msg=0/6 nodes are available: 1 c_wall violated: 2 conflicting context pair(s) with node memory, 5 node(s) had untolerated taint(s). no new claims to deallocate, preemption: 0/6 nodes are available: 1 No preemption victims found for incoming pod, 5 Preemption is not helpful for scheduling."
60.2321,Event,ADDED,eval-sanitize-2-r1-036-qp2wz.18d420e3c424f213,"reason=FailedScheduling count=None msg=0/6 nodes are available: 1 c_wall violated: 2 conflicting context pair(s) with node memory, 5 node(s) had untolerated taint(s). no new claims to deallocate, preemption: 0/6 nodes are available: 1 No preemption victims found for incoming pod, 5 Preemption is not helpful for scheduling."
60.2328,Pod,ADDED,eval-sanitize-2-r1-060-m876n,phase=Pending node=None
60.2331,Event,ADDED,eval-sanitize-2-r1-036-qp2wz.18d420e4267d96ae,"reason=FailedScheduling count=None msg=0/6 nodes are available: 1 c_wall violated: 1 conflicting context pair(s) with node memory, 1 c_wall violated: 2 conflicting context pair(s) with node memory, 4 node(s) had untolerated taint(s). no new claims to deallocate, preemption: 0/6 nodes are available: 2 No preemption victims found for incoming pod, 4 Preemption is not helpful for scheduling."
60.2333,Event,ADDED,eval-sanitize-2-r1-036-qp2wz.18d420e432bf0986,reason=Scheduled count=None msg=Successfully assigned compute/eval-sanitize-2-r1-036-qp2wz to kind-worker2
60.2335,Event,ADDED,eval-sanitize-2-r1-036-qp2wz.18d420e44b15e15b,"reason=Pulled count=1 msg=Container image ""busybox:musl"" already present on machine"
60.2337,Event,ADDED,eval-sanitize-2-r1-036-qp2wz.18d420e44c332afd,reason=Created count=1 msg=Created container: task
60.2338,Event,ADDED,eval-sanitize-2-r1-036-qp2wz.18d420e45040a55d,reason=Started count=1 msg=Started container task
60.234,Event,ADDED,eval-sanitize-2-r1-036.18d420e301ccb5a2,reason=SuccessfulCreate count=1 msg=Created pod: eval-sanitize-2-r1-036-qp2wz
60.2342,Event,ADDED,eval-sanitize-2-r1-036.18d420e75bd9d38b,reason=Completed count=1 msg=Job completed
60.2343,Event,ADDED,eval-sanitize-2-r1-037-7pl9w.18d420e33d753ffe,"reason=FailedScheduling count=None msg=0/6 nodes are available: 6 node(s) had untolerated taint(s). no new claims to deallocate, preemption: 0/6 nodes are available: 6 Preemption is not helpful for scheduling."
60.2345,Event,ADDED,eval-sanitize-2-r1-037-7pl9w.18d420e3be2ff648,"reason=FailedScheduling count=None msg=0/6 nodes are available: 1 c_wall violated: 2 conflicting context pair(s) with node memory, 5 node(s) had untolerated taint(s). no new claims to deallocate, preemption: 0/6 nodes are available: 1 No preemption victims found for incoming pod, 5 Preemption is not helpful for scheduling."
60.2346,Event,ADDED,eval-sanitize-2-r1-037-7pl9w.18d420e3c37df05e,"reason=FailedScheduling count=None msg=0/6 nodes are available: 1 c_wall violated: 3 conflicting context pair(s) with node memory, 5 node(s) had untolerated taint(s). no new claims to deallocate, preemption: 0/6 nodes are available: 1 No preemption victims found for incoming pod, 5 Preemption is not helpful for scheduling."
60.2348,Event,ADDED,eval-sanitize-2-r1-037-7pl9w.18d420e3c44e39f7,"reason=FailedScheduling count=None msg=0/6 nodes are available: 1 c_wall violated: 3 conflicting context pair(s) with node memory, 5 node(s) had untolerated taint(s). no new claims to deallocate, preemption: 0/6 nodes are available: 1 No preemption victims found for incoming pod, 5 Preemption is not helpful for scheduling."
60.235,Event,ADDED,eval-sanitize-2-r1-037-7pl9w.18d420e420d06c36,reason=Scheduled count=None msg=Successfully assigned compute/eval-sanitize-2-r1-037-7pl9w to kind-worker5
60.2351,Event,ADDED,eval-sanitize-2-r1-037-7pl9w.18d420e439ae3918,"reason=Pulled count=1 msg=Container image ""busybox:musl"" already present on machine"
60.2353,Event,ADDED,eval-sanitize-2-r1-037-7pl9w.18d420e43b13ecd8,reason=Created count=1 msg=Created container: task
60.2356,Event,ADDED,eval-sanitize-2-r1-037-7pl9w.18d420e43f735a61,reason=Started count=1 msg=Started container task
60.2359,Event,ADDED,eval-sanitize-2-r1-037.18d420e33d6a751e,reason=SuccessfulCreate count=1 msg=Created pod: eval-sanitize-2-r1-037-7pl9w
60.2392,Event,ADDED,eval-sanitize-2-r1-037.18d420e784bc26d4,reason=Completed count=1 msg=Job completed
60.2398,Job,ADDED,eval-sanitize-2-r1-059,
60.2401,Job,ADDED,eval-sanitize-2-r1-060,
60.241,Pod,MODIFIED,eval-sanitize-2-r1-060-m876n,phase=Pending node=None
60.2413,Event,ADDED,eval-sanitize-2-r1-038-f2884.18d420e3790440de,"reason=FailedScheduling count=None msg=0/6 nodes are available: 6 node(s) had untolerated taint(s). no new claims to deallocate, preemption: 0/6 nodes are available: 6 Preemption is not helpful for scheduling."
60.2414,Event,ADDED,eval-sanitize-2-r1-038-f2884.18d420e3bf2d8df2,reason=Scheduled count=None msg=Successfully assigned compute/eval-sanitize-2-r1-038-f2884 to kind-worker3
60.2416,Event,ADDED,eval-sanitize-2-r1-038-f2884.18d420e3dbd540fb,"reason=Pulled count=1 msg=Container image ""busybox:musl"" already present on machine"
60.2418,Event,ADDED,eval-sanitize-2-r1-038-f2884.18d420e3dd575544,reason=Created count=1 msg=Created container: task
60.2421,Event,ADDED,eval-sanitize-2-r1-038-f2884.18d420e3e9f22c3d,reason=Started count=1 msg=Started container task
60.2424,Event,ADDED,eval-sanitize-2-r1-038.18d420e378fb76c6,reason=SuccessfulCreate count=1 msg=Created pod: eval-sanitize-2-r1-038-f2884
60.2426,Event,ADDED,eval-sanitize-2-r1-038.18d420e72548324c,reason=Completed count=1 msg=Job completed
60.2431,Job,MODIFIED,eval-sanitize-2-r1-060,
60.2433,Event,ADDED,eval-sanitize-2-r1-039-thkjq.18d420e3b4d4571e,"reason=FailedScheduling count=None msg=0/6 nodes are available: 6 node(s) had untolerated taint(s). no new claims to deallocate, preemption: 0/6 nodes are available: 6 Preemption is not helpful for scheduling."
60.2435,Event,ADDED,eval-sanitize-2-r1-039-thkjq.18d420e3bf4de1e2,reason=Scheduled count=None msg=Successfully assigned compute/eval-sanitize-2-r1-039-thkjq to kind-worker3
60.2437,Event,ADDED,eval-sanitize-2-r1-039-thkjq.18d420e3dac9b517,"reason=Pulled count=1 msg=Container image ""busybox:musl"" already present on machine"
60.2438,Event,ADDED,eval-sanitize-2-r1-039-thkjq.18d420e3dc6a92e0,reason=Created count=1 msg=Created container: task
60.2442,Event,ADDED,eval-sanitize-2-r1-039-thkjq.18d420e3e981b3c5,reason=Started count=1 msg=Started container task
60.2443,Event,ADDED,eval-sanitize-2-r1-039.18d420e3b4cd03e3,reason=SuccessfulCreate count=1 msg=Created pod: eval-sanitize-2-r1-039-thkjq
60.2445,Event,ADDED,eval-sanitize-2-r1-039.18d420e72509e818,reason=Completed count=1 msg=Job completed
60.2447,Event,ADDED,eval-sanitize-2-r1-040-8rcmf.18d420e3f0f2c740,reason=Scheduled count=None msg=Successfully assigned compute/eval-sanitize-2-r1-040-8rcmf to kind-worker3
60.2449,Event,ADDED,eval-sanitize-2-r1-040-8rcmf.18d420e40a54a6f1,"reason=Pulled count=1 msg=Container image ""busybox:musl"" already present on machine"
60.2451,Event,ADDED,eval-sanitize-2-r1-040-8rcmf.18d420e40b6e74b5,reason=Created count=1 msg=Created container: task
60.2452,Event,ADDED,eval-sanitize-2-r1-040-8rcmf.18d420e40f6b3ce6,reason=Started count=1 msg=Started container task
60.2454,Event,ADDED,eval-sanitize-2-r1-040.18d420e3f058ef4e,reason=SuccessfulCreate count=1 msg=Created pod: eval-sanitize-2-r1-040-8rcmf
60.2456,Event,ADDED,eval-sanitize-2-r1-040.18d420e725829bcd,reason=Completed count=1 msg=Job completed
60.2457,Event,ADDED,eval-sanitize-2-r1-041-2kf6h.18d420e42d1e5c9e,reason=Scheduled count=None msg=Successfully assigned compute/eval-sanitize-2-r1-041-2kf6h to kind-worker5
60.2459,Event,ADDED,eval-sanitize-2-r1-041-2kf6h.18d420e446376725,"reason=Pulled count=1 msg=Container image ""busybox:musl"" already present on machine"
60.2461,Event,ADDED,eval-sanitize-2-r1-041-2kf6h.18d420e447932a90,reason=Created count=1 msg=Created container: task
60.2469,Job,MODIFIED,eval-sanitize-2-r1-058,
60.2482,Job,MODIFIED,eval-sanitize-2-r1-059,
60.2489,Job,MODIFIED,eval-sanitize-2-r1-058,
60.2491,Event,ADDED,eval-sanitize-2-r1-041-2kf6h.18d420e44ac2540e,reason=Started count=1 msg=Started container task
60.2494,Event,ADDED,eval-sanitize-2-r1-041.18d420e42bd9f38f,reason=SuccessfulCreate count=1 msg=Created pod: eval-sanitize-2-r1-041-2kf6h
60.2495,Event,ADDED,eval-sanitize-2-r1-041.18d420e7843cd616,reason=Completed count=1 msg=Job completed
60.2499,Event,ADDED,eval-sanitize-2-r1-042-9wtgn.18d420e467f38cdf,"reason=FailedScheduling count=None msg=0/6 nodes are available: 1 c_wall violated: 1 conflicting context pair(s) with node memory, 1 c_wall violated: 2 conflicting context pair(s) with node memory, 4 node(s) had untolerated taint(s). no new claims to deallocate, preemption: 0/6 nodes are available: 2 No preemption victims found for incoming pod, 4 Preemption is not helpful for scheduling."
60.2503,Event,ADDED,eval-sanitize-2-r1-042-9wtgn.18d420e468a5d8d3,"reason=FailedScheduling count=None msg=0/6 nodes are available: 1 c_wall violated: 1 conflicting context pair(s) with node memory, 1 c_wall violated: 2 conflicting context pair(s) with node memory, 4 node(s) had untolerated taint(s). no new claims to deallocate, preemption: 0/6 nodes are available: 2 No preemption victims found for incoming pod, 4 Preemption is not helpful for scheduling."
60.251,Job,MODIFIED,eval-sanitize-2-r1-059,
60.2513,Event,ADDED,eval-sanitize-2-r1-042-9wtgn.18d420e498fc078b,"reason=FailedScheduling count=None msg=0/6 nodes are available: 1 c_wall violated: 1 conflicting context pair(s) with node memory, 5 node(s) had untolerated taint(s). no new claims to deallocate, preemption: 0/6 nodes are available: 1 No preemption victims found for incoming pod, 5 Preemption is not helpful for scheduling."
60.2515,Event,ADDED,eval-sanitize-2-r1-042-9wtgn.18d420e4ce8fdee1,reason=Scheduled count=None msg=Successfully assigned compute/eval-sanitize-2-r1-042-9wtgn to kind-worker
60.2517,Event,ADDED,eval-sanitize-2-r1-042-9wtgn.18d420e4e8bff0be,"reason=Pulled count=1 msg=Container image ""busybox:musl"" already present on machine"
60.2519,Event,ADDED,eval-sanitize-2-r1-042-9wtgn.18d420e4ea5c4653,reason=Created count=1 msg=Created container: task
60.2522,Event,ADDED,eval-sanitize-2-r1-042-9wtgn.18d420e4ec6c576b,reason=Started count=1 msg=Started container task
60.2524,Event,ADDED,eval-sanitize-2-r1-042.18d420e46780dd96,reason=SuccessfulCreate count=1 msg=Created pod: eval-sanitize-2-r1-042-9wtgn
60.2526,Event,ADDED,eval-sanitize-2-r1-042.18d420e8015e2d02,reason=Completed count=1 msg=Job completed
60.2528,Event,ADDED,eval-sanitize-2-r1-043-qdbxg.18d420e4a34f20fa,"reason=FailedScheduling count=None msg=0/6 nodes are available: 1 c_wall violated: 1 conflicting context pair(s) with node memory, 5 node(s) had untolerated taint(s). no new claims to deallocate, preemption: 0/6 nodes are available: 1 No preemption victims found for incoming pod, 5 Preemption is not helpful for scheduling."
60.2531,Event,ADDED,eval-sanitize-2-r1-043-qdbxg.18d420e4a3d5473c,"reason=FailedScheduling count=None msg=0/6 nodes are available: 1 c_wall violated: 1 conflicting context pair(s) with node memory, 5 node(s) had untolerated taint(s). no new claims to deallocate, preemption: 0/6 nodes are available: 1 No preemption victims found for incoming pod, 5 Preemption is not helpful for scheduling."
60.2533,Event,ADDED,eval-sanitize-2-r1-043-qdbxg.18d420e4ceba1671,reason=Scheduled count=None msg=Successfully assigned compute/eval-sanitize-2-r1-043-qdbxg to kind-worker
60.2536,Event,ADDED,eval-sanitize-2-r1-043-qdbxg.18d420e4e8a8c441,"reason=Pulled count=1 msg=Container image ""busybox:musl"" already present on machine"
60.2541,Event,ADDED,eval-sanitize-2-r1-043-qdbxg.18d420e4e9f5c2d3,reason=Created count=1 msg=Created container: task
60.2543,Event,ADDED,eval-sanitize-2-r1-043-qdbxg.18d420e4ec15a0bc,reason=Started count=1 msg=Started container task
60.2545,Event,ADDED,eval-sanitize-2-r1-043.18d420e4a30c0788,reason=SuccessfulCreate count=1 msg=Created pod: eval-sanitize-2-r1-043-qdbxg
60.2547,Event,ADDED,eval-sanitize-2-r1-043.18d420e8008350af,reason=Completed count=1 msg=Job completed
60.255,Event,ADDED,eval-sanitize-2-r1-044-nh4hg.18d420e4dedb78f4,"reason=FailedScheduling count=None msg=0/6 nodes are available: 1 c_wall violated: 1 conflicting context pair(s) with node memory, 5 node(s) had untolerated taint(s). no new claims to deallocate, preemption: 0/6 nodes are available: 1 No preemption victims found for incoming pod, 5 Preemption is not helpful for scheduling."
60.2552,Event,ADDED,eval-sanitize-2-r1-044-nh4hg.18d420e4df5dd8a6,"reason=FailedScheduling count=None msg=0/6 nodes are available: 1 c_wall violated: 1 conflicting context pair(s) with node memory, 5 node(s) had untolerated taint(s). no new claims to deallocate, preemption: 0/6 nodes are available: 1 No preemption victims found for incoming pod, 5 Preemption is not helpful for scheduling."
60.2554,Event,ADDED,eval-sanitize-2-r1-044-nh4hg.18d420e562b366d6,reason=Scheduled count=None msg=Successfully assigned compute/eval-sanitize-2-r1-044-nh4hg to kind-worker4
60.2557,Event,ADDED,eval-sanitize-2-r1-044-nh4hg.18d420e57c978f57,"reason=Pulled count=1 msg=Container image ""busybox:musl"" already present on machine"
60.2559,Event,ADDED,eval-sanitize-2-r1-044-nh4hg.18d420e57de4ecd7,reason=Created count=1 msg=Created container: task
60.2561,Event,ADDED,eval-sanitize-2-r1-044-nh4hg.18d420e57fe90fbf,reason=Started count=1 msg=Started container task
60.2564,Event,ADDED,eval-sanitize-2-r1-044.18d420e4dea15172,reason=SuccessfulCreate count=1 msg=Created pod: eval-sanitize-2-r1-044-nh4hg
60.2566,Event,ADDED,eval-sanitize-2-r1-045-ph5q2.18d420e51a943f63,"reason=FailedScheduling count=None msg=0/6 nodes are available: 1 c_wall violated: 2 conflicting context pair(s) with node memory, 5 node(s) had untolerated taint(s). no new claims to deallocate, preemption: 0/6 nodes are available: 1 No preemption victims found for incoming pod, 5 Preemption is not helpful for scheduling."
60.2568,Event,ADDED,eval-sanitize-2-r1-045-ph5q2.18d420e51b19bc75,"reason=FailedScheduling count=None msg=0/6 nodes are available: 1 c_wall violated: 2 conflicting context pair(s) with node memory, 5 node(s) had untolerated taint(s). no new claims to deallocate, preemption: 0/6 nodes are available: 1 No preemption victims found for incoming pod, 5 Preemption is not helpful for scheduling."
60.257,Event,ADDED,eval-sanitize-2-r1-045-ph5q2.18d420e5630d076e,reason=Scheduled count=None msg=Successfully assigned compute/eval-sanitize-2-r1-045-ph5q2 to kind-worker4
60.2573,Event,ADDED,eval-sanitize-2-r1-045-ph5q2.18d420e57cb06754,"reason=Pulled count=1 msg=Container image ""busybox:musl"" already present on machine"
60.2576,Event,ADDED,eval-sanitize-2-r1-045-ph5q2.18d420e57e3a3f2d,reason=Created count=1 msg=Created container: task
60.2579,Event,ADDED,eval-sanitize-2-r1-045-ph5q2.18d420e58029b266,reason=Started count=1 msg=Started container task
60.2582,Event,ADDED,eval-sanitize-2-r1-045.18d420e51a4f2bc7,reason=SuccessfulCreate count=1 msg=Created pod: eval-sanitize-2-r1-045-ph5q2
60.2584,Event,ADDED,eval-sanitize-2-r1-046-qpmdw.18d420e555dde073,"reason=FailedScheduling count=None msg=0/6 nodes are available: 6 node(s) had untolerated taint(s). no new claims to deallocate, preemption: 0/6 nodes are available: 6 Preemption is not helpful for scheduling."
60.2586,Event,ADDED,eval-sanitize-2-r1-046-qpmdw.18d420e562e30fb6,"reason=FailedScheduling count=None msg=0/6 nodes are available: 1 c_wall violated: 1 conflicting context pair(s) with node memory, 5 node(s) had untolerated taint(s). no new claims to deallocate, preemption: 0/6 nodes are available: 1 No preemption victims found for incoming pod, 5 Preemption is not helpful for scheduling."
60.259,Event,ADDED,eval-sanitize-2-r1-046-qpmdw.18d420e563df1546,"reason=FailedScheduling count=None msg=0/6 nodes are available: 1 c_wall violated: 1 conflicting context pair(s) with node memory, 5 node(s) had untolerated taint(s). no new claims to deallocate, preemption: 0/6 nodes are available: 1 No preemption victims found for incoming pod, 5 Preemption is not helpful for scheduling."
60.2592,Event,ADDED,eval-sanitize-2-r1-046-qpmdw.18d420e7291f3294,reason=Scheduled count=None msg=Successfully assigned compute/eval-sanitize-2-r1-046-qpmdw to kind-worker2
60.2593,Event,ADDED,eval-sanitize-2-r1-046-qpmdw.18d420e748493950,"reason=Pulled count=1 msg=Container image ""busybox:musl"" already present on machine"
60.2595,Event,ADDED,eval-sanitize-2-r1-046-qpmdw.18d420e74acd7452,reason=Created count=1 msg=Created container: task
60.2599,Event,ADDED,eval-sanitize-2-r1-046-qpmdw.18d420e74dfb1136,reason=Started count=1 msg=Started container task
60.2601,Event,ADDED,eval-sanitize-2-r1-046.18d420e555d19325,reason=SuccessfulCreate count=1 msg=Created pod: eval-sanitize-2-r1-046-qpmdw
60.2603,Event,ADDED,eval-sanitize-2-r1-047-v644x.18d420e59200715d,reason=Scheduled count=None msg=Successfully assigned compute/eval-sanitize-2-r1-047-v644x to kind-worker4
60.2606,Event,ADDED,eval-sanitize-2-r1-047-v644x.18d420e5aa28de5d,"reason=Pulled count=1 msg=Container image ""busybox:musl"" already present on machine"
60.2608,Event,ADDED,eval-sanitize-2-r1-047-v644x.18d420e5ab2eed72,reason=Created count=1 msg=Created container: task
60.261,Event,ADDED,eval-sanitize-2-r1-047-v644x.18d420e5ad102b58,reason=Started count=1 msg=Started container task
60.2612,Event,ADDED,eval-sanitize-2-r1-047.18d420e59177b027,reason=SuccessfulCreate count=1 msg=Created pod: eval-sanitize-2-r1-047-v644x
60.2616,Event,ADDED,eval-sanitize-2-r1-048-6852f.18d420e5cd403db6,"reason=FailedScheduling count=None msg=0/6 nodes are available: 1 c_wall violated: 1 conflicting context pair(s) with node memory, 5 node(s) had untolerated taint(s). no new claims to deallocate, preemption: 0/6 nodes are available: 1 No preemption victims found for incoming pod, 5 Preemption is not helpful for scheduling."
60.2618,Event,ADDED,eval-sanitize-2-r1-048-6852f.18d420e5cdd37761,"reason=FailedScheduling count=None msg=0/6 nodes are available: 1 c_wall violated: 1 conflicting context pair(s) with node memory, 5 node(s) had untolerated taint(s). no new claims to deallocate, preemption: 0/6 nodes are available: 1 No preemption victims found for incoming pod, 5 Preemption is not helpful for scheduling."
60.262,Event,ADDED,eval-sanitize-2-r1-048-6852f.18d420e729b2d0c0,reason=Scheduled count=None msg=Successfully assigned compute/eval-sanitize-2-r1-048-6852f to kind-worker2
60.2624,Event,ADDED,eval-sanitize-2-r1-048-6852f.18d420e748776f5f,"reason=Pulled count=1 msg=Container image ""busybox:musl"" already present on machine"
60.2626,Event,ADDED,eval-sanitize-2-r1-048-6852f.18d420e74b65b5dd,reason=Created count=1 msg=Created container: task
60.2627,Event,ADDED,eval-sanitize-2-r1-048-6852f.18d420e74e722149,reason=Started count=1 msg=Started container task
60.2629,Event,ADDED,eval-sanitize-2-r1-048.18d420e5ccfa213a,reason=SuccessfulCreate count=1 msg=Created pod: eval-sanitize-2-r1-048-6852f
60.2632,Event,ADDED,eval-sanitize-2-r1-049-lmphz.18d420e608b12260,"reason=FailedScheduling count=None msg=0/6 nodes are available: 6 node(s) had untolerated taint(s). no new claims to deallocate, preemption: 0/6 nodes are available: 6 Preemption is not helpful for scheduling."
60.2634,Event,ADDED,eval-sanitize-2-r1-049-lmphz.18d420e7299352ee,"reason=FailedScheduling count=None msg=0/6 nodes are available: 1 c_wall violated: 1 conflicting context pair(s) with node memory, 5 node(s) had untolerated taint(s). no new claims to deallocate, preemption: 0/6 nodes are available: 1 No preemption victims found for incoming pod, 5 Preemption is not helpful for scheduling."
60.2641,Event,ADDED,eval-sanitize-2-r1-049-lmphz.18d420e72f96ebc3,"reason=FailedScheduling count=None msg=0/6 nodes are available: 1 c_wall violated: 3 conflicting context pair(s) with node memory, 5 node(s) had untolerated taint(s). no new claims to deallocate, preemption: 0/6 nodes are available: 1 No preemption victims found for incoming pod, 5 Preemption is not helpful for scheduling."
60.2645,Event,ADDED,eval-sanitize-2-r1-049-lmphz.18d420e73051aaa1,"reason=FailedScheduling count=None msg=0/6 nodes are available: 1 c_wall violated: 3 conflicting context pair(s) with node memory, 5 node(s) had untolerated taint(s). no new claims to deallocate, preemption: 0/6 nodes are available: 1 No preemption victims found for incoming pod, 5 Preemption is not helpful for scheduling."
60.2647,Event,ADDED,eval-sanitize-2-r1-049-lmphz.18d420e745a33cb4,"reason=FailedScheduling count=None msg=0/6 nodes are available: 1 c_wall violated: 1 conflicting context pair(s) with node memory, 1 c_wall violated: 3 conflicting context pair(s) with node memory, 4 node(s) had untolerated taint(s). no new claims to deallocate, preemption: 0/6 nodes are available: 2 No preemption victims found for incoming pod, 4 Preemption is not helpful for scheduling."
60.2649,Event,ADDED,eval-sanitize-2-r1-049-lmphz.18d420e7a0eb4cab,reason=Scheduled count=None msg=Successfully assigned compute/eval-sanitize-2-r1-049-lmphz to kind-worker5
60.2651,Event,ADDED,eval-sanitize-2-r1-049-lmphz.18d420e7ba28a712,"reason=Pulled count=1 msg=Container image ""busybox:musl"" already present on machine"
60.2653,Event,ADDED,eval-sanitize-2-r1-049-lmphz.18d420e7bb2fda6c,reason=Created count=1 msg=Created container: task
60.2655,Event,ADDED,eval-sanitize-2-r1-049-lmphz.18d420e7bd1f8794,reason=Started count=1 msg=Started container task
60.2656,Event,ADDED,eval-sanitize-2-r1-049.18d420e608a503ce,reason=SuccessfulCreate count=1 msg=Created pod: eval-sanitize-2-r1-049-lmphz
60.2658,Event,ADDED,eval-sanitize-2-r1-050-qkt2f.18d420e644819f5e,"reason=FailedScheduling count=None msg=0/6 nodes are available: 6 node(s) had untolerated taint(s). no new claims to deallocate, preemption: 0/6 nodes are available: 6 Preemption is not helpful for scheduling."
60.2659,Event,ADDED,eval-sanitize-2-r1-050-qkt2f.18d420e72a5581b3,reason=Scheduled count=None msg=Successfully assigned compute/eval-sanitize-2-r1-050-qkt2f to kind-worker2
60.2662,Event,ADDED,eval-sanitize-2-r1-050-qkt2f.18d420e7489b6683,"reason=Pulled count=1 msg=Container image ""busybox:musl"" already present on machine"
60.2665,Event,ADDED,eval-sanitize-2-r1-050-qkt2f.18d420e74b99a428,reason=Created count=1 msg=Created container: task
60.2667,Event,ADDED,eval-sanitize-2-r1-050-qkt2f.18d420e74eaca93a,reason=Started count=1 msg=Started container task
60.2669,Event,ADDED,eval-sanitize-2-r1-050.18d420e64476b68a,reason=SuccessfulCreate count=1 msg=Created pod: eval-sanitize-2-r1-050-qkt2f
60.2671,Event,ADDED,eval-sanitize-2-r1-051-2k9qx.18d420e67fcf051a,"reason=FailedScheduling count=None msg=0/6 nodes are available: 6 node(s) had untolerated taint(s). no new claims to deallocate, preemption: 0/6 nodes are available: 6 Preemption is not helpful for scheduling."
60.2673,Event,ADDED,eval-sanitize-2-r1-051-2k9qx.18d420e72d052f94,reason=Scheduled count=None msg=Successfully assigned compute/eval-sanitize-2-r1-051-2k9qx to kind-worker2
60.2674,Event,ADDED,eval-sanitize-2-r1-051-2k9qx.18d420e745873ca2,"reason=Pulled count=1 msg=Container image ""busybox:musl"" already present on machine"
60.2676,Event,ADDED,eval-sanitize-2-r1-051-2k9qx.18d420e747d2f5d1,reason=Created count=1 msg=Created container: task
60.268,Event,ADDED,eval-sanitize-2-r1-051-2k9qx.18d420e74cfdc2c7,reason=Started count=1 msg=Started container task
60.2682,Event,ADDED,eval-sanitize-2-r1-051.18d420e67fc59d58,reason=SuccessfulCreate count=1 msg=Created pod: eval-sanitize-2-r1-051-2k9qx
60.2683,Event,ADDED,eval-sanitize-2-r1-052-hlv5q.18d420e6bb505216,"reason=FailedScheduling count=None msg=0/6 nodes are available: 6 node(s) had untolerated taint(s). no new claims to deallocate, preemption: 0/6 nodes are available: 6 Preemption is not helpful for scheduling."
60.2685,Event,ADDED,eval-sanitize-2-r1-052-hlv5q.18d420e72d023544,reason=Scheduled count=None msg=Successfully assigned compute/eval-sanitize-2-r1-052-hlv5q to kind-worker2
60.2688,Event,ADDED,eval-sanitize-2-r1-052-hlv5q.18d420e745a04de1,"reason=Pulled count=1 msg=Container image ""busybox:musl"" already present on machine"
60.269,Event,ADDED,eval-sanitize-2-r1-052-hlv5q.18d420e7482404d0,reason=Created count=1 msg=Created container: task
60.2692,Event,ADDED,eval-sanitize-2-r1-052-hlv5q.18d420e74cfd6d26,reason=Started count=1 msg=Started container task
60.2694,Event,ADDED,eval-sanitize-2-r1-052.18d420e6bb4d1e3f,reason=SuccessfulCreate count=1 msg=Created pod: eval-sanitize-2-r1-052-hlv5q
60.2697,Event,ADDED,eval-sanitize-2-r1-053-plshx.18d420e6f6f167a8,"reason=FailedScheduling count=None msg=0/6 nodes are available: 6 node(s) had untolerated taint(s). no new claims to deallocate, preemption: 0/6 nodes are available: 6 Preemption is not helpful for scheduling."
60.2699,Event,ADDED,eval-sanitize-2-r1-053-plshx.18d420e72d5c79ff,reason=Scheduled count=None msg=Successfully assigned compute/eval-sanitize-2-r1-053-plshx to kind-worker2
60.2702,Event,ADDED,eval-sanitize-2-r1-053-plshx.18d420e7468d13ff,"reason=Pulled count=1 msg=Container image ""busybox:musl"" already present on machine"
60.2706,Event,ADDED,eval-sanitize-2-r1-053-plshx.18d420e74a49159e,reason=Created count=1 msg=Created container: task
60.2707,Event,ADDED,eval-sanitize-2-r1-053-plshx.18d420e74dcc9bfc,reason=Started count=1 msg=Started container task
60.2709,Event,ADDED,eval-sanitize-2-r1-053.18d420e6f6e6195d,reason=SuccessfulCreate count=1 msg=Created pod: eval-sanitize-2-r1-053-plshx
60.2711,Event,ADDED,eval-sanitize-2-r1-054-w4wn7.18d420e732b7d092,"reason=FailedScheduling count=None msg=0/6 nodes are available: 1 c_wall violated: 2 conflicting context pair(s) with node memory, 5 node(s) had untolerated taint(s). no new claims to deallocate, preemption: 0/6 nodes are available: 1 No preemption victims found for incoming pod, 5 Preemption is not helpful for scheduling."
60.2715,Event,ADDED,eval-sanitize-2-r1-054-w4wn7.18d420e7332c02a3,"reason=FailedScheduling count=None msg=0/6 nodes are available: 1 c_wall violated: 2 conflicting context pair(s) with node memory, 5 node(s) had untolerated taint(s). no new claims to deallocate, preemption: 0/6 nodes are available: 1 No preemption victims found for incoming pod, 5 Preemption is not helpful for scheduling."
60.2716,Event,ADDED,eval-sanitize-2-r1-054-w4wn7.18d420e740abe13e,reason=Scheduled count=None msg=Successfully assigned compute/eval-sanitize-2-r1-054-w4wn7 to kind-worker3
60.2718,Event,ADDED,eval-sanitize-2-r1-054-w4wn7.18d420e75a635f59,"reason=Pulled count=1 msg=Container image ""busybox:musl"" already present on machine"
60.2722,Event,ADDED,eval-sanitize-2-r1-054-w4wn7.18d420e75bb51dc1,reason=Created count=1 msg=Created container: task
60.2724,Event,ADDED,eval-sanitize-2-r1-054-w4wn7.18d420e760c4abb2,reason=Started count=1 msg=Started container task
60.2726,Event,ADDED,eval-sanitize-2-r1-054.18d420e7327d5f9e,reason=SuccessfulCreate count=1 msg=Created pod: eval-sanitize-2-r1-054-w4wn7
60.2727,Event,ADDED,eval-sanitize-2-r1-055-nz9p5.18d420e76eeac9c3,reason=Scheduled count=None msg=Successfully assigned compute/eval-sanitize-2-r1-055-nz9p5 to kind-worker3
60.273,Event,ADDED,eval-sanitize-2-r1-055-nz9p5.18d420e7883f8ab2,"reason=Pulled count=1 msg=Container image ""busybox:musl"" already present on machine"
60.2732,Event,ADDED,eval-sanitize-2-r1-055-nz9p5.18d420e7898dec08,reason=Created count=1 msg=Created container: task
60.2733,Event,ADDED,eval-sanitize-2-r1-055-nz9p5.18d420e78d2579d6,reason=Started count=1 msg=Started container task
60.2735,Event,ADDED,eval-sanitize-2-r1-055.18d420e76e3bd087,reason=SuccessfulCreate count=1 msg=Created pod: eval-sanitize-2-r1-055-nz9p5
60.2737,Event,ADDED,eval-sanitize-2-r1-056-kmcc9.18d420e7b10626fe,"reason=FailedScheduling count=None msg=0/6 nodes are available: 2 c_wall violated: 1 conflicting context pair(s) with node memory, 4 node(s) had untolerated taint(s). no new claims to deallocate, preemption: 0/6 nodes are available: 2 No preemption victims found for incoming pod, 4 Preemption is not helpful for scheduling."
60.2739,Event,ADDED,eval-sanitize-2-r1-056-kmcc9.18d420e7b1a6c949,"reason=FailedScheduling count=None msg=0/6 nodes are available: 2 c_wall violated: 1 conflicting context pair(s) with node memory, 4 node(s) had untolerated taint(s). no new claims to deallocate, preemption: 0/6 nodes are available: 2 No preemption victims found for incoming pod, 4 Preemption is not helpful for scheduling."
60.2741,Event,ADDED,eval-sanitize-2-r1-056-kmcc9.18d420e7c3cf84ca,"reason=FailedScheduling count=None msg=0/6 nodes are available: 1 c_wall violated: 1 conflicting context pair(s) with node memory, 5 node(s) had untolerated taint(s). no new claims to deallocate, preemption: 0/6 nodes are available: 1 No preemption victims found for incoming pod, 5 Preemption is not helpful for scheduling."
60.2743,Event,ADDED,eval-sanitize-2-r1-056-kmcc9.18d420e7e090ecd7,reason=Scheduled count=None msg=Successfully assigned compute/eval-sanitize-2-r1-056-kmcc9 to kind-worker
60.2745,Event,ADDED,eval-sanitize-2-r1-056-kmcc9.18d420e7f9e7a31d,"reason=Pulled count=1 msg=Container image ""busybox:musl"" already present on machine"
60.2748,Event,ADDED,eval-sanitize-2-r1-056-kmcc9.18d420e7fb32f221,reason=Created count=1 msg=Created container: task
60.2751,Event,ADDED,eval-sanitize-2-r1-056-kmcc9.18d420e7fd532156,reason=Started count=1 msg=Started container task
60.2753,Event,ADDED,eval-sanitize-2-r1-056.18d420e7b09e8a34,reason=SuccessfulCreate count=1 msg=Created pod: eval-sanitize-2-r1-056-kmcc9
60.2755,Event,ADDED,eval-sanitize-2-r1-057-n6fs2.18d420e7e6162999,reason=Scheduled count=None msg=Successfully assigned compute/eval-sanitize-2-r1-057-n6fs2 to kind-worker
60.2759,Event,ADDED,eval-sanitize-2-r1-057-n6fs2.18d420e7fe3e1feb,"reason=Pulled count=1 msg=Container image ""busybox:musl"" already present on machine"
60.2766,Event,ADDED,eval-sanitize-2-r1-057-n6fs2.18d420e7ff401da9,reason=Created count=1 msg=Created container: task
60.2768,Event,ADDED,eval-sanitize-2-r1-057-n6fs2.18d420e8048c66e1,reason=Started count=1 msg=Started container task
60.277,Event,ADDED,eval-sanitize-2-r1-057.18d420e7e5647bdc,reason=SuccessfulCreate count=1 msg=Created pod: eval-sanitize-2-r1-057-n6fs2
60.2772,Event,ADDED,eval-sanitize-2-r1-058-6nf7f.18d420e821ae49ad,reason=Scheduled count=None msg=Successfully assigned compute/eval-sanitize-2-r1-058-6nf7f to kind-worker
60.2774,Event,ADDED,eval-sanitize-2-r1-058-6nf7f.18d420e83bd90139,"reason=Pulled count=1 msg=Container image ""busybox:musl"" already present on machine"
60.2775,Event,ADDED,eval-sanitize-2-r1-058-6nf7f.18d420e83d0b9408,reason=Created count=1 msg=Created container: task
60.2782,Event,ADDED,eval-sanitize-2-r1-058-6nf7f.18d420e841767da8,reason=Started count=1 msg=Started container task
60.2785,Event,ADDED,eval-sanitize-2-r1-058.18d420e8211bd7a8,reason=SuccessfulCreate count=1 msg=Created pod: eval-sanitize-2-r1-058-6nf7f
60.2787,Event,ADDED,eval-sanitize-2-r1-059-j7flz.18d420e85d9395fb,"reason=FailedScheduling count=None msg=0/6 nodes are available: 6 node(s) had untolerated taint(s). no new claims to deallocate, preemption: 0/6 nodes are available: 6 Preemption is not helpful for scheduling."
60.2789,Event,ADDED,eval-sanitize-2-r1-059.18d420e85d88a940,reason=SuccessfulCreate count=1 msg=Created pod: eval-sanitize-2-r1-059-j7flz
60.2792,Event,ADDED,eval-sanitize-2-r1-060.18d420e898819633,reason=SuccessfulCreate count=1 msg=Created pod: eval-sanitize-2-r1-060-m876n
60.2794,Event,ADDED,eval-sanitize-2-r1-060-m876n.18d420e8988979da,"reason=FailedScheduling count=None msg=0/6 nodes are available: 6 node(s) had untolerated taint(s). no new claims to deallocate, preemption: 0/6 nodes are available: 6 Preemption is not helpful for scheduling."
60.3825,Job,MODIFIED,eval-sanitize-2-r1-047,
60.3846,Job,MODIFIED,eval-sanitize-2-r1-045,
60.3886,Job,MODIFIED,eval-sanitize-2-r1-045,
60.391,Job,MODIFIED,eval-sanitize-2-r1-044,
60.3923,Pod,MODIFIED,eval-sanitize-2-r1-047-v644x,phase=Succeeded node=kind-worker4
60.3935,Job,MODIFIED,eval-sanitize-2-r1-047,
60.3958,Job,MODIFIED,eval-sanitize-2-r1-044,
60.3963,Event,ADDED,eval-sanitize-2-r1-045.18d420e8ad7b392b,reason=Completed count=1 msg=Job completed
60.4014,Job,MODIFIED,eval-sanitize-2-r1-045,
60.4018,Event,ADDED,eval-sanitize-2-r1-044.18d420e8ade68fff,reason=Completed count=1 msg=Job completed
60.4049,Job,MODIFIED,eval-sanitize-2-r1-044,
60.4064,TaskRequest,MODIFIED,eval-sanitize-2-r1-045,phase=Complete job=None
60.4102,TaskRequest,MODIFIED,eval-sanitize-2-r1-044,phase=Complete job=None
60.4155,Job,MODIFIED,eval-sanitize-2-r1-045,
60.4185,Job,MODIFIED,eval-sanitize-2-r1-044,
61.0087,TaskRequest,ADDED,eval-sanitize-2-r1-061,phase=None job=None
61.0122,TaskRequest,MODIFIED,eval-sanitize-2-r1-061,phase=Pending job=None
61.0273,Job,ADDED,eval-sanitize-2-r1-061,
61.0325,TaskRequest,MODIFIED,eval-sanitize-2-r1-061,phase=Scheduled job=None
61.0358,Pod,ADDED,eval-sanitize-2-r1-061-cv94w,phase=Pending node=None
61.0367,Job,MODIFIED,eval-sanitize-2-r1-061,
61.0399,TaskRequest,MODIFIED,eval-sanitize-2-r1-061,phase=Scheduled job=None
61.0422,Event,ADDED,eval-sanitize-2-r1-061.18d420e8d408943c,reason=SuccessfulCreate count=1 msg=Created pod: eval-sanitize-2-r1-061-cv94w
61.0432,Job,MODIFIED,eval-sanitize-2-r1-060,
61.044,Pod,MODIFIED,eval-sanitize-2-r1-061-cv94w,phase=Pending node=None
61.0444,Event,ADDED,eval-sanitize-2-r1-061-cv94w.18d420e8d4134f4b,"reason=FailedScheduling count=None msg=0/6 nodes are available: 6 node(s) had untolerated taint(s). no new claims to deallocate, preemption: 0/6 nodes are available: 6 Preemption is not helpful for scheduling."
61.051,Job,MODIFIED,eval-sanitize-2-r1-060,
61.3497,Node,MODIFIED,kind-worker4,taints=1
61.3882,Job,MODIFIED,eval-sanitize-2-r1-047,
61.394,Job,MODIFIED,eval-sanitize-2-r1-047,
61.3979,Event,ADDED,eval-sanitize-2-r1-047.18d420e8e95cdc9d,reason=Completed count=1 msg=Job completed
61.407,Job,MODIFIED,eval-sanitize-2-r1-047,
61.4113,TaskRequest,MODIFIED,eval-sanitize-2-r1-047,phase=Complete job=None
61.4215,Job,MODIFIED,eval-sanitize-2-r1-047,
61.4509,Node,MODIFIED,kind-worker4,taints=0
61.4552,Pod,MODIFIED,eval-sanitize-2-r1-059-j7flz,phase=Pending node=kind-worker4
61.4617,Pod,MODIFIED,eval-sanitize-2-r1-060-m876n,phase=Pending node=None
61.4625,Event,ADDED,eval-sanitize-2-r1-059-j7flz.18d420e8ed07f90d,reason=Scheduled count=None msg=Successfully assigned compute/eval-sanitize-2-r1-059-j7flz to kind-worker4
61.4627,Event,ADDED,eval-sanitize-2-r1-060-m876n.18d420e8ed04d306,"reason=FailedScheduling count=None msg=0/6 nodes are available: 1 c_wall violated: 1 conflicting context pair(s) with node memory, 5 node(s) had untolerated taint(s). no new claims to deallocate, preemption: 0/6 nodes are available: 1 No preemption victims found for incoming pod, 5 Preemption is not helpful for scheduling."
61.4666,Node,MODIFIED,kind-worker4,taints=0
61.4683,Pod,MODIFIED,eval-sanitize-2-r1-059-j7flz,phase=Pending node=kind-worker4
61.4754,Pod,MODIFIED,eval-sanitize-2-r1-061-cv94w,phase=Pending node=kind-worker4
61.4782,Pod,MODIFIED,eval-sanitize-2-r1-060-m876n,phase=Pending node=None
61.4789,Event,ADDED,eval-sanitize-2-r1-060-m876n.18d420e8ee15dee7,"reason=FailedScheduling count=None msg=0/6 nodes are available: 1 c_wall violated: 2 conflicting context pair(s) with node memory, 5 node(s) had untolerated taint(s). no new claims to deallocate, preemption: 0/6 nodes are available: 1 No preemption victims found for incoming pod, 5 Preemption is not helpful for scheduling."
61.4795,Event,ADDED,eval-sanitize-2-r1-061-cv94w.18d420e8ee413edb,reason=Scheduled count=None msg=Successfully assigned compute/eval-sanitize-2-r1-061-cv94w to kind-worker4
61.4869,Node,MODIFIED,kind-worker4,taints=0
61.4884,Pod,MODIFIED,eval-sanitize-2-r1-061-cv94w,phase=Pending node=kind-worker4
61.4888,Event,MODIFIED,eval-sanitize-2-r1-060-m876n.18d420e8ee15dee7,"reason=FailedScheduling count=None msg=0/6 nodes are available: 1 c_wall violated: 2 conflicting context pair(s) with node memory, 5 node(s) had untolerated taint(s). no new claims to deallocate, preemption: 0/6 nodes are available: 1 No preemption victims found for incoming pod, 5 Preemption is not helpful for scheduling."
61.5439,Event,ADDED,eval-sanitize-2-r1-060-m876n.18d420e8f203e723,"reason=FailedScheduling count=None msg=0/6 nodes are available: 1 c_wall violated: 2 conflicting context pair(s) with node memory, 5 node(s) had untolerated taint(s). no new claims to deallocate, preemption: 0/6 nodes are available: 1 No preemption victims found for incoming pod, 5 Preemption is not helpful for scheduling."
61.5582,Node,MODIFIED,kind-worker4,taints=0
61.646,Node,MODIFIED,kind-worker4,taints=0
61.8756,Event,ADDED,eval-sanitize-2-r1-059-j7flz.18d420e905d9e84b,"reason=Pulled count=1 msg=Container image ""busybox:musl"" already present on machine"
61.8906,Event,ADDED,eval-sanitize-2-r1-061-cv94w.18d420e906c01b68,"reason=Pulled count=1 msg=Container image ""busybox:musl"" already present on machine"
61.8964,Event,ADDED,eval-sanitize-2-r1-059-j7flz.18d420e907213162,reason=Created count=1 msg=Created container: task
61.9094,Event,ADDED,eval-sanitize-2-r1-061-cv94w.18d420e907e4d09d,reason=Created count=1 msg=Created container: task
61.9335,Event,ADDED,eval-sanitize-2-r1-059-j7flz.18d420e90934bfa5,reason=Started count=1 msg=Started container task
61.9425,Event,ADDED,eval-sanitize-2-r1-061-cv94w.18d420e909e2cbf6,reason=Started count=1 msg=Started container task
62.0209,TaskRequest,ADDED,eval-sanitize-2-r1-062,phase=None job=None
62.0252,TaskRequest,MODIFIED,eval-sanitize-2-r1-062,phase=Pending job=None
62.0405,Job,ADDED,eval-sanitize-2-r1-062,
62.043,Job,MODIFIED,eval-sanitize-2-r1-061,
62.0463,Pod,ADDED,eval-sanitize-2-r1-062-8zcsz,phase=Pending node=None
62.0474,TaskRequest,MODIFIED,eval-sanitize-2-r1-062,phase=Scheduled job=None
62.0509,Job,MODIFIED,eval-sanitize-2-r1-062,
62.0524,Event,ADDED,eval-sanitize-2-r1-062.18d420e910443e41,reason=SuccessfulCreate count=1 msg=Created pod: eval-sanitize-2-r1-062-8zcsz
62.055,Pod,MODIFIED,eval-sanitize-2-r1-062-8zcsz,phase=Pending node=None
62.0559,Event,ADDED,eval-sanitize-2-r1-062-8zcsz.18d420e910840465,"reason=FailedScheduling count=None msg=0/6 nodes are available: 1 c_wall violated: 2 conflicting context pair(s) with node memory, 5 node(s) had untolerated taint(s). no new claims to deallocate, preemption: 0/6 nodes are available: 1 No preemption victims found for incoming pod, 5 Preemption is not helpful for scheduling."
62.056,TaskRequest,MODIFIED,eval-sanitize-2-r1-062,phase=Scheduled job=None
62.0599,Job,MODIFIED,eval-sanitize-2-r1-061,
62.0613,Event,ADDED,eval-sanitize-2-r1-062-8zcsz.18d420e911035547,"reason=FailedScheduling count=None msg=0/6 nodes are available: 1 c_wall violated: 2 conflicting context pair(s) with node memory, 5 node(s) had untolerated taint(s). no new claims to deallocate, preemption: 0/6 nodes are available: 1 No preemption victims found for incoming pod, 5 Preemption is not helpful for scheduling."
62.3815,Pod,MODIFIED,eval-sanitize-2-r1-061-cv94w,phase=Running node=kind-worker4
62.3885,Pod,MODIFIED,eval-sanitize-2-r1-059-j7flz,phase=Running node=kind-worker4
62.3939,Event,MODIFIED,eval-sanitize-2-r1-062-8zcsz.18d420e911035547,"reason=FailedScheduling count=None msg=0/6 nodes are available: 1 c_wall violated: 2 conflicting context pair(s) with node memory, 5 node(s) had untolerated taint(s). no new claims to deallocate, preemption: 0/6 nodes are available: 1 No preemption victims found for incoming pod, 5 Preemption is not helpful for scheduling."
62.4607,Job,MODIFIED,eval-sanitize-2-r1-059,
62.469,Job,MODIFIED,eval-sanitize-2-r1-059,
63.0112,TaskRequest,ADDED,eval-sanitize-2-r1-063,phase=None job=None
63.0146,TaskRequest,MODIFIED,eval-sanitize-2-r1-063,phase=Pending job=None
63.0291,Job,ADDED,eval-sanitize-2-r1-063,
63.0339,TaskRequest,MODIFIED,eval-sanitize-2-r1-063,phase=Scheduled job=None
63.036,Pod,ADDED,eval-sanitize-2-r1-063-ftk49,phase=Pending node=None
63.0379,Job,MODIFIED,eval-sanitize-2-r1-063,
63.0405,Event,ADDED,eval-sanitize-2-r1-063.18d420e94b4180be,reason=SuccessfulCreate count=1 msg=Created pod: eval-sanitize-2-r1-063-ftk49
63.044,Pod,MODIFIED,eval-sanitize-2-r1-063-ftk49,phase=Pending node=kind-worker4
63.0499,Job,MODIFIED,eval-sanitize-2-r1-061,
63.0517,Event,ADDED,eval-sanitize-2-r1-063-ftk49.18d420e94bb8c86b,reason=Scheduled count=None msg=Successfully assigned compute/eval-sanitize-2-r1-063-ftk49 to kind-worker4
63.0519,TaskRequest,MODIFIED,eval-sanitize-2-r1-063,phase=Scheduled job=None
63.0531,Job,MODIFIED,eval-sanitize-2-r1-062,
63.055,Node,MODIFIED,kind-worker4,taints=0
63.0575,Pod,MODIFIED,eval-sanitize-2-r1-063-ftk49,phase=Pending node=kind-worker4
63.06,Job,MODIFIED,eval-sanitize-2-r1-061,
63.0629,Job,MODIFIED,eval-sanitize-2-r1-062,
63.1458,Node,MODIFIED,kind-worker4,taints=0
63.4667,Event,ADDED,eval-sanitize-2-r1-063-ftk49.18d420e964a2a970,"reason=Pulled count=1 msg=Container image ""busybox:musl"" already present on machine"
63.4827,Event,ADDED,eval-sanitize-2-r1-063-ftk49.18d420e965b3cd48,reason=Created count=1 msg=Created container: task
63.5372,Event,ADDED,eval-sanitize-2-r1-063-ftk49.18d420e968ec2a01,reason=Started count=1 msg=Started container task
63.5694,Node,MODIFIED,kind-worker4,taints=1
63.574,Pod,MODIFIED,eval-sanitize-2-r1-062-8zcsz,phase=Pending node=None
63.5786,Pod,MODIFIED,eval-sanitize-2-r1-060-m876n,phase=Pending node=None
63.7578,Node,MODIFIED,kind-worker4,taints=1
64.0071,TaskRequest,ADDED,eval-sanitize-2-r1-064,phase=None job=None
64.0105,TaskRequest,MODIFIED,eval-sanitize-2-r1-064,phase=Pending job=None
64.0254,Job,ADDED,eval-sanitize-2-r1-064,
64.032,Pod,ADDED,eval-sanitize-2-r1-064-qhlmp,phase=Pending node=None
64.0328,TaskRequest,MODIFIED,eval-sanitize-2-r1-064,phase=Scheduled job=None
64.0335,Job,MODIFIED,eval-sanitize-2-r1-064,
64.0373,Event,ADDED,eval-sanitize-2-r1-064.18d420e9869f423f,reason=SuccessfulCreate count=1 msg=Created pod: eval-sanitize-2-r1-064-qhlmp
64.0375,Event,ADDED,eval-sanitize-2-r1-064-qhlmp.18d420e986ae60c0,"reason=FailedScheduling count=None msg=0/6 nodes are available: 6 node(s) had untolerated taint(s). no new claims to deallocate, preemption: 0/6 nodes are available: 6 Preemption is not helpful for scheduling."
64.0383,Pod,MODIFIED,eval-sanitize-2-r1-064-qhlmp,phase=Pending node=None
64.0399,Job,MODIFIED,eval-sanitize-2-r1-063,
64.0401,TaskRequest,MODIFIED,eval-sanitize-2-r1-064,phase=Scheduled job=None
64.0494,Job,MODIFIED,eval-sanitize-2-r1-063,
64.3875,Pod,MODIFIED,eval-sanitize-2-r1-063-ftk49,phase=Running node=kind-worker4
64.7348,Pod,MODIFIED,eval-sanitize-2-r1-051-2k9qx,phase=Running node=kind-worker2
64.7408,Pod,MODIFIED,eval-sanitize-2-r1-050-qkt2f,phase=Running node=kind-worker2
64.747,Pod,MODIFIED,eval-sanitize-2-r1-046-qpmdw,phase=Running node=kind-worker2
64.7528,Pod,MODIFIED,eval-sanitize-2-r1-052-hlv5q,phase=Running node=kind-worker2
64.7594,Pod,MODIFIED,eval-sanitize-2-r1-048-6852f,phase=Running node=kind-worker2
64.7647,Pod,MODIFIED,eval-sanitize-2-r1-053-plshx,phase=Running node=kind-worker2
65.0132,TaskRequest,ADDED,eval-sanitize-2-r1-065,phase=None job=None
65.0167,TaskRequest,MODIFIED,eval-sanitize-2-r1-065,phase=Pending job=None
65.031,Job,ADDED,eval-sanitize-2-r1-065,
65.0364,Job,MODIFIED,eval-sanitize-2-r1-064,
65.0377,TaskRequest,MODIFIED,eval-sanitize-2-r1-065,phase=Scheduled job=None
65.0387,Pod,ADDED,eval-sanitize-2-r1-065-2kmq8,phase=Pending node=None
65.0406,Job,MODIFIED,eval-sanitize-2-r1-065,
65.0448,Event,ADDED,eval-sanitize-2-r1-065.18d420e9c2a5a00b,reason=SuccessfulCreate count=1 msg=Created pod: eval-sanitize-2-r1-065-2kmq8
65.0451,Event,ADDED,eval-sanitize-2-r1-065-2kmq8.18d420e9c2b00618,"reason=FailedScheduling count=None msg=0/6 nodes are available: 6 node(s) had untolerated taint(s). no new claims to deallocate, preemption: 0/6 nodes are available: 6 Preemption is not helpful for scheduling."
65.0462,Pod,MODIFIED,eval-sanitize-2-r1-065-2kmq8,phase=Pending node=None
65.0468,Job,MODIFIED,eval-sanitize-2-r1-063,
65.0476,Job,MODIFIED,eval-sanitize-2-r1-064,
65.0509,TaskRequest,MODIFIED,eval-sanitize-2-r1-065,phase=Scheduled job=None
65.0532,Job,MODIFIED,eval-sanitize-2-r1-063,
65.743,Job,MODIFIED,eval-sanitize-2-r1-051,
65.7481,Job,MODIFIED,eval-sanitize-2-r1-050,
65.7534,Job,MODIFIED,eval-sanitize-2-r1-046,
65.7557,Job,MODIFIED,eval-sanitize-2-r1-051,
65.7579,Job,MODIFIED,eval-sanitize-2-r1-050,
65.7587,Job,MODIFIED,eval-sanitize-2-r1-052,
65.762,Job,MODIFIED,eval-sanitize-2-r1-046,
65.7645,Job,MODIFIED,eval-sanitize-2-r1-048,
65.7674,Job,MODIFIED,eval-sanitize-2-r1-052,
65.7698,Job,MODIFIED,eval-sanitize-2-r1-053,
65.7741,Job,MODIFIED,eval-sanitize-2-r1-048,
65.7784,Job,MODIFIED,eval-sanitize-2-r1-053,
65.8186,Pod,MODIFIED,eval-sanitize-2-r1-055-nz9p5,phase=Running node=kind-worker3
65.8265,Pod,MODIFIED,eval-sanitize-2-r1-054-w4wn7,phase=Running node=kind-worker3
65.9485,Pod,MODIFIED,eval-sanitize-2-r1-046-qpmdw,phase=Succeeded node=kind-worker2
65.9849,Pod,MODIFIED,eval-sanitize-2-r1-048-6852f,phase=Succeeded node=kind-worker2
66.0122,TaskRequest,ADDED,eval-sanitize-2-r1-066,phase=None job=None
66.0161,TaskRequest,MODIFIED,eval-sanitize-2-r1-066,phase=Pending job=None
66.0311,Pod,MODIFIED,eval-sanitize-2-r1-052-hlv5q,phase=Succeeded node=kind-worker2
66.0317,Job,ADDED,eval-sanitize-2-r1-066,
66.0366,Pod,ADDED,eval-sanitize-2-r1-066-5xfnl,phase=Pending node=None
66.0395,TaskRequest,MODIFIED,eval-sanitize-2-r1-066,phase=Scheduled job=None
66.0412,Pod,MODIFIED,eval-sanitize-2-r1-053-plshx,phase=Succeeded node=kind-worker2
66.0443,Event,ADDED,eval-sanitize-2-r1-066.18d420e9fe21672e,reason=SuccessfulCreate count=1 msg=Created pod: eval-sanitize-2-r1-066-5xfnl
66.0453,Pod,MODIFIED,eval-sanitize-2-r1-066-5xfnl,phase=Pending node=None
66.0462,Job,MODIFIED,eval-sanitize-2-r1-066,
66.0465,Event,ADDED,eval-sanitize-2-r1-066-5xfnl.18d420e9fe2a8c71,"reason=FailedScheduling count=None msg=0/6 nodes are available: 6 node(s) had untolerated taint(s). no new claims to deallocate, preemption: 0/6 nodes are available: 6 Preemption is not helpful for scheduling."
66.0474,Job,MODIFIED,eval-sanitize-2-r1-065,
66.0484,TaskRequest,MODIFIED,eval-sanitize-2-r1-066,phase=Scheduled job=None
66.0531,Pod,MODIFIED,eval-sanitize-2-r1-050-qkt2f,phase=Succeeded node=kind-worker2
66.0554,Job,MODIFIED,eval-sanitize-2-r1-065,
66.0622,Pod,MODIFIED,eval-sanitize-2-r1-051-2k9qx,phase=Succeeded node=kind-worker2
66.4097,Pod,MODIFIED,eval-sanitize-2-r1-049-lmphz,phase=Running node=kind-worker5
66.7477,Job,MODIFIED,eval-sanitize-2-r1-051,
66.7526,Job,MODIFIED,eval-sanitize-2-r1-050,
66.7571,Pod,MODIFIED,eval-sanitize-2-r1-051-2k9qx,phase=Succeeded node=kind-worker2
66.7586,Job,MODIFIED,eval-sanitize-2-r1-051,
66.7595,Job,MODIFIED,eval-sanitize-2-r1-046,
66.7616,Pod,MODIFIED,eval-sanitize-2-r1-050-qkt2f,phase=Succeeded node=kind-worker2
66.763,Job,MODIFIED,eval-sanitize-2-r1-050,
66.7638,Job,MODIFIED,eval-sanitize-2-r1-052,
66.7689,Pod,MODIFIED,eval-sanitize-2-r1-046-qpmdw,phase=Succeeded node=kind-worker2
66.7711,Job,MODIFIED,eval-sanitize-2-r1-046,
66.7725,Pod,MODIFIED,eval-sanitize-2-r1-052-hlv5q,phase=Succeeded node=kind-worker2
66.7734,Job,MODIFIED,eval-sanitize-2-r1-048,
66.7743,Job,MODIFIED,eval-sanitize-2-r1-052,
66.7751,Job,MODIFIED,eval-sanitize-2-r1-053,
66.7801,Pod,MODIFIED,eval-sanitize-2-r1-048-6852f,phase=Succeeded node=kind-worker2
66.7822,Pod,MODIFIED,eval-sanitize-2-r1-053-plshx,phase=Succeeded node=kind-worker2
66.7833,Job,MODIFIED,eval-sanitize-2-r1-048,
66.7852,Job,MODIFIED,eval-sanitize-2-r1-053,
66.8248,Job,MODIFIED,eval-sanitize-2-r1-055,
66.8322,Job,MODIFIED,eval-sanitize-2-r1-054,
66.8348,Job,MODIFIED,eval-sanitize-2-r1-055,
66.8635,Job,MODIFIED,eval-sanitize-2-r1-054,
66.9847,Pod,MODIFIED,eval-sanitize-2-r1-055-nz9p5,phase=Succeeded node=kind-worker3
67.007,TaskRequest,ADDED,eval-sanitize-2-r1-067,phase=None job=None
67.0119,TaskRequest,MODIFIED,eval-sanitize-2-r1-067,phase=Pending job=None
67.0293,Job,ADDED,eval-sanitize-2-r1-067,
67.0336,TaskRequest,MODIFIED,eval-sanitize-2-r1-067,phase=Scheduled job=None
67.0372,Pod,ADDED,eval-sanitize-2-r1-067-7hd6x,phase=Pending node=None
67.0388,Pod,MODIFIED,eval-sanitize-2-r1-054-w4wn7,phase=Succeeded node=kind-worker3
67.0396,Job,MODIFIED,eval-sanitize-2-r1-067,
67.0426,Event,ADDED,eval-sanitize-2-r1-067.18d420ea39b92138,reason=SuccessfulCreate count=1 msg=Created pod: eval-sanitize-2-r1-067-7hd6x
67.0428,Event,ADDED,eval-sanitize-2-r1-067-7hd6x.18d420ea39c80b32,"reason=FailedScheduling count=None msg=0/6 nodes are available: 6 node(s) had untolerated taint(s). no new claims to deallocate, preemption: 0/6 nodes are available: 6 Preemption is not helpful for scheduling."
67.0435,Job,MODIFIED,eval-sanitize-2-r1-066,
67.0436,TaskRequest,MODIFIED,eval-sanitize-2-r1-067,phase=Scheduled job=None
67.0446,Pod,MODIFIED,eval-sanitize-2-r1-067-7hd6x,phase=Pending node=None
67.0524,Job,MODIFIED,eval-sanitize-2-r1-066,
67.4154,Job,MODIFIED,eval-sanitize-2-r1-049,
67.427,Job,MODIFIED,eval-sanitize-2-r1-049,
67.4435,Node,MODIFIED,kind-worker2,taints=1
67.4615,Node,MODIFIED,kind-worker2,taints=0
67.4662,Pod,MODIFIED,eval-sanitize-2-r1-062-8zcsz,phase=Pending node=kind-worker2
67.474,Node,MODIFIED,kind-worker2,taints=0
67.4757,Event,ADDED,eval-sanitize-2-r1-062-8zcsz.18d420ea5353d701,reason=Scheduled count=None msg=Successfully assigned compute/eval-sanitize-2-r1-062-8zcsz to kind-worker2
67.4767,Pod,MODIFIED,eval-sanitize-2-r1-060-m876n,phase=Pending node=kind-worker2
67.4782,Pod,MODIFIED,eval-sanitize-2-r1-064-qhlmp,phase=Pending node=kind-worker2
67.4786,Event,ADDED,eval-sanitize-2-r1-065-2kmq8.18d420ea53a648b8,"reason=FailedScheduling count=None msg=0/6 nodes are available: 1 c_wall violated: 1 conflicting context pair(s) with node memory, 5 node(s) had untolerated taint(s). no new claims to deallocate, preemption: 0/6 nodes are available: 1 No preemption victims found for incoming pod, 5 Preemption is not helpful for scheduling."
67.4799,Pod,MODIFIED,eval-sanitize-2-r1-065-2kmq8,phase=Pending node=None
67.4833,Pod,MODIFIED,eval-sanitize-2-r1-062-8zcsz,phase=Pending node=kind-worker2
67.4853,Event,ADDED,eval-sanitize-2-r1-064-qhlmp.18d420ea53eae389,reason=Scheduled count=None msg=Successfully assigned compute/eval-sanitize-2-r1-064-qhlmp to kind-worker2
67.4855,Event,ADDED,eval-sanitize-2-r1-060-m876n.18d420ea53f2584f,reason=Scheduled count=None msg=Successfully assigned compute/eval-sanitize-2-r1-060-m876n to kind-worker2
67.4911,Pod,MODIFIED,eval-sanitize-2-r1-066-5xfnl,phase=Pending node=kind-worker2
67.494,Node,MODIFIED,kind-worker2,taints=0
67.4953,Pod,MODIFIED,eval-sanitize-2-r1-060-m876n,phase=Pending node=kind-worker2
67.4969,Pod,MODIFIED,eval-sanitize-2-r1-067-7hd6x,phase=Pending node=kind-worker2
67.4972,Event,ADDED,eval-sanitize-2-r1-065-2kmq8.18d420ea54b82bb1,"reason=FailedScheduling count=None msg=0/6 nodes are available: 1 c_wall violated: 1 conflicting context pair(s) with node memory, 5 node(s) had untolerated taint(s). no new claims to deallocate, preemption: 0/6 nodes are available: 1 No preemption victims found for incoming pod, 5 Preemption is not helpful for scheduling."
67.4978,Event,ADDED,eval-sanitize-2-r1-066-5xfnl.18d420ea54bfaea0,reason=Scheduled count=None msg=Successfully assigned compute/eval-sanitize-2-r1-066-5xfnl to kind-worker2
67.4981,Event,ADDED,eval-sanitize-2-r1-067-7hd6x.18d420ea54ee4c82,reason=Scheduled count=None msg=Successfully assigned compute/eval-sanitize-2-r1-067-7hd6x to kind-worker2
67.5025,Node,MODIFIED,kind-worker2,taints=0
67.5035,Event,MODIFIED,eval-sanitize-2-r1-065-2kmq8.18d420ea54b82bb1,"reason=FailedScheduling count=None msg=0/6 nodes are available: 1 c_wall violated: 1 conflicting context pair(s) with node memory, 5 node(s) had untolerated taint(s). no new claims to deallocate, preemption: 0/6 nodes are available: 1 No preemption victims found for incoming pod, 5 Preemption is not helpful for scheduling."
67.5049,Pod,MODIFIED,eval-sanitize-2-r1-064-qhlmp,phase=Pending node=kind-worker2
67.5114,Pod,MODIFIED,eval-sanitize-2-r1-066-5xfnl,phase=Pending node=kind-worker2
67.5169,Pod,MODIFIED,eval-sanitize-2-r1-067-7hd6x,phase=Pending node=kind-worker2
67.5493,Node,MODIFIED,kind-worker2,taints=0
67.5856,Pod,MODIFIED,eval-sanitize-2-r1-049-lmphz,phase=Succeeded node=kind-worker5
67.6514,Node,MODIFIED,kind-worker3,taints=1
67.6532,Node,MODIFIED,kind-worker2,taints=0
67.6661,Node,MODIFIED,kind-worker3,taints=0
67.6683,Node,MODIFIED,kind-worker2,taints=0
67.6729,Pod,MODIFIED,eval-sanitize-2-r1-065-2kmq8,phase=Pending node=kind-worker3
67.6774,Event,ADDED,eval-sanitize-2-r1-065-2kmq8.18d420ea5fa3e48f,reason=Scheduled count=None msg=Successfully assigned compute/eval-sanitize-2-r1-065-2kmq8 to kind-worker3
67.6823,Node,MODIFIED,kind-worker3,taints=0
67.6843,Pod,MODIFIED,eval-sanitize-2-r1-065-2kmq8,phase=Pending node=kind-worker3
67.7494,Node,MODIFIED,kind-worker3,taints=0
67.7541,Job,MODIFIED,eval-sanitize-2-r1-051,
67.7574,Job,MODIFIED,eval-sanitize-2-r1-050,
67.7601,Job,MODIFIED,eval-sanitize-2-r1-051,
67.7615,Node,MODIFIED,kind-worker3,taints=0
67.7629,Job,MODIFIED,eval-sanitize-2-r1-050,
67.764,Event,ADDED,eval-sanitize-2-r1-051.18d420ea64d41caf,reason=Completed count=1 msg=Job completed
67.765,Job,MODIFIED,eval-sanitize-2-r1-046,
67.7689,Job,MODIFIED,eval-sanitize-2-r1-052,
67.7706,Event,ADDED,eval-sanitize-2-r1-050.18d420ea6505c13e,reason=Completed count=1 msg=Job completed
67.7715,Job,MODIFIED,eval-sanitize-2-r1-046,
67.7735,Job,MODIFIED,eval-sanitize-2-r1-051,
67.7748,Job,MODIFIED,eval-sanitize-2-r1-052,
67.7759,Job,MODIFIED,eval-sanitize-2-r1-050,
67.7767,Job,MODIFIED,eval-sanitize-2-r1-048,
67.777,Event,ADDED,eval-sanitize-2-r1-046.18d420ea65844552,reason=Completed count=1 msg=Job completed
67.7829,Event,ADDED,eval-sanitize-2-r1-052.18d420ea65a9b646,reason=Completed count=1 msg=Job completed
67.783,TaskRequest,MODIFIED,eval-sanitize-2-r1-051,phase=Complete job=None
67.784,Job,MODIFIED,eval-sanitize-2-r1-053,
67.7849,Job,MODIFIED,eval-sanitize-2-r1-048,
67.786,Job,MODIFIED,eval-sanitize-2-r1-046,
67.7906,Job,MODIFIED,eval-sanitize-2-r1-052,
67.791,Event,ADDED,eval-sanitize-2-r1-048.18d420ea663dac8a,reason=Completed count=1 msg=Job completed
67.7911,TaskRequest,MODIFIED,eval-sanitize-2-r1-050,phase=Complete job=None
67.7922,Job,MODIFIED,eval-sanitize-2-r1-053,
67.7952,Job,MODIFIED,eval-sanitize-2-r1-051,
67.7956,Event,ADDED,eval-sanitize-2-r1-053.18d420ea66ab5b63,reason=Completed count=1 msg=Job completed
67.8321,Job,MODIFIED,eval-sanitize-2-r1-055,
67.8348,Job,MODIFIED,eval-sanitize-2-r1-050,
67.838,Job,MODIFIED,eval-sanitize-2-r1-054,
67.8415,Pod,MODIFIED,eval-sanitize-2-r1-055-nz9p5,phase=Succeeded node=kind-worker3
67.8467,Job,MODIFIED,eval-sanitize-2-r1-055,
67.8532,Pod,MODIFIED,eval-sanitize-2-r1-054-w4wn7,phase=Succeeded node=kind-worker3
67.8538,Event,ADDED,eval-sanitize-2-r1-055.18d420ea6a03faba,reason=Completed count=1 msg=Job completed
67.8582,Job,MODIFIED,eval-sanitize-2-r1-054,
67.8597,TaskRequest,MODIFIED,eval-sanitize-2-r1-046,phase=Complete job=None
67.8631,Job,MODIFIED,eval-sanitize-2-r1-048,
67.8649,Event,ADDED,eval-sanitize-2-r1-054.18d420ea6ab35e02,reason=Completed count=1 msg=Job completed
67.866,Job,MODIFIED,eval-sanitize-2-r1-053,
67.8662,TaskRequest,MODIFIED,eval-sanitize-2-r1-052,phase=Complete job=None
67.8711,Job,MODIFIED,eval-sanitize-2-r1-046,
67.8712,TaskRequest,MODIFIED,eval-sanitize-2-r1-048,phase=Complete job=None
67.9312,TaskRequest,MODIFIED,eval-sanitize-2-r1-053,phase=Complete job=None
67.9318,Event,ADDED,eval-sanitize-2-r1-062-8zcsz.18d420ea6ed4c8d7,"reason=Pulled count=1 msg=Container image ""busybox:musl"" already present on machine"
67.9361,Job,MODIFIED,eval-sanitize-2-r1-052,
67.9574,Event,ADDED,eval-sanitize-2-r1-062-8zcsz.18d420ea70230f7a,reason=Created count=1 msg=Created container: task
67.962,Event,ADDED,eval-sanitize-2-r1-064-qhlmp.18d420ea7098f819,"reason=Pulled count=1 msg=Container image ""busybox:musl"" already present on machine"
67.9679,Job,MODIFIED,eval-sanitize-2-r1-055,
67.969,Job,MODIFIED,eval-sanitize-2-r1-054,
67.9728,Event,ADDED,eval-sanitize-2-r1-067-7hd6x.18d420ea70b0c59a,"reason=Pulled count=1 msg=Container image ""busybox:musl"" already present on machine"
67.974,Job,MODIFIED,eval-sanitize-2-r1-048,
67.9749,Job,MODIFIED,eval-sanitize-2-r1-053,
67.9769,Event,ADDED,eval-sanitize-2-r1-060-m876n.18d420ea70d0fb6e,"reason=Pulled count=1 msg=Container image ""busybox:musl"" already present on machine"
67.9829,Event,ADDED,eval-sanitize-2-r1-066-5xfnl.18d420ea70fadac7,"reason=Pulled count=1 msg=Container image ""busybox:musl"" already present on machine"
67.9969,Event,ADDED,eval-sanitize-2-r1-064-qhlmp.18d420ea72b79ec0,reason=Created count=1 msg=Created container: task
68.0071,Event,ADDED,eval-sanitize-2-r1-067-7hd6x.18d420ea734fba1a,reason=Created count=1 msg=Created container: task
68.0082,TaskRequest,ADDED,eval-sanitize-2-r1-068,phase=None job=None
68.018,Event,ADDED,eval-sanitize-2-r1-060-m876n.18d420ea73f526f6,reason=Created count=1 msg=Created container: task
68.0247,Event,ADDED,eval-sanitize-2-r1-062-8zcsz.18d420ea73fc5575,reason=Started count=1 msg=Started container task
68.026,TaskRequest,MODIFIED,eval-sanitize-2-r1-055,phase=Complete job=None
68.0305,Event,ADDED,eval-sanitize-2-r1-066-5xfnl.18d420ea743731f0,reason=Created count=1 msg=Created container: task
68.0335,TaskRequest,MODIFIED,eval-sanitize-2-r1-054,phase=Complete job=None
68.0367,Event,ADDED,eval-sanitize-2-r1-064-qhlmp.18d420ea751cd571,reason=Started count=1 msg=Started container task
68.0426,Job,MODIFIED,eval-sanitize-2-r1-067,
68.0504,Event,ADDED,eval-sanitize-2-r1-067-7hd6x.18d420ea75d29f34,reason=Started count=1 msg=Started container task
68.0592,TaskRequest,MODIFIED,eval-sanitize-2-r1-068,phase=Pending job=None
68.0602,Event,ADDED,eval-sanitize-2-r1-060-m876n.18d420ea767bcda0,reason=Started count=1 msg=Started container task
68.0646,Job,MODIFIED,eval-sanitize-2-r1-055,
68.067,Job,MODIFIED,eval-sanitize-2-r1-054,
68.0674,Event,ADDED,eval-sanitize-2-r1-066-5xfnl.18d420ea76aff6f1,reason=Started count=1 msg=Started container task
68.0765,Job,ADDED,eval-sanitize-2-r1-068,
68.0806,TaskRequest,MODIFIED,eval-sanitize-2-r1-068,phase=Scheduled job=None
68.0838,Pod,ADDED,eval-sanitize-2-r1-068-j9bqc,phase=Pending node=None
68.0848,Event,ADDED,eval-sanitize-2-r1-065-2kmq8.18d420ea77e8b268,"reason=Pulled count=1 msg=Container image ""busybox:musl"" already present on machine"
68.0868,Job,MODIFIED,eval-sanitize-2-r1-068,
68.0888,Event,ADDED,eval-sanitize-2-r1-068.18d420ea78265791,reason=SuccessfulCreate count=1 msg=Created pod: eval-sanitize-2-r1-068-j9bqc
68.1052,Pod,MODIFIED,eval-sanitize-2-r1-068-j9bqc,phase=Pending node=kind-worker3
68.1066,Event,ADDED,eval-sanitize-2-r1-065-2kmq8.18d420ea7927b874,reason=Created count=1 msg=Created container: task
68.1148,Pod,MODIFIED,eval-sanitize-2-r1-068-j9bqc,phase=Pending node=kind-worker3
68.1283,TaskRequest,MODIFIED,eval-sanitize-2-r1-068,phase=Scheduled job=None
68.1308,Job,MODIFIED,eval-sanitize-2-r1-068,
68.1323,Job,MODIFIED,eval-sanitize-2-r1-067,
68.1647,Job,MODIFIED,eval-sanitize-2-r1-068,
68.1702,Event,ADDED,eval-sanitize-2-r1-065-2kmq8.18d420ea7d1adc29,reason=Started count=1 msg=Started container task
68.1863,Event,ADDED,eval-sanitize-2-r1-068-j9bqc.18d420ea7df67d15,reason=Scheduled count=None msg=Successfully assigned compute/eval-sanitize-2-r1-068-j9bqc to kind-worker3
68.1924,Node,MODIFIED,kind-worker3,taints=0
68.2454,Node,MODIFIED,kind-worker3,taints=0
68.4216,Job,MODIFIED,eval-sanitize-2-r1-049,
68.43,Pod,MODIFIED,eval-sanitize-2-r1-049-lmphz,phase=Succeeded node=kind-worker5
68.4312,Job,MODIFIED,eval-sanitize-2-r1-049,
68.5048,Pod,MODIFIED,eval-sanitize-2-r1-056-kmcc9,phase=Running node=kind-worker
68.5112,Pod,MODIFIED,eval-sanitize-2-r1-057-n6fs2,phase=Running node=kind-worker
68.5508,Event,ADDED,eval-sanitize-2-r1-068-j9bqc.18d420ea93bfcb7d,"reason=Pulled count=1 msg=Container image ""busybox:musl"" already present on machine"
68.5697,Event,ADDED,eval-sanitize-2-r1-068-j9bqc.18d420ea94c9d540,reason=Created count=1 msg=Created container: task
68.6038,Event,ADDED,eval-sanitize-2-r1-068-j9bqc.18d420ea96e1edee,reason=Started count=1 msg=Started container task
68.7688,Pod,MODIFIED,eval-sanitize-2-r1-067-7hd6x,phase=Running node=kind-worker2
68.777,Pod,MODIFIED,eval-sanitize-2-r1-060-m876n,phase=Running node=kind-worker2
68.7833,Pod,MODIFIED,eval-sanitize-2-r1-062-8zcsz,phase=Running node=kind-worker2
68.7894,Pod,MODIFIED,eval-sanitize-2-r1-066-5xfnl,phase=Running node=kind-worker2
68.7963,Pod,MODIFIED,eval-sanitize-2-r1-064-qhlmp,phase=Running node=kind-worker2
68.8307,Pod,MODIFIED,eval-sanitize-2-r1-065-2kmq8,phase=Running node=kind-worker3
68.8408,Pod,MODIFIED,eval-sanitize-2-r1-068-j9bqc,phase=Running node=kind-worker3
68.9608,Node,MODIFIED,kind-worker5,taints=1
69.0088,TaskRequest,ADDED,eval-sanitize-2-r1-069,phase=None job=None
69.0125,TaskRequest,MODIFIED,eval-sanitize-2-r1-069,phase=Pending job=None
69.0273,Job,ADDED,eval-sanitize-2-r1-069,
69.0335,Pod,ADDED,eval-sanitize-2-r1-069-bw57v,phase=Pending node=None
69.0372,Job,MODIFIED,eval-sanitize-2-r1-069,
69.0374,TaskRequest,MODIFIED,eval-sanitize-2-r1-069,phase=Scheduled job=None
69.0391,Event,ADDED,eval-sanitize-2-r1-069.18d420eab0c7265e,reason=SuccessfulCreate count=1 msg=Created pod: eval-sanitize-2-r1-069-bw57v
69.0448,Pod,MODIFIED,eval-sanitize-2-r1-069-bw57v,phase=Pending node=None
69.0462,Event,ADDED,eval-sanitize-2-r1-069-bw57v.18d420eab1285341,"reason=FailedScheduling count=None msg=0/6 nodes are available: 2 c_wall violated: 2 conflicting context pair(s) with node memory, 4 node(s) had untolerated taint(s). no new claims to deallocate, preemption: 0/6 nodes are available: 2 No preemption victims found for incoming pod, 4 Preemption is not helpful for scheduling."
69.0464,TaskRequest,MODIFIED,eval-sanitize-2-r1-069,phase=Scheduled job=None
69.0478,Node,MODIFIED,kind-worker5,taints=1
69.0486,Job,MODIFIED,eval-sanitize-2-r1-067,
69.0541,Event,ADDED,eval-sanitize-2-r1-069-bw57v.18d420eab1ca1f8f,"reason=FailedScheduling count=None msg=0/6 nodes are available: 2 c_wall violated: 2 conflicting context pair(s) with node memory, 4 node(s) had untolerated taint(s). no new claims to deallocate, preemption: 0/6 nodes are available: 2 No preemption victims found for incoming pod, 4 Preemption is not helpful for scheduling."
69.0571,Job,MODIFIED,eval-sanitize-2-r1-067,
69.0623,Node,MODIFIED,kind-worker5,taints=0
69.0657,Event,MODIFIED,eval-sanitize-2-r1-069-bw57v.18d420eab1ca1f8f,"reason=FailedScheduling count=None msg=0/6 nodes are available: 2 c_wall violated: 2 conflicting context pair(s) with node memory, 4 node(s) had untolerated taint(s). no new claims to deallocate, preemption: 0/6 nodes are available: 2 No preemption victims found for incoming pod, 4 Preemption is not helpful for scheduling."
69.0741,Node,MODIFIED,kind-worker5,taints=0
69.0803,Pod,MODIFIED,eval-sanitize-2-r1-069-bw57v,phase=Pending node=kind-worker5
69.0837,Event,ADDED,eval-sanitize-2-r1-069-bw57v.18d420eab388f196,reason=Scheduled count=None msg=Successfully assigned compute/eval-sanitize-2-r1-069-bw57v to kind-worker5
69.0893,Job,MODIFIED,eval-sanitize-2-r1-068,
69.0922,Node,MODIFIED,kind-worker5,taints=0
69.0935,Pod,MODIFIED,eval-sanitize-2-r1-069-bw57v,phase=Pending node=kind-worker5
69.0988,Job,MODIFIED,eval-sanitize-2-r1-068,
69.1029,Node,MODIFIED,kind-worker5,taints=0
69.4274,Job,MODIFIED,eval-sanitize-2-r1-049,
69.4316,Job,MODIFIED,eval-sanitize-2-r1-049,
69.4365,Event,ADDED,eval-sanitize-2-r1-049.18d420eac87cf231,reason=Completed count=1 msg=Job completed
69.443,Job,MODIFIED,eval-sanitize-2-r1-049,
69.448,TaskRequest,MODIFIED,eval-sanitize-2-r1-049,phase=Complete job=None
69.4572,Job,MODIFIED,eval-sanitize-2-r1-049,
69.4934,Event,ADDED,eval-sanitize-2-r1-069-bw57v.18d420eacbf6b0a8,"reason=Pulled count=1 msg=Container image ""busybox:musl"" already present on machine"
69.5095,Pod,MODIFIED,eval-sanitize-2-r1-058-6nf7f,phase=Running node=kind-worker
69.513,Job,MODIFIED,eval-sanitize-2-r1-056,
69.5177,Job,MODIFIED,eval-sanitize-2-r1-057,
69.5183,Event,ADDED,eval-sanitize-2-r1-069-bw57v.18d420eacd357e43,reason=Created count=1 msg=Created container: task
69.5257,Job,MODIFIED,eval-sanitize-2-r1-056,
69.5285,Job,MODIFIED,eval-sanitize-2-r1-057,
69.6608,Node,MODIFIED,kind-worker2,taints=1
69.6683,Event,ADDED,eval-sanitize-2-r1-069-bw57v.18d420ead65a9c56,reason=Started count=1 msg=Started container task
69.6722,Node,MODIFIED,kind-worker2,taints=1
69.7125,Pod,MODIFIED,eval-sanitize-2-r1-057-n6fs2,phase=Succeeded node=kind-worker
69.7648,Pod,MODIFIED,eval-sanitize-2-r1-056-kmcc9,phase=Succeeded node=kind-worker
69.7809,Job,MODIFIED,eval-sanitize-2-r1-060,
69.7868,Job,MODIFIED,eval-sanitize-2-r1-062,
69.7893,Job,MODIFIED,eval-sanitize-2-r1-060,
69.7975,Job,MODIFIED,eval-sanitize-2-r1-066,
69.7981,Job,MODIFIED,eval-sanitize-2-r1-062,
69.7993,Job,MODIFIED,eval-sanitize-2-r1-064,
69.8061,Job,MODIFIED,eval-sanitize-2-r1-066,
69.808,Job,MODIFIED,eval-sanitize-2-r1-064,
69.8354,Job,MODIFIED,eval-sanitize-2-r1-065,
69.8441,Job,MODIFIED,eval-sanitize-2-r1-065,
69.8556,Node,MODIFIED,kind-worker3,taints=1
69.9449,Node,MODIFIED,kind-worker3,taints=1
70.0065,TaskRequest,ADDED,eval-sanitize-2-r1-070,phase=None job=None
70.0109,TaskRequest,MODIFIED,eval-sanitize-2-r1-070,phase=Pending job=None
70.0247,Job,ADDED,eval-sanitize-2-r1-070,
70.0307,Pod,ADDED,eval-sanitize-2-r1-070-cnjxq,phase=Pending node=None
70.0321,TaskRequest,MODIFIED,eval-sanitize-2-r1-070,phase=Scheduled job=None
70.0351,Job,MODIFIED,eval-sanitize-2-r1-070,
70.0354,Event,ADDED,eval-sanitize-2-r1-070.18d420eaec315591,reason=SuccessfulCreate count=1 msg=Created pod: eval-sanitize-2-r1-070-cnjxq
70.0382,Job,MODIFIED,eval-sanitize-2-r1-069,
70.0411,Pod,MODIFIED,eval-sanitize-2-r1-070-cnjxq,phase=Pending node=kind-worker5
70.0412,TaskRequest,MODIFIED,eval-sanitize-2-r1-070,phase=Scheduled job=None
70.0455,Event,ADDED,eval-sanitize-2-r1-070-cnjxq.18d420eaeccbb912,reason=Scheduled count=None msg=Successfully assigned compute/eval-sanitize-2-r1-070-cnjxq to kind-worker5
70.0486,Job,MODIFIED,eval-sanitize-2-r1-069,
70.0516,Pod,MODIFIED,eval-sanitize-2-r1-070-cnjxq,phase=Pending node=kind-worker5
70.0531,Node,MODIFIED,kind-worker5,taints=0
70.0613,Node,MODIFIED,kind-worker5,taints=0
70.4205,Pod,MODIFIED,eval-sanitize-2-r1-069-bw57v,phase=Running node=kind-worker5
70.4551,Event,ADDED,eval-sanitize-2-r1-070-cnjxq.18d420eb0547122d,"reason=Pulled count=1 msg=Container image ""busybox:musl"" already present on machine"
70.4725,Event,ADDED,eval-sanitize-2-r1-070-cnjxq.18d420eb06500640,reason=Created count=1 msg=Created container: task
70.5071,Event,ADDED,eval-sanitize-2-r1-070-cnjxq.18d420eb082e5ed1,reason=Started count=1 msg=Started container task
70.5148,Job,MODIFIED,eval-sanitize-2-r1-058,
70.5189,Job,MODIFIED,eval-sanitize-2-r1-056,
70.5226,Job,MODIFIED,eval-sanitize-2-r1-057,
70.525,Job,MODIFIED,eval-sanitize-2-r1-058,
70.529,Pod,MODIFIED,eval-sanitize-2-r1-056-kmcc9,phase=Succeeded node=kind-worker
70.5325,Job,MODIFIED,eval-sanitize-2-r1-056,
70.5338,Pod,MODIFIED,eval-sanitize-2-r1-057-n6fs2,phase=Succeeded node=kind-worker
70.5356,Job,MODIFIED,eval-sanitize-2-r1-057,
70.6328,Pod,MODIFIED,eval-sanitize-2-r1-058-6nf7f,phase=Succeeded node=kind-worker
71.0085,TaskRequest,ADDED,eval-sanitize-2-r1-071,phase=None job=None
71.0121,TaskRequest,MODIFIED,eval-sanitize-2-r1-071,phase=Pending job=None
71.0274,Job,ADDED,eval-sanitize-2-r1-071,
71.0317,TaskRequest,MODIFIED,eval-sanitize-2-r1-071,phase=Scheduled job=None
71.0349,Pod,ADDED,eval-sanitize-2-r1-071-swskf,phase=Pending node=None
71.0374,Job,MODIFIED,eval-sanitize-2-r1-071,
71.0383,Job,MODIFIED,eval-sanitize-2-r1-070,
71.0395,Event,ADDED,eval-sanitize-2-r1-071.18d420eb280e5dbc,reason=SuccessfulCreate count=1 msg=Created pod: eval-sanitize-2-r1-071-swskf
71.0396,TaskRequest,MODIFIED,eval-sanitize-2-r1-071,phase=Scheduled job=None
71.0425,Job,MODIFIED,eval-sanitize-2-r1-069,
71.0448,Pod,MODIFIED,eval-sanitize-2-r1-071-swskf,phase=Pending node=kind-worker5
71.0474,Job,MODIFIED,eval-sanitize-2-r1-070,
71.048,Event,ADDED,eval-sanitize-2-r1-071-swskf.18d420eb28a79bd0,reason=Scheduled count=None msg=Successfully assigned compute/eval-sanitize-2-r1-071-swskf to kind-worker5
71.0512,Job,MODIFIED,eval-sanitize-2-r1-069,
71.0569,Pod,MODIFIED,eval-sanitize-2-r1-071-swskf,phase=Pending node=kind-worker5
71.0847,Node,MODIFIED,kind-worker5,taints=1
71.0969,Node,MODIFIED,kind-worker5,taints=1
71.4239,Pod,MODIFIED,eval-sanitize-2-r1-070-cnjxq,phase=Running node=kind-worker5
71.464,Event,ADDED,eval-sanitize-2-r1-071-swskf.18d420eb41526143,"reason=Pulled count=1 msg=Container image ""busybox:musl"" already present on machine"
71.4799,Event,ADDED,eval-sanitize-2-r1-071-swskf.18d420eb42631bb2,reason=Created count=1 msg=Created container: task
71.5131,Event,ADDED,eval-sanitize-2-r1-071-swskf.18d420eb44500a09,reason=Started count=1 msg=Started container task
71.5214,Job,MODIFIED,eval-sanitize-2-r1-058,
71.5248,Job,MODIFIED,eval-sanitize-2-r1-056,
71.5276,Job,MODIFIED,eval-sanitize-2-r1-057,
71.5299,Job,MODIFIED,eval-sanitize-2-r1-056,
71.5316,Pod,MODIFIED,eval-sanitize-2-r1-058-6nf7f,phase=Succeeded node=kind-worker
71.5324,Job,MODIFIED,eval-sanitize-2-r1-058,
71.5335,Job,MODIFIED,eval-sanitize-2-r1-057,
71.5348,Event,ADDED,eval-sanitize-2-r1-056.18d420eb458d160f,reason=Completed count=1 msg=Job completed
71.5381,Event,ADDED,eval-sanitize-2-r1-057.18d420eb45ccdb74,reason=Completed count=1 msg=Job completed
71.5418,Job,MODIFIED,eval-sanitize-2-r1-056,
71.5435,Job,MODIFIED,eval-sanitize-2-r1-057,
71.5459,TaskRequest,MODIFIED,eval-sanitize-2-r1-056,phase=Complete job=None
71.5504,TaskRequest,MODIFIED,eval-sanitize-2-r1-057,phase=Complete job=None
71.5547,Job,MODIFIED,eval-sanitize-2-r1-056,
71.5584,Job,MODIFIED,eval-sanitize-2-r1-057,
71.6116,Event,MODIFIED,eval-sanitize-2-r1-060-m876n.18d420e8f203e723,"reason=FailedScheduling count=None msg=0/6 nodes are available: 1 c_wall violated: 2 conflicting context pair(s) with node memory, 5 node(s) had untolerated taint(s). no new claims to deallocate, preemption: 0/6 nodes are available: 1 No preemption victims found for incoming pod, 5 Preemption is not helpful for scheduling."
72.0086,TaskRequest,ADDED,eval-sanitize-2-r1-072,phase=None job=None
72.0125,TaskRequest,MODIFIED,eval-sanitize-2-r1-072,phase=Pending job=None
72.0285,Job,ADDED,eval-sanitize-2-r1-072,
72.0341,Pod,ADDED,eval-sanitize-2-r1-072-mc9d2,phase=Pending node=None
72.0354,TaskRequest,MODIFIED,eval-sanitize-2-r1-072,phase=Scheduled job=None
72.0379,Job,MODIFIED,eval-sanitize-2-r1-072,
72.0397,Event,ADDED,eval-sanitize-2-r1-072.18d420eb639a03c3,reason=SuccessfulCreate count=1 msg=Created pod: eval-sanitize-2-r1-072-mc9d2
72.04,Event,ADDED,eval-sanitize-2-r1-072-mc9d2.18d420eb63a66d93,"reason=FailedScheduling count=None msg=0/6 nodes are available: 6 node(s) had untolerated taint(s). no new claims to deallocate, preemption: 0/6 nodes are available: 6 Preemption is not helpful for scheduling."
72.041,Job,MODIFIED,eval-sanitize-2-r1-071,
72.0418,Pod,MODIFIED,eval-sanitize-2-r1-072-mc9d2,phase=Pending node=None
72.0427,Job,MODIFIED,eval-sanitize-2-r1-070,
72.0428,TaskRequest,MODIFIED,eval-sanitize-2-r1-072,phase=Scheduled job=None
72.0489,Job,MODIFIED,eval-sanitize-2-r1-071,
72.0505,Job,MODIFIED,eval-sanitize-2-r1-070,
72.4073,Pod,MODIFIED,eval-sanitize-2-r1-061-cv94w,phase=Running node=kind-worker4
72.413,Pod,MODIFIED,eval-sanitize-2-r1-059-j7flz,phase=Running node=kind-worker4
72.4251,Pod,MODIFIED,eval-sanitize-2-r1-071-swskf,phase=Running node=kind-worker5
72.4578,Node,MODIFIED,kind-worker,taints=1
72.4703,Node,MODIFIED,kind-worker,taints=1
72.5263,Job,MODIFIED,eval-sanitize-2-r1-058,
72.5307,Job,MODIFIED,eval-sanitize-2-r1-058,
72.5351,Event,ADDED,eval-sanitize-2-r1-058.18d420eb8139ffca,reason=Completed count=1 msg=Job completed
72.5413,Job,MODIFIED,eval-sanitize-2-r1-058,
72.544,Node,MODIFIED,kind-worker,taints=0
72.5471,TaskRequest,MODIFIED,eval-sanitize-2-r1-058,phase=Complete job=None
72.5512,Pod,MODIFIED,eval-sanitize-2-r1-072-mc9d2,phase=Pending node=kind-worker
72.5541,Event,ADDED,eval-sanitize-2-r1-072-mc9d2.18d420eb826662b3,reason=Scheduled count=None msg=Successfully assigned compute/eval-sanitize-2-r1-072-mc9d2 to kind-worker
72.5582,Job,MODIFIED,eval-sanitize-2-r1-058,
72.5595,Node,MODIFIED,kind-worker,taints=0
72.5649,Pod,MODIFIED,eval-sanitize-2-r1-072-mc9d2,phase=Pending node=kind-worker
72.5864,Node,MODIFIED,kind-worker,taints=0
72.8531,Node,MODIFIED,kind-worker,taints=0
72.9703,Event,ADDED,eval-sanitize-2-r1-072-mc9d2.18d420eb9b2a405e,"reason=Pulled count=1 msg=Container image ""busybox:musl"" already present on machine"
72.9873,Event,ADDED,eval-sanitize-2-r1-072-mc9d2.18d420eb9c3a3585,reason=Created count=1 msg=Created container: task
73.0216,TaskRequest,ADDED,eval-sanitize-2-r1-073,phase=None job=None
73.0239,Event,ADDED,eval-sanitize-2-r1-072-mc9d2.18d420eb9e56535d,reason=Started count=1 msg=Started container task
73.025,TaskRequest,MODIFIED,eval-sanitize-2-r1-073,phase=Pending job=None
73.039,Job,MODIFIED,eval-sanitize-2-r1-072,
73.0405,Job,ADDED,eval-sanitize-2-r1-073,
73.0445,Job,MODIFIED,eval-sanitize-2-r1-071,
73.0459,TaskRequest,MODIFIED,eval-sanitize-2-r1-073,phase=Scheduled job=None
73.047,Pod,ADDED,eval-sanitize-2-r1-073-rnl9b,phase=Pending node=None
73.0507,Job,MODIFIED,eval-sanitize-2-r1-073,
73.0514,Event,ADDED,eval-sanitize-2-r1-073.18d420eb9ffa24ac,reason=SuccessfulCreate count=1 msg=Created pod: eval-sanitize-2-r1-073-rnl9b
73.0528,TaskRequest,MODIFIED,eval-sanitize-2-r1-073,phase=Scheduled job=None
73.0556,Pod,MODIFIED,eval-sanitize-2-r1-073-rnl9b,phase=Pending node=kind-worker
73.0577,Job,MODIFIED,eval-sanitize-2-r1-072,
73.0585,Job,MODIFIED,eval-sanitize-2-r1-071,
73.0591,Event,ADDED,eval-sanitize-2-r1-073-rnl9b.18d420eba084985c,reason=Scheduled count=None msg=Successfully assigned compute/eval-sanitize-2-r1-073-rnl9b to kind-worker
73.0658,Node,MODIFIED,kind-worker,taints=0
73.0679,Pod,MODIFIED,eval-sanitize-2-r1-073-rnl9b,phase=Pending node=kind-worker
73.0767,Node,MODIFIED,kind-worker,taints=0
73.413,Job,MODIFIED,eval-sanitize-2-r1-061,
73.4172,Job,MODIFIED,eval-sanitize-2-r1-059,
73.4219,Job,MODIFIED,eval-sanitize-2-r1-061,
73.4253,Job,MODIFIED,eval-sanitize-2-r1-059,
73.5244,Pod,MODIFIED,eval-sanitize-2-r1-072-mc9d2,phase=Running node=kind-worker
73.5555,Event,ADDED,eval-sanitize-2-r1-073-rnl9b.18d420ebbe08b6d9,"reason=Pulled count=1 msg=Container image ""busybox:musl"" already present on machine"
73.5772,Pod,MODIFIED,eval-sanitize-2-r1-059-j7flz,phase=Succeeded node=kind-worker4
73.5779,Event,ADDED,eval-sanitize-2-r1-073-rnl9b.18d420ebbf419b7c,reason=Created count=1 msg=Created container: task
73.6154,Pod,MODIFIED,eval-sanitize-2-r1-061-cv94w,phase=Succeeded node=kind-worker4
73.6287,Event,ADDED,eval-sanitize-2-r1-073-rnl9b.18d420ebc26ea7e9,reason=Started count=1 msg=Started container task
74.0124,TaskRequest,ADDED,eval-sanitize-2-r1-074,phase=None job=None
74.0169,TaskRequest,MODIFIED,eval-sanitize-2-r1-074,phase=Pending job=None
74.0309,Job,ADDED,eval-sanitize-2-r1-074,
74.036,TaskRequest,MODIFIED,eval-sanitize-2-r1-074,phase=Scheduled job=None
74.039,Job,MODIFIED,eval-sanitize-2-r1-074,
74.0399,Pod,ADDED,eval-sanitize-2-r1-074-rjdcz,phase=Pending node=None
74.0441,Job,MODIFIED,eval-sanitize-2-r1-072,
74.0452,Event,ADDED,eval-sanitize-2-r1-074.18d420ebdb29782b,reason=SuccessfulCreate count=1 msg=Created pod: eval-sanitize-2-r1-074-rjdcz
74.0453,TaskRequest,MODIFIED,eval-sanitize-2-r1-074,phase=Scheduled job=None
74.0489,Pod,MODIFIED,eval-sanitize-2-r1-074-rjdcz,phase=Pending node=None
74.0493,Event,ADDED,eval-sanitize-2-r1-074-rjdcz.18d420ebdb6e1e24,"reason=FailedScheduling count=None msg=0/6 nodes are available: 1 c_wall violated: 1 conflicting context pair(s) with node memory, 5 node(s) had untolerated taint(s). no new claims to deallocate, preemption: 0/6 nodes are available: 1 No preemption victims found for incoming pod, 5 Preemption is not helpful for scheduling."
74.0514,Job,MODIFIED,eval-sanitize-2-r1-073,
74.053,Job,MODIFIED,eval-sanitize-2-r1-072,
74.0553,Event,ADDED,eval-sanitize-2-r1-074-rjdcz.18d420ebdbeb72f0,"reason=FailedScheduling count=None msg=0/6 nodes are available: 1 c_wall violated: 1 conflicting context pair(s) with node memory, 5 node(s) had untolerated taint(s). no new claims to deallocate, preemption: 0/6 nodes are available: 1 No preemption victims found for incoming pod, 5 Preemption is not helpful for scheduling."
74.0593,Job,MODIFIED,eval-sanitize-2-r1-073,
74.4138,Pod,MODIFIED,eval-sanitize-2-r1-063-ftk49,phase=Running node=kind-worker4
74.4176,Job,MODIFIED,eval-sanitize-2-r1-061,
74.4216,Job,MODIFIED,eval-sanitize-2-r1-059,
74.4232,Event,MODIFIED,eval-sanitize-2-r1-074-rjdcz.18d420ebdbeb72f0,"reason=FailedScheduling count=None msg=0/6 nodes are available: 1 c_wall violated: 1 conflicting context pair(s) with node memory, 5 node(s) had untolerated taint(s). no new claims to deallocate, preemption: 0/6 nodes are available: 1 No preemption victims found for incoming pod, 5 Preemption is not helpful for scheduling."
74.4271,Pod,MODIFIED,eval-sanitize-2-r1-061-cv94w,phase=Succeeded node=kind-worker4
74.4279,Job,MODIFIED,eval-sanitize-2-r1-061,
74.4302,Pod,MODIFIED,eval-sanitize-2-r1-059-j7flz,phase=Succeeded node=kind-worker4
74.4317,Job,MODIFIED,eval-sanitize-2-r1-059,
74.528,Pod,MODIFIED,eval-sanitize-2-r1-073-rnl9b,phase=Running node=kind-worker
74.5625,Node,MODIFIED,kind-worker,taints=1
74.5672,Pod,MODIFIED,eval-sanitize-2-r1-074-rjdcz,phase=Pending node=None
74.5746,Node,MODIFIED,kind-worker,taints=1
75.007,TaskRequest,ADDED,eval-sanitize-2-r1-075,phase=None job=None
75.0103,TaskRequest,MODIFIED,eval-sanitize-2-r1-075,phase=Pending job=None
75.0267,Job,ADDED,eval-sanitize-2-r1-075,
75.03,TaskRequest,MODIFIED,eval-sanitize-2-r1-075,phase=Scheduled job=None
75.0331,Pod,ADDED,eval-sanitize-2-r1-075-bgl4f,phase=Pending node=None
75.0353,Job,MODIFIED,eval-sanitize-2-r1-075,
75.0394,Event,ADDED,eval-sanitize-2-r1-075.18d420ec1661db5f,reason=SuccessfulCreate count=1 msg=Created pod: eval-sanitize-2-r1-075-bgl4f
75.0396,Event,ADDED,eval-sanitize-2-r1-075-bgl4f.18d420ec166bf5b7,"reason=FailedScheduling count=None msg=0/6 nodes are available: 6 node(s) had untolerated taint(s). no new claims to deallocate, preemption: 0/6 nodes are available: 6 Preemption is not helpful for scheduling."
75.0397,TaskRequest,MODIFIED,eval-sanitize-2-r1-075,phase=Scheduled job=None
75.0406,Pod,MODIFIED,eval-sanitize-2-r1-075-bgl4f,phase=Pending node=None
75.0432,Job,MODIFIED,eval-sanitize-2-r1-074,
75.0515,Job,MODIFIED,eval-sanitize-2-r1-074,
75.0559,Job,MODIFIED,eval-sanitize-2-r1-073,
75.064,Job,MODIFIED,eval-sanitize-2-r1-073,
75.4199,Job,MODIFIED,eval-sanitize-2-r1-063,
75.4235,Job,MODIFIED,eval-sanitize-2-r1-061,
75.4267,Job,MODIFIED,eval-sanitize-2-r1-059,
75.4298,Job,MODIFIED,eval-sanitize-2-r1-061,
75.4333,Job,MODIFIED,eval-sanitize-2-r1-063,
75.4345,Job,MODIFIED,eval-sanitize-2-r1-059,
75.4349,Event,ADDED,eval-sanitize-2-r1-061.18d420ec2e066b2f,reason=Completed count=1 msg=Job completed
75.4405,Event,ADDED,eval-sanitize-2-r1-059.18d420ec2e40dbe4,reason=Completed count=1 msg=Job completed
75.4439,Job,MODIFIED,eval-sanitize-2-r1-061,
75.4459,Job,MODIFIED,eval-sanitize-2-r1-059,
75.4491,TaskRequest,MODIFIED,eval-sanitize-2-r1-061,phase=Complete job=None
75.4531,TaskRequest,MODIFIED,eval-sanitize-2-r1-059,phase=Complete job=None
75.4585,Job,MODIFIED,eval-sanitize-2-r1-061,
75.4618,Job,MODIFIED,eval-sanitize-2-r1-059,
75.5455,Pod,MODIFIED,eval-sanitize-2-r1-063-ftk49,phase=Succeeded node=kind-worker4
76.0131,TaskRequest,ADDED,eval-sanitize-2-r1-076,phase=None job=None
76.0175,TaskRequest,MODIFIED,eval-sanitize-2-r1-076,phase=Pending job=None
76.0328,Job,ADDED,eval-sanitize-2-r1-076,
76.0377,Job,MODIFIED,eval-sanitize-2-r1-075,
76.0389,TaskRequest,MODIFIED,eval-sanitize-2-r1-076,phase=Scheduled job=None
76.0404,Pod,ADDED,eval-sanitize-2-r1-076-njvmb,phase=Pending node=None
76.0418,Job,MODIFIED,eval-sanitize-2-r1-076,
76.0457,Event,ADDED,eval-sanitize-2-r1-076.18d420ec5266eec8,reason=SuccessfulCreate count=1 msg=Created pod: eval-sanitize-2-r1-076-njvmb
76.0459,Event,ADDED,eval-sanitize-2-r1-076-njvmb.18d420ec526abf94,"reason=FailedScheduling count=None msg=0/6 nodes are available: 6 node(s) had untolerated taint(s). no new claims to deallocate, preemption: 0/6 nodes are available: 6 Preemption is not helpful for scheduling."
76.0468,Pod,MODIFIED,eval-sanitize-2-r1-076-njvmb,phase=Pending node=None
76.0481,Job,MODIFIED,eval-sanitize-2-r1-075,
76.0616,TaskRequest,MODIFIED,eval-sanitize-2-r1-076,phase=Scheduled job=None
76.4256,Job,MODIFIED,eval-sanitize-2-r1-063,
76.4339,Pod,MODIFIED,eval-sanitize-2-r1-063-ftk49,phase=Succeeded node=kind-worker4
76.4351,Job,MODIFIED,eval-sanitize-2-r1-063,
77.013,TaskRequest,ADDED,eval-sanitize-2-r1-077,phase=None job=None
77.0166,TaskRequest,MODIFIED,eval-sanitize-2-r1-077,phase=Pending job=None
77.0313,Job,ADDED,eval-sanitize-2-r1-077,
77.038,Pod,ADDED,eval-sanitize-2-r1-077-m74bz,phase=Pending node=None
77.0381,TaskRequest,MODIFIED,eval-sanitize-2-r1-077,phase=Scheduled job=None
77.0404,Job,MODIFIED,eval-sanitize-2-r1-077,
77.0428,Pod,MODIFIED,eval-sanitize-2-r1-077-m74bz,phase=Pending node=None
77.0442,Event,ADDED,eval-sanitize-2-r1-077.18d420ec8ddb2d4b,reason=SuccessfulCreate count=1 msg=Created pod: eval-sanitize-2-r1-077-m74bz
77.0444,Event,ADDED,eval-sanitize-2-r1-077-m74bz.18d420ec8de66de6,"reason=FailedScheduling count=None msg=0/6 nodes are available: 6 node(s) had untolerated taint(s). no new claims to deallocate, preemption: 0/6 nodes are available: 6 Preemption is not helpful for scheduling."
77.0452,Job,MODIFIED,eval-sanitize-2-r1-076,
77.0454,TaskRequest,MODIFIED,eval-sanitize-2-r1-077,phase=Scheduled job=None
77.0558,Node,MODIFIED,kind-worker4,taints=1
77.0566,Job,MODIFIED,eval-sanitize-2-r1-076,
77.1252,Node,MODIFIED,kind-worker4,taints=0
77.1308,Pod,MODIFIED,eval-sanitize-2-r1-074-rjdcz,phase=Pending node=kind-worker4
77.1347,Pod,MODIFIED,eval-sanitize-2-r1-075-bgl4f,phase=Pending node=kind-worker4
77.1352,Event,ADDED,eval-sanitize-2-r1-074-rjdcz.18d420ec936783ef,reason=Scheduled count=None msg=Successfully assigned compute/eval-sanitize-2-r1-074-rjdcz to kind-worker4
77.1388,Pod,MODIFIED,eval-sanitize-2-r1-076-njvmb,phase=Pending node=None
77.1392,Event,ADDED,eval-sanitize-2-r1-076-njvmb.18d420ec9382998f,"reason=FailedScheduling count=None msg=0/6 nodes are available: 1 c_wall violated: 1 conflicting context pair(s) with node memory, 5 node(s) had untolerated taint(s). no new claims to deallocate, preemption: 0/6 nodes are available: 1 No preemption victims found for incoming pod, 5 Preemption is not helpful for scheduling."
77.1395,Event,ADDED,eval-sanitize-2-r1-075-bgl4f.18d420ec93a066c5,reason=Scheduled count=None msg=Successfully assigned compute/eval-sanitize-2-r1-075-bgl4f to kind-worker4
77.1434,Node,MODIFIED,kind-worker4,taints=0
77.1452,Pod,MODIFIED,eval-sanitize-2-r1-074-rjdcz,phase=Pending node=kind-worker4
77.148,Event,ADDED,eval-sanitize-2-r1-077-m74bz.18d420ec941c337f,"reason=FailedScheduling count=None msg=0/6 nodes are available: 1 c_wall violated: 2 conflicting context pair(s) with node memory, 5 node(s) had untolerated taint(s). no new claims to deallocate, preemption: 0/6 nodes are available: 1 No preemption victims found for incoming pod, 5 Preemption is not helpful for scheduling."
77.1488,Pod,MODIFIED,eval-sanitize-2-r1-077-m74bz,phase=Pending node=None
77.1515,Pod,MODIFIED,eval-sanitize-2-r1-075-bgl4f,phase=Pending node=kind-worker4
77.1535,Node,MODIFIED,kind-worker4,taints=0
77.1567,Event,ADDED,eval-sanitize-2-r1-076-njvmb.18d420ec94c102a3,"reason=FailedScheduling count=None msg=0/6 nodes are available: 1 c_wall violated: 1 conflicting context pair(s) with node memory, 5 node(s) had untolerated taint(s). no new claims to deallocate, preemption: 0/6 nodes are available: 1 No preemption victims found for incoming pod, 5 Preemption is not helpful for scheduling."
77.161,Event,ADDED,eval-sanitize-2-r1-077-m74bz.18d420ec94f09d7c,"reason=FailedScheduling count=None msg=0/6 nodes are available: 1 c_wall violated: 2 conflicting context pair(s) with node memory, 5 node(s) had untolerated taint(s). no new claims to deallocate, preemption: 0/6 nodes are available: 1 No preemption victims found for incoming pod, 5 Preemption is not helpful for scheduling."
77.1645,Node,MODIFIED,kind-worker4,taints=0
77.1672,Event,MODIFIED,eval-sanitize-2-r1-076-njvmb.18d420ec94c102a3,"reason=FailedScheduling count=None msg=0/6 nodes are available: 1 c_wall violated: 1 conflicting context pair(s) with node memory, 5 node(s) had untolerated taint(s). no new claims to deallocate, preemption: 0/6 nodes are available: 1 No preemption victims found for incoming pod, 5 Preemption is not helpful for scheduling."
77.169,Event,MODIFIED,eval-sanitize-2-r1-077-m74bz.18d420ec94f09d7c,"reason=FailedScheduling count=None msg=0/6 nodes are available: 1 c_wall violated: 2 conflicting context pair(s) with node memory, 5 node(s) had untolerated taint(s). no new claims to deallocate, preemption: 0/6 nodes are available: 1 No preemption victims found for incoming pod, 5 Preemption is not helpful for scheduling."
77.2485,Node,MODIFIED,kind-worker4,taints=0
77.261,Node,MODIFIED,kind-worker4,taints=0
77.4304,Job,MODIFIED,eval-sanitize-2-r1-063,
77.4351,Job,MODIFIED,eval-sanitize-2-r1-063,
77.4396,Event,ADDED,eval-sanitize-2-r1-063.18d420eca5918884,reason=Completed count=1 msg=Job completed
77.4471,Job,MODIFIED,eval-sanitize-2-r1-063,
77.4517,TaskRequest,MODIFIED,eval-sanitize-2-r1-063,phase=Complete job=None
77.4623,Job,MODIFIED,eval-sanitize-2-r1-063,
77.5634,Event,ADDED,eval-sanitize-2-r1-074-rjdcz.18d420ecacec4e6e,"reason=Pulled count=1 msg=Container image ""busybox:musl"" already present on machine"
77.5677,Event,ADDED,eval-sanitize-2-r1-075-bgl4f.18d420ecad3a7bb5,"reason=Pulled count=1 msg=Container image ""busybox:musl"" already present on machine"
77.5892,Event,ADDED,eval-sanitize-2-r1-074-rjdcz.18d420ecae64aa38,reason=Created count=1 msg=Created container: task
77.5934,Event,ADDED,eval-sanitize-2-r1-075-bgl4f.18d420ecaeace735,reason=Created count=1 msg=Created container: task
77.668,Event,ADDED,eval-sanitize-2-r1-075-bgl4f.18d420ecb3300727,reason=Started count=1 msg=Started container task
77.6714,Event,ADDED,eval-sanitize-2-r1-074-rjdcz.18d420ecb3308b5e,reason=Started count=1 msg=Started container task
78.0085,TaskRequest,ADDED,eval-sanitize-2-r1-078,phase=None job=None
78.0123,TaskRequest,MODIFIED,eval-sanitize-2-r1-078,phase=Pending job=None
78.0278,Job,ADDED,eval-sanitize-2-r1-078,
78.0346,Pod,ADDED,eval-sanitize-2-r1-078-stwxj,phase=Pending node=None
78.0361,TaskRequest,MODIFIED,eval-sanitize-2-r1-078,phase=Scheduled job=None
78.0397,Job,MODIFIED,eval-sanitize-2-r1-078,
78.0402,Event,ADDED,eval-sanitize-2-r1-078.18d420ecc9496562,reason=SuccessfulCreate count=1 msg=Created pod: eval-sanitize-2-r1-078-stwxj
78.0432,Job,MODIFIED,eval-sanitize-2-r1-077,
78.0448,TaskRequest,MODIFIED,eval-sanitize-2-r1-078,phase=Scheduled job=None
78.0459,Pod,MODIFIED,eval-sanitize-2-r1-078-stwxj,phase=Pending node=kind-worker4
78.0514,Event,ADDED,eval-sanitize-2-r1-078-stwxj.18d420ecc9f0df22,reason=Scheduled count=None msg=Successfully assigned compute/eval-sanitize-2-r1-078-stwxj to kind-worker4
78.0549,Job,MODIFIED,eval-sanitize-2-r1-077,
78.0577,Node,MODIFIED,kind-worker4,taints=0
78.059,Pod,MODIFIED,eval-sanitize-2-r1-077-m74bz,phase=Pending node=None
78.0611,Pod,MODIFIED,eval-sanitize-2-r1-078-stwxj,phase=Pending node=kind-worker4
78.069,Node,MODIFIED,kind-worker4,taints=0
78.0696,Event,ADDED,eval-sanitize-2-r1-077-m74bz.18d420eccb298828,"reason=FailedScheduling count=None msg=0/6 nodes are available: 1 c_wall violated: 3 conflicting context pair(s) with node memory, 5 node(s) had untolerated taint(s). no new claims to deallocate, preemption: 0/6 nodes are available: 1 No preemption victims found for incoming pod, 5 Preemption is not helpful for scheduling."
78.0765,Event,MODIFIED,eval-sanitize-2-r1-077-m74bz.18d420eccb298828,"reason=FailedScheduling count=None msg=0/6 nodes are available: 1 c_wall violated: 3 conflicting context pair(s) with node memory, 5 node(s) had untolerated taint(s). no new claims to deallocate, preemption: 0/6 nodes are available: 1 No preemption victims found for incoming pod, 5 Preemption is not helpful for scheduling."
78.4261,Pod,MODIFIED,eval-sanitize-2-r1-075-bgl4f,phase=Running node=kind-worker4
78.4326,Pod,MODIFIED,eval-sanitize-2-r1-074-rjdcz,phase=Running node=kind-worker4
78.4748,Event,ADDED,eval-sanitize-2-r1-078-stwxj.18d420ece34a15b2,"reason=Pulled count=1 msg=Container image ""busybox:musl"" already present on machine"
78.4916,Event,ADDED,eval-sanitize-2-r1-078-stwxj.18d420ece450507f,reason=Created count=1 msg=Created container: task
78.5269,Event,ADDED,eval-sanitize-2-r1-078-stwxj.18d420ece65198b6,reason=Started count=1 msg=Started container task
78.7921,Pod,MODIFIED,eval-sanitize-2-r1-064-qhlmp,phase=Running node=kind-worker2
78.7983,Pod,MODIFIED,eval-sanitize-2-r1-060-m876n,phase=Running node=kind-worker2
78.8049,Pod,MODIFIED,eval-sanitize-2-r1-067-7hd6x,phase=Running node=kind-worker2
78.8114,Pod,MODIFIED,eval-sanitize-2-r1-062-8zcsz,phase=Running node=kind-worker2
78.8176,Pod,MODIFIED,eval-sanitize-2-r1-066-5xfnl,phase=Running node=kind-worker2
78.8536,Pod,MODIFIED,eval-sanitize-2-r1-068-j9bqc,phase=Running node=kind-worker3
78.8596,Pod,MODIFIED,eval-sanitize-2-r1-065-2kmq8,phase=Running node=kind-worker3
79.0093,TaskRequest,ADDED,eval-sanitize-2-r1-079,phase=None job=None
79.0128,TaskRequest,MODIFIED,eval-sanitize-2-r1-079,phase=Pending job=None
79.0276,Job,ADDED,eval-sanitize-2-r1-079,
79.0305,TaskRequest,MODIFIED,eval-sanitize-2-r1-079,phase=Scheduled job=None
79.0338,Pod,ADDED,eval-sanitize-2-r1-079-xrxgm,phase=Pending node=None
79.0366,Job,MODIFIED,eval-sanitize-2-r1-079,
79.0382,TaskRequest,MODIFIED,eval-sanitize-2-r1-079,phase=Scheduled job=None
79.0399,Event,ADDED,eval-sanitize-2-r1-079.18d420ed04d9cba1,reason=SuccessfulCreate count=1 msg=Created pod: eval-sanitize-2-r1-079-xrxgm
79.0408,Job,MODIFIED,eval-sanitize-2-r1-078,
79.0436,Pod,MODIFIED,eval-sanitize-2-r1-079-xrxgm,phase=Pending node=kind-worker4
79.0543,Event,ADDED,eval-sanitize-2-r1-079-xrxgm.18d420ed0562e433,reason=Scheduled count=None msg=Successfully assigned compute/eval-sanitize-2-r1-079-xrxgm to kind-worker4
79.0551,Job,MODIFIED,eval-sanitize-2-r1-078,
79.06,Pod,MODIFIED,eval-sanitize-2-r1-079-xrxgm,phase=Pending node=kind-worker4
79.1541,Node,MODIFIED,kind-worker4,taints=1
79.159,Pod,MODIFIED,eval-sanitize-2-r1-076-njvmb,phase=Pending node=None
79.1638,Pod,MODIFIED,eval-sanitize-2-r1-077-m74bz,phase=Pending node=None
79.1667,Node,MODIFIED,kind-worker4,taints=1
79.4295,Pod,MODIFIED,eval-sanitize-2-r1-078-stwxj,phase=Running node=kind-worker4
79.4309,Job,MODIFIED,eval-sanitize-2-r1-075,
79.4378,Job,MODIFIED,eval-sanitize-2-r1-074,
79.4395,Job,MODIFIED,eval-sanitize-2-r1-075,
79.4463,Job,MODIFIED,eval-sanitize-2-r1-074,
79.4683,Event,ADDED,eval-sanitize-2-r1-079-xrxgm.18d420ed1e84ce16,"reason=Pulled count=1 msg=Container image ""busybox:musl"" already present on machine"
79.4851,Event,ADDED,eval-sanitize-2-r1-079-xrxgm.18d420ed1f8e1fe3,reason=Created count=1 msg=Created container: task
79.5195,Event,ADDED,eval-sanitize-2-r1-079-xrxgm.18d420ed2185cf36,reason=Started count=1 msg=Started container task
79.7988,Job,MODIFIED,eval-sanitize-2-r1-064,
79.8043,Job,MODIFIED,eval-sanitize-2-r1-060,
79.8092,Job,MODIFIED,eval-sanitize-2-r1-067,
79.8112,Job,MODIFIED,eval-sanitize-2-r1-064,
79.8142,Job,MODIFIED,eval-sanitize-2-r1-060,
79.8162,Job,MODIFIED,eval-sanitize-2-r1-062,
79.8188,Job,MODIFIED,eval-sanitize-2-r1-067,
79.8233,Job,MODIFIED,eval-sanitize-2-r1-066,
79.8265,Job,MODIFIED,eval-sanitize-2-r1-062,
79.8314,Job,MODIFIED,eval-sanitize-2-r1-066,
79.8587,Job,MODIFIED,eval-sanitize-2-r1-068,
79.8643,Job,MODIFIED,eval-sanitize-2-r1-065,
79.8696,Job,MODIFIED,eval-sanitize-2-r1-068,
79.8723,Job,MODIFIED,eval-sanitize-2-r1-065,
79.9451,Pod,MODIFIED,eval-sanitize-2-r1-064-qhlmp,phase=Succeeded node=kind-worker2
79.9838,Pod,MODIFIED,eval-sanitize-2-r1-067-7hd6x,phase=Succeeded node=kind-worker2
79.9907,Pod,MODIFIED,eval-sanitize-2-r1-066-5xfnl,phase=Succeeded node=kind-worker2
79.9973,Pod,MODIFIED,eval-sanitize-2-r1-060-m876n,phase=Succeeded node=kind-worker2
80.0029,Pod,MODIFIED,eval-sanitize-2-r1-062-8zcsz,phase=Succeeded node=kind-worker2
80.0061,TaskRequest,ADDED,eval-sanitize-2-r1-080,phase=None job=None
80.0109,TaskRequest,MODIFIED,eval-sanitize-2-r1-080,phase=Pending job=None
80.026,Job,ADDED,eval-sanitize-2-r1-080,
80.0297,TaskRequest,MODIFIED,eval-sanitize-2-r1-080,phase=Scheduled job=None
80.0327,Pod,ADDED,eval-sanitize-2-r1-080-8rv2w,phase=Pending node=None
80.0347,Job,MODIFIED,eval-sanitize-2-r1-080,
80.0382,Event,ADDED,eval-sanitize-2-r1-080.18d420ed40635275,reason=SuccessfulCreate count=1 msg=Created pod: eval-sanitize-2-r1-080-8rv2w
80.0384,Event,ADDED,eval-sanitize-2-r1-080-8rv2w.18d420ed406a9c04,"reason=FailedScheduling count=None msg=0/6 nodes are available: 6 node(s) had untolerated taint(s). no new claims to deallocate, preemption: 0/6 nodes are available: 6 Preemption is not helpful for scheduling."
80.0386,TaskRequest,MODIFIED,eval-sanitize-2-r1-080,phase=Scheduled job=None
80.0396,Pod,MODIFIED,eval-sanitize-2-r1-080-8rv2w,phase=Pending node=None
80.0403,Job,MODIFIED,eval-sanitize-2-r1-079,
80.0455,Job,MODIFIED,eval-sanitize-2-r1-078,
80.0486,Job,MODIFIED,eval-sanitize-2-r1-079,
80.0542,Job,MODIFIED,eval-sanitize-2-r1-078,
80.0771,Pod,MODIFIED,eval-sanitize-2-r1-065-2kmq8,phase=Succeeded node=kind-worker3
80.0835,Pod,MODIFIED,eval-sanitize-2-r1-068-j9bqc,phase=Succeeded node=kind-worker3
80.4328,Pod,MODIFIED,eval-sanitize-2-r1-079-xrxgm,phase=Running node=kind-worker4
80.4447,Pod,MODIFIED,eval-sanitize-2-r1-069-bw57v,phase=Running node=kind-worker5
80.6481,Node,MODIFIED,kind-worker2,taints=1
80.6759,Node,MODIFIED,kind-worker2,taints=0
80.6842,Pod,MODIFIED,eval-sanitize-2-r1-076-njvmb,phase=Pending node=kind-worker2
80.6857,Pod,MODIFIED,eval-sanitize-2-r1-077-m74bz,phase=Pending node=kind-worker2
80.688,Node,MODIFIED,kind-worker2,taints=0
80.6906,Event,ADDED,eval-sanitize-2-r1-076-njvmb.18d420ed672e5bf2,reason=Scheduled count=None msg=Successfully assigned compute/eval-sanitize-2-r1-076-njvmb to kind-worker2
80.6916,Pod,MODIFIED,eval-sanitize-2-r1-080-8rv2w,phase=Pending node=kind-worker2
80.6919,Event,ADDED,eval-sanitize-2-r1-077-m74bz.18d420ed67499a11,reason=Scheduled count=None msg=Successfully assigned compute/eval-sanitize-2-r1-077-m74bz to kind-worker2
80.6977,Pod,MODIFIED,eval-sanitize-2-r1-076-njvmb,phase=Pending node=kind-worker2
80.6986,Event,ADDED,eval-sanitize-2-r1-080-8rv2w.18d420ed67ab32d0,reason=Scheduled count=None msg=Successfully assigned compute/eval-sanitize-2-r1-080-8rv2w to kind-worker2
80.7001,Node,MODIFIED,kind-worker2,taints=0
80.7042,Pod,MODIFIED,eval-sanitize-2-r1-077-m74bz,phase=Pending node=kind-worker2
80.7102,Pod,MODIFIED,eval-sanitize-2-r1-080-8rv2w,phase=Pending node=kind-worker2
80.7122,Node,MODIFIED,kind-worker2,taints=0
80.8041,Job,MODIFIED,eval-sanitize-2-r1-064,
80.8097,Job,MODIFIED,eval-sanitize-2-r1-060,
80.8123,Pod,MODIFIED,eval-sanitize-2-r1-064-qhlmp,phase=Succeeded node=kind-worker2
80.8136,Job,MODIFIED,eval-sanitize-2-r1-064,
80.8159,Job,MODIFIED,eval-sanitize-2-r1-067,
80.8191,Pod,MODIFIED,eval-sanitize-2-r1-060-m876n,phase=Succeeded node=kind-worker2
80.8199,Job,MODIFIED,eval-sanitize-2-r1-060,
80.8218,Job,MODIFIED,eval-sanitize-2-r1-062,
80.8248,Pod,MODIFIED,eval-sanitize-2-r1-067-7hd6x,phase=Succeeded node=kind-worker2
80.8265,Job,MODIFIED,eval-sanitize-2-r1-067,
80.8282,Job,MODIFIED,eval-sanitize-2-r1-066,
80.8312,Pod,MODIFIED,eval-sanitize-2-r1-062-8zcsz,phase=Succeeded node=kind-worker2
80.8327,Job,MODIFIED,eval-sanitize-2-r1-062,
80.8376,Pod,MODIFIED,eval-sanitize-2-r1-066-5xfnl,phase=Succeeded node=kind-worker2
80.8398,Job,MODIFIED,eval-sanitize-2-r1-066,
80.8576,Node,MODIFIED,kind-worker3,taints=1
80.8593,Node,MODIFIED,kind-worker2,taints=0
80.8633,Job,MODIFIED,eval-sanitize-2-r1-068,
80.869,Job,MODIFIED,eval-sanitize-2-r1-065,
80.8715,Pod,MODIFIED,eval-sanitize-2-r1-068-j9bqc,phase=Succeeded node=kind-worker3
80.8729,Job,MODIFIED,eval-sanitize-2-r1-068,
80.8787,Pod,MODIFIED,eval-sanitize-2-r1-065-2kmq8,phase=Succeeded node=kind-worker3
80.8809,Job,MODIFIED,eval-sanitize-2-r1-065,
80.9476,Node,MODIFIED,kind-worker3,taints=0
80.9492,Node,MODIFIED,kind-worker2,taints=0
80.9558,Node,MODIFIED,kind-worker3,taints=0
80.9655,Node,MODIFIED,kind-worker3,taints=0
81.0142,TaskRequest,ADDED,eval-sanitize-2-r1-081,phase=None job=None
81.0185,TaskRequest,MODIFIED,eval-sanitize-2-r1-081,phase=Pending job=None
81.0358,Job,ADDED,eval-sanitize-2-r1-081,
81.0397,Job,MODIFIED,eval-sanitize-2-r1-080,
81.0429,Pod,ADDED,eval-sanitize-2-r1-081-jlnkm,phase=Pending node=None
81.0452,TaskRequest,MODIFIED,eval-sanitize-2-r1-081,phase=Scheduled job=None
81.0461,Job,MODIFIED,eval-sanitize-2-r1-081,
81.0491,Job,MODIFIED,eval-sanitize-2-r1-079,
81.0496,Event,ADDED,eval-sanitize-2-r1-081.18d420ed7c89dd9b,reason=SuccessfulCreate count=1 msg=Created pod: eval-sanitize-2-r1-081-jlnkm
81.0549,Pod,MODIFIED,eval-sanitize-2-r1-081-jlnkm,phase=Pending node=kind-worker3
81.0551,TaskRequest,MODIFIED,eval-sanitize-2-r1-081,phase=Scheduled job=None
81.0583,Job,MODIFIED,eval-sanitize-2-r1-080,
81.0619,Job,MODIFIED,eval-sanitize-2-r1-079,
81.0622,Event,ADDED,eval-sanitize-2-r1-081-jlnkm.18d420ed7d38df82,reason=Scheduled count=None msg=Successfully assigned compute/eval-sanitize-2-r1-081-jlnkm to kind-worker3
81.0665,Node,MODIFIED,kind-worker3,taints=0
81.0686,Pod,MODIFIED,eval-sanitize-2-r1-081-jlnkm,phase=Pending node=kind-worker3
81.0781,Node,MODIFIED,kind-worker3,taints=0
81.1177,Event,ADDED,eval-sanitize-2-r1-076-njvmb.18d420ed80b4a5ed,"reason=Pulled count=1 msg=Container image ""busybox:musl"" already present on machine"
81.1256,Event,ADDED,eval-sanitize-2-r1-077-m74bz.18d420ed812a7571,"reason=Pulled count=1 msg=Container image ""busybox:musl"" already present on machine"
81.1319,Event,ADDED,eval-sanitize-2-r1-080-8rv2w.18d420ed81673925,"reason=Pulled count=1 msg=Container image ""busybox:musl"" already present on machine"
81.1492,Event,ADDED,eval-sanitize-2-r1-076-njvmb.18d420ed829af36a,reason=Created count=1 msg=Created container: task
81.1555,Event,ADDED,eval-sanitize-2-r1-077-m74bz.18d420ed8301f8be,reason=Created count=1 msg=Created container: task
81.1621,Event,ADDED,eval-sanitize-2-r1-080-8rv2w.18d420ed8370cdf6,reason=Created count=1 msg=Created container: task
81.2337,Event,ADDED,eval-sanitize-2-r1-076-njvmb.18d420ed878b5cc0,reason=Started count=1 msg=Started container task
81.2416,Event,ADDED,eval-sanitize-2-r1-080-8rv2w.18d420ed88261681,reason=Started count=1 msg=Started container task
81.2458,Event,ADDED,eval-sanitize-2-r1-077-m74bz.18d420ed88265bba,reason=Started count=1 msg=Started container task
81.4501,Pod,MODIFIED,eval-sanitize-2-r1-070-cnjxq,phase=Running node=kind-worker5
81.4511,Job,MODIFIED,eval-sanitize-2-r1-069,
81.4597,Job,MODIFIED,eval-sanitize-2-r1-069,
81.5198,Event,ADDED,eval-sanitize-2-r1-081-jlnkm.18d420ed98b5044b,"reason=Pulled count=1 msg=Container image ""busybox:musl"" already present on machine"
81.5403,Event,ADDED,eval-sanitize-2-r1-081-jlnkm.18d420ed99e0fb3b,reason=Created count=1 msg=Created container: task
81.5917,Pod,MODIFIED,eval-sanitize-2-r1-069-bw57v,phase=Succeeded node=kind-worker5
81.6064,Event,ADDED,eval-sanitize-2-r1-081-jlnkm.18d420ed9ddebaa7,reason=Started count=1 msg=Started container task
81.8101,Job,MODIFIED,eval-sanitize-2-r1-064,
81.8143,Job,MODIFIED,eval-sanitize-2-r1-060,
81.8168,Job,MODIFIED,eval-sanitize-2-r1-064,
81.8185,Pod,MODIFIED,eval-sanitize-2-r1-077-m74bz,phase=Running node=kind-worker2
81.8193,Job,MODIFIED,eval-sanitize-2-r1-060,
81.8206,Job,MODIFIED,eval-sanitize-2-r1-067,
81.8211,Event,ADDED,eval-sanitize-2-r1-064.18d420edaaa46069,reason=Completed count=1 msg=Job completed
81.8242,Pod,MODIFIED,eval-sanitize-2-r1-076-njvmb,phase=Running node=kind-worker2
81.826,Job,MODIFIED,eval-sanitize-2-r1-067,
81.828,Event,ADDED,eval-sanitize-2-r1-060.18d420edaac6c055,reason=Completed count=1 msg=Job completed
81.829,Job,MODIFIED,eval-sanitize-2-r1-064,
81.8297,Job,MODIFIED,eval-sanitize-2-r1-062,
81.8312,Job,MODIFIED,eval-sanitize-2-r1-060,
81.8331,Pod,MODIFIED,eval-sanitize-2-r1-080-8rv2w,phase=Running node=kind-worker2
81.834,Job,MODIFIED,eval-sanitize-2-r1-066,
81.8361,Event,ADDED,eval-sanitize-2-r1-067.18d420edab3885b6,reason=Completed count=1 msg=Job completed
81.837,Job,MODIFIED,eval-sanitize-2-r1-062,
81.8381,TaskRequest,MODIFIED,eval-sanitize-2-r1-064,phase=Complete job=None
81.839,Job,MODIFIED,eval-sanitize-2-r1-066,
81.8398,Job,MODIFIED,eval-sanitize-2-r1-067,
81.8409,Event,ADDED,eval-sanitize-2-r1-062.18d420edabdc1511,reason=Completed count=1 msg=Job completed
81.8419,TaskRequest,MODIFIED,eval-sanitize-2-r1-060,phase=Complete job=None
81.8446,Event,ADDED,eval-sanitize-2-r1-066.18d420edabfbfa80,reason=Completed count=1 msg=Job completed
81.8482,Job,MODIFIED,eval-sanitize-2-r1-064,
81.8596,TaskRequest,MODIFIED,eval-sanitize-2-r1-067,phase=Complete job=None
81.8627,Job,MODIFIED,eval-sanitize-2-r1-062,
81.865,Pod,MODIFIED,eval-sanitize-2-r1-081-jlnkm,phase=Running node=kind-worker3
81.8665,Job,MODIFIED,eval-sanitize-2-r1-060,
81.8687,Job,MODIFIED,eval-sanitize-2-r1-066,
81.8696,Job,MODIFIED,eval-sanitize-2-r1-068,
81.8724,Job,MODIFIED,eval-sanitize-2-r1-068,
81.8741,Job,MODIFIED,eval-sanitize-2-r1-065,
81.8752,Event,ADDED,eval-sanitize-2-r1-068.18d420edadfbe104,reason=Completed count=1 msg=Job completed
81.8778,Job,MODIFIED,eval-sanitize-2-r1-065,
81.8806,Event,ADDED,eval-sanitize-2-r1-065.18d420edae4f8ced,reason=Completed count=1 msg=Job completed
81.9288,TaskRequest,MODIFIED,eval-sanitize-2-r1-066,phase=Complete job=None
81.9328,Job,MODIFIED,eval-sanitize-2-r1-067,
81.9341,TaskRequest,MODIFIED,eval-sanitize-2-r1-062,phase=Complete job=None
81.9384,Job,MODIFIED,eval-sanitize-2-r1-066,
81.9437,Job,MODIFIED,eval-sanitize-2-r1-062,
81.9457,Job,MODIFIED,eval-sanitize-2-r1-068,
81.9465,Job,MODIFIED,eval-sanitize-2-r1-065,
81.9609,TaskRequest,MODIFIED,eval-sanitize-2-r1-068,phase=Complete job=None
82.0073,TaskRequest,ADDED,eval-sanitize-2-r1-082,phase=None job=None
82.0248,TaskRequest,MODIFIED,eval-sanitize-2-r1-065,phase=Complete job=None
82.0293,Job,MODIFIED,eval-sanitize-2-r1-068,
82.0312,TaskRequest,MODIFIED,eval-sanitize-2-r1-082,phase=Pending job=None
82.0342,Job,MODIFIED,eval-sanitize-2-r1-065,
82.0452,Job,MODIFIED,eval-sanitize-2-r1-080,
82.0458,Job,ADDED,eval-sanitize-2-r1-082,
82.0478,Job,MODIFIED,eval-sanitize-2-r1-081,
82.0504,Pod,ADDED,eval-sanitize-2-r1-082-rvmmb,phase=Pending node=None
82.0548,Job,MODIFIED,eval-sanitize-2-r1-082,
82.0551,Event,ADDED,eval-sanitize-2-r1-082.18d420edb89b6ef2,reason=SuccessfulCreate count=1 msg=Created pod: eval-sanitize-2-r1-082-rvmmb
82.0589,TaskRequest,MODIFIED,eval-sanitize-2-r1-082,phase=Scheduled job=None
82.0634,Pod,MODIFIED,eval-sanitize-2-r1-082-rvmmb,phase=Pending node=kind-worker2
82.0651,Job,MODIFIED,eval-sanitize-2-r1-082,
82.0741,Event,ADDED,eval-sanitize-2-r1-082-rvmmb.18d420edb95d55dc,reason=Scheduled count=None msg=Successfully assigned compute/eval-sanitize-2-r1-082-rvmmb to kind-worker2
82.0813,Pod,MODIFIED,eval-sanitize-2-r1-082-rvmmb,phase=Pending node=kind-worker2
82.129,TaskRequest,MODIFIED,eval-sanitize-2-r1-082,phase=Scheduled job=None
82.132,Job,MODIFIED,eval-sanitize-2-r1-080,
82.1327,Job,MODIFIED,eval-sanitize-2-r1-081,
82.1335,Job,MODIFIED,eval-sanitize-2-r1-082,
82.4535,Pod,MODIFIED,eval-sanitize-2-r1-071-swskf,phase=Running node=kind-worker5
82.4553,Job,MODIFIED,eval-sanitize-2-r1-070,
82.4573,Job,MODIFIED,eval-sanitize-2-r1-069,
82.4647,Job,MODIFIED,eval-sanitize-2-r1-070,
82.4674,Job,MODIFIED,eval-sanitize-2-r1-069,
82.4688,Pod,MODIFIED,eval-sanitize-2-r1-069-bw57v,phase=Succeeded node=kind-worker5
82.4855,Event,ADDED,eval-sanitize-2-r1-082-rvmmb.18d420edd24773a4,"reason=Pulled count=1 msg=Container image ""busybox:musl"" already present on machine"
82.5023,Event,ADDED,eval-sanitize-2-r1-082-rvmmb.18d420edd3556d1d,reason=Created count=1 msg=Created container: task
82.5694,Event,ADDED,eval-sanitize-2-r1-082-rvmmb.18d420edd7490375,reason=Started count=1 msg=Started container task
82.5925,Pod,MODIFIED,eval-sanitize-2-r1-070-cnjxq,phase=Succeeded node=kind-worker5
82.8198,Pod,MODIFIED,eval-sanitize-2-r1-082-rvmmb,phase=Running node=kind-worker2
82.8221,Job,MODIFIED,eval-sanitize-2-r1-077,
82.8295,Job,MODIFIED,eval-sanitize-2-r1-076,
82.8311,Job,MODIFIED,eval-sanitize-2-r1-077,
82.8374,Job,MODIFIED,eval-sanitize-2-r1-076,
82.8668,Node,MODIFIED,kind-worker2,taints=1
82.8784,Node,MODIFIED,kind-worker2,taints=1
83.0201,TaskRequest,ADDED,eval-sanitize-2-r1-083,phase=None job=None
83.0254,TaskRequest,MODIFIED,eval-sanitize-2-r1-083,phase=Pending job=None
83.0402,Job,ADDED,eval-sanitize-2-r1-083,
83.0465,TaskRequest,MODIFIED,eval-sanitize-2-r1-083,phase=Scheduled job=None
83.0493,Job,MODIFIED,eval-sanitize-2-r1-083,
83.0504,Pod,ADDED,eval-sanitize-2-r1-083-6skt5,phase=Pending node=None
83.0527,Event,ADDED,eval-sanitize-2-r1-083.18d420edf4217acb,reason=SuccessfulCreate count=1 msg=Created pod: eval-sanitize-2-r1-083-6skt5
83.0553,Job,MODIFIED,eval-sanitize-2-r1-082,
83.0555,TaskRequest,MODIFIED,eval-sanitize-2-r1-083,phase=Scheduled job=None
83.0575,Pod,MODIFIED,eval-sanitize-2-r1-083-6skt5,phase=Pending node=kind-worker3
83.0627,Event,ADDED,eval-sanitize-2-r1-083-6skt5.18d420edf49f593a,reason=Scheduled count=None msg=Successfully assigned compute/eval-sanitize-2-r1-083-6skt5 to kind-worker3
83.0656,Job,MODIFIED,eval-sanitize-2-r1-082,
83.0686,Node,MODIFIED,kind-worker3,taints=0
83.0703,Pod,MODIFIED,eval-sanitize-2-r1-083-6skt5,phase=Pending node=kind-worker3
83.1554,Node,MODIFIED,kind-worker3,taints=1
83.1638,Node,MODIFIED,kind-worker3,taints=1
83.2427,Node,MODIFIED,kind-worker3,taints=1
83.4593,Job,MODIFIED,eval-sanitize-2-r1-071,
83.4619,Job,MODIFIED,eval-sanitize-2-r1-070,
83.4635,Job,MODIFIED,eval-sanitize-2-r1-069,
83.4699,Job,MODIFIED,eval-sanitize-2-r1-069,
83.4716,Job,MODIFIED,eval-sanitize-2-r1-071,
83.4728,Pod,MODIFIED,eval-sanitize-2-r1-070-cnjxq,phase=Succeeded node=kind-worker5
83.476,Job,MODIFIED,eval-sanitize-2-r1-070,
83.4777,Event,ADDED,eval-sanitize-2-r1-069.18d420ee0d29f12e,reason=Completed count=1 msg=Job completed
83.4852,Job,MODIFIED,eval-sanitize-2-r1-069,
83.4891,TaskRequest,MODIFIED,eval-sanitize-2-r1-069,phase=Complete job=None
83.4984,Job,MODIFIED,eval-sanitize-2-r1-069,
83.5569,Pod,MODIFIED,eval-sanitize-2-r1-072-mc9d2,phase=Running node=kind-worker
83.5612,Event,ADDED,eval-sanitize-2-r1-083-6skt5.18d420ee12671838,"reason=Pulled count=1 msg=Container image ""busybox:musl"" already present on machine"
83.5794,Event,ADDED,eval-sanitize-2-r1-083-6skt5.18d420ee1380e622,reason=Created count=1 msg=Created container: task
83.6192,Pod,MODIFIED,eval-sanitize-2-r1-071-swskf,phase=Succeeded node=kind-worker5
83.6341,Event,ADDED,eval-sanitize-2-r1-083-6skt5.18d420ee16bc2632,reason=Started count=1 msg=Started container task
83.8716,Pod,MODIFIED,eval-sanitize-2-r1-083-6skt5,phase=Running node=kind-worker3
84.0068,TaskRequest,ADDED,eval-sanitize-2-r1-084,phase=None job=None
84.0113,TaskRequest,MODIFIED,eval-sanitize-2-r1-084,phase=Pending job=None
84.0262,Job,ADDED,eval-sanitize-2-r1-084,
84.0307,TaskRequest,MODIFIED,eval-sanitize-2-r1-084,phase=Scheduled job=None
84.0326,Pod,ADDED,eval-sanitize-2-r1-084-g4lzj,phase=Pending node=None
84.035,Job,MODIFIED,eval-sanitize-2-r1-084,
84.0375,Event,ADDED,eval-sanitize-2-r1-084.18d420ee2ebec8d6,reason=SuccessfulCreate count=1 msg=Created pod: eval-sanitize-2-r1-084-g4lzj
84.0387,Pod,MODIFIED,eval-sanitize-2-r1-084-g4lzj,phase=Pending node=None
84.039,Event,ADDED,eval-sanitize-2-r1-084-g4lzj.18d420ee2ec6b43f,"reason=FailedScheduling count=None msg=0/6 nodes are available: 6 node(s) had untolerated taint(s). no new claims to deallocate, preemption: 0/6 nodes are available: 6 Preemption is not helpful for scheduling."
84.039,TaskRequest,MODIFIED,eval-sanitize-2-r1-084,phase=Scheduled job=None
84.0541,Job,MODIFIED,eval-sanitize-2-r1-083,
84.0632,Job,MODIFIED,eval-sanitize-2-r1-083,
84.152,Node,MODIFIED,kind-worker5,taints=1
84.1665,Node,MODIFIED,kind-worker5,taints=0
84.1716,Pod,MODIFIED,eval-sanitize-2-r1-084-g4lzj,phase=Pending node=kind-worker5
84.1752,Node,MODIFIED,kind-worker5,taints=0
84.1755,Event,ADDED,eval-sanitize-2-r1-084-g4lzj.18d420ee37013dc6,reason=Scheduled count=None msg=Successfully assigned compute/eval-sanitize-2-r1-084-g4lzj to kind-worker5
84.1825,Pod,MODIFIED,eval-sanitize-2-r1-084-g4lzj,phase=Pending node=kind-worker5
84.1976,Node,MODIFIED,kind-worker5,taints=0
84.2452,Node,MODIFIED,kind-worker5,taints=0
84.2595,Node,MODIFIED,kind-worker5,taints=0
84.4643,Job,MODIFIED,eval-sanitize-2-r1-071,
84.4664,Job,MODIFIED,eval-sanitize-2-r1-070,
84.4716,Job,MODIFIED,eval-sanitize-2-r1-070,
84.4736,Job,MODIFIED,eval-sanitize-2-r1-071,
84.4749,Pod,MODIFIED,eval-sanitize-2-r1-071-swskf,phase=Succeeded node=kind-worker5
84.4756,Event,ADDED,eval-sanitize-2-r1-070.18d420ee48eb4fbe,reason=Completed count=1 msg=Job completed
84.4818,Job,MODIFIED,eval-sanitize-2-r1-070,
84.4882,TaskRequest,MODIFIED,eval-sanitize-2-r1-070,phase=Complete job=None
84.4976,Job,MODIFIED,eval-sanitize-2-r1-070,
84.5501,Pod,MODIFIED,eval-sanitize-2-r1-073-rnl9b,phase=Running node=kind-worker
84.5625,Job,MODIFIED,eval-sanitize-2-r1-072,
84.5748,Job,MODIFIED,eval-sanitize-2-r1-072,
84.5922,Event,ADDED,eval-sanitize-2-r1-084-g4lzj.18d420ee4fd80e1f,"reason=Pulled count=1 msg=Container image ""busybox:musl"" already present on machine"
84.6108,Event,ADDED,eval-sanitize-2-r1-084-g4lzj.18d420ee50fbdf31,reason=Created count=1 msg=Created container: task
84.6462,Pod,MODIFIED,eval-sanitize-2-r1-072-mc9d2,phase=Succeeded node=kind-worker
84.6467,Event,ADDED,eval-sanitize-2-r1-084-g4lzj.18d420ee5306961f,reason=Started count=1 msg=Started container task
85.0084,TaskRequest,ADDED,eval-sanitize-2-r1-085,phase=None job=None
85.0122,TaskRequest,MODIFIED,eval-sanitize-2-r1-085,phase=Pending job=None
85.0269,Job,ADDED,eval-sanitize-2-r1-085,
85.0309,TaskRequest,MODIFIED,eval-sanitize-2-r1-085,phase=Scheduled job=None
85.0338,Pod,ADDED,eval-sanitize-2-r1-085-2dbgq,phase=Pending node=None
85.0355,Job,MODIFIED,eval-sanitize-2-r1-085,
85.0376,Job,MODIFIED,eval-sanitize-2-r1-084,
85.0392,Event,ADDED,eval-sanitize-2-r1-085.18d420ee6a692960,reason=SuccessfulCreate count=1 msg=Created pod: eval-sanitize-2-r1-085-2dbgq
85.0393,TaskRequest,MODIFIED,eval-sanitize-2-r1-085,phase=Scheduled job=None
85.0428,Pod,MODIFIED,eval-sanitize-2-r1-085-2dbgq,phase=Pending node=None
85.0432,Event,ADDED,eval-sanitize-2-r1-085-2dbgq.18d420ee6aaf8eea,"reason=FailedScheduling count=None msg=0/6 nodes are available: 1 c_wall violated: 1 conflicting context pair(s) with node memory, 5 node(s) had untolerated taint(s). no new claims to deallocate, preemption: 0/6 nodes are available: 1 No preemption victims found for incoming pod, 5 Preemption is not helpful for scheduling."
85.046,Job,MODIFIED,eval-sanitize-2-r1-084,
85.0508,Event,ADDED,eval-sanitize-2-r1-085-2dbgq.18d420ee6b331cfb,"reason=FailedScheduling count=None msg=0/6 nodes are available: 1 c_wall violated: 1 conflicting context pair(s) with node memory, 5 node(s) had untolerated taint(s). no new claims to deallocate, preemption: 0/6 nodes are available: 1 No preemption victims found for incoming pod, 5 Preemption is not helpful for scheduling."
85.4627,Pod,MODIFIED,eval-sanitize-2-r1-084-g4lzj,phase=Running node=kind-worker5
85.4697,Job,MODIFIED,eval-sanitize-2-r1-071,
85.4733,Event,MODIFIED,eval-sanitize-2-r1-085-2dbgq.18d420ee6b331cfb,"reason=FailedScheduling count=None msg=0/6 nodes are available: 1 c_wall violated: 1 conflicting context pair(s) with node memory, 5 node(s) had untolerated taint(s). no new claims to deallocate, preemption: 0/6 nodes are available: 1 No preemption victims found for incoming pod, 5 Preemption is not helpful for scheduling."
85.4757,Job,MODIFIED,eval-sanitize-2-r1-071,
85.4788,Event,ADDED,eval-sanitize-2-r1-071.18d420ee84c560a2,reason=Completed count=1 msg=Job completed
85.4842,Job,MODIFIED,eval-sanitize-2-r1-071,
85.4892,TaskRequest,MODIFIED,eval-sanitize-2-r1-071,phase=Complete job=None
85.4978,Job,MODIFIED,eval-sanitize-2-r1-071,
85.5551,Job,MODIFIED,eval-sanitize-2-r1-073,
85.563,Job,MODIFIED,eval-sanitize-2-r1-073,
85.5697,Job,MODIFIED,eval-sanitize-2-r1-072,
85.5783,Pod,MODIFIED,eval-sanitize-2-r1-072-mc9d2,phase=Succeeded node=kind-worker
85.5794,Job,MODIFIED,eval-sanitize-2-r1-072,
85.6485,Pod,MODIFIED,eval-sanitize-2-r1-073-rnl9b,phase=Succeeded node=kind-worker
86.0069,TaskRequest,ADDED,eval-sanitize-2-r1-086,phase=None job=None
86.0119,TaskRequest,MODIFIED,eval-sanitize-2-r1-086,phase=Pending job=None
86.0263,Job,ADDED,eval-sanitize-2-r1-086,
86.0324,Pod,ADDED,eval-sanitize-2-r1-086-56hbr,phase=Pending node=None
86.0326,TaskRequest,MODIFIED,eval-sanitize-2-r1-086,phase=Scheduled job=None
86.0352,Job,MODIFIED,eval-sanitize-2-r1-086,
86.0393,Event,ADDED,eval-sanitize-2-r1-086.18d420eea5f57a5b,reason=SuccessfulCreate count=1 msg=Created pod: eval-sanitize-2-r1-086-56hbr
86.0401,Job,MODIFIED,eval-sanitize-2-r1-085,
86.0422,Pod,MODIFIED,eval-sanitize-2-r1-086-56hbr,phase=Pending node=kind-worker5
86.0423,TaskRequest,MODIFIED,eval-sanitize-2-r1-086,phase=Scheduled job=None
86.0455,Job,MODIFIED,eval-sanitize-2-r1-084,
86.0459,Event,ADDED,eval-sanitize-2-r1-086-56hbr.18d420eea685e48d,reason=Scheduled count=None msg=Successfully assigned compute/eval-sanitize-2-r1-086-56hbr to kind-worker5
86.0505,Job,MODIFIED,eval-sanitize-2-r1-085,
86.0547,Job,MODIFIED,eval-sanitize-2-r1-084,
86.0573,Pod,MODIFIED,eval-sanitize-2-r1-086-56hbr,phase=Pending node=kind-worker5
86.2532,Node,MODIFIED,kind-worker5,taints=1
86.2587,Pod,MODIFIED,eval-sanitize-2-r1-085-2dbgq,phase=Pending node=None
86.2677,Node,MODIFIED,kind-worker5,taints=1
86.4502,Event,ADDED,eval-sanitize-2-r1-086-56hbr.18d420eebe840a7e,"reason=Pulled count=1 msg=Container image ""busybox:musl"" already present on machine"
86.4657,Event,ADDED,eval-sanitize-2-r1-086-56hbr.18d420eebf8fdbf5,reason=Created count=1 msg=Created container: task
86.4977,Event,ADDED,eval-sanitize-2-r1-086-56hbr.18d420eec16c7933,reason=Started count=1 msg=Started container task
86.5606,Job,MODIFIED,eval-sanitize-2-r1-073,
86.5696,Pod,MODIFIED,eval-sanitize-2-r1-073-rnl9b,phase=Succeeded node=kind-worker
86.5707,Job,MODIFIED,eval-sanitize-2-r1-073,
86.5746,Job,MODIFIED,eval-sanitize-2-r1-072,
86.5783,Job,MODIFIED,eval-sanitize-2-r1-072,
86.5813,Event,ADDED,eval-sanitize-2-r1-072.18d420eec6803ff4,reason=Completed count=1 msg=Job completed
86.5894,Job,MODIFIED,eval-sanitize-2-r1-072,
86.5936,TaskRequest,MODIFIED,eval-sanitize-2-r1-072,phase=Complete job=None
86.6031,Job,MODIFIED,eval-sanitize-2-r1-072,
87.0072,TaskRequest,ADDED,eval-sanitize-2-r1-087,phase=None job=None
87.0109,TaskRequest,MODIFIED,eval-sanitize-2-r1-087,phase=Pending job=None
87.0262,Job,ADDED,eval-sanitize-2-r1-087,
87.0332,Pod,ADDED,eval-sanitize-2-r1-087-98pxc,phase=Pending node=None
87.0333,TaskRequest,MODIFIED,eval-sanitize-2-r1-087,phase=Scheduled job=None
87.0364,Job,MODIFIED,eval-sanitize-2-r1-087,
87.0385,Event,ADDED,eval-sanitize-2-r1-087.18d420eee19096f2,reason=SuccessfulCreate count=1 msg=Created pod: eval-sanitize-2-r1-087-98pxc
87.0387,Event,ADDED,eval-sanitize-2-r1-087-98pxc.18d420eee19b28d0,"reason=FailedScheduling count=None msg=0/6 nodes are available: 6 node(s) had untolerated taint(s). no new claims to deallocate, preemption: 0/6 nodes are available: 6 Preemption is not helpful for scheduling."
87.0395,Pod,MODIFIED,eval-sanitize-2-r1-087-98pxc,phase=Pending node=None
87.0403,Job,MODIFIED,eval-sanitize-2-r1-086,
87.0405,TaskRequest,MODIFIED,eval-sanitize-2-r1-087,phase=Scheduled job=None
87.0466,Job,MODIFIED,eval-sanitize-2-r1-086,
87.4682,Pod,MODIFIED,eval-sanitize-2-r1-086-56hbr,phase=Running node=kind-worker5
87.5663,Job,MODIFIED,eval-sanitize-2-r1-073,
87.5701,Job,MODIFIED,eval-sanitize-2-r1-073,
87.5749,Event,ADDED,eval-sanitize-2-r1-073.18d420ef019d8816,reason=Completed count=1 msg=Job completed
87.5812,Job,MODIFIED,eval-sanitize-2-r1-073,
87.5857,TaskRequest,MODIFIED,eval-sanitize-2-r1-073,phase=Complete job=None
87.5939,Job,MODIFIED,eval-sanitize-2-r1-073,
88.0186,TaskRequest,ADDED,eval-sanitize-2-r1-088,phase=None job=None
88.0226,TaskRequest,MODIFIED,eval-sanitize-2-r1-088,phase=Pending job=None
88.0373,Job,ADDED,eval-sanitize-2-r1-088,
88.0394,Job,MODIFIED,eval-sanitize-2-r1-087,
88.0424,TaskRequest,MODIFIED,eval-sanitize-2-r1-088,phase=Scheduled job=None
88.0461,Job,MODIFIED,eval-sanitize-2-r1-086,
88.0474,Pod,ADDED,eval-sanitize-2-r1-088-g9zxh,phase=Pending node=None
88.0488,Node,MODIFIED,kind-worker,taints=1
88.0496,Job,MODIFIED,eval-sanitize-2-r1-088,
88.0516,Event,ADDED,eval-sanitize-2-r1-088.18d420ef1ded7061,reason=SuccessfulCreate count=1 msg=Created pod: eval-sanitize-2-r1-088-g9zxh
88.0518,Event,ADDED,eval-sanitize-2-r1-088-g9zxh.18d420ef1df4f855,"reason=FailedScheduling count=None msg=0/6 nodes are available: 6 node(s) had untolerated taint(s). no new claims to deallocate, preemption: 0/6 nodes are available: 6 Preemption is not helpful for scheduling."
88.0527,Pod,MODIFIED,eval-sanitize-2-r1-088-g9zxh,phase=Pending node=None
88.0538,Job,MODIFIED,eval-sanitize-2-r1-087,
88.0539,TaskRequest,MODIFIED,eval-sanitize-2-r1-088,phase=Scheduled job=None
88.0559,Job,MODIFIED,eval-sanitize-2-r1-086,
88.0599,Node,MODIFIED,kind-worker,taints=1
88.0689,Node,MODIFIED,kind-worker,taints=0
88.0726,Pod,MODIFIED,eval-sanitize-2-r1-085-2dbgq,phase=Pending node=kind-worker
88.0786,Pod,MODIFIED,eval-sanitize-2-r1-087-98pxc,phase=Pending node=kind-worker
88.0799,Event,ADDED,eval-sanitize-2-r1-085-2dbgq.18d420ef1f8cd6af,reason=Scheduled count=None msg=Successfully assigned compute/eval-sanitize-2-r1-085-2dbgq to kind-worker
88.0837,Event,ADDED,eval-sanitize-2-r1-088-g9zxh.18d420ef1fc0f150,"reason=FailedScheduling count=None msg=0/6 nodes are available: 1 c_wall violated: 1 conflicting context pair(s) with node memory, 5 node(s) had untolerated taint(s). no new claims to deallocate, preemption: 0/6 nodes are available: 1 No preemption victims found for incoming pod, 5 Preemption is not helpful for scheduling."
88.0849,Pod,MODIFIED,eval-sanitize-2-r1-088-g9zxh,phase=Pending node=None
88.0869,Node,MODIFIED,kind-worker,taints=0
88.0872,Event,ADDED,eval-sanitize-2-r1-087-98pxc.18d420ef1fe390c6,reason=Scheduled count=None msg=Successfully assigned compute/eval-sanitize-2-r1-087-98pxc to kind-worker
88.0889,Pod,MODIFIED,eval-sanitize-2-r1-085-2dbgq,phase=Pending node=kind-worker
88.0944,Pod,MODIFIED,eval-sanitize-2-r1-087-98pxc,phase=Pending node=kind-worker
88.0947,Event,ADDED,eval-sanitize-2-r1-088-g9zxh.18d420ef20841e1a,"reason=FailedScheduling count=None msg=0/6 nodes are available: 1 c_wall violated: 1 conflicting context pair(s) with node memory, 5 node(s) had untolerated taint(s). no new claims to deallocate, preemption: 0/6 nodes are available: 1 No preemption victims found for incoming pod, 5 Preemption is not helpful for scheduling."
88.1119,Node,MODIFIED,kind-worker,taints=0
88.2601,Node,MODIFIED,kind-worker,taints=0
88.3427,Node,MODIFIED,kind-worker,taints=0
88.4495,Pod,MODIFIED,eval-sanitize-2-r1-074-rjdcz,phase=Running node=kind-worker4
88.4568,Pod,MODIFIED,eval-sanitize-2-r1-075-bgl4f,phase=Running node=kind-worker4
88.4867,Event,ADDED,eval-sanitize-2-r1-085-2dbgq.18d420ef37fad808,"reason=Pulled count=1 msg=Container image ""busybox:musl"" already present on machine"
88.4904,Event,ADDED,eval-sanitize-2-r1-087-98pxc.18d420ef381ab21d,"reason=Pulled count=1 msg=Container image ""busybox:musl"" already present on machine"
88.5078,Event,ADDED,eval-sanitize-2-r1-085-2dbgq.18d420ef39496d0c,reason=Created count=1 msg=Created container: task
88.5145,Event,ADDED,eval-sanitize-2-r1-087-98pxc.18d420ef399f2dd9,reason=Created count=1 msg=Created container: task
88.5723,Event,ADDED,eval-sanitize-2-r1-085-2dbgq.18d420ef3d161cfb,reason=Started count=1 msg=Started container task
88.6497,Event,ADDED,eval-sanitize-2-r1-087-98pxc.18d420ef41b77052,reason=Started count=1 msg=Started container task
89.0121,TaskRequest,ADDED,eval-sanitize-2-r1-089,phase=None job=None
89.0168,TaskRequest,MODIFIED,eval-sanitize-2-r1-089,phase=Pending job=None
89.0299,Job,ADDED,eval-sanitize-2-r1-089,
89.0365,Pod,ADDED,eval-sanitize-2-r1-089-6g5p2,phase=Pending node=None
89.0366,TaskRequest,MODIFIED,eval-sanitize-2-r1-089,phase=Scheduled job=None
89.0391,Job,MODIFIED,eval-sanitize-2-r1-089,
89.0426,Event,ADDED,eval-sanitize-2-r1-089.18d420ef59017b8f,reason=SuccessfulCreate count=1 msg=Created pod: eval-sanitize-2-r1-089-6g5p2
89.0441,TaskRequest,MODIFIED,eval-sanitize-2-r1-089,phase=Scheduled job=None
89.0453,Pod,MODIFIED,eval-sanitize-2-r1-089-6g5p2,phase=Pending node=None
89.0456,Event,ADDED,eval-sanitize-2-r1-089-6g5p2.18d420ef593ebc89,"reason=FailedScheduling count=None msg=0/6 nodes are available: 1 c_wall violated: 2 conflicting context pair(s) with node memory, 5 node(s) had untolerated taint(s). no new claims to deallocate, preemption: 0/6 nodes are available: 1 No preemption victims found for incoming pod, 5 Preemption is not helpful for scheduling."
89.05,Job,MODIFIED,eval-sanitize-2-r1-088,
89.0519,Event,ADDED,eval-sanitize-2-r1-089-6g5p2.18d420ef59ba8698,"reason=FailedScheduling count=None msg=0/6 nodes are available: 1 c_wall violated: 2 conflicting context pair(s) with node memory, 5 node(s) had untolerated taint(s). no new claims to deallocate, preemption: 0/6 nodes are available: 1 No preemption victims found for incoming pod, 5 Preemption is not helpful for scheduling."
89.0582,Job,MODIFIED,eval-sanitize-2-r1-088,
89.4545,Pod,MODIFIED,eval-sanitize-2-r1-078-stwxj,phase=Running node=kind-worker4
89.4564,Job,MODIFIED,eval-sanitize-2-r1-074,
89.4608,Job,MODIFIED,eval-sanitize-2-r1-075,
89.4666,Job,MODIFIED,eval-sanitize-2-r1-074,
89.4671,Event,MODIFIED,eval-sanitize-2-r1-089-6g5p2.18d420ef59ba8698,"reason=FailedScheduling count=None msg=0/6 nodes are available: 1 c_wall violated: 2 conflicting context pair(s) with node memory, 5 node(s) had untolerated taint(s). no new claims to deallocate, preemption: 0/6 nodes are available: 1 No preemption victims found for incoming pod, 5 Preemption is not helpful for scheduling."
89.4718,Job,MODIFIED,eval-sanitize-2-r1-075,
89.5368,Pod,MODIFIED,eval-sanitize-2-r1-074-rjdcz,phase=Succeeded node=kind-worker4
89.569,Pod,MODIFIED,eval-sanitize-2-r1-087-98pxc,phase=Running node=kind-worker
89.5744,Pod,MODIFIED,eval-sanitize-2-r1-075-bgl4f,phase=Succeeded node=kind-worker4
89.5762,Pod,MODIFIED,eval-sanitize-2-r1-085-2dbgq,phase=Running node=kind-worker
90.0072,TaskRequest,ADDED,eval-sanitize-2-r1-090,phase=None job=None
90.0123,TaskRequest,MODIFIED,eval-sanitize-2-r1-090,phase=Pending job=None
90.027,Job,ADDED,eval-sanitize-2-r1-090,
90.0358,Pod,ADDED,eval-sanitize-2-r1-090-7rhl4,phase=Pending node=None
90.0369,TaskRequest,MODIFIED,eval-sanitize-2-r1-090,phase=Scheduled job=None
90.0377,Job,MODIFIED,eval-sanitize-2-r1-090,
90.0407,Job,MODIFIED,eval-sanitize-2-r1-089,
90.0412,Event,ADDED,eval-sanitize-2-r1-090.18d420ef949093a5,reason=SuccessfulCreate count=1 msg=Created pod: eval-sanitize-2-r1-090-7rhl4
90.0457,Pod,MODIFIED,eval-sanitize-2-r1-090-7rhl4,phase=Pending node=None
90.0461,Event,ADDED,eval-sanitize-2-r1-090-7rhl4.18d420ef94d0f091,"reason=FailedScheduling count=None msg=0/6 nodes are available: 1 c_wall violated: 1 conflicting context pair(s) with node memory, 5 node(s) had untolerated taint(s). no new claims to deallocate, preemption: 0/6 nodes are available: 1 No preemption victims found for incoming pod, 5 Preemption is not helpful for scheduling."
90.0475,TaskRequest,MODIFIED,eval-sanitize-2-r1-090,phase=Scheduled job=None
90.0502,Job,MODIFIED,eval-sanitize-2-r1-089,
90.0521,Event,ADDED,eval-sanitize-2-r1-090-7rhl4.18d420ef955ae775,"reason=FailedScheduling count=None msg=0/6 nodes are available: 1 c_wall violated: 1 conflicting context pair(s) with node memory, 5 node(s) had untolerated taint(s). no new claims to deallocate, preemption: 0/6 nodes are available: 1 No preemption victims found for incoming pod, 5 Preemption is not helpful for scheduling."
90.2711,Node,MODIFIED,kind-worker,taints=1
90.2758,Pod,MODIFIED,eval-sanitize-2-r1-089-6g5p2,phase=Pending node=None
90.2807,Pod,MODIFIED,eval-sanitize-2-r1-088-g9zxh,phase=Pending node=None
90.2851,Pod,MODIFIED,eval-sanitize-2-r1-090-7rhl4,phase=Pending node=None
90.2857,Event,MODIFIED,eval-sanitize-2-r1-090-7rhl4.18d420ef955ae775,"reason=FailedScheduling count=None msg=0/6 nodes are available: 1 c_wall violated: 1 conflicting context pair(s) with node memory, 5 node(s) had untolerated taint(s). no new claims to deallocate, preemption: 0/6 nodes are available: 1 No preemption victims found for incoming pod, 5 Preemption is not helpful for scheduling."
90.459,Job,MODIFIED,eval-sanitize-2-r1-078,
