t_recv,kind,type,name,detail
0.0196,Node,ADDED,kind-control-plane,taints=1
0.0214,Node,ADDED,kind-worker,taints=0
0.0228,Node,ADDED,kind-worker2,taints=0
0.0241,Node,ADDED,kind-worker3,taints=0
0.0255,Node,ADDED,kind-worker4,taints=0
0.027,Node,ADDED,kind-worker5,taints=0
0.043,TaskRequest,ADDED,eval-sanitize-30-r3-000,phase=None job=None
0.0485,TaskRequest,MODIFIED,eval-sanitize-30-r3-000,phase=Pending job=None
0.0512,Event,ADDED,eval-image-prepull-552k2.18d4b290939d66c9,reason=Scheduled count=1 msg=Successfully assigned compute/eval-image-prepull-552k2 to kind-worker3
0.0516,Event,ADDED,eval-image-prepull-552k2.18d4b290b3630153,"reason=Pulled count=1 msg=Container image ""busybox:musl"" already present on machine"
0.0518,Event,ADDED,eval-image-prepull-552k2.18d4b290b621b19c,reason=Created count=1 msg=Created container: pause
0.0519,Event,ADDED,eval-image-prepull-552k2.18d4b290bb0dadcb,reason=Started count=1 msg=Started container pause
0.0521,Event,ADDED,eval-image-prepull-552k2.18d4b290faf002a4,reason=Killing count=1 msg=Stopping container pause
0.0524,Event,ADDED,eval-image-prepull-56r9k.18d4b290939d66ab,reason=Scheduled count=1 msg=Successfully assigned compute/eval-image-prepull-56r9k to kind-worker4
0.0526,Event,ADDED,eval-image-prepull-56r9k.18d4b290b393cef2,"reason=Pulled count=1 msg=Container image ""busybox:musl"" already present on machine"
0.0527,Event,ADDED,eval-image-prepull-56r9k.18d4b290b623135e,reason=Created count=1 msg=Created container: pause
0.0529,Event,ADDED,eval-image-prepull-56r9k.18d4b290bb1212a8,reason=Started count=1 msg=Started container pause
0.0531,Event,ADDED,eval-image-prepull-56r9k.18d4b29105ec6296,reason=Killing count=1 msg=Stopping container pause
0.0532,Event,ADDED,eval-image-prepull-98l7z.18d4b0a0b6f896c2,reason=Scheduled count=1 msg=Successfully assigned compute/eval-image-prepull-98l7z to kind-worker2
0.0534,Event,ADDED,eval-image-prepull-98l7z.18d4b0a0dd1fcfd8,"reason=Pulled count=1 msg=Container image ""busybox:musl"" already present on machine"
0.0538,Event,ADDED,eval-image-prepull-98l7z.18d4b0a0dfe7310a,reason=Created count=1 msg=Created container: pause
0.054,Event,ADDED,eval-image-prepull-98l7z.18d4b0a0ea7d9ff3,reason=Started count=1 msg=Started container pause
0.0542,Event,ADDED,eval-image-prepull-98l7z.18d4b0a1620de921,reason=Killing count=1 msg=Stopping container pause
0.0544,Event,ADDED,eval-image-prepull-pkbbb.18d4b29092956a66,reason=Scheduled count=1 msg=Successfully assigned compute/eval-image-prepull-pkbbb to kind-worker5
0.0547,Event,ADDED,eval-image-prepull-pkbbb.18d4b290b37c203c,"reason=Pulled count=1 msg=Container image ""busybox:musl"" already present on machine"
0.0549,Event,ADDED,eval-image-prepull-pkbbb.18d4b290b6000694,reason=Created count=1 msg=Created container: pause
0.0551,Event,ADDED,eval-image-prepull-pkbbb.18d4b290baf78e8f,reason=Started count=1 msg=Started container pause
0.0555,Event,ADDED,eval-image-prepull-pkbbb.18d4b290ffd90ecd,reason=Killing count=1 msg=Stopping container pause
0.0557,Event,ADDED,eval-image-prepull-rdh2g.18d4b290932ac150,reason=Scheduled count=1 msg=Successfully assigned compute/eval-image-prepull-rdh2g to kind-worker
0.0559,Event,ADDED,eval-image-prepull-rdh2g.18d4b290b38bda45,"reason=Pulled count=1 msg=Container image ""busybox:musl"" already present on machine"
0.056,Event,ADDED,eval-image-prepull-rdh2g.18d4b290b641c37b,reason=Created count=1 msg=Created container: pause
0.0564,Event,ADDED,eval-image-prepull-rdh2g.18d4b290bb0dabf0,reason=Started count=1 msg=Started container pause
0.0566,Event,ADDED,eval-image-prepull-rdh2g.18d4b2910f25b6cb,reason=Killing count=1 msg=Stopping container pause
0.0568,Event,ADDED,eval-image-prepull-rwjzn.18d4b0a0b66ec208,reason=Scheduled count=1 msg=Successfully assigned compute/eval-image-prepull-rwjzn to kind-worker5
0.0569,Event,ADDED,eval-image-prepull-rwjzn.18d4b0a0dd11c4d3,"reason=Pulled count=1 msg=Container image ""busybox:musl"" already present on machine"
0.0572,Event,ADDED,eval-image-prepull-rwjzn.18d4b0a0dfe592e9,reason=Created count=1 msg=Created container: pause
0.0574,Event,ADDED,eval-image-prepull-rwjzn.18d4b0a0ea80885b,reason=Started count=1 msg=Started container pause
0.0575,Event,ADDED,eval-image-prepull-rwjzn.18d4b0a192640263,reason=Killing count=1 msg=Stopping container pause
0.0578,Event,ADDED,eval-image-prepull-skd9h.18d4b0a0b6029c2b,reason=Scheduled count=1 msg=Successfully assigned compute/eval-image-prepull-skd9h to kind-worker4
0.058,Event,ADDED,eval-image-prepull-skd9h.18d4b0a0dd1eb07b,"reason=Pulled count=1 msg=Container image ""busybox:musl"" already present on machine"
0.0582,Event,ADDED,eval-image-prepull-skd9h.18d4b0a0dfe53148,reason=Created count=1 msg=Created container: pause
0.0585,Event,ADDED,eval-image-prepull-skd9h.18d4b0a0ea814dd9,reason=Started count=1 msg=Started container pause
0.0589,Event,ADDED,eval-image-prepull-skd9h.18d4b0a13f5e413e,reason=Killing count=1 msg=Stopping container pause
0.059,Event,ADDED,eval-image-prepull-smw7s.18d4b29093078884,reason=Scheduled count=1 msg=Successfully assigned compute/eval-image-prepull-smw7s to kind-worker2
0.0592,Event,ADDED,eval-image-prepull-smw7s.18d4b290b3730abf,"reason=Pulled count=1 msg=Container image ""busybox:musl"" already present on machine"
0.0595,Event,ADDED,eval-image-prepull-smw7s.18d4b290b623a06a,reason=Created count=1 msg=Created container: pause
0.0597,Event,ADDED,eval-image-prepull-smw7s.18d4b290bb0f29b9,reason=Started count=1 msg=Started container pause
0.0599,Event,ADDED,eval-image-prepull-smw7s.18d4b2911b5ef152,reason=Killing count=1 msg=Stopping container pause
0.0601,Event,ADDED,eval-image-prepull-vfn86.18d4b0a0b670dc36,reason=Scheduled count=1 msg=Successfully assigned compute/eval-image-prepull-vfn86 to kind-worker3
0.0604,Event,ADDED,eval-image-prepull-vfn86.18d4b0a0dd06294d,"reason=Pulled count=1 msg=Container image ""busybox:musl"" already present on machine"
0.0605,Event,ADDED,eval-image-prepull-vfn86.18d4b0a0dfcd261d,reason=Created count=1 msg=Created container: pause
0.0607,Event,ADDED,eval-image-prepull-vfn86.18d4b0a0ea83075c,reason=Started count=1 msg=Started container pause
0.0609,Event,ADDED,eval-image-prepull-vfn86.18d4b0a14b9d9f76,reason=Killing count=1 msg=Stopping container pause
0.0612,Event,ADDED,eval-image-prepull-z9xnb.18d4b0a0b6f9d604,reason=Scheduled count=1 msg=Successfully assigned compute/eval-image-prepull-z9xnb to kind-worker
0.0614,Event,ADDED,eval-image-prepull-z9xnb.18d4b0a0dd30f809,"reason=Pulled count=1 msg=Container image ""busybox:musl"" already present on machine"
0.0616,Event,ADDED,eval-image-prepull-z9xnb.18d4b0a0dfe530cf,reason=Created count=1 msg=Created container: pause
0.0619,Event,ADDED,eval-image-prepull-z9xnb.18d4b0a0ea4bede6,reason=Started count=1 msg=Started container pause
0.0621,Event,ADDED,eval-image-prepull-z9xnb.18d4b0a137bf0966,reason=Killing count=1 msg=Stopping container pause
0.0623,Event,ADDED,eval-image-prepull.18d4b0a0b5b88861,reason=SuccessfulCreate count=1 msg=Created pod: eval-image-prepull-skd9h
0.0625,Event,ADDED,eval-image-prepull.18d4b0a0b623ff80,reason=SuccessfulCreate count=1 msg=Created pod: eval-image-prepull-vfn86
0.0629,Event,ADDED,eval-image-prepull.18d4b0a0b6240129,reason=SuccessfulCreate count=1 msg=Created pod: eval-image-prepull-rwjzn
0.0631,Event,ADDED,eval-image-prepull.18d4b0a0b691c9fc,reason=SuccessfulCreate count=1 msg=Created pod: eval-image-prepull-98l7z
0.0632,Event,ADDED,eval-image-prepull.18d4b0a0b6922064,reason=SuccessfulCreate count=1 msg=Created pod: eval-image-prepull-z9xnb
0.0634,Event,ADDED,eval-image-prepull.18d4b290925dcdd5,reason=SuccessfulCreate count=1 msg=Created pod: eval-image-prepull-pkbbb
0.0638,Event,ADDED,eval-image-prepull.18d4b29092b5463d,reason=SuccessfulCreate count=1 msg=Created pod: eval-image-prepull-smw7s
0.0639,Event,ADDED,eval-image-prepull.18d4b29092c34a2a,reason=SuccessfulCreate count=1 msg=Created pod: eval-image-prepull-rdh2g
0.0641,Event,ADDED,eval-image-prepull.18d4b290932ba4f0,reason=SuccessfulCreate count=1 msg=Created pod: eval-image-prepull-56r9k
0.0643,Event,ADDED,eval-image-prepull.18d4b290932bc392,reason=SuccessfulCreate count=1 msg=Created pod: eval-image-prepull-552k2
0.0645,Event,ADDED,eval-sanitize-30-r0-000-2w7gp.18d4b29fbee744a5,reason=Scheduled count=None msg=Successfully assigned compute/eval-sanitize-30-r0-000-2w7gp to kind-worker3
0.0647,Event,ADDED,eval-sanitize-30-r0-000-2w7gp.18d4b29fdc6c7945,"reason=Pulled count=1 msg=Container image ""busybox:musl"" already present on machine"
0.0649,Event,ADDED,eval-sanitize-30-r0-000-2w7gp.18d4b29fdda268b2,reason=Created count=1 msg=Created container: task
0.0653,Event,ADDED,eval-sanitize-30-r0-000-2w7gp.18d4b29fe26eeec2,reason=Started count=1 msg=Started container task
0.0657,Event,ADDED,eval-sanitize-30-r0-000-nn82p.18d4b0b17fffa126,reason=Scheduled count=None msg=Successfully assigned compute/eval-sanitize-30-r0-000-nn82p to kind-worker3
0.066,Event,ADDED,eval-sanitize-30-r0-000-nn82p.18d4b0b19fcc170f,"reason=Pulled count=1 msg=Container image ""busybox:musl"" already present on machine"
0.0662,Event,ADDED,eval-sanitize-30-r0-000-nn82p.18d4b0b1a1469e6d,reason=Created count=1 msg=Created container: task
0.0665,Event,ADDED,eval-sanitize-30-r0-000-nn82p.18d4b0b1a374ffa1,reason=Started count=1 msg=Started container task
0.0667,Event,ADDED,eval-sanitize-30-r0-000.18d4b0b17ef501ef,reason=SuccessfulCreate count=1 msg=Created pod: eval-sanitize-30-r0-000-nn82p
0.0668,Event,ADDED,eval-sanitize-30-r0-000.18d4b0b73acedd2d,reason=Completed count=1 msg=Job completed
0.0674,Job,ADDED,eval-sanitize-30-r3-000,
0.0678,Event,ADDED,eval-sanitize-30-r0-000.18d4b29fbdd2d7b3,reason=SuccessfulCreate count=1 msg=Created pod: eval-sanitize-30-r0-000-2w7gp
0.068,Event,ADDED,eval-sanitize-30-r0-000.18d4b2a54ae152c6,reason=Completed count=1 msg=Job completed
0.0681,Event,ADDED,eval-sanitize-30-r0-001-g4swr.18d4b0b1b53fcc11,reason=Scheduled count=None msg=Successfully assigned compute/eval-sanitize-30-r0-001-g4swr to kind-worker
0.0683,Event,ADDED,eval-sanitize-30-r0-001-g4swr.18d4b0b1cf75ed7e,"reason=Pulled count=1 msg=Container image ""busybox:musl"" already present on machine"
0.0687,Event,ADDED,eval-sanitize-30-r0-001-g4swr.18d4b0b1d0a8af0f,reason=Created count=1 msg=Created container: task
0.0689,Event,ADDED,eval-sanitize-30-r0-001-g4swr.18d4b0b1d2c1428a,reason=Started count=1 msg=Started container task
0.069,Event,ADDED,eval-sanitize-30-r0-001-hpn6x.18d4b29ff8af8c35,reason=Scheduled count=None msg=Successfully assigned compute/eval-sanitize-30-r0-001-hpn6x to kind-worker5
0.0692,Event,ADDED,eval-sanitize-30-r0-001-hpn6x.18d4b2a0123007fb,"reason=Pulled count=1 msg=Container image ""busybox:musl"" already present on machine"
0.0694,Event,ADDED,eval-sanitize-30-r0-001-hpn6x.18d4b2a0134f55e9,reason=Created count=1 msg=Created container: task
0.0696,Event,ADDED,eval-sanitize-30-r0-001-hpn6x.18d4b2a01998aae9,reason=Started count=1 msg=Started container task
0.0698,Event,ADDED,eval-sanitize-30-r0-001.18d4b0b1b4235765,reason=SuccessfulCreate count=1 msg=Created pod: eval-sanitize-30-r0-001-g4swr
0.07,Event,ADDED,eval-sanitize-30-r0-001.18d4b0b75a7022ed,reason=Completed count=1 msg=Job completed
0.0702,Event,ADDED,eval-sanitize-30-r0-001.18d4b29ff78cf751,reason=SuccessfulCreate count=1 msg=Created pod: eval-sanitize-30-r0-001-hpn6x
0.0704,Event,ADDED,eval-sanitize-30-r0-001.18d4b2a58b6e1078,reason=Completed count=1 msg=Job completed
0.0707,Event,ADDED,eval-sanitize-30-r0-002-h279d.18d4b0b1ef6433c1,reason=Scheduled count=None msg=Successfully assigned compute/eval-sanitize-30-r0-002-h279d to kind-worker5
0.071,Event,ADDED,eval-sanitize-30-r0-002-h279d.18d4b0b20b75eb5c,"reason=Pulled count=1 msg=Container image ""busybox:musl"" already present on machine"
0.0712,Event,ADDED,eval-sanitize-30-r0-002-h279d.18d4b0b20cbcff0d,reason=Created count=1 msg=Created container: task
0.0714,Event,ADDED,eval-sanitize-30-r0-002-h279d.18d4b0b210f2f857,reason=Started count=1 msg=Started container task
0.0716,Event,ADDED,eval-sanitize-30-r0-002-ttv2q.18d4b2a03426ca9d,reason=Scheduled count=None msg=Successfully assigned compute/eval-sanitize-30-r0-002-ttv2q to kind-worker
0.0719,Event,ADDED,eval-sanitize-30-r0-002-ttv2q.18d4b2a04d79d5cd,"reason=Pulled count=1 msg=Container image ""busybox:musl"" already present on machine"
0.0721,Event,ADDED,eval-sanitize-30-r0-002-ttv2q.18d4b2a04e9d3c92,reason=Created count=1 msg=Created container: task
0.0723,Event,ADDED,eval-sanitize-30-r0-002-ttv2q.18d4b2a052a40c31,reason=Started count=1 msg=Started container task
0.0726,Event,ADDED,eval-sanitize-30-r0-002.18d4b0b1ee4c2cd6,reason=SuccessfulCreate count=1 msg=Created pod: eval-sanitize-30-r0-002-h279d
0.0728,Event,ADDED,eval-sanitize-30-r0-002.18d4b0b781c854f1,reason=Completed count=1 msg=Job completed
0.073,Event,ADDED,eval-sanitize-30-r0-002.18d4b2a03326a794,reason=SuccessfulCreate count=1 msg=Created pod: eval-sanitize-30-r0-002-ttv2q
0.0731,Event,ADDED,eval-sanitize-30-r0-002.18d4b2a5dd97f54e,reason=Completed count=1 msg=Job completed
0.0733,TaskRequest,MODIFIED,eval-sanitize-30-r3-000,phase=Scheduled job=None
0.0736,Event,ADDED,eval-sanitize-30-r0-003-4nsvk.18d4b0b230ea8044,reason=Scheduled count=None msg=Successfully assigned compute/eval-sanitize-30-r0-003-4nsvk to kind-worker3
0.0738,Event,ADDED,eval-sanitize-30-r0-003-4nsvk.18d4b0b24aa92b31,"reason=Pulled count=1 msg=Container image ""busybox:musl"" already present on machine"
0.074,Event,ADDED,eval-sanitize-30-r0-003-4nsvk.18d4b0b24bd56095,reason=Created count=1 msg=Created container: task
0.0742,Event,ADDED,eval-sanitize-30-r0-003-4nsvk.18d4b0b24edd8924,reason=Started count=1 msg=Started container task
0.0745,Event,ADDED,eval-sanitize-30-r0-003-wjh88.18d4b2a0708643e9,reason=Scheduled count=None msg=Successfully assigned compute/eval-sanitize-30-r0-003-wjh88 to kind-worker3
0.0748,Event,ADDED,eval-sanitize-30-r0-003-wjh88.18d4b2a08ba87ec3,"reason=Pulled count=1 msg=Container image ""busybox:musl"" already present on machine"
0.0752,Event,ADDED,eval-sanitize-30-r0-003-wjh88.18d4b2a08cc3568a,reason=Created count=1 msg=Created container: task
0.0759,Event,ADDED,eval-sanitize-30-r0-003-wjh88.18d4b2a09206f7d6,reason=Started count=1 msg=Started container task
0.0763,Event,ADDED,eval-sanitize-30-r0-003.18d4b0b22f90bd6b,reason=SuccessfulCreate count=1 msg=Created pod: eval-sanitize-30-r0-003-4nsvk
0.0767,Event,ADDED,eval-sanitize-30-r0-003.18d4b0b7b28236fd,reason=Completed count=1 msg=Job completed
0.0773,Event,ADDED,eval-sanitize-30-r0-003.18d4b2a06f5a8c62,reason=SuccessfulCreate count=1 msg=Created pod: eval-sanitize-30-r0-003-wjh88
0.0777,Event,ADDED,eval-sanitize-30-r0-003.18d4b2a6030af610,reason=Completed count=1 msg=Job completed
0.0781,Event,ADDED,eval-sanitize-30-r0-004-47gm4.18d4b0b2668e83dd,reason=Scheduled count=None msg=Successfully assigned compute/eval-sanitize-30-r0-004-47gm4 to kind-worker
0.0784,Event,ADDED,eval-sanitize-30-r0-004-47gm4.18d4b0b28128d7e0,"reason=Pulled count=1 msg=Container image ""busybox:musl"" already present on machine"
0.0787,Event,ADDED,eval-sanitize-30-r0-004-47gm4.18d4b0b2826b17e5,reason=Created count=1 msg=Created container: task
0.0791,Event,ADDED,eval-sanitize-30-r0-004-47gm4.18d4b0b286c88a00,reason=Started count=1 msg=Started container task
0.0793,Event,ADDED,eval-sanitize-30-r0-004-q27lz.18d4b2a0acd053c5,reason=Scheduled count=None msg=Successfully assigned compute/eval-sanitize-30-r0-004-q27lz to kind-worker5
0.0796,Event,ADDED,eval-sanitize-30-r0-004-q27lz.18d4b2a0c4ef994a,"reason=Pulled count=1 msg=Container image ""busybox:musl"" already present on machine"
0.0804,Pod,ADDED,eval-sanitize-30-r3-000-4cpr6,phase=Pending node=None
0.0811,Job,MODIFIED,eval-sanitize-30-r3-000,
0.0815,Event,ADDED,eval-sanitize-30-r0-004-q27lz.18d4b2a0c5ff974f,reason=Created count=1 msg=Created container: task
0.0817,Event,ADDED,eval-sanitize-30-r0-004-q27lz.18d4b2a0cb6a792f,reason=Started count=1 msg=Started container task
0.082,Event,ADDED,eval-sanitize-30-r0-004.18d4b0b265413612,reason=SuccessfulCreate count=1 msg=Created pod: eval-sanitize-30-r0-004-47gm4
0.0822,Event,ADDED,eval-sanitize-30-r0-004.18d4b0b80e669820,reason=Completed count=1 msg=Job completed
0.0823,TaskRequest,MODIFIED,eval-sanitize-30-r3-000,phase=Scheduled job=None
0.0826,Event,ADDED,eval-sanitize-30-r0-004.18d4b2a0ab8e8b36,reason=SuccessfulCreate count=1 msg=Created pod: eval-sanitize-30-r0-004-q27lz
0.0828,Event,ADDED,eval-sanitize-30-r0-004.18d4b2a63fa7b994,reason=Completed count=1 msg=Job completed
0.083,Event,ADDED,eval-sanitize-30-r0-005-fzkvw.18d4b0b2a10a5033,reason=Scheduled count=None msg=Successfully assigned compute/eval-sanitize-30-r0-005-fzkvw to kind-worker5
0.0831,Event,ADDED,eval-sanitize-30-r0-005-fzkvw.18d4b0b2ba13741a,"reason=Pulled count=1 msg=Container image ""busybox:musl"" already present on machine"
0.0834,Event,ADDED,eval-sanitize-30-r0-005-fzkvw.18d4b0b2bb264308,reason=Created count=1 msg=Created container: task
0.0837,Event,ADDED,eval-sanitize-30-r0-005-fzkvw.18d4b0b2bd56ca06,reason=Started count=1 msg=Started container task
0.0839,Event,ADDED,eval-sanitize-30-r0-005-rtfzj.18d4b2a0e8db9779,reason=Scheduled count=None msg=Successfully assigned compute/eval-sanitize-30-r0-005-rtfzj to kind-worker3
0.084,Event,ADDED,eval-sanitize-30-r0-005-rtfzj.18d4b2a1027d8748,"reason=Pulled count=1 msg=Container image ""busybox:musl"" already present on machine"
0.0842,Event,ADDED,eval-sanitize-30-r0-005-rtfzj.18d4b2a1038b1cb3,reason=Created count=1 msg=Created container: task
0.0844,Event,ADDED,eval-sanitize-30-r0-005-rtfzj.18d4b2a107f0a04d,reason=Started count=1 msg=Started container task
0.0845,Event,ADDED,eval-sanitize-30-r0-005.18d4b0b29fe50ab7,reason=SuccessfulCreate count=1 msg=Created pod: eval-sanitize-30-r0-005-fzkvw
0.0849,Event,ADDED,eval-sanitize-30-r0-005.18d4b0b8360fff56,reason=Completed count=1 msg=Job completed
0.0851,Event,ADDED,eval-sanitize-30-r0-005.18d4b2a0e7a5b79a,reason=SuccessfulCreate count=1 msg=Created pod: eval-sanitize-30-r0-005-rtfzj
0.0853,Event,ADDED,eval-sanitize-30-r0-005.18d4b2a677506736,reason=Completed count=1 msg=Job completed
0.0854,Event,ADDED,eval-sanitize-30-r0-006-7vqd9.18d4b2a1227b8805,reason=Scheduled count=None msg=Successfully assigned compute/eval-sanitize-30-r0-006-7vqd9 to kind-worker
0.0858,Event,ADDED,eval-sanitize-30-r0-006-7vqd9.18d4b2a13f247d91,"reason=Pulled count=1 msg=Container image ""busybox:musl"" already present on machine"
0.086,Event,ADDED,eval-sanitize-30-r0-006-7vqd9.18d4b2a1404b2b04,reason=Created count=1 msg=Created container: task
0.0862,Event,ADDED,eval-sanitize-30-r0-006-7vqd9.18d4b2a144fb7da0,reason=Started count=1 msg=Started container task
0.0864,Event,ADDED,eval-sanitize-30-r0-006-zgc55.18d4b0b2dcf12924,reason=Scheduled count=None msg=Successfully assigned compute/eval-sanitize-30-r0-006-zgc55 to kind-worker2
0.0866,Event,ADDED,eval-sanitize-30-r0-006-zgc55.18d4b0b2f751f45d,"reason=Pulled count=1 msg=Container image ""busybox:musl"" already present on machine"
0.0868,Event,ADDED,eval-sanitize-30-r0-006-zgc55.18d4b0b2f867c103,reason=Created count=1 msg=Created container: task
0.087,Event,ADDED,eval-sanitize-30-r0-006-zgc55.18d4b0b2fc08f144,reason=Started count=1 msg=Started container task
0.0873,Event,ADDED,eval-sanitize-30-r0-006.18d4b0b2dbe13890,reason=SuccessfulCreate count=1 msg=Created pod: eval-sanitize-30-r0-006-zgc55
0.0875,Event,ADDED,eval-sanitize-30-r0-006.18d4b0b87c21df1e,reason=Completed count=1 msg=Job completed
0.0876,Event,ADDED,eval-sanitize-30-r0-006.18d4b2a12141cdf8,reason=SuccessfulCreate count=1 msg=Created pod: eval-sanitize-30-r0-006-7vqd9
0.0878,Event,ADDED,eval-sanitize-30-r0-006.18d4b2a6c37464b2,reason=Completed count=1 msg=Job completed
0.0881,Event,ADDED,eval-sanitize-30-r0-007-5749f.18d4b2a15e826c1a,reason=Scheduled count=None msg=Successfully assigned compute/eval-sanitize-30-r0-007-5749f to kind-worker2
0.0883,Event,ADDED,eval-sanitize-30-r0-007-5749f.18d4b2a17935b528,"reason=Pulled count=1 msg=Container image ""busybox:musl"" already present on machine"
0.0885,Event,ADDED,eval-sanitize-30-r0-007-5749f.18d4b2a17a56b6ed,reason=Created count=1 msg=Created container: task
0.0888,Event,ADDED,eval-sanitize-30-r0-007-5749f.18d4b2a17f93005f,reason=Started count=1 msg=Started container task
0.089,Event,ADDED,eval-sanitize-30-r0-007-wcqh8.18d4b0b31cbd324c,reason=Scheduled count=None msg=Successfully assigned compute/eval-sanitize-30-r0-007-wcqh8 to kind-worker3
0.0891,Event,ADDED,eval-sanitize-30-r0-007-wcqh8.18d4b0b33e0db342,"reason=Pulled count=1 msg=Container image ""busybox:musl"" already present on machine"
0.0893,Event,ADDED,eval-sanitize-30-r0-007-wcqh8.18d4b0b33f37367b,reason=Created count=1 msg=Created container: task
0.0904,Event,ADDED,eval-sanitize-30-r0-007-wcqh8.18d4b0b3437efc2b,reason=Started count=1 msg=Started container task
0.0911,Event,ADDED,eval-sanitize-30-r0-007.18d4b0b31730fd4c,reason=SuccessfulCreate count=1 msg=Created pod: eval-sanitize-30-r0-007-wcqh8
0.0916,Event,ADDED,eval-sanitize-30-r0-007.18d4b0b8dffe1ece,reason=Completed count=1 msg=Job completed
0.0929,Pod,MODIFIED,eval-sanitize-30-r3-000-4cpr6,phase=Pending node=kind-worker3
0.0933,Event,ADDED,eval-sanitize-30-r0-007.18d4b2a15d5048a1,reason=SuccessfulCreate count=1 msg=Created pod: eval-sanitize-30-r0-007-5749f
0.0935,Event,ADDED,eval-sanitize-30-r0-007.18d4b2a709921da6,reason=Completed count=1 msg=Job completed
0.0936,Event,ADDED,eval-sanitize-30-r0-008-6lh4h.18d4b2a19a483d74,reason=Scheduled count=None msg=Successfully assigned compute/eval-sanitize-30-r0-008-6lh4h to kind-worker5
0.0938,Event,ADDED,eval-sanitize-30-r0-008-6lh4h.18d4b2a1b73e3616,"reason=Pulled count=1 msg=Container image ""busybox:musl"" already present on machine"
0.0942,Event,ADDED,eval-sanitize-30-r0-008-6lh4h.18d4b2a1b8594ed3,reason=Created count=1 msg=Created container: task
0.0946,Event,ADDED,eval-sanitize-30-r0-008-6lh4h.18d4b2a1bf86f2e9,reason=Started count=1 msg=Started container task
0.095,Event,ADDED,eval-sanitize-30-r0-008-xwn89.18d4b0b3582bb0d7,reason=Scheduled count=None msg=Successfully assigned compute/eval-sanitize-30-r0-008-xwn89 to kind-worker2
0.0955,Event,ADDED,eval-sanitize-30-r0-008-xwn89.18d4b0b371ea8fb9,"reason=Pulled count=1 msg=Container image ""busybox:musl"" already present on machine"
0.0958,Event,ADDED,eval-sanitize-30-r0-008-xwn89.18d4b0b3730cc321,reason=Created count=1 msg=Created container: task
0.0961,Event,ADDED,eval-sanitize-30-r0-008-xwn89.18d4b0b375241687,reason=Started count=1 msg=Started container task
0.0963,Event,ADDED,eval-sanitize-30-r0-008.18d4b0b35398604e,reason=SuccessfulCreate count=1 msg=Created pod: eval-sanitize-30-r0-008-xwn89
0.0967,Event,ADDED,eval-sanitize-30-r0-008.18d4b0b8f538c179,reason=Completed count=1 msg=Job completed
0.0969,Event,ADDED,eval-sanitize-30-r0-008.18d4b2a198c3378a,reason=SuccessfulCreate count=1 msg=Created pod: eval-sanitize-30-r0-008-6lh4h
0.0971,Event,ADDED,eval-sanitize-30-r0-008.18d4b2a72d99c87f,reason=Completed count=1 msg=Job completed
0.0972,Event,ADDED,eval-sanitize-30-r0-009-h99xs.18d4b0b38f7e7606,reason=Scheduled count=None msg=Successfully assigned compute/eval-sanitize-30-r0-009-h99xs to kind-worker3
0.0975,Event,ADDED,eval-sanitize-30-r0-009-h99xs.18d4b0b3a9702c75,"reason=Pulled count=1 msg=Container image ""busybox:musl"" already present on machine"
0.0977,Event,ADDED,eval-sanitize-30-r0-009-h99xs.18d4b0b3aa823066,reason=Created count=1 msg=Created container: task
0.0979,Event,ADDED,eval-sanitize-30-r0-009-h99xs.18d4b0b3ac925edc,reason=Started count=1 msg=Started container task
0.098,Event,ADDED,eval-sanitize-30-r0-009-mjkmm.18d4b2a1df188eb4,reason=Scheduled count=None msg=Successfully assigned compute/eval-sanitize-30-r0-009-mjkmm to kind-worker2
0.0982,Event,ADDED,eval-sanitize-30-r0-009-mjkmm.18d4b2a1fa01d299,"reason=Pulled count=1 msg=Container image ""busybox:musl"" already present on machine"
0.0984,Event,ADDED,eval-sanitize-30-r0-009-mjkmm.18d4b2a1fb2daa89,reason=Created count=1 msg=Created container: task
0.0986,Event,ADDED,eval-sanitize-30-r0-009-mjkmm.18d4b2a20090975d,reason=Started count=1 msg=Started container task
0.0988,Event,ADDED,eval-sanitize-30-r0-009.18d4b0b38e1c5ac7,reason=SuccessfulCreate count=1 msg=Created pod: eval-sanitize-30-r0-009-h99xs
0.099,Event,ADDED,eval-sanitize-30-r0-009.18d4b0b91ed92c1e,reason=Completed count=1 msg=Job completed
0.0992,Event,ADDED,eval-sanitize-30-r0-009.18d4b2a1d9cf3ac3,reason=SuccessfulCreate count=1 msg=Created pod: eval-sanitize-30-r0-009-mjkmm
0.0995,Event,ADDED,eval-sanitize-30-r0-009.18d4b2a780f21f77,reason=Completed count=1 msg=Job completed
0.0998,Event,ADDED,eval-sanitize-30-r0-010-2qqvn.18d4b2a210e09f39,reason=Scheduled count=None msg=Successfully assigned compute/eval-sanitize-30-r0-010-2qqvn to kind-worker3
0.1004,Event,ADDED,eval-sanitize-30-r0-010-2qqvn.18d4b2a22b62b952,"reason=Pulled count=1 msg=Container image ""busybox:musl"" already present on machine"
0.1007,Event,ADDED,eval-sanitize-30-r0-010-2qqvn.18d4b2a22c869255,reason=Created count=1 msg=Created container: task
0.101,Event,ADDED,eval-sanitize-30-r0-010-2qqvn.18d4b2a23100fcdb,reason=Started count=1 msg=Started container task
0.1014,Event,ADDED,eval-sanitize-30-r0-010-lgxfk.18d4b0b3d578e3c4,reason=Scheduled count=None msg=Successfully assigned compute/eval-sanitize-30-r0-010-lgxfk to kind-worker5
0.1016,Event,ADDED,eval-sanitize-30-r0-010-lgxfk.18d4b0b3eeb315a0,"reason=Pulled count=1 msg=Container image ""busybox:musl"" already present on machine"
0.1018,Event,ADDED,eval-sanitize-30-r0-010-lgxfk.18d4b0b3f0151ae8,reason=Created count=1 msg=Created container: task
0.1021,Event,ADDED,eval-sanitize-30-r0-010-lgxfk.18d4b0b3f4573fa6,reason=Started count=1 msg=Started container task
0.1023,Event,ADDED,eval-sanitize-30-r0-010.18d4b0b3ca3edbdf,reason=SuccessfulCreate count=1 msg=Created pod: eval-sanitize-30-r0-010-lgxfk
0.1025,Event,ADDED,eval-sanitize-30-r0-010.18d4b0b9263b3840,reason=Completed count=1 msg=Job completed
0.1027,Event,ADDED,eval-sanitize-30-r0-010.18d4b2a20f85305b,reason=SuccessfulCreate count=1 msg=Created pod: eval-sanitize-30-r0-010-2qqvn
0.1048,Node,MODIFIED,kind-worker3,taints=0
0.1051,Event,ADDED,eval-sanitize-30-r0-010.18d4b2a7a2b403c0,reason=Completed count=1 msg=Job completed
0.1053,Event,ADDED,eval-sanitize-30-r0-011-fdtl4.18d4b2a250426221,reason=Scheduled count=None msg=Successfully assigned compute/eval-sanitize-30-r0-011-fdtl4 to kind-worker5
0.1054,Event,ADDED,eval-sanitize-30-r0-011-fdtl4.18d4b2a26c9ac507,"reason=Pulled count=1 msg=Container image ""busybox:musl"" already present on machine"
0.1056,Event,ADDED,eval-sanitize-30-r0-011-fdtl4.18d4b2a26dcde4d6,reason=Created count=1 msg=Created container: task
0.106,Event,ADDED,eval-sanitize-30-r0-011-fdtl4.18d4b2a276c3f1f9,reason=Started count=1 msg=Started container task
0.1062,Event,ADDED,eval-sanitize-30-r0-011-xfnql.18d4b0b406b778ea,reason=Scheduled count=None msg=Successfully assigned compute/eval-sanitize-30-r0-011-xfnql to kind-worker
0.1064,Event,ADDED,eval-sanitize-30-r0-011-xfnql.18d4b0b41fda7ae1,"reason=Pulled count=1 msg=Container image ""busybox:musl"" already present on machine"
0.1076,Pod,MODIFIED,eval-sanitize-30-r3-000-4cpr6,phase=Pending node=kind-worker3
0.1079,Event,ADDED,eval-sanitize-30-r0-011-xfnql.18d4b0b420ebac10,reason=Created count=1 msg=Created container: task
0.108,Event,ADDED,eval-sanitize-30-r0-011-xfnql.18d4b0b4230362e0,reason=Started count=1 msg=Started container task
0.1082,Event,ADDED,eval-sanitize-30-r0-011.18d4b0b40559cf77,reason=SuccessfulCreate count=1 msg=Created pod: eval-sanitize-30-r0-011-xfnql
0.1084,Event,ADDED,eval-sanitize-30-r0-011.18d4b0b9af113041,reason=Completed count=1 msg=Job completed
0.1087,Event,ADDED,eval-sanitize-30-r0-011.18d4b2a24f6648d0,reason=SuccessfulCreate count=1 msg=Created pod: eval-sanitize-30-r0-011-fdtl4
0.1089,Event,ADDED,eval-sanitize-30-r0-011.18d4b2a7e4afb8e4,reason=Completed count=1 msg=Job completed
0.109,Event,ADDED,eval-sanitize-30-r0-012-4fscb.18d4b0b442928296,reason=Scheduled count=None msg=Successfully assigned compute/eval-sanitize-30-r0-012-4fscb to kind-worker5
0.1092,Event,ADDED,eval-sanitize-30-r0-012-4fscb.18d4b0b45be7d10a,"reason=Pulled count=1 msg=Container image ""busybox:musl"" already present on machine"
0.1095,Event,ADDED,eval-sanitize-30-r0-012-4fscb.18d4b0b45d0949dc,reason=Created count=1 msg=Created container: task
0.1097,Event,ADDED,eval-sanitize-30-r0-012-4fscb.18d4b0b45f0f5d15,reason=Started count=1 msg=Started container task
0.1099,Event,ADDED,eval-sanitize-30-r0-012-dszkf.18d4b2a28755c235,reason=Scheduled count=None msg=Successfully assigned compute/eval-sanitize-30-r0-012-dszkf to kind-worker3
0.1102,Event,ADDED,eval-sanitize-30-r0-012-dszkf.18d4b2a2a69285bd,"reason=Pulled count=1 msg=Container image ""busybox:musl"" already present on machine"
0.1104,Event,ADDED,eval-sanitize-30-r0-012-dszkf.18d4b2a2a7babd38,reason=Created count=1 msg=Created container: task
0.1105,Event,ADDED,eval-sanitize-30-r0-012-dszkf.18d4b2a2ae046922,reason=Started count=1 msg=Started container task
0.1107,Event,ADDED,eval-sanitize-30-r0-012.18d4b0b44110795a,reason=SuccessfulCreate count=1 msg=Created pod: eval-sanitize-30-r0-012-4fscb
0.1109,Event,ADDED,eval-sanitize-30-r0-012.18d4b0b99bd7d4fa,reason=Completed count=1 msg=Job completed
0.111,Event,ADDED,eval-sanitize-30-r0-012.18d4b2a286a184b6,reason=SuccessfulCreate count=1 msg=Created pod: eval-sanitize-30-r0-012-dszkf
0.1112,Event,ADDED,eval-sanitize-30-r0-012.18d4b2a81cbd9025,reason=Completed count=1 msg=Job completed
0.1114,Event,ADDED,eval-sanitize-30-r0-013-4xbf5.18d4b0b481141630,reason=Scheduled count=None msg=Successfully assigned compute/eval-sanitize-30-r0-013-4xbf5 to kind-worker4
0.1115,Event,ADDED,eval-sanitize-30-r0-013-4xbf5.18d4b0b49aa7efe2,"reason=Pulled count=1 msg=Container image ""busybox:musl"" already present on machine"
0.1117,Event,ADDED,eval-sanitize-30-r0-013-4xbf5.18d4b0b49bb7df2b,reason=Created count=1 msg=Created container: task
0.1119,Event,ADDED,eval-sanitize-30-r0-013-4xbf5.18d4b0b49dcb5bff,reason=Started count=1 msg=Started container task
0.1123,Event,ADDED,eval-sanitize-30-r0-013-jmw55.18d4b2a2c352ec3d,reason=Scheduled count=None msg=Successfully assigned compute/eval-sanitize-30-r0-013-jmw55 to kind-worker4
0.1127,Event,ADDED,eval-sanitize-30-r0-013-jmw55.18d4b2a2e4dfefb8,"reason=Pulled count=1 msg=Container image ""busybox:musl"" already present on machine"
0.1134,Event,ADDED,eval-sanitize-30-r0-013-jmw55.18d4b2a2e6069b28,reason=Created count=1 msg=Created container: task
0.1135,Event,ADDED,eval-sanitize-30-r0-013-jmw55.18d4b2a2f21acdea,reason=Started count=1 msg=Started container task
0.114,Event,ADDED,eval-sanitize-30-r0-013.18d4b0b47cf4cdf9,reason=SuccessfulCreate count=1 msg=Created pod: eval-sanitize-30-r0-013-4xbf5
0.1142,Event,ADDED,eval-sanitize-30-r0-013.18d4b0ba37366bff,reason=Completed count=1 msg=Job completed
0.1143,Event,ADDED,eval-sanitize-30-r0-013.18d4b2a2c2f75a2d,reason=SuccessfulCreate count=1 msg=Created pod: eval-sanitize-30-r0-013-jmw55
0.1145,Event,ADDED,eval-sanitize-30-r0-013.18d4b2a85b5b79d3,reason=Completed count=1 msg=Job completed
0.1148,Event,ADDED,eval-sanitize-30-r0-014-77n8n.18d4b2a2fe06a88b,"reason=FailedScheduling count=None msg=0/6 nodes are available: 1 c_wall violated: 1 conflicting context pair(s) with node memory, 5 node(s) had untolerated taint(s). no new claims to deallocate, preemption: 0/6 nodes are available: 1 No preemption victims found for incoming pod, 5 Preemption is not helpful for scheduling."
0.115,Event,ADDED,eval-sanitize-30-r0-014-77n8n.18d4b2a2feb995b3,"reason=FailedScheduling count=None msg=0/6 nodes are available: 1 c_wall violated: 1 conflicting context pair(s) with node memory, 5 node(s) had untolerated taint(s). no new claims to deallocate, preemption: 0/6 nodes are available: 1 No preemption victims found for incoming pod, 5 Preemption is not helpful for scheduling."
0.1152,Event,ADDED,eval-sanitize-30-r0-014-77n8n.18d4b2a9a1c3172e,reason=Scheduled count=None msg=Successfully assigned compute/eval-sanitize-30-r0-014-77n8n to kind-worker
0.1165,Node,MODIFIED,kind-worker3,taints=0
0.1168,Event,ADDED,eval-sanitize-30-r0-014-77n8n.18d4b2a9d0737837,"reason=Pulled count=1 msg=Container image ""busybox:musl"" already present on machine"
0.117,Event,ADDED,eval-sanitize-30-r0-014-77n8n.18d4b2a9d2b19650,reason=Created count=1 msg=Created container: task
0.1172,Event,ADDED,eval-sanitize-30-r0-014-77n8n.18d4b2a9dee3677e,reason=Started count=1 msg=Started container task
0.1174,Event,ADDED,eval-sanitize-30-r0-014-nfw4r.18d4b0b4bda4caec,reason=Scheduled count=None msg=Successfully assigned compute/eval-sanitize-30-r0-014-nfw4r to kind-worker2
0.1176,Event,ADDED,eval-sanitize-30-r0-014-nfw4r.18d4b0b4d7f4ac32,"reason=Pulled count=1 msg=Container image ""busybox:musl"" already present on machine"
0.1177,Event,ADDED,eval-sanitize-30-r0-014-nfw4r.18d4b0b4d9183bf5,reason=Created count=1 msg=Created container: task
0.118,Event,ADDED,eval-sanitize-30-r0-014-nfw4r.18d4b0b4ddcb5bc0,reason=Started count=1 msg=Started container task
0.1183,Event,ADDED,eval-sanitize-30-r0-014.18d4b0b4b8661383,reason=SuccessfulCreate count=1 msg=Created pod: eval-sanitize-30-r0-014-nfw4r
0.1185,Event,ADDED,eval-sanitize-30-r0-014.18d4b0ba59e54c3f,reason=Completed count=1 msg=Job completed
0.1187,Event,ADDED,eval-sanitize-30-r0-014.18d4b2a2fdc626aa,reason=SuccessfulCreate count=1 msg=Created pod: eval-sanitize-30-r0-014-77n8n
0.1188,Event,ADDED,eval-sanitize-30-r0-014.18d4b2b0564585a8,reason=Completed count=1 msg=Job completed
0.1191,Event,ADDED,eval-sanitize-30-r0-015-6k477.18d4b2a33feeba96,"reason=FailedScheduling count=None msg=0/6 nodes are available: 1 c_wall violated: 1 conflicting context pair(s) with node memory, 5 node(s) had untolerated taint(s). no new claims to deallocate, preemption: 0/6 nodes are available: 1 No preemption victims found for incoming pod, 5 Preemption is not helpful for scheduling."
0.1194,Event,ADDED,eval-sanitize-30-r0-015-6k477.18d4b2a3406ce3ba,"reason=FailedScheduling count=None msg=0/6 nodes are available: 1 c_wall violated: 1 conflicting context pair(s) with node memory, 5 node(s) had untolerated taint(s). no new claims to deallocate, preemption: 0/6 nodes are available: 1 No preemption victims found for incoming pod, 5 Preemption is not helpful for scheduling."
0.1196,Event,ADDED,eval-sanitize-30-r0-015-6k477.18d4b2a4e07fa7d1,"reason=FailedScheduling count=None msg=0/6 nodes are available: 1 c_wall violated: 2 conflicting context pair(s) with node memory, 5 node(s) had untolerated taint(s). no new claims to deallocate, preemption: 0/6 nodes are available: 1 No preemption victims found for incoming pod, 5 Preemption is not helpful for scheduling."
0.1198,Event,ADDED,eval-sanitize-30-r0-015-6k477.18d4b2a55cb08ae1,"reason=FailedScheduling count=None msg=0/6 nodes are available: 1 c_wall violated: 3 conflicting context pair(s) with node memory, 5 node(s) had untolerated taint(s). no new claims to deallocate, preemption: 0/6 nodes are available: 1 No preemption victims found for incoming pod, 5 Preemption is not helpful for scheduling."
0.12,Event,ADDED,eval-sanitize-30-r0-015-6k477.18d4b2a98d3bca07,reason=Scheduled count=None msg=Successfully assigned compute/eval-sanitize-30-r0-015-6k477 to kind-worker2
0.1202,Event,ADDED,eval-sanitize-30-r0-015-6k477.18d4b2a9bacd952e,"reason=Pulled count=1 msg=Container image ""busybox:musl"" already present on machine"
0.1203,Event,ADDED,eval-sanitize-30-r0-015-6k477.18d4b2a9bc375d70,reason=Created count=1 msg=Created container: task
0.1205,Event,ADDED,eval-sanitize-30-r0-015-6k477.18d4b2a9bf7c7afe,reason=Started count=1 msg=Started container task
0.1207,Event,ADDED,eval-sanitize-30-r0-015-rw9q5.18d4b0b4f985af81,reason=Scheduled count=None msg=Successfully assigned compute/eval-sanitize-30-r0-015-rw9q5 to kind-worker4
0.1208,Event,ADDED,eval-sanitize-30-r0-015-rw9q5.18d4b0b512aa89e0,"reason=Pulled count=1 msg=Container image ""busybox:musl"" already present on machine"
0.121,Event,ADDED,eval-sanitize-30-r0-015-rw9q5.18d4b0b513b8532a,reason=Created count=1 msg=Created container: task
0.1212,Event,ADDED,eval-sanitize-30-r0-015-rw9q5.18d4b0b515b32749,reason=Started count=1 msg=Started container task
0.1214,Event,ADDED,eval-sanitize-30-r0-015.18d4b0b4f427c91d,reason=SuccessfulCreate count=1 msg=Created pod: eval-sanitize-30-r0-015-rw9q5
0.1215,Event,ADDED,eval-sanitize-30-r0-015.18d4b0baaf858983,reason=Completed count=1 msg=Job completed
0.1217,Event,ADDED,eval-sanitize-30-r0-015.18d4b2a33fa7d6e9,reason=SuccessfulCreate count=1 msg=Created pod: eval-sanitize-30-r0-015-6k477
0.1219,Event,ADDED,eval-sanitize-30-r0-015.18d4b2b00649b397,reason=Completed count=1 msg=Job completed
0.122,Event,ADDED,eval-sanitize-30-r0-016-4q5kq.18d4b2a3755a627d,"reason=FailedScheduling count=None msg=0/6 nodes are available: 1 c_wall violated: 1 conflicting context pair(s) with node memory, 5 node(s) had untolerated taint(s). no new claims to deallocate, preemption: 0/6 nodes are available: 1 No preemption victims found for incoming pod, 5 Preemption is not helpful for scheduling."
0.1222,Event,ADDED,eval-sanitize-30-r0-016-4q5kq.18d4b2a375d6ddf7,"reason=FailedScheduling count=None msg=0/6 nodes are available: 1 c_wall violated: 1 conflicting context pair(s) with node memory, 5 node(s) had untolerated taint(s). no new claims to deallocate, preemption: 0/6 nodes are available: 1 No preemption victims found for incoming pod, 5 Preemption is not helpful for scheduling."
0.1224,Event,ADDED,eval-sanitize-30-r0-016-4q5kq.18d4b2a4e0a795aa,"reason=FailedScheduling count=None msg=0/6 nodes are available: 1 c_wall violated: 2 conflicting context pair(s) with node memory, 5 node(s) had untolerated taint(s). no new claims to deallocate, preemption: 0/6 nodes are available: 1 No preemption victims found for incoming pod, 5 Preemption is not helpful for scheduling."
0.1226,Event,ADDED,eval-sanitize-30-r0-016-4q5kq.18d4b2a55ce046c7,"reason=FailedScheduling count=None msg=0/6 nodes are available: 1 c_wall violated: 3 conflicting context pair(s) with node memory, 5 node(s) had untolerated taint(s). no new claims to deallocate, preemption: 0/6 nodes are available: 1 No preemption victims found for incoming pod, 5 Preemption is not helpful for scheduling."
0.123,Event,ADDED,eval-sanitize-30-r0-016-4q5kq.18d4b2a9968300ba,reason=Scheduled count=None msg=Successfully assigned compute/eval-sanitize-30-r0-016-4q5kq to kind-worker2
0.1236,Event,ADDED,eval-sanitize-30-r0-016-4q5kq.18d4b2a9b9b23377,"reason=Pulled count=1 msg=Container image ""busybox:musl"" already present on machine"
0.1238,Event,ADDED,eval-sanitize-30-r0-016-4q5kq.18d4b2a9bb2f1024,reason=Created count=1 msg=Created container: task
0.1246,Event,ADDED,eval-sanitize-30-r0-016-4q5kq.18d4b2a9bf197507,reason=Started count=1 msg=Started container task
0.1249,Event,ADDED,eval-sanitize-30-r0-016-f4lw7.18d4b0b53529cdb9,reason=Scheduled count=None msg=Successfully assigned compute/eval-sanitize-30-r0-016-f4lw7 to kind-worker4
0.1252,Event,ADDED,eval-sanitize-30-r0-016-f4lw7.18d4b0b54d7fa5e4,"reason=Pulled count=1 msg=Container image ""busybox:musl"" already present on machine"
0.1254,Event,ADDED,eval-sanitize-30-r0-016-f4lw7.18d4b0b54e99f287,reason=Created count=1 msg=Created container: task
0.1258,Event,ADDED,eval-sanitize-30-r0-016-f4lw7.18d4b0b552d607b8,reason=Started count=1 msg=Started container task
0.126,Event,ADDED,eval-sanitize-30-r0-016.18d4b0b52fa02184,reason=SuccessfulCreate count=1 msg=Created pod: eval-sanitize-30-r0-016-f4lw7
0.1262,Event,ADDED,eval-sanitize-30-r0-016.18d4b0baecc9c046,reason=Completed count=1 msg=Job completed
0.1265,Event,ADDED,eval-sanitize-30-r0-016.18d4b2a375164598,reason=SuccessfulCreate count=1 msg=Created pod: eval-sanitize-30-r0-016-4q5kq
0.1267,Event,ADDED,eval-sanitize-30-r0-016.18d4b2b0062b4133,reason=Completed count=1 msg=Job completed
0.1269,Event,ADDED,eval-sanitize-30-r0-017-6drwt.18d4b0b5705e69c6,reason=Scheduled count=None msg=Successfully assigned compute/eval-sanitize-30-r0-017-6drwt to kind-worker2
0.1271,Event,ADDED,eval-sanitize-30-r0-017-6drwt.18d4b0b58a54b6ac,"reason=Pulled count=1 msg=Container image ""busybox:musl"" already present on machine"
0.1275,Event,ADDED,eval-sanitize-30-r0-017-6drwt.18d4b0b58b9024a3,reason=Created count=1 msg=Created container: task
0.1277,Event,ADDED,eval-sanitize-30-r0-017-6drwt.18d4b0b58d8f615b,reason=Started count=1 msg=Started container task
0.128,Event,ADDED,eval-sanitize-30-r0-017-kht6x.18d4b2a3b23e5f58,"reason=FailedScheduling count=None msg=0/6 nodes are available: 1 c_wall violated: 1 conflicting context pair(s) with node memory, 5 node(s) had untolerated taint(s). no new claims to deallocate, preemption: 0/6 nodes are available: 1 No preemption victims found for incoming pod, 5 Preemption is not helpful for scheduling."
0.1283,Event,ADDED,eval-sanitize-30-r0-017-kht6x.18d4b2a3b2c0e288,"reason=FailedScheduling count=None msg=0/6 nodes are available: 1 c_wall violated: 1 conflicting context pair(s) with node memory, 5 node(s) had untolerated taint(s). no new claims to deallocate, preemption: 0/6 nodes are available: 1 No preemption victims found for incoming pod, 5 Preemption is not helpful for scheduling."
0.1285,Event,ADDED,eval-sanitize-30-r0-017-kht6x.18d4b2a55d0c43ad,"reason=FailedScheduling count=None msg=0/6 nodes are available: 1 c_wall violated: 2 conflicting context pair(s) with node memory, 5 node(s) had untolerated taint(s). no new claims to deallocate, preemption: 0/6 nodes are available: 1 No preemption victims found for incoming pod, 5 Preemption is not helpful for scheduling."
0.1287,Event,ADDED,eval-sanitize-30-r0-017-kht6x.18d4b2a9b8e63f6e,"reason=FailedScheduling count=None msg=0/6 nodes are available: 2 c_wall violated: 2 conflicting context pair(s) with node memory, 4 node(s) had untolerated taint(s). no new claims to deallocate, preemption: 0/6 nodes are available: 2 No preemption victims found for incoming pod, 4 Preemption is not helpful for scheduling."
0.129,Event,ADDED,eval-sanitize-30-r0-017-kht6x.18d4b2a9e16d8881,reason=Scheduled count=None msg=Successfully assigned compute/eval-sanitize-30-r0-017-kht6x to kind-worker5
0.1292,Event,ADDED,eval-sanitize-30-r0-017-kht6x.18d4b2aa01261753,"reason=Pulled count=1 msg=Container image ""busybox:musl"" already present on machine"
0.1294,Event,ADDED,eval-sanitize-30-r0-017-kht6x.18d4b2aa0470c3d0,reason=Created count=1 msg=Created container: task
0.1295,Event,ADDED,eval-sanitize-30-r0-017-kht6x.18d4b2aa0856dfcc,reason=Started count=1 msg=Started container task
0.1298,Event,ADDED,eval-sanitize-30-r0-017.18d4b0b56b067f16,reason=SuccessfulCreate count=1 msg=Created pod: eval-sanitize-30-r0-017-6drwt
0.13,Event,ADDED,eval-sanitize-30-r0-017.18d4b0bb124d39a6,reason=Completed count=1 msg=Job completed
0.1303,Event,ADDED,eval-sanitize-30-r0-017.18d4b2a3b1fbe46d,reason=SuccessfulCreate count=1 msg=Created pod: eval-sanitize-30-r0-017-kht6x
0.1305,Event,ADDED,eval-sanitize-30-r0-017.18d4b2b07963cd4b,reason=Completed count=1 msg=Job completed
0.1309,Event,ADDED,eval-sanitize-30-r0-018-gznrc.18d4b0b5ac379978,reason=Scheduled count=None msg=Successfully assigned compute/eval-sanitize-30-r0-018-gznrc to kind-worker3
0.131,Event,ADDED,eval-sanitize-30-r0-018-gznrc.18d4b0b5c5b897af,"reason=Pulled count=1 msg=Container image ""busybox:musl"" already present on machine"
0.1312,Event,ADDED,eval-sanitize-30-r0-018-gznrc.18d4b0b5c6d13fd8,reason=Created count=1 msg=Created container: task
0.1316,Event,ADDED,eval-sanitize-30-r0-018-gznrc.18d4b0b5c8ee213a,reason=Started count=1 msg=Started container task
0.1318,Event,ADDED,eval-sanitize-30-r0-018-snwnn.18d4b2a3ed431248,reason=Scheduled count=None msg=Successfully assigned compute/eval-sanitize-30-r0-018-snwnn to kind-worker4
0.132,Event,ADDED,eval-sanitize-30-r0-018-snwnn.18d4b2a40c7aec11,"reason=Pulled count=1 msg=Container image ""busybox:musl"" already present on machine"
0.1321,Event,ADDED,eval-sanitize-30-r0-018-snwnn.18d4b2a40f3d791c,reason=Created count=1 msg=Created container: task
0.1324,Event,ADDED,eval-sanitize-30-r0-018-snwnn.18d4b2a4186227e8,reason=Started count=1 msg=Started container task
0.1326,Event,ADDED,eval-sanitize-30-r0-018.18d4b0b5a6eceeef,reason=SuccessfulCreate count=1 msg=Created pod: eval-sanitize-30-r0-018-gznrc
0.1328,Event,ADDED,eval-sanitize-30-r0-018.18d4b0bb34c287ca,reason=Completed count=1 msg=Job completed
0.1329,Event,ADDED,eval-sanitize-30-r0-018.18d4b2a3ecb92dd6,reason=SuccessfulCreate count=1 msg=Created pod: eval-sanitize-30-r0-018-snwnn
0.1332,Event,ADDED,eval-sanitize-30-r0-018.18d4b2a94a80420b,reason=Completed count=1 msg=Job completed
0.1334,Event,ADDED,eval-sanitize-30-r0-019-2d9jl.18d4b2a42db8e2b6,reason=Scheduled count=None msg=Successfully assigned compute/eval-sanitize-30-r0-019-2d9jl to kind-worker4
0.1336,Event,ADDED,eval-sanitize-30-r0-019-2d9jl.18d4b2a4626be770,"reason=Pulled count=1 msg=Container image ""busybox:musl"" already present on machine"
0.1339,Event,ADDED,eval-sanitize-30-r0-019-2d9jl.18d4b2a464ff2e7e,reason=Created count=1 msg=Created container: task
0.134,Event,ADDED,eval-sanitize-30-r0-019-2d9jl.18d4b2a469dd3fd2,reason=Started count=1 msg=Started container task
0.1342,Event,ADDED,eval-sanitize-30-r0-019-jn7xd.18d4b0b5e823e962,reason=Scheduled count=None msg=Successfully assigned compute/eval-sanitize-30-r0-019-jn7xd to kind-worker5
0.1344,Event,ADDED,eval-sanitize-30-r0-019-jn7xd.18d4b0b601a4b8ff,"reason=Pulled count=1 msg=Container image ""busybox:musl"" already present on machine"
0.1347,Event,ADDED,eval-sanitize-30-r0-019-jn7xd.18d4b0b602ba4619,reason=Created count=1 msg=Created container: task
0.1348,Event,ADDED,eval-sanitize-30-r0-019-jn7xd.18d4b0b6077aa2fd,reason=Started count=1 msg=Started container task
0.135,Event,ADDED,eval-sanitize-30-r0-019.18d4b0b5e2540695,reason=SuccessfulCreate count=1 msg=Created pod: eval-sanitize-30-r0-019-jn7xd
0.1352,Event,ADDED,eval-sanitize-30-r0-019.18d4b0bb7a32a25c,reason=Completed count=1 msg=Job completed
0.1354,Event,ADDED,eval-sanitize-30-r0-019.18d4b2a42d381301,reason=SuccessfulCreate count=1 msg=Created pod: eval-sanitize-30-r0-019-2d9jl
0.1356,Event,ADDED,eval-sanitize-30-r0-019.18d4b2a9fd91b731,reason=Completed count=1 msg=Job completed
0.1357,Event,ADDED,eval-sanitize-30-r0-020-mgl5s.18d4b2a465d2ccbb,"reason=FailedScheduling count=None msg=0/6 nodes are available: 1 c_wall violated: 1 conflicting context pair(s) with node memory, 5 node(s) had untolerated taint(s). no new claims to deallocate, preemption: 0/6 nodes are available: 1 No preemption victims found for incoming pod, 5 Preemption is not helpful for scheduling."
0.1359,Event,ADDED,eval-sanitize-30-r0-020-mgl5s.18d4b2a46657ae88,"reason=FailedScheduling count=None msg=0/6 nodes are available: 1 c_wall violated: 1 conflicting context pair(s) with node memory, 5 node(s) had untolerated taint(s). no new claims to deallocate, preemption: 0/6 nodes are available: 1 No preemption victims found for incoming pod, 5 Preemption is not helpful for scheduling."
0.1361,Event,ADDED,eval-sanitize-30-r0-020-mgl5s.18d4b2a5590df6a7,"reason=FailedScheduling count=None msg=0/6 nodes are available: 1 c_wall violated: 2 conflicting context pair(s) with node memory, 5 node(s) had untolerated taint(s). no new claims to deallocate, preemption: 0/6 nodes are available: 1 No preemption victims found for incoming pod, 5 Preemption is not helpful for scheduling."
0.1363,Event,ADDED,eval-sanitize-30-r0-020-mgl5s.18d4b2a9bd86dd79,"reason=FailedScheduling count=None msg=0/6 nodes are available: 2 c_wall violated: 2 conflicting context pair(s) with node memory, 4 node(s) had untolerated taint(s). no new claims to deallocate, preemption: 0/6 nodes are available: 2 No preemption victims found for incoming pod, 4 Preemption is not helpful for scheduling."
0.1365,Event,ADDED,eval-sanitize-30-r0-020-mgl5s.18d4b2a9e51b5db4,reason=Scheduled count=None msg=Successfully assigned compute/eval-sanitize-30-r0-020-mgl5s to kind-worker3
0.1367,Event,ADDED,eval-sanitize-30-r0-020-mgl5s.18d4b2aa010ef8cf,"reason=Pulled count=1 msg=Container image ""busybox:musl"" already present on machine"
0.1369,Event,ADDED,eval-sanitize-30-r0-020-mgl5s.18d4b2aa02d95bb3,reason=Created count=1 msg=Created container: task
0.1371,Event,ADDED,eval-sanitize-30-r0-020-mgl5s.18d4b2aa07272e55,reason=Started count=1 msg=Started container task
0.1374,Event,ADDED,eval-sanitize-30-r0-020-swcjd.18d4b0b6235b4a8b,reason=Scheduled count=None msg=Successfully assigned compute/eval-sanitize-30-r0-020-swcjd to kind-worker4
0.1376,Event,ADDED,eval-sanitize-30-r0-020-swcjd.18d4b0b63caa1c4b,"reason=Pulled count=1 msg=Container image ""busybox:musl"" already present on machine"
0.1378,Event,ADDED,eval-sanitize-30-r0-020-swcjd.18d4b0b63dc81bbf,reason=Created count=1 msg=Created container: task
0.1381,Event,ADDED,eval-sanitize-30-r0-020-swcjd.18d4b0b63fea1918,reason=Started count=1 msg=Started container task
0.1382,Event,ADDED,eval-sanitize-30-r0-020.18d4b0b61e49d8ed,reason=SuccessfulCreate count=1 msg=Created pod: eval-sanitize-30-r0-020-swcjd
0.1384,Event,ADDED,eval-sanitize-30-r0-020.18d4b0bbd942b457,reason=Completed count=1 msg=Job completed
0.1386,Event,ADDED,eval-sanitize-30-r0-020.18d4b2a46585f6dd,reason=SuccessfulCreate count=1 msg=Created pod: eval-sanitize-30-r0-020-mgl5s
0.1388,Event,ADDED,eval-sanitize-30-r0-020.18d4b2b0760460b6,reason=Completed count=1 msg=Job completed
0.1389,Event,ADDED,eval-sanitize-30-r0-021-58s4b.18d4b2a49f89ed50,"reason=FailedScheduling count=None msg=0/6 nodes are available: 1 c_wall violated: 1 conflicting context pair(s) with node memory, 5 node(s) had untolerated taint(s). no new claims to deallocate, preemption: 0/6 nodes are available: 1 No preemption victims found for incoming pod, 5 Preemption is not helpful for scheduling."
0.1391,Event,ADDED,eval-sanitize-30-r0-021-58s4b.18d4b2a4a007a0ac,"reason=FailedScheduling count=None msg=0/6 nodes are available: 1 c_wall violated: 1 conflicting context pair(s) with node memory, 5 node(s) had untolerated taint(s). no new claims to deallocate, preemption: 0/6 nodes are available: 1 No preemption victims found for incoming pod, 5 Preemption is not helpful for scheduling."
0.1393,Event,ADDED,eval-sanitize-30-r0-021-58s4b.18d4b2a55934cc1d,"reason=FailedScheduling count=None msg=0/6 nodes are available: 1 c_wall violated: 2 conflicting context pair(s) with node memory, 5 node(s) had untolerated taint(s). no new claims to deallocate, preemption: 0/6 nodes are available: 1 No preemption victims found for incoming pod, 5 Preemption is not helpful for scheduling."
0.1395,Event,ADDED,eval-sanitize-30-r0-021-58s4b.18d4b2a9b73589f9,"reason=FailedScheduling count=None msg=0/6 nodes are available: 2 c_wall violated: 2 conflicting context pair(s) with node memory, 4 node(s) had untolerated taint(s). no new claims to deallocate, preemption: 0/6 nodes are available: 2 No preemption victims found for incoming pod, 4 Preemption is not helpful for scheduling."
0.1397,Event,ADDED,eval-sanitize-30-r0-021-58s4b.18d4b2a9df011cbb,reason=Scheduled count=None msg=Successfully assigned compute/eval-sanitize-30-r0-021-58s4b to kind-worker5
0.14,Event,ADDED,eval-sanitize-30-r0-021-58s4b.18d4b2aa014c64f1,"reason=Pulled count=1 msg=Container image ""busybox:musl"" already present on machine"
0.1401,Event,ADDED,eval-sanitize-30-r0-021-58s4b.18d4b2aa04b37e29,reason=Created count=1 msg=Created container: task
0.1403,Event,ADDED,eval-sanitize-30-r0-021-58s4b.18d4b2aa0857b428,reason=Started count=1 msg=Started container task
0.1405,Event,ADDED,eval-sanitize-30-r0-021-hxmz7.18d4b0b65f4ad69a,reason=Scheduled count=None msg=Successfully assigned compute/eval-sanitize-30-r0-021-hxmz7 to kind-worker
0.1408,Event,ADDED,eval-sanitize-30-r0-021-hxmz7.18d4b0b678d445f3,"reason=Pulled count=1 msg=Container image ""busybox:musl"" already present on machine"
0.141,Event,ADDED,eval-sanitize-30-r0-021-hxmz7.18d4b0b67a0d920e,reason=Created count=1 msg=Created container: task
0.1411,Event,ADDED,eval-sanitize-30-r0-021-hxmz7.18d4b0b67c880061,reason=Started count=1 msg=Started container task
0.1414,Event,ADDED,eval-sanitize-30-r0-021.18d4b0b65996789c,reason=SuccessfulCreate count=1 msg=Created pod: eval-sanitize-30-r0-021-hxmz7
0.1416,Event,ADDED,eval-sanitize-30-r0-021.18d4b0bc0408791b,reason=Completed count=1 msg=Job completed
0.1418,Event,ADDED,eval-sanitize-30-r0-021.18d4b2a49f4ee702,reason=SuccessfulCreate count=1 msg=Created pod: eval-sanitize-30-r0-021-58s4b
0.1419,Event,ADDED,eval-sanitize-30-r0-021.18d4b2b07f582a43,reason=Completed count=1 msg=Job completed
0.1422,Event,ADDED,eval-sanitize-30-r0-022-4dzlr.18d4b0b69ad3924c,reason=Scheduled count=None msg=Successfully assigned compute/eval-sanitize-30-r0-022-4dzlr to kind-worker2
0.1424,Event,ADDED,eval-sanitize-30-r0-022-4dzlr.18d4b0b6b4806be1,"reason=Pulled count=1 msg=Container image ""busybox:musl"" already present on machine"
0.1428,Event,ADDED,eval-sanitize-30-r0-022-4dzlr.18d4b0b6b5a91994,reason=Created count=1 msg=Created container: task
0.143,Event,ADDED,eval-sanitize-30-r0-022-4dzlr.18d4b0b6ba721028,reason=Started count=1 msg=Started container task
0.1433,Event,ADDED,eval-sanitize-30-r0-022-9pww5.18d4b2a4db03a7ef,reason=Scheduled count=None msg=Successfully assigned compute/eval-sanitize-30-r0-022-9pww5 to kind-worker4
0.1434,Event,ADDED,eval-sanitize-30-r0-022-9pww5.18d4b2a4f459fedf,"reason=Pulled count=1 msg=Container image ""busybox:musl"" already present on machine"
0.1436,Event,ADDED,eval-sanitize-30-r0-022-9pww5.18d4b2a4f5780bf8,reason=Created count=1 msg=Created container: task
0.1438,Event,ADDED,eval-sanitize-30-r0-022-9pww5.18d4b2a4fa29fc98,reason=Started count=1 msg=Started container task
0.144,Event,ADDED,eval-sanitize-30-r0-022.18d4b0b695196533,reason=SuccessfulCreate count=1 msg=Created pod: eval-sanitize-30-r0-022-4dzlr
0.1442,Event,ADDED,eval-sanitize-30-r0-022.18d4b0bc3afe2725,reason=Completed count=1 msg=Job completed
0.1444,Event,ADDED,eval-sanitize-30-r0-022.18d4b2a4da97401e,reason=SuccessfulCreate count=1 msg=Created pod: eval-sanitize-30-r0-022-9pww5
0.1445,Event,ADDED,eval-sanitize-30-r0-022.18d4b2aa39dadfb5,reason=Completed count=1 msg=Job completed
0.1447,Event,ADDED,eval-sanitize-30-r0-023-2lf42.18d4b0b6d66df5bb,reason=Scheduled count=None msg=Successfully assigned compute/eval-sanitize-30-r0-023-2lf42 to kind-worker4
0.1448,Event,ADDED,eval-sanitize-30-r0-023-2lf42.18d4b0b6f0a31b26,"reason=Pulled count=1 msg=Container image ""busybox:musl"" already present on machine"
0.145,Event,ADDED,eval-sanitize-30-r0-023-2lf42.18d4b0b6f1d355b7,reason=Created count=1 msg=Created container: task
0.1452,Event,ADDED,eval-sanitize-30-r0-023-2lf42.18d4b0b6f46303e1,reason=Started count=1 msg=Started container task
0.1453,Event,ADDED,eval-sanitize-30-r0-023-fz8c4.18d4b2a51b9e09dc,reason=Scheduled count=None msg=Successfully assigned compute/eval-sanitize-30-r0-023-fz8c4 to kind-worker4
0.1456,Event,ADDED,eval-sanitize-30-r0-023-fz8c4.18d4b2a538c0091a,"reason=Pulled count=1 msg=Container image ""busybox:musl"" already present on machine"
0.1459,Event,ADDED,eval-sanitize-30-r0-023-fz8c4.18d4b2a539dc2ba0,reason=Created count=1 msg=Created container: task
0.1461,Event,ADDED,eval-sanitize-30-r0-023-fz8c4.18d4b2a5419739a4,reason=Started count=1 msg=Started container task
0.1463,Event,ADDED,eval-sanitize-30-r0-023.18d4b0b6d0c554d5,reason=SuccessfulCreate count=1 msg=Created pod: eval-sanitize-30-r0-023-2lf42
0.1465,Event,ADDED,eval-sanitize-30-r0-023.18d4b0bc923d0fb9,reason=Completed count=1 msg=Job completed
0.1468,Event,ADDED,eval-sanitize-30-r0-023.18d4b2a5198103e2,reason=SuccessfulCreate count=1 msg=Created pod: eval-sanitize-30-r0-023-fz8c4
0.1469,Event,ADDED,eval-sanitize-30-r0-023.18d4b2aa76745608,reason=Completed count=1 msg=Job completed
0.1471,Event,ADDED,eval-sanitize-30-r0-024-2dw9t.18d4b0b70cafd45f,"reason=FailedScheduling count=None msg=0/6 nodes are available: 1 c_wall violated: 1 conflicting context pair(s) with node memory, 1 c_wall violated: 2 conflicting context pair(s) with node memory, 4 node(s) had untolerated taint(s). no new claims to deallocate, preemption: 0/6 nodes are available: 2 No preemption victims found for incoming pod, 4 Preemption is not helpful for scheduling."
0.1474,Event,ADDED,eval-sanitize-30-r0-024-2dw9t.18d4b0b70d955994,"reason=FailedScheduling count=None msg=0/6 nodes are available: 1 c_wall violated: 1 conflicting context pair(s) with node memory, 1 c_wall violated: 2 conflicting context pair(s) with node memory, 4 node(s) had untolerated taint(s). no new claims to deallocate, preemption: 0/6 nodes are available: 2 No preemption victims found for incoming pod, 4 Preemption is not helpful for scheduling."
0.1476,Event,ADDED,eval-sanitize-30-r0-024-2dw9t.18d4b0b715b4f2c3,"reason=FailedScheduling count=None msg=0/6 nodes are available: 6 node(s) had untolerated taint(s). no new claims to deallocate, preemption: 0/6 nodes are available: 6 Preemption is not helpful for scheduling."
0.1478,Event,ADDED,eval-sanitize-30-r0-024-2dw9t.18d4b0be3b4cf4f1,reason=Scheduled count=None msg=Successfully assigned compute/eval-sanitize-30-r0-024-2dw9t to kind-worker
0.1479,Event,ADDED,eval-sanitize-30-r0-024-2dw9t.18d4b0be57e47f56,"reason=Pulled count=1 msg=Container image ""busybox:musl"" already present on machine"
0.1482,Event,ADDED,eval-sanitize-30-r0-024-2dw9t.18d4b0be594a1ce8,reason=Created count=1 msg=Created container: task
0.1484,Event,ADDED,eval-sanitize-30-r0-024-2dw9t.18d4b0be5d68e773,reason=Started count=1 msg=Started container task
0.1486,Event,ADDED,eval-sanitize-30-r0-024-9gxqx.18d4b2a553aa2643,reason=Scheduled count=None msg=Successfully assigned compute/eval-sanitize-30-r0-024-9gxqx to kind-worker4
0.1489,Event,ADDED,eval-sanitize-30-r0-024-9gxqx.18d4b2a56e0d855f,"reason=Pulled count=1 msg=Container image ""busybox:musl"" already present on machine"
0.1491,Event,ADDED,eval-sanitize-30-r0-024-9gxqx.18d4b2a56f179c26,reason=Created count=1 msg=Created container: task
0.1493,Event,ADDED,eval-sanitize-30-r0-024-9gxqx.18d4b2a575933439,reason=Started count=1 msg=Started container task
0.1495,Event,ADDED,eval-sanitize-30-r0-024.18d4b0b70c30ab0f,reason=SuccessfulCreate count=1 msg=Created pod: eval-sanitize-30-r0-024-2dw9t
0.1498,Event,ADDED,eval-sanitize-30-r0-024.18d4b0c3bcdd5146,reason=Completed count=1 msg=Job completed
0.15,Event,ADDED,eval-sanitize-30-r0-024.18d4b2a55335f5e6,reason=SuccessfulCreate count=1 msg=Created pod: eval-sanitize-30-r0-024-9gxqx
0.1502,Event,ADDED,eval-sanitize-30-r0-024.18d4b2aaeea5fdf6,reason=Completed count=1 msg=Job completed
0.1504,Event,ADDED,eval-sanitize-30-r0-025-86z2w.18d4b2a591be36f8,"reason=FailedScheduling count=None msg=0/6 nodes are available: 1 c_wall violated: 2 conflicting context pair(s) with node memory, 5 node(s) had untolerated taint(s). no new claims to deallocate, preemption: 0/6 nodes are available: 1 No preemption victims found for incoming pod, 5 Preemption is not helpful for scheduling."
0.1507,Event,ADDED,eval-sanitize-30-r0-025-86z2w.18d4b2a5937eaa3f,"reason=FailedScheduling count=None msg=0/6 nodes are available: 1 c_wall violated: 2 conflicting context pair(s) with node memory, 5 node(s) had untolerated taint(s). no new claims to deallocate, preemption: 0/6 nodes are available: 1 No preemption victims found for incoming pod, 5 Preemption is not helpful for scheduling."
0.1509,Event,ADDED,eval-sanitize-30-r0-025-86z2w.18d4b2a97577f4c2,reason=Scheduled count=None msg=Successfully assigned compute/eval-sanitize-30-r0-025-86z2w to kind-worker
0.1511,Event,ADDED,eval-sanitize-30-r0-025-86z2w.18d4b2a98d5e59fa,"reason=Pulled count=1 msg=Container image ""busybox:musl"" already present on machine"
0.1514,Event,ADDED,eval-sanitize-30-r0-025-86z2w.18d4b2a98eebedf4,reason=Created count=1 msg=Created container: task
0.1516,Event,ADDED,eval-sanitize-30-r0-025-86z2w.18d4b2a996872db0,reason=Started count=1 msg=Started container task
0.1517,Event,ADDED,eval-sanitize-30-r0-025-rtnnp.18d4b0b748bc5997,"reason=FailedScheduling count=None msg=0/6 nodes are available: 6 node(s) had untolerated taint(s). no new claims to deallocate, preemption: 0/6 nodes are available: 6 Preemption is not helpful for scheduling."
0.152,Event,ADDED,eval-sanitize-30-r0-025-rtnnp.18d4b0be3bd9c623,reason=Scheduled count=None msg=Successfully assigned compute/eval-sanitize-30-r0-025-rtnnp to kind-worker
0.1522,Event,ADDED,eval-sanitize-30-r0-025-rtnnp.18d4b0be5978189f,"reason=Pulled count=1 msg=Container image ""busybox:musl"" already present on machine"
0.1524,Event,ADDED,eval-sanitize-30-r0-025-rtnnp.18d4b0be5bd14c87,reason=Created count=1 msg=Created container: task
0.1526,Event,ADDED,eval-sanitize-30-r0-025-rtnnp.18d4b0be5ef69cdf,reason=Started count=1 msg=Started container task
0.1528,Event,ADDED,eval-sanitize-30-r0-025.18d4b0b748b2b11c,reason=SuccessfulCreate count=1 msg=Created pod: eval-sanitize-30-r0-025-rtnnp
0.153,Event,ADDED,eval-sanitize-30-r0-025.18d4b0c56b20b634,reason=Completed count=1 msg=Job completed
0.1531,Event,ADDED,eval-sanitize-30-r0-025.18d4b2a58e5b7bd5,reason=SuccessfulCreate count=1 msg=Created pod: eval-sanitize-30-r0-025-86z2w
0.1533,Event,ADDED,eval-sanitize-30-r0-025.18d4b2afe14c570d,reason=Completed count=1 msg=Job completed
0.1536,Event,ADDED,eval-sanitize-30-r0-026-5q7gp.18d4b0b783d6795c,"reason=FailedScheduling count=None msg=0/6 nodes are available: 6 node(s) had untolerated taint(s). no new claims to deallocate, preemption: 0/6 nodes are available: 6 Preemption is not helpful for scheduling."
0.1539,Event,ADDED,eval-sanitize-30-r0-026-5q7gp.18d4b0be3c3e4285,reason=Scheduled count=None msg=Successfully assigned compute/eval-sanitize-30-r0-026-5q7gp to kind-worker
0.1542,Event,ADDED,eval-sanitize-30-r0-026-5q7gp.18d4b0be59941a16,"reason=Pulled count=1 msg=Container image ""busybox:musl"" already present on machine"
0.1544,Event,ADDED,eval-sanitize-30-r0-026-5q7gp.18d4b0be5ba3b745,reason=Created count=1 msg=Created container: task
0.1546,Event,ADDED,eval-sanitize-30-r0-026-5q7gp.18d4b0be5e85cf21,reason=Started count=1 msg=Started container task
0.1548,Event,ADDED,eval-sanitize-30-r0-026-t5q57.18d4b2a5c97ed9c5,"reason=FailedScheduling count=None msg=0/6 nodes are available: 1 c_wall violated: 2 conflicting context pair(s) with node memory, 5 node(s) had untolerated taint(s). no new claims to deallocate, preemption: 0/6 nodes are available: 1 No preemption victims found for incoming pod, 5 Preemption is not helpful for scheduling."
0.155,Event,ADDED,eval-sanitize-30-r0-026-t5q57.18d4b2a5cded50b7,"reason=FailedScheduling count=None msg=0/6 nodes are available: 1 c_wall violated: 2 conflicting context pair(s) with node memory, 5 node(s) had untolerated taint(s). no new claims to deallocate, preemption: 0/6 nodes are available: 1 No preemption victims found for incoming pod, 5 Preemption is not helpful for scheduling."
0.1551,Event,ADDED,eval-sanitize-30-r0-026-t5q57.18d4b2a97ae352cb,reason=Scheduled count=None msg=Successfully assigned compute/eval-sanitize-30-r0-026-t5q57 to kind-worker
0.1554,Event,ADDED,eval-sanitize-30-r0-026-t5q57.18d4b2a98e55f93b,"reason=Pulled count=1 msg=Container image ""busybox:musl"" already present on machine"
0.1556,Event,ADDED,eval-sanitize-30-r0-026-t5q57.18d4b2a98fac169f,reason=Created count=1 msg=Created container: task
0.1558,Event,ADDED,eval-sanitize-30-r0-026-t5q57.18d4b2a99685e751,reason=Started count=1 msg=Started container task
0.156,Event,ADDED,eval-sanitize-30-r0-026.18d4b0b783cca5b0,reason=SuccessfulCreate count=1 msg=Created pod: eval-sanitize-30-r0-026-5q7gp
0.1563,Event,ADDED,eval-sanitize-30-r0-026.18d4b0c3bdadfda1,reason=Completed count=1 msg=Job completed
0.1564,Event,ADDED,eval-sanitize-30-r0-026.18d4b2a5c939513c,reason=SuccessfulCreate count=1 msg=Created pod: eval-sanitize-30-r0-026-t5q57
0.1571,Event,ADDED,eval-sanitize-30-r0-026.18d4b2afe005ecb2,reason=Completed count=1 msg=Job completed
0.1572,Event,ADDED,eval-sanitize-30-r0-027-9s9sc.18d4b2a608ac576c,"reason=FailedScheduling count=None msg=0/6 nodes are available: 1 c_wall violated: 3 conflicting context pair(s) with node memory, 5 node(s) had untolerated taint(s). no new claims to deallocate, preemption: 0/6 nodes are available: 1 No preemption victims found for incoming pod, 5 Preemption is not helpful for scheduling."
0.1574,Event,ADDED,eval-sanitize-30-r0-027-9s9sc.18d4b2a6095723b7,"reason=FailedScheduling count=None msg=0/6 nodes are available: 1 c_wall violated: 3 conflicting context pair(s) with node memory, 5 node(s) had untolerated taint(s). no new claims to deallocate, preemption: 0/6 nodes are available: 1 No preemption victims found for incoming pod, 5 Preemption is not helpful for scheduling."
0.1577,Event,ADDED,eval-sanitize-30-r0-027-9s9sc.18d4b2a97d8edee1,reason=Scheduled count=None msg=Successfully assigned compute/eval-sanitize-30-r0-027-9s9sc to kind-worker2
0.1579,Event,ADDED,eval-sanitize-30-r0-027-9s9sc.18d4b2a9a079b787,"reason=Pulled count=1 msg=Container image ""busybox:musl"" already present on machine"
0.1581,Event,ADDED,eval-sanitize-30-r0-027-9s9sc.18d4b2a9a28641a7,reason=Created count=1 msg=Created container: task
0.1582,Event,ADDED,eval-sanitize-30-r0-027-9s9sc.18d4b2a9a78009ff,reason=Started count=1 msg=Started container task
0.1586,Event,ADDED,eval-sanitize-30-r0-027-pr5wx.18d4b0b7bf274344,"reason=FailedScheduling count=None msg=0/6 nodes are available: 6 node(s) had untolerated taint(s). no new claims to deallocate, preemption: 0/6 nodes are available: 6 Preemption is not helpful for scheduling."
0.1588,Event,ADDED,eval-sanitize-30-r0-027-pr5wx.18d4b0be3bf95059,"reason=FailedScheduling count=None msg=0/6 nodes are available: 1 c_wall violated: 1 conflicting context pair(s) with node memory, 5 node(s) had untolerated taint(s). no new claims to deallocate, preemption: 0/6 nodes are available: 1 No preemption victims found for incoming pod, 5 Preemption is not helpful for scheduling."
0.1589,Event,ADDED,eval-sanitize-30-r0-027-pr5wx.18d4b0be6419f7c1,reason=Scheduled count=None msg=Successfully assigned compute/eval-sanitize-30-r0-027-pr5wx to kind-worker2
0.1592,Event,ADDED,eval-sanitize-30-r0-027-pr5wx.18d4b0be841b353a,"reason=Pulled count=1 msg=Container image ""busybox:musl"" already present on machine"
0.1594,Event,ADDED,eval-sanitize-30-r0-027-pr5wx.18d4b0be86cd72e8,reason=Created count=1 msg=Created container: task
0.1596,Event,ADDED,eval-sanitize-30-r0-027-pr5wx.18d4b0be8a63b7c0,reason=Started count=1 msg=Started container task
0.1597,Event,ADDED,eval-sanitize-30-r0-027.18d4b0b7bf1baf4d,reason=SuccessfulCreate count=1 msg=Created pod: eval-sanitize-30-r0-027-pr5wx
0.1601,Event,ADDED,eval-sanitize-30-r0-027.18d4b0c63a19d998,reason=Completed count=1 msg=Job completed
0.1602,Event,ADDED,eval-sanitize-30-r0-027.18d4b2a6051a8b98,reason=SuccessfulCreate count=1 msg=Created pod: eval-sanitize-30-r0-027-9s9sc
0.1605,Event,ADDED,eval-sanitize-30-r0-027.18d4b2affb00e398,reason=Completed count=1 msg=Job completed
0.1607,Event,ADDED,eval-sanitize-30-r0-028-2jrv8.18d4b2a641b91f30,reason=Scheduled count=None msg=Successfully assigned compute/eval-sanitize-30-r0-028-2jrv8 to kind-worker4
0.1609,Event,ADDED,eval-sanitize-30-r0-028-2jrv8.18d4b2a65bd59ffc,"reason=Pulled count=1 msg=Container image ""busybox:musl"" already present on machine"
0.1611,Event,ADDED,eval-sanitize-30-r0-028-2jrv8.18d4b2a65cf16acb,reason=Created count=1 msg=Created container: task
0.1613,Event,ADDED,eval-sanitize-30-r0-028-2jrv8.18d4b2a6603040d1,reason=Started count=1 msg=Started container task
0.1616,Event,ADDED,eval-sanitize-30-r0-028-9dt62.18d4b0b7facaaea0,"reason=FailedScheduling count=None msg=0/6 nodes are available: 6 node(s) had untolerated taint(s). no new claims to deallocate, preemption: 0/6 nodes are available: 6 Preemption is not helpful for scheduling."
0.1617,Event,ADDED,eval-sanitize-30-r0-028-9dt62.18d4b0be3cfa03c9,reason=Scheduled count=None msg=Successfully assigned compute/eval-sanitize-30-r0-028-9dt62 to kind-worker
0.1619,Event,ADDED,eval-sanitize-30-r0-028-9dt62.18d4b0be595a29ac,"reason=Pulled count=1 msg=Container image ""busybox:musl"" already present on machine"
0.1621,Event,ADDED,eval-sanitize-30-r0-028-9dt62.18d4b0be5b247a54,reason=Created count=1 msg=Created container: task
0.1623,Event,ADDED,eval-sanitize-30-r0-028-9dt62.18d4b0be5dc29914,reason=Started count=1 msg=Started container task
0.1625,Event,ADDED,eval-sanitize-30-r0-028.18d4b0b7fabd71a3,reason=SuccessfulCreate count=1 msg=Created pod: eval-sanitize-30-r0-028-9dt62
0.1626,Event,ADDED,eval-sanitize-30-r0-028.18d4b0c3c9ccace4,reason=Completed count=1 msg=Job completed
0.1628,Event,ADDED,eval-sanitize-30-r0-028.18d4b2a6410ca970,reason=SuccessfulCreate count=1 msg=Created pod: eval-sanitize-30-r0-028-2jrv8
0.163,Event,ADDED,eval-sanitize-30-r0-028.18d4b2abe3d79e12,reason=Completed count=1 msg=Job completed
0.1632,Event,ADDED,eval-sanitize-30-r0-029-9qlmn.18d4b0b837a68f82,"reason=FailedScheduling count=None msg=0/6 nodes are available: 6 node(s) had untolerated taint(s). no new claims to deallocate, preemption: 0/6 nodes are available: 6 Preemption is not helpful for scheduling."
0.1634,Event,ADDED,eval-sanitize-30-r0-029-9qlmn.18d4b0be3cd4ba34,"reason=FailedScheduling count=None msg=0/6 nodes are available: 1 c_wall violated: 1 conflicting context pair(s) with node memory, 5 node(s) had untolerated taint(s). no new claims to deallocate, preemption: 0/6 nodes are available: 1 No preemption victims found for incoming pod, 5 Preemption is not helpful for scheduling."
0.1641,Event,ADDED,eval-sanitize-30-r0-029-9qlmn.18d4b0be61e3661d,"reason=FailedScheduling count=None msg=0/6 nodes are available: 1 c_wall violated: 1 conflicting context pair(s) with node memory, 1 c_wall violated: 2 conflicting context pair(s) with node memory, 4 node(s) had untolerated taint(s). no new claims to deallocate, preemption: 0/6 nodes are available: 2 No preemption victims found for incoming pod, 4 Preemption is not helpful for scheduling."
0.1643,Event,ADDED,eval-sanitize-30-r0-029-9qlmn.18d4b0be9364bd09,"reason=FailedScheduling count=None msg=0/6 nodes are available: 1 c_wall violated: 1 conflicting context pair(s) with node memory, 1 c_wall violated: 2 conflicting context pair(s) with node memory, 4 node(s) had untolerated taint(s). no new claims to deallocate, preemption: 0/6 nodes are available: 2 No preemption victims found for incoming pod, 4 Preemption is not helpful for scheduling."
0.1644,Event,ADDED,eval-sanitize-30-r0-029-9qlmn.18d4b0bef6a428a5,reason=Scheduled count=None msg=Successfully assigned compute/eval-sanitize-30-r0-029-9qlmn to kind-worker4
0.1647,Event,ADDED,eval-sanitize-30-r0-029-9qlmn.18d4b0bf128b1714,"reason=Pulled count=1 msg=Container image ""busybox:musl"" already present on machine"
0.1648,Event,ADDED,eval-sanitize-30-r0-029-9qlmn.18d4b0bf13b01519,reason=Created count=1 msg=Created container: task
0.165,Event,ADDED,eval-sanitize-30-r0-029-9qlmn.18d4b0bf1c4af981,reason=Started count=1 msg=Started container task
0.1652,Event,ADDED,eval-sanitize-30-r0-029-9rcxg.18d4b2a67c055ee0,"reason=FailedScheduling count=None msg=0/6 nodes are available: 1 c_wall violated: 4 conflicting context pair(s) with node memory, 5 node(s) had untolerated taint(s). no new claims to deallocate, preemption: 0/6 nodes are available: 1 No preemption victims found for incoming pod, 5 Preemption is not helpful for scheduling."
0.1654,Event,ADDED,eval-sanitize-30-r0-029-9rcxg.18d4b2a68179a73d,"reason=FailedScheduling count=None msg=0/6 nodes are available: 1 c_wall violated: 4 conflicting context pair(s) with node memory, 5 node(s) had untolerated taint(s). no new claims to deallocate, preemption: 0/6 nodes are available: 1 No preemption victims found for incoming pod, 5 Preemption is not helpful for scheduling."
0.1656,Event,ADDED,eval-sanitize-30-r0-029-9rcxg.18d4b2a9b8950a58,"reason=FailedScheduling count=None msg=0/6 nodes are available: 1 c_wall violated: 1 conflicting context pair(s) with node memory, 1 c_wall violated: 2 conflicting context pair(s) with node memory, 4 node(s) had untolerated taint(s). no new claims to deallocate, preemption: 0/6 nodes are available: 2 No preemption victims found for incoming pod, 4 Preemption is not helpful for scheduling."
0.1657,Event,ADDED,eval-sanitize-30-r0-029-9rcxg.18d4b2a9eaafdee8,"reason=FailedScheduling count=None msg=0/6 nodes are available: 1 c_wall violated: 2 conflicting context pair(s) with node memory, 1 c_wall violated: 3 conflicting context pair(s) with node memory, 2 c_wall violated: 1 conflicting context pair(s) with node memory, 2 node(s) had untolerated taint(s). no new claims to deallocate, preemption: 0/6 nodes are available: 2 Preemption is not helpful for scheduling, 4 No preemption victims found for incoming pod."
0.1659,Event,ADDED,eval-sanitize-30-r0-029-9rcxg.18d4b2a9f32632eb,"reason=FailedScheduling count=None msg=0/6 nodes are available: 1 c_wall violated: 2 conflicting context pair(s) with node memory, 1 c_wall violated: 3 conflicting context pair(s) with node memory, 2 c_wall violated: 1 conflicting context pair(s) with node memory, 2 node(s) had untolerated taint(s). no new claims to deallocate, preemption: 0/6 nodes are available: 2 Preemption is not helpful for scheduling, 4 No preemption victims found for incoming pod."
0.1661,Event,ADDED,eval-sanitize-30-r0-029-9rcxg.18d4b2aa87d90866,"reason=FailedScheduling count=None msg=0/6 nodes are available: 1 c_wall violated: 1 conflicting context pair(s) with node memory, 1 c_wall violated: 3 conflicting context pair(s) with node memory, 2 c_wall violated: 2 conflicting context pair(s) with node memory, 2 node(s) had untolerated taint(s). no new claims to deallocate, preemption: 0/6 nodes are available: 2 Preemption is not helpful for scheduling, 4 No preemption victims found for incoming pod."
0.1663,Event,ADDED,eval-sanitize-30-r0-029-9rcxg.18d4b2ac415b73b1,"reason=FailedScheduling count=None msg=0/6 nodes are available: 1 c_wall violated: 1 conflicting context pair(s) with node memory, 1 c_wall violated: 2 conflicting context pair(s) with node memory, 2 c_wall violated: 3 conflicting context pair(s) with node memory, 2 node(s) had untolerated taint(s). no new claims to deallocate, preemption: 0/6 nodes are available: 2 Preemption is not helpful for scheduling, 4 No preemption victims found for incoming pod."
0.1665,Event,ADDED,eval-sanitize-30-r0-029-9rcxg.18d4b2af71c6d14d,"reason=FailedScheduling count=None msg=0/6 nodes are available: 2 c_wall violated: 2 conflicting context pair(s) with node memory, 2 c_wall violated: 3 conflicting context pair(s) with node memory, 2 node(s) had untolerated taint(s). no new claims to deallocate, preemption: 0/6 nodes are available: 2 Preemption is not helpful for scheduling, 4 No preemption victims found for incoming pod."
0.1666,Event,ADDED,eval-sanitize-30-r0-029-9rcxg.18d4b2b0bf6c051a,"reason=FailedScheduling count=None msg=0/6 nodes are available: 1 c_wall violated: 2 conflicting context pair(s) with node memory, 2 c_wall violated: 3 conflicting context pair(s) with node memory, 3 node(s) had untolerated taint(s). no new claims to deallocate, preemption: 0/6 nodes are available: 3 No preemption victims found for incoming pod, 3 Preemption is not helpful for scheduling."
0.1668,Event,ADDED,eval-sanitize-30-r0-029-9rcxg.18d4b2b0dec8c10f,"reason=FailedScheduling count=None msg=0/6 nodes are available: 1 c_wall violated: 2 conflicting context pair(s) with node memory, 5 node(s) had untolerated taint(s). no new claims to deallocate, preemption: 0/6 nodes are available: 1 No preemption victims found for incoming pod, 5 Preemption is not helpful for scheduling."
0.167,Event,ADDED,eval-sanitize-30-r0-029-9rcxg.18d4b2b0ea4381cd,"reason=FailedScheduling count=None msg=0/6 nodes are available: 1 c_wall violated: 2 conflicting context pair(s) with node memory, 5 node(s) had untolerated taint(s). no new claims to deallocate, preemption: 0/6 nodes are available: 1 No preemption victims found for incoming pod, 5 Preemption is not helpful for scheduling."
0.1672,Event,ADDED,eval-sanitize-30-r0-029-9rcxg.18d4b2b361a42885,"reason=FailedScheduling count=None msg=0/6 nodes are available: 1 c_wall violated: 3 conflicting context pair(s) with node memory, 5 node(s) had untolerated taint(s). no new claims to deallocate, preemption: 0/6 nodes are available: 1 No preemption victims found for incoming pod, 5 Preemption is not helpful for scheduling."
0.1673,Event,ADDED,eval-sanitize-30-r0-029-9rcxg.18d4b2b7d99ac768,"reason=FailedScheduling count=None msg=0/6 nodes are available: 1 c_wall violated: 1 conflicting context pair(s) with node memory, 2 c_wall violated: 2 conflicting context pair(s) with node memory, 3 node(s) had untolerated taint(s). no new claims to deallocate, preemption: 0/6 nodes are available: 3 No preemption victims found for incoming pod, 3 Preemption is not helpful for scheduling."
0.1675,Event,ADDED,eval-sanitize-30-r0-029-9rcxg.18d4b2b80f855f84,reason=Scheduled count=None msg=Successfully assigned compute/eval-sanitize-30-r0-029-9rcxg to kind-worker3
0.1677,Event,ADDED,eval-sanitize-30-r0-029-9rcxg.18d4b2b830badd6a,"reason=Pulled count=1 msg=Container image ""busybox:musl"" already present on machine"
0.1678,Event,ADDED,eval-sanitize-30-r0-029-9rcxg.18d4b2b832a61287,reason=Created count=1 msg=Created container: task
0.168,Event,ADDED,eval-sanitize-30-r0-029-9rcxg.18d4b2b84657d478,reason=Started count=1 msg=Started container task
0.1682,Event,ADDED,eval-sanitize-30-r0-029.18d4b0b8379a7731,reason=SuccessfulCreate count=1 msg=Created pod: eval-sanitize-30-r0-029-9qlmn
0.1683,Event,ADDED,eval-sanitize-30-r0-029.18d4b0c658be93f4,reason=Completed count=1 msg=Job completed
0.1685,Event,ADDED,eval-sanitize-30-r0-029.18d4b2a67bc8375f,reason=SuccessfulCreate count=1 msg=Created pod: eval-sanitize-30-r0-029-9rcxg
0.1687,Event,ADDED,eval-sanitize-30-r0-029.18d4b2bf7b9b4479,reason=Completed count=1 msg=Job completed
0.1688,Event,ADDED,eval-sanitize-30-r0-030-gkklr.18d4b0b8720b9ca4,"reason=FailedScheduling count=None msg=0/6 nodes are available: 6 node(s) had untolerated taint(s). no new claims to deallocate, preemption: 0/6 nodes are available: 6 Preemption is not helpful for scheduling."
0.169,Event,ADDED,eval-sanitize-30-r0-030-gkklr.18d4b0be3f5eb535,"reason=FailedScheduling count=None msg=0/6 nodes are available: 1 c_wall violated: 1 conflicting context pair(s) with node memory, 5 node(s) had untolerated taint(s). no new claims to deallocate, preemption: 0/6 nodes are available: 1 No preemption victims found for incoming pod, 5 Preemption is not helpful for scheduling."
0.1691,Event,ADDED,eval-sanitize-30-r0-030-gkklr.18d4b0be6708f9c2,"reason=FailedScheduling count=None msg=0/6 nodes are available: 1 c_wall violated: 1 conflicting context pair(s) with node memory, 1 c_wall violated: 2 conflicting context pair(s) with node memory, 4 node(s) had untolerated taint(s). no new claims to deallocate, preemption: 0/6 nodes are available: 2 No preemption victims found for incoming pod, 4 Preemption is not helpful for scheduling."
0.1693,Event,ADDED,eval-sanitize-30-r0-030-gkklr.18d4b0be96c46182,"reason=FailedScheduling count=None msg=0/6 nodes are available: 1 c_wall violated: 1 conflicting context pair(s) with node memory, 1 c_wall violated: 2 conflicting context pair(s) with node memory, 4 node(s) had untolerated taint(s). no new claims to deallocate, preemption: 0/6 nodes are available: 2 No preemption victims found for incoming pod, 4 Preemption is not helpful for scheduling."
0.1694,Event,ADDED,eval-sanitize-30-r0-030-gkklr.18d4b0bf020cc186,reason=Scheduled count=None msg=Successfully assigned compute/eval-sanitize-30-r0-030-gkklr to kind-worker4
0.1696,Event,ADDED,eval-sanitize-30-r0-030-gkklr.18d4b0bf2266ea07,"reason=Pulled count=1 msg=Container image ""busybox:musl"" already present on machine"
0.1698,Event,ADDED,eval-sanitize-30-r0-030-gkklr.18d4b0bf23cddd59,reason=Created count=1 msg=Created container: task
0.1699,Event,ADDED,eval-sanitize-30-r0-030-gkklr.18d4b0bf2a30e926,reason=Started count=1 msg=Started container task
0.1701,Event,ADDED,eval-sanitize-30-r0-030-zgdx2.18d4b2a6bcb3a253,reason=Scheduled count=None msg=Successfully assigned compute/eval-sanitize-30-r0-030-zgdx2 to kind-worker4
0.1703,Event,ADDED,eval-sanitize-30-r0-030-zgdx2.18d4b2a6d5d0e182,"reason=Pulled count=1 msg=Container image ""busybox:musl"" already present on machine"
0.1704,Event,ADDED,eval-sanitize-30-r0-030-zgdx2.18d4b2a6d6f105b3,reason=Created count=1 msg=Created container: task
0.1706,Event,ADDED,eval-sanitize-30-r0-030-zgdx2.18d4b2a6dd33c51a,reason=Started count=1 msg=Started container task
0.1709,Event,ADDED,eval-sanitize-30-r0-030.18d4b0b871fd3c48,reason=SuccessfulCreate count=1 msg=Created pod: eval-sanitize-30-r0-030-gkklr
0.1711,Event,ADDED,eval-sanitize-30-r0-030.18d4b0c6bdf6c83d,reason=Completed count=1 msg=Job completed
0.1713,Event,ADDED,eval-sanitize-30-r0-030.18d4b2a6ba1dd7a9,reason=SuccessfulCreate count=1 msg=Created pod: eval-sanitize-30-r0-030-zgdx2
0.1715,Event,ADDED,eval-sanitize-30-r0-030.18d4b2ac578baa4c,reason=Completed count=1 msg=Job completed
0.1717,Event,ADDED,eval-sanitize-30-r0-031-sh7gw.18d4b2a6f7f8f51d,"reason=FailedScheduling count=None msg=0/6 nodes are available: 1 c_wall violated: 1 conflicting context pair(s) with node memory, 5 node(s) had untolerated taint(s). no new claims to deallocate, preemption: 0/6 nodes are available: 1 No preemption victims found for incoming pod, 5 Preemption is not helpful for scheduling."
0.1719,Event,ADDED,eval-sanitize-30-r0-031-sh7gw.18d4b2a6fd08b2cd,"reason=FailedScheduling count=None msg=0/6 nodes are available: 1 c_wall violated: 1 conflicting context pair(s) with node memory, 5 node(s) had untolerated taint(s). no new claims to deallocate, preemption: 0/6 nodes are available: 1 No preemption victims found for incoming pod, 5 Preemption is not helpful for scheduling."
0.172,Event,ADDED,eval-sanitize-30-r0-031-sh7gw.18d4b2a9b4ed0027,"reason=FailedScheduling count=None msg=0/6 nodes are available: 2 c_wall violated: 1 conflicting context pair(s) with node memory, 4 node(s) had untolerated taint(s). no new claims to deallocate, preemption: 0/6 nodes are available: 2 No preemption victims found for incoming pod, 4 Preemption is not helpful for scheduling."
0.1722,Event,ADDED,eval-sanitize-30-r0-031-sh7gw.18d4b2a9d07349bb,reason=Scheduled count=None msg=Successfully assigned compute/eval-sanitize-30-r0-031-sh7gw to kind-worker5
0.1723,Event,ADDED,eval-sanitize-30-r0-031-sh7gw.18d4b2a9ec9a0e52,"reason=Pulled count=1 msg=Container image ""busybox:musl"" already present on machine"
0.1725,Event,ADDED,eval-sanitize-30-r0-031-sh7gw.18d4b2a9edc43f82,reason=Created count=1 msg=Created container: task
0.1727,Event,ADDED,eval-sanitize-30-r0-031-sh7gw.18d4b2a9f6899560,reason=Started count=1 msg=Started container task
0.1728,Event,ADDED,eval-sanitize-30-r0-031-sn7ww.18d4b0b8adddfe45,"reason=FailedScheduling count=None msg=0/6 nodes are available: 6 node(s) had untolerated taint(s). no new claims to deallocate, preemption: 0/6 nodes are available: 6 Preemption is not helpful for scheduling."
0.173,Event,ADDED,eval-sanitize-30-r0-031-sn7ww.18d4b0be3fe61128,"reason=FailedScheduling count=None msg=0/6 nodes are available: 1 c_wall violated: 1 conflicting context pair(s) with node memory, 5 node(s) had untolerated taint(s). no new claims to deallocate, preemption: 0/6 nodes are available: 1 No preemption victims found for incoming pod, 5 Preemption is not helpful for scheduling."
0.1731,Event,ADDED,eval-sanitize-30-r0-031-sn7ww.18d4b0be67f6b9fa,reason=Scheduled count=None msg=Successfully assigned compute/eval-sanitize-30-r0-031-sn7ww to kind-worker2
0.1733,Event,ADDED,eval-sanitize-30-r0-031-sn7ww.18d4b0be84335146,"reason=Pulled count=1 msg=Container image ""busybox:musl"" already present on machine"
0.1735,Event,ADDED,eval-sanitize-30-r0-031-sn7ww.18d4b0be87247fa0,reason=Created count=1 msg=Created container: task
0.1736,Event,ADDED,eval-sanitize-30-r0-031-sn7ww.18d4b0be8a645083,reason=Started count=1 msg=Started container task
0.1738,Event,ADDED,eval-sanitize-30-r0-031.18d4b0b8add56dcf,reason=SuccessfulCreate count=1 msg=Created pod: eval-sanitize-30-r0-031-sn7ww
0.174,Event,ADDED,eval-sanitize-30-r0-031.18d4b0c618171215,reason=Completed count=1 msg=Job completed
0.1741,Event,ADDED,eval-sanitize-30-r0-031.18d4b2a6f72f9620,reason=SuccessfulCreate count=1 msg=Created pod: eval-sanitize-30-r0-031-sh7gw
0.1743,Event,ADDED,eval-sanitize-30-r0-031.18d4b2af1b73d037,reason=Completed count=1 msg=Job completed
0.1745,Event,ADDED,eval-sanitize-30-r0-032-sm4cx.18d4b2a7335a9127,reason=Scheduled count=None msg=Successfully assigned compute/eval-sanitize-30-r0-032-sm4cx to kind-worker4
0.1746,Event,ADDED,eval-sanitize-30-r0-032-sm4cx.18d4b2a74d6e4820,"reason=Pulled count=1 msg=Container image ""busybox:musl"" already present on machine"
0.1748,Event,ADDED,eval-sanitize-30-r0-032-sm4cx.18d4b2a74e906d67,reason=Created count=1 msg=Created container: task
0.175,Event,ADDED,eval-sanitize-30-r0-032-sm4cx.18d4b2a755113ac4,reason=Started count=1 msg=Started container task
0.1751,Event,ADDED,eval-sanitize-30-r0-032-zqt5z.18d4b0b8ea2689a6,"reason=FailedScheduling count=None msg=0/6 nodes are available: 6 node(s) had untolerated taint(s). no new claims to deallocate, preemption: 0/6 nodes are available: 6 Preemption is not helpful for scheduling."
0.1753,Event,ADDED,eval-sanitize-30-r0-032-zqt5z.18d4b0be40650fc7,"reason=FailedScheduling count=None msg=0/6 nodes are available: 1 c_wall violated: 1 conflicting context pair(s) with node memory, 5 node(s) had untolerated taint(s). no new claims to deallocate, preemption: 0/6 nodes are available: 1 No preemption victims found for incoming pod, 5 Preemption is not helpful for scheduling."
0.1755,Event,ADDED,eval-sanitize-30-r0-032-zqt5z.18d4b0be67fd5620,"reason=FailedScheduling count=None msg=0/6 nodes are available: 1 c_wall violated: 1 conflicting context pair(s) with node memory, 1 c_wall violated: 2 conflicting context pair(s) with node memory, 4 node(s) had untolerated taint(s). no new claims to deallocate, preemption: 0/6 nodes are available: 2 No preemption victims found for incoming pod, 4 Preemption is not helpful for scheduling."
0.1756,Event,ADDED,eval-sanitize-30-r0-032-zqt5z.18d4b0be976a028a,reason=Scheduled count=None msg=Successfully assigned compute/eval-sanitize-30-r0-032-zqt5z to kind-worker4
0.1758,Event,ADDED,eval-sanitize-30-r0-032-zqt5z.18d4b0beb1e515fd,"reason=Pulled count=1 msg=Container image ""busybox:musl"" already present on machine"
0.176,Event,ADDED,eval-sanitize-30-r0-032-zqt5z.18d4b0beb2f6090d,reason=Created count=1 msg=Created container: task
0.1761,Event,ADDED,eval-sanitize-30-r0-032-zqt5z.18d4b0beb90b2b04,reason=Started count=1 msg=Started container task
0.1763,Event,ADDED,eval-sanitize-30-r0-032.18d4b0b8ea18dbcd,reason=SuccessfulCreate count=1 msg=Created pod: eval-sanitize-30-r0-032-zqt5z
0.1765,Event,ADDED,eval-sanitize-30-r0-032.18d4b0c6634c2864,reason=Completed count=1 msg=Job completed
0.1766,Event,ADDED,eval-sanitize-30-r0-032.18d4b2a72f1b83bf,reason=SuccessfulCreate count=1 msg=Created pod: eval-sanitize-30-r0-032-sm4cx
0.1768,Event,ADDED,eval-sanitize-30-r0-032.18d4b2acd189c286,reason=Completed count=1 msg=Job completed
0.1769,Event,ADDED,eval-sanitize-30-r0-033-lxvtq.18d4b2a76f677e49,"reason=FailedScheduling count=None msg=0/6 nodes are available: 1 c_wall violated: 2 conflicting context pair(s) with node memory, 5 node(s) had untolerated taint(s). no new claims to deallocate, preemption: 0/6 nodes are available: 1 No preemption victims found for incoming pod, 5 Preemption is not helpful for scheduling."
0.1771,Event,ADDED,eval-sanitize-30-r0-033-lxvtq.18d4b2a77504da45,"reason=FailedScheduling count=None msg=0/6 nodes are available: 1 c_wall violated: 2 conflicting context pair(s) with node memory, 5 node(s) had untolerated taint(s). no new claims to deallocate, preemption: 0/6 nodes are available: 1 No preemption victims found for incoming pod, 5 Preemption is not helpful for scheduling."
0.1773,Event,ADDED,eval-sanitize-30-r0-033-lxvtq.18d4b2a9b7dd2c00,"reason=FailedScheduling count=None msg=0/6 nodes are available: 2 c_wall violated: 2 conflicting context pair(s) with node memory, 4 node(s) had untolerated taint(s). no new claims to deallocate, preemption: 0/6 nodes are available: 2 No preemption victims found for incoming pod, 4 Preemption is not helpful for scheduling."
0.1774,Event,ADDED,eval-sanitize-30-r0-033-lxvtq.18d4b2a9df308ddd,reason=Scheduled count=None msg=Successfully assigned compute/eval-sanitize-30-r0-033-lxvtq to kind-worker5
0.1776,Event,ADDED,eval-sanitize-30-r0-033-lxvtq.18d4b2aa0104a182,"reason=Pulled count=1 msg=Container image ""busybox:musl"" already present on machine"
0.1778,Event,ADDED,eval-sanitize-30-r0-033-lxvtq.18d4b2aa03f06748,reason=Created count=1 msg=Created container: task
0.1779,Event,ADDED,eval-sanitize-30-r0-033-lxvtq.18d4b2aa085aa0cb,reason=Started count=1 msg=Started container task
0.1781,Event,ADDED,eval-sanitize-30-r0-033-tknb6.18d4b0b9270d19e9,"reason=FailedScheduling count=None msg=0/6 nodes are available: 6 node(s) had untolerated taint(s). no new claims to deallocate, preemption: 0/6 nodes are available: 6 Preemption is not helpful for scheduling."
0.1783,Event,ADDED,eval-sanitize-30-r0-033-tknb6.18d4b0be41e80084,"reason=FailedScheduling count=None msg=0/6 nodes are available: 1 c_wall violated: 1 conflicting context pair(s) with node memory, 5 node(s) had untolerated taint(s). no new claims to deallocate, preemption: 0/6 nodes are available: 1 No preemption victims found for incoming pod, 5 Preemption is not helpful for scheduling."
0.1784,Event,ADDED,eval-sanitize-30-r0-033-tknb6.18d4b0be6cef3e5f,"reason=FailedScheduling count=None msg=0/6 nodes are available: 1 c_wall violated: 1 conflicting context pair(s) with node memory, 1 c_wall violated: 2 conflicting context pair(s) with node memory, 4 node(s) had untolerated taint(s). no new claims to deallocate, preemption: 0/6 nodes are available: 2 No preemption victims found for incoming pod, 4 Preemption is not helpful for scheduling."
0.1786,Event,ADDED,eval-sanitize-30-r0-033-tknb6.18d4b0be9d173bcb,reason=Scheduled count=None msg=Successfully assigned compute/eval-sanitize-30-r0-033-tknb6 to kind-worker4
0.1788,Event,ADDED,eval-sanitize-30-r0-033-tknb6.18d4b0beb90ef575,"reason=Pulled count=1 msg=Container image ""busybox:musl"" already present on machine"
0.1789,Event,ADDED,eval-sanitize-30-r0-033-tknb6.18d4b0bebabe0c9e,reason=Created count=1 msg=Created container: task
0.1791,Event,ADDED,eval-sanitize-30-r0-033-tknb6.18d4b0bebf4e0414,reason=Started count=1 msg=Started container task
0.1793,Event,ADDED,eval-sanitize-30-r0-033.18d4b0b92700e82f,reason=SuccessfulCreate count=1 msg=Created pod: eval-sanitize-30-r0-033-tknb6
0.1794,Event,ADDED,eval-sanitize-30-r0-033.18d4b0c66c8ac2eb,reason=Completed count=1 msg=Job completed
0.1796,Event,ADDED,eval-sanitize-30-r0-033.18d4b2a76e7f02a0,reason=SuccessfulCreate count=1 msg=Created pod: eval-sanitize-30-r0-033-lxvtq
0.1803,Event,ADDED,eval-sanitize-30-r0-033.18d4b2b0942af953,reason=Completed count=1 msg=Job completed
0.1805,Event,ADDED,eval-sanitize-30-r0-034-mrcs7.18d4b0b960f5dc16,"reason=FailedScheduling count=None msg=0/6 nodes are available: 6 node(s) had untolerated taint(s). no new claims to deallocate, preemption: 0/6 nodes are available: 6 Preemption is not helpful for scheduling."
0.1806,Event,ADDED,eval-sanitize-30-r0-034-mrcs7.18d4b0be4482c509,"reason=FailedScheduling count=None msg=0/6 nodes are available: 1 c_wall violated: 1 conflicting context pair(s) with node memory, 5 node(s) had untolerated taint(s). no new claims to deallocate, preemption: 0/6 nodes are available: 1 No preemption victims found for incoming pod, 5 Preemption is not helpful for scheduling."
0.1809,Event,ADDED,eval-sanitize-30-r0-034-mrcs7.18d4b0be6e1c91aa,reason=Scheduled count=None msg=Successfully assigned compute/eval-sanitize-30-r0-034-mrcs7 to kind-worker2
0.1811,Event,ADDED,eval-sanitize-30-r0-034-mrcs7.18d4b0be891909e8,"reason=Pulled count=1 msg=Container image ""busybox:musl"" already present on machine"
0.1813,Event,ADDED,eval-sanitize-30-r0-034-mrcs7.18d4b0be8aedfb46,reason=Created count=1 msg=Created container: task
0.1814,Event,ADDED,eval-sanitize-30-r0-034-mrcs7.18d4b0be8ea19e9f,reason=Started count=1 msg=Started container task
0.1817,Event,ADDED,eval-sanitize-30-r0-034-vnpc7.18d4b2a7a6893d3b,"reason=FailedScheduling count=None msg=0/6 nodes are available: 1 c_wall violated: 3 conflicting context pair(s) with node memory, 5 node(s) had untolerated taint(s). no new claims to deallocate, preemption: 0/6 nodes are available: 1 No preemption victims found for incoming pod, 5 Preemption is not helpful for scheduling."
0.182,Event,ADDED,eval-sanitize-30-r0-034-vnpc7.18d4b2a7a714c07a,"reason=FailedScheduling count=None msg=0/6 nodes are available: 1 c_wall violated: 3 conflicting context pair(s) with node memory, 5 node(s) had untolerated taint(s). no new claims to deallocate, preemption: 0/6 nodes are available: 1 No preemption victims found for incoming pod, 5 Preemption is not helpful for scheduling."
0.1821,Event,ADDED,eval-sanitize-30-r0-034-vnpc7.18d4b2a98726bb0d,reason=Scheduled count=None msg=Successfully assigned compute/eval-sanitize-30-r0-034-vnpc7 to kind-worker2
0.1824,Event,ADDED,eval-sanitize-30-r0-034-vnpc7.18d4b2a9a7868c06,"reason=Pulled count=1 msg=Container image ""busybox:musl"" already present on machine"
0.1826,Event,ADDED,eval-sanitize-30-r0-034-vnpc7.18d4b2a9a9332701,reason=Created count=1 msg=Created container: task
0.1827,Event,ADDED,eval-sanitize-30-r0-034-vnpc7.18d4b2a9b3fd2e54,reason=Started count=1 msg=Started container task
0.1829,Event,ADDED,eval-sanitize-30-r0-034.18d4b0b960e7b518,reason=SuccessfulCreate count=1 msg=Created pod: eval-sanitize-30-r0-034-mrcs7
0.1832,Event,ADDED,eval-sanitize-30-r0-034.18d4b0c63b7fb9ea,reason=Completed count=1 msg=Job completed
0.1834,Event,ADDED,eval-sanitize-30-r0-034.18d4b2a7a63f5998,reason=SuccessfulCreate count=1 msg=Created pod: eval-sanitize-30-r0-034-vnpc7
0.1836,Event,ADDED,eval-sanitize-30-r0-034.18d4b2aff3415906,reason=Completed count=1 msg=Job completed
0.1839,Event,ADDED,eval-sanitize-30-r0-035-75jq6.18d4b2a7e28a7601,"reason=FailedScheduling count=None msg=0/6 nodes are available: 1 c_wall violated: 1 conflicting context pair(s) with node memory, 5 node(s) had untolerated taint(s). no new claims to deallocate, preemption: 0/6 nodes are available: 1 No preemption victims found for incoming pod, 5 Preemption is not helpful for scheduling."
0.1841,Event,ADDED,eval-sanitize-30-r0-035-75jq6.18d4b2a7e332d521,"reason=FailedScheduling count=None msg=0/6 nodes are available: 1 c_wall violated: 1 conflicting context pair(s) with node memory, 5 node(s) had untolerated taint(s). no new claims to deallocate, preemption: 0/6 nodes are available: 1 No preemption victims found for incoming pod, 5 Preemption is not helpful for scheduling."
0.1842,Event,ADDED,eval-sanitize-30-r0-035-75jq6.18d4b2a9be4d7f0d,reason=Scheduled count=None msg=Successfully assigned compute/eval-sanitize-30-r0-035-75jq6 to kind-worker5
0.1844,Event,ADDED,eval-sanitize-30-r0-035-75jq6.18d4b2a9dee40506,"reason=Pulled count=1 msg=Container image ""busybox:musl"" already present on machine"
0.1847,Event,ADDED,eval-sanitize-30-r0-035-75jq6.18d4b2a9e0cab553,reason=Created count=1 msg=Created container: task
0.1849,Event,ADDED,eval-sanitize-30-r0-035-75jq6.18d4b2a9e4e28ebc,reason=Started count=1 msg=Started container task
0.185,Event,ADDED,eval-sanitize-30-r0-035-8569q.18d4b0b99c2e524a,"reason=FailedScheduling count=None msg=0/6 nodes are available: 6 node(s) had untolerated taint(s). no new claims to deallocate, preemption: 0/6 nodes are available: 6 Preemption is not helpful for scheduling."
0.1853,Event,ADDED,eval-sanitize-30-r0-035-8569q.18d4b0be45218538,"reason=FailedScheduling count=None msg=0/6 nodes are available: 1 c_wall violated: 2 conflicting context pair(s) with node memory, 5 node(s) had untolerated taint(s). no new claims to deallocate, preemption: 0/6 nodes are available: 1 No preemption victims found for incoming pod, 5 Preemption is not helpful for scheduling."
0.1855,Event,ADDED,eval-sanitize-30-r0-035-8569q.18d4b0be72abcd86,"reason=FailedScheduling count=None msg=0/6 nodes are available: 2 c_wall violated: 2 conflicting context pair(s) with node memory, 4 node(s) had untolerated taint(s). no new claims to deallocate, preemption: 0/6 nodes are available: 2 No preemption victims found for incoming pod, 4 Preemption is not helpful for scheduling."
0.1856,Event,ADDED,eval-sanitize-30-r0-035-8569q.18d4b0bea2e63f6b,reason=Scheduled count=None msg=Successfully assigned compute/eval-sanitize-30-r0-035-8569q to kind-worker3
0.1859,Event,ADDED,eval-sanitize-30-r0-035-8569q.18d4b0bec088ecc4,"reason=Pulled count=1 msg=Container image ""busybox:musl"" already present on machine"
0.1861,Event,ADDED,eval-sanitize-30-r0-035-8569q.18d4b0bec1a769c7,reason=Created count=1 msg=Created container: task
0.1862,Event,ADDED,eval-sanitize-30-r0-035-8569q.18d4b0bec641ae8c,reason=Started count=1 msg=Started container task
0.1864,Event,ADDED,eval-sanitize-30-r0-035.18d4b0b99c264017,reason=SuccessfulCreate count=1 msg=Created pod: eval-sanitize-30-r0-035-8569q
0.1866,Event,ADDED,eval-sanitize-30-r0-035.18d4b0c68ef59eaf,reason=Completed count=1 msg=Job completed
0.1867,Event,ADDED,eval-sanitize-30-r0-035.18d4b2a7e24b6b3a,reason=SuccessfulCreate count=1 msg=Created pod: eval-sanitize-30-r0-035-75jq6
0.1869,Event,ADDED,eval-sanitize-30-r0-035.18d4b2b016a14ca0,reason=Completed count=1 msg=Job completed
0.187,Event,ADDED,eval-sanitize-30-r0-036-2kkgx.18d4b0b9d83935bc,"reason=FailedScheduling count=None msg=0/6 nodes are available: 6 node(s) had untolerated taint(s). no new claims to deallocate, preemption: 0/6 nodes are available: 6 Preemption is not helpful for scheduling."
0.1872,Event,ADDED,eval-sanitize-30-r0-036-2kkgx.18d4b0be45a45bfa,"reason=FailedScheduling count=None msg=0/6 nodes are available: 1 c_wall violated: 1 conflicting context pair(s) with node memory, 5 node(s) had untolerated taint(s). no new claims to deallocate, preemption: 0/6 nodes are available: 1 No preemption victims found for incoming pod, 5 Preemption is not helpful for scheduling."
0.1873,Event,ADDED,eval-sanitize-30-r0-036-2kkgx.18d4b0be74074cdb,"reason=FailedScheduling count=None msg=0/6 nodes are available: 2 c_wall violated: 1 conflicting context pair(s) with node memory, 4 node(s) had untolerated taint(s). no new claims to deallocate, preemption: 0/6 nodes are available: 2 No preemption victims found for incoming pod, 4 Preemption is not helpful for scheduling."
0.1875,Event,ADDED,eval-sanitize-30-r0-036-2kkgx.18d4b0beaae5020c,reason=Scheduled count=None msg=Successfully assigned compute/eval-sanitize-30-r0-036-2kkgx to kind-worker5
0.1877,Event,ADDED,eval-sanitize-30-r0-036-2kkgx.18d4b0bec64802f5,"reason=Pulled count=1 msg=Container image ""busybox:musl"" already present on machine"
0.1878,Event,ADDED,eval-sanitize-30-r0-036-2kkgx.18d4b0bec7e5e70e,reason=Created count=1 msg=Created container: task
0.188,Event,ADDED,eval-sanitize-30-r0-036-2kkgx.18d4b0becbbe6797,reason=Started count=1 msg=Started container task
0.1881,Event,ADDED,eval-sanitize-30-r0-036-rdgh2.18d4b2a81e9ce744,"reason=FailedScheduling count=None msg=0/6 nodes are available: 1 c_wall violated: 1 conflicting context pair(s) with node memory, 5 node(s) had untolerated taint(s). no new claims to deallocate, preemption: 0/6 nodes are available: 1 No preemption victims found for incoming pod, 5 Preemption is not helpful for scheduling."
0.1883,Event,ADDED,eval-sanitize-30-r0-036-rdgh2.18d4b2a81f36952d,"reason=FailedScheduling count=None msg=0/6 nodes are available: 1 c_wall violated: 1 conflicting context pair(s) with node memory, 5 node(s) had untolerated taint(s). no new claims to deallocate, preemption: 0/6 nodes are available: 1 No preemption victims found for incoming pod, 5 Preemption is not helpful for scheduling."
0.1885,Event,ADDED,eval-sanitize-30-r0-036-rdgh2.18d4b2a9a8a4d695,reason=Scheduled count=None msg=Successfully assigned compute/eval-sanitize-30-r0-036-rdgh2 to kind-worker
0.1886,Event,ADDED,eval-sanitize-30-r0-036-rdgh2.18d4b2a9c3e4a0b2,"reason=Pulled count=1 msg=Container image ""busybox:musl"" already present on machine"
0.1888,Event,ADDED,eval-sanitize-30-r0-036-rdgh2.18d4b2a9c522e96a,reason=Created count=1 msg=Created container: task
0.189,Event,ADDED,eval-sanitize-30-r0-036-rdgh2.18d4b2a9c900329f,reason=Started count=1 msg=Started container task
0.1892,Event,ADDED,eval-sanitize-30-r0-036.18d4b0b9d828b0f6,reason=SuccessfulCreate count=1 msg=Created pod: eval-sanitize-30-r0-036-2kkgx
0.1893,Event,ADDED,eval-sanitize-30-r0-036.18d4b0c6b6216873,reason=Completed count=1 msg=Job completed
0.1895,Event,ADDED,eval-sanitize-30-r0-036.18d4b2a81e57956f,reason=SuccessfulCreate count=1 msg=Created pod: eval-sanitize-30-r0-036-rdgh2
0.1897,Event,ADDED,eval-sanitize-30-r0-036.18d4b2aff23b3419,reason=Completed count=1 msg=Job completed
0.1899,Event,ADDED,eval-sanitize-30-r0-037-2whkn.18d4b0ba135fc7b8,"reason=FailedScheduling count=None msg=0/6 nodes are available: 6 node(s) had untolerated taint(s). no new claims to deallocate, preemption: 0/6 nodes are available: 6 Preemption is not helpful for scheduling."
0.19,Event,ADDED,eval-sanitize-30-r0-037-2whkn.18d4b0be46387aac,"reason=FailedScheduling count=None msg=0/6 nodes are available: 1 c_wall violated: 1 conflicting context pair(s) with node memory, 5 node(s) had untolerated taint(s). no new claims to deallocate, preemption: 0/6 nodes are available: 1 No preemption victims found for incoming pod, 5 Preemption is not helpful for scheduling."
0.1902,Event,ADDED,eval-sanitize-30-r0-037-2whkn.18d4b0be7532afbb,reason=Scheduled count=None msg=Successfully assigned compute/eval-sanitize-30-r0-037-2whkn to kind-worker2
0.1904,Event,ADDED,eval-sanitize-30-r0-037-2whkn.18d4b0be8eadc245,"reason=Pulled count=1 msg=Container image ""busybox:musl"" already present on machine"
0.1906,Event,ADDED,eval-sanitize-30-r0-037-2whkn.18d4b0be9021ca4b,reason=Created count=1 msg=Created container: task
0.1908,Event,ADDED,eval-sanitize-30-r0-037-2whkn.18d4b0be9560438a,reason=Started count=1 msg=Started container task
0.1909,Event,ADDED,eval-sanitize-30-r0-037-kt56x.18d4b2a859724a0e,"reason=FailedScheduling count=None msg=0/6 nodes are available: 1 c_wall violated: 1 conflicting context pair(s) with node memory, 5 node(s) had untolerated taint(s). no new claims to deallocate, preemption: 0/6 nodes are available: 1 No preemption victims found for incoming pod, 5 Preemption is not helpful for scheduling."
0.1911,Event,ADDED,eval-sanitize-30-r0-037-kt56x.18d4b2a85a85902d,"reason=FailedScheduling count=None msg=0/6 nodes are available: 1 c_wall violated: 1 conflicting context pair(s) with node memory, 5 node(s) had untolerated taint(s). no new claims to deallocate, preemption: 0/6 nodes are available: 1 No preemption victims found for incoming pod, 5 Preemption is not helpful for scheduling."
0.1912,Event,ADDED,eval-sanitize-30-r0-037-kt56x.18d4b2a9c3bd6c84,reason=Scheduled count=None msg=Successfully assigned compute/eval-sanitize-30-r0-037-kt56x to kind-worker5
0.1914,Event,ADDED,eval-sanitize-30-r0-037-kt56x.18d4b2a9e5e4c03a,"reason=Pulled count=1 msg=Container image ""busybox:musl"" already present on machine"
0.1916,Event,ADDED,eval-sanitize-30-r0-037-kt56x.18d4b2a9e712ff82,reason=Created count=1 msg=Created container: task
0.1918,Event,ADDED,eval-sanitize-30-r0-037-kt56x.18d4b2a9ec900900,reason=Started count=1 msg=Started container task
0.1919,Event,ADDED,eval-sanitize-30-r0-037.18d4b0ba1353ecb5,reason=SuccessfulCreate count=1 msg=Created pod: eval-sanitize-30-r0-037-2whkn
0.1921,Event,ADDED,eval-sanitize-30-r0-037.18d4b0c6299cb0e4,reason=Completed count=1 msg=Job completed
0.1922,Event,ADDED,eval-sanitize-30-r0-037.18d4b2a85931990c,reason=SuccessfulCreate count=1 msg=Created pod: eval-sanitize-30-r0-037-kt56x
0.1924,Event,ADDED,eval-sanitize-30-r0-037.18d4b2b01cf5053e,reason=Completed count=1 msg=Job completed
0.1926,Event,ADDED,eval-sanitize-30-r0-038-l5mn8.18d4b2a894e701b8,"reason=FailedScheduling count=None msg=0/6 nodes are available: 1 c_wall violated: 2 conflicting context pair(s) with node memory, 5 node(s) had untolerated taint(s). no new claims to deallocate, preemption: 0/6 nodes are available: 1 No preemption victims found for incoming pod, 5 Preemption is not helpful for scheduling."
0.1927,Event,ADDED,eval-sanitize-30-r0-038-l5mn8.18d4b2a89589143d,"reason=FailedScheduling count=None msg=0/6 nodes are available: 1 c_wall violated: 2 conflicting context pair(s) with node memory, 5 node(s) had untolerated taint(s). no new claims to deallocate, preemption: 0/6 nodes are available: 1 No preemption victims found for incoming pod, 5 Preemption is not helpful for scheduling."
0.1929,Event,ADDED,eval-sanitize-30-r0-038-l5mn8.18d4b2a9ca6c58fa,reason=Scheduled count=None msg=Successfully assigned compute/eval-sanitize-30-r0-038-l5mn8 to kind-worker5
0.193,Event,ADDED,eval-sanitize-30-r0-038-l5mn8.18d4b2aa03f10034,"reason=Pulled count=1 msg=Container image ""busybox:musl"" already present on machine"
0.1932,Event,ADDED,eval-sanitize-30-r0-038-l5mn8.18d4b2aa059c2b14,reason=Created count=1 msg=Created container: task
0.1934,Event,ADDED,eval-sanitize-30-r0-038-l5mn8.18d4b2aa094074c3,reason=Started count=1 msg=Started container task
0.1935,Event,ADDED,eval-sanitize-30-r0-038-r8ml9.18d4b0ba4ef2912e,"reason=FailedScheduling count=None msg=0/6 nodes are available: 6 node(s) had untolerated taint(s). no new claims to deallocate, preemption: 0/6 nodes are available: 6 Preemption is not helpful for scheduling."
0.1937,Event,ADDED,eval-sanitize-30-r0-038-r8ml9.18d4b0be46e5224a,"reason=FailedScheduling count=None msg=0/6 nodes are available: 1 c_wall violated: 1 conflicting context pair(s) with node memory, 5 node(s) had untolerated taint(s). no new claims to deallocate, preemption: 0/6 nodes are available: 1 No preemption victims found for incoming pod, 5 Preemption is not helpful for scheduling."
0.1938,Event,ADDED,eval-sanitize-30-r0-038-r8ml9.18d4b0be7b68abf8,reason=Scheduled count=None msg=Successfully assigned compute/eval-sanitize-30-r0-038-r8ml9 to kind-worker2
0.194,Event,ADDED,eval-sanitize-30-r0-038-r8ml9.18d4b0be95e6de94,"reason=Pulled count=1 msg=Container image ""busybox:musl"" already present on machine"
0.1941,Event,ADDED,eval-sanitize-30-r0-038-r8ml9.18d4b0be97470eb7,reason=Created count=1 msg=Created container: task
0.1943,Event,ADDED,eval-sanitize-30-r0-038-r8ml9.18d4b0be9ae317ea,reason=Started count=1 msg=Started container task
0.1945,Event,ADDED,eval-sanitize-30-r0-038.18d4b0ba4ee647e0,reason=SuccessfulCreate count=1 msg=Created pod: eval-sanitize-30-r0-038-r8ml9
0.1946,Event,ADDED,eval-sanitize-30-r0-038.18d4b0c62fa769cd,reason=Completed count=1 msg=Job completed
0.1948,Event,ADDED,eval-sanitize-30-r0-038.18d4b2a894a29bce,reason=SuccessfulCreate count=1 msg=Created pod: eval-sanitize-30-r0-038-l5mn8
0.195,Event,ADDED,eval-sanitize-30-r0-038.18d4b2b08dc55aa7,reason=Completed count=1 msg=Job completed
0.1951,Event,ADDED,eval-sanitize-30-r0-039-66nr5.18d4b0ba8a7deed9,"reason=FailedScheduling count=None msg=0/6 nodes are available: 6 node(s) had untolerated taint(s). no new claims to deallocate, preemption: 0/6 nodes are available: 6 Preemption is not helpful for scheduling."
0.1953,Event,ADDED,eval-sanitize-30-r0-039-66nr5.18d4b0be4977d389,reason=Scheduled count=None msg=Successfully assigned compute/eval-sanitize-30-r0-039-66nr5 to kind-worker
0.1954,Event,ADDED,eval-sanitize-30-r0-039-66nr5.18d4b0be63db8f08,"reason=Pulled count=1 msg=Container image ""busybox:musl"" already present on machine"
0.1956,Event,ADDED,eval-sanitize-30-r0-039-66nr5.18d4b0be65dd15f5,reason=Created count=1 msg=Created container: task
0.1958,Event,ADDED,eval-sanitize-30-r0-039-66nr5.18d4b0be6a106834,reason=Started count=1 msg=Started container task
0.1959,Event,ADDED,eval-sanitize-30-r0-039-tgn75.18d4b2a8d0f689b7,"reason=FailedScheduling count=None msg=0/6 nodes are available: 1 c_wall violated: 3 conflicting context pair(s) with node memory, 5 node(s) had untolerated taint(s). no new claims to deallocate, preemption: 0/6 nodes are available: 1 No preemption victims found for incoming pod, 5 Preemption is not helpful for scheduling."
0.1961,Event,ADDED,eval-sanitize-30-r0-039-tgn75.18d4b2a8d18273ab,"reason=FailedScheduling count=None msg=0/6 nodes are available: 1 c_wall violated: 3 conflicting context pair(s) with node memory, 5 node(s) had untolerated taint(s). no new claims to deallocate, preemption: 0/6 nodes are available: 1 No preemption victims found for incoming pod, 5 Preemption is not helpful for scheduling."
0.1962,Event,ADDED,eval-sanitize-30-r0-039-tgn75.18d4b2a96a9e2eb8,reason=Scheduled count=None msg=Successfully assigned compute/eval-sanitize-30-r0-039-tgn75 to kind-worker2
0.1964,Event,ADDED,eval-sanitize-30-r0-039-tgn75.18d4b2a98471af2f,"reason=Pulled count=1 msg=Container image ""busybox:musl"" already present on machine"
0.1966,Event,ADDED,eval-sanitize-30-r0-039-tgn75.18d4b2a985dafeb2,reason=Created count=1 msg=Created container: task
0.1982,Event,ADDED,eval-sanitize-30-r0-039-tgn75.18d4b2a98d476899,reason=Started count=1 msg=Started container task
0.1984,Event,ADDED,eval-sanitize-30-r0-039.18d4b0ba8a7966e9,reason=SuccessfulCreate count=1 msg=Created pod: eval-sanitize-30-r0-039-66nr5
0.1986,Event,ADDED,eval-sanitize-30-r0-039.18d4b0c3c3fb55a4,reason=Completed count=1 msg=Job completed
0.1987,Event,ADDED,eval-sanitize-30-r0-039.18d4b2a8d0af16d4,reason=SuccessfulCreate count=1 msg=Created pod: eval-sanitize-30-r0-039-tgn75
0.1989,Event,ADDED,eval-sanitize-30-r0-039.18d4b2aefd482ab7,reason=Completed count=1 msg=Job completed
0.199,Event,ADDED,eval-sanitize-30-r0-040-8dmxh.18d4b2a90c991de0,"reason=FailedScheduling count=None msg=0/6 nodes are available: 1 c_wall violated: 2 conflicting context pair(s) with node memory, 5 node(s) had untolerated taint(s). no new claims to deallocate, preemption: 0/6 nodes are available: 1 No preemption victims found for incoming pod, 5 Preemption is not helpful for scheduling."
0.1992,Event,ADDED,eval-sanitize-30-r0-040-8dmxh.18d4b2a90d1f558d,"reason=FailedScheduling count=None msg=0/6 nodes are available: 1 c_wall violated: 2 conflicting context pair(s) with node memory, 5 node(s) had untolerated taint(s). no new claims to deallocate, preemption: 0/6 nodes are available: 1 No preemption victims found for incoming pod, 5 Preemption is not helpful for scheduling."
0.1994,Event,ADDED,eval-sanitize-30-r0-040-8dmxh.18d4b2a9b4e258ee,reason=Scheduled count=None msg=Successfully assigned compute/eval-sanitize-30-r0-040-8dmxh to kind-worker
0.1996,Event,ADDED,eval-sanitize-30-r0-040-8dmxh.18d4b2a9d0953acf,"reason=Pulled count=1 msg=Container image ""busybox:musl"" already present on machine"
0.1997,Event,ADDED,eval-sanitize-30-r0-040-8dmxh.18d4b2a9d32e5a2d,reason=Created count=1 msg=Created container: task
0.1999,Event,ADDED,eval-sanitize-30-r0-040-8dmxh.18d4b2a9dee37af7,reason=Started count=1 msg=Started container task
0.2,Event,ADDED,eval-sanitize-30-r0-040-qn9fp.18d4b0bac762a625,"reason=FailedScheduling count=None msg=0/6 nodes are available: 6 node(s) had untolerated taint(s). no new claims to deallocate, preemption: 0/6 nodes are available: 6 Preemption is not helpful for scheduling."
0.2002,Event,ADDED,eval-sanitize-30-r0-040-qn9fp.18d4b0be493d111e,"reason=FailedScheduling count=None msg=0/6 nodes are available: 1 c_wall violated: 1 conflicting context pair(s) with node memory, 5 node(s) had untolerated taint(s). no new claims to deallocate, preemption: 0/6 nodes are available: 1 No preemption victims found for incoming pod, 5 Preemption is not helpful for scheduling."
0.2003,Event,ADDED,eval-sanitize-30-r0-040-qn9fp.18d4b0be7926f462,"reason=FailedScheduling count=None msg=0/6 nodes are available: 1 c_wall violated: 1 conflicting context pair(s) with node memory, 1 c_wall violated: 2 conflicting context pair(s) with node memory, 4 node(s) had untolerated taint(s). no new claims to deallocate, preemption: 0/6 nodes are available: 2 No preemption victims found for incoming pod, 4 Preemption is not helpful for scheduling."
0.2005,Event,ADDED,eval-sanitize-30-r0-040-qn9fp.18d4b0beaee6b8dc,reason=Scheduled count=None msg=Successfully assigned compute/eval-sanitize-30-r0-040-qn9fp to kind-worker3
0.2006,Event,ADDED,eval-sanitize-30-r0-040-qn9fp.18d4b0beccb12ccc,"reason=Pulled count=1 msg=Container image ""busybox:musl"" already present on machine"
0.2008,Event,ADDED,eval-sanitize-30-r0-040-qn9fp.18d4b0bece324709,reason=Created count=1 msg=Created container: task
0.201,Event,ADDED,eval-sanitize-30-r0-040-qn9fp.18d4b0bed2b1a99a,reason=Started count=1 msg=Started container task
0.2012,Event,ADDED,eval-sanitize-30-r0-040.18d4b0bac75b7dd4,reason=SuccessfulCreate count=1 msg=Created pod: eval-sanitize-30-r0-040-qn9fp
0.2013,Event,ADDED,eval-sanitize-30-r0-040.18d4b0c688f950db,reason=Completed count=1 msg=Job completed
0.2015,Event,ADDED,eval-sanitize-30-r0-040.18d4b2a90c56f674,reason=SuccessfulCreate count=1 msg=Created pod: eval-sanitize-30-r0-040-8dmxh
0.2017,Event,ADDED,eval-sanitize-30-r0-040.18d4b2b05e924ce2,reason=Completed count=1 msg=Job completed
0.2018,Event,ADDED,eval-sanitize-30-r0-041-68887.18d4b0bb01fc8f65,"reason=FailedScheduling count=None msg=0/6 nodes are available: 6 node(s) had untolerated taint(s). no new claims to deallocate, preemption: 0/6 nodes are available: 6 Preemption is not helpful for scheduling."
0.202,Event,ADDED,eval-sanitize-30-r0-041-68887.18d4b0be4b17eb70,reason=Scheduled count=None msg=Successfully assigned compute/eval-sanitize-30-r0-041-68887 to kind-worker
0.2021,Event,ADDED,eval-sanitize-30-r0-041-68887.18d4b0be640934d2,"reason=Pulled count=1 msg=Container image ""busybox:musl"" already present on machine"
0.2023,Event,ADDED,eval-sanitize-30-r0-041-68887.18d4b0be668f9e58,reason=Created count=1 msg=Created container: task
0.2025,Event,ADDED,eval-sanitize-30-r0-041-68887.18d4b0be6a732405,reason=Started count=1 msg=Started container task
0.2026,Event,ADDED,eval-sanitize-30-r0-041-fws4n.18d4b2a94aba7d03,"reason=FailedScheduling count=None msg=0/6 nodes are available: 1 c_wall violated: 1 conflicting context pair(s) with node memory, 5 node(s) had untolerated taint(s). no new claims to deallocate, preemption: 0/6 nodes are available: 1 No preemption victims found for incoming pod, 5 Preemption is not helpful for scheduling."
0.2028,Event,ADDED,eval-sanitize-30-r0-041-fws4n.18d4b2a952505e0d,"reason=FailedScheduling count=None msg=0/6 nodes are available: 1 c_wall violated: 1 conflicting context pair(s) with node memory, 5 node(s) had untolerated taint(s). no new claims to deallocate, preemption: 0/6 nodes are available: 1 No preemption victims found for incoming pod, 5 Preemption is not helpful for scheduling."
0.2029,Event,ADDED,eval-sanitize-30-r0-041-fws4n.18d4b2a96b5d5920,reason=Scheduled count=None msg=Successfully assigned compute/eval-sanitize-30-r0-041-fws4n to kind-worker2
0.2031,Event,ADDED,eval-sanitize-30-r0-041-fws4n.18d4b2a984c5bc6d,"reason=Pulled count=1 msg=Container image ""busybox:musl"" already present on machine"
0.2032,Event,ADDED,eval-sanitize-30-r0-041-fws4n.18d4b2a98675dc5f,reason=Created count=1 msg=Created container: task
0.2034,Event,ADDED,eval-sanitize-30-r0-041-fws4n.18d4b2a98d487467,reason=Started count=1 msg=Started container task
0.2036,Event,ADDED,eval-sanitize-30-r0-041.18d4b0bb01eeafc1,reason=SuccessfulCreate count=1 msg=Created pod: eval-sanitize-30-r0-041-68887
0.2037,Event,ADDED,eval-sanitize-30-r0-041.18d4b0c54d0dc661,reason=Completed count=1 msg=Job completed
0.2039,Event,ADDED,eval-sanitize-30-r0-041.18d4b2a94a77843e,reason=SuccessfulCreate count=1 msg=Created pod: eval-sanitize-30-r0-041-fws4n
0.2041,Event,ADDED,eval-sanitize-30-r0-041.18d4b2aefdfea616,reason=Completed count=1 msg=Job completed
0.2042,Event,ADDED,eval-sanitize-30-r0-042-8rm4l.18d4b0bb3d30997a,"reason=FailedScheduling count=None msg=0/6 nodes are available: 6 node(s) had untolerated taint(s). no new claims to deallocate, preemption: 0/6 nodes are available: 6 Preemption is not helpful for scheduling."
0.2044,Event,ADDED,eval-sanitize-30-r0-042-8rm4l.18d4b0be4a06da88,"reason=FailedScheduling count=None msg=0/6 nodes are available: 1 c_wall violated: 2 conflicting context pair(s) with node memory, 5 node(s) had untolerated taint(s). no new claims to deallocate, preemption: 0/6 nodes are available: 1 No preemption victims found for incoming pod, 5 Preemption is not helpful for scheduling."
0.2045,Event,ADDED,eval-sanitize-30-r0-042-8rm4l.18d4b0be7ec67622,"reason=FailedScheduling count=None msg=0/6 nodes are available: 2 c_wall violated: 2 conflicting context pair(s) with node memory, 4 node(s) had untolerated taint(s). no new claims to deallocate, preemption: 0/6 nodes are available: 2 No preemption victims found for incoming pod, 4 Preemption is not helpful for scheduling."
0.2047,Event,ADDED,eval-sanitize-30-r0-042-8rm4l.18d4b0beb9271e3b,reason=Scheduled count=None msg=Successfully assigned compute/eval-sanitize-30-r0-042-8rm4l to kind-worker5
0.2048,Event,ADDED,eval-sanitize-30-r0-042-8rm4l.18d4b0bed2e0aab8,"reason=Pulled count=1 msg=Container image ""busybox:musl"" already present on machine"
0.2051,Event,ADDED,eval-sanitize-30-r0-042-8rm4l.18d4b0bed42c534d,reason=Created count=1 msg=Created container: task
0.2052,Event,ADDED,eval-sanitize-30-r0-042-8rm4l.18d4b0bedbbb0a55,reason=Started count=1 msg=Started container task
0.2054,Event,ADDED,eval-sanitize-30-r0-042-wfdww.18d4b2a98848ea2d,reason=Scheduled count=None msg=Successfully assigned compute/eval-sanitize-30-r0-042-wfdww to kind-worker
0.2055,Event,ADDED,eval-sanitize-30-r0-042-wfdww.18d4b2a9a79a59fe,"reason=Pulled count=1 msg=Container image ""busybox:musl"" already present on machine"
0.2057,Event,ADDED,eval-sanitize-30-r0-042-wfdww.18d4b2a9a9539560,reason=Created count=1 msg=Created container: task
0.2059,Event,ADDED,eval-sanitize-30-r0-042-wfdww.18d4b2a9b3fff6e1,reason=Started count=1 msg=Started container task
0.206,Event,ADDED,eval-sanitize-30-r0-042.18d4b0bb3d24eae3,reason=SuccessfulCreate count=1 msg=Created pod: eval-sanitize-30-r0-042-8rm4l
0.2062,Event,ADDED,eval-sanitize-30-r0-042.18d4b0c69c1e0b41,reason=Completed count=1 msg=Job completed
0.2064,Event,ADDED,eval-sanitize-30-r0-042.18d4b2a982e35b3f,reason=SuccessfulCreate count=1 msg=Created pod: eval-sanitize-30-r0-042-wfdww
0.2065,Event,ADDED,eval-sanitize-30-r0-042.18d4b2afe02538bc,reason=Completed count=1 msg=Job completed
0.2067,Event,ADDED,eval-sanitize-30-r0-043-6hkcz.18d4b0bb7962d41a,"reason=FailedScheduling count=None msg=0/6 nodes are available: 6 node(s) had untolerated taint(s). no new claims to deallocate, preemption: 0/6 nodes are available: 6 Preemption is not helpful for scheduling."
0.2068,Event,ADDED,eval-sanitize-30-r0-043-6hkcz.18d4b0be4b559daa,"reason=FailedScheduling count=None msg=0/6 nodes are available: 1 c_wall violated: 1 conflicting context pair(s) with node memory, 5 node(s) had untolerated taint(s). no new claims to deallocate, preemption: 0/6 nodes are available: 1 No preemption victims found for incoming pod, 5 Preemption is not helpful for scheduling."
0.207,Event,ADDED,eval-sanitize-30-r0-043-6hkcz.18d4b0be8006439c,reason=Scheduled count=None msg=Successfully assigned compute/eval-sanitize-30-r0-043-6hkcz to kind-worker2
0.2072,Event,ADDED,eval-sanitize-30-r0-043-6hkcz.18d4b0be9ae9b6be,"reason=Pulled count=1 msg=Container image ""busybox:musl"" already present on machine"
0.2073,Event,ADDED,eval-sanitize-30-r0-043-6hkcz.18d4b0be9ce1415a,reason=Created count=1 msg=Created container: task
0.2075,Event,ADDED,eval-sanitize-30-r0-043-6hkcz.18d4b0bea28ea1ca,reason=Started count=1 msg=Started container task
0.2076,Event,ADDED,eval-sanitize-30-r0-043-8s2sw.18d4b2a9c9d5b35f,reason=Scheduled count=None msg=Successfully assigned compute/eval-sanitize-30-r0-043-8s2sw to kind-worker5
0.2078,Event,ADDED,eval-sanitize-30-r0-043-8s2sw.18d4b2aa00e31e5e,"reason=Pulled count=1 msg=Container image ""busybox:musl"" already present on machine"
0.208,Event,ADDED,eval-sanitize-30-r0-043-8s2sw.18d4b2aa037db63e,reason=Created count=1 msg=Created container: task
0.2081,Event,ADDED,eval-sanitize-30-r0-043-8s2sw.18d4b2aa0912eb0f,reason=Started count=1 msg=Started container task
0.2083,Event,ADDED,eval-sanitize-30-r0-043.18d4b0bb795781f0,reason=SuccessfulCreate count=1 msg=Created pod: eval-sanitize-30-r0-043-6hkcz
0.2085,Event,ADDED,eval-sanitize-30-r0-043.18d4b0c60ed2dfb6,reason=Completed count=1 msg=Job completed
0.2086,Event,ADDED,eval-sanitize-30-r0-043.18d4b2a9bf46da35,reason=SuccessfulCreate count=1 msg=Created pod: eval-sanitize-30-r0-043-8s2sw
0.2088,Event,ADDED,eval-sanitize-30-r0-043.18d4b2b08dc9e6ca,reason=Completed count=1 msg=Job completed
0.2089,Event,ADDED,eval-sanitize-30-r0-044-8ljxn.18d4b0bbb4737762,"reason=FailedScheduling count=None msg=0/6 nodes are available: 6 node(s) had untolerated taint(s). no new claims to deallocate, preemption: 0/6 nodes are available: 6 Preemption is not helpful for scheduling."
0.2091,Event,ADDED,eval-sanitize-30-r0-044-8ljxn.18d4b0be4de893c7,"reason=FailedScheduling count=None msg=0/6 nodes are available: 1 c_wall violated: 1 conflicting context pair(s) with node memory, 5 node(s) had untolerated taint(s). no new claims to deallocate, preemption: 0/6 nodes are available: 1 No preemption victims found for incoming pod, 5 Preemption is not helpful for scheduling."
0.2092,Event,ADDED,eval-sanitize-30-r0-044-8ljxn.18d4b0be84b44a7c,"reason=FailedScheduling count=None msg=0/6 nodes are available: 2 c_wall violated: 1 conflicting context pair(s) with node memory, 4 node(s) had untolerated taint(s). no new claims to deallocate, preemption: 0/6 nodes are available: 2 No preemption victims found for incoming pod, 4 Preemption is not helpful for scheduling."
0.2094,Event,ADDED,eval-sanitize-30-r0-044-8ljxn.18d4b0bebb9129d1,reason=Scheduled count=None msg=Successfully assigned compute/eval-sanitize-30-r0-044-8ljxn to kind-worker5
0.2095,Event,ADDED,eval-sanitize-30-r0-044-8ljxn.18d4b0bedbbdc83d,"reason=Pulled count=1 msg=Container image ""busybox:musl"" already present on machine"
0.2097,Event,ADDED,eval-sanitize-30-r0-044-8ljxn.18d4b0bedd7a0e40,reason=Created count=1 msg=Created container: task
0.2099,Event,ADDED,eval-sanitize-30-r0-044-8ljxn.18d4b0bee11ab8cf,reason=Started count=1 msg=Started container task
0.21,Event,ADDED,eval-sanitize-30-r0-044-sf2bm.18d4b2aa05e08f00,reason=Scheduled count=None msg=Successfully assigned compute/eval-sanitize-30-r0-044-sf2bm to kind-worker
0.2102,Event,ADDED,eval-sanitize-30-r0-044-sf2bm.18d4b2aa288c2ff8,"reason=Pulled count=1 msg=Container image ""busybox:musl"" already present on machine"
0.2104,Event,ADDED,eval-sanitize-30-r0-044-sf2bm.18d4b2aa29a03796,reason=Created count=1 msg=Created container: task
0.2106,Event,ADDED,eval-sanitize-30-r0-044-sf2bm.18d4b2aa2e7e1a84,reason=Started count=1 msg=Started container task
0.2107,Event,ADDED,eval-sanitize-30-r0-044.18d4b0bbb4655d37,reason=SuccessfulCreate count=1 msg=Created pod: eval-sanitize-30-r0-044-8ljxn
0.2109,Event,ADDED,eval-sanitize-30-r0-044.18d4b0c697e1b83b,reason=Completed count=1 msg=Job completed
0.2111,Event,ADDED,eval-sanitize-30-r0-044.18d4b2a9fa624000,reason=SuccessfulCreate count=1 msg=Created pod: eval-sanitize-30-r0-044-sf2bm
0.2112,Event,ADDED,eval-sanitize-30-r0-044.18d4b2b09d154d31,reason=Completed count=1 msg=Job completed
0.2114,Event,ADDED,eval-sanitize-30-r0-045-9xddh.18d4b2aa3b3568a8,"reason=FailedScheduling count=None msg=0/6 nodes are available: 1 c_wall violated: 2 conflicting context pair(s) with node memory, 2 node(s) had untolerated taint(s), 3 c_wall violated: 1 conflicting context pair(s) with node memory. no new claims to deallocate, preemption: 0/6 nodes are available: 2 Preemption is not helpful for scheduling, 4 No preemption victims found for incoming pod."
0.2116,Event,ADDED,eval-sanitize-30-r0-045-9xddh.18d4b2aa468f21b8,"reason=FailedScheduling count=None msg=0/6 nodes are available: 1 c_wall violated: 2 conflicting context pair(s) with node memory, 2 node(s) had untolerated taint(s), 3 c_wall violated: 1 conflicting context pair(s) with node memory. no new claims to deallocate, preemption: 0/6 nodes are available: 2 Preemption is not helpful for scheduling, 4 No preemption victims found for incoming pod."
0.2117,Event,ADDED,eval-sanitize-30-r0-045-9xddh.18d4b2b0957ad811,"reason=FailedScheduling count=None msg=0/6 nodes are available: 2 c_wall violated: 1 conflicting context pair(s) with node memory, 4 node(s) had untolerated taint(s). no new claims to deallocate, preemption: 0/6 nodes are available: 2 No preemption victims found for incoming pod, 4 Preemption is not helpful for scheduling."
0.2118,Event,ADDED,eval-sanitize-30-r0-045-9xddh.18d4b2b0c657fe5d,reason=Scheduled count=None msg=Successfully assigned compute/eval-sanitize-30-r0-045-9xddh to kind-worker4
0.2121,Event,ADDED,eval-sanitize-30-r0-045-9xddh.18d4b2b0e6501ac6,"reason=Pulled count=1 msg=Container image ""busybox:musl"" already present on machine"
0.2122,Event,ADDED,eval-sanitize-30-r0-045-9xddh.18d4b2b0e82e1693,reason=Created count=1 msg=Created container: task
0.2124,Event,ADDED,eval-sanitize-30-r0-045-9xddh.18d4b2b0faff71da,reason=Started count=1 msg=Started container task
0.2125,Event,ADDED,eval-sanitize-30-r0-045-ghkbl.18d4b0bbf057f972,"reason=FailedScheduling count=None msg=0/6 nodes are available: 6 node(s) had untolerated taint(s). no new claims to deallocate, preemption: 0/6 nodes are available: 6 Preemption is not helpful for scheduling."
0.2127,Event,ADDED,eval-sanitize-30-r0-045-ghkbl.18d4b0be4fd8d21c,"reason=FailedScheduling count=None msg=0/6 nodes are available: 1 c_wall violated: 1 conflicting context pair(s) with node memory, 5 node(s) had untolerated taint(s). no new claims to deallocate, preemption: 0/6 nodes are available: 1 No preemption victims found for incoming pod, 5 Preemption is not helpful for scheduling."
0.2128,Event,ADDED,eval-sanitize-30-r0-045-ghkbl.18d4b0be869043a5,reason=Scheduled count=None msg=Successfully assigned compute/eval-sanitize-30-r0-045-ghkbl to kind-worker2
0.213,Event,ADDED,eval-sanitize-30-r0-045-ghkbl.18d4b0bea2adc7bf,"reason=Pulled count=1 msg=Container image ""busybox:musl"" already present on machine"
0.2132,Event,ADDED,eval-sanitize-30-r0-045-ghkbl.18d4b0bea433642c,reason=Created count=1 msg=Created container: task
0.2133,Event,ADDED,eval-sanitize-30-r0-045-ghkbl.18d4b0beaac2d241,reason=Started count=1 msg=Started container task
0.2135,Event,ADDED,eval-sanitize-30-r0-045.18d4b0bbf04d2425,reason=SuccessfulCreate count=1 msg=Created pod: eval-sanitize-30-r0-045-ghkbl
0.2137,Event,ADDED,eval-sanitize-30-r0-045.18d4b0c5f3fe7987,reason=Completed count=1 msg=Job completed
0.2138,Event,ADDED,eval-sanitize-30-r0-045.18d4b2aa39b89960,reason=SuccessfulCreate count=1 msg=Created pod: eval-sanitize-30-r0-045-9xddh
0.214,Event,ADDED,eval-sanitize-30-r0-045.18d4b2b668d0cf80,reason=Completed count=1 msg=Job completed
0.2141,Event,ADDED,eval-sanitize-30-r0-046-9mxkg.18d4b0bc2d9b9bc2,"reason=FailedScheduling count=None msg=0/6 nodes are available: 6 node(s) had untolerated taint(s). no new claims to deallocate, preemption: 0/6 nodes are available: 6 Preemption is not helpful for scheduling."
0.2143,Event,ADDED,eval-sanitize-30-r0-046-9mxkg.18d4b0be507d648f,"reason=FailedScheduling count=None msg=0/6 nodes are available: 1 c_wall violated: 1 conflicting context pair(s) with node memory, 5 node(s) had untolerated taint(s). no new claims to deallocate, preemption: 0/6 nodes are available: 1 No preemption victims found for incoming pod, 5 Preemption is not helpful for scheduling."
0.2144,Event,ADDED,eval-sanitize-30-r0-046-9mxkg.18d4b0be8a991705,"reason=FailedScheduling count=None msg=0/6 nodes are available: 1 c_wall violated: 1 conflicting context pair(s) with node memory, 1 c_wall violated: 2 conflicting context pair(s) with node memory, 4 node(s) had untolerated taint(s). no new claims to deallocate, preemption: 0/6 nodes are available: 2 No preemption victims found for incoming pod, 4 Preemption is not helpful for scheduling."
0.2146,Event,ADDED,eval-sanitize-30-r0-046-9mxkg.18d4b0bed2f9c889,reason=Scheduled count=None msg=Successfully assigned compute/eval-sanitize-30-r0-046-9mxkg to kind-worker3
0.2148,Event,ADDED,eval-sanitize-30-r0-046-9mxkg.18d4b0beee70b452,"reason=Pulled count=1 msg=Container image ""busybox:musl"" already present on machine"
0.2149,Event,ADDED,eval-sanitize-30-r0-046-9mxkg.18d4b0beefbc2b32,reason=Created count=1 msg=Created container: task
0.2151,Event,ADDED,eval-sanitize-30-r0-046-9mxkg.18d4b0bef325ba45,reason=Started count=1 msg=Started container task
0.2152,Event,ADDED,eval-sanitize-30-r0-046-mxzmd.18d4b2aa7694c8cf,reason=Scheduled count=None msg=Successfully assigned compute/eval-sanitize-30-r0-046-mxzmd to kind-worker3
0.2154,Event,ADDED,eval-sanitize-30-r0-046-mxzmd.18d4b2aa9324389e,"reason=Pulled count=1 msg=Container image ""busybox:musl"" already present on machine"
0.2156,Event,ADDED,eval-sanitize-30-r0-046-mxzmd.18d4b2aa942ccdd6,reason=Created count=1 msg=Created container: task
0.2157,Event,ADDED,eval-sanitize-30-r0-046-mxzmd.18d4b2aa97af319d,reason=Started count=1 msg=Started container task
0.2159,Event,ADDED,eval-sanitize-30-r0-046.18d4b0bc2d90cdff,reason=SuccessfulCreate count=1 msg=Created pod: eval-sanitize-30-r0-046-9mxkg
0.2161,Event,ADDED,eval-sanitize-30-r0-046.18d4b0c6872072ea,reason=Completed count=1 msg=Job completed
0.2162,Event,ADDED,eval-sanitize-30-r0-046.18d4b2aa71b428a0,reason=SuccessfulCreate count=1 msg=Created pod: eval-sanitize-30-r0-046-mxzmd
0.2164,Event,ADDED,eval-sanitize-30-r0-046.18d4b2b0acebdc7b,reason=Completed count=1 msg=Job completed
0.2165,Event,ADDED,eval-sanitize-30-r0-047-8lkxb.18d4b0bc6963e255,"reason=FailedScheduling count=None msg=0/6 nodes are available: 6 node(s) had untolerated taint(s). no new claims to deallocate, preemption: 0/6 nodes are available: 6 Preemption is not helpful for scheduling."
0.2167,Event,ADDED,eval-sanitize-30-r0-047-8lkxb.18d4b0be519ff9b1,reason=Scheduled count=None msg=Successfully assigned compute/eval-sanitize-30-r0-047-8lkxb to kind-worker
0.2169,Event,ADDED,eval-sanitize-30-r0-047-8lkxb.18d4b0be6b11cd68,"reason=Pulled count=1 msg=Container image ""busybox:musl"" already present on machine"
0.217,Event,ADDED,eval-sanitize-30-r0-047-8lkxb.18d4b0be6c283154,reason=Created count=1 msg=Created container: task
0.2172,Event,ADDED,eval-sanitize-30-r0-047-8lkxb.18d4b0be6f60f80d,reason=Started count=1 msg=Started container task
0.2173,Event,ADDED,eval-sanitize-30-r0-047-vpcp2.18d4b2aab230ef5b,reason=Scheduled count=None msg=Successfully assigned compute/eval-sanitize-30-r0-047-vpcp2 to kind-worker3
0.2175,Event,ADDED,eval-sanitize-30-r0-047-vpcp2.18d4b2aaccc61f6e,"reason=Pulled count=1 msg=Container image ""busybox:musl"" already present on machine"
0.2177,Event,ADDED,eval-sanitize-30-r0-047-vpcp2.18d4b2aacdcfabcf,reason=Created count=1 msg=Created container: task
0.2178,Event,ADDED,eval-sanitize-30-r0-047-vpcp2.18d4b2aad1bcfd75,reason=Started count=1 msg=Started container task
0.218,Event,ADDED,eval-sanitize-30-r0-047.18d4b0bc69583d1c,reason=SuccessfulCreate count=1 msg=Created pod: eval-sanitize-30-r0-047-8lkxb
0.2182,Event,ADDED,eval-sanitize-30-r0-047.18d4b0c3bc5ee641,reason=Completed count=1 msg=Job completed
0.2183,Event,ADDED,eval-sanitize-30-r0-047.18d4b2aaad5ca67a,reason=SuccessfulCreate count=1 msg=Created pod: eval-sanitize-30-r0-047-vpcp2
0.2185,Event,ADDED,eval-sanitize-30-r0-047.18d4b2b0d0811515,reason=Completed count=1 msg=Job completed
0.2187,Event,ADDED,eval-sanitize-30-r0-048-25dp5.18d4b0bca2e4eac9,"reason=FailedScheduling count=None msg=0/6 nodes are available: 6 node(s) had untolerated taint(s). no new claims to deallocate, preemption: 0/6 nodes are available: 6 Preemption is not helpful for scheduling."
0.2188,Event,ADDED,eval-sanitize-30-r0-048-25dp5.18d4b0be517939f7,"reason=FailedScheduling count=None msg=0/6 nodes are available: 1 c_wall violated: 1 conflicting context pair(s) with node memory, 5 node(s) had untolerated taint(s). no new claims to deallocate, preemption: 0/6 nodes are available: 1 No preemption victims found for incoming pod, 5 Preemption is not helpful for scheduling."
0.219,Event,ADDED,eval-sanitize-30-r0-048-25dp5.18d4b0be8b6dc08d,"reason=FailedScheduling count=None msg=0/6 nodes are available: 2 c_wall violated: 1 conflicting context pair(s) with node memory, 4 node(s) had untolerated taint(s). no new claims to deallocate, preemption: 0/6 nodes are available: 2 No preemption victims found for incoming pod, 4 Preemption is not helpful for scheduling."
0.2191,Event,ADDED,eval-sanitize-30-r0-048-25dp5.18d4b0bedbddc34a,reason=Scheduled count=None msg=Successfully assigned compute/eval-sanitize-30-r0-048-25dp5 to kind-worker5
0.2193,Event,ADDED,eval-sanitize-30-r0-048-25dp5.18d4b0bef43429c6,"reason=Pulled count=1 msg=Container image ""busybox:musl"" already present on machine"
0.2195,Event,ADDED,eval-sanitize-30-r0-048-25dp5.18d4b0bef5537423,reason=Created count=1 msg=Created container: task
0.2197,Event,ADDED,eval-sanitize-30-r0-048-25dp5.18d4b0bef7f545d7,reason=Started count=1 msg=Started container task
0.2198,Event,ADDED,eval-sanitize-30-r0-048-7g6fh.18d4b2aaed885cdb,"reason=FailedScheduling count=None msg=0/6 nodes are available: 1 c_wall violated: 1 conflicting context pair(s) with node memory, 1 c_wall violated: 3 conflicting context pair(s) with node memory, 2 c_wall violated: 2 conflicting context pair(s) with node memory, 2 node(s) had untolerated taint(s). no new claims to deallocate, preemption: 0/6 nodes are available: 2 Preemption is not helpful for scheduling, 4 No preemption victims found for incoming pod."
0.22,Event,ADDED,eval-sanitize-30-r0-048-7g6fh.18d4b2aaf37e9253,"reason=FailedScheduling count=None msg=0/6 nodes are available: 1 c_wall violated: 1 conflicting context pair(s) with node memory, 1 c_wall violated: 3 conflicting context pair(s) with node memory, 2 c_wall violated: 2 conflicting context pair(s) with node memory, 2 node(s) had untolerated taint(s). no new claims to deallocate, preemption: 0/6 nodes are available: 2 Preemption is not helpful for scheduling, 4 No preemption victims found for incoming pod."
0.2202,Event,ADDED,eval-sanitize-30-r0-048-7g6fh.18d4b2ac473bfda5,"reason=FailedScheduling count=None msg=0/6 nodes are available: 1 c_wall violated: 1 conflicting context pair(s) with node memory, 1 c_wall violated: 2 conflicting context pair(s) with node memory, 2 c_wall violated: 3 conflicting context pair(s) with node memory, 2 node(s) had untolerated taint(s). no new claims to deallocate, preemption: 0/6 nodes are available: 2 Preemption is not helpful for scheduling, 4 No preemption victims found for incoming pod."
0.2204,Event,ADDED,eval-sanitize-30-r0-048-7g6fh.18d4b2af77ad26ac,"reason=FailedScheduling count=None msg=0/6 nodes are available: 2 c_wall violated: 2 conflicting context pair(s) with node memory, 2 c_wall violated: 3 conflicting context pair(s) with node memory, 2 node(s) had untolerated taint(s). no new claims to deallocate, preemption: 0/6 nodes are available: 2 Preemption is not helpful for scheduling, 4 No preemption victims found for incoming pod."
0.2206,Event,ADDED,eval-sanitize-30-r0-048-7g6fh.18d4b2b0c03b77c0,"reason=FailedScheduling count=None msg=0/6 nodes are available: 1 c_wall violated: 2 conflicting context pair(s) with node memory, 1 c_wall violated: 3 conflicting context pair(s) with node memory, 4 node(s) had untolerated taint(s). no new claims to deallocate, preemption: 0/6 nodes are available: 2 No preemption victims found for incoming pod, 4 Preemption is not helpful for scheduling."
0.2207,Event,ADDED,eval-sanitize-30-r0-048-7g6fh.18d4b2b0df785263,"reason=FailedScheduling count=None msg=0/6 nodes are available: 1 c_wall violated: 2 conflicting context pair(s) with node memory, 5 node(s) had untolerated taint(s). no new claims to deallocate, preemption: 0/6 nodes are available: 1 No preemption victims found for incoming pod, 5 Preemption is not helpful for scheduling."
0.2209,Event,ADDED,eval-sanitize-30-r0-048-7g6fh.18d4b2b0ea6f853f,"reason=FailedScheduling count=None msg=0/6 nodes are available: 1 c_wall violated: 2 conflicting context pair(s) with node memory, 5 node(s) had untolerated taint(s). no new claims to deallocate, preemption: 0/6 nodes are available: 1 No preemption victims found for incoming pod, 5 Preemption is not helpful for scheduling."
0.2211,Event,ADDED,eval-sanitize-30-r0-048-7g6fh.18d4b2b366b60cc0,"reason=FailedScheduling count=None msg=0/6 nodes are available: 1 c_wall violated: 3 conflicting context pair(s) with node memory, 5 node(s) had untolerated taint(s). no new claims to deallocate, preemption: 0/6 nodes are available: 1 No preemption victims found for incoming pod, 5 Preemption is not helpful for scheduling."
0.2212,Event,ADDED,eval-sanitize-30-r0-048-7g6fh.18d4b2b7e4f0879e,"reason=FailedScheduling count=None msg=0/6 nodes are available: 1 c_wall violated: 1 conflicting context pair(s) with node memory, 2 c_wall violated: 2 conflicting context pair(s) with node memory, 3 node(s) had untolerated taint(s). no new claims to deallocate, preemption: 0/6 nodes are available: 3 No preemption victims found for incoming pod, 3 Preemption is not helpful for scheduling."
0.2214,Event,ADDED,eval-sanitize-30-r0-048-7g6fh.18d4b2b8158faba1,reason=Scheduled count=None msg=Successfully assigned compute/eval-sanitize-30-r0-048-7g6fh to kind-worker3
0.2215,Event,ADDED,eval-sanitize-30-r0-048-7g6fh.18d4b2b830d032b9,"reason=Pulled count=1 msg=Container image ""busybox:musl"" already present on machine"
0.2217,Event,ADDED,eval-sanitize-30-r0-048-7g6fh.18d4b2b833142b5b,reason=Created count=1 msg=Created container: task
0.2219,Event,ADDED,eval-sanitize-30-r0-048-7g6fh.18d4b2b8465b1916,reason=Started count=1 msg=Started container task
0.222,Event,ADDED,eval-sanitize-30-r0-048.18d4b0bca2da7e28,reason=SuccessfulCreate count=1 msg=Created pod: eval-sanitize-30-r0-048-25dp5
0.2222,Event,ADDED,eval-sanitize-30-r0-048.18d4b0c6afa85e6e,reason=Completed count=1 msg=Job completed
0.2224,Event,ADDED,eval-sanitize-30-r0-048.18d4b2aae9745a3a,reason=SuccessfulCreate count=1 msg=Created pod: eval-sanitize-30-r0-048-7g6fh
0.2225,Event,ADDED,eval-sanitize-30-r0-048.18d4b2bf6dc7a98b,reason=Completed count=1 msg=Job completed
0.2227,Event,ADDED,eval-sanitize-30-r0-049-c4trm.18d4b2ab252bf726,"reason=FailedScheduling count=None msg=0/6 nodes are available: 1 c_wall violated: 1 conflicting context pair(s) with node memory, 1 c_wall violated: 3 conflicting context pair(s) with node memory, 2 c_wall violated: 2 conflicting context pair(s) with node memory, 2 node(s) had untolerated taint(s). no new claims to deallocate, preemption: 0/6 nodes are available: 2 Preemption is not helpful for scheduling, 4 No preemption victims found for incoming pod."
0.2229,Event,ADDED,eval-sanitize-30-r0-049-c4trm.18d4b2ab2931d25f,"reason=FailedScheduling count=None msg=0/6 nodes are available: 1 c_wall violated: 1 conflicting context pair(s) with node memory, 1 c_wall violated: 3 conflicting context pair(s) with node memory, 2 c_wall violated: 2 conflicting context pair(s) with node memory, 2 node(s) had untolerated taint(s). no new claims to deallocate, preemption: 0/6 nodes are available: 2 Preemption is not helpful for scheduling, 4 No preemption victims found for incoming pod."
0.223,Event,ADDED,eval-sanitize-30-r0-049-c4trm.18d4b2ac350bc652,"reason=FailedScheduling count=None msg=0/6 nodes are available: 1 c_wall violated: 1 conflicting context pair(s) with node memory, 1 c_wall violated: 2 conflicting context pair(s) with node memory, 2 c_wall violated: 3 conflicting context pair(s) with node memory, 2 node(s) had untolerated taint(s). no new claims to deallocate, preemption: 0/6 nodes are available: 2 Preemption is not helpful for scheduling, 4 No preemption victims found for incoming pod."
0.2232,Event,ADDED,eval-sanitize-30-r0-049-c4trm.18d4b2af7d74116a,"reason=FailedScheduling count=None msg=0/6 nodes are available: 2 c_wall violated: 2 conflicting context pair(s) with node memory, 2 c_wall violated: 3 conflicting context pair(s) with node memory, 2 node(s) had untolerated taint(s). no new claims to deallocate, preemption: 0/6 nodes are available: 2 Preemption is not helpful for scheduling, 4 No preemption victims found for incoming pod."
0.2234,Event,ADDED,eval-sanitize-30-r0-049-c4trm.18d4b2b0949d9909,"reason=FailedScheduling count=None msg=0/6 nodes are available: 2 c_wall violated: 3 conflicting context pair(s) with node memory, 4 node(s) had untolerated taint(s). no new claims to deallocate, preemption: 0/6 nodes are available: 2 No preemption victims found for incoming pod, 4 Preemption is not helpful for scheduling."
0.2235,Event,ADDED,eval-sanitize-30-r0-049-c4trm.18d4b2b0c0d5e278,"reason=FailedScheduling count=None msg=0/6 nodes are available: 1 c_wall violated: 2 conflicting context pair(s) with node memory, 1 c_wall violated: 3 conflicting context pair(s) with node memory, 4 node(s) had untolerated taint(s). no new claims to deallocate, preemption: 0/6 nodes are available: 2 No preemption victims found for incoming pod, 4 Preemption is not helpful for scheduling."
0.2237,Event,ADDED,eval-sanitize-30-r0-049-c4trm.18d4b2b0e02b5e78,"reason=FailedScheduling count=None msg=0/6 nodes are available: 1 c_wall violated: 2 conflicting context pair(s) with node memory, 5 node(s) had untolerated taint(s). no new claims to deallocate, preemption: 0/6 nodes are available: 1 No preemption victims found for incoming pod, 5 Preemption is not helpful for scheduling."
0.2238,Event,ADDED,eval-sanitize-30-r0-049-c4trm.18d4b2b0edba8e46,"reason=FailedScheduling count=None msg=0/6 nodes are available: 1 c_wall violated: 2 conflicting context pair(s) with node memory, 5 node(s) had untolerated taint(s). no new claims to deallocate, preemption: 0/6 nodes are available: 1 No preemption victims found for incoming pod, 5 Preemption is not helpful for scheduling."
0.224,Event,ADDED,eval-sanitize-30-r0-049-c4trm.18d4b2b366e10553,"reason=FailedScheduling count=None msg=0/6 nodes are available: 1 c_wall violated: 3 conflicting context pair(s) with node memory, 5 node(s) had untolerated taint(s). no new claims to deallocate, preemption: 0/6 nodes are available: 1 No preemption victims found for incoming pod, 5 Preemption is not helpful for scheduling."
0.2242,Event,ADDED,eval-sanitize-30-r0-049-c4trm.18d4b2b7eaeab033,"reason=FailedScheduling count=None msg=0/6 nodes are available: 1 c_wall violated: 1 conflicting context pair(s) with node memory, 2 c_wall violated: 2 conflicting context pair(s) with node memory, 3 node(s) had untolerated taint(s). no new claims to deallocate, preemption: 0/6 nodes are available: 3 No preemption victims found for incoming pod, 3 Preemption is not helpful for scheduling."
0.2243,Event,ADDED,eval-sanitize-30-r0-049-c4trm.18d4b2b81b542653,reason=Scheduled count=None msg=Successfully assigned compute/eval-sanitize-30-r0-049-c4trm to kind-worker3
0.2245,Event,ADDED,eval-sanitize-30-r0-049-c4trm.18d4b2b8465e85e7,"reason=Pulled count=1 msg=Container image ""busybox:musl"" already present on machine"
0.2247,Event,ADDED,eval-sanitize-30-r0-049-c4trm.18d4b2b8482a75b1,reason=Created count=1 msg=Created container: task
0.2248,Event,ADDED,eval-sanitize-30-r0-049-c4trm.18d4b2b84f110a30,reason=Started count=1 msg=Started container task
0.225,Event,ADDED,eval-sanitize-30-r0-049-sxrcc.18d4b0bcdf3f626e,"reason=FailedScheduling count=None msg=0/6 nodes are available: 6 node(s) had untolerated taint(s). no new claims to deallocate, preemption: 0/6 nodes are available: 6 Preemption is not helpful for scheduling."
0.2251,Event,ADDED,eval-sanitize-30-r0-049-sxrcc.18d4b0be55af24b2,reason=Scheduled count=None msg=Successfully assigned compute/eval-sanitize-30-r0-049-sxrcc to kind-worker2
0.2253,Event,ADDED,eval-sanitize-30-r0-049-sxrcc.18d4b0be6f049fd3,"reason=Pulled count=1 msg=Container image ""busybox:musl"" already present on machine"
0.2255,Event,ADDED,eval-sanitize-30-r0-049-sxrcc.18d4b0be70338d6a,reason=Created count=1 msg=Created container: task
0.2257,Event,ADDED,eval-sanitize-30-r0-049-sxrcc.18d4b0be74fcd803,reason=Started count=1 msg=Started container task
0.2259,Event,ADDED,eval-sanitize-30-r0-049.18d4b0bcdf30194f,reason=SuccessfulCreate count=1 msg=Created pod: eval-sanitize-30-r0-049-sxrcc
0.2261,Event,ADDED,eval-sanitize-30-r0-049.18d4b0c3bbf42e5d,reason=Completed count=1 msg=Job completed
0.2263,Event,ADDED,eval-sanitize-30-r0-049.18d4b2ab2445a99e,reason=SuccessfulCreate count=1 msg=Created pod: eval-sanitize-30-r0-049-c4trm
0.2264,Event,ADDED,eval-sanitize-30-r0-049.18d4b2bf7bba386e,reason=Completed count=1 msg=Job completed
0.2266,Event,ADDED,eval-sanitize-30-r0-050-72czk.18d4b0bd1a06c3b2,"reason=FailedScheduling count=None msg=0/6 nodes are available: 6 node(s) had untolerated taint(s). no new claims to deallocate, preemption: 0/6 nodes are available: 6 Preemption is not helpful for scheduling."
0.2267,Event,ADDED,eval-sanitize-30-r0-050-72czk.18d4b0be570cd718,"reason=FailedScheduling count=None msg=0/6 nodes are available: 1 c_wall violated: 1 conflicting context pair(s) with node memory, 1 c_wall violated: 2 conflicting context pair(s) with node memory, 4 node(s) had untolerated taint(s). no new claims to deallocate, preemption: 0/6 nodes are available: 2 No preemption victims found for incoming pod, 4 Preemption is not helpful for scheduling."
0.2269,Event,ADDED,eval-sanitize-30-r0-050-72czk.18d4b0be8c2e02dc,"reason=FailedScheduling count=None msg=0/6 nodes are available: 2 c_wall violated: 2 conflicting context pair(s) with node memory, 4 node(s) had untolerated taint(s). no new claims to deallocate, preemption: 0/6 nodes are available: 2 No preemption victims found for incoming pod, 4 Preemption is not helpful for scheduling."
0.227,Event,ADDED,eval-sanitize-30-r0-050-72czk.18d4b0bee01a7268,reason=Scheduled count=None msg=Successfully assigned compute/eval-sanitize-30-r0-050-72czk to kind-worker3
0.2272,Event,ADDED,eval-sanitize-30-r0-050-72czk.18d4b0bef66ff9da,"reason=Pulled count=1 msg=Container image ""busybox:musl"" already present on machine"
0.2274,Event,ADDED,eval-sanitize-30-r0-050-72czk.18d4b0bef84fedcf,reason=Created count=1 msg=Created container: task
0.2275,Event,ADDED,eval-sanitize-30-r0-050-72czk.18d4b0bf01349208,reason=Started count=1 msg=Started container task
0.2277,Event,ADDED,eval-sanitize-30-r0-050-jsj4r.18d4b2ab6891caa3,reason=Scheduled count=None msg=Successfully assigned compute/eval-sanitize-30-r0-050-jsj4r to kind-worker3
0.2279,Event,ADDED,eval-sanitize-30-r0-050-jsj4r.18d4b2ab81cd4a06,"reason=Pulled count=1 msg=Container image ""busybox:musl"" already present on machine"
0.228,Event,ADDED,eval-sanitize-30-r0-050-jsj4r.18d4b2ab82db7d02,reason=Created count=1 msg=Created container: task
0.2282,Event,ADDED,eval-sanitize-30-r0-050-jsj4r.18d4b2ab8b1162f8,reason=Started count=1 msg=Started container task
0.2284,Event,ADDED,eval-sanitize-30-r0-050.18d4b0bd19fec106,reason=SuccessfulCreate count=1 msg=Created pod: eval-sanitize-30-r0-050-72czk
0.2286,Event,ADDED,eval-sanitize-30-r0-050.18d4b0c66c6a101b,reason=Completed count=1 msg=Job completed
0.2287,Event,ADDED,eval-sanitize-30-r0-050.18d4b2ab5fbbb8e1,reason=SuccessfulCreate count=1 msg=Created pod: eval-sanitize-30-r0-050-jsj4r
0.2292,Event,ADDED,eval-sanitize-30-r0-050.18d4b2b115c54bc2,reason=Completed count=1 msg=Job completed
0.2295,Event,ADDED,eval-sanitize-30-r0-051-kjk7h.18d4b0bd55b2a125,"reason=FailedScheduling count=None msg=0/6 nodes are available: 6 node(s) had untolerated taint(s). no new claims to deallocate, preemption: 0/6 nodes are available: 6 Preemption is not helpful for scheduling."
0.2297,Event,ADDED,eval-sanitize-30-r0-051-kjk7h.18d4b0be5a96a1d8,"reason=FailedScheduling count=None msg=0/6 nodes are available: 2 c_wall violated: 1 conflicting context pair(s) with node memory, 4 node(s) had untolerated taint(s). no new claims to deallocate, preemption: 0/6 nodes are available: 2 No preemption victims found for incoming pod, 4 Preemption is not helpful for scheduling."
0.2301,Event,ADDED,eval-sanitize-30-r0-051-kjk7h.18d4b0be90bc5edd,"reason=FailedScheduling count=None msg=0/6 nodes are available: 1 c_wall violated: 1 conflicting context pair(s) with node memory, 1 c_wall violated: 2 conflicting context pair(s) with node memory, 4 node(s) had untolerated taint(s). no new claims to deallocate, preemption: 0/6 nodes are available: 2 No preemption victims found for incoming pod, 4 Preemption is not helpful for scheduling."
0.2303,Event,ADDED,eval-sanitize-30-r0-051-kjk7h.18d4b0bee75072af,reason=Scheduled count=None msg=Successfully assigned compute/eval-sanitize-30-r0-051-kjk7h to kind-worker3
0.2305,Event,ADDED,eval-sanitize-30-r0-051-kjk7h.18d4b0bf070398b5,"reason=Pulled count=1 msg=Container image ""busybox:musl"" already present on machine"
0.2307,Event,ADDED,eval-sanitize-30-r0-051-kjk7h.18d4b0bf084c6096,reason=Created count=1 msg=Created container: task
0.231,Event,ADDED,eval-sanitize-30-r0-051-kjk7h.18d4b0bf0abfe1f4,reason=Started count=1 msg=Started container task
0.2312,Event,ADDED,eval-sanitize-30-r0-051-lfcjx.18d4b2aba6094675,"reason=FailedScheduling count=None msg=0/6 nodes are available: 1 c_wall violated: 1 conflicting context pair(s) with node memory, 1 c_wall violated: 3 conflicting context pair(s) with node memory, 2 c_wall violated: 2 conflicting context pair(s) with node memory, 2 node(s) had untolerated taint(s). no new claims to deallocate, preemption: 0/6 nodes are available: 2 Preemption is not helpful for scheduling, 4 No preemption victims found for incoming pod."
0.2314,Event,ADDED,eval-sanitize-30-r0-051-lfcjx.18d4b2abbe1d72c0,"reason=FailedScheduling count=None msg=0/6 nodes are available: 1 c_wall violated: 1 conflicting context pair(s) with node memory, 1 c_wall violated: 3 conflicting context pair(s) with node memory, 2 c_wall violated: 2 conflicting context pair(s) with node memory, 2 node(s) had untolerated taint(s). no new claims to deallocate, preemption: 0/6 nodes are available: 2 Preemption is not helpful for scheduling, 4 No preemption victims found for incoming pod."
0.2318,Event,ADDED,eval-sanitize-30-r0-051-lfcjx.18d4b2ac3b9228e4,"reason=FailedScheduling count=None msg=0/6 nodes are available: 1 c_wall violated: 1 conflicting context pair(s) with node memory, 1 c_wall violated: 2 conflicting context pair(s) with node memory, 2 c_wall violated: 3 conflicting context pair(s) with node memory, 2 node(s) had untolerated taint(s). no new claims to deallocate, preemption: 0/6 nodes are available: 2 Preemption is not helpful for scheduling, 4 No preemption victims found for incoming pod."
0.232,Event,ADDED,eval-sanitize-30-r0-051-lfcjx.18d4b2af60589208,"reason=FailedScheduling count=None msg=0/6 nodes are available: 2 c_wall violated: 2 conflicting context pair(s) with node memory, 2 c_wall violated: 3 conflicting context pair(s) with node memory, 2 node(s) had untolerated taint(s). no new claims to deallocate, preemption: 0/6 nodes are available: 2 Preemption is not helpful for scheduling, 4 No preemption victims found for incoming pod."
0.2324,Event,ADDED,eval-sanitize-30-r0-051-lfcjx.18d4b2b0ae9c3494,"reason=FailedScheduling count=None msg=0/6 nodes are available: 1 c_wall violated: 1 conflicting context pair(s) with node memory, 2 c_wall violated: 3 conflicting context pair(s) with node memory, 3 node(s) had untolerated taint(s). no new claims to deallocate, preemption: 0/6 nodes are available: 3 No preemption victims found for incoming pod, 3 Preemption is not helpful for scheduling."
0.2326,Event,ADDED,eval-sanitize-30-r0-051-lfcjx.18d4b2b0dd6880f1,"reason=FailedScheduling count=None msg=0/6 nodes are available: 1 c_wall violated: 2 conflicting context pair(s) with node memory, 1 c_wall violated: 3 conflicting context pair(s) with node memory, 4 node(s) had untolerated taint(s). no new claims to deallocate, preemption: 0/6 nodes are available: 2 No preemption victims found for incoming pod, 4 Preemption is not helpful for scheduling."
0.2327,Event,ADDED,eval-sanitize-30-r0-051-lfcjx.18d4b2b0e98fab1f,"reason=FailedScheduling count=None msg=0/6 nodes are available: 1 c_wall violated: 2 conflicting context pair(s) with node memory, 5 node(s) had untolerated taint(s). no new claims to deallocate, preemption: 0/6 nodes are available: 1 No preemption victims found for incoming pod, 5 Preemption is not helpful for scheduling."
0.2332,Event,ADDED,eval-sanitize-30-r0-051-lfcjx.18d4b2b0ef72be4b,"reason=FailedScheduling count=None msg=0/6 nodes are available: 1 c_wall violated: 2 conflicting context pair(s) with node memory, 5 node(s) had untolerated taint(s). no new claims to deallocate, preemption: 0/6 nodes are available: 1 No preemption victims found for incoming pod, 5 Preemption is not helpful for scheduling."
0.2334,Event,ADDED,eval-sanitize-30-r0-051-lfcjx.18d4b2b3615c0521,"reason=FailedScheduling count=None msg=0/6 nodes are available: 1 c_wall violated: 3 conflicting context pair(s) with node memory, 5 node(s) had untolerated taint(s). no new claims to deallocate, preemption: 0/6 nodes are available: 1 No preemption victims found for incoming pod, 5 Preemption is not helpful for scheduling."
0.2336,Event,ADDED,eval-sanitize-30-r0-051-lfcjx.18d4b2b7d31545d8,"reason=FailedScheduling count=None msg=0/6 nodes are available: 1 c_wall violated: 1 conflicting context pair(s) with node memory, 2 c_wall violated: 2 conflicting context pair(s) with node memory, 3 node(s) had untolerated taint(s). no new claims to deallocate, preemption: 0/6 nodes are available: 3 No preemption victims found for incoming pod, 3 Preemption is not helpful for scheduling."
0.2339,Event,ADDED,eval-sanitize-30-r0-051-lfcjx.18d4b2b80976e62c,reason=Scheduled count=None msg=Successfully assigned compute/eval-sanitize-30-r0-051-lfcjx to kind-worker3
0.2341,Event,ADDED,eval-sanitize-30-r0-051-lfcjx.18d4b2b828849255,"reason=Pulled count=1 msg=Container image ""busybox:musl"" already present on machine"
0.2343,Event,ADDED,eval-sanitize-30-r0-051-lfcjx.18d4b2b82a9c3f43,reason=Created count=1 msg=Created container: task
0.2345,Event,ADDED,eval-sanitize-30-r0-051-lfcjx.18d4b2b82f5bf410,reason=Started count=1 msg=Started container task
0.2348,Event,ADDED,eval-sanitize-30-r0-051.18d4b0bd55a78da2,reason=SuccessfulCreate count=1 msg=Created pod: eval-sanitize-30-r0-051-kjk7h
0.235,Event,ADDED,eval-sanitize-30-r0-051.18d4b0c686f6a071,reason=Completed count=1 msg=Job completed
0.2352,Event,ADDED,eval-sanitize-30-r0-051.18d4b2ab9dcf07ae,reason=SuccessfulCreate count=1 msg=Created pod: eval-sanitize-30-r0-051-lfcjx
0.2354,Event,ADDED,eval-sanitize-30-r0-051.18d4b2bf877410c6,reason=Completed count=1 msg=Job completed
0.2357,Event,ADDED,eval-sanitize-30-r0-052-85j6l.18d4b0bd91b41ddf,"reason=FailedScheduling count=None msg=0/6 nodes are available: 6 node(s) had untolerated taint(s). no new claims to deallocate, preemption: 0/6 nodes are available: 6 Preemption is not helpful for scheduling."
0.2359,Event,ADDED,eval-sanitize-30-r0-052-85j6l.18d4b0be5cfbd3c1,"reason=FailedScheduling count=None msg=0/6 nodes are available: 2 c_wall violated: 1 conflicting context pair(s) with node memory, 4 node(s) had untolerated taint(s). no new claims to deallocate, preemption: 0/6 nodes are available: 2 No preemption victims found for incoming pod, 4 Preemption is not helpful for scheduling."
0.2361,Event,ADDED,eval-sanitize-30-r0-052-85j6l.18d4b0be929ecda1,"reason=FailedScheduling count=None msg=0/6 nodes are available: 1 c_wall violated: 1 conflicting context pair(s) with node memory, 1 c_wall violated: 2 conflicting context pair(s) with node memory, 4 node(s) had untolerated taint(s). no new claims to deallocate, preemption: 0/6 nodes are available: 2 No preemption victims found for incoming pod, 4 Preemption is not helpful for scheduling."
0.2364,Event,ADDED,eval-sanitize-30-r0-052-85j6l.18d4b0bef054221c,reason=Scheduled count=None msg=Successfully assigned compute/eval-sanitize-30-r0-052-85j6l to kind-worker4
0.2366,Event,ADDED,eval-sanitize-30-r0-052-85j6l.18d4b0bf09e09a17,"reason=Pulled count=1 msg=Container image ""busybox:musl"" already present on machine"
0.2368,Event,ADDED,eval-sanitize-30-r0-052-85j6l.18d4b0bf0b58bb3d,reason=Created count=1 msg=Created container: task
0.237,Event,ADDED,eval-sanitize-30-r0-052-85j6l.18d4b0bf1286515f,reason=Started count=1 msg=Started container task
0.2372,Event,ADDED,eval-sanitize-30-r0-052-dk54r.18d4b2abdcde3fd0,reason=Scheduled count=None msg=Successfully assigned compute/eval-sanitize-30-r0-052-dk54r to kind-worker
0.2373,Event,ADDED,eval-sanitize-30-r0-052-dk54r.18d4b2abf82302bd,"reason=Pulled count=1 msg=Container image ""busybox:musl"" already present on machine"
0.2376,Event,ADDED,eval-sanitize-30-r0-052-dk54r.18d4b2abf93d465c,reason=Created count=1 msg=Created container: task
0.2378,Event,ADDED,eval-sanitize-30-r0-052-dk54r.18d4b2abfda15a4b,reason=Started count=1 msg=Started container task
0.238,Event,ADDED,eval-sanitize-30-r0-052.18d4b0bd91a98333,reason=SuccessfulCreate count=1 msg=Created pod: eval-sanitize-30-r0-052-85j6l
0.2382,Event,ADDED,eval-sanitize-30-r0-052.18d4b0c658c04a30,reason=Completed count=1 msg=Job completed
0.2383,Event,ADDED,eval-sanitize-30-r0-052.18d4b2abdb3ef331,reason=SuccessfulCreate count=1 msg=Created pod: eval-sanitize-30-r0-052-dk54r
0.2385,Event,ADDED,eval-sanitize-30-r0-052.18d4b2b194b29509,reason=Completed count=1 msg=Job completed
0.2386,Event,ADDED,eval-sanitize-30-r0-053-fnmxp.18d4b0bdcdbc5473,"reason=FailedScheduling count=None msg=0/6 nodes are available: 6 node(s) had untolerated taint(s). no new claims to deallocate, preemption: 0/6 nodes are available: 6 Preemption is not helpful for scheduling."
0.2388,Event,ADDED,eval-sanitize-30-r0-053-fnmxp.18d4b0be5e8135a4,reason=Scheduled count=None msg=Successfully assigned compute/eval-sanitize-30-r0-053-fnmxp to kind-worker2
0.239,Event,ADDED,eval-sanitize-30-r0-053-fnmxp.18d4b0be7bf26226,"reason=Pulled count=1 msg=Container image ""busybox:musl"" already present on machine"
0.2391,Event,ADDED,eval-sanitize-30-r0-053-fnmxp.18d4b0be7f1f657f,reason=Created count=1 msg=Created container: task
0.2393,Event,ADDED,eval-sanitize-30-r0-053-fnmxp.18d4b0be83a52c2b,reason=Started count=1 msg=Started container task
0.2394,Event,ADDED,eval-sanitize-30-r0-053-h6m2d.18d4b2ac175ec6c0,reason=Scheduled count=None msg=Successfully assigned compute/eval-sanitize-30-r0-053-h6m2d to kind-worker3
0.2396,Event,ADDED,eval-sanitize-30-r0-053-h6m2d.18d4b2ac32d6b26a,"reason=Pulled count=1 msg=Container image ""busybox:musl"" already present on machine"
0.2398,Event,ADDED,eval-sanitize-30-r0-053-h6m2d.18d4b2ac33e32f0b,reason=Created count=1 msg=Created container: task
0.2399,Event,ADDED,eval-sanitize-30-r0-053-h6m2d.18d4b2ac36e0802f,reason=Started count=1 msg=Started container task
0.2401,Event,ADDED,eval-sanitize-30-r0-053.18d4b0bdcdb0b8b1,reason=SuccessfulCreate count=1 msg=Created pod: eval-sanitize-30-r0-053-fnmxp
0.2404,Event,ADDED,eval-sanitize-30-r0-053.18d4b0c3bbed88e5,reason=Completed count=1 msg=Job completed
0.2405,Event,ADDED,eval-sanitize-30-r0-053.18d4b2ac1302753a,reason=SuccessfulCreate count=1 msg=Created pod: eval-sanitize-30-r0-053-h6m2d
0.2407,Event,ADDED,eval-sanitize-30-r0-053.18d4b2b17cb6b3ee,reason=Completed count=1 msg=Job completed
0.2409,Event,ADDED,eval-sanitize-30-r0-054-jzf5l.18d4b2ac5943c017,reason=Scheduled count=None msg=Successfully assigned compute/eval-sanitize-30-r0-054-jzf5l to kind-worker3
0.241,Event,ADDED,eval-sanitize-30-r0-054-jzf5l.18d4b2ac7273be62,"reason=Pulled count=1 msg=Container image ""busybox:musl"" already present on machine"
0.2412,Event,ADDED,eval-sanitize-30-r0-054-jzf5l.18d4b2ac73875d4e,reason=Created count=1 msg=Created container: task
0.2414,Event,ADDED,eval-sanitize-30-r0-054-jzf5l.18d4b2ac75964dca,reason=Started count=1 msg=Started container task
0.2415,Event,ADDED,eval-sanitize-30-r0-054-nlq7t.18d4b0be08a9eaba,"reason=FailedScheduling count=None msg=0/6 nodes are available: 6 node(s) had untolerated taint(s). no new claims to deallocate, preemption: 0/6 nodes are available: 6 Preemption is not helpful for scheduling."
0.2417,Event,ADDED,eval-sanitize-30-r0-054-nlq7t.18d4b0be63c43adb,reason=Scheduled count=None msg=Successfully assigned compute/eval-sanitize-30-r0-054-nlq7t to kind-worker2
0.2418,Event,ADDED,eval-sanitize-30-r0-054-nlq7t.18d4b0be82fb6f4e,"reason=Pulled count=1 msg=Container image ""busybox:musl"" already present on machine"
0.242,Event,ADDED,eval-sanitize-30-r0-054-nlq7t.18d4b0be85e3dfdd,reason=Created count=1 msg=Created container: task
0.2422,Event,ADDED,eval-sanitize-30-r0-054-nlq7t.18d4b0be8a688456,reason=Started count=1 msg=Started container task
0.2423,Event,ADDED,eval-sanitize-30-r0-054.18d4b0be089a87e6,reason=SuccessfulCreate count=1 msg=Created pod: eval-sanitize-30-r0-054-nlq7t
0.2425,Event,ADDED,eval-sanitize-30-r0-054.18d4b0c606216a74,reason=Completed count=1 msg=Job completed
0.2427,Event,ADDED,eval-sanitize-30-r0-054.18d4b2ac50e5e517,reason=SuccessfulCreate count=1 msg=Created pod: eval-sanitize-30-r0-054-jzf5l
0.2428,Event,ADDED,eval-sanitize-30-r0-054.18d4b2b1fb45bb3f,reason=Completed count=1 msg=Job completed
0.243,Event,ADDED,eval-sanitize-30-r0-055-6wnbm.18d4b0be616417e8,reason=Scheduled count=None msg=Successfully assigned compute/eval-sanitize-30-r0-055-6wnbm to kind-worker2
0.2431,Event,ADDED,eval-sanitize-30-r0-055-6wnbm.18d4b0be83bb7826,"reason=Pulled count=1 msg=Container image ""busybox:musl"" already present on machine"
0.2433,Event,ADDED,eval-sanitize-30-r0-055-6wnbm.18d4b0be86666270,reason=Created count=1 msg=Created container: task
0.2435,Event,ADDED,eval-sanitize-30-r0-055-6wnbm.18d4b0be8a64afe8,reason=Started count=1 msg=Started container task
0.2436,Event,ADDED,eval-sanitize-30-r0-055-smwjg.18d4b2ac93483496,"reason=FailedScheduling count=None msg=0/6 nodes are available: 1 c_wall violated: 1 conflicting context pair(s) with node memory, 1 c_wall violated: 2 conflicting context pair(s) with node memory, 2 c_wall violated: 3 conflicting context pair(s) with node memory, 2 node(s) had untolerated taint(s). no new claims to deallocate, preemption: 0/6 nodes are available: 2 Preemption is not helpful for scheduling, 4 No preemption victims found for incoming pod."
0.2438,Event,ADDED,eval-sanitize-30-r0-055-smwjg.18d4b2aca67bf39c,"reason=FailedScheduling count=None msg=0/6 nodes are available: 1 c_wall violated: 1 conflicting context pair(s) with node memory, 1 c_wall violated: 2 conflicting context pair(s) with node memory, 2 c_wall violated: 3 conflicting context pair(s) with node memory, 2 node(s) had untolerated taint(s). no new claims to deallocate, preemption: 0/6 nodes are available: 2 Preemption is not helpful for scheduling, 4 No preemption victims found for incoming pod."
0.244,Event,ADDED,eval-sanitize-30-r0-055-smwjg.18d4b2af6c5948de,"reason=FailedScheduling count=None msg=0/6 nodes are available: 2 c_wall violated: 2 conflicting context pair(s) with node memory, 2 c_wall violated: 3 conflicting context pair(s) with node memory, 2 node(s) had untolerated taint(s). no new claims to deallocate, preemption: 0/6 nodes are available: 2 Preemption is not helpful for scheduling, 4 No preemption victims found for incoming pod."
0.2442,Event,ADDED,eval-sanitize-30-r0-055-smwjg.18d4b2b0b979193c,"reason=FailedScheduling count=None msg=0/6 nodes are available: 1 c_wall violated: 2 conflicting context pair(s) with node memory, 2 c_wall violated: 3 conflicting context pair(s) with node memory, 3 node(s) had untolerated taint(s). no new claims to deallocate, preemption: 0/6 nodes are available: 3 No preemption victims found for incoming pod, 3 Preemption is not helpful for scheduling."
0.2443,Event,ADDED,eval-sanitize-30-r0-055-smwjg.18d4b2b0de24e900,"reason=FailedScheduling count=None msg=0/6 nodes are available: 1 c_wall violated: 2 conflicting context pair(s) with node memory, 5 node(s) had untolerated taint(s). no new claims to deallocate, preemption: 0/6 nodes are available: 1 No preemption victims found for incoming pod, 5 Preemption is not helpful for scheduling."
0.2445,Event,ADDED,eval-sanitize-30-r0-055-smwjg.18d4b2b0ea1bc378,"reason=FailedScheduling count=None msg=0/6 nodes are available: 1 c_wall violated: 2 conflicting context pair(s) with node memory, 5 node(s) had untolerated taint(s). no new claims to deallocate, preemption: 0/6 nodes are available: 1 No preemption victims found for incoming pod, 5 Preemption is not helpful for scheduling."
0.2447,Event,ADDED,eval-sanitize-30-r0-055-smwjg.18d4b2b3617fb9ca,"reason=FailedScheduling count=None msg=0/6 nodes are available: 1 c_wall violated: 3 conflicting context pair(s) with node memory, 5 node(s) had untolerated taint(s). no new claims to deallocate, preemption: 0/6 nodes are available: 1 No preemption victims found for incoming pod, 5 Preemption is not helpful for scheduling."
0.2448,Event,ADDED,eval-sanitize-30-r0-055-smwjg.18d4b2b7d48eef6d,"reason=FailedScheduling count=None msg=0/6 nodes are available: 1 c_wall violated: 1 conflicting context pair(s) with node memory, 2 c_wall violated: 2 conflicting context pair(s) with node memory, 3 node(s) had untolerated taint(s). no new claims to deallocate, preemption: 0/6 nodes are available: 3 No preemption victims found for incoming pod, 3 Preemption is not helpful for scheduling."
0.245,Event,ADDED,eval-sanitize-30-r0-055-smwjg.18d4b2b809f1c02e,reason=Scheduled count=None msg=Successfully assigned compute/eval-sanitize-30-r0-055-smwjg to kind-worker3
0.2452,Event,ADDED,eval-sanitize-30-r0-055-smwjg.18d4b2b828b007bc,"reason=Pulled count=1 msg=Container image ""busybox:musl"" already present on machine"
0.2454,Event,ADDED,eval-sanitize-30-r0-055-smwjg.18d4b2b82b2633d8,reason=Created count=1 msg=Created container: task
0.2455,Event,ADDED,eval-sanitize-30-r0-055-smwjg.18d4b2b8300a3dfc,reason=Started count=1 msg=Started container task
0.2457,Event,ADDED,eval-sanitize-30-r0-055.18d4b0be46227440,reason=SuccessfulCreate count=1 msg=Created pod: eval-sanitize-30-r0-055-6wnbm
0.2459,Event,ADDED,eval-sanitize-30-r0-055.18d4b0c64c233a24,reason=Completed count=1 msg=Job completed
0.2462,Event,ADDED,eval-sanitize-30-r0-055.18d4b2ac8bb643d6,reason=SuccessfulCreate count=1 msg=Created pod: eval-sanitize-30-r0-055-smwjg
0.2463,Event,ADDED,eval-sanitize-30-r0-055.18d4b2bf8d628263,reason=Completed count=1 msg=Job completed
0.2465,Event,ADDED,eval-sanitize-30-r0-056-nj42m.18d4b2accafa7ce3,reason=Scheduled count=None msg=Successfully assigned compute/eval-sanitize-30-r0-056-nj42m to kind-worker3
0.2467,Event,ADDED,eval-sanitize-30-r0-056-nj42m.18d4b2ace678cfd6,"reason=Pulled count=1 msg=Container image ""busybox:musl"" already present on machine"
0.2469,Event,ADDED,eval-sanitize-30-r0-056-nj42m.18d4b2ace8050bc9,reason=Created count=1 msg=Created container: task
0.2471,Event,ADDED,eval-sanitize-30-r0-056-nj42m.18d4b2acee2518bc,reason=Started count=1 msg=Started container task
0.2472,Event,ADDED,eval-sanitize-30-r0-056-rm5xs.18d4b0be8573de82,"reason=FailedScheduling count=None msg=0/6 nodes are available: 1 c_wall violated: 1 conflicting context pair(s) with node memory, 1 c_wall violated: 2 conflicting context pair(s) with node memory, 4 node(s) had untolerated taint(s). no new claims to deallocate, preemption: 0/6 nodes are available: 2 No preemption victims found for incoming pod, 4 Preemption is not helpful for scheduling."
0.2474,Event,ADDED,eval-sanitize-30-r0-056-rm5xs.18d4b0bec6b9664a,reason=Scheduled count=None msg=Successfully assigned compute/eval-sanitize-30-r0-056-rm5xs to kind-worker5
0.2476,Event,ADDED,eval-sanitize-30-r0-056-rm5xs.18d4b0bee74b718a,"reason=Pulled count=1 msg=Container image ""busybox:musl"" already present on machine"
0.2477,Event,ADDED,eval-sanitize-30-r0-056-rm5xs.18d4b0bee928b54a,reason=Created count=1 msg=Created container: task
0.2479,Event,ADDED,eval-sanitize-30-r0-056-rm5xs.18d4b0beed729cc9,reason=Started count=1 msg=Started container task
0.2481,Event,ADDED,eval-sanitize-30-r0-056.18d4b0be810181a3,reason=SuccessfulCreate count=1 msg=Created pod: eval-sanitize-30-r0-056-rm5xs
0.2482,Event,ADDED,eval-sanitize-30-r0-056.18d4b0c6af8ebfd6,reason=Completed count=1 msg=Job completed
0.2484,Event,ADDED,eval-sanitize-30-r0-056.18d4b2acc5a73747,reason=SuccessfulCreate count=1 msg=Created pod: eval-sanitize-30-r0-056-nj42m
0.2486,Event,ADDED,eval-sanitize-30-r0-056.18d4b2b2699780bf,reason=Completed count=1 msg=Job completed
0.2487,Event,ADDED,eval-sanitize-30-r0-057-6h4ht.18d4b0beccdaa618,reason=Scheduled count=None msg=Successfully assigned compute/eval-sanitize-30-r0-057-6h4ht to kind-worker
0.2489,Event,ADDED,eval-sanitize-30-r0-057-6h4ht.18d4b0bee7683255,"reason=Pulled count=1 msg=Container image ""busybox:musl"" already present on machine"
0.249,Event,ADDED,eval-sanitize-30-r0-057-6h4ht.18d4b0bee9440697,reason=Created count=1 msg=Created container: task
0.2497,Event,ADDED,eval-sanitize-30-r0-057-6h4ht.18d4b0beed870a9b,reason=Started count=1 msg=Started container task
0.25,Event,ADDED,eval-sanitize-30-r0-057-kq86w.18d4b2ad0f3bf61e,reason=Scheduled count=None msg=Successfully assigned compute/eval-sanitize-30-r0-057-kq86w to kind-worker3
0.2502,Event,ADDED,eval-sanitize-30-r0-057-kq86w.18d4b2ad3396764e,"reason=Pulled count=1 msg=Container image ""busybox:musl"" already present on machine"
0.2506,Event,ADDED,eval-sanitize-30-r0-057-kq86w.18d4b2ad34ba6c28,reason=Created count=1 msg=Created container: task
0.2508,Event,ADDED,eval-sanitize-30-r0-057-kq86w.18d4b2ad41f1b4fc,reason=Started count=1 msg=Started container task
0.2509,Event,ADDED,eval-sanitize-30-r0-057.18d4b0bebbacfb15,reason=SuccessfulCreate count=1 msg=Created pod: eval-sanitize-30-r0-057-6h4ht
0.2511,Event,ADDED,eval-sanitize-30-r0-057.18d4b0c5e88625ce,reason=Completed count=1 msg=Job completed
0.2514,Event,ADDED,eval-sanitize-30-r0-057.18d4b2ad00e896e4,reason=SuccessfulCreate count=1 msg=Created pod: eval-sanitize-30-r0-057-kq86w
0.2516,Event,ADDED,eval-sanitize-30-r0-057.18d4b2b2e2ffe663,reason=Completed count=1 msg=Job completed
0.2518,Event,ADDED,eval-sanitize-30-r0-058-8zhvb.18d4b0bf0868b639,reason=Scheduled count=None msg=Successfully assigned compute/eval-sanitize-30-r0-058-8zhvb to kind-worker3
0.2519,Event,ADDED,eval-sanitize-30-r0-058-8zhvb.18d4b0bf229bb87b,"reason=Pulled count=1 msg=Container image ""busybox:musl"" already present on machine"
0.2522,Event,ADDED,eval-sanitize-30-r0-058-8zhvb.18d4b0bf23f6108e,reason=Created count=1 msg=Created container: task
0.2523,Event,ADDED,eval-sanitize-30-r0-058-8zhvb.18d4b0bf2a30017d,reason=Started count=1 msg=Started container task
0.2525,Event,ADDED,eval-sanitize-30-r0-058-jm4mg.18d4b2ad44e0b266,"reason=FailedScheduling count=None msg=0/6 nodes are available: 1 c_wall violated: 2 conflicting context pair(s) with node memory, 2 node(s) had untolerated taint(s), 3 c_wall violated: 1 conflicting context pair(s) with node memory. no new claims to deallocate, preemption: 0/6 nodes are available: 2 Preemption is not helpful for scheduling, 4 No preemption victims found for incoming pod."
0.2527,Event,ADDED,eval-sanitize-30-r0-058-jm4mg.18d4b2ad479cebb0,"reason=FailedScheduling count=None msg=0/6 nodes are available: 1 c_wall violated: 2 conflicting context pair(s) with node memory, 2 node(s) had untolerated taint(s), 3 c_wall violated: 1 conflicting context pair(s) with node memory. no new claims to deallocate, preemption: 0/6 nodes are available: 2 Preemption is not helpful for scheduling, 4 No preemption victims found for incoming pod."
0.2528,Event,ADDED,eval-sanitize-30-r0-058-jm4mg.18d4b2b09ab372a7,"reason=FailedScheduling count=None msg=0/6 nodes are available: 2 c_wall violated: 1 conflicting context pair(s) with node memory, 4 node(s) had untolerated taint(s). no new claims to deallocate, preemption: 0/6 nodes are available: 2 No preemption victims found for incoming pod, 4 Preemption is not helpful for scheduling."
0.253,Event,ADDED,eval-sanitize-30-r0-058-jm4mg.18d4b2b0c67b08b5,reason=Scheduled count=None msg=Successfully assigned compute/eval-sanitize-30-r0-058-jm4mg to kind-worker4
0.2532,Event,ADDED,eval-sanitize-30-r0-058-jm4mg.18d4b2b0e67d340d,"reason=Pulled count=1 msg=Container image ""busybox:musl"" already present on machine"
0.2533,Event,ADDED,eval-sanitize-30-r0-058-jm4mg.18d4b2b0e886824c,reason=Created count=1 msg=Created container: task
0.2535,Event,ADDED,eval-sanitize-30-r0-058-jm4mg.18d4b2b0fafac2e8,reason=Started count=1 msg=Started container task
0.2537,Event,ADDED,eval-sanitize-30-r0-058.18d4b0bef8f3716a,reason=SuccessfulCreate count=1 msg=Created pod: eval-sanitize-30-r0-058-8zhvb
0.2538,Event,ADDED,eval-sanitize-30-r0-058.18d4b0c6d65428e8,reason=Completed count=1 msg=Job completed
0.254,Event,ADDED,eval-sanitize-30-r0-058.18d4b2ad43edc04c,reason=SuccessfulCreate count=1 msg=Created pod: eval-sanitize-30-r0-058-jm4mg
0.2542,Event,ADDED,eval-sanitize-30-r0-058.18d4b2b668d1e77b,reason=Completed count=1 msg=Job completed
0.2543,Event,ADDED,eval-sanitize-30-r0-059-kns9j.18d4b2ad95070cf8,"reason=FailedScheduling count=None msg=0/6 nodes are available: 1 c_wall violated: 1 conflicting context pair(s) with node memory, 1 c_wall violated: 2 conflicting context pair(s) with node memory, 2 c_wall violated: 3 conflicting context pair(s) with node memory, 2 node(s) had untolerated taint(s). no new claims to deallocate, preemption: 0/6 nodes are available: 2 Preemption is not helpful for scheduling, 4 No preemption victims found for incoming pod."
0.2546,Event,ADDED,eval-sanitize-30-r0-059-kns9j.18d4b2ada0c9d1ab,"reason=FailedScheduling count=None msg=0/6 nodes are available: 1 c_wall violated: 1 conflicting context pair(s) with node memory, 1 c_wall violated: 2 conflicting context pair(s) with node memory, 2 c_wall violated: 3 conflicting context pair(s) with node memory, 2 node(s) had untolerated taint(s). no new claims to deallocate, preemption: 0/6 nodes are available: 2 Preemption is not helpful for scheduling, 4 No preemption victims found for incoming pod."
0.2548,Event,ADDED,eval-sanitize-30-r0-059-kns9j.18d4b2af8993b273,"reason=FailedScheduling count=None msg=0/6 nodes are available: 2 c_wall violated: 2 conflicting context pair(s) with node memory, 2 c_wall violated: 3 conflicting context pair(s) with node memory, 2 node(s) had untolerated taint(s). no new claims to deallocate, preemption: 0/6 nodes are available: 2 Preemption is not helpful for scheduling, 4 No preemption victims found for incoming pod."
0.2549,Event,ADDED,eval-sanitize-30-r0-059-kns9j.18d4b2b0a08be1c7,"reason=FailedScheduling count=None msg=0/6 nodes are available: 1 c_wall violated: 1 conflicting context pair(s) with node memory, 2 c_wall violated: 3 conflicting context pair(s) with node memory, 3 node(s) had untolerated taint(s). no new claims to deallocate, preemption: 0/6 nodes are available: 3 No preemption victims found for incoming pod, 3 Preemption is not helpful for scheduling."
0.2551,Event,ADDED,eval-sanitize-30-r0-059-kns9j.18d4b2b0cb243c20,"reason=FailedScheduling count=None msg=0/6 nodes are available: 1 c_wall violated: 2 conflicting context pair(s) with node memory, 1 c_wall violated: 3 conflicting context pair(s) with node memory, 4 node(s) had untolerated taint(s). no new claims to deallocate, preemption: 0/6 nodes are available: 2 No preemption victims found for incoming pod, 4 Preemption is not helpful for scheduling."
0.2552,Event,ADDED,eval-sanitize-30-r0-059-kns9j.18d4b2b0e6d2bbeb,"reason=FailedScheduling count=None msg=0/6 nodes are available: 1 c_wall violated: 2 conflicting context pair(s) with node memory, 5 node(s) had untolerated taint(s). no new claims to deallocate, preemption: 0/6 nodes are available: 1 No preemption victims found for incoming pod, 5 Preemption is not helpful for scheduling."
0.2554,Event,ADDED,eval-sanitize-30-r0-059-kns9j.18d4b2b0eed9020b,"reason=FailedScheduling count=None msg=0/6 nodes are available: 1 c_wall violated: 2 conflicting context pair(s) with node memory, 5 node(s) had untolerated taint(s). no new claims to deallocate, preemption: 0/6 nodes are available: 1 No preemption victims found for incoming pod, 5 Preemption is not helpful for scheduling."
0.2556,Event,ADDED,eval-sanitize-30-r0-059-kns9j.18d4b2b360b57200,"reason=FailedScheduling count=None msg=0/6 nodes are available: 1 c_wall violated: 3 conflicting context pair(s) with node memory, 5 node(s) had untolerated taint(s). no new claims to deallocate, preemption: 0/6 nodes are available: 1 No preemption victims found for incoming pod, 5 Preemption is not helpful for scheduling."
0.2557,Event,ADDED,eval-sanitize-30-r0-059-kns9j.18d4b2b7fcfcfdbc,"reason=FailedScheduling count=None msg=0/6 nodes are available: 1 c_wall violated: 1 conflicting context pair(s) with node memory, 2 c_wall violated: 2 conflicting context pair(s) with node memory, 3 node(s) had untolerated taint(s). no new claims to deallocate, preemption: 0/6 nodes are available: 3 No preemption victims found for incoming pod, 3 Preemption is not helpful for scheduling."
0.2559,Event,ADDED,eval-sanitize-30-r0-059-kns9j.18d4b2b828875174,reason=Scheduled count=None msg=Successfully assigned compute/eval-sanitize-30-r0-059-kns9j to kind-worker3
0.2561,Event,ADDED,eval-sanitize-30-r0-059-kns9j.18d4b2b84f15b9fe,"reason=Pulled count=1 msg=Container image ""busybox:musl"" already present on machine"
0.2562,Event,ADDED,eval-sanitize-30-r0-059-kns9j.18d4b2b850e012e1,reason=Created count=1 msg=Created container: task
0.2564,Event,ADDED,eval-sanitize-30-r0-059-kns9j.18d4b2b854acf659,reason=Started count=1 msg=Started container task
0.2565,Event,ADDED,eval-sanitize-30-r0-059-psvjr.18d4b0bf40cccdaa,reason=Scheduled count=None msg=Successfully assigned compute/eval-sanitize-30-r0-059-psvjr to kind-worker
0.2567,Event,ADDED,eval-sanitize-30-r0-059-psvjr.18d4b0bf609725ab,"reason=Pulled count=1 msg=Container image ""busybox:musl"" already present on machine"
0.2569,Event,ADDED,eval-sanitize-30-r0-059-psvjr.18d4b0bf61bcdee7,reason=Created count=1 msg=Created container: task
0.2571,Event,ADDED,eval-sanitize-30-r0-059-psvjr.18d4b0bf706fb344,reason=Started count=1 msg=Started container task
0.2572,Event,ADDED,eval-sanitize-30-r0-059.18d4b0bf36d4e3c8,reason=SuccessfulCreate count=1 msg=Created pod: eval-sanitize-30-r0-059-psvjr
0.2574,Event,ADDED,eval-sanitize-30-r0-059.18d4b0c6df0b2a87,reason=Completed count=1 msg=Job completed
0.2575,Event,ADDED,eval-sanitize-30-r0-059.18d4b2ad78316fe0,reason=SuccessfulCreate count=1 msg=Created pod: eval-sanitize-30-r0-059-kns9j
0.2577,Event,ADDED,eval-sanitize-30-r0-059.18d4b2bf7bb8ceea,reason=Completed count=1 msg=Job completed
0.2579,Event,ADDED,eval-sanitize-30-r0-060-lspq9.18d4b2adb54da274,"reason=FailedScheduling count=None msg=0/6 nodes are available: 2 node(s) had untolerated taint(s), 4 c_wall violated: 1 conflicting context pair(s) with node memory. no new claims to deallocate, preemption: 0/6 nodes are available: 2 Preemption is not helpful for scheduling, 4 No preemption victims found for incoming pod."
0.2581,Event,ADDED,eval-sanitize-30-r0-060-lspq9.18d4b2adb8ee673c,"reason=FailedScheduling count=None msg=0/6 nodes are available: 2 node(s) had untolerated taint(s), 4 c_wall violated: 1 conflicting context pair(s) with node memory. no new claims to deallocate, preemption: 0/6 nodes are available: 2 Preemption is not helpful for scheduling, 4 No preemption victims found for incoming pod."
0.2582,Event,ADDED,eval-sanitize-30-r0-060-lspq9.18d4b2b0a69b8b66,"reason=FailedScheduling count=None msg=0/6 nodes are available: 3 c_wall violated: 1 conflicting context pair(s) with node memory, 3 node(s) had untolerated taint(s). no new claims to deallocate, preemption: 0/6 nodes are available: 3 No preemption victims found for incoming pod, 3 Preemption is not helpful for scheduling."
0.2583,Event,ADDED,eval-sanitize-30-r0-060-lspq9.18d4b2b0d199dea3,"reason=FailedScheduling count=None msg=0/6 nodes are available: 2 c_wall violated: 1 conflicting context pair(s) with node memory, 4 node(s) had untolerated taint(s). no new claims to deallocate, preemption: 0/6 nodes are available: 2 No preemption victims found for incoming pod, 4 Preemption is not helpful for scheduling."
0.2585,Event,ADDED,eval-sanitize-30-r0-060-lspq9.18d4b2b0e838bfcf,"reason=FailedScheduling count=None msg=0/6 nodes are available: 1 c_wall violated: 1 conflicting context pair(s) with node memory, 5 node(s) had untolerated taint(s). no new claims to deallocate, preemption: 0/6 nodes are available: 1 No preemption victims found for incoming pod, 5 Preemption is not helpful for scheduling."
0.2587,Event,ADDED,eval-sanitize-30-r0-060-lspq9.18d4b2b0ef215f07,"reason=FailedScheduling count=None msg=0/6 nodes are available: 1 c_wall violated: 1 conflicting context pair(s) with node memory, 5 node(s) had untolerated taint(s). no new claims to deallocate, preemption: 0/6 nodes are available: 1 No preemption victims found for incoming pod, 5 Preemption is not helpful for scheduling."
0.2588,Event,ADDED,eval-sanitize-30-r0-060-lspq9.18d4b2b778fd7d59,reason=Scheduled count=None msg=Successfully assigned compute/eval-sanitize-30-r0-060-lspq9 to kind-worker2
0.259,Event,ADDED,eval-sanitize-30-r0-060-lspq9.18d4b2b793fc84d1,"reason=Pulled count=1 msg=Container image ""busybox:musl"" already present on machine"
0.2592,Event,ADDED,eval-sanitize-30-r0-060-lspq9.18d4b2b7962a5670,reason=Created count=1 msg=Created container: task
0.2594,Event,ADDED,eval-sanitize-30-r0-060-lspq9.18d4b2b799ed908c,reason=Started count=1 msg=Started container task
0.2595,Event,ADDED,eval-sanitize-30-r0-060-nfp5p.18d4b0bf7c2a8d98,reason=Scheduled count=None msg=Successfully assigned compute/eval-sanitize-30-r0-060-nfp5p to kind-worker5
0.2597,Event,ADDED,eval-sanitize-30-r0-060-nfp5p.18d4b0bf96ed7ff6,"reason=Pulled count=1 msg=Container image ""busybox:musl"" already present on machine"
0.2599,Event,ADDED,eval-sanitize-30-r0-060-nfp5p.18d4b0bf98245bb7,reason=Created count=1 msg=Created container: task
0.26,Event,ADDED,eval-sanitize-30-r0-060-nfp5p.18d4b0bf9f53c378,reason=Started count=1 msg=Started container task
0.2602,Event,ADDED,eval-sanitize-30-r0-060.18d4b0bf72d30cce,reason=SuccessfulCreate count=1 msg=Created pod: eval-sanitize-30-r0-060-nfp5p
0.2604,Event,ADDED,eval-sanitize-30-r0-060.18d4b0c6ecdd0916,reason=Completed count=1 msg=Job completed
0.2605,Event,ADDED,eval-sanitize-30-r0-060.18d4b2adb43e1926,reason=SuccessfulCreate count=1 msg=Created pod: eval-sanitize-30-r0-060-lspq9
0.2607,Event,ADDED,eval-sanitize-30-r0-060.18d4b2bd06d68674,reason=Completed count=1 msg=Job completed
0.2609,Event,ADDED,eval-sanitize-30-r0-061-g8h9x.18d4b2adf655a7bf,reason=Scheduled count=None msg=Successfully assigned compute/eval-sanitize-30-r0-061-g8h9x to kind-worker2
0.261,Event,ADDED,eval-sanitize-30-r0-061-g8h9x.18d4b2ae13eddc93,"reason=Pulled count=1 msg=Container image ""busybox:musl"" already present on machine"
0.2613,Event,ADDED,eval-sanitize-30-r0-061-g8h9x.18d4b2ae15114fcf,reason=Created count=1 msg=Created container: task
0.2616,Event,ADDED,eval-sanitize-30-r0-061-g8h9x.18d4b2ae1a1204c1,reason=Started count=1 msg=Started container task
0.2619,Event,ADDED,eval-sanitize-30-r0-061-nhb7m.18d4b0bfaf35a5e7,reason=Scheduled count=None msg=Successfully assigned compute/eval-sanitize-30-r0-061-nhb7m to kind-worker3
0.2624,Event,ADDED,eval-sanitize-30-r0-061-nhb7m.18d4b0bfceb6e3a0,"reason=Pulled count=1 msg=Container image ""busybox:musl"" already present on machine"
0.263,Event,ADDED,eval-sanitize-30-r0-061-nhb7m.18d4b0bfd07b5c90,reason=Created count=1 msg=Created container: task
0.2631,Event,ADDED,eval-sanitize-30-r0-061-nhb7m.18d4b0bfd81a57a9,reason=Started count=1 msg=Started container task
0.2633,Event,ADDED,eval-sanitize-30-r0-061.18d4b0bfac728238,reason=SuccessfulCreate count=1 msg=Created pod: eval-sanitize-30-r0-061-nhb7m
0.2636,Event,ADDED,eval-sanitize-30-r0-061.18d4b0c7032e9fc5,reason=Completed count=1 msg=Job completed
0.2638,Event,ADDED,eval-sanitize-30-r0-061.18d4b2adf51c4f24,reason=SuccessfulCreate count=1 msg=Created pod: eval-sanitize-30-r0-061-g8h9x
0.264,Event,ADDED,eval-sanitize-30-r0-061.18d4b2b3a5a0db59,reason=Completed count=1 msg=Job completed
0.2642,Event,ADDED,eval-sanitize-30-r0-062-4xlnm.18d4b0bfec1b2cef,reason=Scheduled count=None msg=Successfully assigned compute/eval-sanitize-30-r0-062-4xlnm to kind-worker5
0.2644,Event,ADDED,eval-sanitize-30-r0-062-4xlnm.18d4b0c00fce7e9e,"reason=Pulled count=1 msg=Container image ""busybox:musl"" already present on machine"
0.2646,Event,ADDED,eval-sanitize-30-r0-062-4xlnm.18d4b0c0111c4e5f,reason=Created count=1 msg=Created container: task
0.2647,Event,ADDED,eval-sanitize-30-r0-062-4xlnm.18d4b0c0181549c6,reason=Started count=1 msg=Started container task
0.2649,Event,ADDED,eval-sanitize-30-r0-062-x7zqx.18d4b2ae4219dbf0,reason=Scheduled count=None msg=Successfully assigned compute/eval-sanitize-30-r0-062-x7zqx to kind-worker
0.265,Event,ADDED,eval-sanitize-30-r0-062-x7zqx.18d4b2ae63d81a41,"reason=Pulled count=1 msg=Container image ""busybox:musl"" already present on machine"
0.2652,Event,ADDED,eval-sanitize-30-r0-062-x7zqx.18d4b2ae652f9563,reason=Created count=1 msg=Created container: task
0.2654,Event,ADDED,eval-sanitize-30-r0-062-x7zqx.18d4b2ae7033d361,reason=Started count=1 msg=Started container task
0.2655,Event,ADDED,eval-sanitize-30-r0-062.18d4b0bfe592d17b,reason=SuccessfulCreate count=1 msg=Created pod: eval-sanitize-30-r0-062-4xlnm
0.2657,Event,ADDED,eval-sanitize-30-r0-062.18d4b0c7223a0f7d,reason=Completed count=1 msg=Job completed
0.2659,Event,ADDED,eval-sanitize-30-r0-062.18d4b2ae2f309bac,reason=SuccessfulCreate count=1 msg=Created pod: eval-sanitize-30-r0-062-x7zqx
0.2661,Event,ADDED,eval-sanitize-30-r0-062.18d4b2b3e14ea826,reason=Completed count=1 msg=Job completed
0.2662,Event,ADDED,eval-sanitize-30-r0-063-8bxgb.18d4b0c0316eff77,reason=Scheduled count=None msg=Successfully assigned compute/eval-sanitize-30-r0-063-8bxgb to kind-worker3
0.2664,Event,ADDED,eval-sanitize-30-r0-063-8bxgb.18d4b0c04fb384a8,"reason=Pulled count=1 msg=Container image ""busybox:musl"" already present on machine"
0.2665,Event,ADDED,eval-sanitize-30-r0-063-8bxgb.18d4b0c051c3b04e,reason=Created count=1 msg=Created container: task
0.2667,Event,ADDED,eval-sanitize-30-r0-063-8bxgb.18d4b0c055e79ca7,reason=Started count=1 msg=Started container task
0.2669,Event,ADDED,eval-sanitize-30-r0-063-996vn.18d4b2ae711eaace,"reason=FailedScheduling count=None msg=0/6 nodes are available: 2 node(s) had untolerated taint(s), 4 c_wall violated: 1 conflicting context pair(s) with node memory. no new claims to deallocate, preemption: 0/6 nodes are available: 2 Preemption is not helpful for scheduling, 4 No preemption victims found for incoming pod."
0.2671,Event,ADDED,eval-sanitize-30-r0-063-996vn.18d4b2aea171ce93,"reason=FailedScheduling count=None msg=0/6 nodes are available: 2 node(s) had untolerated taint(s), 4 c_wall violated: 1 conflicting context pair(s) with node memory. no new claims to deallocate, preemption: 0/6 nodes are available: 2 Preemption is not helpful for scheduling, 4 No preemption victims found for incoming pod."
0.2672,Event,ADDED,eval-sanitize-30-r0-063-996vn.18d4b2b0adbba3fe,"reason=FailedScheduling count=None msg=0/6 nodes are available: 3 c_wall violated: 1 conflicting context pair(s) with node memory, 3 node(s) had untolerated taint(s). no new claims to deallocate, preemption: 0/6 nodes are available: 3 No preemption victims found for incoming pod, 3 Preemption is not helpful for scheduling."
0.2674,Event,ADDED,eval-sanitize-30-r0-063-996vn.18d4b2b0d5ea4d80,"reason=FailedScheduling count=None msg=0/6 nodes are available: 2 c_wall violated: 1 conflicting context pair(s) with node memory, 4 node(s) had untolerated taint(s). no new claims to deallocate, preemption: 0/6 nodes are available: 2 No preemption victims found for incoming pod, 4 Preemption is not helpful for scheduling."
0.2675,Event,ADDED,eval-sanitize-30-r0-063-996vn.18d4b2b0e8f503b4,"reason=FailedScheduling count=None msg=0/6 nodes are available: 1 c_wall violated: 1 conflicting context pair(s) with node memory, 5 node(s) had untolerated taint(s). no new claims to deallocate, preemption: 0/6 nodes are available: 1 No preemption victims found for incoming pod, 5 Preemption is not helpful for scheduling."
0.2677,Event,ADDED,eval-sanitize-30-r0-063-996vn.18d4b2b0ef4306f5,"reason=FailedScheduling count=None msg=0/6 nodes are available: 1 c_wall violated: 1 conflicting context pair(s) with node memory, 5 node(s) had untolerated taint(s). no new claims to deallocate, preemption: 0/6 nodes are available: 1 No preemption victims found for incoming pod, 5 Preemption is not helpful for scheduling."
0.2679,Event,ADDED,eval-sanitize-30-r0-063-996vn.18d4b2b778fd4087,reason=Scheduled count=None msg=Successfully assigned compute/eval-sanitize-30-r0-063-996vn to kind-worker2
0.268,Event,ADDED,eval-sanitize-30-r0-063-996vn.18d4b2b79417b8c3,"reason=Pulled count=1 msg=Container image ""busybox:musl"" already present on machine"
0.2682,Event,ADDED,eval-sanitize-30-r0-063-996vn.18d4b2b79669920d,reason=Created count=1 msg=Created container: task
0.2684,Event,ADDED,eval-sanitize-30-r0-063-996vn.18d4b2b799f03847,reason=Started count=1 msg=Started container task
0.2687,Event,ADDED,eval-sanitize-30-r0-063.18d4b0c027c6422a,reason=SuccessfulCreate count=1 msg=Created pod: eval-sanitize-30-r0-063-8bxgb
0.2689,Event,ADDED,eval-sanitize-30-r0-063.18d4b0c73146affc,reason=Completed count=1 msg=Job completed
0.269,Event,ADDED,eval-sanitize-30-r0-063.18d4b2ae66e2e673,reason=SuccessfulCreate count=1 msg=Created pod: eval-sanitize-30-r0-063-996vn
0.2693,Event,ADDED,eval-sanitize-30-r0-063.18d4b2bd025d0308,reason=Completed count=1 msg=Job completed
0.2695,Event,ADDED,eval-sanitize-30-r0-064-j8td2.18d4b2aead476a87,"reason=FailedScheduling count=None msg=0/6 nodes are available: 1 c_wall violated: 2 conflicting context pair(s) with node memory, 2 node(s) had untolerated taint(s), 3 c_wall violated: 1 conflicting context pair(s) with node memory. no new claims to deallocate, preemption: 0/6 nodes are available: 2 Preemption is not helpful for scheduling, 4 No preemption victims found for incoming pod."
0.2697,Event,ADDED,eval-sanitize-30-r0-064-j8td2.18d4b2aee94fb6fc,"reason=FailedScheduling count=None msg=0/6 nodes are available: 1 c_wall violated: 2 conflicting context pair(s) with node memory, 2 node(s) had untolerated taint(s), 3 c_wall violated: 1 conflicting context pair(s) with node memory. no new claims to deallocate, preemption: 0/6 nodes are available: 2 Preemption is not helpful for scheduling, 4 No preemption victims found for incoming pod."
0.2699,Event,ADDED,eval-sanitize-30-r0-064-j8td2.18d4b2b0b9ca2317,reason=Scheduled count=None msg=Successfully assigned compute/eval-sanitize-30-r0-064-j8td2 to kind-worker4
0.2701,Event,ADDED,eval-sanitize-30-r0-064-j8td2.18d4b2b0dce658d2,"reason=Pulled count=1 msg=Container image ""busybox:musl"" already present on machine"
0.2703,Event,ADDED,eval-sanitize-30-r0-064-j8td2.18d4b2b0df67f260,reason=Created count=1 msg=Created container: task
0.2705,Event,ADDED,eval-sanitize-30-r0-064-j8td2.18d4b2b0e73506c1,reason=Started count=1 msg=Started container task
0.2706,Event,ADDED,eval-sanitize-30-r0-064-vf894.18d4b0c06695767f,reason=Scheduled count=None msg=Successfully assigned compute/eval-sanitize-30-r0-064-vf894 to kind-worker
0.2708,Event,ADDED,eval-sanitize-30-r0-064-vf894.18d4b0c08a789650,"reason=Pulled count=1 msg=Container image ""busybox:musl"" already present on machine"
0.271,Event,ADDED,eval-sanitize-30-r0-064-vf894.18d4b0c08bc79bc8,reason=Created count=1 msg=Created container: task
0.2712,Event,ADDED,eval-sanitize-30-r0-064-vf894.18d4b0c0963427e7,reason=Started count=1 msg=Started container task
0.2714,Event,ADDED,eval-sanitize-30-r0-064.18d4b0c060f2f4f9,reason=SuccessfulCreate count=1 msg=Created pod: eval-sanitize-30-r0-064-vf894
0.2715,Event,ADDED,eval-sanitize-30-r0-064.18d4b0c747ed4af7,reason=Completed count=1 msg=Job completed
0.2717,Event,ADDED,eval-sanitize-30-r0-064.18d4b2aea331b270,reason=SuccessfulCreate count=1 msg=Created pod: eval-sanitize-30-r0-064-j8td2
0.2719,Event,ADDED,eval-sanitize-30-r0-064.18d4b2b625b16790,reason=Completed count=1 msg=Job completed
0.2721,Event,ADDED,eval-sanitize-30-r0-065-plspb.18d4b0c0a5456bff,reason=Scheduled count=None msg=Successfully assigned compute/eval-sanitize-30-r0-065-plspb to kind-worker2
0.2722,Event,ADDED,eval-sanitize-30-r0-065-plspb.18d4b0c0c4e28167,"reason=Pulled count=1 msg=Container image ""busybox:musl"" already present on machine"
0.2724,Event,ADDED,eval-sanitize-30-r0-065-plspb.18d4b0c0c61db65c,reason=Created count=1 msg=Created container: task
0.2726,Event,ADDED,eval-sanitize-30-r0-065-plspb.18d4b0c0ccb9cfcc,reason=Started count=1 msg=Started container task
0.2727,Event,ADDED,eval-sanitize-30-r0-065-vgn25.18d4b2aeeb15bd36,reason=Scheduled count=None msg=Successfully assigned compute/eval-sanitize-30-r0-065-vgn25 to kind-worker3
0.2729,Event,ADDED,eval-sanitize-30-r0-065-vgn25.18d4b2af0434dc62,"reason=Pulled count=1 msg=Container image ""busybox:musl"" already present on machine"
0.273,Event,ADDED,eval-sanitize-30-r0-065-vgn25.18d4b2af05596aba,reason=Created count=1 msg=Created container: task
0.2732,Event,ADDED,eval-sanitize-30-r0-065-vgn25.18d4b2af0cd0166e,reason=Started count=1 msg=Started container task
0.2734,Event,ADDED,eval-sanitize-30-r0-065.18d4b0c0984cce31,reason=SuccessfulCreate count=1 msg=Created pod: eval-sanitize-30-r0-065-plspb
0.2735,Event,ADDED,eval-sanitize-30-r0-065.18d4b0c75c960ff1,reason=Completed count=1 msg=Job completed
0.2737,Event,ADDED,eval-sanitize-30-r0-065.18d4b2aeddb7e2f6,reason=SuccessfulCreate count=1 msg=Created pod: eval-sanitize-30-r0-065-vgn25
0.274,Event,ADDED,eval-sanitize-30-r0-065.18d4b2b47d40f4de,reason=Completed count=1 msg=Job completed
0.2742,Event,ADDED,eval-sanitize-30-r0-066-744h7.18d4b0c0d8f5e22c,reason=Scheduled count=None msg=Successfully assigned compute/eval-sanitize-30-r0-066-744h7 to kind-worker
0.2743,Event,ADDED,eval-sanitize-30-r0-066-744h7.18d4b0c0fe58c586,"reason=Pulled count=1 msg=Container image ""busybox:musl"" already present on machine"
0.2745,Event,ADDED,eval-sanitize-30-r0-066-744h7.18d4b0c0ff7ec845,reason=Created count=1 msg=Created container: task
0.2748,Event,ADDED,eval-sanitize-30-r0-066-744h7.18d4b0c10a1e8c7b,reason=Started count=1 msg=Started container task
0.2749,Event,ADDED,eval-sanitize-30-r0-066-qvctn.18d4b2af244b1b95,reason=Scheduled count=None msg=Successfully assigned compute/eval-sanitize-30-r0-066-qvctn to kind-worker2
0.2751,Event,ADDED,eval-sanitize-30-r0-066-qvctn.18d4b2af41b6bf84,"reason=Pulled count=1 msg=Container image ""busybox:musl"" already present on machine"
0.2753,Event,ADDED,eval-sanitize-30-r0-066-qvctn.18d4b2af42ef6a44,reason=Created count=1 msg=Created container: task
0.2754,Event,ADDED,eval-sanitize-30-r0-066-qvctn.18d4b2af46978387,reason=Started count=1 msg=Started container task
0.2756,Event,ADDED,eval-sanitize-30-r0-066.18d4b0c0d74e9d2e,reason=SuccessfulCreate count=1 msg=Created pod: eval-sanitize-30-r0-066-744h7
0.2758,Event,ADDED,eval-sanitize-30-r0-066.18d4b0c76ffd0c5b,reason=Completed count=1 msg=Job completed
0.276,Event,ADDED,eval-sanitize-30-r0-066.18d4b2af1b504a49,reason=SuccessfulCreate count=1 msg=Created pod: eval-sanitize-30-r0-066-qvctn
0.2761,Event,ADDED,eval-sanitize-30-r0-066.18d4b2b4db965706,reason=Completed count=1 msg=Job completed
0.2763,Event,ADDED,eval-sanitize-30-r0-067-42sxx.18d4b2afa85c9e13,reason=Scheduled count=None msg=Successfully assigned compute/eval-sanitize-30-r0-067-42sxx to kind-worker2
0.2765,Event,ADDED,eval-sanitize-30-r0-067-42sxx.18d4b2afc1d46c8b,"reason=Pulled count=1 msg=Container image ""busybox:musl"" already present on machine"
0.2768,Event,ADDED,eval-sanitize-30-r0-067-42sxx.18d4b2afc2ec6772,reason=Created count=1 msg=Created container: task
0.277,Event,ADDED,eval-sanitize-30-r0-067-42sxx.18d4b2afc4dbd8b8,reason=Started count=1 msg=Started container task
0.2771,Event,ADDED,eval-sanitize-30-r0-067-crjkq.18d4b0c11815156a,reason=Scheduled count=None msg=Successfully assigned compute/eval-sanitize-30-r0-067-crjkq to kind-worker5
0.2773,Event,ADDED,eval-sanitize-30-r0-067-crjkq.18d4b0c14313bb9a,"reason=Pulled count=1 msg=Container image ""busybox:musl"" already present on machine"
0.2775,Event,ADDED,eval-sanitize-30-r0-067-crjkq.18d4b0c14455b122,reason=Created count=1 msg=Created container: task
0.2777,Event,ADDED,eval-sanitize-30-r0-067-crjkq.18d4b0c1546d4aa1,reason=Started count=1 msg=Started container task
0.2778,Event,ADDED,eval-sanitize-30-r0-067.18d4b0c116a0a41c,reason=SuccessfulCreate count=1 msg=Created pod: eval-sanitize-30-r0-067-crjkq
0.278,Event,ADDED,eval-sanitize-30-r0-067.18d4b0c7806b9609,reason=Completed count=1 msg=Job completed
0.2782,Event,ADDED,eval-sanitize-30-r0-067.18d4b2afa603f03b,reason=SuccessfulCreate count=1 msg=Created pod: eval-sanitize-30-r0-067-42sxx
0.2784,Event,ADDED,eval-sanitize-30-r0-067.18d4b2b54d7e22c4,reason=Completed count=1 msg=Job completed
0.2785,Event,ADDED,eval-sanitize-30-r0-068-5f9pw.18d4b0c157c30ac3,reason=Scheduled count=None msg=Successfully assigned compute/eval-sanitize-30-r0-068-5f9pw to kind-worker2
0.2787,Event,ADDED,eval-sanitize-30-r0-068-5f9pw.18d4b0c17bd7871e,"reason=Pulled count=1 msg=Container image ""busybox:musl"" already present on machine"
0.2788,Event,ADDED,eval-sanitize-30-r0-068-5f9pw.18d4b0c17d10dac0,reason=Created count=1 msg=Created container: task
0.279,Event,ADDED,eval-sanitize-30-r0-068-5f9pw.18d4b0c182ee9675,reason=Started count=1 msg=Started container task
0.2792,Event,ADDED,eval-sanitize-30-r0-068-6d4xk.18d4b2aff593b34e,reason=Scheduled count=None msg=Successfully assigned compute/eval-sanitize-30-r0-068-6d4xk to kind-worker
0.2793,Event,ADDED,eval-sanitize-30-r0-068-6d4xk.18d4b2b016b894fa,"reason=Pulled count=1 msg=Container image ""busybox:musl"" already present on machine"
0.2795,Event,ADDED,eval-sanitize-30-r0-068-6d4xk.18d4b2b018279c53,reason=Created count=1 msg=Created container: task
0.2797,Event,ADDED,eval-sanitize-30-r0-068-6d4xk.18d4b2b01c89e8c3,reason=Started count=1 msg=Started container task
0.2799,Event,ADDED,eval-sanitize-30-r0-068.18d4b0c1561f3690,reason=SuccessfulCreate count=1 msg=Created pod: eval-sanitize-30-r0-068-5f9pw
0.2801,Event,ADDED,eval-sanitize-30-r0-068.18d4b0c78c3de0fb,reason=Completed count=1 msg=Job completed
0.2802,Event,ADDED,eval-sanitize-30-r0-068.18d4b2afeddc17cd,reason=SuccessfulCreate count=1 msg=Created pod: eval-sanitize-30-r0-068-6d4xk
0.2804,Event,ADDED,eval-sanitize-30-r0-068.18d4b2b5b55eeb2f,reason=Completed count=1 msg=Job completed
0.2806,Event,ADDED,eval-sanitize-30-r0-069-cp2dd.18d4b2b036ae57a9,"reason=FailedScheduling count=None msg=0/6 nodes are available: 2 node(s) had untolerated taint(s), 4 c_wall violated: 1 conflicting context pair(s) with node memory. no new claims to deallocate, preemption: 0/6 nodes are available: 2 Preemption is not helpful for scheduling, 4 No preemption victims found for incoming pod."
0.2808,Event,ADDED,eval-sanitize-30-r0-069-cp2dd.18d4b2b0428347ea,"reason=FailedScheduling count=None msg=0/6 nodes are available: 2 node(s) had untolerated taint(s), 4 c_wall violated: 1 conflicting context pair(s) with node memory. no new claims to deallocate, preemption: 0/6 nodes are available: 2 Preemption is not helpful for scheduling, 4 No preemption victims found for incoming pod."
0.281,Event,ADDED,eval-sanitize-30-r0-069-cp2dd.18d4b2b0a2b96465,"reason=FailedScheduling count=None msg=0/6 nodes are available: 3 c_wall violated: 1 conflicting context pair(s) with node memory, 3 node(s) had untolerated taint(s). no new claims to deallocate, preemption: 0/6 nodes are available: 3 No preemption victims found for incoming pod, 3 Preemption is not helpful for scheduling."
0.2811,Event,ADDED,eval-sanitize-30-r0-069-cp2dd.18d4b2b0d0e365d0,"reason=FailedScheduling count=None msg=0/6 nodes are available: 2 c_wall violated: 1 conflicting context pair(s) with node memory, 4 node(s) had untolerated taint(s). no new claims to deallocate, preemption: 0/6 nodes are available: 2 No preemption victims found for incoming pod, 4 Preemption is not helpful for scheduling."
0.2813,Event,ADDED,eval-sanitize-30-r0-069-cp2dd.18d4b2b0e7ab2775,"reason=FailedScheduling count=None msg=0/6 nodes are available: 1 c_wall violated: 1 conflicting context pair(s) with node memory, 5 node(s) had untolerated taint(s). no new claims to deallocate, preemption: 0/6 nodes are available: 1 No preemption victims found for incoming pod, 5 Preemption is not helpful for scheduling."
0.2815,Event,ADDED,eval-sanitize-30-r0-069-cp2dd.18d4b2b0eefe7369,"reason=FailedScheduling count=None msg=0/6 nodes are available: 1 c_wall violated: 1 conflicting context pair(s) with node memory, 5 node(s) had untolerated taint(s). no new claims to deallocate, preemption: 0/6 nodes are available: 1 No preemption victims found for incoming pod, 5 Preemption is not helpful for scheduling."
0.2816,Event,ADDED,eval-sanitize-30-r0-069-cp2dd.18d4b2b778feca75,reason=Scheduled count=None msg=Successfully assigned compute/eval-sanitize-30-r0-069-cp2dd to kind-worker2
0.2818,Event,ADDED,eval-sanitize-30-r0-069-cp2dd.18d4b2b79322e41c,"reason=Pulled count=1 msg=Container image ""busybox:musl"" already present on machine"
0.282,Event,ADDED,eval-sanitize-30-r0-069-cp2dd.18d4b2b795c7f875,reason=Created count=1 msg=Created container: task
0.2821,Event,ADDED,eval-sanitize-30-r0-069-cp2dd.18d4b2b799ed909b,reason=Started count=1 msg=Started container task
0.2823,Event,ADDED,eval-sanitize-30-r0-069-g8nln.18d4b0c19c9147ef,reason=Scheduled count=None msg=Successfully assigned compute/eval-sanitize-30-r0-069-g8nln to kind-worker
0.2824,Event,ADDED,eval-sanitize-30-r0-069-g8nln.18d4b0c1c27d8721,"reason=Pulled count=1 msg=Container image ""busybox:musl"" already present on machine"
0.2826,Event,ADDED,eval-sanitize-30-r0-069-g8nln.18d4b0c1c3ca6ee8,reason=Created count=1 msg=Created container: task
0.2828,Event,ADDED,eval-sanitize-30-r0-069-g8nln.18d4b0c1caa4dcdf,reason=Started count=1 msg=Started container task
0.2829,Event,ADDED,eval-sanitize-30-r0-069.18d4b0c1912c61ea,reason=SuccessfulCreate count=1 msg=Created pod: eval-sanitize-30-r0-069-g8nln
0.2831,Event,ADDED,eval-sanitize-30-r0-069.18d4b0c77a2bb23f,reason=Completed count=1 msg=Job completed
0.2833,Event,ADDED,eval-sanitize-30-r0-069.18d4b2b02c44c895,reason=SuccessfulCreate count=1 msg=Created pod: eval-sanitize-30-r0-069-cp2dd
0.2836,Event,ADDED,eval-sanitize-30-r0-069.18d4b2bda4b071bb,reason=Completed count=1 msg=Job completed
0.2838,Event,ADDED,eval-sanitize-30-r0-070-ntdl4.18d4b2b0622ed5cd,reason=Scheduled count=None msg=Successfully assigned compute/eval-sanitize-30-r0-070-ntdl4 to kind-worker5
0.284,Event,ADDED,eval-sanitize-30-r0-070-ntdl4.18d4b2b07d7027ed,"reason=Pulled count=1 msg=Container image ""busybox:musl"" already present on machine"
0.2843,Event,ADDED,eval-sanitize-30-r0-070-ntdl4.18d4b2b07eb32a62,reason=Created count=1 msg=Created container: task
0.2845,Event,ADDED,eval-sanitize-30-r0-070-ntdl4.18d4b2b08d9c420b,reason=Started count=1 msg=Started container task
0.2846,Event,ADDED,eval-sanitize-30-r0-070-tg8hd.18d4b0c1caa6860e,reason=Scheduled count=None msg=Successfully assigned compute/eval-sanitize-30-r0-070-tg8hd to kind-worker
0.2848,Event,ADDED,eval-sanitize-30-r0-070-tg8hd.18d4b0c1f1aafc5f,"reason=Pulled count=1 msg=Container image ""busybox:musl"" already present on machine"
0.2851,Event,ADDED,eval-sanitize-30-r0-070-tg8hd.18d4b0c1f3201da6,reason=Created count=1 msg=Created container: task
0.2853,Event,ADDED,eval-sanitize-30-r0-070-tg8hd.18d4b0c1fb840858,reason=Started count=1 msg=Started container task
0.2854,Event,ADDED,eval-sanitize-30-r0-070.18d4b0c1c40c227b,reason=SuccessfulCreate count=1 msg=Created pod: eval-sanitize-30-r0-070-tg8hd
0.2856,Event,ADDED,eval-sanitize-30-r0-070.18d4b0c78c5f5435,reason=Completed count=1 msg=Job completed
0.2859,Event,ADDED,eval-sanitize-30-r0-070.18d4b2b05c5a63fa,reason=SuccessfulCreate count=1 msg=Created pod: eval-sanitize-30-r0-070-ntdl4
0.2861,Event,ADDED,eval-sanitize-30-r0-070.18d4b2b6232478c4,reason=Completed count=1 msg=Job completed
0.2862,Event,ADDED,eval-sanitize-30-r0-071-mtqnx.18d4b2b07673d485,"reason=FailedScheduling count=None msg=0/6 nodes are available: 2 c_wall violated: 1 conflicting context pair(s) with node memory, 4 node(s) had untolerated taint(s). no new claims to deallocate, preemption: 0/6 nodes are available: 2 No preemption victims found for incoming pod, 4 Preemption is not helpful for scheduling."
0.2865,Event,ADDED,eval-sanitize-30-r0-071-mtqnx.18d4b2b09610db04,"reason=FailedScheduling count=None msg=0/6 nodes are available: 2 c_wall violated: 1 conflicting context pair(s) with node memory, 4 node(s) had untolerated taint(s). no new claims to deallocate, preemption: 0/6 nodes are available: 2 No preemption victims found for incoming pod, 4 Preemption is not helpful for scheduling."
0.2867,Event,ADDED,eval-sanitize-30-r0-071-mtqnx.18d4b2b0edec4dce,"reason=FailedScheduling count=None msg=0/6 nodes are available: 1 c_wall violated: 1 conflicting context pair(s) with node memory, 5 node(s) had untolerated taint(s). no new claims to deallocate, preemption: 0/6 nodes are available: 1 No preemption victims found for incoming pod, 5 Preemption is not helpful for scheduling."
0.2868,Event,ADDED,eval-sanitize-30-r0-071-mtqnx.18d4b2b7bbef2cd7,reason=Scheduled count=None msg=Successfully assigned compute/eval-sanitize-30-r0-071-mtqnx to kind-worker2
0.287,Event,ADDED,eval-sanitize-30-r0-071-mtqnx.18d4b2b7dc7ab115,"reason=Pulled count=1 msg=Container image ""busybox:musl"" already present on machine"
0.2872,Event,ADDED,eval-sanitize-30-r0-071-mtqnx.18d4b2b7dea3f320,reason=Created count=1 msg=Created container: task
0.2874,Event,ADDED,eval-sanitize-30-r0-071-mtqnx.18d4b2b7e64a1fca,reason=Started count=1 msg=Started container task
0.2875,Event,ADDED,eval-sanitize-30-r0-071-qg9cq.18d4b0c20af848e4,reason=Scheduled count=None msg=Successfully assigned compute/eval-sanitize-30-r0-071-qg9cq to kind-worker4
0.2877,Event,ADDED,eval-sanitize-30-r0-071-qg9cq.18d4b0c2281be8aa,"reason=Pulled count=1 msg=Container image ""busybox:musl"" already present on machine"
0.2878,Event,ADDED,eval-sanitize-30-r0-071-qg9cq.18d4b0c22925bca3,reason=Created count=1 msg=Created container: task
0.288,Event,ADDED,eval-sanitize-30-r0-071-qg9cq.18d4b0c2383e60c1,reason=Started count=1 msg=Started container task
0.2882,Event,ADDED,eval-sanitize-30-r0-071.18d4b0c1fe2b3e89,reason=SuccessfulCreate count=1 msg=Created pod: eval-sanitize-30-r0-071-qg9cq
0.2883,Event,ADDED,eval-sanitize-30-r0-071.18d4b0c819faaaf4,reason=Completed count=1 msg=Job completed
0.2886,Event,ADDED,eval-sanitize-30-r0-071.18d4b2b075cf4e90,reason=SuccessfulCreate count=1 msg=Created pod: eval-sanitize-30-r0-071-mtqnx
0.2887,Event,ADDED,eval-sanitize-30-r0-071.18d4b2bf0a41dab7,reason=Completed count=1 msg=Job completed
0.2889,Event,ADDED,eval-sanitize-30-r0-072-8xnnp.18d4b0c2487b8378,reason=Scheduled count=None msg=Successfully assigned compute/eval-sanitize-30-r0-072-8xnnp to kind-worker3
0.289,Event,ADDED,eval-sanitize-30-r0-072-8xnnp.18d4b0c265e809c0,"reason=Pulled count=1 msg=Container image ""busybox:musl"" already present on machine"
0.2892,Event,ADDED,eval-sanitize-30-r0-072-8xnnp.18d4b0c2671d0d2c,reason=Created count=1 msg=Created container: task
0.2894,Event,ADDED,eval-sanitize-30-r0-072-8xnnp.18d4b0c27020d07c,reason=Started count=1 msg=Started container task
0.2896,Event,ADDED,eval-sanitize-30-r0-072-fhsm8.18d4b2b09bbe1a06,reason=Scheduled count=None msg=Successfully assigned compute/eval-sanitize-30-r0-072-fhsm8 to kind-worker4
0.2897,Event,ADDED,eval-sanitize-30-r0-072-fhsm8.18d4b2b0b9b9b6a9,"reason=Pulled count=1 msg=Container image ""busybox:musl"" already present on machine"
0.2899,Event,ADDED,eval-sanitize-30-r0-072-fhsm8.18d4b2b0bb42f87d,reason=Created count=1 msg=Created container: task
0.2901,Event,ADDED,eval-sanitize-30-r0-072-fhsm8.18d4b2b0bf038424,reason=Started count=1 msg=Started container task
0.2902,Event,ADDED,eval-sanitize-30-r0-072.18d4b0c239ed8f87,reason=SuccessfulCreate count=1 msg=Created pod: eval-sanitize-30-r0-072-8xnnp
0.2904,Event,ADDED,eval-sanitize-30-r0-072.18d4b0c833b77331,reason=Completed count=1 msg=Job completed
0.2905,Event,ADDED,eval-sanitize-30-r0-072.18d4b2b097254c69,reason=SuccessfulCreate count=1 msg=Created pod: eval-sanitize-30-r0-072-fhsm8
0.2908,Event,ADDED,eval-sanitize-30-r0-072.18d4b2b62521f2b9,reason=Completed count=1 msg=Job completed
0.2909,Event,ADDED,eval-sanitize-30-r0-073-pnppt.18d4b2b0c65608ea,reason=Scheduled count=None msg=Successfully assigned compute/eval-sanitize-30-r0-073-pnppt to kind-worker3
0.2911,Event,ADDED,eval-sanitize-30-r0-073-pnppt.18d4b2b0e7e344a9,"reason=Pulled count=1 msg=Container image ""busybox:musl"" already present on machine"
0.2913,Event,ADDED,eval-sanitize-30-r0-073-pnppt.18d4b2b0e973165d,reason=Created count=1 msg=Created container: task
0.2914,Event,ADDED,eval-sanitize-30-r0-073-pnppt.18d4b2b0fafdf89a,reason=Started count=1 msg=Started container task
0.2916,Event,ADDED,eval-sanitize-30-r0-073-qgv7z.18d4b0c28033a2a3,reason=Scheduled count=None msg=Successfully assigned compute/eval-sanitize-30-r0-073-qgv7z to kind-worker4
0.2917,Event,ADDED,eval-sanitize-30-r0-073-qgv7z.18d4b0c2a34a26be,"reason=Pulled count=1 msg=Container image ""busybox:musl"" already present on machine"
0.2919,Event,ADDED,eval-sanitize-30-r0-073-qgv7z.18d4b0c2a48f952e,reason=Created count=1 msg=Created container: task
0.2921,Event,ADDED,eval-sanitize-30-r0-073-qgv7z.18d4b0c2a8eda8c7,reason=Started count=1 msg=Started container task
0.2922,Event,ADDED,eval-sanitize-30-r0-073.18d4b0c27e3d0062,reason=SuccessfulCreate count=1 msg=Created pod: eval-sanitize-30-r0-073-qgv7z
0.2924,Event,ADDED,eval-sanitize-30-r0-073.18d4b0c847ec9140,reason=Completed count=1 msg=Job completed
0.2926,Event,ADDED,eval-sanitize-30-r0-073.18d4b2b0c0fa0aed,reason=SuccessfulCreate count=1 msg=Created pod: eval-sanitize-30-r0-073-pnppt
0.2927,Event,ADDED,eval-sanitize-30-r0-073.18d4b2b668accd0e,reason=Completed count=1 msg=Job completed
0.2929,Event,ADDED,eval-sanitize-30-r0-074-hf4ts.18d4b0c2bba9a3b3,reason=Scheduled count=None msg=Successfully assigned compute/eval-sanitize-30-r0-074-hf4ts to kind-worker
0.293,Event,ADDED,eval-sanitize-30-r0-074-hf4ts.18d4b0c2e08bb377,"reason=Pulled count=1 msg=Container image ""busybox:musl"" already present on machine"
0.2932,Event,ADDED,eval-sanitize-30-r0-074-hf4ts.18d4b0c2e1e13976,reason=Created count=1 msg=Created container: task
0.2934,Event,ADDED,eval-sanitize-30-r0-074-hf4ts.18d4b0c2edf45a29,reason=Started count=1 msg=Started container task
0.2935,Event,ADDED,eval-sanitize-30-r0-074-ndsx5.18d4b2b1010d603e,reason=Scheduled count=None msg=Successfully assigned compute/eval-sanitize-30-r0-074-ndsx5 to kind-worker4
0.2937,Event,ADDED,eval-sanitize-30-r0-074-ndsx5.18d4b2b12e236bb5,"reason=Pulled count=1 msg=Container image ""busybox:musl"" already present on machine"
0.2938,Event,ADDED,eval-sanitize-30-r0-074-ndsx5.18d4b2b12f3a29f2,reason=Created count=1 msg=Created container: task
0.294,Event,ADDED,eval-sanitize-30-r0-074-ndsx5.18d4b2b131469e58,reason=Started count=1 msg=Started container task
0.2942,Event,ADDED,eval-sanitize-30-r0-074.18d4b0c2b7284eb7,reason=SuccessfulCreate count=1 msg=Created pod: eval-sanitize-30-r0-074-hf4ts
0.2943,Event,ADDED,eval-sanitize-30-r0-074.18d4b0c8752b97f3,reason=Completed count=1 msg=Job completed
0.2945,Event,ADDED,eval-sanitize-30-r0-074.18d4b2b0fd16a57a,reason=SuccessfulCreate count=1 msg=Created pod: eval-sanitize-30-r0-074-ndsx5
0.2947,Event,ADDED,eval-sanitize-30-r0-074.18d4b2b66934506f,reason=Completed count=1 msg=Job completed
0.2948,Event,ADDED,eval-sanitize-30-r0-075-92cmh.18d4b2b131f6c788,"reason=FailedScheduling count=None msg=0/6 nodes are available: 1 c_wall violated: 1 conflicting context pair(s) with node memory, 5 node(s) had untolerated taint(s). no new claims to deallocate, preemption: 0/6 nodes are available: 1 No preemption victims found for incoming pod, 5 Preemption is not helpful for scheduling."
0.295,Event,ADDED,eval-sanitize-30-r0-075-92cmh.18d4b2b13270e810,"reason=FailedScheduling count=None msg=0/6 nodes are available: 1 c_wall violated: 1 conflicting context pair(s) with node memory, 5 node(s) had untolerated taint(s). no new claims to deallocate, preemption: 0/6 nodes are available: 1 No preemption victims found for incoming pod, 5 Preemption is not helpful for scheduling."
0.2951,Event,ADDED,eval-sanitize-30-r0-075-92cmh.18d4b2b7b6217e32,reason=Scheduled count=None msg=Successfully assigned compute/eval-sanitize-30-r0-075-92cmh to kind-worker2
0.2953,Event,ADDED,eval-sanitize-30-r0-075-92cmh.18d4b2b7df393a90,"reason=Pulled count=1 msg=Container image ""busybox:musl"" already present on machine"
0.2955,Event,ADDED,eval-sanitize-30-r0-075-92cmh.18d4b2b7e3588793,reason=Created count=1 msg=Created container: task
0.2974,Event,ADDED,eval-sanitize-30-r0-075-92cmh.18d4b2b7e6c4fe87,reason=Started count=1 msg=Started container task
0.2976,Event,ADDED,eval-sanitize-30-r0-075-kljxg.18d4b0c2f6ca60f1,reason=Scheduled count=None msg=Successfully assigned compute/eval-sanitize-30-r0-075-kljxg to kind-worker5
0.2978,Event,ADDED,eval-sanitize-30-r0-075-kljxg.18d4b0c31bf3c19f,"reason=Pulled count=1 msg=Container image ""busybox:musl"" already present on machine"
0.2979,Event,ADDED,eval-sanitize-30-r0-075-kljxg.18d4b0c31d508c4b,reason=Created count=1 msg=Created container: task
0.2981,Event,ADDED,eval-sanitize-30-r0-075-kljxg.18d4b0c32b72df46,reason=Started count=1 msg=Started container task
0.2983,Event,ADDED,eval-sanitize-30-r0-075.18d4b0c2ef864930,reason=SuccessfulCreate count=1 msg=Created pod: eval-sanitize-30-r0-075-kljxg
0.2985,Event,ADDED,eval-sanitize-30-r0-075.18d4b0c8a4bc67a1,reason=Completed count=1 msg=Job completed
0.2986,Event,ADDED,eval-sanitize-30-r0-075.18d4b2b131b3f632,reason=SuccessfulCreate count=1 msg=Created pod: eval-sanitize-30-r0-075-92cmh
0.2988,Event,ADDED,eval-sanitize-30-r0-075.18d4b2bf1337c67e,reason=Completed count=1 msg=Job completed
0.2989,Event,ADDED,eval-sanitize-30-r0-076-drvsx.18d4b0c33d45c860,reason=Scheduled count=None msg=Successfully assigned compute/eval-sanitize-30-r0-076-drvsx to kind-worker4
0.2991,Event,ADDED,eval-sanitize-30-r0-076-drvsx.18d4b0c366c06148,"reason=Pulled count=1 msg=Container image ""busybox:musl"" already present on machine"
0.2993,Event,ADDED,eval-sanitize-30-r0-076-drvsx.18d4b0c36822cf31,reason=Created count=1 msg=Created container: task
0.2995,Event,ADDED,eval-sanitize-30-r0-076-drvsx.18d4b0c37873547b,reason=Started count=1 msg=Started container task
0.2999,Event,ADDED,eval-sanitize-30-r0-076-ssscm.18d4b2b172a6b031,reason=Scheduled count=None msg=Successfully assigned compute/eval-sanitize-30-r0-076-ssscm to kind-worker4
0.3001,Event,ADDED,eval-sanitize-30-r0-076-ssscm.18d4b2b1943b6c98,"reason=Pulled count=1 msg=Container image ""busybox:musl"" already present on machine"
0.3002,Event,ADDED,eval-sanitize-30-r0-076-ssscm.18d4b2b195ed42e9,reason=Created count=1 msg=Created container: task
0.3004,Event,ADDED,eval-sanitize-30-r0-076-ssscm.18d4b2b1a22ccd7f,reason=Started count=1 msg=Started container task
0.3008,Event,ADDED,eval-sanitize-30-r0-076.18d4b0c32d09ea07,reason=SuccessfulCreate count=1 msg=Created pod: eval-sanitize-30-r0-076-drvsx
0.3009,Event,ADDED,eval-sanitize-30-r0-076.18d4b0c8ed946f32,reason=Completed count=1 msg=Job completed
0.3011,Event,ADDED,eval-sanitize-30-r0-076.18d4b2b17220b54e,reason=SuccessfulCreate count=1 msg=Created pod: eval-sanitize-30-r0-076-ssscm
0.3013,Event,ADDED,eval-sanitize-30-r0-076.18d4b2b71f39eec4,reason=Completed count=1 msg=Job completed
0.3015,Event,ADDED,eval-sanitize-30-r0-077-ktb72.18d4b2b1abbc010f,reason=Scheduled count=None msg=Successfully assigned compute/eval-sanitize-30-r0-077-ktb72 to kind-worker4
0.3017,Event,ADDED,eval-sanitize-30-r0-077-ktb72.18d4b2b1cbd49e10,"reason=Pulled count=1 msg=Container image ""busybox:musl"" already present on machine"
0.3019,Event,ADDED,eval-sanitize-30-r0-077-ktb72.18d4b2b1cce5c3e8,reason=Created count=1 msg=Created container: task
0.302,Event,ADDED,eval-sanitize-30-r0-077-ktb72.18d4b2b1da00dc7f,reason=Started count=1 msg=Started container task
0.3022,Event,ADDED,eval-sanitize-30-r0-077-vvs62.18d4b0c37849ed99,reason=Scheduled count=None msg=Successfully assigned compute/eval-sanitize-30-r0-077-vvs62 to kind-worker2
0.3024,Event,ADDED,eval-sanitize-30-r0-077-vvs62.18d4b0c3a0794cbf,"reason=Pulled count=1 msg=Container image ""busybox:musl"" already present on machine"
0.3025,Event,ADDED,eval-sanitize-30-r0-077-vvs62.18d4b0c3a24f4301,reason=Created count=1 msg=Created container: task
0.3027,Event,ADDED,eval-sanitize-30-r0-077-vvs62.18d4b0c3a6dba332,reason=Started count=1 msg=Started container task
0.3029,Event,ADDED,eval-sanitize-30-r0-077.18d4b0c368a57671,reason=SuccessfulCreate count=1 msg=Created pod: eval-sanitize-30-r0-077-vvs62
0.3031,Event,ADDED,eval-sanitize-30-r0-077.18d4b0c916a2c940,reason=Completed count=1 msg=Job completed
0.3033,Event,ADDED,eval-sanitize-30-r0-077.18d4b2b1ab4e702e,reason=SuccessfulCreate count=1 msg=Created pod: eval-sanitize-30-r0-077-ktb72
0.3034,Event,ADDED,eval-sanitize-30-r0-077.18d4b2b753f0d251,reason=Completed count=1 msg=Job completed
0.3036,Event,ADDED,eval-sanitize-30-r0-078-dtcfz.18d4b2b1ee640665,"reason=FailedScheduling count=None msg=0/6 nodes are available: 1 c_wall violated: 1 conflicting context pair(s) with node memory, 5 node(s) had untolerated taint(s). no new claims to deallocate, preemption: 0/6 nodes are available: 1 No preemption victims found for incoming pod, 5 Preemption is not helpful for scheduling."
0.3038,Event,ADDED,eval-sanitize-30-r0-078-dtcfz.18d4b2b1f4644930,"reason=FailedScheduling count=None msg=0/6 nodes are available: 1 c_wall violated: 1 conflicting context pair(s) with node memory, 5 node(s) had untolerated taint(s). no new claims to deallocate, preemption: 0/6 nodes are available: 1 No preemption victims found for incoming pod, 5 Preemption is not helpful for scheduling."
0.3039,Event,ADDED,eval-sanitize-30-r0-078-dtcfz.18d4b2b7b4dcca11,reason=Scheduled count=None msg=Successfully assigned compute/eval-sanitize-30-r0-078-dtcfz to kind-worker2
0.3041,Event,ADDED,eval-sanitize-30-r0-078-dtcfz.18d4b2b7dfaa2809,"reason=Pulled count=1 msg=Container image ""busybox:musl"" already present on machine"
0.3043,Event,ADDED,eval-sanitize-30-r0-078-dtcfz.18d4b2b7e450b196,reason=Created count=1 msg=Created container: task
0.3044,Event,ADDED,eval-sanitize-30-r0-078-dtcfz.18d4b2b7e74ad426,reason=Started count=1 msg=Started container task
0.3046,Event,ADDED,eval-sanitize-30-r0-078-fbd7p.18d4b0c3af97d160,reason=Scheduled count=None msg=Successfully assigned compute/eval-sanitize-30-r0-078-fbd7p to kind-worker2
0.3047,Event,ADDED,eval-sanitize-30-r0-078-fbd7p.18d4b0c3cc403569,"reason=Pulled count=1 msg=Container image ""busybox:musl"" already present on machine"
0.3049,Event,ADDED,eval-sanitize-30-r0-078-fbd7p.18d4b0c3cd720546,reason=Created count=1 msg=Created container: task
0.3051,Event,ADDED,eval-sanitize-30-r0-078-fbd7p.18d4b0c3d756c3c5,reason=Started count=1 msg=Started container task
0.3053,Event,ADDED,eval-sanitize-30-r0-078.18d4b0c3a2c09c1c,reason=SuccessfulCreate count=1 msg=Created pod: eval-sanitize-30-r0-078-fbd7p
0.3054,Event,ADDED,eval-sanitize-30-r0-078.18d4b0c95293202b,reason=Completed count=1 msg=Job completed
0.3056,Event,ADDED,eval-sanitize-30-r0-078.18d4b2b1ee28309f,reason=SuccessfulCreate count=1 msg=Created pod: eval-sanitize-30-r0-078-dtcfz
0.3058,Event,ADDED,eval-sanitize-30-r0-078.18d4b2bf01561ce6,reason=Completed count=1 msg=Job completed
0.306,Event,ADDED,eval-sanitize-30-r0-079-ffn9z.18d4b0c3ebbd27ca,reason=Scheduled count=None msg=Successfully assigned compute/eval-sanitize-30-r0-079-ffn9z to kind-worker2
0.3062,Event,ADDED,eval-sanitize-30-r0-079-ffn9z.18d4b0c412ca712b,"reason=Pulled count=1 msg=Container image ""busybox:musl"" already present on machine"
0.3063,Event,ADDED,eval-sanitize-30-r0-079-ffn9z.18d4b0c4149b8b8a,reason=Created count=1 msg=Created container: task
0.3065,Event,ADDED,eval-sanitize-30-r0-079-ffn9z.18d4b0c41fd3bf2f,reason=Started count=1 msg=Started container task
0.3067,Event,ADDED,eval-sanitize-30-r0-079-ggc8l.18d4b2b227eaccdf,"reason=FailedScheduling count=None msg=0/6 nodes are available: 1 c_wall violated: 2 conflicting context pair(s) with node memory, 5 node(s) had untolerated taint(s). no new claims to deallocate, preemption: 0/6 nodes are available: 1 No preemption victims found for incoming pod, 5 Preemption is not helpful for scheduling."
0.3068,Event,ADDED,eval-sanitize-30-r0-079-ggc8l.18d4b2b22b98575a,"reason=FailedScheduling count=None msg=0/6 nodes are available: 1 c_wall violated: 2 conflicting context pair(s) with node memory, 5 node(s) had untolerated taint(s). no new claims to deallocate, preemption: 0/6 nodes are available: 1 No preemption victims found for incoming pod, 5 Preemption is not helpful for scheduling."
0.3071,Event,ADDED,eval-sanitize-30-r0-079-ggc8l.18d4b2b365af45dc,"reason=FailedScheduling count=None msg=0/6 nodes are available: 1 c_wall violated: 3 conflicting context pair(s) with node memory, 5 node(s) had untolerated taint(s). no new claims to deallocate, preemption: 0/6 nodes are available: 1 No preemption victims found for incoming pod, 5 Preemption is not helpful for scheduling."
0.3072,Event,ADDED,eval-sanitize-30-r0-079-ggc8l.18d4b2b7dfe45de1,reason=Scheduled count=None msg=Successfully assigned compute/eval-sanitize-30-r0-079-ggc8l to kind-worker5
0.3074,Event,ADDED,eval-sanitize-30-r0-079-ggc8l.18d4b2b810e6895a,"reason=Pulled count=1 msg=Container image ""busybox:musl"" already present on machine"
0.3075,Event,ADDED,eval-sanitize-30-r0-079-ggc8l.18d4b2b8124cf701,reason=Created count=1 msg=Created container: task
0.3077,Event,ADDED,eval-sanitize-30-r0-079-ggc8l.18d4b2b816fd167a,reason=Started count=1 msg=Started container task
0.3079,Event,ADDED,eval-sanitize-30-r0-079.18d4b0c3e9871239,reason=SuccessfulCreate count=1 msg=Created pod: eval-sanitize-30-r0-079-ffn9z
0.308,Event,ADDED,eval-sanitize-30-r0-079.18d4b0c98de2a36e,reason=Completed count=1 msg=Job completed
0.3082,Event,ADDED,eval-sanitize-30-r0-079.18d4b2b227a7d9c4,reason=SuccessfulCreate count=1 msg=Created pod: eval-sanitize-30-r0-079-ggc8l
0.3084,Event,ADDED,eval-sanitize-30-r0-079.18d4b2bf84782e84,reason=Completed count=1 msg=Job completed
0.3085,Event,ADDED,eval-sanitize-30-r0-080-77mkz.18d4b2b25c66dc43,"reason=FailedScheduling count=None msg=0/6 nodes are available: 1 c_wall violated: 1 conflicting context pair(s) with node memory, 5 node(s) had untolerated taint(s). no new claims to deallocate, preemption: 0/6 nodes are available: 1 No preemption victims found for incoming pod, 5 Preemption is not helpful for scheduling."
0.3087,Event,ADDED,eval-sanitize-30-r0-080-77mkz.18d4b2b25cfc3e23,"reason=FailedScheduling count=None msg=0/6 nodes are available: 1 c_wall violated: 1 conflicting context pair(s) with node memory, 5 node(s) had untolerated taint(s). no new claims to deallocate, preemption: 0/6 nodes are available: 1 No preemption victims found for incoming pod, 5 Preemption is not helpful for scheduling."
0.3089,Event,ADDED,eval-sanitize-30-r0-080-77mkz.18d4b2b7b4dcc9ee,reason=Scheduled count=None msg=Successfully assigned compute/eval-sanitize-30-r0-080-77mkz to kind-worker2
0.309,Event,ADDED,eval-sanitize-30-r0-080-77mkz.18d4b2b7df1ac864,"reason=Pulled count=1 msg=Container image ""busybox:musl"" already present on machine"
0.3092,Event,ADDED,eval-sanitize-30-r0-080-77mkz.18d4b2b7e2d6fb52,reason=Created count=1 msg=Created container: task
0.3094,Event,ADDED,eval-sanitize-30-r0-080-77mkz.18d4b2b7e64f47f5,reason=Started count=1 msg=Started container task
0.3095,Event,ADDED,eval-sanitize-30-r0-080-zc9ms.18d4b0c4c45d7274,reason=Scheduled count=None msg=Successfully assigned compute/eval-sanitize-30-r0-080-zc9ms to kind-worker5
0.3097,Event,ADDED,eval-sanitize-30-r0-080-zc9ms.18d4b0c4ec7fbee9,"reason=Pulled count=1 msg=Container image ""busybox:musl"" already present on machine"
0.3099,Event,ADDED,eval-sanitize-30-r0-080-zc9ms.18d4b0c4edaf48f0,reason=Created count=1 msg=Created container: task
0.31,Event,ADDED,eval-sanitize-30-r0-080-zc9ms.18d4b0c4f5ba3e0f,reason=Started count=1 msg=Started container task
0.3102,Event,ADDED,eval-sanitize-30-r0-080.18d4b0c4b0bdf12e,reason=SuccessfulCreate count=1 msg=Created pod: eval-sanitize-30-r0-080-zc9ms
0.3103,Event,ADDED,eval-sanitize-30-r0-080.18d4b0ca74666d51,reason=Completed count=1 msg=Job completed
0.3105,Event,ADDED,eval-sanitize-30-r0-080.18d4b2b25c1d2d7d,reason=SuccessfulCreate count=1 msg=Created pod: eval-sanitize-30-r0-080-77mkz
0.3107,Event,ADDED,eval-sanitize-30-r0-080.18d4b2bf1f127b9c,reason=Completed count=1 msg=Job completed
0.3108,Event,ADDED,eval-sanitize-30-r0-081-m9qgf.18d4b2b2983b4a76,reason=Scheduled count=None msg=Successfully assigned compute/eval-sanitize-30-r0-081-m9qgf to kind-worker4
0.311,Event,ADDED,eval-sanitize-30-r0-081-m9qgf.18d4b2b2b66a4d64,"reason=Pulled count=1 msg=Container image ""busybox:musl"" already present on machine"
0.3112,Event,ADDED,eval-sanitize-30-r0-081-m9qgf.18d4b2b2b805655b,reason=Created count=1 msg=Created container: task
0.3113,Event,ADDED,eval-sanitize-30-r0-081-m9qgf.18d4b2b2c048b5ab,reason=Started count=1 msg=Started container task
0.3115,Event,ADDED,eval-sanitize-30-r0-081-mq2md.18d4b0c530430651,reason=Scheduled count=None msg=Successfully assigned compute/eval-sanitize-30-r0-081-mq2md to kind-worker2
0.3117,Event,ADDED,eval-sanitize-30-r0-081-mq2md.18d4b0c55267b130,"reason=Pulled count=1 msg=Container image ""busybox:musl"" already present on machine"
0.3119,Event,ADDED,eval-sanitize-30-r0-081-mq2md.18d4b0c5539af4da,reason=Created count=1 msg=Created container: task
0.3121,Event,ADDED,eval-sanitize-30-r0-081-mq2md.18d4b0c55fde72e0,reason=Started count=1 msg=Started container task
0.3122,Event,ADDED,eval-sanitize-30-r0-081.18d4b0c527357b58,reason=SuccessfulCreate count=1 msg=Created pod: eval-sanitize-30-r0-081-mq2md
0.3126,Event,ADDED,eval-sanitize-30-r0-081.18d4b0cafbf6086e,reason=Completed count=1 msg=Job completed
0.3127,Event,ADDED,eval-sanitize-30-r0-081.18d4b2b2979c5ad7,reason=SuccessfulCreate count=1 msg=Created pod: eval-sanitize-30-r0-081-m9qgf
0.3129,Event,ADDED,eval-sanitize-30-r0-081.18d4b2b847033dd4,reason=Completed count=1 msg=Job completed
0.3132,Event,ADDED,eval-sanitize-30-r0-082-dl4tc.18d4b0c553d5c7d7,reason=Scheduled count=None msg=Successfully assigned compute/eval-sanitize-30-r0-082-dl4tc to kind-worker5
0.3134,Event,ADDED,eval-sanitize-30-r0-082-dl4tc.18d4b0c57b3d3063,"reason=Pulled count=1 msg=Container image ""busybox:musl"" already present on machine"
0.3137,Event,ADDED,eval-sanitize-30-r0-082-dl4tc.18d4b0c57c9505a0,reason=Created count=1 msg=Created container: task
0.3139,Event,ADDED,eval-sanitize-30-r0-082-dl4tc.18d4b0c589ffecc5,reason=Started count=1 msg=Started container task
0.3142,Event,ADDED,eval-sanitize-30-r0-082-xdtnk.18d4b2b2d332ca77,"reason=FailedScheduling count=None msg=0/6 nodes are available: 1 c_wall violated: 1 conflicting context pair(s) with node memory, 5 node(s) had untolerated taint(s). no new claims to deallocate, preemption: 0/6 nodes are available: 1 No preemption victims found for incoming pod, 5 Preemption is not helpful for scheduling."
0.3144,Event,ADDED,eval-sanitize-30-r0-082-xdtnk.18d4b2b2d3af7158,"reason=FailedScheduling count=None msg=0/6 nodes are available: 1 c_wall violated: 1 conflicting context pair(s) with node memory, 5 node(s) had untolerated taint(s). no new claims to deallocate, preemption: 0/6 nodes are available: 1 No preemption victims found for incoming pod, 5 Preemption is not helpful for scheduling."
0.3145,Event,ADDED,eval-sanitize-30-r0-082-xdtnk.18d4b2b7c2011ddc,reason=Scheduled count=None msg=Successfully assigned compute/eval-sanitize-30-r0-082-xdtnk to kind-worker2
0.315,Event,ADDED,eval-sanitize-30-r0-082-xdtnk.18d4b2b7df62be08,"reason=Pulled count=1 msg=Container image ""busybox:musl"" already present on machine"
0.3151,Event,ADDED,eval-sanitize-30-r0-082-xdtnk.18d4b2b7e4505174,reason=Created count=1 msg=Created container: task
0.3153,Event,ADDED,eval-sanitize-30-r0-082-xdtnk.18d4b2b7e74cdaf0,reason=Started count=1 msg=Started container task
0.3155,Event,ADDED,eval-sanitize-30-r0-082.18d4b0c5526c0365,reason=SuccessfulCreate count=1 msg=Created pod: eval-sanitize-30-r0-082-dl4tc
0.3158,Event,ADDED,eval-sanitize-30-r0-082.18d4b0caec246e00,reason=Completed count=1 msg=Job completed
0.316,Event,ADDED,eval-sanitize-30-r0-082.18d4b2b2d2ed747c,reason=SuccessfulCreate count=1 msg=Created pod: eval-sanitize-30-r0-082-xdtnk
0.3162,Event,ADDED,eval-sanitize-30-r0-082.18d4b2bf3110d6c2,reason=Completed count=1 msg=Job completed
0.3165,Event,ADDED,eval-sanitize-30-r0-083-l2j4t.18d4b2b311695a1b,"reason=FailedScheduling count=None msg=0/6 nodes are available: 1 c_wall violated: 1 conflicting context pair(s) with node memory, 5 node(s) had untolerated taint(s). no new claims to deallocate, preemption: 0/6 nodes are available: 1 No preemption victims found for incoming pod, 5 Preemption is not helpful for scheduling."
0.3167,Event,ADDED,eval-sanitize-30-r0-083-l2j4t.18d4b2b311f5d9a4,"reason=FailedScheduling count=None msg=0/6 nodes are available: 1 c_wall violated: 1 conflicting context pair(s) with node memory, 5 node(s) had untolerated taint(s). no new claims to deallocate, preemption: 0/6 nodes are available: 1 No preemption victims found for incoming pod, 5 Preemption is not helpful for scheduling."
0.3168,Event,ADDED,eval-sanitize-30-r0-083-l2j4t.18d4b2b7c25ca339,reason=Scheduled count=None msg=Successfully assigned compute/eval-sanitize-30-r0-083-l2j4t to kind-worker
0.317,Event,ADDED,eval-sanitize-30-r0-083-l2j4t.18d4b2b7dd095e69,"reason=Pulled count=1 msg=Container image ""busybox:musl"" already present on machine"
0.3176,Event,ADDED,eval-sanitize-30-r0-083-l2j4t.18d4b2b7de83ba9f,reason=Created count=1 msg=Created container: task
0.318,Event,ADDED,eval-sanitize-30-r0-083-l2j4t.18d4b2b7e641869e,reason=Started count=1 msg=Started container task
0.3182,Event,ADDED,eval-sanitize-30-r0-083-rrx52.18d4b0c5955a4def,"reason=FailedScheduling count=None msg=0/6 nodes are available: 1 c_wall violated: 3 conflicting context pair(s) with node memory, 2 c_wall violated: 1 conflicting context pair(s) with node memory, 3 node(s) had untolerated taint(s). no new claims to deallocate, preemption: 0/6 nodes are available: 3 No preemption victims found for incoming pod, 3 Preemption is not helpful for scheduling."
0.3185,Event,ADDED,eval-sanitize-30-r0-083-rrx52.18d4b0c598fa137d,"reason=FailedScheduling count=None msg=0/6 nodes are available: 1 c_wall violated: 1 conflicting context pair(s) with node memory, 1 c_wall violated: 3 conflicting context pair(s) with node memory, 4 node(s) had untolerated taint(s). no new claims to deallocate, preemption: 0/6 nodes are available: 2 No preemption victims found for incoming pod, 4 Preemption is not helpful for scheduling."
0.3187,Event,ADDED,eval-sanitize-30-r0-083-rrx52.18d4b0c59a924123,"reason=FailedScheduling count=None msg=0/6 nodes are available: 1 c_wall violated: 1 conflicting context pair(s) with node memory, 1 c_wall violated: 3 conflicting context pair(s) with node memory, 4 node(s) had untolerated taint(s). no new claims to deallocate, preemption: 0/6 nodes are available: 2 No preemption victims found for incoming pod, 4 Preemption is not helpful for scheduling."
0.3188,Event,ADDED,eval-sanitize-30-r0-083-rrx52.18d4b0cc5ef899fd,reason=Scheduled count=None msg=Successfully assigned compute/eval-sanitize-30-r0-083-rrx52 to kind-worker
0.3191,Event,ADDED,eval-sanitize-30-r0-083-rrx52.18d4b0cc7f9aad25,"reason=Pulled count=1 msg=Container image ""busybox:musl"" already present on machine"
0.3192,Event,ADDED,eval-sanitize-30-r0-083-rrx52.18d4b0cc80fb20a7,reason=Created count=1 msg=Created container: task
0.3194,Event,ADDED,eval-sanitize-30-r0-083-rrx52.18d4b0cc84d74643,reason=Started count=1 msg=Started container task
0.3196,Event,ADDED,eval-sanitize-30-r0-083.18d4b0c594a9fb83,reason=SuccessfulCreate count=1 msg=Created pod: eval-sanitize-30-r0-083-rrx52
0.3197,Event,ADDED,eval-sanitize-30-r0-083.18d4b0d1f85f81ca,reason=Completed count=1 msg=Job completed
0.3199,Event,ADDED,eval-sanitize-30-r0-083.18d4b2b3111d991a,reason=SuccessfulCreate count=1 msg=Created pod: eval-sanitize-30-r0-083-l2j4t
0.3201,Event,ADDED,eval-sanitize-30-r0-083.18d4b2bee6999df5,reason=Completed count=1 msg=Job completed
0.3202,Event,ADDED,eval-sanitize-30-r0-084-lkqgh.18d4b0c5c1b3d388,"reason=FailedScheduling count=None msg=0/6 nodes are available: 6 node(s) had untolerated taint(s). no new claims to deallocate, preemption: 0/6 nodes are available: 6 Preemption is not helpful for scheduling."
0.3204,Event,ADDED,eval-sanitize-30-r0-084-lkqgh.18d4b0cc5f4983b6,"reason=FailedScheduling count=None msg=0/6 nodes are available: 1 c_wall violated: 1 conflicting context pair(s) with node memory, 5 node(s) had untolerated taint(s). no new claims to deallocate, preemption: 0/6 nodes are available: 1 No preemption victims found for incoming pod, 5 Preemption is not helpful for scheduling."
0.3205,Event,ADDED,eval-sanitize-30-r0-084-lkqgh.18d4b0cc9001ad3c,"reason=FailedScheduling count=None msg=0/6 nodes are available: 1 c_wall violated: 2 conflicting context pair(s) with node memory, 5 node(s) had untolerated taint(s). no new claims to deallocate, preemption: 0/6 nodes are available: 1 No preemption victims found for incoming pod, 5 Preemption is not helpful for scheduling."
0.3207,Event,ADDED,eval-sanitize-30-r0-084-lkqgh.18d4b0cd05b9e8b6,"reason=FailedScheduling count=None msg=0/6 nodes are available: 1 c_wall violated: 2 conflicting context pair(s) with node memory, 1 node(s) had untolerated taint(s), 4 c_wall violated: 1 conflicting context pair(s) with node memory. no new claims to deallocate, preemption: 0/6 nodes are available: 1 Preemption is not helpful for scheduling, 5 No preemption victims found for incoming pod."
0.3209,Event,ADDED,eval-sanitize-30-r0-084-lkqgh.18d4b0cd6480ce35,"reason=FailedScheduling count=None msg=0/6 nodes are available: 1 c_wall violated: 2 conflicting context pair(s) with node memory, 1 node(s) had untolerated taint(s), 4 c_wall violated: 1 conflicting context pair(s) with node memory. no new claims to deallocate, preemption: 0/6 nodes are available: 1 Preemption is not helpful for scheduling, 5 No preemption victims found for incoming pod."
0.321,Event,ADDED,eval-sanitize-30-r0-084-lkqgh.18d4b0d3ad6bfadf,"reason=FailedScheduling count=None msg=0/6 nodes are available: 2 c_wall violated: 1 conflicting context pair(s) with node memory, 4 node(s) had untolerated taint(s). no new claims to deallocate, preemption: 0/6 nodes are available: 2 No preemption victims found for incoming pod, 4 Preemption is not helpful for scheduling."
0.3212,Event,ADDED,eval-sanitize-30-r0-084-lkqgh.18d4b0d3c1df022c,"reason=FailedScheduling count=None msg=0/6 nodes are available: 1 c_wall violated: 1 conflicting context pair(s) with node memory, 5 node(s) had untolerated taint(s). no new claims to deallocate, preemption: 0/6 nodes are available: 1 No preemption victims found for incoming pod, 5 Preemption is not helpful for scheduling."
0.3213,Event,ADDED,eval-sanitize-30-r0-084-lkqgh.18d4b0d3cc10ca14,"reason=FailedScheduling count=None msg=0/6 nodes are available: 1 c_wall violated: 1 conflicting context pair(s) with node memory, 5 node(s) had untolerated taint(s). no new claims to deallocate, preemption: 0/6 nodes are available: 1 No preemption victims found for incoming pod, 5 Preemption is not helpful for scheduling."
0.3215,Event,ADDED,eval-sanitize-30-r0-084-lkqgh.18d4b0da747c52a8,reason=Scheduled count=None msg=Successfully assigned compute/eval-sanitize-30-r0-084-lkqgh to kind-worker
0.3216,Event,ADDED,eval-sanitize-30-r0-084-lkqgh.18d4b0da8ff98513,"reason=Pulled count=1 msg=Container image ""busybox:musl"" already present on machine"
0.3218,Event,ADDED,eval-sanitize-30-r0-084-lkqgh.18d4b0da93bc559c,reason=Created count=1 msg=Created container: task
0.322,Event,ADDED,eval-sanitize-30-r0-084-lkqgh.18d4b0da98475e0d,reason=Started count=1 msg=Started container task
0.3221,Event,ADDED,eval-sanitize-30-r0-084-p9z8t.18d4b2b3534b83f6,reason=Scheduled count=None msg=Successfully assigned compute/eval-sanitize-30-r0-084-p9z8t to kind-worker4
0.3223,Event,ADDED,eval-sanitize-30-r0-084-p9z8t.18d4b2b384f0146c,"reason=Pulled count=1 msg=Container image ""busybox:musl"" already present on machine"
0.3225,Event,ADDED,eval-sanitize-30-r0-084-p9z8t.18d4b2b3862dbe15,reason=Created count=1 msg=Created container: task
0.3227,Event,ADDED,eval-sanitize-30-r0-084-p9z8t.18d4b2b388ce9ed0,reason=Started count=1 msg=Started container task
0.3229,Event,ADDED,eval-sanitize-30-r0-084.18d4b0c5c1ab2202,reason=SuccessfulCreate count=1 msg=Created pod: eval-sanitize-30-r0-084-lkqgh
0.3232,Event,ADDED,eval-sanitize-30-r0-084.18d4b0dfd5eff2d5,reason=Completed count=1 msg=Job completed
0.3234,Event,ADDED,eval-sanitize-30-r0-084.18d4b2b352aca83c,reason=SuccessfulCreate count=1 msg=Created pod: eval-sanitize-30-r0-084-p9z8t
0.3235,Event,ADDED,eval-sanitize-30-r0-084.18d4b2b90918eb0e,reason=Completed count=1 msg=Job completed
0.3239,Event,ADDED,eval-sanitize-30-r0-085-9pcnk.18d4b2b386ef9db8,"reason=FailedScheduling count=None msg=0/6 nodes are available: 1 c_wall violated: 1 conflicting context pair(s) with node memory, 5 node(s) had untolerated taint(s). no new claims to deallocate, preemption: 0/6 nodes are available: 1 No preemption victims found for incoming pod, 5 Preemption is not helpful for scheduling."
0.3241,Event,ADDED,eval-sanitize-30-r0-085-9pcnk.18d4b2b387b08f37,"reason=FailedScheduling count=None msg=0/6 nodes are available: 1 c_wall violated: 1 conflicting context pair(s) with node memory, 5 node(s) had untolerated taint(s). no new claims to deallocate, preemption: 0/6 nodes are available: 1 No preemption victims found for incoming pod, 5 Preemption is not helpful for scheduling."
0.3242,Event,ADDED,eval-sanitize-30-r0-085-9pcnk.18d4b2b7b49316ca,reason=Scheduled count=None msg=Successfully assigned compute/eval-sanitize-30-r0-085-9pcnk to kind-worker2
0.3244,Event,ADDED,eval-sanitize-30-r0-085-9pcnk.18d4b2b7dc5179a7,"reason=Pulled count=1 msg=Container image ""busybox:musl"" already present on machine"
0.3247,Event,ADDED,eval-sanitize-30-r0-085-9pcnk.18d4b2b7de320d09,reason=Created count=1 msg=Created container: task
0.3249,Event,ADDED,eval-sanitize-30-r0-085-9pcnk.18d4b2b7e4510aef,reason=Started count=1 msg=Started container task
0.325,Event,ADDED,eval-sanitize-30-r0-085-fwc6n.18d4b0c5fdfcc910,"reason=FailedScheduling count=None msg=0/6 nodes are available: 6 node(s) had untolerated taint(s). no new claims to deallocate, preemption: 0/6 nodes are available: 6 Preemption is not helpful for scheduling."
0.3253,Event,ADDED,eval-sanitize-30-r0-085-fwc6n.18d4b0cc602fa5cd,reason=Scheduled count=None msg=Successfully assigned compute/eval-sanitize-30-r0-085-fwc6n to kind-worker
0.3255,Event,ADDED,eval-sanitize-30-r0-085-fwc6n.18d4b0cc7fb67c72,"reason=Pulled count=1 msg=Container image ""busybox:musl"" already present on machine"
0.3257,Event,ADDED,eval-sanitize-30-r0-085-fwc6n.18d4b0cc81979ea8,reason=Created count=1 msg=Created container: task
0.3259,Event,ADDED,eval-sanitize-30-r0-085-fwc6n.18d4b0cc859a76dc,reason=Started count=1 msg=Started container task
0.3262,Event,ADDED,eval-sanitize-30-r0-085.18d4b0c5fdefdcc7,reason=SuccessfulCreate count=1 msg=Created pod: eval-sanitize-30-r0-085-fwc6n
0.3264,Event,ADDED,eval-sanitize-30-r0-085.18d4b0d1bdbbffe4,reason=Completed count=1 msg=Job completed
0.3265,Event,ADDED,eval-sanitize-30-r0-085.18d4b2b386872f61,reason=SuccessfulCreate count=1 msg=Created pod: eval-sanitize-30-r0-085-9pcnk
0.3267,Event,ADDED,eval-sanitize-30-r0-085.18d4b2bf1cfe2d29,reason=Completed count=1 msg=Job completed
0.3272,Event,ADDED,eval-sanitize-30-r0-086-c5lsw.18d4b2b3c1efcb4d,reason=Scheduled count=None msg=Successfully assigned compute/eval-sanitize-30-r0-086-c5lsw to kind-worker4
0.3274,Event,ADDED,eval-sanitize-30-r0-086-c5lsw.18d4b2b3df4f4895,"reason=Pulled count=1 msg=Container image ""busybox:musl"" already present on machine"
0.3277,Event,ADDED,eval-sanitize-30-r0-086-c5lsw.18d4b2b3e0637f1b,reason=Created count=1 msg=Created container: task
0.3281,Event,ADDED,eval-sanitize-30-r0-086-c5lsw.18d4b2b3e3e1ffa8,reason=Started count=1 msg=Started container task
0.3283,Event,ADDED,eval-sanitize-30-r0-086-mml5l.18d4b0c63a257428,"reason=FailedScheduling count=None msg=0/6 nodes are available: 6 node(s) had untolerated taint(s). no new claims to deallocate, preemption: 0/6 nodes are available: 6 Preemption is not helpful for scheduling."
0.3285,Event,ADDED,eval-sanitize-30-r0-086-mml5l.18d4b0cc600f10e4,"reason=FailedScheduling count=None msg=0/6 nodes are available: 1 c_wall violated: 1 conflicting context pair(s) with node memory, 5 node(s) had untolerated taint(s). no new claims to deallocate, preemption: 0/6 nodes are available: 1 No preemption victims found for incoming pod, 5 Preemption is not helpful for scheduling."
0.3287,Event,ADDED,eval-sanitize-30-r0-086-mml5l.18d4b0cc93867c30,"reason=FailedScheduling count=None msg=0/6 nodes are available: 1 c_wall violated: 1 conflicting context pair(s) with node memory, 5 node(s) had untolerated taint(s). no new claims to deallocate, preemption: 0/6 nodes are available: 1 No preemption victims found for incoming pod, 5 Preemption is not helpful for scheduling."
0.3289,Event,ADDED,eval-sanitize-30-r0-086-mml5l.18d4b0cd115a2c8e,reason=Scheduled count=None msg=Successfully assigned compute/eval-sanitize-30-r0-086-mml5l to kind-worker5
0.3291,Event,ADDED,eval-sanitize-30-r0-086-mml5l.18d4b0cd2c669846,"reason=Pulled count=1 msg=Container image ""busybox:musl"" already present on machine"
0.3292,Event,ADDED,eval-sanitize-30-r0-086-mml5l.18d4b0cd2dd4f549,reason=Created count=1 msg=Created container: task
0.3295,Event,ADDED,eval-sanitize-30-r0-086-mml5l.18d4b0cd31fa7be1,reason=Started count=1 msg=Started container task
0.3296,Event,ADDED,eval-sanitize-30-r0-086.18d4b0c63a1b0e72,reason=SuccessfulCreate count=1 msg=Created pod: eval-sanitize-30-r0-086-mml5l
0.3298,Event,ADDED,eval-sanitize-30-r0-086.18d4b0d3ec88ab26,reason=Completed count=1 msg=Job completed
0.33,Event,ADDED,eval-sanitize-30-r0-086.18d4b2b3c16c2077,reason=SuccessfulCreate count=1 msg=Created pod: eval-sanitize-30-r0-086-c5lsw
0.3302,Event,ADDED,eval-sanitize-30-r0-086.18d4b2b976a48f0d,reason=Completed count=1 msg=Job completed
0.3303,Event,ADDED,eval-sanitize-30-r0-087-n5sdm.18d4b0c6655eab5f,"reason=FailedScheduling count=None msg=0/6 nodes are available: 6 node(s) had untolerated taint(s). no new claims to deallocate, preemption: 0/6 nodes are available: 6 Preemption is not helpful for scheduling."
0.3305,Event,ADDED,eval-sanitize-30-r0-087-n5sdm.18d4b0cc60d2fcb0,"reason=FailedScheduling count=None msg=0/6 nodes are available: 1 c_wall violated: 1 conflicting context pair(s) with node memory, 5 node(s) had untolerated taint(s). no new claims to deallocate, preemption: 0/6 nodes are available: 1 No preemption victims found for incoming pod, 5 Preemption is not helpful for scheduling."
0.3306,Event,ADDED,eval-sanitize-30-r0-087-n5sdm.18d4b0cc942d5624,reason=Scheduled count=None msg=Successfully assigned compute/eval-sanitize-30-r0-087-n5sdm to kind-worker2
0.3308,Event,ADDED,eval-sanitize-30-r0-087-n5sdm.18d4b0ccac8b5e99,"reason=Pulled count=1 msg=Container image ""busybox:musl"" already present on machine"
0.3309,Event,ADDED,eval-sanitize-30-r0-087-n5sdm.18d4b0ccae26940c,reason=Created count=1 msg=Created container: task
0.3311,Event,ADDED,eval-sanitize-30-r0-087-n5sdm.18d4b0ccbca6fd6f,reason=Started count=1 msg=Started container task
0.3313,Event,ADDED,eval-sanitize-30-r0-087-vbrl5.18d4b2b3fda9b54a,reason=Scheduled count=None msg=Successfully assigned compute/eval-sanitize-30-r0-087-vbrl5 to kind-worker4
0.3314,Event,ADDED,eval-sanitize-30-r0-087-vbrl5.18d4b2b42b52ae30,"reason=Pulled count=1 msg=Container image ""busybox:musl"" already present on machine"
0.3316,Event,ADDED,eval-sanitize-30-r0-087-vbrl5.18d4b2b42c811efe,reason=Created count=1 msg=Created container: task
0.3318,Event,ADDED,eval-sanitize-30-r0-087-vbrl5.18d4b2b430fbb394,reason=Started count=1 msg=Started container task
0.3319,Event,ADDED,eval-sanitize-30-r0-087.18d4b0c66551901c,reason=SuccessfulCreate count=1 msg=Created pod: eval-sanitize-30-r0-087-n5sdm
0.3321,Event,ADDED,eval-sanitize-30-r0-087.18d4b0d35c118a4c,reason=Completed count=1 msg=Job completed
0.3322,Event,ADDED,eval-sanitize-30-r0-087.18d4b2b3fd313387,reason=SuccessfulCreate count=1 msg=Created pod: eval-sanitize-30-r0-087-vbrl5
0.3324,Event,ADDED,eval-sanitize-30-r0-087.18d4b2b9b282c627,reason=Completed count=1 msg=Job completed
0.3326,Event,ADDED,eval-sanitize-30-r0-088-872kp.18d4b0c697760306,"reason=FailedScheduling count=None msg=0/6 nodes are available: 6 node(s) had untolerated taint(s). no new claims to deallocate, preemption: 0/6 nodes are available: 6 Preemption is not helpful for scheduling."
0.3327,Event,ADDED,eval-sanitize-30-r0-088-872kp.18d4b0cc64be0fcf,"reason=FailedScheduling count=None msg=0/6 nodes are available: 1 c_wall violated: 1 conflicting context pair(s) with node memory, 5 node(s) had untolerated taint(s). no new claims to deallocate, preemption: 0/6 nodes are available: 1 No preemption victims found for incoming pod, 5 Preemption is not helpful for scheduling."
0.3329,Event,ADDED,eval-sanitize-30-r0-088-872kp.18d4b0cc94d366e8,"reason=FailedScheduling count=None msg=0/6 nodes are available: 2 c_wall violated: 1 conflicting context pair(s) with node memory, 4 node(s) had untolerated taint(s). no new claims to deallocate, preemption: 0/6 nodes are available: 2 No preemption victims found for incoming pod, 4 Preemption is not helpful for scheduling."
0.333,Event,ADDED,eval-sanitize-30-r0-088-872kp.18d4b0cd175944ed,reason=Scheduled count=None msg=Successfully assigned compute/eval-sanitize-30-r0-088-872kp to kind-worker3
0.3332,Event,ADDED,eval-sanitize-30-r0-088-872kp.18d4b0cd32622cfa,"reason=Pulled count=1 msg=Container image ""busybox:musl"" already present on machine"
0.3333,Event,ADDED,eval-sanitize-30-r0-088-872kp.18d4b0cd336ec93c,reason=Created count=1 msg=Created container: task
0.3335,Event,ADDED,eval-sanitize-30-r0-088-872kp.18d4b0cd371319e5,reason=Started count=1 msg=Started container task
0.3336,Event,ADDED,eval-sanitize-30-r0-088-9ksqt.18d4b2b440566847,"reason=FailedScheduling count=None msg=0/6 nodes are available: 1 c_wall violated: 2 conflicting context pair(s) with node memory, 5 node(s) had untolerated taint(s). no new claims to deallocate, preemption: 0/6 nodes are available: 1 No preemption victims found for incoming pod, 5 Preemption is not helpful for scheduling."
0.3338,Event,ADDED,eval-sanitize-30-r0-088-9ksqt.18d4b2b4410b6a84,"reason=FailedScheduling count=None msg=0/6 nodes are available: 1 c_wall violated: 2 conflicting context pair(s) with node memory, 5 node(s) had untolerated taint(s). no new claims to deallocate, preemption: 0/6 nodes are available: 1 No preemption victims found for incoming pod, 5 Preemption is not helpful for scheduling."
0.3341,Event,ADDED,eval-sanitize-30-r0-088-9ksqt.18d4b2b7932ec79c,reason=Scheduled count=None msg=Successfully assigned compute/eval-sanitize-30-r0-088-9ksqt to kind-worker
0.3342,Event,ADDED,eval-sanitize-30-r0-088-9ksqt.18d4b2b7b47be2e0,"reason=Pulled count=1 msg=Container image ""busybox:musl"" already present on machine"
0.3344,Event,ADDED,eval-sanitize-30-r0-088-9ksqt.18d4b2b7b65a88e5,reason=Created count=1 msg=Created container: task
0.3346,Event,ADDED,eval-sanitize-30-r0-088-9ksqt.18d4b2b7bad46c64,reason=Started count=1 msg=Started container task
0.3347,Event,ADDED,eval-sanitize-30-r0-088.18d4b0c6975ff11d,reason=SuccessfulCreate count=1 msg=Created pod: eval-sanitize-30-r0-088-872kp
0.3349,Event,ADDED,eval-sanitize-30-r0-088.18d4b0d457e78b56,reason=Completed count=1 msg=Job completed
0.3351,Event,ADDED,eval-sanitize-30-r0-088.18d4b2b440000490,reason=SuccessfulCreate count=1 msg=Created pod: eval-sanitize-30-r0-088-9ksqt
0.3352,Event,ADDED,eval-sanitize-30-r0-088.18d4b2be26045c65,reason=Completed count=1 msg=Job completed
0.3354,Event,ADDED,eval-sanitize-30-r0-089-sjvr8.18d4b0c6bed90ffa,"reason=FailedScheduling count=None msg=0/6 nodes are available: 6 node(s) had untolerated taint(s). no new claims to deallocate, preemption: 0/6 nodes are available: 6 Preemption is not helpful for scheduling."
0.3355,Event,ADDED,eval-sanitize-30-r0-089-sjvr8.18d4b0cc6e7e2660,"reason=FailedScheduling count=None msg=0/6 nodes are available: 1 c_wall violated: 1 conflicting context pair(s) with node memory, 5 node(s) had untolerated taint(s). no new claims to deallocate, preemption: 0/6 nodes are available: 1 No preemption victims found for incoming pod, 5 Preemption is not helpful for scheduling."
0.3357,Event,ADDED,eval-sanitize-30-r0-089-sjvr8.18d4b0cc99dca0c3,reason=Scheduled count=None msg=Successfully assigned compute/eval-sanitize-30-r0-089-sjvr8 to kind-worker2
0.3359,Event,ADDED,eval-sanitize-30-r0-089-sjvr8.18d4b0ccbcb0c88d,"reason=Pulled count=1 msg=Container image ""busybox:musl"" already present on machine"
0.3361,Event,ADDED,eval-sanitize-30-r0-089-sjvr8.18d4b0ccbeabe1ff,reason=Created count=1 msg=Created container: task
0.3363,Event,ADDED,eval-sanitize-30-r0-089-sjvr8.18d4b0ccc3fa6fb8,reason=Started count=1 msg=Started container task
0.3365,Event,ADDED,eval-sanitize-30-r0-089-zqtb9.18d4b2b4788f8f58,reason=Scheduled count=None msg=Successfully assigned compute/eval-sanitize-30-r0-089-zqtb9 to kind-worker4
0.3366,Event,ADDED,eval-sanitize-30-r0-089-zqtb9.18d4b2b4a3f506b5,"reason=Pulled count=1 msg=Container image ""busybox:musl"" already present on machine"
0.3368,Event,ADDED,eval-sanitize-30-r0-089-zqtb9.18d4b2b4a516407a,reason=Created count=1 msg=Created container: task
0.337,Event,ADDED,eval-sanitize-30-r0-089-zqtb9.18d4b2b4ac3e1bf7,reason=Started count=1 msg=Started container task
0.3374,Event,ADDED,eval-sanitize-30-r0-089.18d4b0c6bece9c42,reason=SuccessfulCreate count=1 msg=Created pod: eval-sanitize-30-r0-089-sjvr8
0.3375,Event,ADDED,eval-sanitize-30-r0-089.18d4b0d360d8bb09,reason=Completed count=1 msg=Job completed
0.3377,Event,ADDED,eval-sanitize-30-r0-089.18d4b2b477fc87ed,reason=SuccessfulCreate count=1 msg=Created pod: eval-sanitize-30-r0-089-zqtb9
0.3379,Event,ADDED,eval-sanitize-30-r0-089.18d4b2ba26fdf9b4,reason=Completed count=1 msg=Job completed
0.338,Event,ADDED,eval-sanitize-30-r0-090-bxwt6.18d4b2b4b02ac763,"reason=FailedScheduling count=None msg=0/6 nodes are available: 1 c_wall violated: 1 conflicting context pair(s) with node memory, 5 node(s) had untolerated taint(s). no new claims to deallocate, preemption: 0/6 nodes are available: 1 No preemption victims found for incoming pod, 5 Preemption is not helpful for scheduling."
0.3382,Event,ADDED,eval-sanitize-30-r0-090-bxwt6.18d4b2b4b0aee904,"reason=FailedScheduling count=None msg=0/6 nodes are available: 1 c_wall violated: 1 conflicting context pair(s) with node memory, 5 node(s) had untolerated taint(s). no new claims to deallocate, preemption: 0/6 nodes are available: 1 No preemption victims found for incoming pod, 5 Preemption is not helpful for scheduling."
0.3383,Event,ADDED,eval-sanitize-30-r0-090-bxwt6.18d4b2b7ab3cfa16,reason=Scheduled count=None msg=Successfully assigned compute/eval-sanitize-30-r0-090-bxwt6 to kind-worker2
0.3385,Event,ADDED,eval-sanitize-30-r0-090-bxwt6.18d4b2b7cd0d6e0c,"reason=Pulled count=1 msg=Container image ""busybox:musl"" already present on machine"
0.3387,Event,ADDED,eval-sanitize-30-r0-090-bxwt6.18d4b2b7d0fe998a,reason=Created count=1 msg=Created container: task
0.3389,Event,ADDED,eval-sanitize-30-r0-090-bxwt6.18d4b2b7db1bb3a1,reason=Started count=1 msg=Started container task
0.339,Event,ADDED,eval-sanitize-30-r0-090-jmlzg.18d4b0c6e283b382,"reason=FailedScheduling count=None msg=0/6 nodes are available: 6 node(s) had untolerated taint(s). no new claims to deallocate, preemption: 0/6 nodes are available: 6 Preemption is not helpful for scheduling."
0.3392,Event,ADDED,eval-sanitize-30-r0-090-jmlzg.18d4b0cc6f19faa4,"reason=FailedScheduling count=None msg=0/6 nodes are available: 1 c_wall violated: 1 conflicting context pair(s) with node memory, 5 node(s) had untolerated taint(s). no new claims to deallocate, preemption: 0/6 nodes are available: 1 No preemption victims found for incoming pod, 5 Preemption is not helpful for scheduling."
0.3393,Event,ADDED,eval-sanitize-30-r0-090-jmlzg.18d4b0cc99d3295b,"reason=FailedScheduling count=None msg=0/6 nodes are available: 2 c_wall violated: 1 conflicting context pair(s) with node memory, 4 node(s) had untolerated taint(s). no new claims to deallocate, preemption: 0/6 nodes are available: 2 No preemption victims found for incoming pod, 4 Preemption is not helpful for scheduling."
0.3395,Event,ADDED,eval-sanitize-30-r0-090-jmlzg.18d4b0cd1d18057f,"reason=FailedScheduling count=None msg=0/6 nodes are available: 1 c_wall violated: 2 conflicting context pair(s) with node memory, 1 node(s) had untolerated taint(s), 4 c_wall violated: 1 conflicting context pair(s) with node memory. no new claims to deallocate, preemption: 0/6 nodes are available: 1 Preemption is not helpful for scheduling, 5 No preemption victims found for incoming pod."
0.3396,Event,ADDED,eval-sanitize-30-r0-090-jmlzg.18d4b0cd703459b9,"reason=FailedScheduling count=None msg=0/6 nodes are available: 1 c_wall violated: 2 conflicting context pair(s) with node memory, 1 node(s) had untolerated taint(s), 4 c_wall violated: 1 conflicting context pair(s) with node memory. no new claims to deallocate, preemption: 0/6 nodes are available: 1 Preemption is not helpful for scheduling, 5 No preemption victims found for incoming pod."
0.3398,Event,ADDED,eval-sanitize-30-r0-090-jmlzg.18d4b0d3b163d71c,"reason=FailedScheduling count=None msg=0/6 nodes are available: 2 c_wall violated: 1 conflicting context pair(s) with node memory, 4 node(s) had untolerated taint(s). no new claims to deallocate, preemption: 0/6 nodes are available: 2 No preemption victims found for incoming pod, 4 Preemption is not helpful for scheduling."
0.3399,Event,ADDED,eval-sanitize-30-r0-090-jmlzg.18d4b0d3c2e596d2,"reason=FailedScheduling count=None msg=0/6 nodes are available: 1 c_wall violated: 1 conflicting context pair(s) with node memory, 5 node(s) had untolerated taint(s). no new claims to deallocate, preemption: 0/6 nodes are available: 1 No preemption victims found for incoming pod, 5 Preemption is not helpful for scheduling."
0.3401,Event,ADDED,eval-sanitize-30-r0-090-jmlzg.18d4b0d3ce526f08,"reason=FailedScheduling count=None msg=0/6 nodes are available: 1 c_wall violated: 1 conflicting context pair(s) with node memory, 5 node(s) had untolerated taint(s). no new claims to deallocate, preemption: 0/6 nodes are available: 1 No preemption victims found for incoming pod, 5 Preemption is not helpful for scheduling."
0.3403,Event,ADDED,eval-sanitize-30-r0-090-jmlzg.18d4b0da7540a316,"reason=FailedScheduling count=None msg=0/6 nodes are available: 1 c_wall violated: 1 conflicting context pair(s) with node memory, 5 node(s) had untolerated taint(s). no new claims to deallocate, preemption: 0/6 nodes are available: 1 No preemption victims found for incoming pod, 5 Preemption is not helpful for scheduling."
0.3404,Event,ADDED,eval-sanitize-30-r0-090-jmlzg.18d4b0daa77a0960,"reason=FailedScheduling count=None msg=0/6 nodes are available: 1 c_wall violated: 1 conflicting context pair(s) with node memory, 1 c_wall violated: 2 conflicting context pair(s) with node memory, 4 node(s) had untolerated taint(s). no new claims to deallocate, preemption: 0/6 nodes are available: 2 No preemption victims found for incoming pod, 4 Preemption is not helpful for scheduling."
0.3406,Event,ADDED,eval-sanitize-30-r0-090-jmlzg.18d4b0db22622472,reason=Scheduled count=None msg=Successfully assigned compute/eval-sanitize-30-r0-090-jmlzg to kind-worker3
0.3407,Event,ADDED,eval-sanitize-30-r0-090-jmlzg.18d4b0db3c5daa09,"reason=Pulled count=1 msg=Container image ""busybox:musl"" already present on machine"
0.3409,Event,ADDED,eval-sanitize-30-r0-090-jmlzg.18d4b0db3daeb066,reason=Created count=1 msg=Created container: task
0.3411,Event,ADDED,eval-sanitize-30-r0-090-jmlzg.18d4b0db4436aa5d,reason=Started count=1 msg=Started container task
0.3412,Event,ADDED,eval-sanitize-30-r0-090.18d4b0c6e277a9fa,reason=SuccessfulCreate count=1 msg=Created pod: eval-sanitize-30-r0-090-jmlzg
0.3414,Event,ADDED,eval-sanitize-30-r0-090.18d4b0e338f97de5,reason=Completed count=1 msg=Job completed
0.3416,Event,ADDED,eval-sanitize-30-r0-090.18d4b2b4afe8db3c,reason=SuccessfulCreate count=1 msg=Created pod: eval-sanitize-30-r0-090-bxwt6
0.3417,Event,ADDED,eval-sanitize-30-r0-090.18d4b2bf1d014142,reason=Completed count=1 msg=Job completed
0.3419,Event,ADDED,eval-sanitize-30-r0-091-h2hs8.18d4b0c6fa49717a,"reason=FailedScheduling count=None msg=0/6 nodes are available: 6 node(s) had untolerated taint(s). no new claims to deallocate, preemption: 0/6 nodes are available: 6 Preemption is not helpful for scheduling."
0.342,Event,ADDED,eval-sanitize-30-r0-091-h2hs8.18d4b0cc6f9fb006,"reason=FailedScheduling count=None msg=0/6 nodes are available: 1 c_wall violated: 2 conflicting context pair(s) with node memory, 5 node(s) had untolerated taint(s). no new claims to deallocate, preemption: 0/6 nodes are available: 1 No preemption victims found for incoming pod, 5 Preemption is not helpful for scheduling."
0.3422,Event,ADDED,eval-sanitize-30-r0-091-h2hs8.18d4b0cc9adcf544,"reason=FailedScheduling count=None msg=0/6 nodes are available: 1 c_wall violated: 1 conflicting context pair(s) with node memory, 1 c_wall violated: 2 conflicting context pair(s) with node memory, 4 node(s) had untolerated taint(s). no new claims to deallocate, preemption: 0/6 nodes are available: 2 No preemption victims found for incoming pod, 4 Preemption is not helpful for scheduling."
0.3423,Event,ADDED,eval-sanitize-30-r0-091-h2hs8.18d4b0cd23b84917,"reason=FailedScheduling count=None msg=0/6 nodes are available: 1 c_wall violated: 2 conflicting context pair(s) with node memory, 1 node(s) had untolerated taint(s), 4 c_wall violated: 1 conflicting context pair(s) with node memory. no new claims to deallocate, preemption: 0/6 nodes are available: 1 Preemption is not helpful for scheduling, 5 No preemption victims found for incoming pod."
0.3425,Event,ADDED,eval-sanitize-30-r0-091-h2hs8.18d4b0cd81f6854f,"reason=FailedScheduling count=None msg=0/6 nodes are available: 1 c_wall violated: 2 conflicting context pair(s) with node memory, 1 node(s) had untolerated taint(s), 4 c_wall violated: 1 conflicting context pair(s) with node memory. no new claims to deallocate, preemption: 0/6 nodes are available: 1 Preemption is not helpful for scheduling, 5 No preemption victims found for incoming pod."
0.3427,Event,ADDED,eval-sanitize-30-r0-091-h2hs8.18d4b0d3b58dd99a,"reason=FailedScheduling count=None msg=0/6 nodes are available: 2 c_wall violated: 1 conflicting context pair(s) with node memory, 4 node(s) had untolerated taint(s). no new claims to deallocate, preemption: 0/6 nodes are available: 2 No preemption victims found for incoming pod, 4 Preemption is not helpful for scheduling."
0.3428,Event,ADDED,eval-sanitize-30-r0-091-h2hs8.18d4b0d3c85fd37e,"reason=FailedScheduling count=None msg=0/6 nodes are available: 1 c_wall violated: 1 conflicting context pair(s) with node memory, 5 node(s) had untolerated taint(s). no new claims to deallocate, preemption: 0/6 nodes are available: 1 No preemption victims found for incoming pod, 5 Preemption is not helpful for scheduling."
0.343,Event,ADDED,eval-sanitize-30-r0-091-h2hs8.18d4b0d3cedabf19,"reason=FailedScheduling count=None msg=0/6 nodes are available: 1 c_wall violated: 1 conflicting context pair(s) with node memory, 5 node(s) had untolerated taint(s). no new claims to deallocate, preemption: 0/6 nodes are available: 1 No preemption victims found for incoming pod, 5 Preemption is not helpful for scheduling."
0.3432,Event,ADDED,eval-sanitize-30-r0-091-h2hs8.18d4b0da7a84da77,reason=Scheduled count=None msg=Successfully assigned compute/eval-sanitize-30-r0-091-h2hs8 to kind-worker
0.3434,Event,ADDED,eval-sanitize-30-r0-091-h2hs8.18d4b0da9a0d5f62,"reason=Pulled count=1 msg=Container image ""busybox:musl"" already present on machine"
0.3435,Event,ADDED,eval-sanitize-30-r0-091-h2hs8.18d4b0da9db59d17,reason=Created count=1 msg=Created container: task
0.3437,Event,ADDED,eval-sanitize-30-r0-091-h2hs8.18d4b0daa0cecedd,reason=Started count=1 msg=Started container task
0.3439,Event,ADDED,eval-sanitize-30-r0-091-qp6ff.18d4b2b4f18aba08,"reason=FailedScheduling count=None msg=0/6 nodes are available: 1 c_wall violated: 1 conflicting context pair(s) with node memory, 5 node(s) had untolerated taint(s). no new claims to deallocate, preemption: 0/6 nodes are available: 1 No preemption victims found for incoming pod, 5 Preemption is not helpful for scheduling."
0.344,Event,ADDED,eval-sanitize-30-r0-091-qp6ff.18d4b2b4f20bca5b,"reason=FailedScheduling count=None msg=0/6 nodes are available: 1 c_wall violated: 1 conflicting context pair(s) with node memory, 5 node(s) had untolerated taint(s). no new claims to deallocate, preemption: 0/6 nodes are available: 1 No preemption victims found for incoming pod, 5 Preemption is not helpful for scheduling."
0.3442,Event,ADDED,eval-sanitize-30-r0-091-qp6ff.18d4b2b7abb3577a,reason=Scheduled count=None msg=Successfully assigned compute/eval-sanitize-30-r0-091-qp6ff to kind-worker2
0.3444,Event,ADDED,eval-sanitize-30-r0-091-qp6ff.18d4b2b7cd41be20,"reason=Pulled count=1 msg=Container image ""busybox:musl"" already present on machine"
0.3446,Event,ADDED,eval-sanitize-30-r0-091-qp6ff.18d4b2b7d2216fa8,reason=Created count=1 msg=Created container: task
0.3448,Event,ADDED,eval-sanitize-30-r0-091-qp6ff.18d4b2b7db21cd79,reason=Started count=1 msg=Started container task
0.3449,Event,ADDED,eval-sanitize-30-r0-091.18d4b0c6fa41ff0b,reason=SuccessfulCreate count=1 msg=Created pod: eval-sanitize-30-r0-091-h2hs8
0.3451,Event,ADDED,eval-sanitize-30-r0-091.18d4b0dfd4b40fcc,reason=Completed count=1 msg=Job completed
0.3453,Event,ADDED,eval-sanitize-30-r0-091.18d4b2b4f14767bc,reason=SuccessfulCreate count=1 msg=Created pod: eval-sanitize-30-r0-091-qp6ff
0.3454,Event,ADDED,eval-sanitize-30-r0-091.18d4b2bef856bb34,reason=Completed count=1 msg=Job completed
0.3456,Event,ADDED,eval-sanitize-30-r0-092-5wl9z.18d4b2b5279e0359,"reason=FailedScheduling count=None msg=0/6 nodes are available: 1 c_wall violated: 2 conflicting context pair(s) with node memory, 5 node(s) had untolerated taint(s). no new claims to deallocate, preemption: 0/6 nodes are available: 1 No preemption victims found for incoming pod, 5 Preemption is not helpful for scheduling."
0.3458,Event,ADDED,eval-sanitize-30-r0-092-5wl9z.18d4b2b5282dcd4f,"reason=FailedScheduling count=None msg=0/6 nodes are available: 1 c_wall violated: 2 conflicting context pair(s) with node memory, 5 node(s) had untolerated taint(s). no new claims to deallocate, preemption: 0/6 nodes are available: 1 No preemption victims found for incoming pod, 5 Preemption is not helpful for scheduling."
0.346,Event,ADDED,eval-sanitize-30-r0-092-5wl9z.18d4b2b7abeb0cf4,reason=Scheduled count=None msg=Successfully assigned compute/eval-sanitize-30-r0-092-5wl9z to kind-worker
0.3463,Event,ADDED,eval-sanitize-30-r0-092-5wl9z.18d4b2b7cd2bf8a5,"reason=Pulled count=1 msg=Container image ""busybox:musl"" already present on machine"
0.3465,Event,ADDED,eval-sanitize-30-r0-092-5wl9z.18d4b2b7cf58f53e,reason=Created count=1 msg=Created container: task
0.3466,Event,ADDED,eval-sanitize-30-r0-092-5wl9z.18d4b2b7d5482d01,reason=Started count=1 msg=Started container task
0.3468,Event,ADDED,eval-sanitize-30-r0-092-vnl95.18d4b0c7224639e5,"reason=FailedScheduling count=None msg=0/6 nodes are available: 6 node(s) had untolerated taint(s). no new claims to deallocate, preemption: 0/6 nodes are available: 6 Preemption is not helpful for scheduling."
0.3471,Event,ADDED,eval-sanitize-30-r0-092-vnl95.18d4b0cc72e62a29,"reason=FailedScheduling count=None msg=0/6 nodes are available: 1 c_wall violated: 2 conflicting context pair(s) with node memory, 5 node(s) had untolerated taint(s). no new claims to deallocate, preemption: 0/6 nodes are available: 1 No preemption victims found for incoming pod, 5 Preemption is not helpful for scheduling."
0.3472,Event,ADDED,eval-sanitize-30-r0-092-vnl95.18d4b0cc9fb7cdeb,"reason=FailedScheduling count=None msg=0/6 nodes are available: 1 c_wall violated: 1 conflicting context pair(s) with node memory, 1 c_wall violated: 2 conflicting context pair(s) with node memory, 4 node(s) had untolerated taint(s). no new claims to deallocate, preemption: 0/6 nodes are available: 2 No preemption victims found for incoming pod, 4 Preemption is not helpful for scheduling."
0.3474,Event,ADDED,eval-sanitize-30-r0-092-vnl95.18d4b0cd2e9e2e40,"reason=FailedScheduling count=None msg=0/6 nodes are available: 1 c_wall violated: 2 conflicting context pair(s) with node memory, 1 node(s) had untolerated taint(s), 4 c_wall violated: 1 conflicting context pair(s) with node memory. no new claims to deallocate, preemption: 0/6 nodes are available: 1 Preemption is not helpful for scheduling, 5 No preemption victims found for incoming pod."
0.3476,Event,ADDED,eval-sanitize-30-r0-092-vnl95.18d4b0cd88d7d05d,"reason=FailedScheduling count=None msg=0/6 nodes are available: 1 c_wall violated: 2 conflicting context pair(s) with node memory, 1 node(s) had untolerated taint(s), 4 c_wall violated: 1 conflicting context pair(s) with node memory. no new claims to deallocate, preemption: 0/6 nodes are available: 1 Preemption is not helpful for scheduling, 5 No preemption victims found for incoming pod."
0.3478,Event,ADDED,eval-sanitize-30-r0-092-vnl95.18d4b0d3ba577008,"reason=FailedScheduling count=None msg=0/6 nodes are available: 2 c_wall violated: 1 conflicting context pair(s) with node memory, 4 node(s) had untolerated taint(s). no new claims to deallocate, preemption: 0/6 nodes are available: 2 No preemption victims found for incoming pod, 4 Preemption is not helpful for scheduling."
0.3479,Event,ADDED,eval-sanitize-30-r0-092-vnl95.18d4b0d3c96ec4ff,"reason=FailedScheduling count=None msg=0/6 nodes are available: 1 c_wall violated: 1 conflicting context pair(s) with node memory, 5 node(s) had untolerated taint(s). no new claims to deallocate, preemption: 0/6 nodes are available: 1 No preemption victims found for incoming pod, 5 Preemption is not helpful for scheduling."
0.3481,Event,ADDED,eval-sanitize-30-r0-092-vnl95.18d4b0d3cf2f1a57,"reason=FailedScheduling count=None msg=0/6 nodes are available: 1 c_wall violated: 1 conflicting context pair(s) with node memory, 5 node(s) had untolerated taint(s). no new claims to deallocate, preemption: 0/6 nodes are available: 1 No preemption victims found for incoming pod, 5 Preemption is not helpful for scheduling."
0.3483,Event,ADDED,eval-sanitize-30-r0-092-vnl95.18d4b0da7b63c1ba,reason=Scheduled count=None msg=Successfully assigned compute/eval-sanitize-30-r0-092-vnl95 to kind-worker
0.3484,Event,ADDED,eval-sanitize-30-r0-092-vnl95.18d4b0da9a6c3170,"reason=Pulled count=1 msg=Container image ""busybox:musl"" already present on machine"
0.3486,Event,ADDED,eval-sanitize-30-r0-092-vnl95.18d4b0da9e27daa2,reason=Created count=1 msg=Created container: task
0.3488,Event,ADDED,eval-sanitize-30-r0-092-vnl95.18d4b0daa14da4d6,reason=Started count=1 msg=Started container task
0.3489,Event,ADDED,eval-sanitize-30-r0-092.18d4b0c7223e0771,reason=SuccessfulCreate count=1 msg=Created pod: eval-sanitize-30-r0-092-vnl95
0.3491,Event,ADDED,eval-sanitize-30-r0-092.18d4b0dfd5a68a4c,reason=Completed count=1 msg=Job completed
0.3493,Event,ADDED,eval-sanitize-30-r0-092.18d4b2b52760f5d3,reason=SuccessfulCreate count=1 msg=Created pod: eval-sanitize-30-r0-092-5wl9z
0.3494,Event,ADDED,eval-sanitize-30-r0-092.18d4b2beec695fc7,reason=Completed count=1 msg=Job completed
0.3496,Event,ADDED,eval-sanitize-30-r0-093-48mnb.18d4b0c747d2c8c6,"reason=FailedScheduling count=None msg=0/6 nodes are available: 6 node(s) had untolerated taint(s). no new claims to deallocate, preemption: 0/6 nodes are available: 6 Preemption is not helpful for scheduling."
0.3497,Event,ADDED,eval-sanitize-30-r0-093-48mnb.18d4b0cc774c4074,"reason=FailedScheduling count=None msg=0/6 nodes are available: 1 c_wall violated: 1 conflicting context pair(s) with node memory, 5 node(s) had untolerated taint(s). no new claims to deallocate, preemption: 0/6 nodes are available: 1 No preemption victims found for incoming pod, 5 Preemption is not helpful for scheduling."
0.3499,Event,ADDED,eval-sanitize-30-r0-093-48mnb.18d4b0cca4fd6696,reason=Scheduled count=None msg=Successfully assigned compute/eval-sanitize-30-r0-093-48mnb to kind-worker2
0.35,Event,ADDED,eval-sanitize-30-r0-093-48mnb.18d4b0ccc4f07d32,"reason=Pulled count=1 msg=Container image ""busybox:musl"" already present on machine"
0.3502,Event,ADDED,eval-sanitize-30-r0-093-48mnb.18d4b0ccc6645e78,reason=Created count=1 msg=Created container: task
0.3504,Event,ADDED,eval-sanitize-30-r0-093-48mnb.18d4b0cccdce7f37,reason=Started count=1 msg=Started container task
0.3505,Event,ADDED,eval-sanitize-30-r0-093-sr6f8.18d4b2b5635f14e2,reason=Scheduled count=None msg=Successfully assigned compute/eval-sanitize-30-r0-093-sr6f8 to kind-worker4
0.3507,Event,ADDED,eval-sanitize-30-r0-093-sr6f8.18d4b2b57e372e8b,"reason=Pulled count=1 msg=Container image ""busybox:musl"" already present on machine"
0.3509,Event,ADDED,eval-sanitize-30-r0-093-sr6f8.18d4b2b57f51f2fa,reason=Created count=1 msg=Created container: task
0.351,Event,ADDED,eval-sanitize-30-r0-093-sr6f8.18d4b2b583abd3fb,reason=Started count=1 msg=Started container task
0.3512,Event,ADDED,eval-sanitize-30-r0-093.18d4b0c747c9780d,reason=SuccessfulCreate count=1 msg=Created pod: eval-sanitize-30-r0-093-48mnb
0.3513,Event,ADDED,eval-sanitize-30-r0-093.18d4b0d375508822,reason=Completed count=1 msg=Job completed
0.3515,Event,ADDED,eval-sanitize-30-r0-093.18d4b2b562c9ce74,reason=SuccessfulCreate count=1 msg=Created pod: eval-sanitize-30-r0-093-sr6f8
0.3517,Event,ADDED,eval-sanitize-30-r0-093.18d4b2bb0dc9fe5e,reason=Completed count=1 msg=Job completed
0.3519,Event,ADDED,eval-sanitize-30-r0-094-pj4xm.18d4b0c77011a758,"reason=FailedScheduling count=None msg=0/6 nodes are available: 6 node(s) had untolerated taint(s). no new claims to deallocate, preemption: 0/6 nodes are available: 6 Preemption is not helpful for scheduling."
0.3521,Event,ADDED,eval-sanitize-30-r0-094-pj4xm.18d4b0cc78d70662,reason=Scheduled count=None msg=Successfully assigned compute/eval-sanitize-30-r0-094-pj4xm to kind-worker
0.3523,Event,ADDED,eval-sanitize-30-r0-094-pj4xm.18d4b0cc9397c6cc,"reason=Pulled count=1 msg=Container image ""busybox:musl"" already present on machine"
0.3525,Event,ADDED,eval-sanitize-30-r0-094-pj4xm.18d4b0cc952f033e,reason=Created count=1 msg=Created container: task
0.3526,Event,ADDED,eval-sanitize-30-r0-094-pj4xm.18d4b0cc979c9dfa,reason=Started count=1 msg=Started container task
0.3529,Event,ADDED,eval-sanitize-30-r0-094-pv7mt.18d4b2b59eb4f88e,"reason=FailedScheduling count=None msg=0/6 nodes are available: 1 c_wall violated: 1 conflicting context pair(s) with node memory, 5 node(s) had untolerated taint(s). no new claims to deallocate, preemption: 0/6 nodes are available: 1 No preemption victims found for incoming pod, 5 Preemption is not helpful for scheduling."
0.3533,Event,ADDED,eval-sanitize-30-r0-094-pv7mt.18d4b2b59f3e24d0,"reason=FailedScheduling count=None msg=0/6 nodes are available: 1 c_wall violated: 1 conflicting context pair(s) with node memory, 5 node(s) had untolerated taint(s). no new claims to deallocate, preemption: 0/6 nodes are available: 1 No preemption victims found for incoming pod, 5 Preemption is not helpful for scheduling."
0.3536,Event,ADDED,eval-sanitize-30-r0-094-pv7mt.18d4b2b79cf95226,reason=Scheduled count=None msg=Successfully assigned compute/eval-sanitize-30-r0-094-pv7mt to kind-worker2
0.3539,Event,ADDED,eval-sanitize-30-r0-094-pv7mt.18d4b2b7bce8f43c,"reason=Pulled count=1 msg=Container image ""busybox:musl"" already present on machine"
0.3541,Event,ADDED,eval-sanitize-30-r0-094-pv7mt.18d4b2b7bea2f6bd,reason=Created count=1 msg=Created container: task
0.3543,Event,ADDED,eval-sanitize-30-r0-094-pv7mt.18d4b2b7c2eedf5c,reason=Started count=1 msg=Started container task
0.3545,Event,ADDED,eval-sanitize-30-r0-094.18d4b0c770043ea1,reason=SuccessfulCreate count=1 msg=Created pod: eval-sanitize-30-r0-094-pj4xm
0.3547,Event,ADDED,eval-sanitize-30-r0-094.18d4b0d1bdb9f4eb,reason=Completed count=1 msg=Job completed
0.3548,Event,ADDED,eval-sanitize-30-r0-094.18d4b2b59e6e3bc7,reason=SuccessfulCreate count=1 msg=Created pod: eval-sanitize-30-r0-094-pv7mt
0.355,Event,ADDED,eval-sanitize-30-r0-094.18d4b2be3ca4136f,reason=Completed count=1 msg=Job completed
0.3552,Event,ADDED,eval-sanitize-30-r0-095-dw6c4.18d4b0c7a1dc0163,"reason=FailedScheduling count=None msg=0/6 nodes are available: 6 node(s) had untolerated taint(s). no new claims to deallocate, preemption: 0/6 nodes are available: 6 Preemption is not helpful for scheduling."
0.3553,Event,ADDED,eval-sanitize-30-r0-095-dw6c4.18d4b0cc782044ed,"reason=FailedScheduling count=None msg=0/6 nodes are available: 1 c_wall violated: 1 conflicting context pair(s) with node memory, 5 node(s) had untolerated taint(s). no new claims to deallocate, preemption: 0/6 nodes are available: 1 No preemption victims found for incoming pod, 5 Preemption is not helpful for scheduling."
0.3555,Event,ADDED,eval-sanitize-30-r0-095-dw6c4.18d4b0cca883bd7a,"reason=FailedScheduling count=None msg=0/6 nodes are available: 2 c_wall violated: 1 conflicting context pair(s) with node memory, 4 node(s) had untolerated taint(s). no new claims to deallocate, preemption: 0/6 nodes are available: 2 No preemption victims found for incoming pod, 4 Preemption is not helpful for scheduling."
0.3557,Event,ADDED,eval-sanitize-30-r0-095-dw6c4.18d4b0cd3acd233d,"reason=FailedScheduling count=None msg=0/6 nodes are available: 1 c_wall violated: 2 conflicting context pair(s) with node memory, 1 node(s) had untolerated taint(s), 4 c_wall violated: 1 conflicting context pair(s) with node memory. no new claims to deallocate, preemption: 0/6 nodes are available: 1 Preemption is not helpful for scheduling, 5 No preemption victims found for incoming pod."
0.3561,Event,ADDED,eval-sanitize-30-r0-095-dw6c4.18d4b0cd8eda7a6d,"reason=FailedScheduling count=None msg=0/6 nodes are available: 1 c_wall violated: 2 conflicting context pair(s) with node memory, 1 node(s) had untolerated taint(s), 4 c_wall violated: 1 conflicting context pair(s) with node memory. no new claims to deallocate, preemption: 0/6 nodes are available: 1 Preemption is not helpful for scheduling, 5 No preemption victims found for incoming pod."
0.3562,Event,ADDED,eval-sanitize-30-r0-095-dw6c4.18d4b0d3a76cb849,"reason=FailedScheduling count=None msg=0/6 nodes are available: 1 c_wall violated: 2 conflicting context pair(s) with node memory, 2 c_wall violated: 1 conflicting context pair(s) with node memory, 3 node(s) had untolerated taint(s). no new claims to deallocate, preemption: 0/6 nodes are available: 3 No preemption victims found for incoming pod, 3 Preemption is not helpful for scheduling."
0.3565,Event,ADDED,eval-sanitize-30-r0-095-dw6c4.18d4b0d3bb1384c6,"reason=FailedScheduling count=None msg=0/6 nodes are available: 2 c_wall violated: 1 conflicting context pair(s) with node memory, 4 node(s) had untolerated taint(s). no new claims to deallocate, preemption: 0/6 nodes are available: 2 No preemption victims found for incoming pod, 4 Preemption is not helpful for scheduling."
0.3567,Event,ADDED,eval-sanitize-30-r0-095-dw6c4.18d4b0d3c9efb994,"reason=FailedScheduling count=None msg=0/6 nodes are available: 1 c_wall violated: 1 conflicting context pair(s) with node memory, 5 node(s) had untolerated taint(s). no new claims to deallocate, preemption: 0/6 nodes are available: 1 No preemption victims found for incoming pod, 5 Preemption is not helpful for scheduling."
0.3569,Event,ADDED,eval-sanitize-30-r0-095-dw6c4.18d4b0d3d11f7371,"reason=FailedScheduling count=None msg=0/6 nodes are available: 1 c_wall violated: 1 conflicting context pair(s) with node memory, 5 node(s) had untolerated taint(s). no new claims to deallocate, preemption: 0/6 nodes are available: 1 No preemption victims found for incoming pod, 5 Preemption is not helpful for scheduling."
0.3572,Event,ADDED,eval-sanitize-30-r0-095-dw6c4.18d4b0da7b4dd4b5,"reason=FailedScheduling count=None msg=0/6 nodes are available: 1 c_wall violated: 1 conflicting context pair(s) with node memory, 5 node(s) had untolerated taint(s). no new claims to deallocate, preemption: 0/6 nodes are available: 1 No preemption victims found for incoming pod, 5 Preemption is not helpful for scheduling."
0.3573,Event,ADDED,eval-sanitize-30-r0-095-dw6c4.18d4b0daaf53d7a1,"reason=FailedScheduling count=None msg=0/6 nodes are available: 1 c_wall violated: 1 conflicting context pair(s) with node memory, 1 c_wall violated: 2 conflicting context pair(s) with node memory, 4 node(s) had untolerated taint(s). no new claims to deallocate, preemption: 0/6 nodes are available: 2 No preemption victims found for incoming pod, 4 Preemption is not helpful for scheduling."
0.3575,Event,ADDED,eval-sanitize-30-r0-095-dw6c4.18d4b0db44c2b421,reason=Scheduled count=None msg=Successfully assigned compute/eval-sanitize-30-r0-095-dw6c4 to kind-worker3
0.3577,Event,ADDED,eval-sanitize-30-r0-095-dw6c4.18d4b0db6791f6c8,"reason=Pulled count=1 msg=Container image ""busybox:musl"" already present on machine"
0.3581,Event,ADDED,eval-sanitize-30-r0-095-dw6c4.18d4b0db69a1fceb,reason=Created count=1 msg=Created container: task
0.3583,Event,ADDED,eval-sanitize-30-r0-095-dw6c4.18d4b0db6dd136b7,reason=Started count=1 msg=Started container task
0.3584,Event,ADDED,eval-sanitize-30-r0-095-rnhll.18d4b2b5db2c9aeb,"reason=FailedScheduling count=None msg=0/6 nodes are available: 1 c_wall violated: 1 conflicting context pair(s) with node memory, 5 node(s) had untolerated taint(s). no new claims to deallocate, preemption: 0/6 nodes are available: 1 No preemption victims found for incoming pod, 5 Preemption is not helpful for scheduling."
0.3587,Event,ADDED,eval-sanitize-30-r0-095-rnhll.18d4b2b5dbcab461,"reason=FailedScheduling count=None msg=0/6 nodes are available: 1 c_wall violated: 1 conflicting context pair(s) with node memory, 5 node(s) had untolerated taint(s). no new claims to deallocate, preemption: 0/6 nodes are available: 1 No preemption victims found for incoming pod, 5 Preemption is not helpful for scheduling."
0.3589,Event,ADDED,eval-sanitize-30-r0-095-rnhll.18d4b2b7b6f3b2e0,reason=Scheduled count=None msg=Successfully assigned compute/eval-sanitize-30-r0-095-rnhll to kind-worker2
0.3591,Event,ADDED,eval-sanitize-30-r0-095-rnhll.18d4b2b7decd5da1,"reason=Pulled count=1 msg=Container image ""busybox:musl"" already present on machine"
0.3593,Event,ADDED,eval-sanitize-30-r0-095-rnhll.18d4b2b7e1d8a2a2,reason=Created count=1 msg=Created container: task
0.3595,Event,ADDED,eval-sanitize-30-r0-095-rnhll.18d4b2b7e456864c,reason=Started count=1 msg=Started container task
0.3597,Event,ADDED,eval-sanitize-30-r0-095.18d4b0c7a1cdea9f,reason=SuccessfulCreate count=1 msg=Created pod: eval-sanitize-30-r0-095-dw6c4
0.3598,Event,ADDED,eval-sanitize-30-r0-095.18d4b0e338f5ab5a,reason=Completed count=1 msg=Job completed
0.3601,Event,ADDED,eval-sanitize-30-r0-095.18d4b2b5dadd77c1,reason=SuccessfulCreate count=1 msg=Created pod: eval-sanitize-30-r0-095-rnhll
0.3603,Event,ADDED,eval-sanitize-30-r0-095.18d4b2bf2e93133d,reason=Completed count=1 msg=Job completed
0.3604,Event,ADDED,eval-sanitize-30-r0-096-lrzvz.18d4b0c7dfdd4faf,"reason=FailedScheduling count=None msg=0/6 nodes are available: 6 node(s) had untolerated taint(s). no new claims to deallocate, preemption: 0/6 nodes are available: 6 Preemption is not helpful for scheduling."
0.3606,Event,ADDED,eval-sanitize-30-r0-096-lrzvz.18d4b0cc79184fee,"reason=FailedScheduling count=None msg=0/6 nodes are available: 1 c_wall violated: 1 conflicting context pair(s) with node memory, 5 node(s) had untolerated taint(s). no new claims to deallocate, preemption: 0/6 nodes are available: 1 No preemption victims found for incoming pod, 5 Preemption is not helpful for scheduling."
0.3609,Event,ADDED,eval-sanitize-30-r0-096-lrzvz.18d4b0cca9c6040f,reason=Scheduled count=None msg=Successfully assigned compute/eval-sanitize-30-r0-096-lrzvz to kind-worker4
0.3611,Event,ADDED,eval-sanitize-30-r0-096-lrzvz.18d4b0ccd52073db,"reason=Pulled count=1 msg=Container image ""busybox:musl"" already present on machine"
0.3613,Event,ADDED,eval-sanitize-30-r0-096-lrzvz.18d4b0ccd6ee140a,reason=Created count=1 msg=Created container: task
0.3615,Event,ADDED,eval-sanitize-30-r0-096-lrzvz.18d4b0ccd93def05,reason=Started count=1 msg=Started container task
0.3616,Event,ADDED,eval-sanitize-30-r0-096-xkmjz.18d4b2b61680389c,reason=Scheduled count=None msg=Successfully assigned compute/eval-sanitize-30-r0-096-xkmjz to kind-worker4
0.3618,Event,ADDED,eval-sanitize-30-r0-096-xkmjz.18d4b2b63895aa63,"reason=Pulled count=1 msg=Container image ""busybox:musl"" already present on machine"
0.362,Event,ADDED,eval-sanitize-30-r0-096-xkmjz.18d4b2b639d0ac25,reason=Created count=1 msg=Created container: task
0.3622,Event,ADDED,eval-sanitize-30-r0-096-xkmjz.18d4b2b63e530020,reason=Started count=1 msg=Started container task
0.3623,Event,ADDED,eval-sanitize-30-r0-096.18d4b0c7dfcdf3e0,reason=SuccessfulCreate count=1 msg=Created pod: eval-sanitize-30-r0-096-lrzvz
0.3625,Event,ADDED,eval-sanitize-30-r0-096.18d4b0d3dd3be260,reason=Completed count=1 msg=Job completed
0.3627,Event,ADDED,eval-sanitize-30-r0-096.18d4b2b615f39206,reason=SuccessfulCreate count=1 msg=Created pod: eval-sanitize-30-r0-096-xkmjz
0.3628,Event,ADDED,eval-sanitize-30-r0-096.18d4b2bbc28ef73c,reason=Completed count=1 msg=Job completed
0.363,Event,ADDED,eval-sanitize-30-r0-097-6sjnx.18d4b2b65659eb8b,reason=Scheduled count=None msg=Successfully assigned compute/eval-sanitize-30-r0-097-6sjnx to kind-worker4
0.3632,Event,ADDED,eval-sanitize-30-r0-097-6sjnx.18d4b2b67012ce1f,"reason=Pulled count=1 msg=Container image ""busybox:musl"" already present on machine"
0.3635,Event,ADDED,eval-sanitize-30-r0-097-6sjnx.18d4b2b6767f66e1,reason=Created count=1 msg=Created container: task
0.3637,Event,ADDED,eval-sanitize-30-r0-097-6sjnx.18d4b2b67f79a3db,reason=Started count=1 msg=Started container task
0.3639,Event,ADDED,eval-sanitize-30-r0-097-fzsw2.18d4b0c819caf602,"reason=FailedScheduling count=None msg=0/6 nodes are available: 6 node(s) had untolerated taint(s). no new claims to deallocate, preemption: 0/6 nodes are available: 6 Preemption is not helpful for scheduling."
0.364,Event,ADDED,eval-sanitize-30-r0-097-fzsw2.18d4b0cc79d22d88,"reason=FailedScheduling count=None msg=0/6 nodes are available: 1 c_wall violated: 1 conflicting context pair(s) with node memory, 5 node(s) had untolerated taint(s). no new claims to deallocate, preemption: 0/6 nodes are available: 1 No preemption victims found for incoming pod, 5 Preemption is not helpful for scheduling."
0.3643,Event,ADDED,eval-sanitize-30-r0-097-fzsw2.18d4b0ccae7a3d89,reason=Scheduled count=None msg=Successfully assigned compute/eval-sanitize-30-r0-097-fzsw2 to kind-worker2
0.3645,Event,ADDED,eval-sanitize-30-r0-097-fzsw2.18d4b0cccdd13224,"reason=Pulled count=1 msg=Container image ""busybox:musl"" already present on machine"
0.3647,Event,ADDED,eval-sanitize-30-r0-097-fzsw2.18d4b0cccf71c96d,reason=Created count=1 msg=Created container: task
0.3649,Event,ADDED,eval-sanitize-30-r0-097-fzsw2.18d4b0ccd3e6a89f,reason=Started count=1 msg=Started container task
0.365,Event,ADDED,eval-sanitize-30-r0-097.18d4b0c819c07985,reason=SuccessfulCreate count=1 msg=Created pod: eval-sanitize-30-r0-097-fzsw2
0.3653,Event,ADDED,eval-sanitize-30-r0-097.18d4b0d4136091be,reason=Completed count=1 msg=Job completed
0.3654,Event,ADDED,eval-sanitize-30-r0-097.18d4b2b655d55029,reason=SuccessfulCreate count=1 msg=Created pod: eval-sanitize-30-r0-097-6sjnx
0.3656,Event,ADDED,eval-sanitize-30-r0-097.18d4b2bbfe5409c3,reason=Completed count=1 msg=Job completed
0.3657,Event,ADDED,eval-sanitize-30-r0-098-jklxz.18d4b0c84739c66a,"reason=FailedScheduling count=None msg=0/6 nodes are available: 6 node(s) had untolerated taint(s). no new claims to deallocate, preemption: 0/6 nodes are available: 6 Preemption is not helpful for scheduling."
0.3659,Event,ADDED,eval-sanitize-30-r0-098-jklxz.18d4b0cc7a83e2fc,"reason=FailedScheduling count=None msg=0/6 nodes are available: 1 c_wall violated: 1 conflicting context pair(s) with node memory, 5 node(s) had untolerated taint(s). no new claims to deallocate, preemption: 0/6 nodes are available: 1 No preemption victims found for incoming pod, 5 Preemption is not helpful for scheduling."
0.366,Event,ADDED,eval-sanitize-30-r0-098-jklxz.18d4b0ccbcc9541b,reason=Scheduled count=None msg=Successfully assigned compute/eval-sanitize-30-r0-098-jklxz to kind-worker4
0.3662,Event,ADDED,eval-sanitize-30-r0-098-jklxz.18d4b0ccd8d87216,"reason=Pulled count=1 msg=Container image ""busybox:musl"" already present on machine"
0.3664,Event,ADDED,eval-sanitize-30-r0-098-jklxz.18d4b0ccda950eae,reason=Created count=1 msg=Created container: task
0.3665,Event,ADDED,eval-sanitize-30-r0-098-jklxz.18d4b0ccdf80169c,reason=Started count=1 msg=Started container task
0.3667,Event,ADDED,eval-sanitize-30-r0-098-zhjlf.18d4b2b691806da6,"reason=FailedScheduling count=None msg=0/6 nodes are available: 1 c_wall violated: 1 conflicting context pair(s) with node memory, 5 node(s) had untolerated taint(s). no new claims to deallocate, preemption: 0/6 nodes are available: 1 No preemption victims found for incoming pod, 5 Preemption is not helpful for scheduling."
0.3669,Event,ADDED,eval-sanitize-30-r0-098-zhjlf.18d4b2b692288d04,"reason=FailedScheduling count=None msg=0/6 nodes are available: 1 c_wall violated: 1 conflicting context pair(s) with node memory, 5 node(s) had untolerated taint(s). no new claims to deallocate, preemption: 0/6 nodes are available: 1 No preemption victims found for incoming pod, 5 Preemption is not helpful for scheduling."
0.367,Event,ADDED,eval-sanitize-30-r0-098-zhjlf.18d4b2b79dcd6460,reason=Scheduled count=None msg=Successfully assigned compute/eval-sanitize-30-r0-098-zhjlf to kind-worker2
0.3672,Event,ADDED,eval-sanitize-30-r0-098-zhjlf.18d4b2b7bcbe6b67,"reason=Pulled count=1 msg=Container image ""busybox:musl"" already present on machine"
0.3674,Event,ADDED,eval-sanitize-30-r0-098-zhjlf.18d4b2b7be3b1f94,reason=Created count=1 msg=Created container: task
0.3675,Event,ADDED,eval-sanitize-30-r0-098-zhjlf.18d4b2b7c2edf552,reason=Started count=1 msg=Started container task
0.3677,Event,ADDED,eval-sanitize-30-r0-098.18d4b0c8472f979f,reason=SuccessfulCreate count=1 msg=Created pod: eval-sanitize-30-r0-098-jklxz
0.3679,Event,ADDED,eval-sanitize-30-r0-098.18d4b0d3b41adf37,reason=Completed count=1 msg=Job completed
0.368,Event,ADDED,eval-sanitize-30-r0-098.18d4b2b6913e70d2,reason=SuccessfulCreate count=1 msg=Created pod: eval-sanitize-30-r0-098-zhjlf
0.3682,Event,ADDED,eval-sanitize-30-r0-098.18d4b2bd017eaa4b,reason=Completed count=1 msg=Job completed
0.3684,Event,ADDED,eval-sanitize-30-r0-099-db6cp.18d4b2b6c928354f,"reason=FailedScheduling count=None msg=0/6 nodes are available: 1 c_wall violated: 3 conflicting context pair(s) with node memory, 5 node(s) had untolerated taint(s). no new claims to deallocate, preemption: 0/6 nodes are available: 1 No preemption victims found for incoming pod, 5 Preemption is not helpful for scheduling."
0.3685,Event,ADDED,eval-sanitize-30-r0-099-db6cp.18d4b2b6c9b6e351,"reason=FailedScheduling count=None msg=0/6 nodes are available: 1 c_wall violated: 3 conflicting context pair(s) with node memory, 5 node(s) had untolerated taint(s). no new claims to deallocate, preemption: 0/6 nodes are available: 1 No preemption victims found for incoming pod, 5 Preemption is not helpful for scheduling."
0.3687,Event,ADDED,eval-sanitize-30-r0-099-db6cp.18d4b2b7ce300487,reason=Scheduled count=None msg=Successfully assigned compute/eval-sanitize-30-r0-099-db6cp to kind-worker5
0.3689,Event,ADDED,eval-sanitize-30-r0-099-db6cp.18d4b2b7e6f90385,"reason=Pulled count=1 msg=Container image ""busybox:musl"" already present on machine"
0.3691,Event,ADDED,eval-sanitize-30-r0-099-db6cp.18d4b2b7e8311218,reason=Created count=1 msg=Created container: task
0.3693,Event,ADDED,eval-sanitize-30-r0-099-db6cp.18d4b2b7f6fbf584,reason=Started count=1 msg=Started container task
0.3694,Event,ADDED,eval-sanitize-30-r0-099-dp2bc.18d4b0c883dfc525,"reason=FailedScheduling count=None msg=0/6 nodes are available: 6 node(s) had untolerated taint(s). no new claims to deallocate, preemption: 0/6 nodes are available: 6 Preemption is not helpful for scheduling."
0.3696,Event,ADDED,eval-sanitize-30-r0-099-dp2bc.18d4b0cc7d254b95,reason=Scheduled count=None msg=Successfully assigned compute/eval-sanitize-30-r0-099-dp2bc to kind-worker
0.3697,Event,ADDED,eval-sanitize-30-r0-099-dp2bc.18d4b0cc96e10313,"reason=Pulled count=1 msg=Container image ""busybox:musl"" already present on machine"
0.3699,Event,ADDED,eval-sanitize-30-r0-099-dp2bc.18d4b0cc9af6a49e,reason=Created count=1 msg=Created container: task
0.3701,Event,ADDED,eval-sanitize-30-r0-099-dp2bc.18d4b0cca422fb4b,reason=Started count=1 msg=Started container task
0.3702,Event,ADDED,eval-sanitize-30-r0-099.18d4b0c883d32e42,reason=SuccessfulCreate count=1 msg=Created pod: eval-sanitize-30-r0-099-dp2bc
0.3704,Event,ADDED,eval-sanitize-30-r0-099.18d4b0d3b9e5c0ec,reason=Completed count=1 msg=Job completed
0.3706,Event,ADDED,eval-sanitize-30-r0-099.18d4b2b6c8e3c611,reason=SuccessfulCreate count=1 msg=Created pod: eval-sanitize-30-r0-099-db6cp
0.3707,Event,ADDED,eval-sanitize-30-r0-099.18d4b2bebd29e5e3,reason=Completed count=1 msg=Job completed
0.3709,Event,ADDED,eval-sanitize-30-r0-100-cjp8h.18d4b0c8be4f7476,"reason=FailedScheduling count=None msg=0/6 nodes are available: 6 node(s) had untolerated taint(s). no new claims to deallocate, preemption: 0/6 nodes are available: 6 Preemption is not helpful for scheduling."
0.371,Event,ADDED,eval-sanitize-30-r0-100-cjp8h.18d4b0cc7ce4f8e3,"reason=FailedScheduling count=None msg=0/6 nodes are available: 1 c_wall violated: 1 conflicting context pair(s) with node memory, 5 node(s) had untolerated taint(s). no new claims to deallocate, preemption: 0/6 nodes are available: 1 No preemption victims found for incoming pod, 5 Preemption is not helpful for scheduling."
0.3712,Event,ADDED,eval-sanitize-30-r0-100-cjp8h.18d4b0ccb2f15d0d,"reason=FailedScheduling count=None msg=0/6 nodes are available: 1 c_wall violated: 2 conflicting context pair(s) with node memory, 2 c_wall violated: 1 conflicting context pair(s) with node memory, 3 node(s) had untolerated taint(s). no new claims to deallocate, preemption: 0/6 nodes are available: 3 No preemption victims found for incoming pod, 3 Preemption is not helpful for scheduling."
0.3713,Event,ADDED,eval-sanitize-30-r0-100-cjp8h.18d4b0cd438f02f8,reason=Scheduled count=None msg=Successfully assigned compute/eval-sanitize-30-r0-100-cjp8h to kind-worker3
0.3715,Event,ADDED,eval-sanitize-30-r0-100-cjp8h.18d4b0cd5cc402cb,"reason=Pulled count=1 msg=Container image ""busybox:musl"" already present on machine"
0.3718,Event,ADDED,eval-sanitize-30-r0-100-cjp8h.18d4b0cd5e35bb2a,reason=Created count=1 msg=Created container: task
0.3719,Event,ADDED,eval-sanitize-30-r0-100-cjp8h.18d4b0cd62bcd346,reason=Started count=1 msg=Started container task
0.3721,Event,ADDED,eval-sanitize-30-r0-100-r997k.18d4b2b7085335dd,"reason=FailedScheduling count=None msg=0/6 nodes are available: 1 c_wall violated: 1 conflicting context pair(s) with node memory, 5 node(s) had untolerated taint(s). no new claims to deallocate, preemption: 0/6 nodes are available: 1 No preemption victims found for incoming pod, 5 Preemption is not helpful for scheduling."
0.3723,Event,ADDED,eval-sanitize-30-r0-100-r997k.18d4b2b708e6debe,"reason=FailedScheduling count=None msg=0/6 nodes are available: 1 c_wall violated: 1 conflicting context pair(s) with node memory, 5 node(s) had untolerated taint(s). no new claims to deallocate, preemption: 0/6 nodes are available: 1 No preemption victims found for incoming pod, 5 Preemption is not helpful for scheduling."
0.3724,Event,ADDED,eval-sanitize-30-r0-100-r997k.18d4b2b77b041068,reason=Scheduled count=None msg=Successfully assigned compute/eval-sanitize-30-r0-100-r997k to kind-worker2
0.3726,Event,ADDED,eval-sanitize-30-r0-100-r997k.18d4b2b799225e7e,"reason=Pulled count=1 msg=Container image ""busybox:musl"" already present on machine"
0.3728,Event,ADDED,eval-sanitize-30-r0-100-r997k.18d4b2b79a7f8603,reason=Created count=1 msg=Created container: task
0.3729,Event,ADDED,eval-sanitize-30-r0-100-r997k.18d4b2b79e61a6a2,reason=Started count=1 msg=Started container task
0.3731,Event,ADDED,eval-sanitize-30-r0-100.18d4b0c8be4940d4,reason=SuccessfulCreate count=1 msg=Created pod: eval-sanitize-30-r0-100-cjp8h
0.3732,Event,ADDED,eval-sanitize-30-r0-100.18d4b0d45ef82fad,reason=Completed count=1 msg=Job completed
0.3735,Event,ADDED,eval-sanitize-30-r0-100.18d4b2b7080f1755,reason=SuccessfulCreate count=1 msg=Created pod: eval-sanitize-30-r0-100-r997k
0.3736,Event,ADDED,eval-sanitize-30-r0-100.18d4b2be3fbfd9dc,reason=Completed count=1 msg=Job completed
0.3738,Event,ADDED,eval-sanitize-30-r0-101-4ptd2.18d4b0c8fefdbd13,"reason=FailedScheduling count=None msg=0/6 nodes are available: 6 node(s) had untolerated taint(s). no new claims to deallocate, preemption: 0/6 nodes are available: 6 Preemption is not helpful for scheduling."
0.3739,Event,ADDED,eval-sanitize-30-r0-101-4ptd2.18d4b0cc7d7aa18f,"reason=FailedScheduling count=None msg=0/6 nodes are available: 1 c_wall violated: 1 conflicting context pair(s) with node memory, 5 node(s) had untolerated taint(s). no new claims to deallocate, preemption: 0/6 nodes are available: 1 No preemption victims found for incoming pod, 5 Preemption is not helpful for scheduling."
0.3741,Event,ADDED,eval-sanitize-30-r0-101-4ptd2.18d4b0ccbe238ef5,reason=Scheduled count=None msg=Successfully assigned compute/eval-sanitize-30-r0-101-4ptd2 to kind-worker2
0.3742,Event,ADDED,eval-sanitize-30-r0-101-4ptd2.18d4b0ccd8d1d5a8,"reason=Pulled count=1 msg=Container image ""busybox:musl"" already present on machine"
0.3744,Event,ADDED,eval-sanitize-30-r0-101-4ptd2.18d4b0ccda7addc8,reason=Created count=1 msg=Created container: task
0.3746,Event,ADDED,eval-sanitize-30-r0-101-4ptd2.18d4b0ccdf62997d,reason=Started count=1 msg=Started container task
0.3747,Event,ADDED,eval-sanitize-30-r0-101-kxsff.18d4b2b7403d2d40,reason=Scheduled count=None msg=Successfully assigned compute/eval-sanitize-30-r0-101-kxsff to kind-worker4
0.3749,Event,ADDED,eval-sanitize-30-r0-101-kxsff.18d4b2b75ad31e37,"reason=Pulled count=1 msg=Container image ""busybox:musl"" already present on machine"
0.3751,Event,ADDED,eval-sanitize-30-r0-101-kxsff.18d4b2b75c0ed191,reason=Created count=1 msg=Created container: task
0.3752,Event,ADDED,eval-sanitize-30-r0-101-kxsff.18d4b2b75fc6d4d7,reason=Started count=1 msg=Started container task
0.3754,Event,ADDED,eval-sanitize-30-r0-101.18d4b0c8fef33ac4,reason=SuccessfulCreate count=1 msg=Created pod: eval-sanitize-30-r0-101-4ptd2
0.3755,Event,ADDED,eval-sanitize-30-r0-101.18d4b0d42b356396,reason=Completed count=1 msg=Job completed
0.3757,Event,ADDED,eval-sanitize-30-r0-101.18d4b2b73f7604dd,reason=SuccessfulCreate count=1 msg=Created pod: eval-sanitize-30-r0-101-kxsff
0.3759,Event,ADDED,eval-sanitize-30-r0-101.18d4b2bcef91306b,reason=Completed count=1 msg=Job completed
0.376,Event,ADDED,eval-sanitize-30-r0-102-hkml8.18d4b2b78c4b3481,reason=Scheduled count=None msg=Successfully assigned compute/eval-sanitize-30-r0-102-hkml8 to kind-worker
0.3762,Event,ADDED,eval-sanitize-30-r0-102-hkml8.18d4b2b7aa648666,"reason=Pulled count=1 msg=Container image ""busybox:musl"" already present on machine"
0.3764,Event,ADDED,eval-sanitize-30-r0-102-hkml8.18d4b2b7ac12bcb6,reason=Created count=1 msg=Created container: task
0.3765,Event,ADDED,eval-sanitize-30-r0-102-hkml8.18d4b2b7b47dbc6d,reason=Started count=1 msg=Started container task
0.3767,Event,ADDED,eval-sanitize-30-r0-102-vsx4n.18d4b0c93abe5580,"reason=FailedScheduling count=None msg=0/6 nodes are available: 6 node(s) had untolerated taint(s). no new claims to deallocate, preemption: 0/6 nodes are available: 6 Preemption is not helpful for scheduling."
0.3768,Event,ADDED,eval-sanitize-30-r0-102-vsx4n.18d4b0cc7ec92500,reason=Scheduled count=None msg=Successfully assigned compute/eval-sanitize-30-r0-102-vsx4n to kind-worker
0.377,Event,ADDED,eval-sanitize-30-r0-102-vsx4n.18d4b0cc97411f4e,"reason=Pulled count=1 msg=Container image ""busybox:musl"" already present on machine"
0.3771,Event,ADDED,eval-sanitize-30-r0-102-vsx4n.18d4b0cc9b7a6a8c,reason=Created count=1 msg=Created container: task
0.3773,Event,ADDED,eval-sanitize-30-r0-102-vsx4n.18d4b0cca422e3f9,reason=Started count=1 msg=Started container task
0.3775,Event,ADDED,eval-sanitize-30-r0-102.18d4b0c93ab565c2,reason=SuccessfulCreate count=1 msg=Created pod: eval-sanitize-30-r0-102-vsx4n
0.3776,Event,ADDED,eval-sanitize-30-r0-102.18d4b0d38a2ee3a5,reason=Completed count=1 msg=Job completed
0.3778,Event,ADDED,eval-sanitize-30-r0-102.18d4b2b7836f38c0,reason=SuccessfulCreate count=1 msg=Created pod: eval-sanitize-30-r0-102-hkml8
0.378,Event,ADDED,eval-sanitize-30-r0-102.18d4b2be2b203a4f,reason=Completed count=1 msg=Job completed
0.3781,Event,ADDED,eval-sanitize-30-r0-103-jpg4k.18d4b0c97133af22,"reason=FailedScheduling count=None msg=0/6 nodes are available: 6 node(s) had untolerated taint(s). no new claims to deallocate, preemption: 0/6 nodes are available: 6 Preemption is not helpful for scheduling."
0.3783,Event,ADDED,eval-sanitize-30-r0-103-jpg4k.18d4b0cc7e3ca72b,"reason=FailedScheduling count=None msg=0/6 nodes are available: 1 c_wall violated: 1 conflicting context pair(s) with node memory, 5 node(s) had untolerated taint(s). no new claims to deallocate, preemption: 0/6 nodes are available: 1 No preemption victims found for incoming pod, 5 Preemption is not helpful for scheduling."
0.3784,Event,ADDED,eval-sanitize-30-r0-103-jpg4k.18d4b0ccc3388445,"reason=FailedScheduling count=None msg=0/6 nodes are available: 1 c_wall violated: 2 conflicting context pair(s) with node memory, 2 c_wall violated: 1 conflicting context pair(s) with node memory, 3 node(s) had untolerated taint(s). no new claims to deallocate, preemption: 0/6 nodes are available: 3 No preemption victims found for incoming pod, 3 Preemption is not helpful for scheduling."
0.3786,Event,ADDED,eval-sanitize-30-r0-103-jpg4k.18d4b0cd4880bba5,reason=Scheduled count=None msg=Successfully assigned compute/eval-sanitize-30-r0-103-jpg4k to kind-worker3
0.3788,Event,ADDED,eval-sanitize-30-r0-103-jpg4k.18d4b0cd62c64b2a,"reason=Pulled count=1 msg=Container image ""busybox:musl"" already present on machine"
0.379,Event,ADDED,eval-sanitize-30-r0-103-jpg4k.18d4b0cd63ed3a66,reason=Created count=1 msg=Created container: task
0.3791,Event,ADDED,eval-sanitize-30-r0-103-jpg4k.18d4b0cd67e44138,reason=Started count=1 msg=Started container task
0.3793,Event,ADDED,eval-sanitize-30-r0-103-lnnkh.18d4b2b7bc1efcd9,"reason=FailedScheduling count=None msg=0/6 nodes are available: 1 c_wall violated: 1 conflicting context pair(s) with node memory, 1 c_wall violated: 2 conflicting context pair(s) with node memory, 4 node(s) had untolerated taint(s). no new claims to deallocate, preemption: 0/6 nodes are available: 2 No preemption victims found for incoming pod, 4 Preemption is not helpful for scheduling."
0.3794,Event,ADDED,eval-sanitize-30-r0-103-lnnkh.18d4b2b7f82036bd,reason=Scheduled count=None msg=Successfully assigned compute/eval-sanitize-30-r0-103-lnnkh to kind-worker5
0.3796,Event,ADDED,eval-sanitize-30-r0-103-lnnkh.18d4b2b811b8288e,"reason=Pulled count=1 msg=Container image ""busybox:musl"" already present on machine"
0.3797,Event,ADDED,eval-sanitize-30-r0-103-lnnkh.18d4b2b81364b086,reason=Created count=1 msg=Created container: task
0.3799,Event,ADDED,eval-sanitize-30-r0-103-lnnkh.18d4b2b81760d328,reason=Started count=1 msg=Started container task
0.3801,Event,ADDED,eval-sanitize-30-r0-103.18d4b0c9712784fe,reason=SuccessfulCreate count=1 msg=Created pod: eval-sanitize-30-r0-103-jpg4k
0.3802,Event,ADDED,eval-sanitize-30-r0-103.18d4b0d469c1bf51,reason=Completed count=1 msg=Job completed
0.3804,Event,ADDED,eval-sanitize-30-r0-103.18d4b2b7b7c76bf5,reason=SuccessfulCreate count=1 msg=Created pod: eval-sanitize-30-r0-103-lnnkh
0.3806,Event,ADDED,eval-sanitize-30-r0-103.18d4b2bf64507a0e,reason=Completed count=1 msg=Job completed
0.3807,Event,ADDED,eval-sanitize-30-r0-104-84qzl.18d4b2b8020145ca,reason=Scheduled count=None msg=Successfully assigned compute/eval-sanitize-30-r0-104-84qzl to kind-worker3
0.3809,Event,ADDED,eval-sanitize-30-r0-104-84qzl.18d4b2b81848d206,"reason=Pulled count=1 msg=Container image ""busybox:musl"" already present on machine"
0.381,Event,ADDED,eval-sanitize-30-r0-104-84qzl.18d4b2b819625daa,reason=Created count=1 msg=Created container: task
0.3812,Event,ADDED,eval-sanitize-30-r0-104-84qzl.18d4b2b81e7f200b,reason=Started count=1 msg=Started container task
0.3814,Event,ADDED,eval-sanitize-30-r0-104-zmh28.18d4b0c9ad464ec8,"reason=FailedScheduling count=None msg=0/6 nodes are available: 6 node(s) had untolerated taint(s). no new claims to deallocate, preemption: 0/6 nodes are available: 6 Preemption is not helpful for scheduling."
0.3815,Event,ADDED,eval-sanitize-30-r0-104-zmh28.18d4b0cc7f180941,"reason=FailedScheduling count=None msg=0/6 nodes are available: 1 c_wall violated: 1 conflicting context pair(s) with node memory, 5 node(s) had untolerated taint(s). no new claims to deallocate, preemption: 0/6 nodes are available: 1 No preemption victims found for incoming pod, 5 Preemption is not helpful for scheduling."
0.3816,Event,ADDED,eval-sanitize-30-r0-104-zmh28.18d4b0cccdd0c3ff,reason=Scheduled count=None msg=Successfully assigned compute/eval-sanitize-30-r0-104-zmh28 to kind-worker4
0.3818,Event,ADDED,eval-sanitize-30-r0-104-zmh28.18d4b0cce5e610ba,"reason=Pulled count=1 msg=Container image ""busybox:musl"" already present on machine"
0.382,Event,ADDED,eval-sanitize-30-r0-104-zmh28.18d4b0cce747848b,reason=Created count=1 msg=Created container: task
0.3822,Event,ADDED,eval-sanitize-30-r0-104-zmh28.18d4b0cceaa2f3f3,reason=Started count=1 msg=Started container task
0.3824,Event,ADDED,eval-sanitize-30-r0-104.18d4b0c9ad37e29b,reason=SuccessfulCreate count=1 msg=Created pod: eval-sanitize-30-r0-104-zmh28
0.3825,Event,ADDED,eval-sanitize-30-r0-104.18d4b0d44eeae108,reason=Completed count=1 msg=Job completed
0.3827,Event,ADDED,eval-sanitize-30-r0-104.18d4b2b7f90762dc,reason=SuccessfulCreate count=1 msg=Created pod: eval-sanitize-30-r0-104-84qzl
0.3829,Event,ADDED,eval-sanitize-30-r0-104.18d4b2bf8a64d2ef,reason=Completed count=1 msg=Job completed
0.383,Event,ADDED,eval-sanitize-30-r0-105-92lwh.18d4b0c9e842fe26,"reason=FailedScheduling count=None msg=0/6 nodes are available: 6 node(s) had untolerated taint(s). no new claims to deallocate, preemption: 0/6 nodes are available: 6 Preemption is not helpful for scheduling."
0.3832,Event,ADDED,eval-sanitize-30-r0-105-92lwh.18d4b0cc82fb6ab2,reason=Scheduled count=None msg=Successfully assigned compute/eval-sanitize-30-r0-105-92lwh to kind-worker
0.3833,Event,ADDED,eval-sanitize-30-r0-105-92lwh.18d4b0cca429f5a3,"reason=Pulled count=1 msg=Container image ""busybox:musl"" already present on machine"
0.3835,Event,ADDED,eval-sanitize-30-r0-105-92lwh.18d4b0cca73b3556,reason=Created count=1 msg=Created container: task
0.3837,Event,ADDED,eval-sanitize-30-r0-105-92lwh.18d4b0ccab458b1f,reason=Started count=1 msg=Started container task
0.384,Event,ADDED,eval-sanitize-30-r0-105-kmvp2.18d4b2b82f93c658,reason=Scheduled count=None msg=Successfully assigned compute/eval-sanitize-30-r0-105-kmvp2 to kind-worker2
0.3842,Event,ADDED,eval-sanitize-30-r0-105-kmvp2.18d4b2b84f141ebc,"reason=Pulled count=1 msg=Container image ""busybox:musl"" already present on machine"
0.3844,Event,ADDED,eval-sanitize-30-r0-105-kmvp2.18d4b2b850e084a7,reason=Created count=1 msg=Created container: task
0.3845,Event,ADDED,eval-sanitize-30-r0-105-kmvp2.18d4b2b854925c6a,reason=Started count=1 msg=Started container task
0.3848,Event,ADDED,eval-sanitize-30-r0-105.18d4b0c9e83b83b7,reason=SuccessfulCreate count=1 msg=Created pod: eval-sanitize-30-r0-105-92lwh
0.385,Event,ADDED,eval-sanitize-30-r0-105.18d4b0d394150fc4,reason=Completed count=1 msg=Job completed
0.3852,Event,ADDED,eval-sanitize-30-r0-105.18d4b2b82e322268,reason=SuccessfulCreate count=1 msg=Created pod: eval-sanitize-30-r0-105-kmvp2
0.3854,Event,ADDED,eval-sanitize-30-r0-105.18d4b2bf9cbe617c,reason=Completed count=1 msg=Job completed
0.386,Event,ADDED,eval-sanitize-30-r0-106-rztv9.18d4b2b86a8719b6,"reason=FailedScheduling count=None msg=0/6 nodes are available: 1 c_wall violated: 2 conflicting context pair(s) with node memory, 2 node(s) had untolerated taint(s), 3 c_wall violated: 1 conflicting context pair(s) with node memory. no new claims to deallocate, preemption: 0/6 nodes are available: 2 Preemption is not helpful for scheduling, 4 No preemption victims found for incoming pod."
0.3862,Event,ADDED,eval-sanitize-30-r0-106-rztv9.18d4b2b86ed5616e,"reason=FailedScheduling count=None msg=0/6 nodes are available: 1 c_wall violated: 2 conflicting context pair(s) with node memory, 2 node(s) had untolerated taint(s), 3 c_wall violated: 1 conflicting context pair(s) with node memory. no new claims to deallocate, preemption: 0/6 nodes are available: 2 Preemption is not helpful for scheduling, 4 No preemption victims found for incoming pod."
0.3866,Event,ADDED,eval-sanitize-30-r0-106-rztv9.18d4b2b96e58e5bb,"reason=FailedScheduling count=None msg=0/6 nodes are available: 2 c_wall violated: 1 conflicting context pair(s) with node memory, 2 c_wall violated: 2 conflicting context pair(s) with node memory, 2 node(s) had untolerated taint(s). no new claims to deallocate, preemption: 0/6 nodes are available: 2 Preemption is not helpful for scheduling, 4 No preemption victims found for incoming pod."
0.3867,Event,ADDED,eval-sanitize-30-r0-106-rztv9.18d4b2be99d001a6,"reason=FailedScheduling count=None msg=0/6 nodes are available: 2 c_wall violated: 2 conflicting context pair(s) with node memory, 4 node(s) had untolerated taint(s). no new claims to deallocate, preemption: 0/6 nodes are available: 2 No preemption victims found for incoming pod, 4 Preemption is not helpful for scheduling."
0.3869,Event,ADDED,eval-sanitize-30-r0-106-rztv9.18d4b2beabf3bd48,"reason=FailedScheduling count=None msg=0/6 nodes are available: 2 c_wall violated: 2 conflicting context pair(s) with node memory, 4 node(s) had untolerated taint(s). no new claims to deallocate, preemption: 0/6 nodes are available: 2 No preemption victims found for incoming pod, 4 Preemption is not helpful for scheduling."
0.387,Event,ADDED,eval-sanitize-30-r0-106-rztv9.18d4b2beca0f7e01,reason=Scheduled count=None msg=Successfully assigned compute/eval-sanitize-30-r0-106-rztv9 to kind-worker4
0.3872,Event,ADDED,eval-sanitize-30-r0-106-rztv9.18d4b2bee6b9ae2c,"reason=Pulled count=1 msg=Container image ""busybox:musl"" already present on machine"
0.3874,Event,ADDED,eval-sanitize-30-r0-106-rztv9.18d4b2bee9355452,reason=Created count=1 msg=Created container: task
0.3876,Event,ADDED,eval-sanitize-30-r0-106-rztv9.18d4b2beeb793e8b,reason=Started count=1 msg=Started container task
0.3877,Event,ADDED,eval-sanitize-30-r0-106-xpf97.18d4b0ca23f80ae3,"reason=FailedScheduling count=None msg=0/6 nodes are available: 6 node(s) had untolerated taint(s). no new claims to deallocate, preemption: 0/6 nodes are available: 6 Preemption is not helpful for scheduling."
0.3879,Event,ADDED,eval-sanitize-30-r0-106-xpf97.18d4b0cc835afb6d,reason=Scheduled count=None msg=Successfully assigned compute/eval-sanitize-30-r0-106-xpf97 to kind-worker
0.3881,Event,ADDED,eval-sanitize-30-r0-106-xpf97.18d4b0cca430720a,"reason=Pulled count=1 msg=Container image ""busybox:musl"" already present on machine"
0.3882,Event,ADDED,eval-sanitize-30-r0-106-xpf97.18d4b0cca7c4d22b,reason=Created count=1 msg=Created container: task
0.3884,Event,ADDED,eval-sanitize-30-r0-106-xpf97.18d4b0ccae3331d2,reason=Started count=1 msg=Started container task
0.3886,Event,ADDED,eval-sanitize-30-r0-106.18d4b0ca23eba7ea,reason=SuccessfulCreate count=1 msg=Created pod: eval-sanitize-30-r0-106-xpf97
0.3887,Event,ADDED,eval-sanitize-30-r0-106.18d4b0d3a2047335,reason=Completed count=1 msg=Job completed
0.3889,Event,ADDED,eval-sanitize-30-r0-106.18d4b2b8697ce324,reason=SuccessfulCreate count=1 msg=Created pod: eval-sanitize-30-r0-106-rztv9
0.3891,Event,ADDED,eval-sanitize-30-r0-106.18d4b2c473291134,reason=Completed count=1 msg=Job completed
0.3892,Event,ADDED,eval-sanitize-30-r0-107-46mtk.18d4b2b8aee866aa,reason=Scheduled count=None msg=Successfully assigned compute/eval-sanitize-30-r0-107-46mtk to kind-worker2
0.3894,Event,ADDED,eval-sanitize-30-r0-107-46mtk.18d4b2b8d0349413,"reason=Pulled count=1 msg=Container image ""busybox:musl"" already present on machine"
0.3895,Event,ADDED,eval-sanitize-30-r0-107-46mtk.18d4b2b8d14b16e6,reason=Created count=1 msg=Created container: task
0.3897,Event,ADDED,eval-sanitize-30-r0-107-46mtk.18d4b2b8ddbaea0d,reason=Started count=1 msg=Started container task
0.3899,Event,ADDED,eval-sanitize-30-r0-107-zq878.18d4b0ca5fa7b5c2,"reason=FailedScheduling count=None msg=0/6 nodes are available: 6 node(s) had untolerated taint(s). no new claims to deallocate, preemption: 0/6 nodes are available: 6 Preemption is not helpful for scheduling."
0.39,Event,ADDED,eval-sanitize-30-r0-107-zq878.18d4b0cc83030702,"reason=FailedScheduling count=None msg=0/6 nodes are available: 1 c_wall violated: 1 conflicting context pair(s) with node memory, 5 node(s) had untolerated taint(s). no new claims to deallocate, preemption: 0/6 nodes are available: 1 No preemption victims found for incoming pod, 5 Preemption is not helpful for scheduling."
0.3902,Event,ADDED,eval-sanitize-30-r0-107-zq878.18d4b0ccd02cd421,reason=Scheduled count=None msg=Successfully assigned compute/eval-sanitize-30-r0-107-zq878 to kind-worker5
0.3904,Event,ADDED,eval-sanitize-30-r0-107-zq878.18d4b0cceace344b,"reason=Pulled count=1 msg=Container image ""busybox:musl"" already present on machine"
0.3906,Event,ADDED,eval-sanitize-30-r0-107-zq878.18d4b0ccec608827,reason=Created count=1 msg=Created container: task
0.3908,Event,ADDED,eval-sanitize-30-r0-107-zq878.18d4b0ccf0765753,reason=Started count=1 msg=Started container task
0.3909,Event,ADDED,eval-sanitize-30-r0-107.18d4b0ca5f937832,reason=SuccessfulCreate count=1 msg=Created pod: eval-sanitize-30-r0-107-zq878
0.3911,Event,ADDED,eval-sanitize-30-r0-107.18d4b0d3f579b2c7,reason=Completed count=1 msg=Job completed
0.3912,Event,ADDED,eval-sanitize-30-r0-107.18d4b2b8adabddae,reason=SuccessfulCreate count=1 msg=Created pod: eval-sanitize-30-r0-107-46mtk
0.3914,Event,ADDED,eval-sanitize-30-r0-107.18d4b2bfd3c4124e,reason=Completed count=1 msg=Job completed
0.3916,Event,ADDED,eval-sanitize-30-r0-108-fp2pz.18d4b0caa0689cc0,"reason=FailedScheduling count=None msg=0/6 nodes are available: 6 node(s) had untolerated taint(s). no new claims to deallocate, preemption: 0/6 nodes are available: 6 Preemption is not helpful for scheduling."
0.3917,Event,ADDED,eval-sanitize-30-r0-108-fp2pz.18d4b0cc83b9a69b,"reason=FailedScheduling count=None msg=0/6 nodes are available: 1 c_wall violated: 1 conflicting context pair(s) with node memory, 5 node(s) had untolerated taint(s). no new claims to deallocate, preemption: 0/6 nodes are available: 1 No preemption victims found for incoming pod, 5 Preemption is not helpful for scheduling."
0.3919,Event,ADDED,eval-sanitize-30-r0-108-fp2pz.18d4b0ccd623fe64,reason=Scheduled count=None msg=Successfully assigned compute/eval-sanitize-30-r0-108-fp2pz to kind-worker5
0.392,Event,ADDED,eval-sanitize-30-r0-108-fp2pz.18d4b0ccf098b2aa,"reason=Pulled count=1 msg=Container image ""busybox:musl"" already present on machine"
0.3922,Event,ADDED,eval-sanitize-30-r0-108-fp2pz.18d4b0ccf1ee3ec8,reason=Created count=1 msg=Created container: task
0.3924,Event,ADDED,eval-sanitize-30-r0-108-fp2pz.18d4b0ccf6d49c8b,reason=Started count=1 msg=Started container task
0.393,Event,ADDED,eval-sanitize-30-r0-108-vrt7x.18d4b2b8e1d17cc7,reason=Scheduled count=None msg=Successfully assigned compute/eval-sanitize-30-r0-108-vrt7x to kind-worker2
0.3931,Event,ADDED,eval-sanitize-30-r0-108-vrt7x.18d4b2b8ff9a08ca,"reason=Pulled count=1 msg=Container image ""busybox:musl"" already present on machine"
0.3933,Event,ADDED,eval-sanitize-30-r0-108-vrt7x.18d4b2b900cf6044,reason=Created count=1 msg=Created container: task
0.3935,Event,ADDED,eval-sanitize-30-r0-108-vrt7x.18d4b2b908b3c62c,reason=Started count=1 msg=Started container task
0.3937,Event,ADDED,eval-sanitize-30-r0-108.18d4b0caa059c933,reason=SuccessfulCreate count=1 msg=Created pod: eval-sanitize-30-r0-108-fp2pz
0.3939,Event,ADDED,eval-sanitize-30-r0-108.18d4b0d3fe65d2ca,reason=Completed count=1 msg=Job completed
0.394,Event,ADDED,eval-sanitize-30-r0-108.18d4b2b8e09b736b,reason=SuccessfulCreate count=1 msg=Created pod: eval-sanitize-30-r0-108-vrt7x
0.3942,Event,ADDED,eval-sanitize-30-r0-108.18d4b2bfbfbe843b,reason=Completed count=1 msg=Job completed
0.3944,Event,ADDED,eval-sanitize-30-r0-109-7cdcr.18d4b0cad6a88ea5,"reason=FailedScheduling count=None msg=0/6 nodes are available: 6 node(s) had untolerated taint(s). no new claims to deallocate, preemption: 0/6 nodes are available: 6 Preemption is not helpful for scheduling."
0.3945,Event,ADDED,eval-sanitize-30-r0-109-7cdcr.18d4b0cc8540fd55,reason=Scheduled count=None msg=Successfully assigned compute/eval-sanitize-30-r0-109-7cdcr to kind-worker
0.3947,Event,ADDED,eval-sanitize-30-r0-109-7cdcr.18d4b0cca47834b3,"reason=Pulled count=1 msg=Container image ""busybox:musl"" already present on machine"
0.3952,Event,ADDED,eval-sanitize-30-r0-109-7cdcr.18d4b0cca919e9be,reason=Created count=1 msg=Created container: task
0.3954,Event,ADDED,eval-sanitize-30-r0-109-7cdcr.18d4b0ccae2ff1d9,reason=Started count=1 msg=Started container task
0.3955,Event,ADDED,eval-sanitize-30-r0-109-mc9mz.18d4b2b920bfa83a,"reason=FailedScheduling count=None msg=0/6 nodes are available: 1 c_wall violated: 2 conflicting context pair(s) with node memory, 2 node(s) had untolerated taint(s), 3 c_wall violated: 1 conflicting context pair(s) with node memory. no new claims to deallocate, preemption: 0/6 nodes are available: 2 Preemption is not helpful for scheduling, 4 No preemption victims found for incoming pod."
0.3958,Event,ADDED,eval-sanitize-30-r0-109-mc9mz.18d4b2b92640d271,"reason=FailedScheduling count=None msg=0/6 nodes are available: 1 c_wall violated: 2 conflicting context pair(s) with node memory, 2 node(s) had untolerated taint(s), 3 c_wall violated: 1 conflicting context pair(s) with node memory. no new claims to deallocate, preemption: 0/6 nodes are available: 2 Preemption is not helpful for scheduling, 4 No preemption victims found for incoming pod."
0.396,Event,ADDED,eval-sanitize-30-r0-109-mc9mz.18d4b2b9689d4320,"reason=FailedScheduling count=None msg=0/6 nodes are available: 2 c_wall violated: 1 conflicting context pair(s) with node memory, 2 c_wall violated: 2 conflicting context pair(s) with node memory, 2 node(s) had untolerated taint(s). no new claims to deallocate, preemption: 0/6 nodes are available: 2 Preemption is not helpful for scheduling, 4 No preemption victims found for incoming pod."
0.3961,Event,ADDED,eval-sanitize-30-r0-109-mc9mz.18d4b2be9af7df32,"reason=FailedScheduling count=None msg=0/6 nodes are available: 2 c_wall violated: 2 conflicting context pair(s) with node memory, 4 node(s) had untolerated taint(s). no new claims to deallocate, preemption: 0/6 nodes are available: 2 No preemption victims found for incoming pod, 4 Preemption is not helpful for scheduling."
0.3963,Event,ADDED,eval-sanitize-30-r0-109-mc9mz.18d4b2beb1948ad2,"reason=FailedScheduling count=None msg=0/6 nodes are available: 2 c_wall violated: 2 conflicting context pair(s) with node memory, 4 node(s) had untolerated taint(s). no new claims to deallocate, preemption: 0/6 nodes are available: 2 No preemption victims found for incoming pod, 4 Preemption is not helpful for scheduling."
0.3964,Event,ADDED,eval-sanitize-30-r0-109-mc9mz.18d4b2becf9e9a73,reason=Scheduled count=None msg=Successfully assigned compute/eval-sanitize-30-r0-109-mc9mz to kind-worker4
0.3966,Event,ADDED,eval-sanitize-30-r0-109-mc9mz.18d4b2bee8f0ab20,"reason=Pulled count=1 msg=Container image ""busybox:musl"" already present on machine"
0.3968,Event,ADDED,eval-sanitize-30-r0-109-mc9mz.18d4b2beea6e549e,reason=Created count=1 msg=Created container: task
0.3969,Event,ADDED,eval-sanitize-30-r0-109-mc9mz.18d4b2beec87aa7f,reason=Started count=1 msg=Started container task
0.3971,Event,ADDED,eval-sanitize-30-r0-109.18d4b0cad69e496a,reason=SuccessfulCreate count=1 msg=Created pod: eval-sanitize-30-r0-109-7cdcr
0.3972,Event,ADDED,eval-sanitize-30-r0-109.18d4b0d399fbbf79,reason=Completed count=1 msg=Job completed
0.3974,Event,ADDED,eval-sanitize-30-r0-109.18d4b2b91fc44587,reason=SuccessfulCreate count=1 msg=Created pod: eval-sanitize-30-r0-109-mc9mz
0.3976,Event,ADDED,eval-sanitize-30-r0-109.18d4b2c4737c77c3,reason=Completed count=1 msg=Job completed
0.3977,Event,ADDED,eval-sanitize-30-r0-110-jt5gl.18d4b2b9597a43b4,reason=Scheduled count=None msg=Successfully assigned compute/eval-sanitize-30-r0-110-jt5gl to kind-worker5
0.3979,Event,ADDED,eval-sanitize-30-r0-110-jt5gl.18d4b2b9763ed9fa,"reason=Pulled count=1 msg=Container image ""busybox:musl"" already present on machine"
0.3981,Event,ADDED,eval-sanitize-30-r0-110-jt5gl.18d4b2b9782e8c0d,reason=Created count=1 msg=Created container: task
0.3982,Event,ADDED,eval-sanitize-30-r0-110-jt5gl.18d4b2b9803194af,reason=Started count=1 msg=Started container task
0.3984,Event,ADDED,eval-sanitize-30-r0-110-pqq9g.18d4b0cb128abf3c,"reason=FailedScheduling count=None msg=0/6 nodes are available: 6 node(s) had untolerated taint(s). no new claims to deallocate, preemption: 0/6 nodes are available: 6 Preemption is not helpful for scheduling."
0.3985,Event,ADDED,eval-sanitize-30-r0-110-pqq9g.18d4b0cc8579f419,reason=Scheduled count=None msg=Successfully assigned compute/eval-sanitize-30-r0-110-pqq9g to kind-worker
0.3987,Event,ADDED,eval-sanitize-30-r0-110-pqq9g.18d4b0cca45113d3,"reason=Pulled count=1 msg=Container image ""busybox:musl"" already present on machine"
0.3988,Event,ADDED,eval-sanitize-30-r0-110-pqq9g.18d4b0cca84b822d,reason=Created count=1 msg=Created container: task
0.399,Event,ADDED,eval-sanitize-30-r0-110-pqq9g.18d4b0ccae29a58e,reason=Started count=1 msg=Started container task
0.3992,Event,ADDED,eval-sanitize-30-r0-110.18d4b0cb127cff48,reason=SuccessfulCreate count=1 msg=Created pod: eval-sanitize-30-r0-110-pqq9g
0.3993,Event,ADDED,eval-sanitize-30-r0-110.18d4b0d38165dbf8,reason=Completed count=1 msg=Job completed
0.3995,Event,ADDED,eval-sanitize-30-r0-110.18d4b2b957e5733c,reason=SuccessfulCreate count=1 msg=Created pod: eval-sanitize-30-r0-110-jt5gl
0.3997,Event,ADDED,eval-sanitize-30-r0-110.18d4b2bfe7188fb4,reason=Completed count=1 msg=Job completed
0.3998,Event,ADDED,eval-sanitize-30-r0-111-s6jp9.18d4b2b999611f26,reason=Scheduled count=None msg=Successfully assigned compute/eval-sanitize-30-r0-111-s6jp9 to kind-worker5
0.4,Event,ADDED,eval-sanitize-30-r0-111-s6jp9.18d4b2b9ba06cca3,"reason=Pulled count=1 msg=Container image ""busybox:musl"" already present on machine"
0.4002,Event,ADDED,eval-sanitize-30-r0-111-s6jp9.18d4b2b9bb2a9475,reason=Created count=1 msg=Created container: task
0.4003,Event,ADDED,eval-sanitize-30-r0-111-s6jp9.18d4b2b9c390b3c4,reason=Started count=1 msg=Started container task
0.4005,Event,ADDED,eval-sanitize-30-r0-111-vqmfr.18d4b0cb4de6dc1c,"reason=FailedScheduling count=None msg=0/6 nodes are available: 6 node(s) had untolerated taint(s). no new claims to deallocate, preemption: 0/6 nodes are available: 6 Preemption is not helpful for scheduling."
0.4006,Event,ADDED,eval-sanitize-30-r0-111-vqmfr.18d4b0cc88a45ece,"reason=FailedScheduling count=None msg=0/6 nodes are available: 1 c_wall violated: 2 conflicting context pair(s) with node memory, 5 node(s) had untolerated taint(s). no new claims to deallocate, preemption: 0/6 nodes are available: 1 No preemption victims found for incoming pod, 5 Preemption is not helpful for scheduling."
0.4008,Event,ADDED,eval-sanitize-30-r0-111-vqmfr.18d4b0ccdc45ed0c,reason=Scheduled count=None msg=Successfully assigned compute/eval-sanitize-30-r0-111-vqmfr to kind-worker3
0.4009,Event,ADDED,eval-sanitize-30-r0-111-vqmfr.18d4b0ccf6fe7bf3,"reason=Pulled count=1 msg=Container image ""busybox:musl"" already present on machine"
0.4011,Event,ADDED,eval-sanitize-30-r0-111-vqmfr.18d4b0ccf8264c65,reason=Created count=1 msg=Created container: task
0.4013,Event,ADDED,eval-sanitize-30-r0-111-vqmfr.18d4b0ccfb9e33f0,reason=Started count=1 msg=Started container task
0.4015,Event,ADDED,eval-sanitize-30-r0-111.18d4b0cb4dd9cffa,reason=SuccessfulCreate count=1 msg=Created pod: eval-sanitize-30-r0-111-vqmfr
0.4016,Event,ADDED,eval-sanitize-30-r0-111.18d4b0d3e3b9d094,reason=Completed count=1 msg=Job completed
0.4018,Event,ADDED,eval-sanitize-30-r0-111.18d4b2b99800de42,reason=SuccessfulCreate count=1 msg=Created pod: eval-sanitize-30-r0-111-s6jp9
0.402,Event,ADDED,eval-sanitize-30-r0-111.18d4b2c01e70f05b,reason=Completed count=1 msg=Job completed
0.4021,Event,ADDED,eval-sanitize-30-r0-112-lkxtb.18d4b2b9d0368673,reason=Scheduled count=None msg=Successfully assigned compute/eval-sanitize-30-r0-112-lkxtb to kind-worker2
0.4024,Event,ADDED,eval-sanitize-30-r0-112-lkxtb.18d4b2b9f0bd8b09,"reason=Pulled count=1 msg=Container image ""busybox:musl"" already present on machine"
0.4025,Event,ADDED,eval-sanitize-30-r0-112-lkxtb.18d4b2b9f1d4a440,reason=Created count=1 msg=Created container: task
0.4028,Event,ADDED,eval-sanitize-30-r0-112-lkxtb.18d4b2b9fa3c58d2,reason=Started count=1 msg=Started container task
0.4029,Event,ADDED,eval-sanitize-30-r0-112-wwhj6.18d4b0cb8984e716,"reason=FailedScheduling count=None msg=0/6 nodes are available: 6 node(s) had untolerated taint(s). no new claims to deallocate, preemption: 0/6 nodes are available: 6 Preemption is not helpful for scheduling."
0.403,Event,ADDED,eval-sanitize-30-r0-112-wwhj6.18d4b0cc8de8210c,reason=Scheduled count=None msg=Successfully assigned compute/eval-sanitize-30-r0-112-wwhj6 to kind-worker
0.4032,Event,ADDED,eval-sanitize-30-r0-112-wwhj6.18d4b0ccae9dcfe1,"reason=Pulled count=1 msg=Container image ""busybox:musl"" already present on machine"
0.4034,Event,ADDED,eval-sanitize-30-r0-112-wwhj6.18d4b0ccafdce2b6,reason=Created count=1 msg=Created container: task
0.4035,Event,ADDED,eval-sanitize-30-r0-112-wwhj6.18d4b0ccbca4de6b,reason=Started count=1 msg=Started container task
0.4037,Event,ADDED,eval-sanitize-30-r0-112.18d4b0cb897fdaff,reason=SuccessfulCreate count=1 msg=Created pod: eval-sanitize-30-r0-112-wwhj6
0.4039,Event,ADDED,eval-sanitize-30-r0-112.18d4b0d3873d8187,reason=Completed count=1 msg=Job completed
0.404,Event,ADDED,eval-sanitize-30-r0-112.18d4b2b9cefb6d03,reason=SuccessfulCreate count=1 msg=Created pod: eval-sanitize-30-r0-112-lkxtb
0.4042,Event,ADDED,eval-sanitize-30-r0-112.18d4b2c031a42b5a,reason=Completed count=1 msg=Job completed
0.4044,Event,ADDED,eval-sanitize-30-r0-113-twvq5.18d4b0cbc693792d,"reason=FailedScheduling count=None msg=0/6 nodes are available: 6 node(s) had untolerated taint(s). no new claims to deallocate, preemption: 0/6 nodes are available: 6 Preemption is not helpful for scheduling."
0.4045,Event,ADDED,eval-sanitize-30-r0-113-twvq5.18d4b0cc8dbf369a,"reason=FailedScheduling count=None msg=0/6 nodes are available: 1 c_wall violated: 1 conflicting context pair(s) with node memory, 5 node(s) had untolerated taint(s). no new claims to deallocate, preemption: 0/6 nodes are available: 1 No preemption victims found for incoming pod, 5 Preemption is not helpful for scheduling."
0.4047,Event,ADDED,eval-sanitize-30-r0-113-twvq5.18d4b0cce25e21da,reason=Scheduled count=None msg=Successfully assigned compute/eval-sanitize-30-r0-113-twvq5 to kind-worker2
0.4048,Event,ADDED,eval-sanitize-30-r0-113-twvq5.18d4b0ccfb8b8942,"reason=Pulled count=1 msg=Container image ""busybox:musl"" already present on machine"
0.405,Event,ADDED,eval-sanitize-30-r0-113-twvq5.18d4b0ccfca1b0fb,reason=Created count=1 msg=Created container: task
0.4052,Event,ADDED,eval-sanitize-30-r0-113-twvq5.18d4b0cd06b70194,reason=Started count=1 msg=Started container task
0.4053,Event,ADDED,eval-sanitize-30-r0-113-zcfws.18d4b2ba10cdeffd,reason=Scheduled count=None msg=Successfully assigned compute/eval-sanitize-30-r0-113-zcfws to kind-worker2
0.4055,Event,ADDED,eval-sanitize-30-r0-113-zcfws.18d4b2ba2dfda98a,"reason=Pulled count=1 msg=Container image ""busybox:musl"" already present on machine"
0.4056,Event,ADDED,eval-sanitize-30-r0-113-zcfws.18d4b2ba2f53b014,reason=Created count=1 msg=Created container: task
0.4059,Event,ADDED,eval-sanitize-30-r0-113-zcfws.18d4b2ba3722fae6,reason=Started count=1 msg=Started container task
0.4061,Event,ADDED,eval-sanitize-30-r0-113.18d4b0cbc6871c64,reason=SuccessfulCreate count=1 msg=Created pod: eval-sanitize-30-r0-113-twvq5
0.4063,Event,ADDED,eval-sanitize-30-r0-113.18d4b0d43a141c64,reason=Completed count=1 msg=Job completed
0.4064,Event,ADDED,eval-sanitize-30-r0-113.18d4b2ba0f5efe71,reason=SuccessfulCreate count=1 msg=Created pod: eval-sanitize-30-r0-113-zcfws
0.4066,Event,ADDED,eval-sanitize-30-r0-113.18d4b2c04e0e8afb,reason=Completed count=1 msg=Job completed
0.4068,Event,ADDED,eval-sanitize-30-r0-114-2xp2p.18d4b0cc00c5e76e,"reason=FailedScheduling count=None msg=0/6 nodes are available: 6 node(s) had untolerated taint(s). no new claims to deallocate, preemption: 0/6 nodes are available: 6 Preemption is not helpful for scheduling."
0.4071,Event,ADDED,eval-sanitize-30-r0-114-2xp2p.18d4b0cc8f01c63b,"reason=FailedScheduling count=None msg=0/6 nodes are available: 1 c_wall violated: 1 conflicting context pair(s) with node memory, 5 node(s) had untolerated taint(s). no new claims to deallocate, preemption: 0/6 nodes are available: 1 No preemption victims found for incoming pod, 5 Preemption is not helpful for scheduling."
0.4072,Event,ADDED,eval-sanitize-30-r0-114-2xp2p.18d4b0ccf3755f74,reason=Scheduled count=None msg=Successfully assigned compute/eval-sanitize-30-r0-114-2xp2p to kind-worker3
0.4074,Event,ADDED,eval-sanitize-30-r0-114-2xp2p.18d4b0cd0dd98860,"reason=Pulled count=1 msg=Container image ""busybox:musl"" already present on machine"
0.4076,Event,ADDED,eval-sanitize-30-r0-114-2xp2p.18d4b0cd0f89f201,reason=Created count=1 msg=Created container: task
0.4079,Event,ADDED,eval-sanitize-30-r0-114-2xp2p.18d4b0cd146f8081,reason=Started count=1 msg=Started container task
0.4082,Event,ADDED,eval-sanitize-30-r0-114-zwrwr.18d4b2ba4ce7a62b,reason=Scheduled count=None msg=Successfully assigned compute/eval-sanitize-30-r0-114-zwrwr to kind-worker
0.4084,Event,ADDED,eval-sanitize-30-r0-114-zwrwr.18d4b2ba676bc68e,"reason=Pulled count=1 msg=Container image ""busybox:musl"" already present on machine"
0.4086,Event,ADDED,eval-sanitize-30-r0-114-zwrwr.18d4b2ba688ce426,reason=Created count=1 msg=Created container: task
0.4088,Event,ADDED,eval-sanitize-30-r0-114-zwrwr.18d4b2ba72e6dec8,reason=Started count=1 msg=Started container task
0.409,Event,ADDED,eval-sanitize-30-r0-114.18d4b0cc00b722df,reason=SuccessfulCreate count=1 msg=Created pod: eval-sanitize-30-r0-114-2xp2p
0.4092,Event,ADDED,eval-sanitize-30-r0-114.18d4b0d3e9aa97ed,reason=Completed count=1 msg=Job completed
0.4093,Event,ADDED,eval-sanitize-30-r0-114.18d4b2ba477ab263,reason=SuccessfulCreate count=1 msg=Created pod: eval-sanitize-30-r0-114-zwrwr
0.4095,Event,ADDED,eval-sanitize-30-r0-114.18d4b2c0234ecc83,reason=Completed count=1 msg=Job completed
0.4097,Event,ADDED,eval-sanitize-30-r0-115-7nhqh.18d4b2ba89e710d5,reason=Scheduled count=None msg=Successfully assigned compute/eval-sanitize-30-r0-115-7nhqh to kind-worker5
0.4098,Event,ADDED,eval-sanitize-30-r0-115-7nhqh.18d4b2baa91c0536,"reason=Pulled count=1 msg=Container image ""busybox:musl"" already present on machine"
0.41,Event,ADDED,eval-sanitize-30-r0-115-7nhqh.18d4b2baaa43facb,reason=Created count=1 msg=Created container: task
0.4102,Event,ADDED,eval-sanitize-30-r0-115-7nhqh.18d4b2baaeb13c47,reason=Started count=1 msg=Started container task
0.4103,Event,ADDED,eval-sanitize-30-r0-115-jpnx2.18d4b0cc3e2f89e8,"reason=FailedScheduling count=None msg=0/6 nodes are available: 6 node(s) had untolerated taint(s). no new claims to deallocate, preemption: 0/6 nodes are available: 6 Preemption is not helpful for scheduling."
0.4129,Event,ADDED,eval-sanitize-30-r0-115-jpnx2.18d4b0cc8f823a64,"reason=FailedScheduling count=None msg=0/6 nodes are available: 1 c_wall violated: 1 conflicting context pair(s) with node memory, 5 node(s) had untolerated taint(s). no new claims to deallocate, preemption: 0/6 nodes are available: 1 No preemption victims found for incoming pod, 5 Preemption is not helpful for scheduling."
0.413,Event,ADDED,eval-sanitize-30-r0-115-jpnx2.18d4b0cd06b2e752,reason=Scheduled count=None msg=Successfully assigned compute/eval-sanitize-30-r0-115-jpnx2 to kind-worker2
0.4132,Event,ADDED,eval-sanitize-30-r0-115-jpnx2.18d4b0cd20c0fd44,"reason=Pulled count=1 msg=Container image ""busybox:musl"" already present on machine"
0.4134,Event,ADDED,eval-sanitize-30-r0-115-jpnx2.18d4b0cd223fa840,reason=Created count=1 msg=Created container: task
0.4137,Event,ADDED,eval-sanitize-30-r0-115-jpnx2.18d4b0cd27399642,reason=Started count=1 msg=Started container task
0.4139,Event,ADDED,eval-sanitize-30-r0-115.18d4b0cc3e23ead8,reason=SuccessfulCreate count=1 msg=Created pod: eval-sanitize-30-r0-115-jpnx2
0.4141,Event,ADDED,eval-sanitize-30-r0-115.18d4b0d40467e1e3,reason=Completed count=1 msg=Job completed
0.4142,Event,ADDED,eval-sanitize-30-r0-115.18d4b2ba888a796c,reason=SuccessfulCreate count=1 msg=Created pod: eval-sanitize-30-r0-115-7nhqh
0.4145,Event,ADDED,eval-sanitize-30-r0-115.18d4b2c0437fe3f2,reason=Completed count=1 msg=Job completed
0.4146,Event,ADDED,eval-sanitize-30-r0-116-dkshf.18d4b2bac4992720,reason=Scheduled count=None msg=Successfully assigned compute/eval-sanitize-30-r0-116-dkshf to kind-worker3
0.4148,Event,ADDED,eval-sanitize-30-r0-116-dkshf.18d4b2bae1e16bd7,"reason=Pulled count=1 msg=Container image ""busybox:musl"" already present on machine"
0.415,Event,ADDED,eval-sanitize-30-r0-116-dkshf.18d4b2bae2fce20a,reason=Created count=1 msg=Created container: task
0.4151,Event,ADDED,eval-sanitize-30-r0-116-dkshf.18d4b2baedb71d97,reason=Started count=1 msg=Started container task
0.4153,Event,ADDED,eval-sanitize-30-r0-116-ft4pl.18d4b0cc8e5a881c,"reason=FailedScheduling count=None msg=0/6 nodes are available: 1 c_wall violated: 2 conflicting context pair(s) with node memory, 5 node(s) had untolerated taint(s). no new claims to deallocate, preemption: 0/6 nodes are available: 1 No preemption victims found for incoming pod, 5 Preemption is not helpful for scheduling."
0.4154,Event,ADDED,eval-sanitize-30-r0-116-ft4pl.18d4b0cced105912,"reason=FailedScheduling count=None msg=0/6 nodes are available: 1 c_wall violated: 2 conflicting context pair(s) with node memory, 1 node(s) had untolerated taint(s), 4 c_wall violated: 1 conflicting context pair(s) with node memory. no new claims to deallocate, preemption: 0/6 nodes are available: 1 Preemption is not helpful for scheduling, 5 No preemption victims found for incoming pod."
0.4158,Event,ADDED,eval-sanitize-30-r0-116-ft4pl.18d4b0cd527aca7e,"reason=FailedScheduling count=None msg=0/6 nodes are available: 1 c_wall violated: 2 conflicting context pair(s) with node memory, 1 node(s) had untolerated taint(s), 4 c_wall violated: 1 conflicting context pair(s) with node memory. no new claims to deallocate, preemption: 0/6 nodes are available: 1 Preemption is not helpful for scheduling, 5 No preemption victims found for incoming pod."
0.416,Event,ADDED,eval-sanitize-30-r0-116-ft4pl.18d4b0d3a8a5a8df,"reason=FailedScheduling count=None msg=0/6 nodes are available: 2 c_wall violated: 1 conflicting context pair(s) with node memory, 4 node(s) had untolerated taint(s). no new claims to deallocate, preemption: 0/6 nodes are available: 2 No preemption victims found for incoming pod, 4 Preemption is not helpful for scheduling."
0.4163,Event,ADDED,eval-sanitize-30-r0-116-ft4pl.18d4b0d3bf2daba4,"reason=FailedScheduling count=None msg=0/6 nodes are available: 2 c_wall violated: 1 conflicting context pair(s) with node memory, 4 node(s) had untolerated taint(s). no new claims to deallocate, preemption: 0/6 nodes are available: 2 No preemption victims found for incoming pod, 4 Preemption is not helpful for scheduling."
0.4165,Event,ADDED,eval-sanitize-30-r0-116-ft4pl.18d4b0d3d14fa91c,"reason=FailedScheduling count=None msg=0/6 nodes are available: 1 c_wall violated: 1 conflicting context pair(s) with node memory, 5 node(s) had untolerated taint(s). no new claims to deallocate, preemption: 0/6 nodes are available: 1 No preemption victims found for incoming pod, 5 Preemption is not helpful for scheduling."
0.4167,Event,ADDED,eval-sanitize-30-r0-116-ft4pl.18d4b0da8103c505,reason=Scheduled count=None msg=Successfully assigned compute/eval-sanitize-30-r0-116-ft4pl to kind-worker
0.4169,Event,ADDED,eval-sanitize-30-r0-116-ft4pl.18d4b0da9eb42e67,"reason=Pulled count=1 msg=Container image ""busybox:musl"" already present on machine"
0.4171,Event,ADDED,eval-sanitize-30-r0-116-ft4pl.18d4b0daa302055d,reason=Created count=1 msg=Created container: task
0.4173,Event,ADDED,eval-sanitize-30-r0-116-ft4pl.18d4b0daa8c16f05,reason=Started count=1 msg=Started container task
0.4175,Event,ADDED,eval-sanitize-30-r0-116.18d4b0cc78c6685a,reason=SuccessfulCreate count=1 msg=Created pod: eval-sanitize-30-r0-116-ft4pl
0.4177,Event,ADDED,eval-sanitize-30-r0-116.18d4b0e22b5dd0ab,reason=Completed count=1 msg=Job completed
0.418,Event,ADDED,eval-sanitize-30-r0-116.18d4b2bac33a3b72,reason=SuccessfulCreate count=1 msg=Created pod: eval-sanitize-30-r0-116-dkshf
0.4182,Event,ADDED,eval-sanitize-30-r0-116.18d4b2c073eb2520,reason=Completed count=1 msg=Job completed
0.4183,Event,ADDED,eval-sanitize-30-r0-117-945gz.18d4b2bafff53111,"reason=FailedScheduling count=None msg=0/6 nodes are available: 2 c_wall violated: 1 conflicting context pair(s) with node memory, 2 c_wall violated: 2 conflicting context pair(s) with node memory, 2 node(s) had untolerated taint(s). no new claims to deallocate, preemption: 0/6 nodes are available: 2 Preemption is not helpful for scheduling, 4 No preemption victims found for incoming pod."
0.4187,Event,ADDED,eval-sanitize-30-r0-117-945gz.18d4b2bb0425a887,"reason=FailedScheduling count=None msg=0/6 nodes are available: 2 c_wall violated: 1 conflicting context pair(s) with node memory, 2 c_wall violated: 2 conflicting context pair(s) with node memory, 2 node(s) had untolerated taint(s). no new claims to deallocate, preemption: 0/6 nodes are available: 2 Preemption is not helpful for scheduling, 4 No preemption victims found for incoming pod."
0.4189,Event,ADDED,eval-sanitize-30-r0-117-945gz.18d4b2be9a5baba2,"reason=FailedScheduling count=None msg=0/6 nodes are available: 2 c_wall violated: 2 conflicting context pair(s) with node memory, 4 node(s) had untolerated taint(s). no new claims to deallocate, preemption: 0/6 nodes are available: 2 No preemption victims found for incoming pod, 4 Preemption is not helpful for scheduling."
0.419,Event,ADDED,eval-sanitize-30-r0-117-945gz.18d4b2beac585bc5,"reason=FailedScheduling count=None msg=0/6 nodes are available: 2 c_wall violated: 2 conflicting context pair(s) with node memory, 4 node(s) had untolerated taint(s). no new claims to deallocate, preemption: 0/6 nodes are available: 2 No preemption victims found for incoming pod, 4 Preemption is not helpful for scheduling."
0.4193,Event,ADDED,eval-sanitize-30-r0-117-945gz.18d4b2beca6855da,reason=Scheduled count=None msg=Successfully assigned compute/eval-sanitize-30-r0-117-945gz to kind-worker4
0.4195,Event,ADDED,eval-sanitize-30-r0-117-945gz.18d4b2bee62aee18,"reason=Pulled count=1 msg=Container image ""busybox:musl"" already present on machine"
0.4197,Event,ADDED,eval-sanitize-30-r0-117-945gz.18d4b2bee86b26bb,reason=Created count=1 msg=Created container: task
0.42,Event,ADDED,eval-sanitize-30-r0-117-945gz.18d4b2beeae1ec6d,reason=Started count=1 msg=Started container task
0.4201,Event,ADDED,eval-sanitize-30-r0-117-9zw25.18d4b0ccc53b8f8f,reason=Scheduled count=None msg=Successfully assigned compute/eval-sanitize-30-r0-117-9zw25 to kind-worker5
0.4203,Event,ADDED,eval-sanitize-30-r0-117-9zw25.18d4b0ccdfe42797,"reason=Pulled count=1 msg=Container image ""busybox:musl"" already present on machine"
0.4205,Event,ADDED,eval-sanitize-30-r0-117-9zw25.18d4b0cce127a5cc,reason=Created count=1 msg=Created container: task
0.4208,Event,ADDED,eval-sanitize-30-r0-117-9zw25.18d4b0cce4d9f7da,reason=Started count=1 msg=Started container task
0.421,Event,ADDED,eval-sanitize-30-r0-117.18d4b0ccbeda2796,reason=SuccessfulCreate count=1 msg=Created pod: eval-sanitize-30-r0-117-9zw25
0.4212,Event,ADDED,eval-sanitize-30-r0-117.18d4b0d410455031,reason=Completed count=1 msg=Job completed
0.4213,Event,ADDED,eval-sanitize-30-r0-117.18d4b2baff0d9be5,reason=SuccessfulCreate count=1 msg=Created pod: eval-sanitize-30-r0-117-945gz
0.4217,Event,ADDED,eval-sanitize-30-r0-117.18d4b2c47385f37e,reason=Completed count=1 msg=Job completed
0.4219,Event,ADDED,eval-sanitize-30-r0-118-prn59.18d4b0ccf954860f,"reason=FailedScheduling count=None msg=0/6 nodes are available: 1 c_wall violated: 2 conflicting context pair(s) with node memory, 1 node(s) had untolerated taint(s), 4 c_wall violated: 1 conflicting context pair(s) with node memory. no new claims to deallocate, preemption: 0/6 nodes are available: 1 Preemption is not helpful for scheduling, 5 No preemption victims found for incoming pod."
0.4221,Event,ADDED,eval-sanitize-30-r0-118-prn59.18d4b0cd5e230dac,"reason=FailedScheduling count=None msg=0/6 nodes are available: 1 c_wall violated: 2 conflicting context pair(s) with node memory, 1 node(s) had untolerated taint(s), 4 c_wall violated: 1 conflicting context pair(s) with node memory. no new claims to deallocate, preemption: 0/6 nodes are available: 1 Preemption is not helpful for scheduling, 5 No preemption victims found for incoming pod."
0.4224,Event,ADDED,eval-sanitize-30-r0-118-prn59.18d4b0d3a96a02f8,"reason=FailedScheduling count=None msg=0/6 nodes are available: 2 c_wall violated: 1 conflicting context pair(s) with node memory, 4 node(s) had untolerated taint(s). no new claims to deallocate, preemption: 0/6 nodes are available: 2 No preemption victims found for incoming pod, 4 Preemption is not helpful for scheduling."
0.4226,Event,ADDED,eval-sanitize-30-r0-118-prn59.18d4b0d3c038ef00,"reason=FailedScheduling count=None msg=0/6 nodes are available: 1 c_wall violated: 1 conflicting context pair(s) with node memory, 5 node(s) had untolerated taint(s). no new claims to deallocate, preemption: 0/6 nodes are available: 1 No preemption victims found for incoming pod, 5 Preemption is not helpful for scheduling."
0.4228,Event,ADDED,eval-sanitize-30-r0-118-prn59.18d4b0d3cbe52180,"reason=FailedScheduling count=None msg=0/6 nodes are available: 1 c_wall violated: 1 conflicting context pair(s) with node memory, 5 node(s) had untolerated taint(s). no new claims to deallocate, preemption: 0/6 nodes are available: 1 No preemption victims found for incoming pod, 5 Preemption is not helpful for scheduling."
0.4232,Event,ADDED,eval-sanitize-30-r0-118-prn59.18d4b0da73ce0c77,reason=Scheduled count=None msg=Successfully assigned compute/eval-sanitize-30-r0-118-prn59 to kind-worker
0.4234,Event,ADDED,eval-sanitize-30-r0-118-prn59.18d4b0da8fd87173,"reason=Pulled count=1 msg=Container image ""busybox:musl"" already present on machine"
0.4236,Event,ADDED,eval-sanitize-30-r0-118-prn59.18d4b0da93619aa8,reason=Created count=1 msg=Created container: task
0.4239,Event,ADDED,eval-sanitize-30-r0-118-prn59.18d4b0da97b79f52,reason=Started count=1 msg=Started container task
0.4241,Event,ADDED,eval-sanitize-30-r0-118-rpnpm.18d4b2bb35d23387,"reason=FailedScheduling count=None msg=0/6 nodes are available: 1 c_wall violated: 1 conflicting context pair(s) with node memory, 2 node(s) had untolerated taint(s), 3 c_wall violated: 2 conflicting context pair(s) with node memory. no new claims to deallocate, preemption: 0/6 nodes are available: 2 Preemption is not helpful for scheduling, 4 No preemption victims found for incoming pod."
0.4243,Event,ADDED,eval-sanitize-30-r0-118-rpnpm.18d4b2bb39b62a1f,"reason=FailedScheduling count=None msg=0/6 nodes are available: 1 c_wall violated: 1 conflicting context pair(s) with node memory, 2 node(s) had untolerated taint(s), 3 c_wall violated: 2 conflicting context pair(s) with node memory. no new claims to deallocate, preemption: 0/6 nodes are available: 2 Preemption is not helpful for scheduling, 4 No preemption victims found for incoming pod."
0.4246,Event,ADDED,eval-sanitize-30-r0-118-rpnpm.18d4b2be95af39e2,"reason=FailedScheduling count=None msg=0/6 nodes are available: 1 c_wall violated: 1 conflicting context pair(s) with node memory, 1 c_wall violated: 2 conflicting context pair(s) with node memory, 4 node(s) had untolerated taint(s). no new claims to deallocate, preemption: 0/6 nodes are available: 2 No preemption victims found for incoming pod, 4 Preemption is not helpful for scheduling."
0.4247,Event,ADDED,eval-sanitize-30-r0-118-rpnpm.18d4b2beab908952,"reason=FailedScheduling count=None msg=0/6 nodes are available: 1 c_wall violated: 1 conflicting context pair(s) with node memory, 1 c_wall violated: 2 conflicting context pair(s) with node memory, 4 node(s) had untolerated taint(s). no new claims to deallocate, preemption: 0/6 nodes are available: 2 No preemption victims found for incoming pod, 4 Preemption is not helpful for scheduling."
0.4249,Event,ADDED,eval-sanitize-30-r0-118-rpnpm.18d4b2bec9c2476d,reason=Scheduled count=None msg=Successfully assigned compute/eval-sanitize-30-r0-118-rpnpm to kind-worker4
0.4252,Event,ADDED,eval-sanitize-30-r0-118-rpnpm.18d4b2bee698098f,"reason=Pulled count=1 msg=Container image ""busybox:musl"" already present on machine"
0.4255,Event,ADDED,eval-sanitize-30-r0-118-rpnpm.18d4b2bee8effd9a,reason=Created count=1 msg=Created container: task
0.4257,Event,ADDED,eval-sanitize-30-r0-118-rpnpm.18d4b2beeb791568,reason=Started count=1 msg=Started container task
0.4259,Event,ADDED,eval-sanitize-30-r0-118.18d4b0cceee1ee44,reason=SuccessfulCreate count=1 msg=Created pod: eval-sanitize-30-r0-118-prn59
0.4262,Event,ADDED,eval-sanitize-30-r0-118.18d4b0e240245e4c,reason=Completed count=1 msg=Job completed
0.4263,Event,ADDED,eval-sanitize-30-r0-118.18d4b2bb34f885ae,reason=SuccessfulCreate count=1 msg=Created pod: eval-sanitize-30-r0-118-rpnpm
0.4265,Event,ADDED,eval-sanitize-30-r0-118.18d4b2c47404726c,reason=Completed count=1 msg=Job completed
0.4267,Event,ADDED,eval-sanitize-30-r0-119-4bvjd.18d4b0cd35039109,reason=Scheduled count=None msg=Successfully assigned compute/eval-sanitize-30-r0-119-4bvjd to kind-worker4
0.4268,Event,ADDED,eval-sanitize-30-r0-119-4bvjd.18d4b0cd4ef04fc0,"reason=Pulled count=1 msg=Container image ""busybox:musl"" already present on machine"
0.427,Event,ADDED,eval-sanitize-30-r0-119-4bvjd.18d4b0cd501e7181,reason=Created count=1 msg=Created container: task
0.4272,Event,ADDED,eval-sanitize-30-r0-119-4bvjd.18d4b0cd521c55c9,reason=Started count=1 msg=Started container task
0.4273,Event,ADDED,eval-sanitize-30-r0-119-k7v87.18d4b2bb78824961,reason=Scheduled count=None msg=Successfully assigned compute/eval-sanitize-30-r0-119-k7v87 to kind-worker2
0.4276,Event,ADDED,eval-sanitize-30-r0-119-k7v87.18d4b2bb95816845,"reason=Pulled count=1 msg=Container image ""busybox:musl"" already present on machine"
0.4278,Event,ADDED,eval-sanitize-30-r0-119-k7v87.18d4b2bb96925f9c,reason=Created count=1 msg=Created container: task
0.428,Event,ADDED,eval-sanitize-30-r0-119-k7v87.18d4b2bb9f665a0d,reason=Started count=1 msg=Started container task
0.4281,Event,ADDED,eval-sanitize-30-r0-119.18d4b0cd2c1279bf,reason=SuccessfulCreate count=1 msg=Created pod: eval-sanitize-30-r0-119-4bvjd
0.4283,Event,ADDED,eval-sanitize-30-r0-119.18d4b0d44bf03b57,reason=Completed count=1 msg=Job completed
0.4285,Event,ADDED,eval-sanitize-30-r0-119.18d4b2bb70a052f8,reason=SuccessfulCreate count=1 msg=Created pod: eval-sanitize-30-r0-119-k7v87
0.4286,Event,ADDED,eval-sanitize-30-r0-119.18d4b2c137227a7c,reason=Completed count=1 msg=Job completed
0.4288,Event,ADDED,eval-sanitize-30-r0-120-k4tgk.18d4b2bbad318c99,"reason=FailedScheduling count=None msg=0/6 nodes are available: 2 c_wall violated: 1 conflicting context pair(s) with node memory, 2 c_wall violated: 2 conflicting context pair(s) with node memory, 2 node(s) had untolerated taint(s). no new claims to deallocate, preemption: 0/6 nodes are available: 2 Preemption is not helpful for scheduling, 4 No preemption victims found for incoming pod."
0.429,Event,ADDED,eval-sanitize-30-r0-120-k4tgk.18d4b2bbb1450ef6,"reason=FailedScheduling count=None msg=0/6 nodes are available: 2 c_wall violated: 1 conflicting context pair(s) with node memory, 2 c_wall violated: 2 conflicting context pair(s) with node memory, 2 node(s) had untolerated taint(s). no new claims to deallocate, preemption: 0/6 nodes are available: 2 Preemption is not helpful for scheduling, 4 No preemption victims found for incoming pod."
0.4292,Event,ADDED,eval-sanitize-30-r0-120-k4tgk.18d4b2bea31830ab,"reason=FailedScheduling count=None msg=0/6 nodes are available: 2 c_wall violated: 2 conflicting context pair(s) with node memory, 4 node(s) had untolerated taint(s). no new claims to deallocate, preemption: 0/6 nodes are available: 2 No preemption victims found for incoming pod, 4 Preemption is not helpful for scheduling."
0.4294,Event,ADDED,eval-sanitize-30-r0-120-k4tgk.18d4b2beba2ab4e1,reason=Scheduled count=None msg=Successfully assigned compute/eval-sanitize-30-r0-120-k4tgk to kind-worker4
0.4295,Event,ADDED,eval-sanitize-30-r0-120-k4tgk.18d4b2bed39278d1,"reason=Pulled count=1 msg=Container image ""busybox:musl"" already present on machine"
0.4297,Event,ADDED,eval-sanitize-30-r0-120-k4tgk.18d4b2bed4c0b39b,reason=Created count=1 msg=Created container: task
0.43,Event,ADDED,eval-sanitize-30-r0-120-k4tgk.18d4b2bed70d0dc2,reason=Started count=1 msg=Started container task
0.4301,Event,ADDED,eval-sanitize-30-r0-120-z4pcd.18d4b0cd77989284,reason=Scheduled count=None msg=Successfully assigned compute/eval-sanitize-30-r0-120-z4pcd to kind-worker5
0.4303,Event,ADDED,eval-sanitize-30-r0-120-z4pcd.18d4b0cd9250f591,"reason=Pulled count=1 msg=Container image ""busybox:musl"" already present on machine"
0.4305,Event,ADDED,eval-sanitize-30-r0-120-z4pcd.18d4b0cd94126121,reason=Created count=1 msg=Created container: task
0.4307,Event,ADDED,eval-sanitize-30-r0-120-z4pcd.18d4b0cd9837c3b8,reason=Started count=1 msg=Started container task
0.4309,Event,ADDED,eval-sanitize-30-r0-120.18d4b0cd66c18265,reason=SuccessfulCreate count=1 msg=Created pod: eval-sanitize-30-r0-120-z4pcd
0.4311,Event,ADDED,eval-sanitize-30-r0-120.18d4b0d485f019a9,reason=Completed count=1 msg=Job completed
0.4312,Event,ADDED,eval-sanitize-30-r0-120.18d4b2bbac3737e8,reason=SuccessfulCreate count=1 msg=Created pod: eval-sanitize-30-r0-120-k4tgk
0.4314,Event,ADDED,eval-sanitize-30-r0-120.18d4b2c47384ddb6,reason=Completed count=1 msg=Job completed
0.4316,Event,ADDED,eval-sanitize-30-r0-121-b57px.18d4b0cdacda1c2e,"reason=FailedScheduling count=None msg=0/6 nodes are available: 1 c_wall violated: 2 conflicting context pair(s) with node memory, 1 node(s) had untolerated taint(s), 4 c_wall violated: 1 conflicting context pair(s) with node memory. no new claims to deallocate, preemption: 0/6 nodes are available: 1 Preemption is not helpful for scheduling, 5 No preemption victims found for incoming pod."
0.4317,Event,ADDED,eval-sanitize-30-r0-121-b57px.18d4b0cde881b22a,"reason=FailedScheduling count=None msg=0/6 nodes are available: 1 c_wall violated: 2 conflicting context pair(s) with node memory, 1 node(s) had untolerated taint(s), 4 c_wall violated: 1 conflicting context pair(s) with node memory. no new claims to deallocate, preemption: 0/6 nodes are available: 1 Preemption is not helpful for scheduling, 5 No preemption victims found for incoming pod."
0.4319,Event,ADDED,eval-sanitize-30-r0-121-b57px.18d4b0d3b07eb916,"reason=FailedScheduling count=None msg=0/6 nodes are available: 2 c_wall violated: 1 conflicting context pair(s) with node memory, 4 node(s) had untolerated taint(s). no new claims to deallocate, preemption: 0/6 nodes are available: 2 No preemption victims found for incoming pod, 4 Preemption is not helpful for scheduling."
0.4321,Event,ADDED,eval-sanitize-30-r0-121-b57px.18d4b0d3c265e6e8,"reason=FailedScheduling count=None msg=0/6 nodes are available: 1 c_wall violated: 1 conflicting context pair(s) with node memory, 5 node(s) had untolerated taint(s). no new claims to deallocate, preemption: 0/6 nodes are available: 1 No preemption victims found for incoming pod, 5 Preemption is not helpful for scheduling."
0.4322,Event,ADDED,eval-sanitize-30-r0-121-b57px.18d4b0d3cc3d0c7e,"reason=FailedScheduling count=None msg=0/6 nodes are available: 1 c_wall violated: 1 conflicting context pair(s) with node memory, 5 node(s) had untolerated taint(s). no new claims to deallocate, preemption: 0/6 nodes are available: 1 No preemption victims found for incoming pod, 5 Preemption is not helpful for scheduling."
0.4324,Event,ADDED,eval-sanitize-30-r0-121-b57px.18d4b0da74667519,"reason=FailedScheduling count=None msg=0/6 nodes are available: 1 c_wall violated: 1 conflicting context pair(s) with node memory, 5 node(s) had untolerated taint(s). no new claims to deallocate, preemption: 0/6 nodes are available: 1 No preemption victims found for incoming pod, 5 Preemption is not helpful for scheduling."
0.4325,Event,ADDED,eval-sanitize-30-r0-121-b57px.18d4b0daa6942b2f,"reason=FailedScheduling count=None msg=0/6 nodes are available: 1 c_wall violated: 1 conflicting context pair(s) with node memory, 1 c_wall violated: 2 conflicting context pair(s) with node memory, 4 node(s) had untolerated taint(s). no new claims to deallocate, preemption: 0/6 nodes are available: 2 No preemption victims found for incoming pod, 4 Preemption is not helpful for scheduling."
0.4327,Event,ADDED,eval-sanitize-30-r0-121-b57px.18d4b0db1b0932d2,reason=Scheduled count=None msg=Successfully assigned compute/eval-sanitize-30-r0-121-b57px to kind-worker3
0.4329,Event,ADDED,eval-sanitize-30-r0-121-b57px.18d4b0db35b44610,"reason=Pulled count=1 msg=Container image ""busybox:musl"" already present on machine"
0.433,Event,ADDED,eval-sanitize-30-r0-121-b57px.18d4b0db36f7e4fa,reason=Created count=1 msg=Created container: task
0.4332,Event,ADDED,eval-sanitize-30-r0-121-b57px.18d4b0db3c4904e6,reason=Started count=1 msg=Started container task
0.4334,Event,ADDED,eval-sanitize-30-r0-121-wwc4h.18d4b2bbec6120eb,"reason=FailedScheduling count=None msg=0/6 nodes are available: 2 c_wall violated: 1 conflicting context pair(s) with node memory, 2 c_wall violated: 2 conflicting context pair(s) with node memory, 2 node(s) had untolerated taint(s). no new claims to deallocate, preemption: 0/6 nodes are available: 2 Preemption is not helpful for scheduling, 4 No preemption victims found for incoming pod."
0.4335,Event,ADDED,eval-sanitize-30-r0-121-wwc4h.18d4b2bbf2179af4,"reason=FailedScheduling count=None msg=0/6 nodes are available: 2 c_wall violated: 1 conflicting context pair(s) with node memory, 2 c_wall violated: 2 conflicting context pair(s) with node memory, 2 node(s) had untolerated taint(s). no new claims to deallocate, preemption: 0/6 nodes are available: 2 Preemption is not helpful for scheduling, 4 No preemption victims found for incoming pod."
0.4337,Event,ADDED,eval-sanitize-30-r0-121-wwc4h.18d4b2be9482fd86,"reason=FailedScheduling count=None msg=0/6 nodes are available: 2 c_wall violated: 2 conflicting context pair(s) with node memory, 4 node(s) had untolerated taint(s). no new claims to deallocate, preemption: 0/6 nodes are available: 2 No preemption victims found for incoming pod, 4 Preemption is not helpful for scheduling."
0.434,Event,ADDED,eval-sanitize-30-r0-121-wwc4h.18d4b2bea606d583,"reason=FailedScheduling count=None msg=0/6 nodes are available: 2 c_wall violated: 2 conflicting context pair(s) with node memory, 4 node(s) had untolerated taint(s). no new claims to deallocate, preemption: 0/6 nodes are available: 2 No preemption victims found for incoming pod, 4 Preemption is not helpful for scheduling."
0.4342,Event,ADDED,eval-sanitize-30-r0-121-wwc4h.18d4b2bec744a413,reason=Scheduled count=None msg=Successfully assigned compute/eval-sanitize-30-r0-121-wwc4h to kind-worker4
0.4343,Event,ADDED,eval-sanitize-30-r0-121-wwc4h.18d4b2bee4cd3153,"reason=Pulled count=1 msg=Container image ""busybox:musl"" already present on machine"
0.4345,Event,ADDED,eval-sanitize-30-r0-121-wwc4h.18d4b2bee693d210,reason=Created count=1 msg=Created container: task
0.4348,Event,ADDED,eval-sanitize-30-r0-121-wwc4h.18d4b2bee8d6ec20,reason=Started count=1 msg=Started container task
0.435,Event,ADDED,eval-sanitize-30-r0-121.18d4b0cda561d1b9,reason=SuccessfulCreate count=1 msg=Created pod: eval-sanitize-30-r0-121-b57px
0.4352,Event,ADDED,eval-sanitize-30-r0-121.18d4b0e346669bbc,reason=Completed count=1 msg=Job completed
0.4353,Event,ADDED,eval-sanitize-30-r0-121.18d4b2bbeb3836f0,reason=SuccessfulCreate count=1 msg=Created pod: eval-sanitize-30-r0-121-wwc4h
0.4356,Event,ADDED,eval-sanitize-30-r0-121.18d4b2c4747a1ee1,reason=Completed count=1 msg=Job completed
0.4357,Event,ADDED,eval-sanitize-30-r0-122-jvmxb.18d4b2bc249fcb2f,reason=Scheduled count=None msg=Successfully assigned compute/eval-sanitize-30-r0-122-jvmxb to kind-worker2
0.4359,Event,ADDED,eval-sanitize-30-r0-122-jvmxb.18d4b2bc4061eea9,"reason=Pulled count=1 msg=Container image ""busybox:musl"" already present on machine"
0.4361,Event,ADDED,eval-sanitize-30-r0-122-jvmxb.18d4b2bc417e5851,reason=Created count=1 msg=Created container: task
0.4362,Event,ADDED,eval-sanitize-30-r0-122-jvmxb.18d4b2bc4e41889d,reason=Started count=1 msg=Started container task
0.4364,Event,ADDED,eval-sanitize-30-r0-122-vtf8n.18d4b0cdf7a12f22,reason=Scheduled count=None msg=Successfully assigned compute/eval-sanitize-30-r0-122-vtf8n to kind-worker3
0.4366,Event,ADDED,eval-sanitize-30-r0-122-vtf8n.18d4b0ce1b0090ee,"reason=Pulled count=1 msg=Container image ""busybox:musl"" already present on machine"
0.4368,Event,ADDED,eval-sanitize-30-r0-122-vtf8n.18d4b0ce1c373eee,reason=Created count=1 msg=Created container: task
0.4369,Event,ADDED,eval-sanitize-30-r0-122-vtf8n.18d4b0ce2a0ff9f9,reason=Started count=1 msg=Started container task
0.4371,Event,ADDED,eval-sanitize-30-r0-122.18d4b0cde32a65a3,reason=SuccessfulCreate count=1 msg=Created pod: eval-sanitize-30-r0-122-vtf8n
0.4375,Event,ADDED,eval-sanitize-30-r0-122.18d4b0d4c04fa931,reason=Completed count=1 msg=Job completed
0.4377,Event,ADDED,eval-sanitize-30-r0-122.18d4b2bc23705c65,reason=SuccessfulCreate count=1 msg=Created pod: eval-sanitize-30-r0-122-jvmxb
0.4379,Event,ADDED,eval-sanitize-30-r0-122.18d4b2c1b3dff121,reason=Completed count=1 msg=Job completed
0.4381,Event,ADDED,eval-sanitize-30-r0-123-hf9bk.18d4b0ce3badc215,reason=Scheduled count=None msg=Successfully assigned compute/eval-sanitize-30-r0-123-hf9bk to kind-worker3
0.4384,Event,ADDED,eval-sanitize-30-r0-123-hf9bk.18d4b0ce5798b189,"reason=Pulled count=1 msg=Container image ""busybox:musl"" already present on machine"
0.4385,Event,ADDED,eval-sanitize-30-r0-123-hf9bk.18d4b0ce58c75733,reason=Created count=1 msg=Created container: task
0.4387,Event,ADDED,eval-sanitize-30-r0-123-hf9bk.18d4b0ce5f084ea4,reason=Started count=1 msg=Started container task
0.4389,Event,ADDED,eval-sanitize-30-r0-123-rpc27.18d4b2bc6dd3d705,reason=Scheduled count=None msg=Successfully assigned compute/eval-sanitize-30-r0-123-rpc27 to kind-worker2
0.439,Event,ADDED,eval-sanitize-30-r0-123-rpc27.18d4b2bc8f5ea4a0,"reason=Pulled count=1 msg=Container image ""busybox:musl"" already present on machine"
0.4392,Event,ADDED,eval-sanitize-30-r0-123-rpc27.18d4b2bc90a4801b,reason=Created count=1 msg=Created container: task
0.4394,Event,ADDED,eval-sanitize-30-r0-123-rpc27.18d4b2bc946879c8,reason=Started count=1 msg=Started container task
0.4395,Event,ADDED,eval-sanitize-30-r0-123.18d4b0ce2c16e3d8,reason=SuccessfulCreate count=1 msg=Created pod: eval-sanitize-30-r0-123-hf9bk
0.4397,Event,ADDED,eval-sanitize-30-r0-123.18d4b0d4cc1fa49c,reason=Completed count=1 msg=Job completed
0.4399,Event,ADDED,eval-sanitize-30-r0-123.18d4b2bc61c27db8,reason=SuccessfulCreate count=1 msg=Created pod: eval-sanitize-30-r0-123-rpc27
0.44,Event,ADDED,eval-sanitize-30-r0-123.18d4b2c2259d5a32,reason=Completed count=1 msg=Job completed
0.4402,Event,ADDED,eval-sanitize-30-r0-124-j56lq.18d4b0ce74a818de,reason=Scheduled count=None msg=Successfully assigned compute/eval-sanitize-30-r0-124-j56lq to kind-worker2
0.4405,Event,ADDED,eval-sanitize-30-r0-124-j56lq.18d4b0ce8ebf8701,"reason=Pulled count=1 msg=Container image ""busybox:musl"" already present on machine"
0.4407,Event,ADDED,eval-sanitize-30-r0-124-j56lq.18d4b0ce9017347a,reason=Created count=1 msg=Created container: task
0.4408,Event,ADDED,eval-sanitize-30-r0-124-j56lq.18d4b0ce92db81a4,reason=Started count=1 msg=Started container task
0.4411,Event,ADDED,eval-sanitize-30-r0-124-kslxg.18d4b2bca4da3143,"reason=FailedScheduling count=None msg=0/6 nodes are available: 1 c_wall violated: 1 conflicting context pair(s) with node memory, 2 node(s) had untolerated taint(s), 3 c_wall violated: 2 conflicting context pair(s) with node memory. no new claims to deallocate, preemption: 0/6 nodes are available: 2 Preemption is not helpful for scheduling, 4 No preemption victims found for incoming pod."
0.4414,Event,ADDED,eval-sanitize-30-r0-124-kslxg.18d4b2bcc30d30ee,"reason=FailedScheduling count=None msg=0/6 nodes are available: 1 c_wall violated: 1 conflicting context pair(s) with node memory, 2 node(s) had untolerated taint(s), 3 c_wall violated: 2 conflicting context pair(s) with node memory. no new claims to deallocate, preemption: 0/6 nodes are available: 2 Preemption is not helpful for scheduling, 4 No preemption victims found for incoming pod."
0.4416,Event,ADDED,eval-sanitize-30-r0-124-kslxg.18d4b2bea360ee34,"reason=FailedScheduling count=None msg=0/6 nodes are available: 1 c_wall violated: 1 conflicting context pair(s) with node memory, 1 c_wall violated: 2 conflicting context pair(s) with node memory, 4 node(s) had untolerated taint(s). no new claims to deallocate, preemption: 0/6 nodes are available: 2 No preemption victims found for incoming pod, 4 Preemption is not helpful for scheduling."
0.442,Event,ADDED,eval-sanitize-30-r0-124-kslxg.18d4b2bebddf4681,reason=Scheduled count=None msg=Successfully assigned compute/eval-sanitize-30-r0-124-kslxg to kind-worker4
0.4422,Event,ADDED,eval-sanitize-30-r0-124-kslxg.18d4b2bed532b8da,"reason=Pulled count=1 msg=Container image ""busybox:musl"" already present on machine"
0.4424,Event,ADDED,eval-sanitize-30-r0-124-kslxg.18d4b2bed66d78a4,reason=Created count=1 msg=Created container: task
0.4428,Event,ADDED,eval-sanitize-30-r0-124-kslxg.18d4b2bed8783b5c,reason=Started count=1 msg=Started container task
0.443,Event,ADDED,eval-sanitize-30-r0-124.18d4b0ce674697d5,reason=SuccessfulCreate count=1 msg=Created pod: eval-sanitize-30-r0-124-j56lq
0.4431,Event,ADDED,eval-sanitize-30-r0-124.18d4b0d4dafa7cea,reason=Completed count=1 msg=Job completed
0.4433,Event,ADDED,eval-sanitize-30-r0-124.18d4b2bc9a942dfa,reason=SuccessfulCreate count=1 msg=Created pod: eval-sanitize-30-r0-124-kslxg
0.4437,Event,ADDED,eval-sanitize-30-r0-124.18d4b2c474534f52,reason=Completed count=1 msg=Job completed
0.4439,Event,ADDED,eval-sanitize-30-r0-125-k5tn2.18d4b0ce9b730aaf,reason=Scheduled count=None msg=Successfully assigned compute/eval-sanitize-30-r0-125-k5tn2 to kind-worker4
0.4441,Event,ADDED,eval-sanitize-30-r0-125-k5tn2.18d4b0ceb6b1aa7c,"reason=Pulled count=1 msg=Container image ""busybox:musl"" already present on machine"
0.4442,Event,ADDED,eval-sanitize-30-r0-125-k5tn2.18d4b0ceb7e93cb3,reason=Created count=1 msg=Created container: task
0.4445,Event,ADDED,eval-sanitize-30-r0-125-k5tn2.18d4b0cebbf8f6c5,reason=Started count=1 msg=Started container task
0.4447,Event,ADDED,eval-sanitize-30-r0-125-m7scc.18d4b2bcdbb243e3,reason=Scheduled count=None msg=Successfully assigned compute/eval-sanitize-30-r0-125-m7scc to kind-worker
0.4449,Event,ADDED,eval-sanitize-30-r0-125-m7scc.18d4b2bcf5f84aab,"reason=Pulled count=1 msg=Container image ""busybox:musl"" already present on machine"
0.4453,Event,ADDED,eval-sanitize-30-r0-125-m7scc.18d4b2bcf73745c2,reason=Created count=1 msg=Created container: task
0.4454,Event,ADDED,eval-sanitize-30-r0-125-m7scc.18d4b2bcfbeb77fb,reason=Started count=1 msg=Started container task
0.4456,Event,ADDED,eval-sanitize-30-r0-125.18d4b0ce90bcc2fc,reason=SuccessfulCreate count=1 msg=Created pod: eval-sanitize-30-r0-125-k5tn2
0.4458,Event,ADDED,eval-sanitize-30-r0-125.18d4b0d4e9cf2b4c,reason=Completed count=1 msg=Job completed
0.4461,Event,ADDED,eval-sanitize-30-r0-125.18d4b2bcd6f727c9,reason=SuccessfulCreate count=1 msg=Created pod: eval-sanitize-30-r0-125-m7scc
0.4463,Event,ADDED,eval-sanitize-30-r0-125.18d4b2c289fe1741,reason=Completed count=1 msg=Job completed
0.4466,Event,ADDED,eval-sanitize-30-r0-126-56n28.18d4b0ced793130e,reason=Scheduled count=None msg=Successfully assigned compute/eval-sanitize-30-r0-126-56n28 to kind-worker3
0.4467,Event,ADDED,eval-sanitize-30-r0-126-56n28.18d4b0cef12d4580,"reason=Pulled count=1 msg=Container image ""busybox:musl"" already present on machine"
0.447,Event,ADDED,eval-sanitize-30-r0-126-56n28.18d4b0cef24cb5ae,reason=Created count=1 msg=Created container: task
0.4472,Event,ADDED,eval-sanitize-30-r0-126-56n28.18d4b0cef752ed8b,reason=Started count=1 msg=Started container task
0.4474,Event,ADDED,eval-sanitize-30-r0-126-fvnbj.18d4b2bd23211d53,reason=Scheduled count=None msg=Successfully assigned compute/eval-sanitize-30-r0-126-fvnbj to kind-worker2
0.4477,Event,ADDED,eval-sanitize-30-r0-126-fvnbj.18d4b2bd3f0411da,"reason=Pulled count=1 msg=Container image ""busybox:musl"" already present on machine"
0.4479,Event,ADDED,eval-sanitize-30-r0-126-fvnbj.18d4b2bd403ff71d,reason=Created count=1 msg=Created container: task
0.448,Event,ADDED,eval-sanitize-30-r0-126-fvnbj.18d4b2bd43cdc04e,reason=Started count=1 msg=Started container task
0.4482,Event,ADDED,eval-sanitize-30-r0-126.18d4b0cecc885f3c,reason=SuccessfulCreate count=1 msg=Created pod: eval-sanitize-30-r0-126-56n28
0.4485,Event,ADDED,eval-sanitize-30-r0-126.18d4b0d4fbdd0df2,reason=Completed count=1 msg=Job completed
0.4487,Event,ADDED,eval-sanitize-30-r0-126.18d4b2bd1af51f0b,reason=SuccessfulCreate count=1 msg=Created pod: eval-sanitize-30-r0-126-fvnbj
0.4489,Event,ADDED,eval-sanitize-30-r0-126.18d4b2c2d933dd1d,reason=Completed count=1 msg=Job completed
0.449,Event,ADDED,eval-sanitize-30-r0-127-vgknk.18d4b0cf13b18260,reason=Scheduled count=None msg=Successfully assigned compute/eval-sanitize-30-r0-127-vgknk to kind-worker4
0.4494,Event,ADDED,eval-sanitize-30-r0-127-vgknk.18d4b0cf2e0bf156,"reason=Pulled count=1 msg=Container image ""busybox:musl"" already present on machine"
0.4496,Event,ADDED,eval-sanitize-30-r0-127-vgknk.18d4b0cf2f23ed1b,reason=Created count=1 msg=Created container: task
0.4498,Event,ADDED,eval-sanitize-30-r0-127-vgknk.18d4b0cf33b21e23,reason=Started count=1 msg=Started container task
0.4502,Event,ADDED,eval-sanitize-30-r0-127-w552x.18d4b2bdaa0c9bf8,"reason=FailedScheduling count=None msg=0/6 nodes are available: 1 c_wall violated: 1 conflicting context pair(s) with node memory, 2 node(s) had untolerated taint(s), 3 c_wall violated: 2 conflicting context pair(s) with node memory. no new claims to deallocate, preemption: 0/6 nodes are available: 2 Preemption is not helpful for scheduling, 4 No preemption victims found for incoming pod."
0.4504,Event,ADDED,eval-sanitize-30-r0-127-w552x.18d4b2bdb0acd7bb,"reason=FailedScheduling count=None msg=0/6 nodes are available: 1 c_wall violated: 1 conflicting context pair(s) with node memory, 2 node(s) had untolerated taint(s), 3 c_wall violated: 2 conflicting context pair(s) with node memory. no new claims to deallocate, preemption: 0/6 nodes are available: 2 Preemption is not helpful for scheduling, 4 No preemption victims found for incoming pod."
0.4505,Event,ADDED,eval-sanitize-30-r0-127-w552x.18d4b2be9f7dc245,"reason=FailedScheduling count=None msg=0/6 nodes are available: 1 c_wall violated: 1 conflicting context pair(s) with node memory, 1 c_wall violated: 2 conflicting context pair(s) with node memory, 4 node(s) had untolerated taint(s). no new claims to deallocate, preemption: 0/6 nodes are available: 2 No preemption victims found for incoming pod, 4 Preemption is not helpful for scheduling."
0.4507,Event,ADDED,eval-sanitize-30-r0-127-w552x.18d4b2beb2ac251d,reason=Scheduled count=None msg=Successfully assigned compute/eval-sanitize-30-r0-127-w552x to kind-worker4
0.4509,Event,ADDED,eval-sanitize-30-r0-127-w552x.18d4b2becd36ecd9,"reason=Pulled count=1 msg=Container image ""busybox:musl"" already present on machine"
0.451,Event,ADDED,eval-sanitize-30-r0-127-w552x.18d4b2bece8b8c8b,reason=Created count=1 msg=Created container: task
0.4512,Event,ADDED,eval-sanitize-30-r0-127-w552x.18d4b2bed2900ab3,reason=Started count=1 msg=Started container task
0.4514,Event,ADDED,eval-sanitize-30-r0-127.18d4b0cf07edfcf2,reason=SuccessfulCreate count=1 msg=Created pod: eval-sanitize-30-r0-127-vgknk
0.4516,Event,ADDED,eval-sanitize-30-r0-127.18d4b0d4c924bede,reason=Completed count=1 msg=Job completed
0.4519,Event,ADDED,eval-sanitize-30-r0-127.18d4b2bda7fb3f16,reason=SuccessfulCreate count=1 msg=Created pod: eval-sanitize-30-r0-127-w552x
0.4522,Event,ADDED,eval-sanitize-30-r0-127.18d4b2c47474b105,reason=Completed count=1 msg=Job completed
0.4524,Event,ADDED,eval-sanitize-30-r0-128-xh2wl.18d4b2be3252c54a,"reason=FailedScheduling count=None msg=0/6 nodes are available: 2 c_wall violated: 1 conflicting context pair(s) with node memory, 2 c_wall violated: 2 conflicting context pair(s) with node memory, 2 node(s) had untolerated taint(s). no new claims to deallocate, preemption: 0/6 nodes are available: 2 Preemption is not helpful for scheduling, 4 No preemption victims found for incoming pod."
0.4526,Event,ADDED,eval-sanitize-30-r0-128-xh2wl.18d4b2be34b14182,"reason=FailedScheduling count=None msg=0/6 nodes are available: 2 c_wall violated: 1 conflicting context pair(s) with node memory, 2 c_wall violated: 2 conflicting context pair(s) with node memory, 2 node(s) had untolerated taint(s). no new claims to deallocate, preemption: 0/6 nodes are available: 2 Preemption is not helpful for scheduling, 4 No preemption victims found for incoming pod."
0.4528,Event,ADDED,eval-sanitize-30-r0-128-xh2wl.18d4b2bea5bd0d63,"reason=FailedScheduling count=None msg=0/6 nodes are available: 2 c_wall violated: 2 conflicting context pair(s) with node memory, 4 node(s) had untolerated taint(s). no new claims to deallocate, preemption: 0/6 nodes are available: 2 No preemption victims found for incoming pod, 4 Preemption is not helpful for scheduling."
0.453,Event,ADDED,eval-sanitize-30-r0-128-xh2wl.18d4b2bebeb2d243,reason=Scheduled count=None msg=Successfully assigned compute/eval-sanitize-30-r0-128-xh2wl to kind-worker4
0.4532,Event,ADDED,eval-sanitize-30-r0-128-xh2wl.18d4b2bed673aae0,"reason=Pulled count=1 msg=Container image ""busybox:musl"" already present on machine"
0.4534,Event,ADDED,eval-sanitize-30-r0-128-xh2wl.18d4b2bed7ac4773,reason=Created count=1 msg=Created container: task
0.4537,Event,ADDED,eval-sanitize-30-r0-128-xh2wl.18d4b2bed9af31d4,reason=Started count=1 msg=Started container task
0.454,Event,ADDED,eval-sanitize-30-r0-128-xsqk8.18d4b0cf4e616cde,reason=Scheduled count=None msg=Successfully assigned compute/eval-sanitize-30-r0-128-xsqk8 to kind-worker4
0.4542,Event,ADDED,eval-sanitize-30-r0-128-xsqk8.18d4b0cf6689a1c1,"reason=Pulled count=1 msg=Container image ""busybox:musl"" already present on machine"
0.4545,Event,ADDED,eval-sanitize-30-r0-128-xsqk8.18d4b0cf67a900e7,reason=Created count=1 msg=Created container: task
0.4546,Event,ADDED,eval-sanitize-30-r0-128-xsqk8.18d4b0cf69d487e7,reason=Started count=1 msg=Started container task
0.4548,Event,ADDED,eval-sanitize-30-r0-128.18d4b0cf434590c8,reason=SuccessfulCreate count=1 msg=Created pod: eval-sanitize-30-r0-128-xsqk8
0.455,Event,ADDED,eval-sanitize-30-r0-128.18d4b0d4f2d90562,reason=Completed count=1 msg=Job completed
0.4553,Event,ADDED,eval-sanitize-30-r0-128.18d4b2be317b81bd,reason=SuccessfulCreate count=1 msg=Created pod: eval-sanitize-30-r0-128-xh2wl
0.4555,Event,ADDED,eval-sanitize-30-r0-128.18d4b2c473852092,reason=Completed count=1 msg=Job completed
0.4556,Event,ADDED,eval-sanitize-30-r0-129-62c4p.18d4b2be7bd4f007,"reason=FailedScheduling count=None msg=0/6 nodes are available: 1 c_wall violated: 2 conflicting context pair(s) with node memory, 2 c_wall violated: 1 conflicting context pair(s) with node memory, 3 node(s) had untolerated taint(s). no new claims to deallocate, preemption: 0/6 nodes are available: 3 No preemption victims found for incoming pod, 3 Preemption is not helpful for scheduling."
0.456,Event,ADDED,eval-sanitize-30-r0-129-62c4p.18d4b2be95107c9e,"reason=FailedScheduling count=None msg=0/6 nodes are available: 1 c_wall violated: 1 conflicting context pair(s) with node memory, 1 c_wall violated: 2 conflicting context pair(s) with node memory, 4 node(s) had untolerated taint(s). no new claims to deallocate, preemption: 0/6 nodes are available: 2 No preemption victims found for incoming pod, 4 Preemption is not helpful for scheduling."
0.4562,Event,ADDED,eval-sanitize-30-r0-129-62c4p.18d4b2bea64f69b7,"reason=FailedScheduling count=None msg=0/6 nodes are available: 1 c_wall violated: 1 conflicting context pair(s) with node memory, 1 c_wall violated: 2 conflicting context pair(s) with node memory, 4 node(s) had untolerated taint(s). no new claims to deallocate, preemption: 0/6 nodes are available: 2 No preemption victims found for incoming pod, 4 Preemption is not helpful for scheduling."
0.4564,Event,ADDED,eval-sanitize-30-r0-129-62c4p.18d4b2bed3fb5733,"reason=FailedScheduling count=None msg=0/6 nodes are available: 2 c_wall violated: 1 conflicting context pair(s) with node memory, 4 node(s) had untolerated taint(s). no new claims to deallocate, preemption: 0/6 nodes are available: 2 No preemption victims found for incoming pod, 4 Preemption is not helpful for scheduling."
0.4567,Event,ADDED,eval-sanitize-30-r0-129-62c4p.18d4b2bef8352af7,"reason=FailedScheduling count=None msg=0/6 nodes are available: 1 c_wall violated: 1 conflicting context pair(s) with node memory, 5 node(s) had untolerated taint(s). no new claims to deallocate, preemption: 0/6 nodes are available: 1 No preemption victims found for incoming pod, 5 Preemption is not helpful for scheduling."
0.4569,Event,ADDED,eval-sanitize-30-r0-129-62c4p.18d4b2c5c5f9da20,reason=Scheduled count=None msg=Successfully assigned compute/eval-sanitize-30-r0-129-62c4p to kind-worker
0.4571,Event,ADDED,eval-sanitize-30-r0-129-62c4p.18d4b2c5e95736b9,"reason=Pulled count=1 msg=Container image ""busybox:musl"" already present on machine"
0.4573,Event,ADDED,eval-sanitize-30-r0-129-62c4p.18d4b2c5ecbf0632,reason=Created count=1 msg=Created container: task
0.4576,Event,ADDED,eval-sanitize-30-r0-129-62c4p.18d4b2c5f1bef335,reason=Started count=1 msg=Started container task
0.4579,Event,ADDED,eval-sanitize-30-r0-129-7wfsm.18d4b0cf8ef4bd7e,reason=Scheduled count=None msg=Successfully assigned compute/eval-sanitize-30-r0-129-7wfsm to kind-worker5
0.4581,Event,ADDED,eval-sanitize-30-r0-129-7wfsm.18d4b0cfa7dac2e8,"reason=Pulled count=1 msg=Container image ""busybox:musl"" already present on machine"
0.4584,Event,ADDED,eval-sanitize-30-r0-129-7wfsm.18d4b0cfa8f1c9a6,reason=Created count=1 msg=Created container: task
0.4585,Event,ADDED,eval-sanitize-30-r0-129-7wfsm.18d4b0cfaaf5b02e,reason=Started count=1 msg=Started container task
0.4587,Event,ADDED,eval-sanitize-30-r0-129.18d4b0cf8552c337,reason=SuccessfulCreate count=1 msg=Created pod: eval-sanitize-30-r0-129-7wfsm
0.4589,Event,ADDED,eval-sanitize-30-r0-129.18d4b0d54bb3a013,reason=Completed count=1 msg=Job completed
0.4591,Event,ADDED,eval-sanitize-30-r0-129.18d4b2be72a81d60,reason=SuccessfulCreate count=1 msg=Created pod: eval-sanitize-30-r0-129-62c4p
0.4594,Event,ADDED,eval-sanitize-30-r0-129.18d4b2ccc4658286,reason=Completed count=1 msg=Job completed
0.4596,Event,ADDED,eval-sanitize-30-r0-130-chxn4.18d4b2bea28836c7,"reason=FailedScheduling count=None msg=0/6 nodes are available: 2 c_wall violated: 2 conflicting context pair(s) with node memory, 4 node(s) had untolerated taint(s). no new claims to deallocate, preemption: 0/6 nodes are available: 2 No preemption victims found for incoming pod, 4 Preemption is not helpful for scheduling."
0.4597,Event,ADDED,eval-sanitize-30-r0-130-chxn4.18d4b2beb7771ef4,"reason=FailedScheduling count=None msg=0/6 nodes are available: 1 c_wall violated: 1 conflicting context pair(s) with node memory, 2 c_wall violated: 2 conflicting context pair(s) with node memory, 3 node(s) had untolerated taint(s). no new claims to deallocate, preemption: 0/6 nodes are available: 3 No preemption victims found for incoming pod, 3 Preemption is not helpful for scheduling."
0.4599,Event,ADDED,eval-sanitize-30-r0-130-chxn4.18d4b2becf979cd9,"reason=FailedScheduling count=None msg=0/6 nodes are available: 2 c_wall violated: 2 conflicting context pair(s) with node memory, 4 node(s) had untolerated taint(s). no new claims to deallocate, preemption: 0/6 nodes are available: 2 No preemption victims found for incoming pod, 4 Preemption is not helpful for scheduling."
0.4602,Event,ADDED,eval-sanitize-30-r0-130-chxn4.18d4b2bed566808e,"reason=FailedScheduling count=None msg=0/6 nodes are available: 2 c_wall violated: 2 conflicting context pair(s) with node memory, 4 node(s) had untolerated taint(s). no new claims to deallocate, preemption: 0/6 nodes are available: 2 No preemption victims found for incoming pod, 4 Preemption is not helpful for scheduling."
0.4605,Event,ADDED,eval-sanitize-30-r0-130-chxn4.18d4b2bef80fed4d,"reason=FailedScheduling count=None msg=0/6 nodes are available: 1 c_wall violated: 2 conflicting context pair(s) with node memory, 5 node(s) had untolerated taint(s). no new claims to deallocate, preemption: 0/6 nodes are available: 1 No preemption victims found for incoming pod, 5 Preemption is not helpful for scheduling."
0.4607,Event,ADDED,eval-sanitize-30-r0-130-chxn4.18d4b2c5b2ad0100,reason=Scheduled count=None msg=Successfully assigned compute/eval-sanitize-30-r0-130-chxn4 to kind-worker
0.4609,Event,ADDED,eval-sanitize-30-r0-130-chxn4.18d4b2c5d26d9097,"reason=Pulled count=1 msg=Container image ""busybox:musl"" already present on machine"
0.461,Event,ADDED,eval-sanitize-30-r0-130-chxn4.18d4b2c5d5322b56,reason=Created count=1 msg=Created container: task
0.4614,Event,ADDED,eval-sanitize-30-r0-130-chxn4.18d4b2c5d943a500,reason=Started count=1 msg=Started container task
0.4616,Event,ADDED,eval-sanitize-30-r0-130-gtvzl.18d4b0cfca8b5d89,reason=Scheduled count=None msg=Successfully assigned compute/eval-sanitize-30-r0-130-gtvzl to kind-worker5
0.4618,Event,ADDED,eval-sanitize-30-r0-130-gtvzl.18d4b0cfe3b99202,"reason=Pulled count=1 msg=Container image ""busybox:musl"" already present on machine"
0.4621,Event,ADDED,eval-sanitize-30-r0-130-gtvzl.18d4b0cfe4d5879c,reason=Created count=1 msg=Created container: task
0.4623,Event,ADDED,eval-sanitize-30-r0-130-gtvzl.18d4b0cfe6d12778,reason=Started count=1 msg=Started container task
0.4624,Event,ADDED,eval-sanitize-30-r0-130.18d4b0cfc04c229e,reason=SuccessfulCreate count=1 msg=Created pod: eval-sanitize-30-r0-130-gtvzl
0.4626,Event,ADDED,eval-sanitize-30-r0-130.18d4b0d57be785a3,reason=Completed count=1 msg=Job completed
0.4628,Event,ADDED,eval-sanitize-30-r0-130.18d4b2be9c332890,reason=SuccessfulCreate count=1 msg=Created pod: eval-sanitize-30-r0-130-chxn4
0.463,Event,ADDED,eval-sanitize-30-r0-130.18d4b2ccdc67f693,reason=Completed count=1 msg=Job completed
0.4632,Event,ADDED,eval-sanitize-30-r0-131-7fpbb.18d4b0d0009b9731,reason=Scheduled count=None msg=Successfully assigned compute/eval-sanitize-30-r0-131-7fpbb to kind-worker5
0.4633,Event,ADDED,eval-sanitize-30-r0-131-7fpbb.18d4b0d019a41b3e,"reason=Pulled count=1 msg=Container image ""busybox:musl"" already present on machine"
0.4636,Event,ADDED,eval-sanitize-30-r0-131-7fpbb.18d4b0d01ab5c012,reason=Created count=1 msg=Created container: task
0.4638,Event,ADDED,eval-sanitize-30-r0-131-7fpbb.18d4b0d01cb8b158,reason=Started count=1 msg=Started container task
0.464,Event,ADDED,eval-sanitize-30-r0-131-9hvx6.18d4b2bee0ff9da0,"reason=FailedScheduling count=None msg=0/6 nodes are available: 2 c_wall violated: 2 conflicting context pair(s) with node memory, 4 node(s) had untolerated taint(s). no new claims to deallocate, preemption: 0/6 nodes are available: 2 No preemption victims found for incoming pod, 4 Preemption is not helpful for scheduling."
0.4642,Event,ADDED,eval-sanitize-30-r0-131-9hvx6.18d4b2bee1deabe4,"reason=FailedScheduling count=None msg=0/6 nodes are available: 2 c_wall violated: 2 conflicting context pair(s) with node memory, 4 node(s) had untolerated taint(s). no new claims to deallocate, preemption: 0/6 nodes are available: 2 No preemption victims found for incoming pod, 4 Preemption is not helpful for scheduling."
0.4644,Event,ADDED,eval-sanitize-30-r0-131-9hvx6.18d4b2bef863d32b,"reason=FailedScheduling count=None msg=0/6 nodes are available: 1 c_wall violated: 2 conflicting context pair(s) with node memory, 5 node(s) had untolerated taint(s). no new claims to deallocate, preemption: 0/6 nodes are available: 1 No preemption victims found for incoming pod, 5 Preemption is not helpful for scheduling."
0.4646,Event,ADDED,eval-sanitize-30-r0-131-9hvx6.18d4b2c5a48f63ba,reason=Scheduled count=None msg=Successfully assigned compute/eval-sanitize-30-r0-131-9hvx6 to kind-worker
0.4649,Event,ADDED,eval-sanitize-30-r0-131-9hvx6.18d4b2c5bf89662d,"reason=Pulled count=1 msg=Container image ""busybox:musl"" already present on machine"
0.465,Event,ADDED,eval-sanitize-30-r0-131-9hvx6.18d4b2c5c1b54d80,reason=Created count=1 msg=Created container: task
0.4652,Event,ADDED,eval-sanitize-30-r0-131-9hvx6.18d4b2c5c6453830,reason=Started count=1 msg=Started container task
0.4654,Event,ADDED,eval-sanitize-30-r0-131.18d4b0cff5ee7026,reason=SuccessfulCreate count=1 msg=Created pod: eval-sanitize-30-r0-131-7fpbb
0.4656,Event,ADDED,eval-sanitize-30-r0-131.18d4b0d5b0444c58,reason=Completed count=1 msg=Job completed
0.4658,Event,ADDED,eval-sanitize-30-r0-131.18d4b2bee08f5fb3,reason=SuccessfulCreate count=1 msg=Created pod: eval-sanitize-30-r0-131-9hvx6
0.4661,Event,ADDED,eval-sanitize-30-r0-131.18d4b2ccca67021a,reason=Completed count=1 msg=Job completed
0.4663,Event,ADDED,eval-sanitize-30-r0-132-78cmt.18d4b2befba62d00,"reason=FailedScheduling count=None msg=0/6 nodes are available: 1 c_wall violated: 1 conflicting context pair(s) with node memory, 5 node(s) had untolerated taint(s). no new claims to deallocate, preemption: 0/6 nodes are available: 1 No preemption victims found for incoming pod, 5 Preemption is not helpful for scheduling."
0.4665,Event,ADDED,eval-sanitize-30-r0-132-78cmt.18d4b2befc411302,"reason=FailedScheduling count=None msg=0/6 nodes are available: 1 c_wall violated: 1 conflicting context pair(s) with node memory, 5 node(s) had untolerated taint(s). no new claims to deallocate, preemption: 0/6 nodes are available: 1 No preemption victims found for incoming pod, 5 Preemption is not helpful for scheduling."
0.4667,Event,ADDED,eval-sanitize-30-r0-132-78cmt.18d4b2c5a48eb5af,reason=Scheduled count=None msg=Successfully assigned compute/eval-sanitize-30-r0-132-78cmt to kind-worker
0.4668,Event,ADDED,eval-sanitize-30-r0-132-78cmt.18d4b2c5c063501a,"reason=Pulled count=1 msg=Container image ""busybox:musl"" already present on machine"
0.467,Event,ADDED,eval-sanitize-30-r0-132-78cmt.18d4b2c5c26fca42,reason=Created count=1 msg=Created container: task
0.4672,Event,ADDED,eval-sanitize-30-r0-132-78cmt.18d4b2c5c733bec9,reason=Started count=1 msg=Started container task
0.4673,Event,ADDED,eval-sanitize-30-r0-132-hm679.18d4b0d04245b4f0,"reason=FailedScheduling count=None msg=0/6 nodes are available: 1 c_wall violated: 2 conflicting context pair(s) with node memory, 1 node(s) had untolerated taint(s), 4 c_wall violated: 1 conflicting context pair(s) with node memory. no new claims to deallocate, preemption: 0/6 nodes are available: 1 Preemption is not helpful for scheduling, 5 No preemption victims found for incoming pod."
0.4675,Event,ADDED,eval-sanitize-30-r0-132-hm679.18d4b0d0889fb370,"reason=FailedScheduling count=None msg=0/6 nodes are available: 1 c_wall violated: 2 conflicting context pair(s) with node memory, 1 node(s) had untolerated taint(s), 4 c_wall violated: 1 conflicting context pair(s) with node memory. no new claims to deallocate, preemption: 0/6 nodes are available: 1 Preemption is not helpful for scheduling, 5 No preemption victims found for incoming pod."
0.4677,Event,ADDED,eval-sanitize-30-r0-132-hm679.18d4b0d3b4519624,"reason=FailedScheduling count=None msg=0/6 nodes are available: 2 c_wall violated: 1 conflicting context pair(s) with node memory, 4 node(s) had untolerated taint(s). no new claims to deallocate, preemption: 0/6 nodes are available: 2 No preemption victims found for incoming pod, 4 Preemption is not helpful for scheduling."
0.4678,Event,ADDED,eval-sanitize-30-r0-132-hm679.18d4b0d3c35d19e5,"reason=FailedScheduling count=None msg=0/6 nodes are available: 1 c_wall violated: 1 conflicting context pair(s) with node memory, 5 node(s) had untolerated taint(s). no new claims to deallocate, preemption: 0/6 nodes are available: 1 No preemption victims found for incoming pod, 5 Preemption is not helpful for scheduling."
0.468,Event,ADDED,eval-sanitize-30-r0-132-hm679.18d4b0d3ce81e8f7,"reason=FailedScheduling count=None msg=0/6 nodes are available: 1 c_wall violated: 1 conflicting context pair(s) with node memory, 5 node(s) had untolerated taint(s). no new claims to deallocate, preemption: 0/6 nodes are available: 1 No preemption victims found for incoming pod, 5 Preemption is not helpful for scheduling."
0.4682,Event,ADDED,eval-sanitize-30-r0-132-hm679.18d4b0da79f1d3c1,reason=Scheduled count=None msg=Successfully assigned compute/eval-sanitize-30-r0-132-hm679 to kind-worker
0.4683,Event,ADDED,eval-sanitize-30-r0-132-hm679.18d4b0da99f4713f,"reason=Pulled count=1 msg=Container image ""busybox:musl"" already present on machine"
0.4685,Event,ADDED,eval-sanitize-30-r0-132-hm679.18d4b0da9d9ac92a,reason=Created count=1 msg=Created container: task
0.4687,Event,ADDED,eval-sanitize-30-r0-132-hm679.18d4b0daa0d1ffa9,reason=Started count=1 msg=Started container task
0.469,Event,ADDED,eval-sanitize-30-r0-132.18d4b0d037b9277b,reason=SuccessfulCreate count=1 msg=Created pod: eval-sanitize-30-r0-132-hm679
0.4692,Event,ADDED,eval-sanitize-30-r0-132.18d4b0dfd530c594,reason=Completed count=1 msg=Job completed
0.4693,Event,ADDED,eval-sanitize-30-r0-132.18d4b2befb6f88ad,reason=SuccessfulCreate count=1 msg=Created pod: eval-sanitize-30-r0-132-78cmt
0.4695,Event,ADDED,eval-sanitize-30-r0-132.18d4b2ccf1873420,reason=Completed count=1 msg=Job completed
0.4697,Event,ADDED,eval-sanitize-30-r0-133-9ftbh.18d4b0d07e885c63,reason=Scheduled count=None msg=Successfully assigned compute/eval-sanitize-30-r0-133-9ftbh to kind-worker
0.4699,Event,ADDED,eval-sanitize-30-r0-133-9ftbh.18d4b0d09815b4b4,"reason=Pulled count=1 msg=Container image ""busybox:musl"" already present on machine"
0.4701,Event,ADDED,eval-sanitize-30-r0-133-9ftbh.18d4b0d09931fc89,reason=Created count=1 msg=Created container: task
0.4703,Event,ADDED,eval-sanitize-30-r0-133-9ftbh.18d4b0d09b521269,reason=Started count=1 msg=Started container task
0.4705,Event,ADDED,eval-sanitize-30-r0-133-z8b7n.18d4b2bf2b3865c3,"reason=FailedScheduling count=None msg=0/6 nodes are available: 1 c_wall violated: 2 conflicting context pair(s) with node memory, 5 node(s) had untolerated taint(s). no new claims to deallocate, preemption: 0/6 nodes are available: 1 No preemption victims found for incoming pod, 5 Preemption is not helpful for scheduling."
0.4708,Event,ADDED,eval-sanitize-30-r0-133-z8b7n.18d4b2bf2bb1713b,"reason=FailedScheduling count=None msg=0/6 nodes are available: 1 c_wall violated: 2 conflicting context pair(s) with node memory, 5 node(s) had untolerated taint(s). no new claims to deallocate, preemption: 0/6 nodes are available: 1 No preemption victims found for incoming pod, 5 Preemption is not helpful for scheduling."
0.4709,Event,ADDED,eval-sanitize-30-r0-133-z8b7n.18d4b2c5b41e6610,reason=Scheduled count=None msg=Successfully assigned compute/eval-sanitize-30-r0-133-z8b7n to kind-worker
0.4711,Event,ADDED,eval-sanitize-30-r0-133-z8b7n.18d4b2c5d395e94d,"reason=Pulled count=1 msg=Container image ""busybox:musl"" already present on machine"
0.4713,Event,ADDED,eval-sanitize-30-r0-133-z8b7n.18d4b2c5d663d567,reason=Created count=1 msg=Created container: task
0.4714,Event,ADDED,eval-sanitize-30-r0-133-z8b7n.18d4b2c5da6cd18a,reason=Started count=1 msg=Started container task
0.4717,Event,ADDED,eval-sanitize-30-r0-133.18d4b0d072c5892f,reason=SuccessfulCreate count=1 msg=Created pod: eval-sanitize-30-r0-133-9ftbh
0.4719,Event,ADDED,eval-sanitize-30-r0-133.18d4b0d6394bfcae,reason=Completed count=1 msg=Job completed
0.472,Event,ADDED,eval-sanitize-30-r0-133.18d4b2bf2af85b43,reason=SuccessfulCreate count=1 msg=Created pod: eval-sanitize-30-r0-133-z8b7n
0.4722,Event,ADDED,eval-sanitize-30-r0-133.18d4b2ccfad2201c,reason=Completed count=1 msg=Job completed
0.4724,Event,ADDED,eval-sanitize-30-r0-134-pc79g.18d4b2bf6fdf8cd7,"reason=FailedScheduling count=None msg=0/6 nodes are available: 1 c_wall violated: 1 conflicting context pair(s) with node memory, 5 node(s) had untolerated taint(s). no new claims to deallocate, preemption: 0/6 nodes are available: 1 No preemption victims found for incoming pod, 5 Preemption is not helpful for scheduling."
0.4726,Event,ADDED,eval-sanitize-30-r0-134-pc79g.18d4b2bf70559bfc,"reason=FailedScheduling count=None msg=0/6 nodes are available: 1 c_wall violated: 1 conflicting context pair(s) with node memory, 5 node(s) had untolerated taint(s). no new claims to deallocate, preemption: 0/6 nodes are available: 1 No preemption victims found for incoming pod, 5 Preemption is not helpful for scheduling."
0.4727,Event,ADDED,eval-sanitize-30-r0-134-pc79g.18d4b2c5ba618aef,reason=Scheduled count=None msg=Successfully assigned compute/eval-sanitize-30-r0-134-pc79g to kind-worker
0.4729,Event,ADDED,eval-sanitize-30-r0-134-pc79g.18d4b2c5d45c2619,"reason=Pulled count=1 msg=Container image ""busybox:musl"" already present on machine"
0.4731,Event,ADDED,eval-sanitize-30-r0-134-pc79g.18d4b2c5d6fceba2,reason=Created count=1 msg=Created container: task
0.4732,Event,ADDED,eval-sanitize-30-r0-134-pc79g.18d4b2c5da7c70ad,reason=Started count=1 msg=Started container task
0.4734,Event,ADDED,eval-sanitize-30-r0-134-wtdh8.18d4b0d0b8c69570,reason=Scheduled count=None msg=Successfully assigned compute/eval-sanitize-30-r0-134-wtdh8 to kind-worker
0.4736,Event,ADDED,eval-sanitize-30-r0-134-wtdh8.18d4b0d0d27db863,"reason=Pulled count=1 msg=Container image ""busybox:musl"" already present on machine"
0.4737,Event,ADDED,eval-sanitize-30-r0-134-wtdh8.18d4b0d0d393e9e8,reason=Created count=1 msg=Created container: task
0.474,Event,ADDED,eval-sanitize-30-r0-134-wtdh8.18d4b0d0d59fdb5d,reason=Started count=1 msg=Started container task
0.4742,Event,ADDED,eval-sanitize-30-r0-134.18d4b0d0a8be00fc,reason=SuccessfulCreate count=1 msg=Created pod: eval-sanitize-30-r0-134-wtdh8
0.4744,Event,ADDED,eval-sanitize-30-r0-134.18d4b0d66c3a5c92,reason=Completed count=1 msg=Job completed
0.4745,Event,ADDED,eval-sanitize-30-r0-134.18d4b2bf6fa436b5,reason=SuccessfulCreate count=1 msg=Created pod: eval-sanitize-30-r0-134-pc79g
0.4747,Event,ADDED,eval-sanitize-30-r0-134.18d4b2ccdc1c9c78,reason=Completed count=1 msg=Job completed
0.4749,Event,ADDED,eval-sanitize-30-r0-135-d6chc.18d4b0d0eee5783e,reason=Scheduled count=None msg=Successfully assigned compute/eval-sanitize-30-r0-135-d6chc to kind-worker5
0.475,Event,ADDED,eval-sanitize-30-r0-135-d6chc.18d4b0d1080523a0,"reason=Pulled count=1 msg=Container image ""busybox:musl"" already present on machine"
0.4752,Event,ADDED,eval-sanitize-30-r0-135-d6chc.18d4b0d109144f98,reason=Created count=1 msg=Created container: task
0.4754,Event,ADDED,eval-sanitize-30-r0-135-d6chc.18d4b0d10afa9d61,reason=Started count=1 msg=Started container task
0.4755,Event,ADDED,eval-sanitize-30-r0-135-fvrqt.18d4b2bf9cd1c11e,"reason=FailedScheduling count=None msg=0/6 nodes are available: 1 c_wall violated: 2 conflicting context pair(s) with node memory, 5 node(s) had untolerated taint(s). no new claims to deallocate, preemption: 0/6 nodes are available: 1 No preemption victims found for incoming pod, 5 Preemption is not helpful for scheduling."
0.4757,Event,ADDED,eval-sanitize-30-r0-135-fvrqt.18d4b2bf9d550b9e,"reason=FailedScheduling count=None msg=0/6 nodes are available: 1 c_wall violated: 2 conflicting context pair(s) with node memory, 5 node(s) had untolerated taint(s). no new claims to deallocate, preemption: 0/6 nodes are available: 1 No preemption victims found for incoming pod, 5 Preemption is not helpful for scheduling."
0.4759,Event,ADDED,eval-sanitize-30-r0-135-fvrqt.18d4b2c5c4f8dc66,reason=Scheduled count=None msg=Successfully assigned compute/eval-sanitize-30-r0-135-fvrqt to kind-worker
0.476,Event,ADDED,eval-sanitize-30-r0-135-fvrqt.18d4b2c5e92b2ca0,"reason=Pulled count=1 msg=Container image ""busybox:musl"" already present on machine"
0.4762,Event,ADDED,eval-sanitize-30-r0-135-fvrqt.18d4b2c5eb96347c,reason=Created count=1 msg=Created container: task
0.4764,Event,ADDED,eval-sanitize-30-r0-135-fvrqt.18d4b2c5f0cfb33e,reason=Started count=1 msg=Started container task
0.4765,Event,ADDED,eval-sanitize-30-r0-135.18d4b0d0e46e4ecf,reason=SuccessfulCreate count=1 msg=Created pod: eval-sanitize-30-r0-135-d6chc
0.4767,Event,ADDED,eval-sanitize-30-r0-135.18d4b0d69cafd63e,reason=Completed count=1 msg=Job completed
0.4769,Event,ADDED,eval-sanitize-30-r0-135.18d4b2bf9c95f0f3,reason=SuccessfulCreate count=1 msg=Created pod: eval-sanitize-30-r0-135-fvrqt
0.477,Event,ADDED,eval-sanitize-30-r0-135.18d4b2cd0bfcbacf,reason=Completed count=1 msg=Job completed
0.4772,Event,ADDED,eval-sanitize-30-r0-136-cszvz.18d4b2bfb593420b,reason=Scheduled count=None msg=Successfully assigned compute/eval-sanitize-30-r0-136-cszvz to kind-worker4
0.4773,Event,ADDED,eval-sanitize-30-r0-136-cszvz.18d4b2bfd3dc7a9c,"reason=Pulled count=1 msg=Container image ""busybox:musl"" already present on machine"
0.4775,Event,ADDED,eval-sanitize-30-r0-136-cszvz.18d4b2bfd51765cb,reason=Created count=1 msg=Created container: task
0.4777,Event,ADDED,eval-sanitize-30-r0-136-cszvz.18d4b2bfd9b38cd2,reason=Started count=1 msg=Started container task
0.4779,Event,ADDED,eval-sanitize-30-r0-136-d2znl.18d4b0d1307421d2,reason=Scheduled count=None msg=Successfully assigned compute/eval-sanitize-30-r0-136-d2znl to kind-worker4
0.4781,Event,ADDED,eval-sanitize-30-r0-136-d2znl.18d4b0d14d230d1e,"reason=Pulled count=1 msg=Container image ""busybox:musl"" already present on machine"
0.4782,Event,ADDED,eval-sanitize-30-r0-136-d2znl.18d4b0d14e3b0263,reason=Created count=1 msg=Created container: task
0.4785,Event,ADDED,eval-sanitize-30-r0-136-d2znl.18d4b0d152a0885e,reason=Started count=1 msg=Started container task
0.4787,Event,ADDED,eval-sanitize-30-r0-136.18d4b0d1259e1fd4,reason=SuccessfulCreate count=1 msg=Created pod: eval-sanitize-30-r0-136-d2znl
0.4789,Event,ADDED,eval-sanitize-30-r0-136.18d4b0d6b30d8491,reason=Completed count=1 msg=Job completed
0.4791,Event,ADDED,eval-sanitize-30-r0-136.18d4b2bfb4e78574,reason=SuccessfulCreate count=1 msg=Created pod: eval-sanitize-30-r0-136-cszvz
0.4794,Event,ADDED,eval-sanitize-30-r0-136.18d4b2c555b55cac,reason=Completed count=1 msg=Job completed
0.4796,Event,ADDED,eval-sanitize-30-r0-137-kzp4k.18d4b2bfd8d13d49,"reason=FailedScheduling count=None msg=0/6 nodes are available: 1 c_wall violated: 2 conflicting context pair(s) with node memory, 5 node(s) had untolerated taint(s). no new claims to deallocate, preemption: 0/6 nodes are available: 1 No preemption victims found for incoming pod, 5 Preemption is not helpful for scheduling."
0.4798,Event,ADDED,eval-sanitize-30-r0-137-kzp4k.18d4b2bfd9502de0,"reason=FailedScheduling count=None msg=0/6 nodes are available: 1 c_wall violated: 2 conflicting context pair(s) with node memory, 5 node(s) had untolerated taint(s). no new claims to deallocate, preemption: 0/6 nodes are available: 1 No preemption victims found for incoming pod, 5 Preemption is not helpful for scheduling."
0.4801,Event,ADDED,eval-sanitize-30-r0-137-kzp4k.18d4b2c09a98261e,"reason=FailedScheduling count=None msg=0/6 nodes are available: 1 c_wall violated: 3 conflicting context pair(s) with node memory, 5 node(s) had untolerated taint(s). no new claims to deallocate, preemption: 0/6 nodes are available: 1 No preemption victims found for incoming pod, 5 Preemption is not helpful for scheduling."
0.4802,Event,ADDED,eval-sanitize-30-r0-137-kzp4k.18d4b2c5bf09c876,reason=Scheduled count=None msg=Successfully assigned compute/eval-sanitize-30-r0-137-kzp4k to kind-worker2
0.4804,Event,ADDED,eval-sanitize-30-r0-137-kzp4k.18d4b2c5dac82fc1,"reason=Pulled count=1 msg=Container image ""busybox:musl"" already present on machine"
0.4805,Event,ADDED,eval-sanitize-30-r0-137-kzp4k.18d4b2c5dc7290ff,reason=Created count=1 msg=Created container: task
0.4807,Event,ADDED,eval-sanitize-30-r0-137-kzp4k.18d4b2c5e929e24b,reason=Started count=1 msg=Started container task
0.4809,Event,ADDED,eval-sanitize-30-r0-137-zjdkg.18d4b0d16666a29f,reason=Scheduled count=None msg=Successfully assigned compute/eval-sanitize-30-r0-137-zjdkg to kind-worker5
0.481,Event,ADDED,eval-sanitize-30-r0-137-zjdkg.18d4b0d181aeb283,"reason=Pulled count=1 msg=Container image ""busybox:musl"" already present on machine"
0.4812,Event,ADDED,eval-sanitize-30-r0-137-zjdkg.18d4b0d1831273b7,reason=Created count=1 msg=Created container: task
0.4814,Event,ADDED,eval-sanitize-30-r0-137-zjdkg.18d4b0d18662cd34,reason=Started count=1 msg=Started container task
0.4815,Event,ADDED,eval-sanitize-30-r0-137.18d4b0d15c15eb0e,reason=SuccessfulCreate count=1 msg=Created pod: eval-sanitize-30-r0-137-zjdkg
0.4818,Event,ADDED,eval-sanitize-30-r0-137.18d4b0d70f092796,reason=Completed count=1 msg=Job completed
0.4821,Event,ADDED,eval-sanitize-30-r0-137.18d4b2bfd894aa53,reason=SuccessfulCreate count=1 msg=Created pod: eval-sanitize-30-r0-137-kzp4k
0.4823,Event,ADDED,eval-sanitize-30-r0-137.18d4b2cd0c3355ec,reason=Completed count=1 msg=Job completed
0.4825,Event,ADDED,eval-sanitize-30-r0-138-4xrtv.18d4b0d1a1dad5e3,reason=Scheduled count=None msg=Successfully assigned compute/eval-sanitize-30-r0-138-4xrtv to kind-worker
0.4826,Event,ADDED,eval-sanitize-30-r0-138-4xrtv.18d4b0d1bc4789ee,"reason=Pulled count=1 msg=Container image ""busybox:musl"" already present on machine"
0.4828,Event,ADDED,eval-sanitize-30-r0-138-4xrtv.18d4b0d1bde698cd,reason=Created count=1 msg=Created container: task
0.483,Event,ADDED,eval-sanitize-30-r0-138-4xrtv.18d4b0d1c20de6f6,reason=Started count=1 msg=Started container task
0.4831,Event,ADDED,eval-sanitize-30-r0-138-dvkqn.18d4b2bffa0089cf,"reason=FailedScheduling count=None msg=0/6 nodes are available: 1 c_wall violated: 1 conflicting context pair(s) with node memory, 5 node(s) had untolerated taint(s). no new claims to deallocate, preemption: 0/6 nodes are available: 1 No preemption victims found for incoming pod, 5 Preemption is not helpful for scheduling."
0.4834,Event,ADDED,eval-sanitize-30-r0-138-dvkqn.18d4b2bffa775894,"reason=FailedScheduling count=None msg=0/6 nodes are available: 1 c_wall violated: 1 conflicting context pair(s) with node memory, 5 node(s) had untolerated taint(s). no new claims to deallocate, preemption: 0/6 nodes are available: 1 No preemption victims found for incoming pod, 5 Preemption is not helpful for scheduling."
0.4835,Event,ADDED,eval-sanitize-30-r0-138-dvkqn.18d4b2c5d206e621,reason=Scheduled count=None msg=Successfully assigned compute/eval-sanitize-30-r0-138-dvkqn to kind-worker5
0.4837,Event,ADDED,eval-sanitize-30-r0-138-dvkqn.18d4b2c5f0cb8217,"reason=Pulled count=1 msg=Container image ""busybox:musl"" already present on machine"
0.4839,Event,ADDED,eval-sanitize-30-r0-138-dvkqn.18d4b2c5f254c43b,reason=Created count=1 msg=Created container: task
0.484,Event,ADDED,eval-sanitize-30-r0-138-dvkqn.18d4b2c5f69ca63a,reason=Started count=1 msg=Started container task
0.4842,Event,ADDED,eval-sanitize-30-r0-138.18d4b0d1971eb587,reason=SuccessfulCreate count=1 msg=Created pod: eval-sanitize-30-r0-138-4xrtv
0.4843,Event,ADDED,eval-sanitize-30-r0-138.18d4b0d75c4f7d7d,reason=Completed count=1 msg=Job completed
0.4845,Event,ADDED,eval-sanitize-30-r0-138.18d4b2bff9ce51ab,reason=SuccessfulCreate count=1 msg=Created pod: eval-sanitize-30-r0-138-dvkqn
0.4847,Event,ADDED,eval-sanitize-30-r0-138.18d4b2cb225d1cf5,reason=Completed count=1 msg=Job completed
0.4848,Event,ADDED,eval-sanitize-30-r0-139-7nlfl.18d4b2c02a38753d,"reason=FailedScheduling count=None msg=0/6 nodes are available: 1 c_wall violated: 1 conflicting context pair(s) with node memory, 5 node(s) had untolerated taint(s). no new claims to deallocate, preemption: 0/6 nodes are available: 1 No preemption victims found for incoming pod, 5 Preemption is not helpful for scheduling."
