t_recv,kind,type,name,detail
0.023,Node,ADDED,kind-control-plane,taints=1
0.0254,Node,ADDED,kind-worker,taints=0
0.0269,Node,ADDED,kind-worker2,taints=0
0.0283,Node,ADDED,kind-worker3,taints=0
0.0297,Node,ADDED,kind-worker4,taints=0
0.031,Node,ADDED,kind-worker5,taints=0
0.0438,TaskRequest,ADDED,eval-sanitize-3-r0-000,phase=None job=None
0.0497,TaskRequest,MODIFIED,eval-sanitize-3-r0-000,phase=Pending job=None
0.0632,Event,ADDED,eval-image-prepull-6kt7n.18d4a1d3f076f033,reason=Scheduled count=1 msg=Successfully assigned compute/eval-image-prepull-6kt7n to kind-worker
0.0637,Event,ADDED,eval-image-prepull-6kt7n.18d4a1d40c115a5c,"reason=Pulled count=1 msg=Container image ""busybox:musl"" already present on machine"
0.0639,Event,ADDED,eval-image-prepull-6kt7n.18d4a1d40ec3e5be,reason=Created count=1 msg=Created container: pause
0.0641,Event,ADDED,eval-image-prepull-6kt7n.18d4a1d412dc71a4,reason=Started count=1 msg=Started container pause
0.0643,Event,ADDED,eval-image-prepull-6kt7n.18d4a1d46849058f,reason=Killing count=1 msg=Stopping container pause
0.0647,Event,ADDED,eval-image-prepull-c9m54.18d4a1d3f10ba701,reason=Scheduled count=1 msg=Successfully assigned compute/eval-image-prepull-c9m54 to kind-worker2
0.0649,Event,ADDED,eval-image-prepull-c9m54.18d4a1d40c09787c,"reason=Pulled count=1 msg=Container image ""busybox:musl"" already present on machine"
0.0651,Event,ADDED,eval-image-prepull-c9m54.18d4a1d40e98903b,reason=Created count=1 msg=Created container: pause
0.0652,Event,ADDED,eval-image-prepull-c9m54.18d4a1d412d32c53,reason=Started count=1 msg=Started container pause
0.0656,Event,ADDED,eval-image-prepull-c9m54.18d4a1d47f555b17,reason=Killing count=1 msg=Stopping container pause
0.0658,Event,ADDED,eval-image-prepull-gkpnn.18d4a1d3f1b1227a,reason=Scheduled count=1 msg=Successfully assigned compute/eval-image-prepull-gkpnn to kind-worker3
0.066,Event,ADDED,eval-image-prepull-gkpnn.18d4a1d40c120330,"reason=Pulled count=1 msg=Container image ""busybox:musl"" already present on machine"
0.0665,Event,ADDED,eval-image-prepull-gkpnn.18d4a1d40ef8e10d,reason=Created count=1 msg=Created container: pause
0.0667,Event,ADDED,eval-image-prepull-gkpnn.18d4a1d4132a47a9,reason=Started count=1 msg=Started container pause
0.0669,Event,ADDED,eval-image-prepull-gkpnn.18d4a1d463fab557,reason=Killing count=1 msg=Stopping container pause
0.0671,Event,ADDED,eval-image-prepull-j75pm.18d4a1d3f1b14f49,reason=Scheduled count=1 msg=Successfully assigned compute/eval-image-prepull-j75pm to kind-worker5
0.0675,Event,ADDED,eval-image-prepull-j75pm.18d4a1d40bfff774,"reason=Pulled count=1 msg=Container image ""busybox:musl"" already present on machine"
0.0677,Event,ADDED,eval-image-prepull-j75pm.18d4a1d40e63b644,reason=Created count=1 msg=Created container: pause
0.068,Event,ADDED,eval-image-prepull-j75pm.18d4a1d412c39eff,reason=Started count=1 msg=Started container pause
0.0688,Job,ADDED,eval-sanitize-3-r0-000,
0.0692,Event,ADDED,eval-image-prepull-j75pm.18d4a1d4bf8b5910,reason=Killing count=1 msg=Stopping container pause
0.0694,Event,ADDED,eval-image-prepull-pvfmc.18d4a1d3f111b33c,reason=Scheduled count=1 msg=Successfully assigned compute/eval-image-prepull-pvfmc to kind-worker4
0.0696,Event,ADDED,eval-image-prepull-pvfmc.18d4a1d40c0d6db2,"reason=Pulled count=1 msg=Container image ""busybox:musl"" already present on machine"
0.0697,Event,ADDED,eval-image-prepull-pvfmc.18d4a1d40f1664f8,reason=Created count=1 msg=Created container: pause
0.0701,Event,ADDED,eval-image-prepull-pvfmc.18d4a1d413482b76,reason=Started count=1 msg=Started container pause
0.0703,Event,ADDED,eval-image-prepull-pvfmc.18d4a1d4c5fefb0b,reason=Killing count=1 msg=Stopping container pause
0.0705,Event,ADDED,eval-image-prepull.18d4a1d3f03c9698,reason=SuccessfulCreate count=1 msg=Created pod: eval-image-prepull-6kt7n
0.0708,Event,ADDED,eval-image-prepull.18d4a1d3f09aff7b,reason=SuccessfulCreate count=1 msg=Created pod: eval-image-prepull-c9m54
0.0711,Event,ADDED,eval-image-prepull.18d4a1d3f0a930f7,reason=SuccessfulCreate count=1 msg=Created pod: eval-image-prepull-pvfmc
0.0713,Event,ADDED,eval-image-prepull.18d4a1d3f10ac527,reason=SuccessfulCreate count=1 msg=Created pod: eval-image-prepull-j75pm
0.0715,Event,ADDED,eval-image-prepull.18d4a1d3f10f074c,reason=SuccessfulCreate count=1 msg=Created pod: eval-image-prepull-gkpnn
0.072,Event,ADDED,eval-sanitize-1-r0-000-6g6vw.18d4a1e489c946d4,reason=Scheduled count=None msg=Successfully assigned compute/eval-sanitize-1-r0-000-6g6vw to kind-worker
0.0722,Event,ADDED,eval-sanitize-1-r0-000-6g6vw.18d4a1e4a7e18085,"reason=Pulled count=1 msg=Container image ""busybox:musl"" already present on machine"
0.0724,Event,ADDED,eval-sanitize-1-r0-000-6g6vw.18d4a1e4a901d572,reason=Created count=1 msg=Created container: task
0.0725,Event,ADDED,eval-sanitize-1-r0-000-6g6vw.18d4a1e4ac7d7571,reason=Started count=1 msg=Started container task
0.073,Event,ADDED,eval-sanitize-1-r0-000.18d4a1e488d4b2cd,reason=SuccessfulCreate count=1 msg=Created pod: eval-sanitize-1-r0-000-6g6vw
0.0739,Event,ADDED,eval-sanitize-1-r0-000.18d4a1ea1db17a04,reason=Completed count=1 msg=Job completed
0.0745,Event,ADDED,eval-sanitize-1-r0-001-m9nsx.18d4a1e4c3a7b963,reason=Scheduled count=None msg=Successfully assigned compute/eval-sanitize-1-r0-001-m9nsx to kind-worker5
0.0749,Event,ADDED,eval-sanitize-1-r0-001-m9nsx.18d4a1e4dd6216bd,"reason=Pulled count=1 msg=Container image ""busybox:musl"" already present on machine"
0.0751,TaskRequest,MODIFIED,eval-sanitize-3-r0-000,phase=Scheduled job=None
0.0757,Event,ADDED,eval-sanitize-1-r0-001-m9nsx.18d4a1e4dea6ea96,reason=Created count=1 msg=Created container: task
0.0761,Event,ADDED,eval-sanitize-1-r0-001-m9nsx.18d4a1e4e516de67,reason=Started count=1 msg=Started container task
0.0764,Event,ADDED,eval-sanitize-1-r0-001.18d4a1e4c32413f4,reason=SuccessfulCreate count=1 msg=Created pod: eval-sanitize-1-r0-001-m9nsx
0.0768,Event,ADDED,eval-sanitize-1-r0-001.18d4a1ea744774dd,reason=Completed count=1 msg=Job completed
0.0771,Event,ADDED,eval-sanitize-1-r0-002-nwf2t.18d4a1e4ff6d6b2a,reason=Scheduled count=None msg=Successfully assigned compute/eval-sanitize-1-r0-002-nwf2t to kind-worker3
0.0775,Event,ADDED,eval-sanitize-1-r0-002-nwf2t.18d4a1e519cad581,"reason=Pulled count=1 msg=Container image ""busybox:musl"" already present on machine"
0.0777,Event,ADDED,eval-sanitize-1-r0-002-nwf2t.18d4a1e51b5bf68d,reason=Created count=1 msg=Created container: task
0.079,Pod,ADDED,eval-sanitize-3-r0-000-8w4zh,phase=Pending node=None
0.0794,Event,ADDED,eval-sanitize-1-r0-002-nwf2t.18d4a1e522f9fc91,reason=Started count=1 msg=Started container task
0.0796,Event,ADDED,eval-sanitize-1-r0-002.18d4a1e4fee26ab5,reason=SuccessfulCreate count=1 msg=Created pod: eval-sanitize-1-r0-002-nwf2t
0.0797,Event,ADDED,eval-sanitize-1-r0-002.18d4a1ea91b7e2d4,reason=Completed count=1 msg=Job completed
0.0799,Event,ADDED,eval-sanitize-1-r0-003-hmtxj.18d4a1e53c267f82,reason=Scheduled count=None msg=Successfully assigned compute/eval-sanitize-1-r0-003-hmtxj to kind-worker2
0.0803,Event,ADDED,eval-sanitize-1-r0-003-hmtxj.18d4a1e5585e1bc6,"reason=Pulled count=1 msg=Container image ""busybox:musl"" already present on machine"
0.0805,Event,ADDED,eval-sanitize-1-r0-003-hmtxj.18d4a1e5597b455a,reason=Created count=1 msg=Created container: task
0.0806,Event,ADDED,eval-sanitize-1-r0-003-hmtxj.18d4a1e55fc8aef6,reason=Started count=1 msg=Started container task
0.0814,Job,MODIFIED,eval-sanitize-3-r0-000,
0.0817,Event,ADDED,eval-sanitize-1-r0-003.18d4a1e53ba22894,reason=SuccessfulCreate count=1 msg=Created pod: eval-sanitize-1-r0-003-hmtxj
0.0819,Event,ADDED,eval-sanitize-1-r0-003.18d4a1eaeacd925f,reason=Completed count=1 msg=Job completed
0.0821,Event,ADDED,eval-sanitize-1-r0-004-jv58t.18d4a1e575511a09,reason=Scheduled count=None msg=Successfully assigned compute/eval-sanitize-1-r0-004-jv58t to kind-worker4
0.0822,Event,ADDED,eval-sanitize-1-r0-004-jv58t.18d4a1e58e6868d9,"reason=Pulled count=1 msg=Container image ""busybox:musl"" already present on machine"
0.0826,Event,ADDED,eval-sanitize-1-r0-004-jv58t.18d4a1e58f905b16,reason=Created count=1 msg=Created container: task
0.0828,Event,ADDED,eval-sanitize-1-r0-004-jv58t.18d4a1e5971ebcaf,reason=Started count=1 msg=Started container task
0.083,Event,ADDED,eval-sanitize-1-r0-004.18d4a1e574e8c7a8,reason=SuccessfulCreate count=1 msg=Created pod: eval-sanitize-1-r0-004-jv58t
0.0832,Event,ADDED,eval-sanitize-1-r0-004.18d4a1eb000e8562,reason=Completed count=1 msg=Job completed
0.0834,TaskRequest,MODIFIED,eval-sanitize-3-r0-000,phase=Scheduled job=None
0.0837,Event,ADDED,eval-sanitize-1-r0-005-xczgs.18d4a1e5b0ac6453,"reason=FailedScheduling count=None msg=0/6 nodes are available: 6 node(s) had untolerated taint(s). no new claims to deallocate, preemption: 0/6 nodes are available: 6 Preemption is not helpful for scheduling."
0.084,Event,ADDED,eval-sanitize-1-r0-005-xczgs.18d4a1e9b6ebd6a1,reason=Scheduled count=None msg=Successfully assigned compute/eval-sanitize-1-r0-005-xczgs to kind-worker
0.0845,Event,ADDED,eval-sanitize-1-r0-005-xczgs.18d4a1e9d2487b92,"reason=Pulled count=1 msg=Container image ""busybox:musl"" already present on machine"
0.0848,Event,ADDED,eval-sanitize-1-r0-005-xczgs.18d4a1e9d47ec8f3,reason=Created count=1 msg=Created container: task
0.0851,Event,ADDED,eval-sanitize-1-r0-005-xczgs.18d4a1e9d8250c8d,reason=Started count=1 msg=Started container task
0.0853,Event,ADDED,eval-sanitize-1-r0-005.18d4a1e5b0a0db3c,reason=SuccessfulCreate count=1 msg=Created pod: eval-sanitize-1-r0-005-xczgs
0.0855,Event,ADDED,eval-sanitize-1-r0-005.18d4a1ef44754569,reason=Completed count=1 msg=Job completed
0.0858,Event,ADDED,eval-sanitize-1-r0-006-xhw86.18d4a1e5ebc7b8a9,"reason=FailedScheduling count=None msg=0/6 nodes are available: 6 node(s) had untolerated taint(s). no new claims to deallocate, preemption: 0/6 nodes are available: 6 Preemption is not helpful for scheduling."
0.086,Event,ADDED,eval-sanitize-1-r0-006-xhw86.18d4a1e9b76178ca,reason=Scheduled count=None msg=Successfully assigned compute/eval-sanitize-1-r0-006-xhw86 to kind-worker
0.0862,Event,ADDED,eval-sanitize-1-r0-006-xhw86.18d4a1e9d62ac632,"reason=Pulled count=1 msg=Container image ""busybox:musl"" already present on machine"
0.0863,Event,ADDED,eval-sanitize-1-r0-006-xhw86.18d4a1e9d7efa28a,reason=Created count=1 msg=Created container: task
0.0867,Event,ADDED,eval-sanitize-1-r0-006-xhw86.18d4a1e9dd4e4f43,reason=Started count=1 msg=Started container task
0.0869,Event,ADDED,eval-sanitize-1-r0-006.18d4a1e5ebbe0652,reason=SuccessfulCreate count=1 msg=Created pod: eval-sanitize-1-r0-006-xhw86
0.0873,Event,ADDED,eval-sanitize-1-r0-006.18d4a1ef861e2dc8,reason=Completed count=1 msg=Job completed
0.0876,Event,ADDED,eval-sanitize-1-r0-007-28hgk.18d4a1e62a380070,"reason=FailedScheduling count=None msg=0/6 nodes are available: 6 node(s) had untolerated taint(s). no new claims to deallocate, preemption: 0/6 nodes are available: 6 Preemption is not helpful for scheduling."
0.0877,Event,ADDED,eval-sanitize-1-r0-007-28hgk.18d4a1e9b7ec5a3b,reason=Scheduled count=None msg=Successfully assigned compute/eval-sanitize-1-r0-007-28hgk to kind-worker
0.0879,Event,ADDED,eval-sanitize-1-r0-007-28hgk.18d4a1e9d755ada7,"reason=Pulled count=1 msg=Container image ""busybox:musl"" already present on machine"
0.0881,Event,ADDED,eval-sanitize-1-r0-007-28hgk.18d4a1e9d922b7f3,reason=Created count=1 msg=Created container: task
0.0884,Event,ADDED,eval-sanitize-1-r0-007-28hgk.18d4a1e9dd4c2686,reason=Started count=1 msg=Started container task
0.0886,Event,ADDED,eval-sanitize-1-r0-007.18d4a1e62a2d92c0,reason=SuccessfulCreate count=1 msg=Created pod: eval-sanitize-1-r0-007-28hgk
0.0888,Event,ADDED,eval-sanitize-1-r0-007.18d4a1f038d49455,reason=Completed count=1 msg=Job completed
0.0892,Event,ADDED,eval-sanitize-1-r0-008-xjcpg.18d4a1e665fde69a,"reason=FailedScheduling count=None msg=0/6 nodes are available: 6 node(s) had untolerated taint(s). no new claims to deallocate, preemption: 0/6 nodes are available: 6 Preemption is not helpful for scheduling."
0.0895,Event,ADDED,eval-sanitize-1-r0-008-xjcpg.18d4a1e9b79ffbc7,"reason=FailedScheduling count=None msg=0/6 nodes are available: 1 c_wall violated: 1 conflicting context pair(s) with node memory, 5 node(s) had untolerated taint(s). no new claims to deallocate, preemption: 0/6 nodes are available: 1 No preemption victims found for incoming pod, 5 Preemption is not helpful for scheduling."
0.0902,Event,ADDED,eval-sanitize-1-r0-008-xjcpg.18d4a1e9c947d4b5,"reason=FailedScheduling count=None msg=0/6 nodes are available: 1 c_wall violated: 1 conflicting context pair(s) with node memory, 5 node(s) had untolerated taint(s). no new claims to deallocate, preemption: 0/6 nodes are available: 1 No preemption victims found for incoming pod, 5 Preemption is not helpful for scheduling."
0.0905,Event,ADDED,eval-sanitize-1-r0-008-xjcpg.18d4a1ea276c8251,reason=Scheduled count=None msg=Successfully assigned compute/eval-sanitize-1-r0-008-xjcpg to kind-worker5
0.0916,Pod,MODIFIED,eval-sanitize-3-r0-000-8w4zh,phase=Pending node=kind-worker3
0.092,Event,ADDED,eval-sanitize-1-r0-008-xjcpg.18d4a1ea44b1bed6,"reason=Pulled count=1 msg=Container image ""busybox:musl"" already present on machine"
0.0922,Event,ADDED,eval-sanitize-1-r0-008-xjcpg.18d4a1ea48185f1e,reason=Created count=1 msg=Created container: task
0.0924,Event,ADDED,eval-sanitize-1-r0-008-xjcpg.18d4a1ea55495ac4,reason=Started count=1 msg=Started container task
0.0926,Event,ADDED,eval-sanitize-1-r0-008.18d4a1e665f11288,reason=SuccessfulCreate count=1 msg=Created pod: eval-sanitize-1-r0-008-xjcpg
0.0928,Event,ADDED,eval-sanitize-1-r0-008.18d4a1f0dfadaace,reason=Completed count=1 msg=Job completed
0.093,Event,ADDED,eval-sanitize-1-r0-009-xq8hk.18d4a1e69f2c5cc2,"reason=FailedScheduling count=None msg=0/6 nodes are available: 6 node(s) had untolerated taint(s). no new claims to deallocate, preemption: 0/6 nodes are available: 6 Preemption is not helpful for scheduling."
0.0931,Event,ADDED,eval-sanitize-1-r0-009-xq8hk.18d4a1e9b8661a1d,"reason=FailedScheduling count=None msg=0/6 nodes are available: 1 c_wall violated: 1 conflicting context pair(s) with node memory, 5 node(s) had untolerated taint(s). no new claims to deallocate, preemption: 0/6 nodes are available: 1 No preemption victims found for incoming pod, 5 Preemption is not helpful for scheduling."
0.0934,Event,ADDED,eval-sanitize-1-r0-009-xq8hk.18d4a1e9c97f9ca8,"reason=FailedScheduling count=None msg=0/6 nodes are available: 1 c_wall violated: 2 conflicting context pair(s) with node memory, 5 node(s) had untolerated taint(s). no new claims to deallocate, preemption: 0/6 nodes are available: 1 No preemption victims found for incoming pod, 5 Preemption is not helpful for scheduling."
0.0936,Event,ADDED,eval-sanitize-1-r0-009-xq8hk.18d4a1e9d2eb1732,"reason=FailedScheduling count=None msg=0/6 nodes are available: 1 c_wall violated: 2 conflicting context pair(s) with node memory, 5 node(s) had untolerated taint(s). no new claims to deallocate, preemption: 0/6 nodes are available: 1 No preemption victims found for incoming pod, 5 Preemption is not helpful for scheduling."
0.094,Event,ADDED,eval-sanitize-1-r0-009-xq8hk.18d4a1ea27449fcd,"reason=FailedScheduling count=None msg=0/6 nodes are available: 1 c_wall violated: 2 conflicting context pair(s) with node memory, 5 node(s) had untolerated taint(s). no new claims to deallocate, preemption: 0/6 nodes are available: 1 No preemption victims found for incoming pod, 5 Preemption is not helpful for scheduling."
0.0943,Event,ADDED,eval-sanitize-1-r0-009-xq8hk.18d4a1ea32474b03,"reason=FailedScheduling count=None msg=0/6 nodes are available: 1 c_wall violated: 2 conflicting context pair(s) with node memory, 5 node(s) had untolerated taint(s). no new claims to deallocate, preemption: 0/6 nodes are available: 1 No preemption victims found for incoming pod, 5 Preemption is not helpful for scheduling."
0.0944,Event,ADDED,eval-sanitize-1-r0-009-xq8hk.18d4a1ea6017a83f,reason=Scheduled count=None msg=Successfully assigned compute/eval-sanitize-1-r0-009-xq8hk to kind-worker3
0.0946,Event,ADDED,eval-sanitize-1-r0-009-xq8hk.18d4a1ea7e0a7ec1,"reason=Pulled count=1 msg=Container image ""busybox:musl"" already present on machine"
0.0948,Event,ADDED,eval-sanitize-1-r0-009-xq8hk.18d4a1ea80b61e55,reason=Created count=1 msg=Created container: task
0.095,Event,ADDED,eval-sanitize-1-r0-009-xq8hk.18d4a1ea88864352,reason=Started count=1 msg=Started container task
0.0952,Event,ADDED,eval-sanitize-1-r0-009.18d4a1e69f267195,reason=SuccessfulCreate count=1 msg=Created pod: eval-sanitize-1-r0-009-xq8hk
0.0953,Event,ADDED,eval-sanitize-1-r0-009.18d4a1f0f241d8ac,reason=Completed count=1 msg=Job completed
0.0957,Event,ADDED,eval-sanitize-1-r0-010-mrp6r.18d4a1e6da5966bd,"reason=FailedScheduling count=None msg=0/6 nodes are available: 6 node(s) had untolerated taint(s). no new claims to deallocate, preemption: 0/6 nodes are available: 6 Preemption is not helpful for scheduling."
0.0959,Event,ADDED,eval-sanitize-1-r0-010-mrp6r.18d4a1e9bb354c21,reason=Scheduled count=None msg=Successfully assigned compute/eval-sanitize-1-r0-010-mrp6r to kind-worker
0.096,Event,ADDED,eval-sanitize-1-r0-010-mrp6r.18d4a1e9dd66d85c,"reason=Pulled count=1 msg=Container image ""busybox:musl"" already present on machine"
0.0964,Event,ADDED,eval-sanitize-1-r0-010-mrp6r.18d4a1e9e236477e,reason=Created count=1 msg=Created container: task
0.0966,Event,ADDED,eval-sanitize-1-r0-010-mrp6r.18d4a1e9e6690e5d,reason=Started count=1 msg=Started container task
0.0968,Event,ADDED,eval-sanitize-1-r0-010.18d4a1e6da529e72,reason=SuccessfulCreate count=1 msg=Created pod: eval-sanitize-1-r0-010-mrp6r
0.097,Event,ADDED,eval-sanitize-1-r0-010.18d4a1f043316b93,reason=Completed count=1 msg=Job completed
0.0973,Event,ADDED,eval-sanitize-1-r0-011-26l2v.18d4a1e715cf99fa,"reason=FailedScheduling count=None msg=0/6 nodes are available: 6 node(s) had untolerated taint(s). no new claims to deallocate, preemption: 0/6 nodes are available: 6 Preemption is not helpful for scheduling."
0.0975,Event,ADDED,eval-sanitize-1-r0-011-26l2v.18d4a1e9c0c520a6,reason=Scheduled count=None msg=Successfully assigned compute/eval-sanitize-1-r0-011-26l2v to kind-worker
0.0976,Event,ADDED,eval-sanitize-1-r0-011-26l2v.18d4a1e9dd8823ff,"reason=Pulled count=1 msg=Container image ""busybox:musl"" already present on machine"
0.0978,Event,ADDED,eval-sanitize-1-r0-011-26l2v.18d4a1e9e2511a0a,reason=Created count=1 msg=Created container: task
0.0984,Event,ADDED,eval-sanitize-1-r0-011-26l2v.18d4a1e9e6691fa6,reason=Started count=1 msg=Started container task
0.099,Event,ADDED,eval-sanitize-1-r0-011.18d4a1e715c348ad,reason=SuccessfulCreate count=1 msg=Created pod: eval-sanitize-1-r0-011-26l2v
0.0992,Event,ADDED,eval-sanitize-1-r0-011.18d4a1ef47771c06,reason=Completed count=1 msg=Job completed
0.0995,Event,ADDED,eval-sanitize-1-r0-012-k4xb7.18d4a1e75371bb8b,"reason=FailedScheduling count=None msg=0/6 nodes are available: 6 node(s) had untolerated taint(s). no new claims to deallocate, preemption: 0/6 nodes are available: 6 Preemption is not helpful for scheduling."
0.0997,Event,ADDED,eval-sanitize-1-r0-012-k4xb7.18d4a1e9c0c51912,reason=Scheduled count=None msg=Successfully assigned compute/eval-sanitize-1-r0-012-k4xb7 to kind-worker
0.0999,Event,ADDED,eval-sanitize-1-r0-012-k4xb7.18d4a1e9dcd4bb0f,"reason=Pulled count=1 msg=Container image ""busybox:musl"" already present on machine"
0.1001,Event,ADDED,eval-sanitize-1-r0-012-k4xb7.18d4a1e9e19c08f4,reason=Created count=1 msg=Created container: task
0.1014,Pod,MODIFIED,eval-sanitize-3-r0-000-8w4zh,phase=Pending node=kind-worker3
0.1017,Event,ADDED,eval-sanitize-1-r0-012-k4xb7.18d4a1e9e669743a,reason=Started count=1 msg=Started container task
0.1019,Event,ADDED,eval-sanitize-1-r0-012.18d4a1e75360f665,reason=SuccessfulCreate count=1 msg=Created pod: eval-sanitize-1-r0-012-k4xb7
0.1021,Event,ADDED,eval-sanitize-1-r0-012.18d4a1ef46556c21,reason=Completed count=1 msg=Job completed
0.1033,Node,MODIFIED,kind-worker3,taints=0
0.1036,Event,ADDED,eval-sanitize-1-r0-013-9dnkt.18d4a1e78df30f4a,"reason=FailedScheduling count=None msg=0/6 nodes are available: 6 node(s) had untolerated taint(s). no new claims to deallocate, preemption: 0/6 nodes are available: 6 Preemption is not helpful for scheduling."
0.1037,Event,ADDED,eval-sanitize-1-r0-013-9dnkt.18d4a1e9bd43c1ce,"reason=FailedScheduling count=None msg=0/6 nodes are available: 1 c_wall violated: 1 conflicting context pair(s) with node memory, 5 node(s) had untolerated taint(s). no new claims to deallocate, preemption: 0/6 nodes are available: 1 No preemption victims found for incoming pod, 5 Preemption is not helpful for scheduling."
0.1039,Event,ADDED,eval-sanitize-1-r0-013-9dnkt.18d4a1e9ccb411ba,"reason=FailedScheduling count=None msg=0/6 nodes are available: 1 c_wall violated: 1 conflicting context pair(s) with node memory, 5 node(s) had untolerated taint(s). no new claims to deallocate, preemption: 0/6 nodes are available: 1 No preemption victims found for incoming pod, 5 Preemption is not helpful for scheduling."
0.1041,Event,ADDED,eval-sanitize-1-r0-013-9dnkt.18d4a1ea2c18ea3c,reason=Scheduled count=None msg=Successfully assigned compute/eval-sanitize-1-r0-013-9dnkt to kind-worker5
0.1043,Event,ADDED,eval-sanitize-1-r0-013-9dnkt.18d4a1ea4d0d2fa0,"reason=Pulled count=1 msg=Container image ""busybox:musl"" already present on machine"
0.1045,Event,ADDED,eval-sanitize-1-r0-013-9dnkt.18d4a1ea4e1f679a,reason=Created count=1 msg=Created container: task
0.1047,Event,ADDED,eval-sanitize-1-r0-013-9dnkt.18d4a1ea5542f343,reason=Started count=1 msg=Started container task
0.105,Event,ADDED,eval-sanitize-1-r0-013.18d4a1e78def5880,reason=SuccessfulCreate count=1 msg=Created pod: eval-sanitize-1-r0-013-9dnkt
0.1052,Event,ADDED,eval-sanitize-1-r0-013.18d4a1f0dcf8b92b,reason=Completed count=1 msg=Job completed
0.1053,Event,ADDED,eval-sanitize-1-r0-014-zhtr8.18d4a1e7c8de3b49,"reason=FailedScheduling count=None msg=0/6 nodes are available: 6 node(s) had untolerated taint(s). no new claims to deallocate, preemption: 0/6 nodes are available: 6 Preemption is not helpful for scheduling."
0.1055,Event,ADDED,eval-sanitize-1-r0-014-zhtr8.18d4a1e9c1097001,"reason=FailedScheduling count=None msg=0/6 nodes are available: 1 c_wall violated: 2 conflicting context pair(s) with node memory, 5 node(s) had untolerated taint(s). no new claims to deallocate, preemption: 0/6 nodes are available: 1 No preemption victims found for incoming pod, 5 Preemption is not helpful for scheduling."
0.1058,Event,ADDED,eval-sanitize-1-r0-014-zhtr8.18d4a1e9ccf9124e,"reason=FailedScheduling count=None msg=0/6 nodes are available: 1 c_wall violated: 3 conflicting context pair(s) with node memory, 5 node(s) had untolerated taint(s). no new claims to deallocate, preemption: 0/6 nodes are available: 1 No preemption victims found for incoming pod, 5 Preemption is not helpful for scheduling."
0.1061,Event,ADDED,eval-sanitize-1-r0-014-zhtr8.18d4a1e9d32500b5,"reason=FailedScheduling count=None msg=0/6 nodes are available: 1 c_wall violated: 3 conflicting context pair(s) with node memory, 5 node(s) had untolerated taint(s). no new claims to deallocate, preemption: 0/6 nodes are available: 1 No preemption victims found for incoming pod, 5 Preemption is not helpful for scheduling."
0.1062,Event,ADDED,eval-sanitize-1-r0-014-zhtr8.18d4a1ea27fb6008,"reason=FailedScheduling count=None msg=0/6 nodes are available: 1 c_wall violated: 1 conflicting context pair(s) with node memory, 5 node(s) had untolerated taint(s). no new claims to deallocate, preemption: 0/6 nodes are available: 1 No preemption victims found for incoming pod, 5 Preemption is not helpful for scheduling."
0.1068,Event,ADDED,eval-sanitize-1-r0-014-zhtr8.18d4a1ea32755765,"reason=FailedScheduling count=None msg=0/6 nodes are available: 1 c_wall violated: 2 conflicting context pair(s) with node memory, 5 node(s) had untolerated taint(s). no new claims to deallocate, preemption: 0/6 nodes are available: 1 No preemption victims found for incoming pod, 5 Preemption is not helpful for scheduling."
0.1072,Event,ADDED,eval-sanitize-1-r0-014-zhtr8.18d4a1ea3770d8f2,"reason=FailedScheduling count=None msg=0/6 nodes are available: 1 c_wall violated: 2 conflicting context pair(s) with node memory, 5 node(s) had untolerated taint(s). no new claims to deallocate, preemption: 0/6 nodes are available: 1 No preemption victims found for incoming pod, 5 Preemption is not helpful for scheduling."
0.1074,Event,ADDED,eval-sanitize-1-r0-014-zhtr8.18d4a1ea64940b64,reason=Scheduled count=None msg=Successfully assigned compute/eval-sanitize-1-r0-014-zhtr8 to kind-worker3
0.1078,Event,ADDED,eval-sanitize-1-r0-014-zhtr8.18d4a1ea88873c36,"reason=Pulled count=1 msg=Container image ""busybox:musl"" already present on machine"
0.1079,Event,ADDED,eval-sanitize-1-r0-014-zhtr8.18d4a1ea8efbd18c,reason=Created count=1 msg=Created container: task
0.1081,Event,ADDED,eval-sanitize-1-r0-014-zhtr8.18d4a1ea94122d35,reason=Started count=1 msg=Started container task
0.1085,Event,ADDED,eval-sanitize-1-r0-014.18d4a1e7c8d32638,reason=SuccessfulCreate count=1 msg=Created pod: eval-sanitize-1-r0-014-zhtr8
0.1087,Event,ADDED,eval-sanitize-1-r0-014.18d4a1f1008d9d0c,reason=Completed count=1 msg=Job completed
0.1088,Event,ADDED,eval-sanitize-1-r0-015-h8fgm.18d4a1e804ab51ac,"reason=FailedScheduling count=None msg=0/6 nodes are available: 6 node(s) had untolerated taint(s). no new claims to deallocate, preemption: 0/6 nodes are available: 6 Preemption is not helpful for scheduling."
0.1091,Event,ADDED,eval-sanitize-1-r0-015-h8fgm.18d4a1e9c3fe3935,reason=Scheduled count=None msg=Successfully assigned compute/eval-sanitize-1-r0-015-h8fgm to kind-worker
0.1094,Event,ADDED,eval-sanitize-1-r0-015-h8fgm.18d4a1e9e00d9f7e,"reason=Pulled count=1 msg=Container image ""busybox:musl"" already present on machine"
0.1096,Event,ADDED,eval-sanitize-1-r0-015-h8fgm.18d4a1e9e31ecc68,reason=Created count=1 msg=Created container: task
0.1098,Event,ADDED,eval-sanitize-1-r0-015-h8fgm.18d4a1e9e69cc805,reason=Started count=1 msg=Started container task
0.1099,Event,ADDED,eval-sanitize-1-r0-015.18d4a1e8049cbe84,reason=SuccessfulCreate count=1 msg=Created pod: eval-sanitize-1-r0-015-h8fgm
0.1103,Event,ADDED,eval-sanitize-1-r0-015.18d4a1ef830e7a77,reason=Completed count=1 msg=Job completed
0.1105,Event,ADDED,eval-sanitize-1-r0-016-7mb4n.18d4a1e8401a0f93,"reason=FailedScheduling count=None msg=0/6 nodes are available: 6 node(s) had untolerated taint(s). no new claims to deallocate, preemption: 0/6 nodes are available: 6 Preemption is not helpful for scheduling."
0.1108,Event,ADDED,eval-sanitize-1-r0-016-7mb4n.18d4a1e9c39b73b4,"reason=FailedScheduling count=None msg=0/6 nodes are available: 1 c_wall violated: 3 conflicting context pair(s) with node memory, 5 node(s) had untolerated taint(s). no new claims to deallocate, preemption: 0/6 nodes are available: 1 No preemption victims found for incoming pod, 5 Preemption is not helpful for scheduling."
0.1111,Event,ADDED,eval-sanitize-1-r0-016-7mb4n.18d4a1e9cd8eb7a2,"reason=FailedScheduling count=None msg=0/6 nodes are available: 1 c_wall violated: 3 conflicting context pair(s) with node memory, 5 node(s) had untolerated taint(s). no new claims to deallocate, preemption: 0/6 nodes are available: 1 No preemption victims found for incoming pod, 5 Preemption is not helpful for scheduling."
0.1113,Event,ADDED,eval-sanitize-1-r0-016-7mb4n.18d4a1ea28c3573b,"reason=FailedScheduling count=None msg=0/6 nodes are available: 1 c_wall violated: 1 conflicting context pair(s) with node memory, 5 node(s) had untolerated taint(s). no new claims to deallocate, preemption: 0/6 nodes are available: 1 No preemption victims found for incoming pod, 5 Preemption is not helpful for scheduling."
0.1115,Event,ADDED,eval-sanitize-1-r0-016-7mb4n.18d4a1ea3683dd8a,"reason=FailedScheduling count=None msg=0/6 nodes are available: 1 c_wall violated: 2 conflicting context pair(s) with node memory, 5 node(s) had untolerated taint(s). no new claims to deallocate, preemption: 0/6 nodes are available: 1 No preemption victims found for incoming pod, 5 Preemption is not helpful for scheduling."
0.1119,Event,ADDED,eval-sanitize-1-r0-016-7mb4n.18d4a1ea37fe6c4c,"reason=FailedScheduling count=None msg=0/6 nodes are available: 1 c_wall violated: 2 conflicting context pair(s) with node memory, 5 node(s) had untolerated taint(s). no new claims to deallocate, preemption: 0/6 nodes are available: 1 No preemption victims found for incoming pod, 5 Preemption is not helpful for scheduling."
0.112,Event,ADDED,eval-sanitize-1-r0-016-7mb4n.18d4a1ea5e97cc60,reason=Scheduled count=None msg=Successfully assigned compute/eval-sanitize-1-r0-016-7mb4n to kind-worker3
0.1122,Event,ADDED,eval-sanitize-1-r0-016-7mb4n.18d4a1ea7df0ffb4,"reason=Pulled count=1 msg=Container image ""busybox:musl"" already present on machine"
0.1126,Event,ADDED,eval-sanitize-1-r0-016-7mb4n.18d4a1ea806af052,reason=Created count=1 msg=Created container: task
0.1131,Event,ADDED,eval-sanitize-1-r0-016-7mb4n.18d4a1ea8885bb74,reason=Started count=1 msg=Started container task
0.1135,Event,ADDED,eval-sanitize-1-r0-016.18d4a1e8400b0c70,reason=SuccessfulCreate count=1 msg=Created pod: eval-sanitize-1-r0-016-7mb4n
0.1137,Event,ADDED,eval-sanitize-1-r0-016.18d4a1f0fa983b90,reason=Completed count=1 msg=Job completed
0.1141,Event,ADDED,eval-sanitize-1-r0-017-b8jx9.18d4a1e87c3f6cf4,"reason=FailedScheduling count=None msg=0/6 nodes are available: 6 node(s) had untolerated taint(s). no new claims to deallocate, preemption: 0/6 nodes are available: 6 Preemption is not helpful for scheduling."
0.1143,Event,ADDED,eval-sanitize-1-r0-017-b8jx9.18d4a1e9c48c4a4f,reason=Scheduled count=None msg=Successfully assigned compute/eval-sanitize-1-r0-017-b8jx9 to kind-worker
0.1145,Event,ADDED,eval-sanitize-1-r0-017-b8jx9.18d4a1e9e4d8b523,"reason=Pulled count=1 msg=Container image ""busybox:musl"" already present on machine"
0.1147,Event,ADDED,eval-sanitize-1-r0-017-b8jx9.18d4a1e9e721f390,reason=Created count=1 msg=Created container: task
0.1153,Event,ADDED,eval-sanitize-1-r0-017-b8jx9.18d4a1e9e978fc73,reason=Started count=1 msg=Started container task
0.1155,Event,ADDED,eval-sanitize-1-r0-017.18d4a1e87c3480c9,reason=SuccessfulCreate count=1 msg=Created pod: eval-sanitize-1-r0-017-b8jx9
0.1156,Event,ADDED,eval-sanitize-1-r0-017.18d4a1ef8136fd7a,reason=Completed count=1 msg=Job completed
0.1168,Node,MODIFIED,kind-worker3,taints=0
0.1172,Event,ADDED,eval-sanitize-1-r0-018-6l9xb.18d4a1e8b79bbc22,"reason=FailedScheduling count=None msg=0/6 nodes are available: 6 node(s) had untolerated taint(s). no new claims to deallocate, preemption: 0/6 nodes are available: 6 Preemption is not helpful for scheduling."
0.1174,Event,ADDED,eval-sanitize-1-r0-018-6l9xb.18d4a1e9c4707ecd,"reason=FailedScheduling count=None msg=0/6 nodes are available: 1 c_wall violated: 2 conflicting context pair(s) with node memory, 5 node(s) had untolerated taint(s). no new claims to deallocate, preemption: 0/6 nodes are available: 1 No preemption victims found for incoming pod, 5 Preemption is not helpful for scheduling."
0.1176,Event,ADDED,eval-sanitize-1-r0-018-6l9xb.18d4a1e9cf4b2dfc,"reason=FailedScheduling count=None msg=0/6 nodes are available: 1 c_wall violated: 2 conflicting context pair(s) with node memory, 5 node(s) had untolerated taint(s). no new claims to deallocate, preemption: 0/6 nodes are available: 1 No preemption victims found for incoming pod, 5 Preemption is not helpful for scheduling."
0.1179,Event,ADDED,eval-sanitize-1-r0-018-6l9xb.18d4a1ea26e2034e,reason=Scheduled count=None msg=Successfully assigned compute/eval-sanitize-1-r0-018-6l9xb to kind-worker5
0.118,Event,ADDED,eval-sanitize-1-r0-018-6l9xb.18d4a1ea446832c8,"reason=Pulled count=1 msg=Container image ""busybox:musl"" already present on machine"
0.1182,Event,ADDED,eval-sanitize-1-r0-018-6l9xb.18d4a1ea4773ce22,reason=Created count=1 msg=Created container: task
0.1184,Event,ADDED,eval-sanitize-1-r0-018-6l9xb.18d4a1ea5546fefe,reason=Started count=1 msg=Started container task
0.1186,Event,ADDED,eval-sanitize-1-r0-018.18d4a1e8b78e3c30,reason=SuccessfulCreate count=1 msg=Created pod: eval-sanitize-1-r0-018-6l9xb
0.1188,Event,ADDED,eval-sanitize-1-r0-018.18d4a1f0e8d42c9b,reason=Completed count=1 msg=Job completed
0.1189,Event,ADDED,eval-sanitize-1-r0-019-79mlm.18d4a1e8f4d36dd8,"reason=FailedScheduling count=None msg=0/6 nodes are available: 6 node(s) had untolerated taint(s). no new claims to deallocate, preemption: 0/6 nodes are available: 6 Preemption is not helpful for scheduling."
0.1191,Event,ADDED,eval-sanitize-1-r0-019-79mlm.18d4a1e9c58ee2c0,reason=Scheduled count=None msg=Successfully assigned compute/eval-sanitize-1-r0-019-79mlm to kind-worker
0.1193,Event,ADDED,eval-sanitize-1-r0-019-79mlm.18d4a1e9e3dc5a9c,"reason=Pulled count=1 msg=Container image ""busybox:musl"" already present on machine"
0.1194,Event,ADDED,eval-sanitize-1-r0-019-79mlm.18d4a1e9e556e810,reason=Created count=1 msg=Created container: task
0.1196,Event,ADDED,eval-sanitize-1-r0-019-79mlm.18d4a1e9e7fb6142,reason=Started count=1 msg=Started container task
0.1198,Event,ADDED,eval-sanitize-1-r0-019.18d4a1e8f4c7422d,reason=SuccessfulCreate count=1 msg=Created pod: eval-sanitize-1-r0-019-79mlm
0.1199,Event,ADDED,eval-sanitize-1-r0-019.18d4a1f0100956ae,reason=Completed count=1 msg=Job completed
0.1201,Event,ADDED,eval-sanitize-1-r0-020-x7b6m.18d4a1e92e9d0174,"reason=FailedScheduling count=None msg=0/6 nodes are available: 6 node(s) had untolerated taint(s). no new claims to deallocate, preemption: 0/6 nodes are available: 6 Preemption is not helpful for scheduling."
0.1202,Event,ADDED,eval-sanitize-1-r0-020-x7b6m.18d4a1e9c55f838e,"reason=FailedScheduling count=None msg=0/6 nodes are available: 1 c_wall violated: 2 conflicting context pair(s) with node memory, 5 node(s) had untolerated taint(s). no new claims to deallocate, preemption: 0/6 nodes are available: 1 No preemption victims found for incoming pod, 5 Preemption is not helpful for scheduling."
0.1204,Event,ADDED,eval-sanitize-1-r0-020-x7b6m.18d4a1e9cf9078e7,"reason=FailedScheduling count=None msg=0/6 nodes are available: 1 c_wall violated: 2 conflicting context pair(s) with node memory, 5 node(s) had untolerated taint(s). no new claims to deallocate, preemption: 0/6 nodes are available: 1 No preemption victims found for incoming pod, 5 Preemption is not helpful for scheduling."
0.1206,Event,ADDED,eval-sanitize-1-r0-020-x7b6m.18d4a1ea272caf25,reason=Scheduled count=None msg=Successfully assigned compute/eval-sanitize-1-r0-020-x7b6m to kind-worker5
0.1207,Event,ADDED,eval-sanitize-1-r0-020-x7b6m.18d4a1ea449336d0,"reason=Pulled count=1 msg=Container image ""busybox:musl"" already present on machine"
0.121,Event,ADDED,eval-sanitize-1-r0-020-x7b6m.18d4a1ea47f0ce5e,reason=Created count=1 msg=Created container: task
0.1213,Event,ADDED,eval-sanitize-1-r0-020-x7b6m.18d4a1ea5546d500,reason=Started count=1 msg=Started container task
0.1214,Event,ADDED,eval-sanitize-1-r0-020.18d4a1e92e941511,reason=SuccessfulCreate count=1 msg=Created pod: eval-sanitize-1-r0-020-x7b6m
0.1216,Event,ADDED,eval-sanitize-1-r0-020.18d4a1f0d6c1548f,reason=Completed count=1 msg=Job completed
0.1218,Event,ADDED,eval-sanitize-1-r0-021-dlgsx.18d4a1e9694c8c3b,"reason=FailedScheduling count=None msg=0/6 nodes are available: 6 node(s) had untolerated taint(s). no new claims to deallocate, preemption: 0/6 nodes are available: 6 Preemption is not helpful for scheduling."
0.122,Event,ADDED,eval-sanitize-1-r0-021-dlgsx.18d4a1e9c743bd7a,reason=Scheduled count=None msg=Successfully assigned compute/eval-sanitize-1-r0-021-dlgsx to kind-worker
0.1221,Event,ADDED,eval-sanitize-1-r0-021-dlgsx.18d4a1e9e55bd823,"reason=Pulled count=1 msg=Container image ""busybox:musl"" already present on machine"
0.1223,Event,ADDED,eval-sanitize-1-r0-021-dlgsx.18d4a1e9e7aa3e0d,reason=Created count=1 msg=Created container: task
0.1225,Event,ADDED,eval-sanitize-1-r0-021-dlgsx.18d4a1e9e9cb4717,reason=Started count=1 msg=Started container task
0.1226,Event,ADDED,eval-sanitize-1-r0-021.18d4a1e9694080a0,reason=SuccessfulCreate count=1 msg=Created pod: eval-sanitize-1-r0-021-dlgsx
0.1228,Event,ADDED,eval-sanitize-1-r0-021.18d4a1ef4a97d921,reason=Completed count=1 msg=Job completed
0.1232,Event,ADDED,eval-sanitize-1-r0-022-fwgsk.18d4a1e9a4f31bdd,"reason=FailedScheduling count=None msg=0/6 nodes are available: 6 node(s) had untolerated taint(s). no new claims to deallocate, preemption: 0/6 nodes are available: 6 Preemption is not helpful for scheduling."
0.1234,Event,ADDED,eval-sanitize-1-r0-022-fwgsk.18d4a1e9c768d49f,reason=Scheduled count=None msg=Successfully assigned compute/eval-sanitize-1-r0-022-fwgsk to kind-worker
0.1236,Event,ADDED,eval-sanitize-1-r0-022-fwgsk.18d4a1e9e579302d,"reason=Pulled count=1 msg=Container image ""busybox:musl"" already present on machine"
0.1237,Event,ADDED,eval-sanitize-1-r0-022-fwgsk.18d4a1e9e7f50e4c,reason=Created count=1 msg=Created container: task
0.124,Event,ADDED,eval-sanitize-1-r0-022-fwgsk.18d4a1e9ea36afe7,reason=Started count=1 msg=Started container task
0.1241,Event,ADDED,eval-sanitize-1-r0-022.18d4a1e9a4e342f1,reason=SuccessfulCreate count=1 msg=Created pod: eval-sanitize-1-r0-022-fwgsk
0.1243,Event,ADDED,eval-sanitize-1-r0-022.18d4a1f042fd6c74,reason=Completed count=1 msg=Job completed
0.1244,Event,ADDED,eval-sanitize-1-r0-023-xvhxj.18d4a1e9e647226d,"reason=FailedScheduling count=None msg=0/6 nodes are available: 1 c_wall violated: 1 conflicting context pair(s) with node memory, 5 node(s) had untolerated taint(s). no new claims to deallocate, preemption: 0/6 nodes are available: 1 No preemption victims found for incoming pod, 5 Preemption is not helpful for scheduling."
0.1246,Event,ADDED,eval-sanitize-1-r0-023-xvhxj.18d4a1e9e77191d8,"reason=FailedScheduling count=None msg=0/6 nodes are available: 1 c_wall violated: 1 conflicting context pair(s) with node memory, 5 node(s) had untolerated taint(s). no new claims to deallocate, preemption: 0/6 nodes are available: 1 No preemption victims found for incoming pod, 5 Preemption is not helpful for scheduling."
0.1248,Event,ADDED,eval-sanitize-1-r0-023-xvhxj.18d4a1ea30a5f7a9,reason=Scheduled count=None msg=Successfully assigned compute/eval-sanitize-1-r0-023-xvhxj to kind-worker5
0.1249,Event,ADDED,eval-sanitize-1-r0-023-xvhxj.18d4a1ea554b2447,"reason=Pulled count=1 msg=Container image ""busybox:musl"" already present on machine"
0.1252,Event,ADDED,eval-sanitize-1-r0-023-xvhxj.18d4a1ea569db8a8,reason=Created count=1 msg=Created container: task
0.1254,Event,ADDED,eval-sanitize-1-r0-023-xvhxj.18d4a1ea5ab749ae,reason=Started count=1 msg=Started container task
0.1255,Event,ADDED,eval-sanitize-1-r0-023.18d4a1e9e2eb2fbe,reason=SuccessfulCreate count=1 msg=Created pod: eval-sanitize-1-r0-023-xvhxj
0.1258,Event,ADDED,eval-sanitize-1-r0-023.18d4a1f0d0cef828,reason=Completed count=1 msg=Job completed
0.1259,Event,ADDED,eval-sanitize-1-r0-024-gzh4k.18d4a1ea1f0b1b5e,"reason=FailedScheduling count=None msg=0/6 nodes are available: 6 node(s) had untolerated taint(s). no new claims to deallocate, preemption: 0/6 nodes are available: 6 Preemption is not helpful for scheduling."
0.1261,Event,ADDED,eval-sanitize-1-r0-024-gzh4k.18d4a1ea2c8a37c7,"reason=FailedScheduling count=None msg=0/6 nodes are available: 1 c_wall violated: 2 conflicting context pair(s) with node memory, 5 node(s) had untolerated taint(s). no new claims to deallocate, preemption: 0/6 nodes are available: 1 No preemption victims found for incoming pod, 5 Preemption is not helpful for scheduling."
0.1263,Event,ADDED,eval-sanitize-1-r0-024-gzh4k.18d4a1ea371163b9,"reason=FailedScheduling count=None msg=0/6 nodes are available: 1 c_wall violated: 2 conflicting context pair(s) with node memory, 5 node(s) had untolerated taint(s). no new claims to deallocate, preemption: 0/6 nodes are available: 1 No preemption victims found for incoming pod, 5 Preemption is not helpful for scheduling."
0.1265,Event,ADDED,eval-sanitize-1-r0-024-gzh4k.18d4a1ea64975d7c,"reason=FailedScheduling count=None msg=0/6 nodes are available: 1 c_wall violated: 2 conflicting context pair(s) with node memory, 5 node(s) had untolerated taint(s). no new claims to deallocate, preemption: 0/6 nodes are available: 1 No preemption victims found for incoming pod, 5 Preemption is not helpful for scheduling."
0.1266,Event,ADDED,eval-sanitize-1-r0-024-gzh4k.18d4a1ea6605d6c1,"reason=FailedScheduling count=None msg=0/6 nodes are available: 1 c_wall violated: 2 conflicting context pair(s) with node memory, 5 node(s) had untolerated taint(s). no new claims to deallocate, preemption: 0/6 nodes are available: 1 No preemption victims found for incoming pod, 5 Preemption is not helpful for scheduling."
0.1268,Event,ADDED,eval-sanitize-1-r0-024-gzh4k.18d4a1eaa02916c5,reason=Scheduled count=None msg=Successfully assigned compute/eval-sanitize-1-r0-024-gzh4k to kind-worker4
0.127,Event,ADDED,eval-sanitize-1-r0-024-gzh4k.18d4a1eac06aa488,"reason=Pulled count=1 msg=Container image ""busybox:musl"" already present on machine"
0.1271,Event,ADDED,eval-sanitize-1-r0-024-gzh4k.18d4a1eac1e020f6,reason=Created count=1 msg=Created container: task
0.1273,Event,ADDED,eval-sanitize-1-r0-024-gzh4k.18d4a1eacb311ffe,reason=Started count=1 msg=Started container task
0.1275,Event,ADDED,eval-sanitize-1-r0-024.18d4a1ea1f01e927,reason=SuccessfulCreate count=1 msg=Created pod: eval-sanitize-1-r0-024-gzh4k
0.1276,Event,ADDED,eval-sanitize-1-r0-024.18d4a1f106c16c5c,reason=Completed count=1 msg=Job completed
0.1278,Event,ADDED,eval-sanitize-1-r0-025-pdqlc.18d4a1ea5888aeec,"reason=FailedScheduling count=None msg=0/6 nodes are available: 1 c_wall violated: 2 conflicting context pair(s) with node memory, 5 node(s) had untolerated taint(s). no new claims to deallocate, preemption: 0/6 nodes are available: 1 No preemption victims found for incoming pod, 5 Preemption is not helpful for scheduling."
0.128,Event,ADDED,eval-sanitize-1-r0-025-pdqlc.18d4a1ea5901664a,"reason=FailedScheduling count=None msg=0/6 nodes are available: 1 c_wall violated: 2 conflicting context pair(s) with node memory, 5 node(s) had untolerated taint(s). no new claims to deallocate, preemption: 0/6 nodes are available: 1 No preemption victims found for incoming pod, 5 Preemption is not helpful for scheduling."
0.1281,Event,ADDED,eval-sanitize-1-r0-025-pdqlc.18d4a1ea64bcfdf0,reason=Scheduled count=None msg=Successfully assigned compute/eval-sanitize-1-r0-025-pdqlc to kind-worker3
0.1283,Event,ADDED,eval-sanitize-1-r0-025-pdqlc.18d4a1ea888bae2c,"reason=Pulled count=1 msg=Container image ""busybox:musl"" already present on machine"
0.1285,Event,ADDED,eval-sanitize-1-r0-025-pdqlc.18d4a1ea89f160cd,reason=Created count=1 msg=Created container: task
0.1286,Event,ADDED,eval-sanitize-1-r0-025-pdqlc.18d4a1ea8efedc82,reason=Started count=1 msg=Started container task
0.1288,Event,ADDED,eval-sanitize-1-r0-025.18d4a1ea58406d2a,reason=SuccessfulCreate count=1 msg=Created pod: eval-sanitize-1-r0-025-pdqlc
0.129,Event,ADDED,eval-sanitize-1-r0-025.18d4a1f0ee965a28,reason=Completed count=1 msg=Job completed
0.1292,Event,ADDED,eval-sanitize-1-r0-026-fnk7r.18d4a1ea94c2e24d,"reason=FailedScheduling count=None msg=0/6 nodes are available: 1 c_wall violated: 2 conflicting context pair(s) with node memory, 5 node(s) had untolerated taint(s). no new claims to deallocate, preemption: 0/6 nodes are available: 1 No preemption victims found for incoming pod, 5 Preemption is not helpful for scheduling."
0.1294,Event,ADDED,eval-sanitize-1-r0-026-fnk7r.18d4a1ea95b1c034,"reason=FailedScheduling count=None msg=0/6 nodes are available: 1 c_wall violated: 2 conflicting context pair(s) with node memory, 5 node(s) had untolerated taint(s). no new claims to deallocate, preemption: 0/6 nodes are available: 1 No preemption victims found for incoming pod, 5 Preemption is not helpful for scheduling."
0.1295,Event,ADDED,eval-sanitize-1-r0-026-fnk7r.18d4a1ea9fbf45e1,reason=Scheduled count=None msg=Successfully assigned compute/eval-sanitize-1-r0-026-fnk7r to kind-worker4
0.1297,Event,ADDED,eval-sanitize-1-r0-026-fnk7r.18d4a1eac0878693,"reason=Pulled count=1 msg=Container image ""busybox:musl"" already present on machine"
0.1299,Event,ADDED,eval-sanitize-1-r0-026-fnk7r.18d4a1eac236cb18,reason=Created count=1 msg=Created container: task
0.1301,Event,ADDED,eval-sanitize-1-r0-026-fnk7r.18d4a1eacb30e6dd,reason=Started count=1 msg=Started container task
0.1303,Event,ADDED,eval-sanitize-1-r0-026.18d4a1ea9481ada0,reason=SuccessfulCreate count=1 msg=Created pod: eval-sanitize-1-r0-026-fnk7r
0.1305,Event,ADDED,eval-sanitize-1-r0-026.18d4a1f10978f186,reason=Completed count=1 msg=Job completed
0.1306,Event,ADDED,eval-sanitize-1-r0-027-l2jnc.18d4a1ead4ffbd98,reason=Scheduled count=None msg=Successfully assigned compute/eval-sanitize-1-r0-027-l2jnc to kind-worker2
0.1308,Event,ADDED,eval-sanitize-1-r0-027-l2jnc.18d4a1eb0632d8be,"reason=Pulled count=1 msg=Container image ""busybox:musl"" already present on machine"
0.131,Event,ADDED,eval-sanitize-1-r0-027-l2jnc.18d4a1eb07420718,reason=Created count=1 msg=Created container: task
0.1315,Event,ADDED,eval-sanitize-1-r0-027-l2jnc.18d4a1eb09486a11,reason=Started count=1 msg=Started container task
0.1316,Event,ADDED,eval-sanitize-1-r0-027.18d4a1ead48fdc08,reason=SuccessfulCreate count=1 msg=Created pod: eval-sanitize-1-r0-027-l2jnc
0.1318,Event,ADDED,eval-sanitize-1-r0-027.18d4a1f128208e70,reason=Completed count=1 msg=Job completed
0.132,Event,ADDED,eval-sanitize-1-r0-028-7sd2b.18d4a1eb0ab24f42,"reason=FailedScheduling count=None msg=0/6 nodes are available: 6 node(s) had untolerated taint(s). no new claims to deallocate, preemption: 0/6 nodes are available: 6 Preemption is not helpful for scheduling."
0.1322,Event,ADDED,eval-sanitize-1-r0-028-7sd2b.18d4a1ef408f9825,reason=Scheduled count=None msg=Successfully assigned compute/eval-sanitize-1-r0-028-7sd2b to kind-worker
0.1324,Event,ADDED,eval-sanitize-1-r0-028-7sd2b.18d4a1ef6cb8cc0c,"reason=Pulled count=1 msg=Container image ""busybox:musl"" already present on machine"
0.1326,Event,ADDED,eval-sanitize-1-r0-028-7sd2b.18d4a1ef6e276659,reason=Created count=1 msg=Created container: task
0.1329,Event,ADDED,eval-sanitize-1-r0-028-7sd2b.18d4a1ef7f91e5a5,reason=Started count=1 msg=Started container task
0.1332,Event,ADDED,eval-sanitize-1-r0-028.18d4a1eb0aa44b89,reason=SuccessfulCreate count=1 msg=Created pod: eval-sanitize-1-r0-028-7sd2b
0.1334,Event,ADDED,eval-sanitize-1-r0-028.18d4a1f4ab194be6,reason=Completed count=1 msg=Job completed
0.1336,Event,ADDED,eval-sanitize-1-r0-029-l6s5v.18d4a1eb4640a568,"reason=FailedScheduling count=None msg=0/6 nodes are available: 6 node(s) had untolerated taint(s). no new claims to deallocate, preemption: 0/6 nodes are available: 6 Preemption is not helpful for scheduling."
0.1344,Event,ADDED,eval-sanitize-1-r0-029-l6s5v.18d4a1ef4118301f,reason=Scheduled count=None msg=Successfully assigned compute/eval-sanitize-1-r0-029-l6s5v to kind-worker
0.1346,Event,ADDED,eval-sanitize-1-r0-029-l6s5v.18d4a1ef5e6edefc,"reason=Pulled count=1 msg=Container image ""busybox:musl"" already present on machine"
0.1348,Event,ADDED,eval-sanitize-1-r0-029-l6s5v.18d4a1ef61d4bf9c,reason=Created count=1 msg=Created container: task
0.1351,Event,ADDED,eval-sanitize-1-r0-029-l6s5v.18d4a1ef67309168,reason=Started count=1 msg=Started container task
0.1353,Event,ADDED,eval-sanitize-1-r0-029.18d4a1eb46353e55,reason=SuccessfulCreate count=1 msg=Created pod: eval-sanitize-1-r0-029-l6s5v
0.1355,Event,ADDED,eval-sanitize-1-r0-029.18d4a1f4e91f48e9,reason=Completed count=1 msg=Job completed
0.1356,Event,ADDED,eval-sanitize-1-r0-030-vw62w.18d4a1eb824b5164,"reason=FailedScheduling count=None msg=0/6 nodes are available: 6 node(s) had untolerated taint(s). no new claims to deallocate, preemption: 0/6 nodes are available: 6 Preemption is not helpful for scheduling."
0.1359,Event,ADDED,eval-sanitize-1-r0-030-vw62w.18d4a1ef40f31a83,"reason=FailedScheduling count=None msg=0/6 nodes are available: 1 c_wall violated: 2 conflicting context pair(s) with node memory, 5 node(s) had untolerated taint(s). no new claims to deallocate, preemption: 0/6 nodes are available: 1 No preemption victims found for incoming pod, 5 Preemption is not helpful for scheduling."
0.1361,Event,ADDED,eval-sanitize-1-r0-030-vw62w.18d4a1ef54f2b9c1,"reason=FailedScheduling count=None msg=0/6 nodes are available: 1 c_wall violated: 3 conflicting context pair(s) with node memory, 5 node(s) had untolerated taint(s). no new claims to deallocate, preemption: 0/6 nodes are available: 1 No preemption victims found for incoming pod, 5 Preemption is not helpful for scheduling."
0.1363,Event,ADDED,eval-sanitize-1-r0-030-vw62w.18d4a1ef6013c693,"reason=FailedScheduling count=None msg=0/6 nodes are available: 1 c_wall violated: 3 conflicting context pair(s) with node memory, 5 node(s) had untolerated taint(s). no new claims to deallocate, preemption: 0/6 nodes are available: 1 No preemption victims found for incoming pod, 5 Preemption is not helpful for scheduling."
0.1366,Event,ADDED,eval-sanitize-1-r0-030-vw62w.18d4a1efbaf7622a,"reason=FailedScheduling count=None msg=0/6 nodes are available: 1 c_wall violated: 1 conflicting context pair(s) with node memory, 5 node(s) had untolerated taint(s). no new claims to deallocate, preemption: 0/6 nodes are available: 1 No preemption victims found for incoming pod, 5 Preemption is not helpful for scheduling."
0.1368,Event,ADDED,eval-sanitize-1-r0-030-vw62w.18d4a1efc5422c96,"reason=FailedScheduling count=None msg=0/6 nodes are available: 1 c_wall violated: 1 conflicting context pair(s) with node memory, 5 node(s) had untolerated taint(s). no new claims to deallocate, preemption: 0/6 nodes are available: 1 No preemption victims found for incoming pod, 5 Preemption is not helpful for scheduling."
0.137,Event,ADDED,eval-sanitize-1-r0-030-vw62w.18d4a1f0106665fe,reason=Scheduled count=None msg=Successfully assigned compute/eval-sanitize-1-r0-030-vw62w to kind-worker3
0.1373,Event,ADDED,eval-sanitize-1-r0-030-vw62w.18d4a1f042fb88c9,"reason=Pulled count=1 msg=Container image ""busybox:musl"" already present on machine"
0.1375,Event,ADDED,eval-sanitize-1-r0-030-vw62w.18d4a1f044e692bc,reason=Created count=1 msg=Created container: task
0.1377,Event,ADDED,eval-sanitize-1-r0-030-vw62w.18d4a1f048912a19,reason=Started count=1 msg=Started container task
0.1379,Event,ADDED,eval-sanitize-1-r0-030.18d4a1eb823e1d0a,reason=SuccessfulCreate count=1 msg=Created pod: eval-sanitize-1-r0-030-vw62w
0.1382,Event,ADDED,eval-sanitize-1-r0-030.18d4a1f66e465dfd,reason=Completed count=1 msg=Job completed
0.1383,Event,ADDED,eval-sanitize-1-r0-031-l2zt6.18d4a1ebbfd686c3,"reason=FailedScheduling count=None msg=0/6 nodes are available: 6 node(s) had untolerated taint(s). no new claims to deallocate, preemption: 0/6 nodes are available: 6 Preemption is not helpful for scheduling."
0.1385,Event,ADDED,eval-sanitize-1-r0-031-l2zt6.18d4a1ef41fd7323,reason=Scheduled count=None msg=Successfully assigned compute/eval-sanitize-1-r0-031-l2zt6 to kind-worker
0.1387,Event,ADDED,eval-sanitize-1-r0-031-l2zt6.18d4a1ef5e9d4293,"reason=Pulled count=1 msg=Container image ""busybox:musl"" already present on machine"
0.139,Event,ADDED,eval-sanitize-1-r0-031-l2zt6.18d4a1ef628be6a6,reason=Created count=1 msg=Created container: task
0.1392,Event,ADDED,eval-sanitize-1-r0-031-l2zt6.18d4a1ef6730ad4b,reason=Started count=1 msg=Started container task
0.1394,Event,ADDED,eval-sanitize-1-r0-031.18d4a1ebbfcc7783,reason=SuccessfulCreate count=1 msg=Created pod: eval-sanitize-1-r0-031-l2zt6
0.1397,Event,ADDED,eval-sanitize-1-r0-031.18d4a1f4e8abdf10,reason=Completed count=1 msg=Job completed
0.1398,Event,ADDED,eval-sanitize-1-r0-032-sgw5t.18d4a1ebfa13d48a,"reason=FailedScheduling count=None msg=0/6 nodes are available: 6 node(s) had untolerated taint(s). no new claims to deallocate, preemption: 0/6 nodes are available: 6 Preemption is not helpful for scheduling."
0.14,Event,ADDED,eval-sanitize-1-r0-032-sgw5t.18d4a1ef41ddc96c,"reason=FailedScheduling count=None msg=0/6 nodes are available: 1 c_wall violated: 1 conflicting context pair(s) with node memory, 5 node(s) had untolerated taint(s). no new claims to deallocate, preemption: 0/6 nodes are available: 1 No preemption victims found for incoming pod, 5 Preemption is not helpful for scheduling."
0.1402,Event,ADDED,eval-sanitize-1-r0-032-sgw5t.18d4a1ef579e1698,"reason=FailedScheduling count=None msg=0/6 nodes are available: 1 c_wall violated: 1 conflicting context pair(s) with node memory, 5 node(s) had untolerated taint(s). no new claims to deallocate, preemption: 0/6 nodes are available: 1 No preemption victims found for incoming pod, 5 Preemption is not helpful for scheduling."
0.1404,Event,ADDED,eval-sanitize-1-r0-032-sgw5t.18d4a1efc321e701,reason=Scheduled count=None msg=Successfully assigned compute/eval-sanitize-1-r0-032-sgw5t to kind-worker5
0.1406,Event,ADDED,eval-sanitize-1-r0-032-sgw5t.18d4a1efe20e7e62,"reason=Pulled count=1 msg=Container image ""busybox:musl"" already present on machine"
0.1407,Event,ADDED,eval-sanitize-1-r0-032-sgw5t.18d4a1efe4953e13,reason=Created count=1 msg=Created container: task
0.1409,Event,ADDED,eval-sanitize-1-r0-032-sgw5t.18d4a1efe971ee1a,reason=Started count=1 msg=Started container task
0.1411,Event,ADDED,eval-sanitize-1-r0-032.18d4a1ebfa07f0c1,reason=SuccessfulCreate count=1 msg=Created pod: eval-sanitize-1-r0-032-sgw5t
0.1413,Event,ADDED,eval-sanitize-1-r0-032.18d4a1f5dc47c324,reason=Completed count=1 msg=Job completed
0.1414,Event,ADDED,eval-sanitize-1-r0-033-dqq5s.18d4a1ec3514930f,"reason=FailedScheduling count=None msg=0/6 nodes are available: 6 node(s) had untolerated taint(s). no new claims to deallocate, preemption: 0/6 nodes are available: 6 Preemption is not helpful for scheduling."
0.1416,Event,ADDED,eval-sanitize-1-r0-033-dqq5s.18d4a1ef4262dda9,"reason=FailedScheduling count=None msg=0/6 nodes are available: 1 c_wall violated: 2 conflicting context pair(s) with node memory, 5 node(s) had untolerated taint(s). no new claims to deallocate, preemption: 0/6 nodes are available: 1 No preemption victims found for incoming pod, 5 Preemption is not helpful for scheduling."
0.1417,Event,ADDED,eval-sanitize-1-r0-033-dqq5s.18d4a1ef58bcda41,"reason=FailedScheduling count=None msg=0/6 nodes are available: 1 c_wall violated: 3 conflicting context pair(s) with node memory, 5 node(s) had untolerated taint(s). no new claims to deallocate, preemption: 0/6 nodes are available: 1 No preemption victims found for incoming pod, 5 Preemption is not helpful for scheduling."
0.1419,Event,ADDED,eval-sanitize-1-r0-033-dqq5s.18d4a1ef64b5615f,"reason=FailedScheduling count=None msg=0/6 nodes are available: 1 c_wall violated: 3 conflicting context pair(s) with node memory, 5 node(s) had untolerated taint(s). no new claims to deallocate, preemption: 0/6 nodes are available: 1 No preemption victims found for incoming pod, 5 Preemption is not helpful for scheduling."
0.1421,Event,ADDED,eval-sanitize-1-r0-033-dqq5s.18d4a1efc2f004e3,"reason=FailedScheduling count=None msg=0/6 nodes are available: 1 c_wall violated: 1 conflicting context pair(s) with node memory, 5 node(s) had untolerated taint(s). no new claims to deallocate, preemption: 0/6 nodes are available: 1 No preemption victims found for incoming pod, 5 Preemption is not helpful for scheduling."
0.1422,Event,ADDED,eval-sanitize-1-r0-033-dqq5s.18d4a1efc8c61c35,"reason=FailedScheduling count=None msg=0/6 nodes are available: 1 c_wall violated: 1 conflicting context pair(s) with node memory, 5 node(s) had untolerated taint(s). no new claims to deallocate, preemption: 0/6 nodes are available: 1 No preemption victims found for incoming pod, 5 Preemption is not helpful for scheduling."
0.1424,Event,ADDED,eval-sanitize-1-r0-033-dqq5s.18d4a1f010c6b1db,reason=Scheduled count=None msg=Successfully assigned compute/eval-sanitize-1-r0-033-dqq5s to kind-worker3
0.1426,Event,ADDED,eval-sanitize-1-r0-033-dqq5s.18d4a1f0435a6bd9,"reason=Pulled count=1 msg=Container image ""busybox:musl"" already present on machine"
0.1427,Event,ADDED,eval-sanitize-1-r0-033-dqq5s.18d4a1f0460a643b,reason=Created count=1 msg=Created container: task
0.1429,Event,ADDED,eval-sanitize-1-r0-033-dqq5s.18d4a1f049386af0,reason=Started count=1 msg=Started container task
0.1434,Event,ADDED,eval-sanitize-1-r0-033.18d4a1ec35068d52,reason=SuccessfulCreate count=1 msg=Created pod: eval-sanitize-1-r0-033-dqq5s
0.1435,Event,ADDED,eval-sanitize-1-r0-033.18d4a1f6655ce791,reason=Completed count=1 msg=Job completed
0.1437,Event,ADDED,eval-sanitize-1-r0-034-cgj4z.18d4a1ec75edbe6a,"reason=FailedScheduling count=None msg=0/6 nodes are available: 6 node(s) had untolerated taint(s). no new claims to deallocate, preemption: 0/6 nodes are available: 6 Preemption is not helpful for scheduling."
0.1439,Event,ADDED,eval-sanitize-1-r0-034-cgj4z.18d4a1ef45cefdec,reason=Scheduled count=None msg=Successfully assigned compute/eval-sanitize-1-r0-034-cgj4z to kind-worker
0.1442,Event,ADDED,eval-sanitize-1-r0-034-cgj4z.18d4a1ef604c705c,"reason=Pulled count=1 msg=Container image ""busybox:musl"" already present on machine"
0.1444,Event,ADDED,eval-sanitize-1-r0-034-cgj4z.18d4a1ef6317eabd,reason=Created count=1 msg=Created container: task
0.1446,Event,ADDED,eval-sanitize-1-r0-034-cgj4z.18d4a1ef672875f1,reason=Started count=1 msg=Started container task
0.1448,Event,ADDED,eval-sanitize-1-r0-034.18d4a1ec75e4330c,reason=SuccessfulCreate count=1 msg=Created pod: eval-sanitize-1-r0-034-cgj4z
0.1451,Event,ADDED,eval-sanitize-1-r0-034.18d4a1f4ac372e77,reason=Completed count=1 msg=Job completed
0.1452,Event,ADDED,eval-sanitize-1-r0-035-ztqvr.18d4a1ecad263f5e,"reason=FailedScheduling count=None msg=0/6 nodes are available: 6 node(s) had untolerated taint(s). no new claims to deallocate, preemption: 0/6 nodes are available: 6 Preemption is not helpful for scheduling."
0.1454,Event,ADDED,eval-sanitize-1-r0-035-ztqvr.18d4a1ef46ce4ada,"reason=FailedScheduling count=None msg=0/6 nodes are available: 1 c_wall violated: 3 conflicting context pair(s) with node memory, 5 node(s) had untolerated taint(s). no new claims to deallocate, preemption: 0/6 nodes are available: 1 No preemption victims found for incoming pod, 5 Preemption is not helpful for scheduling."
0.1458,Event,ADDED,eval-sanitize-1-r0-035-ztqvr.18d4a1ef59b12f81,"reason=FailedScheduling count=None msg=0/6 nodes are available: 1 c_wall violated: 3 conflicting context pair(s) with node memory, 5 node(s) had untolerated taint(s). no new claims to deallocate, preemption: 0/6 nodes are available: 1 No preemption victims found for incoming pod, 5 Preemption is not helpful for scheduling."
0.146,Event,ADDED,eval-sanitize-1-r0-035-ztqvr.18d4a1efc3b902d7,reason=Scheduled count=None msg=Successfully assigned compute/eval-sanitize-1-r0-035-ztqvr to kind-worker5
0.1461,Event,ADDED,eval-sanitize-1-r0-035-ztqvr.18d4a1efe22e7c15,"reason=Pulled count=1 msg=Container image ""busybox:musl"" already present on machine"
0.1464,Event,ADDED,eval-sanitize-1-r0-035-ztqvr.18d4a1efe4ea54f9,reason=Created count=1 msg=Created container: task
0.1466,Event,ADDED,eval-sanitize-1-r0-035-ztqvr.18d4a1efe972c3a3,reason=Started count=1 msg=Started container task
0.1468,Event,ADDED,eval-sanitize-1-r0-035.18d4a1ecad1894b9,reason=SuccessfulCreate count=1 msg=Created pod: eval-sanitize-1-r0-035-ztqvr
0.147,Event,ADDED,eval-sanitize-1-r0-035.18d4a1f5ee260334,reason=Completed count=1 msg=Job completed
0.1472,Event,ADDED,eval-sanitize-1-r0-036-m42xk.18d4a1ececd2c4d0,"reason=FailedScheduling count=None msg=0/6 nodes are available: 6 node(s) had untolerated taint(s). no new claims to deallocate, preemption: 0/6 nodes are available: 6 Preemption is not helpful for scheduling."
0.1473,Event,ADDED,eval-sanitize-1-r0-036-m42xk.18d4a1ef4757be2c,"reason=FailedScheduling count=None msg=0/6 nodes are available: 1 c_wall violated: 1 conflicting context pair(s) with node memory, 5 node(s) had untolerated taint(s). no new claims to deallocate, preemption: 0/6 nodes are available: 1 No preemption victims found for incoming pod, 5 Preemption is not helpful for scheduling."
0.1475,Event,ADDED,eval-sanitize-1-r0-036-m42xk.18d4a1ef59e7dce9,"reason=FailedScheduling count=None msg=0/6 nodes are available: 1 c_wall violated: 1 conflicting context pair(s) with node memory, 5 node(s) had untolerated taint(s). no new claims to deallocate, preemption: 0/6 nodes are available: 1 No preemption victims found for incoming pod, 5 Preemption is not helpful for scheduling."
0.1477,Event,ADDED,eval-sanitize-1-r0-036-m42xk.18d4a1efb64f66cd,reason=Scheduled count=None msg=Successfully assigned compute/eval-sanitize-1-r0-036-m42xk to kind-worker5
0.1479,Event,ADDED,eval-sanitize-1-r0-036-m42xk.18d4a1efd06cc0f7,"reason=Pulled count=1 msg=Container image ""busybox:musl"" already present on machine"
0.148,Event,ADDED,eval-sanitize-1-r0-036-m42xk.18d4a1efd212e046,reason=Created count=1 msg=Created container: task
0.1484,Event,ADDED,eval-sanitize-1-r0-036-m42xk.18d4a1efd70c96b3,reason=Started count=1 msg=Started container task
0.1486,Event,ADDED,eval-sanitize-1-r0-036.18d4a1ececc8fe24,reason=SuccessfulCreate count=1 msg=Created pod: eval-sanitize-1-r0-036-m42xk
0.1487,Event,ADDED,eval-sanitize-1-r0-036.18d4a1f5db9bc018,reason=Completed count=1 msg=Job completed
0.149,Event,ADDED,eval-sanitize-1-r0-037-tvl8d.18d4a1ed23b1153d,"reason=FailedScheduling count=None msg=0/6 nodes are available: 6 node(s) had untolerated taint(s). no new claims to deallocate, preemption: 0/6 nodes are available: 6 Preemption is not helpful for scheduling."
0.1493,Event,ADDED,eval-sanitize-1-r0-037-tvl8d.18d4a1ef47fab200,reason=Scheduled count=None msg=Successfully assigned compute/eval-sanitize-1-r0-037-tvl8d to kind-worker
0.1495,Event,ADDED,eval-sanitize-1-r0-037-tvl8d.18d4a1ef6154907f,"reason=Pulled count=1 msg=Container image ""busybox:musl"" already present on machine"
0.1497,Event,ADDED,eval-sanitize-1-r0-037-tvl8d.18d4a1ef6376149e,reason=Created count=1 msg=Created container: task
0.1498,Event,ADDED,eval-sanitize-1-r0-037-tvl8d.18d4a1ef672f5283,reason=Started count=1 msg=Started container task
0.1502,Event,ADDED,eval-sanitize-1-r0-037.18d4a1ed23a0833c,reason=SuccessfulCreate count=1 msg=Created pod: eval-sanitize-1-r0-037-tvl8d
0.1504,Event,ADDED,eval-sanitize-1-r0-037.18d4a1f4e8ab6c4a,reason=Completed count=1 msg=Job completed
0.1505,Event,ADDED,eval-sanitize-1-r0-038-zk8s4.18d4a1ed5ecc76fe,"reason=FailedScheduling count=None msg=0/6 nodes are available: 6 node(s) had untolerated taint(s). no new claims to deallocate, preemption: 0/6 nodes are available: 6 Preemption is not helpful for scheduling."
0.1508,Event,ADDED,eval-sanitize-1-r0-038-zk8s4.18d4a1ef47ee872c,"reason=FailedScheduling count=None msg=0/6 nodes are available: 1 c_wall violated: 3 conflicting context pair(s) with node memory, 5 node(s) had untolerated taint(s). no new claims to deallocate, preemption: 0/6 nodes are available: 1 No preemption victims found for incoming pod, 5 Preemption is not helpful for scheduling."
0.151,Event,ADDED,eval-sanitize-1-r0-038-zk8s4.18d4a1ef5a1c9978,"reason=FailedScheduling count=None msg=0/6 nodes are available: 1 c_wall violated: 3 conflicting context pair(s) with node memory, 5 node(s) had untolerated taint(s). no new claims to deallocate, preemption: 0/6 nodes are available: 1 No preemption victims found for incoming pod, 5 Preemption is not helpful for scheduling."
0.1512,Event,ADDED,eval-sanitize-1-r0-038-zk8s4.18d4a1efb6aa25eb,reason=Scheduled count=None msg=Successfully assigned compute/eval-sanitize-1-r0-038-zk8s4 to kind-worker5
0.1513,Event,ADDED,eval-sanitize-1-r0-038-zk8s4.18d4a1efd0e92a05,"reason=Pulled count=1 msg=Container image ""busybox:musl"" already present on machine"
0.1516,Event,ADDED,eval-sanitize-1-r0-038-zk8s4.18d4a1efd2f3b00b,reason=Created count=1 msg=Created container: task
0.1517,Event,ADDED,eval-sanitize-1-r0-038-zk8s4.18d4a1efd7e85184,reason=Started count=1 msg=Started container task
0.1519,Event,ADDED,eval-sanitize-1-r0-038.18d4a1ed5ec3cf00,reason=SuccessfulCreate count=1 msg=Created pod: eval-sanitize-1-r0-038-zk8s4
0.1521,Event,ADDED,eval-sanitize-1-r0-038.18d4a1f5c16df68f,reason=Completed count=1 msg=Job completed
0.1524,Event,ADDED,eval-sanitize-1-r0-039-tgxx5.18d4a1ed9aabf7a3,"reason=FailedScheduling count=None msg=0/6 nodes are available: 6 node(s) had untolerated taint(s). no new claims to deallocate, preemption: 0/6 nodes are available: 6 Preemption is not helpful for scheduling."
0.1525,Event,ADDED,eval-sanitize-1-r0-039-tgxx5.18d4a1ef4977a834,reason=Scheduled count=None msg=Successfully assigned compute/eval-sanitize-1-r0-039-tgxx5 to kind-worker
0.1527,Event,ADDED,eval-sanitize-1-r0-039-tgxx5.18d4a1ef660d8949,"reason=Pulled count=1 msg=Container image ""busybox:musl"" already present on machine"
0.153,Event,ADDED,eval-sanitize-1-r0-039-tgxx5.18d4a1ef684e6ca8,reason=Created count=1 msg=Created container: task
0.1532,Event,ADDED,eval-sanitize-1-r0-039-tgxx5.18d4a1ef6bfd36ca,reason=Started count=1 msg=Started container task
0.1533,Event,ADDED,eval-sanitize-1-r0-039.18d4a1ed9aa324f6,reason=SuccessfulCreate count=1 msg=Created pod: eval-sanitize-1-r0-039-tgxx5
0.1535,Event,ADDED,eval-sanitize-1-r0-039.18d4a1f4e8a99430,reason=Completed count=1 msg=Job completed
0.1538,Event,ADDED,eval-sanitize-1-r0-040-wvscn.18d4a1edd74aefbc,"reason=FailedScheduling count=None msg=0/6 nodes are available: 6 node(s) had untolerated taint(s). no new claims to deallocate, preemption: 0/6 nodes are available: 6 Preemption is not helpful for scheduling."
0.154,Event,ADDED,eval-sanitize-1-r0-040-wvscn.18d4a1ef497a9475,"reason=FailedScheduling count=None msg=0/6 nodes are available: 1 c_wall violated: 1 conflicting context pair(s) with node memory, 5 node(s) had untolerated taint(s). no new claims to deallocate, preemption: 0/6 nodes are available: 1 No preemption victims found for incoming pod, 5 Preemption is not helpful for scheduling."
0.1542,Event,ADDED,eval-sanitize-1-r0-040-wvscn.18d4a1ef5a4b72a4,"reason=FailedScheduling count=None msg=0/6 nodes are available: 1 c_wall violated: 1 conflicting context pair(s) with node memory, 5 node(s) had untolerated taint(s). no new claims to deallocate, preemption: 0/6 nodes are available: 1 No preemption victims found for incoming pod, 5 Preemption is not helpful for scheduling."
0.1545,Event,ADDED,eval-sanitize-1-r0-040-wvscn.18d4a1efb67153df,"reason=FailedScheduling count=None msg=0/6 nodes are available: 1 c_wall violated: 1 conflicting context pair(s) with node memory, 5 node(s) had untolerated taint(s). no new claims to deallocate, preemption: 0/6 nodes are available: 1 No preemption victims found for incoming pod, 5 Preemption is not helpful for scheduling."
0.155,Event,ADDED,eval-sanitize-1-r0-040-wvscn.18d4a1efc3e8b338,"reason=FailedScheduling count=None msg=0/6 nodes are available: 1 c_wall violated: 1 conflicting context pair(s) with node memory, 5 node(s) had untolerated taint(s). no new claims to deallocate, preemption: 0/6 nodes are available: 1 No preemption victims found for incoming pod, 5 Preemption is not helpful for scheduling."
0.1551,Event,ADDED,eval-sanitize-1-r0-040-wvscn.18d4a1f010f8762f,reason=Scheduled count=None msg=Successfully assigned compute/eval-sanitize-1-r0-040-wvscn to kind-worker3
0.1561,Event,ADDED,eval-sanitize-1-r0-040-wvscn.18d4a1f0432d1b1b,"reason=Pulled count=1 msg=Container image ""busybox:musl"" already present on machine"
0.1563,Event,ADDED,eval-sanitize-1-r0-040-wvscn.18d4a1f0458765c3,reason=Created count=1 msg=Created container: task
0.1565,Event,ADDED,eval-sanitize-1-r0-040-wvscn.18d4a1f049386ae6,reason=Started count=1 msg=Started container task
0.1566,Event,ADDED,eval-sanitize-1-r0-040.18d4a1edd740b7de,reason=SuccessfulCreate count=1 msg=Created pod: eval-sanitize-1-r0-040-wvscn
0.157,Event,ADDED,eval-sanitize-1-r0-040.18d4a1f6628ce996,reason=Completed count=1 msg=Job completed
0.1572,Event,ADDED,eval-sanitize-1-r0-041-wblcb.18d4a1ee11d8e3f5,"reason=FailedScheduling count=None msg=0/6 nodes are available: 6 node(s) had untolerated taint(s). no new claims to deallocate, preemption: 0/6 nodes are available: 6 Preemption is not helpful for scheduling."
0.1573,Event,ADDED,eval-sanitize-1-r0-041-wblcb.18d4a1ef4b60b49b,"reason=FailedScheduling count=None msg=0/6 nodes are available: 1 c_wall violated: 3 conflicting context pair(s) with node memory, 5 node(s) had untolerated taint(s). no new claims to deallocate, preemption: 0/6 nodes are available: 1 No preemption victims found for incoming pod, 5 Preemption is not helpful for scheduling."
0.1577,Event,ADDED,eval-sanitize-1-r0-041-wblcb.18d4a1ef5a83eb2e,"reason=FailedScheduling count=None msg=0/6 nodes are available: 1 c_wall violated: 3 conflicting context pair(s) with node memory, 5 node(s) had untolerated taint(s). no new claims to deallocate, preemption: 0/6 nodes are available: 1 No preemption victims found for incoming pod, 5 Preemption is not helpful for scheduling."
0.1579,Event,ADDED,eval-sanitize-1-r0-041-wblcb.18d4a1efb77d5c16,reason=Scheduled count=None msg=Successfully assigned compute/eval-sanitize-1-r0-041-wblcb to kind-worker5
0.1581,Event,ADDED,eval-sanitize-1-r0-041-wblcb.18d4a1efd16769b0,"reason=Pulled count=1 msg=Container image ""busybox:musl"" already present on machine"
0.1584,Event,ADDED,eval-sanitize-1-r0-041-wblcb.18d4a1efd32c13fe,reason=Created count=1 msg=Created container: task
0.1586,Event,ADDED,eval-sanitize-1-r0-041-wblcb.18d4a1efd7e92954,reason=Started count=1 msg=Started container task
0.1588,Event,ADDED,eval-sanitize-1-r0-041.18d4a1ee11c7f818,reason=SuccessfulCreate count=1 msg=Created pod: eval-sanitize-1-r0-041-wblcb
0.1589,Event,ADDED,eval-sanitize-1-r0-041.18d4a1f5eb46a1cf,reason=Completed count=1 msg=Job completed
0.1592,Event,ADDED,eval-sanitize-1-r0-042-8j6tf.18d4a1ee4d5f52b5,"reason=FailedScheduling count=None msg=0/6 nodes are available: 6 node(s) had untolerated taint(s). no new claims to deallocate, preemption: 0/6 nodes are available: 6 Preemption is not helpful for scheduling."
0.1593,Event,ADDED,eval-sanitize-1-r0-042-8j6tf.18d4a1ef518b7dc3,"reason=FailedScheduling count=None msg=0/6 nodes are available: 1 c_wall violated: 2 conflicting context pair(s) with node memory, 5 node(s) had untolerated taint(s). no new claims to deallocate, preemption: 0/6 nodes are available: 1 No preemption victims found for incoming pod, 5 Preemption is not helpful for scheduling."
0.1595,Event,ADDED,eval-sanitize-1-r0-042-8j6tf.18d4a1ef5eb6b07f,"reason=FailedScheduling count=None msg=0/6 nodes are available: 1 c_wall violated: 2 conflicting context pair(s) with node memory, 5 node(s) had untolerated taint(s). no new claims to deallocate, preemption: 0/6 nodes are available: 1 No preemption victims found for incoming pod, 5 Preemption is not helpful for scheduling."
0.1597,Event,ADDED,eval-sanitize-1-r0-042-8j6tf.18d4a1efb74dbc93,"reason=FailedScheduling count=None msg=0/6 nodes are available: 1 c_wall violated: 1 conflicting context pair(s) with node memory, 5 node(s) had untolerated taint(s). no new claims to deallocate, preemption: 0/6 nodes are available: 1 No preemption victims found for incoming pod, 5 Preemption is not helpful for scheduling."
0.1599,Event,ADDED,eval-sanitize-1-r0-042-8j6tf.18d4a1efc41a5164,"reason=FailedScheduling count=None msg=0/6 nodes are available: 1 c_wall violated: 1 conflicting context pair(s) with node memory, 5 node(s) had untolerated taint(s). no new claims to deallocate, preemption: 0/6 nodes are available: 1 No preemption victims found for incoming pod, 5 Preemption is not helpful for scheduling."
0.16,Event,ADDED,eval-sanitize-1-r0-042-8j6tf.18d4a1f010bdec70,"reason=FailedScheduling count=None msg=0/6 nodes are available: 1 c_wall violated: 1 conflicting context pair(s) with node memory, 5 node(s) had untolerated taint(s). no new claims to deallocate, preemption: 0/6 nodes are available: 1 No preemption victims found for incoming pod, 5 Preemption is not helpful for scheduling."
0.1602,Event,ADDED,eval-sanitize-1-r0-042-8j6tf.18d4a1f0163e26a2,"reason=FailedScheduling count=None msg=0/6 nodes are available: 1 c_wall violated: 1 conflicting context pair(s) with node memory, 5 node(s) had untolerated taint(s). no new claims to deallocate, preemption: 0/6 nodes are available: 1 No preemption victims found for incoming pod, 5 Preemption is not helpful for scheduling."
0.1603,Event,ADDED,eval-sanitize-1-r0-042-8j6tf.18d4a1f0699707e4,"reason=FailedScheduling count=None msg=0/6 nodes are available: 1 c_wall violated: 1 conflicting context pair(s) with node memory, 5 node(s) had untolerated taint(s). no new claims to deallocate, preemption: 0/6 nodes are available: 1 No preemption victims found for incoming pod, 5 Preemption is not helpful for scheduling."
0.1606,Event,ADDED,eval-sanitize-1-r0-042-8j6tf.18d4a1f06ac459f6,"reason=FailedScheduling count=None msg=0/6 nodes are available: 1 c_wall violated: 1 conflicting context pair(s) with node memory, 5 node(s) had untolerated taint(s). no new claims to deallocate, preemption: 0/6 nodes are available: 1 No preemption victims found for incoming pod, 5 Preemption is not helpful for scheduling."
0.1608,Event,ADDED,eval-sanitize-1-r0-042-8j6tf.18d4a1f0ec702748,reason=Scheduled count=None msg=Successfully assigned compute/eval-sanitize-1-r0-042-8j6tf to kind-worker2
0.161,Event,ADDED,eval-sanitize-1-r0-042-8j6tf.18d4a1f105f4c2ed,"reason=Pulled count=1 msg=Container image ""busybox:musl"" already present on machine"
0.1612,Event,ADDED,eval-sanitize-1-r0-042-8j6tf.18d4a1f10781aa4a,reason=Created count=1 msg=Created container: task
0.1614,Event,ADDED,eval-sanitize-1-r0-042-8j6tf.18d4a1f10979b0dc,reason=Started count=1 msg=Started container task
0.1616,Event,ADDED,eval-sanitize-1-r0-042.18d4a1ee4d55b8f7,reason=SuccessfulCreate count=1 msg=Created pod: eval-sanitize-1-r0-042-8j6tf
0.1617,Event,ADDED,eval-sanitize-1-r0-042.18d4a1f6b04a9b97,reason=Completed count=1 msg=Job completed
0.1619,Event,ADDED,eval-sanitize-1-r0-043-mzbz2.18d4a1ee8940a1be,"reason=FailedScheduling count=None msg=0/6 nodes are available: 6 node(s) had untolerated taint(s). no new claims to deallocate, preemption: 0/6 nodes are available: 6 Preemption is not helpful for scheduling."
0.1621,Event,ADDED,eval-sanitize-1-r0-043-mzbz2.18d4a1ef5342c266,"reason=FailedScheduling count=None msg=0/6 nodes are available: 1 c_wall violated: 2 conflicting context pair(s) with node memory, 5 node(s) had untolerated taint(s). no new claims to deallocate, preemption: 0/6 nodes are available: 1 No preemption victims found for incoming pod, 5 Preemption is not helpful for scheduling."
0.1622,Event,ADDED,eval-sanitize-1-r0-043-mzbz2.18d4a1ef5efefa2b,"reason=FailedScheduling count=None msg=0/6 nodes are available: 1 c_wall violated: 2 conflicting context pair(s) with node memory, 5 node(s) had untolerated taint(s). no new claims to deallocate, preemption: 0/6 nodes are available: 1 No preemption victims found for incoming pod, 5 Preemption is not helpful for scheduling."
0.1624,Event,ADDED,eval-sanitize-1-r0-043-mzbz2.18d4a1efb7d7f2fa,"reason=FailedScheduling count=None msg=0/6 nodes are available: 1 c_wall violated: 1 conflicting context pair(s) with node memory, 5 node(s) had untolerated taint(s). no new claims to deallocate, preemption: 0/6 nodes are available: 1 No preemption victims found for incoming pod, 5 Preemption is not helpful for scheduling."
0.1627,Event,ADDED,eval-sanitize-1-r0-043-mzbz2.18d4a1efc5133bb3,"reason=FailedScheduling count=None msg=0/6 nodes are available: 1 c_wall violated: 1 conflicting context pair(s) with node memory, 5 node(s) had untolerated taint(s). no new claims to deallocate, preemption: 0/6 nodes are available: 1 No preemption victims found for incoming pod, 5 Preemption is not helpful for scheduling."
0.1629,Event,ADDED,eval-sanitize-1-r0-043-mzbz2.18d4a1f011b2e9d7,"reason=FailedScheduling count=None msg=0/6 nodes are available: 1 c_wall violated: 1 conflicting context pair(s) with node memory, 5 node(s) had untolerated taint(s). no new claims to deallocate, preemption: 0/6 nodes are available: 1 No preemption victims found for incoming pod, 5 Preemption is not helpful for scheduling."
0.1631,Event,ADDED,eval-sanitize-1-r0-043-mzbz2.18d4a1f0166cd967,"reason=FailedScheduling count=None msg=0/6 nodes are available: 1 c_wall violated: 1 conflicting context pair(s) with node memory, 5 node(s) had untolerated taint(s). no new claims to deallocate, preemption: 0/6 nodes are available: 1 No preemption victims found for incoming pod, 5 Preemption is not helpful for scheduling."
0.1634,Event,ADDED,eval-sanitize-1-r0-043-mzbz2.18d4a1f06a1f0813,"reason=FailedScheduling count=None msg=0/6 nodes are available: 1 c_wall violated: 1 conflicting context pair(s) with node memory, 5 node(s) had untolerated taint(s). no new claims to deallocate, preemption: 0/6 nodes are available: 1 No preemption victims found for incoming pod, 5 Preemption is not helpful for scheduling."
0.1636,Event,ADDED,eval-sanitize-1-r0-043-mzbz2.18d4a1f06b07e4ea,"reason=FailedScheduling count=None msg=0/6 nodes are available: 1 c_wall violated: 1 conflicting context pair(s) with node memory, 5 node(s) had untolerated taint(s). no new claims to deallocate, preemption: 0/6 nodes are available: 1 No preemption victims found for incoming pod, 5 Preemption is not helpful for scheduling."
0.1638,Event,ADDED,eval-sanitize-1-r0-043-mzbz2.18d4a1f0ecd54ddc,reason=Scheduled count=None msg=Successfully assigned compute/eval-sanitize-1-r0-043-mzbz2 to kind-worker2
0.1641,Event,ADDED,eval-sanitize-1-r0-043-mzbz2.18d4a1f10655a8b2,"reason=Pulled count=1 msg=Container image ""busybox:musl"" already present on machine"
0.1643,Event,ADDED,eval-sanitize-1-r0-043-mzbz2.18d4a1f107f36f4b,reason=Created count=1 msg=Created container: task
0.1645,Event,ADDED,eval-sanitize-1-r0-043-mzbz2.18d4a1f10a172c8f,reason=Started count=1 msg=Started container task
0.1647,Event,ADDED,eval-sanitize-1-r0-043.18d4a1ee8936a2df,reason=SuccessfulCreate count=1 msg=Created pod: eval-sanitize-1-r0-043-mzbz2
0.1651,Event,ADDED,eval-sanitize-1-r0-043.18d4a1f6a7acb69a,reason=Completed count=1 msg=Job completed
0.1652,Event,ADDED,eval-sanitize-1-r0-044-lx7l4.18d4a1eec8b27704,"reason=FailedScheduling count=None msg=0/6 nodes are available: 6 node(s) had untolerated taint(s). no new claims to deallocate, preemption: 0/6 nodes are available: 6 Preemption is not helpful for scheduling."
0.1654,Event,ADDED,eval-sanitize-1-r0-044-lx7l4.18d4a1ef5451bc4a,reason=Scheduled count=None msg=Successfully assigned compute/eval-sanitize-1-r0-044-lx7l4 to kind-worker
0.1656,Event,ADDED,eval-sanitize-1-r0-044-lx7l4.18d4a1ef6d423e6e,"reason=Pulled count=1 msg=Container image ""busybox:musl"" already present on machine"
0.1659,Event,ADDED,eval-sanitize-1-r0-044-lx7l4.18d4a1ef6ef0078c,reason=Created count=1 msg=Created container: task
0.1661,Event,ADDED,eval-sanitize-1-r0-044-lx7l4.18d4a1ef7f8957ed,reason=Started count=1 msg=Started container task
0.1662,Event,ADDED,eval-sanitize-1-r0-044.18d4a1eec8a966fe,reason=SuccessfulCreate count=1 msg=Created pod: eval-sanitize-1-r0-044-lx7l4
0.1666,Event,ADDED,eval-sanitize-1-r0-044.18d4a1f4e8855179,reason=Completed count=1 msg=Job completed
0.167,Event,ADDED,eval-sanitize-1-r0-045-g45gd.18d4a1ef0009e018,"reason=FailedScheduling count=None msg=0/6 nodes are available: 6 node(s) had untolerated taint(s). no new claims to deallocate, preemption: 0/6 nodes are available: 6 Preemption is not helpful for scheduling."
0.1671,Event,ADDED,eval-sanitize-1-r0-045-g45gd.18d4a1ef5430faab,"reason=FailedScheduling count=None msg=0/6 nodes are available: 1 c_wall violated: 1 conflicting context pair(s) with node memory, 5 node(s) had untolerated taint(s). no new claims to deallocate, preemption: 0/6 nodes are available: 1 No preemption victims found for incoming pod, 5 Preemption is not helpful for scheduling."
0.1675,Event,ADDED,eval-sanitize-1-r0-045-g45gd.18d4a1ef5fd82eea,"reason=FailedScheduling count=None msg=0/6 nodes are available: 1 c_wall violated: 1 conflicting context pair(s) with node memory, 5 node(s) had untolerated taint(s). no new claims to deallocate, preemption: 0/6 nodes are available: 1 No preemption victims found for incoming pod, 5 Preemption is not helpful for scheduling."
0.1676,Event,ADDED,eval-sanitize-1-r0-045-g45gd.18d4a1efc26b09d7,reason=Scheduled count=None msg=Successfully assigned compute/eval-sanitize-1-r0-045-g45gd to kind-worker5
0.1678,Event,ADDED,eval-sanitize-1-r0-045-g45gd.18d4a1efe1f00364,"reason=Pulled count=1 msg=Container image ""busybox:musl"" already present on machine"
0.168,Event,ADDED,eval-sanitize-1-r0-045-g45gd.18d4a1efe4719da4,reason=Created count=1 msg=Created container: task
0.1682,Event,ADDED,eval-sanitize-1-r0-045-g45gd.18d4a1efe971ee0b,reason=Started count=1 msg=Started container task
0.1684,Event,ADDED,eval-sanitize-1-r0-045.18d4a1eefffd95cd,reason=SuccessfulCreate count=1 msg=Created pod: eval-sanitize-1-r0-045-g45gd
0.1685,Event,ADDED,eval-sanitize-1-r0-045.18d4a1f5d077b38b,reason=Completed count=1 msg=Job completed
0.1687,Event,ADDED,eval-sanitize-1-r0-046-sh7sk.18d4a1ef3ba271b9,"reason=FailedScheduling count=None msg=0/6 nodes are available: 6 node(s) had untolerated taint(s). no new claims to deallocate, preemption: 0/6 nodes are available: 6 Preemption is not helpful for scheduling."
0.1688,Event,ADDED,eval-sanitize-1-r0-046-sh7sk.18d4a1ef574c37ff,reason=Scheduled count=None msg=Successfully assigned compute/eval-sanitize-1-r0-046-sh7sk to kind-worker
0.169,Event,ADDED,eval-sanitize-1-r0-046-sh7sk.18d4a1ef6e8800ac,"reason=Pulled count=1 msg=Container image ""busybox:musl"" already present on machine"
0.1692,Event,ADDED,eval-sanitize-1-r0-046-sh7sk.18d4a1ef6ff6eb4c,reason=Created count=1 msg=Created container: task
0.1694,Event,ADDED,eval-sanitize-1-r0-046-sh7sk.18d4a1ef7f908c8d,reason=Started count=1 msg=Started container task
0.1695,Event,ADDED,eval-sanitize-1-r0-046.18d4a1ef3b988f8b,reason=SuccessfulCreate count=1 msg=Created pod: eval-sanitize-1-r0-046-sh7sk
0.1698,Event,ADDED,eval-sanitize-1-r0-046.18d4a1f4e8ad511c,reason=Completed count=1 msg=Job completed
0.17,Event,ADDED,eval-sanitize-1-r0-047-qj4c7.18d4a1efb36b6a4b,"reason=FailedScheduling count=None msg=0/6 nodes are available: 6 node(s) had untolerated taint(s). no new claims to deallocate, preemption: 0/6 nodes are available: 6 Preemption is not helpful for scheduling."
0.1702,Event,ADDED,eval-sanitize-1-r0-047-qj4c7.18d4a1efc43c573e,reason=Scheduled count=None msg=Successfully assigned compute/eval-sanitize-1-r0-047-qj4c7 to kind-worker5
0.1704,Event,ADDED,eval-sanitize-1-r0-047-qj4c7.18d4a1efe88a9a06,"reason=Pulled count=1 msg=Container image ""busybox:musl"" already present on machine"
0.1706,Event,ADDED,eval-sanitize-1-r0-047-qj4c7.18d4a1efe9eccf25,reason=Created count=1 msg=Created container: task
0.1708,Event,ADDED,eval-sanitize-1-r0-047-qj4c7.18d4a1efed8b205b,reason=Started count=1 msg=Started container task
0.171,Event,ADDED,eval-sanitize-1-r0-047.18d4a1efb365c5ab,reason=SuccessfulCreate count=1 msg=Created pod: eval-sanitize-1-r0-047-qj4c7
0.1714,Event,ADDED,eval-sanitize-1-r0-047.18d4a1f5c75f40bb,reason=Completed count=1 msg=Job completed
0.1716,Event,ADDED,eval-sanitize-1-r0-048-v6658.18d4a1efe5b6d362,"reason=FailedScheduling count=None msg=0/6 nodes are available: 1 c_wall violated: 1 conflicting context pair(s) with node memory, 5 node(s) had untolerated taint(s). no new claims to deallocate, preemption: 0/6 nodes are available: 1 No preemption victims found for incoming pod, 5 Preemption is not helpful for scheduling."
0.1718,Event,ADDED,eval-sanitize-1-r0-048-v6658.18d4a1efe630c432,"reason=FailedScheduling count=None msg=0/6 nodes are available: 1 c_wall violated: 1 conflicting context pair(s) with node memory, 5 node(s) had untolerated taint(s). no new claims to deallocate, preemption: 0/6 nodes are available: 1 No preemption victims found for incoming pod, 5 Preemption is not helpful for scheduling."
0.172,Event,ADDED,eval-sanitize-1-r0-048-v6658.18d4a1f0142261ec,"reason=FailedScheduling count=None msg=0/6 nodes are available: 1 c_wall violated: 2 conflicting context pair(s) with node memory, 5 node(s) had untolerated taint(s). no new claims to deallocate, preemption: 0/6 nodes are available: 1 No preemption victims found for incoming pod, 5 Preemption is not helpful for scheduling."
0.1722,Event,ADDED,eval-sanitize-1-r0-048-v6658.18d4a1f016a0af8c,"reason=FailedScheduling count=None msg=0/6 nodes are available: 1 c_wall violated: 2 conflicting context pair(s) with node memory, 5 node(s) had untolerated taint(s). no new claims to deallocate, preemption: 0/6 nodes are available: 1 No preemption victims found for incoming pod, 5 Preemption is not helpful for scheduling."
0.1723,Event,ADDED,eval-sanitize-1-r0-048-v6658.18d4a1f06976f95a,reason=Scheduled count=None msg=Successfully assigned compute/eval-sanitize-1-r0-048-v6658 to kind-worker4
0.1725,Event,ADDED,eval-sanitize-1-r0-048-v6658.18d4a1f0836d1e7b,"reason=Pulled count=1 msg=Container image ""busybox:musl"" already present on machine"
0.1727,Event,ADDED,eval-sanitize-1-r0-048-v6658.18d4a1f084bcc3f1,reason=Created count=1 msg=Created container: task
0.1728,Event,ADDED,eval-sanitize-1-r0-048-v6658.18d4a1f086e81a7f,reason=Started count=1 msg=Started container task
0.173,Event,ADDED,eval-sanitize-1-r0-048.18d4a1efe57a16ea,reason=SuccessfulCreate count=1 msg=Created pod: eval-sanitize-1-r0-048-v6658
0.1732,Event,ADDED,eval-sanitize-1-r0-048.18d4a1f68636f5b7,reason=Completed count=1 msg=Job completed
0.1733,Event,ADDED,eval-sanitize-1-r0-049-8c67j.18d4a1f0481e3849,"reason=FailedScheduling count=None msg=0/6 nodes are available: 1 c_wall violated: 1 conflicting context pair(s) with node memory, 5 node(s) had untolerated taint(s). no new claims to deallocate, preemption: 0/6 nodes are available: 1 No preemption victims found for incoming pod, 5 Preemption is not helpful for scheduling."
0.1735,Event,ADDED,eval-sanitize-1-r0-049-8c67j.18d4a1f048b899fd,"reason=FailedScheduling count=None msg=0/6 nodes are available: 1 c_wall violated: 1 conflicting context pair(s) with node memory, 5 node(s) had untolerated taint(s). no new claims to deallocate, preemption: 0/6 nodes are available: 1 No preemption victims found for incoming pod, 5 Preemption is not helpful for scheduling."
0.1737,Event,ADDED,eval-sanitize-1-r0-049-8c67j.18d4a1f069aee116,reason=Scheduled count=None msg=Successfully assigned compute/eval-sanitize-1-r0-049-8c67j to kind-worker4
0.1739,Event,ADDED,eval-sanitize-1-r0-049-8c67j.18d4a1f0838651a9,"reason=Pulled count=1 msg=Container image ""busybox:musl"" already present on machine"
0.174,Event,ADDED,eval-sanitize-1-r0-049-8c67j.18d4a1f0850f2dc3,reason=Created count=1 msg=Created container: task
0.1743,Event,ADDED,eval-sanitize-1-r0-049-8c67j.18d4a1f08736c3e7,reason=Started count=1 msg=Started container task
0.1745,Event,ADDED,eval-sanitize-1-r0-049.18d4a1f047e434d7,reason=SuccessfulCreate count=1 msg=Created pod: eval-sanitize-1-r0-049-8c67j
0.1747,Event,ADDED,eval-sanitize-1-r0-049.18d4a1f641da402f,reason=Completed count=1 msg=Job completed
0.175,Event,ADDED,eval-sanitize-1-r0-050-2wdl4.18d4a1f094fc9cf4,"reason=FailedScheduling count=None msg=0/6 nodes are available: 1 c_wall violated: 1 conflicting context pair(s) with node memory, 5 node(s) had untolerated taint(s). no new claims to deallocate, preemption: 0/6 nodes are available: 1 No preemption victims found for incoming pod, 5 Preemption is not helpful for scheduling."
0.1752,Event,ADDED,eval-sanitize-1-r0-050-2wdl4.18d4a1f0956c0ba2,"reason=FailedScheduling count=None msg=0/6 nodes are available: 1 c_wall violated: 1 conflicting context pair(s) with node memory, 5 node(s) had untolerated taint(s). no new claims to deallocate, preemption: 0/6 nodes are available: 1 No preemption victims found for incoming pod, 5 Preemption is not helpful for scheduling."
0.1755,Event,ADDED,eval-sanitize-1-r0-050-2wdl4.18d4a1f0ec997051,"reason=FailedScheduling count=None msg=0/6 nodes are available: 1 c_wall violated: 1 conflicting context pair(s) with node memory, 5 node(s) had untolerated taint(s). no new claims to deallocate, preemption: 0/6 nodes are available: 1 No preemption victims found for incoming pod, 5 Preemption is not helpful for scheduling."
0.1758,Event,ADDED,eval-sanitize-1-r0-050-2wdl4.18d4a1f0ee536f21,"reason=FailedScheduling count=None msg=0/6 nodes are available: 1 c_wall violated: 1 conflicting context pair(s) with node memory, 5 node(s) had untolerated taint(s). no new claims to deallocate, preemption: 0/6 nodes are available: 1 No preemption victims found for incoming pod, 5 Preemption is not helpful for scheduling."
0.176,Event,ADDED,eval-sanitize-1-r0-050-2wdl4.18d4a1f4d9f4dfeb,reason=Scheduled count=None msg=Successfully assigned compute/eval-sanitize-1-r0-050-2wdl4 to kind-worker
0.1761,Event,ADDED,eval-sanitize-1-r0-050-2wdl4.18d4a1f4f2a3ae46,"reason=Pulled count=1 msg=Container image ""busybox:musl"" already present on machine"
0.1764,Event,ADDED,eval-sanitize-1-r0-050-2wdl4.18d4a1f4f4e1bf47,reason=Created count=1 msg=Created container: task
0.1766,Event,ADDED,eval-sanitize-1-r0-050-2wdl4.18d4a1f4fb58cd89,reason=Started count=1 msg=Started container task
0.1768,Event,ADDED,eval-sanitize-1-r0-050.18d4a1f094c46bd2,reason=SuccessfulCreate count=1 msg=Created pod: eval-sanitize-1-r0-050-2wdl4
0.177,Event,ADDED,eval-sanitize-1-r0-050.18d4a1fa7f9f56f5,reason=Completed count=1 msg=Job completed
0.1773,Event,ADDED,eval-sanitize-1-r0-051-6r7z5.18d4a1f0b6d79afc,"reason=FailedScheduling count=None msg=0/6 nodes are available: 1 c_wall violated: 1 conflicting context pair(s) with node memory, 5 node(s) had untolerated taint(s). no new claims to deallocate, preemption: 0/6 nodes are available: 1 No preemption victims found for incoming pod, 5 Preemption is not helpful for scheduling."
0.1775,Event,ADDED,eval-sanitize-1-r0-051-6r7z5.18d4a1f0b753f83f,"reason=FailedScheduling count=None msg=0/6 nodes are available: 1 c_wall violated: 1 conflicting context pair(s) with node memory, 5 node(s) had untolerated taint(s). no new claims to deallocate, preemption: 0/6 nodes are available: 1 No preemption victims found for incoming pod, 5 Preemption is not helpful for scheduling."
0.1777,Event,ADDED,eval-sanitize-1-r0-051-6r7z5.18d4a1f0ed4125e5,"reason=FailedScheduling count=None msg=0/6 nodes are available: 1 c_wall violated: 1 conflicting context pair(s) with node memory, 5 node(s) had untolerated taint(s). no new claims to deallocate, preemption: 0/6 nodes are available: 1 No preemption victims found for incoming pod, 5 Preemption is not helpful for scheduling."
0.1781,Event,ADDED,eval-sanitize-1-r0-051-6r7z5.18d4a1f0f27fd9c3,"reason=FailedScheduling count=None msg=0/6 nodes are available: 1 c_wall violated: 1 conflicting context pair(s) with node memory, 5 node(s) had untolerated taint(s). no new claims to deallocate, preemption: 0/6 nodes are available: 1 No preemption victims found for incoming pod, 5 Preemption is not helpful for scheduling."
0.1783,Event,ADDED,eval-sanitize-1-r0-051-6r7z5.18d4a1f4d7f50ac1,"reason=FailedScheduling count=None msg=0/6 nodes are available: 1 c_wall violated: 1 conflicting context pair(s) with node memory, 5 node(s) had untolerated taint(s). no new claims to deallocate, preemption: 0/6 nodes are available: 1 No preemption victims found for incoming pod, 5 Preemption is not helpful for scheduling."
0.1785,Event,ADDED,eval-sanitize-1-r0-051-6r7z5.18d4a1f4f0628df0,"reason=FailedScheduling count=None msg=0/6 nodes are available: 1 c_wall violated: 1 conflicting context pair(s) with node memory, 5 node(s) had untolerated taint(s). no new claims to deallocate, preemption: 0/6 nodes are available: 1 No preemption victims found for incoming pod, 5 Preemption is not helpful for scheduling."
0.179,Event,ADDED,eval-sanitize-1-r0-051-6r7z5.18d4a1f54687d1c4,reason=Scheduled count=None msg=Successfully assigned compute/eval-sanitize-1-r0-051-6r7z5 to kind-worker5
0.1792,Event,ADDED,eval-sanitize-1-r0-051-6r7z5.18d4a1f56be5c214,"reason=Pulled count=1 msg=Container image ""busybox:musl"" already present on machine"
0.1794,Event,ADDED,eval-sanitize-1-r0-051-6r7z5.18d4a1f56ec80c03,reason=Created count=1 msg=Created container: task
0.1796,Event,ADDED,eval-sanitize-1-r0-051-6r7z5.18d4a1f5714df403,reason=Started count=1 msg=Started container task
0.1799,Event,ADDED,eval-sanitize-1-r0-051.18d4a1f0b6987d6f,reason=SuccessfulCreate count=1 msg=Created pod: eval-sanitize-1-r0-051-6r7z5
0.1801,Event,ADDED,eval-sanitize-1-r0-051.18d4a1fbb483bff3,reason=Completed count=1 msg=Job completed
0.1802,Event,ADDED,eval-sanitize-1-r0-052-br5gp.18d4a1f0dcee61f9,"reason=FailedScheduling count=None msg=0/6 nodes are available: 6 node(s) had untolerated taint(s). no new claims to deallocate, preemption: 0/6 nodes are available: 6 Preemption is not helpful for scheduling."
0.1804,Event,ADDED,eval-sanitize-1-r0-052-br5gp.18d4a1f0edde5693,"reason=FailedScheduling count=None msg=0/6 nodes are available: 1 c_wall violated: 1 conflicting context pair(s) with node memory, 5 node(s) had untolerated taint(s). no new claims to deallocate, preemption: 0/6 nodes are available: 1 No preemption victims found for incoming pod, 5 Preemption is not helpful for scheduling."
0.1806,Event,ADDED,eval-sanitize-1-r0-052-br5gp.18d4a1f0f2b57232,"reason=FailedScheduling count=None msg=0/6 nodes are available: 1 c_wall violated: 1 conflicting context pair(s) with node memory, 5 node(s) had untolerated taint(s). no new claims to deallocate, preemption: 0/6 nodes are available: 1 No preemption victims found for incoming pod, 5 Preemption is not helpful for scheduling."
0.1808,Event,ADDED,eval-sanitize-1-r0-052-br5gp.18d4a1f4d693c31e,reason=Scheduled count=None msg=Successfully assigned compute/eval-sanitize-1-r0-052-br5gp to kind-worker
0.181,Event,ADDED,eval-sanitize-1-r0-052-br5gp.18d4a1f4f158626f,"reason=Pulled count=1 msg=Container image ""busybox:musl"" already present on machine"
0.1811,Event,ADDED,eval-sanitize-1-r0-052-br5gp.18d4a1f4f3ac2e19,reason=Created count=1 msg=Created container: task
0.1813,Event,ADDED,eval-sanitize-1-r0-052-br5gp.18d4a1f4fb165215,reason=Started count=1 msg=Started container task
0.1815,Event,ADDED,eval-sanitize-1-r0-052.18d4a1f0dce63fb0,reason=SuccessfulCreate count=1 msg=Created pod: eval-sanitize-1-r0-052-br5gp
0.1817,Event,ADDED,eval-sanitize-1-r0-052.18d4a1fa7f9d4a2b,reason=Completed count=1 msg=Job completed
0.1818,Event,ADDED,eval-sanitize-1-r0-053-lqtg7.18d4a1f0fe9fa4b0,"reason=FailedScheduling count=None msg=0/6 nodes are available: 1 c_wall violated: 1 conflicting context pair(s) with node memory, 5 node(s) had untolerated taint(s). no new claims to deallocate, preemption: 0/6 nodes are available: 1 No preemption victims found for incoming pod, 5 Preemption is not helpful for scheduling."
0.182,Event,ADDED,eval-sanitize-1-r0-053-lqtg7.18d4a1f0ff30859b,"reason=FailedScheduling count=None msg=0/6 nodes are available: 1 c_wall violated: 1 conflicting context pair(s) with node memory, 5 node(s) had untolerated taint(s). no new claims to deallocate, preemption: 0/6 nodes are available: 1 No preemption victims found for incoming pod, 5 Preemption is not helpful for scheduling."
0.1823,Event,ADDED,eval-sanitize-1-r0-053-lqtg7.18d4a1f4d72f29ce,reason=Scheduled count=None msg=Successfully assigned compute/eval-sanitize-1-r0-053-lqtg7 to kind-worker
0.1825,Event,ADDED,eval-sanitize-1-r0-053-lqtg7.18d4a1f4f191b50d,"reason=Pulled count=1 msg=Container image ""busybox:musl"" already present on machine"
0.1826,Event,ADDED,eval-sanitize-1-r0-053-lqtg7.18d4a1f4f45c6818,reason=Created count=1 msg=Created container: task
0.1828,Event,ADDED,eval-sanitize-1-r0-053-lqtg7.18d4a1f4fb12d836,reason=Started count=1 msg=Started container task
0.1831,Event,ADDED,eval-sanitize-1-r0-053.18d4a1f0fe60f512,reason=SuccessfulCreate count=1 msg=Created pod: eval-sanitize-1-r0-053-lqtg7
0.1833,Event,ADDED,eval-sanitize-1-r0-053.18d4a1fa7f5de616,reason=Completed count=1 msg=Job completed
0.1834,Event,ADDED,eval-sanitize-1-r0-054-7pxw8.18d4a1f11bd32980,"reason=FailedScheduling count=None msg=0/6 nodes are available: 1 c_wall violated: 1 conflicting context pair(s) with node memory, 5 node(s) had untolerated taint(s). no new claims to deallocate, preemption: 0/6 nodes are available: 1 No preemption victims found for incoming pod, 5 Preemption is not helpful for scheduling."
0.1837,Event,ADDED,eval-sanitize-1-r0-054-7pxw8.18d4a1f11c3c516f,"reason=FailedScheduling count=None msg=0/6 nodes are available: 1 c_wall violated: 1 conflicting context pair(s) with node memory, 5 node(s) had untolerated taint(s). no new claims to deallocate, preemption: 0/6 nodes are available: 1 No preemption victims found for incoming pod, 5 Preemption is not helpful for scheduling."
0.1838,Event,ADDED,eval-sanitize-1-r0-054-7pxw8.18d4a1f4d71b1faa,"reason=FailedScheduling count=None msg=0/6 nodes are available: 1 c_wall violated: 1 conflicting context pair(s) with node memory, 5 node(s) had untolerated taint(s). no new claims to deallocate, preemption: 0/6 nodes are available: 1 No preemption victims found for incoming pod, 5 Preemption is not helpful for scheduling."
0.184,Event,ADDED,eval-sanitize-1-r0-054-7pxw8.18d4a1f4f03a908d,"reason=FailedScheduling count=None msg=0/6 nodes are available: 1 c_wall violated: 1 conflicting context pair(s) with node memory, 5 node(s) had untolerated taint(s). no new claims to deallocate, preemption: 0/6 nodes are available: 1 No preemption victims found for incoming pod, 5 Preemption is not helpful for scheduling."
0.1842,Event,ADDED,eval-sanitize-1-r0-054-7pxw8.18d4a1f546640c99,reason=Scheduled count=None msg=Successfully assigned compute/eval-sanitize-1-r0-054-7pxw8 to kind-worker5
0.1844,Event,ADDED,eval-sanitize-1-r0-054-7pxw8.18d4a1f56b7ba169,"reason=Pulled count=1 msg=Container image ""busybox:musl"" already present on machine"
0.1845,Event,ADDED,eval-sanitize-1-r0-054-7pxw8.18d4a1f56dcebe97,reason=Created count=1 msg=Created container: task
0.1847,Event,ADDED,eval-sanitize-1-r0-054-7pxw8.18d4a1f5700ce7db,reason=Started count=1 msg=Started container task
0.1849,Event,ADDED,eval-sanitize-1-r0-054.18d4a1f11b95e951,reason=SuccessfulCreate count=1 msg=Created pod: eval-sanitize-1-r0-054-7pxw8
0.185,Event,ADDED,eval-sanitize-1-r0-054.18d4a1fc11a2ecc7,reason=Completed count=1 msg=Job completed
0.1852,Event,ADDED,eval-sanitize-1-r0-055-s7f58.18d4a1f1565f2fc8,"reason=FailedScheduling count=None msg=0/6 nodes are available: 6 node(s) had untolerated taint(s). no new claims to deallocate, preemption: 0/6 nodes are available: 6 Preemption is not helpful for scheduling."
0.1853,Event,ADDED,eval-sanitize-1-r0-055-s7f58.18d4a1f4e1d7eaca,reason=Scheduled count=None msg=Successfully assigned compute/eval-sanitize-1-r0-055-s7f58 to kind-worker
0.1855,Event,ADDED,eval-sanitize-1-r0-055-s7f58.18d4a1f4f73c12a3,"reason=Pulled count=1 msg=Container image ""busybox:musl"" already present on machine"
0.1857,Event,ADDED,eval-sanitize-1-r0-055-s7f58.18d4a1f4f8c0ca55,reason=Created count=1 msg=Created container: task
0.1858,Event,ADDED,eval-sanitize-1-r0-055-s7f58.18d4a1f4fcbfbe89,reason=Started count=1 msg=Started container task
0.186,Event,ADDED,eval-sanitize-1-r0-055.18d4a1f15653d7ca,reason=SuccessfulCreate count=1 msg=Created pod: eval-sanitize-1-r0-055-s7f58
0.1862,Event,ADDED,eval-sanitize-1-r0-055.18d4a1fa7f99417c,reason=Completed count=1 msg=Job completed
0.1863,Event,ADDED,eval-sanitize-1-r0-056-mjw5f.18d4a1f18fd3cbe6,"reason=FailedScheduling count=None msg=0/6 nodes are available: 6 node(s) had untolerated taint(s). no new claims to deallocate, preemption: 0/6 nodes are available: 6 Preemption is not helpful for scheduling."
0.1865,Event,ADDED,eval-sanitize-1-r0-056-mjw5f.18d4a1f4e1d66c11,"reason=FailedScheduling count=None msg=0/6 nodes are available: 1 c_wall violated: 2 conflicting context pair(s) with node memory, 5 node(s) had untolerated taint(s). no new claims to deallocate, preemption: 0/6 nodes are available: 1 No preemption victims found for incoming pod, 5 Preemption is not helpful for scheduling."
0.1867,Event,ADDED,eval-sanitize-1-r0-056-mjw5f.18d4a1f4f097322b,"reason=FailedScheduling count=None msg=0/6 nodes are available: 1 c_wall violated: 2 conflicting context pair(s) with node memory, 5 node(s) had untolerated taint(s). no new claims to deallocate, preemption: 0/6 nodes are available: 1 No preemption victims found for incoming pod, 5 Preemption is not helpful for scheduling."
0.1868,Event,ADDED,eval-sanitize-1-r0-056-mjw5f.18d4a1f54676dd16,"reason=FailedScheduling count=None msg=0/6 nodes are available: 1 c_wall violated: 1 conflicting context pair(s) with node memory, 5 node(s) had untolerated taint(s). no new claims to deallocate, preemption: 0/6 nodes are available: 1 No preemption victims found for incoming pod, 5 Preemption is not helpful for scheduling."
0.187,Event,ADDED,eval-sanitize-1-r0-056-mjw5f.18d4a1f55483256b,"reason=FailedScheduling count=None msg=0/6 nodes are available: 1 c_wall violated: 1 conflicting context pair(s) with node memory, 5 node(s) had untolerated taint(s). no new claims to deallocate, preemption: 0/6 nodes are available: 1 No preemption victims found for incoming pod, 5 Preemption is not helpful for scheduling."
0.1874,Event,ADDED,eval-sanitize-1-r0-056-mjw5f.18d4a1f5a32c5b5e,"reason=FailedScheduling count=None msg=0/6 nodes are available: 1 c_wall violated: 1 conflicting context pair(s) with node memory, 5 node(s) had untolerated taint(s). no new claims to deallocate, preemption: 0/6 nodes are available: 1 No preemption victims found for incoming pod, 5 Preemption is not helpful for scheduling."
0.1878,Event,ADDED,eval-sanitize-1-r0-056-mjw5f.18d4a1f5a9ab6086,"reason=FailedScheduling count=None msg=0/6 nodes are available: 1 c_wall violated: 2 conflicting context pair(s) with node memory, 5 node(s) had untolerated taint(s). no new claims to deallocate, preemption: 0/6 nodes are available: 1 No preemption victims found for incoming pod, 5 Preemption is not helpful for scheduling."
0.188,Event,ADDED,eval-sanitize-1-r0-056-mjw5f.18d4a1f5af3277c2,"reason=FailedScheduling count=None msg=0/6 nodes are available: 1 c_wall violated: 2 conflicting context pair(s) with node memory, 5 node(s) had untolerated taint(s). no new claims to deallocate, preemption: 0/6 nodes are available: 1 No preemption victims found for incoming pod, 5 Preemption is not helpful for scheduling."
0.1882,Event,ADDED,eval-sanitize-1-r0-056-mjw5f.18d4a1f5ccc59036,"reason=FailedScheduling count=None msg=0/6 nodes are available: 1 c_wall violated: 1 conflicting context pair(s) with node memory, 1 c_wall violated: 2 conflicting context pair(s) with node memory, 4 node(s) had untolerated taint(s). no new claims to deallocate, preemption: 0/6 nodes are available: 2 No preemption victims found for incoming pod, 4 Preemption is not helpful for scheduling."
0.1888,Event,ADDED,eval-sanitize-1-r0-056-mjw5f.18d4a1f5f10f8c99,"reason=FailedScheduling count=None msg=0/6 nodes are available: 1 c_wall violated: 1 conflicting context pair(s) with node memory, 5 node(s) had untolerated taint(s). no new claims to deallocate, preemption: 0/6 nodes are available: 1 No preemption victims found for incoming pod, 5 Preemption is not helpful for scheduling."
0.1891,Event,ADDED,eval-sanitize-1-r0-056-mjw5f.18d4a1f673128e42,reason=Scheduled count=None msg=Successfully assigned compute/eval-sanitize-1-r0-056-mjw5f to kind-worker2
0.1893,Event,ADDED,eval-sanitize-1-r0-056-mjw5f.18d4a1f68d31ec7c,"reason=Pulled count=1 msg=Container image ""busybox:musl"" already present on machine"
0.1896,Event,ADDED,eval-sanitize-1-r0-056-mjw5f.18d4a1f69016227c,reason=Created count=1 msg=Created container: task
0.1898,Event,ADDED,eval-sanitize-1-r0-056-mjw5f.18d4a1f6942bde29,reason=Started count=1 msg=Started container task
0.19,Event,ADDED,eval-sanitize-1-r0-056.18d4a1f18fc28513,reason=SuccessfulCreate count=1 msg=Created pod: eval-sanitize-1-r0-056-mjw5f
0.1901,Event,ADDED,eval-sanitize-1-r0-056.18d4a1fc5b6fbf2a,reason=Completed count=1 msg=Job completed
0.1904,Event,ADDED,eval-sanitize-1-r0-057-b57zn.18d4a1f1cb447c11,"reason=FailedScheduling count=None msg=0/6 nodes are available: 6 node(s) had untolerated taint(s). no new claims to deallocate, preemption: 0/6 nodes are available: 6 Preemption is not helpful for scheduling."
0.1905,Event,ADDED,eval-sanitize-1-r0-057-b57zn.18d4a1f4e2631d3f,"reason=FailedScheduling count=None msg=0/6 nodes are available: 1 c_wall violated: 2 conflicting context pair(s) with node memory, 5 node(s) had untolerated taint(s). no new claims to deallocate, preemption: 0/6 nodes are available: 1 No preemption victims found for incoming pod, 5 Preemption is not helpful for scheduling."
0.1907,Event,ADDED,eval-sanitize-1-r0-057-b57zn.18d4a1f4f3aec8dc,"reason=FailedScheduling count=None msg=0/6 nodes are available: 1 c_wall violated: 2 conflicting context pair(s) with node memory, 5 node(s) had untolerated taint(s). no new claims to deallocate, preemption: 0/6 nodes are available: 1 No preemption victims found for incoming pod, 5 Preemption is not helpful for scheduling."
0.1909,Event,ADDED,eval-sanitize-1-r0-057-b57zn.18d4a1f54729a46b,"reason=FailedScheduling count=None msg=0/6 nodes are available: 1 c_wall violated: 1 conflicting context pair(s) with node memory, 5 node(s) had untolerated taint(s). no new claims to deallocate, preemption: 0/6 nodes are available: 1 No preemption victims found for incoming pod, 5 Preemption is not helpful for scheduling."
0.191,Event,ADDED,eval-sanitize-1-r0-057-b57zn.18d4a1f554b35a3b,"reason=FailedScheduling count=None msg=0/6 nodes are available: 1 c_wall violated: 2 conflicting context pair(s) with node memory, 5 node(s) had untolerated taint(s). no new claims to deallocate, preemption: 0/6 nodes are available: 1 No preemption victims found for incoming pod, 5 Preemption is not helpful for scheduling."
0.1912,Event,ADDED,eval-sanitize-1-r0-057-b57zn.18d4a1f55ba27d5d,"reason=FailedScheduling count=None msg=0/6 nodes are available: 1 c_wall violated: 2 conflicting context pair(s) with node memory, 5 node(s) had untolerated taint(s). no new claims to deallocate, preemption: 0/6 nodes are available: 1 No preemption victims found for incoming pod, 5 Preemption is not helpful for scheduling."
0.1914,Event,ADDED,eval-sanitize-1-r0-057-b57zn.18d4a1f5a3f26748,reason=Scheduled count=None msg=Successfully assigned compute/eval-sanitize-1-r0-057-b57zn to kind-worker4
0.1915,Event,ADDED,eval-sanitize-1-r0-057-b57zn.18d4a1f5bf4a9017,"reason=Pulled count=1 msg=Container image ""busybox:musl"" already present on machine"
0.1917,Event,ADDED,eval-sanitize-1-r0-057-b57zn.18d4a1f5c0af197b,reason=Created count=1 msg=Created container: task
0.1919,Event,ADDED,eval-sanitize-1-r0-057-b57zn.18d4a1f5c505a267,reason=Started count=1 msg=Started container task
0.1922,Event,ADDED,eval-sanitize-1-r0-057.18d4a1f1cb390ab0,reason=SuccessfulCreate count=1 msg=Created pod: eval-sanitize-1-r0-057-b57zn
0.1925,Event,ADDED,eval-sanitize-1-r0-057.18d4a1fc230d626f,reason=Completed count=1 msg=Job completed
0.1927,Event,ADDED,eval-sanitize-1-r0-058-xpgtw.18d4a1f206ed06fa,"reason=FailedScheduling count=None msg=0/6 nodes are available: 6 node(s) had untolerated taint(s). no new claims to deallocate, preemption: 0/6 nodes are available: 6 Preemption is not helpful for scheduling."
0.193,Event,ADDED,eval-sanitize-1-r0-058-xpgtw.18d4a1f4e3247afa,reason=Scheduled count=None msg=Successfully assigned compute/eval-sanitize-1-r0-058-xpgtw to kind-worker
0.1932,Event,ADDED,eval-sanitize-1-r0-058-xpgtw.18d4a1f4fd601230,"reason=Pulled count=1 msg=Container image ""busybox:musl"" already present on machine"
0.1935,Event,ADDED,eval-sanitize-1-r0-058-xpgtw.18d4a1f4ff063093,reason=Created count=1 msg=Created container: task
0.1937,Event,ADDED,eval-sanitize-1-r0-058-xpgtw.18d4a1f5047dc827,reason=Started count=1 msg=Started container task
0.194,Event,ADDED,eval-sanitize-1-r0-058.18d4a1f206e15fc1,reason=SuccessfulCreate count=1 msg=Created pod: eval-sanitize-1-r0-058-xpgtw
0.1942,Event,ADDED,eval-sanitize-1-r0-058.18d4a1fa806dff28,reason=Completed count=1 msg=Job completed
0.1943,Event,ADDED,eval-sanitize-1-r0-059-fn7qr.18d4a1f242f7f629,"reason=FailedScheduling count=None msg=0/6 nodes are available: 6 node(s) had untolerated taint(s). no new claims to deallocate, preemption: 0/6 nodes are available: 6 Preemption is not helpful for scheduling."
0.1946,Event,ADDED,eval-sanitize-1-r0-059-fn7qr.18d4a1f4e30451cc,"reason=FailedScheduling count=None msg=0/6 nodes are available: 1 c_wall violated: 1 conflicting context pair(s) with node memory, 5 node(s) had untolerated taint(s). no new claims to deallocate, preemption: 0/6 nodes are available: 1 No preemption victims found for incoming pod, 5 Preemption is not helpful for scheduling."
0.1948,Event,ADDED,eval-sanitize-1-r0-059-fn7qr.18d4a1f4f5173214,"reason=FailedScheduling count=None msg=0/6 nodes are available: 1 c_wall violated: 1 conflicting context pair(s) with node memory, 5 node(s) had untolerated taint(s). no new claims to deallocate, preemption: 0/6 nodes are available: 1 No preemption victims found for incoming pod, 5 Preemption is not helpful for scheduling."
0.1949,Event,ADDED,eval-sanitize-1-r0-059-fn7qr.18d4a1f549e34c23,reason=Scheduled count=None msg=Successfully assigned compute/eval-sanitize-1-r0-059-fn7qr to kind-worker5
0.1951,Event,ADDED,eval-sanitize-1-r0-059-fn7qr.18d4a1f56a476434,"reason=Pulled count=1 msg=Container image ""busybox:musl"" already present on machine"
0.1954,Event,ADDED,eval-sanitize-1-r0-059-fn7qr.18d4a1f56c3f8a3d,reason=Created count=1 msg=Created container: task
0.1955,Event,ADDED,eval-sanitize-1-r0-059-fn7qr.18d4a1f56e694e26,reason=Started count=1 msg=Started container task
0.1957,Event,ADDED,eval-sanitize-1-r0-059.18d4a1f242e55641,reason=SuccessfulCreate count=1 msg=Created pod: eval-sanitize-1-r0-059-fn7qr
0.1959,Event,ADDED,eval-sanitize-1-r0-059.18d4a1fbf2f32593,reason=Completed count=1 msg=Job completed
0.196,Event,ADDED,eval-sanitize-1-r0-060-wjq6s.18d4a1f2841043e3,"reason=FailedScheduling count=None msg=0/6 nodes are available: 6 node(s) had untolerated taint(s). no new claims to deallocate, preemption: 0/6 nodes are available: 6 Preemption is not helpful for scheduling."
0.1962,Event,ADDED,eval-sanitize-1-r0-060-wjq6s.18d4a1f4e38da53b,"reason=FailedScheduling count=None msg=0/6 nodes are available: 1 c_wall violated: 2 conflicting context pair(s) with node memory, 5 node(s) had untolerated taint(s). no new claims to deallocate, preemption: 0/6 nodes are available: 1 No preemption victims found for incoming pod, 5 Preemption is not helpful for scheduling."
0.1964,Event,ADDED,eval-sanitize-1-r0-060-wjq6s.18d4a1f4f5667260,"reason=FailedScheduling count=None msg=0/6 nodes are available: 1 c_wall violated: 2 conflicting context pair(s) with node memory, 5 node(s) had untolerated taint(s). no new claims to deallocate, preemption: 0/6 nodes are available: 1 No preemption victims found for incoming pod, 5 Preemption is not helpful for scheduling."
0.1965,Event,ADDED,eval-sanitize-1-r0-060-wjq6s.18d4a1f549c6b9c4,"reason=FailedScheduling count=None msg=0/6 nodes are available: 1 c_wall violated: 1 conflicting context pair(s) with node memory, 5 node(s) had untolerated taint(s). no new claims to deallocate, preemption: 0/6 nodes are available: 1 No preemption victims found for incoming pod, 5 Preemption is not helpful for scheduling."
0.1967,Event,ADDED,eval-sanitize-1-r0-060-wjq6s.18d4a1f5560214d4,"reason=FailedScheduling count=None msg=0/6 nodes are available: 1 c_wall violated: 1 conflicting context pair(s) with node memory, 5 node(s) had untolerated taint(s). no new claims to deallocate, preemption: 0/6 nodes are available: 1 No preemption victims found for incoming pod, 5 Preemption is not helpful for scheduling."
0.1969,Event,ADDED,eval-sanitize-1-r0-060-wjq6s.18d4a1f5a3d7f15e,"reason=FailedScheduling count=None msg=0/6 nodes are available: 1 c_wall violated: 2 conflicting context pair(s) with node memory, 5 node(s) had untolerated taint(s). no new claims to deallocate, preemption: 0/6 nodes are available: 1 No preemption victims found for incoming pod, 5 Preemption is not helpful for scheduling."
0.1971,Event,ADDED,eval-sanitize-1-r0-060-wjq6s.18d4a1f5aa2e8ed0,"reason=FailedScheduling count=None msg=0/6 nodes are available: 1 c_wall violated: 2 conflicting context pair(s) with node memory, 5 node(s) had untolerated taint(s). no new claims to deallocate, preemption: 0/6 nodes are available: 1 No preemption victims found for incoming pod, 5 Preemption is not helpful for scheduling."
0.1973,Event,ADDED,eval-sanitize-1-r0-060-wjq6s.18d4a1f5cd22bba5,"reason=FailedScheduling count=None msg=0/6 nodes are available: 1 c_wall violated: 1 conflicting context pair(s) with node memory, 1 c_wall violated: 2 conflicting context pair(s) with node memory, 4 node(s) had untolerated taint(s). no new claims to deallocate, preemption: 0/6 nodes are available: 2 No preemption victims found for incoming pod, 4 Preemption is not helpful for scheduling."
0.1977,Event,ADDED,eval-sanitize-1-r0-060-wjq6s.18d4a1f5f1501808,"reason=FailedScheduling count=None msg=0/6 nodes are available: 1 c_wall violated: 1 conflicting context pair(s) with node memory, 5 node(s) had untolerated taint(s). no new claims to deallocate, preemption: 0/6 nodes are available: 1 No preemption victims found for incoming pod, 5 Preemption is not helpful for scheduling."
0.1978,Event,ADDED,eval-sanitize-1-r0-060-wjq6s.18d4a1f67167e813,reason=Scheduled count=None msg=Successfully assigned compute/eval-sanitize-1-r0-060-wjq6s to kind-worker2
0.198,Event,ADDED,eval-sanitize-1-r0-060-wjq6s.18d4a1f68c4a148a,"reason=Pulled count=1 msg=Container image ""busybox:musl"" already present on machine"
0.1982,Event,ADDED,eval-sanitize-1-r0-060-wjq6s.18d4a1f68e454b73,reason=Created count=1 msg=Created container: task
0.1985,Event,ADDED,eval-sanitize-1-r0-060-wjq6s.18d4a1f6942b705c,reason=Started count=1 msg=Started container task
0.1988,Event,ADDED,eval-sanitize-1-r0-060.18d4a1f28406676c,reason=SuccessfulCreate count=1 msg=Created pod: eval-sanitize-1-r0-060-wjq6s
0.199,Event,ADDED,eval-sanitize-1-r0-060.18d4a1fc4c677f8b,reason=Completed count=1 msg=Job completed
0.1993,Event,ADDED,eval-sanitize-1-r0-061-jvv6k.18d4a1f2f92076b5,"reason=FailedScheduling count=None msg=0/6 nodes are available: 6 node(s) had untolerated taint(s). no new claims to deallocate, preemption: 0/6 nodes are available: 6 Preemption is not helpful for scheduling."
0.1994,Event,ADDED,eval-sanitize-1-r0-061-jvv6k.18d4a1f4e801cfca,"reason=FailedScheduling count=None msg=0/6 nodes are available: 1 c_wall violated: 2 conflicting context pair(s) with node memory, 5 node(s) had untolerated taint(s). no new claims to deallocate, preemption: 0/6 nodes are available: 1 No preemption victims found for incoming pod, 5 Preemption is not helpful for scheduling."
0.1997,Event,ADDED,eval-sanitize-1-r0-061-jvv6k.18d4a1f4f6559069,"reason=FailedScheduling count=None msg=0/6 nodes are available: 1 c_wall violated: 2 conflicting context pair(s) with node memory, 5 node(s) had untolerated taint(s). no new claims to deallocate, preemption: 0/6 nodes are available: 1 No preemption victims found for incoming pod, 5 Preemption is not helpful for scheduling."
0.1999,Event,ADDED,eval-sanitize-1-r0-061-jvv6k.18d4a1f54b83b3a6,reason=Scheduled count=None msg=Successfully assigned compute/eval-sanitize-1-r0-061-jvv6k to kind-worker5
0.2004,Event,ADDED,eval-sanitize-1-r0-061-jvv6k.18d4a1f56bb82d9a,"reason=Pulled count=1 msg=Container image ""busybox:musl"" already present on machine"
0.2006,Event,ADDED,eval-sanitize-1-r0-061-jvv6k.18d4a1f56e8f3172,reason=Created count=1 msg=Created container: task
0.2008,Event,ADDED,eval-sanitize-1-r0-061-jvv6k.18d4a1f570f5c49a,reason=Started count=1 msg=Started container task
0.2011,Event,ADDED,eval-sanitize-1-r0-061.18d4a1f2f9128313,reason=SuccessfulCreate count=1 msg=Created pod: eval-sanitize-1-r0-061-jvv6k
0.2013,Event,ADDED,eval-sanitize-1-r0-061.18d4a1fc04d1bba1,reason=Completed count=1 msg=Job completed
0.2015,Event,ADDED,eval-sanitize-1-r0-062-rbcw4.18d4a1f2fa82e502,"reason=FailedScheduling count=None msg=0/6 nodes are available: 6 node(s) had untolerated taint(s). no new claims to deallocate, preemption: 0/6 nodes are available: 6 Preemption is not helpful for scheduling."
0.2016,Event,ADDED,eval-sanitize-1-r0-062-rbcw4.18d4a1f4e89b4497,"reason=FailedScheduling count=None msg=0/6 nodes are available: 1 c_wall violated: 3 conflicting context pair(s) with node memory, 5 node(s) had untolerated taint(s). no new claims to deallocate, preemption: 0/6 nodes are available: 1 No preemption victims found for incoming pod, 5 Preemption is not helpful for scheduling."
0.2019,Event,ADDED,eval-sanitize-1-r0-062-rbcw4.18d4a1f4f693ee29,"reason=FailedScheduling count=None msg=0/6 nodes are available: 1 c_wall violated: 3 conflicting context pair(s) with node memory, 5 node(s) had untolerated taint(s). no new claims to deallocate, preemption: 0/6 nodes are available: 1 No preemption victims found for incoming pod, 5 Preemption is not helpful for scheduling."
0.202,Event,ADDED,eval-sanitize-1-r0-062-rbcw4.18d4a1f54b717c92,"reason=FailedScheduling count=None msg=0/6 nodes are available: 1 c_wall violated: 1 conflicting context pair(s) with node memory, 5 node(s) had untolerated taint(s). no new claims to deallocate, preemption: 0/6 nodes are available: 1 No preemption victims found for incoming pod, 5 Preemption is not helpful for scheduling."
0.2025,Event,ADDED,eval-sanitize-1-r0-062-rbcw4.18d4a1f5563e6096,"reason=FailedScheduling count=None msg=0/6 nodes are available: 1 c_wall violated: 1 conflicting context pair(s) with node memory, 5 node(s) had untolerated taint(s). no new claims to deallocate, preemption: 0/6 nodes are available: 1 No preemption victims found for incoming pod, 5 Preemption is not helpful for scheduling."
0.2027,Event,ADDED,eval-sanitize-1-r0-062-rbcw4.18d4a1f5a156c180,reason=Scheduled count=None msg=Successfully assigned compute/eval-sanitize-1-r0-062-rbcw4 to kind-worker4
0.2028,Event,ADDED,eval-sanitize-1-r0-062-rbcw4.18d4a1f5bee581ab,"reason=Pulled count=1 msg=Container image ""busybox:musl"" already present on machine"
0.203,Event,ADDED,eval-sanitize-1-r0-062-rbcw4.18d4a1f5c083f0eb,reason=Created count=1 msg=Created container: task
0.2032,Event,ADDED,eval-sanitize-1-r0-062-rbcw4.18d4a1f5c506fcb7,reason=Started count=1 msg=Started container task
0.2033,Event,ADDED,eval-sanitize-1-r0-062.18d4a1f2fa795859,reason=SuccessfulCreate count=1 msg=Created pod: eval-sanitize-1-r0-062-rbcw4
0.2035,Event,ADDED,eval-sanitize-1-r0-062.18d4a1fc3d763cb6,reason=Completed count=1 msg=Job completed
0.2036,Event,ADDED,eval-sanitize-1-r0-063-ttkvl.18d4a1f332125631,"reason=FailedScheduling count=None msg=0/6 nodes are available: 6 node(s) had untolerated taint(s). no new claims to deallocate, preemption: 0/6 nodes are available: 6 Preemption is not helpful for scheduling."
0.2038,Event,ADDED,eval-sanitize-1-r0-063-ttkvl.18d4a1f4e948dab3,"reason=FailedScheduling count=None msg=0/6 nodes are available: 1 c_wall violated: 1 conflicting context pair(s) with node memory, 5 node(s) had untolerated taint(s). no new claims to deallocate, preemption: 0/6 nodes are available: 1 No preemption victims found for incoming pod, 5 Preemption is not helpful for scheduling."
0.204,Event,ADDED,eval-sanitize-1-r0-063-ttkvl.18d4a1f4f6fc9ef9,"reason=FailedScheduling count=None msg=0/6 nodes are available: 1 c_wall violated: 1 conflicting context pair(s) with node memory, 5 node(s) had untolerated taint(s). no new claims to deallocate, preemption: 0/6 nodes are available: 1 No preemption victims found for incoming pod, 5 Preemption is not helpful for scheduling."
0.2041,Event,ADDED,eval-sanitize-1-r0-063-ttkvl.18d4a1f54d5fc943,reason=Scheduled count=None msg=Successfully assigned compute/eval-sanitize-1-r0-063-ttkvl to kind-worker5
0.2043,Event,ADDED,eval-sanitize-1-r0-063-ttkvl.18d4a1f582dda6f6,"reason=Pulled count=1 msg=Container image ""busybox:musl"" already present on machine"
0.2045,Event,ADDED,eval-sanitize-1-r0-063-ttkvl.18d4a1f5843385cf,reason=Created count=1 msg=Created container: task
0.2046,Event,ADDED,eval-sanitize-1-r0-063-ttkvl.18d4a1f58d285231,reason=Started count=1 msg=Started container task
0.2048,Event,ADDED,eval-sanitize-1-r0-063.18d4a1f3320685cd,reason=SuccessfulCreate count=1 msg=Created pod: eval-sanitize-1-r0-063-ttkvl
0.205,Event,ADDED,eval-sanitize-1-r0-063.18d4a1fbb231ac64,reason=Completed count=1 msg=Job completed
0.2051,Event,ADDED,eval-sanitize-1-r0-064-5rcs7.18d4a1f36d3af536,"reason=FailedScheduling count=None msg=0/6 nodes are available: 6 node(s) had untolerated taint(s). no new claims to deallocate, preemption: 0/6 nodes are available: 6 Preemption is not helpful for scheduling."
0.2053,Event,ADDED,eval-sanitize-1-r0-064-5rcs7.18d4a1f4ea534f10,reason=Scheduled count=None msg=Successfully assigned compute/eval-sanitize-1-r0-064-5rcs7 to kind-worker
0.2056,Event,ADDED,eval-sanitize-1-r0-064-5rcs7.18d4a1f505d353f0,"reason=Pulled count=1 msg=Container image ""busybox:musl"" already present on machine"
0.2057,Event,ADDED,eval-sanitize-1-r0-064-5rcs7.18d4a1f50776f455,reason=Created count=1 msg=Created container: task
0.2059,Event,ADDED,eval-sanitize-1-r0-064-5rcs7.18d4a1f50a13d602,reason=Started count=1 msg=Started container task
0.2061,Event,ADDED,eval-sanitize-1-r0-064.18d4a1f36d1f701f,reason=SuccessfulCreate count=1 msg=Created pod: eval-sanitize-1-r0-064-5rcs7
0.2066,Event,ADDED,eval-sanitize-1-r0-064.18d4a1fa43399b38,reason=Completed count=1 msg=Job completed
0.2068,Event,ADDED,eval-sanitize-1-r0-065-2n9qq.18d4a1f3a92be87a,"reason=FailedScheduling count=None msg=0/6 nodes are available: 6 node(s) had untolerated taint(s). no new claims to deallocate, preemption: 0/6 nodes are available: 6 Preemption is not helpful for scheduling."
0.207,Event,ADDED,eval-sanitize-1-r0-065-2n9qq.18d4a1f4ea888811,reason=Scheduled count=None msg=Successfully assigned compute/eval-sanitize-1-r0-065-2n9qq to kind-worker
0.2077,Event,ADDED,eval-sanitize-1-r0-065-2n9qq.18d4a1f505f07aa4,"reason=Pulled count=1 msg=Container image ""busybox:musl"" already present on machine"
0.2081,Event,ADDED,eval-sanitize-1-r0-065-2n9qq.18d4a1f507c684c4,reason=Created count=1 msg=Created container: task
0.2083,Event,ADDED,eval-sanitize-1-r0-065-2n9qq.18d4a1f50a158dcd,reason=Started count=1 msg=Started container task
0.2084,Event,ADDED,eval-sanitize-1-r0-065.18d4a1f3a920847d,reason=SuccessfulCreate count=1 msg=Created pod: eval-sanitize-1-r0-065-2n9qq
0.209,Event,ADDED,eval-sanitize-1-r0-065.18d4a1fa80aa425a,reason=Completed count=1 msg=Job completed
0.2091,Event,ADDED,eval-sanitize-1-r0-066-fvhwf.18d4a1f3e5844d83,"reason=FailedScheduling count=None msg=0/6 nodes are available: 6 node(s) had untolerated taint(s). no new claims to deallocate, preemption: 0/6 nodes are available: 6 Preemption is not helpful for scheduling."
0.2093,Event,ADDED,eval-sanitize-1-r0-066-fvhwf.18d4a1f4ea64a312,"reason=FailedScheduling count=None msg=0/6 nodes are available: 1 c_wall violated: 2 conflicting context pair(s) with node memory, 5 node(s) had untolerated taint(s). no new claims to deallocate, preemption: 0/6 nodes are available: 1 No preemption victims found for incoming pod, 5 Preemption is not helpful for scheduling."
0.2097,Event,ADDED,eval-sanitize-1-r0-066-fvhwf.18d4a1f4fb5663c1,"reason=FailedScheduling count=None msg=0/6 nodes are available: 1 c_wall violated: 2 conflicting context pair(s) with node memory, 5 node(s) had untolerated taint(s). no new claims to deallocate, preemption: 0/6 nodes are available: 1 No preemption victims found for incoming pod, 5 Preemption is not helpful for scheduling."
0.2099,Event,ADDED,eval-sanitize-1-r0-066-fvhwf.18d4a1f54f97e54c,"reason=FailedScheduling count=None msg=0/6 nodes are available: 1 c_wall violated: 1 conflicting context pair(s) with node memory, 5 node(s) had untolerated taint(s). no new claims to deallocate, preemption: 0/6 nodes are available: 1 No preemption victims found for incoming pod, 5 Preemption is not helpful for scheduling."
0.2101,Event,ADDED,eval-sanitize-1-r0-066-fvhwf.18d4a1f556b2f382,"reason=FailedScheduling count=None msg=0/6 nodes are available: 1 c_wall violated: 1 conflicting context pair(s) with node memory, 5 node(s) had untolerated taint(s). no new claims to deallocate, preemption: 0/6 nodes are available: 1 No preemption victims found for incoming pod, 5 Preemption is not helpful for scheduling."
0.2104,Event,ADDED,eval-sanitize-1-r0-066-fvhwf.18d4a1f5a2111c67,"reason=FailedScheduling count=None msg=0/6 nodes are available: 1 c_wall violated: 1 conflicting context pair(s) with node memory, 5 node(s) had untolerated taint(s). no new claims to deallocate, preemption: 0/6 nodes are available: 1 No preemption victims found for incoming pod, 5 Preemption is not helpful for scheduling."
0.2106,Event,ADDED,eval-sanitize-1-r0-066-fvhwf.18d4a1f5a8e3f7eb,"reason=FailedScheduling count=None msg=0/6 nodes are available: 1 c_wall violated: 2 conflicting context pair(s) with node memory, 5 node(s) had untolerated taint(s). no new claims to deallocate, preemption: 0/6 nodes are available: 1 No preemption victims found for incoming pod, 5 Preemption is not helpful for scheduling."
0.2108,Event,ADDED,eval-sanitize-1-r0-066-fvhwf.18d4a1f5ae318c47,"reason=FailedScheduling count=None msg=0/6 nodes are available: 1 c_wall violated: 2 conflicting context pair(s) with node memory, 5 node(s) had untolerated taint(s). no new claims to deallocate, preemption: 0/6 nodes are available: 1 No preemption victims found for incoming pod, 5 Preemption is not helpful for scheduling."
0.2111,Event,ADDED,eval-sanitize-1-r0-066-fvhwf.18d4a1f5c7fb8803,"reason=FailedScheduling count=None msg=0/6 nodes are available: 1 c_wall violated: 1 conflicting context pair(s) with node memory, 1 c_wall violated: 2 conflicting context pair(s) with node memory, 4 node(s) had untolerated taint(s). no new claims to deallocate, preemption: 0/6 nodes are available: 2 No preemption victims found for incoming pod, 4 Preemption is not helpful for scheduling."
0.2113,Event,ADDED,eval-sanitize-1-r0-066-fvhwf.18d4a1f5f0d0e3ec,"reason=FailedScheduling count=None msg=0/6 nodes are available: 1 c_wall violated: 1 conflicting context pair(s) with node memory, 5 node(s) had untolerated taint(s). no new claims to deallocate, preemption: 0/6 nodes are available: 1 No preemption victims found for incoming pod, 5 Preemption is not helpful for scheduling."
0.2114,Event,ADDED,eval-sanitize-1-r0-066-fvhwf.18d4a1f672c0efcf,reason=Scheduled count=None msg=Successfully assigned compute/eval-sanitize-1-r0-066-fvhwf to kind-worker2
0.2119,Event,ADDED,eval-sanitize-1-r0-066-fvhwf.18d4a1f68d562006,"reason=Pulled count=1 msg=Container image ""busybox:musl"" already present on machine"
0.212,Event,ADDED,eval-sanitize-1-r0-066-fvhwf.18d4a1f68ff98647,reason=Created count=1 msg=Created container: task
0.2122,Event,ADDED,eval-sanitize-1-r0-066-fvhwf.18d4a1f6942b7067,reason=Started count=1 msg=Started container task
0.2124,Event,ADDED,eval-sanitize-1-r0-066.18d4a1f3e5772df6,reason=SuccessfulCreate count=1 msg=Created pod: eval-sanitize-1-r0-066-fvhwf
0.2126,Event,ADDED,eval-sanitize-1-r0-066.18d4a1fc5565a476,reason=Completed count=1 msg=Job completed
0.2128,Event,ADDED,eval-sanitize-1-r0-067-d9jz6.18d4a1f41f7cb916,"reason=FailedScheduling count=None msg=0/6 nodes are available: 6 node(s) had untolerated taint(s). no new claims to deallocate, preemption: 0/6 nodes are available: 6 Preemption is not helpful for scheduling."
0.2129,Event,ADDED,eval-sanitize-1-r0-067-d9jz6.18d4a1f4edf7dccf,"reason=FailedScheduling count=None msg=0/6 nodes are available: 1 c_wall violated: 2 conflicting context pair(s) with node memory, 5 node(s) had untolerated taint(s). no new claims to deallocate, preemption: 0/6 nodes are available: 1 No preemption victims found for incoming pod, 5 Preemption is not helpful for scheduling."
0.2131,Event,ADDED,eval-sanitize-1-r0-067-d9jz6.18d4a1f4fc0ca83f,"reason=FailedScheduling count=None msg=0/6 nodes are available: 1 c_wall violated: 2 conflicting context pair(s) with node memory, 5 node(s) had untolerated taint(s). no new claims to deallocate, preemption: 0/6 nodes are available: 1 No preemption victims found for incoming pod, 5 Preemption is not helpful for scheduling."
0.2133,Event,ADDED,eval-sanitize-1-r0-067-d9jz6.18d4a1f5548298aa,reason=Scheduled count=None msg=Successfully assigned compute/eval-sanitize-1-r0-067-d9jz6 to kind-worker5
0.2134,Event,ADDED,eval-sanitize-1-r0-067-d9jz6.18d4a1f56d08ce86,"reason=Pulled count=1 msg=Container image ""busybox:musl"" already present on machine"
0.2136,Event,ADDED,eval-sanitize-1-r0-067-d9jz6.18d4a1f56f375018,reason=Created count=1 msg=Created container: task
0.2138,Event,ADDED,eval-sanitize-1-r0-067-d9jz6.18d4a1f571a21096,reason=Started count=1 msg=Started container task
0.2139,Event,ADDED,eval-sanitize-1-r0-067.18d4a1f41f6d68b4,reason=SuccessfulCreate count=1 msg=Created pod: eval-sanitize-1-r0-067-d9jz6
0.2141,Event,ADDED,eval-sanitize-1-r0-067.18d4a1fbbd59f6b9,reason=Completed count=1 msg=Job completed
0.2142,Event,ADDED,eval-sanitize-1-r0-068-skrlk.18d4a1f45fc9213e,"reason=FailedScheduling count=None msg=0/6 nodes are available: 6 node(s) had untolerated taint(s). no new claims to deallocate, preemption: 0/6 nodes are available: 6 Preemption is not helpful for scheduling."
0.2144,Event,ADDED,eval-sanitize-1-r0-068-skrlk.18d4a1f4eed0a1bf,"reason=FailedScheduling count=None msg=0/6 nodes are available: 1 c_wall violated: 1 conflicting context pair(s) with node memory, 5 node(s) had untolerated taint(s). no new claims to deallocate, preemption: 0/6 nodes are available: 1 No preemption victims found for incoming pod, 5 Preemption is not helpful for scheduling."
0.2146,Event,ADDED,eval-sanitize-1-r0-068-skrlk.18d4a1f4fc63edad,"reason=FailedScheduling count=None msg=0/6 nodes are available: 1 c_wall violated: 1 conflicting context pair(s) with node memory, 5 node(s) had untolerated taint(s). no new claims to deallocate, preemption: 0/6 nodes are available: 1 No preemption victims found for incoming pod, 5 Preemption is not helpful for scheduling."
0.2147,Event,ADDED,eval-sanitize-1-r0-068-skrlk.18d4a1f5458e3879,reason=Scheduled count=None msg=Successfully assigned compute/eval-sanitize-1-r0-068-skrlk to kind-worker5
0.2149,Event,ADDED,eval-sanitize-1-r0-068-skrlk.18d4a1f5635ed8ee,"reason=Pulled count=1 msg=Container image ""busybox:musl"" already present on machine"
0.2151,Event,ADDED,eval-sanitize-1-r0-068-skrlk.18d4a1f56692e666,reason=Created count=1 msg=Created container: task
0.2152,Event,ADDED,eval-sanitize-1-r0-068-skrlk.18d4a1f56b38f0b2,reason=Started count=1 msg=Started container task
0.2154,Event,ADDED,eval-sanitize-1-r0-068.18d4a1f45fbf47d1,reason=SuccessfulCreate count=1 msg=Created pod: eval-sanitize-1-r0-068-skrlk
0.2156,Event,ADDED,eval-sanitize-1-r0-068.18d4a1fb3a2cb4e5,reason=Completed count=1 msg=Job completed
0.2157,Event,ADDED,eval-sanitize-1-r0-069-hr6mw.18d4a1f4969d07e8,"reason=FailedScheduling count=None msg=0/6 nodes are available: 6 node(s) had untolerated taint(s). no new claims to deallocate, preemption: 0/6 nodes are available: 6 Preemption is not helpful for scheduling."
0.2158,Event,ADDED,eval-sanitize-1-r0-069-hr6mw.18d4a1f4ef6268a7,"reason=FailedScheduling count=None msg=0/6 nodes are available: 1 c_wall violated: 4 conflicting context pair(s) with node memory, 5 node(s) had untolerated taint(s). no new claims to deallocate, preemption: 0/6 nodes are available: 1 No preemption victims found for incoming pod, 5 Preemption is not helpful for scheduling."
0.216,Event,ADDED,eval-sanitize-1-r0-069-hr6mw.18d4a1f500f71c5d,"reason=FailedScheduling count=None msg=0/6 nodes are available: 1 c_wall violated: 4 conflicting context pair(s) with node memory, 5 node(s) had untolerated taint(s). no new claims to deallocate, preemption: 0/6 nodes are available: 1 No preemption victims found for incoming pod, 5 Preemption is not helpful for scheduling."
0.2162,Event,ADDED,eval-sanitize-1-r0-069-hr6mw.18d4a1f5456ca2a7,"reason=FailedScheduling count=None msg=0/6 nodes are available: 1 c_wall violated: 1 conflicting context pair(s) with node memory, 5 node(s) had untolerated taint(s). no new claims to deallocate, preemption: 0/6 nodes are available: 1 No preemption victims found for incoming pod, 5 Preemption is not helpful for scheduling."
0.2164,Event,ADDED,eval-sanitize-1-r0-069-hr6mw.18d4a1f55450ca64,"reason=FailedScheduling count=None msg=0/6 nodes are available: 1 c_wall violated: 1 conflicting context pair(s) with node memory, 5 node(s) had untolerated taint(s). no new claims to deallocate, preemption: 0/6 nodes are available: 1 No preemption victims found for incoming pod, 5 Preemption is not helpful for scheduling."
0.2165,Event,ADDED,eval-sanitize-1-r0-069-hr6mw.18d4a1f5a2a9c56d,"reason=FailedScheduling count=None msg=0/6 nodes are available: 1 c_wall violated: 1 conflicting context pair(s) with node memory, 5 node(s) had untolerated taint(s). no new claims to deallocate, preemption: 0/6 nodes are available: 1 No preemption victims found for incoming pod, 5 Preemption is not helpful for scheduling."
0.2167,Event,ADDED,eval-sanitize-1-r0-069-hr6mw.18d4a1f5a9703194,"reason=FailedScheduling count=None msg=0/6 nodes are available: 1 c_wall violated: 1 conflicting context pair(s) with node memory, 5 node(s) had untolerated taint(s). no new claims to deallocate, preemption: 0/6 nodes are available: 1 No preemption victims found for incoming pod, 5 Preemption is not helpful for scheduling."
0.2168,Event,ADDED,eval-sanitize-1-r0-069-hr6mw.18d4a1f5c1df0016,reason=Scheduled count=None msg=Successfully assigned compute/eval-sanitize-1-r0-069-hr6mw to kind-worker3
0.217,Event,ADDED,eval-sanitize-1-r0-069-hr6mw.18d4a1f5e9c033e6,"reason=Pulled count=1 msg=Container image ""busybox:musl"" already present on machine"
0.2172,Event,ADDED,eval-sanitize-1-r0-069-hr6mw.18d4a1f5eb911f4d,reason=Created count=1 msg=Created container: task
0.2174,Event,ADDED,eval-sanitize-1-r0-069-hr6mw.18d4a1f5efb0fd96,reason=Started count=1 msg=Started container task
0.2175,Event,ADDED,eval-sanitize-1-r0-069.18d4a1f4969209ee,reason=SuccessfulCreate count=1 msg=Created pod: eval-sanitize-1-r0-069-hr6mw
0.2177,Event,ADDED,eval-sanitize-1-r0-069.18d4a1fc08e80010,reason=Completed count=1 msg=Job completed
0.2178,Event,ADDED,eval-sanitize-1-r0-070-fq4g9.18d4a1f4d3f3df66,"reason=FailedScheduling count=None msg=0/6 nodes are available: 6 node(s) had untolerated taint(s). no new claims to deallocate, preemption: 0/6 nodes are available: 6 Preemption is not helpful for scheduling."
0.218,Event,ADDED,eval-sanitize-1-r0-070-fq4g9.18d4a1f4f05d8f5e,reason=Scheduled count=None msg=Successfully assigned compute/eval-sanitize-1-r0-070-fq4g9 to kind-worker
0.2182,Event,ADDED,eval-sanitize-1-r0-070-fq4g9.18d4a1f508bf0824,"reason=Pulled count=1 msg=Container image ""busybox:musl"" already present on machine"
0.2183,Event,ADDED,eval-sanitize-1-r0-070-fq4g9.18d4a1f50a100e20,reason=Created count=1 msg=Created container: task
0.2185,Event,ADDED,eval-sanitize-1-r0-070-fq4g9.18d4a1f50e8f88ff,reason=Started count=1 msg=Started container task
0.2186,Event,ADDED,eval-sanitize-1-r0-070.18d4a1f4d3dffeba,reason=SuccessfulCreate count=1 msg=Created pod: eval-sanitize-1-r0-070-fq4g9
0.219,Event,ADDED,eval-sanitize-1-r0-070.18d4a1fa80ac6e88,reason=Completed count=1 msg=Job completed
0.2191,Event,ADDED,eval-sanitize-1-r0-071-zcn82.18d4a1f51624d2dc,reason=Scheduled count=None msg=Successfully assigned compute/eval-sanitize-1-r0-071-zcn82 to kind-worker
0.2193,Event,ADDED,eval-sanitize-1-r0-071-zcn82.18d4a1f544260dad,"reason=Pulled count=1 msg=Container image ""busybox:musl"" already present on machine"
0.2194,Event,ADDED,eval-sanitize-1-r0-071-zcn82.18d4a1f5455d7c22,reason=Created count=1 msg=Created container: task
0.2196,Event,ADDED,eval-sanitize-1-r0-071-zcn82.18d4a1f54a1c0466,reason=Started count=1 msg=Started container task
0.2198,Event,ADDED,eval-sanitize-1-r0-071.18d4a1f50fb45347,reason=SuccessfulCreate count=1 msg=Created pod: eval-sanitize-1-r0-071-zcn82
0.2199,Event,ADDED,eval-sanitize-1-r0-071.18d4a1fabb370d85,reason=Completed count=1 msg=Job completed
0.2201,Event,ADDED,eval-sanitize-1-r0-072-wtpgw.18d4a1f54c022480,"reason=FailedScheduling count=None msg=0/6 nodes are available: 1 c_wall violated: 1 conflicting context pair(s) with node memory, 5 node(s) had untolerated taint(s). no new claims to deallocate, preemption: 0/6 nodes are available: 1 No preemption victims found for incoming pod, 5 Preemption is not helpful for scheduling."
0.2203,Event,ADDED,eval-sanitize-1-r0-072-wtpgw.18d4a1f5568001a1,"reason=FailedScheduling count=None msg=0/6 nodes are available: 1 c_wall violated: 1 conflicting context pair(s) with node memory, 5 node(s) had untolerated taint(s). no new claims to deallocate, preemption: 0/6 nodes are available: 1 No preemption victims found for incoming pod, 5 Preemption is not helpful for scheduling."
0.2204,Event,ADDED,eval-sanitize-1-r0-072-wtpgw.18d4a1f5a1421dd3,"reason=FailedScheduling count=None msg=0/6 nodes are available: 1 c_wall violated: 1 conflicting context pair(s) with node memory, 5 node(s) had untolerated taint(s). no new claims to deallocate, preemption: 0/6 nodes are available: 1 No preemption victims found for incoming pod, 5 Preemption is not helpful for scheduling."
0.2206,Event,ADDED,eval-sanitize-1-r0-072-wtpgw.18d4a1f5a868b4c4,"reason=FailedScheduling count=None msg=0/6 nodes are available: 1 c_wall violated: 1 conflicting context pair(s) with node memory, 5 node(s) had untolerated taint(s). no new claims to deallocate, preemption: 0/6 nodes are available: 1 No preemption victims found for incoming pod, 5 Preemption is not helpful for scheduling."
0.2208,Event,ADDED,eval-sanitize-1-r0-072-wtpgw.18d4a1f5c79d7c98,"reason=FailedScheduling count=None msg=0/6 nodes are available: 2 c_wall violated: 1 conflicting context pair(s) with node memory, 4 node(s) had untolerated taint(s). no new claims to deallocate, preemption: 0/6 nodes are available: 2 No preemption victims found for incoming pod, 4 Preemption is not helpful for scheduling."
0.221,Event,ADDED,eval-sanitize-1-r0-072-wtpgw.18d4a1f5f1835c2c,"reason=FailedScheduling count=None msg=0/6 nodes are available: 1 c_wall violated: 1 conflicting context pair(s) with node memory, 5 node(s) had untolerated taint(s). no new claims to deallocate, preemption: 0/6 nodes are available: 1 No preemption victims found for incoming pod, 5 Preemption is not helpful for scheduling."
0.2211,Event,ADDED,eval-sanitize-1-r0-072-wtpgw.18d4a1f6713f5b82,"reason=FailedScheduling count=None msg=0/6 nodes are available: 1 c_wall violated: 1 conflicting context pair(s) with node memory, 5 node(s) had untolerated taint(s). no new claims to deallocate, preemption: 0/6 nodes are available: 1 No preemption victims found for incoming pod, 5 Preemption is not helpful for scheduling."
0.2213,Event,ADDED,eval-sanitize-1-r0-072-wtpgw.18d4a1f67818cb68,"reason=FailedScheduling count=None msg=0/6 nodes are available: 1 c_wall violated: 1 conflicting context pair(s) with node memory, 5 node(s) had untolerated taint(s). no new claims to deallocate, preemption: 0/6 nodes are available: 1 No preemption victims found for incoming pod, 5 Preemption is not helpful for scheduling."
0.2214,Event,ADDED,eval-sanitize-1-r0-072-wtpgw.18d4a1fa7541131a,reason=Scheduled count=None msg=Successfully assigned compute/eval-sanitize-1-r0-072-wtpgw to kind-worker
0.2217,Event,ADDED,eval-sanitize-1-r0-072-wtpgw.18d4a1faa5fe15cd,"reason=Pulled count=1 msg=Container image ""busybox:musl"" already present on machine"
0.2219,Event,ADDED,eval-sanitize-1-r0-072-wtpgw.18d4a1faabb7868e,reason=Created count=1 msg=Created container: task
0.222,Event,ADDED,eval-sanitize-1-r0-072-wtpgw.18d4a1faae93ce15,reason=Started count=1 msg=Started container task
0.2222,Event,ADDED,eval-sanitize-1-r0-072.18d4a1f54a51c3b0,reason=SuccessfulCreate count=1 msg=Created pod: eval-sanitize-1-r0-072-wtpgw
0.2224,Event,ADDED,eval-sanitize-1-r0-072.18d4a2001e2ef427,reason=Completed count=1 msg=Job completed
0.2225,Event,ADDED,eval-sanitize-1-r0-073-ltbjx.18d4a1f59a1469e7,"reason=FailedScheduling count=None msg=0/6 nodes are available: 6 node(s) had untolerated taint(s). no new claims to deallocate, preemption: 0/6 nodes are available: 6 Preemption is not helpful for scheduling."
0.2227,Event,ADDED,eval-sanitize-1-r0-073-ltbjx.18d4a1f5a7dc8b01,"reason=FailedScheduling count=None msg=0/6 nodes are available: 1 c_wall violated: 1 conflicting context pair(s) with node memory, 5 node(s) had untolerated taint(s). no new claims to deallocate, preemption: 0/6 nodes are available: 1 No preemption victims found for incoming pod, 5 Preemption is not helpful for scheduling."
0.2229,Event,ADDED,eval-sanitize-1-r0-073-ltbjx.18d4a1f5add01fff,"reason=FailedScheduling count=None msg=0/6 nodes are available: 1 c_wall violated: 1 conflicting context pair(s) with node memory, 5 node(s) had untolerated taint(s). no new claims to deallocate, preemption: 0/6 nodes are available: 1 No preemption victims found for incoming pod, 5 Preemption is not helpful for scheduling."
0.223,Event,ADDED,eval-sanitize-1-r0-073-ltbjx.18d4a1f5bc732ef6,reason=Scheduled count=None msg=Successfully assigned compute/eval-sanitize-1-r0-073-ltbjx to kind-worker3
0.2232,Event,ADDED,eval-sanitize-1-r0-073-ltbjx.18d4a1f5efb58123,"reason=Pulled count=1 msg=Container image ""busybox:musl"" already present on machine"
0.2233,Event,ADDED,eval-sanitize-1-r0-073-ltbjx.18d4a1f5f11f4f39,reason=Created count=1 msg=Created container: task
0.2235,Event,ADDED,eval-sanitize-1-r0-073-ltbjx.18d4a1f5fbdcd562,reason=Started count=1 msg=Started container task
0.2237,Event,ADDED,eval-sanitize-1-r0-073.18d4a1f59a08cbb6,reason=SuccessfulCreate count=1 msg=Created pod: eval-sanitize-1-r0-073-ltbjx
0.2238,Event,ADDED,eval-sanitize-1-r0-073.18d4a1fc16e49c15,reason=Completed count=1 msg=Job completed
0.224,Event,ADDED,eval-sanitize-1-r0-074-vnnb9.18d4a1f5ea6cbd65,"reason=FailedScheduling count=None msg=0/6 nodes are available: 2 c_wall violated: 1 conflicting context pair(s) with node memory, 4 node(s) had untolerated taint(s). no new claims to deallocate, preemption: 0/6 nodes are available: 2 No preemption victims found for incoming pod, 4 Preemption is not helpful for scheduling."
0.2241,Event,ADDED,eval-sanitize-1-r0-074-vnnb9.18d4a1f5f030ccf3,"reason=FailedScheduling count=None msg=0/6 nodes are available: 1 c_wall violated: 1 conflicting context pair(s) with node memory, 5 node(s) had untolerated taint(s). no new claims to deallocate, preemption: 0/6 nodes are available: 1 No preemption victims found for incoming pod, 5 Preemption is not helpful for scheduling."
0.2243,Event,ADDED,eval-sanitize-1-r0-074-vnnb9.18d4a1f5f55595b8,"reason=FailedScheduling count=None msg=0/6 nodes are available: 1 c_wall violated: 1 conflicting context pair(s) with node memory, 5 node(s) had untolerated taint(s). no new claims to deallocate, preemption: 0/6 nodes are available: 1 No preemption victims found for incoming pod, 5 Preemption is not helpful for scheduling."
0.2245,Event,ADDED,eval-sanitize-1-r0-074-vnnb9.18d4a1f67281b284,reason=Scheduled count=None msg=Successfully assigned compute/eval-sanitize-1-r0-074-vnnb9 to kind-worker2
0.2246,Event,ADDED,eval-sanitize-1-r0-074-vnnb9.18d4a1f68d184c0a,"reason=Pulled count=1 msg=Container image ""busybox:musl"" already present on machine"
0.2248,Event,ADDED,eval-sanitize-1-r0-074-vnnb9.18d4a1f68f307056,reason=Created count=1 msg=Created container: task
0.225,Event,ADDED,eval-sanitize-1-r0-074-vnnb9.18d4a1f6942bde0e,reason=Started count=1 msg=Started container task
0.2251,Event,ADDED,eval-sanitize-1-r0-074.18d4a1f5ea001e8d,reason=SuccessfulCreate count=1 msg=Created pod: eval-sanitize-1-r0-074-vnnb9
0.2253,Event,ADDED,eval-sanitize-1-r0-074.18d4a1fc64316086,reason=Completed count=1 msg=Job completed
0.2254,Event,ADDED,eval-sanitize-1-r0-075-xgcrg.18d4a1f6240b7334,"reason=FailedScheduling count=None msg=0/6 nodes are available: 6 node(s) had untolerated taint(s). no new claims to deallocate, preemption: 0/6 nodes are available: 6 Preemption is not helpful for scheduling."
0.2256,Event,ADDED,eval-sanitize-1-r0-075-xgcrg.18d4a1f672afae54,"reason=FailedScheduling count=None msg=0/6 nodes are available: 1 c_wall violated: 1 conflicting context pair(s) with node memory, 5 node(s) had untolerated taint(s). no new claims to deallocate, preemption: 0/6 nodes are available: 1 No preemption victims found for incoming pod, 5 Preemption is not helpful for scheduling."
0.2272,Event,ADDED,eval-sanitize-1-r0-075-xgcrg.18d4a1f6784e2228,"reason=FailedScheduling count=None msg=0/6 nodes are available: 1 c_wall violated: 1 conflicting context pair(s) with node memory, 5 node(s) had untolerated taint(s). no new claims to deallocate, preemption: 0/6 nodes are available: 1 No preemption victims found for incoming pod, 5 Preemption is not helpful for scheduling."
0.2273,Event,ADDED,eval-sanitize-1-r0-075-xgcrg.18d4a1fa7332c9ea,reason=Scheduled count=None msg=Successfully assigned compute/eval-sanitize-1-r0-075-xgcrg to kind-worker
0.2275,Event,ADDED,eval-sanitize-1-r0-075-xgcrg.18d4a1faa41e9709,"reason=Pulled count=1 msg=Container image ""busybox:musl"" already present on machine"
0.2276,Event,ADDED,eval-sanitize-1-r0-075-xgcrg.18d4a1faa8968ad6,reason=Created count=1 msg=Created container: task
0.2279,Event,ADDED,eval-sanitize-1-r0-075-xgcrg.18d4a1faabb416cc,reason=Started count=1 msg=Started container task
0.2281,Event,ADDED,eval-sanitize-1-r0-075.18d4a1f624017d75,reason=SuccessfulCreate count=1 msg=Created pod: eval-sanitize-1-r0-075-xgcrg
0.2283,Event,ADDED,eval-sanitize-1-r0-075.18d4a2001e2fa27f,reason=Completed count=1 msg=Job completed
0.2285,Event,ADDED,eval-sanitize-1-r0-076-dxgnq.18d4a1f65a1dfc0b,"reason=FailedScheduling count=None msg=0/6 nodes are available: 6 node(s) had untolerated taint(s). no new claims to deallocate, preemption: 0/6 nodes are available: 6 Preemption is not helpful for scheduling."
0.2286,Event,ADDED,eval-sanitize-1-r0-076-dxgnq.18d4a1f677212338,"reason=FailedScheduling count=None msg=0/6 nodes are available: 1 c_wall violated: 2 conflicting context pair(s) with node memory, 5 node(s) had untolerated taint(s). no new claims to deallocate, preemption: 0/6 nodes are available: 1 No preemption victims found for incoming pod, 5 Preemption is not helpful for scheduling."
0.2289,Event,ADDED,eval-sanitize-1-r0-076-dxgnq.18d4a1f6788733f1,"reason=FailedScheduling count=None msg=0/6 nodes are available: 1 c_wall violated: 2 conflicting context pair(s) with node memory, 5 node(s) had untolerated taint(s). no new claims to deallocate, preemption: 0/6 nodes are available: 1 No preemption victims found for incoming pod, 5 Preemption is not helpful for scheduling."
0.229,Event,ADDED,eval-sanitize-1-r0-076-dxgnq.18d4a1fa73290d9a,"reason=FailedScheduling count=None msg=0/6 nodes are available: 1 c_wall violated: 1 conflicting context pair(s) with node memory, 5 node(s) had untolerated taint(s). no new claims to deallocate, preemption: 0/6 nodes are available: 1 No preemption victims found for incoming pod, 5 Preemption is not helpful for scheduling."
0.2292,Event,ADDED,eval-sanitize-1-r0-076-dxgnq.18d4a1fa8ed45206,"reason=FailedScheduling count=None msg=0/6 nodes are available: 1 c_wall violated: 4 conflicting context pair(s) with node memory, 5 node(s) had untolerated taint(s). no new claims to deallocate, preemption: 0/6 nodes are available: 1 No preemption victims found for incoming pod, 5 Preemption is not helpful for scheduling."
0.2294,Event,ADDED,eval-sanitize-1-r0-076-dxgnq.18d4a1fa9a1b9924,"reason=FailedScheduling count=None msg=0/6 nodes are available: 1 c_wall violated: 4 conflicting context pair(s) with node memory, 5 node(s) had untolerated taint(s). no new claims to deallocate, preemption: 0/6 nodes are available: 1 No preemption victims found for incoming pod, 5 Preemption is not helpful for scheduling."
0.2295,Event,ADDED,eval-sanitize-1-r0-076-dxgnq.18d4a1faeb048df8,"reason=FailedScheduling count=None msg=0/6 nodes are available: 1 c_wall violated: 1 conflicting context pair(s) with node memory, 5 node(s) had untolerated taint(s). no new claims to deallocate, preemption: 0/6 nodes are available: 1 No preemption victims found for incoming pod, 5 Preemption is not helpful for scheduling."
0.2297,Event,ADDED,eval-sanitize-1-r0-076-dxgnq.18d4a1faf20055d9,"reason=FailedScheduling count=None msg=0/6 nodes are available: 1 c_wall violated: 1 conflicting context pair(s) with node memory, 5 node(s) had untolerated taint(s). no new claims to deallocate, preemption: 0/6 nodes are available: 1 No preemption victims found for incoming pod, 5 Preemption is not helpful for scheduling."
0.2298,Event,ADDED,eval-sanitize-1-r0-076-dxgnq.18d4a1fb16dc7680,reason=Scheduled count=None msg=Successfully assigned compute/eval-sanitize-1-r0-076-dxgnq to kind-worker3
0.23,Event,ADDED,eval-sanitize-1-r0-076-dxgnq.18d4a1fb3760a4e7,"reason=Pulled count=1 msg=Container image ""busybox:musl"" already present on machine"
0.2302,Event,ADDED,eval-sanitize-1-r0-076-dxgnq.18d4a1fb38ed430d,reason=Created count=1 msg=Created container: task
0.2303,Event,ADDED,eval-sanitize-1-r0-076-dxgnq.18d4a1fb3f06b946,reason=Started count=1 msg=Started container task
0.2305,Event,ADDED,eval-sanitize-1-r0-076.18d4a1f65a18dbf2,reason=SuccessfulCreate count=1 msg=Created pod: eval-sanitize-1-r0-076-dxgnq
0.2307,Event,ADDED,eval-sanitize-1-r0-076.18d4a201d0f5ae77,reason=Completed count=1 msg=Job completed
0.2308,Event,ADDED,eval-sanitize-1-r0-077-8xn87.18d4a1f6834234b4,"reason=FailedScheduling count=None msg=0/6 nodes are available: 1 c_wall violated: 1 conflicting context pair(s) with node memory, 5 node(s) had untolerated taint(s). no new claims to deallocate, preemption: 0/6 nodes are available: 1 No preemption victims found for incoming pod, 5 Preemption is not helpful for scheduling."
0.231,Event,ADDED,eval-sanitize-1-r0-077-8xn87.18d4a1f6845010c1,"reason=FailedScheduling count=None msg=0/6 nodes are available: 1 c_wall violated: 1 conflicting context pair(s) with node memory, 5 node(s) had untolerated taint(s). no new claims to deallocate, preemption: 0/6 nodes are available: 1 No preemption victims found for incoming pod, 5 Preemption is not helpful for scheduling."
0.2312,Event,ADDED,eval-sanitize-1-r0-077-8xn87.18d4a1fa747a1066,reason=Scheduled count=None msg=Successfully assigned compute/eval-sanitize-1-r0-077-8xn87 to kind-worker
0.2314,Event,ADDED,eval-sanitize-1-r0-077-8xn87.18d4a1fa8f8c7062,"reason=Pulled count=1 msg=Container image ""busybox:musl"" already present on machine"
0.2315,Event,ADDED,eval-sanitize-1-r0-077-8xn87.18d4a1fa9596821e,reason=Created count=1 msg=Created container: task
0.2317,Event,ADDED,eval-sanitize-1-r0-077-8xn87.18d4a1fa992d738a,reason=Started count=1 msg=Started container task
0.2319,Event,ADDED,eval-sanitize-1-r0-077.18d4a1f67e80eb9e,reason=SuccessfulCreate count=1 msg=Created pod: eval-sanitize-1-r0-077-8xn87
0.2321,Event,ADDED,eval-sanitize-1-r0-077.18d4a1ffe3e41a2a,reason=Completed count=1 msg=Job completed
0.2324,Event,ADDED,eval-sanitize-1-r0-078-775c5.18d4a1f6af538e41,"reason=FailedScheduling count=None msg=0/6 nodes are available: 1 c_wall violated: 2 conflicting context pair(s) with node memory, 5 node(s) had untolerated taint(s). no new claims to deallocate, preemption: 0/6 nodes are available: 1 No preemption victims found for incoming pod, 5 Preemption is not helpful for scheduling."
0.2326,Event,ADDED,eval-sanitize-1-r0-078-775c5.18d4a1f6b02ae2c4,"reason=FailedScheduling count=None msg=0/6 nodes are available: 1 c_wall violated: 2 conflicting context pair(s) with node memory, 5 node(s) had untolerated taint(s). no new claims to deallocate, preemption: 0/6 nodes are available: 1 No preemption victims found for incoming pod, 5 Preemption is not helpful for scheduling."
0.2328,Event,ADDED,eval-sanitize-1-r0-078-775c5.18d4a1fa741fb1b1,"reason=FailedScheduling count=None msg=0/6 nodes are available: 1 c_wall violated: 1 conflicting context pair(s) with node memory, 5 node(s) had untolerated taint(s). no new claims to deallocate, preemption: 0/6 nodes are available: 1 No preemption victims found for incoming pod, 5 Preemption is not helpful for scheduling."
0.2331,Event,ADDED,eval-sanitize-1-r0-078-775c5.18d4a1fa904cf5e4,"reason=FailedScheduling count=None msg=0/6 nodes are available: 1 c_wall violated: 4 conflicting context pair(s) with node memory, 5 node(s) had untolerated taint(s). no new claims to deallocate, preemption: 0/6 nodes are available: 1 No preemption victims found for incoming pod, 5 Preemption is not helpful for scheduling."
0.2333,Event,ADDED,eval-sanitize-1-r0-078-775c5.18d4a1fa9e889a78,"reason=FailedScheduling count=None msg=0/6 nodes are available: 1 c_wall violated: 4 conflicting context pair(s) with node memory, 5 node(s) had untolerated taint(s). no new claims to deallocate, preemption: 0/6 nodes are available: 1 No preemption victims found for incoming pod, 5 Preemption is not helpful for scheduling."
0.2334,Event,ADDED,eval-sanitize-1-r0-078-775c5.18d4a1faefd78bcd,"reason=FailedScheduling count=None msg=0/6 nodes are available: 1 c_wall violated: 1 conflicting context pair(s) with node memory, 5 node(s) had untolerated taint(s). no new claims to deallocate, preemption: 0/6 nodes are available: 1 No preemption victims found for incoming pod, 5 Preemption is not helpful for scheduling."
0.2337,Event,ADDED,eval-sanitize-1-r0-078-775c5.18d4a1faf59d2ab8,"reason=FailedScheduling count=None msg=0/6 nodes are available: 1 c_wall violated: 1 conflicting context pair(s) with node memory, 5 node(s) had untolerated taint(s). no new claims to deallocate, preemption: 0/6 nodes are available: 1 No preemption victims found for incoming pod, 5 Preemption is not helpful for scheduling."
0.2338,Event,ADDED,eval-sanitize-1-r0-078-775c5.18d4a1fb172e0b48,reason=Scheduled count=None msg=Successfully assigned compute/eval-sanitize-1-r0-078-775c5 to kind-worker3
0.234,Event,ADDED,eval-sanitize-1-r0-078-775c5.18d4a1fb4330b25c,"reason=Pulled count=1 msg=Container image ""busybox:musl"" already present on machine"
0.2342,Event,ADDED,eval-sanitize-1-r0-078-775c5.18d4a1fb447617eb,reason=Created count=1 msg=Created container: task
0.2345,Event,ADDED,eval-sanitize-1-r0-078-775c5.18d4a1fb48c18fb3,reason=Started count=1 msg=Started container task
0.2347,Event,ADDED,eval-sanitize-1-r0-078.18d4a1f6af0ea58d,reason=SuccessfulCreate count=1 msg=Created pod: eval-sanitize-1-r0-078-775c5
0.2348,Event,ADDED,eval-sanitize-1-r0-078.18d4a201e14d34e4,reason=Completed count=1 msg=Job completed
0.235,Event,ADDED,eval-sanitize-1-r0-079-vvmrn.18d4a1f6ebde0a6f,"reason=FailedScheduling count=None msg=0/6 nodes are available: 6 node(s) had untolerated taint(s). no new claims to deallocate, preemption: 0/6 nodes are available: 6 Preemption is not helpful for scheduling."
0.2351,Event,ADDED,eval-sanitize-1-r0-079-vvmrn.18d4a1fa78401625,reason=Scheduled count=None msg=Successfully assigned compute/eval-sanitize-1-r0-079-vvmrn to kind-worker
0.2353,Event,ADDED,eval-sanitize-1-r0-079-vvmrn.18d4a1fa94f9b322,"reason=Pulled count=1 msg=Container image ""busybox:musl"" already present on machine"
0.2355,Event,ADDED,eval-sanitize-1-r0-079-vvmrn.18d4a1fa96fcbd16,reason=Created count=1 msg=Created container: task
0.2356,Event,ADDED,eval-sanitize-1-r0-079-vvmrn.18d4a1fa9a0e53eb,reason=Started count=1 msg=Started container task
0.2358,Event,ADDED,eval-sanitize-1-r0-079.18d4a1f6ebd1105c,reason=SuccessfulCreate count=1 msg=Created pod: eval-sanitize-1-r0-079-vvmrn
0.236,Event,ADDED,eval-sanitize-1-r0-079.18d4a2001d4cfb4d,reason=Completed count=1 msg=Job completed
0.2361,Event,ADDED,eval-sanitize-1-r0-080-rk94z.18d4a1f7294c01c8,"reason=FailedScheduling count=None msg=0/6 nodes are available: 6 node(s) had untolerated taint(s). no new claims to deallocate, preemption: 0/6 nodes are available: 6 Preemption is not helpful for scheduling."
0.2363,Event,ADDED,eval-sanitize-1-r0-080-rk94z.18d4a1fa7529fb8d,"reason=FailedScheduling count=None msg=0/6 nodes are available: 1 c_wall violated: 1 conflicting context pair(s) with node memory, 5 node(s) had untolerated taint(s). no new claims to deallocate, preemption: 0/6 nodes are available: 1 No preemption victims found for incoming pod, 5 Preemption is not helpful for scheduling."
0.2364,Event,ADDED,eval-sanitize-1-r0-080-rk94z.18d4a1fa9540baca,"reason=FailedScheduling count=None msg=0/6 nodes are available: 1 c_wall violated: 1 conflicting context pair(s) with node memory, 5 node(s) had untolerated taint(s). no new claims to deallocate, preemption: 0/6 nodes are available: 1 No preemption victims found for incoming pod, 5 Preemption is not helpful for scheduling."
0.2366,Event,ADDED,eval-sanitize-1-r0-080-rk94z.18d4a1faf0c200ba,reason=Scheduled count=None msg=Successfully assigned compute/eval-sanitize-1-r0-080-rk94z to kind-worker5
0.2368,Event,ADDED,eval-sanitize-1-r0-080-rk94z.18d4a1fb18d2d094,"reason=Pulled count=1 msg=Container image ""busybox:musl"" already present on machine"
0.2369,Event,ADDED,eval-sanitize-1-r0-080-rk94z.18d4a1fb1ba66dda,reason=Created count=1 msg=Created container: task
0.2371,Event,ADDED,eval-sanitize-1-r0-080-rk94z.18d4a1fb20c78f9c,reason=Started count=1 msg=Started container task
0.2373,Event,ADDED,eval-sanitize-1-r0-080.18d4a1f7294002fd,reason=SuccessfulCreate count=1 msg=Created pod: eval-sanitize-1-r0-080-rk94z
0.2374,Event,ADDED,eval-sanitize-1-r0-080.18d4a201bdc98505,reason=Completed count=1 msg=Job completed
0.2376,Event,ADDED,eval-sanitize-1-r0-081-82qhn.18d4a1f765c5db6d,"reason=FailedScheduling count=None msg=0/6 nodes are available: 6 node(s) had untolerated taint(s). no new claims to deallocate, preemption: 0/6 nodes are available: 6 Preemption is not helpful for scheduling."
0.2377,Event,ADDED,eval-sanitize-1-r0-081-82qhn.18d4a1fa7ef8eb72,reason=Scheduled count=None msg=Successfully assigned compute/eval-sanitize-1-r0-081-82qhn to kind-worker
0.238,Event,ADDED,eval-sanitize-1-r0-081-82qhn.18d4a1faad6c5e42,"reason=Pulled count=1 msg=Container image ""busybox:musl"" already present on machine"
0.2381,Event,ADDED,eval-sanitize-1-r0-081-82qhn.18d4a1faaf7bd529,reason=Created count=1 msg=Created container: task
0.2383,Event,ADDED,eval-sanitize-1-r0-081-82qhn.18d4a1fab385c52e,reason=Started count=1 msg=Started container task
0.2385,Event,ADDED,eval-sanitize-1-r0-081.18d4a1f765badab6,reason=SuccessfulCreate count=1 msg=Created pod: eval-sanitize-1-r0-081-82qhn
0.2386,Event,ADDED,eval-sanitize-1-r0-081.18d4a200243dbaa1,reason=Completed count=1 msg=Job completed
0.2388,Event,ADDED,eval-sanitize-1-r0-082-ckmtn.18d4a1f79dcdfe62,"reason=FailedScheduling count=None msg=0/6 nodes are available: 6 node(s) had untolerated taint(s). no new claims to deallocate, preemption: 0/6 nodes are available: 6 Preemption is not helpful for scheduling."
0.2389,Event,ADDED,eval-sanitize-1-r0-082-ckmtn.18d4a1fa7e6f74d8,"reason=FailedScheduling count=None msg=0/6 nodes are available: 1 c_wall violated: 2 conflicting context pair(s) with node memory, 5 node(s) had untolerated taint(s). no new claims to deallocate, preemption: 0/6 nodes are available: 1 No preemption victims found for incoming pod, 5 Preemption is not helpful for scheduling."
0.2391,Event,ADDED,eval-sanitize-1-r0-082-ckmtn.18d4a1fa95901b4a,"reason=FailedScheduling count=None msg=0/6 nodes are available: 1 c_wall violated: 2 conflicting context pair(s) with node memory, 5 node(s) had untolerated taint(s). no new claims to deallocate, preemption: 0/6 nodes are available: 1 No preemption victims found for incoming pod, 5 Preemption is not helpful for scheduling."
0.2393,Event,ADDED,eval-sanitize-1-r0-082-ckmtn.18d4a1faf0ae10a4,"reason=FailedScheduling count=None msg=0/6 nodes are available: 1 c_wall violated: 1 conflicting context pair(s) with node memory, 5 node(s) had untolerated taint(s). no new claims to deallocate, preemption: 0/6 nodes are available: 1 No preemption victims found for incoming pod, 5 Preemption is not helpful for scheduling."
0.2394,Event,ADDED,eval-sanitize-1-r0-082-ckmtn.18d4a1faf5ca4dc9,"reason=FailedScheduling count=None msg=0/6 nodes are available: 1 c_wall violated: 1 conflicting context pair(s) with node memory, 5 node(s) had untolerated taint(s). no new claims to deallocate, preemption: 0/6 nodes are available: 1 No preemption victims found for incoming pod, 5 Preemption is not helpful for scheduling."
0.2396,Event,ADDED,eval-sanitize-1-r0-082-ckmtn.18d4a1fb06b1c5f2,reason=Scheduled count=None msg=Successfully assigned compute/eval-sanitize-1-r0-082-ckmtn to kind-worker3
0.2398,Event,ADDED,eval-sanitize-1-r0-082-ckmtn.18d4a1fb2167fe09,"reason=Pulled count=1 msg=Container image ""busybox:musl"" already present on machine"
0.2399,Event,ADDED,eval-sanitize-1-r0-082-ckmtn.18d4a1fb2296cb3f,reason=Created count=1 msg=Created container: task
0.2401,Event,ADDED,eval-sanitize-1-r0-082-ckmtn.18d4a1fb2b3109e7,reason=Started count=1 msg=Started container task
0.2403,Event,ADDED,eval-sanitize-1-r0-082.18d4a1f79dbc5bf9,reason=SuccessfulCreate count=1 msg=Created pod: eval-sanitize-1-r0-082-ckmtn
0.2404,Event,ADDED,eval-sanitize-1-r0-082.18d4a201cf7fe89f,reason=Completed count=1 msg=Job completed
0.2406,Event,ADDED,eval-sanitize-1-r0-083-q2p88.18d4a1f7de206d00,"reason=FailedScheduling count=None msg=0/6 nodes are available: 6 node(s) had untolerated taint(s). no new claims to deallocate, preemption: 0/6 nodes are available: 6 Preemption is not helpful for scheduling."
0.2407,Event,ADDED,eval-sanitize-1-r0-083-q2p88.18d4a1fa7fcd0921,reason=Scheduled count=None msg=Successfully assigned compute/eval-sanitize-1-r0-083-q2p88 to kind-worker
0.2409,Event,ADDED,eval-sanitize-1-r0-083-q2p88.18d4a1faafb71fcd,"reason=Pulled count=1 msg=Container image ""busybox:musl"" already present on machine"
0.241,Event,ADDED,eval-sanitize-1-r0-083-q2p88.18d4a1fab251004d,reason=Created count=1 msg=Created container: task
0.2412,Event,ADDED,eval-sanitize-1-r0-083-q2p88.18d4a1fab4943619,reason=Started count=1 msg=Started container task
0.2414,Event,ADDED,eval-sanitize-1-r0-083.18d4a1f7de14cf2c,reason=SuccessfulCreate count=1 msg=Created pod: eval-sanitize-1-r0-083-q2p88
0.2415,Event,ADDED,eval-sanitize-1-r0-083.18d4a2001d6ed05d,reason=Completed count=1 msg=Job completed
0.2417,Event,ADDED,eval-sanitize-1-r0-084-cfqqc.18d4a1f814e87385,"reason=FailedScheduling count=None msg=0/6 nodes are available: 6 node(s) had untolerated taint(s). no new claims to deallocate, preemption: 0/6 nodes are available: 6 Preemption is not helpful for scheduling."
0.2419,Event,ADDED,eval-sanitize-1-r0-084-cfqqc.18d4a1fa80199f9f,reason=Scheduled count=None msg=Successfully assigned compute/eval-sanitize-1-r0-084-cfqqc to kind-worker
0.2421,Event,ADDED,eval-sanitize-1-r0-084-cfqqc.18d4a1faaf96d295,"reason=Pulled count=1 msg=Container image ""busybox:musl"" already present on machine"
0.2422,Event,ADDED,eval-sanitize-1-r0-084-cfqqc.18d4a1fab1beff78,reason=Created count=1 msg=Created container: task
0.2424,Event,ADDED,eval-sanitize-1-r0-084-cfqqc.18d4a1fab435af5b,reason=Started count=1 msg=Started container task
0.2427,Event,ADDED,eval-sanitize-1-r0-084.18d4a1f814dd5c68,reason=SuccessfulCreate count=1 msg=Created pod: eval-sanitize-1-r0-084-cfqqc
0.2429,Event,ADDED,eval-sanitize-1-r0-084.18d4a2001d931c8c,reason=Completed count=1 msg=Job completed
0.243,Event,ADDED,eval-sanitize-1-r0-085-pk5pl.18d4a1f856944f66,"reason=FailedScheduling count=None msg=0/6 nodes are available: 6 node(s) had untolerated taint(s). no new claims to deallocate, preemption: 0/6 nodes are available: 6 Preemption is not helpful for scheduling."
0.2432,Event,ADDED,eval-sanitize-1-r0-085-pk5pl.18d4a1fa7fe8bf5e,"reason=FailedScheduling count=None msg=0/6 nodes are available: 1 c_wall violated: 1 conflicting context pair(s) with node memory, 5 node(s) had untolerated taint(s). no new claims to deallocate, preemption: 0/6 nodes are available: 1 No preemption victims found for incoming pod, 5 Preemption is not helpful for scheduling."
0.2434,Event,ADDED,eval-sanitize-1-r0-085-pk5pl.18d4a1fa95ec74a6,"reason=FailedScheduling count=None msg=0/6 nodes are available: 1 c_wall violated: 1 conflicting context pair(s) with node memory, 5 node(s) had untolerated taint(s). no new claims to deallocate, preemption: 0/6 nodes are available: 1 No preemption victims found for incoming pod, 5 Preemption is not helpful for scheduling."
0.2436,Event,ADDED,eval-sanitize-1-r0-085-pk5pl.18d4a1fae548c2ec,reason=Scheduled count=None msg=Successfully assigned compute/eval-sanitize-1-r0-085-pk5pl to kind-worker5
0.2438,Event,ADDED,eval-sanitize-1-r0-085-pk5pl.18d4a1fb05335241,"reason=Pulled count=1 msg=Container image ""busybox:musl"" already present on machine"
0.2439,Event,ADDED,eval-sanitize-1-r0-085-pk5pl.18d4a1fb08b13f58,reason=Created count=1 msg=Created container: task
0.2441,Event,ADDED,eval-sanitize-1-r0-085-pk5pl.18d4a1fb0dfb73a0,reason=Started count=1 msg=Started container task
0.2443,Event,ADDED,eval-sanitize-1-r0-085.18d4a1f85689e415,reason=SuccessfulCreate count=1 msg=Created pod: eval-sanitize-1-r0-085-pk5pl
0.2444,Event,ADDED,eval-sanitize-1-r0-085.18d4a20190e8f027,reason=Completed count=1 msg=Job completed
0.2446,Event,ADDED,eval-sanitize-1-r0-086-rgjfc.18d4a1f88be58229,"reason=FailedScheduling count=None msg=0/6 nodes are available: 6 node(s) had untolerated taint(s). no new claims to deallocate, preemption: 0/6 nodes are available: 6 Preemption is not helpful for scheduling."
0.2447,Event,ADDED,eval-sanitize-1-r0-086-rgjfc.18d4a1fa87b55595,reason=Scheduled count=None msg=Successfully assigned compute/eval-sanitize-1-r0-086-rgjfc to kind-worker
0.245,Event,ADDED,eval-sanitize-1-r0-086-rgjfc.18d4a1faa5ae3cb9,"reason=Pulled count=1 msg=Container image ""busybox:musl"" already present on machine"
0.2454,Event,ADDED,eval-sanitize-1-r0-086-rgjfc.18d4a1faab2dab29,reason=Created count=1 msg=Created container: task
0.2455,Event,ADDED,eval-sanitize-1-r0-086-rgjfc.18d4a1faae532b5b,reason=Started count=1 msg=Started container task
0.2458,Event,ADDED,eval-sanitize-1-r0-086.18d4a1f88bdbaec9,reason=SuccessfulCreate count=1 msg=Created pod: eval-sanitize-1-r0-086-rgjfc
0.2461,Event,ADDED,eval-sanitize-1-r0-086.18d4a2001e2f4676,reason=Completed count=1 msg=Job completed
0.2464,Event,ADDED,eval-sanitize-1-r0-087-nx8ps.18d4a1f8c78b4ee4,"reason=FailedScheduling count=None msg=0/6 nodes are available: 6 node(s) had untolerated taint(s). no new claims to deallocate, preemption: 0/6 nodes are available: 6 Preemption is not helpful for scheduling."
0.2465,Event,ADDED,eval-sanitize-1-r0-087-nx8ps.18d4a1fa847630e8,"reason=FailedScheduling count=None msg=0/6 nodes are available: 1 c_wall violated: 2 conflicting context pair(s) with node memory, 5 node(s) had untolerated taint(s). no new claims to deallocate, preemption: 0/6 nodes are available: 1 No preemption victims found for incoming pod, 5 Preemption is not helpful for scheduling."
0.2467,Event,ADDED,eval-sanitize-1-r0-087-nx8ps.18d4a1fa96444101,"reason=FailedScheduling count=None msg=0/6 nodes are available: 1 c_wall violated: 2 conflicting context pair(s) with node memory, 5 node(s) had untolerated taint(s). no new claims to deallocate, preemption: 0/6 nodes are available: 1 No preemption victims found for incoming pod, 5 Preemption is not helpful for scheduling."
0.247,Event,ADDED,eval-sanitize-1-r0-087-nx8ps.18d4a1fae52f1b61,"reason=FailedScheduling count=None msg=0/6 nodes are available: 1 c_wall violated: 1 conflicting context pair(s) with node memory, 5 node(s) had untolerated taint(s). no new claims to deallocate, preemption: 0/6 nodes are available: 1 No preemption victims found for incoming pod, 5 Preemption is not helpful for scheduling."
0.2472,Event,ADDED,eval-sanitize-1-r0-087-nx8ps.18d4a1faf1641908,"reason=FailedScheduling count=None msg=0/6 nodes are available: 1 c_wall violated: 1 conflicting context pair(s) with node memory, 5 node(s) had untolerated taint(s). no new claims to deallocate, preemption: 0/6 nodes are available: 1 No preemption victims found for incoming pod, 5 Preemption is not helpful for scheduling."
0.2474,Event,ADDED,eval-sanitize-1-r0-087-nx8ps.18d4a1fb09f3585b,reason=Scheduled count=None msg=Successfully assigned compute/eval-sanitize-1-r0-087-nx8ps to kind-worker3
0.2476,Event,ADDED,eval-sanitize-1-r0-087-nx8ps.18d4a1fb2b2f8764,"reason=Pulled count=1 msg=Container image ""busybox:musl"" already present on machine"
0.2478,Event,ADDED,eval-sanitize-1-r0-087-nx8ps.18d4a1fb2ce2e629,reason=Created count=1 msg=Created container: task
0.248,Event,ADDED,eval-sanitize-1-r0-087-nx8ps.18d4a1fb37575af6,reason=Started count=1 msg=Started container task
0.2481,Event,ADDED,eval-sanitize-1-r0-087.18d4a1f8c7809144,reason=SuccessfulCreate count=1 msg=Created pod: eval-sanitize-1-r0-087-nx8ps
0.2483,Event,ADDED,eval-sanitize-1-r0-087.18d4a201cb2845f5,reason=Completed count=1 msg=Job completed
0.2485,Event,ADDED,eval-sanitize-1-r0-088-mk4c8.18d4a1f903de98d5,"reason=FailedScheduling count=None msg=0/6 nodes are available: 6 node(s) had untolerated taint(s). no new claims to deallocate, preemption: 0/6 nodes are available: 6 Preemption is not helpful for scheduling."
0.2486,Event,ADDED,eval-sanitize-1-r0-088-mk4c8.18d4a1fa880e121a,"reason=FailedScheduling count=None msg=0/6 nodes are available: 1 c_wall violated: 1 conflicting context pair(s) with node memory, 5 node(s) had untolerated taint(s). no new claims to deallocate, preemption: 0/6 nodes are available: 1 No preemption victims found for incoming pod, 5 Preemption is not helpful for scheduling."
0.2488,Event,ADDED,eval-sanitize-1-r0-088-mk4c8.18d4a1fa988fbaad,"reason=FailedScheduling count=None msg=0/6 nodes are available: 1 c_wall violated: 1 conflicting context pair(s) with node memory, 5 node(s) had untolerated taint(s). no new claims to deallocate, preemption: 0/6 nodes are available: 1 No preemption victims found for incoming pod, 5 Preemption is not helpful for scheduling."
0.249,Event,ADDED,eval-sanitize-1-r0-088-mk4c8.18d4a1fae6256916,reason=Scheduled count=None msg=Successfully assigned compute/eval-sanitize-1-r0-088-mk4c8 to kind-worker5
0.2492,Event,ADDED,eval-sanitize-1-r0-088-mk4c8.18d4a1fb05a78c76,"reason=Pulled count=1 msg=Container image ""busybox:musl"" already present on machine"
0.2496,Event,ADDED,eval-sanitize-1-r0-088-mk4c8.18d4a1fb0aad4d9c,reason=Created count=1 msg=Created container: task
0.2498,Event,ADDED,eval-sanitize-1-r0-088-mk4c8.18d4a1fb1707959d,reason=Started count=1 msg=Started container task
0.2499,Event,ADDED,eval-sanitize-1-r0-088.18d4a1f903ce599f,reason=SuccessfulCreate count=1 msg=Created pod: eval-sanitize-1-r0-088-mk4c8
0.2501,Event,ADDED,eval-sanitize-1-r0-088.18d4a201aa5f6edc,reason=Completed count=1 msg=Job completed
0.2504,Event,ADDED,eval-sanitize-1-r0-089-wsn8f.18d4a1f93eb9b8c3,"reason=FailedScheduling count=None msg=0/6 nodes are available: 6 node(s) had untolerated taint(s). no new claims to deallocate, preemption: 0/6 nodes are available: 6 Preemption is not helpful for scheduling."
0.2506,Event,ADDED,eval-sanitize-1-r0-089-wsn8f.18d4a1fa889db436,"reason=FailedScheduling count=None msg=0/6 nodes are available: 1 c_wall violated: 1 conflicting context pair(s) with node memory, 5 node(s) had untolerated taint(s). no new claims to deallocate, preemption: 0/6 nodes are available: 1 No preemption victims found for incoming pod, 5 Preemption is not helpful for scheduling."
0.2508,Event,ADDED,eval-sanitize-1-r0-089-wsn8f.18d4a1fa98d35675,"reason=FailedScheduling count=None msg=0/6 nodes are available: 1 c_wall violated: 1 conflicting context pair(s) with node memory, 5 node(s) had untolerated taint(s). no new claims to deallocate, preemption: 0/6 nodes are available: 1 No preemption victims found for incoming pod, 5 Preemption is not helpful for scheduling."
0.2509,Event,ADDED,eval-sanitize-1-r0-089-wsn8f.18d4a1fae6742705,reason=Scheduled count=None msg=Successfully assigned compute/eval-sanitize-1-r0-089-wsn8f to kind-worker5
0.2511,Event,ADDED,eval-sanitize-1-r0-089-wsn8f.18d4a1fb0555a79c,"reason=Pulled count=1 msg=Container image ""busybox:musl"" already present on machine"
0.2513,Event,ADDED,eval-sanitize-1-r0-089-wsn8f.18d4a1fb0a1e62d0,reason=Created count=1 msg=Created container: task
0.2515,Event,ADDED,eval-sanitize-1-r0-089-wsn8f.18d4a1fb17073661,reason=Started count=1 msg=Started container task
0.2516,Event,ADDED,eval-sanitize-1-r0-089.18d4a1f93eac8706,reason=SuccessfulCreate count=1 msg=Created pod: eval-sanitize-1-r0-089-wsn8f
0.2518,Event,ADDED,eval-sanitize-1-r0-089.18d4a201bf0e4739,reason=Completed count=1 msg=Job completed
0.252,Event,ADDED,eval-sanitize-1-r0-090-xmt8w.18d4a1f97b2536ec,"reason=FailedScheduling count=None msg=0/6 nodes are available: 6 node(s) had untolerated taint(s). no new claims to deallocate, preemption: 0/6 nodes are available: 6 Preemption is not helpful for scheduling."
0.2521,Event,ADDED,eval-sanitize-1-r0-090-xmt8w.18d4a1fa8a1cae8c,reason=Scheduled count=None msg=Successfully assigned compute/eval-sanitize-1-r0-090-xmt8w to kind-worker
0.2523,Event,ADDED,eval-sanitize-1-r0-090-xmt8w.18d4a1faa3d231a7,"reason=Pulled count=1 msg=Container image ""busybox:musl"" already present on machine"
0.2525,Event,ADDED,eval-sanitize-1-r0-090-xmt8w.18d4a1faa70b818a,reason=Created count=1 msg=Created container: task
0.2526,Event,ADDED,eval-sanitize-1-r0-090-xmt8w.18d4a1faab110c3f,reason=Started count=1 msg=Started container task
0.2529,Event,ADDED,eval-sanitize-1-r0-090.18d4a1f97b163193,reason=SuccessfulCreate count=1 msg=Created pod: eval-sanitize-1-r0-090-xmt8w
0.2531,Event,ADDED,eval-sanitize-1-r0-090.18d4a2001e0e2a1f,reason=Completed count=1 msg=Job completed
0.2533,Event,ADDED,eval-sanitize-1-r0-091-b8v5n.18d4a1f9b6511132,"reason=FailedScheduling count=None msg=0/6 nodes are available: 6 node(s) had untolerated taint(s). no new claims to deallocate, preemption: 0/6 nodes are available: 6 Preemption is not helpful for scheduling."
0.2535,Event,ADDED,eval-sanitize-1-r0-091-b8v5n.18d4a1fa8a20c944,"reason=FailedScheduling count=None msg=0/6 nodes are available: 1 c_wall violated: 1 conflicting context pair(s) with node memory, 5 node(s) had untolerated taint(s). no new claims to deallocate, preemption: 0/6 nodes are available: 1 No preemption victims found for incoming pod, 5 Preemption is not helpful for scheduling."
0.2538,Event,ADDED,eval-sanitize-1-r0-091-b8v5n.18d4a1fa9912c9dd,"reason=FailedScheduling count=None msg=0/6 nodes are available: 1 c_wall violated: 1 conflicting context pair(s) with node memory, 5 node(s) had untolerated taint(s). no new claims to deallocate, preemption: 0/6 nodes are available: 1 No preemption victims found for incoming pod, 5 Preemption is not helpful for scheduling."
0.254,Event,ADDED,eval-sanitize-1-r0-091-b8v5n.18d4a1fae6970f2b,reason=Scheduled count=None msg=Successfully assigned compute/eval-sanitize-1-r0-091-b8v5n to kind-worker5
0.2541,Event,ADDED,eval-sanitize-1-r0-091-b8v5n.18d4a1fb05870d22,"reason=Pulled count=1 msg=Container image ""busybox:musl"" already present on machine"
0.2544,Event,ADDED,eval-sanitize-1-r0-091-b8v5n.18d4a1fb0a4bba61,reason=Created count=1 msg=Created container: task
0.2545,Event,ADDED,eval-sanitize-1-r0-091-b8v5n.18d4a1fb17085fa0,reason=Started count=1 msg=Started container task
0.2547,Event,ADDED,eval-sanitize-1-r0-091.18d4a1f9b63fb8d7,reason=SuccessfulCreate count=1 msg=Created pod: eval-sanitize-1-r0-091-b8v5n
0.2549,Event,ADDED,eval-sanitize-1-r0-091.18d4a201985a79ef,reason=Completed count=1 msg=Job completed
0.2551,Event,ADDED,eval-sanitize-1-r0-092-fqjfm.18d4a1f9f3fa3283,"reason=FailedScheduling count=None msg=0/6 nodes are available: 6 node(s) had untolerated taint(s). no new claims to deallocate, preemption: 0/6 nodes are available: 6 Preemption is not helpful for scheduling."
0.2552,Event,ADDED,eval-sanitize-1-r0-092-fqjfm.18d4a1fa8ad1c549,"reason=FailedScheduling count=None msg=0/6 nodes are available: 1 c_wall violated: 2 conflicting context pair(s) with node memory, 5 node(s) had untolerated taint(s). no new claims to deallocate, preemption: 0/6 nodes are available: 1 No preemption victims found for incoming pod, 5 Preemption is not helpful for scheduling."
0.2554,Event,ADDED,eval-sanitize-1-r0-092-fqjfm.18d4a1fa9952c533,"reason=FailedScheduling count=None msg=0/6 nodes are available: 1 c_wall violated: 2 conflicting context pair(s) with node memory, 5 node(s) had untolerated taint(s). no new claims to deallocate, preemption: 0/6 nodes are available: 1 No preemption victims found for incoming pod, 5 Preemption is not helpful for scheduling."
0.2556,Event,ADDED,eval-sanitize-1-r0-092-fqjfm.18d4a1fae6551343,"reason=FailedScheduling count=None msg=0/6 nodes are available: 1 c_wall violated: 1 conflicting context pair(s) with node memory, 5 node(s) had untolerated taint(s). no new claims to deallocate, preemption: 0/6 nodes are available: 1 No preemption victims found for incoming pod, 5 Preemption is not helpful for scheduling."
0.2557,Event,ADDED,eval-sanitize-1-r0-092-fqjfm.18d4a1faf1a0b93a,"reason=FailedScheduling count=None msg=0/6 nodes are available: 1 c_wall violated: 1 conflicting context pair(s) with node memory, 5 node(s) had untolerated taint(s). no new claims to deallocate, preemption: 0/6 nodes are available: 1 No preemption victims found for incoming pod, 5 Preemption is not helpful for scheduling."
0.2559,Event,ADDED,eval-sanitize-1-r0-092-fqjfm.18d4a1fb0bcb2418,reason=Scheduled count=None msg=Successfully assigned compute/eval-sanitize-1-r0-092-fqjfm to kind-worker3
0.2561,Event,ADDED,eval-sanitize-1-r0-092-fqjfm.18d4a1fb2b559c14,"reason=Pulled count=1 msg=Container image ""busybox:musl"" already present on machine"
0.2562,Event,ADDED,eval-sanitize-1-r0-092-fqjfm.18d4a1fb2d5db7df,reason=Created count=1 msg=Created container: task
0.2565,Event,ADDED,eval-sanitize-1-r0-092-fqjfm.18d4a1fb37553bcd,reason=Started count=1 msg=Started container task
0.2566,Event,ADDED,eval-sanitize-1-r0-092.18d4a1f9f3f18d62,reason=SuccessfulCreate count=1 msg=Created pod: eval-sanitize-1-r0-092-fqjfm
0.2568,Event,ADDED,eval-sanitize-1-r0-092.18d4a201dce0cd5c,reason=Completed count=1 msg=Job completed
0.257,Event,ADDED,eval-sanitize-1-r0-093-rwslv.18d4a1fa2d604524,"reason=FailedScheduling count=None msg=0/6 nodes are available: 6 node(s) had untolerated taint(s). no new claims to deallocate, preemption: 0/6 nodes are available: 6 Preemption is not helpful for scheduling."
0.2572,Event,ADDED,eval-sanitize-1-r0-093-rwslv.18d4a1fa8e605be7,reason=Scheduled count=None msg=Successfully assigned compute/eval-sanitize-1-r0-093-rwslv to kind-worker
0.2574,Event,ADDED,eval-sanitize-1-r0-093-rwslv.18d4a1faa53244cf,"reason=Pulled count=1 msg=Container image ""busybox:musl"" already present on machine"
0.2576,Event,ADDED,eval-sanitize-1-r0-093-rwslv.18d4a1faab0f96aa,reason=Created count=1 msg=Created container: task
0.2578,Event,ADDED,eval-sanitize-1-r0-093-rwslv.18d4a1faae5396e8,reason=Started count=1 msg=Started container task
0.2579,Event,ADDED,eval-sanitize-1-r0-093.18d4a1fa2d58d53d,reason=SuccessfulCreate count=1 msg=Created pod: eval-sanitize-1-r0-093-rwslv
0.2582,Event,ADDED,eval-sanitize-1-r0-093.18d4a1ffe3c2c78e,reason=Completed count=1 msg=Job completed
0.2583,Event,ADDED,eval-sanitize-1-r0-094-xfvvp.18d4a1fa68d6b255,"reason=FailedScheduling count=None msg=0/6 nodes are available: 6 node(s) had untolerated taint(s). no new claims to deallocate, preemption: 0/6 nodes are available: 6 Preemption is not helpful for scheduling."
0.2585,Event,ADDED,eval-sanitize-1-r0-094-xfvvp.18d4a1fa8cb7aa0c,"reason=FailedScheduling count=None msg=0/6 nodes are available: 1 c_wall violated: 1 conflicting context pair(s) with node memory, 5 node(s) had untolerated taint(s). no new claims to deallocate, preemption: 0/6 nodes are available: 1 No preemption victims found for incoming pod, 5 Preemption is not helpful for scheduling."
0.2587,Event,ADDED,eval-sanitize-1-r0-094-xfvvp.18d4a1fa9993a374,"reason=FailedScheduling count=None msg=0/6 nodes are available: 1 c_wall violated: 1 conflicting context pair(s) with node memory, 5 node(s) had untolerated taint(s). no new claims to deallocate, preemption: 0/6 nodes are available: 1 No preemption victims found for incoming pod, 5 Preemption is not helpful for scheduling."
0.2588,Event,ADDED,eval-sanitize-1-r0-094-xfvvp.18d4a1faef8dad7e,reason=Scheduled count=None msg=Successfully assigned compute/eval-sanitize-1-r0-094-xfvvp to kind-worker5
0.259,Event,ADDED,eval-sanitize-1-r0-094-xfvvp.18d4a1fb18b0ac49,"reason=Pulled count=1 msg=Container image ""busybox:musl"" already present on machine"
0.2592,Event,ADDED,eval-sanitize-1-r0-094-xfvvp.18d4a1fb1ad772b3,reason=Created count=1 msg=Created container: task
0.2594,Event,ADDED,eval-sanitize-1-r0-094-xfvvp.18d4a1fb20c787ad,reason=Started count=1 msg=Started container task
0.2595,Event,ADDED,eval-sanitize-1-r0-094.18d4a1fa68cd3186,reason=SuccessfulCreate count=1 msg=Created pod: eval-sanitize-1-r0-094-xfvvp
0.2597,Event,ADDED,eval-sanitize-1-r0-094.18d4a201b961f931,reason=Completed count=1 msg=Job completed
0.2599,Event,ADDED,eval-sanitize-1-r0-095-765mj.18d4a1fab06079cd,"reason=FailedScheduling count=None msg=0/6 nodes are available: 1 c_wall violated: 1 conflicting context pair(s) with node memory, 5 node(s) had untolerated taint(s). no new claims to deallocate, preemption: 0/6 nodes are available: 1 No preemption victims found for incoming pod, 5 Preemption is not helpful for scheduling."
0.26,Event,ADDED,eval-sanitize-1-r0-095-765mj.18d4a1fab1f4bbbb,"reason=FailedScheduling count=None msg=0/6 nodes are available: 1 c_wall violated: 1 conflicting context pair(s) with node memory, 5 node(s) had untolerated taint(s). no new claims to deallocate, preemption: 0/6 nodes are available: 1 No preemption victims found for incoming pod, 5 Preemption is not helpful for scheduling."
0.2602,Event,ADDED,eval-sanitize-1-r0-095-765mj.18d4a1fae725e642,"reason=FailedScheduling count=None msg=0/6 nodes are available: 1 c_wall violated: 1 conflicting context pair(s) with node memory, 5 node(s) had untolerated taint(s). no new claims to deallocate, preemption: 0/6 nodes are available: 1 No preemption victims found for incoming pod, 5 Preemption is not helpful for scheduling."
0.2604,Event,ADDED,eval-sanitize-1-r0-095-765mj.18d4a1faf1cb24e3,"reason=FailedScheduling count=None msg=0/6 nodes are available: 1 c_wall violated: 1 conflicting context pair(s) with node memory, 5 node(s) had untolerated taint(s). no new claims to deallocate, preemption: 0/6 nodes are available: 1 No preemption victims found for incoming pod, 5 Preemption is not helpful for scheduling."
0.2606,Event,ADDED,eval-sanitize-1-r0-095-765mj.18d4a1fb14a97169,"reason=FailedScheduling count=None msg=0/6 nodes are available: 2 c_wall violated: 1 conflicting context pair(s) with node memory, 4 node(s) had untolerated taint(s). no new claims to deallocate, preemption: 0/6 nodes are available: 2 No preemption victims found for incoming pod, 4 Preemption is not helpful for scheduling."
0.2607,Event,ADDED,eval-sanitize-1-r0-095-765mj.18d4a1fb39908cc9,"reason=FailedScheduling count=None msg=0/6 nodes are available: 1 c_wall violated: 1 conflicting context pair(s) with node memory, 5 node(s) had untolerated taint(s). no new claims to deallocate, preemption: 0/6 nodes are available: 1 No preemption victims found for incoming pod, 5 Preemption is not helpful for scheduling."
0.2609,Event,ADDED,eval-sanitize-1-r0-095-765mj.18d4a1fb3cff46d2,reason=Scheduled count=None msg=Successfully assigned compute/eval-sanitize-1-r0-095-765mj to kind-worker4
0.2611,Event,ADDED,eval-sanitize-1-r0-095-765mj.18d4a1fb5c460082,"reason=Pulled count=1 msg=Container image ""busybox:musl"" already present on machine"
0.2613,Event,ADDED,eval-sanitize-1-r0-095-765mj.18d4a1fb5db7c7b6,reason=Created count=1 msg=Created container: task
0.2615,Event,ADDED,eval-sanitize-1-r0-095-765mj.18d4a1fb62a7b888,reason=Started count=1 msg=Started container task
0.2617,Event,ADDED,eval-sanitize-1-r0-095.18d4a1faabb593a7,reason=SuccessfulCreate count=1 msg=Created pod: eval-sanitize-1-r0-095-765mj
0.2619,Event,ADDED,eval-sanitize-1-r0-095.18d4a201f0735b07,reason=Completed count=1 msg=Job completed
0.262,Event,ADDED,eval-sanitize-1-r0-096-2778r.18d4a1faf63bda10,reason=Scheduled count=None msg=Successfully assigned compute/eval-sanitize-1-r0-096-2778r to kind-worker5
0.2624,Event,ADDED,eval-sanitize-1-r0-096-2778r.18d4a1fb18b61954,"reason=Pulled count=1 msg=Container image ""busybox:musl"" already present on machine"
0.2625,Event,ADDED,eval-sanitize-1-r0-096-2778r.18d4a1fb1b4d6a9b,reason=Created count=1 msg=Created container: task
0.2627,Event,ADDED,eval-sanitize-1-r0-096-2778r.18d4a1fb2076b65c,reason=Started count=1 msg=Started container task
0.2629,Event,ADDED,eval-sanitize-1-r0-096.18d4a1faf5c2dcd2,reason=SuccessfulCreate count=1 msg=Created pod: eval-sanitize-1-r0-096-2778r
0.2631,Event,ADDED,eval-sanitize-1-r0-096.18d4a201a14b4022,reason=Completed count=1 msg=Job completed
0.2633,Event,ADDED,eval-sanitize-1-r0-097-8px6j.18d4a1fb4a480223,reason=Scheduled count=None msg=Successfully assigned compute/eval-sanitize-1-r0-097-8px6j to kind-worker4
0.2635,Event,ADDED,eval-sanitize-1-r0-097-8px6j.18d4a1fb63e72a70,"reason=Pulled count=1 msg=Container image ""busybox:musl"" already present on machine"
0.2636,Event,ADDED,eval-sanitize-1-r0-097-8px6j.18d4a1fb651e402f,reason=Created count=1 msg=Created container: task
0.2638,Event,ADDED,eval-sanitize-1-r0-097-8px6j.18d4a1fb693cb784,reason=Started count=1 msg=Started container task
0.264,Event,ADDED,eval-sanitize-1-r0-097.18d4a1fb49274a50,reason=SuccessfulCreate count=1 msg=Created pod: eval-sanitize-1-r0-097-8px6j
0.2642,Event,ADDED,eval-sanitize-1-r0-097.18d4a201ebc9e904,reason=Completed count=1 msg=Job completed
0.2646,Event,ADDED,eval-sanitize-1-r0-098-9k5ds.18d4a1fba8938c12,"reason=FailedScheduling count=None msg=0/6 nodes are available: 6 node(s) had untolerated taint(s). no new claims to deallocate, preemption: 0/6 nodes are available: 6 Preemption is not helpful for scheduling."
0.2648,Event,ADDED,eval-sanitize-1-r0-098-9k5ds.18d4a1fbf7f79be7,reason=Scheduled count=None msg=Successfully assigned compute/eval-sanitize-1-r0-098-9k5ds to kind-worker2
0.2649,Event,ADDED,eval-sanitize-1-r0-098-9k5ds.18d4a1fc11cf8ae5,"reason=Pulled count=1 msg=Container image ""busybox:musl"" already present on machine"
0.2652,Event,ADDED,eval-sanitize-1-r0-098-9k5ds.18d4a1fc12ee4433,reason=Created count=1 msg=Created container: task
0.2655,Event,ADDED,eval-sanitize-1-r0-098-9k5ds.18d4a1fc14e0c0f5,reason=Started count=1 msg=Started container task
0.2657,Event,ADDED,eval-sanitize-1-r0-098.18d4a1fba88c02f0,reason=SuccessfulCreate count=1 msg=Created pod: eval-sanitize-1-r0-098-9k5ds
0.2658,Event,ADDED,eval-sanitize-1-r0-098.18d4a202151b1eed,reason=Completed count=1 msg=Job completed
0.266,Event,ADDED,eval-sanitize-1-r0-099-8hrsf.18d4a1fbc6dc78ee,"reason=FailedScheduling count=None msg=0/6 nodes are available: 6 node(s) had untolerated taint(s). no new claims to deallocate, preemption: 0/6 nodes are available: 6 Preemption is not helpful for scheduling."
0.2662,Event,ADDED,eval-sanitize-1-r0-099-8hrsf.18d4a1fbf7d2bf36,"reason=FailedScheduling count=None msg=0/6 nodes are available: 1 c_wall violated: 1 conflicting context pair(s) with node memory, 5 node(s) had untolerated taint(s). no new claims to deallocate, preemption: 0/6 nodes are available: 1 No preemption victims found for incoming pod, 5 Preemption is not helpful for scheduling."
0.2664,Event,ADDED,eval-sanitize-1-r0-099-8hrsf.18d4a1fbf85a985e,"reason=FailedScheduling count=None msg=0/6 nodes are available: 1 c_wall violated: 1 conflicting context pair(s) with node memory, 5 node(s) had untolerated taint(s). no new claims to deallocate, preemption: 0/6 nodes are available: 1 No preemption victims found for incoming pod, 5 Preemption is not helpful for scheduling."
0.2666,Event,ADDED,eval-sanitize-1-r0-099-8hrsf.18d4a2004042ba5e,reason=Scheduled count=None msg=Successfully assigned compute/eval-sanitize-1-r0-099-8hrsf to kind-worker
0.2667,Event,ADDED,eval-sanitize-1-r0-099-8hrsf.18d4a2005c1175a4,"reason=Pulled count=1 msg=Container image ""busybox:musl"" already present on machine"
0.2669,Event,ADDED,eval-sanitize-1-r0-099-8hrsf.18d4a2005ee5d95f,reason=Created count=1 msg=Created container: task
0.2671,Event,ADDED,eval-sanitize-1-r0-099-8hrsf.18d4a200628f08bb,reason=Started count=1 msg=Started container task
0.2673,Event,ADDED,eval-sanitize-1-r0-099.18d4a1fbc6d18129,reason=SuccessfulCreate count=1 msg=Created pod: eval-sanitize-1-r0-099-8hrsf
0.2675,Event,ADDED,eval-sanitize-1-r0-099.18d4a205bbeb6dbb,reason=Completed count=1 msg=Job completed
0.2676,Event,ADDED,eval-sanitize-1-r0-100-6m4d9.18d4a1fc1a54f7a7,"reason=FailedScheduling count=None msg=0/6 nodes are available: 1 c_wall violated: 1 conflicting context pair(s) with node memory, 5 node(s) had untolerated taint(s). no new claims to deallocate, preemption: 0/6 nodes are available: 1 No preemption victims found for incoming pod, 5 Preemption is not helpful for scheduling."
0.2678,Event,ADDED,eval-sanitize-1-r0-100-6m4d9.18d4a1fc1adf97ef,"reason=FailedScheduling count=None msg=0/6 nodes are available: 1 c_wall violated: 1 conflicting context pair(s) with node memory, 5 node(s) had untolerated taint(s). no new claims to deallocate, preemption: 0/6 nodes are available: 1 No preemption victims found for incoming pod, 5 Preemption is not helpful for scheduling."
0.268,Event,ADDED,eval-sanitize-1-r0-100-6m4d9.18d4a200408931b2,"reason=FailedScheduling count=None msg=0/6 nodes are available: 1 c_wall violated: 1 conflicting context pair(s) with node memory, 5 node(s) had untolerated taint(s). no new claims to deallocate, preemption: 0/6 nodes are available: 1 No preemption victims found for incoming pod, 5 Preemption is not helpful for scheduling."
0.2681,Event,ADDED,eval-sanitize-1-r0-100-6m4d9.18d4a20053c3cb32,"reason=FailedScheduling count=None msg=0/6 nodes are available: 1 c_wall violated: 1 conflicting context pair(s) with node memory, 5 node(s) had untolerated taint(s). no new claims to deallocate, preemption: 0/6 nodes are available: 1 No preemption victims found for incoming pod, 5 Preemption is not helpful for scheduling."
0.2683,Event,ADDED,eval-sanitize-1-r0-100-6m4d9.18d4a2006fb75518,reason=Scheduled count=None msg=Successfully assigned compute/eval-sanitize-1-r0-100-6m4d9 to kind-worker5
0.2684,Event,ADDED,eval-sanitize-1-r0-100-6m4d9.18d4a2008b6cd174,"reason=Pulled count=1 msg=Container image ""busybox:musl"" already present on machine"
0.2686,Event,ADDED,eval-sanitize-1-r0-100-6m4d9.18d4a2008dd81c88,reason=Created count=1 msg=Created container: task
0.2687,Event,ADDED,eval-sanitize-1-r0-100-6m4d9.18d4a2009213f858,reason=Started count=1 msg=Started container task
0.2689,Event,ADDED,eval-sanitize-1-r0-100.18d4a1fc1a1b68c2,reason=SuccessfulCreate count=1 msg=Created pod: eval-sanitize-1-r0-100-6m4d9
0.2692,Event,ADDED,eval-sanitize-1-r0-100.18d4a207082e9ffb,reason=Completed count=1 msg=Job completed
0.2693,Event,ADDED,eval-sanitize-1-r0-101-5sdhr.18d4a1fc2a04734e,"reason=FailedScheduling count=None msg=0/6 nodes are available: 1 c_wall violated: 1 conflicting context pair(s) with node memory, 5 node(s) had untolerated taint(s). no new claims to deallocate, preemption: 0/6 nodes are available: 1 No preemption victims found for incoming pod, 5 Preemption is not helpful for scheduling."
0.2695,Event,ADDED,eval-sanitize-1-r0-101-5sdhr.18d4a1fc2ab1d99d,"reason=FailedScheduling count=None msg=0/6 nodes are available: 1 c_wall violated: 1 conflicting context pair(s) with node memory, 5 node(s) had untolerated taint(s). no new claims to deallocate, preemption: 0/6 nodes are available: 1 No preemption victims found for incoming pod, 5 Preemption is not helpful for scheduling."
0.2697,Event,ADDED,eval-sanitize-1-r0-101-5sdhr.18d4a20041201fee,"reason=FailedScheduling count=None msg=0/6 nodes are available: 1 c_wall violated: 1 conflicting context pair(s) with node memory, 5 node(s) had untolerated taint(s). no new claims to deallocate, preemption: 0/6 nodes are available: 1 No preemption victims found for incoming pod, 5 Preemption is not helpful for scheduling."
0.2699,Event,ADDED,eval-sanitize-1-r0-101-5sdhr.18d4a20057899433,"reason=FailedScheduling count=None msg=0/6 nodes are available: 1 c_wall violated: 2 conflicting context pair(s) with node memory, 5 node(s) had untolerated taint(s). no new claims to deallocate, preemption: 0/6 nodes are available: 1 No preemption victims found for incoming pod, 5 Preemption is not helpful for scheduling."
0.27,Event,ADDED,eval-sanitize-1-r0-101-5sdhr.18d4a200700cd2ec,reason=Scheduled count=None msg=Successfully assigned compute/eval-sanitize-1-r0-101-5sdhr to kind-worker5
0.2702,Event,ADDED,eval-sanitize-1-r0-101-5sdhr.18d4a2008c273b56,"reason=Pulled count=1 msg=Container image ""busybox:musl"" already present on machine"
0.2704,Event,ADDED,eval-sanitize-1-r0-101-5sdhr.18d4a2008eca7d03,reason=Created count=1 msg=Created container: task
0.2705,Event,ADDED,eval-sanitize-1-r0-101-5sdhr.18d4a200934ff6d2,reason=Started count=1 msg=Started container task
0.2707,Event,ADDED,eval-sanitize-1-r0-101.18d4a1fc29bb1ab7,reason=SuccessfulCreate count=1 msg=Created pod: eval-sanitize-1-r0-101-5sdhr
0.2709,Event,ADDED,eval-sanitize-1-r0-101.18d4a206deae04a6,reason=Completed count=1 msg=Job completed
0.271,Event,ADDED,eval-sanitize-1-r0-102-vfnvk.18d4a1fc527d826b,"reason=FailedScheduling count=None msg=0/6 nodes are available: 6 node(s) had untolerated taint(s). no new claims to deallocate, preemption: 0/6 nodes are available: 6 Preemption is not helpful for scheduling."
0.2712,Event,ADDED,eval-sanitize-1-r0-102-vfnvk.18d4a2004196a113,"reason=FailedScheduling count=None msg=0/6 nodes are available: 1 c_wall violated: 1 conflicting context pair(s) with node memory, 5 node(s) had untolerated taint(s). no new claims to deallocate, preemption: 0/6 nodes are available: 1 No preemption victims found for incoming pod, 5 Preemption is not helpful for scheduling."
0.2713,Event,ADDED,eval-sanitize-1-r0-102-vfnvk.18d4a2005c34432d,"reason=FailedScheduling count=None msg=0/6 nodes are available: 1 c_wall violated: 2 conflicting context pair(s) with node memory, 5 node(s) had untolerated taint(s). no new claims to deallocate, preemption: 0/6 nodes are available: 1 No preemption victims found for incoming pod, 5 Preemption is not helpful for scheduling."
0.2715,Event,ADDED,eval-sanitize-1-r0-102-vfnvk.18d4a200711ea969,reason=Scheduled count=None msg=Successfully assigned compute/eval-sanitize-1-r0-102-vfnvk to kind-worker5
0.2716,Event,ADDED,eval-sanitize-1-r0-102-vfnvk.18d4a2008d227a6b,"reason=Pulled count=1 msg=Container image ""busybox:musl"" already present on machine"
0.2718,Event,ADDED,eval-sanitize-1-r0-102-vfnvk.18d4a2008f0a267a,reason=Created count=1 msg=Created container: task
0.272,Event,ADDED,eval-sanitize-1-r0-102-vfnvk.18d4a200934bf125,reason=Started count=1 msg=Started container task
0.2722,Event,ADDED,eval-sanitize-1-r0-102.18d4a1fc52720817,reason=SuccessfulCreate count=1 msg=Created pod: eval-sanitize-1-r0-102-vfnvk
0.2723,Event,ADDED,eval-sanitize-1-r0-102.18d4a206d5858102,reason=Completed count=1 msg=Job completed
0.2728,Event,ADDED,eval-sanitize-1-r0-103-wwkc6.18d4a1fc812f0fe0,"reason=FailedScheduling count=None msg=0/6 nodes are available: 6 node(s) had untolerated taint(s). no new claims to deallocate, preemption: 0/6 nodes are available: 6 Preemption is not helpful for scheduling."
0.273,Event,ADDED,eval-sanitize-1-r0-103-wwkc6.18d4a20044cdaa98,reason=Scheduled count=None msg=Successfully assigned compute/eval-sanitize-1-r0-103-wwkc6 to kind-worker
0.2733,Event,ADDED,eval-sanitize-1-r0-103-wwkc6.18d4a2006456d021,"reason=Pulled count=1 msg=Container image ""busybox:musl"" already present on machine"
0.2734,Event,ADDED,eval-sanitize-1-r0-103-wwkc6.18d4a2006613a1fe,reason=Created count=1 msg=Created container: task
0.2738,Event,ADDED,eval-sanitize-1-r0-103-wwkc6.18d4a2006d66587b,reason=Started count=1 msg=Started container task
0.274,Event,ADDED,eval-sanitize-1-r0-103.18d4a1fc81223a5a,reason=SuccessfulCreate count=1 msg=Created pod: eval-sanitize-1-r0-103-wwkc6
0.2741,Event,ADDED,eval-sanitize-1-r0-103.18d4a206baac76cb,reason=Completed count=1 msg=Job completed
0.2744,Event,ADDED,eval-sanitize-1-r0-104-24b4v.18d4a1fcbd2ac878,"reason=FailedScheduling count=None msg=0/6 nodes are available: 6 node(s) had untolerated taint(s). no new claims to deallocate, preemption: 0/6 nodes are available: 6 Preemption is not helpful for scheduling."
0.2746,Event,ADDED,eval-sanitize-1-r0-104-24b4v.18d4a200461a20ea,reason=Scheduled count=None msg=Successfully assigned compute/eval-sanitize-1-r0-104-24b4v to kind-worker
0.2749,Event,ADDED,eval-sanitize-1-r0-104-24b4v.18d4a20064317a62,"reason=Pulled count=1 msg=Container image ""busybox:musl"" already present on machine"
0.275,Event,ADDED,eval-sanitize-1-r0-104-24b4v.18d4a20065feae1f,reason=Created count=1 msg=Created container: task
0.2753,Event,ADDED,eval-sanitize-1-r0-104-24b4v.18d4a2006a9537df,reason=Started count=1 msg=Started container task
0.2754,Event,ADDED,eval-sanitize-1-r0-104.18d4a1fcbd1e1199,reason=SuccessfulCreate count=1 msg=Created pod: eval-sanitize-1-r0-104-24b4v
0.2756,Event,ADDED,eval-sanitize-1-r0-104.18d4a205bbeb2507,reason=Completed count=1 msg=Job completed
0.2758,Event,ADDED,eval-sanitize-1-r0-105-hkhnq.18d4a1fcf896f337,"reason=FailedScheduling count=None msg=0/6 nodes are available: 6 node(s) had untolerated taint(s). no new claims to deallocate, preemption: 0/6 nodes are available: 6 Preemption is not helpful for scheduling."
0.2759,Event,ADDED,eval-sanitize-1-r0-105-hkhnq.18d4a20047147aba,reason=Scheduled count=None msg=Successfully assigned compute/eval-sanitize-1-r0-105-hkhnq to kind-worker
0.2761,Event,ADDED,eval-sanitize-1-r0-105-hkhnq.18d4a200737d061e,"reason=Pulled count=1 msg=Container image ""busybox:musl"" already present on machine"
0.2763,Event,ADDED,eval-sanitize-1-r0-105-hkhnq.18d4a200757e28d5,reason=Created count=1 msg=Created container: task
0.2765,Event,ADDED,eval-sanitize-1-r0-105-hkhnq.18d4a2007a002e9a,reason=Started count=1 msg=Started container task
0.2766,Event,ADDED,eval-sanitize-1-r0-105.18d4a1fcf88d3856,reason=SuccessfulCreate count=1 msg=Created pod: eval-sanitize-1-r0-105-hkhnq
0.2768,Event,ADDED,eval-sanitize-1-r0-105.18d4a205bba23d89,reason=Completed count=1 msg=Job completed
0.2769,Event,ADDED,eval-sanitize-1-r0-106-fk2pc.18d4a1fd34f59524,"reason=FailedScheduling count=None msg=0/6 nodes are available: 6 node(s) had untolerated taint(s). no new claims to deallocate, preemption: 0/6 nodes are available: 6 Preemption is not helpful for scheduling."
0.2774,Event,ADDED,eval-sanitize-1-r0-106-fk2pc.18d4a2004710fb81,"reason=FailedScheduling count=None msg=0/6 nodes are available: 1 c_wall violated: 1 conflicting context pair(s) with node memory, 5 node(s) had untolerated taint(s). no new claims to deallocate, preemption: 0/6 nodes are available: 1 No preemption victims found for incoming pod, 5 Preemption is not helpful for scheduling."
0.2776,Event,ADDED,eval-sanitize-1-r0-106-fk2pc.18d4a2005d0a0f68,"reason=FailedScheduling count=None msg=0/6 nodes are available: 1 c_wall violated: 1 conflicting context pair(s) with node memory, 5 node(s) had untolerated taint(s). no new claims to deallocate, preemption: 0/6 nodes are available: 1 No preemption victims found for incoming pod, 5 Preemption is not helpful for scheduling."
0.2778,Event,ADDED,eval-sanitize-1-r0-106-fk2pc.18d4a2008866248a,"reason=FailedScheduling count=None msg=0/6 nodes are available: 2 c_wall violated: 1 conflicting context pair(s) with node memory, 4 node(s) had untolerated taint(s). no new claims to deallocate, preemption: 0/6 nodes are available: 2 No preemption victims found for incoming pod, 4 Preemption is not helpful for scheduling."
0.2781,Event,ADDED,eval-sanitize-1-r0-106-fk2pc.18d4a2009a5db657,"reason=FailedScheduling count=None msg=0/6 nodes are available: 1 c_wall violated: 1 conflicting context pair(s) with node memory, 1 c_wall violated: 2 conflicting context pair(s) with node memory, 4 node(s) had untolerated taint(s). no new claims to deallocate, preemption: 0/6 nodes are available: 2 No preemption victims found for incoming pod, 4 Preemption is not helpful for scheduling."
0.2783,Event,ADDED,eval-sanitize-1-r0-106-fk2pc.18d4a200d187cfb5,"reason=FailedScheduling count=None msg=0/6 nodes are available: 1 c_wall violated: 1 conflicting context pair(s) with node memory, 5 node(s) had untolerated taint(s). no new claims to deallocate, preemption: 0/6 nodes are available: 1 No preemption victims found for incoming pod, 5 Preemption is not helpful for scheduling."
0.2785,Event,ADDED,eval-sanitize-1-r0-106-fk2pc.18d4a2012327bf11,reason=Scheduled count=None msg=Successfully assigned compute/eval-sanitize-1-r0-106-fk2pc to kind-worker2
0.2788,Event,ADDED,eval-sanitize-1-r0-106-fk2pc.18d4a2013fb2c33a,"reason=Pulled count=1 msg=Container image ""busybox:musl"" already present on machine"
0.279,Event,ADDED,eval-sanitize-1-r0-106-fk2pc.18d4a2014149b22b,reason=Created count=1 msg=Created container: task
0.2793,Event,ADDED,eval-sanitize-1-r0-106-fk2pc.18d4a20148d61958,reason=Started count=1 msg=Started container task
0.2796,Event,ADDED,eval-sanitize-1-r0-106.18d4a1fd34ea2368,reason=SuccessfulCreate count=1 msg=Created pod: eval-sanitize-1-r0-106-fk2pc
0.2797,Event,ADDED,eval-sanitize-1-r0-106.18d4a207797e627f,reason=Completed count=1 msg=Job completed
0.2799,Event,ADDED,eval-sanitize-1-r0-107-6wzdd.18d4a1fd703a0a84,"reason=FailedScheduling count=None msg=0/6 nodes are available: 6 node(s) had untolerated taint(s). no new claims to deallocate, preemption: 0/6 nodes are available: 6 Preemption is not helpful for scheduling."
0.28,Event,ADDED,eval-sanitize-1-r0-107-6wzdd.18d4a20047ed31aa,"reason=FailedScheduling count=None msg=0/6 nodes are available: 1 c_wall violated: 2 conflicting context pair(s) with node memory, 5 node(s) had untolerated taint(s). no new claims to deallocate, preemption: 0/6 nodes are available: 1 No preemption victims found for incoming pod, 5 Preemption is not helpful for scheduling."
0.2805,Event,ADDED,eval-sanitize-1-r0-107-6wzdd.18d4a2005d3ff8d4,"reason=FailedScheduling count=None msg=0/6 nodes are available: 1 c_wall violated: 2 conflicting context pair(s) with node memory, 5 node(s) had untolerated taint(s). no new claims to deallocate, preemption: 0/6 nodes are available: 1 No preemption victims found for incoming pod, 5 Preemption is not helpful for scheduling."
0.2807,Event,ADDED,eval-sanitize-1-r0-107-6wzdd.18d4a200771c5bef,reason=Scheduled count=None msg=Successfully assigned compute/eval-sanitize-1-r0-107-6wzdd to kind-worker5
0.2809,Event,ADDED,eval-sanitize-1-r0-107-6wzdd.18d4a200927a1808,"reason=Pulled count=1 msg=Container image ""busybox:musl"" already present on machine"
0.2812,Event,ADDED,eval-sanitize-1-r0-107-6wzdd.18d4a200941214a3,reason=Created count=1 msg=Created container: task
0.2813,Event,ADDED,eval-sanitize-1-r0-107-6wzdd.18d4a2009c2451d4,reason=Started count=1 msg=Started container task
0.2815,Event,ADDED,eval-sanitize-1-r0-107.18d4a1fd702e7a06,reason=SuccessfulCreate count=1 msg=Created pod: eval-sanitize-1-r0-107-6wzdd
0.2817,Event,ADDED,eval-sanitize-1-r0-107.18d4a20714ef6e6a,reason=Completed count=1 msg=Job completed
0.2819,Event,ADDED,eval-sanitize-1-r0-108-4rk6h.18d4a1fdab69dd2d,"reason=FailedScheduling count=None msg=0/6 nodes are available: 6 node(s) had untolerated taint(s). no new claims to deallocate, preemption: 0/6 nodes are available: 6 Preemption is not helpful for scheduling."
0.2821,Event,ADDED,eval-sanitize-1-r0-108-4rk6h.18d4a20048711fef,"reason=FailedScheduling count=None msg=0/6 nodes are available: 1 c_wall violated: 1 conflicting context pair(s) with node memory, 5 node(s) had untolerated taint(s). no new claims to deallocate, preemption: 0/6 nodes are available: 1 No preemption victims found for incoming pod, 5 Preemption is not helpful for scheduling."
0.2823,Event,ADDED,eval-sanitize-1-r0-108-4rk6h.18d4a2005d8994c5,"reason=FailedScheduling count=None msg=0/6 nodes are available: 1 c_wall violated: 1 conflicting context pair(s) with node memory, 5 node(s) had untolerated taint(s). no new claims to deallocate, preemption: 0/6 nodes are available: 1 No preemption victims found for incoming pod, 5 Preemption is not helpful for scheduling."
0.2825,Event,ADDED,eval-sanitize-1-r0-108-4rk6h.18d4a20088f21555,reason=Scheduled count=None msg=Successfully assigned compute/eval-sanitize-1-r0-108-4rk6h to kind-worker4
0.2827,Event,ADDED,eval-sanitize-1-r0-108-4rk6h.18d4a200a54c3a08,"reason=Pulled count=1 msg=Container image ""busybox:musl"" already present on machine"
0.2828,Event,ADDED,eval-sanitize-1-r0-108-4rk6h.18d4a200a7a686e4,reason=Created count=1 msg=Created container: task
0.283,Event,ADDED,eval-sanitize-1-r0-108-4rk6h.18d4a200accbdbf2,reason=Started count=1 msg=Started container task
0.2832,Event,ADDED,eval-sanitize-1-r0-108.18d4a1fdab5f0d1e,reason=SuccessfulCreate count=1 msg=Created pod: eval-sanitize-1-r0-108-4rk6h
0.2833,Event,ADDED,eval-sanitize-1-r0-108.18d4a2075bc1919d,reason=Completed count=1 msg=Job completed
0.2835,Event,ADDED,eval-sanitize-1-r0-109-8qs95.18d4a1fde7f16af9,"reason=FailedScheduling count=None msg=0/6 nodes are available: 6 node(s) had untolerated taint(s). no new claims to deallocate, preemption: 0/6 nodes are available: 6 Preemption is not helpful for scheduling."
0.2841,Event,ADDED,eval-sanitize-1-r0-109-8qs95.18d4a2004bb23e75,"reason=FailedScheduling count=None msg=0/6 nodes are available: 1 c_wall violated: 1 conflicting context pair(s) with node memory, 5 node(s) had untolerated taint(s). no new claims to deallocate, preemption: 0/6 nodes are available: 1 No preemption victims found for incoming pod, 5 Preemption is not helpful for scheduling."
0.2844,Event,ADDED,eval-sanitize-1-r0-109-8qs95.18d4a2005dc5dbf2,"reason=FailedScheduling count=None msg=0/6 nodes are available: 1 c_wall violated: 1 conflicting context pair(s) with node memory, 5 node(s) had untolerated taint(s). no new claims to deallocate, preemption: 0/6 nodes are available: 1 No preemption victims found for incoming pod, 5 Preemption is not helpful for scheduling."
0.2846,Event,ADDED,eval-sanitize-1-r0-109-8qs95.18d4a2008d4227c8,"reason=FailedScheduling count=None msg=0/6 nodes are available: 1 c_wall violated: 1 conflicting context pair(s) with node memory, 1 c_wall violated: 3 conflicting context pair(s) with node memory, 4 node(s) had untolerated taint(s). no new claims to deallocate, preemption: 0/6 nodes are available: 2 No preemption victims found for incoming pod, 4 Preemption is not helpful for scheduling."
0.2853,Event,ADDED,eval-sanitize-1-r0-109-8qs95.18d4a200b76e6ccc,reason=Scheduled count=None msg=Successfully assigned compute/eval-sanitize-1-r0-109-8qs95 to kind-worker3
0.2855,Event,ADDED,eval-sanitize-1-r0-109-8qs95.18d4a200d1aff4a8,"reason=Pulled count=1 msg=Container image ""busybox:musl"" already present on machine"
0.2858,Event,ADDED,eval-sanitize-1-r0-109-8qs95.18d4a200d32a09aa,reason=Created count=1 msg=Created container: task
0.286,Event,ADDED,eval-sanitize-1-r0-109-8qs95.18d4a200d9f80f9f,reason=Started count=1 msg=Started container task
0.2862,Event,ADDED,eval-sanitize-1-r0-109.18d4a1fde7e0330a,reason=SuccessfulCreate count=1 msg=Created pod: eval-sanitize-1-r0-109-8qs95
0.2864,Event,ADDED,eval-sanitize-1-r0-109.18d4a207230aac72,reason=Completed count=1 msg=Job completed
0.2867,Event,ADDED,eval-sanitize-1-r0-110-kw7g6.18d4a1fe227bccd3,"reason=FailedScheduling count=None msg=0/6 nodes are available: 6 node(s) had untolerated taint(s). no new claims to deallocate, preemption: 0/6 nodes are available: 6 Preemption is not helpful for scheduling."
0.2869,Event,ADDED,eval-sanitize-1-r0-110-kw7g6.18d4a2004c3d29c0,"reason=FailedScheduling count=None msg=0/6 nodes are available: 1 c_wall violated: 1 conflicting context pair(s) with node memory, 5 node(s) had untolerated taint(s). no new claims to deallocate, preemption: 0/6 nodes are available: 1 No preemption victims found for incoming pod, 5 Preemption is not helpful for scheduling."
0.287,Event,ADDED,eval-sanitize-1-r0-110-kw7g6.18d4a2005e0976cd,"reason=FailedScheduling count=None msg=0/6 nodes are available: 1 c_wall violated: 1 conflicting context pair(s) with node memory, 5 node(s) had untolerated taint(s). no new claims to deallocate, preemption: 0/6 nodes are available: 1 No preemption victims found for incoming pod, 5 Preemption is not helpful for scheduling."
0.2874,Event,ADDED,eval-sanitize-1-r0-110-kw7g6.18d4a20081ab2b66,reason=Scheduled count=None msg=Successfully assigned compute/eval-sanitize-1-r0-110-kw7g6 to kind-worker5
0.2876,Event,ADDED,eval-sanitize-1-r0-110-kw7g6.18d4a200a1087b40,"reason=Pulled count=1 msg=Container image ""busybox:musl"" already present on machine"
0.2879,Event,ADDED,eval-sanitize-1-r0-110-kw7g6.18d4a200a26c99bf,reason=Created count=1 msg=Created container: task
0.2882,Event,ADDED,eval-sanitize-1-r0-110-kw7g6.18d4a200a644478d,reason=Started count=1 msg=Started container task
0.2884,Event,ADDED,eval-sanitize-1-r0-110.18d4a1fe227265ec,reason=SuccessfulCreate count=1 msg=Created pod: eval-sanitize-1-r0-110-kw7g6
0.2886,Event,ADDED,eval-sanitize-1-r0-110.18d4a207568d48f9,reason=Completed count=1 msg=Job completed
0.2887,Event,ADDED,eval-sanitize-1-r0-111-b8qzx.18d4a1fe5e1cbfa7,"reason=FailedScheduling count=None msg=0/6 nodes are available: 6 node(s) had untolerated taint(s). no new claims to deallocate, preemption: 0/6 nodes are available: 6 Preemption is not helpful for scheduling."
0.2889,Event,ADDED,eval-sanitize-1-r0-111-b8qzx.18d4a2004d174da4,reason=Scheduled count=None msg=Successfully assigned compute/eval-sanitize-1-r0-111-b8qzx to kind-worker
0.2891,Event,ADDED,eval-sanitize-1-r0-111-b8qzx.18d4a20068712fb2,"reason=Pulled count=1 msg=Container image ""busybox:musl"" already present on machine"
0.2893,Event,ADDED,eval-sanitize-1-r0-111-b8qzx.18d4a2006a90d8df,reason=Created count=1 msg=Created container: task
0.2894,Event,ADDED,eval-sanitize-1-r0-111-b8qzx.18d4a20072130ac7,reason=Started count=1 msg=Started container task
0.2896,Event,ADDED,eval-sanitize-1-r0-111.18d4a1fe5e09691e,reason=SuccessfulCreate count=1 msg=Created pod: eval-sanitize-1-r0-111-b8qzx
0.2898,Event,ADDED,eval-sanitize-1-r0-111.18d4a205bbec8962,reason=Completed count=1 msg=Job completed
0.2901,Event,ADDED,eval-sanitize-1-r0-112-5cpgw.18d4a1fe99bcc643,"reason=FailedScheduling count=None msg=0/6 nodes are available: 6 node(s) had untolerated taint(s). no new claims to deallocate, preemption: 0/6 nodes are available: 6 Preemption is not helpful for scheduling."
0.2905,Event,ADDED,eval-sanitize-1-r0-112-5cpgw.18d4a2004cf2f3de,"reason=FailedScheduling count=None msg=0/6 nodes are available: 1 c_wall violated: 1 conflicting context pair(s) with node memory, 5 node(s) had untolerated taint(s). no new claims to deallocate, preemption: 0/6 nodes are available: 1 No preemption victims found for incoming pod, 5 Preemption is not helpful for scheduling."
0.2907,Event,ADDED,eval-sanitize-1-r0-112-5cpgw.18d4a20062b19f7a,reason=Scheduled count=None msg=Successfully assigned compute/eval-sanitize-1-r0-112-5cpgw to kind-worker5
0.2909,Event,ADDED,eval-sanitize-1-r0-112-5cpgw.18d4a2007d78c539,"reason=Pulled count=1 msg=Container image ""busybox:musl"" already present on machine"
0.291,Event,ADDED,eval-sanitize-1-r0-112-5cpgw.18d4a2007ec85093,reason=Created count=1 msg=Created container: task
0.2914,Event,ADDED,eval-sanitize-1-r0-112-5cpgw.18d4a20084d0a598,reason=Started count=1 msg=Started container task
0.2919,Event,ADDED,eval-sanitize-1-r0-112.18d4a1fe99b00c64,reason=SuccessfulCreate count=1 msg=Created pod: eval-sanitize-1-r0-112-5cpgw
0.292,Event,ADDED,eval-sanitize-1-r0-112.18d4a206e88cf48e,reason=Completed count=1 msg=Job completed
0.2926,Event,ADDED,eval-sanitize-1-r0-113-h26cn.18d4a1fed56dd33a,"reason=FailedScheduling count=None msg=0/6 nodes are available: 6 node(s) had untolerated taint(s). no new claims to deallocate, preemption: 0/6 nodes are available: 6 Preemption is not helpful for scheduling."
0.2928,Event,ADDED,eval-sanitize-1-r0-113-h26cn.18d4a2004d76c58b,"reason=FailedScheduling count=None msg=0/6 nodes are available: 1 c_wall violated: 2 conflicting context pair(s) with node memory, 5 node(s) had untolerated taint(s). no new claims to deallocate, preemption: 0/6 nodes are available: 1 No preemption victims found for incoming pod, 5 Preemption is not helpful for scheduling."
0.2929,Event,ADDED,eval-sanitize-1-r0-113-h26cn.18d4a20062be59ad,"reason=FailedScheduling count=None msg=0/6 nodes are available: 1 c_wall violated: 1 conflicting context pair(s) with node memory, 1 c_wall violated: 2 conflicting context pair(s) with node memory, 4 node(s) had untolerated taint(s). no new claims to deallocate, preemption: 0/6 nodes are available: 2 No preemption victims found for incoming pod, 4 Preemption is not helpful for scheduling."
0.2933,Event,ADDED,eval-sanitize-1-r0-113-h26cn.18d4a20081ad8f46,"reason=FailedScheduling count=None msg=0/6 nodes are available: 1 c_wall violated: 1 conflicting context pair(s) with node memory, 1 c_wall violated: 2 conflicting context pair(s) with node memory, 4 node(s) had untolerated taint(s). no new claims to deallocate, preemption: 0/6 nodes are available: 2 No preemption victims found for incoming pod, 4 Preemption is not helpful for scheduling."
0.2934,Event,ADDED,eval-sanitize-1-r0-113-h26cn.18d4a2008e9b8a7b,reason=Scheduled count=None msg=Successfully assigned compute/eval-sanitize-1-r0-113-h26cn to kind-worker4
0.2936,Event,ADDED,eval-sanitize-1-r0-113-h26cn.18d4a200acf462d9,"reason=Pulled count=1 msg=Container image ""busybox:musl"" already present on machine"
0.2937,Event,ADDED,eval-sanitize-1-r0-113-h26cn.18d4a200ae5df8f4,reason=Created count=1 msg=Created container: task
0.294,Event,ADDED,eval-sanitize-1-r0-113-h26cn.18d4a200b28782b3,reason=Started count=1 msg=Started container task
0.2942,Event,ADDED,eval-sanitize-1-r0-113.18d4a1fed5619649,reason=SuccessfulCreate count=1 msg=Created pod: eval-sanitize-1-r0-113-h26cn
0.2943,Event,ADDED,eval-sanitize-1-r0-113.18d4a2071a29f0cb,reason=Completed count=1 msg=Job completed
0.2945,Event,ADDED,eval-sanitize-1-r0-114-cxncl.18d4a1ff110a3416,"reason=FailedScheduling count=None msg=0/6 nodes are available: 6 node(s) had untolerated taint(s). no new claims to deallocate, preemption: 0/6 nodes are available: 6 Preemption is not helpful for scheduling."
0.2946,Event,ADDED,eval-sanitize-1-r0-114-cxncl.18d4a2004e356a60,"reason=FailedScheduling count=None msg=0/6 nodes are available: 1 c_wall violated: 1 conflicting context pair(s) with node memory, 5 node(s) had untolerated taint(s). no new claims to deallocate, preemption: 0/6 nodes are available: 1 No preemption victims found for incoming pod, 5 Preemption is not helpful for scheduling."
0.2948,Event,ADDED,eval-sanitize-1-r0-114-cxncl.18d4a20063dcba7b,"reason=FailedScheduling count=None msg=0/6 nodes are available: 2 c_wall violated: 1 conflicting context pair(s) with node memory, 4 node(s) had untolerated taint(s). no new claims to deallocate, preemption: 0/6 nodes are available: 2 No preemption victims found for incoming pod, 4 Preemption is not helpful for scheduling."
0.2949,Event,ADDED,eval-sanitize-1-r0-114-cxncl.18d4a20082cc1124,"reason=FailedScheduling count=None msg=0/6 nodes are available: 1 c_wall violated: 1 conflicting context pair(s) with node memory, 1 c_wall violated: 3 conflicting context pair(s) with node memory, 4 node(s) had untolerated taint(s). no new claims to deallocate, preemption: 0/6 nodes are available: 2 No preemption victims found for incoming pod, 4 Preemption is not helpful for scheduling."
0.2951,Event,ADDED,eval-sanitize-1-r0-114-cxncl.18d4a2008f0de580,reason=Scheduled count=None msg=Successfully assigned compute/eval-sanitize-1-r0-114-cxncl to kind-worker4
0.2953,Event,ADDED,eval-sanitize-1-r0-114-cxncl.18d4a200abf652f1,"reason=Pulled count=1 msg=Container image ""busybox:musl"" already present on machine"
0.2954,Event,ADDED,eval-sanitize-1-r0-114-cxncl.18d4a200ada4464f,reason=Created count=1 msg=Created container: task
0.2956,Event,ADDED,eval-sanitize-1-r0-114-cxncl.18d4a200b2876c38,reason=Started count=1 msg=Started container task
0.2958,Event,ADDED,eval-sanitize-1-r0-114.18d4a1ff10fd98cd,reason=SuccessfulCreate count=1 msg=Created pod: eval-sanitize-1-r0-114-cxncl
0.2959,Event,ADDED,eval-sanitize-1-r0-114.18d4a2076073470a,reason=Completed count=1 msg=Job completed
0.2961,Event,ADDED,eval-sanitize-1-r0-115-tm6jm.18d4a1ff4d65b297,"reason=FailedScheduling count=None msg=0/6 nodes are available: 6 node(s) had untolerated taint(s). no new claims to deallocate, preemption: 0/6 nodes are available: 6 Preemption is not helpful for scheduling."
0.2963,Event,ADDED,eval-sanitize-1-r0-115-tm6jm.18d4a2005190918f,"reason=FailedScheduling count=None msg=0/6 nodes are available: 1 c_wall violated: 1 conflicting context pair(s) with node memory, 5 node(s) had untolerated taint(s). no new claims to deallocate, preemption: 0/6 nodes are available: 1 No preemption victims found for incoming pod, 5 Preemption is not helpful for scheduling."
0.2964,Event,ADDED,eval-sanitize-1-r0-115-tm6jm.18d4a2006526e6f6,reason=Scheduled count=None msg=Successfully assigned compute/eval-sanitize-1-r0-115-tm6jm to kind-worker5
0.2966,Event,ADDED,eval-sanitize-1-r0-115-tm6jm.18d4a20082363fb9,"reason=Pulled count=1 msg=Container image ""busybox:musl"" already present on machine"
0.2968,Event,ADDED,eval-sanitize-1-r0-115-tm6jm.18d4a20083a634f4,reason=Created count=1 msg=Created container: task
0.2971,Event,ADDED,eval-sanitize-1-r0-115-tm6jm.18d4a200865bd984,reason=Started count=1 msg=Started container task
0.2973,Event,ADDED,eval-sanitize-1-r0-115.18d4a1ff4d5d26b0,reason=SuccessfulCreate count=1 msg=Created pod: eval-sanitize-1-r0-115-tm6jm
0.2975,Event,ADDED,eval-sanitize-1-r0-115.18d4a206ff453202,reason=Completed count=1 msg=Job completed
0.2978,Event,ADDED,eval-sanitize-1-r0-116-tn6gj.18d4a1ff880e061b,"reason=FailedScheduling count=None msg=0/6 nodes are available: 6 node(s) had untolerated taint(s). no new claims to deallocate, preemption: 0/6 nodes are available: 6 Preemption is not helpful for scheduling."
0.298,Event,ADDED,eval-sanitize-1-r0-116-tn6gj.18d4a20052298015,"reason=FailedScheduling count=None msg=0/6 nodes are available: 1 c_wall violated: 1 conflicting context pair(s) with node memory, 5 node(s) had untolerated taint(s). no new claims to deallocate, preemption: 0/6 nodes are available: 1 No preemption victims found for incoming pod, 5 Preemption is not helpful for scheduling."
0.2982,Event,ADDED,eval-sanitize-1-r0-116-tn6gj.18d4a20069e56241,reason=Scheduled count=None msg=Successfully assigned compute/eval-sanitize-1-r0-116-tn6gj to kind-worker5
0.2986,Event,ADDED,eval-sanitize-1-r0-116-tn6gj.18d4a200868fa860,"reason=Pulled count=1 msg=Container image ""busybox:musl"" already present on machine"
0.2987,Event,ADDED,eval-sanitize-1-r0-116-tn6gj.18d4a20088b1fe31,reason=Created count=1 msg=Created container: task
0.2989,Event,ADDED,eval-sanitize-1-r0-116-tn6gj.18d4a2008b69564d,reason=Started count=1 msg=Started container task
0.2991,Event,ADDED,eval-sanitize-1-r0-116.18d4a1ff88041fbf,reason=SuccessfulCreate count=1 msg=Created pod: eval-sanitize-1-r0-116-tn6gj
0.2994,Event,ADDED,eval-sanitize-1-r0-116.18d4a2071e4d9c44,reason=Completed count=1 msg=Job completed
0.2996,Event,ADDED,eval-sanitize-1-r0-117-jl6lr.18d4a1ffc721f80a,"reason=FailedScheduling count=None msg=0/6 nodes are available: 6 node(s) had untolerated taint(s). no new claims to deallocate, preemption: 0/6 nodes are available: 6 Preemption is not helpful for scheduling."
0.2997,Event,ADDED,eval-sanitize-1-r0-117-jl6lr.18d4a20052a0e8c7,"reason=FailedScheduling count=None msg=0/6 nodes are available: 1 c_wall violated: 1 conflicting context pair(s) with node memory, 5 node(s) had untolerated taint(s). no new claims to deallocate, preemption: 0/6 nodes are available: 1 No preemption victims found for incoming pod, 5 Preemption is not helpful for scheduling."
0.3,Event,ADDED,eval-sanitize-1-r0-117-jl6lr.18d4a2006a885db7,"reason=FailedScheduling count=None msg=0/6 nodes are available: 2 c_wall violated: 1 conflicting context pair(s) with node memory, 4 node(s) had untolerated taint(s). no new claims to deallocate, preemption: 0/6 nodes are available: 2 No preemption victims found for incoming pod, 4 Preemption is not helpful for scheduling."
0.3002,Event,ADDED,eval-sanitize-1-r0-117-jl6lr.18d4a20087774863,"reason=FailedScheduling count=None msg=0/6 nodes are available: 2 c_wall violated: 1 conflicting context pair(s) with node memory, 4 node(s) had untolerated taint(s). no new claims to deallocate, preemption: 0/6 nodes are available: 2 No preemption victims found for incoming pod, 4 Preemption is not helpful for scheduling."
0.3004,Event,ADDED,eval-sanitize-1-r0-117-jl6lr.18d4a20099792e67,"reason=FailedScheduling count=None msg=0/6 nodes are available: 1 c_wall violated: 1 conflicting context pair(s) with node memory, 1 c_wall violated: 2 conflicting context pair(s) with node memory, 4 node(s) had untolerated taint(s). no new claims to deallocate, preemption: 0/6 nodes are available: 2 No preemption victims found for incoming pod, 4 Preemption is not helpful for scheduling."
0.3007,Event,ADDED,eval-sanitize-1-r0-117-jl6lr.18d4a200d156ac3a,"reason=FailedScheduling count=None msg=0/6 nodes are available: 1 c_wall violated: 1 conflicting context pair(s) with node memory, 5 node(s) had untolerated taint(s). no new claims to deallocate, preemption: 0/6 nodes are available: 1 No preemption victims found for incoming pod, 5 Preemption is not helpful for scheduling."
0.3009,Event,ADDED,eval-sanitize-1-r0-117-jl6lr.18d4a20122fbc8e2,reason=Scheduled count=None msg=Successfully assigned compute/eval-sanitize-1-r0-117-jl6lr to kind-worker2
0.3011,Event,ADDED,eval-sanitize-1-r0-117-jl6lr.18d4a2013f9f5984,"reason=Pulled count=1 msg=Container image ""busybox:musl"" already present on machine"
0.3013,Event,ADDED,eval-sanitize-1-r0-117-jl6lr.18d4a20140f27ab7,reason=Created count=1 msg=Created container: task
0.3016,Event,ADDED,eval-sanitize-1-r0-117-jl6lr.18d4a20148d6197f,reason=Started count=1 msg=Started container task
0.3018,Event,ADDED,eval-sanitize-1-r0-117.18d4a1ffc71538d0,reason=SuccessfulCreate count=1 msg=Created pod: eval-sanitize-1-r0-117-jl6lr
0.3022,Event,ADDED,eval-sanitize-1-r0-117.18d4a207855bfbea,reason=Completed count=1 msg=Job completed
0.3025,Event,ADDED,eval-sanitize-1-r0-118-ctgmq.18d4a1ffffda3748,"reason=FailedScheduling count=None msg=0/6 nodes are available: 6 node(s) had untolerated taint(s). no new claims to deallocate, preemption: 0/6 nodes are available: 6 Preemption is not helpful for scheduling."
0.3026,Event,ADDED,eval-sanitize-1-r0-118-ctgmq.18d4a20053bfcd31,reason=Scheduled count=None msg=Successfully assigned compute/eval-sanitize-1-r0-118-ctgmq to kind-worker
0.3028,Event,ADDED,eval-sanitize-1-r0-118-ctgmq.18d4a2007250b315,"reason=Pulled count=1 msg=Container image ""busybox:musl"" already present on machine"
0.303,Event,ADDED,eval-sanitize-1-r0-118-ctgmq.18d4a2007418e197,reason=Created count=1 msg=Created container: task
0.3031,Event,ADDED,eval-sanitize-1-r0-118-ctgmq.18d4a200795eb0c8,reason=Started count=1 msg=Started container task
0.3033,Event,ADDED,eval-sanitize-1-r0-118.18d4a1ffffd1a2ed,reason=SuccessfulCreate count=1 msg=Created pod: eval-sanitize-1-r0-118-ctgmq
0.3035,Event,ADDED,eval-sanitize-1-r0-118.18d4a206b922916b,reason=Completed count=1 msg=Job completed
0.3036,Event,ADDED,eval-sanitize-1-r0-119-d25sg.18d4a20053e6e1d1,reason=Scheduled count=None msg=Successfully assigned compute/eval-sanitize-1-r0-119-d25sg to kind-worker
0.3038,Event,ADDED,eval-sanitize-1-r0-119-d25sg.18d4a20072b4b394,"reason=Pulled count=1 msg=Container image ""busybox:musl"" already present on machine"
0.304,Event,ADDED,eval-sanitize-1-r0-119-d25sg.18d4a20074ae83cc,reason=Created count=1 msg=Created container: task
0.3041,Event,ADDED,eval-sanitize-1-r0-119-d25sg.18d4a2007a009296,reason=Started count=1 msg=Started container task
0.3043,Event,ADDED,eval-sanitize-1-r0-119.18d4a20047c528cf,reason=SuccessfulCreate count=1 msg=Created pod: eval-sanitize-1-r0-119-d25sg
0.3045,Event,ADDED,eval-sanitize-1-r0-119.18d4a205bd12f6ce,reason=Completed count=1 msg=Job completed
0.3046,Event,ADDED,eval-sanitize-1-r0-120-tlzzd.18d4a200aca3807a,reason=Scheduled count=None msg=Successfully assigned compute/eval-sanitize-1-r0-120-tlzzd to kind-worker5
0.3048,Event,ADDED,eval-sanitize-1-r0-120-tlzzd.18d4a200c8019c6c,"reason=Pulled count=1 msg=Container image ""busybox:musl"" already present on machine"
0.3049,Event,ADDED,eval-sanitize-1-r0-120-tlzzd.18d4a200c94d5d87,reason=Created count=1 msg=Created container: task
0.3052,Event,ADDED,eval-sanitize-1-r0-120-tlzzd.18d4a200cd59dbb0,reason=Started count=1 msg=Started container task
0.3054,Event,ADDED,eval-sanitize-1-r0-120.18d4a200a6f52e7b,reason=SuccessfulCreate count=1 msg=Created pod: eval-sanitize-1-r0-120-tlzzd
0.3056,Event,ADDED,eval-sanitize-1-r0-120.18d4a2074fbaa8e3,reason=Completed count=1 msg=Job completed
0.3058,Event,ADDED,eval-sanitize-1-r0-121-78tdc.18d4a2011c757ba5,"reason=FailedScheduling count=None msg=0/6 nodes are available: 6 node(s) had untolerated taint(s). no new claims to deallocate, preemption: 0/6 nodes are available: 6 Preemption is not helpful for scheduling."
0.306,Event,ADDED,eval-sanitize-1-r0-121-78tdc.18d4a201230b01f3,"reason=FailedScheduling count=None msg=0/6 nodes are available: 1 c_wall violated: 1 conflicting context pair(s) with node memory, 5 node(s) had untolerated taint(s). no new claims to deallocate, preemption: 0/6 nodes are available: 1 No preemption victims found for incoming pod, 5 Preemption is not helpful for scheduling."
0.3062,Event,ADDED,eval-sanitize-1-r0-121-78tdc.18d4a2012433d5f5,"reason=FailedScheduling count=None msg=0/6 nodes are available: 1 c_wall violated: 1 conflicting context pair(s) with node memory, 5 node(s) had untolerated taint(s). no new claims to deallocate, preemption: 0/6 nodes are available: 1 No preemption victims found for incoming pod, 5 Preemption is not helpful for scheduling."
0.3064,Event,ADDED,eval-sanitize-1-r0-121-78tdc.18d4a205ad151879,reason=Scheduled count=None msg=Successfully assigned compute/eval-sanitize-1-r0-121-78tdc to kind-worker
0.3066,Event,ADDED,eval-sanitize-1-r0-121-78tdc.18d4a205c79d24d5,"reason=Pulled count=1 msg=Container image ""busybox:musl"" already present on machine"
0.3068,Event,ADDED,eval-sanitize-1-r0-121-78tdc.18d4a205c9bb7058,reason=Created count=1 msg=Created container: task
0.3071,Event,ADDED,eval-sanitize-1-r0-121-78tdc.18d4a205d2aaf8bf,reason=Started count=1 msg=Started container task
0.3072,Event,ADDED,eval-sanitize-1-r0-121.18d4a2011c67c00a,reason=SuccessfulCreate count=1 msg=Created pod: eval-sanitize-1-r0-121-78tdc
0.3074,Event,ADDED,eval-sanitize-1-r0-121.18d4a20b54ee9df4,reason=Completed count=1 msg=Job completed
0.3076,Event,ADDED,eval-sanitize-1-r0-122-8dfjm.18d4a201570c8466,reason=Scheduled count=None msg=Successfully assigned compute/eval-sanitize-1-r0-122-8dfjm to kind-worker2
0.308,Event,ADDED,eval-sanitize-1-r0-122-8dfjm.18d4a201738eb368,"reason=Pulled count=1 msg=Container image ""busybox:musl"" already present on machine"
0.3082,Event,ADDED,eval-sanitize-1-r0-122-8dfjm.18d4a20175367957,reason=Created count=1 msg=Created container: task
0.3084,Event,ADDED,eval-sanitize-1-r0-122-8dfjm.18d4a2017eff78a1,reason=Started count=1 msg=Started container task
0.3085,Event,ADDED,eval-sanitize-1-r0-122.18d4a201568a2a94,reason=SuccessfulCreate count=1 msg=Created pod: eval-sanitize-1-r0-122-8dfjm
0.309,Event,ADDED,eval-sanitize-1-r0-122.18d4a20783e15f22,reason=Completed count=1 msg=Job completed
0.3092,Event,ADDED,eval-sanitize-1-r0-123-pfdnr.18d4a20180ac51df,"reason=FailedScheduling count=None msg=0/6 nodes are available: 6 node(s) had untolerated taint(s). no new claims to deallocate, preemption: 0/6 nodes are available: 6 Preemption is not helpful for scheduling."
0.3094,Event,ADDED,eval-sanitize-1-r0-123-pfdnr.18d4a205ad4666f0,"reason=FailedScheduling count=None msg=0/6 nodes are available: 1 c_wall violated: 1 conflicting context pair(s) with node memory, 5 node(s) had untolerated taint(s). no new claims to deallocate, preemption: 0/6 nodes are available: 1 No preemption victims found for incoming pod, 5 Preemption is not helpful for scheduling."
0.3096,Event,ADDED,eval-sanitize-1-r0-123-pfdnr.18d4a205c46e5f0f,"reason=FailedScheduling count=None msg=0/6 nodes are available: 1 c_wall violated: 2 conflicting context pair(s) with node memory, 5 node(s) had untolerated taint(s). no new claims to deallocate, preemption: 0/6 nodes are available: 1 No preemption victims found for incoming pod, 5 Preemption is not helpful for scheduling."
0.3098,Event,ADDED,eval-sanitize-1-r0-123-pfdnr.18d4a205d183161b,"reason=FailedScheduling count=None msg=0/6 nodes are available: 1 c_wall violated: 2 conflicting context pair(s) with node memory, 5 node(s) had untolerated taint(s). no new claims to deallocate, preemption: 0/6 nodes are available: 1 No preemption victims found for incoming pod, 5 Preemption is not helpful for scheduling."
0.31,Event,ADDED,eval-sanitize-1-r0-123-pfdnr.18d4a2060d13d5ec,"reason=FailedScheduling count=None msg=0/6 nodes are available: 1 c_wall violated: 3 conflicting context pair(s) with node memory, 5 node(s) had untolerated taint(s). no new claims to deallocate, preemption: 0/6 nodes are available: 1 No preemption victims found for incoming pod, 5 Preemption is not helpful for scheduling."
0.3102,Event,ADDED,eval-sanitize-1-r0-123-pfdnr.18d4a2066086d874,"reason=FailedScheduling count=None msg=0/6 nodes are available: 1 c_wall violated: 1 conflicting context pair(s) with node memory, 5 node(s) had untolerated taint(s). no new claims to deallocate, preemption: 0/6 nodes are available: 1 No preemption victims found for incoming pod, 5 Preemption is not helpful for scheduling."
0.3104,Event,ADDED,eval-sanitize-1-r0-123-pfdnr.18d4a206680bda3c,"reason=FailedScheduling count=None msg=0/6 nodes are available: 1 c_wall violated: 1 conflicting context pair(s) with node memory, 5 node(s) had untolerated taint(s). no new claims to deallocate, preemption: 0/6 nodes are available: 1 No preemption victims found for incoming pod, 5 Preemption is not helpful for scheduling."
0.3106,Event,ADDED,eval-sanitize-1-r0-123-pfdnr.18d4a206e10aa2d2,reason=Scheduled count=None msg=Successfully assigned compute/eval-sanitize-1-r0-123-pfdnr to kind-worker5
0.3109,Event,ADDED,eval-sanitize-1-r0-123-pfdnr.18d4a206fbeec51d,"reason=Pulled count=1 msg=Container image ""busybox:musl"" already present on machine"
0.311,Event,ADDED,eval-sanitize-1-r0-123-pfdnr.18d4a206fe04f4e9,reason=Created count=1 msg=Created container: task
0.3112,Event,ADDED,eval-sanitize-1-r0-123-pfdnr.18d4a20701d864ab,reason=Started count=1 msg=Started container task
0.3114,Event,ADDED,eval-sanitize-1-r0-123.18d4a20180a23250,reason=SuccessfulCreate count=1 msg=Created pod: eval-sanitize-1-r0-123-pfdnr
0.3115,Event,ADDED,eval-sanitize-1-r0-123.18d4a20d2b4d9867,reason=Completed count=1 msg=Job completed
0.3117,Event,ADDED,eval-sanitize-1-r0-124-4ppkb.18d4a201b3424449,"reason=FailedScheduling count=None msg=0/6 nodes are available: 6 node(s) had untolerated taint(s). no new claims to deallocate, preemption: 0/6 nodes are available: 6 Preemption is not helpful for scheduling."
0.3118,Event,ADDED,eval-sanitize-1-r0-124-4ppkb.18d4a205ae334b52,reason=Scheduled count=None msg=Successfully assigned compute/eval-sanitize-1-r0-124-4ppkb to kind-worker
0.312,Event,ADDED,eval-sanitize-1-r0-124-4ppkb.18d4a205d2457932,"reason=Pulled count=1 msg=Container image ""busybox:musl"" already present on machine"
0.3122,Event,ADDED,eval-sanitize-1-r0-124-4ppkb.18d4a205d5212a92,reason=Created count=1 msg=Created container: task
0.3123,Event,ADDED,eval-sanitize-1-r0-124-4ppkb.18d4a205da17bc21,reason=Started count=1 msg=Started container task
0.3126,Event,ADDED,eval-sanitize-1-r0-124.18d4a201b3349ce0,reason=SuccessfulCreate count=1 msg=Created pod: eval-sanitize-1-r0-124-4ppkb
0.3129,Event,ADDED,eval-sanitize-1-r0-124.18d4a20b54e2654e,reason=Completed count=1 msg=Job completed
0.3131,Event,ADDED,eval-sanitize-1-r0-125-thfdn.18d4a201d548a120,"reason=FailedScheduling count=None msg=0/6 nodes are available: 6 node(s) had untolerated taint(s). no new claims to deallocate, preemption: 0/6 nodes are available: 6 Preemption is not helpful for scheduling."
0.3132,Event,ADDED,eval-sanitize-1-r0-125-thfdn.18d4a205ae66dbdd,reason=Scheduled count=None msg=Successfully assigned compute/eval-sanitize-1-r0-125-thfdn to kind-worker
0.3134,Event,ADDED,eval-sanitize-1-r0-125-thfdn.18d4a205d2693c59,"reason=Pulled count=1 msg=Container image ""busybox:musl"" already present on machine"
0.3137,Event,ADDED,eval-sanitize-1-r0-125-thfdn.18d4a205d56fd353,reason=Created count=1 msg=Created container: task
0.3139,Event,ADDED,eval-sanitize-1-r0-125-thfdn.18d4a205da18e309,reason=Started count=1 msg=Started container task
0.3141,Event,ADDED,eval-sanitize-1-r0-125.18d4a201d53ede3e,reason=SuccessfulCreate count=1 msg=Created pod: eval-sanitize-1-r0-125-thfdn
0.3145,Event,ADDED,eval-sanitize-1-r0-125.18d4a20b52401335,reason=Completed count=1 msg=Job completed
0.3147,Event,ADDED,eval-sanitize-1-r0-126-hpdbr.18d4a201f1d09e03,"reason=FailedScheduling count=None msg=0/6 nodes are available: 6 node(s) had untolerated taint(s). no new claims to deallocate, preemption: 0/6 nodes are available: 6 Preemption is not helpful for scheduling."
0.3148,Event,ADDED,eval-sanitize-1-r0-126-hpdbr.18d4a205aea96af6,reason=Scheduled count=None msg=Successfully assigned compute/eval-sanitize-1-r0-126-hpdbr to kind-worker
0.315,Event,ADDED,eval-sanitize-1-r0-126-hpdbr.18d4a205ca9cf745,"reason=Pulled count=1 msg=Container image ""busybox:musl"" already present on machine"
0.3153,Event,ADDED,eval-sanitize-1-r0-126-hpdbr.18d4a205cc13a08e,reason=Created count=1 msg=Created container: task
0.3154,Event,ADDED,eval-sanitize-1-r0-126-hpdbr.18d4a205d3258ac4,reason=Started count=1 msg=Started container task
0.3156,Event,ADDED,eval-sanitize-1-r0-126.18d4a201f1c6e082,reason=SuccessfulCreate count=1 msg=Created pod: eval-sanitize-1-r0-126-hpdbr
0.3158,Event,ADDED,eval-sanitize-1-r0-126.18d4a20b52b7d76e,reason=Completed count=1 msg=Job completed
0.3159,Event,ADDED,eval-sanitize-1-r0-127-jslxp.18d4a202215c4a7f,"reason=FailedScheduling count=None msg=0/6 nodes are available: 6 node(s) had untolerated taint(s). no new claims to deallocate, preemption: 0/6 nodes are available: 6 Preemption is not helpful for scheduling."
0.3161,Event,ADDED,eval-sanitize-1-r0-127-jslxp.18d4a205ae795bce,"reason=FailedScheduling count=None msg=0/6 nodes are available: 1 c_wall violated: 1 conflicting context pair(s) with node memory, 5 node(s) had untolerated taint(s). no new claims to deallocate, preemption: 0/6 nodes are available: 1 No preemption victims found for incoming pod, 5 Preemption is not helpful for scheduling."
0.3163,Event,ADDED,eval-sanitize-1-r0-127-jslxp.18d4a205c56a8161,"reason=FailedScheduling count=None msg=0/6 nodes are available: 1 c_wall violated: 1 conflicting context pair(s) with node memory, 5 node(s) had untolerated taint(s). no new claims to deallocate, preemption: 0/6 nodes are available: 1 No preemption victims found for incoming pod, 5 Preemption is not helpful for scheduling."
0.3164,Event,ADDED,eval-sanitize-1-r0-127-jslxp.18d4a205f933cb9e,"reason=FailedScheduling count=None msg=0/6 nodes are available: 1 c_wall violated: 1 conflicting context pair(s) with node memory, 5 node(s) had untolerated taint(s). no new claims to deallocate, preemption: 0/6 nodes are available: 1 No preemption victims found for incoming pod, 5 Preemption is not helpful for scheduling."
0.3166,Event,ADDED,eval-sanitize-1-r0-127-jslxp.18d4a20606de0410,"reason=FailedScheduling count=None msg=0/6 nodes are available: 1 c_wall violated: 2 conflicting context pair(s) with node memory, 5 node(s) had untolerated taint(s). no new claims to deallocate, preemption: 0/6 nodes are available: 1 No preemption victims found for incoming pod, 5 Preemption is not helpful for scheduling."
0.3167,Event,ADDED,eval-sanitize-1-r0-127-jslxp.18d4a2060d489f30,"reason=FailedScheduling count=None msg=0/6 nodes are available: 1 c_wall violated: 2 conflicting context pair(s) with node memory, 5 node(s) had untolerated taint(s). no new claims to deallocate, preemption: 0/6 nodes are available: 1 No preemption victims found for incoming pod, 5 Preemption is not helpful for scheduling."
0.3169,Event,ADDED,eval-sanitize-1-r0-127-jslxp.18d4a2065aa54cef,reason=Scheduled count=None msg=Successfully assigned compute/eval-sanitize-1-r0-127-jslxp to kind-worker3
0.3171,Event,ADDED,eval-sanitize-1-r0-127-jslxp.18d4a206812aea40,"reason=Pulled count=1 msg=Container image ""busybox:musl"" already present on machine"
0.3172,Event,ADDED,eval-sanitize-1-r0-127-jslxp.18d4a206831c3224,reason=Created count=1 msg=Created container: task
0.3174,Event,ADDED,eval-sanitize-1-r0-127-jslxp.18d4a206875b25ca,reason=Started count=1 msg=Started container task
0.3176,Event,ADDED,eval-sanitize-1-r0-127.18d4a20221572fb0,reason=SuccessfulCreate count=1 msg=Created pod: eval-sanitize-1-r0-127-jslxp
0.3177,Event,ADDED,eval-sanitize-1-r0-127.18d4a20c9015b15d,reason=Completed count=1 msg=Job completed
0.3179,Event,ADDED,eval-sanitize-1-r0-128-dqczf.18d4a202537d301b,"reason=FailedScheduling count=None msg=0/6 nodes are available: 6 node(s) had untolerated taint(s). no new claims to deallocate, preemption: 0/6 nodes are available: 6 Preemption is not helpful for scheduling."
0.318,Event,ADDED,eval-sanitize-1-r0-128-dqczf.18d4a205b25af938,"reason=FailedScheduling count=None msg=0/6 nodes are available: 1 c_wall violated: 1 conflicting context pair(s) with node memory, 5 node(s) had untolerated taint(s). no new claims to deallocate, preemption: 0/6 nodes are available: 1 No preemption victims found for incoming pod, 5 Preemption is not helpful for scheduling."
0.3182,Event,ADDED,eval-sanitize-1-r0-128-dqczf.18d4a205c8d4c990,"reason=FailedScheduling count=None msg=0/6 nodes are available: 1 c_wall violated: 1 conflicting context pair(s) with node memory, 5 node(s) had untolerated taint(s). no new claims to deallocate, preemption: 0/6 nodes are available: 1 No preemption victims found for incoming pod, 5 Preemption is not helpful for scheduling."
0.3184,Event,ADDED,eval-sanitize-1-r0-128-dqczf.18d4a205ff475051,reason=Scheduled count=None msg=Successfully assigned compute/eval-sanitize-1-r0-128-dqczf to kind-worker4
0.3186,Event,ADDED,eval-sanitize-1-r0-128-dqczf.18d4a20626b5b616,"reason=Pulled count=1 msg=Container image ""busybox:musl"" already present on machine"
0.3187,Event,ADDED,eval-sanitize-1-r0-128-dqczf.18d4a20628e4516f,reason=Created count=1 msg=Created container: task
0.319,Event,ADDED,eval-sanitize-1-r0-128-dqczf.18d4a2062e2e9ecc,reason=Started count=1 msg=Started container task
0.3192,Event,ADDED,eval-sanitize-1-r0-128.18d4a2025370554d,reason=SuccessfulCreate count=1 msg=Created pod: eval-sanitize-1-r0-128-dqczf
0.3198,Event,ADDED,eval-sanitize-1-r0-128.18d4a20c55261a4e,reason=Completed count=1 msg=Job completed
0.32,Event,ADDED,eval-sanitize-1-r0-129-lhfnh.18d4a2028f2249e4,"reason=FailedScheduling count=None msg=0/6 nodes are available: 6 node(s) had untolerated taint(s). no new claims to deallocate, preemption: 0/6 nodes are available: 6 Preemption is not helpful for scheduling."
0.3201,Event,ADDED,eval-sanitize-1-r0-129-lhfnh.18d4a205b31a7bc5,"reason=FailedScheduling count=None msg=0/6 nodes are available: 1 c_wall violated: 2 conflicting context pair(s) with node memory, 5 node(s) had untolerated taint(s). no new claims to deallocate, preemption: 0/6 nodes are available: 1 No preemption victims found for incoming pod, 5 Preemption is not helpful for scheduling."
0.3204,Event,ADDED,eval-sanitize-1-r0-129-lhfnh.18d4a205c9176a3e,"reason=FailedScheduling count=None msg=0/6 nodes are available: 1 c_wall violated: 2 conflicting context pair(s) with node memory, 5 node(s) had untolerated taint(s). no new claims to deallocate, preemption: 0/6 nodes are available: 1 No preemption victims found for incoming pod, 5 Preemption is not helpful for scheduling."
0.3205,Event,ADDED,eval-sanitize-1-r0-129-lhfnh.18d4a205fcd937dc,"reason=FailedScheduling count=None msg=0/6 nodes are available: 1 c_wall violated: 3 conflicting context pair(s) with node memory, 5 node(s) had untolerated taint(s). no new claims to deallocate, preemption: 0/6 nodes are available: 1 No preemption victims found for incoming pod, 5 Preemption is not helpful for scheduling."
0.3207,Event,ADDED,eval-sanitize-1-r0-129-lhfnh.18d4a20608873589,"reason=FailedScheduling count=None msg=0/6 nodes are available: 1 c_wall violated: 3 conflicting context pair(s) with node memory, 5 node(s) had untolerated taint(s). no new claims to deallocate, preemption: 0/6 nodes are available: 1 No preemption victims found for incoming pod, 5 Preemption is not helpful for scheduling."
0.321,Event,ADDED,eval-sanitize-1-r0-129-lhfnh.18d4a20667143b95,"reason=FailedScheduling count=None msg=0/6 nodes are available: 1 c_wall violated: 1 conflicting context pair(s) with node memory, 5 node(s) had untolerated taint(s). no new claims to deallocate, preemption: 0/6 nodes are available: 1 No preemption victims found for incoming pod, 5 Preemption is not helpful for scheduling."
0.3211,Event,ADDED,eval-sanitize-1-r0-129-lhfnh.18d4a206dd0db2da,reason=Scheduled count=None msg=Successfully assigned compute/eval-sanitize-1-r0-129-lhfnh to kind-worker5
0.3213,Event,ADDED,eval-sanitize-1-r0-129-lhfnh.18d4a206fa9ff311,"reason=Pulled count=1 msg=Container image ""busybox:musl"" already present on machine"
0.3215,Event,ADDED,eval-sanitize-1-r0-129-lhfnh.18d4a206fcc6c1fa,reason=Created count=1 msg=Created container: task
0.3216,Event,ADDED,eval-sanitize-1-r0-129-lhfnh.18d4a20700cc95d0,reason=Started count=1 msg=Started container task
0.3218,Event,ADDED,eval-sanitize-1-r0-129.18d4a2028f171087,reason=SuccessfulCreate count=1 msg=Created pod: eval-sanitize-1-r0-129-lhfnh
0.322,Event,ADDED,eval-sanitize-1-r0-129.18d4a20d1f7fea1c,reason=Completed count=1 msg=Job completed
0.3221,Event,ADDED,eval-sanitize-1-r0-130-lz4lr.18d4a202cacfceb9,"reason=FailedScheduling count=None msg=0/6 nodes are available: 6 node(s) had untolerated taint(s). no new claims to deallocate, preemption: 0/6 nodes are available: 6 Preemption is not helpful for scheduling."
0.3223,Event,ADDED,eval-sanitize-1-r0-130-lz4lr.18d4a205b39d9e67,"reason=FailedScheduling count=None msg=0/6 nodes are available: 1 c_wall violated: 2 conflicting context pair(s) with node memory, 5 node(s) had untolerated taint(s). no new claims to deallocate, preemption: 0/6 nodes are available: 1 No preemption victims found for incoming pod, 5 Preemption is not helpful for scheduling."
0.3225,Event,ADDED,eval-sanitize-1-r0-130-lz4lr.18d4a205c94847a9,"reason=FailedScheduling count=None msg=0/6 nodes are available: 1 c_wall violated: 2 conflicting context pair(s) with node memory, 5 node(s) had untolerated taint(s). no new claims to deallocate, preemption: 0/6 nodes are available: 1 No preemption victims found for incoming pod, 5 Preemption is not helpful for scheduling."
0.3226,Event,ADDED,eval-sanitize-1-r0-130-lz4lr.18d4a2060037fcab,reason=Scheduled count=None msg=Successfully assigned compute/eval-sanitize-1-r0-130-lz4lr to kind-worker4
0.3228,Event,ADDED,eval-sanitize-1-r0-130-lz4lr.18d4a20626933a3a,"reason=Pulled count=1 msg=Container image ""busybox:musl"" already present on machine"
0.323,Event,ADDED,eval-sanitize-1-r0-130-lz4lr.18d4a206283d9389,reason=Created count=1 msg=Created container: task
0.3231,Event,ADDED,eval-sanitize-1-r0-130-lz4lr.18d4a2062e2de4c0,reason=Started count=1 msg=Started container task
0.3233,Event,ADDED,eval-sanitize-1-r0-130.18d4a202cac34f03,reason=SuccessfulCreate count=1 msg=Created pod: eval-sanitize-1-r0-130-lz4lr
0.3235,Event,ADDED,eval-sanitize-1-r0-130.18d4a20c8424edae,reason=Completed count=1 msg=Job completed
0.3236,Event,ADDED,eval-sanitize-1-r0-131-lqs5r.18d4a20306251907,"reason=FailedScheduling count=None msg=0/6 nodes are available: 6 node(s) had untolerated taint(s). no new claims to deallocate, preemption: 0/6 nodes are available: 6 Preemption is not helpful for scheduling."
0.3238,Event,ADDED,eval-sanitize-1-r0-131-lqs5r.18d4a205b420963e,"reason=FailedScheduling count=None msg=0/6 nodes are available: 1 c_wall violated: 1 conflicting context pair(s) with node memory, 5 node(s) had untolerated taint(s). no new claims to deallocate, preemption: 0/6 nodes are available: 1 No preemption victims found for incoming pod, 5 Preemption is not helpful for scheduling."
0.324,Event,ADDED,eval-sanitize-1-r0-131-lqs5r.18d4a205ca553c63,"reason=FailedScheduling count=None msg=0/6 nodes are available: 1 c_wall violated: 1 conflicting context pair(s) with node memory, 5 node(s) had untolerated taint(s). no new claims to deallocate, preemption: 0/6 nodes are available: 1 No preemption victims found for incoming pod, 5 Preemption is not helpful for scheduling."
0.3241,Event,ADDED,eval-sanitize-1-r0-131-lqs5r.18d4a20600370c74,"reason=FailedScheduling count=None msg=0/6 nodes are available: 1 c_wall violated: 2 conflicting context pair(s) with node memory, 5 node(s) had untolerated taint(s). no new claims to deallocate, preemption: 0/6 nodes are available: 1 No preemption victims found for incoming pod, 5 Preemption is not helpful for scheduling."
0.3243,Event,ADDED,eval-sanitize-1-r0-131-lqs5r.18d4a20608c3aed1,"reason=FailedScheduling count=None msg=0/6 nodes are available: 1 c_wall violated: 2 conflicting context pair(s) with node memory, 5 node(s) had untolerated taint(s). no new claims to deallocate, preemption: 0/6 nodes are available: 1 No preemption victims found for incoming pod, 5 Preemption is not helpful for scheduling."
0.3244,Event,ADDED,eval-sanitize-1-r0-131-lqs5r.18d4a2065b9a691f,reason=Scheduled count=None msg=Successfully assigned compute/eval-sanitize-1-r0-131-lqs5r to kind-worker3
0.3246,Event,ADDED,eval-sanitize-1-r0-131-lqs5r.18d4a206813ed4f9,"reason=Pulled count=1 msg=Container image ""busybox:musl"" already present on machine"
0.3248,Event,ADDED,eval-sanitize-1-r0-131-lqs5r.18d4a20683c1baa3,reason=Created count=1 msg=Created container: task
0.3249,Event,ADDED,eval-sanitize-1-r0-131-lqs5r.18d4a20688497a6a,reason=Started count=1 msg=Started container task
0.3251,Event,ADDED,eval-sanitize-1-r0-131.18d4a2030619b8ca,reason=SuccessfulCreate count=1 msg=Created pod: eval-sanitize-1-r0-131-lqs5r
0.3253,Event,ADDED,eval-sanitize-1-r0-131.18d4a20d0d272a26,reason=Completed count=1 msg=Job completed
0.3254,Event,ADDED,eval-sanitize-1-r0-132-zcswb.18d4a20341d398a8,"reason=FailedScheduling count=None msg=0/6 nodes are available: 6 node(s) had untolerated taint(s). no new claims to deallocate, preemption: 0/6 nodes are available: 6 Preemption is not helpful for scheduling."
0.3256,Event,ADDED,eval-sanitize-1-r0-132-zcswb.18d4a205b73336bc,"reason=FailedScheduling count=None msg=0/6 nodes are available: 1 c_wall violated: 2 conflicting context pair(s) with node memory, 5 node(s) had untolerated taint(s). no new claims to deallocate, preemption: 0/6 nodes are available: 1 No preemption victims found for incoming pod, 5 Preemption is not helpful for scheduling."
0.3257,Event,ADDED,eval-sanitize-1-r0-132-zcswb.18d4a205cb4176a3,"reason=FailedScheduling count=None msg=0/6 nodes are available: 1 c_wall violated: 2 conflicting context pair(s) with node memory, 5 node(s) had untolerated taint(s). no new claims to deallocate, preemption: 0/6 nodes are available: 1 No preemption victims found for incoming pod, 5 Preemption is not helpful for scheduling."
0.3259,Event,ADDED,eval-sanitize-1-r0-132-zcswb.18d4a2060291d0d4,"reason=FailedScheduling count=None msg=0/6 nodes are available: 1 c_wall violated: 1 conflicting context pair(s) with node memory, 5 node(s) had untolerated taint(s). no new claims to deallocate, preemption: 0/6 nodes are available: 1 No preemption victims found for incoming pod, 5 Preemption is not helpful for scheduling."
0.3261,Event,ADDED,eval-sanitize-1-r0-132-zcswb.18d4a20608efe4bb,"reason=FailedScheduling count=None msg=0/6 nodes are available: 1 c_wall violated: 1 conflicting context pair(s) with node memory, 5 node(s) had untolerated taint(s). no new claims to deallocate, preemption: 0/6 nodes are available: 1 No preemption victims found for incoming pod, 5 Preemption is not helpful for scheduling."
0.3262,Event,ADDED,eval-sanitize-1-r0-132-zcswb.18d4a206dd3fdf19,reason=Scheduled count=None msg=Successfully assigned compute/eval-sanitize-1-r0-132-zcswb to kind-worker5
0.3264,Event,ADDED,eval-sanitize-1-r0-132-zcswb.18d4a206fb29db29,"reason=Pulled count=1 msg=Container image ""busybox:musl"" already present on machine"
0.3266,Event,ADDED,eval-sanitize-1-r0-132-zcswb.18d4a206fd544e3d,reason=Created count=1 msg=Created container: task
0.3267,Event,ADDED,eval-sanitize-1-r0-132-zcswb.18d4a20701d84b00,reason=Started count=1 msg=Started container task
0.3269,Event,ADDED,eval-sanitize-1-r0-132.18d4a20341c778f8,reason=SuccessfulCreate count=1 msg=Created pod: eval-sanitize-1-r0-132-zcswb
0.3273,Event,ADDED,eval-sanitize-1-r0-132.18d4a20d22275c4c,reason=Completed count=1 msg=Job completed
0.3276,Event,ADDED,eval-sanitize-1-r0-133-x6n68.18d4a2037d6f6c82,"reason=FailedScheduling count=None msg=0/6 nodes are available: 6 node(s) had untolerated taint(s). no new claims to deallocate, preemption: 0/6 nodes are available: 6 Preemption is not helpful for scheduling."
0.3277,Event,ADDED,eval-sanitize-1-r0-133-x6n68.18d4a205baeb2ae4,"reason=FailedScheduling count=None msg=0/6 nodes are available: 1 c_wall violated: 2 conflicting context pair(s) with node memory, 5 node(s) had untolerated taint(s). no new claims to deallocate, preemption: 0/6 nodes are available: 1 No preemption victims found for incoming pod, 5 Preemption is not helpful for scheduling."
0.3281,Event,ADDED,eval-sanitize-1-r0-133-x6n68.18d4a205cb8e3051,"reason=FailedScheduling count=None msg=0/6 nodes are available: 1 c_wall violated: 2 conflicting context pair(s) with node memory, 5 node(s) had untolerated taint(s). no new claims to deallocate, preemption: 0/6 nodes are available: 1 No preemption victims found for incoming pod, 5 Preemption is not helpful for scheduling."
0.3283,Event,ADDED,eval-sanitize-1-r0-133-x6n68.18d4a2060474b0ae,"reason=FailedScheduling count=None msg=0/6 nodes are available: 1 c_wall violated: 3 conflicting context pair(s) with node memory, 5 node(s) had untolerated taint(s). no new claims to deallocate, preemption: 0/6 nodes are available: 1 No preemption victims found for incoming pod, 5 Preemption is not helpful for scheduling."
0.3285,Event,ADDED,eval-sanitize-1-r0-133-x6n68.18d4a2060a6b8a05,"reason=FailedScheduling count=None msg=0/6 nodes are available: 1 c_wall violated: 3 conflicting context pair(s) with node memory, 5 node(s) had untolerated taint(s). no new claims to deallocate, preemption: 0/6 nodes are available: 1 No preemption victims found for incoming pod, 5 Preemption is not helpful for scheduling."
0.3289,Event,ADDED,eval-sanitize-1-r0-133-x6n68.18d4a20667a0f509,"reason=FailedScheduling count=None msg=0/6 nodes are available: 1 c_wall violated: 1 conflicting context pair(s) with node memory, 5 node(s) had untolerated taint(s). no new claims to deallocate, preemption: 0/6 nodes are available: 1 No preemption victims found for incoming pod, 5 Preemption is not helpful for scheduling."
0.3291,Event,ADDED,eval-sanitize-1-r0-133-x6n68.18d4a206dd8819ff,reason=Scheduled count=None msg=Successfully assigned compute/eval-sanitize-1-r0-133-x6n68 to kind-worker5
0.3292,Event,ADDED,eval-sanitize-1-r0-133-x6n68.18d4a206fc0c8c7b,"reason=Pulled count=1 msg=Container image ""busybox:musl"" already present on machine"
0.3294,Event,ADDED,eval-sanitize-1-r0-133-x6n68.18d4a206fe5b3c57,reason=Created count=1 msg=Created container: task
0.3298,Event,ADDED,eval-sanitize-1-r0-133-x6n68.18d4a20701d9514e,reason=Started count=1 msg=Started container task
0.3299,Event,ADDED,eval-sanitize-1-r0-133.18d4a2037d60ae05,reason=SuccessfulCreate count=1 msg=Created pod: eval-sanitize-1-r0-133-x6n68
0.3303,Event,ADDED,eval-sanitize-1-r0-133.18d4a20d2b315a85,reason=Completed count=1 msg=Job completed
0.3306,Event,ADDED,eval-sanitize-1-r0-134-hx6pk.18d4a203b9760b0e,"reason=FailedScheduling count=None msg=0/6 nodes are available: 6 node(s) had untolerated taint(s). no new claims to deallocate, preemption: 0/6 nodes are available: 6 Preemption is not helpful for scheduling."
0.3308,Event,ADDED,eval-sanitize-1-r0-134-hx6pk.18d4a205bd274c90,"reason=FailedScheduling count=None msg=0/6 nodes are available: 1 c_wall violated: 1 conflicting context pair(s) with node memory, 5 node(s) had untolerated taint(s). no new claims to deallocate, preemption: 0/6 nodes are available: 1 No preemption victims found for incoming pod, 5 Preemption is not helpful for scheduling."
0.331,Event,ADDED,eval-sanitize-1-r0-134-hx6pk.18d4a205cbc36027,"reason=FailedScheduling count=None msg=0/6 nodes are available: 1 c_wall violated: 1 conflicting context pair(s) with node memory, 5 node(s) had untolerated taint(s). no new claims to deallocate, preemption: 0/6 nodes are available: 1 No preemption victims found for incoming pod, 5 Preemption is not helpful for scheduling."
0.3313,Event,ADDED,eval-sanitize-1-r0-134-hx6pk.18d4a20605004e1f,"reason=FailedScheduling count=None msg=0/6 nodes are available: 1 c_wall violated: 2 conflicting context pair(s) with node memory, 5 node(s) had untolerated taint(s). no new claims to deallocate, preemption: 0/6 nodes are available: 1 No preemption victims found for incoming pod, 5 Preemption is not helpful for scheduling."
0.3315,Event,ADDED,eval-sanitize-1-r0-134-hx6pk.18d4a2060bee6259,"reason=FailedScheduling count=None msg=0/6 nodes are available: 1 c_wall violated: 2 conflicting context pair(s) with node memory, 5 node(s) had untolerated taint(s). no new claims to deallocate, preemption: 0/6 nodes are available: 1 No preemption victims found for incoming pod, 5 Preemption is not helpful for scheduling."
0.3317,Event,ADDED,eval-sanitize-1-r0-134-hx6pk.18d4a20666c640ac,reason=Scheduled count=None msg=Successfully assigned compute/eval-sanitize-1-r0-134-hx6pk to kind-worker3
0.3319,Event,ADDED,eval-sanitize-1-r0-134-hx6pk.18d4a206886f3631,"reason=Pulled count=1 msg=Container image ""busybox:musl"" already present on machine"
0.3322,Event,ADDED,eval-sanitize-1-r0-134-hx6pk.18d4a206899248d7,reason=Created count=1 msg=Created container: task
0.3324,Event,ADDED,eval-sanitize-1-r0-134-hx6pk.18d4a206915982f3,reason=Started count=1 msg=Started container task
0.3326,Event,ADDED,eval-sanitize-1-r0-134.18d4a203b969c92e,reason=SuccessfulCreate count=1 msg=Created pod: eval-sanitize-1-r0-134-hx6pk
0.3329,Event,ADDED,eval-sanitize-1-r0-134.18d4a20c963fba26,reason=Completed count=1 msg=Job completed
0.3331,Event,ADDED,eval-sanitize-1-r0-135-tbqnb.18d4a203f5381cd0,"reason=FailedScheduling count=None msg=0/6 nodes are available: 6 node(s) had untolerated taint(s). no new claims to deallocate, preemption: 0/6 nodes are available: 6 Preemption is not helpful for scheduling."
0.3333,Event,ADDED,eval-sanitize-1-r0-135-tbqnb.18d4a205bdb2c696,"reason=FailedScheduling count=None msg=0/6 nodes are available: 1 c_wall violated: 2 conflicting context pair(s) with node memory, 5 node(s) had untolerated taint(s). no new claims to deallocate, preemption: 0/6 nodes are available: 1 No preemption victims found for incoming pod, 5 Preemption is not helpful for scheduling."
0.3335,Event,ADDED,eval-sanitize-1-r0-135-tbqnb.18d4a205cbf73569,"reason=FailedScheduling count=None msg=0/6 nodes are available: 1 c_wall violated: 2 conflicting context pair(s) with node memory, 5 node(s) had untolerated taint(s). no new claims to deallocate, preemption: 0/6 nodes are available: 1 No preemption victims found for incoming pod, 5 Preemption is not helpful for scheduling."
0.3341,Event,ADDED,eval-sanitize-1-r0-135-tbqnb.18d4a205f70a7c7e,reason=Scheduled count=None msg=Successfully assigned compute/eval-sanitize-1-r0-135-tbqnb to kind-worker4
0.3346,Event,ADDED,eval-sanitize-1-r0-135-tbqnb.18d4a2060faf46d7,"reason=Pulled count=1 msg=Container image ""busybox:musl"" already present on machine"
0.3348,Event,ADDED,eval-sanitize-1-r0-135-tbqnb.18d4a20610e3cfb6,reason=Created count=1 msg=Created container: task
0.3351,Event,ADDED,eval-sanitize-1-r0-135-tbqnb.18d4a20613454dd8,reason=Started count=1 msg=Started container task
0.3353,Event,ADDED,eval-sanitize-1-r0-135.18d4a203f527c007,reason=SuccessfulCreate count=1 msg=Created pod: eval-sanitize-1-r0-135-tbqnb
0.3354,Event,ADDED,eval-sanitize-1-r0-135.18d4a20ca1e39809,reason=Completed count=1 msg=Job completed
0.3356,Event,ADDED,eval-sanitize-1-r0-136-pxssj.18d4a2043067e6f1,"reason=FailedScheduling count=None msg=0/6 nodes are available: 6 node(s) had untolerated taint(s). no new claims to deallocate, preemption: 0/6 nodes are available: 6 Preemption is not helpful for scheduling."
0.3359,Event,ADDED,eval-sanitize-1-r0-136-pxssj.18d4a205bec22f3b,reason=Scheduled count=None msg=Successfully assigned compute/eval-sanitize-1-r0-136-pxssj to kind-worker
0.3361,Event,ADDED,eval-sanitize-1-r0-136-pxssj.18d4a205dac46778,"reason=Pulled count=1 msg=Container image ""busybox:musl"" already present on machine"
0.3363,Event,ADDED,eval-sanitize-1-r0-136-pxssj.18d4a205de273ade,reason=Created count=1 msg=Created container: task
0.3366,Event,ADDED,eval-sanitize-1-r0-136-pxssj.18d4a205e063f2a5,reason=Started count=1 msg=Started container task
0.3368,Event,ADDED,eval-sanitize-1-r0-136.18d4a204305ba745,reason=SuccessfulCreate count=1 msg=Created pod: eval-sanitize-1-r0-136-pxssj
0.3369,Event,ADDED,eval-sanitize-1-r0-136.18d4a20b548d0056,reason=Completed count=1 msg=Job completed
0.3371,Event,ADDED,eval-sanitize-1-r0-137-8p6w5.18d4a2046c52b42e,"reason=FailedScheduling count=None msg=0/6 nodes are available: 6 node(s) had untolerated taint(s). no new claims to deallocate, preemption: 0/6 nodes are available: 6 Preemption is not helpful for scheduling."
0.3374,Event,ADDED,eval-sanitize-1-r0-137-8p6w5.18d4a205be99438f,"reason=FailedScheduling count=None msg=0/6 nodes are available: 1 c_wall violated: 1 conflicting context pair(s) with node memory, 5 node(s) had untolerated taint(s). no new claims to deallocate, preemption: 0/6 nodes are available: 1 No preemption victims found for incoming pod, 5 Preemption is not helpful for scheduling."
0.3376,Event,ADDED,eval-sanitize-1-r0-137-8p6w5.18d4a205cc26de31,"reason=FailedScheduling count=None msg=0/6 nodes are available: 1 c_wall violated: 1 conflicting context pair(s) with node memory, 5 node(s) had untolerated taint(s). no new claims to deallocate, preemption: 0/6 nodes are available: 1 No preemption victims found for incoming pod, 5 Preemption is not helpful for scheduling."
0.3378,Event,ADDED,eval-sanitize-1-r0-137-8p6w5.18d4a2060cd582bf,"reason=FailedScheduling count=None msg=0/6 nodes are available: 1 c_wall violated: 2 conflicting context pair(s) with node memory, 5 node(s) had untolerated taint(s). no new claims to deallocate, preemption: 0/6 nodes are available: 1 No preemption victims found for incoming pod, 5 Preemption is not helpful for scheduling."
0.3381,Event,ADDED,eval-sanitize-1-r0-137-8p6w5.18d4a20655929b94,reason=Scheduled count=None msg=Successfully assigned compute/eval-sanitize-1-r0-137-8p6w5 to kind-worker3
0.3383,Event,ADDED,eval-sanitize-1-r0-137-8p6w5.18d4a20672553511,"reason=Pulled count=1 msg=Container image ""busybox:musl"" already present on machine"
0.3385,Event,ADDED,eval-sanitize-1-r0-137-8p6w5.18d4a2067396840c,reason=Created count=1 msg=Created container: task
0.3386,Event,ADDED,eval-sanitize-1-r0-137-8p6w5.18d4a206812362b1,reason=Started count=1 msg=Started container task
0.3389,Event,ADDED,eval-sanitize-1-r0-137.18d4a2046c47b20e,reason=SuccessfulCreate count=1 msg=Created pod: eval-sanitize-1-r0-137-8p6w5
0.3391,Event,ADDED,eval-sanitize-1-r0-137.18d4a20c932c1acc,reason=Completed count=1 msg=Job completed
0.3392,Event,ADDED,eval-sanitize-1-r0-138-sjv85.18d4a204ad5a837f,"reason=FailedScheduling count=None msg=0/6 nodes are available: 6 node(s) had untolerated taint(s). no new claims to deallocate, preemption: 0/6 nodes are available: 6 Preemption is not helpful for scheduling."
0.3394,Event,ADDED,eval-sanitize-1-r0-138-sjv85.18d4a205bf1c2bf6,"reason=FailedScheduling count=None msg=0/6 nodes are available: 1 c_wall violated: 2 conflicting context pair(s) with node memory, 5 node(s) had untolerated taint(s). no new claims to deallocate, preemption: 0/6 nodes are available: 1 No preemption victims found for incoming pod, 5 Preemption is not helpful for scheduling."
0.3396,Event,ADDED,eval-sanitize-1-r0-138-sjv85.18d4a205d02f2438,"reason=FailedScheduling count=None msg=0/6 nodes are available: 1 c_wall violated: 2 conflicting context pair(s) with node memory, 5 node(s) had untolerated taint(s). no new claims to deallocate, preemption: 0/6 nodes are available: 1 No preemption victims found for incoming pod, 5 Preemption is not helpful for scheduling."
0.3397,Event,ADDED,eval-sanitize-1-r0-138-sjv85.18d4a205f8dd7565,reason=Scheduled count=None msg=Successfully assigned compute/eval-sanitize-1-r0-138-sjv85 to kind-worker4
0.3399,Event,ADDED,eval-sanitize-1-r0-138-sjv85.18d4a20610e80d61,"reason=Pulled count=1 msg=Container image ""busybox:musl"" already present on machine"
0.3401,Event,ADDED,eval-sanitize-1-r0-138-sjv85.18d4a206122ece8e,reason=Created count=1 msg=Created container: task
0.3403,Event,ADDED,eval-sanitize-1-r0-138-sjv85.18d4a20614965563,reason=Started count=1 msg=Started container task
0.3405,Event,ADDED,eval-sanitize-1-r0-138.18d4a204ad4ddb6d,reason=SuccessfulCreate count=1 msg=Created pod: eval-sanitize-1-r0-138-sjv85
0.3409,Event,ADDED,eval-sanitize-1-r0-138.18d4a20c3f8e8800,reason=Completed count=1 msg=Job completed
0.341,Event,ADDED,eval-sanitize-1-r0-139-vnkrj.18d4a204e41e34ba,"reason=FailedScheduling count=None msg=0/6 nodes are available: 6 node(s) had untolerated taint(s). no new claims to deallocate, preemption: 0/6 nodes are available: 6 Preemption is not helpful for scheduling."
0.3412,Event,ADDED,eval-sanitize-1-r0-139-vnkrj.18d4a205c2e102d6,reason=Scheduled count=None msg=Successfully assigned compute/eval-sanitize-1-r0-139-vnkrj to kind-worker
0.3414,Event,ADDED,eval-sanitize-1-r0-139-vnkrj.18d4a205db8d7386,"reason=Pulled count=1 msg=Container image ""busybox:musl"" already present on machine"
0.3419,Event,ADDED,eval-sanitize-1-r0-139-vnkrj.18d4a205dddb9846,reason=Created count=1 msg=Created container: task
0.3421,Event,ADDED,eval-sanitize-1-r0-139-vnkrj.18d4a205e0391783,reason=Started count=1 msg=Started container task
0.3423,Event,ADDED,eval-sanitize-1-r0-139.18d4a204e4133f2b,reason=SuccessfulCreate count=1 msg=Created pod: eval-sanitize-1-r0-139-vnkrj
0.3425,Event,ADDED,eval-sanitize-1-r0-139.18d4a20b53a555a7,reason=Completed count=1 msg=Job completed
0.3426,Event,ADDED,eval-sanitize-1-r0-140-r68d4.18d4a205224f09cf,"reason=FailedScheduling count=None msg=0/6 nodes are available: 6 node(s) had untolerated taint(s). no new claims to deallocate, preemption: 0/6 nodes are available: 6 Preemption is not helpful for scheduling."
0.3428,Event,ADDED,eval-sanitize-1-r0-140-r68d4.18d4a205c2e4c751,"reason=FailedScheduling count=None msg=0/6 nodes are available: 1 c_wall violated: 2 conflicting context pair(s) with node memory, 5 node(s) had untolerated taint(s). no new claims to deallocate, preemption: 0/6 nodes are available: 1 No preemption victims found for incoming pod, 5 Preemption is not helpful for scheduling."
0.3431,Event,ADDED,eval-sanitize-1-r0-140-r68d4.18d4a205d14f12d4,"reason=FailedScheduling count=None msg=0/6 nodes are available: 1 c_wall violated: 2 conflicting context pair(s) with node memory, 5 node(s) had untolerated taint(s). no new claims to deallocate, preemption: 0/6 nodes are available: 1 No preemption victims found for incoming pod, 5 Preemption is not helpful for scheduling."
0.3433,Event,ADDED,eval-sanitize-1-r0-140-r68d4.18d4a205f960fcdf,reason=Scheduled count=None msg=Successfully assigned compute/eval-sanitize-1-r0-140-r68d4 to kind-worker4
0.3435,Event,ADDED,eval-sanitize-1-r0-140-r68d4.18d4a206122ebf64,"reason=Pulled count=1 msg=Container image ""busybox:musl"" already present on machine"
0.3436,Event,ADDED,eval-sanitize-1-r0-140-r68d4.18d4a20614127965,reason=Created count=1 msg=Created container: task
0.3439,Event,ADDED,eval-sanitize-1-r0-140-r68d4.18d4a206190584a0,reason=Started count=1 msg=Started container task
0.344,Event,ADDED,eval-sanitize-1-r0-140.18d4a20522447c15,reason=SuccessfulCreate count=1 msg=Created pod: eval-sanitize-1-r0-140-r68d4
0.3442,Event,ADDED,eval-sanitize-1-r0-140.18d4a20c3d229c03,reason=Completed count=1 msg=Job completed
0.3444,Event,ADDED,eval-sanitize-1-r0-141-hdnpx.18d4a2055ceccc9d,"reason=FailedScheduling count=None msg=0/6 nodes are available: 6 node(s) had untolerated taint(s). no new claims to deallocate, preemption: 0/6 nodes are available: 6 Preemption is not helpful for scheduling."
0.3446,Event,ADDED,eval-sanitize-1-r0-141-hdnpx.18d4a205c3d8dcfd,reason=Scheduled count=None msg=Successfully assigned compute/eval-sanitize-1-r0-141-hdnpx to kind-worker
0.3447,Event,ADDED,eval-sanitize-1-r0-141-hdnpx.18d4a205ed8ab208,"reason=Pulled count=1 msg=Container image ""busybox:musl"" already present on machine"
0.3449,Event,ADDED,eval-sanitize-1-r0-141-hdnpx.18d4a205ef7097da,reason=Created count=1 msg=Created container: task
0.3451,Event,ADDED,eval-sanitize-1-r0-141-hdnpx.18d4a205f3fbfb94,reason=Started count=1 msg=Started container task
0.3453,Event,ADDED,eval-sanitize-1-r0-141.18d4a2055ce67e1b,reason=SuccessfulCreate count=1 msg=Created pod: eval-sanitize-1-r0-141-hdnpx
0.3454,Event,ADDED,eval-sanitize-1-r0-141.18d4a20b54e3d7ea,reason=Completed count=1 msg=Job completed
0.3456,Event,ADDED,eval-sanitize-1-r0-142-nmhqq.18d4a20596008469,"reason=FailedScheduling count=None msg=0/6 nodes are available: 6 node(s) had untolerated taint(s). no new claims to deallocate, preemption: 0/6 nodes are available: 6 Preemption is not helpful for scheduling."
0.3457,Event,ADDED,eval-sanitize-1-r0-142-nmhqq.18d4a205c492eda0,reason=Scheduled count=None msg=Successfully assigned compute/eval-sanitize-1-r0-142-nmhqq to kind-worker
0.3459,Event,ADDED,eval-sanitize-1-r0-142-nmhqq.18d4a205ee141a56,"reason=Pulled count=1 msg=Container image ""busybox:musl"" already present on machine"
0.3461,Event,ADDED,eval-sanitize-1-r0-142-nmhqq.18d4a205f03ee6f8,reason=Created count=1 msg=Created container: task
0.3462,Event,ADDED,eval-sanitize-1-r0-142-nmhqq.18d4a205f4a53cdb,reason=Started count=1 msg=Started container task
0.3464,Event,ADDED,eval-sanitize-1-r0-142.18d4a20595f2d888,reason=SuccessfulCreate count=1 msg=Created pod: eval-sanitize-1-r0-142-nmhqq
0.3466,Event,ADDED,eval-sanitize-1-r0-142.18d4a20c398e8373,reason=Completed count=1 msg=Job completed
0.3467,Event,ADDED,eval-sanitize-1-r0-143-v5vsg.18d4a206004d7fc2,reason=Scheduled count=None msg=Successfully assigned compute/eval-sanitize-1-r0-143-v5vsg to kind-worker4
0.3469,Event,ADDED,eval-sanitize-1-r0-143-v5vsg.18d4a20626ddddc3,"reason=Pulled count=1 msg=Container image ""busybox:musl"" already present on machine"
0.347,Event,ADDED,eval-sanitize-1-r0-143-v5vsg.18d4a2062959ccfb,reason=Created count=1 msg=Created container: task
0.3472,Event,ADDED,eval-sanitize-1-r0-143-v5vsg.18d4a2062e2d0fc0,reason=Started count=1 msg=Started container task
0.3474,Event,ADDED,eval-sanitize-1-r0-143.18d4a205ff6935fe,reason=SuccessfulCreate count=1 msg=Created pod: eval-sanitize-1-r0-143-v5vsg
0.3476,Event,ADDED,eval-sanitize-1-r0-143.18d4a20c872f5996,reason=Completed count=1 msg=Job completed
0.3477,Event,ADDED,eval-sanitize-1-r0-144-l4fbx.18d4a2065c403d2d,"reason=FailedScheduling count=None msg=0/6 nodes are available: 1 c_wall violated: 1 conflicting context pair(s) with node memory, 5 node(s) had untolerated taint(s). no new claims to deallocate, preemption: 0/6 nodes are available: 1 No preemption victims found for incoming pod, 5 Preemption is not helpful for scheduling."
0.3479,Event,ADDED,eval-sanitize-1-r0-144-l4fbx.18d4a20667d724a3,"reason=FailedScheduling count=None msg=0/6 nodes are available: 1 c_wall violated: 1 conflicting context pair(s) with node memory, 5 node(s) had untolerated taint(s). no new claims to deallocate, preemption: 0/6 nodes are available: 1 No preemption victims found for incoming pod, 5 Preemption is not helpful for scheduling."
0.348,Event,ADDED,eval-sanitize-1-r0-144-l4fbx.18d4a206dd68b1c4,"reason=FailedScheduling count=None msg=0/6 nodes are available: 1 c_wall violated: 1 conflicting context pair(s) with node memory, 5 node(s) had untolerated taint(s). no new claims to deallocate, preemption: 0/6 nodes are available: 1 No preemption victims found for incoming pod, 5 Preemption is not helpful for scheduling."
0.3482,Event,ADDED,eval-sanitize-1-r0-144-l4fbx.18d4a206e2573bb9,"reason=FailedScheduling count=None msg=0/6 nodes are available: 1 c_wall violated: 1 conflicting context pair(s) with node memory, 5 node(s) had untolerated taint(s). no new claims to deallocate, preemption: 0/6 nodes are available: 1 No preemption victims found for incoming pod, 5 Preemption is not helpful for scheduling."
0.3484,Event,ADDED,eval-sanitize-1-r0-144-l4fbx.18d4a207610527c0,"reason=FailedScheduling count=None msg=0/6 nodes are available: 1 c_wall violated: 2 conflicting context pair(s) with node memory, 5 node(s) had untolerated taint(s). no new claims to deallocate, preemption: 0/6 nodes are available: 1 No preemption victims found for incoming pod, 5 Preemption is not helpful for scheduling."
0.3485,Event,ADDED,eval-sanitize-1-r0-144-l4fbx.18d4a20762d7eb46,"reason=FailedScheduling count=None msg=0/6 nodes are available: 1 c_wall violated: 2 conflicting context pair(s) with node memory, 5 node(s) had untolerated taint(s). no new claims to deallocate, preemption: 0/6 nodes are available: 1 No preemption victims found for incoming pod, 5 Preemption is not helpful for scheduling."
0.3487,Event,ADDED,eval-sanitize-1-r0-144-l4fbx.18d4a20b36932b33,"reason=FailedScheduling count=None msg=0/6 nodes are available: 1 c_wall violated: 1 conflicting context pair(s) with node memory, 5 node(s) had untolerated taint(s). no new claims to deallocate, preemption: 0/6 nodes are available: 1 No preemption victims found for incoming pod, 5 Preemption is not helpful for scheduling."
0.3489,Event,ADDED,eval-sanitize-1-r0-144-l4fbx.18d4a20b59a8f68c,"reason=FailedScheduling count=None msg=0/6 nodes are available: 1 c_wall violated: 1 conflicting context pair(s) with node memory, 5 node(s) had untolerated taint(s). no new claims to deallocate, preemption: 0/6 nodes are available: 1 No preemption victims found for incoming pod, 5 Preemption is not helpful for scheduling."
0.349,Event,ADDED,eval-sanitize-1-r0-144-l4fbx.18d4a20ba513923c,reason=Scheduled count=None msg=Successfully assigned compute/eval-sanitize-1-r0-144-l4fbx to kind-worker4
0.3492,Event,ADDED,eval-sanitize-1-r0-144-l4fbx.18d4a20bbe81343c,"reason=Pulled count=1 msg=Container image ""busybox:musl"" already present on machine"
0.3494,Event,ADDED,eval-sanitize-1-r0-144-l4fbx.18d4a20bc02e1bf2,reason=Created count=1 msg=Created container: task
0.3495,Event,ADDED,eval-sanitize-1-r0-144-l4fbx.18d4a20bc34fd52a,reason=Started count=1 msg=Started container task
0.3498,Event,ADDED,eval-sanitize-1-r0-144.18d4a2065b9c3e91,reason=SuccessfulCreate count=1 msg=Created pod: eval-sanitize-1-r0-144-l4fbx
0.3499,Event,ADDED,eval-sanitize-1-r0-144.18d4a212222aa6f0,reason=Completed count=1 msg=Job completed
0.3501,Event,ADDED,eval-sanitize-1-r0-145-r6vdb.18d4a206b4d52898,"reason=FailedScheduling count=None msg=0/6 nodes are available: 6 node(s) had untolerated taint(s). no new claims to deallocate, preemption: 0/6 nodes are available: 6 Preemption is not helpful for scheduling."
0.3502,Event,ADDED,eval-sanitize-1-r0-145-r6vdb.18d4a206e1069005,"reason=FailedScheduling count=None msg=0/6 nodes are available: 1 c_wall violated: 1 conflicting context pair(s) with node memory, 5 node(s) had untolerated taint(s). no new claims to deallocate, preemption: 0/6 nodes are available: 1 No preemption victims found for incoming pod, 5 Preemption is not helpful for scheduling."
0.3504,Event,ADDED,eval-sanitize-1-r0-145-r6vdb.18d4a206e73099b1,"reason=FailedScheduling count=None msg=0/6 nodes are available: 1 c_wall violated: 1 conflicting context pair(s) with node memory, 5 node(s) had untolerated taint(s). no new claims to deallocate, preemption: 0/6 nodes are available: 1 No preemption victims found for incoming pod, 5 Preemption is not helpful for scheduling."
0.3506,Event,ADDED,eval-sanitize-1-r0-145-r6vdb.18d4a2076199ea53,"reason=FailedScheduling count=None msg=0/6 nodes are available: 1 c_wall violated: 1 conflicting context pair(s) with node memory, 5 node(s) had untolerated taint(s). no new claims to deallocate, preemption: 0/6 nodes are available: 1 No preemption victims found for incoming pod, 5 Preemption is not helpful for scheduling."
0.3509,Event,ADDED,eval-sanitize-1-r0-145-r6vdb.18d4a20763053bfb,"reason=FailedScheduling count=None msg=0/6 nodes are available: 1 c_wall violated: 1 conflicting context pair(s) with node memory, 5 node(s) had untolerated taint(s). no new claims to deallocate, preemption: 0/6 nodes are available: 1 No preemption victims found for incoming pod, 5 Preemption is not helpful for scheduling."
0.351,Event,ADDED,eval-sanitize-1-r0-145-r6vdb.18d4a20b376bc329,reason=Scheduled count=None msg=Successfully assigned compute/eval-sanitize-1-r0-145-r6vdb to kind-worker
0.3512,Event,ADDED,eval-sanitize-1-r0-145-r6vdb.18d4a20b50dc73b1,"reason=Pulled count=1 msg=Container image ""busybox:musl"" already present on machine"
0.352,Event,ADDED,eval-sanitize-1-r0-145-r6vdb.18d4a20b521d21bd,reason=Created count=1 msg=Created container: task
0.3523,Event,ADDED,eval-sanitize-1-r0-145-r6vdb.18d4a20b5ae19809,reason=Started count=1 msg=Started container task
0.3525,Event,ADDED,eval-sanitize-1-r0-145.18d4a206b4cd7cbc,reason=SuccessfulCreate count=1 msg=Created pod: eval-sanitize-1-r0-145-r6vdb
0.3527,Event,ADDED,eval-sanitize-1-r0-145.18d4a210f3e72991,reason=Completed count=1 msg=Job completed
0.353,Event,ADDED,eval-sanitize-1-r0-146-qzd9v.18d4a206fa51f8e1,"reason=FailedScheduling count=None msg=0/6 nodes are available: 1 c_wall violated: 1 conflicting context pair(s) with node memory, 5 node(s) had untolerated taint(s). no new claims to deallocate, preemption: 0/6 nodes are available: 1 No preemption victims found for incoming pod, 5 Preemption is not helpful for scheduling."
0.3532,Event,ADDED,eval-sanitize-1-r0-146-qzd9v.18d4a206fb0d0cf9,"reason=FailedScheduling count=None msg=0/6 nodes are available: 1 c_wall violated: 1 conflicting context pair(s) with node memory, 5 node(s) had untolerated taint(s). no new claims to deallocate, preemption: 0/6 nodes are available: 1 No preemption victims found for incoming pod, 5 Preemption is not helpful for scheduling."
0.3534,Event,ADDED,eval-sanitize-1-r0-146-qzd9v.18d4a20760eec2e3,reason=Scheduled count=None msg=Successfully assigned compute/eval-sanitize-1-r0-146-qzd9v to kind-worker2
0.3536,Event,ADDED,eval-sanitize-1-r0-146-qzd9v.18d4a2077bc6468c,"reason=Pulled count=1 msg=Container image ""busybox:musl"" already present on machine"
0.3538,Event,ADDED,eval-sanitize-1-r0-146-qzd9v.18d4a2077d3607bf,reason=Created count=1 msg=Created container: task
0.3539,Event,ADDED,eval-sanitize-1-r0-146-qzd9v.18d4a20783e558f8,reason=Started count=1 msg=Started container task
0.3541,Event,ADDED,eval-sanitize-1-r0-146.18d4a206f9df876f,reason=SuccessfulCreate count=1 msg=Created pod: eval-sanitize-1-r0-146-qzd9v
0.3543,Event,ADDED,eval-sanitize-1-r0-146.18d4a20d3dc93296,reason=Completed count=1 msg=Job completed
0.3544,Event,ADDED,eval-sanitize-1-r0-147-p7c54.18d4a2072c5d8967,"reason=FailedScheduling count=None msg=0/6 nodes are available: 1 c_wall violated: 2 conflicting context pair(s) with node memory, 5 node(s) had untolerated taint(s). no new claims to deallocate, preemption: 0/6 nodes are available: 1 No preemption victims found for incoming pod, 5 Preemption is not helpful for scheduling."
0.3546,Event,ADDED,eval-sanitize-1-r0-147-p7c54.18d4a2072cedaae0,"reason=FailedScheduling count=None msg=0/6 nodes are available: 1 c_wall violated: 2 conflicting context pair(s) with node memory, 5 node(s) had untolerated taint(s). no new claims to deallocate, preemption: 0/6 nodes are available: 1 No preemption victims found for incoming pod, 5 Preemption is not helpful for scheduling."
0.3549,Event,ADDED,eval-sanitize-1-r0-147-p7c54.18d4a207611fdd98,reason=Scheduled count=None msg=Successfully assigned compute/eval-sanitize-1-r0-147-p7c54 to kind-worker2
0.3551,Event,ADDED,eval-sanitize-1-r0-147-p7c54.18d4a2077c0afdfe,"reason=Pulled count=1 msg=Container image ""busybox:musl"" already present on machine"
0.3553,Event,ADDED,eval-sanitize-1-r0-147-p7c54.18d4a2077d95becc,reason=Created count=1 msg=Created container: task
0.3554,Event,ADDED,eval-sanitize-1-r0-147-p7c54.18d4a20783e558e6,reason=Started count=1 msg=Started container task
0.3557,Event,ADDED,eval-sanitize-1-r0-147.18d4a2072c1ab2fc,reason=SuccessfulCreate count=1 msg=Created pod: eval-sanitize-1-r0-147-p7c54
0.3558,Event,ADDED,eval-sanitize-1-r0-147.18d4a20d7cb77179,reason=Completed count=1 msg=Job completed
0.356,Event,ADDED,eval-sanitize-1-r0-148-8chqz.18d4a2073b6bbb6c,reason=Scheduled count=None msg=Successfully assigned compute/eval-sanitize-1-r0-148-8chqz to kind-worker5
0.3562,Event,ADDED,eval-sanitize-1-r0-148-8chqz.18d4a20756885382,"reason=Pulled count=1 msg=Container image ""busybox:musl"" already present on machine"
0.3564,Event,ADDED,eval-sanitize-1-r0-148-8chqz.18d4a20757e2487c,reason=Created count=1 msg=Created container: task
0.3565,Event,ADDED,eval-sanitize-1-r0-148-8chqz.18d4a2075c6283ee,reason=Started count=1 msg=Started container task
0.3567,Event,ADDED,eval-sanitize-1-r0-148.18d4a2073af659c7,reason=SuccessfulCreate count=1 msg=Created pod: eval-sanitize-1-r0-148-8chqz
0.3569,Event,ADDED,eval-sanitize-1-r0-148.18d4a20d48c35cae,reason=Completed count=1 msg=Job completed
0.357,Event,ADDED,eval-sanitize-1-r0-149-8sckt.18d4a20758d20532,"reason=FailedScheduling count=None msg=0/6 nodes are available: 6 node(s) had untolerated taint(s). no new claims to deallocate, preemption: 0/6 nodes are available: 6 Preemption is not helpful for scheduling."
0.3572,Event,ADDED,eval-sanitize-1-r0-149-8sckt.18d4a207622d36fe,"reason=FailedScheduling count=None msg=0/6 nodes are available: 1 c_wall violated: 2 conflicting context pair(s) with node memory, 5 node(s) had untolerated taint(s). no new claims to deallocate, preemption: 0/6 nodes are available: 1 No preemption victims found for incoming pod, 5 Preemption is not helpful for scheduling."
0.3574,Event,ADDED,eval-sanitize-1-r0-149-8sckt.18d4a2076330ee67,"reason=FailedScheduling count=None msg=0/6 nodes are available: 1 c_wall violated: 2 conflicting context pair(s) with node memory, 5 node(s) had untolerated taint(s). no new claims to deallocate, preemption: 0/6 nodes are available: 1 No preemption victims found for incoming pod, 5 Preemption is not helpful for scheduling."
0.3575,Event,ADDED,eval-sanitize-1-r0-149-8sckt.18d4a20b37607b18,"reason=FailedScheduling count=None msg=0/6 nodes are available: 1 c_wall violated: 1 conflicting context pair(s) with node memory, 5 node(s) had untolerated taint(s). no new claims to deallocate, preemption: 0/6 nodes are available: 1 No preemption victims found for incoming pod, 5 Preemption is not helpful for scheduling."
0.3577,Event,ADDED,eval-sanitize-1-r0-149-8sckt.18d4a20b5ad56eea,"reason=FailedScheduling count=None msg=0/6 nodes are available: 1 c_wall violated: 1 conflicting context pair(s) with node memory, 5 node(s) had untolerated taint(s). no new claims to deallocate, preemption: 0/6 nodes are available: 1 No preemption victims found for incoming pod, 5 Preemption is not helpful for scheduling."
0.3578,Event,ADDED,eval-sanitize-1-r0-149-8sckt.18d4a20b95d62fdf,reason=Scheduled count=None msg=Successfully assigned compute/eval-sanitize-1-r0-149-8sckt to kind-worker4
0.358,Event,ADDED,eval-sanitize-1-r0-149-8sckt.18d4a20bb2fe4504,"reason=Pulled count=1 msg=Container image ""busybox:musl"" already present on machine"
0.3582,Event,ADDED,eval-sanitize-1-r0-149-8sckt.18d4a20bb4f5b585,reason=Created count=1 msg=Created container: task
0.3583,Event,ADDED,eval-sanitize-1-r0-149-8sckt.18d4a20bbca8bcea,reason=Started count=1 msg=Started container task
0.3585,Event,ADDED,eval-sanitize-1-r0-149.18d4a20758c3eda5,reason=SuccessfulCreate count=1 msg=Created pod: eval-sanitize-1-r0-149-8sckt
0.3587,Event,ADDED,eval-sanitize-1-r0-149.18d4a212350e598b,reason=Completed count=1 msg=Job completed
0.3588,Event,ADDED,eval-sanitize-1-r0-150-7rpq8.18d4a2078345a216,"reason=FailedScheduling count=None msg=0/6 nodes are available: 1 c_wall violated: 2 conflicting context pair(s) with node memory, 5 node(s) had untolerated taint(s). no new claims to deallocate, preemption: 0/6 nodes are available: 1 No preemption victims found for incoming pod, 5 Preemption is not helpful for scheduling."
0.359,Event,ADDED,eval-sanitize-1-r0-150-7rpq8.18d4a207844701bb,"reason=FailedScheduling count=None msg=0/6 nodes are available: 1 c_wall violated: 2 conflicting context pair(s) with node memory, 5 node(s) had untolerated taint(s). no new claims to deallocate, preemption: 0/6 nodes are available: 1 No preemption victims found for incoming pod, 5 Preemption is not helpful for scheduling."
0.3592,Event,ADDED,eval-sanitize-1-r0-150-7rpq8.18d4a20b3656ccfb,reason=Scheduled count=None msg=Successfully assigned compute/eval-sanitize-1-r0-150-7rpq8 to kind-worker
0.3593,Event,ADDED,eval-sanitize-1-r0-150-7rpq8.18d4a20b4fe3762f,"reason=Pulled count=1 msg=Container image ""busybox:musl"" already present on machine"
0.3595,Event,ADDED,eval-sanitize-1-r0-150-7rpq8.18d4a20b513f5bc0,reason=Created count=1 msg=Created container: task
0.3597,Event,ADDED,eval-sanitize-1-r0-150-7rpq8.18d4a20b56b9e852,reason=Started count=1 msg=Started container task
0.3598,Event,ADDED,eval-sanitize-1-r0-150.18d4a207801a1b05,reason=SuccessfulCreate count=1 msg=Created pod: eval-sanitize-1-r0-150-7rpq8
0.36,Event,ADDED,eval-sanitize-1-r0-150.18d4a210f3e833cb,reason=Completed count=1 msg=Job completed
0.3602,Event,ADDED,eval-sanitize-1-r0-151-hhnhr.18d4a207b22a652b,"reason=FailedScheduling count=None msg=0/6 nodes are available: 6 node(s) had untolerated taint(s). no new claims to deallocate, preemption: 0/6 nodes are available: 6 Preemption is not helpful for scheduling."
0.3604,Event,ADDED,eval-sanitize-1-r0-151-hhnhr.18d4a20b385cdeb1,"reason=FailedScheduling count=None msg=0/6 nodes are available: 1 c_wall violated: 1 conflicting context pair(s) with node memory, 5 node(s) had untolerated taint(s). no new claims to deallocate, preemption: 0/6 nodes are available: 1 No preemption victims found for incoming pod, 5 Preemption is not helpful for scheduling."
0.3605,Event,ADDED,eval-sanitize-1-r0-151-hhnhr.18d4a20b5b0a13f7,"reason=FailedScheduling count=None msg=0/6 nodes are available: 1 c_wall violated: 1 conflicting context pair(s) with node memory, 5 node(s) had untolerated taint(s). no new claims to deallocate, preemption: 0/6 nodes are available: 1 No preemption victims found for incoming pod, 5 Preemption is not helpful for scheduling."
0.3607,Event,ADDED,eval-sanitize-1-r0-151-hhnhr.18d4a20b963212c1,reason=Scheduled count=None msg=Successfully assigned compute/eval-sanitize-1-r0-151-hhnhr to kind-worker4
0.3609,Event,ADDED,eval-sanitize-1-r0-151-hhnhr.18d4a20bb32699dc,"reason=Pulled count=1 msg=Container image ""busybox:musl"" already present on machine"
0.3611,Event,ADDED,eval-sanitize-1-r0-151-hhnhr.18d4a20bb5766d17,reason=Created count=1 msg=Created container: task
0.3612,Event,ADDED,eval-sanitize-1-r0-151-hhnhr.18d4a20bbe1fd4bf,reason=Started count=1 msg=Started container task
0.3614,Event,ADDED,eval-sanitize-1-r0-151.18d4a207b2223a60,reason=SuccessfulCreate count=1 msg=Created pod: eval-sanitize-1-r0-151-hhnhr
0.3616,Event,ADDED,eval-sanitize-1-r0-151.18d4a212250521a3,reason=Completed count=1 msg=Job completed
0.3617,Event,ADDED,eval-sanitize-1-r0-152-xsdzd.18d4a207eaa939d4,"reason=FailedScheduling count=None msg=0/6 nodes are available: 6 node(s) had untolerated taint(s). no new claims to deallocate, preemption: 0/6 nodes are available: 6 Preemption is not helpful for scheduling."
0.3619,Event,ADDED,eval-sanitize-1-r0-152-xsdzd.18d4a20b3bce064e,"reason=FailedScheduling count=None msg=0/6 nodes are available: 1 c_wall violated: 1 conflicting context pair(s) with node memory, 5 node(s) had untolerated taint(s). no new claims to deallocate, preemption: 0/6 nodes are available: 1 No preemption victims found for incoming pod, 5 Preemption is not helpful for scheduling."
0.3621,Event,ADDED,eval-sanitize-1-r0-152-xsdzd.18d4a20b5bce0678,"reason=FailedScheduling count=None msg=0/6 nodes are available: 1 c_wall violated: 1 conflicting context pair(s) with node memory, 5 node(s) had untolerated taint(s). no new claims to deallocate, preemption: 0/6 nodes are available: 1 No preemption victims found for incoming pod, 5 Preemption is not helpful for scheduling."
0.3623,Event,ADDED,eval-sanitize-1-r0-152-xsdzd.18d4a20b9608a1ea,"reason=FailedScheduling count=None msg=0/6 nodes are available: 1 c_wall violated: 1 conflicting context pair(s) with node memory, 5 node(s) had untolerated taint(s). no new claims to deallocate, preemption: 0/6 nodes are available: 1 No preemption victims found for incoming pod, 5 Preemption is not helpful for scheduling."
0.3624,Event,ADDED,eval-sanitize-1-r0-152-xsdzd.18d4a20bab0a45f3,"reason=FailedScheduling count=None msg=0/6 nodes are available: 1 c_wall violated: 1 conflicting context pair(s) with node memory, 5 node(s) had untolerated taint(s). no new claims to deallocate, preemption: 0/6 nodes are available: 1 No preemption victims found for incoming pod, 5 Preemption is not helpful for scheduling."
0.3626,Event,ADDED,eval-sanitize-1-r0-152-xsdzd.18d4a20bb60a7e95,reason=Scheduled count=None msg=Successfully assigned compute/eval-sanitize-1-r0-152-xsdzd to kind-worker3
0.3628,Event,ADDED,eval-sanitize-1-r0-152-xsdzd.18d4a20bd38876a4,"reason=Pulled count=1 msg=Container image ""busybox:musl"" already present on machine"
0.3629,Event,ADDED,eval-sanitize-1-r0-152-xsdzd.18d4a20bd6dcd907,reason=Created count=1 msg=Created container: task
0.3631,Event,ADDED,eval-sanitize-1-r0-152-xsdzd.18d4a20bdb24b795,reason=Started count=1 msg=Started container task
0.3633,Event,ADDED,eval-sanitize-1-r0-152.18d4a207ea9780af,reason=SuccessfulCreate count=1 msg=Created pod: eval-sanitize-1-r0-152-xsdzd
0.3634,Event,ADDED,eval-sanitize-1-r0-152.18d4a212817616d7,reason=Completed count=1 msg=Job completed
0.3636,Event,ADDED,eval-sanitize-1-r0-153-7l9w2.18d4a20825d2f006,"reason=FailedScheduling count=None msg=0/6 nodes are available: 6 node(s) had untolerated taint(s). no new claims to deallocate, preemption: 0/6 nodes are available: 6 Preemption is not helpful for scheduling."
0.3638,Event,ADDED,eval-sanitize-1-r0-153-7l9w2.18d4a20b48513b38,reason=Scheduled count=None msg=Successfully assigned compute/eval-sanitize-1-r0-153-7l9w2 to kind-worker
0.3639,Event,ADDED,eval-sanitize-1-r0-153-7l9w2.18d4a20b6257adc4,"reason=Pulled count=1 msg=Container image ""busybox:musl"" already present on machine"
0.3641,Event,ADDED,eval-sanitize-1-r0-153-7l9w2.18d4a20b63ccda60,reason=Created count=1 msg=Created container: task
0.3643,Event,ADDED,eval-sanitize-1-r0-153-7l9w2.18d4a20b66015cd4,reason=Started count=1 msg=Started container task
0.3648,Event,ADDED,eval-sanitize-1-r0-153.18d4a20825c73079,reason=SuccessfulCreate count=1 msg=Created pod: eval-sanitize-1-r0-153-7l9w2
0.3649,Event,ADDED,eval-sanitize-1-r0-153.18d4a210f403dd94,reason=Completed count=1 msg=Job completed
0.3651,Event,ADDED,eval-sanitize-1-r0-154-9c596.18d4a208616c6731,"reason=FailedScheduling count=None msg=0/6 nodes are available: 6 node(s) had untolerated taint(s). no new claims to deallocate, preemption: 0/6 nodes are available: 6 Preemption is not helpful for scheduling."
0.3653,Event,ADDED,eval-sanitize-1-r0-154-9c596.18d4a20b481694f7,"reason=FailedScheduling count=None msg=0/6 nodes are available: 1 c_wall violated: 1 conflicting context pair(s) with node memory, 5 node(s) had untolerated taint(s). no new claims to deallocate, preemption: 0/6 nodes are available: 1 No preemption victims found for incoming pod, 5 Preemption is not helpful for scheduling."
0.3655,Event,ADDED,eval-sanitize-1-r0-154-9c596.18d4a20b5c029746,"reason=FailedScheduling count=None msg=0/6 nodes are available: 1 c_wall violated: 1 conflicting context pair(s) with node memory, 5 node(s) had untolerated taint(s). no new claims to deallocate, preemption: 0/6 nodes are available: 1 No preemption victims found for incoming pod, 5 Preemption is not helpful for scheduling."
0.3657,Event,ADDED,eval-sanitize-1-r0-154-9c596.18d4a20b9b346d4a,"reason=FailedScheduling count=None msg=0/6 nodes are available: 1 c_wall violated: 1 conflicting context pair(s) with node memory, 5 node(s) had untolerated taint(s). no new claims to deallocate, preemption: 0/6 nodes are available: 1 No preemption victims found for incoming pod, 5 Preemption is not helpful for scheduling."
0.3662,Event,ADDED,eval-sanitize-1-r0-154-9c596.18d4a20bab441699,"reason=FailedScheduling count=None msg=0/6 nodes are available: 1 c_wall violated: 1 conflicting context pair(s) with node memory, 5 node(s) had untolerated taint(s). no new claims to deallocate, preemption: 0/6 nodes are available: 1 No preemption victims found for incoming pod, 5 Preemption is not helpful for scheduling."
0.3663,Event,ADDED,eval-sanitize-1-r0-154-9c596.18d4a20bb67c5ad0,reason=Scheduled count=None msg=Successfully assigned compute/eval-sanitize-1-r0-154-9c596 to kind-worker3
0.3665,Event,ADDED,eval-sanitize-1-r0-154-9c596.18d4a20bd3b00a60,"reason=Pulled count=1 msg=Container image ""busybox:musl"" already present on machine"
0.3667,Event,ADDED,eval-sanitize-1-r0-154-9c596.18d4a20bd71b2021,reason=Created count=1 msg=Created container: task
0.3669,Event,ADDED,eval-sanitize-1-r0-154-9c596.18d4a20bda8b85ad,reason=Started count=1 msg=Started container task
0.3671,Event,ADDED,eval-sanitize-1-r0-154.18d4a20861614257,reason=SuccessfulCreate count=1 msg=Created pod: eval-sanitize-1-r0-154-9c596
0.3673,Event,ADDED,eval-sanitize-1-r0-154.18d4a21236f8ddbc,reason=Completed count=1 msg=Job completed
0.3675,Event,ADDED,eval-sanitize-1-r0-155-dfm25.18d4a2089cb43554,"reason=FailedScheduling count=None msg=0/6 nodes are available: 6 node(s) had untolerated taint(s). no new claims to deallocate, preemption: 0/6 nodes are available: 6 Preemption is not helpful for scheduling."
0.3677,Event,ADDED,eval-sanitize-1-r0-155-dfm25.18d4a20b48e090be,"reason=FailedScheduling count=None msg=0/6 nodes are available: 1 c_wall violated: 2 conflicting context pair(s) with node memory, 5 node(s) had untolerated taint(s). no new claims to deallocate, preemption: 0/6 nodes are available: 1 No preemption victims found for incoming pod, 5 Preemption is not helpful for scheduling."
0.3679,Event,ADDED,eval-sanitize-1-r0-155-dfm25.18d4a20b5c2eb837,"reason=FailedScheduling count=None msg=0/6 nodes are available: 1 c_wall violated: 2 conflicting context pair(s) with node memory, 5 node(s) had untolerated taint(s). no new claims to deallocate, preemption: 0/6 nodes are available: 1 No preemption victims found for incoming pod, 5 Preemption is not helpful for scheduling."
0.3684,Event,ADDED,eval-sanitize-1-r0-155-dfm25.18d4a20b9bc18640,"reason=FailedScheduling count=None msg=0/6 nodes are available: 1 c_wall violated: 1 conflicting context pair(s) with node memory, 5 node(s) had untolerated taint(s). no new claims to deallocate, preemption: 0/6 nodes are available: 1 No preemption victims found for incoming pod, 5 Preemption is not helpful for scheduling."
0.3686,Event,ADDED,eval-sanitize-1-r0-155-dfm25.18d4a20bab7f6311,"reason=FailedScheduling count=None msg=0/6 nodes are available: 1 c_wall violated: 1 conflicting context pair(s) with node memory, 5 node(s) had untolerated taint(s). no new claims to deallocate, preemption: 0/6 nodes are available: 1 No preemption victims found for incoming pod, 5 Preemption is not helpful for scheduling."
0.3687,Event,ADDED,eval-sanitize-1-r0-155-dfm25.18d4a20bcd0cf81e,"reason=FailedScheduling count=None msg=0/6 nodes are available: 2 c_wall violated: 1 conflicting context pair(s) with node memory, 4 node(s) had untolerated taint(s). no new claims to deallocate, preemption: 0/6 nodes are available: 2 No preemption victims found for incoming pod, 4 Preemption is not helpful for scheduling."
0.3691,Event,ADDED,eval-sanitize-1-r0-155-dfm25.18d4a20be4fcade3,"reason=FailedScheduling count=None msg=0/6 nodes are available: 1 c_wall violated: 1 conflicting context pair(s) with node memory, 5 node(s) had untolerated taint(s). no new claims to deallocate, preemption: 0/6 nodes are available: 1 No preemption victims found for incoming pod, 5 Preemption is not helpful for scheduling."
0.3692,Event,ADDED,eval-sanitize-1-r0-155-dfm25.18d4a20c7771d292,reason=Scheduled count=None msg=Successfully assigned compute/eval-sanitize-1-r0-155-dfm25 to kind-worker5
0.3694,Event,ADDED,eval-sanitize-1-r0-155-dfm25.18d4a20c92ea0f70,"reason=Pulled count=1 msg=Container image ""busybox:musl"" already present on machine"
0.3695,Event,ADDED,eval-sanitize-1-r0-155-dfm25.18d4a20c95e80255,reason=Created count=1 msg=Created container: task
0.3698,Event,ADDED,eval-sanitize-1-r0-155-dfm25.18d4a20c9a23aa77,reason=Started count=1 msg=Started container task
0.37,Event,ADDED,eval-sanitize-1-r0-155.18d4a2089cac8d10,reason=SuccessfulCreate count=1 msg=Created pod: eval-sanitize-1-r0-155-dfm25
0.3702,Event,ADDED,eval-sanitize-1-r0-155.18d4a212f41e4561,reason=Completed count=1 msg=Job completed
0.3704,Event,ADDED,eval-sanitize-1-r0-156-r7qpd.18d4a208d8387c5c,"reason=FailedScheduling count=None msg=0/6 nodes are available: 6 node(s) had untolerated taint(s). no new claims to deallocate, preemption: 0/6 nodes are available: 6 Preemption is not helpful for scheduling."
0.3705,Event,ADDED,eval-sanitize-1-r0-156-r7qpd.18d4a20b4e120520,reason=Scheduled count=None msg=Successfully assigned compute/eval-sanitize-1-r0-156-r7qpd to kind-worker
0.3707,Event,ADDED,eval-sanitize-1-r0-156-r7qpd.18d4a20b65c70eee,"reason=Pulled count=1 msg=Container image ""busybox:musl"" already present on machine"
0.3709,Event,ADDED,eval-sanitize-1-r0-156-r7qpd.18d4a20b672de578,reason=Created count=1 msg=Created container: task
0.3711,Event,ADDED,eval-sanitize-1-r0-156-r7qpd.18d4a20b694c260c,reason=Started count=1 msg=Started container task
0.3712,Event,ADDED,eval-sanitize-1-r0-156.18d4a208d82e5d5f,reason=SuccessfulCreate count=1 msg=Created pod: eval-sanitize-1-r0-156-r7qpd
0.3714,Event,ADDED,eval-sanitize-1-r0-156.18d4a210f2c336ff,reason=Completed count=1 msg=Job completed
0.3715,Event,ADDED,eval-sanitize-1-r0-157-hx2rb.18d4a20913f6dbab,"reason=FailedScheduling count=None msg=0/6 nodes are available: 6 node(s) had untolerated taint(s). no new claims to deallocate, preemption: 0/6 nodes are available: 6 Preemption is not helpful for scheduling."
0.3717,Event,ADDED,eval-sanitize-1-r0-157-hx2rb.18d4a20b4dda7dba,"reason=FailedScheduling count=None msg=0/6 nodes are available: 1 c_wall violated: 2 conflicting context pair(s) with node memory, 5 node(s) had untolerated taint(s). no new claims to deallocate, preemption: 0/6 nodes are available: 1 No preemption victims found for incoming pod, 5 Preemption is not helpful for scheduling."
0.3719,Event,ADDED,eval-sanitize-1-r0-157-hx2rb.18d4a20b5c5dc25b,"reason=FailedScheduling count=None msg=0/6 nodes are available: 1 c_wall violated: 2 conflicting context pair(s) with node memory, 5 node(s) had untolerated taint(s). no new claims to deallocate, preemption: 0/6 nodes are available: 1 No preemption victims found for incoming pod, 5 Preemption is not helpful for scheduling."
0.372,Event,ADDED,eval-sanitize-1-r0-157-hx2rb.18d4a20b9c4753b5,"reason=FailedScheduling count=None msg=0/6 nodes are available: 1 c_wall violated: 1 conflicting context pair(s) with node memory, 5 node(s) had untolerated taint(s). no new claims to deallocate, preemption: 0/6 nodes are available: 1 No preemption victims found for incoming pod, 5 Preemption is not helpful for scheduling."
0.3722,Event,ADDED,eval-sanitize-1-r0-157-hx2rb.18d4a20babbdf0fb,"reason=FailedScheduling count=None msg=0/6 nodes are available: 1 c_wall violated: 1 conflicting context pair(s) with node memory, 5 node(s) had untolerated taint(s). no new claims to deallocate, preemption: 0/6 nodes are available: 1 No preemption victims found for incoming pod, 5 Preemption is not helpful for scheduling."
0.3724,Event,ADDED,eval-sanitize-1-r0-157-hx2rb.18d4a20bcdc77847,"reason=FailedScheduling count=None msg=0/6 nodes are available: 2 c_wall violated: 1 conflicting context pair(s) with node memory, 4 node(s) had untolerated taint(s). no new claims to deallocate, preemption: 0/6 nodes are available: 2 No preemption victims found for incoming pod, 4 Preemption is not helpful for scheduling."
0.3727,Event,ADDED,eval-sanitize-1-r0-157-hx2rb.18d4a20be5387756,"reason=FailedScheduling count=None msg=0/6 nodes are available: 1 c_wall violated: 1 conflicting context pair(s) with node memory, 5 node(s) had untolerated taint(s). no new claims to deallocate, preemption: 0/6 nodes are available: 1 No preemption victims found for incoming pod, 5 Preemption is not helpful for scheduling."
0.3728,Event,ADDED,eval-sanitize-1-r0-157-hx2rb.18d4a20c727ee634,reason=Scheduled count=None msg=Successfully assigned compute/eval-sanitize-1-r0-157-hx2rb to kind-worker5
0.373,Event,ADDED,eval-sanitize-1-r0-157-hx2rb.18d4a20c8dc15e07,"reason=Pulled count=1 msg=Container image ""busybox:musl"" already present on machine"
0.3731,Event,ADDED,eval-sanitize-1-r0-157-hx2rb.18d4a20c8f41b818,reason=Created count=1 msg=Created container: task
0.3734,Event,ADDED,eval-sanitize-1-r0-157-hx2rb.18d4a20c9150b84b,reason=Started count=1 msg=Started container task
0.3736,Event,ADDED,eval-sanitize-1-r0-157.18d4a20913eac323,reason=SuccessfulCreate count=1 msg=Created pod: eval-sanitize-1-r0-157-hx2rb
0.3738,Event,ADDED,eval-sanitize-1-r0-157.18d4a212e26e75c3,reason=Completed count=1 msg=Job completed
0.3739,Event,ADDED,eval-sanitize-1-r0-158-fcvs4.18d4a209513a3483,"reason=FailedScheduling count=None msg=0/6 nodes are available: 6 node(s) had untolerated taint(s). no new claims to deallocate, preemption: 0/6 nodes are available: 6 Preemption is not helpful for scheduling."
0.3742,Event,ADDED,eval-sanitize-1-r0-158-fcvs4.18d4a20b4e7dee2e,"reason=FailedScheduling count=None msg=0/6 nodes are available: 1 c_wall violated: 1 conflicting context pair(s) with node memory, 5 node(s) had untolerated taint(s). no new claims to deallocate, preemption: 0/6 nodes are available: 1 No preemption victims found for incoming pod, 5 Preemption is not helpful for scheduling."
0.3744,Event,ADDED,eval-sanitize-1-r0-158-fcvs4.18d4a20b5c8cb8c7,"reason=FailedScheduling count=None msg=0/6 nodes are available: 1 c_wall violated: 1 conflicting context pair(s) with node memory, 5 node(s) had untolerated taint(s). no new claims to deallocate, preemption: 0/6 nodes are available: 1 No preemption victims found for incoming pod, 5 Preemption is not helpful for scheduling."
0.3746,Event,ADDED,eval-sanitize-1-r0-158-fcvs4.18d4a20b9cd3a75a,"reason=FailedScheduling count=None msg=0/6 nodes are available: 1 c_wall violated: 1 conflicting context pair(s) with node memory, 5 node(s) had untolerated taint(s). no new claims to deallocate, preemption: 0/6 nodes are available: 1 No preemption victims found for incoming pod, 5 Preemption is not helpful for scheduling."
0.3748,Event,ADDED,eval-sanitize-1-r0-158-fcvs4.18d4a20babed1741,"reason=FailedScheduling count=None msg=0/6 nodes are available: 1 c_wall violated: 1 conflicting context pair(s) with node memory, 5 node(s) had untolerated taint(s). no new claims to deallocate, preemption: 0/6 nodes are available: 1 No preemption victims found for incoming pod, 5 Preemption is not helpful for scheduling."
0.375,Event,ADDED,eval-sanitize-1-r0-158-fcvs4.18d4a20bbcfa5a29,reason=Scheduled count=None msg=Successfully assigned compute/eval-sanitize-1-r0-158-fcvs4 to kind-worker3
0.3752,Event,ADDED,eval-sanitize-1-r0-158-fcvs4.18d4a20bda3ecd93,"reason=Pulled count=1 msg=Container image ""busybox:musl"" already present on machine"
0.3754,Event,ADDED,eval-sanitize-1-r0-158-fcvs4.18d4a20bdbba5b71,reason=Created count=1 msg=Created container: task
0.3756,Event,ADDED,eval-sanitize-1-r0-158-fcvs4.18d4a20be4e7cb6e,reason=Started count=1 msg=Started container task
0.3758,Event,ADDED,eval-sanitize-1-r0-158.18d4a209512d4d3e,reason=SuccessfulCreate count=1 msg=Created pod: eval-sanitize-1-r0-158-fcvs4
0.3759,Event,ADDED,eval-sanitize-1-r0-158.18d4a212666f0920,reason=Completed count=1 msg=Job completed
0.3761,Event,ADDED,eval-sanitize-1-r0-159-zhk8t.18d4a2098af1146c,"reason=FailedScheduling count=None msg=0/6 nodes are available: 6 node(s) had untolerated taint(s). no new claims to deallocate, preemption: 0/6 nodes are available: 6 Preemption is not helpful for scheduling."
0.3762,Event,ADDED,eval-sanitize-1-r0-159-zhk8t.18d4a20b4f281f63,"reason=FailedScheduling count=None msg=0/6 nodes are available: 1 c_wall violated: 1 conflicting context pair(s) with node memory, 5 node(s) had untolerated taint(s). no new claims to deallocate, preemption: 0/6 nodes are available: 1 No preemption victims found for incoming pod, 5 Preemption is not helpful for scheduling."
0.3764,Event,ADDED,eval-sanitize-1-r0-159-zhk8t.18d4a20b60cee925,"reason=FailedScheduling count=None msg=0/6 nodes are available: 1 c_wall violated: 1 conflicting context pair(s) with node memory, 5 node(s) had untolerated taint(s). no new claims to deallocate, preemption: 0/6 nodes are available: 1 No preemption victims found for incoming pod, 5 Preemption is not helpful for scheduling."
0.3766,Event,ADDED,eval-sanitize-1-r0-159-zhk8t.18d4a20b9d4ecd5b,"reason=FailedScheduling count=None msg=0/6 nodes are available: 1 c_wall violated: 1 conflicting context pair(s) with node memory, 5 node(s) had untolerated taint(s). no new claims to deallocate, preemption: 0/6 nodes are available: 1 No preemption victims found for incoming pod, 5 Preemption is not helpful for scheduling."
0.3767,Event,ADDED,eval-sanitize-1-r0-159-zhk8t.18d4a20baf3d7f9f,"reason=FailedScheduling count=None msg=0/6 nodes are available: 1 c_wall violated: 1 conflicting context pair(s) with node memory, 5 node(s) had untolerated taint(s). no new claims to deallocate, preemption: 0/6 nodes are available: 1 No preemption victims found for incoming pod, 5 Preemption is not helpful for scheduling."
0.3769,Event,ADDED,eval-sanitize-1-r0-159-zhk8t.18d4a20bc1794c66,reason=Scheduled count=None msg=Successfully assigned compute/eval-sanitize-1-r0-159-zhk8t to kind-worker3
0.3771,Event,ADDED,eval-sanitize-1-r0-159-zhk8t.18d4a20be5448b1c,"reason=Pulled count=1 msg=Container image ""busybox:musl"" already present on machine"
0.3772,Event,ADDED,eval-sanitize-1-r0-159-zhk8t.18d4a20be7bb3258,reason=Created count=1 msg=Created container: task
0.3774,Event,ADDED,eval-sanitize-1-r0-159-zhk8t.18d4a20beb6372fe,reason=Started count=1 msg=Started container task
0.3823,Event,ADDED,eval-sanitize-1-r0-159.18d4a2098ae79444,reason=SuccessfulCreate count=1 msg=Created pod: eval-sanitize-1-r0-159-zhk8t
0.3828,Event,ADDED,eval-sanitize-1-r0-159.18d4a212523c0907,reason=Completed count=1 msg=Job completed
0.3832,Event,ADDED,eval-sanitize-1-r0-160-t77ng.18d4a209c6904123,"reason=FailedScheduling count=None msg=0/6 nodes are available: 6 node(s) had untolerated taint(s). no new claims to deallocate, preemption: 0/6 nodes are available: 6 Preemption is not helpful for scheduling."
0.3835,Event,ADDED,eval-sanitize-1-r0-160-t77ng.18d4a20b5374b27e,"reason=FailedScheduling count=None msg=0/6 nodes are available: 1 c_wall violated: 1 conflicting context pair(s) with node memory, 5 node(s) had untolerated taint(s). no new claims to deallocate, preemption: 0/6 nodes are available: 1 No preemption victims found for incoming pod, 5 Preemption is not helpful for scheduling."
0.3839,Event,ADDED,eval-sanitize-1-r0-160-t77ng.18d4a20b6103f753,"reason=FailedScheduling count=None msg=0/6 nodes are available: 1 c_wall violated: 1 conflicting context pair(s) with node memory, 5 node(s) had untolerated taint(s). no new claims to deallocate, preemption: 0/6 nodes are available: 1 No preemption victims found for incoming pod, 5 Preemption is not helpful for scheduling."
0.3841,Event,ADDED,eval-sanitize-1-r0-160-t77ng.18d4a20ba0ed95cc,"reason=FailedScheduling count=None msg=0/6 nodes are available: 1 c_wall violated: 1 conflicting context pair(s) with node memory, 5 node(s) had untolerated taint(s). no new claims to deallocate, preemption: 0/6 nodes are available: 1 No preemption victims found for incoming pod, 5 Preemption is not helpful for scheduling."
0.3842,Event,ADDED,eval-sanitize-1-r0-160-t77ng.18d4a20baf76e2ad,"reason=FailedScheduling count=None msg=0/6 nodes are available: 1 c_wall violated: 1 conflicting context pair(s) with node memory, 5 node(s) had untolerated taint(s). no new claims to deallocate, preemption: 0/6 nodes are available: 1 No preemption victims found for incoming pod, 5 Preemption is not helpful for scheduling."
0.3846,Event,ADDED,eval-sanitize-1-r0-160-t77ng.18d4a20bc1d98fb7,reason=Scheduled count=None msg=Successfully assigned compute/eval-sanitize-1-r0-160-t77ng to kind-worker3
0.3848,Event,ADDED,eval-sanitize-1-r0-160-t77ng.18d4a20be4934360,"reason=Pulled count=1 msg=Container image ""busybox:musl"" already present on machine"
0.385,Event,ADDED,eval-sanitize-1-r0-160-t77ng.18d4a20be77985a4,reason=Created count=1 msg=Created container: task
0.3852,Event,ADDED,eval-sanitize-1-r0-160-t77ng.18d4a20beb643f0c,reason=Started count=1 msg=Started container task
0.3855,Event,ADDED,eval-sanitize-1-r0-160.18d4a209c6861502,reason=SuccessfulCreate count=1 msg=Created pod: eval-sanitize-1-r0-160-t77ng
0.3857,Event,ADDED,eval-sanitize-1-r0-160.18d4a212549fb266,reason=Completed count=1 msg=Job completed
0.3859,Event,ADDED,eval-sanitize-1-r0-161-9jp9t.18d4a20a0288c000,"reason=FailedScheduling count=None msg=0/6 nodes are available: 6 node(s) had untolerated taint(s). no new claims to deallocate, preemption: 0/6 nodes are available: 6 Preemption is not helpful for scheduling."
0.3862,Event,ADDED,eval-sanitize-1-r0-161-9jp9t.18d4a20b5469c052,"reason=FailedScheduling count=None msg=0/6 nodes are available: 1 c_wall violated: 1 conflicting context pair(s) with node memory, 5 node(s) had untolerated taint(s). no new claims to deallocate, preemption: 0/6 nodes are available: 1 No preemption victims found for incoming pod, 5 Preemption is not helpful for scheduling."
0.3865,Event,ADDED,eval-sanitize-1-r0-161-9jp9t.18d4a20b61e5fdd7,"reason=FailedScheduling count=None msg=0/6 nodes are available: 1 c_wall violated: 1 conflicting context pair(s) with node memory, 5 node(s) had untolerated taint(s). no new claims to deallocate, preemption: 0/6 nodes are available: 1 No preemption victims found for incoming pod, 5 Preemption is not helpful for scheduling."
0.3866,Event,ADDED,eval-sanitize-1-r0-161-9jp9t.18d4a20ba2c3f18e,reason=Scheduled count=None msg=Successfully assigned compute/eval-sanitize-1-r0-161-9jp9t to kind-worker4
0.3868,Event,ADDED,eval-sanitize-1-r0-161-9jp9t.18d4a20bbe2c0751,"reason=Pulled count=1 msg=Container image ""busybox:musl"" already present on machine"
0.3873,Event,ADDED,eval-sanitize-1-r0-161-9jp9t.18d4a20bbff8f611,reason=Created count=1 msg=Created container: task
0.3875,Event,ADDED,eval-sanitize-1-r0-161-9jp9t.18d4a20bc34fd520,reason=Started count=1 msg=Started container task
0.3877,Event,ADDED,eval-sanitize-1-r0-161.18d4a20a0278acba,reason=SuccessfulCreate count=1 msg=Created pod: eval-sanitize-1-r0-161-9jp9t
0.3881,Event,ADDED,eval-sanitize-1-r0-161.18d4a21234e8e9f7,reason=Completed count=1 msg=Job completed
0.3883,Event,ADDED,eval-sanitize-1-r0-162-jv62p.18d4a20a3e5391fe,"reason=FailedScheduling count=None msg=0/6 nodes are available: 6 node(s) had untolerated taint(s). no new claims to deallocate, preemption: 0/6 nodes are available: 6 Preemption is not helpful for scheduling."
0.3884,Event,ADDED,eval-sanitize-1-r0-162-jv62p.18d4a20b551d29af,"reason=FailedScheduling count=None msg=0/6 nodes are available: 1 c_wall violated: 1 conflicting context pair(s) with node memory, 5 node(s) had untolerated taint(s). no new claims to deallocate, preemption: 0/6 nodes are available: 1 No preemption victims found for incoming pod, 5 Preemption is not helpful for scheduling."
0.3888,Event,ADDED,eval-sanitize-1-r0-162-jv62p.18d4a20b62196cf2,"reason=FailedScheduling count=None msg=0/6 nodes are available: 1 c_wall violated: 1 conflicting context pair(s) with node memory, 5 node(s) had untolerated taint(s). no new claims to deallocate, preemption: 0/6 nodes are available: 1 No preemption victims found for incoming pod, 5 Preemption is not helpful for scheduling."
0.3891,Event,ADDED,eval-sanitize-1-r0-162-jv62p.18d4a20ba2a2cc51,"reason=FailedScheduling count=None msg=0/6 nodes are available: 1 c_wall violated: 1 conflicting context pair(s) with node memory, 5 node(s) had untolerated taint(s). no new claims to deallocate, preemption: 0/6 nodes are available: 1 No preemption victims found for incoming pod, 5 Preemption is not helpful for scheduling."
0.3893,Event,ADDED,eval-sanitize-1-r0-162-jv62p.18d4a20bafb631dd,"reason=FailedScheduling count=None msg=0/6 nodes are available: 1 c_wall violated: 1 conflicting context pair(s) with node memory, 5 node(s) had untolerated taint(s). no new claims to deallocate, preemption: 0/6 nodes are available: 1 No preemption victims found for incoming pod, 5 Preemption is not helpful for scheduling."
0.39,Event,ADDED,eval-sanitize-1-r0-162-jv62p.18d4a20bd33a4b12,"reason=FailedScheduling count=None msg=0/6 nodes are available: 2 c_wall violated: 1 conflicting context pair(s) with node memory, 4 node(s) had untolerated taint(s). no new claims to deallocate, preemption: 0/6 nodes are available: 2 No preemption victims found for incoming pod, 4 Preemption is not helpful for scheduling."
0.3902,Event,ADDED,eval-sanitize-1-r0-162-jv62p.18d4a20be56d2610,"reason=FailedScheduling count=None msg=0/6 nodes are available: 1 c_wall violated: 1 conflicting context pair(s) with node memory, 5 node(s) had untolerated taint(s). no new claims to deallocate, preemption: 0/6 nodes are available: 1 No preemption victims found for incoming pod, 5 Preemption is not helpful for scheduling."
0.3905,Event,ADDED,eval-sanitize-1-r0-162-jv62p.18d4a20c72656a86,"reason=FailedScheduling count=None msg=0/6 nodes are available: 1 c_wall violated: 1 conflicting context pair(s) with node memory, 5 node(s) had untolerated taint(s). no new claims to deallocate, preemption: 0/6 nodes are available: 1 No preemption victims found for incoming pod, 5 Preemption is not helpful for scheduling."
0.391,Event,ADDED,eval-sanitize-1-r0-162-jv62p.18d4a20c7770441f,"reason=FailedScheduling count=None msg=0/6 nodes are available: 1 c_wall violated: 3 conflicting context pair(s) with node memory, 5 node(s) had untolerated taint(s). no new claims to deallocate, preemption: 0/6 nodes are available: 1 No preemption victims found for incoming pod, 5 Preemption is not helpful for scheduling."
0.3913,Event,ADDED,eval-sanitize-1-r0-162-jv62p.18d4a20c78675c00,"reason=FailedScheduling count=None msg=0/6 nodes are available: 1 c_wall violated: 3 conflicting context pair(s) with node memory, 5 node(s) had untolerated taint(s). no new claims to deallocate, preemption: 0/6 nodes are available: 1 No preemption victims found for incoming pod, 5 Preemption is not helpful for scheduling."
0.3915,Event,ADDED,eval-sanitize-1-r0-162-jv62p.18d4a20cdd98b0d4,reason=Scheduled count=None msg=Successfully assigned compute/eval-sanitize-1-r0-162-jv62p to kind-worker2
0.3918,Event,ADDED,eval-sanitize-1-r0-162-jv62p.18d4a20cf8f0a4be,"reason=Pulled count=1 msg=Container image ""busybox:musl"" already present on machine"
0.392,Event,ADDED,eval-sanitize-1-r0-162-jv62p.18d4a20cf9fcaaa3,reason=Created count=1 msg=Created container: task
0.3922,Event,ADDED,eval-sanitize-1-r0-162-jv62p.18d4a20cfbdc5953,reason=Started count=1 msg=Started container task
0.3923,Event,ADDED,eval-sanitize-1-r0-162.18d4a20a3e487252,reason=SuccessfulCreate count=1 msg=Created pod: eval-sanitize-1-r0-162-jv62p
0.3927,Event,ADDED,eval-sanitize-1-r0-162.18d4a2132b353900,reason=Completed count=1 msg=Job completed
0.3928,Event,ADDED,eval-sanitize-1-r0-163-bpht9.18d4a20a799f9194,"reason=FailedScheduling count=None msg=0/6 nodes are available: 6 node(s) had untolerated taint(s). no new claims to deallocate, preemption: 0/6 nodes are available: 6 Preemption is not helpful for scheduling."
0.393,Event,ADDED,eval-sanitize-1-r0-163-bpht9.18d4a20b55a8def6,"reason=FailedScheduling count=None msg=0/6 nodes are available: 1 c_wall violated: 1 conflicting context pair(s) with node memory, 5 node(s) had untolerated taint(s). no new claims to deallocate, preemption: 0/6 nodes are available: 1 No preemption victims found for incoming pod, 5 Preemption is not helpful for scheduling."
0.3934,Event,ADDED,eval-sanitize-1-r0-163-bpht9.18d4a20b6248ed3e,"reason=FailedScheduling count=None msg=0/6 nodes are available: 1 c_wall violated: 1 conflicting context pair(s) with node memory, 5 node(s) had untolerated taint(s). no new claims to deallocate, preemption: 0/6 nodes are available: 1 No preemption victims found for incoming pod, 5 Preemption is not helpful for scheduling."
0.3936,Event,ADDED,eval-sanitize-1-r0-163-bpht9.18d4a20ba32be396,"reason=FailedScheduling count=None msg=0/6 nodes are available: 1 c_wall violated: 1 conflicting context pair(s) with node memory, 5 node(s) had untolerated taint(s). no new claims to deallocate, preemption: 0/6 nodes are available: 1 No preemption victims found for incoming pod, 5 Preemption is not helpful for scheduling."
0.3939,Event,ADDED,eval-sanitize-1-r0-163-bpht9.18d4a20bafeeb155,"reason=FailedScheduling count=None msg=0/6 nodes are available: 1 c_wall violated: 1 conflicting context pair(s) with node memory, 5 node(s) had untolerated taint(s). no new claims to deallocate, preemption: 0/6 nodes are available: 1 No preemption victims found for incoming pod, 5 Preemption is not helpful for scheduling."
0.3941,Event,ADDED,eval-sanitize-1-r0-163-bpht9.18d4a20bc89a4662,reason=Scheduled count=None msg=Successfully assigned compute/eval-sanitize-1-r0-163-bpht9 to kind-worker3
0.3942,Event,ADDED,eval-sanitize-1-r0-163-bpht9.18d4a20bea3bbd3d,"reason=Pulled count=1 msg=Container image ""busybox:musl"" already present on machine"
0.3945,Event,ADDED,eval-sanitize-1-r0-163-bpht9.18d4a20beba7f995,reason=Created count=1 msg=Created container: task
0.3947,Event,ADDED,eval-sanitize-1-r0-163-bpht9.18d4a20bf010faf9,reason=Started count=1 msg=Started container task
0.3948,Event,ADDED,eval-sanitize-1-r0-163.18d4a20a7996c1f0,reason=SuccessfulCreate count=1 msg=Created pod: eval-sanitize-1-r0-163-bpht9
0.395,Event,ADDED,eval-sanitize-1-r0-163.18d4a212523f0df8,reason=Completed count=1 msg=Job completed
0.3952,Event,ADDED,eval-sanitize-1-r0-164-9nl2j.18d4a20ab54956ff,"reason=FailedScheduling count=None msg=0/6 nodes are available: 6 node(s) had untolerated taint(s). no new claims to deallocate, preemption: 0/6 nodes are available: 6 Preemption is not helpful for scheduling."
0.3953,Event,ADDED,eval-sanitize-1-r0-164-9nl2j.18d4a20b561b5d4e,"reason=FailedScheduling count=None msg=0/6 nodes are available: 1 c_wall violated: 1 conflicting context pair(s) with node memory, 5 node(s) had untolerated taint(s). no new claims to deallocate, preemption: 0/6 nodes are available: 1 No preemption victims found for incoming pod, 5 Preemption is not helpful for scheduling."
0.3955,Event,ADDED,eval-sanitize-1-r0-164-9nl2j.18d4a20b627ac8dc,"reason=FailedScheduling count=None msg=0/6 nodes are available: 1 c_wall violated: 1 conflicting context pair(s) with node memory, 5 node(s) had untolerated taint(s). no new claims to deallocate, preemption: 0/6 nodes are available: 1 No preemption victims found for incoming pod, 5 Preemption is not helpful for scheduling."
0.3957,Event,ADDED,eval-sanitize-1-r0-164-9nl2j.18d4a20ba3b26972,"reason=FailedScheduling count=None msg=0/6 nodes are available: 1 c_wall violated: 1 conflicting context pair(s) with node memory, 5 node(s) had untolerated taint(s). no new claims to deallocate, preemption: 0/6 nodes are available: 1 No preemption victims found for incoming pod, 5 Preemption is not helpful for scheduling."
0.3958,Event,ADDED,eval-sanitize-1-r0-164-9nl2j.18d4a20bb020d1b2,"reason=FailedScheduling count=None msg=0/6 nodes are available: 1 c_wall violated: 1 conflicting context pair(s) with node memory, 5 node(s) had untolerated taint(s). no new claims to deallocate, preemption: 0/6 nodes are available: 1 No preemption victims found for incoming pod, 5 Preemption is not helpful for scheduling."
0.396,Event,ADDED,eval-sanitize-1-r0-164-9nl2j.18d4a20bc8bd35be,reason=Scheduled count=None msg=Successfully assigned compute/eval-sanitize-1-r0-164-9nl2j to kind-worker3
0.3962,Event,ADDED,eval-sanitize-1-r0-164-9nl2j.18d4a20bebbc3c38,"reason=Pulled count=1 msg=Container image ""busybox:musl"" already present on machine"
0.3964,Event,ADDED,eval-sanitize-1-r0-164-9nl2j.18d4a20bed408ab3,reason=Created count=1 msg=Created container: task
0.3966,Event,ADDED,eval-sanitize-1-r0-164-9nl2j.18d4a20bf0cc191e,reason=Started count=1 msg=Started container task
0.3968,Event,ADDED,eval-sanitize-1-r0-164.18d4a20ab5405f1a,reason=SuccessfulCreate count=1 msg=Created pod: eval-sanitize-1-r0-164-9nl2j
0.3974,Event,ADDED,eval-sanitize-1-r0-164.18d4a212523c125d,reason=Completed count=1 msg=Job completed
0.3976,Event,ADDED,eval-sanitize-1-r0-165-l845j.18d4a20af1b0e5ca,"reason=FailedScheduling count=None msg=0/6 nodes are available: 6 node(s) had untolerated taint(s). no new claims to deallocate, preemption: 0/6 nodes are available: 6 Preemption is not helpful for scheduling."
0.3977,Event,ADDED,eval-sanitize-1-r0-165-l845j.18d4a20b596b6e3a,reason=Scheduled count=None msg=Successfully assigned compute/eval-sanitize-1-r0-165-l845j to kind-worker
0.3979,Event,ADDED,eval-sanitize-1-r0-165-l845j.18d4a20b75a0e431,"reason=Pulled count=1 msg=Container image ""busybox:musl"" already present on machine"
0.3983,Event,ADDED,eval-sanitize-1-r0-165-l845j.18d4a20b76f8465e,reason=Created count=1 msg=Created container: task
0.3985,Event,ADDED,eval-sanitize-1-r0-165-l845j.18d4a20b7bf0ba50,reason=Started count=1 msg=Started container task
0.3987,Event,ADDED,eval-sanitize-1-r0-165.18d4a20af1a0644b,reason=SuccessfulCreate count=1 msg=Created pod: eval-sanitize-1-r0-165-l845j
0.399,Event,ADDED,eval-sanitize-1-r0-165.18d4a210f39f44cb,reason=Completed count=1 msg=Job completed
0.3992,Event,ADDED,eval-sanitize-1-r0-166-kqqrs.18d4a20b2d3c5e57,"reason=FailedScheduling count=None msg=0/6 nodes are available: 6 node(s) had untolerated taint(s). no new claims to deallocate, preemption: 0/6 nodes are available: 6 Preemption is not helpful for scheduling."
0.3994,Event,ADDED,eval-sanitize-1-r0-166-kqqrs.18d4a20b56cfa328,"reason=FailedScheduling count=None msg=0/6 nodes are available: 1 c_wall violated: 1 conflicting context pair(s) with node memory, 5 node(s) had untolerated taint(s). no new claims to deallocate, preemption: 0/6 nodes are available: 1 No preemption victims found for incoming pod, 5 Preemption is not helpful for scheduling."
0.3997,Event,ADDED,eval-sanitize-1-r0-166-kqqrs.18d4a20b62aaee81,"reason=FailedScheduling count=None msg=0/6 nodes are available: 1 c_wall violated: 1 conflicting context pair(s) with node memory, 5 node(s) had untolerated taint(s). no new claims to deallocate, preemption: 0/6 nodes are available: 1 No preemption victims found for incoming pod, 5 Preemption is not helpful for scheduling."
0.3999,Event,ADDED,eval-sanitize-1-r0-166-kqqrs.18d4a20ba4368e2f,"reason=FailedScheduling count=None msg=0/6 nodes are available: 1 c_wall violated: 1 conflicting context pair(s) with node memory, 5 node(s) had untolerated taint(s). no new claims to deallocate, preemption: 0/6 nodes are available: 1 No preemption victims found for incoming pod, 5 Preemption is not helpful for scheduling."
0.4001,Event,ADDED,eval-sanitize-1-r0-166-kqqrs.18d4a20bb4237818,"reason=FailedScheduling count=None msg=0/6 nodes are available: 1 c_wall violated: 1 conflicting context pair(s) with node memory, 5 node(s) had untolerated taint(s). no new claims to deallocate, preemption: 0/6 nodes are available: 1 No preemption victims found for incoming pod, 5 Preemption is not helpful for scheduling."
0.4005,Event,ADDED,eval-sanitize-1-r0-166-kqqrs.18d4a20bd3a1d550,"reason=FailedScheduling count=None msg=0/6 nodes are available: 1 c_wall violated: 1 conflicting context pair(s) with node memory, 1 c_wall violated: 2 conflicting context pair(s) with node memory, 4 node(s) had untolerated taint(s). no new claims to deallocate, preemption: 0/6 nodes are available: 2 No preemption victims found for incoming pod, 4 Preemption is not helpful for scheduling."
0.4007,Event,ADDED,eval-sanitize-1-r0-166-kqqrs.18d4a20be5a884b5,"reason=FailedScheduling count=None msg=0/6 nodes are available: 1 c_wall violated: 2 conflicting context pair(s) with node memory, 5 node(s) had untolerated taint(s). no new claims to deallocate, preemption: 0/6 nodes are available: 1 No preemption victims found for incoming pod, 5 Preemption is not helpful for scheduling."
0.4008,Event,ADDED,eval-sanitize-1-r0-166-kqqrs.18d4a20c73626064,reason=Scheduled count=None msg=Successfully assigned compute/eval-sanitize-1-r0-166-kqqrs to kind-worker5
0.4012,Event,ADDED,eval-sanitize-1-r0-166-kqqrs.18d4a20c92b1fc72,"reason=Pulled count=1 msg=Container image ""busybox:musl"" already present on machine"
0.4014,Event,ADDED,eval-sanitize-1-r0-166-kqqrs.18d4a20c94dbb800,reason=Created count=1 msg=Created container: task
0.4017,Event,ADDED,eval-sanitize-1-r0-166-kqqrs.18d4a20c9a2602fe,reason=Started count=1 msg=Started container task
0.4018,Event,ADDED,eval-sanitize-1-r0-166.18d4a20b2d3044f6,reason=SuccessfulCreate count=1 msg=Created pod: eval-sanitize-1-r0-166-kqqrs
0.4021,Event,ADDED,eval-sanitize-1-r0-166.18d4a212e39d1b86,reason=Completed count=1 msg=Job completed
0.4023,Event,ADDED,eval-sanitize-1-r0-167-9hvz4.18d4a20b76219341,"reason=FailedScheduling count=None msg=0/6 nodes are available: 1 c_wall violated: 1 conflicting context pair(s) with node memory, 5 node(s) had untolerated taint(s). no new claims to deallocate, preemption: 0/6 nodes are available: 1 No preemption victims found for incoming pod, 5 Preemption is not helpful for scheduling."
0.4025,Event,ADDED,eval-sanitize-1-r0-167-9hvz4.18d4a20b76c466e9,"reason=FailedScheduling count=None msg=0/6 nodes are available: 1 c_wall violated: 1 conflicting context pair(s) with node memory, 5 node(s) had untolerated taint(s). no new claims to deallocate, preemption: 0/6 nodes are available: 1 No preemption victims found for incoming pod, 5 Preemption is not helpful for scheduling."
0.4026,Event,ADDED,eval-sanitize-1-r0-167-9hvz4.18d4a20ba8418f0a,"reason=FailedScheduling count=None msg=0/6 nodes are available: 1 c_wall violated: 1 conflicting context pair(s) with node memory, 5 node(s) had untolerated taint(s). no new claims to deallocate, preemption: 0/6 nodes are available: 1 No preemption victims found for incoming pod, 5 Preemption is not helpful for scheduling."
0.4029,Event,ADDED,eval-sanitize-1-r0-167-9hvz4.18d4a20bb5a02f76,reason=Scheduled count=None msg=Successfully assigned compute/eval-sanitize-1-r0-167-9hvz4 to kind-worker3
0.4031,Event,ADDED,eval-sanitize-1-r0-167-9hvz4.18d4a20bd312edf2,"reason=Pulled count=1 msg=Container image ""busybox:musl"" already present on machine"
0.4035,Event,ADDED,eval-sanitize-1-r0-167-9hvz4.18d4a20bd620746a,reason=Created count=1 msg=Created container: task
0.4037,Event,ADDED,eval-sanitize-1-r0-167-9hvz4.18d4a20bdb22a1c1,reason=Started count=1 msg=Started container task
0.4039,Event,ADDED,eval-sanitize-1-r0-167.18d4a20b75ce77ea,reason=SuccessfulCreate count=1 msg=Created pod: eval-sanitize-1-r0-167-9hvz4
0.4041,Event,ADDED,eval-sanitize-1-r0-167.18d4a212614fac46,reason=Completed count=1 msg=Job completed
0.4042,Event,ADDED,eval-sanitize-1-r0-168-mj72b.18d4a20bcdaf5d6a,reason=Scheduled count=None msg=Successfully assigned compute/eval-sanitize-1-r0-168-mj72b to kind-worker3
0.4044,Event,ADDED,eval-sanitize-1-r0-168-mj72b.18d4a20bebf02119,"reason=Pulled count=1 msg=Container image ""busybox:musl"" already present on machine"
0.4045,Event,ADDED,eval-sanitize-1-r0-168-mj72b.18d4a20bed9d2b68,reason=Created count=1 msg=Created container: task
0.4047,Event,ADDED,eval-sanitize-1-r0-168-mj72b.18d4a20bf0cc5c1c,reason=Started count=1 msg=Started container task
0.4049,Event,ADDED,eval-sanitize-1-r0-168.18d4a20bc8bedf3d,reason=SuccessfulCreate count=1 msg=Created pod: eval-sanitize-1-r0-168-mj72b
0.4051,Event,ADDED,eval-sanitize-1-r0-168.18d4a212637f0220,reason=Completed count=1 msg=Job completed
0.4053,Event,ADDED,eval-sanitize-1-r0-169-cmmlr.18d4a20c349b2d95,"reason=FailedScheduling count=None msg=0/6 nodes are available: 6 node(s) had untolerated taint(s). no new claims to deallocate, preemption: 0/6 nodes are available: 6 Preemption is not helpful for scheduling."
0.4054,Event,ADDED,eval-sanitize-1-r0-169-cmmlr.18d4a20c77775864,reason=Scheduled count=None msg=Successfully assigned compute/eval-sanitize-1-r0-169-cmmlr to kind-worker5
0.4057,Event,ADDED,eval-sanitize-1-r0-169-cmmlr.18d4a20c928f41dd,"reason=Pulled count=1 msg=Container image ""busybox:musl"" already present on machine"
0.4058,Event,ADDED,eval-sanitize-1-r0-169-cmmlr.18d4a20c94554b7b,reason=Created count=1 msg=Created container: task
0.406,Event,ADDED,eval-sanitize-1-r0-169-cmmlr.18d4a20c9a2660f7,reason=Started count=1 msg=Started container task
0.4063,Event,ADDED,eval-sanitize-1-r0-169.18d4a20c349293b6,reason=SuccessfulCreate count=1 msg=Created pod: eval-sanitize-1-r0-169-cmmlr
0.4065,Event,ADDED,eval-sanitize-1-r0-169.18d4a21306bcaee3,reason=Completed count=1 msg=Job completed
0.4067,Event,ADDED,eval-sanitize-1-r0-170-lf4k4.18d4a20c7d5b5063,reason=Scheduled count=None msg=Successfully assigned compute/eval-sanitize-1-r0-170-lf4k4 to kind-worker5
0.4068,Event,ADDED,eval-sanitize-1-r0-170-lf4k4.18d4a20c93d04468,"reason=Pulled count=1 msg=Container image ""busybox:musl"" already present on machine"
0.4071,Event,ADDED,eval-sanitize-1-r0-170-lf4k4.18d4a20c96412eea,reason=Created count=1 msg=Created container: task
0.4073,Event,ADDED,eval-sanitize-1-r0-170-lf4k4.18d4a20c9a266110,reason=Started count=1 msg=Started container task
0.4075,Event,ADDED,eval-sanitize-1-r0-170.18d4a20c785a8c66,reason=SuccessfulCreate count=1 msg=Created pod: eval-sanitize-1-r0-170-lf4k4
0.4076,Event,ADDED,eval-sanitize-1-r0-170.18d4a212e9e07d86,reason=Completed count=1 msg=Job completed
0.4079,Event,ADDED,eval-sanitize-1-r0-171-x4kdh.18d4a20ca59daae8,reason=Scheduled count=None msg=Successfully assigned compute/eval-sanitize-1-r0-171-x4kdh to kind-worker5
0.408,Event,ADDED,eval-sanitize-1-r0-171-x4kdh.18d4a20cbebfca07,"reason=Pulled count=1 msg=Container image ""busybox:musl"" already present on machine"
0.4082,Event,ADDED,eval-sanitize-1-r0-171-x4kdh.18d4a20cbfd6850a,reason=Created count=1 msg=Created container: task
0.4084,Event,ADDED,eval-sanitize-1-r0-171-x4kdh.18d4a20cc3909f51,reason=Started count=1 msg=Started container task
0.4085,Event,ADDED,eval-sanitize-1-r0-171.18d4a20ca503fcc1,reason=SuccessfulCreate count=1 msg=Created pod: eval-sanitize-1-r0-171-x4kdh
0.4087,Event,ADDED,eval-sanitize-1-r0-171.18d4a21311dd7c8b,reason=Completed count=1 msg=Job completed
0.4088,Event,ADDED,eval-sanitize-1-r0-172-rzqlr.18d4a20ce0b9de60,"reason=FailedScheduling count=None msg=0/6 nodes are available: 1 c_wall violated: 1 conflicting context pair(s) with node memory, 5 node(s) had untolerated taint(s). no new claims to deallocate, preemption: 0/6 nodes are available: 1 No preemption victims found for incoming pod, 5 Preemption is not helpful for scheduling."
0.4091,Event,ADDED,eval-sanitize-1-r0-172-rzqlr.18d4a20ce1307ba2,"reason=FailedScheduling count=None msg=0/6 nodes are available: 1 c_wall violated: 1 conflicting context pair(s) with node memory, 5 node(s) had untolerated taint(s). no new claims to deallocate, preemption: 0/6 nodes are available: 1 No preemption victims found for incoming pod, 5 Preemption is not helpful for scheduling."
0.4094,Event,ADDED,eval-sanitize-1-r0-172-rzqlr.18d4a20d0c3e6961,"reason=FailedScheduling count=None msg=0/6 nodes are available: 1 c_wall violated: 2 conflicting context pair(s) with node memory, 5 node(s) had untolerated taint(s). no new claims to deallocate, preemption: 0/6 nodes are available: 1 No preemption victims found for incoming pod, 5 Preemption is not helpful for scheduling."
0.4095,Event,ADDED,eval-sanitize-1-r0-172-rzqlr.18d4a21146636134,reason=Scheduled count=None msg=Successfully assigned compute/eval-sanitize-1-r0-172-rzqlr to kind-worker
0.4098,Event,ADDED,eval-sanitize-1-r0-172-rzqlr.18d4a211627f571b,"reason=Pulled count=1 msg=Container image ""busybox:musl"" already present on machine"
0.41,Event,ADDED,eval-sanitize-1-r0-172-rzqlr.18d4a211652de64d,reason=Created count=1 msg=Created container: task
0.4101,Event,ADDED,eval-sanitize-1-r0-172-rzqlr.18d4a211677eaf1c,reason=Started count=1 msg=Started container task
0.4103,Event,ADDED,eval-sanitize-1-r0-172.18d4a20ce07e7615,reason=SuccessfulCreate count=1 msg=Created pod: eval-sanitize-1-r0-172-rzqlr
0.4105,Event,ADDED,eval-sanitize-1-r0-172.18d4a2176c85a4c3,reason=Completed count=1 msg=Job completed
0.4107,Event,ADDED,eval-sanitize-1-r0-173-tllhw.18d4a20d0b6b0132,reason=Scheduled count=None msg=Successfully assigned compute/eval-sanitize-1-r0-173-tllhw to kind-worker2
0.4108,Event,ADDED,eval-sanitize-1-r0-173-tllhw.18d4a20d3da9eeb0,"reason=Pulled count=1 msg=Container image ""busybox:musl"" already present on machine"
0.411,Event,ADDED,eval-sanitize-1-r0-173-tllhw.18d4a20d3ee2c38d,reason=Created count=1 msg=Created container: task
0.4112,Event,ADDED,eval-sanitize-1-r0-173-tllhw.18d4a20d478f5cf6,reason=Started count=1 msg=Started container task
0.4113,Event,ADDED,eval-sanitize-1-r0-173.18d4a20d0ae1a5be,reason=SuccessfulCreate count=1 msg=Created pod: eval-sanitize-1-r0-173-tllhw
0.4115,Event,ADDED,eval-sanitize-1-r0-173.18d4a21311fb4692,reason=Completed count=1 msg=Job completed
0.4117,Event,ADDED,eval-sanitize-1-r0-174-kwvsm.18d4a20d341f65f4,"reason=FailedScheduling count=None msg=0/6 nodes are available: 6 node(s) had untolerated taint(s). no new claims to deallocate, preemption: 0/6 nodes are available: 6 Preemption is not helpful for scheduling."
0.4118,Event,ADDED,eval-sanitize-1-r0-174-kwvsm.18d4a21146f82377,reason=Scheduled count=None msg=Successfully assigned compute/eval-sanitize-1-r0-174-kwvsm to kind-worker
0.412,Event,ADDED,eval-sanitize-1-r0-174-kwvsm.18d4a211648baa64,"reason=Pulled count=1 msg=Container image ""busybox:musl"" already present on machine"
0.4121,Event,ADDED,eval-sanitize-1-r0-174-kwvsm.18d4a2116971d199,reason=Created count=1 msg=Created container: task
0.4124,Event,ADDED,eval-sanitize-1-r0-174-kwvsm.18d4a21172582817,reason=Started count=1 msg=Started container task
0.4126,Event,ADDED,eval-sanitize-1-r0-174.18d4a20d3413e7ff,reason=SuccessfulCreate count=1 msg=Created pod: eval-sanitize-1-r0-174-kwvsm
0.4128,Event,ADDED,eval-sanitize-1-r0-174.18d4a21707515176,reason=Completed count=1 msg=Job completed
0.4131,Event,ADDED,eval-sanitize-1-r0-175-wxgtr.18d4a20d51ff013d,"reason=FailedScheduling count=None msg=0/6 nodes are available: 6 node(s) had untolerated taint(s). no new claims to deallocate, preemption: 0/6 nodes are available: 6 Preemption is not helpful for scheduling."
0.4134,Event,ADDED,eval-sanitize-1-r0-175-wxgtr.18d4a2114762bf95,reason=Scheduled count=None msg=Successfully assigned compute/eval-sanitize-1-r0-175-wxgtr to kind-worker
0.4136,Event,ADDED,eval-sanitize-1-r0-175-wxgtr.18d4a21164afd571,"reason=Pulled count=1 msg=Container image ""busybox:musl"" already present on machine"
0.4138,Event,ADDED,eval-sanitize-1-r0-175-wxgtr.18d4a21169acf350,reason=Created count=1 msg=Created container: task
0.4142,Event,ADDED,eval-sanitize-1-r0-175-wxgtr.18d4a211725cbab0,reason=Started count=1 msg=Started container task
0.4144,Event,ADDED,eval-sanitize-1-r0-175.18d4a20d51f2245c,reason=SuccessfulCreate count=1 msg=Created pod: eval-sanitize-1-r0-175-wxgtr
0.4146,Event,ADDED,eval-sanitize-1-r0-175.18d4a2170751c3bb,reason=Completed count=1 msg=Job completed
0.4149,Event,ADDED,eval-sanitize-1-r0-176-t45t6.18d4a20d888710ef,"reason=FailedScheduling count=None msg=0/6 nodes are available: 6 node(s) had untolerated taint(s). no new claims to deallocate, preemption: 0/6 nodes are available: 6 Preemption is not helpful for scheduling."
0.4151,Event,ADDED,eval-sanitize-1-r0-176-t45t6.18d4a21147881849,reason=Scheduled count=None msg=Successfully assigned compute/eval-sanitize-1-r0-176-t45t6 to kind-worker
0.4153,Event,ADDED,eval-sanitize-1-r0-176-t45t6.18d4a211659bfdfd,"reason=Pulled count=1 msg=Container image ""busybox:musl"" already present on machine"
0.4154,Event,ADDED,eval-sanitize-1-r0-176-t45t6.18d4a2116b473d38,reason=Created count=1 msg=Created container: task
0.4157,Event,ADDED,eval-sanitize-1-r0-176-t45t6.18d4a2116efc06c5,reason=Started count=1 msg=Started container task
0.4159,Event,ADDED,eval-sanitize-1-r0-176.18d4a20d887ae33f,reason=SuccessfulCreate count=1 msg=Created pod: eval-sanitize-1-r0-176-t45t6
0.4161,Event,ADDED,eval-sanitize-1-r0-176.18d4a21760a6a058,reason=Completed count=1 msg=Job completed
0.4163,Event,ADDED,eval-sanitize-1-r0-177-wls5g.18d4a20dc2b2f32d,"reason=FailedScheduling count=None msg=0/6 nodes are available: 6 node(s) had untolerated taint(s). no new claims to deallocate, preemption: 0/6 nodes are available: 6 Preemption is not helpful for scheduling."
0.4166,Event,ADDED,eval-sanitize-1-r0-177-wls5g.18d4a21147d0ff4a,reason=Scheduled count=None msg=Successfully assigned compute/eval-sanitize-1-r0-177-wls5g to kind-worker
0.4167,Event,ADDED,eval-sanitize-1-r0-177-wls5g.18d4a2116560d876,"reason=Pulled count=1 msg=Container image ""busybox:musl"" already present on machine"
0.4169,Event,ADDED,eval-sanitize-1-r0-177-wls5g.18d4a2116b213df2,reason=Created count=1 msg=Created container: task
0.4173,Event,ADDED,eval-sanitize-1-r0-177-wls5g.18d4a2116efa912f,reason=Started count=1 msg=Started container task
0.4175,Event,ADDED,eval-sanitize-1-r0-177.18d4a20dc2a5fcaa,reason=SuccessfulCreate count=1 msg=Created pod: eval-sanitize-1-r0-177-wls5g
0.4177,Event,ADDED,eval-sanitize-1-r0-177.18d4a216cbea09bc,reason=Completed count=1 msg=Job completed
0.4178,Event,ADDED,eval-sanitize-1-r0-178-ks6sw.18d4a20df7b76734,"reason=FailedScheduling count=None msg=0/6 nodes are available: 6 node(s) had untolerated taint(s). no new claims to deallocate, preemption: 0/6 nodes are available: 6 Preemption is not helpful for scheduling."
0.4182,Event,ADDED,eval-sanitize-1-r0-178-ks6sw.18d4a21147999abc,"reason=FailedScheduling count=None msg=0/6 nodes are available: 1 c_wall violated: 3 conflicting context pair(s) with node memory, 5 node(s) had untolerated taint(s). no new claims to deallocate, preemption: 0/6 nodes are available: 1 No preemption victims found for incoming pod, 5 Preemption is not helpful for scheduling."
0.4184,Event,ADDED,eval-sanitize-1-r0-178-ks6sw.18d4a21157f4f141,"reason=FailedScheduling count=None msg=0/6 nodes are available: 1 c_wall violated: 3 conflicting context pair(s) with node memory, 5 node(s) had untolerated taint(s). no new claims to deallocate, preemption: 0/6 nodes are available: 1 No preemption victims found for incoming pod, 5 Preemption is not helpful for scheduling."
0.4186,Event,ADDED,eval-sanitize-1-r0-178-ks6sw.18d4a21193227c06,reason=Scheduled count=None msg=Successfully assigned compute/eval-sanitize-1-r0-178-ks6sw to kind-worker4
0.4188,Event,ADDED,eval-sanitize-1-r0-178-ks6sw.18d4a211ad8b78c9,"reason=Pulled count=1 msg=Container image ""busybox:musl"" already present on machine"
0.4189,Event,ADDED,eval-sanitize-1-r0-178-ks6sw.18d4a211b01fa2e2,reason=Created count=1 msg=Created container: task
0.4191,Event,ADDED,eval-sanitize-1-r0-178-ks6sw.18d4a211bf375ff2,reason=Started count=1 msg=Started container task
0.4193,Event,ADDED,eval-sanitize-1-r0-178.18d4a20df7ad6178,reason=SuccessfulCreate count=1 msg=Created pod: eval-sanitize-1-r0-178-ks6sw
0.4195,Event,ADDED,eval-sanitize-1-r0-178.18d4a217f29b4e98,reason=Completed count=1 msg=Job completed
0.4196,Event,ADDED,eval-sanitize-1-r0-179-2xntk.18d4a20e3488c677,"reason=FailedScheduling count=None msg=0/6 nodes are available: 6 node(s) had untolerated taint(s). no new claims to deallocate, preemption: 0/6 nodes are available: 6 Preemption is not helpful for scheduling."
0.4199,Event,ADDED,eval-sanitize-1-r0-179-2xntk.18d4a2114be8542f,reason=Scheduled count=None msg=Successfully assigned compute/eval-sanitize-1-r0-179-2xntk to kind-worker
0.4201,Event,ADDED,eval-sanitize-1-r0-179-2xntk.18d4a21166942ce3,"reason=Pulled count=1 msg=Container image ""busybox:musl"" already present on machine"
0.4203,Event,ADDED,eval-sanitize-1-r0-179-2xntk.18d4a2116a8c589c,reason=Created count=1 msg=Created container: task
0.4205,Event,ADDED,eval-sanitize-1-r0-179-2xntk.18d4a2116e7b3ddd,reason=Started count=1 msg=Started container task
0.4207,Event,ADDED,eval-sanitize-1-r0-179.18d4a20e347c1d39,reason=SuccessfulCreate count=1 msg=Created pod: eval-sanitize-1-r0-179-2xntk
0.4208,Event,ADDED,eval-sanitize-1-r0-179.18d4a2170700cd2d,reason=Completed count=1 msg=Job completed
0.4211,Event,ADDED,eval-sanitize-1-r0-180-fphfd.18d4a20e70bccb09,"reason=FailedScheduling count=None msg=0/6 nodes are available: 6 node(s) had untolerated taint(s). no new claims to deallocate, preemption: 0/6 nodes are available: 6 Preemption is not helpful for scheduling."
0.4213,Event,ADDED,eval-sanitize-1-r0-180-fphfd.18d4a2114bdc0a2b,"reason=FailedScheduling count=None msg=0/6 nodes are available: 1 c_wall violated: 4 conflicting context pair(s) with node memory, 5 node(s) had untolerated taint(s). no new claims to deallocate, preemption: 0/6 nodes are available: 1 No preemption victims found for incoming pod, 5 Preemption is not helpful for scheduling."
0.4216,Event,ADDED,eval-sanitize-1-r0-180-fphfd.18d4a21159388cc7,"reason=FailedScheduling count=None msg=0/6 nodes are available: 1 c_wall violated: 4 conflicting context pair(s) with node memory, 5 node(s) had untolerated taint(s). no new claims to deallocate, preemption: 0/6 nodes are available: 1 No preemption victims found for incoming pod, 5 Preemption is not helpful for scheduling."
0.4217,Event,ADDED,eval-sanitize-1-r0-180-fphfd.18d4a2119f692c7f,"reason=FailedScheduling count=None msg=0/6 nodes are available: 2 c_wall violated: 1 conflicting context pair(s) with node memory, 4 node(s) had untolerated taint(s). no new claims to deallocate, preemption: 0/6 nodes are available: 2 No preemption victims found for incoming pod, 4 Preemption is not helpful for scheduling."
0.4219,Event,ADDED,eval-sanitize-1-r0-180-fphfd.18d4a211aba261a7,"reason=FailedScheduling count=None msg=0/6 nodes are available: 2 c_wall violated: 1 conflicting context pair(s) with node memory, 4 node(s) had untolerated taint(s). no new claims to deallocate, preemption: 0/6 nodes are available: 2 No preemption victims found for incoming pod, 4 Preemption is not helpful for scheduling."
0.4223,Event,ADDED,eval-sanitize-1-r0-180-fphfd.18d4a211e6c69988,"reason=FailedScheduling count=None msg=0/6 nodes are available: 1 c_wall violated: 1 conflicting context pair(s) with node memory, 5 node(s) had untolerated taint(s). no new claims to deallocate, preemption: 0/6 nodes are available: 1 No preemption victims found for incoming pod, 5 Preemption is not helpful for scheduling."
0.4224,Event,ADDED,eval-sanitize-1-r0-180-fphfd.18d4a2120648c5cd,reason=Scheduled count=None msg=Successfully assigned compute/eval-sanitize-1-r0-180-fphfd to kind-worker5
0.4226,Event,ADDED,eval-sanitize-1-r0-180-fphfd.18d4a212230415e2,"reason=Pulled count=1 msg=Container image ""busybox:musl"" already present on machine"
0.4228,Event,ADDED,eval-sanitize-1-r0-180-fphfd.18d4a21226e6075b,reason=Created count=1 msg=Created container: task
0.423,Event,ADDED,eval-sanitize-1-r0-180-fphfd.18d4a21229e620b0,reason=Started count=1 msg=Started container task
0.4232,Event,ADDED,eval-sanitize-1-r0-180.18d4a20e70ae2b47,reason=SuccessfulCreate count=1 msg=Created pod: eval-sanitize-1-r0-180-fphfd
0.4234,Event,ADDED,eval-sanitize-1-r0-180.18d4a2182c024571,reason=Completed count=1 msg=Job completed
0.4236,Event,ADDED,eval-sanitize-1-r0-181-6nzxf.18d4a20eaabd6013,"reason=FailedScheduling count=None msg=0/6 nodes are available: 6 node(s) had untolerated taint(s). no new claims to deallocate, preemption: 0/6 nodes are available: 6 Preemption is not helpful for scheduling."
0.4238,Event,ADDED,eval-sanitize-1-r0-181-6nzxf.18d4a2114c7bfff2,"reason=FailedScheduling count=None msg=0/6 nodes are available: 1 c_wall violated: 1 conflicting context pair(s) with node memory, 5 node(s) had untolerated taint(s). no new claims to deallocate, preemption: 0/6 nodes are available: 1 No preemption victims found for incoming pod, 5 Preemption is not helpful for scheduling."
0.424,Event,ADDED,eval-sanitize-1-r0-181-6nzxf.18d4a211596f405a,"reason=FailedScheduling count=None msg=0/6 nodes are available: 1 c_wall violated: 1 conflicting context pair(s) with node memory, 5 node(s) had untolerated taint(s). no new claims to deallocate, preemption: 0/6 nodes are available: 1 No preemption victims found for incoming pod, 5 Preemption is not helpful for scheduling."
0.4242,Event,ADDED,eval-sanitize-1-r0-181-6nzxf.18d4a211943047e8,reason=Scheduled count=None msg=Successfully assigned compute/eval-sanitize-1-r0-181-6nzxf to kind-worker4
0.4244,Event,ADDED,eval-sanitize-1-r0-181-6nzxf.18d4a211ae114839,"reason=Pulled count=1 msg=Container image ""busybox:musl"" already present on machine"
0.4246,Event,ADDED,eval-sanitize-1-r0-181-6nzxf.18d4a211b0b5282b,reason=Created count=1 msg=Created container: task
0.4248,Event,ADDED,eval-sanitize-1-r0-181-6nzxf.18d4a211bf434033,reason=Started count=1 msg=Started container task
0.4251,Event,ADDED,eval-sanitize-1-r0-181.18d4a20eaaaf186e,reason=SuccessfulCreate count=1 msg=Created pod: eval-sanitize-1-r0-181-6nzxf
0.4253,Event,ADDED,eval-sanitize-1-r0-181.18d4a217f9d7cb3c,reason=Completed count=1 msg=Job completed
0.4255,Event,ADDED,eval-sanitize-1-r0-182-8brr9.18d4a20ee65a6946,"reason=FailedScheduling count=None msg=0/6 nodes are available: 6 node(s) had untolerated taint(s). no new claims to deallocate, preemption: 0/6 nodes are available: 6 Preemption is not helpful for scheduling."
0.4257,Event,ADDED,eval-sanitize-1-r0-182-8brr9.18d4a2114d7e7c03,"reason=FailedScheduling count=None msg=0/6 nodes are available: 1 c_wall violated: 4 conflicting context pair(s) with node memory, 5 node(s) had untolerated taint(s). no new claims to deallocate, preemption: 0/6 nodes are available: 1 No preemption victims found for incoming pod, 5 Preemption is not helpful for scheduling."
0.4259,Event,ADDED,eval-sanitize-1-r0-182-8brr9.18d4a2115c7990ea,"reason=FailedScheduling count=None msg=0/6 nodes are available: 1 c_wall violated: 4 conflicting context pair(s) with node memory, 5 node(s) had untolerated taint(s). no new claims to deallocate, preemption: 0/6 nodes are available: 1 No preemption victims found for incoming pod, 5 Preemption is not helpful for scheduling."
0.426,Event,ADDED,eval-sanitize-1-r0-182-8brr9.18d4a211a536b3ba,"reason=FailedScheduling count=None msg=0/6 nodes are available: 2 c_wall violated: 1 conflicting context pair(s) with node memory, 4 node(s) had untolerated taint(s). no new claims to deallocate, preemption: 0/6 nodes are available: 2 No preemption victims found for incoming pod, 4 Preemption is not helpful for scheduling."
0.4262,Event,ADDED,eval-sanitize-1-r0-182-8brr9.18d4a211b15516ce,"reason=FailedScheduling count=None msg=0/6 nodes are available: 2 c_wall violated: 1 conflicting context pair(s) with node memory, 4 node(s) had untolerated taint(s). no new claims to deallocate, preemption: 0/6 nodes are available: 2 No preemption victims found for incoming pod, 4 Preemption is not helpful for scheduling."
0.4264,Event,ADDED,eval-sanitize-1-r0-182-8brr9.18d4a211e25288d5,"reason=FailedScheduling count=None msg=0/6 nodes are available: 1 c_wall violated: 1 conflicting context pair(s) with node memory, 5 node(s) had untolerated taint(s). no new claims to deallocate, preemption: 0/6 nodes are available: 1 No preemption victims found for incoming pod, 5 Preemption is not helpful for scheduling."
0.4266,Event,ADDED,eval-sanitize-1-r0-182-8brr9.18d4a21204f82ae5,reason=Scheduled count=None msg=Successfully assigned compute/eval-sanitize-1-r0-182-8brr9 to kind-worker5
0.4267,Event,ADDED,eval-sanitize-1-r0-182-8brr9.18d4a21220b88570,"reason=Pulled count=1 msg=Container image ""busybox:musl"" already present on machine"
0.4271,Event,ADDED,eval-sanitize-1-r0-182-8brr9.18d4a21222d78159,reason=Created count=1 msg=Created container: task
0.4273,Event,ADDED,eval-sanitize-1-r0-182-8brr9.18d4a212256e6a95,reason=Started count=1 msg=Started container task
0.4274,Event,ADDED,eval-sanitize-1-r0-182.18d4a20ee651a585,reason=SuccessfulCreate count=1 msg=Created pod: eval-sanitize-1-r0-182-8brr9
0.4277,Event,ADDED,eval-sanitize-1-r0-182.18d4a21828773075,reason=Completed count=1 msg=Job completed
0.4278,Event,ADDED,eval-sanitize-1-r0-183-d6bm4.18d4a20f21e5ce7c,"reason=FailedScheduling count=None msg=0/6 nodes are available: 6 node(s) had untolerated taint(s). no new claims to deallocate, preemption: 0/6 nodes are available: 6 Preemption is not helpful for scheduling."
0.428,Event,ADDED,eval-sanitize-1-r0-183-d6bm4.18d4a2114f7dc8e3,reason=Scheduled count=None msg=Successfully assigned compute/eval-sanitize-1-r0-183-d6bm4 to kind-worker
0.4281,Event,ADDED,eval-sanitize-1-r0-183-d6bm4.18d4a2116ffb0dc8,"reason=Pulled count=1 msg=Container image ""busybox:musl"" already present on machine"
0.4284,Event,ADDED,eval-sanitize-1-r0-183-d6bm4.18d4a21172504a42,reason=Created count=1 msg=Created container: task
0.4285,Event,ADDED,eval-sanitize-1-r0-183-d6bm4.18d4a211759740bb,reason=Started count=1 msg=Started container task
0.4287,Event,ADDED,eval-sanitize-1-r0-183.18d4a20f21d84b7e,reason=SuccessfulCreate count=1 msg=Created pod: eval-sanitize-1-r0-183-d6bm4
0.4289,Event,ADDED,eval-sanitize-1-r0-183.18d4a216cdd529d2,reason=Completed count=1 msg=Job completed
0.4292,Event,ADDED,eval-sanitize-1-r0-184-jwstm.18d4a20f5d6d3519,"reason=FailedScheduling count=None msg=0/6 nodes are available: 6 node(s) had untolerated taint(s). no new claims to deallocate, preemption: 0/6 nodes are available: 6 Preemption is not helpful for scheduling."
0.4294,Event,ADDED,eval-sanitize-1-r0-184-jwstm.18d4a2114fbacf46,reason=Scheduled count=None msg=Successfully assigned compute/eval-sanitize-1-r0-184-jwstm to kind-worker
0.4296,Event,ADDED,eval-sanitize-1-r0-184-jwstm.18d4a2116f042e69,"reason=Pulled count=1 msg=Container image ""busybox:musl"" already present on machine"
0.4298,Event,ADDED,eval-sanitize-1-r0-184-jwstm.18d4a21170e0d1dc,reason=Created count=1 msg=Created container: task
0.43,Event,ADDED,eval-sanitize-1-r0-184-jwstm.18d4a2117416106c,reason=Started count=1 msg=Started container task
0.4302,Event,ADDED,eval-sanitize-1-r0-184.18d4a20f5d60875c,reason=SuccessfulCreate count=1 msg=Created pod: eval-sanitize-1-r0-184-jwstm
0.4303,Event,ADDED,eval-sanitize-1-r0-184.18d4a21755cafd9b,reason=Completed count=1 msg=Job completed
0.4305,Event,ADDED,eval-sanitize-1-r0-185-5hxgz.18d4a20f9e714d86,"reason=FailedScheduling count=None msg=0/6 nodes are available: 6 node(s) had untolerated taint(s). no new claims to deallocate, preemption: 0/6 nodes are available: 6 Preemption is not helpful for scheduling."
0.4306,Event,ADDED,eval-sanitize-1-r0-185-5hxgz.18d4a21151ad7055,"reason=FailedScheduling count=None msg=0/6 nodes are available: 1 c_wall violated: 2 conflicting context pair(s) with node memory, 5 node(s) had untolerated taint(s). no new claims to deallocate, preemption: 0/6 nodes are available: 1 No preemption victims found for incoming pod, 5 Preemption is not helpful for scheduling."
0.4308,Event,ADDED,eval-sanitize-1-r0-185-5hxgz.18d4a2116114faa2,"reason=FailedScheduling count=None msg=0/6 nodes are available: 1 c_wall violated: 2 conflicting context pair(s) with node memory, 5 node(s) had untolerated taint(s). no new claims to deallocate, preemption: 0/6 nodes are available: 1 No preemption victims found for incoming pod, 5 Preemption is not helpful for scheduling."
0.431,Event,ADDED,eval-sanitize-1-r0-185-5hxgz.18d4a211a5feaeba,"reason=FailedScheduling count=None msg=0/6 nodes are available: 2 c_wall violated: 1 conflicting context pair(s) with node memory, 4 node(s) had untolerated taint(s). no new claims to deallocate, preemption: 0/6 nodes are available: 2 No preemption victims found for incoming pod, 4 Preemption is not helpful for scheduling."
0.4312,Event,ADDED,eval-sanitize-1-r0-185-5hxgz.18d4a211b5d7975f,"reason=FailedScheduling count=None msg=0/6 nodes are available: 2 c_wall violated: 1 conflicting context pair(s) with node memory, 4 node(s) had untolerated taint(s). no new claims to deallocate, preemption: 0/6 nodes are available: 2 No preemption victims found for incoming pod, 4 Preemption is not helpful for scheduling."
0.4314,Event,ADDED,eval-sanitize-1-r0-185-5hxgz.18d4a211e2848f49,"reason=FailedScheduling count=None msg=0/6 nodes are available: 1 c_wall violated: 1 conflicting context pair(s) with node memory, 5 node(s) had untolerated taint(s). no new claims to deallocate, preemption: 0/6 nodes are available: 1 No preemption victims found for incoming pod, 5 Preemption is not helpful for scheduling."
0.4317,Event,ADDED,eval-sanitize-1-r0-185-5hxgz.18d4a212056e1920,reason=Scheduled count=None msg=Successfully assigned compute/eval-sanitize-1-r0-185-5hxgz to kind-worker5
0.4319,Event,ADDED,eval-sanitize-1-r0-185-5hxgz.18d4a2122267e4c6,"reason=Pulled count=1 msg=Container image ""busybox:musl"" already present on machine"
0.4321,Event,ADDED,eval-sanitize-1-r0-185-5hxgz.18d4a2122604046c,reason=Created count=1 msg=Created container: task
0.4325,Event,ADDED,eval-sanitize-1-r0-185-5hxgz.18d4a2122981d753,reason=Started count=1 msg=Started container task
0.4327,Event,ADDED,eval-sanitize-1-r0-185.18d4a20f9e678280,reason=SuccessfulCreate count=1 msg=Created pod: eval-sanitize-1-r0-185-5hxgz
0.4329,Event,ADDED,eval-sanitize-1-r0-185.18d4a2182e37363c,reason=Completed count=1 msg=Job completed
0.4331,Event,ADDED,eval-sanitize-1-r0-186-bw5hl.18d4a20fd485bc43,"reason=FailedScheduling count=None msg=0/6 nodes are available: 6 node(s) had untolerated taint(s). no new claims to deallocate, preemption: 0/6 nodes are available: 6 Preemption is not helpful for scheduling."
0.4333,Event,ADDED,eval-sanitize-1-r0-186-bw5hl.18d4a21152b0f99f,reason=Scheduled count=None msg=Successfully assigned compute/eval-sanitize-1-r0-186-bw5hl to kind-worker
0.4335,Event,ADDED,eval-sanitize-1-r0-186-bw5hl.18d4a2116fa2d770,"reason=Pulled count=1 msg=Container image ""busybox:musl"" already present on machine"
0.4336,Event,ADDED,eval-sanitize-1-r0-186-bw5hl.18d4a21172535575,reason=Created count=1 msg=Created container: task
0.4338,Event,ADDED,eval-sanitize-1-r0-186-bw5hl.18d4a2117591b21c,reason=Started count=1 msg=Started container task
0.434,Event,ADDED,eval-sanitize-1-r0-186.18d4a20fd479ac21,reason=SuccessfulCreate count=1 msg=Created pod: eval-sanitize-1-r0-186-bw5hl
0.4342,Event,ADDED,eval-sanitize-1-r0-186.18d4a217072b915c,reason=Completed count=1 msg=Job completed
0.4343,Event,ADDED,eval-sanitize-1-r0-187-kr8bp.18d4a21010935446,"reason=FailedScheduling count=None msg=0/6 nodes are available: 6 node(s) had untolerated taint(s). no new claims to deallocate, preemption: 0/6 nodes are available: 6 Preemption is not helpful for scheduling."
0.4345,Event,ADDED,eval-sanitize-1-r0-187-kr8bp.18d4a211527f1c9b,"reason=FailedScheduling count=None msg=0/6 nodes are available: 1 c_wall violated: 1 conflicting context pair(s) with node memory, 5 node(s) had untolerated taint(s). no new claims to deallocate, preemption: 0/6 nodes are available: 1 No preemption victims found for incoming pod, 5 Preemption is not helpful for scheduling."
0.4347,Event,ADDED,eval-sanitize-1-r0-187-kr8bp.18d4a211616e1708,"reason=FailedScheduling count=None msg=0/6 nodes are available: 1 c_wall violated: 1 conflicting context pair(s) with node memory, 5 node(s) had untolerated taint(s). no new claims to deallocate, preemption: 0/6 nodes are available: 1 No preemption victims found for incoming pod, 5 Preemption is not helpful for scheduling."
0.4348,Event,ADDED,eval-sanitize-1-r0-187-kr8bp.18d4a21199b8f82e,reason=Scheduled count=None msg=Successfully assigned compute/eval-sanitize-1-r0-187-kr8bp to kind-worker4
0.4355,Event,ADDED,eval-sanitize-1-r0-187-kr8bp.18d4a211bf404114,"reason=Pulled count=1 msg=Container image ""busybox:musl"" already present on machine"
0.4356,Event,ADDED,eval-sanitize-1-r0-187-kr8bp.18d4a211c178760c,reason=Created count=1 msg=Created container: task
0.4358,Event,ADDED,eval-sanitize-1-r0-187-kr8bp.18d4a211c50c6fb5,reason=Started count=1 msg=Started container task
0.436,Event,ADDED,eval-sanitize-1-r0-187.18d4a210108a86c4,reason=SuccessfulCreate count=1 msg=Created pod: eval-sanitize-1-r0-187-kr8bp
0.4363,Event,ADDED,eval-sanitize-1-r0-187.18d4a217ecc7b650,reason=Completed count=1 msg=Job completed
0.4365,Event,ADDED,eval-sanitize-1-r0-188-sdqtn.18d4a21052458829,"reason=FailedScheduling count=None msg=0/6 nodes are available: 6 node(s) had untolerated taint(s). no new claims to deallocate, preemption: 0/6 nodes are available: 6 Preemption is not helpful for scheduling."
0.4366,Event,ADDED,eval-sanitize-1-r0-188-sdqtn.18d4a211555cb6df,"reason=FailedScheduling count=None msg=0/6 nodes are available: 1 c_wall violated: 3 conflicting context pair(s) with node memory, 5 node(s) had untolerated taint(s). no new claims to deallocate, preemption: 0/6 nodes are available: 1 No preemption victims found for incoming pod, 5 Preemption is not helpful for scheduling."
0.4369,Event,ADDED,eval-sanitize-1-r0-188-sdqtn.18d4a21161b29b10,"reason=FailedScheduling count=None msg=0/6 nodes are available: 1 c_wall violated: 3 conflicting context pair(s) with node memory, 5 node(s) had untolerated taint(s). no new claims to deallocate, preemption: 0/6 nodes are available: 1 No preemption victims found for incoming pod, 5 Preemption is not helpful for scheduling."
0.437,Event,ADDED,eval-sanitize-1-r0-188-sdqtn.18d4a2119a3a4bfa,reason=Scheduled count=None msg=Successfully assigned compute/eval-sanitize-1-r0-188-sdqtn to kind-worker3
0.4372,Event,ADDED,eval-sanitize-1-r0-188-sdqtn.18d4a211bf0d8be6,"reason=Pulled count=1 msg=Container image ""busybox:musl"" already present on machine"
0.4374,Event,ADDED,eval-sanitize-1-r0-188-sdqtn.18d4a211c1e35098,reason=Created count=1 msg=Created container: task
0.4377,Event,ADDED,eval-sanitize-1-r0-188-sdqtn.18d4a211c52aa561,reason=Started count=1 msg=Started container task
0.4378,Event,ADDED,eval-sanitize-1-r0-188.18d4a210523cad4e,reason=SuccessfulCreate count=1 msg=Created pod: eval-sanitize-1-r0-188-sdqtn
0.438,Event,ADDED,eval-sanitize-1-r0-188.18d4a217a21f0de1,reason=Completed count=1 msg=Job completed
0.4382,Event,ADDED,eval-sanitize-1-r0-189-xp29g.18d4a21087105ecd,"reason=FailedScheduling count=None msg=0/6 nodes are available: 6 node(s) had untolerated taint(s). no new claims to deallocate, preemption: 0/6 nodes are available: 6 Preemption is not helpful for scheduling."
0.4386,Event,ADDED,eval-sanitize-1-r0-189-xp29g.18d4a211561fee8f,"reason=FailedScheduling count=None msg=0/6 nodes are available: 1 c_wall violated: 4 conflicting context pair(s) with node memory, 5 node(s) had untolerated taint(s). no new claims to deallocate, preemption: 0/6 nodes are available: 1 No preemption victims found for incoming pod, 5 Preemption is not helpful for scheduling."
0.4389,Event,ADDED,eval-sanitize-1-r0-189-xp29g.18d4a21161f78b4e,"reason=FailedScheduling count=None msg=0/6 nodes are available: 1 c_wall violated: 4 conflicting context pair(s) with node memory, 5 node(s) had untolerated taint(s). no new claims to deallocate, preemption: 0/6 nodes are available: 1 No preemption victims found for incoming pod, 5 Preemption is not helpful for scheduling."
0.4394,Event,ADDED,eval-sanitize-1-r0-189-xp29g.18d4a211aa0db901,"reason=FailedScheduling count=None msg=0/6 nodes are available: 2 c_wall violated: 1 conflicting context pair(s) with node memory, 4 node(s) had untolerated taint(s). no new claims to deallocate, preemption: 0/6 nodes are available: 2 No preemption victims found for incoming pod, 4 Preemption is not helpful for scheduling."
0.4396,Event,ADDED,eval-sanitize-1-r0-189-xp29g.18d4a211e5a8bd8c,"reason=FailedScheduling count=None msg=0/6 nodes are available: 1 c_wall violated: 1 conflicting context pair(s) with node memory, 5 node(s) had untolerated taint(s). no new claims to deallocate, preemption: 0/6 nodes are available: 1 No preemption victims found for incoming pod, 5 Preemption is not helpful for scheduling."
0.4397,Event,ADDED,eval-sanitize-1-r0-189-xp29g.18d4a21205b0285e,reason=Scheduled count=None msg=Successfully assigned compute/eval-sanitize-1-r0-189-xp29g to kind-worker5
0.4399,Event,ADDED,eval-sanitize-1-r0-189-xp29g.18d4a212221f67f2,"reason=Pulled count=1 msg=Container image ""busybox:musl"" already present on machine"
0.4403,Event,ADDED,eval-sanitize-1-r0-189-xp29g.18d4a212249b0c01,reason=Created count=1 msg=Created container: task
0.4405,Event,ADDED,eval-sanitize-1-r0-189-xp29g.18d4a21228eae21d,reason=Started count=1 msg=Started container task
0.4406,Event,ADDED,eval-sanitize-1-r0-189.18d4a210870914ce,reason=SuccessfulCreate count=1 msg=Created pod: eval-sanitize-1-r0-189-xp29g
0.441,Event,ADDED,eval-sanitize-1-r0-189.18d4a2183d2f6bac,reason=Completed count=1 msg=Job completed
0.4412,Event,ADDED,eval-sanitize-1-r0-190-wbcwf.18d4a210c3609b99,"reason=FailedScheduling count=None msg=0/6 nodes are available: 6 node(s) had untolerated taint(s). no new claims to deallocate, preemption: 0/6 nodes are available: 6 Preemption is not helpful for scheduling."
0.4414,Event,ADDED,eval-sanitize-1-r0-190-wbcwf.18d4a21156b9925c,"reason=FailedScheduling count=None msg=0/6 nodes are available: 1 c_wall violated: 4 conflicting context pair(s) with node memory, 5 node(s) had untolerated taint(s). no new claims to deallocate, preemption: 0/6 nodes are available: 1 No preemption victims found for incoming pod, 5 Preemption is not helpful for scheduling."
0.4416,Event,ADDED,eval-sanitize-1-r0-190-wbcwf.18d4a2116386ac6e,"reason=FailedScheduling count=None msg=0/6 nodes are available: 1 c_wall violated: 4 conflicting context pair(s) with node memory, 5 node(s) had untolerated taint(s). no new claims to deallocate, preemption: 0/6 nodes are available: 1 No preemption victims found for incoming pod, 5 Preemption is not helpful for scheduling."
0.4419,Event,ADDED,eval-sanitize-1-r0-190-wbcwf.18d4a211ab48a42a,"reason=FailedScheduling count=None msg=0/6 nodes are available: 2 c_wall violated: 1 conflicting context pair(s) with node memory, 4 node(s) had untolerated taint(s). no new claims to deallocate, preemption: 0/6 nodes are available: 2 No preemption victims found for incoming pod, 4 Preemption is not helpful for scheduling."
0.4421,Event,ADDED,eval-sanitize-1-r0-190-wbcwf.18d4a211e6977efb,"reason=FailedScheduling count=None msg=0/6 nodes are available: 1 c_wall violated: 1 conflicting context pair(s) with node memory, 5 node(s) had untolerated taint(s). no new claims to deallocate, preemption: 0/6 nodes are available: 1 No preemption victims found for incoming pod, 5 Preemption is not helpful for scheduling."
0.4423,Event,ADDED,eval-sanitize-1-r0-190-wbcwf.18d4a21205fda990,reason=Scheduled count=None msg=Successfully assigned compute/eval-sanitize-1-r0-190-wbcwf to kind-worker5
0.4427,Event,ADDED,eval-sanitize-1-r0-190-wbcwf.18d4a21223b6cbe8,"reason=Pulled count=1 msg=Container image ""busybox:musl"" already present on machine"
0.4432,Event,ADDED,eval-sanitize-1-r0-190-wbcwf.18d4a2122784f7c0,reason=Created count=1 msg=Created container: task
0.4434,Event,ADDED,eval-sanitize-1-r0-190-wbcwf.18d4a2122ab8f1b7,reason=Started count=1 msg=Started container task
0.4437,Event,ADDED,eval-sanitize-1-r0-190.18d4a210c35631de,reason=SuccessfulCreate count=1 msg=Created pod: eval-sanitize-1-r0-190-wbcwf
0.4439,Event,ADDED,eval-sanitize-1-r0-190.18d4a21847bdf500,reason=Completed count=1 msg=Job completed
0.444,Event,ADDED,eval-sanitize-1-r0-191-f85kr.18d4a210fe7ab4c5,"reason=FailedScheduling count=None msg=0/6 nodes are available: 6 node(s) had untolerated taint(s). no new claims to deallocate, preemption: 0/6 nodes are available: 6 Preemption is not helpful for scheduling."
0.4442,Event,ADDED,eval-sanitize-1-r0-191-f85kr.18d4a21157f59ed3,reason=Scheduled count=None msg=Successfully assigned compute/eval-sanitize-1-r0-191-f85kr to kind-worker
0.4445,Event,ADDED,eval-sanitize-1-r0-191-f85kr.18d4a2117366ccb3,"reason=Pulled count=1 msg=Container image ""busybox:musl"" already present on machine"
0.4446,Event,ADDED,eval-sanitize-1-r0-191-f85kr.18d4a211753a2063,reason=Created count=1 msg=Created container: task
0.4448,Event,ADDED,eval-sanitize-1-r0-191-f85kr.18d4a21179762857,reason=Started count=1 msg=Started container task
0.4452,Event,ADDED,eval-sanitize-1-r0-191.18d4a210fe6db9b5,reason=SuccessfulCreate count=1 msg=Created pod: eval-sanitize-1-r0-191-f85kr
0.4454,Event,ADDED,eval-sanitize-1-r0-191.18d4a21757aed16e,reason=Completed count=1 msg=Job completed
0.4455,Event,ADDED,eval-sanitize-1-r0-192-vhx4r.18d4a2115826302c,reason=Scheduled count=None msg=Successfully assigned compute/eval-sanitize-1-r0-192-vhx4r to kind-worker
0.4457,Event,ADDED,eval-sanitize-1-r0-192-vhx4r.18d4a211741eb7bb,"reason=Pulled count=1 msg=Container image ""busybox:musl"" already present on machine"
0.4459,Event,ADDED,eval-sanitize-1-r0-192-vhx4r.18d4a2117611d778,reason=Created count=1 msg=Created container: task
0.4461,Event,ADDED,eval-sanitize-1-r0-192-vhx4r.18d4a21179e617b2,reason=Started count=1 msg=Started container task
0.4463,Event,ADDED,eval-sanitize-1-r0-192.18d4a211546e4fa2,reason=SuccessfulCreate count=1 msg=Created pod: eval-sanitize-1-r0-192-vhx4r
0.4464,Event,ADDED,eval-sanitize-1-r0-192.18d4a216ceac8ccf,reason=Completed count=1 msg=Job completed
0.4466,Event,ADDED,eval-sanitize-1-r0-193-ctk77.18d4a211a2ab2f03,"reason=FailedScheduling count=None msg=0/6 nodes are available: 2 c_wall violated: 1 conflicting context pair(s) with node memory, 4 node(s) had untolerated taint(s). no new claims to deallocate, preemption: 0/6 nodes are available: 2 No preemption victims found for incoming pod, 4 Preemption is not helpful for scheduling."
0.4468,Event,ADDED,eval-sanitize-1-r0-193-ctk77.18d4a211b0f46cc0,"reason=FailedScheduling count=None msg=0/6 nodes are available: 2 c_wall violated: 1 conflicting context pair(s) with node memory, 4 node(s) had untolerated taint(s). no new claims to deallocate, preemption: 0/6 nodes are available: 2 No preemption victims found for incoming pod, 4 Preemption is not helpful for scheduling."
0.447,Event,ADDED,eval-sanitize-1-r0-193-ctk77.18d4a211e6f36704,"reason=FailedScheduling count=None msg=0/6 nodes are available: 1 c_wall violated: 1 conflicting context pair(s) with node memory, 5 node(s) had untolerated taint(s). no new claims to deallocate, preemption: 0/6 nodes are available: 1 No preemption victims found for incoming pod, 5 Preemption is not helpful for scheduling."
0.4471,Event,ADDED,eval-sanitize-1-r0-193-ctk77.18d4a21206b867de,reason=Scheduled count=None msg=Successfully assigned compute/eval-sanitize-1-r0-193-ctk77 to kind-worker5
0.4473,Event,ADDED,eval-sanitize-1-r0-193-ctk77.18d4a2122381e233,"reason=Pulled count=1 msg=Container image ""busybox:musl"" already present on machine"
0.4475,Event,ADDED,eval-sanitize-1-r0-193-ctk77.18d4a21227b4a7af,reason=Created count=1 msg=Created container: task
0.4478,Event,ADDED,eval-sanitize-1-r0-193-ctk77.18d4a2122ab6ccac,reason=Started count=1 msg=Started container task
0.4479,Event,ADDED,eval-sanitize-1-r0-193.18d4a211a2260651,reason=SuccessfulCreate count=1 msg=Created pod: eval-sanitize-1-r0-193-ctk77
0.4481,Event,ADDED,eval-sanitize-1-r0-193.18d4a21851e83a87,reason=Completed count=1 msg=Job completed
0.4483,Event,ADDED,eval-sanitize-1-r0-194-z9x42.18d4a211f9acb43b,"reason=FailedScheduling count=None msg=0/6 nodes are available: 6 node(s) had untolerated taint(s). no new claims to deallocate, preemption: 0/6 nodes are available: 6 Preemption is not helpful for scheduling."
0.4484,Event,ADDED,eval-sanitize-1-r0-194-z9x42.18d4a2120ac51eaa,reason=Scheduled count=None msg=Successfully assigned compute/eval-sanitize-1-r0-194-z9x42 to kind-worker5
0.4487,Event,ADDED,eval-sanitize-1-r0-194-z9x42.18d4a2122571a7e1,"reason=Pulled count=1 msg=Container image ""busybox:musl"" already present on machine"
0.449,Event,ADDED,eval-sanitize-1-r0-194-z9x42.18d4a21228be3658,reason=Created count=1 msg=Created container: task
0.4492,Event,ADDED,eval-sanitize-1-r0-194-z9x42.18d4a2122b42a2be,reason=Started count=1 msg=Started container task
0.4495,Event,ADDED,eval-sanitize-1-r0-194.18d4a211f9a2896f,reason=SuccessfulCreate count=1 msg=Created pod: eval-sanitize-1-r0-194-z9x42
0.4497,Event,ADDED,eval-sanitize-1-r0-194.18d4a2184c4290dd,reason=Completed count=1 msg=Job completed
0.4499,Event,ADDED,eval-sanitize-1-r0-195-pl49h.18d4a2125ef8963e,"reason=FailedScheduling count=None msg=0/6 nodes are available: 6 node(s) had untolerated taint(s). no new claims to deallocate, preemption: 0/6 nodes are available: 6 Preemption is not helpful for scheduling."
0.4501,Event,ADDED,eval-sanitize-1-r0-195-pl49h.18d4a212826bedc3,reason=Scheduled count=None msg=Successfully assigned compute/eval-sanitize-1-r0-195-pl49h to kind-worker2
0.4503,Event,ADDED,eval-sanitize-1-r0-195-pl49h.18d4a2129c87e9bf,"reason=Pulled count=1 msg=Container image ""busybox:musl"" already present on machine"
0.4505,Event,ADDED,eval-sanitize-1-r0-195-pl49h.18d4a2129daedf5e,reason=Created count=1 msg=Created container: task
0.4507,Event,ADDED,eval-sanitize-1-r0-195-pl49h.18d4a212a2393e65,reason=Started count=1 msg=Started container task
0.4513,Event,ADDED,eval-sanitize-1-r0-195.18d4a2125eed72ac,reason=SuccessfulCreate count=1 msg=Created pod: eval-sanitize-1-r0-195-pl49h
0.4515,Event,ADDED,eval-sanitize-1-r0-195.18d4a218414e070b,reason=Completed count=1 msg=Job completed
0.4517,Event,ADDED,eval-sanitize-1-r0-196-jm9zl.18d4a212a2d1d46c,reason=Scheduled count=None msg=Successfully assigned compute/eval-sanitize-1-r0-196-jm9zl to kind-worker2
0.4519,Event,ADDED,eval-sanitize-1-r0-196-jm9zl.18d4a212bd88b0ee,"reason=Pulled count=1 msg=Container image ""busybox:musl"" already present on machine"
0.4522,Event,ADDED,eval-sanitize-1-r0-196-jm9zl.18d4a212bebe5410,reason=Created count=1 msg=Created container: task
0.4524,Event,ADDED,eval-sanitize-1-r0-196-jm9zl.18d4a212c214b664,reason=Started count=1 msg=Started container task
0.4526,Event,ADDED,eval-sanitize-1-r0-196.18d4a212a24e9b8d,reason=SuccessfulCreate count=1 msg=Created pod: eval-sanitize-1-r0-196-jm9zl
0.4529,Event,ADDED,eval-sanitize-1-r0-196.18d4a218374b4d26,reason=Completed count=1 msg=Job completed
0.4532,Event,ADDED,eval-sanitize-1-r0-197-rnqdx.18d4a212bd49ead3,"reason=FailedScheduling count=None msg=0/6 nodes are available: 1 c_wall violated: 2 conflicting context pair(s) with node memory, 5 node(s) had untolerated taint(s). no new claims to deallocate, preemption: 0/6 nodes are available: 1 No preemption victims found for incoming pod, 5 Preemption is not helpful for scheduling."
0.4534,Event,ADDED,eval-sanitize-1-r0-197-rnqdx.18d4a212bde378ff,"reason=FailedScheduling count=None msg=0/6 nodes are available: 1 c_wall violated: 2 conflicting context pair(s) with node memory, 5 node(s) had untolerated taint(s). no new claims to deallocate, preemption: 0/6 nodes are available: 1 No preemption victims found for incoming pod, 5 Preemption is not helpful for scheduling."
0.4537,Event,ADDED,eval-sanitize-1-r0-197-rnqdx.18d4a2175f74d33b,reason=Scheduled count=None msg=Successfully assigned compute/eval-sanitize-1-r0-197-rnqdx to kind-worker3
0.4538,Event,ADDED,eval-sanitize-1-r0-197-rnqdx.18d4a217791cbab2,"reason=Pulled count=1 msg=Container image ""busybox:musl"" already present on machine"
0.454,Event,ADDED,eval-sanitize-1-r0-197-rnqdx.18d4a2177a31ef93,reason=Created count=1 msg=Created container: task
0.4543,Event,ADDED,eval-sanitize-1-r0-197-rnqdx.18d4a2177c340f80,reason=Started count=1 msg=Started container task
0.4546,Event,ADDED,eval-sanitize-1-r0-197.18d4a212bd0b653d,reason=SuccessfulCreate count=1 msg=Created pod: eval-sanitize-1-r0-197-rnqdx
0.4548,Event,ADDED,eval-sanitize-1-r0-197.18d4a21d1508e022,reason=Completed count=1 msg=Job completed
0.455,Event,ADDED,eval-sanitize-1-r0-198-k96z2.18d4a212c6879e5a,"reason=FailedScheduling count=None msg=0/6 nodes are available: 1 c_wall violated: 1 conflicting context pair(s) with node memory, 5 node(s) had untolerated taint(s). no new claims to deallocate, preemption: 0/6 nodes are available: 1 No preemption victims found for incoming pod, 5 Preemption is not helpful for scheduling."
0.4552,Event,ADDED,eval-sanitize-1-r0-198-k96z2.18d4a212c710aa5c,"reason=FailedScheduling count=None msg=0/6 nodes are available: 1 c_wall violated: 1 conflicting context pair(s) with node memory, 5 node(s) had untolerated taint(s). no new claims to deallocate, preemption: 0/6 nodes are available: 1 No preemption victims found for incoming pod, 5 Preemption is not helpful for scheduling."
0.4554,Event,ADDED,eval-sanitize-1-r0-198-k96z2.18d4a2175f994129,"reason=FailedScheduling count=None msg=0/6 nodes are available: 1 c_wall violated: 1 conflicting context pair(s) with node memory, 5 node(s) had untolerated taint(s). no new claims to deallocate, preemption: 0/6 nodes are available: 1 No preemption victims found for incoming pod, 5 Preemption is not helpful for scheduling."
0.4555,Event,ADDED,eval-sanitize-1-r0-198-k96z2.18d4a217609c2b43,"reason=FailedScheduling count=None msg=0/6 nodes are available: 1 c_wall violated: 1 conflicting context pair(s) with node memory, 5 node(s) had untolerated taint(s). no new claims to deallocate, preemption: 0/6 nodes are available: 1 No preemption victims found for incoming pod, 5 Preemption is not helpful for scheduling."
0.4557,Event,ADDED,eval-sanitize-1-r0-198-k96z2.18d4a21819840528,reason=Scheduled count=None msg=Successfully assigned compute/eval-sanitize-1-r0-198-k96z2 to kind-worker4
0.4559,Event,ADDED,eval-sanitize-1-r0-198-k96z2.18d4a21835cd1a95,"reason=Pulled count=1 msg=Container image ""busybox:musl"" already present on machine"
0.456,Event,ADDED,eval-sanitize-1-r0-198-k96z2.18d4a218372c91fa,reason=Created count=1 msg=Created container: task
0.4562,Event,ADDED,eval-sanitize-1-r0-198-k96z2.18d4a2183d15503e,reason=Started count=1 msg=Started container task
0.4564,Event,ADDED,eval-sanitize-1-r0-198.18d4a212c647922a,reason=SuccessfulCreate count=1 msg=Created pod: eval-sanitize-1-r0-198-k96z2
0.4565,Event,ADDED,eval-sanitize-1-r0-198.18d4a21dd8428fc6,reason=Completed count=1 msg=Job completed
0.4567,Event,ADDED,eval-sanitize-1-r0-199-tczbx.18d4a212f5b5a1a4,"reason=FailedScheduling count=None msg=0/6 nodes are available: 6 node(s) had untolerated taint(s). no new claims to deallocate, preemption: 0/6 nodes are available: 6 Preemption is not helpful for scheduling."
0.4568,Event,ADDED,eval-sanitize-1-r0-199-tczbx.18d4a217601c2346,"reason=FailedScheduling count=None msg=0/6 nodes are available: 1 c_wall violated: 1 conflicting context pair(s) with node memory, 5 node(s) had untolerated taint(s). no new claims to deallocate, preemption: 0/6 nodes are available: 1 No preemption victims found for incoming pod, 5 Preemption is not helpful for scheduling."
0.4571,Event,ADDED,eval-sanitize-1-r0-199-tczbx.18d4a21760cc6d96,"reason=FailedScheduling count=None msg=0/6 nodes are available: 1 c_wall violated: 1 conflicting context pair(s) with node memory, 5 node(s) had untolerated taint(s). no new claims to deallocate, preemption: 0/6 nodes are available: 1 No preemption victims found for incoming pod, 5 Preemption is not helpful for scheduling."
0.4573,Event,ADDED,eval-sanitize-1-r0-199-tczbx.18d4a218197b7356,"reason=FailedScheduling count=None msg=0/6 nodes are available: 1 c_wall violated: 1 conflicting context pair(s) with node memory, 5 node(s) had untolerated taint(s). no new claims to deallocate, preemption: 0/6 nodes are available: 1 No preemption victims found for incoming pod, 5 Preemption is not helpful for scheduling."
0.4574,Event,ADDED,eval-sanitize-1-r0-199-tczbx.18d4a2181a6bd9b4,reason=Scheduled count=None msg=Successfully assigned compute/eval-sanitize-1-r0-199-tczbx to kind-worker
0.4577,Event,ADDED,eval-sanitize-1-r0-199-tczbx.18d4a21835d322e7,"reason=Pulled count=1 msg=Container image ""busybox:musl"" already present on machine"
0.4578,Event,ADDED,eval-sanitize-1-r0-199-tczbx.18d4a2183748338d,reason=Created count=1 msg=Created container: task
0.458,Event,ADDED,eval-sanitize-1-r0-199-tczbx.18d4a2183d13d320,reason=Started count=1 msg=Started container task
0.4582,Event,ADDED,eval-sanitize-1-r0-199.18d4a212f5ab854b,reason=SuccessfulCreate count=1 msg=Created pod: eval-sanitize-1-r0-199-tczbx
0.4584,Event,ADDED,eval-sanitize-1-r0-199.18d4a21dc9528209,reason=Completed count=1 msg=Job completed
0.4585,Event,ADDED,eval-sanitize-1-r1-000-dtxtp.18d4a227c89af41c,reason=Scheduled count=None msg=Successfully assigned compute/eval-sanitize-1-r1-000-dtxtp to kind-worker3
0.4587,Event,ADDED,eval-sanitize-1-r1-000-dtxtp.18d4a227e1d018e7,"reason=Pulled count=1 msg=Container image ""busybox:musl"" already present on machine"
0.4589,Event,ADDED,eval-sanitize-1-r1-000-dtxtp.18d4a227e2fcc477,reason=Created count=1 msg=Created container: task
0.459,Event,ADDED,eval-sanitize-1-r1-000-dtxtp.18d4a227e638302a,reason=Started count=1 msg=Started container task
0.4592,Event,ADDED,eval-sanitize-1-r1-000.18d4a227c7a11d44,reason=SuccessfulCreate count=1 msg=Created pod: eval-sanitize-1-r1-000-dtxtp
0.4594,Event,ADDED,eval-sanitize-1-r1-000.18d4a22d509c4f3a,reason=Completed count=1 msg=Job completed
0.4599,Event,ADDED,eval-sanitize-1-r1-001-v7r9t.18d4a22802d3e23d,reason=Scheduled count=None msg=Successfully assigned compute/eval-sanitize-1-r1-001-v7r9t to kind-worker
0.4601,Event,ADDED,eval-sanitize-1-r1-001-v7r9t.18d4a2281c02f9b1,"reason=Pulled count=1 msg=Container image ""busybox:musl"" already present on machine"
0.4603,Event,ADDED,eval-sanitize-1-r1-001-v7r9t.18d4a2281d1e5c20,reason=Created count=1 msg=Created container: task
0.4605,Event,ADDED,eval-sanitize-1-r1-001-v7r9t.18d4a2281f1408b1,reason=Started count=1 msg=Started container task
0.4607,Event,ADDED,eval-sanitize-1-r1-001.18d4a228024d436e,reason=SuccessfulCreate count=1 msg=Created pod: eval-sanitize-1-r1-001-v7r9t
0.4609,Event,ADDED,eval-sanitize-1-r1-001.18d4a22da3e4b09b,reason=Completed count=1 msg=Job completed
0.4611,Event,ADDED,eval-sanitize-1-r1-002-bt6jp.18d4a2283e891d32,reason=Scheduled count=None msg=Successfully assigned compute/eval-sanitize-1-r1-002-bt6jp to kind-worker5
0.4614,Event,ADDED,eval-sanitize-1-r1-002-bt6jp.18d4a22856a97ca2,"reason=Pulled count=1 msg=Container image ""busybox:musl"" already present on machine"
0.4616,Event,ADDED,eval-sanitize-1-r1-002-bt6jp.18d4a22857c1dd2d,reason=Created count=1 msg=Created container: task
0.4618,Event,ADDED,eval-sanitize-1-r1-002-bt6jp.18d4a2285a01da46,reason=Started count=1 msg=Started container task
0.462,Event,ADDED,eval-sanitize-1-r1-002.18d4a2283d62c8b5,reason=SuccessfulCreate count=1 msg=Created pod: eval-sanitize-1-r1-002-bt6jp
0.4623,Event,ADDED,eval-sanitize-1-r1-002.18d4a22df0d6cea0,reason=Completed count=1 msg=Job completed
0.4624,Event,ADDED,eval-sanitize-1-r1-003-9s8g8.18d4a22879ce177e,reason=Scheduled count=None msg=Successfully assigned compute/eval-sanitize-1-r1-003-9s8g8 to kind-worker2
0.4626,Event,ADDED,eval-sanitize-1-r1-003-9s8g8.18d4a2289206148f,"reason=Pulled count=1 msg=Container image ""busybox:musl"" already present on machine"
0.463,Event,ADDED,eval-sanitize-1-r1-003-9s8g8.18d4a22893421ca6,reason=Created count=1 msg=Created container: task
0.4632,Event,ADDED,eval-sanitize-1-r1-003-9s8g8.18d4a22895353ff5,reason=Started count=1 msg=Started container task
0.4634,Event,ADDED,eval-sanitize-1-r1-003.18d4a22878b5e693,reason=SuccessfulCreate count=1 msg=Created pod: eval-sanitize-1-r1-003-9s8g8
0.4635,Event,ADDED,eval-sanitize-1-r1-003.18d4a22e16bda172,reason=Completed count=1 msg=Job completed
0.4637,Event,ADDED,eval-sanitize-1-r1-004-zphsx.18d4a228b451f808,reason=Scheduled count=None msg=Successfully assigned compute/eval-sanitize-1-r1-004-zphsx to kind-worker4
0.4639,Event,ADDED,eval-sanitize-1-r1-004-zphsx.18d4a228cd6f2135,"reason=Pulled count=1 msg=Container image ""busybox:musl"" already present on machine"
0.4641,Event,ADDED,eval-sanitize-1-r1-004-zphsx.18d4a228ce95c991,reason=Created count=1 msg=Created container: task
0.4642,Event,ADDED,eval-sanitize-1-r1-004-zphsx.18d4a228d23c296c,reason=Started count=1 msg=Started container task
0.4646,Event,ADDED,eval-sanitize-1-r1-004.18d4a228b3ea577e,reason=SuccessfulCreate count=1 msg=Created pod: eval-sanitize-1-r1-004-zphsx
0.4649,Event,ADDED,eval-sanitize-1-r1-004.18d4a22e68673d4f,reason=Completed count=1 msg=Job completed
0.4653,Event,ADDED,eval-sanitize-1-r1-005-g7klm.18d4a228ef95d43a,"reason=FailedScheduling count=None msg=0/6 nodes are available: 6 node(s) had untolerated taint(s). no new claims to deallocate, preemption: 0/6 nodes are available: 6 Preemption is not helpful for scheduling."
0.4655,Event,ADDED,eval-sanitize-1-r1-005-g7klm.18d4a22cedd615b5,reason=Scheduled count=None msg=Successfully assigned compute/eval-sanitize-1-r1-005-g7klm to kind-worker3
0.4657,Event,ADDED,eval-sanitize-1-r1-005-g7klm.18d4a22d0786549e,"reason=Pulled count=1 msg=Container image ""busybox:musl"" already present on machine"
0.4658,Event,ADDED,eval-sanitize-1-r1-005-g7klm.18d4a22d090b5739,reason=Created count=1 msg=Created container: task
0.466,Event,ADDED,eval-sanitize-1-r1-005-g7klm.18d4a22d0b7e1fff,reason=Started count=1 msg=Started container task
0.4662,Event,ADDED,eval-sanitize-1-r1-005.18d4a228ef8b31d8,reason=SuccessfulCreate count=1 msg=Created pod: eval-sanitize-1-r1-005-g7klm
0.4663,Event,ADDED,eval-sanitize-1-r1-005.18d4a232742b09f6,reason=Completed count=1 msg=Job completed
0.4665,Event,ADDED,eval-sanitize-1-r1-006-xzc9f.18d4a2292bc75c6a,"reason=FailedScheduling count=None msg=0/6 nodes are available: 6 node(s) had untolerated taint(s). no new claims to deallocate, preemption: 0/6 nodes are available: 6 Preemption is not helpful for scheduling."
0.4666,Event,ADDED,eval-sanitize-1-r1-006-xzc9f.18d4a22cee837eb3,reason=Scheduled count=None msg=Successfully assigned compute/eval-sanitize-1-r1-006-xzc9f to kind-worker3
0.4668,Event,ADDED,eval-sanitize-1-r1-006-xzc9f.18d4a22d0895b16c,"reason=Pulled count=1 msg=Container image ""busybox:musl"" already present on machine"
0.467,Event,ADDED,eval-sanitize-1-r1-006-xzc9f.18d4a22d0a86aa0c,reason=Created count=1 msg=Created container: task
0.4672,Event,ADDED,eval-sanitize-1-r1-006-xzc9f.18d4a22d0cdbb624,reason=Started count=1 msg=Started container task
0.4673,Event,ADDED,eval-sanitize-1-r1-006.18d4a2292bb94999,reason=SuccessfulCreate count=1 msg=Created pod: eval-sanitize-1-r1-006-xzc9f
0.4675,Event,ADDED,eval-sanitize-1-r1-006.18d4a23275554967,reason=Completed count=1 msg=Job completed
0.4676,Event,ADDED,eval-sanitize-1-r1-007-ml9kv.18d4a22967469212,"reason=FailedScheduling count=None msg=0/6 nodes are available: 6 node(s) had untolerated taint(s). no new claims to deallocate, preemption: 0/6 nodes are available: 6 Preemption is not helpful for scheduling."
0.4678,Event,ADDED,eval-sanitize-1-r1-007-ml9kv.18d4a22ceea4f5ae,reason=Scheduled count=None msg=Successfully assigned compute/eval-sanitize-1-r1-007-ml9kv to kind-worker3
0.4679,Event,ADDED,eval-sanitize-1-r1-007-ml9kv.18d4a22d087e879b,"reason=Pulled count=1 msg=Container image ""busybox:musl"" already present on machine"
0.4681,Event,ADDED,eval-sanitize-1-r1-007-ml9kv.18d4a22d0a1b430c,reason=Created count=1 msg=Created container: task
0.4683,Event,ADDED,eval-sanitize-1-r1-007-ml9kv.18d4a22d0c991389,reason=Started count=1 msg=Started container task
0.4685,Event,ADDED,eval-sanitize-1-r1-007.18d4a229673ba011,reason=SuccessfulCreate count=1 msg=Created pod: eval-sanitize-1-r1-007-ml9kv
0.4686,Event,ADDED,eval-sanitize-1-r1-007.18d4a232b12f4242,reason=Completed count=1 msg=Job completed
0.4688,Event,ADDED,eval-sanitize-1-r1-008-54ljj.18d4a229a2bb34fd,"reason=FailedScheduling count=None msg=0/6 nodes are available: 6 node(s) had untolerated taint(s). no new claims to deallocate, preemption: 0/6 nodes are available: 6 Preemption is not helpful for scheduling."
0.4689,Event,ADDED,eval-sanitize-1-r1-008-54ljj.18d4a22cee65da6f,"reason=FailedScheduling count=None msg=0/6 nodes are available: 1 c_wall violated: 3 conflicting context pair(s) with node memory, 5 node(s) had untolerated taint(s). no new claims to deallocate, preemption: 0/6 nodes are available: 1 No preemption victims found for incoming pod, 5 Preemption is not helpful for scheduling."
0.4692,Event,ADDED,eval-sanitize-1-r1-008-54ljj.18d4a22cff5c738c,"reason=FailedScheduling count=None msg=0/6 nodes are available: 1 c_wall violated: 3 conflicting context pair(s) with node memory, 5 node(s) had untolerated taint(s). no new claims to deallocate, preemption: 0/6 nodes are available: 1 No preemption victims found for incoming pod, 5 Preemption is not helpful for scheduling."
0.4694,Event,ADDED,eval-sanitize-1-r1-008-54ljj.18d4a22d6e2cf889,"reason=FailedScheduling count=None msg=0/6 nodes are available: 1 c_wall violated: 1 conflicting context pair(s) with node memory, 5 node(s) had untolerated taint(s). no new claims to deallocate, preemption: 0/6 nodes are available: 1 No preemption victims found for incoming pod, 5 Preemption is not helpful for scheduling."
0.4695,Event,ADDED,eval-sanitize-1-r1-008-54ljj.18d4a22d74d288b4,"reason=FailedScheduling count=None msg=0/6 nodes are available: 1 c_wall violated: 2 conflicting context pair(s) with node memory, 5 node(s) had untolerated taint(s). no new claims to deallocate, preemption: 0/6 nodes are available: 1 No preemption victims found for incoming pod, 5 Preemption is not helpful for scheduling."
0.4698,Event,ADDED,eval-sanitize-1-r1-008-54ljj.18d4a22d7981125d,"reason=FailedScheduling count=None msg=0/6 nodes are available: 1 c_wall violated: 2 conflicting context pair(s) with node memory, 5 node(s) had untolerated taint(s). no new claims to deallocate, preemption: 0/6 nodes are available: 1 No preemption victims found for incoming pod, 5 Preemption is not helpful for scheduling."
0.4699,Event,ADDED,eval-sanitize-1-r1-008-54ljj.18d4a22db3273eda,"reason=FailedScheduling count=None msg=0/6 nodes are available: 1 c_wall violated: 1 conflicting context pair(s) with node memory, 5 node(s) had untolerated taint(s). no new claims to deallocate, preemption: 0/6 nodes are available: 1 No preemption victims found for incoming pod, 5 Preemption is not helpful for scheduling."
0.4701,Event,ADDED,eval-sanitize-1-r1-008-54ljj.18d4a22de2458559,reason=Scheduled count=None msg=Successfully assigned compute/eval-sanitize-1-r1-008-54ljj to kind-worker2
0.4703,Event,ADDED,eval-sanitize-1-r1-008-54ljj.18d4a22dfecf3233,"reason=Pulled count=1 msg=Container image ""busybox:musl"" already present on machine"
0.4704,Event,ADDED,eval-sanitize-1-r1-008-54ljj.18d4a22e01058da8,reason=Created count=1 msg=Created container: task
0.4706,Event,ADDED,eval-sanitize-1-r1-008-54ljj.18d4a22e06d214ab,reason=Started count=1 msg=Started container task
0.4708,Event,ADDED,eval-sanitize-1-r1-008.18d4a229a2b0fc4a,reason=SuccessfulCreate count=1 msg=Created pod: eval-sanitize-1-r1-008-54ljj
0.4714,Event,ADDED,eval-sanitize-1-r1-008.18d4a23448c1b8fd,reason=Completed count=1 msg=Job completed
0.4716,Event,ADDED,eval-sanitize-1-r1-009-pcsqk.18d4a229de8be662,"reason=FailedScheduling count=None msg=0/6 nodes are available: 6 node(s) had untolerated taint(s). no new claims to deallocate, preemption: 0/6 nodes are available: 6 Preemption is not helpful for scheduling."
0.4717,Event,ADDED,eval-sanitize-1-r1-009-pcsqk.18d4a22cef17f2f1,"reason=FailedScheduling count=None msg=0/6 nodes are available: 1 c_wall violated: 1 conflicting context pair(s) with node memory, 5 node(s) had untolerated taint(s). no new claims to deallocate, preemption: 0/6 nodes are available: 1 No preemption victims found for incoming pod, 5 Preemption is not helpful for scheduling."
0.472,Event,ADDED,eval-sanitize-1-r1-009-pcsqk.18d4a22cff863026,"reason=FailedScheduling count=None msg=0/6 nodes are available: 1 c_wall violated: 2 conflicting context pair(s) with node memory, 5 node(s) had untolerated taint(s). no new claims to deallocate, preemption: 0/6 nodes are available: 1 No preemption victims found for incoming pod, 5 Preemption is not helpful for scheduling."
0.4722,Event,ADDED,eval-sanitize-1-r1-009-pcsqk.18d4a22d0632282d,"reason=FailedScheduling count=None msg=0/6 nodes are available: 1 c_wall violated: 2 conflicting context pair(s) with node memory, 5 node(s) had untolerated taint(s). no new claims to deallocate, preemption: 0/6 nodes are available: 1 No preemption victims found for incoming pod, 5 Preemption is not helpful for scheduling."
0.4723,Event,ADDED,eval-sanitize-1-r1-009-pcsqk.18d4a22d6eb0817d,"reason=FailedScheduling count=None msg=0/6 nodes are available: 1 c_wall violated: 1 conflicting context pair(s) with node memory, 5 node(s) had untolerated taint(s). no new claims to deallocate, preemption: 0/6 nodes are available: 1 No preemption victims found for incoming pod, 5 Preemption is not helpful for scheduling."
0.4726,Event,ADDED,eval-sanitize-1-r1-009-pcsqk.18d4a22d75474667,"reason=FailedScheduling count=None msg=0/6 nodes are available: 1 c_wall violated: 3 conflicting context pair(s) with node memory, 5 node(s) had untolerated taint(s). no new claims to deallocate, preemption: 0/6 nodes are available: 1 No preemption victims found for incoming pod, 5 Preemption is not helpful for scheduling."
0.4728,Event,ADDED,eval-sanitize-1-r1-009-pcsqk.18d4a22d79aeec40,"reason=FailedScheduling count=None msg=0/6 nodes are available: 1 c_wall violated: 3 conflicting context pair(s) with node memory, 5 node(s) had untolerated taint(s). no new claims to deallocate, preemption: 0/6 nodes are available: 1 No preemption victims found for incoming pod, 5 Preemption is not helpful for scheduling."
0.473,Event,ADDED,eval-sanitize-1-r1-009-pcsqk.18d4a22db0b58fcb,reason=Scheduled count=None msg=Successfully assigned compute/eval-sanitize-1-r1-009-pcsqk to kind-worker5
0.4733,Event,ADDED,eval-sanitize-1-r1-009-pcsqk.18d4a22dca856d99,"reason=Pulled count=1 msg=Container image ""busybox:musl"" already present on machine"
0.4735,Event,ADDED,eval-sanitize-1-r1-009-pcsqk.18d4a22dcb942a30,reason=Created count=1 msg=Created container: task
0.4736,Event,ADDED,eval-sanitize-1-r1-009-pcsqk.18d4a22dcf13183c,reason=Started count=1 msg=Started container task
0.474,Event,ADDED,eval-sanitize-1-r1-009.18d4a229de7d0f16,reason=SuccessfulCreate count=1 msg=Created pod: eval-sanitize-1-r1-009-pcsqk
0.4742,Event,ADDED,eval-sanitize-1-r1-009.18d4a234383d24ed,reason=Completed count=1 msg=Job completed
0.4744,Event,ADDED,eval-sanitize-1-r1-010-fzljc.18d4a22a1a28d60d,"reason=FailedScheduling count=None msg=0/6 nodes are available: 6 node(s) had untolerated taint(s). no new claims to deallocate, preemption: 0/6 nodes are available: 6 Preemption is not helpful for scheduling."
0.4746,Event,ADDED,eval-sanitize-1-r1-010-fzljc.18d4a22cefad7a81,"reason=FailedScheduling count=None msg=0/6 nodes are available: 1 c_wall violated: 3 conflicting context pair(s) with node memory, 5 node(s) had untolerated taint(s). no new claims to deallocate, preemption: 0/6 nodes are available: 1 No preemption victims found for incoming pod, 5 Preemption is not helpful for scheduling."
0.4748,Event,ADDED,eval-sanitize-1-r1-010-fzljc.18d4a22d03d04d3b,"reason=FailedScheduling count=None msg=0/6 nodes are available: 1 c_wall violated: 3 conflicting context pair(s) with node memory, 5 node(s) had untolerated taint(s). no new claims to deallocate, preemption: 0/6 nodes are available: 1 No preemption victims found for incoming pod, 5 Preemption is not helpful for scheduling."
0.475,Event,ADDED,eval-sanitize-1-r1-010-fzljc.18d4a22d6f6fa572,reason=Scheduled count=None msg=Successfully assigned compute/eval-sanitize-1-r1-010-fzljc to kind-worker
0.4751,Event,ADDED,eval-sanitize-1-r1-010-fzljc.18d4a22d88419513,"reason=Pulled count=1 msg=Container image ""busybox:musl"" already present on machine"
0.4753,Event,ADDED,eval-sanitize-1-r1-010-fzljc.18d4a22d8ab13ad3,reason=Created count=1 msg=Created container: task
0.4755,Event,ADDED,eval-sanitize-1-r1-010-fzljc.18d4a22d8ec48998,reason=Started count=1 msg=Started container task
0.4757,Event,ADDED,eval-sanitize-1-r1-010.18d4a22a1a213143,reason=SuccessfulCreate count=1 msg=Created pod: eval-sanitize-1-r1-010-fzljc
0.4759,Event,ADDED,eval-sanitize-1-r1-010.18d4a233a4184d30,reason=Completed count=1 msg=Job completed
0.4761,Event,ADDED,eval-sanitize-1-r1-011-4gx5x.18d4a22a5521a7a5,"reason=FailedScheduling count=None msg=0/6 nodes are available: 6 node(s) had untolerated taint(s). no new claims to deallocate, preemption: 0/6 nodes are available: 6 Preemption is not helpful for scheduling."
0.4763,Event,ADDED,eval-sanitize-1-r1-011-4gx5x.18d4a22cf291d4f0,reason=Scheduled count=None msg=Successfully assigned compute/eval-sanitize-1-r1-011-4gx5x to kind-worker3
0.4765,Event,ADDED,eval-sanitize-1-r1-011-4gx5x.18d4a22d0a3f8c6e,"reason=Pulled count=1 msg=Container image ""busybox:musl"" already present on machine"
0.4766,Event,ADDED,eval-sanitize-1-r1-011-4gx5x.18d4a22d0bb59ee3,reason=Created count=1 msg=Created container: task
0.4768,Event,ADDED,eval-sanitize-1-r1-011-4gx5x.18d4a22d0df5f271,reason=Started count=1 msg=Started container task
0.477,Event,ADDED,eval-sanitize-1-r1-011.18d4a22a55157373,reason=SuccessfulCreate count=1 msg=Created pod: eval-sanitize-1-r1-011-4gx5x
0.4772,Event,ADDED,eval-sanitize-1-r1-011.18d4a23274311451,reason=Completed count=1 msg=Job completed
0.4774,Event,ADDED,eval-sanitize-1-r1-012-snd79.18d4a22a913c8df6,"reason=FailedScheduling count=None msg=0/6 nodes are available: 6 node(s) had untolerated taint(s). no new claims to deallocate, preemption: 0/6 nodes are available: 6 Preemption is not helpful for scheduling."
0.4776,Event,ADDED,eval-sanitize-1-r1-012-snd79.18d4a22cf7e36140,"reason=FailedScheduling count=None msg=0/6 nodes are available: 1 c_wall violated: 3 conflicting context pair(s) with node memory, 5 node(s) had untolerated taint(s). no new claims to deallocate, preemption: 0/6 nodes are available: 1 No preemption victims found for incoming pod, 5 Preemption is not helpful for scheduling."
0.4777,Event,ADDED,eval-sanitize-1-r1-012-snd79.18d4a22d0406de95,"reason=FailedScheduling count=None msg=0/6 nodes are available: 1 c_wall violated: 4 conflicting context pair(s) with node memory, 5 node(s) had untolerated taint(s). no new claims to deallocate, preemption: 0/6 nodes are available: 1 No preemption victims found for incoming pod, 5 Preemption is not helpful for scheduling."
0.4779,Event,ADDED,eval-sanitize-1-r1-012-snd79.18d4a22d0b52f029,"reason=FailedScheduling count=None msg=0/6 nodes are available: 1 c_wall violated: 4 conflicting context pair(s) with node memory, 5 node(s) had untolerated taint(s). no new claims to deallocate, preemption: 0/6 nodes are available: 1 No preemption victims found for incoming pod, 5 Preemption is not helpful for scheduling."
0.4781,Event,ADDED,eval-sanitize-1-r1-012-snd79.18d4a22d6f50cf4f,"reason=FailedScheduling count=None msg=0/6 nodes are available: 1 c_wall violated: 2 conflicting context pair(s) with node memory, 5 node(s) had untolerated taint(s). no new claims to deallocate, preemption: 0/6 nodes are available: 1 No preemption victims found for incoming pod, 5 Preemption is not helpful for scheduling."
0.4782,Event,ADDED,eval-sanitize-1-r1-012-snd79.18d4a22d75b6aab7,"reason=FailedScheduling count=None msg=0/6 nodes are available: 1 c_wall violated: 3 conflicting context pair(s) with node memory, 5 node(s) had untolerated taint(s). no new claims to deallocate, preemption: 0/6 nodes are available: 1 No preemption victims found for incoming pod, 5 Preemption is not helpful for scheduling."
0.4784,Event,ADDED,eval-sanitize-1-r1-012-snd79.18d4a22d79dce1b8,"reason=FailedScheduling count=None msg=0/6 nodes are available: 1 c_wall violated: 3 conflicting context pair(s) with node memory, 5 node(s) had untolerated taint(s). no new claims to deallocate, preemption: 0/6 nodes are available: 1 No preemption victims found for incoming pod, 5 Preemption is not helpful for scheduling."
0.4786,Event,ADDED,eval-sanitize-1-r1-012-snd79.18d4a22da9732745,reason=Scheduled count=None msg=Successfully assigned compute/eval-sanitize-1-r1-012-snd79 to kind-worker5
0.4788,Event,ADDED,eval-sanitize-1-r1-012-snd79.18d4a22dc30468b8,"reason=Pulled count=1 msg=Container image ""busybox:musl"" already present on machine"
0.4789,Event,ADDED,eval-sanitize-1-r1-012-snd79.18d4a22dc4cb5189,reason=Created count=1 msg=Created container: task
0.4791,Event,ADDED,eval-sanitize-1-r1-012-snd79.18d4a22dc9bd691f,reason=Started count=1 msg=Started container task
0.4793,Event,ADDED,eval-sanitize-1-r1-012.18d4a22a912fb175,reason=SuccessfulCreate count=1 msg=Created pod: eval-sanitize-1-r1-012-snd79
0.4794,Event,ADDED,eval-sanitize-1-r1-012.18d4a233d0be0289,reason=Completed count=1 msg=Job completed
0.4796,Event,ADDED,eval-sanitize-1-r1-013-fckpr.18d4a22accab4e4a,"reason=FailedScheduling count=None msg=0/6 nodes are available: 6 node(s) had untolerated taint(s). no new claims to deallocate, preemption: 0/6 nodes are available: 6 Preemption is not helpful for scheduling."
0.4797,Event,ADDED,eval-sanitize-1-r1-013-fckpr.18d4a22cf8753a4b,"reason=FailedScheduling count=None msg=0/6 nodes are available: 1 c_wall violated: 1 conflicting context pair(s) with node memory, 5 node(s) had untolerated taint(s). no new claims to deallocate, preemption: 0/6 nodes are available: 1 No preemption victims found for incoming pod, 5 Preemption is not helpful for scheduling."
0.4799,Event,ADDED,eval-sanitize-1-r1-013-fckpr.18d4a22d048590dd,"reason=FailedScheduling count=None msg=0/6 nodes are available: 1 c_wall violated: 1 conflicting context pair(s) with node memory, 5 node(s) had untolerated taint(s). no new claims to deallocate, preemption: 0/6 nodes are available: 1 No preemption victims found for incoming pod, 5 Preemption is not helpful for scheduling."
0.48,Event,ADDED,eval-sanitize-1-r1-013-fckpr.18d4a22d6cbeb59b,reason=Scheduled count=None msg=Successfully assigned compute/eval-sanitize-1-r1-013-fckpr to kind-worker
0.4802,Event,ADDED,eval-sanitize-1-r1-013-fckpr.18d4a22d87443289,"reason=Pulled count=1 msg=Container image ""busybox:musl"" already present on machine"
0.4804,Event,ADDED,eval-sanitize-1-r1-013-fckpr.18d4a22d89179fa2,reason=Created count=1 msg=Created container: task
0.4805,Event,ADDED,eval-sanitize-1-r1-013-fckpr.18d4a22d8e092f06,reason=Started count=1 msg=Started container task
0.4807,Event,ADDED,eval-sanitize-1-r1-013.18d4a22acca0c6a8,reason=SuccessfulCreate count=1 msg=Created pod: eval-sanitize-1-r1-013-fckpr
0.4809,Event,ADDED,eval-sanitize-1-r1-013.18d4a233a648b30d,reason=Completed count=1 msg=Job completed
0.4811,Event,ADDED,eval-sanitize-1-r1-014-s8xgd.18d4a22b08295f76,"reason=FailedScheduling count=None msg=0/6 nodes are available: 6 node(s) had untolerated taint(s). no new claims to deallocate, preemption: 0/6 nodes are available: 6 Preemption is not helpful for scheduling."
0.4813,Event,ADDED,eval-sanitize-1-r1-014-s8xgd.18d4a22cf92b07d4,reason=Scheduled count=None msg=Successfully assigned compute/eval-sanitize-1-r1-014-s8xgd to kind-worker3
0.4816,Event,ADDED,eval-sanitize-1-r1-014-s8xgd.18d4a22d13acd5fe,"reason=Pulled count=1 msg=Container image ""busybox:musl"" already present on machine"
0.4818,Event,ADDED,eval-sanitize-1-r1-014-s8xgd.18d4a22d165e4a53,reason=Created count=1 msg=Created container: task
0.482,Event,ADDED,eval-sanitize-1-r1-014-s8xgd.18d4a22d1a0671b7,reason=Started count=1 msg=Started container task
0.4822,Event,ADDED,eval-sanitize-1-r1-014.18d4a22b081dd7a7,reason=SuccessfulCreate count=1 msg=Created pod: eval-sanitize-1-r1-014-s8xgd
0.4824,Event,ADDED,eval-sanitize-1-r1-014.18d4a232b1c68141,reason=Completed count=1 msg=Job completed
0.4825,Event,ADDED,eval-sanitize-1-r1-015-qvnqr.18d4a22b43bc2d11,"reason=FailedScheduling count=None msg=0/6 nodes are available: 6 node(s) had untolerated taint(s). no new claims to deallocate, preemption: 0/6 nodes are available: 6 Preemption is not helpful for scheduling."
0.4827,Event,ADDED,eval-sanitize-1-r1-015-qvnqr.18d4a22cf90e650e,"reason=FailedScheduling count=None msg=0/6 nodes are available: 1 c_wall violated: 1 conflicting context pair(s) with node memory, 5 node(s) had untolerated taint(s). no new claims to deallocate, preemption: 0/6 nodes are available: 1 No preemption victims found for incoming pod, 5 Preemption is not helpful for scheduling."
