t_recv,kind,type,name,detail
0.0208,Node,ADDED,kind-control-plane,taints=1
0.0254,Node,ADDED,kind-worker,taints=0
0.0268,Node,ADDED,kind-worker2,taints=0
0.0281,Node,ADDED,kind-worker3,taints=0
0.0295,Node,ADDED,kind-worker4,taints=0
0.0307,Node,ADDED,kind-worker5,taints=0
0.0435,TaskRequest,ADDED,eval-conflicts-rho040-r4-000,phase=None job=None
0.0471,TaskRequest,MODIFIED,eval-conflicts-rho040-r4-000,phase=Pending job=None
0.0567,Event,ADDED,eval-conflicts-rho010-r7-097.18d46734c55d068c,reason=Completed count=1 msg=Job completed
0.0572,Event,ADDED,eval-conflicts-rho010-r7-099.18d467349ba6da1d,reason=Completed count=1 msg=Job completed
0.0574,Event,ADDED,eval-conflicts-rho010-r8-000-tn6sl.18d4673a65b7afdd,reason=Scheduled count=None msg=Successfully assigned compute/eval-conflicts-rho010-r8-000-tn6sl to kind-worker
0.0576,Event,ADDED,eval-conflicts-rho010-r8-000-tn6sl.18d4673a86bf747d,"reason=Pulled count=1 msg=Container image ""busybox:musl"" already present on machine"
0.0578,Event,ADDED,eval-conflicts-rho010-r8-000-tn6sl.18d4673a87fd7167,reason=Created count=1 msg=Created container: task
0.0581,Event,ADDED,eval-conflicts-rho010-r8-000-tn6sl.18d4673a8c945aa1,reason=Started count=1 msg=Started container task
0.0582,Event,ADDED,eval-conflicts-rho010-r8-000.18d4673a64a32838,reason=SuccessfulCreate count=1 msg=Created pod: eval-conflicts-rho010-r8-000-tn6sl
0.0584,Event,ADDED,eval-conflicts-rho010-r8-000.18d4673db5de56b3,reason=Completed count=1 msg=Job completed
0.0586,Event,ADDED,eval-conflicts-rho010-r8-001-njlm8.18d4673a9fd56748,reason=Scheduled count=None msg=Successfully assigned compute/eval-conflicts-rho010-r8-001-njlm8 to kind-worker2
0.059,Event,ADDED,eval-conflicts-rho010-r8-001-njlm8.18d4673abb33c870,"reason=Pulled count=1 msg=Container image ""busybox:musl"" already present on machine"
0.0592,Event,ADDED,eval-conflicts-rho010-r8-001-njlm8.18d4673abc5b3699,reason=Created count=1 msg=Created container: task
0.0594,Event,ADDED,eval-conflicts-rho010-r8-001-njlm8.18d4673abea59590,reason=Started count=1 msg=Started container task
0.0599,Event,ADDED,eval-conflicts-rho010-r8-001.18d4673a9ebe6447,reason=SuccessfulCreate count=1 msg=Created pod: eval-conflicts-rho010-r8-001-njlm8
0.0601,Event,ADDED,eval-conflicts-rho010-r8-001.18d4673df2be9af7,reason=Completed count=1 msg=Job completed
0.0603,Event,ADDED,eval-conflicts-rho010-r8-002-cw5kd.18d4673ae0e5e09f,reason=Scheduled count=None msg=Successfully assigned compute/eval-conflicts-rho010-r8-002-cw5kd to kind-worker5
0.0605,Event,ADDED,eval-conflicts-rho010-r8-002-cw5kd.18d4673af9d9e950,"reason=Pulled count=1 msg=Container image ""busybox:musl"" already present on machine"
0.0608,Event,ADDED,eval-conflicts-rho010-r8-002-cw5kd.18d4673afae99315,reason=Created count=1 msg=Created container: task
0.061,Event,ADDED,eval-conflicts-rho010-r8-002-cw5kd.18d4673b03239377,reason=Started count=1 msg=Started container task
0.0612,Event,ADDED,eval-conflicts-rho010-r8-002.18d4673ae02bd233,reason=SuccessfulCreate count=1 msg=Created pod: eval-conflicts-rho010-r8-002-cw5kd
0.0613,Event,ADDED,eval-conflicts-rho010-r8-002.18d4673e3765c17d,reason=Completed count=1 msg=Job completed
0.0617,Event,ADDED,eval-conflicts-rho010-r8-003-f96vf.18d4673b16a43fc0,reason=Scheduled count=None msg=Successfully assigned compute/eval-conflicts-rho010-r8-003-f96vf to kind-worker5
0.0619,Event,ADDED,eval-conflicts-rho010-r8-003-f96vf.18d4673b33a93a96,"reason=Pulled count=1 msg=Container image ""busybox:musl"" already present on machine"
0.0621,Event,ADDED,eval-conflicts-rho010-r8-003-f96vf.18d4673b34debe22,reason=Created count=1 msg=Created container: task
0.0624,Event,ADDED,eval-conflicts-rho010-r8-003-f96vf.18d4673b3a522b06,reason=Started count=1 msg=Started container task
0.0626,Event,ADDED,eval-conflicts-rho010-r8-003.18d4673b15e6b7d3,reason=SuccessfulCreate count=1 msg=Created pod: eval-conflicts-rho010-r8-003-f96vf
0.0628,Event,ADDED,eval-conflicts-rho010-r8-003.18d4673e732f9ac2,reason=Completed count=1 msg=Job completed
0.063,Event,ADDED,eval-conflicts-rho010-r8-004-bglfb.18d4673b523b7769,reason=Scheduled count=None msg=Successfully assigned compute/eval-conflicts-rho010-r8-004-bglfb to kind-worker5
0.0636,Job,ADDED,eval-conflicts-rho040-r4-000,
0.0639,Event,ADDED,eval-conflicts-rho010-r8-004-bglfb.18d4673b6b6ece75,"reason=Pulled count=1 msg=Container image ""busybox:musl"" already present on machine"
0.0641,Event,ADDED,eval-conflicts-rho010-r8-004-bglfb.18d4673b6cb0b7dc,reason=Created count=1 msg=Created container: task
0.0643,Event,ADDED,eval-conflicts-rho010-r8-004-bglfb.18d4673b75557ea7,reason=Started count=1 msg=Started container task
0.0646,Event,ADDED,eval-conflicts-rho010-r8-004.18d4673b51682fb0,reason=SuccessfulCreate count=1 msg=Created pod: eval-conflicts-rho010-r8-004-bglfb
0.0648,Event,ADDED,eval-conflicts-rho010-r8-004.18d4673eaf73e6d3,reason=Completed count=1 msg=Job completed
0.065,Event,ADDED,eval-conflicts-rho010-r8-005-2r2mh.18d4673b914be17d,reason=Scheduled count=None msg=Successfully assigned compute/eval-conflicts-rho010-r8-005-2r2mh to kind-worker4
0.0652,Event,ADDED,eval-conflicts-rho010-r8-005-2r2mh.18d4673bac013234,"reason=Pulled count=1 msg=Container image ""busybox:musl"" already present on machine"
0.0655,Event,ADDED,eval-conflicts-rho010-r8-005-2r2mh.18d4673bad19d920,reason=Created count=1 msg=Created container: task
0.0656,Event,ADDED,eval-conflicts-rho010-r8-005-2r2mh.18d4673bb6f46363,reason=Started count=1 msg=Started container task
0.0658,Event,ADDED,eval-conflicts-rho010-r8-005.18d4673b90c38a57,reason=SuccessfulCreate count=1 msg=Created pod: eval-conflicts-rho010-r8-005-2r2mh
0.066,Event,ADDED,eval-conflicts-rho010-r8-005.18d4673ef37aad27,reason=Completed count=1 msg=Job completed
0.0663,Event,ADDED,eval-conflicts-rho010-r8-006-ngpgs.18d4673bc92746fa,reason=Scheduled count=None msg=Successfully assigned compute/eval-conflicts-rho010-r8-006-ngpgs to kind-worker4
0.0665,Event,ADDED,eval-conflicts-rho010-r8-006-ngpgs.18d4673be60f9299,"reason=Pulled count=1 msg=Container image ""busybox:musl"" already present on machine"
0.0667,Event,ADDED,eval-conflicts-rho010-r8-006-ngpgs.18d4673be7264cfc,reason=Created count=1 msg=Created container: task
0.0671,Event,ADDED,eval-conflicts-rho010-r8-006-ngpgs.18d4673bf1e05ac6,reason=Started count=1 msg=Started container task
0.0673,Event,ADDED,eval-conflicts-rho010-r8-006.18d4673bc884301e,reason=SuccessfulCreate count=1 msg=Created pod: eval-conflicts-rho010-r8-006-ngpgs
0.0675,Event,ADDED,eval-conflicts-rho010-r8-006.18d4673f2ec0d893,reason=Completed count=1 msg=Job completed
0.0677,Event,ADDED,eval-conflicts-rho010-r8-007-fx9zs.18d4673c0aaa0b0d,reason=Scheduled count=None msg=Successfully assigned compute/eval-conflicts-rho010-r8-007-fx9zs to kind-worker4
0.0679,TaskRequest,MODIFIED,eval-conflicts-rho040-r4-000,phase=Scheduled job=None
0.0682,Event,ADDED,eval-conflicts-rho010-r8-007-fx9zs.18d4673c271f80d0,"reason=Pulled count=1 msg=Container image ""busybox:musl"" already present on machine"
0.0686,Event,ADDED,eval-conflicts-rho010-r8-007-fx9zs.18d4673c284d1926,reason=Created count=1 msg=Created container: task
0.0688,Event,ADDED,eval-conflicts-rho010-r8-007-fx9zs.18d4673c320e5249,reason=Started count=1 msg=Started container task
0.0694,Event,ADDED,eval-conflicts-rho010-r8-007.18d4673c09d09122,reason=SuccessfulCreate count=1 msg=Created pod: eval-conflicts-rho010-r8-007-fx9zs
0.0698,Event,ADDED,eval-conflicts-rho010-r8-007.18d4673f6afae138,reason=Completed count=1 msg=Job completed
0.07,Event,ADDED,eval-conflicts-rho010-r8-008-d4jkz.18d4673c409f5c44,reason=Scheduled count=None msg=Successfully assigned compute/eval-conflicts-rho010-r8-008-d4jkz to kind-worker3
0.0702,Event,ADDED,eval-conflicts-rho010-r8-008-d4jkz.18d4673c5f1e8230,"reason=Pulled count=1 msg=Container image ""busybox:musl"" already present on machine"
0.0707,Event,ADDED,eval-conflicts-rho010-r8-008-d4jkz.18d4673c604560bd,reason=Created count=1 msg=Created container: task
0.0712,Event,ADDED,eval-conflicts-rho010-r8-008-d4jkz.18d4673c68710656,reason=Started count=1 msg=Started container task
0.0714,Event,ADDED,eval-conflicts-rho010-r8-008.18d4673c4016dc56,reason=SuccessfulCreate count=1 msg=Created pod: eval-conflicts-rho010-r8-008-d4jkz
0.0716,Event,ADDED,eval-conflicts-rho010-r8-008.18d4673f80f2b9af,reason=Completed count=1 msg=Job completed
0.0724,Pod,ADDED,eval-conflicts-rho040-r4-000-nlsct,phase=Pending node=None
0.0726,Event,ADDED,eval-conflicts-rho010-r8-009-ls7rk.18d4673c81e34b95,reason=Scheduled count=None msg=Successfully assigned compute/eval-conflicts-rho010-r8-009-ls7rk to kind-worker4
0.0728,Event,ADDED,eval-conflicts-rho010-r8-009-ls7rk.18d4673c9d02079b,"reason=Pulled count=1 msg=Container image ""busybox:musl"" already present on machine"
0.073,Event,ADDED,eval-conflicts-rho010-r8-009-ls7rk.18d4673c9e551e4d,reason=Created count=1 msg=Created container: task
0.0734,Event,ADDED,eval-conflicts-rho010-r8-009-ls7rk.18d4673ca0868744,reason=Started count=1 msg=Started container task
0.0736,Event,ADDED,eval-conflicts-rho010-r8-009.18d4673c810d116d,reason=SuccessfulCreate count=1 msg=Created pod: eval-conflicts-rho010-r8-009-ls7rk
0.0737,Event,ADDED,eval-conflicts-rho010-r8-009.18d4673fe28bb826,reason=Completed count=1 msg=Job completed
0.0739,Event,ADDED,eval-conflicts-rho010-r8-010-p6cqq.18d4673cb848cf1a,"reason=FailedScheduling count=None msg=0/6 nodes are available: 2 c_wall violated: 1 conflicting context pair(s) with node memory, 4 node(s) had untolerated taint(s). no new claims to deallocate, preemption: 0/6 nodes are available: 2 No preemption victims found for incoming pod, 4 Preemption is not helpful for scheduling."
0.0743,Event,ADDED,eval-conflicts-rho010-r8-010-p6cqq.18d4673cb9504268,"reason=FailedScheduling count=None msg=0/6 nodes are available: 2 c_wall violated: 1 conflicting context pair(s) with node memory, 4 node(s) had untolerated taint(s). no new claims to deallocate, preemption: 0/6 nodes are available: 2 No preemption victims found for incoming pod, 4 Preemption is not helpful for scheduling."
0.0746,Event,ADDED,eval-conflicts-rho010-r8-010-p6cqq.18d4673d2a641b1a,"reason=FailedScheduling count=None msg=0/6 nodes are available: 1 c_wall violated: 1 conflicting context pair(s) with node memory, 5 node(s) had untolerated taint(s). no new claims to deallocate, preemption: 0/6 nodes are available: 1 No preemption victims found for incoming pod, 5 Preemption is not helpful for scheduling."
0.0747,Event,ADDED,eval-conflicts-rho010-r8-010-p6cqq.18d4673f5db17d85,reason=Scheduled count=None msg=Successfully assigned compute/eval-conflicts-rho010-r8-010-p6cqq to kind-worker
0.0754,Job,MODIFIED,eval-conflicts-rho040-r4-000,
0.0758,Event,ADDED,eval-conflicts-rho010-r8-010-p6cqq.18d4673f7896bc8b,"reason=Pulled count=1 msg=Container image ""busybox:musl"" already present on machine"
0.076,Event,ADDED,eval-conflicts-rho010-r8-010-p6cqq.18d4673f7c0f9631,reason=Created count=1 msg=Created container: task
0.0762,Event,ADDED,eval-conflicts-rho010-r8-010-p6cqq.18d4673f8168b1f9,reason=Started count=1 msg=Started container task
0.0763,TaskRequest,MODIFIED,eval-conflicts-rho040-r4-000,phase=Scheduled job=None
0.0766,Event,ADDED,eval-conflicts-rho010-r8-010.18d4673cb7d546f2,reason=SuccessfulCreate count=1 msg=Created pod: eval-conflicts-rho010-r8-010-p6cqq
0.0768,Event,ADDED,eval-conflicts-rho010-r8-010.18d467426479c1fa,reason=Completed count=1 msg=Job completed
0.077,Event,ADDED,eval-conflicts-rho010-r8-011-2zv4h.18d4673cf2d8d59f,reason=Scheduled count=None msg=Successfully assigned compute/eval-conflicts-rho010-r8-011-2zv4h to kind-worker4
0.0771,Event,ADDED,eval-conflicts-rho010-r8-011-2zv4h.18d4673d0b6daedc,"reason=Pulled count=1 msg=Container image ""busybox:musl"" already present on machine"
0.0775,Event,ADDED,eval-conflicts-rho010-r8-011-2zv4h.18d4673d0c83377d,reason=Created count=1 msg=Created container: task
0.0778,Event,ADDED,eval-conflicts-rho010-r8-011-2zv4h.18d4673d0ef31de8,reason=Started count=1 msg=Started container task
0.0782,Event,ADDED,eval-conflicts-rho010-r8-011.18d4673cf2458109,reason=SuccessfulCreate count=1 msg=Created pod: eval-conflicts-rho010-r8-011-2zv4h
0.0784,Event,ADDED,eval-conflicts-rho010-r8-011.18d467401dcd73bb,reason=Completed count=1 msg=Job completed
0.0786,Event,ADDED,eval-conflicts-rho010-r8-012-h9vq9.18d4673d2df05ecc,"reason=FailedScheduling count=None msg=0/6 nodes are available: 1 c_wall violated: 1 conflicting context pair(s) with node memory, 5 node(s) had untolerated taint(s). no new claims to deallocate, preemption: 0/6 nodes are available: 1 No preemption victims found for incoming pod, 5 Preemption is not helpful for scheduling."
0.0788,Event,ADDED,eval-conflicts-rho010-r8-012-h9vq9.18d4673d2e74718e,"reason=FailedScheduling count=None msg=0/6 nodes are available: 1 c_wall violated: 1 conflicting context pair(s) with node memory, 5 node(s) had untolerated taint(s). no new claims to deallocate, preemption: 0/6 nodes are available: 1 No preemption victims found for incoming pod, 5 Preemption is not helpful for scheduling."
0.079,Event,ADDED,eval-conflicts-rho010-r8-012-h9vq9.18d4673f627597dd,reason=Scheduled count=None msg=Successfully assigned compute/eval-conflicts-rho010-r8-012-h9vq9 to kind-worker
0.0793,Event,ADDED,eval-conflicts-rho010-r8-012-h9vq9.18d4673f79cabaa5,"reason=Pulled count=1 msg=Container image ""busybox:musl"" already present on machine"
0.0795,Event,ADDED,eval-conflicts-rho010-r8-012-h9vq9.18d4673f7cdfa994,reason=Created count=1 msg=Created container: task
0.0797,Event,ADDED,eval-conflicts-rho010-r8-012-h9vq9.18d4673f80b20ed3,reason=Started count=1 msg=Started container task
0.08,Event,ADDED,eval-conflicts-rho010-r8-012.18d4673d2db70dc2,reason=SuccessfulCreate count=1 msg=Created pod: eval-conflicts-rho010-r8-012-h9vq9
0.0802,Event,ADDED,eval-conflicts-rho010-r8-012.18d467429dac2c42,reason=Completed count=1 msg=Job completed
0.0804,Event,ADDED,eval-conflicts-rho010-r8-013-lq2xp.18d4673d69c960f3,"reason=FailedScheduling count=None msg=0/6 nodes are available: 6 node(s) had untolerated taint(s). no new claims to deallocate, preemption: 0/6 nodes are available: 6 Preemption is not helpful for scheduling."
0.0805,Event,ADDED,eval-conflicts-rho010-r8-013-lq2xp.18d4673f62775afc,reason=Scheduled count=None msg=Successfully assigned compute/eval-conflicts-rho010-r8-013-lq2xp to kind-worker
0.0807,Event,ADDED,eval-conflicts-rho010-r8-013-lq2xp.18d4673f79b5bbe0,"reason=Pulled count=1 msg=Container image ""busybox:musl"" already present on machine"
0.0809,Event,ADDED,eval-conflicts-rho010-r8-013-lq2xp.18d4673f7d0133c1,reason=Created count=1 msg=Created container: task
0.0811,Event,ADDED,eval-conflicts-rho010-r8-013-lq2xp.18d4673f814cba36,reason=Started count=1 msg=Started container task
0.0812,Event,ADDED,eval-conflicts-rho010-r8-013.18d4673d69bc7e9b,reason=SuccessfulCreate count=1 msg=Created pod: eval-conflicts-rho010-r8-013-lq2xp
0.0817,Event,ADDED,eval-conflicts-rho010-r8-013.18d467429e24e33b,reason=Completed count=1 msg=Job completed
0.0821,Event,ADDED,eval-conflicts-rho010-r8-014-mhx7n.18d4673da633634e,"reason=FailedScheduling count=None msg=0/6 nodes are available: 6 node(s) had untolerated taint(s). no new claims to deallocate, preemption: 0/6 nodes are available: 6 Preemption is not helpful for scheduling."
0.0823,Event,ADDED,eval-conflicts-rho010-r8-014-mhx7n.18d4673f62c73d44,reason=Scheduled count=None msg=Successfully assigned compute/eval-conflicts-rho010-r8-014-mhx7n to kind-worker
0.0829,Event,ADDED,eval-conflicts-rho010-r8-014-mhx7n.18d4673f80d4a601,"reason=Pulled count=1 msg=Container image ""busybox:musl"" already present on machine"
0.0831,Event,ADDED,eval-conflicts-rho010-r8-014-mhx7n.18d4673f834d8e9a,reason=Created count=1 msg=Created container: task
0.0833,Event,ADDED,eval-conflicts-rho010-r8-014-mhx7n.18d4673f88183003,reason=Started count=1 msg=Started container task
0.0836,Event,ADDED,eval-conflicts-rho010-r8-014.18d4673da62b15cc,reason=SuccessfulCreate count=1 msg=Created pod: eval-conflicts-rho010-r8-014-mhx7n
0.0844,Pod,MODIFIED,eval-conflicts-rho040-r4-000-nlsct,phase=Pending node=kind-worker2
0.0847,Event,ADDED,eval-conflicts-rho010-r8-014.18d46742da00551a,reason=Completed count=1 msg=Job completed
0.0849,Event,ADDED,eval-conflicts-rho010-r8-015-nhzdh.18d4673de185ed82,"reason=FailedScheduling count=None msg=0/6 nodes are available: 6 node(s) had untolerated taint(s). no new claims to deallocate, preemption: 0/6 nodes are available: 6 Preemption is not helpful for scheduling."
0.0851,Event,ADDED,eval-conflicts-rho010-r8-015-nhzdh.18d4673f63094459,reason=Scheduled count=None msg=Successfully assigned compute/eval-conflicts-rho010-r8-015-nhzdh to kind-worker
0.0854,Event,ADDED,eval-conflicts-rho010-r8-015-nhzdh.18d4673f7f25d897,"reason=Pulled count=1 msg=Container image ""busybox:musl"" already present on machine"
0.0858,Event,ADDED,eval-conflicts-rho010-r8-015-nhzdh.18d4673f80cc8b3d,reason=Created count=1 msg=Created container: task
0.086,Event,ADDED,eval-conflicts-rho010-r8-015-nhzdh.18d4673f86d6e88b,reason=Started count=1 msg=Started container task
0.0862,Event,ADDED,eval-conflicts-rho010-r8-015.18d4673de1754084,reason=SuccessfulCreate count=1 msg=Created pod: eval-conflicts-rho010-r8-015-nhzdh
0.0866,Event,ADDED,eval-conflicts-rho010-r8-015.18d46742db3f187d,reason=Completed count=1 msg=Job completed
0.0868,Event,ADDED,eval-conflicts-rho010-r8-016-tcnb8.18d4673e1c968f7b,"reason=FailedScheduling count=None msg=0/6 nodes are available: 6 node(s) had untolerated taint(s). no new claims to deallocate, preemption: 0/6 nodes are available: 6 Preemption is not helpful for scheduling."
0.087,Event,ADDED,eval-conflicts-rho010-r8-016-tcnb8.18d4673f63823c11,reason=Scheduled count=None msg=Successfully assigned compute/eval-conflicts-rho010-r8-016-tcnb8 to kind-worker
0.0872,Event,ADDED,eval-conflicts-rho010-r8-016-tcnb8.18d4673f8399b56c,"reason=Pulled count=1 msg=Container image ""busybox:musl"" already present on machine"
0.0874,Event,ADDED,eval-conflicts-rho010-r8-016-tcnb8.18d4673f84e2933b,reason=Created count=1 msg=Created container: task
0.0877,Event,ADDED,eval-conflicts-rho010-r8-016-tcnb8.18d4673f89000c49,reason=Started count=1 msg=Started container task
0.0879,Event,ADDED,eval-conflicts-rho010-r8-016.18d4673e1c8a7cc8,reason=SuccessfulCreate count=1 msg=Created pod: eval-conflicts-rho010-r8-016-tcnb8
0.0881,Event,ADDED,eval-conflicts-rho010-r8-016.18d46742649b9583,reason=Completed count=1 msg=Job completed
0.0883,Event,ADDED,eval-conflicts-rho010-r8-017-nmdd9.18d4673e592b8c20,"reason=FailedScheduling count=None msg=0/6 nodes are available: 6 node(s) had untolerated taint(s). no new claims to deallocate, preemption: 0/6 nodes are available: 6 Preemption is not helpful for scheduling."
0.0885,Event,ADDED,eval-conflicts-rho010-r8-017-nmdd9.18d4673f63a117c7,reason=Scheduled count=None msg=Successfully assigned compute/eval-conflicts-rho010-r8-017-nmdd9 to kind-worker
0.0886,Event,ADDED,eval-conflicts-rho010-r8-017-nmdd9.18d4673f81c49e91,"reason=Pulled count=1 msg=Container image ""busybox:musl"" already present on machine"
0.0888,Event,ADDED,eval-conflicts-rho010-r8-017-nmdd9.18d4673f83f366cf,reason=Created count=1 msg=Created container: task
0.089,Event,ADDED,eval-conflicts-rho010-r8-017-nmdd9.18d4673f890f3cf5,reason=Started count=1 msg=Started container task
0.0892,Event,ADDED,eval-conflicts-rho010-r8-017.18d4673e5922546c,reason=SuccessfulCreate count=1 msg=Created pod: eval-conflicts-rho010-r8-017-nmdd9
0.0894,Event,ADDED,eval-conflicts-rho010-r8-017.18d46742ea23da86,reason=Completed count=1 msg=Job completed
0.0895,Event,ADDED,eval-conflicts-rho010-r8-018-7l6pf.18d4673e942ec3a6,"reason=FailedScheduling count=None msg=0/6 nodes are available: 6 node(s) had untolerated taint(s). no new claims to deallocate, preemption: 0/6 nodes are available: 6 Preemption is not helpful for scheduling."
0.0897,Event,ADDED,eval-conflicts-rho010-r8-018-7l6pf.18d4673f63d7d3a9,"reason=FailedScheduling count=None msg=0/6 nodes are available: 1 c_wall violated: 1 conflicting context pair(s) with node memory, 5 node(s) had untolerated taint(s). no new claims to deallocate, preemption: 0/6 nodes are available: 1 No preemption victims found for incoming pod, 5 Preemption is not helpful for scheduling."
0.0903,Event,ADDED,eval-conflicts-rho010-r8-018-7l6pf.18d4673f69bfaa87,"reason=FailedScheduling count=None msg=0/6 nodes are available: 1 c_wall violated: 1 conflicting context pair(s) with node memory, 5 node(s) had untolerated taint(s). no new claims to deallocate, preemption: 0/6 nodes are available: 1 No preemption victims found for incoming pod, 5 Preemption is not helpful for scheduling."
0.0905,Event,ADDED,eval-conflicts-rho010-r8-018-7l6pf.18d4673f8e80ae9d,reason=Scheduled count=None msg=Successfully assigned compute/eval-conflicts-rho010-r8-018-7l6pf to kind-worker3
0.0907,Event,ADDED,eval-conflicts-rho010-r8-018-7l6pf.18d4673fa68a5ea2,"reason=Pulled count=1 msg=Container image ""busybox:musl"" already present on machine"
0.0909,Event,ADDED,eval-conflicts-rho010-r8-018-7l6pf.18d4673fa810eb63,reason=Created count=1 msg=Created container: task
0.0912,Event,ADDED,eval-conflicts-rho010-r8-018-7l6pf.18d4673faca15e0c,reason=Started count=1 msg=Started container task
0.0913,Event,ADDED,eval-conflicts-rho010-r8-018.18d4673e942483fc,reason=SuccessfulCreate count=1 msg=Created pod: eval-conflicts-rho010-r8-018-7l6pf
0.0915,Event,ADDED,eval-conflicts-rho010-r8-018.18d46742895bbb7a,reason=Completed count=1 msg=Job completed
0.0917,Event,ADDED,eval-conflicts-rho010-r8-019-zrf9n.18d4673ecf6ebabd,"reason=FailedScheduling count=None msg=0/6 nodes are available: 6 node(s) had untolerated taint(s). no new claims to deallocate, preemption: 0/6 nodes are available: 6 Preemption is not helpful for scheduling."
0.092,Event,ADDED,eval-conflicts-rho010-r8-019-zrf9n.18d4673f693e0ae3,reason=Scheduled count=None msg=Successfully assigned compute/eval-conflicts-rho010-r8-019-zrf9n to kind-worker
0.0922,Event,ADDED,eval-conflicts-rho010-r8-019-zrf9n.18d4673f86e4139a,"reason=Pulled count=1 msg=Container image ""busybox:musl"" already present on machine"
0.0924,Event,ADDED,eval-conflicts-rho010-r8-019-zrf9n.18d4673f8918e93f,reason=Created count=1 msg=Created container: task
0.0928,Event,ADDED,eval-conflicts-rho010-r8-019-zrf9n.18d4673f8ccff873,reason=Started count=1 msg=Started container task
0.093,Event,ADDED,eval-conflicts-rho010-r8-019.18d4673ecf6361ae,reason=SuccessfulCreate count=1 msg=Created pod: eval-conflicts-rho010-r8-019-zrf9n
0.0931,Event,ADDED,eval-conflicts-rho010-r8-019.18d4674263e076dc,reason=Completed count=1 msg=Job completed
0.0933,Event,ADDED,eval-conflicts-rho010-r8-020-tgr8x.18d4673f0ad99e5f,"reason=FailedScheduling count=None msg=0/6 nodes are available: 6 node(s) had untolerated taint(s). no new claims to deallocate, preemption: 0/6 nodes are available: 6 Preemption is not helpful for scheduling."
0.0938,Event,ADDED,eval-conflicts-rho010-r8-020-tgr8x.18d4673f68de9a0e,"reason=FailedScheduling count=None msg=0/6 nodes are available: 1 c_wall violated: 1 conflicting context pair(s) with node memory, 5 node(s) had untolerated taint(s). no new claims to deallocate, preemption: 0/6 nodes are available: 1 No preemption victims found for incoming pod, 5 Preemption is not helpful for scheduling."
0.0941,Event,ADDED,eval-conflicts-rho010-r8-020-tgr8x.18d4673f6a020c32,"reason=FailedScheduling count=None msg=0/6 nodes are available: 1 c_wall violated: 1 conflicting context pair(s) with node memory, 5 node(s) had untolerated taint(s). no new claims to deallocate, preemption: 0/6 nodes are available: 1 No preemption victims found for incoming pod, 5 Preemption is not helpful for scheduling."
0.0942,Event,ADDED,eval-conflicts-rho010-r8-020-tgr8x.18d4673f8ce3403b,reason=Scheduled count=None msg=Successfully assigned compute/eval-conflicts-rho010-r8-020-tgr8x to kind-worker3
0.0945,Event,ADDED,eval-conflicts-rho010-r8-020-tgr8x.18d4673fa573eefb,"reason=Pulled count=1 msg=Container image ""busybox:musl"" already present on machine"
0.0946,Event,ADDED,eval-conflicts-rho010-r8-020-tgr8x.18d4673fa75da449,reason=Created count=1 msg=Created container: task
0.0948,Event,ADDED,eval-conflicts-rho010-r8-020-tgr8x.18d4673fac2f0513,reason=Started count=1 msg=Started container task
0.095,Event,ADDED,eval-conflicts-rho010-r8-020.18d4673f0ad0faec,reason=SuccessfulCreate count=1 msg=Created pod: eval-conflicts-rho010-r8-020-tgr8x
0.0952,Event,ADDED,eval-conflicts-rho010-r8-020.18d4674288d1ce86,reason=Completed count=1 msg=Job completed
0.0953,Event,ADDED,eval-conflicts-rho010-r8-021-gnnrx.18d4673f461edc5d,"reason=FailedScheduling count=None msg=0/6 nodes are available: 6 node(s) had untolerated taint(s). no new claims to deallocate, preemption: 0/6 nodes are available: 6 Preemption is not helpful for scheduling."
0.0955,Event,ADDED,eval-conflicts-rho010-r8-021-gnnrx.18d4673f69e544b5,reason=Scheduled count=None msg=Successfully assigned compute/eval-conflicts-rho010-r8-021-gnnrx to kind-worker
0.0959,Event,ADDED,eval-conflicts-rho010-r8-021-gnnrx.18d4673f86dc68ab,"reason=Pulled count=1 msg=Container image ""busybox:musl"" already present on machine"
0.096,Event,ADDED,eval-conflicts-rho010-r8-021-gnnrx.18d4673f88ff61d4,reason=Created count=1 msg=Created container: task
0.0962,Event,ADDED,eval-conflicts-rho010-r8-021-gnnrx.18d4673f8ccecced,reason=Started count=1 msg=Started container task
0.0964,Event,ADDED,eval-conflicts-rho010-r8-021.18d4673f46165d35,reason=SuccessfulCreate count=1 msg=Created pod: eval-conflicts-rho010-r8-021-gnnrx
0.097,Event,ADDED,eval-conflicts-rho010-r8-021.18d4674264468639,reason=Completed count=1 msg=Job completed
0.0974,Event,ADDED,eval-conflicts-rho010-r8-022-wndq4.18d4673f82e0f549,reason=Scheduled count=None msg=Successfully assigned compute/eval-conflicts-rho010-r8-022-wndq4 to kind-worker
0.0976,Event,ADDED,eval-conflicts-rho010-r8-022-wndq4.18d4673f9bd01878,"reason=Pulled count=1 msg=Container image ""busybox:musl"" already present on machine"
0.0979,Event,ADDED,eval-conflicts-rho010-r8-022-wndq4.18d4673f9cd9173e,reason=Created count=1 msg=Created container: task
0.0982,Event,ADDED,eval-conflicts-rho010-r8-022-wndq4.18d4673f9eeae502,reason=Started count=1 msg=Started container task
0.0985,Event,ADDED,eval-conflicts-rho010-r8-022.18d4673f824df11d,reason=SuccessfulCreate count=1 msg=Created pod: eval-conflicts-rho010-r8-022-wndq4
0.0991,Event,ADDED,eval-conflicts-rho010-r8-022.18d467431d4a8d79,reason=Completed count=1 msg=Job completed
0.1005,Node,MODIFIED,kind-worker2,taints=0
0.1016,Pod,MODIFIED,eval-conflicts-rho040-r4-000-nlsct,phase=Pending node=kind-worker2
0.1019,Event,ADDED,eval-conflicts-rho010-r8-023-dc4nd.18d4673fbe5ecdc4,reason=Scheduled count=None msg=Successfully assigned compute/eval-conflicts-rho010-r8-023-dc4nd to kind-worker2
0.1021,Event,ADDED,eval-conflicts-rho010-r8-023-dc4nd.18d4673fd8231552,"reason=Pulled count=1 msg=Container image ""busybox:musl"" already present on machine"
0.1023,Event,ADDED,eval-conflicts-rho010-r8-023-dc4nd.18d4673fd93484b8,reason=Created count=1 msg=Created container: task
0.1024,Event,ADDED,eval-conflicts-rho010-r8-023-dc4nd.18d4673fddb8ffbe,reason=Started count=1 msg=Started container task
0.1028,Event,ADDED,eval-conflicts-rho010-r8-023.18d4673fbd3ab1f3,reason=SuccessfulCreate count=1 msg=Created pod: eval-conflicts-rho010-r8-023-dc4nd
0.103,Event,ADDED,eval-conflicts-rho010-r8-023.18d4674314bf37c9,reason=Completed count=1 msg=Job completed
0.1032,Event,ADDED,eval-conflicts-rho010-r8-024-fg4kx.18d4673ffac4107c,reason=Scheduled count=None msg=Successfully assigned compute/eval-conflicts-rho010-r8-024-fg4kx to kind-worker2
0.1037,Event,ADDED,eval-conflicts-rho010-r8-024-fg4kx.18d4674013e46a89,"reason=Pulled count=1 msg=Container image ""busybox:musl"" already present on machine"
0.1039,Event,ADDED,eval-conflicts-rho010-r8-024-fg4kx.18d4674014f1d28c,reason=Created count=1 msg=Created container: task
0.1041,Event,ADDED,eval-conflicts-rho010-r8-024-fg4kx.18d4674016f29bd2,reason=Started count=1 msg=Started container task
0.1042,Event,ADDED,eval-conflicts-rho010-r8-024.18d4673ff98cfb2e,reason=SuccessfulCreate count=1 msg=Created pod: eval-conflicts-rho010-r8-024-fg4kx
0.1046,Event,ADDED,eval-conflicts-rho010-r8-024.18d4674350a5984f,reason=Completed count=1 msg=Job completed
0.1047,Event,ADDED,eval-conflicts-rho010-r8-025-tjmbt.18d4674036821426,reason=Scheduled count=None msg=Successfully assigned compute/eval-conflicts-rho010-r8-025-tjmbt to kind-worker5
0.1051,Event,ADDED,eval-conflicts-rho010-r8-025-tjmbt.18d467404fefd4ad,"reason=Pulled count=1 msg=Container image ""busybox:musl"" already present on machine"
0.1054,Event,ADDED,eval-conflicts-rho010-r8-025-tjmbt.18d4674051352786,reason=Created count=1 msg=Created container: task
0.1059,Event,ADDED,eval-conflicts-rho010-r8-025-tjmbt.18d46740532e63b8,reason=Started count=1 msg=Started container task
0.106,Event,ADDED,eval-conflicts-rho010-r8-025.18d4674035492ce5,reason=SuccessfulCreate count=1 msg=Created pod: eval-conflicts-rho010-r8-025-tjmbt
0.1062,Event,ADDED,eval-conflicts-rho010-r8-025.18d46743962c8a21,reason=Completed count=1 msg=Job completed
0.1065,Event,ADDED,eval-conflicts-rho010-r8-026-9m2kl.18d4674071829619,reason=Scheduled count=None msg=Successfully assigned compute/eval-conflicts-rho010-r8-026-9m2kl to kind-worker5
0.1067,Event,ADDED,eval-conflicts-rho010-r8-026-9m2kl.18d467408a5a5b46,"reason=Pulled count=1 msg=Container image ""busybox:musl"" already present on machine"
0.1069,Event,ADDED,eval-conflicts-rho010-r8-026-9m2kl.18d467408b624e29,reason=Created count=1 msg=Created container: task
0.107,Event,ADDED,eval-conflicts-rho010-r8-026-9m2kl.18d467408eb04815,reason=Started count=1 msg=Started container task
0.1073,Event,ADDED,eval-conflicts-rho010-r8-026.18d46740703131c8,reason=SuccessfulCreate count=1 msg=Created pod: eval-conflicts-rho010-r8-026-9m2kl
0.1074,Event,ADDED,eval-conflicts-rho010-r8-026.18d46743d233dba8,reason=Completed count=1 msg=Job completed
0.1077,Event,ADDED,eval-conflicts-rho010-r8-027-j4p62.18d46740adc4f952,reason=Scheduled count=None msg=Successfully assigned compute/eval-conflicts-rho010-r8-027-j4p62 to kind-worker5
0.1079,Event,ADDED,eval-conflicts-rho010-r8-027-j4p62.18d46740c80d0583,"reason=Pulled count=1 msg=Container image ""busybox:musl"" already present on machine"
0.1081,Event,ADDED,eval-conflicts-rho010-r8-027-j4p62.18d46740c92ca8da,reason=Created count=1 msg=Created container: task
0.1083,Event,ADDED,eval-conflicts-rho010-r8-027-j4p62.18d46740cb3ee22a,reason=Started count=1 msg=Started container task
0.1084,Event,ADDED,eval-conflicts-rho010-r8-027.18d46740ac560dab,reason=SuccessfulCreate count=1 msg=Created pod: eval-conflicts-rho010-r8-027-j4p62
0.1086,Event,ADDED,eval-conflicts-rho010-r8-027.18d467440e1a7fcd,reason=Completed count=1 msg=Job completed
0.1088,Event,ADDED,eval-conflicts-rho010-r8-028-nnfpw.18d46740e9582f7a,reason=Scheduled count=None msg=Successfully assigned compute/eval-conflicts-rho010-r8-028-nnfpw to kind-worker5
0.1089,Event,ADDED,eval-conflicts-rho010-r8-028-nnfpw.18d46741034e6d36,"reason=Pulled count=1 msg=Container image ""busybox:musl"" already present on machine"
0.1095,Event,ADDED,eval-conflicts-rho010-r8-028-nnfpw.18d46741047b9d51,reason=Created count=1 msg=Created container: task
0.1098,Event,ADDED,eval-conflicts-rho010-r8-028-nnfpw.18d4674108e5c958,reason=Started count=1 msg=Started container task
0.11,Event,ADDED,eval-conflicts-rho010-r8-028.18d46740e7cfe909,reason=SuccessfulCreate count=1 msg=Created pod: eval-conflicts-rho010-r8-028-nnfpw
0.1102,Event,ADDED,eval-conflicts-rho010-r8-028.18d4674449da2eff,reason=Completed count=1 msg=Job completed
0.1114,Node,MODIFIED,kind-worker2,taints=0
0.1117,Event,ADDED,eval-conflicts-rho010-r8-029-l6kgv.18d46741247f9323,reason=Scheduled count=None msg=Successfully assigned compute/eval-conflicts-rho010-r8-029-l6kgv to kind-worker2
0.1118,Event,ADDED,eval-conflicts-rho010-r8-029-l6kgv.18d467413d71d0ce,"reason=Pulled count=1 msg=Container image ""busybox:musl"" already present on machine"
0.112,Event,ADDED,eval-conflicts-rho010-r8-029-l6kgv.18d467413e838240,reason=Created count=1 msg=Created container: task
0.1122,Event,ADDED,eval-conflicts-rho010-r8-029-l6kgv.18d46741428bd3c3,reason=Started count=1 msg=Started container task
0.1125,Event,ADDED,eval-conflicts-rho010-r8-029.18d467412314883a,reason=SuccessfulCreate count=1 msg=Created pod: eval-conflicts-rho010-r8-029-l6kgv
0.1127,Event,ADDED,eval-conflicts-rho010-r8-029.18d467447ba954d5,reason=Completed count=1 msg=Job completed
0.1128,Event,ADDED,eval-conflicts-rho010-r8-030-p2gk9.18d467416044a0a1,reason=Scheduled count=None msg=Successfully assigned compute/eval-conflicts-rho010-r8-030-p2gk9 to kind-worker2
0.1131,Event,ADDED,eval-conflicts-rho010-r8-030-p2gk9.18d46741791ab41e,"reason=Pulled count=1 msg=Container image ""busybox:musl"" already present on machine"
0.1133,Event,ADDED,eval-conflicts-rho010-r8-030-p2gk9.18d467417a3157cc,reason=Created count=1 msg=Created container: task
0.1134,Event,ADDED,eval-conflicts-rho010-r8-030-p2gk9.18d467417e111d29,reason=Started count=1 msg=Started container task
0.1136,Event,ADDED,eval-conflicts-rho010-r8-030.18d467415ed43b62,reason=SuccessfulCreate count=1 msg=Created pod: eval-conflicts-rho010-r8-030-p2gk9
0.1139,Event,ADDED,eval-conflicts-rho010-r8-030.18d46744b77ac9bb,reason=Completed count=1 msg=Job completed
0.1141,Event,ADDED,eval-conflicts-rho010-r8-031-9bmbm.18d467419d055e61,reason=Scheduled count=None msg=Successfully assigned compute/eval-conflicts-rho010-r8-031-9bmbm to kind-worker5
0.1142,Event,ADDED,eval-conflicts-rho010-r8-031-9bmbm.18d46741b613f798,"reason=Pulled count=1 msg=Container image ""busybox:musl"" already present on machine"
0.1144,Event,ADDED,eval-conflicts-rho010-r8-031-9bmbm.18d46741b72ead1c,reason=Created count=1 msg=Created container: task
0.1149,Event,ADDED,eval-conflicts-rho010-r8-031-9bmbm.18d46741b92782d3,reason=Started count=1 msg=Started container task
0.1151,Event,ADDED,eval-conflicts-rho010-r8-031.18d467419b79ae76,reason=SuccessfulCreate count=1 msg=Created pod: eval-conflicts-rho010-r8-031-9bmbm
0.1152,Event,ADDED,eval-conflicts-rho010-r8-031.18d46744fd2c884b,reason=Completed count=1 msg=Job completed
0.1155,Event,ADDED,eval-conflicts-rho010-r8-032-mff4g.18d46741d7c56c56,reason=Scheduled count=None msg=Successfully assigned compute/eval-conflicts-rho010-r8-032-mff4g to kind-worker2
0.1158,Event,ADDED,eval-conflicts-rho010-r8-032-mff4g.18d46741f08dbfb5,"reason=Pulled count=1 msg=Container image ""busybox:musl"" already present on machine"
0.1159,Event,ADDED,eval-conflicts-rho010-r8-032-mff4g.18d46741f19a647a,reason=Created count=1 msg=Created container: task
0.1161,Event,ADDED,eval-conflicts-rho010-r8-032-mff4g.18d46741f3ad0993,reason=Started count=1 msg=Started container task
0.1165,Event,ADDED,eval-conflicts-rho010-r8-032.18d46741d69047a7,reason=SuccessfulCreate count=1 msg=Created pod: eval-conflicts-rho010-r8-032-mff4g
0.1166,Event,ADDED,eval-conflicts-rho010-r8-032.18d467452ee77343,reason=Completed count=1 msg=Job completed
0.1168,Event,ADDED,eval-conflicts-rho010-r8-033-pf64h.18d4674212237f28,reason=Scheduled count=None msg=Successfully assigned compute/eval-conflicts-rho010-r8-033-pf64h to kind-worker4
0.117,Event,ADDED,eval-conflicts-rho010-r8-033-pf64h.18d467422cb565f0,"reason=Pulled count=1 msg=Container image ""busybox:musl"" already present on machine"
0.1172,Event,ADDED,eval-conflicts-rho010-r8-033-pf64h.18d467422dfb67ac,reason=Created count=1 msg=Created container: task
0.1174,Event,ADDED,eval-conflicts-rho010-r8-033-pf64h.18d467423273bfec,reason=Started count=1 msg=Started container task
0.1175,Event,ADDED,eval-conflicts-rho010-r8-033.18d4674211b8c454,reason=SuccessfulCreate count=1 msg=Created pod: eval-conflicts-rho010-r8-033-pf64h
0.1179,Event,ADDED,eval-conflicts-rho010-r8-033.18d467457dc1263a,reason=Completed count=1 msg=Job completed
0.118,Event,ADDED,eval-conflicts-rho010-r8-034-sgnkc.18d467424e96093d,reason=Scheduled count=None msg=Successfully assigned compute/eval-conflicts-rho010-r8-034-sgnkc to kind-worker5
0.1182,Event,ADDED,eval-conflicts-rho010-r8-034-sgnkc.18d46742684bf049,"reason=Pulled count=1 msg=Container image ""busybox:musl"" already present on machine"
0.1184,Event,ADDED,eval-conflicts-rho010-r8-034-sgnkc.18d467426976433f,reason=Created count=1 msg=Created container: task
0.1187,Event,ADDED,eval-conflicts-rho010-r8-034-sgnkc.18d467426b728630,reason=Started count=1 msg=Started container task
0.1189,Event,ADDED,eval-conflicts-rho010-r8-034.18d467424d957166,reason=SuccessfulCreate count=1 msg=Created pod: eval-conflicts-rho010-r8-034-sgnkc
0.119,Event,ADDED,eval-conflicts-rho010-r8-034.18d46745b232fd24,reason=Completed count=1 msg=Job completed
0.1192,Event,ADDED,eval-conflicts-rho010-r8-035-csj6q.18d467428983ab01,reason=Scheduled count=None msg=Successfully assigned compute/eval-conflicts-rho010-r8-035-csj6q to kind-worker4
0.1194,Event,ADDED,eval-conflicts-rho010-r8-035-csj6q.18d46742a3a1ff9f,"reason=Pulled count=1 msg=Container image ""busybox:musl"" already present on machine"
0.1197,Event,ADDED,eval-conflicts-rho010-r8-035-csj6q.18d46742a4b4afc8,reason=Created count=1 msg=Created container: task
0.1198,Event,ADDED,eval-conflicts-rho010-r8-035-csj6q.18d46742a6bb0ff7,reason=Started count=1 msg=Started container task
0.1203,Event,ADDED,eval-conflicts-rho010-r8-035.18d4674288f6ca67,reason=SuccessfulCreate count=1 msg=Created pod: eval-conflicts-rho010-r8-035-csj6q
0.1205,Event,ADDED,eval-conflicts-rho010-r8-035.18d46745b9d4e43c,reason=Completed count=1 msg=Job completed
0.1207,Event,ADDED,eval-conflicts-rho010-r8-036-csgwr.18d46742c5417fa0,reason=Scheduled count=None msg=Successfully assigned compute/eval-conflicts-rho010-r8-036-csgwr to kind-worker4
0.1209,Event,ADDED,eval-conflicts-rho010-r8-036-csgwr.18d46742de755851,"reason=Pulled count=1 msg=Container image ""busybox:musl"" already present on machine"
0.1212,Event,ADDED,eval-conflicts-rho010-r8-036-csgwr.18d46742df78f4cb,reason=Created count=1 msg=Created container: task
0.1213,Event,ADDED,eval-conflicts-rho010-r8-036-csgwr.18d46742e15b8339,reason=Started count=1 msg=Started container task
0.1215,Event,ADDED,eval-conflicts-rho010-r8-036.18d46742c4aaf455,reason=SuccessfulCreate count=1 msg=Created pod: eval-conflicts-rho010-r8-036-csgwr
0.1217,Event,ADDED,eval-conflicts-rho010-r8-036.18d46745f57ccf2c,reason=Completed count=1 msg=Job completed
0.1219,Event,ADDED,eval-conflicts-rho010-r8-037-qc984.18d46743008d69ce,"reason=FailedScheduling count=None msg=0/6 nodes are available: 1 c_wall violated: 1 conflicting context pair(s) with node memory, 5 node(s) had untolerated taint(s). no new claims to deallocate, preemption: 0/6 nodes are available: 1 No preemption victims found for incoming pod, 5 Preemption is not helpful for scheduling."
0.1221,Event,ADDED,eval-conflicts-rho010-r8-037-qc984.18d46743010d5f4a,"reason=FailedScheduling count=None msg=0/6 nodes are available: 1 c_wall violated: 1 conflicting context pair(s) with node memory, 5 node(s) had untolerated taint(s). no new claims to deallocate, preemption: 0/6 nodes are available: 1 No preemption victims found for incoming pod, 5 Preemption is not helpful for scheduling."
0.1222,Event,ADDED,eval-conflicts-rho010-r8-037-qc984.18d467441443b055,reason=Scheduled count=None msg=Successfully assigned compute/eval-conflicts-rho010-r8-037-qc984 to kind-worker
0.1225,Event,ADDED,eval-conflicts-rho010-r8-037-qc984.18d467443fdd02f1,"reason=Pulled count=1 msg=Container image ""busybox:musl"" already present on machine"
0.1226,Event,ADDED,eval-conflicts-rho010-r8-037-qc984.18d4674441b69066,reason=Created count=1 msg=Created container: task
0.1228,Event,ADDED,eval-conflicts-rho010-r8-037-qc984.18d4674445dd654d,reason=Started count=1 msg=Started container task
0.123,Event,ADDED,eval-conflicts-rho010-r8-037.18d4674300470793,reason=SuccessfulCreate count=1 msg=Created pod: eval-conflicts-rho010-r8-037-qc984
0.1231,Event,ADDED,eval-conflicts-rho010-r8-037.18d4674785b8ea2d,reason=Completed count=1 msg=Job completed
0.1233,Event,ADDED,eval-conflicts-rho010-r8-038-shzdl.18d467433c59d733,reason=Scheduled count=None msg=Successfully assigned compute/eval-conflicts-rho010-r8-038-shzdl to kind-worker4
0.1235,Event,ADDED,eval-conflicts-rho010-r8-038-shzdl.18d4674355dc0b10,"reason=Pulled count=1 msg=Container image ""busybox:musl"" already present on machine"
0.1238,Event,ADDED,eval-conflicts-rho010-r8-038-shzdl.18d4674357061e3f,reason=Created count=1 msg=Created container: task
0.124,Event,ADDED,eval-conflicts-rho010-r8-038-shzdl.18d46743592a73c6,reason=Started count=1 msg=Started container task
0.1241,Event,ADDED,eval-conflicts-rho010-r8-038.18d467433bcefa60,reason=SuccessfulCreate count=1 msg=Created pod: eval-conflicts-rho010-r8-038-shzdl
0.1243,Event,ADDED,eval-conflicts-rho010-r8-038.18d467466d74eae8,reason=Completed count=1 msg=Job completed
0.1244,Event,ADDED,eval-conflicts-rho010-r8-039-zmhc4.18d4674378d55c37,reason=Scheduled count=None msg=Successfully assigned compute/eval-conflicts-rho010-r8-039-zmhc4 to kind-worker4
0.1246,Event,ADDED,eval-conflicts-rho010-r8-039-zmhc4.18d467439201fe78,"reason=Pulled count=1 msg=Container image ""busybox:musl"" already present on machine"
0.1248,Event,ADDED,eval-conflicts-rho010-r8-039-zmhc4.18d46743931ba266,reason=Created count=1 msg=Created container: task
0.125,Event,ADDED,eval-conflicts-rho010-r8-039-zmhc4.18d46743951388bc,reason=Started count=1 msg=Started container task
0.1251,Event,ADDED,eval-conflicts-rho010-r8-039.18d467437849dff1,reason=SuccessfulCreate count=1 msg=Created pod: eval-conflicts-rho010-r8-039-zmhc4
0.1253,Event,ADDED,eval-conflicts-rho010-r8-039.18d467466e15f46c,reason=Completed count=1 msg=Job completed
0.1254,Event,ADDED,eval-conflicts-rho010-r8-040-cjkt2.18d46743b3ac0b31,reason=Scheduled count=None msg=Successfully assigned compute/eval-conflicts-rho010-r8-040-cjkt2 to kind-worker4
0.1256,Event,ADDED,eval-conflicts-rho010-r8-040-cjkt2.18d46743cd069530,"reason=Pulled count=1 msg=Container image ""busybox:musl"" already present on machine"
0.1258,Event,ADDED,eval-conflicts-rho010-r8-040-cjkt2.18d46743ce2d2754,reason=Created count=1 msg=Created container: task
0.1259,Event,ADDED,eval-conflicts-rho010-r8-040-cjkt2.18d46743d2a9af29,reason=Started count=1 msg=Started container task
0.1262,Event,ADDED,eval-conflicts-rho010-r8-040.18d46743b32d5f40,reason=SuccessfulCreate count=1 msg=Created pod: eval-conflicts-rho010-r8-040-cjkt2
0.1263,Event,ADDED,eval-conflicts-rho010-r8-040.18d46746e6c82b8e,reason=Completed count=1 msg=Job completed
0.1265,Event,ADDED,eval-conflicts-rho010-r8-041-flcd9.18d46743efdbdeab,reason=Scheduled count=None msg=Successfully assigned compute/eval-conflicts-rho010-r8-041-flcd9 to kind-worker4
0.1267,Event,ADDED,eval-conflicts-rho010-r8-041-flcd9.18d4674408b7841d,"reason=Pulled count=1 msg=Container image ""busybox:musl"" already present on machine"
0.1268,Event,ADDED,eval-conflicts-rho010-r8-041-flcd9.18d4674409dd8376,reason=Created count=1 msg=Created container: task
0.127,Event,ADDED,eval-conflicts-rho010-r8-041-flcd9.18d467440d8f9683,reason=Started count=1 msg=Started container task
0.1272,Event,ADDED,eval-conflicts-rho010-r8-041.18d46743ef439e43,reason=SuccessfulCreate count=1 msg=Created pod: eval-conflicts-rho010-r8-041-flcd9
0.1273,Event,ADDED,eval-conflicts-rho010-r8-041.18d4674723d42c24,reason=Completed count=1 msg=Job completed
0.1276,Event,ADDED,eval-conflicts-rho010-r8-042-znm8s.18d467442b6edbec,reason=Scheduled count=None msg=Successfully assigned compute/eval-conflicts-rho010-r8-042-znm8s to kind-worker
0.1278,Event,ADDED,eval-conflicts-rho010-r8-042-znm8s.18d4674445e553fb,"reason=Pulled count=1 msg=Container image ""busybox:musl"" already present on machine"
0.128,Event,ADDED,eval-conflicts-rho010-r8-042-znm8s.18d4674447038961,reason=Created count=1 msg=Created container: task
0.1281,Event,ADDED,eval-conflicts-rho010-r8-042-znm8s.18d467444b7b39c7,reason=Started count=1 msg=Started container task
0.1283,Event,ADDED,eval-conflicts-rho010-r8-042.18d467442a31ccf8,reason=SuccessfulCreate count=1 msg=Created pod: eval-conflicts-rho010-r8-042-znm8s
0.1285,Event,ADDED,eval-conflicts-rho010-r8-042.18d4674785e8725b,reason=Completed count=1 msg=Job completed
0.1287,Event,ADDED,eval-conflicts-rho010-r8-043-t7p29.18d46744668db857,reason=Scheduled count=None msg=Successfully assigned compute/eval-conflicts-rho010-r8-043-t7p29 to kind-worker
0.1291,Event,ADDED,eval-conflicts-rho010-r8-043-t7p29.18d4674482691529,"reason=Pulled count=1 msg=Container image ""busybox:musl"" already present on machine"
0.1293,Event,ADDED,eval-conflicts-rho010-r8-043-t7p29.18d46744837b884b,reason=Created count=1 msg=Created container: task
0.1295,Event,ADDED,eval-conflicts-rho010-r8-043-t7p29.18d4674486f40001,reason=Started count=1 msg=Started container task
0.1297,Event,ADDED,eval-conflicts-rho010-r8-043.18d4674465c5e581,reason=SuccessfulCreate count=1 msg=Created pod: eval-conflicts-rho010-r8-043-t7p29
0.1299,Event,ADDED,eval-conflicts-rho010-r8-043.18d46747c1fe189f,reason=Completed count=1 msg=Job completed
0.1301,Event,ADDED,eval-conflicts-rho010-r8-044-b69x7.18d46744a3a67824,reason=Scheduled count=None msg=Successfully assigned compute/eval-conflicts-rho010-r8-044-b69x7 to kind-worker
0.1303,Event,ADDED,eval-conflicts-rho010-r8-044-b69x7.18d46744be14981a,"reason=Pulled count=1 msg=Container image ""busybox:musl"" already present on machine"
0.1304,Event,ADDED,eval-conflicts-rho010-r8-044-b69x7.18d46744bf382d5d,reason=Created count=1 msg=Created container: task
0.1306,Event,ADDED,eval-conflicts-rho010-r8-044-b69x7.18d46744c9a3013c,reason=Started count=1 msg=Started container task
0.1308,Event,ADDED,eval-conflicts-rho010-r8-044.18d46744a2d1febe,reason=SuccessfulCreate count=1 msg=Created pod: eval-conflicts-rho010-r8-044-b69x7
0.131,Event,ADDED,eval-conflicts-rho010-r8-044.18d46747fe3a6fa0,reason=Completed count=1 msg=Job completed
0.1311,Event,ADDED,eval-conflicts-rho010-r8-045-6fxvc.18d46744de558b6c,reason=Scheduled count=None msg=Successfully assigned compute/eval-conflicts-rho010-r8-045-6fxvc to kind-worker
0.1314,Event,ADDED,eval-conflicts-rho010-r8-045-6fxvc.18d46744f8afb327,"reason=Pulled count=1 msg=Container image ""busybox:musl"" already present on machine"
0.1316,Event,ADDED,eval-conflicts-rho010-r8-045-6fxvc.18d46744f9c9836e,reason=Created count=1 msg=Created container: task
0.1319,Event,ADDED,eval-conflicts-rho010-r8-045-6fxvc.18d46744fd54273e,reason=Started count=1 msg=Started container task
0.1321,Event,ADDED,eval-conflicts-rho010-r8-045.18d46744ddacfbac,reason=SuccessfulCreate count=1 msg=Created pod: eval-conflicts-rho010-r8-045-6fxvc
0.1323,Event,ADDED,eval-conflicts-rho010-r8-045.18d467483a7e4442,reason=Completed count=1 msg=Job completed
0.1325,Event,ADDED,eval-conflicts-rho010-r8-046-tlrbp.18d46745194c8aa2,reason=Scheduled count=None msg=Successfully assigned compute/eval-conflicts-rho010-r8-046-tlrbp to kind-worker
0.1329,Event,ADDED,eval-conflicts-rho010-r8-046-tlrbp.18d4674533bd20b9,"reason=Pulled count=1 msg=Container image ""busybox:musl"" already present on machine"
0.1331,Event,ADDED,eval-conflicts-rho010-r8-046-tlrbp.18d4674534e1f30e,reason=Created count=1 msg=Created container: task
0.1332,Event,ADDED,eval-conflicts-rho010-r8-046-tlrbp.18d4674537074985,reason=Started count=1 msg=Started container task
0.1336,Event,ADDED,eval-conflicts-rho010-r8-046.18d46745188ce651,reason=SuccessfulCreate count=1 msg=Created pod: eval-conflicts-rho010-r8-046-tlrbp
0.1338,Event,ADDED,eval-conflicts-rho010-r8-046.18d46748768c6035,reason=Completed count=1 msg=Job completed
0.1339,Event,ADDED,eval-conflicts-rho010-r8-047-gvfcx.18d46745560bb60a,reason=Scheduled count=None msg=Successfully assigned compute/eval-conflicts-rho010-r8-047-gvfcx to kind-worker3
0.1341,Event,ADDED,eval-conflicts-rho010-r8-047-gvfcx.18d4674570e5f31c,"reason=Pulled count=1 msg=Container image ""busybox:musl"" already present on machine"
0.1344,Event,ADDED,eval-conflicts-rho010-r8-047-gvfcx.18d46745720d2a49,reason=Created count=1 msg=Created container: task
0.1348,Event,ADDED,eval-conflicts-rho010-r8-047-gvfcx.18d467457594e4e6,reason=Started count=1 msg=Started container task
0.135,Event,ADDED,eval-conflicts-rho010-r8-047.18d46745555b6a7b,reason=SuccessfulCreate count=1 msg=Created pod: eval-conflicts-rho010-r8-047-gvfcx
0.1352,Event,ADDED,eval-conflicts-rho010-r8-047.18d4674899b0807b,reason=Completed count=1 msg=Job completed
0.1356,Event,ADDED,eval-conflicts-rho010-r8-048-8bdf8.18d46745904c56f8,"reason=FailedScheduling count=None msg=0/6 nodes are available: 2 c_wall violated: 1 conflicting context pair(s) with node memory, 4 node(s) had untolerated taint(s). no new claims to deallocate, preemption: 0/6 nodes are available: 2 No preemption victims found for incoming pod, 4 Preemption is not helpful for scheduling."
0.1358,Event,ADDED,eval-conflicts-rho010-r8-048-8bdf8.18d467459539ca9a,"reason=FailedScheduling count=None msg=0/6 nodes are available: 2 c_wall violated: 1 conflicting context pair(s) with node memory, 4 node(s) had untolerated taint(s). no new claims to deallocate, preemption: 0/6 nodes are available: 2 No preemption victims found for incoming pod, 4 Preemption is not helpful for scheduling."
0.136,Event,ADDED,eval-conflicts-rho010-r8-048-8bdf8.18d467466f3baa2a,"reason=FailedScheduling count=None msg=0/6 nodes are available: 1 c_wall violated: 1 conflicting context pair(s) with node memory, 5 node(s) had untolerated taint(s). no new claims to deallocate, preemption: 0/6 nodes are available: 1 No preemption victims found for incoming pod, 5 Preemption is not helpful for scheduling."
0.1364,Event,ADDED,eval-conflicts-rho010-r8-048-8bdf8.18d46746b3e49d0e,"reason=FailedScheduling count=None msg=0/6 nodes are available: 1 c_wall violated: 1 conflicting context pair(s) with node memory, 5 node(s) had untolerated taint(s). no new claims to deallocate, preemption: 0/6 nodes are available: 1 No preemption victims found for incoming pod, 5 Preemption is not helpful for scheduling."
0.1366,Event,ADDED,eval-conflicts-rho010-r8-048-8bdf8.18d46746b526735d,"reason=FailedScheduling count=None msg=0/6 nodes are available: 1 c_wall violated: 1 conflicting context pair(s) with node memory, 5 node(s) had untolerated taint(s). no new claims to deallocate, preemption: 0/6 nodes are available: 1 No preemption victims found for incoming pod, 5 Preemption is not helpful for scheduling."
0.1368,Event,ADDED,eval-conflicts-rho010-r8-048-8bdf8.18d4674736f523a5,reason=Scheduled count=None msg=Successfully assigned compute/eval-conflicts-rho010-r8-048-8bdf8 to kind-worker5
0.1371,Event,ADDED,eval-conflicts-rho010-r8-048-8bdf8.18d467475293b530,"reason=Pulled count=1 msg=Container image ""busybox:musl"" already present on machine"
0.1373,Event,ADDED,eval-conflicts-rho010-r8-048-8bdf8.18d467475471b7d8,reason=Created count=1 msg=Created container: task
0.1375,Event,ADDED,eval-conflicts-rho010-r8-048-8bdf8.18d467475852d8dc,reason=Started count=1 msg=Started container task
0.1379,Event,ADDED,eval-conflicts-rho010-r8-048.18d467458fb51c6c,reason=SuccessfulCreate count=1 msg=Created pod: eval-conflicts-rho010-r8-048-8bdf8
0.1381,Event,ADDED,eval-conflicts-rho010-r8-048.18d4674a9851a24d,reason=Completed count=1 msg=Job completed
0.1382,Event,ADDED,eval-conflicts-rho010-r8-049-cj5dq.18d46745cc75450a,reason=Scheduled count=None msg=Successfully assigned compute/eval-conflicts-rho010-r8-049-cj5dq to kind-worker3
0.1384,Event,ADDED,eval-conflicts-rho010-r8-049-cj5dq.18d46745e590da62,"reason=Pulled count=1 msg=Container image ""busybox:musl"" already present on machine"
0.1387,Event,ADDED,eval-conflicts-rho010-r8-049-cj5dq.18d46745e6b0dc4d,reason=Created count=1 msg=Created container: task
0.1389,Event,ADDED,eval-conflicts-rho010-r8-049-cj5dq.18d46745ea532c87,reason=Started count=1 msg=Started container task
0.1391,Event,ADDED,eval-conflicts-rho010-r8-049.18d46745cb82e2d8,reason=SuccessfulCreate count=1 msg=Created pod: eval-conflicts-rho010-r8-049-cj5dq
0.1393,Event,ADDED,eval-conflicts-rho010-r8-049.18d4674911a26f46,reason=Completed count=1 msg=Job completed
0.1396,Event,ADDED,eval-conflicts-rho010-r8-050-hrwc9.18d4674607f5a740,reason=Scheduled count=None msg=Successfully assigned compute/eval-conflicts-rho010-r8-050-hrwc9 to kind-worker
0.1398,Event,ADDED,eval-conflicts-rho010-r8-050-hrwc9.18d4674620f4f642,"reason=Pulled count=1 msg=Container image ""busybox:musl"" already present on machine"
0.14,Event,ADDED,eval-conflicts-rho010-r8-050-hrwc9.18d46746220d29a0,reason=Created count=1 msg=Created container: task
0.1405,Event,ADDED,eval-conflicts-rho010-r8-050-hrwc9.18d4674626080b96,reason=Started count=1 msg=Started container task
0.1406,Event,ADDED,eval-conflicts-rho010-r8-050.18d4674606d83d33,reason=SuccessfulCreate count=1 msg=Created pod: eval-conflicts-rho010-r8-050-hrwc9
0.1408,Event,ADDED,eval-conflicts-rho010-r8-050.18d4674964722b29,reason=Completed count=1 msg=Job completed
0.141,Event,ADDED,eval-conflicts-rho010-r8-051-rg487.18d467464404be23,"reason=FailedScheduling count=None msg=0/6 nodes are available: 2 c_wall violated: 1 conflicting context pair(s) with node memory, 4 node(s) had untolerated taint(s). no new claims to deallocate, preemption: 0/6 nodes are available: 2 No preemption victims found for incoming pod, 4 Preemption is not helpful for scheduling."
0.1413,Event,ADDED,eval-conflicts-rho010-r8-051-rg487.18d4674644c0d065,"reason=FailedScheduling count=None msg=0/6 nodes are available: 2 c_wall violated: 1 conflicting context pair(s) with node memory, 4 node(s) had untolerated taint(s). no new claims to deallocate, preemption: 0/6 nodes are available: 2 No preemption victims found for incoming pod, 4 Preemption is not helpful for scheduling."
0.1416,Event,ADDED,eval-conflicts-rho010-r8-051-rg487.18d467466f0fdb97,"reason=FailedScheduling count=None msg=0/6 nodes are available: 1 c_wall violated: 1 conflicting context pair(s) with node memory, 5 node(s) had untolerated taint(s). no new claims to deallocate, preemption: 0/6 nodes are available: 1 No preemption victims found for incoming pod, 5 Preemption is not helpful for scheduling."
0.1417,Event,ADDED,eval-conflicts-rho010-r8-051-rg487.18d46746b3e5b6d0,reason=Scheduled count=None msg=Successfully assigned compute/eval-conflicts-rho010-r8-051-rg487 to kind-worker2
0.142,Event,ADDED,eval-conflicts-rho010-r8-051-rg487.18d46746ceec730f,"reason=Pulled count=1 msg=Container image ""busybox:musl"" already present on machine"
0.1422,Event,ADDED,eval-conflicts-rho010-r8-051-rg487.18d46746d03cba2a,reason=Created count=1 msg=Created container: task
0.1424,Event,ADDED,eval-conflicts-rho010-r8-051-rg487.18d46746d4b7ff20,reason=Started count=1 msg=Started container task
0.1427,Event,ADDED,eval-conflicts-rho010-r8-051.18d46746439729b5,reason=SuccessfulCreate count=1 msg=Created pod: eval-conflicts-rho010-r8-051-rg487
0.1429,Event,ADDED,eval-conflicts-rho010-r8-051.18d4674a162aa8df,reason=Completed count=1 msg=Job completed
0.1431,Event,ADDED,eval-conflicts-rho010-r8-052-wnt7j.18d467467f23c335,"reason=FailedScheduling count=None msg=0/6 nodes are available: 1 c_wall violated: 1 conflicting context pair(s) with node memory, 5 node(s) had untolerated taint(s). no new claims to deallocate, preemption: 0/6 nodes are available: 1 No preemption victims found for incoming pod, 5 Preemption is not helpful for scheduling."
0.1434,Event,ADDED,eval-conflicts-rho010-r8-052-wnt7j.18d467467fdfb2be,"reason=FailedScheduling count=None msg=0/6 nodes are available: 1 c_wall violated: 1 conflicting context pair(s) with node memory, 5 node(s) had untolerated taint(s). no new claims to deallocate, preemption: 0/6 nodes are available: 1 No preemption victims found for incoming pod, 5 Preemption is not helpful for scheduling."
0.1436,Event,ADDED,eval-conflicts-rho010-r8-052-wnt7j.18d46746b4a3f1a9,"reason=FailedScheduling count=None msg=0/6 nodes are available: 1 c_wall violated: 1 conflicting context pair(s) with node memory, 5 node(s) had untolerated taint(s). no new claims to deallocate, preemption: 0/6 nodes are available: 1 No preemption victims found for incoming pod, 5 Preemption is not helpful for scheduling."
0.1437,Event,ADDED,eval-conflicts-rho010-r8-052-wnt7j.18d46746b550a883,"reason=FailedScheduling count=None msg=0/6 nodes are available: 1 c_wall violated: 1 conflicting context pair(s) with node memory, 5 node(s) had untolerated taint(s). no new claims to deallocate, preemption: 0/6 nodes are available: 1 No preemption victims found for incoming pod, 5 Preemption is not helpful for scheduling."
0.1439,Event,ADDED,eval-conflicts-rho010-r8-052-wnt7j.18d4674737c8e262,reason=Scheduled count=None msg=Successfully assigned compute/eval-conflicts-rho010-r8-052-wnt7j to kind-worker5
0.1442,Event,ADDED,eval-conflicts-rho010-r8-052-wnt7j.18d4674752d469c4,"reason=Pulled count=1 msg=Container image ""busybox:musl"" already present on machine"
0.1444,Event,ADDED,eval-conflicts-rho010-r8-052-wnt7j.18d4674754d51bed,reason=Created count=1 msg=Created container: task
0.1446,Event,ADDED,eval-conflicts-rho010-r8-052-wnt7j.18d467475852d8cd,reason=Started count=1 msg=Started container task
0.1449,Event,ADDED,eval-conflicts-rho010-r8-052.18d467467ee67ec5,reason=SuccessfulCreate count=1 msg=Created pod: eval-conflicts-rho010-r8-052-wnt7j
0.1451,Event,ADDED,eval-conflicts-rho010-r8-052.18d4674a97b3d4f5,reason=Completed count=1 msg=Job completed
0.1455,Event,ADDED,eval-conflicts-rho010-r8-053-vjz8b.18d46746bc32b20e,reason=Scheduled count=None msg=Successfully assigned compute/eval-conflicts-rho010-r8-053-vjz8b to kind-worker2
0.1458,Event,ADDED,eval-conflicts-rho010-r8-053-vjz8b.18d46746d4c402ba,"reason=Pulled count=1 msg=Container image ""busybox:musl"" already present on machine"
0.1462,Event,ADDED,eval-conflicts-rho010-r8-053-vjz8b.18d46746d5f79d37,reason=Created count=1 msg=Created container: task
0.1464,Event,ADDED,eval-conflicts-rho010-r8-053-vjz8b.18d46746daa35e9e,reason=Started count=1 msg=Started container task
0.1466,Event,ADDED,eval-conflicts-rho010-r8-053.18d46746bb98d449,reason=SuccessfulCreate count=1 msg=Created pod: eval-conflicts-rho010-r8-053-vjz8b
0.1469,Event,ADDED,eval-conflicts-rho010-r8-053.18d4674a1609776e,reason=Completed count=1 msg=Job completed
0.1471,Event,ADDED,eval-conflicts-rho010-r8-054-sx9lz.18d46746f681d384,reason=Scheduled count=None msg=Successfully assigned compute/eval-conflicts-rho010-r8-054-sx9lz to kind-worker2
0.1473,Event,ADDED,eval-conflicts-rho010-r8-054-sx9lz.18d467471053ff61,"reason=Pulled count=1 msg=Container image ""busybox:musl"" already present on machine"
0.1474,Event,ADDED,eval-conflicts-rho010-r8-054-sx9lz.18d46747118d5b49,reason=Created count=1 msg=Created container: task
0.1478,Event,ADDED,eval-conflicts-rho010-r8-054-sx9lz.18d4674713a71409,reason=Started count=1 msg=Started container task
0.148,Event,ADDED,eval-conflicts-rho010-r8-054.18d46746f5f35ed9,reason=SuccessfulCreate count=1 msg=Created pod: eval-conflicts-rho010-r8-054-sx9lz
0.1482,Event,ADDED,eval-conflicts-rho010-r8-054.18d4674a51fe3261,reason=Completed count=1 msg=Job completed
0.1484,Event,ADDED,eval-conflicts-rho010-r8-055-lzkf8.18d467473203d8ad,reason=Scheduled count=None msg=Successfully assigned compute/eval-conflicts-rho010-r8-055-lzkf8 to kind-worker2
0.1488,Event,ADDED,eval-conflicts-rho010-r8-055-lzkf8.18d467475190e250,"reason=Pulled count=1 msg=Container image ""busybox:musl"" already present on machine"
0.1489,Event,ADDED,eval-conflicts-rho010-r8-055-lzkf8.18d4674753730d2d,reason=Created count=1 msg=Created container: task
0.1491,Event,ADDED,eval-conflicts-rho010-r8-055-lzkf8.18d4674757b6edc9,reason=Started count=1 msg=Started container task
0.1493,Event,ADDED,eval-conflicts-rho010-r8-055.18d46747319b5370,reason=SuccessfulCreate count=1 msg=Created pod: eval-conflicts-rho010-r8-055-lzkf8
0.1495,Event,ADDED,eval-conflicts-rho010-r8-055.18d4674a8de2eaf9,reason=Completed count=1 msg=Job completed
0.1497,Event,ADDED,eval-conflicts-rho010-r8-056-m94xb.18d467476dcbbccf,reason=Scheduled count=None msg=Successfully assigned compute/eval-conflicts-rho010-r8-056-m94xb to kind-worker5
0.1498,Event,ADDED,eval-conflicts-rho010-r8-056-m94xb.18d467478bd785c1,"reason=Pulled count=1 msg=Container image ""busybox:musl"" already present on machine"
0.1502,Event,ADDED,eval-conflicts-rho010-r8-056-m94xb.18d467478d75d038,reason=Created count=1 msg=Created container: task
0.1504,Event,ADDED,eval-conflicts-rho010-r8-056-m94xb.18d4674792340c4a,reason=Started count=1 msg=Started container task
0.1506,Event,ADDED,eval-conflicts-rho010-r8-056.18d467476d0ff623,reason=SuccessfulCreate count=1 msg=Created pod: eval-conflicts-rho010-r8-056-m94xb
0.1507,Event,ADDED,eval-conflicts-rho010-r8-056.18d4674ad331570e,reason=Completed count=1 msg=Job completed
0.151,Event,ADDED,eval-conflicts-rho010-r8-057-lcx8h.18d46747a90b118f,reason=Scheduled count=None msg=Successfully assigned compute/eval-conflicts-rho010-r8-057-lcx8h to kind-worker2
0.1512,Event,ADDED,eval-conflicts-rho010-r8-057-lcx8h.18d46747c300f510,"reason=Pulled count=1 msg=Container image ""busybox:musl"" already present on machine"
0.1514,Event,ADDED,eval-conflicts-rho010-r8-057-lcx8h.18d46747c44cc3cf,reason=Created count=1 msg=Created container: task
0.1517,Event,ADDED,eval-conflicts-rho010-r8-057-lcx8h.18d46747c8d6e46d,reason=Started count=1 msg=Started container task
0.1519,Event,ADDED,eval-conflicts-rho010-r8-057.18d46747a840f4a7,reason=SuccessfulCreate count=1 msg=Created pod: eval-conflicts-rho010-r8-057-lcx8h
0.1523,Event,ADDED,eval-conflicts-rho010-r8-057.18d4674b0576e98a,reason=Completed count=1 msg=Job completed
0.1525,Event,ADDED,eval-conflicts-rho010-r8-058-bz24l.18d46747e4cb3a94,reason=Scheduled count=None msg=Successfully assigned compute/eval-conflicts-rho010-r8-058-bz24l to kind-worker5
0.1528,Event,ADDED,eval-conflicts-rho010-r8-058-bz24l.18d46747fe789078,"reason=Pulled count=1 msg=Container image ""busybox:musl"" already present on machine"
0.153,Event,ADDED,eval-conflicts-rho010-r8-058-bz24l.18d46747ffb8b748,reason=Created count=1 msg=Created container: task
0.1532,Event,ADDED,eval-conflicts-rho010-r8-058-bz24l.18d4674801ddbda8,reason=Started count=1 msg=Started container task
0.1535,Event,ADDED,eval-conflicts-rho010-r8-058.18d46747e3e0fd2e,reason=SuccessfulCreate count=1 msg=Created pod: eval-conflicts-rho010-r8-058-bz24l
0.1537,Event,ADDED,eval-conflicts-rho010-r8-058.18d4674b0f4503db,reason=Completed count=1 msg=Job completed
0.1538,Event,ADDED,eval-conflicts-rho010-r8-059-pr267.18d4674821077ea9,reason=Scheduled count=None msg=Successfully assigned compute/eval-conflicts-rho010-r8-059-pr267 to kind-worker5
0.154,Event,ADDED,eval-conflicts-rho010-r8-059-pr267.18d467483f3fc311,"reason=Pulled count=1 msg=Container image ""busybox:musl"" already present on machine"
0.1543,Event,ADDED,eval-conflicts-rho010-r8-059-pr267.18d467484048a295,reason=Created count=1 msg=Created container: task
0.1545,Event,ADDED,eval-conflicts-rho010-r8-059-pr267.18d4674845223c41,reason=Started count=1 msg=Started container task
0.1547,Event,ADDED,eval-conflicts-rho010-r8-059.18d467481fdd6e0e,reason=SuccessfulCreate count=1 msg=Created pod: eval-conflicts-rho010-r8-059-pr267
0.1549,Event,ADDED,eval-conflicts-rho010-r8-059.18d4674b87544eac,reason=Completed count=1 msg=Job completed
0.1552,Event,ADDED,eval-conflicts-rho010-r8-060-4hkww.18d467485c9543e5,reason=Scheduled count=None msg=Successfully assigned compute/eval-conflicts-rho010-r8-060-4hkww to kind-worker5
0.1554,Event,ADDED,eval-conflicts-rho010-r8-060-4hkww.18d4674876352465,"reason=Pulled count=1 msg=Container image ""busybox:musl"" already present on machine"
0.1556,Event,ADDED,eval-conflicts-rho010-r8-060-4hkww.18d46748776933b1,reason=Created count=1 msg=Created container: task
0.1559,Event,ADDED,eval-conflicts-rho010-r8-060-4hkww.18d46748796e3169,reason=Started count=1 msg=Started container task
0.1561,Event,ADDED,eval-conflicts-rho010-r8-060.18d467485bd405fa,reason=SuccessfulCreate count=1 msg=Created pod: eval-conflicts-rho010-r8-060-4hkww
0.1563,Event,ADDED,eval-conflicts-rho010-r8-060.18d4674b87c44b6f,reason=Completed count=1 msg=Job completed
0.1564,Event,ADDED,eval-conflicts-rho010-r8-061-sms94.18d4674897e18a68,reason=Scheduled count=None msg=Successfully assigned compute/eval-conflicts-rho010-r8-061-sms94 to kind-worker5
0.1567,Event,ADDED,eval-conflicts-rho010-r8-061-sms94.18d46748b0dc4b8a,"reason=Pulled count=1 msg=Container image ""busybox:musl"" already present on machine"
0.1569,Event,ADDED,eval-conflicts-rho010-r8-061-sms94.18d46748b1f367bd,reason=Created count=1 msg=Created container: task
0.1571,Event,ADDED,eval-conflicts-rho010-r8-061-sms94.18d46748b3f09388,reason=Started count=1 msg=Started container task
0.1574,Event,ADDED,eval-conflicts-rho010-r8-061.18d4674896f71900,reason=SuccessfulCreate count=1 msg=Created pod: eval-conflicts-rho010-r8-061-sms94
0.1576,Event,ADDED,eval-conflicts-rho010-r8-061.18d4674bc2fa799c,reason=Completed count=1 msg=Job completed
0.1578,Event,ADDED,eval-conflicts-rho010-r8-062-s6hlf.18d46748d358fb2e,reason=Scheduled count=None msg=Successfully assigned compute/eval-conflicts-rho010-r8-062-s6hlf to kind-worker2
0.158,Event,ADDED,eval-conflicts-rho010-r8-062-s6hlf.18d46748ecb1cae3,"reason=Pulled count=1 msg=Container image ""busybox:musl"" already present on machine"
0.1583,Event,ADDED,eval-conflicts-rho010-r8-062-s6hlf.18d46748edf6839f,reason=Created count=1 msg=Created container: task
0.1585,Event,ADDED,eval-conflicts-rho010-r8-062-s6hlf.18d46748f2d0991e,reason=Started count=1 msg=Started container task
0.1587,Event,ADDED,eval-conflicts-rho010-r8-062.18d46748d24e7676,reason=SuccessfulCreate count=1 msg=Created pod: eval-conflicts-rho010-r8-062-s6hlf
0.1589,Event,ADDED,eval-conflicts-rho010-r8-062.18d4674c300fcbc5,reason=Completed count=1 msg=Job completed
0.1591,Event,ADDED,eval-conflicts-rho010-r8-063-z8k9l.18d467490ec7ed83,reason=Scheduled count=None msg=Successfully assigned compute/eval-conflicts-rho010-r8-063-z8k9l to kind-worker4
0.1593,Event,ADDED,eval-conflicts-rho010-r8-063-z8k9l.18d467492714db23,"reason=Pulled count=1 msg=Container image ""busybox:musl"" already present on machine"
0.1595,Event,ADDED,eval-conflicts-rho010-r8-063-z8k9l.18d4674928651386,reason=Created count=1 msg=Created container: task
0.16,Event,ADDED,eval-conflicts-rho010-r8-063-z8k9l.18d467492d27e565,reason=Started count=1 msg=Started container task
0.1602,Event,ADDED,eval-conflicts-rho010-r8-063.18d467490e037633,reason=SuccessfulCreate count=1 msg=Created pod: eval-conflicts-rho010-r8-063-z8k9l
0.1604,Event,ADDED,eval-conflicts-rho010-r8-063.18d4674c4235a4a0,reason=Completed count=1 msg=Job completed
0.1606,Event,ADDED,eval-conflicts-rho010-r8-064-vhjvj.18d467494a70b1cf,reason=Scheduled count=None msg=Successfully assigned compute/eval-conflicts-rho010-r8-064-vhjvj to kind-worker4
0.1609,Event,ADDED,eval-conflicts-rho010-r8-064-vhjvj.18d46749639b306c,"reason=Pulled count=1 msg=Container image ""busybox:musl"" already present on machine"
0.1611,Event,ADDED,eval-conflicts-rho010-r8-064-vhjvj.18d4674964d37de9,reason=Created count=1 msg=Created container: task
0.1613,Event,ADDED,eval-conflicts-rho010-r8-064-vhjvj.18d467496854a48d,reason=Started count=1 msg=Started container task
0.1615,Event,ADDED,eval-conflicts-rho010-r8-064.18d46749496dd5f4,reason=SuccessfulCreate count=1 msg=Created pod: eval-conflicts-rho010-r8-064-vhjvj
0.1619,Event,ADDED,eval-conflicts-rho010-r8-064.18d4674c7e1ce04f,reason=Completed count=1 msg=Job completed
0.162,Event,ADDED,eval-conflicts-rho010-r8-065-kfjbd.18d4674985d9270c,reason=Scheduled count=None msg=Successfully assigned compute/eval-conflicts-rho010-r8-065-kfjbd to kind-worker4
0.1622,Event,ADDED,eval-conflicts-rho010-r8-065-kfjbd.18d467499f8f9e85,"reason=Pulled count=1 msg=Container image ""busybox:musl"" already present on machine"
0.1624,Event,ADDED,eval-conflicts-rho010-r8-065-kfjbd.18d46749a0a5ba09,reason=Created count=1 msg=Created container: task
0.1626,Event,ADDED,eval-conflicts-rho010-r8-065-kfjbd.18d46749a4db1aae,reason=Started count=1 msg=Started container task
0.1628,Event,ADDED,eval-conflicts-rho010-r8-065.18d4674984fba6e6,reason=SuccessfulCreate count=1 msg=Created pod: eval-conflicts-rho010-r8-065-kfjbd
0.1629,Event,ADDED,eval-conflicts-rho010-r8-065.18d4674cb99a9940,reason=Completed count=1 msg=Job completed
0.1631,Event,ADDED,eval-conflicts-rho010-r8-066-qdmfx.18d46749c1a89a51,reason=Scheduled count=None msg=Successfully assigned compute/eval-conflicts-rho010-r8-066-qdmfx to kind-worker3
0.1633,Event,ADDED,eval-conflicts-rho010-r8-066-qdmfx.18d46749d97c519e,"reason=Pulled count=1 msg=Container image ""busybox:musl"" already present on machine"
0.1635,Event,ADDED,eval-conflicts-rho010-r8-066-qdmfx.18d46749dafdaf43,reason=Created count=1 msg=Created container: task
0.1638,Event,ADDED,eval-conflicts-rho010-r8-066-qdmfx.18d46749deb94ac6,reason=Started count=1 msg=Started container task
0.164,Event,ADDED,eval-conflicts-rho010-r8-066.18d46749c0fa72c8,reason=SuccessfulCreate count=1 msg=Created pod: eval-conflicts-rho010-r8-066-qdmfx
0.1642,Event,ADDED,eval-conflicts-rho010-r8-066.18d4674d08d32efe,reason=Completed count=1 msg=Job completed
0.1644,Event,ADDED,eval-conflicts-rho010-r8-067-rkjc2.18d46749fe4ad7a1,reason=Scheduled count=None msg=Successfully assigned compute/eval-conflicts-rho010-r8-067-rkjc2 to kind-worker4
0.1647,Event,ADDED,eval-conflicts-rho010-r8-067-rkjc2.18d4674a1be9305c,"reason=Pulled count=1 msg=Container image ""busybox:musl"" already present on machine"
0.1649,Event,ADDED,eval-conflicts-rho010-r8-067-rkjc2.18d4674a1cff785c,reason=Created count=1 msg=Created container: task
0.1651,Event,ADDED,eval-conflicts-rho010-r8-067-rkjc2.18d4674a280fa20d,reason=Started count=1 msg=Started container task
0.1652,Event,ADDED,eval-conflicts-rho010-r8-067.18d46749fd680708,reason=SuccessfulCreate count=1 msg=Created pod: eval-conflicts-rho010-r8-067-rkjc2
0.1655,Event,ADDED,eval-conflicts-rho010-r8-067.18d4674d6d43c7b8,reason=Completed count=1 msg=Job completed
0.1656,Event,ADDED,eval-conflicts-rho010-r8-068-nxhxm.18d4674a38af973e,reason=Scheduled count=None msg=Successfully assigned compute/eval-conflicts-rho010-r8-068-nxhxm to kind-worker3
0.1658,Event,ADDED,eval-conflicts-rho010-r8-068-nxhxm.18d4674a5272ed90,"reason=Pulled count=1 msg=Container image ""busybox:musl"" already present on machine"
0.1662,Event,ADDED,eval-conflicts-rho010-r8-068-nxhxm.18d4674a53a2cebd,reason=Created count=1 msg=Created container: task
0.1664,Event,ADDED,eval-conflicts-rho010-r8-068-nxhxm.18d4674a558f1c3d,reason=Started count=1 msg=Started container task
0.1665,Event,ADDED,eval-conflicts-rho010-r8-068.18d4674a37db11c4,reason=SuccessfulCreate count=1 msg=Created pod: eval-conflicts-rho010-r8-068-nxhxm
0.1667,Event,ADDED,eval-conflicts-rho010-r8-068.18d4674d8083567d,reason=Completed count=1 msg=Job completed
0.167,Event,ADDED,eval-conflicts-rho010-r8-069-h7dfs.18d4674a7444b5cf,reason=Scheduled count=None msg=Successfully assigned compute/eval-conflicts-rho010-r8-069-h7dfs to kind-worker3
0.1672,Event,ADDED,eval-conflicts-rho010-r8-069-h7dfs.18d4674a8dae1e40,"reason=Pulled count=1 msg=Container image ""busybox:musl"" already present on machine"
0.1674,Event,ADDED,eval-conflicts-rho010-r8-069-h7dfs.18d4674a8f18fd86,reason=Created count=1 msg=Created container: task
0.1675,Event,ADDED,eval-conflicts-rho010-r8-069-h7dfs.18d4674a928327d3,reason=Started count=1 msg=Started container task
0.1678,Event,ADDED,eval-conflicts-rho010-r8-069.18d4674a739f6140,reason=SuccessfulCreate count=1 msg=Created pod: eval-conflicts-rho010-r8-069-h7dfs
0.168,Event,ADDED,eval-conflicts-rho010-r8-069.18d4674dbc684a4b,reason=Completed count=1 msg=Job completed
0.1683,Event,ADDED,eval-conflicts-rho010-r8-070-qhrg9.18d4674ab00fab96,reason=Scheduled count=None msg=Successfully assigned compute/eval-conflicts-rho010-r8-070-qhrg9 to kind-worker4
0.1687,Event,ADDED,eval-conflicts-rho010-r8-070-qhrg9.18d4674ac978b92a,"reason=Pulled count=1 msg=Container image ""busybox:musl"" already present on machine"
0.1689,Event,ADDED,eval-conflicts-rho010-r8-070-qhrg9.18d4674acab153b0,reason=Created count=1 msg=Created container: task
0.169,Event,ADDED,eval-conflicts-rho010-r8-070-qhrg9.18d4674acea25d02,reason=Started count=1 msg=Started container task
0.1692,Event,ADDED,eval-conflicts-rho010-r8-070.18d4674aaf179d83,reason=SuccessfulCreate count=1 msg=Created pod: eval-conflicts-rho010-r8-070-qhrg9
0.1695,Event,ADDED,eval-conflicts-rho010-r8-070.18d4674de4b59f08,reason=Completed count=1 msg=Job completed
0.1697,Event,ADDED,eval-conflicts-rho010-r8-071-vvqbd.18d4674aebb243a9,reason=Scheduled count=None msg=Successfully assigned compute/eval-conflicts-rho010-r8-071-vvqbd to kind-worker3
0.1698,Event,ADDED,eval-conflicts-rho010-r8-071-vvqbd.18d4674b0592efa3,"reason=Pulled count=1 msg=Container image ""busybox:musl"" already present on machine"
0.1702,Event,ADDED,eval-conflicts-rho010-r8-071-vvqbd.18d4674b075286c7,reason=Created count=1 msg=Created container: task
0.1704,Event,ADDED,eval-conflicts-rho010-r8-071-vvqbd.18d4674b0ae0c3b2,reason=Started count=1 msg=Started container task
0.1705,Event,ADDED,eval-conflicts-rho010-r8-071.18d4674aead82cd5,reason=SuccessfulCreate count=1 msg=Created pod: eval-conflicts-rho010-r8-071-vvqbd
0.1707,Event,ADDED,eval-conflicts-rho010-r8-071.18d4674e3436146c,reason=Completed count=1 msg=Job completed
0.171,Event,ADDED,eval-conflicts-rho010-r8-072-7lf8l.18d4674b27a0c788,"reason=FailedScheduling count=None msg=0/6 nodes are available: 2 c_wall violated: 1 conflicting context pair(s) with node memory, 4 node(s) had untolerated taint(s). no new claims to deallocate, preemption: 0/6 nodes are available: 2 No preemption victims found for incoming pod, 4 Preemption is not helpful for scheduling."
0.1712,Event,ADDED,eval-conflicts-rho010-r8-072-7lf8l.18d4674b28424107,"reason=FailedScheduling count=None msg=0/6 nodes are available: 2 c_wall violated: 1 conflicting context pair(s) with node memory, 4 node(s) had untolerated taint(s). no new claims to deallocate, preemption: 0/6 nodes are available: 2 No preemption victims found for incoming pod, 4 Preemption is not helpful for scheduling."
0.1714,Event,ADDED,eval-conflicts-rho010-r8-072-7lf8l.18d4674b32063c75,reason=Scheduled count=None msg=Successfully assigned compute/eval-conflicts-rho010-r8-072-7lf8l to kind-worker
0.1716,Event,ADDED,eval-conflicts-rho010-r8-072-7lf8l.18d4674b50e213c6,"reason=Pulled count=1 msg=Container image ""busybox:musl"" already present on machine"
0.1718,Event,ADDED,eval-conflicts-rho010-r8-072-7lf8l.18d4674b51f9e2f4,reason=Created count=1 msg=Created container: task
0.1719,Event,ADDED,eval-conflicts-rho010-r8-072-7lf8l.18d4674b56f4f3c3,reason=Started count=1 msg=Started container task
0.1721,Event,ADDED,eval-conflicts-rho010-r8-072.18d4674b273bb945,reason=SuccessfulCreate count=1 msg=Created pod: eval-conflicts-rho010-r8-072-7lf8l
0.1723,Event,ADDED,eval-conflicts-rho010-r8-072.18d4674e8738de13,reason=Completed count=1 msg=Job completed
0.1724,Event,ADDED,eval-conflicts-rho010-r8-073-85hbb.18d4674b61f3ebbb,"reason=FailedScheduling count=None msg=0/6 nodes are available: 1 c_wall violated: 1 conflicting context pair(s) with node memory, 5 node(s) had untolerated taint(s). no new claims to deallocate, preemption: 0/6 nodes are available: 1 No preemption victims found for incoming pod, 5 Preemption is not helpful for scheduling."
0.1726,Event,ADDED,eval-conflicts-rho010-r8-073-85hbb.18d4674b6276a264,"reason=FailedScheduling count=None msg=0/6 nodes are available: 1 c_wall violated: 1 conflicting context pair(s) with node memory, 5 node(s) had untolerated taint(s). no new claims to deallocate, preemption: 0/6 nodes are available: 1 No preemption victims found for incoming pod, 5 Preemption is not helpful for scheduling."
0.1728,Event,ADDED,eval-conflicts-rho010-r8-073-85hbb.18d4674bf1c5d574,reason=Scheduled count=None msg=Successfully assigned compute/eval-conflicts-rho010-r8-073-85hbb to kind-worker5
0.173,Event,ADDED,eval-conflicts-rho010-r8-073-85hbb.18d4674c0c446364,"reason=Pulled count=1 msg=Container image ""busybox:musl"" already present on machine"
0.1731,Event,ADDED,eval-conflicts-rho010-r8-073-85hbb.18d4674c0de15fd7,reason=Created count=1 msg=Created container: task
0.1733,Event,ADDED,eval-conflicts-rho010-r8-073-85hbb.18d4674c11f6e709,reason=Started count=1 msg=Started container task
0.1735,Event,ADDED,eval-conflicts-rho010-r8-073.18d4674b61b4ec8b,reason=SuccessfulCreate count=1 msg=Created pod: eval-conflicts-rho010-r8-073-85hbb
0.1736,Event,ADDED,eval-conflicts-rho010-r8-073.18d4674f445d236c,reason=Completed count=1 msg=Job completed
0.1738,Event,ADDED,eval-conflicts-rho010-r8-074-nt54n.18d4674b9dfa245d,reason=Scheduled count=None msg=Successfully assigned compute/eval-conflicts-rho010-r8-074-nt54n to kind-worker
0.174,Event,ADDED,eval-conflicts-rho010-r8-074-nt54n.18d4674bb7a763b4,"reason=Pulled count=1 msg=Container image ""busybox:musl"" already present on machine"
0.1741,Event,ADDED,eval-conflicts-rho010-r8-074-nt54n.18d4674bb8f1091e,reason=Created count=1 msg=Created container: task
0.1743,Event,ADDED,eval-conflicts-rho010-r8-074-nt54n.18d4674bc3657562,reason=Started count=1 msg=Started container task
0.1745,Event,ADDED,eval-conflicts-rho010-r8-074.18d4674b9d6a8337,reason=SuccessfulCreate count=1 msg=Created pod: eval-conflicts-rho010-r8-074-nt54n
0.1746,Event,ADDED,eval-conflicts-rho010-r8-074.18d4674eff6d65f9,reason=Completed count=1 msg=Job completed
0.1748,Event,ADDED,eval-conflicts-rho010-r8-075-fc8w2.18d4674bd9576cd1,"reason=FailedScheduling count=None msg=0/6 nodes are available: 1 c_wall violated: 1 conflicting context pair(s) with node memory, 5 node(s) had untolerated taint(s). no new claims to deallocate, preemption: 0/6 nodes are available: 1 No preemption victims found for incoming pod, 5 Preemption is not helpful for scheduling."
0.175,Event,ADDED,eval-conflicts-rho010-r8-075-fc8w2.18d4674bd9ce0d4f,"reason=FailedScheduling count=None msg=0/6 nodes are available: 1 c_wall violated: 1 conflicting context pair(s) with node memory, 5 node(s) had untolerated taint(s). no new claims to deallocate, preemption: 0/6 nodes are available: 1 No preemption victims found for incoming pod, 5 Preemption is not helpful for scheduling."
0.1752,Event,ADDED,eval-conflicts-rho010-r8-075-fc8w2.18d4674bf1f81635,reason=Scheduled count=None msg=Successfully assigned compute/eval-conflicts-rho010-r8-075-fc8w2 to kind-worker5
0.1753,Event,ADDED,eval-conflicts-rho010-r8-075-fc8w2.18d4674c0c59363a,"reason=Pulled count=1 msg=Container image ""busybox:musl"" already present on machine"
0.1756,Event,ADDED,eval-conflicts-rho010-r8-075-fc8w2.18d4674c0dc5fa76,reason=Created count=1 msg=Created container: task
0.1758,Event,ADDED,eval-conflicts-rho010-r8-075-fc8w2.18d4674c11f6f253,reason=Started count=1 msg=Started container task
0.1761,Event,ADDED,eval-conflicts-rho010-r8-075.18d4674bd918e651,reason=SuccessfulCreate count=1 msg=Created pod: eval-conflicts-rho010-r8-075-fc8w2
0.1762,Event,ADDED,eval-conflicts-rho010-r8-075.18d4674f43a7e8f5,reason=Completed count=1 msg=Job completed
0.1764,Event,ADDED,eval-conflicts-rho010-r8-076-zsp5c.18d4674c16aac458,reason=Scheduled count=None msg=Successfully assigned compute/eval-conflicts-rho010-r8-076-zsp5c to kind-worker5
0.1767,Event,ADDED,eval-conflicts-rho010-r8-076-zsp5c.18d4674c30311503,"reason=Pulled count=1 msg=Container image ""busybox:musl"" already present on machine"
0.1769,Event,ADDED,eval-conflicts-rho010-r8-076-zsp5c.18d4674c3160e13e,reason=Created count=1 msg=Created container: task
0.1771,Event,ADDED,eval-conflicts-rho010-r8-076-zsp5c.18d4674c35a156a5,reason=Started count=1 msg=Started container task
0.1773,Event,ADDED,eval-conflicts-rho010-r8-076.18d4674c1570ba4d,reason=SuccessfulCreate count=1 msg=Created pod: eval-conflicts-rho010-r8-076-zsp5c
0.1776,Event,ADDED,eval-conflicts-rho010-r8-076.18d4674f43d2ab20,reason=Completed count=1 msg=Job completed
0.1777,Event,ADDED,eval-conflicts-rho010-r8-077-gjsfx.18d4674c5176414b,reason=Scheduled count=None msg=Successfully assigned compute/eval-conflicts-rho010-r8-077-gjsfx to kind-worker5
0.1779,Event,ADDED,eval-conflicts-rho010-r8-077-gjsfx.18d4674c6ae0c353,"reason=Pulled count=1 msg=Container image ""busybox:musl"" already present on machine"
0.1781,Event,ADDED,eval-conflicts-rho010-r8-077-gjsfx.18d4674c6c0f5d3c,reason=Created count=1 msg=Created container: task
0.1784,Event,ADDED,eval-conflicts-rho010-r8-077-gjsfx.18d4674c6eb5e7a7,reason=Started count=1 msg=Started container task
0.1786,Event,ADDED,eval-conflicts-rho010-r8-077.18d4674c509c8694,reason=SuccessfulCreate count=1 msg=Created pod: eval-conflicts-rho010-r8-077-gjsfx
0.1787,Event,ADDED,eval-conflicts-rho010-r8-077.18d4674f7f870b77,reason=Completed count=1 msg=Job completed
0.1789,Event,ADDED,eval-conflicts-rho010-r8-078-8vt9x.18d4674c8d1900d1,reason=Scheduled count=None msg=Successfully assigned compute/eval-conflicts-rho010-r8-078-8vt9x to kind-worker
0.1791,Event,ADDED,eval-conflicts-rho010-r8-078-8vt9x.18d4674ca6ecec33,"reason=Pulled count=1 msg=Container image ""busybox:musl"" already present on machine"
0.1793,Event,ADDED,eval-conflicts-rho010-r8-078-8vt9x.18d4674ca812c799,reason=Created count=1 msg=Created container: task
0.1795,Event,ADDED,eval-conflicts-rho010-r8-078-8vt9x.18d4674caa246d51,reason=Started count=1 msg=Started container task
0.18,Event,ADDED,eval-conflicts-rho010-r8-078.18d4674c8beee22a,reason=SuccessfulCreate count=1 msg=Created pod: eval-conflicts-rho010-r8-078-8vt9x
0.1802,Event,ADDED,eval-conflicts-rho010-r8-078.18d4674fee34c98c,reason=Completed count=1 msg=Job completed
0.1803,Event,ADDED,eval-conflicts-rho010-r8-079-bbw8k.18d4674cc84aa914,reason=Scheduled count=None msg=Successfully assigned compute/eval-conflicts-rho010-r8-079-bbw8k to kind-worker
0.1807,Event,ADDED,eval-conflicts-rho010-r8-079-bbw8k.18d4674ce1650083,"reason=Pulled count=1 msg=Container image ""busybox:musl"" already present on machine"
0.1809,Event,ADDED,eval-conflicts-rho010-r8-079-bbw8k.18d4674ce27e878a,reason=Created count=1 msg=Created container: task
0.1811,Event,ADDED,eval-conflicts-rho010-r8-079-bbw8k.18d4674ce482723b,reason=Started count=1 msg=Started container task
0.1812,Event,ADDED,eval-conflicts-rho010-r8-079.18d4674cc779296f,reason=SuccessfulCreate count=1 msg=Created pod: eval-conflicts-rho010-r8-079-bbw8k
0.1815,Event,ADDED,eval-conflicts-rho010-r8-079.18d467502a6eab71,reason=Completed count=1 msg=Job completed
0.1817,Event,ADDED,eval-conflicts-rho010-r8-080-ph565.18d4674d03f3d62a,reason=Scheduled count=None msg=Successfully assigned compute/eval-conflicts-rho010-r8-080-ph565 to kind-worker
0.182,Event,ADDED,eval-conflicts-rho010-r8-080-ph565.18d4674d1d72fdc4,"reason=Pulled count=1 msg=Container image ""busybox:musl"" already present on machine"
0.1822,Event,ADDED,eval-conflicts-rho010-r8-080-ph565.18d4674d1e85c133,reason=Created count=1 msg=Created container: task
0.1824,Event,ADDED,eval-conflicts-rho010-r8-080-ph565.18d4674d208438f7,reason=Started count=1 msg=Started container task
0.1827,Event,ADDED,eval-conflicts-rho010-r8-080.18d4674d02f8c4fe,reason=SuccessfulCreate count=1 msg=Created pod: eval-conflicts-rho010-r8-080-ph565
0.1829,Event,ADDED,eval-conflicts-rho010-r8-080.18d467506622c92a,reason=Completed count=1 msg=Job completed
0.1831,Event,ADDED,eval-conflicts-rho010-r8-081-zqts4.18d4674d3f95f202,reason=Scheduled count=None msg=Successfully assigned compute/eval-conflicts-rho010-r8-081-zqts4 to kind-worker5
0.1832,Event,ADDED,eval-conflicts-rho010-r8-081-zqts4.18d4674d58af5e8a,"reason=Pulled count=1 msg=Container image ""busybox:musl"" already present on machine"
0.1835,Event,ADDED,eval-conflicts-rho010-r8-081-zqts4.18d4674d59cfef87,reason=Created count=1 msg=Created container: task
0.1837,Event,ADDED,eval-conflicts-rho010-r8-081-zqts4.18d4674d5da31472,reason=Started count=1 msg=Started container task
0.1839,Event,ADDED,eval-conflicts-rho010-r8-081.18d4674d3e9b9e81,reason=SuccessfulCreate count=1 msg=Created pod: eval-conflicts-rho010-r8-081-zqts4
0.184,Event,ADDED,eval-conflicts-rho010-r8-081.18d467506ee011a3,reason=Completed count=1 msg=Job completed
0.1843,Event,ADDED,eval-conflicts-rho010-r8-082-9jd5n.18d4674d7a8cc4a4,"reason=FailedScheduling count=None msg=0/6 nodes are available: 2 c_wall violated: 1 conflicting context pair(s) with node memory, 4 node(s) had untolerated taint(s). no new claims to deallocate, preemption: 0/6 nodes are available: 2 No preemption victims found for incoming pod, 4 Preemption is not helpful for scheduling."
0.1845,Event,ADDED,eval-conflicts-rho010-r8-082-9jd5n.18d4674d7b474761,"reason=FailedScheduling count=None msg=0/6 nodes are available: 2 c_wall violated: 1 conflicting context pair(s) with node memory, 4 node(s) had untolerated taint(s). no new claims to deallocate, preemption: 0/6 nodes are available: 2 No preemption victims found for incoming pod, 4 Preemption is not helpful for scheduling."
0.1847,Event,ADDED,eval-conflicts-rho010-r8-082-9jd5n.18d4674d87807d1c,"reason=FailedScheduling count=None msg=0/6 nodes are available: 1 c_wall violated: 1 conflicting context pair(s) with node memory, 5 node(s) had untolerated taint(s). no new claims to deallocate, preemption: 0/6 nodes are available: 1 No preemption victims found for incoming pod, 5 Preemption is not helpful for scheduling."
0.1851,Event,ADDED,eval-conflicts-rho010-r8-082-9jd5n.18d4674dc766290c,reason=Scheduled count=None msg=Successfully assigned compute/eval-conflicts-rho010-r8-082-9jd5n to kind-worker4
0.1853,Event,ADDED,eval-conflicts-rho010-r8-082-9jd5n.18d4674de10742df,"reason=Pulled count=1 msg=Container image ""busybox:musl"" already present on machine"
0.1854,Event,ADDED,eval-conflicts-rho010-r8-082-9jd5n.18d4674de21c85e1,reason=Created count=1 msg=Created container: task
0.1858,Event,ADDED,eval-conflicts-rho010-r8-082-9jd5n.18d4674de5db9da1,reason=Started count=1 msg=Started container task
0.186,Event,ADDED,eval-conflicts-rho010-r8-082.18d4674d7a1e2bb0,reason=SuccessfulCreate count=1 msg=Created pod: eval-conflicts-rho010-r8-082-9jd5n
0.1862,Event,ADDED,eval-conflicts-rho010-r8-082.18d46751297e44f5,reason=Completed count=1 msg=Job completed
0.1864,Event,ADDED,eval-conflicts-rho010-r8-083-4mhsg.18d4674db65ea8fd,reason=Scheduled count=None msg=Successfully assigned compute/eval-conflicts-rho010-r8-083-4mhsg to kind-worker5
0.1873,Event,ADDED,eval-conflicts-rho010-r8-083-4mhsg.18d4674dcebc4bc9,"reason=Pulled count=1 msg=Container image ""busybox:musl"" already present on machine"
0.1875,Event,ADDED,eval-conflicts-rho010-r8-083-4mhsg.18d4674dcfe9889f,reason=Created count=1 msg=Created container: task
0.1877,Event,ADDED,eval-conflicts-rho010-r8-083-4mhsg.18d4674dd47af214,reason=Started count=1 msg=Started container task
0.188,Event,ADDED,eval-conflicts-rho010-r8-083.18d4674db5da0f6c,reason=SuccessfulCreate count=1 msg=Created pod: eval-conflicts-rho010-r8-083-4mhsg
0.1882,Event,ADDED,eval-conflicts-rho010-r8-083.18d46750e6be9050,reason=Completed count=1 msg=Job completed
0.1883,Event,ADDED,eval-conflicts-rho010-r8-084-rn7lx.18d4674df23de909,reason=Scheduled count=None msg=Successfully assigned compute/eval-conflicts-rho010-r8-084-rn7lx to kind-worker2
0.1885,Event,ADDED,eval-conflicts-rho010-r8-084-rn7lx.18d4674e0b40b9a2,"reason=Pulled count=1 msg=Container image ""busybox:musl"" already present on machine"
0.1888,Event,ADDED,eval-conflicts-rho010-r8-084-rn7lx.18d4674e0c53bb64,reason=Created count=1 msg=Created container: task
0.189,Event,ADDED,eval-conflicts-rho010-r8-084-rn7lx.18d4674e0e675019,reason=Started count=1 msg=Started container task
0.1892,Event,ADDED,eval-conflicts-rho010-r8-084.18d4674df15d44c9,reason=SuccessfulCreate count=1 msg=Created pod: eval-conflicts-rho010-r8-084-rn7lx
0.1894,Event,ADDED,eval-conflicts-rho010-r8-084.18d4675152e89ebd,reason=Completed count=1 msg=Job completed
0.1897,Event,ADDED,eval-conflicts-rho010-r8-085-qgcbb.18d4674e2f0d319c,reason=Scheduled count=None msg=Successfully assigned compute/eval-conflicts-rho010-r8-085-qgcbb to kind-worker2
0.1899,Event,ADDED,eval-conflicts-rho010-r8-085-qgcbb.18d4674e48493ac0,"reason=Pulled count=1 msg=Container image ""busybox:musl"" already present on machine"
0.1901,Event,ADDED,eval-conflicts-rho010-r8-085-qgcbb.18d4674e495fe9fa,reason=Created count=1 msg=Created container: task
0.1912,Event,ADDED,eval-conflicts-rho010-r8-085-qgcbb.18d4674e4d5519ce,reason=Started count=1 msg=Started container task
0.1914,Event,ADDED,eval-conflicts-rho010-r8-085.18d4674e2dc7f517,reason=SuccessfulCreate count=1 msg=Created pod: eval-conflicts-rho010-r8-085-qgcbb
0.1916,Event,ADDED,eval-conflicts-rho010-r8-085.18d467518ece01cf,reason=Completed count=1 msg=Job completed
0.1917,Event,ADDED,eval-conflicts-rho010-r8-086-rrfcl.18d4674e69d07bf9,reason=Scheduled count=None msg=Successfully assigned compute/eval-conflicts-rho010-r8-086-rrfcl to kind-worker2
0.192,Event,ADDED,eval-conflicts-rho010-r8-086-rrfcl.18d4674e82b1ed91,"reason=Pulled count=1 msg=Container image ""busybox:musl"" already present on machine"
0.1922,Event,ADDED,eval-conflicts-rho010-r8-086-rrfcl.18d4674e83b6ba1d,reason=Created count=1 msg=Created container: task
0.1924,Event,ADDED,eval-conflicts-rho010-r8-086-rrfcl.18d4674e85ead031,reason=Started count=1 msg=Started container task
0.1925,Event,ADDED,eval-conflicts-rho010-r8-086.18d4674e68dafc06,reason=SuccessfulCreate count=1 msg=Created pod: eval-conflicts-rho010-r8-086-rrfcl
0.1927,Event,ADDED,eval-conflicts-rho010-r8-086.18d46751ca82c938,reason=Completed count=1 msg=Job completed
0.1929,Event,ADDED,eval-conflicts-rho010-r8-087-7b7gg.18d4674ea5681c78,reason=Scheduled count=None msg=Successfully assigned compute/eval-conflicts-rho010-r8-087-7b7gg to kind-worker4
0.1931,Event,ADDED,eval-conflicts-rho010-r8-087-7b7gg.18d4674ebe9ba13c,"reason=Pulled count=1 msg=Container image ""busybox:musl"" already present on machine"
0.1932,Event,ADDED,eval-conflicts-rho010-r8-087-7b7gg.18d4674ebfb476d6,reason=Created count=1 msg=Created container: task
0.1934,Event,ADDED,eval-conflicts-rho010-r8-087-7b7gg.18d4674ec1d5a7e4,reason=Started count=1 msg=Started container task
0.1936,Event,ADDED,eval-conflicts-rho010-r8-087.18d4674ea4752e63,reason=SuccessfulCreate count=1 msg=Created pod: eval-conflicts-rho010-r8-087-7b7gg
0.1937,Event,ADDED,eval-conflicts-rho010-r8-087.18d46751dd072d46,reason=Completed count=1 msg=Job completed
0.1939,Event,ADDED,eval-conflicts-rho010-r8-088-bqr6t.18d4674ee0eb9904,reason=Scheduled count=None msg=Successfully assigned compute/eval-conflicts-rho010-r8-088-bqr6t to kind-worker4
0.194,Event,ADDED,eval-conflicts-rho010-r8-088-bqr6t.18d4674ef9e142d1,"reason=Pulled count=1 msg=Container image ""busybox:musl"" already present on machine"
0.1942,Event,ADDED,eval-conflicts-rho010-r8-088-bqr6t.18d4674efaf6d2d3,reason=Created count=1 msg=Created container: task
0.1944,Event,ADDED,eval-conflicts-rho010-r8-088-bqr6t.18d4674efd0663ed,reason=Started count=1 msg=Started container task
0.1946,Event,ADDED,eval-conflicts-rho010-r8-088.18d4674edffa298d,reason=SuccessfulCreate count=1 msg=Created pod: eval-conflicts-rho010-r8-088-bqr6t
0.1947,Event,ADDED,eval-conflicts-rho010-r8-088.18d4675218cac11a,reason=Completed count=1 msg=Job completed
0.1949,Event,ADDED,eval-conflicts-rho010-r8-089-snc8g.18d4674f1c5688c5,reason=Scheduled count=None msg=Successfully assigned compute/eval-conflicts-rho010-r8-089-snc8g to kind-worker2
0.1952,Event,ADDED,eval-conflicts-rho010-r8-089-snc8g.18d4674f3520a188,"reason=Pulled count=1 msg=Container image ""busybox:musl"" already present on machine"
0.1954,Event,ADDED,eval-conflicts-rho010-r8-089-snc8g.18d4674f3630950e,reason=Created count=1 msg=Created container: task
0.1955,Event,ADDED,eval-conflicts-rho010-r8-089-snc8g.18d4674f39ed17a7,reason=Started count=1 msg=Started container task
0.196,Event,ADDED,eval-conflicts-rho010-r8-089.18d4674f1ba82d0f,reason=SuccessfulCreate count=1 msg=Created pod: eval-conflicts-rho010-r8-089-snc8g
0.1963,Event,ADDED,eval-conflicts-rho010-r8-089.18d467527e49c090,reason=Completed count=1 msg=Job completed
0.1964,Event,ADDED,eval-conflicts-rho010-r8-090-2fqkz.18d4674f580bfd2e,reason=Scheduled count=None msg=Successfully assigned compute/eval-conflicts-rho010-r8-090-2fqkz to kind-worker2
0.1966,Event,ADDED,eval-conflicts-rho010-r8-090-2fqkz.18d4674f7199691b,"reason=Pulled count=1 msg=Container image ""busybox:musl"" already present on machine"
0.1969,Event,ADDED,eval-conflicts-rho010-r8-090-2fqkz.18d4674f72ba089e,reason=Created count=1 msg=Created container: task
0.1971,Event,ADDED,eval-conflicts-rho010-r8-090-2fqkz.18d4674f74aaf00a,reason=Started count=1 msg=Started container task
0.1973,Event,ADDED,eval-conflicts-rho010-r8-090.18d4674f5720bcc0,reason=SuccessfulCreate count=1 msg=Created pod: eval-conflicts-rho010-r8-090-2fqkz
0.1974,Event,ADDED,eval-conflicts-rho010-r8-090.18d46752b9f4b633,reason=Completed count=1 msg=Job completed
0.1979,Event,ADDED,eval-conflicts-rho010-r8-091-nxcmj.18d4674f93dabc1f,reason=Scheduled count=None msg=Successfully assigned compute/eval-conflicts-rho010-r8-091-nxcmj to kind-worker4
0.198,Event,ADDED,eval-conflicts-rho010-r8-091-nxcmj.18d4674facfb7d8b,"reason=Pulled count=1 msg=Container image ""busybox:musl"" already present on machine"
0.1982,Event,ADDED,eval-conflicts-rho010-r8-091-nxcmj.18d4674fae04be05,reason=Created count=1 msg=Created container: task
0.1983,Event,ADDED,eval-conflicts-rho010-r8-091-nxcmj.18d4674fafed2a01,reason=Started count=1 msg=Started container task
0.1985,Event,ADDED,eval-conflicts-rho010-r8-091.18d4674f92e1180e,reason=SuccessfulCreate count=1 msg=Created pod: eval-conflicts-rho010-r8-091-nxcmj
0.1987,Event,ADDED,eval-conflicts-rho010-r8-091.18d46752cc0543ed,reason=Completed count=1 msg=Job completed
0.1988,Event,ADDED,eval-conflicts-rho010-r8-092-gvgc8.18d4674fcf568dea,reason=Scheduled count=None msg=Successfully assigned compute/eval-conflicts-rho010-r8-092-gvgc8 to kind-worker4
0.199,Event,ADDED,eval-conflicts-rho010-r8-092-gvgc8.18d4674fe7e1d3a3,"reason=Pulled count=1 msg=Container image ""busybox:musl"" already present on machine"
0.1992,Event,ADDED,eval-conflicts-rho010-r8-092-gvgc8.18d4674fe8eee963,reason=Created count=1 msg=Created container: task
0.1993,Event,ADDED,eval-conflicts-rho010-r8-092-gvgc8.18d4674feb0d2028,reason=Started count=1 msg=Started container task
0.1995,Event,ADDED,eval-conflicts-rho010-r8-092.18d4674fce9acd4d,reason=SuccessfulCreate count=1 msg=Created pod: eval-conflicts-rho010-r8-092-gvgc8
0.1997,Event,ADDED,eval-conflicts-rho010-r8-092.18d4675307dfd400,reason=Completed count=1 msg=Job completed
0.1998,Event,ADDED,eval-conflicts-rho010-r8-093-pc9mq.18d467500afdb23a,reason=Scheduled count=None msg=Successfully assigned compute/eval-conflicts-rho010-r8-093-pc9mq to kind-worker2
0.2,Event,ADDED,eval-conflicts-rho010-r8-093-pc9mq.18d46750241a52e9,"reason=Pulled count=1 msg=Container image ""busybox:musl"" already present on machine"
0.2002,Event,ADDED,eval-conflicts-rho010-r8-093-pc9mq.18d4675025453394,reason=Created count=1 msg=Created container: task
0.2003,Event,ADDED,eval-conflicts-rho010-r8-093-pc9mq.18d4675029c8dde1,reason=Started count=1 msg=Started container task
0.2005,Event,ADDED,eval-conflicts-rho010-r8-093.18d467500a10bc5e,reason=SuccessfulCreate count=1 msg=Created pod: eval-conflicts-rho010-r8-093-pc9mq
0.2007,Event,ADDED,eval-conflicts-rho010-r8-093.18d467536d286639,reason=Completed count=1 msg=Job completed
0.2008,Event,ADDED,eval-conflicts-rho010-r8-094-54vfw.18d4675045bfc139,reason=Scheduled count=None msg=Successfully assigned compute/eval-conflicts-rho010-r8-094-54vfw to kind-worker3
0.201,Event,ADDED,eval-conflicts-rho010-r8-094-54vfw.18d467505da6ae5b,"reason=Pulled count=1 msg=Container image ""busybox:musl"" already present on machine"
0.2011,Event,ADDED,eval-conflicts-rho010-r8-094-54vfw.18d467505eb39e69,reason=Created count=1 msg=Created container: task
0.2013,Event,ADDED,eval-conflicts-rho010-r8-094-54vfw.18d46750624cbeb0,reason=Started count=1 msg=Started container task
0.2016,Event,ADDED,eval-conflicts-rho010-r8-094.18d467504569302f,reason=SuccessfulCreate count=1 msg=Created pod: eval-conflicts-rho010-r8-094-54vfw
0.2018,Event,ADDED,eval-conflicts-rho010-r8-094.18d46753925f4fe1,reason=Completed count=1 msg=Job completed
0.202,Event,ADDED,eval-conflicts-rho010-r8-095-9hhcw.18d467508227d196,reason=Scheduled count=None msg=Successfully assigned compute/eval-conflicts-rho010-r8-095-9hhcw to kind-worker3
0.2023,Event,ADDED,eval-conflicts-rho010-r8-095-9hhcw.18d467509b8c8cd4,"reason=Pulled count=1 msg=Container image ""busybox:musl"" already present on machine"
0.2025,Event,ADDED,eval-conflicts-rho010-r8-095-9hhcw.18d467509cd45399,reason=Created count=1 msg=Created container: task
0.2027,Event,ADDED,eval-conflicts-rho010-r8-095-9hhcw.18d467509ed3ecc4,reason=Started count=1 msg=Started container task
0.2029,Event,ADDED,eval-conflicts-rho010-r8-095.18d4675081387a5f,reason=SuccessfulCreate count=1 msg=Created pod: eval-conflicts-rho010-r8-095-9hhcw
0.2031,Event,ADDED,eval-conflicts-rho010-r8-095.18d46753ce429b39,reason=Completed count=1 msg=Job completed
0.2032,Event,ADDED,eval-conflicts-rho010-r8-096-jfxvx.18d46750be491ca7,reason=Scheduled count=None msg=Successfully assigned compute/eval-conflicts-rho010-r8-096-jfxvx to kind-worker5
0.2034,Event,ADDED,eval-conflicts-rho010-r8-096-jfxvx.18d46750d83cf430,"reason=Pulled count=1 msg=Container image ""busybox:musl"" already present on machine"
0.2036,Event,ADDED,eval-conflicts-rho010-r8-096-jfxvx.18d46750d955f8cd,reason=Created count=1 msg=Created container: task
0.2038,Event,ADDED,eval-conflicts-rho010-r8-096-jfxvx.18d46750db7e84d9,reason=Started count=1 msg=Started container task
0.2039,Event,ADDED,eval-conflicts-rho010-r8-096.18d46750bda7dc98,reason=SuccessfulCreate count=1 msg=Created pod: eval-conflicts-rho010-r8-096-jfxvx
0.2041,Event,ADDED,eval-conflicts-rho010-r8-096.18d46753ef98bc05,reason=Completed count=1 msg=Job completed
0.2043,Event,ADDED,eval-conflicts-rho010-r8-097-527zs.18d46750f93fd142,reason=Scheduled count=None msg=Successfully assigned compute/eval-conflicts-rho010-r8-097-527zs to kind-worker5
0.2047,Event,ADDED,eval-conflicts-rho010-r8-097-527zs.18d46751121fbf22,"reason=Pulled count=1 msg=Container image ""busybox:musl"" already present on machine"
0.2049,Event,ADDED,eval-conflicts-rho010-r8-097-527zs.18d4675113322d0a,reason=Created count=1 msg=Created container: task
0.205,Event,ADDED,eval-conflicts-rho010-r8-097-527zs.18d46751151b6ca6,reason=Started count=1 msg=Started container task
0.2052,Event,ADDED,eval-conflicts-rho010-r8-097.18d46750f85c9984,reason=SuccessfulCreate count=1 msg=Created pod: eval-conflicts-rho010-r8-097-527zs
0.2054,Event,ADDED,eval-conflicts-rho010-r8-097.18d467542b51be48,reason=Completed count=1 msg=Job completed
0.2055,Event,ADDED,eval-conflicts-rho010-r8-098-kdpbm.18d46751350bba10,"reason=FailedScheduling count=None msg=0/6 nodes are available: 2 c_wall violated: 1 conflicting context pair(s) with node memory, 4 node(s) had untolerated taint(s). no new claims to deallocate, preemption: 0/6 nodes are available: 2 No preemption victims found for incoming pod, 4 Preemption is not helpful for scheduling."
0.2057,Event,ADDED,eval-conflicts-rho010-r8-098-kdpbm.18d4675135b3454a,"reason=FailedScheduling count=None msg=0/6 nodes are available: 2 c_wall violated: 1 conflicting context pair(s) with node memory, 4 node(s) had untolerated taint(s). no new claims to deallocate, preemption: 0/6 nodes are available: 2 No preemption victims found for incoming pod, 4 Preemption is not helpful for scheduling."
0.2059,Event,ADDED,eval-conflicts-rho010-r8-098-kdpbm.18d46752523e1172,reason=Scheduled count=None msg=Successfully assigned compute/eval-conflicts-rho010-r8-098-kdpbm to kind-worker
0.2062,Event,ADDED,eval-conflicts-rho010-r8-098-kdpbm.18d467526b9e7d82,"reason=Pulled count=1 msg=Container image ""busybox:musl"" already present on machine"
0.2064,Event,ADDED,eval-conflicts-rho010-r8-098-kdpbm.18d467526cbf8f36,reason=Created count=1 msg=Created container: task
0.2066,Event,ADDED,eval-conflicts-rho010-r8-098-kdpbm.18d467526eb523e1,reason=Started count=1 msg=Started container task
0.2068,Event,ADDED,eval-conflicts-rho010-r8-098.18d467513493827e,reason=SuccessfulCreate count=1 msg=Created pod: eval-conflicts-rho010-r8-098-kdpbm
0.207,Event,ADDED,eval-conflicts-rho010-r8-098.18d467558a630126,reason=Completed count=1 msg=Job completed
0.2071,Event,ADDED,eval-conflicts-rho010-r8-099-vlt62.18d467516ff511c9,reason=Scheduled count=None msg=Successfully assigned compute/eval-conflicts-rho010-r8-099-vlt62 to kind-worker3
0.2073,Event,ADDED,eval-conflicts-rho010-r8-099-vlt62.18d4675188b9bdf6,"reason=Pulled count=1 msg=Container image ""busybox:musl"" already present on machine"
0.2074,Event,ADDED,eval-conflicts-rho010-r8-099-vlt62.18d467518a0602ad,reason=Created count=1 msg=Created container: task
0.2076,Event,ADDED,eval-conflicts-rho010-r8-099-vlt62.18d467518dbffad2,reason=Started count=1 msg=Started container task
0.2081,Event,ADDED,eval-conflicts-rho010-r8-099.18d467516f4f0cf3,reason=SuccessfulCreate count=1 msg=Created pod: eval-conflicts-rho010-r8-099-vlt62
0.2085,Event,ADDED,eval-conflicts-rho010-r8-099.18d46754be118cfe,reason=Completed count=1 msg=Job completed
0.2086,Event,ADDED,eval-conflicts-rho010-r9-000-n6cgm.18d4675a746e4260,reason=Scheduled count=None msg=Successfully assigned compute/eval-conflicts-rho010-r9-000-n6cgm to kind-worker5
0.2089,Event,ADDED,eval-conflicts-rho010-r9-000-n6cgm.18d4675a90d99f7b,"reason=Pulled count=1 msg=Container image ""busybox:musl"" already present on machine"
0.2091,Event,ADDED,eval-conflicts-rho010-r9-000-n6cgm.18d4675a91fd36df,reason=Created count=1 msg=Created container: task
0.2093,Event,ADDED,eval-conflicts-rho010-r9-000-n6cgm.18d4675a98df89e7,reason=Started count=1 msg=Started container task
0.2094,Event,ADDED,eval-conflicts-rho010-r9-000.18d4675a73831612,reason=SuccessfulCreate count=1 msg=Created pod: eval-conflicts-rho010-r9-000-n6cgm
0.2097,Event,ADDED,eval-conflicts-rho010-r9-000.18d4675dbdc49eeb,reason=Completed count=1 msg=Job completed
0.2099,Event,ADDED,eval-conflicts-rho010-r9-001-f2c7h.18d4675aaf9204af,reason=Scheduled count=None msg=Successfully assigned compute/eval-conflicts-rho010-r9-001-f2c7h to kind-worker2
0.2101,Event,ADDED,eval-conflicts-rho010-r9-001-f2c7h.18d4675ac9bb5ebe,"reason=Pulled count=1 msg=Container image ""busybox:musl"" already present on machine"
0.2103,Event,ADDED,eval-conflicts-rho010-r9-001-f2c7h.18d4675acacc42fc,reason=Created count=1 msg=Created container: task
0.2105,Event,ADDED,eval-conflicts-rho010-r9-001-f2c7h.18d4675acf230d52,reason=Started count=1 msg=Started container task
0.2107,Event,ADDED,eval-conflicts-rho010-r9-001.18d4675aae686939,reason=SuccessfulCreate count=1 msg=Created pod: eval-conflicts-rho010-r9-001-f2c7h
0.2108,Event,ADDED,eval-conflicts-rho010-r9-001.18d4675dee0a44dd,reason=Completed count=1 msg=Job completed
0.211,Event,ADDED,eval-conflicts-rho010-r9-002-h4wgj.18d4675aecd18d86,reason=Scheduled count=None msg=Successfully assigned compute/eval-conflicts-rho010-r9-002-h4wgj to kind-worker5
0.2112,Event,ADDED,eval-conflicts-rho010-r9-002-h4wgj.18d4675b087fe598,"reason=Pulled count=1 msg=Container image ""busybox:musl"" already present on machine"
0.2113,Event,ADDED,eval-conflicts-rho010-r9-002-h4wgj.18d4675b09b06676,reason=Created count=1 msg=Created container: task
0.2115,Event,ADDED,eval-conflicts-rho010-r9-002-h4wgj.18d4675b12f2c1f8,reason=Started count=1 msg=Started container task
0.2117,Event,ADDED,eval-conflicts-rho010-r9-002.18d4675aebc41f60,reason=SuccessfulCreate count=1 msg=Created pod: eval-conflicts-rho010-r9-002-h4wgj
0.2118,Event,ADDED,eval-conflicts-rho010-r9-002.18d4675e35b3aeab,reason=Completed count=1 msg=Job completed
0.212,Event,ADDED,eval-conflicts-rho010-r9-003-xklv2.18d4675b25570a80,reason=Scheduled count=None msg=Successfully assigned compute/eval-conflicts-rho010-r9-003-xklv2 to kind-worker
0.2121,Event,ADDED,eval-conflicts-rho010-r9-003-xklv2.18d4675b3e61636e,"reason=Pulled count=1 msg=Container image ""busybox:musl"" already present on machine"
0.2123,Event,ADDED,eval-conflicts-rho010-r9-003-xklv2.18d4675b3fb1c794,reason=Created count=1 msg=Created container: task
0.2125,Event,ADDED,eval-conflicts-rho010-r9-003-xklv2.18d4675b440fbed2,reason=Started count=1 msg=Started container task
0.2126,Event,ADDED,eval-conflicts-rho010-r9-003.18d4675b244d0e40,reason=SuccessfulCreate count=1 msg=Created pod: eval-conflicts-rho010-r9-003-xklv2
0.2129,Event,ADDED,eval-conflicts-rho010-r9-003.18d4675e2bcac412,reason=Completed count=1 msg=Job completed
0.213,Event,ADDED,eval-conflicts-rho010-r9-004-cq2pv.18d4675b60d90368,reason=Scheduled count=None msg=Successfully assigned compute/eval-conflicts-rho010-r9-004-cq2pv to kind-worker
0.2132,Event,ADDED,eval-conflicts-rho010-r9-004-cq2pv.18d4675b7ae7e51b,"reason=Pulled count=1 msg=Container image ""busybox:musl"" already present on machine"
0.2134,Event,ADDED,eval-conflicts-rho010-r9-004-cq2pv.18d4675b7bfeb008,reason=Created count=1 msg=Created container: task
0.2136,Event,ADDED,eval-conflicts-rho010-r9-004-cq2pv.18d4675b7e503a63,reason=Started count=1 msg=Started container task
0.2139,Event,ADDED,eval-conflicts-rho010-r9-004.18d4675b5fb723e7,reason=SuccessfulCreate count=1 msg=Created pod: eval-conflicts-rho010-r9-004-cq2pv
0.2144,Event,ADDED,eval-conflicts-rho010-r9-004.18d4675ea306e255,reason=Completed count=1 msg=Job completed
0.2146,Event,ADDED,eval-conflicts-rho010-r9-005-dq6s4.18d4675b9c628cf5,reason=Scheduled count=None msg=Successfully assigned compute/eval-conflicts-rho010-r9-005-dq6s4 to kind-worker2
0.215,Event,ADDED,eval-conflicts-rho010-r9-005-dq6s4.18d4675bb56ccbea,"reason=Pulled count=1 msg=Container image ""busybox:musl"" already present on machine"
0.2152,Event,ADDED,eval-conflicts-rho010-r9-005-dq6s4.18d4675bb69b04b6,reason=Created count=1 msg=Created container: task
0.2154,Event,ADDED,eval-conflicts-rho010-r9-005-dq6s4.18d4675bb89e99ed,reason=Started count=1 msg=Started container task
0.2158,Event,ADDED,eval-conflicts-rho010-r9-005.18d4675b9b3b35d7,reason=SuccessfulCreate count=1 msg=Created pod: eval-conflicts-rho010-r9-005-dq6s4
0.216,Event,ADDED,eval-conflicts-rho010-r9-005.18d4675ea1aa90ab,reason=Completed count=1 msg=Job completed
0.2161,Event,ADDED,eval-conflicts-rho010-r9-006-6s6jp.18d4675bd7f5c273,reason=Scheduled count=None msg=Successfully assigned compute/eval-conflicts-rho010-r9-006-6s6jp to kind-worker5
0.2163,Event,ADDED,eval-conflicts-rho010-r9-006-6s6jp.18d4675bf12072f6,"reason=Pulled count=1 msg=Container image ""busybox:musl"" already present on machine"
0.2166,Event,ADDED,eval-conflicts-rho010-r9-006-6s6jp.18d4675bf2538972,reason=Created count=1 msg=Created container: task
0.2167,Event,ADDED,eval-conflicts-rho010-r9-006-6s6jp.18d4675bf5c16740,reason=Started count=1 msg=Started container task
0.2169,Event,ADDED,eval-conflicts-rho010-r9-006.18d4675bd71c11da,reason=SuccessfulCreate count=1 msg=Created pod: eval-conflicts-rho010-r9-006-6s6jp
0.2171,Event,ADDED,eval-conflicts-rho010-r9-006.18d4675f246e1e0e,reason=Completed count=1 msg=Job completed
0.2173,Event,ADDED,eval-conflicts-rho010-r9-007-xtd4z.18d4675c13718368,reason=Scheduled count=None msg=Successfully assigned compute/eval-conflicts-rho010-r9-007-xtd4z to kind-worker5
0.2174,Event,ADDED,eval-conflicts-rho010-r9-007-xtd4z.18d4675c2d01658e,"reason=Pulled count=1 msg=Container image ""busybox:musl"" already present on machine"
0.2176,Event,ADDED,eval-conflicts-rho010-r9-007-xtd4z.18d4675c2e1a3156,reason=Created count=1 msg=Created container: task
0.2178,Event,ADDED,eval-conflicts-rho010-r9-007-xtd4z.18d4675c33361258,reason=Started count=1 msg=Started container task
0.2183,Event,ADDED,eval-conflicts-rho010-r9-007.18d4675c12ba08d6,reason=SuccessfulCreate count=1 msg=Created pod: eval-conflicts-rho010-r9-007-xtd4z
0.2185,Event,ADDED,eval-conflicts-rho010-r9-007.18d4675f6038ce2a,reason=Completed count=1 msg=Job completed
0.2186,Event,ADDED,eval-conflicts-rho010-r9-008-rtkfz.18d4675c4f5afcf1,reason=Scheduled count=None msg=Successfully assigned compute/eval-conflicts-rho010-r9-008-rtkfz to kind-worker4
0.219,Event,ADDED,eval-conflicts-rho010-r9-008-rtkfz.18d4675c689c536b,"reason=Pulled count=1 msg=Container image ""busybox:musl"" already present on machine"
0.2192,Event,ADDED,eval-conflicts-rho010-r9-008-rtkfz.18d4675c69ae2352,reason=Created count=1 msg=Created container: task
0.2193,Event,ADDED,eval-conflicts-rho010-r9-008-rtkfz.18d4675c6b7cc49d,reason=Started count=1 msg=Started container task
0.2196,Event,ADDED,eval-conflicts-rho010-r9-008.18d4675c4e5e52a7,reason=SuccessfulCreate count=1 msg=Created pod: eval-conflicts-rho010-r9-008-rtkfz
0.2197,Event,ADDED,eval-conflicts-rho010-r9-008.18d4675fa216ff78,reason=Completed count=1 msg=Job completed
0.2199,Event,ADDED,eval-conflicts-rho010-r9-009-rgqcm.18d4675c8a70bced,reason=Scheduled count=None msg=Successfully assigned compute/eval-conflicts-rho010-r9-009-rgqcm to kind-worker4
0.2201,Event,ADDED,eval-conflicts-rho010-r9-009-rgqcm.18d4675ca4da1fd3,"reason=Pulled count=1 msg=Container image ""busybox:musl"" already present on machine"
0.2203,Event,ADDED,eval-conflicts-rho010-r9-009-rgqcm.18d4675ca5ed4066,reason=Created count=1 msg=Created container: task
0.2204,Event,ADDED,eval-conflicts-rho010-r9-009-rgqcm.18d4675ca7d2698a,reason=Started count=1 msg=Started container task
0.2206,Event,ADDED,eval-conflicts-rho010-r9-009.18d4675c89bb6fcd,reason=SuccessfulCreate count=1 msg=Created pod: eval-conflicts-rho010-r9-009-rgqcm
0.2207,Event,ADDED,eval-conflicts-rho010-r9-009.18d4675fdde8c301,reason=Completed count=1 msg=Job completed
0.2209,Event,ADDED,eval-conflicts-rho010-r9-010-qjhx7.18d4675cc65019e9,reason=Scheduled count=None msg=Successfully assigned compute/eval-conflicts-rho010-r9-010-qjhx7 to kind-worker3
0.2211,Event,ADDED,eval-conflicts-rho010-r9-010-qjhx7.18d4675cdf6ba52e,"reason=Pulled count=1 msg=Container image ""busybox:musl"" already present on machine"
0.2213,Event,ADDED,eval-conflicts-rho010-r9-010-qjhx7.18d4675ce07e15c0,reason=Created count=1 msg=Created container: task
0.2214,Event,ADDED,eval-conflicts-rho010-r9-010-qjhx7.18d4675ce2afe12c,reason=Started count=1 msg=Started container task
0.2216,Event,ADDED,eval-conflicts-rho010-r9-010.18d4675cc5c4327f,reason=SuccessfulCreate count=1 msg=Created pod: eval-conflicts-rho010-r9-010-qjhx7
0.2218,Event,ADDED,eval-conflicts-rho010-r9-010.18d4675ff012c975,reason=Completed count=1 msg=Job completed
0.2219,Event,ADDED,eval-conflicts-rho010-r9-011-nfh84.18d4675d01e5a22e,reason=Scheduled count=None msg=Successfully assigned compute/eval-conflicts-rho010-r9-011-nfh84 to kind-worker4
0.2221,Event,ADDED,eval-conflicts-rho010-r9-011-nfh84.18d4675d1b511b48,"reason=Pulled count=1 msg=Container image ""busybox:musl"" already present on machine"
0.2223,Event,ADDED,eval-conflicts-rho010-r9-011-nfh84.18d4675d1c6c1151,reason=Created count=1 msg=Created container: task
0.2225,Event,ADDED,eval-conflicts-rho010-r9-011-nfh84.18d4675d1e760555,reason=Started count=1 msg=Started container task
0.2226,Event,ADDED,eval-conflicts-rho010-r9-011.18d4675d00fa7395,reason=SuccessfulCreate count=1 msg=Created pod: eval-conflicts-rho010-r9-011-nfh84
0.2228,Event,ADDED,eval-conflicts-rho010-r9-011.18d4676055b26497,reason=Completed count=1 msg=Job completed
0.2229,Event,ADDED,eval-conflicts-rho010-r9-012-sm9tf.18d4675d3d7e0292,reason=Scheduled count=None msg=Successfully assigned compute/eval-conflicts-rho010-r9-012-sm9tf to kind-worker4
0.2231,Event,ADDED,eval-conflicts-rho010-r9-012-sm9tf.18d4675d56c7564e,"reason=Pulled count=1 msg=Container image ""busybox:musl"" already present on machine"
0.2233,Event,ADDED,eval-conflicts-rho010-r9-012-sm9tf.18d4675d57f84a36,reason=Created count=1 msg=Created container: task
0.2235,Event,ADDED,eval-conflicts-rho010-r9-012-sm9tf.18d4675d5b670dcb,reason=Started count=1 msg=Started container task
0.2237,Event,ADDED,eval-conflicts-rho010-r9-012.18d4675d3cafdcac,reason=SuccessfulCreate count=1 msg=Created pod: eval-conflicts-rho010-r9-012-sm9tf
0.2239,Event,ADDED,eval-conflicts-rho010-r9-012.18d4676091f84642,reason=Completed count=1 msg=Job completed
0.224,Event,ADDED,eval-conflicts-rho010-r9-013-2drkq.18d4675d7910fb69,reason=Scheduled count=None msg=Successfully assigned compute/eval-conflicts-rho010-r9-013-2drkq to kind-worker3
0.2242,Event,ADDED,eval-conflicts-rho010-r9-013-2drkq.18d4675d93400f51,"reason=Pulled count=1 msg=Container image ""busybox:musl"" already present on machine"
0.2244,Event,ADDED,eval-conflicts-rho010-r9-013-2drkq.18d4675d9460e7d1,reason=Created count=1 msg=Created container: task
0.2247,Event,ADDED,eval-conflicts-rho010-r9-013-2drkq.18d4675d9654fbf5,reason=Started count=1 msg=Started container task
0.2249,Event,ADDED,eval-conflicts-rho010-r9-013.18d4675d780dd69b,reason=SuccessfulCreate count=1 msg=Created pod: eval-conflicts-rho010-r9-013-2drkq
0.2251,Event,ADDED,eval-conflicts-rho010-r9-013.18d46760a39c001b,reason=Completed count=1 msg=Job completed
0.2252,Event,ADDED,eval-conflicts-rho010-r9-014-wm8jq.18d4675db490cd54,reason=Scheduled count=None msg=Successfully assigned compute/eval-conflicts-rho010-r9-014-wm8jq to kind-worker4
0.2255,Event,ADDED,eval-conflicts-rho010-r9-014-wm8jq.18d4675dccab851e,"reason=Pulled count=1 msg=Container image ""busybox:musl"" already present on machine"
0.2257,Event,ADDED,eval-conflicts-rho010-r9-014-wm8jq.18d4675dcdbd7a82,reason=Created count=1 msg=Created container: task
0.2259,Event,ADDED,eval-conflicts-rho010-r9-014-wm8jq.18d4675dcfa0a4fb,reason=Started count=1 msg=Started container task
0.2261,Event,ADDED,eval-conflicts-rho010-r9-014.18d4675db3e4b0d4,reason=SuccessfulCreate count=1 msg=Created pod: eval-conflicts-rho010-r9-014-wm8jq
0.2264,Event,ADDED,eval-conflicts-rho010-r9-014.18d467610943f5f1,reason=Completed count=1 msg=Job completed
0.2266,Event,ADDED,eval-conflicts-rho010-r9-015-dcnpz.18d4675df0ef1d2a,reason=Scheduled count=None msg=Successfully assigned compute/eval-conflicts-rho010-r9-015-dcnpz to kind-worker3
0.2267,Event,ADDED,eval-conflicts-rho010-r9-015-dcnpz.18d4675e09199ce3,"reason=Pulled count=1 msg=Container image ""busybox:musl"" already present on machine"
0.227,Event,ADDED,eval-conflicts-rho010-r9-015-dcnpz.18d4675e0a232dfd,reason=Created count=1 msg=Created container: task
0.2272,Event,ADDED,eval-conflicts-rho010-r9-015-dcnpz.18d4675e0c1e02c7,reason=Started count=1 msg=Started container task
0.2273,Event,ADDED,eval-conflicts-rho010-r9-015.18d4675df0012082,reason=SuccessfulCreate count=1 msg=Created pod: eval-conflicts-rho010-r9-015-dcnpz
0.2275,Event,ADDED,eval-conflicts-rho010-r9-015.18d467611b15731f,reason=Completed count=1 msg=Job completed
0.2278,Event,ADDED,eval-conflicts-rho010-r9-016-669r4.18d4675e2bc8c3ef,reason=Scheduled count=None msg=Successfully assigned compute/eval-conflicts-rho010-r9-016-669r4 to kind-worker4
0.228,Event,ADDED,eval-conflicts-rho010-r9-016-669r4.18d4675e45755795,"reason=Pulled count=1 msg=Container image ""busybox:musl"" already present on machine"
0.2282,Event,ADDED,eval-conflicts-rho010-r9-016-669r4.18d4675e46a67a18,reason=Created count=1 msg=Created container: task
0.2285,Event,ADDED,eval-conflicts-rho010-r9-016-669r4.18d4675e48f84a39,reason=Started count=1 msg=Started container task
0.2286,Event,ADDED,eval-conflicts-rho010-r9-016.18d4675e2af03d62,reason=SuccessfulCreate count=1 msg=Created pod: eval-conflicts-rho010-r9-016-669r4
0.2288,Event,ADDED,eval-conflicts-rho010-r9-016.18d46761811c248c,reason=Completed count=1 msg=Job completed
0.2292,Event,ADDED,eval-conflicts-rho010-r9-017-hh9bz.18d4675e66b5f037,"reason=FailedScheduling count=None msg=0/6 nodes are available: 6 node(s) had untolerated taint(s). no new claims to deallocate, preemption: 0/6 nodes are available: 6 Preemption is not helpful for scheduling."
0.2295,Event,ADDED,eval-conflicts-rho010-r9-017-hh9bz.18d4676073489d8e,reason=Scheduled count=None msg=Successfully assigned compute/eval-conflicts-rho010-r9-017-hh9bz to kind-worker
0.2297,Event,ADDED,eval-conflicts-rho010-r9-017-hh9bz.18d467608ebe4e92,"reason=Pulled count=1 msg=Container image ""busybox:musl"" already present on machine"
0.2298,Event,ADDED,eval-conflicts-rho010-r9-017-hh9bz.18d46760927fbca8,reason=Created count=1 msg=Created container: task
0.23,Event,ADDED,eval-conflicts-rho010-r9-017-hh9bz.18d4676097729227,reason=Started count=1 msg=Started container task
0.2302,Event,ADDED,eval-conflicts-rho010-r9-017.18d4675e66ae2afa,reason=SuccessfulCreate count=1 msg=Created pod: eval-conflicts-rho010-r9-017-hh9bz
0.2304,Event,ADDED,eval-conflicts-rho010-r9-017.18d467638ba1b631,reason=Completed count=1 msg=Job completed
0.2308,Event,ADDED,eval-conflicts-rho010-r9-018-dq9kb.18d4675ea23e42f2,"reason=FailedScheduling count=None msg=0/6 nodes are available: 6 node(s) had untolerated taint(s). no new claims to deallocate, preemption: 0/6 nodes are available: 6 Preemption is not helpful for scheduling."
0.231,Event,ADDED,eval-conflicts-rho010-r9-018-dq9kb.18d4676073e1c08b,reason=Scheduled count=None msg=Successfully assigned compute/eval-conflicts-rho010-r9-018-dq9kb to kind-worker
0.2312,Event,ADDED,eval-conflicts-rho010-r9-018-dq9kb.18d467608f268b48,"reason=Pulled count=1 msg=Container image ""busybox:musl"" already present on machine"
0.2314,Event,ADDED,eval-conflicts-rho010-r9-018-dq9kb.18d467609432b0e7,reason=Created count=1 msg=Created container: task
0.2316,Event,ADDED,eval-conflicts-rho010-r9-018-dq9kb.18d467609a8d2b71,reason=Started count=1 msg=Started container task
0.2319,Event,ADDED,eval-conflicts-rho010-r9-018.18d4675ea2303047,reason=SuccessfulCreate count=1 msg=Created pod: eval-conflicts-rho010-r9-018-dq9kb
0.2321,Event,ADDED,eval-conflicts-rho010-r9-018.18d467638d1208a2,reason=Completed count=1 msg=Job completed
0.2322,Event,ADDED,eval-conflicts-rho010-r9-019-j8tn5.18d4675eddc51716,"reason=FailedScheduling count=None msg=0/6 nodes are available: 6 node(s) had untolerated taint(s). no new claims to deallocate, preemption: 0/6 nodes are available: 6 Preemption is not helpful for scheduling."
0.2325,Event,ADDED,eval-conflicts-rho010-r9-019-j8tn5.18d4676074715781,reason=Scheduled count=None msg=Successfully assigned compute/eval-conflicts-rho010-r9-019-j8tn5 to kind-worker
0.2327,Event,ADDED,eval-conflicts-rho010-r9-019-j8tn5.18d4676090637651,"reason=Pulled count=1 msg=Container image ""busybox:musl"" already present on machine"
0.2329,Event,ADDED,eval-conflicts-rho010-r9-019-j8tn5.18d46760954ae149,reason=Created count=1 msg=Created container: task
0.233,Event,ADDED,eval-conflicts-rho010-r9-019-j8tn5.18d467609ca26ab8,reason=Started count=1 msg=Started container task
0.2333,Event,ADDED,eval-conflicts-rho010-r9-019.18d4675eddbbfa51,reason=SuccessfulCreate count=1 msg=Created pod: eval-conflicts-rho010-r9-019-j8tn5
0.2335,Event,ADDED,eval-conflicts-rho010-r9-019.18d467640cb82098,reason=Completed count=1 msg=Job completed
0.2337,Event,ADDED,eval-conflicts-rho010-r9-020-rks54.18d4675f193ed087,"reason=FailedScheduling count=None msg=0/6 nodes are available: 6 node(s) had untolerated taint(s). no new claims to deallocate, preemption: 0/6 nodes are available: 6 Preemption is not helpful for scheduling."
0.2339,Event,ADDED,eval-conflicts-rho010-r9-020-rks54.18d467607471f44d,reason=Scheduled count=None msg=Successfully assigned compute/eval-conflicts-rho010-r9-020-rks54 to kind-worker
0.2341,Event,ADDED,eval-conflicts-rho010-r9-020-rks54.18d46760903a8181,"reason=Pulled count=1 msg=Container image ""busybox:musl"" already present on machine"
0.2343,Event,ADDED,eval-conflicts-rho010-r9-020-rks54.18d46760950d4516,reason=Created count=1 msg=Created container: task
0.2344,Event,ADDED,eval-conflicts-rho010-r9-020-rks54.18d467609c682599,reason=Started count=1 msg=Started container task
0.2346,Event,ADDED,eval-conflicts-rho010-r9-020.18d4675f19305056,reason=SuccessfulCreate count=1 msg=Created pod: eval-conflicts-rho010-r9-020-rks54
0.2348,Event,ADDED,eval-conflicts-rho010-r9-020.18d467638c658375,reason=Completed count=1 msg=Job completed
0.2349,Event,ADDED,eval-conflicts-rho010-r9-021-sx6ds.18d4675f55266153,"reason=FailedScheduling count=None msg=0/6 nodes are available: 6 node(s) had untolerated taint(s). no new claims to deallocate, preemption: 0/6 nodes are available: 6 Preemption is not helpful for scheduling."
0.2351,Event,ADDED,eval-conflicts-rho010-r9-021-sx6ds.18d46760749f1a80,reason=Scheduled count=None msg=Successfully assigned compute/eval-conflicts-rho010-r9-021-sx6ds to kind-worker
0.2353,Event,ADDED,eval-conflicts-rho010-r9-021-sx6ds.18d467609147998d,"reason=Pulled count=1 msg=Container image ""busybox:musl"" already present on machine"
0.2374,Event,ADDED,eval-conflicts-rho010-r9-021-sx6ds.18d4676095cafb49,reason=Created count=1 msg=Created container: task
0.2375,Event,ADDED,eval-conflicts-rho010-r9-021-sx6ds.18d467609c68d9d9,reason=Started count=1 msg=Started container task
0.2377,Event,ADDED,eval-conflicts-rho010-r9-021.18d4675f551d2757,reason=SuccessfulCreate count=1 msg=Created pod: eval-conflicts-rho010-r9-021-sx6ds
0.2379,Event,ADDED,eval-conflicts-rho010-r9-021.18d467638be96e57,reason=Completed count=1 msg=Job completed
0.238,Event,ADDED,eval-conflicts-rho010-r9-022-t4vjw.18d4675f913884ad,"reason=FailedScheduling count=None msg=0/6 nodes are available: 6 node(s) had untolerated taint(s). no new claims to deallocate, preemption: 0/6 nodes are available: 6 Preemption is not helpful for scheduling."
0.2382,Event,ADDED,eval-conflicts-rho010-r9-022-t4vjw.18d4676074ee5c82,reason=Scheduled count=None msg=Successfully assigned compute/eval-conflicts-rho010-r9-022-t4vjw to kind-worker
0.2386,Event,ADDED,eval-conflicts-rho010-r9-022-t4vjw.18d4676090d888c7,"reason=Pulled count=1 msg=Container image ""busybox:musl"" already present on machine"
0.2387,Event,ADDED,eval-conflicts-rho010-r9-022-t4vjw.18d4676095afe787,reason=Created count=1 msg=Created container: task
0.2389,Event,ADDED,eval-conflicts-rho010-r9-022-t4vjw.18d467609c647c04,reason=Started count=1 msg=Started container task
0.2393,Event,ADDED,eval-conflicts-rho010-r9-022.18d4675f912f7e24,reason=SuccessfulCreate count=1 msg=Created pod: eval-conflicts-rho010-r9-022-t4vjw
0.2394,Event,ADDED,eval-conflicts-rho010-r9-022.18d467638aab02b0,reason=Completed count=1 msg=Job completed
0.2396,Event,ADDED,eval-conflicts-rho010-r9-023-vlntw.18d4675fcc3770c9,"reason=FailedScheduling count=None msg=0/6 nodes are available: 6 node(s) had untolerated taint(s). no new claims to deallocate, preemption: 0/6 nodes are available: 6 Preemption is not helpful for scheduling."
0.2397,Event,ADDED,eval-conflicts-rho010-r9-023-vlntw.18d4676078251697,reason=Scheduled count=None msg=Successfully assigned compute/eval-conflicts-rho010-r9-023-vlntw to kind-worker
0.2401,Event,ADDED,eval-conflicts-rho010-r9-023-vlntw.18d467609229f314,"reason=Pulled count=1 msg=Container image ""busybox:musl"" already present on machine"
0.2402,Event,ADDED,eval-conflicts-rho010-r9-023-vlntw.18d46760960bddd5,reason=Created count=1 msg=Created container: task
0.2404,Event,ADDED,eval-conflicts-rho010-r9-023-vlntw.18d467609c656317,reason=Started count=1 msg=Started container task
0.2406,Event,ADDED,eval-conflicts-rho010-r9-023.18d4675fcc2a084e,reason=SuccessfulCreate count=1 msg=Created pod: eval-conflicts-rho010-r9-023-vlntw
0.2408,Event,ADDED,eval-conflicts-rho010-r9-023.18d467640c78cd2f,reason=Completed count=1 msg=Job completed
0.241,Event,ADDED,eval-conflicts-rho010-r9-024-dkpsm.18d4676007f34f1c,"reason=FailedScheduling count=None msg=0/6 nodes are available: 6 node(s) had untolerated taint(s). no new claims to deallocate, preemption: 0/6 nodes are available: 6 Preemption is not helpful for scheduling."
0.2411,Event,ADDED,eval-conflicts-rho010-r9-024-dkpsm.18d46760799420d4,reason=Scheduled count=None msg=Successfully assigned compute/eval-conflicts-rho010-r9-024-dkpsm to kind-worker
0.2413,Event,ADDED,eval-conflicts-rho010-r9-024-dkpsm.18d4676097a87fea,"reason=Pulled count=1 msg=Container image ""busybox:musl"" already present on machine"
0.2415,Event,ADDED,eval-conflicts-rho010-r9-024-dkpsm.18d4676098e601f4,reason=Created count=1 msg=Created container: task
0.2417,Event,ADDED,eval-conflicts-rho010-r9-024-dkpsm.18d467609d83cb0d,reason=Started count=1 msg=Started container task
0.2418,Event,ADDED,eval-conflicts-rho010-r9-024.18d4676007e72717,reason=SuccessfulCreate count=1 msg=Created pod: eval-conflicts-rho010-r9-024-dkpsm
0.242,Event,ADDED,eval-conflicts-rho010-r9-024.18d467640464c431,reason=Completed count=1 msg=Job completed
0.2422,Event,ADDED,eval-conflicts-rho010-r9-025-dtp6r.18d4676043c7547e,"reason=FailedScheduling count=None msg=0/6 nodes are available: 6 node(s) had untolerated taint(s). no new claims to deallocate, preemption: 0/6 nodes are available: 6 Preemption is not helpful for scheduling."
0.2423,Event,ADDED,eval-conflicts-rho010-r9-025-dtp6r.18d4676079c6e016,reason=Scheduled count=None msg=Successfully assigned compute/eval-conflicts-rho010-r9-025-dtp6r to kind-worker
0.2425,Event,ADDED,eval-conflicts-rho010-r9-025-dtp6r.18d46760966c9379,"reason=Pulled count=1 msg=Container image ""busybox:musl"" already present on machine"
0.2427,Event,ADDED,eval-conflicts-rho010-r9-025-dtp6r.18d46760981da9a3,reason=Created count=1 msg=Created container: task
0.2428,Event,ADDED,eval-conflicts-rho010-r9-025-dtp6r.18d467609d81dd81,reason=Started count=1 msg=Started container task
0.243,Event,ADDED,eval-conflicts-rho010-r9-025.18d4676043bf0b0b,reason=SuccessfulCreate count=1 msg=Created pod: eval-conflicts-rho010-r9-025-dtp6r
0.2432,Event,ADDED,eval-conflicts-rho010-r9-025.18d467638b45b823,reason=Completed count=1 msg=Job completed
0.2433,Event,ADDED,eval-conflicts-rho010-r9-026-jjgzq.18d46760845053be,reason=Scheduled count=None msg=Successfully assigned compute/eval-conflicts-rho010-r9-026-jjgzq to kind-worker
0.2435,Event,ADDED,eval-conflicts-rho010-r9-026-jjgzq.18d46760a1e01068,"reason=Pulled count=1 msg=Container image ""busybox:musl"" already present on machine"
0.2437,Event,ADDED,eval-conflicts-rho010-r9-026-jjgzq.18d46760a30c1589,reason=Created count=1 msg=Created container: task
0.2438,Event,ADDED,eval-conflicts-rho010-r9-026-jjgzq.18d46760a724af32,reason=Started count=1 msg=Started container task
0.244,Event,ADDED,eval-conflicts-rho010-r9-026.18d467607f7c4a9a,reason=SuccessfulCreate count=1 msg=Created pod: eval-conflicts-rho010-r9-026-jjgzq
0.2442,Event,ADDED,eval-conflicts-rho010-r9-026.18d4676415c3fd29,reason=Completed count=1 msg=Job completed
0.2443,Event,ADDED,eval-conflicts-rho010-r9-027-99btz.18d46760bbb23931,reason=Scheduled count=None msg=Successfully assigned compute/eval-conflicts-rho010-r9-027-99btz to kind-worker2
0.2445,Event,ADDED,eval-conflicts-rho010-r9-027-99btz.18d46760d460f103,"reason=Pulled count=1 msg=Container image ""busybox:musl"" already present on machine"
0.2447,Event,ADDED,eval-conflicts-rho010-r9-027-99btz.18d46760d5781b5e,reason=Created count=1 msg=Created container: task
0.2448,Event,ADDED,eval-conflicts-rho010-r9-027-99btz.18d46760d7389e58,reason=Started count=1 msg=Started container task
0.245,Event,ADDED,eval-conflicts-rho010-r9-027.18d46760ba85bae2,reason=SuccessfulCreate count=1 msg=Created pod: eval-conflicts-rho010-r9-027-99btz
0.2452,Event,ADDED,eval-conflicts-rho010-r9-027.18d46763ff1c12c8,reason=Completed count=1 msg=Job completed
0.2453,Event,ADDED,eval-conflicts-rho010-r9-028-6vvhh.18d46760f7b3572d,reason=Scheduled count=None msg=Successfully assigned compute/eval-conflicts-rho010-r9-028-6vvhh to kind-worker2
0.2455,Event,ADDED,eval-conflicts-rho010-r9-028-6vvhh.18d467611031d9fb,"reason=Pulled count=1 msg=Container image ""busybox:musl"" already present on machine"
0.2456,Event,ADDED,eval-conflicts-rho010-r9-028-6vvhh.18d46761113b0249,reason=Created count=1 msg=Created container: task
0.2458,Event,ADDED,eval-conflicts-rho010-r9-028-6vvhh.18d467611329c861,reason=Started count=1 msg=Started container task
0.246,Event,ADDED,eval-conflicts-rho010-r9-028.18d46760f6a60d9f,reason=SuccessfulCreate count=1 msg=Created pod: eval-conflicts-rho010-r9-028-6vvhh
0.2461,Event,ADDED,eval-conflicts-rho010-r9-028.18d467643b369c2a,reason=Completed count=1 msg=Job completed
0.2464,Event,ADDED,eval-conflicts-rho010-r9-029-mt4vx.18d467613387c4fb,reason=Scheduled count=None msg=Successfully assigned compute/eval-conflicts-rho010-r9-029-mt4vx to kind-worker5
0.2466,Event,ADDED,eval-conflicts-rho010-r9-029-mt4vx.18d467614c1a129b,"reason=Pulled count=1 msg=Container image ""busybox:musl"" already present on machine"
0.2467,Event,ADDED,eval-conflicts-rho010-r9-029-mt4vx.18d467614d36731f,reason=Created count=1 msg=Created container: task
0.2469,Event,ADDED,eval-conflicts-rho010-r9-029-mt4vx.18d467614f180b88,reason=Started count=1 msg=Started container task
0.2471,Event,ADDED,eval-conflicts-rho010-r9-029.18d46761327e2c29,reason=SuccessfulCreate count=1 msg=Created pod: eval-conflicts-rho010-r9-029-mt4vx
0.2472,Event,ADDED,eval-conflicts-rho010-r9-029.18d46764881ffb48,reason=Completed count=1 msg=Job completed
0.2474,Event,ADDED,eval-conflicts-rho010-r9-030-bbkng.18d467616ea1d793,reason=Scheduled count=None msg=Successfully assigned compute/eval-conflicts-rho010-r9-030-bbkng to kind-worker5
0.2476,Event,ADDED,eval-conflicts-rho010-r9-030-bbkng.18d4676187024e48,"reason=Pulled count=1 msg=Container image ""busybox:musl"" already present on machine"
0.2477,Event,ADDED,eval-conflicts-rho010-r9-030-bbkng.18d46761881ce0e3,reason=Created count=1 msg=Created container: task
0.2479,Event,ADDED,eval-conflicts-rho010-r9-030-bbkng.18d467618a219cda,reason=Started count=1 msg=Started container task
0.2481,Event,ADDED,eval-conflicts-rho010-r9-030.18d467616d5eab62,reason=SuccessfulCreate count=1 msg=Created pod: eval-conflicts-rho010-r9-030-bbkng
0.2482,Event,ADDED,eval-conflicts-rho010-r9-030.18d46764bee152d6,reason=Completed count=1 msg=Job completed
0.2484,Event,ADDED,eval-conflicts-rho010-r9-031-4rqtm.18d46761aab4fa0f,reason=Scheduled count=None msg=Successfully assigned compute/eval-conflicts-rho010-r9-031-4rqtm to kind-worker5
0.2485,Event,ADDED,eval-conflicts-rho010-r9-031-4rqtm.18d46761c3d1b8d9,"reason=Pulled count=1 msg=Container image ""busybox:musl"" already present on machine"
0.2488,Event,ADDED,eval-conflicts-rho010-r9-031-4rqtm.18d46761c4eca832,reason=Created count=1 msg=Created container: task
0.249,Event,ADDED,eval-conflicts-rho010-r9-031-4rqtm.18d46761c6f327f0,reason=Started count=1 msg=Started container task
0.2491,Event,ADDED,eval-conflicts-rho010-r9-031.18d46761a96388a7,reason=SuccessfulCreate count=1 msg=Created pod: eval-conflicts-rho010-r9-031-4rqtm
0.2493,Event,ADDED,eval-conflicts-rho010-r9-031.18d46764faceb3c3,reason=Completed count=1 msg=Job completed
0.2495,Event,ADDED,eval-conflicts-rho010-r9-032-7zqdd.18d46761e5c5075d,reason=Scheduled count=None msg=Successfully assigned compute/eval-conflicts-rho010-r9-032-7zqdd to kind-worker2
0.2496,Event,ADDED,eval-conflicts-rho010-r9-032-7zqdd.18d46761ff1e6fae,"reason=Pulled count=1 msg=Container image ""busybox:musl"" already present on machine"
0.2498,Event,ADDED,eval-conflicts-rho010-r9-032-7zqdd.18d46762003f3e22,reason=Created count=1 msg=Created container: task
0.25,Event,ADDED,eval-conflicts-rho010-r9-032-7zqdd.18d4676202510ebd,reason=Started count=1 msg=Started container task
0.2501,Event,ADDED,eval-conflicts-rho010-r9-032.18d46761e4aa1e8a,reason=SuccessfulCreate count=1 msg=Created pod: eval-conflicts-rho010-r9-032-7zqdd
0.2503,Event,ADDED,eval-conflicts-rho010-r9-032.18d4676529faa853,reason=Completed count=1 msg=Job completed
0.2505,Event,ADDED,eval-conflicts-rho010-r9-033-6lmsd.18d467622160a37b,reason=Scheduled count=None msg=Successfully assigned compute/eval-conflicts-rho010-r9-033-6lmsd to kind-worker5
0.2506,Event,ADDED,eval-conflicts-rho010-r9-033-6lmsd.18d467623b905dd4,"reason=Pulled count=1 msg=Container image ""busybox:musl"" already present on machine"
0.2508,Event,ADDED,eval-conflicts-rho010-r9-033-6lmsd.18d467623caa05e1,reason=Created count=1 msg=Created container: task
0.251,Event,ADDED,eval-conflicts-rho010-r9-033-6lmsd.18d467623ece368a,reason=Started count=1 msg=Started container task
0.2511,Event,ADDED,eval-conflicts-rho010-r9-033.18d4676220335b6b,reason=SuccessfulCreate count=1 msg=Created pod: eval-conflicts-rho010-r9-033-6lmsd
0.2513,Event,ADDED,eval-conflicts-rho010-r9-033.18d4676571eb3050,reason=Completed count=1 msg=Job completed
0.2514,Event,ADDED,eval-conflicts-rho010-r9-034-cn922.18d467625cf166a3,reason=Scheduled count=None msg=Successfully assigned compute/eval-conflicts-rho010-r9-034-cn922 to kind-worker2
0.2516,Event,ADDED,eval-conflicts-rho010-r9-034-cn922.18d4676276beb872,"reason=Pulled count=1 msg=Container image ""busybox:musl"" already present on machine"
0.2518,Event,ADDED,eval-conflicts-rho010-r9-034-cn922.18d4676277eb5e10,reason=Created count=1 msg=Created container: task
0.2519,Event,ADDED,eval-conflicts-rho010-r9-034-cn922.18d467627a0a8569,reason=Started count=1 msg=Started container task
0.2521,Event,ADDED,eval-conflicts-rho010-r9-034.18d467625bd3b8ce,reason=SuccessfulCreate count=1 msg=Created pod: eval-conflicts-rho010-r9-034-cn922
0.2523,Event,ADDED,eval-conflicts-rho010-r9-034.18d46765a1d2c932,reason=Completed count=1 msg=Job completed
0.2524,Event,ADDED,eval-conflicts-rho010-r9-035-p8xcv.18d467629913db01,reason=Scheduled count=None msg=Successfully assigned compute/eval-conflicts-rho010-r9-035-p8xcv to kind-worker2
0.2526,Event,ADDED,eval-conflicts-rho010-r9-035-p8xcv.18d46762b3c2e352,"reason=Pulled count=1 msg=Container image ""busybox:musl"" already present on machine"
0.2527,Event,ADDED,eval-conflicts-rho010-r9-035-p8xcv.18d46762b4f9a6c3,reason=Created count=1 msg=Created container: task
0.2529,Event,ADDED,eval-conflicts-rho010-r9-035-p8xcv.18d46762b94f0c00,reason=Started count=1 msg=Started container task
0.2531,Event,ADDED,eval-conflicts-rho010-r9-035.18d4676297d36126,reason=SuccessfulCreate count=1 msg=Created pod: eval-conflicts-rho010-r9-035-p8xcv
0.2533,Event,ADDED,eval-conflicts-rho010-r9-035.18d46765dd974609,reason=Completed count=1 msg=Job completed
0.2535,Event,ADDED,eval-conflicts-rho010-r9-036-7mstw.18d46762d4906862,reason=Scheduled count=None msg=Successfully assigned compute/eval-conflicts-rho010-r9-036-7mstw to kind-worker5
0.2537,Event,ADDED,eval-conflicts-rho010-r9-036-7mstw.18d46762ee4416f9,"reason=Pulled count=1 msg=Container image ""busybox:musl"" already present on machine"
0.2538,Event,ADDED,eval-conflicts-rho010-r9-036-7mstw.18d46762efa96644,reason=Created count=1 msg=Created container: task
0.254,Event,ADDED,eval-conflicts-rho010-r9-036-7mstw.18d46762f63434f5,reason=Started count=1 msg=Started container task
0.2542,Event,ADDED,eval-conflicts-rho010-r9-036.18d46762d3b09bde,reason=SuccessfulCreate count=1 msg=Created pod: eval-conflicts-rho010-r9-036-7mstw
0.2543,Event,ADDED,eval-conflicts-rho010-r9-036.18d46766262a659f,reason=Completed count=1 msg=Job completed
0.2545,Event,ADDED,eval-conflicts-rho010-r9-037-s498b.18d467630f4ca2d5,reason=Scheduled count=None msg=Successfully assigned compute/eval-conflicts-rho010-r9-037-s498b to kind-worker4
0.2546,Event,ADDED,eval-conflicts-rho010-r9-037-s498b.18d467632c9530e0,"reason=Pulled count=1 msg=Container image ""busybox:musl"" already present on machine"
0.2548,Event,ADDED,eval-conflicts-rho010-r9-037-s498b.18d467632dd32f55,reason=Created count=1 msg=Created container: task
0.255,Event,ADDED,eval-conflicts-rho010-r9-037-s498b.18d4676336207eef,reason=Started count=1 msg=Started container task
0.2552,Event,ADDED,eval-conflicts-rho010-r9-037.18d467630ea58bdc,reason=SuccessfulCreate count=1 msg=Created pod: eval-conflicts-rho010-r9-037-s498b
0.2553,Event,ADDED,eval-conflicts-rho010-r9-037.18d46766676ee89e,reason=Completed count=1 msg=Job completed
0.2555,Event,ADDED,eval-conflicts-rho010-r9-038-bnnxq.18d467634b65c271,reason=Scheduled count=None msg=Successfully assigned compute/eval-conflicts-rho010-r9-038-bnnxq to kind-worker4
0.2556,Event,ADDED,eval-conflicts-rho010-r9-038-bnnxq.18d4676364cba0cb,"reason=Pulled count=1 msg=Container image ""busybox:musl"" already present on machine"
0.2558,Event,ADDED,eval-conflicts-rho010-r9-038-bnnxq.18d4676365ea435f,reason=Created count=1 msg=Created container: task
0.256,Event,ADDED,eval-conflicts-rho010-r9-038-bnnxq.18d467636a004da0,reason=Started count=1 msg=Started container task
0.2561,Event,ADDED,eval-conflicts-rho010-r9-038.18d467634a4b367b,reason=SuccessfulCreate count=1 msg=Created pod: eval-conflicts-rho010-r9-038-bnnxq
0.2563,Event,ADDED,eval-conflicts-rho010-r9-038.18d46766a315c387,reason=Completed count=1 msg=Job completed
0.2564,Event,ADDED,eval-conflicts-rho010-r9-039-pfp2q.18d4676388426cab,reason=Scheduled count=None msg=Successfully assigned compute/eval-conflicts-rho010-r9-039-pfp2q to kind-worker4
0.2566,Event,ADDED,eval-conflicts-rho010-r9-039-pfp2q.18d46763a2afdcbb,"reason=Pulled count=1 msg=Container image ""busybox:musl"" already present on machine"
0.2568,Event,ADDED,eval-conflicts-rho010-r9-039-pfp2q.18d46763a3bccb54,reason=Created count=1 msg=Created container: task
0.2569,Event,ADDED,eval-conflicts-rho010-r9-039-pfp2q.18d46763a9b68858,reason=Started count=1 msg=Started container task
0.2571,Event,ADDED,eval-conflicts-rho010-r9-039.18d46763871af63b,reason=SuccessfulCreate count=1 msg=Created pod: eval-conflicts-rho010-r9-039-pfp2q
0.2573,Event,ADDED,eval-conflicts-rho010-r9-039.18d46766df404d17,reason=Completed count=1 msg=Job completed
0.2574,Event,ADDED,eval-conflicts-rho010-r9-040-7bkjc.18d46763c1df0e6d,reason=Scheduled count=None msg=Successfully assigned compute/eval-conflicts-rho010-r9-040-7bkjc to kind-worker3
0.2576,Event,ADDED,eval-conflicts-rho010-r9-040-7bkjc.18d46763dbd438d6,"reason=Pulled count=1 msg=Container image ""busybox:musl"" already present on machine"
0.2578,Event,ADDED,eval-conflicts-rho010-r9-040-7bkjc.18d46763dcfa2d5d,reason=Created count=1 msg=Created container: task
0.2579,Event,ADDED,eval-conflicts-rho010-r9-040-7bkjc.18d46763e64305cf,reason=Started count=1 msg=Started container task
0.2581,Event,ADDED,eval-conflicts-rho010-r9-040.18d46763c1649ce6,reason=SuccessfulCreate count=1 msg=Created pod: eval-conflicts-rho010-r9-040-7bkjc
0.2582,Event,ADDED,eval-conflicts-rho010-r9-040.18d46766f0fb06f6,reason=Completed count=1 msg=Job completed
0.2585,Event,ADDED,eval-conflicts-rho010-r9-041-9tbjx.18d46763fe6af148,reason=Scheduled count=None msg=Successfully assigned compute/eval-conflicts-rho010-r9-041-9tbjx to kind-worker4
0.2586,Event,ADDED,eval-conflicts-rho010-r9-041-9tbjx.18d4676417b14214,"reason=Pulled count=1 msg=Container image ""busybox:musl"" already present on machine"
0.2588,Event,ADDED,eval-conflicts-rho010-r9-041-9tbjx.18d4676418bdb6df,reason=Created count=1 msg=Created container: task
0.2591,Event,ADDED,eval-conflicts-rho010-r9-041-9tbjx.18d467641ac07f4d,reason=Started count=1 msg=Started container task
0.2593,Event,ADDED,eval-conflicts-rho010-r9-041.18d46763fd885be5,reason=SuccessfulCreate count=1 msg=Created pod: eval-conflicts-rho010-r9-041-9tbjx
0.2594,Event,ADDED,eval-conflicts-rho010-r9-041.18d4676756b2da58,reason=Completed count=1 msg=Job completed
0.2596,Event,ADDED,eval-conflicts-rho010-r9-042-5cmxd.18d4676439f75ba8,reason=Scheduled count=None msg=Successfully assigned compute/eval-conflicts-rho010-r9-042-5cmxd to kind-worker3
0.2598,Event,ADDED,eval-conflicts-rho010-r9-042-5cmxd.18d467645351d7d0,"reason=Pulled count=1 msg=Container image ""busybox:musl"" already present on machine"
0.26,Event,ADDED,eval-conflicts-rho010-r9-042-5cmxd.18d46764545c3d3b,reason=Created count=1 msg=Created container: task
0.2602,Event,ADDED,eval-conflicts-rho010-r9-042-5cmxd.18d467645641896e,reason=Started count=1 msg=Started container task
0.2603,Event,ADDED,eval-conflicts-rho010-r9-042.18d467643903e270,reason=SuccessfulCreate count=1 msg=Created pod: eval-conflicts-rho010-r9-042-5cmxd
0.2605,Event,ADDED,eval-conflicts-rho010-r9-042.18d4676768702238,reason=Completed count=1 msg=Job completed
0.2607,Event,ADDED,eval-conflicts-rho010-r9-043-z4z2q.18d46764753e7996,"reason=FailedScheduling count=None msg=0/6 nodes are available: 2 c_wall violated: 1 conflicting context pair(s) with node memory, 4 node(s) had untolerated taint(s). no new claims to deallocate, preemption: 0/6 nodes are available: 2 No preemption victims found for incoming pod, 4 Preemption is not helpful for scheduling."
0.2609,Event,ADDED,eval-conflicts-rho010-r9-043-z4z2q.18d46764760dac8a,"reason=FailedScheduling count=None msg=0/6 nodes are available: 2 c_wall violated: 1 conflicting context pair(s) with node memory, 4 node(s) had untolerated taint(s). no new claims to deallocate, preemption: 0/6 nodes are available: 2 No preemption victims found for incoming pod, 4 Preemption is not helpful for scheduling."
0.2611,Event,ADDED,eval-conflicts-rho010-r9-043-z4z2q.18d4676533fa3d9e,reason=Scheduled count=None msg=Successfully assigned compute/eval-conflicts-rho010-r9-043-z4z2q to kind-worker
0.2613,Event,ADDED,eval-conflicts-rho010-r9-043-z4z2q.18d467654dc35ab4,"reason=Pulled count=1 msg=Container image ""busybox:musl"" already present on machine"
0.2614,Event,ADDED,eval-conflicts-rho010-r9-043-z4z2q.18d467654ed07bb6,reason=Created count=1 msg=Created container: task
0.2616,Event,ADDED,eval-conflicts-rho010-r9-043-z4z2q.18d4676550db8ed8,reason=Started count=1 msg=Started container task
0.2618,Event,ADDED,eval-conflicts-rho010-r9-043.18d4676474d28b32,reason=SuccessfulCreate count=1 msg=Created pod: eval-conflicts-rho010-r9-043-z4z2q
0.2619,Event,ADDED,eval-conflicts-rho010-r9-043.18d46768733c8385,reason=Completed count=1 msg=Job completed
0.2621,Event,ADDED,eval-conflicts-rho010-r9-044-b629j.18d46764b0f45f01,reason=Scheduled count=None msg=Successfully assigned compute/eval-conflicts-rho010-r9-044-b629j to kind-worker4
0.2623,Event,ADDED,eval-conflicts-rho010-r9-044-b629j.18d46764c9c48bbd,"reason=Pulled count=1 msg=Container image ""busybox:musl"" already present on machine"
0.2624,Event,ADDED,eval-conflicts-rho010-r9-044-b629j.18d46764cad06362,reason=Created count=1 msg=Created container: task
0.2626,Event,ADDED,eval-conflicts-rho010-r9-044-b629j.18d46764cec94a3f,reason=Started count=1 msg=Started container task
0.2628,Event,ADDED,eval-conflicts-rho010-r9-044.18d46764b000a0ab,reason=SuccessfulCreate count=1 msg=Created pod: eval-conflicts-rho010-r9-044-b629j
0.2629,Event,ADDED,eval-conflicts-rho010-r9-044.18d467680a07331d,reason=Completed count=1 msg=Job completed
0.2631,Event,ADDED,eval-conflicts-rho010-r9-045-29lzr.18d46764ec4605f3,reason=Scheduled count=None msg=Successfully assigned compute/eval-conflicts-rho010-r9-045-29lzr to kind-worker3
0.2632,Event,ADDED,eval-conflicts-rho010-r9-045-29lzr.18d4676505e57026,"reason=Pulled count=1 msg=Container image ""busybox:musl"" already present on machine"
0.2634,Event,ADDED,eval-conflicts-rho010-r9-045-29lzr.18d4676506fa6312,reason=Created count=1 msg=Created container: task
0.2636,Event,ADDED,eval-conflicts-rho010-r9-045-29lzr.18d467650b8e0c8c,reason=Started count=1 msg=Started container task
0.2637,Event,ADDED,eval-conflicts-rho010-r9-045.18d46764eb8d2b23,reason=SuccessfulCreate count=1 msg=Created pod: eval-conflicts-rho010-r9-045-29lzr
0.2639,Event,ADDED,eval-conflicts-rho010-r9-045.18d467681bc989ff,reason=Completed count=1 msg=Job completed
0.264,Event,ADDED,eval-conflicts-rho010-r9-046-jffnn.18d4676528422b31,reason=Scheduled count=None msg=Successfully assigned compute/eval-conflicts-rho010-r9-046-jffnn to kind-worker3
0.2642,Event,ADDED,eval-conflicts-rho010-r9-046-jffnn.18d46765410771b5,"reason=Pulled count=1 msg=Container image ""busybox:musl"" already present on machine"
0.2644,Event,ADDED,eval-conflicts-rho010-r9-046-jffnn.18d467654229b45e,reason=Created count=1 msg=Created container: task
0.2646,Event,ADDED,eval-conflicts-rho010-r9-046-jffnn.18d46765462e42ca,reason=Started count=1 msg=Started container task
0.2647,Event,ADDED,eval-conflicts-rho010-r9-046.18d46765275cee4a,reason=SuccessfulCreate count=1 msg=Created pod: eval-conflicts-rho010-r9-046-jffnn
0.2649,Event,ADDED,eval-conflicts-rho010-r9-046.18d4676857c16093,reason=Completed count=1 msg=Job completed
0.265,Event,ADDED,eval-conflicts-rho010-r9-047-7287l.18d46765632d7e8e,reason=Scheduled count=None msg=Successfully assigned compute/eval-conflicts-rho010-r9-047-7287l to kind-worker
0.2652,Event,ADDED,eval-conflicts-rho010-r9-047-7287l.18d467657ba9a6e4,"reason=Pulled count=1 msg=Container image ""busybox:musl"" already present on machine"
0.2654,Event,ADDED,eval-conflicts-rho010-r9-047-7287l.18d467657d48ea59,reason=Created count=1 msg=Created container: task
0.2655,Event,ADDED,eval-conflicts-rho010-r9-047-7287l.18d46765811886a8,reason=Started count=1 msg=Started container task
0.2657,Event,ADDED,eval-conflicts-rho010-r9-047.18d4676562a66eb9,reason=SuccessfulCreate count=1 msg=Created pod: eval-conflicts-rho010-r9-047-7287l
0.2659,Event,ADDED,eval-conflicts-rho010-r9-047.18d46768aed6daea,reason=Completed count=1 msg=Job completed
0.266,Event,ADDED,eval-conflicts-rho010-r9-048-4g9rg.18d467659f401313,reason=Scheduled count=None msg=Successfully assigned compute/eval-conflicts-rho010-r9-048-4g9rg to kind-worker
0.2662,Event,ADDED,eval-conflicts-rho010-r9-048-4g9rg.18d46765b8a7b728,"reason=Pulled count=1 msg=Container image ""busybox:musl"" already present on machine"
0.2663,Event,ADDED,eval-conflicts-rho010-r9-048-4g9rg.18d46765b9b47ee8,reason=Created count=1 msg=Created container: task
0.2665,Event,ADDED,eval-conflicts-rho010-r9-048-4g9rg.18d46765bb88c583,reason=Started count=1 msg=Started container task
0.2667,Event,ADDED,eval-conflicts-rho010-r9-048.18d467659eabaa4a,reason=SuccessfulCreate count=1 msg=Created pod: eval-conflicts-rho010-r9-048-4g9rg
0.2668,Event,ADDED,eval-conflicts-rho010-r9-048.18d46768eac6e826,reason=Completed count=1 msg=Job completed
0.267,Event,ADDED,eval-conflicts-rho010-r9-049-hj8cw.18d46765db52daaa,reason=Scheduled count=None msg=Successfully assigned compute/eval-conflicts-rho010-r9-049-hj8cw to kind-worker
0.2671,Event,ADDED,eval-conflicts-rho010-r9-049-hj8cw.18d46765f4944158,"reason=Pulled count=1 msg=Container image ""busybox:musl"" already present on machine"
0.2673,Event,ADDED,eval-conflicts-rho010-r9-049-hj8cw.18d46765f5ab01ad,reason=Created count=1 msg=Created container: task
0.2677,Event,ADDED,eval-conflicts-rho010-r9-049-hj8cw.18d46765f9cb4308,reason=Started count=1 msg=Started container task
0.2679,Event,ADDED,eval-conflicts-rho010-r9-049.18d46765dac55a82,reason=SuccessfulCreate count=1 msg=Created pod: eval-conflicts-rho010-r9-049-hj8cw
0.2681,Event,ADDED,eval-conflicts-rho010-r9-049.18d467692666198f,reason=Completed count=1 msg=Job completed
0.2682,Event,ADDED,eval-conflicts-rho010-r9-050-m86jc.18d4676616d46df3,reason=Scheduled count=None msg=Successfully assigned compute/eval-conflicts-rho010-r9-050-m86jc to kind-worker5
0.2686,Event,ADDED,eval-conflicts-rho010-r9-050-m86jc.18d467662f7be05e,"reason=Pulled count=1 msg=Container image ""busybox:musl"" already present on machine"
0.2688,Event,ADDED,eval-conflicts-rho010-r9-050-m86jc.18d46766308a4c7b,reason=Created count=1 msg=Created container: task
0.269,Event,ADDED,eval-conflicts-rho010-r9-050-m86jc.18d46766326bdac9,reason=Started count=1 msg=Started container task
0.2692,Event,ADDED,eval-conflicts-rho010-r9-050.18d46766164db201,reason=SuccessfulCreate count=1 msg=Created pod: eval-conflicts-rho010-r9-050-m86jc
0.2695,Event,ADDED,eval-conflicts-rho010-r9-050.18d4676969f5b958,reason=Completed count=1 msg=Job completed
0.2696,Event,ADDED,eval-conflicts-rho010-r9-051-8m8sx.18d4676651d5236d,reason=Scheduled count=None msg=Successfully assigned compute/eval-conflicts-rho010-r9-051-8m8sx to kind-worker
0.2698,Event,ADDED,eval-conflicts-rho010-r9-051-8m8sx.18d467666f7042f6,"reason=Pulled count=1 msg=Container image ""busybox:musl"" already present on machine"
0.2701,Event,ADDED,eval-conflicts-rho010-r9-051-8m8sx.18d4676670b03cca,reason=Created count=1 msg=Created container: task
0.2702,Event,ADDED,eval-conflicts-rho010-r9-051-8m8sx.18d4676675388f11,reason=Started count=1 msg=Started container task
0.2705,Event,ADDED,eval-conflicts-rho010-r9-051.18d467665139a83c,reason=SuccessfulCreate count=1 msg=Created pod: eval-conflicts-rho010-r9-051-8m8sx
0.2707,Event,ADDED,eval-conflicts-rho010-r9-051.18d467699e26d0e0,reason=Completed count=1 msg=Job completed
0.2708,Event,ADDED,eval-conflicts-rho010-r9-052-2lrng.18d467668df9a65e,reason=Scheduled count=None msg=Successfully assigned compute/eval-conflicts-rho010-r9-052-2lrng to kind-worker5
0.271,Event,ADDED,eval-conflicts-rho010-r9-052-2lrng.18d46766a7e68932,"reason=Pulled count=1 msg=Container image ""busybox:musl"" already present on machine"
0.2712,Event,ADDED,eval-conflicts-rho010-r9-052-2lrng.18d46766a90ac149,reason=Created count=1 msg=Created container: task
0.2713,Event,ADDED,eval-conflicts-rho010-r9-052-2lrng.18d46766aaf99f15,reason=Started count=1 msg=Started container task
0.2715,Event,ADDED,eval-conflicts-rho010-r9-052.18d467668cb8805c,reason=SuccessfulCreate count=1 msg=Created pod: eval-conflicts-rho010-r9-052-2lrng
0.2717,Event,ADDED,eval-conflicts-rho010-r9-052.18d46769e1974a1c,reason=Completed count=1 msg=Job completed
0.2718,Event,ADDED,eval-conflicts-rho010-r9-053-lzhp7.18d46766c9aa0c98,reason=Scheduled count=None msg=Successfully assigned compute/eval-conflicts-rho010-r9-053-lzhp7 to kind-worker5
0.2721,Event,ADDED,eval-conflicts-rho010-r9-053-lzhp7.18d46766e7a84f94,"reason=Pulled count=1 msg=Container image ""busybox:musl"" already present on machine"
0.2722,Event,ADDED,eval-conflicts-rho010-r9-053-lzhp7.18d46766e8f3fc79,reason=Created count=1 msg=Created container: task
0.2724,Event,ADDED,eval-conflicts-rho010-r9-053-lzhp7.18d46766ec5856e2,reason=Started count=1 msg=Started container task
0.2725,Event,ADDED,eval-conflicts-rho010-r9-053.18d46766c8c47178,reason=SuccessfulCreate count=1 msg=Created pod: eval-conflicts-rho010-r9-053-lzhp7
0.2727,Event,ADDED,eval-conflicts-rho010-r9-053.18d4676a1d7449f2,reason=Completed count=1 msg=Job completed
0.2729,Event,ADDED,eval-conflicts-rho010-r9-054-4r2zn.18d46767048ce951,"reason=FailedScheduling count=None msg=0/6 nodes are available: 2 c_wall violated: 1 conflicting context pair(s) with node memory, 4 node(s) had untolerated taint(s). no new claims to deallocate, preemption: 0/6 nodes are available: 2 No preemption victims found for incoming pod, 4 Preemption is not helpful for scheduling."
0.2731,Event,ADDED,eval-conflicts-rho010-r9-054-4r2zn.18d46767053125e0,"reason=FailedScheduling count=None msg=0/6 nodes are available: 2 c_wall violated: 1 conflicting context pair(s) with node memory, 4 node(s) had untolerated taint(s). no new claims to deallocate, preemption: 0/6 nodes are available: 2 No preemption victims found for incoming pod, 4 Preemption is not helpful for scheduling."
0.2733,Event,ADDED,eval-conflicts-rho010-r9-054-4r2zn.18d467678d30fd83,"reason=FailedScheduling count=None msg=0/6 nodes are available: 1 c_wall violated: 1 conflicting context pair(s) with node memory, 5 node(s) had untolerated taint(s). no new claims to deallocate, preemption: 0/6 nodes are available: 1 No preemption victims found for incoming pod, 5 Preemption is not helpful for scheduling."
0.2734,Event,ADDED,eval-conflicts-rho010-r9-054-4r2zn.18d46767b7f97228,reason=Scheduled count=None msg=Successfully assigned compute/eval-conflicts-rho010-r9-054-4r2zn to kind-worker4
0.2736,Event,ADDED,eval-conflicts-rho010-r9-054-4r2zn.18d46767d337fc94,"reason=Pulled count=1 msg=Container image ""busybox:musl"" already present on machine"
0.2739,Event,ADDED,eval-conflicts-rho010-r9-054-4r2zn.18d46767d444c491,reason=Created count=1 msg=Created container: task
0.274,Event,ADDED,eval-conflicts-rho010-r9-054-4r2zn.18d46767dccddd21,reason=Started count=1 msg=Started container task
0.2742,Event,ADDED,eval-conflicts-rho010-r9-054.18d467670419f3c2,reason=SuccessfulCreate count=1 msg=Created pod: eval-conflicts-rho010-r9-054-4r2zn
0.2744,Event,ADDED,eval-conflicts-rho010-r9-054.18d4676b13144914,reason=Completed count=1 msg=Job completed
0.2746,Event,ADDED,eval-conflicts-rho010-r9-055-5jm6b.18d467674084a4b3,reason=Scheduled count=None msg=Successfully assigned compute/eval-conflicts-rho010-r9-055-5jm6b to kind-worker5
0.2748,Event,ADDED,eval-conflicts-rho010-r9-055-5jm6b.18d467675a7b0c2b,"reason=Pulled count=1 msg=Container image ""busybox:musl"" already present on machine"
0.275,Event,ADDED,eval-conflicts-rho010-r9-055-5jm6b.18d467675b902181,reason=Created count=1 msg=Created container: task
0.2751,Event,ADDED,eval-conflicts-rho010-r9-055-5jm6b.18d467675daad2e3,reason=Started count=1 msg=Started container task
0.2753,Event,ADDED,eval-conflicts-rho010-r9-055.18d467673fa1f23f,reason=SuccessfulCreate count=1 msg=Created pod: eval-conflicts-rho010-r9-055-5jm6b
0.2755,Event,ADDED,eval-conflicts-rho010-r9-055.18d4676a95173425,reason=Completed count=1 msg=Job completed
0.2757,Event,ADDED,eval-conflicts-rho010-r9-056-p7kwn.18d467677c699da7,reason=Scheduled count=None msg=Successfully assigned compute/eval-conflicts-rho010-r9-056-p7kwn to kind-worker5
0.2758,Event,ADDED,eval-conflicts-rho010-r9-056-p7kwn.18d467679b1de7ee,"reason=Pulled count=1 msg=Container image ""busybox:musl"" already present on machine"
0.276,Event,ADDED,eval-conflicts-rho010-r9-056-p7kwn.18d467679c50ec86,reason=Created count=1 msg=Created container: task
0.2762,Event,ADDED,eval-conflicts-rho010-r9-056-p7kwn.18d46767a15ec3df,reason=Started count=1 msg=Started container task
0.2763,Event,ADDED,eval-conflicts-rho010-r9-056.18d467677b7fb7e8,reason=SuccessfulCreate count=1 msg=Created pod: eval-conflicts-rho010-r9-056-p7kwn
0.2765,Event,ADDED,eval-conflicts-rho010-r9-056.18d4676ad1511abe,reason=Completed count=1 msg=Job completed
0.2767,Event,ADDED,eval-conflicts-rho010-r9-057-xgpnp.18d46767b817fd12,reason=Scheduled count=None msg=Successfully assigned compute/eval-conflicts-rho010-r9-057-xgpnp to kind-worker4
0.2768,Event,ADDED,eval-conflicts-rho010-r9-057-xgpnp.18d46767d53b79ab,"reason=Pulled count=1 msg=Container image ""busybox:musl"" already present on machine"
0.277,Event,ADDED,eval-conflicts-rho010-r9-057-xgpnp.18d46767d66f82e5,reason=Created count=1 msg=Created container: task
0.2772,Event,ADDED,eval-conflicts-rho010-r9-057-xgpnp.18d46767dd332eac,reason=Started count=1 msg=Started container task
0.2773,Event,ADDED,eval-conflicts-rho010-r9-057.18d46767b70bdf4b,reason=SuccessfulCreate count=1 msg=Created pod: eval-conflicts-rho010-r9-057-xgpnp
0.2775,Event,ADDED,eval-conflicts-rho010-r9-057.18d4676b12f4dfaa,reason=Completed count=1 msg=Job completed
0.2777,Event,ADDED,eval-conflicts-rho010-r9-058-svnsq.18d46767f374c774,reason=Scheduled count=None msg=Successfully assigned compute/eval-conflicts-rho010-r9-058-svnsq to kind-worker2
0.2778,Event,ADDED,eval-conflicts-rho010-r9-058-svnsq.18d467680bf6efa8,"reason=Pulled count=1 msg=Container image ""busybox:musl"" already present on machine"
0.278,Event,ADDED,eval-conflicts-rho010-r9-058-svnsq.18d467680cfc4e83,reason=Created count=1 msg=Created container: task
0.2782,Event,ADDED,eval-conflicts-rho010-r9-058-svnsq.18d467680ecb67ca,reason=Started count=1 msg=Started container task
0.2785,Event,ADDED,eval-conflicts-rho010-r9-058.18d46767f284bb90,reason=SuccessfulCreate count=1 msg=Created pod: eval-conflicts-rho010-r9-058-svnsq
0.2787,Event,ADDED,eval-conflicts-rho010-r9-058.18d4676b3bd0d79b,reason=Completed count=1 msg=Job completed
0.2788,Event,ADDED,eval-conflicts-rho010-r9-059-jsks2.18d467682f408f80,reason=Scheduled count=None msg=Successfully assigned compute/eval-conflicts-rho010-r9-059-jsks2 to kind-worker2
0.279,Event,ADDED,eval-conflicts-rho010-r9-059-jsks2.18d4676847e75d1a,"reason=Pulled count=1 msg=Container image ""busybox:musl"" already present on machine"
0.2792,Event,ADDED,eval-conflicts-rho010-r9-059-jsks2.18d4676848f80dcd,reason=Created count=1 msg=Created container: task
0.2793,Event,ADDED,eval-conflicts-rho010-r9-059-jsks2.18d467684adcc7b2,reason=Started count=1 msg=Started container task
0.2795,Event,ADDED,eval-conflicts-rho010-r9-059.18d467682dedc4a7,reason=SuccessfulCreate count=1 msg=Created pod: eval-conflicts-rho010-r9-059-jsks2
0.2797,Event,ADDED,eval-conflicts-rho010-r9-059.18d4676b77910dcf,reason=Completed count=1 msg=Job completed
0.2798,Event,ADDED,eval-conflicts-rho010-r9-060-jt4hp.18d467686add633f,reason=Scheduled count=None msg=Successfully assigned compute/eval-conflicts-rho010-r9-060-jt4hp to kind-worker2
0.28,Event,ADDED,eval-conflicts-rho010-r9-060-jt4hp.18d4676883b1377e,"reason=Pulled count=1 msg=Container image ""busybox:musl"" already present on machine"
0.2802,Event,ADDED,eval-conflicts-rho010-r9-060-jt4hp.18d4676884c6f7fb,reason=Created count=1 msg=Created container: task
0.2803,Event,ADDED,eval-conflicts-rho010-r9-060-jt4hp.18d4676886dd9bea,reason=Started count=1 msg=Started container task
0.2805,Event,ADDED,eval-conflicts-rho010-r9-060.18d4676869c748e3,reason=SuccessfulCreate count=1 msg=Created pod: eval-conflicts-rho010-r9-060-jt4hp
0.2807,Event,ADDED,eval-conflicts-rho010-r9-060.18d4676bb39805aa,reason=Completed count=1 msg=Job completed
0.2808,Event,ADDED,eval-conflicts-rho010-r9-061-f9pwv.18d46768a68a3f39,reason=Scheduled count=None msg=Successfully assigned compute/eval-conflicts-rho010-r9-061-f9pwv to kind-worker4
0.281,Event,ADDED,eval-conflicts-rho010-r9-061-f9pwv.18d46768c0620272,"reason=Pulled count=1 msg=Container image ""busybox:musl"" already present on machine"
0.2812,Event,ADDED,eval-conflicts-rho010-r9-061-f9pwv.18d46768c170e44c,reason=Created count=1 msg=Created container: task
0.2813,Event,ADDED,eval-conflicts-rho010-r9-061-f9pwv.18d46768c372fca0,reason=Started count=1 msg=Started container task
0.2815,Event,ADDED,eval-conflicts-rho010-r9-061.18d46768a5afe88c,reason=SuccessfulCreate count=1 msg=Created pod: eval-conflicts-rho010-r9-061-f9pwv
0.2817,Event,ADDED,eval-conflicts-rho010-r9-061.18d4676c024d921c,reason=Completed count=1 msg=Job completed
0.2818,Event,ADDED,eval-conflicts-rho010-r9-062-wg2z7.18d46768e315b0ca,reason=Scheduled count=None msg=Successfully assigned compute/eval-conflicts-rho010-r9-062-wg2z7 to kind-worker2
0.282,Event,ADDED,eval-conflicts-rho010-r9-062-wg2z7.18d46768fcc2ea2b,"reason=Pulled count=1 msg=Container image ""busybox:musl"" already present on machine"
0.2821,Event,ADDED,eval-conflicts-rho010-r9-062-wg2z7.18d46768fdd3bf09,reason=Created count=1 msg=Created container: task
0.2823,Event,ADDED,eval-conflicts-rho010-r9-062-wg2z7.18d46768ffe7ff03,reason=Started count=1 msg=Started container task
0.2825,Event,ADDED,eval-conflicts-rho010-r9-062.18d46768e239ae04,reason=SuccessfulCreate count=1 msg=Created pod: eval-conflicts-rho010-r9-062-wg2z7
0.2827,Event,ADDED,eval-conflicts-rho010-r9-062.18d4676c2b2fd1c5,reason=Completed count=1 msg=Job completed
0.2828,Event,ADDED,eval-conflicts-rho010-r9-063-b8mvn.18d467691d19a1ed,reason=Scheduled count=None msg=Successfully assigned compute/eval-conflicts-rho010-r9-063-b8mvn to kind-worker2
0.283,Event,ADDED,eval-conflicts-rho010-r9-063-b8mvn.18d46769366a76b1,"reason=Pulled count=1 msg=Container image ""busybox:musl"" already present on machine"
0.2832,Event,ADDED,eval-conflicts-rho010-r9-063-b8mvn.18d46769378147a3,reason=Created count=1 msg=Created container: task
0.2833,Event,ADDED,eval-conflicts-rho010-r9-063-b8mvn.18d46769399c822a,reason=Started count=1 msg=Started container task
0.2836,Event,ADDED,eval-conflicts-rho010-r9-063.18d467691c5d435a,reason=SuccessfulCreate count=1 msg=Created pod: eval-conflicts-rho010-r9-063-b8mvn
0.2839,Event,ADDED,eval-conflicts-rho010-r9-063.18d4676c671b1f07,reason=Completed count=1 msg=Job completed
0.2841,Event,ADDED,eval-conflicts-rho010-r9-064-tq482.18d4676959211542,reason=Scheduled count=None msg=Successfully assigned compute/eval-conflicts-rho010-r9-064-tq482 to kind-worker4
0.2843,Event,ADDED,eval-conflicts-rho010-r9-064-tq482.18d4676971d5ebe7,"reason=Pulled count=1 msg=Container image ""busybox:musl"" already present on machine"
0.2844,Event,ADDED,eval-conflicts-rho010-r9-064-tq482.18d4676972fc5f91,reason=Created count=1 msg=Created container: task
0.2847,Event,ADDED,eval-conflicts-rho010-r9-064-tq482.18d4676974f7dea0,reason=Started count=1 msg=Started container task
0.285,Event,ADDED,eval-conflicts-rho010-r9-064.18d467695840ac9a,reason=SuccessfulCreate count=1 msg=Created pod: eval-conflicts-rho010-r9-064-tq482
0.2852,Event,ADDED,eval-conflicts-rho010-r9-064.18d4676cb5a9373f,reason=Completed count=1 msg=Job completed
0.2856,Event,ADDED,eval-conflicts-rho010-r9-065-tzdkq.18d4676994115881,reason=Scheduled count=None msg=Successfully assigned compute/eval-conflicts-rho010-r9-065-tzdkq to kind-worker2
0.2858,Event,ADDED,eval-conflicts-rho010-r9-065-tzdkq.18d46769ad0c23af,"reason=Pulled count=1 msg=Container image ""busybox:musl"" already present on machine"
0.2859,Event,ADDED,eval-conflicts-rho010-r9-065-tzdkq.18d46769ae2aa642,reason=Created count=1 msg=Created container: task
0.2863,Event,ADDED,eval-conflicts-rho010-r9-065-tzdkq.18d46769affdde02,reason=Started count=1 msg=Started container task
0.2865,Event,ADDED,eval-conflicts-rho010-r9-065.18d46769933bfdcb,reason=SuccessfulCreate count=1 msg=Created pod: eval-conflicts-rho010-r9-065-tzdkq
0.2867,Event,ADDED,eval-conflicts-rho010-r9-065.18d4676cdf946fb1,reason=Completed count=1 msg=Job completed
0.2868,Event,ADDED,eval-conflicts-rho010-r9-066-tdl26.18d46769d035df72,reason=Scheduled count=None msg=Successfully assigned compute/eval-conflicts-rho010-r9-066-tdl26 to kind-worker4
0.2871,Event,ADDED,eval-conflicts-rho010-r9-066-tdl26.18d46769e8d614da,"reason=Pulled count=1 msg=Container image ""busybox:musl"" already present on machine"
0.2872,Event,ADDED,eval-conflicts-rho010-r9-066-tdl26.18d46769e9e9957d,reason=Created count=1 msg=Created container: task
0.2875,Event,ADDED,eval-conflicts-rho010-r9-066-tdl26.18d46769ebc7349f,reason=Started count=1 msg=Started container task
0.2877,Event,ADDED,eval-conflicts-rho010-r9-066.18d46769cf3d3fbe,reason=SuccessfulCreate count=1 msg=Created pod: eval-conflicts-rho010-r9-066-tdl26
0.2879,Event,ADDED,eval-conflicts-rho010-r9-066.18d4676d2d267fec,reason=Completed count=1 msg=Job completed
0.288,Event,ADDED,eval-conflicts-rho010-r9-067-m5t4r.18d4676a0bd3c943,reason=Scheduled count=None msg=Successfully assigned compute/eval-conflicts-rho010-r9-067-m5t4r to kind-worker
0.2882,Event,ADDED,eval-conflicts-rho010-r9-067-m5t4r.18d4676a250113bf,"reason=Pulled count=1 msg=Container image ""busybox:musl"" already present on machine"
0.2884,Event,ADDED,eval-conflicts-rho010-r9-067-m5t4r.18d4676a260cace3,reason=Created count=1 msg=Created container: task
0.2885,Event,ADDED,eval-conflicts-rho010-r9-067-m5t4r.18d4676a282aaa1a,reason=Started count=1 msg=Started container task
0.2887,Event,ADDED,eval-conflicts-rho010-r9-067.18d4676a0af3c6bf,reason=SuccessfulCreate count=1 msg=Created pod: eval-conflicts-rho010-r9-067-m5t4r
0.2888,Event,ADDED,eval-conflicts-rho010-r9-067.18d4676d5a5e6701,reason=Completed count=1 msg=Job completed
0.2892,Event,ADDED,eval-conflicts-rho010-r9-068-fxnqg.18d4676a46d5eaad,reason=Scheduled count=None msg=Successfully assigned compute/eval-conflicts-rho010-r9-068-fxnqg to kind-worker3
0.2894,Event,ADDED,eval-conflicts-rho010-r9-068-fxnqg.18d4676a60bf3360,"reason=Pulled count=1 msg=Container image ""busybox:musl"" already present on machine"
0.2896,Event,ADDED,eval-conflicts-rho010-r9-068-fxnqg.18d4676a61d5fce6,reason=Created count=1 msg=Created container: task
0.2902,Event,ADDED,eval-conflicts-rho010-r9-068-fxnqg.18d4676a668dd29c,reason=Started count=1 msg=Started container task
0.2905,Event,ADDED,eval-conflicts-rho010-r9-068.18d4676a46545bde,reason=SuccessfulCreate count=1 msg=Created pod: eval-conflicts-rho010-r9-068-fxnqg
0.2906,Event,ADDED,eval-conflicts-rho010-r9-068.18d4676d79ec0a1d,reason=Completed count=1 msg=Job completed
0.2908,Event,ADDED,eval-conflicts-rho010-r9-069-9jsnv.18d4676a833f9834,reason=Scheduled count=None msg=Successfully assigned compute/eval-conflicts-rho010-r9-069-9jsnv to kind-worker
0.2911,Event,ADDED,eval-conflicts-rho010-r9-069-9jsnv.18d4676a9f8f013f,"reason=Pulled count=1 msg=Container image ""busybox:musl"" already present on machine"
0.2913,Event,ADDED,eval-conflicts-rho010-r9-069-9jsnv.18d4676aa0b6bed7,reason=Created count=1 msg=Created container: task
0.2914,Event,ADDED,eval-conflicts-rho010-r9-069-9jsnv.18d4676aa4ea639d,reason=Started count=1 msg=Started container task
0.2916,Event,ADDED,eval-conflicts-rho010-r9-069.18d4676a8255584e,reason=SuccessfulCreate count=1 msg=Created pod: eval-conflicts-rho010-r9-069-9jsnv
0.2919,Event,ADDED,eval-conflicts-rho010-r9-069.18d4676dd21f14ec,reason=Completed count=1 msg=Job completed
0.292,Event,ADDED,eval-conflicts-rho010-r9-070-rv5l8.18d4676abe72044e,reason=Scheduled count=None msg=Successfully assigned compute/eval-conflicts-rho010-r9-070-rv5l8 to kind-worker5
0.2922,Event,ADDED,eval-conflicts-rho010-r9-070-rv5l8.18d4676adb3be33e,"reason=Pulled count=1 msg=Container image ""busybox:musl"" already present on machine"
0.2924,Event,ADDED,eval-conflicts-rho010-r9-070-rv5l8.18d4676adc8ecc33,reason=Created count=1 msg=Created container: task
0.2925,Event,ADDED,eval-conflicts-rho010-r9-070-rv5l8.18d4676adff2d63f,reason=Started count=1 msg=Started container task
0.2927,Event,ADDED,eval-conflicts-rho010-r9-070.18d4676abdac6264,reason=SuccessfulCreate count=1 msg=Created pod: eval-conflicts-rho010-r9-070-rv5l8
0.2929,Event,ADDED,eval-conflicts-rho010-r9-070.18d4676e16710a44,reason=Completed count=1 msg=Job completed
0.293,Event,ADDED,eval-conflicts-rho010-r9-071-gvmq6.18d4676afacc8b1c,reason=Scheduled count=None msg=Successfully assigned compute/eval-conflicts-rho010-r9-071-gvmq6 to kind-worker5
0.2932,Event,ADDED,eval-conflicts-rho010-r9-071-gvmq6.18d4676b140cd6de,"reason=Pulled count=1 msg=Container image ""busybox:musl"" already present on machine"
0.2934,Event,ADDED,eval-conflicts-rho010-r9-071-gvmq6.18d4676b153cf813,reason=Created count=1 msg=Created container: task
0.2935,Event,ADDED,eval-conflicts-rho010-r9-071-gvmq6.18d4676b190e4020,reason=Started count=1 msg=Started container task
0.2937,Event,ADDED,eval-conflicts-rho010-r9-071.18d4676af9861855,reason=SuccessfulCreate count=1 msg=Created pod: eval-conflicts-rho010-r9-071-gvmq6
0.2939,Event,ADDED,eval-conflicts-rho010-r9-071.18d4676e5148b8d1,reason=Completed count=1 msg=Job completed
0.294,Event,ADDED,eval-conflicts-rho010-r9-072-4mggf.18d4676b361e0deb,reason=Scheduled count=None msg=Successfully assigned compute/eval-conflicts-rho010-r9-072-4mggf to kind-worker5
0.2942,Event,ADDED,eval-conflicts-rho010-r9-072-4mggf.18d4676b4e9f7dc6,"reason=Pulled count=1 msg=Container image ""busybox:musl"" already present on machine"
0.2944,Event,ADDED,eval-conflicts-rho010-r9-072-4mggf.18d4676b4fb9014c,reason=Created count=1 msg=Created container: task
0.2945,Event,ADDED,eval-conflicts-rho010-r9-072-4mggf.18d4676b53108d4a,reason=Started count=1 msg=Started container task
0.2947,Event,ADDED,eval-conflicts-rho010-r9-072.18d4676b34f613de,reason=SuccessfulCreate count=1 msg=Created pod: eval-conflicts-rho010-r9-072-4mggf
0.2949,Event,ADDED,eval-conflicts-rho010-r9-072.18d4676e8d57079d,reason=Completed count=1 msg=Job completed
0.295,Event,ADDED,eval-conflicts-rho010-r9-073-qpt9s.18d4676b71ac681c,reason=Scheduled count=None msg=Successfully assigned compute/eval-conflicts-rho010-r9-073-qpt9s to kind-worker
0.2952,Event,ADDED,eval-conflicts-rho010-r9-073-qpt9s.18d4676b8ba3ada0,"reason=Pulled count=1 msg=Container image ""busybox:musl"" already present on machine"
0.2954,Event,ADDED,eval-conflicts-rho010-r9-073-qpt9s.18d4676b8cc55172,reason=Created count=1 msg=Created container: task
0.2955,Event,ADDED,eval-conflicts-rho010-r9-073-qpt9s.18d4676b8f3fa3e5,reason=Started count=1 msg=Started container task
0.2957,Event,ADDED,eval-conflicts-rho010-r9-073.18d4676b707eb06b,reason=SuccessfulCreate count=1 msg=Created pod: eval-conflicts-rho010-r9-073-qpt9s
0.296,Event,ADDED,eval-conflicts-rho010-r9-073.18d4676ec18a0735,reason=Completed count=1 msg=Job completed
0.2963,Event,ADDED,eval-conflicts-rho010-r9-074-8gvqx.18d4676bad4a8699,reason=Scheduled count=None msg=Successfully assigned compute/eval-conflicts-rho010-r9-074-8gvqx to kind-worker
0.2965,Event,ADDED,eval-conflicts-rho010-r9-074-8gvqx.18d4676bc61516ce,"reason=Pulled count=1 msg=Container image ""busybox:musl"" already present on machine"
0.2966,Event,ADDED,eval-conflicts-rho010-r9-074-8gvqx.18d4676bc747050c,reason=Created count=1 msg=Created container: task
0.2968,Event,ADDED,eval-conflicts-rho010-r9-074-8gvqx.18d4676bc94f3c10,reason=Started count=1 msg=Started container task
0.2973,Event,ADDED,eval-conflicts-rho010-r9-074.18d4676bac357755,reason=SuccessfulCreate count=1 msg=Created pod: eval-conflicts-rho010-r9-074-8gvqx
0.2976,Event,ADDED,eval-conflicts-rho010-r9-074.18d4676efd38a38d,reason=Completed count=1 msg=Job completed
0.2977,Event,ADDED,eval-conflicts-rho010-r9-075-ns8gr.18d4676be8ef2ec6,reason=Scheduled count=None msg=Successfully assigned compute/eval-conflicts-rho010-r9-075-ns8gr to kind-worker
0.298,Event,ADDED,eval-conflicts-rho010-r9-075-ns8gr.18d4676c02b3cb7a,"reason=Pulled count=1 msg=Container image ""busybox:musl"" already present on machine"
0.2982,Event,ADDED,eval-conflicts-rho010-r9-075-ns8gr.18d4676c03e1bc7f,reason=Created count=1 msg=Created container: task
0.2984,Event,ADDED,eval-conflicts-rho010-r9-075-ns8gr.18d4676c05d5423b,reason=Started count=1 msg=Started container task
0.2985,Event,ADDED,eval-conflicts-rho010-r9-075.18d4676be7b7147c,reason=SuccessfulCreate count=1 msg=Created pod: eval-conflicts-rho010-r9-075-ns8gr
0.2988,Event,ADDED,eval-conflicts-rho010-r9-075.18d4676f3918ece7,reason=Completed count=1 msg=Job completed
0.299,Event,ADDED,eval-conflicts-rho010-r9-076-t9v9g.18d4676c246a9e6f,reason=Scheduled count=None msg=Successfully assigned compute/eval-conflicts-rho010-r9-076-t9v9g to kind-worker3
0.2992,Event,ADDED,eval-conflicts-rho010-r9-076-t9v9g.18d4676c3d6f4920,"reason=Pulled count=1 msg=Container image ""busybox:musl"" already present on machine"
0.2994,Event,ADDED,eval-conflicts-rho010-r9-076-t9v9g.18d4676c3eb3d82e,reason=Created count=1 msg=Created container: task
0.2997,Event,ADDED,eval-conflicts-rho010-r9-076-t9v9g.18d4676c4365bb7a,reason=Started count=1 msg=Started container task
0.2999,Event,ADDED,eval-conflicts-rho010-r9-076.18d4676c23590db9,reason=SuccessfulCreate count=1 msg=Created pod: eval-conflicts-rho010-r9-076-t9v9g
0.3002,Event,ADDED,eval-conflicts-rho010-r9-076.18d4676f574243cc,reason=Completed count=1 msg=Job completed
0.3004,Event,ADDED,eval-conflicts-rho010-r9-077-c57hs.18d4676c5fc6a206,reason=Scheduled count=None msg=Successfully assigned compute/eval-conflicts-rho010-r9-077-c57hs to kind-worker3
0.3006,Event,ADDED,eval-conflicts-rho010-r9-077-c57hs.18d4676c8a342ad3,"reason=Pulled count=1 msg=Container image ""busybox:musl"" already present on machine"
0.3008,Event,ADDED,eval-conflicts-rho010-r9-077-c57hs.18d4676c8b44f950,reason=Created count=1 msg=Created container: task
0.3009,Event,ADDED,eval-conflicts-rho010-r9-077-c57hs.18d4676c8ef64e17,reason=Started count=1 msg=Started container task
0.3012,Event,ADDED,eval-conflicts-rho010-r9-077.18d4676c5f0d956c,reason=SuccessfulCreate count=1 msg=Created pod: eval-conflicts-rho010-r9-077-c57hs
0.3014,Event,ADDED,eval-conflicts-rho010-r9-077.18d4676fcf2b5e3e,reason=Completed count=1 msg=Job completed
0.3015,Event,ADDED,eval-conflicts-rho010-r9-078-q9dbb.18d4676c9b0789fa,reason=Scheduled count=None msg=Successfully assigned compute/eval-conflicts-rho010-r9-078-q9dbb to kind-worker2
0.3017,Event,ADDED,eval-conflicts-rho010-r9-078-q9dbb.18d4676cb30ac4d2,"reason=Pulled count=1 msg=Container image ""busybox:musl"" already present on machine"
0.3019,Event,ADDED,eval-conflicts-rho010-r9-078-q9dbb.18d4676cb43afdf4,reason=Created count=1 msg=Created container: task
0.302,Event,ADDED,eval-conflicts-rho010-r9-078-q9dbb.18d4676cbade9651,reason=Started count=1 msg=Started container task
0.3022,Event,ADDED,eval-conflicts-rho010-r9-078.18d4676c9a41f0e1,reason=SuccessfulCreate count=1 msg=Created pod: eval-conflicts-rho010-r9-078-q9dbb
0.3024,Event,ADDED,eval-conflicts-rho010-r9-078.18d4676fe80b8a72,reason=Completed count=1 msg=Job completed
0.3025,Event,ADDED,eval-conflicts-rho010-r9-079-4mmpp.18d4676cd7923a98,reason=Scheduled count=None msg=Successfully assigned compute/eval-conflicts-rho010-r9-079-4mmpp to kind-worker2
0.3027,Event,ADDED,eval-conflicts-rho010-r9-079-4mmpp.18d4676cf01ad5c4,"reason=Pulled count=1 msg=Container image ""busybox:musl"" already present on machine"
0.3028,Event,ADDED,eval-conflicts-rho010-r9-079-4mmpp.18d4676cf13e09d6,reason=Created count=1 msg=Created container: task
0.303,Event,ADDED,eval-conflicts-rho010-r9-079-4mmpp.18d4676cf612ed89,reason=Started count=1 msg=Started container task
0.3032,Event,ADDED,eval-conflicts-rho010-r9-079.18d4676cd6cce3f1,reason=SuccessfulCreate count=1 msg=Created pod: eval-conflicts-rho010-r9-079-4mmpp
0.3033,Event,ADDED,eval-conflicts-rho010-r9-079.18d4677023b8e041,reason=Completed count=1 msg=Job completed
0.3035,Event,ADDED,eval-conflicts-rho010-r9-080-jvtr9.18d4676d11d41dcc,"reason=FailedScheduling count=None msg=0/6 nodes are available: 1 c_wall violated: 1 conflicting context pair(s) with node memory, 5 node(s) had untolerated taint(s). no new claims to deallocate, preemption: 0/6 nodes are available: 1 No preemption victims found for incoming pod, 5 Preemption is not helpful for scheduling."
0.3037,Event,ADDED,eval-conflicts-rho010-r9-080-jvtr9.18d4676d125897cb,"reason=FailedScheduling count=None msg=0/6 nodes are available: 1 c_wall violated: 1 conflicting context pair(s) with node memory, 5 node(s) had untolerated taint(s). no new claims to deallocate, preemption: 0/6 nodes are available: 1 No preemption victims found for incoming pod, 5 Preemption is not helpful for scheduling."
0.3038,Event,ADDED,eval-conflicts-rho010-r9-080-jvtr9.18d4676f6cedd6bf,reason=Scheduled count=None msg=Successfully assigned compute/eval-conflicts-rho010-r9-080-jvtr9 to kind-worker5
0.304,Event,ADDED,eval-conflicts-rho010-r9-080-jvtr9.18d4676f8673600e,"reason=Pulled count=1 msg=Container image ""busybox:musl"" already present on machine"
0.3042,Event,ADDED,eval-conflicts-rho010-r9-080-jvtr9.18d4676f8782b952,reason=Created count=1 msg=Created container: task
0.3044,Event,ADDED,eval-conflicts-rho010-r9-080-jvtr9.18d4676f8afffbb9,reason=Started count=1 msg=Started container task
0.3046,Event,ADDED,eval-conflicts-rho010-r9-080.18d4676d1191f9e4,reason=SuccessfulCreate count=1 msg=Created pod: eval-conflicts-rho010-r9-080-jvtr9
0.3047,Event,ADDED,eval-conflicts-rho010-r9-080.18d46772c20fb28e,reason=Completed count=1 msg=Job completed
0.3049,Event,ADDED,eval-conflicts-rho010-r9-081-jdvc2.18d4676d4df331e4,"reason=FailedScheduling count=None msg=0/6 nodes are available: 1 c_wall violated: 1 conflicting context pair(s) with node memory, 5 node(s) had untolerated taint(s). no new claims to deallocate, preemption: 0/6 nodes are available: 1 No preemption victims found for incoming pod, 5 Preemption is not helpful for scheduling."
0.3051,Event,ADDED,eval-conflicts-rho010-r9-081-jdvc2.18d4676d4e8b43f9,"reason=FailedScheduling count=None msg=0/6 nodes are available: 1 c_wall violated: 1 conflicting context pair(s) with node memory, 5 node(s) had untolerated taint(s). no new claims to deallocate, preemption: 0/6 nodes are available: 1 No preemption victims found for incoming pod, 5 Preemption is not helpful for scheduling."
0.3052,Event,ADDED,eval-conflicts-rho010-r9-081-jdvc2.18d4676edcdfc6e8,reason=Scheduled count=None msg=Successfully assigned compute/eval-conflicts-rho010-r9-081-jdvc2 to kind-worker4
0.3054,Event,ADDED,eval-conflicts-rho010-r9-081-jdvc2.18d4676ef507cea1,"reason=Pulled count=1 msg=Container image ""busybox:musl"" already present on machine"
0.3056,Event,ADDED,eval-conflicts-rho010-r9-081-jdvc2.18d4676ef679c49e,reason=Created count=1 msg=Created container: task
0.3057,Event,ADDED,eval-conflicts-rho010-r9-081-jdvc2.18d4676ef893e181,reason=Started count=1 msg=Started container task
0.3059,Event,ADDED,eval-conflicts-rho010-r9-081.18d4676d4da9d8d6,reason=SuccessfulCreate count=1 msg=Created pod: eval-conflicts-rho010-r9-081-jdvc2
0.306,Event,ADDED,eval-conflicts-rho010-r9-081.18d4677215d7da57,reason=Completed count=1 msg=Job completed
0.3062,Event,ADDED,eval-conflicts-rho010-r9-082-74nwz.18d4676d8937fae4,reason=Scheduled count=None msg=Successfully assigned compute/eval-conflicts-rho010-r9-082-74nwz to kind-worker2
0.3064,Event,ADDED,eval-conflicts-rho010-r9-082-74nwz.18d4676da441dda8,"reason=Pulled count=1 msg=Container image ""busybox:musl"" already present on machine"
0.3065,Event,ADDED,eval-conflicts-rho010-r9-082-74nwz.18d4676da55e6524,reason=Created count=1 msg=Created container: task
0.3067,Event,ADDED,eval-conflicts-rho010-r9-082-74nwz.18d4676dac067b0a,reason=Started count=1 msg=Started container task
0.3069,Event,ADDED,eval-conflicts-rho010-r9-082.18d4676d88bef4c1,reason=SuccessfulCreate count=1 msg=Created pod: eval-conflicts-rho010-r9-082-74nwz
0.307,Event,ADDED,eval-conflicts-rho010-r9-082.18d46770d76b3ae5,reason=Completed count=1 msg=Job completed
0.3072,Event,ADDED,eval-conflicts-rho010-r9-083-k8b7d.18d4676dc50b42c5,"reason=FailedScheduling count=None msg=0/6 nodes are available: 1 c_wall violated: 1 conflicting context pair(s) with node memory, 5 node(s) had untolerated taint(s). no new claims to deallocate, preemption: 0/6 nodes are available: 1 No preemption victims found for incoming pod, 5 Preemption is not helpful for scheduling."
0.3074,Event,ADDED,eval-conflicts-rho010-r9-083-k8b7d.18d4676dc5b2e225,"reason=FailedScheduling count=None msg=0/6 nodes are available: 1 c_wall violated: 1 conflicting context pair(s) with node memory, 5 node(s) had untolerated taint(s). no new claims to deallocate, preemption: 0/6 nodes are available: 1 No preemption victims found for incoming pod, 5 Preemption is not helpful for scheduling."
0.3076,Event,ADDED,eval-conflicts-rho010-r9-083-k8b7d.18d4676edd092afd,reason=Scheduled count=None msg=Successfully assigned compute/eval-conflicts-rho010-r9-083-k8b7d to kind-worker4
0.3078,Event,ADDED,eval-conflicts-rho010-r9-083-k8b7d.18d4676ef607adc3,"reason=Pulled count=1 msg=Container image ""busybox:musl"" already present on machine"
0.308,Event,ADDED,eval-conflicts-rho010-r9-083-k8b7d.18d4676ef75473cd,reason=Created count=1 msg=Created container: task
0.3081,Event,ADDED,eval-conflicts-rho010-r9-083-k8b7d.18d4676ef950e318,reason=Started count=1 msg=Started container task
0.3084,Event,ADDED,eval-conflicts-rho010-r9-083.18d4676dc4c8f73d,reason=SuccessfulCreate count=1 msg=Created pod: eval-conflicts-rho010-r9-083-k8b7d
0.3086,Event,ADDED,eval-conflicts-rho010-r9-083.18d467721640e7c4,reason=Completed count=1 msg=Job completed
0.3088,Event,ADDED,eval-conflicts-rho010-r9-084-2plwk.18d4676e00f1a3a8,reason=Scheduled count=None msg=Successfully assigned compute/eval-conflicts-rho010-r9-084-2plwk to kind-worker2
0.3089,Event,ADDED,eval-conflicts-rho010-r9-084-2plwk.18d4676e1f2aa8f2,"reason=Pulled count=1 msg=Container image ""busybox:musl"" already present on machine"
0.3091,Event,ADDED,eval-conflicts-rho010-r9-084-2plwk.18d4676e20611f74,reason=Created count=1 msg=Created container: task
0.3093,Event,ADDED,eval-conflicts-rho010-r9-084-2plwk.18d4676e23449ecb,reason=Started count=1 msg=Started container task
0.3095,Event,ADDED,eval-conflicts-rho010-r9-084.18d4676e0067de94,reason=SuccessfulCreate count=1 msg=Created pod: eval-conflicts-rho010-r9-084-2plwk
0.3096,Event,ADDED,eval-conflicts-rho010-r9-084.18d467714f00a8a3,reason=Completed count=1 msg=Job completed
0.3098,Event,ADDED,eval-conflicts-rho010-r9-085-q7gvh.18d4676e3c256be6,reason=Scheduled count=None msg=Successfully assigned compute/eval-conflicts-rho010-r9-085-q7gvh to kind-worker2
0.3099,Event,ADDED,eval-conflicts-rho010-r9-085-q7gvh.18d4676e596ef62e,"reason=Pulled count=1 msg=Container image ""busybox:musl"" already present on machine"
0.3101,Event,ADDED,eval-conflicts-rho010-r9-085-q7gvh.18d4676e5a9b6eb8,reason=Created count=1 msg=Created container: task
0.3103,Event,ADDED,eval-conflicts-rho010-r9-085-q7gvh.18d4676e613c0080,reason=Started count=1 msg=Started container task
0.3105,Event,ADDED,eval-conflicts-rho010-r9-085.18d4676e3ba12059,reason=SuccessfulCreate count=1 msg=Created pod: eval-conflicts-rho010-r9-085-q7gvh
0.3106,Event,ADDED,eval-conflicts-rho010-r9-085.18d467718b5b6f74,reason=Completed count=1 msg=Job completed
0.311,Event,ADDED,eval-conflicts-rho010-r9-086-z2n44.18d4676e77f7eb52,"reason=FailedScheduling count=None msg=0/6 nodes are available: 1 c_wall violated: 1 conflicting context pair(s) with node memory, 5 node(s) had untolerated taint(s). no new claims to deallocate, preemption: 0/6 nodes are available: 1 No preemption victims found for incoming pod, 5 Preemption is not helpful for scheduling."
0.3112,Event,ADDED,eval-conflicts-rho010-r9-086-z2n44.18d4676e78a3aa41,"reason=FailedScheduling count=None msg=0/6 nodes are available: 1 c_wall violated: 1 conflicting context pair(s) with node memory, 5 node(s) had untolerated taint(s). no new claims to deallocate, preemption: 0/6 nodes are available: 1 No preemption victims found for incoming pod, 5 Preemption is not helpful for scheduling."
0.3114,Event,ADDED,eval-conflicts-rho010-r9-086-z2n44.18d4676f67670e8b,reason=Scheduled count=None msg=Successfully assigned compute/eval-conflicts-rho010-r9-086-z2n44 to kind-worker5
0.3116,Event,ADDED,eval-conflicts-rho010-r9-086-z2n44.18d4676f806583b2,"reason=Pulled count=1 msg=Container image ""busybox:musl"" already present on machine"
0.3118,Event,ADDED,eval-conflicts-rho010-r9-086-z2n44.18d4676f818a2bd2,reason=Created count=1 msg=Created container: task
0.312,Event,ADDED,eval-conflicts-rho010-r9-086-z2n44.18d4676f853f8937,reason=Started count=1 msg=Started container task
0.3121,Event,ADDED,eval-conflicts-rho010-r9-086.18d4676e77abceb4,reason=SuccessfulCreate count=1 msg=Created pod: eval-conflicts-rho010-r9-086-z2n44
0.3124,Event,ADDED,eval-conflicts-rho010-r9-086.18d46772c1ea8381,reason=Completed count=1 msg=Job completed
0.3125,Event,ADDED,eval-conflicts-rho010-r9-087-skrsk.18d4676eb344527e,"reason=FailedScheduling count=None msg=0/6 nodes are available: 1 c_wall violated: 1 conflicting context pair(s) with node memory, 5 node(s) had untolerated taint(s). no new claims to deallocate, preemption: 0/6 nodes are available: 1 No preemption victims found for incoming pod, 5 Preemption is not helpful for scheduling."
0.3127,Event,ADDED,eval-conflicts-rho010-r9-087-skrsk.18d4676eb3e24a6f,"reason=FailedScheduling count=None msg=0/6 nodes are available: 1 c_wall violated: 1 conflicting context pair(s) with node memory, 5 node(s) had untolerated taint(s). no new claims to deallocate, preemption: 0/6 nodes are available: 1 No preemption victims found for incoming pod, 5 Preemption is not helpful for scheduling."
0.3129,Event,ADDED,eval-conflicts-rho010-r9-087-skrsk.18d4676ed816bf09,reason=Scheduled count=None msg=Successfully assigned compute/eval-conflicts-rho010-r9-087-skrsk to kind-worker4
0.313,Event,ADDED,eval-conflicts-rho010-r9-087-skrsk.18d4676ef173795b,"reason=Pulled count=1 msg=Container image ""busybox:musl"" already present on machine"
0.3132,Event,ADDED,eval-conflicts-rho010-r9-087-skrsk.18d4676ef347b070,reason=Created count=1 msg=Created container: task
0.3133,Event,ADDED,eval-conflicts-rho010-r9-087-skrsk.18d4676ef5ab79f6,reason=Started count=1 msg=Started container task
0.3135,Event,ADDED,eval-conflicts-rho010-r9-087.18d4676eb2fcd347,reason=SuccessfulCreate count=1 msg=Created pod: eval-conflicts-rho010-r9-087-skrsk
0.3137,Event,ADDED,eval-conflicts-rho010-r9-087.18d4677216743b4b,reason=Completed count=1 msg=Job completed
0.3138,Event,ADDED,eval-conflicts-rho010-r9-088-lcww8.18d4676eef46ba07,reason=Scheduled count=None msg=Successfully assigned compute/eval-conflicts-rho010-r9-088-lcww8 to kind-worker4
0.314,Event,ADDED,eval-conflicts-rho010-r9-088-lcww8.18d4676f09c6cba7,"reason=Pulled count=1 msg=Container image ""busybox:musl"" already present on machine"
0.3142,Event,ADDED,eval-conflicts-rho010-r9-088-lcww8.18d4676f0b3f1398,reason=Created count=1 msg=Created container: task
0.3145,Event,ADDED,eval-conflicts-rho010-r9-088-lcww8.18d4676f11da880d,reason=Started count=1 msg=Started container task
0.3147,Event,ADDED,eval-conflicts-rho010-r9-088.18d4676eeeb57f05,reason=SuccessfulCreate count=1 msg=Created pod: eval-conflicts-rho010-r9-088-lcww8
0.3149,Event,ADDED,eval-conflicts-rho010-r9-088.18d4677251d27d32,reason=Completed count=1 msg=Job completed
0.3151,Event,ADDED,eval-conflicts-rho010-r9-089-66ff2.18d4676f2a516173,"reason=FailedScheduling count=None msg=0/6 nodes are available: 1 c_wall violated: 1 conflicting context pair(s) with node memory, 5 node(s) had untolerated taint(s). no new claims to deallocate, preemption: 0/6 nodes are available: 1 No preemption victims found for incoming pod, 5 Preemption is not helpful for scheduling."
0.3153,Event,ADDED,eval-conflicts-rho010-r9-089-66ff2.18d4676f2ad76c09,"reason=FailedScheduling count=None msg=0/6 nodes are available: 1 c_wall violated: 1 conflicting context pair(s) with node memory, 5 node(s) had untolerated taint(s). no new claims to deallocate, preemption: 0/6 nodes are available: 1 No preemption victims found for incoming pod, 5 Preemption is not helpful for scheduling."
0.3155,Event,ADDED,eval-conflicts-rho010-r9-089-66ff2.18d4676f718e2197,"reason=FailedScheduling count=None msg=0/6 nodes are available: 2 c_wall violated: 1 conflicting context pair(s) with node memory, 4 node(s) had untolerated taint(s). no new claims to deallocate, preemption: 0/6 nodes are available: 2 No preemption victims found for incoming pod, 4 Preemption is not helpful for scheduling."
0.3156,Event,ADDED,eval-conflicts-rho010-r9-089-66ff2.18d467712cc3dbe4,reason=Scheduled count=None msg=Successfully assigned compute/eval-conflicts-rho010-r9-089-66ff2 to kind-worker
0.3158,Event,ADDED,eval-conflicts-rho010-r9-089-66ff2.18d4677149f82f34,"reason=Pulled count=1 msg=Container image ""busybox:musl"" already present on machine"
0.316,Event,ADDED,eval-conflicts-rho010-r9-089-66ff2.18d467714b50d5a8,reason=Created count=1 msg=Created container: task
0.3161,Event,ADDED,eval-conflicts-rho010-r9-089-66ff2.18d4677152869d78,reason=Started count=1 msg=Started container task
0.3163,Event,ADDED,eval-conflicts-rho010-r9-089.18d4676f2a1666a0,reason=SuccessfulCreate count=1 msg=Created pod: eval-conflicts-rho010-r9-089-66ff2
0.3165,Event,ADDED,eval-conflicts-rho010-r9-089.18d4677498bed326,reason=Completed count=1 msg=Job completed
0.3166,Event,ADDED,eval-conflicts-rho010-r9-090-pbx9n.18d4676f6627e366,"reason=FailedScheduling count=None msg=0/6 nodes are available: 1 c_wall violated: 1 conflicting context pair(s) with node memory, 5 node(s) had untolerated taint(s). no new claims to deallocate, preemption: 0/6 nodes are available: 1 No preemption victims found for incoming pod, 5 Preemption is not helpful for scheduling."
0.3168,Event,ADDED,eval-conflicts-rho010-r9-090-pbx9n.18d4676f6b7d7ae9,"reason=FailedScheduling count=None msg=0/6 nodes are available: 2 c_wall violated: 1 conflicting context pair(s) with node memory, 4 node(s) had untolerated taint(s). no new claims to deallocate, preemption: 0/6 nodes are available: 2 No preemption victims found for incoming pod, 4 Preemption is not helpful for scheduling."
0.317,Event,ADDED,eval-conflicts-rho010-r9-090-pbx9n.18d4676f6cf465a5,"reason=FailedScheduling count=None msg=0/6 nodes are available: 2 c_wall violated: 1 conflicting context pair(s) with node memory, 4 node(s) had untolerated taint(s). no new claims to deallocate, preemption: 0/6 nodes are available: 2 No preemption victims found for incoming pod, 4 Preemption is not helpful for scheduling."
0.3171,Event,ADDED,eval-conflicts-rho010-r9-090-pbx9n.18d467712c9bf632,reason=Scheduled count=None msg=Successfully assigned compute/eval-conflicts-rho010-r9-090-pbx9n to kind-worker
0.3173,Event,ADDED,eval-conflicts-rho010-r9-090-pbx9n.18d46771484885c5,"reason=Pulled count=1 msg=Container image ""busybox:musl"" already present on machine"
0.3174,Event,ADDED,eval-conflicts-rho010-r9-090-pbx9n.18d4677149fc3194,reason=Created count=1 msg=Created container: task
0.3176,Event,ADDED,eval-conflicts-rho010-r9-090-pbx9n.18d46771599b2c89,reason=Started count=1 msg=Started container task
0.3178,Event,ADDED,eval-conflicts-rho010-r9-090.18d4676f65d53c9d,reason=SuccessfulCreate count=1 msg=Created pod: eval-conflicts-rho010-r9-090-pbx9n
0.318,Event,ADDED,eval-conflicts-rho010-r9-090.18d467749875355f,reason=Completed count=1 msg=Job completed
0.3182,Event,ADDED,eval-conflicts-rho010-r9-091-jdtfk.18d4676fa2b7ed8b,reason=Scheduled count=None msg=Successfully assigned compute/eval-conflicts-rho010-r9-091-jdtfk to kind-worker5
0.3183,Event,ADDED,eval-conflicts-rho010-r9-091-jdtfk.18d4676fbc04c71f,"reason=Pulled count=1 msg=Container image ""busybox:musl"" already present on machine"
0.3186,Event,ADDED,eval-conflicts-rho010-r9-091-jdtfk.18d4676fbd36cc33,reason=Created count=1 msg=Created container: task
0.3188,Event,ADDED,eval-conflicts-rho010-r9-091-jdtfk.18d4676fbf216ae8,reason=Started count=1 msg=Started container task
0.319,Event,ADDED,eval-conflicts-rho010-r9-091.18d4676fa17bb90a,reason=SuccessfulCreate count=1 msg=Created pod: eval-conflicts-rho010-r9-091-jdtfk
0.3192,Event,ADDED,eval-conflicts-rho010-r9-091.18d46772c28eeb67,reason=Completed count=1 msg=Job completed
0.3194,Event,ADDED,eval-conflicts-rho010-r9-092-hnf8t.18d4676fdef5cc5e,reason=Scheduled count=None msg=Successfully assigned compute/eval-conflicts-rho010-r9-092-hnf8t to kind-worker5
0.3196,Event,ADDED,eval-conflicts-rho010-r9-092-hnf8t.18d4676ff873481e,"reason=Pulled count=1 msg=Container image ""busybox:musl"" already present on machine"
0.3197,Event,ADDED,eval-conflicts-rho010-r9-092-hnf8t.18d4676ff97ddb50,reason=Created count=1 msg=Created container: task
0.3199,Event,ADDED,eval-conflicts-rho010-r9-092-hnf8t.18d4676ffb633e17,reason=Started count=1 msg=Started container task
0.3201,Event,ADDED,eval-conflicts-rho010-r9-092.18d4676fde19dc55,reason=SuccessfulCreate count=1 msg=Created pod: eval-conflicts-rho010-r9-092-hnf8t
0.3202,Event,ADDED,eval-conflicts-rho010-r9-092.18d467733a79ef01,reason=Completed count=1 msg=Job completed
0.3204,Event,ADDED,eval-conflicts-rho010-r9-093-q6rqb.18d4677019912402,reason=Scheduled count=None msg=Successfully assigned compute/eval-conflicts-rho010-r9-093-q6rqb to kind-worker5
0.3206,Event,ADDED,eval-conflicts-rho010-r9-093-q6rqb.18d46770332df8dc,"reason=Pulled count=1 msg=Container image ""busybox:musl"" already present on machine"
0.3207,Event,ADDED,eval-conflicts-rho010-r9-093-q6rqb.18d467703454ca48,reason=Created count=1 msg=Created container: task
0.3209,Event,ADDED,eval-conflicts-rho010-r9-093-q6rqb.18d4677036ad94f0,reason=Started count=1 msg=Started container task
0.3212,Event,ADDED,eval-conflicts-rho010-r9-093.18d4677018ac7f5b,reason=SuccessfulCreate count=1 msg=Created pod: eval-conflicts-rho010-r9-093-q6rqb
0.3214,Event,ADDED,eval-conflicts-rho010-r9-093.18d46773765bfaab,reason=Completed count=1 msg=Job completed
0.3216,Event,ADDED,eval-conflicts-rho010-r9-094-hrbpr.18d46770549dfef1,"reason=FailedScheduling count=None msg=0/6 nodes are available: 2 c_wall violated: 1 conflicting context pair(s) with node memory, 4 node(s) had untolerated taint(s). no new claims to deallocate, preemption: 0/6 nodes are available: 2 No preemption victims found for incoming pod, 4 Preemption is not helpful for scheduling."
0.3219,Event,ADDED,eval-conflicts-rho010-r9-094-hrbpr.18d467705559c837,"reason=FailedScheduling count=None msg=0/6 nodes are available: 2 c_wall violated: 1 conflicting context pair(s) with node memory, 4 node(s) had untolerated taint(s). no new claims to deallocate, preemption: 0/6 nodes are available: 2 No preemption victims found for incoming pod, 4 Preemption is not helpful for scheduling."
0.322,Event,ADDED,eval-conflicts-rho010-r9-094-hrbpr.18d46771261cb088,reason=Scheduled count=None msg=Successfully assigned compute/eval-conflicts-rho010-r9-094-hrbpr to kind-worker
0.3222,Event,ADDED,eval-conflicts-rho010-r9-094-hrbpr.18d467714248d71b,"reason=Pulled count=1 msg=Container image ""busybox:musl"" already present on machine"
0.3224,Event,ADDED,eval-conflicts-rho010-r9-094-hrbpr.18d467714496de46,reason=Created count=1 msg=Created container: task
0.3227,Event,ADDED,eval-conflicts-rho010-r9-094-hrbpr.18d4677148c0f1f3,reason=Started count=1 msg=Started container task
0.3229,Event,ADDED,eval-conflicts-rho010-r9-094.18d4677054271834,reason=SuccessfulCreate count=1 msg=Created pod: eval-conflicts-rho010-r9-094-hrbpr
0.3231,Event,ADDED,eval-conflicts-rho010-r9-094.18d467745c5fe799,reason=Completed count=1 msg=Job completed
0.3232,Event,ADDED,eval-conflicts-rho010-r9-095-gwrc7.18d4677090b4ea86,reason=Scheduled count=None msg=Successfully assigned compute/eval-conflicts-rho010-r9-095-gwrc7 to kind-worker4
0.3235,Event,ADDED,eval-conflicts-rho010-r9-095-gwrc7.18d46770aa7b7a02,"reason=Pulled count=1 msg=Container image ""busybox:musl"" already present on machine"
0.3236,Event,ADDED,eval-conflicts-rho010-r9-095-gwrc7.18d46770ab9a5132,reason=Created count=1 msg=Created container: task
0.3238,Event,ADDED,eval-conflicts-rho010-r9-095-gwrc7.18d46770ada09985,reason=Started count=1 msg=Started container task
0.3241,Event,ADDED,eval-conflicts-rho010-r9-095.18d467708fddf662,reason=SuccessfulCreate count=1 msg=Created pod: eval-conflicts-rho010-r9-095-gwrc7
0.3243,Event,ADDED,eval-conflicts-rho010-r9-095.18d46773f314fc86,reason=Completed count=1 msg=Job completed
0.3245,Event,ADDED,eval-conflicts-rho010-r9-096-s6tws.18d46770cc7ebc01,reason=Scheduled count=None msg=Successfully assigned compute/eval-conflicts-rho010-r9-096-s6tws to kind-worker5
0.3247,Event,ADDED,eval-conflicts-rho010-r9-096-s6tws.18d46770e6c2d16b,"reason=Pulled count=1 msg=Container image ""busybox:musl"" already present on machine"
0.3249,Event,ADDED,eval-conflicts-rho010-r9-096-s6tws.18d46770e84f01eb,reason=Created count=1 msg=Created container: task
0.325,Event,ADDED,eval-conflicts-rho010-r9-096-s6tws.18d46770ec609565,reason=Started count=1 msg=Started container task
0.3253,Event,ADDED,eval-conflicts-rho010-r9-096.18d46770cb883cf9,reason=SuccessfulCreate count=1 msg=Created pod: eval-conflicts-rho010-r9-096-s6tws
0.3254,Event,ADDED,eval-conflicts-rho010-r9-096.18d46774289ea9b8,reason=Completed count=1 msg=Job completed
0.3256,Event,ADDED,eval-conflicts-rho010-r9-097-66nvf.18d4677107ebe5ea,reason=Scheduled count=None msg=Successfully assigned compute/eval-conflicts-rho010-r9-097-66nvf to kind-worker4
0.3258,Event,ADDED,eval-conflicts-rho010-r9-097-66nvf.18d4677120a105d7,"reason=Pulled count=1 msg=Container image ""busybox:musl"" already present on machine"
0.3259,Event,ADDED,eval-conflicts-rho010-r9-097-66nvf.18d4677121c7086b,reason=Created count=1 msg=Created container: task
0.3261,Event,ADDED,eval-conflicts-rho010-r9-097-66nvf.18d4677123da5b6e,reason=Started count=1 msg=Started container task
0.3263,Event,ADDED,eval-conflicts-rho010-r9-097.18d4677106fb4568,reason=SuccessfulCreate count=1 msg=Created pod: eval-conflicts-rho010-r9-097-66nvf
0.3264,Event,ADDED,eval-conflicts-rho010-r9-097.18d467742edeef54,reason=Completed count=1 msg=Job completed
0.3266,Event,ADDED,eval-conflicts-rho010-r9-098-vlh9j.18d4677143f87dea,reason=Scheduled count=None msg=Successfully assigned compute/eval-conflicts-rho010-r9-098-vlh9j to kind-worker
0.3268,Event,ADDED,eval-conflicts-rho010-r9-098-vlh9j.18d467715f88dbfc,"reason=Pulled count=1 msg=Container image ""busybox:musl"" already present on machine"
0.3269,Event,ADDED,eval-conflicts-rho010-r9-098-vlh9j.18d4677160e9cc2c,reason=Created count=1 msg=Created container: task
0.3271,Event,ADDED,eval-conflicts-rho010-r9-098-vlh9j.18d4677164d79da2,reason=Started count=1 msg=Started container task
0.3273,Event,ADDED,eval-conflicts-rho010-r9-098.18d4677142e71418,reason=SuccessfulCreate count=1 msg=Created pod: eval-conflicts-rho010-r9-098-vlh9j
0.3274,Event,ADDED,eval-conflicts-rho010-r9-098.18d467749856005e,reason=Completed count=1 msg=Job completed
0.3276,Event,ADDED,eval-conflicts-rho010-r9-099-cxgsv.18d46771805f256b,reason=Scheduled count=None msg=Successfully assigned compute/eval-conflicts-rho010-r9-099-cxgsv to kind-worker2
0.3278,Event,ADDED,eval-conflicts-rho010-r9-099-cxgsv.18d467719b545151,"reason=Pulled count=1 msg=Container image ""busybox:musl"" already present on machine"
0.3279,Event,ADDED,eval-conflicts-rho010-r9-099-cxgsv.18d467719d426539,reason=Created count=1 msg=Created container: task
0.3281,Event,ADDED,eval-conflicts-rho010-r9-099-cxgsv.18d46771a2976aa5,reason=Started count=1 msg=Started container task
0.3284,Event,ADDED,eval-conflicts-rho010-r9-099.18d467717f6e1177,reason=SuccessfulCreate count=1 msg=Created pod: eval-conflicts-rho010-r9-099-cxgsv
0.3285,Event,ADDED,eval-conflicts-rho010-r9-099.18d46774cf9f712a,reason=Completed count=1 msg=Job completed
0.3287,Event,ADDED,eval-conflicts-rho020-r0-000-ktmb9.18d4677df479e92b,reason=Scheduled count=None msg=Successfully assigned compute/eval-conflicts-rho020-r0-000-ktmb9 to kind-worker5
0.3289,Event,ADDED,eval-conflicts-rho020-r0-000-ktmb9.18d4677e12a61816,"reason=Pulled count=1 msg=Container image ""busybox:musl"" already present on machine"
0.3291,Event,ADDED,eval-conflicts-rho020-r0-000-ktmb9.18d4677e145884e7,reason=Created count=1 msg=Created container: task
0.3293,Event,ADDED,eval-conflicts-rho020-r0-000-ktmb9.18d4677e1795b922,reason=Started count=1 msg=Started container task
0.3294,Event,ADDED,eval-conflicts-rho020-r0-000.18d4677df365239b,reason=SuccessfulCreate count=1 msg=Created pod: eval-conflicts-rho020-r0-000-ktmb9
0.3296,Event,ADDED,eval-conflicts-rho020-r0-000.18d467813a6634ea,reason=Completed count=1 msg=Job completed
0.3298,Event,ADDED,eval-conflicts-rho020-r0-001-ndskb.18d4677e2f2b327b,reason=Scheduled count=None msg=Successfully assigned compute/eval-conflicts-rho020-r0-001-ndskb to kind-worker2
0.3299,Event,ADDED,eval-conflicts-rho020-r0-001-ndskb.18d4677e4d7deaf7,"reason=Pulled count=1 msg=Container image ""busybox:musl"" already present on machine"
0.3301,Event,ADDED,eval-conflicts-rho020-r0-001-ndskb.18d4677e4ea5a7fe,reason=Created count=1 msg=Created container: task
0.3303,Event,ADDED,eval-conflicts-rho020-r0-001-ndskb.18d4677e53332f8e,reason=Started count=1 msg=Started container task
0.3304,Event,ADDED,eval-conflicts-rho020-r0-001.18d4677e2e13df84,reason=SuccessfulCreate count=1 msg=Created pod: eval-conflicts-rho020-r0-001-ndskb
0.3306,Event,ADDED,eval-conflicts-rho020-r0-001.18d467816938258d,reason=Completed count=1 msg=Job completed
0.3308,Event,ADDED,eval-conflicts-rho020-r0-002-2xhq7.18d4677e6a502114,reason=Scheduled count=None msg=Successfully assigned compute/eval-conflicts-rho020-r0-002-2xhq7 to kind-worker5
0.3309,Event,ADDED,eval-conflicts-rho020-r0-002-2xhq7.18d4677e82f68d9d,"reason=Pulled count=1 msg=Container image ""busybox:musl"" already present on machine"
0.3312,Event,ADDED,eval-conflicts-rho020-r0-002-2xhq7.18d4677e84220d5b,reason=Created count=1 msg=Created container: task
0.3314,Event,ADDED,eval-conflicts-rho020-r0-002-2xhq7.18d4677e862ef2c5,reason=Started count=1 msg=Started container task
0.3315,Event,ADDED,eval-conflicts-rho020-r0-002.18d4677e69463362,reason=SuccessfulCreate count=1 msg=Created pod: eval-conflicts-rho020-r0-002-2xhq7
0.3317,Event,ADDED,eval-conflicts-rho020-r0-002.18d46781b1ceb28e,reason=Completed count=1 msg=Job completed
0.3319,Event,ADDED,eval-conflicts-rho020-r0-003-4k7pc.18d4677ea65825cd,reason=Scheduled count=None msg=Successfully assigned compute/eval-conflicts-rho020-r0-003-4k7pc to kind-worker
0.3321,Event,ADDED,eval-conflicts-rho020-r0-003-4k7pc.18d4677ebe8cd782,"reason=Pulled count=1 msg=Container image ""busybox:musl"" already present on machine"
0.3323,Event,ADDED,eval-conflicts-rho020-r0-003-4k7pc.18d4677ebffb0129,reason=Created count=1 msg=Created container: task
0.3324,Event,ADDED,eval-conflicts-rho020-r0-003-4k7pc.18d4677ec20a8e1c,reason=Started count=1 msg=Started container task
0.3326,Event,ADDED,eval-conflicts-rho020-r0-003.18d4677ea553d63b,reason=SuccessfulCreate count=1 msg=Created pod: eval-conflicts-rho020-r0-003-4k7pc
0.3328,Event,ADDED,eval-conflicts-rho020-r0-003.18d46781e591ab13,reason=Completed count=1 msg=Job completed
0.3329,Event,ADDED,eval-conflicts-rho020-r0-004-wds79.18d4677ee0c3c401,reason=Scheduled count=None msg=Successfully assigned compute/eval-conflicts-rho020-r0-004-wds79 to kind-worker
0.3331,Event,ADDED,eval-conflicts-rho020-r0-004-wds79.18d4677efad7bc80,"reason=Pulled count=1 msg=Container image ""busybox:musl"" already present on machine"
0.3333,Event,ADDED,eval-conflicts-rho020-r0-004-wds79.18d4677efc042a85,reason=Created count=1 msg=Created container: task
0.3334,Event,ADDED,eval-conflicts-rho020-r0-004-wds79.18d4677efe0ef6d8,reason=Started count=1 msg=Started container task
0.3336,Event,ADDED,eval-conflicts-rho020-r0-004.18d4677edf9c4f3c,reason=SuccessfulCreate count=1 msg=Created pod: eval-conflicts-rho020-r0-004-wds79
0.3337,Event,ADDED,eval-conflicts-rho020-r0-004.18d46782214420ec,reason=Completed count=1 msg=Job completed
0.3339,Event,ADDED,eval-conflicts-rho020-r0-005-rkx9b.18d4677f1d0d3061,reason=Scheduled count=None msg=Successfully assigned compute/eval-conflicts-rho020-r0-005-rkx9b to kind-worker2
0.3341,Event,ADDED,eval-conflicts-rho020-r0-005-rkx9b.18d4677f36cb6d8e,"reason=Pulled count=1 msg=Container image ""busybox:musl"" already present on machine"
0.3342,Event,ADDED,eval-conflicts-rho020-r0-005-rkx9b.18d4677f37f86312,reason=Created count=1 msg=Created container: task
0.3345,Event,ADDED,eval-conflicts-rho020-r0-005-rkx9b.18d4677f3b140765,reason=Started count=1 msg=Started container task
0.3347,Event,ADDED,eval-conflicts-rho020-r0-005.18d4677f1bc594cc,reason=SuccessfulCreate count=1 msg=Created pod: eval-conflicts-rho020-r0-005-rkx9b
0.3349,Event,ADDED,eval-conflicts-rho020-r0-005.18d467825823ae56,reason=Completed count=1 msg=Job completed
0.3351,Event,ADDED,eval-conflicts-rho020-r0-006-wz8wq.18d4677f587f758e,reason=Scheduled count=None msg=Successfully assigned compute/eval-conflicts-rho020-r0-006-wz8wq to kind-worker4
0.3353,Event,ADDED,eval-conflicts-rho020-r0-006-wz8wq.18d4677f71757fbd,"reason=Pulled count=1 msg=Container image ""busybox:musl"" already present on machine"
0.3354,Event,ADDED,eval-conflicts-rho020-r0-006-wz8wq.18d4677f728bac33,reason=Created count=1 msg=Created container: task
0.3357,Event,ADDED,eval-conflicts-rho020-r0-006-wz8wq.18d4677f7636b23f,reason=Started count=1 msg=Started container task
0.3359,Event,ADDED,eval-conflicts-rho020-r0-006.18d4677f57546068,reason=SuccessfulCreate count=1 msg=Created pod: eval-conflicts-rho020-r0-006-wz8wq
0.3361,Event,ADDED,eval-conflicts-rho020-r0-006.18d46782a696d36c,reason=Completed count=1 msg=Job completed
0.3363,Event,ADDED,eval-conflicts-rho020-r0-007-4h55j.18d4677f937fd4a9,reason=Scheduled count=None msg=Successfully assigned compute/eval-conflicts-rho020-r0-007-4h55j to kind-worker3
0.3366,Event,ADDED,eval-conflicts-rho020-r0-007-4h55j.18d4677fac352c0b,"reason=Pulled count=1 msg=Container image ""busybox:musl"" already present on machine"
0.3367,Event,ADDED,eval-conflicts-rho020-r0-007-4h55j.18d4677fad3bef47,reason=Created count=1 msg=Created container: task
0.3369,Event,ADDED,eval-conflicts-rho020-r0-007-4h55j.18d4677faf195392,reason=Started count=1 msg=Started container task
0.3372,Event,ADDED,eval-conflicts-rho020-r0-007.18d4677f92ecf379,reason=SuccessfulCreate count=1 msg=Created pod: eval-conflicts-rho020-r0-007-4h55j
0.3375,Event,ADDED,eval-conflicts-rho020-r0-007.18d46782f03ee197,reason=Completed count=1 msg=Job completed
0.3376,Event,ADDED,eval-conflicts-rho020-r0-008-qndfq.18d4677fceef9a49,reason=Scheduled count=None msg=Successfully assigned compute/eval-conflicts-rho020-r0-008-qndfq to kind-worker3
0.3378,Event,ADDED,eval-conflicts-rho020-r0-008-qndfq.18d4677fe8035067,"reason=Pulled count=1 msg=Container image ""busybox:musl"" already present on machine"
0.338,Event,ADDED,eval-conflicts-rho020-r0-008-qndfq.18d4677fe9169a5c,reason=Created count=1 msg=Created container: task
0.3382,Event,ADDED,eval-conflicts-rho020-r0-008-qndfq.18d4677feb10bfa7,reason=Started count=1 msg=Started container task
0.3384,Event,ADDED,eval-conflicts-rho020-r0-008.18d4677fce46e424,reason=SuccessfulCreate count=1 msg=Created pod: eval-conflicts-rho020-r0-008-qndfq
0.3385,Event,ADDED,eval-conflicts-rho020-r0-008.18d467832c264621,reason=Completed count=1 msg=Job completed
0.3387,Event,ADDED,eval-conflicts-rho020-r0-009-zxncj.18d467800a9fb5f9,"reason=FailedScheduling count=None msg=0/6 nodes are available: 1 c_wall violated: 1 conflicting context pair(s) with node memory, 5 node(s) had untolerated taint(s). no new claims to deallocate, preemption: 0/6 nodes are available: 1 No preemption victims found for incoming pod, 5 Preemption is not helpful for scheduling."
0.3389,Event,ADDED,eval-conflicts-rho020-r0-009-zxncj.18d467800b432771,"reason=FailedScheduling count=None msg=0/6 nodes are available: 1 c_wall violated: 1 conflicting context pair(s) with node memory, 5 node(s) had untolerated taint(s). no new claims to deallocate, preemption: 0/6 nodes are available: 1 No preemption victims found for incoming pod, 5 Preemption is not helpful for scheduling."
0.339,Event,ADDED,eval-conflicts-rho020-r0-009-zxncj.18d46781c3e952bf,reason=Scheduled count=None msg=Successfully assigned compute/eval-conflicts-rho020-r0-009-zxncj to kind-worker
0.3392,Event,ADDED,eval-conflicts-rho020-r0-009-zxncj.18d46781dd5e06d8,"reason=Pulled count=1 msg=Container image ""busybox:musl"" already present on machine"
0.3394,Event,ADDED,eval-conflicts-rho020-r0-009-zxncj.18d46781dee189c6,reason=Created count=1 msg=Created container: task
0.3395,Event,ADDED,eval-conflicts-rho020-r0-009-zxncj.18d46781e6f55e29,reason=Started count=1 msg=Started container task
0.3398,Event,ADDED,eval-conflicts-rho020-r0-009.18d467800a5b0570,reason=SuccessfulCreate count=1 msg=Created pod: eval-conflicts-rho020-r0-009-zxncj
0.34,Event,ADDED,eval-conflicts-rho020-r0-009.18d46784f252aad4,reason=Completed count=1 msg=Job completed
0.3402,Event,ADDED,eval-conflicts-rho020-r0-010-ffhc2.18d467804617ed0b,"reason=FailedScheduling count=None msg=0/6 nodes are available: 1 c_wall violated: 1 conflicting context pair(s) with node memory, 5 node(s) had untolerated taint(s). no new claims to deallocate, preemption: 0/6 nodes are available: 1 No preemption victims found for incoming pod, 5 Preemption is not helpful for scheduling."
0.3404,Event,ADDED,eval-conflicts-rho020-r0-010-ffhc2.18d4678046a0b30f,"reason=FailedScheduling count=None msg=0/6 nodes are available: 1 c_wall violated: 1 conflicting context pair(s) with node memory, 5 node(s) had untolerated taint(s). no new claims to deallocate, preemption: 0/6 nodes are available: 1 No preemption victims found for incoming pod, 5 Preemption is not helpful for scheduling."
0.3406,Event,ADDED,eval-conflicts-rho020-r0-010-ffhc2.18d46781c3d04e49,"reason=FailedScheduling count=None msg=0/6 nodes are available: 1 c_wall violated: 1 conflicting context pair(s) with node memory, 5 node(s) had untolerated taint(s). no new claims to deallocate, preemption: 0/6 nodes are available: 1 No preemption victims found for incoming pod, 5 Preemption is not helpful for scheduling."
0.3408,Event,ADDED,eval-conflicts-rho020-r0-010-ffhc2.18d46781c544228f,"reason=FailedScheduling count=None msg=0/6 nodes are available: 1 c_wall violated: 1 conflicting context pair(s) with node memory, 5 node(s) had untolerated taint(s). no new claims to deallocate, preemption: 0/6 nodes are available: 1 No preemption victims found for incoming pod, 5 Preemption is not helpful for scheduling."
0.341,Event,ADDED,eval-conflicts-rho020-r0-010-ffhc2.18d46782387c5ba3,reason=Scheduled count=None msg=Successfully assigned compute/eval-conflicts-rho020-r0-010-ffhc2 to kind-worker5
0.3412,Event,ADDED,eval-conflicts-rho020-r0-010-ffhc2.18d467824de2b1d5,"reason=Pulled count=1 msg=Container image ""busybox:musl"" already present on machine"
0.3413,Event,ADDED,eval-conflicts-rho020-r0-010-ffhc2.18d467824f3bf78c,reason=Created count=1 msg=Created container: task
0.3415,Event,ADDED,eval-conflicts-rho020-r0-010-ffhc2.18d4678253523def,reason=Started count=1 msg=Started container task
0.3416,Event,ADDED,eval-conflicts-rho020-r0-010.18d4678045c9a350,reason=SuccessfulCreate count=1 msg=Created pod: eval-conflicts-rho020-r0-010-ffhc2
0.342,Event,ADDED,eval-conflicts-rho020-r0-010.18d4678532ebb830,reason=Completed count=1 msg=Job completed
0.3421,Event,ADDED,eval-conflicts-rho020-r0-011-zr7jb.18d46780818c131b,"reason=FailedScheduling count=None msg=0/6 nodes are available: 1 c_wall violated: 1 conflicting context pair(s) with node memory, 5 node(s) had untolerated taint(s). no new claims to deallocate, preemption: 0/6 nodes are available: 1 No preemption victims found for incoming pod, 5 Preemption is not helpful for scheduling."
0.3424,Event,ADDED,eval-conflicts-rho020-r0-011-zr7jb.18d46780821d636f,"reason=FailedScheduling count=None msg=0/6 nodes are available: 1 c_wall violated: 1 conflicting context pair(s) with node memory, 5 node(s) had untolerated taint(s). no new claims to deallocate, preemption: 0/6 nodes are available: 1 No preemption victims found for incoming pod, 5 Preemption is not helpful for scheduling."
0.3426,Event,ADDED,eval-conflicts-rho020-r0-011-zr7jb.18d46781c4c1f5ef,reason=Scheduled count=None msg=Successfully assigned compute/eval-conflicts-rho020-r0-011-zr7jb to kind-worker
0.3427,Event,ADDED,eval-conflicts-rho020-r0-011-zr7jb.18d46781de5d5ecb,"reason=Pulled count=1 msg=Container image ""busybox:musl"" already present on machine"
0.3429,Event,ADDED,eval-conflicts-rho020-r0-011-zr7jb.18d46781e0257c15,reason=Created count=1 msg=Created container: task
0.3432,Event,ADDED,eval-conflicts-rho020-r0-011-zr7jb.18d46781e30573ac,reason=Started count=1 msg=Started container task
0.3434,Event,ADDED,eval-conflicts-rho020-r0-011.18d46780814e46fc,reason=SuccessfulCreate count=1 msg=Created pod: eval-conflicts-rho020-r0-011-zr7jb
0.3436,Event,ADDED,eval-conflicts-rho020-r0-011.18d467852ce0d855,reason=Completed count=1 msg=Job completed
0.3437,Event,ADDED,eval-conflicts-rho020-r0-012-xjx5d.18d46780bd8f4962,reason=Scheduled count=None msg=Successfully assigned compute/eval-conflicts-rho020-r0-012-xjx5d to kind-worker3
0.344,Event,ADDED,eval-conflicts-rho020-r0-012-xjx5d.18d46780d6d5a409,"reason=Pulled count=1 msg=Container image ""busybox:musl"" already present on machine"
0.3441,Event,ADDED,eval-conflicts-rho020-r0-012-xjx5d.18d46780d7fb2525,reason=Created count=1 msg=Created container: task
0.3443,Event,ADDED,eval-conflicts-rho020-r0-012-xjx5d.18d46780da244268,reason=Started count=1 msg=Started container task
0.3445,Event,ADDED,eval-conflicts-rho020-r0-012.18d46780bd079552,reason=SuccessfulCreate count=1 msg=Created pod: eval-conflicts-rho020-r0-012-xjx5d
0.3447,Event,ADDED,eval-conflicts-rho020-r0-012.18d467841bdc13ad,reason=Completed count=1 msg=Job completed
0.3449,Event,ADDED,eval-conflicts-rho020-r0-013-fkznw.18d46780f8a3e38d,reason=Scheduled count=None msg=Successfully assigned compute/eval-conflicts-rho020-r0-013-fkznw to kind-worker3
0.345,Event,ADDED,eval-conflicts-rho020-r0-013-fkznw.18d46781120ae587,"reason=Pulled count=1 msg=Container image ""busybox:musl"" already present on machine"
0.3452,Event,ADDED,eval-conflicts-rho020-r0-013-fkznw.18d46781132683e4,reason=Created count=1 msg=Created container: task
0.3454,Event,ADDED,eval-conflicts-rho020-r0-013-fkznw.18d4678117ebf3a1,reason=Started count=1 msg=Started container task
0.3456,Event,ADDED,eval-conflicts-rho020-r0-013.18d46780f81d63dc,reason=SuccessfulCreate count=1 msg=Created pod: eval-conflicts-rho020-r0-013-fkznw
0.3458,Event,ADDED,eval-conflicts-rho020-r0-013.18d4678457afd53e,reason=Completed count=1 msg=Job completed
0.3459,Event,ADDED,eval-conflicts-rho020-r0-014-7j25q.18d4678134b91386,reason=Scheduled count=None msg=Successfully assigned compute/eval-conflicts-rho020-r0-014-7j25q to kind-worker3
0.3461,Event,ADDED,eval-conflicts-rho020-r0-014-7j25q.18d467814f1da493,"reason=Pulled count=1 msg=Container image ""busybox:musl"" already present on machine"
0.3463,Event,ADDED,eval-conflicts-rho020-r0-014-7j25q.18d46781503e0fd2,reason=Created count=1 msg=Created container: task
0.3464,Event,ADDED,eval-conflicts-rho020-r0-014-7j25q.18d46781523f20e8,reason=Started count=1 msg=Started container task
0.3466,Event,ADDED,eval-conflicts-rho020-r0-014.18d4678134192679,reason=SuccessfulCreate count=1 msg=Created pod: eval-conflicts-rho020-r0-014-7j25q
0.3468,Event,ADDED,eval-conflicts-rho020-r0-014.18d4678493171321,reason=Completed count=1 msg=Job completed
0.35,Event,ADDED,eval-conflicts-rho020-r0-015-8jmzp.18d46781700cde5f,"reason=FailedScheduling count=None msg=0/6 nodes are available: 1 c_wall violated: 1 conflicting context pair(s) with node memory, 5 node(s) had untolerated taint(s). no new claims to deallocate, preemption: 0/6 nodes are available: 1 No preemption victims found for incoming pod, 5 Preemption is not helpful for scheduling."
0.3503,Event,ADDED,eval-conflicts-rho020-r0-015-8jmzp.18d46781710dc5ff,"reason=FailedScheduling count=None msg=0/6 nodes are available: 1 c_wall violated: 1 conflicting context pair(s) with node memory, 5 node(s) had untolerated taint(s). no new claims to deallocate, preemption: 0/6 nodes are available: 1 No preemption victims found for incoming pod, 5 Preemption is not helpful for scheduling."
0.3505,Event,ADDED,eval-conflicts-rho020-r0-015-8jmzp.18d46781c4de5f1a,reason=Scheduled count=None msg=Successfully assigned compute/eval-conflicts-rho020-r0-015-8jmzp to kind-worker
0.3507,Event,ADDED,eval-conflicts-rho020-r0-015-8jmzp.18d46781de426ec3,"reason=Pulled count=1 msg=Container image ""busybox:musl"" already present on machine"
0.3509,Event,ADDED,eval-conflicts-rho020-r0-015-8jmzp.18d46781dfd56990,reason=Created count=1 msg=Created container: task
0.3511,Event,ADDED,eval-conflicts-rho020-r0-015-8jmzp.18d46781e301dc65,reason=Started count=1 msg=Started container task
0.3513,Event,ADDED,eval-conflicts-rho020-r0-015.18d467816fcfe0f6,reason=SuccessfulCreate count=1 msg=Created pod: eval-conflicts-rho020-r0-015-8jmzp
0.3514,Event,ADDED,eval-conflicts-rho020-r0-015.18d46784f0e7a985,reason=Completed count=1 msg=Job completed
0.3516,Event,ADDED,eval-conflicts-rho020-r0-016-lqmf8.18d46781ab551664,"reason=FailedScheduling count=None msg=0/6 nodes are available: 6 node(s) had untolerated taint(s). no new claims to deallocate, preemption: 0/6 nodes are available: 6 Preemption is not helpful for scheduling."
0.3518,Event,ADDED,eval-conflicts-rho020-r0-016-lqmf8.18d46781c4afeeef,"reason=FailedScheduling count=None msg=0/6 nodes are available: 1 c_wall violated: 1 conflicting context pair(s) with node memory, 5 node(s) had untolerated taint(s). no new claims to deallocate, preemption: 0/6 nodes are available: 1 No preemption victims found for incoming pod, 5 Preemption is not helpful for scheduling."
0.3519,Event,ADDED,eval-conflicts-rho020-r0-016-lqmf8.18d46781c57804e1,"reason=FailedScheduling count=None msg=0/6 nodes are available: 1 c_wall violated: 1 conflicting context pair(s) with node memory, 5 node(s) had untolerated taint(s). no new claims to deallocate, preemption: 0/6 nodes are available: 1 No preemption victims found for incoming pod, 5 Preemption is not helpful for scheduling."
0.3521,Event,ADDED,eval-conflicts-rho020-r0-016-lqmf8.18d4678238cdd8f4,reason=Scheduled count=None msg=Successfully assigned compute/eval-conflicts-rho020-r0-016-lqmf8 to kind-worker5
0.3523,Event,ADDED,eval-conflicts-rho020-r0-016-lqmf8.18d467825449455c,"reason=Pulled count=1 msg=Container image ""busybox:musl"" already present on machine"
0.3524,Event,ADDED,eval-conflicts-rho020-r0-016-lqmf8.18d46782555be1e2,reason=Created count=1 msg=Created container: task
0.3526,Event,ADDED,eval-conflicts-rho020-r0-016-lqmf8.18d4678258fac059,reason=Started count=1 msg=Started container task
0.3528,Event,ADDED,eval-conflicts-rho020-r0-016.18d46781ab4f6cc5,reason=SuccessfulCreate count=1 msg=Created pod: eval-conflicts-rho020-r0-016-lqmf8
0.3529,Event,ADDED,eval-conflicts-rho020-r0-016.18d4678533c7f5e2,reason=Completed count=1 msg=Job completed
0.3531,Event,ADDED,eval-conflicts-rho020-r0-017-d87dk.18d46781e79636c0,reason=Scheduled count=None msg=Successfully assigned compute/eval-conflicts-rho020-r0-017-d87dk to kind-worker
0.3533,Event,ADDED,eval-conflicts-rho020-r0-017-d87dk.18d4678200d18614,"reason=Pulled count=1 msg=Container image ""busybox:musl"" already present on machine"
0.3534,Event,ADDED,eval-conflicts-rho020-r0-017-d87dk.18d4678201f89794,reason=Created count=1 msg=Created container: task
0.3536,Event,ADDED,eval-conflicts-rho020-r0-017-d87dk.18d4678203ff288a,reason=Started count=1 msg=Started container task
0.3538,Event,ADDED,eval-conflicts-rho020-r0-017.18d46781e70dffeb,reason=SuccessfulCreate count=1 msg=Created pod: eval-conflicts-rho020-r0-017-d87dk
0.354,Event,ADDED,eval-conflicts-rho020-r0-017.18d467852c33682d,reason=Completed count=1 msg=Job completed
0.3541,Event,ADDED,eval-conflicts-rho020-r0-018-wjgg6.18d46782230fe948,reason=Scheduled count=None msg=Successfully assigned compute/eval-conflicts-rho020-r0-018-wjgg6 to kind-worker
0.3543,Event,ADDED,eval-conflicts-rho020-r0-018-wjgg6.18d467823da6822b,"reason=Pulled count=1 msg=Container image ""busybox:musl"" already present on machine"
0.3545,Event,ADDED,eval-conflicts-rho020-r0-018-wjgg6.18d467823ec44021,reason=Created count=1 msg=Created container: task
0.3546,Event,ADDED,eval-conflicts-rho020-r0-018-wjgg6.18d4678240c4cf36,reason=Started count=1 msg=Started container task
0.3548,Event,ADDED,eval-conflicts-rho020-r0-018.18d4678222812151,reason=SuccessfulCreate count=1 msg=Created pod: eval-conflicts-rho020-r0-018-wjgg6
0.355,Event,ADDED,eval-conflicts-rho020-r0-018.18d467852d0a668c,reason=Completed count=1 msg=Job completed
0.3552,Event,ADDED,eval-conflicts-rho020-r0-019-wb9vv.18d467825e5b856f,"reason=FailedScheduling count=None msg=0/6 nodes are available: 2 c_wall violated: 1 conflicting context pair(s) with node memory, 4 node(s) had untolerated taint(s). no new claims to deallocate, preemption: 0/6 nodes are available: 2 No preemption victims found for incoming pod, 4 Preemption is not helpful for scheduling."
0.3554,Event,ADDED,eval-conflicts-rho020-r0-019-wb9vv.18d467825f0e7cdd,"reason=FailedScheduling count=None msg=0/6 nodes are available: 2 c_wall violated: 1 conflicting context pair(s) with node memory, 4 node(s) had untolerated taint(s). no new claims to deallocate, preemption: 0/6 nodes are available: 2 No preemption victims found for incoming pod, 4 Preemption is not helpful for scheduling."
0.3556,Event,ADDED,eval-conflicts-rho020-r0-019-wb9vv.18d46783132af16f,"reason=FailedScheduling count=None msg=0/6 nodes are available: 1 c_wall violated: 1 conflicting context pair(s) with node memory, 1 c_wall violated: 2 conflicting context pair(s) with node memory, 4 node(s) had untolerated taint(s). no new claims to deallocate, preemption: 0/6 nodes are available: 2 No preemption victims found for incoming pod, 4 Preemption is not helpful for scheduling."
0.3558,Event,ADDED,eval-conflicts-rho020-r0-019-wb9vv.18d467841fd893ad,"reason=FailedScheduling count=None msg=0/6 nodes are available: 1 c_wall violated: 2 conflicting context pair(s) with node memory, 5 node(s) had untolerated taint(s). no new claims to deallocate, preemption: 0/6 nodes are available: 1 No preemption victims found for incoming pod, 5 Preemption is not helpful for scheduling."
0.3559,Event,ADDED,eval-conflicts-rho020-r0-019-wb9vv.18d467843caa8792,reason=Scheduled count=None msg=Successfully assigned compute/eval-conflicts-rho020-r0-019-wb9vv to kind-worker4
0.3561,Event,ADDED,eval-conflicts-rho020-r0-019-wb9vv.18d46784569afcdd,"reason=Pulled count=1 msg=Container image ""busybox:musl"" already present on machine"
0.3563,Event,ADDED,eval-conflicts-rho020-r0-019-wb9vv.18d46784588c75da,reason=Created count=1 msg=Created container: task
0.3564,Event,ADDED,eval-conflicts-rho020-r0-019-wb9vv.18d467845c47385c,reason=Started count=1 msg=Started container task
0.3566,Event,ADDED,eval-conflicts-rho020-r0-019.18d467825de63a80,reason=SuccessfulCreate count=1 msg=Created pod: eval-conflicts-rho020-r0-019-wb9vv
0.3568,Event,ADDED,eval-conflicts-rho020-r0-019.18d467878e8e0a25,reason=Completed count=1 msg=Job completed
0.3569,Event,ADDED,eval-conflicts-rho020-r0-020-4cppg.18d467829a842425,reason=Scheduled count=None msg=Successfully assigned compute/eval-conflicts-rho020-r0-020-4cppg to kind-worker5
0.3571,Event,ADDED,eval-conflicts-rho020-r0-020-4cppg.18d46782b3bf6071,"reason=Pulled count=1 msg=Container image ""busybox:musl"" already present on machine"
0.3572,Event,ADDED,eval-conflicts-rho020-r0-020-4cppg.18d46782b529650b,reason=Created count=1 msg=Created container: task
0.3574,Event,ADDED,eval-conflicts-rho020-r0-020-4cppg.18d46782b90ef460,reason=Started count=1 msg=Started container task
0.3576,Event,ADDED,eval-conflicts-rho020-r0-020.18d4678299af8ce5,reason=SuccessfulCreate count=1 msg=Created pod: eval-conflicts-rho020-r0-020-4cppg
0.3578,Event,ADDED,eval-conflicts-rho020-r0-020.18d46785e7c05013,reason=Completed count=1 msg=Job completed
0.358,Event,ADDED,eval-conflicts-rho020-r0-021-f572g.18d46782d64fab06,reason=Scheduled count=None msg=Successfully assigned compute/eval-conflicts-rho020-r0-021-f572g to kind-worker5
0.3581,Event,ADDED,eval-conflicts-rho020-r0-021-f572g.18d46782efabf437,"reason=Pulled count=1 msg=Container image ""busybox:musl"" already present on machine"
0.3583,Event,ADDED,eval-conflicts-rho020-r0-021-f572g.18d46782f1117544,reason=Created count=1 msg=Created container: task
0.3585,Event,ADDED,eval-conflicts-rho020-r0-021-f572g.18d46782f44886cf,reason=Started count=1 msg=Started container task
0.3586,Event,ADDED,eval-conflicts-rho020-r0-021.18d46782d51c664d,reason=SuccessfulCreate count=1 msg=Created pod: eval-conflicts-rho020-r0-021-f572g
0.3588,Event,ADDED,eval-conflicts-rho020-r0-021.18d4678623872364,reason=Completed count=1 msg=Job completed
0.3589,Event,ADDED,eval-conflicts-rho020-r0-022-mcvjk.18d46783117373e5,reason=Scheduled count=None msg=Successfully assigned compute/eval-conflicts-rho020-r0-022-mcvjk to kind-worker5
0.3591,Event,ADDED,eval-conflicts-rho020-r0-022-mcvjk.18d467832c9191b8,"reason=Pulled count=1 msg=Container image ""busybox:musl"" already present on machine"
0.3593,Event,ADDED,eval-conflicts-rho020-r0-022-mcvjk.18d467832ded4c2e,reason=Created count=1 msg=Created container: task
0.3594,Event,ADDED,eval-conflicts-rho020-r0-022-mcvjk.18d4678333edeaab,reason=Started count=1 msg=Started container task
0.3596,Event,ADDED,eval-conflicts-rho020-r0-022.18d46783108eb6bb,reason=SuccessfulCreate count=1 msg=Created pod: eval-conflicts-rho020-r0-022-mcvjk
0.3598,Event,ADDED,eval-conflicts-rho020-r0-022.18d467865fed67d9,reason=Completed count=1 msg=Job completed
0.3599,Event,ADDED,eval-conflicts-rho020-r0-023-rts7d.18d467834ce0fa62,"reason=FailedScheduling count=None msg=0/6 nodes are available: 1 c_wall violated: 1 conflicting context pair(s) with node memory, 1 c_wall violated: 2 conflicting context pair(s) with node memory, 4 node(s) had untolerated taint(s). no new claims to deallocate, preemption: 0/6 nodes are available: 2 No preemption victims found for incoming pod, 4 Preemption is not helpful for scheduling."
0.3601,Event,ADDED,eval-conflicts-rho020-r0-023-rts7d.18d467834dbf6df4,"reason=FailedScheduling count=None msg=0/6 nodes are available: 1 c_wall violated: 1 conflicting context pair(s) with node memory, 1 c_wall violated: 2 conflicting context pair(s) with node memory, 4 node(s) had untolerated taint(s). no new claims to deallocate, preemption: 0/6 nodes are available: 2 No preemption victims found for incoming pod, 4 Preemption is not helpful for scheduling."
0.3603,Event,ADDED,eval-conflicts-rho020-r0-023-rts7d.18d46784200331d8,"reason=FailedScheduling count=None msg=0/6 nodes are available: 1 c_wall violated: 2 conflicting context pair(s) with node memory, 5 node(s) had untolerated taint(s). no new claims to deallocate, preemption: 0/6 nodes are available: 1 No preemption victims found for incoming pod, 5 Preemption is not helpful for scheduling."
0.3604,Event,ADDED,eval-conflicts-rho020-r0-023-rts7d.18d467843ceab57e,reason=Scheduled count=None msg=Successfully assigned compute/eval-conflicts-rho020-r0-023-rts7d to kind-worker4
0.3606,Event,ADDED,eval-conflicts-rho020-r0-023-rts7d.18d4678457340cb9,"reason=Pulled count=1 msg=Container image ""busybox:musl"" already present on machine"
0.3608,Event,ADDED,eval-conflicts-rho020-r0-023-rts7d.18d46784592b95f6,reason=Created count=1 msg=Created container: task
0.3609,Event,ADDED,eval-conflicts-rho020-r0-023-rts7d.18d4678460eb750e,reason=Started count=1 msg=Started container task
0.3612,Event,ADDED,eval-conflicts-rho020-r0-023.18d467834c647a43,reason=SuccessfulCreate count=1 msg=Created pod: eval-conflicts-rho020-r0-023-rts7d
0.3613,Event,ADDED,eval-conflicts-rho020-r0-023.18d467878e8f2941,reason=Completed count=1 msg=Job completed
0.3615,Event,ADDED,eval-conflicts-rho020-r0-024-6fk82.18d46783891fd016,"reason=FailedScheduling count=None msg=0/6 nodes are available: 1 c_wall violated: 1 conflicting context pair(s) with node memory, 1 c_wall violated: 2 conflicting context pair(s) with node memory, 4 node(s) had untolerated taint(s). no new claims to deallocate, preemption: 0/6 nodes are available: 2 No preemption victims found for incoming pod, 4 Preemption is not helpful for scheduling."
0.3617,Event,ADDED,eval-conflicts-rho020-r0-024-6fk82.18d4678389cd5f22,"reason=FailedScheduling count=None msg=0/6 nodes are available: 1 c_wall violated: 1 conflicting context pair(s) with node memory, 1 c_wall violated: 2 conflicting context pair(s) with node memory, 4 node(s) had untolerated taint(s). no new claims to deallocate, preemption: 0/6 nodes are available: 2 No preemption victims found for incoming pod, 4 Preemption is not helpful for scheduling."
0.3619,Event,ADDED,eval-conflicts-rho020-r0-024-6fk82.18d467841faa5aed,"reason=FailedScheduling count=None msg=0/6 nodes are available: 1 c_wall violated: 2 conflicting context pair(s) with node memory, 5 node(s) had untolerated taint(s). no new claims to deallocate, preemption: 0/6 nodes are available: 1 No preemption victims found for incoming pod, 5 Preemption is not helpful for scheduling."
0.3621,Event,ADDED,eval-conflicts-rho020-r0-024-6fk82.18d4678442c3b4c3,reason=Scheduled count=None msg=Successfully assigned compute/eval-conflicts-rho020-r0-024-6fk82 to kind-worker4
0.3623,Event,ADDED,eval-conflicts-rho020-r0-024-6fk82.18d467845e9d62a7,"reason=Pulled count=1 msg=Container image ""busybox:musl"" already present on machine"
0.3625,Event,ADDED,eval-conflicts-rho020-r0-024-6fk82.18d467845fd428ea,reason=Created count=1 msg=Created container: task
0.3627,Event,ADDED,eval-conflicts-rho020-r0-024-6fk82.18d46784621143a7,reason=Started count=1 msg=Started container task
0.3628,Event,ADDED,eval-conflicts-rho020-r0-024.18d4678388a8318f,reason=SuccessfulCreate count=1 msg=Created pod: eval-conflicts-rho020-r0-024-6fk82
0.363,Event,ADDED,eval-conflicts-rho020-r0-024.18d467878e683954,reason=Completed count=1 msg=Job completed
0.3631,Event,ADDED,eval-conflicts-rho020-r0-025-jnppp.18d46783c442975f,reason=Scheduled count=None msg=Successfully assigned compute/eval-conflicts-rho020-r0-025-jnppp to kind-worker
0.3633,Event,ADDED,eval-conflicts-rho020-r0-025-jnppp.18d46783ddbe4a36,"reason=Pulled count=1 msg=Container image ""busybox:musl"" already present on machine"
0.3635,Event,ADDED,eval-conflicts-rho020-r0-025-jnppp.18d46783df15149e,reason=Created count=1 msg=Created container: task
0.3636,Event,ADDED,eval-conflicts-rho020-r0-025-jnppp.18d46783e79a5db5,reason=Started count=1 msg=Started container task
0.3638,Event,ADDED,eval-conflicts-rho020-r0-025.18d46783c3916916,reason=SuccessfulCreate count=1 msg=Created pod: eval-conflicts-rho020-r0-025-jnppp
0.364,Event,ADDED,eval-conflicts-rho020-r0-025.18d467870c3791a8,reason=Completed count=1 msg=Job completed
0.3641,Event,ADDED,eval-conflicts-rho020-r0-026-8psns.18d467840015dc6b,reason=Scheduled count=None msg=Successfully assigned compute/eval-conflicts-rho020-r0-026-8psns to kind-worker
0.3643,Event,ADDED,eval-conflicts-rho020-r0-026-8psns.18d467841a1876ad,"reason=Pulled count=1 msg=Container image ""busybox:musl"" already present on machine"
0.3644,Event,ADDED,eval-conflicts-rho020-r0-026-8psns.18d467841bc0039c,reason=Created count=1 msg=Created container: task
0.3647,Event,ADDED,eval-conflicts-rho020-r0-026-8psns.18d46784213d5988,reason=Started count=1 msg=Started container task
0.3648,Event,ADDED,eval-conflicts-rho020-r0-026.18d46783ff5b1c27,reason=SuccessfulCreate count=1 msg=Created pod: eval-conflicts-rho020-r0-026-8psns
0.3651,Event,ADDED,eval-conflicts-rho020-r0-026.18d46787484d4320,reason=Completed count=1 msg=Job completed
0.3653,Event,ADDED,eval-conflicts-rho020-r0-027-h6pl5.18d467843aede448,"reason=FailedScheduling count=None msg=0/6 nodes are available: 1 c_wall violated: 1 conflicting context pair(s) with node memory, 5 node(s) had untolerated taint(s). no new claims to deallocate, preemption: 0/6 nodes are available: 1 No preemption victims found for incoming pod, 5 Preemption is not helpful for scheduling."
0.3655,Event,ADDED,eval-conflicts-rho020-r0-027-h6pl5.18d467843b9dfcd2,"reason=FailedScheduling count=None msg=0/6 nodes are available: 1 c_wall violated: 1 conflicting context pair(s) with node memory, 5 node(s) had untolerated taint(s). no new claims to deallocate, preemption: 0/6 nodes are available: 1 No preemption victims found for incoming pod, 5 Preemption is not helpful for scheduling."
0.3656,Event,ADDED,eval-conflicts-rho020-r0-027-h6pl5.18d4678442baa4f8,"reason=FailedScheduling count=None msg=0/6 nodes are available: 2 c_wall violated: 1 conflicting context pair(s) with node memory, 4 node(s) had untolerated taint(s). no new claims to deallocate, preemption: 0/6 nodes are available: 2 No preemption victims found for incoming pod, 4 Preemption is not helpful for scheduling."
0.3658,Event,ADDED,eval-conflicts-rho020-r0-027-h6pl5.18d4678448f024fd,reason=Scheduled count=None msg=Successfully assigned compute/eval-conflicts-rho020-r0-027-h6pl5 to kind-worker2
0.366,Event,ADDED,eval-conflicts-rho020-r0-027-h6pl5.18d4678461fe1fc5,"reason=Pulled count=1 msg=Container image ""busybox:musl"" already present on machine"
0.3661,Event,ADDED,eval-conflicts-rho020-r0-027-h6pl5.18d467846336f8a6,reason=Created count=1 msg=Created container: task
0.3663,Event,ADDED,eval-conflicts-rho020-r0-027-h6pl5.18d4678465a0a3fa,reason=Started count=1 msg=Started container task
0.3665,Event,ADDED,eval-conflicts-rho020-r0-027.18d467843aad6b2c,reason=SuccessfulCreate count=1 msg=Created pod: eval-conflicts-rho020-r0-027-h6pl5
0.3666,Event,ADDED,eval-conflicts-rho020-r0-027.18d467877a571b3e,reason=Completed count=1 msg=Job completed
0.3668,Event,ADDED,eval-conflicts-rho020-r0-028-2bsts.18d46784787cafc9,reason=Scheduled count=None msg=Successfully assigned compute/eval-conflicts-rho020-r0-028-2bsts to kind-worker5
0.3669,Event,ADDED,eval-conflicts-rho020-r0-028-2bsts.18d467849117f901,"reason=Pulled count=1 msg=Container image ""busybox:musl"" already present on machine"
0.3671,Event,ADDED,eval-conflicts-rho020-r0-028-2bsts.18d467849238834e,reason=Created count=1 msg=Created container: task
0.3673,Event,ADDED,eval-conflicts-rho020-r0-028-2bsts.18d467849454b50d,reason=Started count=1 msg=Started container task
0.3674,Event,ADDED,eval-conflicts-rho020-r0-028.18d4678476ae5df4,reason=SuccessfulCreate count=1 msg=Created pod: eval-conflicts-rho020-r0-028-2bsts
0.3676,Event,ADDED,eval-conflicts-rho020-r0-028.18d46787c5cdba45,reason=Completed count=1 msg=Job completed
0.3677,Event,ADDED,eval-conflicts-rho020-r0-029-wx5ws.18d46784b266adea,reason=Scheduled count=None msg=Successfully assigned compute/eval-conflicts-rho020-r0-029-wx5ws to kind-worker4
0.3679,Event,ADDED,eval-conflicts-rho020-r0-029-wx5ws.18d46784cb803750,"reason=Pulled count=1 msg=Container image ""busybox:musl"" already present on machine"
0.3681,Event,ADDED,eval-conflicts-rho020-r0-029-wx5ws.18d46784cc9e58e6,reason=Created count=1 msg=Created container: task
0.3682,Event,ADDED,eval-conflicts-rho020-r0-029-wx5ws.18d46784ce85f097,reason=Started count=1 msg=Started container task
0.3684,Event,ADDED,eval-conflicts-rho020-r0-029.18d46784b1d01d40,reason=SuccessfulCreate count=1 msg=Created pod: eval-conflicts-rho020-r0-029-wx5ws
0.3686,Event,ADDED,eval-conflicts-rho020-r0-029.18d4678806326fcd,reason=Completed count=1 msg=Job completed
0.3687,Event,ADDED,eval-conflicts-rho020-r0-030-9tszl.18d46784ee787be8,reason=Scheduled count=None msg=Successfully assigned compute/eval-conflicts-rho020-r0-030-9tszl to kind-worker2
0.3689,Event,ADDED,eval-conflicts-rho020-r0-030-9tszl.18d4678507cf58cd,"reason=Pulled count=1 msg=Container image ""busybox:musl"" already present on machine"
0.369,Event,ADDED,eval-conflicts-rho020-r0-030-9tszl.18d4678508d80f55,reason=Created count=1 msg=Created container: task
0.3692,Event,ADDED,eval-conflicts-rho020-r0-030-9tszl.18d467850f086535,reason=Started count=1 msg=Started container task
0.3694,Event,ADDED,eval-conflicts-rho020-r0-030.18d46784edb647e6,reason=SuccessfulCreate count=1 msg=Created pod: eval-conflicts-rho020-r0-030-9tszl
0.3695,Event,ADDED,eval-conflicts-rho020-r0-030.18d467882e6caf56,reason=Completed count=1 msg=Job completed
0.3697,Event,ADDED,eval-conflicts-rho020-r0-031-dh7tc.18d467852a5abc9f,"reason=FailedScheduling count=None msg=0/6 nodes are available: 2 c_wall violated: 1 conflicting context pair(s) with node memory, 4 node(s) had untolerated taint(s). no new claims to deallocate, preemption: 0/6 nodes are available: 2 No preemption victims found for incoming pod, 4 Preemption is not helpful for scheduling."
0.3699,Event,ADDED,eval-conflicts-rho020-r0-031-dh7tc.18d467852afb9a3d,"reason=FailedScheduling count=None msg=0/6 nodes are available: 2 c_wall violated: 1 conflicting context pair(s) with node memory, 4 node(s) had untolerated taint(s). no new claims to deallocate, preemption: 0/6 nodes are available: 2 No preemption victims found for incoming pod, 4 Preemption is not helpful for scheduling."
0.37,Event,ADDED,eval-conflicts-rho020-r0-031-dh7tc.18d467866d27f98d,reason=Scheduled count=None msg=Successfully assigned compute/eval-conflicts-rho020-r0-031-dh7tc to kind-worker3
0.3702,Event,ADDED,eval-conflicts-rho020-r0-031-dh7tc.18d4678686a89663,"reason=Pulled count=1 msg=Container image ""busybox:musl"" already present on machine"
0.3704,Event,ADDED,eval-conflicts-rho020-r0-031-dh7tc.18d4678687bf94c1,reason=Created count=1 msg=Created container: task
0.3705,Event,ADDED,eval-conflicts-rho020-r0-031-dh7tc.18d4678689992158,reason=Started count=1 msg=Started container task
0.3707,Event,ADDED,eval-conflicts-rho020-r0-031.18d4678529e95b84,reason=SuccessfulCreate count=1 msg=Created pod: eval-conflicts-rho020-r0-031-dh7tc
0.3709,Event,ADDED,eval-conflicts-rho020-r0-031.18d46789b5e7423b,reason=Completed count=1 msg=Job completed
0.371,Event,ADDED,eval-conflicts-rho020-r0-032-jl6pc.18d46785657aaa6d,reason=Scheduled count=None msg=Successfully assigned compute/eval-conflicts-rho020-r0-032-jl6pc to kind-worker2
0.3712,Event,ADDED,eval-conflicts-rho020-r0-032-jl6pc.18d467858128b5c0,"reason=Pulled count=1 msg=Container image ""busybox:musl"" already present on machine"
0.3713,Event,ADDED,eval-conflicts-rho020-r0-032-jl6pc.18d467858239d124,reason=Created count=1 msg=Created container: task
0.3715,Event,ADDED,eval-conflicts-rho020-r0-032-jl6pc.18d467858a95ada2,reason=Started count=1 msg=Started container task
0.3717,Event,ADDED,eval-conflicts-rho020-r0-032.18d4678564bd185f,reason=SuccessfulCreate count=1 msg=Created pod: eval-conflicts-rho020-r0-032-jl6pc
0.3719,Event,ADDED,eval-conflicts-rho020-r0-032.18d46788a5562990,reason=Completed count=1 msg=Job completed
0.372,Event,ADDED,eval-conflicts-rho020-r0-033-p69lz.18d46785a13465c6,reason=Scheduled count=None msg=Successfully assigned compute/eval-conflicts-rho020-r0-033-p69lz to kind-worker2
0.3722,Event,ADDED,eval-conflicts-rho020-r0-033-p69lz.18d46785ba10ece5,"reason=Pulled count=1 msg=Container image ""busybox:musl"" already present on machine"
0.3724,Event,ADDED,eval-conflicts-rho020-r0-033-p69lz.18d46785bb2d822d,reason=Created count=1 msg=Created container: task
0.3725,Event,ADDED,eval-conflicts-rho020-r0-033-p69lz.18d46785c0a77584,reason=Started count=1 msg=Started container task
0.3727,Event,ADDED,eval-conflicts-rho020-r0-033.18d46785a070a051,reason=SuccessfulCreate count=1 msg=Created pod: eval-conflicts-rho020-r0-033-p69lz
0.3729,Event,ADDED,eval-conflicts-rho020-r0-033.18d46788e1486561,reason=Completed count=1 msg=Job completed
0.373,Event,ADDED,eval-conflicts-rho020-r0-034-4lcrn.18d46785dd43ebf7,reason=Scheduled count=None msg=Successfully assigned compute/eval-conflicts-rho020-r0-034-4lcrn to kind-worker2
0.3732,Event,ADDED,eval-conflicts-rho020-r0-034-4lcrn.18d46785f6997600,"reason=Pulled count=1 msg=Container image ""busybox:musl"" already present on machine"
0.3733,Event,ADDED,eval-conflicts-rho020-r0-034-4lcrn.18d46785f7b4289f,reason=Created count=1 msg=Created container: task
0.3735,Event,ADDED,eval-conflicts-rho020-r0-034-4lcrn.18d46785fa98b367,reason=Started count=1 msg=Started container task
0.3737,Event,ADDED,eval-conflicts-rho020-r0-034.18d46785dc88a45f,reason=SuccessfulCreate count=1 msg=Created pod: eval-conflicts-rho020-r0-034-4lcrn
0.3738,Event,ADDED,eval-conflicts-rho020-r0-034.18d467891d988f30,reason=Completed count=1 msg=Job completed
0.374,Event,ADDED,eval-conflicts-rho020-r0-035-krgjj.18d4678618cd394f,reason=Scheduled count=None msg=Successfully assigned compute/eval-conflicts-rho020-r0-035-krgjj to kind-worker2
0.3742,Event,ADDED,eval-conflicts-rho020-r0-035-krgjj.18d4678630e5f7b6,"reason=Pulled count=1 msg=Container image ""busybox:musl"" already present on machine"
0.3744,Event,ADDED,eval-conflicts-rho020-r0-035-krgjj.18d4678632076155,reason=Created count=1 msg=Created container: task
0.3745,Event,ADDED,eval-conflicts-rho020-r0-035-krgjj.18d4678633e4c4fe,reason=Started count=1 msg=Started container task
0.3747,Event,ADDED,eval-conflicts-rho020-r0-035.18d46786178f63cb,reason=SuccessfulCreate count=1 msg=Created pod: eval-conflicts-rho020-r0-035-krgjj
0.3749,Event,ADDED,eval-conflicts-rho020-r0-035.18d46789590bb25d,reason=Completed count=1 msg=Job completed
0.375,Event,ADDED,eval-conflicts-rho020-r0-036-dkp5l.18d4678653b522a2,reason=Scheduled count=None msg=Successfully assigned compute/eval-conflicts-rho020-r0-036-dkp5l to kind-worker4
0.3752,Event,ADDED,eval-conflicts-rho020-r0-036-dkp5l.18d467866cbefb7e,"reason=Pulled count=1 msg=Container image ""busybox:musl"" already present on machine"
0.3754,Event,ADDED,eval-conflicts-rho020-r0-036-dkp5l.18d467866e1425a4,reason=Created count=1 msg=Created container: task
0.3755,Event,ADDED,eval-conflicts-rho020-r0-036-dkp5l.18d46786702b64a1,reason=Started count=1 msg=Started container task
0.3757,Event,ADDED,eval-conflicts-rho020-r0-036.18d4678652fc6e6f,reason=SuccessfulCreate count=1 msg=Created pod: eval-conflicts-rho020-r0-036-dkp5l
0.3759,Event,ADDED,eval-conflicts-rho020-r0-036.18d46789a79db4a2,reason=Completed count=1 msg=Job completed
0.376,Event,ADDED,eval-conflicts-rho020-r0-037-cjbnk.18d467868fc1b3d5,reason=Scheduled count=None msg=Successfully assigned compute/eval-conflicts-rho020-r0-037-cjbnk to kind-worker3
0.3762,Event,ADDED,eval-conflicts-rho020-r0-037-cjbnk.18d46786a8d837fb,"reason=Pulled count=1 msg=Container image ""busybox:musl"" already present on machine"
0.3765,Event,ADDED,eval-conflicts-rho020-r0-037-cjbnk.18d46786a9e2b82e,reason=Created count=1 msg=Created container: task
0.3768,Event,ADDED,eval-conflicts-rho020-r0-037-cjbnk.18d46786abdbaf14,reason=Started count=1 msg=Started container task
0.377,Event,ADDED,eval-conflicts-rho020-r0-037.18d467868e9cb0bc,reason=SuccessfulCreate count=1 msg=Created pod: eval-conflicts-rho020-r0-037-cjbnk
0.3772,Event,ADDED,eval-conflicts-rho020-r0-037.18d46789f2b3830a,reason=Completed count=1 msg=Job completed
0.3773,Event,ADDED,eval-conflicts-rho020-r0-038-rf2lq.18d46786cab8325f,reason=Scheduled count=None msg=Successfully assigned compute/eval-conflicts-rho020-r0-038-rf2lq to kind-worker3
0.3777,Event,ADDED,eval-conflicts-rho020-r0-038-rf2lq.18d46786e42b14b4,"reason=Pulled count=1 msg=Container image ""busybox:musl"" already present on machine"
0.3779,Event,ADDED,eval-conflicts-rho020-r0-038-rf2lq.18d46786e534d87d,reason=Created count=1 msg=Created container: task
0.378,Event,ADDED,eval-conflicts-rho020-r0-038-rf2lq.18d46786e9cb9466,reason=Started count=1 msg=Started container task
0.3782,Event,ADDED,eval-conflicts-rho020-r0-038.18d46786ca34171c,reason=SuccessfulCreate count=1 msg=Created pod: eval-conflicts-rho020-r0-038-rf2lq
0.3785,Event,ADDED,eval-conflicts-rho020-r0-038.18d4678a2e819ba6,reason=Completed count=1 msg=Job completed
0.3787,Event,ADDED,eval-conflicts-rho020-r0-039-zbn6l.18d4678706716d6d,reason=Scheduled count=None msg=Successfully assigned compute/eval-conflicts-rho020-r0-039-zbn6l to kind-worker3
0.3789,Event,ADDED,eval-conflicts-rho020-r0-039-zbn6l.18d467872008f4bd,"reason=Pulled count=1 msg=Container image ""busybox:musl"" already present on machine"
0.3791,Event,ADDED,eval-conflicts-rho020-r0-039-zbn6l.18d46787211e8285,reason=Created count=1 msg=Created container: task
0.3793,Event,ADDED,eval-conflicts-rho020-r0-039-zbn6l.18d46787233f93ad,reason=Started count=1 msg=Started container task
0.3794,Event,ADDED,eval-conflicts-rho020-r0-039.18d4678705e5e5a4,reason=SuccessfulCreate count=1 msg=Created pod: eval-conflicts-rho020-r0-039-zbn6l
0.3796,Event,ADDED,eval-conflicts-rho020-r0-039.18d4678a2d9a1afc,reason=Completed count=1 msg=Job completed
0.3798,Event,ADDED,eval-conflicts-rho020-r0-040-57xfx.18d4678742632be2,reason=Scheduled count=None msg=Successfully assigned compute/eval-conflicts-rho020-r0-040-57xfx to kind-worker3
0.38,Event,ADDED,eval-conflicts-rho020-r0-040-57xfx.18d467875c2ca4b1,"reason=Pulled count=1 msg=Container image ""busybox:musl"" already present on machine"
0.3802,Event,ADDED,eval-conflicts-rho020-r0-040-57xfx.18d467875d3ebe43,reason=Created count=1 msg=Created container: task
0.3805,Event,ADDED,eval-conflicts-rho020-r0-040-57xfx.18d467875f4efb94,reason=Started count=1 msg=Started container task
0.3807,Event,ADDED,eval-conflicts-rho020-r0-040.18d46787416d1349,reason=SuccessfulCreate count=1 msg=Created pod: eval-conflicts-rho020-r0-040-57xfx
0.3808,Event,ADDED,eval-conflicts-rho020-r0-040.18d4678a69b17b18,reason=Completed count=1 msg=Job completed
0.381,Event,ADDED,eval-conflicts-rho020-r0-041-cx5wf.18d46787821312be,reason=Scheduled count=None msg=Successfully assigned compute/eval-conflicts-rho020-r0-041-cx5wf to kind-worker3
0.3813,Event,ADDED,eval-conflicts-rho020-r0-041-cx5wf.18d467879ad3a384,"reason=Pulled count=1 msg=Container image ""busybox:musl"" already present on machine"
0.3815,Event,ADDED,eval-conflicts-rho020-r0-041-cx5wf.18d467879be60fd3,reason=Created count=1 msg=Created container: task
0.3817,Event,ADDED,eval-conflicts-rho020-r0-041-cx5wf.18d467879dd6fe2d,reason=Started count=1 msg=Started container task
0.3819,Event,ADDED,eval-conflicts-rho020-r0-041.18d467877d2cc0a3,reason=SuccessfulCreate count=1 msg=Created pod: eval-conflicts-rho020-r0-041-cx5wf
0.3822,Event,ADDED,eval-conflicts-rho020-r0-041.18d4678ae15b58f3,reason=Completed count=1 msg=Job completed
0.3823,Event,ADDED,eval-conflicts-rho020-r0-042-mv8sp.18d46787babac865,reason=Scheduled count=None msg=Successfully assigned compute/eval-conflicts-rho020-r0-042-mv8sp to kind-worker3
0.3825,Event,ADDED,eval-conflicts-rho020-r0-042-mv8sp.18d46787d4506a15,"reason=Pulled count=1 msg=Container image ""busybox:musl"" already present on machine"
0.3828,Event,ADDED,eval-conflicts-rho020-r0-042-mv8sp.18d46787d568f222,reason=Created count=1 msg=Created container: task
0.383,Event,ADDED,eval-conflicts-rho020-r0-042-mv8sp.18d46787d9d71a02,reason=Started count=1 msg=Started container task
0.3831,Event,ADDED,eval-conflicts-rho020-r0-042.18d46787ba016404,reason=SuccessfulCreate count=1 msg=Created pod: eval-conflicts-rho020-r0-042-mv8sp
0.3833,Event,ADDED,eval-conflicts-rho020-r0-042.18d4678ae1bb7fa5,reason=Completed count=1 msg=Job completed
0.3837,Event,ADDED,eval-conflicts-rho020-r0-043-cqj42.18d46787f4a9cdde,"reason=FailedScheduling count=None msg=0/6 nodes are available: 1 c_wall violated: 2 conflicting context pair(s) with node memory, 5 node(s) had untolerated taint(s). no new claims to deallocate, preemption: 0/6 nodes are available: 1 No preemption victims found for incoming pod, 5 Preemption is not helpful for scheduling."
0.3839,Event,ADDED,eval-conflicts-rho020-r0-043-cqj42.18d46787f535f213,"reason=FailedScheduling count=None msg=0/6 nodes are available: 1 c_wall violated: 2 conflicting context pair(s) with node memory, 5 node(s) had untolerated taint(s). no new claims to deallocate, preemption: 0/6 nodes are available: 1 No preemption victims found for incoming pod, 5 Preemption is not helpful for scheduling."
0.384,Event,ADDED,eval-conflicts-rho020-r0-043-cqj42.18d46789026084e7,reason=Scheduled count=None msg=Successfully assigned compute/eval-conflicts-rho020-r0-043-cqj42 to kind-worker
0.3843,Event,ADDED,eval-conflicts-rho020-r0-043-cqj42.18d467891b878214,"reason=Pulled count=1 msg=Container image ""busybox:musl"" already present on machine"
0.3845,Event,ADDED,eval-conflicts-rho020-r0-043-cqj42.18d467891d5ee7e2,reason=Created count=1 msg=Created container: task
0.3848,Event,ADDED,eval-conflicts-rho020-r0-043-cqj42.18d4678921f45420,reason=Started count=1 msg=Started container task
0.385,Event,ADDED,eval-conflicts-rho020-r0-043.18d46787f4683e34,reason=SuccessfulCreate count=1 msg=Created pod: eval-conflicts-rho020-r0-043-cqj42
0.3852,Event,ADDED,eval-conflicts-rho020-r0-043.18d4678c2f2d2c1a,reason=Completed count=1 msg=Job completed
0.3853,Event,ADDED,eval-conflicts-rho020-r0-044-vdcql.18d46788310139e8,reason=Scheduled count=None msg=Successfully assigned compute/eval-conflicts-rho020-r0-044-vdcql to kind-worker3
0.3857,Event,ADDED,eval-conflicts-rho020-r0-044-vdcql.18d467884a20eb83,"reason=Pulled count=1 msg=Container image ""busybox:musl"" already present on machine"
0.3859,Event,ADDED,eval-conflicts-rho020-r0-044-vdcql.18d467884b37c189,reason=Created count=1 msg=Created container: task
0.3861,Event,ADDED,eval-conflicts-rho020-r0-044-vdcql.18d467884d48a713,reason=Started count=1 msg=Started container task
0.387,Event,ADDED,eval-conflicts-rho020-r0-044.18d467883065a5d8,reason=SuccessfulCreate count=1 msg=Created pod: eval-conflicts-rho020-r0-044-vdcql
0.3872,Event,ADDED,eval-conflicts-rho020-r0-044.18d4678b596da52c,reason=Completed count=1 msg=Job completed
0.3873,Event,ADDED,eval-conflicts-rho020-r0-045-5xzj4.18d467886c739a04,reason=Scheduled count=None msg=Successfully assigned compute/eval-conflicts-rho020-r0-045-5xzj4 to kind-worker3
0.3875,Event,ADDED,eval-conflicts-rho020-r0-045-5xzj4.18d4678885cbc09c,"reason=Pulled count=1 msg=Container image ""busybox:musl"" already present on machine"
0.3878,Event,ADDED,eval-conflicts-rho020-r0-045-5xzj4.18d4678886f34586,reason=Created count=1 msg=Created container: task
0.388,Event,ADDED,eval-conflicts-rho020-r0-045-5xzj4.18d4678889093a4b,reason=Started count=1 msg=Started container task
0.3882,Event,ADDED,eval-conflicts-rho020-r0-045.18d467886bd957b9,reason=SuccessfulCreate count=1 msg=Created pod: eval-conflicts-rho020-r0-045-5xzj4
0.3884,Event,ADDED,eval-conflicts-rho020-r0-045.18d4678b95580b17,reason=Completed count=1 msg=Job completed
0.3885,Event,ADDED,eval-conflicts-rho020-r0-046-v5hnp.18d46788a82e2e03,reason=Scheduled count=None msg=Successfully assigned compute/eval-conflicts-rho020-r0-046-v5hnp to kind-worker3
0.3887,Event,ADDED,eval-conflicts-rho020-r0-046-v5hnp.18d46788c150bb5c,"reason=Pulled count=1 msg=Container image ""busybox:musl"" already present on machine"
0.3889,Event,ADDED,eval-conflicts-rho020-r0-046-v5hnp.18d46788c268338d,reason=Created count=1 msg=Created container: task
0.3891,Event,ADDED,eval-conflicts-rho020-r0-046-v5hnp.18d46788c44e6ce8,reason=Started count=1 msg=Started container task
0.3892,Event,ADDED,eval-conflicts-rho020-r0-046.18d46788a79b6fc0,reason=SuccessfulCreate count=1 msg=Created pod: eval-conflicts-rho020-r0-046-v5hnp
0.3894,Event,ADDED,eval-conflicts-rho020-r0-046.18d4678bd1138dff,reason=Completed count=1 msg=Job completed
0.3895,Event,ADDED,eval-conflicts-rho020-r0-047-7jnp8.18d46788e2f0889e,"reason=FailedScheduling count=None msg=0/6 nodes are available: 6 node(s) had untolerated taint(s). no new claims to deallocate, preemption: 0/6 nodes are available: 6 Preemption is not helpful for scheduling."
0.3897,Event,ADDED,eval-conflicts-rho020-r0-047-7jnp8.18d4678902963806,reason=Scheduled count=None msg=Successfully assigned compute/eval-conflicts-rho020-r0-047-7jnp8 to kind-worker
0.3899,Event,ADDED,eval-conflicts-rho020-r0-047-7jnp8.18d467891b6ddab2,"reason=Pulled count=1 msg=Container image ""busybox:musl"" already present on machine"
0.39,Event,ADDED,eval-conflicts-rho020-r0-047-7jnp8.18d467891cf0a4a9,reason=Created count=1 msg=Created container: task
0.3903,Event,ADDED,eval-conflicts-rho020-r0-047-7jnp8.18d4678921bcdba9,reason=Started count=1 msg=Started container task
0.3905,Event,ADDED,eval-conflicts-rho020-r0-047.18d46788e2e8bf83,reason=SuccessfulCreate count=1 msg=Created pod: eval-conflicts-rho020-r0-047-7jnp8
0.3907,Event,ADDED,eval-conflicts-rho020-r0-047.18d4678c2ed40707,reason=Completed count=1 msg=Job completed
0.3909,Event,ADDED,eval-conflicts-rho020-r0-048-djs5p.18d467891feb9ad9,reason=Scheduled count=None msg=Successfully assigned compute/eval-conflicts-rho020-r0-048-djs5p to kind-worker2
0.3912,Event,ADDED,eval-conflicts-rho020-r0-048-djs5p.18d4678939a6afae,"reason=Pulled count=1 msg=Container image ""busybox:musl"" already present on machine"
0.3914,Event,ADDED,eval-conflicts-rho020-r0-048-djs5p.18d467893abd959b,reason=Created count=1 msg=Created container: task
0.3916,Event,ADDED,eval-conflicts-rho020-r0-048-djs5p.18d467893cb29dba,reason=Started count=1 msg=Started container task
0.3918,Event,ADDED,eval-conflicts-rho020-r0-048.18d467891ee90ef0,reason=SuccessfulCreate count=1 msg=Created pod: eval-conflicts-rho020-r0-048-djs5p
0.392,Event,ADDED,eval-conflicts-rho020-r0-048.18d4678c276d603e,reason=Completed count=1 msg=Job completed
0.3921,Event,ADDED,eval-conflicts-rho020-r0-049-9qxwk.18d467895ae7e1dd,reason=Scheduled count=None msg=Successfully assigned compute/eval-conflicts-rho020-r0-049-9qxwk to kind-worker5
0.3923,Event,ADDED,eval-conflicts-rho020-r0-049-9qxwk.18d46789736eef78,"reason=Pulled count=1 msg=Container image ""busybox:musl"" already present on machine"
0.3925,Event,ADDED,eval-conflicts-rho020-r0-049-9qxwk.18d4678974783258,reason=Created count=1 msg=Created container: task
0.3927,Event,ADDED,eval-conflicts-rho020-r0-049-9qxwk.18d4678976728adc,reason=Started count=1 msg=Started container task
0.3928,Event,ADDED,eval-conflicts-rho020-r0-049.18d4678959e735b4,reason=SuccessfulCreate count=1 msg=Created pod: eval-conflicts-rho020-r0-049-9qxwk
0.393,Event,ADDED,eval-conflicts-rho020-r0-049.18d4678cab0ffb37,reason=Completed count=1 msg=Job completed
0.3932,Event,ADDED,eval-conflicts-rho020-r0-050-qjjv6.18d4678996deeb44,reason=Scheduled count=None msg=Successfully assigned compute/eval-conflicts-rho020-r0-050-qjjv6 to kind-worker2
0.3933,Event,ADDED,eval-conflicts-rho020-r0-050-qjjv6.18d46789af68231a,"reason=Pulled count=1 msg=Container image ""busybox:musl"" already present on machine"
0.3936,Event,ADDED,eval-conflicts-rho020-r0-050-qjjv6.18d46789b077c2f1,reason=Created count=1 msg=Created container: task
0.3939,Event,ADDED,eval-conflicts-rho020-r0-050-qjjv6.18d46789b412314b,reason=Started count=1 msg=Started container task
0.3941,Event,ADDED,eval-conflicts-rho020-r0-050.18d4678995ec907d,reason=SuccessfulCreate count=1 msg=Created pod: eval-conflicts-rho020-r0-050-qjjv6
0.3943,Event,ADDED,eval-conflicts-rho020-r0-050.18d4678cd98b65d7,reason=Completed count=1 msg=Job completed
0.3944,Event,ADDED,eval-conflicts-rho020-r0-051-96665.18d46789d2353ee1,reason=Scheduled count=None msg=Successfully assigned compute/eval-conflicts-rho020-r0-051-96665 to kind-worker5
0.3947,Event,ADDED,eval-conflicts-rho020-r0-051-96665.18d46789ebd9730e,"reason=Pulled count=1 msg=Container image ""busybox:musl"" already present on machine"
0.3949,Event,ADDED,eval-conflicts-rho020-r0-051-96665.18d46789ed4598cc,reason=Created count=1 msg=Created container: task
0.3951,Event,ADDED,eval-conflicts-rho020-r0-051-96665.18d46789ef6e633a,reason=Started count=1 msg=Started container task
0.3952,Event,ADDED,eval-conflicts-rho020-r0-051.18d46789d140d4f7,reason=SuccessfulCreate count=1 msg=Created pod: eval-conflicts-rho020-r0-051-96665
0.3955,Event,ADDED,eval-conflicts-rho020-r0-051.18d4678ce78dcf5b,reason=Completed count=1 msg=Job completed
0.3956,Event,ADDED,eval-conflicts-rho020-r0-052-8hdgh.18d4678a0e2a9793,reason=Scheduled count=None msg=Successfully assigned compute/eval-conflicts-rho020-r0-052-8hdgh to kind-worker5
0.3958,Event,ADDED,eval-conflicts-rho020-r0-052-8hdgh.18d4678a27b2af0c,"reason=Pulled count=1 msg=Container image ""busybox:musl"" already present on machine"
0.3961,Event,ADDED,eval-conflicts-rho020-r0-052-8hdgh.18d4678a28cf5aec,reason=Created count=1 msg=Created container: task
0.3963,Event,ADDED,eval-conflicts-rho020-r0-052-8hdgh.18d4678a2add5255,reason=Started count=1 msg=Started container task
0.3964,Event,ADDED,eval-conflicts-rho020-r0-052.18d4678a0cf2de26,reason=SuccessfulCreate count=1 msg=Created pod: eval-conflicts-rho020-r0-052-8hdgh
0.3966,Event,ADDED,eval-conflicts-rho020-r0-052.18d4678d5ffcacf4,reason=Completed count=1 msg=Job completed
0.3967,Event,ADDED,eval-conflicts-rho020-r0-053-ckm5b.18d4678a49eba011,reason=Scheduled count=None msg=Successfully assigned compute/eval-conflicts-rho020-r0-053-ckm5b to kind-worker
0.3969,Event,ADDED,eval-conflicts-rho020-r0-053-ckm5b.18d4678a63312ff4,"reason=Pulled count=1 msg=Container image ""busybox:musl"" already present on machine"
0.3971,Event,ADDED,eval-conflicts-rho020-r0-053-ckm5b.18d4678a6440bf44,reason=Created count=1 msg=Created container: task
0.3978,Event,ADDED,eval-conflicts-rho020-r0-053-ckm5b.18d4678a68d301e4,reason=Started count=1 msg=Started container task
0.398,Event,ADDED,eval-conflicts-rho020-r0-053.18d4678a487f3cf7,reason=SuccessfulCreate count=1 msg=Created pod: eval-conflicts-rho020-r0-053-ckm5b
0.3981,Event,ADDED,eval-conflicts-rho020-r0-053.18d4678d969def59,reason=Completed count=1 msg=Job completed
0.3983,Event,ADDED,eval-conflicts-rho020-r0-054-pv672.18d4678a854ddebf,reason=Scheduled count=None msg=Successfully assigned compute/eval-conflicts-rho020-r0-054-pv672 to kind-worker
0.3989,Event,ADDED,eval-conflicts-rho020-r0-054-pv672.18d4678a9e272e67,"reason=Pulled count=1 msg=Container image ""busybox:musl"" already present on machine"
0.3991,Event,ADDED,eval-conflicts-rho020-r0-054-pv672.18d4678a9f3d70b9,reason=Created count=1 msg=Created container: task
0.3993,Event,ADDED,eval-conflicts-rho020-r0-054-pv672.18d4678aa391c199,reason=Started count=1 msg=Started container task
0.3994,Event,ADDED,eval-conflicts-rho020-r0-054.18d4678a840ae4f4,reason=SuccessfulCreate count=1 msg=Created pod: eval-conflicts-rho020-r0-054-pv672
0.3997,Event,ADDED,eval-conflicts-rho020-r0-054.18d4678dd24fe48e,reason=Completed count=1 msg=Job completed
0.3999,Event,ADDED,eval-conflicts-rho020-r0-055-77wnl.18d4678ac116e61d,reason=Scheduled count=None msg=Successfully assigned compute/eval-conflicts-rho020-r0-055-77wnl to kind-worker2
0.4001,Event,ADDED,eval-conflicts-rho020-r0-055-77wnl.18d4678adb811005,"reason=Pulled count=1 msg=Container image ""busybox:musl"" already present on machine"
0.4003,Event,ADDED,eval-conflicts-rho020-r0-055-77wnl.18d4678adc914125,reason=Created count=1 msg=Created container: task
0.4005,Event,ADDED,eval-conflicts-rho020-r0-055-77wnl.18d4678aded13e06,reason=Started count=1 msg=Started container task
0.4007,Event,ADDED,eval-conflicts-rho020-r0-055.18d4678abfc0ffd3,reason=SuccessfulCreate count=1 msg=Created pod: eval-conflicts-rho020-r0-055-77wnl
0.4008,Event,ADDED,eval-conflicts-rho020-r0-055.18d4678e0511c74b,reason=Completed count=1 msg=Job completed
0.401,Event,ADDED,eval-conflicts-rho020-r0-056-zttq2.18d4678afca00e43,reason=Scheduled count=None msg=Successfully assigned compute/eval-conflicts-rho020-r0-056-zttq2 to kind-worker2
0.4012,Event,ADDED,eval-conflicts-rho020-r0-056-zttq2.18d4678b152ab7ae,"reason=Pulled count=1 msg=Container image ""busybox:musl"" already present on machine"
0.4014,Event,ADDED,eval-conflicts-rho020-r0-056-zttq2.18d4678b1639ca5f,reason=Created count=1 msg=Created container: task
0.4015,Event,ADDED,eval-conflicts-rho020-r0-056-zttq2.18d4678b18471e7f,reason=Started count=1 msg=Started container task
0.4017,Event,ADDED,eval-conflicts-rho020-r0-056.18d4678afb801d69,reason=SuccessfulCreate count=1 msg=Created pod: eval-conflicts-rho020-r0-056-zttq2
0.4019,Event,ADDED,eval-conflicts-rho020-r0-056.18d4678e4101f2a0,reason=Completed count=1 msg=Job completed
0.402,Event,ADDED,eval-conflicts-rho020-r0-057-r22dv.18d4678b3801a5b9,reason=Scheduled count=None msg=Successfully assigned compute/eval-conflicts-rho020-r0-057-r22dv to kind-worker5
0.4022,Event,ADDED,eval-conflicts-rho020-r0-057-r22dv.18d4678b51a9695c,"reason=Pulled count=1 msg=Container image ""busybox:musl"" already present on machine"
0.4024,Event,ADDED,eval-conflicts-rho020-r0-057-r22dv.18d4678b52c72301,reason=Created count=1 msg=Created container: task
0.4025,Event,ADDED,eval-conflicts-rho020-r0-057-r22dv.18d4678b54dab1b8,reason=Started count=1 msg=Started container task
0.4027,Event,ADDED,eval-conflicts-rho020-r0-057.18d4678b370a6209,reason=SuccessfulCreate count=1 msg=Created pod: eval-conflicts-rho020-r0-057-r22dv
0.4029,Event,ADDED,eval-conflicts-rho020-r0-057.18d4678e8968ebae,reason=Completed count=1 msg=Job completed
0.403,Event,ADDED,eval-conflicts-rho020-r0-058-7nvjn.18d4678b73206206,reason=Scheduled count=None msg=Successfully assigned compute/eval-conflicts-rho020-r0-058-7nvjn to kind-worker2
0.4032,Event,ADDED,eval-conflicts-rho020-r0-058-7nvjn.18d4678b8c614ab7,"reason=Pulled count=1 msg=Container image ""busybox:musl"" already present on machine"
0.4033,Event,ADDED,eval-conflicts-rho020-r0-058-7nvjn.18d4678b8d6375fe,reason=Created count=1 msg=Created container: task
0.4035,Event,ADDED,eval-conflicts-rho020-r0-058-7nvjn.18d4678b8f5ce894,reason=Started count=1 msg=Started container task
0.4037,Event,ADDED,eval-conflicts-rho020-r0-058.18d4678b726dced6,reason=SuccessfulCreate count=1 msg=Created pod: eval-conflicts-rho020-r0-058-7nvjn
0.4039,Event,ADDED,eval-conflicts-rho020-r0-058.18d4678eb8192a7e,reason=Completed count=1 msg=Job completed
0.4041,Event,ADDED,eval-conflicts-rho020-r0-059-rd6fx.18d4678bae8defb6,reason=Scheduled count=None msg=Successfully assigned compute/eval-conflicts-rho020-r0-059-rd6fx to kind-worker4
0.4043,Event,ADDED,eval-conflicts-rho020-r0-059-rd6fx.18d4678bc64a762f,"reason=Pulled count=1 msg=Container image ""busybox:musl"" already present on machine"
0.4045,Event,ADDED,eval-conflicts-rho020-r0-059-rd6fx.18d4678bc75de491,reason=Created count=1 msg=Created container: task
0.4047,Event,ADDED,eval-conflicts-rho020-r0-059-rd6fx.18d4678bc94eaf5a,reason=Started count=1 msg=Started container task
0.405,Event,ADDED,eval-conflicts-rho020-r0-059.18d4678bae483368,reason=SuccessfulCreate count=1 msg=Created pod: eval-conflicts-rho020-r0-059-rd6fx
0.4051,Event,ADDED,eval-conflicts-rho020-r0-059.18d4678f05b96272,reason=Completed count=1 msg=Job completed
0.4053,Event,ADDED,eval-conflicts-rho020-r0-060-jp5tb.18d4678beb927745,reason=Scheduled count=None msg=Successfully assigned compute/eval-conflicts-rho020-r0-060-jp5tb to kind-worker4
0.4056,Event,ADDED,eval-conflicts-rho020-r0-060-jp5tb.18d4678c059c6758,"reason=Pulled count=1 msg=Container image ""busybox:musl"" already present on machine"
0.4058,Event,ADDED,eval-conflicts-rho020-r0-060-jp5tb.18d4678c06c9072f,reason=Created count=1 msg=Created container: task
0.406,Event,ADDED,eval-conflicts-rho020-r0-060-jp5tb.18d4678c08dd2be9,reason=Started count=1 msg=Started container task
0.4062,Event,ADDED,eval-conflicts-rho020-r0-060.18d4678beae675a6,reason=SuccessfulCreate count=1 msg=Created pod: eval-conflicts-rho020-r0-060-jp5tb
0.4064,Event,ADDED,eval-conflicts-rho020-r0-060.18d4678f41cedd42,reason=Completed count=1 msg=Job completed
0.4066,Event,ADDED,eval-conflicts-rho020-r0-061-4s2j8.18d4678c28b2fe3d,reason=Scheduled count=None msg=Successfully assigned compute/eval-conflicts-rho020-r0-061-4s2j8 to kind-worker4
0.4067,Event,ADDED,eval-conflicts-rho020-r0-061-4s2j8.18d4678c41b5de44,"reason=Pulled count=1 msg=Container image ""busybox:musl"" already present on machine"
0.4069,Event,ADDED,eval-conflicts-rho020-r0-061-4s2j8.18d4678c4310c394,reason=Created count=1 msg=Created container: task
0.4071,Event,ADDED,eval-conflicts-rho020-r0-061-4s2j8.18d4678c4cfbdfd3,reason=Started count=1 msg=Started container task
0.4073,Event,ADDED,eval-conflicts-rho020-r0-061.18d4678c27f7444f,reason=SuccessfulCreate count=1 msg=Created pod: eval-conflicts-rho020-r0-061-4s2j8
0.4074,Event,ADDED,eval-conflicts-rho020-r0-061.18d4678f7d45243c,reason=Completed count=1 msg=Job completed
0.4077,Event,ADDED,eval-conflicts-rho020-r0-062-87q6z.18d4678c61acdabd,"reason=FailedScheduling count=None msg=0/6 nodes are available: 1 c_wall violated: 1 conflicting context pair(s) with node memory, 5 node(s) had untolerated taint(s). no new claims to deallocate, preemption: 0/6 nodes are available: 1 No preemption victims found for incoming pod, 5 Preemption is not helpful for scheduling."
0.4079,Event,ADDED,eval-conflicts-rho020-r0-062-87q6z.18d4678c626e34ec,"reason=FailedScheduling count=None msg=0/6 nodes are available: 1 c_wall violated: 1 conflicting context pair(s) with node memory, 5 node(s) had untolerated taint(s). no new claims to deallocate, preemption: 0/6 nodes are available: 1 No preemption victims found for incoming pod, 5 Preemption is not helpful for scheduling."
0.4081,Event,ADDED,eval-conflicts-rho020-r0-062-87q6z.18d4678d91ee1baa,"reason=FailedScheduling count=None msg=0/6 nodes are available: 2 c_wall violated: 1 conflicting context pair(s) with node memory, 4 node(s) had untolerated taint(s). no new claims to deallocate, preemption: 0/6 nodes are available: 2 No preemption victims found for incoming pod, 4 Preemption is not helpful for scheduling."
0.4085,Event,ADDED,eval-conflicts-rho020-r0-062-87q6z.18d4678dc8caae6a,"reason=FailedScheduling count=None msg=0/6 nodes are available: 1 c_wall violated: 1 conflicting context pair(s) with node memory, 1 c_wall violated: 2 conflicting context pair(s) with node memory, 4 node(s) had untolerated taint(s). no new claims to deallocate, preemption: 0/6 nodes are available: 2 No preemption victims found for incoming pod, 4 Preemption is not helpful for scheduling."
0.4087,Event,ADDED,eval-conflicts-rho020-r0-062-87q6z.18d4678dd99b5624,reason=Scheduled count=None msg=Successfully assigned compute/eval-conflicts-rho020-r0-062-87q6z to kind-worker
0.4089,Event,ADDED,eval-conflicts-rho020-r0-062-87q6z.18d4678df2f50025,"reason=Pulled count=1 msg=Container image ""busybox:musl"" already present on machine"
0.4092,Event,ADDED,eval-conflicts-rho020-r0-062-87q6z.18d4678df400715a,reason=Created count=1 msg=Created container: task
0.4094,Event,ADDED,eval-conflicts-rho020-r0-062-87q6z.18d4678df62f5e2c,reason=Started count=1 msg=Started container task
0.4095,Event,ADDED,eval-conflicts-rho020-r0-062.18d4678c6166fe4c,reason=SuccessfulCreate count=1 msg=Created pod: eval-conflicts-rho020-r0-062-87q6z
0.4097,Event,ADDED,eval-conflicts-rho020-r0-062.18d4679117cfa506,reason=Completed count=1 msg=Job completed
0.41,Event,ADDED,eval-conflicts-rho020-r0-063-7l4ld.18d4678c9d0d83cd,"reason=FailedScheduling count=None msg=0/6 nodes are available: 1 c_wall violated: 1 conflicting context pair(s) with node memory, 5 node(s) had untolerated taint(s). no new claims to deallocate, preemption: 0/6 nodes are available: 1 No preemption victims found for incoming pod, 5 Preemption is not helpful for scheduling."
0.4102,Event,ADDED,eval-conflicts-rho020-r0-063-7l4ld.18d4678c9dece81e,"reason=FailedScheduling count=None msg=0/6 nodes are available: 1 c_wall violated: 1 conflicting context pair(s) with node memory, 5 node(s) had untolerated taint(s). no new claims to deallocate, preemption: 0/6 nodes are available: 1 No preemption victims found for incoming pod, 5 Preemption is not helpful for scheduling."
0.4103,Event,ADDED,eval-conflicts-rho020-r0-063-7l4ld.18d4678d8bfab924,reason=Scheduled count=None msg=Successfully assigned compute/eval-conflicts-rho020-r0-063-7l4ld to kind-worker3
0.4106,Event,ADDED,eval-conflicts-rho020-r0-063-7l4ld.18d4678da5e7f1a5,"reason=Pulled count=1 msg=Container image ""busybox:musl"" already present on machine"
0.4108,Event,ADDED,eval-conflicts-rho020-r0-063-7l4ld.18d4678da7935b4d,reason=Created count=1 msg=Created container: task
0.411,Event,ADDED,eval-conflicts-rho020-r0-063-7l4ld.18d4678dabb184c3,reason=Started count=1 msg=Started container task
0.4111,Event,ADDED,eval-conflicts-rho020-r0-063.18d4678c9cc633d9,reason=SuccessfulCreate count=1 msg=Created pod: eval-conflicts-rho020-r0-063-7l4ld
0.4115,Event,ADDED,eval-conflicts-rho020-r0-063.18d46790b8256c51,reason=Completed count=1 msg=Job completed
0.4116,Event,ADDED,eval-conflicts-rho020-r0-064-lzc88.18d4678cd9d7583c,reason=Scheduled count=None msg=Successfully assigned compute/eval-conflicts-rho020-r0-064-lzc88 to kind-worker4
0.4118,Event,ADDED,eval-conflicts-rho020-r0-064-lzc88.18d4678cf2fdfd89,"reason=Pulled count=1 msg=Container image ""busybox:musl"" already present on machine"
0.4121,Event,ADDED,eval-conflicts-rho020-r0-064-lzc88.18d4678cf41e5f0e,reason=Created count=1 msg=Created container: task
0.4123,Event,ADDED,eval-conflicts-rho020-r0-064-lzc88.18d4678cf984a459,reason=Started count=1 msg=Started container task
0.4125,Event,ADDED,eval-conflicts-rho020-r0-064.18d4678cd913275a,reason=SuccessfulCreate count=1 msg=Created pod: eval-conflicts-rho020-r0-064-lzc88
0.4126,Event,ADDED,eval-conflicts-rho020-r0-064.18d467903112533c,reason=Completed count=1 msg=Job completed
0.413,Event,ADDED,eval-conflicts-rho020-r0-065-mnt2l.18d4678d1457a857,reason=Scheduled count=None msg=Successfully assigned compute/eval-conflicts-rho020-r0-065-mnt2l to kind-worker4
0.4133,Event,ADDED,eval-conflicts-rho020-r0-065-mnt2l.18d4678d2d9b237c,"reason=Pulled count=1 msg=Container image ""busybox:musl"" already present on machine"
0.4134,Event,ADDED,eval-conflicts-rho020-r0-065-mnt2l.18d4678d2eb9c49d,reason=Created count=1 msg=Created container: task
0.4136,Event,ADDED,eval-conflicts-rho020-r0-065-mnt2l.18d4678d32e602da,reason=Started count=1 msg=Started container task
0.414,Event,ADDED,eval-conflicts-rho020-r0-065.18d4678d13c6f70f,reason=SuccessfulCreate count=1 msg=Created pod: eval-conflicts-rho020-r0-065-mnt2l
0.4141,Event,ADDED,eval-conflicts-rho020-r0-065.18d467906d132b10,reason=Completed count=1 msg=Job completed
0.4143,Event,ADDED,eval-conflicts-rho020-r0-066-sz9xv.18d4678d501f7fae,"reason=FailedScheduling count=None msg=0/6 nodes are available: 1 c_wall violated: 1 conflicting context pair(s) with node memory, 5 node(s) had untolerated taint(s). no new claims to deallocate, preemption: 0/6 nodes are available: 1 No preemption victims found for incoming pod, 5 Preemption is not helpful for scheduling."
0.4147,Event,ADDED,eval-conflicts-rho020-r0-066-sz9xv.18d4678d510258a8,"reason=FailedScheduling count=None msg=0/6 nodes are available: 1 c_wall violated: 1 conflicting context pair(s) with node memory, 5 node(s) had untolerated taint(s). no new claims to deallocate, preemption: 0/6 nodes are available: 1 No preemption victims found for incoming pod, 5 Preemption is not helpful for scheduling."
0.4148,Event,ADDED,eval-conflicts-rho020-r0-066-sz9xv.18d4678d8d8bd966,reason=Scheduled count=None msg=Successfully assigned compute/eval-conflicts-rho020-r0-066-sz9xv to kind-worker3
0.415,Event,ADDED,eval-conflicts-rho020-r0-066-sz9xv.18d4678da6d755e9,"reason=Pulled count=1 msg=Container image ""busybox:musl"" already present on machine"
0.4154,Event,ADDED,eval-conflicts-rho020-r0-066-sz9xv.18d4678da8437752,reason=Created count=1 msg=Created container: task
0.4155,Event,ADDED,eval-conflicts-rho020-r0-066-sz9xv.18d4678dae6b5a89,reason=Started count=1 msg=Started container task
0.4157,Event,ADDED,eval-conflicts-rho020-r0-066.18d4678d4fdfdc53,reason=SuccessfulCreate count=1 msg=Created pod: eval-conflicts-rho020-r0-066-sz9xv
0.4159,Event,ADDED,eval-conflicts-rho020-r0-066.18d46790f4e45e59,reason=Completed count=1 msg=Job completed
0.4162,Event,ADDED,eval-conflicts-rho020-r0-067-w8p7x.18d4678d8b64b7b2,reason=Scheduled count=None msg=Successfully assigned compute/eval-conflicts-rho020-r0-067-w8p7x to kind-worker4
0.4164,Event,ADDED,eval-conflicts-rho020-r0-067-w8p7x.18d4678da5e57534,"reason=Pulled count=1 msg=Container image ""busybox:musl"" already present on machine"
0.4165,Event,ADDED,eval-conflicts-rho020-r0-067-w8p7x.18d4678da76f3c2b,reason=Created count=1 msg=Created container: task
0.4167,Event,ADDED,eval-conflicts-rho020-r0-067-w8p7x.18d4678dab9bf38a,reason=Started count=1 msg=Started container task
0.417,Event,ADDED,eval-conflicts-rho020-r0-067.18d4678d8ae1af28,reason=SuccessfulCreate count=1 msg=Created pod: eval-conflicts-rho020-r0-067-w8p7x
0.4172,Event,ADDED,eval-conflicts-rho020-r0-067.18d46790e4fa9e27,reason=Completed count=1 msg=Job completed
0.4174,Event,ADDED,eval-conflicts-rho020-r0-068-56h4z.18d4678dc757b64f,reason=Scheduled count=None msg=Successfully assigned compute/eval-conflicts-rho020-r0-068-56h4z to kind-worker4
0.4176,Event,ADDED,eval-conflicts-rho020-r0-068-56h4z.18d4678de16105bb,"reason=Pulled count=1 msg=Container image ""busybox:musl"" already present on machine"
0.4178,Event,ADDED,eval-conflicts-rho020-r0-068-56h4z.18d4678de276dffc,reason=Created count=1 msg=Created container: task
0.4183,Event,ADDED,eval-conflicts-rho020-r0-068-56h4z.18d4678de4df63d4,reason=Started count=1 msg=Started container task
0.4185,Event,ADDED,eval-conflicts-rho020-r0-068.18d4678dc69ef3c2,reason=SuccessfulCreate count=1 msg=Created pod: eval-conflicts-rho020-r0-068-56h4z
0.4188,Event,ADDED,eval-conflicts-rho020-r0-068.18d46791211f11ca,reason=Completed count=1 msg=Job completed
0.419,Event,ADDED,eval-conflicts-rho020-r0-069-vms9g.18d4678e02c28054,reason=Scheduled count=None msg=Successfully assigned compute/eval-conflicts-rho020-r0-069-vms9g to kind-worker3
0.4192,Event,ADDED,eval-conflicts-rho020-r0-069-vms9g.18d4678e1b9517e8,"reason=Pulled count=1 msg=Container image ""busybox:musl"" already present on machine"
0.4193,Event,ADDED,eval-conflicts-rho020-r0-069-vms9g.18d4678e1cae4da7,reason=Created count=1 msg=Created container: task
0.4198,Event,ADDED,eval-conflicts-rho020-r0-069-vms9g.18d4678e1f0d35d3,reason=Started count=1 msg=Started container task
0.42,Event,ADDED,eval-conflicts-rho020-r0-069.18d4678e0217875e,reason=SuccessfulCreate count=1 msg=Created pod: eval-conflicts-rho020-r0-069-vms9g
0.4201,Event,ADDED,eval-conflicts-rho020-r0-069.18d4679130b1be60,reason=Completed count=1 msg=Job completed
0.4204,Event,ADDED,eval-conflicts-rho020-r0-070-fp55s.18d4678e3f688906,reason=Scheduled count=None msg=Successfully assigned compute/eval-conflicts-rho020-r0-070-fp55s to kind-worker
0.4206,Event,ADDED,eval-conflicts-rho020-r0-070-fp55s.18d4678e58d8aca7,"reason=Pulled count=1 msg=Container image ""busybox:musl"" already present on machine"
0.4208,Event,ADDED,eval-conflicts-rho020-r0-070-fp55s.18d4678e59e772d7,reason=Created count=1 msg=Created container: task
0.4209,Event,ADDED,eval-conflicts-rho020-r0-070-fp55s.18d4678e5cf5646f,reason=Started count=1 msg=Started container task
0.4212,Event,ADDED,eval-conflicts-rho020-r0-070.18d4678e3e2982fd,reason=SuccessfulCreate count=1 msg=Created pod: eval-conflicts-rho020-r0-070-fp55s
0.4214,Event,ADDED,eval-conflicts-rho020-r0-070.18d467918fb7c144,reason=Completed count=1 msg=Job completed
0.4215,Event,ADDED,eval-conflicts-rho020-r0-071-cz2w5.18d4678e7a2d497c,reason=Scheduled count=None msg=Successfully assigned compute/eval-conflicts-rho020-r0-071-cz2w5 to kind-worker
0.4218,Event,ADDED,eval-conflicts-rho020-r0-071-cz2w5.18d4678e93d576a7,"reason=Pulled count=1 msg=Container image ""busybox:musl"" already present on machine"
0.422,Event,ADDED,eval-conflicts-rho020-r0-071-cz2w5.18d4678e94e1db90,reason=Created count=1 msg=Created container: task
0.4222,Event,ADDED,eval-conflicts-rho020-r0-071-cz2w5.18d4678e96d338e1,reason=Started count=1 msg=Started container task
0.4224,Event,ADDED,eval-conflicts-rho020-r0-071.18d4678e7975446f,reason=SuccessfulCreate count=1 msg=Created pod: eval-conflicts-rho020-r0-071-cz2w5
0.4226,Event,ADDED,eval-conflicts-rho020-r0-071.18d46791cad94b3f,reason=Completed count=1 msg=Job completed
0.4227,Event,ADDED,eval-conflicts-rho020-r0-072-hl5tc.18d4678eb5c21f7b,reason=Scheduled count=None msg=Successfully assigned compute/eval-conflicts-rho020-r0-072-hl5tc to kind-worker
0.4229,Event,ADDED,eval-conflicts-rho020-r0-072-hl5tc.18d4678ecfd7d3b6,"reason=Pulled count=1 msg=Container image ""busybox:musl"" already present on machine"
0.423,Event,ADDED,eval-conflicts-rho020-r0-072-hl5tc.18d4678ed0e16084,reason=Created count=1 msg=Created container: task
0.4232,Event,ADDED,eval-conflicts-rho020-r0-072-hl5tc.18d4678ed50b7204,reason=Started count=1 msg=Started container task
0.4234,Event,ADDED,eval-conflicts-rho020-r0-072.18d4678eb4f415ce,reason=SuccessfulCreate count=1 msg=Created pod: eval-conflicts-rho020-r0-072-hl5tc
0.4235,Event,ADDED,eval-conflicts-rho020-r0-072.18d467920716008a,reason=Completed count=1 msg=Job completed
0.4237,Event,ADDED,eval-conflicts-rho020-r0-073-4nwfv.18d4678ef0eede3e,"reason=FailedScheduling count=None msg=0/6 nodes are available: 2 c_wall violated: 1 conflicting context pair(s) with node memory, 4 node(s) had untolerated taint(s). no new claims to deallocate, preemption: 0/6 nodes are available: 2 No preemption victims found for incoming pod, 4 Preemption is not helpful for scheduling."
0.4239,Event,ADDED,eval-conflicts-rho020-r0-073-4nwfv.18d4678ef1c0e6b9,"reason=FailedScheduling count=None msg=0/6 nodes are available: 2 c_wall violated: 1 conflicting context pair(s) with node memory, 4 node(s) had untolerated taint(s). no new claims to deallocate, preemption: 0/6 nodes are available: 2 No preemption victims found for incoming pod, 4 Preemption is not helpful for scheduling."
0.4241,Event,ADDED,eval-conflicts-rho020-r0-073-4nwfv.18d4678fe1eddb47,"reason=FailedScheduling count=None msg=0/6 nodes are available: 1 c_wall violated: 1 conflicting context pair(s) with node memory, 5 node(s) had untolerated taint(s). no new claims to deallocate, preemption: 0/6 nodes are available: 1 No preemption victims found for incoming pod, 5 Preemption is not helpful for scheduling."
0.4242,Event,ADDED,eval-conflicts-rho020-r0-073-4nwfv.18d467904619ffc1,reason=Scheduled count=None msg=Successfully assigned compute/eval-conflicts-rho020-r0-073-4nwfv to kind-worker2
0.4244,Event,ADDED,eval-conflicts-rho020-r0-073-4nwfv.18d467905f17cece,"reason=Pulled count=1 msg=Container image ""busybox:musl"" already present on machine"
0.4246,Event,ADDED,eval-conflicts-rho020-r0-073-4nwfv.18d4679060b42477,reason=Created count=1 msg=Created container: task
0.4247,Event,ADDED,eval-conflicts-rho020-r0-073-4nwfv.18d46790650d5806,reason=Started count=1 msg=Started container task
0.425,Event,ADDED,eval-conflicts-rho020-r0-073.18d4678ef084e4b1,reason=SuccessfulCreate count=1 msg=Created pod: eval-conflicts-rho020-r0-073-4nwfv
0.4252,Event,ADDED,eval-conflicts-rho020-r0-073.18d467939fcdf8fa,reason=Completed count=1 msg=Job completed
0.4254,Event,ADDED,eval-conflicts-rho020-r0-074-4t5bt.18d4678f2ce0209a,reason=Scheduled count=None msg=Successfully assigned compute/eval-conflicts-rho020-r0-074-4t5bt to kind-worker
0.4257,Event,ADDED,eval-conflicts-rho020-r0-074-4t5bt.18d4678f4784fb85,"reason=Pulled count=1 msg=Container image ""busybox:musl"" already present on machine"
0.4259,Event,ADDED,eval-conflicts-rho020-r0-074-4t5bt.18d4678f48ad2691,reason=Created count=1 msg=Created container: task
0.426,Event,ADDED,eval-conflicts-rho020-r0-074-4t5bt.18d4678f4d0e7edc,reason=Started count=1 msg=Started container task
0.4262,Event,ADDED,eval-conflicts-rho020-r0-074.18d4678f2c352df0,reason=SuccessfulCreate count=1 msg=Created pod: eval-conflicts-rho020-r0-074-4t5bt
0.4265,Event,ADDED,eval-conflicts-rho020-r0-074.18d467927ed86655,reason=Completed count=1 msg=Job completed
0.4266,Event,ADDED,eval-conflicts-rho020-r0-075-n8mt4.18d4678f687506e7,reason=Scheduled count=None msg=Successfully assigned compute/eval-conflicts-rho020-r0-075-n8mt4 to kind-worker
0.4268,Event,ADDED,eval-conflicts-rho020-r0-075-n8mt4.18d4678f812d738e,"reason=Pulled count=1 msg=Container image ""busybox:musl"" already present on machine"
0.427,Event,ADDED,eval-conflicts-rho020-r0-075-n8mt4.18d4678f82343946,reason=Created count=1 msg=Created container: task
0.4272,Event,ADDED,eval-conflicts-rho020-r0-075-n8mt4.18d4678f84301df0,reason=Started count=1 msg=Started container task
0.4274,Event,ADDED,eval-conflicts-rho020-r0-075.18d4678f67b9add3,reason=SuccessfulCreate count=1 msg=Created pod: eval-conflicts-rho020-r0-075-n8mt4
0.4276,Event,ADDED,eval-conflicts-rho020-r0-075.18d46792ba01bcf8,reason=Completed count=1 msg=Job completed
0.4279,Event,ADDED,eval-conflicts-rho020-r0-076-9jl9x.18d4678fa45c849f,reason=Scheduled count=None msg=Successfully assigned compute/eval-conflicts-rho020-r0-076-9jl9x to kind-worker
0.428,Event,ADDED,eval-conflicts-rho020-r0-076-9jl9x.18d4678fc03dc862,"reason=Pulled count=1 msg=Container image ""busybox:musl"" already present on machine"
0.4282,Event,ADDED,eval-conflicts-rho020-r0-076-9jl9x.18d4678fc18c70ae,reason=Created count=1 msg=Created container: task
0.4284,Event,ADDED,eval-conflicts-rho020-r0-076-9jl9x.18d4678fc5e0a97c,reason=Started count=1 msg=Started container task
0.4287,Event,ADDED,eval-conflicts-rho020-r0-076.18d4678fa390f99e,reason=SuccessfulCreate count=1 msg=Created pod: eval-conflicts-rho020-r0-076-9jl9x
0.4289,Event,ADDED,eval-conflicts-rho020-r0-076.18d46792f5a3f6c7,reason=Completed count=1 msg=Job completed
0.429,Event,ADDED,eval-conflicts-rho020-r0-077-zrlqs.18d4678fdf9a3739,"reason=FailedScheduling count=None msg=0/6 nodes are available: 2 c_wall violated: 1 conflicting context pair(s) with node memory, 4 node(s) had untolerated taint(s). no new claims to deallocate, preemption: 0/6 nodes are available: 2 No preemption victims found for incoming pod, 4 Preemption is not helpful for scheduling."
0.4293,Event,ADDED,eval-conflicts-rho020-r0-077-zrlqs.18d4678fe065b3cb,"reason=FailedScheduling count=None msg=0/6 nodes are available: 2 c_wall violated: 1 conflicting context pair(s) with node memory, 4 node(s) had untolerated taint(s). no new claims to deallocate, preemption: 0/6 nodes are available: 2 No preemption victims found for incoming pod, 4 Preemption is not helpful for scheduling."
0.4294,Event,ADDED,eval-conflicts-rho020-r0-077-zrlqs.18d4678fe21d6958,"reason=FailedScheduling count=None msg=0/6 nodes are available: 1 c_wall violated: 1 conflicting context pair(s) with node memory, 5 node(s) had untolerated taint(s). no new claims to deallocate, preemption: 0/6 nodes are available: 1 No preemption victims found for incoming pod, 5 Preemption is not helpful for scheduling."
0.4296,Event,ADDED,eval-conflicts-rho020-r0-077-zrlqs.18d4679045d80d50,reason=Scheduled count=None msg=Successfully assigned compute/eval-conflicts-rho020-r0-077-zrlqs to kind-worker2
0.4299,Event,ADDED,eval-conflicts-rho020-r0-077-zrlqs.18d467905ef2ba56,"reason=Pulled count=1 msg=Container image ""busybox:musl"" already present on machine"
0.4301,Event,ADDED,eval-conflicts-rho020-r0-077-zrlqs.18d46790605a4232,reason=Created count=1 msg=Created container: task
0.4303,Event,ADDED,eval-conflicts-rho020-r0-077-zrlqs.18d46790650d57f2,reason=Started count=1 msg=Started container task
0.4305,Event,ADDED,eval-conflicts-rho020-r0-077.18d4678fdf1ef74e,reason=SuccessfulCreate count=1 msg=Created pod: eval-conflicts-rho020-r0-077-zrlqs
0.431,Event,ADDED,eval-conflicts-rho020-r0-077.18d467939f6f7f4e,reason=Completed count=1 msg=Job completed
0.4311,Event,ADDED,eval-conflicts-rho020-r0-078-zbbjd.18d467901b5a6cef,reason=Scheduled count=None msg=Successfully assigned compute/eval-conflicts-rho020-r0-078-zbbjd to kind-worker
0.4313,Event,ADDED,eval-conflicts-rho020-r0-078-zbbjd.18d4679034de777f,"reason=Pulled count=1 msg=Container image ""busybox:musl"" already present on machine"
0.4315,Event,ADDED,eval-conflicts-rho020-r0-078-zbbjd.18d46790360d5088,reason=Created count=1 msg=Created container: task
0.4318,Event,ADDED,eval-conflicts-rho020-r0-078-zbbjd.18d467903aead8c3,reason=Started count=1 msg=Started container task
0.432,Event,ADDED,eval-conflicts-rho020-r0-078.18d467901ad59b68,reason=SuccessfulCreate count=1 msg=Created pod: eval-conflicts-rho020-r0-078-zbbjd
0.4322,Event,ADDED,eval-conflicts-rho020-r0-078.18d467936d7c947e,reason=Completed count=1 msg=Job completed
0.4325,Event,ADDED,eval-conflicts-rho020-r0-079-bjmxc.18d4679056ff2f51,reason=Scheduled count=None msg=Successfully assigned compute/eval-conflicts-rho020-r0-079-bjmxc to kind-worker2
0.4327,Event,ADDED,eval-conflicts-rho020-r0-079-bjmxc.18d4679074b2ac76,"reason=Pulled count=1 msg=Container image ""busybox:musl"" already present on machine"
0.433,Event,ADDED,eval-conflicts-rho020-r0-079-bjmxc.18d4679075c630ea,reason=Created count=1 msg=Created container: task
0.4331,Event,ADDED,eval-conflicts-rho020-r0-079-bjmxc.18d4679079bdb981,reason=Started count=1 msg=Started container task
0.4335,Event,ADDED,eval-conflicts-rho020-r0-079.18d467905671e394,reason=SuccessfulCreate count=1 msg=Created pod: eval-conflicts-rho020-r0-079-bjmxc
0.4337,Event,ADDED,eval-conflicts-rho020-r0-079.18d467939f47012d,reason=Completed count=1 msg=Job completed
0.4339,Event,ADDED,eval-conflicts-rho020-r0-080-d5j9k.18d4679092a7391f,reason=Scheduled count=None msg=Successfully assigned compute/eval-conflicts-rho020-r0-080-d5j9k to kind-worker5
0.4342,Event,ADDED,eval-conflicts-rho020-r0-080-d5j9k.18d46790ae062caf,"reason=Pulled count=1 msg=Container image ""busybox:musl"" already present on machine"
0.4345,Event,ADDED,eval-conflicts-rho020-r0-080-d5j9k.18d46790af1d9479,reason=Created count=1 msg=Created container: task
0.4347,Event,ADDED,eval-conflicts-rho020-r0-080-d5j9k.18d46790b35a9792,reason=Started count=1 msg=Started container task
0.4348,Event,ADDED,eval-conflicts-rho020-r0-080.18d4679092268a8f,reason=SuccessfulCreate count=1 msg=Created pod: eval-conflicts-rho020-r0-080-d5j9k
0.4352,Event,ADDED,eval-conflicts-rho020-r0-080.18d46793e7c31b67,reason=Completed count=1 msg=Job completed
0.4353,Event,ADDED,eval-conflicts-rho020-r0-081-swqks.18d46790cf1bd0e0,reason=Scheduled count=None msg=Successfully assigned compute/eval-conflicts-rho020-r0-081-swqks to kind-worker5
0.4356,Event,ADDED,eval-conflicts-rho020-r0-081-swqks.18d46790e9da5c64,"reason=Pulled count=1 msg=Container image ""busybox:musl"" already present on machine"
0.4358,Event,ADDED,eval-conflicts-rho020-r0-081-swqks.18d46790eadeb056,reason=Created count=1 msg=Created container: task
0.4361,Event,ADDED,eval-conflicts-rho020-r0-081-swqks.18d46790ecd4331c,reason=Started count=1 msg=Started container task
0.4363,Event,ADDED,eval-conflicts-rho020-r0-081.18d46790ce85d552,reason=SuccessfulCreate count=1 msg=Created pod: eval-conflicts-rho020-r0-081-swqks
0.4365,Event,ADDED,eval-conflicts-rho020-r0-081.18d46794239d72ad,reason=Completed count=1 msg=Job completed
0.4369,Event,ADDED,eval-conflicts-rho020-r0-082-vjr68.18d4679109e9ccb0,"reason=FailedScheduling count=None msg=0/6 nodes are available: 2 c_wall violated: 1 conflicting context pair(s) with node memory, 4 node(s) had untolerated taint(s). no new claims to deallocate, preemption: 0/6 nodes are available: 2 No preemption victims found for incoming pod, 4 Preemption is not helpful for scheduling."
0.4373,Event,ADDED,eval-conflicts-rho020-r0-082-vjr68.18d467910aa21047,"reason=FailedScheduling count=None msg=0/6 nodes are available: 2 c_wall violated: 1 conflicting context pair(s) with node memory, 4 node(s) had untolerated taint(s). no new claims to deallocate, preemption: 0/6 nodes are available: 2 No preemption victims found for incoming pod, 4 Preemption is not helpful for scheduling."
0.4376,Event,ADDED,eval-conflicts-rho020-r0-082-vjr68.18d46791823e2933,"reason=FailedScheduling count=None msg=0/6 nodes are available: 1 c_wall violated: 1 conflicting context pair(s) with node memory, 1 c_wall violated: 2 conflicting context pair(s) with node memory, 4 node(s) had untolerated taint(s). no new claims to deallocate, preemption: 0/6 nodes are available: 2 No preemption victims found for incoming pod, 4 Preemption is not helpful for scheduling."
0.4381,Event,ADDED,eval-conflicts-rho020-r0-082-vjr68.18d4679258aae977,reason=Scheduled count=None msg=Successfully assigned compute/eval-conflicts-rho020-r0-082-vjr68 to kind-worker3
0.4384,Event,ADDED,eval-conflicts-rho020-r0-082-vjr68.18d46792713d1215,"reason=Pulled count=1 msg=Container image ""busybox:musl"" already present on machine"
0.4387,Event,ADDED,eval-conflicts-rho020-r0-082-vjr68.18d4679272584186,reason=Created count=1 msg=Created container: task
0.4389,Event,ADDED,eval-conflicts-rho020-r0-082-vjr68.18d467927730256d,reason=Started count=1 msg=Started container task
0.4393,Event,ADDED,eval-conflicts-rho020-r0-082.18d4679109808840,reason=SuccessfulCreate count=1 msg=Created pod: eval-conflicts-rho020-r0-082-vjr68
0.4396,Event,ADDED,eval-conflicts-rho020-r0-082.18d467959ef8016e,reason=Completed count=1 msg=Job completed
0.4398,Event,ADDED,eval-conflicts-rho020-r0-083-nj5r7.18d46791455f5d76,reason=Scheduled count=None msg=Successfully assigned compute/eval-conflicts-rho020-r0-083-nj5r7 to kind-worker2
0.4401,Event,ADDED,eval-conflicts-rho020-r0-083-nj5r7.18d467915fbff555,"reason=Pulled count=1 msg=Container image ""busybox:musl"" already present on machine"
0.4403,Event,ADDED,eval-conflicts-rho020-r0-083-nj5r7.18d4679160f6ae48,reason=Created count=1 msg=Created container: task
0.4405,Event,ADDED,eval-conflicts-rho020-r0-083-nj5r7.18d46791633a8f31,reason=Started count=1 msg=Started container task
0.4407,Event,ADDED,eval-conflicts-rho020-r0-083.18d4679144aac7fe,reason=SuccessfulCreate count=1 msg=Created pod: eval-conflicts-rho020-r0-083-nj5r7
0.441,Event,ADDED,eval-conflicts-rho020-r0-083.18d46794905414e3,reason=Completed count=1 msg=Job completed
0.4412,Event,ADDED,eval-conflicts-rho020-r0-084-xwskm.18d4679181118348,reason=Scheduled count=None msg=Successfully assigned compute/eval-conflicts-rho020-r0-084-xwskm to kind-worker5
0.4414,Event,ADDED,eval-conflicts-rho020-r0-084-xwskm.18d467919ac0f3ac,"reason=Pulled count=1 msg=Container image ""busybox:musl"" already present on machine"
0.4416,Event,ADDED,eval-conflicts-rho020-r0-084-xwskm.18d467919bd3fd70,reason=Created count=1 msg=Created container: task
0.4419,Event,ADDED,eval-conflicts-rho020-r0-084-xwskm.18d467919df7a293,reason=Started count=1 msg=Started container task
0.4421,Event,ADDED,eval-conflicts-rho020-r0-084.18d467918059c578,reason=SuccessfulCreate count=1 msg=Created pod: eval-conflicts-rho020-r0-084-xwskm
0.4423,Event,ADDED,eval-conflicts-rho020-r0-084.18d46794d6cdcb37,reason=Completed count=1 msg=Job completed
0.4426,Event,ADDED,eval-conflicts-rho020-r0-085-bc8wb.18d46791bc81a627,reason=Scheduled count=None msg=Successfully assigned compute/eval-conflicts-rho020-r0-085-bc8wb to kind-worker2
0.4428,Event,ADDED,eval-conflicts-rho020-r0-085-bc8wb.18d46791d71ffd81,"reason=Pulled count=1 msg=Container image ""busybox:musl"" already present on machine"
0.443,Event,ADDED,eval-conflicts-rho020-r0-085-bc8wb.18d46791d866c337,reason=Created count=1 msg=Created container: task
0.4432,Event,ADDED,eval-conflicts-rho020-r0-085-bc8wb.18d46791ddf8f448,reason=Started count=1 msg=Started container task
0.4435,Event,ADDED,eval-conflicts-rho020-r0-085.18d46791bbd9478d,reason=SuccessfulCreate count=1 msg=Created pod: eval-conflicts-rho020-r0-085-bc8wb
0.4437,Event,ADDED,eval-conflicts-rho020-r0-085.18d46795061cd960,reason=Completed count=1 msg=Job completed
0.4439,Event,ADDED,eval-conflicts-rho020-r0-086-9t9fh.18d46791f922d5a6,reason=Scheduled count=None msg=Successfully assigned compute/eval-conflicts-rho020-r0-086-9t9fh to kind-worker5
0.4441,Event,ADDED,eval-conflicts-rho020-r0-086-9t9fh.18d46792141d7312,"reason=Pulled count=1 msg=Container image ""busybox:musl"" already present on machine"
0.4443,Event,ADDED,eval-conflicts-rho020-r0-086-9t9fh.18d4679215669c79,reason=Created count=1 msg=Created container: task
0.4444,Event,ADDED,eval-conflicts-rho020-r0-086-9t9fh.18d4679219ad291f,reason=Started count=1 msg=Started container task
0.4446,Event,ADDED,eval-conflicts-rho020-r0-086.18d46791f7e277cc,reason=SuccessfulCreate count=1 msg=Created pod: eval-conflicts-rho020-r0-086-9t9fh
0.4448,Event,ADDED,eval-conflicts-rho020-r0-086.18d467954e62b2b8,reason=Completed count=1 msg=Job completed
0.4449,Event,ADDED,eval-conflicts-rho020-r0-087-ms59s.18d4679233ff8be7,reason=Scheduled count=None msg=Successfully assigned compute/eval-conflicts-rho020-r0-087-ms59s to kind-worker5
0.4452,Event,ADDED,eval-conflicts-rho020-r0-087-ms59s.18d467924c730ad5,"reason=Pulled count=1 msg=Container image ""busybox:musl"" already present on machine"
0.4454,Event,ADDED,eval-conflicts-rho020-r0-087-ms59s.18d467924d82d0d5,reason=Created count=1 msg=Created container: task
0.4457,Event,ADDED,eval-conflicts-rho020-r0-087-ms59s.18d467924f8bfbde,reason=Started count=1 msg=Started container task
0.4459,Event,ADDED,eval-conflicts-rho020-r0-087.18d4679233137513,reason=SuccessfulCreate count=1 msg=Created pod: eval-conflicts-rho020-r0-087-ms59s
0.4461,Event,ADDED,eval-conflicts-rho020-r0-087.18d467958a30dd00,reason=Completed count=1 msg=Job completed
0.4464,Event,ADDED,eval-conflicts-rho020-r0-088-g2mg9.18d467926f8665c4,reason=Scheduled count=None msg=Successfully assigned compute/eval-conflicts-rho020-r0-088-g2mg9 to kind-worker2
0.4465,Event,ADDED,eval-conflicts-rho020-r0-088-g2mg9.18d4679288d24ff9,"reason=Pulled count=1 msg=Container image ""busybox:musl"" already present on machine"
0.4467,Event,ADDED,eval-conflicts-rho020-r0-088-g2mg9.18d4679289efdae7,reason=Created count=1 msg=Created container: task
0.4469,Event,ADDED,eval-conflicts-rho020-r0-088-g2mg9.18d467928bdc9ff6,reason=Started count=1 msg=Started container task
0.4471,Event,ADDED,eval-conflicts-rho020-r0-088.18d467926ea6073e,reason=SuccessfulCreate count=1 msg=Created pod: eval-conflicts-rho020-r0-088-g2mg9
0.4473,Event,ADDED,eval-conflicts-rho020-r0-088.18d46795b9be1fbc,reason=Completed count=1 msg=Job completed
0.4475,Event,ADDED,eval-conflicts-rho020-r0-089-mlmwd.18d46792aabb1c84,reason=Scheduled count=None msg=Successfully assigned compute/eval-conflicts-rho020-r0-089-mlmwd to kind-worker3
0.4477,Event,ADDED,eval-conflicts-rho020-r0-089-mlmwd.18d46792c3a0e034,"reason=Pulled count=1 msg=Container image ""busybox:musl"" already present on machine"
0.448,Event,ADDED,eval-conflicts-rho020-r0-089-mlmwd.18d46792c4bc9b13,reason=Created count=1 msg=Created container: task
0.4482,Event,ADDED,eval-conflicts-rho020-r0-089-mlmwd.18d46792c6e43df9,reason=Started count=1 msg=Started container task
0.4483,Event,ADDED,eval-conflicts-rho020-r0-089.18d46792aa0bc2ff,reason=SuccessfulCreate count=1 msg=Created pod: eval-conflicts-rho020-r0-089-mlmwd
0.4485,Event,ADDED,eval-conflicts-rho020-r0-089.18d46795db259bc4,reason=Completed count=1 msg=Job completed
0.4487,Event,ADDED,eval-conflicts-rho020-r0-090-ms5qj.18d46792e670579d,reason=Scheduled count=None msg=Successfully assigned compute/eval-conflicts-rho020-r0-090-ms5qj to kind-worker4
0.4488,Event,ADDED,eval-conflicts-rho020-r0-090-ms5qj.18d46792ffcf1cad,"reason=Pulled count=1 msg=Container image ""busybox:musl"" already present on machine"
0.449,Event,ADDED,eval-conflicts-rho020-r0-090-ms5qj.18d4679300d78134,reason=Created count=1 msg=Created container: task
0.4493,Event,ADDED,eval-conflicts-rho020-r0-090-ms5qj.18d4679302c77050,reason=Started count=1 msg=Started container task
0.4495,Event,ADDED,eval-conflicts-rho020-r0-090.18d46792e5ca6113,reason=SuccessfulCreate count=1 msg=Created pod: eval-conflicts-rho020-r0-090-ms5qj
0.4496,Event,ADDED,eval-conflicts-rho020-r0-090.18d4679642e9ac6f,reason=Completed count=1 msg=Job completed
0.4498,Event,ADDED,eval-conflicts-rho020-r0-091-fqbts.18d4679321fc2517,reason=Scheduled count=None msg=Successfully assigned compute/eval-conflicts-rho020-r0-091-fqbts to kind-worker3
0.4499,Event,ADDED,eval-conflicts-rho020-r0-091-fqbts.18d467933b43f29d,"reason=Pulled count=1 msg=Container image ""busybox:musl"" already present on machine"
0.4501,Event,ADDED,eval-conflicts-rho020-r0-091-fqbts.18d467933c53a8e8,reason=Created count=1 msg=Created container: task
0.4503,Event,ADDED,eval-conflicts-rho020-r0-091-fqbts.18d467933e5e5abe,reason=Started count=1 msg=Started container task
0.4504,Event,ADDED,eval-conflicts-rho020-r0-091.18d46793215f0a9f,reason=SuccessfulCreate count=1 msg=Created pod: eval-conflicts-rho020-r0-091-fqbts
0.4506,Event,ADDED,eval-conflicts-rho020-r0-091.18d46796526f5d11,reason=Completed count=1 msg=Job completed
0.4507,Event,ADDED,eval-conflicts-rho020-r0-092-cmrjr.18d467935e4120cf,reason=Scheduled count=None msg=Successfully assigned compute/eval-conflicts-rho020-r0-092-cmrjr to kind-worker4
0.4509,Event,ADDED,eval-conflicts-rho020-r0-092-cmrjr.18d4679376badbb9,"reason=Pulled count=1 msg=Container image ""busybox:musl"" already present on machine"
0.4511,Event,ADDED,eval-conflicts-rho020-r0-092-cmrjr.18d4679377cc923d,reason=Created count=1 msg=Created container: task
0.4512,Event,ADDED,eval-conflicts-rho020-r0-092-cmrjr.18d4679379dad1d4,reason=Started count=1 msg=Started container task
0.4514,Event,ADDED,eval-conflicts-rho020-r0-092.18d467935d73f350,reason=SuccessfulCreate count=1 msg=Created pod: eval-conflicts-rho020-r0-092-cmrjr
0.4517,Event,ADDED,eval-conflicts-rho020-r0-092.18d46796bb093d37,reason=Completed count=1 msg=Job completed
0.4519,Event,ADDED,eval-conflicts-rho020-r0-093-f7hvr.18d467939a5864c2,"reason=FailedScheduling count=None msg=0/6 nodes are available: 2 c_wall violated: 1 conflicting context pair(s) with node memory, 4 node(s) had untolerated taint(s). no new claims to deallocate, preemption: 0/6 nodes are available: 2 No preemption victims found for incoming pod, 4 Preemption is not helpful for scheduling."
0.4521,Event,ADDED,eval-conflicts-rho020-r0-093-f7hvr.18d467939b1ca207,"reason=FailedScheduling count=None msg=0/6 nodes are available: 2 c_wall violated: 1 conflicting context pair(s) with node memory, 4 node(s) had untolerated taint(s). no new claims to deallocate, preemption: 0/6 nodes are available: 2 No preemption victims found for incoming pod, 4 Preemption is not helpful for scheduling."
0.4524,Event,ADDED,eval-conflicts-rho020-r0-093-f7hvr.18d46794af36b70f,"reason=FailedScheduling count=None msg=0/6 nodes are available: 1 c_wall violated: 1 conflicting context pair(s) with node memory, 5 node(s) had untolerated taint(s). no new claims to deallocate, preemption: 0/6 nodes are available: 1 No preemption victims found for incoming pod, 5 Preemption is not helpful for scheduling."
0.4526,Event,ADDED,eval-conflicts-rho020-r0-093-f7hvr.18d46794f9669edb,reason=Scheduled count=None msg=Successfully assigned compute/eval-conflicts-rho020-r0-093-f7hvr to kind-worker
0.4527,Event,ADDED,eval-conflicts-rho020-r0-093-f7hvr.18d467951294e44a,"reason=Pulled count=1 msg=Container image ""busybox:musl"" already present on machine"
0.4529,Event,ADDED,eval-conflicts-rho020-r0-093-f7hvr.18d467951436104d,reason=Created count=1 msg=Created container: task
0.4532,Event,ADDED,eval-conflicts-rho020-r0-093-f7hvr.18d4679518c9185f,reason=Started count=1 msg=Started container task
0.4534,Event,ADDED,eval-conflicts-rho020-r0-093.18d4679399e8f14a,reason=SuccessfulCreate count=1 msg=Created pod: eval-conflicts-rho020-r0-093-f7hvr
0.4536,Event,ADDED,eval-conflicts-rho020-r0-093.18d4679855e2d788,reason=Completed count=1 msg=Job completed
0.4538,Event,ADDED,eval-conflicts-rho020-r0-094-gstkm.18d46793d523bce1,"reason=FailedScheduling count=None msg=0/6 nodes are available: 2 c_wall violated: 1 conflicting context pair(s) with node memory, 4 node(s) had untolerated taint(s). no new claims to deallocate, preemption: 0/6 nodes are available: 2 No preemption victims found for incoming pod, 4 Preemption is not helpful for scheduling."
0.454,Event,ADDED,eval-conflicts-rho020-r0-094-gstkm.18d46793d5d16615,"reason=FailedScheduling count=None msg=0/6 nodes are available: 2 c_wall violated: 1 conflicting context pair(s) with node memory, 4 node(s) had untolerated taint(s). no new claims to deallocate, preemption: 0/6 nodes are available: 2 No preemption victims found for incoming pod, 4 Preemption is not helpful for scheduling."
0.4542,Event,ADDED,eval-conflicts-rho020-r0-094-gstkm.18d46794aee483ae,"reason=FailedScheduling count=None msg=0/6 nodes are available: 1 c_wall violated: 1 conflicting context pair(s) with node memory, 5 node(s) had untolerated taint(s). no new claims to deallocate, preemption: 0/6 nodes are available: 1 No preemption victims found for incoming pod, 5 Preemption is not helpful for scheduling."
0.4543,Event,ADDED,eval-conflicts-rho020-r0-094-gstkm.18d46794fa1b4b3a,reason=Scheduled count=None msg=Successfully assigned compute/eval-conflicts-rho020-r0-094-gstkm to kind-worker
0.4545,Event,ADDED,eval-conflicts-rho020-r0-094-gstkm.18d4679518cd01bb,"reason=Pulled count=1 msg=Container image ""busybox:musl"" already present on machine"
0.4547,Event,ADDED,eval-conflicts-rho020-r0-094-gstkm.18d467951a8173d5,reason=Created count=1 msg=Created container: task
0.4548,Event,ADDED,eval-conflicts-rho020-r0-094-gstkm.18d4679522ae3f93,reason=Started count=1 msg=Started container task
0.455,Event,ADDED,eval-conflicts-rho020-r0-094.18d46793d4b63c69,reason=SuccessfulCreate count=1 msg=Created pod: eval-conflicts-rho020-r0-094-gstkm
0.4552,Event,ADDED,eval-conflicts-rho020-r0-094.18d4679854ed385a,reason=Completed count=1 msg=Job completed
0.4553,Event,ADDED,eval-conflicts-rho020-r0-095-7hh7k.18d4679410cb7236,"reason=FailedScheduling count=None msg=0/6 nodes are available: 2 c_wall violated: 1 conflicting context pair(s) with node memory, 4 node(s) had untolerated taint(s). no new claims to deallocate, preemption: 0/6 nodes are available: 2 No preemption victims found for incoming pod, 4 Preemption is not helpful for scheduling."
0.4556,Event,ADDED,eval-conflicts-rho020-r0-095-7hh7k.18d46794117c014d,"reason=FailedScheduling count=None msg=0/6 nodes are available: 2 c_wall violated: 1 conflicting context pair(s) with node memory, 4 node(s) had untolerated taint(s). no new claims to deallocate, preemption: 0/6 nodes are available: 2 No preemption victims found for incoming pod, 4 Preemption is not helpful for scheduling."
0.4558,Event,ADDED,eval-conflicts-rho020-r0-095-7hh7k.18d46794af0b34cd,"reason=FailedScheduling count=None msg=0/6 nodes are available: 1 c_wall violated: 1 conflicting context pair(s) with node memory, 5 node(s) had untolerated taint(s). no new claims to deallocate, preemption: 0/6 nodes are available: 1 No preemption victims found for incoming pod, 5 Preemption is not helpful for scheduling."
0.4559,Event,ADDED,eval-conflicts-rho020-r0-095-7hh7k.18d46794fa46d784,reason=Scheduled count=None msg=Successfully assigned compute/eval-conflicts-rho020-r0-095-7hh7k to kind-worker
0.4562,Event,ADDED,eval-conflicts-rho020-r0-095-7hh7k.18d4679518da5764,"reason=Pulled count=1 msg=Container image ""busybox:musl"" already present on machine"
0.4564,Event,ADDED,eval-conflicts-rho020-r0-095-7hh7k.18d467951b3d0fe9,reason=Created count=1 msg=Created container: task
0.4565,Event,ADDED,eval-conflicts-rho020-r0-095-7hh7k.18d467951f7c2735,reason=Started count=1 msg=Started container task
0.4567,Event,ADDED,eval-conflicts-rho020-r0-095.18d467941057cadd,reason=SuccessfulCreate count=1 msg=Created pod: eval-conflicts-rho020-r0-095-7hh7k
0.4576,Event,ADDED,eval-conflicts-rho020-r0-095.18d4679854ef53f8,reason=Completed count=1 msg=Job completed
0.4577,Event,ADDED,eval-conflicts-rho020-r0-096-jnrhm.18d467944c9a0877,reason=Scheduled count=None msg=Successfully assigned compute/eval-conflicts-rho020-r0-096-jnrhm to kind-worker3
0.4579,Event,ADDED,eval-conflicts-rho020-r0-096-jnrhm.18d4679466083dc3,"reason=Pulled count=1 msg=Container image ""busybox:musl"" already present on machine"
0.4581,Event,ADDED,eval-conflicts-rho020-r0-096-jnrhm.18d467946715cdc8,reason=Created count=1 msg=Created container: task
0.4583,Event,ADDED,eval-conflicts-rho020-r0-096-jnrhm.18d4679468fca044,reason=Started count=1 msg=Started container task
0.4586,Event,ADDED,eval-conflicts-rho020-r0-096.18d467944be2dabe,reason=SuccessfulCreate count=1 msg=Created pod: eval-conflicts-rho020-r0-096-jnrhm
0.4588,Event,ADDED,eval-conflicts-rho020-r0-096.18d467977d8e65d1,reason=Completed count=1 msg=Job completed
0.459,Event,ADDED,eval-conflicts-rho020-r0-097-z6nsd.18d46794883e786d,reason=Scheduled count=None msg=Successfully assigned compute/eval-conflicts-rho020-r0-097-z6nsd to kind-worker4
0.4592,Event,ADDED,eval-conflicts-rho020-r0-097-z6nsd.18d46794a25af158,"reason=Pulled count=1 msg=Container image ""busybox:musl"" already present on machine"
0.4593,Event,ADDED,eval-conflicts-rho020-r0-097-z6nsd.18d46794a3781444,reason=Created count=1 msg=Created container: task
0.4596,Event,ADDED,eval-conflicts-rho020-r0-097-z6nsd.18d46794ac8468b6,reason=Started count=1 msg=Started container task
0.4598,Event,ADDED,eval-conflicts-rho020-r0-097.18d467948719c6b3,reason=SuccessfulCreate count=1 msg=Created pod: eval-conflicts-rho020-r0-097-z6nsd
0.46,Event,ADDED,eval-conflicts-rho020-r0-097.18d46797eaaef804,reason=Completed count=1 msg=Job completed
0.4602,Event,ADDED,eval-conflicts-rho020-r0-098-rxrfn.18d46794c2fb3fe1,reason=Scheduled count=None msg=Successfully assigned compute/eval-conflicts-rho020-r0-098-rxrfn to kind-worker4
0.4603,Event,ADDED,eval-conflicts-rho020-r0-098-rxrfn.18d46794dbb634ac,"reason=Pulled count=1 msg=Container image ""busybox:musl"" already present on machine"
0.4607,Event,ADDED,eval-conflicts-rho020-r0-098-rxrfn.18d46794dccb6077,reason=Created count=1 msg=Created container: task
0.4608,Event,ADDED,eval-conflicts-rho020-r0-098-rxrfn.18d46794df3a4493,reason=Started count=1 msg=Started container task
0.461,Event,ADDED,eval-conflicts-rho020-r0-098.18d46794c278f30e,reason=SuccessfulCreate count=1 msg=Created pod: eval-conflicts-rho020-r0-098-rxrfn
0.4612,Event,ADDED,eval-conflicts-rho020-r0-098.18d4679826d1d326,reason=Completed count=1 msg=Job completed
0.4614,Event,ADDED,eval-conflicts-rho020-r0-099-q54dz.18d46794ff4bfc94,reason=Scheduled count=None msg=Successfully assigned compute/eval-conflicts-rho020-r0-099-q54dz to kind-worker
0.4616,Event,ADDED,eval-conflicts-rho020-r0-099-q54dz.18d46795192d1505,"reason=Pulled count=1 msg=Container image ""busybox:musl"" already present on machine"
0.4617,Event,ADDED,eval-conflicts-rho020-r0-099-q54dz.18d467951b707581,reason=Created count=1 msg=Created container: task
0.4619,Event,ADDED,eval-conflicts-rho020-r0-099-q54dz.18d467951f7b4de3,reason=Started count=1 msg=Started container task
0.4621,Event,ADDED,eval-conflicts-rho020-r0-099.18d46794fe0dbf8b,reason=SuccessfulCreate count=1 msg=Created pod: eval-conflicts-rho020-r0-099-q54dz
0.4623,Event,ADDED,eval-conflicts-rho020-r0-099.18d4679855101985,reason=Completed count=1 msg=Job completed
0.4624,Event,ADDED,eval-conflicts-rho020-r1-000-2db75.18d4679d81e5ea43,reason=Scheduled count=None msg=Successfully assigned compute/eval-conflicts-rho020-r1-000-2db75 to kind-worker5
0.4626,Event,ADDED,eval-conflicts-rho020-r1-000-2db75.18d4679d9b86ae32,"reason=Pulled count=1 msg=Container image ""busybox:musl"" already present on machine"
0.4628,Event,ADDED,eval-conflicts-rho020-r1-000-2db75.18d4679d9cbe330c,reason=Created count=1 msg=Created container: task
0.4629,Event,ADDED,eval-conflicts-rho020-r1-000-2db75.18d4679d9ee52d53,reason=Started count=1 msg=Started container task
0.4631,Event,ADDED,eval-conflicts-rho020-r1-000.18d4679d80dad958,reason=SuccessfulCreate count=1 msg=Created pod: eval-conflicts-rho020-r1-000-2db75
0.4633,Event,ADDED,eval-conflicts-rho020-r1-000.18d467a0c27d801c,reason=Completed count=1 msg=Job completed
0.4634,Event,ADDED,eval-conflicts-rho020-r1-001-fpwsm.18d4679dbd1a59bb,reason=Scheduled count=None msg=Successfully assigned compute/eval-conflicts-rho020-r1-001-fpwsm to kind-worker5
0.4637,Event,ADDED,eval-conflicts-rho020-r1-001-fpwsm.18d4679dd6b7c32f,"reason=Pulled count=1 msg=Container image ""busybox:musl"" already present on machine"
0.4639,Event,ADDED,eval-conflicts-rho020-r1-001-fpwsm.18d4679dd7e079c0,reason=Created count=1 msg=Created container: task
0.4641,Event,ADDED,eval-conflicts-rho020-r1-001-fpwsm.18d4679dd9e3c40f,reason=Started count=1 msg=Started container task
0.4643,Event,ADDED,eval-conflicts-rho020-r1-001.18d4679dbc068b88,reason=SuccessfulCreate count=1 msg=Created pod: eval-conflicts-rho020-r1-001-fpwsm
0.4645,Event,ADDED,eval-conflicts-rho020-r1-001.18d467a0fe4f7280,reason=Completed count=1 msg=Job completed
0.4646,Event,ADDED,eval-conflicts-rho020-r1-002-xkpgb.18d4679df732997b,reason=Scheduled count=None msg=Successfully assigned compute/eval-conflicts-rho020-r1-002-xkpgb to kind-worker2
0.4648,Event,ADDED,eval-conflicts-rho020-r1-002-xkpgb.18d4679e10220e1b,"reason=Pulled count=1 msg=Container image ""busybox:musl"" already present on machine"
0.465,Event,ADDED,eval-conflicts-rho020-r1-002-xkpgb.18d4679e113b307d,reason=Created count=1 msg=Created container: task
0.4651,Event,ADDED,eval-conflicts-rho020-r1-002-xkpgb.18d4679e15ef3360,reason=Started count=1 msg=Started container task
0.4653,Event,ADDED,eval-conflicts-rho020-r1-002.18d4679df67b77e0,reason=SuccessfulCreate count=1 msg=Created pod: eval-conflicts-rho020-r1-002-xkpgb
0.4655,Event,ADDED,eval-conflicts-rho020-r1-002.18d467a12a435f29,reason=Completed count=1 msg=Job completed
0.4656,Event,ADDED,eval-conflicts-rho020-r1-003-5x2l8.18d4679e33a72944,reason=Scheduled count=None msg=Successfully assigned compute/eval-conflicts-rho020-r1-003-5x2l8 to kind-worker
0.4658,Event,ADDED,eval-conflicts-rho020-r1-003-5x2l8.18d4679e4d355a18,"reason=Pulled count=1 msg=Container image ""busybox:musl"" already present on machine"
0.466,Event,ADDED,eval-conflicts-rho020-r1-003-5x2l8.18d4679e4e4bc344,reason=Created count=1 msg=Created container: task
0.4661,Event,ADDED,eval-conflicts-rho020-r1-003-5x2l8.18d4679e5043ad82,reason=Started count=1 msg=Started container task
0.4663,Event,ADDED,eval-conflicts-rho020-r1-003.18d4679e32a05d3e,reason=SuccessfulCreate count=1 msg=Created pod: eval-conflicts-rho020-r1-003-5x2l8
0.4667,Event,ADDED,eval-conflicts-rho020-r1-003.18d467a1716ee5a0,reason=Completed count=1 msg=Job completed
0.4668,Event,ADDED,eval-conflicts-rho020-r1-004-b8lrq.18d4679e6fde35cd,reason=Scheduled count=None msg=Successfully assigned compute/eval-conflicts-rho020-r1-004-b8lrq to kind-worker
0.467,Event,ADDED,eval-conflicts-rho020-r1-004-b8lrq.18d4679e8814f91a,"reason=Pulled count=1 msg=Container image ""busybox:musl"" already present on machine"
0.4672,Event,ADDED,eval-conflicts-rho020-r1-004-b8lrq.18d4679e89276098,reason=Created count=1 msg=Created container: task
0.4673,Event,ADDED,eval-conflicts-rho020-r1-004-b8lrq.18d4679e8b411604,reason=Started count=1 msg=Started container task
0.4676,Event,ADDED,eval-conflicts-rho020-r1-004.18d4679e6ea80a30,reason=SuccessfulCreate count=1 msg=Created pod: eval-conflicts-rho020-r1-004-b8lrq
0.4678,Event,ADDED,eval-conflicts-rho020-r1-004.18d467a1ad28be28,reason=Completed count=1 msg=Job completed
0.468,Event,ADDED,eval-conflicts-rho020-r1-005-nrjz7.18d4679eaa2812de,reason=Scheduled count=None msg=Successfully assigned compute/eval-conflicts-rho020-r1-005-nrjz7 to kind-worker4
0.4682,Event,ADDED,eval-conflicts-rho020-r1-005-nrjz7.18d4679ec32881c3,"reason=Pulled count=1 msg=Container image ""busybox:musl"" already present on machine"
0.4684,Event,ADDED,eval-conflicts-rho020-r1-005-nrjz7.18d4679ec42daeea,reason=Created count=1 msg=Created container: task
0.4686,Event,ADDED,eval-conflicts-rho020-r1-005-nrjz7.18d4679ec61653f3,reason=Started count=1 msg=Started container task
0.4688,Event,ADDED,eval-conflicts-rho020-r1-005.18d4679ea995f9a5,reason=SuccessfulCreate count=1 msg=Created pod: eval-conflicts-rho020-r1-005-nrjz7
0.469,Event,ADDED,eval-conflicts-rho020-r1-005.18d467a1b301dd14,reason=Completed count=1 msg=Job completed
0.4691,Event,ADDED,eval-conflicts-rho020-r1-006-dlnd9.18d4679ee5e84082,reason=Scheduled count=None msg=Successfully assigned compute/eval-conflicts-rho020-r1-006-dlnd9 to kind-worker4
0.4693,Event,ADDED,eval-conflicts-rho020-r1-006-dlnd9.18d4679eff02097d,"reason=Pulled count=1 msg=Container image ""busybox:musl"" already present on machine"
0.4695,Event,ADDED,eval-conflicts-rho020-r1-006-dlnd9.18d4679f00991508,reason=Created count=1 msg=Created container: task
0.4697,Event,ADDED,eval-conflicts-rho020-r1-006-dlnd9.18d4679f0567dfca,reason=Started count=1 msg=Started container task
0.4698,Event,ADDED,eval-conflicts-rho020-r1-006.18d4679ee5332d44,reason=SuccessfulCreate count=1 msg=Created pod: eval-conflicts-rho020-r1-006-dlnd9
0.47,Event,ADDED,eval-conflicts-rho020-r1-006.18d467a22a80218c,reason=Completed count=1 msg=Job completed
0.4701,Event,ADDED,eval-conflicts-rho020-r1-007-5d9ck.18d4679f21e422d7,reason=Scheduled count=None msg=Successfully assigned compute/eval-conflicts-rho020-r1-007-5d9ck to kind-worker4
0.4703,Event,ADDED,eval-conflicts-rho020-r1-007-5d9ck.18d4679f3b673edc,"reason=Pulled count=1 msg=Container image ""busybox:musl"" already present on machine"
0.4705,Event,ADDED,eval-conflicts-rho020-r1-007-5d9ck.18d4679f3c754066,reason=Created count=1 msg=Created container: task
0.4706,Event,ADDED,eval-conflicts-rho020-r1-007-5d9ck.18d4679f3ff4e7ea,reason=Started count=1 msg=Started container task
0.4708,Event,ADDED,eval-conflicts-rho020-r1-007.18d4679f21052a32,reason=SuccessfulCreate count=1 msg=Created pod: eval-conflicts-rho020-r1-007-5d9ck
0.471,Event,ADDED,eval-conflicts-rho020-r1-007.18d467a2662d475f,reason=Completed count=1 msg=Job completed
0.4711,Event,ADDED,eval-conflicts-rho020-r1-008-5svl6.18d4679f5e067de7,reason=Scheduled count=None msg=Successfully assigned compute/eval-conflicts-rho020-r1-008-5svl6 to kind-worker4
0.4713,Event,ADDED,eval-conflicts-rho020-r1-008-5svl6.18d4679f76aea3f1,"reason=Pulled count=1 msg=Container image ""busybox:musl"" already present on machine"
0.4714,Event,ADDED,eval-conflicts-rho020-r1-008-5svl6.18d4679f77c54084,reason=Created count=1 msg=Created container: task
0.4717,Event,ADDED,eval-conflicts-rho020-r1-008-5svl6.18d4679f7b93fcf2,reason=Started count=1 msg=Started container task
0.4719,Event,ADDED,eval-conflicts-rho020-r1-008.18d4679f5d3f1297,reason=SuccessfulCreate count=1 msg=Created pod: eval-conflicts-rho020-r1-008-5svl6
0.4721,Event,ADDED,eval-conflicts-rho020-r1-008.18d467a2a1f91cfe,reason=Completed count=1 msg=Job completed
0.4722,Event,ADDED,eval-conflicts-rho020-r1-009-wbrrg.18d4679f9886cf75,reason=Scheduled count=None msg=Successfully assigned compute/eval-conflicts-rho020-r1-009-wbrrg to kind-worker3
0.4724,Event,ADDED,eval-conflicts-rho020-r1-009-wbrrg.18d4679fb18d18c1,"reason=Pulled count=1 msg=Container image ""busybox:musl"" already present on machine"
0.4726,Event,ADDED,eval-conflicts-rho020-r1-009-wbrrg.18d4679fb2c1ff3f,reason=Created count=1 msg=Created container: task
0.4728,Event,ADDED,eval-conflicts-rho020-r1-009-wbrrg.18d4679fb4bf51d3,reason=Started count=1 msg=Started container task
0.4729,Event,ADDED,eval-conflicts-rho020-r1-009.18d4679f97e90885,reason=SuccessfulCreate count=1 msg=Created pod: eval-conflicts-rho020-r1-009-wbrrg
0.4731,Event,ADDED,eval-conflicts-rho020-r1-009.18d467a2ef2afd73,reason=Completed count=1 msg=Job completed
0.4733,Event,ADDED,eval-conflicts-rho020-r1-010-8s2ck.18d4679fd49ac79a,reason=Scheduled count=None msg=Successfully assigned compute/eval-conflicts-rho020-r1-010-8s2ck to kind-worker3
0.4734,Event,ADDED,eval-conflicts-rho020-r1-010-8s2ck.18d4679feda238e8,"reason=Pulled count=1 msg=Container image ""busybox:musl"" already present on machine"
0.4736,Event,ADDED,eval-conflicts-rho020-r1-010-8s2ck.18d4679feebcb864,reason=Created count=1 msg=Created container: task
0.4738,Event,ADDED,eval-conflicts-rho020-r1-010-8s2ck.18d4679ff0c0f999,reason=Started count=1 msg=Started container task
0.4739,Event,ADDED,eval-conflicts-rho020-r1-010.18d4679fd39152b2,reason=SuccessfulCreate count=1 msg=Created pod: eval-conflicts-rho020-r1-010-8s2ck
0.4741,Event,ADDED,eval-conflicts-rho020-r1-010.18d467a329c3e59d,reason=Completed count=1 msg=Job completed
0.4742,Event,ADDED,eval-conflicts-rho020-r1-011-9dqq6.18d467a00ff18b75,reason=Scheduled count=None msg=Successfully assigned compute/eval-conflicts-rho020-r1-011-9dqq6 to kind-worker4
0.4744,Event,ADDED,eval-conflicts-rho020-r1-011-9dqq6.18d467a02ba58181,"reason=Pulled count=1 msg=Container image ""busybox:musl"" already present on machine"
0.4746,Event,ADDED,eval-conflicts-rho020-r1-011-9dqq6.18d467a02cd389bb,reason=Created count=1 msg=Created container: task
0.4748,Event,ADDED,eval-conflicts-rho020-r1-011-9dqq6.18d467a030fe94b8,reason=Started count=1 msg=Started container task
0.475,Event,ADDED,eval-conflicts-rho020-r1-011.18d467a00f1e883a,reason=SuccessfulCreate count=1 msg=Created pod: eval-conflicts-rho020-r1-011-9dqq6
0.4751,Event,ADDED,eval-conflicts-rho020-r1-011.18d467a357a1addf,reason=Completed count=1 msg=Job completed
0.4753,Event,ADDED,eval-conflicts-rho020-r1-012-kfszv.18d467a04d580229,reason=Scheduled count=None msg=Successfully assigned compute/eval-conflicts-rho020-r1-012-kfszv to kind-worker3
0.4755,Event,ADDED,eval-conflicts-rho020-r1-012-kfszv.18d467a06769bf93,"reason=Pulled count=1 msg=Container image ""busybox:musl"" already present on machine"
0.4756,Event,ADDED,eval-conflicts-rho020-r1-012-kfszv.18d467a06881d280,reason=Created count=1 msg=Created container: task
0.4758,Event,ADDED,eval-conflicts-rho020-r1-012-kfszv.18d467a06db3d2e5,reason=Started count=1 msg=Started container task
0.476,Event,ADDED,eval-conflicts-rho020-r1-012.18d467a04ca44fde,reason=SuccessfulCreate count=1 msg=Created pod: eval-conflicts-rho020-r1-012-kfszv
0.4761,Event,ADDED,eval-conflicts-rho020-r1-012.18d467a3a45d1413,reason=Completed count=1 msg=Job completed
0.4763,Event,ADDED,eval-conflicts-rho020-r1-013-hxf64.18d467a088885741,"reason=FailedScheduling count=None msg=0/6 nodes are available: 1 c_wall violated: 1 conflicting context pair(s) with node memory, 5 node(s) had untolerated taint(s). no new claims to deallocate, preemption: 0/6 nodes are available: 1 No preemption victims found for incoming pod, 5 Preemption is not helpful for scheduling."
0.4765,Event,ADDED,eval-conflicts-rho020-r1-013-hxf64.18d467a0890ea9ea,"reason=FailedScheduling count=None msg=0/6 nodes are available: 1 c_wall violated: 1 conflicting context pair(s) with node memory, 5 node(s) had untolerated taint(s). no new claims to deallocate, preemption: 0/6 nodes are available: 1 No preemption victims found for incoming pod, 5 Preemption is not helpful for scheduling."
0.4766,Event,ADDED,eval-conflicts-rho020-r1-013-hxf64.18d467a0ea981ae2,reason=Scheduled count=None msg=Successfully assigned compute/eval-conflicts-rho020-r1-013-hxf64 to kind-worker2
0.4768,Event,ADDED,eval-conflicts-rho020-r1-013-hxf64.18d467a1047d6d6a,"reason=Pulled count=1 msg=Container image ""busybox:musl"" already present on machine"
0.4769,Event,ADDED,eval-conflicts-rho020-r1-013-hxf64.18d467a10593475a,reason=Created count=1 msg=Created container: task
0.4771,Event,ADDED,eval-conflicts-rho020-r1-013-hxf64.18d467a1076e73d9,reason=Started count=1 msg=Started container task
0.4773,Event,ADDED,eval-conflicts-rho020-r1-013.18d467a0884bc76a,reason=SuccessfulCreate count=1 msg=Created pod: eval-conflicts-rho020-r1-013-hxf64
0.4774,Event,ADDED,eval-conflicts-rho020-r1-013.18d467a438299cbc,reason=Completed count=1 msg=Job completed
0.4776,Event,ADDED,eval-conflicts-rho020-r1-014-bp9sj.18d467a0c24b0fb9,"reason=FailedScheduling count=None msg=0/6 nodes are available: 1 c_wall violated: 2 conflicting context pair(s) with node memory, 5 node(s) had untolerated taint(s). no new claims to deallocate, preemption: 0/6 nodes are available: 1 No preemption victims found for incoming pod, 5 Preemption is not helpful for scheduling."
0.4778,Event,ADDED,eval-conflicts-rho020-r1-014-bp9sj.18d467a0c3013201,"reason=FailedScheduling count=None msg=0/6 nodes are available: 1 c_wall violated: 2 conflicting context pair(s) with node memory, 5 node(s) had untolerated taint(s). no new claims to deallocate, preemption: 0/6 nodes are available: 1 No preemption victims found for incoming pod, 5 Preemption is not helpful for scheduling."
0.478,Event,ADDED,eval-conflicts-rho020-r1-014-bp9sj.18d467a0ebdb5483,"reason=FailedScheduling count=None msg=0/6 nodes are available: 1 c_wall violated: 1 conflicting context pair(s) with node memory, 1 c_wall violated: 2 conflicting context pair(s) with node memory, 4 node(s) had untolerated taint(s). no new claims to deallocate, preemption: 0/6 nodes are available: 2 No preemption victims found for incoming pod, 4 Preemption is not helpful for scheduling."
0.4781,Event,ADDED,eval-conflicts-rho020-r1-014-bp9sj.18d467a0fc52a047,"reason=FailedScheduling count=None msg=0/6 nodes are available: 1 c_wall violated: 1 conflicting context pair(s) with node memory, 5 node(s) had untolerated taint(s). no new claims to deallocate, preemption: 0/6 nodes are available: 1 No preemption victims found for incoming pod, 5 Preemption is not helpful for scheduling."
0.4784,Event,ADDED,eval-conflicts-rho020-r1-014-bp9sj.18d467a1094ad03c,reason=Scheduled count=None msg=Successfully assigned compute/eval-conflicts-rho020-r1-014-bp9sj to kind-worker5
0.4786,Event,ADDED,eval-conflicts-rho020-r1-014-bp9sj.18d467a122e92fa5,"reason=Pulled count=1 msg=Container image ""busybox:musl"" already present on machine"
0.4787,Event,ADDED,eval-conflicts-rho020-r1-014-bp9sj.18d467a123fd90e9,reason=Created count=1 msg=Created container: task
0.4789,Event,ADDED,eval-conflicts-rho020-r1-014-bp9sj.18d467a129d54d91,reason=Started count=1 msg=Started container task
0.4791,Event,ADDED,eval-conflicts-rho020-r1-014.18d467a0c20a750a,reason=SuccessfulCreate count=1 msg=Created pod: eval-conflicts-rho020-r1-014-bp9sj
0.4793,Event,ADDED,eval-conflicts-rho020-r1-014.18d467a442f367db,reason=Completed count=1 msg=Job completed
0.4794,Event,ADDED,eval-conflicts-rho020-r1-015-kwk7h.18d467a0fd737c72,"reason=FailedScheduling count=None msg=0/6 nodes are available: 1 c_wall violated: 1 conflicting context pair(s) with node memory, 5 node(s) had untolerated taint(s). no new claims to deallocate, preemption: 0/6 nodes are available: 1 No preemption victims found for incoming pod, 5 Preemption is not helpful for scheduling."
0.4796,Event,ADDED,eval-conflicts-rho020-r1-015-kwk7h.18d467a0fe01a0b1,"reason=FailedScheduling count=None msg=0/6 nodes are available: 1 c_wall violated: 1 conflicting context pair(s) with node memory, 5 node(s) had untolerated taint(s). no new claims to deallocate, preemption: 0/6 nodes are available: 1 No preemption victims found for incoming pod, 5 Preemption is not helpful for scheduling."
0.4798,Event,ADDED,eval-conflicts-rho020-r1-015-kwk7h.18d467a10e72110c,"reason=FailedScheduling count=None msg=0/6 nodes are available: 2 c_wall violated: 1 conflicting context pair(s) with node memory, 4 node(s) had untolerated taint(s). no new claims to deallocate, preemption: 0/6 nodes are available: 2 No preemption victims found for incoming pod, 4 Preemption is not helpful for scheduling."
0.4799,Event,ADDED,eval-conflicts-rho020-r1-015-kwk7h.18d467a32dcd01d9,reason=Scheduled count=None msg=Successfully assigned compute/eval-conflicts-rho020-r1-015-kwk7h to kind-worker
0.4801,Event,ADDED,eval-conflicts-rho020-r1-015-kwk7h.18d467a3484364cd,"reason=Pulled count=1 msg=Container image ""busybox:musl"" already present on machine"
0.4803,Event,ADDED,eval-conflicts-rho020-r1-015-kwk7h.18d467a349670e4f,reason=Created count=1 msg=Created container: task
0.4804,Event,ADDED,eval-conflicts-rho020-r1-015-kwk7h.18d467a34b60d84f,reason=Started count=1 msg=Started container task
0.4806,Event,ADDED,eval-conflicts-rho020-r1-015.18d467a0fd37c38b,reason=SuccessfulCreate count=1 msg=Created pod: eval-conflicts-rho020-r1-015-kwk7h
0.4808,Event,ADDED,eval-conflicts-rho020-r1-015.18d467a61ea445a2,reason=Completed count=1 msg=Job completed
0.4809,Event,ADDED,eval-conflicts-rho020-r1-016-d2nc6.18d467a13a11a2e5,reason=Scheduled count=None msg=Successfully assigned compute/eval-conflicts-rho020-r1-016-d2nc6 to kind-worker5
0.4811,Event,ADDED,eval-conflicts-rho020-r1-016-d2nc6.18d467a156c95fa6,"reason=Pulled count=1 msg=Container image ""busybox:musl"" already present on machine"
0.4812,Event,ADDED,eval-conflicts-rho020-r1-016-d2nc6.18d467a1582bdae7,reason=Created count=1 msg=Created container: task
0.4814,Event,ADDED,eval-conflicts-rho020-r1-016-d2nc6.18d467a15ba933d0,reason=Started count=1 msg=Started container task
0.4816,Event,ADDED,eval-conflicts-rho020-r1-016.18d467a138d7f265,reason=SuccessfulCreate count=1 msg=Created pod: eval-conflicts-rho020-r1-016-d2nc6
0.4817,Event,ADDED,eval-conflicts-rho020-r1-016.18d467a47eba5d44,reason=Completed count=1 msg=Job completed
0.4819,Event,ADDED,eval-conflicts-rho020-r1-017-6dh4z.18d467a17afa2a11,reason=Scheduled count=None msg=Successfully assigned compute/eval-conflicts-rho020-r1-017-6dh4z to kind-worker2
0.482,Event,ADDED,eval-conflicts-rho020-r1-017-6dh4z.18d467a194a837a9,"reason=Pulled count=1 msg=Container image ""busybox:musl"" already present on machine"
0.4853,Event,ADDED,eval-conflicts-rho020-r1-017-6dh4z.18d467a19663a043,reason=Created count=1 msg=Created container: task
0.4856,Event,ADDED,eval-conflicts-rho020-r1-017-6dh4z.18d467a19ab1bc67,reason=Started count=1 msg=Started container task
0.4858,Event,ADDED,eval-conflicts-rho020-r1-017.18d467a17524f366,reason=SuccessfulCreate count=1 msg=Created pod: eval-conflicts-rho020-r1-017-6dh4z
0.486,Event,ADDED,eval-conflicts-rho020-r1-017.18d467a4aae83f15,reason=Completed count=1 msg=Job completed
0.4861,Event,ADDED,eval-conflicts-rho020-r1-018-mvzjx.18d467a1b0f61f1f,reason=Scheduled count=None msg=Successfully assigned compute/eval-conflicts-rho020-r1-018-mvzjx to kind-worker5
0.4865,Event,ADDED,eval-conflicts-rho020-r1-018-mvzjx.18d467a1cdce51d8,"reason=Pulled count=1 msg=Container image ""busybox:musl"" already present on machine"
0.4866,Event,ADDED,eval-conflicts-rho020-r1-018-mvzjx.18d467a1cf1b6dfc,reason=Created count=1 msg=Created container: task
0.4868,Event,ADDED,eval-conflicts-rho020-r1-018-mvzjx.18d467a1d4fec5a8,reason=Started count=1 msg=Started container task
0.4872,Event,ADDED,eval-conflicts-rho020-r1-018.18d467a1b03ef420,reason=SuccessfulCreate count=1 msg=Created pod: eval-conflicts-rho020-r1-018-mvzjx
0.4873,Event,ADDED,eval-conflicts-rho020-r1-018.18d467a4b73241ba,reason=Completed count=1 msg=Job completed
0.4875,Event,ADDED,eval-conflicts-rho020-r1-019-bql7q.18d467a1ed5d35e4,reason=Scheduled count=None msg=Successfully assigned compute/eval-conflicts-rho020-r1-019-bql7q to kind-worker5
0.4877,Event,ADDED,eval-conflicts-rho020-r1-019-bql7q.18d467a207e7f05d,"reason=Pulled count=1 msg=Container image ""busybox:musl"" already present on machine"
0.488,Event,ADDED,eval-conflicts-rho020-r1-019-bql7q.18d467a20903b2e1,reason=Created count=1 msg=Created container: task
0.4882,Event,ADDED,eval-conflicts-rho020-r1-019-bql7q.18d467a211a00713,reason=Started count=1 msg=Started container task
0.4883,Event,ADDED,eval-conflicts-rho020-r1-019.18d467a1ec821a3d,reason=SuccessfulCreate count=1 msg=Created pod: eval-conflicts-rho020-r1-019-bql7q
0.4885,Event,ADDED,eval-conflicts-rho020-r1-019.18d467a4f4563862,reason=Completed count=1 msg=Job completed
0.4887,Event,ADDED,eval-conflicts-rho020-r1-020-6rw8j.18d467a229bf16ed,reason=Scheduled count=None msg=Successfully assigned compute/eval-conflicts-rho020-r1-020-6rw8j to kind-worker5
0.4888,Event,ADDED,eval-conflicts-rho020-r1-020-6rw8j.18d467a24403b89a,"reason=Pulled count=1 msg=Container image ""busybox:musl"" already present on machine"
0.489,Event,ADDED,eval-conflicts-rho020-r1-020-6rw8j.18d467a245130e20,reason=Created count=1 msg=Created container: task
0.4892,Event,ADDED,eval-conflicts-rho020-r1-020-6rw8j.18d467a24cb4c37f,reason=Started count=1 msg=Started container task
0.4894,Event,ADDED,eval-conflicts-rho020-r1-020.18d467a22900ab3b,reason=SuccessfulCreate count=1 msg=Created pod: eval-conflicts-rho020-r1-020-6rw8j
0.4896,Event,ADDED,eval-conflicts-rho020-r1-020.18d467a56bc89956,reason=Completed count=1 msg=Job completed
0.4897,Event,ADDED,eval-conflicts-rho020-r1-021-f9vs7.18d467a263d9b80f,reason=Scheduled count=None msg=Successfully assigned compute/eval-conflicts-rho020-r1-021-f9vs7 to kind-worker2
0.4899,Event,ADDED,eval-conflicts-rho020-r1-021-f9vs7.18d467a27e2cbc89,"reason=Pulled count=1 msg=Container image ""busybox:musl"" already present on machine"
0.4901,Event,ADDED,eval-conflicts-rho020-r1-021-f9vs7.18d467a27f422be4,reason=Created count=1 msg=Created container: task
0.4902,Event,ADDED,eval-conflicts-rho020-r1-021-f9vs7.18d467a28506fa76,reason=Started count=1 msg=Started container task
0.4904,Event,ADDED,eval-conflicts-rho020-r1-021.18d467a263455ee3,reason=SuccessfulCreate count=1 msg=Created pod: eval-conflicts-rho020-r1-021-f9vs7
0.4906,Event,ADDED,eval-conflicts-rho020-r1-021.18d467a59fbf6321,reason=Completed count=1 msg=Job completed
0.4907,Event,ADDED,eval-conflicts-rho020-r1-022-6s9xx.18d467a29fb904de,reason=Scheduled count=None msg=Successfully assigned compute/eval-conflicts-rho020-r1-022-6s9xx to kind-worker2
0.4909,Event,ADDED,eval-conflicts-rho020-r1-022-6s9xx.18d467a2bbfedfca,"reason=Pulled count=1 msg=Container image ""busybox:musl"" already present on machine"
0.4911,Event,ADDED,eval-conflicts-rho020-r1-022-6s9xx.18d467a2bd214818,reason=Created count=1 msg=Created container: task
0.4913,Event,ADDED,eval-conflicts-rho020-r1-022-6s9xx.18d467a2c7ae7e71,reason=Started count=1 msg=Started container task
0.4914,Event,ADDED,eval-conflicts-rho020-r1-022.18d467a29ed925c3,reason=SuccessfulCreate count=1 msg=Created pod: eval-conflicts-rho020-r1-022-6s9xx
0.4917,Event,ADDED,eval-conflicts-rho020-r1-022.18d467a5d4b48bba,reason=Completed count=1 msg=Job completed
0.492,Event,ADDED,eval-conflicts-rho020-r1-023-2dxvz.18d467a2db1cb942,"reason=FailedScheduling count=None msg=0/6 nodes are available: 2 c_wall violated: 1 conflicting context pair(s) with node memory, 4 node(s) had untolerated taint(s). no new claims to deallocate, preemption: 0/6 nodes are available: 2 No preemption victims found for incoming pod, 4 Preemption is not helpful for scheduling."
0.4922,Event,ADDED,eval-conflicts-rho020-r1-023-2dxvz.18d467a2dbc8940c,"reason=FailedScheduling count=None msg=0/6 nodes are available: 2 c_wall violated: 1 conflicting context pair(s) with node memory, 4 node(s) had untolerated taint(s). no new claims to deallocate, preemption: 0/6 nodes are available: 2 No preemption victims found for incoming pod, 4 Preemption is not helpful for scheduling."
0.4923,Event,ADDED,eval-conflicts-rho020-r1-023-2dxvz.18d467a332fc8c6b,reason=Scheduled count=None msg=Successfully assigned compute/eval-conflicts-rho020-r1-023-2dxvz to kind-worker
0.4926,Event,ADDED,eval-conflicts-rho020-r1-023-2dxvz.18d467a34a9523b2,"reason=Pulled count=1 msg=Container image ""busybox:musl"" already present on machine"
0.4928,Event,ADDED,eval-conflicts-rho020-r1-023-2dxvz.18d467a34bbb25af,reason=Created count=1 msg=Created container: task
0.493,Event,ADDED,eval-conflicts-rho020-r1-023-2dxvz.18d467a3509e6c0e,reason=Started count=1 msg=Started container task
0.4932,Event,ADDED,eval-conflicts-rho020-r1-023.18d467a2daa577b1,reason=SuccessfulCreate count=1 msg=Created pod: eval-conflicts-rho020-r1-023-2dxvz
0.4934,Event,ADDED,eval-conflicts-rho020-r1-023.18d467a65acc42c9,reason=Completed count=1 msg=Job completed
0.4935,Event,ADDED,eval-conflicts-rho020-r1-024-vvxmp.18d467a3171e17c4,reason=Scheduled count=None msg=Successfully assigned compute/eval-conflicts-rho020-r1-024-vvxmp to kind-worker2
0.4937,Event,ADDED,eval-conflicts-rho020-r1-024-vvxmp.18d467a33284dc62,"reason=Pulled count=1 msg=Container image ""busybox:musl"" already present on machine"
0.4939,Event,ADDED,eval-conflicts-rho020-r1-024-vvxmp.18d467a333ccb70e,reason=Created count=1 msg=Created container: task
0.494,Event,ADDED,eval-conflicts-rho020-r1-024-vvxmp.18d467a33791b9ff,reason=Started count=1 msg=Started container task
0.4942,Event,ADDED,eval-conflicts-rho020-r1-024.18d467a31629d7fc,reason=SuccessfulCreate count=1 msg=Created pod: eval-conflicts-rho020-r1-024-vvxmp
0.4944,Event,ADDED,eval-conflicts-rho020-r1-024.18d467a64c9272ea,reason=Completed count=1 msg=Job completed
0.4945,Event,ADDED,eval-conflicts-rho020-r1-025-9g9q7.18d467a3525f0dec,reason=Scheduled count=None msg=Successfully assigned compute/eval-conflicts-rho020-r1-025-9g9q7 to kind-worker
0.4947,Event,ADDED,eval-conflicts-rho020-r1-025-9g9q7.18d467a370fd9432,"reason=Pulled count=1 msg=Container image ""busybox:musl"" already present on machine"
0.4949,Event,ADDED,eval-conflicts-rho020-r1-025-9g9q7.18d467a372165eff,reason=Created count=1 msg=Created container: task
0.495,Event,ADDED,eval-conflicts-rho020-r1-025-9g9q7.18d467a378f45a09,reason=Started count=1 msg=Started container task
0.4952,Event,ADDED,eval-conflicts-rho020-r1-025.18d467a3516c2b04,reason=SuccessfulCreate count=1 msg=Created pod: eval-conflicts-rho020-r1-025-9g9q7
0.4954,Event,ADDED,eval-conflicts-rho020-r1-025.18d467a65a948e7c,reason=Completed count=1 msg=Job completed
0.4955,Event,ADDED,eval-conflicts-rho020-r1-026-dr2t9.18d467a38d81577e,reason=Scheduled count=None msg=Successfully assigned compute/eval-conflicts-rho020-r1-026-dr2t9 to kind-worker4
0.4958,Event,ADDED,eval-conflicts-rho020-r1-026-dr2t9.18d467a3ab37a0e7,"reason=Pulled count=1 msg=Container image ""busybox:musl"" already present on machine"
0.4959,Event,ADDED,eval-conflicts-rho020-r1-026-dr2t9.18d467a3ac617482,reason=Created count=1 msg=Created container: task
0.4961,Event,ADDED,eval-conflicts-rho020-r1-026-dr2t9.18d467a3b6fb74ac,reason=Started count=1 msg=Started container task
0.4963,Event,ADDED,eval-conflicts-rho020-r1-026.18d467a38cc83749,reason=SuccessfulCreate count=1 msg=Created pod: eval-conflicts-rho020-r1-026-dr2t9
0.4966,Event,ADDED,eval-conflicts-rho020-r1-026.18d467a6d7b0017a,reason=Completed count=1 msg=Job completed
0.4967,Event,ADDED,eval-conflicts-rho020-r1-027-4ln55.18d467a3ccdf2a8a,reason=Scheduled count=None msg=Successfully assigned compute/eval-conflicts-rho020-r1-027-4ln55 to kind-worker
0.497,Event,ADDED,eval-conflicts-rho020-r1-027-4ln55.18d467a3e7c0c1ef,"reason=Pulled count=1 msg=Container image ""busybox:musl"" already present on machine"
0.4972,Event,ADDED,eval-conflicts-rho020-r1-027-4ln55.18d467a3e8d8e532,reason=Created count=1 msg=Created container: task
0.4974,Event,ADDED,eval-conflicts-rho020-r1-027-4ln55.18d467a3ee94b5be,reason=Started count=1 msg=Started container task
0.4977,Event,ADDED,eval-conflicts-rho020-r1-027.18d467a3cc2072f1,reason=SuccessfulCreate count=1 msg=Created pod: eval-conflicts-rho020-r1-027-4ln55
0.4978,Event,ADDED,eval-conflicts-rho020-r1-027.18d467a70cabe4e3,reason=Completed count=1 msg=Job completed
0.498,Event,ADDED,eval-conflicts-rho020-r1-028-5n7vn.18d467a4055ba333,reason=Scheduled count=None msg=Successfully assigned compute/eval-conflicts-rho020-r1-028-5n7vn to kind-worker4
0.4982,Event,ADDED,eval-conflicts-rho020-r1-028-5n7vn.18d467a41f4ce301,"reason=Pulled count=1 msg=Container image ""busybox:musl"" already present on machine"
0.4985,Event,ADDED,eval-conflicts-rho020-r1-028-5n7vn.18d467a420579c46,reason=Created count=1 msg=Created container: task
0.4987,Event,ADDED,eval-conflicts-rho020-r1-028-5n7vn.18d467a4222a0a7a,reason=Started count=1 msg=Started container task
0.4988,Event,ADDED,eval-conflicts-rho020-r1-028.18d467a4048ef26b,reason=SuccessfulCreate count=1 msg=Created pod: eval-conflicts-rho020-r1-028-5n7vn
0.4992,Event,ADDED,eval-conflicts-rho020-r1-028.18d467a7518a3d08,reason=Completed count=1 msg=Job completed
0.4993,Event,ADDED,eval-conflicts-rho020-r1-029-5qdnz.18d467a440b6c931,reason=Scheduled count=None msg=Successfully assigned compute/eval-conflicts-rho020-r1-029-5qdnz to kind-worker
0.4995,Event,ADDED,eval-conflicts-rho020-r1-029-5qdnz.18d467a459949b3c,"reason=Pulled count=1 msg=Container image ""busybox:musl"" already present on machine"
0.4998,Event,ADDED,eval-conflicts-rho020-r1-029-5qdnz.18d467a45aa962a8,reason=Created count=1 msg=Created container: task
0.5001,Event,ADDED,eval-conflicts-rho020-r1-029-5qdnz.18d467a45ef3dbc2,reason=Started count=1 msg=Started container task
0.5002,Event,ADDED,eval-conflicts-rho020-r1-029.18d467a43fb6e438,reason=SuccessfulCreate count=1 msg=Created pod: eval-conflicts-rho020-r1-029-5qdnz
0.5004,Event,ADDED,eval-conflicts-rho020-r1-029.18d467a746185993,reason=Completed count=1 msg=Job completed
0.5006,Event,ADDED,eval-conflicts-rho020-r1-030-fbkpq.18d467a47ca1f173,reason=Scheduled count=None msg=Successfully assigned compute/eval-conflicts-rho020-r1-030-fbkpq to kind-worker4
0.5008,Event,ADDED,eval-conflicts-rho020-r1-030-fbkpq.18d467a4982cfc06,"reason=Pulled count=1 msg=Container image ""busybox:musl"" already present on machine"
0.501,Event,ADDED,eval-conflicts-rho020-r1-030-fbkpq.18d467a4994644cf,reason=Created count=1 msg=Created container: task
0.5011,Event,ADDED,eval-conflicts-rho020-r1-030-fbkpq.18d467a49dd8be9d,reason=Started count=1 msg=Started container task
0.5014,Event,ADDED,eval-conflicts-rho020-r1-030.18d467a47bc70904,reason=SuccessfulCreate count=1 msg=Created pod: eval-conflicts-rho020-r1-030-fbkpq
0.5016,Event,ADDED,eval-conflicts-rho020-r1-030.18d467a7c870d957,reason=Completed count=1 msg=Job completed
0.5018,Event,ADDED,eval-conflicts-rho020-r1-031-gfbx9.18d467a4b8aceda5,reason=Scheduled count=None msg=Successfully assigned compute/eval-conflicts-rho020-r1-031-gfbx9 to kind-worker
0.502,Event,ADDED,eval-conflicts-rho020-r1-031-gfbx9.18d467a4d2f8088e,"reason=Pulled count=1 msg=Container image ""busybox:musl"" already present on machine"
0.5022,Event,ADDED,eval-conflicts-rho020-r1-031-gfbx9.18d467a4d403eb64,reason=Created count=1 msg=Created container: task
0.5024,Event,ADDED,eval-conflicts-rho020-r1-031-gfbx9.18d467a4d83b4ea3,reason=Started count=1 msg=Started container task
0.5026,Event,ADDED,eval-conflicts-rho020-r1-031.18d467a4b7ce21a7,reason=SuccessfulCreate count=1 msg=Created pod: eval-conflicts-rho020-r1-031-gfbx9
0.5028,Event,ADDED,eval-conflicts-rho020-r1-031.18d467a7bd8c4365,reason=Completed count=1 msg=Job completed
0.503,Event,ADDED,eval-conflicts-rho020-r1-032-n8mnk.18d467a4f6236958,reason=Scheduled count=None msg=Successfully assigned compute/eval-conflicts-rho020-r1-032-n8mnk to kind-worker4
0.5032,Event,ADDED,eval-conflicts-rho020-r1-032-n8mnk.18d467a50e66af4a,"reason=Pulled count=1 msg=Container image ""busybox:musl"" already present on machine"
0.5034,Event,ADDED,eval-conflicts-rho020-r1-032-n8mnk.18d467a50f7f9690,reason=Created count=1 msg=Created container: task
0.5037,Event,ADDED,eval-conflicts-rho020-r1-032-n8mnk.18d467a5145728ca,reason=Started count=1 msg=Started container task
0.5039,Event,ADDED,eval-conflicts-rho020-r1-032.18d467a4f50708c3,reason=SuccessfulCreate count=1 msg=Created pod: eval-conflicts-rho020-r1-032-n8mnk
0.5041,Event,ADDED,eval-conflicts-rho020-r1-032.18d467a84049d099,reason=Completed count=1 msg=Job completed
0.5043,Event,ADDED,eval-conflicts-rho020-r1-033-xdpvh.18d467a52f3f1e05,reason=Scheduled count=None msg=Successfully assigned compute/eval-conflicts-rho020-r1-033-xdpvh to kind-worker3
0.5046,Event,ADDED,eval-conflicts-rho020-r1-033-xdpvh.18d467a54c12a6b0,"reason=Pulled count=1 msg=Container image ""busybox:musl"" already present on machine"
0.5048,Event,ADDED,eval-conflicts-rho020-r1-033-xdpvh.18d467a54d3f2692,reason=Created count=1 msg=Created container: task
0.505,Event,ADDED,eval-conflicts-rho020-r1-033-xdpvh.18d467a55213d7a9,reason=Started count=1 msg=Started container task
0.5055,Event,ADDED,eval-conflicts-rho020-r1-033.18d467a52e5e7df0,reason=SuccessfulCreate count=1 msg=Created pod: eval-conflicts-rho020-r1-033-xdpvh
0.5057,Event,ADDED,eval-conflicts-rho020-r1-033.18d467a888635991,reason=Completed count=1 msg=Job completed
0.5058,Event,ADDED,eval-conflicts-rho020-r1-034-kjgm2.18d467a56a82805d,"reason=FailedScheduling count=None msg=0/6 nodes are available: 1 c_wall violated: 2 conflicting context pair(s) with node memory, 2 c_wall violated: 1 conflicting context pair(s) with node memory, 3 node(s) had untolerated taint(s). no new claims to deallocate, preemption: 0/6 nodes are available: 3 No preemption victims found for incoming pod, 3 Preemption is not helpful for scheduling."
0.5062,Event,ADDED,eval-conflicts-rho020-r1-034-kjgm2.18d467a56fc75cd3,"reason=FailedScheduling count=None msg=0/6 nodes are available: 1 c_wall violated: 2 conflicting context pair(s) with node memory, 2 c_wall violated: 1 conflicting context pair(s) with node memory, 3 node(s) had untolerated taint(s). no new claims to deallocate, preemption: 0/6 nodes are available: 3 No preemption victims found for incoming pod, 3 Preemption is not helpful for scheduling."
0.5065,Event,ADDED,eval-conflicts-rho020-r1-034-kjgm2.18d467a581797ccb,"reason=FailedScheduling count=None msg=0/6 nodes are available: 2 c_wall violated: 1 conflicting context pair(s) with node memory, 4 node(s) had untolerated taint(s). no new claims to deallocate, preemption: 0/6 nodes are available: 2 No preemption victims found for incoming pod, 4 Preemption is not helpful for scheduling."
0.5067,Event,ADDED,eval-conflicts-rho020-r1-034-kjgm2.18d467a5b6cdefe9,"reason=FailedScheduling count=None msg=0/6 nodes are available: 1 c_wall violated: 1 conflicting context pair(s) with node memory, 5 node(s) had untolerated taint(s). no new claims to deallocate, preemption: 0/6 nodes are available: 1 No preemption victims found for incoming pod, 5 Preemption is not helpful for scheduling."
0.5073,Event,ADDED,eval-conflicts-rho020-r1-034-kjgm2.18d467a5cb7f8095,reason=Scheduled count=None msg=Successfully assigned compute/eval-conflicts-rho020-r1-034-kjgm2 to kind-worker5
0.5075,Event,ADDED,eval-conflicts-rho020-r1-034-kjgm2.18d467a5e7724c79,"reason=Pulled count=1 msg=Container image ""busybox:musl"" already present on machine"
0.5077,Event,ADDED,eval-conflicts-rho020-r1-034-kjgm2.18d467a5e8ae43f6,reason=Created count=1 msg=Created container: task
0.5079,Event,ADDED,eval-conflicts-rho020-r1-034-kjgm2.18d467a5eda0f150,reason=Started count=1 msg=Started container task
0.5082,Event,ADDED,eval-conflicts-rho020-r1-034.18d467a569c9dd32,reason=SuccessfulCreate count=1 msg=Created pod: eval-conflicts-rho020-r1-034-kjgm2
0.5084,Event,ADDED,eval-conflicts-rho020-r1-034.18d467a9264152cc,reason=Completed count=1 msg=Job completed
0.5086,Event,ADDED,eval-conflicts-rho020-r1-035-2q557.18d467a5a6f06ce9,reason=Scheduled count=None msg=Successfully assigned compute/eval-conflicts-rho020-r1-035-2q557 to kind-worker3
0.5088,Event,ADDED,eval-conflicts-rho020-r1-035-2q557.18d467a5c0594e57,"reason=Pulled count=1 msg=Container image ""busybox:musl"" already present on machine"
0.5091,Event,ADDED,eval-conflicts-rho020-r1-035-2q557.18d467a5c17dcf7f,reason=Created count=1 msg=Created container: task
0.5093,Event,ADDED,eval-conflicts-rho020-r1-035-2q557.18d467a5c3792f56,reason=Started count=1 msg=Started container task
0.5095,Event,ADDED,eval-conflicts-rho020-r1-035.18d467a5a6144c9d,reason=SuccessfulCreate count=1 msg=Created pod: eval-conflicts-rho020-r1-035-2q557
0.5098,Event,ADDED,eval-conflicts-rho020-r1-035.18d467a9004e371f,reason=Completed count=1 msg=Job completed
0.5099,Event,ADDED,eval-conflicts-rho020-r1-036-xbmbp.18d467a5e36096e2,reason=Scheduled count=None msg=Successfully assigned compute/eval-conflicts-rho020-r1-036-xbmbp to kind-worker5
0.5101,Event,ADDED,eval-conflicts-rho020-r1-036-xbmbp.18d467a5fcc59d18,"reason=Pulled count=1 msg=Container image ""busybox:musl"" already present on machine"
0.5103,Event,ADDED,eval-conflicts-rho020-r1-036-xbmbp.18d467a5fde3d339,reason=Created count=1 msg=Created container: task
0.5105,Event,ADDED,eval-conflicts-rho020-r1-036-xbmbp.18d467a5ffecdd18,reason=Started count=1 msg=Started container task
0.5107,Event,ADDED,eval-conflicts-rho020-r1-036.18d467a5e2c15329,reason=SuccessfulCreate count=1 msg=Created pod: eval-conflicts-rho020-r1-036-xbmbp
0.5109,Event,ADDED,eval-conflicts-rho020-r1-036.18d467a8eb9b7e1a,reason=Completed count=1 msg=Job completed
0.511,Event,ADDED,eval-conflicts-rho020-r1-037-xmtzx.18d467a620597e19,reason=Scheduled count=None msg=Successfully assigned compute/eval-conflicts-rho020-r1-037-xmtzx to kind-worker5
0.5112,Event,ADDED,eval-conflicts-rho020-r1-037-xmtzx.18d467a6398276ef,"reason=Pulled count=1 msg=Container image ""busybox:musl"" already present on machine"
0.5113,Event,ADDED,eval-conflicts-rho020-r1-037-xmtzx.18d467a63aaae1cd,reason=Created count=1 msg=Created container: task
0.5115,Event,ADDED,eval-conflicts-rho020-r1-037-xmtzx.18d467a6401b91ee,reason=Started count=1 msg=Started container task
0.5117,Event,ADDED,eval-conflicts-rho020-r1-037.18d467a61f66e3e2,reason=SuccessfulCreate count=1 msg=Created pod: eval-conflicts-rho020-r1-037-xmtzx
0.5119,Event,ADDED,eval-conflicts-rho020-r1-037.18d467a927046479,reason=Completed count=1 msg=Job completed
0.512,Event,ADDED,eval-conflicts-rho020-r1-038-x949z.18d467a65b7a5546,reason=Scheduled count=None msg=Successfully assigned compute/eval-conflicts-rho020-r1-038-x949z to kind-worker5
0.5122,Event,ADDED,eval-conflicts-rho020-r1-038-x949z.18d467a674ee4f8c,"reason=Pulled count=1 msg=Container image ""busybox:musl"" already present on machine"
0.5125,Event,ADDED,eval-conflicts-rho020-r1-038-x949z.18d467a67606c490,reason=Created count=1 msg=Created container: task
0.5128,Event,ADDED,eval-conflicts-rho020-r1-038-x949z.18d467a67d4d57ca,reason=Started count=1 msg=Started container task
0.5129,Event,ADDED,eval-conflicts-rho020-r1-038.18d467a65a6d0c9a,reason=SuccessfulCreate count=1 msg=Created pod: eval-conflicts-rho020-r1-038-x949z
0.5133,Event,ADDED,eval-conflicts-rho020-r1-038.18d467a962f66bab,reason=Completed count=1 msg=Job completed
0.5135,Event,ADDED,eval-conflicts-rho020-r1-039-qxgcc.18d467a69728c262,reason=Scheduled count=None msg=Successfully assigned compute/eval-conflicts-rho020-r1-039-qxgcc to kind-worker5
0.5137,Event,ADDED,eval-conflicts-rho020-r1-039-qxgcc.18d467a6b041166d,"reason=Pulled count=1 msg=Container image ""busybox:musl"" already present on machine"
0.5138,Event,ADDED,eval-conflicts-rho020-r1-039-qxgcc.18d467a6b16b04db,reason=Created count=1 msg=Created container: task
0.5142,Event,ADDED,eval-conflicts-rho020-r1-039-qxgcc.18d467a6ba0b0c23,reason=Started count=1 msg=Started container task
0.5144,Event,ADDED,eval-conflicts-rho020-r1-039.18d467a69626c913,reason=SuccessfulCreate count=1 msg=Created pod: eval-conflicts-rho020-r1-039-qxgcc
0.5146,Event,ADDED,eval-conflicts-rho020-r1-039.18d467a99e9d127c,reason=Completed count=1 msg=Job completed
0.5147,Event,ADDED,eval-conflicts-rho020-r1-040-d2zcv.18d467a6d0358e52,reason=Scheduled count=None msg=Successfully assigned compute/eval-conflicts-rho020-r1-040-d2zcv to kind-worker5
0.5151,Event,ADDED,eval-conflicts-rho020-r1-040-d2zcv.18d467a6e88265e8,"reason=Pulled count=1 msg=Container image ""busybox:musl"" already present on machine"
0.5153,Event,ADDED,eval-conflicts-rho020-r1-040-d2zcv.18d467a6e998fac2,reason=Created count=1 msg=Created container: task
0.5157,Event,ADDED,eval-conflicts-rho020-r1-040-d2zcv.18d467a6eb89ac8c,reason=Started count=1 msg=Started container task
0.516,Event,ADDED,eval-conflicts-rho020-r1-040.18d467a6cf5392d2,reason=SuccessfulCreate count=1 msg=Created pod: eval-conflicts-rho020-r1-040-d2zcv
0.5161,Event,ADDED,eval-conflicts-rho020-r1-040.18d467aa16059ed5,reason=Completed count=1 msg=Job completed
0.5163,Event,ADDED,eval-conflicts-rho020-r1-041-swtwk.18d467a70beeabce,reason=Scheduled count=None msg=Successfully assigned compute/eval-conflicts-rho020-r1-041-swtwk to kind-worker3
0.5165,Event,ADDED,eval-conflicts-rho020-r1-041-swtwk.18d467a725fe979d,"reason=Pulled count=1 msg=Container image ""busybox:musl"" already present on machine"
0.5168,Event,ADDED,eval-conflicts-rho020-r1-041-swtwk.18d467a727028feb,reason=Created count=1 msg=Created container: task
0.5169,Event,ADDED,eval-conflicts-rho020-r1-041-swtwk.18d467a728e26311,reason=Started count=1 msg=Started container task
0.5171,Event,ADDED,eval-conflicts-rho020-r1-041.18d467a70b4ef7ac,reason=SuccessfulCreate count=1 msg=Created pod: eval-conflicts-rho020-r1-041-swtwk
0.5173,Event,ADDED,eval-conflicts-rho020-r1-041.18d467aa64d16298,reason=Completed count=1 msg=Job completed
0.5176,Event,ADDED,eval-conflicts-rho020-r1-042-tl9g2.18d467a747816e6e,reason=Scheduled count=None msg=Successfully assigned compute/eval-conflicts-rho020-r1-042-tl9g2 to kind-worker5
0.5178,Event,ADDED,eval-conflicts-rho020-r1-042-tl9g2.18d467a764284793,"reason=Pulled count=1 msg=Container image ""busybox:musl"" already present on machine"
0.5179,Event,ADDED,eval-conflicts-rho020-r1-042-tl9g2.18d467a766b35580,reason=Created count=1 msg=Created container: task
0.5182,Event,ADDED,eval-conflicts-rho020-r1-042-tl9g2.18d467a76fb5db42,reason=Started count=1 msg=Started container task
0.5184,Event,ADDED,eval-conflicts-rho020-r1-042.18d467a746a7635d,reason=SuccessfulCreate count=1 msg=Created pod: eval-conflicts-rho020-r1-042-tl9g2
0.5186,Event,ADDED,eval-conflicts-rho020-r1-042.18d467aa8d95f4f9,reason=Completed count=1 msg=Job completed
0.5188,Event,ADDED,eval-conflicts-rho020-r1-043-lmg9t.18d467a7837d1276,reason=Scheduled count=None msg=Successfully assigned compute/eval-conflicts-rho020-r1-043-lmg9t to kind-worker3
0.519,Event,ADDED,eval-conflicts-rho020-r1-043-lmg9t.18d467a79f83810a,"reason=Pulled count=1 msg=Container image ""busybox:musl"" already present on machine"
0.5192,Event,ADDED,eval-conflicts-rho020-r1-043-lmg9t.18d467a7a0957c9e,reason=Created count=1 msg=Created container: task
0.5193,Event,ADDED,eval-conflicts-rho020-r1-043-lmg9t.18d467a7a5cd9afe,reason=Started count=1 msg=Started container task
0.5196,Event,ADDED,eval-conflicts-rho020-r1-043.18d467a782ac80a7,reason=SuccessfulCreate count=1 msg=Created pod: eval-conflicts-rho020-r1-043-lmg9t
0.5198,Event,ADDED,eval-conflicts-rho020-r1-043.18d467aadca3e332,reason=Completed count=1 msg=Job completed
0.5199,Event,ADDED,eval-conflicts-rho020-r1-044-2m5jb.18d467a7be75db86,"reason=FailedScheduling count=None msg=0/6 nodes are available: 1 c_wall violated: 1 conflicting context pair(s) with node memory, 5 node(s) had untolerated taint(s). no new claims to deallocate, preemption: 0/6 nodes are available: 1 No preemption victims found for incoming pod, 5 Preemption is not helpful for scheduling."
0.5201,Event,ADDED,eval-conflicts-rho020-r1-044-2m5jb.18d467a7bf1b2c8e,"reason=FailedScheduling count=None msg=0/6 nodes are available: 1 c_wall violated: 1 conflicting context pair(s) with node memory, 5 node(s) had untolerated taint(s). no new claims to deallocate, preemption: 0/6 nodes are available: 1 No preemption victims found for incoming pod, 5 Preemption is not helpful for scheduling."
0.5205,Event,ADDED,eval-conflicts-rho020-r1-044-2m5jb.18d467a7db9f990a,reason=Scheduled count=None msg=Successfully assigned compute/eval-conflicts-rho020-r1-044-2m5jb to kind-worker
0.5207,Event,ADDED,eval-conflicts-rho020-r1-044-2m5jb.18d467a7f58596df,"reason=Pulled count=1 msg=Container image ""busybox:musl"" already present on machine"
0.5209,Event,ADDED,eval-conflicts-rho020-r1-044-2m5jb.18d467a7f694c146,reason=Created count=1 msg=Created container: task
0.5212,Event,ADDED,eval-conflicts-rho020-r1-044-2m5jb.18d467a7f8814986,reason=Started count=1 msg=Started container task
0.5215,Event,ADDED,eval-conflicts-rho020-r1-044.18d467a7be2d7eae,reason=SuccessfulCreate count=1 msg=Created pod: eval-conflicts-rho020-r1-044-2m5jb
0.5217,Event,ADDED,eval-conflicts-rho020-r1-044.18d467ab0264dc08,reason=Completed count=1 msg=Job completed
0.5219,Event,ADDED,eval-conflicts-rho020-r1-045-6fz5d.18d467a7fa22d0f1,reason=Scheduled count=None msg=Successfully assigned compute/eval-conflicts-rho020-r1-045-6fz5d to kind-worker
0.5221,Event,ADDED,eval-conflicts-rho020-r1-045-6fz5d.18d467a81690a33f,"reason=Pulled count=1 msg=Container image ""busybox:musl"" already present on machine"
0.5223,Event,ADDED,eval-conflicts-rho020-r1-045-6fz5d.18d467a817cd839c,reason=Created count=1 msg=Created container: task
0.5225,Event,ADDED,eval-conflicts-rho020-r1-045-6fz5d.18d467a81efa7241,reason=Started count=1 msg=Started container task
0.5228,Event,ADDED,eval-conflicts-rho020-r1-045.18d467a7f946c1f9,reason=SuccessfulCreate count=1 msg=Created pod: eval-conflicts-rho020-r1-045-6fz5d
0.523,Event,ADDED,eval-conflicts-rho020-r1-045.18d467ab03112d02,reason=Completed count=1 msg=Job completed
0.5231,Event,ADDED,eval-conflicts-rho020-r1-046-52lj5.18d467a83627c22e,reason=Scheduled count=None msg=Successfully assigned compute/eval-conflicts-rho020-r1-046-52lj5 to kind-worker2
0.5233,Event,ADDED,eval-conflicts-rho020-r1-046-52lj5.18d467a851ce7b8f,"reason=Pulled count=1 msg=Container image ""busybox:musl"" already present on machine"
0.5237,Event,ADDED,eval-conflicts-rho020-r1-046-52lj5.18d467a852e906f9,reason=Created count=1 msg=Created container: task
0.5239,Event,ADDED,eval-conflicts-rho020-r1-046-52lj5.18d467a8558c2b9c,reason=Started count=1 msg=Started container task
0.5241,Event,ADDED,eval-conflicts-rho020-r1-046.18d467a83569ba1f,reason=SuccessfulCreate count=1 msg=Created pod: eval-conflicts-rho020-r1-046-52lj5
0.5242,Event,ADDED,eval-conflicts-rho020-r1-046.18d467ab6dee18e8,reason=Completed count=1 msg=Job completed
0.5246,Event,ADDED,eval-conflicts-rho020-r1-047-62dvq.18d467a871bf3ea7,reason=Scheduled count=None msg=Successfully assigned compute/eval-conflicts-rho020-r1-047-62dvq to kind-worker2
0.5248,Event,ADDED,eval-conflicts-rho020-r1-047-62dvq.18d467a88b3000dc,"reason=Pulled count=1 msg=Container image ""busybox:musl"" already present on machine"
0.5249,Event,ADDED,eval-conflicts-rho020-r1-047-62dvq.18d467a88c59075d,reason=Created count=1 msg=Created container: task
0.5252,Event,ADDED,eval-conflicts-rho020-r1-047-62dvq.18d467a8908608c9,reason=Started count=1 msg=Started container task
0.5254,Event,ADDED,eval-conflicts-rho020-r1-047.18d467a870c593d0,reason=SuccessfulCreate count=1 msg=Created pod: eval-conflicts-rho020-r1-047-62dvq
0.5255,Event,ADDED,eval-conflicts-rho020-r1-047.18d467aba9de48dc,reason=Completed count=1 msg=Job completed
0.5257,Event,ADDED,eval-conflicts-rho020-r1-048-hf4qq.18d467a8ada3c7c2,reason=Scheduled count=None msg=Successfully assigned compute/eval-conflicts-rho020-r1-048-hf4qq to kind-worker2
0.5259,Event,ADDED,eval-conflicts-rho020-r1-048-hf4qq.18d467a8c6bc5191,"reason=Pulled count=1 msg=Container image ""busybox:musl"" already present on machine"
0.526,Event,ADDED,eval-conflicts-rho020-r1-048-hf4qq.18d467a8c7ca78b6,reason=Created count=1 msg=Created container: task
0.5262,Event,ADDED,eval-conflicts-rho020-r1-048-hf4qq.18d467a8cc226fae,reason=Started count=1 msg=Started container task
0.5264,Event,ADDED,eval-conflicts-rho020-r1-048.18d467a8ac7f8dbd,reason=SuccessfulCreate count=1 msg=Created pod: eval-conflicts-rho020-r1-048-hf4qq
0.5265,Event,ADDED,eval-conflicts-rho020-r1-048.18d467abe5ba54ee,reason=Completed count=1 msg=Job completed
0.5267,Event,ADDED,eval-conflicts-rho020-r1-049-74tp2.18d467a8e8da338b,reason=Scheduled count=None msg=Successfully assigned compute/eval-conflicts-rho020-r1-049-74tp2 to kind-worker
0.527,Event,ADDED,eval-conflicts-rho020-r1-049-74tp2.18d467a90234b04e,"reason=Pulled count=1 msg=Container image ""busybox:musl"" already present on machine"
0.5273,Event,ADDED,eval-conflicts-rho020-r1-049-74tp2.18d467a903623996,reason=Created count=1 msg=Created container: task
0.5274,Event,ADDED,eval-conflicts-rho020-r1-049-74tp2.18d467a90578454d,reason=Started count=1 msg=Started container task
0.5277,Event,ADDED,eval-conflicts-rho020-r1-049.18d467a8e7db6d2c,reason=SuccessfulCreate count=1 msg=Created pod: eval-conflicts-rho020-r1-049-74tp2
0.5279,Event,ADDED,eval-conflicts-rho020-r1-049.18d467ac2cd1e606,reason=Completed count=1 msg=Job completed
0.5283,Event,ADDED,eval-conflicts-rho020-r1-050-45dxr.18d467a924c62117,reason=Scheduled count=None msg=Successfully assigned compute/eval-conflicts-rho020-r1-050-45dxr to kind-worker4
0.5285,Event,ADDED,eval-conflicts-rho020-r1-050-45dxr.18d467a93daf8054,"reason=Pulled count=1 msg=Container image ""busybox:musl"" already present on machine"
0.5287,Event,ADDED,eval-conflicts-rho020-r1-050-45dxr.18d467a93f8fa395,reason=Created count=1 msg=Created container: task
0.5289,Event,ADDED,eval-conflicts-rho020-r1-050-45dxr.18d467a945a20216,reason=Started count=1 msg=Started container task
0.5291,Event,ADDED,eval-conflicts-rho020-r1-050.18d467a923eb606a,reason=SuccessfulCreate count=1 msg=Created pod: eval-conflicts-rho020-r1-050-45dxr
0.5292,Event,ADDED,eval-conflicts-rho020-r1-050.18d467ac703827e4,reason=Completed count=1 msg=Job completed
0.5294,Event,ADDED,eval-conflicts-rho020-r1-051-jsw2l.18d467a99cb421bc,reason=Scheduled count=None msg=Successfully assigned compute/eval-conflicts-rho020-r1-051-jsw2l to kind-worker
0.5296,Event,ADDED,eval-conflicts-rho020-r1-051-jsw2l.18d467a9b5c14865,"reason=Pulled count=1 msg=Container image ""busybox:musl"" already present on machine"
0.5297,Event,ADDED,eval-conflicts-rho020-r1-051-jsw2l.18d467a9b7055c61,reason=Created count=1 msg=Created container: task
0.5299,Event,ADDED,eval-conflicts-rho020-r1-051-jsw2l.18d467a9b9204641,reason=Started count=1 msg=Started container task
0.5301,Event,ADDED,eval-conflicts-rho020-r1-051.18d467a99b417c25,reason=SuccessfulCreate count=1 msg=Created pod: eval-conflicts-rho020-r1-051-jsw2l
0.5302,Event,ADDED,eval-conflicts-rho020-r1-051.18d467aca4edb3fd,reason=Completed count=1 msg=Job completed
0.5304,Event,ADDED,eval-conflicts-rho020-r1-052-x5kgn.18d467a9a103af48,reason=Scheduled count=None msg=Successfully assigned compute/eval-conflicts-rho020-r1-052-x5kgn to kind-worker
0.5305,Event,ADDED,eval-conflicts-rho020-r1-052-x5kgn.18d467a9b80f46c6,"reason=Pulled count=1 msg=Container image ""busybox:musl"" already present on machine"
0.5307,Event,ADDED,eval-conflicts-rho020-r1-052-x5kgn.18d467a9b94d1180,reason=Created count=1 msg=Created container: task
0.5309,Event,ADDED,eval-conflicts-rho020-r1-052-x5kgn.18d467a9bba29f1a,reason=Started count=1 msg=Started container task
0.531,Event,ADDED,eval-conflicts-rho020-r1-052.18d467a99d139647,reason=SuccessfulCreate count=1 msg=Created pod: eval-conflicts-rho020-r1-052-x5kgn
0.5312,Event,ADDED,eval-conflicts-rho020-r1-052.18d467ace02802b5,reason=Completed count=1 msg=Job completed
0.5314,Event,ADDED,eval-conflicts-rho020-r1-053-t9zxn.18d467a9d7487541,reason=Scheduled count=None msg=Successfully assigned compute/eval-conflicts-rho020-r1-053-t9zxn to kind-worker4
0.5317,Event,ADDED,eval-conflicts-rho020-r1-053-t9zxn.18d467a9f4c6c2ee,"reason=Pulled count=1 msg=Container image ""busybox:musl"" already present on machine"
0.5319,Event,ADDED,eval-conflicts-rho020-r1-053-t9zxn.18d467a9f5f1c5f0,reason=Created count=1 msg=Created container: task
0.5321,Event,ADDED,eval-conflicts-rho020-r1-053-t9zxn.18d467a9faa757f9,reason=Started count=1 msg=Started container task
0.5324,Event,ADDED,eval-conflicts-rho020-r1-053.18d467a9d627ae04,reason=SuccessfulCreate count=1 msg=Created pod: eval-conflicts-rho020-r1-053-t9zxn
0.5326,Event,ADDED,eval-conflicts-rho020-r1-053.18d467ad2419b02c,reason=Completed count=1 msg=Job completed
0.5328,Event,ADDED,eval-conflicts-rho020-r1-054-cfgzn.18d467aa139dd9db,reason=Scheduled count=None msg=Successfully assigned compute/eval-conflicts-rho020-r1-054-cfgzn to kind-worker4
0.5331,Event,ADDED,eval-conflicts-rho020-r1-054-cfgzn.18d467aa2ceeb8cf,"reason=Pulled count=1 msg=Container image ""busybox:musl"" already present on machine"
0.5332,Event,ADDED,eval-conflicts-rho020-r1-054-cfgzn.18d467aa2e0b06b8,reason=Created count=1 msg=Created container: task
0.5334,Event,ADDED,eval-conflicts-rho020-r1-054-cfgzn.18d467aa300c70ac,reason=Started count=1 msg=Started container task
0.5336,Event,ADDED,eval-conflicts-rho020-r1-054.18d467aa127de47f,reason=SuccessfulCreate count=1 msg=Created pod: eval-conflicts-rho020-r1-054-cfgzn
0.5339,Event,ADDED,eval-conflicts-rho020-r1-054.18d467ad5ff2a13a,reason=Completed count=1 msg=Job completed
0.5341,Event,ADDED,eval-conflicts-rho020-r1-055-rkmvb.18d467aa4ed19a2d,reason=Scheduled count=None msg=Successfully assigned compute/eval-conflicts-rho020-r1-055-rkmvb to kind-worker2
0.5342,Event,ADDED,eval-conflicts-rho020-r1-055-rkmvb.18d467aa6d55f90c,"reason=Pulled count=1 msg=Container image ""busybox:musl"" already present on machine"
0.5345,Event,ADDED,eval-conflicts-rho020-r1-055-rkmvb.18d467aa6e729945,reason=Created count=1 msg=Created container: task
0.5347,Event,ADDED,eval-conflicts-rho020-r1-055-rkmvb.18d467aa73481294,reason=Started count=1 msg=Started container task
0.5349,Event,ADDED,eval-conflicts-rho020-r1-055.18d467aa4debeab9,reason=SuccessfulCreate count=1 msg=Created pod: eval-conflicts-rho020-r1-055-rkmvb
0.5351,Event,ADDED,eval-conflicts-rho020-r1-055.18d467ad891b255f,reason=Completed count=1 msg=Job completed
0.5353,Event,ADDED,eval-conflicts-rho020-r1-056-t2wf4.18d467aa89c78480,reason=Scheduled count=None msg=Successfully assigned compute/eval-conflicts-rho020-r1-056-t2wf4 to kind-worker5
0.5356,Event,ADDED,eval-conflicts-rho020-r1-056-t2wf4.18d467aaa3131247,"reason=Pulled count=1 msg=Container image ""busybox:musl"" already present on machine"
0.5358,Event,ADDED,eval-conflicts-rho020-r1-056-t2wf4.18d467aaa42f5fa3,reason=Created count=1 msg=Created container: task
0.536,Event,ADDED,eval-conflicts-rho020-r1-056-t2wf4.18d467aaa62e4cc9,reason=Started count=1 msg=Started container task
0.5362,Event,ADDED,eval-conflicts-rho020-r1-056.18d467aa895dadf6,reason=SuccessfulCreate count=1 msg=Created pod: eval-conflicts-rho020-r1-056-t2wf4
0.5364,Event,ADDED,eval-conflicts-rho020-r1-056.18d467add425bda7,reason=Completed count=1 msg=Job completed
0.5365,Event,ADDED,eval-conflicts-rho020-r1-057-b4c2s.18d467aac602ad5c,reason=Scheduled count=None msg=Successfully assigned compute/eval-conflicts-rho020-r1-057-b4c2s to kind-worker5
0.5368,Event,ADDED,eval-conflicts-rho020-r1-057-b4c2s.18d467aadf415284,"reason=Pulled count=1 msg=Container image ""busybox:musl"" already present on machine"
0.5369,Event,ADDED,eval-conflicts-rho020-r1-057-b4c2s.18d467aae055ce2d,reason=Created count=1 msg=Created container: task
0.5371,Event,ADDED,eval-conflicts-rho020-r1-057-b4c2s.18d467aae267954c,reason=Started count=1 msg=Started container task
0.5372,Event,ADDED,eval-conflicts-rho020-r1-057.18d467aac52e8a60,reason=SuccessfulCreate count=1 msg=Created pod: eval-conflicts-rho020-r1-057-b4c2s
0.5374,Event,ADDED,eval-conflicts-rho020-r1-057.18d467ae0eda76d1,reason=Completed count=1 msg=Job completed
0.5376,Event,ADDED,eval-conflicts-rho020-r1-058-2mxbv.18d467ab0185bcf3,reason=Scheduled count=None msg=Successfully assigned compute/eval-conflicts-rho020-r1-058-2mxbv to kind-worker5
0.5377,Event,ADDED,eval-conflicts-rho020-r1-058-2mxbv.18d467ab1c3fb5d3,"reason=Pulled count=1 msg=Container image ""busybox:musl"" already present on machine"
0.5379,Event,ADDED,eval-conflicts-rho020-r1-058-2mxbv.18d467ab1d579db1,reason=Created count=1 msg=Created container: task
0.5383,Event,ADDED,eval-conflicts-rho020-r1-058-2mxbv.18d467ab21a46501,reason=Started count=1 msg=Started container task
0.5385,Event,ADDED,eval-conflicts-rho020-r1-058.18d467ab011ec3a8,reason=SuccessfulCreate count=1 msg=Created pod: eval-conflicts-rho020-r1-058-2mxbv
0.5388,Event,ADDED,eval-conflicts-rho020-r1-058.18d467ae0f86d73d,reason=Completed count=1 msg=Job completed
0.539,Event,ADDED,eval-conflicts-rho020-r1-059-bmlsq.18d467ab3d0aaa5e,reason=Scheduled count=None msg=Successfully assigned compute/eval-conflicts-rho020-r1-059-bmlsq to kind-worker5
0.5392,Event,ADDED,eval-conflicts-rho020-r1-059-bmlsq.18d467ab55a4dc85,"reason=Pulled count=1 msg=Container image ""busybox:musl"" already present on machine"
0.5394,Event,ADDED,eval-conflicts-rho020-r1-059-bmlsq.18d467ab56ab54e9,reason=Created count=1 msg=Created container: task
0.5396,Event,ADDED,eval-conflicts-rho020-r1-059-bmlsq.18d467ab58d5a3ea,reason=Started count=1 msg=Started container task
0.5399,Event,ADDED,eval-conflicts-rho020-r1-059.18d467ab3c829da7,reason=SuccessfulCreate count=1 msg=Created pod: eval-conflicts-rho020-r1-059-bmlsq
0.5401,Event,ADDED,eval-conflicts-rho020-r1-059.18d467ae86d774dd,reason=Completed count=1 msg=Job completed
0.5402,Event,ADDED,eval-conflicts-rho020-r1-060-cfgwk.18d467ab785781a2,reason=Scheduled count=None msg=Successfully assigned compute/eval-conflicts-rho020-r1-060-cfgwk to kind-worker5
0.5404,Event,ADDED,eval-conflicts-rho020-r1-060-cfgwk.18d467ab936dacad,"reason=Pulled count=1 msg=Container image ""busybox:musl"" already present on machine"
0.5406,Event,ADDED,eval-conflicts-rho020-r1-060-cfgwk.18d467ab948f1e44,reason=Created count=1 msg=Created container: task
0.5408,Event,ADDED,eval-conflicts-rho020-r1-060-cfgwk.18d467ab97eac996,reason=Started count=1 msg=Started container task
0.541,Event,ADDED,eval-conflicts-rho020-r1-060.18d467ab77be9d04,reason=SuccessfulCreate count=1 msg=Created pod: eval-conflicts-rho020-r1-060-cfgwk
0.5412,Event,ADDED,eval-conflicts-rho020-r1-060.18d467aec2cd39f3,reason=Completed count=1 msg=Job completed
0.5413,Event,ADDED,eval-conflicts-rho020-r1-061-fj29z.18d467abb3d121d8,reason=Scheduled count=None msg=Successfully assigned compute/eval-conflicts-rho020-r1-061-fj29z to kind-worker5
0.5415,Event,ADDED,eval-conflicts-rho020-r1-061-fj29z.18d467abccd99db6,"reason=Pulled count=1 msg=Container image ""busybox:musl"" already present on machine"
0.5416,Event,ADDED,eval-conflicts-rho020-r1-061-fj29z.18d467abcdf547a5,reason=Created count=1 msg=Created container: task
0.5418,Event,ADDED,eval-conflicts-rho020-r1-061-fj29z.18d467abcff45ccd,reason=Started count=1 msg=Started container task
0.542,Event,ADDED,eval-conflicts-rho020-r1-061.18d467abb341e6e5,reason=SuccessfulCreate count=1 msg=Created pod: eval-conflicts-rho020-r1-061-fj29z
0.5421,Event,ADDED,eval-conflicts-rho020-r1-061.18d467aefed59fa4,reason=Completed count=1 msg=Job completed
0.5423,Event,ADDED,eval-conflicts-rho020-r1-062-qtsbv.18d467abef7f9caf,reason=Scheduled count=None msg=Successfully assigned compute/eval-conflicts-rho020-r1-062-qtsbv to kind-worker5
0.5426,Event,ADDED,eval-conflicts-rho020-r1-062-qtsbv.18d467ac08c37f2a,"reason=Pulled count=1 msg=Container image ""busybox:musl"" already present on machine"
0.5427,Event,ADDED,eval-conflicts-rho020-r1-062-qtsbv.18d467ac09ce1515,reason=Created count=1 msg=Created container: task
0.5429,Event,ADDED,eval-conflicts-rho020-r1-062-qtsbv.18d467ac0ba79a29,reason=Started count=1 msg=Started container task
0.5431,Event,ADDED,eval-conflicts-rho020-r1-062.18d467abeefb5da6,reason=SuccessfulCreate count=1 msg=Created pod: eval-conflicts-rho020-r1-062-qtsbv
0.5432,Event,ADDED,eval-conflicts-rho020-r1-062.18d467af3ae21131,reason=Completed count=1 msg=Job completed
0.5434,Event,ADDED,eval-conflicts-rho020-r1-063-vrqfq.18d467ac2b494bb1,reason=Scheduled count=None msg=Successfully assigned compute/eval-conflicts-rho020-r1-063-vrqfq to kind-worker5
0.5436,Event,ADDED,eval-conflicts-rho020-r1-063-vrqfq.18d467ac44be04ab,"reason=Pulled count=1 msg=Container image ""busybox:musl"" already present on machine"
0.544,Event,ADDED,eval-conflicts-rho020-r1-063-vrqfq.18d467ac45db9efa,reason=Created count=1 msg=Created container: task
0.5442,Event,ADDED,eval-conflicts-rho020-r1-063-vrqfq.18d467ac4a88731c,reason=Started count=1 msg=Started container task
0.5444,Event,ADDED,eval-conflicts-rho020-r1-063.18d467ac2aa43864,reason=SuccessfulCreate count=1 msg=Created pod: eval-conflicts-rho020-r1-063-vrqfq
0.5448,Event,ADDED,eval-conflicts-rho020-r1-063.18d467af761db4a7,reason=Completed count=1 msg=Job completed
0.545,Event,ADDED,eval-conflicts-rho020-r1-064-ctkmw.18d467ac673269f3,reason=Scheduled count=None msg=Successfully assigned compute/eval-conflicts-rho020-r1-064-ctkmw to kind-worker3
0.5452,Event,ADDED,eval-conflicts-rho020-r1-064-ctkmw.18d467ac803f0b6f,"reason=Pulled count=1 msg=Container image ""busybox:musl"" already present on machine"
0.5453,Event,ADDED,eval-conflicts-rho020-r1-064-ctkmw.18d467ac814af0d0,reason=Created count=1 msg=Created container: task
0.5457,Event,ADDED,eval-conflicts-rho020-r1-064-ctkmw.18d467ac837e9407,reason=Started count=1 msg=Started container task
0.5458,Event,ADDED,eval-conflicts-rho020-r1-064.18d467ac6626fe3d,reason=SuccessfulCreate count=1 msg=Created pod: eval-conflicts-rho020-r1-064-ctkmw
0.546,Event,ADDED,eval-conflicts-rho020-r1-064.18d467afc4d53b2a,reason=Completed count=1 msg=Job completed
0.5462,Event,ADDED,eval-conflicts-rho020-r1-065-v9ctv.18d467aca29966b2,reason=Scheduled count=None msg=Successfully assigned compute/eval-conflicts-rho020-r1-065-v9ctv to kind-worker
0.5465,Event,ADDED,eval-conflicts-rho020-r1-065-v9ctv.18d467acbb2f2c29,"reason=Pulled count=1 msg=Container image ""busybox:musl"" already present on machine"
0.5467,Event,ADDED,eval-conflicts-rho020-r1-065-v9ctv.18d467acbcf0ccdc,reason=Created count=1 msg=Created container: task
0.5469,Event,ADDED,eval-conflicts-rho020-r1-065-v9ctv.18d467acbf225a8d,reason=Started count=1 msg=Started container task
0.5476,Event,ADDED,eval-conflicts-rho020-r1-065.18d467aca180b50e,reason=SuccessfulCreate count=1 msg=Created pod: eval-conflicts-rho020-r1-065-v9ctv
0.548,Event,ADDED,eval-conflicts-rho020-r1-065.18d467afead8a6dd,reason=Completed count=1 msg=Job completed
0.5483,Event,ADDED,eval-conflicts-rho020-r1-066-8qdxt.18d467acdea03775,reason=Scheduled count=None msg=Successfully assigned compute/eval-conflicts-rho020-r1-066-8qdxt to kind-worker
0.5485,Event,ADDED,eval-conflicts-rho020-r1-066-8qdxt.18d467acf7da18ce,"reason=Pulled count=1 msg=Container image ""busybox:musl"" already present on machine"
0.5489,Event,ADDED,eval-conflicts-rho020-r1-066-8qdxt.18d467acf8fa65e9,reason=Created count=1 msg=Created container: task
0.5491,Event,ADDED,eval-conflicts-rho020-r1-066-8qdxt.18d467acfb16c93e,reason=Started count=1 msg=Started container task
0.5493,Event,ADDED,eval-conflicts-rho020-r1-066.18d467acdda967ed,reason=SuccessfulCreate count=1 msg=Created pod: eval-conflicts-rho020-r1-066-8qdxt
0.5496,Event,ADDED,eval-conflicts-rho020-r1-066.18d467b026ae7440,reason=Completed count=1 msg=Job completed
0.5498,Event,ADDED,eval-conflicts-rho020-r1-067-99hd6.18d467ad1ab5ea92,reason=Scheduled count=None msg=Successfully assigned compute/eval-conflicts-rho020-r1-067-99hd6 to kind-worker
0.55,Event,ADDED,eval-conflicts-rho020-r1-067-99hd6.18d467ad34a51429,"reason=Pulled count=1 msg=Container image ""busybox:musl"" already present on machine"
0.5501,Event,ADDED,eval-conflicts-rho020-r1-067-99hd6.18d467ad35d69621,reason=Created count=1 msg=Created container: task
0.5505,Event,ADDED,eval-conflicts-rho020-r1-067-99hd6.18d467ad39c78e3a,reason=Started count=1 msg=Started container task
0.5507,Event,ADDED,eval-conflicts-rho020-r1-067.18d467ad19d9a7f8,reason=SuccessfulCreate count=1 msg=Created pod: eval-conflicts-rho020-r1-067-99hd6
0.5509,Event,ADDED,eval-conflicts-rho020-r1-067.18d467b06201c81b,reason=Completed count=1 msg=Job completed
0.551,Event,ADDED,eval-conflicts-rho020-r1-068-lhdfq.18d467ad55cc3162,reason=Scheduled count=None msg=Successfully assigned compute/eval-conflicts-rho020-r1-068-lhdfq to kind-worker
0.5514,Event,ADDED,eval-conflicts-rho020-r1-068-lhdfq.18d467ad6f8653b3,"reason=Pulled count=1 msg=Container image ""busybox:musl"" already present on machine"
0.5516,Event,ADDED,eval-conflicts-rho020-r1-068-lhdfq.18d467ad70c0e29a,reason=Created count=1 msg=Created container: task
0.5517,Event,ADDED,eval-conflicts-rho020-r1-068-lhdfq.18d467ad74d28362,reason=Started count=1 msg=Started container task
0.5521,Event,ADDED,eval-conflicts-rho020-r1-068.18d467ad54e20a22,reason=SuccessfulCreate count=1 msg=Created pod: eval-conflicts-rho020-r1-068-lhdfq
0.5522,Event,ADDED,eval-conflicts-rho020-r1-068.18d467b09e39dad2,reason=Completed count=1 msg=Job completed
0.5524,Event,ADDED,eval-conflicts-rho020-r1-069-z2mq8.18d467ad91c126c9,"reason=FailedScheduling count=None msg=0/6 nodes are available: 2 c_wall violated: 1 conflicting context pair(s) with node memory, 4 node(s) had untolerated taint(s). no new claims to deallocate, preemption: 0/6 nodes are available: 2 No preemption victims found for incoming pod, 4 Preemption is not helpful for scheduling."
0.5526,Event,ADDED,eval-conflicts-rho020-r1-069-z2mq8.18d467ad92671870,"reason=FailedScheduling count=None msg=0/6 nodes are available: 2 c_wall violated: 1 conflicting context pair(s) with node memory, 4 node(s) had untolerated taint(s). no new claims to deallocate, preemption: 0/6 nodes are available: 2 No preemption victims found for incoming pod, 4 Preemption is not helpful for scheduling."
0.5528,Event,ADDED,eval-conflicts-rho020-r1-069-z2mq8.18d467adce089bdf,"reason=FailedScheduling count=None msg=0/6 nodes are available: 1 c_wall violated: 1 conflicting context pair(s) with node memory, 1 c_wall violated: 2 conflicting context pair(s) with node memory, 4 node(s) had untolerated taint(s). no new claims to deallocate, preemption: 0/6 nodes are available: 2 No preemption victims found for incoming pod, 4 Preemption is not helpful for scheduling."
0.553,Event,ADDED,eval-conflicts-rho020-r1-069-z2mq8.18d467ae95b65150,"reason=FailedScheduling count=None msg=0/6 nodes are available: 1 c_wall violated: 1 conflicting context pair(s) with node memory, 5 node(s) had untolerated taint(s). no new claims to deallocate, preemption: 0/6 nodes are available: 1 No preemption victims found for incoming pod, 5 Preemption is not helpful for scheduling."
0.5532,Event,ADDED,eval-conflicts-rho020-r1-069-z2mq8.18d467af1338d0bf,reason=Scheduled count=None msg=Successfully assigned compute/eval-conflicts-rho020-r1-069-z2mq8 to kind-worker2
0.5534,Event,ADDED,eval-conflicts-rho020-r1-069-z2mq8.18d467af2cca0818,"reason=Pulled count=1 msg=Container image ""busybox:musl"" already present on machine"
0.5535,Event,ADDED,eval-conflicts-rho020-r1-069-z2mq8.18d467af2e29acb3,reason=Created count=1 msg=Created container: task
0.5537,Event,ADDED,eval-conflicts-rho020-r1-069-z2mq8.18d467af303f37e0,reason=Started count=1 msg=Started container task
0.5539,Event,ADDED,eval-conflicts-rho020-r1-069.18d467ad91581fe5,reason=SuccessfulCreate count=1 msg=Created pod: eval-conflicts-rho020-r1-069-z2mq8
0.554,Event,ADDED,eval-conflicts-rho020-r1-069.18d467b26ea7a358,reason=Completed count=1 msg=Job completed
0.5542,Event,ADDED,eval-conflicts-rho020-r1-070-wk685.18d467adcc96649a,reason=Scheduled count=None msg=Successfully assigned compute/eval-conflicts-rho020-r1-070-wk685 to kind-worker3
0.5543,Event,ADDED,eval-conflicts-rho020-r1-070-wk685.18d467ade587df11,"reason=Pulled count=1 msg=Container image ""busybox:musl"" already present on machine"
0.5546,Event,ADDED,eval-conflicts-rho020-r1-070-wk685.18d467ade6a4fd34,reason=Created count=1 msg=Created container: task
0.5548,Event,ADDED,eval-conflicts-rho020-r1-070-wk685.18d467ade89bc440,reason=Started count=1 msg=Started container task
0.555,Event,ADDED,eval-conflicts-rho020-r1-070.18d467adcbf9dcf7,reason=SuccessfulCreate count=1 msg=Created pod: eval-conflicts-rho020-r1-070-wk685
0.5553,Event,ADDED,eval-conflicts-rho020-r1-070.18d467b12a85db4a,reason=Completed count=1 msg=Job completed
0.5555,Event,ADDED,eval-conflicts-rho020-r1-071-bztnn.18d467ae084139e8,reason=Scheduled count=None msg=Successfully assigned compute/eval-conflicts-rho020-r1-071-bztnn to kind-worker3
0.5558,Event,ADDED,eval-conflicts-rho020-r1-071-bztnn.18d467ae20ce1b00,"reason=Pulled count=1 msg=Container image ""busybox:musl"" already present on machine"
0.5559,Event,ADDED,eval-conflicts-rho020-r1-071-bztnn.18d467ae21f06c91,reason=Created count=1 msg=Created container: task
0.5562,Event,ADDED,eval-conflicts-rho020-r1-071-bztnn.18d467ae2682c63c,reason=Started count=1 msg=Started container task
0.5563,Event,ADDED,eval-conflicts-rho020-r1-071.18d467ae078d6e8b,reason=SuccessfulCreate count=1 msg=Created pod: eval-conflicts-rho020-r1-071-bztnn
0.5565,Event,ADDED,eval-conflicts-rho020-r1-071.18d467b16622214d,reason=Completed count=1 msg=Job completed
0.5566,Event,ADDED,eval-conflicts-rho020-r1-072-ffspt.18d467ae43cd7a75,reason=Scheduled count=None msg=Successfully assigned compute/eval-conflicts-rho020-r1-072-ffspt to kind-worker3
0.5568,Event,ADDED,eval-conflicts-rho020-r1-072-ffspt.18d467ae5d931c10,"reason=Pulled count=1 msg=Container image ""busybox:musl"" already present on machine"
0.557,Event,ADDED,eval-conflicts-rho020-r1-072-ffspt.18d467ae5eb6ada5,reason=Created count=1 msg=Created container: task
0.5571,Event,ADDED,eval-conflicts-rho020-r1-072-ffspt.18d467ae68b26380,reason=Started count=1 msg=Started container task
0.5575,Event,ADDED,eval-conflicts-rho020-r1-072.18d467ae431a59f7,reason=SuccessfulCreate count=1 msg=Created pod: eval-conflicts-rho020-r1-072-ffspt
0.5576,Event,ADDED,eval-conflicts-rho020-r1-072.18d467b1a13f35c6,reason=Completed count=1 msg=Job completed
0.5578,Event,ADDED,eval-conflicts-rho020-r1-073-vb7sf.18d467ae80bc2839,reason=Scheduled count=None msg=Successfully assigned compute/eval-conflicts-rho020-r1-073-vb7sf to kind-worker
0.558,Event,ADDED,eval-conflicts-rho020-r1-073-vb7sf.18d467ae9962bc87,"reason=Pulled count=1 msg=Container image ""busybox:musl"" already present on machine"
0.5582,Event,ADDED,eval-conflicts-rho020-r1-073-vb7sf.18d467ae9ab551f4,reason=Created count=1 msg=Created container: task
0.5584,Event,ADDED,eval-conflicts-rho020-r1-073-vb7sf.18d467ae9caa68b3,reason=Started count=1 msg=Started container task
0.5585,Event,ADDED,eval-conflicts-rho020-r1-073.18d467ae7f82f2b6,reason=SuccessfulCreate count=1 msg=Created pod: eval-conflicts-rho020-r1-073-vb7sf
0.5587,Event,ADDED,eval-conflicts-rho020-r1-073.18d467b1c836e039,reason=Completed count=1 msg=Job completed
0.5589,Event,ADDED,eval-conflicts-rho020-r1-074-hp58n.18d467aebab77489,reason=Scheduled count=None msg=Successfully assigned compute/eval-conflicts-rho020-r1-074-hp58n to kind-worker
0.559,Event,ADDED,eval-conflicts-rho020-r1-074-hp58n.18d467aed39c7380,"reason=Pulled count=1 msg=Container image ""busybox:musl"" already present on machine"
0.5592,Event,ADDED,eval-conflicts-rho020-r1-074-hp58n.18d467aed4a5dc30,reason=Created count=1 msg=Created container: task
0.5594,Event,ADDED,eval-conflicts-rho020-r1-074-hp58n.18d467aed67fe9f7,reason=Started count=1 msg=Started container task
0.5597,Event,ADDED,eval-conflicts-rho020-r1-074.18d467aeba32a30b,reason=SuccessfulCreate count=1 msg=Created pod: eval-conflicts-rho020-r1-074-hp58n
0.56,Event,ADDED,eval-conflicts-rho020-r1-074.18d467b203f79084,reason=Completed count=1 msg=Job completed
0.5601,Event,ADDED,eval-conflicts-rho020-r1-075-8bm2l.18d467aef593ca75,"reason=FailedScheduling count=None msg=0/6 nodes are available: 6 node(s) had untolerated taint(s). no new claims to deallocate, preemption: 0/6 nodes are available: 6 Preemption is not helpful for scheduling."
0.5604,Event,ADDED,eval-conflicts-rho020-r1-075-8bm2l.18d467af136ab41a,reason=Scheduled count=None msg=Successfully assigned compute/eval-conflicts-rho020-r1-075-8bm2l to kind-worker2
0.5605,Event,ADDED,eval-conflicts-rho020-r1-075-8bm2l.18d467af2cdf311c,"reason=Pulled count=1 msg=Container image ""busybox:musl"" already present on machine"
0.5607,Event,ADDED,eval-conflicts-rho020-r1-075-8bm2l.18d467af2e76fb34,reason=Created count=1 msg=Created container: task
0.5609,Event,ADDED,eval-conflicts-rho020-r1-075-8bm2l.18d467af307e9e33,reason=Started count=1 msg=Started container task
0.5611,Event,ADDED,eval-conflicts-rho020-r1-075.18d467aef587a3b9,reason=SuccessfulCreate count=1 msg=Created pod: eval-conflicts-rho020-r1-075-8bm2l
0.5613,Event,ADDED,eval-conflicts-rho020-r1-075.18d467b26e7e05f8,reason=Completed count=1 msg=Job completed
0.5614,Event,ADDED,eval-conflicts-rho020-r1-076-2xxgk.18d467af31a16f21,reason=Scheduled count=None msg=Successfully assigned compute/eval-conflicts-rho020-r1-076-2xxgk to kind-worker4
0.5616,Event,ADDED,eval-conflicts-rho020-r1-076-2xxgk.18d467af4bc37bc8,"reason=Pulled count=1 msg=Container image ""busybox:musl"" already present on machine"
0.5618,Event,ADDED,eval-conflicts-rho020-r1-076-2xxgk.18d467af4cef1ffb,reason=Created count=1 msg=Created container: task
0.562,Event,ADDED,eval-conflicts-rho020-r1-076-2xxgk.18d467af50625391,reason=Started count=1 msg=Started container task
0.5621,Event,ADDED,eval-conflicts-rho020-r1-076.18d467af3126cd0f,reason=SuccessfulCreate count=1 msg=Created pod: eval-conflicts-rho020-r1-076-2xxgk
0.5623,Event,ADDED,eval-conflicts-rho020-r1-076.18d467b281d5999d,reason=Completed count=1 msg=Job completed
0.5624,Event,ADDED,eval-conflicts-rho020-r1-077-msx6f.18d467af6e31e6fb,reason=Scheduled count=None msg=Successfully assigned compute/eval-conflicts-rho020-r1-077-msx6f to kind-worker5
0.5626,Event,ADDED,eval-conflicts-rho020-r1-077-msx6f.18d467af883d53df,"reason=Pulled count=1 msg=Container image ""busybox:musl"" already present on machine"
0.5629,Event,ADDED,eval-conflicts-rho020-r1-077-msx6f.18d467af89801a30,reason=Created count=1 msg=Created container: task
0.5631,Event,ADDED,eval-conflicts-rho020-r1-077-msx6f.18d467af8db5e7e1,reason=Started count=1 msg=Started container task
0.5632,Event,ADDED,eval-conflicts-rho020-r1-077.18d467af6d2e9125,reason=SuccessfulCreate count=1 msg=Created pod: eval-conflicts-rho020-r1-077-msx6f
0.5634,Event,ADDED,eval-conflicts-rho020-r1-077.18d467b2bb3976d4,reason=Completed count=1 msg=Job completed
0.5636,Event,ADDED,eval-conflicts-rho020-r1-078-qlcvl.18d467afaa325687,reason=Scheduled count=None msg=Successfully assigned compute/eval-conflicts-rho020-r1-078-qlcvl to kind-worker5
0.5638,Event,ADDED,eval-conflicts-rho020-r1-078-qlcvl.18d467afc47728b9,"reason=Pulled count=1 msg=Container image ""busybox:musl"" already present on machine"
0.5641,Event,ADDED,eval-conflicts-rho020-r1-078-qlcvl.18d467afc5c8513c,reason=Created count=1 msg=Created container: task
0.5643,Event,ADDED,eval-conflicts-rho020-r1-078-qlcvl.18d467afc9e09705,reason=Started count=1 msg=Started container task
0.5645,Event,ADDED,eval-conflicts-rho020-r1-078.18d467afa8e5ae76,reason=SuccessfulCreate count=1 msg=Created pod: eval-conflicts-rho020-r1-078-qlcvl
0.5646,Event,ADDED,eval-conflicts-rho020-r1-078.18d467b2f727d123,reason=Completed count=1 msg=Job completed
0.5648,Event,ADDED,eval-conflicts-rho020-r1-079-wnjmx.18d467afe569fa1a,reason=Scheduled count=None msg=Successfully assigned compute/eval-conflicts-rho020-r1-079-wnjmx to kind-worker5
0.565,Event,ADDED,eval-conflicts-rho020-r1-079-wnjmx.18d467affdf6e572,"reason=Pulled count=1 msg=Container image ""busybox:musl"" already present on machine"
0.5651,Event,ADDED,eval-conflicts-rho020-r1-079-wnjmx.18d467afff12924f,reason=Created count=1 msg=Created container: task
0.5653,Event,ADDED,eval-conflicts-rho020-r1-079-wnjmx.18d467b00105663a,reason=Started count=1 msg=Started container task
0.5655,Event,ADDED,eval-conflicts-rho020-r1-079.18d467afe3f7c254,reason=SuccessfulCreate count=1 msg=Created pod: eval-conflicts-rho020-r1-079-wnjmx
0.5656,Event,ADDED,eval-conflicts-rho020-r1-079.18d467b333b42fb5,reason=Completed count=1 msg=Job completed
0.5658,Event,ADDED,eval-conflicts-rho020-r1-080-qfncq.18d467b020ca5633,reason=Scheduled count=None msg=Successfully assigned compute/eval-conflicts-rho020-r1-080-qfncq to kind-worker2
0.566,Event,ADDED,eval-conflicts-rho020-r1-080-qfncq.18d467b03ae029c5,"reason=Pulled count=1 msg=Container image ""busybox:musl"" already present on machine"
0.5661,Event,ADDED,eval-conflicts-rho020-r1-080-qfncq.18d467b03bf4d4d3,reason=Created count=1 msg=Created container: task
0.5663,Event,ADDED,eval-conflicts-rho020-r1-080-qfncq.18d467b03dee0cdf,reason=Started count=1 msg=Started container task
0.5664,Event,ADDED,eval-conflicts-rho020-r1-080.18d467b01f8b28ce,reason=SuccessfulCreate count=1 msg=Created pod: eval-conflicts-rho020-r1-080-qfncq
0.5666,Event,ADDED,eval-conflicts-rho020-r1-080.18d467b35dee75ea,reason=Completed count=1 msg=Job completed
0.5668,Event,ADDED,eval-conflicts-rho020-r1-081-5zsgr.18d467b05ca02760,reason=Scheduled count=None msg=Successfully assigned compute/eval-conflicts-rho020-r1-081-5zsgr to kind-worker5
0.567,Event,ADDED,eval-conflicts-rho020-r1-081-5zsgr.18d467b0761644d7,"reason=Pulled count=1 msg=Container image ""busybox:musl"" already present on machine"
0.5671,Event,ADDED,eval-conflicts-rho020-r1-081-5zsgr.18d467b07728e89c,reason=Created count=1 msg=Created container: task
0.5673,Event,ADDED,eval-conflicts-rho020-r1-081-5zsgr.18d467b0797acd74,reason=Started count=1 msg=Started container task
0.5675,Event,ADDED,eval-conflicts-rho020-r1-081.18d467b05b85ccda,reason=SuccessfulCreate count=1 msg=Created pod: eval-conflicts-rho020-r1-081-5zsgr
0.5676,Event,ADDED,eval-conflicts-rho020-r1-081.18d467b3aae00cab,reason=Completed count=1 msg=Job completed
0.5678,Event,ADDED,eval-conflicts-rho020-r1-082-kw79d.18d467b099471d1e,reason=Scheduled count=None msg=Successfully assigned compute/eval-conflicts-rho020-r1-082-kw79d to kind-worker4
0.568,Event,ADDED,eval-conflicts-rho020-r1-082-kw79d.18d467b0b207b926,"reason=Pulled count=1 msg=Container image ""busybox:musl"" already present on machine"
0.5681,Event,ADDED,eval-conflicts-rho020-r1-082-kw79d.18d467b0b344fd0e,reason=Created count=1 msg=Created container: task
0.5683,Event,ADDED,eval-conflicts-rho020-r1-082-kw79d.18d467b0b666ff8f,reason=Started count=1 msg=Started container task
0.5685,Event,ADDED,eval-conflicts-rho020-r1-082.18d467b0984e9af9,reason=SuccessfulCreate count=1 msg=Created pod: eval-conflicts-rho020-r1-082-kw79d
0.5686,Event,ADDED,eval-conflicts-rho020-r1-082.18d467b3e81a796d,reason=Completed count=1 msg=Job completed
0.5688,Event,ADDED,eval-conflicts-rho020-r1-083-6lp5h.18d467b0d3851829,reason=Scheduled count=None msg=Successfully assigned compute/eval-conflicts-rho020-r1-083-6lp5h to kind-worker2
0.5689,Event,ADDED,eval-conflicts-rho020-r1-083-6lp5h.18d467b0ed0c1b6a,"reason=Pulled count=1 msg=Container image ""busybox:musl"" already present on machine"
0.5691,Event,ADDED,eval-conflicts-rho020-r1-083-6lp5h.18d467b0ee7b9063,reason=Created count=1 msg=Created container: task
0.5693,Event,ADDED,eval-conflicts-rho020-r1-083-6lp5h.18d467b0f26f4b08,reason=Started count=1 msg=Started container task
0.5694,Event,ADDED,eval-conflicts-rho020-r1-083.18d467b0d26eb1d8,reason=SuccessfulCreate count=1 msg=Created pod: eval-conflicts-rho020-r1-083-6lp5h
0.5696,Event,ADDED,eval-conflicts-rho020-r1-083.18d467b410f4d05e,reason=Completed count=1 msg=Job completed
0.5697,Event,ADDED,eval-conflicts-rho020-r1-084-fzdhn.18d467b10ef5db33,"reason=FailedScheduling count=None msg=0/6 nodes are available: 3 c_wall violated: 1 conflicting context pair(s) with node memory, 3 node(s) had untolerated taint(s). no new claims to deallocate, preemption: 0/6 nodes are available: 3 No preemption victims found for incoming pod, 3 Preemption is not helpful for scheduling."
0.5699,Event,ADDED,eval-conflicts-rho020-r1-084-fzdhn.18d467b113b14efa,"reason=FailedScheduling count=None msg=0/6 nodes are available: 3 c_wall violated: 1 conflicting context pair(s) with node memory, 3 node(s) had untolerated taint(s). no new claims to deallocate, preemption: 0/6 nodes are available: 3 No preemption victims found for incoming pod, 3 Preemption is not helpful for scheduling."
0.5701,Event,ADDED,eval-conflicts-rho020-r1-084-fzdhn.18d467b16ccda504,"reason=FailedScheduling count=None msg=0/6 nodes are available: 2 c_wall violated: 1 conflicting context pair(s) with node memory, 4 node(s) had untolerated taint(s). no new claims to deallocate, preemption: 0/6 nodes are available: 2 No preemption victims found for incoming pod, 4 Preemption is not helpful for scheduling."
0.5703,Event,ADDED,eval-conflicts-rho020-r1-084-fzdhn.18d467b18bad6300,"reason=FailedScheduling count=None msg=0/6 nodes are available: 1 c_wall violated: 1 conflicting context pair(s) with node memory, 5 node(s) had untolerated taint(s). no new claims to deallocate, preemption: 0/6 nodes are available: 1 No preemption victims found for incoming pod, 5 Preemption is not helpful for scheduling."
0.5705,Event,ADDED,eval-conflicts-rho020-r1-084-fzdhn.18d467b35b0d78c4,reason=Scheduled count=None msg=Successfully assigned compute/eval-conflicts-rho020-r1-084-fzdhn to kind-worker3
0.5706,Event,ADDED,eval-conflicts-rho020-r1-084-fzdhn.18d467b37511b975,"reason=Pulled count=1 msg=Container image ""busybox:musl"" already present on machine"
0.5708,Event,ADDED,eval-conflicts-rho020-r1-084-fzdhn.18d467b377e92532,reason=Created count=1 msg=Created container: task
0.571,Event,ADDED,eval-conflicts-rho020-r1-084-fzdhn.18d467b37bc3914d,reason=Started count=1 msg=Started container task
0.5712,Event,ADDED,eval-conflicts-rho020-r1-084.18d467b10e32d7af,reason=SuccessfulCreate count=1 msg=Created pod: eval-conflicts-rho020-r1-084-fzdhn
0.5713,Event,ADDED,eval-conflicts-rho020-r1-084.18d467b689473afc,reason=Completed count=1 msg=Job completed
0.5716,Event,ADDED,eval-conflicts-rho020-r1-085-x67xq.18d467b14ad04992,reason=Scheduled count=None msg=Successfully assigned compute/eval-conflicts-rho020-r1-085-x67xq to kind-worker2
0.5718,Event,ADDED,eval-conflicts-rho020-r1-085-x67xq.18d467b16424dc7f,"reason=Pulled count=1 msg=Container image ""busybox:musl"" already present on machine"
0.572,Event,ADDED,eval-conflicts-rho020-r1-085-x67xq.18d467b165410b0c,reason=Created count=1 msg=Created container: task
0.5723,Event,ADDED,eval-conflicts-rho020-r1-085-x67xq.18d467b168e00205,reason=Started count=1 msg=Started container task
0.5725,Event,ADDED,eval-conflicts-rho020-r1-085.18d467b149b847c0,reason=SuccessfulCreate count=1 msg=Created pod: eval-conflicts-rho020-r1-085-x67xq
0.5727,Event,ADDED,eval-conflicts-rho020-r1-085.18d467b488ff069e,reason=Completed count=1 msg=Job completed
0.5728,Event,ADDED,eval-conflicts-rho020-r1-086-8p7ff.18d467b18637596f,reason=Scheduled count=None msg=Successfully assigned compute/eval-conflicts-rho020-r1-086-8p7ff to kind-worker4
0.5731,Event,ADDED,eval-conflicts-rho020-r1-086-8p7ff.18d467b19ee3ee88,"reason=Pulled count=1 msg=Container image ""busybox:musl"" already present on machine"
0.5733,Event,ADDED,eval-conflicts-rho020-r1-086-8p7ff.18d467b19fea5808,reason=Created count=1 msg=Created container: task
0.5736,Event,ADDED,eval-conflicts-rho020-r1-086-8p7ff.18d467b1a21c8e50,reason=Started count=1 msg=Started container task
0.5737,Event,ADDED,eval-conflicts-rho020-r1-086.18d467b185280e61,reason=SuccessfulCreate count=1 msg=Created pod: eval-conflicts-rho020-r1-086-8p7ff
0.574,Event,ADDED,eval-conflicts-rho020-r1-086.18d467b4d724f8c1,reason=Completed count=1 msg=Job completed
0.5742,Event,ADDED,eval-conflicts-rho020-r1-087-htw7n.18d467b1c0b7ad85,"reason=FailedScheduling count=None msg=0/6 nodes are available: 6 node(s) had untolerated taint(s). no new claims to deallocate, preemption: 0/6 nodes are available: 6 Preemption is not helpful for scheduling."
0.5744,Event,ADDED,eval-conflicts-rho020-r1-087-htw7n.18d467b35b96fe3d,reason=Scheduled count=None msg=Successfully assigned compute/eval-conflicts-rho020-r1-087-htw7n to kind-worker3
0.5746,Event,ADDED,eval-conflicts-rho020-r1-087-htw7n.18d467b375bb971c,"reason=Pulled count=1 msg=Container image ""busybox:musl"" already present on machine"
0.5748,Event,ADDED,eval-conflicts-rho020-r1-087-htw7n.18d467b3796f85c7,reason=Created count=1 msg=Created container: task
0.575,Event,ADDED,eval-conflicts-rho020-r1-087-htw7n.18d467b37c79cee4,reason=Started count=1 msg=Started container task
0.5752,Event,ADDED,eval-conflicts-rho020-r1-087.18d467b1c0afb7fa,reason=SuccessfulCreate count=1 msg=Created pod: eval-conflicts-rho020-r1-087-htw7n
0.5755,Event,ADDED,eval-conflicts-rho020-r1-087.18d467b6890b14c4,reason=Completed count=1 msg=Job completed
0.5757,Event,ADDED,eval-conflicts-rho020-r1-088-br5xx.18d467b1fc82cb92,"reason=FailedScheduling count=None msg=0/6 nodes are available: 6 node(s) had untolerated taint(s). no new claims to deallocate, preemption: 0/6 nodes are available: 6 Preemption is not helpful for scheduling."
0.5759,Event,ADDED,eval-conflicts-rho020-r1-088-br5xx.18d467b35bf5bd43,reason=Scheduled count=None msg=Successfully assigned compute/eval-conflicts-rho020-r1-088-br5xx to kind-worker3
0.5762,Event,ADDED,eval-conflicts-rho020-r1-088-br5xx.18d467b375d771a2,"reason=Pulled count=1 msg=Container image ""busybox:musl"" already present on machine"
0.5764,Event,ADDED,eval-conflicts-rho020-r1-088-br5xx.18d467b379948be8,reason=Created count=1 msg=Created container: task
0.5765,Event,ADDED,eval-conflicts-rho020-r1-088-br5xx.18d467b37c77ac51,reason=Started count=1 msg=Started container task
0.5767,Event,ADDED,eval-conflicts-rho020-r1-088.18d467b1fc74940b,reason=SuccessfulCreate count=1 msg=Created pod: eval-conflicts-rho020-r1-088-br5xx
0.577,Event,ADDED,eval-conflicts-rho020-r1-088.18d467b689ab2ccf,reason=Completed count=1 msg=Job completed
0.5772,Event,ADDED,eval-conflicts-rho020-r1-089-p6p5w.18d467b2380db67f,"reason=FailedScheduling count=None msg=0/6 nodes are available: 6 node(s) had untolerated taint(s). no new claims to deallocate, preemption: 0/6 nodes are available: 6 Preemption is not helpful for scheduling."
0.5774,Event,ADDED,eval-conflicts-rho020-r1-089-p6p5w.18d467b35bae81e7,"reason=FailedScheduling count=None msg=0/6 nodes are available: 1 c_wall violated: 2 conflicting context pair(s) with node memory, 5 node(s) had untolerated taint(s). no new claims to deallocate, preemption: 0/6 nodes are available: 1 No preemption victims found for incoming pod, 5 Preemption is not helpful for scheduling."
0.5777,Event,ADDED,eval-conflicts-rho020-r1-089-p6p5w.18d467b361630ae7,"reason=FailedScheduling count=None msg=0/6 nodes are available: 1 c_wall violated: 2 conflicting context pair(s) with node memory, 5 node(s) had untolerated taint(s). no new claims to deallocate, preemption: 0/6 nodes are available: 1 No preemption victims found for incoming pod, 5 Preemption is not helpful for scheduling."
0.5779,Event,ADDED,eval-conflicts-rho020-r1-089-p6p5w.18d467b3baabc939,reason=Scheduled count=None msg=Successfully assigned compute/eval-conflicts-rho020-r1-089-p6p5w to kind-worker
0.578,Event,ADDED,eval-conflicts-rho020-r1-089-p6p5w.18d467b3d490760c,"reason=Pulled count=1 msg=Container image ""busybox:musl"" already present on machine"
0.5782,Event,ADDED,eval-conflicts-rho020-r1-089-p6p5w.18d467b3d6357db6,reason=Created count=1 msg=Created container: task
0.5784,Event,ADDED,eval-conflicts-rho020-r1-089-p6p5w.18d467b3d98bc283,reason=Started count=1 msg=Started container task
0.5786,Event,ADDED,eval-conflicts-rho020-r1-089.18d467b23801e1e5,reason=SuccessfulCreate count=1 msg=Created pod: eval-conflicts-rho020-r1-089-p6p5w
0.5788,Event,ADDED,eval-conflicts-rho020-r1-089.18d467b6ec104fd3,reason=Completed count=1 msg=Job completed
0.5789,Event,ADDED,eval-conflicts-rho020-r1-090-d6z4j.18d467b2739bc33a,"reason=FailedScheduling count=None msg=0/6 nodes are available: 6 node(s) had untolerated taint(s). no new claims to deallocate, preemption: 0/6 nodes are available: 6 Preemption is not helpful for scheduling."
0.5791,Event,ADDED,eval-conflicts-rho020-r1-090-d6z4j.18d467b35c51af2f,"reason=FailedScheduling count=None msg=0/6 nodes are available: 1 c_wall violated: 2 conflicting context pair(s) with node memory, 5 node(s) had untolerated taint(s). no new claims to deallocate, preemption: 0/6 nodes are available: 1 No preemption victims found for incoming pod, 5 Preemption is not helpful for scheduling."
0.5793,Event,ADDED,eval-conflicts-rho020-r1-090-d6z4j.18d467b36194d1aa,"reason=FailedScheduling count=None msg=0/6 nodes are available: 1 c_wall violated: 2 conflicting context pair(s) with node memory, 5 node(s) had untolerated taint(s). no new claims to deallocate, preemption: 0/6 nodes are available: 1 No preemption victims found for incoming pod, 5 Preemption is not helpful for scheduling."
0.5795,Event,ADDED,eval-conflicts-rho020-r1-090-d6z4j.18d467b3ba098690,reason=Scheduled count=None msg=Successfully assigned compute/eval-conflicts-rho020-r1-090-d6z4j to kind-worker
0.5797,Event,ADDED,eval-conflicts-rho020-r1-090-d6z4j.18d467b3d376101f,"reason=Pulled count=1 msg=Container image ""busybox:musl"" already present on machine"
0.5799,Event,ADDED,eval-conflicts-rho020-r1-090-d6z4j.18d467b3d55bceb5,reason=Created count=1 msg=Created container: task
0.5801,Event,ADDED,eval-conflicts-rho020-r1-090-d6z4j.18d467b3d8c148d6,reason=Started count=1 msg=Started container task
0.5803,Event,ADDED,eval-conflicts-rho020-r1-090.18d467b27394eaa5,reason=SuccessfulCreate count=1 msg=Created pod: eval-conflicts-rho020-r1-090-d6z4j
0.5805,Event,ADDED,eval-conflicts-rho020-r1-090.18d467b6ec564235,reason=Completed count=1 msg=Job completed
0.5807,Event,ADDED,eval-conflicts-rho020-r1-091-gccvp.18d467b2b00b0151,"reason=FailedScheduling count=None msg=0/6 nodes are available: 6 node(s) had untolerated taint(s). no new claims to deallocate, preemption: 0/6 nodes are available: 6 Preemption is not helpful for scheduling."
0.5808,Event,ADDED,eval-conflicts-rho020-r1-091-gccvp.18d467b35eb61757,reason=Scheduled count=None msg=Successfully assigned compute/eval-conflicts-rho020-r1-091-gccvp to kind-worker3
0.581,Event,ADDED,eval-conflicts-rho020-r1-091-gccvp.18d467b378c17995,"reason=Pulled count=1 msg=Container image ""busybox:musl"" already present on machine"
0.5812,Event,ADDED,eval-conflicts-rho020-r1-091-gccvp.18d467b37a53f23b,reason=Created count=1 msg=Created container: task
0.5813,Event,ADDED,eval-conflicts-rho020-r1-091-gccvp.18d467b37dc61e1a,reason=Started count=1 msg=Started container task
0.5815,Event,ADDED,eval-conflicts-rho020-r1-091.18d467b2b0062d45,reason=SuccessfulCreate count=1 msg=Created pod: eval-conflicts-rho020-r1-091-gccvp
0.5817,Event,ADDED,eval-conflicts-rho020-r1-091.18d467b6c63cd8ca,reason=Completed count=1 msg=Job completed
0.5818,Event,ADDED,eval-conflicts-rho020-r1-092-wksgh.18d467b2eb6fca6a,"reason=FailedScheduling count=None msg=0/6 nodes are available: 6 node(s) had untolerated taint(s). no new claims to deallocate, preemption: 0/6 nodes are available: 6 Preemption is not helpful for scheduling."
0.582,Event,ADDED,eval-conflicts-rho020-r1-092-wksgh.18d467b361511f49,reason=Scheduled count=None msg=Successfully assigned compute/eval-conflicts-rho020-r1-092-wksgh to kind-worker3
0.5821,Event,ADDED,eval-conflicts-rho020-r1-092-wksgh.18d467b37de9c561,"reason=Pulled count=1 msg=Container image ""busybox:musl"" already present on machine"
0.5823,Event,ADDED,eval-conflicts-rho020-r1-092-wksgh.18d467b37fcdccf2,reason=Created count=1 msg=Created container: task
0.5825,Event,ADDED,eval-conflicts-rho020-r1-092-wksgh.18d467b384313ec2,reason=Started count=1 msg=Started container task
0.5827,Event,ADDED,eval-conflicts-rho020-r1-092.18d467b2eb6998d8,reason=SuccessfulCreate count=1 msg=Created pod: eval-conflicts-rho020-r1-092-wksgh
0.5828,Event,ADDED,eval-conflicts-rho020-r1-092.18d467b6c5b450a5,reason=Completed count=1 msg=Job completed
0.583,Event,ADDED,eval-conflicts-rho020-r1-093-rwkwt.18d467b3270590ab,"reason=FailedScheduling count=None msg=0/6 nodes are available: 6 node(s) had untolerated taint(s). no new claims to deallocate, preemption: 0/6 nodes are available: 6 Preemption is not helpful for scheduling."
0.5832,Event,ADDED,eval-conflicts-rho020-r1-093-rwkwt.18d467b36188805d,reason=Scheduled count=None msg=Successfully assigned compute/eval-conflicts-rho020-r1-093-rwkwt to kind-worker3
0.5835,Event,ADDED,eval-conflicts-rho020-r1-093-rwkwt.18d467b37dca22b7,"reason=Pulled count=1 msg=Container image ""busybox:musl"" already present on machine"
0.5837,Event,ADDED,eval-conflicts-rho020-r1-093-rwkwt.18d467b37f5b53ea,reason=Created count=1 msg=Created container: task
0.5838,Event,ADDED,eval-conflicts-rho020-r1-093-rwkwt.18d467b383fb28bd,reason=Started count=1 msg=Started container task
0.5841,Event,ADDED,eval-conflicts-rho020-r1-093.18d467b326fa33f2,reason=SuccessfulCreate count=1 msg=Created pod: eval-conflicts-rho020-r1-093-rwkwt
0.5843,Event,ADDED,eval-conflicts-rho020-r1-093.18d467b6c4ef4f13,reason=Completed count=1 msg=Job completed
0.5844,Event,ADDED,eval-conflicts-rho020-r1-094-vr42b.18d467b3670eb4d6,"reason=FailedScheduling count=None msg=0/6 nodes are available: 1 c_wall violated: 2 conflicting context pair(s) with node memory, 5 node(s) had untolerated taint(s). no new claims to deallocate, preemption: 0/6 nodes are available: 1 No preemption victims found for incoming pod, 5 Preemption is not helpful for scheduling."
0.5846,Event,ADDED,eval-conflicts-rho020-r1-094-vr42b.18d467b36a92b4de,"reason=FailedScheduling count=None msg=0/6 nodes are available: 1 c_wall violated: 2 conflicting context pair(s) with node memory, 5 node(s) had untolerated taint(s). no new claims to deallocate, preemption: 0/6 nodes are available: 1 No preemption victims found for incoming pod, 5 Preemption is not helpful for scheduling."
0.5849,Event,ADDED,eval-conflicts-rho020-r1-094-vr42b.18d467b3bb6595be,reason=Scheduled count=None msg=Successfully assigned compute/eval-conflicts-rho020-r1-094-vr42b to kind-worker
0.5851,Event,ADDED,eval-conflicts-rho020-r1-094-vr42b.18d467b3d4becde2,"reason=Pulled count=1 msg=Container image ""busybox:musl"" already present on machine"
0.5852,Event,ADDED,eval-conflicts-rho020-r1-094-vr42b.18d467b3d6895375,reason=Created count=1 msg=Created container: task
0.5855,Event,ADDED,eval-conflicts-rho020-r1-094-vr42b.18d467b3d9895f63,reason=Started count=1 msg=Started container task
0.5856,Event,ADDED,eval-conflicts-rho020-r1-094.18d467b362631c06,reason=SuccessfulCreate count=1 msg=Created pod: eval-conflicts-rho020-r1-094-vr42b
0.5858,Event,ADDED,eval-conflicts-rho020-r1-094.18d467b7282ea44e,reason=Completed count=1 msg=Job completed
0.5859,Event,ADDED,eval-conflicts-rho020-r1-095-gfvdp.18d467b39e77108f,reason=Scheduled count=None msg=Successfully assigned compute/eval-conflicts-rho020-r1-095-gfvdp to kind-worker3
0.5861,Event,ADDED,eval-conflicts-rho020-r1-095-gfvdp.18d467b3b8a4d2e4,"reason=Pulled count=1 msg=Container image ""busybox:musl"" already present on machine"
0.5863,Event,ADDED,eval-conflicts-rho020-r1-095-gfvdp.18d467b3b9ceeb43,reason=Created count=1 msg=Created container: task
