t_recv,kind,type,name,detail
0.0232,Event,ADDED,eval-sanitize-3-r1-011-tjxzk.18d3d2697133fcf9,"reason=FailedScheduling count=None msg=0/6 nodes are available: 1 c_wall violated: 1 conflicting context pair(s) with node memory, 5 node(s) had untolerated taint(s). no new claims to deallocate, preemption: 0/6 nodes are available: 1 No preemption victims found for incoming pod, 5 Preemption is not helpful for scheduling."
0.0237,Event,ADDED,eval-sanitize-3-r1-012-rsrs2.18d3d269716929f4,"reason=FailedScheduling count=None msg=0/6 nodes are available: 1 c_wall violated: 1 conflicting context pair(s) with node memory, 5 node(s) had untolerated taint(s). no new claims to deallocate, preemption: 0/6 nodes are available: 1 No preemption victims found for incoming pod, 5 Preemption is not helpful for scheduling."
0.0239,Event,ADDED,eval-sanitize-3-r1-021-qx7fh.18d3d26b6037849c,"reason=FailedScheduling count=None msg=0/6 nodes are available: 1 c_wall violated: 1 conflicting context pair(s) with node memory, 5 node(s) had untolerated taint(s). no new claims to deallocate, preemption: 0/6 nodes are available: 1 No preemption victims found for incoming pod, 5 Preemption is not helpful for scheduling."
0.0241,Event,ADDED,eval-sanitize-3-r1-023-d979z.18d3d26c95b4199d,"reason=FailedScheduling count=None msg=0/6 nodes are available: 1 c_wall violated: 1 conflicting context pair(s) with node memory, 5 node(s) had untolerated taint(s). no new claims to deallocate, preemption: 0/6 nodes are available: 1 No preemption victims found for incoming pod, 5 Preemption is not helpful for scheduling."
0.0277,Node,ADDED,kind-control-plane,taints=1
0.0282,Event,ADDED,eval-sanitize-3-r1-023-d979z.18d3d26d07491213,"reason=FailedScheduling count=None msg=0/6 nodes are available: 1 c_wall violated: 1 conflicting context pair(s) with node memory, 1 c_wall violated: 2 conflicting context pair(s) with node memory, 4 node(s) had untolerated taint(s). no new claims to deallocate, preemption: 0/6 nodes are available: 2 No preemption victims found for incoming pod, 4 Preemption is not helpful for scheduling."
0.0284,Event,ADDED,eval-sanitize-3-r1-023-d979z.18d3d26d0cec5cdf,"reason=FailedScheduling count=None msg=0/6 nodes are available: 1 c_wall violated: 1 conflicting context pair(s) with node memory, 1 c_wall violated: 2 conflicting context pair(s) with node memory, 4 node(s) had untolerated taint(s). no new claims to deallocate, preemption: 0/6 nodes are available: 2 No preemption victims found for incoming pod, 4 Preemption is not helpful for scheduling."
0.0286,Event,ADDED,eval-sanitize-3-r1-023-d979z.18d3d26d42bcf201,"reason=FailedScheduling count=None msg=0/6 nodes are available: 1 c_wall violated: 1 conflicting context pair(s) with node memory, 5 node(s) had untolerated taint(s). no new claims to deallocate, preemption: 0/6 nodes are available: 1 No preemption victims found for incoming pod, 5 Preemption is not helpful for scheduling."
0.0288,Event,ADDED,eval-sanitize-3-r1-024-xqg87.18d3d26c95f27eb8,"reason=FailedScheduling count=None msg=0/6 nodes are available: 1 c_wall violated: 1 conflicting context pair(s) with node memory, 5 node(s) had untolerated taint(s). no new claims to deallocate, preemption: 0/6 nodes are available: 1 No preemption victims found for incoming pod, 5 Preemption is not helpful for scheduling."
0.029,Event,ADDED,eval-sanitize-3-r1-026-g4zsx.18d3d26c9623e1d2,"reason=FailedScheduling count=None msg=0/6 nodes are available: 1 c_wall violated: 1 conflicting context pair(s) with node memory, 5 node(s) had untolerated taint(s). no new claims to deallocate, preemption: 0/6 nodes are available: 1 No preemption victims found for incoming pod, 5 Preemption is not helpful for scheduling."
0.0292,Event,ADDED,eval-sanitize-3-r1-030-6rtz8.18d3d26d78779ecd,"reason=FailedScheduling count=None msg=0/6 nodes are available: 1 c_wall violated: 1 conflicting context pair(s) with node memory, 5 node(s) had untolerated taint(s). no new claims to deallocate, preemption: 0/6 nodes are available: 1 No preemption victims found for incoming pod, 5 Preemption is not helpful for scheduling."
0.0294,Event,ADDED,eval-sanitize-3-r1-032-d2qr4.18d3d26df008fffb,"reason=FailedScheduling count=None msg=0/6 nodes are available: 1 c_wall violated: 1 conflicting context pair(s) with node memory, 5 node(s) had untolerated taint(s). no new claims to deallocate, preemption: 0/6 nodes are available: 1 No preemption victims found for incoming pod, 5 Preemption is not helpful for scheduling."
0.0296,Event,ADDED,eval-sanitize-3-r1-033-grsj2.18d3d26e2ca1dff9,"reason=FailedScheduling count=None msg=0/6 nodes are available: 2 c_wall violated: 1 conflicting context pair(s) with node memory, 4 node(s) had untolerated taint(s). no new claims to deallocate, preemption: 0/6 nodes are available: 2 No preemption victims found for incoming pod, 4 Preemption is not helpful for scheduling."
0.0298,Event,ADDED,eval-sanitize-3-r1-036-tg5qj.18d3d26ede164bb6,"reason=FailedScheduling count=None msg=0/6 nodes are available: 1 c_wall violated: 1 conflicting context pair(s) with node memory, 5 node(s) had untolerated taint(s). no new claims to deallocate, preemption: 0/6 nodes are available: 1 No preemption victims found for incoming pod, 5 Preemption is not helpful for scheduling."
0.03,Event,ADDED,eval-sanitize-3-r1-037-tjlj8.18d3d27030aad843,"reason=FailedScheduling count=None msg=0/6 nodes are available: 1 c_wall violated: 1 conflicting context pair(s) with node memory, 5 node(s) had untolerated taint(s). no new claims to deallocate, preemption: 0/6 nodes are available: 1 No preemption victims found for incoming pod, 5 Preemption is not helpful for scheduling."
0.0302,Event,ADDED,eval-sanitize-3-r1-037-tjlj8.18d3d270b5c91c26,"reason=FailedScheduling count=None msg=0/6 nodes are available: 2 c_wall violated: 1 conflicting context pair(s) with node memory, 4 node(s) had untolerated taint(s). no new claims to deallocate, preemption: 0/6 nodes are available: 2 No preemption victims found for incoming pod, 4 Preemption is not helpful for scheduling."
0.0305,Event,ADDED,eval-sanitize-3-r1-037-tjlj8.18d3d270dc753828,"reason=FailedScheduling count=None msg=0/6 nodes are available: 1 c_wall violated: 1 conflicting context pair(s) with node memory, 5 node(s) had untolerated taint(s). no new claims to deallocate, preemption: 0/6 nodes are available: 1 No preemption victims found for incoming pod, 5 Preemption is not helpful for scheduling."
0.0309,Event,ADDED,eval-sanitize-3-r1-037-tjlj8.18d3d2713db36ed6,"reason=FailedScheduling count=None msg=0/6 nodes are available: 2 c_wall violated: 1 conflicting context pair(s) with node memory, 4 node(s) had untolerated taint(s). no new claims to deallocate, preemption: 0/6 nodes are available: 2 No preemption victims found for incoming pod, 4 Preemption is not helpful for scheduling."
0.0311,Event,ADDED,eval-sanitize-3-r1-037-tjlj8.18d3d27169b3dae4,"reason=FailedScheduling count=None msg=0/6 nodes are available: 1 c_wall violated: 1 conflicting context pair(s) with node memory, 5 node(s) had untolerated taint(s). no new claims to deallocate, preemption: 0/6 nodes are available: 1 No preemption victims found for incoming pod, 5 Preemption is not helpful for scheduling."
0.0326,Node,ADDED,kind-worker,taints=0
0.033,Event,ADDED,eval-sanitize-3-r1-041-t24pt.18d3d27030e5eb7e,"reason=FailedScheduling count=None msg=0/6 nodes are available: 1 c_wall violated: 2 conflicting context pair(s) with node memory, 5 node(s) had untolerated taint(s). no new claims to deallocate, preemption: 0/6 nodes are available: 1 No preemption victims found for incoming pod, 5 Preemption is not helpful for scheduling."
0.0332,Event,ADDED,eval-sanitize-3-r1-043-dx7ft.18d3d2707f710d9f,"reason=FailedScheduling count=None msg=0/6 nodes are available: 1 c_wall violated: 2 conflicting context pair(s) with node memory, 5 node(s) had untolerated taint(s). no new claims to deallocate, preemption: 0/6 nodes are available: 1 No preemption victims found for incoming pod, 5 Preemption is not helpful for scheduling."
0.0337,Event,ADDED,eval-sanitize-3-r1-044-5wvrz.18d3d270c09190f2,"reason=FailedScheduling count=None msg=0/6 nodes are available: 1 c_wall violated: 1 conflicting context pair(s) with node memory, 1 c_wall violated: 2 conflicting context pair(s) with node memory, 4 node(s) had untolerated taint(s). no new claims to deallocate, preemption: 0/6 nodes are available: 2 No preemption victims found for incoming pod, 4 Preemption is not helpful for scheduling."
0.0339,Event,ADDED,eval-sanitize-3-r1-044-5wvrz.18d3d270dc48d914,"reason=FailedScheduling count=None msg=0/6 nodes are available: 1 c_wall violated: 1 conflicting context pair(s) with node memory, 5 node(s) had untolerated taint(s). no new claims to deallocate, preemption: 0/6 nodes are available: 1 No preemption victims found for incoming pod, 5 Preemption is not helpful for scheduling."
0.0341,Event,ADDED,eval-sanitize-3-r1-045-9vs4b.18d3d270f6750e8e,"reason=FailedScheduling count=None msg=0/6 nodes are available: 1 c_wall violated: 1 conflicting context pair(s) with node memory, 5 node(s) had untolerated taint(s). no new claims to deallocate, preemption: 0/6 nodes are available: 1 No preemption victims found for incoming pod, 5 Preemption is not helpful for scheduling."
0.0354,Node,ADDED,kind-worker2,taints=0
0.0357,Event,ADDED,eval-sanitize-3-r1-046-46pb6.18d3d271321be2bb,"reason=FailedScheduling count=None msg=0/6 nodes are available: 1 c_wall violated: 1 conflicting context pair(s) with node memory, 5 node(s) had untolerated taint(s). no new claims to deallocate, preemption: 0/6 nodes are available: 1 No preemption victims found for incoming pod, 5 Preemption is not helpful for scheduling."
0.0359,Event,ADDED,eval-sanitize-3-r1-046-46pb6.18d3d2713dfcda16,"reason=FailedScheduling count=None msg=0/6 nodes are available: 2 c_wall violated: 1 conflicting context pair(s) with node memory, 4 node(s) had untolerated taint(s). no new claims to deallocate, preemption: 0/6 nodes are available: 2 No preemption victims found for incoming pod, 4 Preemption is not helpful for scheduling."
0.0361,Event,ADDED,eval-sanitize-3-r1-046-46pb6.18d3d27169df09e4,"reason=FailedScheduling count=None msg=0/6 nodes are available: 1 c_wall violated: 1 conflicting context pair(s) with node memory, 5 node(s) had untolerated taint(s). no new claims to deallocate, preemption: 0/6 nodes are available: 1 No preemption victims found for incoming pod, 5 Preemption is not helpful for scheduling."
0.0363,Event,ADDED,eval-sanitize-3-r1-047-7722w.18d3d2716dd70593,"reason=FailedScheduling count=None msg=0/6 nodes are available: 1 c_wall violated: 1 conflicting context pair(s) with node memory, 5 node(s) had untolerated taint(s). no new claims to deallocate, preemption: 0/6 nodes are available: 1 No preemption victims found for incoming pod, 5 Preemption is not helpful for scheduling."
0.0365,Event,ADDED,eval-sanitize-3-r1-047-7722w.18d3d271aac14dbb,"reason=FailedScheduling count=None msg=0/6 nodes are available: 1 c_wall violated: 2 conflicting context pair(s) with node memory, 5 node(s) had untolerated taint(s). no new claims to deallocate, preemption: 0/6 nodes are available: 1 No preemption victims found for incoming pod, 5 Preemption is not helpful for scheduling."
0.0367,Event,ADDED,eval-sanitize-3-r1-055-7lwd6.18d3d273cd461dfc,"reason=FailedScheduling count=None msg=0/6 nodes are available: 1 c_wall violated: 3 conflicting context pair(s) with node memory, 5 node(s) had untolerated taint(s). no new claims to deallocate, preemption: 0/6 nodes are available: 1 No preemption victims found for incoming pod, 5 Preemption is not helpful for scheduling."
0.0369,Event,ADDED,eval-sanitize-3-r1-056-txkm8.18d3d273cd71673c,"reason=FailedScheduling count=None msg=0/6 nodes are available: 1 c_wall violated: 3 conflicting context pair(s) with node memory, 5 node(s) had untolerated taint(s). no new claims to deallocate, preemption: 0/6 nodes are available: 1 No preemption victims found for incoming pod, 5 Preemption is not helpful for scheduling."
0.0371,Event,ADDED,eval-sanitize-3-r1-057-55lw7.18d3d273cd9debff,"reason=FailedScheduling count=None msg=0/6 nodes are available: 1 c_wall violated: 1 conflicting context pair(s) with node memory, 5 node(s) had untolerated taint(s). no new claims to deallocate, preemption: 0/6 nodes are available: 1 No preemption victims found for incoming pod, 5 Preemption is not helpful for scheduling."
0.0373,Event,ADDED,eval-sanitize-3-r1-059-kd5p6.18d3d27438f502a6,"reason=FailedScheduling count=None msg=0/6 nodes are available: 1 c_wall violated: 3 conflicting context pair(s) with node memory, 5 node(s) had untolerated taint(s). no new claims to deallocate, preemption: 0/6 nodes are available: 1 No preemption victims found for incoming pod, 5 Preemption is not helpful for scheduling."
0.0385,Node,ADDED,kind-worker3,taints=0
0.0389,Event,ADDED,eval-sanitize-3-r1-064-jhpsd.18d3d27562bbb6f5,"reason=FailedScheduling count=None msg=0/6 nodes are available: 1 c_wall violated: 1 conflicting context pair(s) with node memory, 5 node(s) had untolerated taint(s). no new claims to deallocate, preemption: 0/6 nodes are available: 1 No preemption victims found for incoming pod, 5 Preemption is not helpful for scheduling."
0.0391,Event,ADDED,eval-sanitize-3-r1-066-qmgrb.18d3d275da92567c,"reason=FailedScheduling count=None msg=0/6 nodes are available: 1 c_wall violated: 1 conflicting context pair(s) with node memory, 5 node(s) had untolerated taint(s). no new claims to deallocate, preemption: 0/6 nodes are available: 1 No preemption victims found for incoming pod, 5 Preemption is not helpful for scheduling."
0.0395,Event,ADDED,eval-sanitize-3-r1-067-lqnsb.18d3d276163322d0,"reason=FailedScheduling count=None msg=0/6 nodes are available: 1 c_wall violated: 2 conflicting context pair(s) with node memory, 5 node(s) had untolerated taint(s). no new claims to deallocate, preemption: 0/6 nodes are available: 1 No preemption victims found for incoming pod, 5 Preemption is not helpful for scheduling."
0.0398,Event,ADDED,eval-sanitize-3-r1-068-5n2cw.18d3d277811b407d,"reason=FailedScheduling count=None msg=0/6 nodes are available: 1 c_wall violated: 3 conflicting context pair(s) with node memory, 5 node(s) had untolerated taint(s). no new claims to deallocate, preemption: 0/6 nodes are available: 1 No preemption victims found for incoming pod, 5 Preemption is not helpful for scheduling."
0.0403,Event,ADDED,eval-sanitize-3-r1-069-z9wxc.18d3d2777be673e6,"reason=FailedScheduling count=None msg=0/6 nodes are available: 1 c_wall violated: 2 conflicting context pair(s) with node memory, 5 node(s) had untolerated taint(s). no new claims to deallocate, preemption: 0/6 nodes are available: 1 No preemption victims found for incoming pod, 5 Preemption is not helpful for scheduling."
0.0419,Node,ADDED,kind-worker4,taints=0
0.0422,Event,ADDED,eval-sanitize-3-r1-069-z9wxc.18d3d278232b9940,"reason=FailedScheduling count=None msg=0/6 nodes are available: 1 c_wall violated: 1 conflicting context pair(s) with node memory, 1 c_wall violated: 2 conflicting context pair(s) with node memory, 4 node(s) had untolerated taint(s). no new claims to deallocate, preemption: 0/6 nodes are available: 2 No preemption victims found for incoming pod, 4 Preemption is not helpful for scheduling."
0.0424,Event,ADDED,eval-sanitize-3-r1-069-z9wxc.18d3d27834e78c70,"reason=FailedScheduling count=None msg=0/6 nodes are available: 1 c_wall violated: 1 conflicting context pair(s) with node memory, 5 node(s) had untolerated taint(s). no new claims to deallocate, preemption: 0/6 nodes are available: 1 No preemption victims found for incoming pod, 5 Preemption is not helpful for scheduling."
0.0427,Event,ADDED,eval-sanitize-3-r1-071-x6gr5.18d3d2777c17f51f,"reason=FailedScheduling count=None msg=0/6 nodes are available: 1 c_wall violated: 2 conflicting context pair(s) with node memory, 5 node(s) had untolerated taint(s). no new claims to deallocate, preemption: 0/6 nodes are available: 1 No preemption victims found for incoming pod, 5 Preemption is not helpful for scheduling."
0.043,Event,ADDED,eval-sanitize-3-r1-071-x6gr5.18d3d27827ea40c0,"reason=FailedScheduling count=None msg=0/6 nodes are available: 1 c_wall violated: 1 conflicting context pair(s) with node memory, 1 c_wall violated: 2 conflicting context pair(s) with node memory, 4 node(s) had untolerated taint(s). no new claims to deallocate, preemption: 0/6 nodes are available: 2 No preemption victims found for incoming pod, 4 Preemption is not helpful for scheduling."
0.0432,Event,ADDED,eval-sanitize-3-r1-071-x6gr5.18d3d2783467a791,"reason=FailedScheduling count=None msg=0/6 nodes are available: 1 c_wall violated: 1 conflicting context pair(s) with node memory, 5 node(s) had untolerated taint(s). no new claims to deallocate, preemption: 0/6 nodes are available: 1 No preemption victims found for incoming pod, 5 Preemption is not helpful for scheduling."
0.0434,Event,ADDED,eval-sanitize-3-r1-072-gjkvb.18d3d2777c4ea613,"reason=FailedScheduling count=None msg=0/6 nodes are available: 1 c_wall violated: 2 conflicting context pair(s) with node memory, 5 node(s) had untolerated taint(s). no new claims to deallocate, preemption: 0/6 nodes are available: 1 No preemption victims found for incoming pod, 5 Preemption is not helpful for scheduling."
0.0436,Event,ADDED,eval-sanitize-3-r1-072-gjkvb.18d3d2782846d3f6,"reason=FailedScheduling count=None msg=0/6 nodes are available: 1 c_wall violated: 1 conflicting context pair(s) with node memory, 1 c_wall violated: 2 conflicting context pair(s) with node memory, 4 node(s) had untolerated taint(s). no new claims to deallocate, preemption: 0/6 nodes are available: 2 No preemption victims found for incoming pod, 4 Preemption is not helpful for scheduling."
0.0438,Event,ADDED,eval-sanitize-3-r1-072-gjkvb.18d3d27834940234,"reason=FailedScheduling count=None msg=0/6 nodes are available: 1 c_wall violated: 2 conflicting context pair(s) with node memory, 5 node(s) had untolerated taint(s). no new claims to deallocate, preemption: 0/6 nodes are available: 1 No preemption victims found for incoming pod, 5 Preemption is not helpful for scheduling."
0.0439,Event,ADDED,eval-sanitize-3-r1-072-gjkvb.18d3d2785249a100,"reason=FailedScheduling count=None msg=0/6 nodes are available: 2 c_wall violated: 2 conflicting context pair(s) with node memory, 4 node(s) had untolerated taint(s). no new claims to deallocate, preemption: 0/6 nodes are available: 2 No preemption victims found for incoming pod, 4 Preemption is not helpful for scheduling."
0.0451,Node,ADDED,kind-worker5,taints=0
0.0454,Event,ADDED,eval-sanitize-3-r1-072-gjkvb.18d3d27857f5dbaf,"reason=FailedScheduling count=None msg=0/6 nodes are available: 2 c_wall violated: 2 conflicting context pair(s) with node memory, 4 node(s) had untolerated taint(s). no new claims to deallocate, preemption: 0/6 nodes are available: 2 No preemption victims found for incoming pod, 4 Preemption is not helpful for scheduling."
0.0456,Event,ADDED,eval-sanitize-3-r1-073-dlw2g.18d3d27786f7b3d6,"reason=FailedScheduling count=None msg=0/6 nodes are available: 1 c_wall violated: 2 conflicting context pair(s) with node memory, 5 node(s) had untolerated taint(s). no new claims to deallocate, preemption: 0/6 nodes are available: 1 No preemption victims found for incoming pod, 5 Preemption is not helpful for scheduling."
0.046,TaskRequest,ADDED,eval-sanitize-3-r3-000,phase=None job=None
0.0463,Event,ADDED,eval-sanitize-3-r1-073-dlw2g.18d3d27822d6e202,"reason=FailedScheduling count=None msg=0/6 nodes are available: 1 c_wall violated: 1 conflicting context pair(s) with node memory, 1 c_wall violated: 2 conflicting context pair(s) with node memory, 4 node(s) had untolerated taint(s). no new claims to deallocate, preemption: 0/6 nodes are available: 2 No preemption victims found for incoming pod, 4 Preemption is not helpful for scheduling."
0.0465,Event,ADDED,eval-sanitize-3-r1-073-dlw2g.18d3d27834bec813,"reason=FailedScheduling count=None msg=0/6 nodes are available: 1 c_wall violated: 1 conflicting context pair(s) with node memory, 5 node(s) had untolerated taint(s). no new claims to deallocate, preemption: 0/6 nodes are available: 1 No preemption victims found for incoming pod, 5 Preemption is not helpful for scheduling."
0.0468,Event,ADDED,eval-sanitize-3-r1-075-fffjt.18d3d277f31e61ab,"reason=FailedScheduling count=None msg=0/6 nodes are available: 1 c_wall violated: 1 conflicting context pair(s) with node memory, 5 node(s) had untolerated taint(s). no new claims to deallocate, preemption: 0/6 nodes are available: 1 No preemption victims found for incoming pod, 5 Preemption is not helpful for scheduling."
0.0471,Event,ADDED,eval-sanitize-3-r1-080-lkw4s.18d3d2791cb4d75b,"reason=FailedScheduling count=None msg=0/6 nodes are available: 1 c_wall violated: 1 conflicting context pair(s) with node memory, 5 node(s) had untolerated taint(s). no new claims to deallocate, preemption: 0/6 nodes are available: 1 No preemption victims found for incoming pod, 5 Preemption is not helpful for scheduling."
0.0473,Event,ADDED,eval-sanitize-3-r1-081-btlgw.18d3d279589689de,"reason=FailedScheduling count=None msg=0/6 nodes are available: 1 c_wall violated: 1 conflicting context pair(s) with node memory, 5 node(s) had untolerated taint(s). no new claims to deallocate, preemption: 0/6 nodes are available: 1 No preemption victims found for incoming pod, 5 Preemption is not helpful for scheduling."
0.0475,Event,ADDED,eval-sanitize-3-r1-082-w92n4.18d3d279956615b3,"reason=FailedScheduling count=None msg=0/6 nodes are available: 1 c_wall violated: 1 conflicting context pair(s) with node memory, 5 node(s) had untolerated taint(s). no new claims to deallocate, preemption: 0/6 nodes are available: 1 No preemption victims found for incoming pod, 5 Preemption is not helpful for scheduling."
0.0477,Event,ADDED,eval-sanitize-3-r1-085-sdskd.18d3d27b54665f01,"reason=FailedScheduling count=None msg=0/6 nodes are available: 1 c_wall violated: 3 conflicting context pair(s) with node memory, 5 node(s) had untolerated taint(s). no new claims to deallocate, preemption: 0/6 nodes are available: 1 No preemption victims found for incoming pod, 5 Preemption is not helpful for scheduling."
0.0479,Event,ADDED,eval-sanitize-3-r1-086-rv9m8.18d3d27b5653f527,"reason=FailedScheduling count=None msg=0/6 nodes are available: 1 c_wall violated: 2 conflicting context pair(s) with node memory, 5 node(s) had untolerated taint(s). no new claims to deallocate, preemption: 0/6 nodes are available: 1 No preemption victims found for incoming pod, 5 Preemption is not helpful for scheduling."
0.0481,Event,ADDED,eval-sanitize-3-r1-086-rv9m8.18d3d27bfa91f290,"reason=FailedScheduling count=None msg=0/6 nodes are available: 1 c_wall violated: 2 conflicting context pair(s) with node memory, 1 c_wall violated: 3 conflicting context pair(s) with node memory, 4 node(s) had untolerated taint(s). no new claims to deallocate, preemption: 0/6 nodes are available: 2 No preemption victims found for incoming pod, 4 Preemption is not helpful for scheduling."
0.0484,Event,ADDED,eval-sanitize-3-r1-086-rv9m8.18d3d27c076e44fd,"reason=FailedScheduling count=None msg=0/6 nodes are available: 1 c_wall violated: 3 conflicting context pair(s) with node memory, 5 node(s) had untolerated taint(s). no new claims to deallocate, preemption: 0/6 nodes are available: 1 No preemption victims found for incoming pod, 5 Preemption is not helpful for scheduling."
0.0487,Event,ADDED,eval-sanitize-3-r1-086-rv9m8.18d3d27c3bfab04d,"reason=FailedScheduling count=None msg=0/6 nodes are available: 1 c_wall violated: 1 conflicting context pair(s) with node memory, 1 c_wall violated: 3 conflicting context pair(s) with node memory, 4 node(s) had untolerated taint(s). no new claims to deallocate, preemption: 0/6 nodes are available: 2 No preemption victims found for incoming pod, 4 Preemption is not helpful for scheduling."
0.049,Event,ADDED,eval-sanitize-3-r1-086-rv9m8.18d3d27c64ee584f,"reason=FailedScheduling count=None msg=0/6 nodes are available: 1 c_wall violated: 2 conflicting context pair(s) with node memory, 1 c_wall violated: 3 conflicting context pair(s) with node memory, 4 node(s) had untolerated taint(s). no new claims to deallocate, preemption: 0/6 nodes are available: 2 No preemption victims found for incoming pod, 4 Preemption is not helpful for scheduling."
0.0492,Event,ADDED,eval-sanitize-3-r1-086-rv9m8.18d3d27cbf4f8ae5,"reason=FailedScheduling count=None msg=0/6 nodes are available: 1 c_wall violated: 2 conflicting context pair(s) with node memory, 5 node(s) had untolerated taint(s). no new claims to deallocate, preemption: 0/6 nodes are available: 1 No preemption victims found for incoming pod, 5 Preemption is not helpful for scheduling."
0.0494,Event,ADDED,eval-sanitize-3-r1-087-97cqb.18d3d27b54083f51,"reason=FailedScheduling count=None msg=0/6 nodes are available: 1 c_wall violated: 2 conflicting context pair(s) with node memory, 5 node(s) had untolerated taint(s). no new claims to deallocate, preemption: 0/6 nodes are available: 1 No preemption victims found for incoming pod, 5 Preemption is not helpful for scheduling."
0.0497,Event,ADDED,eval-sanitize-3-r1-089-fmlmf.18d3d27b543bd3c5,"reason=FailedScheduling count=None msg=0/6 nodes are available: 1 c_wall violated: 1 conflicting context pair(s) with node memory, 5 node(s) had untolerated taint(s). no new claims to deallocate, preemption: 0/6 nodes are available: 1 No preemption victims found for incoming pod, 5 Preemption is not helpful for scheduling."
0.0499,Event,ADDED,eval-sanitize-3-r1-089-fmlmf.18d3d27bfa51b068,"reason=FailedScheduling count=None msg=0/6 nodes are available: 1 c_wall violated: 1 conflicting context pair(s) with node memory, 1 c_wall violated: 2 conflicting context pair(s) with node memory, 4 node(s) had untolerated taint(s). no new claims to deallocate, preemption: 0/6 nodes are available: 2 No preemption victims found for incoming pod, 4 Preemption is not helpful for scheduling."
0.0501,Event,ADDED,eval-sanitize-3-r1-089-fmlmf.18d3d27c07422efc,"reason=FailedScheduling count=None msg=0/6 nodes are available: 1 c_wall violated: 2 conflicting context pair(s) with node memory, 5 node(s) had untolerated taint(s). no new claims to deallocate, preemption: 0/6 nodes are available: 1 No preemption victims found for incoming pod, 5 Preemption is not helpful for scheduling."
0.0505,Event,ADDED,eval-sanitize-3-r1-090-qxp85.18d3d27b70839b2e,"reason=FailedScheduling count=None msg=0/6 nodes are available: 1 c_wall violated: 2 conflicting context pair(s) with node memory, 5 node(s) had untolerated taint(s). no new claims to deallocate, preemption: 0/6 nodes are available: 1 No preemption victims found for incoming pod, 5 Preemption is not helpful for scheduling."
0.0508,Event,ADDED,eval-sanitize-3-r1-091-5mc4w.18d3d27bac48ce9a,"reason=FailedScheduling count=None msg=0/6 nodes are available: 1 c_wall violated: 3 conflicting context pair(s) with node memory, 5 node(s) had untolerated taint(s). no new claims to deallocate, preemption: 0/6 nodes are available: 1 No preemption victims found for incoming pod, 5 Preemption is not helpful for scheduling."
0.051,Event,ADDED,eval-sanitize-3-r1-093-hv55n.18d3d27c241a89df,"reason=FailedScheduling count=None msg=0/6 nodes are available: 1 c_wall violated: 3 conflicting context pair(s) with node memory, 5 node(s) had untolerated taint(s). no new claims to deallocate, preemption: 0/6 nodes are available: 1 No preemption victims found for incoming pod, 5 Preemption is not helpful for scheduling."
0.0514,Event,ADDED,eval-sanitize-3-r1-093-hv55n.18d3d27c40ca68e1,"reason=FailedScheduling count=None msg=0/6 nodes are available: 1 c_wall violated: 1 conflicting context pair(s) with node memory, 1 c_wall violated: 3 conflicting context pair(s) with node memory, 4 node(s) had untolerated taint(s). no new claims to deallocate, preemption: 0/6 nodes are available: 2 No preemption victims found for incoming pod, 4 Preemption is not helpful for scheduling."
0.0516,Event,ADDED,eval-sanitize-3-r1-093-hv55n.18d3d27cbf1a9a77,"reason=FailedScheduling count=None msg=0/6 nodes are available: 1 c_wall violated: 1 conflicting context pair(s) with node memory, 5 node(s) had untolerated taint(s). no new claims to deallocate, preemption: 0/6 nodes are available: 1 No preemption victims found for incoming pod, 5 Preemption is not helpful for scheduling."
0.0518,Event,ADDED,eval-sanitize-3-r1-093-hv55n.18d3d27cdc0863ae,"reason=FailedScheduling count=None msg=0/6 nodes are available: 2 c_wall violated: 1 conflicting context pair(s) with node memory, 4 node(s) had untolerated taint(s). no new claims to deallocate, preemption: 0/6 nodes are available: 2 No preemption victims found for incoming pod, 4 Preemption is not helpful for scheduling."
0.0519,TaskRequest,MODIFIED,eval-sanitize-3-r3-000,phase=Pending job=None
0.0523,Event,ADDED,eval-sanitize-3-r1-093-hv55n.18d3d27cf5ddba09,"reason=FailedScheduling count=None msg=0/6 nodes are available: 1 c_wall violated: 1 conflicting context pair(s) with node memory, 5 node(s) had untolerated taint(s). no new claims to deallocate, preemption: 0/6 nodes are available: 1 No preemption victims found for incoming pod, 5 Preemption is not helpful for scheduling."
0.0525,Event,ADDED,eval-sanitize-3-r1-096-chwwn.18d3d27cd6a9f29d,"reason=FailedScheduling count=None msg=0/6 nodes are available: 1 c_wall violated: 1 conflicting context pair(s) with node memory, 5 node(s) had untolerated taint(s). no new claims to deallocate, preemption: 0/6 nodes are available: 1 No preemption victims found for incoming pod, 5 Preemption is not helpful for scheduling."
0.0529,Event,ADDED,eval-sanitize-3-r1-096-chwwn.18d3d27cdc588bd6,"reason=FailedScheduling count=None msg=0/6 nodes are available: 2 c_wall violated: 1 conflicting context pair(s) with node memory, 4 node(s) had untolerated taint(s). no new claims to deallocate, preemption: 0/6 nodes are available: 2 No preemption victims found for incoming pod, 4 Preemption is not helpful for scheduling."
0.0531,Event,ADDED,eval-sanitize-3-r1-096-chwwn.18d3d27cf608522d,"reason=FailedScheduling count=None msg=0/6 nodes are available: 1 c_wall violated: 1 conflicting context pair(s) with node memory, 5 node(s) had untolerated taint(s). no new claims to deallocate, preemption: 0/6 nodes are available: 1 No preemption victims found for incoming pod, 5 Preemption is not helpful for scheduling."
0.0533,Event,ADDED,eval-sanitize-3-r1-096-chwwn.18d3d27d71aef7e9,"reason=FailedScheduling count=None msg=0/6 nodes are available: 2 c_wall violated: 1 conflicting context pair(s) with node memory, 4 node(s) had untolerated taint(s). no new claims to deallocate, preemption: 0/6 nodes are available: 2 No preemption victims found for incoming pod, 4 Preemption is not helpful for scheduling."
0.0535,Event,ADDED,eval-sanitize-3-r1-096-chwwn.18d3d27d8e9bc951,"reason=FailedScheduling count=None msg=0/6 nodes are available: 1 c_wall violated: 1 conflicting context pair(s) with node memory, 1 c_wall violated: 2 conflicting context pair(s) with node memory, 4 node(s) had untolerated taint(s). no new claims to deallocate, preemption: 0/6 nodes are available: 2 No preemption victims found for incoming pod, 4 Preemption is not helpful for scheduling."
0.0537,Event,ADDED,eval-sanitize-3-r1-096-chwwn.18d3d27d9284fb4f,"reason=FailedScheduling count=None msg=0/6 nodes are available: 1 c_wall violated: 1 conflicting context pair(s) with node memory, 5 node(s) had untolerated taint(s). no new claims to deallocate, preemption: 0/6 nodes are available: 1 No preemption victims found for incoming pod, 5 Preemption is not helpful for scheduling."
0.0539,Event,ADDED,eval-sanitize-3-r1-097-dxvqj.18d3d27d12603368,"reason=FailedScheduling count=None msg=0/6 nodes are available: 1 c_wall violated: 1 conflicting context pair(s) with node memory, 5 node(s) had untolerated taint(s). no new claims to deallocate, preemption: 0/6 nodes are available: 1 No preemption victims found for incoming pod, 5 Preemption is not helpful for scheduling."
0.0541,Event,ADDED,eval-sanitize-3-r1-098-nv54x.18d3d27d4df49446,"reason=FailedScheduling count=None msg=0/6 nodes are available: 1 c_wall violated: 1 conflicting context pair(s) with node memory, 5 node(s) had untolerated taint(s). no new claims to deallocate, preemption: 0/6 nodes are available: 1 No preemption victims found for incoming pod, 5 Preemption is not helpful for scheduling."
0.0705,Job,ADDED,eval-sanitize-3-r3-000,
0.0747,TaskRequest,MODIFIED,eval-sanitize-3-r3-000,phase=Scheduled job=None
0.0818,Job,MODIFIED,eval-sanitize-3-r3-000,
0.0846,TaskRequest,MODIFIED,eval-sanitize-3-r3-000,phase=Scheduled job=None
0.1277,Pod,ADDED,eval-sanitize-3-r3-000-jfrb4,phase=Pending node=None
0.135,Event,ADDED,eval-sanitize-3-r3-000.18d3d2f4cf762988,reason=SuccessfulCreate count=1 msg=Created pod: eval-sanitize-3-r3-000-jfrb4
0.1412,Pod,MODIFIED,eval-sanitize-3-r3-000-jfrb4,phase=Pending node=kind-worker2
0.1444,Event,ADDED,eval-sanitize-3-r3-000-jfrb4.18d3d2f4d0496f31,reason=Scheduled count=None msg=Successfully assigned compute/eval-sanitize-3-r3-000-jfrb4 to kind-worker2
0.1522,Node,MODIFIED,kind-worker2,taints=0
0.1539,Pod,MODIFIED,eval-sanitize-3-r3-000-jfrb4,phase=Pending node=kind-worker2
0.1708,Node,MODIFIED,kind-worker2,taints=0
0.5694,Event,ADDED,eval-sanitize-3-r3-000-jfrb4.18d3d2f4e986d180,"reason=Pulled count=1 msg=Container image ""busybox:musl"" already present on machine"
0.5914,Event,ADDED,eval-sanitize-3-r3-000-jfrb4.18d3d2f4ead23a6e,reason=Created count=1 msg=Created container: task
0.6275,Event,ADDED,eval-sanitize-3-r3-000-jfrb4.18d3d2f4ed02e11a,reason=Started count=1 msg=Started container task
1.0154,TaskRequest,ADDED,eval-sanitize-3-r3-001,phase=None job=None
1.0198,TaskRequest,MODIFIED,eval-sanitize-3-r3-001,phase=Pending job=None
1.0371,Job,ADDED,eval-sanitize-3-r3-001,
1.0428,Pod,ADDED,eval-sanitize-3-r3-001-x9hkn,phase=Pending node=None
1.044,TaskRequest,MODIFIED,eval-sanitize-3-r3-001,phase=Scheduled job=None
1.0474,Job,MODIFIED,eval-sanitize-3-r3-001,
1.0488,Event,ADDED,eval-sanitize-3-r3-001.18d3d2f505f91a5f,reason=SuccessfulCreate count=1 msg=Created pod: eval-sanitize-3-r3-001-x9hkn
1.0521,TaskRequest,MODIFIED,eval-sanitize-3-r3-001,phase=Scheduled job=None
1.0557,Job,MODIFIED,eval-sanitize-3-r3-001,
1.0641,Pod,MODIFIED,eval-sanitize-3-r3-001-x9hkn,phase=Pending node=kind-worker
1.0661,Job,MODIFIED,eval-sanitize-3-r3-001,
1.0664,Event,ADDED,eval-sanitize-3-r3-001-x9hkn.18d3d2f507276e8e,reason=Scheduled count=None msg=Successfully assigned compute/eval-sanitize-3-r3-001-x9hkn to kind-worker
1.076,Node,MODIFIED,kind-worker,taints=0
1.0782,Pod,MODIFIED,eval-sanitize-3-r3-001-x9hkn,phase=Pending node=kind-worker
1.0873,Job,MODIFIED,eval-sanitize-3-r3-000,
1.0902,Node,MODIFIED,kind-worker,taints=0
1.0975,Job,MODIFIED,eval-sanitize-3-r3-000,
1.1726,Pod,MODIFIED,eval-sanitize-3-r3-000-jfrb4,phase=Running node=kind-worker2
1.4748,Event,ADDED,eval-sanitize-3-r3-001-x9hkn.18d3d2f51f786474,"reason=Pulled count=1 msg=Container image ""busybox:musl"" already present on machine"
1.4941,Event,ADDED,eval-sanitize-3-r3-001-x9hkn.18d3d2f520a50538,reason=Created count=1 msg=Created container: task
1.5597,Event,ADDED,eval-sanitize-3-r3-001-x9hkn.18d3d2f5248b8af9,reason=Started count=1 msg=Started container task
1.7589,Node,MODIFIED,kind-worker2,taints=1
1.7615,Node,MODIFIED,kind-worker,taints=1
1.7628,Pod,MODIFIED,eval-sanitize-3-r3-001-x9hkn,phase=Running node=kind-worker
1.831,Node,MODIFIED,kind-worker2,taints=1
1.8362,Node,MODIFIED,kind-worker,taints=1
2.0128,TaskRequest,ADDED,eval-sanitize-3-r3-002,phase=None job=None
2.018,TaskRequest,MODIFIED,eval-sanitize-3-r3-002,phase=Pending job=None
2.033,Job,ADDED,eval-sanitize-3-r3-002,
2.0391,TaskRequest,MODIFIED,eval-sanitize-3-r3-002,phase=Scheduled job=None
2.0419,Pod,ADDED,eval-sanitize-3-r3-002-7fs7w,phase=Pending node=None
2.043,Job,MODIFIED,eval-sanitize-3-r3-002,
2.0455,Event,ADDED,eval-sanitize-3-r3-002.18d3d2f54188efb1,reason=SuccessfulCreate count=1 msg=Created pod: eval-sanitize-3-r3-002-7fs7w
2.0484,Job,MODIFIED,eval-sanitize-3-r3-001,
2.0515,Pod,MODIFIED,eval-sanitize-3-r3-002-7fs7w,phase=Pending node=kind-worker4
2.0563,Event,ADDED,eval-sanitize-3-r3-002-7fs7w.18d3d2f5421fb91b,reason=Scheduled count=None msg=Successfully assigned compute/eval-sanitize-3-r3-002-7fs7w to kind-worker4
2.06,Job,MODIFIED,eval-sanitize-3-r3-001,
2.0632,Pod,MODIFIED,eval-sanitize-3-r3-002-7fs7w,phase=Pending node=kind-worker4
2.0638,TaskRequest,MODIFIED,eval-sanitize-3-r3-002,phase=Scheduled job=None
2.0652,Node,MODIFIED,kind-worker4,taints=0
2.093,Job,MODIFIED,eval-sanitize-3-r3-000,
2.1014,Job,MODIFIED,eval-sanitize-3-r3-000,
2.2315,Node,MODIFIED,kind-worker4,taints=0
2.4763,Event,ADDED,eval-sanitize-3-r3-002-7fs7w.18d3d2f55b2b4298,"reason=Pulled count=1 msg=Container image ""busybox:musl"" already present on machine"
2.4969,Event,ADDED,eval-sanitize-3-r3-002-7fs7w.18d3d2f55c6be66a,reason=Created count=1 msg=Created container: task
2.5303,Event,ADDED,eval-sanitize-3-r3-002-7fs7w.18d3d2f55e6b47d1,reason=Started count=1 msg=Started container task
3.012,TaskRequest,ADDED,eval-sanitize-3-r3-003,phase=None job=None
3.0159,TaskRequest,MODIFIED,eval-sanitize-3-r3-003,phase=Pending job=None
3.0313,Job,ADDED,eval-sanitize-3-r3-003,
3.0358,TaskRequest,MODIFIED,eval-sanitize-3-r3-003,phase=Scheduled job=None
3.0392,Pod,ADDED,eval-sanitize-3-r3-003-vp5rl,phase=Pending node=None
3.0421,Job,MODIFIED,eval-sanitize-3-r3-003,
3.0457,Event,ADDED,eval-sanitize-3-r3-003.18d3d2f57cf8678e,reason=SuccessfulCreate count=1 msg=Created pod: eval-sanitize-3-r3-003-vp5rl
3.0459,TaskRequest,MODIFIED,eval-sanitize-3-r3-003,phase=Scheduled job=None
3.047,Job,MODIFIED,eval-sanitize-3-r3-002,
3.0516,Pod,MODIFIED,eval-sanitize-3-r3-003-vp5rl,phase=Pending node=kind-worker5
3.0576,Job,MODIFIED,eval-sanitize-3-r3-002,
3.0579,Event,ADDED,eval-sanitize-3-r3-003-vp5rl.18d3d2f57db4a590,reason=Scheduled count=None msg=Successfully assigned compute/eval-sanitize-3-r3-003-vp5rl to kind-worker5
3.0621,Node,MODIFIED,kind-worker5,taints=0
3.0636,Pod,MODIFIED,eval-sanitize-3-r3-003-vp5rl,phase=Pending node=kind-worker5
3.0723,Node,MODIFIED,kind-worker5,taints=0
3.325,Pod,MODIFIED,eval-sanitize-3-r3-002-7fs7w,phase=Running node=kind-worker4
3.4794,Event,ADDED,eval-sanitize-3-r3-003-vp5rl.18d3d2f596f85f29,"reason=Pulled count=1 msg=Container image ""busybox:musl"" already present on machine"
3.5019,Event,ADDED,eval-sanitize-3-r3-003-vp5rl.18d3d2f5983e98ac,reason=Created count=1 msg=Created container: task
3.5734,Event,ADDED,eval-sanitize-3-r3-003-vp5rl.18d3d2f59c7ff0b3,reason=Started count=1 msg=Started container task
3.8021,Node,MODIFIED,kind-worker2,taints=1
3.8173,Node,MODIFIED,kind-worker4,taints=1
3.8295,Node,MODIFIED,kind-worker4,taints=1
4.0128,TaskRequest,ADDED,eval-sanitize-3-r3-004,phase=None job=None
4.0171,TaskRequest,MODIFIED,eval-sanitize-3-r3-004,phase=Pending job=None
4.0343,Job,ADDED,eval-sanitize-3-r3-004,
4.041,Pod,ADDED,eval-sanitize-3-r3-004-rz87f,phase=Pending node=None
4.0412,TaskRequest,MODIFIED,eval-sanitize-3-r3-004,phase=Scheduled job=None
4.0444,Job,MODIFIED,eval-sanitize-3-r3-004,
4.0457,Event,ADDED,eval-sanitize-3-r3-004.18d3d2f5b8b09b59,reason=SuccessfulCreate count=1 msg=Created pod: eval-sanitize-3-r3-004-rz87f
4.0467,Job,MODIFIED,eval-sanitize-3-r3-003,
4.0486,Pod,MODIFIED,eval-sanitize-3-r3-004-rz87f,phase=Pending node=kind-worker3
4.0499,TaskRequest,MODIFIED,eval-sanitize-3-r3-004,phase=Scheduled job=None
4.0548,Job,MODIFIED,eval-sanitize-3-r3-002,
4.0568,Event,ADDED,eval-sanitize-3-r3-004-rz87f.18d3d2f5b9274309,reason=Scheduled count=None msg=Successfully assigned compute/eval-sanitize-3-r3-004-rz87f to kind-worker3
4.0577,Job,MODIFIED,eval-sanitize-3-r3-003,
4.0604,Node,MODIFIED,kind-worker3,taints=0
4.0625,Pod,MODIFIED,eval-sanitize-3-r3-004-rz87f,phase=Pending node=kind-worker3
4.0639,Job,MODIFIED,eval-sanitize-3-r3-002,
4.0709,Node,MODIFIED,kind-worker3,taints=0
4.3847,Pod,MODIFIED,eval-sanitize-3-r3-003-vp5rl,phase=Running node=kind-worker5
4.4997,Event,ADDED,eval-sanitize-3-r3-004-rz87f.18d3d2f5d3c66f0e,"reason=Pulled count=1 msg=Container image ""busybox:musl"" already present on machine"
4.5183,Event,ADDED,eval-sanitize-3-r3-004-rz87f.18d3d2f5d4e9efe4,reason=Created count=1 msg=Created container: task
4.5526,Event,ADDED,eval-sanitize-3-r3-004-rz87f.18d3d2f5d6f98fa7,reason=Started count=1 msg=Started container task
5.0076,TaskRequest,ADDED,eval-sanitize-3-r3-005,phase=None job=None
5.0133,TaskRequest,MODIFIED,eval-sanitize-3-r3-005,phase=Pending job=None
5.0286,Job,ADDED,eval-sanitize-3-r3-005,
5.0356,Pod,ADDED,eval-sanitize-3-r3-005-zlzdh,phase=Pending node=None
5.0357,TaskRequest,MODIFIED,eval-sanitize-3-r3-005,phase=Scheduled job=None
5.0381,Job,MODIFIED,eval-sanitize-3-r3-005,
5.0406,Event,ADDED,eval-sanitize-3-r3-005.18d3d2f5f3f54c84,reason=SuccessfulCreate count=1 msg=Created pod: eval-sanitize-3-r3-005-zlzdh
5.0429,TaskRequest,MODIFIED,eval-sanitize-3-r3-005,phase=Scheduled job=None
5.0458,Job,MODIFIED,eval-sanitize-3-r3-004,
5.0504,Pod,MODIFIED,eval-sanitize-3-r3-005-zlzdh,phase=Pending node=kind-worker5
5.0535,Job,MODIFIED,eval-sanitize-3-r3-003,
5.0571,Job,MODIFIED,eval-sanitize-3-r3-004,
5.0576,Event,ADDED,eval-sanitize-3-r3-005-zlzdh.18d3d2f5f4db0e4d,reason=Scheduled count=None msg=Successfully assigned compute/eval-sanitize-3-r3-005-zlzdh to kind-worker5
5.0626,Pod,MODIFIED,eval-sanitize-3-r3-005-zlzdh,phase=Pending node=kind-worker5
5.065,Job,MODIFIED,eval-sanitize-3-r3-003,
5.1406,Node,MODIFIED,kind-worker5,taints=1
5.2365,Node,MODIFIED,kind-worker5,taints=1
5.3402,Pod,MODIFIED,eval-sanitize-3-r3-004-rz87f,phase=Running node=kind-worker3
5.489,Event,ADDED,eval-sanitize-3-r3-005-zlzdh.18d3d2f60ea6ac13,"reason=Pulled count=1 msg=Container image ""busybox:musl"" already present on machine"
5.5065,Event,ADDED,eval-sanitize-3-r3-005-zlzdh.18d3d2f60fd0455a,reason=Created count=1 msg=Created container: task
5.5416,Event,ADDED,eval-sanitize-3-r3-005-zlzdh.18d3d2f611e63e84,reason=Started count=1 msg=Started container task
5.99,Node,MODIFIED,kind-worker3,taints=1
6.0053,Node,MODIFIED,kind-worker3,taints=1
6.0119,TaskRequest,ADDED,eval-sanitize-3-r3-006,phase=None job=None
6.0157,TaskRequest,MODIFIED,eval-sanitize-3-r3-006,phase=Pending job=None
6.0309,Job,ADDED,eval-sanitize-3-r3-006,
6.035,TaskRequest,MODIFIED,eval-sanitize-3-r3-006,phase=Scheduled job=None
6.0389,Pod,ADDED,eval-sanitize-3-r3-006-bjfc4,phase=Pending node=None
6.0417,Job,MODIFIED,eval-sanitize-3-r3-005,
6.0428,Job,MODIFIED,eval-sanitize-3-r3-006,
6.0433,TaskRequest,MODIFIED,eval-sanitize-3-r3-006,phase=Scheduled job=None
6.0452,Event,ADDED,eval-sanitize-3-r3-006.18d3d2f62fc0ed50,reason=SuccessfulCreate count=1 msg=Created pod: eval-sanitize-3-r3-006-bjfc4
6.0455,Event,ADDED,eval-sanitize-3-r3-006-bjfc4.18d3d2f62fcdb556,"reason=FailedScheduling count=None msg=0/6 nodes are available: 6 node(s) had untolerated taint(s). no new claims to deallocate, preemption: 0/6 nodes are available: 6 Preemption is not helpful for scheduling."
6.0466,Pod,MODIFIED,eval-sanitize-3-r3-006-bjfc4,phase=Pending node=None
6.0502,Job,MODIFIED,eval-sanitize-3-r3-004,
6.0524,Job,MODIFIED,eval-sanitize-3-r3-005,
6.0584,Job,MODIFIED,eval-sanitize-3-r3-004,
6.3889,Pod,MODIFIED,eval-sanitize-3-r3-005-zlzdh,phase=Running node=kind-worker5
7.0122,TaskRequest,ADDED,eval-sanitize-3-r3-007,phase=None job=None
7.0168,TaskRequest,MODIFIED,eval-sanitize-3-r3-007,phase=Pending job=None
7.0301,Job,ADDED,eval-sanitize-3-r3-007,
7.0353,TaskRequest,MODIFIED,eval-sanitize-3-r3-007,phase=Scheduled job=None
7.0386,Pod,ADDED,eval-sanitize-3-r3-007-mt7xl,phase=Pending node=None
7.0415,Job,MODIFIED,eval-sanitize-3-r3-007,
7.0453,Event,ADDED,eval-sanitize-3-r3-007.18d3d2f66b62cb91,reason=SuccessfulCreate count=1 msg=Created pod: eval-sanitize-3-r3-007-mt7xl
7.0456,Event,ADDED,eval-sanitize-3-r3-007-mt7xl.18d3d2f66b6b6024,"reason=FailedScheduling count=None msg=0/6 nodes are available: 6 node(s) had untolerated taint(s). no new claims to deallocate, preemption: 0/6 nodes are available: 6 Preemption is not helpful for scheduling."
7.0465,Job,MODIFIED,eval-sanitize-3-r3-006,
7.0467,TaskRequest,MODIFIED,eval-sanitize-3-r3-007,phase=Scheduled job=None
7.0475,Pod,MODIFIED,eval-sanitize-3-r3-007-mt7xl,phase=Pending node=None
7.0485,Job,MODIFIED,eval-sanitize-3-r3-005,
7.0567,Job,MODIFIED,eval-sanitize-3-r3-006,
7.0585,Job,MODIFIED,eval-sanitize-3-r3-005,
8.0069,TaskRequest,ADDED,eval-sanitize-3-r3-008,phase=None job=None
8.0106,TaskRequest,MODIFIED,eval-sanitize-3-r3-008,phase=Pending job=None
8.0264,Job,ADDED,eval-sanitize-3-r3-008,
8.0339,Pod,ADDED,eval-sanitize-3-r3-008-jtwkx,phase=Pending node=None
8.0346,TaskRequest,MODIFIED,eval-sanitize-3-r3-008,phase=Scheduled job=None
8.0356,Job,MODIFIED,eval-sanitize-3-r3-008,
8.0398,Event,ADDED,eval-sanitize-3-r3-008.18d3d2f6a6ab0336,reason=SuccessfulCreate count=1 msg=Created pod: eval-sanitize-3-r3-008-jtwkx
8.0401,Event,ADDED,eval-sanitize-3-r3-008-jtwkx.18d3d2f6a6b5fced,"reason=FailedScheduling count=None msg=0/6 nodes are available: 6 node(s) had untolerated taint(s). no new claims to deallocate, preemption: 0/6 nodes are available: 6 Preemption is not helpful for scheduling."
8.0412,Pod,MODIFIED,eval-sanitize-3-r3-008-jtwkx,phase=Pending node=None
8.0439,Job,MODIFIED,eval-sanitize-3-r3-007,
8.044,TaskRequest,MODIFIED,eval-sanitize-3-r3-008,phase=Scheduled job=None
8.0534,Job,MODIFIED,eval-sanitize-3-r3-007,
9.0074,TaskRequest,ADDED,eval-sanitize-3-r3-009,phase=None job=None
9.011,TaskRequest,MODIFIED,eval-sanitize-3-r3-009,phase=Pending job=None
9.0286,Job,ADDED,eval-sanitize-3-r3-009,
9.0385,Pod,ADDED,eval-sanitize-3-r3-009-97txr,phase=Pending node=None
9.0416,TaskRequest,MODIFIED,eval-sanitize-3-r3-009,phase=Scheduled job=None
9.0426,Job,MODIFIED,eval-sanitize-3-r3-009,
9.0435,Job,MODIFIED,eval-sanitize-3-r3-008,
9.0469,Event,ADDED,eval-sanitize-3-r3-009.18d3d2f6e2921e3f,reason=SuccessfulCreate count=1 msg=Created pod: eval-sanitize-3-r3-009-97txr
9.0474,Event,ADDED,eval-sanitize-3-r3-009-97txr.18d3d2f6e29daa04,"reason=FailedScheduling count=None msg=0/6 nodes are available: 6 node(s) had untolerated taint(s). no new claims to deallocate, preemption: 0/6 nodes are available: 6 Preemption is not helpful for scheduling."
9.0486,Pod,MODIFIED,eval-sanitize-3-r3-009-97txr,phase=Pending node=None
9.0498,TaskRequest,MODIFIED,eval-sanitize-3-r3-009,phase=Scheduled job=None
9.054,Job,MODIFIED,eval-sanitize-3-r3-008,
10.021,TaskRequest,ADDED,eval-sanitize-3-r3-010,phase=None job=None
10.0252,TaskRequest,MODIFIED,eval-sanitize-3-r3-010,phase=Pending job=None
10.0413,Job,ADDED,eval-sanitize-3-r3-010,
10.0439,Job,MODIFIED,eval-sanitize-3-r3-009,
10.0456,TaskRequest,MODIFIED,eval-sanitize-3-r3-010,phase=Scheduled job=None
10.0486,Pod,ADDED,eval-sanitize-3-r3-010-tnkj2,phase=Pending node=None
10.0504,Job,MODIFIED,eval-sanitize-3-r3-010,
10.0582,Event,ADDED,eval-sanitize-3-r3-010.18d3d2f71ecf1433,reason=SuccessfulCreate count=1 msg=Created pod: eval-sanitize-3-r3-010-tnkj2
10.0585,Event,ADDED,eval-sanitize-3-r3-010-tnkj2.18d3d2f71ed75ddf,"reason=FailedScheduling count=None msg=0/6 nodes are available: 6 node(s) had untolerated taint(s). no new claims to deallocate, preemption: 0/6 nodes are available: 6 Preemption is not helpful for scheduling."
10.0586,TaskRequest,MODIFIED,eval-sanitize-3-r3-010,phase=Scheduled job=None
10.0596,Pod,MODIFIED,eval-sanitize-3-r3-010-tnkj2,phase=Pending node=None
10.0609,Job,MODIFIED,eval-sanitize-3-r3-009,
11.0076,TaskRequest,ADDED,eval-sanitize-3-r3-011,phase=None job=None
11.0111,TaskRequest,MODIFIED,eval-sanitize-3-r3-011,phase=Pending job=None
11.028,Job,ADDED,eval-sanitize-3-r3-011,
11.032,TaskRequest,MODIFIED,eval-sanitize-3-r3-011,phase=Scheduled job=None
11.0355,Pod,ADDED,eval-sanitize-3-r3-011-prswl,phase=Pending node=None
11.0378,Job,MODIFIED,eval-sanitize-3-r3-011,
11.0412,Event,ADDED,eval-sanitize-3-r3-011.18d3d2f75999ce9f,reason=SuccessfulCreate count=1 msg=Created pod: eval-sanitize-3-r3-011-prswl
11.0413,TaskRequest,MODIFIED,eval-sanitize-3-r3-011,phase=Scheduled job=None
11.0419,Event,ADDED,eval-sanitize-3-r3-011-prswl.18d3d2f759a83a00,"reason=FailedScheduling count=None msg=0/6 nodes are available: 6 node(s) had untolerated taint(s). no new claims to deallocate, preemption: 0/6 nodes are available: 6 Preemption is not helpful for scheduling."
11.043,Pod,MODIFIED,eval-sanitize-3-r3-011-prswl,phase=Pending node=None
11.0535,Job,MODIFIED,eval-sanitize-3-r3-010,
11.0618,Job,MODIFIED,eval-sanitize-3-r3-010,
11.1892,Pod,MODIFIED,eval-sanitize-3-r3-000-jfrb4,phase=Running node=kind-worker2
11.7785,Pod,MODIFIED,eval-sanitize-3-r3-001-x9hkn,phase=Running node=kind-worker
12.0071,TaskRequest,ADDED,eval-sanitize-3-r3-012,phase=None job=None
12.011,TaskRequest,MODIFIED,eval-sanitize-3-r3-012,phase=Pending job=None
12.0272,Job,ADDED,eval-sanitize-3-r3-012,
12.032,TaskRequest,MODIFIED,eval-sanitize-3-r3-012,phase=Scheduled job=None
12.0351,Pod,ADDED,eval-sanitize-3-r3-012-bfdmn,phase=Pending node=None
12.0374,Job,MODIFIED,eval-sanitize-3-r3-012,
12.0418,Event,ADDED,eval-sanitize-3-r3-012.18d3d2f795334d44,reason=SuccessfulCreate count=1 msg=Created pod: eval-sanitize-3-r3-012-bfdmn
12.042,TaskRequest,MODIFIED,eval-sanitize-3-r3-012,phase=Scheduled job=None
12.043,Pod,MODIFIED,eval-sanitize-3-r3-012-bfdmn,phase=Pending node=None
12.0438,Job,MODIFIED,eval-sanitize-3-r3-011,
12.0442,Event,ADDED,eval-sanitize-3-r3-012-bfdmn.18d3d2f7953e3bbf,"reason=FailedScheduling count=None msg=0/6 nodes are available: 6 node(s) had untolerated taint(s). no new claims to deallocate, preemption: 0/6 nodes are available: 6 Preemption is not helpful for scheduling."
12.0523,Job,MODIFIED,eval-sanitize-3-r3-011,
12.2043,Job,MODIFIED,eval-sanitize-3-r3-000,
12.214,Job,MODIFIED,eval-sanitize-3-r3-000,
12.3011,Pod,MODIFIED,eval-sanitize-3-r3-000-jfrb4,phase=Succeeded node=kind-worker2
12.7847,Job,MODIFIED,eval-sanitize-3-r3-001,
12.7942,Job,MODIFIED,eval-sanitize-3-r3-001,
12.9002,Pod,MODIFIED,eval-sanitize-3-r3-001-x9hkn,phase=Succeeded node=kind-worker
13.0075,TaskRequest,ADDED,eval-sanitize-3-r3-013,phase=None job=None
13.0118,TaskRequest,MODIFIED,eval-sanitize-3-r3-013,phase=Pending job=None
13.0281,Job,ADDED,eval-sanitize-3-r3-013,
13.0325,TaskRequest,MODIFIED,eval-sanitize-3-r3-013,phase=Scheduled job=None
13.0364,Pod,ADDED,eval-sanitize-3-r3-013-77wdv,phase=Pending node=None
13.0381,Job,MODIFIED,eval-sanitize-3-r3-013,
13.0408,Job,MODIFIED,eval-sanitize-3-r3-012,
13.0433,Event,ADDED,eval-sanitize-3-r3-013.18d3d2f7d0db900c,reason=SuccessfulCreate count=1 msg=Created pod: eval-sanitize-3-r3-013-77wdv
13.0436,Event,ADDED,eval-sanitize-3-r3-013-77wdv.18d3d2f7d0e85d96,"reason=FailedScheduling count=None msg=0/6 nodes are available: 6 node(s) had untolerated taint(s). no new claims to deallocate, preemption: 0/6 nodes are available: 6 Preemption is not helpful for scheduling."
13.0438,TaskRequest,MODIFIED,eval-sanitize-3-r3-013,phase=Scheduled job=None
13.0448,Pod,MODIFIED,eval-sanitize-3-r3-013-77wdv,phase=Pending node=None
13.0502,Job,MODIFIED,eval-sanitize-3-r3-012,
13.2106,Job,MODIFIED,eval-sanitize-3-r3-000,
13.2188,Pod,MODIFIED,eval-sanitize-3-r3-000-jfrb4,phase=Succeeded node=kind-worker2
13.2207,Job,MODIFIED,eval-sanitize-3-r3-000,
13.3433,Pod,MODIFIED,eval-sanitize-3-r3-002-7fs7w,phase=Running node=kind-worker4
13.7903,Job,MODIFIED,eval-sanitize-3-r3-001,
13.7983,Pod,MODIFIED,eval-sanitize-3-r3-001-x9hkn,phase=Succeeded node=kind-worker
13.7998,Job,MODIFIED,eval-sanitize-3-r3-001,
14.007,TaskRequest,ADDED,eval-sanitize-3-r3-014,phase=None job=None
14.011,TaskRequest,MODIFIED,eval-sanitize-3-r3-014,phase=Pending job=None
14.0279,Job,ADDED,eval-sanitize-3-r3-014,
14.0333,TaskRequest,MODIFIED,eval-sanitize-3-r3-014,phase=Scheduled job=None
14.035,Pod,ADDED,eval-sanitize-3-r3-014-mnwm8,phase=Pending node=None
14.0376,Job,MODIFIED,eval-sanitize-3-r3-014,
14.0411,Pod,MODIFIED,eval-sanitize-3-r3-014-mnwm8,phase=Pending node=None
14.0424,Event,ADDED,eval-sanitize-3-r3-014.18d3d2f80c69c75d,reason=SuccessfulCreate count=1 msg=Created pod: eval-sanitize-3-r3-014-mnwm8
14.0426,Event,ADDED,eval-sanitize-3-r3-014-mnwm8.18d3d2f80c74fb6b,"reason=FailedScheduling count=None msg=0/6 nodes are available: 6 node(s) had untolerated taint(s). no new claims to deallocate, preemption: 0/6 nodes are available: 6 Preemption is not helpful for scheduling."
14.0428,TaskRequest,MODIFIED,eval-sanitize-3-r3-014,phase=Scheduled job=None
14.0436,Job,MODIFIED,eval-sanitize-3-r3-013,
14.0534,Job,MODIFIED,eval-sanitize-3-r3-013,
14.2156,Job,MODIFIED,eval-sanitize-3-r3-000,
14.2197,Job,MODIFIED,eval-sanitize-3-r3-000,
14.2273,Event,ADDED,eval-sanitize-3-r3-000.18d3d2f81767eb64,reason=Completed count=1 msg=Job completed
14.2303,Job,MODIFIED,eval-sanitize-3-r3-000,
14.2359,TaskRequest,MODIFIED,eval-sanitize-3-r3-000,phase=Complete job=None
14.2459,Job,MODIFIED,eval-sanitize-3-r3-000,
14.3494,Job,MODIFIED,eval-sanitize-3-r3-002,
14.3604,Job,MODIFIED,eval-sanitize-3-r3-002,
14.4034,Pod,MODIFIED,eval-sanitize-3-r3-003-vp5rl,phase=Running node=kind-worker5
14.4247,Pod,MODIFIED,eval-sanitize-3-r3-002-7fs7w,phase=Succeeded node=kind-worker4
14.7966,Job,MODIFIED,eval-sanitize-3-r3-001,
14.8026,Job,MODIFIED,eval-sanitize-3-r3-001,
14.8063,Event,ADDED,eval-sanitize-3-r3-001.18d3d2f83a2673b1,reason=Completed count=1 msg=Job completed
14.8123,Job,MODIFIED,eval-sanitize-3-r3-001,
14.8165,TaskRequest,MODIFIED,eval-sanitize-3-r3-001,phase=Complete job=None
14.8256,Job,MODIFIED,eval-sanitize-3-r3-001,
14.9237,Node,MODIFIED,kind-worker2,taints=1
14.9373,Node,MODIFIED,kind-worker2,taints=0
14.9433,Pod,MODIFIED,eval-sanitize-3-r3-006-bjfc4,phase=Pending node=kind-worker2
14.9469,Pod,MODIFIED,eval-sanitize-3-r3-007-mt7xl,phase=Pending node=None
14.9473,Event,ADDED,eval-sanitize-3-r3-007-mt7xl.18d3d2f8427193e6,"reason=FailedScheduling count=None msg=0/6 nodes are available: 1 c_wall violated: 1 conflicting context pair(s) with node memory, 5 node(s) had untolerated taint(s). no new claims to deallocate, preemption: 0/6 nodes are available: 1 No preemption victims found for incoming pod, 5 Preemption is not helpful for scheduling."
14.9475,Event,ADDED,eval-sanitize-3-r3-006-bjfc4.18d3d2f8428a4d03,reason=Scheduled count=None msg=Successfully assigned compute/eval-sanitize-3-r3-006-bjfc4 to kind-worker2
14.9555,Pod,MODIFIED,eval-sanitize-3-r3-006-bjfc4,phase=Pending node=kind-worker2
14.9581,Pod,MODIFIED,eval-sanitize-3-r3-008-jtwkx,phase=Pending node=None
14.9597,Node,MODIFIED,kind-worker2,taints=0
14.96,Event,ADDED,eval-sanitize-3-r3-008-jtwkx.18d3d2f8430e8cd1,"reason=FailedScheduling count=None msg=0/6 nodes are available: 1 c_wall violated: 1 conflicting context pair(s) with node memory, 5 node(s) had untolerated taint(s). no new claims to deallocate, preemption: 0/6 nodes are available: 1 No preemption victims found for incoming pod, 5 Preemption is not helpful for scheduling."
14.9661,Pod,MODIFIED,eval-sanitize-3-r3-009-97txr,phase=Pending node=None
14.9666,Event,ADDED,eval-sanitize-3-r3-009-97txr.18d3d2f8439e3131,"reason=FailedScheduling count=None msg=0/6 nodes are available: 1 c_wall violated: 1 conflicting context pair(s) with node memory, 5 node(s) had untolerated taint(s). no new claims to deallocate, preemption: 0/6 nodes are available: 1 No preemption victims found for incoming pod, 5 Preemption is not helpful for scheduling."
14.9741,Pod,MODIFIED,eval-sanitize-3-r3-010-tnkj2,phase=Pending node=None
14.9744,Event,ADDED,eval-sanitize-3-r3-010-tnkj2.18d3d2f84419dd84,"reason=FailedScheduling count=None msg=0/6 nodes are available: 1 c_wall violated: 1 conflicting context pair(s) with node memory, 5 node(s) had untolerated taint(s). no new claims to deallocate, preemption: 0/6 nodes are available: 1 No preemption victims found for incoming pod, 5 Preemption is not helpful for scheduling."
14.9819,Pod,MODIFIED,eval-sanitize-3-r3-011-prswl,phase=Pending node=None
14.9823,Event,ADDED,eval-sanitize-3-r3-011-prswl.18d3d2f8449050ed,"reason=FailedScheduling count=None msg=0/6 nodes are available: 1 c_wall violated: 1 conflicting context pair(s) with node memory, 5 node(s) had untolerated taint(s). no new claims to deallocate, preemption: 0/6 nodes are available: 1 No preemption victims found for incoming pod, 5 Preemption is not helpful for scheduling."
14.9894,Pod,MODIFIED,eval-sanitize-3-r3-012-bfdmn,phase=Pending node=kind-worker2
14.9929,Event,ADDED,eval-sanitize-3-r3-012-bfdmn.18d3d2f8454aff4c,reason=Scheduled count=None msg=Successfully assigned compute/eval-sanitize-3-r3-012-bfdmn to kind-worker2
14.9991,Pod,MODIFIED,eval-sanitize-3-r3-012-bfdmn,phase=Pending node=kind-worker2
15.0066,TaskRequest,ADDED,eval-sanitize-3-r3-015,phase=None job=None
15.0129,Node,MODIFIED,kind-worker2,taints=0
15.013,TaskRequest,MODIFIED,eval-sanitize-3-r3-015,phase=Pending job=None
15.0211,Pod,MODIFIED,eval-sanitize-3-r3-013-77wdv,phase=Pending node=None
15.0215,Event,ADDED,eval-sanitize-3-r3-013-77wdv.18d3d2f846dd15f8,"reason=FailedScheduling count=None msg=0/6 nodes are available: 1 c_wall violated: 2 conflicting context pair(s) with node memory, 5 node(s) had untolerated taint(s). no new claims to deallocate, preemption: 0/6 nodes are available: 1 No preemption victims found for incoming pod, 5 Preemption is not helpful for scheduling."
15.0302,Pod,MODIFIED,eval-sanitize-3-r3-014-mnwm8,phase=Pending node=kind-worker2
15.0317,Job,ADDED,eval-sanitize-3-r3-015,
15.0358,Event,ADDED,eval-sanitize-3-r3-007-mt7xl.18d3d2f847984751,"reason=FailedScheduling count=None msg=0/6 nodes are available: 1 c_wall violated: 2 conflicting context pair(s) with node memory, 5 node(s) had untolerated taint(s). no new claims to deallocate, preemption: 0/6 nodes are available: 1 No preemption victims found for incoming pod, 5 Preemption is not helpful for scheduling."
15.0368,Pod,MODIFIED,eval-sanitize-3-r3-007-mt7xl,phase=Pending node=None
15.0392,Event,ADDED,eval-sanitize-3-r3-014-mnwm8.18d3d2f847b3999b,reason=Scheduled count=None msg=Successfully assigned compute/eval-sanitize-3-r3-014-mnwm8 to kind-worker2
15.0401,Pod,ADDED,eval-sanitize-3-r3-015-vwlfs,phase=Pending node=None
15.0439,Job,MODIFIED,eval-sanitize-3-r3-014,
15.044,TaskRequest,MODIFIED,eval-sanitize-3-r3-015,phase=Scheduled job=None
15.046,Pod,MODIFIED,eval-sanitize-3-r3-014-mnwm8,phase=Pending node=kind-worker2
15.0473,Job,MODIFIED,eval-sanitize-3-r3-015,
15.048,Event,ADDED,eval-sanitize-3-r3-015.18d3d2f8484e234d,reason=SuccessfulCreate count=1 msg=Created pod: eval-sanitize-3-r3-015-vwlfs
15.0483,Event,ADDED,eval-sanitize-3-r3-008-jtwkx.18d3d2f8485e2f1a,"reason=FailedScheduling count=None msg=0/6 nodes are available: 1 c_wall violated: 2 conflicting context pair(s) with node memory, 5 node(s) had untolerated taint(s). no new claims to deallocate, preemption: 0/6 nodes are available: 1 No preemption victims found for incoming pod, 5 Preemption is not helpful for scheduling."
15.0492,Pod,MODIFIED,eval-sanitize-3-r3-008-jtwkx,phase=Pending node=None
15.0538,TaskRequest,MODIFIED,eval-sanitize-3-r3-015,phase=Scheduled job=None
15.0565,Job,MODIFIED,eval-sanitize-3-r3-014,
15.0578,Event,ADDED,eval-sanitize-3-r3-015-vwlfs.18d3d2f8490cdd9f,"reason=FailedScheduling count=None msg=0/6 nodes are available: 1 c_wall violated: 2 conflicting context pair(s) with node memory, 5 node(s) had untolerated taint(s). no new claims to deallocate, preemption: 0/6 nodes are available: 1 No preemption victims found for incoming pod, 5 Preemption is not helpful for scheduling."
15.0589,Pod,MODIFIED,eval-sanitize-3-r3-015-vwlfs,phase=Pending node=None
15.1099,Pod,MODIFIED,eval-sanitize-3-r3-009-97txr,phase=Pending node=None
15.1104,Event,ADDED,eval-sanitize-3-r3-009-97txr.18d3d2f84c2a4ab3,"reason=FailedScheduling count=None msg=0/6 nodes are available: 1 c_wall violated: 2 conflicting context pair(s) with node memory, 5 node(s) had untolerated taint(s). no new claims to deallocate, preemption: 0/6 nodes are available: 1 No preemption victims found for incoming pod, 5 Preemption is not helpful for scheduling."
15.121,Pod,MODIFIED,eval-sanitize-3-r3-010-tnkj2,phase=Pending node=None
15.1216,Event,ADDED,eval-sanitize-3-r3-010-tnkj2.18d3d2f84cb3944d,"reason=FailedScheduling count=None msg=0/6 nodes are available: 1 c_wall violated: 2 conflicting context pair(s) with node memory, 5 node(s) had untolerated taint(s). no new claims to deallocate, preemption: 0/6 nodes are available: 1 No preemption victims found for incoming pod, 5 Preemption is not helpful for scheduling."
15.129,Pod,MODIFIED,eval-sanitize-3-r3-011-prswl,phase=Pending node=None
15.1294,Event,ADDED,eval-sanitize-3-r3-011-prswl.18d3d2f84d521ba3,"reason=FailedScheduling count=None msg=0/6 nodes are available: 1 c_wall violated: 2 conflicting context pair(s) with node memory, 5 node(s) had untolerated taint(s). no new claims to deallocate, preemption: 0/6 nodes are available: 1 No preemption victims found for incoming pod, 5 Preemption is not helpful for scheduling."
15.1355,Event,ADDED,eval-sanitize-3-r3-013-77wdv.18d3d2f84dcbab35,"reason=FailedScheduling count=None msg=0/6 nodes are available: 1 c_wall violated: 2 conflicting context pair(s) with node memory, 5 node(s) had untolerated taint(s). no new claims to deallocate, preemption: 0/6 nodes are available: 1 No preemption victims found for incoming pod, 5 Preemption is not helpful for scheduling."
15.139,Event,ADDED,eval-sanitize-3-r3-007-mt7xl.18d3d2f84df35bc5,"reason=FailedScheduling count=None msg=0/6 nodes are available: 1 c_wall violated: 2 conflicting context pair(s) with node memory, 5 node(s) had untolerated taint(s). no new claims to deallocate, preemption: 0/6 nodes are available: 1 No preemption victims found for incoming pod, 5 Preemption is not helpful for scheduling."
15.1402,Event,ADDED,eval-sanitize-3-r3-008-jtwkx.18d3d2f84e1c4a06,"reason=FailedScheduling count=None msg=0/6 nodes are available: 1 c_wall violated: 2 conflicting context pair(s) with node memory, 5 node(s) had untolerated taint(s). no new claims to deallocate, preemption: 0/6 nodes are available: 1 No preemption victims found for incoming pod, 5 Preemption is not helpful for scheduling."
15.1455,Event,ADDED,eval-sanitize-3-r3-015-vwlfs.18d3d2f84e43f8dd,"reason=FailedScheduling count=None msg=0/6 nodes are available: 1 c_wall violated: 2 conflicting context pair(s) with node memory, 5 node(s) had untolerated taint(s). no new claims to deallocate, preemption: 0/6 nodes are available: 1 No preemption victims found for incoming pod, 5 Preemption is not helpful for scheduling."
15.1457,Event,ADDED,eval-sanitize-3-r3-009-97txr.18d3d2f84e6a451e,"reason=FailedScheduling count=None msg=0/6 nodes are available: 1 c_wall violated: 2 conflicting context pair(s) with node memory, 5 node(s) had untolerated taint(s). no new claims to deallocate, preemption: 0/6 nodes are available: 1 No preemption victims found for incoming pod, 5 Preemption is not helpful for scheduling."
15.1888,Event,ADDED,eval-sanitize-3-r3-010-tnkj2.18d3d2f850e3ff85,"reason=FailedScheduling count=None msg=0/6 nodes are available: 1 c_wall violated: 2 conflicting context pair(s) with node memory, 5 node(s) had untolerated taint(s). no new claims to deallocate, preemption: 0/6 nodes are available: 1 No preemption victims found for incoming pod, 5 Preemption is not helpful for scheduling."
15.2198,Event,ADDED,eval-sanitize-3-r3-011-prswl.18d3d2f852ccb4c4,"reason=FailedScheduling count=None msg=0/6 nodes are available: 1 c_wall violated: 2 conflicting context pair(s) with node memory, 5 node(s) had untolerated taint(s). no new claims to deallocate, preemption: 0/6 nodes are available: 1 No preemption victims found for incoming pod, 5 Preemption is not helpful for scheduling."
15.2273,Node,MODIFIED,kind-worker2,taints=0
15.2291,Node,MODIFIED,kind-worker,taints=1
15.237,Event,MODIFIED,eval-sanitize-3-r3-013-77wdv.18d3d2f84dcbab35,"reason=FailedScheduling count=None msg=0/6 nodes are available: 1 c_wall violated: 2 conflicting context pair(s) with node memory, 5 node(s) had untolerated taint(s). no new claims to deallocate, preemption: 0/6 nodes are available: 1 No preemption victims found for incoming pod, 5 Preemption is not helpful for scheduling."
15.2407,Event,MODIFIED,eval-sanitize-3-r3-007-mt7xl.18d3d2f84df35bc5,"reason=FailedScheduling count=None msg=0/6 nodes are available: 1 c_wall violated: 2 conflicting context pair(s) with node memory, 5 node(s) had untolerated taint(s). no new claims to deallocate, preemption: 0/6 nodes are available: 1 No preemption victims found for incoming pod, 5 Preemption is not helpful for scheduling."
15.2412,Event,MODIFIED,eval-sanitize-3-r3-008-jtwkx.18d3d2f84e1c4a06,"reason=FailedScheduling count=None msg=0/6 nodes are available: 1 c_wall violated: 2 conflicting context pair(s) with node memory, 5 node(s) had untolerated taint(s). no new claims to deallocate, preemption: 0/6 nodes are available: 1 No preemption victims found for incoming pod, 5 Preemption is not helpful for scheduling."
15.2476,Event,MODIFIED,eval-sanitize-3-r3-015-vwlfs.18d3d2f84e43f8dd,"reason=FailedScheduling count=None msg=0/6 nodes are available: 1 c_wall violated: 2 conflicting context pair(s) with node memory, 5 node(s) had untolerated taint(s). no new claims to deallocate, preemption: 0/6 nodes are available: 1 No preemption victims found for incoming pod, 5 Preemption is not helpful for scheduling."
15.2894,Event,MODIFIED,eval-sanitize-3-r3-009-97txr.18d3d2f84e6a451e,"reason=FailedScheduling count=None msg=0/6 nodes are available: 1 c_wall violated: 2 conflicting context pair(s) with node memory, 5 node(s) had untolerated taint(s). no new claims to deallocate, preemption: 0/6 nodes are available: 1 No preemption victims found for incoming pod, 5 Preemption is not helpful for scheduling."
15.2928,Event,MODIFIED,eval-sanitize-3-r3-010-tnkj2.18d3d2f850e3ff85,"reason=FailedScheduling count=None msg=0/6 nodes are available: 1 c_wall violated: 2 conflicting context pair(s) with node memory, 5 node(s) had untolerated taint(s). no new claims to deallocate, preemption: 0/6 nodes are available: 1 No preemption victims found for incoming pod, 5 Preemption is not helpful for scheduling."
15.3274,Node,MODIFIED,kind-worker,taints=0
15.3279,Event,MODIFIED,eval-sanitize-3-r3-011-prswl.18d3d2f852ccb4c4,"reason=FailedScheduling count=None msg=0/6 nodes are available: 1 c_wall violated: 2 conflicting context pair(s) with node memory, 5 node(s) had untolerated taint(s). no new claims to deallocate, preemption: 0/6 nodes are available: 1 No preemption victims found for incoming pod, 5 Preemption is not helpful for scheduling."
15.338,Pod,MODIFIED,eval-sanitize-3-r3-007-mt7xl,phase=Pending node=kind-worker
15.3435,Event,ADDED,eval-sanitize-3-r3-007-mt7xl.18d3d2f85a098ad2,reason=Scheduled count=None msg=Successfully assigned compute/eval-sanitize-3-r3-007-mt7xl to kind-worker
15.3538,Node,MODIFIED,kind-worker,taints=0
15.3558,Pod,MODIFIED,eval-sanitize-3-r3-007-mt7xl,phase=Pending node=kind-worker
15.3573,Job,MODIFIED,eval-sanitize-3-r3-002,
15.3637,Pod,MODIFIED,eval-sanitize-3-r3-004-rz87f,phase=Running node=kind-worker3
15.3671,Pod,MODIFIED,eval-sanitize-3-r3-002-7fs7w,phase=Succeeded node=kind-worker4
15.3692,Job,MODIFIED,eval-sanitize-3-r3-002,
15.3769,Event,ADDED,eval-sanitize-3-r3-006-bjfc4.18d3d2f85bc5fb13,"reason=Pulled count=1 msg=Container image ""busybox:musl"" already present on machine"
15.4027,Event,ADDED,eval-sanitize-3-r3-006-bjfc4.18d3d2f85daf8037,reason=Created count=1 msg=Created container: task
15.4088,Job,MODIFIED,eval-sanitize-3-r3-003,
15.4116,Pod,MODIFIED,eval-sanitize-3-r3-008-jtwkx,phase=Pending node=kind-worker
15.415,Event,ADDED,eval-sanitize-3-r3-008-jtwkx.18d3d2f85e73cdf0,reason=Scheduled count=None msg=Successfully assigned compute/eval-sanitize-3-r3-008-jtwkx to kind-worker
15.4183,Job,MODIFIED,eval-sanitize-3-r3-003,
15.4222,Node,MODIFIED,kind-worker2,taints=0
15.4242,Node,MODIFIED,kind-worker,taints=0
15.426,Pod,MODIFIED,eval-sanitize-3-r3-008-jtwkx,phase=Pending node=kind-worker
15.4278,Pod,MODIFIED,eval-sanitize-3-r3-015-vwlfs,phase=Pending node=kind-worker
15.4388,Event,ADDED,eval-sanitize-3-r3-015-vwlfs.18d3d2f85f51e396,reason=Scheduled count=None msg=Successfully assigned compute/eval-sanitize-3-r3-015-vwlfs to kind-worker
15.4459,Node,MODIFIED,kind-worker,taints=0
15.4481,Pod,MODIFIED,eval-sanitize-3-r3-015-vwlfs,phase=Pending node=kind-worker
15.4611,Node,MODIFIED,kind-worker,taints=0
15.4705,Event,ADDED,eval-sanitize-3-r3-012-bfdmn.18d3d2f861af114c,"reason=Pulled count=1 msg=Container image ""busybox:musl"" already present on machine"
15.4889,Pod,MODIFIED,eval-sanitize-3-r3-009-97txr,phase=Pending node=kind-worker
15.4939,Event,ADDED,eval-sanitize-3-r3-012-bfdmn.18d3d2f862eaee41,reason=Created count=1 msg=Created container: task
15.4945,Event,ADDED,eval-sanitize-3-r3-009-97txr.18d3d2f8630991d1,reason=Scheduled count=None msg=Successfully assigned compute/eval-sanitize-3-r3-009-97txr to kind-worker
15.4993,Node,MODIFIED,kind-worker,taints=0
15.5015,Pod,MODIFIED,eval-sanitize-3-r3-009-97txr,phase=Pending node=kind-worker
15.5253,Pod,MODIFIED,eval-sanitize-3-r3-010-tnkj2,phase=Pending node=kind-worker
15.5327,Pod,MODIFIED,eval-sanitize-3-r3-011-prswl,phase=Pending node=kind-worker
15.5346,Event,ADDED,eval-sanitize-3-r3-010-tnkj2.18d3d2f8652c660c,reason=Scheduled count=None msg=Successfully assigned compute/eval-sanitize-3-r3-010-tnkj2 to kind-worker
15.5363,Node,MODIFIED,kind-worker,taints=0
15.5397,Event,ADDED,eval-sanitize-3-r3-012-bfdmn.18d3d2f8656a61f2,reason=Started count=1 msg=Started container task
15.5427,Pod,MODIFIED,eval-sanitize-3-r3-010-tnkj2,phase=Pending node=kind-worker
15.543,Event,ADDED,eval-sanitize-3-r3-011-prswl.18d3d2f8659f507f,reason=Scheduled count=None msg=Successfully assigned compute/eval-sanitize-3-r3-011-prswl to kind-worker
15.5501,Pod,MODIFIED,eval-sanitize-3-r3-011-prswl,phase=Pending node=kind-worker
15.5514,Event,ADDED,eval-sanitize-3-r3-006-bjfc4.18d3d2f8664943df,reason=Started count=1 msg=Started container task
15.5563,Event,ADDED,eval-sanitize-3-r3-014-mnwm8.18d3d2f866a9a3bf,"reason=Pulled count=1 msg=Container image ""busybox:musl"" already present on machine"
15.5771,Event,ADDED,eval-sanitize-3-r3-014-mnwm8.18d3d2f868201db2,reason=Created count=1 msg=Created container: task
15.5885,Pod,MODIFIED,eval-sanitize-3-r3-013-77wdv,phase=Pending node=kind-worker
15.5918,Event,ADDED,eval-sanitize-3-r3-013-77wdv.18d3d2f868fa9e6e,reason=Scheduled count=None msg=Successfully assigned compute/eval-sanitize-3-r3-013-77wdv to kind-worker
15.5988,Pod,MODIFIED,eval-sanitize-3-r3-013-77wdv,phase=Pending node=kind-worker
15.6421,Pod,MODIFIED,eval-sanitize-3-r3-003-vp5rl,phase=Succeeded node=kind-worker5
15.6543,Event,ADDED,eval-sanitize-3-r3-014-mnwm8.18d3d2f86ca97ffe,reason=Started count=1 msg=Started container task
15.7814,Event,ADDED,eval-sanitize-3-r3-007-mt7xl.18d3d2f8743bdfea,"reason=Pulled count=1 msg=Container image ""busybox:musl"" already present on machine"
15.8074,Event,ADDED,eval-sanitize-3-r3-007-mt7xl.18d3d2f875cb8a45,reason=Created count=1 msg=Created container: task
15.8332,Event,ADDED,eval-sanitize-3-r3-008-jtwkx.18d3d2f877443c07,"reason=Pulled count=1 msg=Container image ""busybox:musl"" already present on machine"
15.842,Event,ADDED,eval-sanitize-3-r3-015-vwlfs.18d3d2f877ac1da1,"reason=Pulled count=1 msg=Container image ""busybox:musl"" already present on machine"
15.8513,Event,ADDED,eval-sanitize-3-r3-007-mt7xl.18d3d2f8786fa9cc,reason=Started count=1 msg=Started container task
15.8661,Event,ADDED,eval-sanitize-3-r3-008-jtwkx.18d3d2f879501e36,reason=Created count=1 msg=Created container: task
15.8874,Event,ADDED,eval-sanitize-3-r3-015-vwlfs.18d3d2f87a98a87c,reason=Created count=1 msg=Created container: task
15.9795,Event,ADDED,eval-sanitize-3-r3-008-jtwkx.18d3d2f87de390d6,reason=Started count=1 msg=Started container task
16.0327,Event,ADDED,eval-sanitize-3-r3-011-prswl.18d3d2f881785b8b,"reason=Pulled count=1 msg=Container image ""busybox:musl"" already present on machine"
16.0329,TaskRequest,ADDED,eval-sanitize-3-r3-016,phase=None job=None
16.0348,Node,MODIFIED,kind-worker4,taints=1
16.0374,TaskRequest,MODIFIED,eval-sanitize-3-r3-016,phase=Pending job=None
16.0413,Event,ADDED,eval-sanitize-3-r3-015-vwlfs.18d3d2f882c306f2,reason=Started count=1 msg=Started container task
16.0794,Event,ADDED,eval-sanitize-3-r3-009-97txr.18d3d2f882c79539,"reason=Pulled count=1 msg=Container image ""busybox:musl"" already present on machine"
16.0808,Job,MODIFIED,eval-sanitize-3-r3-015,
16.0818,Job,ADDED,eval-sanitize-3-r3-016,
16.0853,Event,ADDED,eval-sanitize-3-r3-011-prswl.18d3d2f882e0b49b,reason=Created count=1 msg=Created container: task
16.0889,Pod,ADDED,eval-sanitize-3-r3-016-h5x2s,phase=Pending node=None
16.0892,TaskRequest,MODIFIED,eval-sanitize-3-r3-016,phase=Scheduled job=None
16.1016,Event,ADDED,eval-sanitize-3-r3-013-77wdv.18d3d2f882f1813e,"reason=Pulled count=1 msg=Container image ""busybox:musl"" already present on machine"
16.1024,Event,ADDED,eval-sanitize-3-r3-016.18d3d2f886d1757e,reason=SuccessfulCreate count=1 msg=Created pod: eval-sanitize-3-r3-016-h5x2s
16.1039,Job,MODIFIED,eval-sanitize-3-r3-016,
16.1049,Job,MODIFIED,eval-sanitize-3-r3-015,
16.1075,Pod,MODIFIED,eval-sanitize-3-r3-016-h5x2s,phase=Pending node=kind-worker
16.1099,Node,MODIFIED,kind-worker4,taints=0
16.1191,Event,ADDED,eval-sanitize-3-r3-010-tnkj2.18d3d2f8840c7704,"reason=Pulled count=1 msg=Container image ""busybox:musl"" already present on machine"
16.1193,Event,ADDED,eval-sanitize-3-r3-016-h5x2s.18d3d2f887ed4cec,reason=Scheduled count=None msg=Successfully assigned compute/eval-sanitize-3-r3-016-h5x2s to kind-worker
16.1194,TaskRequest,MODIFIED,eval-sanitize-3-r3-016,phase=Scheduled job=None
16.1211,Node,MODIFIED,kind-worker,taints=0
16.1233,Pod,MODIFIED,eval-sanitize-3-r3-016-h5x2s,phase=Pending node=kind-worker
16.1235,Event,ADDED,eval-sanitize-3-r3-009-97txr.18d3d2f884c7ce56,reason=Created count=1 msg=Created container: task
16.1277,Node,MODIFIED,kind-worker4,taints=0
16.1285,Event,ADDED,eval-sanitize-3-r3-013-77wdv.18d3d2f88510f724,reason=Created count=1 msg=Created container: task
16.1299,Node,MODIFIED,kind-worker,taints=0
16.1467,Event,ADDED,eval-sanitize-3-r3-011-prswl.18d3d2f8851643fe,reason=Started count=1 msg=Started container task
16.1484,Node,MODIFIED,kind-worker4,taints=0
16.1508,Event,ADDED,eval-sanitize-3-r3-010-tnkj2.18d3d2f885bf44f2,reason=Created count=1 msg=Created container: task
16.1596,Event,ADDED,eval-sanitize-3-r3-013-77wdv.18d3d2f8879721de,reason=Started count=1 msg=Started container task
16.1641,Event,ADDED,eval-sanitize-3-r3-009-97txr.18d3d2f88798deb8,reason=Started count=1 msg=Started container task
16.1677,Event,ADDED,eval-sanitize-3-r3-010-tnkj2.18d3d2f88852d313,reason=Started count=1 msg=Started container task
16.2034,Pod,MODIFIED,eval-sanitize-3-r3-012-bfdmn,phase=Running node=kind-worker2
16.2098,Pod,MODIFIED,eval-sanitize-3-r3-006-bjfc4,phase=Running node=kind-worker2
16.2242,Pod,MODIFIED,eval-sanitize-3-r3-014-mnwm8,phase=Running node=kind-worker2
16.3629,Job,MODIFIED,eval-sanitize-3-r3-002,
16.3681,Job,MODIFIED,eval-sanitize-3-r3-002,
16.3698,Job,MODIFIED,eval-sanitize-3-r3-004,
16.3726,Event,ADDED,eval-sanitize-3-r3-002.18d3d2f89779b6bf,reason=Completed count=1 msg=Job completed
16.3813,Job,MODIFIED,eval-sanitize-3-r3-004,
16.3853,Job,MODIFIED,eval-sanitize-3-r3-002,
16.3901,TaskRequest,MODIFIED,eval-sanitize-3-r3-002,phase=Complete job=None
16.3999,Job,MODIFIED,eval-sanitize-3-r3-002,
16.4085,Pod,MODIFIED,eval-sanitize-3-r3-005-zlzdh,phase=Running node=kind-worker5
16.4146,Job,MODIFIED,eval-sanitize-3-r3-003,
16.4234,Pod,MODIFIED,eval-sanitize-3-r3-003-vp5rl,phase=Succeeded node=kind-worker5
16.4249,Job,MODIFIED,eval-sanitize-3-r3-003,
16.5374,Event,ADDED,eval-sanitize-3-r3-016-h5x2s.18d3d2f8a140de46,"reason=Pulled count=1 msg=Container image ""busybox:musl"" already present on machine"
16.5606,Pod,MODIFIED,eval-sanitize-3-r3-004-rz87f,phase=Succeeded node=kind-worker3
16.5609,Event,ADDED,eval-sanitize-3-r3-016-h5x2s.18d3d2f8a2931616,reason=Created count=1 msg=Created container: task
16.6206,Event,ADDED,eval-sanitize-3-r3-016-h5x2s.18d3d2f8a62fdbd1,reason=Started count=1 msg=Started container task
16.7929,Pod,MODIFIED,eval-sanitize-3-r3-011-prswl,phase=Running node=kind-worker
16.7994,Pod,MODIFIED,eval-sanitize-3-r3-015-vwlfs,phase=Running node=kind-worker
16.8061,Pod,MODIFIED,eval-sanitize-3-r3-010-tnkj2,phase=Running node=kind-worker
16.8124,Pod,MODIFIED,eval-sanitize-3-r3-008-jtwkx,phase=Running node=kind-worker
16.8179,Pod,MODIFIED,eval-sanitize-3-r3-016-h5x2s,phase=Running node=kind-worker
16.8238,Pod,MODIFIED,eval-sanitize-3-r3-007-mt7xl,phase=Running node=kind-worker
16.8295,Pod,MODIFIED,eval-sanitize-3-r3-009-97txr,phase=Running node=kind-worker
16.8356,Pod,MODIFIED,eval-sanitize-3-r3-013-77wdv,phase=Running node=kind-worker
17.0084,TaskRequest,ADDED,eval-sanitize-3-r3-017,phase=None job=None
17.0128,TaskRequest,MODIFIED,eval-sanitize-3-r3-017,phase=Pending job=None
17.0297,Job,ADDED,eval-sanitize-3-r3-017,
17.0354,TaskRequest,MODIFIED,eval-sanitize-3-r3-017,phase=Scheduled job=None
17.0428,Pod,ADDED,eval-sanitize-3-r3-017-g2ttz,phase=Pending node=None
17.0446,Job,MODIFIED,eval-sanitize-3-r3-017,
17.0464,TaskRequest,MODIFIED,eval-sanitize-3-r3-017,phase=Scheduled job=None
17.0488,Event,ADDED,eval-sanitize-3-r3-017.18d3d2f8bfaa7494,reason=SuccessfulCreate count=1 msg=Created pod: eval-sanitize-3-r3-017-g2ttz
17.0645,Pod,MODIFIED,eval-sanitize-3-r3-017-g2ttz,phase=Pending node=kind-worker4
17.0701,Event,ADDED,eval-sanitize-3-r3-017-g2ttz.18d3d2f8c0f2437e,reason=Scheduled count=None msg=Successfully assigned compute/eval-sanitize-3-r3-017-g2ttz to kind-worker4
17.0748,Node,MODIFIED,kind-worker4,taints=0
17.0783,Pod,MODIFIED,eval-sanitize-3-r3-017-g2ttz,phase=Pending node=kind-worker4
17.0865,Job,MODIFIED,eval-sanitize-3-r3-015,
17.0891,Node,MODIFIED,kind-worker4,taints=0
17.0927,Job,MODIFIED,eval-sanitize-3-r3-016,
17.0954,Job,MODIFIED,eval-sanitize-3-r3-015,
17.101,Job,MODIFIED,eval-sanitize-3-r3-016,
17.2081,Job,MODIFIED,eval-sanitize-3-r3-012,
17.2151,Job,MODIFIED,eval-sanitize-3-r3-006,
17.2172,Job,MODIFIED,eval-sanitize-3-r3-012,
17.2237,Job,MODIFIED,eval-sanitize-3-r3-006,
17.2271,Job,MODIFIED,eval-sanitize-3-r3-014,
17.236,Job,MODIFIED,eval-sanitize-3-r3-014,
17.378,Job,MODIFIED,eval-sanitize-3-r3-004,
17.3879,Pod,MODIFIED,eval-sanitize-3-r3-004-rz87f,phase=Succeeded node=kind-worker3
17.3888,Job,MODIFIED,eval-sanitize-3-r3-004,
17.4131,Job,MODIFIED,eval-sanitize-3-r3-005,
17.4208,Job,MODIFIED,eval-sanitize-3-r3-003,
17.4237,Job,MODIFIED,eval-sanitize-3-r3-005,
17.4259,Job,MODIFIED,eval-sanitize-3-r3-003,
17.4305,Event,ADDED,eval-sanitize-3-r3-003.18d3d2f8d689d0fc,reason=Completed count=1 msg=Job completed
17.4366,Job,MODIFIED,eval-sanitize-3-r3-003,
17.4415,TaskRequest,MODIFIED,eval-sanitize-3-r3-003,phase=Complete job=None
17.4501,Job,MODIFIED,eval-sanitize-3-r3-003,
17.4914,Event,ADDED,eval-sanitize-3-r3-017-g2ttz.18d3d2f8da2e0967,"reason=Pulled count=1 msg=Container image ""busybox:musl"" already present on machine"
17.513,Event,ADDED,eval-sanitize-3-r3-017-g2ttz.18d3d2f8db4cf2e0,reason=Created count=1 msg=Created container: task
17.6104,Event,ADDED,eval-sanitize-3-r3-017-g2ttz.18d3d2f8e148b7b6,reason=Started count=1 msg=Started container task
17.6614,Pod,MODIFIED,eval-sanitize-3-r3-005-zlzdh,phase=Succeeded node=kind-worker5
17.7994,Job,MODIFIED,eval-sanitize-3-r3-011,
17.8098,Job,MODIFIED,eval-sanitize-3-r3-011,
17.8117,Job,MODIFIED,eval-sanitize-3-r3-010,
17.8177,Job,MODIFIED,eval-sanitize-3-r3-008,
17.82,Job,MODIFIED,eval-sanitize-3-r3-010,
17.8268,Job,MODIFIED,eval-sanitize-3-r3-008,
17.8318,Job,MODIFIED,eval-sanitize-3-r3-007,
17.835,Job,MODIFIED,eval-sanitize-3-r3-009,
17.8399,Job,MODIFIED,eval-sanitize-3-r3-013,
17.8424,Job,MODIFIED,eval-sanitize-3-r3-007,
17.8448,Job,MODIFIED,eval-sanitize-3-r3-009,
17.8487,Job,MODIFIED,eval-sanitize-3-r3-013,
18.0168,TaskRequest,ADDED,eval-sanitize-3-r3-018,phase=None job=None
18.0208,TaskRequest,MODIFIED,eval-sanitize-3-r3-018,phase=Pending job=None
18.0382,Job,ADDED,eval-sanitize-3-r3-018,
18.0453,Pod,ADDED,eval-sanitize-3-r3-018-gz22z,phase=Pending node=None
18.0454,TaskRequest,MODIFIED,eval-sanitize-3-r3-018,phase=Scheduled job=None
18.048,Job,MODIFIED,eval-sanitize-3-r3-018,
18.0506,Job,MODIFIED,eval-sanitize-3-r3-017,
18.051,Event,ADDED,eval-sanitize-3-r3-018.18d3d2f8fb70ca74,reason=SuccessfulCreate count=1 msg=Created pod: eval-sanitize-3-r3-018-gz22z
18.0533,TaskRequest,MODIFIED,eval-sanitize-3-r3-018,phase=Scheduled job=None
18.0595,Job,MODIFIED,eval-sanitize-3-r3-017,
18.0619,Pod,MODIFIED,eval-sanitize-3-r3-018-gz22z,phase=Pending node=None
18.0622,Event,ADDED,eval-sanitize-3-r3-018-gz22z.18d3d2f8fc21eadc,"reason=FailedScheduling count=None msg=0/6 nodes are available: 1 c_wall violated: 3 conflicting context pair(s) with node memory, 2 c_wall violated: 1 conflicting context pair(s) with node memory, 3 node(s) had untolerated taint(s). no new claims to deallocate, preemption: 0/6 nodes are available: 3 No preemption victims found for incoming pod, 3 Preemption is not helpful for scheduling."
18.1197,Event,ADDED,eval-sanitize-3-r3-018-gz22z.18d3d2f8ffa71db1,"reason=FailedScheduling count=None msg=0/6 nodes are available: 1 c_wall violated: 3 conflicting context pair(s) with node memory, 2 c_wall violated: 1 conflicting context pair(s) with node memory, 3 node(s) had untolerated taint(s). no new claims to deallocate, preemption: 0/6 nodes are available: 3 No preemption victims found for incoming pod, 3 Preemption is not helpful for scheduling."
18.2367,Node,MODIFIED,kind-worker2,taints=1
18.248,Pod,MODIFIED,eval-sanitize-3-r3-018-gz22z,phase=Pending node=None
18.2497,Event,MODIFIED,eval-sanitize-3-r3-018-gz22z.18d3d2f8ffa71db1,"reason=FailedScheduling count=None msg=0/6 nodes are available: 1 c_wall violated: 3 conflicting context pair(s) with node memory, 2 c_wall violated: 1 conflicting context pair(s) with node memory, 3 node(s) had untolerated taint(s). no new claims to deallocate, preemption: 0/6 nodes are available: 3 No preemption victims found for incoming pod, 3 Preemption is not helpful for scheduling."
18.2512,Node,MODIFIED,kind-worker2,taints=1
18.2577,Event,ADDED,eval-sanitize-3-r3-018-gz22z.18d3d2f907e3e59a,"reason=FailedScheduling count=None msg=0/6 nodes are available: 1 c_wall violated: 1 conflicting context pair(s) with node memory, 1 c_wall violated: 3 conflicting context pair(s) with node memory, 4 node(s) had untolerated taint(s). no new claims to deallocate, preemption: 0/6 nodes are available: 2 No preemption victims found for incoming pod, 4 Preemption is not helpful for scheduling."
18.2628,Event,MODIFIED,eval-sanitize-3-r3-018-gz22z.18d3d2f907e3e59a,"reason=FailedScheduling count=None msg=0/6 nodes are available: 1 c_wall violated: 1 conflicting context pair(s) with node memory, 1 c_wall violated: 3 conflicting context pair(s) with node memory, 4 node(s) had untolerated taint(s). no new claims to deallocate, preemption: 0/6 nodes are available: 2 No preemption victims found for incoming pod, 4 Preemption is not helpful for scheduling."
18.3554,Pod,MODIFIED,eval-sanitize-3-r3-017-g2ttz,phase=Running node=kind-worker4
18.3845,Job,MODIFIED,eval-sanitize-3-r3-004,
18.3887,Job,MODIFIED,eval-sanitize-3-r3-004,
18.3935,Event,ADDED,eval-sanitize-3-r3-004.18d3d2f90fea3f95,reason=Completed count=1 msg=Job completed
18.4,Job,MODIFIED,eval-sanitize-3-r3-004,
18.4064,TaskRequest,MODIFIED,eval-sanitize-3-r3-004,phase=Complete job=None
18.4168,Job,MODIFIED,eval-sanitize-3-r3-004,
18.4185,Job,MODIFIED,eval-sanitize-3-r3-005,
18.4271,Pod,MODIFIED,eval-sanitize-3-r3-005-zlzdh,phase=Succeeded node=kind-worker5
18.4281,Job,MODIFIED,eval-sanitize-3-r3-005,
18.451,Node,MODIFIED,kind-worker,taints=1
18.4604,Pod,MODIFIED,eval-sanitize-3-r3-018-gz22z,phase=Pending node=None
18.468,Event,ADDED,eval-sanitize-3-r3-018-gz22z.18d3d2f9146790c1,"reason=FailedScheduling count=None msg=0/6 nodes are available: 1 c_wall violated: 1 conflicting context pair(s) with node memory, 5 node(s) had untolerated taint(s). no new claims to deallocate, preemption: 0/6 nodes are available: 1 No preemption victims found for incoming pod, 5 Preemption is not helpful for scheduling."
18.5337,Node,MODIFIED,kind-worker3,taints=1
18.5357,Node,MODIFIED,kind-worker,taints=1
18.5421,Event,MODIFIED,eval-sanitize-3-r3-018-gz22z.18d3d2f9146790c1,"reason=FailedScheduling count=None msg=0/6 nodes are available: 1 c_wall violated: 1 conflicting context pair(s) with node memory, 5 node(s) had untolerated taint(s). no new claims to deallocate, preemption: 0/6 nodes are available: 1 No preemption victims found for incoming pod, 5 Preemption is not helpful for scheduling."
18.5479,Node,MODIFIED,kind-worker3,taints=1
18.6247,Node,MODIFIED,kind-worker3,taints=0
18.6339,Pod,MODIFIED,eval-sanitize-3-r3-018-gz22z,phase=Pending node=kind-worker3
18.6374,Event,ADDED,eval-sanitize-3-r3-018-gz22z.18d3d2f91e7dd272,reason=Scheduled count=None msg=Successfully assigned compute/eval-sanitize-3-r3-018-gz22z to kind-worker3
18.6436,Pod,MODIFIED,eval-sanitize-3-r3-018-gz22z,phase=Pending node=kind-worker3
18.6459,Node,MODIFIED,kind-worker3,taints=0
18.7354,Node,MODIFIED,kind-worker3,taints=0
18.7466,Node,MODIFIED,kind-worker3,taints=0
19.0067,TaskRequest,ADDED,eval-sanitize-3-r3-019,phase=None job=None
19.0119,TaskRequest,MODIFIED,eval-sanitize-3-r3-019,phase=Pending job=None
19.0261,Job,ADDED,eval-sanitize-3-r3-019,
19.0318,TaskRequest,MODIFIED,eval-sanitize-3-r3-019,phase=Scheduled job=None
19.0357,Job,MODIFIED,eval-sanitize-3-r3-019,
19.0368,Pod,ADDED,eval-sanitize-3-r3-019-svm65,phase=Pending node=None
19.0387,TaskRequest,MODIFIED,eval-sanitize-3-r3-019,phase=Scheduled job=None
19.0395,Event,ADDED,eval-sanitize-3-r3-019.18d3d2f936796eeb,reason=SuccessfulCreate count=1 msg=Created pod: eval-sanitize-3-r3-019-svm65
19.0477,Pod,MODIFIED,eval-sanitize-3-r3-019-svm65,phase=Pending node=None
19.0491,Event,ADDED,eval-sanitize-3-r3-019-svm65.18d3d2f936e6f69f,"reason=FailedScheduling count=None msg=0/6 nodes are available: 2 c_wall violated: 1 conflicting context pair(s) with node memory, 4 node(s) had untolerated taint(s). no new claims to deallocate, preemption: 0/6 nodes are available: 2 No preemption victims found for incoming pod, 4 Preemption is not helpful for scheduling."
19.0519,Job,MODIFIED,eval-sanitize-3-r3-018,
19.0566,Job,MODIFIED,eval-sanitize-3-r3-017,
19.0599,Event,ADDED,eval-sanitize-3-r3-019-svm65.18d3d2f937a0dbab,"reason=FailedScheduling count=None msg=0/6 nodes are available: 2 c_wall violated: 1 conflicting context pair(s) with node memory, 4 node(s) had untolerated taint(s). no new claims to deallocate, preemption: 0/6 nodes are available: 2 No preemption victims found for incoming pod, 4 Preemption is not helpful for scheduling."
19.0683,Job,MODIFIED,eval-sanitize-3-r3-018,
19.0687,Event,ADDED,eval-sanitize-3-r3-018-gz22z.18d3d2f937d8ae5f,"reason=Pulled count=1 msg=Container image ""busybox:musl"" already present on machine"
19.0694,Job,MODIFIED,eval-sanitize-3-r3-017,
19.0836,Event,ADDED,eval-sanitize-3-r3-018-gz22z.18d3d2f9391f2525,reason=Created count=1 msg=Created container: task
19.1328,Node,MODIFIED,kind-worker4,taints=1
19.1429,Pod,MODIFIED,eval-sanitize-3-r3-019-svm65,phase=Pending node=None
19.1432,Event,MODIFIED,eval-sanitize-3-r3-019-svm65.18d3d2f937a0dbab,"reason=FailedScheduling count=None msg=0/6 nodes are available: 2 c_wall violated: 1 conflicting context pair(s) with node memory, 4 node(s) had untolerated taint(s). no new claims to deallocate, preemption: 0/6 nodes are available: 2 No preemption victims found for incoming pod, 4 Preemption is not helpful for scheduling."
19.1475,Node,MODIFIED,kind-worker4,taints=1
19.1615,Event,ADDED,eval-sanitize-3-r3-018-gz22z.18d3d2f93dc3be7a,reason=Started count=1 msg=Started container task
19.2117,Event,ADDED,eval-sanitize-3-r3-019-svm65.18d3d2f940becdfb,"reason=FailedScheduling count=None msg=0/6 nodes are available: 1 c_wall violated: 1 conflicting context pair(s) with node memory, 5 node(s) had untolerated taint(s). no new claims to deallocate, preemption: 0/6 nodes are available: 1 No preemption victims found for incoming pod, 5 Preemption is not helpful for scheduling."
19.3696,Pod,MODIFIED,eval-sanitize-3-r3-018-gz22z,phase=Running node=kind-worker3
19.3811,Event,MODIFIED,eval-sanitize-3-r3-019-svm65.18d3d2f940becdfb,"reason=FailedScheduling count=None msg=0/6 nodes are available: 1 c_wall violated: 1 conflicting context pair(s) with node memory, 5 node(s) had untolerated taint(s). no new claims to deallocate, preemption: 0/6 nodes are available: 1 No preemption victims found for incoming pod, 5 Preemption is not helpful for scheduling."
19.4241,Job,MODIFIED,eval-sanitize-3-r3-005,
19.4285,Job,MODIFIED,eval-sanitize-3-r3-005,
19.4318,Event,ADDED,eval-sanitize-3-r3-005.18d3d2f94deae9a3,reason=Completed count=1 msg=Job completed
19.4413,Job,MODIFIED,eval-sanitize-3-r3-005,
19.445,TaskRequest,MODIFIED,eval-sanitize-3-r3-005,phase=Complete job=None
19.4563,Job,MODIFIED,eval-sanitize-3-r3-005,
20.0076,TaskRequest,ADDED,eval-sanitize-3-r3-020,phase=None job=None
20.0111,TaskRequest,MODIFIED,eval-sanitize-3-r3-020,phase=Pending job=None
20.0262,Job,ADDED,eval-sanitize-3-r3-020,
20.0333,Pod,ADDED,eval-sanitize-3-r3-020-7xstb,phase=Pending node=None
20.0348,TaskRequest,MODIFIED,eval-sanitize-3-r3-020,phase=Scheduled job=None
20.0356,Job,MODIFIED,eval-sanitize-3-r3-020,
20.0406,Event,ADDED,eval-sanitize-3-r3-020.18d3d2f971f2d5a8,reason=SuccessfulCreate count=1 msg=Created pod: eval-sanitize-3-r3-020-7xstb
20.042,Job,MODIFIED,eval-sanitize-3-r3-019,
20.044,Pod,MODIFIED,eval-sanitize-3-r3-020-7xstb,phase=Pending node=kind-worker3
20.0441,TaskRequest,MODIFIED,eval-sanitize-3-r3-020,phase=Scheduled job=None
20.0477,Event,ADDED,eval-sanitize-3-r3-020-7xstb.18d3d2f9728f8968,reason=Scheduled count=None msg=Successfully assigned compute/eval-sanitize-3-r3-020-7xstb to kind-worker3
20.0519,Job,MODIFIED,eval-sanitize-3-r3-019,
20.0547,Pod,MODIFIED,eval-sanitize-3-r3-020-7xstb,phase=Pending node=kind-worker3
20.0584,Job,MODIFIED,eval-sanitize-3-r3-018,
20.0676,Job,MODIFIED,eval-sanitize-3-r3-018,
20.4009,Node,MODIFIED,kind-worker5,taints=1
20.4228,Node,MODIFIED,kind-worker5,taints=1
20.4313,Node,MODIFIED,kind-worker5,taints=0
20.4408,Pod,MODIFIED,eval-sanitize-3-r3-019-svm65,phase=Pending node=kind-worker5
20.4443,Node,MODIFIED,kind-worker5,taints=0
20.4453,Event,ADDED,eval-sanitize-3-r3-019-svm65.18d3d2f98a375638,reason=Scheduled count=None msg=Successfully assigned compute/eval-sanitize-3-r3-019-svm65 to kind-worker5
20.4533,Pod,MODIFIED,eval-sanitize-3-r3-019-svm65,phase=Pending node=kind-worker5
20.4687,Node,MODIFIED,kind-worker5,taints=0
20.4692,Event,ADDED,eval-sanitize-3-r3-020-7xstb.18d3d2f98b9d6a0d,"reason=Pulled count=1 msg=Container image ""busybox:musl"" already present on machine"
20.4803,Node,MODIFIED,kind-worker5,taints=0
20.4901,Event,ADDED,eval-sanitize-3-r3-020-7xstb.18d3d2f98cfab1dc,reason=Created count=1 msg=Created container: task
20.5677,Event,ADDED,eval-sanitize-3-r3-020-7xstb.18d3d2f9917c6896,reason=Started count=1 msg=Started container task
20.8522,Event,ADDED,eval-sanitize-3-r3-019-svm65.18d3d2f9a280b781,"reason=Pulled count=1 msg=Container image ""busybox:musl"" already present on machine"
20.8721,Event,ADDED,eval-sanitize-3-r3-019-svm65.18d3d2f9a3b14be0,reason=Created count=1 msg=Created container: task
20.9426,Event,ADDED,eval-sanitize-3-r3-019-svm65.18d3d2f9a7e79d15,reason=Started count=1 msg=Started container task
21.0126,TaskRequest,ADDED,eval-sanitize-3-r3-021,phase=None job=None
21.0165,TaskRequest,MODIFIED,eval-sanitize-3-r3-021,phase=Pending job=None
21.0338,Job,ADDED,eval-sanitize-3-r3-021,
21.0382,Job,MODIFIED,eval-sanitize-3-r3-020,
21.0406,Pod,ADDED,eval-sanitize-3-r3-021-nbbns,phase=Pending node=None
21.0407,TaskRequest,MODIFIED,eval-sanitize-3-r3-021,phase=Scheduled job=None
21.0436,Job,MODIFIED,eval-sanitize-3-r3-021,
21.045,Event,ADDED,eval-sanitize-3-r3-021.18d3d2f9adfcfbe8,reason=SuccessfulCreate count=1 msg=Created pod: eval-sanitize-3-r3-021-nbbns
21.0475,TaskRequest,MODIFIED,eval-sanitize-3-r3-021,phase=Scheduled job=None
21.0504,Job,MODIFIED,eval-sanitize-3-r3-020,
21.0517,Pod,MODIFIED,eval-sanitize-3-r3-021-nbbns,phase=Pending node=kind-worker3
21.0575,Event,ADDED,eval-sanitize-3-r3-021-nbbns.18d3d2f9aea6f944,reason=Scheduled count=None msg=Successfully assigned compute/eval-sanitize-3-r3-021-nbbns to kind-worker3
21.1185,Node,MODIFIED,kind-worker3,taints=0
21.1228,Pod,MODIFIED,eval-sanitize-3-r3-021-nbbns,phase=Pending node=kind-worker3
21.1286,Node,MODIFIED,kind-worker3,taints=0
21.3809,Pod,MODIFIED,eval-sanitize-3-r3-020-7xstb,phase=Running node=kind-worker3
21.4236,Pod,MODIFIED,eval-sanitize-3-r3-019-svm65,phase=Running node=kind-worker5
21.4947,Event,ADDED,eval-sanitize-3-r3-021-nbbns.18d3d2f9c8ca68fa,"reason=Pulled count=1 msg=Container image ""busybox:musl"" already present on machine"
21.5146,Event,ADDED,eval-sanitize-3-r3-021-nbbns.18d3d2f9c9fdadb1,reason=Created count=1 msg=Created container: task
21.5489,Event,ADDED,eval-sanitize-3-r3-021-nbbns.18d3d2f9cc02d182,reason=Started count=1 msg=Started container task
21.7436,Node,MODIFIED,kind-worker3,taints=1
21.8389,Node,MODIFIED,kind-worker3,taints=1
22.0088,TaskRequest,ADDED,eval-sanitize-3-r3-022,phase=None job=None
22.0123,TaskRequest,MODIFIED,eval-sanitize-3-r3-022,phase=Pending job=None
22.0288,Job,ADDED,eval-sanitize-3-r3-022,
22.0357,TaskRequest,MODIFIED,eval-sanitize-3-r3-022,phase=Scheduled job=None
22.0373,Pod,ADDED,eval-sanitize-3-r3-022-xkvgt,phase=Pending node=None
22.0402,Job,MODIFIED,eval-sanitize-3-r3-022,
22.0444,Event,ADDED,eval-sanitize-3-r3-022.18d3d2f9e96575df,reason=SuccessfulCreate count=1 msg=Created pod: eval-sanitize-3-r3-022-xkvgt
22.0454,Job,MODIFIED,eval-sanitize-3-r3-020,
22.0467,Event,ADDED,eval-sanitize-3-r3-022-xkvgt.18d3d2f9e9ab2580,"reason=FailedScheduling count=None msg=0/6 nodes are available: 1 c_wall violated: 1 conflicting context pair(s) with node memory, 5 node(s) had untolerated taint(s). no new claims to deallocate, preemption: 0/6 nodes are available: 1 No preemption victims found for incoming pod, 5 Preemption is not helpful for scheduling."
22.0469,TaskRequest,MODIFIED,eval-sanitize-3-r3-022,phase=Scheduled job=None
22.0479,Job,MODIFIED,eval-sanitize-3-r3-021,
22.0492,Pod,MODIFIED,eval-sanitize-3-r3-022-xkvgt,phase=Pending node=None
22.0551,Job,MODIFIED,eval-sanitize-3-r3-020,
22.0566,Event,ADDED,eval-sanitize-3-r3-022-xkvgt.18d3d2f9ea4069b7,"reason=FailedScheduling count=None msg=0/6 nodes are available: 1 c_wall violated: 1 conflicting context pair(s) with node memory, 5 node(s) had untolerated taint(s). no new claims to deallocate, preemption: 0/6 nodes are available: 1 No preemption victims found for incoming pod, 5 Preemption is not helpful for scheduling."
22.0576,Job,MODIFIED,eval-sanitize-3-r3-021,
22.377,Pod,MODIFIED,eval-sanitize-3-r3-021-nbbns,phase=Running node=kind-worker3
22.3852,Event,MODIFIED,eval-sanitize-3-r3-022-xkvgt.18d3d2f9ea4069b7,"reason=FailedScheduling count=None msg=0/6 nodes are available: 1 c_wall violated: 1 conflicting context pair(s) with node memory, 5 node(s) had untolerated taint(s). no new claims to deallocate, preemption: 0/6 nodes are available: 1 No preemption victims found for incoming pod, 5 Preemption is not helpful for scheduling."
22.428,Job,MODIFIED,eval-sanitize-3-r3-019,
22.4373,Job,MODIFIED,eval-sanitize-3-r3-019,
23.0128,TaskRequest,ADDED,eval-sanitize-3-r3-023,phase=None job=None
23.019,TaskRequest,MODIFIED,eval-sanitize-3-r3-023,phase=Pending job=None
23.0351,Job,ADDED,eval-sanitize-3-r3-023,
23.0425,TaskRequest,MODIFIED,eval-sanitize-3-r3-023,phase=Scheduled job=None
23.0459,Job,MODIFIED,eval-sanitize-3-r3-022,
23.0468,Pod,ADDED,eval-sanitize-3-r3-023-7hhqc,phase=Pending node=None
23.0481,Job,MODIFIED,eval-sanitize-3-r3-023,
23.0532,Event,ADDED,eval-sanitize-3-r3-023.18d3d2fa258353c2,reason=SuccessfulCreate count=1 msg=Created pod: eval-sanitize-3-r3-023-7hhqc
23.0543,Job,MODIFIED,eval-sanitize-3-r3-021,
23.055,TaskRequest,MODIFIED,eval-sanitize-3-r3-023,phase=Scheduled job=None
23.0559,Job,MODIFIED,eval-sanitize-3-r3-022,
23.0574,Event,ADDED,eval-sanitize-3-r3-023-7hhqc.18d3d2fa25db21af,"reason=FailedScheduling count=None msg=0/6 nodes are available: 1 c_wall violated: 1 conflicting context pair(s) with node memory, 5 node(s) had untolerated taint(s). no new claims to deallocate, preemption: 0/6 nodes are available: 1 No preemption victims found for incoming pod, 5 Preemption is not helpful for scheduling."
23.0585,Pod,MODIFIED,eval-sanitize-3-r3-023-7hhqc,phase=Pending node=None
23.0639,Job,MODIFIED,eval-sanitize-3-r3-021,
23.0659,Event,ADDED,eval-sanitize-3-r3-023-7hhqc.18d3d2fa267e15ee,"reason=FailedScheduling count=None msg=0/6 nodes are available: 1 c_wall violated: 1 conflicting context pair(s) with node memory, 5 node(s) had untolerated taint(s). no new claims to deallocate, preemption: 0/6 nodes are available: 1 No preemption victims found for incoming pod, 5 Preemption is not helpful for scheduling."
23.4521,Node,MODIFIED,kind-worker5,taints=1
23.4577,Pod,MODIFIED,eval-sanitize-3-r3-022-xkvgt,phase=Pending node=None
23.4628,Pod,MODIFIED,eval-sanitize-3-r3-023-7hhqc,phase=Pending node=None
23.4648,Event,MODIFIED,eval-sanitize-3-r3-023-7hhqc.18d3d2fa267e15ee,"reason=FailedScheduling count=None msg=0/6 nodes are available: 1 c_wall violated: 1 conflicting context pair(s) with node memory, 5 node(s) had untolerated taint(s). no new claims to deallocate, preemption: 0/6 nodes are available: 1 No preemption victims found for incoming pod, 5 Preemption is not helpful for scheduling."
23.4663,Node,MODIFIED,kind-worker5,taints=1
24.0075,TaskRequest,ADDED,eval-sanitize-3-r3-024,phase=None job=None
24.0112,TaskRequest,MODIFIED,eval-sanitize-3-r3-024,phase=Pending job=None
24.0282,Job,ADDED,eval-sanitize-3-r3-024,
24.0356,Pod,ADDED,eval-sanitize-3-r3-024-7gkdr,phase=Pending node=None
24.0358,TaskRequest,MODIFIED,eval-sanitize-3-r3-024,phase=Scheduled job=None
24.038,Job,MODIFIED,eval-sanitize-3-r3-024,
24.0423,Event,ADDED,eval-sanitize-3-r3-024-7gkdr.18d3d2fa6086a1d2,"reason=FailedScheduling count=None msg=0/6 nodes are available: 6 node(s) had untolerated taint(s). no new claims to deallocate, preemption: 0/6 nodes are available: 6 Preemption is not helpful for scheduling."
24.0426,Event,ADDED,eval-sanitize-3-r3-024.18d3d2fa6088a001,reason=SuccessfulCreate count=1 msg=Created pod: eval-sanitize-3-r3-024-7gkdr
24.0437,Pod,MODIFIED,eval-sanitize-3-r3-024-7gkdr,phase=Pending node=None
24.044,TaskRequest,MODIFIED,eval-sanitize-3-r3-024,phase=Scheduled job=None
24.05,Job,MODIFIED,eval-sanitize-3-r3-023,
24.0587,Job,MODIFIED,eval-sanitize-3-r3-023,
25.0073,TaskRequest,ADDED,eval-sanitize-3-r3-025,phase=None job=None
25.0128,TaskRequest,MODIFIED,eval-sanitize-3-r3-025,phase=Pending job=None
25.0285,Job,ADDED,eval-sanitize-3-r3-025,
25.0356,Pod,ADDED,eval-sanitize-3-r3-025-mtstx,phase=Pending node=None
25.0385,Job,MODIFIED,eval-sanitize-3-r3-025,
25.0386,TaskRequest,MODIFIED,eval-sanitize-3-r3-025,phase=Scheduled job=None
25.041,Job,MODIFIED,eval-sanitize-3-r3-024,
25.0431,Event,ADDED,eval-sanitize-3-r3-025.18d3d2fa9c1dde3b,reason=SuccessfulCreate count=1 msg=Created pod: eval-sanitize-3-r3-025-mtstx
25.0434,Event,ADDED,eval-sanitize-3-r3-025-mtstx.18d3d2fa9c2e15ad,"reason=FailedScheduling count=None msg=0/6 nodes are available: 6 node(s) had untolerated taint(s). no new claims to deallocate, preemption: 0/6 nodes are available: 6 Preemption is not helpful for scheduling."
25.0443,Pod,MODIFIED,eval-sanitize-3-r3-025-mtstx,phase=Pending node=None
25.0468,TaskRequest,MODIFIED,eval-sanitize-3-r3-025,phase=Scheduled job=None
25.0496,Job,MODIFIED,eval-sanitize-3-r3-024,
26.0074,TaskRequest,ADDED,eval-sanitize-3-r3-026,phase=None job=None
26.0127,TaskRequest,MODIFIED,eval-sanitize-3-r3-026,phase=Pending job=None
26.0281,Job,ADDED,eval-sanitize-3-r3-026,
26.0356,Pod,ADDED,eval-sanitize-3-r3-026-mmf5k,phase=Pending node=None
26.0358,TaskRequest,MODIFIED,eval-sanitize-3-r3-026,phase=Scheduled job=None
26.0389,Job,MODIFIED,eval-sanitize-3-r3-026,
26.0412,Event,ADDED,eval-sanitize-3-r3-026.18d3d2fad7b18e41,reason=SuccessfulCreate count=1 msg=Created pod: eval-sanitize-3-r3-026-mmf5k
26.0422,Job,MODIFIED,eval-sanitize-3-r3-025,
26.0431,Pod,MODIFIED,eval-sanitize-3-r3-026-mmf5k,phase=Pending node=None
26.0434,Event,ADDED,eval-sanitize-3-r3-026-mmf5k.18d3d2fad7bdd2f1,"reason=FailedScheduling count=None msg=0/6 nodes are available: 6 node(s) had untolerated taint(s). no new claims to deallocate, preemption: 0/6 nodes are available: 6 Preemption is not helpful for scheduling."
26.0439,TaskRequest,MODIFIED,eval-sanitize-3-r3-026,phase=Scheduled job=None
26.0506,Job,MODIFIED,eval-sanitize-3-r3-025,
26.2279,Pod,MODIFIED,eval-sanitize-3-r3-012-bfdmn,phase=Running node=kind-worker2
26.2337,Pod,MODIFIED,eval-sanitize-3-r3-006-bjfc4,phase=Running node=kind-worker2
26.2413,Pod,MODIFIED,eval-sanitize-3-r3-014-mnwm8,phase=Running node=kind-worker2
26.8219,Pod,MODIFIED,eval-sanitize-3-r3-016-h5x2s,phase=Running node=kind-worker
26.8279,Pod,MODIFIED,eval-sanitize-3-r3-010-tnkj2,phase=Running node=kind-worker
26.8338,Pod,MODIFIED,eval-sanitize-3-r3-011-prswl,phase=Running node=kind-worker
26.84,Pod,MODIFIED,eval-sanitize-3-r3-008-jtwkx,phase=Running node=kind-worker
26.8465,Pod,MODIFIED,eval-sanitize-3-r3-013-77wdv,phase=Running node=kind-worker
26.8556,Pod,MODIFIED,eval-sanitize-3-r3-007-mt7xl,phase=Running node=kind-worker
26.8619,Pod,MODIFIED,eval-sanitize-3-r3-015-vwlfs,phase=Running node=kind-worker
26.8692,Pod,MODIFIED,eval-sanitize-3-r3-009-97txr,phase=Running node=kind-worker
27.0087,TaskRequest,ADDED,eval-sanitize-3-r3-027,phase=None job=None
27.0126,TaskRequest,MODIFIED,eval-sanitize-3-r3-027,phase=Pending job=None
27.0273,Job,ADDED,eval-sanitize-3-r3-027,
27.0317,TaskRequest,MODIFIED,eval-sanitize-3-r3-027,phase=Scheduled job=None
27.0355,Pod,ADDED,eval-sanitize-3-r3-027-4wfbw,phase=Pending node=None
27.0382,Job,MODIFIED,eval-sanitize-3-r3-027,
27.0405,Pod,MODIFIED,eval-sanitize-3-r3-027-4wfbw,phase=Pending node=None
27.0409,Event,ADDED,eval-sanitize-3-r3-027.18d3d2fb134ea03c,reason=SuccessfulCreate count=1 msg=Created pod: eval-sanitize-3-r3-027-4wfbw
27.041,TaskRequest,MODIFIED,eval-sanitize-3-r3-027,phase=Scheduled job=None
27.0413,Event,ADDED,eval-sanitize-3-r3-027-4wfbw.18d3d2fb1358c118,"reason=FailedScheduling count=None msg=0/6 nodes are available: 6 node(s) had untolerated taint(s). no new claims to deallocate, preemption: 0/6 nodes are available: 6 Preemption is not helpful for scheduling."
27.0423,Job,MODIFIED,eval-sanitize-3-r3-026,
27.0515,Job,MODIFIED,eval-sanitize-3-r3-026,
27.2344,Job,MODIFIED,eval-sanitize-3-r3-012,
27.2382,Job,MODIFIED,eval-sanitize-3-r3-006,
27.244,Job,MODIFIED,eval-sanitize-3-r3-012,
27.2464,Job,MODIFIED,eval-sanitize-3-r3-014,
27.2493,Job,MODIFIED,eval-sanitize-3-r3-006,
27.259,Job,MODIFIED,eval-sanitize-3-r3-014,
27.3136,Pod,MODIFIED,eval-sanitize-3-r3-006-bjfc4,phase=Succeeded node=kind-worker2
27.3585,Pod,MODIFIED,eval-sanitize-3-r3-014-mnwm8,phase=Succeeded node=kind-worker2
27.3692,Pod,MODIFIED,eval-sanitize-3-r3-012-bfdmn,phase=Succeeded node=kind-worker2
27.7219,Node,MODIFIED,kind-worker2,taints=1
27.7356,Node,MODIFIED,kind-worker2,taints=1
27.7439,Node,MODIFIED,kind-worker2,taints=0
27.75,Pod,MODIFIED,eval-sanitize-3-r3-022-xkvgt,phase=Pending node=kind-worker2
27.7538,Pod,MODIFIED,eval-sanitize-3-r3-023-7hhqc,phase=Pending node=None
27.757,Event,ADDED,eval-sanitize-3-r3-023-7hhqc.18d3d2fb3dcd2055,"reason=FailedScheduling count=None msg=0/6 nodes are available: 1 c_wall violated: 1 conflicting context pair(s) with node memory, 5 node(s) had untolerated taint(s). no new claims to deallocate, preemption: 0/6 nodes are available: 1 No preemption victims found for incoming pod, 5 Preemption is not helpful for scheduling."
27.7574,Event,ADDED,eval-sanitize-3-r3-022-xkvgt.18d3d2fb3de748ec,reason=Scheduled count=None msg=Successfully assigned compute/eval-sanitize-3-r3-022-xkvgt to kind-worker2
27.7616,Node,MODIFIED,kind-worker2,taints=0
27.7638,Pod,MODIFIED,eval-sanitize-3-r3-024-7gkdr,phase=Pending node=kind-worker2
27.765,Pod,MODIFIED,eval-sanitize-3-r3-022-xkvgt,phase=Pending node=kind-worker2
27.7689,Pod,MODIFIED,eval-sanitize-3-r3-025-mtstx,phase=Pending node=kind-worker2
27.7708,Pod,MODIFIED,eval-sanitize-3-r3-026-mmf5k,phase=Pending node=None
27.7748,Event,ADDED,eval-sanitize-3-r3-024-7gkdr.18d3d2fb3ebda829,reason=Scheduled count=None msg=Successfully assigned compute/eval-sanitize-3-r3-024-7gkdr to kind-worker2
27.7753,Event,ADDED,eval-sanitize-3-r3-026-mmf5k.18d3d2fb3ebf9163,"reason=FailedScheduling count=None msg=0/6 nodes are available: 1 c_wall violated: 2 conflicting context pair(s) with node memory, 5 node(s) had untolerated taint(s). no new claims to deallocate, preemption: 0/6 nodes are available: 1 No preemption victims found for incoming pod, 5 Preemption is not helpful for scheduling."
27.7757,Event,ADDED,eval-sanitize-3-r3-025-mtstx.18d3d2fb3ee2c4b9,reason=Scheduled count=None msg=Successfully assigned compute/eval-sanitize-3-r3-025-mtstx to kind-worker2
27.7789,Node,MODIFIED,kind-worker2,taints=0
27.7847,Pod,MODIFIED,eval-sanitize-3-r3-027-4wfbw,phase=Pending node=kind-worker2
27.7851,Event,ADDED,eval-sanitize-3-r3-023-7hhqc.18d3d2fb3fa412c9,"reason=FailedScheduling count=None msg=0/6 nodes are available: 1 c_wall violated: 1 conflicting context pair(s) with node memory, 5 node(s) had untolerated taint(s). no new claims to deallocate, preemption: 0/6 nodes are available: 1 No preemption victims found for incoming pod, 5 Preemption is not helpful for scheduling."
27.7864,Pod,MODIFIED,eval-sanitize-3-r3-024-7gkdr,phase=Pending node=kind-worker2
27.7907,Node,MODIFIED,kind-worker2,taints=0
27.7917,Event,ADDED,eval-sanitize-3-r3-027-4wfbw.18d3d2fb3ff0648f,reason=Scheduled count=None msg=Successfully assigned compute/eval-sanitize-3-r3-027-4wfbw to kind-worker2
27.7932,Pod,MODIFIED,eval-sanitize-3-r3-025-mtstx,phase=Pending node=kind-worker2
27.799,Pod,MODIFIED,eval-sanitize-3-r3-027-4wfbw,phase=Pending node=kind-worker2
27.8132,Node,MODIFIED,kind-worker2,taints=0
27.8244,Node,MODIFIED,kind-worker2,taints=0
27.8252,Event,ADDED,eval-sanitize-3-r3-026-mmf5k.18d3d2fb41ecdb5f,"reason=FailedScheduling count=None msg=0/6 nodes are available: 1 c_wall violated: 2 conflicting context pair(s) with node memory, 5 node(s) had untolerated taint(s). no new claims to deallocate, preemption: 0/6 nodes are available: 1 No preemption victims found for incoming pod, 5 Preemption is not helpful for scheduling."
27.8289,Job,MODIFIED,eval-sanitize-3-r3-016,
27.8317,Event,MODIFIED,eval-sanitize-3-r3-023-7hhqc.18d3d2fb3fa412c9,"reason=FailedScheduling count=None msg=0/6 nodes are available: 1 c_wall violated: 1 conflicting context pair(s) with node memory, 5 node(s) had untolerated taint(s). no new claims to deallocate, preemption: 0/6 nodes are available: 1 No preemption victims found for incoming pod, 5 Preemption is not helpful for scheduling."
27.8341,Event,MODIFIED,eval-sanitize-3-r3-026-mmf5k.18d3d2fb41ecdb5f,"reason=FailedScheduling count=None msg=0/6 nodes are available: 1 c_wall violated: 2 conflicting context pair(s) with node memory, 5 node(s) had untolerated taint(s). no new claims to deallocate, preemption: 0/6 nodes are available: 1 No preemption victims found for incoming pod, 5 Preemption is not helpful for scheduling."
27.836,Job,MODIFIED,eval-sanitize-3-r3-010,
27.8437,Job,MODIFIED,eval-sanitize-3-r3-011,
27.8449,Job,MODIFIED,eval-sanitize-3-r3-016,
27.8476,Job,MODIFIED,eval-sanitize-3-r3-008,
27.8499,Job,MODIFIED,eval-sanitize-3-r3-010,
27.8517,Job,MODIFIED,eval-sanitize-3-r3-013,
27.8543,Job,MODIFIED,eval-sanitize-3-r3-011,
27.8564,Job,MODIFIED,eval-sanitize-3-r3-008,
27.8596,Job,MODIFIED,eval-sanitize-3-r3-007,
27.862,Job,MODIFIED,eval-sanitize-3-r3-013,
27.8668,Job,MODIFIED,eval-sanitize-3-r3-015,
27.8738,Job,MODIFIED,eval-sanitize-3-r3-009,
27.8965,Node,MODIFIED,kind-worker2,taints=0
27.9078,Node,MODIFIED,kind-worker2,taints=0
28.0066,Pod,MODIFIED,eval-sanitize-3-r3-011-prswl,phase=Succeeded node=kind-worker
28.0075,TaskRequest,ADDED,eval-sanitize-3-r3-028,phase=None job=None
28.0286,TaskRequest,MODIFIED,eval-sanitize-3-r3-028,phase=Pending job=None
28.0355,Job,MODIFIED,eval-sanitize-3-r3-007,
28.0415,Job,MODIFIED,eval-sanitize-3-r3-027,
28.0456,Job,ADDED,eval-sanitize-3-r3-028,
28.0509,TaskRequest,MODIFIED,eval-sanitize-3-r3-028,phase=Scheduled job=None
28.0556,Pod,ADDED,eval-sanitize-3-r3-028-cq5fx,phase=Pending node=None
28.0627,Job,MODIFIED,eval-sanitize-3-r3-028,
28.0632,Event,ADDED,eval-sanitize-3-r3-028.18d3d2fb501fbe16,reason=SuccessfulCreate count=1 msg=Created pod: eval-sanitize-3-r3-028-cq5fx
28.068,Pod,MODIFIED,eval-sanitize-3-r3-028-cq5fx,phase=Pending node=kind-worker2
28.0718,Event,ADDED,eval-sanitize-3-r3-028-cq5fx.18d3d2fb50d7971a,reason=Scheduled count=None msg=Successfully assigned compute/eval-sanitize-3-r3-028-cq5fx to kind-worker2
28.0819,Pod,MODIFIED,eval-sanitize-3-r3-028-cq5fx,phase=Pending node=kind-worker2
28.1314,TaskRequest,MODIFIED,eval-sanitize-3-r3-028,phase=Scheduled job=None
28.1378,Job,MODIFIED,eval-sanitize-3-r3-015,
28.1386,Job,MODIFIED,eval-sanitize-3-r3-009,
28.1436,Job,MODIFIED,eval-sanitize-3-r3-027,
28.1443,Job,MODIFIED,eval-sanitize-3-r3-028,
28.1511,Pod,MODIFIED,eval-sanitize-3-r3-013-77wdv,phase=Succeeded node=kind-worker
28.1603,Job,MODIFIED,eval-sanitize-3-r3-028,
28.1634,Pod,MODIFIED,eval-sanitize-3-r3-009-97txr,phase=Succeeded node=kind-worker
28.1722,Pod,MODIFIED,eval-sanitize-3-r3-015-vwlfs,phase=Succeeded node=kind-worker
28.184,Pod,MODIFIED,eval-sanitize-3-r3-010-tnkj2,phase=Succeeded node=kind-worker
28.1911,Pod,MODIFIED,eval-sanitize-3-r3-016-h5x2s,phase=Succeeded node=kind-worker
28.1996,Pod,MODIFIED,eval-sanitize-3-r3-007-mt7xl,phase=Succeeded node=kind-worker
28.2111,Pod,MODIFIED,eval-sanitize-3-r3-008-jtwkx,phase=Succeeded node=kind-worker
28.2117,Event,ADDED,eval-sanitize-3-r3-022-xkvgt.18d3d2fb58d48720,"reason=Pulled count=1 msg=Container image ""busybox:musl"" already present on machine"
28.2278,Event,ADDED,eval-sanitize-3-r3-024-7gkdr.18d3d2fb59d7edc3,"reason=Pulled count=1 msg=Container image ""busybox:musl"" already present on machine"
28.2319,Event,ADDED,eval-sanitize-3-r3-025-mtstx.18d3d2fb5a1fbb7a,"reason=Pulled count=1 msg=Container image ""busybox:musl"" already present on machine"
28.2365,Event,ADDED,eval-sanitize-3-r3-027-4wfbw.18d3d2fb5a98dfde,"reason=Pulled count=1 msg=Container image ""busybox:musl"" already present on machine"
28.2426,Job,MODIFIED,eval-sanitize-3-r3-012,
28.2458,Event,ADDED,eval-sanitize-3-r3-022-xkvgt.18d3d2fb5a9cac9e,reason=Created count=1 msg=Created container: task
28.2468,Job,MODIFIED,eval-sanitize-3-r3-006,
28.2608,Pod,MODIFIED,eval-sanitize-3-r3-012-bfdmn,phase=Succeeded node=kind-worker2
28.264,Pod,MODIFIED,eval-sanitize-3-r3-006-bjfc4,phase=Succeeded node=kind-worker2
28.2649,Job,MODIFIED,eval-sanitize-3-r3-014,
28.2661,Job,MODIFIED,eval-sanitize-3-r3-012,
28.268,Job,MODIFIED,eval-sanitize-3-r3-006,
28.2804,Pod,MODIFIED,eval-sanitize-3-r3-014-mnwm8,phase=Succeeded node=kind-worker2
28.2861,Event,ADDED,eval-sanitize-3-r3-024-7gkdr.18d3d2fb5d02b87e,reason=Created count=1 msg=Created container: task
28.2878,Job,MODIFIED,eval-sanitize-3-r3-014,
28.2915,Event,ADDED,eval-sanitize-3-r3-025-mtstx.18d3d2fb5d898675,reason=Created count=1 msg=Created container: task
28.2963,Event,ADDED,eval-sanitize-3-r3-027-4wfbw.18d3d2fb5dbab45b,reason=Created count=1 msg=Created container: task
28.3098,Event,ADDED,eval-sanitize-3-r3-022-xkvgt.18d3d2fb5ee6a03d,reason=Started count=1 msg=Started container task
28.3299,Event,ADDED,eval-sanitize-3-r3-024-7gkdr.18d3d2fb602f3601,reason=Started count=1 msg=Started container task
28.3356,Event,ADDED,eval-sanitize-3-r3-025-mtstx.18d3d2fb60a470d2,reason=Started count=1 msg=Started container task
28.3391,Event,ADDED,eval-sanitize-3-r3-027-4wfbw.18d3d2fb60a470eb,reason=Started count=1 msg=Started container task
28.3732,Pod,MODIFIED,eval-sanitize-3-r3-017-g2ttz,phase=Running node=kind-worker4
28.492,Event,ADDED,eval-sanitize-3-r3-028-cq5fx.18d3d2fb69cb7052,"reason=Pulled count=1 msg=Container image ""busybox:musl"" already present on machine"
28.5087,Event,ADDED,eval-sanitize-3-r3-028-cq5fx.18d3d2fb6af0a09b,reason=Created count=1 msg=Created container: task
28.5733,Event,ADDED,eval-sanitize-3-r3-028-cq5fx.18d3d2fb6ec44a5f,reason=Started count=1 msg=Started container task
28.8349,Job,MODIFIED,eval-sanitize-3-r3-016,
28.8414,Job,MODIFIED,eval-sanitize-3-r3-010,
28.8446,Pod,MODIFIED,eval-sanitize-3-r3-016-h5x2s,phase=Succeeded node=kind-worker
28.8469,Job,MODIFIED,eval-sanitize-3-r3-016,
28.8506,Job,MODIFIED,eval-sanitize-3-r3-011,
28.8534,Job,MODIFIED,eval-sanitize-3-r3-010,
28.8543,Job,MODIFIED,eval-sanitize-3-r3-008,
28.8558,Pod,MODIFIED,eval-sanitize-3-r3-010-tnkj2,phase=Succeeded node=kind-worker
28.8575,Job,MODIFIED,eval-sanitize-3-r3-013,
28.8608,Pod,MODIFIED,eval-sanitize-3-r3-011-prswl,phase=Succeeded node=kind-worker
28.8627,Job,MODIFIED,eval-sanitize-3-r3-011,
28.8643,Pod,MODIFIED,eval-sanitize-3-r3-008-jtwkx,phase=Succeeded node=kind-worker
28.8652,Job,MODIFIED,eval-sanitize-3-r3-008,
28.8664,Job,MODIFIED,eval-sanitize-3-r3-007,
28.8676,Pod,MODIFIED,eval-sanitize-3-r3-013-77wdv,phase=Succeeded node=kind-worker
28.8688,Job,MODIFIED,eval-sanitize-3-r3-013,
28.8715,Job,MODIFIED,eval-sanitize-3-r3-015,
28.8742,Pod,MODIFIED,eval-sanitize-3-r3-007-mt7xl,phase=Succeeded node=kind-worker
28.8762,Job,MODIFIED,eval-sanitize-3-r3-007,
28.8789,Job,MODIFIED,eval-sanitize-3-r3-009,
28.8802,Pod,MODIFIED,eval-sanitize-3-r3-015-vwlfs,phase=Succeeded node=kind-worker
28.8813,Job,MODIFIED,eval-sanitize-3-r3-015,
28.8869,Pod,MODIFIED,eval-sanitize-3-r3-009-97txr,phase=Succeeded node=kind-worker
28.8906,Job,MODIFIED,eval-sanitize-3-r3-009,
28.8937,Event,ADDED,eval-sanitize-3-r3-009.18d3d2fb81e76ffa,reason=Completed count=1 msg=Job completed
28.9289,Job,MODIFIED,eval-sanitize-3-r3-009,
28.9341,TaskRequest,MODIFIED,eval-sanitize-3-r3-009,phase=Complete job=None
28.944,Job,MODIFIED,eval-sanitize-3-r3-009,
29.0071,TaskRequest,ADDED,eval-sanitize-3-r3-029,phase=None job=None
29.0118,TaskRequest,MODIFIED,eval-sanitize-3-r3-029,phase=Pending job=None
29.0286,Job,ADDED,eval-sanitize-3-r3-029,
29.0341,Pod,ADDED,eval-sanitize-3-r3-029-8klt2,phase=Pending node=None
29.0361,TaskRequest,MODIFIED,eval-sanitize-3-r3-029,phase=Scheduled job=None
29.0394,Job,MODIFIED,eval-sanitize-3-r3-029,
29.0397,Event,ADDED,eval-sanitize-3-r3-029.18d3d2fb8a7635f6,reason=SuccessfulCreate count=1 msg=Created pod: eval-sanitize-3-r3-029-8klt2
29.0429,Pod,MODIFIED,eval-sanitize-3-r3-029-8klt2,phase=Pending node=None
29.0432,Event,ADDED,eval-sanitize-3-r3-029-8klt2.18d3d2fb8ab9a8ae,"reason=FailedScheduling count=None msg=0/6 nodes are available: 1 c_wall violated: 2 conflicting context pair(s) with node memory, 5 node(s) had untolerated taint(s). no new claims to deallocate, preemption: 0/6 nodes are available: 1 No preemption victims found for incoming pod, 5 Preemption is not helpful for scheduling."
29.0448,TaskRequest,MODIFIED,eval-sanitize-3-r3-029,phase=Scheduled job=None
29.0499,Event,ADDED,eval-sanitize-3-r3-029-8klt2.18d3d2fb8b369acc,"reason=FailedScheduling count=None msg=0/6 nodes are available: 1 c_wall violated: 2 conflicting context pair(s) with node memory, 5 node(s) had untolerated taint(s). no new claims to deallocate, preemption: 0/6 nodes are available: 1 No preemption victims found for incoming pod, 5 Preemption is not helpful for scheduling."
29.2413,Pod,MODIFIED,eval-sanitize-3-r3-022-xkvgt,phase=Running node=kind-worker2
29.2485,Pod,MODIFIED,eval-sanitize-3-r3-024-7gkdr,phase=Running node=kind-worker2
29.2503,Job,MODIFIED,eval-sanitize-3-r3-012,
29.2521,Job,MODIFIED,eval-sanitize-3-r3-006,
29.255,Job,MODIFIED,eval-sanitize-3-r3-012,
29.258,Job,MODIFIED,eval-sanitize-3-r3-006,
29.2595,Pod,MODIFIED,eval-sanitize-3-r3-025-mtstx,phase=Running node=kind-worker2
29.261,Event,MODIFIED,eval-sanitize-3-r3-029-8klt2.18d3d2fb8b369acc,"reason=FailedScheduling count=None msg=0/6 nodes are available: 1 c_wall violated: 2 conflicting context pair(s) with node memory, 5 node(s) had untolerated taint(s). no new claims to deallocate, preemption: 0/6 nodes are available: 1 No preemption victims found for incoming pod, 5 Preemption is not helpful for scheduling."
29.2613,Event,ADDED,eval-sanitize-3-r3-012.18d3d2fb97a1b902,reason=Completed count=1 msg=Job completed
29.2681,Pod,MODIFIED,eval-sanitize-3-r3-027-4wfbw,phase=Running node=kind-worker2
29.2686,Event,ADDED,eval-sanitize-3-r3-006.18d3d2fb97c9b571,reason=Completed count=1 msg=Job completed
29.2697,Job,MODIFIED,eval-sanitize-3-r3-014,
29.271,Job,MODIFIED,eval-sanitize-3-r3-012,
29.273,Job,MODIFIED,eval-sanitize-3-r3-006,
29.2776,Pod,MODIFIED,eval-sanitize-3-r3-028-cq5fx,phase=Running node=kind-worker2
29.2795,Job,MODIFIED,eval-sanitize-3-r3-014,
29.2797,TaskRequest,MODIFIED,eval-sanitize-3-r3-012,phase=Complete job=None
29.2802,Event,ADDED,eval-sanitize-3-r3-014.18d3d2fb98dd3db7,reason=Completed count=1 msg=Job completed
29.2851,TaskRequest,MODIFIED,eval-sanitize-3-r3-006,phase=Complete job=None
29.2926,Job,MODIFIED,eval-sanitize-3-r3-012,
29.2943,Job,MODIFIED,eval-sanitize-3-r3-014,
29.2961,Job,MODIFIED,eval-sanitize-3-r3-006,
29.3252,TaskRequest,MODIFIED,eval-sanitize-3-r3-014,phase=Complete job=None
29.335,Job,MODIFIED,eval-sanitize-3-r3-014,
29.3793,Job,MODIFIED,eval-sanitize-3-r3-017,
29.3888,Job,MODIFIED,eval-sanitize-3-r3-017,
29.3937,Pod,MODIFIED,eval-sanitize-3-r3-018-gz22z,phase=Running node=kind-worker3
29.4695,Pod,MODIFIED,eval-sanitize-3-r3-017-g2ttz,phase=Succeeded node=kind-worker4
29.8411,Job,MODIFIED,eval-sanitize-3-r3-016,
29.8459,Job,MODIFIED,eval-sanitize-3-r3-016,
29.8477,Job,MODIFIED,eval-sanitize-3-r3-010,
29.8516,Event,ADDED,eval-sanitize-3-r3-016.18d3d2fbbad9f584,reason=Completed count=1 msg=Job completed
29.8526,Job,MODIFIED,eval-sanitize-3-r3-010,
29.8543,Job,MODIFIED,eval-sanitize-3-r3-011,
29.8569,Job,MODIFIED,eval-sanitize-3-r3-016,
29.8584,Event,ADDED,eval-sanitize-3-r3-010.18d3d2fbbb3d9480,reason=Completed count=1 msg=Job completed
29.8592,Job,MODIFIED,eval-sanitize-3-r3-008,
29.86,Job,MODIFIED,eval-sanitize-3-r3-011,
29.8624,Job,MODIFIED,eval-sanitize-3-r3-013,
29.864,Event,ADDED,eval-sanitize-3-r3-011.18d3d2fbbba20b17,reason=Completed count=1 msg=Job completed
29.8642,TaskRequest,MODIFIED,eval-sanitize-3-r3-016,phase=Complete job=None
29.8669,Job,MODIFIED,eval-sanitize-3-r3-010,
29.8713,Job,MODIFIED,eval-sanitize-3-r3-011,
29.8738,Job,MODIFIED,eval-sanitize-3-r3-016,
29.8753,TaskRequest,MODIFIED,eval-sanitize-3-r3-010,phase=Complete job=None
29.8762,Job,MODIFIED,eval-sanitize-3-r3-008,
29.8769,Job,MODIFIED,eval-sanitize-3-r3-013,
29.8782,TaskRequest,MODIFIED,eval-sanitize-3-r3-011,phase=Complete job=None
29.9303,Job,MODIFIED,eval-sanitize-3-r3-010,
29.9316,Job,MODIFIED,eval-sanitize-3-r3-011,
29.9773,Job,MODIFIED,eval-sanitize-3-r3-007,
29.9867,Job,MODIFIED,eval-sanitize-3-r3-007,
30.0219,TaskRequest,ADDED,eval-sanitize-3-r3-030,phase=None job=None
30.0271,Job,MODIFIED,eval-sanitize-3-r3-015,
30.0272,TaskRequest,MODIFIED,eval-sanitize-3-r3-030,phase=Pending job=None
30.0427,Job,ADDED,eval-sanitize-3-r3-030,
30.0471,TaskRequest,MODIFIED,eval-sanitize-3-r3-030,phase=Scheduled job=None
30.0518,Job,MODIFIED,eval-sanitize-3-r3-030,
30.0536,TaskRequest,MODIFIED,eval-sanitize-3-r3-030,phase=Scheduled job=None
30.0565,Job,MODIFIED,eval-sanitize-3-r3-015,
30.1775,Job,MODIFIED,eval-sanitize-3-r3-029,
30.1861,Job,MODIFIED,eval-sanitize-3-r3-029,
30.2317,Pod,ADDED,eval-sanitize-3-r3-030-rddvq,phase=Pending node=None
30.2405,Pod,MODIFIED,eval-sanitize-3-r3-030-rddvq,phase=Pending node=None
30.2408,Event,ADDED,eval-sanitize-3-r3-030-rddvq.18d3d2fbd2021725,"reason=FailedScheduling count=None msg=0/6 nodes are available: 1 c_wall violated: 2 conflicting context pair(s) with node memory, 5 node(s) had untolerated taint(s). no new claims to deallocate, preemption: 0/6 nodes are available: 1 No preemption victims found for incoming pod, 5 Preemption is not helpful for scheduling."
30.2486,Event,ADDED,eval-sanitize-3-r3-030-rddvq.18d3d2fbd2831ba9,"reason=FailedScheduling count=None msg=0/6 nodes are available: 1 c_wall violated: 2 conflicting context pair(s) with node memory, 5 node(s) had untolerated taint(s). no new claims to deallocate, preemption: 0/6 nodes are available: 1 No preemption victims found for incoming pod, 5 Preemption is not helpful for scheduling."
30.2762,Event,ADDED,eval-sanitize-3-r3-030.18d3d2fbd1cb5bc2,reason=SuccessfulCreate count=1 msg=Created pod: eval-sanitize-3-r3-030-rddvq
30.3774,Job,MODIFIED,eval-sanitize-3-r3-022,
30.3876,Job,MODIFIED,eval-sanitize-3-r3-022,
30.4277,Job,MODIFIED,eval-sanitize-3-r3-024,
30.4368,Job,MODIFIED,eval-sanitize-3-r3-024,
30.4781,Pod,MODIFIED,eval-sanitize-3-r3-018-gz22z,phase=Succeeded node=kind-worker3
30.4789,Job,MODIFIED,eval-sanitize-3-r3-025,
30.4882,Job,MODIFIED,eval-sanitize-3-r3-025,
30.4952,Event,MODIFIED,eval-sanitize-3-r3-030-rddvq.18d3d2fbd2831ba9,"reason=FailedScheduling count=None msg=0/6 nodes are available: 1 c_wall violated: 2 conflicting context pair(s) with node memory, 5 node(s) had untolerated taint(s). no new claims to deallocate, preemption: 0/6 nodes are available: 1 No preemption victims found for incoming pod, 5 Preemption is not helpful for scheduling."
30.5267,Job,MODIFIED,eval-sanitize-3-r3-027,
30.5373,Job,MODIFIED,eval-sanitize-3-r3-027,
30.5779,Job,MODIFIED,eval-sanitize-3-r3-028,
30.5883,Job,MODIFIED,eval-sanitize-3-r3-028,
30.6265,Job,MODIFIED,eval-sanitize-3-r3-017,
30.6351,Job,MODIFIED,eval-sanitize-3-r3-017,
30.6778,Job,MODIFIED,eval-sanitize-3-r3-018,
30.6867,Job,MODIFIED,eval-sanitize-3-r3-018,
30.7309,Pod,MODIFIED,eval-sanitize-3-r3-017-g2ttz,phase=Succeeded node=kind-worker4
30.7632,Node,MODIFIED,kind-worker2,taints=1
30.7676,Pod,MODIFIED,eval-sanitize-3-r3-029-8klt2,phase=Pending node=None
30.7727,Pod,MODIFIED,eval-sanitize-3-r3-026-mmf5k,phase=Pending node=None
30.7753,Node,MODIFIED,kind-worker2,taints=1
30.7772,Pod,MODIFIED,eval-sanitize-3-r3-023-7hhqc,phase=Pending node=None
30.7817,Pod,MODIFIED,eval-sanitize-3-r3-030-rddvq,phase=Pending node=None
30.8676,Job,MODIFIED,eval-sanitize-3-r3-008,
30.8707,TaskRequest,MODIFIED,eval-sanitize-3-r3-008,phase=Complete job=None
30.877,Job,MODIFIED,eval-sanitize-3-r3-013,
30.8796,Job,MODIFIED,eval-sanitize-3-r3-008,
30.8822,TaskRequest,MODIFIED,eval-sanitize-3-r3-013,phase=Complete job=None
30.8904,Job,MODIFIED,eval-sanitize-3-r3-013,
30.926,Event,ADDED,eval-sanitize-3-r3-008.18d3d2fbf7a9c58d,reason=Completed count=1 msg=Job completed
30.9776,Event,ADDED,eval-sanitize-3-r3-013.18d3d2fbf83e99ff,reason=Completed count=1 msg=Job completed
31.0064,TaskRequest,ADDED,eval-sanitize-3-r3-031,phase=None job=None
31.0098,TaskRequest,MODIFIED,eval-sanitize-3-r3-031,phase=Pending job=None
31.0252,Job,ADDED,eval-sanitize-3-r3-031,
31.0275,Job,MODIFIED,eval-sanitize-3-r3-007,
31.0298,TaskRequest,MODIFIED,eval-sanitize-3-r3-031,phase=Scheduled job=None
31.034,Job,MODIFIED,eval-sanitize-3-r3-031,
31.0358,TaskRequest,MODIFIED,eval-sanitize-3-r3-007,phase=Complete job=None
31.0369,TaskRequest,MODIFIED,eval-sanitize-3-r3-031,phase=Scheduled job=None
31.0453,Job,MODIFIED,eval-sanitize-3-r3-007,
31.0778,Pod,ADDED,eval-sanitize-3-r3-031-4fnvg,phase=Pending node=None
31.0835,Pod,MODIFIED,eval-sanitize-3-r3-031-4fnvg,phase=Pending node=None
31.085,Event,ADDED,eval-sanitize-3-r3-031-4fnvg.18d3d2fc04477fe8,"reason=FailedScheduling count=None msg=0/6 nodes are available: 6 node(s) had untolerated taint(s). no new claims to deallocate, preemption: 0/6 nodes are available: 6 Preemption is not helpful for scheduling."
31.1261,Node,MODIFIED,kind-worker,taints=1
31.1278,Job,MODIFIED,eval-sanitize-3-r3-015,
31.1321,TaskRequest,MODIFIED,eval-sanitize-3-r3-015,phase=Complete job=None
31.1439,Node,MODIFIED,kind-worker,taints=0
31.1454,Job,MODIFIED,eval-sanitize-3-r3-015,
31.1524,Pod,MODIFIED,eval-sanitize-3-r3-029-8klt2,phase=Pending node=kind-worker
31.1533,Pod,MODIFIED,eval-sanitize-3-r3-026-mmf5k,phase=Pending node=kind-worker
31.156,Pod,MODIFIED,eval-sanitize-3-r3-023-7hhqc,phase=Pending node=None
31.1597,Event,ADDED,eval-sanitize-3-r3-023-7hhqc.18d3d2fc0888742e,"reason=FailedScheduling count=None msg=0/6 nodes are available: 1 c_wall violated: 1 conflicting context pair(s) with node memory, 5 node(s) had untolerated taint(s). no new claims to deallocate, preemption: 0/6 nodes are available: 1 No preemption victims found for incoming pod, 5 Preemption is not helpful for scheduling."
31.16,Event,ADDED,eval-sanitize-3-r3-029-8klt2.18d3d2fc08a2e152,reason=Scheduled count=None msg=Successfully assigned compute/eval-sanitize-3-r3-029-8klt2 to kind-worker
31.1601,Event,ADDED,eval-sanitize-3-r3-026-mmf5k.18d3d2fc08a2794a,reason=Scheduled count=None msg=Successfully assigned compute/eval-sanitize-3-r3-026-mmf5k to kind-worker
31.1671,Node,MODIFIED,kind-worker,taints=0
31.1688,Event,ADDED,eval-sanitize-3-r3-031-4fnvg.18d3d2fc09497957,"reason=FailedScheduling count=None msg=0/6 nodes are available: 1 c_wall violated: 1 conflicting context pair(s) with node memory, 5 node(s) had untolerated taint(s). no new claims to deallocate, preemption: 0/6 nodes are available: 1 No preemption victims found for incoming pod, 5 Preemption is not helpful for scheduling."
31.1701,Pod,MODIFIED,eval-sanitize-3-r3-030-rddvq,phase=Pending node=kind-worker
31.1713,Pod,MODIFIED,eval-sanitize-3-r3-029-8klt2,phase=Pending node=kind-worker
31.1724,Pod,MODIFIED,eval-sanitize-3-r3-031-4fnvg,phase=Pending node=None
31.1729,Event,ADDED,eval-sanitize-3-r3-030-rddvq.18d3d2fc09a777fb,reason=Scheduled count=None msg=Successfully assigned compute/eval-sanitize-3-r3-030-rddvq to kind-worker
31.1769,Pod,MODIFIED,eval-sanitize-3-r3-026-mmf5k,phase=Pending node=kind-worker
31.1786,Event,ADDED,eval-sanitize-3-r3-007.18d3d2fc0136b7e9,reason=Completed count=1 msg=Job completed
31.1797,Pod,MODIFIED,eval-sanitize-3-r3-023-7hhqc,phase=Pending node=None
31.1814,Event,ADDED,eval-sanitize-3-r3-023-7hhqc.18d3d2fc09eac443,"reason=FailedScheduling count=None msg=0/6 nodes are available: 1 c_wall violated: 2 conflicting context pair(s) with node memory, 5 node(s) had untolerated taint(s). no new claims to deallocate, preemption: 0/6 nodes are available: 1 No preemption victims found for incoming pod, 5 Preemption is not helpful for scheduling."
31.183,Node,MODIFIED,kind-worker,taints=0
31.1859,Pod,MODIFIED,eval-sanitize-3-r3-030-rddvq,phase=Pending node=kind-worker
31.1872,Event,ADDED,eval-sanitize-3-r3-031-4fnvg.18d3d2fc0a8298d2,"reason=FailedScheduling count=None msg=0/6 nodes are available: 1 c_wall violated: 1 conflicting context pair(s) with node memory, 5 node(s) had untolerated taint(s). no new claims to deallocate, preemption: 0/6 nodes are available: 1 No preemption victims found for incoming pod, 5 Preemption is not helpful for scheduling."
31.2222,Node,MODIFIED,kind-worker,taints=0
31.2225,Event,ADDED,eval-sanitize-3-r3-023-7hhqc.18d3d2fc0c625624,"reason=FailedScheduling count=None msg=0/6 nodes are available: 1 c_wall violated: 2 conflicting context pair(s) with node memory, 5 node(s) had untolerated taint(s). no new claims to deallocate, preemption: 0/6 nodes are available: 1 No preemption victims found for incoming pod, 5 Preemption is not helpful for scheduling."
31.2256,Event,MODIFIED,eval-sanitize-3-r3-031-4fnvg.18d3d2fc0a8298d2,"reason=FailedScheduling count=None msg=0/6 nodes are available: 1 c_wall violated: 1 conflicting context pair(s) with node memory, 5 node(s) had untolerated taint(s). no new claims to deallocate, preemption: 0/6 nodes are available: 1 No preemption victims found for incoming pod, 5 Preemption is not helpful for scheduling."
31.2298,Job,MODIFIED,eval-sanitize-3-r3-030,
31.2303,Event,MODIFIED,eval-sanitize-3-r3-023-7hhqc.18d3d2fc0c625624,"reason=FailedScheduling count=None msg=0/6 nodes are available: 1 c_wall violated: 2 conflicting context pair(s) with node memory, 5 node(s) had untolerated taint(s). no new claims to deallocate, preemption: 0/6 nodes are available: 1 No preemption victims found for incoming pod, 5 Preemption is not helpful for scheduling."
31.2355,Node,MODIFIED,kind-worker,taints=0
31.239,Job,MODIFIED,eval-sanitize-3-r3-030,
31.3287,Event,ADDED,eval-sanitize-3-r3-031.18d3d2fc043a7172,reason=SuccessfulCreate count=1 msg=Created pod: eval-sanitize-3-r3-031-4fnvg
31.376,Event,ADDED,eval-sanitize-3-r3-015.18d3d2fc07326cba,reason=Completed count=1 msg=Job completed
31.3943,Pod,MODIFIED,eval-sanitize-3-r3-020-7xstb,phase=Running node=kind-worker3
31.4415,Pod,MODIFIED,eval-sanitize-3-r3-019-svm65,phase=Running node=kind-worker5
31.4862,Job,MODIFIED,eval-sanitize-3-r3-018,
31.496,Pod,MODIFIED,eval-sanitize-3-r3-018-gz22z,phase=Succeeded node=kind-worker3
31.4993,Job,MODIFIED,eval-sanitize-3-r3-018,
31.6278,Node,MODIFIED,kind-worker4,taints=1
31.6324,Job,MODIFIED,eval-sanitize-3-r3-017,
31.6373,Job,MODIFIED,eval-sanitize-3-r3-017,
31.638,Event,ADDED,eval-sanitize-3-r3-029-8klt2.18d3d2fc25537db2,"reason=Pulled count=1 msg=Container image ""busybox:musl"" already present on machine"
31.6427,Node,MODIFIED,kind-worker4,taints=1
31.6529,Job,MODIFIED,eval-sanitize-3-r3-017,
31.6585,Node,MODIFIED,kind-worker4,taints=0
31.6587,TaskRequest,MODIFIED,eval-sanitize-3-r3-017,phase=Complete job=None
31.6663,Event,ADDED,eval-sanitize-3-r3-029-8klt2.18d3d2fc26ee3e0e,reason=Created count=1 msg=Created container: task
31.6703,Pod,MODIFIED,eval-sanitize-3-r3-031-4fnvg,phase=Pending node=kind-worker4
31.6728,Job,MODIFIED,eval-sanitize-3-r3-017,
31.6743,Event,ADDED,eval-sanitize-3-r3-031-4fnvg.18d3d2fc277eeae0,reason=Scheduled count=None msg=Successfully assigned compute/eval-sanitize-3-r3-031-4fnvg to kind-worker4
31.6763,Event,ADDED,eval-sanitize-3-r3-017.18d3d2fc259081c3,reason=Completed count=1 msg=Job completed
31.6811,Pod,MODIFIED,eval-sanitize-3-r3-031-4fnvg,phase=Pending node=kind-worker4
31.6838,Node,MODIFIED,kind-worker4,taints=0
31.6844,Event,ADDED,eval-sanitize-3-r3-026-mmf5k.18d3d2fc28099e61,"reason=Pulled count=1 msg=Container image ""busybox:musl"" already present on machine"
31.7063,Event,ADDED,eval-sanitize-3-r3-026-mmf5k.18d3d2fc295299eb,reason=Created count=1 msg=Created container: task
31.7135,Event,ADDED,eval-sanitize-3-r3-030-rddvq.18d3d2fc29db2413,"reason=Pulled count=1 msg=Container image ""busybox:musl"" already present on machine"
31.7245,Pod,MODIFIED,eval-sanitize-3-r3-023-7hhqc,phase=Pending node=None
31.7318,Node,MODIFIED,kind-worker4,taints=0
31.7344,Event,ADDED,eval-sanitize-3-r3-029-8klt2.18d3d2fc2b09ba41,reason=Started count=1 msg=Started container task
31.7397,Event,ADDED,eval-sanitize-3-r3-030-rddvq.18d3d2fc2b4c750f,reason=Created count=1 msg=Created container: task
31.7441,Node,MODIFIED,kind-worker4,taints=0
31.7457,Event,ADDED,eval-sanitize-3-r3-026-mmf5k.18d3d2fc2bc72a23,reason=Started count=1 msg=Started container task
31.7475,Event,ADDED,eval-sanitize-3-r3-023-7hhqc.18d3d2fc2be15147,"reason=FailedScheduling count=None msg=0/6 nodes are available: 1 c_wall violated: 1 conflicting context pair(s) with node memory, 1 c_wall violated: 2 conflicting context pair(s) with node memory, 4 node(s) had untolerated taint(s). no new claims to deallocate, preemption: 0/6 nodes are available: 2 No preemption victims found for incoming pod, 4 Preemption is not helpful for scheduling."
31.774,Event,ADDED,eval-sanitize-3-r3-030-rddvq.18d3d2fc2d66cc8a,reason=Started count=1 msg=Started container task
31.8229,Event,MODIFIED,eval-sanitize-3-r3-023-7hhqc.18d3d2fc2be15147,"reason=FailedScheduling count=None msg=0/6 nodes are available: 1 c_wall violated: 1 conflicting context pair(s) with node memory, 1 c_wall violated: 2 conflicting context pair(s) with node memory, 4 node(s) had untolerated taint(s). no new claims to deallocate, preemption: 0/6 nodes are available: 2 No preemption victims found for incoming pod, 4 Preemption is not helpful for scheduling."
31.8532,Pod,MODIFIED,eval-sanitize-3-r3-030-rddvq,phase=Running node=kind-worker
31.8598,Pod,MODIFIED,eval-sanitize-3-r3-029-8klt2,phase=Running node=kind-worker
31.8665,Pod,MODIFIED,eval-sanitize-3-r3-026-mmf5k,phase=Running node=kind-worker
32.0064,TaskRequest,ADDED,eval-sanitize-3-r3-032,phase=None job=None
32.0103,TaskRequest,MODIFIED,eval-sanitize-3-r3-032,phase=Pending job=None
32.0273,Job,ADDED,eval-sanitize-3-r3-032,
32.0318,TaskRequest,MODIFIED,eval-sanitize-3-r3-032,phase=Scheduled job=None
32.036,Pod,ADDED,eval-sanitize-3-r3-032-ps7mn,phase=Pending node=None
32.0393,Job,MODIFIED,eval-sanitize-3-r3-032,
32.0415,TaskRequest,MODIFIED,eval-sanitize-3-r3-032,phase=Scheduled job=None
32.0427,Job,MODIFIED,eval-sanitize-3-r3-031,
32.0431,Event,ADDED,eval-sanitize-3-r3-032.18d3d2fc3d58c3b7,reason=SuccessfulCreate count=1 msg=Created pod: eval-sanitize-3-r3-032-ps7mn
32.0562,Job,MODIFIED,eval-sanitize-3-r3-031,
32.0574,Pod,MODIFIED,eval-sanitize-3-r3-032-ps7mn,phase=Pending node=kind-worker4
32.063,Event,ADDED,eval-sanitize-3-r3-032-ps7mn.18d3d2fc3e8af23c,reason=Scheduled count=None msg=Successfully assigned compute/eval-sanitize-3-r3-032-ps7mn to kind-worker4
32.0675,Node,MODIFIED,kind-worker4,taints=0
32.0693,Pod,MODIFIED,eval-sanitize-3-r3-023-7hhqc,phase=Pending node=None
32.0706,Pod,MODIFIED,eval-sanitize-3-r3-032-ps7mn,phase=Pending node=kind-worker4
32.0796,Node,MODIFIED,kind-worker4,taints=0
32.1283,Event,ADDED,eval-sanitize-3-r3-031-4fnvg.18d3d2fc42782e70,"reason=Pulled count=1 msg=Container image ""busybox:musl"" already present on machine"
32.129,Event,ADDED,eval-sanitize-3-r3-023-7hhqc.18d3d2fc42a1bfd0,"reason=FailedScheduling count=None msg=0/6 nodes are available: 2 c_wall violated: 2 conflicting context pair(s) with node memory, 4 node(s) had untolerated taint(s). no new claims to deallocate, preemption: 0/6 nodes are available: 2 No preemption victims found for incoming pod, 4 Preemption is not helpful for scheduling."
32.1452,Event,ADDED,eval-sanitize-3-r3-031-4fnvg.18d3d2fc43a72066,reason=Created count=1 msg=Created container: task
32.1768,Job,MODIFIED,eval-sanitize-3-r3-030,
32.1883,Event,ADDED,eval-sanitize-3-r3-031-4fnvg.18d3d2fc459c81de,reason=Started count=1 msg=Started container task
32.1928,Job,MODIFIED,eval-sanitize-3-r3-030,
32.3844,Pod,MODIFIED,eval-sanitize-3-r3-031-4fnvg,phase=Running node=kind-worker4
32.3996,Job,MODIFIED,eval-sanitize-3-r3-020,
32.4013,Event,MODIFIED,eval-sanitize-3-r3-023-7hhqc.18d3d2fc42a1bfd0,"reason=FailedScheduling count=None msg=0/6 nodes are available: 2 c_wall violated: 2 conflicting context pair(s) with node memory, 4 node(s) had untolerated taint(s). no new claims to deallocate, preemption: 0/6 nodes are available: 2 No preemption victims found for incoming pod, 4 Preemption is not helpful for scheduling."
32.4032,Pod,MODIFIED,eval-sanitize-3-r3-021-nbbns,phase=Running node=kind-worker3
32.4096,Job,MODIFIED,eval-sanitize-3-r3-020,
32.4475,Job,MODIFIED,eval-sanitize-3-r3-019,
32.4572,Job,MODIFIED,eval-sanitize-3-r3-019,
32.493,Job,MODIFIED,eval-sanitize-3-r3-018,
32.4991,Job,MODIFIED,eval-sanitize-3-r3-018,
32.5032,Event,ADDED,eval-sanitize-3-r3-018.18d3d2fc58eaf893,reason=Completed count=1 msg=Job completed
32.5116,Job,MODIFIED,eval-sanitize-3-r3-018,
32.5184,TaskRequest,MODIFIED,eval-sanitize-3-r3-018,phase=Complete job=None
32.5218,Event,ADDED,eval-sanitize-3-r3-032-ps7mn.18d3d2fc5a0e190a,"reason=Pulled count=1 msg=Container image ""busybox:musl"" already present on machine"
32.5294,Job,MODIFIED,eval-sanitize-3-r3-018,
32.5469,Pod,MODIFIED,eval-sanitize-3-r3-020-7xstb,phase=Succeeded node=kind-worker3
32.5472,Event,ADDED,eval-sanitize-3-r3-032-ps7mn.18d3d2fc5b74cea7,reason=Created count=1 msg=Created container: task
32.6222,Event,ADDED,eval-sanitize-3-r3-032-ps7mn.18d3d2fc6007ccfc,reason=Started count=1 msg=Started container task
32.6781,Pod,MODIFIED,eval-sanitize-3-r3-019-svm65,phase=Succeeded node=kind-worker5
32.8652,Job,MODIFIED,eval-sanitize-3-r3-029,
32.8716,Job,MODIFIED,eval-sanitize-3-r3-026,
32.8736,Job,MODIFIED,eval-sanitize-3-r3-029,
32.8871,Job,MODIFIED,eval-sanitize-3-r3-026,
33.0079,TaskRequest,ADDED,eval-sanitize-3-r3-033,phase=None job=None
33.0114,TaskRequest,MODIFIED,eval-sanitize-3-r3-033,phase=Pending job=None
33.0262,Job,ADDED,eval-sanitize-3-r3-033,
33.0309,Pod,ADDED,eval-sanitize-3-r3-033-zv46r,phase=Pending node=None
33.0327,TaskRequest,MODIFIED,eval-sanitize-3-r3-033,phase=Scheduled job=None
33.0357,Job,MODIFIED,eval-sanitize-3-r3-033,
33.036,Event,ADDED,eval-sanitize-3-r3-033.18d3d2fc78a70d8c,reason=SuccessfulCreate count=1 msg=Created pod: eval-sanitize-3-r3-033-zv46r
33.0404,TaskRequest,MODIFIED,eval-sanitize-3-r3-033,phase=Scheduled job=None
33.0413,Job,MODIFIED,eval-sanitize-3-r3-032,
33.0431,Job,MODIFIED,eval-sanitize-3-r3-033,
33.0462,Pod,MODIFIED,eval-sanitize-3-r3-033-zv46r,phase=Pending node=kind-worker
33.0482,Job,MODIFIED,eval-sanitize-3-r3-031,
33.052,Event,ADDED,eval-sanitize-3-r3-033-zv46r.18d3d2fc798aaddc,reason=Scheduled count=None msg=Successfully assigned compute/eval-sanitize-3-r3-033-zv46r to kind-worker
33.0557,Job,MODIFIED,eval-sanitize-3-r3-033,
33.0565,Job,MODIFIED,eval-sanitize-3-r3-032,
33.0584,Pod,MODIFIED,eval-sanitize-3-r3-033-zv46r,phase=Pending node=kind-worker
33.0592,Job,MODIFIED,eval-sanitize-3-r3-031,
33.3886,Pod,MODIFIED,eval-sanitize-3-r3-032-ps7mn,phase=Running node=kind-worker4
33.4052,Job,MODIFIED,eval-sanitize-3-r3-020,
33.41,Job,MODIFIED,eval-sanitize-3-r3-021,
33.4152,Pod,MODIFIED,eval-sanitize-3-r3-020-7xstb,phase=Succeeded node=kind-worker3
33.4161,Job,MODIFIED,eval-sanitize-3-r3-020,
33.4219,Job,MODIFIED,eval-sanitize-3-r3-021,
33.4542,Job,MODIFIED,eval-sanitize-3-r3-019,
33.463,Pod,MODIFIED,eval-sanitize-3-r3-019-svm65,phase=Succeeded node=kind-worker5
33.4643,Job,MODIFIED,eval-sanitize-3-r3-019,
33.5343,Event,ADDED,eval-sanitize-3-r3-033-zv46r.18d3d2fc96653d98,"reason=Pulled count=1 msg=Container image ""busybox:musl"" already present on machine"
33.5532,Event,ADDED,eval-sanitize-3-r3-033-zv46r.18d3d2fc9784361a,reason=Created count=1 msg=Created container: task
33.6129,Pod,MODIFIED,eval-sanitize-3-r3-021-nbbns,phase=Succeeded node=kind-worker3
33.6285,Event,ADDED,eval-sanitize-3-r3-033-zv46r.18d3d2fc9bef4d2d,reason=Started count=1 msg=Started container task
33.8611,Pod,MODIFIED,eval-sanitize-3-r3-033-zv46r,phase=Running node=kind-worker
34.0083,TaskRequest,ADDED,eval-sanitize-3-r3-034,phase=None job=None
34.0122,TaskRequest,MODIFIED,eval-sanitize-3-r3-034,phase=Pending job=None
34.0279,Job,ADDED,eval-sanitize-3-r3-034,
34.0318,TaskRequest,MODIFIED,eval-sanitize-3-r3-034,phase=Scheduled job=None
34.035,Pod,ADDED,eval-sanitize-3-r3-034-fsqln,phase=Pending node=None
34.0387,Job,MODIFIED,eval-sanitize-3-r3-033,
34.0393,Job,MODIFIED,eval-sanitize-3-r3-034,
34.0416,Event,ADDED,eval-sanitize-3-r3-034.18d3d2fcb47fd2f4,reason=SuccessfulCreate count=1 msg=Created pod: eval-sanitize-3-r3-034-fsqln
34.0417,TaskRequest,MODIFIED,eval-sanitize-3-r3-034,phase=Scheduled job=None
34.0458,Job,MODIFIED,eval-sanitize-3-r3-032,
34.0474,Event,ADDED,eval-sanitize-3-r3-034-fsqln.18d3d2fcb4edb394,"reason=FailedScheduling count=None msg=0/6 nodes are available: 2 c_wall violated: 2 conflicting context pair(s) with node memory, 4 node(s) had untolerated taint(s). no new claims to deallocate, preemption: 0/6 nodes are available: 2 No preemption victims found for incoming pod, 4 Preemption is not helpful for scheduling."
34.0485,Pod,MODIFIED,eval-sanitize-3-r3-034-fsqln,phase=Pending node=None
34.0498,Job,MODIFIED,eval-sanitize-3-r3-033,
34.055,Job,MODIFIED,eval-sanitize-3-r3-032,
34.0573,Event,ADDED,eval-sanitize-3-r3-034-fsqln.18d3d2fcb59d3288,"reason=FailedScheduling count=None msg=0/6 nodes are available: 2 c_wall violated: 2 conflicting context pair(s) with node memory, 4 node(s) had untolerated taint(s). no new claims to deallocate, preemption: 0/6 nodes are available: 2 No preemption victims found for incoming pod, 4 Preemption is not helpful for scheduling."
34.2318,Node,MODIFIED,kind-worker,taints=1
34.2442,Pod,MODIFIED,eval-sanitize-3-r3-023-7hhqc,phase=Pending node=None
34.247,Node,MODIFIED,kind-worker,taints=1
34.2532,Pod,MODIFIED,eval-sanitize-3-r3-034-fsqln,phase=Pending node=None
34.2553,Event,MODIFIED,eval-sanitize-3-r3-034-fsqln.18d3d2fcb59d3288,"reason=FailedScheduling count=None msg=0/6 nodes are available: 2 c_wall violated: 2 conflicting context pair(s) with node memory, 4 node(s) had untolerated taint(s). no new claims to deallocate, preemption: 0/6 nodes are available: 2 No preemption victims found for incoming pod, 4 Preemption is not helpful for scheduling."
34.2597,Event,ADDED,eval-sanitize-3-r3-023-7hhqc.18d3d2fcc1b042d9,"reason=FailedScheduling count=None msg=0/6 nodes are available: 1 c_wall violated: 2 conflicting context pair(s) with node memory, 5 node(s) had untolerated taint(s). no new claims to deallocate, preemption: 0/6 nodes are available: 1 No preemption victims found for incoming pod, 5 Preemption is not helpful for scheduling."
34.2618,Event,ADDED,eval-sanitize-3-r3-034-fsqln.18d3d2fcc1d55085,"reason=FailedScheduling count=None msg=0/6 nodes are available: 1 c_wall violated: 2 conflicting context pair(s) with node memory, 5 node(s) had untolerated taint(s). no new claims to deallocate, preemption: 0/6 nodes are available: 1 No preemption victims found for incoming pod, 5 Preemption is not helpful for scheduling."
34.4107,Job,MODIFIED,eval-sanitize-3-r3-020,
34.4149,Job,MODIFIED,eval-sanitize-3-r3-020,
34.4178,Job,MODIFIED,eval-sanitize-3-r3-021,
34.4213,Event,ADDED,eval-sanitize-3-r3-020.18d3d2fccb2380bc,reason=Completed count=1 msg=Job completed
34.4256,Pod,MODIFIED,eval-sanitize-3-r3-021-nbbns,phase=Succeeded node=kind-worker3
34.4273,Job,MODIFIED,eval-sanitize-3-r3-021,
34.4295,Job,MODIFIED,eval-sanitize-3-r3-020,
34.434,TaskRequest,MODIFIED,eval-sanitize-3-r3-020,phase=Complete job=None
34.4454,Job,MODIFIED,eval-sanitize-3-r3-020,
34.459,Job,MODIFIED,eval-sanitize-3-r3-019,
34.4638,Job,MODIFIED,eval-sanitize-3-r3-019,
34.4679,Event,ADDED,eval-sanitize-3-r3-019.18d3d2fcce0979c7,reason=Completed count=1 msg=Job completed
34.4738,Job,MODIFIED,eval-sanitize-3-r3-019,
34.4783,TaskRequest,MODIFIED,eval-sanitize-3-r3-019,phase=Complete job=None
34.4877,Job,MODIFIED,eval-sanitize-3-r3-019,
34.5225,Node,MODIFIED,kind-worker3,taints=1
34.5311,Event,MODIFIED,eval-sanitize-3-r3-023-7hhqc.18d3d2fcc1b042d9,"reason=FailedScheduling count=None msg=0/6 nodes are available: 1 c_wall violated: 2 conflicting context pair(s) with node memory, 5 node(s) had untolerated taint(s). no new claims to deallocate, preemption: 0/6 nodes are available: 1 No preemption victims found for incoming pod, 5 Preemption is not helpful for scheduling."
34.5373,Event,MODIFIED,eval-sanitize-3-r3-034-fsqln.18d3d2fcc1d55085,"reason=FailedScheduling count=None msg=0/6 nodes are available: 1 c_wall violated: 2 conflicting context pair(s) with node memory, 5 node(s) had untolerated taint(s). no new claims to deallocate, preemption: 0/6 nodes are available: 1 No preemption victims found for incoming pod, 5 Preemption is not helpful for scheduling."
34.539,Node,MODIFIED,kind-worker3,taints=0
34.5475,Node,MODIFIED,kind-worker3,taints=0
34.5487,Pod,MODIFIED,eval-sanitize-3-r3-023-7hhqc,phase=Pending node=kind-worker3
34.554,Pod,MODIFIED,eval-sanitize-3-r3-034-fsqln,phase=Pending node=kind-worker3
34.5555,Event,ADDED,eval-sanitize-3-r3-023-7hhqc.18d3d2fcd2ff5350,reason=Scheduled count=None msg=Successfully assigned compute/eval-sanitize-3-r3-023-7hhqc to kind-worker3
34.5623,Pod,MODIFIED,eval-sanitize-3-r3-023-7hhqc,phase=Pending node=kind-worker3
34.5635,Node,MODIFIED,kind-worker3,taints=0
34.564,Event,ADDED,eval-sanitize-3-r3-034-fsqln.18d3d2fcd3626ab2,reason=Scheduled count=None msg=Successfully assigned compute/eval-sanitize-3-r3-034-fsqln to kind-worker3
34.569,Pod,MODIFIED,eval-sanitize-3-r3-034-fsqln,phase=Pending node=kind-worker3
34.5831,Node,MODIFIED,kind-worker3,taints=0
34.6204,Node,MODIFIED,kind-worker3,taints=0
34.7304,Node,MODIFIED,kind-worker4,taints=1
34.744,Node,MODIFIED,kind-worker4,taints=1
34.9731,Event,ADDED,eval-sanitize-3-r3-023-7hhqc.18d3d2fcec080a19,"reason=Pulled count=1 msg=Container image ""busybox:musl"" already present on machine"
34.977,Event,ADDED,eval-sanitize-3-r3-034-fsqln.18d3d2fcec37cb1d,"reason=Pulled count=1 msg=Container image ""busybox:musl"" already present on machine"
34.9945,Event,ADDED,eval-sanitize-3-r3-023-7hhqc.18d3d2fced77392c,reason=Created count=1 msg=Created container: task
35.0011,Event,ADDED,eval-sanitize-3-r3-034-fsqln.18d3d2fcedd1184d,reason=Created count=1 msg=Created container: task
35.0138,TaskRequest,ADDED,eval-sanitize-3-r3-035,phase=None job=None
35.0189,TaskRequest,MODIFIED,eval-sanitize-3-r3-035,phase=Pending job=None
35.0369,Job,ADDED,eval-sanitize-3-r3-035,
35.0422,Job,MODIFIED,eval-sanitize-3-r3-034,
35.0424,TaskRequest,MODIFIED,eval-sanitize-3-r3-035,phase=Scheduled job=None
35.0456,Pod,ADDED,eval-sanitize-3-r3-035-6bmlr,phase=Pending node=None
35.0488,Job,MODIFIED,eval-sanitize-3-r3-035,
35.0524,Event,ADDED,eval-sanitize-3-r3-035.18d3d2fcf0b7367a,reason=SuccessfulCreate count=1 msg=Created pod: eval-sanitize-3-r3-035-6bmlr
35.0541,TaskRequest,MODIFIED,eval-sanitize-3-r3-035,phase=Scheduled job=None
35.0596,Event,ADDED,eval-sanitize-3-r3-035-6bmlr.18d3d2fcf100cc65,"reason=FailedScheduling count=None msg=0/6 nodes are available: 1 c_wall violated: 1 conflicting context pair(s) with node memory, 5 node(s) had untolerated taint(s). no new claims to deallocate, preemption: 0/6 nodes are available: 1 No preemption victims found for incoming pod, 5 Preemption is not helpful for scheduling."
35.06,Event,ADDED,eval-sanitize-3-r3-023-7hhqc.18d3d2fcf118284a,reason=Started count=1 msg=Started container task
35.0609,Job,MODIFIED,eval-sanitize-3-r3-034,
35.0619,Pod,MODIFIED,eval-sanitize-3-r3-035-6bmlr,phase=Pending node=None
35.066,Event,ADDED,eval-sanitize-3-r3-034-fsqln.18d3d2fcf178188e,reason=Started count=1 msg=Started container task
35.0675,Event,ADDED,eval-sanitize-3-r3-035-6bmlr.18d3d2fcf1d41e5f,"reason=FailedScheduling count=None msg=0/6 nodes are available: 1 c_wall violated: 1 conflicting context pair(s) with node memory, 5 node(s) had untolerated taint(s). no new claims to deallocate, preemption: 0/6 nodes are available: 1 No preemption victims found for incoming pod, 5 Preemption is not helpful for scheduling."
35.4084,Pod,MODIFIED,eval-sanitize-3-r3-034-fsqln,phase=Running node=kind-worker3
35.415,Pod,MODIFIED,eval-sanitize-3-r3-023-7hhqc,phase=Running node=kind-worker3
35.4188,Event,MODIFIED,eval-sanitize-3-r3-035-6bmlr.18d3d2fcf1d41e5f,"reason=FailedScheduling count=None msg=0/6 nodes are available: 1 c_wall violated: 1 conflicting context pair(s) with node memory, 5 node(s) had untolerated taint(s). no new claims to deallocate, preemption: 0/6 nodes are available: 1 No preemption victims found for incoming pod, 5 Preemption is not helpful for scheduling."
35.4222,Job,MODIFIED,eval-sanitize-3-r3-021,
35.426,Job,MODIFIED,eval-sanitize-3-r3-021,
35.4287,Event,ADDED,eval-sanitize-3-r3-021.18d3d2fd07682b4f,reason=Completed count=1 msg=Job completed
35.4369,Job,MODIFIED,eval-sanitize-3-r3-021,
35.4413,TaskRequest,MODIFIED,eval-sanitize-3-r3-021,phase=Complete job=None
35.4502,Job,MODIFIED,eval-sanitize-3-r3-021,
35.6251,Node,MODIFIED,kind-worker5,taints=1
35.7042,Node,MODIFIED,kind-worker5,taints=1
35.7126,Node,MODIFIED,kind-worker5,taints=0
35.7206,Pod,MODIFIED,eval-sanitize-3-r3-035-6bmlr,phase=Pending node=kind-worker5
35.7254,Node,MODIFIED,kind-worker5,taints=0
35.726,Event,ADDED,eval-sanitize-3-r3-035-6bmlr.18d3d2fd18f0bee0,reason=Scheduled count=None msg=Successfully assigned compute/eval-sanitize-3-r3-035-6bmlr to kind-worker5
35.7326,Pod,MODIFIED,eval-sanitize-3-r3-035-6bmlr,phase=Pending node=kind-worker5
35.7517,Node,MODIFIED,kind-worker5,taints=0
35.7609,Node,MODIFIED,kind-worker5,taints=0
36.0072,TaskRequest,ADDED,eval-sanitize-3-r3-036,phase=None job=None
36.0124,TaskRequest,MODIFIED,eval-sanitize-3-r3-036,phase=Pending job=None
36.0262,Job,ADDED,eval-sanitize-3-r3-036,
36.034,Pod,ADDED,eval-sanitize-3-r3-036-4fnh6,phase=Pending node=None
36.0364,TaskRequest,MODIFIED,eval-sanitize-3-r3-036,phase=Scheduled job=None
36.0371,Job,MODIFIED,eval-sanitize-3-r3-036,
36.0395,Event,ADDED,eval-sanitize-3-r3-036.18d3d2fd2ba0bc5d,reason=SuccessfulCreate count=1 msg=Created pod: eval-sanitize-3-r3-036-4fnh6
36.0444,TaskRequest,MODIFIED,eval-sanitize-3-r3-036,phase=Scheduled job=None
36.048,Job,MODIFIED,eval-sanitize-3-r3-034,
36.049,Pod,MODIFIED,eval-sanitize-3-r3-036-4fnh6,phase=Pending node=kind-worker3
36.0521,Job,MODIFIED,eval-sanitize-3-r3-035,
36.0525,Event,ADDED,eval-sanitize-3-r3-036-4fnh6.18d3d2fd2c75b869,reason=Scheduled count=None msg=Successfully assigned compute/eval-sanitize-3-r3-036-4fnh6 to kind-worker3
36.0576,Job,MODIFIED,eval-sanitize-3-r3-034,
36.0611,Job,MODIFIED,eval-sanitize-3-r3-035,
36.065,Pod,MODIFIED,eval-sanitize-3-r3-036-4fnh6,phase=Pending node=kind-worker3
36.1535,Event,ADDED,eval-sanitize-3-r3-035-6bmlr.18d3d2fd32864840,"reason=Pulled count=1 msg=Container image ""busybox:musl"" already present on machine"
36.1716,Event,ADDED,eval-sanitize-3-r3-035-6bmlr.18d3d2fd339d2433,reason=Created count=1 msg=Created container: task
36.2026,Event,ADDED,eval-sanitize-3-r3-035-6bmlr.18d3d2fd3577778c,reason=Started count=1 msg=Started container task
36.4212,Job,MODIFIED,eval-sanitize-3-r3-023,
36.4303,Job,MODIFIED,eval-sanitize-3-r3-023,
36.4566,Pod,MODIFIED,eval-sanitize-3-r3-035-6bmlr,phase=Running node=kind-worker5
36.4673,Event,ADDED,eval-sanitize-3-r3-036-4fnh6.18d3d2fd4520f026,"reason=Pulled count=1 msg=Container image ""busybox:musl"" already present on machine"
36.4853,Event,ADDED,eval-sanitize-3-r3-036-4fnh6.18d3d2fd4652b31c,reason=Created count=1 msg=Created container: task
36.5552,Event,ADDED,eval-sanitize-3-r3-036-4fnh6.18d3d2fd4a620bde,reason=Started count=1 msg=Started container task
37.0065,TaskRequest,ADDED,eval-sanitize-3-r3-037,phase=None job=None
37.01,TaskRequest,MODIFIED,eval-sanitize-3-r3-037,phase=Pending job=None
37.0252,Job,ADDED,eval-sanitize-3-r3-037,
37.0315,Pod,ADDED,eval-sanitize-3-r3-037-cw865,phase=Pending node=None
37.0315,TaskRequest,MODIFIED,eval-sanitize-3-r3-037,phase=Scheduled job=None
37.0353,Job,MODIFIED,eval-sanitize-3-r3-037,
37.0384,Event,ADDED,eval-sanitize-3-r3-037.18d3d2fd671a2279,reason=SuccessfulCreate count=1 msg=Created pod: eval-sanitize-3-r3-037-cw865
37.04,TaskRequest,MODIFIED,eval-sanitize-3-r3-037,phase=Scheduled job=None
37.0409,Job,MODIFIED,eval-sanitize-3-r3-036,
37.047,Pod,MODIFIED,eval-sanitize-3-r3-037-cw865,phase=Pending node=kind-worker5
37.0538,Job,MODIFIED,eval-sanitize-3-r3-036,
37.0555,Event,ADDED,eval-sanitize-3-r3-037-cw865.18d3d2fd67fdd3d9,reason=Scheduled count=None msg=Successfully assigned compute/eval-sanitize-3-r3-037-cw865 to kind-worker5
37.057,Node,MODIFIED,kind-worker5,taints=0
37.0581,Job,MODIFIED,eval-sanitize-3-r3-035,
37.0607,Pod,MODIFIED,eval-sanitize-3-r3-037-cw865,phase=Pending node=kind-worker5
37.0666,Node,MODIFIED,kind-worker5,taints=0
37.0678,Job,MODIFIED,eval-sanitize-3-r3-035,
37.4147,Pod,MODIFIED,eval-sanitize-3-r3-036-4fnh6,phase=Running node=kind-worker3
37.4739,Event,ADDED,eval-sanitize-3-r3-037-cw865.18d3d2fd813933a4,"reason=Pulled count=1 msg=Container image ""busybox:musl"" already present on machine"
37.492,Event,ADDED,eval-sanitize-3-r3-037-cw865.18d3d2fd825b8b3c,reason=Created count=1 msg=Created container: task
37.5249,Event,ADDED,eval-sanitize-3-r3-037-cw865.18d3d2fd84322a6f,reason=Started count=1 msg=Started container task
37.631,Node,MODIFIED,kind-worker3,taints=1
37.6438,Node,MODIFIED,kind-worker3,taints=1
38.0076,TaskRequest,ADDED,eval-sanitize-3-r3-038,phase=None job=None
38.0132,TaskRequest,MODIFIED,eval-sanitize-3-r3-038,phase=Pending job=None
38.0277,Job,ADDED,eval-sanitize-3-r3-038,
38.0338,TaskRequest,MODIFIED,eval-sanitize-3-r3-038,phase=Scheduled job=None
38.0366,Pod,ADDED,eval-sanitize-3-r3-038-vdkjz,phase=Pending node=None
38.0374,Job,MODIFIED,eval-sanitize-3-r3-038,
38.0384,Job,MODIFIED,eval-sanitize-3-r3-037,
38.0399,Event,ADDED,eval-sanitize-3-r3-038.18d3d2fda303e98d,reason=SuccessfulCreate count=1 msg=Created pod: eval-sanitize-3-r3-038-vdkjz
38.0424,TaskRequest,MODIFIED,eval-sanitize-3-r3-038,phase=Scheduled job=None
38.0456,Pod,MODIFIED,eval-sanitize-3-r3-038-vdkjz,phase=Pending node=None
38.0471,Event,ADDED,eval-sanitize-3-r3-038-vdkjz.18d3d2fda3451231,"reason=FailedScheduling count=None msg=0/6 nodes are available: 1 c_wall violated: 1 conflicting context pair(s) with node memory, 5 node(s) had untolerated taint(s). no new claims to deallocate, preemption: 0/6 nodes are available: 1 No preemption victims found for incoming pod, 5 Preemption is not helpful for scheduling."
38.0479,Job,MODIFIED,eval-sanitize-3-r3-036,
38.0486,Job,MODIFIED,eval-sanitize-3-r3-037,
38.0529,Event,ADDED,eval-sanitize-3-r3-038-vdkjz.18d3d2fda3c755b1,"reason=FailedScheduling count=None msg=0/6 nodes are available: 1 c_wall violated: 1 conflicting context pair(s) with node memory, 5 node(s) had untolerated taint(s). no new claims to deallocate, preemption: 0/6 nodes are available: 1 No preemption victims found for incoming pod, 5 Preemption is not helpful for scheduling."
38.0567,Job,MODIFIED,eval-sanitize-3-r3-036,
38.4623,Pod,MODIFIED,eval-sanitize-3-r3-037-cw865,phase=Running node=kind-worker5
38.4719,Event,MODIFIED,eval-sanitize-3-r3-038-vdkjz.18d3d2fda3c755b1,"reason=FailedScheduling count=None msg=0/6 nodes are available: 1 c_wall violated: 1 conflicting context pair(s) with node memory, 5 node(s) had untolerated taint(s). no new claims to deallocate, preemption: 0/6 nodes are available: 1 No preemption victims found for incoming pod, 5 Preemption is not helpful for scheduling."
38.7328,Node,MODIFIED,kind-worker5,taints=1
38.7385,Pod,MODIFIED,eval-sanitize-3-r3-038-vdkjz,phase=Pending node=None
38.7473,Node,MODIFIED,kind-worker5,taints=1
39.0079,TaskRequest,ADDED,eval-sanitize-3-r3-039,phase=None job=None
39.0128,TaskRequest,MODIFIED,eval-sanitize-3-r3-039,phase=Pending job=None
39.0287,Job,ADDED,eval-sanitize-3-r3-039,
39.0353,Pod,ADDED,eval-sanitize-3-r3-039-k4ldp,phase=Pending node=None
39.0355,TaskRequest,MODIFIED,eval-sanitize-3-r3-039,phase=Scheduled job=None
39.0385,Job,MODIFIED,eval-sanitize-3-r3-039,
39.0408,Event,ADDED,eval-sanitize-3-r3-039.18d3d2fdde82b085,reason=SuccessfulCreate count=1 msg=Created pod: eval-sanitize-3-r3-039-k4ldp
39.0422,Pod,MODIFIED,eval-sanitize-3-r3-039-k4ldp,phase=Pending node=None
39.0427,Event,ADDED,eval-sanitize-3-r3-039-k4ldp.18d3d2fdde917336,"reason=FailedScheduling count=None msg=0/6 nodes are available: 6 node(s) had untolerated taint(s). no new claims to deallocate, preemption: 0/6 nodes are available: 6 Preemption is not helpful for scheduling."
39.0438,Job,MODIFIED,eval-sanitize-3-r3-038,
39.0446,Job,MODIFIED,eval-sanitize-3-r3-037,
39.0448,TaskRequest,MODIFIED,eval-sanitize-3-r3-039,phase=Scheduled job=None
39.0544,Job,MODIFIED,eval-sanitize-3-r3-038,
39.0562,Job,MODIFIED,eval-sanitize-3-r3-037,
39.2676,Pod,MODIFIED,eval-sanitize-3-r3-022-xkvgt,phase=Running node=kind-worker2
39.2739,Pod,MODIFIED,eval-sanitize-3-r3-024-7gkdr,phase=Running node=kind-worker2
39.2819,Pod,MODIFIED,eval-sanitize-3-r3-025-mtstx,phase=Running node=kind-worker2
39.29,Pod,MODIFIED,eval-sanitize-3-r3-027-4wfbw,phase=Running node=kind-worker2
39.2957,Pod,MODIFIED,eval-sanitize-3-r3-028-cq5fx,phase=Running node=kind-worker2
40.0081,TaskRequest,ADDED,eval-sanitize-3-r3-040,phase=None job=None
40.0132,TaskRequest,MODIFIED,eval-sanitize-3-r3-040,phase=Pending job=None
40.0265,Job,ADDED,eval-sanitize-3-r3-040,
40.0328,Pod,ADDED,eval-sanitize-3-r3-040-55zl6,phase=Pending node=None
40.034,TaskRequest,MODIFIED,eval-sanitize-3-r3-040,phase=Scheduled job=None
40.0373,Job,MODIFIED,eval-sanitize-3-r3-040,
40.0401,Event,ADDED,eval-sanitize-3-r3-040.18d3d2fe19fd0c40,reason=SuccessfulCreate count=1 msg=Created pod: eval-sanitize-3-r3-040-55zl6
40.0403,Event,ADDED,eval-sanitize-3-r3-040-55zl6.18d3d2fe1a0f7364,"reason=FailedScheduling count=None msg=0/6 nodes are available: 6 node(s) had untolerated taint(s). no new claims to deallocate, preemption: 0/6 nodes are available: 6 Preemption is not helpful for scheduling."
40.0412,Pod,MODIFIED,eval-sanitize-3-r3-040-55zl6,phase=Pending node=None
40.0428,Job,MODIFIED,eval-sanitize-3-r3-039,
40.044,TaskRequest,MODIFIED,eval-sanitize-3-r3-040,phase=Scheduled job=None
40.0515,Job,MODIFIED,eval-sanitize-3-r3-039,
40.2737,Job,MODIFIED,eval-sanitize-3-r3-022,
40.2807,Job,MODIFIED,eval-sanitize-3-r3-024,
40.287,Job,MODIFIED,eval-sanitize-3-r3-025,
40.2897,Job,MODIFIED,eval-sanitize-3-r3-022,
40.2916,Job,MODIFIED,eval-sanitize-3-r3-024,
40.2945,Job,MODIFIED,eval-sanitize-3-r3-027,
40.3,Job,MODIFIED,eval-sanitize-3-r3-025,
40.3023,Job,MODIFIED,eval-sanitize-3-r3-028,
40.3039,Job,MODIFIED,eval-sanitize-3-r3-027,
40.311,Job,MODIFIED,eval-sanitize-3-r3-028,
40.4695,Pod,MODIFIED,eval-sanitize-3-r3-024-7gkdr,phase=Succeeded node=kind-worker2
40.5181,Pod,MODIFIED,eval-sanitize-3-r3-025-mtstx,phase=Succeeded node=kind-worker2
40.5244,Pod,MODIFIED,eval-sanitize-3-r3-028-cq5fx,phase=Succeeded node=kind-worker2
40.5305,Pod,MODIFIED,eval-sanitize-3-r3-022-xkvgt,phase=Succeeded node=kind-worker2
40.5372,Pod,MODIFIED,eval-sanitize-3-r3-027-4wfbw,phase=Succeeded node=kind-worker2
41.025,TaskRequest,ADDED,eval-sanitize-3-r3-041,phase=None job=None
41.0284,TaskRequest,MODIFIED,eval-sanitize-3-r3-041,phase=Pending job=None
41.0382,Job,MODIFIED,eval-sanitize-3-r3-040,
41.0428,Job,ADDED,eval-sanitize-3-r3-041,
41.0496,Pod,ADDED,eval-sanitize-3-r3-041-c9zgv,phase=Pending node=None
41.0497,TaskRequest,MODIFIED,eval-sanitize-3-r3-041,phase=Scheduled job=None
41.0523,Job,MODIFIED,eval-sanitize-3-r3-041,
41.0535,Event,ADDED,eval-sanitize-3-r3-041.18d3d2fe56924c5c,reason=SuccessfulCreate count=1 msg=Created pod: eval-sanitize-3-r3-041-c9zgv
41.0578,Event,ADDED,eval-sanitize-3-r3-041-c9zgv.18d3d2fe569e38c2,"reason=FailedScheduling count=None msg=0/6 nodes are available: 6 node(s) had untolerated taint(s). no new claims to deallocate, preemption: 0/6 nodes are available: 6 Preemption is not helpful for scheduling."
41.0589,Pod,MODIFIED,eval-sanitize-3-r3-041-c9zgv,phase=Pending node=None
41.0591,TaskRequest,MODIFIED,eval-sanitize-3-r3-041,phase=Scheduled job=None
41.0609,Job,MODIFIED,eval-sanitize-3-r3-040,
41.2804,Job,MODIFIED,eval-sanitize-3-r3-022,
41.2884,Job,MODIFIED,eval-sanitize-3-r3-024,
41.2924,Pod,MODIFIED,eval-sanitize-3-r3-022-xkvgt,phase=Succeeded node=kind-worker2
41.2935,Job,MODIFIED,eval-sanitize-3-r3-022,
41.2949,Job,MODIFIED,eval-sanitize-3-r3-025,
41.299,Pod,MODIFIED,eval-sanitize-3-r3-024-7gkdr,phase=Succeeded node=kind-worker2
41.301,Job,MODIFIED,eval-sanitize-3-r3-024,
41.3019,Job,MODIFIED,eval-sanitize-3-r3-027,
41.3047,Job,MODIFIED,eval-sanitize-3-r3-025,
41.3062,Pod,MODIFIED,eval-sanitize-3-r3-025-mtstx,phase=Succeeded node=kind-worker2
41.3079,Job,MODIFIED,eval-sanitize-3-r3-028,
41.3105,Pod,MODIFIED,eval-sanitize-3-r3-027-4wfbw,phase=Succeeded node=kind-worker2
41.3121,Job,MODIFIED,eval-sanitize-3-r3-027,
41.3185,Job,MODIFIED,eval-sanitize-3-r3-028,
41.3199,Pod,MODIFIED,eval-sanitize-3-r3-028-cq5fx,phase=Succeeded node=kind-worker2
41.8779,Pod,MODIFIED,eval-sanitize-3-r3-029-8klt2,phase=Running node=kind-worker
41.8832,Pod,MODIFIED,eval-sanitize-3-r3-026-mmf5k,phase=Running node=kind-worker
42.0197,TaskRequest,ADDED,eval-sanitize-3-r3-042,phase=None job=None
42.0235,TaskRequest,MODIFIED,eval-sanitize-3-r3-042,phase=Pending job=None
42.0392,Job,ADDED,eval-sanitize-3-r3-042,
42.0451,TaskRequest,MODIFIED,eval-sanitize-3-r3-042,phase=Scheduled job=None
42.0462,Pod,ADDED,eval-sanitize-3-r3-042-bkwv9,phase=Pending node=None
42.0485,Job,MODIFIED,eval-sanitize-3-r3-042,
42.0512,Event,ADDED,eval-sanitize-3-r3-042.18d3d2fe91f930c7,reason=SuccessfulCreate count=1 msg=Created pod: eval-sanitize-3-r3-042-bkwv9
42.0522,Pod,MODIFIED,eval-sanitize-3-r3-042-bkwv9,phase=Pending node=None
42.0527,Event,ADDED,eval-sanitize-3-r3-042-bkwv9.18d3d2fe9206e381,"reason=FailedScheduling count=None msg=0/6 nodes are available: 6 node(s) had untolerated taint(s). no new claims to deallocate, preemption: 0/6 nodes are available: 6 Preemption is not helpful for scheduling."
42.0528,TaskRequest,MODIFIED,eval-sanitize-3-r3-042,phase=Scheduled job=None
42.0552,Job,MODIFIED,eval-sanitize-3-r3-041,
42.0633,Job,MODIFIED,eval-sanitize-3-r3-041,
42.2869,Job,MODIFIED,eval-sanitize-3-r3-022,
42.2913,Job,MODIFIED,eval-sanitize-3-r3-022,
42.2935,Job,MODIFIED,eval-sanitize-3-r3-024,
42.2967,Event,ADDED,eval-sanitize-3-r3-022.18d3d2fea0a08d15,reason=Completed count=1 msg=Job completed
42.2979,Job,MODIFIED,eval-sanitize-3-r3-024,
42.3,Job,MODIFIED,eval-sanitize-3-r3-025,
42.3029,Job,MODIFIED,eval-sanitize-3-r3-022,
42.3042,Event,ADDED,eval-sanitize-3-r3-024.18d3d2fea0fecd54,reason=Completed count=1 msg=Job completed
42.3053,Job,MODIFIED,eval-sanitize-3-r3-025,
42.3075,Job,MODIFIED,eval-sanitize-3-r3-027,
42.3091,TaskRequest,MODIFIED,eval-sanitize-3-r3-022,phase=Complete job=None
42.31,Job,MODIFIED,eval-sanitize-3-r3-024,
42.3113,Event,ADDED,eval-sanitize-3-r3-025.18d3d2fea16e4a97,reason=Completed count=1 msg=Job completed
42.3123,Job,MODIFIED,eval-sanitize-3-r3-027,
42.3131,Job,MODIFIED,eval-sanitize-3-r3-028,
42.3166,Job,MODIFIED,eval-sanitize-3-r3-028,
42.3181,Event,ADDED,eval-sanitize-3-r3-027.18d3d2fea1dc2895,reason=Completed count=1 msg=Job completed
42.3182,TaskRequest,MODIFIED,eval-sanitize-3-r3-024,phase=Complete job=None
42.3191,Job,MODIFIED,eval-sanitize-3-r3-025,
42.3207,Job,MODIFIED,eval-sanitize-3-r3-022,
42.3229,Job,MODIFIED,eval-sanitize-3-r3-027,
42.3238,Event,ADDED,eval-sanitize-3-r3-028.18d3d2fea22594c5,reason=Completed count=1 msg=Job completed
42.3254,TaskRequest,MODIFIED,eval-sanitize-3-r3-025,phase=Complete job=None
42.3845,Job,MODIFIED,eval-sanitize-3-r3-024,
42.3862,Job,MODIFIED,eval-sanitize-3-r3-028,
42.3863,TaskRequest,MODIFIED,eval-sanitize-3-r3-027,phase=Complete job=None
42.3883,Job,MODIFIED,eval-sanitize-3-r3-025,
42.3902,TaskRequest,MODIFIED,eval-sanitize-3-r3-028,phase=Complete job=None
42.4069,Job,MODIFIED,eval-sanitize-3-r3-027,
42.4092,Job,MODIFIED,eval-sanitize-3-r3-028,
42.4128,Pod,MODIFIED,eval-sanitize-3-r3-031-4fnvg,phase=Running node=kind-worker4
42.884,Pod,MODIFIED,eval-sanitize-3-r3-030-rddvq,phase=Running node=kind-worker
42.8856,Job,MODIFIED,eval-sanitize-3-r3-029,
42.888,Job,MODIFIED,eval-sanitize-3-r3-026,
42.8963,Job,MODIFIED,eval-sanitize-3-r3-029,
42.8986,Job,MODIFIED,eval-sanitize-3-r3-026,
42.9768,Pod,MODIFIED,eval-sanitize-3-r3-029-8klt2,phase=Succeeded node=kind-worker
43.007,TaskRequest,ADDED,eval-sanitize-3-r3-043,phase=None job=None
43.0125,TaskRequest,MODIFIED,eval-sanitize-3-r3-043,phase=Pending job=None
43.0158,Pod,MODIFIED,eval-sanitize-3-r3-026-mmf5k,phase=Succeeded node=kind-worker
43.0277,Job,ADDED,eval-sanitize-3-r3-043,
43.0334,Pod,ADDED,eval-sanitize-3-r3-043-kslkf,phase=Pending node=None
43.0354,Job,MODIFIED,eval-sanitize-3-r3-043,
43.0355,TaskRequest,MODIFIED,eval-sanitize-3-r3-043,phase=Scheduled job=None
43.0391,Event,ADDED,eval-sanitize-3-r3-043.18d3d2feccdb369d,reason=SuccessfulCreate count=1 msg=Created pod: eval-sanitize-3-r3-043-kslkf
43.0394,Event,ADDED,eval-sanitize-3-r3-043-kslkf.18d3d2fecce64f7a,"reason=FailedScheduling count=None msg=0/6 nodes are available: 6 node(s) had untolerated taint(s). no new claims to deallocate, preemption: 0/6 nodes are available: 6 Preemption is not helpful for scheduling."
43.0403,Pod,MODIFIED,eval-sanitize-3-r3-043-kslkf,phase=Pending node=None
43.0429,TaskRequest,MODIFIED,eval-sanitize-3-r3-043,phase=Scheduled job=None
43.0498,Job,MODIFIED,eval-sanitize-3-r3-042,
43.0586,Job,MODIFIED,eval-sanitize-3-r3-042,
43.4133,Pod,MODIFIED,eval-sanitize-3-r3-032-ps7mn,phase=Running node=kind-worker4
43.4183,Job,MODIFIED,eval-sanitize-3-r3-031,
43.4293,Job,MODIFIED,eval-sanitize-3-r3-031,
43.5066,Pod,MODIFIED,eval-sanitize-3-r3-031-4fnvg,phase=Succeeded node=kind-worker4
43.5286,Node,MODIFIED,kind-worker2,taints=1
43.5412,Node,MODIFIED,kind-worker2,taints=0
43.5469,Pod,MODIFIED,eval-sanitize-3-r3-038-vdkjz,phase=Pending node=kind-worker2
43.554,Node,MODIFIED,kind-worker2,taints=0
43.5554,Event,ADDED,eval-sanitize-3-r3-038-vdkjz.18d3d2feeb6cb031,reason=Scheduled count=None msg=Successfully assigned compute/eval-sanitize-3-r3-038-vdkjz to kind-worker2
43.5567,Pod,MODIFIED,eval-sanitize-3-r3-039-k4ldp,phase=Pending node=kind-worker2
43.5586,Pod,MODIFIED,eval-sanitize-3-r3-040-55zl6,phase=Pending node=kind-worker2
43.5638,Pod,MODIFIED,eval-sanitize-3-r3-038-vdkjz,phase=Pending node=kind-worker2
43.5681,Event,ADDED,eval-sanitize-3-r3-039-k4ldp.18d3d2feec01c154,reason=Scheduled count=None msg=Successfully assigned compute/eval-sanitize-3-r3-039-k4ldp to kind-worker2
43.5687,Event,ADDED,eval-sanitize-3-r3-040-55zl6.18d3d2feec2b1793,reason=Scheduled count=None msg=Successfully assigned compute/eval-sanitize-3-r3-040-55zl6 to kind-worker2
43.5703,Pod,MODIFIED,eval-sanitize-3-r3-041-c9zgv,phase=Pending node=kind-worker2
43.5711,Event,ADDED,eval-sanitize-3-r3-043-kslkf.18d3d2feec65d571,"reason=FailedScheduling count=None msg=0/6 nodes are available: 1 c_wall violated: 2 conflicting context pair(s) with node memory, 5 node(s) had untolerated taint(s). no new claims to deallocate, preemption: 0/6 nodes are available: 1 No preemption victims found for incoming pod, 5 Preemption is not helpful for scheduling."
43.5723,Pod,MODIFIED,eval-sanitize-3-r3-042-bkwv9,phase=Pending node=kind-worker2
43.574,Node,MODIFIED,kind-worker2,taints=0
43.5748,Pod,MODIFIED,eval-sanitize-3-r3-043-kslkf,phase=Pending node=None
43.5791,Event,ADDED,eval-sanitize-3-r3-041-c9zgv.18d3d2feecbdba13,reason=Scheduled count=None msg=Successfully assigned compute/eval-sanitize-3-r3-041-c9zgv to kind-worker2
43.5793,Event,ADDED,eval-sanitize-3-r3-042-bkwv9.18d3d2feecc01305,reason=Scheduled count=None msg=Successfully assigned compute/eval-sanitize-3-r3-042-bkwv9 to kind-worker2
43.5809,Pod,MODIFIED,eval-sanitize-3-r3-039-k4ldp,phase=Pending node=kind-worker2
43.5813,Event,ADDED,eval-sanitize-3-r3-043-kslkf.18d3d2feed32875e,"reason=FailedScheduling count=None msg=0/6 nodes are available: 1 c_wall violated: 2 conflicting context pair(s) with node memory, 5 node(s) had untolerated taint(s). no new claims to deallocate, preemption: 0/6 nodes are available: 1 No preemption victims found for incoming pod, 5 Preemption is not helpful for scheduling."
43.5846,Node,MODIFIED,kind-worker2,taints=0
43.5872,Pod,MODIFIED,eval-sanitize-3-r3-040-55zl6,phase=Pending node=kind-worker2
43.5925,Pod,MODIFIED,eval-sanitize-3-r3-042-bkwv9,phase=Pending node=kind-worker2
43.5983,Pod,MODIFIED,eval-sanitize-3-r3-041-c9zgv,phase=Pending node=kind-worker2
43.6224,Node,MODIFIED,kind-worker2,taints=0
43.6232,Event,MODIFIED,eval-sanitize-3-r3-043-kslkf.18d3d2feed32875e,"reason=FailedScheduling count=None msg=0/6 nodes are available: 1 c_wall violated: 2 conflicting context pair(s) with node memory, 5 node(s) had untolerated taint(s). no new claims to deallocate, preemption: 0/6 nodes are available: 1 No preemption victims found for incoming pod, 5 Preemption is not helpful for scheduling."
43.6354,Node,MODIFIED,kind-worker2,taints=0
43.6897,Node,MODIFIED,kind-worker2,taints=0
43.6994,Node,MODIFIED,kind-worker2,taints=0
43.8896,Pod,MODIFIED,eval-sanitize-3-r3-033-zv46r,phase=Running node=kind-worker
43.891,Job,MODIFIED,eval-sanitize-3-r3-030,
43.8936,Job,MODIFIED,eval-sanitize-3-r3-029,
43.8956,Job,MODIFIED,eval-sanitize-3-r3-026,
43.9035,Job,MODIFIED,eval-sanitize-3-r3-030,
43.9123,Job,MODIFIED,eval-sanitize-3-r3-029,
43.9137,Job,MODIFIED,eval-sanitize-3-r3-026,
43.915,Pod,MODIFIED,eval-sanitize-3-r3-026-mmf5k,phase=Succeeded node=kind-worker
43.9164,Pod,MODIFIED,eval-sanitize-3-r3-029-8klt2,phase=Succeeded node=kind-worker
44.0128,TaskRequest,ADDED,eval-sanitize-3-r3-044,phase=None job=None
44.0167,TaskRequest,MODIFIED,eval-sanitize-3-r3-044,phase=Pending job=None
44.0355,Job,ADDED,eval-sanitize-3-r3-044,
44.041,Job,MODIFIED,eval-sanitize-3-r3-043,
44.0433,Pod,ADDED,eval-sanitize-3-r3-044-fvf52,phase=Pending node=None
44.0435,TaskRequest,MODIFIED,eval-sanitize-3-r3-044,phase=Scheduled job=None
44.0462,Job,MODIFIED,eval-sanitize-3-r3-044,
44.0494,Event,ADDED,eval-sanitize-3-r3-044.18d3d2ff0912a786,reason=SuccessfulCreate count=1 msg=Created pod: eval-sanitize-3-r3-044-fvf52
44.0541,Pod,MODIFIED,eval-sanitize-3-r3-044-fvf52,phase=Pending node=None
44.0551,Job,MODIFIED,eval-sanitize-3-r3-043,
44.0583,Event,ADDED,eval-sanitize-3-r3-042-bkwv9.18d3d2ff09437366,"reason=Pulled count=1 msg=Container image ""busybox:musl"" already present on machine"
44.0585,TaskRequest,MODIFIED,eval-sanitize-3-r3-044,phase=Scheduled job=None
44.0589,Event,ADDED,eval-sanitize-3-r3-044-fvf52.18d3d2ff0950fcae,"reason=FailedScheduling count=None msg=0/6 nodes are available: 1 c_wall violated: 2 conflicting context pair(s) with node memory, 5 node(s) had untolerated taint(s). no new claims to deallocate, preemption: 0/6 nodes are available: 1 No preemption victims found for incoming pod, 5 Preemption is not helpful for scheduling."
44.0631,Event,ADDED,eval-sanitize-3-r3-044-fvf52.18d3d2ff09eaa669,"reason=FailedScheduling count=None msg=0/6 nodes are available: 1 c_wall violated: 2 conflicting context pair(s) with node memory, 5 node(s) had untolerated taint(s). no new claims to deallocate, preemption: 0/6 nodes are available: 1 No preemption victims found for incoming pod, 5 Preemption is not helpful for scheduling."
44.0638,Event,ADDED,eval-sanitize-3-r3-041-c9zgv.18d3d2ff095c80bc,"reason=Pulled count=1 msg=Container image ""busybox:musl"" already present on machine"
44.0758,Event,ADDED,eval-sanitize-3-r3-042-bkwv9.18d3d2ff0ac6e026,reason=Created count=1 msg=Created container: task
44.0826,Event,ADDED,eval-sanitize-3-r3-038-vdkjz.18d3d2ff0ae86c69,"reason=Pulled count=1 msg=Container image ""busybox:musl"" already present on machine"
44.0891,Event,ADDED,eval-sanitize-3-r3-041-c9zgv.18d3d2ff0b9402fa,reason=Created count=1 msg=Created container: task
44.1,Event,ADDED,eval-sanitize-3-r3-038-vdkjz.18d3d2ff0c2fa5de,reason=Created count=1 msg=Created container: task
44.1217,Pod,MODIFIED,eval-sanitize-3-r3-030-rddvq,phase=Succeeded node=kind-worker
44.1293,Event,ADDED,eval-sanitize-3-r3-039-k4ldp.18d3d2ff0d8992f4,"reason=Pulled count=1 msg=Container image ""busybox:musl"" already present on machine"
44.1339,Event,ADDED,eval-sanitize-3-r3-040-55zl6.18d3d2ff0de32468,"reason=Pulled count=1 msg=Container image ""busybox:musl"" already present on machine"
44.1347,Event,MODIFIED,eval-sanitize-3-r3-044-fvf52.18d3d2ff09eaa669,"reason=FailedScheduling count=None msg=0/6 nodes are available: 1 c_wall violated: 2 conflicting context pair(s) with node memory, 5 node(s) had untolerated taint(s). no new claims to deallocate, preemption: 0/6 nodes are available: 1 No preemption victims found for incoming pod, 5 Preemption is not helpful for scheduling."
44.1383,Event,ADDED,eval-sanitize-3-r3-042-bkwv9.18d3d2ff0e61d545,reason=Started count=1 msg=Started container task
44.1543,Event,ADDED,eval-sanitize-3-r3-039-k4ldp.18d3d2ff0f52a3bc,reason=Created count=1 msg=Created container: task
44.1583,Event,ADDED,eval-sanitize-3-r3-038-vdkjz.18d3d2ff0f5930c1,reason=Started count=1 msg=Started container task
44.1625,Event,ADDED,eval-sanitize-3-r3-041-c9zgv.18d3d2ff0f59f351,reason=Started count=1 msg=Started container task
44.1663,Event,ADDED,eval-sanitize-3-r3-040-55zl6.18d3d2ff0fd0c7a9,reason=Created count=1 msg=Created container: task
44.2248,Event,ADDED,eval-sanitize-3-r3-039-k4ldp.18d3d2ff13819d92,reason=Started count=1 msg=Started container task
44.2307,Event,ADDED,eval-sanitize-3-r3-040-55zl6.18d3d2ff14097e35,reason=Started count=1 msg=Started container task
44.2927,Pod,MODIFIED,eval-sanitize-3-r3-040-55zl6,phase=Running node=kind-worker2
44.2993,Pod,MODIFIED,eval-sanitize-3-r3-038-vdkjz,phase=Running node=kind-worker2
44.3073,Pod,MODIFIED,eval-sanitize-3-r3-042-bkwv9,phase=Running node=kind-worker2
44.3141,Pod,MODIFIED,eval-sanitize-3-r3-039-k4ldp,phase=Running node=kind-worker2
44.3201,Pod,MODIFIED,eval-sanitize-3-r3-041-c9zgv,phase=Running node=kind-worker2
44.4191,Job,MODIFIED,eval-sanitize-3-r3-032,
44.4228,Job,MODIFIED,eval-sanitize-3-r3-031,
44.4304,Job,MODIFIED,eval-sanitize-3-r3-032,
44.4356,Pod,MODIFIED,eval-sanitize-3-r3-031-4fnvg,phase=Succeeded node=kind-worker4
44.4366,Job,MODIFIED,eval-sanitize-3-r3-031,
44.5082,Pod,MODIFIED,eval-sanitize-3-r3-032-ps7mn,phase=Succeeded node=kind-worker4
44.5361,Node,MODIFIED,kind-worker4,taints=1
44.5518,Job,MODIFIED,eval-sanitize-3-r3-038,
44.5609,Job,MODIFIED,eval-sanitize-3-r3-038,
44.5627,Job,MODIFIED,eval-sanitize-3-r3-039,
44.5635,Job,MODIFIED,eval-sanitize-3-r3-040,
44.5721,Job,MODIFIED,eval-sanitize-3-r3-039,
44.5744,Job,MODIFIED,eval-sanitize-3-r3-040,
44.575,Job,MODIFIED,eval-sanitize-3-r3-041,
44.583,Job,MODIFIED,eval-sanitize-3-r3-041,
44.8941,Job,MODIFIED,eval-sanitize-3-r3-033,
44.8962,Job,MODIFIED,eval-sanitize-3-r3-030,
44.8991,Job,MODIFIED,eval-sanitize-3-r3-026,
44.9,Job,MODIFIED,eval-sanitize-3-r3-029,
44.9033,Job,MODIFIED,eval-sanitize-3-r3-029,
44.9104,Pod,MODIFIED,eval-sanitize-3-r3-030-rddvq,phase=Succeeded node=kind-worker
44.9114,Job,MODIFIED,eval-sanitize-3-r3-026,
44.9122,Job,MODIFIED,eval-sanitize-3-r3-033,
44.9125,Event,ADDED,eval-sanitize-3-r3-029.18d3d2ff3c51d285,reason=Completed count=1 msg=Job completed
44.9133,Job,MODIFIED,eval-sanitize-3-r3-030,
44.9167,Event,ADDED,eval-sanitize-3-r3-026.18d3d2ff3cb0c19c,reason=Completed count=1 msg=Job completed
44.9198,Job,MODIFIED,eval-sanitize-3-r3-026,
44.9224,Job,MODIFIED,eval-sanitize-3-r3-029,
44.9274,TaskRequest,MODIFIED,eval-sanitize-3-r3-026,phase=Complete job=None
44.9326,TaskRequest,MODIFIED,eval-sanitize-3-r3-029,phase=Complete job=None
44.9384,Job,MODIFIED,eval-sanitize-3-r3-026,
44.972,Pod,MODIFIED,eval-sanitize-3-r3-033-zv46r,phase=Succeeded node=kind-worker
44.9855,Job,MODIFIED,eval-sanitize-3-r3-029,
45.0083,TaskRequest,ADDED,eval-sanitize-3-r3-045,phase=None job=None
45.0118,TaskRequest,MODIFIED,eval-sanitize-3-r3-045,phase=Pending job=None
45.0266,Job,ADDED,eval-sanitize-3-r3-045,
45.0315,Pod,ADDED,eval-sanitize-3-r3-045-vpnjr,phase=Pending node=None
45.0335,TaskRequest,MODIFIED,eval-sanitize-3-r3-045,phase=Scheduled job=None
45.0362,Job,MODIFIED,eval-sanitize-3-r3-045,
45.0367,Event,ADDED,eval-sanitize-3-r3-045.18d3d2ff43fa9440,reason=SuccessfulCreate count=1 msg=Created pod: eval-sanitize-3-r3-045-vpnjr
45.0422,Event,ADDED,eval-sanitize-3-r3-045-vpnjr.18d3d2ff4437d8ca,"reason=FailedScheduling count=None msg=0/6 nodes are available: 1 c_wall violated: 2 conflicting context pair(s) with node memory, 5 node(s) had untolerated taint(s). no new claims to deallocate, preemption: 0/6 nodes are available: 1 No preemption victims found for incoming pod, 5 Preemption is not helpful for scheduling."
45.0423,TaskRequest,MODIFIED,eval-sanitize-3-r3-045,phase=Scheduled job=None
45.0432,Pod,MODIFIED,eval-sanitize-3-r3-045-vpnjr,phase=Pending node=None
45.0484,Job,MODIFIED,eval-sanitize-3-r3-044,
45.0499,Event,ADDED,eval-sanitize-3-r3-045-vpnjr.18d3d2ff44d8d1b0,"reason=FailedScheduling count=None msg=0/6 nodes are available: 1 c_wall violated: 2 conflicting context pair(s) with node memory, 5 node(s) had untolerated taint(s). no new claims to deallocate, preemption: 0/6 nodes are available: 1 No preemption victims found for incoming pod, 5 Preemption is not helpful for scheduling."
45.0574,Job,MODIFIED,eval-sanitize-3-r3-044,
45.3127,Job,MODIFIED,eval-sanitize-3-r3-042,
45.3217,Job,MODIFIED,eval-sanitize-3-r3-042,
45.4241,Job,MODIFIED,eval-sanitize-3-r3-032,
45.4285,Job,MODIFIED,eval-sanitize-3-r3-031,
45.4315,Pod,MODIFIED,eval-sanitize-3-r3-034-fsqln,phase=Running node=kind-worker3
45.4329,Pod,MODIFIED,eval-sanitize-3-r3-032-ps7mn,phase=Succeeded node=kind-worker4
45.4356,Job,MODIFIED,eval-sanitize-3-r3-031,
45.4365,Job,MODIFIED,eval-sanitize-3-r3-032,
45.442,Pod,MODIFIED,eval-sanitize-3-r3-023-7hhqc,phase=Running node=kind-worker3
45.4424,Event,ADDED,eval-sanitize-3-r3-031.18d3d2ff5c0b1d42,reason=Completed count=1 msg=Job completed
45.4455,Job,MODIFIED,eval-sanitize-3-r3-031,
45.4501,Event,MODIFIED,eval-sanitize-3-r3-045-vpnjr.18d3d2ff44d8d1b0,"reason=FailedScheduling count=None msg=0/6 nodes are available: 1 c_wall violated: 2 conflicting context pair(s) with node memory, 5 node(s) had untolerated taint(s). no new claims to deallocate, preemption: 0/6 nodes are available: 1 No preemption victims found for incoming pod, 5 Preemption is not helpful for scheduling."
45.4506,TaskRequest,MODIFIED,eval-sanitize-3-r3-031,phase=Complete job=None
45.4596,Job,MODIFIED,eval-sanitize-3-r3-031,
45.901,Job,MODIFIED,eval-sanitize-3-r3-033,
45.9028,Job,MODIFIED,eval-sanitize-3-r3-030,
45.9072,Job,MODIFIED,eval-sanitize-3-r3-030,
45.9103,Pod,MODIFIED,eval-sanitize-3-r3-033-zv46r,phase=Succeeded node=kind-worker
45.9123,Job,MODIFIED,eval-sanitize-3-r3-033,
45.9136,Event,ADDED,eval-sanitize-3-r3-030.18d3d2ff782748a8,reason=Completed count=1 msg=Job completed
45.9204,Job,MODIFIED,eval-sanitize-3-r3-030,
45.9259,TaskRequest,MODIFIED,eval-sanitize-3-r3-030,phase=Complete job=None
45.9347,Job,MODIFIED,eval-sanitize-3-r3-030,
46.0086,TaskRequest,ADDED,eval-sanitize-3-r3-046,phase=None job=None
46.0124,TaskRequest,MODIFIED,eval-sanitize-3-r3-046,phase=Pending job=None
46.0279,Job,ADDED,eval-sanitize-3-r3-046,
46.0328,Pod,ADDED,eval-sanitize-3-r3-046-6px6g,phase=Pending node=None
46.0345,TaskRequest,MODIFIED,eval-sanitize-3-r3-046,phase=Scheduled job=None
46.038,Job,MODIFIED,eval-sanitize-3-r3-046,
46.0384,Event,ADDED,eval-sanitize-3-r3-046.18d3d2ff7fa6a7d5,reason=SuccessfulCreate count=1 msg=Created pod: eval-sanitize-3-r3-046-6px6g
46.0392,Job,MODIFIED,eval-sanitize-3-r3-045,
46.042,Pod,MODIFIED,eval-sanitize-3-r3-046-6px6g,phase=Pending node=None
46.0431,Event,ADDED,eval-sanitize-3-r3-046-6px6g.18d3d2ff7fe13520,"reason=FailedScheduling count=None msg=0/6 nodes are available: 1 c_wall violated: 1 conflicting context pair(s) with node memory, 5 node(s) had untolerated taint(s). no new claims to deallocate, preemption: 0/6 nodes are available: 1 No preemption victims found for incoming pod, 5 Preemption is not helpful for scheduling."
46.0432,TaskRequest,MODIFIED,eval-sanitize-3-r3-046,phase=Scheduled job=None
46.0472,Job,MODIFIED,eval-sanitize-3-r3-045,
46.0498,Event,ADDED,eval-sanitize-3-r3-046-6px6g.18d3d2ff806e1249,"reason=FailedScheduling count=None msg=0/6 nodes are available: 1 c_wall violated: 1 conflicting context pair(s) with node memory, 5 node(s) had untolerated taint(s). no new claims to deallocate, preemption: 0/6 nodes are available: 1 No preemption victims found for incoming pod, 5 Preemption is not helpful for scheduling."
46.4312,Job,MODIFIED,eval-sanitize-3-r3-032,
46.4366,Job,MODIFIED,eval-sanitize-3-r3-034,
46.4378,Job,MODIFIED,eval-sanitize-3-r3-032,
46.4429,Event,ADDED,eval-sanitize-3-r3-032.18d3d2ff97b4a80a,reason=Completed count=1 msg=Job completed
46.4458,Job,MODIFIED,eval-sanitize-3-r3-023,
46.4488,Job,MODIFIED,eval-sanitize-3-r3-034,
46.4496,Job,MODIFIED,eval-sanitize-3-r3-032,
46.4551,Job,MODIFIED,eval-sanitize-3-r3-023,
46.4568,TaskRequest,MODIFIED,eval-sanitize-3-r3-032,phase=Complete job=None
46.4662,Job,MODIFIED,eval-sanitize-3-r3-032,
46.4769,Pod,MODIFIED,eval-sanitize-3-r3-035-6bmlr,phase=Running node=kind-worker5
46.4952,Event,MODIFIED,eval-sanitize-3-r3-046-6px6g.18d3d2ff806e1249,"reason=FailedScheduling count=None msg=0/6 nodes are available: 1 c_wall violated: 1 conflicting context pair(s) with node memory, 5 node(s) had untolerated taint(s). no new claims to deallocate, preemption: 0/6 nodes are available: 1 No preemption victims found for incoming pod, 5 Preemption is not helpful for scheduling."
46.5599,Node,MODIFIED,kind-worker2,taints=1
46.5677,Pod,MODIFIED,eval-sanitize-3-r3-043-kslkf,phase=Pending node=None
46.5739,Node,MODIFIED,kind-worker2,taints=1
46.5757,Pod,MODIFIED,eval-sanitize-3-r3-044-fvf52,phase=Pending node=None
46.5812,Pod,MODIFIED,eval-sanitize-3-r3-045-vpnjr,phase=Pending node=None
46.5959,Pod,MODIFIED,eval-sanitize-3-r3-023-7hhqc,phase=Succeeded node=kind-worker3
46.6069,Pod,MODIFIED,eval-sanitize-3-r3-046-6px6g,phase=Pending node=None
46.6269,Pod,MODIFIED,eval-sanitize-3-r3-034-fsqln,phase=Succeeded node=kind-worker3
46.9075,Job,MODIFIED,eval-sanitize-3-r3-033,
46.9121,Job,MODIFIED,eval-sanitize-3-r3-033,
46.9167,Event,ADDED,eval-sanitize-3-r3-033.18d3d2ffb408a6c8,reason=Completed count=1 msg=Job completed
46.9232,Job,MODIFIED,eval-sanitize-3-r3-033,
46.9271,TaskRequest,MODIFIED,eval-sanitize-3-r3-033,phase=Complete job=None
46.9317,Node,MODIFIED,kind-worker,taints=1
46.9363,Job,MODIFIED,eval-sanitize-3-r3-033,
46.9425,Node,MODIFIED,kind-worker,taints=1
46.9515,Node,MODIFIED,kind-worker,taints=0
46.9574,Pod,MODIFIED,eval-sanitize-3-r3-043-kslkf,phase=Pending node=kind-worker
46.962,Pod,MODIFIED,eval-sanitize-3-r3-044-fvf52,phase=Pending node=kind-worker
46.9624,Event,ADDED,eval-sanitize-3-r3-043-kslkf.18d3d2ffb6bc2f1c,reason=Scheduled count=None msg=Successfully assigned compute/eval-sanitize-3-r3-043-kslkf to kind-worker
46.9652,Pod,MODIFIED,eval-sanitize-3-r3-045-vpnjr,phase=Pending node=kind-worker
46.9691,Event,ADDED,eval-sanitize-3-r3-044-fvf52.18d3d2ffb6fa995b,reason=Scheduled count=None msg=Successfully assigned compute/eval-sanitize-3-r3-044-fvf52 to kind-worker
46.9695,Event,ADDED,eval-sanitize-3-r3-046-6px6g.18d3d2ffb704572c,"reason=FailedScheduling count=None msg=0/6 nodes are available: 1 c_wall violated: 1 conflicting context pair(s) with node memory, 5 node(s) had untolerated taint(s). no new claims to deallocate, preemption: 0/6 nodes are available: 1 No preemption victims found for incoming pod, 5 Preemption is not helpful for scheduling."
46.9709,Node,MODIFIED,kind-worker,taints=0
46.9717,Pod,MODIFIED,eval-sanitize-3-r3-046-6px6g,phase=Pending node=None
46.9741,Event,ADDED,eval-sanitize-3-r3-045-vpnjr.18d3d2ffb735b49d,reason=Scheduled count=None msg=Successfully assigned compute/eval-sanitize-3-r3-045-vpnjr to kind-worker
46.976,Pod,MODIFIED,eval-sanitize-3-r3-043-kslkf,phase=Pending node=kind-worker
46.9799,Event,MODIFIED,eval-sanitize-3-r3-046-6px6g.18d3d2ffb704572c,"reason=FailedScheduling count=None msg=0/6 nodes are available: 1 c_wall violated: 1 conflicting context pair(s) with node memory, 5 node(s) had untolerated taint(s). no new claims to deallocate, preemption: 0/6 nodes are available: 1 No preemption victims found for incoming pod, 5 Preemption is not helpful for scheduling."
46.9833,Pod,MODIFIED,eval-sanitize-3-r3-044-fvf52,phase=Pending node=kind-worker
46.9841,Event,ADDED,eval-sanitize-3-r3-046-6px6g.18d3d2ffb81409ac,"reason=FailedScheduling count=None msg=0/6 nodes are available: 1 c_wall violated: 1 conflicting context pair(s) with node memory, 5 node(s) had untolerated taint(s). no new claims to deallocate, preemption: 0/6 nodes are available: 1 No preemption victims found for incoming pod, 5 Preemption is not helpful for scheduling."
46.992,Pod,MODIFIED,eval-sanitize-3-r3-045-vpnjr,phase=Pending node=kind-worker
46.9928,Event,MODIFIED,eval-sanitize-3-r3-046-6px6g.18d3d2ffb81409ac,"reason=FailedScheduling count=None msg=0/6 nodes are available: 1 c_wall violated: 1 conflicting context pair(s) with node memory, 5 node(s) had untolerated taint(s). no new claims to deallocate, preemption: 0/6 nodes are available: 1 No preemption victims found for incoming pod, 5 Preemption is not helpful for scheduling."
46.9964,Node,MODIFIED,kind-worker,taints=0
47.0068,TaskRequest,ADDED,eval-sanitize-3-r3-047,phase=None job=None
47.0103,TaskRequest,MODIFIED,eval-sanitize-3-r3-047,phase=Pending job=None
47.0267,Job,ADDED,eval-sanitize-3-r3-047,
47.0335,Pod,ADDED,eval-sanitize-3-r3-047-jkxpc,phase=Pending node=None
47.0345,TaskRequest,MODIFIED,eval-sanitize-3-r3-047,phase=Scheduled job=None
47.0355,Job,MODIFIED,eval-sanitize-3-r3-047,
47.0397,Event,ADDED,eval-sanitize-3-r3-047.18d3d2ffbb493604,reason=SuccessfulCreate count=1 msg=Created pod: eval-sanitize-3-r3-047-jkxpc
47.0411,Job,MODIFIED,eval-sanitize-3-r3-046,
47.0422,Pod,MODIFIED,eval-sanitize-3-r3-047-jkxpc,phase=Pending node=None
47.0428,Event,ADDED,eval-sanitize-3-r3-047-jkxpc.18d3d2ffbb8d5891,"reason=FailedScheduling count=None msg=0/6 nodes are available: 1 c_wall violated: 1 conflicting context pair(s) with node memory, 5 node(s) had untolerated taint(s). no new claims to deallocate, preemption: 0/6 nodes are available: 1 No preemption victims found for incoming pod, 5 Preemption is not helpful for scheduling."
47.0435,TaskRequest,MODIFIED,eval-sanitize-3-r3-047,phase=Scheduled job=None
47.0491,Job,MODIFIED,eval-sanitize-3-r3-046,
47.0494,Event,ADDED,eval-sanitize-3-r3-047-jkxpc.18d3d2ffbbfc89bb,"reason=FailedScheduling count=None msg=0/6 nodes are available: 1 c_wall violated: 1 conflicting context pair(s) with node memory, 5 node(s) had untolerated taint(s). no new claims to deallocate, preemption: 0/6 nodes are available: 1 No preemption victims found for incoming pod, 5 Preemption is not helpful for scheduling."
47.1307,Node,MODIFIED,kind-worker,taints=0
47.1415,Event,MODIFIED,eval-sanitize-3-r3-047-jkxpc.18d3d2ffbbfc89bb,"reason=FailedScheduling count=None msg=0/6 nodes are available: 1 c_wall violated: 1 conflicting context pair(s) with node memory, 5 node(s) had untolerated taint(s). no new claims to deallocate, preemption: 0/6 nodes are available: 1 No preemption victims found for incoming pod, 5 Preemption is not helpful for scheduling."
47.3278,Node,MODIFIED,kind-worker,taints=0
47.4061,Event,ADDED,eval-sanitize-3-r3-043-kslkf.18d3d2ffd13c36d8,"reason=Pulled count=1 msg=Container image ""busybox:musl"" already present on machine"
47.4272,Event,ADDED,eval-sanitize-3-r3-045-vpnjr.18d3d2ffd273bb4c,"reason=Pulled count=1 msg=Container image ""busybox:musl"" already present on machine"
47.4343,Node,MODIFIED,kind-worker4,taints=1
47.4346,Event,ADDED,eval-sanitize-3-r3-043-kslkf.18d3d2ffd2749c5a,reason=Created count=1 msg=Created container: task
47.4396,Event,ADDED,eval-sanitize-3-r3-044-fvf52.18d3d2ffd292183e,"reason=Pulled count=1 msg=Container image ""busybox:musl"" already present on machine"
47.4458,Job,MODIFIED,eval-sanitize-3-r3-034,
47.4471,Pod,MODIFIED,eval-sanitize-3-r3-036-4fnh6,phase=Running node=kind-worker3
47.4534,Job,MODIFIED,eval-sanitize-3-r3-023,
47.457,Pod,MODIFIED,eval-sanitize-3-r3-034-fsqln,phase=Succeeded node=kind-worker3
47.4577,Job,MODIFIED,eval-sanitize-3-r3-034,
47.4602,Event,ADDED,eval-sanitize-3-r3-045-vpnjr.18d3d2ffd42321f1,reason=Created count=1 msg=Created container: task
47.4646,Job,MODIFIED,eval-sanitize-3-r3-023,
47.4671,Pod,MODIFIED,eval-sanitize-3-r3-023-7hhqc,phase=Succeeded node=kind-worker3
47.4675,Event,ADDED,eval-sanitize-3-r3-044-fvf52.18d3d2ffd4abb6a2,reason=Created count=1 msg=Created container: task
47.483,Job,MODIFIED,eval-sanitize-3-r3-035,
47.495,Job,MODIFIED,eval-sanitize-3-r3-035,
47.4971,Event,ADDED,eval-sanitize-3-r3-045-vpnjr.18d3d2ffd68aa67b,reason=Started count=1 msg=Started container task
47.5012,Event,ADDED,eval-sanitize-3-r3-044-fvf52.18d3d2ffd6e383c0,reason=Started count=1 msg=Started container task
47.5117,Event,ADDED,eval-sanitize-3-r3-043-kslkf.18d3d2ffd79af14f,reason=Started count=1 msg=Started container task
47.5198,Node,MODIFIED,kind-worker4,taints=0
47.5321,Node,MODIFIED,kind-worker4,taints=0
47.5334,Pod,MODIFIED,eval-sanitize-3-r3-046-6px6g,phase=Pending node=kind-worker4
47.5384,Pod,MODIFIED,eval-sanitize-3-r3-047-jkxpc,phase=Pending node=kind-worker4
47.5388,Event,ADDED,eval-sanitize-3-r3-046-6px6g.18d3d2ffd9114a04,reason=Scheduled count=None msg=Successfully assigned compute/eval-sanitize-3-r3-046-6px6g to kind-worker4
47.5499,Node,MODIFIED,kind-worker4,taints=0
47.5521,Event,ADDED,eval-sanitize-3-r3-047-jkxpc.18d3d2ffd94d24ef,reason=Scheduled count=None msg=Successfully assigned compute/eval-sanitize-3-r3-047-jkxpc to kind-worker4
47.5542,Pod,MODIFIED,eval-sanitize-3-r3-046-6px6g,phase=Pending node=kind-worker4
47.561,Pod,MODIFIED,eval-sanitize-3-r3-047-jkxpc,phase=Pending node=kind-worker4
47.5761,Node,MODIFIED,kind-worker4,taints=0
47.5861,Node,MODIFIED,kind-worker4,taints=0
47.642,Node,MODIFIED,kind-worker4,taints=0
47.65,Pod,MODIFIED,eval-sanitize-3-r3-035-6bmlr,phase=Succeeded node=kind-worker5
47.6528,Node,MODIFIED,kind-worker4,taints=0
47.9029,Pod,MODIFIED,eval-sanitize-3-r3-043-kslkf,phase=Running node=kind-worker
47.9089,Pod,MODIFIED,eval-sanitize-3-r3-045-vpnjr,phase=Running node=kind-worker
47.9152,Pod,MODIFIED,eval-sanitize-3-r3-044-fvf52,phase=Running node=kind-worker
47.9601,Event,ADDED,eval-sanitize-3-r3-046-6px6g.18d3d2fff2281150,"reason=Pulled count=1 msg=Container image ""busybox:musl"" already present on machine"
47.976,Event,ADDED,eval-sanitize-3-r3-046-6px6g.18d3d2fff343606b,reason=Created count=1 msg=Created container: task
48.0072,TaskRequest,ADDED,eval-sanitize-3-r3-048,phase=None job=None
48.0098,Event,ADDED,eval-sanitize-3-r3-046-6px6g.18d3d2fff54b3327,reason=Started count=1 msg=Started container task
48.0126,TaskRequest,MODIFIED,eval-sanitize-3-r3-048,phase=Pending job=None
48.0265,Job,ADDED,eval-sanitize-3-r3-048,
48.0323,TaskRequest,MODIFIED,eval-sanitize-3-r3-048,phase=Scheduled job=None
48.0338,Pod,ADDED,eval-sanitize-3-r3-048-r5xt9,phase=Pending node=None
48.0357,Job,MODIFIED,eval-sanitize-3-r3-048,
48.0385,Event,ADDED,eval-sanitize-3-r3-048.18d3d2fff6db955e,reason=SuccessfulCreate count=1 msg=Created pod: eval-sanitize-3-r3-048-r5xt9
48.0394,Job,MODIFIED,eval-sanitize-3-r3-047,
48.0396,TaskRequest,MODIFIED,eval-sanitize-3-r3-048,phase=Scheduled job=None
48.0469,Pod,MODIFIED,eval-sanitize-3-r3-048-r5xt9,phase=Pending node=None
48.0481,Event,ADDED,eval-sanitize-3-r3-048-r5xt9.18d3d2fff75c75ee,"reason=FailedScheduling count=None msg=0/6 nodes are available: 1 c_wall violated: 1 conflicting context pair(s) with node memory, 1 c_wall violated: 2 conflicting context pair(s) with node memory, 4 node(s) had untolerated taint(s). no new claims to deallocate, preemption: 0/6 nodes are available: 2 No preemption victims found for incoming pod, 4 Preemption is not helpful for scheduling."
48.0513,Job,MODIFIED,eval-sanitize-3-r3-047,
48.0516,Event,ADDED,eval-sanitize-3-r3-047-jkxpc.18d3d2fff7b33c7a,"reason=Pulled count=1 msg=Container image ""busybox:musl"" already present on machine"
48.0574,Event,ADDED,eval-sanitize-3-r3-048-r5xt9.18d3d2fff8061bca,"reason=FailedScheduling count=None msg=0/6 nodes are available: 1 c_wall violated: 1 conflicting context pair(s) with node memory, 1 c_wall violated: 2 conflicting context pair(s) with node memory, 4 node(s) had untolerated taint(s). no new claims to deallocate, preemption: 0/6 nodes are available: 2 No preemption victims found for incoming pod, 4 Preemption is not helpful for scheduling."
48.0726,Event,ADDED,eval-sanitize-3-r3-047-jkxpc.18d3d2fff8fe9a6d,reason=Created count=1 msg=Created container: task
48.1554,Event,ADDED,eval-sanitize-3-r3-047-jkxpc.18d3d2fffdef1307,reason=Started count=1 msg=Started container task
48.4245,Pod,MODIFIED,eval-sanitize-3-r3-046-6px6g,phase=Running node=kind-worker4
48.4309,Pod,MODIFIED,eval-sanitize-3-r3-047-jkxpc,phase=Running node=kind-worker4
48.436,Event,MODIFIED,eval-sanitize-3-r3-048-r5xt9.18d3d2fff8061bca,"reason=FailedScheduling count=None msg=0/6 nodes are available: 1 c_wall violated: 1 conflicting context pair(s) with node memory, 1 c_wall violated: 2 conflicting context pair(s) with node memory, 4 node(s) had untolerated taint(s). no new claims to deallocate, preemption: 0/6 nodes are available: 2 No preemption victims found for incoming pod, 4 Preemption is not helpful for scheduling."
48.4508,Job,MODIFIED,eval-sanitize-3-r3-034,
48.4534,Job,MODIFIED,eval-sanitize-3-r3-036,
48.4579,Job,MODIFIED,eval-sanitize-3-r3-034,
48.4599,Job,MODIFIED,eval-sanitize-3-r3-023,
48.4635,Job,MODIFIED,eval-sanitize-3-r3-036,
48.4651,Event,ADDED,eval-sanitize-3-r3-034.18d3d3001030d47c,reason=Completed count=1 msg=Job completed
48.466,Job,MODIFIED,eval-sanitize-3-r3-023,
48.4709,Event,ADDED,eval-sanitize-3-r3-023.18d3d30010a649fa,reason=Completed count=1 msg=Job completed
48.4719,Job,MODIFIED,eval-sanitize-3-r3-034,
48.4772,Job,MODIFIED,eval-sanitize-3-r3-023,
48.4774,TaskRequest,MODIFIED,eval-sanitize-3-r3-034,phase=Complete job=None
48.4837,Pod,MODIFIED,eval-sanitize-3-r3-037-cw865,phase=Running node=kind-worker5
48.4843,TaskRequest,MODIFIED,eval-sanitize-3-r3-023,phase=Complete job=None
48.487,Job,MODIFIED,eval-sanitize-3-r3-035,
48.4901,Job,MODIFIED,eval-sanitize-3-r3-034,
48.4937,Job,MODIFIED,eval-sanitize-3-r3-023,
48.496,Pod,MODIFIED,eval-sanitize-3-r3-035-6bmlr,phase=Succeeded node=kind-worker5
48.4974,Job,MODIFIED,eval-sanitize-3-r3-035,
48.5344,Pod,MODIFIED,eval-sanitize-3-r3-036-4fnh6,phase=Succeeded node=kind-worker3
48.9087,Job,MODIFIED,eval-sanitize-3-r3-043,
48.9137,Job,MODIFIED,eval-sanitize-3-r3-045,
48.9176,Job,MODIFIED,eval-sanitize-3-r3-043,
48.9225,Job,MODIFIED,eval-sanitize-3-r3-044,
48.9231,Job,MODIFIED,eval-sanitize-3-r3-045,
48.9312,Job,MODIFIED,eval-sanitize-3-r3-044,
49.0208,TaskRequest,ADDED,eval-sanitize-3-r3-049,phase=None job=None
49.0258,TaskRequest,MODIFIED,eval-sanitize-3-r3-049,phase=Pending job=None
49.0382,Job,MODIFIED,eval-sanitize-3-r3-048,
49.0395,Job,ADDED,eval-sanitize-3-r3-049,
49.044,Job,MODIFIED,eval-sanitize-3-r3-047,
49.0455,TaskRequest,MODIFIED,eval-sanitize-3-r3-049,phase=Scheduled job=None
49.0465,Pod,ADDED,eval-sanitize-3-r3-049-kqlvx,phase=Pending node=None
49.0479,Job,MODIFIED,eval-sanitize-3-r3-049,
49.0524,Event,ADDED,eval-sanitize-3-r3-049.18d3d30033428352,reason=SuccessfulCreate count=1 msg=Created pod: eval-sanitize-3-r3-049-kqlvx
49.0568,TaskRequest,MODIFIED,eval-sanitize-3-r3-049,phase=Scheduled job=None
49.0645,Job,MODIFIED,eval-sanitize-3-r3-048,
49.0655,Job,MODIFIED,eval-sanitize-3-r3-047,
49.0703,Pod,MODIFIED,eval-sanitize-3-r3-049-kqlvx,phase=Pending node=kind-worker4
49.0745,Event,ADDED,eval-sanitize-3-r3-049-kqlvx.18d3d30034ae90fb,reason=Scheduled count=None msg=Successfully assigned compute/eval-sanitize-3-r3-049-kqlvx to kind-worker4
49.0832,Pod,MODIFIED,eval-sanitize-3-r3-049-kqlvx,phase=Pending node=kind-worker4
49.0847,Pod,MODIFIED,eval-sanitize-3-r3-048-r5xt9,phase=Pending node=None
49.0862,Node,MODIFIED,kind-worker4,taints=0
49.0952,Node,MODIFIED,kind-worker4,taints=0
49.1299,Event,ADDED,eval-sanitize-3-r3-048-r5xt9.18d3d30037fbcb0f,"reason=FailedScheduling count=None msg=0/6 nodes are available: 1 c_wall violated: 1 conflicting context pair(s) with node memory, 1 c_wall violated: 3 conflicting context pair(s) with node memory, 4 node(s) had untolerated taint(s). no new claims to deallocate, preemption: 0/6 nodes are available: 2 No preemption victims found for incoming pod, 4 Preemption is not helpful for scheduling."
49.4302,Job,MODIFIED,eval-sanitize-3-r3-046,
49.4403,Job,MODIFIED,eval-sanitize-3-r3-046,
49.4589,Job,MODIFIED,eval-sanitize-3-r3-036,
49.4677,Pod,MODIFIED,eval-sanitize-3-r3-036-4fnh6,phase=Succeeded node=kind-worker3
49.4685,Job,MODIFIED,eval-sanitize-3-r3-036,
49.4885,Job,MODIFIED,eval-sanitize-3-r3-037,
49.4939,Job,MODIFIED,eval-sanitize-3-r3-035,
49.495,Event,ADDED,eval-sanitize-3-r3-049-kqlvx.18d3d3004dcc7889,"reason=Pulled count=1 msg=Container image ""busybox:musl"" already present on machine"
49.4989,Job,MODIFIED,eval-sanitize-3-r3-037,
49.5038,Job,MODIFIED,eval-sanitize-3-r3-035,
49.5081,Event,ADDED,eval-sanitize-3-r3-035.18d3d3004e872ee6,reason=Completed count=1 msg=Job completed
49.5131,Job,MODIFIED,eval-sanitize-3-r3-035,
49.5176,TaskRequest,MODIFIED,eval-sanitize-3-r3-035,phase=Complete job=None
49.5202,Event,ADDED,eval-sanitize-3-r3-049-kqlvx.18d3d3004f3718a0,reason=Created count=1 msg=Created container: task
49.5279,Job,MODIFIED,eval-sanitize-3-r3-035,
49.5772,Event,ADDED,eval-sanitize-3-r3-049-kqlvx.18d3d30052aa9d06,reason=Started count=1 msg=Started container task
49.6647,Pod,MODIFIED,eval-sanitize-3-r3-037-cw865,phase=Succeeded node=kind-worker5
49.6744,Event,MODIFIED,eval-sanitize-3-r3-048-r5xt9.18d3d30037fbcb0f,"reason=FailedScheduling count=None msg=0/6 nodes are available: 1 c_wall violated: 1 conflicting context pair(s) with node memory, 1 c_wall violated: 3 conflicting context pair(s) with node memory, 4 node(s) had untolerated taint(s). no new claims to deallocate, preemption: 0/6 nodes are available: 2 No preemption victims found for incoming pod, 4 Preemption is not helpful for scheduling."
50.0091,TaskRequest,ADDED,eval-sanitize-3-r3-050,phase=None job=None
50.0124,TaskRequest,MODIFIED,eval-sanitize-3-r3-050,phase=Pending job=None
50.0279,Job,ADDED,eval-sanitize-3-r3-050,
50.0333,Pod,ADDED,eval-sanitize-3-r3-050-txwpj,phase=Pending node=None
50.0346,TaskRequest,MODIFIED,eval-sanitize-3-r3-050,phase=Scheduled job=None
50.0376,Job,MODIFIED,eval-sanitize-3-r3-050,
50.038,Event,ADDED,eval-sanitize-3-r3-050.18d3d3006e15b3ae,reason=SuccessfulCreate count=1 msg=Created pod: eval-sanitize-3-r3-050-txwpj
50.0411,TaskRequest,MODIFIED,eval-sanitize-3-r3-050,phase=Scheduled job=None
50.0448,Pod,MODIFIED,eval-sanitize-3-r3-050-txwpj,phase=Pending node=None
50.0478,Event,ADDED,eval-sanitize-3-r3-050-txwpj.18d3d3006e82102c,"reason=FailedScheduling count=None msg=0/6 nodes are available: 1 c_wall violated: 1 conflicting context pair(s) with node memory, 1 c_wall violated: 3 conflicting context pair(s) with node memory, 4 node(s) had untolerated taint(s). no new claims to deallocate, preemption: 0/6 nodes are available: 2 No preemption victims found for incoming pod, 4 Preemption is not helpful for scheduling."
50.0513,Job,MODIFIED,eval-sanitize-3-r3-049,
50.0545,Event,ADDED,eval-sanitize-3-r3-050-txwpj.18d3d3006f21d7fe,"reason=FailedScheduling count=None msg=0/6 nodes are available: 1 c_wall violated: 1 conflicting context pair(s) with node memory, 1 c_wall violated: 3 conflicting context pair(s) with node memory, 4 node(s) had untolerated taint(s). no new claims to deallocate, preemption: 0/6 nodes are available: 2 No preemption victims found for incoming pod, 4 Preemption is not helpful for scheduling."
50.0597,Job,MODIFIED,eval-sanitize-3-r3-049,
50.1364,Node,MODIFIED,kind-worker,taints=1
50.1426,Pod,MODIFIED,eval-sanitize-3-r3-048-r5xt9,phase=Pending node=None
50.149,Node,MODIFIED,kind-worker,taints=1
50.1523,Pod,MODIFIED,eval-sanitize-3-r3-050-txwpj,phase=Pending node=None
50.1533,Event,MODIFIED,eval-sanitize-3-r3-050-txwpj.18d3d3006f21d7fe,"reason=FailedScheduling count=None msg=0/6 nodes are available: 1 c_wall violated: 1 conflicting context pair(s) with node memory, 1 c_wall violated: 3 conflicting context pair(s) with node memory, 4 node(s) had untolerated taint(s). no new claims to deallocate, preemption: 0/6 nodes are available: 2 No preemption victims found for incoming pod, 4 Preemption is not helpful for scheduling."
50.211,Event,ADDED,eval-sanitize-3-r3-048-r5xt9.18d3d30078747224,"reason=FailedScheduling count=None msg=0/6 nodes are available: 1 c_wall violated: 3 conflicting context pair(s) with node memory, 5 node(s) had untolerated taint(s). no new claims to deallocate, preemption: 0/6 nodes are available: 1 No preemption victims found for incoming pod, 5 Preemption is not helpful for scheduling."
50.2123,Event,ADDED,eval-sanitize-3-r3-050-txwpj.18d3d30078989b2d,"reason=FailedScheduling count=None msg=0/6 nodes are available: 1 c_wall violated: 3 conflicting context pair(s) with node memory, 5 node(s) had untolerated taint(s). no new claims to deallocate, preemption: 0/6 nodes are available: 1 No preemption victims found for incoming pod, 5 Preemption is not helpful for scheduling."
50.4298,Pod,MODIFIED,eval-sanitize-3-r3-049-kqlvx,phase=Running node=kind-worker4
50.4392,Event,MODIFIED,eval-sanitize-3-r3-048-r5xt9.18d3d30078747224,"reason=FailedScheduling count=None msg=0/6 nodes are available: 1 c_wall violated: 3 conflicting context pair(s) with node memory, 5 node(s) had untolerated taint(s). no new claims to deallocate, preemption: 0/6 nodes are available: 1 No preemption victims found for incoming pod, 5 Preemption is not helpful for scheduling."
50.4423,Event,MODIFIED,eval-sanitize-3-r3-050-txwpj.18d3d30078989b2d,"reason=FailedScheduling count=None msg=0/6 nodes are available: 1 c_wall violated: 3 conflicting context pair(s) with node memory, 5 node(s) had untolerated taint(s). no new claims to deallocate, preemption: 0/6 nodes are available: 1 No preemption victims found for incoming pod, 5 Preemption is not helpful for scheduling."
50.4642,Job,MODIFIED,eval-sanitize-3-r3-036,
50.4685,Job,MODIFIED,eval-sanitize-3-r3-036,
50.4744,Event,ADDED,eval-sanitize-3-r3-036.18d3d30088092d55,reason=Completed count=1 msg=Job completed
50.4797,Job,MODIFIED,eval-sanitize-3-r3-036,
50.4852,TaskRequest,MODIFIED,eval-sanitize-3-r3-036,phase=Complete job=None
50.4938,Job,MODIFIED,eval-sanitize-3-r3-037,
50.4957,Job,MODIFIED,eval-sanitize-3-r3-036,
50.502,Pod,MODIFIED,eval-sanitize-3-r3-037-cw865,phase=Succeeded node=kind-worker5
50.5032,Job,MODIFIED,eval-sanitize-3-r3-037,
50.5249,Node,MODIFIED,kind-worker3,taints=1
50.5393,Node,MODIFIED,kind-worker3,taints=0
50.5436,Node,MODIFIED,kind-worker4,taints=1
50.5472,Pod,MODIFIED,eval-sanitize-3-r3-048-r5xt9,phase=Pending node=kind-worker3
50.5497,Node,MODIFIED,kind-worker3,taints=0
50.5533,Event,ADDED,eval-sanitize-3-r3-048-r5xt9.18d3d3008cbc6a3a,reason=Scheduled count=None msg=Successfully assigned compute/eval-sanitize-3-r3-048-r5xt9 to kind-worker3
50.5551,Pod,MODIFIED,eval-sanitize-3-r3-050-txwpj,phase=Pending node=kind-worker3
50.5615,Event,ADDED,eval-sanitize-3-r3-050-txwpj.18d3d3008d2f3981,reason=Scheduled count=None msg=Successfully assigned compute/eval-sanitize-3-r3-050-txwpj to kind-worker3
50.5628,Pod,MODIFIED,eval-sanitize-3-r3-048-r5xt9,phase=Pending node=kind-worker3
50.5652,Node,MODIFIED,kind-worker3,taints=0
50.5692,Pod,MODIFIED,eval-sanitize-3-r3-050-txwpj,phase=Pending node=kind-worker3
50.6271,Node,MODIFIED,kind-worker4,taints=1
50.6293,Node,MODIFIED,kind-worker3,taints=0
50.7327,Node,MODIFIED,kind-worker3,taints=0
50.9742,Event,ADDED,eval-sanitize-3-r3-048-r5xt9.18d3d300a5e6b310,"reason=Pulled count=1 msg=Container image ""busybox:musl"" already present on machine"
50.9782,Event,ADDED,eval-sanitize-3-r3-050-txwpj.18d3d300a632e462,"reason=Pulled count=1 msg=Container image ""busybox:musl"" already present on machine"
51.0058,Event,ADDED,eval-sanitize-3-r3-048-r5xt9.18d3d300a7d2a5cf,reason=Created count=1 msg=Created container: task
51.0124,Event,ADDED,eval-sanitize-3-r3-050-txwpj.18d3d300a803fb3d,reason=Created count=1 msg=Created container: task
51.0131,TaskRequest,ADDED,eval-sanitize-3-r3-051,phase=None job=None
51.0168,TaskRequest,MODIFIED,eval-sanitize-3-r3-051,phase=Pending job=None
51.0337,Job,ADDED,eval-sanitize-3-r3-051,
51.0388,Job,MODIFIED,eval-sanitize-3-r3-050,
51.0404,TaskRequest,MODIFIED,eval-sanitize-3-r3-051,phase=Scheduled job=None
51.0415,Pod,ADDED,eval-sanitize-3-r3-051-zkrvm,phase=Pending node=None
51.0438,Job,MODIFIED,eval-sanitize-3-r3-051,
51.0466,Event,ADDED,eval-sanitize-3-r3-051.18d3d300aa2eb4ea,reason=SuccessfulCreate count=1 msg=Created pod: eval-sanitize-3-r3-051-zkrvm
51.0476,TaskRequest,MODIFIED,eval-sanitize-3-r3-051,phase=Scheduled job=None
51.053,Pod,MODIFIED,eval-sanitize-3-r3-051-zkrvm,phase=Pending node=kind-worker3
51.0555,Job,MODIFIED,eval-sanitize-3-r3-050,
51.0598,Job,MODIFIED,eval-sanitize-3-r3-049,
51.0602,Event,ADDED,eval-sanitize-3-r3-051-zkrvm.18d3d300aad42852,reason=Scheduled count=None msg=Successfully assigned compute/eval-sanitize-3-r3-051-zkrvm to kind-worker3
51.0667,Node,MODIFIED,kind-worker3,taints=0
51.0727,Job,MODIFIED,eval-sanitize-3-r3-049,
51.073,Event,ADDED,eval-sanitize-3-r3-048-r5xt9.18d3d300abc4da4b,reason=Started count=1 msg=Started container task
51.0741,Pod,MODIFIED,eval-sanitize-3-r3-051-zkrvm,phase=Pending node=kind-worker3
51.0776,Event,ADDED,eval-sanitize-3-r3-050-txwpj.18d3d300abc4da41,reason=Started count=1 msg=Started container task
51.1257,Node,MODIFIED,kind-worker5,taints=1
51.1282,Node,MODIFIED,kind-worker3,taints=0
51.1431,Node,MODIFIED,kind-worker5,taints=0
51.1514,Node,MODIFIED,kind-worker5,taints=0
51.2225,Node,MODIFIED,kind-worker5,taints=0
51.4503,Pod,MODIFIED,eval-sanitize-3-r3-050-txwpj,phase=Running node=kind-worker3
51.4601,Pod,MODIFIED,eval-sanitize-3-r3-048-r5xt9,phase=Running node=kind-worker3
51.4757,Event,ADDED,eval-sanitize-3-r3-051-zkrvm.18d3d300c3c7ccaa,"reason=Pulled count=1 msg=Container image ""busybox:musl"" already present on machine"
51.495,Event,ADDED,eval-sanitize-3-r3-051-zkrvm.18d3d300c4f3b479,reason=Created count=1 msg=Created container: task
51.5004,Job,MODIFIED,eval-sanitize-3-r3-037,
51.5058,Job,MODIFIED,eval-sanitize-3-r3-037,
51.5099,Event,ADDED,eval-sanitize-3-r3-037.18d3d300c5de620e,reason=Completed count=1 msg=Job completed
51.5169,Job,MODIFIED,eval-sanitize-3-r3-037,
51.5213,TaskRequest,MODIFIED,eval-sanitize-3-r3-037,phase=Complete job=None
51.5315,Job,MODIFIED,eval-sanitize-3-r3-037,
51.5318,Event,ADDED,eval-sanitize-3-r3-051-zkrvm.18d3d300c71d3c00,reason=Started count=1 msg=Started container task
52.009,TaskRequest,ADDED,eval-sanitize-3-r3-052,phase=None job=None
52.0124,TaskRequest,MODIFIED,eval-sanitize-3-r3-052,phase=Pending job=None
52.0285,Job,ADDED,eval-sanitize-3-r3-052,
52.0324,TaskRequest,MODIFIED,eval-sanitize-3-r3-052,phase=Scheduled job=None
52.0353,Pod,ADDED,eval-sanitize-3-r3-052-qdx5l,phase=Pending node=None
52.037,Job,MODIFIED,eval-sanitize-3-r3-052,
52.04,Event,ADDED,eval-sanitize-3-r3-052.18d3d300e56e9a5a,reason=SuccessfulCreate count=1 msg=Created pod: eval-sanitize-3-r3-052-qdx5l
52.0401,TaskRequest,MODIFIED,eval-sanitize-3-r3-052,phase=Scheduled job=None
52.0432,Job,MODIFIED,eval-sanitize-3-r3-050,
52.0454,Pod,MODIFIED,eval-sanitize-3-r3-052-qdx5l,phase=Pending node=kind-worker5
52.047,Job,MODIFIED,eval-sanitize-3-r3-051,
52.0488,Event,ADDED,eval-sanitize-3-r3-052-qdx5l.18d3d300e60b2c79,reason=Scheduled count=None msg=Successfully assigned compute/eval-sanitize-3-r3-052-qdx5l to kind-worker5
52.0534,Job,MODIFIED,eval-sanitize-3-r3-050,
52.0564,Node,MODIFIED,kind-worker5,taints=0
52.0587,Job,MODIFIED,eval-sanitize-3-r3-051,
52.06,Pod,MODIFIED,eval-sanitize-3-r3-052-qdx5l,phase=Pending node=kind-worker5
52.0672,Node,MODIFIED,kind-worker5,taints=0
52.4552,Pod,MODIFIED,eval-sanitize-3-r3-051-zkrvm,phase=Running node=kind-worker3
52.4652,Job,MODIFIED,eval-sanitize-3-r3-048,
52.4755,Job,MODIFIED,eval-sanitize-3-r3-048,
52.485,Event,ADDED,eval-sanitize-3-r3-052-qdx5l.18d3d300ffdf6193,"reason=Pulled count=1 msg=Container image ""busybox:musl"" already present on machine"
52.5035,Event,ADDED,eval-sanitize-3-r3-052-qdx5l.18d3d3010112c21f,reason=Created count=1 msg=Created container: task
52.568,Event,ADDED,eval-sanitize-3-r3-052-qdx5l.18d3d30104f059c8,reason=Started count=1 msg=Started container task
53.0077,TaskRequest,ADDED,eval-sanitize-3-r3-053,phase=None job=None
53.0113,TaskRequest,MODIFIED,eval-sanitize-3-r3-053,phase=Pending job=None
53.0267,Job,ADDED,eval-sanitize-3-r3-053,
53.0308,TaskRequest,MODIFIED,eval-sanitize-3-r3-053,phase=Scheduled job=None
53.0341,Pod,ADDED,eval-sanitize-3-r3-053-f45f7,phase=Pending node=None
53.0362,Job,MODIFIED,eval-sanitize-3-r3-053,
53.0402,Event,ADDED,eval-sanitize-3-r3-053.18d3d30120f47711,reason=SuccessfulCreate count=1 msg=Created pod: eval-sanitize-3-r3-053-f45f7
53.0413,Job,MODIFIED,eval-sanitize-3-r3-052,
53.0415,TaskRequest,MODIFIED,eval-sanitize-3-r3-053,phase=Scheduled job=None
53.0463,Pod,MODIFIED,eval-sanitize-3-r3-053-f45f7,phase=Pending node=kind-worker5
53.0534,Job,MODIFIED,eval-sanitize-3-r3-052,
53.0548,Event,ADDED,eval-sanitize-3-r3-053-f45f7.18d3d30121b0f339,reason=Scheduled count=None msg=Successfully assigned compute/eval-sanitize-3-r3-053-f45f7 to kind-worker5
53.0559,Job,MODIFIED,eval-sanitize-3-r3-051,
53.059,Node,MODIFIED,kind-worker5,taints=0
53.0614,Pod,MODIFIED,eval-sanitize-3-r3-053-f45f7,phase=Pending node=kind-worker5
53.0668,Job,MODIFIED,eval-sanitize-3-r3-051,
53.0694,Node,MODIFIED,kind-worker5,taints=0
53.4705,Event,ADDED,eval-sanitize-3-r3-053-f45f7.18d3d3013abceaea,"reason=Pulled count=1 msg=Container image ""busybox:musl"" already present on machine"
53.4883,Event,ADDED,eval-sanitize-3-r3-053-f45f7.18d3d3013bcb2eee,reason=Created count=1 msg=Created container: task
53.5004,Pod,MODIFIED,eval-sanitize-3-r3-052-qdx5l,phase=Running node=kind-worker5
53.5218,Event,ADDED,eval-sanitize-3-r3-053-f45f7.18d3d3013dcb952c,reason=Started count=1 msg=Started container task
53.6302,Node,MODIFIED,kind-worker3,taints=1
53.6422,Node,MODIFIED,kind-worker3,taints=1
54.0071,TaskRequest,ADDED,eval-sanitize-3-r3-054,phase=None job=None
54.0107,TaskRequest,MODIFIED,eval-sanitize-3-r3-054,phase=Pending job=None
54.0263,Job,ADDED,eval-sanitize-3-r3-054,
54.0303,TaskRequest,MODIFIED,eval-sanitize-3-r3-054,phase=Scheduled job=None
54.0331,Pod,ADDED,eval-sanitize-3-r3-054-mhh2r,phase=Pending node=None
54.0361,Job,MODIFIED,eval-sanitize-3-r3-054,
54.0404,Event,ADDED,eval-sanitize-3-r3-054.18d3d3015c844142,reason=SuccessfulCreate count=1 msg=Created pod: eval-sanitize-3-r3-054-mhh2r
54.0406,TaskRequest,MODIFIED,eval-sanitize-3-r3-054,phase=Scheduled job=None
54.0414,Job,MODIFIED,eval-sanitize-3-r3-053,
54.0428,Pod,MODIFIED,eval-sanitize-3-r3-054-mhh2r,phase=Pending node=kind-worker5
54.0462,Job,MODIFIED,eval-sanitize-3-r3-052,
54.0466,Event,ADDED,eval-sanitize-3-r3-054-mhh2r.18d3d3015d181026,reason=Scheduled count=None msg=Successfully assigned compute/eval-sanitize-3-r3-054-mhh2r to kind-worker5
54.0511,Job,MODIFIED,eval-sanitize-3-r3-053,
54.0557,Node,MODIFIED,kind-worker5,taints=0
54.0571,Pod,MODIFIED,eval-sanitize-3-r3-054-mhh2r,phase=Pending node=kind-worker5
54.058,Job,MODIFIED,eval-sanitize-3-r3-052,
54.065,Node,MODIFIED,kind-worker5,taints=0
54.2329,Node,MODIFIED,kind-worker5,taints=1
54.2479,Node,MODIFIED,kind-worker5,taints=1
54.3187,Pod,MODIFIED,eval-sanitize-3-r3-040-55zl6,phase=Running node=kind-worker2
54.3258,Pod,MODIFIED,eval-sanitize-3-r3-039-k4ldp,phase=Running node=kind-worker2
54.3334,Pod,MODIFIED,eval-sanitize-3-r3-041-c9zgv,phase=Running node=kind-worker2
54.3394,Pod,MODIFIED,eval-sanitize-3-r3-038-vdkjz,phase=Running node=kind-worker2
54.3454,Pod,MODIFIED,eval-sanitize-3-r3-042-bkwv9,phase=Running node=kind-worker2
54.4845,Event,ADDED,eval-sanitize-3-r3-054-mhh2r.18d3d301771bca6d,"reason=Pulled count=1 msg=Container image ""busybox:musl"" already present on machine"
54.504,Pod,MODIFIED,eval-sanitize-3-r3-053-f45f7,phase=Running node=kind-worker5
54.5044,Event,ADDED,eval-sanitize-3-r3-054-mhh2r.18d3d30178627deb,reason=Created count=1 msg=Created container: task
54.5357,Event,ADDED,eval-sanitize-3-r3-054-mhh2r.18d3d3017a3f6cfd,reason=Started count=1 msg=Started container task
55.0074,TaskRequest,ADDED,eval-sanitize-3-r3-055,phase=None job=None
55.0131,TaskRequest,MODIFIED,eval-sanitize-3-r3-055,phase=Pending job=None
55.0269,Job,ADDED,eval-sanitize-3-r3-055,
55.0321,TaskRequest,MODIFIED,eval-sanitize-3-r3-055,phase=Scheduled job=None
55.0339,Pod,ADDED,eval-sanitize-3-r3-055-26snf,phase=Pending node=None
55.036,Job,MODIFIED,eval-sanitize-3-r3-055,
55.0389,Job,MODIFIED,eval-sanitize-3-r3-054,
55.0404,Event,ADDED,eval-sanitize-3-r3-055.18d3d301982a1c3c,reason=SuccessfulCreate count=1 msg=Created pod: eval-sanitize-3-r3-055-26snf
55.0407,Event,ADDED,eval-sanitize-3-r3-055-26snf.18d3d3019835b27e,"reason=FailedScheduling count=None msg=0/6 nodes are available: 6 node(s) had untolerated taint(s). no new claims to deallocate, preemption: 0/6 nodes are available: 6 Preemption is not helpful for scheduling."
55.042,Pod,MODIFIED,eval-sanitize-3-r3-055-26snf,phase=Pending node=None
55.0428,TaskRequest,MODIFIED,eval-sanitize-3-r3-055,phase=Scheduled job=None
55.0461,Job,MODIFIED,eval-sanitize-3-r3-053,
55.0483,Job,MODIFIED,eval-sanitize-3-r3-054,
55.0541,Job,MODIFIED,eval-sanitize-3-r3-053,
55.3264,Job,MODIFIED,eval-sanitize-3-r3-040,
55.3319,Job,MODIFIED,eval-sanitize-3-r3-039,
55.3379,Job,MODIFIED,eval-sanitize-3-r3-040,
55.3399,Job,MODIFIED,eval-sanitize-3-r3-041,
55.3431,Job,MODIFIED,eval-sanitize-3-r3-039,
55.3457,Job,MODIFIED,eval-sanitize-3-r3-038,
55.3539,Job,MODIFIED,eval-sanitize-3-r3-041,
55.355,Job,MODIFIED,eval-sanitize-3-r3-042,
55.3582,Job,MODIFIED,eval-sanitize-3-r3-038,
55.3649,Job,MODIFIED,eval-sanitize-3-r3-042,
55.4731,Pod,MODIFIED,eval-sanitize-3-r3-041-c9zgv,phase=Succeeded node=kind-worker2
55.5074,Pod,MODIFIED,eval-sanitize-3-r3-054-mhh2r,phase=Running node=kind-worker5
55.5212,Pod,MODIFIED,eval-sanitize-3-r3-039-k4ldp,phase=Succeeded node=kind-worker2
55.527,Pod,MODIFIED,eval-sanitize-3-r3-038-vdkjz,phase=Succeeded node=kind-worker2
55.5337,Pod,MODIFIED,eval-sanitize-3-r3-040-55zl6,phase=Succeeded node=kind-worker2
55.5396,Pod,MODIFIED,eval-sanitize-3-r3-042-bkwv9,phase=Succeeded node=kind-worker2
56.0089,TaskRequest,ADDED,eval-sanitize-3-r3-056,phase=None job=None
56.0122,TaskRequest,MODIFIED,eval-sanitize-3-r3-056,phase=Pending job=None
56.028,Job,ADDED,eval-sanitize-3-r3-056,
56.0353,Pod,ADDED,eval-sanitize-3-r3-056-kbj7h,phase=Pending node=None
56.0375,TaskRequest,MODIFIED,eval-sanitize-3-r3-056,phase=Scheduled job=None
56.0382,Job,MODIFIED,eval-sanitize-3-r3-056,
56.0399,Event,ADDED,eval-sanitize-3-r3-056.18d3d301d3d27e16,reason=SuccessfulCreate count=1 msg=Created pod: eval-sanitize-3-r3-056-kbj7h
56.0414,Pod,MODIFIED,eval-sanitize-3-r3-056-kbj7h,phase=Pending node=None
56.0421,Job,MODIFIED,eval-sanitize-3-r3-055,
56.0425,Event,ADDED,eval-sanitize-3-r3-056-kbj7h.18d3d301d3db54dd,"reason=FailedScheduling count=None msg=0/6 nodes are available: 6 node(s) had untolerated taint(s). no new claims to deallocate, preemption: 0/6 nodes are available: 6 Preemption is not helpful for scheduling."
56.0441,Job,MODIFIED,eval-sanitize-3-r3-054,
56.0465,TaskRequest,MODIFIED,eval-sanitize-3-r3-056,phase=Scheduled job=None
56.0491,Job,MODIFIED,eval-sanitize-3-r3-055,
56.0522,Job,MODIFIED,eval-sanitize-3-r3-054,
56.2222,Node,MODIFIED,kind-worker2,taints=1
56.2359,Node,MODIFIED,kind-worker2,taints=0
56.2399,Pod,MODIFIED,eval-sanitize-3-r3-055-26snf,phase=Pending node=kind-worker2
56.2469,Pod,MODIFIED,eval-sanitize-3-r3-056-kbj7h,phase=Pending node=kind-worker2
56.2494,Event,ADDED,eval-sanitize-3-r3-055-26snf.18d3d301e00db0ce,reason=Scheduled count=None msg=Successfully assigned compute/eval-sanitize-3-r3-055-26snf to kind-worker2
56.2515,Node,MODIFIED,kind-worker2,taints=0
56.2548,Pod,MODIFIED,eval-sanitize-3-r3-055-26snf,phase=Pending node=kind-worker2
56.255,Event,ADDED,eval-sanitize-3-r3-056-kbj7h.18d3d301e073d435,reason=Scheduled count=None msg=Successfully assigned compute/eval-sanitize-3-r3-056-kbj7h to kind-worker2
56.261,Pod,MODIFIED,eval-sanitize-3-r3-056-kbj7h,phase=Pending node=kind-worker2
56.2627,Node,MODIFIED,kind-worker2,taints=0
56.2716,Node,MODIFIED,kind-worker2,taints=0
56.2841,Node,MODIFIED,kind-worker2,taints=0
56.3314,Job,MODIFIED,eval-sanitize-3-r3-040,
56.3371,Job,MODIFIED,eval-sanitize-3-r3-039,
56.341,Pod,MODIFIED,eval-sanitize-3-r3-040-55zl6,phase=Succeeded node=kind-worker2
56.3432,Node,MODIFIED,kind-worker2,taints=0
56.3448,Job,MODIFIED,eval-sanitize-3-r3-040,
56.3468,Pod,MODIFIED,eval-sanitize-3-r3-039-k4ldp,phase=Succeeded node=kind-worker2
56.3478,Job,MODIFIED,eval-sanitize-3-r3-041,
56.3488,Job,MODIFIED,eval-sanitize-3-r3-039,
56.3523,Job,MODIFIED,eval-sanitize-3-r3-038,
56.3552,Node,MODIFIED,kind-worker2,taints=0
56.36,Pod,MODIFIED,eval-sanitize-3-r3-041-c9zgv,phase=Succeeded node=kind-worker2
56.3614,Job,MODIFIED,eval-sanitize-3-r3-041,
56.3652,Pod,MODIFIED,eval-sanitize-3-r3-038-vdkjz,phase=Succeeded node=kind-worker2
56.3661,Job,MODIFIED,eval-sanitize-3-r3-042,
56.3672,Job,MODIFIED,eval-sanitize-3-r3-038,
56.3727,Pod,MODIFIED,eval-sanitize-3-r3-042-bkwv9,phase=Succeeded node=kind-worker2
56.3751,Job,MODIFIED,eval-sanitize-3-r3-042,
56.67,Event,ADDED,eval-sanitize-3-r3-055-26snf.18d3d301f96c78b6,"reason=Pulled count=1 msg=Container image ""busybox:musl"" already present on machine"
56.68,Event,ADDED,eval-sanitize-3-r3-056-kbj7h.18d3d301f9e0ff45,"reason=Pulled count=1 msg=Container image ""busybox:musl"" already present on machine"
56.6954,Event,ADDED,eval-sanitize-3-r3-055-26snf.18d3d301fb06df54,reason=Created count=1 msg=Created container: task
56.7017,Event,ADDED,eval-sanitize-3-r3-056-kbj7h.18d3d301fb5b3469,reason=Created count=1 msg=Created container: task
56.7676,Event,ADDED,eval-sanitize-3-r3-055-26snf.18d3d301ff1fad56,reason=Started count=1 msg=Started container task
56.771,Event,ADDED,eval-sanitize-3-r3-056-kbj7h.18d3d301ff4fc3f0,reason=Started count=1 msg=Started container task
57.0071,TaskRequest,ADDED,eval-sanitize-3-r3-057,phase=None job=None
57.0106,TaskRequest,MODIFIED,eval-sanitize-3-r3-057,phase=Pending job=None
57.0265,Job,ADDED,eval-sanitize-3-r3-057,
57.0319,TaskRequest,MODIFIED,eval-sanitize-3-r3-057,phase=Scheduled job=None
57.034,Pod,ADDED,eval-sanitize-3-r3-057-hqpsj,phase=Pending node=None
57.037,Job,MODIFIED,eval-sanitize-3-r3-057,
57.0389,Event,ADDED,eval-sanitize-3-r3-057.18d3d3020f5dba06,reason=SuccessfulCreate count=1 msg=Created pod: eval-sanitize-3-r3-057-hqpsj
57.0418,Job,MODIFIED,eval-sanitize-3-r3-056,
57.0419,TaskRequest,MODIFIED,eval-sanitize-3-r3-057,phase=Scheduled job=None
57.0434,Event,ADDED,eval-sanitize-3-r3-057-hqpsj.18d3d3020f9fbaf5,"reason=FailedScheduling count=None msg=0/6 nodes are available: 1 c_wall violated: 1 conflicting context pair(s) with node memory, 5 node(s) had untolerated taint(s). no new claims to deallocate, preemption: 0/6 nodes are available: 1 No preemption victims found for incoming pod, 5 Preemption is not helpful for scheduling."
57.0444,Pod,MODIFIED,eval-sanitize-3-r3-057-hqpsj,phase=Pending node=None
57.0517,Job,MODIFIED,eval-sanitize-3-r3-056,
57.0522,Event,ADDED,eval-sanitize-3-r3-057-hqpsj.18d3d3021031080c,"reason=FailedScheduling count=None msg=0/6 nodes are available: 1 c_wall violated: 1 conflicting context pair(s) with node memory, 5 node(s) had untolerated taint(s). no new claims to deallocate, preemption: 0/6 nodes are available: 1 No preemption victims found for incoming pod, 5 Preemption is not helpful for scheduling."
57.3368,Job,MODIFIED,eval-sanitize-3-r3-040,
57.34,Pod,MODIFIED,eval-sanitize-3-r3-055-26snf,phase=Running node=kind-worker2
57.343,Job,MODIFIED,eval-sanitize-3-r3-039,
57.3469,Job,MODIFIED,eval-sanitize-3-r3-040,
57.3496,Job,MODIFIED,eval-sanitize-3-r3-039,
57.3501,Event,MODIFIED,eval-sanitize-3-r3-057-hqpsj.18d3d3021031080c,"reason=FailedScheduling count=None msg=0/6 nodes are available: 1 c_wall violated: 1 conflicting context pair(s) with node memory, 5 node(s) had untolerated taint(s). no new claims to deallocate, preemption: 0/6 nodes are available: 1 No preemption victims found for incoming pod, 5 Preemption is not helpful for scheduling."
57.352,Pod,MODIFIED,eval-sanitize-3-r3-056-kbj7h,phase=Running node=kind-worker2
57.3524,Event,ADDED,eval-sanitize-3-r3-040.18d3d302220da249,reason=Completed count=1 msg=Job completed
57.3548,Job,MODIFIED,eval-sanitize-3-r3-041,
57.3577,Job,MODIFIED,eval-sanitize-3-r3-040,
57.3588,Job,MODIFIED,eval-sanitize-3-r3-038,
57.3591,Event,ADDED,eval-sanitize-3-r3-039.18d3d3022231a662,reason=Completed count=1 msg=Job completed
57.3599,Job,MODIFIED,eval-sanitize-3-r3-039,
57.3608,Job,MODIFIED,eval-sanitize-3-r3-041,
57.3616,Job,MODIFIED,eval-sanitize-3-r3-038,
57.3621,Event,ADDED,eval-sanitize-3-r3-041.18d3d30222c7a634,reason=Completed count=1 msg=Job completed
57.3646,TaskRequest,MODIFIED,eval-sanitize-3-r3-040,phase=Complete job=None
57.3655,Event,ADDED,eval-sanitize-3-r3-038.18d3d30222ea7219,reason=Completed count=1 msg=Job completed
57.3689,Job,MODIFIED,eval-sanitize-3-r3-042,
57.3701,TaskRequest,MODIFIED,eval-sanitize-3-r3-039,phase=Complete job=None
57.3711,Job,MODIFIED,eval-sanitize-3-r3-038,
57.3731,Job,MODIFIED,eval-sanitize-3-r3-041,
57.3748,Job,MODIFIED,eval-sanitize-3-r3-042,
57.3756,Job,MODIFIED,eval-sanitize-3-r3-040,
57.3775,Event,ADDED,eval-sanitize-3-r3-042.18d3d30223b922ce,reason=Completed count=1 msg=Job completed
57.4231,TaskRequest,MODIFIED,eval-sanitize-3-r3-038,phase=Complete job=None
57.4287,Job,MODIFIED,eval-sanitize-3-r3-042,
57.4308,Job,MODIFIED,eval-sanitize-3-r3-039,
57.431,TaskRequest,MODIFIED,eval-sanitize-3-r3-041,phase=Complete job=None
57.4336,Job,MODIFIED,eval-sanitize-3-r3-038,
57.435,TaskRequest,MODIFIED,eval-sanitize-3-r3-042,phase=Complete job=None
57.4407,Job,MODIFIED,eval-sanitize-3-r3-041,
57.4432,Job,MODIFIED,eval-sanitize-3-r3-042,
57.9262,Pod,MODIFIED,eval-sanitize-3-r3-043-kslkf,phase=Running node=kind-worker
57.9336,Pod,MODIFIED,eval-sanitize-3-r3-044-fvf52,phase=Running node=kind-worker
57.9402,Pod,MODIFIED,eval-sanitize-3-r3-045-vpnjr,phase=Running node=kind-worker
58.0078,TaskRequest,ADDED,eval-sanitize-3-r3-058,phase=None job=None
58.0116,TaskRequest,MODIFIED,eval-sanitize-3-r3-058,phase=Pending job=None
58.029,Job,ADDED,eval-sanitize-3-r3-058,
58.0324,TaskRequest,MODIFIED,eval-sanitize-3-r3-058,phase=Scheduled job=None
58.0358,Pod,ADDED,eval-sanitize-3-r3-058-8l6ds,phase=Pending node=None
58.0381,Job,MODIFIED,eval-sanitize-3-r3-058,
58.04,Job,MODIFIED,eval-sanitize-3-r3-057,
58.0416,Event,ADDED,eval-sanitize-3-r3-058.18d3d3024b197d4a,reason=SuccessfulCreate count=1 msg=Created pod: eval-sanitize-3-r3-058-8l6ds
58.0417,TaskRequest,MODIFIED,eval-sanitize-3-r3-058,phase=Scheduled job=None
58.0453,Pod,MODIFIED,eval-sanitize-3-r3-058-8l6ds,phase=Pending node=None
58.0463,Event,ADDED,eval-sanitize-3-r3-058-8l6ds.18d3d3024b5929cf,"reason=FailedScheduling count=None msg=0/6 nodes are available: 1 c_wall violated: 2 conflicting context pair(s) with node memory, 5 node(s) had untolerated taint(s). no new claims to deallocate, preemption: 0/6 nodes are available: 1 No preemption victims found for incoming pod, 5 Preemption is not helpful for scheduling."
58.0471,Job,MODIFIED,eval-sanitize-3-r3-056,
58.0491,Job,MODIFIED,eval-sanitize-3-r3-057,
58.0517,Event,ADDED,eval-sanitize-3-r3-058-8l6ds.18d3d3024bdee556,"reason=FailedScheduling count=None msg=0/6 nodes are available: 1 c_wall violated: 2 conflicting context pair(s) with node memory, 5 node(s) had untolerated taint(s). no new claims to deallocate, preemption: 0/6 nodes are available: 1 No preemption victims found for incoming pod, 5 Preemption is not helpful for scheduling."
58.0557,Job,MODIFIED,eval-sanitize-3-r3-056,
58.3444,Job,MODIFIED,eval-sanitize-3-r3-055,
58.3531,Job,MODIFIED,eval-sanitize-3-r3-055,
58.4465,Pod,MODIFIED,eval-sanitize-3-r3-047-jkxpc,phase=Running node=kind-worker4
58.4545,Pod,MODIFIED,eval-sanitize-3-r3-046-6px6g,phase=Running node=kind-worker4
58.4579,Event,MODIFIED,eval-sanitize-3-r3-058-8l6ds.18d3d3024bdee556,"reason=FailedScheduling count=None msg=0/6 nodes are available: 1 c_wall violated: 2 conflicting context pair(s) with node memory, 5 node(s) had untolerated taint(s). no new claims to deallocate, preemption: 0/6 nodes are available: 1 No preemption victims found for incoming pod, 5 Preemption is not helpful for scheduling."
58.9333,Job,MODIFIED,eval-sanitize-3-r3-043,
58.9387,Job,MODIFIED,eval-sanitize-3-r3-044,
58.943,Job,MODIFIED,eval-sanitize-3-r3-043,
58.9453,Job,MODIFIED,eval-sanitize-3-r3-045,
58.9473,Job,MODIFIED,eval-sanitize-3-r3-044,
58.9549,Job,MODIFIED,eval-sanitize-3-r3-045,
59.0084,TaskRequest,ADDED,eval-sanitize-3-r3-059,phase=None job=None
59.0118,TaskRequest,MODIFIED,eval-sanitize-3-r3-059,phase=Pending job=None
59.0273,Job,ADDED,eval-sanitize-3-r3-059,
59.0338,Pod,ADDED,eval-sanitize-3-r3-059-wtxpj,phase=Pending node=None
59.0339,TaskRequest,MODIFIED,eval-sanitize-3-r3-059,phase=Scheduled job=None
59.0367,Job,MODIFIED,eval-sanitize-3-r3-059,
59.0407,Event,ADDED,eval-sanitize-3-r3-059.18d3d3028699e487,reason=SuccessfulCreate count=1 msg=Created pod: eval-sanitize-3-r3-059-wtxpj
59.0416,Job,MODIFIED,eval-sanitize-3-r3-058,
59.0428,TaskRequest,MODIFIED,eval-sanitize-3-r3-059,phase=Scheduled job=None
59.0442,Pod,MODIFIED,eval-sanitize-3-r3-059-wtxpj,phase=Pending node=kind-worker2
59.0477,Event,ADDED,eval-sanitize-3-r3-059-wtxpj.18d3d302872b2cfe,reason=Scheduled count=None msg=Successfully assigned compute/eval-sanitize-3-r3-059-wtxpj to kind-worker2
59.0516,Job,MODIFIED,eval-sanitize-3-r3-058,
59.0572,Pod,MODIFIED,eval-sanitize-3-r3-059-wtxpj,phase=Pending node=kind-worker2
59.1178,Pod,MODIFIED,eval-sanitize-3-r3-043-kslkf,phase=Succeeded node=kind-worker
59.1693,Pod,MODIFIED,eval-sanitize-3-r3-045-vpnjr,phase=Succeeded node=kind-worker
59.1758,Pod,MODIFIED,eval-sanitize-3-r3-044-fvf52,phase=Succeeded node=kind-worker
59.2564,Node,MODIFIED,kind-worker2,taints=1
59.2676,Pod,MODIFIED,eval-sanitize-3-r3-057-hqpsj,phase=Pending node=None
59.2701,Node,MODIFIED,kind-worker2,taints=1
59.2723,Pod,MODIFIED,eval-sanitize-3-r3-058-8l6ds,phase=Pending node=None
59.4533,Job,MODIFIED,eval-sanitize-3-r3-047,
59.4601,Job,MODIFIED,eval-sanitize-3-r3-046,
59.4632,Job,MODIFIED,eval-sanitize-3-r3-047,
59.4693,Job,MODIFIED,eval-sanitize-3-r3-046,
59.4812,Event,ADDED,eval-sanitize-3-r3-059-wtxpj.18d3d302a0fd3dad,"reason=Pulled count=1 msg=Container image ""busybox:musl"" already present on machine"
59.5001,Event,ADDED,eval-sanitize-3-r3-059-wtxpj.18d3d302a20a3321,reason=Created count=1 msg=Created container: task
59.5684,Event,ADDED,eval-sanitize-3-r3-059-wtxpj.18d3d302a6302492,reason=Started count=1 msg=Started container task
59.6026,Pod,MODIFIED,eval-sanitize-3-r3-046-6px6g,phase=Succeeded node=kind-worker4
59.634,Node,MODIFIED,kind-worker,taints=1
59.6476,Node,MODIFIED,kind-worker,taints=0
59.6496,Pod,MODIFIED,eval-sanitize-3-r3-047-jkxpc,phase=Succeeded node=kind-worker4
59.6533,Pod,MODIFIED,eval-sanitize-3-r3-057-hqpsj,phase=Pending node=kind-worker
59.6576,Pod,MODIFIED,eval-sanitize-3-r3-058-8l6ds,phase=Pending node=None
59.6579,Event,ADDED,eval-sanitize-3-r3-058-8l6ds.18d3d302ab6fe80f,"reason=FailedScheduling count=None msg=0/6 nodes are available: 1 c_wall violated: 1 conflicting context pair(s) with node memory, 5 node(s) had untolerated taint(s). no new claims to deallocate, preemption: 0/6 nodes are available: 1 No preemption victims found for incoming pod, 5 Preemption is not helpful for scheduling."
59.6581,Event,ADDED,eval-sanitize-3-r3-057-hqpsj.18d3d302ab811a04,reason=Scheduled count=None msg=Successfully assigned compute/eval-sanitize-3-r3-057-hqpsj to kind-worker
59.6634,Node,MODIFIED,kind-worker,taints=0
59.6681,Pod,MODIFIED,eval-sanitize-3-r3-057-hqpsj,phase=Pending node=kind-worker
59.669,Event,MODIFIED,eval-sanitize-3-r3-058-8l6ds.18d3d302ab6fe80f,"reason=FailedScheduling count=None msg=0/6 nodes are available: 1 c_wall violated: 1 conflicting context pair(s) with node memory, 5 node(s) had untolerated taint(s). no new claims to deallocate, preemption: 0/6 nodes are available: 1 No preemption victims found for incoming pod, 5 Preemption is not helpful for scheduling."
59.67,Event,ADDED,eval-sanitize-3-r3-058-8l6ds.18d3d302ac51dd2b,"reason=FailedScheduling count=None msg=0/6 nodes are available: 1 c_wall violated: 1 conflicting context pair(s) with node memory, 5 node(s) had untolerated taint(s). no new claims to deallocate, preemption: 0/6 nodes are available: 1 No preemption victims found for incoming pod, 5 Preemption is not helpful for scheduling."
59.6742,Event,MODIFIED,eval-sanitize-3-r3-058-8l6ds.18d3d302ac51dd2b,"reason=FailedScheduling count=None msg=0/6 nodes are available: 1 c_wall violated: 1 conflicting context pair(s) with node memory, 5 node(s) had untolerated taint(s). no new claims to deallocate, preemption: 0/6 nodes are available: 1 No preemption victims found for incoming pod, 5 Preemption is not helpful for scheduling."
59.7226,Node,MODIFIED,kind-worker,taints=0
59.7346,Node,MODIFIED,kind-worker,taints=0
59.9399,Job,MODIFIED,eval-sanitize-3-r3-043,
59.9441,Job,MODIFIED,eval-sanitize-3-r3-044,
59.9485,Pod,MODIFIED,eval-sanitize-3-r3-043-kslkf,phase=Succeeded node=kind-worker
59.9501,Job,MODIFIED,eval-sanitize-3-r3-043,
59.9526,Job,MODIFIED,eval-sanitize-3-r3-045,
59.9542,Pod,MODIFIED,eval-sanitize-3-r3-044-fvf52,phase=Succeeded node=kind-worker
59.9551,Job,MODIFIED,eval-sanitize-3-r3-044,
59.961,Pod,MODIFIED,eval-sanitize-3-r3-045-vpnjr,phase=Succeeded node=kind-worker
59.9619,Job,MODIFIED,eval-sanitize-3-r3-045,
60.0075,TaskRequest,ADDED,eval-sanitize-3-r3-060,phase=None job=None
60.011,TaskRequest,MODIFIED,eval-sanitize-3-r3-060,phase=Pending job=None
60.0279,TaskRequest,ADDED,eval-sanitize-3-r3-000,phase=Complete job=None
60.0302,Job,ADDED,eval-sanitize-3-r3-000,
60.0325,Node,ADDED,kind-control-plane,taints=1
60.0351,Pod,ADDED,eval-sanitize-3-r3-000-jfrb4,phase=Succeeded node=kind-worker2
60.0358,Event,ADDED,eval-sanitize-3-r1-011-tjxzk.18d3d2697133fcf9,"reason=FailedScheduling count=None msg=0/6 nodes are available: 1 c_wall violated: 1 conflicting context pair(s) with node memory, 5 node(s) had untolerated taint(s). no new claims to deallocate, preemption: 0/6 nodes are available: 1 No preemption victims found for incoming pod, 5 Preemption is not helpful for scheduling."
60.036,TaskRequest,ADDED,eval-sanitize-3-r3-001,phase=Complete job=None
60.0361,TaskRequest,ADDED,eval-sanitize-3-r3-002,phase=Complete job=None
60.0363,TaskRequest,ADDED,eval-sanitize-3-r3-003,phase=Complete job=None
60.0364,TaskRequest,ADDED,eval-sanitize-3-r3-004,phase=Complete job=None
60.0365,TaskRequest,ADDED,eval-sanitize-3-r3-005,phase=Complete job=None
60.0366,TaskRequest,ADDED,eval-sanitize-3-r3-006,phase=Complete job=None
60.0367,TaskRequest,ADDED,eval-sanitize-3-r3-007,phase=Complete job=None
60.0368,TaskRequest,ADDED,eval-sanitize-3-r3-008,phase=Complete job=None
60.0383,Job,ADDED,eval-sanitize-3-r3-001,
60.0386,Event,ADDED,eval-sanitize-3-r1-012-rsrs2.18d3d269716929f4,"reason=FailedScheduling count=None msg=0/6 nodes are available: 1 c_wall violated: 1 conflicting context pair(s) with node memory, 5 node(s) had untolerated taint(s). no new claims to deallocate, preemption: 0/6 nodes are available: 1 No preemption victims found for incoming pod, 5 Preemption is not helpful for scheduling."
60.0389,Event,ADDED,eval-sanitize-3-r1-021-qx7fh.18d3d26b6037849c,"reason=FailedScheduling count=None msg=0/6 nodes are available: 1 c_wall violated: 1 conflicting context pair(s) with node memory, 5 node(s) had untolerated taint(s). no new claims to deallocate, preemption: 0/6 nodes are available: 1 No preemption victims found for incoming pod, 5 Preemption is not helpful for scheduling."
60.0391,Event,ADDED,eval-sanitize-3-r1-023-d979z.18d3d26c95b4199d,"reason=FailedScheduling count=None msg=0/6 nodes are available: 1 c_wall violated: 1 conflicting context pair(s) with node memory, 5 node(s) had untolerated taint(s). no new claims to deallocate, preemption: 0/6 nodes are available: 1 No preemption victims found for incoming pod, 5 Preemption is not helpful for scheduling."
60.0393,TaskRequest,ADDED,eval-sanitize-3-r3-009,phase=Complete job=None
60.0394,TaskRequest,ADDED,eval-sanitize-3-r3-010,phase=Complete job=None
60.0408,Job,ADDED,eval-sanitize-3-r3-002,
60.0428,Node,ADDED,kind-worker,taints=0
60.0431,Event,ADDED,eval-sanitize-3-r1-023-d979z.18d3d26d07491213,"reason=FailedScheduling count=None msg=0/6 nodes are available: 1 c_wall violated: 1 conflicting context pair(s) with node memory, 1 c_wall violated: 2 conflicting context pair(s) with node memory, 4 node(s) had untolerated taint(s). no new claims to deallocate, preemption: 0/6 nodes are available: 2 No preemption victims found for incoming pod, 4 Preemption is not helpful for scheduling."
60.0434,Event,ADDED,eval-sanitize-3-r1-023-d979z.18d3d26d0cec5cdf,"reason=FailedScheduling count=None msg=0/6 nodes are available: 1 c_wall violated: 1 conflicting context pair(s) with node memory, 1 c_wall violated: 2 conflicting context pair(s) with node memory, 4 node(s) had untolerated taint(s). no new claims to deallocate, preemption: 0/6 nodes are available: 2 No preemption victims found for incoming pod, 4 Preemption is not helpful for scheduling."
60.0448,Pod,ADDED,eval-sanitize-3-r3-001-x9hkn,phase=Succeeded node=kind-worker
60.045,TaskRequest,ADDED,eval-sanitize-3-r3-011,phase=Complete job=None
60.0451,TaskRequest,ADDED,eval-sanitize-3-r3-012,phase=Complete job=None
60.0451,TaskRequest,ADDED,eval-sanitize-3-r3-013,phase=Complete job=None
60.0452,TaskRequest,ADDED,eval-sanitize-3-r3-014,phase=Complete job=None
60.0452,TaskRequest,ADDED,eval-sanitize-3-r3-015,phase=Complete job=None
60.0452,TaskRequest,ADDED,eval-sanitize-3-r3-016,phase=Complete job=None
60.0456,Event,ADDED,eval-sanitize-3-r1-023-d979z.18d3d26d42bcf201,"reason=FailedScheduling count=None msg=0/6 nodes are available: 1 c_wall violated: 1 conflicting context pair(s) with node memory, 5 node(s) had untolerated taint(s). no new claims to deallocate, preemption: 0/6 nodes are available: 1 No preemption victims found for incoming pod, 5 Preemption is not helpful for scheduling."
60.0458,Event,ADDED,eval-sanitize-3-r1-024-xqg87.18d3d26c95f27eb8,"reason=FailedScheduling count=None msg=0/6 nodes are available: 1 c_wall violated: 1 conflicting context pair(s) with node memory, 5 node(s) had untolerated taint(s). no new claims to deallocate, preemption: 0/6 nodes are available: 1 No preemption victims found for incoming pod, 5 Preemption is not helpful for scheduling."
60.046,Event,ADDED,eval-sanitize-3-r1-026-g4zsx.18d3d26c9623e1d2,"reason=FailedScheduling count=None msg=0/6 nodes are available: 1 c_wall violated: 1 conflicting context pair(s) with node memory, 5 node(s) had untolerated taint(s). no new claims to deallocate, preemption: 0/6 nodes are available: 1 No preemption victims found for incoming pod, 5 Preemption is not helpful for scheduling."
60.0474,Pod,ADDED,eval-sanitize-3-r3-002-7fs7w,phase=Succeeded node=kind-worker4
60.0491,Job,ADDED,eval-sanitize-3-r3-003,
60.0504,Node,ADDED,kind-worker2,taints=1
60.0505,TaskRequest,ADDED,eval-sanitize-3-r3-017,phase=Complete job=None
60.0505,TaskRequest,ADDED,eval-sanitize-3-r3-018,phase=Complete job=None
60.0508,Event,ADDED,eval-sanitize-3-r1-030-6rtz8.18d3d26d78779ecd,"reason=FailedScheduling count=None msg=0/6 nodes are available: 1 c_wall violated: 1 conflicting context pair(s) with node memory, 5 node(s) had untolerated taint(s). no new claims to deallocate, preemption: 0/6 nodes are available: 1 No preemption victims found for incoming pod, 5 Preemption is not helpful for scheduling."
60.051,Event,ADDED,eval-sanitize-3-r1-032-d2qr4.18d3d26df008fffb,"reason=FailedScheduling count=None msg=0/6 nodes are available: 1 c_wall violated: 1 conflicting context pair(s) with node memory, 5 node(s) had untolerated taint(s). no new claims to deallocate, preemption: 0/6 nodes are available: 1 No preemption victims found for incoming pod, 5 Preemption is not helpful for scheduling."
60.0513,Event,ADDED,eval-sanitize-3-r1-033-grsj2.18d3d26e2ca1dff9,"reason=FailedScheduling count=None msg=0/6 nodes are available: 2 c_wall violated: 1 conflicting context pair(s) with node memory, 4 node(s) had untolerated taint(s). no new claims to deallocate, preemption: 0/6 nodes are available: 2 No preemption victims found for incoming pod, 4 Preemption is not helpful for scheduling."
60.0524,Job,ADDED,eval-sanitize-3-r3-004,
60.0539,Node,ADDED,kind-worker3,taints=1
60.0551,Pod,ADDED,eval-sanitize-3-r3-003-vp5rl,phase=Succeeded node=kind-worker5
60.0556,Event,ADDED,eval-sanitize-3-r1-036-tg5qj.18d3d26ede164bb6,"reason=FailedScheduling count=None msg=0/6 nodes are available: 1 c_wall violated: 1 conflicting context pair(s) with node memory, 5 node(s) had untolerated taint(s). no new claims to deallocate, preemption: 0/6 nodes are available: 1 No preemption victims found for incoming pod, 5 Preemption is not helpful for scheduling."
60.0559,Event,ADDED,eval-sanitize-3-r1-037-tjlj8.18d3d27030aad843,"reason=FailedScheduling count=None msg=0/6 nodes are available: 1 c_wall violated: 1 conflicting context pair(s) with node memory, 5 node(s) had untolerated taint(s). no new claims to deallocate, preemption: 0/6 nodes are available: 1 No preemption victims found for incoming pod, 5 Preemption is not helpful for scheduling."
60.0562,Event,ADDED,eval-sanitize-3-r1-037-tjlj8.18d3d270b5c91c26,"reason=FailedScheduling count=None msg=0/6 nodes are available: 2 c_wall violated: 1 conflicting context pair(s) with node memory, 4 node(s) had untolerated taint(s). no new claims to deallocate, preemption: 0/6 nodes are available: 2 No preemption victims found for incoming pod, 4 Preemption is not helpful for scheduling."
60.057,Job,ADDED,eval-sanitize-3-r3-005,
60.0571,TaskRequest,ADDED,eval-sanitize-3-r3-019,phase=Complete job=None
60.0572,TaskRequest,ADDED,eval-sanitize-3-r3-020,phase=Complete job=None
60.0572,TaskRequest,ADDED,eval-sanitize-3-r3-021,phase=Complete job=None
60.0572,TaskRequest,ADDED,eval-sanitize-3-r3-022,phase=Complete job=None
60.0573,TaskRequest,ADDED,eval-sanitize-3-r3-023,phase=Complete job=None
60.0583,TaskRequest,ADDED,eval-sanitize-3-r3-024,phase=Complete job=None
60.0584,TaskRequest,ADDED,eval-sanitize-3-r3-025,phase=Complete job=None
60.0584,TaskRequest,ADDED,eval-sanitize-3-r3-026,phase=Complete job=None
60.0587,Event,ADDED,eval-sanitize-3-r1-037-tjlj8.18d3d270dc753828,"reason=FailedScheduling count=None msg=0/6 nodes are available: 1 c_wall violated: 1 conflicting context pair(s) with node memory, 5 node(s) had untolerated taint(s). no new claims to deallocate, preemption: 0/6 nodes are available: 1 No preemption victims found for incoming pod, 5 Preemption is not helpful for scheduling."
60.059,Event,ADDED,eval-sanitize-3-r1-037-tjlj8.18d3d2713db36ed6,"reason=FailedScheduling count=None msg=0/6 nodes are available: 2 c_wall violated: 1 conflicting context pair(s) with node memory, 4 node(s) had untolerated taint(s). no new claims to deallocate, preemption: 0/6 nodes are available: 2 No preemption victims found for incoming pod, 4 Preemption is not helpful for scheduling."
60.0592,Event,ADDED,eval-sanitize-3-r1-037-tjlj8.18d3d27169b3dae4,"reason=FailedScheduling count=None msg=0/6 nodes are available: 1 c_wall violated: 1 conflicting context pair(s) with node memory, 5 node(s) had untolerated taint(s). no new claims to deallocate, preemption: 0/6 nodes are available: 1 No preemption victims found for incoming pod, 5 Preemption is not helpful for scheduling."
60.0599,Job,ADDED,eval-sanitize-3-r3-006,
60.0612,Node,ADDED,kind-worker4,taints=1
60.0624,Pod,ADDED,eval-sanitize-3-r3-004-rz87f,phase=Succeeded node=kind-worker3
60.0629,TaskRequest,ADDED,eval-sanitize-3-r3-027,phase=Complete job=None
60.0629,TaskRequest,ADDED,eval-sanitize-3-r3-028,phase=Complete job=None
60.063,TaskRequest,ADDED,eval-sanitize-3-r3-029,phase=Complete job=None
60.0634,Event,ADDED,eval-sanitize-3-r1-041-t24pt.18d3d27030e5eb7e,"reason=FailedScheduling count=None msg=0/6 nodes are available: 1 c_wall violated: 2 conflicting context pair(s) with node memory, 5 node(s) had untolerated taint(s). no new claims to deallocate, preemption: 0/6 nodes are available: 1 No preemption victims found for incoming pod, 5 Preemption is not helpful for scheduling."
60.0637,Event,ADDED,eval-sanitize-3-r1-043-dx7ft.18d3d2707f710d9f,"reason=FailedScheduling count=None msg=0/6 nodes are available: 1 c_wall violated: 2 conflicting context pair(s) with node memory, 5 node(s) had untolerated taint(s). no new claims to deallocate, preemption: 0/6 nodes are available: 1 No preemption victims found for incoming pod, 5 Preemption is not helpful for scheduling."
60.0644,TaskRequest,ADDED,eval-sanitize-3-r3-030,phase=Complete job=None
60.0645,TaskRequest,ADDED,eval-sanitize-3-r3-031,phase=Complete job=None
60.0649,Event,ADDED,eval-sanitize-3-r1-044-5wvrz.18d3d270c09190f2,"reason=FailedScheduling count=None msg=0/6 nodes are available: 1 c_wall violated: 1 conflicting context pair(s) with node memory, 1 c_wall violated: 2 conflicting context pair(s) with node memory, 4 node(s) had untolerated taint(s). no new claims to deallocate, preemption: 0/6 nodes are available: 2 No preemption victims found for incoming pod, 4 Preemption is not helpful for scheduling."
60.0651,Event,ADDED,eval-sanitize-3-r1-044-5wvrz.18d3d270dc48d914,"reason=FailedScheduling count=None msg=0/6 nodes are available: 1 c_wall violated: 1 conflicting context pair(s) with node memory, 5 node(s) had untolerated taint(s). no new claims to deallocate, preemption: 0/6 nodes are available: 1 No preemption victims found for incoming pod, 5 Preemption is not helpful for scheduling."
60.0654,Event,ADDED,eval-sanitize-3-r1-045-9vs4b.18d3d270f6750e8e,"reason=FailedScheduling count=None msg=0/6 nodes are available: 1 c_wall violated: 1 conflicting context pair(s) with node memory, 5 node(s) had untolerated taint(s). no new claims to deallocate, preemption: 0/6 nodes are available: 1 No preemption victims found for incoming pod, 5 Preemption is not helpful for scheduling."
60.0663,Job,ADDED,eval-sanitize-3-r3-007,
60.0685,Node,ADDED,kind-worker5,taints=1
60.0701,Pod,ADDED,eval-sanitize-3-r3-005-zlzdh,phase=Succeeded node=kind-worker5
60.0708,TaskRequest,ADDED,eval-sanitize-3-r3-032,phase=Complete job=None
60.0708,TaskRequest,ADDED,eval-sanitize-3-r3-033,phase=Complete job=None
60.0709,TaskRequest,ADDED,eval-sanitize-3-r3-034,phase=Complete job=None
60.0713,Event,ADDED,eval-sanitize-3-r1-046-46pb6.18d3d271321be2bb,"reason=FailedScheduling count=None msg=0/6 nodes are available: 1 c_wall violated: 1 conflicting context pair(s) with node memory, 5 node(s) had untolerated taint(s). no new claims to deallocate, preemption: 0/6 nodes are available: 1 No preemption victims found for incoming pod, 5 Preemption is not helpful for scheduling."
60.0716,Event,ADDED,eval-sanitize-3-r1-046-46pb6.18d3d2713dfcda16,"reason=FailedScheduling count=None msg=0/6 nodes are available: 2 c_wall violated: 1 conflicting context pair(s) with node memory, 4 node(s) had untolerated taint(s). no new claims to deallocate, preemption: 0/6 nodes are available: 2 No preemption victims found for incoming pod, 4 Preemption is not helpful for scheduling."
60.0719,Event,ADDED,eval-sanitize-3-r1-046-46pb6.18d3d27169df09e4,"reason=FailedScheduling count=None msg=0/6 nodes are available: 1 c_wall violated: 1 conflicting context pair(s) with node memory, 5 node(s) had untolerated taint(s). no new claims to deallocate, preemption: 0/6 nodes are available: 1 No preemption victims found for incoming pod, 5 Preemption is not helpful for scheduling."
60.073,Job,ADDED,eval-sanitize-3-r3-008,
60.0745,Pod,ADDED,eval-sanitize-3-r3-006-bjfc4,phase=Succeeded node=kind-worker2
60.0749,TaskRequest,ADDED,eval-sanitize-3-r3-035,phase=Complete job=None
60.075,TaskRequest,ADDED,eval-sanitize-3-r3-036,phase=Complete job=None
60.075,TaskRequest,ADDED,eval-sanitize-3-r3-037,phase=Complete job=None
60.0754,Event,ADDED,eval-sanitize-3-r1-047-7722w.18d3d2716dd70593,"reason=FailedScheduling count=None msg=0/6 nodes are available: 1 c_wall violated: 1 conflicting context pair(s) with node memory, 5 node(s) had untolerated taint(s). no new claims to deallocate, preemption: 0/6 nodes are available: 1 No preemption victims found for incoming pod, 5 Preemption is not helpful for scheduling."
60.0756,Event,ADDED,eval-sanitize-3-r1-047-7722w.18d3d271aac14dbb,"reason=FailedScheduling count=None msg=0/6 nodes are available: 1 c_wall violated: 2 conflicting context pair(s) with node memory, 5 node(s) had untolerated taint(s). no new claims to deallocate, preemption: 0/6 nodes are available: 1 No preemption victims found for incoming pod, 5 Preemption is not helpful for scheduling."
60.0759,Event,ADDED,eval-sanitize-3-r1-055-7lwd6.18d3d273cd461dfc,"reason=FailedScheduling count=None msg=0/6 nodes are available: 1 c_wall violated: 3 conflicting context pair(s) with node memory, 5 node(s) had untolerated taint(s). no new claims to deallocate, preemption: 0/6 nodes are available: 1 No preemption victims found for incoming pod, 5 Preemption is not helpful for scheduling."
60.0762,Event,ADDED,eval-sanitize-3-r1-056-txkm8.18d3d273cd71673c,"reason=FailedScheduling count=None msg=0/6 nodes are available: 1 c_wall violated: 3 conflicting context pair(s) with node memory, 5 node(s) had untolerated taint(s). no new claims to deallocate, preemption: 0/6 nodes are available: 1 No preemption victims found for incoming pod, 5 Preemption is not helpful for scheduling."
60.0767,Event,ADDED,eval-sanitize-3-r1-057-55lw7.18d3d273cd9debff,"reason=FailedScheduling count=None msg=0/6 nodes are available: 1 c_wall violated: 1 conflicting context pair(s) with node memory, 5 node(s) had untolerated taint(s). no new claims to deallocate, preemption: 0/6 nodes are available: 1 No preemption victims found for incoming pod, 5 Preemption is not helpful for scheduling."
60.0769,Event,ADDED,eval-sanitize-3-r1-059-kd5p6.18d3d27438f502a6,"reason=FailedScheduling count=None msg=0/6 nodes are available: 1 c_wall violated: 3 conflicting context pair(s) with node memory, 5 node(s) had untolerated taint(s). no new claims to deallocate, preemption: 0/6 nodes are available: 1 No preemption victims found for incoming pod, 5 Preemption is not helpful for scheduling."
60.0772,Event,ADDED,eval-sanitize-3-r1-064-jhpsd.18d3d27562bbb6f5,"reason=FailedScheduling count=None msg=0/6 nodes are available: 1 c_wall violated: 1 conflicting context pair(s) with node memory, 5 node(s) had untolerated taint(s). no new claims to deallocate, preemption: 0/6 nodes are available: 1 No preemption victims found for incoming pod, 5 Preemption is not helpful for scheduling."
60.0774,Event,ADDED,eval-sanitize-3-r1-066-qmgrb.18d3d275da92567c,"reason=FailedScheduling count=None msg=0/6 nodes are available: 1 c_wall violated: 1 conflicting context pair(s) with node memory, 5 node(s) had untolerated taint(s). no new claims to deallocate, preemption: 0/6 nodes are available: 1 No preemption victims found for incoming pod, 5 Preemption is not helpful for scheduling."
60.0776,TaskRequest,ADDED,eval-sanitize-3-r3-038,phase=Complete job=None
60.0777,TaskRequest,ADDED,eval-sanitize-3-r3-039,phase=Complete job=None
60.0787,Job,ADDED,eval-sanitize-3-r3-009,
60.0795,Job,ADDED,eval-sanitize-3-r3-010,
60.0798,Event,ADDED,eval-sanitize-3-r1-067-lqnsb.18d3d276163322d0,"reason=FailedScheduling count=None msg=0/6 nodes are available: 1 c_wall violated: 2 conflicting context pair(s) with node memory, 5 node(s) had untolerated taint(s). no new claims to deallocate, preemption: 0/6 nodes are available: 1 No preemption victims found for incoming pod, 5 Preemption is not helpful for scheduling."
60.08,Event,ADDED,eval-sanitize-3-r1-068-5n2cw.18d3d277811b407d,"reason=FailedScheduling count=None msg=0/6 nodes are available: 1 c_wall violated: 3 conflicting context pair(s) with node memory, 5 node(s) had untolerated taint(s). no new claims to deallocate, preemption: 0/6 nodes are available: 1 No preemption victims found for incoming pod, 5 Preemption is not helpful for scheduling."
60.0803,Event,ADDED,eval-sanitize-3-r1-069-z9wxc.18d3d2777be673e6,"reason=FailedScheduling count=None msg=0/6 nodes are available: 1 c_wall violated: 2 conflicting context pair(s) with node memory, 5 node(s) had untolerated taint(s). no new claims to deallocate, preemption: 0/6 nodes are available: 1 No preemption victims found for incoming pod, 5 Preemption is not helpful for scheduling."
60.0804,TaskRequest,ADDED,eval-sanitize-3-r3-040,phase=Complete job=None
60.0804,TaskRequest,ADDED,eval-sanitize-3-r3-041,phase=Complete job=None
60.0805,TaskRequest,ADDED,eval-sanitize-3-r3-042,phase=Complete job=None
60.082,Pod,ADDED,eval-sanitize-3-r3-007-mt7xl,phase=Succeeded node=kind-worker
60.0825,Event,ADDED,eval-sanitize-3-r1-069-z9wxc.18d3d278232b9940,"reason=FailedScheduling count=None msg=0/6 nodes are available: 1 c_wall violated: 1 conflicting context pair(s) with node memory, 1 c_wall violated: 2 conflicting context pair(s) with node memory, 4 node(s) had untolerated taint(s). no new claims to deallocate, preemption: 0/6 nodes are available: 2 No preemption victims found for incoming pod, 4 Preemption is not helpful for scheduling."
60.0827,Event,ADDED,eval-sanitize-3-r1-069-z9wxc.18d3d27834e78c70,"reason=FailedScheduling count=None msg=0/6 nodes are available: 1 c_wall violated: 1 conflicting context pair(s) with node memory, 5 node(s) had untolerated taint(s). no new claims to deallocate, preemption: 0/6 nodes are available: 1 No preemption victims found for incoming pod, 5 Preemption is not helpful for scheduling."
60.0829,Event,ADDED,eval-sanitize-3-r1-071-x6gr5.18d3d2777c17f51f,"reason=FailedScheduling count=None msg=0/6 nodes are available: 1 c_wall violated: 2 conflicting context pair(s) with node memory, 5 node(s) had untolerated taint(s). no new claims to deallocate, preemption: 0/6 nodes are available: 1 No preemption victims found for incoming pod, 5 Preemption is not helpful for scheduling."
60.083,TaskRequest,ADDED,eval-sanitize-3-r3-043,phase=Scheduled job=None
60.0831,TaskRequest,ADDED,eval-sanitize-3-r3-044,phase=Scheduled job=None
60.0844,Pod,ADDED,eval-sanitize-3-r3-008-jtwkx,phase=Succeeded node=kind-worker
60.086,Job,ADDED,eval-sanitize-3-r3-011,
60.0864,Event,ADDED,eval-sanitize-3-r1-071-x6gr5.18d3d27827ea40c0,"reason=FailedScheduling count=None msg=0/6 nodes are available: 1 c_wall violated: 1 conflicting context pair(s) with node memory, 1 c_wall violated: 2 conflicting context pair(s) with node memory, 4 node(s) had untolerated taint(s). no new claims to deallocate, preemption: 0/6 nodes are available: 2 No preemption victims found for incoming pod, 4 Preemption is not helpful for scheduling."
60.0867,Event,ADDED,eval-sanitize-3-r1-071-x6gr5.18d3d2783467a791,"reason=FailedScheduling count=None msg=0/6 nodes are available: 1 c_wall violated: 1 conflicting context pair(s) with node memory, 5 node(s) had untolerated taint(s). no new claims to deallocate, preemption: 0/6 nodes are available: 1 No preemption victims found for incoming pod, 5 Preemption is not helpful for scheduling."
60.087,Event,ADDED,eval-sanitize-3-r1-072-gjkvb.18d3d2777c4ea613,"reason=FailedScheduling count=None msg=0/6 nodes are available: 1 c_wall violated: 2 conflicting context pair(s) with node memory, 5 node(s) had untolerated taint(s). no new claims to deallocate, preemption: 0/6 nodes are available: 1 No preemption victims found for incoming pod, 5 Preemption is not helpful for scheduling."
60.0871,TaskRequest,ADDED,eval-sanitize-3-r3-045,phase=Scheduled job=None
60.0872,TaskRequest,ADDED,eval-sanitize-3-r3-046,phase=Scheduled job=None
60.0872,TaskRequest,ADDED,eval-sanitize-3-r3-047,phase=Scheduled job=None
60.0885,Job,ADDED,eval-sanitize-3-r3-012,
60.0897,Pod,ADDED,eval-sanitize-3-r3-009-97txr,phase=Succeeded node=kind-worker
60.0907,Event,ADDED,eval-sanitize-3-r1-072-gjkvb.18d3d2782846d3f6,"reason=FailedScheduling count=None msg=0/6 nodes are available: 1 c_wall violated: 1 conflicting context pair(s) with node memory, 1 c_wall violated: 2 conflicting context pair(s) with node memory, 4 node(s) had untolerated taint(s). no new claims to deallocate, preemption: 0/6 nodes are available: 2 No preemption victims found for incoming pod, 4 Preemption is not helpful for scheduling."
60.091,Event,ADDED,eval-sanitize-3-r1-072-gjkvb.18d3d27834940234,"reason=FailedScheduling count=None msg=0/6 nodes are available: 1 c_wall violated: 2 conflicting context pair(s) with node memory, 5 node(s) had untolerated taint(s). no new claims to deallocate, preemption: 0/6 nodes are available: 1 No preemption victims found for incoming pod, 5 Preemption is not helpful for scheduling."
60.0912,Event,ADDED,eval-sanitize-3-r1-072-gjkvb.18d3d2785249a100,"reason=FailedScheduling count=None msg=0/6 nodes are available: 2 c_wall violated: 2 conflicting context pair(s) with node memory, 4 node(s) had untolerated taint(s). no new claims to deallocate, preemption: 0/6 nodes are available: 2 No preemption victims found for incoming pod, 4 Preemption is not helpful for scheduling."
60.0924,Pod,ADDED,eval-sanitize-3-r3-010-tnkj2,phase=Succeeded node=kind-worker
60.0925,TaskRequest,ADDED,eval-sanitize-3-r3-048,phase=Scheduled job=None
60.0925,TaskRequest,ADDED,eval-sanitize-3-r3-049,phase=Scheduled job=None
60.0925,TaskRequest,ADDED,eval-sanitize-3-r3-050,phase=Scheduled job=None
60.0933,Job,ADDED,eval-sanitize-3-r3-013,
60.0937,Event,ADDED,eval-sanitize-3-r1-072-gjkvb.18d3d27857f5dbaf,"reason=FailedScheduling count=None msg=0/6 nodes are available: 2 c_wall violated: 2 conflicting context pair(s) with node memory, 4 node(s) had untolerated taint(s). no new claims to deallocate, preemption: 0/6 nodes are available: 2 No preemption victims found for incoming pod, 4 Preemption is not helpful for scheduling."
60.0939,Event,ADDED,eval-sanitize-3-r1-073-dlw2g.18d3d27786f7b3d6,"reason=FailedScheduling count=None msg=0/6 nodes are available: 1 c_wall violated: 2 conflicting context pair(s) with node memory, 5 node(s) had untolerated taint(s). no new claims to deallocate, preemption: 0/6 nodes are available: 1 No preemption victims found for incoming pod, 5 Preemption is not helpful for scheduling."
60.0942,Event,ADDED,eval-sanitize-3-r1-073-dlw2g.18d3d27822d6e202,"reason=FailedScheduling count=None msg=0/6 nodes are available: 1 c_wall violated: 1 conflicting context pair(s) with node memory, 1 c_wall violated: 2 conflicting context pair(s) with node memory, 4 node(s) had untolerated taint(s). no new claims to deallocate, preemption: 0/6 nodes are available: 2 No preemption victims found for incoming pod, 4 Preemption is not helpful for scheduling."
60.0945,Event,ADDED,eval-sanitize-3-r1-073-dlw2g.18d3d27834bec813,"reason=FailedScheduling count=None msg=0/6 nodes are available: 1 c_wall violated: 1 conflicting context pair(s) with node memory, 5 node(s) had untolerated taint(s). no new claims to deallocate, preemption: 0/6 nodes are available: 1 No preemption victims found for incoming pod, 5 Preemption is not helpful for scheduling."
60.0947,Event,ADDED,eval-sanitize-3-r1-075-fffjt.18d3d277f31e61ab,"reason=FailedScheduling count=None msg=0/6 nodes are available: 1 c_wall violated: 1 conflicting context pair(s) with node memory, 5 node(s) had untolerated taint(s). no new claims to deallocate, preemption: 0/6 nodes are available: 1 No preemption victims found for incoming pod, 5 Preemption is not helpful for scheduling."
60.0948,TaskRequest,ADDED,eval-sanitize-3-r3-051,phase=Scheduled job=None
60.0949,TaskRequest,ADDED,eval-sanitize-3-r3-052,phase=Scheduled job=None
60.0951,TaskRequest,ADDED,eval-sanitize-3-r3-053,phase=Scheduled job=None
60.096,Job,ADDED,eval-sanitize-3-r3-014,
60.097,Job,ADDED,eval-sanitize-3-r3-015,
60.0973,Event,ADDED,eval-sanitize-3-r1-080-lkw4s.18d3d2791cb4d75b,"reason=FailedScheduling count=None msg=0/6 nodes are available: 1 c_wall violated: 1 conflicting context pair(s) with node memory, 5 node(s) had untolerated taint(s). no new claims to deallocate, preemption: 0/6 nodes are available: 1 No preemption victims found for incoming pod, 5 Preemption is not helpful for scheduling."
60.0975,Event,ADDED,eval-sanitize-3-r1-081-btlgw.18d3d279589689de,"reason=FailedScheduling count=None msg=0/6 nodes are available: 1 c_wall violated: 1 conflicting context pair(s) with node memory, 5 node(s) had untolerated taint(s). no new claims to deallocate, preemption: 0/6 nodes are available: 1 No preemption victims found for incoming pod, 5 Preemption is not helpful for scheduling."
60.0979,Event,ADDED,eval-sanitize-3-r1-082-w92n4.18d3d279956615b3,"reason=FailedScheduling count=None msg=0/6 nodes are available: 1 c_wall violated: 1 conflicting context pair(s) with node memory, 5 node(s) had untolerated taint(s). no new claims to deallocate, preemption: 0/6 nodes are available: 1 No preemption victims found for incoming pod, 5 Preemption is not helpful for scheduling."
60.0991,Pod,ADDED,eval-sanitize-3-r3-011-prswl,phase=Succeeded node=kind-worker
60.0992,TaskRequest,ADDED,eval-sanitize-3-r3-054,phase=Scheduled job=None
60.0993,TaskRequest,ADDED,eval-sanitize-3-r3-055,phase=Scheduled job=None
60.1001,Job,ADDED,eval-sanitize-3-r3-016,
60.1003,TaskRequest,ADDED,eval-sanitize-3-r3-056,phase=Scheduled job=None
60.1004,TaskRequest,ADDED,eval-sanitize-3-r3-057,phase=Scheduled job=None
60.1004,TaskRequest,ADDED,eval-sanitize-3-r3-058,phase=Scheduled job=None
60.1007,Event,ADDED,eval-sanitize-3-r1-085-sdskd.18d3d27b54665f01,"reason=FailedScheduling count=None msg=0/6 nodes are available: 1 c_wall violated: 3 conflicting context pair(s) with node memory, 5 node(s) had untolerated taint(s). no new claims to deallocate, preemption: 0/6 nodes are available: 1 No preemption victims found for incoming pod, 5 Preemption is not helpful for scheduling."
60.1009,Event,ADDED,eval-sanitize-3-r1-086-rv9m8.18d3d27b5653f527,"reason=FailedScheduling count=None msg=0/6 nodes are available: 1 c_wall violated: 2 conflicting context pair(s) with node memory, 5 node(s) had untolerated taint(s). no new claims to deallocate, preemption: 0/6 nodes are available: 1 No preemption victims found for incoming pod, 5 Preemption is not helpful for scheduling."
60.1011,Event,ADDED,eval-sanitize-3-r1-086-rv9m8.18d3d27bfa91f290,"reason=FailedScheduling count=None msg=0/6 nodes are available: 1 c_wall violated: 2 conflicting context pair(s) with node memory, 1 c_wall violated: 3 conflicting context pair(s) with node memory, 4 node(s) had untolerated taint(s). no new claims to deallocate, preemption: 0/6 nodes are available: 2 No preemption victims found for incoming pod, 4 Preemption is not helpful for scheduling."
60.1019,Job,ADDED,eval-sanitize-3-r3-017,
60.103,Pod,ADDED,eval-sanitize-3-r3-012-bfdmn,phase=Succeeded node=kind-worker2
60.1031,TaskRequest,ADDED,eval-sanitize-3-r3-059,phase=Scheduled job=None
60.1031,TaskRequest,ADDED,eval-sanitize-3-r3-060,phase=Pending job=None
60.1035,Event,ADDED,eval-sanitize-3-r1-086-rv9m8.18d3d27c076e44fd,"reason=FailedScheduling count=None msg=0/6 nodes are available: 1 c_wall violated: 3 conflicting context pair(s) with node memory, 5 node(s) had untolerated taint(s). no new claims to deallocate, preemption: 0/6 nodes are available: 1 No preemption victims found for incoming pod, 5 Preemption is not helpful for scheduling."
60.1037,Event,ADDED,eval-sanitize-3-r1-086-rv9m8.18d3d27c3bfab04d,"reason=FailedScheduling count=None msg=0/6 nodes are available: 1 c_wall violated: 1 conflicting context pair(s) with node memory, 1 c_wall violated: 3 conflicting context pair(s) with node memory, 4 node(s) had untolerated taint(s). no new claims to deallocate, preemption: 0/6 nodes are available: 2 No preemption victims found for incoming pod, 4 Preemption is not helpful for scheduling."
60.1045,Job,ADDED,eval-sanitize-3-r3-018,
60.1049,Event,ADDED,eval-sanitize-3-r1-086-rv9m8.18d3d27c64ee584f,"reason=FailedScheduling count=None msg=0/6 nodes are available: 1 c_wall violated: 2 conflicting context pair(s) with node memory, 1 c_wall violated: 3 conflicting context pair(s) with node memory, 4 node(s) had untolerated taint(s). no new claims to deallocate, preemption: 0/6 nodes are available: 2 No preemption victims found for incoming pod, 4 Preemption is not helpful for scheduling."
60.1051,Event,ADDED,eval-sanitize-3-r1-086-rv9m8.18d3d27cbf4f8ae5,"reason=FailedScheduling count=None msg=0/6 nodes are available: 1 c_wall violated: 2 conflicting context pair(s) with node memory, 5 node(s) had untolerated taint(s). no new claims to deallocate, preemption: 0/6 nodes are available: 1 No preemption victims found for incoming pod, 5 Preemption is not helpful for scheduling."
60.1053,Event,ADDED,eval-sanitize-3-r1-087-97cqb.18d3d27b54083f51,"reason=FailedScheduling count=None msg=0/6 nodes are available: 1 c_wall violated: 2 conflicting context pair(s) with node memory, 5 node(s) had untolerated taint(s). no new claims to deallocate, preemption: 0/6 nodes are available: 1 No preemption victims found for incoming pod, 5 Preemption is not helpful for scheduling."
60.1062,Job,ADDED,eval-sanitize-3-r3-019,
60.1074,Pod,ADDED,eval-sanitize-3-r3-013-77wdv,phase=Succeeded node=kind-worker
60.1074,TaskRequest,MODIFIED,eval-sanitize-3-r3-060,phase=Scheduled job=None
60.1078,Event,ADDED,eval-sanitize-3-r1-089-fmlmf.18d3d27b543bd3c5,"reason=FailedScheduling count=None msg=0/6 nodes are available: 1 c_wall violated: 1 conflicting context pair(s) with node memory, 5 node(s) had untolerated taint(s). no new claims to deallocate, preemption: 0/6 nodes are available: 1 No preemption victims found for incoming pod, 5 Preemption is not helpful for scheduling."
60.108,Event,ADDED,eval-sanitize-3-r1-089-fmlmf.18d3d27bfa51b068,"reason=FailedScheduling count=None msg=0/6 nodes are available: 1 c_wall violated: 1 conflicting context pair(s) with node memory, 1 c_wall violated: 2 conflicting context pair(s) with node memory, 4 node(s) had untolerated taint(s). no new claims to deallocate, preemption: 0/6 nodes are available: 2 No preemption victims found for incoming pod, 4 Preemption is not helpful for scheduling."
60.1082,Event,ADDED,eval-sanitize-3-r1-089-fmlmf.18d3d27c07422efc,"reason=FailedScheduling count=None msg=0/6 nodes are available: 1 c_wall violated: 2 conflicting context pair(s) with node memory, 5 node(s) had untolerated taint(s). no new claims to deallocate, preemption: 0/6 nodes are available: 1 No preemption victims found for incoming pod, 5 Preemption is not helpful for scheduling."
60.1093,Job,ADDED,eval-sanitize-3-r3-020,
60.1105,Pod,ADDED,eval-sanitize-3-r3-014-mnwm8,phase=Succeeded node=kind-worker2
60.1106,TaskRequest,MODIFIED,eval-sanitize-3-r3-060,phase=Scheduled job=None
60.1109,Event,ADDED,eval-sanitize-3-r1-090-qxp85.18d3d27b70839b2e,"reason=FailedScheduling count=None msg=0/6 nodes are available: 1 c_wall violated: 2 conflicting context pair(s) with node memory, 5 node(s) had untolerated taint(s). no new claims to deallocate, preemption: 0/6 nodes are available: 1 No preemption victims found for incoming pod, 5 Preemption is not helpful for scheduling."
60.1112,Event,ADDED,eval-sanitize-3-r1-091-5mc4w.18d3d27bac48ce9a,"reason=FailedScheduling count=None msg=0/6 nodes are available: 1 c_wall violated: 3 conflicting context pair(s) with node memory, 5 node(s) had untolerated taint(s). no new claims to deallocate, preemption: 0/6 nodes are available: 1 No preemption victims found for incoming pod, 5 Preemption is not helpful for scheduling."
60.1114,Event,ADDED,eval-sanitize-3-r1-093-hv55n.18d3d27c241a89df,"reason=FailedScheduling count=None msg=0/6 nodes are available: 1 c_wall violated: 3 conflicting context pair(s) with node memory, 5 node(s) had untolerated taint(s). no new claims to deallocate, preemption: 0/6 nodes are available: 1 No preemption victims found for incoming pod, 5 Preemption is not helpful for scheduling."
60.1125,Job,ADDED,eval-sanitize-3-r3-021,
60.1129,Event,ADDED,eval-sanitize-3-r1-093-hv55n.18d3d27c40ca68e1,"reason=FailedScheduling count=None msg=0/6 nodes are available: 1 c_wall violated: 1 conflicting context pair(s) with node memory, 1 c_wall violated: 3 conflicting context pair(s) with node memory, 4 node(s) had untolerated taint(s). no new claims to deallocate, preemption: 0/6 nodes are available: 2 No preemption victims found for incoming pod, 4 Preemption is not helpful for scheduling."
60.1132,Event,ADDED,eval-sanitize-3-r1-093-hv55n.18d3d27cbf1a9a77,"reason=FailedScheduling count=None msg=0/6 nodes are available: 1 c_wall violated: 1 conflicting context pair(s) with node memory, 5 node(s) had untolerated taint(s). no new claims to deallocate, preemption: 0/6 nodes are available: 1 No preemption victims found for incoming pod, 5 Preemption is not helpful for scheduling."
60.1135,Event,ADDED,eval-sanitize-3-r1-093-hv55n.18d3d27cdc0863ae,"reason=FailedScheduling count=None msg=0/6 nodes are available: 2 c_wall violated: 1 conflicting context pair(s) with node memory, 4 node(s) had untolerated taint(s). no new claims to deallocate, preemption: 0/6 nodes are available: 2 No preemption victims found for incoming pod, 4 Preemption is not helpful for scheduling."
60.1148,Job,ADDED,eval-sanitize-3-r3-022,
60.1152,Event,ADDED,eval-sanitize-3-r1-093-hv55n.18d3d27cf5ddba09,"reason=FailedScheduling count=None msg=0/6 nodes are available: 1 c_wall violated: 1 conflicting context pair(s) with node memory, 5 node(s) had untolerated taint(s). no new claims to deallocate, preemption: 0/6 nodes are available: 1 No preemption victims found for incoming pod, 5 Preemption is not helpful for scheduling."
60.1155,Event,ADDED,eval-sanitize-3-r1-096-chwwn.18d3d27cd6a9f29d,"reason=FailedScheduling count=None msg=0/6 nodes are available: 1 c_wall violated: 1 conflicting context pair(s) with node memory, 5 node(s) had untolerated taint(s). no new claims to deallocate, preemption: 0/6 nodes are available: 1 No preemption victims found for incoming pod, 5 Preemption is not helpful for scheduling."
60.1158,Event,ADDED,eval-sanitize-3-r1-096-chwwn.18d3d27cdc588bd6,"reason=FailedScheduling count=None msg=0/6 nodes are available: 2 c_wall violated: 1 conflicting context pair(s) with node memory, 4 node(s) had untolerated taint(s). no new claims to deallocate, preemption: 0/6 nodes are available: 2 No preemption victims found for incoming pod, 4 Preemption is not helpful for scheduling."
60.1161,Event,ADDED,eval-sanitize-3-r1-096-chwwn.18d3d27cf608522d,"reason=FailedScheduling count=None msg=0/6 nodes are available: 1 c_wall violated: 1 conflicting context pair(s) with node memory, 5 node(s) had untolerated taint(s). no new claims to deallocate, preemption: 0/6 nodes are available: 1 No preemption victims found for incoming pod, 5 Preemption is not helpful for scheduling."
60.1164,Event,ADDED,eval-sanitize-3-r1-096-chwwn.18d3d27d71aef7e9,"reason=FailedScheduling count=None msg=0/6 nodes are available: 2 c_wall violated: 1 conflicting context pair(s) with node memory, 4 node(s) had untolerated taint(s). no new claims to deallocate, preemption: 0/6 nodes are available: 2 No preemption victims found for incoming pod, 4 Preemption is not helpful for scheduling."
60.1168,Event,ADDED,eval-sanitize-3-r1-096-chwwn.18d3d27d8e9bc951,"reason=FailedScheduling count=None msg=0/6 nodes are available: 1 c_wall violated: 1 conflicting context pair(s) with node memory, 1 c_wall violated: 2 conflicting context pair(s) with node memory, 4 node(s) had untolerated taint(s). no new claims to deallocate, preemption: 0/6 nodes are available: 2 No preemption victims found for incoming pod, 4 Preemption is not helpful for scheduling."
60.1171,Event,ADDED,eval-sanitize-3-r1-096-chwwn.18d3d27d9284fb4f,"reason=FailedScheduling count=None msg=0/6 nodes are available: 1 c_wall violated: 1 conflicting context pair(s) with node memory, 5 node(s) had untolerated taint(s). no new claims to deallocate, preemption: 0/6 nodes are available: 1 No preemption victims found for incoming pod, 5 Preemption is not helpful for scheduling."
60.1173,Event,ADDED,eval-sanitize-3-r1-097-dxvqj.18d3d27d12603368,"reason=FailedScheduling count=None msg=0/6 nodes are available: 1 c_wall violated: 1 conflicting context pair(s) with node memory, 5 node(s) had untolerated taint(s). no new claims to deallocate, preemption: 0/6 nodes are available: 1 No preemption victims found for incoming pod, 5 Preemption is not helpful for scheduling."
60.1187,Pod,ADDED,eval-sanitize-3-r3-015-vwlfs,phase=Succeeded node=kind-worker
60.1196,Job,ADDED,eval-sanitize-3-r3-023,
60.12,Event,ADDED,eval-sanitize-3-r1-098-nv54x.18d3d27d4df49446,"reason=FailedScheduling count=None msg=0/6 nodes are available: 1 c_wall violated: 1 conflicting context pair(s) with node memory, 5 node(s) had untolerated taint(s). no new claims to deallocate, preemption: 0/6 nodes are available: 1 No preemption victims found for incoming pod, 5 Preemption is not helpful for scheduling."
60.1202,Event,ADDED,eval-sanitize-3-r3-000-jfrb4.18d3d2f4d0496f31,reason=Scheduled count=None msg=Successfully assigned compute/eval-sanitize-3-r3-000-jfrb4 to kind-worker2
60.1203,Event,ADDED,eval-sanitize-3-r3-000-jfrb4.18d3d2f4e986d180,"reason=Pulled count=1 msg=Container image ""busybox:musl"" already present on machine"
60.1228,Pod,ADDED,eval-sanitize-3-r3-016-h5x2s,phase=Succeeded node=kind-worker
60.1236,Job,ADDED,eval-sanitize-3-r3-024,
60.1239,Event,ADDED,eval-sanitize-3-r3-000-jfrb4.18d3d2f4ead23a6e,reason=Created count=1 msg=Created container: task
60.1242,Event,ADDED,eval-sanitize-3-r3-000-jfrb4.18d3d2f4ed02e11a,reason=Started count=1 msg=Started container task
60.1245,Event,ADDED,eval-sanitize-3-r3-000.18d3d2f4cf762988,reason=SuccessfulCreate count=1 msg=Created pod: eval-sanitize-3-r3-000-jfrb4
60.1247,Event,ADDED,eval-sanitize-3-r3-000.18d3d2f81767eb64,reason=Completed count=1 msg=Job completed
60.1259,Pod,ADDED,eval-sanitize-3-r3-017-g2ttz,phase=Succeeded node=kind-worker4
60.1263,Event,ADDED,eval-sanitize-3-r3-001-x9hkn.18d3d2f507276e8e,reason=Scheduled count=None msg=Successfully assigned compute/eval-sanitize-3-r3-001-x9hkn to kind-worker
60.1266,Event,ADDED,eval-sanitize-3-r3-001-x9hkn.18d3d2f51f786474,"reason=Pulled count=1 msg=Container image ""busybox:musl"" already present on machine"
60.1269,Event,ADDED,eval-sanitize-3-r3-001-x9hkn.18d3d2f520a50538,reason=Created count=1 msg=Created container: task
60.1273,Event,ADDED,eval-sanitize-3-r3-001-x9hkn.18d3d2f5248b8af9,reason=Started count=1 msg=Started container task
60.1281,Job,ADDED,eval-sanitize-3-r3-025,
60.1296,Pod,ADDED,eval-sanitize-3-r3-018-gz22z,phase=Succeeded node=kind-worker3
60.1302,Event,ADDED,eval-sanitize-3-r3-001.18d3d2f505f91a5f,reason=SuccessfulCreate count=1 msg=Created pod: eval-sanitize-3-r3-001-x9hkn
60.1305,Event,ADDED,eval-sanitize-3-r3-001.18d3d2f83a2673b1,reason=Completed count=1 msg=Job completed
60.1308,Event,ADDED,eval-sanitize-3-r3-002-7fs7w.18d3d2f5421fb91b,reason=Scheduled count=None msg=Successfully assigned compute/eval-sanitize-3-r3-002-7fs7w to kind-worker4
60.131,Event,ADDED,eval-sanitize-3-r3-002-7fs7w.18d3d2f55b2b4298,"reason=Pulled count=1 msg=Container image ""busybox:musl"" already present on machine"
60.1319,Job,ADDED,eval-sanitize-3-r3-026,
60.1324,Event,ADDED,eval-sanitize-3-r3-002-7fs7w.18d3d2f55c6be66a,reason=Created count=1 msg=Created container: task
60.1327,Event,ADDED,eval-sanitize-3-r3-002-7fs7w.18d3d2f55e6b47d1,reason=Started count=1 msg=Started container task
60.133,Event,ADDED,eval-sanitize-3-r3-002.18d3d2f54188efb1,reason=SuccessfulCreate count=1 msg=Created pod: eval-sanitize-3-r3-002-7fs7w
60.1332,Event,ADDED,eval-sanitize-3-r3-002.18d3d2f89779b6bf,reason=Completed count=1 msg=Job completed
60.1334,Event,ADDED,eval-sanitize-3-r3-003-vp5rl.18d3d2f57db4a590,reason=Scheduled count=None msg=Successfully assigned compute/eval-sanitize-3-r3-003-vp5rl to kind-worker5
60.1337,Event,ADDED,eval-sanitize-3-r3-003-vp5rl.18d3d2f596f85f29,"reason=Pulled count=1 msg=Container image ""busybox:musl"" already present on machine"
60.1339,Event,ADDED,eval-sanitize-3-r3-003-vp5rl.18d3d2f5983e98ac,reason=Created count=1 msg=Created container: task
60.1349,Job,ADDED,eval-sanitize-3-r3-027,
60.136,Pod,ADDED,eval-sanitize-3-r3-019-svm65,phase=Succeeded node=kind-worker5
60.1363,Event,ADDED,eval-sanitize-3-r3-003-vp5rl.18d3d2f59c7ff0b3,reason=Started count=1 msg=Started container task
60.1366,Event,ADDED,eval-sanitize-3-r3-003.18d3d2f57cf8678e,reason=SuccessfulCreate count=1 msg=Created pod: eval-sanitize-3-r3-003-vp5rl
60.1367,Event,ADDED,eval-sanitize-3-r3-003.18d3d2f8d689d0fc,reason=Completed count=1 msg=Job completed
60.1369,Event,ADDED,eval-sanitize-3-r3-004-rz87f.18d3d2f5b9274309,reason=Scheduled count=None msg=Successfully assigned compute/eval-sanitize-3-r3-004-rz87f to kind-worker3
60.1377,Job,ADDED,eval-sanitize-3-r3-028,
60.1389,Pod,ADDED,eval-sanitize-3-r3-020-7xstb,phase=Succeeded node=kind-worker3
60.1392,Event,ADDED,eval-sanitize-3-r3-004-rz87f.18d3d2f5d3c66f0e,"reason=Pulled count=1 msg=Container image ""busybox:musl"" already present on machine"
60.1394,Event,ADDED,eval-sanitize-3-r3-004-rz87f.18d3d2f5d4e9efe4,reason=Created count=1 msg=Created container: task
60.1396,Event,ADDED,eval-sanitize-3-r3-004-rz87f.18d3d2f5d6f98fa7,reason=Started count=1 msg=Started container task
60.1406,Job,ADDED,eval-sanitize-3-r3-029,
60.141,Event,ADDED,eval-sanitize-3-r3-004.18d3d2f5b8b09b59,reason=SuccessfulCreate count=1 msg=Created pod: eval-sanitize-3-r3-004-rz87f
60.1412,Event,ADDED,eval-sanitize-3-r3-004.18d3d2f90fea3f95,reason=Completed count=1 msg=Job completed
60.1415,Event,ADDED,eval-sanitize-3-r3-005-zlzdh.18d3d2f5f4db0e4d,reason=Scheduled count=None msg=Successfully assigned compute/eval-sanitize-3-r3-005-zlzdh to kind-worker5
60.1417,Event,ADDED,eval-sanitize-3-r3-005-zlzdh.18d3d2f60ea6ac13,"reason=Pulled count=1 msg=Container image ""busybox:musl"" already present on machine"
60.1428,Job,ADDED,eval-sanitize-3-r3-030,
60.1431,Event,ADDED,eval-sanitize-3-r3-005-zlzdh.18d3d2f60fd0455a,reason=Created count=1 msg=Created container: task
60.1433,Event,ADDED,eval-sanitize-3-r3-005-zlzdh.18d3d2f611e63e84,reason=Started count=1 msg=Started container task
60.1436,Event,ADDED,eval-sanitize-3-r3-005.18d3d2f5f3f54c84,reason=SuccessfulCreate count=1 msg=Created pod: eval-sanitize-3-r3-005-zlzdh
60.1437,Event,ADDED,eval-sanitize-3-r3-005.18d3d2f94deae9a3,reason=Completed count=1 msg=Job completed
60.1451,Pod,ADDED,eval-sanitize-3-r3-021-nbbns,phase=Succeeded node=kind-worker3
60.1466,Pod,ADDED,eval-sanitize-3-r3-022-xkvgt,phase=Succeeded node=kind-worker2
60.1474,Job,ADDED,eval-sanitize-3-r3-031,
60.1476,Event,ADDED,eval-sanitize-3-r3-006-bjfc4.18d3d2f62fcdb556,"reason=FailedScheduling count=None msg=0/6 nodes are available: 6 node(s) had untolerated taint(s). no new claims to deallocate, preemption: 0/6 nodes are available: 6 Preemption is not helpful for scheduling."
60.1478,Event,ADDED,eval-sanitize-3-r3-006-bjfc4.18d3d2f8428a4d03,reason=Scheduled count=None msg=Successfully assigned compute/eval-sanitize-3-r3-006-bjfc4 to kind-worker2
60.148,Event,ADDED,eval-sanitize-3-r3-006-bjfc4.18d3d2f85bc5fb13,"reason=Pulled count=1 msg=Container image ""busybox:musl"" already present on machine"
60.149,Job,ADDED,eval-sanitize-3-r3-032,
60.1501,Pod,ADDED,eval-sanitize-3-r3-023-7hhqc,phase=Succeeded node=kind-worker3
60.1504,Event,ADDED,eval-sanitize-3-r3-006-bjfc4.18d3d2f85daf8037,reason=Created count=1 msg=Created container: task
60.1506,Event,ADDED,eval-sanitize-3-r3-006-bjfc4.18d3d2f8664943df,reason=Started count=1 msg=Started container task
60.1508,Event,ADDED,eval-sanitize-3-r3-006.18d3d2f62fc0ed50,reason=SuccessfulCreate count=1 msg=Created pod: eval-sanitize-3-r3-006-bjfc4
60.1511,Event,ADDED,eval-sanitize-3-r3-006.18d3d2fb97c9b571,reason=Completed count=1 msg=Job completed
60.1532,Pod,ADDED,eval-sanitize-3-r3-024-7gkdr,phase=Succeeded node=kind-worker2
60.1535,Event,ADDED,eval-sanitize-3-r3-007-mt7xl.18d3d2f66b6b6024,"reason=FailedScheduling count=None msg=0/6 nodes are available: 6 node(s) had untolerated taint(s). no new claims to deallocate, preemption: 0/6 nodes are available: 6 Preemption is not helpful for scheduling."
60.1537,Event,ADDED,eval-sanitize-3-r3-007-mt7xl.18d3d2f8427193e6,"reason=FailedScheduling count=None msg=0/6 nodes are available: 1 c_wall violated: 1 conflicting context pair(s) with node memory, 5 node(s) had untolerated taint(s). no new claims to deallocate, preemption: 0/6 nodes are available: 1 No preemption victims found for incoming pod, 5 Preemption is not helpful for scheduling."
60.1539,Event,ADDED,eval-sanitize-3-r3-007-mt7xl.18d3d2f847984751,"reason=FailedScheduling count=None msg=0/6 nodes are available: 1 c_wall violated: 2 conflicting context pair(s) with node memory, 5 node(s) had untolerated taint(s). no new claims to deallocate, preemption: 0/6 nodes are available: 1 No preemption victims found for incoming pod, 5 Preemption is not helpful for scheduling."
60.1549,Job,ADDED,eval-sanitize-3-r3-033,
60.1558,Job,ADDED,eval-sanitize-3-r3-034,
60.1574,Pod,ADDED,eval-sanitize-3-r3-025-mtstx,phase=Succeeded node=kind-worker2
60.1578,Event,ADDED,eval-sanitize-3-r3-007-mt7xl.18d3d2f84df35bc5,"reason=FailedScheduling count=None msg=0/6 nodes are available: 1 c_wall violated: 2 conflicting context pair(s) with node memory, 5 node(s) had untolerated taint(s). no new claims to deallocate, preemption: 0/6 nodes are available: 1 No preemption victims found for incoming pod, 5 Preemption is not helpful for scheduling."
60.1581,Event,ADDED,eval-sanitize-3-r3-007-mt7xl.18d3d2f85a098ad2,reason=Scheduled count=None msg=Successfully assigned compute/eval-sanitize-3-r3-007-mt7xl to kind-worker
60.1584,Event,ADDED,eval-sanitize-3-r3-007-mt7xl.18d3d2f8743bdfea,"reason=Pulled count=1 msg=Container image ""busybox:musl"" already present on machine"
60.1601,Pod,ADDED,eval-sanitize-3-r3-026-mmf5k,phase=Succeeded node=kind-worker
60.1605,Event,ADDED,eval-sanitize-3-r3-007-mt7xl.18d3d2f875cb8a45,reason=Created count=1 msg=Created container: task
60.1607,Event,ADDED,eval-sanitize-3-r3-007-mt7xl.18d3d2f8786fa9cc,reason=Started count=1 msg=Started container task
60.1609,Event,ADDED,eval-sanitize-3-r3-007.18d3d2f66b62cb91,reason=SuccessfulCreate count=1 msg=Created pod: eval-sanitize-3-r3-007-mt7xl
60.1611,Event,ADDED,eval-sanitize-3-r3-007.18d3d2fc0136b7e9,reason=Completed count=1 msg=Job completed
60.162,Job,ADDED,eval-sanitize-3-r3-035,
60.1624,Event,ADDED,eval-sanitize-3-r3-008-jtwkx.18d3d2f6a6b5fced,"reason=FailedScheduling count=None msg=0/6 nodes are available: 6 node(s) had untolerated taint(s). no new claims to deallocate, preemption: 0/6 nodes are available: 6 Preemption is not helpful for scheduling."
60.1627,Event,ADDED,eval-sanitize-3-r3-008-jtwkx.18d3d2f8430e8cd1,"reason=FailedScheduling count=None msg=0/6 nodes are available: 1 c_wall violated: 1 conflicting context pair(s) with node memory, 5 node(s) had untolerated taint(s). no new claims to deallocate, preemption: 0/6 nodes are available: 1 No preemption victims found for incoming pod, 5 Preemption is not helpful for scheduling."
60.1629,Event,ADDED,eval-sanitize-3-r3-008-jtwkx.18d3d2f8485e2f1a,"reason=FailedScheduling count=None msg=0/6 nodes are available: 1 c_wall violated: 2 conflicting context pair(s) with node memory, 5 node(s) had untolerated taint(s). no new claims to deallocate, preemption: 0/6 nodes are available: 1 No preemption victims found for incoming pod, 5 Preemption is not helpful for scheduling."
60.1638,Job,ADDED,eval-sanitize-3-r3-036,
60.1655,Pod,ADDED,eval-sanitize-3-r3-027-4wfbw,phase=Succeeded node=kind-worker2
60.1659,Event,ADDED,eval-sanitize-3-r3-008-jtwkx.18d3d2f84e1c4a06,"reason=FailedScheduling count=None msg=0/6 nodes are available: 1 c_wall violated: 2 conflicting context pair(s) with node memory, 5 node(s) had untolerated taint(s). no new claims to deallocate, preemption: 0/6 nodes are available: 1 No preemption victims found for incoming pod, 5 Preemption is not helpful for scheduling."
60.1661,Event,ADDED,eval-sanitize-3-r3-008-jtwkx.18d3d2f85e73cdf0,reason=Scheduled count=None msg=Successfully assigned compute/eval-sanitize-3-r3-008-jtwkx to kind-worker
60.1663,Event,ADDED,eval-sanitize-3-r3-008-jtwkx.18d3d2f877443c07,"reason=Pulled count=1 msg=Container image ""busybox:musl"" already present on machine"
60.1665,Event,ADDED,eval-sanitize-3-r3-008-jtwkx.18d3d2f879501e36,reason=Created count=1 msg=Created container: task
60.168,Pod,ADDED,eval-sanitize-3-r3-028-cq5fx,phase=Succeeded node=kind-worker2
60.1683,Event,ADDED,eval-sanitize-3-r3-008-jtwkx.18d3d2f87de390d6,reason=Started count=1 msg=Started container task
60.1686,Event,ADDED,eval-sanitize-3-r3-008.18d3d2f6a6ab0336,reason=SuccessfulCreate count=1 msg=Created pod: eval-sanitize-3-r3-008-jtwkx
60.1689,Event,ADDED,eval-sanitize-3-r3-008.18d3d2fbf7a9c58d,reason=Completed count=1 msg=Job completed
60.17,Job,ADDED,eval-sanitize-3-r3-037,
60.1704,Event,ADDED,eval-sanitize-3-r3-009-97txr.18d3d2f6e29daa04,"reason=FailedScheduling count=None msg=0/6 nodes are available: 6 node(s) had untolerated taint(s). no new claims to deallocate, preemption: 0/6 nodes are available: 6 Preemption is not helpful for scheduling."
60.1706,Event,ADDED,eval-sanitize-3-r3-009-97txr.18d3d2f8439e3131,"reason=FailedScheduling count=None msg=0/6 nodes are available: 1 c_wall violated: 1 conflicting context pair(s) with node memory, 5 node(s) had untolerated taint(s). no new claims to deallocate, preemption: 0/6 nodes are available: 1 No preemption victims found for incoming pod, 5 Preemption is not helpful for scheduling."
60.1708,Event,ADDED,eval-sanitize-3-r3-009-97txr.18d3d2f84c2a4ab3,"reason=FailedScheduling count=None msg=0/6 nodes are available: 1 c_wall violated: 2 conflicting context pair(s) with node memory, 5 node(s) had untolerated taint(s). no new claims to deallocate, preemption: 0/6 nodes are available: 1 No preemption victims found for incoming pod, 5 Preemption is not helpful for scheduling."
60.1719,Job,ADDED,eval-sanitize-3-r3-038,
60.1736,Pod,ADDED,eval-sanitize-3-r3-029-8klt2,phase=Succeeded node=kind-worker
60.1739,Event,ADDED,eval-sanitize-3-r3-009-97txr.18d3d2f84e6a451e,"reason=FailedScheduling count=None msg=0/6 nodes are available: 1 c_wall violated: 2 conflicting context pair(s) with node memory, 5 node(s) had untolerated taint(s). no new claims to deallocate, preemption: 0/6 nodes are available: 1 No preemption victims found for incoming pod, 5 Preemption is not helpful for scheduling."
60.1741,Event,ADDED,eval-sanitize-3-r3-009-97txr.18d3d2f8630991d1,reason=Scheduled count=None msg=Successfully assigned compute/eval-sanitize-3-r3-009-97txr to kind-worker
60.1744,Event,ADDED,eval-sanitize-3-r3-009-97txr.18d3d2f882c79539,"reason=Pulled count=1 msg=Container image ""busybox:musl"" already present on machine"
60.1746,Event,ADDED,eval-sanitize-3-r3-009-97txr.18d3d2f884c7ce56,reason=Created count=1 msg=Created container: task
60.1762,Pod,ADDED,eval-sanitize-3-r3-030-rddvq,phase=Succeeded node=kind-worker
60.1765,Event,ADDED,eval-sanitize-3-r3-009-97txr.18d3d2f88798deb8,reason=Started count=1 msg=Started container task
60.1767,Event,ADDED,eval-sanitize-3-r3-009.18d3d2f6e2921e3f,reason=SuccessfulCreate count=1 msg=Created pod: eval-sanitize-3-r3-009-97txr
60.1769,Event,ADDED,eval-sanitize-3-r3-009.18d3d2fb81e76ffa,reason=Completed count=1 msg=Job completed
60.1779,Job,ADDED,eval-sanitize-3-r3-039,
60.1783,Event,ADDED,eval-sanitize-3-r3-010-tnkj2.18d3d2f71ed75ddf,"reason=FailedScheduling count=None msg=0/6 nodes are available: 6 node(s) had untolerated taint(s). no new claims to deallocate, preemption: 0/6 nodes are available: 6 Preemption is not helpful for scheduling."
60.1785,Event,ADDED,eval-sanitize-3-r3-010-tnkj2.18d3d2f84419dd84,"reason=FailedScheduling count=None msg=0/6 nodes are available: 1 c_wall violated: 1 conflicting context pair(s) with node memory, 5 node(s) had untolerated taint(s). no new claims to deallocate, preemption: 0/6 nodes are available: 1 No preemption victims found for incoming pod, 5 Preemption is not helpful for scheduling."
60.1787,Event,ADDED,eval-sanitize-3-r3-010-tnkj2.18d3d2f84cb3944d,"reason=FailedScheduling count=None msg=0/6 nodes are available: 1 c_wall violated: 2 conflicting context pair(s) with node memory, 5 node(s) had untolerated taint(s). no new claims to deallocate, preemption: 0/6 nodes are available: 1 No preemption victims found for incoming pod, 5 Preemption is not helpful for scheduling."
60.1795,Job,ADDED,eval-sanitize-3-r3-040,
60.1812,Pod,ADDED,eval-sanitize-3-r3-031-4fnvg,phase=Succeeded node=kind-worker4
60.1815,Event,ADDED,eval-sanitize-3-r3-010-tnkj2.18d3d2f850e3ff85,"reason=FailedScheduling count=None msg=0/6 nodes are available: 1 c_wall violated: 2 conflicting context pair(s) with node memory, 5 node(s) had untolerated taint(s). no new claims to deallocate, preemption: 0/6 nodes are available: 1 No preemption victims found for incoming pod, 5 Preemption is not helpful for scheduling."
60.1817,Event,ADDED,eval-sanitize-3-r3-010-tnkj2.18d3d2f8652c660c,reason=Scheduled count=None msg=Successfully assigned compute/eval-sanitize-3-r3-010-tnkj2 to kind-worker
60.1819,Event,ADDED,eval-sanitize-3-r3-010-tnkj2.18d3d2f8840c7704,"reason=Pulled count=1 msg=Container image ""busybox:musl"" already present on machine"
60.1821,Event,ADDED,eval-sanitize-3-r3-010-tnkj2.18d3d2f885bf44f2,reason=Created count=1 msg=Created container: task
60.1824,Event,ADDED,eval-sanitize-3-r3-010-tnkj2.18d3d2f88852d313,reason=Started count=1 msg=Started container task
60.1826,Event,ADDED,eval-sanitize-3-r3-010.18d3d2f71ecf1433,reason=SuccessfulCreate count=1 msg=Created pod: eval-sanitize-3-r3-010-tnkj2
60.1828,Event,ADDED,eval-sanitize-3-r3-010.18d3d2fbbb3d9480,reason=Completed count=1 msg=Job completed
60.183,Event,ADDED,eval-sanitize-3-r3-011-prswl.18d3d2f759a83a00,"reason=FailedScheduling count=None msg=0/6 nodes are available: 6 node(s) had untolerated taint(s). no new claims to deallocate, preemption: 0/6 nodes are available: 6 Preemption is not helpful for scheduling."
60.1844,Pod,ADDED,eval-sanitize-3-r3-032-ps7mn,phase=Succeeded node=kind-worker4
60.1853,Job,ADDED,eval-sanitize-3-r3-041,
60.1856,Event,ADDED,eval-sanitize-3-r3-011-prswl.18d3d2f8449050ed,"reason=FailedScheduling count=None msg=0/6 nodes are available: 1 c_wall violated: 1 conflicting context pair(s) with node memory, 5 node(s) had untolerated taint(s). no new claims to deallocate, preemption: 0/6 nodes are available: 1 No preemption victims found for incoming pod, 5 Preemption is not helpful for scheduling."
60.1858,Event,ADDED,eval-sanitize-3-r3-011-prswl.18d3d2f84d521ba3,"reason=FailedScheduling count=None msg=0/6 nodes are available: 1 c_wall violated: 2 conflicting context pair(s) with node memory, 5 node(s) had untolerated taint(s). no new claims to deallocate, preemption: 0/6 nodes are available: 1 No preemption victims found for incoming pod, 5 Preemption is not helpful for scheduling."
60.186,Event,ADDED,eval-sanitize-3-r3-011-prswl.18d3d2f852ccb4c4,"reason=FailedScheduling count=None msg=0/6 nodes are available: 1 c_wall violated: 2 conflicting context pair(s) with node memory, 5 node(s) had untolerated taint(s). no new claims to deallocate, preemption: 0/6 nodes are available: 1 No preemption victims found for incoming pod, 5 Preemption is not helpful for scheduling."
60.187,Job,ADDED,eval-sanitize-3-r3-042,
60.1873,Event,ADDED,eval-sanitize-3-r3-011-prswl.18d3d2f8659f507f,reason=Scheduled count=None msg=Successfully assigned compute/eval-sanitize-3-r3-011-prswl to kind-worker
60.1875,Event,ADDED,eval-sanitize-3-r3-011-prswl.18d3d2f881785b8b,"reason=Pulled count=1 msg=Container image ""busybox:musl"" already present on machine"
60.1879,Event,ADDED,eval-sanitize-3-r3-011-prswl.18d3d2f882e0b49b,reason=Created count=1 msg=Created container: task
60.189,Pod,ADDED,eval-sanitize-3-r3-033-zv46r,phase=Succeeded node=kind-worker
60.1895,Event,ADDED,eval-sanitize-3-r3-011-prswl.18d3d2f8851643fe,reason=Started count=1 msg=Started container task
60.1897,Event,ADDED,eval-sanitize-3-r3-011.18d3d2f75999ce9f,reason=SuccessfulCreate count=1 msg=Created pod: eval-sanitize-3-r3-011-prswl
60.19,Event,ADDED,eval-sanitize-3-r3-011.18d3d2fbbba20b17,reason=Completed count=1 msg=Job completed
60.1902,Event,ADDED,eval-sanitize-3-r3-012-bfdmn.18d3d2f7953e3bbf,"reason=FailedScheduling count=None msg=0/6 nodes are available: 6 node(s) had untolerated taint(s). no new claims to deallocate, preemption: 0/6 nodes are available: 6 Preemption is not helpful for scheduling."
60.1916,Pod,ADDED,eval-sanitize-3-r3-034-fsqln,phase=Succeeded node=kind-worker3
60.1925,Job,ADDED,eval-sanitize-3-r3-043,
60.1928,Event,ADDED,eval-sanitize-3-r3-012-bfdmn.18d3d2f8454aff4c,reason=Scheduled count=None msg=Successfully assigned compute/eval-sanitize-3-r3-012-bfdmn to kind-worker2
60.193,Event,ADDED,eval-sanitize-3-r3-012-bfdmn.18d3d2f861af114c,"reason=Pulled count=1 msg=Container image ""busybox:musl"" already present on machine"
60.1932,Event,ADDED,eval-sanitize-3-r3-012-bfdmn.18d3d2f862eaee41,reason=Created count=1 msg=Created container: task
60.1934,Event,ADDED,eval-sanitize-3-r3-012-bfdmn.18d3d2f8656a61f2,reason=Started count=1 msg=Started container task
60.1945,Job,ADDED,eval-sanitize-3-r3-044,
60.1949,Event,ADDED,eval-sanitize-3-r3-012.18d3d2f795334d44,reason=SuccessfulCreate count=1 msg=Created pod: eval-sanitize-3-r3-012-bfdmn
60.1952,Event,ADDED,eval-sanitize-3-r3-012.18d3d2fb97a1b902,reason=Completed count=1 msg=Job completed
60.1954,Event,ADDED,eval-sanitize-3-r3-013-77wdv.18d3d2f7d0e85d96,"reason=FailedScheduling count=None msg=0/6 nodes are available: 6 node(s) had untolerated taint(s). no new claims to deallocate, preemption: 0/6 nodes are available: 6 Preemption is not helpful for scheduling."
60.1967,Pod,ADDED,eval-sanitize-3-r3-035-6bmlr,phase=Succeeded node=kind-worker5
60.1972,Event,ADDED,eval-sanitize-3-r3-013-77wdv.18d3d2f846dd15f8,"reason=FailedScheduling count=None msg=0/6 nodes are available: 1 c_wall violated: 2 conflicting context pair(s) with node memory, 5 node(s) had untolerated taint(s). no new claims to deallocate, preemption: 0/6 nodes are available: 1 No preemption victims found for incoming pod, 5 Preemption is not helpful for scheduling."
60.1975,Event,ADDED,eval-sanitize-3-r3-013-77wdv.18d3d2f84dcbab35,"reason=FailedScheduling count=None msg=0/6 nodes are available: 1 c_wall violated: 2 conflicting context pair(s) with node memory, 5 node(s) had untolerated taint(s). no new claims to deallocate, preemption: 0/6 nodes are available: 1 No preemption victims found for incoming pod, 5 Preemption is not helpful for scheduling."
60.1977,Event,ADDED,eval-sanitize-3-r3-013-77wdv.18d3d2f868fa9e6e,reason=Scheduled count=None msg=Successfully assigned compute/eval-sanitize-3-r3-013-77wdv to kind-worker
60.1992,Pod,ADDED,eval-sanitize-3-r3-036-4fnh6,phase=Succeeded node=kind-worker3
60.2,Job,ADDED,eval-sanitize-3-r3-045,
60.2004,Event,ADDED,eval-sanitize-3-r3-013-77wdv.18d3d2f882f1813e,"reason=Pulled count=1 msg=Container image ""busybox:musl"" already present on machine"
60.2007,Event,ADDED,eval-sanitize-3-r3-013-77wdv.18d3d2f88510f724,reason=Created count=1 msg=Created container: task
60.2009,Event,ADDED,eval-sanitize-3-r3-013-77wdv.18d3d2f8879721de,reason=Started count=1 msg=Started container task
60.2012,Event,ADDED,eval-sanitize-3-r3-013.18d3d2f7d0db900c,reason=SuccessfulCreate count=1 msg=Created pod: eval-sanitize-3-r3-013-77wdv
60.2015,Event,ADDED,eval-sanitize-3-r3-013.18d3d2fbf83e99ff,reason=Completed count=1 msg=Job completed
60.2017,Event,ADDED,eval-sanitize-3-r3-014-mnwm8.18d3d2f80c74fb6b,"reason=FailedScheduling count=None msg=0/6 nodes are available: 6 node(s) had untolerated taint(s). no new claims to deallocate, preemption: 0/6 nodes are available: 6 Preemption is not helpful for scheduling."
60.2019,Event,ADDED,eval-sanitize-3-r3-014-mnwm8.18d3d2f847b3999b,reason=Scheduled count=None msg=Successfully assigned compute/eval-sanitize-3-r3-014-mnwm8 to kind-worker2
60.2022,Event,ADDED,eval-sanitize-3-r3-014-mnwm8.18d3d2f866a9a3bf,"reason=Pulled count=1 msg=Container image ""busybox:musl"" already present on machine"
60.2032,Job,ADDED,eval-sanitize-3-r3-046,
60.2046,Pod,ADDED,eval-sanitize-3-r3-037-cw865,phase=Succeeded node=kind-worker5
60.2049,Event,ADDED,eval-sanitize-3-r3-014-mnwm8.18d3d2f868201db2,reason=Created count=1 msg=Created container: task
60.2052,Event,ADDED,eval-sanitize-3-r3-014-mnwm8.18d3d2f86ca97ffe,reason=Started count=1 msg=Started container task
60.2054,Event,ADDED,eval-sanitize-3-r3-014.18d3d2f80c69c75d,reason=SuccessfulCreate count=1 msg=Created pod: eval-sanitize-3-r3-014-mnwm8
60.207,Pod,ADDED,eval-sanitize-3-r3-038-vdkjz,phase=Succeeded node=kind-worker2
60.2074,Event,ADDED,eval-sanitize-3-r3-014.18d3d2fb98dd3db7,reason=Completed count=1 msg=Job completed
60.2076,Event,ADDED,eval-sanitize-3-r3-015-vwlfs.18d3d2f8490cdd9f,"reason=FailedScheduling count=None msg=0/6 nodes are available: 1 c_wall violated: 2 conflicting context pair(s) with node memory, 5 node(s) had untolerated taint(s). no new claims to deallocate, preemption: 0/6 nodes are available: 1 No preemption victims found for incoming pod, 5 Preemption is not helpful for scheduling."
60.2079,Event,ADDED,eval-sanitize-3-r3-015-vwlfs.18d3d2f84e43f8dd,"reason=FailedScheduling count=None msg=0/6 nodes are available: 1 c_wall violated: 2 conflicting context pair(s) with node memory, 5 node(s) had untolerated taint(s). no new claims to deallocate, preemption: 0/6 nodes are available: 1 No preemption victims found for incoming pod, 5 Preemption is not helpful for scheduling."
60.2086,Job,ADDED,eval-sanitize-3-r3-047,
60.2093,Job,ADDED,eval-sanitize-3-r3-048,
60.2096,Event,ADDED,eval-sanitize-3-r3-015-vwlfs.18d3d2f85f51e396,reason=Scheduled count=None msg=Successfully assigned compute/eval-sanitize-3-r3-015-vwlfs to kind-worker
60.2099,Event,ADDED,eval-sanitize-3-r3-015-vwlfs.18d3d2f877ac1da1,"reason=Pulled count=1 msg=Container image ""busybox:musl"" already present on machine"
60.2102,Event,ADDED,eval-sanitize-3-r3-015-vwlfs.18d3d2f87a98a87c,reason=Created count=1 msg=Created container: task
60.2104,Event,ADDED,eval-sanitize-3-r3-015-vwlfs.18d3d2f882c306f2,reason=Started count=1 msg=Started container task
60.2119,Pod,ADDED,eval-sanitize-3-r3-039-k4ldp,phase=Succeeded node=kind-worker2
60.2134,Pod,ADDED,eval-sanitize-3-r3-040-55zl6,phase=Succeeded node=kind-worker2
60.2139,Event,ADDED,eval-sanitize-3-r3-015.18d3d2f8484e234d,reason=SuccessfulCreate count=1 msg=Created pod: eval-sanitize-3-r3-015-vwlfs
60.2141,Event,ADDED,eval-sanitize-3-r3-015.18d3d2fc07326cba,reason=Completed count=1 msg=Job completed
60.2144,Event,ADDED,eval-sanitize-3-r3-016-h5x2s.18d3d2f887ed4cec,reason=Scheduled count=None msg=Successfully assigned compute/eval-sanitize-3-r3-016-h5x2s to kind-worker
60.2147,Event,ADDED,eval-sanitize-3-r3-016-h5x2s.18d3d2f8a140de46,"reason=Pulled count=1 msg=Container image ""busybox:musl"" already present on machine"
60.2154,Job,ADDED,eval-sanitize-3-r3-049,
60.2159,Event,ADDED,eval-sanitize-3-r3-016-h5x2s.18d3d2f8a2931616,reason=Created count=1 msg=Created container: task
60.2162,Event,ADDED,eval-sanitize-3-r3-016-h5x2s.18d3d2f8a62fdbd1,reason=Started count=1 msg=Started container task
60.2165,Event,ADDED,eval-sanitize-3-r3-016.18d3d2f886d1757e,reason=SuccessfulCreate count=1 msg=Created pod: eval-sanitize-3-r3-016-h5x2s
60.2172,Job,ADDED,eval-sanitize-3-r3-050,
60.2187,Pod,ADDED,eval-sanitize-3-r3-041-c9zgv,phase=Succeeded node=kind-worker2
60.2191,Event,ADDED,eval-sanitize-3-r3-016.18d3d2fbbad9f584,reason=Completed count=1 msg=Job completed
60.2193,Event,ADDED,eval-sanitize-3-r3-017-g2ttz.18d3d2f8c0f2437e,reason=Scheduled count=None msg=Successfully assigned compute/eval-sanitize-3-r3-017-g2ttz to kind-worker4
60.2195,Event,ADDED,eval-sanitize-3-r3-017-g2ttz.18d3d2f8da2e0967,"reason=Pulled count=1 msg=Container image ""busybox:musl"" already present on machine"
60.2197,Event,ADDED,eval-sanitize-3-r3-017-g2ttz.18d3d2f8db4cf2e0,reason=Created count=1 msg=Created container: task
60.2199,Event,ADDED,eval-sanitize-3-r3-017-g2ttz.18d3d2f8e148b7b6,reason=Started count=1 msg=Started container task
60.2201,Event,ADDED,eval-sanitize-3-r3-017.18d3d2f8bfaa7494,reason=SuccessfulCreate count=1 msg=Created pod: eval-sanitize-3-r3-017-g2ttz
60.2203,Event,ADDED,eval-sanitize-3-r3-017.18d3d2fc259081c3,reason=Completed count=1 msg=Job completed
60.2204,Event,ADDED,eval-sanitize-3-r3-018-gz22z.18d3d2f8fc21eadc,"reason=FailedScheduling count=None msg=0/6 nodes are available: 1 c_wall violated: 3 conflicting context pair(s) with node memory, 2 c_wall violated: 1 conflicting context pair(s) with node memory, 3 node(s) had untolerated taint(s). no new claims to deallocate, preemption: 0/6 nodes are available: 3 No preemption victims found for incoming pod, 3 Preemption is not helpful for scheduling."
60.2208,Event,ADDED,eval-sanitize-3-r3-018-gz22z.18d3d2f8ffa71db1,"reason=FailedScheduling count=None msg=0/6 nodes are available: 1 c_wall violated: 3 conflicting context pair(s) with node memory, 2 c_wall violated: 1 conflicting context pair(s) with node memory, 3 node(s) had untolerated taint(s). no new claims to deallocate, preemption: 0/6 nodes are available: 3 No preemption victims found for incoming pod, 3 Preemption is not helpful for scheduling."
60.221,Event,ADDED,eval-sanitize-3-r3-018-gz22z.18d3d2f907e3e59a,"reason=FailedScheduling count=None msg=0/6 nodes are available: 1 c_wall violated: 1 conflicting context pair(s) with node memory, 1 c_wall violated: 3 conflicting context pair(s) with node memory, 4 node(s) had untolerated taint(s). no new claims to deallocate, preemption: 0/6 nodes are available: 2 No preemption victims found for incoming pod, 4 Preemption is not helpful for scheduling."
60.2225,Pod,ADDED,eval-sanitize-3-r3-042-bkwv9,phase=Succeeded node=kind-worker2
60.2234,Job,ADDED,eval-sanitize-3-r3-051,
60.2238,Event,ADDED,eval-sanitize-3-r3-018-gz22z.18d3d2f9146790c1,"reason=FailedScheduling count=None msg=0/6 nodes are available: 1 c_wall violated: 1 conflicting context pair(s) with node memory, 5 node(s) had untolerated taint(s). no new claims to deallocate, preemption: 0/6 nodes are available: 1 No preemption victims found for incoming pod, 5 Preemption is not helpful for scheduling."
60.224,Event,ADDED,eval-sanitize-3-r3-018-gz22z.18d3d2f91e7dd272,reason=Scheduled count=None msg=Successfully assigned compute/eval-sanitize-3-r3-018-gz22z to kind-worker3
60.2243,Event,ADDED,eval-sanitize-3-r3-018-gz22z.18d3d2f937d8ae5f,"reason=Pulled count=1 msg=Container image ""busybox:musl"" already present on machine"
60.2246,Event,ADDED,eval-sanitize-3-r3-018-gz22z.18d3d2f9391f2525,reason=Created count=1 msg=Created container: task
60.2254,Job,ADDED,eval-sanitize-3-r3-052,
60.2258,Event,ADDED,eval-sanitize-3-r3-018-gz22z.18d3d2f93dc3be7a,reason=Started count=1 msg=Started container task
60.226,Event,ADDED,eval-sanitize-3-r3-018.18d3d2f8fb70ca74,reason=SuccessfulCreate count=1 msg=Created pod: eval-sanitize-3-r3-018-gz22z
60.2265,Event,ADDED,eval-sanitize-3-r3-018.18d3d2fc58eaf893,reason=Completed count=1 msg=Job completed
60.2287,Pod,ADDED,eval-sanitize-3-r3-043-kslkf,phase=Succeeded node=kind-worker
60.2291,Event,ADDED,eval-sanitize-3-r3-019-svm65.18d3d2f936e6f69f,"reason=FailedScheduling count=None msg=0/6 nodes are available: 2 c_wall violated: 1 conflicting context pair(s) with node memory, 4 node(s) had untolerated taint(s). no new claims to deallocate, preemption: 0/6 nodes are available: 2 No preemption victims found for incoming pod, 4 Preemption is not helpful for scheduling."
60.2294,Event,ADDED,eval-sanitize-3-r3-019-svm65.18d3d2f937a0dbab,"reason=FailedScheduling count=None msg=0/6 nodes are available: 2 c_wall violated: 1 conflicting context pair(s) with node memory, 4 node(s) had untolerated taint(s). no new claims to deallocate, preemption: 0/6 nodes are available: 2 No preemption victims found for incoming pod, 4 Preemption is not helpful for scheduling."
60.2297,Event,ADDED,eval-sanitize-3-r3-019-svm65.18d3d2f940becdfb,"reason=FailedScheduling count=None msg=0/6 nodes are available: 1 c_wall violated: 1 conflicting context pair(s) with node memory, 5 node(s) had untolerated taint(s). no new claims to deallocate, preemption: 0/6 nodes are available: 1 No preemption victims found for incoming pod, 5 Preemption is not helpful for scheduling."
60.2309,Pod,ADDED,eval-sanitize-3-r3-044-fvf52,phase=Succeeded node=kind-worker
60.2316,Job,ADDED,eval-sanitize-3-r3-053,
60.232,Event,ADDED,eval-sanitize-3-r3-019-svm65.18d3d2f98a375638,reason=Scheduled count=None msg=Successfully assigned compute/eval-sanitize-3-r3-019-svm65 to kind-worker5
60.2323,Event,ADDED,eval-sanitize-3-r3-019-svm65.18d3d2f9a280b781,"reason=Pulled count=1 msg=Container image ""busybox:musl"" already present on machine"
60.2326,Event,ADDED,eval-sanitize-3-r3-019-svm65.18d3d2f9a3b14be0,reason=Created count=1 msg=Created container: task
60.2328,Event,ADDED,eval-sanitize-3-r3-019-svm65.18d3d2f9a7e79d15,reason=Started count=1 msg=Started container task
60.2331,Event,ADDED,eval-sanitize-3-r3-019.18d3d2f936796eeb,reason=SuccessfulCreate count=1 msg=Created pod: eval-sanitize-3-r3-019-svm65
60.2334,Event,ADDED,eval-sanitize-3-r3-019.18d3d2fcce0979c7,reason=Completed count=1 msg=Job completed
60.2336,Event,ADDED,eval-sanitize-3-r3-020-7xstb.18d3d2f9728f8968,reason=Scheduled count=None msg=Successfully assigned compute/eval-sanitize-3-r3-020-7xstb to kind-worker3
60.2341,Event,ADDED,eval-sanitize-3-r3-020-7xstb.18d3d2f98b9d6a0d,"reason=Pulled count=1 msg=Container image ""busybox:musl"" already present on machine"
60.2356,Pod,ADDED,eval-sanitize-3-r3-045-vpnjr,phase=Succeeded node=kind-worker
60.2364,Job,ADDED,eval-sanitize-3-r3-054,
60.2368,Event,ADDED,eval-sanitize-3-r3-020-7xstb.18d3d2f98cfab1dc,reason=Created count=1 msg=Created container: task
60.2371,Event,ADDED,eval-sanitize-3-r3-020-7xstb.18d3d2f9917c6896,reason=Started count=1 msg=Started container task
60.2373,Event,ADDED,eval-sanitize-3-r3-020.18d3d2f971f2d5a8,reason=SuccessfulCreate count=1 msg=Created pod: eval-sanitize-3-r3-020-7xstb
60.2388,Pod,ADDED,eval-sanitize-3-r3-046-6px6g,phase=Succeeded node=kind-worker4
60.2391,Event,ADDED,eval-sanitize-3-r3-020.18d3d2fccb2380bc,reason=Completed count=1 msg=Job completed
60.2394,Event,ADDED,eval-sanitize-3-r3-021-nbbns.18d3d2f9aea6f944,reason=Scheduled count=None msg=Successfully assigned compute/eval-sanitize-3-r3-021-nbbns to kind-worker3
60.2396,Event,ADDED,eval-sanitize-3-r3-021-nbbns.18d3d2f9c8ca68fa,"reason=Pulled count=1 msg=Container image ""busybox:musl"" already present on machine"
60.2398,Event,ADDED,eval-sanitize-3-r3-021-nbbns.18d3d2f9c9fdadb1,reason=Created count=1 msg=Created container: task
60.2407,Job,ADDED,eval-sanitize-3-r3-055,
60.241,Event,ADDED,eval-sanitize-3-r3-021-nbbns.18d3d2f9cc02d182,reason=Started count=1 msg=Started container task
60.2412,Event,ADDED,eval-sanitize-3-r3-021.18d3d2f9adfcfbe8,reason=SuccessfulCreate count=1 msg=Created pod: eval-sanitize-3-r3-021-nbbns
60.2414,Event,ADDED,eval-sanitize-3-r3-021.18d3d2fd07682b4f,reason=Completed count=1 msg=Job completed
60.2416,Event,ADDED,eval-sanitize-3-r3-022-xkvgt.18d3d2f9e9ab2580,"reason=FailedScheduling count=None msg=0/6 nodes are available: 1 c_wall violated: 1 conflicting context pair(s) with node memory, 5 node(s) had untolerated taint(s). no new claims to deallocate, preemption: 0/6 nodes are available: 1 No preemption victims found for incoming pod, 5 Preemption is not helpful for scheduling."
60.2454,Pod,ADDED,eval-sanitize-3-r3-047-jkxpc,phase=Succeeded node=kind-worker4
60.246,Job,ADDED,eval-sanitize-3-r3-056,
60.2463,Event,ADDED,eval-sanitize-3-r3-022-xkvgt.18d3d2f9ea4069b7,"reason=FailedScheduling count=None msg=0/6 nodes are available: 1 c_wall violated: 1 conflicting context pair(s) with node memory, 5 node(s) had untolerated taint(s). no new claims to deallocate, preemption: 0/6 nodes are available: 1 No preemption victims found for incoming pod, 5 Preemption is not helpful for scheduling."
60.2465,Event,ADDED,eval-sanitize-3-r3-022-xkvgt.18d3d2fb3de748ec,reason=Scheduled count=None msg=Successfully assigned compute/eval-sanitize-3-r3-022-xkvgt to kind-worker2
60.2467,Event,ADDED,eval-sanitize-3-r3-022-xkvgt.18d3d2fb58d48720,"reason=Pulled count=1 msg=Container image ""busybox:musl"" already present on machine"
60.2479,Pod,ADDED,eval-sanitize-3-r3-048-r5xt9,phase=Running node=kind-worker3
60.2482,Event,ADDED,eval-sanitize-3-r3-022-xkvgt.18d3d2fb5a9cac9e,reason=Created count=1 msg=Created container: task
60.2484,Event,ADDED,eval-sanitize-3-r3-022-xkvgt.18d3d2fb5ee6a03d,reason=Started count=1 msg=Started container task
60.2485,Event,ADDED,eval-sanitize-3-r3-022.18d3d2f9e96575df,reason=SuccessfulCreate count=1 msg=Created pod: eval-sanitize-3-r3-022-xkvgt
60.2487,Event,ADDED,eval-sanitize-3-r3-022.18d3d2fea0a08d15,reason=Completed count=1 msg=Job completed
60.2493,Job,ADDED,eval-sanitize-3-r3-057,
60.2505,Pod,ADDED,eval-sanitize-3-r3-049-kqlvx,phase=Running node=kind-worker4
60.2509,Event,ADDED,eval-sanitize-3-r3-023-7hhqc.18d3d2fa25db21af,"reason=FailedScheduling count=None msg=0/6 nodes are available: 1 c_wall violated: 1 conflicting context pair(s) with node memory, 5 node(s) had untolerated taint(s). no new claims to deallocate, preemption: 0/6 nodes are available: 1 No preemption victims found for incoming pod, 5 Preemption is not helpful for scheduling."
60.2512,Event,ADDED,eval-sanitize-3-r3-023-7hhqc.18d3d2fa267e15ee,"reason=FailedScheduling count=None msg=0/6 nodes are available: 1 c_wall violated: 1 conflicting context pair(s) with node memory, 5 node(s) had untolerated taint(s). no new claims to deallocate, preemption: 0/6 nodes are available: 1 No preemption victims found for incoming pod, 5 Preemption is not helpful for scheduling."
60.2513,Event,ADDED,eval-sanitize-3-r3-023-7hhqc.18d3d2fb3dcd2055,"reason=FailedScheduling count=None msg=0/6 nodes are available: 1 c_wall violated: 1 conflicting context pair(s) with node memory, 5 node(s) had untolerated taint(s). no new claims to deallocate, preemption: 0/6 nodes are available: 1 No preemption victims found for incoming pod, 5 Preemption is not helpful for scheduling."
60.2523,Job,ADDED,eval-sanitize-3-r3-058,
60.2535,Pod,ADDED,eval-sanitize-3-r3-050-txwpj,phase=Running node=kind-worker3
60.254,Event,ADDED,eval-sanitize-3-r3-023-7hhqc.18d3d2fb3fa412c9,"reason=FailedScheduling count=None msg=0/6 nodes are available: 1 c_wall violated: 1 conflicting context pair(s) with node memory, 5 node(s) had untolerated taint(s). no new claims to deallocate, preemption: 0/6 nodes are available: 1 No preemption victims found for incoming pod, 5 Preemption is not helpful for scheduling."
60.2543,Event,ADDED,eval-sanitize-3-r3-023-7hhqc.18d3d2fc0888742e,"reason=FailedScheduling count=None msg=0/6 nodes are available: 1 c_wall violated: 1 conflicting context pair(s) with node memory, 5 node(s) had untolerated taint(s). no new claims to deallocate, preemption: 0/6 nodes are available: 1 No preemption victims found for incoming pod, 5 Preemption is not helpful for scheduling."
60.2545,Event,ADDED,eval-sanitize-3-r3-023-7hhqc.18d3d2fc09eac443,"reason=FailedScheduling count=None msg=0/6 nodes are available: 1 c_wall violated: 2 conflicting context pair(s) with node memory, 5 node(s) had untolerated taint(s). no new claims to deallocate, preemption: 0/6 nodes are available: 1 No preemption victims found for incoming pod, 5 Preemption is not helpful for scheduling."
60.2549,Event,ADDED,eval-sanitize-3-r3-023-7hhqc.18d3d2fc0c625624,"reason=FailedScheduling count=None msg=0/6 nodes are available: 1 c_wall violated: 2 conflicting context pair(s) with node memory, 5 node(s) had untolerated taint(s). no new claims to deallocate, preemption: 0/6 nodes are available: 1 No preemption victims found for incoming pod, 5 Preemption is not helpful for scheduling."
60.2552,Event,ADDED,eval-sanitize-3-r3-023-7hhqc.18d3d2fc2be15147,"reason=FailedScheduling count=None msg=0/6 nodes are available: 1 c_wall violated: 1 conflicting context pair(s) with node memory, 1 c_wall violated: 2 conflicting context pair(s) with node memory, 4 node(s) had untolerated taint(s). no new claims to deallocate, preemption: 0/6 nodes are available: 2 No preemption victims found for incoming pod, 4 Preemption is not helpful for scheduling."
60.2558,Job,ADDED,eval-sanitize-3-r3-059,
60.2563,Job,ADDED,eval-sanitize-3-r3-060,
60.2567,Event,ADDED,eval-sanitize-3-r3-023-7hhqc.18d3d2fc42a1bfd0,"reason=FailedScheduling count=None msg=0/6 nodes are available: 2 c_wall violated: 2 conflicting context pair(s) with node memory, 4 node(s) had untolerated taint(s). no new claims to deallocate, preemption: 0/6 nodes are available: 2 No preemption victims found for incoming pod, 4 Preemption is not helpful for scheduling."
60.257,Event,ADDED,eval-sanitize-3-r3-023-7hhqc.18d3d2fcc1b042d9,"reason=FailedScheduling count=None msg=0/6 nodes are available: 1 c_wall violated: 2 conflicting context pair(s) with node memory, 5 node(s) had untolerated taint(s). no new claims to deallocate, preemption: 0/6 nodes are available: 1 No preemption victims found for incoming pod, 5 Preemption is not helpful for scheduling."
60.2573,Event,ADDED,eval-sanitize-3-r3-023-7hhqc.18d3d2fcd2ff5350,reason=Scheduled count=None msg=Successfully assigned compute/eval-sanitize-3-r3-023-7hhqc to kind-worker3
60.2575,Event,ADDED,eval-sanitize-3-r3-023-7hhqc.18d3d2fcec080a19,"reason=Pulled count=1 msg=Container image ""busybox:musl"" already present on machine"
60.2589,Pod,ADDED,eval-sanitize-3-r3-051-zkrvm,phase=Running node=kind-worker3
60.2593,Event,ADDED,eval-sanitize-3-r3-023-7hhqc.18d3d2fced77392c,reason=Created count=1 msg=Created container: task
60.2596,Event,ADDED,eval-sanitize-3-r3-023-7hhqc.18d3d2fcf118284a,reason=Started count=1 msg=Started container task
60.2599,Event,ADDED,eval-sanitize-3-r3-023.18d3d2fa258353c2,reason=SuccessfulCreate count=1 msg=Created pod: eval-sanitize-3-r3-023-7hhqc
60.2607,Job,MODIFIED,eval-sanitize-3-r3-059,
60.262,Pod,ADDED,eval-sanitize-3-r3-052-qdx5l,phase=Running node=kind-worker5
60.2623,Event,ADDED,eval-sanitize-3-r3-023.18d3d30010a649fa,reason=Completed count=1 msg=Job completed
60.2624,Event,ADDED,eval-sanitize-3-r3-024-7gkdr.18d3d2fa6086a1d2,"reason=FailedScheduling count=None msg=0/6 nodes are available: 6 node(s) had untolerated taint(s). no new claims to deallocate, preemption: 0/6 nodes are available: 6 Preemption is not helpful for scheduling."
60.2626,Event,ADDED,eval-sanitize-3-r3-024-7gkdr.18d3d2fb3ebda829,reason=Scheduled count=None msg=Successfully assigned compute/eval-sanitize-3-r3-024-7gkdr to kind-worker2
60.2628,Event,ADDED,eval-sanitize-3-r3-024-7gkdr.18d3d2fb59d7edc3,"reason=Pulled count=1 msg=Container image ""busybox:musl"" already present on machine"
60.2635,Job,MODIFIED,eval-sanitize-3-r3-060,
60.2638,Event,ADDED,eval-sanitize-3-r3-024-7gkdr.18d3d2fb5d02b87e,reason=Created count=1 msg=Created container: task
60.2642,Event,ADDED,eval-sanitize-3-r3-024-7gkdr.18d3d2fb602f3601,reason=Started count=1 msg=Started container task
60.2645,Event,ADDED,eval-sanitize-3-r3-024.18d3d2fa6088a001,reason=SuccessfulCreate count=1 msg=Created pod: eval-sanitize-3-r3-024-7gkdr
60.2648,Event,ADDED,eval-sanitize-3-r3-024.18d3d2fea0fecd54,reason=Completed count=1 msg=Job completed
60.2661,Pod,ADDED,eval-sanitize-3-r3-053-f45f7,phase=Running node=kind-worker5
60.2664,Event,ADDED,eval-sanitize-3-r3-025-mtstx.18d3d2fa9c2e15ad,"reason=FailedScheduling count=None msg=0/6 nodes are available: 6 node(s) had untolerated taint(s). no new claims to deallocate, preemption: 0/6 nodes are available: 6 Preemption is not helpful for scheduling."
60.2666,Event,ADDED,eval-sanitize-3-r3-025-mtstx.18d3d2fb3ee2c4b9,reason=Scheduled count=None msg=Successfully assigned compute/eval-sanitize-3-r3-025-mtstx to kind-worker2
60.2668,Event,ADDED,eval-sanitize-3-r3-025-mtstx.18d3d2fb5a1fbb7a,"reason=Pulled count=1 msg=Container image ""busybox:musl"" already present on machine"
60.2682,Pod,ADDED,eval-sanitize-3-r3-054-mhh2r,phase=Running node=kind-worker5
60.269,Job,MODIFIED,eval-sanitize-3-r3-059,
60.2693,Event,ADDED,eval-sanitize-3-r3-025-mtstx.18d3d2fb5d898675,reason=Created count=1 msg=Created container: task
60.2696,Event,ADDED,eval-sanitize-3-r3-025-mtstx.18d3d2fb60a470d2,reason=Started count=1 msg=Started container task
60.2699,Event,ADDED,eval-sanitize-3-r3-025.18d3d2fa9c1dde3b,reason=SuccessfulCreate count=1 msg=Created pod: eval-sanitize-3-r3-025-mtstx
60.2703,Event,ADDED,eval-sanitize-3-r3-025.18d3d2fea16e4a97,reason=Completed count=1 msg=Job completed
60.2706,Event,ADDED,eval-sanitize-3-r3-026-mmf5k.18d3d2fad7bdd2f1,"reason=FailedScheduling count=None msg=0/6 nodes are available: 6 node(s) had untolerated taint(s). no new claims to deallocate, preemption: 0/6 nodes are available: 6 Preemption is not helpful for scheduling."
60.2708,Event,ADDED,eval-sanitize-3-r3-026-mmf5k.18d3d2fb3ebf9163,"reason=FailedScheduling count=None msg=0/6 nodes are available: 1 c_wall violated: 2 conflicting context pair(s) with node memory, 5 node(s) had untolerated taint(s). no new claims to deallocate, preemption: 0/6 nodes are available: 1 No preemption victims found for incoming pod, 5 Preemption is not helpful for scheduling."
60.2711,Event,ADDED,eval-sanitize-3-r3-026-mmf5k.18d3d2fb41ecdb5f,"reason=FailedScheduling count=None msg=0/6 nodes are available: 1 c_wall violated: 2 conflicting context pair(s) with node memory, 5 node(s) had untolerated taint(s). no new claims to deallocate, preemption: 0/6 nodes are available: 1 No preemption victims found for incoming pod, 5 Preemption is not helpful for scheduling."
60.2725,Pod,ADDED,eval-sanitize-3-r3-055-26snf,phase=Running node=kind-worker2
60.2729,Event,ADDED,eval-sanitize-3-r3-026-mmf5k.18d3d2fc08a2794a,reason=Scheduled count=None msg=Successfully assigned compute/eval-sanitize-3-r3-026-mmf5k to kind-worker
60.2732,Event,ADDED,eval-sanitize-3-r3-026-mmf5k.18d3d2fc28099e61,"reason=Pulled count=1 msg=Container image ""busybox:musl"" already present on machine"
60.2736,Event,ADDED,eval-sanitize-3-r3-026-mmf5k.18d3d2fc295299eb,reason=Created count=1 msg=Created container: task
60.2755,Pod,ADDED,eval-sanitize-3-r3-056-kbj7h,phase=Running node=kind-worker2
60.276,Event,ADDED,eval-sanitize-3-r3-026-mmf5k.18d3d2fc2bc72a23,reason=Started count=1 msg=Started container task
60.2763,Event,ADDED,eval-sanitize-3-r3-026.18d3d2fad7b18e41,reason=SuccessfulCreate count=1 msg=Created pod: eval-sanitize-3-r3-026-mmf5k
60.2766,Event,ADDED,eval-sanitize-3-r3-026.18d3d2ff3cb0c19c,reason=Completed count=1 msg=Job completed
60.2769,Event,ADDED,eval-sanitize-3-r3-027-4wfbw.18d3d2fb1358c118,"reason=FailedScheduling count=None msg=0/6 nodes are available: 6 node(s) had untolerated taint(s). no new claims to deallocate, preemption: 0/6 nodes are available: 6 Preemption is not helpful for scheduling."
60.2791,Pod,ADDED,eval-sanitize-3-r3-057-hqpsj,phase=Pending node=kind-worker
60.2794,Event,ADDED,eval-sanitize-3-r3-027-4wfbw.18d3d2fb3ff0648f,reason=Scheduled count=None msg=Successfully assigned compute/eval-sanitize-3-r3-027-4wfbw to kind-worker2
60.2796,Event,ADDED,eval-sanitize-3-r3-027-4wfbw.18d3d2fb5a98dfde,"reason=Pulled count=1 msg=Container image ""busybox:musl"" already present on machine"
60.2798,Event,ADDED,eval-sanitize-3-r3-027-4wfbw.18d3d2fb5dbab45b,reason=Created count=1 msg=Created container: task
60.2799,Event,ADDED,eval-sanitize-3-r3-027-4wfbw.18d3d2fb60a470eb,reason=Started count=1 msg=Started container task
60.2808,Pod,ADDED,eval-sanitize-3-r3-058-8l6ds,phase=Pending node=None
60.2812,Event,ADDED,eval-sanitize-3-r3-027.18d3d2fb134ea03c,reason=SuccessfulCreate count=1 msg=Created pod: eval-sanitize-3-r3-027-4wfbw
60.2815,Event,ADDED,eval-sanitize-3-r3-027.18d3d2fea1dc2895,reason=Completed count=1 msg=Job completed
60.2818,Event,ADDED,eval-sanitize-3-r3-028-cq5fx.18d3d2fb50d7971a,reason=Scheduled count=None msg=Successfully assigned compute/eval-sanitize-3-r3-028-cq5fx to kind-worker2
60.2831,Pod,ADDED,eval-sanitize-3-r3-059-wtxpj,phase=Pending node=kind-worker2
60.2834,Event,ADDED,eval-sanitize-3-r3-028-cq5fx.18d3d2fb69cb7052,"reason=Pulled count=1 msg=Container image ""busybox:musl"" already present on machine"
60.2837,Event,ADDED,eval-sanitize-3-r3-028-cq5fx.18d3d2fb6af0a09b,reason=Created count=1 msg=Created container: task
60.284,Event,ADDED,eval-sanitize-3-r3-028-cq5fx.18d3d2fb6ec44a5f,reason=Started count=1 msg=Started container task
60.2844,Event,ADDED,eval-sanitize-3-r3-028.18d3d2fb501fbe16,reason=SuccessfulCreate count=1 msg=Created pod: eval-sanitize-3-r3-028-cq5fx
60.2848,Event,ADDED,eval-sanitize-3-r3-028.18d3d2fea22594c5,reason=Completed count=1 msg=Job completed
60.285,Event,ADDED,eval-sanitize-3-r3-029-8klt2.18d3d2fb8ab9a8ae,"reason=FailedScheduling count=None msg=0/6 nodes are available: 1 c_wall violated: 2 conflicting context pair(s) with node memory, 5 node(s) had untolerated taint(s). no new claims to deallocate, preemption: 0/6 nodes are available: 1 No preemption victims found for incoming pod, 5 Preemption is not helpful for scheduling."
60.2853,Event,ADDED,eval-sanitize-3-r3-029-8klt2.18d3d2fb8b369acc,"reason=FailedScheduling count=None msg=0/6 nodes are available: 1 c_wall violated: 2 conflicting context pair(s) with node memory, 5 node(s) had untolerated taint(s). no new claims to deallocate, preemption: 0/6 nodes are available: 1 No preemption victims found for incoming pod, 5 Preemption is not helpful for scheduling."
60.2861,Pod,ADDED,eval-sanitize-3-r3-060-jbqts,phase=Pending node=None
60.2864,Event,ADDED,eval-sanitize-3-r3-029-8klt2.18d3d2fc08a2e152,reason=Scheduled count=None msg=Successfully assigned compute/eval-sanitize-3-r3-029-8klt2 to kind-worker
60.2867,Event,ADDED,eval-sanitize-3-r3-029-8klt2.18d3d2fc25537db2,"reason=Pulled count=1 msg=Container image ""busybox:musl"" already present on machine"
60.287,Event,ADDED,eval-sanitize-3-r3-029-8klt2.18d3d2fc26ee3e0e,reason=Created count=1 msg=Created container: task
60.2872,Event,ADDED,eval-sanitize-3-r3-029-8klt2.18d3d2fc2b09ba41,reason=Started count=1 msg=Started container task
60.2876,Event,ADDED,eval-sanitize-3-r3-029.18d3d2fb8a7635f6,reason=SuccessfulCreate count=1 msg=Created pod: eval-sanitize-3-r3-029-8klt2
60.2878,Event,ADDED,eval-sanitize-3-r3-029.18d3d2ff3c51d285,reason=Completed count=1 msg=Job completed
60.2881,Event,ADDED,eval-sanitize-3-r3-030-rddvq.18d3d2fbd2021725,"reason=FailedScheduling count=None msg=0/6 nodes are available: 1 c_wall violated: 2 conflicting context pair(s) with node memory, 5 node(s) had untolerated taint(s). no new claims to deallocate, preemption: 0/6 nodes are available: 1 No preemption victims found for incoming pod, 5 Preemption is not helpful for scheduling."
60.289,Pod,MODIFIED,eval-sanitize-3-r3-060-jbqts,phase=Pending node=None
60.2893,Event,ADDED,eval-sanitize-3-r3-030-rddvq.18d3d2fbd2831ba9,"reason=FailedScheduling count=None msg=0/6 nodes are available: 1 c_wall violated: 2 conflicting context pair(s) with node memory, 5 node(s) had untolerated taint(s). no new claims to deallocate, preemption: 0/6 nodes are available: 1 No preemption victims found for incoming pod, 5 Preemption is not helpful for scheduling."
60.2895,Event,ADDED,eval-sanitize-3-r3-030-rddvq.18d3d2fc09a777fb,reason=Scheduled count=None msg=Successfully assigned compute/eval-sanitize-3-r3-030-rddvq to kind-worker
60.2896,Event,ADDED,eval-sanitize-3-r3-030-rddvq.18d3d2fc29db2413,"reason=Pulled count=1 msg=Container image ""busybox:musl"" already present on machine"
60.2898,Event,ADDED,eval-sanitize-3-r3-030-rddvq.18d3d2fc2b4c750f,reason=Created count=1 msg=Created container: task
60.2902,Event,ADDED,eval-sanitize-3-r3-030-rddvq.18d3d2fc2d66cc8a,reason=Started count=1 msg=Started container task
60.2906,Event,ADDED,eval-sanitize-3-r3-030.18d3d2fbd1cb5bc2,reason=SuccessfulCreate count=1 msg=Created pod: eval-sanitize-3-r3-030-rddvq
60.291,Event,ADDED,eval-sanitize-3-r3-030.18d3d2ff782748a8,reason=Completed count=1 msg=Job completed
60.2915,Event,ADDED,eval-sanitize-3-r3-031-4fnvg.18d3d2fc04477fe8,"reason=FailedScheduling count=None msg=0/6 nodes are available: 6 node(s) had untolerated taint(s). no new claims to deallocate, preemption: 0/6 nodes are available: 6 Preemption is not helpful for scheduling."
60.2916,Event,ADDED,eval-sanitize-3-r3-031-4fnvg.18d3d2fc09497957,"reason=FailedScheduling count=None msg=0/6 nodes are available: 1 c_wall violated: 1 conflicting context pair(s) with node memory, 5 node(s) had untolerated taint(s). no new claims to deallocate, preemption: 0/6 nodes are available: 1 No preemption victims found for incoming pod, 5 Preemption is not helpful for scheduling."
60.292,Event,ADDED,eval-sanitize-3-r3-031-4fnvg.18d3d2fc0a8298d2,"reason=FailedScheduling count=None msg=0/6 nodes are available: 1 c_wall violated: 1 conflicting context pair(s) with node memory, 5 node(s) had untolerated taint(s). no new claims to deallocate, preemption: 0/6 nodes are available: 1 No preemption victims found for incoming pod, 5 Preemption is not helpful for scheduling."
60.2922,Event,ADDED,eval-sanitize-3-r3-031-4fnvg.18d3d2fc277eeae0,reason=Scheduled count=None msg=Successfully assigned compute/eval-sanitize-3-r3-031-4fnvg to kind-worker4
60.2925,Event,ADDED,eval-sanitize-3-r3-031-4fnvg.18d3d2fc42782e70,"reason=Pulled count=1 msg=Container image ""busybox:musl"" already present on machine"
60.2927,Event,ADDED,eval-sanitize-3-r3-031-4fnvg.18d3d2fc43a72066,reason=Created count=1 msg=Created container: task
60.2929,Event,ADDED,eval-sanitize-3-r3-031-4fnvg.18d3d2fc459c81de,reason=Started count=1 msg=Started container task
60.2933,Event,ADDED,eval-sanitize-3-r3-031.18d3d2fc043a7172,reason=SuccessfulCreate count=1 msg=Created pod: eval-sanitize-3-r3-031-4fnvg
60.2935,Event,ADDED,eval-sanitize-3-r3-031.18d3d2ff5c0b1d42,reason=Completed count=1 msg=Job completed
60.2937,Event,ADDED,eval-sanitize-3-r3-032-ps7mn.18d3d2fc3e8af23c,reason=Scheduled count=None msg=Successfully assigned compute/eval-sanitize-3-r3-032-ps7mn to kind-worker4
60.294,Event,ADDED,eval-sanitize-3-r3-032-ps7mn.18d3d2fc5a0e190a,"reason=Pulled count=1 msg=Container image ""busybox:musl"" already present on machine"
60.2945,Event,ADDED,eval-sanitize-3-r3-032-ps7mn.18d3d2fc5b74cea7,reason=Created count=1 msg=Created container: task
60.2948,Event,ADDED,eval-sanitize-3-r3-032-ps7mn.18d3d2fc6007ccfc,reason=Started count=1 msg=Started container task
60.295,Event,ADDED,eval-sanitize-3-r3-032.18d3d2fc3d58c3b7,reason=SuccessfulCreate count=1 msg=Created pod: eval-sanitize-3-r3-032-ps7mn
60.2953,Event,ADDED,eval-sanitize-3-r3-032.18d3d2ff97b4a80a,reason=Completed count=1 msg=Job completed
60.2956,Event,ADDED,eval-sanitize-3-r3-033-zv46r.18d3d2fc798aaddc,reason=Scheduled count=None msg=Successfully assigned compute/eval-sanitize-3-r3-033-zv46r to kind-worker
60.2959,Event,ADDED,eval-sanitize-3-r3-033-zv46r.18d3d2fc96653d98,"reason=Pulled count=1 msg=Container image ""busybox:musl"" already present on machine"
60.2962,Event,ADDED,eval-sanitize-3-r3-033-zv46r.18d3d2fc9784361a,reason=Created count=1 msg=Created container: task
60.2966,Event,ADDED,eval-sanitize-3-r3-033-zv46r.18d3d2fc9bef4d2d,reason=Started count=1 msg=Started container task
60.2969,Event,ADDED,eval-sanitize-3-r3-033.18d3d2fc78a70d8c,reason=SuccessfulCreate count=1 msg=Created pod: eval-sanitize-3-r3-033-zv46r
60.2971,Event,ADDED,eval-sanitize-3-r3-033.18d3d2ffb408a6c8,reason=Completed count=1 msg=Job completed
60.2974,Event,ADDED,eval-sanitize-3-r3-034-fsqln.18d3d2fcb4edb394,"reason=FailedScheduling count=None msg=0/6 nodes are available: 2 c_wall violated: 2 conflicting context pair(s) with node memory, 4 node(s) had untolerated taint(s). no new claims to deallocate, preemption: 0/6 nodes are available: 2 No preemption victims found for incoming pod, 4 Preemption is not helpful for scheduling."
60.2978,Event,ADDED,eval-sanitize-3-r3-034-fsqln.18d3d2fcb59d3288,"reason=FailedScheduling count=None msg=0/6 nodes are available: 2 c_wall violated: 2 conflicting context pair(s) with node memory, 4 node(s) had untolerated taint(s). no new claims to deallocate, preemption: 0/6 nodes are available: 2 No preemption victims found for incoming pod, 4 Preemption is not helpful for scheduling."
60.298,Event,ADDED,eval-sanitize-3-r3-034-fsqln.18d3d2fcc1d55085,"reason=FailedScheduling count=None msg=0/6 nodes are available: 1 c_wall violated: 2 conflicting context pair(s) with node memory, 5 node(s) had untolerated taint(s). no new claims to deallocate, preemption: 0/6 nodes are available: 1 No preemption victims found for incoming pod, 5 Preemption is not helpful for scheduling."
60.2982,Event,ADDED,eval-sanitize-3-r3-034-fsqln.18d3d2fcd3626ab2,reason=Scheduled count=None msg=Successfully assigned compute/eval-sanitize-3-r3-034-fsqln to kind-worker3
60.2987,Event,ADDED,eval-sanitize-3-r3-034-fsqln.18d3d2fcec37cb1d,"reason=Pulled count=1 msg=Container image ""busybox:musl"" already present on machine"
60.299,Event,ADDED,eval-sanitize-3-r3-034-fsqln.18d3d2fcedd1184d,reason=Created count=1 msg=Created container: task
60.2992,Event,ADDED,eval-sanitize-3-r3-034-fsqln.18d3d2fcf178188e,reason=Started count=1 msg=Started container task
60.2996,Event,ADDED,eval-sanitize-3-r3-034.18d3d2fcb47fd2f4,reason=SuccessfulCreate count=1 msg=Created pod: eval-sanitize-3-r3-034-fsqln
60.2998,Event,ADDED,eval-sanitize-3-r3-034.18d3d3001030d47c,reason=Completed count=1 msg=Job completed
60.3,Event,ADDED,eval-sanitize-3-r3-035-6bmlr.18d3d2fcf100cc65,"reason=FailedScheduling count=None msg=0/6 nodes are available: 1 c_wall violated: 1 conflicting context pair(s) with node memory, 5 node(s) had untolerated taint(s). no new claims to deallocate, preemption: 0/6 nodes are available: 1 No preemption victims found for incoming pod, 5 Preemption is not helpful for scheduling."
60.3004,Event,ADDED,eval-sanitize-3-r3-035-6bmlr.18d3d2fcf1d41e5f,"reason=FailedScheduling count=None msg=0/6 nodes are available: 1 c_wall violated: 1 conflicting context pair(s) with node memory, 5 node(s) had untolerated taint(s). no new claims to deallocate, preemption: 0/6 nodes are available: 1 No preemption victims found for incoming pod, 5 Preemption is not helpful for scheduling."
60.3006,Event,ADDED,eval-sanitize-3-r3-035-6bmlr.18d3d2fd18f0bee0,reason=Scheduled count=None msg=Successfully assigned compute/eval-sanitize-3-r3-035-6bmlr to kind-worker5
60.3009,Event,ADDED,eval-sanitize-3-r3-035-6bmlr.18d3d2fd32864840,"reason=Pulled count=1 msg=Container image ""busybox:musl"" already present on machine"
60.3011,Event,ADDED,eval-sanitize-3-r3-035-6bmlr.18d3d2fd339d2433,reason=Created count=1 msg=Created container: task
60.3015,Event,ADDED,eval-sanitize-3-r3-035-6bmlr.18d3d2fd3577778c,reason=Started count=1 msg=Started container task
60.3018,Event,ADDED,eval-sanitize-3-r3-035.18d3d2fcf0b7367a,reason=SuccessfulCreate count=1 msg=Created pod: eval-sanitize-3-r3-035-6bmlr
60.3021,Event,ADDED,eval-sanitize-3-r3-035.18d3d3004e872ee6,reason=Completed count=1 msg=Job completed
60.3023,Event,ADDED,eval-sanitize-3-r3-036-4fnh6.18d3d2fd2c75b869,reason=Scheduled count=None msg=Successfully assigned compute/eval-sanitize-3-r3-036-4fnh6 to kind-worker3
60.3026,Event,ADDED,eval-sanitize-3-r3-036-4fnh6.18d3d2fd4520f026,"reason=Pulled count=1 msg=Container image ""busybox:musl"" already present on machine"
60.3029,Event,ADDED,eval-sanitize-3-r3-036-4fnh6.18d3d2fd4652b31c,reason=Created count=1 msg=Created container: task
60.3032,Event,ADDED,eval-sanitize-3-r3-036-4fnh6.18d3d2fd4a620bde,reason=Started count=1 msg=Started container task
60.3035,Event,ADDED,eval-sanitize-3-r3-036.18d3d2fd2ba0bc5d,reason=SuccessfulCreate count=1 msg=Created pod: eval-sanitize-3-r3-036-4fnh6
60.3041,Event,ADDED,eval-sanitize-3-r3-036.18d3d30088092d55,reason=Completed count=1 msg=Job completed
60.3044,Event,ADDED,eval-sanitize-3-r3-037-cw865.18d3d2fd67fdd3d9,reason=Scheduled count=None msg=Successfully assigned compute/eval-sanitize-3-r3-037-cw865 to kind-worker5
60.3047,Event,ADDED,eval-sanitize-3-r3-037-cw865.18d3d2fd813933a4,"reason=Pulled count=1 msg=Container image ""busybox:musl"" already present on machine"
60.3051,Event,ADDED,eval-sanitize-3-r3-037-cw865.18d3d2fd825b8b3c,reason=Created count=1 msg=Created container: task
60.3054,Event,ADDED,eval-sanitize-3-r3-037-cw865.18d3d2fd84322a6f,reason=Started count=1 msg=Started container task
60.3057,Event,ADDED,eval-sanitize-3-r3-037.18d3d2fd671a2279,reason=SuccessfulCreate count=1 msg=Created pod: eval-sanitize-3-r3-037-cw865
60.3059,Event,ADDED,eval-sanitize-3-r3-037.18d3d300c5de620e,reason=Completed count=1 msg=Job completed
60.3063,Event,ADDED,eval-sanitize-3-r3-038-vdkjz.18d3d2fda3451231,"reason=FailedScheduling count=None msg=0/6 nodes are available: 1 c_wall violated: 1 conflicting context pair(s) with node memory, 5 node(s) had untolerated taint(s). no new claims to deallocate, preemption: 0/6 nodes are available: 1 No preemption victims found for incoming pod, 5 Preemption is not helpful for scheduling."
60.3066,Event,ADDED,eval-sanitize-3-r3-038-vdkjz.18d3d2fda3c755b1,"reason=FailedScheduling count=None msg=0/6 nodes are available: 1 c_wall violated: 1 conflicting context pair(s) with node memory, 5 node(s) had untolerated taint(s). no new claims to deallocate, preemption: 0/6 nodes are available: 1 No preemption victims found for incoming pod, 5 Preemption is not helpful for scheduling."
60.3068,Event,ADDED,eval-sanitize-3-r3-038-vdkjz.18d3d2feeb6cb031,reason=Scheduled count=None msg=Successfully assigned compute/eval-sanitize-3-r3-038-vdkjz to kind-worker2
60.307,Event,ADDED,eval-sanitize-3-r3-038-vdkjz.18d3d2ff0ae86c69,"reason=Pulled count=1 msg=Container image ""busybox:musl"" already present on machine"
60.3073,Event,ADDED,eval-sanitize-3-r3-038-vdkjz.18d3d2ff0c2fa5de,reason=Created count=1 msg=Created container: task
60.3076,Event,ADDED,eval-sanitize-3-r3-038-vdkjz.18d3d2ff0f5930c1,reason=Started count=1 msg=Started container task
60.3079,Event,ADDED,eval-sanitize-3-r3-038.18d3d2fda303e98d,reason=SuccessfulCreate count=1 msg=Created pod: eval-sanitize-3-r3-038-vdkjz
60.3083,Event,ADDED,eval-sanitize-3-r3-038.18d3d30222ea7219,reason=Completed count=1 msg=Job completed
60.3085,Event,ADDED,eval-sanitize-3-r3-039-k4ldp.18d3d2fdde917336,"reason=FailedScheduling count=None msg=0/6 nodes are available: 6 node(s) had untolerated taint(s). no new claims to deallocate, preemption: 0/6 nodes are available: 6 Preemption is not helpful for scheduling."
60.3087,Event,ADDED,eval-sanitize-3-r3-039-k4ldp.18d3d2feec01c154,reason=Scheduled count=None msg=Successfully assigned compute/eval-sanitize-3-r3-039-k4ldp to kind-worker2
60.3091,Event,ADDED,eval-sanitize-3-r3-039-k4ldp.18d3d2ff0d8992f4,"reason=Pulled count=1 msg=Container image ""busybox:musl"" already present on machine"
60.3094,Event,ADDED,eval-sanitize-3-r3-039-k4ldp.18d3d2ff0f52a3bc,reason=Created count=1 msg=Created container: task
60.3097,Event,ADDED,eval-sanitize-3-r3-039-k4ldp.18d3d2ff13819d92,reason=Started count=1 msg=Started container task
60.31,Event,ADDED,eval-sanitize-3-r3-039.18d3d2fdde82b085,reason=SuccessfulCreate count=1 msg=Created pod: eval-sanitize-3-r3-039-k4ldp
60.3103,Event,ADDED,eval-sanitize-3-r3-039.18d3d3022231a662,reason=Completed count=1 msg=Job completed
60.3105,Event,ADDED,eval-sanitize-3-r3-040-55zl6.18d3d2fe1a0f7364,"reason=FailedScheduling count=None msg=0/6 nodes are available: 6 node(s) had untolerated taint(s). no new claims to deallocate, preemption: 0/6 nodes are available: 6 Preemption is not helpful for scheduling."
60.3108,Event,ADDED,eval-sanitize-3-r3-040-55zl6.18d3d2feec2b1793,reason=Scheduled count=None msg=Successfully assigned compute/eval-sanitize-3-r3-040-55zl6 to kind-worker2
60.311,Event,ADDED,eval-sanitize-3-r3-040-55zl6.18d3d2ff0de32468,"reason=Pulled count=1 msg=Container image ""busybox:musl"" already present on machine"
60.3114,Event,ADDED,eval-sanitize-3-r3-040-55zl6.18d3d2ff0fd0c7a9,reason=Created count=1 msg=Created container: task
60.3117,Event,ADDED,eval-sanitize-3-r3-040-55zl6.18d3d2ff14097e35,reason=Started count=1 msg=Started container task
60.312,Event,ADDED,eval-sanitize-3-r3-040.18d3d2fe19fd0c40,reason=SuccessfulCreate count=1 msg=Created pod: eval-sanitize-3-r3-040-55zl6
60.3124,Event,ADDED,eval-sanitize-3-r3-040.18d3d302220da249,reason=Completed count=1 msg=Job completed
60.3126,Event,ADDED,eval-sanitize-3-r3-041-c9zgv.18d3d2fe569e38c2,"reason=FailedScheduling count=None msg=0/6 nodes are available: 6 node(s) had untolerated taint(s). no new claims to deallocate, preemption: 0/6 nodes are available: 6 Preemption is not helpful for scheduling."
60.313,Event,ADDED,eval-sanitize-3-r3-041-c9zgv.18d3d2feecbdba13,reason=Scheduled count=None msg=Successfully assigned compute/eval-sanitize-3-r3-041-c9zgv to kind-worker2
60.3133,Event,ADDED,eval-sanitize-3-r3-041-c9zgv.18d3d2ff095c80bc,"reason=Pulled count=1 msg=Container image ""busybox:musl"" already present on machine"
60.3137,Event,ADDED,eval-sanitize-3-r3-041-c9zgv.18d3d2ff0b9402fa,reason=Created count=1 msg=Created container: task
60.314,Event,ADDED,eval-sanitize-3-r3-041-c9zgv.18d3d2ff0f59f351,reason=Started count=1 msg=Started container task
60.3142,Event,ADDED,eval-sanitize-3-r3-041.18d3d2fe56924c5c,reason=SuccessfulCreate count=1 msg=Created pod: eval-sanitize-3-r3-041-c9zgv
60.3145,Event,ADDED,eval-sanitize-3-r3-041.18d3d30222c7a634,reason=Completed count=1 msg=Job completed
60.3149,Event,ADDED,eval-sanitize-3-r3-042-bkwv9.18d3d2fe9206e381,"reason=FailedScheduling count=None msg=0/6 nodes are available: 6 node(s) had untolerated taint(s). no new claims to deallocate, preemption: 0/6 nodes are available: 6 Preemption is not helpful for scheduling."
60.3152,Event,ADDED,eval-sanitize-3-r3-042-bkwv9.18d3d2feecc01305,reason=Scheduled count=None msg=Successfully assigned compute/eval-sanitize-3-r3-042-bkwv9 to kind-worker2
60.3154,Event,ADDED,eval-sanitize-3-r3-042-bkwv9.18d3d2ff09437366,"reason=Pulled count=1 msg=Container image ""busybox:musl"" already present on machine"
60.3158,Event,ADDED,eval-sanitize-3-r3-042-bkwv9.18d3d2ff0ac6e026,reason=Created count=1 msg=Created container: task
60.3161,Event,ADDED,eval-sanitize-3-r3-042-bkwv9.18d3d2ff0e61d545,reason=Started count=1 msg=Started container task
60.3164,Event,ADDED,eval-sanitize-3-r3-042.18d3d2fe91f930c7,reason=SuccessfulCreate count=1 msg=Created pod: eval-sanitize-3-r3-042-bkwv9
60.3167,Event,ADDED,eval-sanitize-3-r3-042.18d3d30223b922ce,reason=Completed count=1 msg=Job completed
60.317,Event,ADDED,eval-sanitize-3-r3-043-kslkf.18d3d2fecce64f7a,"reason=FailedScheduling count=None msg=0/6 nodes are available: 6 node(s) had untolerated taint(s). no new claims to deallocate, preemption: 0/6 nodes are available: 6 Preemption is not helpful for scheduling."
60.3172,Event,ADDED,eval-sanitize-3-r3-043-kslkf.18d3d2feec65d571,"reason=FailedScheduling count=None msg=0/6 nodes are available: 1 c_wall violated: 2 conflicting context pair(s) with node memory, 5 node(s) had untolerated taint(s). no new claims to deallocate, preemption: 0/6 nodes are available: 1 No preemption victims found for incoming pod, 5 Preemption is not helpful for scheduling."
60.3174,Event,ADDED,eval-sanitize-3-r3-043-kslkf.18d3d2feed32875e,"reason=FailedScheduling count=None msg=0/6 nodes are available: 1 c_wall violated: 2 conflicting context pair(s) with node memory, 5 node(s) had untolerated taint(s). no new claims to deallocate, preemption: 0/6 nodes are available: 1 No preemption victims found for incoming pod, 5 Preemption is not helpful for scheduling."
60.3178,Event,ADDED,eval-sanitize-3-r3-043-kslkf.18d3d2ffb6bc2f1c,reason=Scheduled count=None msg=Successfully assigned compute/eval-sanitize-3-r3-043-kslkf to kind-worker
60.3181,Event,ADDED,eval-sanitize-3-r3-043-kslkf.18d3d2ffd13c36d8,"reason=Pulled count=1 msg=Container image ""busybox:musl"" already present on machine"
60.3184,Event,ADDED,eval-sanitize-3-r3-043-kslkf.18d3d2ffd2749c5a,reason=Created count=1 msg=Created container: task
60.3187,Event,ADDED,eval-sanitize-3-r3-043-kslkf.18d3d2ffd79af14f,reason=Started count=1 msg=Started container task
60.319,Event,ADDED,eval-sanitize-3-r3-043.18d3d2feccdb369d,reason=SuccessfulCreate count=1 msg=Created pod: eval-sanitize-3-r3-043-kslkf
60.3193,Event,ADDED,eval-sanitize-3-r3-044-fvf52.18d3d2ff0950fcae,"reason=FailedScheduling count=None msg=0/6 nodes are available: 1 c_wall violated: 2 conflicting context pair(s) with node memory, 5 node(s) had untolerated taint(s). no new claims to deallocate, preemption: 0/6 nodes are available: 1 No preemption victims found for incoming pod, 5 Preemption is not helpful for scheduling."
60.3196,Event,ADDED,eval-sanitize-3-r3-044-fvf52.18d3d2ff09eaa669,"reason=FailedScheduling count=None msg=0/6 nodes are available: 1 c_wall violated: 2 conflicting context pair(s) with node memory, 5 node(s) had untolerated taint(s). no new claims to deallocate, preemption: 0/6 nodes are available: 1 No preemption victims found for incoming pod, 5 Preemption is not helpful for scheduling."
60.3199,Event,ADDED,eval-sanitize-3-r3-044-fvf52.18d3d2ffb6fa995b,reason=Scheduled count=None msg=Successfully assigned compute/eval-sanitize-3-r3-044-fvf52 to kind-worker
60.3202,Event,ADDED,eval-sanitize-3-r3-044-fvf52.18d3d2ffd292183e,"reason=Pulled count=1 msg=Container image ""busybox:musl"" already present on machine"
60.3204,Event,ADDED,eval-sanitize-3-r3-044-fvf52.18d3d2ffd4abb6a2,reason=Created count=1 msg=Created container: task
60.3207,Event,ADDED,eval-sanitize-3-r3-044-fvf52.18d3d2ffd6e383c0,reason=Started count=1 msg=Started container task
60.3213,Event,ADDED,eval-sanitize-3-r3-044.18d3d2ff0912a786,reason=SuccessfulCreate count=1 msg=Created pod: eval-sanitize-3-r3-044-fvf52
60.3216,Event,ADDED,eval-sanitize-3-r3-045-vpnjr.18d3d2ff4437d8ca,"reason=FailedScheduling count=None msg=0/6 nodes are available: 1 c_wall violated: 2 conflicting context pair(s) with node memory, 5 node(s) had untolerated taint(s). no new claims to deallocate, preemption: 0/6 nodes are available: 1 No preemption victims found for incoming pod, 5 Preemption is not helpful for scheduling."
60.3219,Event,ADDED,eval-sanitize-3-r3-045-vpnjr.18d3d2ff44d8d1b0,"reason=FailedScheduling count=None msg=0/6 nodes are available: 1 c_wall violated: 2 conflicting context pair(s) with node memory, 5 node(s) had untolerated taint(s). no new claims to deallocate, preemption: 0/6 nodes are available: 1 No preemption victims found for incoming pod, 5 Preemption is not helpful for scheduling."
60.3223,Event,ADDED,eval-sanitize-3-r3-045-vpnjr.18d3d2ffb735b49d,reason=Scheduled count=None msg=Successfully assigned compute/eval-sanitize-3-r3-045-vpnjr to kind-worker
60.3225,Event,ADDED,eval-sanitize-3-r3-045-vpnjr.18d3d2ffd273bb4c,"reason=Pulled count=1 msg=Container image ""busybox:musl"" already present on machine"
60.3228,Event,ADDED,eval-sanitize-3-r3-045-vpnjr.18d3d2ffd42321f1,reason=Created count=1 msg=Created container: task
60.3232,Event,ADDED,eval-sanitize-3-r3-045-vpnjr.18d3d2ffd68aa67b,reason=Started count=1 msg=Started container task
60.3235,Event,ADDED,eval-sanitize-3-r3-045.18d3d2ff43fa9440,reason=SuccessfulCreate count=1 msg=Created pod: eval-sanitize-3-r3-045-vpnjr
60.3238,Event,ADDED,eval-sanitize-3-r3-046-6px6g.18d3d2ff7fe13520,"reason=FailedScheduling count=None msg=0/6 nodes are available: 1 c_wall violated: 1 conflicting context pair(s) with node memory, 5 node(s) had untolerated taint(s). no new claims to deallocate, preemption: 0/6 nodes are available: 1 No preemption victims found for incoming pod, 5 Preemption is not helpful for scheduling."
60.3242,Event,ADDED,eval-sanitize-3-r3-046-6px6g.18d3d2ff806e1249,"reason=FailedScheduling count=None msg=0/6 nodes are available: 1 c_wall violated: 1 conflicting context pair(s) with node memory, 5 node(s) had untolerated taint(s). no new claims to deallocate, preemption: 0/6 nodes are available: 1 No preemption victims found for incoming pod, 5 Preemption is not helpful for scheduling."
60.3245,Event,ADDED,eval-sanitize-3-r3-046-6px6g.18d3d2ffb704572c,"reason=FailedScheduling count=None msg=0/6 nodes are available: 1 c_wall violated: 1 conflicting context pair(s) with node memory, 5 node(s) had untolerated taint(s). no new claims to deallocate, preemption: 0/6 nodes are available: 1 No preemption victims found for incoming pod, 5 Preemption is not helpful for scheduling."
60.3249,Event,ADDED,eval-sanitize-3-r3-046-6px6g.18d3d2ffb81409ac,"reason=FailedScheduling count=None msg=0/6 nodes are available: 1 c_wall violated: 1 conflicting context pair(s) with node memory, 5 node(s) had untolerated taint(s). no new claims to deallocate, preemption: 0/6 nodes are available: 1 No preemption victims found for incoming pod, 5 Preemption is not helpful for scheduling."
60.3252,Event,ADDED,eval-sanitize-3-r3-046-6px6g.18d3d2ffd9114a04,reason=Scheduled count=None msg=Successfully assigned compute/eval-sanitize-3-r3-046-6px6g to kind-worker4
60.3255,Event,ADDED,eval-sanitize-3-r3-046-6px6g.18d3d2fff2281150,"reason=Pulled count=1 msg=Container image ""busybox:musl"" already present on machine"
60.3258,Event,ADDED,eval-sanitize-3-r3-046-6px6g.18d3d2fff343606b,reason=Created count=1 msg=Created container: task
60.3261,Event,ADDED,eval-sanitize-3-r3-046-6px6g.18d3d2fff54b3327,reason=Started count=1 msg=Started container task
60.3266,Event,ADDED,eval-sanitize-3-r3-046.18d3d2ff7fa6a7d5,reason=SuccessfulCreate count=1 msg=Created pod: eval-sanitize-3-r3-046-6px6g
60.3269,Event,ADDED,eval-sanitize-3-r3-047-jkxpc.18d3d2ffbb8d5891,"reason=FailedScheduling count=None msg=0/6 nodes are available: 1 c_wall violated: 1 conflicting context pair(s) with node memory, 5 node(s) had untolerated taint(s). no new claims to deallocate, preemption: 0/6 nodes are available: 1 No preemption victims found for incoming pod, 5 Preemption is not helpful for scheduling."
60.3272,Event,ADDED,eval-sanitize-3-r3-047-jkxpc.18d3d2ffbbfc89bb,"reason=FailedScheduling count=None msg=0/6 nodes are available: 1 c_wall violated: 1 conflicting context pair(s) with node memory, 5 node(s) had untolerated taint(s). no new claims to deallocate, preemption: 0/6 nodes are available: 1 No preemption victims found for incoming pod, 5 Preemption is not helpful for scheduling."
60.3276,Event,ADDED,eval-sanitize-3-r3-047-jkxpc.18d3d2ffd94d24ef,reason=Scheduled count=None msg=Successfully assigned compute/eval-sanitize-3-r3-047-jkxpc to kind-worker4
60.3278,Event,ADDED,eval-sanitize-3-r3-047-jkxpc.18d3d2fff7b33c7a,"reason=Pulled count=1 msg=Container image ""busybox:musl"" already present on machine"
60.3282,Event,ADDED,eval-sanitize-3-r3-047-jkxpc.18d3d2fff8fe9a6d,reason=Created count=1 msg=Created container: task
60.3285,Event,ADDED,eval-sanitize-3-r3-047-jkxpc.18d3d2fffdef1307,reason=Started count=1 msg=Started container task
60.3291,Event,ADDED,eval-sanitize-3-r3-047.18d3d2ffbb493604,reason=SuccessfulCreate count=1 msg=Created pod: eval-sanitize-3-r3-047-jkxpc
60.3295,Event,ADDED,eval-sanitize-3-r3-048-r5xt9.18d3d2fff75c75ee,"reason=FailedScheduling count=None msg=0/6 nodes are available: 1 c_wall violated: 1 conflicting context pair(s) with node memory, 1 c_wall violated: 2 conflicting context pair(s) with node memory, 4 node(s) had untolerated taint(s). no new claims to deallocate, preemption: 0/6 nodes are available: 2 No preemption victims found for incoming pod, 4 Preemption is not helpful for scheduling."
60.3298,Event,ADDED,eval-sanitize-3-r3-048-r5xt9.18d3d2fff8061bca,"reason=FailedScheduling count=None msg=0/6 nodes are available: 1 c_wall violated: 1 conflicting context pair(s) with node memory, 1 c_wall violated: 2 conflicting context pair(s) with node memory, 4 node(s) had untolerated taint(s). no new claims to deallocate, preemption: 0/6 nodes are available: 2 No preemption victims found for incoming pod, 4 Preemption is not helpful for scheduling."
60.3303,Event,ADDED,eval-sanitize-3-r3-048-r5xt9.18d3d30037fbcb0f,"reason=FailedScheduling count=None msg=0/6 nodes are available: 1 c_wall violated: 1 conflicting context pair(s) with node memory, 1 c_wall violated: 3 conflicting context pair(s) with node memory, 4 node(s) had untolerated taint(s). no new claims to deallocate, preemption: 0/6 nodes are available: 2 No preemption victims found for incoming pod, 4 Preemption is not helpful for scheduling."
60.3306,Event,ADDED,eval-sanitize-3-r3-048-r5xt9.18d3d30078747224,"reason=FailedScheduling count=None msg=0/6 nodes are available: 1 c_wall violated: 3 conflicting context pair(s) with node memory, 5 node(s) had untolerated taint(s). no new claims to deallocate, preemption: 0/6 nodes are available: 1 No preemption victims found for incoming pod, 5 Preemption is not helpful for scheduling."
60.3308,Event,ADDED,eval-sanitize-3-r3-048-r5xt9.18d3d3008cbc6a3a,reason=Scheduled count=None msg=Successfully assigned compute/eval-sanitize-3-r3-048-r5xt9 to kind-worker3
60.3312,Event,ADDED,eval-sanitize-3-r3-048-r5xt9.18d3d300a5e6b310,"reason=Pulled count=1 msg=Container image ""busybox:musl"" already present on machine"
60.3314,Event,ADDED,eval-sanitize-3-r3-048-r5xt9.18d3d300a7d2a5cf,reason=Created count=1 msg=Created container: task
60.3317,Event,ADDED,eval-sanitize-3-r3-048-r5xt9.18d3d300abc4da4b,reason=Started count=1 msg=Started container task
60.3321,Event,ADDED,eval-sanitize-3-r3-048.18d3d2fff6db955e,reason=SuccessfulCreate count=1 msg=Created pod: eval-sanitize-3-r3-048-r5xt9
60.3323,Event,ADDED,eval-sanitize-3-r3-049-kqlvx.18d3d30034ae90fb,reason=Scheduled count=None msg=Successfully assigned compute/eval-sanitize-3-r3-049-kqlvx to kind-worker4
60.3326,Event,ADDED,eval-sanitize-3-r3-049-kqlvx.18d3d3004dcc7889,"reason=Pulled count=1 msg=Container image ""busybox:musl"" already present on machine"
60.3328,Event,ADDED,eval-sanitize-3-r3-049-kqlvx.18d3d3004f3718a0,reason=Created count=1 msg=Created container: task
60.3332,Event,ADDED,eval-sanitize-3-r3-049-kqlvx.18d3d30052aa9d06,reason=Started count=1 msg=Started container task
60.3334,Event,ADDED,eval-sanitize-3-r3-049.18d3d30033428352,reason=SuccessfulCreate count=1 msg=Created pod: eval-sanitize-3-r3-049-kqlvx
60.3337,Event,ADDED,eval-sanitize-3-r3-050-txwpj.18d3d3006e82102c,"reason=FailedScheduling count=None msg=0/6 nodes are available: 1 c_wall violated: 1 conflicting context pair(s) with node memory, 1 c_wall violated: 3 conflicting context pair(s) with node memory, 4 node(s) had untolerated taint(s). no new claims to deallocate, preemption: 0/6 nodes are available: 2 No preemption victims found for incoming pod, 4 Preemption is not helpful for scheduling."
60.334,Event,ADDED,eval-sanitize-3-r3-050-txwpj.18d3d3006f21d7fe,"reason=FailedScheduling count=None msg=0/6 nodes are available: 1 c_wall violated: 1 conflicting context pair(s) with node memory, 1 c_wall violated: 3 conflicting context pair(s) with node memory, 4 node(s) had untolerated taint(s). no new claims to deallocate, preemption: 0/6 nodes are available: 2 No preemption victims found for incoming pod, 4 Preemption is not helpful for scheduling."
60.3343,Event,ADDED,eval-sanitize-3-r3-050-txwpj.18d3d30078989b2d,"reason=FailedScheduling count=None msg=0/6 nodes are available: 1 c_wall violated: 3 conflicting context pair(s) with node memory, 5 node(s) had untolerated taint(s). no new claims to deallocate, preemption: 0/6 nodes are available: 1 No preemption victims found for incoming pod, 5 Preemption is not helpful for scheduling."
60.3344,Event,ADDED,eval-sanitize-3-r3-050-txwpj.18d3d3008d2f3981,reason=Scheduled count=None msg=Successfully assigned compute/eval-sanitize-3-r3-050-txwpj to kind-worker3
60.3347,Event,ADDED,eval-sanitize-3-r3-050-txwpj.18d3d300a632e462,"reason=Pulled count=1 msg=Container image ""busybox:musl"" already present on machine"
60.3349,Event,ADDED,eval-sanitize-3-r3-050-txwpj.18d3d300a803fb3d,reason=Created count=1 msg=Created container: task
60.335,Event,ADDED,eval-sanitize-3-r3-050-txwpj.18d3d300abc4da41,reason=Started count=1 msg=Started container task
60.3352,Event,ADDED,eval-sanitize-3-r3-050.18d3d3006e15b3ae,reason=SuccessfulCreate count=1 msg=Created pod: eval-sanitize-3-r3-050-txwpj
60.3354,Event,ADDED,eval-sanitize-3-r3-051-zkrvm.18d3d300aad42852,reason=Scheduled count=None msg=Successfully assigned compute/eval-sanitize-3-r3-051-zkrvm to kind-worker3
60.3356,Event,ADDED,eval-sanitize-3-r3-051-zkrvm.18d3d300c3c7ccaa,"reason=Pulled count=1 msg=Container image ""busybox:musl"" already present on machine"
60.3358,Event,ADDED,eval-sanitize-3-r3-051-zkrvm.18d3d300c4f3b479,reason=Created count=1 msg=Created container: task
60.336,Event,ADDED,eval-sanitize-3-r3-051-zkrvm.18d3d300c71d3c00,reason=Started count=1 msg=Started container task
60.3362,Event,ADDED,eval-sanitize-3-r3-051.18d3d300aa2eb4ea,reason=SuccessfulCreate count=1 msg=Created pod: eval-sanitize-3-r3-051-zkrvm
60.3363,Event,ADDED,eval-sanitize-3-r3-052-qdx5l.18d3d300e60b2c79,reason=Scheduled count=None msg=Successfully assigned compute/eval-sanitize-3-r3-052-qdx5l to kind-worker5
60.3365,Event,ADDED,eval-sanitize-3-r3-052-qdx5l.18d3d300ffdf6193,"reason=Pulled count=1 msg=Container image ""busybox:musl"" already present on machine"
60.3367,Event,ADDED,eval-sanitize-3-r3-052-qdx5l.18d3d3010112c21f,reason=Created count=1 msg=Created container: task
60.3369,Event,ADDED,eval-sanitize-3-r3-052-qdx5l.18d3d30104f059c8,reason=Started count=1 msg=Started container task
60.3371,Event,ADDED,eval-sanitize-3-r3-052.18d3d300e56e9a5a,reason=SuccessfulCreate count=1 msg=Created pod: eval-sanitize-3-r3-052-qdx5l
60.3372,Event,ADDED,eval-sanitize-3-r3-053-f45f7.18d3d30121b0f339,reason=Scheduled count=None msg=Successfully assigned compute/eval-sanitize-3-r3-053-f45f7 to kind-worker5
60.3375,Event,ADDED,eval-sanitize-3-r3-053-f45f7.18d3d3013abceaea,"reason=Pulled count=1 msg=Container image ""busybox:musl"" already present on machine"
60.3376,Event,ADDED,eval-sanitize-3-r3-053-f45f7.18d3d3013bcb2eee,reason=Created count=1 msg=Created container: task
60.3378,Event,ADDED,eval-sanitize-3-r3-053-f45f7.18d3d3013dcb952c,reason=Started count=1 msg=Started container task
60.338,Event,ADDED,eval-sanitize-3-r3-053.18d3d30120f47711,reason=SuccessfulCreate count=1 msg=Created pod: eval-sanitize-3-r3-053-f45f7
60.3382,Event,ADDED,eval-sanitize-3-r3-054-mhh2r.18d3d3015d181026,reason=Scheduled count=None msg=Successfully assigned compute/eval-sanitize-3-r3-054-mhh2r to kind-worker5
60.3384,Event,ADDED,eval-sanitize-3-r3-054-mhh2r.18d3d301771bca6d,"reason=Pulled count=1 msg=Container image ""busybox:musl"" already present on machine"
60.3386,Event,ADDED,eval-sanitize-3-r3-054-mhh2r.18d3d30178627deb,reason=Created count=1 msg=Created container: task
60.3388,Event,ADDED,eval-sanitize-3-r3-054-mhh2r.18d3d3017a3f6cfd,reason=Started count=1 msg=Started container task
60.339,Event,ADDED,eval-sanitize-3-r3-054.18d3d3015c844142,reason=SuccessfulCreate count=1 msg=Created pod: eval-sanitize-3-r3-054-mhh2r
60.3392,Event,ADDED,eval-sanitize-3-r3-055-26snf.18d3d3019835b27e,"reason=FailedScheduling count=None msg=0/6 nodes are available: 6 node(s) had untolerated taint(s). no new claims to deallocate, preemption: 0/6 nodes are available: 6 Preemption is not helpful for scheduling."
60.3393,Event,ADDED,eval-sanitize-3-r3-055-26snf.18d3d301e00db0ce,reason=Scheduled count=None msg=Successfully assigned compute/eval-sanitize-3-r3-055-26snf to kind-worker2
60.3395,Event,ADDED,eval-sanitize-3-r3-055-26snf.18d3d301f96c78b6,"reason=Pulled count=1 msg=Container image ""busybox:musl"" already present on machine"
60.3397,Event,ADDED,eval-sanitize-3-r3-055-26snf.18d3d301fb06df54,reason=Created count=1 msg=Created container: task
60.3399,Event,ADDED,eval-sanitize-3-r3-055-26snf.18d3d301ff1fad56,reason=Started count=1 msg=Started container task
60.3401,Event,ADDED,eval-sanitize-3-r3-055.18d3d301982a1c3c,reason=SuccessfulCreate count=1 msg=Created pod: eval-sanitize-3-r3-055-26snf
60.3402,Event,ADDED,eval-sanitize-3-r3-056-kbj7h.18d3d301d3db54dd,"reason=FailedScheduling count=None msg=0/6 nodes are available: 6 node(s) had untolerated taint(s). no new claims to deallocate, preemption: 0/6 nodes are available: 6 Preemption is not helpful for scheduling."
60.3404,Event,ADDED,eval-sanitize-3-r3-056-kbj7h.18d3d301e073d435,reason=Scheduled count=None msg=Successfully assigned compute/eval-sanitize-3-r3-056-kbj7h to kind-worker2
60.3406,Event,ADDED,eval-sanitize-3-r3-056-kbj7h.18d3d301f9e0ff45,"reason=Pulled count=1 msg=Container image ""busybox:musl"" already present on machine"
60.3408,Event,ADDED,eval-sanitize-3-r3-056-kbj7h.18d3d301fb5b3469,reason=Created count=1 msg=Created container: task
60.341,Event,ADDED,eval-sanitize-3-r3-056-kbj7h.18d3d301ff4fc3f0,reason=Started count=1 msg=Started container task
60.3412,Event,ADDED,eval-sanitize-3-r3-056.18d3d301d3d27e16,reason=SuccessfulCreate count=1 msg=Created pod: eval-sanitize-3-r3-056-kbj7h
60.3413,Event,ADDED,eval-sanitize-3-r3-057-hqpsj.18d3d3020f9fbaf5,"reason=FailedScheduling count=None msg=0/6 nodes are available: 1 c_wall violated: 1 conflicting context pair(s) with node memory, 5 node(s) had untolerated taint(s). no new claims to deallocate, preemption: 0/6 nodes are available: 1 No preemption victims found for incoming pod, 5 Preemption is not helpful for scheduling."
60.3415,Event,ADDED,eval-sanitize-3-r3-057-hqpsj.18d3d3021031080c,"reason=FailedScheduling count=None msg=0/6 nodes are available: 1 c_wall violated: 1 conflicting context pair(s) with node memory, 5 node(s) had untolerated taint(s). no new claims to deallocate, preemption: 0/6 nodes are available: 1 No preemption victims found for incoming pod, 5 Preemption is not helpful for scheduling."
60.3418,Event,ADDED,eval-sanitize-3-r3-057-hqpsj.18d3d302ab811a04,reason=Scheduled count=None msg=Successfully assigned compute/eval-sanitize-3-r3-057-hqpsj to kind-worker
60.3419,Event,ADDED,eval-sanitize-3-r3-057.18d3d3020f5dba06,reason=SuccessfulCreate count=1 msg=Created pod: eval-sanitize-3-r3-057-hqpsj
60.3421,Event,ADDED,eval-sanitize-3-r3-058-8l6ds.18d3d3024b5929cf,"reason=FailedScheduling count=None msg=0/6 nodes are available: 1 c_wall violated: 2 conflicting context pair(s) with node memory, 5 node(s) had untolerated taint(s). no new claims to deallocate, preemption: 0/6 nodes are available: 1 No preemption victims found for incoming pod, 5 Preemption is not helpful for scheduling."
60.3424,Event,ADDED,eval-sanitize-3-r3-058-8l6ds.18d3d3024bdee556,"reason=FailedScheduling count=None msg=0/6 nodes are available: 1 c_wall violated: 2 conflicting context pair(s) with node memory, 5 node(s) had untolerated taint(s). no new claims to deallocate, preemption: 0/6 nodes are available: 1 No preemption victims found for incoming pod, 5 Preemption is not helpful for scheduling."
60.3427,Event,ADDED,eval-sanitize-3-r3-058-8l6ds.18d3d302ab6fe80f,"reason=FailedScheduling count=None msg=0/6 nodes are available: 1 c_wall violated: 1 conflicting context pair(s) with node memory, 5 node(s) had untolerated taint(s). no new claims to deallocate, preemption: 0/6 nodes are available: 1 No preemption victims found for incoming pod, 5 Preemption is not helpful for scheduling."
60.3429,Event,ADDED,eval-sanitize-3-r3-058-8l6ds.18d3d302ac51dd2b,"reason=FailedScheduling count=None msg=0/6 nodes are available: 1 c_wall violated: 1 conflicting context pair(s) with node memory, 5 node(s) had untolerated taint(s). no new claims to deallocate, preemption: 0/6 nodes are available: 1 No preemption victims found for incoming pod, 5 Preemption is not helpful for scheduling."
60.3432,Event,ADDED,eval-sanitize-3-r3-058.18d3d3024b197d4a,reason=SuccessfulCreate count=1 msg=Created pod: eval-sanitize-3-r3-058-8l6ds
60.3433,Event,ADDED,eval-sanitize-3-r3-059-wtxpj.18d3d302872b2cfe,reason=Scheduled count=None msg=Successfully assigned compute/eval-sanitize-3-r3-059-wtxpj to kind-worker2
60.3435,Event,ADDED,eval-sanitize-3-r3-059-wtxpj.18d3d302a0fd3dad,"reason=Pulled count=1 msg=Container image ""busybox:musl"" already present on machine"
60.3438,Event,ADDED,eval-sanitize-3-r3-059-wtxpj.18d3d302a20a3321,reason=Created count=1 msg=Created container: task
60.3441,Event,ADDED,eval-sanitize-3-r3-059-wtxpj.18d3d302a6302492,reason=Started count=1 msg=Started container task
60.3444,Event,ADDED,eval-sanitize-3-r3-059.18d3d3028699e487,reason=SuccessfulCreate count=1 msg=Created pod: eval-sanitize-3-r3-059-wtxpj
60.3446,Event,ADDED,eval-sanitize-3-r3-060.18d3d302c26b1032,reason=SuccessfulCreate count=1 msg=Created pod: eval-sanitize-3-r3-060-jbqts
60.3447,Event,ADDED,eval-sanitize-3-r3-060-jbqts.18d3d302c2b63049,"reason=FailedScheduling count=None msg=0/6 nodes are available: 1 c_wall violated: 1 conflicting context pair(s) with node memory, 5 node(s) had untolerated taint(s). no new claims to deallocate, preemption: 0/6 nodes are available: 1 No preemption victims found for incoming pod, 5 Preemption is not helpful for scheduling."
60.3449,Event,ADDED,eval-sanitize-3-r3-060-jbqts.18d3d302c33d8bfd,"reason=FailedScheduling count=None msg=0/6 nodes are available: 1 c_wall violated: 1 conflicting context pair(s) with node memory, 5 node(s) had untolerated taint(s). no new claims to deallocate, preemption: 0/6 nodes are available: 1 No preemption victims found for incoming pod, 5 Preemption is not helpful for scheduling."
60.3451,Event,ADDED,eval-sanitize-3-r3-057-hqpsj.18d3d302c58fd456,"reason=Pulled count=1 msg=Container image ""busybox:musl"" already present on machine"
60.3454,Event,ADDED,eval-sanitize-3-r3-057-hqpsj.18d3d302c6d1a67d,reason=Created count=1 msg=Created container: task
60.346,Event,ADDED,eval-sanitize-3-r3-057-hqpsj.18d3d302caed01e2,reason=Started count=1 msg=Started container task
60.3477,Pod,MODIFIED,eval-sanitize-3-r3-059-wtxpj,phase=Running node=kind-worker2
60.3582,Event,MODIFIED,eval-sanitize-3-r3-060-jbqts.18d3d302c33d8bfd,"reason=FailedScheduling count=None msg=0/6 nodes are available: 1 c_wall violated: 1 conflicting context pair(s) with node memory, 5 node(s) had untolerated taint(s). no new claims to deallocate, preemption: 0/6 nodes are available: 1 No preemption victims found for incoming pod, 5 Preemption is not helpful for scheduling."
60.4554,Pod,MODIFIED,eval-sanitize-3-r3-049-kqlvx,phase=Running node=kind-worker4
60.4586,Job,MODIFIED,eval-sanitize-3-r3-047,
60.4665,Job,MODIFIED,eval-sanitize-3-r3-046,
60.472,Pod,MODIFIED,eval-sanitize-3-r3-047-jkxpc,phase=Succeeded node=kind-worker4
60.4728,Job,MODIFIED,eval-sanitize-3-r3-047,
60.4744,Pod,MODIFIED,eval-sanitize-3-r3-046-6px6g,phase=Succeeded node=kind-worker4
60.4764,Job,MODIFIED,eval-sanitize-3-r3-046,
60.9409,Pod,MODIFIED,eval-sanitize-3-r3-057-hqpsj,phase=Running node=kind-worker
60.9453,Job,MODIFIED,eval-sanitize-3-r3-043,
60.9497,Job,MODIFIED,eval-sanitize-3-r3-044,
60.9542,Job,MODIFIED,eval-sanitize-3-r3-043,
60.9551,Job,MODIFIED,eval-sanitize-3-r3-044,
60.9593,Job,MODIFIED,eval-sanitize-3-r3-045,
60.9598,Event,ADDED,eval-sanitize-3-r3-043.18d3d302f8f91377,reason=Completed count=1 msg=Job completed
60.9649,Job,MODIFIED,eval-sanitize-3-r3-045,
60.9662,Event,ADDED,eval-sanitize-3-r3-044.18d3d302f8ff34f6,reason=Completed count=1 msg=Job completed
60.9672,Job,MODIFIED,eval-sanitize-3-r3-043,
60.9682,Job,MODIFIED,eval-sanitize-3-r3-044,
60.9715,Event,ADDED,eval-sanitize-3-r3-045.18d3d302f995590d,reason=Completed count=1 msg=Job completed
60.9724,TaskRequest,MODIFIED,eval-sanitize-3-r3-044,phase=Complete job=None
60.9758,Job,MODIFIED,eval-sanitize-3-r3-045,
60.9776,TaskRequest,MODIFIED,eval-sanitize-3-r3-043,phase=Complete job=None
60.9826,Job,MODIFIED,eval-sanitize-3-r3-044,
60.9841,TaskRequest,MODIFIED,eval-sanitize-3-r3-045,phase=Complete job=None
60.9874,Job,MODIFIED,eval-sanitize-3-r3-043,
61.0209,TaskRequest,ADDED,eval-sanitize-3-r3-061,phase=None job=None
61.0238,TaskRequest,MODIFIED,eval-sanitize-3-r3-061,phase=Pending job=None
61.0265,Job,MODIFIED,eval-sanitize-3-r3-045,
61.0387,Job,ADDED,eval-sanitize-3-r3-061,
61.0424,Job,MODIFIED,eval-sanitize-3-r3-060,
61.0435,TaskRequest,MODIFIED,eval-sanitize-3-r3-061,phase=Scheduled job=None
61.0463,Job,MODIFIED,eval-sanitize-3-r3-059,
61.0489,Job,MODIFIED,eval-sanitize-3-r3-061,
61.0498,Pod,ADDED,eval-sanitize-3-r3-061-n9dnt,phase=Pending node=None
61.0515,TaskRequest,MODIFIED,eval-sanitize-3-r3-061,phase=Scheduled job=None
61.0561,Event,ADDED,eval-sanitize-3-r3-061.18d3d302fe999b7a,reason=SuccessfulCreate count=1 msg=Created pod: eval-sanitize-3-r3-061-n9dnt
61.0568,Job,MODIFIED,eval-sanitize-3-r3-060,
61.0581,Pod,MODIFIED,eval-sanitize-3-r3-061-n9dnt,phase=Pending node=None
61.0586,Event,ADDED,eval-sanitize-3-r3-061-n9dnt.18d3d302fedef6ea,"reason=FailedScheduling count=None msg=0/6 nodes are available: 1 c_wall violated: 1 conflicting context pair(s) with node memory, 5 node(s) had untolerated taint(s). no new claims to deallocate, preemption: 0/6 nodes are available: 1 No preemption victims found for incoming pod, 5 Preemption is not helpful for scheduling."
61.0663,Event,ADDED,eval-sanitize-3-r3-061-n9dnt.18d3d302ff625f0b,"reason=FailedScheduling count=None msg=0/6 nodes are available: 1 c_wall violated: 1 conflicting context pair(s) with node memory, 5 node(s) had untolerated taint(s). no new claims to deallocate, preemption: 0/6 nodes are available: 1 No preemption victims found for incoming pod, 5 Preemption is not helpful for scheduling."
61.0878,Job,MODIFIED,eval-sanitize-3-r3-059,
61.4609,Job,MODIFIED,eval-sanitize-3-r3-049,
61.4641,Job,MODIFIED,eval-sanitize-3-r3-047,
61.4693,Job,MODIFIED,eval-sanitize-3-r3-047,
61.4735,Job,MODIFIED,eval-sanitize-3-r3-049,
61.4752,Job,MODIFIED,eval-sanitize-3-r3-046,
61.4756,Event,ADDED,eval-sanitize-3-r3-047.18d3d30317ac826b,reason=Completed count=1 msg=Job completed
61.4777,Pod,MODIFIED,eval-sanitize-3-r3-048-r5xt9,phase=Running node=kind-worker3
61.4788,Job,MODIFIED,eval-sanitize-3-r3-046,
61.4834,Job,MODIFIED,eval-sanitize-3-r3-047,
61.4851,Event,ADDED,eval-sanitize-3-r3-046.18d3d303182c123a,reason=Completed count=1 msg=Job completed
61.4864,Pod,MODIFIED,eval-sanitize-3-r3-050-txwpj,phase=Running node=kind-worker3
61.4878,TaskRequest,MODIFIED,eval-sanitize-3-r3-047,phase=Complete job=None
61.4938,Job,MODIFIED,eval-sanitize-3-r3-046,
61.4941,Event,MODIFIED,eval-sanitize-3-r3-061-n9dnt.18d3d302ff625f0b,"reason=FailedScheduling count=None msg=0/6 nodes are available: 1 c_wall violated: 1 conflicting context pair(s) with node memory, 5 node(s) had untolerated taint(s). no new claims to deallocate, preemption: 0/6 nodes are available: 1 No preemption victims found for incoming pod, 5 Preemption is not helpful for scheduling."
61.4976,Job,MODIFIED,eval-sanitize-3-r3-047,
61.4983,TaskRequest,MODIFIED,eval-sanitize-3-r3-046,phase=Complete job=None
61.507,Job,MODIFIED,eval-sanitize-3-r3-046,
61.5633,Pod,MODIFIED,eval-sanitize-3-r3-049-kqlvx,phase=Succeeded node=kind-worker4
61.9468,Job,MODIFIED,eval-sanitize-3-r3-057,
61.9549,Job,MODIFIED,eval-sanitize-3-r3-057,
62.0067,TaskRequest,ADDED,eval-sanitize-3-r3-062,phase=None job=None
62.0103,TaskRequest,MODIFIED,eval-sanitize-3-r3-062,phase=Pending job=None
62.0251,Job,ADDED,eval-sanitize-3-r3-062,
62.029,TaskRequest,MODIFIED,eval-sanitize-3-r3-062,phase=Scheduled job=None
62.0324,Pod,ADDED,eval-sanitize-3-r3-062-gmfbb,phase=Pending node=None
62.0352,Job,MODIFIED,eval-sanitize-3-r3-062,
62.0386,Event,ADDED,eval-sanitize-3-r3-062.18d3d303393a9b1e,reason=SuccessfulCreate count=1 msg=Created pod: eval-sanitize-3-r3-062-gmfbb
62.0388,TaskRequest,MODIFIED,eval-sanitize-3-r3-062,phase=Scheduled job=None
62.0413,Pod,MODIFIED,eval-sanitize-3-r3-062-gmfbb,phase=Pending node=None
62.0416,Event,ADDED,eval-sanitize-3-r3-062-gmfbb.18d3d303397c9046,"reason=FailedScheduling count=None msg=0/6 nodes are available: 1 c_wall violated: 1 conflicting context pair(s) with node memory, 5 node(s) had untolerated taint(s). no new claims to deallocate, preemption: 0/6 nodes are available: 1 No preemption victims found for incoming pod, 5 Preemption is not helpful for scheduling."
62.0474,Event,ADDED,eval-sanitize-3-r3-062-gmfbb.18d3d30339f5f551,"reason=FailedScheduling count=None msg=0/6 nodes are available: 1 c_wall violated: 1 conflicting context pair(s) with node memory, 5 node(s) had untolerated taint(s). no new claims to deallocate, preemption: 0/6 nodes are available: 1 No preemption victims found for incoming pod, 5 Preemption is not helpful for scheduling."
62.0529,Job,MODIFIED,eval-sanitize-3-r3-061,
62.0611,Job,MODIFIED,eval-sanitize-3-r3-061,
62.4664,Job,MODIFIED,eval-sanitize-3-r3-049,
62.4759,Pod,MODIFIED,eval-sanitize-3-r3-049-kqlvx,phase=Succeeded node=kind-worker4
62.4805,Job,MODIFIED,eval-sanitize-3-r3-049,
62.4834,Job,MODIFIED,eval-sanitize-3-r3-048,
62.4851,Pod,MODIFIED,eval-sanitize-3-r3-051-zkrvm,phase=Running node=kind-worker3
62.4912,Job,MODIFIED,eval-sanitize-3-r3-050,
62.4971,Job,MODIFIED,eval-sanitize-3-r3-048,
62.5015,Job,MODIFIED,eval-sanitize-3-r3-050,
62.5041,Event,MODIFIED,eval-sanitize-3-r3-062-gmfbb.18d3d30339f5f551,"reason=FailedScheduling count=None msg=0/6 nodes are available: 1 c_wall violated: 1 conflicting context pair(s) with node memory, 5 node(s) had untolerated taint(s). no new claims to deallocate, preemption: 0/6 nodes are available: 1 No preemption victims found for incoming pod, 5 Preemption is not helpful for scheduling."
62.6611,Pod,MODIFIED,eval-sanitize-3-r3-050-txwpj,phase=Succeeded node=kind-worker3
62.7126,Pod,MODIFIED,eval-sanitize-3-r3-048-r5xt9,phase=Succeeded node=kind-worker3
62.7315,Node,MODIFIED,kind-worker,taints=1
62.7361,Pod,MODIFIED,eval-sanitize-3-r3-058-8l6ds,phase=Pending node=None
62.7414,Pod,MODIFIED,eval-sanitize-3-r3-060-jbqts,phase=Pending node=None
62.7443,Node,MODIFIED,kind-worker,taints=1
62.7462,Pod,MODIFIED,eval-sanitize-3-r3-061-n9dnt,phase=Pending node=None
62.7508,Pod,MODIFIED,eval-sanitize-3-r3-062-gmfbb,phase=Pending node=None
63.0065,TaskRequest,ADDED,eval-sanitize-3-r3-063,phase=None job=None
63.0116,TaskRequest,MODIFIED,eval-sanitize-3-r3-063,phase=Pending job=None
63.0276,Job,ADDED,eval-sanitize-3-r3-063,
63.0316,TaskRequest,MODIFIED,eval-sanitize-3-r3-063,phase=Scheduled job=None
63.0347,Job,MODIFIED,eval-sanitize-3-r3-063,
63.0355,Pod,ADDED,eval-sanitize-3-r3-063-hzszc,phase=Pending node=None
63.0367,Job,MODIFIED,eval-sanitize-3-r3-062,
63.0402,Pod,MODIFIED,eval-sanitize-3-r3-063-hzszc,phase=Pending node=None
63.0416,Event,ADDED,eval-sanitize-3-r3-063.18d3d30374fc02df,reason=SuccessfulCreate count=1 msg=Created pod: eval-sanitize-3-r3-063-hzszc
63.0419,Event,ADDED,eval-sanitize-3-r3-063-hzszc.18d3d3037507149d,"reason=FailedScheduling count=None msg=0/6 nodes are available: 6 node(s) had untolerated taint(s). no new claims to deallocate, preemption: 0/6 nodes are available: 6 Preemption is not helpful for scheduling."
63.042,TaskRequest,MODIFIED,eval-sanitize-3-r3-063,phase=Scheduled job=None
63.045,Job,MODIFIED,eval-sanitize-3-r3-062,
63.4734,Job,MODIFIED,eval-sanitize-3-r3-049,
63.4775,Job,MODIFIED,eval-sanitize-3-r3-049,
63.4829,Event,ADDED,eval-sanitize-3-r3-049.18d3d3038f5d4c39,reason=Completed count=1 msg=Job completed
63.4876,Job,MODIFIED,eval-sanitize-3-r3-048,
63.4892,Job,MODIFIED,eval-sanitize-3-r3-051,
63.4904,Job,MODIFIED,eval-sanitize-3-r3-049,
63.4979,Pod,MODIFIED,eval-sanitize-3-r3-048-r5xt9,phase=Succeeded node=kind-worker3
63.4982,TaskRequest,MODIFIED,eval-sanitize-3-r3-049,phase=Complete job=None
63.4992,Job,MODIFIED,eval-sanitize-3-r3-050,
63.5,Job,MODIFIED,eval-sanitize-3-r3-048,
63.5028,Job,MODIFIED,eval-sanitize-3-r3-051,
63.5085,Pod,MODIFIED,eval-sanitize-3-r3-050-txwpj,phase=Succeeded node=kind-worker3
63.5106,Job,MODIFIED,eval-sanitize-3-r3-049,
63.5124,Job,MODIFIED,eval-sanitize-3-r3-050,
63.5249,Pod,MODIFIED,eval-sanitize-3-r3-052-qdx5l,phase=Running node=kind-worker5
63.5336,Node,MODIFIED,kind-worker4,taints=1
63.6205,Pod,MODIFIED,eval-sanitize-3-r3-051-zkrvm,phase=Succeeded node=kind-worker3
63.6253,Node,MODIFIED,kind-worker4,taints=0
63.6308,Pod,MODIFIED,eval-sanitize-3-r3-058-8l6ds,phase=Pending node=kind-worker4
63.6372,Node,MODIFIED,kind-worker4,taints=0
63.6388,Event,ADDED,eval-sanitize-3-r3-060-jbqts.18d3d303986f0f6e,"reason=FailedScheduling count=None msg=0/6 nodes are available: 1 c_wall violated: 1 conflicting context pair(s) with node memory, 5 node(s) had untolerated taint(s). no new claims to deallocate, preemption: 0/6 nodes are available: 1 No preemption victims found for incoming pod, 5 Preemption is not helpful for scheduling."
63.639,Event,ADDED,eval-sanitize-3-r3-058-8l6ds.18d3d3039881a210,reason=Scheduled count=None msg=Successfully assigned compute/eval-sanitize-3-r3-058-8l6ds to kind-worker4
63.6399,Pod,MODIFIED,eval-sanitize-3-r3-060-jbqts,phase=Pending node=None
63.6466,Pod,MODIFIED,eval-sanitize-3-r3-058-8l6ds,phase=Pending node=kind-worker4
63.6483,Pod,MODIFIED,eval-sanitize-3-r3-061-n9dnt,phase=Pending node=None
63.6496,Event,ADDED,eval-sanitize-3-r3-061-n9dnt.18d3d303993cea37,"reason=FailedScheduling count=None msg=0/6 nodes are available: 1 c_wall violated: 1 conflicting context pair(s) with node memory, 5 node(s) had untolerated taint(s). no new claims to deallocate, preemption: 0/6 nodes are available: 1 No preemption victims found for incoming pod, 5 Preemption is not helpful for scheduling."
63.6558,Pod,MODIFIED,eval-sanitize-3-r3-062-gmfbb,phase=Pending node=kind-worker4
63.6621,Pod,MODIFIED,eval-sanitize-3-r3-063-hzszc,phase=Pending node=None
63.6641,Event,ADDED,eval-sanitize-3-r3-063-hzszc.18d3d30399f5a096,"reason=FailedScheduling count=None msg=0/6 nodes are available: 1 c_wall violated: 2 conflicting context pair(s) with node memory, 5 node(s) had untolerated taint(s). no new claims to deallocate, preemption: 0/6 nodes are available: 1 No preemption victims found for incoming pod, 5 Preemption is not helpful for scheduling."
63.6644,Event,ADDED,eval-sanitize-3-r3-062-gmfbb.18d3d30399ff11a3,reason=Scheduled count=None msg=Successfully assigned compute/eval-sanitize-3-r3-062-gmfbb to kind-worker4
63.6659,Node,MODIFIED,kind-worker4,taints=0
63.6697,Pod,MODIFIED,eval-sanitize-3-r3-062-gmfbb,phase=Pending node=kind-worker4
63.6712,Pod,MODIFIED,eval-sanitize-3-r3-060-jbqts,phase=Pending node=None
63.6715,Event,ADDED,eval-sanitize-3-r3-060-jbqts.18d3d3039a9ce63c,"reason=FailedScheduling count=None msg=0/6 nodes are available: 1 c_wall violated: 2 conflicting context pair(s) with node memory, 5 node(s) had untolerated taint(s). no new claims to deallocate, preemption: 0/6 nodes are available: 1 No preemption victims found for incoming pod, 5 Preemption is not helpful for scheduling."
63.7072,Pod,MODIFIED,eval-sanitize-3-r3-061-n9dnt,phase=Pending node=None
63.7076,Event,ADDED,eval-sanitize-3-r3-061-n9dnt.18d3d3039cc78e23,"reason=FailedScheduling count=None msg=0/6 nodes are available: 1 c_wall violated: 2 conflicting context pair(s) with node memory, 5 node(s) had untolerated taint(s). no new claims to deallocate, preemption: 0/6 nodes are available: 1 No preemption victims found for incoming pod, 5 Preemption is not helpful for scheduling."
63.7118,Node,MODIFIED,kind-worker4,taints=0
63.7174,Event,ADDED,eval-sanitize-3-r3-063-hzszc.18d3d3039d78bd82,"reason=FailedScheduling count=None msg=0/6 nodes are available: 1 c_wall violated: 2 conflicting context pair(s) with node memory, 5 node(s) had untolerated taint(s). no new claims to deallocate, preemption: 0/6 nodes are available: 1 No preemption victims found for incoming pod, 5 Preemption is not helpful for scheduling."
63.7214,Event,ADDED,eval-sanitize-3-r3-060-jbqts.18d3d3039da33cce,"reason=FailedScheduling count=None msg=0/6 nodes are available: 1 c_wall violated: 2 conflicting context pair(s) with node memory, 5 node(s) had untolerated taint(s). no new claims to deallocate, preemption: 0/6 nodes are available: 1 No preemption victims found for incoming pod, 5 Preemption is not helpful for scheduling."
63.7229,Event,ADDED,eval-sanitize-3-r3-061-n9dnt.18d3d3039dcd2b19,"reason=FailedScheduling count=None msg=0/6 nodes are available: 1 c_wall violated: 2 conflicting context pair(s) with node memory, 5 node(s) had untolerated taint(s). no new claims to deallocate, preemption: 0/6 nodes are available: 1 No preemption victims found for incoming pod, 5 Preemption is not helpful for scheduling."
63.7267,Event,MODIFIED,eval-sanitize-3-r3-063-hzszc.18d3d3039d78bd82,"reason=FailedScheduling count=None msg=0/6 nodes are available: 1 c_wall violated: 2 conflicting context pair(s) with node memory, 5 node(s) had untolerated taint(s). no new claims to deallocate, preemption: 0/6 nodes are available: 1 No preemption victims found for incoming pod, 5 Preemption is not helpful for scheduling."
63.7398,Node,MODIFIED,kind-worker4,taints=0
63.7477,Event,MODIFIED,eval-sanitize-3-r3-060-jbqts.18d3d3039da33cce,"reason=FailedScheduling count=None msg=0/6 nodes are available: 1 c_wall violated: 2 conflicting context pair(s) with node memory, 5 node(s) had untolerated taint(s). no new claims to deallocate, preemption: 0/6 nodes are available: 1 No preemption victims found for incoming pod, 5 Preemption is not helpful for scheduling."
63.7522,Event,MODIFIED,eval-sanitize-3-r3-061-n9dnt.18d3d3039dcd2b19,"reason=FailedScheduling count=None msg=0/6 nodes are available: 1 c_wall violated: 2 conflicting context pair(s) with node memory, 5 node(s) had untolerated taint(s). no new claims to deallocate, preemption: 0/6 nodes are available: 1 No preemption victims found for incoming pod, 5 Preemption is not helpful for scheduling."
63.8203,Node,MODIFIED,kind-worker4,taints=0
64.0219,TaskRequest,ADDED,eval-sanitize-3-r3-064,phase=None job=None
64.0256,TaskRequest,MODIFIED,eval-sanitize-3-r3-064,phase=Pending job=None
64.0418,Job,MODIFIED,eval-sanitize-3-r3-063,
64.0432,Job,ADDED,eval-sanitize-3-r3-064,
64.0471,Event,ADDED,eval-sanitize-3-r3-058-8l6ds.18d3d303b11938a1,"reason=Pulled count=1 msg=Container image ""busybox:musl"" already present on machine"
64.0503,TaskRequest,MODIFIED,eval-sanitize-3-r3-064,phase=Scheduled job=None
64.0518,Pod,ADDED,eval-sanitize-3-r3-064-qptqh,phase=Pending node=None
64.0545,Job,MODIFIED,eval-sanitize-3-r3-064,
64.0579,Event,ADDED,eval-sanitize-3-r3-064.18d3d303b1936b94,reason=SuccessfulCreate count=1 msg=Created pod: eval-sanitize-3-r3-064-qptqh
64.0588,TaskRequest,MODIFIED,eval-sanitize-3-r3-064,phase=Scheduled job=None
64.0628,Pod,MODIFIED,eval-sanitize-3-r3-064-qptqh,phase=Pending node=None
64.0636,Job,MODIFIED,eval-sanitize-3-r3-063,
64.064,Event,ADDED,eval-sanitize-3-r3-064-qptqh.18d3d303b1e5fe70,"reason=FailedScheduling count=None msg=0/6 nodes are available: 1 c_wall violated: 1 conflicting context pair(s) with node memory, 5 node(s) had untolerated taint(s). no new claims to deallocate, preemption: 0/6 nodes are available: 1 No preemption victims found for incoming pod, 5 Preemption is not helpful for scheduling."
64.0661,Event,ADDED,eval-sanitize-3-r3-062-gmfbb.18d3d303b238f2a4,"reason=Pulled count=1 msg=Container image ""busybox:musl"" already present on machine"
64.0699,Event,ADDED,eval-sanitize-3-r3-064-qptqh.18d3d303b276e00a,"reason=FailedScheduling count=None msg=0/6 nodes are available: 1 c_wall violated: 1 conflicting context pair(s) with node memory, 5 node(s) had untolerated taint(s). no new claims to deallocate, preemption: 0/6 nodes are available: 1 No preemption victims found for incoming pod, 5 Preemption is not helpful for scheduling."
64.0731,Event,ADDED,eval-sanitize-3-r3-058-8l6ds.18d3d303b2acd0b1,reason=Created count=1 msg=Created container: task
64.0884,Event,ADDED,eval-sanitize-3-r3-062-gmfbb.18d3d303b37c39de,reason=Created count=1 msg=Created container: task
64.1596,Event,ADDED,eval-sanitize-3-r3-058-8l6ds.18d3d303b7c17ba1,reason=Started count=1 msg=Started container task
64.1632,Event,ADDED,eval-sanitize-3-r3-062-gmfbb.18d3d303b80948e8,reason=Started count=1 msg=Started container task
64.4657,Pod,MODIFIED,eval-sanitize-3-r3-062-gmfbb,phase=Running node=kind-worker4
64.4723,Pod,MODIFIED,eval-sanitize-3-r3-058-8l6ds,phase=Running node=kind-worker4
64.4827,Event,MODIFIED,eval-sanitize-3-r3-064-qptqh.18d3d303b276e00a,"reason=FailedScheduling count=None msg=0/6 nodes are available: 1 c_wall violated: 1 conflicting context pair(s) with node memory, 5 node(s) had untolerated taint(s). no new claims to deallocate, preemption: 0/6 nodes are available: 1 No preemption victims found for incoming pod, 5 Preemption is not helpful for scheduling."
64.5038,Job,MODIFIED,eval-sanitize-3-r3-048,
64.5052,Job,MODIFIED,eval-sanitize-3-r3-051,
64.5078,Job,MODIFIED,eval-sanitize-3-r3-050,
64.5112,Job,MODIFIED,eval-sanitize-3-r3-048,
64.5135,Job,MODIFIED,eval-sanitize-3-r3-050,
64.5149,Pod,MODIFIED,eval-sanitize-3-r3-051-zkrvm,phase=Succeeded node=kind-worker3
64.5165,Job,MODIFIED,eval-sanitize-3-r3-051,
64.5168,Event,ADDED,eval-sanitize-3-r3-048.18d3d303ccfdc5fa,reason=Completed count=1 msg=Job completed
64.522,Event,ADDED,eval-sanitize-3-r3-050.18d3d303cd223827,reason=Completed count=1 msg=Job completed
64.523,Job,MODIFIED,eval-sanitize-3-r3-048,
64.5249,Job,MODIFIED,eval-sanitize-3-r3-050,
64.5296,Pod,MODIFIED,eval-sanitize-3-r3-053-f45f7,phase=Running node=kind-worker5
64.5303,TaskRequest,MODIFIED,eval-sanitize-3-r3-048,phase=Complete job=None
64.5312,Job,MODIFIED,eval-sanitize-3-r3-052,
64.5379,TaskRequest,MODIFIED,eval-sanitize-3-r3-050,phase=Complete job=None
64.5474,Job,MODIFIED,eval-sanitize-3-r3-048,
64.5497,Job,MODIFIED,eval-sanitize-3-r3-052,
64.5506,Job,MODIFIED,eval-sanitize-3-r3-050,
64.7079,Pod,MODIFIED,eval-sanitize-3-r3-052-qdx5l,phase=Succeeded node=kind-worker5
65.0066,TaskRequest,ADDED,eval-sanitize-3-r3-065,phase=None job=None
65.0125,TaskRequest,MODIFIED,eval-sanitize-3-r3-065,phase=Pending job=None
65.029,Job,ADDED,eval-sanitize-3-r3-065,
65.0353,Pod,ADDED,eval-sanitize-3-r3-065-th6fg,phase=Pending node=None
65.0364,TaskRequest,MODIFIED,eval-sanitize-3-r3-065,phase=Scheduled job=None
65.0372,Job,MODIFIED,eval-sanitize-3-r3-065,
65.0401,Event,ADDED,eval-sanitize-3-r3-065.18d3d303ec396994,reason=SuccessfulCreate count=1 msg=Created pod: eval-sanitize-3-r3-065-th6fg
65.0444,Pod,MODIFIED,eval-sanitize-3-r3-065-th6fg,phase=Pending node=None
65.0447,Event,ADDED,eval-sanitize-3-r3-065-th6fg.18d3d303ec772f28,"reason=FailedScheduling count=None msg=0/6 nodes are available: 1 c_wall violated: 1 conflicting context pair(s) with node memory, 5 node(s) had untolerated taint(s). no new claims to deallocate, preemption: 0/6 nodes are available: 1 No preemption victims found for incoming pod, 5 Preemption is not helpful for scheduling."
65.0448,TaskRequest,MODIFIED,eval-sanitize-3-r3-065,phase=Scheduled job=None
65.0518,Event,ADDED,eval-sanitize-3-r3-065-th6fg.18d3d303ecf5ee85,"reason=FailedScheduling count=None msg=0/6 nodes are available: 1 c_wall violated: 1 conflicting context pair(s) with node memory, 5 node(s) had untolerated taint(s). no new claims to deallocate, preemption: 0/6 nodes are available: 1 No preemption victims found for incoming pod, 5 Preemption is not helpful for scheduling."
65.0554,Job,MODIFIED,eval-sanitize-3-r3-064,
65.0641,Job,MODIFIED,eval-sanitize-3-r3-064,
65.4702,Job,MODIFIED,eval-sanitize-3-r3-062,
65.4772,Job,MODIFIED,eval-sanitize-3-r3-058,
65.4787,Job,MODIFIED,eval-sanitize-3-r3-062,
65.4855,Job,MODIFIED,eval-sanitize-3-r3-058,
65.51,Job,MODIFIED,eval-sanitize-3-r3-051,
65.5144,Job,MODIFIED,eval-sanitize-3-r3-051,
65.5172,Event,ADDED,eval-sanitize-3-r3-051.18d3d30408c6553a,reason=Completed count=1 msg=Job completed
65.5262,Job,MODIFIED,eval-sanitize-3-r3-051,
65.5337,Pod,MODIFIED,eval-sanitize-3-r3-054-mhh2r,phase=Running node=kind-worker5
65.5354,TaskRequest,MODIFIED,eval-sanitize-3-r3-051,phase=Complete job=None
65.5383,Job,MODIFIED,eval-sanitize-3-r3-053,
65.5394,Job,MODIFIED,eval-sanitize-3-r3-052,
65.548,Pod,MODIFIED,eval-sanitize-3-r3-052-qdx5l,phase=Succeeded node=kind-worker5
65.5519,Job,MODIFIED,eval-sanitize-3-r3-051,
65.5538,Job,MODIFIED,eval-sanitize-3-r3-052,
65.5547,Job,MODIFIED,eval-sanitize-3-r3-053,
65.5591,Event,MODIFIED,eval-sanitize-3-r3-065-th6fg.18d3d303ecf5ee85,"reason=FailedScheduling count=None msg=0/6 nodes are available: 1 c_wall violated: 1 conflicting context pair(s) with node memory, 5 node(s) had untolerated taint(s). no new claims to deallocate, preemption: 0/6 nodes are available: 1 No preemption victims found for incoming pod, 5 Preemption is not helpful for scheduling."
65.7085,Pod,MODIFIED,eval-sanitize-3-r3-053-f45f7,phase=Succeeded node=kind-worker5
66.0124,TaskRequest,ADDED,eval-sanitize-3-r3-066,phase=None job=None
66.0157,TaskRequest,MODIFIED,eval-sanitize-3-r3-066,phase=Pending job=None
66.0315,Job,ADDED,eval-sanitize-3-r3-066,
66.0385,Pod,ADDED,eval-sanitize-3-r3-066-zt8fx,phase=Pending node=None
66.0399,TaskRequest,MODIFIED,eval-sanitize-3-r3-066,phase=Scheduled job=None
66.0406,Job,MODIFIED,eval-sanitize-3-r3-066,
66.0414,Job,MODIFIED,eval-sanitize-3-r3-065,
66.0448,Event,ADDED,eval-sanitize-3-r3-066.18d3d304280985b2,reason=SuccessfulCreate count=1 msg=Created pod: eval-sanitize-3-r3-066-zt8fx
66.0474,Pod,MODIFIED,eval-sanitize-3-r3-066-zt8fx,phase=Pending node=None
66.0478,Event,ADDED,eval-sanitize-3-r3-066-zt8fx.18d3d30428482ecb,"reason=FailedScheduling count=None msg=0/6 nodes are available: 1 c_wall violated: 2 conflicting context pair(s) with node memory, 5 node(s) had untolerated taint(s). no new claims to deallocate, preemption: 0/6 nodes are available: 1 No preemption victims found for incoming pod, 5 Preemption is not helpful for scheduling."
66.0486,TaskRequest,MODIFIED,eval-sanitize-3-r3-066,phase=Scheduled job=None
66.051,Job,MODIFIED,eval-sanitize-3-r3-065,
66.0539,Event,ADDED,eval-sanitize-3-r3-066-zt8fx.18d3d30428bf3980,"reason=FailedScheduling count=None msg=0/6 nodes are available: 1 c_wall violated: 2 conflicting context pair(s) with node memory, 5 node(s) had untolerated taint(s). no new claims to deallocate, preemption: 0/6 nodes are available: 1 No preemption victims found for incoming pod, 5 Preemption is not helpful for scheduling."
66.5293,Node,MODIFIED,kind-worker3,taints=1
66.5394,Job,MODIFIED,eval-sanitize-3-r3-054,
66.5434,Node,MODIFIED,kind-worker3,taints=1
66.5451,Job,MODIFIED,eval-sanitize-3-r3-052,
66.546,Job,MODIFIED,eval-sanitize-3-r3-053,
66.5492,Job,MODIFIED,eval-sanitize-3-r3-054,
66.555,Job,MODIFIED,eval-sanitize-3-r3-052,
66.5581,Node,MODIFIED,kind-worker3,taints=0
66.5594,Pod,MODIFIED,eval-sanitize-3-r3-053-f45f7,phase=Succeeded node=kind-worker5
66.5606,Event,MODIFIED,eval-sanitize-3-r3-066-zt8fx.18d3d30428bf3980,"reason=FailedScheduling count=None msg=0/6 nodes are available: 1 c_wall violated: 2 conflicting context pair(s) with node memory, 5 node(s) had untolerated taint(s). no new claims to deallocate, preemption: 0/6 nodes are available: 1 No preemption victims found for incoming pod, 5 Preemption is not helpful for scheduling."
66.5608,Event,ADDED,eval-sanitize-3-r3-052.18d3d30446caa4da,reason=Completed count=1 msg=Job completed
66.5619,Job,MODIFIED,eval-sanitize-3-r3-053,
66.5658,Job,MODIFIED,eval-sanitize-3-r3-052,
66.5702,TaskRequest,MODIFIED,eval-sanitize-3-r3-052,phase=Complete job=None
66.5791,Job,MODIFIED,eval-sanitize-3-r3-052,
66.6238,Node,MODIFIED,kind-worker3,taints=0
66.625,Pod,MODIFIED,eval-sanitize-3-r3-061-n9dnt,phase=Pending node=kind-worker3
66.6292,Event,ADDED,eval-sanitize-3-r3-061-n9dnt.18d3d3044ae36756,reason=Scheduled count=None msg=Successfully assigned compute/eval-sanitize-3-r3-061-n9dnt to kind-worker3
66.6336,Pod,MODIFIED,eval-sanitize-3-r3-063-hzszc,phase=Pending node=kind-worker3
66.6364,Pod,MODIFIED,eval-sanitize-3-r3-061-n9dnt,phase=Pending node=kind-worker3
66.638,Node,MODIFIED,kind-worker3,taints=0
66.6406,Event,ADDED,eval-sanitize-3-r3-063-hzszc.18d3d3044b797d1b,reason=Scheduled count=None msg=Successfully assigned compute/eval-sanitize-3-r3-063-hzszc to kind-worker3
66.6467,Node,MODIFIED,kind-worker3,taints=0
66.6488,Pod,MODIFIED,eval-sanitize-3-r3-063-hzszc,phase=Pending node=kind-worker3
66.6615,Node,MODIFIED,kind-worker3,taints=0
66.6717,Node,MODIFIED,kind-worker3,taints=0
66.6831,Pod,MODIFIED,eval-sanitize-3-r3-054-mhh2r,phase=Succeeded node=kind-worker5
66.7177,Pod,MODIFIED,eval-sanitize-3-r3-065-th6fg,phase=Pending node=None
66.7282,Pod,MODIFIED,eval-sanitize-3-r3-066-zt8fx,phase=Pending node=None
66.7382,Pod,MODIFIED,eval-sanitize-3-r3-064-qptqh,phase=Pending node=None
66.7465,Pod,MODIFIED,eval-sanitize-3-r3-060-jbqts,phase=Pending node=kind-worker3
66.75,Node,MODIFIED,kind-worker4,taints=1
66.7505,Event,ADDED,eval-sanitize-3-r3-060-jbqts.18d3d3045235110c,reason=Scheduled count=None msg=Successfully assigned compute/eval-sanitize-3-r3-060-jbqts to kind-worker3
66.7602,Pod,MODIFIED,eval-sanitize-3-r3-060-jbqts,phase=Pending node=kind-worker3
66.8226,Event,ADDED,eval-sanitize-3-r3-065-th6fg.18d3d30456816627,"reason=FailedScheduling count=None msg=0/6 nodes are available: 2 c_wall violated: 1 conflicting context pair(s) with node memory, 4 node(s) had untolerated taint(s). no new claims to deallocate, preemption: 0/6 nodes are available: 2 No preemption victims found for incoming pod, 4 Preemption is not helpful for scheduling."
66.8268,Pod,MODIFIED,eval-sanitize-3-r3-066-zt8fx,phase=Pending node=None
66.8272,Event,ADDED,eval-sanitize-3-r3-066-zt8fx.18d3d30456acaded,"reason=FailedScheduling count=None msg=0/6 nodes are available: 1 c_wall violated: 1 conflicting context pair(s) with node memory, 5 node(s) had untolerated taint(s). no new claims to deallocate, preemption: 0/6 nodes are available: 1 No preemption victims found for incoming pod, 5 Preemption is not helpful for scheduling."
66.8342,Pod,MODIFIED,eval-sanitize-3-r3-064-qptqh,phase=Pending node=None
66.8352,Event,ADDED,eval-sanitize-3-r3-064-qptqh.18d3d304572dcfa7,"reason=FailedScheduling count=None msg=0/6 nodes are available: 1 c_wall violated: 1 conflicting context pair(s) with node memory, 5 node(s) had untolerated taint(s). no new claims to deallocate, preemption: 0/6 nodes are available: 1 No preemption victims found for incoming pod, 5 Preemption is not helpful for scheduling."
66.8367,Node,MODIFIED,kind-worker5,taints=1
66.8431,Pod,MODIFIED,eval-sanitize-3-r3-065-th6fg,phase=Pending node=None
66.8434,Event,MODIFIED,eval-sanitize-3-r3-065-th6fg.18d3d30456816627,"reason=FailedScheduling count=None msg=0/6 nodes are available: 2 c_wall violated: 1 conflicting context pair(s) with node memory, 4 node(s) had untolerated taint(s). no new claims to deallocate, preemption: 0/6 nodes are available: 2 No preemption victims found for incoming pod, 4 Preemption is not helpful for scheduling."
66.8526,Event,ADDED,eval-sanitize-3-r3-066-zt8fx.18d3d3045827a1e0,"reason=FailedScheduling count=None msg=0/6 nodes are available: 1 c_wall violated: 1 conflicting context pair(s) with node memory, 5 node(s) had untolerated taint(s). no new claims to deallocate, preemption: 0/6 nodes are available: 1 No preemption victims found for incoming pod, 5 Preemption is not helpful for scheduling."
66.9181,Event,ADDED,eval-sanitize-3-r3-064-qptqh.18d3d3045c339c9d,"reason=FailedScheduling count=None msg=0/6 nodes are available: 1 c_wall violated: 1 conflicting context pair(s) with node memory, 5 node(s) had untolerated taint(s). no new claims to deallocate, preemption: 0/6 nodes are available: 1 No preemption victims found for incoming pod, 5 Preemption is not helpful for scheduling."
66.9235,Node,MODIFIED,kind-worker4,taints=1
66.9238,Event,ADDED,eval-sanitize-3-r3-065-th6fg.18d3d3045c67f249,"reason=FailedScheduling count=None msg=0/6 nodes are available: 1 c_wall violated: 1 conflicting context pair(s) with node memory, 5 node(s) had untolerated taint(s). no new claims to deallocate, preemption: 0/6 nodes are available: 1 No preemption victims found for incoming pod, 5 Preemption is not helpful for scheduling."
66.9307,Event,MODIFIED,eval-sanitize-3-r3-066-zt8fx.18d3d3045827a1e0,"reason=FailedScheduling count=None msg=0/6 nodes are available: 1 c_wall violated: 1 conflicting context pair(s) with node memory, 5 node(s) had untolerated taint(s). no new claims to deallocate, preemption: 0/6 nodes are available: 1 No preemption victims found for incoming pod, 5 Preemption is not helpful for scheduling."
66.9367,Event,MODIFIED,eval-sanitize-3-r3-064-qptqh.18d3d3045c339c9d,"reason=FailedScheduling count=None msg=0/6 nodes are available: 1 c_wall violated: 1 conflicting context pair(s) with node memory, 5 node(s) had untolerated taint(s). no new claims to deallocate, preemption: 0/6 nodes are available: 1 No preemption victims found for incoming pod, 5 Preemption is not helpful for scheduling."
66.9378,Event,MODIFIED,eval-sanitize-3-r3-065-th6fg.18d3d3045c67f249,"reason=FailedScheduling count=None msg=0/6 nodes are available: 1 c_wall violated: 1 conflicting context pair(s) with node memory, 5 node(s) had untolerated taint(s). no new claims to deallocate, preemption: 0/6 nodes are available: 1 No preemption victims found for incoming pod, 5 Preemption is not helpful for scheduling."
67.0086,TaskRequest,ADDED,eval-sanitize-3-r3-067,phase=None job=None
67.012,TaskRequest,MODIFIED,eval-sanitize-3-r3-067,phase=Pending job=None
67.0283,Job,ADDED,eval-sanitize-3-r3-067,
67.0367,Node,MODIFIED,kind-worker5,taints=0
67.0375,Pod,ADDED,eval-sanitize-3-r3-067-jvkdr,phase=Pending node=None
67.0376,TaskRequest,MODIFIED,eval-sanitize-3-r3-067,phase=Scheduled job=None
67.0386,Job,MODIFIED,eval-sanitize-3-r3-067,
67.0421,Event,ADDED,eval-sanitize-3-r3-067.18d3d304636f6470,reason=SuccessfulCreate count=1 msg=Created pod: eval-sanitize-3-r3-067-jvkdr
67.046,Job,MODIFIED,eval-sanitize-3-r3-066,
67.0475,Pod,MODIFIED,eval-sanitize-3-r3-066-zt8fx,phase=Pending node=kind-worker5
67.0477,TaskRequest,MODIFIED,eval-sanitize-3-r3-067,phase=Scheduled job=None
67.0542,Pod,MODIFIED,eval-sanitize-3-r3-067-jvkdr,phase=Pending node=kind-worker5
67.0546,Event,ADDED,eval-sanitize-3-r3-066-zt8fx.18d3d304640db6f9,reason=Scheduled count=None msg=Successfully assigned compute/eval-sanitize-3-r3-066-zt8fx to kind-worker5
67.0611,Node,MODIFIED,kind-worker5,taints=0
67.0632,Event,ADDED,eval-sanitize-3-r3-067-jvkdr.18d3d304647a34fb,reason=Scheduled count=None msg=Successfully assigned compute/eval-sanitize-3-r3-067-jvkdr to kind-worker5
67.0637,Event,ADDED,eval-sanitize-3-r3-061-n9dnt.18d3d3046497fb3f,"reason=Pulled count=1 msg=Container image ""busybox:musl"" already present on machine"
67.0646,Job,MODIFIED,eval-sanitize-3-r3-066,
67.0656,Pod,MODIFIED,eval-sanitize-3-r3-064-qptqh,phase=Pending node=kind-worker5
67.0668,Pod,MODIFIED,eval-sanitize-3-r3-066-zt8fx,phase=Pending node=kind-worker5
67.0709,Event,ADDED,eval-sanitize-3-r3-064-qptqh.18d3d304651b5300,reason=Scheduled count=None msg=Successfully assigned compute/eval-sanitize-3-r3-064-qptqh to kind-worker5
67.0712,Event,ADDED,eval-sanitize-3-r3-063-hzszc.18d3d3046544c9c6,"reason=Pulled count=1 msg=Container image ""busybox:musl"" already present on machine"
67.0776,Pod,MODIFIED,eval-sanitize-3-r3-067-jvkdr,phase=Pending node=kind-worker5
67.0821,Node,MODIFIED,kind-worker5,taints=0
67.0873,Pod,MODIFIED,eval-sanitize-3-r3-064-qptqh,phase=Pending node=kind-worker5
67.0966,Node,MODIFIED,kind-worker5,taints=0
67.1023,Event,ADDED,eval-sanitize-3-r3-061-n9dnt.18d3d3046736b7b3,reason=Created count=1 msg=Created container: task
67.109,Event,ADDED,eval-sanitize-3-r3-063-hzszc.18d3d3046765d132,reason=Created count=1 msg=Created container: task
67.1214,Pod,MODIFIED,eval-sanitize-3-r3-065-th6fg,phase=Pending node=kind-worker5
67.1251,Node,MODIFIED,kind-worker5,taints=0
67.1254,Event,ADDED,eval-sanitize-3-r3-065-th6fg.18d3d304687e49da,reason=Scheduled count=None msg=Successfully assigned compute/eval-sanitize-3-r3-065-th6fg to kind-worker5
67.1346,Pod,MODIFIED,eval-sanitize-3-r3-065-th6fg,phase=Pending node=kind-worker5
67.1393,Node,MODIFIED,kind-worker5,taints=0
67.1845,Event,ADDED,eval-sanitize-3-r3-061-n9dnt.18d3d3046bfa5738,reason=Started count=1 msg=Started container task
67.188,Event,ADDED,eval-sanitize-3-r3-063-hzszc.18d3d3046c377380,reason=Started count=1 msg=Started container task
67.2018,Event,ADDED,eval-sanitize-3-r3-060-jbqts.18d3d3046d2432c4,"reason=Pulled count=1 msg=Container image ""busybox:musl"" already present on machine"
67.2195,Event,ADDED,eval-sanitize-3-r3-060-jbqts.18d3d3046e332e4d,reason=Created count=1 msg=Created container: task
67.2856,Event,ADDED,eval-sanitize-3-r3-060-jbqts.18d3d3047212b8a6,reason=Started count=1 msg=Started container task
67.3642,Pod,MODIFIED,eval-sanitize-3-r3-055-26snf,phase=Running node=kind-worker2
67.3704,Pod,MODIFIED,eval-sanitize-3-r3-056-kbj7h,phase=Running node=kind-worker2
67.4988,Pod,MODIFIED,eval-sanitize-3-r3-063-hzszc,phase=Running node=kind-worker3
67.5062,Pod,MODIFIED,eval-sanitize-3-r3-061-n9dnt,phase=Running node=kind-worker3
67.5119,Event,ADDED,eval-sanitize-3-r3-066-zt8fx.18d3d3047f4de121,"reason=Pulled count=1 msg=Container image ""busybox:musl"" already present on machine"
67.5192,Pod,MODIFIED,eval-sanitize-3-r3-060-jbqts,phase=Running node=kind-worker3
67.5196,Event,ADDED,eval-sanitize-3-r3-067-jvkdr.18d3d3047f93cf9a,"reason=Pulled count=1 msg=Container image ""busybox:musl"" already present on machine"
67.524,Event,ADDED,eval-sanitize-3-r3-064-qptqh.18d3d304804fc96c,"reason=Pulled count=1 msg=Container image ""busybox:musl"" already present on machine"
67.5401,Event,ADDED,eval-sanitize-3-r3-066-zt8fx.18d3d3048129231a,reason=Created count=1 msg=Created container: task
67.5472,Job,MODIFIED,eval-sanitize-3-r3-054,
67.5488,Event,ADDED,eval-sanitize-3-r3-067-jvkdr.18d3d30481c98dd9,reason=Created count=1 msg=Created container: task
67.5525,Job,MODIFIED,eval-sanitize-3-r3-053,
67.5607,Pod,MODIFIED,eval-sanitize-3-r3-054-mhh2r,phase=Succeeded node=kind-worker5
67.5644,Job,MODIFIED,eval-sanitize-3-r3-053,
67.5656,Job,MODIFIED,eval-sanitize-3-r3-054,
67.5661,Event,ADDED,eval-sanitize-3-r3-064-qptqh.18d3d30482693b00,reason=Created count=1 msg=Created container: task
67.5686,Event,ADDED,eval-sanitize-3-r3-053.18d3d30482fa409d,reason=Completed count=1 msg=Job completed
67.5757,Job,MODIFIED,eval-sanitize-3-r3-053,
67.5797,Event,ADDED,eval-sanitize-3-r3-065-th6fg.18d3d304839f1a55,"reason=Pulled count=1 msg=Container image ""busybox:musl"" already present on machine"
67.5836,TaskRequest,MODIFIED,eval-sanitize-3-r3-053,phase=Complete job=None
67.5942,Job,MODIFIED,eval-sanitize-3-r3-053,
67.6025,Event,ADDED,eval-sanitize-3-r3-065-th6fg.18d3d3048500aea9,reason=Created count=1 msg=Created container: task
67.6306,Job,MODIFIED,eval-sanitize-3-r3-061,
67.6386,Job,MODIFIED,eval-sanitize-3-r3-063,
67.6416,Job,MODIFIED,eval-sanitize-3-r3-061,
67.642,Event,ADDED,eval-sanitize-3-r3-065-th6fg.18d3d30487353330,reason=Started count=1 msg=Started container task
67.6474,Event,ADDED,eval-sanitize-3-r3-066-zt8fx.18d3d3048792b9ba,reason=Started count=1 msg=Started container task
67.652,Job,MODIFIED,eval-sanitize-3-r3-063,
67.6535,Event,ADDED,eval-sanitize-3-r3-064-qptqh.18d3d304881bf586,reason=Started count=1 msg=Started container task
67.657,Event,ADDED,eval-sanitize-3-r3-067-jvkdr.18d3d304881f4f70,reason=Started count=1 msg=Started container task
67.7521,Job,MODIFIED,eval-sanitize-3-r3-060,
67.7616,Job,MODIFIED,eval-sanitize-3-r3-060,
68.0092,TaskRequest,ADDED,eval-sanitize-3-r3-068,phase=None job=None
68.0128,TaskRequest,MODIFIED,eval-sanitize-3-r3-068,phase=Pending job=None
68.0275,Job,ADDED,eval-sanitize-3-r3-068,
68.0325,Pod,ADDED,eval-sanitize-3-r3-068-q5jwl,phase=Pending node=None
68.0345,TaskRequest,MODIFIED,eval-sanitize-3-r3-068,phase=Scheduled job=None
68.0364,Event,ADDED,eval-sanitize-3-r3-068.18d3d3049edf4c40,reason=SuccessfulCreate count=1 msg=Created pod: eval-sanitize-3-r3-068-q5jwl
68.0374,Job,MODIFIED,eval-sanitize-3-r3-068,
68.0407,Job,MODIFIED,eval-sanitize-3-r3-067,
68.0422,TaskRequest,MODIFIED,eval-sanitize-3-r3-068,phase=Scheduled job=None
68.0461,Pod,MODIFIED,eval-sanitize-3-r3-068-q5jwl,phase=Pending node=kind-worker3
68.047,Job,MODIFIED,eval-sanitize-3-r3-068,
68.0498,Job,MODIFIED,eval-sanitize-3-r3-067,
68.053,Event,ADDED,eval-sanitize-3-r3-068-q5jwl.18d3d3049faf77bc,reason=Scheduled count=None msg=Successfully assigned compute/eval-sanitize-3-r3-068-q5jwl to kind-worker3
68.0559,Job,MODIFIED,eval-sanitize-3-r3-068,
68.0587,Pod,MODIFIED,eval-sanitize-3-r3-068-q5jwl,phase=Pending node=kind-worker3
68.3704,Job,MODIFIED,eval-sanitize-3-r3-055,
68.3754,Job,MODIFIED,eval-sanitize-3-r3-056,
68.3804,Job,MODIFIED,eval-sanitize-3-r3-055,
68.3925,Job,MODIFIED,eval-sanitize-3-r3-056,
68.4861,Event,ADDED,eval-sanitize-3-r3-068-q5jwl.18d3d304b9aaae49,"reason=Pulled count=1 msg=Container image ""busybox:musl"" already present on machine"
68.5059,Event,ADDED,eval-sanitize-3-r3-068-q5jwl.18d3d304bae44fb4,reason=Created count=1 msg=Created container: task
68.5262,Pod,MODIFIED,eval-sanitize-3-r3-056-kbj7h,phase=Succeeded node=kind-worker2
68.5405,Event,ADDED,eval-sanitize-3-r3-068-q5jwl.18d3d304bcdac488,reason=Started count=1 msg=Started container task
68.5442,Pod,MODIFIED,eval-sanitize-3-r3-067-jvkdr,phase=Running node=kind-worker5
68.5501,Pod,MODIFIED,eval-sanitize-3-r3-064-qptqh,phase=Running node=kind-worker5
68.553,Job,MODIFIED,eval-sanitize-3-r3-054,
68.5588,Pod,MODIFIED,eval-sanitize-3-r3-066-zt8fx,phase=Running node=kind-worker5
68.5605,Job,MODIFIED,eval-sanitize-3-r3-054,
68.5655,Pod,MODIFIED,eval-sanitize-3-r3-055-26snf,phase=Succeeded node=kind-worker2
68.5664,Event,ADDED,eval-sanitize-3-r3-054.18d3d304be5642a1,reason=Completed count=1 msg=Job completed
68.5678,Pod,MODIFIED,eval-sanitize-3-r3-065-th6fg,phase=Running node=kind-worker5
68.5692,Job,MODIFIED,eval-sanitize-3-r3-054,
68.5743,TaskRequest,MODIFIED,eval-sanitize-3-r3-054,phase=Complete job=None
68.5827,Job,MODIFIED,eval-sanitize-3-r3-054,
69.0214,TaskRequest,ADDED,eval-sanitize-3-r3-069,phase=None job=None
69.0265,TaskRequest,MODIFIED,eval-sanitize-3-r3-069,phase=Pending job=None
69.0402,Job,ADDED,eval-sanitize-3-r3-069,
69.0462,Job,MODIFIED,eval-sanitize-3-r3-067,
69.0477,TaskRequest,MODIFIED,eval-sanitize-3-r3-069,phase=Scheduled job=None
69.0487,Pod,ADDED,eval-sanitize-3-r3-069-7l2k7,phase=Pending node=None
69.0506,Job,MODIFIED,eval-sanitize-3-r3-069,
69.0529,Event,ADDED,eval-sanitize-3-r3-069.18d3d304db6e77f4,reason=SuccessfulCreate count=1 msg=Created pod: eval-sanitize-3-r3-069-7l2k7
69.0551,TaskRequest,MODIFIED,eval-sanitize-3-r3-069,phase=Scheduled job=None
69.0578,Job,MODIFIED,eval-sanitize-3-r3-067,
69.0681,Pod,MODIFIED,eval-sanitize-3-r3-069-7l2k7,phase=Pending node=kind-worker5
69.071,Event,ADDED,eval-sanitize-3-r3-069-7l2k7.18d3d304dc96244e,reason=Scheduled count=None msg=Successfully assigned compute/eval-sanitize-3-r3-069-7l2k7 to kind-worker5
69.0774,Node,MODIFIED,kind-worker5,taints=0
69.0797,Pod,MODIFIED,eval-sanitize-3-r3-069-7l2k7,phase=Pending node=kind-worker5
69.0877,Node,MODIFIED,kind-worker5,taints=0
69.3757,Job,MODIFIED,eval-sanitize-3-r3-055,
69.3825,Job,MODIFIED,eval-sanitize-3-r3-056,
69.3858,Job,MODIFIED,eval-sanitize-3-r3-055,
69.3872,Pod,MODIFIED,eval-sanitize-3-r3-055-26snf,phase=Succeeded node=kind-worker2
69.3914,Pod,MODIFIED,eval-sanitize-3-r3-056-kbj7h,phase=Succeeded node=kind-worker2
69.3933,Job,MODIFIED,eval-sanitize-3-r3-056,
69.4993,Event,ADDED,eval-sanitize-3-r3-069-7l2k7.18d3d304f5f29fc2,"reason=Pulled count=1 msg=Container image ""busybox:musl"" already present on machine"
69.5037,Pod,MODIFIED,eval-sanitize-3-r3-068-q5jwl,phase=Running node=kind-worker3
69.5194,Event,ADDED,eval-sanitize-3-r3-069-7l2k7.18d3d304f731a396,reason=Created count=1 msg=Created container: task
69.551,Event,ADDED,eval-sanitize-3-r3-069-7l2k7.18d3d304f9292de2,reason=Started count=1 msg=Started container task
69.5544,Job,MODIFIED,eval-sanitize-3-r3-064,
69.5635,Job,MODIFIED,eval-sanitize-3-r3-066,
69.5658,Job,MODIFIED,eval-sanitize-3-r3-064,
69.5725,Job,MODIFIED,eval-sanitize-3-r3-065,
