t_recv,kind,type,name,detail
0.0165,Event,ADDED,eval-sanitize-40-r2-010-wfsx6.18d40963574d50a3,"reason=FailedScheduling count=None msg=0/6 nodes are available: 1 c_wall violated: 2 conflicting context pair(s) with node memory, 1 node(s) had untolerated taint(s), 4 c_wall violated: 1 conflicting context pair(s) with node memory. no new claims to deallocate, preemption: 0/6 nodes are available: 1 Preemption is not helpful for scheduling, 5 No preemption victims found for incoming pod."
0.0175,Event,ADDED,eval-sanitize-40-r2-010-wfsx6.18d40963e02671c0,"reason=FailedScheduling count=None msg=0/6 nodes are available: 1 node(s) had untolerated taint(s), 2 c_wall violated: 2 conflicting context pair(s) with node memory, 3 c_wall violated: 1 conflicting context pair(s) with node memory. no new claims to deallocate, preemption: 0/6 nodes are available: 1 Preemption is not helpful for scheduling, 5 No preemption victims found for incoming pod."
0.0177,Event,ADDED,eval-sanitize-40-r2-010-wfsx6.18d40964164d16fb,"reason=FailedScheduling count=None msg=0/6 nodes are available: 1 node(s) had untolerated taint(s), 2 c_wall violated: 1 conflicting context pair(s) with node memory, 3 c_wall violated: 2 conflicting context pair(s) with node memory. no new claims to deallocate, preemption: 0/6 nodes are available: 1 Preemption is not helpful for scheduling, 5 No preemption victims found for incoming pod."
0.0181,Event,ADDED,eval-sanitize-40-r2-010-wfsx6.18d409645208ef55,"reason=FailedScheduling count=None msg=0/6 nodes are available: 1 c_wall violated: 3 conflicting context pair(s) with node memory, 1 node(s) had untolerated taint(s), 2 c_wall violated: 1 conflicting context pair(s) with node memory, 2 c_wall violated: 2 conflicting context pair(s) with node memory. no new claims to deallocate, preemption: 0/6 nodes are available: 1 Preemption is not helpful for scheduling, 5 No preemption victims found for incoming pod."
0.0183,Event,ADDED,eval-sanitize-40-r2-010-wfsx6.18d409658d747ad7,"reason=FailedScheduling count=None msg=0/6 nodes are available: 1 c_wall violated: 2 conflicting context pair(s) with node memory, 2 c_wall violated: 1 conflicting context pair(s) with node memory, 3 node(s) had untolerated taint(s). no new claims to deallocate, preemption: 0/6 nodes are available: 3 No preemption victims found for incoming pod, 3 Preemption is not helpful for scheduling."
0.0185,Event,ADDED,eval-sanitize-40-r2-010-wfsx6.18d4096593e8eea6,"reason=FailedScheduling count=None msg=0/6 nodes are available: 1 c_wall violated: 1 conflicting context pair(s) with node memory, 1 c_wall violated: 2 conflicting context pair(s) with node memory, 4 node(s) had untolerated taint(s). no new claims to deallocate, preemption: 0/6 nodes are available: 2 No preemption victims found for incoming pod, 4 Preemption is not helpful for scheduling."
0.022,Node,ADDED,kind-control-plane,taints=1
0.0223,Event,ADDED,eval-sanitize-40-r2-010-wfsx6.18d40965b90a7398,"reason=FailedScheduling count=None msg=0/6 nodes are available: 1 c_wall violated: 1 conflicting context pair(s) with node memory, 5 node(s) had untolerated taint(s). no new claims to deallocate, preemption: 0/6 nodes are available: 1 No preemption victims found for incoming pod, 5 Preemption is not helpful for scheduling."
0.0225,Event,ADDED,eval-sanitize-40-r2-016-st549.18d40964bcb5027d,"reason=FailedScheduling count=None msg=0/6 nodes are available: 1 c_wall violated: 3 conflicting context pair(s) with node memory, 1 node(s) had untolerated taint(s), 2 c_wall violated: 1 conflicting context pair(s) with node memory, 2 c_wall violated: 2 conflicting context pair(s) with node memory. no new claims to deallocate, preemption: 0/6 nodes are available: 1 Preemption is not helpful for scheduling, 5 No preemption victims found for incoming pod."
0.0227,Event,ADDED,eval-sanitize-40-r2-016-st549.18d409659393897f,"reason=FailedScheduling count=None msg=0/6 nodes are available: 1 c_wall violated: 1 conflicting context pair(s) with node memory, 1 c_wall violated: 2 conflicting context pair(s) with node memory, 4 node(s) had untolerated taint(s). no new claims to deallocate, preemption: 0/6 nodes are available: 2 No preemption victims found for incoming pod, 4 Preemption is not helpful for scheduling."
0.0239,Node,ADDED,kind-worker,taints=0
0.025,Node,ADDED,kind-worker2,taints=0
0.0253,Event,ADDED,eval-sanitize-40-r2-016-st549.18d40965b8da75ae,"reason=FailedScheduling count=None msg=0/6 nodes are available: 1 c_wall violated: 1 conflicting context pair(s) with node memory, 5 node(s) had untolerated taint(s). no new claims to deallocate, preemption: 0/6 nodes are available: 1 No preemption victims found for incoming pod, 5 Preemption is not helpful for scheduling."
0.0255,Event,ADDED,eval-sanitize-40-r2-020-lwlpx.18d40965a0b13418,"reason=FailedScheduling count=None msg=0/6 nodes are available: 1 c_wall violated: 1 conflicting context pair(s) with node memory, 1 c_wall violated: 2 conflicting context pair(s) with node memory, 4 node(s) had untolerated taint(s). no new claims to deallocate, preemption: 0/6 nodes are available: 2 No preemption victims found for incoming pod, 4 Preemption is not helpful for scheduling."
0.0256,Event,ADDED,eval-sanitize-40-r2-020-lwlpx.18d40965bcfd8642,"reason=FailedScheduling count=None msg=0/6 nodes are available: 1 c_wall violated: 1 conflicting context pair(s) with node memory, 5 node(s) had untolerated taint(s). no new claims to deallocate, preemption: 0/6 nodes are available: 1 No preemption victims found for incoming pod, 5 Preemption is not helpful for scheduling."
0.026,Event,ADDED,eval-sanitize-40-r2-021-mkxpd.18d40965db9ffc90,"reason=FailedScheduling count=None msg=0/6 nodes are available: 1 c_wall violated: 1 conflicting context pair(s) with node memory, 5 node(s) had untolerated taint(s). no new claims to deallocate, preemption: 0/6 nodes are available: 1 No preemption victims found for incoming pod, 5 Preemption is not helpful for scheduling."
0.0262,Event,ADDED,eval-sanitize-40-r2-022-ztmt9.18d4096617ad62f1,"reason=FailedScheduling count=None msg=0/6 nodes are available: 1 c_wall violated: 1 conflicting context pair(s) with node memory, 5 node(s) had untolerated taint(s). no new claims to deallocate, preemption: 0/6 nodes are available: 1 No preemption victims found for incoming pod, 5 Preemption is not helpful for scheduling."
0.0274,Node,ADDED,kind-worker3,taints=0
0.0277,Event,ADDED,eval-sanitize-40-r2-023-xt99s.18d40966545ab83f,"reason=FailedScheduling count=None msg=0/6 nodes are available: 1 c_wall violated: 1 conflicting context pair(s) with node memory, 5 node(s) had untolerated taint(s). no new claims to deallocate, preemption: 0/6 nodes are available: 1 No preemption victims found for incoming pod, 5 Preemption is not helpful for scheduling."
0.0279,Event,ADDED,eval-sanitize-40-r2-023-xt99s.18d4096747353a23,"reason=FailedScheduling count=None msg=0/6 nodes are available: 1 c_wall violated: 2 conflicting context pair(s) with node memory, 5 node(s) had untolerated taint(s). no new claims to deallocate, preemption: 0/6 nodes are available: 1 No preemption victims found for incoming pod, 5 Preemption is not helpful for scheduling."
0.0281,Event,ADDED,eval-sanitize-40-r2-023-xt99s.18d40968af254d4c,"reason=FailedScheduling count=None msg=0/6 nodes are available: 1 c_wall violated: 3 conflicting context pair(s) with node memory, 5 node(s) had untolerated taint(s). no new claims to deallocate, preemption: 0/6 nodes are available: 1 No preemption victims found for incoming pod, 5 Preemption is not helpful for scheduling."
0.0283,Event,ADDED,eval-sanitize-40-r2-024-nhld4.18d409668ea7d40a,"reason=FailedScheduling count=None msg=0/6 nodes are available: 1 c_wall violated: 1 conflicting context pair(s) with node memory, 5 node(s) had untolerated taint(s). no new claims to deallocate, preemption: 0/6 nodes are available: 1 No preemption victims found for incoming pod, 5 Preemption is not helpful for scheduling."
0.0287,Event,ADDED,eval-sanitize-40-r2-025-kmc6x.18d40966ca9bc79d,"reason=FailedScheduling count=None msg=0/6 nodes are available: 1 c_wall violated: 1 conflicting context pair(s) with node memory, 5 node(s) had untolerated taint(s). no new claims to deallocate, preemption: 0/6 nodes are available: 1 No preemption victims found for incoming pod, 5 Preemption is not helpful for scheduling."
0.0289,Event,ADDED,eval-sanitize-40-r2-026-6zvzg.18d4096706396b53,"reason=FailedScheduling count=None msg=0/6 nodes are available: 1 c_wall violated: 1 conflicting context pair(s) with node memory, 5 node(s) had untolerated taint(s). no new claims to deallocate, preemption: 0/6 nodes are available: 1 No preemption victims found for incoming pod, 5 Preemption is not helpful for scheduling."
0.0301,Node,ADDED,kind-worker4,taints=0
0.0304,Event,ADDED,eval-sanitize-40-r2-028-r49bh.18d4096780a3a74b,"reason=FailedScheduling count=None msg=0/6 nodes are available: 1 c_wall violated: 1 conflicting context pair(s) with node memory, 5 node(s) had untolerated taint(s). no new claims to deallocate, preemption: 0/6 nodes are available: 1 No preemption victims found for incoming pod, 5 Preemption is not helpful for scheduling."
0.0306,Event,ADDED,eval-sanitize-40-r2-028-r49bh.18d40968af76ec14,"reason=FailedScheduling count=None msg=0/6 nodes are available: 1 c_wall violated: 2 conflicting context pair(s) with node memory, 5 node(s) had untolerated taint(s). no new claims to deallocate, preemption: 0/6 nodes are available: 1 No preemption victims found for incoming pod, 5 Preemption is not helpful for scheduling."
0.0308,Event,ADDED,eval-sanitize-40-r2-028-r49bh.18d4096fc5c6c375,"reason=FailedScheduling count=None msg=0/6 nodes are available: 2 c_wall violated: 2 conflicting context pair(s) with node memory, 2 c_wall violated: 3 conflicting context pair(s) with node memory, 2 node(s) had untolerated taint(s). no new claims to deallocate, preemption: 0/6 nodes are available: 2 Preemption is not helpful for scheduling, 4 No preemption victims found for incoming pod."
0.0319,Node,ADDED,kind-worker5,taints=0
0.0323,Event,ADDED,eval-sanitize-40-r2-028-r49bh.18d409700de6d170,"reason=FailedScheduling count=None msg=0/6 nodes are available: 1 c_wall violated: 2 conflicting context pair(s) with node memory, 2 node(s) had untolerated taint(s), 3 c_wall violated: 3 conflicting context pair(s) with node memory. no new claims to deallocate, preemption: 0/6 nodes are available: 2 Preemption is not helpful for scheduling, 4 No preemption victims found for incoming pod."
0.0325,Event,ADDED,eval-sanitize-40-r2-028-r49bh.18d40978695666a7,"reason=FailedScheduling count=None msg=0/6 nodes are available: 1 c_wall violated: 3 conflicting context pair(s) with node memory, 5 node(s) had untolerated taint(s). no new claims to deallocate, preemption: 0/6 nodes are available: 1 No preemption victims found for incoming pod, 5 Preemption is not helpful for scheduling."
0.0327,Event,ADDED,eval-sanitize-40-r2-028-r49bh.18d40978abf5fae1,"reason=FailedScheduling count=None msg=0/6 nodes are available: 1 c_wall violated: 1 conflicting context pair(s) with node memory, 5 node(s) had untolerated taint(s). no new claims to deallocate, preemption: 0/6 nodes are available: 1 No preemption victims found for incoming pod, 5 Preemption is not helpful for scheduling."
0.0331,Event,ADDED,eval-sanitize-40-r2-030-hmrft.18d40967f55abaed,"reason=FailedScheduling count=None msg=0/6 nodes are available: 1 c_wall violated: 1 conflicting context pair(s) with node memory, 5 node(s) had untolerated taint(s). no new claims to deallocate, preemption: 0/6 nodes are available: 1 No preemption victims found for incoming pod, 5 Preemption is not helpful for scheduling."
0.0333,Event,ADDED,eval-sanitize-40-r2-030-hmrft.18d40968b1f77e42,"reason=FailedScheduling count=None msg=0/6 nodes are available: 1 c_wall violated: 2 conflicting context pair(s) with node memory, 5 node(s) had untolerated taint(s). no new claims to deallocate, preemption: 0/6 nodes are available: 1 No preemption victims found for incoming pod, 5 Preemption is not helpful for scheduling."
0.0336,Event,ADDED,eval-sanitize-40-r2-031-78956.18d40968307d03ba,"reason=FailedScheduling count=None msg=0/6 nodes are available: 1 c_wall violated: 1 conflicting context pair(s) with node memory, 5 node(s) had untolerated taint(s). no new claims to deallocate, preemption: 0/6 nodes are available: 1 No preemption victims found for incoming pod, 5 Preemption is not helpful for scheduling."
0.0338,Event,ADDED,eval-sanitize-40-r2-032-kbznk.18d409686b577d41,"reason=FailedScheduling count=None msg=0/6 nodes are available: 1 c_wall violated: 2 conflicting context pair(s) with node memory, 5 node(s) had untolerated taint(s). no new claims to deallocate, preemption: 0/6 nodes are available: 1 No preemption victims found for incoming pod, 5 Preemption is not helpful for scheduling."
0.034,Event,ADDED,eval-sanitize-40-r2-034-k4szm.18d40968e2a277bd,"reason=FailedScheduling count=None msg=0/6 nodes are available: 1 c_wall violated: 1 conflicting context pair(s) with node memory, 5 node(s) had untolerated taint(s). no new claims to deallocate, preemption: 0/6 nodes are available: 1 No preemption victims found for incoming pod, 5 Preemption is not helpful for scheduling."
0.0343,Event,ADDED,eval-sanitize-40-r2-035-9c652.18d409691e2c6960,"reason=FailedScheduling count=None msg=0/6 nodes are available: 1 c_wall violated: 2 conflicting context pair(s) with node memory, 5 node(s) had untolerated taint(s). no new claims to deallocate, preemption: 0/6 nodes are available: 1 No preemption victims found for incoming pod, 5 Preemption is not helpful for scheduling."
0.0345,Event,ADDED,eval-sanitize-40-r2-035-9c652.18d4096fa81d4e0e,"reason=FailedScheduling count=None msg=0/6 nodes are available: 2 c_wall violated: 2 conflicting context pair(s) with node memory, 2 c_wall violated: 3 conflicting context pair(s) with node memory, 2 node(s) had untolerated taint(s). no new claims to deallocate, preemption: 0/6 nodes are available: 2 Preemption is not helpful for scheduling, 4 No preemption victims found for incoming pod."
0.0347,Event,ADDED,eval-sanitize-40-r2-035-9c652.18d4097019651699,"reason=FailedScheduling count=None msg=0/6 nodes are available: 1 c_wall violated: 2 conflicting context pair(s) with node memory, 2 node(s) had untolerated taint(s), 3 c_wall violated: 3 conflicting context pair(s) with node memory. no new claims to deallocate, preemption: 0/6 nodes are available: 2 Preemption is not helpful for scheduling, 4 No preemption victims found for incoming pod."
0.035,Event,ADDED,eval-sanitize-40-r2-035-9c652.18d4097863ac8417,"reason=FailedScheduling count=None msg=0/6 nodes are available: 1 c_wall violated: 3 conflicting context pair(s) with node memory, 5 node(s) had untolerated taint(s). no new claims to deallocate, preemption: 0/6 nodes are available: 1 No preemption victims found for incoming pod, 5 Preemption is not helpful for scheduling."
0.0352,Event,ADDED,eval-sanitize-40-r2-035-9c652.18d40978ab421c27,"reason=FailedScheduling count=None msg=0/6 nodes are available: 1 c_wall violated: 1 conflicting context pair(s) with node memory, 5 node(s) had untolerated taint(s). no new claims to deallocate, preemption: 0/6 nodes are available: 1 No preemption victims found for incoming pod, 5 Preemption is not helpful for scheduling."
0.0354,Event,ADDED,eval-sanitize-40-r2-038-2wdnv.18d40969d1451f5a,"reason=FailedScheduling count=None msg=0/6 nodes are available: 1 c_wall violated: 2 conflicting context pair(s) with node memory, 5 node(s) had untolerated taint(s). no new claims to deallocate, preemption: 0/6 nodes are available: 1 No preemption victims found for incoming pod, 5 Preemption is not helpful for scheduling."
0.0357,Event,ADDED,eval-sanitize-40-r2-038-2wdnv.18d4096fb9f1711d,"reason=FailedScheduling count=None msg=0/6 nodes are available: 2 c_wall violated: 2 conflicting context pair(s) with node memory, 2 c_wall violated: 3 conflicting context pair(s) with node memory, 2 node(s) had untolerated taint(s). no new claims to deallocate, preemption: 0/6 nodes are available: 2 Preemption is not helpful for scheduling, 4 No preemption victims found for incoming pod."
0.0359,Event,ADDED,eval-sanitize-40-r2-038-2wdnv.18d40970200e6bf0,"reason=FailedScheduling count=None msg=0/6 nodes are available: 1 c_wall violated: 2 conflicting context pair(s) with node memory, 2 node(s) had untolerated taint(s), 3 c_wall violated: 3 conflicting context pair(s) with node memory. no new claims to deallocate, preemption: 0/6 nodes are available: 2 Preemption is not helpful for scheduling, 4 No preemption victims found for incoming pod."
0.0362,Event,ADDED,eval-sanitize-40-r2-038-2wdnv.18d40978673610ab,"reason=FailedScheduling count=None msg=0/6 nodes are available: 1 c_wall violated: 3 conflicting context pair(s) with node memory, 5 node(s) had untolerated taint(s). no new claims to deallocate, preemption: 0/6 nodes are available: 1 No preemption victims found for incoming pod, 5 Preemption is not helpful for scheduling."
0.0364,Event,ADDED,eval-sanitize-40-r2-038-2wdnv.18d40978ab9a420a,"reason=FailedScheduling count=None msg=0/6 nodes are available: 1 c_wall violated: 1 conflicting context pair(s) with node memory, 5 node(s) had untolerated taint(s). no new claims to deallocate, preemption: 0/6 nodes are available: 1 No preemption victims found for incoming pod, 5 Preemption is not helpful for scheduling."
0.0366,Event,ADDED,eval-sanitize-40-r2-039-qvgxk.18d4096a0dd5280c,"reason=FailedScheduling count=None msg=0/6 nodes are available: 1 c_wall violated: 1 conflicting context pair(s) with node memory, 5 node(s) had untolerated taint(s). no new claims to deallocate, preemption: 0/6 nodes are available: 1 No preemption victims found for incoming pod, 5 Preemption is not helpful for scheduling."
0.0369,TaskRequest,ADDED,eval-sanitize-40-r4-000,phase=None job=None
0.0372,Event,ADDED,eval-sanitize-40-r2-040-756vn.18d4096a48a3b83b,"reason=FailedScheduling count=None msg=0/6 nodes are available: 1 c_wall violated: 2 conflicting context pair(s) with node memory, 5 node(s) had untolerated taint(s). no new claims to deallocate, preemption: 0/6 nodes are available: 1 No preemption victims found for incoming pod, 5 Preemption is not helpful for scheduling."
0.0374,Event,ADDED,eval-sanitize-40-r2-041-8nl6j.18d4096a83ec97cb,"reason=FailedScheduling count=None msg=0/6 nodes are available: 1 c_wall violated: 3 conflicting context pair(s) with node memory, 5 node(s) had untolerated taint(s). no new claims to deallocate, preemption: 0/6 nodes are available: 1 No preemption victims found for incoming pod, 5 Preemption is not helpful for scheduling."
0.0376,Event,ADDED,eval-sanitize-40-r2-042-kvmfb.18d4096abfcf88b7,"reason=FailedScheduling count=None msg=0/6 nodes are available: 1 c_wall violated: 2 conflicting context pair(s) with node memory, 5 node(s) had untolerated taint(s). no new claims to deallocate, preemption: 0/6 nodes are available: 1 No preemption victims found for incoming pod, 5 Preemption is not helpful for scheduling."
0.0379,Event,ADDED,eval-sanitize-40-r2-046-28hhw.18d4096baddd1583,"reason=FailedScheduling count=None msg=0/6 nodes are available: 1 c_wall violated: 1 conflicting context pair(s) with node memory, 5 node(s) had untolerated taint(s). no new claims to deallocate, preemption: 0/6 nodes are available: 1 No preemption victims found for incoming pod, 5 Preemption is not helpful for scheduling."
0.0381,Event,ADDED,eval-sanitize-40-r2-048-2rw9n.18d4096c26557961,"reason=FailedScheduling count=None msg=0/6 nodes are available: 1 c_wall violated: 2 conflicting context pair(s) with node memory, 5 node(s) had untolerated taint(s). no new claims to deallocate, preemption: 0/6 nodes are available: 1 No preemption victims found for incoming pod, 5 Preemption is not helpful for scheduling."
0.0383,Event,ADDED,eval-sanitize-40-r2-048-2rw9n.18d4096fa223b425,"reason=FailedScheduling count=None msg=0/6 nodes are available: 2 c_wall violated: 2 conflicting context pair(s) with node memory, 2 c_wall violated: 3 conflicting context pair(s) with node memory, 2 node(s) had untolerated taint(s). no new claims to deallocate, preemption: 0/6 nodes are available: 2 Preemption is not helpful for scheduling, 4 No preemption victims found for incoming pod."
0.0387,Event,ADDED,eval-sanitize-40-r2-048-2rw9n.18d40970138c4c7a,"reason=FailedScheduling count=None msg=0/6 nodes are available: 1 c_wall violated: 2 conflicting context pair(s) with node memory, 2 node(s) had untolerated taint(s), 3 c_wall violated: 3 conflicting context pair(s) with node memory. no new claims to deallocate, preemption: 0/6 nodes are available: 2 Preemption is not helpful for scheduling, 4 No preemption victims found for incoming pod."
0.0389,Event,ADDED,eval-sanitize-40-r2-048-2rw9n.18d409786300af4b,"reason=FailedScheduling count=None msg=0/6 nodes are available: 1 c_wall violated: 3 conflicting context pair(s) with node memory, 5 node(s) had untolerated taint(s). no new claims to deallocate, preemption: 0/6 nodes are available: 1 No preemption victims found for incoming pod, 5 Preemption is not helpful for scheduling."
0.0391,Event,ADDED,eval-sanitize-40-r2-048-2rw9n.18d40978aabccadd,"reason=FailedScheduling count=None msg=0/6 nodes are available: 1 c_wall violated: 1 conflicting context pair(s) with node memory, 5 node(s) had untolerated taint(s). no new claims to deallocate, preemption: 0/6 nodes are available: 1 No preemption victims found for incoming pod, 5 Preemption is not helpful for scheduling."
0.0395,Event,ADDED,eval-sanitize-40-r2-049-m2pw4.18d4096c60a8c569,"reason=FailedScheduling count=None msg=0/6 nodes are available: 1 c_wall violated: 3 conflicting context pair(s) with node memory, 5 node(s) had untolerated taint(s). no new claims to deallocate, preemption: 0/6 nodes are available: 1 No preemption victims found for incoming pod, 5 Preemption is not helpful for scheduling."
0.0397,Event,ADDED,eval-sanitize-40-r2-050-kjx5l.18d4096c9c4a2134,"reason=FailedScheduling count=None msg=0/6 nodes are available: 1 c_wall violated: 2 conflicting context pair(s) with node memory, 5 node(s) had untolerated taint(s). no new claims to deallocate, preemption: 0/6 nodes are available: 1 No preemption victims found for incoming pod, 5 Preemption is not helpful for scheduling."
0.0401,Event,ADDED,eval-sanitize-40-r2-050-kjx5l.18d4096fbfd2056d,"reason=FailedScheduling count=None msg=0/6 nodes are available: 2 c_wall violated: 2 conflicting context pair(s) with node memory, 2 c_wall violated: 3 conflicting context pair(s) with node memory, 2 node(s) had untolerated taint(s). no new claims to deallocate, preemption: 0/6 nodes are available: 2 Preemption is not helpful for scheduling, 4 No preemption victims found for incoming pod."
0.0403,Event,ADDED,eval-sanitize-40-r2-050-kjx5l.18d4097025f1b111,"reason=FailedScheduling count=None msg=0/6 nodes are available: 1 c_wall violated: 2 conflicting context pair(s) with node memory, 2 node(s) had untolerated taint(s), 3 c_wall violated: 3 conflicting context pair(s) with node memory. no new claims to deallocate, preemption: 0/6 nodes are available: 2 Preemption is not helpful for scheduling, 4 No preemption victims found for incoming pod."
0.0405,Event,ADDED,eval-sanitize-40-r2-050-kjx5l.18d409786928a9e3,"reason=FailedScheduling count=None msg=0/6 nodes are available: 1 c_wall violated: 3 conflicting context pair(s) with node memory, 5 node(s) had untolerated taint(s). no new claims to deallocate, preemption: 0/6 nodes are available: 1 No preemption victims found for incoming pod, 5 Preemption is not helpful for scheduling."
0.0408,Event,ADDED,eval-sanitize-40-r2-050-kjx5l.18d40978abc7b7c9,"reason=FailedScheduling count=None msg=0/6 nodes are available: 1 c_wall violated: 1 conflicting context pair(s) with node memory, 5 node(s) had untolerated taint(s). no new claims to deallocate, preemption: 0/6 nodes are available: 1 No preemption victims found for incoming pod, 5 Preemption is not helpful for scheduling."
0.041,Event,ADDED,eval-sanitize-40-r2-051-v5b5j.18d4096cd8219599,"reason=FailedScheduling count=None msg=0/6 nodes are available: 1 c_wall violated: 2 conflicting context pair(s) with node memory, 5 node(s) had untolerated taint(s). no new claims to deallocate, preemption: 0/6 nodes are available: 1 No preemption victims found for incoming pod, 5 Preemption is not helpful for scheduling."
0.0412,Event,ADDED,eval-sanitize-40-r2-053-sd4tx.18d4096d502db698,"reason=FailedScheduling count=None msg=0/6 nodes are available: 1 c_wall violated: 1 conflicting context pair(s) with node memory, 5 node(s) had untolerated taint(s). no new claims to deallocate, preemption: 0/6 nodes are available: 1 No preemption victims found for incoming pod, 5 Preemption is not helpful for scheduling."
0.0416,Event,ADDED,eval-sanitize-40-r2-054-hbxd4.18d4096d8cce6bd5,"reason=FailedScheduling count=None msg=0/6 nodes are available: 1 c_wall violated: 3 conflicting context pair(s) with node memory, 5 node(s) had untolerated taint(s). no new claims to deallocate, preemption: 0/6 nodes are available: 1 No preemption victims found for incoming pod, 5 Preemption is not helpful for scheduling."
0.0418,Event,ADDED,eval-sanitize-40-r2-055-5mvxk.18d4096dc67adcda,"reason=FailedScheduling count=None msg=0/6 nodes are available: 1 c_wall violated: 2 conflicting context pair(s) with node memory, 5 node(s) had untolerated taint(s). no new claims to deallocate, preemption: 0/6 nodes are available: 1 No preemption victims found for incoming pod, 5 Preemption is not helpful for scheduling."
0.042,Event,ADDED,eval-sanitize-40-r2-057-f625x.18d4096e3df14112,"reason=FailedScheduling count=None msg=0/6 nodes are available: 1 c_wall violated: 2 conflicting context pair(s) with node memory, 5 node(s) had untolerated taint(s). no new claims to deallocate, preemption: 0/6 nodes are available: 1 No preemption victims found for incoming pod, 5 Preemption is not helpful for scheduling."
0.0424,Event,ADDED,eval-sanitize-40-r2-058-k5qmn.18d4096e79d6b7d0,"reason=FailedScheduling count=None msg=0/6 nodes are available: 1 c_wall violated: 1 conflicting context pair(s) with node memory, 5 node(s) had untolerated taint(s). no new claims to deallocate, preemption: 0/6 nodes are available: 1 No preemption victims found for incoming pod, 5 Preemption is not helpful for scheduling."
0.0426,Event,ADDED,eval-sanitize-40-r2-062-v8qrh.18d4096fb40b5f7a,"reason=FailedScheduling count=None msg=0/6 nodes are available: 1 c_wall violated: 2 conflicting context pair(s) with node memory, 2 node(s) had untolerated taint(s), 3 c_wall violated: 3 conflicting context pair(s) with node memory. no new claims to deallocate, preemption: 0/6 nodes are available: 2 Preemption is not helpful for scheduling, 4 No preemption victims found for incoming pod."
0.0429,Event,ADDED,eval-sanitize-40-r2-062-v8qrh.18d4097863d381a5,"reason=FailedScheduling count=None msg=0/6 nodes are available: 1 c_wall violated: 3 conflicting context pair(s) with node memory, 5 node(s) had untolerated taint(s). no new claims to deallocate, preemption: 0/6 nodes are available: 1 No preemption victims found for incoming pod, 5 Preemption is not helpful for scheduling."
0.0431,Event,ADDED,eval-sanitize-40-r2-074-d96sk.18d409725fc327ed,"reason=FailedScheduling count=None msg=0/6 nodes are available: 1 c_wall violated: 2 conflicting context pair(s) with node memory, 2 node(s) had untolerated taint(s), 3 c_wall violated: 3 conflicting context pair(s) with node memory. no new claims to deallocate, preemption: 0/6 nodes are available: 2 Preemption is not helpful for scheduling, 4 No preemption victims found for incoming pod."
0.0433,Event,ADDED,eval-sanitize-40-r2-074-d96sk.18d40978635d69c0,"reason=FailedScheduling count=None msg=0/6 nodes are available: 1 c_wall violated: 3 conflicting context pair(s) with node memory, 5 node(s) had untolerated taint(s). no new claims to deallocate, preemption: 0/6 nodes are available: 1 No preemption victims found for incoming pod, 5 Preemption is not helpful for scheduling."
0.0435,Event,ADDED,eval-sanitize-40-r2-074-d96sk.18d40978ab1660ea,"reason=FailedScheduling count=None msg=0/6 nodes are available: 1 c_wall violated: 1 conflicting context pair(s) with node memory, 5 node(s) had untolerated taint(s). no new claims to deallocate, preemption: 0/6 nodes are available: 1 No preemption victims found for incoming pod, 5 Preemption is not helpful for scheduling."
0.0436,Event,ADDED,eval-sanitize-40-r2-078-l6gvn.18d40973bb145ad5,"reason=FailedScheduling count=None msg=0/6 nodes are available: 1 c_wall violated: 2 conflicting context pair(s) with node memory, 2 node(s) had untolerated taint(s), 3 c_wall violated: 3 conflicting context pair(s) with node memory. no new claims to deallocate, preemption: 0/6 nodes are available: 2 Preemption is not helpful for scheduling, 4 No preemption victims found for incoming pod."
0.0438,Event,ADDED,eval-sanitize-40-r2-078-l6gvn.18d4097863333b56,"reason=FailedScheduling count=None msg=0/6 nodes are available: 1 c_wall violated: 3 conflicting context pair(s) with node memory, 5 node(s) had untolerated taint(s). no new claims to deallocate, preemption: 0/6 nodes are available: 1 No preemption victims found for incoming pod, 5 Preemption is not helpful for scheduling."
0.044,Event,ADDED,eval-sanitize-40-r2-078-l6gvn.18d40978aaecbeea,"reason=FailedScheduling count=None msg=0/6 nodes are available: 1 c_wall violated: 1 conflicting context pair(s) with node memory, 5 node(s) had untolerated taint(s). no new claims to deallocate, preemption: 0/6 nodes are available: 1 No preemption victims found for incoming pod, 5 Preemption is not helpful for scheduling."
0.0442,Event,ADDED,eval-sanitize-40-r2-085-l9hq2.18d40974fd816872,"reason=FailedScheduling count=None msg=0/6 nodes are available: 1 c_wall violated: 2 conflicting context pair(s) with node memory, 2 node(s) had untolerated taint(s), 3 c_wall violated: 3 conflicting context pair(s) with node memory. no new claims to deallocate, preemption: 0/6 nodes are available: 2 Preemption is not helpful for scheduling, 4 No preemption victims found for incoming pod."
0.0444,Event,ADDED,eval-sanitize-40-r2-085-l9hq2.18d4097863f7022f,"reason=FailedScheduling count=None msg=0/6 nodes are available: 1 c_wall violated: 3 conflicting context pair(s) with node memory, 5 node(s) had untolerated taint(s). no new claims to deallocate, preemption: 0/6 nodes are available: 1 No preemption victims found for incoming pod, 5 Preemption is not helpful for scheduling."
0.0446,Event,ADDED,eval-sanitize-40-r2-085-l9hq2.18d40978ab6bb0ae,"reason=FailedScheduling count=None msg=0/6 nodes are available: 1 c_wall violated: 1 conflicting context pair(s) with node memory, 5 node(s) had untolerated taint(s). no new claims to deallocate, preemption: 0/6 nodes are available: 1 No preemption victims found for incoming pod, 5 Preemption is not helpful for scheduling."
0.0448,Event,ADDED,eval-sanitize-40-r2-088-nf8c8.18d4097597d0ef76,"reason=FailedScheduling count=None msg=0/6 nodes are available: 1 c_wall violated: 2 conflicting context pair(s) with node memory, 2 node(s) had untolerated taint(s), 3 c_wall violated: 3 conflicting context pair(s) with node memory. no new claims to deallocate, preemption: 0/6 nodes are available: 2 Preemption is not helpful for scheduling, 4 No preemption victims found for incoming pod."
0.0449,TaskRequest,MODIFIED,eval-sanitize-40-r4-000,phase=Pending job=None
0.0452,Event,ADDED,eval-sanitize-40-r2-088-nf8c8.18d409786384d82d,"reason=FailedScheduling count=None msg=0/6 nodes are available: 1 c_wall violated: 3 conflicting context pair(s) with node memory, 5 node(s) had untolerated taint(s). no new claims to deallocate, preemption: 0/6 nodes are available: 1 No preemption victims found for incoming pod, 5 Preemption is not helpful for scheduling."
0.0454,Event,ADDED,eval-sanitize-40-r2-089-hsw77.18d40975f7bae777,"reason=FailedScheduling count=None msg=0/6 nodes are available: 1 c_wall violated: 2 conflicting context pair(s) with node memory, 2 node(s) had untolerated taint(s), 3 c_wall violated: 1 conflicting context pair(s) with node memory. no new claims to deallocate, preemption: 0/6 nodes are available: 2 Preemption is not helpful for scheduling, 4 No preemption victims found for incoming pod."
0.0456,Event,ADDED,eval-sanitize-40-r2-089-hsw77.18d40978611959f5,"reason=FailedScheduling count=None msg=0/6 nodes are available: 1 c_wall violated: 1 conflicting context pair(s) with node memory, 5 node(s) had untolerated taint(s). no new claims to deallocate, preemption: 0/6 nodes are available: 1 No preemption victims found for incoming pod, 5 Preemption is not helpful for scheduling."
0.046,Event,ADDED,eval-sanitize-40-r2-090-vqvhv.18d40976391b7d3a,"reason=FailedScheduling count=None msg=0/6 nodes are available: 1 c_wall violated: 2 conflicting context pair(s) with node memory, 2 node(s) had untolerated taint(s), 3 c_wall violated: 3 conflicting context pair(s) with node memory. no new claims to deallocate, preemption: 0/6 nodes are available: 2 Preemption is not helpful for scheduling, 4 No preemption victims found for incoming pod."
0.0462,Event,ADDED,eval-sanitize-40-r2-090-vqvhv.18d4097860e5f952,"reason=FailedScheduling count=None msg=0/6 nodes are available: 1 c_wall violated: 3 conflicting context pair(s) with node memory, 5 node(s) had untolerated taint(s). no new claims to deallocate, preemption: 0/6 nodes are available: 1 No preemption victims found for incoming pod, 5 Preemption is not helpful for scheduling."
0.0465,Event,ADDED,eval-sanitize-40-r2-091-kjr2x.18d409767ab323de,"reason=FailedScheduling count=None msg=0/6 nodes are available: 1 c_wall violated: 2 conflicting context pair(s) with node memory, 2 node(s) had untolerated taint(s), 3 c_wall violated: 3 conflicting context pair(s) with node memory. no new claims to deallocate, preemption: 0/6 nodes are available: 2 Preemption is not helpful for scheduling, 4 No preemption victims found for incoming pod."
0.0468,Event,ADDED,eval-sanitize-40-r2-091-kjr2x.18d4097869a99d22,"reason=FailedScheduling count=None msg=0/6 nodes are available: 1 c_wall violated: 3 conflicting context pair(s) with node memory, 5 node(s) had untolerated taint(s). no new claims to deallocate, preemption: 0/6 nodes are available: 1 No preemption victims found for incoming pod, 5 Preemption is not helpful for scheduling."
0.047,Event,ADDED,eval-sanitize-40-r2-091-kjr2x.18d40978b0ad7474,"reason=FailedScheduling count=None msg=0/6 nodes are available: 1 c_wall violated: 1 conflicting context pair(s) with node memory, 5 node(s) had untolerated taint(s). no new claims to deallocate, preemption: 0/6 nodes are available: 1 No preemption victims found for incoming pod, 5 Preemption is not helpful for scheduling."
0.0472,Event,ADDED,eval-sanitize-40-r2-096-99gz6.18d40977b64a6277,"reason=FailedScheduling count=None msg=0/6 nodes are available: 1 c_wall violated: 2 conflicting context pair(s) with node memory, 2 node(s) had untolerated taint(s), 3 c_wall violated: 3 conflicting context pair(s) with node memory. no new claims to deallocate, preemption: 0/6 nodes are available: 2 Preemption is not helpful for scheduling, 4 No preemption victims found for incoming pod."
0.0476,Event,ADDED,eval-sanitize-40-r2-096-99gz6.18d40978697c4398,"reason=FailedScheduling count=None msg=0/6 nodes are available: 1 c_wall violated: 3 conflicting context pair(s) with node memory, 5 node(s) had untolerated taint(s). no new claims to deallocate, preemption: 0/6 nodes are available: 1 No preemption victims found for incoming pod, 5 Preemption is not helpful for scheduling."
0.0478,Event,ADDED,eval-sanitize-40-r2-097-vhcrh.18d40977fbcad898,"reason=FailedScheduling count=None msg=0/6 nodes are available: 1 c_wall violated: 2 conflicting context pair(s) with node memory, 2 node(s) had untolerated taint(s), 3 c_wall violated: 1 conflicting context pair(s) with node memory. no new claims to deallocate, preemption: 0/6 nodes are available: 2 Preemption is not helpful for scheduling, 4 No preemption victims found for incoming pod."
0.0482,Event,ADDED,eval-sanitize-40-r2-097-vhcrh.18d40978641e920c,"reason=FailedScheduling count=None msg=0/6 nodes are available: 1 c_wall violated: 1 conflicting context pair(s) with node memory, 5 node(s) had untolerated taint(s). no new claims to deallocate, preemption: 0/6 nodes are available: 1 No preemption victims found for incoming pod, 5 Preemption is not helpful for scheduling."
0.061,Job,ADDED,eval-sanitize-40-r4-000,
0.0648,TaskRequest,MODIFIED,eval-sanitize-40-r4-000,phase=Scheduled job=None
0.069,Pod,ADDED,eval-sanitize-40-r4-000-v4gjb,phase=Pending node=None
0.0715,Job,MODIFIED,eval-sanitize-40-r4-000,
0.0746,TaskRequest,MODIFIED,eval-sanitize-40-r4-000,phase=Scheduled job=None
0.0761,Event,ADDED,eval-sanitize-40-r4-000.18d409fb51b558fb,reason=SuccessfulCreate count=1 msg=Created pod: eval-sanitize-40-r4-000-v4gjb
0.0838,Pod,MODIFIED,eval-sanitize-40-r4-000-v4gjb,phase=Pending node=kind-worker3
0.0877,Event,ADDED,eval-sanitize-40-r4-000-v4gjb.18d409fb52920762,reason=Scheduled count=None msg=Successfully assigned compute/eval-sanitize-40-r4-000-v4gjb to kind-worker3
0.0933,Pod,MODIFIED,eval-sanitize-40-r4-000-v4gjb,phase=Pending node=kind-worker3
0.0955,Node,MODIFIED,kind-worker3,taints=0
0.1073,Node,MODIFIED,kind-worker3,taints=0
0.2205,Node,MODIFIED,kind-worker3,taints=1
0.2328,Node,MODIFIED,kind-worker3,taints=1
0.5221,Event,ADDED,eval-sanitize-40-r4-000-v4gjb.18d409fb6c5d4d66,"reason=Pulled count=1 msg=Container image ""busybox:musl"" already present on machine"
0.5379,Event,ADDED,eval-sanitize-40-r4-000-v4gjb.18d409fb6d711c8a,reason=Created count=1 msg=Created container: task
0.6076,Event,ADDED,eval-sanitize-40-r4-000-v4gjb.18d409fb71900b1b,reason=Started count=1 msg=Started container task
0.6754,Pod,MODIFIED,eval-sanitize-40-r4-000-v4gjb,phase=Running node=kind-worker3
1.0127,TaskRequest,ADDED,eval-sanitize-40-r4-001,phase=None job=None
1.0167,TaskRequest,MODIFIED,eval-sanitize-40-r4-001,phase=Pending job=None
1.0312,Job,ADDED,eval-sanitize-40-r4-001,
1.034,TaskRequest,MODIFIED,eval-sanitize-40-r4-001,phase=Scheduled job=None
1.0379,Pod,ADDED,eval-sanitize-40-r4-001-vsq9b,phase=Pending node=None
1.0401,Job,MODIFIED,eval-sanitize-40-r4-001,
1.0417,TaskRequest,MODIFIED,eval-sanitize-40-r4-001,phase=Scheduled job=None
1.0436,Event,ADDED,eval-sanitize-40-r4-001.18d409fb8b76829a,reason=SuccessfulCreate count=1 msg=Created pod: eval-sanitize-40-r4-001-vsq9b
1.0472,Pod,MODIFIED,eval-sanitize-40-r4-001-vsq9b,phase=Pending node=kind-worker5
1.0505,Event,ADDED,eval-sanitize-40-r4-001-vsq9b.18d409fb8bffe537,reason=Scheduled count=None msg=Successfully assigned compute/eval-sanitize-40-r4-001-vsq9b to kind-worker5
1.0589,Pod,MODIFIED,eval-sanitize-40-r4-001-vsq9b,phase=Pending node=kind-worker5
1.0614,Node,MODIFIED,kind-worker5,taints=0
1.0714,Node,MODIFIED,kind-worker5,taints=0
1.0742,Job,MODIFIED,eval-sanitize-40-r4-000,
1.0824,Job,MODIFIED,eval-sanitize-40-r4-000,
1.4659,Event,ADDED,eval-sanitize-40-r4-001-vsq9b.18d409fba4b9604d,"reason=Pulled count=1 msg=Container image ""busybox:musl"" already present on machine"
1.4928,Event,ADDED,eval-sanitize-40-r4-001-vsq9b.18d409fba6403805,reason=Created count=1 msg=Created container: task
1.5256,Event,ADDED,eval-sanitize-40-r4-001-vsq9b.18d409fba84a5167,reason=Started count=1 msg=Started container task
1.8591,Pod,MODIFIED,eval-sanitize-40-r4-001-vsq9b,phase=Running node=kind-worker5
2.0191,TaskRequest,ADDED,eval-sanitize-40-r4-002,phase=None job=None
2.0256,TaskRequest,MODIFIED,eval-sanitize-40-r4-002,phase=Pending job=None
2.0402,Job,ADDED,eval-sanitize-40-r4-002,
2.0436,Job,MODIFIED,eval-sanitize-40-r4-001,
2.0458,Pod,ADDED,eval-sanitize-40-r4-002-2rvfm,phase=Pending node=None
2.0475,TaskRequest,MODIFIED,eval-sanitize-40-r4-002,phase=Scheduled job=None
2.0516,Job,MODIFIED,eval-sanitize-40-r4-002,
2.0529,Event,ADDED,eval-sanitize-40-r4-002.18d409fbc787eea0,reason=SuccessfulCreate count=1 msg=Created pod: eval-sanitize-40-r4-002-2rvfm
2.0568,TaskRequest,MODIFIED,eval-sanitize-40-r4-002,phase=Scheduled job=None
2.0602,Job,MODIFIED,eval-sanitize-40-r4-001,
2.0621,Job,MODIFIED,eval-sanitize-40-r4-002,
2.0651,Pod,MODIFIED,eval-sanitize-40-r4-002-2rvfm,phase=Pending node=kind-worker
2.069,Event,ADDED,eval-sanitize-40-r4-002-2rvfm.18d409fbc8a7090e,reason=Scheduled count=None msg=Successfully assigned compute/eval-sanitize-40-r4-002-2rvfm to kind-worker
2.0731,Job,MODIFIED,eval-sanitize-40-r4-002,
2.0763,Node,MODIFIED,kind-worker,taints=0
2.0776,Pod,MODIFIED,eval-sanitize-40-r4-002-2rvfm,phase=Pending node=kind-worker
2.0871,Node,MODIFIED,kind-worker,taints=0
2.5078,Event,ADDED,eval-sanitize-40-r4-002-2rvfm.18d409fbe2ba33d8,"reason=Pulled count=1 msg=Container image ""busybox:musl"" already present on machine"
2.5267,Event,ADDED,eval-sanitize-40-r4-002-2rvfm.18d409fbe3f94a90,reason=Created count=1 msg=Created container: task
2.6139,Event,ADDED,eval-sanitize-40-r4-002-2rvfm.18d409fbe9173837,reason=Started count=1 msg=Started container task
2.8838,Pod,MODIFIED,eval-sanitize-40-r4-002-2rvfm,phase=Running node=kind-worker
3.0214,TaskRequest,ADDED,eval-sanitize-40-r4-003,phase=None job=None
3.025,TaskRequest,MODIFIED,eval-sanitize-40-r4-003,phase=Pending job=None
3.0413,Job,ADDED,eval-sanitize-40-r4-003,
3.0481,Pod,ADDED,eval-sanitize-40-r4-003-kgd84,phase=Pending node=None
3.0482,TaskRequest,MODIFIED,eval-sanitize-40-r4-003,phase=Scheduled job=None
3.0512,Job,MODIFIED,eval-sanitize-40-r4-003,
3.052,Job,MODIFIED,eval-sanitize-40-r4-002,
3.0533,Event,ADDED,eval-sanitize-40-r4-003.18d409fc0342ca9c,reason=SuccessfulCreate count=1 msg=Created pod: eval-sanitize-40-r4-003-kgd84
3.0552,TaskRequest,MODIFIED,eval-sanitize-40-r4-003,phase=Scheduled job=None
3.0612,Job,MODIFIED,eval-sanitize-40-r4-002,
3.0665,Pod,MODIFIED,eval-sanitize-40-r4-003-kgd84,phase=Pending node=kind-worker5
3.0718,Event,ADDED,eval-sanitize-40-r4-003-kgd84.18d409fc046034f8,reason=Scheduled count=None msg=Successfully assigned compute/eval-sanitize-40-r4-003-kgd84 to kind-worker5
3.0769,Node,MODIFIED,kind-worker5,taints=0
3.0787,Pod,MODIFIED,eval-sanitize-40-r4-003-kgd84,phase=Pending node=kind-worker5
3.0869,Node,MODIFIED,kind-worker5,taints=0
3.5107,Event,ADDED,eval-sanitize-40-r4-003-kgd84.18d409fc1e942ace,"reason=Pulled count=1 msg=Container image ""busybox:musl"" already present on machine"
3.5294,Event,ADDED,eval-sanitize-40-r4-003-kgd84.18d409fc1fbff025,reason=Created count=1 msg=Created container: task
3.5985,Event,ADDED,eval-sanitize-40-r4-003-kgd84.18d409fc23d5cf55,reason=Started count=1 msg=Started container task
3.8637,Pod,MODIFIED,eval-sanitize-40-r4-003-kgd84,phase=Running node=kind-worker5
4.0187,TaskRequest,ADDED,eval-sanitize-40-r4-004,phase=None job=None
4.0299,TaskRequest,MODIFIED,eval-sanitize-40-r4-004,phase=Pending job=None
4.0469,Job,ADDED,eval-sanitize-40-r4-004,
4.0526,Job,MODIFIED,eval-sanitize-40-r4-003,
4.0539,TaskRequest,MODIFIED,eval-sanitize-40-r4-004,phase=Scheduled job=None
4.0552,Pod,ADDED,eval-sanitize-40-r4-004-85p4k,phase=Pending node=None
4.0571,Job,MODIFIED,eval-sanitize-40-r4-004,
4.0595,Event,ADDED,eval-sanitize-40-r4-004.18d409fc3f47cb32,reason=SuccessfulCreate count=1 msg=Created pod: eval-sanitize-40-r4-004-85p4k
4.0611,TaskRequest,MODIFIED,eval-sanitize-40-r4-004,phase=Scheduled job=None
4.064,Job,MODIFIED,eval-sanitize-40-r4-003,
4.0686,Pod,MODIFIED,eval-sanitize-40-r4-004-85p4k,phase=Pending node=kind-worker4
4.076,Event,ADDED,eval-sanitize-40-r4-004-85p4k.18d409fc4023070a,reason=Scheduled count=None msg=Successfully assigned compute/eval-sanitize-40-r4-004-85p4k to kind-worker4
4.0795,Node,MODIFIED,kind-worker4,taints=0
4.0812,Pod,MODIFIED,eval-sanitize-40-r4-004-85p4k,phase=Pending node=kind-worker4
4.0898,Node,MODIFIED,kind-worker4,taints=0
4.5125,Event,ADDED,eval-sanitize-40-r4-004-85p4k.18d409fc5a3d7b5c,"reason=Pulled count=1 msg=Container image ""busybox:musl"" already present on machine"
4.535,Event,ADDED,eval-sanitize-40-r4-004-85p4k.18d409fc5baac10a,reason=Created count=1 msg=Created container: task
4.6099,Event,ADDED,eval-sanitize-40-r4-004-85p4k.18d409fc60234c30,reason=Started count=1 msg=Started container task
4.7008,Pod,MODIFIED,eval-sanitize-40-r4-004-85p4k,phase=Running node=kind-worker4
5.0136,TaskRequest,ADDED,eval-sanitize-40-r4-005,phase=None job=None
5.0171,TaskRequest,MODIFIED,eval-sanitize-40-r4-005,phase=Pending job=None
5.0321,Job,ADDED,eval-sanitize-40-r4-005,
5.0385,Pod,ADDED,eval-sanitize-40-r4-005-5d8sq,phase=Pending node=None
5.0386,TaskRequest,MODIFIED,eval-sanitize-40-r4-005,phase=Scheduled job=None
5.0427,Job,MODIFIED,eval-sanitize-40-r4-005,
5.0442,Event,ADDED,eval-sanitize-40-r4-005.18d409fc79e7e727,reason=SuccessfulCreate count=1 msg=Created pod: eval-sanitize-40-r4-005-5d8sq
5.0467,TaskRequest,MODIFIED,eval-sanitize-40-r4-005,phase=Scheduled job=None
5.0552,Pod,MODIFIED,eval-sanitize-40-r4-005-5d8sq,phase=Pending node=kind-worker2
5.0601,Job,MODIFIED,eval-sanitize-40-r4-004,
5.0605,Event,ADDED,eval-sanitize-40-r4-005-5d8sq.18d409fc7ae84c7d,reason=Scheduled count=None msg=Successfully assigned compute/eval-sanitize-40-r4-005-5d8sq to kind-worker2
5.0652,Node,MODIFIED,kind-worker2,taints=0
5.0672,Pod,MODIFIED,eval-sanitize-40-r4-005-5d8sq,phase=Pending node=kind-worker2
5.0694,Job,MODIFIED,eval-sanitize-40-r4-004,
5.075,Node,MODIFIED,kind-worker2,taints=0
5.4966,Event,ADDED,eval-sanitize-40-r4-005-5d8sq.18d409fc94fc60f3,"reason=Pulled count=1 msg=Container image ""busybox:musl"" already present on machine"
5.5149,Event,ADDED,eval-sanitize-40-r4-005-5d8sq.18d409fc9606ef31,reason=Created count=1 msg=Created container: task
5.5444,Event,ADDED,eval-sanitize-40-r4-005-5d8sq.18d409fc97da1422,reason=Started count=1 msg=Started container task
6.0126,TaskRequest,ADDED,eval-sanitize-40-r4-006,phase=None job=None
6.0162,TaskRequest,MODIFIED,eval-sanitize-40-r4-006,phase=Pending job=None
6.031,Job,ADDED,eval-sanitize-40-r4-006,
6.0349,TaskRequest,MODIFIED,eval-sanitize-40-r4-006,phase=Scheduled job=None
6.0378,Pod,ADDED,eval-sanitize-40-r4-006-q9nqf,phase=Pending node=None
6.0406,Job,MODIFIED,eval-sanitize-40-r4-006,
6.0445,Event,ADDED,eval-sanitize-40-r4-006.18d409fcb57d47d1,reason=SuccessfulCreate count=1 msg=Created pod: eval-sanitize-40-r4-006-q9nqf
6.0446,TaskRequest,MODIFIED,eval-sanitize-40-r4-006,phase=Scheduled job=None
6.0457,Job,MODIFIED,eval-sanitize-40-r4-005,
6.056,Job,MODIFIED,eval-sanitize-40-r4-005,
6.0601,Pod,MODIFIED,eval-sanitize-40-r4-006-q9nqf,phase=Pending node=kind-worker
6.0648,Event,ADDED,eval-sanitize-40-r4-006-q9nqf.18d409fcb6d1a031,reason=Scheduled count=None msg=Successfully assigned compute/eval-sanitize-40-r4-006-q9nqf to kind-worker
6.0699,Node,MODIFIED,kind-worker,taints=0
6.0717,Pod,MODIFIED,eval-sanitize-40-r4-006-q9nqf,phase=Pending node=kind-worker
6.0797,Node,MODIFIED,kind-worker,taints=0
6.3278,Pod,MODIFIED,eval-sanitize-40-r4-005-5d8sq,phase=Running node=kind-worker2
6.4863,Event,ADDED,eval-sanitize-40-r4-006-q9nqf.18d409fccffaf066,"reason=Pulled count=1 msg=Container image ""busybox:musl"" already present on machine"
6.5034,Event,ADDED,eval-sanitize-40-r4-006-q9nqf.18d409fcd1032b5c,reason=Created count=1 msg=Created container: task
6.5682,Event,ADDED,eval-sanitize-40-r4-006-q9nqf.18d409fcd4e05d4c,reason=Started count=1 msg=Started container task
6.893,Pod,MODIFIED,eval-sanitize-40-r4-006-q9nqf,phase=Running node=kind-worker
7.0069,TaskRequest,ADDED,eval-sanitize-40-r4-007,phase=None job=None
7.011,TaskRequest,MODIFIED,eval-sanitize-40-r4-007,phase=Pending job=None
7.0273,Job,ADDED,eval-sanitize-40-r4-007,
7.0336,Pod,ADDED,eval-sanitize-40-r4-007-2bndt,phase=Pending node=None
7.034,TaskRequest,MODIFIED,eval-sanitize-40-r4-007,phase=Scheduled job=None
7.0372,Job,MODIFIED,eval-sanitize-40-r4-007,
7.0395,Event,ADDED,eval-sanitize-40-r4-007.18d409fcf0da7630,reason=SuccessfulCreate count=1 msg=Created pod: eval-sanitize-40-r4-007-2bndt
7.0428,Job,MODIFIED,eval-sanitize-40-r4-006,
7.0429,TaskRequest,MODIFIED,eval-sanitize-40-r4-007,phase=Scheduled job=None
7.0503,Job,MODIFIED,eval-sanitize-40-r4-005,
7.0525,Job,MODIFIED,eval-sanitize-40-r4-006,
7.0579,Pod,MODIFIED,eval-sanitize-40-r4-007-2bndt,phase=Pending node=kind-worker5
7.0598,Job,MODIFIED,eval-sanitize-40-r4-005,
7.0611,Event,ADDED,eval-sanitize-40-r4-007-2bndt.18d409fcf2477925,reason=Scheduled count=None msg=Successfully assigned compute/eval-sanitize-40-r4-007-2bndt to kind-worker5
7.0678,Pod,MODIFIED,eval-sanitize-40-r4-007-2bndt,phase=Pending node=kind-worker5
7.4818,Event,ADDED,eval-sanitize-40-r4-007-2bndt.18d409fd0b4aba51,"reason=Pulled count=1 msg=Container image ""busybox:musl"" already present on machine"
7.5009,Event,ADDED,eval-sanitize-40-r4-007-2bndt.18d409fd0c7431b4,reason=Created count=1 msg=Created container: task
7.5433,Event,ADDED,eval-sanitize-40-r4-007-2bndt.18d409fd0eff5229,reason=Started count=1 msg=Started container task
7.8615,Pod,MODIFIED,eval-sanitize-40-r4-007-2bndt,phase=Running node=kind-worker5
8.0141,TaskRequest,ADDED,eval-sanitize-40-r4-008,phase=None job=None
8.018,TaskRequest,MODIFIED,eval-sanitize-40-r4-008,phase=Pending job=None
8.0337,Job,ADDED,eval-sanitize-40-r4-008,
8.0379,Job,MODIFIED,eval-sanitize-40-r4-007,
8.041,Pod,ADDED,eval-sanitize-40-r4-008-sbdmc,phase=Pending node=None
8.0411,TaskRequest,MODIFIED,eval-sanitize-40-r4-008,phase=Scheduled job=None
8.0437,Job,MODIFIED,eval-sanitize-40-r4-008,
8.0462,Event,ADDED,eval-sanitize-40-r4-008.18d409fd2ce1a306,reason=SuccessfulCreate count=1 msg=Created pod: eval-sanitize-40-r4-008-sbdmc
8.0492,TaskRequest,MODIFIED,eval-sanitize-40-r4-008,phase=Scheduled job=None
8.0526,Job,MODIFIED,eval-sanitize-40-r4-007,
8.1415,Pod,MODIFIED,eval-sanitize-40-r4-008-sbdmc,phase=Pending node=None
8.142,Event,ADDED,eval-sanitize-40-r4-008-sbdmc.18d409fd3009ca31,"reason=FailedScheduling count=None msg=0/6 nodes are available: 1 c_wall violated: 2 conflicting context pair(s) with node memory, 2 node(s) had untolerated taint(s), 3 c_wall violated: 1 conflicting context pair(s) with node memory. no new claims to deallocate, preemption: 0/6 nodes are available: 2 Preemption is not helpful for scheduling, 4 No preemption victims found for incoming pod."
8.1594,Event,ADDED,eval-sanitize-40-r4-008-sbdmc.18d409fd33b63bed,"reason=FailedScheduling count=None msg=0/6 nodes are available: 1 c_wall violated: 2 conflicting context pair(s) with node memory, 2 node(s) had untolerated taint(s), 3 c_wall violated: 1 conflicting context pair(s) with node memory. no new claims to deallocate, preemption: 0/6 nodes are available: 2 Preemption is not helpful for scheduling, 4 No preemption victims found for incoming pod."
9.0082,TaskRequest,ADDED,eval-sanitize-40-r4-009,phase=None job=None
9.0136,TaskRequest,MODIFIED,eval-sanitize-40-r4-009,phase=Pending job=None
9.0293,Job,ADDED,eval-sanitize-40-r4-009,
9.0351,Pod,ADDED,eval-sanitize-40-r4-009-zv98g,phase=Pending node=None
9.0367,TaskRequest,MODIFIED,eval-sanitize-40-r4-009,phase=Scheduled job=None
9.04,Job,MODIFIED,eval-sanitize-40-r4-009,
9.0404,Event,ADDED,eval-sanitize-40-r4-009.18d409fd68268a88,reason=SuccessfulCreate count=1 msg=Created pod: eval-sanitize-40-r4-009-zv98g
9.0439,TaskRequest,MODIFIED,eval-sanitize-40-r4-009,phase=Scheduled job=None
9.047,Job,MODIFIED,eval-sanitize-40-r4-008,
9.0562,Job,MODIFIED,eval-sanitize-40-r4-008,
9.0597,Pod,MODIFIED,eval-sanitize-40-r4-009-zv98g,phase=Pending node=kind-worker
9.063,Event,ADDED,eval-sanitize-40-r4-009-zv98g.18d409fd6993ce74,reason=Scheduled count=None msg=Successfully assigned compute/eval-sanitize-40-r4-009-zv98g to kind-worker
9.0719,Pod,MODIFIED,eval-sanitize-40-r4-009-zv98g,phase=Pending node=kind-worker
9.117,Event,MODIFIED,eval-sanitize-40-r4-008-sbdmc.18d409fd33b63bed,"reason=FailedScheduling count=None msg=0/6 nodes are available: 1 c_wall violated: 2 conflicting context pair(s) with node memory, 2 node(s) had untolerated taint(s), 3 c_wall violated: 1 conflicting context pair(s) with node memory. no new claims to deallocate, preemption: 0/6 nodes are available: 2 Preemption is not helpful for scheduling, 4 No preemption victims found for incoming pod."
9.5029,Event,ADDED,eval-sanitize-40-r4-009-zv98g.18d409fd83c4a368,"reason=Pulled count=1 msg=Container image ""busybox:musl"" already present on machine"
9.5208,Event,ADDED,eval-sanitize-40-r4-009-zv98g.18d409fd84e0c64f,reason=Created count=1 msg=Created container: task
9.5567,Event,ADDED,eval-sanitize-40-r4-009-zv98g.18d409fd86faf0b0,reason=Started count=1 msg=Started container task
9.9008,Pod,MODIFIED,eval-sanitize-40-r4-009-zv98g,phase=Running node=kind-worker
10.008,TaskRequest,ADDED,eval-sanitize-40-r4-010,phase=None job=None
10.0117,TaskRequest,MODIFIED,eval-sanitize-40-r4-010,phase=Pending job=None
10.0276,Job,ADDED,eval-sanitize-40-r4-010,
10.0328,Pod,ADDED,eval-sanitize-40-r4-010-92scj,phase=Pending node=None
10.0348,TaskRequest,MODIFIED,eval-sanitize-40-r4-010,phase=Scheduled job=None
10.0378,Job,MODIFIED,eval-sanitize-40-r4-010,
10.0406,Event,ADDED,eval-sanitize-40-r4-010.18d409fda3a261ba,reason=SuccessfulCreate count=1 msg=Created pod: eval-sanitize-40-r4-010-92scj
10.0415,Job,MODIFIED,eval-sanitize-40-r4-009,
10.0435,TaskRequest,MODIFIED,eval-sanitize-40-r4-010,phase=Scheduled job=None
10.0499,Job,MODIFIED,eval-sanitize-40-r4-009,
10.099,Pod,MODIFIED,eval-sanitize-40-r4-010-92scj,phase=Pending node=None
10.0994,Event,ADDED,eval-sanitize-40-r4-010-92scj.18d409fda7328cef,"reason=FailedScheduling count=None msg=0/6 nodes are available: 1 c_wall violated: 2 conflicting context pair(s) with node memory, 2 node(s) had untolerated taint(s), 3 c_wall violated: 1 conflicting context pair(s) with node memory. no new claims to deallocate, preemption: 0/6 nodes are available: 2 Preemption is not helpful for scheduling, 4 No preemption victims found for incoming pod."
10.1692,Event,ADDED,eval-sanitize-40-r4-010-92scj.18d409fdab59ae38,"reason=FailedScheduling count=None msg=0/6 nodes are available: 1 c_wall violated: 2 conflicting context pair(s) with node memory, 2 node(s) had untolerated taint(s), 3 c_wall violated: 1 conflicting context pair(s) with node memory. no new claims to deallocate, preemption: 0/6 nodes are available: 2 Preemption is not helpful for scheduling, 4 No preemption victims found for incoming pod."
10.6947,Pod,MODIFIED,eval-sanitize-40-r4-000-v4gjb,phase=Running node=kind-worker3
10.813,Event,MODIFIED,eval-sanitize-40-r4-010-92scj.18d409fdab59ae38,"reason=FailedScheduling count=None msg=0/6 nodes are available: 1 c_wall violated: 2 conflicting context pair(s) with node memory, 2 node(s) had untolerated taint(s), 3 c_wall violated: 1 conflicting context pair(s) with node memory. no new claims to deallocate, preemption: 0/6 nodes are available: 2 Preemption is not helpful for scheduling, 4 No preemption victims found for incoming pod."
11.0111,TaskRequest,ADDED,eval-sanitize-40-r4-011,phase=None job=None
11.0151,TaskRequest,MODIFIED,eval-sanitize-40-r4-011,phase=Pending job=None
11.0311,Job,ADDED,eval-sanitize-40-r4-011,
11.0377,Job,MODIFIED,eval-sanitize-40-r4-010,
11.039,TaskRequest,MODIFIED,eval-sanitize-40-r4-011,phase=Scheduled job=None
11.0408,Pod,ADDED,eval-sanitize-40-r4-011-t2nwq,phase=Pending node=None
11.0421,Job,MODIFIED,eval-sanitize-40-r4-011,
11.0455,Event,ADDED,eval-sanitize-40-r4-011.18d409fddfa28808,reason=SuccessfulCreate count=1 msg=Created pod: eval-sanitize-40-r4-011-t2nwq
11.0466,TaskRequest,MODIFIED,eval-sanitize-40-r4-011,phase=Scheduled job=None
11.0496,Job,MODIFIED,eval-sanitize-40-r4-010,
11.061,Pod,MODIFIED,eval-sanitize-40-r4-011-t2nwq,phase=Pending node=kind-worker
11.066,Event,ADDED,eval-sanitize-40-r4-011-t2nwq.18d409fde0dcc6b4,reason=Scheduled count=None msg=Successfully assigned compute/eval-sanitize-40-r4-011-t2nwq to kind-worker
11.0719,Pod,MODIFIED,eval-sanitize-40-r4-011-t2nwq,phase=Pending node=kind-worker
11.5092,Event,ADDED,eval-sanitize-40-r4-011-t2nwq.18d409fdfb592aec,"reason=Pulled count=1 msg=Container image ""busybox:musl"" already present on machine"
11.5281,Event,ADDED,eval-sanitize-40-r4-011-t2nwq.18d409fdfc81bb5b,reason=Created count=1 msg=Created container: task
11.6468,Event,ADDED,eval-sanitize-40-r4-011-t2nwq.18d409fe039450e7,reason=Started count=1 msg=Started container task
11.7018,Job,MODIFIED,eval-sanitize-40-r4-000,
11.7127,Job,MODIFIED,eval-sanitize-40-r4-000,
11.8123,Pod,MODIFIED,eval-sanitize-40-r4-000-v4gjb,phase=Succeeded node=kind-worker3
11.8686,Pod,MODIFIED,eval-sanitize-40-r4-001-vsq9b,phase=Running node=kind-worker5
11.9178,Pod,MODIFIED,eval-sanitize-40-r4-011-t2nwq,phase=Running node=kind-worker
12.0162,TaskRequest,ADDED,eval-sanitize-40-r4-012,phase=None job=None
12.0199,TaskRequest,MODIFIED,eval-sanitize-40-r4-012,phase=Pending job=None
12.0353,Job,ADDED,eval-sanitize-40-r4-012,
12.0414,Pod,ADDED,eval-sanitize-40-r4-012-vsl8p,phase=Pending node=None
12.0417,TaskRequest,MODIFIED,eval-sanitize-40-r4-012,phase=Scheduled job=None
12.0445,Job,MODIFIED,eval-sanitize-40-r4-012,
12.0459,Event,ADDED,eval-sanitize-40-r4-012.18d409fe1b59d1b8,reason=SuccessfulCreate count=1 msg=Created pod: eval-sanitize-40-r4-012-vsl8p
12.047,Job,MODIFIED,eval-sanitize-40-r4-011,
12.0547,TaskRequest,MODIFIED,eval-sanitize-40-r4-012,phase=Scheduled job=None
12.0645,Job,MODIFIED,eval-sanitize-40-r4-011,
12.2138,Pod,MODIFIED,eval-sanitize-40-r4-012-vsl8p,phase=Pending node=kind-worker5
12.2183,Event,ADDED,eval-sanitize-40-r4-012-vsl8p.18d409fe25930d55,reason=Scheduled count=None msg=Successfully assigned compute/eval-sanitize-40-r4-012-vsl8p to kind-worker5
12.2239,Pod,MODIFIED,eval-sanitize-40-r4-012-vsl8p,phase=Pending node=kind-worker5
12.657,Event,ADDED,eval-sanitize-40-r4-012-vsl8p.18d409fe3fce08b2,"reason=Pulled count=1 msg=Container image ""busybox:musl"" already present on machine"
12.6749,Event,ADDED,eval-sanitize-40-r4-012-vsl8p.18d409fe40e42f0d,reason=Created count=1 msg=Created container: task
12.7686,Job,MODIFIED,eval-sanitize-40-r4-000,
12.7745,Event,ADDED,eval-sanitize-40-r4-012-vsl8p.18d409fe46cc5d7f,reason=Started count=1 msg=Started container task
12.7782,Pod,MODIFIED,eval-sanitize-40-r4-000-v4gjb,phase=Succeeded node=kind-worker3
12.7797,Job,MODIFIED,eval-sanitize-40-r4-000,
12.8729,Pod,MODIFIED,eval-sanitize-40-r4-012-vsl8p,phase=Running node=kind-worker5
12.8743,Job,MODIFIED,eval-sanitize-40-r4-001,
12.8884,Job,MODIFIED,eval-sanitize-40-r4-001,
12.9092,Pod,MODIFIED,eval-sanitize-40-r4-002-2rvfm,phase=Running node=kind-worker
12.9826,Pod,MODIFIED,eval-sanitize-40-r4-001-vsq9b,phase=Succeeded node=kind-worker5
13.0065,TaskRequest,ADDED,eval-sanitize-40-r4-013,phase=None job=None
13.0099,TaskRequest,MODIFIED,eval-sanitize-40-r4-013,phase=Pending job=None
13.0249,Job,ADDED,eval-sanitize-40-r4-013,
13.0286,TaskRequest,MODIFIED,eval-sanitize-40-r4-013,phase=Scheduled job=None
13.0314,Pod,ADDED,eval-sanitize-40-r4-013-fhfpc,phase=Pending node=None
13.0334,Job,MODIFIED,eval-sanitize-40-r4-013,
13.0367,Event,ADDED,eval-sanitize-40-r4-013.18d409fe565f0c16,reason=SuccessfulCreate count=1 msg=Created pod: eval-sanitize-40-r4-013-fhfpc
13.0369,TaskRequest,MODIFIED,eval-sanitize-40-r4-013,phase=Scheduled job=None
13.0455,Job,MODIFIED,eval-sanitize-40-r4-012,
13.0537,Job,MODIFIED,eval-sanitize-40-r4-012,
13.1872,Pod,MODIFIED,eval-sanitize-40-r4-013-fhfpc,phase=Pending node=kind-worker
13.1917,Event,ADDED,eval-sanitize-40-r4-013-fhfpc.18d409fe5fa08353,reason=Scheduled count=None msg=Successfully assigned compute/eval-sanitize-40-r4-013-fhfpc to kind-worker
13.1976,Pod,MODIFIED,eval-sanitize-40-r4-013-fhfpc,phase=Pending node=kind-worker
13.6537,Event,ADDED,eval-sanitize-40-r4-013-fhfpc.18d409fe7b2bffa9,"reason=Pulled count=1 msg=Container image ""busybox:musl"" already present on machine"
13.672,Event,ADDED,eval-sanitize-40-r4-013-fhfpc.18d409fe7c407b3b,reason=Created count=1 msg=Created container: task
13.7669,Event,ADDED,eval-sanitize-40-r4-013-fhfpc.18d409fe81f8159b,reason=Started count=1 msg=Started container task
13.7741,Job,MODIFIED,eval-sanitize-40-r4-000,
13.7791,Job,MODIFIED,eval-sanitize-40-r4-000,
13.7837,Event,ADDED,eval-sanitize-40-r4-000.18d409fe82eb6b28,reason=Completed count=1 msg=Job completed
13.7904,Job,MODIFIED,eval-sanitize-40-r4-000,
13.7947,TaskRequest,MODIFIED,eval-sanitize-40-r4-000,phase=Complete job=None
13.804,Job,MODIFIED,eval-sanitize-40-r4-000,
13.8768,Pod,MODIFIED,eval-sanitize-40-r4-003-kgd84,phase=Running node=kind-worker5
13.8795,Job,MODIFIED,eval-sanitize-40-r4-001,
13.8881,Pod,MODIFIED,eval-sanitize-40-r4-001-vsq9b,phase=Succeeded node=kind-worker5
13.8896,Job,MODIFIED,eval-sanitize-40-r4-001,
13.9092,Pod,MODIFIED,eval-sanitize-40-r4-013-fhfpc,phase=Running node=kind-worker
13.9133,Job,MODIFIED,eval-sanitize-40-r4-002,
13.9234,Job,MODIFIED,eval-sanitize-40-r4-002,
14.0712,TaskRequest,ADDED,eval-sanitize-40-r4-014,phase=None job=None
14.0726,Job,MODIFIED,eval-sanitize-40-r4-013,
14.0765,TaskRequest,MODIFIED,eval-sanitize-40-r4-014,phase=Pending job=None
14.0806,Pod,MODIFIED,eval-sanitize-40-r4-002-2rvfm,phase=Succeeded node=kind-worker
14.0899,Job,ADDED,eval-sanitize-40-r4-014,
14.0961,Pod,ADDED,eval-sanitize-40-r4-014-tdhkt,phase=Pending node=None
14.0962,TaskRequest,MODIFIED,eval-sanitize-40-r4-014,phase=Scheduled job=None
14.099,Job,MODIFIED,eval-sanitize-40-r4-014,
14.1007,Event,ADDED,eval-sanitize-40-r4-014.18d409fe95d0a614,reason=SuccessfulCreate count=1 msg=Created pod: eval-sanitize-40-r4-014-tdhkt
14.1027,TaskRequest,MODIFIED,eval-sanitize-40-r4-014,phase=Scheduled job=None
14.1053,Job,MODIFIED,eval-sanitize-40-r4-013,
14.2671,Pod,MODIFIED,eval-sanitize-40-r4-014-tdhkt,phase=Pending node=kind-worker
14.2731,Event,ADDED,eval-sanitize-40-r4-014-tdhkt.18d409fe9ffc521f,reason=Scheduled count=None msg=Successfully assigned compute/eval-sanitize-40-r4-014-tdhkt to kind-worker
14.2797,Pod,MODIFIED,eval-sanitize-40-r4-014-tdhkt,phase=Pending node=kind-worker
14.7318,Pod,MODIFIED,eval-sanitize-40-r4-004-85p4k,phase=Running node=kind-worker4
14.7333,Event,ADDED,eval-sanitize-40-r4-014-tdhkt.18d409febb684ca6,"reason=Pulled count=1 msg=Container image ""busybox:musl"" already present on machine"
14.7536,Event,ADDED,eval-sanitize-40-r4-014-tdhkt.18d409febcc3ea03,reason=Created count=1 msg=Created container: task
14.8131,Event,ADDED,eval-sanitize-40-r4-014-tdhkt.18d409fec04ed1d6,reason=Started count=1 msg=Started container task
14.9116,Job,MODIFIED,eval-sanitize-40-r4-003,
14.914,Job,MODIFIED,eval-sanitize-40-r4-001,
14.9171,Pod,MODIFIED,eval-sanitize-40-r4-014-tdhkt,phase=Running node=kind-worker
14.919,Job,MODIFIED,eval-sanitize-40-r4-002,
14.9203,Job,MODIFIED,eval-sanitize-40-r4-001,
14.9212,Job,MODIFIED,eval-sanitize-40-r4-003,
14.9254,Event,ADDED,eval-sanitize-40-r4-001.18d409fec6db2f6e,reason=Completed count=1 msg=Job completed
14.9271,Pod,MODIFIED,eval-sanitize-40-r4-002-2rvfm,phase=Succeeded node=kind-worker
14.9281,Job,MODIFIED,eval-sanitize-40-r4-002,
14.9299,Job,MODIFIED,eval-sanitize-40-r4-001,
14.9344,TaskRequest,MODIFIED,eval-sanitize-40-r4-001,phase=Complete job=None
14.9445,Job,MODIFIED,eval-sanitize-40-r4-001,
15.0799,TaskRequest,ADDED,eval-sanitize-40-r4-015,phase=None job=None
15.0836,TaskRequest,MODIFIED,eval-sanitize-40-r4-015,phase=Pending job=None
15.099,Job,ADDED,eval-sanitize-40-r4-015,
15.1013,Job,MODIFIED,eval-sanitize-40-r4-014,
15.1041,TaskRequest,MODIFIED,eval-sanitize-40-r4-015,phase=Scheduled job=None
15.1069,Pod,ADDED,eval-sanitize-40-r4-015-c4nvv,phase=Pending node=None
15.1102,Job,MODIFIED,eval-sanitize-40-r4-015,
15.1134,Event,ADDED,eval-sanitize-40-r4-015.18d409fed213a7b9,reason=SuccessfulCreate count=1 msg=Created pod: eval-sanitize-40-r4-015-c4nvv
15.1135,TaskRequest,MODIFIED,eval-sanitize-40-r4-015,phase=Scheduled job=None
15.1151,Pod,MODIFIED,eval-sanitize-40-r4-003-kgd84,phase=Succeeded node=kind-worker5
15.1164,Job,MODIFIED,eval-sanitize-40-r4-014,
15.1284,Pod,MODIFIED,eval-sanitize-40-r4-015-c4nvv,phase=Pending node=kind-worker
15.1328,Event,ADDED,eval-sanitize-40-r4-015-c4nvv.18d409fed356790e,reason=Scheduled count=None msg=Successfully assigned compute/eval-sanitize-40-r4-015-c4nvv to kind-worker
15.1387,Pod,MODIFIED,eval-sanitize-40-r4-015-c4nvv,phase=Pending node=kind-worker
15.639,Event,ADDED,eval-sanitize-40-r4-015-c4nvv.18d409fef1892e31,"reason=Pulled count=1 msg=Container image ""busybox:musl"" already present on machine"
15.6617,Event,ADDED,eval-sanitize-40-r4-015-c4nvv.18d409fef2e8825e,reason=Created count=1 msg=Created container: task
15.8153,Job,MODIFIED,eval-sanitize-40-r4-004,
15.8163,Event,ADDED,eval-sanitize-40-r4-015-c4nvv.18d409fefc0aa27e,reason=Started count=1 msg=Started container task
15.8248,Job,MODIFIED,eval-sanitize-40-r4-004,
15.8855,Pod,MODIFIED,eval-sanitize-40-r4-004-85p4k,phase=Succeeded node=kind-worker4
16.0019,Job,MODIFIED,eval-sanitize-40-r4-003,
16.0043,Job,MODIFIED,eval-sanitize-40-r4-002,
16.0063,Pod,MODIFIED,eval-sanitize-40-r4-015-c4nvv,phase=Running node=kind-worker
16.01,Job,MODIFIED,eval-sanitize-40-r4-002,
16.0116,TaskRequest,ADDED,eval-sanitize-40-r4-016,phase=None job=None
16.013,Pod,MODIFIED,eval-sanitize-40-r4-003-kgd84,phase=Succeeded node=kind-worker5
16.0156,Job,MODIFIED,eval-sanitize-40-r4-003,
16.0167,Event,ADDED,eval-sanitize-40-r4-002.18d409ff07e65fae,reason=Completed count=1 msg=Job completed
16.0168,TaskRequest,MODIFIED,eval-sanitize-40-r4-016,phase=Pending job=None
16.0214,Job,MODIFIED,eval-sanitize-40-r4-002,
16.0316,Job,ADDED,eval-sanitize-40-r4-016,
16.0356,TaskRequest,MODIFIED,eval-sanitize-40-r4-016,phase=Scheduled job=None
16.0382,Pod,ADDED,eval-sanitize-40-r4-016-cczvx,phase=Pending node=None
16.0401,Job,MODIFIED,eval-sanitize-40-r4-016,
16.0415,TaskRequest,MODIFIED,eval-sanitize-40-r4-002,phase=Complete job=None
16.0432,Event,ADDED,eval-sanitize-40-r4-016.18d409ff09971f90,reason=SuccessfulCreate count=1 msg=Created pod: eval-sanitize-40-r4-016-cczvx
16.044,TaskRequest,MODIFIED,eval-sanitize-40-r4-016,phase=Scheduled job=None
16.1302,Job,MODIFIED,eval-sanitize-40-r4-002,
16.1311,Job,MODIFIED,eval-sanitize-40-r4-015,
16.1405,Job,MODIFIED,eval-sanitize-40-r4-015,
16.2601,Pod,MODIFIED,eval-sanitize-40-r4-016-cczvx,phase=Pending node=kind-worker4
16.2642,Event,ADDED,eval-sanitize-40-r4-016-cczvx.18d409ff16c4ff43,reason=Scheduled count=None msg=Successfully assigned compute/eval-sanitize-40-r4-016-cczvx to kind-worker4
16.2676,Pod,MODIFIED,eval-sanitize-40-r4-010-92scj,phase=Pending node=None
16.2705,Node,MODIFIED,kind-worker4,taints=0
16.2733,Pod,MODIFIED,eval-sanitize-40-r4-016-cczvx,phase=Pending node=kind-worker4
16.2803,Node,MODIFIED,kind-worker4,taints=0
16.3118,Pod,MODIFIED,eval-sanitize-40-r4-008-sbdmc,phase=Pending node=None
16.4369,Pod,MODIFIED,eval-sanitize-40-r4-005-5d8sq,phase=Running node=kind-worker2
16.4373,Event,ADDED,eval-sanitize-40-r4-010-92scj.18d409ff1f4c5f90,"reason=FailedScheduling count=None msg=0/6 nodes are available: 2 c_wall violated: 1 conflicting context pair(s) with node memory, 2 c_wall violated: 2 conflicting context pair(s) with node memory, 2 node(s) had untolerated taint(s). no new claims to deallocate, preemption: 0/6 nodes are available: 2 Preemption is not helpful for scheduling, 4 No preemption victims found for incoming pod."
16.5062,Event,ADDED,eval-sanitize-40-r4-008-sbdmc.18d409ff252644d8,"reason=FailedScheduling count=None msg=0/6 nodes are available: 2 c_wall violated: 1 conflicting context pair(s) with node memory, 2 c_wall violated: 2 conflicting context pair(s) with node memory, 2 node(s) had untolerated taint(s). no new claims to deallocate, preemption: 0/6 nodes are available: 2 Preemption is not helpful for scheduling, 4 No preemption victims found for incoming pod."
16.6067,Event,MODIFIED,eval-sanitize-40-r4-010-92scj.18d409ff1f4c5f90,"reason=FailedScheduling count=None msg=0/6 nodes are available: 2 c_wall violated: 1 conflicting context pair(s) with node memory, 2 c_wall violated: 2 conflicting context pair(s) with node memory, 2 node(s) had untolerated taint(s). no new claims to deallocate, preemption: 0/6 nodes are available: 2 Preemption is not helpful for scheduling, 4 No preemption victims found for incoming pod."
16.783,Event,ADDED,eval-sanitize-40-r4-016-cczvx.18d409ff35bf0b76,"reason=Pulled count=1 msg=Container image ""busybox:musl"" already present on machine"
16.8021,Event,ADDED,eval-sanitize-40-r4-016-cczvx.18d409ff36df6ca3,reason=Created count=1 msg=Created container: task
16.82,Job,MODIFIED,eval-sanitize-40-r4-004,
16.828,Pod,MODIFIED,eval-sanitize-40-r4-004-85p4k,phase=Succeeded node=kind-worker4
16.8291,Job,MODIFIED,eval-sanitize-40-r4-004,
16.8683,Event,MODIFIED,eval-sanitize-40-r4-008-sbdmc.18d409ff252644d8,"reason=FailedScheduling count=None msg=0/6 nodes are available: 2 c_wall violated: 1 conflicting context pair(s) with node memory, 2 c_wall violated: 2 conflicting context pair(s) with node memory, 2 node(s) had untolerated taint(s). no new claims to deallocate, preemption: 0/6 nodes are available: 2 Preemption is not helpful for scheduling, 4 No preemption victims found for incoming pod."
16.8691,Event,ADDED,eval-sanitize-40-r4-016-cczvx.18d409ff3aed655b,reason=Started count=1 msg=Started container task
16.9224,Pod,MODIFIED,eval-sanitize-40-r4-006-q9nqf,phase=Running node=kind-worker
17.0077,Job,MODIFIED,eval-sanitize-40-r4-003,
17.0079,TaskRequest,ADDED,eval-sanitize-40-r4-017,phase=None job=None
17.0118,Job,MODIFIED,eval-sanitize-40-r4-003,
17.0128,TaskRequest,MODIFIED,eval-sanitize-40-r4-017,phase=Pending job=None
17.0155,Event,ADDED,eval-sanitize-40-r4-003.18d409ff43a142c7,reason=Completed count=1 msg=Job completed
17.0197,Job,MODIFIED,eval-sanitize-40-r4-003,
17.0269,Job,ADDED,eval-sanitize-40-r4-017,
17.0328,Pod,ADDED,eval-sanitize-40-r4-017-2p92w,phase=Pending node=None
17.0331,TaskRequest,MODIFIED,eval-sanitize-40-r4-017,phase=Scheduled job=None
17.0362,Job,MODIFIED,eval-sanitize-40-r4-017,
17.0384,Event,ADDED,eval-sanitize-40-r4-017.18d409ff44e13301,reason=SuccessfulCreate count=1 msg=Created pod: eval-sanitize-40-r4-017-2p92w
17.0385,TaskRequest,MODIFIED,eval-sanitize-40-r4-003,phase=Complete job=None
17.0424,Job,MODIFIED,eval-sanitize-40-r4-016,
17.0426,TaskRequest,MODIFIED,eval-sanitize-40-r4-017,phase=Scheduled job=None
17.0467,Job,MODIFIED,eval-sanitize-40-r4-003,
17.0509,Job,MODIFIED,eval-sanitize-40-r4-016,
17.1059,Pod,MODIFIED,eval-sanitize-40-r4-017-2p92w,phase=Pending node=kind-worker5
17.1094,Event,ADDED,eval-sanitize-40-r4-017-2p92w.18d409ff493558a9,reason=Scheduled count=None msg=Successfully assigned compute/eval-sanitize-40-r4-017-2p92w to kind-worker5
17.1155,Pod,MODIFIED,eval-sanitize-40-r4-017-2p92w,phase=Pending node=kind-worker5
17.4442,Job,MODIFIED,eval-sanitize-40-r4-005,
17.4469,Pod,MODIFIED,eval-sanitize-40-r4-005-5d8sq,phase=Succeeded node=kind-worker2
17.4545,Job,MODIFIED,eval-sanitize-40-r4-005,
17.5364,Event,ADDED,eval-sanitize-40-r4-017-2p92w.18d409ff629fe09f,"reason=Pulled count=1 msg=Container image ""busybox:musl"" already present on machine"
17.5608,Event,ADDED,eval-sanitize-40-r4-017-2p92w.18d409ff641b2a4b,reason=Created count=1 msg=Created container: task
17.6607,Event,ADDED,eval-sanitize-40-r4-017-2p92w.18d409ff6a009607,reason=Started count=1 msg=Started container task
17.7299,Pod,MODIFIED,eval-sanitize-40-r4-016-cczvx,phase=Running node=kind-worker4
17.827,Job,MODIFIED,eval-sanitize-40-r4-004,
17.8324,Job,MODIFIED,eval-sanitize-40-r4-004,
17.8386,Event,ADDED,eval-sanitize-40-r4-004.18d409ff747f8252,reason=Completed count=1 msg=Job completed
17.8441,Job,MODIFIED,eval-sanitize-40-r4-004,
17.8494,TaskRequest,MODIFIED,eval-sanitize-40-r4-004,phase=Complete job=None
17.8596,Job,MODIFIED,eval-sanitize-40-r4-004,
17.8903,Pod,MODIFIED,eval-sanitize-40-r4-007-2bndt,phase=Running node=kind-worker5
17.8972,Pod,MODIFIED,eval-sanitize-40-r4-017-2p92w,phase=Running node=kind-worker5
17.9284,Job,MODIFIED,eval-sanitize-40-r4-006,
17.9391,Job,MODIFIED,eval-sanitize-40-r4-006,
18.0078,TaskRequest,ADDED,eval-sanitize-40-r4-018,phase=None job=None
18.0132,TaskRequest,MODIFIED,eval-sanitize-40-r4-018,phase=Pending job=None
18.0271,Job,ADDED,eval-sanitize-40-r4-018,
18.032,TaskRequest,MODIFIED,eval-sanitize-40-r4-018,phase=Scheduled job=None
18.0343,Pod,ADDED,eval-sanitize-40-r4-018-97rrz,phase=Pending node=None
18.0355,Job,MODIFIED,eval-sanitize-40-r4-018,
18.0379,Job,MODIFIED,eval-sanitize-40-r4-017,
18.0406,Event,ADDED,eval-sanitize-40-r4-018.18d409ff808b2a74,reason=SuccessfulCreate count=1 msg=Created pod: eval-sanitize-40-r4-018-97rrz
18.0442,TaskRequest,MODIFIED,eval-sanitize-40-r4-018,phase=Scheduled job=None
18.0482,Job,MODIFIED,eval-sanitize-40-r4-017,
18.0488,Job,MODIFIED,eval-sanitize-40-r4-016,
18.0576,Job,MODIFIED,eval-sanitize-40-r4-016,
18.1432,Pod,MODIFIED,eval-sanitize-40-r4-006-q9nqf,phase=Succeeded node=kind-worker
18.1932,Pod,MODIFIED,eval-sanitize-40-r4-018-97rrz,phase=Pending node=kind-worker5
18.197,Event,ADDED,eval-sanitize-40-r4-018-97rrz.18d409ff8a09feb1,reason=Scheduled count=None msg=Successfully assigned compute/eval-sanitize-40-r4-018-97rrz to kind-worker5
18.2052,Pod,MODIFIED,eval-sanitize-40-r4-018-97rrz,phase=Pending node=kind-worker5
18.4531,Job,MODIFIED,eval-sanitize-40-r4-005,
18.461,Pod,MODIFIED,eval-sanitize-40-r4-005-5d8sq,phase=Succeeded node=kind-worker2
18.4631,Job,MODIFIED,eval-sanitize-40-r4-005,
18.6337,Event,ADDED,eval-sanitize-40-r4-018-97rrz.18d409ffa40a3d72,"reason=Pulled count=1 msg=Container image ""busybox:musl"" already present on machine"
18.6513,Event,ADDED,eval-sanitize-40-r4-018-97rrz.18d409ffa52297e8,reason=Created count=1 msg=Created container: task
18.7178,Event,ADDED,eval-sanitize-40-r4-018-97rrz.18d409ffa91215d0,reason=Started count=1 msg=Started container task
18.8924,Pod,MODIFIED,eval-sanitize-40-r4-018-97rrz,phase=Running node=kind-worker5
18.8963,Job,MODIFIED,eval-sanitize-40-r4-007,
18.9077,Job,MODIFIED,eval-sanitize-40-r4-007,
18.9333,Job,MODIFIED,eval-sanitize-40-r4-006,
18.9408,Pod,MODIFIED,eval-sanitize-40-r4-006-q9nqf,phase=Succeeded node=kind-worker
18.9423,Job,MODIFIED,eval-sanitize-40-r4-006,
19.0412,Job,MODIFIED,eval-sanitize-40-r4-018,
19.0509,Pod,MODIFIED,eval-sanitize-40-r4-007-2bndt,phase=Succeeded node=kind-worker5
19.0519,Job,MODIFIED,eval-sanitize-40-r4-018,
19.1001,TaskRequest,ADDED,eval-sanitize-40-r4-019,phase=None job=None
19.1393,TaskRequest,MODIFIED,eval-sanitize-40-r4-019,phase=Pending job=None
19.1543,Job,ADDED,eval-sanitize-40-r4-019,
19.1631,Pod,ADDED,eval-sanitize-40-r4-019-g28rc,phase=Pending node=None
19.164,TaskRequest,MODIFIED,eval-sanitize-40-r4-019,phase=Scheduled job=None
19.1648,Job,MODIFIED,eval-sanitize-40-r4-019,
19.1675,Event,ADDED,eval-sanitize-40-r4-019.18d409ffc3d614b9,reason=SuccessfulCreate count=1 msg=Created pod: eval-sanitize-40-r4-019-g28rc
19.1715,TaskRequest,MODIFIED,eval-sanitize-40-r4-019,phase=Scheduled job=None
19.3661,Pod,MODIFIED,eval-sanitize-40-r4-019-g28rc,phase=Pending node=kind-worker5
19.3696,Event,ADDED,eval-sanitize-40-r4-019-g28rc.18d409ffcfeb9df8,reason=Scheduled count=None msg=Successfully assigned compute/eval-sanitize-40-r4-019-g28rc to kind-worker5
19.3757,Pod,MODIFIED,eval-sanitize-40-r4-019-g28rc,phase=Pending node=kind-worker5
19.3784,Node,MODIFIED,kind-worker5,taints=0
19.3883,Node,MODIFIED,kind-worker5,taints=0
19.4071,Pod,MODIFIED,eval-sanitize-40-r4-008-sbdmc,phase=Pending node=None
19.4595,Job,MODIFIED,eval-sanitize-40-r4-005,
19.4637,Job,MODIFIED,eval-sanitize-40-r4-005,
19.4689,Event,ADDED,eval-sanitize-40-r4-005.18d409ffd5cabbf4,reason=Completed count=1 msg=Job completed
19.4748,Job,MODIFIED,eval-sanitize-40-r4-005,
19.4791,TaskRequest,MODIFIED,eval-sanitize-40-r4-005,phase=Complete job=None
19.488,Job,MODIFIED,eval-sanitize-40-r4-005,
19.5008,Pod,MODIFIED,eval-sanitize-40-r4-010-92scj,phase=Pending node=None
19.5994,Event,ADDED,eval-sanitize-40-r4-008-sbdmc.18d409ffdd96d95f,"reason=FailedScheduling count=None msg=0/6 nodes are available: 1 c_wall violated: 2 conflicting context pair(s) with node memory, 1 c_wall violated: 3 conflicting context pair(s) with node memory, 2 c_wall violated: 1 conflicting context pair(s) with node memory, 2 node(s) had untolerated taint(s). no new claims to deallocate, preemption: 0/6 nodes are available: 2 Preemption is not helpful for scheduling, 4 No preemption victims found for incoming pod."
19.699,Event,ADDED,eval-sanitize-40-r4-010-92scj.18d409ffe373c30c,"reason=FailedScheduling count=None msg=0/6 nodes are available: 1 c_wall violated: 2 conflicting context pair(s) with node memory, 1 c_wall violated: 3 conflicting context pair(s) with node memory, 2 c_wall violated: 1 conflicting context pair(s) with node memory, 2 node(s) had untolerated taint(s). no new claims to deallocate, preemption: 0/6 nodes are available: 2 Preemption is not helpful for scheduling, 4 No preemption victims found for incoming pod."
19.8503,Event,ADDED,eval-sanitize-40-r4-019-g28rc.18d409ffec90a1de,"reason=Pulled count=1 msg=Container image ""busybox:musl"" already present on machine"
19.867,Event,ADDED,eval-sanitize-40-r4-019-g28rc.18d409ffed9a0569,reason=Created count=1 msg=Created container: task
19.9042,Job,MODIFIED,eval-sanitize-40-r4-007,
19.9127,Pod,MODIFIED,eval-sanitize-40-r4-007-2bndt,phase=Succeeded node=kind-worker5
19.9138,Job,MODIFIED,eval-sanitize-40-r4-007,
19.9229,Event,ADDED,eval-sanitize-40-r4-019-g28rc.18d409fff0f1e41d,reason=Started count=1 msg=Started container task
19.9288,Pod,MODIFIED,eval-sanitize-40-r4-009-zv98g,phase=Running node=kind-worker
19.9382,Job,MODIFIED,eval-sanitize-40-r4-006,
19.9423,Job,MODIFIED,eval-sanitize-40-r4-006,
19.9475,Event,ADDED,eval-sanitize-40-r4-006.18d409fff24c031e,reason=Completed count=1 msg=Job completed
19.9508,Event,MODIFIED,eval-sanitize-40-r4-008-sbdmc.18d409ffdd96d95f,"reason=FailedScheduling count=None msg=0/6 nodes are available: 1 c_wall violated: 2 conflicting context pair(s) with node memory, 1 c_wall violated: 3 conflicting context pair(s) with node memory, 2 c_wall violated: 1 conflicting context pair(s) with node memory, 2 node(s) had untolerated taint(s). no new claims to deallocate, preemption: 0/6 nodes are available: 2 Preemption is not helpful for scheduling, 4 No preemption victims found for incoming pod."
19.9548,Job,MODIFIED,eval-sanitize-40-r4-006,
19.9616,TaskRequest,MODIFIED,eval-sanitize-40-r4-006,phase=Complete job=None
19.9705,Job,MODIFIED,eval-sanitize-40-r4-006,
20.0539,TaskRequest,ADDED,eval-sanitize-40-r4-020,phase=None job=None
20.0573,Event,MODIFIED,eval-sanitize-40-r4-010-92scj.18d409ffe373c30c,"reason=FailedScheduling count=None msg=0/6 nodes are available: 1 c_wall violated: 2 conflicting context pair(s) with node memory, 1 c_wall violated: 3 conflicting context pair(s) with node memory, 2 c_wall violated: 1 conflicting context pair(s) with node memory, 2 node(s) had untolerated taint(s). no new claims to deallocate, preemption: 0/6 nodes are available: 2 Preemption is not helpful for scheduling, 4 No preemption victims found for incoming pod."
20.0574,TaskRequest,MODIFIED,eval-sanitize-40-r4-020,phase=Pending job=None
20.0723,Job,ADDED,eval-sanitize-40-r4-020,
20.0796,Pod,ADDED,eval-sanitize-40-r4-020-f8d9v,phase=Pending node=None
20.0797,TaskRequest,MODIFIED,eval-sanitize-40-r4-020,phase=Scheduled job=None
20.0828,Job,MODIFIED,eval-sanitize-40-r4-020,
20.0846,Event,ADDED,eval-sanitize-40-r4-020.18d409fffa76f473,reason=SuccessfulCreate count=1 msg=Created pod: eval-sanitize-40-r4-020-f8d9v
20.0875,TaskRequest,MODIFIED,eval-sanitize-40-r4-020,phase=Scheduled job=None
20.1096,Pod,MODIFIED,eval-sanitize-40-r4-020-f8d9v,phase=Pending node=kind-worker
20.1189,Pod,MODIFIED,eval-sanitize-40-r4-020-f8d9v,phase=Pending node=kind-worker
20.1608,Event,ADDED,eval-sanitize-40-r4-020-f8d9v.18d409ffff13c18f,reason=Scheduled count=None msg=Successfully assigned compute/eval-sanitize-40-r4-020-f8d9v to kind-worker
20.1677,Job,MODIFIED,eval-sanitize-40-r4-019,
20.176,Job,MODIFIED,eval-sanitize-40-r4-019,
20.5846,Event,ADDED,eval-sanitize-40-r4-020-f8d9v.18d40a00184e559f,"reason=Pulled count=1 msg=Container image ""busybox:musl"" already present on machine"
20.6032,Event,ADDED,eval-sanitize-40-r4-020-f8d9v.18d40a001975da9d,reason=Created count=1 msg=Created container: task
20.7427,Event,ADDED,eval-sanitize-40-r4-020-f8d9v.18d40a0021c72faf,reason=Started count=1 msg=Started container task
20.9106,Job,MODIFIED,eval-sanitize-40-r4-007,
20.9151,Pod,MODIFIED,eval-sanitize-40-r4-019-g28rc,phase=Running node=kind-worker5
20.9179,Job,MODIFIED,eval-sanitize-40-r4-007,
20.9238,Event,ADDED,eval-sanitize-40-r4-007.18d40a002c74538d,reason=Completed count=1 msg=Job completed
20.9298,Job,MODIFIED,eval-sanitize-40-r4-007,
20.9341,Job,MODIFIED,eval-sanitize-40-r4-009,
20.9375,Pod,MODIFIED,eval-sanitize-40-r4-020-f8d9v,phase=Running node=kind-worker
20.9376,TaskRequest,MODIFIED,eval-sanitize-40-r4-007,phase=Complete job=None
20.947,Job,MODIFIED,eval-sanitize-40-r4-007,
20.9485,Job,MODIFIED,eval-sanitize-40-r4-009,
21.115,TaskRequest,ADDED,eval-sanitize-40-r4-021,phase=None job=None
21.1175,Job,MODIFIED,eval-sanitize-40-r4-020,
21.1186,TaskRequest,MODIFIED,eval-sanitize-40-r4-021,phase=Pending job=None
21.1228,Pod,MODIFIED,eval-sanitize-40-r4-009-zv98g,phase=Succeeded node=kind-worker
21.1334,Job,ADDED,eval-sanitize-40-r4-021,
21.1412,Pod,ADDED,eval-sanitize-40-r4-021-pxtwr,phase=Pending node=None
21.1424,TaskRequest,MODIFIED,eval-sanitize-40-r4-021,phase=Scheduled job=None
21.1432,Job,MODIFIED,eval-sanitize-40-r4-021,
21.1454,Event,ADDED,eval-sanitize-40-r4-021.18d40a0039c5cab6,reason=SuccessfulCreate count=1 msg=Created pod: eval-sanitize-40-r4-021-pxtwr
21.1506,TaskRequest,MODIFIED,eval-sanitize-40-r4-021,phase=Scheduled job=None
21.1532,Job,MODIFIED,eval-sanitize-40-r4-020,
21.1729,Job,MODIFIED,eval-sanitize-40-r4-019,
21.1811,Job,MODIFIED,eval-sanitize-40-r4-019,
21.2177,Pod,MODIFIED,eval-sanitize-40-r4-021-pxtwr,phase=Pending node=kind-worker5
21.2211,Event,ADDED,eval-sanitize-40-r4-021-pxtwr.18d40a003e5178da,reason=Scheduled count=None msg=Successfully assigned compute/eval-sanitize-40-r4-021-pxtwr to kind-worker5
21.227,Pod,MODIFIED,eval-sanitize-40-r4-021-pxtwr,phase=Pending node=kind-worker5
21.7238,Event,ADDED,eval-sanitize-40-r4-021-pxtwr.18d40a005c34d588,"reason=Pulled count=1 msg=Container image ""busybox:musl"" already present on machine"
21.7446,Event,ADDED,eval-sanitize-40-r4-021-pxtwr.18d40a005d664b4a,reason=Created count=1 msg=Created container: task
21.8193,Event,ADDED,eval-sanitize-40-r4-021-pxtwr.18d40a0061f18df0,reason=Started count=1 msg=Started container task
21.9229,Pod,MODIFIED,eval-sanitize-40-r4-021-pxtwr,phase=Running node=kind-worker5
21.9387,Pod,MODIFIED,eval-sanitize-40-r4-011-t2nwq,phase=Running node=kind-worker
21.9403,Job,MODIFIED,eval-sanitize-40-r4-009,
21.9492,Pod,MODIFIED,eval-sanitize-40-r4-009-zv98g,phase=Succeeded node=kind-worker
21.9507,Job,MODIFIED,eval-sanitize-40-r4-009,
22.0081,TaskRequest,ADDED,eval-sanitize-40-r4-022,phase=None job=None
22.0119,TaskRequest,MODIFIED,eval-sanitize-40-r4-022,phase=Pending job=None
22.0279,Job,ADDED,eval-sanitize-40-r4-022,
22.0341,Pod,ADDED,eval-sanitize-40-r4-022-7m7tt,phase=Pending node=None
22.0385,Job,MODIFIED,eval-sanitize-40-r4-022,
22.0388,Event,ADDED,eval-sanitize-40-r4-022.18d40a006effb11f,reason=SuccessfulCreate count=1 msg=Created pod: eval-sanitize-40-r4-022-7m7tt
22.1366,TaskRequest,MODIFIED,eval-sanitize-40-r4-022,phase=Scheduled job=None
22.1389,Job,MODIFIED,eval-sanitize-40-r4-022,
22.1443,TaskRequest,MODIFIED,eval-sanitize-40-r4-022,phase=Scheduled job=None
22.1469,Job,MODIFIED,eval-sanitize-40-r4-021,
22.151,Job,MODIFIED,eval-sanitize-40-r4-022,
22.1877,Job,MODIFIED,eval-sanitize-40-r4-021,
22.2023,Pod,MODIFIED,eval-sanitize-40-r4-022-7m7tt,phase=Pending node=None
22.2027,Event,ADDED,eval-sanitize-40-r4-022-7m7tt.18d40a0078accbbd,"reason=FailedScheduling count=None msg=0/6 nodes are available: 1 c_wall violated: 2 conflicting context pair(s) with node memory, 1 c_wall violated: 3 conflicting context pair(s) with node memory, 2 c_wall violated: 1 conflicting context pair(s) with node memory, 2 node(s) had untolerated taint(s). no new claims to deallocate, preemption: 0/6 nodes are available: 2 Preemption is not helpful for scheduling, 4 No preemption victims found for incoming pod."
22.3116,Event,ADDED,eval-sanitize-40-r4-022-7m7tt.18d40a007e901d50,"reason=FailedScheduling count=None msg=0/6 nodes are available: 1 c_wall violated: 2 conflicting context pair(s) with node memory, 1 c_wall violated: 3 conflicting context pair(s) with node memory, 2 c_wall violated: 1 conflicting context pair(s) with node memory, 2 node(s) had untolerated taint(s). no new claims to deallocate, preemption: 0/6 nodes are available: 2 Preemption is not helpful for scheduling, 4 No preemption victims found for incoming pod."
22.9054,Pod,MODIFIED,eval-sanitize-40-r4-012-vsl8p,phase=Running node=kind-worker5
23.0172,Job,MODIFIED,eval-sanitize-40-r4-011,
23.0209,TaskRequest,ADDED,eval-sanitize-40-r4-023,phase=None job=None
23.0222,Job,MODIFIED,eval-sanitize-40-r4-009,
23.026,Job,MODIFIED,eval-sanitize-40-r4-011,
23.0261,TaskRequest,MODIFIED,eval-sanitize-40-r4-023,phase=Pending job=None
23.0269,Job,MODIFIED,eval-sanitize-40-r4-009,
23.0304,Event,ADDED,eval-sanitize-40-r4-009.18d40a00aa1dec3a,reason=Completed count=1 msg=Job completed
23.0405,Job,ADDED,eval-sanitize-40-r4-023,
23.0466,Pod,ADDED,eval-sanitize-40-r4-023-tck4r,phase=Pending node=None
23.0468,TaskRequest,MODIFIED,eval-sanitize-40-r4-023,phase=Scheduled job=None
23.0493,Job,MODIFIED,eval-sanitize-40-r4-023,
23.0515,Event,ADDED,eval-sanitize-40-r4-023.18d40a00ab592ff2,reason=SuccessfulCreate count=1 msg=Created pod: eval-sanitize-40-r4-023-tck4r
23.0535,TaskRequest,MODIFIED,eval-sanitize-40-r4-023,phase=Scheduled job=None
23.0561,Job,MODIFIED,eval-sanitize-40-r4-009,
23.0606,TaskRequest,MODIFIED,eval-sanitize-40-r4-009,phase=Complete job=None
23.07,Job,MODIFIED,eval-sanitize-40-r4-009,
23.1044,Event,MODIFIED,eval-sanitize-40-r4-022-7m7tt.18d40a007e901d50,"reason=FailedScheduling count=None msg=0/6 nodes are available: 1 c_wall violated: 2 conflicting context pair(s) with node memory, 1 c_wall violated: 3 conflicting context pair(s) with node memory, 2 c_wall violated: 1 conflicting context pair(s) with node memory, 2 node(s) had untolerated taint(s). no new claims to deallocate, preemption: 0/6 nodes are available: 2 Preemption is not helpful for scheduling, 4 No preemption victims found for incoming pod."
23.1317,Pod,MODIFIED,eval-sanitize-40-r4-011-t2nwq,phase=Succeeded node=kind-worker
23.2796,Pod,MODIFIED,eval-sanitize-40-r4-023-tck4r,phase=Pending node=kind-worker2
23.2807,Pod,MODIFIED,eval-sanitize-40-r4-010-92scj,phase=Pending node=None
23.2837,Event,ADDED,eval-sanitize-40-r4-023-tck4r.18d40a00b92a8ea5,reason=Scheduled count=None msg=Successfully assigned compute/eval-sanitize-40-r4-023-tck4r to kind-worker2
23.2902,Node,MODIFIED,kind-worker2,taints=0
23.2922,Pod,MODIFIED,eval-sanitize-40-r4-023-tck4r,phase=Pending node=kind-worker2
23.3016,Node,MODIFIED,kind-worker2,taints=0
23.3143,Pod,MODIFIED,eval-sanitize-40-r4-008-sbdmc,phase=Pending node=None
23.4094,Pod,MODIFIED,eval-sanitize-40-r4-022-7m7tt,phase=Pending node=None
23.5602,Event,ADDED,eval-sanitize-40-r4-010-92scj.18d40a00c688a892,"reason=FailedScheduling count=None msg=0/6 nodes are available: 1 c_wall violated: 1 conflicting context pair(s) with node memory, 1 c_wall violated: 3 conflicting context pair(s) with node memory, 2 c_wall violated: 2 conflicting context pair(s) with node memory, 2 node(s) had untolerated taint(s). no new claims to deallocate, preemption: 0/6 nodes are available: 2 Preemption is not helpful for scheduling, 4 No preemption victims found for incoming pod."
23.6071,Event,ADDED,eval-sanitize-40-r4-008-sbdmc.18d40a00cc608b26,"reason=FailedScheduling count=None msg=0/6 nodes are available: 1 c_wall violated: 1 conflicting context pair(s) with node memory, 1 c_wall violated: 3 conflicting context pair(s) with node memory, 2 c_wall violated: 2 conflicting context pair(s) with node memory, 2 node(s) had untolerated taint(s). no new claims to deallocate, preemption: 0/6 nodes are available: 2 Preemption is not helpful for scheduling, 4 No preemption victims found for incoming pod."
23.7322,Event,ADDED,eval-sanitize-40-r4-022-7m7tt.18d40a00d23f21a3,"reason=FailedScheduling count=None msg=0/6 nodes are available: 1 c_wall violated: 1 conflicting context pair(s) with node memory, 1 c_wall violated: 3 conflicting context pair(s) with node memory, 2 c_wall violated: 2 conflicting context pair(s) with node memory, 2 node(s) had untolerated taint(s). no new claims to deallocate, preemption: 0/6 nodes are available: 2 Preemption is not helpful for scheduling, 4 No preemption victims found for incoming pod."
23.7376,Event,ADDED,eval-sanitize-40-r4-023-tck4r.18d40a00d452c21e,"reason=Pulled count=1 msg=Container image ""busybox:musl"" already present on machine"
23.7635,Event,ADDED,eval-sanitize-40-r4-023-tck4r.18d40a00d5acaa72,reason=Created count=1 msg=Created container: task
23.9174,Job,MODIFIED,eval-sanitize-40-r4-012,
23.9201,Event,ADDED,eval-sanitize-40-r4-023-tck4r.18d40a00df27ccec,reason=Started count=1 msg=Started container task
23.9263,Job,MODIFIED,eval-sanitize-40-r4-012,
23.9454,Pod,MODIFIED,eval-sanitize-40-r4-013-fhfpc,phase=Running node=kind-worker
23.9702,Event,MODIFIED,eval-sanitize-40-r4-010-92scj.18d40a00c688a892,"reason=FailedScheduling count=None msg=0/6 nodes are available: 1 c_wall violated: 1 conflicting context pair(s) with node memory, 1 c_wall violated: 3 conflicting context pair(s) with node memory, 2 c_wall violated: 2 conflicting context pair(s) with node memory, 2 node(s) had untolerated taint(s). no new claims to deallocate, preemption: 0/6 nodes are available: 2 Preemption is not helpful for scheduling, 4 No preemption victims found for incoming pod."
23.979,Pod,MODIFIED,eval-sanitize-40-r4-012-vsl8p,phase=Succeeded node=kind-worker5
24.0881,Event,MODIFIED,eval-sanitize-40-r4-008-sbdmc.18d40a00cc608b26,"reason=FailedScheduling count=None msg=0/6 nodes are available: 1 c_wall violated: 1 conflicting context pair(s) with node memory, 1 c_wall violated: 3 conflicting context pair(s) with node memory, 2 c_wall violated: 2 conflicting context pair(s) with node memory, 2 node(s) had untolerated taint(s). no new claims to deallocate, preemption: 0/6 nodes are available: 2 Preemption is not helpful for scheduling, 4 No preemption victims found for incoming pod."
24.0885,TaskRequest,ADDED,eval-sanitize-40-r4-024,phase=None job=None
24.0893,Job,MODIFIED,eval-sanitize-40-r4-011,
24.0904,Job,MODIFIED,eval-sanitize-40-r4-023,
24.0979,Pod,MODIFIED,eval-sanitize-40-r4-011-t2nwq,phase=Succeeded node=kind-worker
24.098,TaskRequest,MODIFIED,eval-sanitize-40-r4-024,phase=Pending job=None
24.101,Job,MODIFIED,eval-sanitize-40-r4-011,
24.1062,Event,MODIFIED,eval-sanitize-40-r4-022-7m7tt.18d40a00d23f21a3,"reason=FailedScheduling count=None msg=0/6 nodes are available: 1 c_wall violated: 1 conflicting context pair(s) with node memory, 1 c_wall violated: 3 conflicting context pair(s) with node memory, 2 c_wall violated: 2 conflicting context pair(s) with node memory, 2 node(s) had untolerated taint(s). no new claims to deallocate, preemption: 0/6 nodes are available: 2 Preemption is not helpful for scheduling, 4 No preemption victims found for incoming pod."
24.1129,Job,ADDED,eval-sanitize-40-r4-024,
24.119,Pod,ADDED,eval-sanitize-40-r4-024-qs8vx,phase=Pending node=None
24.1192,TaskRequest,MODIFIED,eval-sanitize-40-r4-024,phase=Scheduled job=None
24.1221,Job,MODIFIED,eval-sanitize-40-r4-024,
24.1233,Event,ADDED,eval-sanitize-40-r4-024.18d40a00eb43a1cf,reason=SuccessfulCreate count=1 msg=Created pod: eval-sanitize-40-r4-024-qs8vx
24.1265,TaskRequest,MODIFIED,eval-sanitize-40-r4-024,phase=Scheduled job=None
24.129,Job,MODIFIED,eval-sanitize-40-r4-023,
24.3793,Pod,MODIFIED,eval-sanitize-40-r4-024-qs8vx,phase=Pending node=kind-worker
24.3868,Pod,MODIFIED,eval-sanitize-40-r4-023-tck4r,phase=Running node=kind-worker2
24.3873,Event,ADDED,eval-sanitize-40-r4-024-qs8vx.18d40a00fac08961,reason=Scheduled count=None msg=Successfully assigned compute/eval-sanitize-40-r4-024-qs8vx to kind-worker
24.3908,Pod,MODIFIED,eval-sanitize-40-r4-024-qs8vx,phase=Pending node=kind-worker
24.797,Event,ADDED,eval-sanitize-40-r4-024-qs8vx.18d40a01136bcdd0,"reason=Pulled count=1 msg=Container image ""busybox:musl"" already present on machine"
24.8161,Event,ADDED,eval-sanitize-40-r4-024-qs8vx.18d40a01148a69e8,reason=Created count=1 msg=Created container: task
24.9221,Job,MODIFIED,eval-sanitize-40-r4-012,
24.9296,Pod,MODIFIED,eval-sanitize-40-r4-012-vsl8p,phase=Succeeded node=kind-worker5
24.9319,Job,MODIFIED,eval-sanitize-40-r4-012,
24.9496,Pod,MODIFIED,eval-sanitize-40-r4-014-tdhkt,phase=Running node=kind-worker
24.9504,Job,MODIFIED,eval-sanitize-40-r4-013,
24.9601,Job,MODIFIED,eval-sanitize-40-r4-013,
25.0077,TaskRequest,ADDED,eval-sanitize-40-r4-025,phase=None job=None
25.0131,TaskRequest,MODIFIED,eval-sanitize-40-r4-025,phase=Pending job=None
25.0281,Job,ADDED,eval-sanitize-40-r4-025,
25.0339,Pod,ADDED,eval-sanitize-40-r4-025-d52pp,phase=Pending node=None
25.0351,TaskRequest,MODIFIED,eval-sanitize-40-r4-025,phase=Scheduled job=None
25.0377,Job,MODIFIED,eval-sanitize-40-r4-025,
25.0395,Event,ADDED,eval-sanitize-40-r4-025.18d40a0121d0aaf5,reason=SuccessfulCreate count=1 msg=Created pod: eval-sanitize-40-r4-025-d52pp
25.0411,TaskRequest,MODIFIED,eval-sanitize-40-r4-025,phase=Scheduled job=None
25.1062,Job,MODIFIED,eval-sanitize-40-r4-011,
25.1074,Job,MODIFIED,eval-sanitize-40-r4-023,
25.109,Job,MODIFIED,eval-sanitize-40-r4-011,
25.1168,Event,ADDED,eval-sanitize-40-r4-011.18d40a01262f68ad,reason=Completed count=1 msg=Job completed
25.118,Job,MODIFIED,eval-sanitize-40-r4-023,
25.1205,Job,MODIFIED,eval-sanitize-40-r4-011,
25.1212,Event,ADDED,eval-sanitize-40-r4-024-qs8vx.18d40a0126a1b583,reason=Started count=1 msg=Started container task
25.1248,Job,MODIFIED,eval-sanitize-40-r4-024,
25.1256,TaskRequest,MODIFIED,eval-sanitize-40-r4-011,phase=Complete job=None
25.1377,Job,MODIFIED,eval-sanitize-40-r4-024,
25.1385,Job,MODIFIED,eval-sanitize-40-r4-011,
25.2227,Pod,MODIFIED,eval-sanitize-40-r4-025-d52pp,phase=Pending node=kind-worker
25.2294,Pod,MODIFIED,eval-sanitize-40-r4-013-fhfpc,phase=Succeeded node=kind-worker
25.2297,Event,ADDED,eval-sanitize-40-r4-025-d52pp.18d40a012d0533fb,reason=Scheduled count=None msg=Successfully assigned compute/eval-sanitize-40-r4-025-d52pp to kind-worker
25.2358,Pod,MODIFIED,eval-sanitize-40-r4-025-d52pp,phase=Pending node=kind-worker
25.649,Event,ADDED,eval-sanitize-40-r4-025-d52pp.18d40a01461edce2,"reason=Pulled count=1 msg=Container image ""busybox:musl"" already present on machine"
25.6666,Event,ADDED,eval-sanitize-40-r4-025-d52pp.18d40a0147312f2d,reason=Created count=1 msg=Created container: task
25.7514,Event,ADDED,eval-sanitize-40-r4-025-d52pp.18d40a014c366e31,reason=Started count=1 msg=Started container task
25.9279,Job,MODIFIED,eval-sanitize-40-r4-012,
25.9317,Job,MODIFIED,eval-sanitize-40-r4-012,
25.9363,Event,ADDED,eval-sanitize-40-r4-012.18d40a01573c0741,reason=Completed count=1 msg=Job completed
25.9419,Job,MODIFIED,eval-sanitize-40-r4-012,
25.947,TaskRequest,MODIFIED,eval-sanitize-40-r4-012,phase=Complete job=None
25.9542,Pod,MODIFIED,eval-sanitize-40-r4-015-c4nvv,phase=Running node=kind-worker
25.9581,Job,MODIFIED,eval-sanitize-40-r4-014,
25.9588,Job,MODIFIED,eval-sanitize-40-r4-013,
25.96,Job,MODIFIED,eval-sanitize-40-r4-012,
25.9647,Pod,MODIFIED,eval-sanitize-40-r4-024-qs8vx,phase=Running node=kind-worker
25.9663,Pod,MODIFIED,eval-sanitize-40-r4-013-fhfpc,phase=Succeeded node=kind-worker
25.9702,Job,MODIFIED,eval-sanitize-40-r4-013,
25.9726,Job,MODIFIED,eval-sanitize-40-r4-014,
25.9739,Pod,MODIFIED,eval-sanitize-40-r4-025-d52pp,phase=Running node=kind-worker
25.9745,Event,ADDED,eval-sanitize-40-r4-013.18d40a015981e30c,reason=Completed count=1 msg=Job completed
25.9807,Job,MODIFIED,eval-sanitize-40-r4-013,
25.9849,TaskRequest,MODIFIED,eval-sanitize-40-r4-013,phase=Complete job=None
25.9949,Job,MODIFIED,eval-sanitize-40-r4-013,
26.0063,TaskRequest,ADDED,eval-sanitize-40-r4-026,phase=None job=None
26.01,TaskRequest,MODIFIED,eval-sanitize-40-r4-026,phase=Pending job=None
26.07,Job,MODIFIED,eval-sanitize-40-r4-025,
26.0708,Job,ADDED,eval-sanitize-40-r4-026,
26.0755,Pod,MODIFIED,eval-sanitize-40-r4-014-tdhkt,phase=Succeeded node=kind-worker
26.0763,TaskRequest,MODIFIED,eval-sanitize-40-r4-026,phase=Scheduled job=None
26.0771,Pod,ADDED,eval-sanitize-40-r4-026-8vj8k,phase=Pending node=None
26.08,Job,MODIFIED,eval-sanitize-40-r4-026,
26.0823,Event,ADDED,eval-sanitize-40-r4-026.18d40a015fe2ff1b,reason=SuccessfulCreate count=1 msg=Created pod: eval-sanitize-40-r4-026-8vj8k
26.0829,TaskRequest,MODIFIED,eval-sanitize-40-r4-026,phase=Scheduled job=None
26.0855,Job,MODIFIED,eval-sanitize-40-r4-025,
26.1313,Job,MODIFIED,eval-sanitize-40-r4-024,
26.1401,Job,MODIFIED,eval-sanitize-40-r4-024,
26.2827,Pod,MODIFIED,eval-sanitize-40-r4-026-8vj8k,phase=Pending node=None
26.283,Event,ADDED,eval-sanitize-40-r4-026-8vj8k.18d40a016ae0d39b,"reason=FailedScheduling count=None msg=0/6 nodes are available: 1 c_wall violated: 1 conflicting context pair(s) with node memory, 1 c_wall violated: 3 conflicting context pair(s) with node memory, 2 c_wall violated: 2 conflicting context pair(s) with node memory, 2 node(s) had untolerated taint(s). no new claims to deallocate, preemption: 0/6 nodes are available: 2 Preemption is not helpful for scheduling, 4 No preemption victims found for incoming pod."
26.5739,Event,ADDED,eval-sanitize-40-r4-026-8vj8k.18d40a017d135603,"reason=FailedScheduling count=None msg=0/6 nodes are available: 1 c_wall violated: 1 conflicting context pair(s) with node memory, 1 c_wall violated: 3 conflicting context pair(s) with node memory, 2 c_wall violated: 2 conflicting context pair(s) with node memory, 2 node(s) had untolerated taint(s). no new claims to deallocate, preemption: 0/6 nodes are available: 2 Preemption is not helpful for scheduling, 4 No preemption victims found for incoming pod."
26.9604,Job,MODIFIED,eval-sanitize-40-r4-015,
26.9636,Job,MODIFIED,eval-sanitize-40-r4-014,
26.9707,Job,MODIFIED,eval-sanitize-40-r4-015,
26.9733,Pod,MODIFIED,eval-sanitize-40-r4-014-tdhkt,phase=Succeeded node=kind-worker
26.9745,Job,MODIFIED,eval-sanitize-40-r4-014,
27.0223,TaskRequest,ADDED,eval-sanitize-40-r4-027,phase=None job=None
27.0264,TaskRequest,MODIFIED,eval-sanitize-40-r4-027,phase=Pending job=None
27.042,Job,ADDED,eval-sanitize-40-r4-027,
27.0466,TaskRequest,MODIFIED,eval-sanitize-40-r4-027,phase=Scheduled job=None
27.0511,Pod,ADDED,eval-sanitize-40-r4-027-x2p67,phase=Pending node=None
27.0527,Job,MODIFIED,eval-sanitize-40-r4-027,
27.0551,Event,ADDED,eval-sanitize-40-r4-027.18d40a0199e7b6d2,reason=SuccessfulCreate count=1 msg=Created pod: eval-sanitize-40-r4-027-x2p67
27.0551,TaskRequest,MODIFIED,eval-sanitize-40-r4-027,phase=Scheduled job=None
27.0698,Pod,MODIFIED,eval-sanitize-40-r4-027-x2p67,phase=Pending node=None
27.071,Event,ADDED,eval-sanitize-40-r4-027-x2p67.18d40a019ac76d66,"reason=FailedScheduling count=None msg=0/6 nodes are available: 1 c_wall violated: 1 conflicting context pair(s) with node memory, 1 c_wall violated: 3 conflicting context pair(s) with node memory, 2 c_wall violated: 2 conflicting context pair(s) with node memory, 2 node(s) had untolerated taint(s). no new claims to deallocate, preemption: 0/6 nodes are available: 2 Preemption is not helpful for scheduling, 4 No preemption victims found for incoming pod."
27.0818,Job,MODIFIED,eval-sanitize-40-r4-026,
27.0872,Pod,MODIFIED,eval-sanitize-40-r4-015-c4nvv,phase=Succeeded node=kind-worker
27.0905,Job,MODIFIED,eval-sanitize-40-r4-026,
27.2105,Event,ADDED,eval-sanitize-40-r4-027-x2p67.18d40a01a0ba8e04,"reason=FailedScheduling count=None msg=0/6 nodes are available: 1 c_wall violated: 1 conflicting context pair(s) with node memory, 1 c_wall violated: 3 conflicting context pair(s) with node memory, 2 c_wall violated: 2 conflicting context pair(s) with node memory, 2 node(s) had untolerated taint(s). no new claims to deallocate, preemption: 0/6 nodes are available: 2 Preemption is not helpful for scheduling, 4 No preemption victims found for incoming pod."
27.5017,Event,MODIFIED,eval-sanitize-40-r4-026-8vj8k.18d40a017d135603,"reason=FailedScheduling count=None msg=0/6 nodes are available: 1 c_wall violated: 1 conflicting context pair(s) with node memory, 1 c_wall violated: 3 conflicting context pair(s) with node memory, 2 c_wall violated: 2 conflicting context pair(s) with node memory, 2 node(s) had untolerated taint(s). no new claims to deallocate, preemption: 0/6 nodes are available: 2 Preemption is not helpful for scheduling, 4 No preemption victims found for incoming pod."
27.5989,Event,MODIFIED,eval-sanitize-40-r4-027-x2p67.18d40a01a0ba8e04,"reason=FailedScheduling count=None msg=0/6 nodes are available: 1 c_wall violated: 1 conflicting context pair(s) with node memory, 1 c_wall violated: 3 conflicting context pair(s) with node memory, 2 c_wall violated: 2 conflicting context pair(s) with node memory, 2 node(s) had untolerated taint(s). no new claims to deallocate, preemption: 0/6 nodes are available: 2 Preemption is not helpful for scheduling, 4 No preemption victims found for incoming pod."
27.7476,Pod,MODIFIED,eval-sanitize-40-r4-016-cczvx,phase=Running node=kind-worker4
27.9607,Pod,MODIFIED,eval-sanitize-40-r4-017-2p92w,phase=Running node=kind-worker5
27.9855,Job,MODIFIED,eval-sanitize-40-r4-015,
27.987,Job,MODIFIED,eval-sanitize-40-r4-014,
27.9913,Job,MODIFIED,eval-sanitize-40-r4-014,
27.9942,Pod,MODIFIED,eval-sanitize-40-r4-015-c4nvv,phase=Succeeded node=kind-worker
27.997,Job,MODIFIED,eval-sanitize-40-r4-015,
27.9991,Event,ADDED,eval-sanitize-40-r4-014.18d40a01d1fdf70d,reason=Completed count=1 msg=Job completed
28.0063,Job,MODIFIED,eval-sanitize-40-r4-014,
28.0065,TaskRequest,ADDED,eval-sanitize-40-r4-028,phase=None job=None
28.0113,TaskRequest,MODIFIED,eval-sanitize-40-r4-014,phase=Complete job=None
28.0168,TaskRequest,MODIFIED,eval-sanitize-40-r4-028,phase=Pending job=None
28.0208,Job,MODIFIED,eval-sanitize-40-r4-014,
28.0314,Job,ADDED,eval-sanitize-40-r4-028,
28.0374,Pod,ADDED,eval-sanitize-40-r4-028-nxm9c,phase=Pending node=None
28.0392,Job,MODIFIED,eval-sanitize-40-r4-028,
28.0393,TaskRequest,MODIFIED,eval-sanitize-40-r4-028,phase=Scheduled job=None
28.0413,Event,ADDED,eval-sanitize-40-r4-028.18d40a01d4bd5e51,reason=SuccessfulCreate count=1 msg=Created pod: eval-sanitize-40-r4-028-nxm9c
28.0466,TaskRequest,MODIFIED,eval-sanitize-40-r4-028,phase=Scheduled job=None
28.0539,Job,MODIFIED,eval-sanitize-40-r4-027,
28.0877,Job,MODIFIED,eval-sanitize-40-r4-027,
28.1813,Pod,MODIFIED,eval-sanitize-40-r4-028-nxm9c,phase=Pending node=kind-worker4
28.1865,Event,ADDED,eval-sanitize-40-r4-028-nxm9c.18d40a01dd502b85,reason=Scheduled count=None msg=Successfully assigned compute/eval-sanitize-40-r4-028-nxm9c to kind-worker4
28.1913,Pod,MODIFIED,eval-sanitize-40-r4-028-nxm9c,phase=Pending node=kind-worker4
28.6076,Event,ADDED,eval-sanitize-40-r4-028-nxm9c.18d40a01f677c7af,"reason=Pulled count=1 msg=Container image ""busybox:musl"" already present on machine"
28.6249,Event,ADDED,eval-sanitize-40-r4-028-nxm9c.18d40a01f7865438,reason=Created count=1 msg=Created container: task
28.6587,Event,ADDED,eval-sanitize-40-r4-028-nxm9c.18d40a01f98627e8,reason=Started count=1 msg=Started container task
28.7588,Pod,MODIFIED,eval-sanitize-40-r4-028-nxm9c,phase=Running node=kind-worker4
28.7601,Job,MODIFIED,eval-sanitize-40-r4-016,
28.7697,Job,MODIFIED,eval-sanitize-40-r4-016,
28.9224,Pod,MODIFIED,eval-sanitize-40-r4-018-97rrz,phase=Running node=kind-worker5
28.9435,Pod,MODIFIED,eval-sanitize-40-r4-016-cczvx,phase=Succeeded node=kind-worker4
29.0043,Job,MODIFIED,eval-sanitize-40-r4-017,
29.0075,Job,MODIFIED,eval-sanitize-40-r4-015,
29.0078,TaskRequest,ADDED,eval-sanitize-40-r4-029,phase=None job=None
29.0115,Job,MODIFIED,eval-sanitize-40-r4-015,
29.0138,Job,MODIFIED,eval-sanitize-40-r4-017,
29.0139,TaskRequest,MODIFIED,eval-sanitize-40-r4-029,phase=Pending job=None
29.0153,Pod,MODIFIED,eval-sanitize-40-r4-017-2p92w,phase=Succeeded node=kind-worker5
29.0165,Event,ADDED,eval-sanitize-40-r4-015.18d40a020ecd41fc,reason=Completed count=1 msg=Job completed
29.0232,Job,MODIFIED,eval-sanitize-40-r4-015,
29.0275,Job,ADDED,eval-sanitize-40-r4-029,
29.0318,TaskRequest,MODIFIED,eval-sanitize-40-r4-029,phase=Scheduled job=None
29.0347,Pod,ADDED,eval-sanitize-40-r4-029-gbx8m,phase=Pending node=None
29.0365,Job,MODIFIED,eval-sanitize-40-r4-029,
29.038,TaskRequest,MODIFIED,eval-sanitize-40-r4-015,phase=Complete job=None
29.0388,Event,ADDED,eval-sanitize-40-r4-029.18d40a02102eb125,reason=SuccessfulCreate count=1 msg=Created pod: eval-sanitize-40-r4-029-gbx8m
29.0388,TaskRequest,MODIFIED,eval-sanitize-40-r4-029,phase=Scheduled job=None
29.0427,Job,MODIFIED,eval-sanitize-40-r4-028,
29.0465,Job,MODIFIED,eval-sanitize-40-r4-015,
29.0862,Job,MODIFIED,eval-sanitize-40-r4-028,
29.1705,Pod,MODIFIED,eval-sanitize-40-r4-029-gbx8m,phase=Pending node=kind-worker
29.1758,Event,ADDED,eval-sanitize-40-r4-029-gbx8m.18d40a02183fa9b4,reason=Scheduled count=None msg=Successfully assigned compute/eval-sanitize-40-r4-029-gbx8m to kind-worker
29.1818,Pod,MODIFIED,eval-sanitize-40-r4-029-gbx8m,phase=Pending node=kind-worker
29.5893,Event,ADDED,eval-sanitize-40-r4-029-gbx8m.18d40a0230fa4a45,"reason=Pulled count=1 msg=Container image ""busybox:musl"" already present on machine"
29.6074,Event,ADDED,eval-sanitize-40-r4-029-gbx8m.18d40a02320f3e7d,reason=Created count=1 msg=Created container: task
29.6404,Event,ADDED,eval-sanitize-40-r4-029-gbx8m.18d40a0233faa7f6,reason=Started count=1 msg=Started container task
29.7665,Job,MODIFIED,eval-sanitize-40-r4-016,
29.776,Pod,MODIFIED,eval-sanitize-40-r4-016-cczvx,phase=Succeeded node=kind-worker4
29.7771,Job,MODIFIED,eval-sanitize-40-r4-016,
29.9288,Job,MODIFIED,eval-sanitize-40-r4-018,
29.941,Job,MODIFIED,eval-sanitize-40-r4-018,
30.0042,Pod,MODIFIED,eval-sanitize-40-r4-029-gbx8m,phase=Running node=kind-worker
30.0098,Pod,MODIFIED,eval-sanitize-40-r4-018-97rrz,phase=Succeeded node=kind-worker5
30.0106,TaskRequest,ADDED,eval-sanitize-40-r4-030,phase=None job=None
30.0116,Job,MODIFIED,eval-sanitize-40-r4-017,
30.0167,TaskRequest,MODIFIED,eval-sanitize-40-r4-030,phase=Pending job=None
30.0204,Pod,MODIFIED,eval-sanitize-40-r4-017-2p92w,phase=Succeeded node=kind-worker5
30.0227,Job,MODIFIED,eval-sanitize-40-r4-017,
30.0347,Job,ADDED,eval-sanitize-40-r4-030,
30.0392,Job,MODIFIED,eval-sanitize-40-r4-029,
30.0408,TaskRequest,MODIFIED,eval-sanitize-40-r4-030,phase=Scheduled job=None
30.0415,Pod,ADDED,eval-sanitize-40-r4-030-kgdr2,phase=Pending node=None
30.0432,Job,MODIFIED,eval-sanitize-40-r4-030,
30.0458,Event,ADDED,eval-sanitize-40-r4-030.18d40a024c335e02,reason=SuccessfulCreate count=1 msg=Created pod: eval-sanitize-40-r4-030-kgdr2
30.0471,TaskRequest,MODIFIED,eval-sanitize-40-r4-030,phase=Scheduled job=None
30.0494,Job,MODIFIED,eval-sanitize-40-r4-029,
30.2075,Pod,MODIFIED,eval-sanitize-40-r4-030-kgdr2,phase=Pending node=kind-worker5
30.2119,Event,ADDED,eval-sanitize-40-r4-030-kgdr2.18d40a02560cfba2,reason=Scheduled count=None msg=Successfully assigned compute/eval-sanitize-40-r4-030-kgdr2 to kind-worker5
30.218,Pod,MODIFIED,eval-sanitize-40-r4-030-kgdr2,phase=Pending node=kind-worker5
30.6406,Event,ADDED,eval-sanitize-40-r4-030-kgdr2.18d40a026fa5ecba,"reason=Pulled count=1 msg=Container image ""busybox:musl"" already present on machine"
30.6583,Event,ADDED,eval-sanitize-40-r4-030-kgdr2.18d40a0270bab885,reason=Created count=1 msg=Created container: task
30.726,Event,ADDED,eval-sanitize-40-r4-030-kgdr2.18d40a0274c2820f,reason=Started count=1 msg=Started container task
30.7896,Job,MODIFIED,eval-sanitize-40-r4-016,
30.8023,Job,MODIFIED,eval-sanitize-40-r4-016,
30.8056,Event,ADDED,eval-sanitize-40-r4-016.18d40a02798b3b8a,reason=Completed count=1 msg=Job completed
30.8107,Job,MODIFIED,eval-sanitize-40-r4-016,
30.8156,TaskRequest,MODIFIED,eval-sanitize-40-r4-016,phase=Complete job=None
30.8253,Job,MODIFIED,eval-sanitize-40-r4-016,
30.9435,Job,MODIFIED,eval-sanitize-40-r4-018,
30.9496,Pod,MODIFIED,eval-sanitize-40-r4-019-g28rc,phase=Running node=kind-worker5
30.9523,Pod,MODIFIED,eval-sanitize-40-r4-018-97rrz,phase=Succeeded node=kind-worker5
30.9538,Job,MODIFIED,eval-sanitize-40-r4-018,
30.9585,Pod,MODIFIED,eval-sanitize-40-r4-030-kgdr2,phase=Running node=kind-worker5
30.9736,Pod,MODIFIED,eval-sanitize-40-r4-020-f8d9v,phase=Running node=kind-worker
31.0221,TaskRequest,ADDED,eval-sanitize-40-r4-031,phase=None job=None
31.0245,Job,MODIFIED,eval-sanitize-40-r4-017,
31.0269,TaskRequest,MODIFIED,eval-sanitize-40-r4-031,phase=Pending job=None
31.0303,Job,MODIFIED,eval-sanitize-40-r4-017,
31.0334,Event,ADDED,eval-sanitize-40-r4-017.18d40a02871b2a22,reason=Completed count=1 msg=Job completed
31.046,Job,ADDED,eval-sanitize-40-r4-031,
31.0486,Job,MODIFIED,eval-sanitize-40-r4-030,
31.0504,TaskRequest,MODIFIED,eval-sanitize-40-r4-031,phase=Scheduled job=None
31.0546,Pod,ADDED,eval-sanitize-40-r4-031-lf45v,phase=Pending node=None
31.0566,Job,MODIFIED,eval-sanitize-40-r4-031,
31.0609,Event,ADDED,eval-sanitize-40-r4-031.18d40a02888f894b,reason=SuccessfulCreate count=1 msg=Created pod: eval-sanitize-40-r4-031-lf45v
31.061,TaskRequest,MODIFIED,eval-sanitize-40-r4-031,phase=Scheduled job=None
31.062,Job,MODIFIED,eval-sanitize-40-r4-017,
31.0633,Job,MODIFIED,eval-sanitize-40-r4-030,
31.0731,TaskRequest,MODIFIED,eval-sanitize-40-r4-017,phase=Complete job=None
31.0849,Job,MODIFIED,eval-sanitize-40-r4-017,
31.1931,Pod,MODIFIED,eval-sanitize-40-r4-031-lf45v,phase=Pending node=kind-worker5
31.197,Event,ADDED,eval-sanitize-40-r4-031-lf45v.18d40a0290d3dd59,reason=Scheduled count=None msg=Successfully assigned compute/eval-sanitize-40-r4-031-lf45v to kind-worker5
31.2042,Pod,MODIFIED,eval-sanitize-40-r4-031-lf45v,phase=Pending node=kind-worker5
31.6472,Event,ADDED,eval-sanitize-40-r4-031-lf45v.18d40a02aba6a90c,"reason=Pulled count=1 msg=Container image ""busybox:musl"" already present on machine"
31.6655,Event,ADDED,eval-sanitize-40-r4-031-lf45v.18d40a02acc08f69,reason=Created count=1 msg=Created container: task
31.7516,Event,ADDED,eval-sanitize-40-r4-031-lf45v.18d40a02b1e59d15,reason=Started count=1 msg=Started container task
31.9494,Job,MODIFIED,eval-sanitize-40-r4-018,
31.9531,Job,MODIFIED,eval-sanitize-40-r4-019,
31.9559,Job,MODIFIED,eval-sanitize-40-r4-018,
31.9573,Pod,MODIFIED,eval-sanitize-40-r4-021-pxtwr,phase=Running node=kind-worker5
31.9608,Event,ADDED,eval-sanitize-40-r4-018.18d40a02be457f55,reason=Completed count=1 msg=Job completed
31.9642,Job,MODIFIED,eval-sanitize-40-r4-019,
31.9668,Job,MODIFIED,eval-sanitize-40-r4-018,
31.9682,Pod,MODIFIED,eval-sanitize-40-r4-031-lf45v,phase=Running node=kind-worker5
31.9719,TaskRequest,MODIFIED,eval-sanitize-40-r4-018,phase=Complete job=None
31.9789,Job,MODIFIED,eval-sanitize-40-r4-020,
31.9818,Job,MODIFIED,eval-sanitize-40-r4-018,
31.9886,Job,MODIFIED,eval-sanitize-40-r4-020,
32.0079,TaskRequest,ADDED,eval-sanitize-40-r4-032,phase=None job=None
32.0116,TaskRequest,MODIFIED,eval-sanitize-40-r4-032,phase=Pending job=None
32.0822,Job,ADDED,eval-sanitize-40-r4-032,
32.0872,Job,MODIFIED,eval-sanitize-40-r4-031,
32.0873,TaskRequest,MODIFIED,eval-sanitize-40-r4-032,phase=Scheduled job=None
32.0899,Pod,ADDED,eval-sanitize-40-r4-032-9r59c,phase=Pending node=None
32.0915,Job,MODIFIED,eval-sanitize-40-r4-032,
32.0958,Pod,MODIFIED,eval-sanitize-40-r4-019-g28rc,phase=Succeeded node=kind-worker5
32.0965,Event,ADDED,eval-sanitize-40-r4-032.18d40a02c64b443b,reason=SuccessfulCreate count=1 msg=Created pod: eval-sanitize-40-r4-032-9r59c
32.0967,TaskRequest,MODIFIED,eval-sanitize-40-r4-032,phase=Scheduled job=None
32.0986,Job,MODIFIED,eval-sanitize-40-r4-031,
32.2381,Pod,MODIFIED,eval-sanitize-40-r4-020-f8d9v,phase=Succeeded node=kind-worker
32.3032,Pod,MODIFIED,eval-sanitize-40-r4-032-9r59c,phase=Pending node=kind-worker
32.3085,Event,ADDED,eval-sanitize-40-r4-032-9r59c.18d40a02d302076b,reason=Scheduled count=None msg=Successfully assigned compute/eval-sanitize-40-r4-032-9r59c to kind-worker
32.3143,Pod,MODIFIED,eval-sanitize-40-r4-032-9r59c,phase=Pending node=kind-worker
32.7324,Event,ADDED,eval-sanitize-40-r4-032-9r59c.18d40a02ec5466c4,"reason=Pulled count=1 msg=Container image ""busybox:musl"" already present on machine"
32.751,Event,ADDED,eval-sanitize-40-r4-032-9r59c.18d40a02ed76f5bb,reason=Created count=1 msg=Created container: task
32.8425,Event,ADDED,eval-sanitize-40-r4-032-9r59c.18d40a02f2ce99a6,reason=Started count=1 msg=Started container task
33.0,Job,MODIFIED,eval-sanitize-40-r4-019,
33.0046,Job,MODIFIED,eval-sanitize-40-r4-021,
33.0054,Job,MODIFIED,eval-sanitize-40-r4-020,
33.0109,Pod,MODIFIED,eval-sanitize-40-r4-019-g28rc,phase=Succeeded node=kind-worker5
33.0121,TaskRequest,ADDED,eval-sanitize-40-r4-033,phase=None job=None
33.0142,Pod,MODIFIED,eval-sanitize-40-r4-032-9r59c,phase=Running node=kind-worker
33.015,Job,MODIFIED,eval-sanitize-40-r4-019,
33.0164,Pod,MODIFIED,eval-sanitize-40-r4-020-f8d9v,phase=Succeeded node=kind-worker
33.0171,Job,MODIFIED,eval-sanitize-40-r4-021,
33.0178,Job,MODIFIED,eval-sanitize-40-r4-020,
33.0184,TaskRequest,MODIFIED,eval-sanitize-40-r4-033,phase=Pending job=None
33.0338,Job,ADDED,eval-sanitize-40-r4-033,
33.0397,Pod,ADDED,eval-sanitize-40-r4-033-9d9p7,phase=Pending node=None
33.04,TaskRequest,MODIFIED,eval-sanitize-40-r4-033,phase=Scheduled job=None
33.0423,Job,MODIFIED,eval-sanitize-40-r4-033,
33.045,Event,ADDED,eval-sanitize-40-r4-033.18d40a02feeb1743,reason=SuccessfulCreate count=1 msg=Created pod: eval-sanitize-40-r4-033-9d9p7
33.0472,TaskRequest,MODIFIED,eval-sanitize-40-r4-033,phase=Scheduled job=None
33.1382,Job,MODIFIED,eval-sanitize-40-r4-032,
33.1409,Pod,MODIFIED,eval-sanitize-40-r4-033-9d9p7,phase=Pending node=kind-worker5
33.1443,Event,ADDED,eval-sanitize-40-r4-033-9d9p7.18d40a0304ebef1a,reason=Scheduled count=None msg=Successfully assigned compute/eval-sanitize-40-r4-033-9d9p7 to kind-worker5
33.1471,Job,MODIFIED,eval-sanitize-40-r4-032,
33.1509,Node,MODIFIED,kind-worker5,taints=0
33.1531,Pod,MODIFIED,eval-sanitize-40-r4-033-9d9p7,phase=Pending node=kind-worker5
33.1616,Node,MODIFIED,kind-worker5,taints=0
33.1641,Pod,MODIFIED,eval-sanitize-40-r4-021-pxtwr,phase=Succeeded node=kind-worker5
33.2211,Pod,MODIFIED,eval-sanitize-40-r4-010-92scj,phase=Pending node=None
33.3054,Pod,MODIFIED,eval-sanitize-40-r4-026-8vj8k,phase=Pending node=None
33.4108,Pod,MODIFIED,eval-sanitize-40-r4-027-x2p67,phase=Pending node=None
33.5049,Pod,MODIFIED,eval-sanitize-40-r4-008-sbdmc,phase=Pending node=None
33.6102,Pod,MODIFIED,eval-sanitize-40-r4-022-7m7tt,phase=Pending node=None
33.6146,Event,ADDED,eval-sanitize-40-r4-033-9d9p7.18d40a0320e2abfb,"reason=Pulled count=1 msg=Container image ""busybox:musl"" already present on machine"
33.6318,Event,ADDED,eval-sanitize-40-r4-033-9d9p7.18d40a0321fa9152,reason=Created count=1 msg=Created container: task
33.7283,Event,ADDED,eval-sanitize-40-r4-010-92scj.18d40a0325dec0a1,"reason=FailedScheduling count=None msg=0/6 nodes are available: 1 c_wall violated: 1 conflicting context pair(s) with node memory, 1 c_wall violated: 4 conflicting context pair(s) with node memory, 2 c_wall violated: 2 conflicting context pair(s) with node memory, 2 node(s) had untolerated taint(s). no new claims to deallocate, preemption: 0/6 nodes are available: 2 Preemption is not helpful for scheduling, 4 No preemption victims found for incoming pod."
33.7291,Event,ADDED,eval-sanitize-40-r4-026-8vj8k.18d40a0326b01fbd,"reason=FailedScheduling count=None msg=0/6 nodes are available: 1 c_wall violated: 1 conflicting context pair(s) with node memory, 1 c_wall violated: 4 conflicting context pair(s) with node memory, 2 c_wall violated: 2 conflicting context pair(s) with node memory, 2 node(s) had untolerated taint(s). no new claims to deallocate, preemption: 0/6 nodes are available: 2 Preemption is not helpful for scheduling, 4 No preemption victims found for incoming pod."
33.7303,Event,ADDED,eval-sanitize-40-r4-033-9d9p7.18d40a0327dfdd60,reason=Started count=1 msg=Started container task
33.8235,Event,ADDED,eval-sanitize-40-r4-027-x2p67.18d40a032c9d6be0,"reason=FailedScheduling count=None msg=0/6 nodes are available: 1 c_wall violated: 1 conflicting context pair(s) with node memory, 1 c_wall violated: 4 conflicting context pair(s) with node memory, 2 c_wall violated: 2 conflicting context pair(s) with node memory, 2 node(s) had untolerated taint(s). no new claims to deallocate, preemption: 0/6 nodes are available: 2 Preemption is not helpful for scheduling, 4 No preemption victims found for incoming pod."
33.9131,Event,ADDED,eval-sanitize-40-r4-008-sbdmc.18d40a03324d7a01,"reason=FailedScheduling count=None msg=0/6 nodes are available: 1 c_wall violated: 1 conflicting context pair(s) with node memory, 1 c_wall violated: 4 conflicting context pair(s) with node memory, 2 c_wall violated: 2 conflicting context pair(s) with node memory, 2 node(s) had untolerated taint(s). no new claims to deallocate, preemption: 0/6 nodes are available: 2 Preemption is not helpful for scheduling, 4 No preemption victims found for incoming pod."
34.0378,Pod,MODIFIED,eval-sanitize-40-r4-033-9d9p7,phase=Running node=kind-worker5
34.0382,Event,ADDED,eval-sanitize-40-r4-022-7m7tt.18d40a033810f685,"reason=FailedScheduling count=None msg=0/6 nodes are available: 1 c_wall violated: 1 conflicting context pair(s) with node memory, 1 c_wall violated: 4 conflicting context pair(s) with node memory, 2 c_wall violated: 2 conflicting context pair(s) with node memory, 2 node(s) had untolerated taint(s). no new claims to deallocate, preemption: 0/6 nodes are available: 2 Preemption is not helpful for scheduling, 4 No preemption victims found for incoming pod."
34.0383,TaskRequest,ADDED,eval-sanitize-40-r4-034,phase=None job=None
34.0395,Job,MODIFIED,eval-sanitize-40-r4-019,
34.0403,Job,MODIFIED,eval-sanitize-40-r4-021,
34.041,Job,MODIFIED,eval-sanitize-40-r4-020,
34.042,Job,MODIFIED,eval-sanitize-40-r4-019,
34.0437,Job,MODIFIED,eval-sanitize-40-r4-020,
34.0452,TaskRequest,MODIFIED,eval-sanitize-40-r4-034,phase=Pending job=None
34.0466,Pod,MODIFIED,eval-sanitize-40-r4-021-pxtwr,phase=Succeeded node=kind-worker5
34.0473,Job,MODIFIED,eval-sanitize-40-r4-033,
34.0475,Event,ADDED,eval-sanitize-40-r4-019.18d40a033a9f46f5,reason=Completed count=1 msg=Job completed
34.0498,Job,MODIFIED,eval-sanitize-40-r4-021,
34.051,Event,ADDED,eval-sanitize-40-r4-020.18d40a033ac019e2,reason=Completed count=1 msg=Job completed
34.0549,Event,ADDED,eval-sanitize-40-r4-021.18d40a033b1f5d20,reason=Completed count=1 msg=Job completed
34.0584,Job,ADDED,eval-sanitize-40-r4-034,
34.0644,Pod,ADDED,eval-sanitize-40-r4-034-qwc55,phase=Pending node=None
34.0654,TaskRequest,MODIFIED,eval-sanitize-40-r4-034,phase=Scheduled job=None
34.0681,Job,MODIFIED,eval-sanitize-40-r4-034,
34.0684,Event,ADDED,eval-sanitize-40-r4-034.18d40a033bfacf3d,reason=SuccessfulCreate count=1 msg=Created pod: eval-sanitize-40-r4-034-qwc55
34.0729,TaskRequest,MODIFIED,eval-sanitize-40-r4-034,phase=Scheduled job=None
34.0761,Job,MODIFIED,eval-sanitize-40-r4-019,
34.0779,Job,MODIFIED,eval-sanitize-40-r4-021,
34.0787,Job,MODIFIED,eval-sanitize-40-r4-020,
34.0812,TaskRequest,MODIFIED,eval-sanitize-40-r4-019,phase=Complete job=None
34.0862,TaskRequest,MODIFIED,eval-sanitize-40-r4-021,phase=Complete job=None
34.0895,TaskRequest,MODIFIED,eval-sanitize-40-r4-020,phase=Complete job=None
34.1016,Event,MODIFIED,eval-sanitize-40-r4-010-92scj.18d40a0325dec0a1,"reason=FailedScheduling count=None msg=0/6 nodes are available: 1 c_wall violated: 1 conflicting context pair(s) with node memory, 1 c_wall violated: 4 conflicting context pair(s) with node memory, 2 c_wall violated: 2 conflicting context pair(s) with node memory, 2 node(s) had untolerated taint(s). no new claims to deallocate, preemption: 0/6 nodes are available: 2 Preemption is not helpful for scheduling, 4 No preemption victims found for incoming pod."
34.1514,Job,MODIFIED,eval-sanitize-40-r4-033,
34.1539,Job,MODIFIED,eval-sanitize-40-r4-021,
34.1547,Job,MODIFIED,eval-sanitize-40-r4-019,
34.1555,Job,MODIFIED,eval-sanitize-40-r4-020,
34.2548,Pod,MODIFIED,eval-sanitize-40-r4-034-qwc55,phase=Pending node=kind-worker
34.2578,Event,ADDED,eval-sanitize-40-r4-034-qwc55.18d40a03475329b6,reason=Scheduled count=None msg=Successfully assigned compute/eval-sanitize-40-r4-034-qwc55 to kind-worker
34.2598,Event,MODIFIED,eval-sanitize-40-r4-026-8vj8k.18d40a0326b01fbd,"reason=FailedScheduling count=None msg=0/6 nodes are available: 1 c_wall violated: 1 conflicting context pair(s) with node memory, 1 c_wall violated: 4 conflicting context pair(s) with node memory, 2 c_wall violated: 2 conflicting context pair(s) with node memory, 2 node(s) had untolerated taint(s). no new claims to deallocate, preemption: 0/6 nodes are available: 2 Preemption is not helpful for scheduling, 4 No preemption victims found for incoming pod."
34.2653,Pod,MODIFIED,eval-sanitize-40-r4-034-qwc55,phase=Pending node=kind-worker
34.3239,Event,MODIFIED,eval-sanitize-40-r4-027-x2p67.18d40a032c9d6be0,"reason=FailedScheduling count=None msg=0/6 nodes are available: 1 c_wall violated: 1 conflicting context pair(s) with node memory, 1 c_wall violated: 4 conflicting context pair(s) with node memory, 2 c_wall violated: 2 conflicting context pair(s) with node memory, 2 node(s) had untolerated taint(s). no new claims to deallocate, preemption: 0/6 nodes are available: 2 Preemption is not helpful for scheduling, 4 No preemption victims found for incoming pod."
34.3807,Pod,MODIFIED,eval-sanitize-40-r4-023-tck4r,phase=Running node=kind-worker2
34.4842,Event,MODIFIED,eval-sanitize-40-r4-008-sbdmc.18d40a03324d7a01,"reason=FailedScheduling count=None msg=0/6 nodes are available: 1 c_wall violated: 1 conflicting context pair(s) with node memory, 1 c_wall violated: 4 conflicting context pair(s) with node memory, 2 c_wall violated: 2 conflicting context pair(s) with node memory, 2 node(s) had untolerated taint(s). no new claims to deallocate, preemption: 0/6 nodes are available: 2 Preemption is not helpful for scheduling, 4 No preemption victims found for incoming pod."
34.5036,Event,MODIFIED,eval-sanitize-40-r4-022-7m7tt.18d40a033810f685,"reason=FailedScheduling count=None msg=0/6 nodes are available: 1 c_wall violated: 1 conflicting context pair(s) with node memory, 1 c_wall violated: 4 conflicting context pair(s) with node memory, 2 c_wall violated: 2 conflicting context pair(s) with node memory, 2 node(s) had untolerated taint(s). no new claims to deallocate, preemption: 0/6 nodes are available: 2 Preemption is not helpful for scheduling, 4 No preemption victims found for incoming pod."
34.8282,Event,ADDED,eval-sanitize-40-r4-034-qwc55.18d40a03693cd600,"reason=Pulled count=1 msg=Container image ""busybox:musl"" already present on machine"
34.8455,Event,ADDED,eval-sanitize-40-r4-034-qwc55.18d40a036a50a8b6,reason=Created count=1 msg=Created container: task
34.9627,Event,ADDED,eval-sanitize-40-r4-034-qwc55.18d40a03714d4135,reason=Started count=1 msg=Started container task
34.9857,Pod,MODIFIED,eval-sanitize-40-r4-034-qwc55,phase=Running node=kind-worker
35.0433,TaskRequest,ADDED,eval-sanitize-40-r4-035,phase=None job=None
35.0471,TaskRequest,MODIFIED,eval-sanitize-40-r4-035,phase=Pending job=None
35.0631,Job,ADDED,eval-sanitize-40-r4-035,
35.0688,Job,MODIFIED,eval-sanitize-40-r4-034,
35.0716,Pod,ADDED,eval-sanitize-40-r4-035-8pwgh,phase=Pending node=None
35.0718,TaskRequest,MODIFIED,eval-sanitize-40-r4-035,phase=Scheduled job=None
35.0726,Job,MODIFIED,eval-sanitize-40-r4-035,
35.0748,Event,ADDED,eval-sanitize-40-r4-035.18d40a0377f9bf77,reason=SuccessfulCreate count=1 msg=Created pod: eval-sanitize-40-r4-035-8pwgh
35.0775,TaskRequest,MODIFIED,eval-sanitize-40-r4-035,phase=Scheduled job=None
35.0806,Job,MODIFIED,eval-sanitize-40-r4-034,
35.2165,Pod,MODIFIED,eval-sanitize-40-r4-035-8pwgh,phase=Pending node=kind-worker
35.2203,Event,ADDED,eval-sanitize-40-r4-035-8pwgh.18d40a0380a1257d,reason=Scheduled count=None msg=Successfully assigned compute/eval-sanitize-40-r4-035-8pwgh to kind-worker
35.2266,Pod,MODIFIED,eval-sanitize-40-r4-035-8pwgh,phase=Pending node=kind-worker
35.3854,Job,MODIFIED,eval-sanitize-40-r4-023,
35.3947,Job,MODIFIED,eval-sanitize-40-r4-023,
35.4841,Pod,MODIFIED,eval-sanitize-40-r4-023-tck4r,phase=Succeeded node=kind-worker2
35.7626,Event,ADDED,eval-sanitize-40-r4-035-8pwgh.18d40a03a0ed35b2,"reason=Pulled count=1 msg=Container image ""busybox:musl"" already present on machine"
35.781,Event,ADDED,eval-sanitize-40-r4-035-8pwgh.18d40a03a20f3cb9,reason=Created count=1 msg=Created container: task
35.8891,Event,ADDED,eval-sanitize-40-r4-035-8pwgh.18d40a03a86e3efa,reason=Started count=1 msg=Started container task
35.9946,Pod,MODIFIED,eval-sanitize-40-r4-035-8pwgh,phase=Running node=kind-worker
36.0008,Pod,MODIFIED,eval-sanitize-40-r4-025-d52pp,phase=Running node=kind-worker
36.0077,Pod,MODIFIED,eval-sanitize-40-r4-024-qs8vx,phase=Running node=kind-worker
36.0083,TaskRequest,ADDED,eval-sanitize-40-r4-036,phase=None job=None
36.0119,TaskRequest,MODIFIED,eval-sanitize-40-r4-036,phase=Pending job=None
36.0261,Job,ADDED,eval-sanitize-40-r4-036,
36.0311,Pod,ADDED,eval-sanitize-40-r4-036-btf8v,phase=Pending node=None
36.0326,TaskRequest,MODIFIED,eval-sanitize-40-r4-036,phase=Scheduled job=None
36.0344,Job,MODIFIED,eval-sanitize-40-r4-036,
36.037,Event,ADDED,eval-sanitize-40-r4-036.18d40a03b1395104,reason=SuccessfulCreate count=1 msg=Created pod: eval-sanitize-40-r4-036-btf8v
36.039,TaskRequest,MODIFIED,eval-sanitize-40-r4-036,phase=Scheduled job=None
36.0424,Job,MODIFIED,eval-sanitize-40-r4-036,
36.0505,Job,MODIFIED,eval-sanitize-40-r4-036,
36.1341,Job,MODIFIED,eval-sanitize-40-r4-035,
36.1362,Pod,MODIFIED,eval-sanitize-40-r4-036-btf8v,phase=Pending node=kind-worker5
36.1398,Event,ADDED,eval-sanitize-40-r4-036-btf8v.18d40a03b77d6bc1,reason=Scheduled count=None msg=Successfully assigned compute/eval-sanitize-40-r4-036-btf8v to kind-worker5
36.1441,Job,MODIFIED,eval-sanitize-40-r4-035,
36.1469,Pod,MODIFIED,eval-sanitize-40-r4-036-btf8v,phase=Pending node=kind-worker5
36.4119,Job,MODIFIED,eval-sanitize-40-r4-023,
36.4205,Pod,MODIFIED,eval-sanitize-40-r4-023-tck4r,phase=Succeeded node=kind-worker2
36.4214,Job,MODIFIED,eval-sanitize-40-r4-023,
36.5905,Event,ADDED,eval-sanitize-40-r4-036-btf8v.18d40a03d2499dc2,"reason=Pulled count=1 msg=Container image ""busybox:musl"" already present on machine"
36.6082,Event,ADDED,eval-sanitize-40-r4-036-btf8v.18d40a03d36a268b,reason=Created count=1 msg=Created container: task
36.7023,Event,ADDED,eval-sanitize-40-r4-036-btf8v.18d40a03d8e8ee30,reason=Started count=1 msg=Started container task
36.973,Pod,MODIFIED,eval-sanitize-40-r4-036-btf8v,phase=Running node=kind-worker5
37.0249,Job,MODIFIED,eval-sanitize-40-r4-025,
37.0271,TaskRequest,ADDED,eval-sanitize-40-r4-037,phase=None job=None
37.0278,Job,MODIFIED,eval-sanitize-40-r4-024,
37.0354,Job,MODIFIED,eval-sanitize-40-r4-025,
37.0366,TaskRequest,MODIFIED,eval-sanitize-40-r4-037,phase=Pending job=None
37.0375,Job,MODIFIED,eval-sanitize-40-r4-036,
37.0401,Job,MODIFIED,eval-sanitize-40-r4-024,
37.054,Job,ADDED,eval-sanitize-40-r4-037,
37.0599,TaskRequest,MODIFIED,eval-sanitize-40-r4-037,phase=Scheduled job=None
37.0608,Pod,ADDED,eval-sanitize-40-r4-037-dhckp,phase=Pending node=None
37.0622,Job,MODIFIED,eval-sanitize-40-r4-037,
37.0647,Event,ADDED,eval-sanitize-40-r4-037.18d40a03ee93181c,reason=SuccessfulCreate count=1 msg=Created pod: eval-sanitize-40-r4-037-dhckp
37.068,TaskRequest,MODIFIED,eval-sanitize-40-r4-037,phase=Scheduled job=None
37.0707,Job,MODIFIED,eval-sanitize-40-r4-036,
37.0899,Pod,MODIFIED,eval-sanitize-40-r4-025-d52pp,phase=Succeeded node=kind-worker
37.1582,Pod,MODIFIED,eval-sanitize-40-r4-024-qs8vx,phase=Succeeded node=kind-worker
37.1734,Pod,MODIFIED,eval-sanitize-40-r4-037-dhckp,phase=Pending node=kind-worker2
37.1769,Event,ADDED,eval-sanitize-40-r4-037-dhckp.18d40a03f54ebef8,reason=Scheduled count=None msg=Successfully assigned compute/eval-sanitize-40-r4-037-dhckp to kind-worker2
37.1826,Pod,MODIFIED,eval-sanitize-40-r4-037-dhckp,phase=Pending node=kind-worker2
37.4183,Job,MODIFIED,eval-sanitize-40-r4-023,
37.4221,Job,MODIFIED,eval-sanitize-40-r4-023,
37.4279,Event,ADDED,eval-sanitize-40-r4-023.18d40a04042480c5,reason=Completed count=1 msg=Job completed
37.4321,Job,MODIFIED,eval-sanitize-40-r4-023,
37.4357,TaskRequest,MODIFIED,eval-sanitize-40-r4-023,phase=Complete job=None
37.4447,Job,MODIFIED,eval-sanitize-40-r4-023,
37.5925,Event,ADDED,eval-sanitize-40-r4-037-dhckp.18d40a040e052c71,"reason=Pulled count=1 msg=Container image ""busybox:musl"" already present on machine"
37.6115,Event,ADDED,eval-sanitize-40-r4-037-dhckp.18d40a040f208d7c,reason=Created count=1 msg=Created container: task
37.678,Event,ADDED,eval-sanitize-40-r4-037-dhckp.18d40a0413130da2,reason=Started count=1 msg=Started container task
38.0219,TaskRequest,ADDED,eval-sanitize-40-r4-038,phase=None job=None
38.0256,TaskRequest,MODIFIED,eval-sanitize-40-r4-038,phase=Pending job=None
38.0298,Job,MODIFIED,eval-sanitize-40-r4-025,
38.0332,Job,MODIFIED,eval-sanitize-40-r4-024,
38.038,Pod,MODIFIED,eval-sanitize-40-r4-025-d52pp,phase=Succeeded node=kind-worker
38.0415,Pod,MODIFIED,eval-sanitize-40-r4-024-qs8vx,phase=Succeeded node=kind-worker
38.0431,Job,MODIFIED,eval-sanitize-40-r4-025,
38.0446,Job,ADDED,eval-sanitize-40-r4-038,
38.0479,Job,MODIFIED,eval-sanitize-40-r4-024,
38.0482,Event,ADDED,eval-sanitize-40-r4-025.18d40a042925db20,reason=Completed count=1 msg=Job completed
38.0514,Pod,ADDED,eval-sanitize-40-r4-038-k6lc5,phase=Pending node=None
38.0515,TaskRequest,MODIFIED,eval-sanitize-40-r4-038,phase=Scheduled job=None
38.053,Event,ADDED,eval-sanitize-40-r4-024.18d40a04296d61d9,reason=Completed count=1 msg=Job completed
38.0562,Job,MODIFIED,eval-sanitize-40-r4-038,
38.057,Event,ADDED,eval-sanitize-40-r4-038.18d40a042998ee35,reason=SuccessfulCreate count=1 msg=Created pod: eval-sanitize-40-r4-038-k6lc5
38.0588,TaskRequest,MODIFIED,eval-sanitize-40-r4-038,phase=Scheduled job=None
38.0614,Job,MODIFIED,eval-sanitize-40-r4-025,
38.0634,Job,MODIFIED,eval-sanitize-40-r4-024,
38.0656,Job,MODIFIED,eval-sanitize-40-r4-037,
38.0658,TaskRequest,MODIFIED,eval-sanitize-40-r4-025,phase=Complete job=None
38.0757,TaskRequest,MODIFIED,eval-sanitize-40-r4-024,phase=Complete job=None
38.0839,Job,MODIFIED,eval-sanitize-40-r4-025,
38.0859,Job,MODIFIED,eval-sanitize-40-r4-024,
38.0865,Job,MODIFIED,eval-sanitize-40-r4-037,
38.0966,Pod,MODIFIED,eval-sanitize-40-r4-038-k6lc5,phase=Pending node=kind-worker4
38.1001,Event,ADDED,eval-sanitize-40-r4-038-k6lc5.18d40a042c51d9b6,reason=Scheduled count=None msg=Successfully assigned compute/eval-sanitize-40-r4-038-k6lc5 to kind-worker4
38.1061,Pod,MODIFIED,eval-sanitize-40-r4-038-k6lc5,phase=Pending node=kind-worker4
38.1086,Node,MODIFIED,kind-worker4,taints=0
38.1179,Node,MODIFIED,kind-worker4,taints=0
38.3635,Node,MODIFIED,kind-worker,taints=1
38.3763,Node,MODIFIED,kind-worker,taints=1
38.388,Pod,MODIFIED,eval-sanitize-40-r4-037-dhckp,phase=Running node=kind-worker2
38.5017,Pod,MODIFIED,eval-sanitize-40-r4-022-7m7tt,phase=Pending node=None
38.508,Event,ADDED,eval-sanitize-40-r4-038-k6lc5.18d40a044498dbbc,"reason=Pulled count=1 msg=Container image ""busybox:musl"" already present on machine"
38.5262,Event,ADDED,eval-sanitize-40-r4-038-k6lc5.18d40a0445b7c588,reason=Created count=1 msg=Created container: task
38.5572,Event,ADDED,eval-sanitize-40-r4-038-k6lc5.18d40a04478f29e9,reason=Started count=1 msg=Started container task
38.5687,Pod,MODIFIED,eval-sanitize-40-r4-010-92scj,phase=Pending node=None
38.578,Node,MODIFIED,kind-worker2,taints=1
38.5896,Node,MODIFIED,kind-worker2,taints=1
38.6058,Pod,MODIFIED,eval-sanitize-40-r4-026-8vj8k,phase=Pending node=None
38.6875,Pod,MODIFIED,eval-sanitize-40-r4-027-x2p67,phase=Pending node=None
38.6982,Pod,MODIFIED,eval-sanitize-40-r4-008-sbdmc,phase=Pending node=None
38.7083,Pod,MODIFIED,eval-sanitize-40-r4-022-7m7tt,phase=Pending node=None
38.7086,Event,ADDED,eval-sanitize-40-r4-022-7m7tt.18d40a045080d381,"reason=FailedScheduling count=None msg=0/6 nodes are available: 1 c_wall violated: 2 conflicting context pair(s) with node memory, 1 c_wall violated: 4 conflicting context pair(s) with node memory, 4 node(s) had untolerated taint(s). no new claims to deallocate, preemption: 0/6 nodes are available: 2 No preemption victims found for incoming pod, 4 Preemption is not helpful for scheduling."
38.8323,Event,ADDED,eval-sanitize-40-r4-010-92scj.18d40a0453f23a00,"reason=FailedScheduling count=None msg=0/6 nodes are available: 1 c_wall violated: 2 conflicting context pair(s) with node memory, 1 c_wall violated: 4 conflicting context pair(s) with node memory, 4 node(s) had untolerated taint(s). no new claims to deallocate, preemption: 0/6 nodes are available: 2 No preemption victims found for incoming pod, 4 Preemption is not helpful for scheduling."
38.8339,Pod,MODIFIED,eval-sanitize-40-r4-028-nxm9c,phase=Running node=kind-worker4
38.8347,Pod,MODIFIED,eval-sanitize-40-r4-010-92scj,phase=Pending node=None
38.8414,Pod,MODIFIED,eval-sanitize-40-r4-038-k6lc5,phase=Running node=kind-worker4
38.8429,Pod,MODIFIED,eval-sanitize-40-r4-026-8vj8k,phase=Pending node=None
38.8438,Event,ADDED,eval-sanitize-40-r4-026-8vj8k.18d40a045889aaa6,"reason=FailedScheduling count=None msg=0/6 nodes are available: 1 c_wall violated: 2 conflicting context pair(s) with node memory, 1 c_wall violated: 4 conflicting context pair(s) with node memory, 4 node(s) had untolerated taint(s). no new claims to deallocate, preemption: 0/6 nodes are available: 2 No preemption victims found for incoming pod, 4 Preemption is not helpful for scheduling."
38.8519,Event,ADDED,eval-sanitize-40-r4-027-x2p67.18d40a04591f59db,"reason=FailedScheduling count=None msg=0/6 nodes are available: 1 c_wall violated: 2 conflicting context pair(s) with node memory, 1 c_wall violated: 4 conflicting context pair(s) with node memory, 4 node(s) had untolerated taint(s). no new claims to deallocate, preemption: 0/6 nodes are available: 2 No preemption victims found for incoming pod, 4 Preemption is not helpful for scheduling."
38.8632,Event,ADDED,eval-sanitize-40-r4-008-sbdmc.18d40a0459d63f1b,"reason=FailedScheduling count=None msg=0/6 nodes are available: 1 c_wall violated: 2 conflicting context pair(s) with node memory, 1 c_wall violated: 4 conflicting context pair(s) with node memory, 4 node(s) had untolerated taint(s). no new claims to deallocate, preemption: 0/6 nodes are available: 2 No preemption victims found for incoming pod, 4 Preemption is not helpful for scheduling."
38.9554,Event,ADDED,eval-sanitize-40-r4-022-7m7tt.18d40a045bcd2b61,"reason=FailedScheduling count=None msg=0/6 nodes are available: 1 c_wall violated: 2 conflicting context pair(s) with node memory, 1 c_wall violated: 4 conflicting context pair(s) with node memory, 4 node(s) had untolerated taint(s). no new claims to deallocate, preemption: 0/6 nodes are available: 2 No preemption victims found for incoming pod, 4 Preemption is not helpful for scheduling."
38.9557,Event,ADDED,eval-sanitize-40-r4-010-92scj.18d40a045c202639,"reason=FailedScheduling count=None msg=0/6 nodes are available: 1 c_wall violated: 2 conflicting context pair(s) with node memory, 1 c_wall violated: 4 conflicting context pair(s) with node memory, 4 node(s) had untolerated taint(s). no new claims to deallocate, preemption: 0/6 nodes are available: 2 No preemption victims found for incoming pod, 4 Preemption is not helpful for scheduling."
38.9559,Event,ADDED,eval-sanitize-40-r4-026-8vj8k.18d40a045c6e77ed,"reason=FailedScheduling count=None msg=0/6 nodes are available: 1 c_wall violated: 2 conflicting context pair(s) with node memory, 1 c_wall violated: 4 conflicting context pair(s) with node memory, 4 node(s) had untolerated taint(s). no new claims to deallocate, preemption: 0/6 nodes are available: 2 No preemption victims found for incoming pod, 4 Preemption is not helpful for scheduling."
39.0094,Node,MODIFIED,kind-worker4,taints=1
39.0098,TaskRequest,ADDED,eval-sanitize-40-r4-039,phase=None job=None
39.0133,TaskRequest,MODIFIED,eval-sanitize-40-r4-039,phase=Pending job=None
39.0258,Pod,MODIFIED,eval-sanitize-40-r4-027-x2p67,phase=Pending node=None
39.0272,Event,MODIFIED,eval-sanitize-40-r4-027-x2p67.18d40a04591f59db,"reason=FailedScheduling count=None msg=0/6 nodes are available: 1 c_wall violated: 2 conflicting context pair(s) with node memory, 1 c_wall violated: 4 conflicting context pair(s) with node memory, 4 node(s) had untolerated taint(s). no new claims to deallocate, preemption: 0/6 nodes are available: 2 No preemption victims found for incoming pod, 4 Preemption is not helpful for scheduling."
39.0292,Node,MODIFIED,kind-worker4,taints=1
39.0298,Job,ADDED,eval-sanitize-40-r4-039,
39.0363,Pod,ADDED,eval-sanitize-40-r4-039-x7df5,phase=Pending node=None
39.0468,Pod,MODIFIED,eval-sanitize-40-r4-008-sbdmc,phase=Pending node=None
39.0478,TaskRequest,MODIFIED,eval-sanitize-40-r4-039,phase=Scheduled job=None
39.0484,Event,MODIFIED,eval-sanitize-40-r4-008-sbdmc.18d40a0459d63f1b,"reason=FailedScheduling count=None msg=0/6 nodes are available: 1 c_wall violated: 2 conflicting context pair(s) with node memory, 1 c_wall violated: 4 conflicting context pair(s) with node memory, 4 node(s) had untolerated taint(s). no new claims to deallocate, preemption: 0/6 nodes are available: 2 No preemption victims found for incoming pod, 4 Preemption is not helpful for scheduling."
39.0486,Event,ADDED,eval-sanitize-40-r4-039.18d40a046452221c,reason=SuccessfulCreate count=1 msg=Created pod: eval-sanitize-40-r4-039-x7df5
39.0494,Job,MODIFIED,eval-sanitize-40-r4-039,
39.0558,Pod,MODIFIED,eval-sanitize-40-r4-039-x7df5,phase=Pending node=None
39.0585,Event,ADDED,eval-sanitize-40-r4-039-x7df5.18d40a046539ef99,"reason=FailedScheduling count=None msg=0/6 nodes are available: 1 c_wall violated: 2 conflicting context pair(s) with node memory, 5 node(s) had untolerated taint(s). no new claims to deallocate, preemption: 0/6 nodes are available: 1 No preemption victims found for incoming pod, 5 Preemption is not helpful for scheduling."
39.0594,Job,MODIFIED,eval-sanitize-40-r4-038,
39.0596,TaskRequest,MODIFIED,eval-sanitize-40-r4-039,phase=Scheduled job=None
39.0647,Pod,MODIFIED,eval-sanitize-40-r4-022-7m7tt,phase=Pending node=None
39.0657,Event,MODIFIED,eval-sanitize-40-r4-022-7m7tt.18d40a045bcd2b61,"reason=FailedScheduling count=None msg=0/6 nodes are available: 1 c_wall violated: 2 conflicting context pair(s) with node memory, 1 c_wall violated: 4 conflicting context pair(s) with node memory, 4 node(s) had untolerated taint(s). no new claims to deallocate, preemption: 0/6 nodes are available: 2 No preemption victims found for incoming pod, 4 Preemption is not helpful for scheduling."
39.0687,Job,MODIFIED,eval-sanitize-40-r4-038,
39.0707,Job,MODIFIED,eval-sanitize-40-r4-037,
39.073,Pod,MODIFIED,eval-sanitize-40-r4-010-92scj,phase=Pending node=None
39.0755,Event,MODIFIED,eval-sanitize-40-r4-010-92scj.18d40a045c202639,"reason=FailedScheduling count=None msg=0/6 nodes are available: 1 c_wall violated: 2 conflicting context pair(s) with node memory, 1 c_wall violated: 4 conflicting context pair(s) with node memory, 4 node(s) had untolerated taint(s). no new claims to deallocate, preemption: 0/6 nodes are available: 2 No preemption victims found for incoming pod, 4 Preemption is not helpful for scheduling."
39.0798,Job,MODIFIED,eval-sanitize-40-r4-037,
39.0824,Pod,MODIFIED,eval-sanitize-40-r4-026-8vj8k,phase=Pending node=None
39.0829,Event,MODIFIED,eval-sanitize-40-r4-026-8vj8k.18d40a045c6e77ed,"reason=FailedScheduling count=None msg=0/6 nodes are available: 1 c_wall violated: 2 conflicting context pair(s) with node memory, 1 c_wall violated: 4 conflicting context pair(s) with node memory, 4 node(s) had untolerated taint(s). no new claims to deallocate, preemption: 0/6 nodes are available: 2 No preemption victims found for incoming pod, 4 Preemption is not helpful for scheduling."
39.0987,Event,ADDED,eval-sanitize-40-r4-027-x2p67.18d40a0467c0bbbd,"reason=FailedScheduling count=None msg=0/6 nodes are available: 1 c_wall violated: 4 conflicting context pair(s) with node memory, 5 node(s) had untolerated taint(s). no new claims to deallocate, preemption: 0/6 nodes are available: 1 No preemption victims found for incoming pod, 5 Preemption is not helpful for scheduling."
39.0999,Event,ADDED,eval-sanitize-40-r4-008-sbdmc.18d40a0467ea1d43,"reason=FailedScheduling count=None msg=0/6 nodes are available: 1 c_wall violated: 4 conflicting context pair(s) with node memory, 5 node(s) had untolerated taint(s). no new claims to deallocate, preemption: 0/6 nodes are available: 1 No preemption victims found for incoming pod, 5 Preemption is not helpful for scheduling."
39.1026,Event,ADDED,eval-sanitize-40-r4-039-x7df5.18d40a046816a06e,"reason=FailedScheduling count=None msg=0/6 nodes are available: 1 c_wall violated: 2 conflicting context pair(s) with node memory, 5 node(s) had untolerated taint(s). no new claims to deallocate, preemption: 0/6 nodes are available: 1 No preemption victims found for incoming pod, 5 Preemption is not helpful for scheduling."
39.1055,Event,ADDED,eval-sanitize-40-r4-022-7m7tt.18d40a04684786e3,"reason=FailedScheduling count=None msg=0/6 nodes are available: 1 c_wall violated: 4 conflicting context pair(s) with node memory, 5 node(s) had untolerated taint(s). no new claims to deallocate, preemption: 0/6 nodes are available: 1 No preemption victims found for incoming pod, 5 Preemption is not helpful for scheduling."
39.1089,Event,ADDED,eval-sanitize-40-r4-010-92scj.18d40a04686e42c4,"reason=FailedScheduling count=None msg=0/6 nodes are available: 1 c_wall violated: 4 conflicting context pair(s) with node memory, 5 node(s) had untolerated taint(s). no new claims to deallocate, preemption: 0/6 nodes are available: 1 No preemption victims found for incoming pod, 5 Preemption is not helpful for scheduling."
39.2206,Event,ADDED,eval-sanitize-40-r4-026-8vj8k.18d40a046bcb2484,"reason=FailedScheduling count=None msg=0/6 nodes are available: 1 c_wall violated: 4 conflicting context pair(s) with node memory, 5 node(s) had untolerated taint(s). no new claims to deallocate, preemption: 0/6 nodes are available: 1 No preemption victims found for incoming pod, 5 Preemption is not helpful for scheduling."
39.8483,Job,MODIFIED,eval-sanitize-40-r4-028,
39.8579,Job,MODIFIED,eval-sanitize-40-r4-028,
39.8618,Node,MODIFIED,kind-worker5,taints=1
39.8676,Pod,MODIFIED,eval-sanitize-40-r4-027-x2p67,phase=Pending node=None
39.868,Event,MODIFIED,eval-sanitize-40-r4-027-x2p67.18d40a0467c0bbbd,"reason=FailedScheduling count=None msg=0/6 nodes are available: 1 c_wall violated: 4 conflicting context pair(s) with node memory, 5 node(s) had untolerated taint(s). no new claims to deallocate, preemption: 0/6 nodes are available: 1 No preemption victims found for incoming pod, 5 Preemption is not helpful for scheduling."
39.8727,Pod,MODIFIED,eval-sanitize-40-r4-008-sbdmc,phase=Pending node=None
39.8744,Event,MODIFIED,eval-sanitize-40-r4-008-sbdmc.18d40a0467ea1d43,"reason=FailedScheduling count=None msg=0/6 nodes are available: 1 c_wall violated: 4 conflicting context pair(s) with node memory, 5 node(s) had untolerated taint(s). no new claims to deallocate, preemption: 0/6 nodes are available: 1 No preemption victims found for incoming pod, 5 Preemption is not helpful for scheduling."
39.8759,Node,MODIFIED,kind-worker5,taints=1
39.8776,Pod,MODIFIED,eval-sanitize-40-r4-039-x7df5,phase=Pending node=None
39.878,Event,MODIFIED,eval-sanitize-40-r4-039-x7df5.18d40a046816a06e,"reason=FailedScheduling count=None msg=0/6 nodes are available: 1 c_wall violated: 2 conflicting context pair(s) with node memory, 5 node(s) had untolerated taint(s). no new claims to deallocate, preemption: 0/6 nodes are available: 1 No preemption victims found for incoming pod, 5 Preemption is not helpful for scheduling."
39.8825,Pod,MODIFIED,eval-sanitize-40-r4-022-7m7tt,phase=Pending node=None
39.8835,Event,MODIFIED,eval-sanitize-40-r4-022-7m7tt.18d40a04684786e3,"reason=FailedScheduling count=None msg=0/6 nodes are available: 1 c_wall violated: 4 conflicting context pair(s) with node memory, 5 node(s) had untolerated taint(s). no new claims to deallocate, preemption: 0/6 nodes are available: 1 No preemption victims found for incoming pod, 5 Preemption is not helpful for scheduling."
39.8862,Pod,MODIFIED,eval-sanitize-40-r4-010-92scj,phase=Pending node=None
39.8877,Event,MODIFIED,eval-sanitize-40-r4-010-92scj.18d40a04686e42c4,"reason=FailedScheduling count=None msg=0/6 nodes are available: 1 c_wall violated: 4 conflicting context pair(s) with node memory, 5 node(s) had untolerated taint(s). no new claims to deallocate, preemption: 0/6 nodes are available: 1 No preemption victims found for incoming pod, 5 Preemption is not helpful for scheduling."
39.8912,Pod,MODIFIED,eval-sanitize-40-r4-026-8vj8k,phase=Pending node=None
39.8917,Event,MODIFIED,eval-sanitize-40-r4-026-8vj8k.18d40a046bcb2484,"reason=FailedScheduling count=None msg=0/6 nodes are available: 1 c_wall violated: 4 conflicting context pair(s) with node memory, 5 node(s) had untolerated taint(s). no new claims to deallocate, preemption: 0/6 nodes are available: 1 No preemption victims found for incoming pod, 5 Preemption is not helpful for scheduling."
39.9171,Pod,MODIFIED,eval-sanitize-40-r4-028-nxm9c,phase=Succeeded node=kind-worker4
40.0311,Pod,MODIFIED,eval-sanitize-40-r4-029-gbx8m,phase=Running node=kind-worker
40.0331,TaskRequest,ADDED,eval-sanitize-40-r4-040,phase=None job=None
40.037,TaskRequest,MODIFIED,eval-sanitize-40-r4-040,phase=Pending job=None
40.0404,Job,MODIFIED,eval-sanitize-40-r4-039,
40.0527,Job,ADDED,eval-sanitize-40-r4-040,
40.0588,Pod,ADDED,eval-sanitize-40-r4-040-d5rbc,phase=Pending node=None
40.0606,Job,MODIFIED,eval-sanitize-40-r4-040,
40.0607,TaskRequest,MODIFIED,eval-sanitize-40-r4-040,phase=Scheduled job=None
40.0644,Event,ADDED,eval-sanitize-40-r4-040.18d40a04a14ea5e2,reason=SuccessfulCreate count=1 msg=Created pod: eval-sanitize-40-r4-040-d5rbc
40.0646,Event,ADDED,eval-sanitize-40-r4-040-d5rbc.18d40a04a15f3223,"reason=FailedScheduling count=None msg=0/6 nodes are available: 6 node(s) had untolerated taint(s). no new claims to deallocate, preemption: 0/6 nodes are available: 6 Preemption is not helpful for scheduling."
40.0655,Pod,MODIFIED,eval-sanitize-40-r4-040-d5rbc,phase=Pending node=None
40.0672,TaskRequest,MODIFIED,eval-sanitize-40-r4-040,phase=Scheduled job=None
40.0701,Job,MODIFIED,eval-sanitize-40-r4-039,
40.2946,Node,MODIFIED,kind-worker3,taints=1
40.3876,Node,MODIFIED,kind-worker3,taints=1
40.3945,Node,MODIFIED,kind-worker3,taints=0
40.4005,Pod,MODIFIED,eval-sanitize-40-r4-027-x2p67,phase=Pending node=kind-worker3
40.4043,Pod,MODIFIED,eval-sanitize-40-r4-008-sbdmc,phase=Pending node=kind-worker3
40.4046,Event,ADDED,eval-sanitize-40-r4-027-x2p67.18d40a04b5a6af99,reason=Scheduled count=None msg=Successfully assigned compute/eval-sanitize-40-r4-027-x2p67 to kind-worker3
40.4082,Pod,MODIFIED,eval-sanitize-40-r4-039-x7df5,phase=Pending node=kind-worker3
40.4094,Node,MODIFIED,kind-worker3,taints=0
40.4117,Event,ADDED,eval-sanitize-40-r4-008-sbdmc.18d40a04b5d93f6d,reason=Scheduled count=None msg=Successfully assigned compute/eval-sanitize-40-r4-008-sbdmc to kind-worker3
40.4129,Pod,MODIFIED,eval-sanitize-40-r4-022-7m7tt,phase=Pending node=kind-worker3
40.4154,Event,ADDED,eval-sanitize-40-r4-039-x7df5.18d40a04b61662d0,reason=Scheduled count=None msg=Successfully assigned compute/eval-sanitize-40-r4-039-x7df5 to kind-worker3
40.4165,Pod,MODIFIED,eval-sanitize-40-r4-010-92scj,phase=Pending node=kind-worker3
40.4205,Pod,MODIFIED,eval-sanitize-40-r4-026-8vj8k,phase=Pending node=kind-worker3
40.4243,Pod,MODIFIED,eval-sanitize-40-r4-027-x2p67,phase=Pending node=kind-worker3
40.429,Event,ADDED,eval-sanitize-40-r4-022-7m7tt.18d40a04b6628840,reason=Scheduled count=None msg=Successfully assigned compute/eval-sanitize-40-r4-022-7m7tt to kind-worker3
40.4294,Event,ADDED,eval-sanitize-40-r4-040-d5rbc.18d40a04b67d21f3,"reason=FailedScheduling count=None msg=0/6 nodes are available: 1 c_wall violated: 1 conflicting context pair(s) with node memory, 5 node(s) had untolerated taint(s). no new claims to deallocate, preemption: 0/6 nodes are available: 1 No preemption victims found for incoming pod, 5 Preemption is not helpful for scheduling."
40.43,Event,ADDED,eval-sanitize-40-r4-010-92scj.18d40a04b6930dd6,reason=Scheduled count=None msg=Successfully assigned compute/eval-sanitize-40-r4-010-92scj to kind-worker3
40.4314,Pod,MODIFIED,eval-sanitize-40-r4-040-d5rbc,phase=Pending node=None
40.4378,Event,ADDED,eval-sanitize-40-r4-026-8vj8k.18d40a04b6d32528,reason=Scheduled count=None msg=Successfully assigned compute/eval-sanitize-40-r4-026-8vj8k to kind-worker3
40.4401,Node,MODIFIED,kind-worker3,taints=0
40.4446,Pod,MODIFIED,eval-sanitize-40-r4-022-7m7tt,phase=Pending node=kind-worker3
40.45,Node,MODIFIED,kind-worker3,taints=0
40.4517,Pod,MODIFIED,eval-sanitize-40-r4-039-x7df5,phase=Pending node=kind-worker3
40.457,Pod,MODIFIED,eval-sanitize-40-r4-008-sbdmc,phase=Pending node=kind-worker3
40.4628,Pod,MODIFIED,eval-sanitize-40-r4-026-8vj8k,phase=Pending node=kind-worker3
40.4683,Pod,MODIFIED,eval-sanitize-40-r4-010-92scj,phase=Pending node=kind-worker3
40.561,Event,ADDED,eval-sanitize-40-r4-040-d5rbc.18d40a04beeeb04a,"reason=FailedScheduling count=None msg=0/6 nodes are available: 1 c_wall violated: 1 conflicting context pair(s) with node memory, 5 node(s) had untolerated taint(s). no new claims to deallocate, preemption: 0/6 nodes are available: 1 No preemption victims found for incoming pod, 5 Preemption is not helpful for scheduling."
40.6384,Node,MODIFIED,kind-worker3,taints=0
40.6482,Node,MODIFIED,kind-worker3,taints=0
40.855,Job,MODIFIED,eval-sanitize-40-r4-028,
40.8647,Pod,MODIFIED,eval-sanitize-40-r4-028-nxm9c,phase=Succeeded node=kind-worker4
40.8668,Job,MODIFIED,eval-sanitize-40-r4-028,
41.0424,TaskRequest,ADDED,eval-sanitize-40-r4-041,phase=None job=None
41.0437,Job,MODIFIED,eval-sanitize-40-r4-029,
41.0489,Pod,MODIFIED,eval-sanitize-40-r4-030-kgdr2,phase=Running node=kind-worker5
41.0524,Event,ADDED,eval-sanitize-40-r4-027-x2p67.18d40a04dbe05105,"reason=Pulled count=1 msg=Container image ""busybox:musl"" already present on machine"
41.0525,TaskRequest,MODIFIED,eval-sanitize-40-r4-041,phase=Pending job=None
41.057,Event,ADDED,eval-sanitize-40-r4-008-sbdmc.18d40a04dc0656ec,"reason=Pulled count=1 msg=Container image ""busybox:musl"" already present on machine"
41.0621,Event,ADDED,eval-sanitize-40-r4-039-x7df5.18d40a04dc309c1e,"reason=Pulled count=1 msg=Container image ""busybox:musl"" already present on machine"
41.0662,Job,MODIFIED,eval-sanitize-40-r4-040,
41.0671,Event,ADDED,eval-sanitize-40-r4-026-8vj8k.18d40a04dc567ade,"reason=Pulled count=1 msg=Container image ""busybox:musl"" already present on machine"
41.072,Job,ADDED,eval-sanitize-40-r4-041,
41.0725,Event,ADDED,eval-sanitize-40-r4-010-92scj.18d40a04dc75c8c9,"reason=Pulled count=1 msg=Container image ""busybox:musl"" already present on machine"
41.0794,Pod,ADDED,eval-sanitize-40-r4-041-lgn9n,phase=Pending node=None
41.089,Event,ADDED,eval-sanitize-40-r4-022-7m7tt.18d40a04dc996276,"reason=Pulled count=1 msg=Container image ""busybox:musl"" already present on machine"
41.0891,TaskRequest,MODIFIED,eval-sanitize-40-r4-041,phase=Scheduled job=None
41.0899,Job,MODIFIED,eval-sanitize-40-r4-041,
41.0939,Event,ADDED,eval-sanitize-40-r4-041.18d40a04de211539,reason=SuccessfulCreate count=1 msg=Created pod: eval-sanitize-40-r4-041-lgn9n
41.0942,Event,ADDED,eval-sanitize-40-r4-041-lgn9n.18d40a04de678a8c,"reason=FailedScheduling count=None msg=0/6 nodes are available: 1 c_wall violated: 1 conflicting context pair(s) with node memory, 5 node(s) had untolerated taint(s). no new claims to deallocate, preemption: 0/6 nodes are available: 1 No preemption victims found for incoming pod, 5 Preemption is not helpful for scheduling."
41.0954,Pod,MODIFIED,eval-sanitize-40-r4-041-lgn9n,phase=Pending node=None
41.0976,TaskRequest,MODIFIED,eval-sanitize-40-r4-041,phase=Scheduled job=None
41.1038,Job,MODIFIED,eval-sanitize-40-r4-029,
41.1049,Event,ADDED,eval-sanitize-40-r4-008-sbdmc.18d40a04df2f4c81,reason=Created count=1 msg=Created container: task
41.1059,Job,MODIFIED,eval-sanitize-40-r4-040,
41.1073,Event,ADDED,eval-sanitize-40-r4-041-lgn9n.18d40a04df566dd6,"reason=FailedScheduling count=None msg=0/6 nodes are available: 1 c_wall violated: 1 conflicting context pair(s) with node memory, 5 node(s) had untolerated taint(s). no new claims to deallocate, preemption: 0/6 nodes are available: 1 No preemption victims found for incoming pod, 5 Preemption is not helpful for scheduling."
41.1144,Event,ADDED,eval-sanitize-40-r4-027-x2p67.18d40a04dffaea73,reason=Created count=1 msg=Created container: task
41.1288,Event,ADDED,eval-sanitize-40-r4-039-x7df5.18d40a04e0de561d,reason=Created count=1 msg=Created container: task
41.1516,Event,ADDED,eval-sanitize-40-r4-026-8vj8k.18d40a04e21b0f2b,reason=Created count=1 msg=Created container: task
41.1588,Event,ADDED,eval-sanitize-40-r4-010-92scj.18d40a04e2406a5a,reason=Created count=1 msg=Created container: task
41.1625,Pod,MODIFIED,eval-sanitize-40-r4-029-gbx8m,phase=Succeeded node=kind-worker
41.1637,Event,ADDED,eval-sanitize-40-r4-022-7m7tt.18d40a04e26bab1e,reason=Created count=1 msg=Created container: task
41.1771,Event,MODIFIED,eval-sanitize-40-r4-041-lgn9n.18d40a04df566dd6,"reason=FailedScheduling count=None msg=0/6 nodes are available: 1 c_wall violated: 1 conflicting context pair(s) with node memory, 5 node(s) had untolerated taint(s). no new claims to deallocate, preemption: 0/6 nodes are available: 1 No preemption victims found for incoming pod, 5 Preemption is not helpful for scheduling."
41.179,Event,ADDED,eval-sanitize-40-r4-008-sbdmc.18d40a04e3a9a946,reason=Started count=1 msg=Started container task
41.1835,Event,ADDED,eval-sanitize-40-r4-039-x7df5.18d40a04e406554c,reason=Started count=1 msg=Started container task
41.1878,Event,ADDED,eval-sanitize-40-r4-027-x2p67.18d40a04e45ae526,reason=Started count=1 msg=Started container task
41.1995,Event,ADDED,eval-sanitize-40-r4-026-8vj8k.18d40a04e50014e0,reason=Started count=1 msg=Started container task
41.2056,Event,ADDED,eval-sanitize-40-r4-022-7m7tt.18d40a04e5753dd2,reason=Started count=1 msg=Started container task
41.2108,Event,ADDED,eval-sanitize-40-r4-010-92scj.18d40a04e57594fe,reason=Started count=1 msg=Started container task
41.7849,Pod,MODIFIED,eval-sanitize-40-r4-027-x2p67,phase=Running node=kind-worker3
41.7927,Pod,MODIFIED,eval-sanitize-40-r4-039-x7df5,phase=Running node=kind-worker3
41.7999,Pod,MODIFIED,eval-sanitize-40-r4-008-sbdmc,phase=Running node=kind-worker3
41.8067,Pod,MODIFIED,eval-sanitize-40-r4-010-92scj,phase=Running node=kind-worker3
41.8127,Pod,MODIFIED,eval-sanitize-40-r4-026-8vj8k,phase=Running node=kind-worker3
41.8184,Pod,MODIFIED,eval-sanitize-40-r4-022-7m7tt,phase=Running node=kind-worker3
41.9422,Job,MODIFIED,eval-sanitize-40-r4-028,
41.9467,Job,MODIFIED,eval-sanitize-40-r4-028,
41.9506,Event,ADDED,eval-sanitize-40-r4-028.18d40a0511d4a67b,reason=Completed count=1 msg=Job completed
41.9566,Job,MODIFIED,eval-sanitize-40-r4-028,
41.9622,TaskRequest,MODIFIED,eval-sanitize-40-r4-028,phase=Complete job=None
41.9706,Job,MODIFIED,eval-sanitize-40-r4-028,
41.9841,Pod,MODIFIED,eval-sanitize-40-r4-031-lf45v,phase=Running node=kind-worker5
42.0074,TaskRequest,ADDED,eval-sanitize-40-r4-042,phase=None job=None
42.011,TaskRequest,MODIFIED,eval-sanitize-40-r4-042,phase=Pending job=None
42.026,Job,ADDED,eval-sanitize-40-r4-042,
42.0298,TaskRequest,MODIFIED,eval-sanitize-40-r4-042,phase=Scheduled job=None
42.0328,Pod,ADDED,eval-sanitize-40-r4-042-pc6tp,phase=Pending node=None
42.0348,Job,MODIFIED,eval-sanitize-40-r4-042,
42.0386,Event,ADDED,eval-sanitize-40-r4-042.18d40a0516f28100,reason=SuccessfulCreate count=1 msg=Created pod: eval-sanitize-40-r4-042-pc6tp
42.0387,TaskRequest,MODIFIED,eval-sanitize-40-r4-042,phase=Scheduled job=None
42.0407,Pod,MODIFIED,eval-sanitize-40-r4-042-pc6tp,phase=Pending node=kind-worker3
42.0445,Event,ADDED,eval-sanitize-40-r4-042-pc6tp.18d40a05177077f6,reason=Scheduled count=None msg=Successfully assigned compute/eval-sanitize-40-r4-042-pc6tp to kind-worker3
42.0503,Job,MODIFIED,eval-sanitize-40-r4-029,
42.0535,Pod,MODIFIED,eval-sanitize-40-r4-042-pc6tp,phase=Pending node=kind-worker3
42.0547,Job,MODIFIED,eval-sanitize-40-r4-030,
42.0588,Pod,MODIFIED,eval-sanitize-40-r4-029-gbx8m,phase=Succeeded node=kind-worker
42.0604,Job,MODIFIED,eval-sanitize-40-r4-029,
42.0648,Job,MODIFIED,eval-sanitize-40-r4-030,
42.0834,Job,MODIFIED,eval-sanitize-40-r4-041,
42.0911,Job,MODIFIED,eval-sanitize-40-r4-041,
42.1178,Pod,MODIFIED,eval-sanitize-40-r4-030-kgdr2,phase=Succeeded node=kind-worker5
42.5252,Event,ADDED,eval-sanitize-40-r4-042-pc6tp.18d40a05341223a4,"reason=Pulled count=1 msg=Container image ""busybox:musl"" already present on machine"
42.5445,Event,ADDED,eval-sanitize-40-r4-042-pc6tp.18d40a053526fb60,reason=Created count=1 msg=Created container: task
42.6566,Event,ADDED,eval-sanitize-40-r4-042-pc6tp.18d40a053be913da,reason=Started count=1 msg=Started container task
42.7679,Pod,MODIFIED,eval-sanitize-40-r4-042-pc6tp,phase=Running node=kind-worker3
42.8778,Job,MODIFIED,eval-sanitize-40-r4-027,
42.8811,Job,MODIFIED,eval-sanitize-40-r4-039,
42.8818,Job,MODIFIED,eval-sanitize-40-r4-008,
42.8824,Job,MODIFIED,eval-sanitize-40-r4-010,
42.8831,Job,MODIFIED,eval-sanitize-40-r4-026,
42.8874,Job,MODIFIED,eval-sanitize-40-r4-022,
42.8902,Job,MODIFIED,eval-sanitize-40-r4-027,
42.8921,Job,MODIFIED,eval-sanitize-40-r4-039,
42.894,Job,MODIFIED,eval-sanitize-40-r4-008,
42.8962,Job,MODIFIED,eval-sanitize-40-r4-026,
42.897,Job,MODIFIED,eval-sanitize-40-r4-010,
42.8977,Job,MODIFIED,eval-sanitize-40-r4-022,
43.0133,Job,MODIFIED,eval-sanitize-40-r4-031,
43.0134,TaskRequest,ADDED,eval-sanitize-40-r4-043,phase=None job=None
43.0191,Pod,MODIFIED,eval-sanitize-40-r4-032-9r59c,phase=Running node=kind-worker
43.0192,TaskRequest,MODIFIED,eval-sanitize-40-r4-043,phase=Pending job=None
43.0246,Job,MODIFIED,eval-sanitize-40-r4-031,
43.0334,Job,ADDED,eval-sanitize-40-r4-043,
43.0369,Job,MODIFIED,eval-sanitize-40-r4-042,
43.0397,Pod,ADDED,eval-sanitize-40-r4-043-hmb2v,phase=Pending node=None
43.0398,TaskRequest,MODIFIED,eval-sanitize-40-r4-043,phase=Scheduled job=None
43.0443,Job,MODIFIED,eval-sanitize-40-r4-043,
43.0456,Event,ADDED,eval-sanitize-40-r4-043.18d40a0552f411b3,reason=SuccessfulCreate count=1 msg=Created pod: eval-sanitize-40-r4-043-hmb2v
43.0494,Pod,MODIFIED,eval-sanitize-40-r4-043-hmb2v,phase=Pending node=kind-worker3
43.0506,Job,MODIFIED,eval-sanitize-40-r4-042,
43.0555,Job,MODIFIED,eval-sanitize-40-r4-043,
43.0572,Event,ADDED,eval-sanitize-40-r4-043-hmb2v.18d40a055384d041,reason=Scheduled count=None msg=Successfully assigned compute/eval-sanitize-40-r4-043-hmb2v to kind-worker3
43.0582,Job,MODIFIED,eval-sanitize-40-r4-029,
43.0584,TaskRequest,MODIFIED,eval-sanitize-40-r4-043,phase=Scheduled job=None
43.0601,Job,MODIFIED,eval-sanitize-40-r4-030,
43.0635,Pod,MODIFIED,eval-sanitize-40-r4-043-hmb2v,phase=Pending node=kind-worker3
43.0647,Job,MODIFIED,eval-sanitize-40-r4-029,
43.067,Job,MODIFIED,eval-sanitize-40-r4-043,
43.07,Pod,MODIFIED,eval-sanitize-40-r4-030-kgdr2,phase=Succeeded node=kind-worker5
43.0703,Event,ADDED,eval-sanitize-40-r4-029.18d40a0554792dc2,reason=Completed count=1 msg=Job completed
43.0737,Job,MODIFIED,eval-sanitize-40-r4-030,
43.0784,Event,ADDED,eval-sanitize-40-r4-030.18d40a0554ff88a3,reason=Completed count=1 msg=Job completed
43.0873,Job,MODIFIED,eval-sanitize-40-r4-029,
43.0888,Job,MODIFIED,eval-sanitize-40-r4-030,
43.0916,TaskRequest,MODIFIED,eval-sanitize-40-r4-029,phase=Complete job=None
43.13,Pod,MODIFIED,eval-sanitize-40-r4-031-lf45v,phase=Succeeded node=kind-worker5
43.1459,TaskRequest,MODIFIED,eval-sanitize-40-r4-030,phase=Complete job=None
43.1508,Job,MODIFIED,eval-sanitize-40-r4-029,
43.1553,Job,MODIFIED,eval-sanitize-40-r4-030,
43.4758,Event,ADDED,eval-sanitize-40-r4-043-hmb2v.18d40a056cb86c48,"reason=Pulled count=1 msg=Container image ""busybox:musl"" already present on machine"
43.492,Event,ADDED,eval-sanitize-40-r4-043-hmb2v.18d40a056dbd0133,reason=Created count=1 msg=Created container: task
43.6089,Event,ADDED,eval-sanitize-40-r4-043-hmb2v.18d40a0574a74beb,reason=Started count=1 msg=Started container task
43.7849,Pod,MODIFIED,eval-sanitize-40-r4-043-hmb2v,phase=Running node=kind-worker3
43.9909,Pod,MODIFIED,eval-sanitize-40-r4-033-9d9p7,phase=Running node=kind-worker5
44.0176,TaskRequest,ADDED,eval-sanitize-40-r4-044,phase=None job=None
44.0204,Job,MODIFIED,eval-sanitize-40-r4-031,
44.0213,TaskRequest,MODIFIED,eval-sanitize-40-r4-044,phase=Pending job=None
44.0242,Job,MODIFIED,eval-sanitize-40-r4-032,
44.0288,Pod,MODIFIED,eval-sanitize-40-r4-031-lf45v,phase=Succeeded node=kind-worker5
44.0328,Job,MODIFIED,eval-sanitize-40-r4-031,
44.036,Event,ADDED,eval-sanitize-40-r4-031.18d40a058e2c1445,reason=Completed count=1 msg=Job completed
44.0383,Job,ADDED,eval-sanitize-40-r4-044,
44.0437,Job,MODIFIED,eval-sanitize-40-r4-043,
44.0452,TaskRequest,MODIFIED,eval-sanitize-40-r4-044,phase=Scheduled job=None
44.046,Pod,ADDED,eval-sanitize-40-r4-044-c77pq,phase=Pending node=None
44.0479,Job,MODIFIED,eval-sanitize-40-r4-044,
44.0509,Event,ADDED,eval-sanitize-40-r4-044.18d40a058ef3e7c9,reason=SuccessfulCreate count=1 msg=Created pod: eval-sanitize-40-r4-044-c77pq
44.0522,TaskRequest,MODIFIED,eval-sanitize-40-r4-044,phase=Scheduled job=None
44.0556,Pod,MODIFIED,eval-sanitize-40-r4-044-c77pq,phase=Pending node=None
44.057,Event,ADDED,eval-sanitize-40-r4-044-c77pq.18d40a058f352034,"reason=FailedScheduling count=None msg=0/6 nodes are available: 1 c_wall violated: 2 conflicting context pair(s) with node memory, 5 node(s) had untolerated taint(s). no new claims to deallocate, preemption: 0/6 nodes are available: 1 No preemption victims found for incoming pod, 5 Preemption is not helpful for scheduling."
44.0581,Job,MODIFIED,eval-sanitize-40-r4-031,
44.0589,Job,MODIFIED,eval-sanitize-40-r4-032,
44.06,Job,MODIFIED,eval-sanitize-40-r4-043,
44.0628,TaskRequest,MODIFIED,eval-sanitize-40-r4-031,phase=Complete job=None
44.0646,Event,ADDED,eval-sanitize-40-r4-044-c77pq.18d40a058fc865b2,"reason=FailedScheduling count=None msg=0/6 nodes are available: 1 c_wall violated: 2 conflicting context pair(s) with node memory, 5 node(s) had untolerated taint(s). no new claims to deallocate, preemption: 0/6 nodes are available: 1 No preemption victims found for incoming pod, 5 Preemption is not helpful for scheduling."
44.0834,Job,MODIFIED,eval-sanitize-40-r4-031,
44.3029,Pod,MODIFIED,eval-sanitize-40-r4-032-9r59c,phase=Succeeded node=kind-worker
44.3176,Event,MODIFIED,eval-sanitize-40-r4-044-c77pq.18d40a058fc865b2,"reason=FailedScheduling count=None msg=0/6 nodes are available: 1 c_wall violated: 2 conflicting context pair(s) with node memory, 5 node(s) had untolerated taint(s). no new claims to deallocate, preemption: 0/6 nodes are available: 1 No preemption victims found for incoming pod, 5 Preemption is not helpful for scheduling."
45.0103,Job,MODIFIED,eval-sanitize-40-r4-033,
45.0107,TaskRequest,ADDED,eval-sanitize-40-r4-045,phase=None job=None
45.0177,TaskRequest,MODIFIED,eval-sanitize-40-r4-045,phase=Pending job=None
45.0229,Job,MODIFIED,eval-sanitize-40-r4-033,
45.0255,Pod,MODIFIED,eval-sanitize-40-r4-034-qwc55,phase=Running node=kind-worker
45.0297,Job,MODIFIED,eval-sanitize-40-r4-032,
45.0345,Job,ADDED,eval-sanitize-40-r4-045,
45.0381,Pod,MODIFIED,eval-sanitize-40-r4-032-9r59c,phase=Succeeded node=kind-worker
45.0412,Pod,ADDED,eval-sanitize-40-r4-045-tz6l6,phase=Pending node=None
45.0429,TaskRequest,MODIFIED,eval-sanitize-40-r4-045,phase=Scheduled job=None
45.0439,Job,MODIFIED,eval-sanitize-40-r4-032,
45.0446,Job,MODIFIED,eval-sanitize-40-r4-045,
45.0466,Event,ADDED,eval-sanitize-40-r4-045.18d40a05ca48f2aa,reason=SuccessfulCreate count=1 msg=Created pod: eval-sanitize-40-r4-045-tz6l6
45.0512,Pod,MODIFIED,eval-sanitize-40-r4-045-tz6l6,phase=Pending node=kind-worker3
45.0525,Event,ADDED,eval-sanitize-40-r4-032.18d40a05ca6edb47,reason=Completed count=1 msg=Job completed
45.0527,TaskRequest,MODIFIED,eval-sanitize-40-r4-045,phase=Scheduled job=None
45.0535,Job,MODIFIED,eval-sanitize-40-r4-044,
45.0569,Job,MODIFIED,eval-sanitize-40-r4-032,
45.0574,Event,ADDED,eval-sanitize-40-r4-045-tz6l6.18d40a05cad97f2b,reason=Scheduled count=None msg=Successfully assigned compute/eval-sanitize-40-r4-045-tz6l6 to kind-worker3
45.0632,Pod,MODIFIED,eval-sanitize-40-r4-045-tz6l6,phase=Pending node=kind-worker3
45.0844,TaskRequest,MODIFIED,eval-sanitize-40-r4-032,phase=Complete job=None
45.0941,Job,MODIFIED,eval-sanitize-40-r4-032,
45.0959,Job,MODIFIED,eval-sanitize-40-r4-044,
45.1228,Pod,MODIFIED,eval-sanitize-40-r4-033-9d9p7,phase=Succeeded node=kind-worker5
45.5094,Event,ADDED,eval-sanitize-40-r4-045-tz6l6.18d40a05e5eb0776,"reason=Pulled count=1 msg=Container image ""busybox:musl"" already present on machine"
45.528,Event,ADDED,eval-sanitize-40-r4-045-tz6l6.18d40a05e711bbf9,reason=Created count=1 msg=Created container: task
45.5935,Event,ADDED,eval-sanitize-40-r4-045-tz6l6.18d40a05eae8944e,reason=Started count=1 msg=Started container task
45.7791,Pod,MODIFIED,eval-sanitize-40-r4-045-tz6l6,phase=Running node=kind-worker3
46.0079,TaskRequest,ADDED,eval-sanitize-40-r4-046,phase=None job=None
46.013,TaskRequest,MODIFIED,eval-sanitize-40-r4-046,phase=Pending job=None
46.0158,Job,MODIFIED,eval-sanitize-40-r4-033,
46.0263,Pod,MODIFIED,eval-sanitize-40-r4-033-9d9p7,phase=Succeeded node=kind-worker5
46.029,Pod,MODIFIED,eval-sanitize-40-r4-035-8pwgh,phase=Running node=kind-worker
46.0323,Job,ADDED,eval-sanitize-40-r4-046,
46.0332,Job,MODIFIED,eval-sanitize-40-r4-033,
46.0339,Job,MODIFIED,eval-sanitize-40-r4-034,
46.0362,Event,ADDED,eval-sanitize-40-r4-033.18d40a0605637b13,reason=Completed count=1 msg=Job completed
46.0386,TaskRequest,MODIFIED,eval-sanitize-40-r4-046,phase=Scheduled job=None
46.0395,Pod,ADDED,eval-sanitize-40-r4-046-n9t8x,phase=Pending node=None
46.0434,Job,MODIFIED,eval-sanitize-40-r4-046,
46.0455,Event,ADDED,eval-sanitize-40-r4-046.18d40a0605c8c84e,reason=SuccessfulCreate count=1 msg=Created pod: eval-sanitize-40-r4-046-n9t8x
46.0475,TaskRequest,MODIFIED,eval-sanitize-40-r4-046,phase=Scheduled job=None
46.0484,Job,MODIFIED,eval-sanitize-40-r4-045,
46.0518,Job,MODIFIED,eval-sanitize-40-r4-033,
46.0527,Pod,MODIFIED,eval-sanitize-40-r4-046-n9t8x,phase=Pending node=kind-worker3
46.0534,Job,MODIFIED,eval-sanitize-40-r4-034,
46.0557,Event,ADDED,eval-sanitize-40-r4-046-n9t8x.18d40a0606847549,reason=Scheduled count=None msg=Successfully assigned compute/eval-sanitize-40-r4-046-n9t8x to kind-worker3
46.0584,TaskRequest,MODIFIED,eval-sanitize-40-r4-033,phase=Complete job=None
46.0596,Job,MODIFIED,eval-sanitize-40-r4-045,
46.0645,Pod,MODIFIED,eval-sanitize-40-r4-046-n9t8x,phase=Pending node=kind-worker3
46.1286,Job,MODIFIED,eval-sanitize-40-r4-033,
46.2363,Pod,MODIFIED,eval-sanitize-40-r4-034-qwc55,phase=Succeeded node=kind-worker
46.4772,Event,ADDED,eval-sanitize-40-r4-046-n9t8x.18d40a061f9f430e,"reason=Pulled count=1 msg=Container image ""busybox:musl"" already present on machine"
46.4948,Event,ADDED,eval-sanitize-40-r4-046-n9t8x.18d40a0620aee162,reason=Created count=1 msg=Created container: task
46.5643,Event,ADDED,eval-sanitize-40-r4-046-n9t8x.18d40a0624c18a09,reason=Started count=1 msg=Started container task
46.8192,Pod,MODIFIED,eval-sanitize-40-r4-046-n9t8x,phase=Running node=kind-worker3
47.0021,Pod,MODIFIED,eval-sanitize-40-r4-036-btf8v,phase=Running node=kind-worker5
47.0097,TaskRequest,ADDED,eval-sanitize-40-r4-047,phase=None job=None
47.0135,TaskRequest,MODIFIED,eval-sanitize-40-r4-047,phase=Pending job=None
47.031,Job,ADDED,eval-sanitize-40-r4-047,
47.0356,Job,MODIFIED,eval-sanitize-40-r4-035,
47.0384,Job,MODIFIED,eval-sanitize-40-r4-034,
47.0386,TaskRequest,MODIFIED,eval-sanitize-40-r4-047,phase=Scheduled job=None
47.0395,Pod,ADDED,eval-sanitize-40-r4-047-nzdwf,phase=Pending node=None
47.044,Job,MODIFIED,eval-sanitize-40-r4-047,
47.0468,Event,ADDED,eval-sanitize-40-r4-047.18d40a06414ec54b,reason=SuccessfulCreate count=1 msg=Created pod: eval-sanitize-40-r4-047-nzdwf
47.0479,Job,MODIFIED,eval-sanitize-40-r4-046,
47.0516,Event,ADDED,eval-sanitize-40-r4-047-nzdwf.18d40a06418dd6cc,"reason=FailedScheduling count=None msg=0/6 nodes are available: 1 c_wall violated: 1 conflicting context pair(s) with node memory, 5 node(s) had untolerated taint(s). no new claims to deallocate, preemption: 0/6 nodes are available: 1 No preemption victims found for incoming pod, 5 Preemption is not helpful for scheduling."
47.0518,TaskRequest,MODIFIED,eval-sanitize-40-r4-047,phase=Scheduled job=None
47.0527,Job,MODIFIED,eval-sanitize-40-r4-035,
47.0547,Pod,MODIFIED,eval-sanitize-40-r4-034-qwc55,phase=Succeeded node=kind-worker
47.0559,Job,MODIFIED,eval-sanitize-40-r4-034,
47.0567,Pod,MODIFIED,eval-sanitize-40-r4-047-nzdwf,phase=Pending node=None
47.0577,Job,MODIFIED,eval-sanitize-40-r4-047,
47.0585,Job,MODIFIED,eval-sanitize-40-r4-046,
47.0603,Event,ADDED,eval-sanitize-40-r4-047-nzdwf.18d40a06426ed08f,"reason=FailedScheduling count=None msg=0/6 nodes are available: 1 c_wall violated: 1 conflicting context pair(s) with node memory, 5 node(s) had untolerated taint(s). no new claims to deallocate, preemption: 0/6 nodes are available: 1 No preemption victims found for incoming pod, 5 Preemption is not helpful for scheduling."
47.0877,Job,MODIFIED,eval-sanitize-40-r4-047,
47.2041,Pod,MODIFIED,eval-sanitize-40-r4-035-8pwgh,phase=Succeeded node=kind-worker
47.2207,Event,MODIFIED,eval-sanitize-40-r4-047-nzdwf.18d40a06426ed08f,"reason=FailedScheduling count=None msg=0/6 nodes are available: 1 c_wall violated: 1 conflicting context pair(s) with node memory, 5 node(s) had untolerated taint(s). no new claims to deallocate, preemption: 0/6 nodes are available: 1 No preemption victims found for incoming pod, 5 Preemption is not helpful for scheduling."
48.0117,Job,MODIFIED,eval-sanitize-40-r4-036,
48.0121,TaskRequest,ADDED,eval-sanitize-40-r4-048,phase=None job=None
48.0169,TaskRequest,MODIFIED,eval-sanitize-40-r4-048,phase=Pending job=None
48.022,Job,MODIFIED,eval-sanitize-40-r4-036,
48.0325,Job,ADDED,eval-sanitize-40-r4-048,
48.038,TaskRequest,MODIFIED,eval-sanitize-40-r4-048,phase=Scheduled job=None
48.0402,Pod,ADDED,eval-sanitize-40-r4-048-6xppp,phase=Pending node=None
48.0429,Job,MODIFIED,eval-sanitize-40-r4-035,
48.0451,Job,MODIFIED,eval-sanitize-40-r4-048,
48.0459,Job,MODIFIED,eval-sanitize-40-r4-034,
48.0469,Event,ADDED,eval-sanitize-40-r4-048.18d40a067d05478a,reason=SuccessfulCreate count=1 msg=Created pod: eval-sanitize-40-r4-048-6xppp
48.0511,Job,MODIFIED,eval-sanitize-40-r4-034,
48.0518,Event,ADDED,eval-sanitize-40-r4-048-6xppp.18d40a067d4d199f,"reason=FailedScheduling count=None msg=0/6 nodes are available: 1 c_wall violated: 1 conflicting context pair(s) with node memory, 5 node(s) had untolerated taint(s). no new claims to deallocate, preemption: 0/6 nodes are available: 1 No preemption victims found for incoming pod, 5 Preemption is not helpful for scheduling."
48.052,TaskRequest,MODIFIED,eval-sanitize-40-r4-048,phase=Scheduled job=None
48.0529,Pod,MODIFIED,eval-sanitize-40-r4-048-6xppp,phase=Pending node=None
48.0547,Pod,MODIFIED,eval-sanitize-40-r4-035-8pwgh,phase=Succeeded node=kind-worker
48.056,Job,MODIFIED,eval-sanitize-40-r4-035,
48.0564,Event,ADDED,eval-sanitize-40-r4-034.18d40a067da2c9de,reason=Completed count=1 msg=Job completed
48.0583,Event,ADDED,eval-sanitize-40-r4-048-6xppp.18d40a067ded111d,"reason=FailedScheduling count=None msg=0/6 nodes are available: 1 c_wall violated: 1 conflicting context pair(s) with node memory, 5 node(s) had untolerated taint(s). no new claims to deallocate, preemption: 0/6 nodes are available: 1 No preemption victims found for incoming pod, 5 Preemption is not helpful for scheduling."
48.0655,Job,MODIFIED,eval-sanitize-40-r4-034,
48.0833,TaskRequest,MODIFIED,eval-sanitize-40-r4-034,phase=Complete job=None
48.0908,Pod,MODIFIED,eval-sanitize-40-r4-036-btf8v,phase=Succeeded node=kind-worker5
48.0935,Job,MODIFIED,eval-sanitize-40-r4-034,
48.1102,Event,MODIFIED,eval-sanitize-40-r4-048-6xppp.18d40a067ded111d,"reason=FailedScheduling count=None msg=0/6 nodes are available: 1 c_wall violated: 1 conflicting context pair(s) with node memory, 5 node(s) had untolerated taint(s). no new claims to deallocate, preemption: 0/6 nodes are available: 1 No preemption victims found for incoming pod, 5 Preemption is not helpful for scheduling."
48.4089,Pod,MODIFIED,eval-sanitize-40-r4-037-dhckp,phase=Running node=kind-worker2
48.7905,Pod,MODIFIED,eval-sanitize-40-r4-038-k6lc5,phase=Running node=kind-worker4
49.0086,TaskRequest,ADDED,eval-sanitize-40-r4-049,phase=None job=None
49.0138,TaskRequest,MODIFIED,eval-sanitize-40-r4-049,phase=Pending job=None
49.0173,Job,MODIFIED,eval-sanitize-40-r4-036,
49.0256,Pod,MODIFIED,eval-sanitize-40-r4-036-btf8v,phase=Succeeded node=kind-worker5
49.0301,Job,MODIFIED,eval-sanitize-40-r4-036,
49.0308,Job,ADDED,eval-sanitize-40-r4-049,
49.0338,Event,ADDED,eval-sanitize-40-r4-036.18d40a06b80cf91a,reason=Completed count=1 msg=Job completed
49.0369,Pod,ADDED,eval-sanitize-40-r4-049-p2zf8,phase=Pending node=None
49.0374,TaskRequest,MODIFIED,eval-sanitize-40-r4-049,phase=Scheduled job=None
49.0411,Job,MODIFIED,eval-sanitize-40-r4-049,
49.0427,Event,ADDED,eval-sanitize-40-r4-049.18d40a06b876b5a6,reason=SuccessfulCreate count=1 msg=Created pod: eval-sanitize-40-r4-049-p2zf8
49.0455,Job,MODIFIED,eval-sanitize-40-r4-048,
49.0473,Event,ADDED,eval-sanitize-40-r4-049-p2zf8.18d40a06b8c1d7c1,"reason=FailedScheduling count=None msg=0/6 nodes are available: 1 c_wall violated: 1 conflicting context pair(s) with node memory, 5 node(s) had untolerated taint(s). no new claims to deallocate, preemption: 0/6 nodes are available: 1 No preemption victims found for incoming pod, 5 Preemption is not helpful for scheduling."
49.0475,TaskRequest,MODIFIED,eval-sanitize-40-r4-049,phase=Scheduled job=None
49.0485,Job,MODIFIED,eval-sanitize-40-r4-035,
49.0493,Pod,MODIFIED,eval-sanitize-40-r4-049-p2zf8,phase=Pending node=None
49.0503,Job,MODIFIED,eval-sanitize-40-r4-036,
49.0526,Job,MODIFIED,eval-sanitize-40-r4-035,
49.0558,Job,MODIFIED,eval-sanitize-40-r4-048,
49.0562,Event,ADDED,eval-sanitize-40-r4-049-p2zf8.18d40a06b95859a5,"reason=FailedScheduling count=None msg=0/6 nodes are available: 1 c_wall violated: 1 conflicting context pair(s) with node memory, 5 node(s) had untolerated taint(s). no new claims to deallocate, preemption: 0/6 nodes are available: 1 No preemption victims found for incoming pod, 5 Preemption is not helpful for scheduling."
49.0567,Event,ADDED,eval-sanitize-40-r4-035.18d40a06b962378c,reason=Completed count=1 msg=Job completed
49.0605,Job,MODIFIED,eval-sanitize-40-r4-035,
49.0795,TaskRequest,MODIFIED,eval-sanitize-40-r4-036,phase=Complete job=None
49.0839,TaskRequest,MODIFIED,eval-sanitize-40-r4-035,phase=Complete job=None
49.0925,Job,MODIFIED,eval-sanitize-40-r4-036,
49.0942,Job,MODIFIED,eval-sanitize-40-r4-035,
49.42,Job,MODIFIED,eval-sanitize-40-r4-037,
49.4298,Job,MODIFIED,eval-sanitize-40-r4-037,
49.582,Pod,MODIFIED,eval-sanitize-40-r4-037-dhckp,phase=Succeeded node=kind-worker2
49.6395,Event,MODIFIED,eval-sanitize-40-r4-049-p2zf8.18d40a06b95859a5,"reason=FailedScheduling count=None msg=0/6 nodes are available: 1 c_wall violated: 1 conflicting context pair(s) with node memory, 5 node(s) had untolerated taint(s). no new claims to deallocate, preemption: 0/6 nodes are available: 1 No preemption victims found for incoming pod, 5 Preemption is not helpful for scheduling."
49.8328,Job,MODIFIED,eval-sanitize-40-r4-038,
49.8438,Job,MODIFIED,eval-sanitize-40-r4-038,
49.9483,Pod,MODIFIED,eval-sanitize-40-r4-038-k6lc5,phase=Succeeded node=kind-worker4
50.0604,TaskRequest,ADDED,eval-sanitize-40-r4-050,phase=None job=None
50.0623,Job,MODIFIED,eval-sanitize-40-r4-049,
50.0645,TaskRequest,MODIFIED,eval-sanitize-40-r4-050,phase=Pending job=None
50.0799,Job,ADDED,eval-sanitize-40-r4-050,
50.0859,TaskRequest,MODIFIED,eval-sanitize-40-r4-050,phase=Scheduled job=None
50.0868,Pod,ADDED,eval-sanitize-40-r4-050-l8twf,phase=Pending node=None
50.0897,Job,MODIFIED,eval-sanitize-40-r4-050,
50.0927,Event,ADDED,eval-sanitize-40-r4-050.18d40a06f70ac0d9,reason=SuccessfulCreate count=1 msg=Created pod: eval-sanitize-40-r4-050-l8twf
50.0952,TaskRequest,MODIFIED,eval-sanitize-40-r4-050,phase=Scheduled job=None
50.0961,Pod,MODIFIED,eval-sanitize-40-r4-050-l8twf,phase=Pending node=kind-worker3
50.0985,Job,MODIFIED,eval-sanitize-40-r4-049,
50.0997,Event,ADDED,eval-sanitize-40-r4-050-l8twf.18d40a06f791c652,reason=Scheduled count=None msg=Successfully assigned compute/eval-sanitize-40-r4-050-l8twf to kind-worker3
50.1068,Pod,MODIFIED,eval-sanitize-40-r4-050-l8twf,phase=Pending node=kind-worker3
50.4255,Job,MODIFIED,eval-sanitize-40-r4-037,
50.4351,Pod,MODIFIED,eval-sanitize-40-r4-037-dhckp,phase=Succeeded node=kind-worker2
50.4367,Job,MODIFIED,eval-sanitize-40-r4-037,
50.5196,Event,ADDED,eval-sanitize-40-r4-050-l8twf.18d40a0710966183,"reason=Pulled count=1 msg=Container image ""busybox:musl"" already present on machine"
50.5375,Event,ADDED,eval-sanitize-40-r4-050-l8twf.18d40a0711acd89c,reason=Created count=1 msg=Created container: task
50.5898,Event,ADDED,eval-sanitize-40-r4-050-l8twf.18d40a0714a9126c,reason=Started count=1 msg=Started container task
50.7754,Pod,MODIFIED,eval-sanitize-40-r4-050-l8twf,phase=Running node=kind-worker3
50.8393,Job,MODIFIED,eval-sanitize-40-r4-038,
50.8487,Pod,MODIFIED,eval-sanitize-40-r4-038-k6lc5,phase=Succeeded node=kind-worker4
50.8498,Job,MODIFIED,eval-sanitize-40-r4-038,
51.0451,TaskRequest,ADDED,eval-sanitize-40-r4-051,phase=None job=None
51.0494,TaskRequest,MODIFIED,eval-sanitize-40-r4-051,phase=Pending job=None
51.0665,Job,ADDED,eval-sanitize-40-r4-051,
51.0733,TaskRequest,MODIFIED,eval-sanitize-40-r4-051,phase=Scheduled job=None
51.0748,Pod,ADDED,eval-sanitize-40-r4-051-7cqjl,phase=Pending node=None
51.0763,Job,MODIFIED,eval-sanitize-40-r4-051,
51.0787,Event,ADDED,eval-sanitize-40-r4-051.18d40a0731e1a264,reason=SuccessfulCreate count=1 msg=Created pod: eval-sanitize-40-r4-051-7cqjl
51.0818,TaskRequest,MODIFIED,eval-sanitize-40-r4-051,phase=Scheduled job=None
51.0839,Event,ADDED,eval-sanitize-40-r4-051-7cqjl.18d40a0732252a51,"reason=FailedScheduling count=None msg=0/6 nodes are available: 1 c_wall violated: 1 conflicting context pair(s) with node memory, 5 node(s) had untolerated taint(s). no new claims to deallocate, preemption: 0/6 nodes are available: 1 No preemption victims found for incoming pod, 5 Preemption is not helpful for scheduling."
51.0849,Pod,MODIFIED,eval-sanitize-40-r4-051-7cqjl,phase=Pending node=None
51.0922,Job,MODIFIED,eval-sanitize-40-r4-050,
51.0925,Event,ADDED,eval-sanitize-40-r4-051-7cqjl.18d40a0732bb3ed6,"reason=FailedScheduling count=None msg=0/6 nodes are available: 1 c_wall violated: 1 conflicting context pair(s) with node memory, 5 node(s) had untolerated taint(s). no new claims to deallocate, preemption: 0/6 nodes are available: 1 No preemption victims found for incoming pod, 5 Preemption is not helpful for scheduling."
51.1027,Job,MODIFIED,eval-sanitize-40-r4-050,
51.3322,Event,MODIFIED,eval-sanitize-40-r4-040-d5rbc.18d40a04beeeb04a,"reason=FailedScheduling count=None msg=0/6 nodes are available: 1 c_wall violated: 1 conflicting context pair(s) with node memory, 5 node(s) had untolerated taint(s). no new claims to deallocate, preemption: 0/6 nodes are available: 1 No preemption victims found for incoming pod, 5 Preemption is not helpful for scheduling."
51.4711,Job,MODIFIED,eval-sanitize-40-r4-037,
51.4759,Job,MODIFIED,eval-sanitize-40-r4-037,
51.4799,Event,ADDED,eval-sanitize-40-r4-037.18d40a0749d54ac8,reason=Completed count=1 msg=Job completed
51.486,Job,MODIFIED,eval-sanitize-40-r4-037,
51.491,TaskRequest,MODIFIED,eval-sanitize-40-r4-037,phase=Complete job=None
51.4999,Job,MODIFIED,eval-sanitize-40-r4-037,
51.8408,Pod,MODIFIED,eval-sanitize-40-r4-010-92scj,phase=Running node=kind-worker3
51.8459,Job,MODIFIED,eval-sanitize-40-r4-038,
51.849,Pod,MODIFIED,eval-sanitize-40-r4-027-x2p67,phase=Running node=kind-worker3
51.8505,Job,MODIFIED,eval-sanitize-40-r4-038,
51.8576,Pod,MODIFIED,eval-sanitize-40-r4-026-8vj8k,phase=Running node=kind-worker3
51.8584,Event,ADDED,eval-sanitize-40-r4-038.18d40a0760249078,reason=Completed count=1 msg=Job completed
51.8651,Pod,MODIFIED,eval-sanitize-40-r4-022-7m7tt,phase=Running node=kind-worker3
51.8663,Job,MODIFIED,eval-sanitize-40-r4-038,
51.8689,Event,MODIFIED,eval-sanitize-40-r4-051-7cqjl.18d40a0732bb3ed6,"reason=FailedScheduling count=None msg=0/6 nodes are available: 1 c_wall violated: 1 conflicting context pair(s) with node memory, 5 node(s) had untolerated taint(s). no new claims to deallocate, preemption: 0/6 nodes are available: 1 No preemption victims found for incoming pod, 5 Preemption is not helpful for scheduling."
51.8724,Pod,MODIFIED,eval-sanitize-40-r4-039-x7df5,phase=Running node=kind-worker3
51.8738,TaskRequest,MODIFIED,eval-sanitize-40-r4-038,phase=Complete job=None
51.88,Pod,MODIFIED,eval-sanitize-40-r4-008-sbdmc,phase=Running node=kind-worker3
51.8844,Job,MODIFIED,eval-sanitize-40-r4-038,
52.0084,TaskRequest,ADDED,eval-sanitize-40-r4-052,phase=None job=None
52.0125,TaskRequest,MODIFIED,eval-sanitize-40-r4-052,phase=Pending job=None
52.0286,Job,ADDED,eval-sanitize-40-r4-052,
52.0329,TaskRequest,MODIFIED,eval-sanitize-40-r4-052,phase=Scheduled job=None
52.0365,Pod,ADDED,eval-sanitize-40-r4-052-bt8rh,phase=Pending node=None
52.0383,Job,MODIFIED,eval-sanitize-40-r4-052,
52.0424,Event,ADDED,eval-sanitize-40-r4-052.18d40a076b4318af,reason=SuccessfulCreate count=1 msg=Created pod: eval-sanitize-40-r4-052-bt8rh
52.0425,TaskRequest,MODIFIED,eval-sanitize-40-r4-052,phase=Scheduled job=None
52.0452,Pod,MODIFIED,eval-sanitize-40-r4-052-bt8rh,phase=Pending node=kind-worker3
52.049,Event,ADDED,eval-sanitize-40-r4-052-bt8rh.18d40a076bc28388,reason=Scheduled count=None msg=Successfully assigned compute/eval-sanitize-40-r4-052-bt8rh to kind-worker3
52.0549,Pod,MODIFIED,eval-sanitize-40-r4-052-bt8rh,phase=Pending node=kind-worker3
52.1179,Job,MODIFIED,eval-sanitize-40-r4-051,
52.1265,Job,MODIFIED,eval-sanitize-40-r4-051,
52.5152,Event,ADDED,eval-sanitize-40-r4-052-bt8rh.18d40a0787863262,"reason=Pulled count=1 msg=Container image ""busybox:musl"" already present on machine"
52.5346,Event,ADDED,eval-sanitize-40-r4-052-bt8rh.18d40a0788b563fe,reason=Created count=1 msg=Created container: task
52.608,Event,ADDED,eval-sanitize-40-r4-052-bt8rh.18d40a078d0eea35,reason=Started count=1 msg=Started container task
52.7921,Pod,MODIFIED,eval-sanitize-40-r4-052-bt8rh,phase=Running node=kind-worker3
52.801,Pod,MODIFIED,eval-sanitize-40-r4-042-pc6tp,phase=Running node=kind-worker3
52.8646,Job,MODIFIED,eval-sanitize-40-r4-010,
52.867,Job,MODIFIED,eval-sanitize-40-r4-027,
52.8679,Job,MODIFIED,eval-sanitize-40-r4-026,
52.8704,Job,MODIFIED,eval-sanitize-40-r4-022,
52.8759,Job,MODIFIED,eval-sanitize-40-r4-010,
52.8781,Job,MODIFIED,eval-sanitize-40-r4-039,
52.8794,Job,MODIFIED,eval-sanitize-40-r4-027,
52.8805,Job,MODIFIED,eval-sanitize-40-r4-026,
52.8814,Job,MODIFIED,eval-sanitize-40-r4-022,
52.8842,Job,MODIFIED,eval-sanitize-40-r4-008,
52.891,Job,MODIFIED,eval-sanitize-40-r4-039,
52.8959,Job,MODIFIED,eval-sanitize-40-r4-008,
52.9789,Pod,MODIFIED,eval-sanitize-40-r4-008-sbdmc,phase=Succeeded node=kind-worker3
52.9967,Pod,MODIFIED,eval-sanitize-40-r4-022-7m7tt,phase=Succeeded node=kind-worker3
53.0076,TaskRequest,ADDED,eval-sanitize-40-r4-053,phase=None job=None
53.0118,TaskRequest,MODIFIED,eval-sanitize-40-r4-053,phase=Pending job=None
53.0232,Pod,MODIFIED,eval-sanitize-40-r4-039-x7df5,phase=Succeeded node=kind-worker3
53.0274,Job,ADDED,eval-sanitize-40-r4-053,
53.0304,Pod,MODIFIED,eval-sanitize-40-r4-026-8vj8k,phase=Succeeded node=kind-worker3
53.0329,Pod,ADDED,eval-sanitize-40-r4-053-mfqvs,phase=Pending node=None
53.0348,TaskRequest,MODIFIED,eval-sanitize-40-r4-053,phase=Scheduled job=None
53.0376,Job,MODIFIED,eval-sanitize-40-r4-053,
53.0394,Event,ADDED,eval-sanitize-40-r4-053.18d40a07a6a5a823,reason=SuccessfulCreate count=1 msg=Created pod: eval-sanitize-40-r4-053-mfqvs
53.041,Pod,MODIFIED,eval-sanitize-40-r4-010-92scj,phase=Succeeded node=kind-worker3
53.0423,Job,MODIFIED,eval-sanitize-40-r4-052,
53.0442,Job,MODIFIED,eval-sanitize-40-r4-053,
53.0443,TaskRequest,MODIFIED,eval-sanitize-40-r4-053,phase=Scheduled job=None
53.05,Pod,MODIFIED,eval-sanitize-40-r4-027-x2p67,phase=Succeeded node=kind-worker3
53.0516,Job,MODIFIED,eval-sanitize-40-r4-052,
53.0546,Job,MODIFIED,eval-sanitize-40-r4-053,
53.0687,Pod,MODIFIED,eval-sanitize-40-r4-053-mfqvs,phase=Pending node=None
53.0692,Event,ADDED,eval-sanitize-40-r4-053-mfqvs.18d40a07a8788797,"reason=FailedScheduling count=None msg=0/6 nodes are available: 1 c_wall violated: 1 conflicting context pair(s) with node memory, 5 node(s) had untolerated taint(s). no new claims to deallocate, preemption: 0/6 nodes are available: 1 No preemption victims found for incoming pod, 5 Preemption is not helpful for scheduling."
53.1969,Event,ADDED,eval-sanitize-40-r4-053-mfqvs.18d40a07b01d70bb,"reason=FailedScheduling count=None msg=0/6 nodes are available: 1 c_wall violated: 1 conflicting context pair(s) with node memory, 5 node(s) had untolerated taint(s). no new claims to deallocate, preemption: 0/6 nodes are available: 1 No preemption victims found for incoming pod, 5 Preemption is not helpful for scheduling."
53.8056,Pod,MODIFIED,eval-sanitize-40-r4-043-hmb2v,phase=Running node=kind-worker3
53.8068,Job,MODIFIED,eval-sanitize-40-r4-042,
53.8204,Job,MODIFIED,eval-sanitize-40-r4-042,
53.8838,Job,MODIFIED,eval-sanitize-40-r4-010,
53.8862,Job,MODIFIED,eval-sanitize-40-r4-026,
53.8873,Job,MODIFIED,eval-sanitize-40-r4-027,
53.8882,Job,MODIFIED,eval-sanitize-40-r4-022,
53.8894,Job,MODIFIED,eval-sanitize-40-r4-039,
53.8944,Pod,MODIFIED,eval-sanitize-40-r4-010-92scj,phase=Succeeded node=kind-worker3
53.8974,Pod,MODIFIED,eval-sanitize-40-r4-039-x7df5,phase=Succeeded node=kind-worker3
53.8989,Job,MODIFIED,eval-sanitize-40-r4-010,
53.9013,Pod,MODIFIED,eval-sanitize-40-r4-022-7m7tt,phase=Succeeded node=kind-worker3
53.9024,Job,MODIFIED,eval-sanitize-40-r4-022,
53.9038,Pod,MODIFIED,eval-sanitize-40-r4-026-8vj8k,phase=Succeeded node=kind-worker3
53.9042,Event,MODIFIED,eval-sanitize-40-r4-053-mfqvs.18d40a07b01d70bb,"reason=FailedScheduling count=None msg=0/6 nodes are available: 1 c_wall violated: 1 conflicting context pair(s) with node memory, 5 node(s) had untolerated taint(s). no new claims to deallocate, preemption: 0/6 nodes are available: 1 No preemption victims found for incoming pod, 5 Preemption is not helpful for scheduling."
53.9051,Job,MODIFIED,eval-sanitize-40-r4-026,
53.9059,Job,MODIFIED,eval-sanitize-40-r4-039,
53.9071,Pod,MODIFIED,eval-sanitize-40-r4-027-x2p67,phase=Succeeded node=kind-worker3
53.9082,Job,MODIFIED,eval-sanitize-40-r4-027,
53.9092,Job,MODIFIED,eval-sanitize-40-r4-008,
53.9099,Event,ADDED,eval-sanitize-40-r4-022.18d40a07da6f12e5,reason=Completed count=1 msg=Job completed
53.9124,Job,MODIFIED,eval-sanitize-40-r4-026,
53.9153,Job,MODIFIED,eval-sanitize-40-r4-022,
53.9169,Event,ADDED,eval-sanitize-40-r4-026.18d40a07da7040a1,reason=Completed count=1 msg=Job completed
53.9177,Job,MODIFIED,eval-sanitize-40-r4-039,
53.9198,Pod,MODIFIED,eval-sanitize-40-r4-008-sbdmc,phase=Succeeded node=kind-worker3
53.92,TaskRequest,MODIFIED,eval-sanitize-40-r4-026,phase=Complete job=None
53.9209,Job,MODIFIED,eval-sanitize-40-r4-008,
53.9246,Event,ADDED,eval-sanitize-40-r4-039.18d40a07da717ba6,reason=Completed count=1 msg=Job completed
53.9305,Pod,MODIFIED,eval-sanitize-40-r4-042-pc6tp,phase=Succeeded node=kind-worker3
53.9866,TaskRequest,MODIFIED,eval-sanitize-40-r4-022,phase=Complete job=None
53.9897,Job,MODIFIED,eval-sanitize-40-r4-026,
53.9915,TaskRequest,MODIFIED,eval-sanitize-40-r4-039,phase=Complete job=None
53.9993,Job,MODIFIED,eval-sanitize-40-r4-022,
54.0013,Job,MODIFIED,eval-sanitize-40-r4-039,
54.0077,TaskRequest,ADDED,eval-sanitize-40-r4-054,phase=None job=None
54.0122,TaskRequest,MODIFIED,eval-sanitize-40-r4-054,phase=Pending job=None
54.0879,Job,ADDED,eval-sanitize-40-r4-054,
54.1476,Pod,ADDED,eval-sanitize-40-r4-054-4hwn6,phase=Pending node=None
54.1477,TaskRequest,MODIFIED,eval-sanitize-40-r4-054,phase=Scheduled job=None
54.1484,Job,MODIFIED,eval-sanitize-40-r4-054,
54.1512,Event,ADDED,eval-sanitize-40-r4-054.18d40a07e91087c5,reason=SuccessfulCreate count=1 msg=Created pod: eval-sanitize-40-r4-054-4hwn6
54.1556,Pod,MODIFIED,eval-sanitize-40-r4-054-4hwn6,phase=Pending node=None
54.1569,Event,ADDED,eval-sanitize-40-r4-054-4hwn6.18d40a07e94b98d9,"reason=FailedScheduling count=None msg=0/6 nodes are available: 1 c_wall violated: 2 conflicting context pair(s) with node memory, 5 node(s) had untolerated taint(s). no new claims to deallocate, preemption: 0/6 nodes are available: 1 No preemption victims found for incoming pod, 5 Preemption is not helpful for scheduling."
54.157,TaskRequest,MODIFIED,eval-sanitize-40-r4-054,phase=Scheduled job=None
54.1634,Event,ADDED,eval-sanitize-40-r4-054-4hwn6.18d40a07e9cb9f2e,"reason=FailedScheduling count=None msg=0/6 nodes are available: 1 c_wall violated: 2 conflicting context pair(s) with node memory, 5 node(s) had untolerated taint(s). no new claims to deallocate, preemption: 0/6 nodes are available: 1 No preemption victims found for incoming pod, 5 Preemption is not helpful for scheduling."
54.8118,Job,MODIFIED,eval-sanitize-40-r4-043,
54.8145,Job,MODIFIED,eval-sanitize-40-r4-042,
54.8232,Job,MODIFIED,eval-sanitize-40-r4-043,
54.8265,Job,MODIFIED,eval-sanitize-40-r4-042,
54.8279,Pod,MODIFIED,eval-sanitize-40-r4-042-pc6tp,phase=Succeeded node=kind-worker3
54.9445,Job,MODIFIED,eval-sanitize-40-r4-010,
54.9479,Job,MODIFIED,eval-sanitize-40-r4-027,
54.9488,Job,MODIFIED,eval-sanitize-40-r4-008,
54.9498,Job,MODIFIED,eval-sanitize-40-r4-010,
54.9524,Job,MODIFIED,eval-sanitize-40-r4-027,
54.9532,Job,MODIFIED,eval-sanitize-40-r4-008,
54.9562,Event,ADDED,eval-sanitize-40-r4-010.18d40a0818e55291,reason=Completed count=1 msg=Job completed
54.958,Pod,MODIFIED,eval-sanitize-40-r4-043-hmb2v,phase=Succeeded node=kind-worker3
54.9616,Job,MODIFIED,eval-sanitize-40-r4-010,
54.9619,Event,ADDED,eval-sanitize-40-r4-008.18d40a08190f804a,reason=Completed count=1 msg=Job completed
54.9671,Job,MODIFIED,eval-sanitize-40-r4-027,
54.9682,Event,ADDED,eval-sanitize-40-r4-027.18d40a0819116214,reason=Completed count=1 msg=Job completed
54.969,Job,MODIFIED,eval-sanitize-40-r4-008,
54.9691,TaskRequest,MODIFIED,eval-sanitize-40-r4-010,phase=Complete job=None
54.9726,TaskRequest,MODIFIED,eval-sanitize-40-r4-027,phase=Complete job=None
54.9788,TaskRequest,MODIFIED,eval-sanitize-40-r4-008,phase=Complete job=None
54.9815,Job,MODIFIED,eval-sanitize-40-r4-010,
54.9834,Job,MODIFIED,eval-sanitize-40-r4-027,
54.9873,Job,MODIFIED,eval-sanitize-40-r4-008,
55.067,TaskRequest,ADDED,eval-sanitize-40-r4-055,phase=None job=None
55.0677,Event,MODIFIED,eval-sanitize-40-r4-054-4hwn6.18d40a07e9cb9f2e,"reason=FailedScheduling count=None msg=0/6 nodes are available: 1 c_wall violated: 2 conflicting context pair(s) with node memory, 5 node(s) had untolerated taint(s). no new claims to deallocate, preemption: 0/6 nodes are available: 1 No preemption victims found for incoming pod, 5 Preemption is not helpful for scheduling."
55.0703,TaskRequest,MODIFIED,eval-sanitize-40-r4-055,phase=Pending job=None
55.0834,Job,ADDED,eval-sanitize-40-r4-055,
55.088,TaskRequest,MODIFIED,eval-sanitize-40-r4-055,phase=Scheduled job=None
55.0899,Pod,ADDED,eval-sanitize-40-r4-055-48dtb,phase=Pending node=None
55.0938,Job,MODIFIED,eval-sanitize-40-r4-055,
55.0956,Event,ADDED,eval-sanitize-40-r4-055.18d40a082141644d,reason=SuccessfulCreate count=1 msg=Created pod: eval-sanitize-40-r4-055-48dtb
55.0977,TaskRequest,MODIFIED,eval-sanitize-40-r4-055,phase=Scheduled job=None
55.0986,Pod,MODIFIED,eval-sanitize-40-r4-055-48dtb,phase=Pending node=kind-worker3
55.1022,Event,ADDED,eval-sanitize-40-r4-055-48dtb.18d40a0821c8eb39,reason=Scheduled count=None msg=Successfully assigned compute/eval-sanitize-40-r4-055-48dtb to kind-worker3
55.1093,Pod,MODIFIED,eval-sanitize-40-r4-055-48dtb,phase=Pending node=kind-worker3
55.1718,Job,MODIFIED,eval-sanitize-40-r4-054,
55.1802,Job,MODIFIED,eval-sanitize-40-r4-054,
55.5304,Event,ADDED,eval-sanitize-40-r4-055-48dtb.18d40a083b350881,"reason=Pulled count=1 msg=Container image ""busybox:musl"" already present on machine"
55.5465,Event,ADDED,eval-sanitize-40-r4-055-48dtb.18d40a083c4bca56,reason=Created count=1 msg=Created container: task
55.6167,Event,ADDED,eval-sanitize-40-r4-055-48dtb.18d40a08405e865a,reason=Started count=1 msg=Started container task
55.6304,Node,MODIFIED,kind-control-plane,taints=1
55.8084,Pod,MODIFIED,eval-sanitize-40-r4-055-48dtb,phase=Running node=kind-worker3
55.8158,Pod,MODIFIED,eval-sanitize-40-r4-045-tz6l6,phase=Running node=kind-worker3
55.8175,Job,MODIFIED,eval-sanitize-40-r4-043,
55.8202,Job,MODIFIED,eval-sanitize-40-r4-042,
55.8255,Job,MODIFIED,eval-sanitize-40-r4-042,
55.8278,Job,MODIFIED,eval-sanitize-40-r4-043,
55.829,Pod,MODIFIED,eval-sanitize-40-r4-043-hmb2v,phase=Succeeded node=kind-worker3
55.8321,Event,ADDED,eval-sanitize-40-r4-042.18d40a084d05e9c5,reason=Completed count=1 msg=Job completed
55.8387,Job,MODIFIED,eval-sanitize-40-r4-042,
55.8437,TaskRequest,MODIFIED,eval-sanitize-40-r4-042,phase=Complete job=None
55.8521,Job,MODIFIED,eval-sanitize-40-r4-042,
56.015,TaskRequest,ADDED,eval-sanitize-40-r4-056,phase=None job=None
56.0188,TaskRequest,MODIFIED,eval-sanitize-40-r4-056,phase=Pending job=None
56.0347,Job,ADDED,eval-sanitize-40-r4-056,
56.04,Pod,ADDED,eval-sanitize-40-r4-056-4bf68,phase=Pending node=None
56.0415,TaskRequest,MODIFIED,eval-sanitize-40-r4-056,phase=Scheduled job=None
56.0446,Job,MODIFIED,eval-sanitize-40-r4-056,
56.0459,Event,ADDED,eval-sanitize-40-r4-056.18d40a0859d21f83,reason=SuccessfulCreate count=1 msg=Created pod: eval-sanitize-40-r4-056-4bf68
56.0507,Pod,MODIFIED,eval-sanitize-40-r4-056-4bf68,phase=Pending node=None
56.0512,Event,ADDED,eval-sanitize-40-r4-056-4bf68.18d40a085a156097,"reason=FailedScheduling count=None msg=0/6 nodes are available: 1 c_wall violated: 1 conflicting context pair(s) with node memory, 5 node(s) had untolerated taint(s). no new claims to deallocate, preemption: 0/6 nodes are available: 1 No preemption victims found for incoming pod, 5 Preemption is not helpful for scheduling."
56.0513,TaskRequest,MODIFIED,eval-sanitize-40-r4-056,phase=Scheduled job=None
56.0573,Event,ADDED,eval-sanitize-40-r4-056-4bf68.18d40a085aa53487,"reason=FailedScheduling count=None msg=0/6 nodes are available: 1 c_wall violated: 1 conflicting context pair(s) with node memory, 5 node(s) had untolerated taint(s). no new claims to deallocate, preemption: 0/6 nodes are available: 1 No preemption victims found for incoming pod, 5 Preemption is not helpful for scheduling."
56.0965,Job,MODIFIED,eval-sanitize-40-r4-055,
56.1054,Job,MODIFIED,eval-sanitize-40-r4-055,
56.8508,Pod,MODIFIED,eval-sanitize-40-r4-046-n9t8x,phase=Running node=kind-worker3
56.8539,Job,MODIFIED,eval-sanitize-40-r4-045,
56.8547,Job,MODIFIED,eval-sanitize-40-r4-043,
56.8607,Job,MODIFIED,eval-sanitize-40-r4-043,
56.8651,Job,MODIFIED,eval-sanitize-40-r4-045,
56.8662,Event,ADDED,eval-sanitize-40-r4-043.18d40a088ab4cae9,reason=Completed count=1 msg=Job completed
56.8738,Job,MODIFIED,eval-sanitize-40-r4-043,
56.8783,TaskRequest,MODIFIED,eval-sanitize-40-r4-043,phase=Complete job=None
56.8881,Job,MODIFIED,eval-sanitize-40-r4-043,
56.9016,Event,MODIFIED,eval-sanitize-40-r4-056-4bf68.18d40a085aa53487,"reason=FailedScheduling count=None msg=0/6 nodes are available: 1 c_wall violated: 1 conflicting context pair(s) with node memory, 5 node(s) had untolerated taint(s). no new claims to deallocate, preemption: 0/6 nodes are available: 1 No preemption victims found for incoming pod, 5 Preemption is not helpful for scheduling."
56.9687,Pod,MODIFIED,eval-sanitize-40-r4-045-tz6l6,phase=Succeeded node=kind-worker3
57.0827,TaskRequest,ADDED,eval-sanitize-40-r4-057,phase=None job=None
57.0838,Job,MODIFIED,eval-sanitize-40-r4-056,
57.0897,TaskRequest,MODIFIED,eval-sanitize-40-r4-057,phase=Pending job=None
57.0932,Job,MODIFIED,eval-sanitize-40-r4-056,
57.1041,Job,ADDED,eval-sanitize-40-r4-057,
57.109,Pod,ADDED,eval-sanitize-40-r4-057-nzvpl,phase=Pending node=None
57.1106,TaskRequest,MODIFIED,eval-sanitize-40-r4-057,phase=Scheduled job=None
57.1133,Job,MODIFIED,eval-sanitize-40-r4-057,
57.1147,Event,ADDED,eval-sanitize-40-r4-057.18d40a089987b0fc,reason=SuccessfulCreate count=1 msg=Created pod: eval-sanitize-40-r4-057-nzvpl
57.1178,Pod,MODIFIED,eval-sanitize-40-r4-057-nzvpl,phase=Pending node=None
57.1181,Event,ADDED,eval-sanitize-40-r4-057-nzvpl.18d40a0899c344a4,"reason=FailedScheduling count=None msg=0/6 nodes are available: 1 c_wall violated: 1 conflicting context pair(s) with node memory, 5 node(s) had untolerated taint(s). no new claims to deallocate, preemption: 0/6 nodes are available: 1 No preemption victims found for incoming pod, 5 Preemption is not helpful for scheduling."
57.1213,Job,MODIFIED,eval-sanitize-40-r4-057,
57.1244,Event,ADDED,eval-sanitize-40-r4-057-nzvpl.18d40a089a401bce,"reason=FailedScheduling count=None msg=0/6 nodes are available: 1 c_wall violated: 1 conflicting context pair(s) with node memory, 5 node(s) had untolerated taint(s). no new claims to deallocate, preemption: 0/6 nodes are available: 1 No preemption victims found for incoming pod, 5 Preemption is not helpful for scheduling."
57.13,Job,MODIFIED,eval-sanitize-40-r4-057,
57.1312,TaskRequest,MODIFIED,eval-sanitize-40-r4-057,phase=Scheduled job=None
57.8559,Job,MODIFIED,eval-sanitize-40-r4-046,
57.8592,Job,MODIFIED,eval-sanitize-40-r4-045,
57.866,Job,MODIFIED,eval-sanitize-40-r4-046,
57.8687,Pod,MODIFIED,eval-sanitize-40-r4-045-tz6l6,phase=Succeeded node=kind-worker3
57.8697,Job,MODIFIED,eval-sanitize-40-r4-045,
57.9725,Pod,MODIFIED,eval-sanitize-40-r4-046-n9t8x,phase=Succeeded node=kind-worker3
58.0444,TaskRequest,ADDED,eval-sanitize-40-r4-058,phase=None job=None
58.0484,TaskRequest,MODIFIED,eval-sanitize-40-r4-058,phase=Pending job=None
58.064,Job,ADDED,eval-sanitize-40-r4-058,
58.075,TaskRequest,MODIFIED,eval-sanitize-40-r4-058,phase=Scheduled job=None
58.0782,Job,MODIFIED,eval-sanitize-40-r4-058,
58.0787,Event,MODIFIED,eval-sanitize-40-r4-057-nzvpl.18d40a089a401bce,"reason=FailedScheduling count=None msg=0/6 nodes are available: 1 c_wall violated: 1 conflicting context pair(s) with node memory, 5 node(s) had untolerated taint(s). no new claims to deallocate, preemption: 0/6 nodes are available: 1 No preemption victims found for incoming pod, 5 Preemption is not helpful for scheduling."
58.0797,Pod,ADDED,eval-sanitize-40-r4-058-7z94v,phase=Pending node=None
58.0825,Event,ADDED,eval-sanitize-40-r4-058.18d40a08d3465f89,reason=SuccessfulCreate count=1 msg=Created pod: eval-sanitize-40-r4-058-7z94v
58.0833,TaskRequest,MODIFIED,eval-sanitize-40-r4-058,phase=Scheduled job=None
58.0872,Pod,MODIFIED,eval-sanitize-40-r4-058-7z94v,phase=Pending node=None
58.0877,Event,ADDED,eval-sanitize-40-r4-058-7z94v.18d40a08d38bba63,"reason=FailedScheduling count=None msg=0/6 nodes are available: 1 c_wall violated: 1 conflicting context pair(s) with node memory, 5 node(s) had untolerated taint(s). no new claims to deallocate, preemption: 0/6 nodes are available: 1 No preemption victims found for incoming pod, 5 Preemption is not helpful for scheduling."
58.0946,Event,ADDED,eval-sanitize-40-r4-058-7z94v.18d40a08d4072dd5,"reason=FailedScheduling count=None msg=0/6 nodes are available: 1 c_wall violated: 1 conflicting context pair(s) with node memory, 5 node(s) had untolerated taint(s). no new claims to deallocate, preemption: 0/6 nodes are available: 1 No preemption victims found for incoming pod, 5 Preemption is not helpful for scheduling."
58.8696,Job,MODIFIED,eval-sanitize-40-r4-046,
58.871,Job,MODIFIED,eval-sanitize-40-r4-045,
58.8762,Job,MODIFIED,eval-sanitize-40-r4-045,
58.8797,Pod,MODIFIED,eval-sanitize-40-r4-046-n9t8x,phase=Succeeded node=kind-worker3
58.8806,Job,MODIFIED,eval-sanitize-40-r4-046,
58.8814,Event,ADDED,eval-sanitize-40-r4-045.18d40a0902db4436,reason=Completed count=1 msg=Job completed
58.8892,Job,MODIFIED,eval-sanitize-40-r4-045,
58.8961,TaskRequest,MODIFIED,eval-sanitize-40-r4-045,phase=Complete job=None
58.9084,Job,MODIFIED,eval-sanitize-40-r4-045,
59.0172,TaskRequest,ADDED,eval-sanitize-40-r4-059,phase=None job=None
59.0226,TaskRequest,MODIFIED,eval-sanitize-40-r4-059,phase=Pending job=None
59.0367,Job,ADDED,eval-sanitize-40-r4-059,
59.045,Pod,ADDED,eval-sanitize-40-r4-059-9bxnn,phase=Pending node=None
59.0467,Job,MODIFIED,eval-sanitize-40-r4-059,
59.0468,TaskRequest,MODIFIED,eval-sanitize-40-r4-059,phase=Scheduled job=None
59.0494,Event,ADDED,eval-sanitize-40-r4-059.18d40a090ced13eb,reason=SuccessfulCreate count=1 msg=Created pod: eval-sanitize-40-r4-059-9bxnn
59.0546,Pod,MODIFIED,eval-sanitize-40-r4-059-9bxnn,phase=Pending node=kind-worker3
59.0548,TaskRequest,MODIFIED,eval-sanitize-40-r4-059,phase=Scheduled job=None
59.058,Event,ADDED,eval-sanitize-40-r4-059-9bxnn.18d40a090d75ecdf,reason=Scheduled count=None msg=Successfully assigned compute/eval-sanitize-40-r4-059-9bxnn to kind-worker3
59.0652,Pod,MODIFIED,eval-sanitize-40-r4-059-9bxnn,phase=Pending node=kind-worker3
59.0833,Job,MODIFIED,eval-sanitize-40-r4-058,
59.0932,Job,MODIFIED,eval-sanitize-40-r4-058,
59.1788,Event,MODIFIED,eval-sanitize-40-r4-058-7z94v.18d40a08d4072dd5,"reason=FailedScheduling count=None msg=0/6 nodes are available: 1 c_wall violated: 1 conflicting context pair(s) with node memory, 5 node(s) had untolerated taint(s). no new claims to deallocate, preemption: 0/6 nodes are available: 1 No preemption victims found for incoming pod, 5 Preemption is not helpful for scheduling."
59.4939,Event,ADDED,eval-sanitize-40-r4-059-9bxnn.18d40a09276f7c84,"reason=Pulled count=1 msg=Container image ""busybox:musl"" already present on machine"
59.5121,Event,ADDED,eval-sanitize-40-r4-059-9bxnn.18d40a0928878e36,reason=Created count=1 msg=Created container: task
59.6136,Event,ADDED,eval-sanitize-40-r4-059-9bxnn.18d40a092e9481f3,reason=Started count=1 msg=Started container task
59.8361,Pod,MODIFIED,eval-sanitize-40-r4-059-9bxnn,phase=Running node=kind-worker3
59.8826,Job,MODIFIED,eval-sanitize-40-r4-046,
59.8868,Job,MODIFIED,eval-sanitize-40-r4-046,
59.8916,Event,ADDED,eval-sanitize-40-r4-046.18d40a093f1af429,reason=Completed count=1 msg=Job completed
59.898,Job,MODIFIED,eval-sanitize-40-r4-046,
59.9015,TaskRequest,MODIFIED,eval-sanitize-40-r4-046,phase=Complete job=None
59.9097,Job,MODIFIED,eval-sanitize-40-r4-046,
60.0156,TaskRequest,ADDED,eval-sanitize-40-r4-000,phase=Complete job=None
60.0158,TaskRequest,ADDED,eval-sanitize-40-r4-001,phase=Complete job=None
60.0158,TaskRequest,ADDED,eval-sanitize-40-r4-002,phase=Complete job=None
60.0186,Pod,ADDED,eval-sanitize-40-r4-000-v4gjb,phase=Succeeded node=kind-worker3
60.0187,TaskRequest,ADDED,eval-sanitize-40-r4-003,phase=Complete job=None
60.0188,TaskRequest,ADDED,eval-sanitize-40-r4-004,phase=Complete job=None
60.0189,TaskRequest,ADDED,eval-sanitize-40-r4-005,phase=Complete job=None
60.0196,Event,ADDED,eval-sanitize-40-r2-010-wfsx6.18d40963574d50a3,"reason=FailedScheduling count=None msg=0/6 nodes are available: 1 c_wall violated: 2 conflicting context pair(s) with node memory, 1 node(s) had untolerated taint(s), 4 c_wall violated: 1 conflicting context pair(s) with node memory. no new claims to deallocate, preemption: 0/6 nodes are available: 1 Preemption is not helpful for scheduling, 5 No preemption victims found for incoming pod."
60.0199,Event,ADDED,eval-sanitize-40-r2-010-wfsx6.18d40963e02671c0,"reason=FailedScheduling count=None msg=0/6 nodes are available: 1 node(s) had untolerated taint(s), 2 c_wall violated: 2 conflicting context pair(s) with node memory, 3 c_wall violated: 1 conflicting context pair(s) with node memory. no new claims to deallocate, preemption: 0/6 nodes are available: 1 Preemption is not helpful for scheduling, 5 No preemption victims found for incoming pod."
60.0201,Event,ADDED,eval-sanitize-40-r2-010-wfsx6.18d40964164d16fb,"reason=FailedScheduling count=None msg=0/6 nodes are available: 1 node(s) had untolerated taint(s), 2 c_wall violated: 1 conflicting context pair(s) with node memory, 3 c_wall violated: 2 conflicting context pair(s) with node memory. no new claims to deallocate, preemption: 0/6 nodes are available: 1 Preemption is not helpful for scheduling, 5 No preemption victims found for incoming pod."
60.0203,TaskRequest,ADDED,eval-sanitize-40-r4-006,phase=Complete job=None
60.0204,TaskRequest,ADDED,eval-sanitize-40-r4-007,phase=Complete job=None
60.0204,TaskRequest,ADDED,eval-sanitize-40-r4-008,phase=Complete job=None
60.0216,Pod,ADDED,eval-sanitize-40-r4-001-vsq9b,phase=Succeeded node=kind-worker5
60.0228,Node,ADDED,kind-control-plane,taints=1
60.0232,Event,ADDED,eval-sanitize-40-r2-010-wfsx6.18d409645208ef55,"reason=FailedScheduling count=None msg=0/6 nodes are available: 1 c_wall violated: 3 conflicting context pair(s) with node memory, 1 node(s) had untolerated taint(s), 2 c_wall violated: 1 conflicting context pair(s) with node memory, 2 c_wall violated: 2 conflicting context pair(s) with node memory. no new claims to deallocate, preemption: 0/6 nodes are available: 1 Preemption is not helpful for scheduling, 5 No preemption victims found for incoming pod."
60.0235,Event,ADDED,eval-sanitize-40-r2-010-wfsx6.18d409658d747ad7,"reason=FailedScheduling count=None msg=0/6 nodes are available: 1 c_wall violated: 2 conflicting context pair(s) with node memory, 2 c_wall violated: 1 conflicting context pair(s) with node memory, 3 node(s) had untolerated taint(s). no new claims to deallocate, preemption: 0/6 nodes are available: 3 No preemption victims found for incoming pod, 3 Preemption is not helpful for scheduling."
60.0237,Event,ADDED,eval-sanitize-40-r2-010-wfsx6.18d4096593e8eea6,"reason=FailedScheduling count=None msg=0/6 nodes are available: 1 c_wall violated: 1 conflicting context pair(s) with node memory, 1 c_wall violated: 2 conflicting context pair(s) with node memory, 4 node(s) had untolerated taint(s). no new claims to deallocate, preemption: 0/6 nodes are available: 2 No preemption victims found for incoming pod, 4 Preemption is not helpful for scheduling."
60.024,TaskRequest,ADDED,eval-sanitize-40-r4-009,phase=Complete job=None
60.024,TaskRequest,ADDED,eval-sanitize-40-r4-010,phase=Complete job=None
60.0254,Pod,ADDED,eval-sanitize-40-r4-002-2rvfm,phase=Succeeded node=kind-worker
60.027,Node,ADDED,kind-worker,taints=1
60.0271,TaskRequest,ADDED,eval-sanitize-40-r4-011,phase=Complete job=None
60.0272,TaskRequest,ADDED,eval-sanitize-40-r4-012,phase=Complete job=None
60.0272,TaskRequest,ADDED,eval-sanitize-40-r4-013,phase=Complete job=None
60.0275,Event,ADDED,eval-sanitize-40-r2-010-wfsx6.18d40965b90a7398,"reason=FailedScheduling count=None msg=0/6 nodes are available: 1 c_wall violated: 1 conflicting context pair(s) with node memory, 5 node(s) had untolerated taint(s). no new claims to deallocate, preemption: 0/6 nodes are available: 1 No preemption victims found for incoming pod, 5 Preemption is not helpful for scheduling."
60.0278,Event,ADDED,eval-sanitize-40-r2-016-st549.18d40964bcb5027d,"reason=FailedScheduling count=None msg=0/6 nodes are available: 1 c_wall violated: 3 conflicting context pair(s) with node memory, 1 node(s) had untolerated taint(s), 2 c_wall violated: 1 conflicting context pair(s) with node memory, 2 c_wall violated: 2 conflicting context pair(s) with node memory. no new claims to deallocate, preemption: 0/6 nodes are available: 1 Preemption is not helpful for scheduling, 5 No preemption victims found for incoming pod."
60.028,Event,ADDED,eval-sanitize-40-r2-016-st549.18d409659393897f,"reason=FailedScheduling count=None msg=0/6 nodes are available: 1 c_wall violated: 1 conflicting context pair(s) with node memory, 1 c_wall violated: 2 conflicting context pair(s) with node memory, 4 node(s) had untolerated taint(s). no new claims to deallocate, preemption: 0/6 nodes are available: 2 No preemption victims found for incoming pod, 4 Preemption is not helpful for scheduling."
60.0289,Job,ADDED,eval-sanitize-40-r4-000,
60.0302,Node,ADDED,kind-worker2,taints=1
60.0303,TaskRequest,ADDED,eval-sanitize-40-r4-014,phase=Complete job=None
60.0304,TaskRequest,ADDED,eval-sanitize-40-r4-015,phase=Complete job=None
60.0305,TaskRequest,ADDED,eval-sanitize-40-r4-016,phase=Complete job=None
60.0314,Event,ADDED,eval-sanitize-40-r2-016-st549.18d40965b8da75ae,"reason=FailedScheduling count=None msg=0/6 nodes are available: 1 c_wall violated: 1 conflicting context pair(s) with node memory, 5 node(s) had untolerated taint(s). no new claims to deallocate, preemption: 0/6 nodes are available: 1 No preemption victims found for incoming pod, 5 Preemption is not helpful for scheduling."
60.0316,Event,ADDED,eval-sanitize-40-r2-020-lwlpx.18d40965a0b13418,"reason=FailedScheduling count=None msg=0/6 nodes are available: 1 c_wall violated: 1 conflicting context pair(s) with node memory, 1 c_wall violated: 2 conflicting context pair(s) with node memory, 4 node(s) had untolerated taint(s). no new claims to deallocate, preemption: 0/6 nodes are available: 2 No preemption victims found for incoming pod, 4 Preemption is not helpful for scheduling."
60.0318,Event,ADDED,eval-sanitize-40-r2-020-lwlpx.18d40965bcfd8642,"reason=FailedScheduling count=None msg=0/6 nodes are available: 1 c_wall violated: 1 conflicting context pair(s) with node memory, 5 node(s) had untolerated taint(s). no new claims to deallocate, preemption: 0/6 nodes are available: 1 No preemption victims found for incoming pod, 5 Preemption is not helpful for scheduling."
60.0319,TaskRequest,ADDED,eval-sanitize-40-r4-017,phase=Complete job=None
60.0319,TaskRequest,ADDED,eval-sanitize-40-r4-018,phase=Complete job=None
60.0331,Pod,ADDED,eval-sanitize-40-r4-003-kgd84,phase=Succeeded node=kind-worker5
60.034,Job,ADDED,eval-sanitize-40-r4-001,
60.0353,Node,ADDED,kind-worker3,taints=0
60.0357,Event,ADDED,eval-sanitize-40-r2-021-mkxpd.18d40965db9ffc90,"reason=FailedScheduling count=None msg=0/6 nodes are available: 1 c_wall violated: 1 conflicting context pair(s) with node memory, 5 node(s) had untolerated taint(s). no new claims to deallocate, preemption: 0/6 nodes are available: 1 No preemption victims found for incoming pod, 5 Preemption is not helpful for scheduling."
60.0359,Event,ADDED,eval-sanitize-40-r2-022-ztmt9.18d4096617ad62f1,"reason=FailedScheduling count=None msg=0/6 nodes are available: 1 c_wall violated: 1 conflicting context pair(s) with node memory, 5 node(s) had untolerated taint(s). no new claims to deallocate, preemption: 0/6 nodes are available: 1 No preemption victims found for incoming pod, 5 Preemption is not helpful for scheduling."
60.036,TaskRequest,ADDED,eval-sanitize-40-r4-019,phase=Complete job=None
60.036,TaskRequest,ADDED,eval-sanitize-40-r4-020,phase=Complete job=None
60.036,TaskRequest,ADDED,eval-sanitize-40-r4-021,phase=Complete job=None
60.0372,Pod,ADDED,eval-sanitize-40-r4-004-85p4k,phase=Succeeded node=kind-worker4
60.0379,Job,ADDED,eval-sanitize-40-r4-002,
60.0383,Event,ADDED,eval-sanitize-40-r2-023-xt99s.18d40966545ab83f,"reason=FailedScheduling count=None msg=0/6 nodes are available: 1 c_wall violated: 1 conflicting context pair(s) with node memory, 5 node(s) had untolerated taint(s). no new claims to deallocate, preemption: 0/6 nodes are available: 1 No preemption victims found for incoming pod, 5 Preemption is not helpful for scheduling."
60.0385,Event,ADDED,eval-sanitize-40-r2-023-xt99s.18d4096747353a23,"reason=FailedScheduling count=None msg=0/6 nodes are available: 1 c_wall violated: 2 conflicting context pair(s) with node memory, 5 node(s) had untolerated taint(s). no new claims to deallocate, preemption: 0/6 nodes are available: 1 No preemption victims found for incoming pod, 5 Preemption is not helpful for scheduling."
60.0387,Event,ADDED,eval-sanitize-40-r2-023-xt99s.18d40968af254d4c,"reason=FailedScheduling count=None msg=0/6 nodes are available: 1 c_wall violated: 3 conflicting context pair(s) with node memory, 5 node(s) had untolerated taint(s). no new claims to deallocate, preemption: 0/6 nodes are available: 1 No preemption victims found for incoming pod, 5 Preemption is not helpful for scheduling."
60.0388,TaskRequest,ADDED,eval-sanitize-40-r4-022,phase=Complete job=None
60.0389,TaskRequest,ADDED,eval-sanitize-40-r4-023,phase=Complete job=None
60.0389,TaskRequest,ADDED,eval-sanitize-40-r4-024,phase=Complete job=None
60.039,TaskRequest,ADDED,eval-sanitize-40-r4-025,phase=Complete job=None
60.0391,TaskRequest,ADDED,eval-sanitize-40-r4-026,phase=Complete job=None
60.0403,Node,ADDED,kind-worker4,taints=1
60.0412,Job,ADDED,eval-sanitize-40-r4-003,
60.0415,Event,ADDED,eval-sanitize-40-r2-024-nhld4.18d409668ea7d40a,"reason=FailedScheduling count=None msg=0/6 nodes are available: 1 c_wall violated: 1 conflicting context pair(s) with node memory, 5 node(s) had untolerated taint(s). no new claims to deallocate, preemption: 0/6 nodes are available: 1 No preemption victims found for incoming pod, 5 Preemption is not helpful for scheduling."
60.0417,Event,ADDED,eval-sanitize-40-r2-025-kmc6x.18d40966ca9bc79d,"reason=FailedScheduling count=None msg=0/6 nodes are available: 1 c_wall violated: 1 conflicting context pair(s) with node memory, 5 node(s) had untolerated taint(s). no new claims to deallocate, preemption: 0/6 nodes are available: 1 No preemption victims found for incoming pod, 5 Preemption is not helpful for scheduling."
60.042,Event,ADDED,eval-sanitize-40-r2-026-6zvzg.18d4096706396b53,"reason=FailedScheduling count=None msg=0/6 nodes are available: 1 c_wall violated: 1 conflicting context pair(s) with node memory, 5 node(s) had untolerated taint(s). no new claims to deallocate, preemption: 0/6 nodes are available: 1 No preemption victims found for incoming pod, 5 Preemption is not helpful for scheduling."
60.0432,Pod,ADDED,eval-sanitize-40-r4-005-5d8sq,phase=Succeeded node=kind-worker2
60.0433,TaskRequest,ADDED,eval-sanitize-40-r4-027,phase=Complete job=None
60.0433,TaskRequest,ADDED,eval-sanitize-40-r4-028,phase=Complete job=None
60.0433,TaskRequest,ADDED,eval-sanitize-40-r4-029,phase=Complete job=None
60.0434,TaskRequest,ADDED,eval-sanitize-40-r4-030,phase=Complete job=None
60.0434,TaskRequest,ADDED,eval-sanitize-40-r4-031,phase=Complete job=None
60.0437,Event,ADDED,eval-sanitize-40-r2-028-r49bh.18d4096780a3a74b,"reason=FailedScheduling count=None msg=0/6 nodes are available: 1 c_wall violated: 1 conflicting context pair(s) with node memory, 5 node(s) had untolerated taint(s). no new claims to deallocate, preemption: 0/6 nodes are available: 1 No preemption victims found for incoming pod, 5 Preemption is not helpful for scheduling."
60.044,Event,ADDED,eval-sanitize-40-r2-028-r49bh.18d40968af76ec14,"reason=FailedScheduling count=None msg=0/6 nodes are available: 1 c_wall violated: 2 conflicting context pair(s) with node memory, 5 node(s) had untolerated taint(s). no new claims to deallocate, preemption: 0/6 nodes are available: 1 No preemption victims found for incoming pod, 5 Preemption is not helpful for scheduling."
60.0443,Event,ADDED,eval-sanitize-40-r2-028-r49bh.18d4096fc5c6c375,"reason=FailedScheduling count=None msg=0/6 nodes are available: 2 c_wall violated: 2 conflicting context pair(s) with node memory, 2 c_wall violated: 3 conflicting context pair(s) with node memory, 2 node(s) had untolerated taint(s). no new claims to deallocate, preemption: 0/6 nodes are available: 2 Preemption is not helpful for scheduling, 4 No preemption victims found for incoming pod."
60.0458,Pod,ADDED,eval-sanitize-40-r4-006-q9nqf,phase=Succeeded node=kind-worker
60.0471,Node,ADDED,kind-worker5,taints=1
60.0481,Job,ADDED,eval-sanitize-40-r4-004,
60.0483,TaskRequest,ADDED,eval-sanitize-40-r4-032,phase=Complete job=None
60.0485,TaskRequest,ADDED,eval-sanitize-40-r4-033,phase=Complete job=None
60.0486,TaskRequest,ADDED,eval-sanitize-40-r4-034,phase=Complete job=None
60.0493,Event,ADDED,eval-sanitize-40-r2-028-r49bh.18d409700de6d170,"reason=FailedScheduling count=None msg=0/6 nodes are available: 1 c_wall violated: 2 conflicting context pair(s) with node memory, 2 node(s) had untolerated taint(s), 3 c_wall violated: 3 conflicting context pair(s) with node memory. no new claims to deallocate, preemption: 0/6 nodes are available: 2 Preemption is not helpful for scheduling, 4 No preemption victims found for incoming pod."
60.0497,Event,ADDED,eval-sanitize-40-r2-028-r49bh.18d40978695666a7,"reason=FailedScheduling count=None msg=0/6 nodes are available: 1 c_wall violated: 3 conflicting context pair(s) with node memory, 5 node(s) had untolerated taint(s). no new claims to deallocate, preemption: 0/6 nodes are available: 1 No preemption victims found for incoming pod, 5 Preemption is not helpful for scheduling."
60.05,Event,ADDED,eval-sanitize-40-r2-028-r49bh.18d40978abf5fae1,"reason=FailedScheduling count=None msg=0/6 nodes are available: 1 c_wall violated: 1 conflicting context pair(s) with node memory, 5 node(s) had untolerated taint(s). no new claims to deallocate, preemption: 0/6 nodes are available: 1 No preemption victims found for incoming pod, 5 Preemption is not helpful for scheduling."
60.0503,TaskRequest,ADDED,eval-sanitize-40-r4-035,phase=Complete job=None
60.0504,TaskRequest,ADDED,eval-sanitize-40-r4-036,phase=Complete job=None
60.0507,Event,ADDED,eval-sanitize-40-r2-030-hmrft.18d40967f55abaed,"reason=FailedScheduling count=None msg=0/6 nodes are available: 1 c_wall violated: 1 conflicting context pair(s) with node memory, 5 node(s) had untolerated taint(s). no new claims to deallocate, preemption: 0/6 nodes are available: 1 No preemption victims found for incoming pod, 5 Preemption is not helpful for scheduling."
60.0513,Event,ADDED,eval-sanitize-40-r2-030-hmrft.18d40968b1f77e42,"reason=FailedScheduling count=None msg=0/6 nodes are available: 1 c_wall violated: 2 conflicting context pair(s) with node memory, 5 node(s) had untolerated taint(s). no new claims to deallocate, preemption: 0/6 nodes are available: 1 No preemption victims found for incoming pod, 5 Preemption is not helpful for scheduling."
60.0528,Pod,ADDED,eval-sanitize-40-r4-007-2bndt,phase=Succeeded node=kind-worker5
60.053,TaskRequest,ADDED,eval-sanitize-40-r4-037,phase=Complete job=None
60.0531,TaskRequest,ADDED,eval-sanitize-40-r4-038,phase=Complete job=None
60.0532,TaskRequest,ADDED,eval-sanitize-40-r4-039,phase=Complete job=None
60.0537,Event,ADDED,eval-sanitize-40-r2-031-78956.18d40968307d03ba,"reason=FailedScheduling count=None msg=0/6 nodes are available: 1 c_wall violated: 1 conflicting context pair(s) with node memory, 5 node(s) had untolerated taint(s). no new claims to deallocate, preemption: 0/6 nodes are available: 1 No preemption victims found for incoming pod, 5 Preemption is not helpful for scheduling."
60.0541,Event,ADDED,eval-sanitize-40-r2-032-kbznk.18d409686b577d41,"reason=FailedScheduling count=None msg=0/6 nodes are available: 1 c_wall violated: 2 conflicting context pair(s) with node memory, 5 node(s) had untolerated taint(s). no new claims to deallocate, preemption: 0/6 nodes are available: 1 No preemption victims found for incoming pod, 5 Preemption is not helpful for scheduling."
60.0543,Event,ADDED,eval-sanitize-40-r2-034-k4szm.18d40968e2a277bd,"reason=FailedScheduling count=None msg=0/6 nodes are available: 1 c_wall violated: 1 conflicting context pair(s) with node memory, 5 node(s) had untolerated taint(s). no new claims to deallocate, preemption: 0/6 nodes are available: 1 No preemption victims found for incoming pod, 5 Preemption is not helpful for scheduling."
60.0554,Job,ADDED,eval-sanitize-40-r4-005,
60.0576,Pod,ADDED,eval-sanitize-40-r4-008-sbdmc,phase=Succeeded node=kind-worker3
60.0577,TaskRequest,ADDED,eval-sanitize-40-r4-040,phase=Scheduled job=None
60.0577,TaskRequest,ADDED,eval-sanitize-40-r4-041,phase=Scheduled job=None
60.0578,TaskRequest,ADDED,eval-sanitize-40-r4-042,phase=Complete job=None
60.0579,TaskRequest,ADDED,eval-sanitize-40-r4-043,phase=Complete job=None
60.0579,TaskRequest,ADDED,eval-sanitize-40-r4-044,phase=Scheduled job=None
60.0591,Job,ADDED,eval-sanitize-40-r4-006,
60.0597,Event,ADDED,eval-sanitize-40-r2-035-9c652.18d409691e2c6960,"reason=FailedScheduling count=None msg=0/6 nodes are available: 1 c_wall violated: 2 conflicting context pair(s) with node memory, 5 node(s) had untolerated taint(s). no new claims to deallocate, preemption: 0/6 nodes are available: 1 No preemption victims found for incoming pod, 5 Preemption is not helpful for scheduling."
60.0601,Event,ADDED,eval-sanitize-40-r2-035-9c652.18d4096fa81d4e0e,"reason=FailedScheduling count=None msg=0/6 nodes are available: 2 c_wall violated: 2 conflicting context pair(s) with node memory, 2 c_wall violated: 3 conflicting context pair(s) with node memory, 2 node(s) had untolerated taint(s). no new claims to deallocate, preemption: 0/6 nodes are available: 2 Preemption is not helpful for scheduling, 4 No preemption victims found for incoming pod."
60.0603,Event,ADDED,eval-sanitize-40-r2-035-9c652.18d4097019651699,"reason=FailedScheduling count=None msg=0/6 nodes are available: 1 c_wall violated: 2 conflicting context pair(s) with node memory, 2 node(s) had untolerated taint(s), 3 c_wall violated: 3 conflicting context pair(s) with node memory. no new claims to deallocate, preemption: 0/6 nodes are available: 2 Preemption is not helpful for scheduling, 4 No preemption victims found for incoming pod."
60.0604,TaskRequest,ADDED,eval-sanitize-40-r4-045,phase=Complete job=None
60.0605,TaskRequest,ADDED,eval-sanitize-40-r4-046,phase=Complete job=None
60.0608,TaskRequest,ADDED,eval-sanitize-40-r4-047,phase=Scheduled job=None
60.0608,TaskRequest,ADDED,eval-sanitize-40-r4-048,phase=Scheduled job=None
60.0609,TaskRequest,ADDED,eval-sanitize-40-r4-049,phase=Scheduled job=None
60.0609,TaskRequest,ADDED,eval-sanitize-40-r4-050,phase=Scheduled job=None
60.0628,Pod,ADDED,eval-sanitize-40-r4-009-zv98g,phase=Succeeded node=kind-worker
60.0636,Job,ADDED,eval-sanitize-40-r4-007,
60.0637,TaskRequest,ADDED,eval-sanitize-40-r4-051,phase=Scheduled job=None
60.0637,TaskRequest,ADDED,eval-sanitize-40-r4-052,phase=Scheduled job=None
60.064,Event,ADDED,eval-sanitize-40-r2-035-9c652.18d4097863ac8417,"reason=FailedScheduling count=None msg=0/6 nodes are available: 1 c_wall violated: 3 conflicting context pair(s) with node memory, 5 node(s) had untolerated taint(s). no new claims to deallocate, preemption: 0/6 nodes are available: 1 No preemption victims found for incoming pod, 5 Preemption is not helpful for scheduling."
60.0643,Event,ADDED,eval-sanitize-40-r2-035-9c652.18d40978ab421c27,"reason=FailedScheduling count=None msg=0/6 nodes are available: 1 c_wall violated: 1 conflicting context pair(s) with node memory, 5 node(s) had untolerated taint(s). no new claims to deallocate, preemption: 0/6 nodes are available: 1 No preemption victims found for incoming pod, 5 Preemption is not helpful for scheduling."
60.0645,Event,ADDED,eval-sanitize-40-r2-038-2wdnv.18d40969d1451f5a,"reason=FailedScheduling count=None msg=0/6 nodes are available: 1 c_wall violated: 2 conflicting context pair(s) with node memory, 5 node(s) had untolerated taint(s). no new claims to deallocate, preemption: 0/6 nodes are available: 1 No preemption victims found for incoming pod, 5 Preemption is not helpful for scheduling."
60.0661,Pod,ADDED,eval-sanitize-40-r4-010-92scj,phase=Succeeded node=kind-worker3
60.0669,Job,ADDED,eval-sanitize-40-r4-008,
60.067,TaskRequest,ADDED,eval-sanitize-40-r4-053,phase=Scheduled job=None
60.067,TaskRequest,ADDED,eval-sanitize-40-r4-054,phase=Scheduled job=None
60.067,TaskRequest,ADDED,eval-sanitize-40-r4-055,phase=Scheduled job=None
60.0673,Event,ADDED,eval-sanitize-40-r2-038-2wdnv.18d4096fb9f1711d,"reason=FailedScheduling count=None msg=0/6 nodes are available: 2 c_wall violated: 2 conflicting context pair(s) with node memory, 2 c_wall violated: 3 conflicting context pair(s) with node memory, 2 node(s) had untolerated taint(s). no new claims to deallocate, preemption: 0/6 nodes are available: 2 Preemption is not helpful for scheduling, 4 No preemption victims found for incoming pod."
60.0676,Event,ADDED,eval-sanitize-40-r2-038-2wdnv.18d40970200e6bf0,"reason=FailedScheduling count=None msg=0/6 nodes are available: 1 c_wall violated: 2 conflicting context pair(s) with node memory, 2 node(s) had untolerated taint(s), 3 c_wall violated: 3 conflicting context pair(s) with node memory. no new claims to deallocate, preemption: 0/6 nodes are available: 2 Preemption is not helpful for scheduling, 4 No preemption victims found for incoming pod."
60.0682,TaskRequest,ADDED,eval-sanitize-40-r4-056,phase=Scheduled job=None
60.0683,TaskRequest,ADDED,eval-sanitize-40-r4-057,phase=Scheduled job=None
60.0683,TaskRequest,ADDED,eval-sanitize-40-r4-058,phase=Scheduled job=None
60.0688,Event,ADDED,eval-sanitize-40-r2-038-2wdnv.18d40978673610ab,"reason=FailedScheduling count=None msg=0/6 nodes are available: 1 c_wall violated: 3 conflicting context pair(s) with node memory, 5 node(s) had untolerated taint(s). no new claims to deallocate, preemption: 0/6 nodes are available: 1 No preemption victims found for incoming pod, 5 Preemption is not helpful for scheduling."
60.0691,Event,ADDED,eval-sanitize-40-r2-038-2wdnv.18d40978ab9a420a,"reason=FailedScheduling count=None msg=0/6 nodes are available: 1 c_wall violated: 1 conflicting context pair(s) with node memory, 5 node(s) had untolerated taint(s). no new claims to deallocate, preemption: 0/6 nodes are available: 1 No preemption victims found for incoming pod, 5 Preemption is not helpful for scheduling."
60.0693,Event,ADDED,eval-sanitize-40-r2-039-qvgxk.18d4096a0dd5280c,"reason=FailedScheduling count=None msg=0/6 nodes are available: 1 c_wall violated: 1 conflicting context pair(s) with node memory, 5 node(s) had untolerated taint(s). no new claims to deallocate, preemption: 0/6 nodes are available: 1 No preemption victims found for incoming pod, 5 Preemption is not helpful for scheduling."
60.071,Pod,ADDED,eval-sanitize-40-r4-011-t2nwq,phase=Succeeded node=kind-worker
60.0721,Job,ADDED,eval-sanitize-40-r4-009,
60.0722,TaskRequest,ADDED,eval-sanitize-40-r4-059,phase=Scheduled job=None
60.0723,TaskRequest,ADDED,eval-sanitize-40-r4-060,phase=None job=None
60.0723,TaskRequest,MODIFIED,eval-sanitize-40-r4-060,phase=Pending job=None
60.0726,Event,ADDED,eval-sanitize-40-r2-040-756vn.18d4096a48a3b83b,"reason=FailedScheduling count=None msg=0/6 nodes are available: 1 c_wall violated: 2 conflicting context pair(s) with node memory, 5 node(s) had untolerated taint(s). no new claims to deallocate, preemption: 0/6 nodes are available: 1 No preemption victims found for incoming pod, 5 Preemption is not helpful for scheduling."
60.0729,Event,ADDED,eval-sanitize-40-r2-041-8nl6j.18d4096a83ec97cb,"reason=FailedScheduling count=None msg=0/6 nodes are available: 1 c_wall violated: 3 conflicting context pair(s) with node memory, 5 node(s) had untolerated taint(s). no new claims to deallocate, preemption: 0/6 nodes are available: 1 No preemption victims found for incoming pod, 5 Preemption is not helpful for scheduling."
60.0731,Event,ADDED,eval-sanitize-40-r2-042-kvmfb.18d4096abfcf88b7,"reason=FailedScheduling count=None msg=0/6 nodes are available: 1 c_wall violated: 2 conflicting context pair(s) with node memory, 5 node(s) had untolerated taint(s). no new claims to deallocate, preemption: 0/6 nodes are available: 1 No preemption victims found for incoming pod, 5 Preemption is not helpful for scheduling."
60.075,Pod,ADDED,eval-sanitize-40-r4-012-vsl8p,phase=Succeeded node=kind-worker5
60.0758,Job,ADDED,eval-sanitize-40-r4-010,
60.0759,TaskRequest,MODIFIED,eval-sanitize-40-r4-060,phase=Scheduled job=None
60.0763,Event,ADDED,eval-sanitize-40-r2-046-28hhw.18d4096baddd1583,"reason=FailedScheduling count=None msg=0/6 nodes are available: 1 c_wall violated: 1 conflicting context pair(s) with node memory, 5 node(s) had untolerated taint(s). no new claims to deallocate, preemption: 0/6 nodes are available: 1 No preemption victims found for incoming pod, 5 Preemption is not helpful for scheduling."
60.0765,Event,ADDED,eval-sanitize-40-r2-048-2rw9n.18d4096c26557961,"reason=FailedScheduling count=None msg=0/6 nodes are available: 1 c_wall violated: 2 conflicting context pair(s) with node memory, 5 node(s) had untolerated taint(s). no new claims to deallocate, preemption: 0/6 nodes are available: 1 No preemption victims found for incoming pod, 5 Preemption is not helpful for scheduling."
60.0767,Event,ADDED,eval-sanitize-40-r2-048-2rw9n.18d4096fa223b425,"reason=FailedScheduling count=None msg=0/6 nodes are available: 2 c_wall violated: 2 conflicting context pair(s) with node memory, 2 c_wall violated: 3 conflicting context pair(s) with node memory, 2 node(s) had untolerated taint(s). no new claims to deallocate, preemption: 0/6 nodes are available: 2 Preemption is not helpful for scheduling, 4 No preemption victims found for incoming pod."
60.0769,TaskRequest,MODIFIED,eval-sanitize-40-r4-060,phase=Scheduled job=None
60.0773,Event,ADDED,eval-sanitize-40-r2-048-2rw9n.18d40970138c4c7a,"reason=FailedScheduling count=None msg=0/6 nodes are available: 1 c_wall violated: 2 conflicting context pair(s) with node memory, 2 node(s) had untolerated taint(s), 3 c_wall violated: 3 conflicting context pair(s) with node memory. no new claims to deallocate, preemption: 0/6 nodes are available: 2 Preemption is not helpful for scheduling, 4 No preemption victims found for incoming pod."
60.0776,Event,ADDED,eval-sanitize-40-r2-048-2rw9n.18d409786300af4b,"reason=FailedScheduling count=None msg=0/6 nodes are available: 1 c_wall violated: 3 conflicting context pair(s) with node memory, 5 node(s) had untolerated taint(s). no new claims to deallocate, preemption: 0/6 nodes are available: 1 No preemption victims found for incoming pod, 5 Preemption is not helpful for scheduling."
60.0778,Event,ADDED,eval-sanitize-40-r2-048-2rw9n.18d40978aabccadd,"reason=FailedScheduling count=None msg=0/6 nodes are available: 1 c_wall violated: 1 conflicting context pair(s) with node memory, 5 node(s) had untolerated taint(s). no new claims to deallocate, preemption: 0/6 nodes are available: 1 No preemption victims found for incoming pod, 5 Preemption is not helpful for scheduling."
60.0791,Pod,ADDED,eval-sanitize-40-r4-013-fhfpc,phase=Succeeded node=kind-worker
60.0799,Job,ADDED,eval-sanitize-40-r4-011,
60.0813,Pod,ADDED,eval-sanitize-40-r4-014-tdhkt,phase=Succeeded node=kind-worker
60.082,Job,ADDED,eval-sanitize-40-r4-012,
60.0823,Event,ADDED,eval-sanitize-40-r2-049-m2pw4.18d4096c60a8c569,"reason=FailedScheduling count=None msg=0/6 nodes are available: 1 c_wall violated: 3 conflicting context pair(s) with node memory, 5 node(s) had untolerated taint(s). no new claims to deallocate, preemption: 0/6 nodes are available: 1 No preemption victims found for incoming pod, 5 Preemption is not helpful for scheduling."
60.0826,Event,ADDED,eval-sanitize-40-r2-050-kjx5l.18d4096c9c4a2134,"reason=FailedScheduling count=None msg=0/6 nodes are available: 1 c_wall violated: 2 conflicting context pair(s) with node memory, 5 node(s) had untolerated taint(s). no new claims to deallocate, preemption: 0/6 nodes are available: 1 No preemption victims found for incoming pod, 5 Preemption is not helpful for scheduling."
60.0831,Event,ADDED,eval-sanitize-40-r2-050-kjx5l.18d4096fbfd2056d,"reason=FailedScheduling count=None msg=0/6 nodes are available: 2 c_wall violated: 2 conflicting context pair(s) with node memory, 2 c_wall violated: 3 conflicting context pair(s) with node memory, 2 node(s) had untolerated taint(s). no new claims to deallocate, preemption: 0/6 nodes are available: 2 Preemption is not helpful for scheduling, 4 No preemption victims found for incoming pod."
60.0834,Event,ADDED,eval-sanitize-40-r2-050-kjx5l.18d4097025f1b111,"reason=FailedScheduling count=None msg=0/6 nodes are available: 1 c_wall violated: 2 conflicting context pair(s) with node memory, 2 node(s) had untolerated taint(s), 3 c_wall violated: 3 conflicting context pair(s) with node memory. no new claims to deallocate, preemption: 0/6 nodes are available: 2 Preemption is not helpful for scheduling, 4 No preemption victims found for incoming pod."
60.0836,Event,ADDED,eval-sanitize-40-r2-050-kjx5l.18d409786928a9e3,"reason=FailedScheduling count=None msg=0/6 nodes are available: 1 c_wall violated: 3 conflicting context pair(s) with node memory, 5 node(s) had untolerated taint(s). no new claims to deallocate, preemption: 0/6 nodes are available: 1 No preemption victims found for incoming pod, 5 Preemption is not helpful for scheduling."
60.0844,Job,ADDED,eval-sanitize-40-r4-013,
60.0854,Pod,ADDED,eval-sanitize-40-r4-015-c4nvv,phase=Succeeded node=kind-worker
60.0867,Pod,ADDED,eval-sanitize-40-r4-016-cczvx,phase=Succeeded node=kind-worker4
60.0874,Job,ADDED,eval-sanitize-40-r4-014,
60.0878,Event,ADDED,eval-sanitize-40-r2-050-kjx5l.18d40978abc7b7c9,"reason=FailedScheduling count=None msg=0/6 nodes are available: 1 c_wall violated: 1 conflicting context pair(s) with node memory, 5 node(s) had untolerated taint(s). no new claims to deallocate, preemption: 0/6 nodes are available: 1 No preemption victims found for incoming pod, 5 Preemption is not helpful for scheduling."
60.088,Event,ADDED,eval-sanitize-40-r2-051-v5b5j.18d4096cd8219599,"reason=FailedScheduling count=None msg=0/6 nodes are available: 1 c_wall violated: 2 conflicting context pair(s) with node memory, 5 node(s) had untolerated taint(s). no new claims to deallocate, preemption: 0/6 nodes are available: 1 No preemption victims found for incoming pod, 5 Preemption is not helpful for scheduling."
60.0883,Event,ADDED,eval-sanitize-40-r2-053-sd4tx.18d4096d502db698,"reason=FailedScheduling count=None msg=0/6 nodes are available: 1 c_wall violated: 1 conflicting context pair(s) with node memory, 5 node(s) had untolerated taint(s). no new claims to deallocate, preemption: 0/6 nodes are available: 1 No preemption victims found for incoming pod, 5 Preemption is not helpful for scheduling."
60.0896,Pod,ADDED,eval-sanitize-40-r4-017-2p92w,phase=Succeeded node=kind-worker5
60.09,Event,ADDED,eval-sanitize-40-r2-054-hbxd4.18d4096d8cce6bd5,"reason=FailedScheduling count=None msg=0/6 nodes are available: 1 c_wall violated: 3 conflicting context pair(s) with node memory, 5 node(s) had untolerated taint(s). no new claims to deallocate, preemption: 0/6 nodes are available: 1 No preemption victims found for incoming pod, 5 Preemption is not helpful for scheduling."
60.0902,Event,ADDED,eval-sanitize-40-r2-055-5mvxk.18d4096dc67adcda,"reason=FailedScheduling count=None msg=0/6 nodes are available: 1 c_wall violated: 2 conflicting context pair(s) with node memory, 5 node(s) had untolerated taint(s). no new claims to deallocate, preemption: 0/6 nodes are available: 1 No preemption victims found for incoming pod, 5 Preemption is not helpful for scheduling."
60.0904,Event,ADDED,eval-sanitize-40-r2-057-f625x.18d4096e3df14112,"reason=FailedScheduling count=None msg=0/6 nodes are available: 1 c_wall violated: 2 conflicting context pair(s) with node memory, 5 node(s) had untolerated taint(s). no new claims to deallocate, preemption: 0/6 nodes are available: 1 No preemption victims found for incoming pod, 5 Preemption is not helpful for scheduling."
60.0912,Job,ADDED,eval-sanitize-40-r4-015,
60.0925,Pod,ADDED,eval-sanitize-40-r4-018-97rrz,phase=Succeeded node=kind-worker5
60.0933,Event,ADDED,eval-sanitize-40-r2-058-k5qmn.18d4096e79d6b7d0,"reason=FailedScheduling count=None msg=0/6 nodes are available: 1 c_wall violated: 1 conflicting context pair(s) with node memory, 5 node(s) had untolerated taint(s). no new claims to deallocate, preemption: 0/6 nodes are available: 1 No preemption victims found for incoming pod, 5 Preemption is not helpful for scheduling."
60.0936,Event,ADDED,eval-sanitize-40-r2-062-v8qrh.18d4096fb40b5f7a,"reason=FailedScheduling count=None msg=0/6 nodes are available: 1 c_wall violated: 2 conflicting context pair(s) with node memory, 2 node(s) had untolerated taint(s), 3 c_wall violated: 3 conflicting context pair(s) with node memory. no new claims to deallocate, preemption: 0/6 nodes are available: 2 Preemption is not helpful for scheduling, 4 No preemption victims found for incoming pod."
60.0944,Job,ADDED,eval-sanitize-40-r4-016,
60.0957,Pod,ADDED,eval-sanitize-40-r4-019-g28rc,phase=Succeeded node=kind-worker5
60.0966,Job,ADDED,eval-sanitize-40-r4-017,
60.0968,Event,ADDED,eval-sanitize-40-r2-062-v8qrh.18d4097863d381a5,"reason=FailedScheduling count=None msg=0/6 nodes are available: 1 c_wall violated: 3 conflicting context pair(s) with node memory, 5 node(s) had untolerated taint(s). no new claims to deallocate, preemption: 0/6 nodes are available: 1 No preemption victims found for incoming pod, 5 Preemption is not helpful for scheduling."
60.0971,Event,ADDED,eval-sanitize-40-r2-074-d96sk.18d409725fc327ed,"reason=FailedScheduling count=None msg=0/6 nodes are available: 1 c_wall violated: 2 conflicting context pair(s) with node memory, 2 node(s) had untolerated taint(s), 3 c_wall violated: 3 conflicting context pair(s) with node memory. no new claims to deallocate, preemption: 0/6 nodes are available: 2 Preemption is not helpful for scheduling, 4 No preemption victims found for incoming pod."
60.0973,Event,ADDED,eval-sanitize-40-r2-074-d96sk.18d40978635d69c0,"reason=FailedScheduling count=None msg=0/6 nodes are available: 1 c_wall violated: 3 conflicting context pair(s) with node memory, 5 node(s) had untolerated taint(s). no new claims to deallocate, preemption: 0/6 nodes are available: 1 No preemption victims found for incoming pod, 5 Preemption is not helpful for scheduling."
60.0985,Pod,ADDED,eval-sanitize-40-r4-020-f8d9v,phase=Succeeded node=kind-worker
60.0993,Job,ADDED,eval-sanitize-40-r4-018,
60.0996,Event,ADDED,eval-sanitize-40-r2-074-d96sk.18d40978ab1660ea,"reason=FailedScheduling count=None msg=0/6 nodes are available: 1 c_wall violated: 1 conflicting context pair(s) with node memory, 5 node(s) had untolerated taint(s). no new claims to deallocate, preemption: 0/6 nodes are available: 1 No preemption victims found for incoming pod, 5 Preemption is not helpful for scheduling."
60.0998,Event,ADDED,eval-sanitize-40-r2-078-l6gvn.18d40973bb145ad5,"reason=FailedScheduling count=None msg=0/6 nodes are available: 1 c_wall violated: 2 conflicting context pair(s) with node memory, 2 node(s) had untolerated taint(s), 3 c_wall violated: 3 conflicting context pair(s) with node memory. no new claims to deallocate, preemption: 0/6 nodes are available: 2 Preemption is not helpful for scheduling, 4 No preemption victims found for incoming pod."
60.1,Event,ADDED,eval-sanitize-40-r2-078-l6gvn.18d4097863333b56,"reason=FailedScheduling count=None msg=0/6 nodes are available: 1 c_wall violated: 3 conflicting context pair(s) with node memory, 5 node(s) had untolerated taint(s). no new claims to deallocate, preemption: 0/6 nodes are available: 1 No preemption victims found for incoming pod, 5 Preemption is not helpful for scheduling."
60.1013,Pod,ADDED,eval-sanitize-40-r4-021-pxtwr,phase=Succeeded node=kind-worker5
60.1016,Event,ADDED,eval-sanitize-40-r2-078-l6gvn.18d40978aaecbeea,"reason=FailedScheduling count=None msg=0/6 nodes are available: 1 c_wall violated: 1 conflicting context pair(s) with node memory, 5 node(s) had untolerated taint(s). no new claims to deallocate, preemption: 0/6 nodes are available: 1 No preemption victims found for incoming pod, 5 Preemption is not helpful for scheduling."
60.1019,Event,ADDED,eval-sanitize-40-r2-085-l9hq2.18d40974fd816872,"reason=FailedScheduling count=None msg=0/6 nodes are available: 1 c_wall violated: 2 conflicting context pair(s) with node memory, 2 node(s) had untolerated taint(s), 3 c_wall violated: 3 conflicting context pair(s) with node memory. no new claims to deallocate, preemption: 0/6 nodes are available: 2 Preemption is not helpful for scheduling, 4 No preemption victims found for incoming pod."
60.1021,Event,ADDED,eval-sanitize-40-r2-085-l9hq2.18d4097863f7022f,"reason=FailedScheduling count=None msg=0/6 nodes are available: 1 c_wall violated: 3 conflicting context pair(s) with node memory, 5 node(s) had untolerated taint(s). no new claims to deallocate, preemption: 0/6 nodes are available: 1 No preemption victims found for incoming pod, 5 Preemption is not helpful for scheduling."
60.1028,Job,ADDED,eval-sanitize-40-r4-019,
60.1065,Pod,ADDED,eval-sanitize-40-r4-022-7m7tt,phase=Succeeded node=kind-worker3
60.1069,Event,ADDED,eval-sanitize-40-r2-085-l9hq2.18d40978ab6bb0ae,"reason=FailedScheduling count=None msg=0/6 nodes are available: 1 c_wall violated: 1 conflicting context pair(s) with node memory, 5 node(s) had untolerated taint(s). no new claims to deallocate, preemption: 0/6 nodes are available: 1 No preemption victims found for incoming pod, 5 Preemption is not helpful for scheduling."
60.1071,Event,ADDED,eval-sanitize-40-r2-088-nf8c8.18d4097597d0ef76,"reason=FailedScheduling count=None msg=0/6 nodes are available: 1 c_wall violated: 2 conflicting context pair(s) with node memory, 2 node(s) had untolerated taint(s), 3 c_wall violated: 3 conflicting context pair(s) with node memory. no new claims to deallocate, preemption: 0/6 nodes are available: 2 Preemption is not helpful for scheduling, 4 No preemption victims found for incoming pod."
60.1079,Job,ADDED,eval-sanitize-40-r4-020,
60.1091,Pod,ADDED,eval-sanitize-40-r4-023-tck4r,phase=Succeeded node=kind-worker2
60.11,Job,ADDED,eval-sanitize-40-r4-021,
60.1105,Event,ADDED,eval-sanitize-40-r2-088-nf8c8.18d409786384d82d,"reason=FailedScheduling count=None msg=0/6 nodes are available: 1 c_wall violated: 3 conflicting context pair(s) with node memory, 5 node(s) had untolerated taint(s). no new claims to deallocate, preemption: 0/6 nodes are available: 1 No preemption victims found for incoming pod, 5 Preemption is not helpful for scheduling."
60.1108,Event,ADDED,eval-sanitize-40-r2-089-hsw77.18d40975f7bae777,"reason=FailedScheduling count=None msg=0/6 nodes are available: 1 c_wall violated: 2 conflicting context pair(s) with node memory, 2 node(s) had untolerated taint(s), 3 c_wall violated: 1 conflicting context pair(s) with node memory. no new claims to deallocate, preemption: 0/6 nodes are available: 2 Preemption is not helpful for scheduling, 4 No preemption victims found for incoming pod."
60.111,Event,ADDED,eval-sanitize-40-r2-089-hsw77.18d40978611959f5,"reason=FailedScheduling count=None msg=0/6 nodes are available: 1 c_wall violated: 1 conflicting context pair(s) with node memory, 5 node(s) had untolerated taint(s). no new claims to deallocate, preemption: 0/6 nodes are available: 1 No preemption victims found for incoming pod, 5 Preemption is not helpful for scheduling."
60.1121,Pod,ADDED,eval-sanitize-40-r4-024-qs8vx,phase=Succeeded node=kind-worker
60.1129,Job,ADDED,eval-sanitize-40-r4-022,
60.1133,Event,ADDED,eval-sanitize-40-r2-090-vqvhv.18d40976391b7d3a,"reason=FailedScheduling count=None msg=0/6 nodes are available: 1 c_wall violated: 2 conflicting context pair(s) with node memory, 2 node(s) had untolerated taint(s), 3 c_wall violated: 3 conflicting context pair(s) with node memory. no new claims to deallocate, preemption: 0/6 nodes are available: 2 Preemption is not helpful for scheduling, 4 No preemption victims found for incoming pod."
60.1135,Event,ADDED,eval-sanitize-40-r2-090-vqvhv.18d4097860e5f952,"reason=FailedScheduling count=None msg=0/6 nodes are available: 1 c_wall violated: 3 conflicting context pair(s) with node memory, 5 node(s) had untolerated taint(s). no new claims to deallocate, preemption: 0/6 nodes are available: 1 No preemption victims found for incoming pod, 5 Preemption is not helpful for scheduling."
60.1137,Event,ADDED,eval-sanitize-40-r2-091-kjr2x.18d409767ab323de,"reason=FailedScheduling count=None msg=0/6 nodes are available: 1 c_wall violated: 2 conflicting context pair(s) with node memory, 2 node(s) had untolerated taint(s), 3 c_wall violated: 3 conflicting context pair(s) with node memory. no new claims to deallocate, preemption: 0/6 nodes are available: 2 Preemption is not helpful for scheduling, 4 No preemption victims found for incoming pod."
60.1141,Event,ADDED,eval-sanitize-40-r2-091-kjr2x.18d4097869a99d22,"reason=FailedScheduling count=None msg=0/6 nodes are available: 1 c_wall violated: 3 conflicting context pair(s) with node memory, 5 node(s) had untolerated taint(s). no new claims to deallocate, preemption: 0/6 nodes are available: 1 No preemption victims found for incoming pod, 5 Preemption is not helpful for scheduling."
60.1143,Event,ADDED,eval-sanitize-40-r2-091-kjr2x.18d40978b0ad7474,"reason=FailedScheduling count=None msg=0/6 nodes are available: 1 c_wall violated: 1 conflicting context pair(s) with node memory, 5 node(s) had untolerated taint(s). no new claims to deallocate, preemption: 0/6 nodes are available: 1 No preemption victims found for incoming pod, 5 Preemption is not helpful for scheduling."
60.1145,Event,ADDED,eval-sanitize-40-r2-096-99gz6.18d40977b64a6277,"reason=FailedScheduling count=None msg=0/6 nodes are available: 1 c_wall violated: 2 conflicting context pair(s) with node memory, 2 node(s) had untolerated taint(s), 3 c_wall violated: 3 conflicting context pair(s) with node memory. no new claims to deallocate, preemption: 0/6 nodes are available: 2 Preemption is not helpful for scheduling, 4 No preemption victims found for incoming pod."
60.1158,Job,ADDED,eval-sanitize-40-r4-023,
60.1169,Pod,ADDED,eval-sanitize-40-r4-025-d52pp,phase=Succeeded node=kind-worker
60.1173,Event,ADDED,eval-sanitize-40-r2-096-99gz6.18d40978697c4398,"reason=FailedScheduling count=None msg=0/6 nodes are available: 1 c_wall violated: 3 conflicting context pair(s) with node memory, 5 node(s) had untolerated taint(s). no new claims to deallocate, preemption: 0/6 nodes are available: 1 No preemption victims found for incoming pod, 5 Preemption is not helpful for scheduling."
60.1175,Event,ADDED,eval-sanitize-40-r2-097-vhcrh.18d40977fbcad898,"reason=FailedScheduling count=None msg=0/6 nodes are available: 1 c_wall violated: 2 conflicting context pair(s) with node memory, 2 node(s) had untolerated taint(s), 3 c_wall violated: 1 conflicting context pair(s) with node memory. no new claims to deallocate, preemption: 0/6 nodes are available: 2 Preemption is not helpful for scheduling, 4 No preemption victims found for incoming pod."
60.1183,Job,ADDED,eval-sanitize-40-r4-024,
60.1194,Pod,ADDED,eval-sanitize-40-r4-026-8vj8k,phase=Succeeded node=kind-worker3
60.1198,Event,ADDED,eval-sanitize-40-r2-097-vhcrh.18d40978641e920c,"reason=FailedScheduling count=None msg=0/6 nodes are available: 1 c_wall violated: 1 conflicting context pair(s) with node memory, 5 node(s) had untolerated taint(s). no new claims to deallocate, preemption: 0/6 nodes are available: 1 No preemption victims found for incoming pod, 5 Preemption is not helpful for scheduling."
60.12,Event,ADDED,eval-sanitize-40-r4-000-v4gjb.18d409fb52920762,reason=Scheduled count=None msg=Successfully assigned compute/eval-sanitize-40-r4-000-v4gjb to kind-worker3
60.1202,Event,ADDED,eval-sanitize-40-r4-000-v4gjb.18d409fb6c5d4d66,"reason=Pulled count=1 msg=Container image ""busybox:musl"" already present on machine"
60.1203,Event,ADDED,eval-sanitize-40-r4-000-v4gjb.18d409fb6d711c8a,reason=Created count=1 msg=Created container: task
60.1207,Event,ADDED,eval-sanitize-40-r4-000-v4gjb.18d409fb71900b1b,reason=Started count=1 msg=Started container task
60.1209,Event,ADDED,eval-sanitize-40-r4-000.18d409fb51b558fb,reason=SuccessfulCreate count=1 msg=Created pod: eval-sanitize-40-r4-000-v4gjb
60.1211,Event,ADDED,eval-sanitize-40-r4-000.18d409fe82eb6b28,reason=Completed count=1 msg=Job completed
60.1213,Event,ADDED,eval-sanitize-40-r4-001-vsq9b.18d409fb8bffe537,reason=Scheduled count=None msg=Successfully assigned compute/eval-sanitize-40-r4-001-vsq9b to kind-worker5
60.1221,Job,ADDED,eval-sanitize-40-r4-025,
60.1224,Event,ADDED,eval-sanitize-40-r4-001-vsq9b.18d409fba4b9604d,"reason=Pulled count=1 msg=Container image ""busybox:musl"" already present on machine"
60.1227,Event,ADDED,eval-sanitize-40-r4-001-vsq9b.18d409fba6403805,reason=Created count=1 msg=Created container: task
60.1229,Event,ADDED,eval-sanitize-40-r4-001-vsq9b.18d409fba84a5167,reason=Started count=1 msg=Started container task
60.1238,Job,ADDED,eval-sanitize-40-r4-026,
60.125,Pod,ADDED,eval-sanitize-40-r4-027-x2p67,phase=Succeeded node=kind-worker3
60.1253,Event,ADDED,eval-sanitize-40-r4-001.18d409fb8b76829a,reason=SuccessfulCreate count=1 msg=Created pod: eval-sanitize-40-r4-001-vsq9b
60.1255,Event,ADDED,eval-sanitize-40-r4-001.18d409fec6db2f6e,reason=Completed count=1 msg=Job completed
60.1257,Event,ADDED,eval-sanitize-40-r4-002-2rvfm.18d409fbc8a7090e,reason=Scheduled count=None msg=Successfully assigned compute/eval-sanitize-40-r4-002-2rvfm to kind-worker
60.1259,Event,ADDED,eval-sanitize-40-r4-002-2rvfm.18d409fbe2ba33d8,"reason=Pulled count=1 msg=Container image ""busybox:musl"" already present on machine"
60.1261,Event,ADDED,eval-sanitize-40-r4-002-2rvfm.18d409fbe3f94a90,reason=Created count=1 msg=Created container: task
60.1263,Event,ADDED,eval-sanitize-40-r4-002-2rvfm.18d409fbe9173837,reason=Started count=1 msg=Started container task
60.1265,Event,ADDED,eval-sanitize-40-r4-002.18d409fbc787eea0,reason=SuccessfulCreate count=1 msg=Created pod: eval-sanitize-40-r4-002-2rvfm
60.1267,Event,ADDED,eval-sanitize-40-r4-002.18d409ff07e65fae,reason=Completed count=1 msg=Job completed
60.1275,Job,ADDED,eval-sanitize-40-r4-027,
60.1287,Pod,ADDED,eval-sanitize-40-r4-028-nxm9c,phase=Succeeded node=kind-worker4
60.129,Event,ADDED,eval-sanitize-40-r4-003-kgd84.18d409fc046034f8,reason=Scheduled count=None msg=Successfully assigned compute/eval-sanitize-40-r4-003-kgd84 to kind-worker5
60.1292,Event,ADDED,eval-sanitize-40-r4-003-kgd84.18d409fc1e942ace,"reason=Pulled count=1 msg=Container image ""busybox:musl"" already present on machine"
60.1294,Event,ADDED,eval-sanitize-40-r4-003-kgd84.18d409fc1fbff025,reason=Created count=1 msg=Created container: task
60.1302,Job,ADDED,eval-sanitize-40-r4-028,
60.1305,Event,ADDED,eval-sanitize-40-r4-003-kgd84.18d409fc23d5cf55,reason=Started count=1 msg=Started container task
60.1307,Event,ADDED,eval-sanitize-40-r4-003.18d409fc0342ca9c,reason=SuccessfulCreate count=1 msg=Created pod: eval-sanitize-40-r4-003-kgd84
60.1309,Event,ADDED,eval-sanitize-40-r4-003.18d409ff43a142c7,reason=Completed count=1 msg=Job completed
60.1311,Event,ADDED,eval-sanitize-40-r4-004-85p4k.18d409fc4023070a,reason=Scheduled count=None msg=Successfully assigned compute/eval-sanitize-40-r4-004-85p4k to kind-worker4
60.1324,Pod,ADDED,eval-sanitize-40-r4-029-gbx8m,phase=Succeeded node=kind-worker
60.1326,Event,ADDED,eval-sanitize-40-r4-004-85p4k.18d409fc5a3d7b5c,"reason=Pulled count=1 msg=Container image ""busybox:musl"" already present on machine"
60.1329,Event,ADDED,eval-sanitize-40-r4-004-85p4k.18d409fc5baac10a,reason=Created count=1 msg=Created container: task
60.1331,Event,ADDED,eval-sanitize-40-r4-004-85p4k.18d409fc60234c30,reason=Started count=1 msg=Started container task
60.1334,Event,ADDED,eval-sanitize-40-r4-004.18d409fc3f47cb32,reason=SuccessfulCreate count=1 msg=Created pod: eval-sanitize-40-r4-004-85p4k
60.1342,Job,ADDED,eval-sanitize-40-r4-029,
60.1355,Pod,ADDED,eval-sanitize-40-r4-030-kgdr2,phase=Succeeded node=kind-worker5
60.1358,Event,ADDED,eval-sanitize-40-r4-004.18d409ff747f8252,reason=Completed count=1 msg=Job completed
60.136,Event,ADDED,eval-sanitize-40-r4-005-5d8sq.18d409fc7ae84c7d,reason=Scheduled count=None msg=Successfully assigned compute/eval-sanitize-40-r4-005-5d8sq to kind-worker2
60.1362,Event,ADDED,eval-sanitize-40-r4-005-5d8sq.18d409fc94fc60f3,"reason=Pulled count=1 msg=Container image ""busybox:musl"" already present on machine"
60.1373,Job,ADDED,eval-sanitize-40-r4-030,
60.1386,Job,ADDED,eval-sanitize-40-r4-031,
60.1389,Event,ADDED,eval-sanitize-40-r4-005-5d8sq.18d409fc9606ef31,reason=Created count=1 msg=Created container: task
60.1391,Event,ADDED,eval-sanitize-40-r4-005-5d8sq.18d409fc97da1422,reason=Started count=1 msg=Started container task
60.1393,Event,ADDED,eval-sanitize-40-r4-005.18d409fc79e7e727,reason=SuccessfulCreate count=1 msg=Created pod: eval-sanitize-40-r4-005-5d8sq
60.1395,Event,ADDED,eval-sanitize-40-r4-005.18d409ffd5cabbf4,reason=Completed count=1 msg=Job completed
60.1403,Pod,ADDED,eval-sanitize-40-r4-031-lf45v,phase=Succeeded node=kind-worker5
60.1411,Job,ADDED,eval-sanitize-40-r4-032,
60.1413,Event,ADDED,eval-sanitize-40-r4-006-q9nqf.18d409fcb6d1a031,reason=Scheduled count=None msg=Successfully assigned compute/eval-sanitize-40-r4-006-q9nqf to kind-worker
60.1416,Event,ADDED,eval-sanitize-40-r4-006-q9nqf.18d409fccffaf066,"reason=Pulled count=1 msg=Container image ""busybox:musl"" already present on machine"
60.1418,Event,ADDED,eval-sanitize-40-r4-006-q9nqf.18d409fcd1032b5c,reason=Created count=1 msg=Created container: task
60.1421,Event,ADDED,eval-sanitize-40-r4-006-q9nqf.18d409fcd4e05d4c,reason=Started count=1 msg=Started container task
60.1432,Pod,ADDED,eval-sanitize-40-r4-032-9r59c,phase=Succeeded node=kind-worker
60.1437,Event,ADDED,eval-sanitize-40-r4-006.18d409fcb57d47d1,reason=SuccessfulCreate count=1 msg=Created pod: eval-sanitize-40-r4-006-q9nqf
60.1442,Event,ADDED,eval-sanitize-40-r4-006.18d409fff24c031e,reason=Completed count=1 msg=Job completed
60.1445,Event,ADDED,eval-sanitize-40-r4-007-2bndt.18d409fcf2477925,reason=Scheduled count=None msg=Successfully assigned compute/eval-sanitize-40-r4-007-2bndt to kind-worker5
60.1459,Pod,ADDED,eval-sanitize-40-r4-033-9d9p7,phase=Succeeded node=kind-worker5
60.1462,Event,ADDED,eval-sanitize-40-r4-007-2bndt.18d409fd0b4aba51,"reason=Pulled count=1 msg=Container image ""busybox:musl"" already present on machine"
60.1464,Event,ADDED,eval-sanitize-40-r4-007-2bndt.18d409fd0c7431b4,reason=Created count=1 msg=Created container: task
60.1466,Event,ADDED,eval-sanitize-40-r4-007-2bndt.18d409fd0eff5229,reason=Started count=1 msg=Started container task
60.1468,Event,ADDED,eval-sanitize-40-r4-007.18d409fcf0da7630,reason=SuccessfulCreate count=1 msg=Created pod: eval-sanitize-40-r4-007-2bndt
60.1475,Job,ADDED,eval-sanitize-40-r4-033,
60.1487,Pod,ADDED,eval-sanitize-40-r4-034-qwc55,phase=Succeeded node=kind-worker
60.1493,Event,ADDED,eval-sanitize-40-r4-007.18d40a002c74538d,reason=Completed count=1 msg=Job completed
60.1495,Event,ADDED,eval-sanitize-40-r4-008-sbdmc.18d409fd3009ca31,"reason=FailedScheduling count=None msg=0/6 nodes are available: 1 c_wall violated: 2 conflicting context pair(s) with node memory, 2 node(s) had untolerated taint(s), 3 c_wall violated: 1 conflicting context pair(s) with node memory. no new claims to deallocate, preemption: 0/6 nodes are available: 2 Preemption is not helpful for scheduling, 4 No preemption victims found for incoming pod."
60.1498,Event,ADDED,eval-sanitize-40-r4-008-sbdmc.18d409fd33b63bed,"reason=FailedScheduling count=None msg=0/6 nodes are available: 1 c_wall violated: 2 conflicting context pair(s) with node memory, 2 node(s) had untolerated taint(s), 3 c_wall violated: 1 conflicting context pair(s) with node memory. no new claims to deallocate, preemption: 0/6 nodes are available: 2 Preemption is not helpful for scheduling, 4 No preemption victims found for incoming pod."
60.1505,Job,ADDED,eval-sanitize-40-r4-034,
60.1509,Event,ADDED,eval-sanitize-40-r4-008-sbdmc.18d409ff252644d8,"reason=FailedScheduling count=None msg=0/6 nodes are available: 2 c_wall violated: 1 conflicting context pair(s) with node memory, 2 c_wall violated: 2 conflicting context pair(s) with node memory, 2 node(s) had untolerated taint(s). no new claims to deallocate, preemption: 0/6 nodes are available: 2 Preemption is not helpful for scheduling, 4 No preemption victims found for incoming pod."
60.1511,Event,ADDED,eval-sanitize-40-r4-008-sbdmc.18d409ffdd96d95f,"reason=FailedScheduling count=None msg=0/6 nodes are available: 1 c_wall violated: 2 conflicting context pair(s) with node memory, 1 c_wall violated: 3 conflicting context pair(s) with node memory, 2 c_wall violated: 1 conflicting context pair(s) with node memory, 2 node(s) had untolerated taint(s). no new claims to deallocate, preemption: 0/6 nodes are available: 2 Preemption is not helpful for scheduling, 4 No preemption victims found for incoming pod."
60.1514,Event,ADDED,eval-sanitize-40-r4-008-sbdmc.18d40a00cc608b26,"reason=FailedScheduling count=None msg=0/6 nodes are available: 1 c_wall violated: 1 conflicting context pair(s) with node memory, 1 c_wall violated: 3 conflicting context pair(s) with node memory, 2 c_wall violated: 2 conflicting context pair(s) with node memory, 2 node(s) had untolerated taint(s). no new claims to deallocate, preemption: 0/6 nodes are available: 2 Preemption is not helpful for scheduling, 4 No preemption victims found for incoming pod."
60.1516,Event,ADDED,eval-sanitize-40-r4-008-sbdmc.18d40a03324d7a01,"reason=FailedScheduling count=None msg=0/6 nodes are available: 1 c_wall violated: 1 conflicting context pair(s) with node memory, 1 c_wall violated: 4 conflicting context pair(s) with node memory, 2 c_wall violated: 2 conflicting context pair(s) with node memory, 2 node(s) had untolerated taint(s). no new claims to deallocate, preemption: 0/6 nodes are available: 2 Preemption is not helpful for scheduling, 4 No preemption victims found for incoming pod."
60.1519,Event,ADDED,eval-sanitize-40-r4-008-sbdmc.18d40a0459d63f1b,"reason=FailedScheduling count=None msg=0/6 nodes are available: 1 c_wall violated: 2 conflicting context pair(s) with node memory, 1 c_wall violated: 4 conflicting context pair(s) with node memory, 4 node(s) had untolerated taint(s). no new claims to deallocate, preemption: 0/6 nodes are available: 2 No preemption victims found for incoming pod, 4 Preemption is not helpful for scheduling."
60.1531,Pod,ADDED,eval-sanitize-40-r4-035-8pwgh,phase=Succeeded node=kind-worker
60.1539,Job,ADDED,eval-sanitize-40-r4-035,
60.1542,Event,ADDED,eval-sanitize-40-r4-008-sbdmc.18d40a0467ea1d43,"reason=FailedScheduling count=None msg=0/6 nodes are available: 1 c_wall violated: 4 conflicting context pair(s) with node memory, 5 node(s) had untolerated taint(s). no new claims to deallocate, preemption: 0/6 nodes are available: 1 No preemption victims found for incoming pod, 5 Preemption is not helpful for scheduling."
60.1545,Event,ADDED,eval-sanitize-40-r4-008-sbdmc.18d40a04b5d93f6d,reason=Scheduled count=None msg=Successfully assigned compute/eval-sanitize-40-r4-008-sbdmc to kind-worker3
60.1547,Event,ADDED,eval-sanitize-40-r4-008-sbdmc.18d40a04dc0656ec,"reason=Pulled count=1 msg=Container image ""busybox:musl"" already present on machine"
60.1549,Event,ADDED,eval-sanitize-40-r4-008-sbdmc.18d40a04df2f4c81,reason=Created count=1 msg=Created container: task
60.156,Pod,ADDED,eval-sanitize-40-r4-036-btf8v,phase=Succeeded node=kind-worker5
60.157,Job,ADDED,eval-sanitize-40-r4-036,
60.1574,Event,ADDED,eval-sanitize-40-r4-008-sbdmc.18d40a04e3a9a946,reason=Started count=1 msg=Started container task
60.1576,Event,ADDED,eval-sanitize-40-r4-008.18d409fd2ce1a306,reason=SuccessfulCreate count=1 msg=Created pod: eval-sanitize-40-r4-008-sbdmc
60.1578,Event,ADDED,eval-sanitize-40-r4-008.18d40a08190f804a,reason=Completed count=1 msg=Job completed
60.1579,Event,ADDED,eval-sanitize-40-r4-009-zv98g.18d409fd6993ce74,reason=Scheduled count=None msg=Successfully assigned compute/eval-sanitize-40-r4-009-zv98g to kind-worker
60.1582,Event,ADDED,eval-sanitize-40-r4-009-zv98g.18d409fd83c4a368,"reason=Pulled count=1 msg=Container image ""busybox:musl"" already present on machine"
60.1584,Event,ADDED,eval-sanitize-40-r4-009-zv98g.18d409fd84e0c64f,reason=Created count=1 msg=Created container: task
60.1586,Event,ADDED,eval-sanitize-40-r4-009-zv98g.18d409fd86faf0b0,reason=Started count=1 msg=Started container task
60.1594,Job,ADDED,eval-sanitize-40-r4-037,
60.1598,Event,ADDED,eval-sanitize-40-r4-009.18d409fd68268a88,reason=SuccessfulCreate count=1 msg=Created pod: eval-sanitize-40-r4-009-zv98g
60.16,Event,ADDED,eval-sanitize-40-r4-009.18d40a00aa1dec3a,reason=Completed count=1 msg=Job completed
60.1601,Event,ADDED,eval-sanitize-40-r4-010-92scj.18d409fda7328cef,"reason=FailedScheduling count=None msg=0/6 nodes are available: 1 c_wall violated: 2 conflicting context pair(s) with node memory, 2 node(s) had untolerated taint(s), 3 c_wall violated: 1 conflicting context pair(s) with node memory. no new claims to deallocate, preemption: 0/6 nodes are available: 2 Preemption is not helpful for scheduling, 4 No preemption victims found for incoming pod."
60.1618,Pod,ADDED,eval-sanitize-40-r4-037-dhckp,phase=Succeeded node=kind-worker2
60.1628,Pod,ADDED,eval-sanitize-40-r4-038-k6lc5,phase=Succeeded node=kind-worker4
60.1632,Event,ADDED,eval-sanitize-40-r4-010-92scj.18d409fdab59ae38,"reason=FailedScheduling count=None msg=0/6 nodes are available: 1 c_wall violated: 2 conflicting context pair(s) with node memory, 2 node(s) had untolerated taint(s), 3 c_wall violated: 1 conflicting context pair(s) with node memory. no new claims to deallocate, preemption: 0/6 nodes are available: 2 Preemption is not helpful for scheduling, 4 No preemption victims found for incoming pod."
60.1634,Event,ADDED,eval-sanitize-40-r4-010-92scj.18d409ff1f4c5f90,"reason=FailedScheduling count=None msg=0/6 nodes are available: 2 c_wall violated: 1 conflicting context pair(s) with node memory, 2 c_wall violated: 2 conflicting context pair(s) with node memory, 2 node(s) had untolerated taint(s). no new claims to deallocate, preemption: 0/6 nodes are available: 2 Preemption is not helpful for scheduling, 4 No preemption victims found for incoming pod."
60.1637,Event,ADDED,eval-sanitize-40-r4-010-92scj.18d409ffe373c30c,"reason=FailedScheduling count=None msg=0/6 nodes are available: 1 c_wall violated: 2 conflicting context pair(s) with node memory, 1 c_wall violated: 3 conflicting context pair(s) with node memory, 2 c_wall violated: 1 conflicting context pair(s) with node memory, 2 node(s) had untolerated taint(s). no new claims to deallocate, preemption: 0/6 nodes are available: 2 Preemption is not helpful for scheduling, 4 No preemption victims found for incoming pod."
60.1645,Job,ADDED,eval-sanitize-40-r4-038,
60.1649,Event,ADDED,eval-sanitize-40-r4-010-92scj.18d40a00c688a892,"reason=FailedScheduling count=None msg=0/6 nodes are available: 1 c_wall violated: 1 conflicting context pair(s) with node memory, 1 c_wall violated: 3 conflicting context pair(s) with node memory, 2 c_wall violated: 2 conflicting context pair(s) with node memory, 2 node(s) had untolerated taint(s). no new claims to deallocate, preemption: 0/6 nodes are available: 2 Preemption is not helpful for scheduling, 4 No preemption victims found for incoming pod."
60.1651,Event,ADDED,eval-sanitize-40-r4-010-92scj.18d40a0325dec0a1,"reason=FailedScheduling count=None msg=0/6 nodes are available: 1 c_wall violated: 1 conflicting context pair(s) with node memory, 1 c_wall violated: 4 conflicting context pair(s) with node memory, 2 c_wall violated: 2 conflicting context pair(s) with node memory, 2 node(s) had untolerated taint(s). no new claims to deallocate, preemption: 0/6 nodes are available: 2 Preemption is not helpful for scheduling, 4 No preemption victims found for incoming pod."
60.1653,Event,ADDED,eval-sanitize-40-r4-010-92scj.18d40a0453f23a00,"reason=FailedScheduling count=None msg=0/6 nodes are available: 1 c_wall violated: 2 conflicting context pair(s) with node memory, 1 c_wall violated: 4 conflicting context pair(s) with node memory, 4 node(s) had untolerated taint(s). no new claims to deallocate, preemption: 0/6 nodes are available: 2 No preemption victims found for incoming pod, 4 Preemption is not helpful for scheduling."
60.1667,Pod,ADDED,eval-sanitize-40-r4-039-x7df5,phase=Succeeded node=kind-worker3
60.1671,Event,ADDED,eval-sanitize-40-r4-010-92scj.18d40a045c202639,"reason=FailedScheduling count=None msg=0/6 nodes are available: 1 c_wall violated: 2 conflicting context pair(s) with node memory, 1 c_wall violated: 4 conflicting context pair(s) with node memory, 4 node(s) had untolerated taint(s). no new claims to deallocate, preemption: 0/6 nodes are available: 2 No preemption victims found for incoming pod, 4 Preemption is not helpful for scheduling."
60.1674,Event,ADDED,eval-sanitize-40-r4-010-92scj.18d40a04686e42c4,"reason=FailedScheduling count=None msg=0/6 nodes are available: 1 c_wall violated: 4 conflicting context pair(s) with node memory, 5 node(s) had untolerated taint(s). no new claims to deallocate, preemption: 0/6 nodes are available: 1 No preemption victims found for incoming pod, 5 Preemption is not helpful for scheduling."
60.1676,Event,ADDED,eval-sanitize-40-r4-010-92scj.18d40a04b6930dd6,reason=Scheduled count=None msg=Successfully assigned compute/eval-sanitize-40-r4-010-92scj to kind-worker3
60.1687,Job,ADDED,eval-sanitize-40-r4-039,
60.1697,Pod,ADDED,eval-sanitize-40-r4-040-d5rbc,phase=Pending node=None
60.1701,Event,ADDED,eval-sanitize-40-r4-010-92scj.18d40a04dc75c8c9,"reason=Pulled count=1 msg=Container image ""busybox:musl"" already present on machine"
60.1703,Event,ADDED,eval-sanitize-40-r4-010-92scj.18d40a04e2406a5a,reason=Created count=1 msg=Created container: task
60.1705,Event,ADDED,eval-sanitize-40-r4-010-92scj.18d40a04e57594fe,reason=Started count=1 msg=Started container task
60.1712,Job,ADDED,eval-sanitize-40-r4-040,
60.1715,Event,ADDED,eval-sanitize-40-r4-010.18d409fda3a261ba,reason=SuccessfulCreate count=1 msg=Created pod: eval-sanitize-40-r4-010-92scj
60.1717,Event,ADDED,eval-sanitize-40-r4-010.18d40a0818e55291,reason=Completed count=1 msg=Job completed
60.1719,Event,ADDED,eval-sanitize-40-r4-011-t2nwq.18d409fde0dcc6b4,reason=Scheduled count=None msg=Successfully assigned compute/eval-sanitize-40-r4-011-t2nwq to kind-worker
60.1721,Event,ADDED,eval-sanitize-40-r4-011-t2nwq.18d409fdfb592aec,"reason=Pulled count=1 msg=Container image ""busybox:musl"" already present on machine"
60.1728,Pod,ADDED,eval-sanitize-40-r4-041-lgn9n,phase=Pending node=None
60.1735,Job,ADDED,eval-sanitize-40-r4-041,
60.1738,Event,ADDED,eval-sanitize-40-r4-011-t2nwq.18d409fdfc81bb5b,reason=Created count=1 msg=Created container: task
60.174,Event,ADDED,eval-sanitize-40-r4-011-t2nwq.18d409fe039450e7,reason=Started count=1 msg=Started container task
60.1742,Event,ADDED,eval-sanitize-40-r4-011.18d409fddfa28808,reason=SuccessfulCreate count=1 msg=Created pod: eval-sanitize-40-r4-011-t2nwq
60.1743,Event,ADDED,eval-sanitize-40-r4-011.18d40a01262f68ad,reason=Completed count=1 msg=Job completed
60.1754,Pod,ADDED,eval-sanitize-40-r4-042-pc6tp,phase=Succeeded node=kind-worker3
60.1763,Job,ADDED,eval-sanitize-40-r4-042,
60.1766,Event,ADDED,eval-sanitize-40-r4-012-vsl8p.18d409fe25930d55,reason=Scheduled count=None msg=Successfully assigned compute/eval-sanitize-40-r4-012-vsl8p to kind-worker5
60.1768,Event,ADDED,eval-sanitize-40-r4-012-vsl8p.18d409fe3fce08b2,"reason=Pulled count=1 msg=Container image ""busybox:musl"" already present on machine"
60.177,Event,ADDED,eval-sanitize-40-r4-012-vsl8p.18d409fe40e42f0d,reason=Created count=1 msg=Created container: task
60.1781,Pod,ADDED,eval-sanitize-40-r4-043-hmb2v,phase=Succeeded node=kind-worker3
60.1792,Job,ADDED,eval-sanitize-40-r4-043,
60.1795,Event,ADDED,eval-sanitize-40-r4-012-vsl8p.18d409fe46cc5d7f,reason=Started count=1 msg=Started container task
60.1797,Event,ADDED,eval-sanitize-40-r4-012.18d409fe1b59d1b8,reason=SuccessfulCreate count=1 msg=Created pod: eval-sanitize-40-r4-012-vsl8p
60.1799,Event,ADDED,eval-sanitize-40-r4-012.18d40a01573c0741,reason=Completed count=1 msg=Job completed
60.18,Event,ADDED,eval-sanitize-40-r4-013-fhfpc.18d409fe5fa08353,reason=Scheduled count=None msg=Successfully assigned compute/eval-sanitize-40-r4-013-fhfpc to kind-worker
60.1809,Pod,ADDED,eval-sanitize-40-r4-044-c77pq,phase=Pending node=None
60.1815,Job,ADDED,eval-sanitize-40-r4-044,
60.1818,Event,ADDED,eval-sanitize-40-r4-013-fhfpc.18d409fe7b2bffa9,"reason=Pulled count=1 msg=Container image ""busybox:musl"" already present on machine"
60.182,Event,ADDED,eval-sanitize-40-r4-013-fhfpc.18d409fe7c407b3b,reason=Created count=1 msg=Created container: task
60.1822,Event,ADDED,eval-sanitize-40-r4-013-fhfpc.18d409fe81f8159b,reason=Started count=1 msg=Started container task
60.1824,Event,ADDED,eval-sanitize-40-r4-013.18d409fe565f0c16,reason=SuccessfulCreate count=1 msg=Created pod: eval-sanitize-40-r4-013-fhfpc
60.1827,Event,ADDED,eval-sanitize-40-r4-013.18d40a015981e30c,reason=Completed count=1 msg=Job completed
60.1829,Event,ADDED,eval-sanitize-40-r4-014-tdhkt.18d409fe9ffc521f,reason=Scheduled count=None msg=Successfully assigned compute/eval-sanitize-40-r4-014-tdhkt to kind-worker
60.1831,Event,ADDED,eval-sanitize-40-r4-014-tdhkt.18d409febb684ca6,"reason=Pulled count=1 msg=Container image ""busybox:musl"" already present on machine"
60.1833,Event,ADDED,eval-sanitize-40-r4-014-tdhkt.18d409febcc3ea03,reason=Created count=1 msg=Created container: task
60.1835,Event,ADDED,eval-sanitize-40-r4-014-tdhkt.18d409fec04ed1d6,reason=Started count=1 msg=Started container task
60.1837,Event,ADDED,eval-sanitize-40-r4-014.18d409fe95d0a614,reason=SuccessfulCreate count=1 msg=Created pod: eval-sanitize-40-r4-014-tdhkt
60.1839,Event,ADDED,eval-sanitize-40-r4-014.18d40a01d1fdf70d,reason=Completed count=1 msg=Job completed
60.1851,Pod,ADDED,eval-sanitize-40-r4-045-tz6l6,phase=Succeeded node=kind-worker3
60.1859,Job,ADDED,eval-sanitize-40-r4-045,
60.1862,Event,ADDED,eval-sanitize-40-r4-015-c4nvv.18d409fed356790e,reason=Scheduled count=None msg=Successfully assigned compute/eval-sanitize-40-r4-015-c4nvv to kind-worker
60.1864,Event,ADDED,eval-sanitize-40-r4-015-c4nvv.18d409fef1892e31,"reason=Pulled count=1 msg=Container image ""busybox:musl"" already present on machine"
60.1866,Event,ADDED,eval-sanitize-40-r4-015-c4nvv.18d409fef2e8825e,reason=Created count=1 msg=Created container: task
60.1868,Event,ADDED,eval-sanitize-40-r4-015-c4nvv.18d409fefc0aa27e,reason=Started count=1 msg=Started container task
60.1879,Event,ADDED,eval-sanitize-40-r4-015.18d409fed213a7b9,reason=SuccessfulCreate count=1 msg=Created pod: eval-sanitize-40-r4-015-c4nvv
60.1882,Event,ADDED,eval-sanitize-40-r4-015.18d40a020ecd41fc,reason=Completed count=1 msg=Job completed
60.1883,Event,ADDED,eval-sanitize-40-r4-016-cczvx.18d409ff16c4ff43,reason=Scheduled count=None msg=Successfully assigned compute/eval-sanitize-40-r4-016-cczvx to kind-worker4
60.1891,Job,ADDED,eval-sanitize-40-r4-046,
60.1895,Pod,ADDED,eval-sanitize-40-r4-046-n9t8x,phase=Succeeded node=kind-worker3
60.1898,Event,ADDED,eval-sanitize-40-r4-016-cczvx.18d409ff35bf0b76,"reason=Pulled count=1 msg=Container image ""busybox:musl"" already present on machine"
60.19,Event,ADDED,eval-sanitize-40-r4-016-cczvx.18d409ff36df6ca3,reason=Created count=1 msg=Created container: task
60.1903,Event,ADDED,eval-sanitize-40-r4-016-cczvx.18d409ff3aed655b,reason=Started count=1 msg=Started container task
60.1905,Event,ADDED,eval-sanitize-40-r4-016.18d409ff09971f90,reason=SuccessfulCreate count=1 msg=Created pod: eval-sanitize-40-r4-016-cczvx
60.1907,Event,ADDED,eval-sanitize-40-r4-016.18d40a02798b3b8a,reason=Completed count=1 msg=Job completed
60.1909,Event,ADDED,eval-sanitize-40-r4-017-2p92w.18d409ff493558a9,reason=Scheduled count=None msg=Successfully assigned compute/eval-sanitize-40-r4-017-2p92w to kind-worker5
60.1911,Event,ADDED,eval-sanitize-40-r4-017-2p92w.18d409ff629fe09f,"reason=Pulled count=1 msg=Container image ""busybox:musl"" already present on machine"
60.1913,Event,ADDED,eval-sanitize-40-r4-017-2p92w.18d409ff641b2a4b,reason=Created count=1 msg=Created container: task
60.192,Job,ADDED,eval-sanitize-40-r4-047,
60.1929,Pod,ADDED,eval-sanitize-40-r4-047-nzdwf,phase=Pending node=None
60.1932,Event,ADDED,eval-sanitize-40-r4-017-2p92w.18d409ff6a009607,reason=Started count=1 msg=Started container task
60.1935,Event,ADDED,eval-sanitize-40-r4-017.18d409ff44e13301,reason=SuccessfulCreate count=1 msg=Created pod: eval-sanitize-40-r4-017-2p92w
60.1937,Event,ADDED,eval-sanitize-40-r4-017.18d40a02871b2a22,reason=Completed count=1 msg=Job completed
60.1947,Job,ADDED,eval-sanitize-40-r4-048,
60.1954,Pod,ADDED,eval-sanitize-40-r4-048-6xppp,phase=Pending node=None
60.1957,Event,ADDED,eval-sanitize-40-r4-018-97rrz.18d409ff8a09feb1,reason=Scheduled count=None msg=Successfully assigned compute/eval-sanitize-40-r4-018-97rrz to kind-worker5
60.1959,Event,ADDED,eval-sanitize-40-r4-018-97rrz.18d409ffa40a3d72,"reason=Pulled count=1 msg=Container image ""busybox:musl"" already present on machine"
60.1961,Event,ADDED,eval-sanitize-40-r4-018-97rrz.18d409ffa52297e8,reason=Created count=1 msg=Created container: task
60.1963,Event,ADDED,eval-sanitize-40-r4-018-97rrz.18d409ffa91215d0,reason=Started count=1 msg=Started container task
60.197,Job,ADDED,eval-sanitize-40-r4-049,
60.1977,Pod,ADDED,eval-sanitize-40-r4-049-p2zf8,phase=Pending node=None
60.198,Event,ADDED,eval-sanitize-40-r4-018.18d409ff808b2a74,reason=SuccessfulCreate count=1 msg=Created pod: eval-sanitize-40-r4-018-97rrz
60.1982,Event,ADDED,eval-sanitize-40-r4-018.18d40a02be457f55,reason=Completed count=1 msg=Job completed
60.1984,Event,ADDED,eval-sanitize-40-r4-019-g28rc.18d409ffcfeb9df8,reason=Scheduled count=None msg=Successfully assigned compute/eval-sanitize-40-r4-019-g28rc to kind-worker5
60.1986,Event,ADDED,eval-sanitize-40-r4-019-g28rc.18d409ffec90a1de,"reason=Pulled count=1 msg=Container image ""busybox:musl"" already present on machine"
60.1993,Job,ADDED,eval-sanitize-40-r4-050,
60.2005,Pod,ADDED,eval-sanitize-40-r4-050-l8twf,phase=Running node=kind-worker3
60.2007,Event,ADDED,eval-sanitize-40-r4-019-g28rc.18d409ffed9a0569,reason=Created count=1 msg=Created container: task
60.201,Event,ADDED,eval-sanitize-40-r4-019-g28rc.18d409fff0f1e41d,reason=Started count=1 msg=Started container task
60.2011,Event,ADDED,eval-sanitize-40-r4-019.18d409ffc3d614b9,reason=SuccessfulCreate count=1 msg=Created pod: eval-sanitize-40-r4-019-g28rc
60.2019,Job,ADDED,eval-sanitize-40-r4-051,
60.2025,Job,ADDED,eval-sanitize-40-r4-052,
60.2032,Pod,ADDED,eval-sanitize-40-r4-051-7cqjl,phase=Pending node=None
60.2035,Event,ADDED,eval-sanitize-40-r4-019.18d40a033a9f46f5,reason=Completed count=1 msg=Job completed
60.2037,Event,ADDED,eval-sanitize-40-r4-020-f8d9v.18d409ffff13c18f,reason=Scheduled count=None msg=Successfully assigned compute/eval-sanitize-40-r4-020-f8d9v to kind-worker
60.2039,Event,ADDED,eval-sanitize-40-r4-020-f8d9v.18d40a00184e559f,"reason=Pulled count=1 msg=Container image ""busybox:musl"" already present on machine"
60.2041,Event,ADDED,eval-sanitize-40-r4-020-f8d9v.18d40a001975da9d,reason=Created count=1 msg=Created container: task
60.2054,Pod,ADDED,eval-sanitize-40-r4-052-bt8rh,phase=Running node=kind-worker3
60.2058,Event,ADDED,eval-sanitize-40-r4-020-f8d9v.18d40a0021c72faf,reason=Started count=1 msg=Started container task
60.206,Event,ADDED,eval-sanitize-40-r4-020.18d409fffa76f473,reason=SuccessfulCreate count=1 msg=Created pod: eval-sanitize-40-r4-020-f8d9v
60.2062,Event,ADDED,eval-sanitize-40-r4-020.18d40a033ac019e2,reason=Completed count=1 msg=Job completed
60.2064,Event,ADDED,eval-sanitize-40-r4-021-pxtwr.18d40a003e5178da,reason=Scheduled count=None msg=Successfully assigned compute/eval-sanitize-40-r4-021-pxtwr to kind-worker5
60.207,Job,ADDED,eval-sanitize-40-r4-053,
60.2107,Pod,ADDED,eval-sanitize-40-r4-053-mfqvs,phase=Pending node=None
60.2111,Event,ADDED,eval-sanitize-40-r4-021-pxtwr.18d40a005c34d588,"reason=Pulled count=1 msg=Container image ""busybox:musl"" already present on machine"
60.2114,Event,ADDED,eval-sanitize-40-r4-021-pxtwr.18d40a005d664b4a,reason=Created count=1 msg=Created container: task
60.2115,Event,ADDED,eval-sanitize-40-r4-021-pxtwr.18d40a0061f18df0,reason=Started count=1 msg=Started container task
60.2123,Job,ADDED,eval-sanitize-40-r4-054,
60.2129,Job,ADDED,eval-sanitize-40-r4-055,
60.2136,Pod,ADDED,eval-sanitize-40-r4-054-4hwn6,phase=Pending node=None
60.2139,Event,ADDED,eval-sanitize-40-r4-021.18d40a0039c5cab6,reason=SuccessfulCreate count=1 msg=Created pod: eval-sanitize-40-r4-021-pxtwr
60.2142,Event,ADDED,eval-sanitize-40-r4-021.18d40a033b1f5d20,reason=Completed count=1 msg=Job completed
60.2144,Event,ADDED,eval-sanitize-40-r4-022-7m7tt.18d40a0078accbbd,"reason=FailedScheduling count=None msg=0/6 nodes are available: 1 c_wall violated: 2 conflicting context pair(s) with node memory, 1 c_wall violated: 3 conflicting context pair(s) with node memory, 2 c_wall violated: 1 conflicting context pair(s) with node memory, 2 node(s) had untolerated taint(s). no new claims to deallocate, preemption: 0/6 nodes are available: 2 Preemption is not helpful for scheduling, 4 No preemption victims found for incoming pod."
60.215,Job,ADDED,eval-sanitize-40-r4-056,
60.2161,Pod,ADDED,eval-sanitize-40-r4-055-48dtb,phase=Running node=kind-worker3
60.2167,Event,ADDED,eval-sanitize-40-r4-022-7m7tt.18d40a007e901d50,"reason=FailedScheduling count=None msg=0/6 nodes are available: 1 c_wall violated: 2 conflicting context pair(s) with node memory, 1 c_wall violated: 3 conflicting context pair(s) with node memory, 2 c_wall violated: 1 conflicting context pair(s) with node memory, 2 node(s) had untolerated taint(s). no new claims to deallocate, preemption: 0/6 nodes are available: 2 Preemption is not helpful for scheduling, 4 No preemption victims found for incoming pod."
60.217,Event,ADDED,eval-sanitize-40-r4-022-7m7tt.18d40a00d23f21a3,"reason=FailedScheduling count=None msg=0/6 nodes are available: 1 c_wall violated: 1 conflicting context pair(s) with node memory, 1 c_wall violated: 3 conflicting context pair(s) with node memory, 2 c_wall violated: 2 conflicting context pair(s) with node memory, 2 node(s) had untolerated taint(s). no new claims to deallocate, preemption: 0/6 nodes are available: 2 Preemption is not helpful for scheduling, 4 No preemption victims found for incoming pod."
60.2173,Event,ADDED,eval-sanitize-40-r4-022-7m7tt.18d40a033810f685,"reason=FailedScheduling count=None msg=0/6 nodes are available: 1 c_wall violated: 1 conflicting context pair(s) with node memory, 1 c_wall violated: 4 conflicting context pair(s) with node memory, 2 c_wall violated: 2 conflicting context pair(s) with node memory, 2 node(s) had untolerated taint(s). no new claims to deallocate, preemption: 0/6 nodes are available: 2 Preemption is not helpful for scheduling, 4 No preemption victims found for incoming pod."
60.2176,Event,ADDED,eval-sanitize-40-r4-022-7m7tt.18d40a045080d381,"reason=FailedScheduling count=None msg=0/6 nodes are available: 1 c_wall violated: 2 conflicting context pair(s) with node memory, 1 c_wall violated: 4 conflicting context pair(s) with node memory, 4 node(s) had untolerated taint(s). no new claims to deallocate, preemption: 0/6 nodes are available: 2 No preemption victims found for incoming pod, 4 Preemption is not helpful for scheduling."
60.2179,Event,ADDED,eval-sanitize-40-r4-022-7m7tt.18d40a045bcd2b61,"reason=FailedScheduling count=None msg=0/6 nodes are available: 1 c_wall violated: 2 conflicting context pair(s) with node memory, 1 c_wall violated: 4 conflicting context pair(s) with node memory, 4 node(s) had untolerated taint(s). no new claims to deallocate, preemption: 0/6 nodes are available: 2 No preemption victims found for incoming pod, 4 Preemption is not helpful for scheduling."
60.2181,Event,ADDED,eval-sanitize-40-r4-022-7m7tt.18d40a04684786e3,"reason=FailedScheduling count=None msg=0/6 nodes are available: 1 c_wall violated: 4 conflicting context pair(s) with node memory, 5 node(s) had untolerated taint(s). no new claims to deallocate, preemption: 0/6 nodes are available: 1 No preemption victims found for incoming pod, 5 Preemption is not helpful for scheduling."
60.219,Pod,ADDED,eval-sanitize-40-r4-056-4bf68,phase=Pending node=None
60.2197,Job,ADDED,eval-sanitize-40-r4-057,
60.22,Event,ADDED,eval-sanitize-40-r4-022-7m7tt.18d40a04b6628840,reason=Scheduled count=None msg=Successfully assigned compute/eval-sanitize-40-r4-022-7m7tt to kind-worker3
60.2202,Event,ADDED,eval-sanitize-40-r4-022-7m7tt.18d40a04dc996276,"reason=Pulled count=1 msg=Container image ""busybox:musl"" already present on machine"
60.2204,Event,ADDED,eval-sanitize-40-r4-022-7m7tt.18d40a04e26bab1e,reason=Created count=1 msg=Created container: task
60.2211,Job,ADDED,eval-sanitize-40-r4-058,
60.2214,Event,ADDED,eval-sanitize-40-r4-022-7m7tt.18d40a04e5753dd2,reason=Started count=1 msg=Started container task
60.2216,Event,ADDED,eval-sanitize-40-r4-022.18d40a006effb11f,reason=SuccessfulCreate count=1 msg=Created pod: eval-sanitize-40-r4-022-7m7tt
60.2218,Event,ADDED,eval-sanitize-40-r4-022.18d40a07da6f12e5,reason=Completed count=1 msg=Job completed
60.2219,Event,ADDED,eval-sanitize-40-r4-023-tck4r.18d40a00b92a8ea5,reason=Scheduled count=None msg=Successfully assigned compute/eval-sanitize-40-r4-023-tck4r to kind-worker2
60.2227,Pod,ADDED,eval-sanitize-40-r4-057-nzvpl,phase=Pending node=None
60.2233,Pod,ADDED,eval-sanitize-40-r4-058-7z94v,phase=Pending node=None
60.2239,Job,ADDED,eval-sanitize-40-r4-059,
60.2241,Event,ADDED,eval-sanitize-40-r4-023-tck4r.18d40a00d452c21e,"reason=Pulled count=1 msg=Container image ""busybox:musl"" already present on machine"
60.2244,Event,ADDED,eval-sanitize-40-r4-023-tck4r.18d40a00d5acaa72,reason=Created count=1 msg=Created container: task
60.2246,Event,ADDED,eval-sanitize-40-r4-023-tck4r.18d40a00df27ccec,reason=Started count=1 msg=Started container task
60.2248,Event,ADDED,eval-sanitize-40-r4-023.18d40a00ab592ff2,reason=SuccessfulCreate count=1 msg=Created pod: eval-sanitize-40-r4-023-tck4r
60.2261,Pod,ADDED,eval-sanitize-40-r4-059-9bxnn,phase=Running node=kind-worker3
60.2267,Job,ADDED,eval-sanitize-40-r4-060,
60.2271,Event,ADDED,eval-sanitize-40-r4-023.18d40a04042480c5,reason=Completed count=1 msg=Job completed
60.2274,Event,ADDED,eval-sanitize-40-r4-024-qs8vx.18d40a00fac08961,reason=Scheduled count=None msg=Successfully assigned compute/eval-sanitize-40-r4-024-qs8vx to kind-worker
60.2276,Event,ADDED,eval-sanitize-40-r4-024-qs8vx.18d40a01136bcdd0,"reason=Pulled count=1 msg=Container image ""busybox:musl"" already present on machine"
60.2282,Job,MODIFIED,eval-sanitize-40-r4-060,
60.2288,Pod,ADDED,eval-sanitize-40-r4-060-cgf97,phase=Pending node=None
60.2292,Event,ADDED,eval-sanitize-40-r4-024-qs8vx.18d40a01148a69e8,reason=Created count=1 msg=Created container: task
60.2294,Event,ADDED,eval-sanitize-40-r4-024-qs8vx.18d40a0126a1b583,reason=Started count=1 msg=Started container task
60.2296,Event,ADDED,eval-sanitize-40-r4-024.18d40a00eb43a1cf,reason=SuccessfulCreate count=1 msg=Created pod: eval-sanitize-40-r4-024-qs8vx
60.2298,Event,ADDED,eval-sanitize-40-r4-024.18d40a04296d61d9,reason=Completed count=1 msg=Job completed
60.23,Event,ADDED,eval-sanitize-40-r4-025-d52pp.18d40a012d0533fb,reason=Scheduled count=None msg=Successfully assigned compute/eval-sanitize-40-r4-025-d52pp to kind-worker
60.2302,Event,ADDED,eval-sanitize-40-r4-025-d52pp.18d40a01461edce2,"reason=Pulled count=1 msg=Container image ""busybox:musl"" already present on machine"
60.2304,Event,ADDED,eval-sanitize-40-r4-025-d52pp.18d40a0147312f2d,reason=Created count=1 msg=Created container: task
60.2306,Event,ADDED,eval-sanitize-40-r4-025-d52pp.18d40a014c366e31,reason=Started count=1 msg=Started container task
60.2313,Job,MODIFIED,eval-sanitize-40-r4-059,
60.232,Pod,MODIFIED,eval-sanitize-40-r4-060-cgf97,phase=Pending node=kind-worker3
60.2324,Event,ADDED,eval-sanitize-40-r4-025.18d40a0121d0aaf5,reason=SuccessfulCreate count=1 msg=Created pod: eval-sanitize-40-r4-025-d52pp
60.2327,Event,ADDED,eval-sanitize-40-r4-025.18d40a042925db20,reason=Completed count=1 msg=Job completed
60.2328,Event,ADDED,eval-sanitize-40-r4-026-8vj8k.18d40a016ae0d39b,"reason=FailedScheduling count=None msg=0/6 nodes are available: 1 c_wall violated: 1 conflicting context pair(s) with node memory, 1 c_wall violated: 3 conflicting context pair(s) with node memory, 2 c_wall violated: 2 conflicting context pair(s) with node memory, 2 node(s) had untolerated taint(s). no new claims to deallocate, preemption: 0/6 nodes are available: 2 Preemption is not helpful for scheduling, 4 No preemption victims found for incoming pod."
60.2342,Pod,MODIFIED,eval-sanitize-40-r4-060-cgf97,phase=Pending node=kind-worker3
60.235,Job,MODIFIED,eval-sanitize-40-r4-059,
60.2353,Event,ADDED,eval-sanitize-40-r4-026-8vj8k.18d40a017d135603,"reason=FailedScheduling count=None msg=0/6 nodes are available: 1 c_wall violated: 1 conflicting context pair(s) with node memory, 1 c_wall violated: 3 conflicting context pair(s) with node memory, 2 c_wall violated: 2 conflicting context pair(s) with node memory, 2 node(s) had untolerated taint(s). no new claims to deallocate, preemption: 0/6 nodes are available: 2 Preemption is not helpful for scheduling, 4 No preemption victims found for incoming pod."
60.2355,Event,ADDED,eval-sanitize-40-r4-026-8vj8k.18d40a0326b01fbd,"reason=FailedScheduling count=None msg=0/6 nodes are available: 1 c_wall violated: 1 conflicting context pair(s) with node memory, 1 c_wall violated: 4 conflicting context pair(s) with node memory, 2 c_wall violated: 2 conflicting context pair(s) with node memory, 2 node(s) had untolerated taint(s). no new claims to deallocate, preemption: 0/6 nodes are available: 2 Preemption is not helpful for scheduling, 4 No preemption victims found for incoming pod."
60.2357,Event,ADDED,eval-sanitize-40-r4-026-8vj8k.18d40a045889aaa6,"reason=FailedScheduling count=None msg=0/6 nodes are available: 1 c_wall violated: 2 conflicting context pair(s) with node memory, 1 c_wall violated: 4 conflicting context pair(s) with node memory, 4 node(s) had untolerated taint(s). no new claims to deallocate, preemption: 0/6 nodes are available: 2 No preemption victims found for incoming pod, 4 Preemption is not helpful for scheduling."
60.236,Event,ADDED,eval-sanitize-40-r4-026-8vj8k.18d40a045c6e77ed,"reason=FailedScheduling count=None msg=0/6 nodes are available: 1 c_wall violated: 2 conflicting context pair(s) with node memory, 1 c_wall violated: 4 conflicting context pair(s) with node memory, 4 node(s) had untolerated taint(s). no new claims to deallocate, preemption: 0/6 nodes are available: 2 No preemption victims found for incoming pod, 4 Preemption is not helpful for scheduling."
60.2362,Event,ADDED,eval-sanitize-40-r4-026-8vj8k.18d40a046bcb2484,"reason=FailedScheduling count=None msg=0/6 nodes are available: 1 c_wall violated: 4 conflicting context pair(s) with node memory, 5 node(s) had untolerated taint(s). no new claims to deallocate, preemption: 0/6 nodes are available: 1 No preemption victims found for incoming pod, 5 Preemption is not helpful for scheduling."
60.2364,Event,ADDED,eval-sanitize-40-r4-026-8vj8k.18d40a04b6d32528,reason=Scheduled count=None msg=Successfully assigned compute/eval-sanitize-40-r4-026-8vj8k to kind-worker3
60.237,Event,ADDED,eval-sanitize-40-r4-026-8vj8k.18d40a04dc567ade,"reason=Pulled count=1 msg=Container image ""busybox:musl"" already present on machine"
60.2373,Event,ADDED,eval-sanitize-40-r4-026-8vj8k.18d40a04e21b0f2b,reason=Created count=1 msg=Created container: task
60.2375,Event,ADDED,eval-sanitize-40-r4-026-8vj8k.18d40a04e50014e0,reason=Started count=1 msg=Started container task
60.2378,Event,ADDED,eval-sanitize-40-r4-026.18d40a015fe2ff1b,reason=SuccessfulCreate count=1 msg=Created pod: eval-sanitize-40-r4-026-8vj8k
60.238,Event,ADDED,eval-sanitize-40-r4-026.18d40a07da7040a1,reason=Completed count=1 msg=Job completed
60.2381,Event,ADDED,eval-sanitize-40-r4-027-x2p67.18d40a019ac76d66,"reason=FailedScheduling count=None msg=0/6 nodes are available: 1 c_wall violated: 1 conflicting context pair(s) with node memory, 1 c_wall violated: 3 conflicting context pair(s) with node memory, 2 c_wall violated: 2 conflicting context pair(s) with node memory, 2 node(s) had untolerated taint(s). no new claims to deallocate, preemption: 0/6 nodes are available: 2 Preemption is not helpful for scheduling, 4 No preemption victims found for incoming pod."
60.2385,Event,ADDED,eval-sanitize-40-r4-027-x2p67.18d40a01a0ba8e04,"reason=FailedScheduling count=None msg=0/6 nodes are available: 1 c_wall violated: 1 conflicting context pair(s) with node memory, 1 c_wall violated: 3 conflicting context pair(s) with node memory, 2 c_wall violated: 2 conflicting context pair(s) with node memory, 2 node(s) had untolerated taint(s). no new claims to deallocate, preemption: 0/6 nodes are available: 2 Preemption is not helpful for scheduling, 4 No preemption victims found for incoming pod."
60.2387,Event,ADDED,eval-sanitize-40-r4-027-x2p67.18d40a032c9d6be0,"reason=FailedScheduling count=None msg=0/6 nodes are available: 1 c_wall violated: 1 conflicting context pair(s) with node memory, 1 c_wall violated: 4 conflicting context pair(s) with node memory, 2 c_wall violated: 2 conflicting context pair(s) with node memory, 2 node(s) had untolerated taint(s). no new claims to deallocate, preemption: 0/6 nodes are available: 2 Preemption is not helpful for scheduling, 4 No preemption victims found for incoming pod."
60.2389,Event,ADDED,eval-sanitize-40-r4-027-x2p67.18d40a04591f59db,"reason=FailedScheduling count=None msg=0/6 nodes are available: 1 c_wall violated: 2 conflicting context pair(s) with node memory, 1 c_wall violated: 4 conflicting context pair(s) with node memory, 4 node(s) had untolerated taint(s). no new claims to deallocate, preemption: 0/6 nodes are available: 2 No preemption victims found for incoming pod, 4 Preemption is not helpful for scheduling."
60.2392,Event,ADDED,eval-sanitize-40-r4-027-x2p67.18d40a0467c0bbbd,"reason=FailedScheduling count=None msg=0/6 nodes are available: 1 c_wall violated: 4 conflicting context pair(s) with node memory, 5 node(s) had untolerated taint(s). no new claims to deallocate, preemption: 0/6 nodes are available: 1 No preemption victims found for incoming pod, 5 Preemption is not helpful for scheduling."
60.2394,Event,ADDED,eval-sanitize-40-r4-027-x2p67.18d40a04b5a6af99,reason=Scheduled count=None msg=Successfully assigned compute/eval-sanitize-40-r4-027-x2p67 to kind-worker3
60.2397,Event,ADDED,eval-sanitize-40-r4-027-x2p67.18d40a04dbe05105,"reason=Pulled count=1 msg=Container image ""busybox:musl"" already present on machine"
60.24,Event,ADDED,eval-sanitize-40-r4-027-x2p67.18d40a04dffaea73,reason=Created count=1 msg=Created container: task
60.2402,Event,ADDED,eval-sanitize-40-r4-027-x2p67.18d40a04e45ae526,reason=Started count=1 msg=Started container task
60.2403,Event,ADDED,eval-sanitize-40-r4-027.18d40a0199e7b6d2,reason=SuccessfulCreate count=1 msg=Created pod: eval-sanitize-40-r4-027-x2p67
60.2406,Event,ADDED,eval-sanitize-40-r4-027.18d40a0819116214,reason=Completed count=1 msg=Job completed
60.2409,Event,ADDED,eval-sanitize-40-r4-028-nxm9c.18d40a01dd502b85,reason=Scheduled count=None msg=Successfully assigned compute/eval-sanitize-40-r4-028-nxm9c to kind-worker4
60.241,Event,ADDED,eval-sanitize-40-r4-028-nxm9c.18d40a01f677c7af,"reason=Pulled count=1 msg=Container image ""busybox:musl"" already present on machine"
60.2412,Event,ADDED,eval-sanitize-40-r4-028-nxm9c.18d40a01f7865438,reason=Created count=1 msg=Created container: task
60.2414,Event,ADDED,eval-sanitize-40-r4-028-nxm9c.18d40a01f98627e8,reason=Started count=1 msg=Started container task
60.2417,Event,ADDED,eval-sanitize-40-r4-028.18d40a01d4bd5e51,reason=SuccessfulCreate count=1 msg=Created pod: eval-sanitize-40-r4-028-nxm9c
60.2419,Event,ADDED,eval-sanitize-40-r4-028.18d40a0511d4a67b,reason=Completed count=1 msg=Job completed
60.2421,Event,ADDED,eval-sanitize-40-r4-029-gbx8m.18d40a02183fa9b4,reason=Scheduled count=None msg=Successfully assigned compute/eval-sanitize-40-r4-029-gbx8m to kind-worker
60.2423,Event,ADDED,eval-sanitize-40-r4-029-gbx8m.18d40a0230fa4a45,"reason=Pulled count=1 msg=Container image ""busybox:musl"" already present on machine"
60.2426,Event,ADDED,eval-sanitize-40-r4-029-gbx8m.18d40a02320f3e7d,reason=Created count=1 msg=Created container: task
60.2428,Event,ADDED,eval-sanitize-40-r4-029-gbx8m.18d40a0233faa7f6,reason=Started count=1 msg=Started container task
60.2429,Event,ADDED,eval-sanitize-40-r4-029.18d40a02102eb125,reason=SuccessfulCreate count=1 msg=Created pod: eval-sanitize-40-r4-029-gbx8m
60.2433,Event,ADDED,eval-sanitize-40-r4-029.18d40a0554792dc2,reason=Completed count=1 msg=Job completed
60.2435,Event,ADDED,eval-sanitize-40-r4-030-kgdr2.18d40a02560cfba2,reason=Scheduled count=None msg=Successfully assigned compute/eval-sanitize-40-r4-030-kgdr2 to kind-worker5
60.2437,Event,ADDED,eval-sanitize-40-r4-030-kgdr2.18d40a026fa5ecba,"reason=Pulled count=1 msg=Container image ""busybox:musl"" already present on machine"
60.2439,Event,ADDED,eval-sanitize-40-r4-030-kgdr2.18d40a0270bab885,reason=Created count=1 msg=Created container: task
60.2444,Event,ADDED,eval-sanitize-40-r4-030-kgdr2.18d40a0274c2820f,reason=Started count=1 msg=Started container task
60.2446,Event,ADDED,eval-sanitize-40-r4-030.18d40a024c335e02,reason=SuccessfulCreate count=1 msg=Created pod: eval-sanitize-40-r4-030-kgdr2
60.2448,Event,ADDED,eval-sanitize-40-r4-030.18d40a0554ff88a3,reason=Completed count=1 msg=Job completed
60.245,Event,ADDED,eval-sanitize-40-r4-031-lf45v.18d40a0290d3dd59,reason=Scheduled count=None msg=Successfully assigned compute/eval-sanitize-40-r4-031-lf45v to kind-worker5
60.2453,Event,ADDED,eval-sanitize-40-r4-031-lf45v.18d40a02aba6a90c,"reason=Pulled count=1 msg=Container image ""busybox:musl"" already present on machine"
60.2455,Event,ADDED,eval-sanitize-40-r4-031-lf45v.18d40a02acc08f69,reason=Created count=1 msg=Created container: task
60.2456,Event,ADDED,eval-sanitize-40-r4-031-lf45v.18d40a02b1e59d15,reason=Started count=1 msg=Started container task
60.246,Event,ADDED,eval-sanitize-40-r4-031.18d40a02888f894b,reason=SuccessfulCreate count=1 msg=Created pod: eval-sanitize-40-r4-031-lf45v
60.2462,Event,ADDED,eval-sanitize-40-r4-031.18d40a058e2c1445,reason=Completed count=1 msg=Job completed
60.2464,Event,ADDED,eval-sanitize-40-r4-032-9r59c.18d40a02d302076b,reason=Scheduled count=None msg=Successfully assigned compute/eval-sanitize-40-r4-032-9r59c to kind-worker
60.2466,Event,ADDED,eval-sanitize-40-r4-032-9r59c.18d40a02ec5466c4,"reason=Pulled count=1 msg=Container image ""busybox:musl"" already present on machine"
60.2469,Event,ADDED,eval-sanitize-40-r4-032-9r59c.18d40a02ed76f5bb,reason=Created count=1 msg=Created container: task
60.2471,Event,ADDED,eval-sanitize-40-r4-032-9r59c.18d40a02f2ce99a6,reason=Started count=1 msg=Started container task
60.2473,Event,ADDED,eval-sanitize-40-r4-032.18d40a02c64b443b,reason=SuccessfulCreate count=1 msg=Created pod: eval-sanitize-40-r4-032-9r59c
60.2476,Event,ADDED,eval-sanitize-40-r4-032.18d40a05ca6edb47,reason=Completed count=1 msg=Job completed
60.2478,Event,ADDED,eval-sanitize-40-r4-033-9d9p7.18d40a0304ebef1a,reason=Scheduled count=None msg=Successfully assigned compute/eval-sanitize-40-r4-033-9d9p7 to kind-worker5
60.248,Event,ADDED,eval-sanitize-40-r4-033-9d9p7.18d40a0320e2abfb,"reason=Pulled count=1 msg=Container image ""busybox:musl"" already present on machine"
60.2482,Event,ADDED,eval-sanitize-40-r4-033-9d9p7.18d40a0321fa9152,reason=Created count=1 msg=Created container: task
60.2485,Event,ADDED,eval-sanitize-40-r4-033-9d9p7.18d40a0327dfdd60,reason=Started count=1 msg=Started container task
60.2487,Event,ADDED,eval-sanitize-40-r4-033.18d40a02feeb1743,reason=SuccessfulCreate count=1 msg=Created pod: eval-sanitize-40-r4-033-9d9p7
60.2489,Event,ADDED,eval-sanitize-40-r4-033.18d40a0605637b13,reason=Completed count=1 msg=Job completed
60.249,Event,ADDED,eval-sanitize-40-r4-034-qwc55.18d40a03475329b6,reason=Scheduled count=None msg=Successfully assigned compute/eval-sanitize-40-r4-034-qwc55 to kind-worker
60.2493,Event,ADDED,eval-sanitize-40-r4-034-qwc55.18d40a03693cd600,"reason=Pulled count=1 msg=Container image ""busybox:musl"" already present on machine"
60.2496,Event,ADDED,eval-sanitize-40-r4-034-qwc55.18d40a036a50a8b6,reason=Created count=1 msg=Created container: task
60.2498,Event,ADDED,eval-sanitize-40-r4-034-qwc55.18d40a03714d4135,reason=Started count=1 msg=Started container task
60.2501,Event,ADDED,eval-sanitize-40-r4-034.18d40a033bfacf3d,reason=SuccessfulCreate count=1 msg=Created pod: eval-sanitize-40-r4-034-qwc55
60.2503,Event,ADDED,eval-sanitize-40-r4-034.18d40a067da2c9de,reason=Completed count=1 msg=Job completed
60.2505,Event,ADDED,eval-sanitize-40-r4-035-8pwgh.18d40a0380a1257d,reason=Scheduled count=None msg=Successfully assigned compute/eval-sanitize-40-r4-035-8pwgh to kind-worker
60.2506,Event,ADDED,eval-sanitize-40-r4-035-8pwgh.18d40a03a0ed35b2,"reason=Pulled count=1 msg=Container image ""busybox:musl"" already present on machine"
60.2509,Event,ADDED,eval-sanitize-40-r4-035-8pwgh.18d40a03a20f3cb9,reason=Created count=1 msg=Created container: task
60.2511,Event,ADDED,eval-sanitize-40-r4-035-8pwgh.18d40a03a86e3efa,reason=Started count=1 msg=Started container task
60.2513,Event,ADDED,eval-sanitize-40-r4-035.18d40a0377f9bf77,reason=SuccessfulCreate count=1 msg=Created pod: eval-sanitize-40-r4-035-8pwgh
60.2514,Event,ADDED,eval-sanitize-40-r4-035.18d40a06b962378c,reason=Completed count=1 msg=Job completed
60.2516,Event,ADDED,eval-sanitize-40-r4-036-btf8v.18d40a03b77d6bc1,reason=Scheduled count=None msg=Successfully assigned compute/eval-sanitize-40-r4-036-btf8v to kind-worker5
60.2518,Event,ADDED,eval-sanitize-40-r4-036-btf8v.18d40a03d2499dc2,"reason=Pulled count=1 msg=Container image ""busybox:musl"" already present on machine"
60.252,Event,ADDED,eval-sanitize-40-r4-036-btf8v.18d40a03d36a268b,reason=Created count=1 msg=Created container: task
60.2523,Event,ADDED,eval-sanitize-40-r4-036-btf8v.18d40a03d8e8ee30,reason=Started count=1 msg=Started container task
60.2526,Event,ADDED,eval-sanitize-40-r4-036.18d40a03b1395104,reason=SuccessfulCreate count=1 msg=Created pod: eval-sanitize-40-r4-036-btf8v
60.2528,Event,ADDED,eval-sanitize-40-r4-036.18d40a06b80cf91a,reason=Completed count=1 msg=Job completed
60.2529,Event,ADDED,eval-sanitize-40-r4-037-dhckp.18d40a03f54ebef8,reason=Scheduled count=None msg=Successfully assigned compute/eval-sanitize-40-r4-037-dhckp to kind-worker2
60.2532,Event,ADDED,eval-sanitize-40-r4-037-dhckp.18d40a040e052c71,"reason=Pulled count=1 msg=Container image ""busybox:musl"" already present on machine"
60.2534,Event,ADDED,eval-sanitize-40-r4-037-dhckp.18d40a040f208d7c,reason=Created count=1 msg=Created container: task
60.2536,Event,ADDED,eval-sanitize-40-r4-037-dhckp.18d40a0413130da2,reason=Started count=1 msg=Started container task
60.2538,Event,ADDED,eval-sanitize-40-r4-037.18d40a03ee93181c,reason=SuccessfulCreate count=1 msg=Created pod: eval-sanitize-40-r4-037-dhckp
60.2541,Event,ADDED,eval-sanitize-40-r4-037.18d40a0749d54ac8,reason=Completed count=1 msg=Job completed
60.2543,Event,ADDED,eval-sanitize-40-r4-038-k6lc5.18d40a042c51d9b6,reason=Scheduled count=None msg=Successfully assigned compute/eval-sanitize-40-r4-038-k6lc5 to kind-worker4
60.2545,Event,ADDED,eval-sanitize-40-r4-038-k6lc5.18d40a044498dbbc,"reason=Pulled count=1 msg=Container image ""busybox:musl"" already present on machine"
60.2549,Event,ADDED,eval-sanitize-40-r4-038-k6lc5.18d40a0445b7c588,reason=Created count=1 msg=Created container: task
60.2551,Event,ADDED,eval-sanitize-40-r4-038-k6lc5.18d40a04478f29e9,reason=Started count=1 msg=Started container task
60.2553,Event,ADDED,eval-sanitize-40-r4-038.18d40a042998ee35,reason=SuccessfulCreate count=1 msg=Created pod: eval-sanitize-40-r4-038-k6lc5
60.2555,Event,ADDED,eval-sanitize-40-r4-038.18d40a0760249078,reason=Completed count=1 msg=Job completed
60.2557,Event,ADDED,eval-sanitize-40-r4-039-x7df5.18d40a046539ef99,"reason=FailedScheduling count=None msg=0/6 nodes are available: 1 c_wall violated: 2 conflicting context pair(s) with node memory, 5 node(s) had untolerated taint(s). no new claims to deallocate, preemption: 0/6 nodes are available: 1 No preemption victims found for incoming pod, 5 Preemption is not helpful for scheduling."
60.2559,Event,ADDED,eval-sanitize-40-r4-039-x7df5.18d40a046816a06e,"reason=FailedScheduling count=None msg=0/6 nodes are available: 1 c_wall violated: 2 conflicting context pair(s) with node memory, 5 node(s) had untolerated taint(s). no new claims to deallocate, preemption: 0/6 nodes are available: 1 No preemption victims found for incoming pod, 5 Preemption is not helpful for scheduling."
60.2561,Event,ADDED,eval-sanitize-40-r4-039-x7df5.18d40a04b61662d0,reason=Scheduled count=None msg=Successfully assigned compute/eval-sanitize-40-r4-039-x7df5 to kind-worker3
60.2564,Event,ADDED,eval-sanitize-40-r4-039-x7df5.18d40a04dc309c1e,"reason=Pulled count=1 msg=Container image ""busybox:musl"" already present on machine"
60.2566,Event,ADDED,eval-sanitize-40-r4-039-x7df5.18d40a04e0de561d,reason=Created count=1 msg=Created container: task
60.2568,Event,ADDED,eval-sanitize-40-r4-039-x7df5.18d40a04e406554c,reason=Started count=1 msg=Started container task
60.257,Event,ADDED,eval-sanitize-40-r4-039.18d40a046452221c,reason=SuccessfulCreate count=1 msg=Created pod: eval-sanitize-40-r4-039-x7df5
60.2573,Event,ADDED,eval-sanitize-40-r4-039.18d40a07da717ba6,reason=Completed count=1 msg=Job completed
60.2575,Event,ADDED,eval-sanitize-40-r4-040-d5rbc.18d40a04a15f3223,"reason=FailedScheduling count=None msg=0/6 nodes are available: 6 node(s) had untolerated taint(s). no new claims to deallocate, preemption: 0/6 nodes are available: 6 Preemption is not helpful for scheduling."
60.2576,Event,ADDED,eval-sanitize-40-r4-040-d5rbc.18d40a04b67d21f3,"reason=FailedScheduling count=None msg=0/6 nodes are available: 1 c_wall violated: 1 conflicting context pair(s) with node memory, 5 node(s) had untolerated taint(s). no new claims to deallocate, preemption: 0/6 nodes are available: 1 No preemption victims found for incoming pod, 5 Preemption is not helpful for scheduling."
60.258,Event,ADDED,eval-sanitize-40-r4-040-d5rbc.18d40a04beeeb04a,"reason=FailedScheduling count=None msg=0/6 nodes are available: 1 c_wall violated: 1 conflicting context pair(s) with node memory, 5 node(s) had untolerated taint(s). no new claims to deallocate, preemption: 0/6 nodes are available: 1 No preemption victims found for incoming pod, 5 Preemption is not helpful for scheduling."
60.2582,Event,ADDED,eval-sanitize-40-r4-040.18d40a04a14ea5e2,reason=SuccessfulCreate count=1 msg=Created pod: eval-sanitize-40-r4-040-d5rbc
60.2583,Event,ADDED,eval-sanitize-40-r4-041-lgn9n.18d40a04de678a8c,"reason=FailedScheduling count=None msg=0/6 nodes are available: 1 c_wall violated: 1 conflicting context pair(s) with node memory, 5 node(s) had untolerated taint(s). no new claims to deallocate, preemption: 0/6 nodes are available: 1 No preemption victims found for incoming pod, 5 Preemption is not helpful for scheduling."
60.2587,Event,ADDED,eval-sanitize-40-r4-041-lgn9n.18d40a04df566dd6,"reason=FailedScheduling count=None msg=0/6 nodes are available: 1 c_wall violated: 1 conflicting context pair(s) with node memory, 5 node(s) had untolerated taint(s). no new claims to deallocate, preemption: 0/6 nodes are available: 1 No preemption victims found for incoming pod, 5 Preemption is not helpful for scheduling."
60.2589,Event,ADDED,eval-sanitize-40-r4-041.18d40a04de211539,reason=SuccessfulCreate count=1 msg=Created pod: eval-sanitize-40-r4-041-lgn9n
60.2591,Event,ADDED,eval-sanitize-40-r4-042-pc6tp.18d40a05177077f6,reason=Scheduled count=None msg=Successfully assigned compute/eval-sanitize-40-r4-042-pc6tp to kind-worker3
60.2592,Event,ADDED,eval-sanitize-40-r4-042-pc6tp.18d40a05341223a4,"reason=Pulled count=1 msg=Container image ""busybox:musl"" already present on machine"
60.2595,Event,ADDED,eval-sanitize-40-r4-042-pc6tp.18d40a053526fb60,reason=Created count=1 msg=Created container: task
60.2597,Event,ADDED,eval-sanitize-40-r4-042-pc6tp.18d40a053be913da,reason=Started count=1 msg=Started container task
60.2599,Event,ADDED,eval-sanitize-40-r4-042.18d40a0516f28100,reason=SuccessfulCreate count=1 msg=Created pod: eval-sanitize-40-r4-042-pc6tp
60.2601,Event,ADDED,eval-sanitize-40-r4-042.18d40a084d05e9c5,reason=Completed count=1 msg=Job completed
60.2604,Event,ADDED,eval-sanitize-40-r4-043-hmb2v.18d40a055384d041,reason=Scheduled count=None msg=Successfully assigned compute/eval-sanitize-40-r4-043-hmb2v to kind-worker3
60.2606,Event,ADDED,eval-sanitize-40-r4-043-hmb2v.18d40a056cb86c48,"reason=Pulled count=1 msg=Container image ""busybox:musl"" already present on machine"
60.2608,Event,ADDED,eval-sanitize-40-r4-043-hmb2v.18d40a056dbd0133,reason=Created count=1 msg=Created container: task
60.261,Event,ADDED,eval-sanitize-40-r4-043-hmb2v.18d40a0574a74beb,reason=Started count=1 msg=Started container task
60.2612,Event,ADDED,eval-sanitize-40-r4-043.18d40a0552f411b3,reason=SuccessfulCreate count=1 msg=Created pod: eval-sanitize-40-r4-043-hmb2v
60.2614,Event,ADDED,eval-sanitize-40-r4-043.18d40a088ab4cae9,reason=Completed count=1 msg=Job completed
60.2616,Event,ADDED,eval-sanitize-40-r4-044-c77pq.18d40a058f352034,"reason=FailedScheduling count=None msg=0/6 nodes are available: 1 c_wall violated: 2 conflicting context pair(s) with node memory, 5 node(s) had untolerated taint(s). no new claims to deallocate, preemption: 0/6 nodes are available: 1 No preemption victims found for incoming pod, 5 Preemption is not helpful for scheduling."
60.2619,Event,ADDED,eval-sanitize-40-r4-044-c77pq.18d40a058fc865b2,"reason=FailedScheduling count=None msg=0/6 nodes are available: 1 c_wall violated: 2 conflicting context pair(s) with node memory, 5 node(s) had untolerated taint(s). no new claims to deallocate, preemption: 0/6 nodes are available: 1 No preemption victims found for incoming pod, 5 Preemption is not helpful for scheduling."
60.2621,Event,ADDED,eval-sanitize-40-r4-044.18d40a058ef3e7c9,reason=SuccessfulCreate count=1 msg=Created pod: eval-sanitize-40-r4-044-c77pq
60.2623,Event,ADDED,eval-sanitize-40-r4-045-tz6l6.18d40a05cad97f2b,reason=Scheduled count=None msg=Successfully assigned compute/eval-sanitize-40-r4-045-tz6l6 to kind-worker3
60.2626,Event,ADDED,eval-sanitize-40-r4-045-tz6l6.18d40a05e5eb0776,"reason=Pulled count=1 msg=Container image ""busybox:musl"" already present on machine"
60.2628,Event,ADDED,eval-sanitize-40-r4-045-tz6l6.18d40a05e711bbf9,reason=Created count=1 msg=Created container: task
60.263,Event,ADDED,eval-sanitize-40-r4-045-tz6l6.18d40a05eae8944e,reason=Started count=1 msg=Started container task
60.2631,Event,ADDED,eval-sanitize-40-r4-045.18d40a05ca48f2aa,reason=SuccessfulCreate count=1 msg=Created pod: eval-sanitize-40-r4-045-tz6l6
60.2634,Event,ADDED,eval-sanitize-40-r4-045.18d40a0902db4436,reason=Completed count=1 msg=Job completed
60.2636,Event,ADDED,eval-sanitize-40-r4-046-n9t8x.18d40a0606847549,reason=Scheduled count=None msg=Successfully assigned compute/eval-sanitize-40-r4-046-n9t8x to kind-worker3
60.2638,Event,ADDED,eval-sanitize-40-r4-046-n9t8x.18d40a061f9f430e,"reason=Pulled count=1 msg=Container image ""busybox:musl"" already present on machine"
60.2641,Event,ADDED,eval-sanitize-40-r4-046-n9t8x.18d40a0620aee162,reason=Created count=1 msg=Created container: task
60.2643,Event,ADDED,eval-sanitize-40-r4-046-n9t8x.18d40a0624c18a09,reason=Started count=1 msg=Started container task
60.2645,Event,ADDED,eval-sanitize-40-r4-046.18d40a0605c8c84e,reason=SuccessfulCreate count=1 msg=Created pod: eval-sanitize-40-r4-046-n9t8x
60.2647,Event,ADDED,eval-sanitize-40-r4-046.18d40a093f1af429,reason=Completed count=1 msg=Job completed
60.2651,Event,ADDED,eval-sanitize-40-r4-047-nzdwf.18d40a06418dd6cc,"reason=FailedScheduling count=None msg=0/6 nodes are available: 1 c_wall violated: 1 conflicting context pair(s) with node memory, 5 node(s) had untolerated taint(s). no new claims to deallocate, preemption: 0/6 nodes are available: 1 No preemption victims found for incoming pod, 5 Preemption is not helpful for scheduling."
60.2654,Event,ADDED,eval-sanitize-40-r4-047-nzdwf.18d40a06426ed08f,"reason=FailedScheduling count=None msg=0/6 nodes are available: 1 c_wall violated: 1 conflicting context pair(s) with node memory, 5 node(s) had untolerated taint(s). no new claims to deallocate, preemption: 0/6 nodes are available: 1 No preemption victims found for incoming pod, 5 Preemption is not helpful for scheduling."
60.2656,Event,ADDED,eval-sanitize-40-r4-047.18d40a06414ec54b,reason=SuccessfulCreate count=1 msg=Created pod: eval-sanitize-40-r4-047-nzdwf
60.2659,Event,ADDED,eval-sanitize-40-r4-048-6xppp.18d40a067d4d199f,"reason=FailedScheduling count=None msg=0/6 nodes are available: 1 c_wall violated: 1 conflicting context pair(s) with node memory, 5 node(s) had untolerated taint(s). no new claims to deallocate, preemption: 0/6 nodes are available: 1 No preemption victims found for incoming pod, 5 Preemption is not helpful for scheduling."
60.2661,Event,ADDED,eval-sanitize-40-r4-048-6xppp.18d40a067ded111d,"reason=FailedScheduling count=None msg=0/6 nodes are available: 1 c_wall violated: 1 conflicting context pair(s) with node memory, 5 node(s) had untolerated taint(s). no new claims to deallocate, preemption: 0/6 nodes are available: 1 No preemption victims found for incoming pod, 5 Preemption is not helpful for scheduling."
60.2663,Event,ADDED,eval-sanitize-40-r4-048.18d40a067d05478a,reason=SuccessfulCreate count=1 msg=Created pod: eval-sanitize-40-r4-048-6xppp
60.2669,Event,ADDED,eval-sanitize-40-r4-049-p2zf8.18d40a06b8c1d7c1,"reason=FailedScheduling count=None msg=0/6 nodes are available: 1 c_wall violated: 1 conflicting context pair(s) with node memory, 5 node(s) had untolerated taint(s). no new claims to deallocate, preemption: 0/6 nodes are available: 1 No preemption victims found for incoming pod, 5 Preemption is not helpful for scheduling."
60.2674,Event,ADDED,eval-sanitize-40-r4-049-p2zf8.18d40a06b95859a5,"reason=FailedScheduling count=None msg=0/6 nodes are available: 1 c_wall violated: 1 conflicting context pair(s) with node memory, 5 node(s) had untolerated taint(s). no new claims to deallocate, preemption: 0/6 nodes are available: 1 No preemption victims found for incoming pod, 5 Preemption is not helpful for scheduling."
60.2676,Event,ADDED,eval-sanitize-40-r4-049.18d40a06b876b5a6,reason=SuccessfulCreate count=1 msg=Created pod: eval-sanitize-40-r4-049-p2zf8
60.2678,Event,ADDED,eval-sanitize-40-r4-050-l8twf.18d40a06f791c652,reason=Scheduled count=None msg=Successfully assigned compute/eval-sanitize-40-r4-050-l8twf to kind-worker3
60.2681,Event,ADDED,eval-sanitize-40-r4-050-l8twf.18d40a0710966183,"reason=Pulled count=1 msg=Container image ""busybox:musl"" already present on machine"
60.2682,Event,ADDED,eval-sanitize-40-r4-050-l8twf.18d40a0711acd89c,reason=Created count=1 msg=Created container: task
60.2684,Event,ADDED,eval-sanitize-40-r4-050-l8twf.18d40a0714a9126c,reason=Started count=1 msg=Started container task
60.2688,Event,ADDED,eval-sanitize-40-r4-050.18d40a06f70ac0d9,reason=SuccessfulCreate count=1 msg=Created pod: eval-sanitize-40-r4-050-l8twf
60.2689,Event,ADDED,eval-sanitize-40-r4-051-7cqjl.18d40a0732252a51,"reason=FailedScheduling count=None msg=0/6 nodes are available: 1 c_wall violated: 1 conflicting context pair(s) with node memory, 5 node(s) had untolerated taint(s). no new claims to deallocate, preemption: 0/6 nodes are available: 1 No preemption victims found for incoming pod, 5 Preemption is not helpful for scheduling."
60.2692,Event,ADDED,eval-sanitize-40-r4-051-7cqjl.18d40a0732bb3ed6,"reason=FailedScheduling count=None msg=0/6 nodes are available: 1 c_wall violated: 1 conflicting context pair(s) with node memory, 5 node(s) had untolerated taint(s). no new claims to deallocate, preemption: 0/6 nodes are available: 1 No preemption victims found for incoming pod, 5 Preemption is not helpful for scheduling."
60.2695,Event,ADDED,eval-sanitize-40-r4-051.18d40a0731e1a264,reason=SuccessfulCreate count=1 msg=Created pod: eval-sanitize-40-r4-051-7cqjl
60.2696,Event,ADDED,eval-sanitize-40-r4-052-bt8rh.18d40a076bc28388,reason=Scheduled count=None msg=Successfully assigned compute/eval-sanitize-40-r4-052-bt8rh to kind-worker3
60.2698,Event,ADDED,eval-sanitize-40-r4-052-bt8rh.18d40a0787863262,"reason=Pulled count=1 msg=Container image ""busybox:musl"" already present on machine"
60.27,Event,ADDED,eval-sanitize-40-r4-052-bt8rh.18d40a0788b563fe,reason=Created count=1 msg=Created container: task
60.2703,Event,ADDED,eval-sanitize-40-r4-052-bt8rh.18d40a078d0eea35,reason=Started count=1 msg=Started container task
60.2706,Event,ADDED,eval-sanitize-40-r4-052.18d40a076b4318af,reason=SuccessfulCreate count=1 msg=Created pod: eval-sanitize-40-r4-052-bt8rh
60.2707,Event,ADDED,eval-sanitize-40-r4-053-mfqvs.18d40a07a8788797,"reason=FailedScheduling count=None msg=0/6 nodes are available: 1 c_wall violated: 1 conflicting context pair(s) with node memory, 5 node(s) had untolerated taint(s). no new claims to deallocate, preemption: 0/6 nodes are available: 1 No preemption victims found for incoming pod, 5 Preemption is not helpful for scheduling."
60.2713,Event,ADDED,eval-sanitize-40-r4-053-mfqvs.18d40a07b01d70bb,"reason=FailedScheduling count=None msg=0/6 nodes are available: 1 c_wall violated: 1 conflicting context pair(s) with node memory, 5 node(s) had untolerated taint(s). no new claims to deallocate, preemption: 0/6 nodes are available: 1 No preemption victims found for incoming pod, 5 Preemption is not helpful for scheduling."
60.2716,Event,ADDED,eval-sanitize-40-r4-053.18d40a07a6a5a823,reason=SuccessfulCreate count=1 msg=Created pod: eval-sanitize-40-r4-053-mfqvs
60.2718,Event,ADDED,eval-sanitize-40-r4-054-4hwn6.18d40a07e94b98d9,"reason=FailedScheduling count=None msg=0/6 nodes are available: 1 c_wall violated: 2 conflicting context pair(s) with node memory, 5 node(s) had untolerated taint(s). no new claims to deallocate, preemption: 0/6 nodes are available: 1 No preemption victims found for incoming pod, 5 Preemption is not helpful for scheduling."
60.2722,Event,ADDED,eval-sanitize-40-r4-054-4hwn6.18d40a07e9cb9f2e,"reason=FailedScheduling count=None msg=0/6 nodes are available: 1 c_wall violated: 2 conflicting context pair(s) with node memory, 5 node(s) had untolerated taint(s). no new claims to deallocate, preemption: 0/6 nodes are available: 1 No preemption victims found for incoming pod, 5 Preemption is not helpful for scheduling."
60.2724,Event,ADDED,eval-sanitize-40-r4-054.18d40a07e91087c5,reason=SuccessfulCreate count=1 msg=Created pod: eval-sanitize-40-r4-054-4hwn6
60.2725,Event,ADDED,eval-sanitize-40-r4-055-48dtb.18d40a0821c8eb39,reason=Scheduled count=None msg=Successfully assigned compute/eval-sanitize-40-r4-055-48dtb to kind-worker3
60.2727,Event,ADDED,eval-sanitize-40-r4-055-48dtb.18d40a083b350881,"reason=Pulled count=1 msg=Container image ""busybox:musl"" already present on machine"
60.273,Event,ADDED,eval-sanitize-40-r4-055-48dtb.18d40a083c4bca56,reason=Created count=1 msg=Created container: task
60.2732,Event,ADDED,eval-sanitize-40-r4-055-48dtb.18d40a08405e865a,reason=Started count=1 msg=Started container task
60.2734,Event,ADDED,eval-sanitize-40-r4-055.18d40a082141644d,reason=SuccessfulCreate count=1 msg=Created pod: eval-sanitize-40-r4-055-48dtb
60.2736,Event,ADDED,eval-sanitize-40-r4-056-4bf68.18d40a085a156097,"reason=FailedScheduling count=None msg=0/6 nodes are available: 1 c_wall violated: 1 conflicting context pair(s) with node memory, 5 node(s) had untolerated taint(s). no new claims to deallocate, preemption: 0/6 nodes are available: 1 No preemption victims found for incoming pod, 5 Preemption is not helpful for scheduling."
60.2739,Event,ADDED,eval-sanitize-40-r4-056-4bf68.18d40a085aa53487,"reason=FailedScheduling count=None msg=0/6 nodes are available: 1 c_wall violated: 1 conflicting context pair(s) with node memory, 5 node(s) had untolerated taint(s). no new claims to deallocate, preemption: 0/6 nodes are available: 1 No preemption victims found for incoming pod, 5 Preemption is not helpful for scheduling."
60.2741,Event,ADDED,eval-sanitize-40-r4-056.18d40a0859d21f83,reason=SuccessfulCreate count=1 msg=Created pod: eval-sanitize-40-r4-056-4bf68
60.2743,Event,ADDED,eval-sanitize-40-r4-057-nzvpl.18d40a0899c344a4,"reason=FailedScheduling count=None msg=0/6 nodes are available: 1 c_wall violated: 1 conflicting context pair(s) with node memory, 5 node(s) had untolerated taint(s). no new claims to deallocate, preemption: 0/6 nodes are available: 1 No preemption victims found for incoming pod, 5 Preemption is not helpful for scheduling."
60.2747,Event,ADDED,eval-sanitize-40-r4-057-nzvpl.18d40a089a401bce,"reason=FailedScheduling count=None msg=0/6 nodes are available: 1 c_wall violated: 1 conflicting context pair(s) with node memory, 5 node(s) had untolerated taint(s). no new claims to deallocate, preemption: 0/6 nodes are available: 1 No preemption victims found for incoming pod, 5 Preemption is not helpful for scheduling."
60.2749,Event,ADDED,eval-sanitize-40-r4-057.18d40a089987b0fc,reason=SuccessfulCreate count=1 msg=Created pod: eval-sanitize-40-r4-057-nzvpl
60.275,Event,ADDED,eval-sanitize-40-r4-058-7z94v.18d40a08d38bba63,"reason=FailedScheduling count=None msg=0/6 nodes are available: 1 c_wall violated: 1 conflicting context pair(s) with node memory, 5 node(s) had untolerated taint(s). no new claims to deallocate, preemption: 0/6 nodes are available: 1 No preemption victims found for incoming pod, 5 Preemption is not helpful for scheduling."
60.2754,Event,ADDED,eval-sanitize-40-r4-058-7z94v.18d40a08d4072dd5,"reason=FailedScheduling count=None msg=0/6 nodes are available: 1 c_wall violated: 1 conflicting context pair(s) with node memory, 5 node(s) had untolerated taint(s). no new claims to deallocate, preemption: 0/6 nodes are available: 1 No preemption victims found for incoming pod, 5 Preemption is not helpful for scheduling."
60.2756,Event,ADDED,eval-sanitize-40-r4-058.18d40a08d3465f89,reason=SuccessfulCreate count=1 msg=Created pod: eval-sanitize-40-r4-058-7z94v
60.2758,Event,ADDED,eval-sanitize-40-r4-059-9bxnn.18d40a090d75ecdf,reason=Scheduled count=None msg=Successfully assigned compute/eval-sanitize-40-r4-059-9bxnn to kind-worker3
60.2763,Event,ADDED,eval-sanitize-40-r4-059-9bxnn.18d40a09276f7c84,"reason=Pulled count=1 msg=Container image ""busybox:musl"" already present on machine"
60.2767,Event,ADDED,eval-sanitize-40-r4-059-9bxnn.18d40a0928878e36,reason=Created count=1 msg=Created container: task
60.2772,Event,ADDED,eval-sanitize-40-r4-059-9bxnn.18d40a092e9481f3,reason=Started count=1 msg=Started container task
60.2775,Event,ADDED,eval-sanitize-40-r4-059.18d40a090ced13eb,reason=SuccessfulCreate count=1 msg=Created pod: eval-sanitize-40-r4-059-9bxnn
60.2778,Event,ADDED,eval-sanitize-40-r4-060.18d40a094840bddf,reason=SuccessfulCreate count=1 msg=Created pod: eval-sanitize-40-r4-060-cgf97
60.278,Event,ADDED,eval-sanitize-40-r4-060-cgf97.18d40a0948ca7073,reason=Scheduled count=None msg=Successfully assigned compute/eval-sanitize-40-r4-060-cgf97 to kind-worker3
60.4982,Event,ADDED,eval-sanitize-40-r4-060-cgf97.18d40a09633a1635,"reason=Pulled count=1 msg=Container image ""busybox:musl"" already present on machine"
60.5141,Event,ADDED,eval-sanitize-40-r4-060-cgf97.18d40a096448215b,reason=Created count=1 msg=Created container: task
60.5897,Event,ADDED,eval-sanitize-40-r4-060-cgf97.18d40a0968c257b9,reason=Started count=1 msg=Started container task
60.8295,Pod,MODIFIED,eval-sanitize-40-r4-050-l8twf,phase=Running node=kind-worker3
60.8365,Pod,MODIFIED,eval-sanitize-40-r4-060-cgf97,phase=Running node=kind-worker3
61.0128,TaskRequest,ADDED,eval-sanitize-40-r4-061,phase=None job=None
61.0168,TaskRequest,MODIFIED,eval-sanitize-40-r4-061,phase=Pending job=None
61.032,Job,ADDED,eval-sanitize-40-r4-061,
61.1113,Pod,ADDED,eval-sanitize-40-r4-061-dzrdw,phase=Pending node=None
61.1121,TaskRequest,MODIFIED,eval-sanitize-40-r4-061,phase=Scheduled job=None
61.1131,Job,MODIFIED,eval-sanitize-40-r4-061,
61.1138,Job,MODIFIED,eval-sanitize-40-r4-060,
61.1157,Event,ADDED,eval-sanitize-40-r4-061.18d40a0988114c12,reason=SuccessfulCreate count=1 msg=Created pod: eval-sanitize-40-r4-061-dzrdw
61.1213,Pod,MODIFIED,eval-sanitize-40-r4-061-dzrdw,phase=Pending node=None
61.1217,Event,ADDED,eval-sanitize-40-r4-061-dzrdw.18d40a09885005a3,"reason=FailedScheduling count=None msg=0/6 nodes are available: 1 c_wall violated: 1 conflicting context pair(s) with node memory, 5 node(s) had untolerated taint(s). no new claims to deallocate, preemption: 0/6 nodes are available: 1 No preemption victims found for incoming pod, 5 Preemption is not helpful for scheduling."
61.1237,TaskRequest,MODIFIED,eval-sanitize-40-r4-061,phase=Scheduled job=None
61.1261,Job,MODIFIED,eval-sanitize-40-r4-060,
61.1279,Event,ADDED,eval-sanitize-40-r4-061-dzrdw.18d40a0988e290e6,"reason=FailedScheduling count=None msg=0/6 nodes are available: 1 c_wall violated: 1 conflicting context pair(s) with node memory, 5 node(s) had untolerated taint(s). no new claims to deallocate, preemption: 0/6 nodes are available: 1 No preemption victims found for incoming pod, 5 Preemption is not helpful for scheduling."
61.8356,Job,MODIFIED,eval-sanitize-40-r4-050,
61.8456,Job,MODIFIED,eval-sanitize-40-r4-050,
61.9288,Pod,MODIFIED,eval-sanitize-40-r4-050-l8twf,phase=Succeeded node=kind-worker3
62.008,Event,MODIFIED,eval-sanitize-40-r4-061-dzrdw.18d40a0988e290e6,"reason=FailedScheduling count=None msg=0/6 nodes are available: 1 c_wall violated: 1 conflicting context pair(s) with node memory, 5 node(s) had untolerated taint(s). no new claims to deallocate, preemption: 0/6 nodes are available: 1 No preemption victims found for incoming pod, 5 Preemption is not helpful for scheduling."
62.011,TaskRequest,ADDED,eval-sanitize-40-r4-062,phase=None job=None
62.015,TaskRequest,MODIFIED,eval-sanitize-40-r4-062,phase=Pending job=None
62.0318,Job,ADDED,eval-sanitize-40-r4-062,
62.0379,TaskRequest,MODIFIED,eval-sanitize-40-r4-062,phase=Scheduled job=None
62.04,Pod,ADDED,eval-sanitize-40-r4-062-5mcl9,phase=Pending node=None
62.0418,Job,MODIFIED,eval-sanitize-40-r4-062,
62.0445,Event,ADDED,eval-sanitize-40-r4-062.18d40a09bf719578,reason=SuccessfulCreate count=1 msg=Created pod: eval-sanitize-40-r4-062-5mcl9
62.0451,TaskRequest,MODIFIED,eval-sanitize-40-r4-062,phase=Scheduled job=None
62.0494,Pod,MODIFIED,eval-sanitize-40-r4-062-5mcl9,phase=Pending node=None
62.0497,Event,ADDED,eval-sanitize-40-r4-062-5mcl9.18d40a09bfb9f5f3,"reason=FailedScheduling count=None msg=0/6 nodes are available: 1 c_wall violated: 1 conflicting context pair(s) with node memory, 5 node(s) had untolerated taint(s). no new claims to deallocate, preemption: 0/6 nodes are available: 1 No preemption victims found for incoming pod, 5 Preemption is not helpful for scheduling."
62.0579,Event,ADDED,eval-sanitize-40-r4-062-5mcl9.18d40a09c036002e,"reason=FailedScheduling count=None msg=0/6 nodes are available: 1 c_wall violated: 1 conflicting context pair(s) with node memory, 5 node(s) had untolerated taint(s). no new claims to deallocate, preemption: 0/6 nodes are available: 1 No preemption victims found for incoming pod, 5 Preemption is not helpful for scheduling."
62.1157,Job,MODIFIED,eval-sanitize-40-r4-061,
62.1247,Job,MODIFIED,eval-sanitize-40-r4-061,
62.8351,Pod,MODIFIED,eval-sanitize-40-r4-052-bt8rh,phase=Running node=kind-worker3
62.8411,Job,MODIFIED,eval-sanitize-40-r4-050,
62.8497,Pod,MODIFIED,eval-sanitize-40-r4-050-l8twf,phase=Succeeded node=kind-worker3
62.8511,Job,MODIFIED,eval-sanitize-40-r4-050,
62.9117,Event,MODIFIED,eval-sanitize-40-r4-062-5mcl9.18d40a09c036002e,"reason=FailedScheduling count=None msg=0/6 nodes are available: 1 c_wall violated: 1 conflicting context pair(s) with node memory, 5 node(s) had untolerated taint(s). no new claims to deallocate, preemption: 0/6 nodes are available: 1 No preemption victims found for incoming pod, 5 Preemption is not helpful for scheduling."
63.0149,TaskRequest,ADDED,eval-sanitize-40-r4-063,phase=None job=None
63.0186,TaskRequest,MODIFIED,eval-sanitize-40-r4-063,phase=Pending job=None
63.0361,Job,ADDED,eval-sanitize-40-r4-063,
63.0442,TaskRequest,MODIFIED,eval-sanitize-40-r4-063,phase=Scheduled job=None
63.0466,Pod,ADDED,eval-sanitize-40-r4-063-m8q9j,phase=Pending node=None
63.0495,Job,MODIFIED,eval-sanitize-40-r4-062,
63.051,Job,MODIFIED,eval-sanitize-40-r4-063,
63.0518,Event,ADDED,eval-sanitize-40-r4-063.18d40a09fb6ea4f4,reason=SuccessfulCreate count=1 msg=Created pod: eval-sanitize-40-r4-063-m8q9j
63.0545,TaskRequest,MODIFIED,eval-sanitize-40-r4-063,phase=Scheduled job=None
63.0581,Pod,MODIFIED,eval-sanitize-40-r4-063-m8q9j,phase=Pending node=None
63.0584,Event,ADDED,eval-sanitize-40-r4-063-m8q9j.18d40a09fbbbff20,"reason=FailedScheduling count=None msg=0/6 nodes are available: 1 c_wall violated: 2 conflicting context pair(s) with node memory, 5 node(s) had untolerated taint(s). no new claims to deallocate, preemption: 0/6 nodes are available: 1 No preemption victims found for incoming pod, 5 Preemption is not helpful for scheduling."
63.063,Job,MODIFIED,eval-sanitize-40-r4-062,
63.0682,Event,ADDED,eval-sanitize-40-r4-063-m8q9j.18d40a09fc5fe125,"reason=FailedScheduling count=None msg=0/6 nodes are available: 1 c_wall violated: 2 conflicting context pair(s) with node memory, 5 node(s) had untolerated taint(s). no new claims to deallocate, preemption: 0/6 nodes are available: 1 No preemption victims found for incoming pod, 5 Preemption is not helpful for scheduling."
63.8432,Job,MODIFIED,eval-sanitize-40-r4-052,
63.8475,Job,MODIFIED,eval-sanitize-40-r4-050,
63.8528,Job,MODIFIED,eval-sanitize-40-r4-050,
63.8576,Job,MODIFIED,eval-sanitize-40-r4-052,
63.8584,Event,ADDED,eval-sanitize-40-r4-050.18d40a0a2b833ca2,reason=Completed count=1 msg=Job completed
63.8652,Job,MODIFIED,eval-sanitize-40-r4-050,
63.87,TaskRequest,MODIFIED,eval-sanitize-40-r4-050,phase=Complete job=None
63.8806,Job,MODIFIED,eval-sanitize-40-r4-050,
63.9355,Pod,MODIFIED,eval-sanitize-40-r4-052-bt8rh,phase=Succeeded node=kind-worker3
64.0121,Event,MODIFIED,eval-sanitize-40-r4-063-m8q9j.18d40a09fc5fe125,"reason=FailedScheduling count=None msg=0/6 nodes are available: 1 c_wall violated: 2 conflicting context pair(s) with node memory, 5 node(s) had untolerated taint(s). no new claims to deallocate, preemption: 0/6 nodes are available: 1 No preemption victims found for incoming pod, 5 Preemption is not helpful for scheduling."
64.0142,TaskRequest,ADDED,eval-sanitize-40-r4-064,phase=None job=None
64.0178,TaskRequest,MODIFIED,eval-sanitize-40-r4-064,phase=Pending job=None
64.0345,Job,ADDED,eval-sanitize-40-r4-064,
64.0409,Pod,ADDED,eval-sanitize-40-r4-064-kdgk4,phase=Pending node=None
64.0416,TaskRequest,MODIFIED,eval-sanitize-40-r4-064,phase=Scheduled job=None
64.0449,Job,MODIFIED,eval-sanitize-40-r4-064,
64.0461,Event,ADDED,eval-sanitize-40-r4-064.18d40a0a36b1cdf4,reason=SuccessfulCreate count=1 msg=Created pod: eval-sanitize-40-r4-064-kdgk4
64.05,Pod,MODIFIED,eval-sanitize-40-r4-064-kdgk4,phase=Pending node=None
64.0516,Event,ADDED,eval-sanitize-40-r4-064-kdgk4.18d40a0a36fa6cff,"reason=FailedScheduling count=None msg=0/6 nodes are available: 1 c_wall violated: 2 conflicting context pair(s) with node memory, 5 node(s) had untolerated taint(s). no new claims to deallocate, preemption: 0/6 nodes are available: 1 No preemption victims found for incoming pod, 5 Preemption is not helpful for scheduling."
64.0528,Job,MODIFIED,eval-sanitize-40-r4-063,
64.053,TaskRequest,MODIFIED,eval-sanitize-40-r4-064,phase=Scheduled job=None
64.0548,Job,MODIFIED,eval-sanitize-40-r4-064,
64.0648,Job,MODIFIED,eval-sanitize-40-r4-063,
64.0657,Job,MODIFIED,eval-sanitize-40-r4-064,
64.098,Event,ADDED,eval-sanitize-40-r4-064-kdgk4.18d40a0a39d868d9,"reason=FailedScheduling count=None msg=0/6 nodes are available: 1 c_wall violated: 2 conflicting context pair(s) with node memory, 5 node(s) had untolerated taint(s). no new claims to deallocate, preemption: 0/6 nodes are available: 1 No preemption victims found for incoming pod, 5 Preemption is not helpful for scheduling."
64.8498,Job,MODIFIED,eval-sanitize-40-r4-052,
64.8586,Pod,MODIFIED,eval-sanitize-40-r4-052-bt8rh,phase=Succeeded node=kind-worker3
64.8599,Job,MODIFIED,eval-sanitize-40-r4-052,
65.0078,TaskRequest,ADDED,eval-sanitize-40-r4-065,phase=None job=None
65.013,TaskRequest,MODIFIED,eval-sanitize-40-r4-065,phase=Pending job=None
65.0289,Job,ADDED,eval-sanitize-40-r4-065,
65.0419,Pod,ADDED,eval-sanitize-40-r4-065-7fskg,phase=Pending node=None
65.0499,TaskRequest,MODIFIED,eval-sanitize-40-r4-065,phase=Scheduled job=None
65.0522,Event,ADDED,eval-sanitize-40-r4-065.18d40a0a71f5b8e5,reason=SuccessfulCreate count=1 msg=Created pod: eval-sanitize-40-r4-065-7fskg
65.0529,Event,ADDED,eval-sanitize-40-r4-065-7fskg.18d40a0a7277f88c,"reason=FailedScheduling count=None msg=0/6 nodes are available: 1 c_wall violated: 2 conflicting context pair(s) with node memory, 5 node(s) had untolerated taint(s). no new claims to deallocate, preemption: 0/6 nodes are available: 1 No preemption victims found for incoming pod, 5 Preemption is not helpful for scheduling."
65.0537,Job,MODIFIED,eval-sanitize-40-r4-065,
65.0546,Pod,MODIFIED,eval-sanitize-40-r4-065-7fskg,phase=Pending node=None
65.0606,Job,MODIFIED,eval-sanitize-40-r4-065,
65.0622,Event,ADDED,eval-sanitize-40-r4-065-7fskg.18d40a0a7350c6bd,"reason=FailedScheduling count=None msg=0/6 nodes are available: 1 c_wall violated: 2 conflicting context pair(s) with node memory, 5 node(s) had untolerated taint(s). no new claims to deallocate, preemption: 0/6 nodes are available: 1 No preemption victims found for incoming pod, 5 Preemption is not helpful for scheduling."
65.066,TaskRequest,MODIFIED,eval-sanitize-40-r4-065,phase=Scheduled job=None
65.0718,Job,MODIFIED,eval-sanitize-40-r4-065,
65.846,Pod,MODIFIED,eval-sanitize-40-r4-055-48dtb,phase=Running node=kind-worker3
65.8566,Job,MODIFIED,eval-sanitize-40-r4-052,
65.8616,Job,MODIFIED,eval-sanitize-40-r4-052,
65.867,Event,ADDED,eval-sanitize-40-r4-052.18d40a0aa34014cf,reason=Completed count=1 msg=Job completed
65.8734,Job,MODIFIED,eval-sanitize-40-r4-052,
65.8793,TaskRequest,MODIFIED,eval-sanitize-40-r4-052,phase=Complete job=None
65.8885,Job,MODIFIED,eval-sanitize-40-r4-052,
65.9742,Event,MODIFIED,eval-sanitize-40-r4-064-kdgk4.18d40a0a39d868d9,"reason=FailedScheduling count=None msg=0/6 nodes are available: 1 c_wall violated: 2 conflicting context pair(s) with node memory, 5 node(s) had untolerated taint(s). no new claims to deallocate, preemption: 0/6 nodes are available: 1 No preemption victims found for incoming pod, 5 Preemption is not helpful for scheduling."
66.0017,Event,MODIFIED,eval-sanitize-40-r4-065-7fskg.18d40a0a7350c6bd,"reason=FailedScheduling count=None msg=0/6 nodes are available: 1 c_wall violated: 2 conflicting context pair(s) with node memory, 5 node(s) had untolerated taint(s). no new claims to deallocate, preemption: 0/6 nodes are available: 1 No preemption victims found for incoming pod, 5 Preemption is not helpful for scheduling."
66.0068,TaskRequest,ADDED,eval-sanitize-40-r4-066,phase=None job=None
66.0104,TaskRequest,MODIFIED,eval-sanitize-40-r4-066,phase=Pending job=None
66.0258,Job,ADDED,eval-sanitize-40-r4-066,
66.0309,TaskRequest,MODIFIED,eval-sanitize-40-r4-066,phase=Scheduled job=None
66.0327,Pod,ADDED,eval-sanitize-40-r4-066-4zrpl,phase=Pending node=None
66.0371,Job,MODIFIED,eval-sanitize-40-r4-066,
66.0384,Event,ADDED,eval-sanitize-40-r4-066.18d40a0aad74d7c6,reason=SuccessfulCreate count=1 msg=Created pod: eval-sanitize-40-r4-066-4zrpl
66.0418,Pod,MODIFIED,eval-sanitize-40-r4-066-4zrpl,phase=Pending node=None
66.0488,Event,ADDED,eval-sanitize-40-r4-066-4zrpl.18d40a0aadafcf96,"reason=FailedScheduling count=None msg=0/6 nodes are available: 1 c_wall violated: 1 conflicting context pair(s) with node memory, 5 node(s) had untolerated taint(s). no new claims to deallocate, preemption: 0/6 nodes are available: 1 No preemption victims found for incoming pod, 5 Preemption is not helpful for scheduling."
66.0496,TaskRequest,MODIFIED,eval-sanitize-40-r4-066,phase=Scheduled job=None
66.0618,Event,ADDED,eval-sanitize-40-r4-066-4zrpl.18d40a0aaefb06e7,"reason=FailedScheduling count=None msg=0/6 nodes are available: 1 c_wall violated: 1 conflicting context pair(s) with node memory, 5 node(s) had untolerated taint(s). no new claims to deallocate, preemption: 0/6 nodes are available: 1 No preemption victims found for incoming pod, 5 Preemption is not helpful for scheduling."
66.8512,Job,MODIFIED,eval-sanitize-40-r4-055,
66.8617,Job,MODIFIED,eval-sanitize-40-r4-055,
66.9373,Pod,MODIFIED,eval-sanitize-40-r4-055-48dtb,phase=Succeeded node=kind-worker3
67.0072,TaskRequest,ADDED,eval-sanitize-40-r4-067,phase=None job=None
67.0113,TaskRequest,MODIFIED,eval-sanitize-40-r4-067,phase=Pending job=None
67.0267,Job,ADDED,eval-sanitize-40-r4-067,
67.0309,TaskRequest,MODIFIED,eval-sanitize-40-r4-067,phase=Scheduled job=None
67.0336,Pod,ADDED,eval-sanitize-40-r4-067-rxcqs,phase=Pending node=None
67.0363,Job,MODIFIED,eval-sanitize-40-r4-067,
67.0384,Job,MODIFIED,eval-sanitize-40-r4-066,
67.0401,Event,ADDED,eval-sanitize-40-r4-067.18d40a0ae91e261f,reason=SuccessfulCreate count=1 msg=Created pod: eval-sanitize-40-r4-067-rxcqs
67.0402,TaskRequest,MODIFIED,eval-sanitize-40-r4-067,phase=Scheduled job=None
67.0466,Job,MODIFIED,eval-sanitize-40-r4-066,
67.1009,Pod,MODIFIED,eval-sanitize-40-r4-067-rxcqs,phase=Pending node=None
67.102,Event,ADDED,eval-sanitize-40-r4-067-rxcqs.18d40a0aecc8e865,"reason=FailedScheduling count=None msg=0/6 nodes are available: 1 c_wall violated: 2 conflicting context pair(s) with node memory, 5 node(s) had untolerated taint(s). no new claims to deallocate, preemption: 0/6 nodes are available: 1 No preemption victims found for incoming pod, 5 Preemption is not helpful for scheduling."
67.2023,Event,MODIFIED,eval-sanitize-40-r4-066-4zrpl.18d40a0aaefb06e7,"reason=FailedScheduling count=None msg=0/6 nodes are available: 1 c_wall violated: 1 conflicting context pair(s) with node memory, 5 node(s) had untolerated taint(s). no new claims to deallocate, preemption: 0/6 nodes are available: 1 No preemption victims found for incoming pod, 5 Preemption is not helpful for scheduling."
67.2042,Event,ADDED,eval-sanitize-40-r4-067-rxcqs.18d40a0af2e992d4,"reason=FailedScheduling count=None msg=0/6 nodes are available: 1 c_wall violated: 2 conflicting context pair(s) with node memory, 5 node(s) had untolerated taint(s). no new claims to deallocate, preemption: 0/6 nodes are available: 1 No preemption victims found for incoming pod, 5 Preemption is not helpful for scheduling."
67.8581,Job,MODIFIED,eval-sanitize-40-r4-055,
67.8656,Pod,MODIFIED,eval-sanitize-40-r4-055-48dtb,phase=Succeeded node=kind-worker3
67.8674,Job,MODIFIED,eval-sanitize-40-r4-055,
68.0076,TaskRequest,ADDED,eval-sanitize-40-r4-068,phase=None job=None
68.0127,TaskRequest,MODIFIED,eval-sanitize-40-r4-068,phase=Pending job=None
68.0273,Job,ADDED,eval-sanitize-40-r4-068,
68.0323,Pod,ADDED,eval-sanitize-40-r4-068-nk9x4,phase=Pending node=None
68.0336,TaskRequest,MODIFIED,eval-sanitize-40-r4-068,phase=Scheduled job=None
68.0387,Job,MODIFIED,eval-sanitize-40-r4-068,
68.0393,Event,ADDED,eval-sanitize-40-r4-068.18d40a0b24a480b5,reason=SuccessfulCreate count=1 msg=Created pod: eval-sanitize-40-r4-068-nk9x4
68.0401,Job,MODIFIED,eval-sanitize-40-r4-067,
68.0425,Pod,MODIFIED,eval-sanitize-40-r4-068-nk9x4,phase=Pending node=None
68.0432,Event,ADDED,eval-sanitize-40-r4-068-nk9x4.18d40a0b24e4b7b1,"reason=FailedScheduling count=None msg=0/6 nodes are available: 1 c_wall violated: 1 conflicting context pair(s) with node memory, 5 node(s) had untolerated taint(s). no new claims to deallocate, preemption: 0/6 nodes are available: 1 No preemption victims found for incoming pod, 5 Preemption is not helpful for scheduling."
68.0433,TaskRequest,MODIFIED,eval-sanitize-40-r4-068,phase=Scheduled job=None
68.0487,Job,MODIFIED,eval-sanitize-40-r4-067,
68.0504,Event,ADDED,eval-sanitize-40-r4-068-nk9x4.18d40a0b2577535f,"reason=FailedScheduling count=None msg=0/6 nodes are available: 1 c_wall violated: 1 conflicting context pair(s) with node memory, 5 node(s) had untolerated taint(s). no new claims to deallocate, preemption: 0/6 nodes are available: 1 No preemption victims found for incoming pod, 5 Preemption is not helpful for scheduling."
68.8654,Job,MODIFIED,eval-sanitize-40-r4-055,
68.8698,Job,MODIFIED,eval-sanitize-40-r4-055,
68.8746,Event,ADDED,eval-sanitize-40-r4-055.18d40a0b568fc58c,reason=Completed count=1 msg=Job completed
68.8809,Job,MODIFIED,eval-sanitize-40-r4-055,
68.8852,TaskRequest,MODIFIED,eval-sanitize-40-r4-055,phase=Complete job=None
68.8937,Job,MODIFIED,eval-sanitize-40-r4-055,
69.0083,TaskRequest,ADDED,eval-sanitize-40-r4-069,phase=None job=None
69.0118,TaskRequest,MODIFIED,eval-sanitize-40-r4-069,phase=Pending job=None
69.0271,Job,ADDED,eval-sanitize-40-r4-069,
69.0315,TaskRequest,MODIFIED,eval-sanitize-40-r4-069,phase=Scheduled job=None
69.0344,Pod,ADDED,eval-sanitize-40-r4-069-wldmk,phase=Pending node=None
69.0361,Job,MODIFIED,eval-sanitize-40-r4-069,
69.0383,Job,MODIFIED,eval-sanitize-40-r4-068,
69.0407,Event,ADDED,eval-sanitize-40-r4-069.18d40a0b605e42cb,reason=SuccessfulCreate count=1 msg=Created pod: eval-sanitize-40-r4-069-wldmk
69.0409,TaskRequest,MODIFIED,eval-sanitize-40-r4-069,phase=Scheduled job=None
69.0434,Pod,MODIFIED,eval-sanitize-40-r4-069-wldmk,phase=Pending node=None
69.0437,Event,ADDED,eval-sanitize-40-r4-069-wldmk.18d40a0b609bad28,"reason=FailedScheduling count=None msg=0/6 nodes are available: 1 c_wall violated: 1 conflicting context pair(s) with node memory, 5 node(s) had untolerated taint(s). no new claims to deallocate, preemption: 0/6 nodes are available: 1 No preemption victims found for incoming pod, 5 Preemption is not helpful for scheduling."
69.0468,Job,MODIFIED,eval-sanitize-40-r4-068,
69.0511,Event,ADDED,eval-sanitize-40-r4-069-wldmk.18d40a0b6121d61a,"reason=FailedScheduling count=None msg=0/6 nodes are available: 1 c_wall violated: 1 conflicting context pair(s) with node memory, 5 node(s) had untolerated taint(s). no new claims to deallocate, preemption: 0/6 nodes are available: 1 No preemption victims found for incoming pod, 5 Preemption is not helpful for scheduling."
69.8535,Pod,MODIFIED,eval-sanitize-40-r4-059-9bxnn,phase=Running node=kind-worker3
69.982,Event,MODIFIED,eval-sanitize-40-r4-067-rxcqs.18d40a0af2e992d4,"reason=FailedScheduling count=None msg=0/6 nodes are available: 1 c_wall violated: 2 conflicting context pair(s) with node memory, 5 node(s) had untolerated taint(s). no new claims to deallocate, preemption: 0/6 nodes are available: 1 No preemption victims found for incoming pod, 5 Preemption is not helpful for scheduling."
69.9948,Event,MODIFIED,eval-sanitize-40-r4-068-nk9x4.18d40a0b2577535f,"reason=FailedScheduling count=None msg=0/6 nodes are available: 1 c_wall violated: 1 conflicting context pair(s) with node memory, 5 node(s) had untolerated taint(s). no new claims to deallocate, preemption: 0/6 nodes are available: 1 No preemption victims found for incoming pod, 5 Preemption is not helpful for scheduling."
70.0416,Job,MODIFIED,eval-sanitize-40-r4-069,
70.0524,Job,MODIFIED,eval-sanitize-40-r4-069,
70.0643,Event,MODIFIED,eval-sanitize-40-r4-069-wldmk.18d40a0b6121d61a,"reason=FailedScheduling count=None msg=0/6 nodes are available: 1 c_wall violated: 1 conflicting context pair(s) with node memory, 5 node(s) had untolerated taint(s). no new claims to deallocate, preemption: 0/6 nodes are available: 1 No preemption victims found for incoming pod, 5 Preemption is not helpful for scheduling."
70.0671,TaskRequest,ADDED,eval-sanitize-40-r4-070,phase=None job=None
70.0721,TaskRequest,MODIFIED,eval-sanitize-40-r4-070,phase=Pending job=None
70.0864,Job,ADDED,eval-sanitize-40-r4-070,
70.0929,Pod,ADDED,eval-sanitize-40-r4-070-cnbn9,phase=Pending node=None
70.0941,TaskRequest,MODIFIED,eval-sanitize-40-r4-070,phase=Scheduled job=None
70.0968,Job,MODIFIED,eval-sanitize-40-r4-070,
70.0973,Event,ADDED,eval-sanitize-40-r4-070.18d40a0b9f757bad,reason=SuccessfulCreate count=1 msg=Created pod: eval-sanitize-40-r4-070-cnbn9
70.1022,Pod,MODIFIED,eval-sanitize-40-r4-070-cnbn9,phase=Pending node=None
70.1027,Event,ADDED,eval-sanitize-40-r4-070-cnbn9.18d40a0b9fb8834f,"reason=FailedScheduling count=None msg=0/6 nodes are available: 1 c_wall violated: 2 conflicting context pair(s) with node memory, 5 node(s) had untolerated taint(s). no new claims to deallocate, preemption: 0/6 nodes are available: 1 No preemption victims found for incoming pod, 5 Preemption is not helpful for scheduling."
70.1028,TaskRequest,MODIFIED,eval-sanitize-40-r4-070,phase=Scheduled job=None
70.1104,Event,ADDED,eval-sanitize-40-r4-070-cnbn9.18d40a0ba0391b12,"reason=FailedScheduling count=None msg=0/6 nodes are available: 1 c_wall violated: 2 conflicting context pair(s) with node memory, 5 node(s) had untolerated taint(s). no new claims to deallocate, preemption: 0/6 nodes are available: 1 No preemption victims found for incoming pod, 5 Preemption is not helpful for scheduling."
70.8587,Pod,MODIFIED,eval-sanitize-40-r4-060-cgf97,phase=Running node=kind-worker3
70.8597,Job,MODIFIED,eval-sanitize-40-r4-059,
70.8698,Job,MODIFIED,eval-sanitize-40-r4-059,
70.9688,Pod,MODIFIED,eval-sanitize-40-r4-059-9bxnn,phase=Succeeded node=kind-worker3
71.0645,TaskRequest,ADDED,eval-sanitize-40-r4-071,phase=None job=None
71.0687,TaskRequest,MODIFIED,eval-sanitize-40-r4-071,phase=Pending job=None
71.086,Job,ADDED,eval-sanitize-40-r4-071,
71.0872,Event,MODIFIED,eval-sanitize-40-r4-070-cnbn9.18d40a0ba0391b12,"reason=FailedScheduling count=None msg=0/6 nodes are available: 1 c_wall violated: 2 conflicting context pair(s) with node memory, 5 node(s) had untolerated taint(s). no new claims to deallocate, preemption: 0/6 nodes are available: 1 No preemption victims found for incoming pod, 5 Preemption is not helpful for scheduling."
71.0909,Pod,ADDED,eval-sanitize-40-r4-071-fggfn,phase=Pending node=None
71.0919,TaskRequest,MODIFIED,eval-sanitize-40-r4-071,phase=Scheduled job=None
71.0945,Job,MODIFIED,eval-sanitize-40-r4-071,
71.0958,Event,ADDED,eval-sanitize-40-r4-071.18d40a0bdaf631bf,reason=SuccessfulCreate count=1 msg=Created pod: eval-sanitize-40-r4-071-fggfn
71.0984,Job,MODIFIED,eval-sanitize-40-r4-070,
71.1068,Job,MODIFIED,eval-sanitize-40-r4-070,
71.1634,TaskRequest,MODIFIED,eval-sanitize-40-r4-071,phase=Scheduled job=None
71.1692,Pod,MODIFIED,eval-sanitize-40-r4-071-fggfn,phase=Pending node=None
71.1699,Event,ADDED,eval-sanitize-40-r4-071-fggfn.18d40a0bdf56fffc,"reason=FailedScheduling count=None msg=0/6 nodes are available: 1 c_wall violated: 2 conflicting context pair(s) with node memory, 5 node(s) had untolerated taint(s). no new claims to deallocate, preemption: 0/6 nodes are available: 1 No preemption victims found for incoming pod, 5 Preemption is not helpful for scheduling."
71.2751,Event,ADDED,eval-sanitize-40-r4-071-fggfn.18d40a0be59d28eb,"reason=FailedScheduling count=None msg=0/6 nodes are available: 1 c_wall violated: 2 conflicting context pair(s) with node memory, 5 node(s) had untolerated taint(s). no new claims to deallocate, preemption: 0/6 nodes are available: 1 No preemption victims found for incoming pod, 5 Preemption is not helpful for scheduling."
71.8658,Job,MODIFIED,eval-sanitize-40-r4-060,
71.8678,Job,MODIFIED,eval-sanitize-40-r4-059,
71.8768,Job,MODIFIED,eval-sanitize-40-r4-060,
71.8783,Pod,MODIFIED,eval-sanitize-40-r4-059-9bxnn,phase=Succeeded node=kind-worker3
71.8795,Job,MODIFIED,eval-sanitize-40-r4-059,
71.951,Pod,MODIFIED,eval-sanitize-40-r4-060-cgf97,phase=Succeeded node=kind-worker3
72.0083,TaskRequest,ADDED,eval-sanitize-40-r4-072,phase=None job=None
72.012,TaskRequest,MODIFIED,eval-sanitize-40-r4-072,phase=Pending job=None
72.0295,Job,ADDED,eval-sanitize-40-r4-072,
72.035,Pod,ADDED,eval-sanitize-40-r4-072-bp7lb,phase=Pending node=None
72.0363,TaskRequest,MODIFIED,eval-sanitize-40-r4-072,phase=Scheduled job=None
72.0392,Job,MODIFIED,eval-sanitize-40-r4-072,
72.0413,Event,ADDED,eval-sanitize-40-r4-072.18d40a0c133d64f1,reason=SuccessfulCreate count=1 msg=Created pod: eval-sanitize-40-r4-072-bp7lb
72.0433,TaskRequest,MODIFIED,eval-sanitize-40-r4-072,phase=Scheduled job=None
72.072,Pod,MODIFIED,eval-sanitize-40-r4-072-bp7lb,phase=Pending node=None
72.0725,Event,ADDED,eval-sanitize-40-r4-072-bp7lb.18d40a0c14f55297,"reason=FailedScheduling count=None msg=0/6 nodes are available: 1 c_wall violated: 2 conflicting context pair(s) with node memory, 5 node(s) had untolerated taint(s). no new claims to deallocate, preemption: 0/6 nodes are available: 1 No preemption victims found for incoming pod, 5 Preemption is not helpful for scheduling."
72.1034,Job,MODIFIED,eval-sanitize-40-r4-071,
72.1123,Job,MODIFIED,eval-sanitize-40-r4-071,
72.1781,Event,MODIFIED,eval-sanitize-40-r4-071-fggfn.18d40a0be59d28eb,"reason=FailedScheduling count=None msg=0/6 nodes are available: 1 c_wall violated: 2 conflicting context pair(s) with node memory, 5 node(s) had untolerated taint(s). no new claims to deallocate, preemption: 0/6 nodes are available: 1 No preemption victims found for incoming pod, 5 Preemption is not helpful for scheduling."
72.1949,Event,ADDED,eval-sanitize-40-r4-072-bp7lb.18d40a0c1c93a061,"reason=FailedScheduling count=None msg=0/6 nodes are available: 1 c_wall violated: 2 conflicting context pair(s) with node memory, 5 node(s) had untolerated taint(s). no new claims to deallocate, preemption: 0/6 nodes are available: 1 No preemption victims found for incoming pod, 5 Preemption is not helpful for scheduling."
72.8728,Job,MODIFIED,eval-sanitize-40-r4-060,
72.8746,Job,MODIFIED,eval-sanitize-40-r4-059,
72.8792,Job,MODIFIED,eval-sanitize-40-r4-059,
72.8822,Pod,MODIFIED,eval-sanitize-40-r4-060-cgf97,phase=Succeeded node=kind-worker3
72.8836,Job,MODIFIED,eval-sanitize-40-r4-060,
72.8849,Event,ADDED,eval-sanitize-40-r4-059.18d40a0c458c9e0c,reason=Completed count=1 msg=Job completed
72.8931,Job,MODIFIED,eval-sanitize-40-r4-059,
72.8971,TaskRequest,MODIFIED,eval-sanitize-40-r4-059,phase=Complete job=None
72.9079,Job,MODIFIED,eval-sanitize-40-r4-059,
73.0082,TaskRequest,ADDED,eval-sanitize-40-r4-073,phase=None job=None
73.013,TaskRequest,MODIFIED,eval-sanitize-40-r4-073,phase=Pending job=None
73.0288,Job,ADDED,eval-sanitize-40-r4-073,
73.0352,Pod,ADDED,eval-sanitize-40-r4-073-9rm5f,phase=Pending node=None
73.0353,TaskRequest,MODIFIED,eval-sanitize-40-r4-073,phase=Scheduled job=None
73.0382,Job,MODIFIED,eval-sanitize-40-r4-073,
73.0409,Job,MODIFIED,eval-sanitize-40-r4-072,
73.0412,Event,ADDED,eval-sanitize-40-r4-073.18d40a0c4ed87cc2,reason=SuccessfulCreate count=1 msg=Created pod: eval-sanitize-40-r4-073-9rm5f
73.0452,Pod,MODIFIED,eval-sanitize-40-r4-073-9rm5f,phase=Pending node=None
73.0476,Event,ADDED,eval-sanitize-40-r4-073-9rm5f.18d40a0c4f1cfa89,"reason=FailedScheduling count=None msg=0/6 nodes are available: 1 c_wall violated: 2 conflicting context pair(s) with node memory, 5 node(s) had untolerated taint(s). no new claims to deallocate, preemption: 0/6 nodes are available: 1 No preemption victims found for incoming pod, 5 Preemption is not helpful for scheduling."
73.0478,TaskRequest,MODIFIED,eval-sanitize-40-r4-073,phase=Scheduled job=None
73.0504,Job,MODIFIED,eval-sanitize-40-r4-072,
73.0521,Event,ADDED,eval-sanitize-40-r4-073-9rm5f.18d40a0c4fab0d86,"reason=FailedScheduling count=None msg=0/6 nodes are available: 1 c_wall violated: 2 conflicting context pair(s) with node memory, 5 node(s) had untolerated taint(s). no new claims to deallocate, preemption: 0/6 nodes are available: 1 No preemption victims found for incoming pod, 5 Preemption is not helpful for scheduling."
73.8811,Job,MODIFIED,eval-sanitize-40-r4-060,
73.8853,Job,MODIFIED,eval-sanitize-40-r4-060,
73.8896,Event,ADDED,eval-sanitize-40-r4-060.18d40a0c818580f1,reason=Completed count=1 msg=Job completed
73.8967,Job,MODIFIED,eval-sanitize-40-r4-060,
73.9007,TaskRequest,MODIFIED,eval-sanitize-40-r4-060,phase=Complete job=None
73.9101,Job,MODIFIED,eval-sanitize-40-r4-060,
74.0085,TaskRequest,ADDED,eval-sanitize-40-r4-074,phase=None job=None
74.0123,TaskRequest,MODIFIED,eval-sanitize-40-r4-074,phase=Pending job=None
74.0287,Job,ADDED,eval-sanitize-40-r4-074,
74.0335,TaskRequest,MODIFIED,eval-sanitize-40-r4-074,phase=Scheduled job=None
74.0363,Pod,ADDED,eval-sanitize-40-r4-074-jx89s,phase=Pending node=None
74.0382,Job,MODIFIED,eval-sanitize-40-r4-074,
74.0404,Job,MODIFIED,eval-sanitize-40-r4-073,
74.0428,TaskRequest,MODIFIED,eval-sanitize-40-r4-074,phase=Scheduled job=None
74.0433,Event,ADDED,eval-sanitize-40-r4-074.18d40a0c8a8632fa,reason=SuccessfulCreate count=1 msg=Created pod: eval-sanitize-40-r4-074-jx89s
74.0468,Pod,MODIFIED,eval-sanitize-40-r4-074-jx89s,phase=Pending node=None
74.0472,Event,ADDED,eval-sanitize-40-r4-074-jx89s.18d40a0c8ac9d66d,"reason=FailedScheduling count=None msg=0/6 nodes are available: 1 c_wall violated: 1 conflicting context pair(s) with node memory, 5 node(s) had untolerated taint(s). no new claims to deallocate, preemption: 0/6 nodes are available: 1 No preemption victims found for incoming pod, 5 Preemption is not helpful for scheduling."
74.0508,Job,MODIFIED,eval-sanitize-40-r4-073,
74.0534,Event,ADDED,eval-sanitize-40-r4-074-jx89s.18d40a0c8b589363,"reason=FailedScheduling count=None msg=0/6 nodes are available: 1 c_wall violated: 1 conflicting context pair(s) with node memory, 5 node(s) had untolerated taint(s). no new claims to deallocate, preemption: 0/6 nodes are available: 1 No preemption victims found for incoming pod, 5 Preemption is not helpful for scheduling."
75.0137,TaskRequest,ADDED,eval-sanitize-40-r4-075,phase=None job=None
75.0179,TaskRequest,MODIFIED,eval-sanitize-40-r4-075,phase=Pending job=None
75.0333,Job,ADDED,eval-sanitize-40-r4-075,
75.0393,Pod,ADDED,eval-sanitize-40-r4-075-bgjbw,phase=Pending node=None
75.0404,TaskRequest,MODIFIED,eval-sanitize-40-r4-075,phase=Scheduled job=None
75.0418,Job,MODIFIED,eval-sanitize-40-r4-074,
75.0431,Job,MODIFIED,eval-sanitize-40-r4-075,
75.0447,Event,ADDED,eval-sanitize-40-r4-075.18d40a0cc64d7744,reason=SuccessfulCreate count=1 msg=Created pod: eval-sanitize-40-r4-075-bgjbw
75.0515,Pod,MODIFIED,eval-sanitize-40-r4-075-bgjbw,phase=Pending node=kind-worker3
75.0518,TaskRequest,MODIFIED,eval-sanitize-40-r4-075,phase=Scheduled job=None
75.0548,Job,MODIFIED,eval-sanitize-40-r4-074,
75.0556,Event,ADDED,eval-sanitize-40-r4-075-bgjbw.18d40a0cc702caf9,reason=Scheduled count=None msg=Successfully assigned compute/eval-sanitize-40-r4-075-bgjbw to kind-worker3
75.0639,Pod,MODIFIED,eval-sanitize-40-r4-075-bgjbw,phase=Pending node=kind-worker3
75.2986,Event,MODIFIED,eval-sanitize-40-r4-072-bp7lb.18d40a0c1c93a061,"reason=FailedScheduling count=None msg=0/6 nodes are available: 1 c_wall violated: 2 conflicting context pair(s) with node memory, 5 node(s) had untolerated taint(s). no new claims to deallocate, preemption: 0/6 nodes are available: 1 No preemption victims found for incoming pod, 5 Preemption is not helpful for scheduling."
75.3019,Event,MODIFIED,eval-sanitize-40-r4-073-9rm5f.18d40a0c4fab0d86,"reason=FailedScheduling count=None msg=0/6 nodes are available: 1 c_wall violated: 2 conflicting context pair(s) with node memory, 5 node(s) had untolerated taint(s). no new claims to deallocate, preemption: 0/6 nodes are available: 1 No preemption victims found for incoming pod, 5 Preemption is not helpful for scheduling."
75.305,Event,MODIFIED,eval-sanitize-40-r4-074-jx89s.18d40a0c8b589363,"reason=FailedScheduling count=None msg=0/6 nodes are available: 1 c_wall violated: 1 conflicting context pair(s) with node memory, 5 node(s) had untolerated taint(s). no new claims to deallocate, preemption: 0/6 nodes are available: 1 No preemption victims found for incoming pod, 5 Preemption is not helpful for scheduling."
75.5146,Event,ADDED,eval-sanitize-40-r4-075-bgjbw.18d40a0ce265126a,"reason=Pulled count=1 msg=Container image ""busybox:musl"" already present on machine"
75.5315,Event,ADDED,eval-sanitize-40-r4-075-bgjbw.18d40a0ce370034a,reason=Created count=1 msg=Created container: task
75.6355,Event,ADDED,eval-sanitize-40-r4-075-bgjbw.18d40a0ce99eda18,reason=Started count=1 msg=Started container task
75.8698,Pod,MODIFIED,eval-sanitize-40-r4-075-bgjbw,phase=Running node=kind-worker3
76.009,TaskRequest,ADDED,eval-sanitize-40-r4-076,phase=None job=None
76.0128,TaskRequest,MODIFIED,eval-sanitize-40-r4-076,phase=Pending job=None
76.0291,Job,ADDED,eval-sanitize-40-r4-076,
76.0325,TaskRequest,MODIFIED,eval-sanitize-40-r4-076,phase=Scheduled job=None
76.0358,Pod,ADDED,eval-sanitize-40-r4-076-d9swp,phase=Pending node=None
76.039,Job,MODIFIED,eval-sanitize-40-r4-076,
76.0404,Event,ADDED,eval-sanitize-40-r4-076.18d40a0d01b3ee81,reason=SuccessfulCreate count=1 msg=Created pod: eval-sanitize-40-r4-076-d9swp
76.0405,TaskRequest,MODIFIED,eval-sanitize-40-r4-076,phase=Scheduled job=None
76.0431,Job,MODIFIED,eval-sanitize-40-r4-075,
76.0521,Job,MODIFIED,eval-sanitize-40-r4-075,
76.0677,Pod,MODIFIED,eval-sanitize-40-r4-076-d9swp,phase=Pending node=None
76.0686,Event,ADDED,eval-sanitize-40-r4-076-d9swp.18d40a0d0351c3f2,"reason=FailedScheduling count=None msg=0/6 nodes are available: 1 c_wall violated: 2 conflicting context pair(s) with node memory, 5 node(s) had untolerated taint(s). no new claims to deallocate, preemption: 0/6 nodes are available: 1 No preemption victims found for incoming pod, 5 Preemption is not helpful for scheduling."
76.1651,Event,ADDED,eval-sanitize-40-r4-076-d9swp.18d40a0d0917e1b7,"reason=FailedScheduling count=None msg=0/6 nodes are available: 1 c_wall violated: 2 conflicting context pair(s) with node memory, 5 node(s) had untolerated taint(s). no new claims to deallocate, preemption: 0/6 nodes are available: 1 No preemption victims found for incoming pod, 5 Preemption is not helpful for scheduling."
77.008,TaskRequest,ADDED,eval-sanitize-40-r4-077,phase=None job=None
77.0133,TaskRequest,MODIFIED,eval-sanitize-40-r4-077,phase=Pending job=None
77.028,Job,ADDED,eval-sanitize-40-r4-077,
77.0346,Pod,ADDED,eval-sanitize-40-r4-077-2fbzp,phase=Pending node=None
77.0359,TaskRequest,MODIFIED,eval-sanitize-40-r4-077,phase=Scheduled job=None
77.039,Job,MODIFIED,eval-sanitize-40-r4-077,
77.0407,Event,ADDED,eval-sanitize-40-r4-077.18d40a0d3d393ed0,reason=SuccessfulCreate count=1 msg=Created pod: eval-sanitize-40-r4-077-2fbzp
77.0415,Job,MODIFIED,eval-sanitize-40-r4-076,
77.0436,Pod,MODIFIED,eval-sanitize-40-r4-077-2fbzp,phase=Pending node=None
77.0452,Event,ADDED,eval-sanitize-40-r4-077-2fbzp.18d40a0d3d7b4cf0,"reason=FailedScheduling count=None msg=0/6 nodes are available: 1 c_wall violated: 1 conflicting context pair(s) with node memory, 5 node(s) had untolerated taint(s). no new claims to deallocate, preemption: 0/6 nodes are available: 1 No preemption victims found for incoming pod, 5 Preemption is not helpful for scheduling."
77.0454,TaskRequest,MODIFIED,eval-sanitize-40-r4-077,phase=Scheduled job=None
77.0503,Job,MODIFIED,eval-sanitize-40-r4-076,
77.0507,Event,ADDED,eval-sanitize-40-r4-077-2fbzp.18d40a0d3e017ec3,"reason=FailedScheduling count=None msg=0/6 nodes are available: 1 c_wall violated: 1 conflicting context pair(s) with node memory, 5 node(s) had untolerated taint(s). no new claims to deallocate, preemption: 0/6 nodes are available: 1 No preemption victims found for incoming pod, 5 Preemption is not helpful for scheduling."
78.008,TaskRequest,ADDED,eval-sanitize-40-r4-078,phase=None job=None
78.0134,TaskRequest,MODIFIED,eval-sanitize-40-r4-078,phase=Pending job=None
78.0281,Job,ADDED,eval-sanitize-40-r4-078,
78.035,Pod,ADDED,eval-sanitize-40-r4-078-2m598,phase=Pending node=None
78.0374,TaskRequest,MODIFIED,eval-sanitize-40-r4-078,phase=Scheduled job=None
78.0419,Job,MODIFIED,eval-sanitize-40-r4-078,
78.0428,Job,MODIFIED,eval-sanitize-40-r4-077,
78.0451,Event,ADDED,eval-sanitize-40-r4-078.18d40a0d78dcdcf7,reason=SuccessfulCreate count=1 msg=Created pod: eval-sanitize-40-r4-078-2m598
78.0464,Pod,MODIFIED,eval-sanitize-40-r4-078-2m598,phase=Pending node=kind-worker3
78.0465,TaskRequest,MODIFIED,eval-sanitize-40-r4-078,phase=Scheduled job=None
78.0508,Event,ADDED,eval-sanitize-40-r4-078-2m598.18d40a0d797c2188,reason=Scheduled count=None msg=Successfully assigned compute/eval-sanitize-40-r4-078-2m598 to kind-worker3
78.054,Job,MODIFIED,eval-sanitize-40-r4-077,
78.0565,Pod,MODIFIED,eval-sanitize-40-r4-078-2m598,phase=Pending node=kind-worker3
78.3027,Event,MODIFIED,eval-sanitize-40-r4-076-d9swp.18d40a0d0917e1b7,"reason=FailedScheduling count=None msg=0/6 nodes are available: 1 c_wall violated: 2 conflicting context pair(s) with node memory, 5 node(s) had untolerated taint(s). no new claims to deallocate, preemption: 0/6 nodes are available: 1 No preemption victims found for incoming pod, 5 Preemption is not helpful for scheduling."
78.3047,Event,MODIFIED,eval-sanitize-40-r4-077-2fbzp.18d40a0d3e017ec3,"reason=FailedScheduling count=None msg=0/6 nodes are available: 1 c_wall violated: 1 conflicting context pair(s) with node memory, 5 node(s) had untolerated taint(s). no new claims to deallocate, preemption: 0/6 nodes are available: 1 No preemption victims found for incoming pod, 5 Preemption is not helpful for scheduling."
78.5155,Event,ADDED,eval-sanitize-40-r4-078-2m598.18d40a0d953dae1b,"reason=Pulled count=1 msg=Container image ""busybox:musl"" already present on machine"
78.5349,Event,ADDED,eval-sanitize-40-r4-078-2m598.18d40a0d96703fe5,reason=Created count=1 msg=Created container: task
78.6191,Event,ADDED,eval-sanitize-40-r4-078-2m598.18d40a0d9b75a38c,reason=Started count=1 msg=Started container task
78.6711,Node,MODIFIED,kind-worker,taints=1
78.6863,Node,MODIFIED,kind-worker,taints=0
78.694,Pod,MODIFIED,eval-sanitize-40-r4-056-4bf68,phase=Pending node=kind-worker
78.6971,Node,MODIFIED,kind-worker,taints=0
78.6993,Event,ADDED,eval-sanitize-40-r4-056-4bf68.18d40a0da0207545,reason=Scheduled count=None msg=Successfully assigned compute/eval-sanitize-40-r4-056-4bf68 to kind-worker
78.7051,Pod,MODIFIED,eval-sanitize-40-r4-056-4bf68,phase=Pending node=kind-worker
78.7263,Node,MODIFIED,kind-worker,taints=0
78.7646,Pod,MODIFIED,eval-sanitize-40-r4-057-nzvpl,phase=Pending node=None
78.7761,Pod,MODIFIED,eval-sanitize-40-r4-058-7z94v,phase=Pending node=None
78.7872,Pod,MODIFIED,eval-sanitize-40-r4-047-nzdwf,phase=Pending node=kind-worker
78.7927,Event,ADDED,eval-sanitize-40-r4-047-nzdwf.18d40a0da5d356c4,reason=Scheduled count=None msg=Successfully assigned compute/eval-sanitize-40-r4-047-nzdwf to kind-worker
78.7973,Pod,MODIFIED,eval-sanitize-40-r4-047-nzdwf,phase=Pending node=kind-worker
78.867,Pod,MODIFIED,eval-sanitize-40-r4-053-mfqvs,phase=Pending node=kind-worker
78.8697,Pod,MODIFIED,eval-sanitize-40-r4-054-4hwn6,phase=Pending node=None
78.8747,Node,MODIFIED,kind-worker2,taints=1
78.8752,Event,ADDED,eval-sanitize-40-r4-053-mfqvs.18d40a0daa746335,reason=Scheduled count=None msg=Successfully assigned compute/eval-sanitize-40-r4-053-mfqvs to kind-worker
78.8767,Node,MODIFIED,kind-worker,taints=0
78.8814,Pod,MODIFIED,eval-sanitize-40-r4-078-2m598,phase=Running node=kind-worker3
78.8831,Pod,MODIFIED,eval-sanitize-40-r4-053-mfqvs,phase=Pending node=kind-worker
78.8839,Pod,MODIFIED,eval-sanitize-40-r4-051-7cqjl,phase=Pending node=None
78.892,Node,MODIFIED,kind-worker2,taints=0
78.8941,Node,MODIFIED,kind-worker,taints=0
78.9018,Node,MODIFIED,kind-worker2,taints=0
78.9597,Node,MODIFIED,kind-worker,taints=0
78.9639,Pod,MODIFIED,eval-sanitize-40-r4-048-6xppp,phase=Pending node=kind-worker
78.9675,Event,ADDED,eval-sanitize-40-r4-048-6xppp.18d40a0db039331f,reason=Scheduled count=None msg=Successfully assigned compute/eval-sanitize-40-r4-048-6xppp to kind-worker
78.9726,Pod,MODIFIED,eval-sanitize-40-r4-049-p2zf8,phase=Pending node=kind-worker2
78.9789,Pod,MODIFIED,eval-sanitize-40-r4-048-6xppp,phase=Pending node=kind-worker
78.9801,Event,ADDED,eval-sanitize-40-r4-049-p2zf8.18d40a0db0beb046,reason=Scheduled count=None msg=Successfully assigned compute/eval-sanitize-40-r4-049-p2zf8 to kind-worker2
78.982,Node,MODIFIED,kind-worker2,taints=0
78.9841,Node,MODIFIED,kind-worker,taints=0
78.9853,Pod,MODIFIED,eval-sanitize-40-r4-049-p2zf8,phase=Pending node=kind-worker2
79.0052,Node,MODIFIED,kind-worker2,taints=0
79.0066,TaskRequest,ADDED,eval-sanitize-40-r4-079,phase=None job=None
79.0103,TaskRequest,MODIFIED,eval-sanitize-40-r4-079,phase=Pending job=None
79.0157,Node,MODIFIED,kind-worker2,taints=0
79.0277,Job,ADDED,eval-sanitize-40-r4-079,
79.0319,TaskRequest,MODIFIED,eval-sanitize-40-r4-079,phase=Scheduled job=None
79.0363,Pod,ADDED,eval-sanitize-40-r4-079-8z9d6,phase=Pending node=None
79.0431,Job,MODIFIED,eval-sanitize-40-r4-079,
79.0435,TaskRequest,MODIFIED,eval-sanitize-40-r4-079,phase=Scheduled job=None
79.0443,Job,MODIFIED,eval-sanitize-40-r4-078,
79.0446,Event,ADDED,eval-sanitize-40-r4-079.18d40a0db48bc1c5,reason=SuccessfulCreate count=1 msg=Created pod: eval-sanitize-40-r4-079-8z9d6
79.0535,Job,MODIFIED,eval-sanitize-40-r4-078,
79.0656,Pod,MODIFIED,eval-sanitize-40-r4-041-lgn9n,phase=Pending node=kind-worker2
79.0692,Event,ADDED,eval-sanitize-40-r4-041-lgn9n.18d40a0db6482cff,reason=Scheduled count=None msg=Successfully assigned compute/eval-sanitize-40-r4-041-lgn9n to kind-worker2
79.0754,Pod,MODIFIED,eval-sanitize-40-r4-041-lgn9n,phase=Pending node=kind-worker2
79.1029,Pod,MODIFIED,eval-sanitize-40-r4-079-8z9d6,phase=Pending node=kind-worker3
79.1091,Event,ADDED,eval-sanitize-40-r4-079-8z9d6.18d40a0db87fd93e,reason=Scheduled count=None msg=Successfully assigned compute/eval-sanitize-40-r4-079-8z9d6 to kind-worker3
79.1162,Pod,MODIFIED,eval-sanitize-40-r4-079-8z9d6,phase=Pending node=kind-worker3
79.1615,Event,ADDED,eval-sanitize-40-r4-056-4bf68.18d40a0dbbbb622a,"reason=Pulled count=1 msg=Container image ""busybox:musl"" already present on machine"
79.174,Pod,MODIFIED,eval-sanitize-40-r4-071-fggfn,phase=Pending node=kind-worker2
79.1774,Event,ADDED,eval-sanitize-40-r4-071-fggfn.18d40a0dbcb4e359,reason=Scheduled count=None msg=Successfully assigned compute/eval-sanitize-40-r4-071-fggfn to kind-worker2
79.1862,Node,MODIFIED,kind-worker2,taints=0
79.1876,Event,ADDED,eval-sanitize-40-r4-056-4bf68.18d40a0dbd203b64,reason=Created count=1 msg=Created container: task
79.1889,Pod,MODIFIED,eval-sanitize-40-r4-071-fggfn,phase=Pending node=kind-worker2
79.1966,Node,MODIFIED,kind-worker2,taints=0
79.2713,Pod,MODIFIED,eval-sanitize-40-r4-072-bp7lb,phase=Pending node=kind-worker2
79.2752,Event,ADDED,eval-sanitize-40-r4-072-bp7lb.18d40a0dc287e220,reason=Scheduled count=None msg=Successfully assigned compute/eval-sanitize-40-r4-072-bp7lb to kind-worker2
79.2803,Event,ADDED,eval-sanitize-40-r4-047-nzdwf.18d40a0dc2bdf136,"reason=Pulled count=1 msg=Container image ""busybox:musl"" already present on machine"
79.289,Pod,MODIFIED,eval-sanitize-40-r4-072-bp7lb,phase=Pending node=kind-worker2
79.2894,Event,ADDED,eval-sanitize-40-r4-056-4bf68.18d40a0dc30fb82c,reason=Started count=1 msg=Started container task
79.298,Pod,MODIFIED,eval-sanitize-40-r4-073-9rm5f,phase=Pending node=None
79.3072,Event,ADDED,eval-sanitize-40-r4-047-nzdwf.18d40a0dc47f2683,reason=Created count=1 msg=Created container: task
79.3765,Pod,MODIFIED,eval-sanitize-40-r4-074-jx89s,phase=Pending node=kind-worker
79.3816,Event,ADDED,eval-sanitize-40-r4-074-jx89s.18d40a0dc8cdfeb2,reason=Scheduled count=None msg=Successfully assigned compute/eval-sanitize-40-r4-074-jx89s to kind-worker
79.3871,Node,MODIFIED,kind-worker4,taints=1
79.3928,Pod,MODIFIED,eval-sanitize-40-r4-074-jx89s,phase=Pending node=kind-worker
79.4028,Node,MODIFIED,kind-worker4,taints=1
79.4177,Event,ADDED,eval-sanitize-40-r4-053-mfqvs.18d40a0dcaf32308,"reason=Pulled count=1 msg=Container image ""busybox:musl"" already present on machine"
79.4453,Event,ADDED,eval-sanitize-40-r4-053-mfqvs.18d40a0dcc79de2d,reason=Created count=1 msg=Created container: task
79.4579,Event,ADDED,eval-sanitize-40-r4-047-nzdwf.18d40a0dcd67ac15,reason=Started count=1 msg=Started container task
79.4716,Pod,MODIFIED,eval-sanitize-40-r4-040-d5rbc,phase=Pending node=kind-worker
79.476,Node,MODIFIED,kind-worker4,taints=0
79.4788,Event,ADDED,eval-sanitize-40-r4-040-d5rbc.18d40a0dce7b5174,reason=Scheduled count=None msg=Successfully assigned compute/eval-sanitize-40-r4-040-d5rbc to kind-worker
79.4877,Pod,MODIFIED,eval-sanitize-40-r4-040-d5rbc,phase=Pending node=kind-worker
79.4912,Node,MODIFIED,kind-worker4,taints=0
79.4918,Event,ADDED,eval-sanitize-40-r4-048-6xppp.18d40a0dcf32eaf2,"reason=Pulled count=1 msg=Container image ""busybox:musl"" already present on machine"
79.492,Event,ADDED,eval-sanitize-40-r4-049-p2zf8.18d40a0dcf62040c,"reason=Pulled count=1 msg=Container image ""busybox:musl"" already present on machine"
79.4963,Event,ADDED,eval-sanitize-40-r4-053-mfqvs.18d40a0dcf848b96,reason=Started count=1 msg=Started container task
79.5188,Event,ADDED,eval-sanitize-40-r4-049-p2zf8.18d40a0dd114350d,reason=Created count=1 msg=Created container: task
79.521,Event,ADDED,eval-sanitize-40-r4-048-6xppp.18d40a0dd12f42d1,reason=Created count=1 msg=Created container: task
79.5662,Pod,MODIFIED,eval-sanitize-40-r4-044-c77pq,phase=Pending node=None
79.5687,Event,ADDED,eval-sanitize-40-r4-041-lgn9n.18d40a0dd403ddd5,"reason=Pulled count=1 msg=Container image ""busybox:musl"" already present on machine"
79.569,Event,ADDED,eval-sanitize-40-r4-079-8z9d6.18d40a0dd3fe15b8,"reason=Pulled count=1 msg=Container image ""busybox:musl"" already present on machine"
79.5738,Event,ADDED,eval-sanitize-40-r4-049-p2zf8.18d40a0dd44a9e4e,reason=Started count=1 msg=Started container task
79.5778,Event,ADDED,eval-sanitize-40-r4-048-6xppp.18d40a0dd475c58d,reason=Started count=1 msg=Started container task
79.5841,Pod,MODIFIED,eval-sanitize-40-r4-061-dzrdw,phase=Pending node=kind-worker4
79.5936,Event,ADDED,eval-sanitize-40-r4-061-dzrdw.18d40a0dd52fe5f7,reason=Scheduled count=None msg=Successfully assigned compute/eval-sanitize-40-r4-061-dzrdw to kind-worker4
79.5993,Node,MODIFIED,kind-worker4,taints=0
79.6022,Event,ADDED,eval-sanitize-40-r4-079-8z9d6.18d40a0dd5ed22ab,reason=Created count=1 msg=Created container: task
79.6038,Pod,MODIFIED,eval-sanitize-40-r4-061-dzrdw,phase=Pending node=kind-worker4
79.6093,Event,ADDED,eval-sanitize-40-r4-041-lgn9n.18d40a0dd66bae20,reason=Created count=1 msg=Created container: task
79.6137,Node,MODIFIED,kind-worker4,taints=0
79.6688,Event,ADDED,eval-sanitize-40-r4-079-8z9d6.18d40a0dd9ef1cb0,reason=Started count=1 msg=Started container task
79.6735,Event,ADDED,eval-sanitize-40-r4-041-lgn9n.18d40a0dda46c43d,reason=Started count=1 msg=Started container task
79.6776,Event,ADDED,eval-sanitize-40-r4-071-fggfn.18d40a0dda4ff692,"reason=Pulled count=1 msg=Container image ""busybox:musl"" already present on machine"
79.6945,Event,ADDED,eval-sanitize-40-r4-071-fggfn.18d40a0ddb7dba80,reason=Created count=1 msg=Created container: task
79.7073,Event,ADDED,eval-sanitize-40-r4-072-bp7lb.18d40a0ddc3d2e88,"reason=Pulled count=1 msg=Container image ""busybox:musl"" already present on machine"
79.7285,Event,ADDED,eval-sanitize-40-r4-071-fggfn.18d40a0ddd8ae383,reason=Started count=1 msg=Started container task
79.7332,Event,ADDED,eval-sanitize-40-r4-072-bp7lb.18d40a0ddda0394b,reason=Created count=1 msg=Created container: task
79.7725,Pod,MODIFIED,eval-sanitize-40-r4-062-5mcl9,phase=Pending node=kind-worker4
79.7766,Event,ADDED,eval-sanitize-40-r4-062-5mcl9.18d40a0de0672f45,reason=Scheduled count=None msg=Successfully assigned compute/eval-sanitize-40-r4-062-5mcl9 to kind-worker4
79.7838,Pod,MODIFIED,eval-sanitize-40-r4-062-5mcl9,phase=Pending node=kind-worker4
79.7871,Node,MODIFIED,kind-worker4,taints=0
79.7994,Node,MODIFIED,kind-worker4,taints=0
79.805,Event,ADDED,eval-sanitize-40-r4-072-bp7lb.18d40a0de21f4648,reason=Started count=1 msg=Started container task
79.8252,Event,ADDED,eval-sanitize-40-r4-074-jx89s.18d40a0de323f0bb,"reason=Pulled count=1 msg=Container image ""busybox:musl"" already present on machine"
79.8433,Event,ADDED,eval-sanitize-40-r4-074-jx89s.18d40a0de4706f22,reason=Created count=1 msg=Created container: task
79.8632,Pod,MODIFIED,eval-sanitize-40-r4-076-d9swp,phase=Pending node=kind-worker4
79.8666,Event,ADDED,eval-sanitize-40-r4-076-d9swp.18d40a0de5d4dfe4,reason=Scheduled count=None msg=Successfully assigned compute/eval-sanitize-40-r4-076-d9swp to kind-worker4
79.875,Node,MODIFIED,kind-worker4,taints=0
79.8775,Pod,MODIFIED,eval-sanitize-40-r4-076-d9swp,phase=Pending node=kind-worker4
79.8829,Pod,MODIFIED,eval-sanitize-40-r4-079-8z9d6,phase=Running node=kind-worker3
79.8859,Node,MODIFIED,kind-worker4,taints=0
79.8965,Pod,MODIFIED,eval-sanitize-40-r4-077-2fbzp,phase=Pending node=None
79.9086,Event,ADDED,eval-sanitize-40-r4-040-d5rbc.18d40a0de84b17bf,"reason=Pulled count=1 msg=Container image ""busybox:musl"" already present on machine"
79.9131,Event,ADDED,eval-sanitize-40-r4-074-jx89s.18d40a0de873cb5b,reason=Started count=1 msg=Started container task
79.9299,Event,ADDED,eval-sanitize-40-r4-040-d5rbc.18d40a0de97cec94,reason=Created count=1 msg=Created container: task
79.9801,Pod,MODIFIED,eval-sanitize-40-r4-063-m8q9j,phase=Pending node=kind-worker4
79.9854,Event,ADDED,eval-sanitize-40-r4-063-m8q9j.18d40a0decc4da72,reason=Scheduled count=None msg=Successfully assigned compute/eval-sanitize-40-r4-063-m8q9j to kind-worker4
79.992,Pod,MODIFIED,eval-sanitize-40-r4-063-m8q9j,phase=Pending node=kind-worker4
80.0077,TaskRequest,ADDED,eval-sanitize-40-r4-080,phase=None job=None
80.0102,Event,ADDED,eval-sanitize-40-r4-040-d5rbc.18d40a0dee5fd5ea,reason=Started count=1 msg=Started container task
80.0126,TaskRequest,MODIFIED,eval-sanitize-40-r4-080,phase=Pending job=None
80.0143,Event,ADDED,eval-sanitize-40-r4-061-dzrdw.18d40a0deeab5f54,"reason=Pulled count=1 msg=Container image ""busybox:musl"" already present on machine"
80.0289,Job,ADDED,eval-sanitize-40-r4-080,
80.0332,TaskRequest,MODIFIED,eval-sanitize-40-r4-080,phase=Scheduled job=None
80.037,Pod,ADDED,eval-sanitize-40-r4-080-5hk4s,phase=Pending node=None
80.0383,Event,ADDED,eval-sanitize-40-r4-061-dzrdw.18d40a0defe824d9,reason=Created count=1 msg=Created container: task
80.039,Job,MODIFIED,eval-sanitize-40-r4-080,
80.041,Job,MODIFIED,eval-sanitize-40-r4-079,
80.0422,Event,ADDED,eval-sanitize-40-r4-080.18d40a0df02d2594,reason=SuccessfulCreate count=1 msg=Created pod: eval-sanitize-40-r4-080-5hk4s
80.0423,TaskRequest,MODIFIED,eval-sanitize-40-r4-080,phase=Scheduled job=None
80.0497,Job,MODIFIED,eval-sanitize-40-r4-079,
80.0761,Pod,MODIFIED,eval-sanitize-40-r4-064-kdgk4,phase=Pending node=kind-worker4
80.0812,Event,ADDED,eval-sanitize-40-r4-064-kdgk4.18d40a0df287964e,reason=Scheduled count=None msg=Successfully assigned compute/eval-sanitize-40-r4-064-kdgk4 to kind-worker4
80.0841,Node,MODIFIED,kind-worker5,taints=1
80.0877,Node,MODIFIED,kind-worker4,taints=0
80.0905,Pod,MODIFIED,eval-sanitize-40-r4-064-kdgk4,phase=Pending node=kind-worker4
80.1033,Pod,MODIFIED,eval-sanitize-40-r4-040-d5rbc,phase=Running node=kind-worker
80.1118,Pod,MODIFIED,eval-sanitize-40-r4-053-mfqvs,phase=Running node=kind-worker
80.1125,Event,ADDED,eval-sanitize-40-r4-061-dzrdw.18d40a0df480b6ab,reason=Started count=1 msg=Started container task
80.1193,Pod,MODIFIED,eval-sanitize-40-r4-074-jx89s,phase=Running node=kind-worker
80.1256,Pod,MODIFIED,eval-sanitize-40-r4-056-4bf68,phase=Running node=kind-worker
80.1318,Pod,MODIFIED,eval-sanitize-40-r4-047-nzdwf,phase=Running node=kind-worker
80.1382,Pod,MODIFIED,eval-sanitize-40-r4-048-6xppp,phase=Running node=kind-worker
80.1817,Pod,MODIFIED,eval-sanitize-40-r4-080-5hk4s,phase=Pending node=kind-worker2
80.1909,Node,MODIFIED,kind-worker5,taints=0
80.1912,Event,ADDED,eval-sanitize-40-r4-080-5hk4s.18d40a0df8c33f48,reason=Scheduled count=None msg=Successfully assigned compute/eval-sanitize-40-r4-080-5hk4s to kind-worker2
80.1931,Node,MODIFIED,kind-worker4,taints=0
80.2008,Node,MODIFIED,kind-worker5,taints=0
80.2026,Pod,MODIFIED,eval-sanitize-40-r4-080-5hk4s,phase=Pending node=kind-worker2
80.2137,Node,MODIFIED,kind-worker5,taints=0
80.2146,Event,ADDED,eval-sanitize-40-r4-062-5mcl9.18d40a0dfa921b6f,"reason=Pulled count=1 msg=Container image ""busybox:musl"" already present on machine"
80.2386,Event,ADDED,eval-sanitize-40-r4-062-5mcl9.18d40a0dfbfa31c9,reason=Created count=1 msg=Created container: task
80.2735,Pod,MODIFIED,eval-sanitize-40-r4-065-7fskg,phase=Pending node=None
80.3136,Event,ADDED,eval-sanitize-40-r4-062-5mcl9.18d40a0e004eeae4,reason=Started count=1 msg=Started container task
80.3178,Event,ADDED,eval-sanitize-40-r4-076-d9swp.18d40a0e009b6006,"reason=Pulled count=1 msg=Container image ""busybox:musl"" already present on machine"
80.3407,Event,ADDED,eval-sanitize-40-r4-076-d9swp.18d40a0e02060d55,reason=Created count=1 msg=Created container: task
80.3773,Pod,MODIFIED,eval-sanitize-40-r4-066-4zrpl,phase=Pending node=kind-worker5
80.3825,Job,MODIFIED,eval-sanitize-40-r4-074,
80.3847,Event,ADDED,eval-sanitize-40-r4-066-4zrpl.18d40a0e04766567,reason=Scheduled count=None msg=Successfully assigned compute/eval-sanitize-40-r4-066-4zrpl to kind-worker5
80.3883,Pod,MODIFIED,eval-sanitize-40-r4-066-4zrpl,phase=Pending node=kind-worker5
80.3903,Node,MODIFIED,kind-worker5,taints=0
80.3949,Job,MODIFIED,eval-sanitize-40-r4-074,
80.4025,Node,MODIFIED,kind-worker5,taints=0
80.4182,Node,MODIFIED,kind-worker3,taints=1
80.4271,Event,ADDED,eval-sanitize-40-r4-076-d9swp.18d40a0e0737a73f,reason=Started count=1 msg=Started container task
80.4326,Node,MODIFIED,kind-worker3,taints=1
80.433,Event,ADDED,eval-sanitize-40-r4-063-m8q9j.18d40a0e074597e0,"reason=Pulled count=1 msg=Container image ""busybox:musl"" already present on machine"
80.448,Event,ADDED,eval-sanitize-40-r4-063-m8q9j.18d40a0e087aac71,reason=Created count=1 msg=Created container: task
80.4604,Pod,MODIFIED,eval-sanitize-40-r4-049-p2zf8,phase=Running node=kind-worker2
80.4673,Pod,MODIFIED,eval-sanitize-40-r4-071-fggfn,phase=Running node=kind-worker2
80.4735,Pod,MODIFIED,eval-sanitize-40-r4-072-bp7lb,phase=Running node=kind-worker2
80.4765,Job,MODIFIED,eval-sanitize-40-r4-040,
80.4811,Pod,MODIFIED,eval-sanitize-40-r4-041-lgn9n,phase=Running node=kind-worker2
80.4874,Job,MODIFIED,eval-sanitize-40-r4-040,
80.5008,Pod,MODIFIED,eval-sanitize-40-r4-067-rxcqs,phase=Pending node=kind-worker4
80.5059,Event,ADDED,eval-sanitize-40-r4-067-rxcqs.18d40a0e0bd4a7dc,reason=Scheduled count=None msg=Successfully assigned compute/eval-sanitize-40-r4-067-rxcqs to kind-worker4
80.5152,Pod,MODIFIED,eval-sanitize-40-r4-067-rxcqs,phase=Pending node=kind-worker4
80.5155,Event,ADDED,eval-sanitize-40-r4-064-kdgk4.18d40a0e0c34560b,"reason=Pulled count=1 msg=Container image ""busybox:musl"" already present on machine"
80.5182,Event,ADDED,eval-sanitize-40-r4-063-m8q9j.18d40a0e0c664425,reason=Started count=1 msg=Started container task
80.5342,Event,ADDED,eval-sanitize-40-r4-064-kdgk4.18d40a0e0d846b2f,reason=Created count=1 msg=Created container: task
80.6014,Pod,MODIFIED,eval-sanitize-40-r4-068-nk9x4,phase=Pending node=kind-worker5
80.6018,Event,ADDED,eval-sanitize-40-r4-064-kdgk4.18d40a0e1194cc7a,reason=Started count=1 msg=Started container task
80.6044,Event,ADDED,eval-sanitize-40-r4-068-nk9x4.18d40a0e11d1d6f4,reason=Scheduled count=None msg=Successfully assigned compute/eval-sanitize-40-r4-068-nk9x4 to kind-worker5
80.6121,Pod,MODIFIED,eval-sanitize-40-r4-068-nk9x4,phase=Pending node=kind-worker5
80.6159,Event,ADDED,eval-sanitize-40-r4-080-5hk4s.18d40a0e127c50dd,"reason=Pulled count=1 msg=Container image ""busybox:musl"" already present on machine"
80.6375,Event,ADDED,eval-sanitize-40-r4-080-5hk4s.18d40a0e13b24249,reason=Created count=1 msg=Created container: task
80.6799,Pod,MODIFIED,eval-sanitize-40-r4-069-wldmk,phase=Pending node=kind-worker5
80.6831,Event,ADDED,eval-sanitize-40-r4-069-wldmk.18d40a0e1681f761,reason=Scheduled count=None msg=Successfully assigned compute/eval-sanitize-40-r4-069-wldmk to kind-worker5
80.69,Pod,MODIFIED,eval-sanitize-40-r4-069-wldmk,phase=Pending node=kind-worker5
80.7109,Event,ADDED,eval-sanitize-40-r4-080-5hk4s.18d40a0e182571f2,reason=Started count=1 msg=Started container task
80.7792,Pod,MODIFIED,eval-sanitize-40-r4-070-cnbn9,phase=Pending node=kind-worker5
80.7828,Event,ADDED,eval-sanitize-40-r4-070-cnbn9.18d40a0e1c67f574,reason=Scheduled count=None msg=Successfully assigned compute/eval-sanitize-40-r4-070-cnbn9 to kind-worker5
80.7904,Pod,MODIFIED,eval-sanitize-40-r4-070-cnbn9,phase=Pending node=kind-worker5
80.7926,Node,MODIFIED,kind-worker5,taints=0
80.8062,Node,MODIFIED,kind-worker5,taints=0
80.8193,Event,ADDED,eval-sanitize-40-r4-066-4zrpl.18d40a0e1e9742a1,"reason=Pulled count=1 msg=Container image ""busybox:musl"" already present on machine"
80.8422,Event,ADDED,eval-sanitize-40-r4-066-4zrpl.18d40a0e1fcc704b,reason=Created count=1 msg=Created container: task
80.8502,Pod,MODIFIED,eval-sanitize-40-r4-063-m8q9j,phase=Running node=kind-worker4
80.8561,Pod,MODIFIED,eval-sanitize-40-r4-061-dzrdw,phase=Running node=kind-worker4
80.862,Pod,MODIFIED,eval-sanitize-40-r4-062-5mcl9,phase=Running node=kind-worker4
80.8694,Pod,MODIFIED,eval-sanitize-40-r4-064-kdgk4,phase=Running node=kind-worker4
80.8703,Pod,MODIFIED,eval-sanitize-40-r4-057-nzvpl,phase=Pending node=kind-worker5
80.8754,Event,ADDED,eval-sanitize-40-r4-057-nzvpl.18d40a0e21da6ef0,reason=Scheduled count=None msg=Successfully assigned compute/eval-sanitize-40-r4-057-nzvpl to kind-worker5
80.8786,Pod,MODIFIED,eval-sanitize-40-r4-076-d9swp,phase=Running node=kind-worker4
80.8816,Node,MODIFIED,kind-worker5,taints=0
80.8836,Pod,MODIFIED,eval-sanitize-40-r4-057-nzvpl,phase=Pending node=kind-worker5
80.8924,Node,MODIFIED,kind-worker5,taints=0
80.9092,Event,ADDED,eval-sanitize-40-r4-066-4zrpl.18d40a0e23f7c948,reason=Started count=1 msg=Started container task
80.9294,Event,ADDED,eval-sanitize-40-r4-067-rxcqs.18d40a0e2526b6d7,"reason=Pulled count=1 msg=Container image ""busybox:musl"" already present on machine"
80.9509,Event,ADDED,eval-sanitize-40-r4-067-rxcqs.18d40a0e267134d1,reason=Created count=1 msg=Created container: task
80.972,Pod,MODIFIED,eval-sanitize-40-r4-058-7z94v,phase=Pending node=kind-worker5
80.9766,Event,ADDED,eval-sanitize-40-r4-058-7z94v.18d40a0e27eb94fb,reason=Scheduled count=None msg=Successfully assigned compute/eval-sanitize-40-r4-058-7z94v to kind-worker5
80.9833,Pod,MODIFIED,eval-sanitize-40-r4-058-7z94v,phase=Pending node=kind-worker5
80.9856,Job,MODIFIED,eval-sanitize-40-r4-063,
80.9956,Job,MODIFIED,eval-sanitize-40-r4-063,
81.0075,TaskRequest,ADDED,eval-sanitize-40-r4-081,phase=None job=None
81.0115,Event,ADDED,eval-sanitize-40-r4-067-rxcqs.18d40a0e2a032b00,reason=Started count=1 msg=Started container task
81.0118,TaskRequest,MODIFIED,eval-sanitize-40-r4-081,phase=Pending job=None
81.0159,Event,ADDED,eval-sanitize-40-r4-068-nk9x4.18d40a0e2a3ebc4c,"reason=Pulled count=1 msg=Container image ""busybox:musl"" already present on machine"
81.0268,Job,ADDED,eval-sanitize-40-r4-081,
81.032,TaskRequest,MODIFIED,eval-sanitize-40-r4-081,phase=Scheduled job=None
81.0339,Pod,ADDED,eval-sanitize-40-r4-081-dpksd,phase=Pending node=None
81.0365,Job,MODIFIED,eval-sanitize-40-r4-081,
81.0396,Event,ADDED,eval-sanitize-40-r4-081.18d40a0e2ba4ea74,reason=SuccessfulCreate count=1 msg=Created pod: eval-sanitize-40-r4-081-dpksd
81.0445,Job,MODIFIED,eval-sanitize-40-r4-080,
81.045,Event,ADDED,eval-sanitize-40-r4-068-nk9x4.18d40a0e2bec2e52,reason=Created count=1 msg=Created container: task
81.0544,Job,MODIFIED,eval-sanitize-40-r4-080,
81.0733,Pod,MODIFIED,eval-sanitize-40-r4-066-4zrpl,phase=Running node=kind-worker5
81.0735,TaskRequest,MODIFIED,eval-sanitize-40-r4-081,phase=Scheduled job=None
81.074,Event,ADDED,eval-sanitize-40-r4-054-4hwn6.18d40a0e2db58a59,"reason=FailedScheduling count=None msg=0/6 nodes are available: 2 c_wall violated: 1 conflicting context pair(s) with node memory, 2 c_wall violated: 2 conflicting context pair(s) with node memory, 2 node(s) had untolerated taint(s). no new claims to deallocate, preemption: 0/6 nodes are available: 2 Preemption is not helpful for scheduling, 4 No preemption victims found for incoming pod."
81.075,Pod,MODIFIED,eval-sanitize-40-r4-054-4hwn6,phase=Pending node=None
81.0811,Job,MODIFIED,eval-sanitize-40-r4-064,
81.0931,Job,MODIFIED,eval-sanitize-40-r4-064,
81.1157,Event,ADDED,eval-sanitize-40-r4-068-nk9x4.18d40a0e302edbd8,reason=Started count=1 msg=Started container task
81.1187,Job,MODIFIED,eval-sanitize-40-r4-053,
81.1199,Event,ADDED,eval-sanitize-40-r4-069-wldmk.18d40a0e30310ecc,"reason=Pulled count=1 msg=Container image ""busybox:musl"" already present on machine"
81.1291,Job,MODIFIED,eval-sanitize-40-r4-053,
81.1308,Job,MODIFIED,eval-sanitize-40-r4-056,
81.137,Job,MODIFIED,eval-sanitize-40-r4-047,
81.1415,Job,MODIFIED,eval-sanitize-40-r4-056,
81.1437,Job,MODIFIED,eval-sanitize-40-r4-048,
81.1442,Event,ADDED,eval-sanitize-40-r4-069-wldmk.18d40a0e31f0f9e0,reason=Created count=1 msg=Created container: task
81.1467,Job,MODIFIED,eval-sanitize-40-r4-047,
81.153,Job,MODIFIED,eval-sanitize-40-r4-048,
81.1703,Pod,MODIFIED,eval-sanitize-40-r4-051-7cqjl,phase=Pending node=kind-worker5
81.1742,Event,ADDED,eval-sanitize-40-r4-051-7cqjl.18d40a0e33c0abc3,reason=Scheduled count=None msg=Successfully assigned compute/eval-sanitize-40-r4-051-7cqjl to kind-worker5
81.18,Pod,MODIFIED,eval-sanitize-40-r4-051-7cqjl,phase=Pending node=kind-worker5
81.2139,Event,ADDED,eval-sanitize-40-r4-070-cnbn9.18d40a0e3619769c,"reason=Pulled count=1 msg=Container image ""busybox:musl"" already present on machine"
81.2207,Event,ADDED,eval-sanitize-40-r4-069-wldmk.18d40a0e363c7f6b,reason=Started count=1 msg=Started container task
81.2392,Event,ADDED,eval-sanitize-40-r4-070-cnbn9.18d40a0e379ce534,reason=Created count=1 msg=Created container: task
81.2714,Pod,MODIFIED,eval-sanitize-40-r4-081-dpksd,phase=Pending node=kind-worker
81.2749,Event,ADDED,eval-sanitize-40-r4-081-dpksd.18d40a0e39c31664,reason=Scheduled count=None msg=Successfully assigned compute/eval-sanitize-40-r4-081-dpksd to kind-worker
81.2811,Pod,MODIFIED,eval-sanitize-40-r4-081-dpksd,phase=Pending node=kind-worker
81.2831,Node,MODIFIED,kind-worker,taints=0
81.2957,Node,MODIFIED,kind-worker,taints=0
81.3148,Event,ADDED,eval-sanitize-40-r4-070-cnbn9.18d40a0e3c263ee3,reason=Started count=1 msg=Started container task
81.3186,Event,ADDED,eval-sanitize-40-r4-057-nzvpl.18d40a0e3c5bd562,"reason=Pulled count=1 msg=Container image ""busybox:musl"" already present on machine"
81.3426,Event,ADDED,eval-sanitize-40-r4-057-nzvpl.18d40a0e3db520a6,reason=Created count=1 msg=Created container: task
81.3746,Pod,MODIFIED,eval-sanitize-40-r4-073-9rm5f,phase=Pending node=None
81.3749,Event,ADDED,eval-sanitize-40-r4-073-9rm5f.18d40a0e3f27ad24,"reason=FailedScheduling count=None msg=0/6 nodes are available: 2 c_wall violated: 1 conflicting context pair(s) with node memory, 2 c_wall violated: 2 conflicting context pair(s) with node memory, 2 node(s) had untolerated taint(s). no new claims to deallocate, preemption: 0/6 nodes are available: 2 Preemption is not helpful for scheduling, 4 No preemption victims found for incoming pod."
81.3816,Job,MODIFIED,eval-sanitize-40-r4-066,
81.3909,Job,MODIFIED,eval-sanitize-40-r4-066,
81.4224,Event,ADDED,eval-sanitize-40-r4-057-nzvpl.18d40a0e428b88e6,reason=Started count=1 msg=Started container task
81.4273,Event,ADDED,eval-sanitize-40-r4-058-7z94v.18d40a0e4295e660,"reason=Pulled count=1 msg=Container image ""busybox:musl"" already present on machine"
81.4413,Event,ADDED,eval-sanitize-40-r4-058-7z94v.18d40a0e43bbdaca,reason=Created count=1 msg=Created container: task
81.4649,Pod,MODIFIED,eval-sanitize-40-r4-044-c77pq,phase=Pending node=None
81.4664,Event,ADDED,eval-sanitize-40-r4-044-c77pq.18d40a0e44f7aa29,"reason=FailedScheduling count=None msg=0/6 nodes are available: 2 c_wall violated: 1 conflicting context pair(s) with node memory, 2 c_wall violated: 2 conflicting context pair(s) with node memory, 2 node(s) had untolerated taint(s). no new claims to deallocate, preemption: 0/6 nodes are available: 2 Preemption is not helpful for scheduling, 4 No preemption victims found for incoming pod."
81.4676,Job,MODIFIED,eval-sanitize-40-r4-049,
81.4717,Pod,MODIFIED,eval-sanitize-40-r4-080-5hk4s,phase=Running node=kind-worker2
81.4728,Job,MODIFIED,eval-sanitize-40-r4-071,
81.477,Job,MODIFIED,eval-sanitize-40-r4-049,
81.4791,Job,MODIFIED,eval-sanitize-40-r4-072,
81.482,Job,MODIFIED,eval-sanitize-40-r4-071,
81.4843,Job,MODIFIED,eval-sanitize-40-r4-041,
81.4873,Job,MODIFIED,eval-sanitize-40-r4-072,
81.4943,Job,MODIFIED,eval-sanitize-40-r4-041,
81.5032,Event,ADDED,eval-sanitize-40-r4-058-7z94v.18d40a0e47641b2e,reason=Started count=1 msg=Started container task
81.5693,Pod,MODIFIED,eval-sanitize-40-r4-077-2fbzp,phase=Pending node=kind-worker5
81.5731,Event,ADDED,eval-sanitize-40-r4-077-2fbzp.18d40a0e4b82e5a2,reason=Scheduled count=None msg=Successfully assigned compute/eval-sanitize-40-r4-077-2fbzp to kind-worker5
81.5793,Pod,MODIFIED,eval-sanitize-40-r4-077-2fbzp,phase=Pending node=kind-worker5
81.5961,Event,ADDED,eval-sanitize-40-r4-051-7cqjl.18d40a0e4ce58959,"reason=Pulled count=1 msg=Container image ""busybox:musl"" already present on machine"
81.6285,Event,ADDED,eval-sanitize-40-r4-051-7cqjl.18d40a0e4eb0c20f,reason=Created count=1 msg=Created container: task
81.6839,Pod,MODIFIED,eval-sanitize-40-r4-065-7fskg,phase=Pending node=None
81.6844,Event,ADDED,eval-sanitize-40-r4-065-7fskg.18d40a0e50f44ffd,"reason=FailedScheduling count=None msg=0/6 nodes are available: 2 c_wall violated: 1 conflicting context pair(s) with node memory, 2 c_wall violated: 2 conflicting context pair(s) with node memory, 2 node(s) had untolerated taint(s). no new claims to deallocate, preemption: 0/6 nodes are available: 2 Preemption is not helpful for scheduling, 4 No preemption victims found for incoming pod."
81.6971,Event,ADDED,eval-sanitize-40-r4-051-7cqjl.18d40a0e52e64008,reason=Started count=1 msg=Started container task
81.7086,Event,ADDED,eval-sanitize-40-r4-081-dpksd.18d40a0e53a04c0c,"reason=Pulled count=1 msg=Container image ""busybox:musl"" already present on machine"
81.7275,Event,ADDED,eval-sanitize-40-r4-081-dpksd.18d40a0e54b54fb8,reason=Created count=1 msg=Created container: task
81.7645,Event,ADDED,eval-sanitize-40-r4-054-4hwn6.18d40a0e56d54628,"reason=FailedScheduling count=None msg=0/6 nodes are available: 2 c_wall violated: 1 conflicting context pair(s) with node memory, 2 c_wall violated: 2 conflicting context pair(s) with node memory, 2 node(s) had untolerated taint(s). no new claims to deallocate, preemption: 0/6 nodes are available: 2 Preemption is not helpful for scheduling, 4 No preemption victims found for incoming pod."
81.7996,Event,ADDED,eval-sanitize-40-r4-081-dpksd.18d40a0e58fa7a82,reason=Started count=1 msg=Started container task
81.802,Event,ADDED,eval-sanitize-40-r4-073-9rm5f.18d40a0e5927578b,"reason=FailedScheduling count=None msg=0/6 nodes are available: 2 c_wall violated: 1 conflicting context pair(s) with node memory, 2 c_wall violated: 2 conflicting context pair(s) with node memory, 2 node(s) had untolerated taint(s). no new claims to deallocate, preemption: 0/6 nodes are available: 2 Preemption is not helpful for scheduling, 4 No preemption victims found for incoming pod."
81.8552,Pod,MODIFIED,eval-sanitize-40-r4-067-rxcqs,phase=Running node=kind-worker4
81.8601,Job,MODIFIED,eval-sanitize-40-r4-061,
81.8667,Job,MODIFIED,eval-sanitize-40-r4-062,
81.8686,Job,MODIFIED,eval-sanitize-40-r4-061,
81.875,Job,MODIFIED,eval-sanitize-40-r4-062,
81.8827,Job,MODIFIED,eval-sanitize-40-r4-076,
81.8908,Job,MODIFIED,eval-sanitize-40-r4-076,
81.899,Event,ADDED,eval-sanitize-40-r4-044-c77pq.18d40a0e5ef3a79d,"reason=FailedScheduling count=None msg=0/6 nodes are available: 2 c_wall violated: 1 conflicting context pair(s) with node memory, 2 c_wall violated: 2 conflicting context pair(s) with node memory, 2 node(s) had untolerated taint(s). no new claims to deallocate, preemption: 0/6 nodes are available: 2 Preemption is not helpful for scheduling, 4 No preemption victims found for incoming pod."
82.0013,Event,ADDED,eval-sanitize-40-r4-065-7fskg.18d40a0e64d32da6,"reason=FailedScheduling count=None msg=0/6 nodes are available: 2 c_wall violated: 1 conflicting context pair(s) with node memory, 2 c_wall violated: 2 conflicting context pair(s) with node memory, 2 node(s) had untolerated taint(s). no new claims to deallocate, preemption: 0/6 nodes are available: 2 Preemption is not helpful for scheduling, 4 No preemption victims found for incoming pod."
82.0084,TaskRequest,ADDED,eval-sanitize-40-r4-082,phase=None job=None
82.0089,Event,ADDED,eval-sanitize-40-r4-077-2fbzp.18d40a0e658ee81a,"reason=Pulled count=1 msg=Container image ""busybox:musl"" already present on machine"
82.0124,TaskRequest,MODIFIED,eval-sanitize-40-r4-082,phase=Pending job=None
82.0281,Job,ADDED,eval-sanitize-40-r4-082,
82.0298,Event,ADDED,eval-sanitize-40-r4-077-2fbzp.18d40a0e66cd5241,reason=Created count=1 msg=Created container: task
82.0353,Pod,ADDED,eval-sanitize-40-r4-082-qvwwd,phase=Pending node=None
82.0354,TaskRequest,MODIFIED,eval-sanitize-40-r4-082,phase=Scheduled job=None
82.0372,Job,MODIFIED,eval-sanitize-40-r4-082,
82.0394,Job,MODIFIED,eval-sanitize-40-r4-081,
82.0417,Event,ADDED,eval-sanitize-40-r4-082.18d40a0e6745e7d4,reason=SuccessfulCreate count=1 msg=Created pod: eval-sanitize-40-r4-082-qvwwd
82.0434,TaskRequest,MODIFIED,eval-sanitize-40-r4-082,phase=Scheduled job=None
82.0482,Job,MODIFIED,eval-sanitize-40-r4-081,
82.0499,Job,MODIFIED,eval-sanitize-40-r4-080,
82.0598,Job,MODIFIED,eval-sanitize-40-r4-080,
82.0769,Pod,MODIFIED,eval-sanitize-40-r4-051-7cqjl,phase=Running node=kind-worker5
82.0832,Pod,MODIFIED,eval-sanitize-40-r4-057-nzvpl,phase=Running node=kind-worker5
82.0893,Pod,MODIFIED,eval-sanitize-40-r4-058-7z94v,phase=Running node=kind-worker5
82.0977,Pod,MODIFIED,eval-sanitize-40-r4-069-wldmk,phase=Running node=kind-worker5
82.0986,Event,MODIFIED,eval-sanitize-40-r4-054-4hwn6.18d40a0e56d54628,"reason=FailedScheduling count=None msg=0/6 nodes are available: 2 c_wall violated: 1 conflicting context pair(s) with node memory, 2 c_wall violated: 2 conflicting context pair(s) with node memory, 2 node(s) had untolerated taint(s). no new claims to deallocate, preemption: 0/6 nodes are available: 2 Preemption is not helpful for scheduling, 4 No preemption victims found for incoming pod."
82.1053,Pod,MODIFIED,eval-sanitize-40-r4-068-nk9x4,phase=Running node=kind-worker5
82.1055,Event,ADDED,eval-sanitize-40-r4-077-2fbzp.18d40a0e6b458e67,reason=Started count=1 msg=Started container task
82.1114,Pod,MODIFIED,eval-sanitize-40-r4-070-cnbn9,phase=Running node=kind-worker5
82.1162,Pod,MODIFIED,eval-sanitize-40-r4-081-dpksd,phase=Running node=kind-worker
82.1754,Job,MODIFIED,eval-sanitize-40-r4-051,
82.1838,Job,MODIFIED,eval-sanitize-40-r4-051,
82.1943,Pod,MODIFIED,eval-sanitize-40-r4-082-qvwwd,phase=Pending node=kind-worker5
82.1989,Event,ADDED,eval-sanitize-40-r4-082-qvwwd.18d40a0e70c99386,reason=Scheduled count=None msg=Successfully assigned compute/eval-sanitize-40-r4-082-qvwwd to kind-worker5
82.2043,Pod,MODIFIED,eval-sanitize-40-r4-082-qvwwd,phase=Pending node=kind-worker5
82.2752,Event,MODIFIED,eval-sanitize-40-r4-073-9rm5f.18d40a0e5927578b,"reason=FailedScheduling count=None msg=0/6 nodes are available: 2 c_wall violated: 1 conflicting context pair(s) with node memory, 2 c_wall violated: 2 conflicting context pair(s) with node memory, 2 node(s) had untolerated taint(s). no new claims to deallocate, preemption: 0/6 nodes are available: 2 Preemption is not helpful for scheduling, 4 No preemption victims found for incoming pod."
82.3768,Event,MODIFIED,eval-sanitize-40-r4-044-c77pq.18d40a0e5ef3a79d,"reason=FailedScheduling count=None msg=0/6 nodes are available: 2 c_wall violated: 1 conflicting context pair(s) with node memory, 2 c_wall violated: 2 conflicting context pair(s) with node memory, 2 node(s) had untolerated taint(s). no new claims to deallocate, preemption: 0/6 nodes are available: 2 Preemption is not helpful for scheduling, 4 No preemption victims found for incoming pod."
82.4808,Event,MODIFIED,eval-sanitize-40-r4-065-7fskg.18d40a0e64d32da6,"reason=FailedScheduling count=None msg=0/6 nodes are available: 2 c_wall violated: 1 conflicting context pair(s) with node memory, 2 c_wall violated: 2 conflicting context pair(s) with node memory, 2 node(s) had untolerated taint(s). no new claims to deallocate, preemption: 0/6 nodes are available: 2 Preemption is not helpful for scheduling, 4 No preemption victims found for incoming pod."
82.616,Event,ADDED,eval-sanitize-40-r4-082-qvwwd.18d40a0e89a98e35,"reason=Pulled count=1 msg=Container image ""busybox:musl"" already present on machine"
82.634,Event,ADDED,eval-sanitize-40-r4-082-qvwwd.18d40a0e8acc3476,reason=Created count=1 msg=Created container: task
82.706,Event,ADDED,eval-sanitize-40-r4-082-qvwwd.18d40a0e8f0de31b,reason=Started count=1 msg=Started container task
82.8685,Job,MODIFIED,eval-sanitize-40-r4-067,
82.8771,Job,MODIFIED,eval-sanitize-40-r4-067,
83.0127,TaskRequest,ADDED,eval-sanitize-40-r4-083,phase=None job=None
83.0181,TaskRequest,MODIFIED,eval-sanitize-40-r4-083,phase=Pending job=None
83.0321,Job,ADDED,eval-sanitize-40-r4-083,
83.0385,Pod,ADDED,eval-sanitize-40-r4-083-pzqt8,phase=Pending node=None
83.04,TaskRequest,MODIFIED,eval-sanitize-40-r4-083,phase=Scheduled job=None
83.0408,Job,MODIFIED,eval-sanitize-40-r4-082,
83.0425,Job,MODIFIED,eval-sanitize-40-r4-083,
83.0446,Event,ADDED,eval-sanitize-40-r4-083.18d40a0ea31fe371,reason=SuccessfulCreate count=1 msg=Created pod: eval-sanitize-40-r4-083-pzqt8
83.0455,Job,MODIFIED,eval-sanitize-40-r4-081,
83.0492,TaskRequest,MODIFIED,eval-sanitize-40-r4-083,phase=Scheduled job=None
83.0517,Job,MODIFIED,eval-sanitize-40-r4-082,
83.0537,Job,MODIFIED,eval-sanitize-40-r4-081,
83.06,Pod,MODIFIED,eval-sanitize-40-r4-083-pzqt8,phase=Pending node=None
83.0604,Event,ADDED,eval-sanitize-40-r4-083-pzqt8.18d40a0ea42310e0,"reason=FailedScheduling count=None msg=0/6 nodes are available: 1 c_wall violated: 1 conflicting context pair(s) with node memory, 1 c_wall violated: 2 conflicting context pair(s) with node memory, 1 c_wall violated: 3 conflicting context pair(s) with node memory, 1 c_wall violated: 4 conflicting context pair(s) with node memory, 2 node(s) had untolerated taint(s). no new claims to deallocate, preemption: 0/6 nodes are available: 2 Preemption is not helpful for scheduling, 4 No preemption victims found for incoming pod."
83.0909,Job,MODIFIED,eval-sanitize-40-r4-057,
83.0943,Pod,MODIFIED,eval-sanitize-40-r4-082-qvwwd,phase=Running node=kind-worker5
83.0952,Job,MODIFIED,eval-sanitize-40-r4-058,
83.1015,Pod,MODIFIED,eval-sanitize-40-r4-077-2fbzp,phase=Running node=kind-worker5
83.1031,Job,MODIFIED,eval-sanitize-40-r4-057,
83.1038,Job,MODIFIED,eval-sanitize-40-r4-069,
83.1052,Job,MODIFIED,eval-sanitize-40-r4-058,
83.1055,Event,ADDED,eval-sanitize-40-r4-083-pzqt8.18d40a0ea6ddbac7,"reason=FailedScheduling count=None msg=0/6 nodes are available: 1 c_wall violated: 1 conflicting context pair(s) with node memory, 1 c_wall violated: 2 conflicting context pair(s) with node memory, 1 c_wall violated: 3 conflicting context pair(s) with node memory, 1 c_wall violated: 4 conflicting context pair(s) with node memory, 2 node(s) had untolerated taint(s). no new claims to deallocate, preemption: 0/6 nodes are available: 2 Preemption is not helpful for scheduling, 4 No preemption victims found for incoming pod."
83.1097,Job,MODIFIED,eval-sanitize-40-r4-068,
83.1139,Job,MODIFIED,eval-sanitize-40-r4-069,
83.1162,Job,MODIFIED,eval-sanitize-40-r4-070,
83.1179,Job,MODIFIED,eval-sanitize-40-r4-068,
83.1481,Job,MODIFIED,eval-sanitize-40-r4-070,
83.5147,Event,MODIFIED,eval-sanitize-40-r4-083-pzqt8.18d40a0ea6ddbac7,"reason=FailedScheduling count=None msg=0/6 nodes are available: 1 c_wall violated: 1 conflicting context pair(s) with node memory, 1 c_wall violated: 2 conflicting context pair(s) with node memory, 1 c_wall violated: 3 conflicting context pair(s) with node memory, 1 c_wall violated: 4 conflicting context pair(s) with node memory, 2 node(s) had untolerated taint(s). no new claims to deallocate, preemption: 0/6 nodes are available: 2 Preemption is not helpful for scheduling, 4 No preemption victims found for incoming pod."
84.0146,TaskRequest,ADDED,eval-sanitize-40-r4-084,phase=None job=None
84.0215,TaskRequest,MODIFIED,eval-sanitize-40-r4-084,phase=Pending job=None
84.0357,Job,ADDED,eval-sanitize-40-r4-084,
84.0422,Pod,ADDED,eval-sanitize-40-r4-084-gcr8q,phase=Pending node=None
84.0423,TaskRequest,MODIFIED,eval-sanitize-40-r4-084,phase=Scheduled job=None
84.0451,Job,MODIFIED,eval-sanitize-40-r4-083,
84.0459,Job,MODIFIED,eval-sanitize-40-r4-084,
84.0497,Job,MODIFIED,eval-sanitize-40-r4-082,
84.0508,Event,ADDED,eval-sanitize-40-r4-084.18d40a0edee777b5,reason=SuccessfulCreate count=1 msg=Created pod: eval-sanitize-40-r4-084-gcr8q
84.0509,TaskRequest,MODIFIED,eval-sanitize-40-r4-084,phase=Scheduled job=None
84.0549,Job,MODIFIED,eval-sanitize-40-r4-083,
84.0577,Job,MODIFIED,eval-sanitize-40-r4-082,
84.0651,Event,ADDED,eval-sanitize-40-r4-084-gcr8q.18d40a0edfe59a10,"reason=FailedScheduling count=None msg=0/6 nodes are available: 2 c_wall violated: 1 conflicting context pair(s) with node memory, 2 c_wall violated: 2 conflicting context pair(s) with node memory, 2 node(s) had untolerated taint(s). no new claims to deallocate, preemption: 0/6 nodes are available: 2 Preemption is not helpful for scheduling, 4 No preemption victims found for incoming pod."
84.0661,Pod,MODIFIED,eval-sanitize-40-r4-084-gcr8q,phase=Pending node=None
84.1186,Job,MODIFIED,eval-sanitize-40-r4-077,
84.119,Event,ADDED,eval-sanitize-40-r4-084-gcr8q.18d40a0ee27be0d8,"reason=FailedScheduling count=None msg=0/6 nodes are available: 2 c_wall violated: 1 conflicting context pair(s) with node memory, 2 c_wall violated: 2 conflicting context pair(s) with node memory, 2 node(s) had untolerated taint(s). no new claims to deallocate, preemption: 0/6 nodes are available: 2 Preemption is not helpful for scheduling, 4 No preemption victims found for incoming pod."
84.1271,Job,MODIFIED,eval-sanitize-40-r4-077,
85.009,TaskRequest,ADDED,eval-sanitize-40-r4-085,phase=None job=None
85.0143,TaskRequest,MODIFIED,eval-sanitize-40-r4-085,phase=Pending job=None
85.0292,Job,ADDED,eval-sanitize-40-r4-085,
85.0341,TaskRequest,MODIFIED,eval-sanitize-40-r4-085,phase=Scheduled job=None
