t_recv,kind,type,name,detail
0.0241,Node,ADDED,kind-control-plane,taints=1
0.0251,Event,ADDED,eval-sanitize-2-r2-007-dtr4x.18d3d140efae2116,"reason=FailedScheduling count=None msg=0/6 nodes are available: 1 c_wall violated: 2 conflicting context pair(s) with node memory, 5 node(s) had untolerated taint(s). no new claims to deallocate, preemption: 0/6 nodes are available: 1 No preemption victims found for incoming pod, 5 Preemption is not helpful for scheduling."
0.0264,Node,ADDED,kind-worker,taints=0
0.0268,Event,ADDED,eval-sanitize-2-r2-007-dtr4x.18d3d1410cc3bdcf,"reason=FailedScheduling count=None msg=0/6 nodes are available: 1 c_wall violated: 3 conflicting context pair(s) with node memory, 5 node(s) had untolerated taint(s). no new claims to deallocate, preemption: 0/6 nodes are available: 1 No preemption victims found for incoming pod, 5 Preemption is not helpful for scheduling."
0.027,Event,ADDED,eval-sanitize-2-r2-007-dtr4x.18d3d1415d07131b,"reason=FailedScheduling count=None msg=0/6 nodes are available: 1 c_wall violated: 2 conflicting context pair(s) with node memory, 1 c_wall violated: 3 conflicting context pair(s) with node memory, 4 node(s) had untolerated taint(s). no new claims to deallocate, preemption: 0/6 nodes are available: 2 No preemption victims found for incoming pod, 4 Preemption is not helpful for scheduling."
0.0272,Event,ADDED,eval-sanitize-2-r2-007-dtr4x.18d3d1415e7e080e,"reason=FailedScheduling count=None msg=0/6 nodes are available: 1 c_wall violated: 2 conflicting context pair(s) with node memory, 5 node(s) had untolerated taint(s). no new claims to deallocate, preemption: 0/6 nodes are available: 1 No preemption victims found for incoming pod, 5 Preemption is not helpful for scheduling."
0.0276,Event,ADDED,eval-sanitize-2-r2-010-p4cht.18d3d140ecc86e9a,"reason=FailedScheduling count=None msg=0/6 nodes are available: 1 c_wall violated: 1 conflicting context pair(s) with node memory, 5 node(s) had untolerated taint(s). no new claims to deallocate, preemption: 0/6 nodes are available: 1 No preemption victims found for incoming pod, 5 Preemption is not helpful for scheduling."
0.0278,Event,ADDED,eval-sanitize-2-r2-010-p4cht.18d3d1410cedb132,"reason=FailedScheduling count=None msg=0/6 nodes are available: 1 c_wall violated: 2 conflicting context pair(s) with node memory, 5 node(s) had untolerated taint(s). no new claims to deallocate, preemption: 0/6 nodes are available: 1 No preemption victims found for incoming pod, 5 Preemption is not helpful for scheduling."
0.0291,Node,ADDED,kind-worker2,taints=0
0.0296,Event,ADDED,eval-sanitize-2-r2-011-rd542.18d3d140ecff5fed,"reason=FailedScheduling count=None msg=0/6 nodes are available: 1 c_wall violated: 1 conflicting context pair(s) with node memory, 5 node(s) had untolerated taint(s). no new claims to deallocate, preemption: 0/6 nodes are available: 1 No preemption victims found for incoming pod, 5 Preemption is not helpful for scheduling."
0.0298,Event,ADDED,eval-sanitize-2-r2-011-rd542.18d3d1410c74c661,"reason=FailedScheduling count=None msg=0/6 nodes are available: 1 c_wall violated: 2 conflicting context pair(s) with node memory, 5 node(s) had untolerated taint(s). no new claims to deallocate, preemption: 0/6 nodes are available: 1 No preemption victims found for incoming pod, 5 Preemption is not helpful for scheduling."
0.03,Event,ADDED,eval-sanitize-2-r2-011-rd542.18d3d14159810efb,"reason=FailedScheduling count=None msg=0/6 nodes are available: 1 c_wall violated: 1 conflicting context pair(s) with node memory, 1 c_wall violated: 2 conflicting context pair(s) with node memory, 4 node(s) had untolerated taint(s). no new claims to deallocate, preemption: 0/6 nodes are available: 2 No preemption victims found for incoming pod, 4 Preemption is not helpful for scheduling."
0.0302,Event,ADDED,eval-sanitize-2-r2-011-rd542.18d3d1415e585ffe,"reason=FailedScheduling count=None msg=0/6 nodes are available: 1 c_wall violated: 1 conflicting context pair(s) with node memory, 5 node(s) had untolerated taint(s). no new claims to deallocate, preemption: 0/6 nodes are available: 1 No preemption victims found for incoming pod, 5 Preemption is not helpful for scheduling."
0.0304,Event,ADDED,eval-sanitize-2-r2-013-dczrl.18d3d140ed3908bd,"reason=FailedScheduling count=None msg=0/6 nodes are available: 1 c_wall violated: 1 conflicting context pair(s) with node memory, 5 node(s) had untolerated taint(s). no new claims to deallocate, preemption: 0/6 nodes are available: 1 No preemption victims found for incoming pod, 5 Preemption is not helpful for scheduling."
0.0306,Event,ADDED,eval-sanitize-2-r2-013-dczrl.18d3d1410c9dde38,"reason=FailedScheduling count=None msg=0/6 nodes are available: 1 c_wall violated: 2 conflicting context pair(s) with node memory, 5 node(s) had untolerated taint(s). no new claims to deallocate, preemption: 0/6 nodes are available: 1 No preemption victims found for incoming pod, 5 Preemption is not helpful for scheduling."
0.0318,Node,ADDED,kind-worker3,taints=0
0.0322,Event,ADDED,eval-sanitize-2-r2-015-mfrnk.18d3d1413ff72aa2,"reason=FailedScheduling count=None msg=0/6 nodes are available: 1 c_wall violated: 1 conflicting context pair(s) with node memory, 5 node(s) had untolerated taint(s). no new claims to deallocate, preemption: 0/6 nodes are available: 1 No preemption victims found for incoming pod, 5 Preemption is not helpful for scheduling."
0.0324,Event,ADDED,eval-sanitize-2-r2-016-bh2mh.18d3d1417e3f741c,"reason=FailedScheduling count=None msg=0/6 nodes are available: 1 c_wall violated: 2 conflicting context pair(s) with node memory, 5 node(s) had untolerated taint(s). no new claims to deallocate, preemption: 0/6 nodes are available: 1 No preemption victims found for incoming pod, 5 Preemption is not helpful for scheduling."
0.0326,Event,ADDED,eval-sanitize-2-r2-017-xzd9m.18d3d141b76563a7,"reason=FailedScheduling count=None msg=0/6 nodes are available: 2 c_wall violated: 1 conflicting context pair(s) with node memory, 4 node(s) had untolerated taint(s). no new claims to deallocate, preemption: 0/6 nodes are available: 2 No preemption victims found for incoming pod, 4 Preemption is not helpful for scheduling."
0.0329,Event,ADDED,eval-sanitize-2-r2-017-xzd9m.18d3d141d1c581ef,"reason=FailedScheduling count=None msg=0/6 nodes are available: 1 c_wall violated: 1 conflicting context pair(s) with node memory, 5 node(s) had untolerated taint(s). no new claims to deallocate, preemption: 0/6 nodes are available: 1 No preemption victims found for incoming pod, 5 Preemption is not helpful for scheduling."
0.0331,Event,ADDED,eval-sanitize-2-r2-026-q6skx.18d3d14453b9cbb7,"reason=FailedScheduling count=None msg=0/6 nodes are available: 1 c_wall violated: 1 conflicting context pair(s) with node memory, 5 node(s) had untolerated taint(s). no new claims to deallocate, preemption: 0/6 nodes are available: 1 No preemption victims found for incoming pod, 5 Preemption is not helpful for scheduling."
0.0333,Event,ADDED,eval-sanitize-2-r2-026-q6skx.18d3d1445e1ef09e,"reason=FailedScheduling count=None msg=0/6 nodes are available: 1 c_wall violated: 1 conflicting context pair(s) with node memory, 1 c_wall violated: 2 conflicting context pair(s) with node memory, 4 node(s) had untolerated taint(s). no new claims to deallocate, preemption: 0/6 nodes are available: 2 No preemption victims found for incoming pod, 4 Preemption is not helpful for scheduling."
0.0345,Node,ADDED,kind-worker4,taints=0
0.0349,Event,ADDED,eval-sanitize-2-r2-028-9bdm2.18d3d14453f03ec3,"reason=FailedScheduling count=None msg=0/6 nodes are available: 1 c_wall violated: 1 conflicting context pair(s) with node memory, 5 node(s) had untolerated taint(s). no new claims to deallocate, preemption: 0/6 nodes are available: 1 No preemption victims found for incoming pod, 5 Preemption is not helpful for scheduling."
0.0351,Event,ADDED,eval-sanitize-2-r2-028-9bdm2.18d3d14462043515,"reason=FailedScheduling count=None msg=0/6 nodes are available: 2 c_wall violated: 1 conflicting context pair(s) with node memory, 4 node(s) had untolerated taint(s). no new claims to deallocate, preemption: 0/6 nodes are available: 2 No preemption victims found for incoming pod, 4 Preemption is not helpful for scheduling."
0.0354,Event,ADDED,eval-sanitize-2-r2-032-jvkrr.18d3d14557bdc5f2,"reason=FailedScheduling count=None msg=0/6 nodes are available: 1 c_wall violated: 1 conflicting context pair(s) with node memory, 5 node(s) had untolerated taint(s). no new claims to deallocate, preemption: 0/6 nodes are available: 1 No preemption victims found for incoming pod, 5 Preemption is not helpful for scheduling."
0.0356,Event,ADDED,eval-sanitize-2-r2-032-jvkrr.18d3d14558ee0875,"reason=FailedScheduling count=None msg=0/6 nodes are available: 1 c_wall violated: 1 conflicting context pair(s) with node memory, 5 node(s) had untolerated taint(s). no new claims to deallocate, preemption: 0/6 nodes are available: 1 No preemption victims found for incoming pod, 5 Preemption is not helpful for scheduling."
0.0358,Event,ADDED,eval-sanitize-2-r2-033-knvll.18d3d1457142f41d,"reason=FailedScheduling count=None msg=0/6 nodes are available: 1 c_wall violated: 1 conflicting context pair(s) with node memory, 5 node(s) had untolerated taint(s). no new claims to deallocate, preemption: 0/6 nodes are available: 1 No preemption victims found for incoming pod, 5 Preemption is not helpful for scheduling."
0.0371,Node,ADDED,kind-worker5,taints=0
0.0374,Event,ADDED,eval-sanitize-2-r2-037-gx4tk.18d3d1473ae04cbc,"reason=FailedScheduling count=None msg=0/6 nodes are available: 1 c_wall violated: 1 conflicting context pair(s) with node memory, 5 node(s) had untolerated taint(s). no new claims to deallocate, preemption: 0/6 nodes are available: 1 No preemption victims found for incoming pod, 5 Preemption is not helpful for scheduling."
0.0376,Event,ADDED,eval-sanitize-2-r2-039-bvd2m.18d3d1473b10498d,"reason=FailedScheduling count=None msg=0/6 nodes are available: 1 c_wall violated: 1 conflicting context pair(s) with node memory, 5 node(s) had untolerated taint(s). no new claims to deallocate, preemption: 0/6 nodes are available: 1 No preemption victims found for incoming pod, 5 Preemption is not helpful for scheduling."
0.0378,Event,ADDED,eval-sanitize-2-r2-039-bvd2m.18d3d1478367cedf,"reason=FailedScheduling count=None msg=0/6 nodes are available: 2 c_wall violated: 1 conflicting context pair(s) with node memory, 4 node(s) had untolerated taint(s). no new claims to deallocate, preemption: 0/6 nodes are available: 2 No preemption victims found for incoming pod, 4 Preemption is not helpful for scheduling."
0.0383,Event,ADDED,eval-sanitize-2-r2-039-bvd2m.18d3d147b7f2dd0c,"reason=FailedScheduling count=None msg=0/6 nodes are available: 1 c_wall violated: 1 conflicting context pair(s) with node memory, 5 node(s) had untolerated taint(s). no new claims to deallocate, preemption: 0/6 nodes are available: 1 No preemption victims found for incoming pod, 5 Preemption is not helpful for scheduling."
0.0385,Event,ADDED,eval-sanitize-2-r2-040-mp4jz.18d3d1473ef820aa,"reason=FailedScheduling count=None msg=0/6 nodes are available: 1 c_wall violated: 1 conflicting context pair(s) with node memory, 5 node(s) had untolerated taint(s). no new claims to deallocate, preemption: 0/6 nodes are available: 1 No preemption victims found for incoming pod, 5 Preemption is not helpful for scheduling."
0.0387,Event,ADDED,eval-sanitize-2-r2-040-mp4jz.18d3d14783beff8c,"reason=FailedScheduling count=None msg=0/6 nodes are available: 2 c_wall violated: 1 conflicting context pair(s) with node memory, 4 node(s) had untolerated taint(s). no new claims to deallocate, preemption: 0/6 nodes are available: 2 No preemption victims found for incoming pod, 4 Preemption is not helpful for scheduling."
0.0391,Event,ADDED,eval-sanitize-2-r2-040-mp4jz.18d3d147b81c2f49,"reason=FailedScheduling count=None msg=0/6 nodes are available: 1 c_wall violated: 1 conflicting context pair(s) with node memory, 5 node(s) had untolerated taint(s). no new claims to deallocate, preemption: 0/6 nodes are available: 1 No preemption victims found for incoming pod, 5 Preemption is not helpful for scheduling."
0.0393,Event,ADDED,eval-sanitize-2-r2-041-xj2qx.18d3d1474dd853f1,"reason=FailedScheduling count=None msg=0/6 nodes are available: 1 c_wall violated: 1 conflicting context pair(s) with node memory, 5 node(s) had untolerated taint(s). no new claims to deallocate, preemption: 0/6 nodes are available: 1 No preemption victims found for incoming pod, 5 Preemption is not helpful for scheduling."
0.0395,Event,ADDED,eval-sanitize-2-r2-041-xj2qx.18d3d1478408519c,"reason=FailedScheduling count=None msg=0/6 nodes are available: 2 c_wall violated: 1 conflicting context pair(s) with node memory, 4 node(s) had untolerated taint(s). no new claims to deallocate, preemption: 0/6 nodes are available: 2 No preemption victims found for incoming pod, 4 Preemption is not helpful for scheduling."
0.0399,TaskRequest,ADDED,eval-sanitize-2-r4-000,phase=None job=None
0.0403,Event,ADDED,eval-sanitize-2-r2-041-xj2qx.18d3d147b843d47e,"reason=FailedScheduling count=None msg=0/6 nodes are available: 1 c_wall violated: 1 conflicting context pair(s) with node memory, 5 node(s) had untolerated taint(s). no new claims to deallocate, preemption: 0/6 nodes are available: 1 No preemption victims found for incoming pod, 5 Preemption is not helpful for scheduling."
0.0405,Event,ADDED,eval-sanitize-2-r2-042-8rwkk.18d3d1478a1e1ebd,"reason=FailedScheduling count=None msg=0/6 nodes are available: 2 c_wall violated: 1 conflicting context pair(s) with node memory, 4 node(s) had untolerated taint(s). no new claims to deallocate, preemption: 0/6 nodes are available: 2 No preemption victims found for incoming pod, 4 Preemption is not helpful for scheduling."
0.0407,Event,ADDED,eval-sanitize-2-r2-042-8rwkk.18d3d147b86ec5c1,"reason=FailedScheduling count=None msg=0/6 nodes are available: 1 c_wall violated: 1 conflicting context pair(s) with node memory, 5 node(s) had untolerated taint(s). no new claims to deallocate, preemption: 0/6 nodes are available: 1 No preemption victims found for incoming pod, 5 Preemption is not helpful for scheduling."
0.0411,Event,ADDED,eval-sanitize-2-r2-042-8rwkk.18d3d147efb21101,"reason=FailedScheduling count=None msg=0/6 nodes are available: 2 c_wall violated: 1 conflicting context pair(s) with node memory, 4 node(s) had untolerated taint(s). no new claims to deallocate, preemption: 0/6 nodes are available: 2 No preemption victims found for incoming pod, 4 Preemption is not helpful for scheduling."
0.0413,Event,ADDED,eval-sanitize-2-r2-042-8rwkk.18d3d147fa9274ff,"reason=FailedScheduling count=None msg=0/6 nodes are available: 1 c_wall violated: 1 conflicting context pair(s) with node memory, 5 node(s) had untolerated taint(s). no new claims to deallocate, preemption: 0/6 nodes are available: 1 No preemption victims found for incoming pod, 5 Preemption is not helpful for scheduling."
0.0416,Event,ADDED,eval-sanitize-2-r2-043-4nhhk.18d3d147c5f6b497,"reason=FailedScheduling count=None msg=0/6 nodes are available: 1 c_wall violated: 1 conflicting context pair(s) with node memory, 5 node(s) had untolerated taint(s). no new claims to deallocate, preemption: 0/6 nodes are available: 1 No preemption victims found for incoming pod, 5 Preemption is not helpful for scheduling."
0.0419,Event,ADDED,eval-sanitize-2-r2-043-4nhhk.18d3d147efff071b,"reason=FailedScheduling count=None msg=0/6 nodes are available: 2 c_wall violated: 1 conflicting context pair(s) with node memory, 4 node(s) had untolerated taint(s). no new claims to deallocate, preemption: 0/6 nodes are available: 2 No preemption victims found for incoming pod, 4 Preemption is not helpful for scheduling."
0.0421,Event,ADDED,eval-sanitize-2-r2-043-4nhhk.18d3d147fa64231a,"reason=FailedScheduling count=None msg=0/6 nodes are available: 1 c_wall violated: 1 conflicting context pair(s) with node memory, 5 node(s) had untolerated taint(s). no new claims to deallocate, preemption: 0/6 nodes are available: 1 No preemption victims found for incoming pod, 5 Preemption is not helpful for scheduling."
0.0424,Event,ADDED,eval-sanitize-2-r2-044-h9lzd.18d3d14800f4fde8,"reason=FailedScheduling count=None msg=0/6 nodes are available: 1 c_wall violated: 2 conflicting context pair(s) with node memory, 5 node(s) had untolerated taint(s). no new claims to deallocate, preemption: 0/6 nodes are available: 1 No preemption victims found for incoming pod, 5 Preemption is not helpful for scheduling."
0.0426,Event,ADDED,eval-sanitize-2-r2-045-4jx76.18d3d1483cff1daa,"reason=FailedScheduling count=None msg=0/6 nodes are available: 1 c_wall violated: 2 conflicting context pair(s) with node memory, 5 node(s) had untolerated taint(s). no new claims to deallocate, preemption: 0/6 nodes are available: 1 No preemption victims found for incoming pod, 5 Preemption is not helpful for scheduling."
0.0428,Event,ADDED,eval-sanitize-2-r2-045-4jx76.18d3d148c388ad11,"reason=FailedScheduling count=None msg=0/6 nodes are available: 1 c_wall violated: 3 conflicting context pair(s) with node memory, 5 node(s) had untolerated taint(s). no new claims to deallocate, preemption: 0/6 nodes are available: 1 No preemption victims found for incoming pod, 5 Preemption is not helpful for scheduling."
0.0432,Event,ADDED,eval-sanitize-2-r2-045-4jx76.18d3d148cb70a393,"reason=FailedScheduling count=None msg=0/6 nodes are available: 1 c_wall violated: 3 conflicting context pair(s) with node memory, 5 node(s) had untolerated taint(s). no new claims to deallocate, preemption: 0/6 nodes are available: 1 No preemption victims found for incoming pod, 5 Preemption is not helpful for scheduling."
0.0434,Event,ADDED,eval-sanitize-2-r2-049-ppsvt.18d3d1492b4fcc20,"reason=FailedScheduling count=None msg=0/6 nodes are available: 1 c_wall violated: 1 conflicting context pair(s) with node memory, 1 c_wall violated: 2 conflicting context pair(s) with node memory, 4 node(s) had untolerated taint(s). no new claims to deallocate, preemption: 0/6 nodes are available: 2 No preemption victims found for incoming pod, 4 Preemption is not helpful for scheduling."
0.0436,Event,ADDED,eval-sanitize-2-r2-049-ppsvt.18d3d1493b530ada,"reason=FailedScheduling count=None msg=0/6 nodes are available: 1 c_wall violated: 1 conflicting context pair(s) with node memory, 5 node(s) had untolerated taint(s). no new claims to deallocate, preemption: 0/6 nodes are available: 1 No preemption victims found for incoming pod, 5 Preemption is not helpful for scheduling."
0.0438,Event,ADDED,eval-sanitize-2-r2-050-drbxp.18d3d149668fb454,"reason=FailedScheduling count=None msg=0/6 nodes are available: 1 c_wall violated: 1 conflicting context pair(s) with node memory, 5 node(s) had untolerated taint(s). no new claims to deallocate, preemption: 0/6 nodes are available: 1 No preemption victims found for incoming pod, 5 Preemption is not helpful for scheduling."
0.044,Event,ADDED,eval-sanitize-2-r2-051-86jxh.18d3d14a3424b500,"reason=FailedScheduling count=None msg=0/6 nodes are available: 1 c_wall violated: 1 conflicting context pair(s) with node memory, 5 node(s) had untolerated taint(s). no new claims to deallocate, preemption: 0/6 nodes are available: 1 No preemption victims found for incoming pod, 5 Preemption is not helpful for scheduling."
0.0442,Event,ADDED,eval-sanitize-2-r2-052-9bx2m.18d3d14a3504d4a5,"reason=FailedScheduling count=None msg=0/6 nodes are available: 1 c_wall violated: 1 conflicting context pair(s) with node memory, 5 node(s) had untolerated taint(s). no new claims to deallocate, preemption: 0/6 nodes are available: 1 No preemption victims found for incoming pod, 5 Preemption is not helpful for scheduling."
0.0446,Event,ADDED,eval-sanitize-2-r2-053-9jn6r.18d3d14a353112a2,"reason=FailedScheduling count=None msg=0/6 nodes are available: 1 c_wall violated: 1 conflicting context pair(s) with node memory, 5 node(s) had untolerated taint(s). no new claims to deallocate, preemption: 0/6 nodes are available: 1 No preemption victims found for incoming pod, 5 Preemption is not helpful for scheduling."
0.0448,Event,ADDED,eval-sanitize-2-r2-053-9jn6r.18d3d14a933a2ffa,"reason=FailedScheduling count=None msg=0/6 nodes are available: 2 c_wall violated: 1 conflicting context pair(s) with node memory, 4 node(s) had untolerated taint(s). no new claims to deallocate, preemption: 0/6 nodes are available: 2 No preemption victims found for incoming pod, 4 Preemption is not helpful for scheduling."
0.0452,Event,ADDED,eval-sanitize-2-r2-053-9jn6r.18d3d14aabc49e8c,"reason=FailedScheduling count=None msg=0/6 nodes are available: 1 c_wall violated: 1 conflicting context pair(s) with node memory, 5 node(s) had untolerated taint(s). no new claims to deallocate, preemption: 0/6 nodes are available: 1 No preemption victims found for incoming pod, 5 Preemption is not helpful for scheduling."
0.0454,Event,ADDED,eval-sanitize-2-r2-054-crmqk.18d3d14a549bc63b,"reason=FailedScheduling count=None msg=0/6 nodes are available: 1 c_wall violated: 1 conflicting context pair(s) with node memory, 5 node(s) had untolerated taint(s). no new claims to deallocate, preemption: 0/6 nodes are available: 1 No preemption victims found for incoming pod, 5 Preemption is not helpful for scheduling."
0.0456,Event,ADDED,eval-sanitize-2-r2-054-crmqk.18d3d14a95445c19,"reason=FailedScheduling count=None msg=0/6 nodes are available: 2 c_wall violated: 1 conflicting context pair(s) with node memory, 4 node(s) had untolerated taint(s). no new claims to deallocate, preemption: 0/6 nodes are available: 2 No preemption victims found for incoming pod, 4 Preemption is not helpful for scheduling."
0.0458,Event,ADDED,eval-sanitize-2-r2-054-crmqk.18d3d14aab9b66ce,"reason=FailedScheduling count=None msg=0/6 nodes are available: 1 c_wall violated: 1 conflicting context pair(s) with node memory, 5 node(s) had untolerated taint(s). no new claims to deallocate, preemption: 0/6 nodes are available: 1 No preemption victims found for incoming pod, 5 Preemption is not helpful for scheduling."
0.046,Event,ADDED,eval-sanitize-2-r2-061-9rfwf.18d3d14c28625a15,"reason=FailedScheduling count=None msg=0/6 nodes are available: 1 c_wall violated: 1 conflicting context pair(s) with node memory, 5 node(s) had untolerated taint(s). no new claims to deallocate, preemption: 0/6 nodes are available: 1 No preemption victims found for incoming pod, 5 Preemption is not helpful for scheduling."
0.0462,Event,ADDED,eval-sanitize-2-r2-061-9rfwf.18d3d14c29aa9bbb,"reason=FailedScheduling count=None msg=0/6 nodes are available: 1 c_wall violated: 1 conflicting context pair(s) with node memory, 5 node(s) had untolerated taint(s). no new claims to deallocate, preemption: 0/6 nodes are available: 1 No preemption victims found for incoming pod, 5 Preemption is not helpful for scheduling."
0.0466,Event,ADDED,eval-sanitize-2-r2-061-9rfwf.18d3d14c31f60ddd,"reason=FailedScheduling count=None msg=0/6 nodes are available: 1 c_wall violated: 2 conflicting context pair(s) with node memory, 5 node(s) had untolerated taint(s). no new claims to deallocate, preemption: 0/6 nodes are available: 1 No preemption victims found for incoming pod, 5 Preemption is not helpful for scheduling."
0.0468,Event,ADDED,eval-sanitize-2-r2-069-2j22t.18d3d14dd29083df,"reason=FailedScheduling count=None msg=0/6 nodes are available: 1 c_wall violated: 2 conflicting context pair(s) with node memory, 5 node(s) had untolerated taint(s). no new claims to deallocate, preemption: 0/6 nodes are available: 1 No preemption victims found for incoming pod, 5 Preemption is not helpful for scheduling."
0.047,Event,ADDED,eval-sanitize-2-r2-069-2j22t.18d3d14dd390c283,"reason=FailedScheduling count=None msg=0/6 nodes are available: 1 c_wall violated: 2 conflicting context pair(s) with node memory, 5 node(s) had untolerated taint(s). no new claims to deallocate, preemption: 0/6 nodes are available: 1 No preemption victims found for incoming pod, 5 Preemption is not helpful for scheduling."
0.0475,Event,ADDED,eval-sanitize-2-r2-070-fnnv4.18d3d14e0e21f762,"reason=FailedScheduling count=None msg=0/6 nodes are available: 1 c_wall violated: 2 conflicting context pair(s) with node memory, 5 node(s) had untolerated taint(s). no new claims to deallocate, preemption: 0/6 nodes are available: 1 No preemption victims found for incoming pod, 5 Preemption is not helpful for scheduling."
0.0477,Event,ADDED,eval-sanitize-2-r2-071-whhp7.18d3d14e4a1cd3d0,"reason=FailedScheduling count=None msg=0/6 nodes are available: 2 c_wall violated: 1 conflicting context pair(s) with node memory, 4 node(s) had untolerated taint(s). no new claims to deallocate, preemption: 0/6 nodes are available: 2 No preemption victims found for incoming pod, 4 Preemption is not helpful for scheduling."
0.0479,Event,ADDED,eval-sanitize-2-r2-071-whhp7.18d3d14e52453955,"reason=FailedScheduling count=None msg=0/6 nodes are available: 1 c_wall violated: 1 conflicting context pair(s) with node memory, 5 node(s) had untolerated taint(s). no new claims to deallocate, preemption: 0/6 nodes are available: 1 No preemption victims found for incoming pod, 5 Preemption is not helpful for scheduling."
0.0481,TaskRequest,MODIFIED,eval-sanitize-2-r4-000,phase=Pending job=None
0.0484,Event,ADDED,eval-sanitize-2-r2-073-drszs.18d3d14ec11630ea,"reason=FailedScheduling count=None msg=0/6 nodes are available: 1 c_wall violated: 1 conflicting context pair(s) with node memory, 5 node(s) had untolerated taint(s). no new claims to deallocate, preemption: 0/6 nodes are available: 1 No preemption victims found for incoming pod, 5 Preemption is not helpful for scheduling."
0.0486,Event,ADDED,eval-sanitize-2-r2-075-w5ctl.18d3d14fc066218e,"reason=FailedScheduling count=None msg=0/6 nodes are available: 1 c_wall violated: 1 conflicting context pair(s) with node memory, 5 node(s) had untolerated taint(s). no new claims to deallocate, preemption: 0/6 nodes are available: 1 No preemption victims found for incoming pod, 5 Preemption is not helpful for scheduling."
0.049,Event,ADDED,eval-sanitize-2-r2-075-w5ctl.18d3d14ff03488bd,"reason=FailedScheduling count=None msg=0/6 nodes are available: 2 c_wall violated: 1 conflicting context pair(s) with node memory, 4 node(s) had untolerated taint(s). no new claims to deallocate, preemption: 0/6 nodes are available: 2 No preemption victims found for incoming pod, 4 Preemption is not helpful for scheduling."
0.0492,Event,ADDED,eval-sanitize-2-r2-075-w5ctl.18d3d1503c18baed,"reason=FailedScheduling count=None msg=0/6 nodes are available: 1 c_wall violated: 1 conflicting context pair(s) with node memory, 5 node(s) had untolerated taint(s). no new claims to deallocate, preemption: 0/6 nodes are available: 1 No preemption victims found for incoming pod, 5 Preemption is not helpful for scheduling."
0.0495,Event,ADDED,eval-sanitize-2-r2-076-v5wgq.18d3d14fc0923d55,"reason=FailedScheduling count=None msg=0/6 nodes are available: 1 c_wall violated: 2 conflicting context pair(s) with node memory, 5 node(s) had untolerated taint(s). no new claims to deallocate, preemption: 0/6 nodes are available: 1 No preemption victims found for incoming pod, 5 Preemption is not helpful for scheduling."
0.0497,Event,ADDED,eval-sanitize-2-r2-077-bzfjj.18d3d14fc0bddbc2,"reason=FailedScheduling count=None msg=0/6 nodes are available: 1 c_wall violated: 1 conflicting context pair(s) with node memory, 5 node(s) had untolerated taint(s). no new claims to deallocate, preemption: 0/6 nodes are available: 1 No preemption victims found for incoming pod, 5 Preemption is not helpful for scheduling."
0.0499,Event,ADDED,eval-sanitize-2-r2-077-bzfjj.18d3d14feff2800e,"reason=FailedScheduling count=None msg=0/6 nodes are available: 2 c_wall violated: 1 conflicting context pair(s) with node memory, 4 node(s) had untolerated taint(s). no new claims to deallocate, preemption: 0/6 nodes are available: 2 No preemption victims found for incoming pod, 4 Preemption is not helpful for scheduling."
0.0501,Event,ADDED,eval-sanitize-2-r2-077-bzfjj.18d3d1503c778f79,"reason=FailedScheduling count=None msg=0/6 nodes are available: 1 c_wall violated: 1 conflicting context pair(s) with node memory, 5 node(s) had untolerated taint(s). no new claims to deallocate, preemption: 0/6 nodes are available: 1 No preemption victims found for incoming pod, 5 Preemption is not helpful for scheduling."
0.0503,Event,ADDED,eval-sanitize-2-r2-077-bzfjj.18d3d15100b6bc99,"reason=FailedScheduling count=None msg=0/6 nodes are available: 1 c_wall violated: 1 conflicting context pair(s) with node memory, 5 node(s) had untolerated taint(s). no new claims to deallocate, preemption: 0/6 nodes are available: 1 No preemption victims found for incoming pod, 5 Preemption is not helpful for scheduling."
0.0505,Event,ADDED,eval-sanitize-2-r2-077-bzfjj.18d3d1513bfb9b90,"reason=FailedScheduling count=None msg=0/6 nodes are available: 2 c_wall violated: 1 conflicting context pair(s) with node memory, 4 node(s) had untolerated taint(s). no new claims to deallocate, preemption: 0/6 nodes are available: 2 No preemption victims found for incoming pod, 4 Preemption is not helpful for scheduling."
0.0509,Event,ADDED,eval-sanitize-2-r2-077-bzfjj.18d3d1517815ca71,"reason=FailedScheduling count=None msg=0/6 nodes are available: 1 c_wall violated: 1 conflicting context pair(s) with node memory, 5 node(s) had untolerated taint(s). no new claims to deallocate, preemption: 0/6 nodes are available: 1 No preemption victims found for incoming pod, 5 Preemption is not helpful for scheduling."
0.0512,Event,ADDED,eval-sanitize-2-r2-078-2flk9.18d3d14ff3f7fa8b,"reason=FailedScheduling count=None msg=0/6 nodes are available: 1 c_wall violated: 1 conflicting context pair(s) with node memory, 1 c_wall violated: 2 conflicting context pair(s) with node memory, 4 node(s) had untolerated taint(s). no new claims to deallocate, preemption: 0/6 nodes are available: 2 No preemption victims found for incoming pod, 4 Preemption is not helpful for scheduling."
0.0514,Event,ADDED,eval-sanitize-2-r2-078-2flk9.18d3d1503c436166,"reason=FailedScheduling count=None msg=0/6 nodes are available: 1 c_wall violated: 1 conflicting context pair(s) with node memory, 5 node(s) had untolerated taint(s). no new claims to deallocate, preemption: 0/6 nodes are available: 1 No preemption victims found for incoming pod, 5 Preemption is not helpful for scheduling."
0.0516,Event,ADDED,eval-sanitize-2-r2-080-q4tzk.18d3d150623c8906,"reason=FailedScheduling count=None msg=0/6 nodes are available: 1 c_wall violated: 1 conflicting context pair(s) with node memory, 5 node(s) had untolerated taint(s). no new claims to deallocate, preemption: 0/6 nodes are available: 1 No preemption victims found for incoming pod, 5 Preemption is not helpful for scheduling."
0.0519,Event,ADDED,eval-sanitize-2-r2-080-q4tzk.18d3d151023b617d,"reason=FailedScheduling count=None msg=0/6 nodes are available: 1 c_wall violated: 2 conflicting context pair(s) with node memory, 5 node(s) had untolerated taint(s). no new claims to deallocate, preemption: 0/6 nodes are available: 1 No preemption victims found for incoming pod, 5 Preemption is not helpful for scheduling."
0.0521,Event,ADDED,eval-sanitize-2-r2-080-q4tzk.18d3d1513e0a748b,"reason=FailedScheduling count=None msg=0/6 nodes are available: 1 c_wall violated: 1 conflicting context pair(s) with node memory, 1 c_wall violated: 2 conflicting context pair(s) with node memory, 4 node(s) had untolerated taint(s). no new claims to deallocate, preemption: 0/6 nodes are available: 2 No preemption victims found for incoming pod, 4 Preemption is not helpful for scheduling."
0.0525,Event,ADDED,eval-sanitize-2-r2-080-q4tzk.18d3d1515685bd4f,"reason=FailedScheduling count=None msg=0/6 nodes are available: 2 c_wall violated: 2 conflicting context pair(s) with node memory, 4 node(s) had untolerated taint(s). no new claims to deallocate, preemption: 0/6 nodes are available: 2 No preemption victims found for incoming pod, 4 Preemption is not helpful for scheduling."
0.0527,Event,ADDED,eval-sanitize-2-r2-080-q4tzk.18d3d151783fa7de,"reason=FailedScheduling count=None msg=0/6 nodes are available: 1 c_wall violated: 2 conflicting context pair(s) with node memory, 5 node(s) had untolerated taint(s). no new claims to deallocate, preemption: 0/6 nodes are available: 1 No preemption victims found for incoming pod, 5 Preemption is not helpful for scheduling."
0.0529,Event,ADDED,eval-sanitize-2-r2-082-n842l.18d3d151026e408f,"reason=FailedScheduling count=None msg=0/6 nodes are available: 1 c_wall violated: 2 conflicting context pair(s) with node memory, 5 node(s) had untolerated taint(s). no new claims to deallocate, preemption: 0/6 nodes are available: 1 No preemption victims found for incoming pod, 5 Preemption is not helpful for scheduling."
0.0532,Event,ADDED,eval-sanitize-2-r2-085-x79s4.18d3d1518c2903dd,"reason=FailedScheduling count=None msg=0/6 nodes are available: 1 c_wall violated: 1 conflicting context pair(s) with node memory, 5 node(s) had untolerated taint(s). no new claims to deallocate, preemption: 0/6 nodes are available: 1 No preemption victims found for incoming pod, 5 Preemption is not helpful for scheduling."
0.0534,Event,ADDED,eval-sanitize-2-r2-086-mmqn9.18d3d151c86c15bc,"reason=FailedScheduling count=None msg=0/6 nodes are available: 1 c_wall violated: 1 conflicting context pair(s) with node memory, 5 node(s) had untolerated taint(s). no new claims to deallocate, preemption: 0/6 nodes are available: 1 No preemption victims found for incoming pod, 5 Preemption is not helpful for scheduling."
0.0536,Event,ADDED,eval-sanitize-2-r2-087-tr6hh.18d3d15203ad4ce3,"reason=FailedScheduling count=None msg=0/6 nodes are available: 1 c_wall violated: 1 conflicting context pair(s) with node memory, 5 node(s) had untolerated taint(s). no new claims to deallocate, preemption: 0/6 nodes are available: 1 No preemption victims found for incoming pod, 5 Preemption is not helpful for scheduling."
0.054,Event,ADDED,eval-sanitize-2-r2-090-kmf8c.18d3d152ea8a520c,"reason=FailedScheduling count=None msg=0/6 nodes are available: 1 c_wall violated: 3 conflicting context pair(s) with node memory, 5 node(s) had untolerated taint(s). no new claims to deallocate, preemption: 0/6 nodes are available: 1 No preemption victims found for incoming pod, 5 Preemption is not helpful for scheduling."
0.0542,Event,ADDED,eval-sanitize-2-r2-091-h4bgm.18d3d152f4d5948d,"reason=FailedScheduling count=None msg=0/6 nodes are available: 1 c_wall violated: 3 conflicting context pair(s) with node memory, 5 node(s) had untolerated taint(s). no new claims to deallocate, preemption: 0/6 nodes are available: 1 No preemption victims found for incoming pod, 5 Preemption is not helpful for scheduling."
0.0543,Event,ADDED,eval-sanitize-2-r2-093-txhn5.18d3d1536979b9a8,"reason=FailedScheduling count=None msg=0/6 nodes are available: 1 c_wall violated: 1 conflicting context pair(s) with node memory, 5 node(s) had untolerated taint(s). no new claims to deallocate, preemption: 0/6 nodes are available: 1 No preemption victims found for incoming pod, 5 Preemption is not helpful for scheduling."
0.055,Event,ADDED,eval-sanitize-2-r2-094-78hgf.18d3d153a4fc7c7e,"reason=FailedScheduling count=None msg=0/6 nodes are available: 1 c_wall violated: 1 conflicting context pair(s) with node memory, 5 node(s) had untolerated taint(s). no new claims to deallocate, preemption: 0/6 nodes are available: 1 No preemption victims found for incoming pod, 5 Preemption is not helpful for scheduling."
0.0554,Event,ADDED,eval-sanitize-2-r2-095-zv7gr.18d3d1549820f57d,"reason=FailedScheduling count=None msg=0/6 nodes are available: 1 c_wall violated: 1 conflicting context pair(s) with node memory, 5 node(s) had untolerated taint(s). no new claims to deallocate, preemption: 0/6 nodes are available: 1 No preemption victims found for incoming pod, 5 Preemption is not helpful for scheduling."
0.0559,Event,ADDED,eval-sanitize-2-r2-097-d62t4.18d3d1549c0ab2ae,"reason=FailedScheduling count=None msg=0/6 nodes are available: 1 c_wall violated: 1 conflicting context pair(s) with node memory, 5 node(s) had untolerated taint(s). no new claims to deallocate, preemption: 0/6 nodes are available: 1 No preemption victims found for incoming pod, 5 Preemption is not helpful for scheduling."
0.0562,Event,ADDED,eval-sanitize-2-r2-098-mbt7r.18d3d1549c321d24,"reason=FailedScheduling count=None msg=0/6 nodes are available: 1 c_wall violated: 1 conflicting context pair(s) with node memory, 5 node(s) had untolerated taint(s). no new claims to deallocate, preemption: 0/6 nodes are available: 1 No preemption victims found for incoming pod, 5 Preemption is not helpful for scheduling."
0.0778,Job,ADDED,eval-sanitize-2-r4-000,
0.0837,TaskRequest,MODIFIED,eval-sanitize-2-r4-000,phase=Scheduled job=None
0.0879,Pod,ADDED,eval-sanitize-2-r4-000-8mtl8,phase=Pending node=None
0.09,Job,MODIFIED,eval-sanitize-2-r4-000,
0.0941,Event,ADDED,eval-sanitize-2-r4-000.18d3d1cf72496d01,reason=SuccessfulCreate count=1 msg=Created pod: eval-sanitize-2-r4-000-8mtl8
0.0951,TaskRequest,MODIFIED,eval-sanitize-2-r4-000,phase=Scheduled job=None
0.1025,Pod,MODIFIED,eval-sanitize-2-r4-000-8mtl8,phase=Pending node=kind-worker2
0.1061,Event,ADDED,eval-sanitize-2-r4-000-8mtl8.18d3d1cf73318e61,reason=Scheduled count=None msg=Successfully assigned compute/eval-sanitize-2-r4-000-8mtl8 to kind-worker2
0.1139,Pod,MODIFIED,eval-sanitize-2-r4-000-8mtl8,phase=Pending node=kind-worker2
0.1164,Node,MODIFIED,kind-worker2,taints=0
0.1284,Node,MODIFIED,kind-worker2,taints=0
0.5334,Event,ADDED,eval-sanitize-2-r4-000-8mtl8.18d3d1cf8ca34b56,"reason=Pulled count=1 msg=Container image ""busybox:musl"" already present on machine"
0.5528,Event,ADDED,eval-sanitize-2-r4-000-8mtl8.18d3d1cf8dc6965d,reason=Created count=1 msg=Created container: task
0.616,Event,ADDED,eval-sanitize-2-r4-000-8mtl8.18d3d1cf9187c84f,reason=Started count=1 msg=Started container task
1.0134,TaskRequest,ADDED,eval-sanitize-2-r4-001,phase=None job=None
1.0172,TaskRequest,MODIFIED,eval-sanitize-2-r4-001,phase=Pending job=None
1.0321,Job,ADDED,eval-sanitize-2-r4-001,
1.0398,TaskRequest,MODIFIED,eval-sanitize-2-r4-001,phase=Scheduled job=None
1.0413,Pod,ADDED,eval-sanitize-2-r4-001-n4msm,phase=Pending node=None
1.0421,Job,MODIFIED,eval-sanitize-2-r4-001,
1.0464,Event,ADDED,eval-sanitize-2-r4-001.18d3d1cfab1ff093,reason=SuccessfulCreate count=1 msg=Created pod: eval-sanitize-2-r4-001-n4msm
1.0499,TaskRequest,MODIFIED,eval-sanitize-2-r4-001,phase=Scheduled job=None
1.0579,Pod,MODIFIED,eval-sanitize-2-r4-001-n4msm,phase=Pending node=kind-worker
1.0611,Event,ADDED,eval-sanitize-2-r4-001-n4msm.18d3d1cfac1d8d6b,reason=Scheduled count=None msg=Successfully assigned compute/eval-sanitize-2-r4-001-n4msm to kind-worker
1.067,Pod,MODIFIED,eval-sanitize-2-r4-001-n4msm,phase=Pending node=kind-worker
1.0697,Node,MODIFIED,kind-worker,taints=0
1.0787,Node,MODIFIED,kind-worker,taints=0
1.092,Job,MODIFIED,eval-sanitize-2-r4-000,
1.1006,Job,MODIFIED,eval-sanitize-2-r4-000,
1.1836,Pod,MODIFIED,eval-sanitize-2-r4-000-8mtl8,phase=Running node=kind-worker2
1.471,Event,ADDED,eval-sanitize-2-r4-001-n4msm.18d3d1cfc482ef12,"reason=Pulled count=1 msg=Container image ""busybox:musl"" already present on machine"
1.4888,Event,ADDED,eval-sanitize-2-r4-001-n4msm.18d3d1cfc591a3d6,reason=Created count=1 msg=Created container: task
1.5216,Event,ADDED,eval-sanitize-2-r4-001-n4msm.18d3d1cfc7899120,reason=Started count=1 msg=Started container task
1.917,Node,MODIFIED,kind-worker2,taints=1
1.9307,Node,MODIFIED,kind-worker2,taints=1
1.9386,Pod,MODIFIED,eval-sanitize-2-r4-001-n4msm,phase=Running node=kind-worker
2.0122,TaskRequest,ADDED,eval-sanitize-2-r4-002,phase=None job=None
2.0192,TaskRequest,MODIFIED,eval-sanitize-2-r4-002,phase=Pending job=None
2.0361,Job,ADDED,eval-sanitize-2-r4-002,
2.0428,Pod,ADDED,eval-sanitize-2-r4-002-z5bgl,phase=Pending node=None
2.0437,TaskRequest,MODIFIED,eval-sanitize-2-r4-002,phase=Scheduled job=None
2.0469,Job,MODIFIED,eval-sanitize-2-r4-001,
2.0473,Event,ADDED,eval-sanitize-2-r4-002.18d3d1cfe6d435d4,reason=SuccessfulCreate count=1 msg=Created pod: eval-sanitize-2-r4-002-z5bgl
2.0481,Job,MODIFIED,eval-sanitize-2-r4-002,
2.0519,TaskRequest,MODIFIED,eval-sanitize-2-r4-002,phase=Scheduled job=None
2.0534,Pod,MODIFIED,eval-sanitize-2-r4-002-z5bgl,phase=Pending node=kind-worker
2.0558,Job,MODIFIED,eval-sanitize-2-r4-001,
2.0565,Event,ADDED,eval-sanitize-2-r4-002-z5bgl.18d3d1cfe77928d0,reason=Scheduled count=None msg=Successfully assigned compute/eval-sanitize-2-r4-002-z5bgl to kind-worker
2.0637,Pod,MODIFIED,eval-sanitize-2-r4-002-z5bgl,phase=Pending node=kind-worker
2.066,Node,MODIFIED,kind-worker,taints=0
2.0751,Node,MODIFIED,kind-worker,taints=0
2.1019,Job,MODIFIED,eval-sanitize-2-r4-000,
2.1104,Job,MODIFIED,eval-sanitize-2-r4-000,
2.4801,Event,ADDED,eval-sanitize-2-r4-002-z5bgl.18d3d1d000978f46,"reason=Pulled count=1 msg=Container image ""busybox:musl"" already present on machine"
2.4979,Event,ADDED,eval-sanitize-2-r4-002-z5bgl.18d3d1d001b20d7d,reason=Created count=1 msg=Created container: task
2.5318,Event,ADDED,eval-sanitize-2-r4-002-z5bgl.18d3d1d003c42dab,reason=Started count=1 msg=Started container task
2.6558,Node,MODIFIED,kind-worker,taints=1
2.6676,Node,MODIFIED,kind-worker,taints=1
2.9431,Pod,MODIFIED,eval-sanitize-2-r4-002-z5bgl,phase=Running node=kind-worker
3.0111,TaskRequest,ADDED,eval-sanitize-2-r4-003,phase=None job=None
3.0155,TaskRequest,MODIFIED,eval-sanitize-2-r4-003,phase=Pending job=None
3.0292,Job,ADDED,eval-sanitize-2-r4-003,
3.0354,Pod,ADDED,eval-sanitize-2-r4-003-7hwjh,phase=Pending node=None
3.0356,TaskRequest,MODIFIED,eval-sanitize-2-r4-003,phase=Scheduled job=None
3.0388,Job,MODIFIED,eval-sanitize-2-r4-003,
3.0419,Event,ADDED,eval-sanitize-2-r4-003.18d3d1d02204d979,reason=SuccessfulCreate count=1 msg=Created pod: eval-sanitize-2-r4-003-7hwjh
3.042,TaskRequest,MODIFIED,eval-sanitize-2-r4-003,phase=Scheduled job=None
3.0449,Pod,MODIFIED,eval-sanitize-2-r4-003-7hwjh,phase=Pending node=kind-worker4
3.047,Job,MODIFIED,eval-sanitize-2-r4-002,
3.0504,Event,ADDED,eval-sanitize-2-r4-003-7hwjh.18d3d1d0229387b5,reason=Scheduled count=None msg=Successfully assigned compute/eval-sanitize-2-r4-003-7hwjh to kind-worker4
3.0553,Node,MODIFIED,kind-worker4,taints=0
3.058,Pod,MODIFIED,eval-sanitize-2-r4-003-7hwjh,phase=Pending node=kind-worker4
3.0587,Job,MODIFIED,eval-sanitize-2-r4-002,
3.065,Node,MODIFIED,kind-worker4,taints=0
3.4847,Event,ADDED,eval-sanitize-2-r4-003-7hwjh.18d3d1d03c8eb47c,"reason=Pulled count=1 msg=Container image ""busybox:musl"" already present on machine"
3.5027,Event,ADDED,eval-sanitize-2-r4-003-7hwjh.18d3d1d03d9ad15d,reason=Created count=1 msg=Created container: task
3.5414,Event,ADDED,eval-sanitize-2-r4-003-7hwjh.18d3d1d03fdf1203,reason=Started count=1 msg=Started container task
3.8186,Pod,MODIFIED,eval-sanitize-2-r4-003-7hwjh,phase=Running node=kind-worker4
4.01,TaskRequest,ADDED,eval-sanitize-2-r4-004,phase=None job=None
4.0147,TaskRequest,MODIFIED,eval-sanitize-2-r4-004,phase=Pending job=None
4.0314,Job,ADDED,eval-sanitize-2-r4-004,
4.0364,Pod,ADDED,eval-sanitize-2-r4-004-ttn6b,phase=Pending node=None
4.0376,TaskRequest,MODIFIED,eval-sanitize-2-r4-004,phase=Scheduled job=None
4.0412,Job,MODIFIED,eval-sanitize-2-r4-003,
4.0415,Event,ADDED,eval-sanitize-2-r4-004.18d3d1d05dabacff,reason=SuccessfulCreate count=1 msg=Created pod: eval-sanitize-2-r4-004-ttn6b
4.0422,Job,MODIFIED,eval-sanitize-2-r4-004,
4.0461,TaskRequest,MODIFIED,eval-sanitize-2-r4-004,phase=Scheduled job=None
4.0491,Job,MODIFIED,eval-sanitize-2-r4-004,
4.0503,Pod,MODIFIED,eval-sanitize-2-r4-004-ttn6b,phase=Pending node=kind-worker4
4.0529,Job,MODIFIED,eval-sanitize-2-r4-003,
4.0533,Event,ADDED,eval-sanitize-2-r4-004-ttn6b.18d3d1d05e70a2e2,reason=Scheduled count=None msg=Successfully assigned compute/eval-sanitize-2-r4-004-ttn6b to kind-worker4
4.0578,Job,MODIFIED,eval-sanitize-2-r4-004,
4.0606,Pod,MODIFIED,eval-sanitize-2-r4-004-ttn6b,phase=Pending node=kind-worker4
4.489,Event,ADDED,eval-sanitize-2-r4-004-ttn6b.18d3d1d0786de56a,"reason=Pulled count=1 msg=Container image ""busybox:musl"" already present on machine"
4.5061,Event,ADDED,eval-sanitize-2-r4-004-ttn6b.18d3d1d0797286f9,reason=Created count=1 msg=Created container: task
4.582,Event,ADDED,eval-sanitize-2-r4-004-ttn6b.18d3d1d07ddfdee5,reason=Started count=1 msg=Started container task
4.6274,Node,MODIFIED,kind-worker4,taints=1
4.6392,Node,MODIFIED,kind-worker4,taints=1
4.8202,Pod,MODIFIED,eval-sanitize-2-r4-004-ttn6b,phase=Running node=kind-worker4
5.0125,TaskRequest,ADDED,eval-sanitize-2-r4-005,phase=None job=None
5.0169,TaskRequest,MODIFIED,eval-sanitize-2-r4-005,phase=Pending job=None
5.0327,Job,ADDED,eval-sanitize-2-r4-005,
5.0388,Pod,ADDED,eval-sanitize-2-r4-005-hs6t9,phase=Pending node=None
5.0409,TaskRequest,MODIFIED,eval-sanitize-2-r4-005,phase=Scheduled job=None
5.0421,Job,MODIFIED,eval-sanitize-2-r4-004,
5.0442,Job,MODIFIED,eval-sanitize-2-r4-005,
5.0453,Event,ADDED,eval-sanitize-2-r4-005.18d3d1d0996eceac,reason=SuccessfulCreate count=1 msg=Created pod: eval-sanitize-2-r4-005-hs6t9
5.0473,Pod,MODIFIED,eval-sanitize-2-r4-005-hs6t9,phase=Pending node=kind-worker5
5.052,TaskRequest,MODIFIED,eval-sanitize-2-r4-005,phase=Scheduled job=None
5.054,Event,ADDED,eval-sanitize-2-r4-005-hs6t9.18d3d1d099eae516,reason=Scheduled count=None msg=Successfully assigned compute/eval-sanitize-2-r4-005-hs6t9 to kind-worker5
5.0548,Job,MODIFIED,eval-sanitize-2-r4-004,
5.0573,Node,MODIFIED,kind-worker5,taints=0
5.0595,Pod,MODIFIED,eval-sanitize-2-r4-005-hs6t9,phase=Pending node=kind-worker5
5.0673,Node,MODIFIED,kind-worker5,taints=0
5.4725,Event,ADDED,eval-sanitize-2-r4-005-hs6t9.18d3d1d0b2f6307d,"reason=Pulled count=1 msg=Container image ""busybox:musl"" already present on machine"
5.489,Event,ADDED,eval-sanitize-2-r4-005-hs6t9.18d3d1d0b40a5a4a,reason=Created count=1 msg=Created container: task
5.5193,Event,ADDED,eval-sanitize-2-r4-005-hs6t9.18d3d1d0b5d611f0,reason=Started count=1 msg=Started container task
5.8152,Pod,MODIFIED,eval-sanitize-2-r4-005-hs6t9,phase=Running node=kind-worker5
5.9329,Node,MODIFIED,kind-worker5,taints=1
5.9461,Node,MODIFIED,kind-worker5,taints=1
6.0125,TaskRequest,ADDED,eval-sanitize-2-r4-006,phase=None job=None
6.0162,TaskRequest,MODIFIED,eval-sanitize-2-r4-006,phase=Pending job=None
6.0314,Job,ADDED,eval-sanitize-2-r4-006,
6.0377,Pod,ADDED,eval-sanitize-2-r4-006-8fdtg,phase=Pending node=None
6.0388,TaskRequest,MODIFIED,eval-sanitize-2-r4-006,phase=Scheduled job=None
6.0395,Job,MODIFIED,eval-sanitize-2-r4-006,
6.0444,Event,ADDED,eval-sanitize-2-r4-006.18d3d1d0d4f8c8f0,reason=SuccessfulCreate count=1 msg=Created pod: eval-sanitize-2-r4-006-8fdtg
6.0454,Job,MODIFIED,eval-sanitize-2-r4-005,
6.0461,Pod,MODIFIED,eval-sanitize-2-r4-006-8fdtg,phase=Pending node=kind-worker3
6.0475,TaskRequest,MODIFIED,eval-sanitize-2-r4-006,phase=Scheduled job=None
6.0487,Event,ADDED,eval-sanitize-2-r4-006-8fdtg.18d3d1d0d565b349,reason=Scheduled count=None msg=Successfully assigned compute/eval-sanitize-2-r4-006-8fdtg to kind-worker3
6.0529,Job,MODIFIED,eval-sanitize-2-r4-005,
6.056,Node,MODIFIED,kind-worker3,taints=0
6.0572,Pod,MODIFIED,eval-sanitize-2-r4-006-8fdtg,phase=Pending node=kind-worker3
6.1352,Node,MODIFIED,kind-worker3,taints=0
6.4842,Event,ADDED,eval-sanitize-2-r4-006-8fdtg.18d3d1d0ef35267e,"reason=Pulled count=1 msg=Container image ""busybox:musl"" already present on machine"
6.5015,Event,ADDED,eval-sanitize-2-r4-006-8fdtg.18d3d1d0f05e79fe,reason=Created count=1 msg=Created container: task
6.5336,Event,ADDED,eval-sanitize-2-r4-006-8fdtg.18d3d1d0f24e0321,reason=Started count=1 msg=Started container task
6.683,Node,MODIFIED,kind-worker3,taints=1
6.7582,Node,MODIFIED,kind-worker3,taints=1
6.7602,Pod,MODIFIED,eval-sanitize-2-r4-006-8fdtg,phase=Running node=kind-worker3
7.0131,TaskRequest,ADDED,eval-sanitize-2-r4-007,phase=None job=None
7.018,TaskRequest,MODIFIED,eval-sanitize-2-r4-007,phase=Pending job=None
7.0314,Job,ADDED,eval-sanitize-2-r4-007,
7.0369,TaskRequest,MODIFIED,eval-sanitize-2-r4-007,phase=Scheduled job=None
7.0399,Pod,ADDED,eval-sanitize-2-r4-007-4mkhx,phase=Pending node=None
7.0405,Job,MODIFIED,eval-sanitize-2-r4-007,
7.0438,Job,MODIFIED,eval-sanitize-2-r4-006,
7.0453,Event,ADDED,eval-sanitize-2-r4-007.18d3d1d110b2ca94,reason=SuccessfulCreate count=1 msg=Created pod: eval-sanitize-2-r4-007-4mkhx
7.0455,Event,ADDED,eval-sanitize-2-r4-007-4mkhx.18d3d1d110c31533,"reason=FailedScheduling count=None msg=0/6 nodes are available: 6 node(s) had untolerated taint(s). no new claims to deallocate, preemption: 0/6 nodes are available: 6 Preemption is not helpful for scheduling."
7.0456,TaskRequest,MODIFIED,eval-sanitize-2-r4-007,phase=Scheduled job=None
7.0464,Pod,MODIFIED,eval-sanitize-2-r4-007-4mkhx,phase=Pending node=None
7.0522,Job,MODIFIED,eval-sanitize-2-r4-006,
8.0126,TaskRequest,ADDED,eval-sanitize-2-r4-008,phase=None job=None
8.0167,TaskRequest,MODIFIED,eval-sanitize-2-r4-008,phase=Pending job=None
8.0332,Job,ADDED,eval-sanitize-2-r4-008,
8.0393,Pod,ADDED,eval-sanitize-2-r4-008-f4zj6,phase=Pending node=None
8.0396,TaskRequest,MODIFIED,eval-sanitize-2-r4-008,phase=Scheduled job=None
8.0425,Job,MODIFIED,eval-sanitize-2-r4-008,
8.0453,Pod,MODIFIED,eval-sanitize-2-r4-008-f4zj6,phase=Pending node=None
8.0464,Job,MODIFIED,eval-sanitize-2-r4-007,
8.0469,Event,ADDED,eval-sanitize-2-r4-008.18d3d1d14c489e22,reason=SuccessfulCreate count=1 msg=Created pod: eval-sanitize-2-r4-008-f4zj6
8.0471,Event,ADDED,eval-sanitize-2-r4-008-f4zj6.18d3d1d14c54c7c6,"reason=FailedScheduling count=None msg=0/6 nodes are available: 6 node(s) had untolerated taint(s). no new claims to deallocate, preemption: 0/6 nodes are available: 6 Preemption is not helpful for scheduling."
8.0472,TaskRequest,MODIFIED,eval-sanitize-2-r4-008,phase=Scheduled job=None
8.0552,Job,MODIFIED,eval-sanitize-2-r4-007,
9.0083,TaskRequest,ADDED,eval-sanitize-2-r4-009,phase=None job=None
9.012,TaskRequest,MODIFIED,eval-sanitize-2-r4-009,phase=Pending job=None
9.0288,Job,ADDED,eval-sanitize-2-r4-009,
9.0332,TaskRequest,MODIFIED,eval-sanitize-2-r4-009,phase=Scheduled job=None
9.036,Pod,ADDED,eval-sanitize-2-r4-009-mwm6s,phase=Pending node=None
9.0381,Job,MODIFIED,eval-sanitize-2-r4-009,
9.0425,Event,ADDED,eval-sanitize-2-r4-009.18d3d1d187b33210,reason=SuccessfulCreate count=1 msg=Created pod: eval-sanitize-2-r4-009-mwm6s
9.0426,TaskRequest,MODIFIED,eval-sanitize-2-r4-009,phase=Scheduled job=None
9.0438,Pod,MODIFIED,eval-sanitize-2-r4-009-mwm6s,phase=Pending node=None
9.0442,Event,ADDED,eval-sanitize-2-r4-009-mwm6s.18d3d1d187bcc462,"reason=FailedScheduling count=None msg=0/6 nodes are available: 6 node(s) had untolerated taint(s). no new claims to deallocate, preemption: 0/6 nodes are available: 6 Preemption is not helpful for scheduling."
9.045,Job,MODIFIED,eval-sanitize-2-r4-008,
9.0533,Job,MODIFIED,eval-sanitize-2-r4-008,
10.0109,TaskRequest,ADDED,eval-sanitize-2-r4-010,phase=None job=None
10.0148,TaskRequest,MODIFIED,eval-sanitize-2-r4-010,phase=Pending job=None
10.0316,Job,ADDED,eval-sanitize-2-r4-010,
10.0374,TaskRequest,MODIFIED,eval-sanitize-2-r4-010,phase=Scheduled job=None
10.0393,Pod,ADDED,eval-sanitize-2-r4-010-wmh29,phase=Pending node=None
10.0417,Job,MODIFIED,eval-sanitize-2-r4-010,
10.0433,Job,MODIFIED,eval-sanitize-2-r4-009,
10.0452,Event,ADDED,eval-sanitize-2-r4-010.18d3d1d1c37fb500,reason=SuccessfulCreate count=1 msg=Created pod: eval-sanitize-2-r4-010-wmh29
10.0455,Event,ADDED,eval-sanitize-2-r4-010-wmh29.18d3d1d1c38aa9ff,"reason=FailedScheduling count=None msg=0/6 nodes are available: 6 node(s) had untolerated taint(s). no new claims to deallocate, preemption: 0/6 nodes are available: 6 Preemption is not helpful for scheduling."
10.0465,Pod,MODIFIED,eval-sanitize-2-r4-010-wmh29,phase=Pending node=None
10.0466,TaskRequest,MODIFIED,eval-sanitize-2-r4-010,phase=Scheduled job=None
10.0524,Job,MODIFIED,eval-sanitize-2-r4-009,
11.0092,TaskRequest,ADDED,eval-sanitize-2-r4-011,phase=None job=None
11.0138,TaskRequest,MODIFIED,eval-sanitize-2-r4-011,phase=Pending job=None
11.0306,Job,ADDED,eval-sanitize-2-r4-011,
11.0371,TaskRequest,MODIFIED,eval-sanitize-2-r4-011,phase=Scheduled job=None
11.039,Pod,ADDED,eval-sanitize-2-r4-011-8l98g,phase=Pending node=None
11.041,Job,MODIFIED,eval-sanitize-2-r4-011,
11.0456,Event,ADDED,eval-sanitize-2-r4-011.18d3d1d1ff1a3879,reason=SuccessfulCreate count=1 msg=Created pod: eval-sanitize-2-r4-011-8l98g
11.0458,Event,ADDED,eval-sanitize-2-r4-011-8l98g.18d3d1d1ff22c7ad,"reason=FailedScheduling count=None msg=0/6 nodes are available: 6 node(s) had untolerated taint(s). no new claims to deallocate, preemption: 0/6 nodes are available: 6 Preemption is not helpful for scheduling."
11.0469,Pod,MODIFIED,eval-sanitize-2-r4-011-8l98g,phase=Pending node=None
11.0477,Job,MODIFIED,eval-sanitize-2-r4-010,
11.0478,TaskRequest,MODIFIED,eval-sanitize-2-r4-011,phase=Scheduled job=None
11.0576,Job,MODIFIED,eval-sanitize-2-r4-010,
11.2032,Pod,MODIFIED,eval-sanitize-2-r4-000-8mtl8,phase=Running node=kind-worker2
11.9565,Pod,MODIFIED,eval-sanitize-2-r4-001-n4msm,phase=Running node=kind-worker
12.0078,TaskRequest,ADDED,eval-sanitize-2-r4-012,phase=None job=None
12.0118,TaskRequest,MODIFIED,eval-sanitize-2-r4-012,phase=Pending job=None
12.0269,Job,ADDED,eval-sanitize-2-r4-012,
12.0321,TaskRequest,MODIFIED,eval-sanitize-2-r4-012,phase=Scheduled job=None
12.0366,Pod,ADDED,eval-sanitize-2-r4-012-s6sg6,phase=Pending node=None
12.0373,Job,MODIFIED,eval-sanitize-2-r4-012,
12.0417,Event,ADDED,eval-sanitize-2-r4-012.18d3d1d23a733079,reason=SuccessfulCreate count=1 msg=Created pod: eval-sanitize-2-r4-012-s6sg6
12.042,Event,ADDED,eval-sanitize-2-r4-012-s6sg6.18d3d1d23a7f4860,"reason=FailedScheduling count=None msg=0/6 nodes are available: 6 node(s) had untolerated taint(s). no new claims to deallocate, preemption: 0/6 nodes are available: 6 Preemption is not helpful for scheduling."
12.0421,TaskRequest,MODIFIED,eval-sanitize-2-r4-012,phase=Scheduled job=None
12.0431,Pod,MODIFIED,eval-sanitize-2-r4-012-s6sg6,phase=Pending node=None
12.0439,Job,MODIFIED,eval-sanitize-2-r4-011,
12.0528,Job,MODIFIED,eval-sanitize-2-r4-011,
12.2114,Job,MODIFIED,eval-sanitize-2-r4-000,
12.2219,Job,MODIFIED,eval-sanitize-2-r4-000,
12.2968,Pod,MODIFIED,eval-sanitize-2-r4-000-8mtl8,phase=Succeeded node=kind-worker2
12.9624,Pod,MODIFIED,eval-sanitize-2-r4-002-z5bgl,phase=Running node=kind-worker
12.9637,Job,MODIFIED,eval-sanitize-2-r4-001,
12.9749,Job,MODIFIED,eval-sanitize-2-r4-001,
13.0212,TaskRequest,ADDED,eval-sanitize-2-r4-013,phase=None job=None
13.0252,TaskRequest,MODIFIED,eval-sanitize-2-r4-013,phase=Pending job=None
13.0412,Job,MODIFIED,eval-sanitize-2-r4-012,
13.0417,Job,ADDED,eval-sanitize-2-r4-013,
13.0471,Pod,MODIFIED,eval-sanitize-2-r4-001-n4msm,phase=Succeeded node=kind-worker
13.0478,Pod,ADDED,eval-sanitize-2-r4-013-tw8qz,phase=Pending node=None
13.0487,TaskRequest,MODIFIED,eval-sanitize-2-r4-013,phase=Scheduled job=None
13.0514,Job,MODIFIED,eval-sanitize-2-r4-013,
13.0534,Event,ADDED,eval-sanitize-2-r4-013.18d3d1d276d1e178,reason=SuccessfulCreate count=1 msg=Created pod: eval-sanitize-2-r4-013-tw8qz
13.0536,Event,ADDED,eval-sanitize-2-r4-013-tw8qz.18d3d1d276d94114,"reason=FailedScheduling count=None msg=0/6 nodes are available: 6 node(s) had untolerated taint(s). no new claims to deallocate, preemption: 0/6 nodes are available: 6 Preemption is not helpful for scheduling."
13.0545,Pod,MODIFIED,eval-sanitize-2-r4-013-tw8qz,phase=Pending node=None
13.0569,TaskRequest,MODIFIED,eval-sanitize-2-r4-013,phase=Scheduled job=None
13.0592,Job,MODIFIED,eval-sanitize-2-r4-012,
13.2178,Job,MODIFIED,eval-sanitize-2-r4-000,
13.2254,Pod,MODIFIED,eval-sanitize-2-r4-000-8mtl8,phase=Succeeded node=kind-worker2
13.2268,Job,MODIFIED,eval-sanitize-2-r4-000,
13.8408,Pod,MODIFIED,eval-sanitize-2-r4-003-7hwjh,phase=Running node=kind-worker4
13.969,Job,MODIFIED,eval-sanitize-2-r4-002,
13.9715,Job,MODIFIED,eval-sanitize-2-r4-001,
13.9797,Job,MODIFIED,eval-sanitize-2-r4-002,
13.9824,Job,MODIFIED,eval-sanitize-2-r4-001,
13.9838,Pod,MODIFIED,eval-sanitize-2-r4-001-n4msm,phase=Succeeded node=kind-worker
14.0103,TaskRequest,ADDED,eval-sanitize-2-r4-014,phase=None job=None
14.0142,TaskRequest,MODIFIED,eval-sanitize-2-r4-014,phase=Pending job=None
14.0311,Job,ADDED,eval-sanitize-2-r4-014,
14.036,TaskRequest,MODIFIED,eval-sanitize-2-r4-014,phase=Scheduled job=None
14.0394,Pod,ADDED,eval-sanitize-2-r4-014-vkvct,phase=Pending node=None
14.041,Job,MODIFIED,eval-sanitize-2-r4-014,
14.0456,Event,ADDED,eval-sanitize-2-r4-014.18d3d1d2b1e5d2fc,reason=SuccessfulCreate count=1 msg=Created pod: eval-sanitize-2-r4-014-vkvct
14.0458,Event,ADDED,eval-sanitize-2-r4-014-vkvct.18d3d1d2b1f249b5,"reason=FailedScheduling count=None msg=0/6 nodes are available: 6 node(s) had untolerated taint(s). no new claims to deallocate, preemption: 0/6 nodes are available: 6 Preemption is not helpful for scheduling."
14.0461,TaskRequest,MODIFIED,eval-sanitize-2-r4-014,phase=Scheduled job=None
14.0471,Pod,MODIFIED,eval-sanitize-2-r4-014-vkvct,phase=Pending node=None
14.0534,Job,MODIFIED,eval-sanitize-2-r4-013,
14.0597,Pod,MODIFIED,eval-sanitize-2-r4-002-z5bgl,phase=Succeeded node=kind-worker
14.0635,Job,MODIFIED,eval-sanitize-2-r4-013,
14.2236,Job,MODIFIED,eval-sanitize-2-r4-000,
14.2277,Job,MODIFIED,eval-sanitize-2-r4-000,
14.23,Node,MODIFIED,kind-worker2,taints=1
14.2336,Event,ADDED,eval-sanitize-2-r4-000.18d3d1d2bd237607,reason=Completed count=1 msg=Job completed
14.2386,Job,MODIFIED,eval-sanitize-2-r4-000,
14.2438,TaskRequest,MODIFIED,eval-sanitize-2-r4-000,phase=Complete job=None
14.2531,Job,MODIFIED,eval-sanitize-2-r4-000,
14.2564,Node,MODIFIED,kind-worker2,taints=1
14.2613,Node,MODIFIED,kind-worker2,taints=0
14.2703,Pod,MODIFIED,eval-sanitize-2-r4-007-4mkhx,phase=Pending node=kind-worker2
14.2769,Node,MODIFIED,kind-worker2,taints=0
14.2776,Event,ADDED,eval-sanitize-2-r4-007-4mkhx.18d3d1d2bfa311e7,reason=Scheduled count=None msg=Successfully assigned compute/eval-sanitize-2-r4-007-4mkhx to kind-worker2
14.2781,Event,ADDED,eval-sanitize-2-r4-008-f4zj6.18d3d1d2bfb6c928,"reason=FailedScheduling count=None msg=0/6 nodes are available: 1 c_wall violated: 1 conflicting context pair(s) with node memory, 5 node(s) had untolerated taint(s). no new claims to deallocate, preemption: 0/6 nodes are available: 1 No preemption victims found for incoming pod, 5 Preemption is not helpful for scheduling."
14.2795,Pod,MODIFIED,eval-sanitize-2-r4-008-f4zj6,phase=Pending node=None
14.2829,Pod,MODIFIED,eval-sanitize-2-r4-007-4mkhx,phase=Pending node=kind-worker2
14.2891,Pod,MODIFIED,eval-sanitize-2-r4-009-mwm6s,phase=Pending node=kind-worker2
14.2916,Pod,MODIFIED,eval-sanitize-2-r4-010-wmh29,phase=Pending node=kind-worker2
14.2955,Pod,MODIFIED,eval-sanitize-2-r4-011-8l98g,phase=Pending node=kind-worker2
14.2958,Event,ADDED,eval-sanitize-2-r4-009-mwm6s.18d3d1d2c0cbfcfe,reason=Scheduled count=None msg=Successfully assigned compute/eval-sanitize-2-r4-009-mwm6s to kind-worker2
14.296,Event,ADDED,eval-sanitize-2-r4-010-wmh29.18d3d1d2c0f394aa,reason=Scheduled count=None msg=Successfully assigned compute/eval-sanitize-2-r4-010-wmh29 to kind-worker2
14.3002,Pod,MODIFIED,eval-sanitize-2-r4-012-s6sg6,phase=Pending node=None
14.3032,Event,ADDED,eval-sanitize-2-r4-012-s6sg6.18d3d1d2c113957c,"reason=FailedScheduling count=None msg=0/6 nodes are available: 1 c_wall violated: 1 conflicting context pair(s) with node memory, 5 node(s) had untolerated taint(s). no new claims to deallocate, preemption: 0/6 nodes are available: 1 No preemption victims found for incoming pod, 5 Preemption is not helpful for scheduling."
14.3053,Node,MODIFIED,kind-worker2,taints=0
14.3058,Event,ADDED,eval-sanitize-2-r4-011-8l98g.18d3d1d2c12d6c4d,reason=Scheduled count=None msg=Successfully assigned compute/eval-sanitize-2-r4-011-8l98g to kind-worker2
14.3072,Pod,MODIFIED,eval-sanitize-2-r4-009-mwm6s,phase=Pending node=kind-worker2
14.3126,Pod,MODIFIED,eval-sanitize-2-r4-011-8l98g,phase=Pending node=kind-worker2
14.315,Node,MODIFIED,kind-worker2,taints=0
14.323,Pod,MODIFIED,eval-sanitize-2-r4-010-wmh29,phase=Pending node=kind-worker2
14.3315,Event,ADDED,eval-sanitize-2-r4-013-tw8qz.18d3d1d2c27a3af7,"reason=FailedScheduling count=None msg=0/6 nodes are available: 1 c_wall violated: 1 conflicting context pair(s) with node memory, 5 node(s) had untolerated taint(s). no new claims to deallocate, preemption: 0/6 nodes are available: 1 No preemption victims found for incoming pod, 5 Preemption is not helpful for scheduling."
14.3331,Pod,MODIFIED,eval-sanitize-2-r4-013-tw8qz,phase=Pending node=None
14.3396,Node,MODIFIED,kind-worker2,taints=0
14.3408,Pod,MODIFIED,eval-sanitize-2-r4-014-vkvct,phase=Pending node=kind-worker2
14.3459,Event,ADDED,eval-sanitize-2-r4-014-vkvct.18d3d1d2c3e16d0e,reason=Scheduled count=None msg=Successfully assigned compute/eval-sanitize-2-r4-014-vkvct to kind-worker2
14.3526,Pod,MODIFIED,eval-sanitize-2-r4-014-vkvct,phase=Pending node=kind-worker2
14.3546,Node,MODIFIED,kind-worker2,taints=0
14.3713,Node,MODIFIED,kind-worker2,taints=0
14.3804,Node,MODIFIED,kind-worker2,taints=0
14.3934,Pod,MODIFIED,eval-sanitize-2-r4-008-f4zj6,phase=Pending node=None
14.3938,Event,ADDED,eval-sanitize-2-r4-008-f4zj6.18d3d1d2c6b80729,"reason=FailedScheduling count=None msg=0/6 nodes are available: 1 c_wall violated: 2 conflicting context pair(s) with node memory, 5 node(s) had untolerated taint(s). no new claims to deallocate, preemption: 0/6 nodes are available: 1 No preemption victims found for incoming pod, 5 Preemption is not helpful for scheduling."
14.4016,Event,ADDED,eval-sanitize-2-r4-012-s6sg6.18d3d1d2c73a0fe2,"reason=FailedScheduling count=None msg=0/6 nodes are available: 1 c_wall violated: 1 conflicting context pair(s) with node memory, 5 node(s) had untolerated taint(s). no new claims to deallocate, preemption: 0/6 nodes are available: 1 No preemption victims found for incoming pod, 5 Preemption is not helpful for scheduling."
14.4059,Event,ADDED,eval-sanitize-2-r4-013-tw8qz.18d3d1d2c7997dc3,"reason=FailedScheduling count=None msg=0/6 nodes are available: 1 c_wall violated: 1 conflicting context pair(s) with node memory, 5 node(s) had untolerated taint(s). no new claims to deallocate, preemption: 0/6 nodes are available: 1 No preemption victims found for incoming pod, 5 Preemption is not helpful for scheduling."
14.4081,Event,ADDED,eval-sanitize-2-r4-008-f4zj6.18d3d1d2c7bed357,"reason=FailedScheduling count=None msg=0/6 nodes are available: 1 c_wall violated: 2 conflicting context pair(s) with node memory, 5 node(s) had untolerated taint(s). no new claims to deallocate, preemption: 0/6 nodes are available: 1 No preemption victims found for incoming pod, 5 Preemption is not helpful for scheduling."
14.7143,Event,ADDED,eval-sanitize-2-r4-007-4mkhx.18d3d1d2d9c3bd07,"reason=Pulled count=1 msg=Container image ""busybox:musl"" already present on machine"
14.7347,Event,ADDED,eval-sanitize-2-r4-009-mwm6s.18d3d1d2db11968c,"reason=Pulled count=1 msg=Container image ""busybox:musl"" already present on machine"
14.7589,Event,ADDED,eval-sanitize-2-r4-007-4mkhx.18d3d1d2db14c308,reason=Created count=1 msg=Created container: task
14.7635,Event,ADDED,eval-sanitize-2-r4-010-wmh29.18d3d1d2db2ddd06,"reason=Pulled count=1 msg=Container image ""busybox:musl"" already present on machine"
14.7678,Event,ADDED,eval-sanitize-2-r4-011-8l98g.18d3d1d2db503a6c,"reason=Pulled count=1 msg=Container image ""busybox:musl"" already present on machine"
14.7736,Event,ADDED,eval-sanitize-2-r4-007-4mkhx.18d3d1d2dd119ae6,reason=Started count=1 msg=Started container task
14.7773,Event,ADDED,eval-sanitize-2-r4-014-vkvct.18d3d1d2dd172f81,"reason=Pulled count=1 msg=Container image ""busybox:musl"" already present on machine"
14.7869,Event,ADDED,eval-sanitize-2-r4-009-mwm6s.18d3d1d2de44c8f2,reason=Created count=1 msg=Created container: task
14.7984,Event,ADDED,eval-sanitize-2-r4-010-wmh29.18d3d1d2dee3e1fe,reason=Created count=1 msg=Created container: task
14.8041,Event,ADDED,eval-sanitize-2-r4-011-8l98g.18d3d1d2df40b3a2,reason=Created count=1 msg=Created container: task
14.8075,Event,ADDED,eval-sanitize-2-r4-014-vkvct.18d3d1d2df72fd11,reason=Created count=1 msg=Created container: task
14.8419,Pod,MODIFIED,eval-sanitize-2-r4-004-ttn6b,phase=Running node=kind-worker4
14.85,Job,MODIFIED,eval-sanitize-2-r4-003,
14.8532,Event,ADDED,eval-sanitize-2-r4-009-mwm6s.18d3d1d2e2089af0,reason=Started count=1 msg=Started container task
14.8544,Event,MODIFIED,eval-sanitize-2-r4-012-s6sg6.18d3d1d2c73a0fe2,"reason=FailedScheduling count=None msg=0/6 nodes are available: 1 c_wall violated: 1 conflicting context pair(s) with node memory, 5 node(s) had untolerated taint(s). no new claims to deallocate, preemption: 0/6 nodes are available: 1 No preemption victims found for incoming pod, 5 Preemption is not helpful for scheduling."
14.8576,Event,MODIFIED,eval-sanitize-2-r4-013-tw8qz.18d3d1d2c7997dc3,"reason=FailedScheduling count=None msg=0/6 nodes are available: 1 c_wall violated: 1 conflicting context pair(s) with node memory, 5 node(s) had untolerated taint(s). no new claims to deallocate, preemption: 0/6 nodes are available: 1 No preemption victims found for incoming pod, 5 Preemption is not helpful for scheduling."
14.8611,Event,MODIFIED,eval-sanitize-2-r4-008-f4zj6.18d3d1d2c7bed357,"reason=FailedScheduling count=None msg=0/6 nodes are available: 1 c_wall violated: 2 conflicting context pair(s) with node memory, 5 node(s) had untolerated taint(s). no new claims to deallocate, preemption: 0/6 nodes are available: 1 No preemption victims found for incoming pod, 5 Preemption is not helpful for scheduling."
14.864,Job,MODIFIED,eval-sanitize-2-r4-003,
14.8655,Event,ADDED,eval-sanitize-2-r4-014-vkvct.18d3d1d2e2fd3828,reason=Started count=1 msg=Started container task
14.8692,Event,ADDED,eval-sanitize-2-r4-011-8l98g.18d3d1d2e2fd3845,reason=Started count=1 msg=Started container task
14.8953,Event,ADDED,eval-sanitize-2-r4-010-wmh29.18d3d1d2e4aeefdf,reason=Started count=1 msg=Started container task
14.9762,Job,MODIFIED,eval-sanitize-2-r4-002,
14.978,Job,MODIFIED,eval-sanitize-2-r4-001,
14.9823,Job,MODIFIED,eval-sanitize-2-r4-001,
14.9847,Pod,MODIFIED,eval-sanitize-2-r4-002-z5bgl,phase=Succeeded node=kind-worker
14.9863,Job,MODIFIED,eval-sanitize-2-r4-002,
14.9872,Event,ADDED,eval-sanitize-2-r4-001.18d3d1d2ea2182e1,reason=Completed count=1 msg=Job completed
14.9937,Job,MODIFIED,eval-sanitize-2-r4-001,
14.9994,TaskRequest,MODIFIED,eval-sanitize-2-r4-001,phase=Complete job=None
15.0055,Pod,MODIFIED,eval-sanitize-2-r4-003-7hwjh,phase=Succeeded node=kind-worker4
15.0085,Job,MODIFIED,eval-sanitize-2-r4-001,
15.0085,TaskRequest,ADDED,eval-sanitize-2-r4-015,phase=None job=None
15.0122,TaskRequest,MODIFIED,eval-sanitize-2-r4-015,phase=Pending job=None
15.027,Job,ADDED,eval-sanitize-2-r4-015,
15.0334,Pod,ADDED,eval-sanitize-2-r4-015-45f4d,phase=Pending node=None
15.0335,TaskRequest,MODIFIED,eval-sanitize-2-r4-015,phase=Scheduled job=None
15.0375,Job,MODIFIED,eval-sanitize-2-r4-015,
15.039,Event,ADDED,eval-sanitize-2-r4-015.18d3d1d2ed2651c7,reason=SuccessfulCreate count=1 msg=Created pod: eval-sanitize-2-r4-015-45f4d
15.0422,Pod,MODIFIED,eval-sanitize-2-r4-015-45f4d,phase=Pending node=kind-worker2
15.043,TaskRequest,MODIFIED,eval-sanitize-2-r4-015,phase=Scheduled job=None
15.0486,Job,MODIFIED,eval-sanitize-2-r4-014,
15.0491,Event,ADDED,eval-sanitize-2-r4-015-45f4d.18d3d1d2edaf4800,reason=Scheduled count=None msg=Successfully assigned compute/eval-sanitize-2-r4-015-45f4d to kind-worker2
15.0551,Pod,MODIFIED,eval-sanitize-2-r4-015-45f4d,phase=Pending node=kind-worker2
15.0581,Job,MODIFIED,eval-sanitize-2-r4-014,
15.1717,Node,MODIFIED,kind-worker,taints=1
15.2121,Pod,MODIFIED,eval-sanitize-2-r4-014-vkvct,phase=Running node=kind-worker2
15.2189,Pod,MODIFIED,eval-sanitize-2-r4-007-4mkhx,phase=Running node=kind-worker2
15.2254,Pod,MODIFIED,eval-sanitize-2-r4-010-wmh29,phase=Running node=kind-worker2
15.2318,Pod,MODIFIED,eval-sanitize-2-r4-009-mwm6s,phase=Running node=kind-worker2
15.2374,Pod,MODIFIED,eval-sanitize-2-r4-011-8l98g,phase=Running node=kind-worker2
15.2541,Node,MODIFIED,kind-worker,taints=0
15.2623,Node,MODIFIED,kind-worker,taints=0
15.2719,Node,MODIFIED,kind-worker,taints=0
15.2736,Job,MODIFIED,eval-sanitize-2-r4-007,
15.2857,Job,MODIFIED,eval-sanitize-2-r4-007,
15.2945,Job,MODIFIED,eval-sanitize-2-r4-009,
15.2967,Job,MODIFIED,eval-sanitize-2-r4-010,
15.301,Job,MODIFIED,eval-sanitize-2-r4-011,
15.304,Job,MODIFIED,eval-sanitize-2-r4-009,
15.3063,Job,MODIFIED,eval-sanitize-2-r4-010,
15.3084,Job,MODIFIED,eval-sanitize-2-r4-011,
15.3208,Pod,MODIFIED,eval-sanitize-2-r4-012-s6sg6,phase=Pending node=kind-worker
15.3255,Event,ADDED,eval-sanitize-2-r4-012-s6sg6.18d3d1d2fe4b7502,reason=Scheduled count=None msg=Successfully assigned compute/eval-sanitize-2-r4-012-s6sg6 to kind-worker
15.3316,Node,MODIFIED,kind-worker,taints=0
15.3331,Pod,MODIFIED,eval-sanitize-2-r4-013-tw8qz,phase=Pending node=None
15.3345,Pod,MODIFIED,eval-sanitize-2-r4-012-s6sg6,phase=Pending node=kind-worker
15.3423,Node,MODIFIED,kind-worker,taints=0
15.3466,Pod,MODIFIED,eval-sanitize-2-r4-008-f4zj6,phase=Pending node=kind-worker
15.3498,Event,ADDED,eval-sanitize-2-r4-008-f4zj6.18d3d1d2ffd54703,reason=Scheduled count=None msg=Successfully assigned compute/eval-sanitize-2-r4-008-f4zj6 to kind-worker
15.3577,Node,MODIFIED,kind-worker,taints=0
15.3609,Pod,MODIFIED,eval-sanitize-2-r4-008-f4zj6,phase=Pending node=kind-worker
15.3678,Node,MODIFIED,kind-worker,taints=0
15.4277,Pod,MODIFIED,eval-sanitize-2-r4-013-tw8qz,phase=Pending node=None
15.4285,Event,ADDED,eval-sanitize-2-r4-013-tw8qz.18d3d1d30411c861,"reason=FailedScheduling count=None msg=0/6 nodes are available: 1 c_wall violated: 1 conflicting context pair(s) with node memory, 1 c_wall violated: 2 conflicting context pair(s) with node memory, 4 node(s) had untolerated taint(s). no new claims to deallocate, preemption: 0/6 nodes are available: 2 No preemption victims found for incoming pod, 4 Preemption is not helpful for scheduling."
15.4378,Event,MODIFIED,eval-sanitize-2-r4-013-tw8qz.18d3d1d30411c861,"reason=FailedScheduling count=None msg=0/6 nodes are available: 1 c_wall violated: 1 conflicting context pair(s) with node memory, 1 c_wall violated: 2 conflicting context pair(s) with node memory, 4 node(s) had untolerated taint(s). no new claims to deallocate, preemption: 0/6 nodes are available: 2 No preemption victims found for incoming pod, 4 Preemption is not helpful for scheduling."
15.4438,Event,ADDED,eval-sanitize-2-r4-013-tw8qz.18d3d1d305776835,"reason=FailedScheduling count=None msg=0/6 nodes are available: 1 c_wall violated: 1 conflicting context pair(s) with node memory, 1 c_wall violated: 2 conflicting context pair(s) with node memory, 4 node(s) had untolerated taint(s). no new claims to deallocate, preemption: 0/6 nodes are available: 2 No preemption victims found for incoming pod, 4 Preemption is not helpful for scheduling."
15.4826,Event,ADDED,eval-sanitize-2-r4-015-45f4d.18d3d1d3079a560f,"reason=Pulled count=1 msg=Container image ""busybox:musl"" already present on machine"
15.498,Event,ADDED,eval-sanitize-2-r4-015-45f4d.18d3d1d308a7b776,reason=Created count=1 msg=Created container: task
15.5326,Event,ADDED,eval-sanitize-2-r4-015-45f4d.18d3d1d30ab18eb5,reason=Started count=1 msg=Started container task
15.7389,Event,ADDED,eval-sanitize-2-r4-012-s6sg6.18d3d1d316f591ae,"reason=Pulled count=1 msg=Container image ""busybox:musl"" already present on machine"
15.7553,Event,ADDED,eval-sanitize-2-r4-008-f4zj6.18d3d1d317b1bdc3,"reason=Pulled count=1 msg=Container image ""busybox:musl"" already present on machine"
15.7616,Event,ADDED,eval-sanitize-2-r4-012-s6sg6.18d3d1d318559248,reason=Created count=1 msg=Created container: task
15.773,Event,ADDED,eval-sanitize-2-r4-008-f4zj6.18d3d1d31909f638,reason=Created count=1 msg=Created container: task
15.7926,Event,ADDED,eval-sanitize-2-r4-012-s6sg6.18d3d1d31a31e283,reason=Started count=1 msg=Started container task
15.8037,Event,ADDED,eval-sanitize-2-r4-008-f4zj6.18d3d1d31ae34f08,reason=Started count=1 msg=Started container task
15.8323,Pod,MODIFIED,eval-sanitize-2-r4-005-hs6t9,phase=Running node=kind-worker5
15.8463,Job,MODIFIED,eval-sanitize-2-r4-004,
15.8469,Event,MODIFIED,eval-sanitize-2-r4-013-tw8qz.18d3d1d305776835,"reason=FailedScheduling count=None msg=0/6 nodes are available: 1 c_wall violated: 1 conflicting context pair(s) with node memory, 1 c_wall violated: 2 conflicting context pair(s) with node memory, 4 node(s) had untolerated taint(s). no new claims to deallocate, preemption: 0/6 nodes are available: 2 No preemption victims found for incoming pod, 4 Preemption is not helpful for scheduling."
15.8561,Job,MODIFIED,eval-sanitize-2-r4-003,
15.8621,Job,MODIFIED,eval-sanitize-2-r4-004,
15.8643,Pod,MODIFIED,eval-sanitize-2-r4-003-7hwjh,phase=Succeeded node=kind-worker4
15.8664,Job,MODIFIED,eval-sanitize-2-r4-003,
15.9422,Pod,MODIFIED,eval-sanitize-2-r4-004-ttn6b,phase=Succeeded node=kind-worker4
15.9687,Pod,MODIFIED,eval-sanitize-2-r4-012-s6sg6,phase=Running node=kind-worker
15.9748,Pod,MODIFIED,eval-sanitize-2-r4-008-f4zj6,phase=Running node=kind-worker
15.9816,Job,MODIFIED,eval-sanitize-2-r4-002,
15.9859,Job,MODIFIED,eval-sanitize-2-r4-002,
15.9899,Event,ADDED,eval-sanitize-2-r4-002.18d3d1d325f36d15,reason=Completed count=1 msg=Job completed
15.9964,Job,MODIFIED,eval-sanitize-2-r4-002,
16.0009,TaskRequest,MODIFIED,eval-sanitize-2-r4-002,phase=Complete job=None
16.008,TaskRequest,ADDED,eval-sanitize-2-r4-016,phase=None job=None
16.0107,Job,MODIFIED,eval-sanitize-2-r4-002,
16.0112,TaskRequest,MODIFIED,eval-sanitize-2-r4-016,phase=Pending job=None
16.0251,Job,ADDED,eval-sanitize-2-r4-016,
16.0316,Pod,ADDED,eval-sanitize-2-r4-016-cjlgc,phase=Pending node=None
16.0318,TaskRequest,MODIFIED,eval-sanitize-2-r4-016,phase=Scheduled job=None
16.0342,Job,MODIFIED,eval-sanitize-2-r4-016,
16.0365,Event,ADDED,eval-sanitize-2-r4-016.18d3d1d328aba4d6,reason=SuccessfulCreate count=1 msg=Created pod: eval-sanitize-2-r4-016-cjlgc
16.0392,Job,MODIFIED,eval-sanitize-2-r4-015,
16.0392,TaskRequest,MODIFIED,eval-sanitize-2-r4-016,phase=Scheduled job=None
16.0429,Pod,MODIFIED,eval-sanitize-2-r4-016-cjlgc,phase=Pending node=kind-worker2
16.047,Event,ADDED,eval-sanitize-2-r4-016-cjlgc.18d3d1d32956d951,reason=Scheduled count=None msg=Successfully assigned compute/eval-sanitize-2-r4-016-cjlgc to kind-worker2
16.0497,Job,MODIFIED,eval-sanitize-2-r4-015,
16.0542,Job,MODIFIED,eval-sanitize-2-r4-014,
16.0574,Pod,MODIFIED,eval-sanitize-2-r4-016-cjlgc,phase=Pending node=kind-worker2
16.0865,Job,MODIFIED,eval-sanitize-2-r4-014,
16.2195,Pod,MODIFIED,eval-sanitize-2-r4-015-45f4d,phase=Running node=kind-worker2
16.2845,Node,MODIFIED,kind-worker2,taints=1
16.2923,Pod,MODIFIED,eval-sanitize-2-r4-013-tw8qz,phase=Pending node=None
16.2994,Node,MODIFIED,kind-worker2,taints=1
16.3004,Event,ADDED,eval-sanitize-2-r4-013-tw8qz.18d3d1d3386a6e6d,"reason=FailedScheduling count=None msg=0/6 nodes are available: 1 c_wall violated: 2 conflicting context pair(s) with node memory, 5 node(s) had untolerated taint(s). no new claims to deallocate, preemption: 0/6 nodes are available: 1 No preemption victims found for incoming pod, 5 Preemption is not helpful for scheduling."
16.3061,Event,MODIFIED,eval-sanitize-2-r4-013-tw8qz.18d3d1d3386a6e6d,"reason=FailedScheduling count=None msg=0/6 nodes are available: 1 c_wall violated: 2 conflicting context pair(s) with node memory, 5 node(s) had untolerated taint(s). no new claims to deallocate, preemption: 0/6 nodes are available: 1 No preemption victims found for incoming pod, 5 Preemption is not helpful for scheduling."
16.3263,Job,MODIFIED,eval-sanitize-2-r4-012,
16.3348,Job,MODIFIED,eval-sanitize-2-r4-012,
16.3517,Job,MODIFIED,eval-sanitize-2-r4-008,
16.3616,Job,MODIFIED,eval-sanitize-2-r4-008,
16.4826,Event,ADDED,eval-sanitize-2-r4-016-cjlgc.18d3d1d343345cde,"reason=Pulled count=1 msg=Container image ""busybox:musl"" already present on machine"
16.4984,Event,ADDED,eval-sanitize-2-r4-016-cjlgc.18d3d1d34443630a,reason=Created count=1 msg=Created container: task
16.5767,Event,ADDED,eval-sanitize-2-r4-016-cjlgc.18d3d1d348eb5d4e,reason=Started count=1 msg=Started container task
16.793,Pod,MODIFIED,eval-sanitize-2-r4-006-8fdtg,phase=Running node=kind-worker3
16.8579,Job,MODIFIED,eval-sanitize-2-r4-005,
16.8601,Job,MODIFIED,eval-sanitize-2-r4-004,
16.8626,Job,MODIFIED,eval-sanitize-2-r4-003,
16.8669,Job,MODIFIED,eval-sanitize-2-r4-003,
16.8692,Job,MODIFIED,eval-sanitize-2-r4-005,
16.8706,Pod,MODIFIED,eval-sanitize-2-r4-004-ttn6b,phase=Succeeded node=kind-worker4
16.8716,Job,MODIFIED,eval-sanitize-2-r4-004,
16.8722,Event,ADDED,eval-sanitize-2-r4-003.18d3d1d35a78c0cf,reason=Completed count=1 msg=Job completed
16.8766,Job,MODIFIED,eval-sanitize-2-r4-003,
16.8802,TaskRequest,MODIFIED,eval-sanitize-2-r4-003,phase=Complete job=None
16.8882,Job,MODIFIED,eval-sanitize-2-r4-003,
16.9152,Node,MODIFIED,kind-worker4,taints=1
16.9715,Node,MODIFIED,kind-worker4,taints=0
16.98,Node,MODIFIED,kind-worker4,taints=0
16.9815,Pod,MODIFIED,eval-sanitize-2-r4-013-tw8qz,phase=Pending node=kind-worker4
16.9849,Event,ADDED,eval-sanitize-2-r4-013-tw8qz.18d3d1d3614bf441,reason=Scheduled count=None msg=Successfully assigned compute/eval-sanitize-2-r4-013-tw8qz to kind-worker4
16.9915,Node,MODIFIED,kind-worker4,taints=0
16.993,Pod,MODIFIED,eval-sanitize-2-r4-013-tw8qz,phase=Pending node=kind-worker4
17.0064,TaskRequest,ADDED,eval-sanitize-2-r4-017,phase=None job=None
17.0097,TaskRequest,MODIFIED,eval-sanitize-2-r4-017,phase=Pending job=None
17.0158,Node,MODIFIED,kind-worker4,taints=0
17.019,Pod,MODIFIED,eval-sanitize-2-r4-005-hs6t9,phase=Succeeded node=kind-worker5
17.0261,Node,MODIFIED,kind-worker4,taints=0
17.0269,Job,ADDED,eval-sanitize-2-r4-017,
17.0304,TaskRequest,MODIFIED,eval-sanitize-2-r4-017,phase=Scheduled job=None
17.0335,Pod,ADDED,eval-sanitize-2-r4-017-mnp4k,phase=Pending node=None
17.036,Job,MODIFIED,eval-sanitize-2-r4-017,
17.0377,Job,MODIFIED,eval-sanitize-2-r4-016,
17.0399,Event,ADDED,eval-sanitize-2-r4-017.18d3d1d36464a2ee,reason=SuccessfulCreate count=1 msg=Created pod: eval-sanitize-2-r4-017-mnp4k
17.04,TaskRequest,MODIFIED,eval-sanitize-2-r4-017,phase=Scheduled job=None
17.0438,Job,MODIFIED,eval-sanitize-2-r4-015,
17.0461,Pod,MODIFIED,eval-sanitize-2-r4-017-mnp4k,phase=Pending node=kind-worker4
17.0486,Job,MODIFIED,eval-sanitize-2-r4-016,
17.0519,Event,ADDED,eval-sanitize-2-r4-017-mnp4k.18d3d1d365250f48,reason=Scheduled count=None msg=Successfully assigned compute/eval-sanitize-2-r4-017-mnp4k to kind-worker4
17.0544,Job,MODIFIED,eval-sanitize-2-r4-015,
17.0576,Node,MODIFIED,kind-worker4,taints=0
17.0591,Pod,MODIFIED,eval-sanitize-2-r4-017-mnp4k,phase=Pending node=kind-worker4
17.0675,Node,MODIFIED,kind-worker4,taints=0
17.2283,Pod,MODIFIED,eval-sanitize-2-r4-016-cjlgc,phase=Running node=kind-worker2
17.2844,Node,MODIFIED,kind-worker,taints=1
17.2991,Node,MODIFIED,kind-worker,taints=1
17.4273,Event,ADDED,eval-sanitize-2-r4-013-tw8qz.18d3d1d37b920147,"reason=Pulled count=1 msg=Container image ""busybox:musl"" already present on machine"
17.4438,Event,ADDED,eval-sanitize-2-r4-013-tw8qz.18d3d1d37ca338fc,reason=Created count=1 msg=Created container: task
17.4641,Event,ADDED,eval-sanitize-2-r4-017-mnp4k.18d3d1d37dcc5f14,"reason=Pulled count=1 msg=Container image ""busybox:musl"" already present on machine"
17.4789,Event,ADDED,eval-sanitize-2-r4-013-tw8qz.18d3d1d37ea0fe75,reason=Started count=1 msg=Started container task
17.4842,Event,ADDED,eval-sanitize-2-r4-017-mnp4k.18d3d1d37f123a82,reason=Created count=1 msg=Created container: task
17.5147,Event,ADDED,eval-sanitize-2-r4-017-mnp4k.18d3d1d380d6e240,reason=Started count=1 msg=Started container task
17.8016,Job,MODIFIED,eval-sanitize-2-r4-006,
17.8121,Job,MODIFIED,eval-sanitize-2-r4-006,
17.8499,Pod,MODIFIED,eval-sanitize-2-r4-017-mnp4k,phase=Running node=kind-worker4
17.8561,Pod,MODIFIED,eval-sanitize-2-r4-013-tw8qz,phase=Running node=kind-worker4
17.8633,Job,MODIFIED,eval-sanitize-2-r4-005,
17.865,Job,MODIFIED,eval-sanitize-2-r4-004,
17.8697,Job,MODIFIED,eval-sanitize-2-r4-004,
17.8741,Pod,MODIFIED,eval-sanitize-2-r4-005-hs6t9,phase=Succeeded node=kind-worker5
17.8745,Event,ADDED,eval-sanitize-2-r4-004.18d3d1d3963b0ce0,reason=Completed count=1 msg=Job completed
17.8755,Job,MODIFIED,eval-sanitize-2-r4-005,
17.8803,Pod,MODIFIED,eval-sanitize-2-r4-006-8fdtg,phase=Succeeded node=kind-worker3
17.8813,Job,MODIFIED,eval-sanitize-2-r4-004,
17.8868,TaskRequest,MODIFIED,eval-sanitize-2-r4-004,phase=Complete job=None
17.8952,Job,MODIFIED,eval-sanitize-2-r4-004,
17.9951,Job,MODIFIED,eval-sanitize-2-r4-013,
18.0039,Job,MODIFIED,eval-sanitize-2-r4-013,
18.0108,TaskRequest,ADDED,eval-sanitize-2-r4-018,phase=None job=None
18.0141,TaskRequest,MODIFIED,eval-sanitize-2-r4-018,phase=Pending job=None
18.0293,Job,ADDED,eval-sanitize-2-r4-018,
18.0367,Pod,ADDED,eval-sanitize-2-r4-018-f6rrd,phase=Pending node=None
18.0385,Job,MODIFIED,eval-sanitize-2-r4-017,
18.0386,TaskRequest,MODIFIED,eval-sanitize-2-r4-018,phase=Scheduled job=None
18.0406,Job,MODIFIED,eval-sanitize-2-r4-018,
18.0422,Event,ADDED,eval-sanitize-2-r4-018.18d3d1d3a02d1f35,reason=SuccessfulCreate count=1 msg=Created pod: eval-sanitize-2-r4-018-f6rrd
18.043,Job,MODIFIED,eval-sanitize-2-r4-016,
18.0451,Pod,MODIFIED,eval-sanitize-2-r4-018-f6rrd,phase=Pending node=None
18.047,Event,ADDED,eval-sanitize-2-r4-018-f6rrd.18d3d1d3a06fcc5c,"reason=FailedScheduling count=None msg=0/6 nodes are available: 1 c_wall violated: 1 conflicting context pair(s) with node memory, 5 node(s) had untolerated taint(s). no new claims to deallocate, preemption: 0/6 nodes are available: 1 No preemption victims found for incoming pod, 5 Preemption is not helpful for scheduling."
18.05,Job,MODIFIED,eval-sanitize-2-r4-017,
18.0501,TaskRequest,MODIFIED,eval-sanitize-2-r4-018,phase=Scheduled job=None
18.0517,Job,MODIFIED,eval-sanitize-2-r4-016,
18.0523,Event,ADDED,eval-sanitize-2-r4-018-f6rrd.18d3d1d3a0e9f5af,"reason=FailedScheduling count=None msg=0/6 nodes are available: 1 c_wall violated: 1 conflicting context pair(s) with node memory, 5 node(s) had untolerated taint(s). no new claims to deallocate, preemption: 0/6 nodes are available: 1 No preemption victims found for incoming pod, 5 Preemption is not helpful for scheduling."
18.1835,Node,MODIFIED,kind-worker5,taints=1
18.1906,Event,MODIFIED,eval-sanitize-2-r4-018-f6rrd.18d3d1d3a0e9f5af,"reason=FailedScheduling count=None msg=0/6 nodes are available: 1 c_wall violated: 1 conflicting context pair(s) with node memory, 5 node(s) had untolerated taint(s). no new claims to deallocate, preemption: 0/6 nodes are available: 1 No preemption victims found for incoming pod, 5 Preemption is not helpful for scheduling."
18.1976,Node,MODIFIED,kind-worker5,taints=1
18.205,Node,MODIFIED,kind-worker5,taints=0
18.2128,Pod,MODIFIED,eval-sanitize-2-r4-018-f6rrd,phase=Pending node=kind-worker5
18.2154,Event,ADDED,eval-sanitize-2-r4-018-f6rrd.18d3d1d3aaa9a88a,reason=Scheduled count=None msg=Successfully assigned compute/eval-sanitize-2-r4-018-f6rrd to kind-worker5
18.2213,Pod,MODIFIED,eval-sanitize-2-r4-018-f6rrd,phase=Pending node=kind-worker5
18.2233,Node,MODIFIED,kind-worker5,taints=0
18.2526,Node,MODIFIED,kind-worker5,taints=0
18.2619,Node,MODIFIED,kind-worker5,taints=0
18.6246,Event,ADDED,eval-sanitize-2-r4-018-f6rrd.18d3d1d3c2fcd625,"reason=Pulled count=1 msg=Container image ""busybox:musl"" already present on machine"
18.6431,Event,ADDED,eval-sanitize-2-r4-018-f6rrd.18d3d1d3c4150845,reason=Created count=1 msg=Created container: task
18.6739,Event,ADDED,eval-sanitize-2-r4-018-f6rrd.18d3d1d3c5f6280f,reason=Started count=1 msg=Started container task
18.8081,Job,MODIFIED,eval-sanitize-2-r4-006,
18.8161,Pod,MODIFIED,eval-sanitize-2-r4-006-8fdtg,phase=Succeeded node=kind-worker3
18.8174,Job,MODIFIED,eval-sanitize-2-r4-006,
18.8348,Pod,MODIFIED,eval-sanitize-2-r4-018-f6rrd,phase=Running node=kind-worker5
18.8682,Job,MODIFIED,eval-sanitize-2-r4-005,
18.8724,Job,MODIFIED,eval-sanitize-2-r4-005,
18.8752,Event,ADDED,eval-sanitize-2-r4-005.18d3d1d3d20267fc,reason=Completed count=1 msg=Job completed
18.8836,Job,MODIFIED,eval-sanitize-2-r4-005,
18.889,TaskRequest,MODIFIED,eval-sanitize-2-r4-005,phase=Complete job=None
18.8979,Job,MODIFIED,eval-sanitize-2-r4-005,
18.9901,Node,MODIFIED,kind-worker4,taints=1
19.0083,TaskRequest,ADDED,eval-sanitize-2-r4-019,phase=None job=None
19.0118,TaskRequest,MODIFIED,eval-sanitize-2-r4-019,phase=Pending job=None
19.0262,Job,ADDED,eval-sanitize-2-r4-019,
19.0309,Pod,ADDED,eval-sanitize-2-r4-019-5xr88,phase=Pending node=None
19.0323,TaskRequest,MODIFIED,eval-sanitize-2-r4-019,phase=Scheduled job=None
19.0349,Job,MODIFIED,eval-sanitize-2-r4-019,
19.0368,Event,ADDED,eval-sanitize-2-r4-019.18d3d1d3db776fff,reason=SuccessfulCreate count=1 msg=Created pod: eval-sanitize-2-r4-019-5xr88
19.0399,Pod,MODIFIED,eval-sanitize-2-r4-019-5xr88,phase=Pending node=None
19.0414,Event,ADDED,eval-sanitize-2-r4-019-5xr88.18d3d1d3dbb59ba4,"reason=FailedScheduling count=None msg=0/6 nodes are available: 1 c_wall violated: 1 conflicting context pair(s) with node memory, 5 node(s) had untolerated taint(s). no new claims to deallocate, preemption: 0/6 nodes are available: 1 No preemption victims found for incoming pod, 5 Preemption is not helpful for scheduling."
19.0426,Job,MODIFIED,eval-sanitize-2-r4-018,
19.0427,TaskRequest,MODIFIED,eval-sanitize-2-r4-019,phase=Scheduled job=None
19.0476,Event,ADDED,eval-sanitize-2-r4-019-5xr88.18d3d1d3dc3fc163,"reason=FailedScheduling count=None msg=0/6 nodes are available: 1 c_wall violated: 1 conflicting context pair(s) with node memory, 5 node(s) had untolerated taint(s). no new claims to deallocate, preemption: 0/6 nodes are available: 1 No preemption victims found for incoming pod, 5 Preemption is not helpful for scheduling."
19.0518,Job,MODIFIED,eval-sanitize-2-r4-018,
19.0628,Node,MODIFIED,kind-worker4,taints=1
19.071,Event,MODIFIED,eval-sanitize-2-r4-019-5xr88.18d3d1d3dc3fc163,"reason=FailedScheduling count=None msg=0/6 nodes are available: 1 c_wall violated: 1 conflicting context pair(s) with node memory, 5 node(s) had untolerated taint(s). no new claims to deallocate, preemption: 0/6 nodes are available: 1 No preemption victims found for incoming pod, 5 Preemption is not helpful for scheduling."
19.262,Node,MODIFIED,kind-worker3,taints=1
19.2745,Node,MODIFIED,kind-worker3,taints=0
19.2852,Pod,MODIFIED,eval-sanitize-2-r4-019-5xr88,phase=Pending node=kind-worker3
19.2888,Node,MODIFIED,kind-worker3,taints=0
19.2892,Event,ADDED,eval-sanitize-2-r4-019-5xr88.18d3d1d3ea888003,reason=Scheduled count=None msg=Successfully assigned compute/eval-sanitize-2-r4-019-5xr88 to kind-worker3
19.2965,Pod,MODIFIED,eval-sanitize-2-r4-019-5xr88,phase=Pending node=kind-worker3
19.3129,Node,MODIFIED,kind-worker3,taints=0
19.3538,Node,MODIFIED,kind-worker3,taints=0
19.3662,Node,MODIFIED,kind-worker3,taints=0
19.7031,Event,ADDED,eval-sanitize-2-r4-019-5xr88.18d3d1d4034b76c2,"reason=Pulled count=1 msg=Container image ""busybox:musl"" already present on machine"
19.7196,Event,ADDED,eval-sanitize-2-r4-019-5xr88.18d3d1d40451acbe,reason=Created count=1 msg=Created container: task
19.7523,Event,ADDED,eval-sanitize-2-r4-019-5xr88.18d3d1d4063a02d1,reason=Started count=1 msg=Started container task
19.7856,Pod,MODIFIED,eval-sanitize-2-r4-019-5xr88,phase=Running node=kind-worker3
19.8149,Job,MODIFIED,eval-sanitize-2-r4-006,
19.8186,Job,MODIFIED,eval-sanitize-2-r4-006,
19.8219,Event,ADDED,eval-sanitize-2-r4-006.18d3d1d40a6d06db,reason=Completed count=1 msg=Job completed
19.8306,Job,MODIFIED,eval-sanitize-2-r4-006,
19.8349,TaskRequest,MODIFIED,eval-sanitize-2-r4-006,phase=Complete job=None
19.8436,Job,MODIFIED,eval-sanitize-2-r4-006,
20.0081,TaskRequest,ADDED,eval-sanitize-2-r4-020,phase=None job=None
20.0122,TaskRequest,MODIFIED,eval-sanitize-2-r4-020,phase=Pending job=None
20.0278,Job,ADDED,eval-sanitize-2-r4-020,
20.0341,Pod,ADDED,eval-sanitize-2-r4-020-qv5qd,phase=Pending node=None
20.0355,TaskRequest,MODIFIED,eval-sanitize-2-r4-020,phase=Scheduled job=None
20.0365,Job,MODIFIED,eval-sanitize-2-r4-019,
20.0381,Job,MODIFIED,eval-sanitize-2-r4-020,
20.0385,Event,ADDED,eval-sanitize-2-r4-020.18d3d1d4173f9673,reason=SuccessfulCreate count=1 msg=Created pod: eval-sanitize-2-r4-020-qv5qd
20.0449,TaskRequest,MODIFIED,eval-sanitize-2-r4-020,phase=Scheduled job=None
20.0477,Job,MODIFIED,eval-sanitize-2-r4-019,
20.0522,Pod,MODIFIED,eval-sanitize-2-r4-020-qv5qd,phase=Pending node=kind-worker3
20.0565,Event,ADDED,eval-sanitize-2-r4-020-qv5qd.18d3d1d41853ee61,reason=Scheduled count=None msg=Successfully assigned compute/eval-sanitize-2-r4-020-qv5qd to kind-worker3
20.063,Node,MODIFIED,kind-worker3,taints=0
20.0647,Pod,MODIFIED,eval-sanitize-2-r4-020-qv5qd,phase=Pending node=kind-worker3
20.0721,Node,MODIFIED,kind-worker3,taints=0
20.2625,Node,MODIFIED,kind-worker5,taints=1
20.2751,Node,MODIFIED,kind-worker5,taints=1
20.4739,Event,ADDED,eval-sanitize-2-r4-020-qv5qd.18d3d1d43139db09,"reason=Pulled count=1 msg=Container image ""busybox:musl"" already present on machine"
20.4911,Event,ADDED,eval-sanitize-2-r4-020-qv5qd.18d3d1d4324669a5,reason=Created count=1 msg=Created container: task
20.5224,Event,ADDED,eval-sanitize-2-r4-020-qv5qd.18d3d1d43411f926,reason=Started count=1 msg=Started container task
20.7898,Pod,MODIFIED,eval-sanitize-2-r4-020-qv5qd,phase=Running node=kind-worker3
21.0095,TaskRequest,ADDED,eval-sanitize-2-r4-021,phase=None job=None
21.0158,TaskRequest,MODIFIED,eval-sanitize-2-r4-021,phase=Pending job=None
21.0309,Job,ADDED,eval-sanitize-2-r4-021,
21.0362,TaskRequest,MODIFIED,eval-sanitize-2-r4-021,phase=Scheduled job=None
21.0404,Pod,ADDED,eval-sanitize-2-r4-021-vzk2p,phase=Pending node=None
21.0415,Job,MODIFIED,eval-sanitize-2-r4-020,
21.0424,Job,MODIFIED,eval-sanitize-2-r4-021,
21.0434,Event,ADDED,eval-sanitize-2-r4-021.18d3d1d45335cbd8,reason=SuccessfulCreate count=1 msg=Created pod: eval-sanitize-2-r4-021-vzk2p
21.0455,TaskRequest,MODIFIED,eval-sanitize-2-r4-021,phase=Scheduled job=None
21.0494,Pod,MODIFIED,eval-sanitize-2-r4-021-vzk2p,phase=Pending node=None
21.0501,Event,ADDED,eval-sanitize-2-r4-021-vzk2p.18d3d1d453760ab8,"reason=FailedScheduling count=None msg=0/6 nodes are available: 1 c_wall violated: 1 conflicting context pair(s) with node memory, 5 node(s) had untolerated taint(s). no new claims to deallocate, preemption: 0/6 nodes are available: 1 No preemption victims found for incoming pod, 5 Preemption is not helpful for scheduling."
21.0509,Job,MODIFIED,eval-sanitize-2-r4-020,
21.0566,Event,ADDED,eval-sanitize-2-r4-021-vzk2p.18d3d1d453ff2018,"reason=FailedScheduling count=None msg=0/6 nodes are available: 1 c_wall violated: 1 conflicting context pair(s) with node memory, 5 node(s) had untolerated taint(s). no new claims to deallocate, preemption: 0/6 nodes are available: 1 No preemption victims found for incoming pod, 5 Preemption is not helpful for scheduling."
21.2999,Node,MODIFIED,kind-worker3,taints=1
21.305,Pod,MODIFIED,eval-sanitize-2-r4-021-vzk2p,phase=Pending node=None
21.3057,Event,MODIFIED,eval-sanitize-2-r4-021-vzk2p.18d3d1d453ff2018,"reason=FailedScheduling count=None msg=0/6 nodes are available: 1 c_wall violated: 1 conflicting context pair(s) with node memory, 5 node(s) had untolerated taint(s). no new claims to deallocate, preemption: 0/6 nodes are available: 1 No preemption victims found for incoming pod, 5 Preemption is not helpful for scheduling."
21.3121,Node,MODIFIED,kind-worker3,taints=1
21.7685,Node,MODIFIED,kind-control-plane,taints=1
22.0097,TaskRequest,ADDED,eval-sanitize-2-r4-022,phase=None job=None
22.014,TaskRequest,MODIFIED,eval-sanitize-2-r4-022,phase=Pending job=None
22.03,Job,ADDED,eval-sanitize-2-r4-022,
22.0342,TaskRequest,MODIFIED,eval-sanitize-2-r4-022,phase=Scheduled job=None
22.0383,Pod,ADDED,eval-sanitize-2-r4-022-kvzd5,phase=Pending node=None
22.0397,Job,MODIFIED,eval-sanitize-2-r4-022,
22.0439,Event,ADDED,eval-sanitize-2-r4-022.18d3d1d48eaba683,reason=SuccessfulCreate count=1 msg=Created pod: eval-sanitize-2-r4-022-kvzd5
22.0441,Event,ADDED,eval-sanitize-2-r4-022-kvzd5.18d3d1d48eb85a27,"reason=FailedScheduling count=None msg=0/6 nodes are available: 6 node(s) had untolerated taint(s). no new claims to deallocate, preemption: 0/6 nodes are available: 6 Preemption is not helpful for scheduling."
22.0442,TaskRequest,MODIFIED,eval-sanitize-2-r4-022,phase=Scheduled job=None
22.0451,Pod,MODIFIED,eval-sanitize-2-r4-022-kvzd5,phase=Pending node=None
22.046,Job,MODIFIED,eval-sanitize-2-r4-021,
22.0559,Job,MODIFIED,eval-sanitize-2-r4-021,
23.0148,TaskRequest,ADDED,eval-sanitize-2-r4-023,phase=None job=None
23.0183,TaskRequest,MODIFIED,eval-sanitize-2-r4-023,phase=Pending job=None
23.0359,Job,ADDED,eval-sanitize-2-r4-023,
23.0444,Job,MODIFIED,eval-sanitize-2-r4-022,
23.0446,TaskRequest,MODIFIED,eval-sanitize-2-r4-023,phase=Scheduled job=None
23.0457,Pod,ADDED,eval-sanitize-2-r4-023-6hkqq,phase=Pending node=None
23.047,Job,MODIFIED,eval-sanitize-2-r4-023,
23.0526,Event,ADDED,eval-sanitize-2-r4-023.18d3d1d4cabfec63,reason=SuccessfulCreate count=1 msg=Created pod: eval-sanitize-2-r4-023-6hkqq
23.0529,Event,ADDED,eval-sanitize-2-r4-023-6hkqq.18d3d1d4cacdd3b6,"reason=FailedScheduling count=None msg=0/6 nodes are available: 6 node(s) had untolerated taint(s). no new claims to deallocate, preemption: 0/6 nodes are available: 6 Preemption is not helpful for scheduling."
23.0539,Pod,MODIFIED,eval-sanitize-2-r4-023-6hkqq,phase=Pending node=None
23.0552,Job,MODIFIED,eval-sanitize-2-r4-022,
23.0553,TaskRequest,MODIFIED,eval-sanitize-2-r4-023,phase=Scheduled job=None
24.0086,TaskRequest,ADDED,eval-sanitize-2-r4-024,phase=None job=None
24.0125,TaskRequest,MODIFIED,eval-sanitize-2-r4-024,phase=Pending job=None
24.0282,Job,ADDED,eval-sanitize-2-r4-024,
24.0349,Pod,ADDED,eval-sanitize-2-r4-024-m4dwq,phase=Pending node=None
24.038,Job,MODIFIED,eval-sanitize-2-r4-024,
24.0413,Event,ADDED,eval-sanitize-2-r4-024.18d3d1d505ba90ce,reason=SuccessfulCreate count=1 msg=Created pod: eval-sanitize-2-r4-024-m4dwq
24.0415,Event,ADDED,eval-sanitize-2-r4-024-m4dwq.18d3d1d505c5fbaf,"reason=FailedScheduling count=None msg=0/6 nodes are available: 6 node(s) had untolerated taint(s). no new claims to deallocate, preemption: 0/6 nodes are available: 6 Preemption is not helpful for scheduling."
24.0426,Pod,MODIFIED,eval-sanitize-2-r4-024-m4dwq,phase=Pending node=None
24.0506,Job,MODIFIED,eval-sanitize-2-r4-023,
24.1353,TaskRequest,MODIFIED,eval-sanitize-2-r4-024,phase=Scheduled job=None
24.1945,Job,MODIFIED,eval-sanitize-2-r4-023,
24.1951,TaskRequest,MODIFIED,eval-sanitize-2-r4-024,phase=Scheduled job=None
25.0085,TaskRequest,ADDED,eval-sanitize-2-r4-025,phase=None job=None
25.0141,TaskRequest,MODIFIED,eval-sanitize-2-r4-025,phase=Pending job=None
25.0282,Job,ADDED,eval-sanitize-2-r4-025,
25.0353,Pod,ADDED,eval-sanitize-2-r4-025-dphm6,phase=Pending node=None
25.0358,TaskRequest,MODIFIED,eval-sanitize-2-r4-025,phase=Scheduled job=None
25.0386,Job,MODIFIED,eval-sanitize-2-r4-025,
25.0403,Event,ADDED,eval-sanitize-2-r4-025.18d3d1d541516615,reason=SuccessfulCreate count=1 msg=Created pod: eval-sanitize-2-r4-025-dphm6
25.0407,Event,ADDED,eval-sanitize-2-r4-025-dphm6.18d3d1d54162aab5,"reason=FailedScheduling count=None msg=0/6 nodes are available: 6 node(s) had untolerated taint(s). no new claims to deallocate, preemption: 0/6 nodes are available: 6 Preemption is not helpful for scheduling."
25.0415,Job,MODIFIED,eval-sanitize-2-r4-024,
25.0423,Pod,MODIFIED,eval-sanitize-2-r4-025-dphm6,phase=Pending node=None
25.0443,TaskRequest,MODIFIED,eval-sanitize-2-r4-025,phase=Scheduled job=None
25.0513,Job,MODIFIED,eval-sanitize-2-r4-024,
25.24,Pod,MODIFIED,eval-sanitize-2-r4-009-mwm6s,phase=Running node=kind-worker2
25.2467,Pod,MODIFIED,eval-sanitize-2-r4-014-vkvct,phase=Running node=kind-worker2
25.2529,Pod,MODIFIED,eval-sanitize-2-r4-007-4mkhx,phase=Running node=kind-worker2
25.2597,Pod,MODIFIED,eval-sanitize-2-r4-010-wmh29,phase=Running node=kind-worker2
25.2653,Pod,MODIFIED,eval-sanitize-2-r4-011-8l98g,phase=Running node=kind-worker2
25.9909,Pod,MODIFIED,eval-sanitize-2-r4-012-s6sg6,phase=Running node=kind-worker
25.9969,Pod,MODIFIED,eval-sanitize-2-r4-008-f4zj6,phase=Running node=kind-worker
26.008,TaskRequest,ADDED,eval-sanitize-2-r4-026,phase=None job=None
26.0118,TaskRequest,MODIFIED,eval-sanitize-2-r4-026,phase=Pending job=None
26.0266,Job,ADDED,eval-sanitize-2-r4-026,
26.0319,Pod,ADDED,eval-sanitize-2-r4-026-ltj94,phase=Pending node=None
26.0335,TaskRequest,MODIFIED,eval-sanitize-2-r4-026,phase=Scheduled job=None
26.036,Job,MODIFIED,eval-sanitize-2-r4-026,
26.0376,Event,ADDED,eval-sanitize-2-r4-026.18d3d1d57cc165c1,reason=SuccessfulCreate count=1 msg=Created pod: eval-sanitize-2-r4-026-ltj94
26.0378,Event,ADDED,eval-sanitize-2-r4-026-ltj94.18d3d1d57ccb4f94,"reason=FailedScheduling count=None msg=0/6 nodes are available: 6 node(s) had untolerated taint(s). no new claims to deallocate, preemption: 0/6 nodes are available: 6 Preemption is not helpful for scheduling."
26.0387,Pod,MODIFIED,eval-sanitize-2-r4-026-ltj94,phase=Pending node=None
26.0399,Job,MODIFIED,eval-sanitize-2-r4-025,
26.0419,TaskRequest,MODIFIED,eval-sanitize-2-r4-026,phase=Scheduled job=None
26.0483,Job,MODIFIED,eval-sanitize-2-r4-025,
26.249,Job,MODIFIED,eval-sanitize-2-r4-009,
26.251,Pod,MODIFIED,eval-sanitize-2-r4-015-45f4d,phase=Running node=kind-worker2
26.2525,Job,MODIFIED,eval-sanitize-2-r4-014,
26.2579,Job,MODIFIED,eval-sanitize-2-r4-007,
26.2607,Job,MODIFIED,eval-sanitize-2-r4-009,
26.2627,Job,MODIFIED,eval-sanitize-2-r4-014,
26.2647,Job,MODIFIED,eval-sanitize-2-r4-010,
26.2667,Job,MODIFIED,eval-sanitize-2-r4-007,
26.2701,Job,MODIFIED,eval-sanitize-2-r4-011,
26.2731,Job,MODIFIED,eval-sanitize-2-r4-010,
26.2797,Job,MODIFIED,eval-sanitize-2-r4-011,
26.3867,Pod,MODIFIED,eval-sanitize-2-r4-010-wmh29,phase=Succeeded node=kind-worker2
26.4365,Pod,MODIFIED,eval-sanitize-2-r4-014-vkvct,phase=Succeeded node=kind-worker2
26.4436,Pod,MODIFIED,eval-sanitize-2-r4-007-4mkhx,phase=Succeeded node=kind-worker2
26.4493,Pod,MODIFIED,eval-sanitize-2-r4-009-mwm6s,phase=Succeeded node=kind-worker2
26.455,Pod,MODIFIED,eval-sanitize-2-r4-011-8l98g,phase=Succeeded node=kind-worker2
26.9987,Job,MODIFIED,eval-sanitize-2-r4-012,
27.0024,Job,MODIFIED,eval-sanitize-2-r4-008,
27.0099,TaskRequest,ADDED,eval-sanitize-2-r4-027,phase=None job=None
27.0146,Job,MODIFIED,eval-sanitize-2-r4-012,
27.0155,Job,MODIFIED,eval-sanitize-2-r4-008,
27.0156,TaskRequest,MODIFIED,eval-sanitize-2-r4-027,phase=Pending job=None
27.0313,Job,ADDED,eval-sanitize-2-r4-027,
27.0365,Job,MODIFIED,eval-sanitize-2-r4-026,
27.0374,TaskRequest,MODIFIED,eval-sanitize-2-r4-027,phase=Scheduled job=None
27.0389,Pod,ADDED,eval-sanitize-2-r4-027-5cbcr,phase=Pending node=None
27.0403,Job,MODIFIED,eval-sanitize-2-r4-027,
27.0442,Event,ADDED,eval-sanitize-2-r4-027.18d3d1d5b8bedee4,reason=SuccessfulCreate count=1 msg=Created pod: eval-sanitize-2-r4-027-5cbcr
27.0445,Event,ADDED,eval-sanitize-2-r4-027-5cbcr.18d3d1d5b8cd5f4e,"reason=FailedScheduling count=None msg=0/6 nodes are available: 6 node(s) had untolerated taint(s). no new claims to deallocate, preemption: 0/6 nodes are available: 6 Preemption is not helpful for scheduling."
27.0454,Pod,MODIFIED,eval-sanitize-2-r4-027-5cbcr,phase=Pending node=None
27.047,Job,MODIFIED,eval-sanitize-2-r4-026,
27.0472,TaskRequest,MODIFIED,eval-sanitize-2-r4-027,phase=Scheduled job=None
27.1384,Pod,MODIFIED,eval-sanitize-2-r4-012-s6sg6,phase=Succeeded node=kind-worker
27.1434,Pod,MODIFIED,eval-sanitize-2-r4-008-f4zj6,phase=Succeeded node=kind-worker
27.2541,Job,MODIFIED,eval-sanitize-2-r4-009,
27.2563,Job,MODIFIED,eval-sanitize-2-r4-015,
27.2608,Job,MODIFIED,eval-sanitize-2-r4-014,
27.2641,Pod,MODIFIED,eval-sanitize-2-r4-016-cjlgc,phase=Running node=kind-worker2
27.2674,Pod,MODIFIED,eval-sanitize-2-r4-009-mwm6s,phase=Succeeded node=kind-worker2
27.2682,Job,MODIFIED,eval-sanitize-2-r4-007,
27.2695,Job,MODIFIED,eval-sanitize-2-r4-009,
27.2704,Job,MODIFIED,eval-sanitize-2-r4-015,
27.2726,Job,MODIFIED,eval-sanitize-2-r4-010,
27.2746,Pod,MODIFIED,eval-sanitize-2-r4-014-vkvct,phase=Succeeded node=kind-worker2
27.2756,Job,MODIFIED,eval-sanitize-2-r4-014,
27.2778,Pod,MODIFIED,eval-sanitize-2-r4-007-4mkhx,phase=Succeeded node=kind-worker2
27.2791,Job,MODIFIED,eval-sanitize-2-r4-011,
27.2821,Job,MODIFIED,eval-sanitize-2-r4-007,
27.2862,Job,MODIFIED,eval-sanitize-2-r4-010,
27.2876,Pod,MODIFIED,eval-sanitize-2-r4-010-wmh29,phase=Succeeded node=kind-worker2
27.2897,Pod,MODIFIED,eval-sanitize-2-r4-011-8l98g,phase=Succeeded node=kind-worker2
27.2919,Job,MODIFIED,eval-sanitize-2-r4-011,
27.4391,Pod,MODIFIED,eval-sanitize-2-r4-015-45f4d,phase=Succeeded node=kind-worker2
27.7291,Node,MODIFIED,kind-worker,taints=1
27.7418,Node,MODIFIED,kind-worker,taints=1
27.7523,Node,MODIFIED,kind-worker,taints=0
27.7577,Pod,MODIFIED,eval-sanitize-2-r4-021-vzk2p,phase=Pending node=kind-worker
27.7623,Event,ADDED,eval-sanitize-2-r4-021-vzk2p.18d3d1d5e39ea894,reason=Scheduled count=None msg=Successfully assigned compute/eval-sanitize-2-r4-021-vzk2p to kind-worker
27.7662,Node,MODIFIED,kind-worker,taints=0
27.7671,Event,ADDED,eval-sanitize-2-r4-022-kvzd5.18d3d1d5e3d7d77c,"reason=FailedScheduling count=None msg=0/6 nodes are available: 1 c_wall violated: 1 conflicting context pair(s) with node memory, 5 node(s) had untolerated taint(s). no new claims to deallocate, preemption: 0/6 nodes are available: 1 No preemption victims found for incoming pod, 5 Preemption is not helpful for scheduling."
27.7681,Pod,MODIFIED,eval-sanitize-2-r4-022-kvzd5,phase=Pending node=None
27.7694,Pod,MODIFIED,eval-sanitize-2-r4-021-vzk2p,phase=Pending node=kind-worker
27.7748,Pod,MODIFIED,eval-sanitize-2-r4-023-6hkqq,phase=Pending node=kind-worker
27.7803,Pod,MODIFIED,eval-sanitize-2-r4-024-m4dwq,phase=Pending node=None
27.7816,Event,ADDED,eval-sanitize-2-r4-024-m4dwq.18d3d1d5e49b11a8,"reason=FailedScheduling count=None msg=0/6 nodes are available: 1 c_wall violated: 2 conflicting context pair(s) with node memory, 5 node(s) had untolerated taint(s). no new claims to deallocate, preemption: 0/6 nodes are available: 1 No preemption victims found for incoming pod, 5 Preemption is not helpful for scheduling."
27.7819,Event,ADDED,eval-sanitize-2-r4-023-6hkqq.18d3d1d5e4a95029,reason=Scheduled count=None msg=Successfully assigned compute/eval-sanitize-2-r4-023-6hkqq to kind-worker
27.7852,Node,MODIFIED,kind-worker,taints=0
27.7879,Pod,MODIFIED,eval-sanitize-2-r4-023-6hkqq,phase=Pending node=kind-worker
27.7885,Event,ADDED,eval-sanitize-2-r4-025-dphm6.18d3d1d5e52c9195,"reason=FailedScheduling count=None msg=0/6 nodes are available: 1 c_wall violated: 2 conflicting context pair(s) with node memory, 5 node(s) had untolerated taint(s). no new claims to deallocate, preemption: 0/6 nodes are available: 1 No preemption victims found for incoming pod, 5 Preemption is not helpful for scheduling."
27.7894,Pod,MODIFIED,eval-sanitize-2-r4-025-dphm6,phase=Pending node=None
27.7973,Pod,MODIFIED,eval-sanitize-2-r4-026-ltj94,phase=Pending node=kind-worker
27.8066,Pod,MODIFIED,eval-sanitize-2-r4-026-ltj94,phase=Pending node=kind-worker
27.8076,Event,ADDED,eval-sanitize-2-r4-026-ltj94.18d3d1d5e64a239e,reason=Scheduled count=None msg=Successfully assigned compute/eval-sanitize-2-r4-026-ltj94 to kind-worker
27.8086,Pod,MODIFIED,eval-sanitize-2-r4-027-5cbcr,phase=Pending node=kind-worker
27.8117,Event,ADDED,eval-sanitize-2-r4-027-5cbcr.18d3d1d5e6a5a00d,reason=Scheduled count=None msg=Successfully assigned compute/eval-sanitize-2-r4-027-5cbcr to kind-worker
27.8173,Pod,MODIFIED,eval-sanitize-2-r4-027-5cbcr,phase=Pending node=kind-worker
27.8225,Pod,MODIFIED,eval-sanitize-2-r4-022-kvzd5,phase=Pending node=None
27.8243,Event,ADDED,eval-sanitize-2-r4-022-kvzd5.18d3d1d5e73adbea,"reason=FailedScheduling count=None msg=0/6 nodes are available: 1 c_wall violated: 2 conflicting context pair(s) with node memory, 5 node(s) had untolerated taint(s). no new claims to deallocate, preemption: 0/6 nodes are available: 1 No preemption victims found for incoming pod, 5 Preemption is not helpful for scheduling."
27.8286,Node,MODIFIED,kind-worker,taints=0
27.8305,Event,ADDED,eval-sanitize-2-r4-024-m4dwq.18d3d1d5e7b40e24,"reason=FailedScheduling count=None msg=0/6 nodes are available: 1 c_wall violated: 2 conflicting context pair(s) with node memory, 5 node(s) had untolerated taint(s). no new claims to deallocate, preemption: 0/6 nodes are available: 1 No preemption victims found for incoming pod, 5 Preemption is not helpful for scheduling."
27.8681,Pod,MODIFIED,eval-sanitize-2-r4-017-mnp4k,phase=Running node=kind-worker4
27.8743,Pod,MODIFIED,eval-sanitize-2-r4-013-tw8qz,phase=Running node=kind-worker4
27.9079,Event,ADDED,eval-sanitize-2-r4-025-dphm6.18d3d1d5ec4c887d,"reason=FailedScheduling count=None msg=0/6 nodes are available: 1 c_wall violated: 2 conflicting context pair(s) with node memory, 5 node(s) had untolerated taint(s). no new claims to deallocate, preemption: 0/6 nodes are available: 1 No preemption victims found for incoming pod, 5 Preemption is not helpful for scheduling."
27.9117,Node,MODIFIED,kind-worker,taints=0
27.9123,Event,ADDED,eval-sanitize-2-r4-022-kvzd5.18d3d1d5ec85d97f,"reason=FailedScheduling count=None msg=0/6 nodes are available: 1 c_wall violated: 2 conflicting context pair(s) with node memory, 5 node(s) had untolerated taint(s). no new claims to deallocate, preemption: 0/6 nodes are available: 1 No preemption victims found for incoming pod, 5 Preemption is not helpful for scheduling."
27.9158,Event,MODIFIED,eval-sanitize-2-r4-024-m4dwq.18d3d1d5e7b40e24,"reason=FailedScheduling count=None msg=0/6 nodes are available: 1 c_wall violated: 2 conflicting context pair(s) with node memory, 5 node(s) had untolerated taint(s). no new claims to deallocate, preemption: 0/6 nodes are available: 1 No preemption victims found for incoming pod, 5 Preemption is not helpful for scheduling."
27.9167,Event,MODIFIED,eval-sanitize-2-r4-025-dphm6.18d3d1d5ec4c887d,"reason=FailedScheduling count=None msg=0/6 nodes are available: 1 c_wall violated: 2 conflicting context pair(s) with node memory, 5 node(s) had untolerated taint(s). no new claims to deallocate, preemption: 0/6 nodes are available: 1 No preemption victims found for incoming pod, 5 Preemption is not helpful for scheduling."
27.9234,Node,MODIFIED,kind-worker,taints=0
27.9238,Event,MODIFIED,eval-sanitize-2-r4-022-kvzd5.18d3d1d5ec85d97f,"reason=FailedScheduling count=None msg=0/6 nodes are available: 1 c_wall violated: 2 conflicting context pair(s) with node memory, 5 node(s) had untolerated taint(s). no new claims to deallocate, preemption: 0/6 nodes are available: 1 No preemption victims found for incoming pod, 5 Preemption is not helpful for scheduling."
28.005,Job,MODIFIED,eval-sanitize-2-r4-012,
28.0078,Job,MODIFIED,eval-sanitize-2-r4-008,
28.0079,TaskRequest,ADDED,eval-sanitize-2-r4-028,phase=None job=None
28.0141,Pod,MODIFIED,eval-sanitize-2-r4-012-s6sg6,phase=Succeeded node=kind-worker
28.0142,TaskRequest,MODIFIED,eval-sanitize-2-r4-028,phase=Pending job=None
28.0158,Job,MODIFIED,eval-sanitize-2-r4-012,
28.0186,Pod,MODIFIED,eval-sanitize-2-r4-008-f4zj6,phase=Succeeded node=kind-worker
28.02,Job,MODIFIED,eval-sanitize-2-r4-008,
28.0277,Job,ADDED,eval-sanitize-2-r4-028,
28.031,TaskRequest,MODIFIED,eval-sanitize-2-r4-028,phase=Scheduled job=None
28.0338,Pod,ADDED,eval-sanitize-2-r4-028-fth75,phase=Pending node=None
28.0361,Job,MODIFIED,eval-sanitize-2-r4-028,
28.039,Event,ADDED,eval-sanitize-2-r4-028.18d3d1d5f41b3aa8,reason=SuccessfulCreate count=1 msg=Created pod: eval-sanitize-2-r4-028-fth75
28.0391,TaskRequest,MODIFIED,eval-sanitize-2-r4-028,phase=Scheduled job=None
28.0427,Pod,MODIFIED,eval-sanitize-2-r4-028-fth75,phase=Pending node=kind-worker
28.0441,Job,MODIFIED,eval-sanitize-2-r4-027,
28.0455,Event,ADDED,eval-sanitize-2-r4-028-fth75.18d3d1d5f4945199,reason=Scheduled count=None msg=Successfully assigned compute/eval-sanitize-2-r4-028-fth75 to kind-worker
28.0567,Pod,MODIFIED,eval-sanitize-2-r4-028-fth75,phase=Pending node=kind-worker
28.0575,Job,MODIFIED,eval-sanitize-2-r4-027,
28.1897,Event,ADDED,eval-sanitize-2-r4-021-vzk2p.18d3d1d5fd1ef9cf,"reason=Pulled count=1 msg=Container image ""busybox:musl"" already present on machine"
28.2043,Event,ADDED,eval-sanitize-2-r4-023-6hkqq.18d3d1d5fdfef94d,"reason=Pulled count=1 msg=Container image ""busybox:musl"" already present on machine"
28.2185,Event,ADDED,eval-sanitize-2-r4-021-vzk2p.18d3d1d5fedd1abc,reason=Created count=1 msg=Created container: task
28.2281,Event,ADDED,eval-sanitize-2-r4-023-6hkqq.18d3d1d5ff63accd,reason=Created count=1 msg=Created container: task
28.2641,Job,MODIFIED,eval-sanitize-2-r4-009,
28.2663,Job,MODIFIED,eval-sanitize-2-r4-015,
28.2696,Job,MODIFIED,eval-sanitize-2-r4-014,
28.2728,Job,MODIFIED,eval-sanitize-2-r4-016,
28.2749,Job,MODIFIED,eval-sanitize-2-r4-009,
28.2765,Pod,MODIFIED,eval-sanitize-2-r4-015-45f4d,phase=Succeeded node=kind-worker2
28.2775,Job,MODIFIED,eval-sanitize-2-r4-007,
28.2792,Job,MODIFIED,eval-sanitize-2-r4-014,
28.2812,Event,ADDED,eval-sanitize-2-r4-009.18d3d1d60258ed2a,reason=Completed count=1 msg=Job completed
28.2829,Job,MODIFIED,eval-sanitize-2-r4-015,
28.2842,Job,MODIFIED,eval-sanitize-2-r4-007,
28.2852,Job,MODIFIED,eval-sanitize-2-r4-010,
28.2882,Job,MODIFIED,eval-sanitize-2-r4-011,
28.2886,Event,ADDED,eval-sanitize-2-r4-014.18d3d1d602a98f33,reason=Completed count=1 msg=Job completed
28.2897,Job,MODIFIED,eval-sanitize-2-r4-009,
28.2908,Job,MODIFIED,eval-sanitize-2-r4-010,
28.2925,Job,MODIFIED,eval-sanitize-2-r4-011,
28.2943,Job,MODIFIED,eval-sanitize-2-r4-014,
28.2955,Event,ADDED,eval-sanitize-2-r4-007.18d3d1d602eb888c,reason=Completed count=1 msg=Job completed
28.2962,Job,MODIFIED,eval-sanitize-2-r4-016,
28.2973,Job,MODIFIED,eval-sanitize-2-r4-007,
28.2995,Event,ADDED,eval-sanitize-2-r4-010.18d3d1d603520c81,reason=Completed count=1 msg=Job completed
28.3025,Job,MODIFIED,eval-sanitize-2-r4-010,
28.3028,Event,ADDED,eval-sanitize-2-r4-011.18d3d1d60382bbee,reason=Completed count=1 msg=Job completed
28.3293,TaskRequest,MODIFIED,eval-sanitize-2-r4-009,phase=Complete job=None
28.3349,Job,MODIFIED,eval-sanitize-2-r4-011,
28.3393,Job,MODIFIED,eval-sanitize-2-r4-009,
28.3703,Event,ADDED,eval-sanitize-2-r4-026-ltj94.18d3d1d607d29604,"reason=Pulled count=1 msg=Container image ""busybox:musl"" already present on machine"
28.3774,Event,ADDED,eval-sanitize-2-r4-027-5cbcr.18d3d1d607f9b31a,"reason=Pulled count=1 msg=Container image ""busybox:musl"" already present on machine"
28.3787,TaskRequest,MODIFIED,eval-sanitize-2-r4-014,phase=Complete job=None
28.3819,Event,ADDED,eval-sanitize-2-r4-021-vzk2p.18d3d1d60877c386,reason=Started count=1 msg=Started container task
28.3863,TaskRequest,MODIFIED,eval-sanitize-2-r4-007,phase=Complete job=None
28.3878,Event,ADDED,eval-sanitize-2-r4-023-6hkqq.18d3d1d60879f95b,reason=Started count=1 msg=Started container task
28.3921,Job,MODIFIED,eval-sanitize-2-r4-014,
28.3923,TaskRequest,MODIFIED,eval-sanitize-2-r4-010,phase=Complete job=None
28.4078,Pod,MODIFIED,eval-sanitize-2-r4-016-cjlgc,phase=Succeeded node=kind-worker2
28.4081,Event,ADDED,eval-sanitize-2-r4-026-ltj94.18d3d1d60a05887e,reason=Created count=1 msg=Created container: task
28.4132,Event,ADDED,eval-sanitize-2-r4-027-5cbcr.18d3d1d60a460fe6,reason=Created count=1 msg=Created container: task
28.4235,TaskRequest,MODIFIED,eval-sanitize-2-r4-011,phase=Complete job=None
28.4306,Job,MODIFIED,eval-sanitize-2-r4-007,
28.433,Job,MODIFIED,eval-sanitize-2-r4-010,
28.434,Job,MODIFIED,eval-sanitize-2-r4-011,
28.4807,Event,ADDED,eval-sanitize-2-r4-027-5cbcr.18d3d1d60e756ac5,reason=Started count=1 msg=Started container task
28.485,Event,ADDED,eval-sanitize-2-r4-026-ltj94.18d3d1d60e75aee9,reason=Started count=1 msg=Started container task
28.4895,Event,ADDED,eval-sanitize-2-r4-028-fth75.18d3d1d60f0d084f,"reason=Pulled count=1 msg=Container image ""busybox:musl"" already present on machine"
28.5085,Event,ADDED,eval-sanitize-2-r4-028-fth75.18d3d1d6101b1bf1,reason=Created count=1 msg=Created container: task
28.5862,Event,ADDED,eval-sanitize-2-r4-028-fth75.18d3d1d614c62375,reason=Started count=1 msg=Started container task
28.8566,Pod,MODIFIED,eval-sanitize-2-r4-018-f6rrd,phase=Running node=kind-worker5
28.874,Job,MODIFIED,eval-sanitize-2-r4-017,
28.8831,Job,MODIFIED,eval-sanitize-2-r4-013,
28.8841,Job,MODIFIED,eval-sanitize-2-r4-017,
28.8949,Job,MODIFIED,eval-sanitize-2-r4-013,
28.9633,Node,MODIFIED,kind-worker2,taints=1
28.9715,Pod,MODIFIED,eval-sanitize-2-r4-013-tw8qz,phase=Succeeded node=kind-worker4
28.9764,Node,MODIFIED,kind-worker2,taints=0
28.9862,Pod,MODIFIED,eval-sanitize-2-r4-024-m4dwq,phase=Pending node=kind-worker2
28.9874,Node,MODIFIED,kind-worker2,taints=0
28.99,Event,ADDED,eval-sanitize-2-r4-024-m4dwq.18d3d1d62cd945ad,reason=Scheduled count=None msg=Successfully assigned compute/eval-sanitize-2-r4-024-m4dwq to kind-worker2
28.9992,Node,MODIFIED,kind-worker2,taints=0
29.0006,Pod,MODIFIED,eval-sanitize-2-r4-024-m4dwq,phase=Pending node=kind-worker2
29.0038,Pod,MODIFIED,eval-sanitize-2-r4-023-6hkqq,phase=Running node=kind-worker
29.0059,Pod,MODIFIED,eval-sanitize-2-r4-017-mnp4k,phase=Succeeded node=kind-worker4
29.0119,Pod,MODIFIED,eval-sanitize-2-r4-028-fth75,phase=Running node=kind-worker
29.0136,Job,MODIFIED,eval-sanitize-2-r4-012,
29.0148,Job,MODIFIED,eval-sanitize-2-r4-008,
29.0206,Pod,MODIFIED,eval-sanitize-2-r4-026-ltj94,phase=Running node=kind-worker
29.0219,Job,MODIFIED,eval-sanitize-2-r4-012,
29.0228,Pod,MODIFIED,eval-sanitize-2-r4-025-dphm6,phase=Pending node=kind-worker2
29.0239,Job,MODIFIED,eval-sanitize-2-r4-008,
29.029,Event,ADDED,eval-sanitize-2-r4-008.18d3d1d62ef6d6ea,reason=Completed count=1 msg=Job completed
29.0293,Event,ADDED,eval-sanitize-2-r4-025-dphm6.18d3d1d62eee2ea6,reason=Scheduled count=None msg=Successfully assigned compute/eval-sanitize-2-r4-025-dphm6 to kind-worker2
29.031,Pod,MODIFIED,eval-sanitize-2-r4-021-vzk2p,phase=Running node=kind-worker
29.0326,Node,MODIFIED,kind-worker2,taints=0
29.0336,TaskRequest,ADDED,eval-sanitize-2-r4-029,phase=None job=None
29.0353,Pod,MODIFIED,eval-sanitize-2-r4-025-dphm6,phase=Pending node=kind-worker2
29.0356,Event,ADDED,eval-sanitize-2-r4-012.18d3d1d62efa931b,reason=Completed count=1 msg=Job completed
29.0363,Pod,MODIFIED,eval-sanitize-2-r4-022-kvzd5,phase=Pending node=None
29.0376,Job,MODIFIED,eval-sanitize-2-r4-012,
29.039,Pod,MODIFIED,eval-sanitize-2-r4-027-5cbcr,phase=Running node=kind-worker
29.0399,Job,MODIFIED,eval-sanitize-2-r4-008,
29.04,TaskRequest,MODIFIED,eval-sanitize-2-r4-029,phase=Pending job=None
29.0407,Job,MODIFIED,eval-sanitize-2-r4-028,
29.0488,Job,MODIFIED,eval-sanitize-2-r4-027,
29.0544,Node,MODIFIED,kind-worker2,taints=0
29.0619,Job,ADDED,eval-sanitize-2-r4-029,
29.0649,Node,MODIFIED,kind-worker2,taints=0
29.0671,Pod,ADDED,eval-sanitize-2-r4-029-55cpp,phase=Pending node=None
29.0685,TaskRequest,MODIFIED,eval-sanitize-2-r4-029,phase=Scheduled job=None
29.0713,Job,MODIFIED,eval-sanitize-2-r4-029,
29.0716,Event,ADDED,eval-sanitize-2-r4-029.18d3d1d631afe88f,reason=SuccessfulCreate count=1 msg=Created pod: eval-sanitize-2-r4-029-55cpp
29.076,TaskRequest,MODIFIED,eval-sanitize-2-r4-029,phase=Scheduled job=None
29.0779,TaskRequest,MODIFIED,eval-sanitize-2-r4-012,phase=Complete job=None
29.081,TaskRequest,MODIFIED,eval-sanitize-2-r4-008,phase=Complete job=None
29.1303,Pod,MODIFIED,eval-sanitize-2-r4-029-55cpp,phase=Pending node=kind-worker
29.132,Job,MODIFIED,eval-sanitize-2-r4-028,
29.1328,Job,MODIFIED,eval-sanitize-2-r4-008,
29.1337,Job,MODIFIED,eval-sanitize-2-r4-012,
29.134,Event,ADDED,eval-sanitize-2-r4-029-55cpp.18d3d1d63570b265,reason=Scheduled count=None msg=Successfully assigned compute/eval-sanitize-2-r4-029-55cpp to kind-worker
29.1347,Job,MODIFIED,eval-sanitize-2-r4-027,
29.1395,Pod,MODIFIED,eval-sanitize-2-r4-029-55cpp,phase=Pending node=kind-worker
29.1909,Event,ADDED,eval-sanitize-2-r4-022-kvzd5.18d3d1d6388cd956,"reason=FailedScheduling count=None msg=0/6 nodes are available: 1 c_wall violated: 1 conflicting context pair(s) with node memory, 1 c_wall violated: 2 conflicting context pair(s) with node memory, 4 node(s) had untolerated taint(s). no new claims to deallocate, preemption: 0/6 nodes are available: 2 No preemption victims found for incoming pod, 4 Preemption is not helpful for scheduling."
29.2208,Event,MODIFIED,eval-sanitize-2-r4-022-kvzd5.18d3d1d6388cd956,"reason=FailedScheduling count=None msg=0/6 nodes are available: 1 c_wall violated: 1 conflicting context pair(s) with node memory, 1 c_wall violated: 2 conflicting context pair(s) with node memory, 4 node(s) had untolerated taint(s). no new claims to deallocate, preemption: 0/6 nodes are available: 2 No preemption victims found for incoming pod, 4 Preemption is not helpful for scheduling."
29.2721,Job,MODIFIED,eval-sanitize-2-r4-015,
29.2767,Job,MODIFIED,eval-sanitize-2-r4-015,
29.2799,Job,MODIFIED,eval-sanitize-2-r4-016,
29.2847,Event,ADDED,eval-sanitize-2-r4-015.18d3d1d63e2d54b2,reason=Completed count=1 msg=Job completed
29.2909,Pod,MODIFIED,eval-sanitize-2-r4-016-cjlgc,phase=Succeeded node=kind-worker2
29.2955,Job,MODIFIED,eval-sanitize-2-r4-016,
29.2964,Job,MODIFIED,eval-sanitize-2-r4-015,
29.3011,TaskRequest,MODIFIED,eval-sanitize-2-r4-015,phase=Complete job=None
29.3105,Job,MODIFIED,eval-sanitize-2-r4-015,
29.4056,Event,ADDED,eval-sanitize-2-r4-024-m4dwq.18d3d1d6459c1bf1,"reason=Pulled count=1 msg=Container image ""busybox:musl"" already present on machine"
29.4238,Event,ADDED,eval-sanitize-2-r4-024-m4dwq.18d3d1d646b50d92,reason=Created count=1 msg=Created container: task
29.4383,Event,ADDED,eval-sanitize-2-r4-025-dphm6.18d3d1d64788178c,"reason=Pulled count=1 msg=Container image ""busybox:musl"" already present on machine"
29.4587,Event,ADDED,eval-sanitize-2-r4-024-m4dwq.18d3d1d648b2aeed,reason=Started count=1 msg=Started container task
29.463,Event,ADDED,eval-sanitize-2-r4-025-dphm6.18d3d1d648c582a4,reason=Created count=1 msg=Created container: task
29.489,Event,ADDED,eval-sanitize-2-r4-025-dphm6.18d3d1d64aa20063,reason=Started count=1 msg=Started container task
29.5212,Event,ADDED,eval-sanitize-2-r4-029-55cpp.18d3d1d64c832524,"reason=Pulled count=1 msg=Container image ""busybox:musl"" already present on machine"
29.5402,Event,ADDED,eval-sanitize-2-r4-029-55cpp.18d3d1d64d9b851b,reason=Created count=1 msg=Created container: task
29.5992,Event,ADDED,eval-sanitize-2-r4-029-55cpp.18d3d1d6512c045d,reason=Started count=1 msg=Started container task
29.6323,Node,MODIFIED,kind-worker4,taints=1
29.6473,Node,MODIFIED,kind-worker4,taints=0
29.6554,Node,MODIFIED,kind-worker4,taints=0
29.6569,Pod,MODIFIED,eval-sanitize-2-r4-022-kvzd5,phase=Pending node=kind-worker4
29.6598,Event,ADDED,eval-sanitize-2-r4-022-kvzd5.18d3d1d654d4bf4a,reason=Scheduled count=None msg=Successfully assigned compute/eval-sanitize-2-r4-022-kvzd5 to kind-worker4
29.6659,Pod,MODIFIED,eval-sanitize-2-r4-022-kvzd5,phase=Pending node=kind-worker4
29.6682,Node,MODIFIED,kind-worker4,taints=0
29.7449,Node,MODIFIED,kind-worker4,taints=0
29.8284,Node,MODIFIED,kind-worker4,taints=0
29.8333,Node,MODIFIED,kind-worker,taints=1
29.8449,Node,MODIFIED,kind-worker,taints=1
29.8604,Job,MODIFIED,eval-sanitize-2-r4-018,
29.8712,Job,MODIFIED,eval-sanitize-2-r4-018,
29.8794,Job,MODIFIED,eval-sanitize-2-r4-017,
29.8874,Job,MODIFIED,eval-sanitize-2-r4-013,
29.8888,Pod,MODIFIED,eval-sanitize-2-r4-017-mnp4k,phase=Succeeded node=kind-worker4
29.8903,Job,MODIFIED,eval-sanitize-2-r4-017,
29.8958,Pod,MODIFIED,eval-sanitize-2-r4-013-tw8qz,phase=Succeeded node=kind-worker4
29.898,Job,MODIFIED,eval-sanitize-2-r4-013,
29.9608,Pod,MODIFIED,eval-sanitize-2-r4-018-f6rrd,phase=Succeeded node=kind-worker5
30.0091,TaskRequest,ADDED,eval-sanitize-2-r4-030,phase=None job=None
30.0127,Pod,MODIFIED,eval-sanitize-2-r4-029-55cpp,phase=Running node=kind-worker
30.0138,Job,MODIFIED,eval-sanitize-2-r4-023,
30.0155,TaskRequest,MODIFIED,eval-sanitize-2-r4-030,phase=Pending job=None
30.0238,Job,MODIFIED,eval-sanitize-2-r4-026,
30.032,Job,ADDED,eval-sanitize-2-r4-030,
30.0353,Job,MODIFIED,eval-sanitize-2-r4-021,
30.0364,TaskRequest,MODIFIED,eval-sanitize-2-r4-030,phase=Scheduled job=None
30.0402,Pod,ADDED,eval-sanitize-2-r4-030-m9bv7,phase=Pending node=None
30.0417,Job,MODIFIED,eval-sanitize-2-r4-030,
30.0445,Event,ADDED,eval-sanitize-2-r4-030.18d3d1d66ba47e82,reason=SuccessfulCreate count=1 msg=Created pod: eval-sanitize-2-r4-030-m9bv7
30.0513,TaskRequest,MODIFIED,eval-sanitize-2-r4-030,phase=Scheduled job=None
30.0523,Job,MODIFIED,eval-sanitize-2-r4-023,
30.0617,Job,MODIFIED,eval-sanitize-2-r4-026,
30.0633,Job,MODIFIED,eval-sanitize-2-r4-021,
30.0642,Pod,MODIFIED,eval-sanitize-2-r4-030-m9bv7,phase=Pending node=kind-worker2
30.0678,Event,ADDED,eval-sanitize-2-r4-030-m9bv7.18d3d1d66d1820cc,reason=Scheduled count=None msg=Successfully assigned compute/eval-sanitize-2-r4-030-m9bv7 to kind-worker2
30.0693,Event,ADDED,eval-sanitize-2-r4-022-kvzd5.18d3d1d66d38dd26,"reason=Pulled count=1 msg=Container image ""busybox:musl"" already present on machine"
30.0735,Job,MODIFIED,eval-sanitize-2-r4-029,
30.0778,Pod,MODIFIED,eval-sanitize-2-r4-030-m9bv7,phase=Pending node=kind-worker2
30.0794,Node,MODIFIED,kind-worker2,taints=0
30.0961,Job,MODIFIED,eval-sanitize-2-r4-029,
30.1,Node,MODIFIED,kind-worker2,taints=0
30.1044,Event,ADDED,eval-sanitize-2-r4-022-kvzd5.18d3d1d66f0e5981,reason=Created count=1 msg=Created container: task
30.1758,Event,ADDED,eval-sanitize-2-r4-022-kvzd5.18d3d1d67377c669,reason=Started count=1 msg=Started container task
30.2655,Pod,MODIFIED,eval-sanitize-2-r4-025-dphm6,phase=Running node=kind-worker2
30.2713,Pod,MODIFIED,eval-sanitize-2-r4-024-m4dwq,phase=Running node=kind-worker2
30.2856,Job,MODIFIED,eval-sanitize-2-r4-016,
30.2906,Job,MODIFIED,eval-sanitize-2-r4-016,
30.2945,Event,ADDED,eval-sanitize-2-r4-016.18d3d1d67a8e3978,reason=Completed count=1 msg=Job completed
30.3005,Job,MODIFIED,eval-sanitize-2-r4-016,
30.3058,TaskRequest,MODIFIED,eval-sanitize-2-r4-016,phase=Complete job=None
30.314,Job,MODIFIED,eval-sanitize-2-r4-016,
30.4953,Event,ADDED,eval-sanitize-2-r4-030-m9bv7.18d3d1d6866c4b63,"reason=Pulled count=1 msg=Container image ""busybox:musl"" already present on machine"
30.5108,Event,ADDED,eval-sanitize-2-r4-030-m9bv7.18d3d1d6877bb634,reason=Created count=1 msg=Created container: task
30.5771,Node,MODIFIED,kind-worker5,taints=1
30.601,Event,ADDED,eval-sanitize-2-r4-030-m9bv7.18d3d1d68cd1db40,reason=Started count=1 msg=Started container task
30.655,Node,MODIFIED,kind-worker5,taints=1
30.6626,Node,MODIFIED,kind-worker5,taints=0
30.6742,Node,MODIFIED,kind-worker5,taints=0
30.8177,Pod,MODIFIED,eval-sanitize-2-r4-019-5xr88,phase=Running node=kind-worker3
30.824,Pod,MODIFIED,eval-sanitize-2-r4-020-qv5qd,phase=Running node=kind-worker3
30.8709,Job,MODIFIED,eval-sanitize-2-r4-018,
30.8788,Pod,MODIFIED,eval-sanitize-2-r4-018-f6rrd,phase=Succeeded node=kind-worker5
30.8814,Job,MODIFIED,eval-sanitize-2-r4-018,
30.8827,Pod,MODIFIED,eval-sanitize-2-r4-022-kvzd5,phase=Running node=kind-worker4
30.8852,Job,MODIFIED,eval-sanitize-2-r4-017,
30.8894,Job,MODIFIED,eval-sanitize-2-r4-017,
30.892,Job,MODIFIED,eval-sanitize-2-r4-013,
30.8933,Event,ADDED,eval-sanitize-2-r4-017.18d3d1d69e3fbd76,reason=Completed count=1 msg=Job completed
30.8961,Job,MODIFIED,eval-sanitize-2-r4-013,
30.8997,Job,MODIFIED,eval-sanitize-2-r4-017,
30.9008,Event,ADDED,eval-sanitize-2-r4-013.18d3d1d69ea5405b,reason=Completed count=1 msg=Job completed
30.9041,TaskRequest,MODIFIED,eval-sanitize-2-r4-017,phase=Complete job=None
30.9076,Job,MODIFIED,eval-sanitize-2-r4-013,
30.9129,Job,MODIFIED,eval-sanitize-2-r4-017,
30.914,TaskRequest,MODIFIED,eval-sanitize-2-r4-013,phase=Complete job=None
30.922,Job,MODIFIED,eval-sanitize-2-r4-013,
31.0138,TaskRequest,ADDED,eval-sanitize-2-r4-031,phase=None job=None
31.0175,TaskRequest,MODIFIED,eval-sanitize-2-r4-031,phase=Pending job=None
31.0335,Job,ADDED,eval-sanitize-2-r4-031,
31.0384,TaskRequest,MODIFIED,eval-sanitize-2-r4-031,phase=Scheduled job=None
31.0408,Job,MODIFIED,eval-sanitize-2-r4-031,
31.0432,Pod,ADDED,eval-sanitize-2-r4-031-88cfn,phase=Pending node=None
31.0451,Job,MODIFIED,eval-sanitize-2-r4-030,
31.0468,TaskRequest,MODIFIED,eval-sanitize-2-r4-031,phase=Scheduled job=None
31.0476,Event,ADDED,eval-sanitize-2-r4-031.18d3d1d6a769177e,reason=SuccessfulCreate count=1 msg=Created pod: eval-sanitize-2-r4-031-88cfn
31.0541,Job,MODIFIED,eval-sanitize-2-r4-030,
31.0576,Pod,MODIFIED,eval-sanitize-2-r4-031-88cfn,phase=Pending node=kind-worker4
31.0643,Node,MODIFIED,kind-worker2,taints=1
31.0646,Event,ADDED,eval-sanitize-2-r4-031-88cfn.18d3d1d6a83c79fd,reason=Scheduled count=None msg=Successfully assigned compute/eval-sanitize-2-r4-031-88cfn to kind-worker4
31.0679,Node,MODIFIED,kind-worker4,taints=0
31.0702,Pod,MODIFIED,eval-sanitize-2-r4-031-88cfn,phase=Pending node=kind-worker4
31.0805,Node,MODIFIED,kind-worker2,taints=1
31.2555,Node,MODIFIED,kind-worker4,taints=0
31.2713,Pod,MODIFIED,eval-sanitize-2-r4-030-m9bv7,phase=Running node=kind-worker2
31.2723,Job,MODIFIED,eval-sanitize-2-r4-025,
31.2745,Job,MODIFIED,eval-sanitize-2-r4-024,
31.2837,Job,MODIFIED,eval-sanitize-2-r4-025,
31.2857,Job,MODIFIED,eval-sanitize-2-r4-024,
31.4825,Event,ADDED,eval-sanitize-2-r4-031-88cfn.18d3d1d6c147087b,"reason=Pulled count=1 msg=Container image ""busybox:musl"" already present on machine"
31.4997,Event,ADDED,eval-sanitize-2-r4-031-88cfn.18d3d1d6c265b40d,reason=Created count=1 msg=Created container: task
31.5641,Event,ADDED,eval-sanitize-2-r4-031-88cfn.18d3d1d6c635d124,reason=Started count=1 msg=Started container task
31.755,Node,MODIFIED,kind-worker4,taints=1
31.7712,Node,MODIFIED,kind-worker4,taints=1
31.8243,Job,MODIFIED,eval-sanitize-2-r4-019,
31.829,Job,MODIFIED,eval-sanitize-2-r4-020,
31.8339,Job,MODIFIED,eval-sanitize-2-r4-019,
31.8385,Job,MODIFIED,eval-sanitize-2-r4-020,
31.8777,Job,MODIFIED,eval-sanitize-2-r4-018,
31.8818,Job,MODIFIED,eval-sanitize-2-r4-018,
31.8844,Pod,MODIFIED,eval-sanitize-2-r4-031-88cfn,phase=Running node=kind-worker4
31.8857,Job,MODIFIED,eval-sanitize-2-r4-022,
31.8884,Event,ADDED,eval-sanitize-2-r4-018.18d3d1d6d9673c9f,reason=Completed count=1 msg=Job completed
31.8939,Job,MODIFIED,eval-sanitize-2-r4-022,
31.8959,Job,MODIFIED,eval-sanitize-2-r4-018,
31.9012,TaskRequest,MODIFIED,eval-sanitize-2-r4-018,phase=Complete job=None
31.9093,Job,MODIFIED,eval-sanitize-2-r4-018,
31.9436,Pod,MODIFIED,eval-sanitize-2-r4-019-5xr88,phase=Succeeded node=kind-worker3
31.9493,Pod,MODIFIED,eval-sanitize-2-r4-020-qv5qd,phase=Succeeded node=kind-worker3
32.0067,TaskRequest,ADDED,eval-sanitize-2-r4-032,phase=None job=None
32.0102,TaskRequest,MODIFIED,eval-sanitize-2-r4-032,phase=Pending job=None
32.0248,Job,ADDED,eval-sanitize-2-r4-032,
32.0299,TaskRequest,MODIFIED,eval-sanitize-2-r4-032,phase=Scheduled job=None
32.0315,Pod,ADDED,eval-sanitize-2-r4-032-jnkcf,phase=Pending node=None
32.034,Job,MODIFIED,eval-sanitize-2-r4-032,
32.0369,Event,ADDED,eval-sanitize-2-r4-032.18d3d1d6e254f278,reason=SuccessfulCreate count=1 msg=Created pod: eval-sanitize-2-r4-032-jnkcf
32.0378,Pod,MODIFIED,eval-sanitize-2-r4-032-jnkcf,phase=Pending node=kind-worker5
32.0384,TaskRequest,MODIFIED,eval-sanitize-2-r4-032,phase=Scheduled job=None
32.0406,Event,ADDED,eval-sanitize-2-r4-032-jnkcf.18d3d1d6e2a9b41d,reason=Scheduled count=None msg=Successfully assigned compute/eval-sanitize-2-r4-032-jnkcf to kind-worker5
32.0456,Job,MODIFIED,eval-sanitize-2-r4-031,
32.0484,Pod,MODIFIED,eval-sanitize-2-r4-032-jnkcf,phase=Pending node=kind-worker5
32.0502,Node,MODIFIED,kind-worker5,taints=0
32.0513,Job,MODIFIED,eval-sanitize-2-r4-030,
32.0543,Job,MODIFIED,eval-sanitize-2-r4-031,
32.0584,Job,MODIFIED,eval-sanitize-2-r4-030,
32.1671,Node,MODIFIED,kind-worker5,taints=0
32.4723,Event,ADDED,eval-sanitize-2-r4-032-jnkcf.18d3d1d6fc58839c,"reason=Pulled count=1 msg=Container image ""busybox:musl"" already present on machine"
32.4917,Event,ADDED,eval-sanitize-2-r4-032-jnkcf.18d3d1d6fd669aae,reason=Created count=1 msg=Created container: task
32.5526,Event,ADDED,eval-sanitize-2-r4-032-jnkcf.18d3d1d701251d42,reason=Started count=1 msg=Started container task
32.6846,Node,MODIFIED,kind-worker5,taints=1
32.7047,Node,MODIFIED,kind-worker5,taints=1
32.8372,Job,MODIFIED,eval-sanitize-2-r4-019,
32.8387,Job,MODIFIED,eval-sanitize-2-r4-020,
32.8479,Pod,MODIFIED,eval-sanitize-2-r4-019-5xr88,phase=Succeeded node=kind-worker3
32.8508,Job,MODIFIED,eval-sanitize-2-r4-019,
32.8525,Pod,MODIFIED,eval-sanitize-2-r4-020-qv5qd,phase=Succeeded node=kind-worker3
32.8533,Job,MODIFIED,eval-sanitize-2-r4-020,
32.8618,Pod,MODIFIED,eval-sanitize-2-r4-032-jnkcf,phase=Running node=kind-worker5
33.0206,TaskRequest,ADDED,eval-sanitize-2-r4-033,phase=None job=None
33.0242,TaskRequest,MODIFIED,eval-sanitize-2-r4-033,phase=Pending job=None
33.0369,Job,MODIFIED,eval-sanitize-2-r4-032,
33.0388,Job,ADDED,eval-sanitize-2-r4-033,
33.0448,Pod,ADDED,eval-sanitize-2-r4-033-p9qml,phase=Pending node=None
33.0451,TaskRequest,MODIFIED,eval-sanitize-2-r4-033,phase=Scheduled job=None
33.0491,Job,MODIFIED,eval-sanitize-2-r4-033,
33.0513,Event,ADDED,eval-sanitize-2-r4-033.18d3d1d71ebc6d6c,reason=SuccessfulCreate count=1 msg=Created pod: eval-sanitize-2-r4-033-p9qml
33.0516,Event,ADDED,eval-sanitize-2-r4-033-p9qml.18d3d1d71ec58d81,"reason=FailedScheduling count=None msg=0/6 nodes are available: 6 node(s) had untolerated taint(s). no new claims to deallocate, preemption: 0/6 nodes are available: 6 Preemption is not helpful for scheduling."
33.0526,Pod,MODIFIED,eval-sanitize-2-r4-033-p9qml,phase=Pending node=None
33.0531,TaskRequest,MODIFIED,eval-sanitize-2-r4-033,phase=Scheduled job=None
33.0555,Job,MODIFIED,eval-sanitize-2-r4-032,
33.8463,Job,MODIFIED,eval-sanitize-2-r4-019,
33.8486,Job,MODIFIED,eval-sanitize-2-r4-020,
33.8519,Job,MODIFIED,eval-sanitize-2-r4-019,
33.8541,Job,MODIFIED,eval-sanitize-2-r4-020,
33.8576,Event,ADDED,eval-sanitize-2-r4-019.18d3d1d74ed07ef6,reason=Completed count=1 msg=Job completed
33.8639,Job,MODIFIED,eval-sanitize-2-r4-019,
33.8643,Event,ADDED,eval-sanitize-2-r4-020.18d3d1d74ef661a5,reason=Completed count=1 msg=Job completed
33.8675,Job,MODIFIED,eval-sanitize-2-r4-020,
33.8682,TaskRequest,MODIFIED,eval-sanitize-2-r4-019,phase=Complete job=None
33.8739,TaskRequest,MODIFIED,eval-sanitize-2-r4-020,phase=Complete job=None
33.8788,Job,MODIFIED,eval-sanitize-2-r4-019,
33.8828,Job,MODIFIED,eval-sanitize-2-r4-020,
33.9558,Node,MODIFIED,kind-worker3,taints=1
33.9738,Node,MODIFIED,kind-worker3,taints=0
33.9861,Pod,MODIFIED,eval-sanitize-2-r4-033-p9qml,phase=Pending node=kind-worker3
33.9921,Node,MODIFIED,kind-worker3,taints=0
33.9924,Event,ADDED,eval-sanitize-2-r4-033-p9qml.18d3d1d756cf7e46,reason=Scheduled count=None msg=Successfully assigned compute/eval-sanitize-2-r4-033-p9qml to kind-worker3
33.9973,Pod,MODIFIED,eval-sanitize-2-r4-033-p9qml,phase=Pending node=kind-worker3
34.0116,TaskRequest,ADDED,eval-sanitize-2-r4-034,phase=None job=None
34.0157,TaskRequest,MODIFIED,eval-sanitize-2-r4-034,phase=Pending job=None
34.0202,Node,MODIFIED,kind-worker3,taints=0
34.0306,Job,ADDED,eval-sanitize-2-r4-034,
34.0367,Pod,ADDED,eval-sanitize-2-r4-034-bjrp7,phase=Pending node=None
34.0368,TaskRequest,MODIFIED,eval-sanitize-2-r4-034,phase=Scheduled job=None
34.0404,Job,MODIFIED,eval-sanitize-2-r4-034,
34.0423,Event,ADDED,eval-sanitize-2-r4-034.18d3d1d759d8db06,reason=SuccessfulCreate count=1 msg=Created pod: eval-sanitize-2-r4-034-bjrp7
34.0482,Pod,MODIFIED,eval-sanitize-2-r4-034-bjrp7,phase=Pending node=None
34.0491,Event,ADDED,eval-sanitize-2-r4-034-bjrp7.18d3d1d75a169f4d,"reason=FailedScheduling count=None msg=0/6 nodes are available: 1 c_wall violated: 1 conflicting context pair(s) with node memory, 5 node(s) had untolerated taint(s). no new claims to deallocate, preemption: 0/6 nodes are available: 1 No preemption victims found for incoming pod, 5 Preemption is not helpful for scheduling."
34.0492,TaskRequest,MODIFIED,eval-sanitize-2-r4-034,phase=Scheduled job=None
34.0501,Job,MODIFIED,eval-sanitize-2-r4-033,
34.0563,Event,ADDED,eval-sanitize-2-r4-034-bjrp7.18d3d1d75abc9dce,"reason=FailedScheduling count=None msg=0/6 nodes are available: 1 c_wall violated: 1 conflicting context pair(s) with node memory, 5 node(s) had untolerated taint(s). no new claims to deallocate, preemption: 0/6 nodes are available: 1 No preemption victims found for incoming pod, 5 Preemption is not helpful for scheduling."
34.0591,Job,MODIFIED,eval-sanitize-2-r4-033,
34.1621,Node,MODIFIED,kind-worker3,taints=0
34.1701,Event,MODIFIED,eval-sanitize-2-r4-034-bjrp7.18d3d1d75abc9dce,"reason=FailedScheduling count=None msg=0/6 nodes are available: 1 c_wall violated: 1 conflicting context pair(s) with node memory, 5 node(s) had untolerated taint(s). no new claims to deallocate, preemption: 0/6 nodes are available: 1 No preemption victims found for incoming pod, 5 Preemption is not helpful for scheduling."
34.2626,Node,MODIFIED,kind-worker3,taints=0
34.4093,Event,ADDED,eval-sanitize-2-r4-033-p9qml.18d3d1d76fcc485c,"reason=Pulled count=1 msg=Container image ""busybox:musl"" already present on machine"
34.426,Event,ADDED,eval-sanitize-2-r4-033-p9qml.18d3d1d770cc7fb5,reason=Created count=1 msg=Created container: task
34.4617,Event,ADDED,eval-sanitize-2-r4-033-p9qml.18d3d1d772d5c5c4,reason=Started count=1 msg=Started container task
34.8264,Pod,MODIFIED,eval-sanitize-2-r4-033-p9qml,phase=Running node=kind-worker3
35.0147,TaskRequest,ADDED,eval-sanitize-2-r4-035,phase=None job=None
35.0183,TaskRequest,MODIFIED,eval-sanitize-2-r4-035,phase=Pending job=None
35.0353,Job,ADDED,eval-sanitize-2-r4-035,
35.0396,TaskRequest,MODIFIED,eval-sanitize-2-r4-035,phase=Scheduled job=None
35.0432,Job,MODIFIED,eval-sanitize-2-r4-034,
35.0441,Pod,ADDED,eval-sanitize-2-r4-035-d2wq7,phase=Pending node=None
35.0448,Job,MODIFIED,eval-sanitize-2-r4-035,
35.0486,Event,ADDED,eval-sanitize-2-r4-035.18d3d1d795cc16bb,reason=SuccessfulCreate count=1 msg=Created pod: eval-sanitize-2-r4-035-d2wq7
35.0487,TaskRequest,MODIFIED,eval-sanitize-2-r4-035,phase=Scheduled job=None
35.0521,Pod,MODIFIED,eval-sanitize-2-r4-035-d2wq7,phase=Pending node=kind-worker3
35.0539,Job,MODIFIED,eval-sanitize-2-r4-034,
35.0574,Job,MODIFIED,eval-sanitize-2-r4-033,
35.0603,Event,ADDED,eval-sanitize-2-r4-035-d2wq7.18d3d1d79658a8be,reason=Scheduled count=None msg=Successfully assigned compute/eval-sanitize-2-r4-035-d2wq7 to kind-worker3
35.0649,Node,MODIFIED,kind-worker3,taints=0
35.0658,Pod,MODIFIED,eval-sanitize-2-r4-034-bjrp7,phase=Pending node=None
35.0672,Pod,MODIFIED,eval-sanitize-2-r4-035-d2wq7,phase=Pending node=kind-worker3
35.068,Job,MODIFIED,eval-sanitize-2-r4-033,
35.0745,Node,MODIFIED,kind-worker3,taints=0
35.0762,Event,ADDED,eval-sanitize-2-r4-034-bjrp7.18d3d1d7979ca4f8,"reason=FailedScheduling count=None msg=0/6 nodes are available: 1 c_wall violated: 2 conflicting context pair(s) with node memory, 5 node(s) had untolerated taint(s). no new claims to deallocate, preemption: 0/6 nodes are available: 1 No preemption victims found for incoming pod, 5 Preemption is not helpful for scheduling."
35.0803,Event,MODIFIED,eval-sanitize-2-r4-034-bjrp7.18d3d1d7979ca4f8,"reason=FailedScheduling count=None msg=0/6 nodes are available: 1 c_wall violated: 2 conflicting context pair(s) with node memory, 5 node(s) had untolerated taint(s). no new claims to deallocate, preemption: 0/6 nodes are available: 1 No preemption victims found for incoming pod, 5 Preemption is not helpful for scheduling."
35.5437,Event,ADDED,eval-sanitize-2-r4-035-d2wq7.18d3d1d7b3294434,"reason=Pulled count=1 msg=Container image ""busybox:musl"" already present on machine"
35.5582,Event,ADDED,eval-sanitize-2-r4-035-d2wq7.18d3d1d7b44f1ccc,reason=Created count=1 msg=Created container: task
35.5913,Event,ADDED,eval-sanitize-2-r4-035-d2wq7.18d3d1d7b6470ee7,reason=Started count=1 msg=Started container task
35.8294,Pod,MODIFIED,eval-sanitize-2-r4-035-d2wq7,phase=Running node=kind-worker3
36.0216,TaskRequest,ADDED,eval-sanitize-2-r4-036,phase=None job=None
36.0256,TaskRequest,MODIFIED,eval-sanitize-2-r4-036,phase=Pending job=None
36.0407,Job,ADDED,eval-sanitize-2-r4-036,
36.0476,Job,MODIFIED,eval-sanitize-2-r4-035,
36.0496,Job,MODIFIED,eval-sanitize-2-r4-036,
36.0497,TaskRequest,MODIFIED,eval-sanitize-2-r4-036,phase=Scheduled job=None
36.0507,Pod,ADDED,eval-sanitize-2-r4-036-5258c,phase=Pending node=None
36.0546,Event,ADDED,eval-sanitize-2-r4-036.18d3d1d7d1d32aff,reason=SuccessfulCreate count=1 msg=Created pod: eval-sanitize-2-r4-036-5258c
36.0578,Pod,MODIFIED,eval-sanitize-2-r4-036-5258c,phase=Pending node=kind-worker3
36.0593,TaskRequest,MODIFIED,eval-sanitize-2-r4-036,phase=Scheduled job=None
36.0641,Job,MODIFIED,eval-sanitize-2-r4-035,
36.066,Event,ADDED,eval-sanitize-2-r4-036-5258c.18d3d1d7d24e6bfa,reason=Scheduled count=None msg=Successfully assigned compute/eval-sanitize-2-r4-036-5258c to kind-worker3
36.067,Pod,MODIFIED,eval-sanitize-2-r4-034-bjrp7,phase=Pending node=None
36.0697,Pod,MODIFIED,eval-sanitize-2-r4-036-5258c,phase=Pending node=kind-worker3
36.0712,Node,MODIFIED,kind-worker3,taints=0
36.0764,Event,ADDED,eval-sanitize-2-r4-034-bjrp7.18d3d1d7d31adb0e,"reason=FailedScheduling count=None msg=0/6 nodes are available: 1 c_wall violated: 3 conflicting context pair(s) with node memory, 5 node(s) had untolerated taint(s). no new claims to deallocate, preemption: 0/6 nodes are available: 1 No preemption victims found for incoming pod, 5 Preemption is not helpful for scheduling."
36.0801,Node,MODIFIED,kind-worker3,taints=0
36.1687,Node,MODIFIED,kind-worker3,taints=1
36.1726,Pod,MODIFIED,eval-sanitize-2-r4-034-bjrp7,phase=Pending node=None
36.3739,Node,MODIFIED,kind-worker3,taints=1
36.4862,Event,ADDED,eval-sanitize-2-r4-036-5258c.18d3d1d7eb8242a1,"reason=Pulled count=1 msg=Container image ""busybox:musl"" already present on machine"
36.5013,Event,ADDED,eval-sanitize-2-r4-036-5258c.18d3d1d7ec91d668,reason=Created count=1 msg=Created container: task
36.5696,Event,ADDED,eval-sanitize-2-r4-036-5258c.18d3d1d7f097b142,reason=Started count=1 msg=Started container task
36.8258,Pod,MODIFIED,eval-sanitize-2-r4-036-5258c,phase=Running node=kind-worker3
37.0074,TaskRequest,ADDED,eval-sanitize-2-r4-037,phase=None job=None
37.011,TaskRequest,MODIFIED,eval-sanitize-2-r4-037,phase=Pending job=None
37.0276,Job,ADDED,eval-sanitize-2-r4-037,
37.0326,Pod,ADDED,eval-sanitize-2-r4-037-r774c,phase=Pending node=None
37.0348,TaskRequest,MODIFIED,eval-sanitize-2-r4-037,phase=Scheduled job=None
37.0376,Job,MODIFIED,eval-sanitize-2-r4-037,
37.0384,Pod,MODIFIED,eval-sanitize-2-r4-037-r774c,phase=Pending node=None
37.0387,Event,ADDED,eval-sanitize-2-r4-037.18d3d1d80c6a297b,reason=SuccessfulCreate count=1 msg=Created pod: eval-sanitize-2-r4-037-r774c
37.0389,Event,ADDED,eval-sanitize-2-r4-037-r774c.18d3d1d80c7415e6,"reason=FailedScheduling count=None msg=0/6 nodes are available: 6 node(s) had untolerated taint(s). no new claims to deallocate, preemption: 0/6 nodes are available: 6 Preemption is not helpful for scheduling."
37.0429,TaskRequest,MODIFIED,eval-sanitize-2-r4-037,phase=Scheduled job=None
37.0543,Job,MODIFIED,eval-sanitize-2-r4-036,
37.0631,Job,MODIFIED,eval-sanitize-2-r4-036,
38.0124,TaskRequest,ADDED,eval-sanitize-2-r4-038,phase=None job=None
38.0165,TaskRequest,MODIFIED,eval-sanitize-2-r4-038,phase=Pending job=None
38.0323,Job,ADDED,eval-sanitize-2-r4-038,
38.0368,Job,MODIFIED,eval-sanitize-2-r4-037,
38.0392,Pod,ADDED,eval-sanitize-2-r4-038-2gqdk,phase=Pending node=None
38.0393,TaskRequest,MODIFIED,eval-sanitize-2-r4-038,phase=Scheduled job=None
38.0437,Job,MODIFIED,eval-sanitize-2-r4-038,
38.046,Event,ADDED,eval-sanitize-2-r4-038.18d3d1d84867e3f5,reason=SuccessfulCreate count=1 msg=Created pod: eval-sanitize-2-r4-038-2gqdk
38.0463,Event,ADDED,eval-sanitize-2-r4-038-2gqdk.18d3d1d84877adb9,"reason=FailedScheduling count=None msg=0/6 nodes are available: 6 node(s) had untolerated taint(s). no new claims to deallocate, preemption: 0/6 nodes are available: 6 Preemption is not helpful for scheduling."
38.0472,Pod,MODIFIED,eval-sanitize-2-r4-038-2gqdk,phase=Pending node=None
38.0491,Job,MODIFIED,eval-sanitize-2-r4-037,
38.0525,Job,MODIFIED,eval-sanitize-2-r4-038,
38.0542,TaskRequest,MODIFIED,eval-sanitize-2-r4-038,phase=Scheduled job=None
38.0618,Job,MODIFIED,eval-sanitize-2-r4-038,
39.014,TaskRequest,ADDED,eval-sanitize-2-r4-039,phase=None job=None
39.018,TaskRequest,MODIFIED,eval-sanitize-2-r4-039,phase=Pending job=None
39.0307,Pod,MODIFIED,eval-sanitize-2-r4-023-6hkqq,phase=Running node=kind-worker
39.0344,Job,ADDED,eval-sanitize-2-r4-039,
39.0378,Pod,MODIFIED,eval-sanitize-2-r4-026-ltj94,phase=Running node=kind-worker
39.0415,Pod,ADDED,eval-sanitize-2-r4-039-62vq7,phase=Pending node=None
39.0438,TaskRequest,MODIFIED,eval-sanitize-2-r4-039,phase=Scheduled job=None
39.0445,Job,MODIFIED,eval-sanitize-2-r4-039,
39.0478,Pod,MODIFIED,eval-sanitize-2-r4-021-vzk2p,phase=Running node=kind-worker
39.0481,Event,ADDED,eval-sanitize-2-r4-039.18d3d1d884275a64,reason=SuccessfulCreate count=1 msg=Created pod: eval-sanitize-2-r4-039-62vq7
39.0483,Event,ADDED,eval-sanitize-2-r4-039-62vq7.18d3d1d8843098a1,"reason=FailedScheduling count=None msg=0/6 nodes are available: 6 node(s) had untolerated taint(s). no new claims to deallocate, preemption: 0/6 nodes are available: 6 Preemption is not helpful for scheduling."
39.0491,Pod,MODIFIED,eval-sanitize-2-r4-039-62vq7,phase=Pending node=None
39.0526,TaskRequest,MODIFIED,eval-sanitize-2-r4-039,phase=Scheduled job=None
39.0563,Pod,MODIFIED,eval-sanitize-2-r4-027-5cbcr,phase=Running node=kind-worker
39.0622,Pod,MODIFIED,eval-sanitize-2-r4-028-fth75,phase=Running node=kind-worker
40.0164,TaskRequest,ADDED,eval-sanitize-2-r4-040,phase=None job=None
40.0221,TaskRequest,MODIFIED,eval-sanitize-2-r4-040,phase=Pending job=None
40.0375,Job,MODIFIED,eval-sanitize-2-r4-023,
40.0403,Job,ADDED,eval-sanitize-2-r4-040,
40.0429,Job,MODIFIED,eval-sanitize-2-r4-026,
40.0466,Pod,MODIFIED,eval-sanitize-2-r4-029-55cpp,phase=Running node=kind-worker
40.0478,Job,MODIFIED,eval-sanitize-2-r4-039,
40.0498,TaskRequest,MODIFIED,eval-sanitize-2-r4-040,phase=Scheduled job=None
40.0517,Pod,ADDED,eval-sanitize-2-r4-040-j9n9j,phase=Pending node=None
40.0532,Job,MODIFIED,eval-sanitize-2-r4-040,
40.0561,Job,MODIFIED,eval-sanitize-2-r4-021,
40.0582,Event,ADDED,eval-sanitize-2-r4-040.18d3d1d8c04f120a,reason=SuccessfulCreate count=1 msg=Created pod: eval-sanitize-2-r4-040-j9n9j
40.0585,Event,ADDED,eval-sanitize-2-r4-040-j9n9j.18d3d1d8c057dc34,"reason=FailedScheduling count=None msg=0/6 nodes are available: 6 node(s) had untolerated taint(s). no new claims to deallocate, preemption: 0/6 nodes are available: 6 Preemption is not helpful for scheduling."
40.0602,Pod,MODIFIED,eval-sanitize-2-r4-040-j9n9j,phase=Pending node=None
40.0614,Job,MODIFIED,eval-sanitize-2-r4-027,
40.0632,TaskRequest,MODIFIED,eval-sanitize-2-r4-040,phase=Scheduled job=None
40.0641,Job,MODIFIED,eval-sanitize-2-r4-023,
40.0649,Job,MODIFIED,eval-sanitize-2-r4-026,
40.0658,Job,MODIFIED,eval-sanitize-2-r4-039,
40.0679,Job,MODIFIED,eval-sanitize-2-r4-028,
40.0687,Job,MODIFIED,eval-sanitize-2-r4-021,
40.134,Job,MODIFIED,eval-sanitize-2-r4-027,
40.1352,Job,MODIFIED,eval-sanitize-2-r4-028,
40.1832,Node,MODIFIED,kind-worker2,taints=1
40.225,Pod,MODIFIED,eval-sanitize-2-r4-028-fth75,phase=Succeeded node=kind-worker
40.2677,Pod,MODIFIED,eval-sanitize-2-r4-021-vzk2p,phase=Succeeded node=kind-worker
40.2737,Pod,MODIFIED,eval-sanitize-2-r4-026-ltj94,phase=Succeeded node=kind-worker
40.2848,Pod,MODIFIED,eval-sanitize-2-r4-023-6hkqq,phase=Succeeded node=kind-worker
40.2901,Pod,MODIFIED,eval-sanitize-2-r4-025-dphm6,phase=Running node=kind-worker2
40.292,Pod,MODIFIED,eval-sanitize-2-r4-027-5cbcr,phase=Succeeded node=kind-worker
40.2962,Pod,MODIFIED,eval-sanitize-2-r4-024-m4dwq,phase=Running node=kind-worker2
40.9003,Pod,MODIFIED,eval-sanitize-2-r4-022-kvzd5,phase=Running node=kind-worker4
41.011,TaskRequest,ADDED,eval-sanitize-2-r4-041,phase=None job=None
41.0156,TaskRequest,MODIFIED,eval-sanitize-2-r4-041,phase=Pending job=None
41.0291,Job,ADDED,eval-sanitize-2-r4-041,
41.0354,Pod,ADDED,eval-sanitize-2-r4-041-d4w9s,phase=Pending node=None
41.0369,TaskRequest,MODIFIED,eval-sanitize-2-r4-041,phase=Scheduled job=None
41.0376,Job,MODIFIED,eval-sanitize-2-r4-041,
41.0427,Event,ADDED,eval-sanitize-2-r4-041.18d3d1d8fb048847,reason=SuccessfulCreate count=1 msg=Created pod: eval-sanitize-2-r4-041-d4w9s
41.043,Event,ADDED,eval-sanitize-2-r4-041-d4w9s.18d3d1d8fb0ff7b5,"reason=FailedScheduling count=None msg=0/6 nodes are available: 6 node(s) had untolerated taint(s). no new claims to deallocate, preemption: 0/6 nodes are available: 6 Preemption is not helpful for scheduling."
41.0445,Job,MODIFIED,eval-sanitize-2-r4-023,
41.0455,Pod,MODIFIED,eval-sanitize-2-r4-041-d4w9s,phase=Pending node=None
41.052,TaskRequest,MODIFIED,eval-sanitize-2-r4-041,phase=Scheduled job=None
41.054,Job,MODIFIED,eval-sanitize-2-r4-026,
41.0554,Job,MODIFIED,eval-sanitize-2-r4-029,
41.0571,Job,MODIFIED,eval-sanitize-2-r4-023,
41.0599,Pod,MODIFIED,eval-sanitize-2-r4-023-6hkqq,phase=Succeeded node=kind-worker
41.0617,Job,MODIFIED,eval-sanitize-2-r4-040,
41.0703,Job,MODIFIED,eval-sanitize-2-r4-021,
41.0759,Job,MODIFIED,eval-sanitize-2-r4-026,
41.0778,Pod,MODIFIED,eval-sanitize-2-r4-026-ltj94,phase=Succeeded node=kind-worker
41.0795,Job,MODIFIED,eval-sanitize-2-r4-029,
41.0803,Job,MODIFIED,eval-sanitize-2-r4-028,
41.0817,Job,MODIFIED,eval-sanitize-2-r4-027,
41.0832,Pod,MODIFIED,eval-sanitize-2-r4-021-vzk2p,phase=Succeeded node=kind-worker
41.0841,Job,MODIFIED,eval-sanitize-2-r4-040,
41.0869,Job,MODIFIED,eval-sanitize-2-r4-021,
41.0899,Pod,MODIFIED,eval-sanitize-2-r4-027-5cbcr,phase=Succeeded node=kind-worker
41.0911,Pod,MODIFIED,eval-sanitize-2-r4-028-fth75,phase=Succeeded node=kind-worker
41.0921,Event,ADDED,eval-sanitize-2-r4-021.18d3d1d8fe17e920,reason=Completed count=1 msg=Job completed
41.0949,Job,MODIFIED,eval-sanitize-2-r4-027,
41.0959,Job,MODIFIED,eval-sanitize-2-r4-028,
41.0992,Event,ADDED,eval-sanitize-2-r4-028.18d3d1d8fe8f5491,reason=Completed count=1 msg=Job completed
41.1026,Event,ADDED,eval-sanitize-2-r4-027.18d3d1d8fe8fc392,reason=Completed count=1 msg=Job completed
41.1343,Job,MODIFIED,eval-sanitize-2-r4-021,
41.1361,Job,MODIFIED,eval-sanitize-2-r4-028,
41.1373,Job,MODIFIED,eval-sanitize-2-r4-027,
41.14,TaskRequest,MODIFIED,eval-sanitize-2-r4-021,phase=Complete job=None
41.1436,TaskRequest,MODIFIED,eval-sanitize-2-r4-027,phase=Complete job=None
41.1475,TaskRequest,MODIFIED,eval-sanitize-2-r4-028,phase=Complete job=None
41.1501,Job,MODIFIED,eval-sanitize-2-r4-021,
41.1802,Pod,MODIFIED,eval-sanitize-2-r4-029-55cpp,phase=Succeeded node=kind-worker
41.2295,Job,MODIFIED,eval-sanitize-2-r4-028,
41.2304,Job,MODIFIED,eval-sanitize-2-r4-027,
41.2954,Job,MODIFIED,eval-sanitize-2-r4-025,
41.2982,Pod,MODIFIED,eval-sanitize-2-r4-030-m9bv7,phase=Running node=kind-worker2
41.3022,Job,MODIFIED,eval-sanitize-2-r4-024,
41.3054,Job,MODIFIED,eval-sanitize-2-r4-025,
41.312,Job,MODIFIED,eval-sanitize-2-r4-024,
41.4076,Pod,MODIFIED,eval-sanitize-2-r4-024-m4dwq,phase=Succeeded node=kind-worker2
41.4129,Pod,MODIFIED,eval-sanitize-2-r4-025-dphm6,phase=Succeeded node=kind-worker2
41.9047,Pod,MODIFIED,eval-sanitize-2-r4-031-88cfn,phase=Running node=kind-worker4
41.9058,Job,MODIFIED,eval-sanitize-2-r4-022,
41.9151,Job,MODIFIED,eval-sanitize-2-r4-022,
41.9813,Pod,MODIFIED,eval-sanitize-2-r4-022-kvzd5,phase=Succeeded node=kind-worker4
42.0091,TaskRequest,ADDED,eval-sanitize-2-r4-042,phase=None job=None
42.0125,TaskRequest,MODIFIED,eval-sanitize-2-r4-042,phase=Pending job=None
42.0272,Job,ADDED,eval-sanitize-2-r4-042,
42.0332,TaskRequest,MODIFIED,eval-sanitize-2-r4-042,phase=Scheduled job=None
42.0346,Pod,ADDED,eval-sanitize-2-r4-042-2k9sd,phase=Pending node=None
42.0357,Job,MODIFIED,eval-sanitize-2-r4-042,
42.0401,Event,ADDED,eval-sanitize-2-r4-042.18d3d1d9368abfc4,reason=SuccessfulCreate count=1 msg=Created pod: eval-sanitize-2-r4-042-2k9sd
42.0403,Event,ADDED,eval-sanitize-2-r4-042-2k9sd.18d3d1d936968f25,"reason=FailedScheduling count=None msg=0/6 nodes are available: 6 node(s) had untolerated taint(s). no new claims to deallocate, preemption: 0/6 nodes are available: 6 Preemption is not helpful for scheduling."
42.0413,Pod,MODIFIED,eval-sanitize-2-r4-042-2k9sd,phase=Pending node=None
42.0421,Job,MODIFIED,eval-sanitize-2-r4-041,
42.0423,TaskRequest,MODIFIED,eval-sanitize-2-r4-042,phase=Scheduled job=None
42.048,Job,MODIFIED,eval-sanitize-2-r4-023,
42.0503,Job,MODIFIED,eval-sanitize-2-r4-041,
42.0529,Job,MODIFIED,eval-sanitize-2-r4-023,
42.0581,Event,ADDED,eval-sanitize-2-r4-023.18d3d1d937af4d6b,reason=Completed count=1 msg=Job completed
42.0595,Job,MODIFIED,eval-sanitize-2-r4-026,
42.0604,Job,MODIFIED,eval-sanitize-2-r4-029,
42.0634,Job,MODIFIED,eval-sanitize-2-r4-026,
42.0652,Job,MODIFIED,eval-sanitize-2-r4-023,
42.0675,Pod,MODIFIED,eval-sanitize-2-r4-029-55cpp,phase=Succeeded node=kind-worker
42.0681,Event,ADDED,eval-sanitize-2-r4-026.18d3d1d93843a73c,reason=Completed count=1 msg=Job completed
42.0709,Job,MODIFIED,eval-sanitize-2-r4-029,
42.0746,Job,MODIFIED,eval-sanitize-2-r4-026,
42.0758,Event,ADDED,eval-sanitize-2-r4-029.18d3d1d938c03e30,reason=Completed count=1 msg=Job completed
42.1221,TaskRequest,MODIFIED,eval-sanitize-2-r4-023,phase=Complete job=None
42.1266,Job,MODIFIED,eval-sanitize-2-r4-029,
42.1268,TaskRequest,MODIFIED,eval-sanitize-2-r4-026,phase=Complete job=None
42.1322,Job,MODIFIED,eval-sanitize-2-r4-023,
42.1323,TaskRequest,MODIFIED,eval-sanitize-2-r4-029,phase=Complete job=None
42.1377,Job,MODIFIED,eval-sanitize-2-r4-026,
42.1413,Job,MODIFIED,eval-sanitize-2-r4-029,
42.3029,Job,MODIFIED,eval-sanitize-2-r4-025,
42.3044,Job,MODIFIED,eval-sanitize-2-r4-030,
42.3072,Job,MODIFIED,eval-sanitize-2-r4-024,
42.3118,Pod,MODIFIED,eval-sanitize-2-r4-025-dphm6,phase=Succeeded node=kind-worker2
42.3134,Job,MODIFIED,eval-sanitize-2-r4-025,
42.3166,Job,MODIFIED,eval-sanitize-2-r4-030,
42.3179,Pod,MODIFIED,eval-sanitize-2-r4-024-m4dwq,phase=Succeeded node=kind-worker2
42.3188,Job,MODIFIED,eval-sanitize-2-r4-024,
42.4489,Pod,MODIFIED,eval-sanitize-2-r4-030-m9bv7,phase=Succeeded node=kind-worker2
42.8869,Pod,MODIFIED,eval-sanitize-2-r4-032-jnkcf,phase=Running node=kind-worker5
42.91,Job,MODIFIED,eval-sanitize-2-r4-031,
42.9119,Job,MODIFIED,eval-sanitize-2-r4-022,
42.9208,Job,MODIFIED,eval-sanitize-2-r4-031,
42.9252,Job,MODIFIED,eval-sanitize-2-r4-022,
42.9266,Pod,MODIFIED,eval-sanitize-2-r4-022-kvzd5,phase=Succeeded node=kind-worker4
43.0086,Pod,MODIFIED,eval-sanitize-2-r4-031-88cfn,phase=Succeeded node=kind-worker4
43.0089,TaskRequest,ADDED,eval-sanitize-2-r4-043,phase=None job=None
43.0124,TaskRequest,MODIFIED,eval-sanitize-2-r4-043,phase=Pending job=None
43.0274,Job,ADDED,eval-sanitize-2-r4-043,
43.0329,Pod,ADDED,eval-sanitize-2-r4-043-rpkcz,phase=Pending node=None
43.0333,TaskRequest,MODIFIED,eval-sanitize-2-r4-043,phase=Scheduled job=None
43.0365,Job,MODIFIED,eval-sanitize-2-r4-043,
43.038,Event,ADDED,eval-sanitize-2-r4-043.18d3d1d97219767e,reason=SuccessfulCreate count=1 msg=Created pod: eval-sanitize-2-r4-043-rpkcz
43.0391,Pod,MODIFIED,eval-sanitize-2-r4-043-rpkcz,phase=Pending node=None
43.0398,Job,MODIFIED,eval-sanitize-2-r4-042,
43.0401,Event,ADDED,eval-sanitize-2-r4-043-rpkcz.18d3d1d97224f2aa,"reason=FailedScheduling count=None msg=0/6 nodes are available: 6 node(s) had untolerated taint(s). no new claims to deallocate, preemption: 0/6 nodes are available: 6 Preemption is not helpful for scheduling."
43.0409,TaskRequest,MODIFIED,eval-sanitize-2-r4-043,phase=Scheduled job=None
43.0464,Job,MODIFIED,eval-sanitize-2-r4-042,
43.159,Node,MODIFIED,kind-worker,taints=1
43.1711,Node,MODIFIED,kind-worker,taints=0
43.1769,Pod,MODIFIED,eval-sanitize-2-r4-034-bjrp7,phase=Pending node=kind-worker
43.1806,Node,MODIFIED,kind-worker,taints=0
43.181,Event,ADDED,eval-sanitize-2-r4-034-bjrp7.18d3d1d97aaae459,reason=Scheduled count=None msg=Successfully assigned compute/eval-sanitize-2-r4-034-bjrp7 to kind-worker
43.186,Pod,MODIFIED,eval-sanitize-2-r4-037-r774c,phase=Pending node=kind-worker
43.1885,Pod,MODIFIED,eval-sanitize-2-r4-034-bjrp7,phase=Pending node=kind-worker
43.1913,Event,ADDED,eval-sanitize-2-r4-038-2gqdk.18d3d1d97b175562,"reason=FailedScheduling count=None msg=0/6 nodes are available: 1 c_wall violated: 2 conflicting context pair(s) with node memory, 5 node(s) had untolerated taint(s). no new claims to deallocate, preemption: 0/6 nodes are available: 1 No preemption victims found for incoming pod, 5 Preemption is not helpful for scheduling."
43.1923,Pod,MODIFIED,eval-sanitize-2-r4-038-2gqdk,phase=Pending node=None
43.1932,Event,ADDED,eval-sanitize-2-r4-037-r774c.18d3d1d97b2e0b79,reason=Scheduled count=None msg=Successfully assigned compute/eval-sanitize-2-r4-037-r774c to kind-worker
43.1946,Node,MODIFIED,kind-worker,taints=0
43.1989,Pod,MODIFIED,eval-sanitize-2-r4-037-r774c,phase=Pending node=kind-worker
43.201,Pod,MODIFIED,eval-sanitize-2-r4-039-62vq7,phase=Pending node=None
43.2014,Event,ADDED,eval-sanitize-2-r4-039-62vq7.18d3d1d97bd1797a,"reason=FailedScheduling count=None msg=0/6 nodes are available: 1 c_wall violated: 1 conflicting context pair(s) with node memory, 5 node(s) had untolerated taint(s). no new claims to deallocate, preemption: 0/6 nodes are available: 1 No preemption victims found for incoming pod, 5 Preemption is not helpful for scheduling."
43.2083,Node,MODIFIED,kind-worker,taints=0
43.2159,Pod,MODIFIED,eval-sanitize-2-r4-040-j9n9j,phase=Pending node=None
43.2171,Event,ADDED,eval-sanitize-2-r4-040-j9n9j.18d3d1d97cb5c435,"reason=FailedScheduling count=None msg=0/6 nodes are available: 1 c_wall violated: 1 conflicting context pair(s) with node memory, 5 node(s) had untolerated taint(s). no new claims to deallocate, preemption: 0/6 nodes are available: 1 No preemption victims found for incoming pod, 5 Preemption is not helpful for scheduling."
43.2185,Node,MODIFIED,kind-worker,taints=0
43.2529,Node,MODIFIED,kind-worker,taints=0
43.266,Node,MODIFIED,kind-worker,taints=0
43.2934,Pod,MODIFIED,eval-sanitize-2-r4-041-d4w9s,phase=Pending node=None
43.2937,Event,ADDED,eval-sanitize-2-r4-041-d4w9s.18d3d1d981398cf6,"reason=FailedScheduling count=None msg=0/6 nodes are available: 1 c_wall violated: 1 conflicting context pair(s) with node memory, 5 node(s) had untolerated taint(s). no new claims to deallocate, preemption: 0/6 nodes are available: 1 No preemption victims found for incoming pod, 5 Preemption is not helpful for scheduling."
43.3014,Pod,MODIFIED,eval-sanitize-2-r4-042-2k9sd,phase=Pending node=None
43.3017,Event,ADDED,eval-sanitize-2-r4-042-2k9sd.18d3d1d981cba9f9,"reason=FailedScheduling count=None msg=0/6 nodes are available: 1 c_wall violated: 2 conflicting context pair(s) with node memory, 5 node(s) had untolerated taint(s). no new claims to deallocate, preemption: 0/6 nodes are available: 1 No preemption victims found for incoming pod, 5 Preemption is not helpful for scheduling."
43.3086,Job,MODIFIED,eval-sanitize-2-r4-025,
43.3112,Event,ADDED,eval-sanitize-2-r4-043-rpkcz.18d3d1d982465663,"reason=FailedScheduling count=None msg=0/6 nodes are available: 1 c_wall violated: 1 conflicting context pair(s) with node memory, 5 node(s) had untolerated taint(s). no new claims to deallocate, preemption: 0/6 nodes are available: 1 No preemption victims found for incoming pod, 5 Preemption is not helpful for scheduling."
43.312,Job,MODIFIED,eval-sanitize-2-r4-030,
43.3134,Pod,MODIFIED,eval-sanitize-2-r4-043-rpkcz,phase=Pending node=None
43.3146,Job,MODIFIED,eval-sanitize-2-r4-024,
43.3156,Job,MODIFIED,eval-sanitize-2-r4-025,
43.318,Job,MODIFIED,eval-sanitize-2-r4-024,
43.3206,Event,ADDED,eval-sanitize-2-r4-025.18d3d1d982ce037b,reason=Completed count=1 msg=Job completed
43.3224,Pod,MODIFIED,eval-sanitize-2-r4-030-m9bv7,phase=Succeeded node=kind-worker2
43.3229,Event,ADDED,eval-sanitize-2-r4-038-2gqdk.18d3d1d982ed5378,"reason=FailedScheduling count=None msg=0/6 nodes are available: 1 c_wall violated: 2 conflicting context pair(s) with node memory, 5 node(s) had untolerated taint(s). no new claims to deallocate, preemption: 0/6 nodes are available: 1 No preemption victims found for incoming pod, 5 Preemption is not helpful for scheduling."
43.3238,Job,MODIFIED,eval-sanitize-2-r4-030,
43.3244,Event,ADDED,eval-sanitize-2-r4-039-62vq7.18d3d1d983224050,"reason=FailedScheduling count=None msg=0/6 nodes are available: 1 c_wall violated: 1 conflicting context pair(s) with node memory, 5 node(s) had untolerated taint(s). no new claims to deallocate, preemption: 0/6 nodes are available: 1 No preemption victims found for incoming pod, 5 Preemption is not helpful for scheduling."
43.3266,Event,ADDED,eval-sanitize-2-r4-024.18d3d1d98310b9dc,reason=Completed count=1 msg=Job completed
43.3285,Event,ADDED,eval-sanitize-2-r4-040-j9n9j.18d3d1d9835d3ecc,"reason=FailedScheduling count=None msg=0/6 nodes are available: 1 c_wall violated: 1 conflicting context pair(s) with node memory, 5 node(s) had untolerated taint(s). no new claims to deallocate, preemption: 0/6 nodes are available: 1 No preemption victims found for incoming pod, 5 Preemption is not helpful for scheduling."
43.3294,Job,MODIFIED,eval-sanitize-2-r4-025,
43.3305,Event,ADDED,eval-sanitize-2-r4-041-d4w9s.18d3d1d98394e087,"reason=FailedScheduling count=None msg=0/6 nodes are available: 1 c_wall violated: 1 conflicting context pair(s) with node memory, 5 node(s) had untolerated taint(s). no new claims to deallocate, preemption: 0/6 nodes are available: 1 No preemption victims found for incoming pod, 5 Preemption is not helpful for scheduling."
43.3332,Job,MODIFIED,eval-sanitize-2-r4-024,
43.3336,TaskRequest,MODIFIED,eval-sanitize-2-r4-025,phase=Complete job=None
43.3383,TaskRequest,MODIFIED,eval-sanitize-2-r4-024,phase=Complete job=None
43.343,Job,MODIFIED,eval-sanitize-2-r4-025,
43.3469,Job,MODIFIED,eval-sanitize-2-r4-024,
43.3861,Event,ADDED,eval-sanitize-2-r4-042-2k9sd.18d3d1d986d2f586,"reason=FailedScheduling count=None msg=0/6 nodes are available: 1 c_wall violated: 2 conflicting context pair(s) with node memory, 5 node(s) had untolerated taint(s). no new claims to deallocate, preemption: 0/6 nodes are available: 1 No preemption victims found for incoming pod, 5 Preemption is not helpful for scheduling."
43.3912,Event,ADDED,eval-sanitize-2-r4-043-rpkcz.18d3d1d9872e9774,"reason=FailedScheduling count=None msg=0/6 nodes are available: 1 c_wall violated: 1 conflicting context pair(s) with node memory, 5 node(s) had untolerated taint(s). no new claims to deallocate, preemption: 0/6 nodes are available: 1 No preemption victims found for incoming pod, 5 Preemption is not helpful for scheduling."
43.606,Event,ADDED,eval-sanitize-2-r4-034-bjrp7.18d3d1d993fa5833,"reason=Pulled count=1 msg=Container image ""busybox:musl"" already present on machine"
43.6098,Event,ADDED,eval-sanitize-2-r4-037-r774c.18d3d1d9941be272,"reason=Pulled count=1 msg=Container image ""busybox:musl"" already present on machine"
43.6288,Event,ADDED,eval-sanitize-2-r4-034-bjrp7.18d3d1d995653ff9,reason=Created count=1 msg=Created container: task
43.6356,Event,ADDED,eval-sanitize-2-r4-037-r774c.18d3d1d995b9d074,reason=Created count=1 msg=Created container: task
43.7008,Event,ADDED,eval-sanitize-2-r4-034-bjrp7.18d3d1d9999e8929,reason=Started count=1 msg=Started container task
43.7041,Event,ADDED,eval-sanitize-2-r4-037-r774c.18d3d1d999a0f0b4,reason=Started count=1 msg=Started container task
43.8599,Node,MODIFIED,kind-worker2,taints=1
43.8677,Event,MODIFIED,eval-sanitize-2-r4-038-2gqdk.18d3d1d982ed5378,"reason=FailedScheduling count=None msg=0/6 nodes are available: 1 c_wall violated: 2 conflicting context pair(s) with node memory, 5 node(s) had untolerated taint(s). no new claims to deallocate, preemption: 0/6 nodes are available: 1 No preemption victims found for incoming pod, 5 Preemption is not helpful for scheduling."
43.8718,Node,MODIFIED,kind-worker2,taints=1
43.873,Event,MODIFIED,eval-sanitize-2-r4-039-62vq7.18d3d1d983224050,"reason=FailedScheduling count=None msg=0/6 nodes are available: 1 c_wall violated: 1 conflicting context pair(s) with node memory, 5 node(s) had untolerated taint(s). no new claims to deallocate, preemption: 0/6 nodes are available: 1 No preemption victims found for incoming pod, 5 Preemption is not helpful for scheduling."
43.8732,Event,MODIFIED,eval-sanitize-2-r4-040-j9n9j.18d3d1d9835d3ecc,"reason=FailedScheduling count=None msg=0/6 nodes are available: 1 c_wall violated: 1 conflicting context pair(s) with node memory, 5 node(s) had untolerated taint(s). no new claims to deallocate, preemption: 0/6 nodes are available: 1 No preemption victims found for incoming pod, 5 Preemption is not helpful for scheduling."
43.8766,Event,MODIFIED,eval-sanitize-2-r4-041-d4w9s.18d3d1d98394e087,"reason=FailedScheduling count=None msg=0/6 nodes are available: 1 c_wall violated: 1 conflicting context pair(s) with node memory, 5 node(s) had untolerated taint(s). no new claims to deallocate, preemption: 0/6 nodes are available: 1 No preemption victims found for incoming pod, 5 Preemption is not helpful for scheduling."
43.8797,Node,MODIFIED,kind-worker2,taints=0
43.8813,Event,MODIFIED,eval-sanitize-2-r4-042-2k9sd.18d3d1d986d2f586,"reason=FailedScheduling count=None msg=0/6 nodes are available: 1 c_wall violated: 2 conflicting context pair(s) with node memory, 5 node(s) had untolerated taint(s). no new claims to deallocate, preemption: 0/6 nodes are available: 1 No preemption victims found for incoming pod, 5 Preemption is not helpful for scheduling."
43.8821,Event,MODIFIED,eval-sanitize-2-r4-043-rpkcz.18d3d1d9872e9774,"reason=FailedScheduling count=None msg=0/6 nodes are available: 1 c_wall violated: 1 conflicting context pair(s) with node memory, 5 node(s) had untolerated taint(s). no new claims to deallocate, preemption: 0/6 nodes are available: 1 No preemption victims found for incoming pod, 5 Preemption is not helpful for scheduling."
43.8915,Job,MODIFIED,eval-sanitize-2-r4-032,
43.904,Job,MODIFIED,eval-sanitize-2-r4-032,
43.9149,Job,MODIFIED,eval-sanitize-2-r4-031,
43.9168,Job,MODIFIED,eval-sanitize-2-r4-022,
43.9241,Job,MODIFIED,eval-sanitize-2-r4-022,
43.9255,Pod,MODIFIED,eval-sanitize-2-r4-040-j9n9j,phase=Pending node=kind-worker2
43.9266,Job,MODIFIED,eval-sanitize-2-r4-031,
43.9286,Pod,MODIFIED,eval-sanitize-2-r4-031-88cfn,phase=Succeeded node=kind-worker4
43.9291,Event,ADDED,eval-sanitize-2-r4-022.18d3d1d9a73152b0,reason=Completed count=1 msg=Job completed
43.9299,Pod,MODIFIED,eval-sanitize-2-r4-041-d4w9s,phase=Pending node=kind-worker2
43.9302,Event,ADDED,eval-sanitize-2-r4-040-j9n9j.18d3d1d9a732d30a,reason=Scheduled count=None msg=Successfully assigned compute/eval-sanitize-2-r4-040-j9n9j to kind-worker2
43.9318,Event,ADDED,eval-sanitize-2-r4-041-d4w9s.18d3d1d9a77358c6,reason=Scheduled count=None msg=Successfully assigned compute/eval-sanitize-2-r4-041-d4w9s to kind-worker2
43.9357,Pod,MODIFIED,eval-sanitize-2-r4-040-j9n9j,phase=Pending node=kind-worker2
43.9376,Node,MODIFIED,kind-worker2,taints=0
43.9386,Pod,MODIFIED,eval-sanitize-2-r4-042-2k9sd,phase=Pending node=None
43.9396,Job,MODIFIED,eval-sanitize-2-r4-022,
43.9423,Pod,MODIFIED,eval-sanitize-2-r4-041-d4w9s,phase=Pending node=kind-worker2
43.9424,TaskRequest,MODIFIED,eval-sanitize-2-r4-022,phase=Complete job=None
43.9522,Job,MODIFIED,eval-sanitize-2-r4-022,
43.9548,Node,MODIFIED,kind-worker2,taints=0
43.9647,Node,MODIFIED,kind-worker2,taints=0
44.0089,TaskRequest,ADDED,eval-sanitize-2-r4-044,phase=None job=None
44.0143,TaskRequest,MODIFIED,eval-sanitize-2-r4-044,phase=Pending job=None
44.023,Pod,MODIFIED,eval-sanitize-2-r4-043-rpkcz,phase=Pending node=kind-worker2
44.0258,Node,MODIFIED,kind-worker2,taints=0
44.0286,Event,ADDED,eval-sanitize-2-r4-043-rpkcz.18d3d1d9ad06f3b5,reason=Scheduled count=None msg=Successfully assigned compute/eval-sanitize-2-r4-043-rpkcz to kind-worker2
44.0319,Pod,MODIFIED,eval-sanitize-2-r4-038-2gqdk,phase=Pending node=None
44.0347,Job,ADDED,eval-sanitize-2-r4-044,
44.0383,Pod,MODIFIED,eval-sanitize-2-r4-043-rpkcz,phase=Pending node=kind-worker2
44.0399,Node,MODIFIED,kind-worker2,taints=0
44.0412,Job,MODIFIED,eval-sanitize-2-r4-043,
44.0415,TaskRequest,MODIFIED,eval-sanitize-2-r4-044,phase=Scheduled job=None
44.0436,Pod,MODIFIED,eval-sanitize-2-r4-032-jnkcf,phase=Succeeded node=kind-worker5
44.0447,Pod,ADDED,eval-sanitize-2-r4-044-w9bj4,phase=Pending node=None
44.0459,Pod,MODIFIED,eval-sanitize-2-r4-039-62vq7,phase=Pending node=None
44.0468,Job,MODIFIED,eval-sanitize-2-r4-044,
44.0471,Event,ADDED,eval-sanitize-2-r4-044.18d3d1d9ae3fc19d,reason=SuccessfulCreate count=1 msg=Created pod: eval-sanitize-2-r4-044-w9bj4
44.049,TaskRequest,MODIFIED,eval-sanitize-2-r4-044,phase=Scheduled job=None
44.0515,Job,MODIFIED,eval-sanitize-2-r4-043,
44.0579,Pod,MODIFIED,eval-sanitize-2-r4-037-r774c,phase=Running node=kind-worker
44.0655,Pod,MODIFIED,eval-sanitize-2-r4-034-bjrp7,phase=Running node=kind-worker
44.1253,Pod,MODIFIED,eval-sanitize-2-r4-044-w9bj4,phase=Pending node=kind-worker2
44.1268,Event,ADDED,eval-sanitize-2-r4-042-2k9sd.18d3d1d9b308f9b1,"reason=FailedScheduling count=None msg=0/6 nodes are available: 2 c_wall violated: 2 conflicting context pair(s) with node memory, 4 node(s) had untolerated taint(s). no new claims to deallocate, preemption: 0/6 nodes are available: 2 No preemption victims found for incoming pod, 4 Preemption is not helpful for scheduling."
44.1315,Event,ADDED,eval-sanitize-2-r4-044-w9bj4.18d3d1d9b3290cb3,reason=Scheduled count=None msg=Successfully assigned compute/eval-sanitize-2-r4-044-w9bj4 to kind-worker2
44.1373,Pod,MODIFIED,eval-sanitize-2-r4-044-w9bj4,phase=Pending node=kind-worker2
44.1832,Job,MODIFIED,eval-sanitize-2-r4-034,
44.1855,Event,ADDED,eval-sanitize-2-r4-038-2gqdk.18d3d1d9b6903c35,"reason=FailedScheduling count=None msg=0/6 nodes are available: 1 c_wall violated: 1 conflicting context pair(s) with node memory, 1 c_wall violated: 2 conflicting context pair(s) with node memory, 4 node(s) had untolerated taint(s). no new claims to deallocate, preemption: 0/6 nodes are available: 2 No preemption victims found for incoming pod, 4 Preemption is not helpful for scheduling."
44.1909,Job,MODIFIED,eval-sanitize-2-r4-037,
44.193,Job,MODIFIED,eval-sanitize-2-r4-034,
44.199,Job,MODIFIED,eval-sanitize-2-r4-037,
44.2286,Event,ADDED,eval-sanitize-2-r4-039-62vq7.18d3d1d9b89541dc,"reason=FailedScheduling count=None msg=0/6 nodes are available: 1 c_wall violated: 1 conflicting context pair(s) with node memory, 1 c_wall violated: 2 conflicting context pair(s) with node memory, 4 node(s) had untolerated taint(s). no new claims to deallocate, preemption: 0/6 nodes are available: 2 No preemption victims found for incoming pod, 4 Preemption is not helpful for scheduling."
44.232,Event,MODIFIED,eval-sanitize-2-r4-038-2gqdk.18d3d1d9b6903c35,"reason=FailedScheduling count=None msg=0/6 nodes are available: 1 c_wall violated: 1 conflicting context pair(s) with node memory, 1 c_wall violated: 2 conflicting context pair(s) with node memory, 4 node(s) had untolerated taint(s). no new claims to deallocate, preemption: 0/6 nodes are available: 2 No preemption victims found for incoming pod, 4 Preemption is not helpful for scheduling."
44.2343,Event,MODIFIED,eval-sanitize-2-r4-042-2k9sd.18d3d1d9b308f9b1,"reason=FailedScheduling count=None msg=0/6 nodes are available: 2 c_wall violated: 2 conflicting context pair(s) with node memory, 4 node(s) had untolerated taint(s). no new claims to deallocate, preemption: 0/6 nodes are available: 2 No preemption victims found for incoming pod, 4 Preemption is not helpful for scheduling."
44.3189,Job,MODIFIED,eval-sanitize-2-r4-030,
44.3234,Job,MODIFIED,eval-sanitize-2-r4-030,
44.3297,Event,ADDED,eval-sanitize-2-r4-030.18d3d1d9befea275,reason=Completed count=1 msg=Job completed
44.3385,Job,MODIFIED,eval-sanitize-2-r4-030,
44.3457,TaskRequest,MODIFIED,eval-sanitize-2-r4-030,phase=Complete job=None
44.3518,Event,ADDED,eval-sanitize-2-r4-040-j9n9j.18d3d1d9c072befe,"reason=Pulled count=1 msg=Container image ""busybox:musl"" already present on machine"
44.3585,Job,MODIFIED,eval-sanitize-2-r4-030,
44.3593,Event,ADDED,eval-sanitize-2-r4-041-d4w9s.18d3d1d9c0af6f0f,"reason=Pulled count=1 msg=Container image ""busybox:musl"" already present on machine"
44.3807,Event,ADDED,eval-sanitize-2-r4-040-j9n9j.18d3d1d9c2282011,reason=Created count=1 msg=Created container: task
44.3886,Event,ADDED,eval-sanitize-2-r4-041-d4w9s.18d3d1d9c2a868c9,reason=Created count=1 msg=Created container: task
44.4596,Event,ADDED,eval-sanitize-2-r4-040-j9n9j.18d3d1d9c6be3ed5,reason=Started count=1 msg=Started container task
44.4646,Event,ADDED,eval-sanitize-2-r4-041-d4w9s.18d3d1d9c72904c7,reason=Started count=1 msg=Started container task
44.4774,Event,ADDED,eval-sanitize-2-r4-043-rpkcz.18d3d1d9c7d29d9f,"reason=Pulled count=1 msg=Container image ""busybox:musl"" already present on machine"
44.4981,Event,ADDED,eval-sanitize-2-r4-043-rpkcz.18d3d1d9c931db72,reason=Created count=1 msg=Created container: task
44.5988,Event,ADDED,eval-sanitize-2-r4-044-w9bj4.18d3d1d9cf13ec8f,"reason=Pulled count=1 msg=Container image ""busybox:musl"" already present on machine"
44.6142,Event,ADDED,eval-sanitize-2-r4-044-w9bj4.18d3d1d9d022cf02,reason=Created count=1 msg=Created container: task
44.659,Event,ADDED,eval-sanitize-2-r4-043-rpkcz.18d3d1d9d2c90408,reason=Started count=1 msg=Started container task
44.6723,Event,ADDED,eval-sanitize-2-r4-044-w9bj4.18d3d1d9d39a413f,reason=Started count=1 msg=Started container task
44.7565,Node,MODIFIED,kind-worker4,taints=1
44.7676,Node,MODIFIED,kind-worker4,taints=1
44.7681,Event,MODIFIED,eval-sanitize-2-r4-039-62vq7.18d3d1d9b89541dc,"reason=FailedScheduling count=None msg=0/6 nodes are available: 1 c_wall violated: 1 conflicting context pair(s) with node memory, 1 c_wall violated: 2 conflicting context pair(s) with node memory, 4 node(s) had untolerated taint(s). no new claims to deallocate, preemption: 0/6 nodes are available: 2 No preemption victims found for incoming pod, 4 Preemption is not helpful for scheduling."
44.7762,Node,MODIFIED,kind-worker4,taints=0
44.787,Node,MODIFIED,kind-worker4,taints=0
44.8261,Pod,MODIFIED,eval-sanitize-2-r4-042-2k9sd,phase=Pending node=kind-worker4
44.8296,Event,ADDED,eval-sanitize-2-r4-042-2k9sd.18d3d1d9dceeaa2c,reason=Scheduled count=None msg=Successfully assigned compute/eval-sanitize-2-r4-042-2k9sd to kind-worker4
44.8353,Pod,MODIFIED,eval-sanitize-2-r4-038-2gqdk,phase=Pending node=kind-worker4
44.8383,Pod,MODIFIED,eval-sanitize-2-r4-042-2k9sd,phase=Pending node=kind-worker4
44.84,Node,MODIFIED,kind-worker4,taints=0
44.8403,Event,ADDED,eval-sanitize-2-r4-038-2gqdk.18d3d1d9dd7e5aee,reason=Scheduled count=None msg=Successfully assigned compute/eval-sanitize-2-r4-038-2gqdk to kind-worker4
44.8436,Pod,MODIFIED,eval-sanitize-2-r4-033-p9qml,phase=Running node=kind-worker3
44.8455,Pod,MODIFIED,eval-sanitize-2-r4-038-2gqdk,phase=Pending node=kind-worker4
44.8476,Node,MODIFIED,kind-worker4,taints=0
44.8593,Node,MODIFIED,kind-worker4,taints=0
44.8701,Node,MODIFIED,kind-worker4,taints=0
44.8993,Job,MODIFIED,eval-sanitize-2-r4-032,
44.9074,Pod,MODIFIED,eval-sanitize-2-r4-032-jnkcf,phase=Succeeded node=kind-worker5
44.9088,Job,MODIFIED,eval-sanitize-2-r4-032,
44.9206,Job,MODIFIED,eval-sanitize-2-r4-031,
44.9246,Job,MODIFIED,eval-sanitize-2-r4-031,
44.9268,Pod,MODIFIED,eval-sanitize-2-r4-039-62vq7,phase=Pending node=None
44.9307,Event,ADDED,eval-sanitize-2-r4-031.18d3d1d9e2db3b50,reason=Completed count=1 msg=Job completed
44.9353,Job,MODIFIED,eval-sanitize-2-r4-031,
44.9406,TaskRequest,MODIFIED,eval-sanitize-2-r4-031,phase=Complete job=None
44.9488,Job,MODIFIED,eval-sanitize-2-r4-031,
45.0072,TaskRequest,ADDED,eval-sanitize-2-r4-045,phase=None job=None
45.0121,TaskRequest,MODIFIED,eval-sanitize-2-r4-045,phase=Pending job=None
45.0193,Event,ADDED,eval-sanitize-2-r4-039-62vq7.18d3d1d9e84d4bb6,"reason=FailedScheduling count=None msg=0/6 nodes are available: 1 c_wall violated: 2 conflicting context pair(s) with node memory, 2 c_wall violated: 1 conflicting context pair(s) with node memory, 3 node(s) had untolerated taint(s). no new claims to deallocate, preemption: 0/6 nodes are available: 3 No preemption victims found for incoming pod, 3 Preemption is not helpful for scheduling."
45.0269,Job,ADDED,eval-sanitize-2-r4-045,
45.0329,Pod,ADDED,eval-sanitize-2-r4-045-z8fq4,phase=Pending node=None
45.033,TaskRequest,MODIFIED,eval-sanitize-2-r4-045,phase=Scheduled job=None
45.0359,Job,MODIFIED,eval-sanitize-2-r4-045,
45.0385,Event,ADDED,eval-sanitize-2-r4-045.18d3d1d9e94f6f2d,reason=SuccessfulCreate count=1 msg=Created pod: eval-sanitize-2-r4-045-z8fq4
45.041,TaskRequest,MODIFIED,eval-sanitize-2-r4-045,phase=Scheduled job=None
45.0482,Job,MODIFIED,eval-sanitize-2-r4-044,
45.0502,Pod,MODIFIED,eval-sanitize-2-r4-045-z8fq4,phase=Pending node=kind-worker4
45.0546,Event,ADDED,eval-sanitize-2-r4-045-z8fq4.18d3d1d9ea5459f4,reason=Scheduled count=None msg=Successfully assigned compute/eval-sanitize-2-r4-045-z8fq4 to kind-worker4
45.0581,Job,MODIFIED,eval-sanitize-2-r4-044,
45.0604,Pod,MODIFIED,eval-sanitize-2-r4-045-z8fq4,phase=Pending node=kind-worker4
45.1291,Event,MODIFIED,eval-sanitize-2-r4-039-62vq7.18d3d1d9e84d4bb6,"reason=FailedScheduling count=None msg=0/6 nodes are available: 1 c_wall violated: 2 conflicting context pair(s) with node memory, 2 c_wall violated: 1 conflicting context pair(s) with node memory, 3 node(s) had untolerated taint(s). no new claims to deallocate, preemption: 0/6 nodes are available: 3 No preemption victims found for incoming pod, 3 Preemption is not helpful for scheduling."
45.1923,Node,MODIFIED,kind-worker,taints=1
45.2053,Node,MODIFIED,kind-worker,taints=1
45.226,Pod,MODIFIED,eval-sanitize-2-r4-039-62vq7,phase=Pending node=None
45.2366,Event,ADDED,eval-sanitize-2-r4-039-62vq7.18d3d1d9f52e1ab1,"reason=FailedScheduling count=None msg=0/6 nodes are available: 1 c_wall violated: 1 conflicting context pair(s) with node memory, 1 c_wall violated: 2 conflicting context pair(s) with node memory, 4 node(s) had untolerated taint(s). no new claims to deallocate, preemption: 0/6 nodes are available: 2 No preemption victims found for incoming pod, 4 Preemption is not helpful for scheduling."
45.2563,Event,ADDED,eval-sanitize-2-r4-042-2k9sd.18d3d1d9f654cdbd,"reason=Pulled count=1 msg=Container image ""busybox:musl"" already present on machine"
45.27,Event,ADDED,eval-sanitize-2-r4-038-2gqdk.18d3d1d9f6dd8c1b,"reason=Pulled count=1 msg=Container image ""busybox:musl"" already present on machine"
45.2801,Event,ADDED,eval-sanitize-2-r4-042-2k9sd.18d3d1d9f7bdcd87,reason=Created count=1 msg=Created container: task
45.2905,Event,ADDED,eval-sanitize-2-r4-038-2gqdk.18d3d1d9f863630b,reason=Created count=1 msg=Created container: task
45.3098,Pod,MODIFIED,eval-sanitize-2-r4-041-d4w9s,phase=Running node=kind-worker2
45.3177,Pod,MODIFIED,eval-sanitize-2-r4-040-j9n9j,phase=Running node=kind-worker2
45.3204,Event,ADDED,eval-sanitize-2-r4-042-2k9sd.18d3d1d9fa159d4a,reason=Started count=1 msg=Started container task
45.3212,Event,MODIFIED,eval-sanitize-2-r4-039-62vq7.18d3d1d9f52e1ab1,"reason=FailedScheduling count=None msg=0/6 nodes are available: 1 c_wall violated: 1 conflicting context pair(s) with node memory, 1 c_wall violated: 2 conflicting context pair(s) with node memory, 4 node(s) had untolerated taint(s). no new claims to deallocate, preemption: 0/6 nodes are available: 2 No preemption victims found for incoming pod, 4 Preemption is not helpful for scheduling."
45.3261,Pod,MODIFIED,eval-sanitize-2-r4-043-rpkcz,phase=Running node=kind-worker2
45.3273,Event,ADDED,eval-sanitize-2-r4-038-2gqdk.18d3d1d9fa999787,reason=Started count=1 msg=Started container task
45.3325,Pod,MODIFIED,eval-sanitize-2-r4-044-w9bj4,phase=Running node=kind-worker2
45.4909,Event,ADDED,eval-sanitize-2-r4-045-z8fq4.18d3d1da045e6b31,"reason=Pulled count=1 msg=Container image ""busybox:musl"" already present on machine"
45.5083,Event,ADDED,eval-sanitize-2-r4-045-z8fq4.18d3d1da056c2dd2,reason=Created count=1 msg=Created container: task
45.5406,Event,ADDED,eval-sanitize-2-r4-045-z8fq4.18d3d1da0756c26d,reason=Started count=1 msg=Started container task
45.5556,Node,MODIFIED,kind-worker5,taints=1
45.5691,Node,MODIFIED,kind-worker5,taints=0
45.5786,Node,MODIFIED,kind-worker5,taints=0
45.5799,Pod,MODIFIED,eval-sanitize-2-r4-039-62vq7,phase=Pending node=kind-worker5
45.5846,Event,ADDED,eval-sanitize-2-r4-039-62vq7.18d3d1da09e36da8,reason=Scheduled count=None msg=Successfully assigned compute/eval-sanitize-2-r4-039-62vq7 to kind-worker5
45.5912,Node,MODIFIED,kind-worker5,taints=0
45.5929,Pod,MODIFIED,eval-sanitize-2-r4-039-62vq7,phase=Pending node=kind-worker5
45.6544,Node,MODIFIED,kind-worker5,taints=0
45.6652,Node,MODIFIED,kind-worker5,taints=0
45.8454,Pod,MODIFIED,eval-sanitize-2-r4-035-d2wq7,phase=Running node=kind-worker3
45.8485,Job,MODIFIED,eval-sanitize-2-r4-033,
45.8594,Job,MODIFIED,eval-sanitize-2-r4-033,
45.9068,Job,MODIFIED,eval-sanitize-2-r4-032,
45.9121,Job,MODIFIED,eval-sanitize-2-r4-032,
45.9172,Pod,MODIFIED,eval-sanitize-2-r4-045-z8fq4,phase=Running node=kind-worker4
45.92,Event,ADDED,eval-sanitize-2-r4-032.18d3d1da1db2eb1a,reason=Completed count=1 msg=Job completed
45.9241,Pod,MODIFIED,eval-sanitize-2-r4-042-2k9sd,phase=Running node=kind-worker4
45.926,Job,MODIFIED,eval-sanitize-2-r4-032,
45.9325,Pod,MODIFIED,eval-sanitize-2-r4-038-2gqdk,phase=Running node=kind-worker4
45.9326,TaskRequest,MODIFIED,eval-sanitize-2-r4-032,phase=Complete job=None
45.9435,Job,MODIFIED,eval-sanitize-2-r4-032,
45.9615,Node,MODIFIED,kind-worker2,taints=1
45.9742,Node,MODIFIED,kind-worker2,taints=1
45.9871,Pod,MODIFIED,eval-sanitize-2-r4-033-p9qml,phase=Succeeded node=kind-worker3
46.0071,Event,ADDED,eval-sanitize-2-r4-039-62vq7.18d3d1da230e8bf6,"reason=Pulled count=1 msg=Container image ""busybox:musl"" already present on machine"
46.008,TaskRequest,ADDED,eval-sanitize-2-r4-046,phase=None job=None
46.0124,TaskRequest,MODIFIED,eval-sanitize-2-r4-046,phase=Pending job=None
46.0267,Event,ADDED,eval-sanitize-2-r4-039-62vq7.18d3d1da243a49ef,reason=Created count=1 msg=Created container: task
46.0306,Job,ADDED,eval-sanitize-2-r4-046,
46.0354,TaskRequest,MODIFIED,eval-sanitize-2-r4-046,phase=Scheduled job=None
46.0384,Pod,ADDED,eval-sanitize-2-r4-046-8lqh5,phase=Pending node=None
46.0405,Job,MODIFIED,eval-sanitize-2-r4-045,
46.0424,Job,MODIFIED,eval-sanitize-2-r4-046,
46.0455,Event,ADDED,eval-sanitize-2-r4-046.18d3d1da253a6c8b,reason=SuccessfulCreate count=1 msg=Created pod: eval-sanitize-2-r4-046-8lqh5
46.051,TaskRequest,MODIFIED,eval-sanitize-2-r4-046,phase=Scheduled job=None
46.0617,Pod,MODIFIED,eval-sanitize-2-r4-046-8lqh5,phase=Pending node=None
46.0674,Event,ADDED,eval-sanitize-2-r4-046-8lqh5.18d3d1da25d5e3df,"reason=FailedScheduling count=None msg=0/6 nodes are available: 1 c_wall violated: 1 conflicting context pair(s) with node memory, 1 c_wall violated: 2 conflicting context pair(s) with node memory, 4 node(s) had untolerated taint(s). no new claims to deallocate, preemption: 0/6 nodes are available: 2 No preemption victims found for incoming pod, 4 Preemption is not helpful for scheduling."
46.0686,Job,MODIFIED,eval-sanitize-2-r4-045,
46.0697,Job,MODIFIED,eval-sanitize-2-r4-044,
46.0749,Event,ADDED,eval-sanitize-2-r4-039-62vq7.18d3d1da27235af4,reason=Started count=1 msg=Started container task
46.0756,Event,ADDED,eval-sanitize-2-r4-046-8lqh5.18d3d1da27121ca3,"reason=FailedScheduling count=None msg=0/6 nodes are available: 1 c_wall violated: 1 conflicting context pair(s) with node memory, 1 c_wall violated: 2 conflicting context pair(s) with node memory, 4 node(s) had untolerated taint(s). no new claims to deallocate, preemption: 0/6 nodes are available: 2 No preemption victims found for incoming pod, 4 Preemption is not helpful for scheduling."
46.0783,Job,MODIFIED,eval-sanitize-2-r4-044,
46.3274,Job,MODIFIED,eval-sanitize-2-r4-041,
46.329,Job,MODIFIED,eval-sanitize-2-r4-040,
46.3309,Job,MODIFIED,eval-sanitize-2-r4-043,
46.3363,Job,MODIFIED,eval-sanitize-2-r4-041,
46.338,Job,MODIFIED,eval-sanitize-2-r4-040,
46.3399,Job,MODIFIED,eval-sanitize-2-r4-043,
46.8131,Node,MODIFIED,kind-worker4,taints=1
46.8223,Pod,MODIFIED,eval-sanitize-2-r4-046-8lqh5,phase=Pending node=None
46.8262,Node,MODIFIED,kind-worker4,taints=1
46.8266,Event,MODIFIED,eval-sanitize-2-r4-046-8lqh5.18d3d1da27121ca3,"reason=FailedScheduling count=None msg=0/6 nodes are available: 1 c_wall violated: 1 conflicting context pair(s) with node memory, 1 c_wall violated: 2 conflicting context pair(s) with node memory, 4 node(s) had untolerated taint(s). no new claims to deallocate, preemption: 0/6 nodes are available: 2 No preemption victims found for incoming pod, 4 Preemption is not helpful for scheduling."
46.8306,Event,ADDED,eval-sanitize-2-r4-046-8lqh5.18d3d1da542b5287,"reason=FailedScheduling count=None msg=0/6 nodes are available: 1 c_wall violated: 1 conflicting context pair(s) with node memory, 5 node(s) had untolerated taint(s). no new claims to deallocate, preemption: 0/6 nodes are available: 1 No preemption victims found for incoming pod, 5 Preemption is not helpful for scheduling."
46.8478,Pod,MODIFIED,eval-sanitize-2-r4-036-5258c,phase=Running node=kind-worker3
46.8502,Job,MODIFIED,eval-sanitize-2-r4-035,
46.8563,Job,MODIFIED,eval-sanitize-2-r4-033,
46.86,Job,MODIFIED,eval-sanitize-2-r4-035,
46.8678,Pod,MODIFIED,eval-sanitize-2-r4-033-p9qml,phase=Succeeded node=kind-worker3
46.869,Job,MODIFIED,eval-sanitize-2-r4-033,
46.892,Pod,MODIFIED,eval-sanitize-2-r4-039-62vq7,phase=Running node=kind-worker5
46.9319,Job,MODIFIED,eval-sanitize-2-r4-042,
46.9358,Job,MODIFIED,eval-sanitize-2-r4-038,
46.9391,Pod,MODIFIED,eval-sanitize-2-r4-035-d2wq7,phase=Succeeded node=kind-worker3
46.9409,Job,MODIFIED,eval-sanitize-2-r4-042,
46.9451,Job,MODIFIED,eval-sanitize-2-r4-038,
47.0158,TaskRequest,ADDED,eval-sanitize-2-r4-047,phase=None job=None
47.0192,TaskRequest,MODIFIED,eval-sanitize-2-r4-047,phase=Pending job=None
47.0335,Job,ADDED,eval-sanitize-2-r4-047,
47.0379,TaskRequest,MODIFIED,eval-sanitize-2-r4-047,phase=Scheduled job=None
47.0408,Pod,ADDED,eval-sanitize-2-r4-047-567wm,phase=Pending node=None
47.0429,Job,MODIFIED,eval-sanitize-2-r4-047,
47.0438,Job,MODIFIED,eval-sanitize-2-r4-046,
47.0451,Event,ADDED,eval-sanitize-2-r4-047.18d3d1da60fdc590,reason=SuccessfulCreate count=1 msg=Created pod: eval-sanitize-2-r4-047-567wm
47.0459,TaskRequest,MODIFIED,eval-sanitize-2-r4-047,phase=Scheduled job=None
47.0493,Pod,MODIFIED,eval-sanitize-2-r4-047-567wm,phase=Pending node=None
47.0496,Event,ADDED,eval-sanitize-2-r4-047-567wm.18d3d1da613acb7a,"reason=FailedScheduling count=None msg=0/6 nodes are available: 1 c_wall violated: 1 conflicting context pair(s) with node memory, 5 node(s) had untolerated taint(s). no new claims to deallocate, preemption: 0/6 nodes are available: 1 No preemption victims found for incoming pod, 5 Preemption is not helpful for scheduling."
47.0518,Job,MODIFIED,eval-sanitize-2-r4-046,
47.0559,Event,ADDED,eval-sanitize-2-r4-047-567wm.18d3d1da61b47efa,"reason=FailedScheduling count=None msg=0/6 nodes are available: 1 c_wall violated: 1 conflicting context pair(s) with node memory, 5 node(s) had untolerated taint(s). no new claims to deallocate, preemption: 0/6 nodes are available: 1 No preemption victims found for incoming pod, 5 Preemption is not helpful for scheduling."
47.6024,Node,MODIFIED,kind-worker5,taints=1
47.609,Pod,MODIFIED,eval-sanitize-2-r4-046-8lqh5,phase=Pending node=None
47.6162,Event,MODIFIED,eval-sanitize-2-r4-047-567wm.18d3d1da61b47efa,"reason=FailedScheduling count=None msg=0/6 nodes are available: 1 c_wall violated: 1 conflicting context pair(s) with node memory, 5 node(s) had untolerated taint(s). no new claims to deallocate, preemption: 0/6 nodes are available: 1 No preemption victims found for incoming pod, 5 Preemption is not helpful for scheduling."
47.6173,Pod,MODIFIED,eval-sanitize-2-r4-047-567wm,phase=Pending node=None
47.6185,Node,MODIFIED,kind-worker5,taints=1
47.8582,Job,MODIFIED,eval-sanitize-2-r4-036,
47.8608,Job,MODIFIED,eval-sanitize-2-r4-035,
47.8627,Job,MODIFIED,eval-sanitize-2-r4-033,
47.8703,Job,MODIFIED,eval-sanitize-2-r4-033,
47.8737,Pod,MODIFIED,eval-sanitize-2-r4-035-d2wq7,phase=Succeeded node=kind-worker3
47.8745,Job,MODIFIED,eval-sanitize-2-r4-036,
47.8751,Event,ADDED,eval-sanitize-2-r4-033.18d3d1da926891a5,reason=Completed count=1 msg=Job completed
47.876,Job,MODIFIED,eval-sanitize-2-r4-035,
47.8818,Job,MODIFIED,eval-sanitize-2-r4-033,
47.8853,TaskRequest,MODIFIED,eval-sanitize-2-r4-033,phase=Complete job=None
47.8942,Job,MODIFIED,eval-sanitize-2-r4-033,
47.8963,Job,MODIFIED,eval-sanitize-2-r4-039,
47.904,Job,MODIFIED,eval-sanitize-2-r4-039,
47.9676,Pod,MODIFIED,eval-sanitize-2-r4-036-5258c,phase=Succeeded node=kind-worker3
48.0158,TaskRequest,ADDED,eval-sanitize-2-r4-048,phase=None job=None
48.0195,TaskRequest,MODIFIED,eval-sanitize-2-r4-048,phase=Pending job=None
48.036,Job,ADDED,eval-sanitize-2-r4-048,
48.0395,TaskRequest,MODIFIED,eval-sanitize-2-r4-048,phase=Scheduled job=None
48.043,Pod,ADDED,eval-sanitize-2-r4-048-l42kt,phase=Pending node=None
48.0451,Job,MODIFIED,eval-sanitize-2-r4-048,
48.0471,Job,MODIFIED,eval-sanitize-2-r4-047,
48.0488,Event,ADDED,eval-sanitize-2-r4-048.18d3d1da9cbc02bb,reason=SuccessfulCreate count=1 msg=Created pod: eval-sanitize-2-r4-048-l42kt
48.049,Event,ADDED,eval-sanitize-2-r4-048-l42kt.18d3d1da9cc6ad6f,"reason=FailedScheduling count=None msg=0/6 nodes are available: 6 node(s) had untolerated taint(s). no new claims to deallocate, preemption: 0/6 nodes are available: 6 Preemption is not helpful for scheduling."
48.0491,TaskRequest,MODIFIED,eval-sanitize-2-r4-048,phase=Scheduled job=None
48.05,Pod,MODIFIED,eval-sanitize-2-r4-048-l42kt,phase=Pending node=None
48.0559,Job,MODIFIED,eval-sanitize-2-r4-047,
48.2954,Event,MODIFIED,eval-sanitize-2-r4-034-bjrp7.18d3d1d7d31adb0e,"reason=FailedScheduling count=None msg=0/6 nodes are available: 1 c_wall violated: 3 conflicting context pair(s) with node memory, 5 node(s) had untolerated taint(s). no new claims to deallocate, preemption: 0/6 nodes are available: 1 No preemption victims found for incoming pod, 5 Preemption is not helpful for scheduling."
48.8684,Job,MODIFIED,eval-sanitize-2-r4-036,
48.8696,Job,MODIFIED,eval-sanitize-2-r4-035,
48.8776,Job,MODIFIED,eval-sanitize-2-r4-035,
48.8789,Pod,MODIFIED,eval-sanitize-2-r4-036-5258c,phase=Succeeded node=kind-worker3
48.8802,Job,MODIFIED,eval-sanitize-2-r4-036,
48.8822,Event,ADDED,eval-sanitize-2-r4-035.18d3d1dace712227,reason=Completed count=1 msg=Job completed
48.886,Job,MODIFIED,eval-sanitize-2-r4-035,
48.8909,TaskRequest,MODIFIED,eval-sanitize-2-r4-035,phase=Complete job=None
48.9004,Job,MODIFIED,eval-sanitize-2-r4-035,
49.0102,TaskRequest,ADDED,eval-sanitize-2-r4-049,phase=None job=None
49.0138,TaskRequest,MODIFIED,eval-sanitize-2-r4-049,phase=Pending job=None
49.0301,Job,ADDED,eval-sanitize-2-r4-049,
49.035,TaskRequest,MODIFIED,eval-sanitize-2-r4-049,phase=Scheduled job=None
49.0394,Pod,ADDED,eval-sanitize-2-r4-049-2mqtp,phase=Pending node=None
49.0413,Job,MODIFIED,eval-sanitize-2-r4-049,
49.0456,TaskRequest,MODIFIED,eval-sanitize-2-r4-049,phase=Scheduled job=None
49.046,Event,ADDED,eval-sanitize-2-r4-049.18d3d1dad81edc01,reason=SuccessfulCreate count=1 msg=Created pod: eval-sanitize-2-r4-049-2mqtp
49.0462,Event,ADDED,eval-sanitize-2-r4-049-2mqtp.18d3d1dad8252a91,"reason=FailedScheduling count=None msg=0/6 nodes are available: 6 node(s) had untolerated taint(s). no new claims to deallocate, preemption: 0/6 nodes are available: 6 Preemption is not helpful for scheduling."
49.0475,Pod,MODIFIED,eval-sanitize-2-r4-049-2mqtp,phase=Pending node=None
49.0485,Job,MODIFIED,eval-sanitize-2-r4-048,
49.0575,Job,MODIFIED,eval-sanitize-2-r4-048,
49.6561,Node,MODIFIED,kind-worker3,taints=1
49.67,Node,MODIFIED,kind-worker3,taints=0
49.676,Pod,MODIFIED,eval-sanitize-2-r4-046-8lqh5,phase=Pending node=kind-worker3
49.6784,Node,MODIFIED,kind-worker3,taints=0
49.6812,Event,ADDED,eval-sanitize-2-r4-047-567wm.18d3d1dafde8e4ca,"reason=FailedScheduling count=None msg=0/6 nodes are available: 1 c_wall violated: 1 conflicting context pair(s) with node memory, 5 node(s) had untolerated taint(s). no new claims to deallocate, preemption: 0/6 nodes are available: 1 No preemption victims found for incoming pod, 5 Preemption is not helpful for scheduling."
49.6816,Event,ADDED,eval-sanitize-2-r4-046-8lqh5.18d3d1dafe09aa1c,reason=Scheduled count=None msg=Successfully assigned compute/eval-sanitize-2-r4-046-8lqh5 to kind-worker3
49.6824,Pod,MODIFIED,eval-sanitize-2-r4-047-567wm,phase=Pending node=None
49.6866,Pod,MODIFIED,eval-sanitize-2-r4-046-8lqh5,phase=Pending node=kind-worker3
49.6899,Pod,MODIFIED,eval-sanitize-2-r4-048-l42kt,phase=Pending node=None
49.6904,Event,ADDED,eval-sanitize-2-r4-048-l42kt.18d3d1dafe9d2f79,"reason=FailedScheduling count=None msg=0/6 nodes are available: 1 c_wall violated: 1 conflicting context pair(s) with node memory, 5 node(s) had untolerated taint(s). no new claims to deallocate, preemption: 0/6 nodes are available: 1 No preemption victims found for incoming pod, 5 Preemption is not helpful for scheduling."
49.6976,Pod,MODIFIED,eval-sanitize-2-r4-049-2mqtp,phase=Pending node=None
49.6979,Event,ADDED,eval-sanitize-2-r4-049-2mqtp.18d3d1daff16f1e5,"reason=FailedScheduling count=None msg=0/6 nodes are available: 1 c_wall violated: 1 conflicting context pair(s) with node memory, 5 node(s) had untolerated taint(s). no new claims to deallocate, preemption: 0/6 nodes are available: 1 No preemption victims found for incoming pod, 5 Preemption is not helpful for scheduling."
49.7043,Node,MODIFIED,kind-worker3,taints=0
49.7048,Event,ADDED,eval-sanitize-2-r4-047-567wm.18d3d1daff8b0988,"reason=FailedScheduling count=None msg=0/6 nodes are available: 1 c_wall violated: 1 conflicting context pair(s) with node memory, 5 node(s) had untolerated taint(s). no new claims to deallocate, preemption: 0/6 nodes are available: 1 No preemption victims found for incoming pod, 5 Preemption is not helpful for scheduling."
49.708,Event,ADDED,eval-sanitize-2-r4-048-l42kt.18d3d1daffbbc01c,"reason=FailedScheduling count=None msg=0/6 nodes are available: 1 c_wall violated: 1 conflicting context pair(s) with node memory, 5 node(s) had untolerated taint(s). no new claims to deallocate, preemption: 0/6 nodes are available: 1 No preemption victims found for incoming pod, 5 Preemption is not helpful for scheduling."
49.7128,Event,ADDED,eval-sanitize-2-r4-049-2mqtp.18d3d1daffee1980,"reason=FailedScheduling count=None msg=0/6 nodes are available: 1 c_wall violated: 1 conflicting context pair(s) with node memory, 5 node(s) had untolerated taint(s). no new claims to deallocate, preemption: 0/6 nodes are available: 1 No preemption victims found for incoming pod, 5 Preemption is not helpful for scheduling."
49.7682,Node,MODIFIED,kind-worker3,taints=0
49.7948,Event,MODIFIED,eval-sanitize-2-r4-047-567wm.18d3d1daff8b0988,"reason=FailedScheduling count=None msg=0/6 nodes are available: 1 c_wall violated: 1 conflicting context pair(s) with node memory, 5 node(s) had untolerated taint(s). no new claims to deallocate, preemption: 0/6 nodes are available: 1 No preemption victims found for incoming pod, 5 Preemption is not helpful for scheduling."
49.7987,Event,MODIFIED,eval-sanitize-2-r4-049-2mqtp.18d3d1daffee1980,"reason=FailedScheduling count=None msg=0/6 nodes are available: 1 c_wall violated: 1 conflicting context pair(s) with node memory, 5 node(s) had untolerated taint(s). no new claims to deallocate, preemption: 0/6 nodes are available: 1 No preemption victims found for incoming pod, 5 Preemption is not helpful for scheduling."
49.7991,Event,MODIFIED,eval-sanitize-2-r4-048-l42kt.18d3d1daffbbc01c,"reason=FailedScheduling count=None msg=0/6 nodes are available: 1 c_wall violated: 1 conflicting context pair(s) with node memory, 5 node(s) had untolerated taint(s). no new claims to deallocate, preemption: 0/6 nodes are available: 1 No preemption victims found for incoming pod, 5 Preemption is not helpful for scheduling."
49.8524,Node,MODIFIED,kind-worker3,taints=0
49.8731,Job,MODIFIED,eval-sanitize-2-r4-036,
49.8774,Job,MODIFIED,eval-sanitize-2-r4-036,
49.8817,Event,ADDED,eval-sanitize-2-r4-036.18d3d1db0a0d014c,reason=Completed count=1 msg=Job completed
49.8876,Job,MODIFIED,eval-sanitize-2-r4-036,
49.8926,TaskRequest,MODIFIED,eval-sanitize-2-r4-036,phase=Complete job=None
49.9032,Job,MODIFIED,eval-sanitize-2-r4-036,
50.0086,TaskRequest,ADDED,eval-sanitize-2-r4-050,phase=None job=None
50.0128,TaskRequest,MODIFIED,eval-sanitize-2-r4-050,phase=Pending job=None
50.0291,Job,ADDED,eval-sanitize-2-r4-050,
50.0357,TaskRequest,MODIFIED,eval-sanitize-2-r4-050,phase=Scheduled job=None
50.0386,Pod,ADDED,eval-sanitize-2-r4-050-r2sx8,phase=Pending node=None
50.0408,Job,MODIFIED,eval-sanitize-2-r4-050,
50.044,Event,ADDED,eval-sanitize-2-r4-050.18d3d1db13ac0971,reason=SuccessfulCreate count=1 msg=Created pod: eval-sanitize-2-r4-050-r2sx8
50.0442,TaskRequest,MODIFIED,eval-sanitize-2-r4-050,phase=Scheduled job=None
50.045,Job,MODIFIED,eval-sanitize-2-r4-049,
50.0477,Pod,MODIFIED,eval-sanitize-2-r4-050-r2sx8,phase=Pending node=None
50.0481,Event,ADDED,eval-sanitize-2-r4-050-r2sx8.18d3d1db13e8c643,"reason=FailedScheduling count=None msg=0/6 nodes are available: 1 c_wall violated: 1 conflicting context pair(s) with node memory, 5 node(s) had untolerated taint(s). no new claims to deallocate, preemption: 0/6 nodes are available: 1 No preemption victims found for incoming pod, 5 Preemption is not helpful for scheduling."
50.0545,Job,MODIFIED,eval-sanitize-2-r4-049,
50.0562,Event,ADDED,eval-sanitize-2-r4-050-r2sx8.18d3d1db1468891c,"reason=FailedScheduling count=None msg=0/6 nodes are available: 1 c_wall violated: 1 conflicting context pair(s) with node memory, 5 node(s) had untolerated taint(s). no new claims to deallocate, preemption: 0/6 nodes are available: 1 No preemption victims found for incoming pod, 5 Preemption is not helpful for scheduling."
50.0905,Event,ADDED,eval-sanitize-2-r4-046-8lqh5.18d3d1db1687f465,"reason=Pulled count=1 msg=Container image ""busybox:musl"" already present on machine"
50.1088,Event,ADDED,eval-sanitize-2-r4-046-8lqh5.18d3d1db179ff9c8,reason=Created count=1 msg=Created container: task
50.1416,Event,ADDED,eval-sanitize-2-r4-046-8lqh5.18d3d1db19938c61,reason=Started count=1 msg=Started container task
50.8662,Pod,MODIFIED,eval-sanitize-2-r4-046-8lqh5,phase=Running node=kind-worker3
50.8845,Event,MODIFIED,eval-sanitize-2-r4-050-r2sx8.18d3d1db1468891c,"reason=FailedScheduling count=None msg=0/6 nodes are available: 1 c_wall violated: 1 conflicting context pair(s) with node memory, 5 node(s) had untolerated taint(s). no new claims to deallocate, preemption: 0/6 nodes are available: 1 No preemption victims found for incoming pod, 5 Preemption is not helpful for scheduling."
51.0085,TaskRequest,ADDED,eval-sanitize-2-r4-051,phase=None job=None
51.0137,TaskRequest,MODIFIED,eval-sanitize-2-r4-051,phase=Pending job=None
51.0288,Job,ADDED,eval-sanitize-2-r4-051,
51.035,Pod,ADDED,eval-sanitize-2-r4-051-bcxdv,phase=Pending node=None
51.0379,TaskRequest,MODIFIED,eval-sanitize-2-r4-051,phase=Scheduled job=None
51.0405,Event,ADDED,eval-sanitize-2-r4-051.18d3d1db4f0f4e62,reason=SuccessfulCreate count=1 msg=Created pod: eval-sanitize-2-r4-051-bcxdv
51.0413,Job,MODIFIED,eval-sanitize-2-r4-051,
51.043,Job,MODIFIED,eval-sanitize-2-r4-050,
51.0447,Event,ADDED,eval-sanitize-2-r4-051-bcxdv.18d3d1db4f50c4fb,"reason=FailedScheduling count=None msg=0/6 nodes are available: 1 c_wall violated: 1 conflicting context pair(s) with node memory, 5 node(s) had untolerated taint(s). no new claims to deallocate, preemption: 0/6 nodes are available: 1 No preemption victims found for incoming pod, 5 Preemption is not helpful for scheduling."
51.0457,Pod,MODIFIED,eval-sanitize-2-r4-051-bcxdv,phase=Pending node=None
51.0465,TaskRequest,MODIFIED,eval-sanitize-2-r4-051,phase=Scheduled job=None
51.0524,Job,MODIFIED,eval-sanitize-2-r4-050,
51.0533,Event,ADDED,eval-sanitize-2-r4-051-bcxdv.18d3d1db4fecc272,"reason=FailedScheduling count=None msg=0/6 nodes are available: 1 c_wall violated: 1 conflicting context pair(s) with node memory, 5 node(s) had untolerated taint(s). no new claims to deallocate, preemption: 0/6 nodes are available: 1 No preemption victims found for incoming pod, 5 Preemption is not helpful for scheduling."
51.78,Node,MODIFIED,kind-worker3,taints=1
51.785,Pod,MODIFIED,eval-sanitize-2-r4-048-l42kt,phase=Pending node=None
51.79,Pod,MODIFIED,eval-sanitize-2-r4-049-2mqtp,phase=Pending node=None
51.7943,Pod,MODIFIED,eval-sanitize-2-r4-047-567wm,phase=Pending node=None
51.7985,Pod,MODIFIED,eval-sanitize-2-r4-050-r2sx8,phase=Pending node=None
51.8031,Pod,MODIFIED,eval-sanitize-2-r4-051-bcxdv,phase=Pending node=None
51.8034,Event,MODIFIED,eval-sanitize-2-r4-051-bcxdv.18d3d1db4fecc272,"reason=FailedScheduling count=None msg=0/6 nodes are available: 1 c_wall violated: 1 conflicting context pair(s) with node memory, 5 node(s) had untolerated taint(s). no new claims to deallocate, preemption: 0/6 nodes are available: 1 No preemption victims found for incoming pod, 5 Preemption is not helpful for scheduling."
51.8561,Node,MODIFIED,kind-worker3,taints=1
51.8703,Job,MODIFIED,eval-sanitize-2-r4-046,
51.8795,Job,MODIFIED,eval-sanitize-2-r4-046,
52.0081,TaskRequest,ADDED,eval-sanitize-2-r4-052,phase=None job=None
52.013,TaskRequest,MODIFIED,eval-sanitize-2-r4-052,phase=Pending job=None
52.0264,Job,ADDED,eval-sanitize-2-r4-052,
52.033,Pod,ADDED,eval-sanitize-2-r4-052-v8g6t,phase=Pending node=None
52.0342,TaskRequest,MODIFIED,eval-sanitize-2-r4-052,phase=Scheduled job=None
52.0349,Job,MODIFIED,eval-sanitize-2-r4-052,
52.0386,Event,ADDED,eval-sanitize-2-r4-052.18d3d1db8a88e8e2,reason=SuccessfulCreate count=1 msg=Created pod: eval-sanitize-2-r4-052-v8g6t
52.0388,Event,ADDED,eval-sanitize-2-r4-052-v8g6t.18d3d1db8a939937,"reason=FailedScheduling count=None msg=0/6 nodes are available: 6 node(s) had untolerated taint(s). no new claims to deallocate, preemption: 0/6 nodes are available: 6 Preemption is not helpful for scheduling."
52.0395,Job,MODIFIED,eval-sanitize-2-r4-051,
52.0403,Pod,MODIFIED,eval-sanitize-2-r4-052-v8g6t,phase=Pending node=None
52.0426,TaskRequest,MODIFIED,eval-sanitize-2-r4-052,phase=Scheduled job=None
52.0484,Job,MODIFIED,eval-sanitize-2-r4-051,
53.0107,TaskRequest,ADDED,eval-sanitize-2-r4-053,phase=None job=None
53.0162,TaskRequest,MODIFIED,eval-sanitize-2-r4-053,phase=Pending job=None
53.0312,Job,ADDED,eval-sanitize-2-r4-053,
53.038,Pod,ADDED,eval-sanitize-2-r4-053-h944b,phase=Pending node=None
53.0396,TaskRequest,MODIFIED,eval-sanitize-2-r4-053,phase=Scheduled job=None
53.0406,Job,MODIFIED,eval-sanitize-2-r4-052,
53.0421,Job,MODIFIED,eval-sanitize-2-r4-053,
53.0443,Event,ADDED,eval-sanitize-2-r4-053.18d3d1dbc6731247,reason=SuccessfulCreate count=1 msg=Created pod: eval-sanitize-2-r4-053-h944b
53.0445,Event,ADDED,eval-sanitize-2-r4-053-h944b.18d3d1dbc67cbf3f,"reason=FailedScheduling count=None msg=0/6 nodes are available: 6 node(s) had untolerated taint(s). no new claims to deallocate, preemption: 0/6 nodes are available: 6 Preemption is not helpful for scheduling."
53.0455,Pod,MODIFIED,eval-sanitize-2-r4-053-h944b,phase=Pending node=None
53.0504,TaskRequest,MODIFIED,eval-sanitize-2-r4-053,phase=Scheduled job=None
53.0529,Job,MODIFIED,eval-sanitize-2-r4-052,
54.0126,TaskRequest,ADDED,eval-sanitize-2-r4-054,phase=None job=None
54.0166,TaskRequest,MODIFIED,eval-sanitize-2-r4-054,phase=Pending job=None
54.0326,Job,ADDED,eval-sanitize-2-r4-054,
54.0383,Pod,ADDED,eval-sanitize-2-r4-054-bp59m,phase=Pending node=None
54.0392,TaskRequest,MODIFIED,eval-sanitize-2-r4-054,phase=Scheduled job=None
54.0409,Job,MODIFIED,eval-sanitize-2-r4-054,
54.0431,Job,MODIFIED,eval-sanitize-2-r4-053,
54.045,Event,ADDED,eval-sanitize-2-r4-054.18d3d1dc0210ee3a,reason=SuccessfulCreate count=1 msg=Created pod: eval-sanitize-2-r4-054-bp59m
54.0454,Event,ADDED,eval-sanitize-2-r4-054-bp59m.18d3d1dc021f82b1,"reason=FailedScheduling count=None msg=0/6 nodes are available: 6 node(s) had untolerated taint(s). no new claims to deallocate, preemption: 0/6 nodes are available: 6 Preemption is not helpful for scheduling."
54.0463,Pod,MODIFIED,eval-sanitize-2-r4-054-bp59m,phase=Pending node=None
54.047,TaskRequest,MODIFIED,eval-sanitize-2-r4-054,phase=Scheduled job=None
54.0496,Job,MODIFIED,eval-sanitize-2-r4-054,
54.0518,Job,MODIFIED,eval-sanitize-2-r4-053,
54.058,Job,MODIFIED,eval-sanitize-2-r4-054,
54.0815,Pod,MODIFIED,eval-sanitize-2-r4-037-r774c,phase=Running node=kind-worker
54.0877,Pod,MODIFIED,eval-sanitize-2-r4-034-bjrp7,phase=Running node=kind-worker
55.0121,TaskRequest,ADDED,eval-sanitize-2-r4-055,phase=None job=None
55.0156,TaskRequest,MODIFIED,eval-sanitize-2-r4-055,phase=Pending job=None
55.0314,Job,ADDED,eval-sanitize-2-r4-055,
55.0364,TaskRequest,MODIFIED,eval-sanitize-2-r4-055,phase=Scheduled job=None
55.0397,Pod,ADDED,eval-sanitize-2-r4-055-dkvq4,phase=Pending node=None
55.0422,Job,MODIFIED,eval-sanitize-2-r4-055,
55.0451,Pod,MODIFIED,eval-sanitize-2-r4-055-dkvq4,phase=Pending node=None
55.0462,TaskRequest,MODIFIED,eval-sanitize-2-r4-055,phase=Scheduled job=None
55.0466,Event,ADDED,eval-sanitize-2-r4-055.18d3d1dc3dc46ab5,reason=SuccessfulCreate count=1 msg=Created pod: eval-sanitize-2-r4-055-dkvq4
55.0469,Event,ADDED,eval-sanitize-2-r4-055-dkvq4.18d3d1dc3dceb04f,"reason=FailedScheduling count=None msg=0/6 nodes are available: 6 node(s) had untolerated taint(s). no new claims to deallocate, preemption: 0/6 nodes are available: 6 Preemption is not helpful for scheduling."
55.0927,Job,MODIFIED,eval-sanitize-2-r4-037,
55.0944,Job,MODIFIED,eval-sanitize-2-r4-034,
55.1037,Job,MODIFIED,eval-sanitize-2-r4-037,
55.1079,Job,MODIFIED,eval-sanitize-2-r4-034,
55.2257,Pod,MODIFIED,eval-sanitize-2-r4-034-bjrp7,phase=Succeeded node=kind-worker
55.2668,Pod,MODIFIED,eval-sanitize-2-r4-037-r774c,phase=Succeeded node=kind-worker
55.3396,Pod,MODIFIED,eval-sanitize-2-r4-040-j9n9j,phase=Running node=kind-worker2
55.3473,Pod,MODIFIED,eval-sanitize-2-r4-043-rpkcz,phase=Running node=kind-worker2
55.3535,Pod,MODIFIED,eval-sanitize-2-r4-044-w9bj4,phase=Running node=kind-worker2
55.3594,Pod,MODIFIED,eval-sanitize-2-r4-041-d4w9s,phase=Running node=kind-worker2
55.8643,Node,MODIFIED,kind-worker,taints=1
55.9344,Pod,MODIFIED,eval-sanitize-2-r4-045-z8fq4,phase=Running node=kind-worker4
55.9405,Pod,MODIFIED,eval-sanitize-2-r4-042-2k9sd,phase=Running node=kind-worker4
55.9471,Pod,MODIFIED,eval-sanitize-2-r4-038-2gqdk,phase=Running node=kind-worker4
55.9502,Node,MODIFIED,kind-worker,taints=0
55.9557,Pod,MODIFIED,eval-sanitize-2-r4-048-l42kt,phase=Pending node=kind-worker
55.959,Node,MODIFIED,kind-worker,taints=0
55.9614,Event,ADDED,eval-sanitize-2-r4-049-2mqtp.18d3d1dc744b5b3d,"reason=FailedScheduling count=None msg=0/6 nodes are available: 1 c_wall violated: 1 conflicting context pair(s) with node memory, 5 node(s) had untolerated taint(s). no new claims to deallocate, preemption: 0/6 nodes are available: 1 No preemption victims found for incoming pod, 5 Preemption is not helpful for scheduling."
55.9624,Pod,MODIFIED,eval-sanitize-2-r4-049-2mqtp,phase=Pending node=None
55.9627,Event,ADDED,eval-sanitize-2-r4-048-l42kt.18d3d1dc74552cf6,reason=Scheduled count=None msg=Successfully assigned compute/eval-sanitize-2-r4-048-l42kt to kind-worker
55.9675,Pod,MODIFIED,eval-sanitize-2-r4-048-l42kt,phase=Pending node=kind-worker
55.9699,Node,MODIFIED,kind-worker,taints=0
55.9705,Event,ADDED,eval-sanitize-2-r4-047-567wm.18d3d1dc74f24972,"reason=FailedScheduling count=None msg=0/6 nodes are available: 1 c_wall violated: 1 conflicting context pair(s) with node memory, 5 node(s) had untolerated taint(s). no new claims to deallocate, preemption: 0/6 nodes are available: 1 No preemption victims found for incoming pod, 5 Preemption is not helpful for scheduling."
55.9714,Pod,MODIFIED,eval-sanitize-2-r4-047-567wm,phase=Pending node=None
55.9791,Pod,MODIFIED,eval-sanitize-2-r4-050-r2sx8,phase=Pending node=None
55.9795,Event,ADDED,eval-sanitize-2-r4-050-r2sx8.18d3d1dc757c4d94,"reason=FailedScheduling count=None msg=0/6 nodes are available: 1 c_wall violated: 1 conflicting context pair(s) with node memory, 5 node(s) had untolerated taint(s). no new claims to deallocate, preemption: 0/6 nodes are available: 1 No preemption victims found for incoming pod, 5 Preemption is not helpful for scheduling."
55.9834,Node,MODIFIED,kind-worker,taints=0
55.988,Pod,MODIFIED,eval-sanitize-2-r4-051-bcxdv,phase=Pending node=kind-worker
55.9912,Pod,MODIFIED,eval-sanitize-2-r4-052-v8g6t,phase=Pending node=None
55.9919,Event,ADDED,eval-sanitize-2-r4-052-v8g6t.18d3d1dc76228908,"reason=FailedScheduling count=None msg=0/6 nodes are available: 1 c_wall violated: 1 conflicting context pair(s) with node memory, 5 node(s) had untolerated taint(s). no new claims to deallocate, preemption: 0/6 nodes are available: 1 No preemption victims found for incoming pod, 5 Preemption is not helpful for scheduling."
55.9921,Event,ADDED,eval-sanitize-2-r4-051-bcxdv.18d3d1dc763f9aff,reason=Scheduled count=None msg=Successfully assigned compute/eval-sanitize-2-r4-051-bcxdv to kind-worker
55.9976,Node,MODIFIED,kind-worker,taints=0
56.0022,Pod,MODIFIED,eval-sanitize-2-r4-053-h944b,phase=Pending node=None
56.0035,Pod,MODIFIED,eval-sanitize-2-r4-051-bcxdv,phase=Pending node=kind-worker
56.0038,Event,ADDED,eval-sanitize-2-r4-053-h944b.18d3d1dc76bd15a8,"reason=FailedScheduling count=None msg=0/6 nodes are available: 1 c_wall violated: 2 conflicting context pair(s) with node memory, 5 node(s) had untolerated taint(s). no new claims to deallocate, preemption: 0/6 nodes are available: 1 No preemption victims found for incoming pod, 5 Preemption is not helpful for scheduling."
56.0078,TaskRequest,ADDED,eval-sanitize-2-r4-056,phase=None job=None
56.0136,TaskRequest,MODIFIED,eval-sanitize-2-r4-056,phase=Pending job=None
56.0179,Pod,MODIFIED,eval-sanitize-2-r4-054-bp59m,phase=Pending node=None
56.0184,Event,ADDED,eval-sanitize-2-r4-054-bp59m.18d3d1dc77d33faa,"reason=FailedScheduling count=None msg=0/6 nodes are available: 1 c_wall violated: 2 conflicting context pair(s) with node memory, 5 node(s) had untolerated taint(s). no new claims to deallocate, preemption: 0/6 nodes are available: 1 No preemption victims found for incoming pod, 5 Preemption is not helpful for scheduling."
56.023,Node,MODIFIED,kind-worker,taints=0
56.0255,Pod,MODIFIED,eval-sanitize-2-r4-055-dkvq4,phase=Pending node=None
56.0258,Event,ADDED,eval-sanitize-2-r4-055-dkvq4.18d3d1dc7843d141,"reason=FailedScheduling count=None msg=0/6 nodes are available: 1 c_wall violated: 1 conflicting context pair(s) with node memory, 5 node(s) had untolerated taint(s). no new claims to deallocate, preemption: 0/6 nodes are available: 1 No preemption victims found for incoming pod, 5 Preemption is not helpful for scheduling."
56.0314,Event,ADDED,eval-sanitize-2-r4-049-2mqtp.18d3d1dc78b5b629,"reason=FailedScheduling count=None msg=0/6 nodes are available: 1 c_wall violated: 1 conflicting context pair(s) with node memory, 5 node(s) had untolerated taint(s). no new claims to deallocate, preemption: 0/6 nodes are available: 1 No preemption victims found for incoming pod, 5 Preemption is not helpful for scheduling."
56.0462,Job,ADDED,eval-sanitize-2-r4-056,
56.0482,Job,MODIFIED,eval-sanitize-2-r4-055,
56.0519,Node,MODIFIED,kind-worker,taints=0
56.0525,TaskRequest,MODIFIED,eval-sanitize-2-r4-056,phase=Scheduled job=None
56.0535,Pod,ADDED,eval-sanitize-2-r4-056-tb4xl,phase=Pending node=None
56.0553,Job,MODIFIED,eval-sanitize-2-r4-056,
56.0579,Event,ADDED,eval-sanitize-2-r4-056.18d3d1dc7a36559c,reason=SuccessfulCreate count=1 msg=Created pod: eval-sanitize-2-r4-056-tb4xl
56.0594,TaskRequest,MODIFIED,eval-sanitize-2-r4-056,phase=Scheduled job=None
56.0623,Job,MODIFIED,eval-sanitize-2-r4-055,
56.0913,Event,ADDED,eval-sanitize-2-r4-047-567wm.18d3d1dc7bce692f,"reason=FailedScheduling count=None msg=0/6 nodes are available: 1 c_wall violated: 1 conflicting context pair(s) with node memory, 5 node(s) had untolerated taint(s). no new claims to deallocate, preemption: 0/6 nodes are available: 1 No preemption victims found for incoming pod, 5 Preemption is not helpful for scheduling."
56.0941,Event,ADDED,eval-sanitize-2-r4-056-tb4xl.18d3d1dc7c08f4f1,"reason=FailedScheduling count=None msg=0/6 nodes are available: 1 c_wall violated: 2 conflicting context pair(s) with node memory, 5 node(s) had untolerated taint(s). no new claims to deallocate, preemption: 0/6 nodes are available: 1 No preemption victims found for incoming pod, 5 Preemption is not helpful for scheduling."
56.0951,Pod,MODIFIED,eval-sanitize-2-r4-056-tb4xl,phase=Pending node=None
56.0984,Job,MODIFIED,eval-sanitize-2-r4-037,
56.1009,Job,MODIFIED,eval-sanitize-2-r4-034,
56.1015,Event,ADDED,eval-sanitize-2-r4-050-r2sx8.18d3d1dc7cdb63b7,"reason=FailedScheduling count=None msg=0/6 nodes are available: 1 c_wall violated: 1 conflicting context pair(s) with node memory, 5 node(s) had untolerated taint(s). no new claims to deallocate, preemption: 0/6 nodes are available: 1 No preemption victims found for incoming pod, 5 Preemption is not helpful for scheduling."
56.1042,Event,ADDED,eval-sanitize-2-r4-052-v8g6t.18d3d1dc7d08c917,"reason=FailedScheduling count=None msg=0/6 nodes are available: 1 c_wall violated: 1 conflicting context pair(s) with node memory, 5 node(s) had untolerated taint(s). no new claims to deallocate, preemption: 0/6 nodes are available: 1 No preemption victims found for incoming pod, 5 Preemption is not helpful for scheduling."
56.1076,Pod,MODIFIED,eval-sanitize-2-r4-037-r774c,phase=Succeeded node=kind-worker
56.109,Job,MODIFIED,eval-sanitize-2-r4-037,
56.1107,Pod,MODIFIED,eval-sanitize-2-r4-034-bjrp7,phase=Succeeded node=kind-worker
56.1116,Job,MODIFIED,eval-sanitize-2-r4-034,
56.1188,Event,ADDED,eval-sanitize-2-r4-053-h944b.18d3d1dc7de4eb47,"reason=FailedScheduling count=None msg=0/6 nodes are available: 1 c_wall violated: 2 conflicting context pair(s) with node memory, 5 node(s) had untolerated taint(s). no new claims to deallocate, preemption: 0/6 nodes are available: 1 No preemption victims found for incoming pod, 5 Preemption is not helpful for scheduling."
56.1208,Event,ADDED,eval-sanitize-2-r4-054-bp59m.18d3d1dc7e0da287,"reason=FailedScheduling count=None msg=0/6 nodes are available: 1 c_wall violated: 2 conflicting context pair(s) with node memory, 5 node(s) had untolerated taint(s). no new claims to deallocate, preemption: 0/6 nodes are available: 1 No preemption victims found for incoming pod, 5 Preemption is not helpful for scheduling."
56.1234,Event,ADDED,eval-sanitize-2-r4-055-dkvq4.18d3d1dc7e3604f1,"reason=FailedScheduling count=None msg=0/6 nodes are available: 1 c_wall violated: 1 conflicting context pair(s) with node memory, 5 node(s) had untolerated taint(s). no new claims to deallocate, preemption: 0/6 nodes are available: 1 No preemption victims found for incoming pod, 5 Preemption is not helpful for scheduling."
56.1283,Event,MODIFIED,eval-sanitize-2-r4-049-2mqtp.18d3d1dc78b5b629,"reason=FailedScheduling count=None msg=0/6 nodes are available: 1 c_wall violated: 1 conflicting context pair(s) with node memory, 5 node(s) had untolerated taint(s). no new claims to deallocate, preemption: 0/6 nodes are available: 1 No preemption victims found for incoming pod, 5 Preemption is not helpful for scheduling."
56.1881,Event,MODIFIED,eval-sanitize-2-r4-047-567wm.18d3d1dc7bce692f,"reason=FailedScheduling count=None msg=0/6 nodes are available: 1 c_wall violated: 1 conflicting context pair(s) with node memory, 5 node(s) had untolerated taint(s). no new claims to deallocate, preemption: 0/6 nodes are available: 1 No preemption victims found for incoming pod, 5 Preemption is not helpful for scheduling."
56.1889,Event,ADDED,eval-sanitize-2-r4-056-tb4xl.18d3d1dc82041aa0,"reason=FailedScheduling count=None msg=0/6 nodes are available: 1 c_wall violated: 2 conflicting context pair(s) with node memory, 5 node(s) had untolerated taint(s). no new claims to deallocate, preemption: 0/6 nodes are available: 1 No preemption victims found for incoming pod, 5 Preemption is not helpful for scheduling."
56.3442,Job,MODIFIED,eval-sanitize-2-r4-040,
56.3503,Job,MODIFIED,eval-sanitize-2-r4-043,
56.3542,Job,MODIFIED,eval-sanitize-2-r4-040,
56.3597,Job,MODIFIED,eval-sanitize-2-r4-044,
56.3628,Job,MODIFIED,eval-sanitize-2-r4-043,
56.3651,Job,MODIFIED,eval-sanitize-2-r4-041,
56.3723,Job,MODIFIED,eval-sanitize-2-r4-044,
56.3748,Job,MODIFIED,eval-sanitize-2-r4-041,
56.4769,Event,ADDED,eval-sanitize-2-r4-048-l42kt.18d3d1dc92ee51a0,"reason=Pulled count=1 msg=Container image ""busybox:musl"" already present on machine"
56.4825,Event,ADDED,eval-sanitize-2-r4-051-bcxdv.18d3d1dc9349aa27,"reason=Pulled count=1 msg=Container image ""busybox:musl"" already present on machine"
56.5008,Event,ADDED,eval-sanitize-2-r4-048-l42kt.18d3d1dc949f36c9,reason=Created count=1 msg=Created container: task
56.5051,Event,ADDED,eval-sanitize-2-r4-051-bcxdv.18d3d1dc94d2268c,reason=Created count=1 msg=Created container: task
56.5603,Pod,MODIFIED,eval-sanitize-2-r4-044-w9bj4,phase=Succeeded node=kind-worker2
56.5706,Event,MODIFIED,eval-sanitize-2-r4-050-r2sx8.18d3d1dc7cdb63b7,"reason=FailedScheduling count=None msg=0/6 nodes are available: 1 c_wall violated: 1 conflicting context pair(s) with node memory, 5 node(s) had untolerated taint(s). no new claims to deallocate, preemption: 0/6 nodes are available: 1 No preemption victims found for incoming pod, 5 Preemption is not helpful for scheduling."
56.5736,Event,MODIFIED,eval-sanitize-2-r4-052-v8g6t.18d3d1dc7d08c917,"reason=FailedScheduling count=None msg=0/6 nodes are available: 1 c_wall violated: 1 conflicting context pair(s) with node memory, 5 node(s) had untolerated taint(s). no new claims to deallocate, preemption: 0/6 nodes are available: 1 No preemption victims found for incoming pod, 5 Preemption is not helpful for scheduling."
56.5752,Event,ADDED,eval-sanitize-2-r4-048-l42kt.18d3d1dc991d0642,reason=Started count=1 msg=Started container task
56.5787,Event,MODIFIED,eval-sanitize-2-r4-053-h944b.18d3d1dc7de4eb47,"reason=FailedScheduling count=None msg=0/6 nodes are available: 1 c_wall violated: 2 conflicting context pair(s) with node memory, 5 node(s) had untolerated taint(s). no new claims to deallocate, preemption: 0/6 nodes are available: 1 No preemption victims found for incoming pod, 5 Preemption is not helpful for scheduling."
56.5802,Pod,MODIFIED,eval-sanitize-2-r4-041-d4w9s,phase=Succeeded node=kind-worker2
56.5806,Event,MODIFIED,eval-sanitize-2-r4-054-bp59m.18d3d1dc7e0da287,"reason=FailedScheduling count=None msg=0/6 nodes are available: 1 c_wall violated: 2 conflicting context pair(s) with node memory, 5 node(s) had untolerated taint(s). no new claims to deallocate, preemption: 0/6 nodes are available: 1 No preemption victims found for incoming pod, 5 Preemption is not helpful for scheduling."
56.5813,Event,ADDED,eval-sanitize-2-r4-051-bcxdv.18d3d1dc9963537d,reason=Started count=1 msg=Started container task
56.5824,Event,MODIFIED,eval-sanitize-2-r4-055-dkvq4.18d3d1dc7e3604f1,"reason=FailedScheduling count=None msg=0/6 nodes are available: 1 c_wall violated: 1 conflicting context pair(s) with node memory, 5 node(s) had untolerated taint(s). no new claims to deallocate, preemption: 0/6 nodes are available: 1 No preemption victims found for incoming pod, 5 Preemption is not helpful for scheduling."
56.5867,Pod,MODIFIED,eval-sanitize-2-r4-040-j9n9j,phase=Succeeded node=kind-worker2
56.5931,Pod,MODIFIED,eval-sanitize-2-r4-043-rpkcz,phase=Succeeded node=kind-worker2
56.6267,Event,MODIFIED,eval-sanitize-2-r4-056-tb4xl.18d3d1dc82041aa0,"reason=FailedScheduling count=None msg=0/6 nodes are available: 1 c_wall violated: 2 conflicting context pair(s) with node memory, 5 node(s) had untolerated taint(s). no new claims to deallocate, preemption: 0/6 nodes are available: 1 No preemption victims found for incoming pod, 5 Preemption is not helpful for scheduling."
56.866,Node,MODIFIED,kind-worker2,taints=1
56.8773,Node,MODIFIED,kind-worker2,taints=1
56.8855,Node,MODIFIED,kind-worker2,taints=0
56.8932,Pod,MODIFIED,eval-sanitize-2-r4-056-tb4xl,phase=Pending node=kind-worker2
56.8989,Event,ADDED,eval-sanitize-2-r4-056-tb4xl.18d3d1dcac3ac21b,reason=Scheduled count=None msg=Successfully assigned compute/eval-sanitize-2-r4-056-tb4xl to kind-worker2
56.9026,Node,MODIFIED,kind-worker2,taints=0
56.9045,Pod,MODIFIED,eval-sanitize-2-r4-056-tb4xl,phase=Pending node=kind-worker2
56.9113,Pod,MODIFIED,eval-sanitize-2-r4-039-62vq7,phase=Running node=kind-worker5
56.9254,Pod,MODIFIED,eval-sanitize-2-r4-050-r2sx8,phase=Pending node=kind-worker2
56.9312,Pod,MODIFIED,eval-sanitize-2-r4-052-v8g6t,phase=Pending node=None
56.9315,Event,ADDED,eval-sanitize-2-r4-050-r2sx8.18d3d1dcae28ab35,reason=Scheduled count=None msg=Successfully assigned compute/eval-sanitize-2-r4-050-r2sx8 to kind-worker2
56.9355,Node,MODIFIED,kind-worker2,taints=0
56.9378,Pod,MODIFIED,eval-sanitize-2-r4-050-r2sx8,phase=Pending node=kind-worker2
56.9415,Job,MODIFIED,eval-sanitize-2-r4-045,
56.9451,Job,MODIFIED,eval-sanitize-2-r4-042,
56.9514,Job,MODIFIED,eval-sanitize-2-r4-045,
56.953,Job,MODIFIED,eval-sanitize-2-r4-038,
56.955,Job,MODIFIED,eval-sanitize-2-r4-042,
56.9587,Node,MODIFIED,kind-worker2,taints=0
56.9631,Job,MODIFIED,eval-sanitize-2-r4-038,
56.9715,Node,MODIFIED,kind-worker2,taints=0
57.0094,TaskRequest,ADDED,eval-sanitize-2-r4-057,phase=None job=None
57.0131,TaskRequest,MODIFIED,eval-sanitize-2-r4-057,phase=Pending job=None
57.0205,Pod,MODIFIED,eval-sanitize-2-r4-053-h944b,phase=Pending node=None
57.0291,Job,ADDED,eval-sanitize-2-r4-057,
57.0323,Pod,MODIFIED,eval-sanitize-2-r4-054-bp59m,phase=Pending node=kind-worker2
57.0338,Pod,MODIFIED,eval-sanitize-2-r4-042-2k9sd,phase=Succeeded node=kind-worker4
57.0358,Pod,ADDED,eval-sanitize-2-r4-057-58mc5,phase=Pending node=None
57.0393,Event,ADDED,eval-sanitize-2-r4-054-bp59m.18d3d1dcb47c9713,reason=Scheduled count=None msg=Successfully assigned compute/eval-sanitize-2-r4-054-bp59m to kind-worker2
57.0394,TaskRequest,MODIFIED,eval-sanitize-2-r4-057,phase=Scheduled job=None
57.0404,Pod,MODIFIED,eval-sanitize-2-r4-055-dkvq4,phase=Pending node=None
57.0431,Event,ADDED,eval-sanitize-2-r4-057.18d3d1dcb4c3cfc6,reason=SuccessfulCreate count=1 msg=Created pod: eval-sanitize-2-r4-057-58mc5
57.044,Job,MODIFIED,eval-sanitize-2-r4-057,
57.0472,TaskRequest,MODIFIED,eval-sanitize-2-r4-057,phase=Scheduled job=None
57.0504,Pod,MODIFIED,eval-sanitize-2-r4-054-bp59m,phase=Pending node=kind-worker2
57.0588,Job,MODIFIED,eval-sanitize-2-r4-056,
57.0677,Job,MODIFIED,eval-sanitize-2-r4-056,
57.0706,Pod,MODIFIED,eval-sanitize-2-r4-045-z8fq4,phase=Succeeded node=kind-worker4
57.077,Pod,MODIFIED,eval-sanitize-2-r4-038-2gqdk,phase=Succeeded node=kind-worker4
57.0895,Pod,MODIFIED,eval-sanitize-2-r4-057-58mc5,phase=Pending node=kind-worker
57.0959,Pod,MODIFIED,eval-sanitize-2-r4-048-l42kt,phase=Running node=kind-worker
57.0962,Event,ADDED,eval-sanitize-2-r4-057-58mc5.18d3d1dcb7efb92b,reason=Scheduled count=None msg=Successfully assigned compute/eval-sanitize-2-r4-057-58mc5 to kind-worker
57.1016,Pod,MODIFIED,eval-sanitize-2-r4-057-58mc5,phase=Pending node=kind-worker
57.1029,Job,MODIFIED,eval-sanitize-2-r4-037,
57.1052,Job,MODIFIED,eval-sanitize-2-r4-034,
57.1074,Job,MODIFIED,eval-sanitize-2-r4-037,
57.1095,Job,MODIFIED,eval-sanitize-2-r4-034,
57.111,Pod,MODIFIED,eval-sanitize-2-r4-051-bcxdv,phase=Running node=kind-worker
57.113,Event,ADDED,eval-sanitize-2-r4-037.18d3d1dcb905dbf5,reason=Completed count=1 msg=Job completed
57.1185,Job,MODIFIED,eval-sanitize-2-r4-037,
57.1198,Event,ADDED,eval-sanitize-2-r4-034.18d3d1dcb922f819,reason=Completed count=1 msg=Job completed
57.1208,Job,MODIFIED,eval-sanitize-2-r4-034,
57.1228,Pod,MODIFIED,eval-sanitize-2-r4-049-2mqtp,phase=Pending node=None
57.124,TaskRequest,MODIFIED,eval-sanitize-2-r4-037,phase=Complete job=None
57.128,TaskRequest,MODIFIED,eval-sanitize-2-r4-034,phase=Complete job=None
57.1336,Pod,MODIFIED,eval-sanitize-2-r4-047-567wm,phase=Pending node=None
57.135,Job,MODIFIED,eval-sanitize-2-r4-037,
57.1369,Job,MODIFIED,eval-sanitize-2-r4-034,
57.1884,Event,ADDED,eval-sanitize-2-r4-052-v8g6t.18d3d1dcbd8abc76,"reason=FailedScheduling count=None msg=0/6 nodes are available: 1 c_wall violated: 1 conflicting context pair(s) with node memory, 1 c_wall violated: 2 conflicting context pair(s) with node memory, 4 node(s) had untolerated taint(s). no new claims to deallocate, preemption: 0/6 nodes are available: 2 No preemption victims found for incoming pod, 4 Preemption is not helpful for scheduling."
57.2224,Event,ADDED,eval-sanitize-2-r4-053-h944b.18d3d1dcbf90f5a1,"reason=FailedScheduling count=None msg=0/6 nodes are available: 1 c_wall violated: 1 conflicting context pair(s) with node memory, 1 c_wall violated: 2 conflicting context pair(s) with node memory, 4 node(s) had untolerated taint(s). no new claims to deallocate, preemption: 0/6 nodes are available: 2 No preemption victims found for incoming pod, 4 Preemption is not helpful for scheduling."
57.2274,Event,ADDED,eval-sanitize-2-r4-055-dkvq4.18d3d1dcbfe93501,"reason=FailedScheduling count=None msg=0/6 nodes are available: 1 c_wall violated: 1 conflicting context pair(s) with node memory, 1 c_wall violated: 2 conflicting context pair(s) with node memory, 4 node(s) had untolerated taint(s). no new claims to deallocate, preemption: 0/6 nodes are available: 2 No preemption victims found for incoming pod, 4 Preemption is not helpful for scheduling."
57.2905,Event,ADDED,eval-sanitize-2-r4-049-2mqtp.18d3d1dcc3915963,"reason=FailedScheduling count=None msg=0/6 nodes are available: 2 c_wall violated: 1 conflicting context pair(s) with node memory, 4 node(s) had untolerated taint(s). no new claims to deallocate, preemption: 0/6 nodes are available: 2 No preemption victims found for incoming pod, 4 Preemption is not helpful for scheduling."
57.318,Event,ADDED,eval-sanitize-2-r4-056-tb4xl.18d3d1dcc54d4f87,"reason=Pulled count=1 msg=Container image ""busybox:musl"" already present on machine"
57.3255,Event,ADDED,eval-sanitize-2-r4-047-567wm.18d3d1dcc59ca90d,"reason=FailedScheduling count=None msg=0/6 nodes are available: 2 c_wall violated: 1 conflicting context pair(s) with node memory, 4 node(s) had untolerated taint(s). no new claims to deallocate, preemption: 0/6 nodes are available: 2 No preemption victims found for incoming pod, 4 Preemption is not helpful for scheduling."
57.3392,Event,ADDED,eval-sanitize-2-r4-056-tb4xl.18d3d1dcc6931f6c,reason=Created count=1 msg=Created container: task
57.3534,Job,MODIFIED,eval-sanitize-2-r4-040,
57.3571,Job,MODIFIED,eval-sanitize-2-r4-043,
57.3576,Event,ADDED,eval-sanitize-2-r4-050-r2sx8.18d3d1dcc7a7ee70,"reason=Pulled count=1 msg=Container image ""busybox:musl"" already present on machine"
57.3647,Pod,MODIFIED,eval-sanitize-2-r4-040-j9n9j,phase=Succeeded node=kind-worker2
57.3672,Job,MODIFIED,eval-sanitize-2-r4-040,
57.3735,Pod,MODIFIED,eval-sanitize-2-r4-043-rpkcz,phase=Succeeded node=kind-worker2
57.3743,Job,MODIFIED,eval-sanitize-2-r4-044,
57.376,Job,MODIFIED,eval-sanitize-2-r4-043,
57.377,Job,MODIFIED,eval-sanitize-2-r4-041,
57.3909,Pod,MODIFIED,eval-sanitize-2-r4-044-w9bj4,phase=Succeeded node=kind-worker2
57.3953,Pod,MODIFIED,eval-sanitize-2-r4-041-d4w9s,phase=Succeeded node=kind-worker2
57.3965,Job,MODIFIED,eval-sanitize-2-r4-044,
57.3973,Job,MODIFIED,eval-sanitize-2-r4-041,
57.3981,Event,ADDED,eval-sanitize-2-r4-050-r2sx8.18d3d1dcc9ad71da,reason=Created count=1 msg=Created container: task
57.4704,Event,ADDED,eval-sanitize-2-r4-056-tb4xl.18d3d1dcce636bcd,reason=Started count=1 msg=Started container task
57.4838,Event,ADDED,eval-sanitize-2-r4-050-r2sx8.18d3d1dccf2474c7,reason=Started count=1 msg=Started container task
57.4969,Event,ADDED,eval-sanitize-2-r4-054-bp59m.18d3d1dccffc23e2,"reason=Pulled count=1 msg=Container image ""busybox:musl"" already present on machine"
57.5164,Event,ADDED,eval-sanitize-2-r4-054-bp59m.18d3d1dcd11ae464,reason=Created count=1 msg=Created container: task
57.5286,Event,ADDED,eval-sanitize-2-r4-057-58mc5.18d3d1dcd1e57cfd,"reason=Pulled count=1 msg=Container image ""busybox:musl"" already present on machine"
57.5485,Event,ADDED,eval-sanitize-2-r4-057-58mc5.18d3d1dcd2fe4a72,reason=Created count=1 msg=Created container: task
57.5492,Event,ADDED,eval-sanitize-2-r4-054-bp59m.18d3d1dcd31ce57c,reason=Started count=1 msg=Started container task
57.5613,Node,MODIFIED,kind-worker4,taints=1
57.5749,Node,MODIFIED,kind-worker4,taints=1
57.5753,Event,MODIFIED,eval-sanitize-2-r4-052-v8g6t.18d3d1dcbd8abc76,"reason=FailedScheduling count=None msg=0/6 nodes are available: 1 c_wall violated: 1 conflicting context pair(s) with node memory, 1 c_wall violated: 2 conflicting context pair(s) with node memory, 4 node(s) had untolerated taint(s). no new claims to deallocate, preemption: 0/6 nodes are available: 2 No preemption victims found for incoming pod, 4 Preemption is not helpful for scheduling."
57.5808,Event,MODIFIED,eval-sanitize-2-r4-053-h944b.18d3d1dcbf90f5a1,"reason=FailedScheduling count=None msg=0/6 nodes are available: 1 c_wall violated: 1 conflicting context pair(s) with node memory, 1 c_wall violated: 2 conflicting context pair(s) with node memory, 4 node(s) had untolerated taint(s). no new claims to deallocate, preemption: 0/6 nodes are available: 2 No preemption victims found for incoming pod, 4 Preemption is not helpful for scheduling."
57.5833,Event,ADDED,eval-sanitize-2-r4-057-58mc5.18d3d1dcd51969cd,reason=Started count=1 msg=Started container task
57.5848,Node,MODIFIED,kind-worker4,taints=0
57.5859,Event,MODIFIED,eval-sanitize-2-r4-055-dkvq4.18d3d1dcbfe93501,"reason=FailedScheduling count=None msg=0/6 nodes are available: 1 c_wall violated: 1 conflicting context pair(s) with node memory, 1 c_wall violated: 2 conflicting context pair(s) with node memory, 4 node(s) had untolerated taint(s). no new claims to deallocate, preemption: 0/6 nodes are available: 2 No preemption victims found for incoming pod, 4 Preemption is not helpful for scheduling."
57.6239,Event,MODIFIED,eval-sanitize-2-r4-049-2mqtp.18d3d1dcc3915963,"reason=FailedScheduling count=None msg=0/6 nodes are available: 2 c_wall violated: 1 conflicting context pair(s) with node memory, 4 node(s) had untolerated taint(s). no new claims to deallocate, preemption: 0/6 nodes are available: 2 No preemption victims found for incoming pod, 4 Preemption is not helpful for scheduling."
57.6259,Pod,MODIFIED,eval-sanitize-2-r4-047-567wm,phase=Pending node=kind-worker4
57.6305,Event,ADDED,eval-sanitize-2-r4-047-567wm.18d3d1dcd7e59d5a,reason=Scheduled count=None msg=Successfully assigned compute/eval-sanitize-2-r4-047-567wm to kind-worker4
57.6358,Node,MODIFIED,kind-worker4,taints=0
57.6375,Pod,MODIFIED,eval-sanitize-2-r4-047-567wm,phase=Pending node=kind-worker4
57.6529,Node,MODIFIED,kind-worker4,taints=0
57.6638,Node,MODIFIED,kind-worker4,taints=0
57.722,Pod,MODIFIED,eval-sanitize-2-r4-052-v8g6t,phase=Pending node=None
57.7362,Pod,MODIFIED,eval-sanitize-2-r4-053-h944b,phase=Pending node=None
57.8237,Pod,MODIFIED,eval-sanitize-2-r4-055-dkvq4,phase=Pending node=None
57.8392,Pod,MODIFIED,eval-sanitize-2-r4-049-2mqtp,phase=Pending node=kind-worker4
57.8423,Event,ADDED,eval-sanitize-2-r4-049-2mqtp.18d3d1dce49d95b9,reason=Scheduled count=None msg=Successfully assigned compute/eval-sanitize-2-r4-049-2mqtp to kind-worker4
57.8479,Pod,MODIFIED,eval-sanitize-2-r4-049-2mqtp,phase=Pending node=kind-worker4
57.9185,Job,MODIFIED,eval-sanitize-2-r4-039,
57.9222,Event,ADDED,eval-sanitize-2-r4-052-v8g6t.18d3d1dce952f714,"reason=FailedScheduling count=None msg=0/6 nodes are available: 1 c_wall violated: 2 conflicting context pair(s) with node memory, 2 c_wall violated: 1 conflicting context pair(s) with node memory, 3 node(s) had untolerated taint(s). no new claims to deallocate, preemption: 0/6 nodes are available: 3 No preemption victims found for incoming pod, 3 Preemption is not helpful for scheduling."
57.9283,Job,MODIFIED,eval-sanitize-2-r4-039,
57.9474,Job,MODIFIED,eval-sanitize-2-r4-045,
57.9515,Job,MODIFIED,eval-sanitize-2-r4-042,
57.9556,Pod,MODIFIED,eval-sanitize-2-r4-045-z8fq4,phase=Succeeded node=kind-worker4
57.9578,Job,MODIFIED,eval-sanitize-2-r4-045,
57.9595,Job,MODIFIED,eval-sanitize-2-r4-038,
57.9626,Job,MODIFIED,eval-sanitize-2-r4-042,
57.9645,Pod,MODIFIED,eval-sanitize-2-r4-042-2k9sd,phase=Succeeded node=kind-worker4
57.9687,Pod,MODIFIED,eval-sanitize-2-r4-038-2gqdk,phase=Succeeded node=kind-worker4
57.9736,Job,MODIFIED,eval-sanitize-2-r4-038,
57.9751,Node,MODIFIED,kind-worker,taints=1
57.9853,Event,ADDED,eval-sanitize-2-r4-053-h944b.18d3d1dced117448,"reason=FailedScheduling count=None msg=0/6 nodes are available: 1 c_wall violated: 2 conflicting context pair(s) with node memory, 2 c_wall violated: 1 conflicting context pair(s) with node memory, 3 node(s) had untolerated taint(s). no new claims to deallocate, preemption: 0/6 nodes are available: 3 No preemption victims found for incoming pod, 3 Preemption is not helpful for scheduling."
57.9917,Node,MODIFIED,kind-worker,taints=1
58.0067,TaskRequest,ADDED,eval-sanitize-2-r4-058,phase=None job=None
58.0102,TaskRequest,MODIFIED,eval-sanitize-2-r4-058,phase=Pending job=None
58.0232,Pod,MODIFIED,eval-sanitize-2-r4-055-dkvq4,phase=Pending node=None
58.0235,Event,ADDED,eval-sanitize-2-r4-055-dkvq4.18d3d1dcef4a631c,"reason=FailedScheduling count=None msg=0/6 nodes are available: 1 c_wall violated: 1 conflicting context pair(s) with node memory, 1 c_wall violated: 2 conflicting context pair(s) with node memory, 4 node(s) had untolerated taint(s). no new claims to deallocate, preemption: 0/6 nodes are available: 2 No preemption victims found for incoming pod, 4 Preemption is not helpful for scheduling."
58.0253,Job,ADDED,eval-sanitize-2-r4-058,
58.0332,Pod,ADDED,eval-sanitize-2-r4-058-qlc2v,phase=Pending node=None
58.0346,TaskRequest,MODIFIED,eval-sanitize-2-r4-058,phase=Scheduled job=None
58.0357,Pod,MODIFIED,eval-sanitize-2-r4-052-v8g6t,phase=Pending node=None
58.0371,Job,MODIFIED,eval-sanitize-2-r4-058,
58.0391,Event,ADDED,eval-sanitize-2-r4-058.18d3d1dcf03007d9,reason=SuccessfulCreate count=1 msg=Created pod: eval-sanitize-2-r4-058-qlc2v
58.0414,Event,MODIFIED,eval-sanitize-2-r4-052-v8g6t.18d3d1dce952f714,"reason=FailedScheduling count=None msg=0/6 nodes are available: 1 c_wall violated: 2 conflicting context pair(s) with node memory, 2 c_wall violated: 1 conflicting context pair(s) with node memory, 3 node(s) had untolerated taint(s). no new claims to deallocate, preemption: 0/6 nodes are available: 3 No preemption victims found for incoming pod, 3 Preemption is not helpful for scheduling."
58.0429,Pod,MODIFIED,eval-sanitize-2-r4-039-62vq7,phase=Succeeded node=kind-worker5
58.0437,Job,MODIFIED,eval-sanitize-2-r4-057,
58.0438,TaskRequest,MODIFIED,eval-sanitize-2-r4-058,phase=Scheduled job=None
58.0528,Job,MODIFIED,eval-sanitize-2-r4-057,
58.0583,Event,ADDED,eval-sanitize-2-r4-047-567wm.18d3d1dcf16b1d14,"reason=Pulled count=1 msg=Container image ""busybox:musl"" already present on machine"
58.0757,Event,ADDED,eval-sanitize-2-r4-047-567wm.18d3d1dcf27c3934,reason=Created count=1 msg=Created container: task
58.0978,Pod,MODIFIED,eval-sanitize-2-r4-057-58mc5,phase=Running node=kind-worker
58.1007,Job,MODIFIED,eval-sanitize-2-r4-048,
58.1078,Event,ADDED,eval-sanitize-2-r4-047-567wm.18d3d1dcf4648fa0,reason=Started count=1 msg=Started container task
58.11,Job,MODIFIED,eval-sanitize-2-r4-048,
58.1143,Job,MODIFIED,eval-sanitize-2-r4-051,
58.1187,Pod,MODIFIED,eval-sanitize-2-r4-058-qlc2v,phase=Pending node=None
58.1198,Event,ADDED,eval-sanitize-2-r4-058-qlc2v.18d3d1dcf50b6db6,"reason=FailedScheduling count=None msg=0/6 nodes are available: 2 c_wall violated: 1 conflicting context pair(s) with node memory, 4 node(s) had untolerated taint(s). no new claims to deallocate, preemption: 0/6 nodes are available: 2 No preemption victims found for incoming pod, 4 Preemption is not helpful for scheduling."
58.1222,Job,MODIFIED,eval-sanitize-2-r4-051,
58.1283,Pod,MODIFIED,eval-sanitize-2-r4-053-h944b,phase=Pending node=None
58.1286,Event,MODIFIED,eval-sanitize-2-r4-053-h944b.18d3d1dced117448,"reason=FailedScheduling count=None msg=0/6 nodes are available: 1 c_wall violated: 2 conflicting context pair(s) with node memory, 2 c_wall violated: 1 conflicting context pair(s) with node memory, 3 node(s) had untolerated taint(s). no new claims to deallocate, preemption: 0/6 nodes are available: 3 No preemption victims found for incoming pod, 3 Preemption is not helpful for scheduling."
58.1367,Event,ADDED,eval-sanitize-2-r4-055-dkvq4.18d3d1dcf6312799,"reason=FailedScheduling count=None msg=0/6 nodes are available: 1 c_wall violated: 1 conflicting context pair(s) with node memory, 1 c_wall violated: 2 conflicting context pair(s) with node memory, 4 node(s) had untolerated taint(s). no new claims to deallocate, preemption: 0/6 nodes are available: 2 No preemption victims found for incoming pod, 4 Preemption is not helpful for scheduling."
58.2215,Event,ADDED,eval-sanitize-2-r4-052-v8g6t.18d3d1dcfafcedb3,"reason=FailedScheduling count=None msg=0/6 nodes are available: 1 c_wall violated: 1 conflicting context pair(s) with node memory, 1 c_wall violated: 2 conflicting context pair(s) with node memory, 4 node(s) had untolerated taint(s). no new claims to deallocate, preemption: 0/6 nodes are available: 2 No preemption victims found for incoming pod, 4 Preemption is not helpful for scheduling."
58.2229,Event,ADDED,eval-sanitize-2-r4-058-qlc2v.18d3d1dcfb4f4866,"reason=FailedScheduling count=None msg=0/6 nodes are available: 2 c_wall violated: 1 conflicting context pair(s) with node memory, 4 node(s) had untolerated taint(s). no new claims to deallocate, preemption: 0/6 nodes are available: 2 No preemption victims found for incoming pod, 4 Preemption is not helpful for scheduling."
58.228,Event,ADDED,eval-sanitize-2-r4-053-h944b.18d3d1dcfb9cfac8,"reason=FailedScheduling count=None msg=0/6 nodes are available: 2 c_wall violated: 1 conflicting context pair(s) with node memory, 4 node(s) had untolerated taint(s). no new claims to deallocate, preemption: 0/6 nodes are available: 2 No preemption victims found for incoming pod, 4 Preemption is not helpful for scheduling."
58.2534,Event,ADDED,eval-sanitize-2-r4-049-2mqtp.18d3d1dcfcebd501,"reason=Pulled count=1 msg=Container image ""busybox:musl"" already present on machine"
58.2624,Node,MODIFIED,kind-worker5,taints=1
58.2706,Event,ADDED,eval-sanitize-2-r4-049-2mqtp.18d3d1dcfe16a2a4,reason=Created count=1 msg=Created container: task
58.288,Event,MODIFIED,eval-sanitize-2-r4-055-dkvq4.18d3d1dcf6312799,"reason=FailedScheduling count=None msg=0/6 nodes are available: 1 c_wall violated: 1 conflicting context pair(s) with node memory, 1 c_wall violated: 2 conflicting context pair(s) with node memory, 4 node(s) had untolerated taint(s). no new claims to deallocate, preemption: 0/6 nodes are available: 2 No preemption victims found for incoming pod, 4 Preemption is not helpful for scheduling."
58.3238,Event,MODIFIED,eval-sanitize-2-r4-052-v8g6t.18d3d1dcfafcedb3,"reason=FailedScheduling count=None msg=0/6 nodes are available: 1 c_wall violated: 1 conflicting context pair(s) with node memory, 1 c_wall violated: 2 conflicting context pair(s) with node memory, 4 node(s) had untolerated taint(s). no new claims to deallocate, preemption: 0/6 nodes are available: 2 No preemption victims found for incoming pod, 4 Preemption is not helpful for scheduling."
58.3302,Event,MODIFIED,eval-sanitize-2-r4-058-qlc2v.18d3d1dcfb4f4866,"reason=FailedScheduling count=None msg=0/6 nodes are available: 2 c_wall violated: 1 conflicting context pair(s) with node memory, 4 node(s) had untolerated taint(s). no new claims to deallocate, preemption: 0/6 nodes are available: 2 No preemption victims found for incoming pod, 4 Preemption is not helpful for scheduling."
58.3566,Pod,MODIFIED,eval-sanitize-2-r4-054-bp59m,phase=Running node=kind-worker2
58.3588,Node,MODIFIED,kind-worker5,taints=1
58.3592,Event,ADDED,eval-sanitize-2-r4-049-2mqtp.18d3d1dd034c72aa,reason=Started count=1 msg=Started container task
58.3601,Job,MODIFIED,eval-sanitize-2-r4-040,
58.3627,Pod,MODIFIED,eval-sanitize-2-r4-056-tb4xl,phase=Running node=kind-worker2
58.365,Job,MODIFIED,eval-sanitize-2-r4-043,
58.3675,Job,MODIFIED,eval-sanitize-2-r4-040,
58.3691,Node,MODIFIED,kind-worker5,taints=0
58.3706,Job,MODIFIED,eval-sanitize-2-r4-043,
58.371,Event,ADDED,eval-sanitize-2-r4-040.18d3d1dd041d97cd,reason=Completed count=1 msg=Job completed
58.3723,Pod,MODIFIED,eval-sanitize-2-r4-050-r2sx8,phase=Running node=kind-worker2
58.3745,Event,ADDED,eval-sanitize-2-r4-043.18d3d1dd043b68b7,reason=Completed count=1 msg=Job completed
58.3772,Job,MODIFIED,eval-sanitize-2-r4-044,
58.378,Job,MODIFIED,eval-sanitize-2-r4-040,
58.3818,Job,MODIFIED,eval-sanitize-2-r4-043,
58.3874,Job,MODIFIED,eval-sanitize-2-r4-041,
58.3882,Job,MODIFIED,eval-sanitize-2-r4-044,
58.3893,TaskRequest,MODIFIED,eval-sanitize-2-r4-040,phase=Complete job=None
58.3913,Event,MODIFIED,eval-sanitize-2-r4-053-h944b.18d3d1dcfb9cfac8,"reason=FailedScheduling count=None msg=0/6 nodes are available: 2 c_wall violated: 1 conflicting context pair(s) with node memory, 4 node(s) had untolerated taint(s). no new claims to deallocate, preemption: 0/6 nodes are available: 2 No preemption victims found for incoming pod, 4 Preemption is not helpful for scheduling."
58.3922,Job,MODIFIED,eval-sanitize-2-r4-041,
58.3925,Event,ADDED,eval-sanitize-2-r4-044.18d3d1dd0552a685,reason=Completed count=1 msg=Job completed
58.3931,TaskRequest,MODIFIED,eval-sanitize-2-r4-043,phase=Complete job=None
58.3967,Event,ADDED,eval-sanitize-2-r4-041.18d3d1dd0599c694,reason=Completed count=1 msg=Job completed
58.4002,Job,MODIFIED,eval-sanitize-2-r4-044,
58.401,Job,MODIFIED,eval-sanitize-2-r4-040,
58.4021,Job,MODIFIED,eval-sanitize-2-r4-043,
58.4029,Job,MODIFIED,eval-sanitize-2-r4-041,
58.4045,TaskRequest,MODIFIED,eval-sanitize-2-r4-044,phase=Complete job=None
58.4224,Pod,MODIFIED,eval-sanitize-2-r4-055-dkvq4,phase=Pending node=kind-worker5
58.4256,Event,ADDED,eval-sanitize-2-r4-055-dkvq4.18d3d1dd07633f93,reason=Scheduled count=None msg=Successfully assigned compute/eval-sanitize-2-r4-055-dkvq4 to kind-worker5
58.4316,Node,MODIFIED,kind-worker5,taints=0
58.4336,Pod,MODIFIED,eval-sanitize-2-r4-055-dkvq4,phase=Pending node=kind-worker5
58.4688,Node,MODIFIED,kind-worker5,taints=0
58.4794,TaskRequest,MODIFIED,eval-sanitize-2-r4-041,phase=Complete job=None
58.4844,Job,MODIFIED,eval-sanitize-2-r4-044,
58.4864,Pod,MODIFIED,eval-sanitize-2-r4-052-v8g6t,phase=Pending node=kind-worker5
58.4909,Job,MODIFIED,eval-sanitize-2-r4-041,
58.4923,Event,ADDED,eval-sanitize-2-r4-052-v8g6t.18d3d1dd0b35737c,reason=Scheduled count=None msg=Successfully assigned compute/eval-sanitize-2-r4-052-v8g6t to kind-worker5
58.4983,Pod,MODIFIED,eval-sanitize-2-r4-052-v8g6t,phase=Pending node=kind-worker5
58.5295,Pod,MODIFIED,eval-sanitize-2-r4-058-qlc2v,phase=Pending node=None
58.5537,Node,MODIFIED,kind-worker5,taints=0
58.6222,Pod,MODIFIED,eval-sanitize-2-r4-053-h944b,phase=Pending node=None
58.6367,Event,ADDED,eval-sanitize-2-r4-058-qlc2v.18d3d1dd13dce241,"reason=FailedScheduling count=None msg=0/6 nodes are available: 3 c_wall violated: 1 conflicting context pair(s) with node memory, 3 node(s) had untolerated taint(s). no new claims to deallocate, preemption: 0/6 nodes are available: 3 No preemption victims found for incoming pod, 3 Preemption is not helpful for scheduling."
58.7259,Event,ADDED,eval-sanitize-2-r4-053-h944b.18d3d1dd18df3581,"reason=FailedScheduling count=None msg=0/6 nodes are available: 3 c_wall violated: 1 conflicting context pair(s) with node memory, 3 node(s) had untolerated taint(s). no new claims to deallocate, preemption: 0/6 nodes are available: 3 No preemption victims found for incoming pod, 3 Preemption is not helpful for scheduling."
58.8485,Event,ADDED,eval-sanitize-2-r4-055-dkvq4.18d3d1dd2087e2f2,"reason=Pulled count=1 msg=Container image ""busybox:musl"" already present on machine"
58.8688,Event,ADDED,eval-sanitize-2-r4-055-dkvq4.18d3d1dd21a9a7bf,reason=Created count=1 msg=Created container: task
58.9066,Event,ADDED,eval-sanitize-2-r4-055-dkvq4.18d3d1dd2404479c,reason=Started count=1 msg=Started container task
58.911,Event,ADDED,eval-sanitize-2-r4-052-v8g6t.18d3d1dd2409fdfb,"reason=Pulled count=1 msg=Container image ""busybox:musl"" already present on machine"
58.9198,Pod,MODIFIED,eval-sanitize-2-r4-055-dkvq4,phase=Running node=kind-worker5
58.9251,Job,MODIFIED,eval-sanitize-2-r4-039,
58.9269,Event,ADDED,eval-sanitize-2-r4-052-v8g6t.18d3d1dd25416205,reason=Created count=1 msg=Created container: task
58.9366,Pod,MODIFIED,eval-sanitize-2-r4-039-62vq7,phase=Succeeded node=kind-worker5
58.9381,Job,MODIFIED,eval-sanitize-2-r4-039,
58.9392,Event,MODIFIED,eval-sanitize-2-r4-058-qlc2v.18d3d1dd13dce241,"reason=FailedScheduling count=None msg=0/6 nodes are available: 3 c_wall violated: 1 conflicting context pair(s) with node memory, 3 node(s) had untolerated taint(s). no new claims to deallocate, preemption: 0/6 nodes are available: 3 No preemption victims found for incoming pod, 3 Preemption is not helpful for scheduling."
58.9498,Pod,MODIFIED,eval-sanitize-2-r4-049-2mqtp,phase=Running node=kind-worker4
58.9518,Job,MODIFIED,eval-sanitize-2-r4-045,
58.9563,Job,MODIFIED,eval-sanitize-2-r4-045,
58.9591,Job,MODIFIED,eval-sanitize-2-r4-042,
58.9606,Pod,MODIFIED,eval-sanitize-2-r4-047-567wm,phase=Running node=kind-worker4
58.9629,Event,ADDED,eval-sanitize-2-r4-045.18d3d1dd273695ab,reason=Completed count=1 msg=Job completed
58.9641,Job,MODIFIED,eval-sanitize-2-r4-042,
58.966,Node,MODIFIED,kind-worker2,taints=1
58.9671,Job,MODIFIED,eval-sanitize-2-r4-038,
58.968,Job,MODIFIED,eval-sanitize-2-r4-045,
58.9708,Event,ADDED,eval-sanitize-2-r4-042.18d3d1dd27a1fa8e,reason=Completed count=1 msg=Job completed
58.9717,Job,MODIFIED,eval-sanitize-2-r4-038,
58.9735,TaskRequest,MODIFIED,eval-sanitize-2-r4-045,phase=Complete job=None
58.9776,Node,MODIFIED,kind-worker2,taints=1
58.9779,Event,ADDED,eval-sanitize-2-r4-038.18d3d1dd28237841,reason=Completed count=1 msg=Job completed
58.9788,Job,MODIFIED,eval-sanitize-2-r4-042,
58.9828,Job,MODIFIED,eval-sanitize-2-r4-045,
58.9844,Event,MODIFIED,eval-sanitize-2-r4-046-8lqh5.18d3d1da542b5287,"reason=FailedScheduling count=None msg=0/6 nodes are available: 1 c_wall violated: 1 conflicting context pair(s) with node memory, 5 node(s) had untolerated taint(s). no new claims to deallocate, preemption: 0/6 nodes are available: 1 No preemption victims found for incoming pod, 5 Preemption is not helpful for scheduling."
58.9845,TaskRequest,MODIFIED,eval-sanitize-2-r4-042,phase=Complete job=None
58.9854,Job,MODIFIED,eval-sanitize-2-r4-038,
59.0078,TaskRequest,ADDED,eval-sanitize-2-r4-059,phase=None job=None
59.0221,Event,MODIFIED,eval-sanitize-2-r4-053-h944b.18d3d1dd18df3581,"reason=FailedScheduling count=None msg=0/6 nodes are available: 3 c_wall violated: 1 conflicting context pair(s) with node memory, 3 node(s) had untolerated taint(s). no new claims to deallocate, preemption: 0/6 nodes are available: 3 No preemption victims found for incoming pod, 3 Preemption is not helpful for scheduling."
59.0228,TaskRequest,MODIFIED,eval-sanitize-2-r4-038,phase=Complete job=None
59.0269,Job,MODIFIED,eval-sanitize-2-r4-042,
59.0288,Pod,MODIFIED,eval-sanitize-2-r4-058-qlc2v,phase=Pending node=None
59.0289,TaskRequest,MODIFIED,eval-sanitize-2-r4-059,phase=Pending job=None
59.0339,Job,MODIFIED,eval-sanitize-2-r4-038,
59.0391,Job,MODIFIED,eval-sanitize-2-r4-058,
59.0415,Pod,MODIFIED,eval-sanitize-2-r4-053-h944b,phase=Pending node=None
59.042,Event,ADDED,eval-sanitize-2-r4-052-v8g6t.18d3d1dd2bfc475f,reason=Started count=1 msg=Started container task
59.0438,Job,ADDED,eval-sanitize-2-r4-059,
59.0463,Job,MODIFIED,eval-sanitize-2-r4-057,
59.05,Pod,ADDED,eval-sanitize-2-r4-059-rrppw,phase=Pending node=None
59.0537,Job,MODIFIED,eval-sanitize-2-r4-059,
59.054,Event,ADDED,eval-sanitize-2-r4-059.18d3d1dd2ccf2c9f,reason=SuccessfulCreate count=1 msg=Created pod: eval-sanitize-2-r4-059-rrppw
59.082,TaskRequest,MODIFIED,eval-sanitize-2-r4-059,phase=Scheduled job=None
59.0858,Job,MODIFIED,eval-sanitize-2-r4-059,
59.0884,TaskRequest,MODIFIED,eval-sanitize-2-r4-059,phase=Scheduled job=None
59.0909,Job,MODIFIED,eval-sanitize-2-r4-058,
59.1193,Event,ADDED,eval-sanitize-2-r4-058-qlc2v.18d3d1dd30b8d37b,"reason=FailedScheduling count=None msg=0/6 nodes are available: 2 c_wall violated: 1 conflicting context pair(s) with node memory, 4 node(s) had untolerated taint(s). no new claims to deallocate, preemption: 0/6 nodes are available: 2 No preemption victims found for incoming pod, 4 Preemption is not helpful for scheduling."
59.1249,Job,MODIFIED,eval-sanitize-2-r4-057,
59.1277,Pod,MODIFIED,eval-sanitize-2-r4-059-rrppw,phase=Pending node=None
59.1284,Event,ADDED,eval-sanitize-2-r4-059-rrppw.18d3d1dd3114f1de,"reason=FailedScheduling count=None msg=0/6 nodes are available: 2 c_wall violated: 1 conflicting context pair(s) with node memory, 4 node(s) had untolerated taint(s). no new claims to deallocate, preemption: 0/6 nodes are available: 2 No preemption victims found for incoming pod, 4 Preemption is not helpful for scheduling."
59.1308,Job,MODIFIED,eval-sanitize-2-r4-059,
59.1369,Event,ADDED,eval-sanitize-2-r4-053-h944b.18d3d1dd31cae31f,"reason=FailedScheduling count=None msg=0/6 nodes are available: 2 c_wall violated: 1 conflicting context pair(s) with node memory, 4 node(s) had untolerated taint(s). no new claims to deallocate, preemption: 0/6 nodes are available: 2 No preemption victims found for incoming pod, 4 Preemption is not helpful for scheduling."
59.2204,Event,ADDED,eval-sanitize-2-r4-059-rrppw.18d3d1dd36c12298,"reason=FailedScheduling count=None msg=0/6 nodes are available: 2 c_wall violated: 1 conflicting context pair(s) with node memory, 4 node(s) had untolerated taint(s). no new claims to deallocate, preemption: 0/6 nodes are available: 2 No preemption victims found for incoming pod, 4 Preemption is not helpful for scheduling."
59.3616,Job,MODIFIED,eval-sanitize-2-r4-054,
59.3668,Job,MODIFIED,eval-sanitize-2-r4-056,
59.3701,Job,MODIFIED,eval-sanitize-2-r4-054,
59.3743,Job,MODIFIED,eval-sanitize-2-r4-056,
59.3765,Job,MODIFIED,eval-sanitize-2-r4-050,
59.3841,Job,MODIFIED,eval-sanitize-2-r4-050,
59.6642,Node,MODIFIED,kind-worker4,taints=1
59.6726,Pod,MODIFIED,eval-sanitize-2-r4-058-qlc2v,phase=Pending node=None
59.6729,Event,MODIFIED,eval-sanitize-2-r4-058-qlc2v.18d3d1dd30b8d37b,"reason=FailedScheduling count=None msg=0/6 nodes are available: 2 c_wall violated: 1 conflicting context pair(s) with node memory, 4 node(s) had untolerated taint(s). no new claims to deallocate, preemption: 0/6 nodes are available: 2 No preemption victims found for incoming pod, 4 Preemption is not helpful for scheduling."
59.6761,Node,MODIFIED,kind-worker4,taints=1
59.6816,Pod,MODIFIED,eval-sanitize-2-r4-053-h944b,phase=Pending node=None
59.682,Event,MODIFIED,eval-sanitize-2-r4-053-h944b.18d3d1dd31cae31f,"reason=FailedScheduling count=None msg=0/6 nodes are available: 2 c_wall violated: 1 conflicting context pair(s) with node memory, 4 node(s) had untolerated taint(s). no new claims to deallocate, preemption: 0/6 nodes are available: 2 No preemption victims found for incoming pod, 4 Preemption is not helpful for scheduling."
59.6889,Pod,MODIFIED,eval-sanitize-2-r4-059-rrppw,phase=Pending node=None
59.6893,Event,MODIFIED,eval-sanitize-2-r4-059-rrppw.18d3d1dd36c12298,"reason=FailedScheduling count=None msg=0/6 nodes are available: 2 c_wall violated: 1 conflicting context pair(s) with node memory, 4 node(s) had untolerated taint(s). no new claims to deallocate, preemption: 0/6 nodes are available: 2 No preemption victims found for incoming pod, 4 Preemption is not helpful for scheduling."
59.6956,Event,ADDED,eval-sanitize-2-r4-058-qlc2v.18d3d1dd530dadfa,"reason=FailedScheduling count=None msg=0/6 nodes are available: 1 c_wall violated: 1 conflicting context pair(s) with node memory, 5 node(s) had untolerated taint(s). no new claims to deallocate, preemption: 0/6 nodes are available: 1 No preemption victims found for incoming pod, 5 Preemption is not helpful for scheduling."
59.697,Event,ADDED,eval-sanitize-2-r4-053-h944b.18d3d1dd5335e0cc,"reason=FailedScheduling count=None msg=0/6 nodes are available: 1 c_wall violated: 1 conflicting context pair(s) with node memory, 5 node(s) had untolerated taint(s). no new claims to deallocate, preemption: 0/6 nodes are available: 1 No preemption victims found for incoming pod, 5 Preemption is not helpful for scheduling."
59.6991,Event,ADDED,eval-sanitize-2-r4-059-rrppw.18d3d1dd53598dae,"reason=FailedScheduling count=None msg=0/6 nodes are available: 1 c_wall violated: 1 conflicting context pair(s) with node memory, 5 node(s) had untolerated taint(s). no new claims to deallocate, preemption: 0/6 nodes are available: 1 No preemption victims found for incoming pod, 5 Preemption is not helpful for scheduling."
59.9238,Pod,MODIFIED,eval-sanitize-2-r4-052-v8g6t,phase=Running node=kind-worker5
59.9248,Job,MODIFIED,eval-sanitize-2-r4-055,
59.9294,Job,MODIFIED,eval-sanitize-2-r4-039,
59.9338,Job,MODIFIED,eval-sanitize-2-r4-039,
59.9363,Event,MODIFIED,eval-sanitize-2-r4-058-qlc2v.18d3d1dd530dadfa,"reason=FailedScheduling count=None msg=0/6 nodes are available: 1 c_wall violated: 1 conflicting context pair(s) with node memory, 5 node(s) had untolerated taint(s). no new claims to deallocate, preemption: 0/6 nodes are available: 1 No preemption victims found for incoming pod, 5 Preemption is not helpful for scheduling."
59.937,Job,MODIFIED,eval-sanitize-2-r4-055,
59.9383,Event,MODIFIED,eval-sanitize-2-r4-053-h944b.18d3d1dd5335e0cc,"reason=FailedScheduling count=None msg=0/6 nodes are available: 1 c_wall violated: 1 conflicting context pair(s) with node memory, 5 node(s) had untolerated taint(s). no new claims to deallocate, preemption: 0/6 nodes are available: 1 No preemption victims found for incoming pod, 5 Preemption is not helpful for scheduling."
59.9385,Event,ADDED,eval-sanitize-2-r4-039.18d3d1dd61832143,reason=Completed count=1 msg=Job completed
59.9404,Event,MODIFIED,eval-sanitize-2-r4-059-rrppw.18d3d1dd53598dae,"reason=FailedScheduling count=None msg=0/6 nodes are available: 1 c_wall violated: 1 conflicting context pair(s) with node memory, 5 node(s) had untolerated taint(s). no new claims to deallocate, preemption: 0/6 nodes are available: 1 No preemption victims found for incoming pod, 5 Preemption is not helpful for scheduling."
59.9459,Job,MODIFIED,eval-sanitize-2-r4-039,
59.9515,TaskRequest,MODIFIED,eval-sanitize-2-r4-039,phase=Complete job=None
59.9537,Job,MODIFIED,eval-sanitize-2-r4-049,
59.9602,Job,MODIFIED,eval-sanitize-2-r4-039,
59.9619,Job,MODIFIED,eval-sanitize-2-r4-049,
59.9638,Job,MODIFIED,eval-sanitize-2-r4-047,
59.9731,Job,MODIFIED,eval-sanitize-2-r4-047,
60.0079,TaskRequest,ADDED,eval-sanitize-2-r4-060,phase=None job=None
60.0115,TaskRequest,MODIFIED,eval-sanitize-2-r4-060,phase=Pending job=None
60.0196,Node,ADDED,kind-control-plane,taints=1
60.021,Job,ADDED,eval-sanitize-2-r4-000,
60.0217,TaskRequest,ADDED,eval-sanitize-2-r4-000,phase=Complete job=None
60.0228,Job,ADDED,eval-sanitize-2-r4-001,
60.023,TaskRequest,ADDED,eval-sanitize-2-r4-001,phase=Complete job=None
60.0231,TaskRequest,ADDED,eval-sanitize-2-r4-002,phase=Complete job=None
60.0256,Node,ADDED,kind-worker,taints=1
60.0271,Pod,ADDED,eval-sanitize-2-r4-000-8mtl8,phase=Succeeded node=kind-worker2
60.0275,Event,ADDED,eval-sanitize-2-r2-007-dtr4x.18d3d140efae2116,"reason=FailedScheduling count=None msg=0/6 nodes are available: 1 c_wall violated: 2 conflicting context pair(s) with node memory, 5 node(s) had untolerated taint(s). no new claims to deallocate, preemption: 0/6 nodes are available: 1 No preemption victims found for incoming pod, 5 Preemption is not helpful for scheduling."
60.0286,Job,ADDED,eval-sanitize-2-r4-002,
60.0287,TaskRequest,ADDED,eval-sanitize-2-r4-003,phase=Complete job=None
60.0288,TaskRequest,ADDED,eval-sanitize-2-r4-004,phase=Complete job=None
60.0288,TaskRequest,ADDED,eval-sanitize-2-r4-005,phase=Complete job=None
60.0289,TaskRequest,ADDED,eval-sanitize-2-r4-006,phase=Complete job=None
60.0289,TaskRequest,ADDED,eval-sanitize-2-r4-007,phase=Complete job=None
60.029,TaskRequest,ADDED,eval-sanitize-2-r4-008,phase=Complete job=None
60.0291,TaskRequest,ADDED,eval-sanitize-2-r4-009,phase=Complete job=None
60.0291,TaskRequest,ADDED,eval-sanitize-2-r4-010,phase=Complete job=None
60.0291,TaskRequest,ADDED,eval-sanitize-2-r4-011,phase=Complete job=None
60.0292,TaskRequest,ADDED,eval-sanitize-2-r4-012,phase=Complete job=None
60.0292,TaskRequest,ADDED,eval-sanitize-2-r4-013,phase=Complete job=None
60.0305,Node,ADDED,kind-worker2,taints=1
60.0308,Event,ADDED,eval-sanitize-2-r2-007-dtr4x.18d3d1410cc3bdcf,"reason=FailedScheduling count=None msg=0/6 nodes are available: 1 c_wall violated: 3 conflicting context pair(s) with node memory, 5 node(s) had untolerated taint(s). no new claims to deallocate, preemption: 0/6 nodes are available: 1 No preemption victims found for incoming pod, 5 Preemption is not helpful for scheduling."
60.031,Event,ADDED,eval-sanitize-2-r2-007-dtr4x.18d3d1415d07131b,"reason=FailedScheduling count=None msg=0/6 nodes are available: 1 c_wall violated: 2 conflicting context pair(s) with node memory, 1 c_wall violated: 3 conflicting context pair(s) with node memory, 4 node(s) had untolerated taint(s). no new claims to deallocate, preemption: 0/6 nodes are available: 2 No preemption victims found for incoming pod, 4 Preemption is not helpful for scheduling."
60.0312,Event,ADDED,eval-sanitize-2-r2-007-dtr4x.18d3d1415e7e080e,"reason=FailedScheduling count=None msg=0/6 nodes are available: 1 c_wall violated: 2 conflicting context pair(s) with node memory, 5 node(s) had untolerated taint(s). no new claims to deallocate, preemption: 0/6 nodes are available: 1 No preemption victims found for incoming pod, 5 Preemption is not helpful for scheduling."
60.0324,Pod,ADDED,eval-sanitize-2-r4-001-n4msm,phase=Succeeded node=kind-worker
60.0333,Job,ADDED,eval-sanitize-2-r4-003,
60.0334,TaskRequest,ADDED,eval-sanitize-2-r4-014,phase=Complete job=None
60.0334,TaskRequest,ADDED,eval-sanitize-2-r4-015,phase=Complete job=None
60.0334,TaskRequest,ADDED,eval-sanitize-2-r4-016,phase=Complete job=None
60.0335,TaskRequest,ADDED,eval-sanitize-2-r4-017,phase=Complete job=None
60.0335,TaskRequest,ADDED,eval-sanitize-2-r4-018,phase=Complete job=None
60.0347,Pod,ADDED,eval-sanitize-2-r4-002-z5bgl,phase=Succeeded node=kind-worker
60.0355,Job,ADDED,eval-sanitize-2-r4-004,
60.0359,Event,ADDED,eval-sanitize-2-r2-010-p4cht.18d3d140ecc86e9a,"reason=FailedScheduling count=None msg=0/6 nodes are available: 1 c_wall violated: 1 conflicting context pair(s) with node memory, 5 node(s) had untolerated taint(s). no new claims to deallocate, preemption: 0/6 nodes are available: 1 No preemption victims found for incoming pod, 5 Preemption is not helpful for scheduling."
60.0361,Event,ADDED,eval-sanitize-2-r2-010-p4cht.18d3d1410cedb132,"reason=FailedScheduling count=None msg=0/6 nodes are available: 1 c_wall violated: 2 conflicting context pair(s) with node memory, 5 node(s) had untolerated taint(s). no new claims to deallocate, preemption: 0/6 nodes are available: 1 No preemption victims found for incoming pod, 5 Preemption is not helpful for scheduling."
60.038,Node,ADDED,kind-worker3,taints=1
60.0381,TaskRequest,ADDED,eval-sanitize-2-r4-019,phase=Complete job=None
60.0382,TaskRequest,ADDED,eval-sanitize-2-r4-020,phase=Complete job=None
60.0382,TaskRequest,ADDED,eval-sanitize-2-r4-021,phase=Complete job=None
60.0383,TaskRequest,ADDED,eval-sanitize-2-r4-022,phase=Complete job=None
60.0383,TaskRequest,ADDED,eval-sanitize-2-r4-023,phase=Complete job=None
60.0387,Event,ADDED,eval-sanitize-2-r2-011-rd542.18d3d140ecff5fed,"reason=FailedScheduling count=None msg=0/6 nodes are available: 1 c_wall violated: 1 conflicting context pair(s) with node memory, 5 node(s) had untolerated taint(s). no new claims to deallocate, preemption: 0/6 nodes are available: 1 No preemption victims found for incoming pod, 5 Preemption is not helpful for scheduling."
60.0389,Event,ADDED,eval-sanitize-2-r2-011-rd542.18d3d1410c74c661,"reason=FailedScheduling count=None msg=0/6 nodes are available: 1 c_wall violated: 2 conflicting context pair(s) with node memory, 5 node(s) had untolerated taint(s). no new claims to deallocate, preemption: 0/6 nodes are available: 1 No preemption victims found for incoming pod, 5 Preemption is not helpful for scheduling."
60.0391,Event,ADDED,eval-sanitize-2-r2-011-rd542.18d3d14159810efb,"reason=FailedScheduling count=None msg=0/6 nodes are available: 1 c_wall violated: 1 conflicting context pair(s) with node memory, 1 c_wall violated: 2 conflicting context pair(s) with node memory, 4 node(s) had untolerated taint(s). no new claims to deallocate, preemption: 0/6 nodes are available: 2 No preemption victims found for incoming pod, 4 Preemption is not helpful for scheduling."
60.0394,Event,ADDED,eval-sanitize-2-r2-011-rd542.18d3d1415e585ffe,"reason=FailedScheduling count=None msg=0/6 nodes are available: 1 c_wall violated: 1 conflicting context pair(s) with node memory, 5 node(s) had untolerated taint(s). no new claims to deallocate, preemption: 0/6 nodes are available: 1 No preemption victims found for incoming pod, 5 Preemption is not helpful for scheduling."
60.0396,Event,ADDED,eval-sanitize-2-r2-013-dczrl.18d3d140ed3908bd,"reason=FailedScheduling count=None msg=0/6 nodes are available: 1 c_wall violated: 1 conflicting context pair(s) with node memory, 5 node(s) had untolerated taint(s). no new claims to deallocate, preemption: 0/6 nodes are available: 1 No preemption victims found for incoming pod, 5 Preemption is not helpful for scheduling."
60.0398,Event,ADDED,eval-sanitize-2-r2-013-dczrl.18d3d1410c9dde38,"reason=FailedScheduling count=None msg=0/6 nodes are available: 1 c_wall violated: 2 conflicting context pair(s) with node memory, 5 node(s) had untolerated taint(s). no new claims to deallocate, preemption: 0/6 nodes are available: 1 No preemption victims found for incoming pod, 5 Preemption is not helpful for scheduling."
60.041,Pod,ADDED,eval-sanitize-2-r4-003-7hwjh,phase=Succeeded node=kind-worker4
60.041,TaskRequest,ADDED,eval-sanitize-2-r4-024,phase=Complete job=None
60.0411,TaskRequest,ADDED,eval-sanitize-2-r4-025,phase=Complete job=None
60.0411,TaskRequest,ADDED,eval-sanitize-2-r4-026,phase=Complete job=None
60.042,Job,ADDED,eval-sanitize-2-r4-005,
60.0433,Node,ADDED,kind-worker4,taints=1
60.0437,Event,ADDED,eval-sanitize-2-r2-015-mfrnk.18d3d1413ff72aa2,"reason=FailedScheduling count=None msg=0/6 nodes are available: 1 c_wall violated: 1 conflicting context pair(s) with node memory, 5 node(s) had untolerated taint(s). no new claims to deallocate, preemption: 0/6 nodes are available: 1 No preemption victims found for incoming pod, 5 Preemption is not helpful for scheduling."
60.0439,Event,ADDED,eval-sanitize-2-r2-016-bh2mh.18d3d1417e3f741c,"reason=FailedScheduling count=None msg=0/6 nodes are available: 1 c_wall violated: 2 conflicting context pair(s) with node memory, 5 node(s) had untolerated taint(s). no new claims to deallocate, preemption: 0/6 nodes are available: 1 No preemption victims found for incoming pod, 5 Preemption is not helpful for scheduling."
60.0441,Event,ADDED,eval-sanitize-2-r2-017-xzd9m.18d3d141b76563a7,"reason=FailedScheduling count=None msg=0/6 nodes are available: 2 c_wall violated: 1 conflicting context pair(s) with node memory, 4 node(s) had untolerated taint(s). no new claims to deallocate, preemption: 0/6 nodes are available: 2 No preemption victims found for incoming pod, 4 Preemption is not helpful for scheduling."
60.0453,Pod,ADDED,eval-sanitize-2-r4-004-ttn6b,phase=Succeeded node=kind-worker4
60.0454,TaskRequest,ADDED,eval-sanitize-2-r4-027,phase=Complete job=None
60.0454,TaskRequest,ADDED,eval-sanitize-2-r4-028,phase=Complete job=None
60.0455,TaskRequest,ADDED,eval-sanitize-2-r4-029,phase=Complete job=None
60.0465,Job,ADDED,eval-sanitize-2-r4-006,
60.0468,TaskRequest,ADDED,eval-sanitize-2-r4-030,phase=Complete job=None
60.0468,TaskRequest,ADDED,eval-sanitize-2-r4-031,phase=Complete job=None
60.0469,TaskRequest,ADDED,eval-sanitize-2-r4-032,phase=Complete job=None
60.0469,TaskRequest,ADDED,eval-sanitize-2-r4-033,phase=Complete job=None
60.047,TaskRequest,ADDED,eval-sanitize-2-r4-034,phase=Complete job=None
60.0482,Node,ADDED,kind-worker5,taints=0
60.0493,Pod,ADDED,eval-sanitize-2-r4-005-hs6t9,phase=Succeeded node=kind-worker5
60.0496,Event,ADDED,eval-sanitize-2-r2-017-xzd9m.18d3d141d1c581ef,"reason=FailedScheduling count=None msg=0/6 nodes are available: 1 c_wall violated: 1 conflicting context pair(s) with node memory, 5 node(s) had untolerated taint(s). no new claims to deallocate, preemption: 0/6 nodes are available: 1 No preemption victims found for incoming pod, 5 Preemption is not helpful for scheduling."
60.0499,Event,ADDED,eval-sanitize-2-r2-026-q6skx.18d3d14453b9cbb7,"reason=FailedScheduling count=None msg=0/6 nodes are available: 1 c_wall violated: 1 conflicting context pair(s) with node memory, 5 node(s) had untolerated taint(s). no new claims to deallocate, preemption: 0/6 nodes are available: 1 No preemption victims found for incoming pod, 5 Preemption is not helpful for scheduling."
60.0501,Event,ADDED,eval-sanitize-2-r2-026-q6skx.18d3d1445e1ef09e,"reason=FailedScheduling count=None msg=0/6 nodes are available: 1 c_wall violated: 1 conflicting context pair(s) with node memory, 1 c_wall violated: 2 conflicting context pair(s) with node memory, 4 node(s) had untolerated taint(s). no new claims to deallocate, preemption: 0/6 nodes are available: 2 No preemption victims found for incoming pod, 4 Preemption is not helpful for scheduling."
60.051,Job,ADDED,eval-sanitize-2-r4-007,
60.0511,TaskRequest,ADDED,eval-sanitize-2-r4-035,phase=Complete job=None
60.0511,TaskRequest,ADDED,eval-sanitize-2-r4-036,phase=Complete job=None
60.0511,TaskRequest,ADDED,eval-sanitize-2-r4-037,phase=Complete job=None
60.0523,Pod,ADDED,eval-sanitize-2-r4-006-8fdtg,phase=Succeeded node=kind-worker3
60.0525,Event,ADDED,eval-sanitize-2-r2-028-9bdm2.18d3d14453f03ec3,"reason=FailedScheduling count=None msg=0/6 nodes are available: 1 c_wall violated: 1 conflicting context pair(s) with node memory, 5 node(s) had untolerated taint(s). no new claims to deallocate, preemption: 0/6 nodes are available: 1 No preemption victims found for incoming pod, 5 Preemption is not helpful for scheduling."
60.0528,Event,ADDED,eval-sanitize-2-r2-028-9bdm2.18d3d14462043515,"reason=FailedScheduling count=None msg=0/6 nodes are available: 2 c_wall violated: 1 conflicting context pair(s) with node memory, 4 node(s) had untolerated taint(s). no new claims to deallocate, preemption: 0/6 nodes are available: 2 No preemption victims found for incoming pod, 4 Preemption is not helpful for scheduling."
60.0536,Job,ADDED,eval-sanitize-2-r4-008,
60.0537,TaskRequest,ADDED,eval-sanitize-2-r4-038,phase=Complete job=None
60.0537,TaskRequest,ADDED,eval-sanitize-2-r4-039,phase=Complete job=None
60.0546,Event,ADDED,eval-sanitize-2-r2-032-jvkrr.18d3d14557bdc5f2,"reason=FailedScheduling count=None msg=0/6 nodes are available: 1 c_wall violated: 1 conflicting context pair(s) with node memory, 5 node(s) had untolerated taint(s). no new claims to deallocate, preemption: 0/6 nodes are available: 1 No preemption victims found for incoming pod, 5 Preemption is not helpful for scheduling."
60.0548,Event,ADDED,eval-sanitize-2-r2-032-jvkrr.18d3d14558ee0875,"reason=FailedScheduling count=None msg=0/6 nodes are available: 1 c_wall violated: 1 conflicting context pair(s) with node memory, 5 node(s) had untolerated taint(s). no new claims to deallocate, preemption: 0/6 nodes are available: 1 No preemption victims found for incoming pod, 5 Preemption is not helpful for scheduling."
60.0551,Event,ADDED,eval-sanitize-2-r2-033-knvll.18d3d1457142f41d,"reason=FailedScheduling count=None msg=0/6 nodes are available: 1 c_wall violated: 1 conflicting context pair(s) with node memory, 5 node(s) had untolerated taint(s). no new claims to deallocate, preemption: 0/6 nodes are available: 1 No preemption victims found for incoming pod, 5 Preemption is not helpful for scheduling."
60.0562,Pod,ADDED,eval-sanitize-2-r4-007-4mkhx,phase=Succeeded node=kind-worker2
60.0564,TaskRequest,ADDED,eval-sanitize-2-r4-040,phase=Complete job=None
60.0564,TaskRequest,ADDED,eval-sanitize-2-r4-041,phase=Complete job=None
60.0565,TaskRequest,ADDED,eval-sanitize-2-r4-042,phase=Complete job=None
60.0571,Event,ADDED,eval-sanitize-2-r2-037-gx4tk.18d3d1473ae04cbc,"reason=FailedScheduling count=None msg=0/6 nodes are available: 1 c_wall violated: 1 conflicting context pair(s) with node memory, 5 node(s) had untolerated taint(s). no new claims to deallocate, preemption: 0/6 nodes are available: 1 No preemption victims found for incoming pod, 5 Preemption is not helpful for scheduling."
60.0574,Event,ADDED,eval-sanitize-2-r2-039-bvd2m.18d3d1473b10498d,"reason=FailedScheduling count=None msg=0/6 nodes are available: 1 c_wall violated: 1 conflicting context pair(s) with node memory, 5 node(s) had untolerated taint(s). no new claims to deallocate, preemption: 0/6 nodes are available: 1 No preemption victims found for incoming pod, 5 Preemption is not helpful for scheduling."
60.0576,Event,ADDED,eval-sanitize-2-r2-039-bvd2m.18d3d1478367cedf,"reason=FailedScheduling count=None msg=0/6 nodes are available: 2 c_wall violated: 1 conflicting context pair(s) with node memory, 4 node(s) had untolerated taint(s). no new claims to deallocate, preemption: 0/6 nodes are available: 2 No preemption victims found for incoming pod, 4 Preemption is not helpful for scheduling."
60.0585,Job,ADDED,eval-sanitize-2-r4-009,
60.0585,TaskRequest,ADDED,eval-sanitize-2-r4-043,phase=Complete job=None
60.0586,TaskRequest,ADDED,eval-sanitize-2-r4-044,phase=Complete job=None
60.0598,Pod,ADDED,eval-sanitize-2-r4-008-f4zj6,phase=Succeeded node=kind-worker
60.0603,Event,ADDED,eval-sanitize-2-r2-039-bvd2m.18d3d147b7f2dd0c,"reason=FailedScheduling count=None msg=0/6 nodes are available: 1 c_wall violated: 1 conflicting context pair(s) with node memory, 5 node(s) had untolerated taint(s). no new claims to deallocate, preemption: 0/6 nodes are available: 1 No preemption victims found for incoming pod, 5 Preemption is not helpful for scheduling."
60.0606,Event,ADDED,eval-sanitize-2-r2-040-mp4jz.18d3d1473ef820aa,"reason=FailedScheduling count=None msg=0/6 nodes are available: 1 c_wall violated: 1 conflicting context pair(s) with node memory, 5 node(s) had untolerated taint(s). no new claims to deallocate, preemption: 0/6 nodes are available: 1 No preemption victims found for incoming pod, 5 Preemption is not helpful for scheduling."
60.0608,Event,ADDED,eval-sanitize-2-r2-040-mp4jz.18d3d14783beff8c,"reason=FailedScheduling count=None msg=0/6 nodes are available: 2 c_wall violated: 1 conflicting context pair(s) with node memory, 4 node(s) had untolerated taint(s). no new claims to deallocate, preemption: 0/6 nodes are available: 2 No preemption victims found for incoming pod, 4 Preemption is not helpful for scheduling."
60.0619,Job,ADDED,eval-sanitize-2-r4-010,
60.062,TaskRequest,ADDED,eval-sanitize-2-r4-045,phase=Complete job=None
60.062,TaskRequest,ADDED,eval-sanitize-2-r4-046,phase=Scheduled job=None
60.062,TaskRequest,ADDED,eval-sanitize-2-r4-047,phase=Scheduled job=None
60.0633,Pod,ADDED,eval-sanitize-2-r4-009-mwm6s,phase=Succeeded node=kind-worker2
60.0637,Event,ADDED,eval-sanitize-2-r2-040-mp4jz.18d3d147b81c2f49,"reason=FailedScheduling count=None msg=0/6 nodes are available: 1 c_wall violated: 1 conflicting context pair(s) with node memory, 5 node(s) had untolerated taint(s). no new claims to deallocate, preemption: 0/6 nodes are available: 1 No preemption victims found for incoming pod, 5 Preemption is not helpful for scheduling."
60.0639,Event,ADDED,eval-sanitize-2-r2-041-xj2qx.18d3d1474dd853f1,"reason=FailedScheduling count=None msg=0/6 nodes are available: 1 c_wall violated: 1 conflicting context pair(s) with node memory, 5 node(s) had untolerated taint(s). no new claims to deallocate, preemption: 0/6 nodes are available: 1 No preemption victims found for incoming pod, 5 Preemption is not helpful for scheduling."
60.0641,Event,ADDED,eval-sanitize-2-r2-041-xj2qx.18d3d1478408519c,"reason=FailedScheduling count=None msg=0/6 nodes are available: 2 c_wall violated: 1 conflicting context pair(s) with node memory, 4 node(s) had untolerated taint(s). no new claims to deallocate, preemption: 0/6 nodes are available: 2 No preemption victims found for incoming pod, 4 Preemption is not helpful for scheduling."
60.0642,TaskRequest,ADDED,eval-sanitize-2-r4-048,phase=Scheduled job=None
60.0643,TaskRequest,ADDED,eval-sanitize-2-r4-049,phase=Scheduled job=None
60.0644,TaskRequest,ADDED,eval-sanitize-2-r4-050,phase=Scheduled job=None
60.0656,Pod,ADDED,eval-sanitize-2-r4-010-wmh29,phase=Succeeded node=kind-worker2
60.0664,Job,ADDED,eval-sanitize-2-r4-011,
60.0667,Event,ADDED,eval-sanitize-2-r2-041-xj2qx.18d3d147b843d47e,"reason=FailedScheduling count=None msg=0/6 nodes are available: 1 c_wall violated: 1 conflicting context pair(s) with node memory, 5 node(s) had untolerated taint(s). no new claims to deallocate, preemption: 0/6 nodes are available: 1 No preemption victims found for incoming pod, 5 Preemption is not helpful for scheduling."
60.0669,Event,ADDED,eval-sanitize-2-r2-042-8rwkk.18d3d1478a1e1ebd,"reason=FailedScheduling count=None msg=0/6 nodes are available: 2 c_wall violated: 1 conflicting context pair(s) with node memory, 4 node(s) had untolerated taint(s). no new claims to deallocate, preemption: 0/6 nodes are available: 2 No preemption victims found for incoming pod, 4 Preemption is not helpful for scheduling."
60.0671,Event,ADDED,eval-sanitize-2-r2-042-8rwkk.18d3d147b86ec5c1,"reason=FailedScheduling count=None msg=0/6 nodes are available: 1 c_wall violated: 1 conflicting context pair(s) with node memory, 5 node(s) had untolerated taint(s). no new claims to deallocate, preemption: 0/6 nodes are available: 1 No preemption victims found for incoming pod, 5 Preemption is not helpful for scheduling."
60.0672,TaskRequest,ADDED,eval-sanitize-2-r4-051,phase=Scheduled job=None
60.0672,TaskRequest,ADDED,eval-sanitize-2-r4-052,phase=Scheduled job=None
60.0673,TaskRequest,ADDED,eval-sanitize-2-r4-053,phase=Scheduled job=None
60.0673,TaskRequest,ADDED,eval-sanitize-2-r4-054,phase=Scheduled job=None
60.0674,TaskRequest,ADDED,eval-sanitize-2-r4-055,phase=Scheduled job=None
60.0674,TaskRequest,ADDED,eval-sanitize-2-r4-056,phase=Scheduled job=None
60.0675,TaskRequest,ADDED,eval-sanitize-2-r4-057,phase=Scheduled job=None
60.0675,TaskRequest,ADDED,eval-sanitize-2-r4-058,phase=Scheduled job=None
60.0678,Event,ADDED,eval-sanitize-2-r2-042-8rwkk.18d3d147efb21101,"reason=FailedScheduling count=None msg=0/6 nodes are available: 2 c_wall violated: 1 conflicting context pair(s) with node memory, 4 node(s) had untolerated taint(s). no new claims to deallocate, preemption: 0/6 nodes are available: 2 No preemption victims found for incoming pod, 4 Preemption is not helpful for scheduling."
60.0681,Event,ADDED,eval-sanitize-2-r2-042-8rwkk.18d3d147fa9274ff,"reason=FailedScheduling count=None msg=0/6 nodes are available: 1 c_wall violated: 1 conflicting context pair(s) with node memory, 5 node(s) had untolerated taint(s). no new claims to deallocate, preemption: 0/6 nodes are available: 1 No preemption victims found for incoming pod, 5 Preemption is not helpful for scheduling."
60.0695,Job,ADDED,eval-sanitize-2-r4-012,
60.0696,TaskRequest,ADDED,eval-sanitize-2-r4-059,phase=Scheduled job=None
60.0696,TaskRequest,ADDED,eval-sanitize-2-r4-060,phase=Pending job=None
60.0699,Event,ADDED,eval-sanitize-2-r2-043-4nhhk.18d3d147c5f6b497,"reason=FailedScheduling count=None msg=0/6 nodes are available: 1 c_wall violated: 1 conflicting context pair(s) with node memory, 5 node(s) had untolerated taint(s). no new claims to deallocate, preemption: 0/6 nodes are available: 1 No preemption victims found for incoming pod, 5 Preemption is not helpful for scheduling."
60.0701,Event,ADDED,eval-sanitize-2-r2-043-4nhhk.18d3d147efff071b,"reason=FailedScheduling count=None msg=0/6 nodes are available: 2 c_wall violated: 1 conflicting context pair(s) with node memory, 4 node(s) had untolerated taint(s). no new claims to deallocate, preemption: 0/6 nodes are available: 2 No preemption victims found for incoming pod, 4 Preemption is not helpful for scheduling."
60.0703,Event,ADDED,eval-sanitize-2-r2-043-4nhhk.18d3d147fa64231a,"reason=FailedScheduling count=None msg=0/6 nodes are available: 1 c_wall violated: 1 conflicting context pair(s) with node memory, 5 node(s) had untolerated taint(s). no new claims to deallocate, preemption: 0/6 nodes are available: 1 No preemption victims found for incoming pod, 5 Preemption is not helpful for scheduling."
60.072,Pod,ADDED,eval-sanitize-2-r4-011-8l98g,phase=Succeeded node=kind-worker2
60.0731,Pod,ADDED,eval-sanitize-2-r4-012-s6sg6,phase=Succeeded node=kind-worker
60.0734,Event,ADDED,eval-sanitize-2-r2-044-h9lzd.18d3d14800f4fde8,"reason=FailedScheduling count=None msg=0/6 nodes are available: 1 c_wall violated: 2 conflicting context pair(s) with node memory, 5 node(s) had untolerated taint(s). no new claims to deallocate, preemption: 0/6 nodes are available: 1 No preemption victims found for incoming pod, 5 Preemption is not helpful for scheduling."
60.0737,Event,ADDED,eval-sanitize-2-r2-045-4jx76.18d3d1483cff1daa,"reason=FailedScheduling count=None msg=0/6 nodes are available: 1 c_wall violated: 2 conflicting context pair(s) with node memory, 5 node(s) had untolerated taint(s). no new claims to deallocate, preemption: 0/6 nodes are available: 1 No preemption victims found for incoming pod, 5 Preemption is not helpful for scheduling."
60.074,Event,ADDED,eval-sanitize-2-r2-045-4jx76.18d3d148c388ad11,"reason=FailedScheduling count=None msg=0/6 nodes are available: 1 c_wall violated: 3 conflicting context pair(s) with node memory, 5 node(s) had untolerated taint(s). no new claims to deallocate, preemption: 0/6 nodes are available: 1 No preemption victims found for incoming pod, 5 Preemption is not helpful for scheduling."
60.0746,TaskRequest,MODIFIED,eval-sanitize-2-r4-060,phase=Scheduled job=None
60.0756,Job,ADDED,eval-sanitize-2-r4-013,
60.076,Event,ADDED,eval-sanitize-2-r2-045-4jx76.18d3d148cb70a393,"reason=FailedScheduling count=None msg=0/6 nodes are available: 1 c_wall violated: 3 conflicting context pair(s) with node memory, 5 node(s) had untolerated taint(s). no new claims to deallocate, preemption: 0/6 nodes are available: 1 No preemption victims found for incoming pod, 5 Preemption is not helpful for scheduling."
60.0763,Event,ADDED,eval-sanitize-2-r2-049-ppsvt.18d3d1492b4fcc20,"reason=FailedScheduling count=None msg=0/6 nodes are available: 1 c_wall violated: 1 conflicting context pair(s) with node memory, 1 c_wall violated: 2 conflicting context pair(s) with node memory, 4 node(s) had untolerated taint(s). no new claims to deallocate, preemption: 0/6 nodes are available: 2 No preemption victims found for incoming pod, 4 Preemption is not helpful for scheduling."
60.0766,Event,ADDED,eval-sanitize-2-r2-049-ppsvt.18d3d1493b530ada,"reason=FailedScheduling count=None msg=0/6 nodes are available: 1 c_wall violated: 1 conflicting context pair(s) with node memory, 5 node(s) had untolerated taint(s). no new claims to deallocate, preemption: 0/6 nodes are available: 1 No preemption victims found for incoming pod, 5 Preemption is not helpful for scheduling."
60.0774,TaskRequest,MODIFIED,eval-sanitize-2-r4-060,phase=Scheduled job=None
60.0782,Job,ADDED,eval-sanitize-2-r4-014,
60.0794,Pod,ADDED,eval-sanitize-2-r4-013-tw8qz,phase=Succeeded node=kind-worker4
60.08,Event,ADDED,eval-sanitize-2-r2-050-drbxp.18d3d149668fb454,"reason=FailedScheduling count=None msg=0/6 nodes are available: 1 c_wall violated: 1 conflicting context pair(s) with node memory, 5 node(s) had untolerated taint(s). no new claims to deallocate, preemption: 0/6 nodes are available: 1 No preemption victims found for incoming pod, 5 Preemption is not helpful for scheduling."
60.0804,Event,ADDED,eval-sanitize-2-r2-051-86jxh.18d3d14a3424b500,"reason=FailedScheduling count=None msg=0/6 nodes are available: 1 c_wall violated: 1 conflicting context pair(s) with node memory, 5 node(s) had untolerated taint(s). no new claims to deallocate, preemption: 0/6 nodes are available: 1 No preemption victims found for incoming pod, 5 Preemption is not helpful for scheduling."
60.0806,Event,ADDED,eval-sanitize-2-r2-052-9bx2m.18d3d14a3504d4a5,"reason=FailedScheduling count=None msg=0/6 nodes are available: 1 c_wall violated: 1 conflicting context pair(s) with node memory, 5 node(s) had untolerated taint(s). no new claims to deallocate, preemption: 0/6 nodes are available: 1 No preemption victims found for incoming pod, 5 Preemption is not helpful for scheduling."
60.0821,Pod,ADDED,eval-sanitize-2-r4-014-vkvct,phase=Succeeded node=kind-worker2
60.0825,Event,ADDED,eval-sanitize-2-r2-053-9jn6r.18d3d14a353112a2,"reason=FailedScheduling count=None msg=0/6 nodes are available: 1 c_wall violated: 1 conflicting context pair(s) with node memory, 5 node(s) had untolerated taint(s). no new claims to deallocate, preemption: 0/6 nodes are available: 1 No preemption victims found for incoming pod, 5 Preemption is not helpful for scheduling."
60.0828,Event,ADDED,eval-sanitize-2-r2-053-9jn6r.18d3d14a933a2ffa,"reason=FailedScheduling count=None msg=0/6 nodes are available: 2 c_wall violated: 1 conflicting context pair(s) with node memory, 4 node(s) had untolerated taint(s). no new claims to deallocate, preemption: 0/6 nodes are available: 2 No preemption victims found for incoming pod, 4 Preemption is not helpful for scheduling."
60.0837,Job,ADDED,eval-sanitize-2-r4-015,
60.0845,Job,ADDED,eval-sanitize-2-r4-016,
60.085,Event,ADDED,eval-sanitize-2-r2-053-9jn6r.18d3d14aabc49e8c,"reason=FailedScheduling count=None msg=0/6 nodes are available: 1 c_wall violated: 1 conflicting context pair(s) with node memory, 5 node(s) had untolerated taint(s). no new claims to deallocate, preemption: 0/6 nodes are available: 1 No preemption victims found for incoming pod, 5 Preemption is not helpful for scheduling."
60.0852,Event,ADDED,eval-sanitize-2-r2-054-crmqk.18d3d14a549bc63b,"reason=FailedScheduling count=None msg=0/6 nodes are available: 1 c_wall violated: 1 conflicting context pair(s) with node memory, 5 node(s) had untolerated taint(s). no new claims to deallocate, preemption: 0/6 nodes are available: 1 No preemption victims found for incoming pod, 5 Preemption is not helpful for scheduling."
60.0854,Event,ADDED,eval-sanitize-2-r2-054-crmqk.18d3d14a95445c19,"reason=FailedScheduling count=None msg=0/6 nodes are available: 2 c_wall violated: 1 conflicting context pair(s) with node memory, 4 node(s) had untolerated taint(s). no new claims to deallocate, preemption: 0/6 nodes are available: 2 No preemption victims found for incoming pod, 4 Preemption is not helpful for scheduling."
60.0865,Pod,ADDED,eval-sanitize-2-r4-015-45f4d,phase=Succeeded node=kind-worker2
60.0877,Pod,ADDED,eval-sanitize-2-r4-016-cjlgc,phase=Succeeded node=kind-worker2
60.0881,Event,ADDED,eval-sanitize-2-r2-054-crmqk.18d3d14aab9b66ce,"reason=FailedScheduling count=None msg=0/6 nodes are available: 1 c_wall violated: 1 conflicting context pair(s) with node memory, 5 node(s) had untolerated taint(s). no new claims to deallocate, preemption: 0/6 nodes are available: 1 No preemption victims found for incoming pod, 5 Preemption is not helpful for scheduling."
60.0883,Event,ADDED,eval-sanitize-2-r2-061-9rfwf.18d3d14c28625a15,"reason=FailedScheduling count=None msg=0/6 nodes are available: 1 c_wall violated: 1 conflicting context pair(s) with node memory, 5 node(s) had untolerated taint(s). no new claims to deallocate, preemption: 0/6 nodes are available: 1 No preemption victims found for incoming pod, 5 Preemption is not helpful for scheduling."
60.0885,Event,ADDED,eval-sanitize-2-r2-061-9rfwf.18d3d14c29aa9bbb,"reason=FailedScheduling count=None msg=0/6 nodes are available: 1 c_wall violated: 1 conflicting context pair(s) with node memory, 5 node(s) had untolerated taint(s). no new claims to deallocate, preemption: 0/6 nodes are available: 1 No preemption victims found for incoming pod, 5 Preemption is not helpful for scheduling."
60.0896,Job,ADDED,eval-sanitize-2-r4-017,
60.0902,Event,ADDED,eval-sanitize-2-r2-061-9rfwf.18d3d14c31f60ddd,"reason=FailedScheduling count=None msg=0/6 nodes are available: 1 c_wall violated: 2 conflicting context pair(s) with node memory, 5 node(s) had untolerated taint(s). no new claims to deallocate, preemption: 0/6 nodes are available: 1 No preemption victims found for incoming pod, 5 Preemption is not helpful for scheduling."
60.0904,Event,ADDED,eval-sanitize-2-r2-069-2j22t.18d3d14dd29083df,"reason=FailedScheduling count=None msg=0/6 nodes are available: 1 c_wall violated: 2 conflicting context pair(s) with node memory, 5 node(s) had untolerated taint(s). no new claims to deallocate, preemption: 0/6 nodes are available: 1 No preemption victims found for incoming pod, 5 Preemption is not helpful for scheduling."
60.0906,Event,ADDED,eval-sanitize-2-r2-069-2j22t.18d3d14dd390c283,"reason=FailedScheduling count=None msg=0/6 nodes are available: 1 c_wall violated: 2 conflicting context pair(s) with node memory, 5 node(s) had untolerated taint(s). no new claims to deallocate, preemption: 0/6 nodes are available: 1 No preemption victims found for incoming pod, 5 Preemption is not helpful for scheduling."
60.0914,Job,ADDED,eval-sanitize-2-r4-018,
60.0926,Pod,ADDED,eval-sanitize-2-r4-017-mnp4k,phase=Succeeded node=kind-worker4
60.0929,Event,ADDED,eval-sanitize-2-r2-070-fnnv4.18d3d14e0e21f762,"reason=FailedScheduling count=None msg=0/6 nodes are available: 1 c_wall violated: 2 conflicting context pair(s) with node memory, 5 node(s) had untolerated taint(s). no new claims to deallocate, preemption: 0/6 nodes are available: 1 No preemption victims found for incoming pod, 5 Preemption is not helpful for scheduling."
60.0932,Event,ADDED,eval-sanitize-2-r2-071-whhp7.18d3d14e4a1cd3d0,"reason=FailedScheduling count=None msg=0/6 nodes are available: 2 c_wall violated: 1 conflicting context pair(s) with node memory, 4 node(s) had untolerated taint(s). no new claims to deallocate, preemption: 0/6 nodes are available: 2 No preemption victims found for incoming pod, 4 Preemption is not helpful for scheduling."
60.0934,Event,ADDED,eval-sanitize-2-r2-071-whhp7.18d3d14e52453955,"reason=FailedScheduling count=None msg=0/6 nodes are available: 1 c_wall violated: 1 conflicting context pair(s) with node memory, 5 node(s) had untolerated taint(s). no new claims to deallocate, preemption: 0/6 nodes are available: 1 No preemption victims found for incoming pod, 5 Preemption is not helpful for scheduling."
60.0937,Event,ADDED,eval-sanitize-2-r2-073-drszs.18d3d14ec11630ea,"reason=FailedScheduling count=None msg=0/6 nodes are available: 1 c_wall violated: 1 conflicting context pair(s) with node memory, 5 node(s) had untolerated taint(s). no new claims to deallocate, preemption: 0/6 nodes are available: 1 No preemption victims found for incoming pod, 5 Preemption is not helpful for scheduling."
60.0939,Event,ADDED,eval-sanitize-2-r2-075-w5ctl.18d3d14fc066218e,"reason=FailedScheduling count=None msg=0/6 nodes are available: 1 c_wall violated: 1 conflicting context pair(s) with node memory, 5 node(s) had untolerated taint(s). no new claims to deallocate, preemption: 0/6 nodes are available: 1 No preemption victims found for incoming pod, 5 Preemption is not helpful for scheduling."
60.095,Pod,ADDED,eval-sanitize-2-r4-018-f6rrd,phase=Succeeded node=kind-worker5
60.0959,Job,ADDED,eval-sanitize-2-r4-019,
60.0978,Job,ADDED,eval-sanitize-2-r4-020,
60.0982,Event,ADDED,eval-sanitize-2-r2-075-w5ctl.18d3d14ff03488bd,"reason=FailedScheduling count=None msg=0/6 nodes are available: 2 c_wall violated: 1 conflicting context pair(s) with node memory, 4 node(s) had untolerated taint(s). no new claims to deallocate, preemption: 0/6 nodes are available: 2 No preemption victims found for incoming pod, 4 Preemption is not helpful for scheduling."
60.0984,Event,ADDED,eval-sanitize-2-r2-075-w5ctl.18d3d1503c18baed,"reason=FailedScheduling count=None msg=0/6 nodes are available: 1 c_wall violated: 1 conflicting context pair(s) with node memory, 5 node(s) had untolerated taint(s). no new claims to deallocate, preemption: 0/6 nodes are available: 1 No preemption victims found for incoming pod, 5 Preemption is not helpful for scheduling."
60.0986,Event,ADDED,eval-sanitize-2-r2-076-v5wgq.18d3d14fc0923d55,"reason=FailedScheduling count=None msg=0/6 nodes are available: 1 c_wall violated: 2 conflicting context pair(s) with node memory, 5 node(s) had untolerated taint(s). no new claims to deallocate, preemption: 0/6 nodes are available: 1 No preemption victims found for incoming pod, 5 Preemption is not helpful for scheduling."
60.1,Pod,ADDED,eval-sanitize-2-r4-019-5xr88,phase=Succeeded node=kind-worker3
60.1011,Pod,ADDED,eval-sanitize-2-r4-020-qv5qd,phase=Succeeded node=kind-worker3
60.1018,Event,ADDED,eval-sanitize-2-r2-077-bzfjj.18d3d14fc0bddbc2,"reason=FailedScheduling count=None msg=0/6 nodes are available: 1 c_wall violated: 1 conflicting context pair(s) with node memory, 5 node(s) had untolerated taint(s). no new claims to deallocate, preemption: 0/6 nodes are available: 1 No preemption victims found for incoming pod, 5 Preemption is not helpful for scheduling."
60.1021,Event,ADDED,eval-sanitize-2-r2-077-bzfjj.18d3d14feff2800e,"reason=FailedScheduling count=None msg=0/6 nodes are available: 2 c_wall violated: 1 conflicting context pair(s) with node memory, 4 node(s) had untolerated taint(s). no new claims to deallocate, preemption: 0/6 nodes are available: 2 No preemption victims found for incoming pod, 4 Preemption is not helpful for scheduling."
60.1023,Event,ADDED,eval-sanitize-2-r2-077-bzfjj.18d3d1503c778f79,"reason=FailedScheduling count=None msg=0/6 nodes are available: 1 c_wall violated: 1 conflicting context pair(s) with node memory, 5 node(s) had untolerated taint(s). no new claims to deallocate, preemption: 0/6 nodes are available: 1 No preemption victims found for incoming pod, 5 Preemption is not helpful for scheduling."
60.1031,Job,ADDED,eval-sanitize-2-r4-021,
60.1036,Event,ADDED,eval-sanitize-2-r2-077-bzfjj.18d3d15100b6bc99,"reason=FailedScheduling count=None msg=0/6 nodes are available: 1 c_wall violated: 1 conflicting context pair(s) with node memory, 5 node(s) had untolerated taint(s). no new claims to deallocate, preemption: 0/6 nodes are available: 1 No preemption victims found for incoming pod, 5 Preemption is not helpful for scheduling."
60.1038,Event,ADDED,eval-sanitize-2-r2-077-bzfjj.18d3d1513bfb9b90,"reason=FailedScheduling count=None msg=0/6 nodes are available: 2 c_wall violated: 1 conflicting context pair(s) with node memory, 4 node(s) had untolerated taint(s). no new claims to deallocate, preemption: 0/6 nodes are available: 2 No preemption victims found for incoming pod, 4 Preemption is not helpful for scheduling."
60.104,Event,ADDED,eval-sanitize-2-r2-077-bzfjj.18d3d1517815ca71,"reason=FailedScheduling count=None msg=0/6 nodes are available: 1 c_wall violated: 1 conflicting context pair(s) with node memory, 5 node(s) had untolerated taint(s). no new claims to deallocate, preemption: 0/6 nodes are available: 1 No preemption victims found for incoming pod, 5 Preemption is not helpful for scheduling."
60.1052,Pod,ADDED,eval-sanitize-2-r4-021-vzk2p,phase=Succeeded node=kind-worker
60.106,Job,ADDED,eval-sanitize-2-r4-022,
60.1064,Event,ADDED,eval-sanitize-2-r2-078-2flk9.18d3d14ff3f7fa8b,"reason=FailedScheduling count=None msg=0/6 nodes are available: 1 c_wall violated: 1 conflicting context pair(s) with node memory, 1 c_wall violated: 2 conflicting context pair(s) with node memory, 4 node(s) had untolerated taint(s). no new claims to deallocate, preemption: 0/6 nodes are available: 2 No preemption victims found for incoming pod, 4 Preemption is not helpful for scheduling."
60.1066,Event,ADDED,eval-sanitize-2-r2-078-2flk9.18d3d1503c436166,"reason=FailedScheduling count=None msg=0/6 nodes are available: 1 c_wall violated: 1 conflicting context pair(s) with node memory, 5 node(s) had untolerated taint(s). no new claims to deallocate, preemption: 0/6 nodes are available: 1 No preemption victims found for incoming pod, 5 Preemption is not helpful for scheduling."
60.1068,Event,ADDED,eval-sanitize-2-r2-080-q4tzk.18d3d150623c8906,"reason=FailedScheduling count=None msg=0/6 nodes are available: 1 c_wall violated: 1 conflicting context pair(s) with node memory, 5 node(s) had untolerated taint(s). no new claims to deallocate, preemption: 0/6 nodes are available: 1 No preemption victims found for incoming pod, 5 Preemption is not helpful for scheduling."
60.1079,Pod,ADDED,eval-sanitize-2-r4-022-kvzd5,phase=Succeeded node=kind-worker4
60.1082,Event,ADDED,eval-sanitize-2-r2-080-q4tzk.18d3d151023b617d,"reason=FailedScheduling count=None msg=0/6 nodes are available: 1 c_wall violated: 2 conflicting context pair(s) with node memory, 5 node(s) had untolerated taint(s). no new claims to deallocate, preemption: 0/6 nodes are available: 1 No preemption victims found for incoming pod, 5 Preemption is not helpful for scheduling."
60.1084,Event,ADDED,eval-sanitize-2-r2-080-q4tzk.18d3d1513e0a748b,"reason=FailedScheduling count=None msg=0/6 nodes are available: 1 c_wall violated: 1 conflicting context pair(s) with node memory, 1 c_wall violated: 2 conflicting context pair(s) with node memory, 4 node(s) had untolerated taint(s). no new claims to deallocate, preemption: 0/6 nodes are available: 2 No preemption victims found for incoming pod, 4 Preemption is not helpful for scheduling."
60.1093,Job,ADDED,eval-sanitize-2-r4-023,
60.1116,Pod,ADDED,eval-sanitize-2-r4-023-6hkqq,phase=Succeeded node=kind-worker
60.1119,Event,ADDED,eval-sanitize-2-r2-080-q4tzk.18d3d1515685bd4f,"reason=FailedScheduling count=None msg=0/6 nodes are available: 2 c_wall violated: 2 conflicting context pair(s) with node memory, 4 node(s) had untolerated taint(s). no new claims to deallocate, preemption: 0/6 nodes are available: 2 No preemption victims found for incoming pod, 4 Preemption is not helpful for scheduling."
60.1121,Event,ADDED,eval-sanitize-2-r2-080-q4tzk.18d3d151783fa7de,"reason=FailedScheduling count=None msg=0/6 nodes are available: 1 c_wall violated: 2 conflicting context pair(s) with node memory, 5 node(s) had untolerated taint(s). no new claims to deallocate, preemption: 0/6 nodes are available: 1 No preemption victims found for incoming pod, 5 Preemption is not helpful for scheduling."
60.1123,Event,ADDED,eval-sanitize-2-r2-082-n842l.18d3d151026e408f,"reason=FailedScheduling count=None msg=0/6 nodes are available: 1 c_wall violated: 2 conflicting context pair(s) with node memory, 5 node(s) had untolerated taint(s). no new claims to deallocate, preemption: 0/6 nodes are available: 1 No preemption victims found for incoming pod, 5 Preemption is not helpful for scheduling."
60.1131,Job,ADDED,eval-sanitize-2-r4-024,
60.1143,Pod,ADDED,eval-sanitize-2-r4-024-m4dwq,phase=Succeeded node=kind-worker2
60.1146,Event,ADDED,eval-sanitize-2-r2-085-x79s4.18d3d1518c2903dd,"reason=FailedScheduling count=None msg=0/6 nodes are available: 1 c_wall violated: 1 conflicting context pair(s) with node memory, 5 node(s) had untolerated taint(s). no new claims to deallocate, preemption: 0/6 nodes are available: 1 No preemption victims found for incoming pod, 5 Preemption is not helpful for scheduling."
60.1148,Event,ADDED,eval-sanitize-2-r2-086-mmqn9.18d3d151c86c15bc,"reason=FailedScheduling count=None msg=0/6 nodes are available: 1 c_wall violated: 1 conflicting context pair(s) with node memory, 5 node(s) had untolerated taint(s). no new claims to deallocate, preemption: 0/6 nodes are available: 1 No preemption victims found for incoming pod, 5 Preemption is not helpful for scheduling."
60.115,Event,ADDED,eval-sanitize-2-r2-087-tr6hh.18d3d15203ad4ce3,"reason=FailedScheduling count=None msg=0/6 nodes are available: 1 c_wall violated: 1 conflicting context pair(s) with node memory, 5 node(s) had untolerated taint(s). no new claims to deallocate, preemption: 0/6 nodes are available: 1 No preemption victims found for incoming pod, 5 Preemption is not helpful for scheduling."
60.1153,Event,ADDED,eval-sanitize-2-r2-090-kmf8c.18d3d152ea8a520c,"reason=FailedScheduling count=None msg=0/6 nodes are available: 1 c_wall violated: 3 conflicting context pair(s) with node memory, 5 node(s) had untolerated taint(s). no new claims to deallocate, preemption: 0/6 nodes are available: 1 No preemption victims found for incoming pod, 5 Preemption is not helpful for scheduling."
60.1156,Event,ADDED,eval-sanitize-2-r2-091-h4bgm.18d3d152f4d5948d,"reason=FailedScheduling count=None msg=0/6 nodes are available: 1 c_wall violated: 3 conflicting context pair(s) with node memory, 5 node(s) had untolerated taint(s). no new claims to deallocate, preemption: 0/6 nodes are available: 1 No preemption victims found for incoming pod, 5 Preemption is not helpful for scheduling."
60.1158,Event,ADDED,eval-sanitize-2-r2-093-txhn5.18d3d1536979b9a8,"reason=FailedScheduling count=None msg=0/6 nodes are available: 1 c_wall violated: 1 conflicting context pair(s) with node memory, 5 node(s) had untolerated taint(s). no new claims to deallocate, preemption: 0/6 nodes are available: 1 No preemption victims found for incoming pod, 5 Preemption is not helpful for scheduling."
60.1161,Event,ADDED,eval-sanitize-2-r2-094-78hgf.18d3d153a4fc7c7e,"reason=FailedScheduling count=None msg=0/6 nodes are available: 1 c_wall violated: 1 conflicting context pair(s) with node memory, 5 node(s) had untolerated taint(s). no new claims to deallocate, preemption: 0/6 nodes are available: 1 No preemption victims found for incoming pod, 5 Preemption is not helpful for scheduling."
60.1163,Event,ADDED,eval-sanitize-2-r2-095-zv7gr.18d3d1549820f57d,"reason=FailedScheduling count=None msg=0/6 nodes are available: 1 c_wall violated: 1 conflicting context pair(s) with node memory, 5 node(s) had untolerated taint(s). no new claims to deallocate, preemption: 0/6 nodes are available: 1 No preemption victims found for incoming pod, 5 Preemption is not helpful for scheduling."
60.1165,Event,ADDED,eval-sanitize-2-r2-097-d62t4.18d3d1549c0ab2ae,"reason=FailedScheduling count=None msg=0/6 nodes are available: 1 c_wall violated: 1 conflicting context pair(s) with node memory, 5 node(s) had untolerated taint(s). no new claims to deallocate, preemption: 0/6 nodes are available: 1 No preemption victims found for incoming pod, 5 Preemption is not helpful for scheduling."
60.1173,Job,ADDED,eval-sanitize-2-r4-025,
60.1185,Pod,ADDED,eval-sanitize-2-r4-025-dphm6,phase=Succeeded node=kind-worker2
60.1188,Event,ADDED,eval-sanitize-2-r2-098-mbt7r.18d3d1549c321d24,"reason=FailedScheduling count=None msg=0/6 nodes are available: 1 c_wall violated: 1 conflicting context pair(s) with node memory, 5 node(s) had untolerated taint(s). no new claims to deallocate, preemption: 0/6 nodes are available: 1 No preemption victims found for incoming pod, 5 Preemption is not helpful for scheduling."
60.119,Event,ADDED,eval-sanitize-2-r4-000-8mtl8.18d3d1cf73318e61,reason=Scheduled count=None msg=Successfully assigned compute/eval-sanitize-2-r4-000-8mtl8 to kind-worker2
60.1192,Event,ADDED,eval-sanitize-2-r4-000-8mtl8.18d3d1cf8ca34b56,"reason=Pulled count=1 msg=Container image ""busybox:musl"" already present on machine"
60.12,Job,ADDED,eval-sanitize-2-r4-026,
60.1212,Pod,ADDED,eval-sanitize-2-r4-026-ltj94,phase=Succeeded node=kind-worker
60.1215,Event,ADDED,eval-sanitize-2-r4-000-8mtl8.18d3d1cf8dc6965d,reason=Created count=1 msg=Created container: task
60.1217,Event,ADDED,eval-sanitize-2-r4-000-8mtl8.18d3d1cf9187c84f,reason=Started count=1 msg=Started container task
60.122,Event,ADDED,eval-sanitize-2-r4-000.18d3d1cf72496d01,reason=SuccessfulCreate count=1 msg=Created pod: eval-sanitize-2-r4-000-8mtl8
60.1221,Event,ADDED,eval-sanitize-2-r4-000.18d3d1d2bd237607,reason=Completed count=1 msg=Job completed
60.1223,Event,ADDED,eval-sanitize-2-r4-001-n4msm.18d3d1cfac1d8d6b,reason=Scheduled count=None msg=Successfully assigned compute/eval-sanitize-2-r4-001-n4msm to kind-worker
60.1226,Event,ADDED,eval-sanitize-2-r4-001-n4msm.18d3d1cfc482ef12,"reason=Pulled count=1 msg=Container image ""busybox:musl"" already present on machine"
60.1228,Event,ADDED,eval-sanitize-2-r4-001-n4msm.18d3d1cfc591a3d6,reason=Created count=1 msg=Created container: task
60.1237,Job,ADDED,eval-sanitize-2-r4-027,
60.1239,Event,ADDED,eval-sanitize-2-r4-001-n4msm.18d3d1cfc7899120,reason=Started count=1 msg=Started container task
60.1242,Event,ADDED,eval-sanitize-2-r4-001.18d3d1cfab1ff093,reason=SuccessfulCreate count=1 msg=Created pod: eval-sanitize-2-r4-001-n4msm
60.1244,Event,ADDED,eval-sanitize-2-r4-001.18d3d1d2ea2182e1,reason=Completed count=1 msg=Job completed
60.1245,Event,ADDED,eval-sanitize-2-r4-002-z5bgl.18d3d1cfe77928d0,reason=Scheduled count=None msg=Successfully assigned compute/eval-sanitize-2-r4-002-z5bgl to kind-worker
60.1259,Pod,ADDED,eval-sanitize-2-r4-027-5cbcr,phase=Succeeded node=kind-worker
60.1269,Job,ADDED,eval-sanitize-2-r4-028,
60.1273,Event,ADDED,eval-sanitize-2-r4-002-z5bgl.18d3d1d000978f46,"reason=Pulled count=1 msg=Container image ""busybox:musl"" already present on machine"
60.1275,Event,ADDED,eval-sanitize-2-r4-002-z5bgl.18d3d1d001b20d7d,reason=Created count=1 msg=Created container: task
60.1277,Event,ADDED,eval-sanitize-2-r4-002-z5bgl.18d3d1d003c42dab,reason=Started count=1 msg=Started container task
60.1279,Event,ADDED,eval-sanitize-2-r4-002.18d3d1cfe6d435d4,reason=SuccessfulCreate count=1 msg=Created pod: eval-sanitize-2-r4-002-z5bgl
60.129,Pod,ADDED,eval-sanitize-2-r4-028-fth75,phase=Succeeded node=kind-worker
60.1294,Event,ADDED,eval-sanitize-2-r4-002.18d3d1d325f36d15,reason=Completed count=1 msg=Job completed
60.1295,Event,ADDED,eval-sanitize-2-r4-003-7hwjh.18d3d1d0229387b5,reason=Scheduled count=None msg=Successfully assigned compute/eval-sanitize-2-r4-003-7hwjh to kind-worker4
60.1298,Event,ADDED,eval-sanitize-2-r4-003-7hwjh.18d3d1d03c8eb47c,"reason=Pulled count=1 msg=Container image ""busybox:musl"" already present on machine"
60.1309,Pod,ADDED,eval-sanitize-2-r4-029-55cpp,phase=Succeeded node=kind-worker
60.1317,Job,ADDED,eval-sanitize-2-r4-029,
60.132,Event,ADDED,eval-sanitize-2-r4-003-7hwjh.18d3d1d03d9ad15d,reason=Created count=1 msg=Created container: task
60.1322,Event,ADDED,eval-sanitize-2-r4-003-7hwjh.18d3d1d03fdf1203,reason=Started count=1 msg=Started container task
60.1324,Event,ADDED,eval-sanitize-2-r4-003.18d3d1d02204d979,reason=SuccessfulCreate count=1 msg=Created pod: eval-sanitize-2-r4-003-7hwjh
60.1326,Event,ADDED,eval-sanitize-2-r4-003.18d3d1d35a78c0cf,reason=Completed count=1 msg=Job completed
60.1339,Pod,ADDED,eval-sanitize-2-r4-030-m9bv7,phase=Succeeded node=kind-worker2
60.1346,Job,ADDED,eval-sanitize-2-r4-030,
60.1349,Event,ADDED,eval-sanitize-2-r4-004-ttn6b.18d3d1d05e70a2e2,reason=Scheduled count=None msg=Successfully assigned compute/eval-sanitize-2-r4-004-ttn6b to kind-worker4
60.1351,Event,ADDED,eval-sanitize-2-r4-004-ttn6b.18d3d1d0786de56a,"reason=Pulled count=1 msg=Container image ""busybox:musl"" already present on machine"
60.1353,Event,ADDED,eval-sanitize-2-r4-004-ttn6b.18d3d1d0797286f9,reason=Created count=1 msg=Created container: task
60.1355,Event,ADDED,eval-sanitize-2-r4-004-ttn6b.18d3d1d07ddfdee5,reason=Started count=1 msg=Started container task
60.1361,Event,ADDED,eval-sanitize-2-r4-004.18d3d1d05dabacff,reason=SuccessfulCreate count=1 msg=Created pod: eval-sanitize-2-r4-004-ttn6b
60.1363,Event,ADDED,eval-sanitize-2-r4-004.18d3d1d3963b0ce0,reason=Completed count=1 msg=Job completed
60.1365,Event,ADDED,eval-sanitize-2-r4-005-hs6t9.18d3d1d099eae516,reason=Scheduled count=None msg=Successfully assigned compute/eval-sanitize-2-r4-005-hs6t9 to kind-worker5
60.1368,Event,ADDED,eval-sanitize-2-r4-005-hs6t9.18d3d1d0b2f6307d,"reason=Pulled count=1 msg=Container image ""busybox:musl"" already present on machine"
60.137,Event,ADDED,eval-sanitize-2-r4-005-hs6t9.18d3d1d0b40a5a4a,reason=Created count=1 msg=Created container: task
60.1371,Event,ADDED,eval-sanitize-2-r4-005-hs6t9.18d3d1d0b5d611f0,reason=Started count=1 msg=Started container task
60.1373,Event,ADDED,eval-sanitize-2-r4-005.18d3d1d0996eceac,reason=SuccessfulCreate count=1 msg=Created pod: eval-sanitize-2-r4-005-hs6t9
60.1387,Pod,ADDED,eval-sanitize-2-r4-031-88cfn,phase=Succeeded node=kind-worker4
60.1392,Event,ADDED,eval-sanitize-2-r4-005.18d3d1d3d20267fc,reason=Completed count=1 msg=Job completed
60.1394,Event,ADDED,eval-sanitize-2-r4-006-8fdtg.18d3d1d0d565b349,reason=Scheduled count=None msg=Successfully assigned compute/eval-sanitize-2-r4-006-8fdtg to kind-worker3
60.1396,Event,ADDED,eval-sanitize-2-r4-006-8fdtg.18d3d1d0ef35267e,"reason=Pulled count=1 msg=Container image ""busybox:musl"" already present on machine"
60.1398,Event,ADDED,eval-sanitize-2-r4-006-8fdtg.18d3d1d0f05e79fe,reason=Created count=1 msg=Created container: task
60.1409,Pod,ADDED,eval-sanitize-2-r4-032-jnkcf,phase=Succeeded node=kind-worker5
60.1417,Job,ADDED,eval-sanitize-2-r4-031,
60.142,Event,ADDED,eval-sanitize-2-r4-006-8fdtg.18d3d1d0f24e0321,reason=Started count=1 msg=Started container task
60.1422,Event,ADDED,eval-sanitize-2-r4-006.18d3d1d0d4f8c8f0,reason=SuccessfulCreate count=1 msg=Created pod: eval-sanitize-2-r4-006-8fdtg
60.1424,Event,ADDED,eval-sanitize-2-r4-006.18d3d1d40a6d06db,reason=Completed count=1 msg=Job completed
60.1427,Event,ADDED,eval-sanitize-2-r4-007-4mkhx.18d3d1d110c31533,"reason=FailedScheduling count=None msg=0/6 nodes are available: 6 node(s) had untolerated taint(s). no new claims to deallocate, preemption: 0/6 nodes are available: 6 Preemption is not helpful for scheduling."
60.1429,Event,ADDED,eval-sanitize-2-r4-007-4mkhx.18d3d1d2bfa311e7,reason=Scheduled count=None msg=Successfully assigned compute/eval-sanitize-2-r4-007-4mkhx to kind-worker2
60.1431,Event,ADDED,eval-sanitize-2-r4-007-4mkhx.18d3d1d2d9c3bd07,"reason=Pulled count=1 msg=Container image ""busybox:musl"" already present on machine"
60.1433,Event,ADDED,eval-sanitize-2-r4-007-4mkhx.18d3d1d2db14c308,reason=Created count=1 msg=Created container: task
60.1446,Pod,ADDED,eval-sanitize-2-r4-033-p9qml,phase=Succeeded node=kind-worker3
60.1454,Job,ADDED,eval-sanitize-2-r4-032,
60.1457,Event,ADDED,eval-sanitize-2-r4-007-4mkhx.18d3d1d2dd119ae6,reason=Started count=1 msg=Started container task
60.1474,Pod,ADDED,eval-sanitize-2-r4-034-bjrp7,phase=Succeeded node=kind-worker
60.1476,Event,ADDED,eval-sanitize-2-r4-007.18d3d1d110b2ca94,reason=SuccessfulCreate count=1 msg=Created pod: eval-sanitize-2-r4-007-4mkhx
60.1479,Event,ADDED,eval-sanitize-2-r4-007.18d3d1d602eb888c,reason=Completed count=1 msg=Job completed
60.1481,Event,ADDED,eval-sanitize-2-r4-008-f4zj6.18d3d1d14c54c7c6,"reason=FailedScheduling count=None msg=0/6 nodes are available: 6 node(s) had untolerated taint(s). no new claims to deallocate, preemption: 0/6 nodes are available: 6 Preemption is not helpful for scheduling."
60.149,Job,ADDED,eval-sanitize-2-r4-033,
60.1494,Event,ADDED,eval-sanitize-2-r4-008-f4zj6.18d3d1d2bfb6c928,"reason=FailedScheduling count=None msg=0/6 nodes are available: 1 c_wall violated: 1 conflicting context pair(s) with node memory, 5 node(s) had untolerated taint(s). no new claims to deallocate, preemption: 0/6 nodes are available: 1 No preemption victims found for incoming pod, 5 Preemption is not helpful for scheduling."
60.1496,Event,ADDED,eval-sanitize-2-r4-008-f4zj6.18d3d1d2c6b80729,"reason=FailedScheduling count=None msg=0/6 nodes are available: 1 c_wall violated: 2 conflicting context pair(s) with node memory, 5 node(s) had untolerated taint(s). no new claims to deallocate, preemption: 0/6 nodes are available: 1 No preemption victims found for incoming pod, 5 Preemption is not helpful for scheduling."
60.1499,Event,ADDED,eval-sanitize-2-r4-008-f4zj6.18d3d1d2c7bed357,"reason=FailedScheduling count=None msg=0/6 nodes are available: 1 c_wall violated: 2 conflicting context pair(s) with node memory, 5 node(s) had untolerated taint(s). no new claims to deallocate, preemption: 0/6 nodes are available: 1 No preemption victims found for incoming pod, 5 Preemption is not helpful for scheduling."
60.1511,Pod,ADDED,eval-sanitize-2-r4-035-d2wq7,phase=Succeeded node=kind-worker3
60.152,Job,ADDED,eval-sanitize-2-r4-034,
60.1526,Event,ADDED,eval-sanitize-2-r4-008-f4zj6.18d3d1d2ffd54703,reason=Scheduled count=None msg=Successfully assigned compute/eval-sanitize-2-r4-008-f4zj6 to kind-worker
60.1528,Event,ADDED,eval-sanitize-2-r4-008-f4zj6.18d3d1d317b1bdc3,"reason=Pulled count=1 msg=Container image ""busybox:musl"" already present on machine"
60.153,Event,ADDED,eval-sanitize-2-r4-008-f4zj6.18d3d1d31909f638,reason=Created count=1 msg=Created container: task
60.1543,Pod,ADDED,eval-sanitize-2-r4-036-5258c,phase=Succeeded node=kind-worker3
60.1552,Job,ADDED,eval-sanitize-2-r4-035,
60.1565,Pod,ADDED,eval-sanitize-2-r4-037-r774c,phase=Succeeded node=kind-worker
60.1567,Event,ADDED,eval-sanitize-2-r4-008-f4zj6.18d3d1d31ae34f08,reason=Started count=1 msg=Started container task
60.157,Event,ADDED,eval-sanitize-2-r4-008.18d3d1d14c489e22,reason=SuccessfulCreate count=1 msg=Created pod: eval-sanitize-2-r4-008-f4zj6
60.1572,Event,ADDED,eval-sanitize-2-r4-008.18d3d1d62ef6d6ea,reason=Completed count=1 msg=Job completed
60.1573,Event,ADDED,eval-sanitize-2-r4-009-mwm6s.18d3d1d187bcc462,"reason=FailedScheduling count=None msg=0/6 nodes are available: 6 node(s) had untolerated taint(s). no new claims to deallocate, preemption: 0/6 nodes are available: 6 Preemption is not helpful for scheduling."
60.1581,Job,ADDED,eval-sanitize-2-r4-036,
60.1593,Pod,ADDED,eval-sanitize-2-r4-038-2gqdk,phase=Succeeded node=kind-worker4
60.1595,Event,ADDED,eval-sanitize-2-r4-009-mwm6s.18d3d1d2c0cbfcfe,reason=Scheduled count=None msg=Successfully assigned compute/eval-sanitize-2-r4-009-mwm6s to kind-worker2
60.1597,Event,ADDED,eval-sanitize-2-r4-009-mwm6s.18d3d1d2db11968c,"reason=Pulled count=1 msg=Container image ""busybox:musl"" already present on machine"
60.16,Event,ADDED,eval-sanitize-2-r4-009-mwm6s.18d3d1d2de44c8f2,reason=Created count=1 msg=Created container: task
60.1606,Event,ADDED,eval-sanitize-2-r4-009-mwm6s.18d3d1d2e2089af0,reason=Started count=1 msg=Started container task
60.1609,Event,ADDED,eval-sanitize-2-r4-009.18d3d1d187b33210,reason=SuccessfulCreate count=1 msg=Created pod: eval-sanitize-2-r4-009-mwm6s
60.1613,Event,ADDED,eval-sanitize-2-r4-009.18d3d1d60258ed2a,reason=Completed count=1 msg=Job completed
60.1615,Event,ADDED,eval-sanitize-2-r4-010-wmh29.18d3d1d1c38aa9ff,"reason=FailedScheduling count=None msg=0/6 nodes are available: 6 node(s) had untolerated taint(s). no new claims to deallocate, preemption: 0/6 nodes are available: 6 Preemption is not helpful for scheduling."
60.1625,Job,ADDED,eval-sanitize-2-r4-037,
60.1637,Pod,ADDED,eval-sanitize-2-r4-039-62vq7,phase=Succeeded node=kind-worker5
60.1639,Event,ADDED,eval-sanitize-2-r4-010-wmh29.18d3d1d2c0f394aa,reason=Scheduled count=None msg=Successfully assigned compute/eval-sanitize-2-r4-010-wmh29 to kind-worker2
60.1641,Event,ADDED,eval-sanitize-2-r4-010-wmh29.18d3d1d2db2ddd06,"reason=Pulled count=1 msg=Container image ""busybox:musl"" already present on machine"
60.1643,Event,ADDED,eval-sanitize-2-r4-010-wmh29.18d3d1d2dee3e1fe,reason=Created count=1 msg=Created container: task
60.1646,Event,ADDED,eval-sanitize-2-r4-010-wmh29.18d3d1d2e4aeefdf,reason=Started count=1 msg=Started container task
60.1654,Job,ADDED,eval-sanitize-2-r4-038,
60.1665,Pod,ADDED,eval-sanitize-2-r4-040-j9n9j,phase=Succeeded node=kind-worker2
60.1668,Event,ADDED,eval-sanitize-2-r4-010.18d3d1d1c37fb500,reason=SuccessfulCreate count=1 msg=Created pod: eval-sanitize-2-r4-010-wmh29
60.167,Event,ADDED,eval-sanitize-2-r4-010.18d3d1d603520c81,reason=Completed count=1 msg=Job completed
60.1672,Event,ADDED,eval-sanitize-2-r4-011-8l98g.18d3d1d1ff22c7ad,"reason=FailedScheduling count=None msg=0/6 nodes are available: 6 node(s) had untolerated taint(s). no new claims to deallocate, preemption: 0/6 nodes are available: 6 Preemption is not helpful for scheduling."
60.1678,Event,ADDED,eval-sanitize-2-r4-011-8l98g.18d3d1d2c12d6c4d,reason=Scheduled count=None msg=Successfully assigned compute/eval-sanitize-2-r4-011-8l98g to kind-worker2
60.168,Event,ADDED,eval-sanitize-2-r4-011-8l98g.18d3d1d2db503a6c,"reason=Pulled count=1 msg=Container image ""busybox:musl"" already present on machine"
60.1682,Event,ADDED,eval-sanitize-2-r4-011-8l98g.18d3d1d2df40b3a2,reason=Created count=1 msg=Created container: task
60.1684,Event,ADDED,eval-sanitize-2-r4-011-8l98g.18d3d1d2e2fd3845,reason=Started count=1 msg=Started container task
60.1691,Job,ADDED,eval-sanitize-2-r4-039,
60.1703,Pod,ADDED,eval-sanitize-2-r4-041-d4w9s,phase=Succeeded node=kind-worker2
60.1706,Event,ADDED,eval-sanitize-2-r4-011.18d3d1d1ff1a3879,reason=SuccessfulCreate count=1 msg=Created pod: eval-sanitize-2-r4-011-8l98g
60.1708,Event,ADDED,eval-sanitize-2-r4-011.18d3d1d60382bbee,reason=Completed count=1 msg=Job completed
60.171,Event,ADDED,eval-sanitize-2-r4-012-s6sg6.18d3d1d23a7f4860,"reason=FailedScheduling count=None msg=0/6 nodes are available: 6 node(s) had untolerated taint(s). no new claims to deallocate, preemption: 0/6 nodes are available: 6 Preemption is not helpful for scheduling."
60.1717,Job,ADDED,eval-sanitize-2-r4-040,
60.173,Pod,ADDED,eval-sanitize-2-r4-042-2k9sd,phase=Succeeded node=kind-worker4
60.1733,Event,ADDED,eval-sanitize-2-r4-012-s6sg6.18d3d1d2c113957c,"reason=FailedScheduling count=None msg=0/6 nodes are available: 1 c_wall violated: 1 conflicting context pair(s) with node memory, 5 node(s) had untolerated taint(s). no new claims to deallocate, preemption: 0/6 nodes are available: 1 No preemption victims found for incoming pod, 5 Preemption is not helpful for scheduling."
60.1735,Event,ADDED,eval-sanitize-2-r4-012-s6sg6.18d3d1d2c73a0fe2,"reason=FailedScheduling count=None msg=0/6 nodes are available: 1 c_wall violated: 1 conflicting context pair(s) with node memory, 5 node(s) had untolerated taint(s). no new claims to deallocate, preemption: 0/6 nodes are available: 1 No preemption victims found for incoming pod, 5 Preemption is not helpful for scheduling."
60.1737,Event,ADDED,eval-sanitize-2-r4-012-s6sg6.18d3d1d2fe4b7502,reason=Scheduled count=None msg=Successfully assigned compute/eval-sanitize-2-r4-012-s6sg6 to kind-worker
60.1739,Event,ADDED,eval-sanitize-2-r4-012-s6sg6.18d3d1d316f591ae,"reason=Pulled count=1 msg=Container image ""busybox:musl"" already present on machine"
60.1741,Event,ADDED,eval-sanitize-2-r4-012-s6sg6.18d3d1d318559248,reason=Created count=1 msg=Created container: task
60.1743,Event,ADDED,eval-sanitize-2-r4-012-s6sg6.18d3d1d31a31e283,reason=Started count=1 msg=Started container task
60.1746,Event,ADDED,eval-sanitize-2-r4-012.18d3d1d23a733079,reason=SuccessfulCreate count=1 msg=Created pod: eval-sanitize-2-r4-012-s6sg6
60.1748,Event,ADDED,eval-sanitize-2-r4-012.18d3d1d62efa931b,reason=Completed count=1 msg=Job completed
60.175,Event,ADDED,eval-sanitize-2-r4-013-tw8qz.18d3d1d276d94114,"reason=FailedScheduling count=None msg=0/6 nodes are available: 6 node(s) had untolerated taint(s). no new claims to deallocate, preemption: 0/6 nodes are available: 6 Preemption is not helpful for scheduling."
60.1752,Event,ADDED,eval-sanitize-2-r4-013-tw8qz.18d3d1d2c27a3af7,"reason=FailedScheduling count=None msg=0/6 nodes are available: 1 c_wall violated: 1 conflicting context pair(s) with node memory, 5 node(s) had untolerated taint(s). no new claims to deallocate, preemption: 0/6 nodes are available: 1 No preemption victims found for incoming pod, 5 Preemption is not helpful for scheduling."
60.1754,Event,ADDED,eval-sanitize-2-r4-013-tw8qz.18d3d1d2c7997dc3,"reason=FailedScheduling count=None msg=0/6 nodes are available: 1 c_wall violated: 1 conflicting context pair(s) with node memory, 5 node(s) had untolerated taint(s). no new claims to deallocate, preemption: 0/6 nodes are available: 1 No preemption victims found for incoming pod, 5 Preemption is not helpful for scheduling."
60.1762,Job,ADDED,eval-sanitize-2-r4-041,
60.1774,Pod,ADDED,eval-sanitize-2-r4-043-rpkcz,phase=Succeeded node=kind-worker2
60.1782,Job,ADDED,eval-sanitize-2-r4-042,
60.1786,Event,ADDED,eval-sanitize-2-r4-013-tw8qz.18d3d1d30411c861,"reason=FailedScheduling count=None msg=0/6 nodes are available: 1 c_wall violated: 1 conflicting context pair(s) with node memory, 1 c_wall violated: 2 conflicting context pair(s) with node memory, 4 node(s) had untolerated taint(s). no new claims to deallocate, preemption: 0/6 nodes are available: 2 No preemption victims found for incoming pod, 4 Preemption is not helpful for scheduling."
60.1788,Event,ADDED,eval-sanitize-2-r4-013-tw8qz.18d3d1d305776835,"reason=FailedScheduling count=None msg=0/6 nodes are available: 1 c_wall violated: 1 conflicting context pair(s) with node memory, 1 c_wall violated: 2 conflicting context pair(s) with node memory, 4 node(s) had untolerated taint(s). no new claims to deallocate, preemption: 0/6 nodes are available: 2 No preemption victims found for incoming pod, 4 Preemption is not helpful for scheduling."
60.18,Pod,ADDED,eval-sanitize-2-r4-044-w9bj4,phase=Succeeded node=kind-worker2
60.1805,Event,ADDED,eval-sanitize-2-r4-013-tw8qz.18d3d1d3386a6e6d,"reason=FailedScheduling count=None msg=0/6 nodes are available: 1 c_wall violated: 2 conflicting context pair(s) with node memory, 5 node(s) had untolerated taint(s). no new claims to deallocate, preemption: 0/6 nodes are available: 1 No preemption victims found for incoming pod, 5 Preemption is not helpful for scheduling."
60.1808,Event,ADDED,eval-sanitize-2-r4-013-tw8qz.18d3d1d3614bf441,reason=Scheduled count=None msg=Successfully assigned compute/eval-sanitize-2-r4-013-tw8qz to kind-worker4
60.1811,Event,ADDED,eval-sanitize-2-r4-013-tw8qz.18d3d1d37b920147,"reason=Pulled count=1 msg=Container image ""busybox:musl"" already present on machine"
60.1813,Event,ADDED,eval-sanitize-2-r4-013-tw8qz.18d3d1d37ca338fc,reason=Created count=1 msg=Created container: task
60.182,Job,ADDED,eval-sanitize-2-r4-043,
60.1831,Pod,ADDED,eval-sanitize-2-r4-045-z8fq4,phase=Succeeded node=kind-worker4
60.1834,Event,ADDED,eval-sanitize-2-r4-013-tw8qz.18d3d1d37ea0fe75,reason=Started count=1 msg=Started container task
60.1836,Event,ADDED,eval-sanitize-2-r4-013.18d3d1d276d1e178,reason=SuccessfulCreate count=1 msg=Created pod: eval-sanitize-2-r4-013-tw8qz
60.1838,Event,ADDED,eval-sanitize-2-r4-013.18d3d1d69ea5405b,reason=Completed count=1 msg=Job completed
60.1846,Job,ADDED,eval-sanitize-2-r4-044,
60.1857,Pod,ADDED,eval-sanitize-2-r4-046-8lqh5,phase=Running node=kind-worker3
60.186,Event,ADDED,eval-sanitize-2-r4-014-vkvct.18d3d1d2b1f249b5,"reason=FailedScheduling count=None msg=0/6 nodes are available: 6 node(s) had untolerated taint(s). no new claims to deallocate, preemption: 0/6 nodes are available: 6 Preemption is not helpful for scheduling."
60.1862,Event,ADDED,eval-sanitize-2-r4-014-vkvct.18d3d1d2c3e16d0e,reason=Scheduled count=None msg=Successfully assigned compute/eval-sanitize-2-r4-014-vkvct to kind-worker2
60.1864,Event,ADDED,eval-sanitize-2-r4-014-vkvct.18d3d1d2dd172f81,"reason=Pulled count=1 msg=Container image ""busybox:musl"" already present on machine"
60.1866,Event,ADDED,eval-sanitize-2-r4-014-vkvct.18d3d1d2df72fd11,reason=Created count=1 msg=Created container: task
60.1869,Event,ADDED,eval-sanitize-2-r4-014-vkvct.18d3d1d2e2fd3828,reason=Started count=1 msg=Started container task
60.1871,Event,ADDED,eval-sanitize-2-r4-014.18d3d1d2b1e5d2fc,reason=SuccessfulCreate count=1 msg=Created pod: eval-sanitize-2-r4-014-vkvct
60.1873,Event,ADDED,eval-sanitize-2-r4-014.18d3d1d602a98f33,reason=Completed count=1 msg=Job completed
60.1875,Event,ADDED,eval-sanitize-2-r4-015-45f4d.18d3d1d2edaf4800,reason=Scheduled count=None msg=Successfully assigned compute/eval-sanitize-2-r4-015-45f4d to kind-worker2
60.1883,Job,ADDED,eval-sanitize-2-r4-045,
60.189,Job,ADDED,eval-sanitize-2-r4-046,
60.1901,Pod,ADDED,eval-sanitize-2-r4-047-567wm,phase=Running node=kind-worker4
60.1904,Event,ADDED,eval-sanitize-2-r4-015-45f4d.18d3d1d3079a560f,"reason=Pulled count=1 msg=Container image ""busybox:musl"" already present on machine"
60.1906,Event,ADDED,eval-sanitize-2-r4-015-45f4d.18d3d1d308a7b776,reason=Created count=1 msg=Created container: task
60.1908,Event,ADDED,eval-sanitize-2-r4-015-45f4d.18d3d1d30ab18eb5,reason=Started count=1 msg=Started container task
60.191,Event,ADDED,eval-sanitize-2-r4-015.18d3d1d2ed2651c7,reason=SuccessfulCreate count=1 msg=Created pod: eval-sanitize-2-r4-015-45f4d
60.1913,Event,ADDED,eval-sanitize-2-r4-015.18d3d1d63e2d54b2,reason=Completed count=1 msg=Job completed
60.1914,Event,ADDED,eval-sanitize-2-r4-016-cjlgc.18d3d1d32956d951,reason=Scheduled count=None msg=Successfully assigned compute/eval-sanitize-2-r4-016-cjlgc to kind-worker2
60.1916,Event,ADDED,eval-sanitize-2-r4-016-cjlgc.18d3d1d343345cde,"reason=Pulled count=1 msg=Container image ""busybox:musl"" already present on machine"
60.1927,Pod,ADDED,eval-sanitize-2-r4-048-l42kt,phase=Running node=kind-worker
60.1937,Event,ADDED,eval-sanitize-2-r4-016-cjlgc.18d3d1d34443630a,reason=Created count=1 msg=Created container: task
60.1939,Event,ADDED,eval-sanitize-2-r4-016-cjlgc.18d3d1d348eb5d4e,reason=Started count=1 msg=Started container task
60.1941,Event,ADDED,eval-sanitize-2-r4-016.18d3d1d328aba4d6,reason=SuccessfulCreate count=1 msg=Created pod: eval-sanitize-2-r4-016-cjlgc
60.1943,Event,ADDED,eval-sanitize-2-r4-016.18d3d1d67a8e3978,reason=Completed count=1 msg=Job completed
60.1947,Event,ADDED,eval-sanitize-2-r4-017-mnp4k.18d3d1d365250f48,reason=Scheduled count=None msg=Successfully assigned compute/eval-sanitize-2-r4-017-mnp4k to kind-worker4
60.1949,Event,ADDED,eval-sanitize-2-r4-017-mnp4k.18d3d1d37dcc5f14,"reason=Pulled count=1 msg=Container image ""busybox:musl"" already present on machine"
60.1951,Event,ADDED,eval-sanitize-2-r4-017-mnp4k.18d3d1d37f123a82,reason=Created count=1 msg=Created container: task
60.1954,Job,ADDED,eval-sanitize-2-r4-047,
60.1967,Pod,ADDED,eval-sanitize-2-r4-049-2mqtp,phase=Running node=kind-worker4
60.1971,Event,ADDED,eval-sanitize-2-r4-017-mnp4k.18d3d1d380d6e240,reason=Started count=1 msg=Started container task
60.1973,Event,ADDED,eval-sanitize-2-r4-017.18d3d1d36464a2ee,reason=SuccessfulCreate count=1 msg=Created pod: eval-sanitize-2-r4-017-mnp4k
60.1975,Event,ADDED,eval-sanitize-2-r4-017.18d3d1d69e3fbd76,reason=Completed count=1 msg=Job completed
60.1977,Event,ADDED,eval-sanitize-2-r4-018-f6rrd.18d3d1d3a06fcc5c,"reason=FailedScheduling count=None msg=0/6 nodes are available: 1 c_wall violated: 1 conflicting context pair(s) with node memory, 5 node(s) had untolerated taint(s). no new claims to deallocate, preemption: 0/6 nodes are available: 1 No preemption victims found for incoming pod, 5 Preemption is not helpful for scheduling."
60.1984,Job,ADDED,eval-sanitize-2-r4-048,
60.1995,Pod,ADDED,eval-sanitize-2-r4-050-r2sx8,phase=Running node=kind-worker2
60.1999,Event,ADDED,eval-sanitize-2-r4-018-f6rrd.18d3d1d3a0e9f5af,"reason=FailedScheduling count=None msg=0/6 nodes are available: 1 c_wall violated: 1 conflicting context pair(s) with node memory, 5 node(s) had untolerated taint(s). no new claims to deallocate, preemption: 0/6 nodes are available: 1 No preemption victims found for incoming pod, 5 Preemption is not helpful for scheduling."
60.2001,Event,ADDED,eval-sanitize-2-r4-018-f6rrd.18d3d1d3aaa9a88a,reason=Scheduled count=None msg=Successfully assigned compute/eval-sanitize-2-r4-018-f6rrd to kind-worker5
60.2003,Event,ADDED,eval-sanitize-2-r4-018-f6rrd.18d3d1d3c2fcd625,"reason=Pulled count=1 msg=Container image ""busybox:musl"" already present on machine"
60.2006,Event,ADDED,eval-sanitize-2-r4-018-f6rrd.18d3d1d3c4150845,reason=Created count=1 msg=Created container: task
60.2008,Event,ADDED,eval-sanitize-2-r4-018-f6rrd.18d3d1d3c5f6280f,reason=Started count=1 msg=Started container task
60.201,Event,ADDED,eval-sanitize-2-r4-018.18d3d1d3a02d1f35,reason=SuccessfulCreate count=1 msg=Created pod: eval-sanitize-2-r4-018-f6rrd
60.2011,Event,ADDED,eval-sanitize-2-r4-018.18d3d1d6d9673c9f,reason=Completed count=1 msg=Job completed
60.2019,Job,ADDED,eval-sanitize-2-r4-049,
60.2021,Event,ADDED,eval-sanitize-2-r4-019-5xr88.18d3d1d3dbb59ba4,"reason=FailedScheduling count=None msg=0/6 nodes are available: 1 c_wall violated: 1 conflicting context pair(s) with node memory, 5 node(s) had untolerated taint(s). no new claims to deallocate, preemption: 0/6 nodes are available: 1 No preemption victims found for incoming pod, 5 Preemption is not helpful for scheduling."
60.2023,Event,ADDED,eval-sanitize-2-r4-019-5xr88.18d3d1d3dc3fc163,"reason=FailedScheduling count=None msg=0/6 nodes are available: 1 c_wall violated: 1 conflicting context pair(s) with node memory, 5 node(s) had untolerated taint(s). no new claims to deallocate, preemption: 0/6 nodes are available: 1 No preemption victims found for incoming pod, 5 Preemption is not helpful for scheduling."
60.2026,Event,ADDED,eval-sanitize-2-r4-019-5xr88.18d3d1d3ea888003,reason=Scheduled count=None msg=Successfully assigned compute/eval-sanitize-2-r4-019-5xr88 to kind-worker3
60.2038,Pod,ADDED,eval-sanitize-2-r4-051-bcxdv,phase=Running node=kind-worker
60.2045,Job,ADDED,eval-sanitize-2-r4-050,
60.2048,Event,ADDED,eval-sanitize-2-r4-019-5xr88.18d3d1d4034b76c2,"reason=Pulled count=1 msg=Container image ""busybox:musl"" already present on machine"
60.205,Event,ADDED,eval-sanitize-2-r4-019-5xr88.18d3d1d40451acbe,reason=Created count=1 msg=Created container: task
60.2052,Event,ADDED,eval-sanitize-2-r4-019-5xr88.18d3d1d4063a02d1,reason=Started count=1 msg=Started container task
60.2054,Event,ADDED,eval-sanitize-2-r4-019.18d3d1d3db776fff,reason=SuccessfulCreate count=1 msg=Created pod: eval-sanitize-2-r4-019-5xr88
60.2065,Pod,ADDED,eval-sanitize-2-r4-052-v8g6t,phase=Running node=kind-worker5
60.2072,Pod,ADDED,eval-sanitize-2-r4-053-h944b,phase=Pending node=None
60.2076,Event,ADDED,eval-sanitize-2-r4-019.18d3d1d74ed07ef6,reason=Completed count=1 msg=Job completed
60.2077,Event,ADDED,eval-sanitize-2-r4-020-qv5qd.18d3d1d41853ee61,reason=Scheduled count=None msg=Successfully assigned compute/eval-sanitize-2-r4-020-qv5qd to kind-worker3
60.2079,Event,ADDED,eval-sanitize-2-r4-020-qv5qd.18d3d1d43139db09,"reason=Pulled count=1 msg=Container image ""busybox:musl"" already present on machine"
60.2085,Job,ADDED,eval-sanitize-2-r4-051,
60.2088,Event,ADDED,eval-sanitize-2-r4-020-qv5qd.18d3d1d4324669a5,reason=Created count=1 msg=Created container: task
60.209,Event,ADDED,eval-sanitize-2-r4-020-qv5qd.18d3d1d43411f926,reason=Started count=1 msg=Started container task
60.2093,Event,ADDED,eval-sanitize-2-r4-020.18d3d1d4173f9673,reason=SuccessfulCreate count=1 msg=Created pod: eval-sanitize-2-r4-020-qv5qd
60.2095,Event,ADDED,eval-sanitize-2-r4-020.18d3d1d74ef661a5,reason=Completed count=1 msg=Job completed
60.2104,Job,ADDED,eval-sanitize-2-r4-052,
60.2153,Pod,ADDED,eval-sanitize-2-r4-054-bp59m,phase=Running node=kind-worker2
60.2157,Event,ADDED,eval-sanitize-2-r4-021-vzk2p.18d3d1d453760ab8,"reason=FailedScheduling count=None msg=0/6 nodes are available: 1 c_wall violated: 1 conflicting context pair(s) with node memory, 5 node(s) had untolerated taint(s). no new claims to deallocate, preemption: 0/6 nodes are available: 1 No preemption victims found for incoming pod, 5 Preemption is not helpful for scheduling."
60.216,Event,ADDED,eval-sanitize-2-r4-021-vzk2p.18d3d1d453ff2018,"reason=FailedScheduling count=None msg=0/6 nodes are available: 1 c_wall violated: 1 conflicting context pair(s) with node memory, 5 node(s) had untolerated taint(s). no new claims to deallocate, preemption: 0/6 nodes are available: 1 No preemption victims found for incoming pod, 5 Preemption is not helpful for scheduling."
60.2161,Event,ADDED,eval-sanitize-2-r4-021-vzk2p.18d3d1d5e39ea894,reason=Scheduled count=None msg=Successfully assigned compute/eval-sanitize-2-r4-021-vzk2p to kind-worker
60.2164,Event,ADDED,eval-sanitize-2-r4-021-vzk2p.18d3d1d5fd1ef9cf,"reason=Pulled count=1 msg=Container image ""busybox:musl"" already present on machine"
60.2165,Event,ADDED,eval-sanitize-2-r4-021-vzk2p.18d3d1d5fedd1abc,reason=Created count=1 msg=Created container: task
60.2167,Event,ADDED,eval-sanitize-2-r4-021-vzk2p.18d3d1d60877c386,reason=Started count=1 msg=Started container task
60.217,Event,ADDED,eval-sanitize-2-r4-021.18d3d1d45335cbd8,reason=SuccessfulCreate count=1 msg=Created pod: eval-sanitize-2-r4-021-vzk2p
60.2182,Pod,ADDED,eval-sanitize-2-r4-055-dkvq4,phase=Running node=kind-worker5
60.2188,Job,ADDED,eval-sanitize-2-r4-053,
60.2191,Event,ADDED,eval-sanitize-2-r4-021.18d3d1d8fe17e920,reason=Completed count=1 msg=Job completed
60.2193,Event,ADDED,eval-sanitize-2-r4-022-kvzd5.18d3d1d48eb85a27,"reason=FailedScheduling count=None msg=0/6 nodes are available: 6 node(s) had untolerated taint(s). no new claims to deallocate, preemption: 0/6 nodes are available: 6 Preemption is not helpful for scheduling."
60.2195,Event,ADDED,eval-sanitize-2-r4-022-kvzd5.18d3d1d5e3d7d77c,"reason=FailedScheduling count=None msg=0/6 nodes are available: 1 c_wall violated: 1 conflicting context pair(s) with node memory, 5 node(s) had untolerated taint(s). no new claims to deallocate, preemption: 0/6 nodes are available: 1 No preemption victims found for incoming pod, 5 Preemption is not helpful for scheduling."
60.2208,Pod,ADDED,eval-sanitize-2-r4-056-tb4xl,phase=Running node=kind-worker2
60.2214,Job,ADDED,eval-sanitize-2-r4-054,
60.2216,Event,ADDED,eval-sanitize-2-r4-022-kvzd5.18d3d1d5e73adbea,"reason=FailedScheduling count=None msg=0/6 nodes are available: 1 c_wall violated: 2 conflicting context pair(s) with node memory, 5 node(s) had untolerated taint(s). no new claims to deallocate, preemption: 0/6 nodes are available: 1 No preemption victims found for incoming pod, 5 Preemption is not helpful for scheduling."
60.2219,Event,ADDED,eval-sanitize-2-r4-022-kvzd5.18d3d1d5ec85d97f,"reason=FailedScheduling count=None msg=0/6 nodes are available: 1 c_wall violated: 2 conflicting context pair(s) with node memory, 5 node(s) had untolerated taint(s). no new claims to deallocate, preemption: 0/6 nodes are available: 1 No preemption victims found for incoming pod, 5 Preemption is not helpful for scheduling."
60.2221,Event,ADDED,eval-sanitize-2-r4-022-kvzd5.18d3d1d6388cd956,"reason=FailedScheduling count=None msg=0/6 nodes are available: 1 c_wall violated: 1 conflicting context pair(s) with node memory, 1 c_wall violated: 2 conflicting context pair(s) with node memory, 4 node(s) had untolerated taint(s). no new claims to deallocate, preemption: 0/6 nodes are available: 2 No preemption victims found for incoming pod, 4 Preemption is not helpful for scheduling."
60.2233,Pod,ADDED,eval-sanitize-2-r4-057-58mc5,phase=Running node=kind-worker
60.2241,Pod,ADDED,eval-sanitize-2-r4-058-qlc2v,phase=Pending node=None
60.2244,Event,ADDED,eval-sanitize-2-r4-022-kvzd5.18d3d1d654d4bf4a,reason=Scheduled count=None msg=Successfully assigned compute/eval-sanitize-2-r4-022-kvzd5 to kind-worker4
60.2245,Event,ADDED,eval-sanitize-2-r4-022-kvzd5.18d3d1d66d38dd26,"reason=Pulled count=1 msg=Container image ""busybox:musl"" already present on machine"
60.2248,Event,ADDED,eval-sanitize-2-r4-022-kvzd5.18d3d1d66f0e5981,reason=Created count=1 msg=Created container: task
60.225,Event,ADDED,eval-sanitize-2-r4-022-kvzd5.18d3d1d67377c669,reason=Started count=1 msg=Started container task
60.2256,Job,ADDED,eval-sanitize-2-r4-055,
60.2265,Job,ADDED,eval-sanitize-2-r4-056,
60.2268,Event,ADDED,eval-sanitize-2-r4-022.18d3d1d48eaba683,reason=SuccessfulCreate count=1 msg=Created pod: eval-sanitize-2-r4-022-kvzd5
60.227,Event,ADDED,eval-sanitize-2-r4-022.18d3d1d9a73152b0,reason=Completed count=1 msg=Job completed
60.2272,Event,ADDED,eval-sanitize-2-r4-023-6hkqq.18d3d1d4cacdd3b6,"reason=FailedScheduling count=None msg=0/6 nodes are available: 6 node(s) had untolerated taint(s). no new claims to deallocate, preemption: 0/6 nodes are available: 6 Preemption is not helpful for scheduling."
60.2279,Pod,ADDED,eval-sanitize-2-r4-059-rrppw,phase=Pending node=None
60.2281,Event,ADDED,eval-sanitize-2-r4-023-6hkqq.18d3d1d5e4a95029,reason=Scheduled count=None msg=Successfully assigned compute/eval-sanitize-2-r4-023-6hkqq to kind-worker
60.2283,Event,ADDED,eval-sanitize-2-r4-023-6hkqq.18d3d1d5fdfef94d,"reason=Pulled count=1 msg=Container image ""busybox:musl"" already present on machine"
60.2285,Event,ADDED,eval-sanitize-2-r4-023-6hkqq.18d3d1d5ff63accd,reason=Created count=1 msg=Created container: task
60.2287,Event,ADDED,eval-sanitize-2-r4-023-6hkqq.18d3d1d60879f95b,reason=Started count=1 msg=Started container task
60.2295,Job,ADDED,eval-sanitize-2-r4-057,
60.2298,Event,ADDED,eval-sanitize-2-r4-023.18d3d1d4cabfec63,reason=SuccessfulCreate count=1 msg=Created pod: eval-sanitize-2-r4-023-6hkqq
60.23,Event,ADDED,eval-sanitize-2-r4-023.18d3d1d937af4d6b,reason=Completed count=1 msg=Job completed
60.2302,Event,ADDED,eval-sanitize-2-r4-024-m4dwq.18d3d1d505c5fbaf,"reason=FailedScheduling count=None msg=0/6 nodes are available: 6 node(s) had untolerated taint(s). no new claims to deallocate, preemption: 0/6 nodes are available: 6 Preemption is not helpful for scheduling."
60.2303,Event,ADDED,eval-sanitize-2-r4-024-m4dwq.18d3d1d5e49b11a8,"reason=FailedScheduling count=None msg=0/6 nodes are available: 1 c_wall violated: 2 conflicting context pair(s) with node memory, 5 node(s) had untolerated taint(s). no new claims to deallocate, preemption: 0/6 nodes are available: 1 No preemption victims found for incoming pod, 5 Preemption is not helpful for scheduling."
60.231,Pod,ADDED,eval-sanitize-2-r4-060-vvv88,phase=Pending node=None
60.2316,Job,ADDED,eval-sanitize-2-r4-058,
60.2319,Event,ADDED,eval-sanitize-2-r4-024-m4dwq.18d3d1d5e7b40e24,"reason=FailedScheduling count=None msg=0/6 nodes are available: 1 c_wall violated: 2 conflicting context pair(s) with node memory, 5 node(s) had untolerated taint(s). no new claims to deallocate, preemption: 0/6 nodes are available: 1 No preemption victims found for incoming pod, 5 Preemption is not helpful for scheduling."
60.2321,Event,ADDED,eval-sanitize-2-r4-024-m4dwq.18d3d1d62cd945ad,reason=Scheduled count=None msg=Successfully assigned compute/eval-sanitize-2-r4-024-m4dwq to kind-worker2
60.2323,Event,ADDED,eval-sanitize-2-r4-024-m4dwq.18d3d1d6459c1bf1,"reason=Pulled count=1 msg=Container image ""busybox:musl"" already present on machine"
60.2326,Event,ADDED,eval-sanitize-2-r4-024-m4dwq.18d3d1d646b50d92,reason=Created count=1 msg=Created container: task
60.2328,Event,ADDED,eval-sanitize-2-r4-024-m4dwq.18d3d1d648b2aeed,reason=Started count=1 msg=Started container task
60.233,Event,ADDED,eval-sanitize-2-r4-024.18d3d1d505ba90ce,reason=SuccessfulCreate count=1 msg=Created pod: eval-sanitize-2-r4-024-m4dwq
60.2332,Event,ADDED,eval-sanitize-2-r4-024.18d3d1d98310b9dc,reason=Completed count=1 msg=Job completed
60.234,Pod,MODIFIED,eval-sanitize-2-r4-060-vvv88,phase=Pending node=None
60.2343,Event,ADDED,eval-sanitize-2-r4-025-dphm6.18d3d1d54162aab5,"reason=FailedScheduling count=None msg=0/6 nodes are available: 6 node(s) had untolerated taint(s). no new claims to deallocate, preemption: 0/6 nodes are available: 6 Preemption is not helpful for scheduling."
60.2345,Event,ADDED,eval-sanitize-2-r4-025-dphm6.18d3d1d5e52c9195,"reason=FailedScheduling count=None msg=0/6 nodes are available: 1 c_wall violated: 2 conflicting context pair(s) with node memory, 5 node(s) had untolerated taint(s). no new claims to deallocate, preemption: 0/6 nodes are available: 1 No preemption victims found for incoming pod, 5 Preemption is not helpful for scheduling."
60.2347,Event,ADDED,eval-sanitize-2-r4-025-dphm6.18d3d1d5ec4c887d,"reason=FailedScheduling count=None msg=0/6 nodes are available: 1 c_wall violated: 2 conflicting context pair(s) with node memory, 5 node(s) had untolerated taint(s). no new claims to deallocate, preemption: 0/6 nodes are available: 1 No preemption victims found for incoming pod, 5 Preemption is not helpful for scheduling."
60.2353,Job,ADDED,eval-sanitize-2-r4-059,
60.2358,Event,ADDED,eval-sanitize-2-r4-025-dphm6.18d3d1d62eee2ea6,reason=Scheduled count=None msg=Successfully assigned compute/eval-sanitize-2-r4-025-dphm6 to kind-worker2
60.236,Event,ADDED,eval-sanitize-2-r4-025-dphm6.18d3d1d64788178c,"reason=Pulled count=1 msg=Container image ""busybox:musl"" already present on machine"
60.2362,Event,ADDED,eval-sanitize-2-r4-025-dphm6.18d3d1d648c582a4,reason=Created count=1 msg=Created container: task
60.2367,Job,ADDED,eval-sanitize-2-r4-060,
60.2371,Event,ADDED,eval-sanitize-2-r4-025-dphm6.18d3d1d64aa20063,reason=Started count=1 msg=Started container task
60.2373,Event,ADDED,eval-sanitize-2-r4-025.18d3d1d541516615,reason=SuccessfulCreate count=1 msg=Created pod: eval-sanitize-2-r4-025-dphm6
60.2375,Event,ADDED,eval-sanitize-2-r4-025.18d3d1d982ce037b,reason=Completed count=1 msg=Job completed
60.2376,Event,ADDED,eval-sanitize-2-r4-026-ltj94.18d3d1d57ccb4f94,"reason=FailedScheduling count=None msg=0/6 nodes are available: 6 node(s) had untolerated taint(s). no new claims to deallocate, preemption: 0/6 nodes are available: 6 Preemption is not helpful for scheduling."
60.2378,Event,ADDED,eval-sanitize-2-r4-026-ltj94.18d3d1d5e64a239e,reason=Scheduled count=None msg=Successfully assigned compute/eval-sanitize-2-r4-026-ltj94 to kind-worker
60.2381,Event,ADDED,eval-sanitize-2-r4-026-ltj94.18d3d1d607d29604,"reason=Pulled count=1 msg=Container image ""busybox:musl"" already present on machine"
60.2383,Event,ADDED,eval-sanitize-2-r4-026-ltj94.18d3d1d60a05887e,reason=Created count=1 msg=Created container: task
60.2389,Job,MODIFIED,eval-sanitize-2-r4-060,
60.2391,Event,ADDED,eval-sanitize-2-r4-026-ltj94.18d3d1d60e75aee9,reason=Started count=1 msg=Started container task
60.2393,Event,ADDED,eval-sanitize-2-r4-026.18d3d1d57cc165c1,reason=SuccessfulCreate count=1 msg=Created pod: eval-sanitize-2-r4-026-ltj94
60.2395,Event,ADDED,eval-sanitize-2-r4-026.18d3d1d93843a73c,reason=Completed count=1 msg=Job completed
60.2399,Event,ADDED,eval-sanitize-2-r4-027-5cbcr.18d3d1d5b8cd5f4e,"reason=FailedScheduling count=None msg=0/6 nodes are available: 6 node(s) had untolerated taint(s). no new claims to deallocate, preemption: 0/6 nodes are available: 6 Preemption is not helpful for scheduling."
60.2402,Event,ADDED,eval-sanitize-2-r4-027-5cbcr.18d3d1d5e6a5a00d,reason=Scheduled count=None msg=Successfully assigned compute/eval-sanitize-2-r4-027-5cbcr to kind-worker
60.2403,Event,ADDED,eval-sanitize-2-r4-027-5cbcr.18d3d1d607f9b31a,"reason=Pulled count=1 msg=Container image ""busybox:musl"" already present on machine"
60.2406,Event,ADDED,eval-sanitize-2-r4-027-5cbcr.18d3d1d60a460fe6,reason=Created count=1 msg=Created container: task
60.2408,Event,ADDED,eval-sanitize-2-r4-027-5cbcr.18d3d1d60e756ac5,reason=Started count=1 msg=Started container task
60.2417,Event,ADDED,eval-sanitize-2-r4-027.18d3d1d5b8bedee4,reason=SuccessfulCreate count=1 msg=Created pod: eval-sanitize-2-r4-027-5cbcr
60.2419,Event,ADDED,eval-sanitize-2-r4-027.18d3d1d8fe8fc392,reason=Completed count=1 msg=Job completed
60.2421,Event,ADDED,eval-sanitize-2-r4-028-fth75.18d3d1d5f4945199,reason=Scheduled count=None msg=Successfully assigned compute/eval-sanitize-2-r4-028-fth75 to kind-worker
60.2427,Event,ADDED,eval-sanitize-2-r4-028-fth75.18d3d1d60f0d084f,"reason=Pulled count=1 msg=Container image ""busybox:musl"" already present on machine"
60.2429,Event,ADDED,eval-sanitize-2-r4-028-fth75.18d3d1d6101b1bf1,reason=Created count=1 msg=Created container: task
60.2432,Event,ADDED,eval-sanitize-2-r4-028-fth75.18d3d1d614c62375,reason=Started count=1 msg=Started container task
60.2435,Event,ADDED,eval-sanitize-2-r4-028.18d3d1d5f41b3aa8,reason=SuccessfulCreate count=1 msg=Created pod: eval-sanitize-2-r4-028-fth75
60.2439,Event,ADDED,eval-sanitize-2-r4-028.18d3d1d8fe8f5491,reason=Completed count=1 msg=Job completed
60.2442,Event,ADDED,eval-sanitize-2-r4-029-55cpp.18d3d1d63570b265,reason=Scheduled count=None msg=Successfully assigned compute/eval-sanitize-2-r4-029-55cpp to kind-worker
60.2445,Event,ADDED,eval-sanitize-2-r4-029-55cpp.18d3d1d64c832524,"reason=Pulled count=1 msg=Container image ""busybox:musl"" already present on machine"
60.2447,Event,ADDED,eval-sanitize-2-r4-029-55cpp.18d3d1d64d9b851b,reason=Created count=1 msg=Created container: task
60.245,Event,ADDED,eval-sanitize-2-r4-029-55cpp.18d3d1d6512c045d,reason=Started count=1 msg=Started container task
60.2452,Event,ADDED,eval-sanitize-2-r4-029.18d3d1d631afe88f,reason=SuccessfulCreate count=1 msg=Created pod: eval-sanitize-2-r4-029-55cpp
60.2454,Event,ADDED,eval-sanitize-2-r4-029.18d3d1d938c03e30,reason=Completed count=1 msg=Job completed
60.2456,Event,ADDED,eval-sanitize-2-r4-030-m9bv7.18d3d1d66d1820cc,reason=Scheduled count=None msg=Successfully assigned compute/eval-sanitize-2-r4-030-m9bv7 to kind-worker2
60.2459,Event,ADDED,eval-sanitize-2-r4-030-m9bv7.18d3d1d6866c4b63,"reason=Pulled count=1 msg=Container image ""busybox:musl"" already present on machine"
60.2461,Event,ADDED,eval-sanitize-2-r4-030-m9bv7.18d3d1d6877bb634,reason=Created count=1 msg=Created container: task
60.2463,Event,ADDED,eval-sanitize-2-r4-030-m9bv7.18d3d1d68cd1db40,reason=Started count=1 msg=Started container task
60.2467,Event,ADDED,eval-sanitize-2-r4-030.18d3d1d66ba47e82,reason=SuccessfulCreate count=1 msg=Created pod: eval-sanitize-2-r4-030-m9bv7
60.2469,Event,ADDED,eval-sanitize-2-r4-030.18d3d1d9befea275,reason=Completed count=1 msg=Job completed
60.2472,Event,ADDED,eval-sanitize-2-r4-031-88cfn.18d3d1d6a83c79fd,reason=Scheduled count=None msg=Successfully assigned compute/eval-sanitize-2-r4-031-88cfn to kind-worker4
60.2474,Event,ADDED,eval-sanitize-2-r4-031-88cfn.18d3d1d6c147087b,"reason=Pulled count=1 msg=Container image ""busybox:musl"" already present on machine"
60.2477,Event,ADDED,eval-sanitize-2-r4-031-88cfn.18d3d1d6c265b40d,reason=Created count=1 msg=Created container: task
60.248,Event,ADDED,eval-sanitize-2-r4-031-88cfn.18d3d1d6c635d124,reason=Started count=1 msg=Started container task
60.2483,Event,ADDED,eval-sanitize-2-r4-031.18d3d1d6a769177e,reason=SuccessfulCreate count=1 msg=Created pod: eval-sanitize-2-r4-031-88cfn
60.2485,Event,ADDED,eval-sanitize-2-r4-031.18d3d1d9e2db3b50,reason=Completed count=1 msg=Job completed
60.2489,Event,ADDED,eval-sanitize-2-r4-032-jnkcf.18d3d1d6e2a9b41d,reason=Scheduled count=None msg=Successfully assigned compute/eval-sanitize-2-r4-032-jnkcf to kind-worker5
60.2491,Event,ADDED,eval-sanitize-2-r4-032-jnkcf.18d3d1d6fc58839c,"reason=Pulled count=1 msg=Container image ""busybox:musl"" already present on machine"
60.2493,Event,ADDED,eval-sanitize-2-r4-032-jnkcf.18d3d1d6fd669aae,reason=Created count=1 msg=Created container: task
60.2495,Event,ADDED,eval-sanitize-2-r4-032-jnkcf.18d3d1d701251d42,reason=Started count=1 msg=Started container task
60.2497,Event,ADDED,eval-sanitize-2-r4-032.18d3d1d6e254f278,reason=SuccessfulCreate count=1 msg=Created pod: eval-sanitize-2-r4-032-jnkcf
60.2499,Event,ADDED,eval-sanitize-2-r4-032.18d3d1da1db2eb1a,reason=Completed count=1 msg=Job completed
60.2501,Event,ADDED,eval-sanitize-2-r4-033-p9qml.18d3d1d71ec58d81,"reason=FailedScheduling count=None msg=0/6 nodes are available: 6 node(s) had untolerated taint(s). no new claims to deallocate, preemption: 0/6 nodes are available: 6 Preemption is not helpful for scheduling."
60.2504,Event,ADDED,eval-sanitize-2-r4-033-p9qml.18d3d1d756cf7e46,reason=Scheduled count=None msg=Successfully assigned compute/eval-sanitize-2-r4-033-p9qml to kind-worker3
60.2506,Event,ADDED,eval-sanitize-2-r4-033-p9qml.18d3d1d76fcc485c,"reason=Pulled count=1 msg=Container image ""busybox:musl"" already present on machine"
60.2508,Event,ADDED,eval-sanitize-2-r4-033-p9qml.18d3d1d770cc7fb5,reason=Created count=1 msg=Created container: task
60.2514,Event,ADDED,eval-sanitize-2-r4-033-p9qml.18d3d1d772d5c5c4,reason=Started count=1 msg=Started container task
60.2517,Event,ADDED,eval-sanitize-2-r4-033.18d3d1d71ebc6d6c,reason=SuccessfulCreate count=1 msg=Created pod: eval-sanitize-2-r4-033-p9qml
60.2519,Event,ADDED,eval-sanitize-2-r4-033.18d3d1da926891a5,reason=Completed count=1 msg=Job completed
60.252,Event,ADDED,eval-sanitize-2-r4-034-bjrp7.18d3d1d75a169f4d,"reason=FailedScheduling count=None msg=0/6 nodes are available: 1 c_wall violated: 1 conflicting context pair(s) with node memory, 5 node(s) had untolerated taint(s). no new claims to deallocate, preemption: 0/6 nodes are available: 1 No preemption victims found for incoming pod, 5 Preemption is not helpful for scheduling."
60.2524,Event,ADDED,eval-sanitize-2-r4-034-bjrp7.18d3d1d75abc9dce,"reason=FailedScheduling count=None msg=0/6 nodes are available: 1 c_wall violated: 1 conflicting context pair(s) with node memory, 5 node(s) had untolerated taint(s). no new claims to deallocate, preemption: 0/6 nodes are available: 1 No preemption victims found for incoming pod, 5 Preemption is not helpful for scheduling."
60.2526,Event,ADDED,eval-sanitize-2-r4-034-bjrp7.18d3d1d7979ca4f8,"reason=FailedScheduling count=None msg=0/6 nodes are available: 1 c_wall violated: 2 conflicting context pair(s) with node memory, 5 node(s) had untolerated taint(s). no new claims to deallocate, preemption: 0/6 nodes are available: 1 No preemption victims found for incoming pod, 5 Preemption is not helpful for scheduling."
60.2528,Event,ADDED,eval-sanitize-2-r4-034-bjrp7.18d3d1d7d31adb0e,"reason=FailedScheduling count=None msg=0/6 nodes are available: 1 c_wall violated: 3 conflicting context pair(s) with node memory, 5 node(s) had untolerated taint(s). no new claims to deallocate, preemption: 0/6 nodes are available: 1 No preemption victims found for incoming pod, 5 Preemption is not helpful for scheduling."
60.2531,Event,ADDED,eval-sanitize-2-r4-034-bjrp7.18d3d1d97aaae459,reason=Scheduled count=None msg=Successfully assigned compute/eval-sanitize-2-r4-034-bjrp7 to kind-worker
60.2533,Event,ADDED,eval-sanitize-2-r4-034-bjrp7.18d3d1d993fa5833,"reason=Pulled count=1 msg=Container image ""busybox:musl"" already present on machine"
60.2535,Event,ADDED,eval-sanitize-2-r4-034-bjrp7.18d3d1d995653ff9,reason=Created count=1 msg=Created container: task
60.2538,Event,ADDED,eval-sanitize-2-r4-034-bjrp7.18d3d1d9999e8929,reason=Started count=1 msg=Started container task
60.2539,Event,ADDED,eval-sanitize-2-r4-034.18d3d1d759d8db06,reason=SuccessfulCreate count=1 msg=Created pod: eval-sanitize-2-r4-034-bjrp7
60.2541,Event,ADDED,eval-sanitize-2-r4-034.18d3d1dcb922f819,reason=Completed count=1 msg=Job completed
60.2543,Event,ADDED,eval-sanitize-2-r4-035-d2wq7.18d3d1d79658a8be,reason=Scheduled count=None msg=Successfully assigned compute/eval-sanitize-2-r4-035-d2wq7 to kind-worker3
60.2545,Event,ADDED,eval-sanitize-2-r4-035-d2wq7.18d3d1d7b3294434,"reason=Pulled count=1 msg=Container image ""busybox:musl"" already present on machine"
60.2547,Event,ADDED,eval-sanitize-2-r4-035-d2wq7.18d3d1d7b44f1ccc,reason=Created count=1 msg=Created container: task
60.2548,Event,ADDED,eval-sanitize-2-r4-035-d2wq7.18d3d1d7b6470ee7,reason=Started count=1 msg=Started container task
60.255,Event,ADDED,eval-sanitize-2-r4-035.18d3d1d795cc16bb,reason=SuccessfulCreate count=1 msg=Created pod: eval-sanitize-2-r4-035-d2wq7
60.2553,Event,ADDED,eval-sanitize-2-r4-035.18d3d1dace712227,reason=Completed count=1 msg=Job completed
60.2555,Event,ADDED,eval-sanitize-2-r4-036-5258c.18d3d1d7d24e6bfa,reason=Scheduled count=None msg=Successfully assigned compute/eval-sanitize-2-r4-036-5258c to kind-worker3
60.2558,Event,ADDED,eval-sanitize-2-r4-036-5258c.18d3d1d7eb8242a1,"reason=Pulled count=1 msg=Container image ""busybox:musl"" already present on machine"
60.2561,Event,ADDED,eval-sanitize-2-r4-036-5258c.18d3d1d7ec91d668,reason=Created count=1 msg=Created container: task
60.2563,Event,ADDED,eval-sanitize-2-r4-036-5258c.18d3d1d7f097b142,reason=Started count=1 msg=Started container task
60.2565,Event,ADDED,eval-sanitize-2-r4-036.18d3d1d7d1d32aff,reason=SuccessfulCreate count=1 msg=Created pod: eval-sanitize-2-r4-036-5258c
60.2566,Event,ADDED,eval-sanitize-2-r4-036.18d3d1db0a0d014c,reason=Completed count=1 msg=Job completed
60.2569,Event,ADDED,eval-sanitize-2-r4-037-r774c.18d3d1d80c7415e6,"reason=FailedScheduling count=None msg=0/6 nodes are available: 6 node(s) had untolerated taint(s). no new claims to deallocate, preemption: 0/6 nodes are available: 6 Preemption is not helpful for scheduling."
60.2571,Event,ADDED,eval-sanitize-2-r4-037-r774c.18d3d1d97b2e0b79,reason=Scheduled count=None msg=Successfully assigned compute/eval-sanitize-2-r4-037-r774c to kind-worker
60.2573,Event,ADDED,eval-sanitize-2-r4-037-r774c.18d3d1d9941be272,"reason=Pulled count=1 msg=Container image ""busybox:musl"" already present on machine"
60.2575,Event,ADDED,eval-sanitize-2-r4-037-r774c.18d3d1d995b9d074,reason=Created count=1 msg=Created container: task
60.2579,Event,ADDED,eval-sanitize-2-r4-037-r774c.18d3d1d999a0f0b4,reason=Started count=1 msg=Started container task
60.2582,Event,ADDED,eval-sanitize-2-r4-037.18d3d1d80c6a297b,reason=SuccessfulCreate count=1 msg=Created pod: eval-sanitize-2-r4-037-r774c
60.2584,Event,ADDED,eval-sanitize-2-r4-037.18d3d1dcb905dbf5,reason=Completed count=1 msg=Job completed
60.2588,Event,ADDED,eval-sanitize-2-r4-038-2gqdk.18d3d1d84877adb9,"reason=FailedScheduling count=None msg=0/6 nodes are available: 6 node(s) had untolerated taint(s). no new claims to deallocate, preemption: 0/6 nodes are available: 6 Preemption is not helpful for scheduling."
60.259,Event,ADDED,eval-sanitize-2-r4-038-2gqdk.18d3d1d97b175562,"reason=FailedScheduling count=None msg=0/6 nodes are available: 1 c_wall violated: 2 conflicting context pair(s) with node memory, 5 node(s) had untolerated taint(s). no new claims to deallocate, preemption: 0/6 nodes are available: 1 No preemption victims found for incoming pod, 5 Preemption is not helpful for scheduling."
60.2592,Event,ADDED,eval-sanitize-2-r4-038-2gqdk.18d3d1d982ed5378,"reason=FailedScheduling count=None msg=0/6 nodes are available: 1 c_wall violated: 2 conflicting context pair(s) with node memory, 5 node(s) had untolerated taint(s). no new claims to deallocate, preemption: 0/6 nodes are available: 1 No preemption victims found for incoming pod, 5 Preemption is not helpful for scheduling."
60.2595,Event,ADDED,eval-sanitize-2-r4-038-2gqdk.18d3d1d9b6903c35,"reason=FailedScheduling count=None msg=0/6 nodes are available: 1 c_wall violated: 1 conflicting context pair(s) with node memory, 1 c_wall violated: 2 conflicting context pair(s) with node memory, 4 node(s) had untolerated taint(s). no new claims to deallocate, preemption: 0/6 nodes are available: 2 No preemption victims found for incoming pod, 4 Preemption is not helpful for scheduling."
60.2597,Event,ADDED,eval-sanitize-2-r4-038-2gqdk.18d3d1d9dd7e5aee,reason=Scheduled count=None msg=Successfully assigned compute/eval-sanitize-2-r4-038-2gqdk to kind-worker4
60.2599,Event,ADDED,eval-sanitize-2-r4-038-2gqdk.18d3d1d9f6dd8c1b,"reason=Pulled count=1 msg=Container image ""busybox:musl"" already present on machine"
60.2601,Event,ADDED,eval-sanitize-2-r4-038-2gqdk.18d3d1d9f863630b,reason=Created count=1 msg=Created container: task
60.2604,Event,ADDED,eval-sanitize-2-r4-038-2gqdk.18d3d1d9fa999787,reason=Started count=1 msg=Started container task
60.2606,Event,ADDED,eval-sanitize-2-r4-038.18d3d1d84867e3f5,reason=SuccessfulCreate count=1 msg=Created pod: eval-sanitize-2-r4-038-2gqdk
60.2608,Event,ADDED,eval-sanitize-2-r4-038.18d3d1dd28237841,reason=Completed count=1 msg=Job completed
60.2611,Event,ADDED,eval-sanitize-2-r4-039-62vq7.18d3d1d8843098a1,"reason=FailedScheduling count=None msg=0/6 nodes are available: 6 node(s) had untolerated taint(s). no new claims to deallocate, preemption: 0/6 nodes are available: 6 Preemption is not helpful for scheduling."
60.2613,Event,ADDED,eval-sanitize-2-r4-039-62vq7.18d3d1d97bd1797a,"reason=FailedScheduling count=None msg=0/6 nodes are available: 1 c_wall violated: 1 conflicting context pair(s) with node memory, 5 node(s) had untolerated taint(s). no new claims to deallocate, preemption: 0/6 nodes are available: 1 No preemption victims found for incoming pod, 5 Preemption is not helpful for scheduling."
60.2615,Event,ADDED,eval-sanitize-2-r4-039-62vq7.18d3d1d983224050,"reason=FailedScheduling count=None msg=0/6 nodes are available: 1 c_wall violated: 1 conflicting context pair(s) with node memory, 5 node(s) had untolerated taint(s). no new claims to deallocate, preemption: 0/6 nodes are available: 1 No preemption victims found for incoming pod, 5 Preemption is not helpful for scheduling."
60.2619,Event,ADDED,eval-sanitize-2-r4-039-62vq7.18d3d1d9b89541dc,"reason=FailedScheduling count=None msg=0/6 nodes are available: 1 c_wall violated: 1 conflicting context pair(s) with node memory, 1 c_wall violated: 2 conflicting context pair(s) with node memory, 4 node(s) had untolerated taint(s). no new claims to deallocate, preemption: 0/6 nodes are available: 2 No preemption victims found for incoming pod, 4 Preemption is not helpful for scheduling."
60.2621,Event,ADDED,eval-sanitize-2-r4-039-62vq7.18d3d1d9e84d4bb6,"reason=FailedScheduling count=None msg=0/6 nodes are available: 1 c_wall violated: 2 conflicting context pair(s) with node memory, 2 c_wall violated: 1 conflicting context pair(s) with node memory, 3 node(s) had untolerated taint(s). no new claims to deallocate, preemption: 0/6 nodes are available: 3 No preemption victims found for incoming pod, 3 Preemption is not helpful for scheduling."
60.2624,Event,ADDED,eval-sanitize-2-r4-039-62vq7.18d3d1d9f52e1ab1,"reason=FailedScheduling count=None msg=0/6 nodes are available: 1 c_wall violated: 1 conflicting context pair(s) with node memory, 1 c_wall violated: 2 conflicting context pair(s) with node memory, 4 node(s) had untolerated taint(s). no new claims to deallocate, preemption: 0/6 nodes are available: 2 No preemption victims found for incoming pod, 4 Preemption is not helpful for scheduling."
60.2628,Event,ADDED,eval-sanitize-2-r4-039-62vq7.18d3d1da09e36da8,reason=Scheduled count=None msg=Successfully assigned compute/eval-sanitize-2-r4-039-62vq7 to kind-worker5
60.2631,Event,ADDED,eval-sanitize-2-r4-039-62vq7.18d3d1da230e8bf6,"reason=Pulled count=1 msg=Container image ""busybox:musl"" already present on machine"
60.2634,Event,ADDED,eval-sanitize-2-r4-039-62vq7.18d3d1da243a49ef,reason=Created count=1 msg=Created container: task
60.2636,Event,ADDED,eval-sanitize-2-r4-039-62vq7.18d3d1da27235af4,reason=Started count=1 msg=Started container task
60.2641,Event,ADDED,eval-sanitize-2-r4-039.18d3d1d884275a64,reason=SuccessfulCreate count=1 msg=Created pod: eval-sanitize-2-r4-039-62vq7
60.2643,Event,ADDED,eval-sanitize-2-r4-039.18d3d1dd61832143,reason=Completed count=1 msg=Job completed
60.2645,Event,ADDED,eval-sanitize-2-r4-040-j9n9j.18d3d1d8c057dc34,"reason=FailedScheduling count=None msg=0/6 nodes are available: 6 node(s) had untolerated taint(s). no new claims to deallocate, preemption: 0/6 nodes are available: 6 Preemption is not helpful for scheduling."
60.2649,Event,ADDED,eval-sanitize-2-r4-040-j9n9j.18d3d1d97cb5c435,"reason=FailedScheduling count=None msg=0/6 nodes are available: 1 c_wall violated: 1 conflicting context pair(s) with node memory, 5 node(s) had untolerated taint(s). no new claims to deallocate, preemption: 0/6 nodes are available: 1 No preemption victims found for incoming pod, 5 Preemption is not helpful for scheduling."
60.2651,Event,ADDED,eval-sanitize-2-r4-040-j9n9j.18d3d1d9835d3ecc,"reason=FailedScheduling count=None msg=0/6 nodes are available: 1 c_wall violated: 1 conflicting context pair(s) with node memory, 5 node(s) had untolerated taint(s). no new claims to deallocate, preemption: 0/6 nodes are available: 1 No preemption victims found for incoming pod, 5 Preemption is not helpful for scheduling."
60.2653,Event,ADDED,eval-sanitize-2-r4-040-j9n9j.18d3d1d9a732d30a,reason=Scheduled count=None msg=Successfully assigned compute/eval-sanitize-2-r4-040-j9n9j to kind-worker2
60.2656,Event,ADDED,eval-sanitize-2-r4-040-j9n9j.18d3d1d9c072befe,"reason=Pulled count=1 msg=Container image ""busybox:musl"" already present on machine"
60.2658,Event,ADDED,eval-sanitize-2-r4-040-j9n9j.18d3d1d9c2282011,reason=Created count=1 msg=Created container: task
60.266,Event,ADDED,eval-sanitize-2-r4-040-j9n9j.18d3d1d9c6be3ed5,reason=Started count=1 msg=Started container task
60.2662,Event,ADDED,eval-sanitize-2-r4-040.18d3d1d8c04f120a,reason=SuccessfulCreate count=1 msg=Created pod: eval-sanitize-2-r4-040-j9n9j
60.2665,Event,ADDED,eval-sanitize-2-r4-040.18d3d1dd041d97cd,reason=Completed count=1 msg=Job completed
60.2666,Event,ADDED,eval-sanitize-2-r4-041-d4w9s.18d3d1d8fb0ff7b5,"reason=FailedScheduling count=None msg=0/6 nodes are available: 6 node(s) had untolerated taint(s). no new claims to deallocate, preemption: 0/6 nodes are available: 6 Preemption is not helpful for scheduling."
60.2669,Event,ADDED,eval-sanitize-2-r4-041-d4w9s.18d3d1d981398cf6,"reason=FailedScheduling count=None msg=0/6 nodes are available: 1 c_wall violated: 1 conflicting context pair(s) with node memory, 5 node(s) had untolerated taint(s). no new claims to deallocate, preemption: 0/6 nodes are available: 1 No preemption victims found for incoming pod, 5 Preemption is not helpful for scheduling."
60.2673,Event,ADDED,eval-sanitize-2-r4-041-d4w9s.18d3d1d98394e087,"reason=FailedScheduling count=None msg=0/6 nodes are available: 1 c_wall violated: 1 conflicting context pair(s) with node memory, 5 node(s) had untolerated taint(s). no new claims to deallocate, preemption: 0/6 nodes are available: 1 No preemption victims found for incoming pod, 5 Preemption is not helpful for scheduling."
60.2675,Event,ADDED,eval-sanitize-2-r4-041-d4w9s.18d3d1d9a77358c6,reason=Scheduled count=None msg=Successfully assigned compute/eval-sanitize-2-r4-041-d4w9s to kind-worker2
60.2677,Event,ADDED,eval-sanitize-2-r4-041-d4w9s.18d3d1d9c0af6f0f,"reason=Pulled count=1 msg=Container image ""busybox:musl"" already present on machine"
60.2679,Event,ADDED,eval-sanitize-2-r4-041-d4w9s.18d3d1d9c2a868c9,reason=Created count=1 msg=Created container: task
60.2684,Event,ADDED,eval-sanitize-2-r4-041-d4w9s.18d3d1d9c72904c7,reason=Started count=1 msg=Started container task
60.2686,Event,ADDED,eval-sanitize-2-r4-041.18d3d1d8fb048847,reason=SuccessfulCreate count=1 msg=Created pod: eval-sanitize-2-r4-041-d4w9s
60.2689,Event,ADDED,eval-sanitize-2-r4-041.18d3d1dd0599c694,reason=Completed count=1 msg=Job completed
60.2693,Event,ADDED,eval-sanitize-2-r4-042-2k9sd.18d3d1d936968f25,"reason=FailedScheduling count=None msg=0/6 nodes are available: 6 node(s) had untolerated taint(s). no new claims to deallocate, preemption: 0/6 nodes are available: 6 Preemption is not helpful for scheduling."
60.2695,Event,ADDED,eval-sanitize-2-r4-042-2k9sd.18d3d1d981cba9f9,"reason=FailedScheduling count=None msg=0/6 nodes are available: 1 c_wall violated: 2 conflicting context pair(s) with node memory, 5 node(s) had untolerated taint(s). no new claims to deallocate, preemption: 0/6 nodes are available: 1 No preemption victims found for incoming pod, 5 Preemption is not helpful for scheduling."
60.2697,Event,ADDED,eval-sanitize-2-r4-042-2k9sd.18d3d1d986d2f586,"reason=FailedScheduling count=None msg=0/6 nodes are available: 1 c_wall violated: 2 conflicting context pair(s) with node memory, 5 node(s) had untolerated taint(s). no new claims to deallocate, preemption: 0/6 nodes are available: 1 No preemption victims found for incoming pod, 5 Preemption is not helpful for scheduling."
60.2703,Event,ADDED,eval-sanitize-2-r4-042-2k9sd.18d3d1d9b308f9b1,"reason=FailedScheduling count=None msg=0/6 nodes are available: 2 c_wall violated: 2 conflicting context pair(s) with node memory, 4 node(s) had untolerated taint(s). no new claims to deallocate, preemption: 0/6 nodes are available: 2 No preemption victims found for incoming pod, 4 Preemption is not helpful for scheduling."
60.2706,Event,ADDED,eval-sanitize-2-r4-042-2k9sd.18d3d1d9dceeaa2c,reason=Scheduled count=None msg=Successfully assigned compute/eval-sanitize-2-r4-042-2k9sd to kind-worker4
60.2708,Event,ADDED,eval-sanitize-2-r4-042-2k9sd.18d3d1d9f654cdbd,"reason=Pulled count=1 msg=Container image ""busybox:musl"" already present on machine"
60.2709,Event,ADDED,eval-sanitize-2-r4-042-2k9sd.18d3d1d9f7bdcd87,reason=Created count=1 msg=Created container: task
60.2712,Event,ADDED,eval-sanitize-2-r4-042-2k9sd.18d3d1d9fa159d4a,reason=Started count=1 msg=Started container task
60.2714,Event,ADDED,eval-sanitize-2-r4-042.18d3d1d9368abfc4,reason=SuccessfulCreate count=1 msg=Created pod: eval-sanitize-2-r4-042-2k9sd
60.2716,Event,ADDED,eval-sanitize-2-r4-042.18d3d1dd27a1fa8e,reason=Completed count=1 msg=Job completed
60.2718,Event,ADDED,eval-sanitize-2-r4-043-rpkcz.18d3d1d97224f2aa,"reason=FailedScheduling count=None msg=0/6 nodes are available: 6 node(s) had untolerated taint(s). no new claims to deallocate, preemption: 0/6 nodes are available: 6 Preemption is not helpful for scheduling."
60.272,Event,ADDED,eval-sanitize-2-r4-043-rpkcz.18d3d1d982465663,"reason=FailedScheduling count=None msg=0/6 nodes are available: 1 c_wall violated: 1 conflicting context pair(s) with node memory, 5 node(s) had untolerated taint(s). no new claims to deallocate, preemption: 0/6 nodes are available: 1 No preemption victims found for incoming pod, 5 Preemption is not helpful for scheduling."
60.2723,Event,ADDED,eval-sanitize-2-r4-043-rpkcz.18d3d1d9872e9774,"reason=FailedScheduling count=None msg=0/6 nodes are available: 1 c_wall violated: 1 conflicting context pair(s) with node memory, 5 node(s) had untolerated taint(s). no new claims to deallocate, preemption: 0/6 nodes are available: 1 No preemption victims found for incoming pod, 5 Preemption is not helpful for scheduling."
60.2724,Event,ADDED,eval-sanitize-2-r4-043-rpkcz.18d3d1d9ad06f3b5,reason=Scheduled count=None msg=Successfully assigned compute/eval-sanitize-2-r4-043-rpkcz to kind-worker2
60.2727,Event,ADDED,eval-sanitize-2-r4-043-rpkcz.18d3d1d9c7d29d9f,"reason=Pulled count=1 msg=Container image ""busybox:musl"" already present on machine"
60.2729,Event,ADDED,eval-sanitize-2-r4-043-rpkcz.18d3d1d9c931db72,reason=Created count=1 msg=Created container: task
60.2731,Event,ADDED,eval-sanitize-2-r4-043-rpkcz.18d3d1d9d2c90408,reason=Started count=1 msg=Started container task
60.2734,Event,ADDED,eval-sanitize-2-r4-043.18d3d1d97219767e,reason=SuccessfulCreate count=1 msg=Created pod: eval-sanitize-2-r4-043-rpkcz
60.2736,Event,ADDED,eval-sanitize-2-r4-043.18d3d1dd043b68b7,reason=Completed count=1 msg=Job completed
60.2737,Event,ADDED,eval-sanitize-2-r4-044-w9bj4.18d3d1d9b3290cb3,reason=Scheduled count=None msg=Successfully assigned compute/eval-sanitize-2-r4-044-w9bj4 to kind-worker2
60.2739,Event,ADDED,eval-sanitize-2-r4-044-w9bj4.18d3d1d9cf13ec8f,"reason=Pulled count=1 msg=Container image ""busybox:musl"" already present on machine"
60.2742,Event,ADDED,eval-sanitize-2-r4-044-w9bj4.18d3d1d9d022cf02,reason=Created count=1 msg=Created container: task
60.2744,Event,ADDED,eval-sanitize-2-r4-044-w9bj4.18d3d1d9d39a413f,reason=Started count=1 msg=Started container task
60.2746,Event,ADDED,eval-sanitize-2-r4-044.18d3d1d9ae3fc19d,reason=SuccessfulCreate count=1 msg=Created pod: eval-sanitize-2-r4-044-w9bj4
60.2748,Event,ADDED,eval-sanitize-2-r4-044.18d3d1dd0552a685,reason=Completed count=1 msg=Job completed
60.2757,Event,ADDED,eval-sanitize-2-r4-045-z8fq4.18d3d1d9ea5459f4,reason=Scheduled count=None msg=Successfully assigned compute/eval-sanitize-2-r4-045-z8fq4 to kind-worker4
60.2763,Event,ADDED,eval-sanitize-2-r4-045-z8fq4.18d3d1da045e6b31,"reason=Pulled count=1 msg=Container image ""busybox:musl"" already present on machine"
60.2768,Event,ADDED,eval-sanitize-2-r4-045-z8fq4.18d3d1da056c2dd2,reason=Created count=1 msg=Created container: task
60.2774,Event,ADDED,eval-sanitize-2-r4-045-z8fq4.18d3d1da0756c26d,reason=Started count=1 msg=Started container task
60.2778,Event,ADDED,eval-sanitize-2-r4-045.18d3d1d9e94f6f2d,reason=SuccessfulCreate count=1 msg=Created pod: eval-sanitize-2-r4-045-z8fq4
60.2781,Event,ADDED,eval-sanitize-2-r4-045.18d3d1dd273695ab,reason=Completed count=1 msg=Job completed
60.2784,Event,ADDED,eval-sanitize-2-r4-046-8lqh5.18d3d1da25d5e3df,"reason=FailedScheduling count=None msg=0/6 nodes are available: 1 c_wall violated: 1 conflicting context pair(s) with node memory, 1 c_wall violated: 2 conflicting context pair(s) with node memory, 4 node(s) had untolerated taint(s). no new claims to deallocate, preemption: 0/6 nodes are available: 2 No preemption victims found for incoming pod, 4 Preemption is not helpful for scheduling."
60.279,Event,ADDED,eval-sanitize-2-r4-046-8lqh5.18d3d1da27121ca3,"reason=FailedScheduling count=None msg=0/6 nodes are available: 1 c_wall violated: 1 conflicting context pair(s) with node memory, 1 c_wall violated: 2 conflicting context pair(s) with node memory, 4 node(s) had untolerated taint(s). no new claims to deallocate, preemption: 0/6 nodes are available: 2 No preemption victims found for incoming pod, 4 Preemption is not helpful for scheduling."
60.2793,Event,ADDED,eval-sanitize-2-r4-046-8lqh5.18d3d1da542b5287,"reason=FailedScheduling count=None msg=0/6 nodes are available: 1 c_wall violated: 1 conflicting context pair(s) with node memory, 5 node(s) had untolerated taint(s). no new claims to deallocate, preemption: 0/6 nodes are available: 1 No preemption victims found for incoming pod, 5 Preemption is not helpful for scheduling."
60.2796,Event,ADDED,eval-sanitize-2-r4-046-8lqh5.18d3d1dafe09aa1c,reason=Scheduled count=None msg=Successfully assigned compute/eval-sanitize-2-r4-046-8lqh5 to kind-worker3
60.28,Event,ADDED,eval-sanitize-2-r4-046-8lqh5.18d3d1db1687f465,"reason=Pulled count=1 msg=Container image ""busybox:musl"" already present on machine"
60.2802,Event,ADDED,eval-sanitize-2-r4-046-8lqh5.18d3d1db179ff9c8,reason=Created count=1 msg=Created container: task
60.2804,Event,ADDED,eval-sanitize-2-r4-046-8lqh5.18d3d1db19938c61,reason=Started count=1 msg=Started container task
60.2807,Event,ADDED,eval-sanitize-2-r4-046.18d3d1da253a6c8b,reason=SuccessfulCreate count=1 msg=Created pod: eval-sanitize-2-r4-046-8lqh5
60.281,Event,ADDED,eval-sanitize-2-r4-047-567wm.18d3d1da613acb7a,"reason=FailedScheduling count=None msg=0/6 nodes are available: 1 c_wall violated: 1 conflicting context pair(s) with node memory, 5 node(s) had untolerated taint(s). no new claims to deallocate, preemption: 0/6 nodes are available: 1 No preemption victims found for incoming pod, 5 Preemption is not helpful for scheduling."
60.2812,Event,ADDED,eval-sanitize-2-r4-047-567wm.18d3d1da61b47efa,"reason=FailedScheduling count=None msg=0/6 nodes are available: 1 c_wall violated: 1 conflicting context pair(s) with node memory, 5 node(s) had untolerated taint(s). no new claims to deallocate, preemption: 0/6 nodes are available: 1 No preemption victims found for incoming pod, 5 Preemption is not helpful for scheduling."
60.2816,Event,ADDED,eval-sanitize-2-r4-047-567wm.18d3d1dafde8e4ca,"reason=FailedScheduling count=None msg=0/6 nodes are available: 1 c_wall violated: 1 conflicting context pair(s) with node memory, 5 node(s) had untolerated taint(s). no new claims to deallocate, preemption: 0/6 nodes are available: 1 No preemption victims found for incoming pod, 5 Preemption is not helpful for scheduling."
60.2818,Event,ADDED,eval-sanitize-2-r4-047-567wm.18d3d1daff8b0988,"reason=FailedScheduling count=None msg=0/6 nodes are available: 1 c_wall violated: 1 conflicting context pair(s) with node memory, 5 node(s) had untolerated taint(s). no new claims to deallocate, preemption: 0/6 nodes are available: 1 No preemption victims found for incoming pod, 5 Preemption is not helpful for scheduling."
60.2822,Event,ADDED,eval-sanitize-2-r4-047-567wm.18d3d1dc74f24972,"reason=FailedScheduling count=None msg=0/6 nodes are available: 1 c_wall violated: 1 conflicting context pair(s) with node memory, 5 node(s) had untolerated taint(s). no new claims to deallocate, preemption: 0/6 nodes are available: 1 No preemption victims found for incoming pod, 5 Preemption is not helpful for scheduling."
60.2825,Event,ADDED,eval-sanitize-2-r4-047-567wm.18d3d1dc7bce692f,"reason=FailedScheduling count=None msg=0/6 nodes are available: 1 c_wall violated: 1 conflicting context pair(s) with node memory, 5 node(s) had untolerated taint(s). no new claims to deallocate, preemption: 0/6 nodes are available: 1 No preemption victims found for incoming pod, 5 Preemption is not helpful for scheduling."
60.2827,Event,ADDED,eval-sanitize-2-r4-047-567wm.18d3d1dcc59ca90d,"reason=FailedScheduling count=None msg=0/6 nodes are available: 2 c_wall violated: 1 conflicting context pair(s) with node memory, 4 node(s) had untolerated taint(s). no new claims to deallocate, preemption: 0/6 nodes are available: 2 No preemption victims found for incoming pod, 4 Preemption is not helpful for scheduling."
60.2832,Event,ADDED,eval-sanitize-2-r4-047-567wm.18d3d1dcd7e59d5a,reason=Scheduled count=None msg=Successfully assigned compute/eval-sanitize-2-r4-047-567wm to kind-worker4
60.2837,Event,ADDED,eval-sanitize-2-r4-047-567wm.18d3d1dcf16b1d14,"reason=Pulled count=1 msg=Container image ""busybox:musl"" already present on machine"
60.2841,Event,ADDED,eval-sanitize-2-r4-047-567wm.18d3d1dcf27c3934,reason=Created count=1 msg=Created container: task
60.2844,Event,ADDED,eval-sanitize-2-r4-047-567wm.18d3d1dcf4648fa0,reason=Started count=1 msg=Started container task
60.2846,Event,ADDED,eval-sanitize-2-r4-047.18d3d1da60fdc590,reason=SuccessfulCreate count=1 msg=Created pod: eval-sanitize-2-r4-047-567wm
60.2848,Event,ADDED,eval-sanitize-2-r4-048-l42kt.18d3d1da9cc6ad6f,"reason=FailedScheduling count=None msg=0/6 nodes are available: 6 node(s) had untolerated taint(s). no new claims to deallocate, preemption: 0/6 nodes are available: 6 Preemption is not helpful for scheduling."
60.285,Event,ADDED,eval-sanitize-2-r4-048-l42kt.18d3d1dafe9d2f79,"reason=FailedScheduling count=None msg=0/6 nodes are available: 1 c_wall violated: 1 conflicting context pair(s) with node memory, 5 node(s) had untolerated taint(s). no new claims to deallocate, preemption: 0/6 nodes are available: 1 No preemption victims found for incoming pod, 5 Preemption is not helpful for scheduling."
60.2852,Event,ADDED,eval-sanitize-2-r4-048-l42kt.18d3d1daffbbc01c,"reason=FailedScheduling count=None msg=0/6 nodes are available: 1 c_wall violated: 1 conflicting context pair(s) with node memory, 5 node(s) had untolerated taint(s). no new claims to deallocate, preemption: 0/6 nodes are available: 1 No preemption victims found for incoming pod, 5 Preemption is not helpful for scheduling."
60.2854,Event,ADDED,eval-sanitize-2-r4-048-l42kt.18d3d1dc74552cf6,reason=Scheduled count=None msg=Successfully assigned compute/eval-sanitize-2-r4-048-l42kt to kind-worker
60.2862,Event,ADDED,eval-sanitize-2-r4-048-l42kt.18d3d1dc92ee51a0,"reason=Pulled count=1 msg=Container image ""busybox:musl"" already present on machine"
60.2864,Event,ADDED,eval-sanitize-2-r4-048-l42kt.18d3d1dc949f36c9,reason=Created count=1 msg=Created container: task
60.2865,Event,ADDED,eval-sanitize-2-r4-048-l42kt.18d3d1dc991d0642,reason=Started count=1 msg=Started container task
60.2868,Event,ADDED,eval-sanitize-2-r4-048.18d3d1da9cbc02bb,reason=SuccessfulCreate count=1 msg=Created pod: eval-sanitize-2-r4-048-l42kt
60.287,Event,ADDED,eval-sanitize-2-r4-049-2mqtp.18d3d1dad8252a91,"reason=FailedScheduling count=None msg=0/6 nodes are available: 6 node(s) had untolerated taint(s). no new claims to deallocate, preemption: 0/6 nodes are available: 6 Preemption is not helpful for scheduling."
60.2872,Event,ADDED,eval-sanitize-2-r4-049-2mqtp.18d3d1daff16f1e5,"reason=FailedScheduling count=None msg=0/6 nodes are available: 1 c_wall violated: 1 conflicting context pair(s) with node memory, 5 node(s) had untolerated taint(s). no new claims to deallocate, preemption: 0/6 nodes are available: 1 No preemption victims found for incoming pod, 5 Preemption is not helpful for scheduling."
60.2875,Event,ADDED,eval-sanitize-2-r4-049-2mqtp.18d3d1daffee1980,"reason=FailedScheduling count=None msg=0/6 nodes are available: 1 c_wall violated: 1 conflicting context pair(s) with node memory, 5 node(s) had untolerated taint(s). no new claims to deallocate, preemption: 0/6 nodes are available: 1 No preemption victims found for incoming pod, 5 Preemption is not helpful for scheduling."
60.2877,Event,ADDED,eval-sanitize-2-r4-049-2mqtp.18d3d1dc744b5b3d,"reason=FailedScheduling count=None msg=0/6 nodes are available: 1 c_wall violated: 1 conflicting context pair(s) with node memory, 5 node(s) had untolerated taint(s). no new claims to deallocate, preemption: 0/6 nodes are available: 1 No preemption victims found for incoming pod, 5 Preemption is not helpful for scheduling."
60.2879,Event,ADDED,eval-sanitize-2-r4-049-2mqtp.18d3d1dc78b5b629,"reason=FailedScheduling count=None msg=0/6 nodes are available: 1 c_wall violated: 1 conflicting context pair(s) with node memory, 5 node(s) had untolerated taint(s). no new claims to deallocate, preemption: 0/6 nodes are available: 1 No preemption victims found for incoming pod, 5 Preemption is not helpful for scheduling."
60.2884,Event,ADDED,eval-sanitize-2-r4-049-2mqtp.18d3d1dcc3915963,"reason=FailedScheduling count=None msg=0/6 nodes are available: 2 c_wall violated: 1 conflicting context pair(s) with node memory, 4 node(s) had untolerated taint(s). no new claims to deallocate, preemption: 0/6 nodes are available: 2 No preemption victims found for incoming pod, 4 Preemption is not helpful for scheduling."
60.2886,Event,ADDED,eval-sanitize-2-r4-049-2mqtp.18d3d1dce49d95b9,reason=Scheduled count=None msg=Successfully assigned compute/eval-sanitize-2-r4-049-2mqtp to kind-worker4
60.2887,Event,ADDED,eval-sanitize-2-r4-049-2mqtp.18d3d1dcfcebd501,"reason=Pulled count=1 msg=Container image ""busybox:musl"" already present on machine"
60.2889,Event,ADDED,eval-sanitize-2-r4-049-2mqtp.18d3d1dcfe16a2a4,reason=Created count=1 msg=Created container: task
60.2893,Event,ADDED,eval-sanitize-2-r4-049-2mqtp.18d3d1dd034c72aa,reason=Started count=1 msg=Started container task
60.2895,Event,ADDED,eval-sanitize-2-r4-049.18d3d1dad81edc01,reason=SuccessfulCreate count=1 msg=Created pod: eval-sanitize-2-r4-049-2mqtp
60.2897,Event,ADDED,eval-sanitize-2-r4-050-r2sx8.18d3d1db13e8c643,"reason=FailedScheduling count=None msg=0/6 nodes are available: 1 c_wall violated: 1 conflicting context pair(s) with node memory, 5 node(s) had untolerated taint(s). no new claims to deallocate, preemption: 0/6 nodes are available: 1 No preemption victims found for incoming pod, 5 Preemption is not helpful for scheduling."
60.29,Event,ADDED,eval-sanitize-2-r4-050-r2sx8.18d3d1db1468891c,"reason=FailedScheduling count=None msg=0/6 nodes are available: 1 c_wall violated: 1 conflicting context pair(s) with node memory, 5 node(s) had untolerated taint(s). no new claims to deallocate, preemption: 0/6 nodes are available: 1 No preemption victims found for incoming pod, 5 Preemption is not helpful for scheduling."
60.2902,Event,ADDED,eval-sanitize-2-r4-050-r2sx8.18d3d1dc757c4d94,"reason=FailedScheduling count=None msg=0/6 nodes are available: 1 c_wall violated: 1 conflicting context pair(s) with node memory, 5 node(s) had untolerated taint(s). no new claims to deallocate, preemption: 0/6 nodes are available: 1 No preemption victims found for incoming pod, 5 Preemption is not helpful for scheduling."
60.2904,Event,ADDED,eval-sanitize-2-r4-050-r2sx8.18d3d1dc7cdb63b7,"reason=FailedScheduling count=None msg=0/6 nodes are available: 1 c_wall violated: 1 conflicting context pair(s) with node memory, 5 node(s) had untolerated taint(s). no new claims to deallocate, preemption: 0/6 nodes are available: 1 No preemption victims found for incoming pod, 5 Preemption is not helpful for scheduling."
60.2907,Event,ADDED,eval-sanitize-2-r4-050-r2sx8.18d3d1dcae28ab35,reason=Scheduled count=None msg=Successfully assigned compute/eval-sanitize-2-r4-050-r2sx8 to kind-worker2
60.2909,Event,ADDED,eval-sanitize-2-r4-050-r2sx8.18d3d1dcc7a7ee70,"reason=Pulled count=1 msg=Container image ""busybox:musl"" already present on machine"
60.2911,Event,ADDED,eval-sanitize-2-r4-050-r2sx8.18d3d1dcc9ad71da,reason=Created count=1 msg=Created container: task
60.2913,Event,ADDED,eval-sanitize-2-r4-050-r2sx8.18d3d1dccf2474c7,reason=Started count=1 msg=Started container task
60.2916,Event,ADDED,eval-sanitize-2-r4-050.18d3d1db13ac0971,reason=SuccessfulCreate count=1 msg=Created pod: eval-sanitize-2-r4-050-r2sx8
60.2918,Event,ADDED,eval-sanitize-2-r4-051-bcxdv.18d3d1db4f50c4fb,"reason=FailedScheduling count=None msg=0/6 nodes are available: 1 c_wall violated: 1 conflicting context pair(s) with node memory, 5 node(s) had untolerated taint(s). no new claims to deallocate, preemption: 0/6 nodes are available: 1 No preemption victims found for incoming pod, 5 Preemption is not helpful for scheduling."
60.292,Event,ADDED,eval-sanitize-2-r4-051-bcxdv.18d3d1db4fecc272,"reason=FailedScheduling count=None msg=0/6 nodes are available: 1 c_wall violated: 1 conflicting context pair(s) with node memory, 5 node(s) had untolerated taint(s). no new claims to deallocate, preemption: 0/6 nodes are available: 1 No preemption victims found for incoming pod, 5 Preemption is not helpful for scheduling."
60.2923,Event,ADDED,eval-sanitize-2-r4-051-bcxdv.18d3d1dc763f9aff,reason=Scheduled count=None msg=Successfully assigned compute/eval-sanitize-2-r4-051-bcxdv to kind-worker
60.2925,Event,ADDED,eval-sanitize-2-r4-051-bcxdv.18d3d1dc9349aa27,"reason=Pulled count=1 msg=Container image ""busybox:musl"" already present on machine"
60.2928,Event,ADDED,eval-sanitize-2-r4-051-bcxdv.18d3d1dc94d2268c,reason=Created count=1 msg=Created container: task
60.2931,Event,ADDED,eval-sanitize-2-r4-051-bcxdv.18d3d1dc9963537d,reason=Started count=1 msg=Started container task
60.2932,Event,ADDED,eval-sanitize-2-r4-051.18d3d1db4f0f4e62,reason=SuccessfulCreate count=1 msg=Created pod: eval-sanitize-2-r4-051-bcxdv
60.2935,Event,ADDED,eval-sanitize-2-r4-052-v8g6t.18d3d1db8a939937,"reason=FailedScheduling count=None msg=0/6 nodes are available: 6 node(s) had untolerated taint(s). no new claims to deallocate, preemption: 0/6 nodes are available: 6 Preemption is not helpful for scheduling."
60.2937,Event,ADDED,eval-sanitize-2-r4-052-v8g6t.18d3d1dc76228908,"reason=FailedScheduling count=None msg=0/6 nodes are available: 1 c_wall violated: 1 conflicting context pair(s) with node memory, 5 node(s) had untolerated taint(s). no new claims to deallocate, preemption: 0/6 nodes are available: 1 No preemption victims found for incoming pod, 5 Preemption is not helpful for scheduling."
60.2939,Event,ADDED,eval-sanitize-2-r4-052-v8g6t.18d3d1dc7d08c917,"reason=FailedScheduling count=None msg=0/6 nodes are available: 1 c_wall violated: 1 conflicting context pair(s) with node memory, 5 node(s) had untolerated taint(s). no new claims to deallocate, preemption: 0/6 nodes are available: 1 No preemption victims found for incoming pod, 5 Preemption is not helpful for scheduling."
60.2944,Event,ADDED,eval-sanitize-2-r4-052-v8g6t.18d3d1dcbd8abc76,"reason=FailedScheduling count=None msg=0/6 nodes are available: 1 c_wall violated: 1 conflicting context pair(s) with node memory, 1 c_wall violated: 2 conflicting context pair(s) with node memory, 4 node(s) had untolerated taint(s). no new claims to deallocate, preemption: 0/6 nodes are available: 2 No preemption victims found for incoming pod, 4 Preemption is not helpful for scheduling."
60.2946,Event,ADDED,eval-sanitize-2-r4-052-v8g6t.18d3d1dce952f714,"reason=FailedScheduling count=None msg=0/6 nodes are available: 1 c_wall violated: 2 conflicting context pair(s) with node memory, 2 c_wall violated: 1 conflicting context pair(s) with node memory, 3 node(s) had untolerated taint(s). no new claims to deallocate, preemption: 0/6 nodes are available: 3 No preemption victims found for incoming pod, 3 Preemption is not helpful for scheduling."
60.2948,Event,ADDED,eval-sanitize-2-r4-052-v8g6t.18d3d1dcfafcedb3,"reason=FailedScheduling count=None msg=0/6 nodes are available: 1 c_wall violated: 1 conflicting context pair(s) with node memory, 1 c_wall violated: 2 conflicting context pair(s) with node memory, 4 node(s) had untolerated taint(s). no new claims to deallocate, preemption: 0/6 nodes are available: 2 No preemption victims found for incoming pod, 4 Preemption is not helpful for scheduling."
60.2951,Event,ADDED,eval-sanitize-2-r4-052-v8g6t.18d3d1dd0b35737c,reason=Scheduled count=None msg=Successfully assigned compute/eval-sanitize-2-r4-052-v8g6t to kind-worker5
60.2953,Event,ADDED,eval-sanitize-2-r4-052-v8g6t.18d3d1dd2409fdfb,"reason=Pulled count=1 msg=Container image ""busybox:musl"" already present on machine"
60.2956,Event,ADDED,eval-sanitize-2-r4-052-v8g6t.18d3d1dd25416205,reason=Created count=1 msg=Created container: task
60.2959,Event,ADDED,eval-sanitize-2-r4-052-v8g6t.18d3d1dd2bfc475f,reason=Started count=1 msg=Started container task
60.2962,Event,ADDED,eval-sanitize-2-r4-052.18d3d1db8a88e8e2,reason=SuccessfulCreate count=1 msg=Created pod: eval-sanitize-2-r4-052-v8g6t
60.2964,Event,ADDED,eval-sanitize-2-r4-053-h944b.18d3d1dbc67cbf3f,"reason=FailedScheduling count=None msg=0/6 nodes are available: 6 node(s) had untolerated taint(s). no new claims to deallocate, preemption: 0/6 nodes are available: 6 Preemption is not helpful for scheduling."
60.2965,Event,ADDED,eval-sanitize-2-r4-053-h944b.18d3d1dc76bd15a8,"reason=FailedScheduling count=None msg=0/6 nodes are available: 1 c_wall violated: 2 conflicting context pair(s) with node memory, 5 node(s) had untolerated taint(s). no new claims to deallocate, preemption: 0/6 nodes are available: 1 No preemption victims found for incoming pod, 5 Preemption is not helpful for scheduling."
60.2969,Event,ADDED,eval-sanitize-2-r4-053-h944b.18d3d1dc7de4eb47,"reason=FailedScheduling count=None msg=0/6 nodes are available: 1 c_wall violated: 2 conflicting context pair(s) with node memory, 5 node(s) had untolerated taint(s). no new claims to deallocate, preemption: 0/6 nodes are available: 1 No preemption victims found for incoming pod, 5 Preemption is not helpful for scheduling."
60.2972,Event,ADDED,eval-sanitize-2-r4-053-h944b.18d3d1dcbf90f5a1,"reason=FailedScheduling count=None msg=0/6 nodes are available: 1 c_wall violated: 1 conflicting context pair(s) with node memory, 1 c_wall violated: 2 conflicting context pair(s) with node memory, 4 node(s) had untolerated taint(s). no new claims to deallocate, preemption: 0/6 nodes are available: 2 No preemption victims found for incoming pod, 4 Preemption is not helpful for scheduling."
60.2974,Event,ADDED,eval-sanitize-2-r4-053-h944b.18d3d1dced117448,"reason=FailedScheduling count=None msg=0/6 nodes are available: 1 c_wall violated: 2 conflicting context pair(s) with node memory, 2 c_wall violated: 1 conflicting context pair(s) with node memory, 3 node(s) had untolerated taint(s). no new claims to deallocate, preemption: 0/6 nodes are available: 3 No preemption victims found for incoming pod, 3 Preemption is not helpful for scheduling."
60.2976,Event,ADDED,eval-sanitize-2-r4-053-h944b.18d3d1dcfb9cfac8,"reason=FailedScheduling count=None msg=0/6 nodes are available: 2 c_wall violated: 1 conflicting context pair(s) with node memory, 4 node(s) had untolerated taint(s). no new claims to deallocate, preemption: 0/6 nodes are available: 2 No preemption victims found for incoming pod, 4 Preemption is not helpful for scheduling."
60.2979,Event,ADDED,eval-sanitize-2-r4-053-h944b.18d3d1dd18df3581,"reason=FailedScheduling count=None msg=0/6 nodes are available: 3 c_wall violated: 1 conflicting context pair(s) with node memory, 3 node(s) had untolerated taint(s). no new claims to deallocate, preemption: 0/6 nodes are available: 3 No preemption victims found for incoming pod, 3 Preemption is not helpful for scheduling."
60.2983,Event,ADDED,eval-sanitize-2-r4-053-h944b.18d3d1dd31cae31f,"reason=FailedScheduling count=None msg=0/6 nodes are available: 2 c_wall violated: 1 conflicting context pair(s) with node memory, 4 node(s) had untolerated taint(s). no new claims to deallocate, preemption: 0/6 nodes are available: 2 No preemption victims found for incoming pod, 4 Preemption is not helpful for scheduling."
60.2985,Event,ADDED,eval-sanitize-2-r4-053-h944b.18d3d1dd5335e0cc,"reason=FailedScheduling count=None msg=0/6 nodes are available: 1 c_wall violated: 1 conflicting context pair(s) with node memory, 5 node(s) had untolerated taint(s). no new claims to deallocate, preemption: 0/6 nodes are available: 1 No preemption victims found for incoming pod, 5 Preemption is not helpful for scheduling."
60.2987,Event,ADDED,eval-sanitize-2-r4-053.18d3d1dbc6731247,reason=SuccessfulCreate count=1 msg=Created pod: eval-sanitize-2-r4-053-h944b
60.2989,Event,ADDED,eval-sanitize-2-r4-054-bp59m.18d3d1dc021f82b1,"reason=FailedScheduling count=None msg=0/6 nodes are available: 6 node(s) had untolerated taint(s). no new claims to deallocate, preemption: 0/6 nodes are available: 6 Preemption is not helpful for scheduling."
60.2992,Event,ADDED,eval-sanitize-2-r4-054-bp59m.18d3d1dc77d33faa,"reason=FailedScheduling count=None msg=0/6 nodes are available: 1 c_wall violated: 2 conflicting context pair(s) with node memory, 5 node(s) had untolerated taint(s). no new claims to deallocate, preemption: 0/6 nodes are available: 1 No preemption victims found for incoming pod, 5 Preemption is not helpful for scheduling."
60.2994,Event,ADDED,eval-sanitize-2-r4-054-bp59m.18d3d1dc7e0da287,"reason=FailedScheduling count=None msg=0/6 nodes are available: 1 c_wall violated: 2 conflicting context pair(s) with node memory, 5 node(s) had untolerated taint(s). no new claims to deallocate, preemption: 0/6 nodes are available: 1 No preemption victims found for incoming pod, 5 Preemption is not helpful for scheduling."
60.2996,Event,ADDED,eval-sanitize-2-r4-054-bp59m.18d3d1dcb47c9713,reason=Scheduled count=None msg=Successfully assigned compute/eval-sanitize-2-r4-054-bp59m to kind-worker2
60.2999,Event,ADDED,eval-sanitize-2-r4-054-bp59m.18d3d1dccffc23e2,"reason=Pulled count=1 msg=Container image ""busybox:musl"" already present on machine"
60.3001,Event,ADDED,eval-sanitize-2-r4-054-bp59m.18d3d1dcd11ae464,reason=Created count=1 msg=Created container: task
60.3003,Event,ADDED,eval-sanitize-2-r4-054-bp59m.18d3d1dcd31ce57c,reason=Started count=1 msg=Started container task
60.3006,Event,ADDED,eval-sanitize-2-r4-054.18d3d1dc0210ee3a,reason=SuccessfulCreate count=1 msg=Created pod: eval-sanitize-2-r4-054-bp59m
60.3009,Event,ADDED,eval-sanitize-2-r4-055-dkvq4.18d3d1dc3dceb04f,"reason=FailedScheduling count=None msg=0/6 nodes are available: 6 node(s) had untolerated taint(s). no new claims to deallocate, preemption: 0/6 nodes are available: 6 Preemption is not helpful for scheduling."
60.301,Event,ADDED,eval-sanitize-2-r4-055-dkvq4.18d3d1dc7843d141,"reason=FailedScheduling count=None msg=0/6 nodes are available: 1 c_wall violated: 1 conflicting context pair(s) with node memory, 5 node(s) had untolerated taint(s). no new claims to deallocate, preemption: 0/6 nodes are available: 1 No preemption victims found for incoming pod, 5 Preemption is not helpful for scheduling."
60.3014,Event,ADDED,eval-sanitize-2-r4-055-dkvq4.18d3d1dc7e3604f1,"reason=FailedScheduling count=None msg=0/6 nodes are available: 1 c_wall violated: 1 conflicting context pair(s) with node memory, 5 node(s) had untolerated taint(s). no new claims to deallocate, preemption: 0/6 nodes are available: 1 No preemption victims found for incoming pod, 5 Preemption is not helpful for scheduling."
60.3016,Event,ADDED,eval-sanitize-2-r4-055-dkvq4.18d3d1dcbfe93501,"reason=FailedScheduling count=None msg=0/6 nodes are available: 1 c_wall violated: 1 conflicting context pair(s) with node memory, 1 c_wall violated: 2 conflicting context pair(s) with node memory, 4 node(s) had untolerated taint(s). no new claims to deallocate, preemption: 0/6 nodes are available: 2 No preemption victims found for incoming pod, 4 Preemption is not helpful for scheduling."
60.3017,Event,ADDED,eval-sanitize-2-r4-055-dkvq4.18d3d1dcef4a631c,"reason=FailedScheduling count=None msg=0/6 nodes are available: 1 c_wall violated: 1 conflicting context pair(s) with node memory, 1 c_wall violated: 2 conflicting context pair(s) with node memory, 4 node(s) had untolerated taint(s). no new claims to deallocate, preemption: 0/6 nodes are available: 2 No preemption victims found for incoming pod, 4 Preemption is not helpful for scheduling."
60.3021,Event,ADDED,eval-sanitize-2-r4-055-dkvq4.18d3d1dcf6312799,"reason=FailedScheduling count=None msg=0/6 nodes are available: 1 c_wall violated: 1 conflicting context pair(s) with node memory, 1 c_wall violated: 2 conflicting context pair(s) with node memory, 4 node(s) had untolerated taint(s). no new claims to deallocate, preemption: 0/6 nodes are available: 2 No preemption victims found for incoming pod, 4 Preemption is not helpful for scheduling."
60.3022,Event,ADDED,eval-sanitize-2-r4-055-dkvq4.18d3d1dd07633f93,reason=Scheduled count=None msg=Successfully assigned compute/eval-sanitize-2-r4-055-dkvq4 to kind-worker5
60.3024,Event,ADDED,eval-sanitize-2-r4-055-dkvq4.18d3d1dd2087e2f2,"reason=Pulled count=1 msg=Container image ""busybox:musl"" already present on machine"
60.3026,Event,ADDED,eval-sanitize-2-r4-055-dkvq4.18d3d1dd21a9a7bf,reason=Created count=1 msg=Created container: task
60.3029,Event,ADDED,eval-sanitize-2-r4-055-dkvq4.18d3d1dd2404479c,reason=Started count=1 msg=Started container task
60.3031,Event,ADDED,eval-sanitize-2-r4-055.18d3d1dc3dc46ab5,reason=SuccessfulCreate count=1 msg=Created pod: eval-sanitize-2-r4-055-dkvq4
60.3033,Event,ADDED,eval-sanitize-2-r4-056-tb4xl.18d3d1dc7c08f4f1,"reason=FailedScheduling count=None msg=0/6 nodes are available: 1 c_wall violated: 2 conflicting context pair(s) with node memory, 5 node(s) had untolerated taint(s). no new claims to deallocate, preemption: 0/6 nodes are available: 1 No preemption victims found for incoming pod, 5 Preemption is not helpful for scheduling."
60.3037,Event,ADDED,eval-sanitize-2-r4-056-tb4xl.18d3d1dc82041aa0,"reason=FailedScheduling count=None msg=0/6 nodes are available: 1 c_wall violated: 2 conflicting context pair(s) with node memory, 5 node(s) had untolerated taint(s). no new claims to deallocate, preemption: 0/6 nodes are available: 1 No preemption victims found for incoming pod, 5 Preemption is not helpful for scheduling."
60.304,Event,ADDED,eval-sanitize-2-r4-056-tb4xl.18d3d1dcac3ac21b,reason=Scheduled count=None msg=Successfully assigned compute/eval-sanitize-2-r4-056-tb4xl to kind-worker2
60.3043,Event,ADDED,eval-sanitize-2-r4-056-tb4xl.18d3d1dcc54d4f87,"reason=Pulled count=1 msg=Container image ""busybox:musl"" already present on machine"
60.3045,Event,ADDED,eval-sanitize-2-r4-056-tb4xl.18d3d1dcc6931f6c,reason=Created count=1 msg=Created container: task
60.3048,Event,ADDED,eval-sanitize-2-r4-056-tb4xl.18d3d1dcce636bcd,reason=Started count=1 msg=Started container task
60.305,Event,ADDED,eval-sanitize-2-r4-056.18d3d1dc7a36559c,reason=SuccessfulCreate count=1 msg=Created pod: eval-sanitize-2-r4-056-tb4xl
60.3051,Event,ADDED,eval-sanitize-2-r4-057-58mc5.18d3d1dcb7efb92b,reason=Scheduled count=None msg=Successfully assigned compute/eval-sanitize-2-r4-057-58mc5 to kind-worker
60.3055,Event,ADDED,eval-sanitize-2-r4-057-58mc5.18d3d1dcd1e57cfd,"reason=Pulled count=1 msg=Container image ""busybox:musl"" already present on machine"
60.3057,Event,ADDED,eval-sanitize-2-r4-057-58mc5.18d3d1dcd2fe4a72,reason=Created count=1 msg=Created container: task
60.3058,Event,ADDED,eval-sanitize-2-r4-057-58mc5.18d3d1dcd51969cd,reason=Started count=1 msg=Started container task
60.306,Event,ADDED,eval-sanitize-2-r4-057.18d3d1dcb4c3cfc6,reason=SuccessfulCreate count=1 msg=Created pod: eval-sanitize-2-r4-057-58mc5
60.3063,Event,ADDED,eval-sanitize-2-r4-058-qlc2v.18d3d1dcf50b6db6,"reason=FailedScheduling count=None msg=0/6 nodes are available: 2 c_wall violated: 1 conflicting context pair(s) with node memory, 4 node(s) had untolerated taint(s). no new claims to deallocate, preemption: 0/6 nodes are available: 2 No preemption victims found for incoming pod, 4 Preemption is not helpful for scheduling."
60.3065,Event,ADDED,eval-sanitize-2-r4-058-qlc2v.18d3d1dcfb4f4866,"reason=FailedScheduling count=None msg=0/6 nodes are available: 2 c_wall violated: 1 conflicting context pair(s) with node memory, 4 node(s) had untolerated taint(s). no new claims to deallocate, preemption: 0/6 nodes are available: 2 No preemption victims found for incoming pod, 4 Preemption is not helpful for scheduling."
60.3067,Event,ADDED,eval-sanitize-2-r4-058-qlc2v.18d3d1dd13dce241,"reason=FailedScheduling count=None msg=0/6 nodes are available: 3 c_wall violated: 1 conflicting context pair(s) with node memory, 3 node(s) had untolerated taint(s). no new claims to deallocate, preemption: 0/6 nodes are available: 3 No preemption victims found for incoming pod, 3 Preemption is not helpful for scheduling."
60.307,Event,ADDED,eval-sanitize-2-r4-058-qlc2v.18d3d1dd30b8d37b,"reason=FailedScheduling count=None msg=0/6 nodes are available: 2 c_wall violated: 1 conflicting context pair(s) with node memory, 4 node(s) had untolerated taint(s). no new claims to deallocate, preemption: 0/6 nodes are available: 2 No preemption victims found for incoming pod, 4 Preemption is not helpful for scheduling."
60.3073,Event,ADDED,eval-sanitize-2-r4-058-qlc2v.18d3d1dd530dadfa,"reason=FailedScheduling count=None msg=0/6 nodes are available: 1 c_wall violated: 1 conflicting context pair(s) with node memory, 5 node(s) had untolerated taint(s). no new claims to deallocate, preemption: 0/6 nodes are available: 1 No preemption victims found for incoming pod, 5 Preemption is not helpful for scheduling."
60.3076,Event,ADDED,eval-sanitize-2-r4-058.18d3d1dcf03007d9,reason=SuccessfulCreate count=1 msg=Created pod: eval-sanitize-2-r4-058-qlc2v
60.3079,Event,ADDED,eval-sanitize-2-r4-059-rrppw.18d3d1dd3114f1de,"reason=FailedScheduling count=None msg=0/6 nodes are available: 2 c_wall violated: 1 conflicting context pair(s) with node memory, 4 node(s) had untolerated taint(s). no new claims to deallocate, preemption: 0/6 nodes are available: 2 No preemption victims found for incoming pod, 4 Preemption is not helpful for scheduling."
60.3082,Event,ADDED,eval-sanitize-2-r4-059-rrppw.18d3d1dd36c12298,"reason=FailedScheduling count=None msg=0/6 nodes are available: 2 c_wall violated: 1 conflicting context pair(s) with node memory, 4 node(s) had untolerated taint(s). no new claims to deallocate, preemption: 0/6 nodes are available: 2 No preemption victims found for incoming pod, 4 Preemption is not helpful for scheduling."
60.3085,Event,ADDED,eval-sanitize-2-r4-059-rrppw.18d3d1dd53598dae,"reason=FailedScheduling count=None msg=0/6 nodes are available: 1 c_wall violated: 1 conflicting context pair(s) with node memory, 5 node(s) had untolerated taint(s). no new claims to deallocate, preemption: 0/6 nodes are available: 1 No preemption victims found for incoming pod, 5 Preemption is not helpful for scheduling."
60.3087,Event,ADDED,eval-sanitize-2-r4-059.18d3d1dd2ccf2c9f,reason=SuccessfulCreate count=1 msg=Created pod: eval-sanitize-2-r4-059-rrppw
60.3091,Event,ADDED,eval-sanitize-2-r4-060.18d3d1dd67b114c2,reason=SuccessfulCreate count=1 msg=Created pod: eval-sanitize-2-r4-060-vvv88
60.3092,Event,ADDED,eval-sanitize-2-r4-060-vvv88.18d3d1dd67f8b0f2,"reason=FailedScheduling count=None msg=0/6 nodes are available: 1 c_wall violated: 1 conflicting context pair(s) with node memory, 5 node(s) had untolerated taint(s). no new claims to deallocate, preemption: 0/6 nodes are available: 1 No preemption victims found for incoming pod, 5 Preemption is not helpful for scheduling."
60.3094,Event,ADDED,eval-sanitize-2-r4-060-vvv88.18d3d1dd686f68e6,"reason=FailedScheduling count=None msg=0/6 nodes are available: 1 c_wall violated: 1 conflicting context pair(s) with node memory, 5 node(s) had untolerated taint(s). no new claims to deallocate, preemption: 0/6 nodes are available: 1 No preemption victims found for incoming pod, 5 Preemption is not helpful for scheduling."
60.4798,Node,MODIFIED,kind-worker5,taints=1
60.4848,Pod,MODIFIED,eval-sanitize-2-r4-058-qlc2v,phase=Pending node=None
60.49,Pod,MODIFIED,eval-sanitize-2-r4-053-h944b,phase=Pending node=None
60.4926,Node,MODIFIED,kind-worker5,taints=1
60.4939,Pod,MODIFIED,eval-sanitize-2-r4-059-rrppw,phase=Pending node=None
60.499,Pod,MODIFIED,eval-sanitize-2-r4-060-vvv88,phase=Pending node=None
60.5059,Event,MODIFIED,eval-sanitize-2-r4-060-vvv88.18d3d1dd686f68e6,"reason=FailedScheduling count=None msg=0/6 nodes are available: 1 c_wall violated: 1 conflicting context pair(s) with node memory, 5 node(s) had untolerated taint(s). no new claims to deallocate, preemption: 0/6 nodes are available: 1 No preemption victims found for incoming pod, 5 Preemption is not helpful for scheduling."
60.8852,Pod,MODIFIED,eval-sanitize-2-r4-046-8lqh5,phase=Running node=kind-worker3
60.9316,Job,MODIFIED,eval-sanitize-2-r4-052,
60.9415,Job,MODIFIED,eval-sanitize-2-r4-052,
61.0086,TaskRequest,ADDED,eval-sanitize-2-r4-061,phase=None job=None
61.0121,TaskRequest,MODIFIED,eval-sanitize-2-r4-061,phase=Pending job=None
61.0303,Job,ADDED,eval-sanitize-2-r4-061,
61.036,Pod,ADDED,eval-sanitize-2-r4-061-sbghd,phase=Pending node=None
61.0389,TaskRequest,MODIFIED,eval-sanitize-2-r4-061,phase=Scheduled job=None
61.0396,Job,MODIFIED,eval-sanitize-2-r4-061,
61.0426,Pod,MODIFIED,eval-sanitize-2-r4-061-sbghd,phase=Pending node=None
61.0438,Event,ADDED,eval-sanitize-2-r4-061-sbghd.18d3d1dda3273767,"reason=FailedScheduling count=None msg=0/6 nodes are available: 6 node(s) had untolerated taint(s). no new claims to deallocate, preemption: 0/6 nodes are available: 6 Preemption is not helpful for scheduling."
61.0445,Job,MODIFIED,eval-sanitize-2-r4-060,
61.045,Event,ADDED,eval-sanitize-2-r4-061.18d3d1dda31d7087,reason=SuccessfulCreate count=1 msg=Created pod: eval-sanitize-2-r4-061-sbghd
61.0535,TaskRequest,MODIFIED,eval-sanitize-2-r4-061,phase=Scheduled job=None
61.0654,Job,MODIFIED,eval-sanitize-2-r4-060,
61.8977,Job,MODIFIED,eval-sanitize-2-r4-046,
61.9076,Job,MODIFIED,eval-sanitize-2-r4-046,
61.9811,Pod,MODIFIED,eval-sanitize-2-r4-046-8lqh5,phase=Succeeded node=kind-worker3
62.0076,TaskRequest,ADDED,eval-sanitize-2-r4-062,phase=None job=None
62.0142,TaskRequest,MODIFIED,eval-sanitize-2-r4-062,phase=Pending job=None
62.0284,Job,ADDED,eval-sanitize-2-r4-062,
62.033,TaskRequest,MODIFIED,eval-sanitize-2-r4-062,phase=Scheduled job=None
62.0371,Job,MODIFIED,eval-sanitize-2-r4-062,
62.04,Pod,ADDED,eval-sanitize-2-r4-062-hqs7d,phase=Pending node=None
62.0408,TaskRequest,MODIFIED,eval-sanitize-2-r4-062,phase=Scheduled job=None
62.042,Job,MODIFIED,eval-sanitize-2-r4-061,
62.0434,Event,ADDED,eval-sanitize-2-r4-062.18d3d1dddeea42ec,reason=SuccessfulCreate count=1 msg=Created pod: eval-sanitize-2-r4-062-hqs7d
62.0466,Pod,MODIFIED,eval-sanitize-2-r4-062-hqs7d,phase=Pending node=None
62.0469,Event,ADDED,eval-sanitize-2-r4-062-hqs7d.18d3d1dddef9bfba,"reason=FailedScheduling count=None msg=0/6 nodes are available: 6 node(s) had untolerated taint(s). no new claims to deallocate, preemption: 0/6 nodes are available: 6 Preemption is not helpful for scheduling."
62.0517,Job,MODIFIED,eval-sanitize-2-r4-061,
62.859,Node,MODIFIED,kind-worker3,taints=1
62.8733,Node,MODIFIED,kind-worker3,taints=0
62.8789,Pod,MODIFIED,eval-sanitize-2-r4-058-qlc2v,phase=Pending node=kind-worker3
62.882,Node,MODIFIED,kind-worker3,taints=0
62.8862,Pod,MODIFIED,eval-sanitize-2-r4-053-h944b,phase=Pending node=kind-worker3
62.8895,Event,ADDED,eval-sanitize-2-r4-058-qlc2v.18d3d1de10eea26c,reason=Scheduled count=None msg=Successfully assigned compute/eval-sanitize-2-r4-058-qlc2v to kind-worker3
62.8899,Event,ADDED,eval-sanitize-2-r4-059-rrppw.18d3d1de1110820b,"reason=FailedScheduling count=None msg=0/6 nodes are available: 1 c_wall violated: 1 conflicting context pair(s) with node memory, 5 node(s) had untolerated taint(s). no new claims to deallocate, preemption: 0/6 nodes are available: 1 No preemption victims found for incoming pod, 5 Preemption is not helpful for scheduling."
62.8905,Event,ADDED,eval-sanitize-2-r4-053-h944b.18d3d1de115a872f,reason=Scheduled count=None msg=Successfully assigned compute/eval-sanitize-2-r4-053-h944b to kind-worker3
62.8914,Pod,MODIFIED,eval-sanitize-2-r4-059-rrppw,phase=Pending node=None
62.8952,Node,MODIFIED,kind-worker3,taints=0
62.8983,Pod,MODIFIED,eval-sanitize-2-r4-058-qlc2v,phase=Pending node=kind-worker3
62.8993,Pod,MODIFIED,eval-sanitize-2-r4-060-vvv88,phase=Pending node=kind-worker3
62.9056,Job,MODIFIED,eval-sanitize-2-r4-046,
62.9078,Pod,MODIFIED,eval-sanitize-2-r4-061-sbghd,phase=Pending node=None
62.9082,Event,ADDED,eval-sanitize-2-r4-061-sbghd.18d3d1de121989b7,"reason=FailedScheduling count=None msg=0/6 nodes are available: 1 c_wall violated: 1 conflicting context pair(s) with node memory, 5 node(s) had untolerated taint(s). no new claims to deallocate, preemption: 0/6 nodes are available: 1 No preemption victims found for incoming pod, 5 Preemption is not helpful for scheduling."
62.9084,Event,ADDED,eval-sanitize-2-r4-060-vvv88.18d3d1de122d5982,reason=Scheduled count=None msg=Successfully assigned compute/eval-sanitize-2-r4-060-vvv88 to kind-worker3
62.9107,Pod,MODIFIED,eval-sanitize-2-r4-053-h944b,phase=Pending node=kind-worker3
62.9125,Node,MODIFIED,kind-worker3,taints=0
62.918,Job,MODIFIED,eval-sanitize-2-r4-046,
62.9212,Pod,MODIFIED,eval-sanitize-2-r4-046-8lqh5,phase=Succeeded node=kind-worker3
62.9216,Event,ADDED,eval-sanitize-2-r4-059-rrppw.18d3d1de130cb12c,"reason=FailedScheduling count=None msg=0/6 nodes are available: 1 c_wall violated: 2 conflicting context pair(s) with node memory, 5 node(s) had untolerated taint(s). no new claims to deallocate, preemption: 0/6 nodes are available: 1 No preemption victims found for incoming pod, 5 Preemption is not helpful for scheduling."
