t_recv,kind,type,name,detail
0.0267,Node,ADDED,kind-control-plane,taints=1
0.0284,Node,ADDED,kind-worker,taints=0
0.0303,Node,ADDED,kind-worker2,taints=0
0.0319,Node,ADDED,kind-worker3,taints=0
0.0332,Node,ADDED,kind-worker4,taints=0
0.0346,Node,ADDED,kind-worker5,taints=0
0.043,TaskRequest,ADDED,eval-sanitize-50-r4-000,phase=None job=None
0.05,TaskRequest,MODIFIED,eval-sanitize-50-r4-000,phase=Pending job=None
0.0682,Event,ADDED,eval-sanitize-30-r0-017-gzrg7.18d4f7781e8da3fc,"reason=FailedScheduling count=None msg=0/6 nodes are available: 1 node(s) had untolerated taint(s), 2 c_wall violated: 2 conflicting context pair(s) with node memory, 3 c_wall violated: 1 conflicting context pair(s) with node memory. no new claims to deallocate, preemption: 0/6 nodes are available: 1 Preemption is not helpful for scheduling, 5 No preemption victims found for incoming pod."
0.0688,Event,ADDED,eval-sanitize-30-r0-019-dtq8t.18d4f7788fe8a465,"reason=FailedScheduling count=None msg=0/6 nodes are available: 1 c_wall violated: 1 conflicting context pair(s) with node memory, 1 node(s) had untolerated taint(s), 4 c_wall violated: 2 conflicting context pair(s) with node memory. no new claims to deallocate, preemption: 0/6 nodes are available: 1 Preemption is not helpful for scheduling, 5 No preemption victims found for incoming pod."
0.0694,Event,ADDED,eval-sanitize-30-r0-020-lk5cb.18d4f778d14c840a,"reason=FailedScheduling count=None msg=0/6 nodes are available: 1 c_wall violated: 2 conflicting context pair(s) with node memory, 1 c_wall violated: 3 conflicting context pair(s) with node memory, 1 node(s) had untolerated taint(s), 3 c_wall violated: 1 conflicting context pair(s) with node memory. no new claims to deallocate, preemption: 0/6 nodes are available: 1 Preemption is not helpful for scheduling, 5 No preemption victims found for incoming pod."
0.0704,Event,ADDED,eval-sanitize-30-r0-022-c28vw.18d4f7796b987ea1,"reason=FailedScheduling count=None msg=0/6 nodes are available: 1 node(s) had untolerated taint(s), 2 c_wall violated: 2 conflicting context pair(s) with node memory, 3 c_wall violated: 1 conflicting context pair(s) with node memory. no new claims to deallocate, preemption: 0/6 nodes are available: 1 Preemption is not helpful for scheduling, 5 No preemption victims found for incoming pod."
0.0712,Event,ADDED,eval-sanitize-30-r0-023-g56qt.18d4f779cacc5595,"reason=FailedScheduling count=None msg=0/6 nodes are available: 1 c_wall violated: 1 conflicting context pair(s) with node memory, 1 node(s) had untolerated taint(s), 4 c_wall violated: 2 conflicting context pair(s) with node memory. no new claims to deallocate, preemption: 0/6 nodes are available: 1 Preemption is not helpful for scheduling, 5 No preemption victims found for incoming pod."
0.0718,Event,ADDED,eval-sanitize-30-r0-086-5m2jb.18d4f788ffd90381,"reason=FailedScheduling count=None msg=0/6 nodes are available: 1 c_wall violated: 1 conflicting context pair(s) with node memory, 1 c_wall violated: 2 conflicting context pair(s) with node memory, 1 c_wall violated: 3 conflicting context pair(s) with node memory, 3 node(s) had untolerated taint(s). no new claims to deallocate, preemption: 0/6 nodes are available: 3 No preemption victims found for incoming pod, 3 Preemption is not helpful for scheduling."
0.0726,Event,ADDED,eval-sanitize-30-r0-086-5m2jb.18d4f78910cd3741,"reason=FailedScheduling count=None msg=0/6 nodes are available: 1 c_wall violated: 1 conflicting context pair(s) with node memory, 1 c_wall violated: 2 conflicting context pair(s) with node memory, 4 node(s) had untolerated taint(s). no new claims to deallocate, preemption: 0/6 nodes are available: 2 No preemption victims found for incoming pod, 4 Preemption is not helpful for scheduling."
0.0732,Event,ADDED,eval-sanitize-30-r0-092-xmsjg.18d4f78fcdf3e2de,"reason=FailedScheduling count=None msg=0/6 nodes are available: 1 c_wall violated: 1 conflicting context pair(s) with node memory, 5 node(s) had untolerated taint(s). no new claims to deallocate, preemption: 0/6 nodes are available: 1 No preemption victims found for incoming pod, 5 Preemption is not helpful for scheduling."
0.0737,Event,ADDED,eval-sanitize-30-r0-094-xwx95.18d4f78fd2c8ec49,"reason=FailedScheduling count=None msg=0/6 nodes are available: 1 c_wall violated: 1 conflicting context pair(s) with node memory, 5 node(s) had untolerated taint(s). no new claims to deallocate, preemption: 0/6 nodes are available: 1 No preemption victims found for incoming pod, 5 Preemption is not helpful for scheduling."
0.0745,Event,ADDED,eval-sanitize-30-r0-147-6pl7z.18d4f79721babd83,"reason=FailedScheduling count=None msg=0/6 nodes are available: 3 c_wall violated: 1 conflicting context pair(s) with node memory, 3 node(s) had untolerated taint(s). no new claims to deallocate, preemption: 0/6 nodes are available: 3 No preemption victims found for incoming pod, 3 Preemption is not helpful for scheduling."
0.0748,Event,ADDED,eval-sanitize-30-r0-147-6pl7z.18d4f79737a4ade6,"reason=FailedScheduling count=None msg=0/6 nodes are available: 2 c_wall violated: 1 conflicting context pair(s) with node memory, 4 node(s) had untolerated taint(s). no new claims to deallocate, preemption: 0/6 nodes are available: 2 No preemption victims found for incoming pod, 4 Preemption is not helpful for scheduling."
0.0754,Event,ADDED,eval-sanitize-30-r0-150-5wnxz.18d4f79df3dd7730,"reason=FailedScheduling count=None msg=0/6 nodes are available: 1 c_wall violated: 1 conflicting context pair(s) with node memory, 5 node(s) had untolerated taint(s). no new claims to deallocate, preemption: 0/6 nodes are available: 1 No preemption victims found for incoming pod, 5 Preemption is not helpful for scheduling."
0.0765,Job,ADDED,eval-sanitize-50-r4-000,
0.0774,Event,ADDED,eval-sanitize-30-r1-009-xl4wc.18d4f7b4a4df4ff8,"reason=FailedScheduling count=None msg=0/6 nodes are available: 1 c_wall violated: 1 conflicting context pair(s) with node memory, 5 node(s) had untolerated taint(s). no new claims to deallocate, preemption: 0/6 nodes are available: 1 No preemption victims found for incoming pod, 5 Preemption is not helpful for scheduling."
0.0781,Event,ADDED,eval-sanitize-30-r1-010-fbtrj.18d4f7b4dc9a8f27,"reason=FailedScheduling count=None msg=0/6 nodes are available: 1 c_wall violated: 3 conflicting context pair(s) with node memory, 5 node(s) had untolerated taint(s). no new claims to deallocate, preemption: 0/6 nodes are available: 1 No preemption victims found for incoming pod, 5 Preemption is not helpful for scheduling."
0.0785,Event,ADDED,eval-sanitize-30-r1-012-db7nz.18d4f7b552fd1209,"reason=FailedScheduling count=None msg=0/6 nodes are available: 1 c_wall violated: 3 conflicting context pair(s) with node memory, 5 node(s) had untolerated taint(s). no new claims to deallocate, preemption: 0/6 nodes are available: 1 No preemption victims found for incoming pod, 5 Preemption is not helpful for scheduling."
0.0791,Event,ADDED,eval-sanitize-30-r1-013-6dvdk.18d4f7b58e90efe6,"reason=FailedScheduling count=None msg=0/6 nodes are available: 1 c_wall violated: 2 conflicting context pair(s) with node memory, 5 node(s) had untolerated taint(s). no new claims to deallocate, preemption: 0/6 nodes are available: 1 No preemption victims found for incoming pod, 5 Preemption is not helpful for scheduling."
0.0799,Event,ADDED,eval-sanitize-30-r1-014-vsj6m.18d4f7b5cccf0b9f,"reason=FailedScheduling count=None msg=0/6 nodes are available: 1 c_wall violated: 1 conflicting context pair(s) with node memory, 5 node(s) had untolerated taint(s). no new claims to deallocate, preemption: 0/6 nodes are available: 1 No preemption victims found for incoming pod, 5 Preemption is not helpful for scheduling."
0.0807,Event,ADDED,eval-sanitize-30-r1-016-kwgh4.18d4f7b64267c363,"reason=FailedScheduling count=None msg=0/6 nodes are available: 1 c_wall violated: 3 conflicting context pair(s) with node memory, 5 node(s) had untolerated taint(s). no new claims to deallocate, preemption: 0/6 nodes are available: 1 No preemption victims found for incoming pod, 5 Preemption is not helpful for scheduling."
0.0814,Event,ADDED,eval-sanitize-30-r1-017-4njv5.18d4f7b67cb6bf54,"reason=FailedScheduling count=None msg=0/6 nodes are available: 1 c_wall violated: 2 conflicting context pair(s) with node memory, 5 node(s) had untolerated taint(s). no new claims to deallocate, preemption: 0/6 nodes are available: 1 No preemption victims found for incoming pod, 5 Preemption is not helpful for scheduling."
0.0831,Event,ADDED,eval-sanitize-30-r1-019-hnqzk.18d4f7b6f518d837,"reason=FailedScheduling count=None msg=0/6 nodes are available: 1 c_wall violated: 1 conflicting context pair(s) with node memory, 5 node(s) had untolerated taint(s). no new claims to deallocate, preemption: 0/6 nodes are available: 1 No preemption victims found for incoming pod, 5 Preemption is not helpful for scheduling."
0.0839,Event,ADDED,eval-sanitize-30-r1-019-hnqzk.18d4f7ba082a7263,"reason=FailedScheduling count=None msg=0/6 nodes are available: 2 c_wall violated: 1 conflicting context pair(s) with node memory, 4 node(s) had untolerated taint(s). no new claims to deallocate, preemption: 0/6 nodes are available: 2 No preemption victims found for incoming pod, 4 Preemption is not helpful for scheduling."
0.0845,Event,ADDED,eval-sanitize-30-r1-019-hnqzk.18d4f7ba7dff7762,"reason=FailedScheduling count=None msg=0/6 nodes are available: 1 c_wall violated: 1 conflicting context pair(s) with node memory, 1 c_wall violated: 2 conflicting context pair(s) with node memory, 4 node(s) had untolerated taint(s). no new claims to deallocate, preemption: 0/6 nodes are available: 2 No preemption victims found for incoming pod, 4 Preemption is not helpful for scheduling."
0.0853,Event,ADDED,eval-sanitize-30-r1-020-6m9rn.18d4f7b73298a8ed,"reason=FailedScheduling count=None msg=0/6 nodes are available: 1 c_wall violated: 2 conflicting context pair(s) with node memory, 5 node(s) had untolerated taint(s). no new claims to deallocate, preemption: 0/6 nodes are available: 1 No preemption victims found for incoming pod, 5 Preemption is not helpful for scheduling."
0.0857,TaskRequest,MODIFIED,eval-sanitize-50-r4-000,phase=Scheduled job=None
0.0866,Event,ADDED,eval-sanitize-30-r1-022-jd2rp.18d4f7b7acb663a7,"reason=FailedScheduling count=None msg=0/6 nodes are available: 1 c_wall violated: 1 conflicting context pair(s) with node memory, 5 node(s) had untolerated taint(s). no new claims to deallocate, preemption: 0/6 nodes are available: 1 No preemption victims found for incoming pod, 5 Preemption is not helpful for scheduling."
0.0875,Event,ADDED,eval-sanitize-30-r1-022-jd2rp.18d4f7ba0e860b76,"reason=FailedScheduling count=None msg=0/6 nodes are available: 2 c_wall violated: 1 conflicting context pair(s) with node memory, 4 node(s) had untolerated taint(s). no new claims to deallocate, preemption: 0/6 nodes are available: 2 No preemption victims found for incoming pod, 4 Preemption is not helpful for scheduling."
0.0888,Event,ADDED,eval-sanitize-30-r1-022-jd2rp.18d4f7ba7306aa44,"reason=FailedScheduling count=None msg=0/6 nodes are available: 1 c_wall violated: 1 conflicting context pair(s) with node memory, 1 c_wall violated: 2 conflicting context pair(s) with node memory, 4 node(s) had untolerated taint(s). no new claims to deallocate, preemption: 0/6 nodes are available: 2 No preemption victims found for incoming pod, 4 Preemption is not helpful for scheduling."
0.0906,Pod,ADDED,eval-sanitize-50-r4-000-lvsn9,phase=Pending node=None
0.0914,Event,ADDED,eval-sanitize-30-r1-023-dhxd2.18d4f7b7e712c69e,"reason=FailedScheduling count=None msg=0/6 nodes are available: 1 c_wall violated: 2 conflicting context pair(s) with node memory, 5 node(s) had untolerated taint(s). no new claims to deallocate, preemption: 0/6 nodes are available: 1 No preemption victims found for incoming pod, 5 Preemption is not helpful for scheduling."
0.0921,Event,ADDED,eval-sanitize-30-r1-024-cb488.18d4f7b829e2a2f7,"reason=FailedScheduling count=None msg=0/6 nodes are available: 1 c_wall violated: 2 conflicting context pair(s) with node memory, 5 node(s) had untolerated taint(s). no new claims to deallocate, preemption: 0/6 nodes are available: 1 No preemption victims found for incoming pod, 5 Preemption is not helpful for scheduling."
0.0927,Event,ADDED,eval-sanitize-30-r1-024-cb488.18d4f7ba0e0f209f,"reason=FailedScheduling count=None msg=0/6 nodes are available: 1 c_wall violated: 1 conflicting context pair(s) with node memory, 1 c_wall violated: 2 conflicting context pair(s) with node memory, 4 node(s) had untolerated taint(s). no new claims to deallocate, preemption: 0/6 nodes are available: 2 No preemption victims found for incoming pod, 4 Preemption is not helpful for scheduling."
0.093,Event,ADDED,eval-sanitize-30-r1-024-cb488.18d4f7ba7eee4289,"reason=FailedScheduling count=None msg=0/6 nodes are available: 1 c_wall violated: 1 conflicting context pair(s) with node memory, 1 c_wall violated: 2 conflicting context pair(s) with node memory, 4 node(s) had untolerated taint(s). no new claims to deallocate, preemption: 0/6 nodes are available: 2 No preemption victims found for incoming pod, 4 Preemption is not helpful for scheduling."
0.0933,Event,ADDED,eval-sanitize-30-r1-025-d2f7x.18d4f7b8598a34c9,"reason=FailedScheduling count=None msg=0/6 nodes are available: 1 c_wall violated: 1 conflicting context pair(s) with node memory, 5 node(s) had untolerated taint(s). no new claims to deallocate, preemption: 0/6 nodes are available: 1 No preemption victims found for incoming pod, 5 Preemption is not helpful for scheduling."
0.0945,Job,MODIFIED,eval-sanitize-50-r4-000,
0.0956,Event,ADDED,eval-sanitize-30-r1-026-txmv6.18d4f7b894dad96a,"reason=FailedScheduling count=None msg=0/6 nodes are available: 1 c_wall violated: 2 conflicting context pair(s) with node memory, 5 node(s) had untolerated taint(s). no new claims to deallocate, preemption: 0/6 nodes are available: 1 No preemption victims found for incoming pod, 5 Preemption is not helpful for scheduling."
0.0964,Event,ADDED,eval-sanitize-30-r1-028-x9tsd.18d4f7b90f66ab9d,"reason=FailedScheduling count=None msg=0/6 nodes are available: 1 c_wall violated: 1 conflicting context pair(s) with node memory, 5 node(s) had untolerated taint(s). no new claims to deallocate, preemption: 0/6 nodes are available: 1 No preemption victims found for incoming pod, 5 Preemption is not helpful for scheduling."
0.0971,Event,ADDED,eval-sanitize-30-r1-030-v5n6w.18d4f7b98974196b,"reason=FailedScheduling count=None msg=0/6 nodes are available: 1 c_wall violated: 2 conflicting context pair(s) with node memory, 5 node(s) had untolerated taint(s). no new claims to deallocate, preemption: 0/6 nodes are available: 1 No preemption victims found for incoming pod, 5 Preemption is not helpful for scheduling."
0.0973,TaskRequest,MODIFIED,eval-sanitize-50-r4-000,phase=Scheduled job=None
0.0978,Event,ADDED,eval-sanitize-30-r1-032-jgbm7.18d4f7ba738dc192,"reason=FailedScheduling count=None msg=0/6 nodes are available: 1 c_wall violated: 1 conflicting context pair(s) with node memory, 1 c_wall violated: 2 conflicting context pair(s) with node memory, 4 node(s) had untolerated taint(s). no new claims to deallocate, preemption: 0/6 nodes are available: 2 No preemption victims found for incoming pod, 4 Preemption is not helpful for scheduling."
0.098,Event,ADDED,eval-sanitize-30-r1-067-4l2v6.18d4f7c22801f78c,"reason=FailedScheduling count=None msg=0/6 nodes are available: 1 c_wall violated: 2 conflicting context pair(s) with node memory, 5 node(s) had untolerated taint(s). no new claims to deallocate, preemption: 0/6 nodes are available: 1 No preemption victims found for incoming pod, 5 Preemption is not helpful for scheduling."
0.0983,Event,ADDED,eval-sanitize-30-r1-067-4l2v6.18d4f7c3160bf416,"reason=FailedScheduling count=None msg=0/6 nodes are available: 1 c_wall violated: 3 conflicting context pair(s) with node memory, 5 node(s) had untolerated taint(s). no new claims to deallocate, preemption: 0/6 nodes are available: 1 No preemption victims found for incoming pod, 5 Preemption is not helpful for scheduling."
0.0987,Event,ADDED,eval-sanitize-30-r1-067-4l2v6.18d4f7c504d1a7ae,"reason=FailedScheduling count=None msg=0/6 nodes are available: 1 c_wall violated: 4 conflicting context pair(s) with node memory, 5 node(s) had untolerated taint(s). no new claims to deallocate, preemption: 0/6 nodes are available: 1 No preemption victims found for incoming pod, 5 Preemption is not helpful for scheduling."
0.099,Event,ADDED,eval-sanitize-30-r1-067-4l2v6.18d4f7c8289c7cda,"reason=FailedScheduling count=None msg=0/6 nodes are available: 1 c_wall violated: 1 conflicting context pair(s) with node memory, 1 c_wall violated: 4 conflicting context pair(s) with node memory, 4 node(s) had untolerated taint(s). no new claims to deallocate, preemption: 0/6 nodes are available: 2 No preemption victims found for incoming pod, 4 Preemption is not helpful for scheduling."
0.0995,Event,ADDED,eval-sanitize-30-r1-067-4l2v6.18d4f7c889293e8e,"reason=FailedScheduling count=None msg=0/6 nodes are available: 2 c_wall violated: 1 conflicting context pair(s) with node memory, 4 node(s) had untolerated taint(s). no new claims to deallocate, preemption: 0/6 nodes are available: 2 No preemption victims found for incoming pod, 4 Preemption is not helpful for scheduling."
0.1002,Event,ADDED,eval-sanitize-30-r1-068-8f9gb.18d4f7c265624ecc,"reason=FailedScheduling count=None msg=0/6 nodes are available: 1 c_wall violated: 1 conflicting context pair(s) with node memory, 5 node(s) had untolerated taint(s). no new claims to deallocate, preemption: 0/6 nodes are available: 1 No preemption victims found for incoming pod, 5 Preemption is not helpful for scheduling."
0.1005,Event,ADDED,eval-sanitize-30-r1-068-8f9gb.18d4f7c31648365a,"reason=FailedScheduling count=None msg=0/6 nodes are available: 1 c_wall violated: 2 conflicting context pair(s) with node memory, 5 node(s) had untolerated taint(s). no new claims to deallocate, preemption: 0/6 nodes are available: 1 No preemption victims found for incoming pod, 5 Preemption is not helpful for scheduling."
0.101,Event,ADDED,eval-sanitize-30-r1-069-x8bxc.18d4f7c2985abf60,"reason=FailedScheduling count=None msg=0/6 nodes are available: 1 c_wall violated: 2 conflicting context pair(s) with node memory, 5 node(s) had untolerated taint(s). no new claims to deallocate, preemption: 0/6 nodes are available: 1 No preemption victims found for incoming pod, 5 Preemption is not helpful for scheduling."
0.1013,Event,ADDED,eval-sanitize-30-r1-069-x8bxc.18d4f7c31688d176,"reason=FailedScheduling count=None msg=0/6 nodes are available: 1 c_wall violated: 3 conflicting context pair(s) with node memory, 5 node(s) had untolerated taint(s). no new claims to deallocate, preemption: 0/6 nodes are available: 1 No preemption victims found for incoming pod, 5 Preemption is not helpful for scheduling."
0.1015,Event,ADDED,eval-sanitize-30-r1-070-g26h5.18d4f7c2d49e72ae,"reason=FailedScheduling count=None msg=0/6 nodes are available: 1 c_wall violated: 2 conflicting context pair(s) with node memory, 5 node(s) had untolerated taint(s). no new claims to deallocate, preemption: 0/6 nodes are available: 1 No preemption victims found for incoming pod, 5 Preemption is not helpful for scheduling."
0.1019,Event,ADDED,eval-sanitize-30-r1-070-g26h5.18d4f7c31a42c2d4,"reason=FailedScheduling count=None msg=0/6 nodes are available: 1 c_wall violated: 3 conflicting context pair(s) with node memory, 5 node(s) had untolerated taint(s). no new claims to deallocate, preemption: 0/6 nodes are available: 1 No preemption victims found for incoming pod, 5 Preemption is not helpful for scheduling."
0.1021,Event,ADDED,eval-sanitize-30-r1-070-g26h5.18d4f7c5053c45ee,"reason=FailedScheduling count=None msg=0/6 nodes are available: 1 c_wall violated: 4 conflicting context pair(s) with node memory, 5 node(s) had untolerated taint(s). no new claims to deallocate, preemption: 0/6 nodes are available: 1 No preemption victims found for incoming pod, 5 Preemption is not helpful for scheduling."
0.1023,Event,ADDED,eval-sanitize-30-r1-070-g26h5.18d4f7c82ea5038a,"reason=FailedScheduling count=None msg=0/6 nodes are available: 1 c_wall violated: 1 conflicting context pair(s) with node memory, 1 c_wall violated: 4 conflicting context pair(s) with node memory, 4 node(s) had untolerated taint(s). no new claims to deallocate, preemption: 0/6 nodes are available: 2 No preemption victims found for incoming pod, 4 Preemption is not helpful for scheduling."
0.1035,Event,ADDED,eval-sanitize-30-r1-070-g26h5.18d4f7c8833177cb,"reason=FailedScheduling count=None msg=0/6 nodes are available: 2 c_wall violated: 1 conflicting context pair(s) with node memory, 4 node(s) had untolerated taint(s). no new claims to deallocate, preemption: 0/6 nodes are available: 2 No preemption victims found for incoming pod, 4 Preemption is not helpful for scheduling."
0.104,Event,ADDED,eval-sanitize-30-r1-073-88phz.18d4f7c386ceb5ec,"reason=FailedScheduling count=None msg=0/6 nodes are available: 1 c_wall violated: 2 conflicting context pair(s) with node memory, 5 node(s) had untolerated taint(s). no new claims to deallocate, preemption: 0/6 nodes are available: 1 No preemption victims found for incoming pod, 5 Preemption is not helpful for scheduling."
0.1045,Event,ADDED,eval-sanitize-30-r1-074-9bcjv.18d4f7c3c2b5887d,"reason=FailedScheduling count=None msg=0/6 nodes are available: 1 c_wall violated: 3 conflicting context pair(s) with node memory, 5 node(s) had untolerated taint(s). no new claims to deallocate, preemption: 0/6 nodes are available: 1 No preemption victims found for incoming pod, 5 Preemption is not helpful for scheduling."
0.1051,Event,ADDED,eval-sanitize-30-r1-077-j9c5b.18d4f7c476d137b2,"reason=FailedScheduling count=None msg=0/6 nodes are available: 1 c_wall violated: 3 conflicting context pair(s) with node memory, 5 node(s) had untolerated taint(s). no new claims to deallocate, preemption: 0/6 nodes are available: 1 No preemption victims found for incoming pod, 5 Preemption is not helpful for scheduling."
0.1058,Event,ADDED,eval-sanitize-30-r1-080-8rqsm.18d4f7c527b15e2d,"reason=FailedScheduling count=None msg=0/6 nodes are available: 1 c_wall violated: 1 conflicting context pair(s) with node memory, 5 node(s) had untolerated taint(s). no new claims to deallocate, preemption: 0/6 nodes are available: 1 No preemption victims found for incoming pod, 5 Preemption is not helpful for scheduling."
0.1064,Event,ADDED,eval-sanitize-30-r1-080-8rqsm.18d4f7c834b72df1,"reason=FailedScheduling count=None msg=0/6 nodes are available: 2 c_wall violated: 1 conflicting context pair(s) with node memory, 4 node(s) had untolerated taint(s). no new claims to deallocate, preemption: 0/6 nodes are available: 2 No preemption victims found for incoming pod, 4 Preemption is not helpful for scheduling."
0.107,Event,ADDED,eval-sanitize-30-r1-080-8rqsm.18d4f7c888b637ef,"reason=FailedScheduling count=None msg=0/6 nodes are available: 2 c_wall violated: 1 conflicting context pair(s) with node memory, 4 node(s) had untolerated taint(s). no new claims to deallocate, preemption: 0/6 nodes are available: 2 No preemption victims found for incoming pod, 4 Preemption is not helpful for scheduling."
0.1074,Event,ADDED,eval-sanitize-30-r1-082-wppn2.18d4f7c59f9543c3,"reason=FailedScheduling count=None msg=0/6 nodes are available: 1 c_wall violated: 2 conflicting context pair(s) with node memory, 5 node(s) had untolerated taint(s). no new claims to deallocate, preemption: 0/6 nodes are available: 1 No preemption victims found for incoming pod, 5 Preemption is not helpful for scheduling."
0.1084,Pod,MODIFIED,eval-sanitize-50-r4-000-lvsn9,phase=Pending node=kind-worker5
0.1092,Event,ADDED,eval-sanitize-30-r1-083-g97l5.18d4f7c5db9a53ca,"reason=FailedScheduling count=None msg=0/6 nodes are available: 1 c_wall violated: 3 conflicting context pair(s) with node memory, 5 node(s) had untolerated taint(s). no new claims to deallocate, preemption: 0/6 nodes are available: 1 No preemption victims found for incoming pod, 5 Preemption is not helpful for scheduling."
0.11,Event,ADDED,eval-sanitize-30-r1-087-n8l2p.18d4f7c6c9a110fb,"reason=FailedScheduling count=None msg=0/6 nodes are available: 1 c_wall violated: 3 conflicting context pair(s) with node memory, 5 node(s) had untolerated taint(s). no new claims to deallocate, preemption: 0/6 nodes are available: 1 No preemption victims found for incoming pod, 5 Preemption is not helpful for scheduling."
0.1104,Event,ADDED,eval-sanitize-30-r1-088-z9jkk.18d4f7c70669e862,"reason=FailedScheduling count=None msg=0/6 nodes are available: 1 c_wall violated: 3 conflicting context pair(s) with node memory, 5 node(s) had untolerated taint(s). no new claims to deallocate, preemption: 0/6 nodes are available: 1 No preemption victims found for incoming pod, 5 Preemption is not helpful for scheduling."
0.1117,Event,ADDED,eval-sanitize-30-r1-094-xsdwg.18d4f7c88214a20f,"reason=FailedScheduling count=None msg=0/6 nodes are available: 2 c_wall violated: 1 conflicting context pair(s) with node memory, 4 node(s) had untolerated taint(s). no new claims to deallocate, preemption: 0/6 nodes are available: 2 No preemption victims found for incoming pod, 4 Preemption is not helpful for scheduling."
0.1126,Event,ADDED,eval-sanitize-30-r1-127-8vq9b.18d4f7d01e390b19,"reason=FailedScheduling count=None msg=0/6 nodes are available: 1 c_wall violated: 2 conflicting context pair(s) with node memory, 5 node(s) had untolerated taint(s). no new claims to deallocate, preemption: 0/6 nodes are available: 1 No preemption victims found for incoming pod, 5 Preemption is not helpful for scheduling."
0.113,Event,ADDED,eval-sanitize-30-r1-127.18d4f7dd4943248d,reason=Completed count=1 msg=Job completed
0.1134,Event,ADDED,eval-sanitize-30-r1-128-g4mr4.18d4f7d056bf7bca,"reason=FailedScheduling count=None msg=0/6 nodes are available: 1 c_wall violated: 2 conflicting context pair(s) with node memory, 5 node(s) had untolerated taint(s). no new claims to deallocate, preemption: 0/6 nodes are available: 1 No preemption victims found for incoming pod, 5 Preemption is not helpful for scheduling."
0.1139,Event,ADDED,eval-sanitize-30-r1-128.18d4f7dcf7cf0f51,reason=Completed count=1 msg=Job completed
0.1142,Event,ADDED,eval-sanitize-30-r1-129-pz5vs.18d4f7d095a67522,"reason=FailedScheduling count=None msg=0/6 nodes are available: 1 c_wall violated: 2 conflicting context pair(s) with node memory, 5 node(s) had untolerated taint(s). no new claims to deallocate, preemption: 0/6 nodes are available: 1 No preemption victims found for incoming pod, 5 Preemption is not helpful for scheduling."
0.1154,Event,ADDED,eval-sanitize-30-r1-130-48f5x.18d4f7d0d3b202f4,"reason=FailedScheduling count=None msg=0/6 nodes are available: 1 c_wall violated: 1 conflicting context pair(s) with node memory, 5 node(s) had untolerated taint(s). no new claims to deallocate, preemption: 0/6 nodes are available: 1 No preemption victims found for incoming pod, 5 Preemption is not helpful for scheduling."
0.1159,Event,ADDED,eval-sanitize-30-r1-130.18d4f7dd31c0a6bf,reason=Completed count=1 msg=Job completed
0.1162,Event,ADDED,eval-sanitize-30-r1-131-429ph.18d4f7d10d45822c,"reason=FailedScheduling count=None msg=0/6 nodes are available: 1 c_wall violated: 2 conflicting context pair(s) with node memory, 5 node(s) had untolerated taint(s). no new claims to deallocate, preemption: 0/6 nodes are available: 1 No preemption victims found for incoming pod, 5 Preemption is not helpful for scheduling."
0.1164,Event,ADDED,eval-sanitize-30-r1-131.18d4f7ddaf8427a9,reason=Completed count=1 msg=Job completed
0.1169,Event,ADDED,eval-sanitize-30-r1-132-d4rwp.18d4f7d1499fc218,"reason=FailedScheduling count=None msg=0/6 nodes are available: 1 c_wall violated: 2 conflicting context pair(s) with node memory, 5 node(s) had untolerated taint(s). no new claims to deallocate, preemption: 0/6 nodes are available: 1 No preemption victims found for incoming pod, 5 Preemption is not helpful for scheduling."
0.1171,Event,ADDED,eval-sanitize-30-r1-132.18d4f7dd6d6ed33f,reason=Completed count=1 msg=Job completed
0.1182,Event,ADDED,eval-sanitize-30-r1-133-92v5f.18d4f7d17f89c993,"reason=FailedScheduling count=None msg=0/6 nodes are available: 1 c_wall violated: 1 conflicting context pair(s) with node memory, 5 node(s) had untolerated taint(s). no new claims to deallocate, preemption: 0/6 nodes are available: 1 No preemption victims found for incoming pod, 5 Preemption is not helpful for scheduling."
0.1192,Event,ADDED,eval-sanitize-30-r1-133.18d4f7ddba9f3bde,reason=Completed count=1 msg=Job completed
0.1196,Event,ADDED,eval-sanitize-30-r1-134-64jzf.18d4f7d1bc4e656f,"reason=FailedScheduling count=None msg=0/6 nodes are available: 1 c_wall violated: 2 conflicting context pair(s) with node memory, 5 node(s) had untolerated taint(s). no new claims to deallocate, preemption: 0/6 nodes are available: 1 No preemption victims found for incoming pod, 5 Preemption is not helpful for scheduling."
0.1199,Event,ADDED,eval-sanitize-30-r1-134-64jzf.18d4f7d6a5598396,"reason=FailedScheduling count=None msg=0/6 nodes are available: 2 c_wall violated: 2 conflicting context pair(s) with node memory, 4 node(s) had untolerated taint(s). no new claims to deallocate, preemption: 0/6 nodes are available: 2 No preemption victims found for incoming pod, 4 Preemption is not helpful for scheduling."
0.1212,Pod,MODIFIED,eval-sanitize-50-r4-000-lvsn9,phase=Pending node=kind-worker5
0.1217,Event,ADDED,eval-sanitize-30-r1-134.18d4f7ddd597ec71,reason=Completed count=1 msg=Job completed
0.1219,Event,ADDED,eval-sanitize-30-r1-135-vljhq.18d4f7d1f5fc7167,"reason=FailedScheduling count=None msg=0/6 nodes are available: 1 c_wall violated: 1 conflicting context pair(s) with node memory, 5 node(s) had untolerated taint(s). no new claims to deallocate, preemption: 0/6 nodes are available: 1 No preemption victims found for incoming pod, 5 Preemption is not helpful for scheduling."
0.1221,Event,ADDED,eval-sanitize-30-r1-135.18d4f7dd2e8055b3,reason=Completed count=1 msg=Job completed
0.1225,Event,ADDED,eval-sanitize-30-r1-138-94lsw.18d4f7d2a93dd87f,"reason=FailedScheduling count=None msg=0/6 nodes are available: 1 c_wall violated: 2 conflicting context pair(s) with node memory, 5 node(s) had untolerated taint(s). no new claims to deallocate, preemption: 0/6 nodes are available: 1 No preemption victims found for incoming pod, 5 Preemption is not helpful for scheduling."
0.1227,Event,ADDED,eval-sanitize-30-r1-138.18d4f7dd79123213,reason=Completed count=1 msg=Job completed
0.1231,Event,ADDED,eval-sanitize-30-r1-139-75tz8.18d4f7d2e7f172e1,"reason=FailedScheduling count=None msg=0/6 nodes are available: 1 c_wall violated: 1 conflicting context pair(s) with node memory, 5 node(s) had untolerated taint(s). no new claims to deallocate, preemption: 0/6 nodes are available: 1 No preemption victims found for incoming pod, 5 Preemption is not helpful for scheduling."
0.1248,Node,MODIFIED,kind-worker5,taints=0
0.1251,Event,ADDED,eval-sanitize-30-r1-140-mqfhq.18d4f7d3254f2ce9,"reason=FailedScheduling count=None msg=0/6 nodes are available: 1 c_wall violated: 1 conflicting context pair(s) with node memory, 5 node(s) had untolerated taint(s). no new claims to deallocate, preemption: 0/6 nodes are available: 1 No preemption victims found for incoming pod, 5 Preemption is not helpful for scheduling."
0.1253,Event,ADDED,eval-sanitize-30-r1-140.18d4f7dd3481e7d9,reason=Completed count=1 msg=Job completed
0.1256,Event,ADDED,eval-sanitize-30-r1-141-fcnzv.18d4f7d35d06b104,"reason=FailedScheduling count=None msg=0/6 nodes are available: 1 c_wall violated: 1 conflicting context pair(s) with node memory, 5 node(s) had untolerated taint(s). no new claims to deallocate, preemption: 0/6 nodes are available: 1 No preemption victims found for incoming pod, 5 Preemption is not helpful for scheduling."
0.126,Event,ADDED,eval-sanitize-30-r1-142-fbn8g.18d4f7d39900fd50,"reason=FailedScheduling count=None msg=0/6 nodes are available: 1 c_wall violated: 1 conflicting context pair(s) with node memory, 5 node(s) had untolerated taint(s). no new claims to deallocate, preemption: 0/6 nodes are available: 1 No preemption victims found for incoming pod, 5 Preemption is not helpful for scheduling."
0.1262,Event,ADDED,eval-sanitize-30-r1-143-hzk2w.18d4f7d3d86e4bcc,"reason=FailedScheduling count=None msg=0/6 nodes are available: 1 c_wall violated: 1 conflicting context pair(s) with node memory, 5 node(s) had untolerated taint(s). no new claims to deallocate, preemption: 0/6 nodes are available: 1 No preemption victims found for incoming pod, 5 Preemption is not helpful for scheduling."
0.1264,Event,ADDED,eval-sanitize-30-r1-143.18d4f7dd8b9cfee5,reason=Completed count=1 msg=Job completed
0.1269,Event,ADDED,eval-sanitize-30-r1-144-wb4ff.18d4f7d40fb707d1,"reason=FailedScheduling count=None msg=0/6 nodes are available: 1 c_wall violated: 1 conflicting context pair(s) with node memory, 5 node(s) had untolerated taint(s). no new claims to deallocate, preemption: 0/6 nodes are available: 1 No preemption victims found for incoming pod, 5 Preemption is not helpful for scheduling."
0.1271,Event,ADDED,eval-sanitize-30-r1-145-4bdst.18d4f7d44b4bc65d,"reason=FailedScheduling count=None msg=0/6 nodes are available: 1 c_wall violated: 1 conflicting context pair(s) with node memory, 5 node(s) had untolerated taint(s). no new claims to deallocate, preemption: 0/6 nodes are available: 1 No preemption victims found for incoming pod, 5 Preemption is not helpful for scheduling."
0.1273,Event,ADDED,eval-sanitize-30-r1-145.18d4f7dd04d87e27,reason=Completed count=1 msg=Job completed
0.1277,Event,ADDED,eval-sanitize-30-r1-146-zt7cn.18d4f7d49862b30d,"reason=FailedScheduling count=None msg=0/6 nodes are available: 1 c_wall violated: 1 conflicting context pair(s) with node memory, 5 node(s) had untolerated taint(s). no new claims to deallocate, preemption: 0/6 nodes are available: 1 No preemption victims found for incoming pod, 5 Preemption is not helpful for scheduling."
0.1282,Event,ADDED,eval-sanitize-30-r1-146.18d4f7dd20482c0c,reason=Completed count=1 msg=Job completed
0.1285,Event,ADDED,eval-sanitize-30-r1-147-k8846.18d4f7d4ce7f515e,"reason=FailedScheduling count=None msg=0/6 nodes are available: 1 c_wall violated: 1 conflicting context pair(s) with node memory, 5 node(s) had untolerated taint(s). no new claims to deallocate, preemption: 0/6 nodes are available: 1 No preemption victims found for incoming pod, 5 Preemption is not helpful for scheduling."
0.1288,Event,ADDED,eval-sanitize-30-r1-147.18d4f7dd182a43c5,reason=Completed count=1 msg=Job completed
0.1294,Event,ADDED,eval-sanitize-30-r1-149-6rvq5.18d4f7d540597d62,"reason=FailedScheduling count=None msg=0/6 nodes are available: 1 c_wall violated: 1 conflicting context pair(s) with node memory, 5 node(s) had untolerated taint(s). no new claims to deallocate, preemption: 0/6 nodes are available: 1 No preemption victims found for incoming pod, 5 Preemption is not helpful for scheduling."
0.13,Event,ADDED,eval-sanitize-30-r1-149.18d4f7dd850c8c7f,reason=Completed count=1 msg=Job completed
0.1304,Event,ADDED,eval-sanitize-30-r1-151.18d4f7dd99d16e2d,reason=Completed count=1 msg=Job completed
0.1306,Event,ADDED,eval-sanitize-30-r1-153.18d4f7dd9ce05564,reason=Completed count=1 msg=Job completed
0.1311,Event,ADDED,eval-sanitize-30-r1-154.18d4f7dd4f69a6af,reason=Completed count=1 msg=Job completed
0.1315,Event,ADDED,eval-sanitize-30-r1-155-snjzp.18d4f7d6c26c759c,"reason=FailedScheduling count=None msg=0/6 nodes are available: 2 c_wall violated: 2 conflicting context pair(s) with node memory, 4 node(s) had untolerated taint(s). no new claims to deallocate, preemption: 0/6 nodes are available: 2 No preemption victims found for incoming pod, 4 Preemption is not helpful for scheduling."
0.1317,Event,ADDED,eval-sanitize-30-r1-155-snjzp.18d4f7d734005b79,"reason=FailedScheduling count=None msg=0/6 nodes are available: 2 c_wall violated: 1 conflicting context pair(s) with node memory, 2 c_wall violated: 2 conflicting context pair(s) with node memory, 2 node(s) had untolerated taint(s). no new claims to deallocate, preemption: 0/6 nodes are available: 2 Preemption is not helpful for scheduling, 4 No preemption victims found for incoming pod."
0.132,Event,ADDED,eval-sanitize-30-r1-155-snjzp.18d4f7d77573345f,"reason=FailedScheduling count=None msg=0/6 nodes are available: 1 c_wall violated: 1 conflicting context pair(s) with node memory, 2 node(s) had untolerated taint(s), 3 c_wall violated: 2 conflicting context pair(s) with node memory. no new claims to deallocate, preemption: 0/6 nodes are available: 2 Preemption is not helpful for scheduling, 4 No preemption victims found for incoming pod."
0.1322,Event,ADDED,eval-sanitize-30-r1-155-snjzp.18d4f7da575492dc,"reason=FailedScheduling count=None msg=0/6 nodes are available: 1 c_wall violated: 3 conflicting context pair(s) with node memory, 2 node(s) had untolerated taint(s), 3 c_wall violated: 2 conflicting context pair(s) with node memory. no new claims to deallocate, preemption: 0/6 nodes are available: 2 Preemption is not helpful for scheduling, 4 No preemption victims found for incoming pod."
0.1327,Event,ADDED,eval-sanitize-30-r1-155-snjzp.18d4f7dd6bb166cc,"reason=FailedScheduling count=None msg=0/6 nodes are available: 1 c_wall violated: 3 conflicting context pair(s) with node memory, 2 c_wall violated: 2 conflicting context pair(s) with node memory, 3 node(s) had untolerated taint(s). no new claims to deallocate, preemption: 0/6 nodes are available: 3 No preemption victims found for incoming pod, 3 Preemption is not helpful for scheduling."
0.1336,Event,ADDED,eval-sanitize-30-r1-155-snjzp.18d4f7dda777d0ec,reason=Scheduled count=None msg=Successfully assigned compute/eval-sanitize-30-r1-155-snjzp to kind-worker3
0.134,Event,ADDED,eval-sanitize-30-r1-155-snjzp.18d4f7ddc32c9231,"reason=Pulled count=1 msg=Container image ""busybox:musl"" already present on machine"
0.1342,Event,ADDED,eval-sanitize-30-r1-155-snjzp.18d4f7ddc4d984f9,reason=Created count=1 msg=Created container: task
0.1345,Event,ADDED,eval-sanitize-30-r1-155-snjzp.18d4f7ddcc62763f,reason=Started count=1 msg=Started container task
0.1348,Event,ADDED,eval-sanitize-30-r1-155.18d4f7e32ea9ab3b,reason=Completed count=1 msg=Job completed
0.135,Event,ADDED,eval-sanitize-30-r1-156-bk9kg.18d4f7d72db34b51,"reason=FailedScheduling count=None msg=0/6 nodes are available: 1 c_wall violated: 2 conflicting context pair(s) with node memory, 1 c_wall violated: 3 conflicting context pair(s) with node memory, 2 c_wall violated: 1 conflicting context pair(s) with node memory, 2 node(s) had untolerated taint(s). no new claims to deallocate, preemption: 0/6 nodes are available: 2 Preemption is not helpful for scheduling, 4 No preemption victims found for incoming pod."
0.1356,Event,ADDED,eval-sanitize-30-r1-156-bk9kg.18d4f7da4cc5926d,"reason=FailedScheduling count=None msg=0/6 nodes are available: 1 c_wall violated: 1 conflicting context pair(s) with node memory, 1 c_wall violated: 3 conflicting context pair(s) with node memory, 2 c_wall violated: 2 conflicting context pair(s) with node memory, 2 node(s) had untolerated taint(s). no new claims to deallocate, preemption: 0/6 nodes are available: 2 Preemption is not helpful for scheduling, 4 No preemption victims found for incoming pod."
0.136,Event,ADDED,eval-sanitize-30-r1-156-bk9kg.18d4f7dacfef2bd3,"reason=FailedScheduling count=None msg=0/6 nodes are available: 1 c_wall violated: 3 conflicting context pair(s) with node memory, 2 node(s) had untolerated taint(s), 3 c_wall violated: 2 conflicting context pair(s) with node memory. no new claims to deallocate, preemption: 0/6 nodes are available: 2 Preemption is not helpful for scheduling, 4 No preemption victims found for incoming pod."
0.1362,Event,ADDED,eval-sanitize-30-r1-156-bk9kg.18d4f7dd71d84828,"reason=FailedScheduling count=None msg=0/6 nodes are available: 2 c_wall violated: 2 conflicting context pair(s) with node memory, 4 node(s) had untolerated taint(s). no new claims to deallocate, preemption: 0/6 nodes are available: 2 No preemption victims found for incoming pod, 4 Preemption is not helpful for scheduling."
0.1379,Node,MODIFIED,kind-worker5,taints=0
0.1382,Event,ADDED,eval-sanitize-30-r1-156-bk9kg.18d4f7dd8ee36b14,"reason=FailedScheduling count=None msg=0/6 nodes are available: 2 c_wall violated: 2 conflicting context pair(s) with node memory, 4 node(s) had untolerated taint(s). no new claims to deallocate, preemption: 0/6 nodes are available: 2 No preemption victims found for incoming pod, 4 Preemption is not helpful for scheduling."
0.1384,Event,ADDED,eval-sanitize-30-r1-156-bk9kg.18d4f7ddb3167d26,reason=Scheduled count=None msg=Successfully assigned compute/eval-sanitize-30-r1-156-bk9kg to kind-worker3
0.1387,Event,ADDED,eval-sanitize-30-r1-156-bk9kg.18d4f7ddd4f38a08,"reason=Pulled count=1 msg=Container image ""busybox:musl"" already present on machine"
0.139,Event,ADDED,eval-sanitize-30-r1-156-bk9kg.18d4f7ddd72c8954,reason=Created count=1 msg=Created container: task
0.1392,Event,ADDED,eval-sanitize-30-r1-156-bk9kg.18d4f7dddba7deba,reason=Started count=1 msg=Started container task
0.1394,Event,ADDED,eval-sanitize-30-r1-156.18d4f7e36c7a87be,reason=Completed count=1 msg=Job completed
0.1395,Event,ADDED,eval-sanitize-30-r1-157.18d4f7ddcf7e0ead,reason=Completed count=1 msg=Job completed
0.1398,Event,ADDED,eval-sanitize-30-r1-158.18d4f7ddeb501459,reason=Completed count=1 msg=Job completed
0.14,Event,ADDED,eval-sanitize-30-r1-159.18d4f7ddff2d2a06,reason=Completed count=1 msg=Job completed
0.1402,Event,ADDED,eval-sanitize-30-r1-160.18d4f7de1d2ea68d,reason=Completed count=1 msg=Job completed
0.1404,Event,ADDED,eval-sanitize-30-r1-161.18d4f7de31c9c7b2,reason=Completed count=1 msg=Job completed
0.1409,Event,ADDED,eval-sanitize-30-r1-162.18d4f7de1114d415,reason=Completed count=1 msg=Job completed
0.1412,Event,ADDED,eval-sanitize-30-r1-163.18d4f7de4e1e7ff0,reason=Completed count=1 msg=Job completed
0.1416,Event,ADDED,eval-sanitize-30-r1-164-w5lgb.18d4f7d8c2d69d9f,"reason=FailedScheduling count=None msg=0/6 nodes are available: 1 c_wall violated: 2 conflicting context pair(s) with node memory, 1 c_wall violated: 3 conflicting context pair(s) with node memory, 2 c_wall violated: 1 conflicting context pair(s) with node memory, 2 node(s) had untolerated taint(s). no new claims to deallocate, preemption: 0/6 nodes are available: 2 Preemption is not helpful for scheduling, 4 No preemption victims found for incoming pod."
0.142,Event,ADDED,eval-sanitize-30-r1-164-w5lgb.18d4f7dac9f52f9a,"reason=FailedScheduling count=None msg=0/6 nodes are available: 1 c_wall violated: 3 conflicting context pair(s) with node memory, 2 node(s) had untolerated taint(s), 3 c_wall violated: 2 conflicting context pair(s) with node memory. no new claims to deallocate, preemption: 0/6 nodes are available: 2 Preemption is not helpful for scheduling, 4 No preemption victims found for incoming pod."
0.1421,Event,ADDED,eval-sanitize-30-r1-164-w5lgb.18d4f7dd71073ecb,"reason=FailedScheduling count=None msg=0/6 nodes are available: 2 c_wall violated: 2 conflicting context pair(s) with node memory, 4 node(s) had untolerated taint(s). no new claims to deallocate, preemption: 0/6 nodes are available: 2 No preemption victims found for incoming pod, 4 Preemption is not helpful for scheduling."
0.1423,Event,ADDED,eval-sanitize-30-r1-164-w5lgb.18d4f7dd8cb482f7,"reason=FailedScheduling count=None msg=0/6 nodes are available: 2 c_wall violated: 2 conflicting context pair(s) with node memory, 4 node(s) had untolerated taint(s). no new claims to deallocate, preemption: 0/6 nodes are available: 2 No preemption victims found for incoming pod, 4 Preemption is not helpful for scheduling."
0.1426,Event,ADDED,eval-sanitize-30-r1-164-w5lgb.18d4f7ddaf8353dd,reason=Scheduled count=None msg=Successfully assigned compute/eval-sanitize-30-r1-164-w5lgb to kind-worker3
0.1428,Event,ADDED,eval-sanitize-30-r1-164-w5lgb.18d4f7ddcc7d915e,"reason=Pulled count=1 msg=Container image ""busybox:musl"" already present on machine"
0.143,Event,ADDED,eval-sanitize-30-r1-164-w5lgb.18d4f7ddceb1a8cf,reason=Created count=1 msg=Created container: task
0.1432,Event,ADDED,eval-sanitize-30-r1-164-w5lgb.18d4f7ddd4e5ad94,reason=Started count=1 msg=Started container task
0.1435,Event,ADDED,eval-sanitize-30-r1-164.18d4f7e3311b736d,reason=Completed count=1 msg=Job completed
0.1437,Event,ADDED,eval-sanitize-30-r1-165-7h78f.18d4f7d8fee46ce9,"reason=FailedScheduling count=None msg=0/6 nodes are available: 1 c_wall violated: 1 conflicting context pair(s) with node memory, 2 node(s) had untolerated taint(s), 3 c_wall violated: 2 conflicting context pair(s) with node memory. no new claims to deallocate, preemption: 0/6 nodes are available: 2 Preemption is not helpful for scheduling, 4 No preemption victims found for incoming pod."
0.1439,Event,ADDED,eval-sanitize-30-r1-165-7h78f.18d4f7da6a943650,"reason=FailedScheduling count=None msg=0/6 nodes are available: 1 c_wall violated: 3 conflicting context pair(s) with node memory, 2 node(s) had untolerated taint(s), 3 c_wall violated: 2 conflicting context pair(s) with node memory. no new claims to deallocate, preemption: 0/6 nodes are available: 2 Preemption is not helpful for scheduling, 4 No preemption victims found for incoming pod."
0.1444,Event,ADDED,eval-sanitize-30-r1-165-7h78f.18d4f7dd82e46367,"reason=FailedScheduling count=None msg=0/6 nodes are available: 1 c_wall violated: 2 conflicting context pair(s) with node memory, 1 c_wall violated: 3 conflicting context pair(s) with node memory, 4 node(s) had untolerated taint(s). no new claims to deallocate, preemption: 0/6 nodes are available: 2 No preemption victims found for incoming pod, 4 Preemption is not helpful for scheduling."
0.1446,Event,ADDED,eval-sanitize-30-r1-165-7h78f.18d4f7dda0b5408d,"reason=FailedScheduling count=None msg=0/6 nodes are available: 1 c_wall violated: 2 conflicting context pair(s) with node memory, 1 c_wall violated: 3 conflicting context pair(s) with node memory, 4 node(s) had untolerated taint(s). no new claims to deallocate, preemption: 0/6 nodes are available: 2 No preemption victims found for incoming pod, 4 Preemption is not helpful for scheduling."
0.1448,Event,ADDED,eval-sanitize-30-r1-165-7h78f.18d4f7ddd74d55fe,reason=Scheduled count=None msg=Successfully assigned compute/eval-sanitize-30-r1-165-7h78f to kind-worker3
0.1451,Event,ADDED,eval-sanitize-30-r1-165-7h78f.18d4f7ddf669308f,"reason=Pulled count=1 msg=Container image ""busybox:musl"" already present on machine"
0.1453,Event,ADDED,eval-sanitize-30-r1-165-7h78f.18d4f7ddf818eb8f,reason=Created count=1 msg=Created container: task
0.1455,Event,ADDED,eval-sanitize-30-r1-165-7h78f.18d4f7ddfc145adc,reason=Started count=1 msg=Started container task
0.1457,Event,ADDED,eval-sanitize-30-r1-165.18d4f7e36e4cfe58,reason=Completed count=1 msg=Job completed
0.146,Event,ADDED,eval-sanitize-30-r1-166-sbjdj.18d4f7d93a12d8b0,"reason=FailedScheduling count=None msg=0/6 nodes are available: 1 c_wall violated: 1 conflicting context pair(s) with node memory, 2 node(s) had untolerated taint(s), 3 c_wall violated: 2 conflicting context pair(s) with node memory. no new claims to deallocate, preemption: 0/6 nodes are available: 2 Preemption is not helpful for scheduling, 4 No preemption victims found for incoming pod."
0.1463,Event,ADDED,eval-sanitize-30-r1-166-sbjdj.18d4f7da75f7629b,"reason=FailedScheduling count=None msg=0/6 nodes are available: 1 c_wall violated: 3 conflicting context pair(s) with node memory, 2 node(s) had untolerated taint(s), 3 c_wall violated: 2 conflicting context pair(s) with node memory. no new claims to deallocate, preemption: 0/6 nodes are available: 2 Preemption is not helpful for scheduling, 4 No preemption victims found for incoming pod."
0.1466,Event,ADDED,eval-sanitize-30-r1-166-sbjdj.18d4f7dd88c42d08,"reason=FailedScheduling count=None msg=0/6 nodes are available: 1 c_wall violated: 2 conflicting context pair(s) with node memory, 1 c_wall violated: 3 conflicting context pair(s) with node memory, 4 node(s) had untolerated taint(s). no new claims to deallocate, preemption: 0/6 nodes are available: 2 No preemption victims found for incoming pod, 4 Preemption is not helpful for scheduling."
0.1468,Event,ADDED,eval-sanitize-30-r1-166-sbjdj.18d4f7dda69cdc49,"reason=FailedScheduling count=None msg=0/6 nodes are available: 1 c_wall violated: 2 conflicting context pair(s) with node memory, 1 c_wall violated: 3 conflicting context pair(s) with node memory, 4 node(s) had untolerated taint(s). no new claims to deallocate, preemption: 0/6 nodes are available: 2 No preemption victims found for incoming pod, 4 Preemption is not helpful for scheduling."
0.1471,Event,ADDED,eval-sanitize-30-r1-166-sbjdj.18d4f7ddeb520d0b,reason=Scheduled count=None msg=Successfully assigned compute/eval-sanitize-30-r1-166-sbjdj to kind-worker3
0.1474,Event,ADDED,eval-sanitize-30-r1-166-sbjdj.18d4f7de055c1858,"reason=Pulled count=1 msg=Container image ""busybox:musl"" already present on machine"
0.1477,Event,ADDED,eval-sanitize-30-r1-166-sbjdj.18d4f7de06d0b74e,reason=Created count=1 msg=Created container: task
0.1479,Event,ADDED,eval-sanitize-30-r1-166-sbjdj.18d4f7de0d228efd,reason=Started count=1 msg=Started container task
0.1481,Event,ADDED,eval-sanitize-30-r1-166.18d4f7e36daba803,reason=Completed count=1 msg=Job completed
0.1484,Event,ADDED,eval-sanitize-30-r1-167.18d4f7df3817a8f2,reason=Completed count=1 msg=Job completed
0.1486,Event,ADDED,eval-sanitize-30-r1-168.18d4f7df6bcb3836,reason=Completed count=1 msg=Job completed
0.1487,Event,ADDED,eval-sanitize-30-r1-169.18d4f7df78d9166e,reason=Completed count=1 msg=Job completed
0.1489,Event,ADDED,eval-sanitize-30-r1-170.18d4f7dff012c64d,reason=Completed count=1 msg=Job completed
0.1492,Event,ADDED,eval-sanitize-30-r1-171-dv9dl.18d4f7dae075b0f1,"reason=FailedScheduling count=None msg=0/6 nodes are available: 1 c_wall violated: 3 conflicting context pair(s) with node memory, 2 node(s) had untolerated taint(s), 3 c_wall violated: 2 conflicting context pair(s) with node memory. no new claims to deallocate, preemption: 0/6 nodes are available: 2 Preemption is not helpful for scheduling, 4 No preemption victims found for incoming pod."
0.1493,Event,ADDED,eval-sanitize-30-r1-171-dv9dl.18d4f7dd7cff7219,"reason=FailedScheduling count=None msg=0/6 nodes are available: 2 c_wall violated: 2 conflicting context pair(s) with node memory, 4 node(s) had untolerated taint(s). no new claims to deallocate, preemption: 0/6 nodes are available: 2 No preemption victims found for incoming pod, 4 Preemption is not helpful for scheduling."
0.1495,Event,ADDED,eval-sanitize-30-r1-171-dv9dl.18d4f7dd9a9bf83c,"reason=FailedScheduling count=None msg=0/6 nodes are available: 2 c_wall violated: 2 conflicting context pair(s) with node memory, 4 node(s) had untolerated taint(s). no new claims to deallocate, preemption: 0/6 nodes are available: 2 No preemption victims found for incoming pod, 4 Preemption is not helpful for scheduling."
0.1498,Event,ADDED,eval-sanitize-30-r1-171-dv9dl.18d4f7ddcc82da5f,reason=Scheduled count=None msg=Successfully assigned compute/eval-sanitize-30-r1-171-dv9dl to kind-worker3
0.15,Event,ADDED,eval-sanitize-30-r1-171-dv9dl.18d4f7ddeb1a3033,"reason=Pulled count=1 msg=Container image ""busybox:musl"" already present on machine"
0.1501,Event,ADDED,eval-sanitize-30-r1-171-dv9dl.18d4f7dded95cd4a,reason=Created count=1 msg=Created container: task
0.1503,Event,ADDED,eval-sanitize-30-r1-171-dv9dl.18d4f7ddf668fa2e,reason=Started count=1 msg=Started container task
0.1507,Event,ADDED,eval-sanitize-30-r1-171.18d4f7e32eaa4c07,reason=Completed count=1 msg=Job completed
0.1509,Event,ADDED,eval-sanitize-30-r1-172.18d4f7e05867ecae,reason=Completed count=1 msg=Job completed
0.1511,Event,ADDED,eval-sanitize-30-r1-173-rr45p.18d4f7dae75b5673,"reason=FailedScheduling count=None msg=0/6 nodes are available: 1 c_wall violated: 3 conflicting context pair(s) with node memory, 2 node(s) had untolerated taint(s), 3 c_wall violated: 2 conflicting context pair(s) with node memory. no new claims to deallocate, preemption: 0/6 nodes are available: 2 Preemption is not helpful for scheduling, 4 No preemption victims found for incoming pod."
0.1513,Event,ADDED,eval-sanitize-30-r1-173-rr45p.18d4f7dd7e6af8d3,"reason=FailedScheduling count=None msg=0/6 nodes are available: 1 c_wall violated: 2 conflicting context pair(s) with node memory, 1 c_wall violated: 3 conflicting context pair(s) with node memory, 4 node(s) had untolerated taint(s). no new claims to deallocate, preemption: 0/6 nodes are available: 2 No preemption victims found for incoming pod, 4 Preemption is not helpful for scheduling."
0.1514,Event,ADDED,eval-sanitize-30-r1-173-rr45p.18d4f7dd9b24220f,"reason=FailedScheduling count=None msg=0/6 nodes are available: 1 c_wall violated: 2 conflicting context pair(s) with node memory, 1 c_wall violated: 3 conflicting context pair(s) with node memory, 4 node(s) had untolerated taint(s). no new claims to deallocate, preemption: 0/6 nodes are available: 2 No preemption victims found for incoming pod, 4 Preemption is not helpful for scheduling."
0.1516,Event,ADDED,eval-sanitize-30-r1-173-rr45p.18d4f7ddd12a4474,reason=Scheduled count=None msg=Successfully assigned compute/eval-sanitize-30-r1-173-rr45p to kind-worker3
0.1518,Event,ADDED,eval-sanitize-30-r1-173-rr45p.18d4f7ddf3ba931f,"reason=Pulled count=1 msg=Container image ""busybox:musl"" already present on machine"
0.152,Event,ADDED,eval-sanitize-30-r1-173-rr45p.18d4f7ddf50a7a28,reason=Created count=1 msg=Created container: task
0.1522,Event,ADDED,eval-sanitize-30-r1-173-rr45p.18d4f7ddf8903e71,reason=Started count=1 msg=Started container task
0.1524,Event,ADDED,eval-sanitize-30-r1-173.18d4f7e3309057be,reason=Completed count=1 msg=Job completed
0.1527,Event,ADDED,eval-sanitize-30-r1-174.18d4f7e0ca60f076,reason=Completed count=1 msg=Job completed
0.153,Event,ADDED,eval-sanitize-30-r1-175-s6wwj.18d4f7db941127ea,"reason=FailedScheduling count=None msg=0/6 nodes are available: 1 c_wall violated: 3 conflicting context pair(s) with node memory, 2 node(s) had untolerated taint(s), 3 c_wall violated: 2 conflicting context pair(s) with node memory. no new claims to deallocate, preemption: 0/6 nodes are available: 2 Preemption is not helpful for scheduling, 4 No preemption victims found for incoming pod."
0.1532,Event,ADDED,eval-sanitize-30-r1-175-s6wwj.18d4f7dd78b1413c,"reason=FailedScheduling count=None msg=0/6 nodes are available: 1 c_wall violated: 2 conflicting context pair(s) with node memory, 1 c_wall violated: 3 conflicting context pair(s) with node memory, 4 node(s) had untolerated taint(s). no new claims to deallocate, preemption: 0/6 nodes are available: 2 No preemption victims found for incoming pod, 4 Preemption is not helpful for scheduling."
0.1535,Event,ADDED,eval-sanitize-30-r1-175-s6wwj.18d4f7dd952b7395,"reason=FailedScheduling count=None msg=0/6 nodes are available: 1 c_wall violated: 2 conflicting context pair(s) with node memory, 1 c_wall violated: 3 conflicting context pair(s) with node memory, 4 node(s) had untolerated taint(s). no new claims to deallocate, preemption: 0/6 nodes are available: 2 No preemption victims found for incoming pod, 4 Preemption is not helpful for scheduling."
0.1538,Event,ADDED,eval-sanitize-30-r1-175-s6wwj.18d4f7ddc5ac812c,reason=Scheduled count=None msg=Successfully assigned compute/eval-sanitize-30-r1-175-s6wwj to kind-worker3
0.154,Event,ADDED,eval-sanitize-30-r1-175-s6wwj.18d4f7dde1a6aa64,"reason=Pulled count=1 msg=Container image ""busybox:musl"" already present on machine"
0.1543,Event,ADDED,eval-sanitize-30-r1-175-s6wwj.18d4f7dde350798a,reason=Created count=1 msg=Created container: task
0.1545,Event,ADDED,eval-sanitize-30-r1-175-s6wwj.18d4f7ddeafa019b,reason=Started count=1 msg=Started container task
0.1546,Event,ADDED,eval-sanitize-30-r1-175.18d4f7e3306029a8,reason=Completed count=1 msg=Job completed
0.1548,Event,ADDED,eval-sanitize-30-r1-176-l76lp.18d4f7dbd61d8dbd,"reason=FailedScheduling count=None msg=0/6 nodes are available: 1 c_wall violated: 3 conflicting context pair(s) with node memory, 2 node(s) had untolerated taint(s), 3 c_wall violated: 2 conflicting context pair(s) with node memory. no new claims to deallocate, preemption: 0/6 nodes are available: 2 Preemption is not helpful for scheduling, 4 No preemption victims found for incoming pod."
0.1551,Event,ADDED,eval-sanitize-30-r1-176-l76lp.18d4f7dd7294fd70,"reason=FailedScheduling count=None msg=0/6 nodes are available: 2 c_wall violated: 2 conflicting context pair(s) with node memory, 4 node(s) had untolerated taint(s). no new claims to deallocate, preemption: 0/6 nodes are available: 2 No preemption victims found for incoming pod, 4 Preemption is not helpful for scheduling."
0.1553,Event,ADDED,eval-sanitize-30-r1-176-l76lp.18d4f7dd8f55ff65,"reason=FailedScheduling count=None msg=0/6 nodes are available: 2 c_wall violated: 2 conflicting context pair(s) with node memory, 4 node(s) had untolerated taint(s). no new claims to deallocate, preemption: 0/6 nodes are available: 2 No preemption victims found for incoming pod, 4 Preemption is not helpful for scheduling."
0.1554,Event,ADDED,eval-sanitize-30-r1-176-l76lp.18d4f7ddb9deef8c,reason=Scheduled count=None msg=Successfully assigned compute/eval-sanitize-30-r1-176-l76lp to kind-worker3
0.1557,Event,ADDED,eval-sanitize-30-r1-176-l76lp.18d4f7ddd6781bb2,"reason=Pulled count=1 msg=Container image ""busybox:musl"" already present on machine"
0.1559,Event,ADDED,eval-sanitize-30-r1-176-l76lp.18d4f7ddd8852dcf,reason=Created count=1 msg=Created container: task
0.156,Event,ADDED,eval-sanitize-30-r1-176-l76lp.18d4f7dddc8b37dd,reason=Started count=1 msg=Started container task
0.1564,Event,ADDED,eval-sanitize-30-r1-176.18d4f7e331643b71,reason=Completed count=1 msg=Job completed
0.1567,Event,ADDED,eval-sanitize-30-r1-177.18d4f7e179a4e726,reason=Completed count=1 msg=Job completed
0.1568,Event,ADDED,eval-sanitize-30-r1-178.18d4f7e1ed4ff8c6,reason=Completed count=1 msg=Job completed
0.157,Event,ADDED,eval-sanitize-30-r1-179-fp4p2.18d4f7dd005ec8e0,"reason=FailedScheduling count=None msg=0/6 nodes are available: 1 c_wall violated: 3 conflicting context pair(s) with node memory, 2 node(s) had untolerated taint(s), 3 c_wall violated: 2 conflicting context pair(s) with node memory. no new claims to deallocate, preemption: 0/6 nodes are available: 2 Preemption is not helpful for scheduling, 4 No preemption victims found for incoming pod."
0.1573,Event,ADDED,eval-sanitize-30-r1-179-fp4p2.18d4f7dd773091a0,"reason=FailedScheduling count=None msg=0/6 nodes are available: 1 c_wall violated: 2 conflicting context pair(s) with node memory, 1 c_wall violated: 3 conflicting context pair(s) with node memory, 4 node(s) had untolerated taint(s). no new claims to deallocate, preemption: 0/6 nodes are available: 2 No preemption victims found for incoming pod, 4 Preemption is not helpful for scheduling."
0.1577,Event,ADDED,eval-sanitize-30-r1-179-fp4p2.18d4f7dd94b0afa6,"reason=FailedScheduling count=None msg=0/6 nodes are available: 1 c_wall violated: 2 conflicting context pair(s) with node memory, 1 c_wall violated: 3 conflicting context pair(s) with node memory, 4 node(s) had untolerated taint(s). no new claims to deallocate, preemption: 0/6 nodes are available: 2 No preemption victims found for incoming pod, 4 Preemption is not helpful for scheduling."
0.1581,Event,ADDED,eval-sanitize-30-r1-179-fp4p2.18d4f7ddbfa2f7cd,reason=Scheduled count=None msg=Successfully assigned compute/eval-sanitize-30-r1-179-fp4p2 to kind-worker3
0.1586,Event,ADDED,eval-sanitize-30-r1-179-fp4p2.18d4f7dddccf8af7,"reason=Pulled count=1 msg=Container image ""busybox:musl"" already present on machine"
0.1589,Event,ADDED,eval-sanitize-30-r1-179-fp4p2.18d4f7ddde896f9a,reason=Created count=1 msg=Created container: task
0.1594,Event,ADDED,eval-sanitize-30-r1-179-fp4p2.18d4f7dde1933618,reason=Started count=1 msg=Started container task
0.1599,Event,ADDED,eval-sanitize-30-r1-179.18d4f7dcab81519f,reason=SuccessfulCreate count=1 msg=Created pod: eval-sanitize-30-r1-179-fp4p2
0.1603,Event,ADDED,eval-sanitize-30-r1-179.18d4f7e32ea98005,reason=Completed count=1 msg=Job completed
0.1605,Event,ADDED,eval-sanitize-30-r1-180-hbgzd.18d4f7dcd68ce05b,reason=Scheduled count=None msg=Successfully assigned compute/eval-sanitize-30-r1-180-hbgzd to kind-worker4
0.1607,Event,ADDED,eval-sanitize-30-r1-180-hbgzd.18d4f7dcf7d60979,"reason=Pulled count=1 msg=Container image ""busybox:musl"" already present on machine"
0.1611,Event,ADDED,eval-sanitize-30-r1-180-hbgzd.18d4f7dcf972ac0c,reason=Created count=1 msg=Created container: task
0.1616,Event,ADDED,eval-sanitize-30-r1-180-hbgzd.18d4f7dd006232d5,reason=Started count=1 msg=Started container task
0.1618,Event,ADDED,eval-sanitize-30-r1-180.18d4f7dccfcd4859,reason=SuccessfulCreate count=1 msg=Created pod: eval-sanitize-30-r1-180-hbgzd
0.162,Event,ADDED,eval-sanitize-30-r1-180.18d4f7e268db3281,reason=Completed count=1 msg=Job completed
0.1623,Event,ADDED,eval-sanitize-30-r1-181-t4crs.18d4f7dd201e6a4e,reason=Scheduled count=None msg=Successfully assigned compute/eval-sanitize-30-r1-181-t4crs to kind-worker4
0.1625,Event,ADDED,eval-sanitize-30-r1-181-t4crs.18d4f7dd3ad796fa,"reason=Pulled count=1 msg=Container image ""busybox:musl"" already present on machine"
0.1627,Event,ADDED,eval-sanitize-30-r1-181-t4crs.18d4f7dd3ce5b602,reason=Created count=1 msg=Created container: task
0.1628,Event,ADDED,eval-sanitize-30-r1-181-t4crs.18d4f7dd4200b552,reason=Started count=1 msg=Started container task
0.1632,Event,ADDED,eval-sanitize-30-r1-181.18d4f7dd17f15a33,reason=SuccessfulCreate count=1 msg=Created pod: eval-sanitize-30-r1-181-t4crs
0.1634,Event,ADDED,eval-sanitize-30-r1-181.18d4f7e2a4ceeb2e,reason=Completed count=1 msg=Job completed
0.1635,Event,ADDED,eval-sanitize-30-r1-182-9nxd4.18d4f7dd4df59c59,reason=Scheduled count=None msg=Successfully assigned compute/eval-sanitize-30-r1-182-9nxd4 to kind-worker5
0.164,Event,ADDED,eval-sanitize-30-r1-182-9nxd4.18d4f7dd6860de8d,"reason=Pulled count=1 msg=Container image ""busybox:musl"" already present on machine"
0.1643,Event,ADDED,eval-sanitize-30-r1-182-9nxd4.18d4f7dd69d2316a,reason=Created count=1 msg=Created container: task
0.1646,Event,ADDED,eval-sanitize-30-r1-182-9nxd4.18d4f7dd6ef4c690,reason=Started count=1 msg=Started container task
0.1649,Event,ADDED,eval-sanitize-30-r1-182.18d4f7dd437e9d62,reason=SuccessfulCreate count=1 msg=Created pod: eval-sanitize-30-r1-182-9nxd4
0.1652,Event,ADDED,eval-sanitize-30-r1-182.18d4f7e2f7ea7ed2,reason=Completed count=1 msg=Job completed
0.1655,Event,ADDED,eval-sanitize-30-r1-183-fflr6.18d4f7dd83b929a0,"reason=FailedScheduling count=None msg=0/6 nodes are available: 1 c_wall violated: 2 conflicting context pair(s) with node memory, 1 c_wall violated: 3 conflicting context pair(s) with node memory, 4 node(s) had untolerated taint(s). no new claims to deallocate, preemption: 0/6 nodes are available: 2 No preemption victims found for incoming pod, 4 Preemption is not helpful for scheduling."
0.1658,Event,ADDED,eval-sanitize-30-r1-183-fflr6.18d4f7dda141272b,"reason=FailedScheduling count=None msg=0/6 nodes are available: 1 c_wall violated: 2 conflicting context pair(s) with node memory, 1 c_wall violated: 3 conflicting context pair(s) with node memory, 4 node(s) had untolerated taint(s). no new claims to deallocate, preemption: 0/6 nodes are available: 2 No preemption victims found for incoming pod, 4 Preemption is not helpful for scheduling."
0.1662,Event,ADDED,eval-sanitize-30-r1-183-fflr6.18d4f7dde2d68afd,reason=Scheduled count=None msg=Successfully assigned compute/eval-sanitize-30-r1-183-fflr6 to kind-worker3
0.1665,Event,ADDED,eval-sanitize-30-r1-183-fflr6.18d4f7ddfe61c56b,"reason=Pulled count=1 msg=Container image ""busybox:musl"" already present on machine"
0.1667,Event,ADDED,eval-sanitize-30-r1-183-fflr6.18d4f7ddffebaec9,reason=Created count=1 msg=Created container: task
0.1669,Event,ADDED,eval-sanitize-30-r1-183-fflr6.18d4f7de03b888a3,reason=Started count=1 msg=Started container task
0.1672,Event,ADDED,eval-sanitize-30-r1-183.18d4f7dd7f06a867,reason=SuccessfulCreate count=1 msg=Created pod: eval-sanitize-30-r1-183-fflr6
0.1674,Event,ADDED,eval-sanitize-30-r1-183.18d4f7e36d73b4b1,reason=Completed count=1 msg=Job completed
0.1676,Event,ADDED,eval-sanitize-30-r1-184-44lrx.18d4f7ddb79a4b4b,"reason=FailedScheduling count=None msg=0/6 nodes are available: 1 c_wall violated: 1 conflicting context pair(s) with node memory, 2 c_wall violated: 2 conflicting context pair(s) with node memory, 3 node(s) had untolerated taint(s). no new claims to deallocate, preemption: 0/6 nodes are available: 3 No preemption victims found for incoming pod, 3 Preemption is not helpful for scheduling."
0.168,Event,ADDED,eval-sanitize-30-r1-184-44lrx.18d4f7dde91d5356,"reason=FailedScheduling count=None msg=0/6 nodes are available: 1 c_wall violated: 1 conflicting context pair(s) with node memory, 2 c_wall violated: 2 conflicting context pair(s) with node memory, 3 node(s) had untolerated taint(s). no new claims to deallocate, preemption: 0/6 nodes are available: 3 No preemption victims found for incoming pod, 3 Preemption is not helpful for scheduling."
0.1682,Event,ADDED,eval-sanitize-30-r1-184-44lrx.18d4f7ddfa5ae1c5,"reason=FailedScheduling count=None msg=0/6 nodes are available: 1 c_wall violated: 1 conflicting context pair(s) with node memory, 1 c_wall violated: 2 conflicting context pair(s) with node memory, 4 node(s) had untolerated taint(s). no new claims to deallocate, preemption: 0/6 nodes are available: 2 No preemption victims found for incoming pod, 4 Preemption is not helpful for scheduling."
0.1684,Event,ADDED,eval-sanitize-30-r1-184-44lrx.18d4f7de0e2bb016,"reason=FailedScheduling count=None msg=0/6 nodes are available: 1 c_wall violated: 2 conflicting context pair(s) with node memory, 5 node(s) had untolerated taint(s). no new claims to deallocate, preemption: 0/6 nodes are available: 1 No preemption victims found for incoming pod, 5 Preemption is not helpful for scheduling."
0.1686,Event,ADDED,eval-sanitize-30-r1-184-44lrx.18d4f7e46843fa95,reason=Scheduled count=None msg=Successfully assigned compute/eval-sanitize-30-r1-184-44lrx to kind-worker
0.1688,Event,ADDED,eval-sanitize-30-r1-184-44lrx.18d4f7e4846020fd,"reason=Pulled count=1 msg=Container image ""busybox:musl"" already present on machine"
0.1689,Event,ADDED,eval-sanitize-30-r1-184-44lrx.18d4f7e485ec4c7a,reason=Created count=1 msg=Created container: task
0.1691,Event,ADDED,eval-sanitize-30-r1-184-44lrx.18d4f7e48aba4985,reason=Started count=1 msg=Started container task
0.1693,Event,ADDED,eval-sanitize-30-r1-184.18d4f7ddaf5c5d39,reason=SuccessfulCreate count=1 msg=Created pod: eval-sanitize-30-r1-184-44lrx
0.1695,Event,ADDED,eval-sanitize-30-r1-184.18d4f7ea221f8296,reason=Completed count=1 msg=Job completed
0.1698,Event,ADDED,eval-sanitize-30-r1-185-dpzck.18d4f7dddd246aa3,reason=Scheduled count=None msg=Successfully assigned compute/eval-sanitize-30-r1-185-dpzck to kind-worker3
0.1703,Event,ADDED,eval-sanitize-30-r1-185-dpzck.18d4f7ddf802abda,"reason=Pulled count=1 msg=Container image ""busybox:musl"" already present on machine"
0.1707,Event,ADDED,eval-sanitize-30-r1-185-dpzck.18d4f7ddf9ae87dc,reason=Created count=1 msg=Created container: task
0.171,Event,ADDED,eval-sanitize-30-r1-185-dpzck.18d4f7ddfd0a729c,reason=Started count=1 msg=Started container task
0.1713,Event,ADDED,eval-sanitize-30-r1-185.18d4f7ddd2c0087d,reason=SuccessfulCreate count=1 msg=Created pod: eval-sanitize-30-r1-185-dpzck
0.1717,Event,ADDED,eval-sanitize-30-r1-185.18d4f7e3a8640ade,reason=Completed count=1 msg=Job completed
0.172,Event,ADDED,eval-sanitize-30-r1-186-fwphb.18d4f7ddf54a0859,"reason=FailedScheduling count=None msg=0/6 nodes are available: 1 c_wall violated: 1 conflicting context pair(s) with node memory, 1 c_wall violated: 3 conflicting context pair(s) with node memory, 4 node(s) had untolerated taint(s). no new claims to deallocate, preemption: 0/6 nodes are available: 2 No preemption victims found for incoming pod, 4 Preemption is not helpful for scheduling."
0.1723,Event,ADDED,eval-sanitize-30-r1-186-fwphb.18d4f7ddfae74d53,"reason=FailedScheduling count=None msg=0/6 nodes are available: 1 c_wall violated: 1 conflicting context pair(s) with node memory, 1 c_wall violated: 3 conflicting context pair(s) with node memory, 4 node(s) had untolerated taint(s). no new claims to deallocate, preemption: 0/6 nodes are available: 2 No preemption victims found for incoming pod, 4 Preemption is not helpful for scheduling."
0.173,Event,ADDED,eval-sanitize-30-r1-186-fwphb.18d4f7de0e6cefc7,"reason=FailedScheduling count=None msg=0/6 nodes are available: 1 c_wall violated: 1 conflicting context pair(s) with node memory, 5 node(s) had untolerated taint(s). no new claims to deallocate, preemption: 0/6 nodes are available: 1 No preemption victims found for incoming pod, 5 Preemption is not helpful for scheduling."
0.1731,Event,ADDED,eval-sanitize-30-r1-186-fwphb.18d4f7e472585017,"reason=FailedScheduling count=None msg=0/6 nodes are available: 1 c_wall violated: 1 conflicting context pair(s) with node memory, 1 c_wall violated: 3 conflicting context pair(s) with node memory, 4 node(s) had untolerated taint(s). no new claims to deallocate, preemption: 0/6 nodes are available: 2 No preemption victims found for incoming pod, 4 Preemption is not helpful for scheduling."
0.1733,Event,ADDED,eval-sanitize-30-r1-186-fwphb.18d4f7e47ede200b,"reason=FailedScheduling count=None msg=0/6 nodes are available: 1 c_wall violated: 1 conflicting context pair(s) with node memory, 1 c_wall violated: 3 conflicting context pair(s) with node memory, 4 node(s) had untolerated taint(s). no new claims to deallocate, preemption: 0/6 nodes are available: 2 No preemption victims found for incoming pod, 4 Preemption is not helpful for scheduling."
0.1738,Event,ADDED,eval-sanitize-30-r1-186-fwphb.18d4f7e49d31c196,"reason=FailedScheduling count=None msg=0/6 nodes are available: 1 c_wall violated: 3 conflicting context pair(s) with node memory, 2 c_wall violated: 1 conflicting context pair(s) with node memory, 3 node(s) had untolerated taint(s). no new claims to deallocate, preemption: 0/6 nodes are available: 3 No preemption victims found for incoming pod, 3 Preemption is not helpful for scheduling."
0.174,Event,ADDED,eval-sanitize-30-r1-186-fwphb.18d4f7e4b3ae0935,"reason=FailedScheduling count=None msg=0/6 nodes are available: 1 c_wall violated: 1 conflicting context pair(s) with node memory, 1 c_wall violated: 3 conflicting context pair(s) with node memory, 4 node(s) had untolerated taint(s). no new claims to deallocate, preemption: 0/6 nodes are available: 2 No preemption victims found for incoming pod, 4 Preemption is not helpful for scheduling."
0.1741,Event,ADDED,eval-sanitize-30-r1-186-fwphb.18d4f7e515089345,reason=Scheduled count=None msg=Successfully assigned compute/eval-sanitize-30-r1-186-fwphb to kind-worker5
0.1745,Event,ADDED,eval-sanitize-30-r1-186-fwphb.18d4f7e53175453c,"reason=Pulled count=1 msg=Container image ""busybox:musl"" already present on machine"
0.1746,Event,ADDED,eval-sanitize-30-r1-186-fwphb.18d4f7e532e8f87d,reason=Created count=1 msg=Created container: task
0.1748,Event,ADDED,eval-sanitize-30-r1-186-fwphb.18d4f7e539696d6f,reason=Started count=1 msg=Started container task
0.1751,Event,ADDED,eval-sanitize-30-r1-186.18d4f7ddf065ff51,reason=SuccessfulCreate count=1 msg=Created pod: eval-sanitize-30-r1-186-fwphb
0.1753,Event,ADDED,eval-sanitize-30-r1-186.18d4f7eaaad88f6f,reason=Completed count=1 msg=Job completed
0.1757,Event,ADDED,eval-sanitize-30-r1-187-7gwbz.18d4f7de2845c78e,reason=Scheduled count=None msg=Successfully assigned compute/eval-sanitize-30-r1-187-7gwbz to kind-worker3
0.1759,Event,ADDED,eval-sanitize-30-r1-187-7gwbz.18d4f7de5eb914d7,"reason=Pulled count=1 msg=Container image ""busybox:musl"" already present on machine"
0.1764,Event,ADDED,eval-sanitize-30-r1-187-7gwbz.18d4f7de606e865d,reason=Created count=1 msg=Created container: task
0.1766,Event,ADDED,eval-sanitize-30-r1-187-7gwbz.18d4f7de68fd63fa,reason=Started count=1 msg=Started container task
0.1768,Event,ADDED,eval-sanitize-30-r1-187.18d4f7de2798e883,reason=SuccessfulCreate count=1 msg=Created pod: eval-sanitize-30-r1-187-7gwbz
0.177,Event,ADDED,eval-sanitize-30-r1-187.18d4f7e3e562ed73,reason=Completed count=1 msg=Job completed
0.1773,Event,ADDED,eval-sanitize-30-r1-188-tmz9x.18d4f7de5f047d6f,"reason=FailedScheduling count=None msg=0/6 nodes are available: 1 c_wall violated: 1 conflicting context pair(s) with node memory, 5 node(s) had untolerated taint(s). no new claims to deallocate, preemption: 0/6 nodes are available: 1 No preemption victims found for incoming pod, 5 Preemption is not helpful for scheduling."
0.1775,Event,ADDED,eval-sanitize-30-r1-188-tmz9x.18d4f7de5fb707c2,"reason=FailedScheduling count=None msg=0/6 nodes are available: 1 c_wall violated: 1 conflicting context pair(s) with node memory, 5 node(s) had untolerated taint(s). no new claims to deallocate, preemption: 0/6 nodes are available: 1 No preemption victims found for incoming pod, 5 Preemption is not helpful for scheduling."
0.1776,Event,ADDED,eval-sanitize-30-r1-188-tmz9x.18d4f7e45ca4f8e3,reason=Scheduled count=None msg=Successfully assigned compute/eval-sanitize-30-r1-188-tmz9x to kind-worker
0.1779,Event,ADDED,eval-sanitize-30-r1-188-tmz9x.18d4f7e4787f64a0,"reason=Pulled count=1 msg=Container image ""busybox:musl"" already present on machine"
0.1781,Event,ADDED,eval-sanitize-30-r1-188-tmz9x.18d4f7e47a2f525c,reason=Created count=1 msg=Created container: task
0.1783,Event,ADDED,eval-sanitize-30-r1-188-tmz9x.18d4f7e47ebf91c5,reason=Started count=1 msg=Started container task
0.1784,Event,ADDED,eval-sanitize-30-r1-188.18d4f7de5eb7aa14,reason=SuccessfulCreate count=1 msg=Created pod: eval-sanitize-30-r1-188-tmz9x
0.1787,Event,ADDED,eval-sanitize-30-r1-188.18d4f7e9a7bfed99,reason=Completed count=1 msg=Job completed
0.1788,Event,ADDED,eval-sanitize-30-r1-189-lhpdw.18d4f7de88472bb8,"reason=FailedScheduling count=None msg=0/6 nodes are available: 1 c_wall violated: 1 conflicting context pair(s) with node memory, 5 node(s) had untolerated taint(s). no new claims to deallocate, preemption: 0/6 nodes are available: 1 No preemption victims found for incoming pod, 5 Preemption is not helpful for scheduling."
0.179,Event,ADDED,eval-sanitize-30-r1-189-lhpdw.18d4f7de8a3ca0ef,"reason=FailedScheduling count=None msg=0/6 nodes are available: 1 c_wall violated: 1 conflicting context pair(s) with node memory, 5 node(s) had untolerated taint(s). no new claims to deallocate, preemption: 0/6 nodes are available: 1 No preemption victims found for incoming pod, 5 Preemption is not helpful for scheduling."
0.1792,Event,ADDED,eval-sanitize-30-r1-189-lhpdw.18d4f7e473946ddc,"reason=FailedScheduling count=None msg=0/6 nodes are available: 1 c_wall violated: 1 conflicting context pair(s) with node memory, 1 c_wall violated: 3 conflicting context pair(s) with node memory, 4 node(s) had untolerated taint(s). no new claims to deallocate, preemption: 0/6 nodes are available: 2 No preemption victims found for incoming pod, 4 Preemption is not helpful for scheduling."
0.1794,Event,ADDED,eval-sanitize-30-r1-189-lhpdw.18d4f7e47f6e2a40,"reason=FailedScheduling count=None msg=0/6 nodes are available: 1 c_wall violated: 1 conflicting context pair(s) with node memory, 1 c_wall violated: 3 conflicting context pair(s) with node memory, 4 node(s) had untolerated taint(s). no new claims to deallocate, preemption: 0/6 nodes are available: 2 No preemption victims found for incoming pod, 4 Preemption is not helpful for scheduling."
0.1796,Event,ADDED,eval-sanitize-30-r1-189-lhpdw.18d4f7e4a3081936,"reason=FailedScheduling count=None msg=0/6 nodes are available: 1 c_wall violated: 3 conflicting context pair(s) with node memory, 2 c_wall violated: 1 conflicting context pair(s) with node memory, 3 node(s) had untolerated taint(s). no new claims to deallocate, preemption: 0/6 nodes are available: 3 No preemption victims found for incoming pod, 3 Preemption is not helpful for scheduling."
0.1798,Event,ADDED,eval-sanitize-30-r1-189-lhpdw.18d4f7e4b49bb45d,"reason=FailedScheduling count=None msg=0/6 nodes are available: 1 c_wall violated: 1 conflicting context pair(s) with node memory, 1 c_wall violated: 3 conflicting context pair(s) with node memory, 4 node(s) had untolerated taint(s). no new claims to deallocate, preemption: 0/6 nodes are available: 2 No preemption victims found for incoming pod, 4 Preemption is not helpful for scheduling."
0.18,Event,ADDED,eval-sanitize-30-r1-189-lhpdw.18d4f7e508dc83fa,reason=Scheduled count=None msg=Successfully assigned compute/eval-sanitize-30-r1-189-lhpdw to kind-worker5
0.1803,Event,ADDED,eval-sanitize-30-r1-189-lhpdw.18d4f7e5245ee4c7,"reason=Pulled count=1 msg=Container image ""busybox:musl"" already present on machine"
0.1805,Event,ADDED,eval-sanitize-30-r1-189-lhpdw.18d4f7e52624635a,reason=Created count=1 msg=Created container: task
0.1807,Event,ADDED,eval-sanitize-30-r1-189-lhpdw.18d4f7e52b5486b8,reason=Started count=1 msg=Started container task
0.1809,Event,ADDED,eval-sanitize-30-r1-189.18d4f7de87f9ac2d,reason=SuccessfulCreate count=1 msg=Created pod: eval-sanitize-30-r1-189-lhpdw
0.181,Event,ADDED,eval-sanitize-30-r1-189.18d4f7eaab21dde6,reason=Completed count=1 msg=Job completed
0.1812,Event,ADDED,eval-sanitize-30-r1-190-hcs5z.18d4f7dec49ff9e3,"reason=FailedScheduling count=None msg=0/6 nodes are available: 1 c_wall violated: 1 conflicting context pair(s) with node memory, 5 node(s) had untolerated taint(s). no new claims to deallocate, preemption: 0/6 nodes are available: 1 No preemption victims found for incoming pod, 5 Preemption is not helpful for scheduling."
0.1815,Event,ADDED,eval-sanitize-30-r1-190-hcs5z.18d4f7dec556200c,"reason=FailedScheduling count=None msg=0/6 nodes are available: 1 c_wall violated: 1 conflicting context pair(s) with node memory, 5 node(s) had untolerated taint(s). no new claims to deallocate, preemption: 0/6 nodes are available: 1 No preemption victims found for incoming pod, 5 Preemption is not helpful for scheduling."
0.1819,Event,ADDED,eval-sanitize-30-r1-190-hcs5z.18d4f7e478f04a0d,"reason=FailedScheduling count=None msg=0/6 nodes are available: 1 c_wall violated: 1 conflicting context pair(s) with node memory, 1 c_wall violated: 3 conflicting context pair(s) with node memory, 4 node(s) had untolerated taint(s). no new claims to deallocate, preemption: 0/6 nodes are available: 2 No preemption victims found for incoming pod, 4 Preemption is not helpful for scheduling."
0.1822,Event,ADDED,eval-sanitize-30-r1-190-hcs5z.18d4f7e48425951e,"reason=FailedScheduling count=None msg=0/6 nodes are available: 1 c_wall violated: 1 conflicting context pair(s) with node memory, 1 c_wall violated: 3 conflicting context pair(s) with node memory, 4 node(s) had untolerated taint(s). no new claims to deallocate, preemption: 0/6 nodes are available: 2 No preemption victims found for incoming pod, 4 Preemption is not helpful for scheduling."
0.1824,Event,ADDED,eval-sanitize-30-r1-190-hcs5z.18d4f7e4a7f54405,"reason=FailedScheduling count=None msg=0/6 nodes are available: 1 c_wall violated: 1 conflicting context pair(s) with node memory, 1 c_wall violated: 3 conflicting context pair(s) with node memory, 4 node(s) had untolerated taint(s). no new claims to deallocate, preemption: 0/6 nodes are available: 2 No preemption victims found for incoming pod, 4 Preemption is not helpful for scheduling."
0.1827,Event,ADDED,eval-sanitize-30-r1-190-hcs5z.18d4f7e4aef7047b,"reason=FailedScheduling count=None msg=0/6 nodes are available: 1 c_wall violated: 1 conflicting context pair(s) with node memory, 1 c_wall violated: 3 conflicting context pair(s) with node memory, 4 node(s) had untolerated taint(s). no new claims to deallocate, preemption: 0/6 nodes are available: 2 No preemption victims found for incoming pod, 4 Preemption is not helpful for scheduling."
0.1829,Event,ADDED,eval-sanitize-30-r1-190-hcs5z.18d4f7e5104ef137,reason=Scheduled count=None msg=Successfully assigned compute/eval-sanitize-30-r1-190-hcs5z to kind-worker5
0.1831,Event,ADDED,eval-sanitize-30-r1-190-hcs5z.18d4f7e52c36dd1d,"reason=Pulled count=1 msg=Container image ""busybox:musl"" already present on machine"
0.1832,Event,ADDED,eval-sanitize-30-r1-190-hcs5z.18d4f7e52d8179a6,reason=Created count=1 msg=Created container: task
0.1835,Event,ADDED,eval-sanitize-30-r1-190-hcs5z.18d4f7e531a20c3f,reason=Started count=1 msg=Started container task
0.1837,Event,ADDED,eval-sanitize-30-r1-190.18d4f7dec3ead37e,reason=SuccessfulCreate count=1 msg=Created pod: eval-sanitize-30-r1-190-hcs5z
0.1838,Event,ADDED,eval-sanitize-30-r1-190.18d4f7eaab4e2556,reason=Completed count=1 msg=Job completed
0.1841,Event,ADDED,eval-sanitize-30-r1-191-p5dz6.18d4f7df008079ae,"reason=FailedScheduling count=None msg=0/6 nodes are available: 1 c_wall violated: 2 conflicting context pair(s) with node memory, 5 node(s) had untolerated taint(s). no new claims to deallocate, preemption: 0/6 nodes are available: 1 No preemption victims found for incoming pod, 5 Preemption is not helpful for scheduling."
0.1843,Event,ADDED,eval-sanitize-30-r1-191-p5dz6.18d4f7df01385c10,"reason=FailedScheduling count=None msg=0/6 nodes are available: 1 c_wall violated: 2 conflicting context pair(s) with node memory, 5 node(s) had untolerated taint(s). no new claims to deallocate, preemption: 0/6 nodes are available: 1 No preemption victims found for incoming pod, 5 Preemption is not helpful for scheduling."
0.1845,Event,ADDED,eval-sanitize-30-r1-191-p5dz6.18d4f7e46ca2256a,reason=Scheduled count=None msg=Successfully assigned compute/eval-sanitize-30-r1-191-p5dz6 to kind-worker
0.1848,Event,ADDED,eval-sanitize-30-r1-191-p5dz6.18d4f7e48b9648e0,"reason=Pulled count=1 msg=Container image ""busybox:musl"" already present on machine"
0.1849,Event,ADDED,eval-sanitize-30-r1-191-p5dz6.18d4f7e48d0c5585,reason=Created count=1 msg=Created container: task
0.1851,Event,ADDED,eval-sanitize-30-r1-191-p5dz6.18d4f7e49586eb55,reason=Started count=1 msg=Started container task
0.1853,Event,ADDED,eval-sanitize-30-r1-191.18d4f7deff7a8493,reason=SuccessfulCreate count=1 msg=Created pod: eval-sanitize-30-r1-191-p5dz6
0.1855,Event,ADDED,eval-sanitize-30-r1-191.18d4f7ea222246f7,reason=Completed count=1 msg=Job completed
0.1857,Event,ADDED,eval-sanitize-30-r1-192-2d6r4.18d4f7df4b58a4b1,reason=Scheduled count=None msg=Successfully assigned compute/eval-sanitize-30-r1-192-2d6r4 to kind-worker3
0.1859,Event,ADDED,eval-sanitize-30-r1-192-2d6r4.18d4f7df6b280a38,"reason=Pulled count=1 msg=Container image ""busybox:musl"" already present on machine"
0.186,Event,ADDED,eval-sanitize-30-r1-192-2d6r4.18d4f7df6d35ecd6,reason=Created count=1 msg=Created container: task
0.1862,Event,ADDED,eval-sanitize-30-r1-192-2d6r4.18d4f7df77600827,reason=Started count=1 msg=Started container task
0.1864,Event,ADDED,eval-sanitize-30-r1-192.18d4f7df3ab9de02,reason=SuccessfulCreate count=1 msg=Created pod: eval-sanitize-30-r1-192-2d6r4
0.1866,Event,ADDED,eval-sanitize-30-r1-192.18d4f7e50add81ed,reason=Completed count=1 msg=Job completed
0.1868,Event,ADDED,eval-sanitize-30-r1-193-4rrcg.18d4f7df7a7a30d6,"reason=FailedScheduling count=None msg=0/6 nodes are available: 1 c_wall violated: 2 conflicting context pair(s) with node memory, 5 node(s) had untolerated taint(s). no new claims to deallocate, preemption: 0/6 nodes are available: 1 No preemption victims found for incoming pod, 5 Preemption is not helpful for scheduling."
0.187,Event,ADDED,eval-sanitize-30-r1-193-4rrcg.18d4f7df7b19f249,"reason=FailedScheduling count=None msg=0/6 nodes are available: 1 c_wall violated: 2 conflicting context pair(s) with node memory, 5 node(s) had untolerated taint(s). no new claims to deallocate, preemption: 0/6 nodes are available: 1 No preemption victims found for incoming pod, 5 Preemption is not helpful for scheduling."
0.1873,Event,ADDED,eval-sanitize-30-r1-193-4rrcg.18d4f7e479e65a04,"reason=FailedScheduling count=None msg=0/6 nodes are available: 2 c_wall violated: 2 conflicting context pair(s) with node memory, 4 node(s) had untolerated taint(s). no new claims to deallocate, preemption: 0/6 nodes are available: 2 No preemption victims found for incoming pod, 4 Preemption is not helpful for scheduling."
0.1876,Event,ADDED,eval-sanitize-30-r1-193-4rrcg.18d4f7e485c02b9b,reason=Scheduled count=None msg=Successfully assigned compute/eval-sanitize-30-r1-193-4rrcg to kind-worker4
0.1878,Event,ADDED,eval-sanitize-30-r1-193-4rrcg.18d4f7e4a46f6496,"reason=Pulled count=1 msg=Container image ""busybox:musl"" already present on machine"
0.188,Event,ADDED,eval-sanitize-30-r1-193-4rrcg.18d4f7e4a634148f,reason=Created count=1 msg=Created container: task
0.1881,Event,ADDED,eval-sanitize-30-r1-193-4rrcg.18d4f7e4abc6fc0e,reason=Started count=1 msg=Started container task
0.1885,Event,ADDED,eval-sanitize-30-r1-193.18d4f7df7a2e84c4,reason=SuccessfulCreate count=1 msg=Created pod: eval-sanitize-30-r1-193-4rrcg
0.1887,Event,ADDED,eval-sanitize-30-r1-193.18d4f7ea22862ede,reason=Completed count=1 msg=Job completed
0.1888,Event,ADDED,eval-sanitize-30-r1-194-d4zc7.18d4f7dfb2547261,"reason=FailedScheduling count=None msg=0/6 nodes are available: 1 c_wall violated: 1 conflicting context pair(s) with node memory, 5 node(s) had untolerated taint(s). no new claims to deallocate, preemption: 0/6 nodes are available: 1 No preemption victims found for incoming pod, 5 Preemption is not helpful for scheduling."
0.1891,Event,ADDED,eval-sanitize-30-r1-194-d4zc7.18d4f7dfb3056ae1,"reason=FailedScheduling count=None msg=0/6 nodes are available: 1 c_wall violated: 1 conflicting context pair(s) with node memory, 5 node(s) had untolerated taint(s). no new claims to deallocate, preemption: 0/6 nodes are available: 1 No preemption victims found for incoming pod, 5 Preemption is not helpful for scheduling."
0.1893,Event,ADDED,eval-sanitize-30-r1-194-d4zc7.18d4f7e461a08e54,reason=Scheduled count=None msg=Successfully assigned compute/eval-sanitize-30-r1-194-d4zc7 to kind-worker
0.1895,Event,ADDED,eval-sanitize-30-r1-194-d4zc7.18d4f7e47aa40dca,"reason=Pulled count=1 msg=Container image ""busybox:musl"" already present on machine"
0.1897,Event,ADDED,eval-sanitize-30-r1-194-d4zc7.18d4f7e47c2476d1,reason=Created count=1 msg=Created container: task
0.19,Event,ADDED,eval-sanitize-30-r1-194-d4zc7.18d4f7e47f4d46e4,reason=Started count=1 msg=Started container task
0.1902,Event,ADDED,eval-sanitize-30-r1-194.18d4f7dfb1f7c8cc,reason=SuccessfulCreate count=1 msg=Created pod: eval-sanitize-30-r1-194-d4zc7
0.1903,Event,ADDED,eval-sanitize-30-r1-194.18d4f7ea2286d9e0,reason=Completed count=1 msg=Job completed
0.1905,Event,ADDED,eval-sanitize-30-r1-195-f889f.18d4f7dfee4f6b41,reason=Scheduled count=None msg=Successfully assigned compute/eval-sanitize-30-r1-195-f889f to kind-worker3
0.1907,Event,ADDED,eval-sanitize-30-r1-195-f889f.18d4f7e0099dd6ef,"reason=Pulled count=1 msg=Container image ""busybox:musl"" already present on machine"
0.1909,Event,ADDED,eval-sanitize-30-r1-195-f889f.18d4f7e00af2d1c3,reason=Created count=1 msg=Created container: task
0.1911,Event,ADDED,eval-sanitize-30-r1-195-f889f.18d4f7e010c9ac1e,reason=Started count=1 msg=Started container task
0.1914,Event,ADDED,eval-sanitize-30-r1-195.18d4f7dfed905fc9,reason=SuccessfulCreate count=1 msg=Created pod: eval-sanitize-30-r1-195-f889f
0.1915,Event,ADDED,eval-sanitize-30-r1-195.18d4f7e585b452ca,reason=Completed count=1 msg=Job completed
0.1917,Event,ADDED,eval-sanitize-30-r1-196-8mgv6.18d4f7e029f046a2,"reason=FailedScheduling count=None msg=0/6 nodes are available: 1 c_wall violated: 2 conflicting context pair(s) with node memory, 5 node(s) had untolerated taint(s). no new claims to deallocate, preemption: 0/6 nodes are available: 1 No preemption victims found for incoming pod, 5 Preemption is not helpful for scheduling."
0.1919,Event,ADDED,eval-sanitize-30-r1-196-8mgv6.18d4f7e02a93296d,"reason=FailedScheduling count=None msg=0/6 nodes are available: 1 c_wall violated: 2 conflicting context pair(s) with node memory, 5 node(s) had untolerated taint(s). no new claims to deallocate, preemption: 0/6 nodes are available: 1 No preemption victims found for incoming pod, 5 Preemption is not helpful for scheduling."
0.1921,Event,ADDED,eval-sanitize-30-r1-196-8mgv6.18d4f7e46daeeaf2,reason=Scheduled count=None msg=Successfully assigned compute/eval-sanitize-30-r1-196-8mgv6 to kind-worker
0.1923,Event,ADDED,eval-sanitize-30-r1-196-8mgv6.18d4f7e48a6f8889,"reason=Pulled count=1 msg=Container image ""busybox:musl"" already present on machine"
0.1924,Event,ADDED,eval-sanitize-30-r1-196-8mgv6.18d4f7e48c484e7d,reason=Created count=1 msg=Created container: task
0.1927,Event,ADDED,eval-sanitize-30-r1-196-8mgv6.18d4f7e4985c6e10,reason=Started count=1 msg=Started container task
0.1929,Event,ADDED,eval-sanitize-30-r1-196.18d4f7e0299a1f0c,reason=SuccessfulCreate count=1 msg=Created pod: eval-sanitize-30-r1-196-8mgv6
0.1932,Event,ADDED,eval-sanitize-30-r1-196.18d4f7ea222348c2,reason=Completed count=1 msg=Job completed
0.1934,Event,ADDED,eval-sanitize-30-r1-197-rbs5j.18d4f7e06560e8c7,"reason=FailedScheduling count=None msg=0/6 nodes are available: 1 c_wall violated: 1 conflicting context pair(s) with node memory, 5 node(s) had untolerated taint(s). no new claims to deallocate, preemption: 0/6 nodes are available: 1 No preemption victims found for incoming pod, 5 Preemption is not helpful for scheduling."
0.1938,Event,ADDED,eval-sanitize-30-r1-197-rbs5j.18d4f7e0664dc487,"reason=FailedScheduling count=None msg=0/6 nodes are available: 1 c_wall violated: 1 conflicting context pair(s) with node memory, 5 node(s) had untolerated taint(s). no new claims to deallocate, preemption: 0/6 nodes are available: 1 No preemption victims found for incoming pod, 5 Preemption is not helpful for scheduling."
0.194,Event,ADDED,eval-sanitize-30-r1-197-rbs5j.18d4f7e45510ed76,reason=Scheduled count=None msg=Successfully assigned compute/eval-sanitize-30-r1-197-rbs5j to kind-worker
0.1942,Event,ADDED,eval-sanitize-30-r1-197-rbs5j.18d4f7e470168edc,"reason=Pulled count=1 msg=Container image ""busybox:musl"" already present on machine"
0.1945,Event,ADDED,eval-sanitize-30-r1-197-rbs5j.18d4f7e4725b67bc,reason=Created count=1 msg=Created container: task
0.1947,Event,ADDED,eval-sanitize-30-r1-197-rbs5j.18d4f7e476b718ad,reason=Started count=1 msg=Started container task
0.1949,Event,ADDED,eval-sanitize-30-r1-197.18d4f7e06504e847,reason=SuccessfulCreate count=1 msg=Created pod: eval-sanitize-30-r1-197-rbs5j
0.1951,Event,ADDED,eval-sanitize-30-r1-197.18d4f7e9e3fa6db0,reason=Completed count=1 msg=Job completed
0.1953,Event,ADDED,eval-sanitize-30-r1-198-l9s2l.18d4f7e0a16cd572,"reason=FailedScheduling count=None msg=0/6 nodes are available: 1 c_wall violated: 1 conflicting context pair(s) with node memory, 5 node(s) had untolerated taint(s). no new claims to deallocate, preemption: 0/6 nodes are available: 1 No preemption victims found for incoming pod, 5 Preemption is not helpful for scheduling."
0.1956,Event,ADDED,eval-sanitize-30-r1-198-l9s2l.18d4f7e0a22667a8,"reason=FailedScheduling count=None msg=0/6 nodes are available: 1 c_wall violated: 1 conflicting context pair(s) with node memory, 5 node(s) had untolerated taint(s). no new claims to deallocate, preemption: 0/6 nodes are available: 1 No preemption victims found for incoming pod, 5 Preemption is not helpful for scheduling."
0.1957,Event,ADDED,eval-sanitize-30-r1-198-l9s2l.18d4f7e45684382b,reason=Scheduled count=None msg=Successfully assigned compute/eval-sanitize-30-r1-198-l9s2l to kind-worker
0.1964,Event,ADDED,eval-sanitize-30-r1-198-l9s2l.18d4f7e470fc1e38,"reason=Pulled count=1 msg=Container image ""busybox:musl"" already present on machine"
0.1966,Event,ADDED,eval-sanitize-30-r1-198-l9s2l.18d4f7e473c4548e,reason=Created count=1 msg=Created container: task
0.1968,Event,ADDED,eval-sanitize-30-r1-198-l9s2l.18d4f7e4775eaa1b,reason=Started count=1 msg=Started container task
0.1973,Event,ADDED,eval-sanitize-30-r1-198.18d4f7e0a120464e,reason=SuccessfulCreate count=1 msg=Created pod: eval-sanitize-30-r1-198-l9s2l
0.1977,Event,ADDED,eval-sanitize-30-r1-198.18d4f7e9a7c01ca6,reason=Completed count=1 msg=Job completed
0.1981,Event,ADDED,eval-sanitize-30-r1-199-5fktr.18d4f7e0dcd2f95e,reason=Scheduled count=None msg=Successfully assigned compute/eval-sanitize-30-r1-199-5fktr to kind-worker3
0.1984,Event,ADDED,eval-sanitize-30-r1-199-5fktr.18d4f7e0fb604a84,"reason=Pulled count=1 msg=Container image ""busybox:musl"" already present on machine"
0.1988,Event,ADDED,eval-sanitize-30-r1-199-5fktr.18d4f7e0fcbedaa1,reason=Created count=1 msg=Created container: task
0.1992,Event,ADDED,eval-sanitize-30-r1-199-5fktr.18d4f7e108a3db17,reason=Started count=1 msg=Started container task
0.1996,Event,ADDED,eval-sanitize-30-r1-199.18d4f7e0dc2114c0,reason=SuccessfulCreate count=1 msg=Created pod: eval-sanitize-30-r1-199-5fktr
0.1998,Event,ADDED,eval-sanitize-30-r1-199.18d4f7e66f453b6e,reason=Completed count=1 msg=Job completed
0.2001,Event,ADDED,eval-sanitize-30-r2-000-kthq8.18d4f7f4a30ea566,reason=Scheduled count=None msg=Successfully assigned compute/eval-sanitize-30-r2-000-kthq8 to kind-worker5
0.2003,Event,ADDED,eval-sanitize-30-r2-000-kthq8.18d4f7f4c05ed4c8,"reason=Pulled count=1 msg=Container image ""busybox:musl"" already present on machine"
0.2004,Event,ADDED,eval-sanitize-30-r2-000-kthq8.18d4f7f4c18a37a0,reason=Created count=1 msg=Created container: task
0.2008,Event,ADDED,eval-sanitize-30-r2-000-kthq8.18d4f7f4c7323b51,reason=Started count=1 msg=Started container task
0.201,Event,ADDED,eval-sanitize-30-r2-000.18d4f7f4a223192b,reason=SuccessfulCreate count=1 msg=Created pod: eval-sanitize-30-r2-000-kthq8
0.2012,Event,ADDED,eval-sanitize-30-r2-000.18d4f7fa4c18f75a,reason=Completed count=1 msg=Job completed
0.2013,Event,ADDED,eval-sanitize-30-r2-001-hgwdx.18d4f7f4dca57680,reason=Scheduled count=None msg=Successfully assigned compute/eval-sanitize-30-r2-001-hgwdx to kind-worker
0.2017,Event,ADDED,eval-sanitize-30-r2-001-hgwdx.18d4f7f4fb4c9c66,"reason=Pulled count=1 msg=Container image ""busybox:musl"" already present on machine"
0.2019,Event,ADDED,eval-sanitize-30-r2-001-hgwdx.18d4f7f4fc6c0791,reason=Created count=1 msg=Created container: task
0.2021,Event,ADDED,eval-sanitize-30-r2-001-hgwdx.18d4f7f4ff4f7af2,reason=Started count=1 msg=Started container task
0.2023,Event,ADDED,eval-sanitize-30-r2-001.18d4f7f4db8fa8e4,reason=SuccessfulCreate count=1 msg=Created pod: eval-sanitize-30-r2-001-hgwdx
0.2027,Event,ADDED,eval-sanitize-30-r2-001.18d4f7fa3b60641d,reason=Completed count=1 msg=Job completed
0.2028,Event,ADDED,eval-sanitize-30-r2-002-mx55q.18d4f7f51bdc25d2,reason=Scheduled count=None msg=Successfully assigned compute/eval-sanitize-30-r2-002-mx55q to kind-worker2
0.2031,Event,ADDED,eval-sanitize-30-r2-002-mx55q.18d4f7f538e3940a,"reason=Pulled count=1 msg=Container image ""busybox:musl"" already present on machine"
0.2035,Event,ADDED,eval-sanitize-30-r2-002-mx55q.18d4f7f53a12af5c,reason=Created count=1 msg=Created container: task
0.2036,Event,ADDED,eval-sanitize-30-r2-002-mx55q.18d4f7f53d5b65b5,reason=Started count=1 msg=Started container task
0.2039,Event,ADDED,eval-sanitize-30-r2-002.18d4f7f5170a1f66,reason=SuccessfulCreate count=1 msg=Created pod: eval-sanitize-30-r2-002-mx55q
0.2041,Event,ADDED,eval-sanitize-30-r2-002.18d4f7fab765f3d6,reason=Completed count=1 msg=Job completed
0.2043,Event,ADDED,eval-sanitize-30-r2-003-6khzh.18d4f7f553cfec33,reason=Scheduled count=None msg=Successfully assigned compute/eval-sanitize-30-r2-003-6khzh to kind-worker4
0.2046,Event,ADDED,eval-sanitize-30-r2-003-6khzh.18d4f7f56edd2b53,"reason=Pulled count=1 msg=Container image ""busybox:musl"" already present on machine"
0.2052,Event,ADDED,eval-sanitize-30-r2-003-6khzh.18d4f7f57010e5e4,reason=Created count=1 msg=Created container: task
0.2057,Event,ADDED,eval-sanitize-30-r2-003-6khzh.18d4f7f5725934b0,reason=Started count=1 msg=Started container task
0.2061,Event,ADDED,eval-sanitize-30-r2-003.18d4f7f55274aaee,reason=SuccessfulCreate count=1 msg=Created pod: eval-sanitize-30-r2-003-6khzh
0.2064,Event,ADDED,eval-sanitize-30-r2-003.18d4f7faf8899099,reason=Completed count=1 msg=Job completed
0.2066,Event,ADDED,eval-sanitize-30-r2-004-qg5fn.18d4f7f590063870,reason=Scheduled count=None msg=Successfully assigned compute/eval-sanitize-30-r2-004-qg5fn to kind-worker5
0.2071,Event,ADDED,eval-sanitize-30-r2-004-qg5fn.18d4f7f5ac259b55,"reason=Pulled count=1 msg=Container image ""busybox:musl"" already present on machine"
0.2073,Event,ADDED,eval-sanitize-30-r2-004-qg5fn.18d4f7f5ad69ab60,reason=Created count=1 msg=Created container: task
0.2075,Event,ADDED,eval-sanitize-30-r2-004-qg5fn.18d4f7f5b28290db,reason=Started count=1 msg=Started container task
0.2077,Event,ADDED,eval-sanitize-30-r2-004.18d4f7f58e84c0fc,reason=SuccessfulCreate count=1 msg=Created pod: eval-sanitize-30-r2-004-qg5fn
0.208,Event,ADDED,eval-sanitize-30-r2-004.18d4f7fb37d757a2,reason=Completed count=1 msg=Job completed
0.2082,Event,ADDED,eval-sanitize-30-r2-005-ddln6.18d4f7f5cc7e7853,reason=Scheduled count=None msg=Successfully assigned compute/eval-sanitize-30-r2-005-ddln6 to kind-worker
0.2084,Event,ADDED,eval-sanitize-30-r2-005-ddln6.18d4f7f5e6b45e3d,"reason=Pulled count=1 msg=Container image ""busybox:musl"" already present on machine"
0.2085,Event,ADDED,eval-sanitize-30-r2-005-ddln6.18d4f7f5e8009bf0,reason=Created count=1 msg=Created container: task
0.2088,Event,ADDED,eval-sanitize-30-r2-005-ddln6.18d4f7f5ebf8c7fc,reason=Started count=1 msg=Started container task
0.2089,Event,ADDED,eval-sanitize-30-r2-005.18d4f7f5caeb93ad,reason=SuccessfulCreate count=1 msg=Created pod: eval-sanitize-30-r2-005-ddln6
0.2091,Event,ADDED,eval-sanitize-30-r2-005.18d4f7fb62db3f76,reason=Completed count=1 msg=Job completed
0.2093,Event,ADDED,eval-sanitize-30-r2-006-lg2nh.18d4f7f60b792d47,reason=Scheduled count=None msg=Successfully assigned compute/eval-sanitize-30-r2-006-lg2nh to kind-worker3
0.2095,Event,ADDED,eval-sanitize-30-r2-006-lg2nh.18d4f7f62614d939,"reason=Pulled count=1 msg=Container image ""busybox:musl"" already present on machine"
0.2097,Event,ADDED,eval-sanitize-30-r2-006-lg2nh.18d4f7f6274792a8,reason=Created count=1 msg=Created container: task
0.2098,Event,ADDED,eval-sanitize-30-r2-006-lg2nh.18d4f7f6297c48c6,reason=Started count=1 msg=Started container task
0.21,Event,ADDED,eval-sanitize-30-r2-006.18d4f7f605d68f23,reason=SuccessfulCreate count=1 msg=Created pod: eval-sanitize-30-r2-006-lg2nh
0.2102,Event,ADDED,eval-sanitize-30-r2-006.18d4f7fbb33a5b2f,reason=Completed count=1 msg=Job completed
0.2104,Event,ADDED,eval-sanitize-30-r2-007-fc2wz.18d4f7f642db7906,reason=Scheduled count=None msg=Successfully assigned compute/eval-sanitize-30-r2-007-fc2wz to kind-worker3
0.2106,Event,ADDED,eval-sanitize-30-r2-007-fc2wz.18d4f7f6766e4660,"reason=Pulled count=1 msg=Container image ""busybox:musl"" already present on machine"
0.211,Event,ADDED,eval-sanitize-30-r2-007-fc2wz.18d4f7f6778b030d,reason=Created count=1 msg=Created container: task
0.2112,Event,ADDED,eval-sanitize-30-r2-007-fc2wz.18d4f7f67efe23e7,reason=Started count=1 msg=Started container task
0.2117,Event,ADDED,eval-sanitize-30-r2-007.18d4f7f641000481,reason=SuccessfulCreate count=1 msg=Created pod: eval-sanitize-30-r2-007-fc2wz
0.212,Event,ADDED,eval-sanitize-30-r2-007.18d4f7fbf1426588,reason=Completed count=1 msg=Job completed
0.2121,Event,ADDED,eval-sanitize-30-r2-008-x9gqp.18d4f7f68ab99dd8,reason=Scheduled count=None msg=Successfully assigned compute/eval-sanitize-30-r2-008-x9gqp to kind-worker2
0.2123,Event,ADDED,eval-sanitize-30-r2-008-x9gqp.18d4f7f6b9cb9453,"reason=Pulled count=1 msg=Container image ""busybox:musl"" already present on machine"
0.2125,Event,ADDED,eval-sanitize-30-r2-008-x9gqp.18d4f7f6bb3f249c,reason=Created count=1 msg=Created container: task
0.2132,Event,ADDED,eval-sanitize-30-r2-008-x9gqp.18d4f7f6bf1adedb,reason=Started count=1 msg=Started container task
0.2134,Event,ADDED,eval-sanitize-30-r2-008.18d4f7f6809dbd43,reason=SuccessfulCreate count=1 msg=Created pod: eval-sanitize-30-r2-008-x9gqp
0.2136,Event,ADDED,eval-sanitize-30-r2-008.18d4f7fc1bd9c7bc,reason=Completed count=1 msg=Job completed
0.2138,Event,ADDED,eval-sanitize-30-r2-009-c76tr.18d4f7f6bf9e2754,"reason=FailedScheduling count=None msg=0/6 nodes are available: 1 node(s) had untolerated taint(s), 2 c_wall violated: 2 conflicting context pair(s) with node memory, 3 c_wall violated: 1 conflicting context pair(s) with node memory. no new claims to deallocate, preemption: 0/6 nodes are available: 1 Preemption is not helpful for scheduling, 5 No preemption victims found for incoming pod."
0.2144,Event,ADDED,eval-sanitize-30-r2-009-c76tr.18d4f7f6ca9d1aea,"reason=FailedScheduling count=None msg=0/6 nodes are available: 1 node(s) had untolerated taint(s), 2 c_wall violated: 2 conflicting context pair(s) with node memory, 3 c_wall violated: 1 conflicting context pair(s) with node memory. no new claims to deallocate, preemption: 0/6 nodes are available: 1 Preemption is not helpful for scheduling, 5 No preemption victims found for incoming pod."
0.2146,Event,ADDED,eval-sanitize-30-r2-009-c76tr.18d4f7f7cbfa27b1,"reason=FailedScheduling count=None msg=0/6 nodes are available: 1 node(s) had untolerated taint(s), 2 c_wall violated: 1 conflicting context pair(s) with node memory, 3 c_wall violated: 2 conflicting context pair(s) with node memory. no new claims to deallocate, preemption: 0/6 nodes are available: 1 Preemption is not helpful for scheduling, 5 No preemption victims found for incoming pod."
0.215,Event,ADDED,eval-sanitize-30-r2-009-c76tr.18d4f7f97685d0fc,"reason=FailedScheduling count=None msg=0/6 nodes are available: 1 c_wall violated: 1 conflicting context pair(s) with node memory, 2 node(s) had untolerated taint(s), 3 c_wall violated: 2 conflicting context pair(s) with node memory. no new claims to deallocate, preemption: 0/6 nodes are available: 2 Preemption is not helpful for scheduling, 4 No preemption victims found for incoming pod."
0.2152,Event,ADDED,eval-sanitize-30-r2-009-c76tr.18d4f7f98b30010c,"reason=FailedScheduling count=None msg=0/6 nodes are available: 1 c_wall violated: 1 conflicting context pair(s) with node memory, 2 c_wall violated: 2 conflicting context pair(s) with node memory, 3 node(s) had untolerated taint(s). no new claims to deallocate, preemption: 0/6 nodes are available: 3 No preemption victims found for incoming pod, 3 Preemption is not helpful for scheduling."
0.2154,Event,ADDED,eval-sanitize-30-r2-009-c76tr.18d4f7f9d261658d,"reason=FailedScheduling count=None msg=0/6 nodes are available: 1 c_wall violated: 1 conflicting context pair(s) with node memory, 1 c_wall violated: 2 conflicting context pair(s) with node memory, 4 node(s) had untolerated taint(s). no new claims to deallocate, preemption: 0/6 nodes are available: 2 No preemption victims found for incoming pod, 4 Preemption is not helpful for scheduling."
0.2157,Event,ADDED,eval-sanitize-30-r2-009-c76tr.18d4f7fa096ffc4f,"reason=FailedScheduling count=None msg=0/6 nodes are available: 1 c_wall violated: 1 conflicting context pair(s) with node memory, 5 node(s) had untolerated taint(s). no new claims to deallocate, preemption: 0/6 nodes are available: 1 No preemption victims found for incoming pod, 5 Preemption is not helpful for scheduling."
0.2159,Event,ADDED,eval-sanitize-30-r2-009-c76tr.18d4f800754397a0,reason=Scheduled count=None msg=Successfully assigned compute/eval-sanitize-30-r2-009-c76tr to kind-worker
0.2162,Event,ADDED,eval-sanitize-30-r2-009-c76tr.18d4f80096729073,"reason=Pulled count=1 msg=Container image ""busybox:musl"" already present on machine"
0.2165,Event,ADDED,eval-sanitize-30-r2-009-c76tr.18d4f8009ba0f8bb,reason=Created count=1 msg=Created container: task
0.2168,Event,ADDED,eval-sanitize-30-r2-009-c76tr.18d4f800a2981f0b,reason=Started count=1 msg=Started container task
0.2171,Event,ADDED,eval-sanitize-30-r2-009.18d4f7f6be078572,reason=SuccessfulCreate count=1 msg=Created pod: eval-sanitize-30-r2-009-c76tr
0.2173,Event,ADDED,eval-sanitize-30-r2-009.18d4f806d62f4272,reason=Completed count=1 msg=Job completed
0.2176,Event,ADDED,eval-sanitize-30-r2-010-7rq26.18d4f7f70b624d72,reason=Scheduled count=None msg=Successfully assigned compute/eval-sanitize-30-r2-010-7rq26 to kind-worker
0.2178,Event,ADDED,eval-sanitize-30-r2-010-7rq26.18d4f7f727e605df,"reason=Pulled count=1 msg=Container image ""busybox:musl"" already present on machine"
0.218,Event,ADDED,eval-sanitize-30-r2-010-7rq26.18d4f7f7292ae36a,reason=Created count=1 msg=Created container: task
0.2181,Event,ADDED,eval-sanitize-30-r2-010-7rq26.18d4f7f72e159012,reason=Started count=1 msg=Started container task
0.2184,Event,ADDED,eval-sanitize-30-r2-010.18d4f7f6f3c9af51,reason=SuccessfulCreate count=1 msg=Created pod: eval-sanitize-30-r2-010-7rq26
0.2185,Event,ADDED,eval-sanitize-30-r2-010.18d4f7fcd862457e,reason=Completed count=1 msg=Job completed
0.2187,Event,ADDED,eval-sanitize-30-r2-011-2zcvq.18d4f7f739bec5e8,reason=Scheduled count=None msg=Successfully assigned compute/eval-sanitize-30-r2-011-2zcvq to kind-worker3
0.2191,Event,ADDED,eval-sanitize-30-r2-011-2zcvq.18d4f7f755d386c1,"reason=Pulled count=1 msg=Container image ""busybox:musl"" already present on machine"
0.2192,Event,ADDED,eval-sanitize-30-r2-011-2zcvq.18d4f7f757167461,reason=Created count=1 msg=Created container: task
0.2195,Event,ADDED,eval-sanitize-30-r2-011-2zcvq.18d4f7f75fde04d3,reason=Started count=1 msg=Started container task
0.2196,Event,ADDED,eval-sanitize-30-r2-011.18d4f7f72fe80794,reason=SuccessfulCreate count=1 msg=Created pod: eval-sanitize-30-r2-011-2zcvq
0.22,Event,ADDED,eval-sanitize-30-r2-011.18d4f7fcd895da12,reason=Completed count=1 msg=Job completed
0.2201,Event,ADDED,eval-sanitize-30-r2-012-n4xjr.18d4f7f773519a16,reason=Scheduled count=None msg=Successfully assigned compute/eval-sanitize-30-r2-012-n4xjr to kind-worker2
0.2203,Event,ADDED,eval-sanitize-30-r2-012-n4xjr.18d4f7f790edc0ee,"reason=Pulled count=1 msg=Container image ""busybox:musl"" already present on machine"
0.2205,Event,ADDED,eval-sanitize-30-r2-012-n4xjr.18d4f7f792697c61,reason=Created count=1 msg=Created container: task
0.2208,Event,ADDED,eval-sanitize-30-r2-012-n4xjr.18d4f7f79b0ef1f9,reason=Started count=1 msg=Started container task
0.221,Event,ADDED,eval-sanitize-30-r2-012.18d4f7f76c2a01c4,reason=SuccessfulCreate count=1 msg=Created pod: eval-sanitize-30-r2-012-n4xjr
0.2212,Event,ADDED,eval-sanitize-30-r2-012.18d4f7fd0abfa743,reason=Completed count=1 msg=Job completed
0.2214,Event,ADDED,eval-sanitize-30-r2-013-9t9qq.18d4f7f7b636ad18,reason=Scheduled count=None msg=Successfully assigned compute/eval-sanitize-30-r2-013-9t9qq to kind-worker4
0.2218,Event,ADDED,eval-sanitize-30-r2-013-9t9qq.18d4f7f7d4b54cdc,"reason=Pulled count=1 msg=Container image ""busybox:musl"" already present on machine"
0.222,Event,ADDED,eval-sanitize-30-r2-013-9t9qq.18d4f7f7db162c9e,reason=Created count=1 msg=Created container: task
0.2225,Event,ADDED,eval-sanitize-30-r2-013-9t9qq.18d4f7f7e3bc8ba0,reason=Started count=1 msg=Started container task
0.2229,Event,ADDED,eval-sanitize-30-r2-013.18d4f7f7ae3b55c3,reason=SuccessfulCreate count=1 msg=Created pod: eval-sanitize-30-r2-013-9t9qq
0.2232,Event,ADDED,eval-sanitize-30-r2-013.18d4f7fd8631f4f8,reason=Completed count=1 msg=Job completed
0.2234,Event,ADDED,eval-sanitize-30-r2-014-d752n.18d4f7f7ee04c967,reason=Scheduled count=None msg=Successfully assigned compute/eval-sanitize-30-r2-014-d752n to kind-worker4
0.2236,Event,ADDED,eval-sanitize-30-r2-014-d752n.18d4f7f810cbaf2b,"reason=Pulled count=1 msg=Container image ""busybox:musl"" already present on machine"
0.2239,Event,ADDED,eval-sanitize-30-r2-014-d752n.18d4f7f81204da77,reason=Created count=1 msg=Created container: task
0.224,Event,ADDED,eval-sanitize-30-r2-014-d752n.18d4f7f8171c9c24,reason=Started count=1 msg=Started container task
0.2242,Event,ADDED,eval-sanitize-30-r2-014.18d4f7f7e54d1259,reason=SuccessfulCreate count=1 msg=Created pod: eval-sanitize-30-r2-014-d752n
0.2245,Event,ADDED,eval-sanitize-30-r2-014.18d4f7fd860ba7df,reason=Completed count=1 msg=Job completed
0.2247,Event,ADDED,eval-sanitize-30-r2-015-99vlx.18d4f7f82d92238f,reason=Scheduled count=None msg=Successfully assigned compute/eval-sanitize-30-r2-015-99vlx to kind-worker2
0.2249,Event,ADDED,eval-sanitize-30-r2-015-99vlx.18d4f7f84d3451cd,"reason=Pulled count=1 msg=Container image ""busybox:musl"" already present on machine"
0.225,Event,ADDED,eval-sanitize-30-r2-015-99vlx.18d4f7f84e56088f,reason=Created count=1 msg=Created container: task
0.2253,Event,ADDED,eval-sanitize-30-r2-015-99vlx.18d4f7f852eeea63,reason=Started count=1 msg=Started container task
0.2255,Event,ADDED,eval-sanitize-30-r2-015.18d4f7f8222f0f0c,reason=SuccessfulCreate count=1 msg=Created pod: eval-sanitize-30-r2-015-99vlx
0.2257,Event,ADDED,eval-sanitize-30-r2-015.18d4f7fdb7d81244,reason=Completed count=1 msg=Job completed
0.2259,Event,ADDED,eval-sanitize-30-r2-016-f9m2l.18d4f7f863301cd8,reason=Scheduled count=None msg=Successfully assigned compute/eval-sanitize-30-r2-016-f9m2l to kind-worker2
0.2263,Event,ADDED,eval-sanitize-30-r2-016-f9m2l.18d4f7f87d6a8ee9,"reason=Pulled count=1 msg=Container image ""busybox:musl"" already present on machine"
0.2265,Event,ADDED,eval-sanitize-30-r2-016-f9m2l.18d4f7f87ea196ab,reason=Created count=1 msg=Created container: task
0.2267,Event,ADDED,eval-sanitize-30-r2-016-f9m2l.18d4f7f8849f2730,reason=Started count=1 msg=Started container task
0.227,Event,ADDED,eval-sanitize-30-r2-016.18d4f7f8598949b7,reason=SuccessfulCreate count=1 msg=Created pod: eval-sanitize-30-r2-016-f9m2l
0.2272,Event,ADDED,eval-sanitize-30-r2-016.18d4f7fdf33950ec,reason=Completed count=1 msg=Job completed
0.2274,Event,ADDED,eval-sanitize-30-r2-017-gxf98.18d4f7f8a38768fe,reason=Scheduled count=None msg=Successfully assigned compute/eval-sanitize-30-r2-017-gxf98 to kind-worker5
0.2275,Event,ADDED,eval-sanitize-30-r2-017-gxf98.18d4f7f8c177280c,"reason=Pulled count=1 msg=Container image ""busybox:musl"" already present on machine"
0.228,Event,ADDED,eval-sanitize-30-r2-017-gxf98.18d4f7f8c2b0bb79,reason=Created count=1 msg=Created container: task
0.2287,Event,ADDED,eval-sanitize-30-r2-017-gxf98.18d4f7f8c7a7b5e3,reason=Started count=1 msg=Started container task
0.2291,Event,ADDED,eval-sanitize-30-r2-017.18d4f7f896f692e7,reason=SuccessfulCreate count=1 msg=Created pod: eval-sanitize-30-r2-017-gxf98
0.2294,Event,ADDED,eval-sanitize-30-r2-017.18d4f7fe3ee3fb93,reason=Completed count=1 msg=Job completed
0.2297,Event,ADDED,eval-sanitize-30-r2-018-fjh4c.18d4f7f8d88160ed,reason=Scheduled count=None msg=Successfully assigned compute/eval-sanitize-30-r2-018-fjh4c to kind-worker
0.23,Event,ADDED,eval-sanitize-30-r2-018-fjh4c.18d4f7f8f1ea609c,"reason=Pulled count=1 msg=Container image ""busybox:musl"" already present on machine"
0.2303,Event,ADDED,eval-sanitize-30-r2-018-fjh4c.18d4f7f8f32e8f15,reason=Created count=1 msg=Created container: task
0.2306,Event,ADDED,eval-sanitize-30-r2-018-fjh4c.18d4f7f8fb06c02c,reason=Started count=1 msg=Started container task
0.2308,Event,ADDED,eval-sanitize-30-r2-018.18d4f7f8d57512b0,reason=SuccessfulCreate count=1 msg=Created pod: eval-sanitize-30-r2-018-fjh4c
0.231,Event,ADDED,eval-sanitize-30-r2-018.18d4f7fe6a53bd4e,reason=Completed count=1 msg=Job completed
0.2312,Event,ADDED,eval-sanitize-30-r2-019-lmtm4.18d4f7f91c1ccd38,reason=Scheduled count=None msg=Successfully assigned compute/eval-sanitize-30-r2-019-lmtm4 to kind-worker3
0.2316,Event,ADDED,eval-sanitize-30-r2-019-lmtm4.18d4f7f937da6aec,"reason=Pulled count=1 msg=Container image ""busybox:musl"" already present on machine"
0.2318,Event,ADDED,eval-sanitize-30-r2-019-lmtm4.18d4f7f9391da885,reason=Created count=1 msg=Created container: task
0.2322,Event,ADDED,eval-sanitize-30-r2-019-lmtm4.18d4f7f941f4d249,reason=Started count=1 msg=Started container task
0.2324,Event,ADDED,eval-sanitize-30-r2-019.18d4f7f912792a10,reason=SuccessfulCreate count=1 msg=Created pod: eval-sanitize-30-r2-019-lmtm4
0.2326,Event,ADDED,eval-sanitize-30-r2-019.18d4f7feb8f196d0,reason=Completed count=1 msg=Job completed
0.2328,Event,ADDED,eval-sanitize-30-r2-020-gdw4l.18d4f7f963309159,reason=Scheduled count=None msg=Successfully assigned compute/eval-sanitize-30-r2-020-gdw4l to kind-worker2
0.233,Event,ADDED,eval-sanitize-30-r2-020-gdw4l.18d4f7f97e52f271,"reason=Pulled count=1 msg=Container image ""busybox:musl"" already present on machine"
0.2332,Event,ADDED,eval-sanitize-30-r2-020-gdw4l.18d4f7f97f83e1ab,reason=Created count=1 msg=Created container: task
0.2334,Event,ADDED,eval-sanitize-30-r2-020-gdw4l.18d4f7f985f89d04,reason=Started count=1 msg=Started container task
0.2336,Event,ADDED,eval-sanitize-30-r2-020.18d4f7f94eb06e31,reason=SuccessfulCreate count=1 msg=Created pod: eval-sanitize-30-r2-020-gdw4l
0.234,Event,ADDED,eval-sanitize-30-r2-020.18d4f7ff22c8c5bb,reason=Completed count=1 msg=Job completed
0.2342,Event,ADDED,eval-sanitize-30-r2-021-gx724.18d4f7f98a95c732,reason=Scheduled count=None msg=Successfully assigned compute/eval-sanitize-30-r2-021-gx724 to kind-worker5
0.2346,Event,ADDED,eval-sanitize-30-r2-021-gx724.18d4f7f9a4b43cc0,"reason=Pulled count=1 msg=Container image ""busybox:musl"" already present on machine"
0.2351,Event,ADDED,eval-sanitize-30-r2-021-gx724.18d4f7f9a60b571c,reason=Created count=1 msg=Created container: task
0.2353,Event,ADDED,eval-sanitize-30-r2-021-gx724.18d4f7f9abf219ea,reason=Started count=1 msg=Started container task
0.2355,Event,ADDED,eval-sanitize-30-r2-021.18d4f7f9848be571,reason=SuccessfulCreate count=1 msg=Created pod: eval-sanitize-30-r2-021-gx724
0.2356,Event,ADDED,eval-sanitize-30-r2-021.18d4f7ff30ffb8e5,reason=Completed count=1 msg=Job completed
0.236,Event,ADDED,eval-sanitize-30-r2-022-c896k.18d4f7f9c8a55a93,reason=Scheduled count=None msg=Successfully assigned compute/eval-sanitize-30-r2-022-c896k to kind-worker5
0.2362,Event,ADDED,eval-sanitize-30-r2-022-c896k.18d4f7f9e33ab0d0,"reason=Pulled count=1 msg=Container image ""busybox:musl"" already present on machine"
0.2364,Event,ADDED,eval-sanitize-30-r2-022-c896k.18d4f7f9e473dcf6,reason=Created count=1 msg=Created container: task
0.2368,Event,ADDED,eval-sanitize-30-r2-022-c896k.18d4f7f9ed4c8290,reason=Started count=1 msg=Started container task
0.2369,Event,ADDED,eval-sanitize-30-r2-022.18d4f7f9c2af9a3f,reason=SuccessfulCreate count=1 msg=Created pod: eval-sanitize-30-r2-022-c896k
0.2371,Event,ADDED,eval-sanitize-30-r2-022.18d4f7ff69899eb6,reason=Completed count=1 msg=Job completed
0.2373,Event,ADDED,eval-sanitize-30-r2-023-67kfr.18d4f7fa01409d40,"reason=FailedScheduling count=None msg=0/6 nodes are available: 2 c_wall violated: 1 conflicting context pair(s) with node memory, 4 node(s) had untolerated taint(s). no new claims to deallocate, preemption: 0/6 nodes are available: 2 No preemption victims found for incoming pod, 4 Preemption is not helpful for scheduling."
0.2376,Event,ADDED,eval-sanitize-30-r2-023-67kfr.18d4f7fa024a3de5,"reason=FailedScheduling count=None msg=0/6 nodes are available: 2 c_wall violated: 1 conflicting context pair(s) with node memory, 4 node(s) had untolerated taint(s). no new claims to deallocate, preemption: 0/6 nodes are available: 2 No preemption victims found for incoming pod, 4 Preemption is not helpful for scheduling."
0.2378,Event,ADDED,eval-sanitize-30-r2-023-67kfr.18d4f7fa09a97318,"reason=FailedScheduling count=None msg=0/6 nodes are available: 1 c_wall violated: 1 conflicting context pair(s) with node memory, 5 node(s) had untolerated taint(s). no new claims to deallocate, preemption: 0/6 nodes are available: 1 No preemption victims found for incoming pod, 5 Preemption is not helpful for scheduling."
0.238,Event,ADDED,eval-sanitize-30-r2-023-67kfr.18d4f800778a7aec,reason=Scheduled count=None msg=Successfully assigned compute/eval-sanitize-30-r2-023-67kfr to kind-worker
0.2382,Event,ADDED,eval-sanitize-30-r2-023-67kfr.18d4f8009692f2fb,"reason=Pulled count=1 msg=Container image ""busybox:musl"" already present on machine"
0.2384,Event,ADDED,eval-sanitize-30-r2-023-67kfr.18d4f8009c0d0b8d,reason=Created count=1 msg=Created container: task
0.2386,Event,ADDED,eval-sanitize-30-r2-023-67kfr.18d4f800a1cc3728,reason=Started count=1 msg=Started container task
0.2387,Event,ADDED,eval-sanitize-30-r2-023.18d4f7fa00a986a1,reason=SuccessfulCreate count=1 msg=Created pod: eval-sanitize-30-r2-023-67kfr
0.2389,Event,ADDED,eval-sanitize-30-r2-023.18d4f805e8606f6c,reason=Completed count=1 msg=Job completed
0.2391,Event,ADDED,eval-sanitize-30-r2-024-vbwl5.18d4f7fa3adfb46c,"reason=FailedScheduling count=None msg=0/6 nodes are available: 6 node(s) had untolerated taint(s). no new claims to deallocate, preemption: 0/6 nodes are available: 6 Preemption is not helpful for scheduling."
0.2392,Event,ADDED,eval-sanitize-30-r2-024-vbwl5.18d4f80075c6b151,"reason=FailedScheduling count=None msg=0/6 nodes are available: 1 c_wall violated: 1 conflicting context pair(s) with node memory, 5 node(s) had untolerated taint(s). no new claims to deallocate, preemption: 0/6 nodes are available: 1 No preemption victims found for incoming pod, 5 Preemption is not helpful for scheduling."
0.2394,Event,ADDED,eval-sanitize-30-r2-024-vbwl5.18d4f800a9dedb9b,"reason=FailedScheduling count=None msg=0/6 nodes are available: 1 c_wall violated: 1 conflicting context pair(s) with node memory, 1 c_wall violated: 2 conflicting context pair(s) with node memory, 4 node(s) had untolerated taint(s). no new claims to deallocate, preemption: 0/6 nodes are available: 2 No preemption victims found for incoming pod, 4 Preemption is not helpful for scheduling."
0.2396,Event,ADDED,eval-sanitize-30-r2-024-vbwl5.18d4f800e0ace91a,"reason=FailedScheduling count=None msg=0/6 nodes are available: 1 c_wall violated: 2 conflicting context pair(s) with node memory, 2 c_wall violated: 1 conflicting context pair(s) with node memory, 3 node(s) had untolerated taint(s). no new claims to deallocate, preemption: 0/6 nodes are available: 3 No preemption victims found for incoming pod, 3 Preemption is not helpful for scheduling."
0.2398,Event,ADDED,eval-sanitize-30-r2-024-vbwl5.18d4f80126024707,reason=Scheduled count=None msg=Successfully assigned compute/eval-sanitize-30-r2-024-vbwl5 to kind-worker5
0.2404,Event,ADDED,eval-sanitize-30-r2-024-vbwl5.18d4f80142380b27,"reason=Pulled count=1 msg=Container image ""busybox:musl"" already present on machine"
0.2406,Event,ADDED,eval-sanitize-30-r2-024-vbwl5.18d4f80143d0c5d8,reason=Created count=1 msg=Created container: task
0.2408,Event,ADDED,eval-sanitize-30-r2-024-vbwl5.18d4f8014c641be1,reason=Started count=1 msg=Started container task
0.241,Event,ADDED,eval-sanitize-30-r2-024.18d4f7fa3ad277b8,reason=SuccessfulCreate count=1 msg=Created pod: eval-sanitize-30-r2-024-vbwl5
0.2413,Event,ADDED,eval-sanitize-30-r2-024.18d4f808b301000e,reason=Completed count=1 msg=Job completed
0.2415,Event,ADDED,eval-sanitize-30-r2-025-nht27.18d4f7fa75ff45f7,"reason=FailedScheduling count=None msg=0/6 nodes are available: 6 node(s) had untolerated taint(s). no new claims to deallocate, preemption: 0/6 nodes are available: 6 Preemption is not helpful for scheduling."
0.2416,Event,ADDED,eval-sanitize-30-r2-025-nht27.18d4f8007891128b,reason=Scheduled count=None msg=Successfully assigned compute/eval-sanitize-30-r2-025-nht27 to kind-worker
0.2419,Event,ADDED,eval-sanitize-30-r2-025-nht27.18d4f80096c08747,"reason=Pulled count=1 msg=Container image ""busybox:musl"" already present on machine"
0.242,Event,ADDED,eval-sanitize-30-r2-025-nht27.18d4f8009c34d451,reason=Created count=1 msg=Created container: task
0.2422,Event,ADDED,eval-sanitize-30-r2-025-nht27.18d4f800a2512e8a,reason=Started count=1 msg=Started container task
0.2424,Event,ADDED,eval-sanitize-30-r2-025.18d4f7fa75f53d8e,reason=SuccessfulCreate count=1 msg=Created pod: eval-sanitize-30-r2-025-nht27
0.2426,Event,ADDED,eval-sanitize-30-r2-025.18d4f8070400fe10,reason=Completed count=1 msg=Job completed
0.2427,Event,ADDED,eval-sanitize-30-r2-026-4scv9.18d4f7faafa1ebdd,"reason=FailedScheduling count=None msg=0/6 nodes are available: 6 node(s) had untolerated taint(s). no new claims to deallocate, preemption: 0/6 nodes are available: 6 Preemption is not helpful for scheduling."
0.2429,Event,ADDED,eval-sanitize-30-r2-026-4scv9.18d4f8007aded212,"reason=FailedScheduling count=None msg=0/6 nodes are available: 1 c_wall violated: 1 conflicting context pair(s) with node memory, 5 node(s) had untolerated taint(s). no new claims to deallocate, preemption: 0/6 nodes are available: 1 No preemption victims found for incoming pod, 5 Preemption is not helpful for scheduling."
0.2432,Event,ADDED,eval-sanitize-30-r2-026-4scv9.18d4f800aaf24b93,"reason=FailedScheduling count=None msg=0/6 nodes are available: 1 c_wall violated: 1 conflicting context pair(s) with node memory, 1 c_wall violated: 2 conflicting context pair(s) with node memory, 4 node(s) had untolerated taint(s). no new claims to deallocate, preemption: 0/6 nodes are available: 2 No preemption victims found for incoming pod, 4 Preemption is not helpful for scheduling."
0.2433,Event,ADDED,eval-sanitize-30-r2-026-4scv9.18d4f800e695941b,"reason=FailedScheduling count=None msg=0/6 nodes are available: 1 c_wall violated: 1 conflicting context pair(s) with node memory, 2 c_wall violated: 2 conflicting context pair(s) with node memory, 3 node(s) had untolerated taint(s). no new claims to deallocate, preemption: 0/6 nodes are available: 3 No preemption victims found for incoming pod, 3 Preemption is not helpful for scheduling."
0.2436,Event,ADDED,eval-sanitize-30-r2-026-4scv9.18d4f8012894523a,"reason=FailedScheduling count=None msg=0/6 nodes are available: 2 c_wall violated: 1 conflicting context pair(s) with node memory, 2 c_wall violated: 2 conflicting context pair(s) with node memory, 2 node(s) had untolerated taint(s). no new claims to deallocate, preemption: 0/6 nodes are available: 2 Preemption is not helpful for scheduling, 4 No preemption victims found for incoming pod."
0.2439,Event,ADDED,eval-sanitize-30-r2-026-4scv9.18d4f801728b339b,reason=Scheduled count=None msg=Successfully assigned compute/eval-sanitize-30-r2-026-4scv9 to kind-worker2
0.2442,Event,ADDED,eval-sanitize-30-r2-026-4scv9.18d4f8018f2d235a,"reason=Pulled count=1 msg=Container image ""busybox:musl"" already present on machine"
0.2444,Event,ADDED,eval-sanitize-30-r2-026-4scv9.18d4f80190f11884,reason=Created count=1 msg=Created container: task
0.2447,Event,ADDED,eval-sanitize-30-r2-026-4scv9.18d4f80196bd5e65,reason=Started count=1 msg=Started container task
0.245,Event,ADDED,eval-sanitize-30-r2-026.18d4f7faaf821e5b,reason=SuccessfulCreate count=1 msg=Created pod: eval-sanitize-30-r2-026-4scv9
0.2452,Event,ADDED,eval-sanitize-30-r2-026.18d4f808cad5895b,reason=Completed count=1 msg=Job completed
0.2454,Event,ADDED,eval-sanitize-30-r2-027-b2v9b.18d4f7fae94c84bc,"reason=FailedScheduling count=None msg=0/6 nodes are available: 6 node(s) had untolerated taint(s). no new claims to deallocate, preemption: 0/6 nodes are available: 6 Preemption is not helpful for scheduling."
0.2458,Event,ADDED,eval-sanitize-30-r2-027-b2v9b.18d4f8007b720e01,"reason=FailedScheduling count=None msg=0/6 nodes are available: 1 c_wall violated: 1 conflicting context pair(s) with node memory, 5 node(s) had untolerated taint(s). no new claims to deallocate, preemption: 0/6 nodes are available: 1 No preemption victims found for incoming pod, 5 Preemption is not helpful for scheduling."
0.2463,Event,ADDED,eval-sanitize-30-r2-027-b2v9b.18d4f800b0924c88,"reason=FailedScheduling count=None msg=0/6 nodes are available: 1 c_wall violated: 1 conflicting context pair(s) with node memory, 1 c_wall violated: 2 conflicting context pair(s) with node memory, 4 node(s) had untolerated taint(s). no new claims to deallocate, preemption: 0/6 nodes are available: 2 No preemption victims found for incoming pod, 4 Preemption is not helpful for scheduling."
0.2465,Event,ADDED,eval-sanitize-30-r2-027-b2v9b.18d4f800f3de504e,"reason=FailedScheduling count=None msg=0/6 nodes are available: 1 c_wall violated: 2 conflicting context pair(s) with node memory, 2 c_wall violated: 1 conflicting context pair(s) with node memory, 3 node(s) had untolerated taint(s). no new claims to deallocate, preemption: 0/6 nodes are available: 3 No preemption victims found for incoming pod, 3 Preemption is not helpful for scheduling."
0.2468,Event,ADDED,eval-sanitize-30-r2-027-b2v9b.18d4f80136f2a7c7,reason=Scheduled count=None msg=Successfully assigned compute/eval-sanitize-30-r2-027-b2v9b to kind-worker5
0.247,Event,ADDED,eval-sanitize-30-r2-027-b2v9b.18d4f8015ba41e22,"reason=Pulled count=1 msg=Container image ""busybox:musl"" already present on machine"
0.2471,Event,ADDED,eval-sanitize-30-r2-027-b2v9b.18d4f8015d91954c,reason=Created count=1 msg=Created container: task
0.2474,Event,ADDED,eval-sanitize-30-r2-027-b2v9b.18d4f801625c69fb,reason=Started count=1 msg=Started container task
0.2477,Event,ADDED,eval-sanitize-30-r2-027.18d4f7fae93d2163,reason=SuccessfulCreate count=1 msg=Created pod: eval-sanitize-30-r2-027-b2v9b
0.2478,Event,ADDED,eval-sanitize-30-r2-027.18d4f808b5f4a4fa,reason=Completed count=1 msg=Job completed
0.248,Event,ADDED,eval-sanitize-30-r2-028-7xdwq.18d4f7fb262bf3c5,"reason=FailedScheduling count=None msg=0/6 nodes are available: 6 node(s) had untolerated taint(s). no new claims to deallocate, preemption: 0/6 nodes are available: 6 Preemption is not helpful for scheduling."
0.2483,Event,ADDED,eval-sanitize-30-r2-028-7xdwq.18d4f8007c84db7e,"reason=FailedScheduling count=None msg=0/6 nodes are available: 1 c_wall violated: 1 conflicting context pair(s) with node memory, 5 node(s) had untolerated taint(s). no new claims to deallocate, preemption: 0/6 nodes are available: 1 No preemption victims found for incoming pod, 5 Preemption is not helpful for scheduling."
0.2485,Event,ADDED,eval-sanitize-30-r2-028-7xdwq.18d4f800b1e630c6,"reason=FailedScheduling count=None msg=0/6 nodes are available: 2 c_wall violated: 2 conflicting context pair(s) with node memory, 4 node(s) had untolerated taint(s). no new claims to deallocate, preemption: 0/6 nodes are available: 2 No preemption victims found for incoming pod, 4 Preemption is not helpful for scheduling."
0.2486,Event,ADDED,eval-sanitize-30-r2-028-7xdwq.18d4f800fa05dc30,reason=Scheduled count=None msg=Successfully assigned compute/eval-sanitize-30-r2-028-7xdwq to kind-worker3
0.2488,Event,ADDED,eval-sanitize-30-r2-028-7xdwq.18d4f801159fcea9,"reason=Pulled count=1 msg=Container image ""busybox:musl"" already present on machine"
0.249,Event,ADDED,eval-sanitize-30-r2-028-7xdwq.18d4f801197467fc,reason=Created count=1 msg=Created container: task
0.2492,Event,ADDED,eval-sanitize-30-r2-028-7xdwq.18d4f80125fa66f0,reason=Started count=1 msg=Started container task
0.2494,Event,ADDED,eval-sanitize-30-r2-028.18d4f7fb261d78bf,reason=SuccessfulCreate count=1 msg=Created pod: eval-sanitize-30-r2-028-7xdwq
0.2496,Event,ADDED,eval-sanitize-30-r2-028.18d4f808271cdc29,reason=Completed count=1 msg=Job completed
0.2498,Event,ADDED,eval-sanitize-30-r2-029-sj672.18d4f7fb603aee45,"reason=FailedScheduling count=None msg=0/6 nodes are available: 6 node(s) had untolerated taint(s). no new claims to deallocate, preemption: 0/6 nodes are available: 6 Preemption is not helpful for scheduling."
0.25,Event,ADDED,eval-sanitize-30-r2-029-sj672.18d4f8007d69612f,reason=Scheduled count=None msg=Successfully assigned compute/eval-sanitize-30-r2-029-sj672 to kind-worker
0.2502,Event,ADDED,eval-sanitize-30-r2-029-sj672.18d4f800a079d954,"reason=Pulled count=1 msg=Container image ""busybox:musl"" already present on machine"
0.2505,Event,ADDED,eval-sanitize-30-r2-029-sj672.18d4f800a24e5089,reason=Created count=1 msg=Created container: task
0.2508,Event,ADDED,eval-sanitize-30-r2-029-sj672.18d4f800a67a31be,reason=Started count=1 msg=Started container task
0.251,Event,ADDED,eval-sanitize-30-r2-029.18d4f7fb602eedf0,reason=SuccessfulCreate count=1 msg=Created pod: eval-sanitize-30-r2-029-sj672
0.2512,Event,ADDED,eval-sanitize-30-r2-029.18d4f805e860f26a,reason=Completed count=1 msg=Job completed
0.2514,Event,ADDED,eval-sanitize-30-r2-030-r2mdq.18d4f7fb9f78a734,"reason=FailedScheduling count=None msg=0/6 nodes are available: 6 node(s) had untolerated taint(s). no new claims to deallocate, preemption: 0/6 nodes are available: 6 Preemption is not helpful for scheduling."
0.2517,Event,ADDED,eval-sanitize-30-r2-030-r2mdq.18d4f8007d42ea50,"reason=FailedScheduling count=None msg=0/6 nodes are available: 1 c_wall violated: 2 conflicting context pair(s) with node memory, 5 node(s) had untolerated taint(s). no new claims to deallocate, preemption: 0/6 nodes are available: 1 No preemption victims found for incoming pod, 5 Preemption is not helpful for scheduling."
0.252,Event,ADDED,eval-sanitize-30-r2-030-r2mdq.18d4f800b6e6b8dc,reason=Scheduled count=None msg=Successfully assigned compute/eval-sanitize-30-r2-030-r2mdq to kind-worker4
0.2524,Event,ADDED,eval-sanitize-30-r2-030-r2mdq.18d4f800d4ff1efe,"reason=Pulled count=1 msg=Container image ""busybox:musl"" already present on machine"
0.2526,Event,ADDED,eval-sanitize-30-r2-030-r2mdq.18d4f800d69d2cb2,reason=Created count=1 msg=Created container: task
0.2528,Event,ADDED,eval-sanitize-30-r2-030-r2mdq.18d4f800dac191f2,reason=Started count=1 msg=Started container task
0.253,Event,ADDED,eval-sanitize-30-r2-030.18d4f7fb9f6f18ee,reason=SuccessfulCreate count=1 msg=Created pod: eval-sanitize-30-r2-030-r2mdq
0.2534,Event,ADDED,eval-sanitize-30-r2-030.18d4f8086b6af8ec,reason=Completed count=1 msg=Job completed
0.2536,Event,ADDED,eval-sanitize-30-r2-031-bbj7f.18d4f7fbdb3851de,"reason=FailedScheduling count=None msg=0/6 nodes are available: 6 node(s) had untolerated taint(s). no new claims to deallocate, preemption: 0/6 nodes are available: 6 Preemption is not helpful for scheduling."
0.2538,Event,ADDED,eval-sanitize-30-r2-031-bbj7f.18d4f8007f54dd80,"reason=FailedScheduling count=None msg=0/6 nodes are available: 1 c_wall violated: 2 conflicting context pair(s) with node memory, 5 node(s) had untolerated taint(s). no new claims to deallocate, preemption: 0/6 nodes are available: 1 No preemption victims found for incoming pod, 5 Preemption is not helpful for scheduling."
0.2541,Event,ADDED,eval-sanitize-30-r2-031-bbj7f.18d4f800b6e87e9e,"reason=FailedScheduling count=None msg=0/6 nodes are available: 2 c_wall violated: 2 conflicting context pair(s) with node memory, 4 node(s) had untolerated taint(s). no new claims to deallocate, preemption: 0/6 nodes are available: 2 No preemption victims found for incoming pod, 4 Preemption is not helpful for scheduling."
0.2543,Event,ADDED,eval-sanitize-30-r2-031-bbj7f.18d4f80101ec72ca,reason=Scheduled count=None msg=Successfully assigned compute/eval-sanitize-30-r2-031-bbj7f to kind-worker3
0.2545,Event,ADDED,eval-sanitize-30-r2-031-bbj7f.18d4f80126039016,"reason=Pulled count=1 msg=Container image ""busybox:musl"" already present on machine"
0.2546,Event,ADDED,eval-sanitize-30-r2-031-bbj7f.18d4f80127fbf404,reason=Created count=1 msg=Created container: task
0.255,Event,ADDED,eval-sanitize-30-r2-031-bbj7f.18d4f8012c40708f,reason=Started count=1 msg=Started container task
0.2551,Event,ADDED,eval-sanitize-30-r2-031.18d4f7fbdb2ffd05,reason=SuccessfulCreate count=1 msg=Created pod: eval-sanitize-30-r2-031-bbj7f
0.2553,Event,ADDED,eval-sanitize-30-r2-031.18d4f80838d08bd8,reason=Completed count=1 msg=Job completed
0.2556,Event,ADDED,eval-sanitize-30-r2-032-x4hl7.18d4f7fc1c833c91,"reason=FailedScheduling count=None msg=0/6 nodes are available: 6 node(s) had untolerated taint(s). no new claims to deallocate, preemption: 0/6 nodes are available: 6 Preemption is not helpful for scheduling."
0.2558,Event,ADDED,eval-sanitize-30-r2-032-x4hl7.18d4f80080f14574,"reason=FailedScheduling count=None msg=0/6 nodes are available: 1 c_wall violated: 1 conflicting context pair(s) with node memory, 5 node(s) had untolerated taint(s). no new claims to deallocate, preemption: 0/6 nodes are available: 1 No preemption victims found for incoming pod, 5 Preemption is not helpful for scheduling."
0.2559,Event,ADDED,eval-sanitize-30-r2-032-x4hl7.18d4f800bbc02896,"reason=FailedScheduling count=None msg=0/6 nodes are available: 1 c_wall violated: 1 conflicting context pair(s) with node memory, 1 c_wall violated: 2 conflicting context pair(s) with node memory, 4 node(s) had untolerated taint(s). no new claims to deallocate, preemption: 0/6 nodes are available: 2 No preemption victims found for incoming pod, 4 Preemption is not helpful for scheduling."
0.2561,Event,ADDED,eval-sanitize-30-r2-032-x4hl7.18d4f80104520efa,"reason=FailedScheduling count=None msg=0/6 nodes are available: 1 c_wall violated: 1 conflicting context pair(s) with node memory, 2 c_wall violated: 2 conflicting context pair(s) with node memory, 3 node(s) had untolerated taint(s). no new claims to deallocate, preemption: 0/6 nodes are available: 3 No preemption victims found for incoming pod, 3 Preemption is not helpful for scheduling."
0.2562,Event,ADDED,eval-sanitize-30-r2-032-x4hl7.18d4f8013a99479d,reason=Scheduled count=None msg=Successfully assigned compute/eval-sanitize-30-r2-032-x4hl7 to kind-worker2
0.2564,Event,ADDED,eval-sanitize-30-r2-032-x4hl7.18d4f8015b879ec1,"reason=Pulled count=1 msg=Container image ""busybox:musl"" already present on machine"
0.2566,Event,ADDED,eval-sanitize-30-r2-032-x4hl7.18d4f8015ddc95ca,reason=Created count=1 msg=Created container: task
0.2568,Event,ADDED,eval-sanitize-30-r2-032-x4hl7.18d4f801625dab1b,reason=Started count=1 msg=Started container task
0.257,Event,ADDED,eval-sanitize-30-r2-032.18d4f7fc1c7811a6,reason=SuccessfulCreate count=1 msg=Created pod: eval-sanitize-30-r2-032-x4hl7
0.2573,Event,ADDED,eval-sanitize-30-r2-032.18d4f808a4cb3a2a,reason=Completed count=1 msg=Job completed
0.2576,Event,ADDED,eval-sanitize-30-r2-033-2x9qh.18d4f7fc52b75e40,"reason=FailedScheduling count=None msg=0/6 nodes are available: 6 node(s) had untolerated taint(s). no new claims to deallocate, preemption: 0/6 nodes are available: 6 Preemption is not helpful for scheduling."
0.2579,Event,ADDED,eval-sanitize-30-r2-033-2x9qh.18d4f80082a38f43,reason=Scheduled count=None msg=Successfully assigned compute/eval-sanitize-30-r2-033-2x9qh to kind-worker
0.2583,Event,ADDED,eval-sanitize-30-r2-033-2x9qh.18d4f800a35fdcdc,"reason=Pulled count=1 msg=Container image ""busybox:musl"" already present on machine"
0.2585,Event,ADDED,eval-sanitize-30-r2-033-2x9qh.18d4f800a59bf160,reason=Created count=1 msg=Created container: task
0.2588,Event,ADDED,eval-sanitize-30-r2-033-2x9qh.18d4f800ac41fa64,reason=Started count=1 msg=Started container task
0.259,Event,ADDED,eval-sanitize-30-r2-033.18d4f7fc52abd6f1,reason=SuccessfulCreate count=1 msg=Created pod: eval-sanitize-30-r2-033-2x9qh
0.2592,Event,ADDED,eval-sanitize-30-r2-033.18d4f806dc284bb4,reason=Completed count=1 msg=Job completed
0.2594,Event,ADDED,eval-sanitize-30-r2-034-zv7xs.18d4f7fc93e31109,"reason=FailedScheduling count=None msg=0/6 nodes are available: 6 node(s) had untolerated taint(s). no new claims to deallocate, preemption: 0/6 nodes are available: 6 Preemption is not helpful for scheduling."
0.2597,Event,ADDED,eval-sanitize-30-r2-034-zv7xs.18d4f800827788bb,"reason=FailedScheduling count=None msg=0/6 nodes are available: 1 c_wall violated: 1 conflicting context pair(s) with node memory, 5 node(s) had untolerated taint(s). no new claims to deallocate, preemption: 0/6 nodes are available: 1 No preemption victims found for incoming pod, 5 Preemption is not helpful for scheduling."
0.26,Event,ADDED,eval-sanitize-30-r2-034-zv7xs.18d4f800bd813b92,"reason=FailedScheduling count=None msg=0/6 nodes are available: 1 c_wall violated: 1 conflicting context pair(s) with node memory, 1 c_wall violated: 2 conflicting context pair(s) with node memory, 4 node(s) had untolerated taint(s). no new claims to deallocate, preemption: 0/6 nodes are available: 2 No preemption victims found for incoming pod, 4 Preemption is not helpful for scheduling."
0.2603,Event,ADDED,eval-sanitize-30-r2-034-zv7xs.18d4f8010a3323ad,"reason=FailedScheduling count=None msg=0/6 nodes are available: 1 c_wall violated: 1 conflicting context pair(s) with node memory, 2 c_wall violated: 2 conflicting context pair(s) with node memory, 3 node(s) had untolerated taint(s). no new claims to deallocate, preemption: 0/6 nodes are available: 3 No preemption victims found for incoming pod, 3 Preemption is not helpful for scheduling."
0.2606,Event,ADDED,eval-sanitize-30-r2-034-zv7xs.18d4f80145164cd4,reason=Scheduled count=None msg=Successfully assigned compute/eval-sanitize-30-r2-034-zv7xs to kind-worker2
0.2608,Event,ADDED,eval-sanitize-30-r2-034-zv7xs.18d4f801641f3839,"reason=Pulled count=1 msg=Container image ""busybox:musl"" already present on machine"
0.261,Event,ADDED,eval-sanitize-30-r2-034-zv7xs.18d4f8016562ecfa,reason=Created count=1 msg=Created container: task
0.2613,Event,ADDED,eval-sanitize-30-r2-034-zv7xs.18d4f80172451010,reason=Started count=1 msg=Started container task
0.2615,Event,ADDED,eval-sanitize-30-r2-034.18d4f7fc93dbd65d,reason=SuccessfulCreate count=1 msg=Created pod: eval-sanitize-30-r2-034-zv7xs
0.2617,Event,ADDED,eval-sanitize-30-r2-034.18d4f8089e2f165a,reason=Completed count=1 msg=Job completed
0.2618,Event,ADDED,eval-sanitize-30-r2-035-8fjqz.18d4f7fcc7dee18e,"reason=FailedScheduling count=None msg=0/6 nodes are available: 6 node(s) had untolerated taint(s). no new claims to deallocate, preemption: 0/6 nodes are available: 6 Preemption is not helpful for scheduling."
0.2621,Event,ADDED,eval-sanitize-30-r2-035-8fjqz.18d4f80083a4ae12,reason=Scheduled count=None msg=Successfully assigned compute/eval-sanitize-30-r2-035-8fjqz to kind-worker
0.2622,Event,ADDED,eval-sanitize-30-r2-035-8fjqz.18d4f800a381024b,"reason=Pulled count=1 msg=Container image ""busybox:musl"" already present on machine"
0.2624,Event,ADDED,eval-sanitize-30-r2-035-8fjqz.18d4f800a5e238ac,reason=Created count=1 msg=Created container: task
0.2626,Event,ADDED,eval-sanitize-30-r2-035-8fjqz.18d4f800ac415fa6,reason=Started count=1 msg=Started container task
0.2628,Event,ADDED,eval-sanitize-30-r2-035.18d4f7fcc7d2289f,reason=SuccessfulCreate count=1 msg=Created pod: eval-sanitize-30-r2-035-8fjqz
0.2629,Event,ADDED,eval-sanitize-30-r2-035.18d4f80705cdcd8f,reason=Completed count=1 msg=Job completed
0.2631,Event,ADDED,eval-sanitize-30-r2-036-597dz.18d4f7fd03d0dcd7,"reason=FailedScheduling count=None msg=0/6 nodes are available: 6 node(s) had untolerated taint(s). no new claims to deallocate, preemption: 0/6 nodes are available: 6 Preemption is not helpful for scheduling."
0.2635,Event,ADDED,eval-sanitize-30-r2-036-597dz.18d4f8008604c0f2,"reason=FailedScheduling count=None msg=0/6 nodes are available: 1 c_wall violated: 3 conflicting context pair(s) with node memory, 5 node(s) had untolerated taint(s). no new claims to deallocate, preemption: 0/6 nodes are available: 1 No preemption victims found for incoming pod, 5 Preemption is not helpful for scheduling."
0.2638,Event,ADDED,eval-sanitize-30-r2-036-597dz.18d4f800cc909ca1,reason=Scheduled count=None msg=Successfully assigned compute/eval-sanitize-30-r2-036-597dz to kind-worker4
0.264,Event,ADDED,eval-sanitize-30-r2-036-597dz.18d4f800e96605a0,"reason=Pulled count=1 msg=Container image ""busybox:musl"" already present on machine"
0.2642,Event,ADDED,eval-sanitize-30-r2-036-597dz.18d4f800eb6e6359,reason=Created count=1 msg=Created container: task
0.2645,Event,ADDED,eval-sanitize-30-r2-036-597dz.18d4f800f55e0967,reason=Started count=1 msg=Started container task
0.2646,Event,ADDED,eval-sanitize-30-r2-036.18d4f7fd03ca30e5,reason=SuccessfulCreate count=1 msg=Created pod: eval-sanitize-30-r2-036-597dz
0.2648,Event,ADDED,eval-sanitize-30-r2-036.18d4f8089009b320,reason=Completed count=1 msg=Job completed
0.2651,Event,ADDED,eval-sanitize-30-r2-037-2xptq.18d4f7fd4056f67e,"reason=FailedScheduling count=None msg=0/6 nodes are available: 6 node(s) had untolerated taint(s). no new claims to deallocate, preemption: 0/6 nodes are available: 6 Preemption is not helpful for scheduling."
0.2653,Event,ADDED,eval-sanitize-30-r2-037-2xptq.18d4f8008af68764,"reason=FailedScheduling count=None msg=0/6 nodes are available: 1 c_wall violated: 1 conflicting context pair(s) with node memory, 5 node(s) had untolerated taint(s). no new claims to deallocate, preemption: 0/6 nodes are available: 1 No preemption victims found for incoming pod, 5 Preemption is not helpful for scheduling."
0.2654,Event,ADDED,eval-sanitize-30-r2-037-2xptq.18d4f800cd0628d3,reason=Scheduled count=None msg=Successfully assigned compute/eval-sanitize-30-r2-037-2xptq to kind-worker4
0.2656,Event,ADDED,eval-sanitize-30-r2-037-2xptq.18d4f800eaab6e5e,"reason=Pulled count=1 msg=Container image ""busybox:musl"" already present on machine"
0.2661,Event,ADDED,eval-sanitize-30-r2-037-2xptq.18d4f800ecfebd3d,reason=Created count=1 msg=Created container: task
0.2664,Event,ADDED,eval-sanitize-30-r2-037-2xptq.18d4f800f55fef16,reason=Started count=1 msg=Started container task
0.2666,Event,ADDED,eval-sanitize-30-r2-037.18d4f7fd404e7c7c,reason=SuccessfulCreate count=1 msg=Created pod: eval-sanitize-30-r2-037-2xptq
0.267,Event,ADDED,eval-sanitize-30-r2-037.18d4f808810bfd3b,reason=Completed count=1 msg=Job completed
0.2672,Event,ADDED,eval-sanitize-30-r2-038-mmdbm.18d4f7fd7b5925bf,"reason=FailedScheduling count=None msg=0/6 nodes are available: 6 node(s) had untolerated taint(s). no new claims to deallocate, preemption: 0/6 nodes are available: 6 Preemption is not helpful for scheduling."
0.2673,Event,ADDED,eval-sanitize-30-r2-038-mmdbm.18d4f8008bc0a7ac,"reason=FailedScheduling count=None msg=0/6 nodes are available: 1 c_wall violated: 1 conflicting context pair(s) with node memory, 5 node(s) had untolerated taint(s). no new claims to deallocate, preemption: 0/6 nodes are available: 1 No preemption victims found for incoming pod, 5 Preemption is not helpful for scheduling."
0.2676,Event,ADDED,eval-sanitize-30-r2-038-mmdbm.18d4f800c8ef6c73,"reason=FailedScheduling count=None msg=0/6 nodes are available: 1 c_wall violated: 1 conflicting context pair(s) with node memory, 1 c_wall violated: 2 conflicting context pair(s) with node memory, 4 node(s) had untolerated taint(s). no new claims to deallocate, preemption: 0/6 nodes are available: 2 No preemption victims found for incoming pod, 4 Preemption is not helpful for scheduling."
0.2678,Event,ADDED,eval-sanitize-30-r2-038-mmdbm.18d4f80110a367a1,"reason=FailedScheduling count=None msg=0/6 nodes are available: 1 c_wall violated: 2 conflicting context pair(s) with node memory, 2 c_wall violated: 1 conflicting context pair(s) with node memory, 3 node(s) had untolerated taint(s). no new claims to deallocate, preemption: 0/6 nodes are available: 3 No preemption victims found for incoming pod, 3 Preemption is not helpful for scheduling."
0.268,Event,ADDED,eval-sanitize-30-r2-038-mmdbm.18d4f8015ee42912,reason=Scheduled count=None msg=Successfully assigned compute/eval-sanitize-30-r2-038-mmdbm to kind-worker5
0.2681,Event,ADDED,eval-sanitize-30-r2-038-mmdbm.18d4f8018d0064b0,"reason=Pulled count=1 msg=Container image ""busybox:musl"" already present on machine"
0.2684,Event,ADDED,eval-sanitize-30-r2-038-mmdbm.18d4f8018ef20eb1,reason=Created count=1 msg=Created container: task
0.2685,Event,ADDED,eval-sanitize-30-r2-038-mmdbm.18d4f80196e791ef,reason=Started count=1 msg=Started container task
0.2689,Event,ADDED,eval-sanitize-30-r2-038.18d4f7fd7b52df5f,reason=SuccessfulCreate count=1 msg=Created pod: eval-sanitize-30-r2-038-mmdbm
0.2692,Event,ADDED,eval-sanitize-30-r2-038.18d4f809065f4ff1,reason=Completed count=1 msg=Job completed
0.2696,Event,ADDED,eval-sanitize-30-r2-039-w494g.18d4f7fdb41a77f0,"reason=FailedScheduling count=None msg=0/6 nodes are available: 6 node(s) had untolerated taint(s). no new claims to deallocate, preemption: 0/6 nodes are available: 6 Preemption is not helpful for scheduling."
0.2698,Event,ADDED,eval-sanitize-30-r2-039-w494g.18d4f8008ce0f270,"reason=FailedScheduling count=None msg=0/6 nodes are available: 1 c_wall violated: 3 conflicting context pair(s) with node memory, 5 node(s) had untolerated taint(s). no new claims to deallocate, preemption: 0/6 nodes are available: 1 No preemption victims found for incoming pod, 5 Preemption is not helpful for scheduling."
0.27,Event,ADDED,eval-sanitize-30-r2-039-w494g.18d4f800cee3c674,reason=Scheduled count=None msg=Successfully assigned compute/eval-sanitize-30-r2-039-w494g to kind-worker4
0.2702,Event,ADDED,eval-sanitize-30-r2-039-w494g.18d4f800eb742dba,"reason=Pulled count=1 msg=Container image ""busybox:musl"" already present on machine"
0.2704,Event,ADDED,eval-sanitize-30-r2-039-w494g.18d4f800ed667acc,reason=Created count=1 msg=Created container: task
0.2706,Event,ADDED,eval-sanitize-30-r2-039-w494g.18d4f800f55fa85b,reason=Started count=1 msg=Started container task
0.2708,Event,ADDED,eval-sanitize-30-r2-039.18d4f7fdb416a027,reason=SuccessfulCreate count=1 msg=Created pod: eval-sanitize-30-r2-039-w494g
0.2711,Event,ADDED,eval-sanitize-30-r2-039.18d4f8080c099f8a,reason=Completed count=1 msg=Job completed
0.2712,Event,ADDED,eval-sanitize-30-r2-040-zjnhx.18d4f7fdefce4a64,"reason=FailedScheduling count=None msg=0/6 nodes are available: 6 node(s) had untolerated taint(s). no new claims to deallocate, preemption: 0/6 nodes are available: 6 Preemption is not helpful for scheduling."
0.2714,Event,ADDED,eval-sanitize-30-r2-040-zjnhx.18d4f8008dfd0a07,reason=Scheduled count=None msg=Successfully assigned compute/eval-sanitize-30-r2-040-zjnhx to kind-worker
0.2717,Event,ADDED,eval-sanitize-30-r2-040-zjnhx.18d4f800aca2d1a9,"reason=Pulled count=1 msg=Container image ""busybox:musl"" already present on machine"
0.2719,Event,ADDED,eval-sanitize-30-r2-040-zjnhx.18d4f800ae86bf30,reason=Created count=1 msg=Created container: task
0.2721,Event,ADDED,eval-sanitize-30-r2-040-zjnhx.18d4f800b17e8138,reason=Started count=1 msg=Started container task
0.2722,Event,ADDED,eval-sanitize-30-r2-040.18d4f7fdefc244bb,reason=SuccessfulCreate count=1 msg=Created pod: eval-sanitize-30-r2-040-zjnhx
0.2725,Event,ADDED,eval-sanitize-30-r2-040.18d4f805e8f55637,reason=Completed count=1 msg=Job completed
0.2726,Event,ADDED,eval-sanitize-30-r2-041-2xr4p.18d4f7fe2b870794,"reason=FailedScheduling count=None msg=0/6 nodes are available: 6 node(s) had untolerated taint(s). no new claims to deallocate, preemption: 0/6 nodes are available: 6 Preemption is not helpful for scheduling."
0.2728,Event,ADDED,eval-sanitize-30-r2-041-2xr4p.18d4f8008dd8e6c3,"reason=FailedScheduling count=None msg=0/6 nodes are available: 1 c_wall violated: 1 conflicting context pair(s) with node memory, 5 node(s) had untolerated taint(s). no new claims to deallocate, preemption: 0/6 nodes are available: 1 No preemption victims found for incoming pod, 5 Preemption is not helpful for scheduling."
0.2731,Event,ADDED,eval-sanitize-30-r2-041-2xr4p.18d4f800ceed454f,"reason=FailedScheduling count=None msg=0/6 nodes are available: 1 c_wall violated: 1 conflicting context pair(s) with node memory, 1 c_wall violated: 2 conflicting context pair(s) with node memory, 4 node(s) had untolerated taint(s). no new claims to deallocate, preemption: 0/6 nodes are available: 2 No preemption victims found for incoming pod, 4 Preemption is not helpful for scheduling."
0.2733,Event,ADDED,eval-sanitize-30-r2-041-2xr4p.18d4f80116543eb2,"reason=FailedScheduling count=None msg=0/6 nodes are available: 1 c_wall violated: 2 conflicting context pair(s) with node memory, 2 c_wall violated: 1 conflicting context pair(s) with node memory, 3 node(s) had untolerated taint(s). no new claims to deallocate, preemption: 0/6 nodes are available: 3 No preemption victims found for incoming pod, 3 Preemption is not helpful for scheduling."
0.2734,Event,ADDED,eval-sanitize-30-r2-041-2xr4p.18d4f80171fe0b8b,reason=Scheduled count=None msg=Successfully assigned compute/eval-sanitize-30-r2-041-2xr4p to kind-worker2
0.2737,Event,ADDED,eval-sanitize-30-r2-041-2xr4p.18d4f8018dfda09c,"reason=Pulled count=1 msg=Container image ""busybox:musl"" already present on machine"
0.2739,Event,ADDED,eval-sanitize-30-r2-041-2xr4p.18d4f8018fefcea9,reason=Created count=1 msg=Created container: task
0.2742,Event,ADDED,eval-sanitize-30-r2-041-2xr4p.18d4f80196bd5e51,reason=Started count=1 msg=Started container task
0.2744,Event,ADDED,eval-sanitize-30-r2-041.18d4f7fe2b7b79d9,reason=SuccessfulCreate count=1 msg=Created pod: eval-sanitize-30-r2-041-2xr4p
0.2746,Event,ADDED,eval-sanitize-30-r2-041.18d4f808fe41b639,reason=Completed count=1 msg=Job completed
0.275,Event,ADDED,eval-sanitize-30-r2-042-mqrsk.18d4f7fe6aabb54b,"reason=FailedScheduling count=None msg=0/6 nodes are available: 6 node(s) had untolerated taint(s). no new claims to deallocate, preemption: 0/6 nodes are available: 6 Preemption is not helpful for scheduling."
0.2753,Event,ADDED,eval-sanitize-30-r2-042-mqrsk.18d4f80091008a87,"reason=FailedScheduling count=None msg=0/6 nodes are available: 1 c_wall violated: 2 conflicting context pair(s) with node memory, 5 node(s) had untolerated taint(s). no new claims to deallocate, preemption: 0/6 nodes are available: 1 No preemption victims found for incoming pod, 5 Preemption is not helpful for scheduling."
0.2756,Event,ADDED,eval-sanitize-30-r2-042-mqrsk.18d4f800d46a147a,"reason=FailedScheduling count=None msg=0/6 nodes are available: 2 c_wall violated: 2 conflicting context pair(s) with node memory, 4 node(s) had untolerated taint(s). no new claims to deallocate, preemption: 0/6 nodes are available: 2 No preemption victims found for incoming pod, 4 Preemption is not helpful for scheduling."
0.2758,Event,ADDED,eval-sanitize-30-r2-042-mqrsk.18d4f8011daa4776,reason=Scheduled count=None msg=Successfully assigned compute/eval-sanitize-30-r2-042-mqrsk to kind-worker5
0.276,Event,ADDED,eval-sanitize-30-r2-042-mqrsk.18d4f8014159c146,"reason=Pulled count=1 msg=Container image ""busybox:musl"" already present on machine"
0.2763,Event,ADDED,eval-sanitize-30-r2-042-mqrsk.18d4f80142caed46,reason=Created count=1 msg=Created container: task
0.2766,Event,ADDED,eval-sanitize-30-r2-042-mqrsk.18d4f8014c641beb,reason=Started count=1 msg=Started container task
0.2768,Event,ADDED,eval-sanitize-30-r2-042.18d4f7fe6aa1d94f,reason=SuccessfulCreate count=1 msg=Created pod: eval-sanitize-30-r2-042-mqrsk
0.277,Event,ADDED,eval-sanitize-30-r2-042.18d4f808b2cbf5e2,reason=Completed count=1 msg=Job completed
0.2771,Event,ADDED,eval-sanitize-30-r2-043-kfd48.18d4f7fea28c46e0,"reason=FailedScheduling count=None msg=0/6 nodes are available: 6 node(s) had untolerated taint(s). no new claims to deallocate, preemption: 0/6 nodes are available: 6 Preemption is not helpful for scheduling."
0.2773,Event,ADDED,eval-sanitize-30-r2-043-kfd48.18d4f80096e6f2cc,reason=Scheduled count=None msg=Successfully assigned compute/eval-sanitize-30-r2-043-kfd48 to kind-worker4
0.2775,Event,ADDED,eval-sanitize-30-r2-043-kfd48.18d4f800b0adf5c2,"reason=Pulled count=1 msg=Container image ""busybox:musl"" already present on machine"
0.2777,Event,ADDED,eval-sanitize-30-r2-043-kfd48.18d4f800b44f9efa,reason=Created count=1 msg=Created container: task
0.2779,Event,ADDED,eval-sanitize-30-r2-043-kfd48.18d4f800b9eb7e87,reason=Started count=1 msg=Started container task
0.2781,Event,ADDED,eval-sanitize-30-r2-043.18d4f7fea289ba7a,reason=SuccessfulCreate count=1 msg=Created pod: eval-sanitize-30-r2-043-kfd48
0.2783,Event,ADDED,eval-sanitize-30-r2-043.18d4f807302542ba,reason=Completed count=1 msg=Job completed
0.2785,Event,ADDED,eval-sanitize-30-r2-044-n2c7g.18d4f7feded9e3ee,"reason=FailedScheduling count=None msg=0/6 nodes are available: 6 node(s) had untolerated taint(s). no new claims to deallocate, preemption: 0/6 nodes are available: 6 Preemption is not helpful for scheduling."
0.2789,Event,ADDED,eval-sanitize-30-r2-044-n2c7g.18d4f80097af307b,reason=Scheduled count=None msg=Successfully assigned compute/eval-sanitize-30-r2-044-n2c7g to kind-worker4
0.279,Event,ADDED,eval-sanitize-30-r2-044-n2c7g.18d4f800b2289fee,"reason=Pulled count=1 msg=Container image ""busybox:musl"" already present on machine"
0.2792,Event,ADDED,eval-sanitize-30-r2-044-n2c7g.18d4f800b59439ec,reason=Created count=1 msg=Created container: task
0.2795,Event,ADDED,eval-sanitize-30-r2-044-n2c7g.18d4f800ba7bb86f,reason=Started count=1 msg=Started container task
0.2796,Event,ADDED,eval-sanitize-30-r2-044.18d4f7feded19e5c,reason=SuccessfulCreate count=1 msg=Created pod: eval-sanitize-30-r2-044-n2c7g
0.2798,Event,ADDED,eval-sanitize-30-r2-044.18d4f8073e377d3e,reason=Completed count=1 msg=Job completed
0.28,Event,ADDED,eval-sanitize-30-r2-045-ncmlk.18d4f7ff19dc5c4e,"reason=FailedScheduling count=None msg=0/6 nodes are available: 6 node(s) had untolerated taint(s). no new claims to deallocate, preemption: 0/6 nodes are available: 6 Preemption is not helpful for scheduling."
0.2802,Event,ADDED,eval-sanitize-30-r2-045-ncmlk.18d4f80097f0b370,reason=Scheduled count=None msg=Successfully assigned compute/eval-sanitize-30-r2-045-ncmlk to kind-worker
0.2805,Event,ADDED,eval-sanitize-30-r2-045-ncmlk.18d4f800b2044f30,"reason=Pulled count=1 msg=Container image ""busybox:musl"" already present on machine"
0.2808,Event,ADDED,eval-sanitize-30-r2-045-ncmlk.18d4f800b41ba9f0,reason=Created count=1 msg=Created container: task
0.281,Event,ADDED,eval-sanitize-30-r2-045-ncmlk.18d4f800b96880f8,reason=Started count=1 msg=Started container task
0.2813,Event,ADDED,eval-sanitize-30-r2-045.18d4f7ff19cc67f6,reason=SuccessfulCreate count=1 msg=Created pod: eval-sanitize-30-r2-045-ncmlk
0.2815,Event,ADDED,eval-sanitize-30-r2-045.18d4f808048a4c17,reason=Completed count=1 msg=Job completed
0.2817,Event,ADDED,eval-sanitize-30-r2-046-bv2xj.18d4f7ff5559d644,"reason=FailedScheduling count=None msg=0/6 nodes are available: 6 node(s) had untolerated taint(s). no new claims to deallocate, preemption: 0/6 nodes are available: 6 Preemption is not helpful for scheduling."
0.2819,Event,ADDED,eval-sanitize-30-r2-046-bv2xj.18d4f8009a1ce51c,"reason=FailedScheduling count=None msg=0/6 nodes are available: 2 c_wall violated: 2 conflicting context pair(s) with node memory, 4 node(s) had untolerated taint(s). no new claims to deallocate, preemption: 0/6 nodes are available: 2 No preemption victims found for incoming pod, 4 Preemption is not helpful for scheduling."
0.282,Event,ADDED,eval-sanitize-30-r2-046-bv2xj.18d4f800d5d770e2,reason=Scheduled count=None msg=Successfully assigned compute/eval-sanitize-30-r2-046-bv2xj to kind-worker3
0.2822,Event,ADDED,eval-sanitize-30-r2-046-bv2xj.18d4f800f58a9845,"reason=Pulled count=1 msg=Container image ""busybox:musl"" already present on machine"
0.2823,Event,ADDED,eval-sanitize-30-r2-046-bv2xj.18d4f800f77aafef,reason=Created count=1 msg=Created container: task
0.2826,Event,ADDED,eval-sanitize-30-r2-046-bv2xj.18d4f800fc01be51,reason=Started count=1 msg=Started container task
0.2828,Event,ADDED,eval-sanitize-30-r2-046.18d4f7ff554dc857,reason=SuccessfulCreate count=1 msg=Created pod: eval-sanitize-30-r2-046-bv2xj
0.283,Event,ADDED,eval-sanitize-30-r2-046.18d4f807a8a30058,reason=Completed count=1 msg=Job completed
0.2832,Event,ADDED,eval-sanitize-30-r2-047-4xqwx.18d4f7ff91053691,"reason=FailedScheduling count=None msg=0/6 nodes are available: 6 node(s) had untolerated taint(s). no new claims to deallocate, preemption: 0/6 nodes are available: 6 Preemption is not helpful for scheduling."
0.2834,Event,ADDED,eval-sanitize-30-r2-047-4xqwx.18d4f8009ead1682,reason=Scheduled count=None msg=Successfully assigned compute/eval-sanitize-30-r2-047-4xqwx to kind-worker4
0.2835,Event,ADDED,eval-sanitize-30-r2-047-4xqwx.18d4f800bb843f2d,"reason=Pulled count=1 msg=Container image ""busybox:musl"" already present on machine"
0.2837,Event,ADDED,eval-sanitize-30-r2-047-4xqwx.18d4f800bdcd6205,reason=Created count=1 msg=Created container: task
0.2844,Event,ADDED,eval-sanitize-30-r2-047-4xqwx.18d4f800c2549a5e,reason=Started count=1 msg=Started container task
0.2846,Event,ADDED,eval-sanitize-30-r2-047.18d4f7ff90fa2d58,reason=SuccessfulCreate count=1 msg=Created pod: eval-sanitize-30-r2-047-4xqwx
0.2848,Event,ADDED,eval-sanitize-30-r2-047.18d4f8079dc5e614,reason=Completed count=1 msg=Job completed
0.2849,Event,ADDED,eval-sanitize-30-r2-048-bqn89.18d4f7ffce29fd28,"reason=FailedScheduling count=None msg=0/6 nodes are available: 6 node(s) had untolerated taint(s). no new claims to deallocate, preemption: 0/6 nodes are available: 6 Preemption is not helpful for scheduling."
0.2852,Event,ADDED,eval-sanitize-30-r2-048-bqn89.18d4f8009f7f625d,reason=Scheduled count=None msg=Successfully assigned compute/eval-sanitize-30-r2-048-bqn89 to kind-worker4
0.2853,Event,ADDED,eval-sanitize-30-r2-048-bqn89.18d4f800bbf333b1,"reason=Pulled count=1 msg=Container image ""busybox:musl"" already present on machine"
0.2855,Event,ADDED,eval-sanitize-30-r2-048-bqn89.18d4f800be872b44,reason=Created count=1 msg=Created container: task
0.2857,Event,ADDED,eval-sanitize-30-r2-048-bqn89.18d4f800c29a895a,reason=Started count=1 msg=Started container task
0.2859,Event,ADDED,eval-sanitize-30-r2-048.18d4f7ffce1e110b,reason=SuccessfulCreate count=1 msg=Created pod: eval-sanitize-30-r2-048-bqn89
0.286,Event,ADDED,eval-sanitize-30-r2-048.18d4f80883413498,reason=Completed count=1 msg=Job completed
0.2863,Event,ADDED,eval-sanitize-30-r2-049-r4tbw.18d4f800082a6363,"reason=FailedScheduling count=None msg=0/6 nodes are available: 6 node(s) had untolerated taint(s). no new claims to deallocate, preemption: 0/6 nodes are available: 6 Preemption is not helpful for scheduling."
0.2866,Event,ADDED,eval-sanitize-30-r2-049-r4tbw.18d4f800a2d427d4,reason=Scheduled count=None msg=Successfully assigned compute/eval-sanitize-30-r2-049-r4tbw to kind-worker
0.287,Event,ADDED,eval-sanitize-30-r2-049-r4tbw.18d4f800bd3a7b86,"reason=Pulled count=1 msg=Container image ""busybox:musl"" already present on machine"
0.2873,Event,ADDED,eval-sanitize-30-r2-049-r4tbw.18d4f800bf34fc86,reason=Created count=1 msg=Created container: task
0.2876,Event,ADDED,eval-sanitize-30-r2-049-r4tbw.18d4f800c43da7d3,reason=Started count=1 msg=Started container task
0.2878,Event,ADDED,eval-sanitize-30-r2-049.18d4f8000825e6dc,reason=SuccessfulCreate count=1 msg=Created pod: eval-sanitize-30-r2-049-r4tbw
0.2879,Event,ADDED,eval-sanitize-30-r2-049.18d4f8080653a7be,reason=Completed count=1 msg=Job completed
0.2881,Event,ADDED,eval-sanitize-30-r2-050-2d8ms.18d4f800451a6309,"reason=FailedScheduling count=None msg=0/6 nodes are available: 6 node(s) had untolerated taint(s). no new claims to deallocate, preemption: 0/6 nodes are available: 6 Preemption is not helpful for scheduling."
0.2884,Event,ADDED,eval-sanitize-30-r2-050-2d8ms.18d4f800a50f4416,"reason=FailedScheduling count=None msg=0/6 nodes are available: 2 c_wall violated: 2 conflicting context pair(s) with node memory, 4 node(s) had untolerated taint(s). no new claims to deallocate, preemption: 0/6 nodes are available: 2 No preemption victims found for incoming pod, 4 Preemption is not helpful for scheduling."
0.2886,Event,ADDED,eval-sanitize-30-r2-050-2d8ms.18d4f800db5aced6,reason=Scheduled count=None msg=Successfully assigned compute/eval-sanitize-30-r2-050-2d8ms to kind-worker3
0.2888,Event,ADDED,eval-sanitize-30-r2-050-2d8ms.18d4f800fc07d121,"reason=Pulled count=1 msg=Container image ""busybox:musl"" already present on machine"
0.289,Event,ADDED,eval-sanitize-30-r2-050-2d8ms.18d4f8010177faff,reason=Created count=1 msg=Created container: task
0.2893,Event,ADDED,eval-sanitize-30-r2-050-2d8ms.18d4f801061b2766,reason=Started count=1 msg=Started container task
0.2895,Event,ADDED,eval-sanitize-30-r2-050.18d4f80045112ade,reason=SuccessfulCreate count=1 msg=Created pod: eval-sanitize-30-r2-050-2d8ms
0.2897,Event,ADDED,eval-sanitize-30-r2-050.18d4f80841eac43d,reason=Completed count=1 msg=Job completed
0.29,Event,ADDED,eval-sanitize-30-r2-051-sl2v5.18d4f800a519853a,reason=Scheduled count=None msg=Successfully assigned compute/eval-sanitize-30-r2-051-sl2v5 to kind-worker
0.2902,Event,ADDED,eval-sanitize-30-r2-051-sl2v5.18d4f800c1b04f10,"reason=Pulled count=1 msg=Container image ""busybox:musl"" already present on machine"
0.2904,Event,ADDED,eval-sanitize-30-r2-051-sl2v5.18d4f800c3b4e327,reason=Created count=1 msg=Created container: task
0.2905,Event,ADDED,eval-sanitize-30-r2-051-sl2v5.18d4f800cc9afb5c,reason=Started count=1 msg=Started container task
0.2908,Event,ADDED,eval-sanitize-30-r2-051.18d4f80080194131,reason=SuccessfulCreate count=1 msg=Created pod: eval-sanitize-30-r2-051-sl2v5
0.291,Event,ADDED,eval-sanitize-30-r2-051.18d4f807d690587f,reason=Completed count=1 msg=Job completed
0.2911,Event,ADDED,eval-sanitize-30-r2-052-5r55g.18d4f800c2b84d3e,"reason=FailedScheduling count=None msg=0/6 nodes are available: 1 c_wall violated: 1 conflicting context pair(s) with node memory, 1 c_wall violated: 2 conflicting context pair(s) with node memory, 4 node(s) had untolerated taint(s). no new claims to deallocate, preemption: 0/6 nodes are available: 2 No preemption victims found for incoming pod, 4 Preemption is not helpful for scheduling."
0.2914,Event,ADDED,eval-sanitize-30-r2-052-5r55g.18d4f8010b5c55ba,"reason=FailedScheduling count=None msg=0/6 nodes are available: 1 c_wall violated: 2 conflicting context pair(s) with node memory, 2 c_wall violated: 1 conflicting context pair(s) with node memory, 3 node(s) had untolerated taint(s). no new claims to deallocate, preemption: 0/6 nodes are available: 3 No preemption victims found for incoming pod, 3 Preemption is not helpful for scheduling."
0.2916,Event,ADDED,eval-sanitize-30-r2-052-5r55g.18d4f8015bbbd336,reason=Scheduled count=None msg=Successfully assigned compute/eval-sanitize-30-r2-052-5r55g to kind-worker2
0.2918,Event,ADDED,eval-sanitize-30-r2-052-5r55g.18d4f8017aca56d0,"reason=Pulled count=1 msg=Container image ""busybox:musl"" already present on machine"
0.2921,Event,ADDED,eval-sanitize-30-r2-052-5r55g.18d4f8017c5b219c,reason=Created count=1 msg=Created container: task
0.2927,Event,ADDED,eval-sanitize-30-r2-052-5r55g.18d4f80181c9610e,reason=Started count=1 msg=Started container task
0.2931,Event,ADDED,eval-sanitize-30-r2-052.18d4f800bcb88a77,reason=SuccessfulCreate count=1 msg=Created pod: eval-sanitize-30-r2-052-5r55g
0.2936,Event,ADDED,eval-sanitize-30-r2-052.18d4f808eecea96d,reason=Completed count=1 msg=Job completed
0.294,Event,ADDED,eval-sanitize-30-r2-053-c69tt.18d4f8010199d840,reason=Scheduled count=None msg=Successfully assigned compute/eval-sanitize-30-r2-053-c69tt to kind-worker4
0.2943,Event,ADDED,eval-sanitize-30-r2-053-c69tt.18d4f8012d966a0b,"reason=Pulled count=1 msg=Container image ""busybox:musl"" already present on machine"
0.2946,Event,ADDED,eval-sanitize-30-r2-053-c69tt.18d4f8012ec7df05,reason=Created count=1 msg=Created container: task
0.2949,Event,ADDED,eval-sanitize-30-r2-053-c69tt.18d4f80136af8488,reason=Started count=1 msg=Started container task
0.2953,Event,ADDED,eval-sanitize-30-r2-053.18d4f800f7c4e776,reason=SuccessfulCreate count=1 msg=Created pod: eval-sanitize-30-r2-053-c69tt
0.2957,Event,ADDED,eval-sanitize-30-r2-053.18d4f808121f0c6a,reason=Completed count=1 msg=Job completed
0.2958,Event,ADDED,eval-sanitize-30-r2-054-wztsh.18d4f8014fb1c805,reason=Scheduled count=None msg=Successfully assigned compute/eval-sanitize-30-r2-054-wztsh to kind-worker3
0.296,Event,ADDED,eval-sanitize-30-r2-054-wztsh.18d4f80171f16c82,"reason=Pulled count=1 msg=Container image ""busybox:musl"" already present on machine"
0.2965,Event,ADDED,eval-sanitize-30-r2-054-wztsh.18d4f801749d76fb,reason=Created count=1 msg=Created container: task
0.2967,Event,ADDED,eval-sanitize-30-r2-054-wztsh.18d4f801797f65ee,reason=Started count=1 msg=Started container task
0.2969,Event,ADDED,eval-sanitize-30-r2-054.18d4f8013a7a0529,reason=SuccessfulCreate count=1 msg=Created pod: eval-sanitize-30-r2-054-wztsh
0.2971,Event,ADDED,eval-sanitize-30-r2-054.18d4f809007d6e57,reason=Completed count=1 msg=Job completed
0.2973,Event,ADDED,eval-sanitize-30-r2-055-mbxnk.18d4f8017be9536c,reason=Scheduled count=None msg=Successfully assigned compute/eval-sanitize-30-r2-055-mbxnk to kind-worker2
0.2975,Event,ADDED,eval-sanitize-30-r2-055-mbxnk.18d4f8019df722e0,"reason=Pulled count=1 msg=Container image ""busybox:musl"" already present on machine"
0.2977,Event,ADDED,eval-sanitize-30-r2-055-mbxnk.18d4f8019f3a8541,reason=Created count=1 msg=Created container: task
0.298,Event,ADDED,eval-sanitize-30-r2-055-mbxnk.18d4f801a4f5d014,reason=Started count=1 msg=Started container task
0.2985,Event,ADDED,eval-sanitize-30-r2-055.18d4f801760cd2a5,reason=SuccessfulCreate count=1 msg=Created pod: eval-sanitize-30-r2-055-mbxnk
0.2991,Event,ADDED,eval-sanitize-30-r2-055.18d4f808d1bbd064,reason=Completed count=1 msg=Job completed
0.2993,Event,ADDED,eval-sanitize-30-r2-056-8mt2t.18d4f801b2445b7a,reason=Scheduled count=None msg=Successfully assigned compute/eval-sanitize-30-r2-056-8mt2t to kind-worker2
0.2996,Event,ADDED,eval-sanitize-30-r2-056-8mt2t.18d4f801cf1fe5c3,"reason=Pulled count=1 msg=Container image ""busybox:musl"" already present on machine"
0.2998,Event,ADDED,eval-sanitize-30-r2-056-8mt2t.18d4f801d06d3092,reason=Created count=1 msg=Created container: task
0.3001,Event,ADDED,eval-sanitize-30-r2-056-8mt2t.18d4f801d7b25c85,reason=Started count=1 msg=Started container task
0.3004,Event,ADDED,eval-sanitize-30-r2-056.18d4f801a9cecfd7,reason=SuccessfulCreate count=1 msg=Created pod: eval-sanitize-30-r2-056-8mt2t
0.303,Event,ADDED,eval-sanitize-30-r2-056.18d4f809124e80c5,reason=Completed count=1 msg=Job completed
0.3032,Event,ADDED,eval-sanitize-30-r2-057-zsq42.18d4f801eda35b39,reason=Scheduled count=None msg=Successfully assigned compute/eval-sanitize-30-r2-057-zsq42 to kind-worker2
0.3034,Event,ADDED,eval-sanitize-30-r2-057-zsq42.18d4f802095223bf,"reason=Pulled count=1 msg=Container image ""busybox:musl"" already present on machine"
0.3037,Event,ADDED,eval-sanitize-30-r2-057-zsq42.18d4f8020ab2c02e,reason=Created count=1 msg=Created container: task
0.3042,Event,ADDED,eval-sanitize-30-r2-057-zsq42.18d4f80212935d89,reason=Started count=1 msg=Started container task
0.3047,Event,ADDED,eval-sanitize-30-r2-057.18d4f801e9cd11b8,reason=SuccessfulCreate count=1 msg=Created pod: eval-sanitize-30-r2-057-zsq42
0.305,Event,ADDED,eval-sanitize-30-r2-057.18d4f8092d23d347,reason=Completed count=1 msg=Job completed
0.3052,Event,ADDED,eval-sanitize-30-r2-058-84b4k.18d4f80229220762,reason=Scheduled count=None msg=Successfully assigned compute/eval-sanitize-30-r2-058-84b4k to kind-worker5
0.3054,Event,ADDED,eval-sanitize-30-r2-058-84b4k.18d4f8024b2893f8,"reason=Pulled count=1 msg=Container image ""busybox:musl"" already present on machine"
0.3057,Event,ADDED,eval-sanitize-30-r2-058-84b4k.18d4f8024c66af2b,reason=Created count=1 msg=Created container: task
0.306,Event,ADDED,eval-sanitize-30-r2-058-84b4k.18d4f8025371e334,reason=Started count=1 msg=Started container task
0.3062,Event,ADDED,eval-sanitize-30-r2-058.18d4f8022231ad5b,reason=SuccessfulCreate count=1 msg=Created pod: eval-sanitize-30-r2-058-84b4k
0.3064,Event,ADDED,eval-sanitize-30-r2-058.18d4f8094b2a2125,reason=Completed count=1 msg=Job completed
0.3066,Event,ADDED,eval-sanitize-30-r2-059-wfkb5.18d4f802646b6cff,reason=Scheduled count=None msg=Successfully assigned compute/eval-sanitize-30-r2-059-wfkb5 to kind-worker4
0.3069,Event,ADDED,eval-sanitize-30-r2-059-wfkb5.18d4f80284a6b64b,"reason=Pulled count=1 msg=Container image ""busybox:musl"" already present on machine"
0.3071,Event,ADDED,eval-sanitize-30-r2-059-wfkb5.18d4f80285eea401,reason=Created count=1 msg=Created container: task
0.3072,Event,ADDED,eval-sanitize-30-r2-059-wfkb5.18d4f8028f1e19d3,reason=Started count=1 msg=Started container task
0.3074,Event,ADDED,eval-sanitize-30-r2-059.18d4f80261c8d2bd,reason=SuccessfulCreate count=1 msg=Created pod: eval-sanitize-30-r2-059-wfkb5
0.3077,Event,ADDED,eval-sanitize-30-r2-059.18d4f8094e07148d,reason=Completed count=1 msg=Job completed
0.3079,Event,ADDED,eval-sanitize-30-r2-060-g4wdf.18d4f802ac35b58c,reason=Scheduled count=None msg=Successfully assigned compute/eval-sanitize-30-r2-060-g4wdf to kind-worker4
0.3081,Event,ADDED,eval-sanitize-30-r2-060-g4wdf.18d4f802c8e0d2fd,"reason=Pulled count=1 msg=Container image ""busybox:musl"" already present on machine"
0.3083,Event,ADDED,eval-sanitize-30-r2-060-g4wdf.18d4f802ca2eedff,reason=Created count=1 msg=Created container: task
0.3084,Event,ADDED,eval-sanitize-30-r2-060-g4wdf.18d4f802cd1f8e08,reason=Started count=1 msg=Started container task
0.3086,Event,ADDED,eval-sanitize-30-r2-060.18d4f802a1a925b3,reason=SuccessfulCreate count=1 msg=Created pod: eval-sanitize-30-r2-060-g4wdf
0.3088,Event,ADDED,eval-sanitize-30-r2-060.18d4f80965f066d1,reason=Completed count=1 msg=Job completed
0.309,Event,ADDED,eval-sanitize-30-r2-061-rknmq.18d4f802dba37c75,reason=Scheduled count=None msg=Successfully assigned compute/eval-sanitize-30-r2-061-rknmq to kind-worker4
0.3092,Event,ADDED,eval-sanitize-30-r2-061-rknmq.18d4f8030117cb56,"reason=Pulled count=1 msg=Container image ""busybox:musl"" already present on machine"
0.3093,Event,ADDED,eval-sanitize-30-r2-061-rknmq.18d4f8030275f205,reason=Created count=1 msg=Created container: task
0.3095,Event,ADDED,eval-sanitize-30-r2-061-rknmq.18d4f80307b47567,reason=Started count=1 msg=Started container task
0.3101,Event,ADDED,eval-sanitize-30-r2-061.18d4f802d6893afb,reason=SuccessfulCreate count=1 msg=Created pod: eval-sanitize-30-r2-061-rknmq
0.3104,Event,ADDED,eval-sanitize-30-r2-061.18d4f8097a8b2177,reason=Completed count=1 msg=Job completed
0.3107,Event,ADDED,eval-sanitize-30-r2-062-gqr2f.18d4f8031a05f590,reason=Scheduled count=None msg=Successfully assigned compute/eval-sanitize-30-r2-062-gqr2f to kind-worker4
0.311,Event,ADDED,eval-sanitize-30-r2-062-gqr2f.18d4f803362b44a4,"reason=Pulled count=1 msg=Container image ""busybox:musl"" already present on machine"
0.3112,Event,ADDED,eval-sanitize-30-r2-062-gqr2f.18d4f8033773bb16,reason=Created count=1 msg=Created container: task
0.3113,Event,ADDED,eval-sanitize-30-r2-062-gqr2f.18d4f8033cd2c248,reason=Started count=1 msg=Started container task
0.3115,Event,ADDED,eval-sanitize-30-r2-062.18d4f80312d2f527,reason=SuccessfulCreate count=1 msg=Created pod: eval-sanitize-30-r2-062-gqr2f
0.3118,Event,ADDED,eval-sanitize-30-r2-062.18d4f80990606f84,reason=Completed count=1 msg=Job completed
0.312,Event,ADDED,eval-sanitize-30-r2-063-dtz2v.18d4f8035697f0d5,reason=Scheduled count=None msg=Successfully assigned compute/eval-sanitize-30-r2-063-dtz2v to kind-worker4
0.3122,Event,ADDED,eval-sanitize-30-r2-063-dtz2v.18d4f8037e37442d,"reason=Pulled count=1 msg=Container image ""busybox:musl"" already present on machine"
0.3123,Event,ADDED,eval-sanitize-30-r2-063-dtz2v.18d4f8037fedd167,reason=Created count=1 msg=Created container: task
0.3126,Event,ADDED,eval-sanitize-30-r2-063-dtz2v.18d4f8038919e505,reason=Started count=1 msg=Started container task
0.3127,Event,ADDED,eval-sanitize-30-r2-063.18d4f8034c2032ac,reason=SuccessfulCreate count=1 msg=Created pod: eval-sanitize-30-r2-063-dtz2v
0.3129,Event,ADDED,eval-sanitize-30-r2-063.18d4f8099b56cea4,reason=Completed count=1 msg=Job completed
0.3131,Event,ADDED,eval-sanitize-30-r2-064-g9mkh.18d4f8038f72bde8,reason=Scheduled count=None msg=Successfully assigned compute/eval-sanitize-30-r2-064-g9mkh to kind-worker5
0.3133,Event,ADDED,eval-sanitize-30-r2-064-g9mkh.18d4f803b7a63fb4,"reason=Pulled count=1 msg=Container image ""busybox:musl"" already present on machine"
0.3135,Event,ADDED,eval-sanitize-30-r2-064-g9mkh.18d4f803b9396c5f,reason=Created count=1 msg=Created container: task
0.3136,Event,ADDED,eval-sanitize-30-r2-064-g9mkh.18d4f803c2cb488f,reason=Started count=1 msg=Started container task
0.3138,Event,ADDED,eval-sanitize-30-r2-064.18d4f8038b0616fa,reason=SuccessfulCreate count=1 msg=Created pod: eval-sanitize-30-r2-064-g9mkh
0.314,Event,ADDED,eval-sanitize-30-r2-064.18d4f809bce13d29,reason=Completed count=1 msg=Job completed
0.3141,Event,ADDED,eval-sanitize-30-r2-065-ljqsn.18d4f803ca12092a,reason=Scheduled count=None msg=Successfully assigned compute/eval-sanitize-30-r2-065-ljqsn to kind-worker2
0.3143,Event,ADDED,eval-sanitize-30-r2-065-ljqsn.18d4f803ecc7c54d,"reason=Pulled count=1 msg=Container image ""busybox:musl"" already present on machine"
0.3145,Event,ADDED,eval-sanitize-30-r2-065-ljqsn.18d4f803ee3d8b14,reason=Created count=1 msg=Created container: task
0.3146,Event,ADDED,eval-sanitize-30-r2-065-ljqsn.18d4f803f2a12bf8,reason=Started count=1 msg=Started container task
0.3148,Event,ADDED,eval-sanitize-30-r2-065.18d4f803c631bd84,reason=SuccessfulCreate count=1 msg=Created pod: eval-sanitize-30-r2-065-ljqsn
0.315,Event,ADDED,eval-sanitize-30-r2-065.18d4f809925a29fd,reason=Completed count=1 msg=Job completed
0.3152,Event,ADDED,eval-sanitize-30-r2-066-2mq9h.18d4f80406edd483,reason=Scheduled count=None msg=Successfully assigned compute/eval-sanitize-30-r2-066-2mq9h to kind-worker
0.3155,Event,ADDED,eval-sanitize-30-r2-066-2mq9h.18d4f80429a47973,"reason=Pulled count=1 msg=Container image ""busybox:musl"" already present on machine"
0.3159,Event,ADDED,eval-sanitize-30-r2-066-2mq9h.18d4f8042b42289d,reason=Created count=1 msg=Created container: task
0.3163,Event,ADDED,eval-sanitize-30-r2-066-2mq9h.18d4f804323c32f8,reason=Started count=1 msg=Started container task
0.3165,Event,ADDED,eval-sanitize-30-r2-066.18d4f803fe837501,reason=SuccessfulCreate count=1 msg=Created pod: eval-sanitize-30-r2-066-2mq9h
0.3167,Event,ADDED,eval-sanitize-30-r2-066.18d4f809b9a60852,reason=Completed count=1 msg=Job completed
0.3169,Event,ADDED,eval-sanitize-30-r2-067-6rrxz.18d4f8044522026a,reason=Scheduled count=None msg=Successfully assigned compute/eval-sanitize-30-r2-067-6rrxz to kind-worker4
0.3171,Event,ADDED,eval-sanitize-30-r2-067-6rrxz.18d4f804654186f4,"reason=Pulled count=1 msg=Container image ""busybox:musl"" already present on machine"
0.3174,Event,ADDED,eval-sanitize-30-r2-067-6rrxz.18d4f80466aff0e4,reason=Created count=1 msg=Created container: task
0.3176,Event,ADDED,eval-sanitize-30-r2-067-6rrxz.18d4f8046e9c7dad,reason=Started count=1 msg=Started container task
0.3178,Event,ADDED,eval-sanitize-30-r2-067.18d4f8043e024748,reason=SuccessfulCreate count=1 msg=Created pod: eval-sanitize-30-r2-067-6rrxz
0.318,Event,ADDED,eval-sanitize-30-r2-067.18d4f80a3caeb246,reason=Completed count=1 msg=Job completed
0.3181,Event,ADDED,eval-sanitize-30-r2-068-sc8lt.18d4f8047ce0e3f9,reason=Scheduled count=None msg=Successfully assigned compute/eval-sanitize-30-r2-068-sc8lt to kind-worker4
0.3183,Event,ADDED,eval-sanitize-30-r2-068-sc8lt.18d4f80498438117,"reason=Pulled count=1 msg=Container image ""busybox:musl"" already present on machine"
0.3185,Event,ADDED,eval-sanitize-30-r2-068-sc8lt.18d4f80499953724,reason=Created count=1 msg=Created container: task
0.3186,Event,ADDED,eval-sanitize-30-r2-068-sc8lt.18d4f804a0b2d675,reason=Started count=1 msg=Started container task
0.3189,Event,ADDED,eval-sanitize-30-r2-068.18d4f80477251ad7,reason=SuccessfulCreate count=1 msg=Created pod: eval-sanitize-30-r2-068-sc8lt
0.3191,Event,ADDED,eval-sanitize-30-r2-068.18d4f80a2e26b967,reason=Completed count=1 msg=Job completed
0.3195,Event,ADDED,eval-sanitize-30-r2-069-8h6qc.18d4f804bad2bed7,reason=Scheduled count=None msg=Successfully assigned compute/eval-sanitize-30-r2-069-8h6qc to kind-worker4
0.3197,Event,ADDED,eval-sanitize-30-r2-069-8h6qc.18d4f804e2ce21ed,"reason=Pulled count=1 msg=Container image ""busybox:musl"" already present on machine"
0.3199,Event,ADDED,eval-sanitize-30-r2-069-8h6qc.18d4f804e4338d40,reason=Created count=1 msg=Created container: task
0.3202,Event,ADDED,eval-sanitize-30-r2-069-8h6qc.18d4f804eb872ba7,reason=Started count=1 msg=Started container task
0.3204,Event,ADDED,eval-sanitize-30-r2-069.18d4f804b0b4e2fa,reason=SuccessfulCreate count=1 msg=Created pod: eval-sanitize-30-r2-069-8h6qc
0.3206,Event,ADDED,eval-sanitize-30-r2-069.18d4f80a62ca1efc,reason=Completed count=1 msg=Job completed
0.3208,Event,ADDED,eval-sanitize-30-r2-070-g29w2.18d4f804fc8580f5,reason=Scheduled count=None msg=Successfully assigned compute/eval-sanitize-30-r2-070-g29w2 to kind-worker2
0.321,Event,ADDED,eval-sanitize-30-r2-070-g29w2.18d4f805237ff918,"reason=Pulled count=1 msg=Container image ""busybox:musl"" already present on machine"
0.3212,Event,ADDED,eval-sanitize-30-r2-070-g29w2.18d4f80524dbdf25,reason=Created count=1 msg=Created container: task
0.3214,Event,ADDED,eval-sanitize-30-r2-070-g29w2.18d4f8052a6b94a8,reason=Started count=1 msg=Started container task
0.3218,Event,ADDED,eval-sanitize-30-r2-070.18d4f804edd80acb,reason=SuccessfulCreate count=1 msg=Created pod: eval-sanitize-30-r2-070-g29w2
0.3221,Event,ADDED,eval-sanitize-30-r2-070.18d4f80aa06b9421,reason=Completed count=1 msg=Job completed
0.3224,Event,ADDED,eval-sanitize-30-r2-071-6lrvb.18d4f8052f1c86f8,reason=Scheduled count=None msg=Successfully assigned compute/eval-sanitize-30-r2-071-6lrvb to kind-worker5
0.3227,Event,ADDED,eval-sanitize-30-r2-071-6lrvb.18d4f8054da2e4f0,"reason=Pulled count=1 msg=Container image ""busybox:musl"" already present on machine"
0.3231,Event,ADDED,eval-sanitize-30-r2-071-6lrvb.18d4f8054efa2f76,reason=Created count=1 msg=Created container: task
0.3233,Event,ADDED,eval-sanitize-30-r2-071-6lrvb.18d4f8055aef239a,reason=Started count=1 msg=Started container task
0.3235,Event,ADDED,eval-sanitize-30-r2-071.18d4f80527f6b9f6,reason=SuccessfulCreate count=1 msg=Created pod: eval-sanitize-30-r2-071-6lrvb
0.3237,Event,ADDED,eval-sanitize-30-r2-071.18d4f80adf836a2b,reason=Completed count=1 msg=Job completed
0.3239,Event,ADDED,eval-sanitize-30-r2-072-z444l.18d4f8057130df1c,reason=Scheduled count=None msg=Successfully assigned compute/eval-sanitize-30-r2-072-z444l to kind-worker5
0.3241,Event,ADDED,eval-sanitize-30-r2-072-z444l.18d4f8058da89a2c,"reason=Pulled count=1 msg=Container image ""busybox:musl"" already present on machine"
0.3243,Event,ADDED,eval-sanitize-30-r2-072-z444l.18d4f8058ef57b5d,reason=Created count=1 msg=Created container: task
0.3244,Event,ADDED,eval-sanitize-30-r2-072-z444l.18d4f80595925e22,reason=Started count=1 msg=Started container task
0.3246,Event,ADDED,eval-sanitize-30-r2-072.18d4f80568031898,reason=SuccessfulCreate count=1 msg=Created pod: eval-sanitize-30-r2-072-z444l
0.3248,Event,ADDED,eval-sanitize-30-r2-072.18d4f80b1b821160,reason=Completed count=1 msg=Job completed
0.3249,Event,ADDED,eval-sanitize-30-r2-073-jzmv5.18d4f805a74b1849,reason=Scheduled count=None msg=Successfully assigned compute/eval-sanitize-30-r2-073-jzmv5 to kind-worker3
0.3252,Event,ADDED,eval-sanitize-30-r2-073-jzmv5.18d4f805cae62921,"reason=Pulled count=1 msg=Container image ""busybox:musl"" already present on machine"
0.3254,Event,ADDED,eval-sanitize-30-r2-073-jzmv5.18d4f805cc9ed769,reason=Created count=1 msg=Created container: task
0.3256,Event,ADDED,eval-sanitize-30-r2-073-jzmv5.18d4f805d32aaa99,reason=Started count=1 msg=Started container task
0.3257,Event,ADDED,eval-sanitize-30-r2-073.18d4f8059fcf3558,reason=SuccessfulCreate count=1 msg=Created pod: eval-sanitize-30-r2-073-jzmv5
0.326,Event,ADDED,eval-sanitize-30-r2-073.18d4f80b5e198439,reason=Completed count=1 msg=Job completed
0.3261,Event,ADDED,eval-sanitize-30-r2-074-fxhh9.18d4f805e2c4b226,reason=Scheduled count=None msg=Successfully assigned compute/eval-sanitize-30-r2-074-fxhh9 to kind-worker
0.3263,Event,ADDED,eval-sanitize-30-r2-074-fxhh9.18d4f805feba6815,"reason=Pulled count=1 msg=Container image ""busybox:musl"" already present on machine"
0.3265,Event,ADDED,eval-sanitize-30-r2-074-fxhh9.18d4f806003ba4b6,reason=Created count=1 msg=Created container: task
0.3267,Event,ADDED,eval-sanitize-30-r2-074-fxhh9.18d4f80604a0c26e,reason=Started count=1 msg=Started container task
0.3269,Event,ADDED,eval-sanitize-30-r2-074.18d4f805dc11771e,reason=SuccessfulCreate count=1 msg=Created pod: eval-sanitize-30-r2-074-fxhh9
0.327,Event,ADDED,eval-sanitize-30-r2-074.18d4f80b8343a54e,reason=Completed count=1 msg=Job completed
0.3272,Event,ADDED,eval-sanitize-30-r2-075-jz5sr.18d4f806243c6ccb,reason=Scheduled count=None msg=Successfully assigned compute/eval-sanitize-30-r2-075-jz5sr to kind-worker
0.3276,Event,ADDED,eval-sanitize-30-r2-075-jz5sr.18d4f806401decb8,"reason=Pulled count=1 msg=Container image ""busybox:musl"" already present on machine"
0.328,Event,ADDED,eval-sanitize-30-r2-075-jz5sr.18d4f80641d3178c,reason=Created count=1 msg=Created container: task
0.3282,Event,ADDED,eval-sanitize-30-r2-075-jz5sr.18d4f8064b40d456,reason=Started count=1 msg=Started container task
0.3285,Event,ADDED,eval-sanitize-30-r2-075.18d4f8061d676eb1,reason=SuccessfulCreate count=1 msg=Created pod: eval-sanitize-30-r2-075-jz5sr
0.3287,Event,ADDED,eval-sanitize-30-r2-075.18d4f80bbf6f886c,reason=Completed count=1 msg=Job completed
0.3289,Event,ADDED,eval-sanitize-30-r2-076-vhhk6.18d4f806bf25b7ed,reason=Scheduled count=None msg=Successfully assigned compute/eval-sanitize-30-r2-076-vhhk6 to kind-worker3
0.3292,Event,ADDED,eval-sanitize-30-r2-076-vhhk6.18d4f806dc991fcc,"reason=Pulled count=1 msg=Container image ""busybox:musl"" already present on machine"
0.3294,Event,ADDED,eval-sanitize-30-r2-076-vhhk6.18d4f806de115fc0,reason=Created count=1 msg=Created container: task
0.3297,Event,ADDED,eval-sanitize-30-r2-076-vhhk6.18d4f806e7feef13,reason=Started count=1 msg=Started container task
0.3298,Event,ADDED,eval-sanitize-30-r2-076.18d4f806bb51b664,reason=SuccessfulCreate count=1 msg=Created pod: eval-sanitize-30-r2-076-vhhk6
0.3301,Event,ADDED,eval-sanitize-30-r2-076.18d4f80c7bf2acc1,reason=Completed count=1 msg=Job completed
0.3304,Event,ADDED,eval-sanitize-30-r2-077-7h78k.18d4f8073e679110,reason=Scheduled count=None msg=Successfully assigned compute/eval-sanitize-30-r2-077-7h78k to kind-worker4
0.3306,Event,ADDED,eval-sanitize-30-r2-077-7h78k.18d4f8075a093933,"reason=Pulled count=1 msg=Container image ""busybox:musl"" already present on machine"
0.3307,Event,ADDED,eval-sanitize-30-r2-077-7h78k.18d4f8075b821cca,reason=Created count=1 msg=Created container: task
0.331,Event,ADDED,eval-sanitize-30-r2-077-7h78k.18d4f80761b75556,reason=Started count=1 msg=Started container task
0.3311,Event,ADDED,eval-sanitize-30-r2-077.18d4f80735bc18c0,reason=SuccessfulCreate count=1 msg=Created pod: eval-sanitize-30-r2-077-7h78k
0.3313,Event,ADDED,eval-sanitize-30-r2-077.18d4f80cf2b31765,reason=Completed count=1 msg=Job completed
0.3315,Event,ADDED,eval-sanitize-30-r2-078-9q8xm.18d4f8079ba05661,reason=Scheduled count=None msg=Successfully assigned compute/eval-sanitize-30-r2-078-9q8xm to kind-worker2
0.3317,Event,ADDED,eval-sanitize-30-r2-078-9q8xm.18d4f807bd9a7d80,"reason=Pulled count=1 msg=Container image ""busybox:musl"" already present on machine"
0.3318,Event,ADDED,eval-sanitize-30-r2-078-9q8xm.18d4f807bf0b282a,reason=Created count=1 msg=Created container: task
0.332,Event,ADDED,eval-sanitize-30-r2-078-9q8xm.18d4f807c8041571,reason=Started count=1 msg=Started container task
0.3322,Event,ADDED,eval-sanitize-30-r2-078.18d4f8079a01afb9,reason=SuccessfulCreate count=1 msg=Created pod: eval-sanitize-30-r2-078-9q8xm
0.3323,Event,ADDED,eval-sanitize-30-r2-078.18d4f80d2bf49aba,reason=Completed count=1 msg=Job completed
0.3325,Event,ADDED,eval-sanitize-30-r2-079-bhl5b.18d4f807c01679c9,reason=Scheduled count=None msg=Successfully assigned compute/eval-sanitize-30-r2-079-bhl5b to kind-worker2
0.3327,Event,ADDED,eval-sanitize-30-r2-079-bhl5b.18d4f807e3668ebb,"reason=Pulled count=1 msg=Container image ""busybox:musl"" already present on machine"
0.3329,Event,ADDED,eval-sanitize-30-r2-079-bhl5b.18d4f807e4bf2b67,reason=Created count=1 msg=Created container: task
0.3332,Event,ADDED,eval-sanitize-30-r2-079-bhl5b.18d4f807ee3aa60e,reason=Started count=1 msg=Started container task
0.3336,Event,ADDED,eval-sanitize-30-r2-079.18d4f807beb5515c,reason=SuccessfulCreate count=1 msg=Created pod: eval-sanitize-30-r2-079-bhl5b
0.3339,Event,ADDED,eval-sanitize-30-r2-079.18d4f80d67ddbb44,reason=Completed count=1 msg=Job completed
0.3341,Event,ADDED,eval-sanitize-30-r2-080-slm8x.18d4f807f89cc371,"reason=FailedScheduling count=None msg=0/6 nodes are available: 2 c_wall violated: 1 conflicting context pair(s) with node memory, 4 node(s) had untolerated taint(s). no new claims to deallocate, preemption: 0/6 nodes are available: 2 No preemption victims found for incoming pod, 4 Preemption is not helpful for scheduling."
0.3343,Event,ADDED,eval-sanitize-30-r2-080-slm8x.18d4f807f9934868,"reason=FailedScheduling count=None msg=0/6 nodes are available: 2 c_wall violated: 1 conflicting context pair(s) with node memory, 4 node(s) had untolerated taint(s). no new claims to deallocate, preemption: 0/6 nodes are available: 2 No preemption victims found for incoming pod, 4 Preemption is not helpful for scheduling."
0.3349,Event,ADDED,eval-sanitize-30-r2-080-slm8x.18d4f808166a0a43,"reason=FailedScheduling count=None msg=0/6 nodes are available: 1 c_wall violated: 1 conflicting context pair(s) with node memory, 5 node(s) had untolerated taint(s). no new claims to deallocate, preemption: 0/6 nodes are available: 1 No preemption victims found for incoming pod, 5 Preemption is not helpful for scheduling."
0.3352,Event,ADDED,eval-sanitize-30-r2-080-slm8x.18d4f80e944568e1,reason=Scheduled count=None msg=Successfully assigned compute/eval-sanitize-30-r2-080-slm8x to kind-worker
0.3354,Event,ADDED,eval-sanitize-30-r2-080-slm8x.18d4f80eafaf127b,"reason=Pulled count=1 msg=Container image ""busybox:musl"" already present on machine"
0.3356,Event,ADDED,eval-sanitize-30-r2-080-slm8x.18d4f80eb17588da,reason=Created count=1 msg=Created container: task
0.3359,Event,ADDED,eval-sanitize-30-r2-080-slm8x.18d4f80eb6a70acb,reason=Started count=1 msg=Started container task
0.3361,Event,ADDED,eval-sanitize-30-r2-080.18d4f807f81c551f,reason=SuccessfulCreate count=1 msg=Created pod: eval-sanitize-30-r2-080-slm8x
0.3363,Event,ADDED,eval-sanitize-30-r2-080.18d4f813f005dea8,reason=Completed count=1 msg=Job completed
0.3364,Event,ADDED,eval-sanitize-30-r2-081-z955f.18d4f80824af91c0,reason=Scheduled count=None msg=Successfully assigned compute/eval-sanitize-30-r2-081-z955f to kind-worker2
0.3367,Event,ADDED,eval-sanitize-30-r2-081-z955f.18d4f8084926c429,"reason=Pulled count=1 msg=Container image ""busybox:musl"" already present on machine"
0.3369,Event,ADDED,eval-sanitize-30-r2-081-z955f.18d4f8084af05c75,reason=Created count=1 msg=Created container: task
0.3371,Event,ADDED,eval-sanitize-30-r2-081-z955f.18d4f808508b72eb,reason=Started count=1 msg=Started container task
0.3374,Event,ADDED,eval-sanitize-30-r2-081.18d4f808240af0f9,reason=SuccessfulCreate count=1 msg=Created pod: eval-sanitize-30-r2-081-z955f
0.3377,Event,ADDED,eval-sanitize-30-r2-081.18d4f80de3e27153,reason=Completed count=1 msg=Job completed
0.3378,Event,ADDED,eval-sanitize-30-r2-082-hdd6f.18d4f80869073a6e,"reason=FailedScheduling count=None msg=0/6 nodes are available: 6 node(s) had untolerated taint(s). no new claims to deallocate, preemption: 0/6 nodes are available: 6 Preemption is not helpful for scheduling."
0.338,Event,ADDED,eval-sanitize-30-r2-082-hdd6f.18d4f80e954f06cf,reason=Scheduled count=None msg=Successfully assigned compute/eval-sanitize-30-r2-082-hdd6f to kind-worker
0.3383,Event,ADDED,eval-sanitize-30-r2-082-hdd6f.18d4f80eb13bafc1,"reason=Pulled count=1 msg=Container image ""busybox:musl"" already present on machine"
0.3384,Event,ADDED,eval-sanitize-30-r2-082-hdd6f.18d4f80eb3597328,reason=Created count=1 msg=Created container: task
0.3386,Event,ADDED,eval-sanitize-30-r2-082-hdd6f.18d4f80eb734f930,reason=Started count=1 msg=Started container task
0.3388,Event,ADDED,eval-sanitize-30-r2-082.18d4f808690c98b7,reason=SuccessfulCreate count=1 msg=Created pod: eval-sanitize-30-r2-082-hdd6f
0.3392,Event,ADDED,eval-sanitize-30-r2-082.18d4f813f006ba40,reason=Completed count=1 msg=Job completed
0.3396,Event,ADDED,eval-sanitize-30-r2-083-7lpf7.18d4f808901e0d17,"reason=FailedScheduling count=None msg=0/6 nodes are available: 6 node(s) had untolerated taint(s). no new claims to deallocate, preemption: 0/6 nodes are available: 6 Preemption is not helpful for scheduling."
0.3398,Event,ADDED,eval-sanitize-30-r2-083-7lpf7.18d4f80e95dafacd,reason=Scheduled count=None msg=Successfully assigned compute/eval-sanitize-30-r2-083-7lpf7 to kind-worker
0.3402,Event,ADDED,eval-sanitize-30-r2-083-7lpf7.18d4f80eb22db27f,"reason=Pulled count=1 msg=Container image ""busybox:musl"" already present on machine"
0.3404,Event,ADDED,eval-sanitize-30-r2-083-7lpf7.18d4f80eb4272099,reason=Created count=1 msg=Created container: task
0.3406,Event,ADDED,eval-sanitize-30-r2-083-7lpf7.18d4f80eb82e9918,reason=Started count=1 msg=Started container task
0.3408,Event,ADDED,eval-sanitize-30-r2-083.18d4f8089018da1c,reason=SuccessfulCreate count=1 msg=Created pod: eval-sanitize-30-r2-083-7lpf7
0.3411,Event,ADDED,eval-sanitize-30-r2-083.18d4f814296f2edb,reason=Completed count=1 msg=Job completed
0.3412,Event,ADDED,eval-sanitize-30-r2-084-mw4kl.18d4f808c211f34e,"reason=FailedScheduling count=None msg=0/6 nodes are available: 6 node(s) had untolerated taint(s). no new claims to deallocate, preemption: 0/6 nodes are available: 6 Preemption is not helpful for scheduling."
0.3414,Event,ADDED,eval-sanitize-30-r2-084-mw4kl.18d4f80e956a4489,"reason=FailedScheduling count=None msg=0/6 nodes are available: 1 c_wall violated: 1 conflicting context pair(s) with node memory, 5 node(s) had untolerated taint(s). no new claims to deallocate, preemption: 0/6 nodes are available: 1 No preemption victims found for incoming pod, 5 Preemption is not helpful for scheduling."
0.3416,Event,ADDED,eval-sanitize-30-r2-084-mw4kl.18d4f80ec1a0665b,"reason=FailedScheduling count=None msg=0/6 nodes are available: 1 c_wall violated: 1 conflicting context pair(s) with node memory, 5 node(s) had untolerated taint(s). no new claims to deallocate, preemption: 0/6 nodes are available: 1 No preemption victims found for incoming pod, 5 Preemption is not helpful for scheduling."
0.3418,Event,ADDED,eval-sanitize-30-r2-084-mw4kl.18d4f80f20a88ff4,reason=Scheduled count=None msg=Successfully assigned compute/eval-sanitize-30-r2-084-mw4kl to kind-worker3
0.3419,Event,ADDED,eval-sanitize-30-r2-084-mw4kl.18d4f80f3ea43a96,"reason=Pulled count=1 msg=Container image ""busybox:musl"" already present on machine"
0.3421,Event,ADDED,eval-sanitize-30-r2-084-mw4kl.18d4f80f41039056,reason=Created count=1 msg=Created container: task
0.3423,Event,ADDED,eval-sanitize-30-r2-084-mw4kl.18d4f80f47c688bc,reason=Started count=1 msg=Started container task
0.3425,Event,ADDED,eval-sanitize-30-r2-084.18d4f808c20569ae,reason=SuccessfulCreate count=1 msg=Created pod: eval-sanitize-30-r2-084-mw4kl
0.3426,Event,ADDED,eval-sanitize-30-r2-084.18d4f816b8561bd9,reason=Completed count=1 msg=Job completed
0.3428,Event,ADDED,eval-sanitize-30-r2-085-zngbd.18d4f808e2b566cf,"reason=FailedScheduling count=None msg=0/6 nodes are available: 6 node(s) had untolerated taint(s). no new claims to deallocate, preemption: 0/6 nodes are available: 6 Preemption is not helpful for scheduling."
0.3429,Event,ADDED,eval-sanitize-30-r2-085-zngbd.18d4f80e970cb20c,"reason=FailedScheduling count=None msg=0/6 nodes are available: 1 c_wall violated: 1 conflicting context pair(s) with node memory, 5 node(s) had untolerated taint(s). no new claims to deallocate, preemption: 0/6 nodes are available: 1 No preemption victims found for incoming pod, 5 Preemption is not helpful for scheduling."
0.3431,Event,ADDED,eval-sanitize-30-r2-085-zngbd.18d4f80ec1f5ac08,"reason=FailedScheduling count=None msg=0/6 nodes are available: 1 c_wall violated: 1 conflicting context pair(s) with node memory, 5 node(s) had untolerated taint(s). no new claims to deallocate, preemption: 0/6 nodes are available: 1 No preemption victims found for incoming pod, 5 Preemption is not helpful for scheduling."
0.3432,Event,ADDED,eval-sanitize-30-r2-085-zngbd.18d4f80f26a98f02,reason=Scheduled count=None msg=Successfully assigned compute/eval-sanitize-30-r2-085-zngbd to kind-worker3
0.3434,Event,ADDED,eval-sanitize-30-r2-085-zngbd.18d4f80f47e8add3,"reason=Pulled count=1 msg=Container image ""busybox:musl"" already present on machine"
0.3436,Event,ADDED,eval-sanitize-30-r2-085-zngbd.18d4f80f49c06f6f,reason=Created count=1 msg=Created container: task
0.3437,Event,ADDED,eval-sanitize-30-r2-085-zngbd.18d4f80f503ca820,reason=Started count=1 msg=Started container task
0.3439,Event,ADDED,eval-sanitize-30-r2-085.18d4f808e2acb278,reason=SuccessfulCreate count=1 msg=Created pod: eval-sanitize-30-r2-085-zngbd
0.3441,Event,ADDED,eval-sanitize-30-r2-085.18d4f816be3a7cd4,reason=Completed count=1 msg=Job completed
0.3444,Event,ADDED,eval-sanitize-30-r2-086-z94c6.18d4f8090dded532,"reason=FailedScheduling count=None msg=0/6 nodes are available: 6 node(s) had untolerated taint(s). no new claims to deallocate, preemption: 0/6 nodes are available: 6 Preemption is not helpful for scheduling."
0.3445,Event,ADDED,eval-sanitize-30-r2-086-z94c6.18d4f80e98691162,"reason=FailedScheduling count=None msg=0/6 nodes are available: 1 c_wall violated: 1 conflicting context pair(s) with node memory, 5 node(s) had untolerated taint(s). no new claims to deallocate, preemption: 0/6 nodes are available: 1 No preemption victims found for incoming pod, 5 Preemption is not helpful for scheduling."
0.3448,Event,ADDED,eval-sanitize-30-r2-086-z94c6.18d4f80ec68a6ba6,"reason=FailedScheduling count=None msg=0/6 nodes are available: 1 c_wall violated: 1 conflicting context pair(s) with node memory, 5 node(s) had untolerated taint(s). no new claims to deallocate, preemption: 0/6 nodes are available: 1 No preemption victims found for incoming pod, 5 Preemption is not helpful for scheduling."
0.3451,Event,ADDED,eval-sanitize-30-r2-086-z94c6.18d4f80f2794c3cd,reason=Scheduled count=None msg=Successfully assigned compute/eval-sanitize-30-r2-086-z94c6 to kind-worker3
0.3454,Event,ADDED,eval-sanitize-30-r2-086-z94c6.18d4f80f467ef297,"reason=Pulled count=1 msg=Container image ""busybox:musl"" already present on machine"
0.3458,Event,ADDED,eval-sanitize-30-r2-086-z94c6.18d4f80f487dbe97,reason=Created count=1 msg=Created container: task
0.346,Event,ADDED,eval-sanitize-30-r2-086-z94c6.18d4f80f4fce6c24,reason=Started count=1 msg=Started container task
0.3461,Event,ADDED,eval-sanitize-30-r2-086.18d4f8090dd6b544,reason=SuccessfulCreate count=1 msg=Created pod: eval-sanitize-30-r2-086-z94c6
0.3463,Event,ADDED,eval-sanitize-30-r2-086.18d4f816b9e8551f,reason=Completed count=1 msg=Job completed
0.3467,Event,ADDED,eval-sanitize-30-r2-087-mj445.18d4f80928822024,"reason=FailedScheduling count=None msg=0/6 nodes are available: 6 node(s) had untolerated taint(s). no new claims to deallocate, preemption: 0/6 nodes are available: 6 Preemption is not helpful for scheduling."
0.3469,Event,ADDED,eval-sanitize-30-r2-087-mj445.18d4f80e9aed5c07,reason=Scheduled count=None msg=Successfully assigned compute/eval-sanitize-30-r2-087-mj445 to kind-worker
0.3471,Event,ADDED,eval-sanitize-30-r2-087-mj445.18d4f80eb6592668,"reason=Pulled count=1 msg=Container image ""busybox:musl"" already present on machine"
0.3474,Event,ADDED,eval-sanitize-30-r2-087-mj445.18d4f80eb82eeaad,reason=Created count=1 msg=Created container: task
0.3476,Event,ADDED,eval-sanitize-30-r2-087-mj445.18d4f80ebde181e1,reason=Started count=1 msg=Started container task
0.3482,Event,ADDED,eval-sanitize-30-r2-087.18d4f809287799ac,reason=SuccessfulCreate count=1 msg=Created pod: eval-sanitize-30-r2-087-mj445
0.3484,Event,ADDED,eval-sanitize-30-r2-087.18d4f81429a3bcd7,reason=Completed count=1 msg=Job completed
0.3486,Event,ADDED,eval-sanitize-30-r2-088-t8bq7.18d4f8094b6f8b04,"reason=FailedScheduling count=None msg=0/6 nodes are available: 6 node(s) had untolerated taint(s). no new claims to deallocate, preemption: 0/6 nodes are available: 6 Preemption is not helpful for scheduling."
0.3488,Event,ADDED,eval-sanitize-30-r2-088-t8bq7.18d4f80e9e17e073,"reason=FailedScheduling count=None msg=0/6 nodes are available: 1 c_wall violated: 1 conflicting context pair(s) with node memory, 5 node(s) had untolerated taint(s). no new claims to deallocate, preemption: 0/6 nodes are available: 1 No preemption victims found for incoming pod, 5 Preemption is not helpful for scheduling."
0.3489,Event,ADDED,eval-sanitize-30-r2-088-t8bq7.18d4f80ec7a0824f,reason=Scheduled count=None msg=Successfully assigned compute/eval-sanitize-30-r2-088-t8bq7 to kind-worker4
0.3491,Event,ADDED,eval-sanitize-30-r2-088-t8bq7.18d4f80ee76cd0f1,"reason=Pulled count=1 msg=Container image ""busybox:musl"" already present on machine"
0.3493,Event,ADDED,eval-sanitize-30-r2-088-t8bq7.18d4f80ee9a4c79e,reason=Created count=1 msg=Created container: task
0.3494,Event,ADDED,eval-sanitize-30-r2-088-t8bq7.18d4f80eedf1b859,reason=Started count=1 msg=Started container task
0.3496,Event,ADDED,eval-sanitize-30-r2-088.18d4f8094b641c4c,reason=SuccessfulCreate count=1 msg=Created pod: eval-sanitize-30-r2-088-t8bq7
0.3498,Event,ADDED,eval-sanitize-30-r2-088.18d4f8163aa75bf8,reason=Completed count=1 msg=Job completed
0.3499,Event,ADDED,eval-sanitize-30-r2-089-xjxr5.18d4f8096eccbc4a,"reason=FailedScheduling count=None msg=0/6 nodes are available: 6 node(s) had untolerated taint(s). no new claims to deallocate, preemption: 0/6 nodes are available: 6 Preemption is not helpful for scheduling."
0.3501,Event,ADDED,eval-sanitize-30-r2-089-xjxr5.18d4f80e9f3405ae,"reason=FailedScheduling count=None msg=0/6 nodes are available: 1 c_wall violated: 1 conflicting context pair(s) with node memory, 5 node(s) had untolerated taint(s). no new claims to deallocate, preemption: 0/6 nodes are available: 1 No preemption victims found for incoming pod, 5 Preemption is not helpful for scheduling."
0.3503,Event,ADDED,eval-sanitize-30-r2-089-xjxr5.18d4f80ecd5ef91c,reason=Scheduled count=None msg=Successfully assigned compute/eval-sanitize-30-r2-089-xjxr5 to kind-worker4
0.3505,Event,ADDED,eval-sanitize-30-r2-089-xjxr5.18d4f80eeda274fa,"reason=Pulled count=1 msg=Container image ""busybox:musl"" already present on machine"
0.3509,Event,ADDED,eval-sanitize-30-r2-089-xjxr5.18d4f80eef97080d,reason=Created count=1 msg=Created container: task
0.3513,Event,ADDED,eval-sanitize-30-r2-089-xjxr5.18d4f80ef52c2839,reason=Started count=1 msg=Started container task
0.3516,Event,ADDED,eval-sanitize-30-r2-089.18d4f8096ec2c7d9,reason=SuccessfulCreate count=1 msg=Created pod: eval-sanitize-30-r2-089-xjxr5
0.3518,Event,ADDED,eval-sanitize-30-r2-089.18d4f81615d3160d,reason=Completed count=1 msg=Job completed
0.352,Event,ADDED,eval-sanitize-30-r2-090-jrjkf.18d4f8099f83cabc,"reason=FailedScheduling count=None msg=0/6 nodes are available: 6 node(s) had untolerated taint(s). no new claims to deallocate, preemption: 0/6 nodes are available: 6 Preemption is not helpful for scheduling."
0.3521,Event,ADDED,eval-sanitize-30-r2-090-jrjkf.18d4f80e9fe720e7,"reason=FailedScheduling count=None msg=0/6 nodes are available: 1 c_wall violated: 1 conflicting context pair(s) with node memory, 5 node(s) had untolerated taint(s). no new claims to deallocate, preemption: 0/6 nodes are available: 1 No preemption victims found for incoming pod, 5 Preemption is not helpful for scheduling."
0.3524,Event,ADDED,eval-sanitize-30-r2-090-jrjkf.18d4f80ecdc7526c,reason=Scheduled count=None msg=Successfully assigned compute/eval-sanitize-30-r2-090-jrjkf to kind-worker4
0.3526,Event,ADDED,eval-sanitize-30-r2-090-jrjkf.18d4f80eee1868ee,"reason=Pulled count=1 msg=Container image ""busybox:musl"" already present on machine"
0.3528,Event,ADDED,eval-sanitize-30-r2-090-jrjkf.18d4f80ef0aa9184,reason=Created count=1 msg=Created container: task
0.3532,Event,ADDED,eval-sanitize-30-r2-090-jrjkf.18d4f80ef70a2821,reason=Started count=1 msg=Started container task
0.3536,Event,ADDED,eval-sanitize-30-r2-090.18d4f8099f784dff,reason=SuccessfulCreate count=1 msg=Created pod: eval-sanitize-30-r2-090-jrjkf
0.3538,Event,ADDED,eval-sanitize-30-r2-090.18d4f81657693581,reason=Completed count=1 msg=Job completed
0.3543,Event,ADDED,eval-sanitize-30-r2-091-qrgg5.18d4f809d47e75fc,"reason=FailedScheduling count=None msg=0/6 nodes are available: 6 node(s) had untolerated taint(s). no new claims to deallocate, preemption: 0/6 nodes are available: 6 Preemption is not helpful for scheduling."
0.3546,Event,ADDED,eval-sanitize-30-r2-091-qrgg5.18d4f80ea445aace,"reason=FailedScheduling count=None msg=0/6 nodes are available: 1 c_wall violated: 1 conflicting context pair(s) with node memory, 5 node(s) had untolerated taint(s). no new claims to deallocate, preemption: 0/6 nodes are available: 1 No preemption victims found for incoming pod, 5 Preemption is not helpful for scheduling."
0.3547,Event,ADDED,eval-sanitize-30-r2-091-qrgg5.18d4f80ed33f7991,reason=Scheduled count=None msg=Successfully assigned compute/eval-sanitize-30-r2-091-qrgg5 to kind-worker4
0.3549,Event,ADDED,eval-sanitize-30-r2-091-qrgg5.18d4f80ef037071b,"reason=Pulled count=1 msg=Container image ""busybox:musl"" already present on machine"
0.3552,Event,ADDED,eval-sanitize-30-r2-091-qrgg5.18d4f80ef2c5839a,reason=Created count=1 msg=Created container: task
0.3554,Event,ADDED,eval-sanitize-30-r2-091-qrgg5.18d4f80ef70c6128,reason=Started count=1 msg=Started container task
0.3557,Event,ADDED,eval-sanitize-30-r2-091.18d4f809d4736774,reason=SuccessfulCreate count=1 msg=Created pod: eval-sanitize-30-r2-091-qrgg5
0.3558,Event,ADDED,eval-sanitize-30-r2-091.18d4f8167e422d14,reason=Completed count=1 msg=Job completed
0.356,Event,ADDED,eval-sanitize-30-r2-092-qp8s2.18d4f80a1298fa7a,"reason=FailedScheduling count=None msg=0/6 nodes are available: 6 node(s) had untolerated taint(s). no new claims to deallocate, preemption: 0/6 nodes are available: 6 Preemption is not helpful for scheduling."
0.3561,Event,ADDED,eval-sanitize-30-r2-092-qp8s2.18d4f80ea61979c4,reason=Scheduled count=None msg=Successfully assigned compute/eval-sanitize-30-r2-092-qp8s2 to kind-worker
0.3564,Event,ADDED,eval-sanitize-30-r2-092-qp8s2.18d4f80ec77f105c,"reason=Pulled count=1 msg=Container image ""busybox:musl"" already present on machine"
0.3568,Event,ADDED,eval-sanitize-30-r2-092-qp8s2.18d4f80eca44713d,reason=Created count=1 msg=Created container: task
0.357,Event,ADDED,eval-sanitize-30-r2-092-qp8s2.18d4f80ecfcd2d45,reason=Started count=1 msg=Started container task
0.3574,Event,ADDED,eval-sanitize-30-r2-092.18d4f80a128dbe93,reason=SuccessfulCreate count=1 msg=Created pod: eval-sanitize-30-r2-092-qp8s2
0.3577,Event,ADDED,eval-sanitize-30-r2-092.18d4f815b55b8864,reason=Completed count=1 msg=Job completed
0.3578,Event,ADDED,eval-sanitize-30-r2-093-4knkp.18d4f80a48f97035,"reason=FailedScheduling count=None msg=0/6 nodes are available: 6 node(s) had untolerated taint(s). no new claims to deallocate, preemption: 0/6 nodes are available: 6 Preemption is not helpful for scheduling."
0.358,Event,ADDED,eval-sanitize-30-r2-093-4knkp.18d4f80ea5ed0014,"reason=FailedScheduling count=None msg=0/6 nodes are available: 1 c_wall violated: 1 conflicting context pair(s) with node memory, 5 node(s) had untolerated taint(s). no new claims to deallocate, preemption: 0/6 nodes are available: 1 No preemption victims found for incoming pod, 5 Preemption is not helpful for scheduling."
0.3583,Event,ADDED,eval-sanitize-30-r2-093-4knkp.18d4f80ed31f3d1b,"reason=FailedScheduling count=None msg=0/6 nodes are available: 1 c_wall violated: 1 conflicting context pair(s) with node memory, 1 c_wall violated: 3 conflicting context pair(s) with node memory, 4 node(s) had untolerated taint(s). no new claims to deallocate, preemption: 0/6 nodes are available: 2 No preemption victims found for incoming pod, 4 Preemption is not helpful for scheduling."
0.3584,Event,ADDED,eval-sanitize-30-r2-093-4knkp.18d4f80f31ff5451,"reason=FailedScheduling count=None msg=0/6 nodes are available: 1 c_wall violated: 1 conflicting context pair(s) with node memory, 2 c_wall violated: 3 conflicting context pair(s) with node memory, 3 node(s) had untolerated taint(s). no new claims to deallocate, preemption: 0/6 nodes are available: 3 No preemption victims found for incoming pod, 3 Preemption is not helpful for scheduling."
0.3587,Event,ADDED,eval-sanitize-30-r2-093-4knkp.18d4f80f77131037,reason=Scheduled count=None msg=Successfully assigned compute/eval-sanitize-30-r2-093-4knkp to kind-worker5
0.359,Event,ADDED,eval-sanitize-30-r2-093-4knkp.18d4f80f93fe7169,"reason=Pulled count=1 msg=Container image ""busybox:musl"" already present on machine"
0.3592,Event,ADDED,eval-sanitize-30-r2-093-4knkp.18d4f80f95b76837,reason=Created count=1 msg=Created container: task
0.3594,Event,ADDED,eval-sanitize-30-r2-093-4knkp.18d4f80f9c973763,reason=Started count=1 msg=Started container task
0.3596,Event,ADDED,eval-sanitize-30-r2-093.18d4f80a48f0996b,reason=SuccessfulCreate count=1 msg=Created pod: eval-sanitize-30-r2-093-4knkp
0.3598,Event,ADDED,eval-sanitize-30-r2-093.18d4f8172361a58c,reason=Completed count=1 msg=Job completed
0.3599,Event,ADDED,eval-sanitize-30-r2-094-njzt5.18d4f80a8440ce84,"reason=FailedScheduling count=None msg=0/6 nodes are available: 6 node(s) had untolerated taint(s). no new claims to deallocate, preemption: 0/6 nodes are available: 6 Preemption is not helpful for scheduling."
0.3601,Event,ADDED,eval-sanitize-30-r2-094-njzt5.18d4f80ea761d5ac,reason=Scheduled count=None msg=Successfully assigned compute/eval-sanitize-30-r2-094-njzt5 to kind-worker
0.3606,Event,ADDED,eval-sanitize-30-r2-094-njzt5.18d4f80ec625b0e6,"reason=Pulled count=1 msg=Container image ""busybox:musl"" already present on machine"
0.3607,Event,ADDED,eval-sanitize-30-r2-094-njzt5.18d4f80ec9508109,reason=Created count=1 msg=Created container: task
0.361,Event,ADDED,eval-sanitize-30-r2-094-njzt5.18d4f80ecfcdad65,reason=Started count=1 msg=Started container task
0.3612,Event,ADDED,eval-sanitize-30-r2-094.18d4f80a84387a5c,reason=SuccessfulCreate count=1 msg=Created pod: eval-sanitize-30-r2-094-njzt5
0.3615,Event,ADDED,eval-sanitize-30-r2-094.18d4f815cb3e8aa4,reason=Completed count=1 msg=Job completed
0.3617,Event,ADDED,eval-sanitize-30-r2-095-bf898.18d4f80abeec4c07,"reason=FailedScheduling count=None msg=0/6 nodes are available: 6 node(s) had untolerated taint(s). no new claims to deallocate, preemption: 0/6 nodes are available: 6 Preemption is not helpful for scheduling."
0.3618,Event,ADDED,eval-sanitize-30-r2-095-bf898.18d4f80ea796cbcb,reason=Scheduled count=None msg=Successfully assigned compute/eval-sanitize-30-r2-095-bf898 to kind-worker
0.3622,Event,ADDED,eval-sanitize-30-r2-095-bf898.18d4f80ec5fbfa91,"reason=Pulled count=1 msg=Container image ""busybox:musl"" already present on machine"
0.3626,Event,ADDED,eval-sanitize-30-r2-095-bf898.18d4f80ec8808044,reason=Created count=1 msg=Created container: task
0.3629,Event,ADDED,eval-sanitize-30-r2-095-bf898.18d4f80ece155dfb,reason=Started count=1 msg=Started container task
0.3632,Event,ADDED,eval-sanitize-30-r2-095.18d4f80abedd56ee,reason=SuccessfulCreate count=1 msg=Created pod: eval-sanitize-30-r2-095-bf898
0.3636,Event,ADDED,eval-sanitize-30-r2-095.18d4f8159e9969d3,reason=Completed count=1 msg=Job completed
0.3638,Event,ADDED,eval-sanitize-30-r2-096-z7znd.18d4f80afa625c9c,"reason=FailedScheduling count=None msg=0/6 nodes are available: 6 node(s) had untolerated taint(s). no new claims to deallocate, preemption: 0/6 nodes are available: 6 Preemption is not helpful for scheduling."
0.3639,Event,ADDED,eval-sanitize-30-r2-096-z7znd.18d4f80eaa85af86,reason=Scheduled count=None msg=Successfully assigned compute/eval-sanitize-30-r2-096-z7znd to kind-worker
0.3642,Event,ADDED,eval-sanitize-30-r2-096-z7znd.18d4f80ec8be9949,"reason=Pulled count=1 msg=Container image ""busybox:musl"" already present on machine"
0.3645,Event,ADDED,eval-sanitize-30-r2-096-z7znd.18d4f80ecaada156,reason=Created count=1 msg=Created container: task
0.3647,Event,ADDED,eval-sanitize-30-r2-096-z7znd.18d4f80ecfcd07e3,reason=Started count=1 msg=Started container task
0.3649,Event,ADDED,eval-sanitize-30-r2-096.18d4f80afa572723,reason=SuccessfulCreate count=1 msg=Created pod: eval-sanitize-30-r2-096-z7znd
0.3652,Event,ADDED,eval-sanitize-30-r2-096.18d4f815bfaeb43d,reason=Completed count=1 msg=Job completed
0.3654,Event,ADDED,eval-sanitize-30-r2-097-wfk2b.18d4f80b363ee22b,"reason=FailedScheduling count=None msg=0/6 nodes are available: 6 node(s) had untolerated taint(s). no new claims to deallocate, preemption: 0/6 nodes are available: 6 Preemption is not helpful for scheduling."
0.3656,Event,ADDED,eval-sanitize-30-r2-097-wfk2b.18d4f80eaa5c7787,"reason=FailedScheduling count=None msg=0/6 nodes are available: 1 c_wall violated: 2 conflicting context pair(s) with node memory, 5 node(s) had untolerated taint(s). no new claims to deallocate, preemption: 0/6 nodes are available: 1 No preemption victims found for incoming pod, 5 Preemption is not helpful for scheduling."
0.3659,Event,ADDED,eval-sanitize-30-r2-097-wfk2b.18d4f80ed8b77d36,"reason=FailedScheduling count=None msg=0/6 nodes are available: 2 c_wall violated: 2 conflicting context pair(s) with node memory, 4 node(s) had untolerated taint(s). no new claims to deallocate, preemption: 0/6 nodes are available: 2 No preemption victims found for incoming pod, 4 Preemption is not helpful for scheduling."
0.3661,Event,ADDED,eval-sanitize-30-r2-097-wfk2b.18d4f80f3e77b73e,reason=Scheduled count=None msg=Successfully assigned compute/eval-sanitize-30-r2-097-wfk2b to kind-worker5
0.3663,Event,ADDED,eval-sanitize-30-r2-097-wfk2b.18d4f80f5c8a90ca,"reason=Pulled count=1 msg=Container image ""busybox:musl"" already present on machine"
0.3665,Event,ADDED,eval-sanitize-30-r2-097-wfk2b.18d4f80f5e48ebc5,reason=Created count=1 msg=Created container: task
0.3667,Event,ADDED,eval-sanitize-30-r2-097-wfk2b.18d4f80f62c9d4b4,reason=Started count=1 msg=Started container task
0.3669,Event,ADDED,eval-sanitize-30-r2-097.18d4f80b3636bd80,reason=SuccessfulCreate count=1 msg=Created pod: eval-sanitize-30-r2-097-wfk2b
0.3671,Event,ADDED,eval-sanitize-30-r2-097.18d4f816c9c4abd5,reason=Completed count=1 msg=Job completed
0.3672,Event,ADDED,eval-sanitize-30-r2-098-l6qfj.18d4f80b72b8f378,"reason=FailedScheduling count=None msg=0/6 nodes are available: 6 node(s) had untolerated taint(s). no new claims to deallocate, preemption: 0/6 nodes are available: 6 Preemption is not helpful for scheduling."
0.3674,Event,ADDED,eval-sanitize-30-r2-098-l6qfj.18d4f80eab47b5ed,"reason=FailedScheduling count=None msg=0/6 nodes are available: 1 c_wall violated: 1 conflicting context pair(s) with node memory, 5 node(s) had untolerated taint(s). no new claims to deallocate, preemption: 0/6 nodes are available: 1 No preemption victims found for incoming pod, 5 Preemption is not helpful for scheduling."
0.3675,Event,ADDED,eval-sanitize-30-r2-098-l6qfj.18d4f80ed9f00c5d,reason=Scheduled count=None msg=Successfully assigned compute/eval-sanitize-30-r2-098-l6qfj to kind-worker4
0.3677,Event,ADDED,eval-sanitize-30-r2-098-l6qfj.18d4f80ef74950f8,"reason=Pulled count=1 msg=Container image ""busybox:musl"" already present on machine"
0.368,Event,ADDED,eval-sanitize-30-r2-098-l6qfj.18d4f80ef901389a,reason=Created count=1 msg=Created container: task
0.3684,Event,ADDED,eval-sanitize-30-r2-098-l6qfj.18d4f80efc5554ec,reason=Started count=1 msg=Started container task
0.3687,Event,ADDED,eval-sanitize-30-r2-098.18d4f80b72bd7121,reason=SuccessfulCreate count=1 msg=Created pod: eval-sanitize-30-r2-098-l6qfj
0.369,Event,ADDED,eval-sanitize-30-r2-098.18d4f81627a88c6b,reason=Completed count=1 msg=Job completed
0.3692,Event,ADDED,eval-sanitize-30-r2-099-dvrfb.18d4f80bacbf5ec2,"reason=FailedScheduling count=None msg=0/6 nodes are available: 6 node(s) had untolerated taint(s). no new claims to deallocate, preemption: 0/6 nodes are available: 6 Preemption is not helpful for scheduling."
0.3694,Event,ADDED,eval-sanitize-30-r2-099-dvrfb.18d4f80eae95499b,"reason=FailedScheduling count=None msg=0/6 nodes are available: 1 c_wall violated: 1 conflicting context pair(s) with node memory, 5 node(s) had untolerated taint(s). no new claims to deallocate, preemption: 0/6 nodes are available: 1 No preemption victims found for incoming pod, 5 Preemption is not helpful for scheduling."
0.3696,Event,ADDED,eval-sanitize-30-r2-099-dvrfb.18d4f80edf182584,reason=Scheduled count=None msg=Successfully assigned compute/eval-sanitize-30-r2-099-dvrfb to kind-worker4
0.3698,Event,ADDED,eval-sanitize-30-r2-099-dvrfb.18d4f80efbc7b408,"reason=Pulled count=1 msg=Container image ""busybox:musl"" already present on machine"
0.37,Event,ADDED,eval-sanitize-30-r2-099-dvrfb.18d4f80efdd182cc,reason=Created count=1 msg=Created container: task
0.3702,Event,ADDED,eval-sanitize-30-r2-099-dvrfb.18d4f80f0500939f,reason=Started count=1 msg=Started container task
0.3703,Event,ADDED,eval-sanitize-30-r2-099.18d4f80bacb45d97,reason=SuccessfulCreate count=1 msg=Created pod: eval-sanitize-30-r2-099-dvrfb
0.3706,Event,ADDED,eval-sanitize-30-r2-099.18d4f8164b704bab,reason=Completed count=1 msg=Job completed
0.3707,Event,ADDED,eval-sanitize-30-r2-100-8g7hd.18d4f80be87f1f3a,"reason=FailedScheduling count=None msg=0/6 nodes are available: 6 node(s) had untolerated taint(s). no new claims to deallocate, preemption: 0/6 nodes are available: 6 Preemption is not helpful for scheduling."
0.371,Event,ADDED,eval-sanitize-30-r2-100-8g7hd.18d4f80eb03c83f0,"reason=FailedScheduling count=None msg=0/6 nodes are available: 1 c_wall violated: 1 conflicting context pair(s) with node memory, 5 node(s) had untolerated taint(s). no new claims to deallocate, preemption: 0/6 nodes are available: 1 No preemption victims found for incoming pod, 5 Preemption is not helpful for scheduling."
0.3713,Event,ADDED,eval-sanitize-30-r2-100-8g7hd.18d4f80edf0ce506,"reason=FailedScheduling count=None msg=0/6 nodes are available: 1 c_wall violated: 1 conflicting context pair(s) with node memory, 1 c_wall violated: 3 conflicting context pair(s) with node memory, 4 node(s) had untolerated taint(s). no new claims to deallocate, preemption: 0/6 nodes are available: 2 No preemption victims found for incoming pod, 4 Preemption is not helpful for scheduling."
0.3715,Event,ADDED,eval-sanitize-30-r2-100-8g7hd.18d4f80f45a630d0,reason=Scheduled count=None msg=Successfully assigned compute/eval-sanitize-30-r2-100-8g7hd to kind-worker5
0.3717,Event,ADDED,eval-sanitize-30-r2-100-8g7hd.18d4f80f62c4e2d2,"reason=Pulled count=1 msg=Container image ""busybox:musl"" already present on machine"
0.3719,Event,ADDED,eval-sanitize-30-r2-100-8g7hd.18d4f80f6448c819,reason=Created count=1 msg=Created container: task
0.3723,Event,ADDED,eval-sanitize-30-r2-100-8g7hd.18d4f80f6a1ee6f8,reason=Started count=1 msg=Started container task
0.3725,Event,ADDED,eval-sanitize-30-r2-100.18d4f80be86b31ef,reason=SuccessfulCreate count=1 msg=Created pod: eval-sanitize-30-r2-100-8g7hd
0.3727,Event,ADDED,eval-sanitize-30-r2-100.18d4f816da644c50,reason=Completed count=1 msg=Job completed
0.373,Event,ADDED,eval-sanitize-30-r2-101-92vsj.18d4f80c25b34b21,"reason=FailedScheduling count=None msg=0/6 nodes are available: 6 node(s) had untolerated taint(s). no new claims to deallocate, preemption: 0/6 nodes are available: 6 Preemption is not helpful for scheduling."
0.3732,Event,ADDED,eval-sanitize-30-r2-101-92vsj.18d4f80eb115ec10,"reason=FailedScheduling count=None msg=0/6 nodes are available: 1 c_wall violated: 1 conflicting context pair(s) with node memory, 5 node(s) had untolerated taint(s). no new claims to deallocate, preemption: 0/6 nodes are available: 1 No preemption victims found for incoming pod, 5 Preemption is not helpful for scheduling."
0.3735,Event,ADDED,eval-sanitize-30-r2-101-92vsj.18d4f80ee6171275,reason=Scheduled count=None msg=Successfully assigned compute/eval-sanitize-30-r2-101-92vsj to kind-worker4
0.3737,Event,ADDED,eval-sanitize-30-r2-101-92vsj.18d4f80f0544ad7b,"reason=Pulled count=1 msg=Container image ""busybox:musl"" already present on machine"
0.3744,Event,ADDED,eval-sanitize-30-r2-101-92vsj.18d4f80f077d7288,reason=Created count=1 msg=Created container: task
0.3746,Event,ADDED,eval-sanitize-30-r2-101-92vsj.18d4f80f0fd48a50,reason=Started count=1 msg=Started container task
0.3749,Event,ADDED,eval-sanitize-30-r2-101.18d4f80c25aad367,reason=SuccessfulCreate count=1 msg=Created pod: eval-sanitize-30-r2-101-92vsj
0.3752,Event,ADDED,eval-sanitize-30-r2-101.18d4f816eeea638f,reason=Completed count=1 msg=Job completed
0.3754,Event,ADDED,eval-sanitize-30-r2-102-2z4jj.18d4f80c5fb0540f,"reason=FailedScheduling count=None msg=0/6 nodes are available: 6 node(s) had untolerated taint(s). no new claims to deallocate, preemption: 0/6 nodes are available: 6 Preemption is not helpful for scheduling."
0.3756,Event,ADDED,eval-sanitize-30-r2-102-2z4jj.18d4f80eb1f109bd,"reason=FailedScheduling count=None msg=0/6 nodes are available: 1 c_wall violated: 1 conflicting context pair(s) with node memory, 5 node(s) had untolerated taint(s). no new claims to deallocate, preemption: 0/6 nodes are available: 1 No preemption victims found for incoming pod, 5 Preemption is not helpful for scheduling."
0.3757,Event,ADDED,eval-sanitize-30-r2-102-2z4jj.18d4f80ee4e960ab,"reason=FailedScheduling count=None msg=0/6 nodes are available: 2 c_wall violated: 1 conflicting context pair(s) with node memory, 4 node(s) had untolerated taint(s). no new claims to deallocate, preemption: 0/6 nodes are available: 2 No preemption victims found for incoming pod, 4 Preemption is not helpful for scheduling."
0.3759,Event,ADDED,eval-sanitize-30-r2-102-2z4jj.18d4f80f4fca3ba3,"reason=FailedScheduling count=None msg=0/6 nodes are available: 2 c_wall violated: 1 conflicting context pair(s) with node memory, 2 c_wall violated: 2 conflicting context pair(s) with node memory, 2 node(s) had untolerated taint(s). no new claims to deallocate, preemption: 0/6 nodes are available: 2 Preemption is not helpful for scheduling, 4 No preemption victims found for incoming pod."
0.3761,Event,ADDED,eval-sanitize-30-r2-102-2z4jj.18d4f80f8bcea8d3,reason=Scheduled count=None msg=Successfully assigned compute/eval-sanitize-30-r2-102-2z4jj to kind-worker2
0.3763,Event,ADDED,eval-sanitize-30-r2-102-2z4jj.18d4f80facf2eab8,"reason=Pulled count=1 msg=Container image ""busybox:musl"" already present on machine"
0.3766,Event,ADDED,eval-sanitize-30-r2-102-2z4jj.18d4f80faeccce68,reason=Created count=1 msg=Created container: task
0.3767,Event,ADDED,eval-sanitize-30-r2-102-2z4jj.18d4f80fb7245d07,reason=Started count=1 msg=Started container task
0.3769,Event,ADDED,eval-sanitize-30-r2-102.18d4f80c5fab02c2,reason=SuccessfulCreate count=1 msg=Created pod: eval-sanitize-30-r2-102-2z4jj
0.3771,Event,ADDED,eval-sanitize-30-r2-102.18d4f8172ae59cae,reason=Completed count=1 msg=Job completed
0.3774,Event,ADDED,eval-sanitize-30-r2-103-ffwj6.18d4f80c9b67fb59,"reason=FailedScheduling count=None msg=0/6 nodes are available: 6 node(s) had untolerated taint(s). no new claims to deallocate, preemption: 0/6 nodes are available: 6 Preemption is not helpful for scheduling."
0.3776,Event,ADDED,eval-sanitize-30-r2-103-ffwj6.18d4f80eb384a174,"reason=FailedScheduling count=None msg=0/6 nodes are available: 1 c_wall violated: 2 conflicting context pair(s) with node memory, 5 node(s) had untolerated taint(s). no new claims to deallocate, preemption: 0/6 nodes are available: 1 No preemption victims found for incoming pod, 5 Preemption is not helpful for scheduling."
0.3777,Event,ADDED,eval-sanitize-30-r2-103-ffwj6.18d4f80eea6af9ff,"reason=FailedScheduling count=None msg=0/6 nodes are available: 2 c_wall violated: 2 conflicting context pair(s) with node memory, 4 node(s) had untolerated taint(s). no new claims to deallocate, preemption: 0/6 nodes are available: 2 No preemption victims found for incoming pod, 4 Preemption is not helpful for scheduling."
0.378,Event,ADDED,eval-sanitize-30-r2-103-ffwj6.18d4f80f5657d59c,reason=Scheduled count=None msg=Successfully assigned compute/eval-sanitize-30-r2-103-ffwj6 to kind-worker5
0.3781,Event,ADDED,eval-sanitize-30-r2-103-ffwj6.18d4f80f709c90cb,"reason=Pulled count=1 msg=Container image ""busybox:musl"" already present on machine"
0.3783,Event,ADDED,eval-sanitize-30-r2-103-ffwj6.18d4f80f71e5a32c,reason=Created count=1 msg=Created container: task
0.3786,Event,ADDED,eval-sanitize-30-r2-103-ffwj6.18d4f80f771564f0,reason=Started count=1 msg=Started container task
0.3788,Event,ADDED,eval-sanitize-30-r2-103.18d4f80c9b5845ac,reason=SuccessfulCreate count=1 msg=Created pod: eval-sanitize-30-r2-103-ffwj6
0.379,Event,ADDED,eval-sanitize-30-r2-103.18d4f816d949ec48,reason=Completed count=1 msg=Job completed
0.3791,Event,ADDED,eval-sanitize-30-r2-104-vkvkh.18d4f80cd6cd8a46,"reason=FailedScheduling count=None msg=0/6 nodes are available: 6 node(s) had untolerated taint(s). no new claims to deallocate, preemption: 0/6 nodes are available: 6 Preemption is not helpful for scheduling."
0.3794,Event,ADDED,eval-sanitize-30-r2-104-vkvkh.18d4f80eb63eb46d,"reason=FailedScheduling count=None msg=0/6 nodes are available: 1 c_wall violated: 1 conflicting context pair(s) with node memory, 5 node(s) had untolerated taint(s). no new claims to deallocate, preemption: 0/6 nodes are available: 1 No preemption victims found for incoming pod, 5 Preemption is not helpful for scheduling."
0.3796,Event,ADDED,eval-sanitize-30-r2-104-vkvkh.18d4f80eeb6200e9,"reason=FailedScheduling count=None msg=0/6 nodes are available: 2 c_wall violated: 1 conflicting context pair(s) with node memory, 4 node(s) had untolerated taint(s). no new claims to deallocate, preemption: 0/6 nodes are available: 2 No preemption victims found for incoming pod, 4 Preemption is not helpful for scheduling."
0.3801,Event,ADDED,eval-sanitize-30-r2-104-vkvkh.18d4f80f5d154570,reason=Scheduled count=None msg=Successfully assigned compute/eval-sanitize-30-r2-104-vkvkh to kind-worker2
0.3806,Event,ADDED,eval-sanitize-30-r2-104-vkvkh.18d4f80f7f0d21fc,"reason=Pulled count=1 msg=Container image ""busybox:musl"" already present on machine"
0.381,Event,ADDED,eval-sanitize-30-r2-104-vkvkh.18d4f80f812bc973,reason=Created count=1 msg=Created container: task
0.3811,Event,ADDED,eval-sanitize-30-r2-104-vkvkh.18d4f80f87f039e1,reason=Started count=1 msg=Started container task
0.3813,Event,ADDED,eval-sanitize-30-r2-104.18d4f80cd6c67d7c,reason=SuccessfulCreate count=1 msg=Created pod: eval-sanitize-30-r2-104-vkvkh
0.3816,Event,ADDED,eval-sanitize-30-r2-104.18d4f816ffcbb27f,reason=Completed count=1 msg=Job completed
0.3818,Event,ADDED,eval-sanitize-30-r2-105-mkww4.18d4f80d168ac921,"reason=FailedScheduling count=None msg=0/6 nodes are available: 6 node(s) had untolerated taint(s). no new claims to deallocate, preemption: 0/6 nodes are available: 6 Preemption is not helpful for scheduling."
0.3819,Event,ADDED,eval-sanitize-30-r2-105-mkww4.18d4f80eb7416cab,"reason=FailedScheduling count=None msg=0/6 nodes are available: 1 c_wall violated: 1 conflicting context pair(s) with node memory, 5 node(s) had untolerated taint(s). no new claims to deallocate, preemption: 0/6 nodes are available: 1 No preemption victims found for incoming pod, 5 Preemption is not helpful for scheduling."
0.3821,Event,ADDED,eval-sanitize-30-r2-105-mkww4.18d4f80ef10fb812,reason=Scheduled count=None msg=Successfully assigned compute/eval-sanitize-30-r2-105-mkww4 to kind-worker4
0.3823,Event,ADDED,eval-sanitize-30-r2-105-mkww4.18d4f80f0fd47905,"reason=Pulled count=1 msg=Container image ""busybox:musl"" already present on machine"
0.3825,Event,ADDED,eval-sanitize-30-r2-105-mkww4.18d4f80f11a2a6e6,reason=Created count=1 msg=Created container: task
0.3826,Event,ADDED,eval-sanitize-30-r2-105-mkww4.18d4f80f16f68e35,reason=Started count=1 msg=Started container task
0.3829,Event,ADDED,eval-sanitize-30-r2-105.18d4f80d167f0efd,reason=SuccessfulCreate count=1 msg=Created pod: eval-sanitize-30-r2-105-mkww4
0.3831,Event,ADDED,eval-sanitize-30-r2-105.18d4f81625fea448,reason=Completed count=1 msg=Job completed
0.3833,Event,ADDED,eval-sanitize-30-r2-106-8wkfb.18d4f80d4f1729d2,"reason=FailedScheduling count=None msg=0/6 nodes are available: 6 node(s) had untolerated taint(s). no new claims to deallocate, preemption: 0/6 nodes are available: 6 Preemption is not helpful for scheduling."
0.3835,Event,ADDED,eval-sanitize-30-r2-106-8wkfb.18d4f80eb8021935,"reason=FailedScheduling count=None msg=0/6 nodes are available: 1 c_wall violated: 1 conflicting context pair(s) with node memory, 5 node(s) had untolerated taint(s). no new claims to deallocate, preemption: 0/6 nodes are available: 1 No preemption victims found for incoming pod, 5 Preemption is not helpful for scheduling."
0.3836,Event,ADDED,eval-sanitize-30-r2-106-8wkfb.18d4f80ef7a69fb8,reason=Scheduled count=None msg=Successfully assigned compute/eval-sanitize-30-r2-106-8wkfb to kind-worker3
0.3838,Event,ADDED,eval-sanitize-30-r2-106-8wkfb.18d4f80f177fa68c,"reason=Pulled count=1 msg=Container image ""busybox:musl"" already present on machine"
0.384,Event,ADDED,eval-sanitize-30-r2-106-8wkfb.18d4f80f19a8b7de,reason=Created count=1 msg=Created container: task
0.3842,Event,ADDED,eval-sanitize-30-r2-106-8wkfb.18d4f80f1ee7c334,reason=Started count=1 msg=Started container task
0.3843,Event,ADDED,eval-sanitize-30-r2-106.18d4f80d4f07497e,reason=SuccessfulCreate count=1 msg=Created pod: eval-sanitize-30-r2-106-8wkfb
0.3845,Event,ADDED,eval-sanitize-30-r2-106.18d4f8163c81fd4d,reason=Completed count=1 msg=Job completed
0.3846,Event,ADDED,eval-sanitize-30-r2-107-46mcw.18d4f80d89fbc330,"reason=FailedScheduling count=None msg=0/6 nodes are available: 6 node(s) had untolerated taint(s). no new claims to deallocate, preemption: 0/6 nodes are available: 6 Preemption is not helpful for scheduling."
0.3848,Event,ADDED,eval-sanitize-30-r2-107-46mcw.18d4f80ebb111b7f,reason=Scheduled count=None msg=Successfully assigned compute/eval-sanitize-30-r2-107-46mcw to kind-worker
0.3851,Event,ADDED,eval-sanitize-30-r2-107-46mcw.18d4f80ed7b8598c,"reason=Pulled count=1 msg=Container image ""busybox:musl"" already present on machine"
0.3852,Event,ADDED,eval-sanitize-30-r2-107-46mcw.18d4f80ed99edfcb,reason=Created count=1 msg=Created container: task
0.3854,Event,ADDED,eval-sanitize-30-r2-107-46mcw.18d4f80ee0504aa9,reason=Started count=1 msg=Started container task
0.3856,Event,ADDED,eval-sanitize-30-r2-107.18d4f80d89f0e838,reason=SuccessfulCreate count=1 msg=Created pod: eval-sanitize-30-r2-107-46mcw
0.3859,Event,ADDED,eval-sanitize-30-r2-107.18d4f8160402fc2f,reason=Completed count=1 msg=Job completed
0.3861,Event,ADDED,eval-sanitize-30-r2-108-hjxk9.18d4f80dc56a30e9,"reason=FailedScheduling count=None msg=0/6 nodes are available: 6 node(s) had untolerated taint(s). no new claims to deallocate, preemption: 0/6 nodes are available: 6 Preemption is not helpful for scheduling."
0.3865,Event,ADDED,eval-sanitize-30-r2-108-hjxk9.18d4f80ebae77b3c,"reason=FailedScheduling count=None msg=0/6 nodes are available: 1 c_wall violated: 1 conflicting context pair(s) with node memory, 5 node(s) had untolerated taint(s). no new claims to deallocate, preemption: 0/6 nodes are available: 1 No preemption victims found for incoming pod, 5 Preemption is not helpful for scheduling."
0.3867,Event,ADDED,eval-sanitize-30-r2-108-hjxk9.18d4f80f003de425,reason=Scheduled count=None msg=Successfully assigned compute/eval-sanitize-30-r2-108-hjxk9 to kind-worker3
0.3868,Event,ADDED,eval-sanitize-30-r2-108-hjxk9.18d4f80f1e5d463a,"reason=Pulled count=1 msg=Container image ""busybox:musl"" already present on machine"
0.3871,Event,ADDED,eval-sanitize-30-r2-108-hjxk9.18d4f80f1ff72f9a,reason=Created count=1 msg=Created container: task
0.3873,Event,ADDED,eval-sanitize-30-r2-108-hjxk9.18d4f80f2532eeb8,reason=Started count=1 msg=Started container task
0.3875,Event,ADDED,eval-sanitize-30-r2-108.18d4f80dc55e6b01,reason=SuccessfulCreate count=1 msg=Created pod: eval-sanitize-30-r2-108-hjxk9
0.3877,Event,ADDED,eval-sanitize-30-r2-108.18d4f81634344d7f,reason=Completed count=1 msg=Job completed
0.3879,Event,ADDED,eval-sanitize-30-r2-109-v2n5n.18d4f80e0796a21d,"reason=FailedScheduling count=None msg=0/6 nodes are available: 6 node(s) had untolerated taint(s). no new claims to deallocate, preemption: 0/6 nodes are available: 6 Preemption is not helpful for scheduling."
0.388,Event,ADDED,eval-sanitize-30-r2-109-v2n5n.18d4f80ebc3fc8da,reason=Scheduled count=None msg=Successfully assigned compute/eval-sanitize-30-r2-109-v2n5n to kind-worker
0.3883,Event,ADDED,eval-sanitize-30-r2-109-v2n5n.18d4f80ed8508fe9,"reason=Pulled count=1 msg=Container image ""busybox:musl"" already present on machine"
0.3885,Event,ADDED,eval-sanitize-30-r2-109-v2n5n.18d4f80eda34d805,reason=Created count=1 msg=Created container: task
0.3887,Event,ADDED,eval-sanitize-30-r2-109-v2n5n.18d4f80ede771185,reason=Started count=1 msg=Started container task
0.3888,Event,ADDED,eval-sanitize-30-r2-109.18d4f80e07873342,reason=SuccessfulCreate count=1 msg=Created pod: eval-sanitize-30-r2-109-v2n5n
0.389,Event,ADDED,eval-sanitize-30-r2-109.18d4f815c8ea8636,reason=Completed count=1 msg=Job completed
0.3892,Event,ADDED,eval-sanitize-30-r2-110-59ggs.18d4f80e3c7c8a41,"reason=FailedScheduling count=None msg=0/6 nodes are available: 6 node(s) had untolerated taint(s). no new claims to deallocate, preemption: 0/6 nodes are available: 6 Preemption is not helpful for scheduling."
0.3893,Event,ADDED,eval-sanitize-30-r2-110-59ggs.18d4f80ec1036a88,reason=Scheduled count=None msg=Successfully assigned compute/eval-sanitize-30-r2-110-59ggs to kind-worker
0.3895,Event,ADDED,eval-sanitize-30-r2-110-59ggs.18d4f80ede82fd20,"reason=Pulled count=1 msg=Container image ""busybox:musl"" already present on machine"
0.3897,Event,ADDED,eval-sanitize-30-r2-110-59ggs.18d4f80ee0b59ce4,reason=Created count=1 msg=Created container: task
0.39,Event,ADDED,eval-sanitize-30-r2-110-59ggs.18d4f80ee66e52b6,reason=Started count=1 msg=Started container task
0.3901,Event,ADDED,eval-sanitize-30-r2-110.18d4f80e3c780269,reason=SuccessfulCreate count=1 msg=Created pod: eval-sanitize-30-r2-110-59ggs
0.3903,Event,ADDED,eval-sanitize-30-r2-110.18d4f815ae16c4cf,reason=Completed count=1 msg=Job completed
0.3905,Event,ADDED,eval-sanitize-30-r2-111-hmdh7.18d4f80e78422518,"reason=FailedScheduling count=None msg=0/6 nodes are available: 6 node(s) had untolerated taint(s). no new claims to deallocate, preemption: 0/6 nodes are available: 6 Preemption is not helpful for scheduling."
0.3906,Event,ADDED,eval-sanitize-30-r2-111-hmdh7.18d4f80ec0e2cfbb,"reason=FailedScheduling count=None msg=0/6 nodes are available: 1 c_wall violated: 1 conflicting context pair(s) with node memory, 5 node(s) had untolerated taint(s). no new claims to deallocate, preemption: 0/6 nodes are available: 1 No preemption victims found for incoming pod, 5 Preemption is not helpful for scheduling."
0.3908,Event,ADDED,eval-sanitize-30-r2-111-hmdh7.18d4f80f0fd753bf,reason=Scheduled count=None msg=Successfully assigned compute/eval-sanitize-30-r2-111-hmdh7 to kind-worker3
0.3909,Event,ADDED,eval-sanitize-30-r2-111-hmdh7.18d4f80f2acf69fe,"reason=Pulled count=1 msg=Container image ""busybox:musl"" already present on machine"
0.3911,Event,ADDED,eval-sanitize-30-r2-111-hmdh7.18d4f80f2c61da40,reason=Created count=1 msg=Created container: task
0.3913,Event,ADDED,eval-sanitize-30-r2-111-hmdh7.18d4f80f30c5a3e0,reason=Started count=1 msg=Started container task
0.3916,Event,ADDED,eval-sanitize-30-r2-111.18d4f80e783ca1da,reason=SuccessfulCreate count=1 msg=Created pod: eval-sanitize-30-r2-111-hmdh7
0.392,Event,ADDED,eval-sanitize-30-r2-111.18d4f8168fa5a565,reason=Completed count=1 msg=Job completed
0.3925,Event,ADDED,eval-sanitize-30-r2-112-r845f.18d4f80ebc4f89a9,"reason=FailedScheduling count=None msg=0/6 nodes are available: 1 c_wall violated: 2 conflicting context pair(s) with node memory, 5 node(s) had untolerated taint(s). no new claims to deallocate, preemption: 0/6 nodes are available: 1 No preemption victims found for incoming pod, 5 Preemption is not helpful for scheduling."
0.3926,Event,ADDED,eval-sanitize-30-r2-112-r845f.18d4f80f07f93732,"reason=FailedScheduling count=None msg=0/6 nodes are available: 3 c_wall violated: 2 conflicting context pair(s) with node memory, 3 node(s) had untolerated taint(s). no new claims to deallocate, preemption: 0/6 nodes are available: 3 No preemption victims found for incoming pod, 3 Preemption is not helpful for scheduling."
0.3928,Event,ADDED,eval-sanitize-30-r2-112-r845f.18d4f80f6896ab75,reason=Scheduled count=None msg=Successfully assigned compute/eval-sanitize-30-r2-112-r845f to kind-worker5
0.3931,Event,ADDED,eval-sanitize-30-r2-112-r845f.18d4f80f888ec388,"reason=Pulled count=1 msg=Container image ""busybox:musl"" already present on machine"
0.3933,Event,ADDED,eval-sanitize-30-r2-112-r845f.18d4f80f89de7360,reason=Created count=1 msg=Created container: task
0.3935,Event,ADDED,eval-sanitize-30-r2-112-r845f.18d4f80f8e57a24f,reason=Started count=1 msg=Started container task
0.3937,Event,ADDED,eval-sanitize-30-r2-112.18d4f80eb4430389,reason=SuccessfulCreate count=1 msg=Created pod: eval-sanitize-30-r2-112-r845f
0.394,Event,ADDED,eval-sanitize-30-r2-112.18d4f817130a0f2c,reason=Completed count=1 msg=Job completed
0.3942,Event,ADDED,eval-sanitize-30-r2-113-ncjfw.18d4f80efcedbf71,reason=Scheduled count=None msg=Successfully assigned compute/eval-sanitize-30-r2-113-ncjfw to kind-worker3
0.3944,Event,ADDED,eval-sanitize-30-r2-113-ncjfw.18d4f80f18644f44,"reason=Pulled count=1 msg=Container image ""busybox:musl"" already present on machine"
0.3947,Event,ADDED,eval-sanitize-30-r2-113-ncjfw.18d4f80f1a56a9aa,reason=Created count=1 msg=Created container: task
0.395,Event,ADDED,eval-sanitize-30-r2-113-ncjfw.18d4f80f1ee7f969,reason=Started count=1 msg=Started container task
0.3952,Event,ADDED,eval-sanitize-30-r2-113.18d4f80ef549edc8,reason=SuccessfulCreate count=1 msg=Created pod: eval-sanitize-30-r2-113-ncjfw
0.3953,Event,ADDED,eval-sanitize-30-r2-113.18d4f81686fd3e86,reason=Completed count=1 msg=Job completed
0.3956,Event,ADDED,eval-sanitize-30-r2-114-b2ww5.18d4f80f3819c566,reason=Scheduled count=None msg=Successfully assigned compute/eval-sanitize-30-r2-114-b2ww5 to kind-worker5
0.3958,Event,ADDED,eval-sanitize-30-r2-114-b2ww5.18d4f80f568f827b,"reason=Pulled count=1 msg=Container image ""busybox:musl"" already present on machine"
0.3962,Event,ADDED,eval-sanitize-30-r2-114-b2ww5.18d4f80f582f55bb,reason=Created count=1 msg=Created container: task
0.3965,Event,ADDED,eval-sanitize-30-r2-114-b2ww5.18d4f80f5d28e335,reason=Started count=1 msg=Started container task
0.3967,Event,ADDED,eval-sanitize-30-r2-114.18d4f80f2ef681a6,reason=SuccessfulCreate count=1 msg=Created pod: eval-sanitize-30-r2-114-b2ww5
0.3969,Event,ADDED,eval-sanitize-30-r2-114.18d4f816c9c47d26,reason=Completed count=1 msg=Job completed
0.397,Event,ADDED,eval-sanitize-30-r2-115-nxhrc.18d4f80f80059c2f,reason=Scheduled count=None msg=Successfully assigned compute/eval-sanitize-30-r2-115-nxhrc to kind-worker4
0.3974,Event,ADDED,eval-sanitize-30-r2-115-nxhrc.18d4f80f9c9b786c,"reason=Pulled count=1 msg=Container image ""busybox:musl"" already present on machine"
0.398,Event,ADDED,eval-sanitize-30-r2-115-nxhrc.18d4f80f9de1b951,reason=Created count=1 msg=Created container: task
0.3982,Event,ADDED,eval-sanitize-30-r2-115-nxhrc.18d4f80fa2ee282b,reason=Started count=1 msg=Started container task
0.3985,Event,ADDED,eval-sanitize-30-r2-115.18d4f80f7010064a,reason=SuccessfulCreate count=1 msg=Created pod: eval-sanitize-30-r2-115-nxhrc
0.3989,Event,ADDED,eval-sanitize-30-r2-115.18d4f817112a4175,reason=Completed count=1 msg=Job completed
0.399,Event,ADDED,eval-sanitize-30-r2-116-tkxnm.18d4f80face8750b,reason=Scheduled count=None msg=Successfully assigned compute/eval-sanitize-30-r2-116-tkxnm to kind-worker5
0.3992,Event,ADDED,eval-sanitize-30-r2-116-tkxnm.18d4f80fca122eb8,"reason=Pulled count=1 msg=Container image ""busybox:musl"" already present on machine"
0.3996,Event,ADDED,eval-sanitize-30-r2-116-tkxnm.18d4f80fcb6519bd,reason=Created count=1 msg=Created container: task
0.3999,Event,ADDED,eval-sanitize-30-r2-116-tkxnm.18d4f80fcf87f931,reason=Started count=1 msg=Started container task
0.4002,Event,ADDED,eval-sanitize-30-r2-116.18d4f80fa26df35a,reason=SuccessfulCreate count=1 msg=Created pod: eval-sanitize-30-r2-116-tkxnm
0.4004,Event,ADDED,eval-sanitize-30-r2-116.18d4f8173522c7a0,reason=Completed count=1 msg=Job completed
0.4007,Event,ADDED,eval-sanitize-30-r2-117-lzqm4.18d4f80fe9bd364a,reason=Scheduled count=None msg=Successfully assigned compute/eval-sanitize-30-r2-117-lzqm4 to kind-worker5
0.4009,Event,ADDED,eval-sanitize-30-r2-117-lzqm4.18d4f8100906cf7d,"reason=Pulled count=1 msg=Container image ""busybox:musl"" already present on machine"
0.4011,Event,ADDED,eval-sanitize-30-r2-117-lzqm4.18d4f8100a883044,reason=Created count=1 msg=Created container: task
0.4012,Event,ADDED,eval-sanitize-30-r2-117-lzqm4.18d4f81019ecaba0,reason=Started count=1 msg=Started container task
0.4015,Event,ADDED,eval-sanitize-30-r2-117.18d4f80fdea8b7c1,reason=SuccessfulCreate count=1 msg=Created pod: eval-sanitize-30-r2-117-lzqm4
0.4019,Event,ADDED,eval-sanitize-30-r2-117.18d4f8175672bb95,reason=Completed count=1 msg=Job completed
0.402,Event,ADDED,eval-sanitize-30-r2-118-q5tb2.18d4f810208fbbd6,reason=Scheduled count=None msg=Successfully assigned compute/eval-sanitize-30-r2-118-q5tb2 to kind-worker2
0.4022,Event,ADDED,eval-sanitize-30-r2-118-q5tb2.18d4f8105533978c,"reason=Pulled count=1 msg=Container image ""busybox:musl"" already present on machine"
0.4025,Event,ADDED,eval-sanitize-30-r2-118-q5tb2.18d4f8105704d4de,reason=Created count=1 msg=Created container: task
0.4027,Event,ADDED,eval-sanitize-30-r2-118-q5tb2.18d4f810637b9c7e,reason=Started count=1 msg=Started container task
0.4029,Event,ADDED,eval-sanitize-30-r2-118.18d4f8101ca000af,reason=SuccessfulCreate count=1 msg=Created pod: eval-sanitize-30-r2-118-q5tb2
0.4033,Event,ADDED,eval-sanitize-30-r2-118.18d4f81763707fdd,reason=Completed count=1 msg=Job completed
0.4036,Event,ADDED,eval-sanitize-30-r2-119-pgm5r.18d4f81063824433,reason=Scheduled count=None msg=Successfully assigned compute/eval-sanitize-30-r2-119-pgm5r to kind-worker2
0.4038,Event,ADDED,eval-sanitize-30-r2-119-pgm5r.18d4f81082042b90,"reason=Pulled count=1 msg=Container image ""busybox:musl"" already present on machine"
0.404,Event,ADDED,eval-sanitize-30-r2-119-pgm5r.18d4f810836d3490,reason=Created count=1 msg=Created container: task
0.4043,Event,ADDED,eval-sanitize-30-r2-119-pgm5r.18d4f8108cffccb4,reason=Started count=1 msg=Started container task
0.4045,Event,ADDED,eval-sanitize-30-r2-119.18d4f81057c01b66,reason=SuccessfulCreate count=1 msg=Created pod: eval-sanitize-30-r2-119-pgm5r
0.4047,Event,ADDED,eval-sanitize-30-r2-119.18d4f8177d1db26e,reason=Completed count=1 msg=Job completed
0.4048,Event,ADDED,eval-sanitize-30-r2-120-r5km8.18d4f8109c4d0594,reason=Scheduled count=None msg=Successfully assigned compute/eval-sanitize-30-r2-120-r5km8 to kind-worker3
0.4051,Event,ADDED,eval-sanitize-30-r2-120-r5km8.18d4f810bd0d23d6,"reason=Pulled count=1 msg=Container image ""busybox:musl"" already present on machine"
0.4053,Event,ADDED,eval-sanitize-30-r2-120-r5km8.18d4f810bebd3a36,reason=Created count=1 msg=Created container: task
0.4055,Event,ADDED,eval-sanitize-30-r2-120-r5km8.18d4f810c55f4c1b,reason=Started count=1 msg=Started container task
0.4058,Event,ADDED,eval-sanitize-30-r2-120.18d4f810909702ca,reason=SuccessfulCreate count=1 msg=Created pod: eval-sanitize-30-r2-120-r5km8
0.406,Event,ADDED,eval-sanitize-30-r2-120.18d4f8178e4dca45,reason=Completed count=1 msg=Job completed
0.4061,Event,ADDED,eval-sanitize-30-r2-121-6pxpj.18d4f810d5143153,reason=Scheduled count=None msg=Successfully assigned compute/eval-sanitize-30-r2-121-6pxpj to kind-worker
0.4063,Event,ADDED,eval-sanitize-30-r2-121-6pxpj.18d4f810f55b034f,"reason=Pulled count=1 msg=Container image ""busybox:musl"" already present on machine"
0.4065,Event,ADDED,eval-sanitize-30-r2-121-6pxpj.18d4f810f7595822,reason=Created count=1 msg=Created container: task
0.4067,Event,ADDED,eval-sanitize-30-r2-121-6pxpj.18d4f810ffdcc7f4,reason=Started count=1 msg=Started container task
0.4069,Event,ADDED,eval-sanitize-30-r2-121.18d4f810cdf2cd2f,reason=SuccessfulCreate count=1 msg=Created pod: eval-sanitize-30-r2-121-6pxpj
0.407,Event,ADDED,eval-sanitize-30-r2-121.18d4f8179f0b8df6,reason=Completed count=1 msg=Job completed
0.4072,Event,ADDED,eval-sanitize-30-r2-122-wgd87.18d4f81110009f9d,reason=Scheduled count=None msg=Successfully assigned compute/eval-sanitize-30-r2-122-wgd87 to kind-worker2
0.4074,Event,ADDED,eval-sanitize-30-r2-122-wgd87.18d4f8112f0111a4,"reason=Pulled count=1 msg=Container image ""busybox:musl"" already present on machine"
0.4076,Event,ADDED,eval-sanitize-30-r2-122-wgd87.18d4f8113082a9ff,reason=Created count=1 msg=Created container: task
0.4078,Event,ADDED,eval-sanitize-30-r2-122-wgd87.18d4f81140961218,reason=Started count=1 msg=Started container task
0.408,Event,ADDED,eval-sanitize-30-r2-122.18d4f8110a3174ed,reason=SuccessfulCreate count=1 msg=Created pod: eval-sanitize-30-r2-122-wgd87
0.4082,Event,ADDED,eval-sanitize-30-r2-122.18d4f817adf2a0da,reason=Completed count=1 msg=Job completed
0.4084,Event,ADDED,eval-sanitize-30-r2-123-jn446.18d4f8114bf0ebd1,reason=Scheduled count=None msg=Successfully assigned compute/eval-sanitize-30-r2-123-jn446 to kind-worker3
0.4086,Event,ADDED,eval-sanitize-30-r2-123-jn446.18d4f8116ea822aa,"reason=Pulled count=1 msg=Container image ""busybox:musl"" already present on machine"
0.4088,Event,ADDED,eval-sanitize-30-r2-123-jn446.18d4f811711ca1be,reason=Created count=1 msg=Created container: task
0.409,Event,ADDED,eval-sanitize-30-r2-123-jn446.18d4f8117be27c62,reason=Started count=1 msg=Started container task
0.4094,Event,ADDED,eval-sanitize-30-r2-123.18d4f81144340f3a,reason=SuccessfulCreate count=1 msg=Created pod: eval-sanitize-30-r2-123-jn446
0.4096,Event,ADDED,eval-sanitize-30-r2-123.18d4f817b0e35783,reason=Completed count=1 msg=Job completed
0.4099,Event,ADDED,eval-sanitize-30-r2-124-qjmgd.18d4f8118b108951,reason=Scheduled count=None msg=Successfully assigned compute/eval-sanitize-30-r2-124-qjmgd to kind-worker2
0.4101,Event,ADDED,eval-sanitize-30-r2-124-qjmgd.18d4f811a9771ff1,"reason=Pulled count=1 msg=Container image ""busybox:musl"" already present on machine"
0.4104,Event,ADDED,eval-sanitize-30-r2-124-qjmgd.18d4f811aac30e91,reason=Created count=1 msg=Created container: task
0.4106,Event,ADDED,eval-sanitize-30-r2-124-qjmgd.18d4f811ae734d57,reason=Started count=1 msg=Started container task
0.4108,Event,ADDED,eval-sanitize-30-r2-124.18d4f81180df5ea8,reason=SuccessfulCreate count=1 msg=Created pod: eval-sanitize-30-r2-124-qjmgd
0.411,Event,ADDED,eval-sanitize-30-r2-124.18d4f817c5cbcf0e,reason=Completed count=1 msg=Job completed
0.4113,Event,ADDED,eval-sanitize-30-r2-125-m6r66.18d4f811c15ee3dd,reason=Scheduled count=None msg=Successfully assigned compute/eval-sanitize-30-r2-125-m6r66 to kind-worker
0.4115,Event,ADDED,eval-sanitize-30-r2-125-m6r66.18d4f811de23919d,"reason=Pulled count=1 msg=Container image ""busybox:musl"" already present on machine"
0.4117,Event,ADDED,eval-sanitize-30-r2-125-m6r66.18d4f811df9acb04,reason=Created count=1 msg=Created container: task
0.4123,Event,ADDED,eval-sanitize-30-r2-125-m6r66.18d4f811e58b0c37,reason=Started count=1 msg=Started container task
0.4125,Event,ADDED,eval-sanitize-30-r2-125.18d4f811baa16de0,reason=SuccessfulCreate count=1 msg=Created pod: eval-sanitize-30-r2-125-m6r66
0.4127,Event,ADDED,eval-sanitize-30-r2-125.18d4f817add5b46a,reason=Completed count=1 msg=Job completed
0.413,Event,ADDED,eval-sanitize-30-r2-126-vzrrn.18d4f811fd7f9be6,reason=Scheduled count=None msg=Successfully assigned compute/eval-sanitize-30-r2-126-vzrrn to kind-worker5
0.4133,Event,ADDED,eval-sanitize-30-r2-126-vzrrn.18d4f8121a16e5e8,"reason=Pulled count=1 msg=Container image ""busybox:musl"" already present on machine"
0.4134,Event,ADDED,eval-sanitize-30-r2-126-vzrrn.18d4f8121b85d193,reason=Created count=1 msg=Created container: task
0.4136,Event,ADDED,eval-sanitize-30-r2-126-vzrrn.18d4f8122093fa2f,reason=Started count=1 msg=Started container task
0.4138,Event,ADDED,eval-sanitize-30-r2-126.18d4f811f664232c,reason=SuccessfulCreate count=1 msg=Created pod: eval-sanitize-30-r2-126-vzrrn
0.414,Event,ADDED,eval-sanitize-30-r2-126.18d4f817c8c2dc7b,reason=Completed count=1 msg=Job completed
0.4142,Event,ADDED,eval-sanitize-30-r2-127-wptlx.18d4f81239349aee,"reason=FailedScheduling count=None msg=0/6 nodes are available: 1 c_wall violated: 1 conflicting context pair(s) with node memory, 1 c_wall violated: 3 conflicting context pair(s) with node memory, 1 c_wall violated: 4 conflicting context pair(s) with node memory, 1 node(s) had untolerated taint(s), 2 c_wall violated: 2 conflicting context pair(s) with node memory. no new claims to deallocate, preemption: 0/6 nodes are available: 1 Preemption is not helpful for scheduling, 5 No preemption victims found for incoming pod."
0.4145,Event,ADDED,eval-sanitize-30-r2-127-wptlx.18d4f81244bbb305,"reason=FailedScheduling count=None msg=0/6 nodes are available: 1 c_wall violated: 1 conflicting context pair(s) with node memory, 1 c_wall violated: 3 conflicting context pair(s) with node memory, 1 c_wall violated: 4 conflicting context pair(s) with node memory, 1 node(s) had untolerated taint(s), 2 c_wall violated: 2 conflicting context pair(s) with node memory. no new claims to deallocate, preemption: 0/6 nodes are available: 1 Preemption is not helpful for scheduling, 5 No preemption victims found for incoming pod."
0.415,Event,ADDED,eval-sanitize-30-r2-127-wptlx.18d4f815afc38749,"reason=FailedScheduling count=None msg=0/6 nodes are available: 1 c_wall violated: 3 conflicting context pair(s) with node memory, 1 c_wall violated: 4 conflicting context pair(s) with node memory, 2 c_wall violated: 2 conflicting context pair(s) with node memory, 2 node(s) had untolerated taint(s). no new claims to deallocate, preemption: 0/6 nodes are available: 2 Preemption is not helpful for scheduling, 4 No preemption victims found for incoming pod."
0.4155,Event,ADDED,eval-sanitize-30-r2-127-wptlx.18d4f815cec16ff5,"reason=FailedScheduling count=None msg=0/6 nodes are available: 1 c_wall violated: 4 conflicting context pair(s) with node memory, 2 c_wall violated: 2 conflicting context pair(s) with node memory, 3 node(s) had untolerated taint(s). no new claims to deallocate, preemption: 0/6 nodes are available: 3 No preemption victims found for incoming pod, 3 Preemption is not helpful for scheduling."
0.4158,Event,ADDED,eval-sanitize-30-r2-127-wptlx.18d4f815efdbbac5,"reason=FailedScheduling count=None msg=0/6 nodes are available: 2 c_wall violated: 2 conflicting context pair(s) with node memory, 4 node(s) had untolerated taint(s). no new claims to deallocate, preemption: 0/6 nodes are available: 2 No preemption victims found for incoming pod, 4 Preemption is not helpful for scheduling."
0.416,Event,ADDED,eval-sanitize-30-r2-127-wptlx.18d4f8163740a136,"reason=FailedScheduling count=None msg=0/6 nodes are available: 1 c_wall violated: 2 conflicting context pair(s) with node memory, 5 node(s) had untolerated taint(s). no new claims to deallocate, preemption: 0/6 nodes are available: 1 No preemption victims found for incoming pod, 5 Preemption is not helpful for scheduling."
0.4162,Event,ADDED,eval-sanitize-30-r2-127-wptlx.18d4f81cb7c178ce,reason=Scheduled count=None msg=Successfully assigned compute/eval-sanitize-30-r2-127-wptlx to kind-worker
0.4164,Event,ADDED,eval-sanitize-30-r2-127-wptlx.18d4f81cd3e224d6,"reason=Pulled count=1 msg=Container image ""busybox:musl"" already present on machine"
0.4166,Event,ADDED,eval-sanitize-30-r2-127-wptlx.18d4f81cd7437380,reason=Created count=1 msg=Created container: task
0.4168,Event,ADDED,eval-sanitize-30-r2-127-wptlx.18d4f81cdb4a7ff9,reason=Started count=1 msg=Started container task
0.417,Event,ADDED,eval-sanitize-30-r2-127.18d4f8123349a5fe,reason=SuccessfulCreate count=1 msg=Created pod: eval-sanitize-30-r2-127-wptlx
0.4171,Event,ADDED,eval-sanitize-30-r2-127.18d4f82402fd808b,reason=Completed count=1 msg=Job completed
0.4173,Event,ADDED,eval-sanitize-30-r2-128-q9zs9.18d4f81274ec9be0,reason=Scheduled count=None msg=Successfully assigned compute/eval-sanitize-30-r2-128-q9zs9 to kind-worker5
0.4175,Event,ADDED,eval-sanitize-30-r2-128-q9zs9.18d4f8129cfe1de4,"reason=Pulled count=1 msg=Container image ""busybox:musl"" already present on machine"
0.4176,Event,ADDED,eval-sanitize-30-r2-128-q9zs9.18d4f8129ee365e4,reason=Created count=1 msg=Created container: task
0.418,Event,ADDED,eval-sanitize-30-r2-128-q9zs9.18d4f812a4613207,reason=Started count=1 msg=Started container task
0.4182,Event,ADDED,eval-sanitize-30-r2-128.18d4f8126db04fb2,reason=SuccessfulCreate count=1 msg=Created pod: eval-sanitize-30-r2-128-q9zs9
0.4183,Event,ADDED,eval-sanitize-30-r2-128.18d4f81844ad1b9e,reason=Completed count=1 msg=Job completed
0.4185,Event,ADDED,eval-sanitize-30-r2-129-4s45w.18d4f812b0fe359d,reason=Scheduled count=None msg=Successfully assigned compute/eval-sanitize-30-r2-129-4s45w to kind-worker4
0.4188,Event,ADDED,eval-sanitize-30-r2-129-4s45w.18d4f812cd065223,"reason=Pulled count=1 msg=Container image ""busybox:musl"" already present on machine"
0.419,Event,ADDED,eval-sanitize-30-r2-129-4s45w.18d4f812cedb2e53,reason=Created count=1 msg=Created container: task
0.4192,Event,ADDED,eval-sanitize-30-r2-129-4s45w.18d4f812d3bd6ad3,reason=Started count=1 msg=Started container task
0.4194,Event,ADDED,eval-sanitize-30-r2-129.18d4f812a8d9c844,reason=SuccessfulCreate count=1 msg=Created pod: eval-sanitize-30-r2-129-4s45w
0.4196,Event,ADDED,eval-sanitize-30-r2-129.18d4f81874a48a17,reason=Completed count=1 msg=Job completed
0.4198,Event,ADDED,eval-sanitize-30-r2-130-kgrsx.18d4f812ec51f124,reason=Scheduled count=None msg=Successfully assigned compute/eval-sanitize-30-r2-130-kgrsx to kind-worker2
0.4199,Event,ADDED,eval-sanitize-30-r2-130-kgrsx.18d4f81309158f25,"reason=Pulled count=1 msg=Container image ""busybox:musl"" already present on machine"
0.4201,Event,ADDED,eval-sanitize-30-r2-130-kgrsx.18d4f8130a9a2f1e,reason=Created count=1 msg=Created container: task
0.4204,Event,ADDED,eval-sanitize-30-r2-130-kgrsx.18d4f8130fd5cb2f,reason=Started count=1 msg=Started container task
0.4206,Event,ADDED,eval-sanitize-30-r2-130.18d4f812e547d81a,reason=SuccessfulCreate count=1 msg=Created pod: eval-sanitize-30-r2-130-kgrsx
0.4211,Event,ADDED,eval-sanitize-30-r2-130.18d4f818a8318d97,reason=Completed count=1 msg=Job completed
0.4214,Event,ADDED,eval-sanitize-30-r2-131-xtjtr.18d4f8132918c2eb,reason=Scheduled count=None msg=Successfully assigned compute/eval-sanitize-30-r2-131-xtjtr to kind-worker2
0.4217,Event,ADDED,eval-sanitize-30-r2-131-xtjtr.18d4f81344c11d5d,"reason=Pulled count=1 msg=Container image ""busybox:musl"" already present on machine"
0.4221,Event,ADDED,eval-sanitize-30-r2-131-xtjtr.18d4f813461ec47d,reason=Created count=1 msg=Created container: task
0.4226,Event,ADDED,eval-sanitize-30-r2-131-xtjtr.18d4f8134aa6db15,reason=Started count=1 msg=Started container task
0.4229,Event,ADDED,eval-sanitize-30-r2-131.18d4f81320b3d9e5,reason=SuccessfulCreate count=1 msg=Created pod: eval-sanitize-30-r2-131-xtjtr
0.4232,Event,ADDED,eval-sanitize-30-r2-131.18d4f818df505a1e,reason=Completed count=1 msg=Job completed
0.4234,Event,ADDED,eval-sanitize-30-r2-132-4x4mc.18d4f81362703daf,reason=Scheduled count=None msg=Successfully assigned compute/eval-sanitize-30-r2-132-4x4mc to kind-worker5
0.4239,Event,ADDED,eval-sanitize-30-r2-132-4x4mc.18d4f8137cd16f0e,"reason=Pulled count=1 msg=Container image ""busybox:musl"" already present on machine"
0.4242,Event,ADDED,eval-sanitize-30-r2-132-4x4mc.18d4f8137e7c6f65,reason=Created count=1 msg=Created container: task
0.4245,Event,ADDED,eval-sanitize-30-r2-132-4x4mc.18d4f813836304fd,reason=Started count=1 msg=Started container task
0.425,Event,ADDED,eval-sanitize-30-r2-132.18d4f8135bc7aee2,reason=SuccessfulCreate count=1 msg=Created pod: eval-sanitize-30-r2-132-4x4mc
0.4255,Event,ADDED,eval-sanitize-30-r2-132.18d4f81921134add,reason=Completed count=1 msg=Job completed
0.4259,Event,ADDED,eval-sanitize-30-r2-133-x57nk.18d4f8139ee50deb,reason=Scheduled count=None msg=Successfully assigned compute/eval-sanitize-30-r2-133-x57nk to kind-worker2
0.4271,Event,ADDED,eval-sanitize-30-r2-133-x57nk.18d4f813bf6db490,"reason=Pulled count=1 msg=Container image ""busybox:musl"" already present on machine"
0.4279,Event,ADDED,eval-sanitize-30-r2-133-x57nk.18d4f813c0cf1995,reason=Created count=1 msg=Created container: task
0.4283,Event,ADDED,eval-sanitize-30-r2-133-x57nk.18d4f813c5d41b4d,reason=Started count=1 msg=Started container task
0.4288,Event,ADDED,eval-sanitize-30-r2-133.18d4f81397af2e0b,reason=SuccessfulCreate count=1 msg=Created pod: eval-sanitize-30-r2-133-x57nk
0.4291,Event,ADDED,eval-sanitize-30-r2-133.18d4f81958a0c2d2,reason=Completed count=1 msg=Job completed
0.4296,Event,ADDED,eval-sanitize-30-r2-134-jr8xl.18d4f813da9f6b39,reason=Scheduled count=None msg=Successfully assigned compute/eval-sanitize-30-r2-134-jr8xl to kind-worker2
0.4301,Event,ADDED,eval-sanitize-30-r2-134-jr8xl.18d4f813f998639b,"reason=Pulled count=1 msg=Container image ""busybox:musl"" already present on machine"
0.4307,Event,ADDED,eval-sanitize-30-r2-134-jr8xl.18d4f813fb38199f,reason=Created count=1 msg=Created container: task
0.4313,Event,ADDED,eval-sanitize-30-r2-134-jr8xl.18d4f81400d7cca5,reason=Started count=1 msg=Started container task
0.4317,Event,ADDED,eval-sanitize-30-r2-134.18d4f813d3a86af5,reason=SuccessfulCreate count=1 msg=Created pod: eval-sanitize-30-r2-134-jr8xl
0.4319,Event,ADDED,eval-sanitize-30-r2-134.18d4f81988d2f2bc,reason=Completed count=1 msg=Job completed
0.4321,Event,ADDED,eval-sanitize-30-r2-135-dxgdc.18d4f8141cef3f75,reason=Scheduled count=None msg=Successfully assigned compute/eval-sanitize-30-r2-135-dxgdc to kind-worker3
0.4327,Event,ADDED,eval-sanitize-30-r2-135-dxgdc.18d4f8143d20909a,"reason=Pulled count=1 msg=Container image ""busybox:musl"" already present on machine"
0.4334,Event,ADDED,eval-sanitize-30-r2-135-dxgdc.18d4f8143eca25a3,reason=Created count=1 msg=Created container: task
0.4341,Event,ADDED,eval-sanitize-30-r2-135-dxgdc.18d4f8144443af4b,reason=Started count=1 msg=Started container task
0.4345,Event,ADDED,eval-sanitize-30-r2-135.18d4f8140e8636e0,reason=SuccessfulCreate count=1 msg=Created pod: eval-sanitize-30-r2-135-dxgdc
0.4349,Event,ADDED,eval-sanitize-30-r2-135.18d4f819d0f08dd4,reason=Completed count=1 msg=Job completed
0.435,Event,ADDED,eval-sanitize-30-r2-136-kmzps.18d4f814b0a1c797,reason=Scheduled count=None msg=Successfully assigned compute/eval-sanitize-30-r2-136-kmzps to kind-worker5
0.4354,Event,ADDED,eval-sanitize-30-r2-136-kmzps.18d4f814ce4a81ce,"reason=Pulled count=1 msg=Container image ""busybox:musl"" already present on machine"
0.4358,Event,ADDED,eval-sanitize-30-r2-136-kmzps.18d4f814cfd0bc92,reason=Created count=1 msg=Created container: task
0.4363,Event,ADDED,eval-sanitize-30-r2-136-kmzps.18d4f814d5cf1d87,reason=Started count=1 msg=Started container task
0.4367,Event,ADDED,eval-sanitize-30-r2-136.18d4f814a45f3a72,reason=SuccessfulCreate count=1 msg=Created pod: eval-sanitize-30-r2-136-kmzps
0.4372,Event,ADDED,eval-sanitize-30-r2-136.18d4f81a4b1dfbe9,reason=Completed count=1 msg=Job completed
0.4377,Event,ADDED,eval-sanitize-30-r2-137-s8gcv.18d4f8154c8cd08b,reason=Scheduled count=None msg=Successfully assigned compute/eval-sanitize-30-r2-137-s8gcv to kind-worker4
0.4379,Event,ADDED,eval-sanitize-30-r2-137-s8gcv.18d4f815698201b4,"reason=Pulled count=1 msg=Container image ""busybox:musl"" already present on machine"
0.4381,Event,ADDED,eval-sanitize-30-r2-137-s8gcv.18d4f8156b0db334,reason=Created count=1 msg=Created container: task
0.4383,Event,ADDED,eval-sanitize-30-r2-137-s8gcv.18d4f81574025356,reason=Started count=1 msg=Started container task
0.4387,Event,ADDED,eval-sanitize-30-r2-137.18d4f81548bb12b0,reason=SuccessfulCreate count=1 msg=Created pod: eval-sanitize-30-r2-137-s8gcv
0.4389,Event,ADDED,eval-sanitize-30-r2-137.18d4f81afa05c654,reason=Completed count=1 msg=Job completed
0.4391,Event,ADDED,eval-sanitize-30-r2-138-cjmtq.18d4f815880bdbd6,reason=Scheduled count=None msg=Successfully assigned compute/eval-sanitize-30-r2-138-cjmtq to kind-worker4
0.4393,Event,ADDED,eval-sanitize-30-r2-138-cjmtq.18d4f815a3fb489c,"reason=Pulled count=1 msg=Container image ""busybox:musl"" already present on machine"
0.4397,Event,ADDED,eval-sanitize-30-r2-138-cjmtq.18d4f815a5857bd9,reason=Created count=1 msg=Created container: task
0.4399,Event,ADDED,eval-sanitize-30-r2-138-cjmtq.18d4f815ade66350,reason=Started count=1 msg=Started container task
0.4401,Event,ADDED,eval-sanitize-30-r2-138.18d4f8157f79695b,reason=SuccessfulCreate count=1 msg=Created pod: eval-sanitize-30-r2-138-cjmtq
0.4405,Event,ADDED,eval-sanitize-30-r2-138.18d4f81b36d2c821,reason=Completed count=1 msg=Job completed
0.4408,Event,ADDED,eval-sanitize-30-r2-139-h47nr.18d4f815bf1f9e0a,reason=Scheduled count=None msg=Successfully assigned compute/eval-sanitize-30-r2-139-h47nr to kind-worker5
0.441,Event,ADDED,eval-sanitize-30-r2-139-h47nr.18d4f815ed7918e5,"reason=Pulled count=1 msg=Container image ""busybox:musl"" already present on machine"
0.4412,Event,ADDED,eval-sanitize-30-r2-139-h47nr.18d4f815ef1d38f8,reason=Created count=1 msg=Created container: task
0.4416,Event,ADDED,eval-sanitize-30-r2-139-h47nr.18d4f815f67d88e4,reason=Started count=1 msg=Started container task
0.4418,Event,ADDED,eval-sanitize-30-r2-139.18d4f815b67ab127,reason=SuccessfulCreate count=1 msg=Created pod: eval-sanitize-30-r2-139-h47nr
0.442,Event,ADDED,eval-sanitize-30-r2-139.18d4f81b77e1c4cb,reason=Completed count=1 msg=Job completed
0.4423,Event,ADDED,eval-sanitize-30-r2-140-kftvh.18d4f816039daf2d,"reason=FailedScheduling count=None msg=0/6 nodes are available: 2 c_wall violated: 2 conflicting context pair(s) with node memory, 4 node(s) had untolerated taint(s). no new claims to deallocate, preemption: 0/6 nodes are available: 2 No preemption victims found for incoming pod, 4 Preemption is not helpful for scheduling."
0.4427,Event,ADDED,eval-sanitize-30-r2-140-kftvh.18d4f81604d8c7b0,"reason=FailedScheduling count=None msg=0/6 nodes are available: 2 c_wall violated: 2 conflicting context pair(s) with node memory, 4 node(s) had untolerated taint(s). no new claims to deallocate, preemption: 0/6 nodes are available: 2 No preemption victims found for incoming pod, 4 Preemption is not helpful for scheduling."
0.4431,Event,ADDED,eval-sanitize-30-r2-140-kftvh.18d4f81639c515b1,"reason=FailedScheduling count=None msg=0/6 nodes are available: 1 c_wall violated: 2 conflicting context pair(s) with node memory, 5 node(s) had untolerated taint(s). no new claims to deallocate, preemption: 0/6 nodes are available: 1 No preemption victims found for incoming pod, 5 Preemption is not helpful for scheduling."
0.4436,Event,ADDED,eval-sanitize-30-r2-140-kftvh.18d4f81cb81a1140,"reason=FailedScheduling count=None msg=0/6 nodes are available: 1 c_wall violated: 1 conflicting context pair(s) with node memory, 5 node(s) had untolerated taint(s). no new claims to deallocate, preemption: 0/6 nodes are available: 1 No preemption victims found for incoming pod, 5 Preemption is not helpful for scheduling."
0.4439,Event,ADDED,eval-sanitize-30-r2-140-kftvh.18d4f81cf58a4bb9,"reason=FailedScheduling count=None msg=0/6 nodes are available: 2 c_wall violated: 2 conflicting context pair(s) with node memory, 4 node(s) had untolerated taint(s). no new claims to deallocate, preemption: 0/6 nodes are available: 2 No preemption victims found for incoming pod, 4 Preemption is not helpful for scheduling."
0.4441,Event,ADDED,eval-sanitize-30-r2-140-kftvh.18d4f81d41c68933,"reason=FailedScheduling count=None msg=0/6 nodes are available: 1 c_wall violated: 1 conflicting context pair(s) with node memory, 2 c_wall violated: 2 conflicting context pair(s) with node memory, 3 node(s) had untolerated taint(s). no new claims to deallocate, preemption: 0/6 nodes are available: 3 No preemption victims found for incoming pod, 3 Preemption is not helpful for scheduling."
0.4444,Event,ADDED,eval-sanitize-30-r2-140-kftvh.18d4f81d9c1fb06d,reason=Scheduled count=None msg=Successfully assigned compute/eval-sanitize-30-r2-140-kftvh to kind-worker2
0.4446,Event,ADDED,eval-sanitize-30-r2-140-kftvh.18d4f81dba8e262e,"reason=Pulled count=1 msg=Container image ""busybox:musl"" already present on machine"
0.4448,Event,ADDED,eval-sanitize-30-r2-140-kftvh.18d4f81dbc2ed705,reason=Created count=1 msg=Created container: task
0.4449,Event,ADDED,eval-sanitize-30-r2-140-kftvh.18d4f81dc254f0f5,reason=Started count=1 msg=Started container task
0.4451,Event,ADDED,eval-sanitize-30-r2-140.18d4f8160313784d,reason=SuccessfulCreate count=1 msg=Created pod: eval-sanitize-30-r2-140-kftvh
0.4453,Event,ADDED,eval-sanitize-30-r2-140.18d4f825090f3e0c,reason=Completed count=1 msg=Job completed
0.4454,Event,ADDED,eval-sanitize-30-r2-141-9t5c7.18d4f816378baf61,"reason=FailedScheduling count=None msg=0/6 nodes are available: 1 c_wall violated: 1 conflicting context pair(s) with node memory, 5 node(s) had untolerated taint(s). no new claims to deallocate, preemption: 0/6 nodes are available: 1 No preemption victims found for incoming pod, 5 Preemption is not helpful for scheduling."
0.4458,Event,ADDED,eval-sanitize-30-r2-141-9t5c7.18d4f81639fbedac,"reason=FailedScheduling count=None msg=0/6 nodes are available: 1 c_wall violated: 1 conflicting context pair(s) with node memory, 5 node(s) had untolerated taint(s). no new claims to deallocate, preemption: 0/6 nodes are available: 1 No preemption victims found for incoming pod, 5 Preemption is not helpful for scheduling."
0.4459,Event,ADDED,eval-sanitize-30-r2-141-9t5c7.18d4f81cb981dc11,reason=Scheduled count=None msg=Successfully assigned compute/eval-sanitize-30-r2-141-9t5c7 to kind-worker
0.4461,Event,ADDED,eval-sanitize-30-r2-141-9t5c7.18d4f81cd5d48a5b,"reason=Pulled count=1 msg=Container image ""busybox:musl"" already present on machine"
0.4463,Event,ADDED,eval-sanitize-30-r2-141-9t5c7.18d4f81cd93d89cd,reason=Created count=1 msg=Created container: task
0.4467,Event,ADDED,eval-sanitize-30-r2-141-9t5c7.18d4f81cde413fee,reason=Started count=1 msg=Started container task
0.447,Event,ADDED,eval-sanitize-30-r2-141.18d4f81636ea21df,reason=SuccessfulCreate count=1 msg=Created pod: eval-sanitize-30-r2-141-9t5c7
0.4472,Event,ADDED,eval-sanitize-30-r2-141.18d4f823ca469ce3,reason=Completed count=1 msg=Job completed
0.4475,Event,ADDED,eval-sanitize-30-r2-142-l7st2.18d4f816739c66a0,"reason=FailedScheduling count=None msg=0/6 nodes are available: 6 node(s) had untolerated taint(s). no new claims to deallocate, preemption: 0/6 nodes are available: 6 Preemption is not helpful for scheduling."
0.4478,Event,ADDED,eval-sanitize-30-r2-142-l7st2.18d4f81cb96ac4aa,"reason=FailedScheduling count=None msg=0/6 nodes are available: 1 c_wall violated: 2 conflicting context pair(s) with node memory, 5 node(s) had untolerated taint(s). no new claims to deallocate, preemption: 0/6 nodes are available: 1 No preemption victims found for incoming pod, 5 Preemption is not helpful for scheduling."
0.4481,Event,ADDED,eval-sanitize-30-r2-142-l7st2.18d4f81cfa219bea,"reason=FailedScheduling count=None msg=0/6 nodes are available: 1 c_wall violated: 1 conflicting context pair(s) with node memory, 1 c_wall violated: 2 conflicting context pair(s) with node memory, 4 node(s) had untolerated taint(s). no new claims to deallocate, preemption: 0/6 nodes are available: 2 No preemption victims found for incoming pod, 4 Preemption is not helpful for scheduling."
0.4483,Event,ADDED,eval-sanitize-30-r2-142-l7st2.18d4f81d481ae3ab,reason=Scheduled count=None msg=Successfully assigned compute/eval-sanitize-30-r2-142-l7st2 to kind-worker3
0.4487,Event,ADDED,eval-sanitize-30-r2-142-l7st2.18d4f81d642979a8,"reason=Pulled count=1 msg=Container image ""busybox:musl"" already present on machine"
0.4489,Event,ADDED,eval-sanitize-30-r2-142-l7st2.18d4f81d65828d8a,reason=Created count=1 msg=Created container: task
0.4492,Event,ADDED,eval-sanitize-30-r2-142-l7st2.18d4f81d69e6e303,reason=Started count=1 msg=Started container task
0.4498,Event,ADDED,eval-sanitize-30-r2-142.18d4f8167392af3f,reason=SuccessfulCreate count=1 msg=Created pod: eval-sanitize-30-r2-142-l7st2
0.4502,Event,ADDED,eval-sanitize-30-r2-142.18d4f824b58bbfe1,reason=Completed count=1 msg=Job completed
0.4504,Event,ADDED,eval-sanitize-30-r2-143-qf5bh.18d4f8169902ea6a,"reason=FailedScheduling count=None msg=0/6 nodes are available: 6 node(s) had untolerated taint(s). no new claims to deallocate, preemption: 0/6 nodes are available: 6 Preemption is not helpful for scheduling."
0.4506,Event,ADDED,eval-sanitize-30-r2-143-qf5bh.18d4f81cbacf26d7,reason=Scheduled count=None msg=Successfully assigned compute/eval-sanitize-30-r2-143-qf5bh to kind-worker
0.4511,Event,ADDED,eval-sanitize-30-r2-143-qf5bh.18d4f81cd51ebcc4,"reason=Pulled count=1 msg=Container image ""busybox:musl"" already present on machine"
0.4517,Event,ADDED,eval-sanitize-30-r2-143-qf5bh.18d4f81cd8239a44,reason=Created count=1 msg=Created container: task
0.452,Event,ADDED,eval-sanitize-30-r2-143-qf5bh.18d4f81cdcd5398f,reason=Started count=1 msg=Started container task
0.4523,Event,ADDED,eval-sanitize-30-r2-143.18d4f81698f982da,reason=SuccessfulCreate count=1 msg=Created pod: eval-sanitize-30-r2-143-qf5bh
0.4527,Event,ADDED,eval-sanitize-30-r2-143.18d4f8244fed06b2,reason=Completed count=1 msg=Job completed
0.453,Event,ADDED,eval-sanitize-30-r2-144-52fs9.18d4f816d3cdd370,"reason=FailedScheduling count=None msg=0/6 nodes are available: 6 node(s) had untolerated taint(s). no new claims to deallocate, preemption: 0/6 nodes are available: 6 Preemption is not helpful for scheduling."
0.4533,Event,ADDED,eval-sanitize-30-r2-144-52fs9.18d4f81cbe2c5891,reason=Scheduled count=None msg=Successfully assigned compute/eval-sanitize-30-r2-144-52fs9 to kind-worker
0.4537,Event,ADDED,eval-sanitize-30-r2-144-52fs9.18d4f81cdb51074c,"reason=Pulled count=1 msg=Container image ""busybox:musl"" already present on machine"
0.4539,Event,ADDED,eval-sanitize-30-r2-144-52fs9.18d4f81cde38f29d,reason=Created count=1 msg=Created container: task
0.4541,Event,ADDED,eval-sanitize-30-r2-144-52fs9.18d4f81ce4547372,reason=Started count=1 msg=Started container task
0.4543,Event,ADDED,eval-sanitize-30-r2-144.18d4f816d3c4ba80,reason=SuccessfulCreate count=1 msg=Created pod: eval-sanitize-30-r2-144-52fs9
0.4548,Event,ADDED,eval-sanitize-30-r2-144.18d4f824562e21b0,reason=Completed count=1 msg=Job completed
0.4552,Event,ADDED,eval-sanitize-30-r2-145-kxlk6.18d4f816ef92025c,"reason=FailedScheduling count=None msg=0/6 nodes are available: 6 node(s) had untolerated taint(s). no new claims to deallocate, preemption: 0/6 nodes are available: 6 Preemption is not helpful for scheduling."
0.4559,Event,ADDED,eval-sanitize-30-r2-145-kxlk6.18d4f81cbe6233e1,reason=Scheduled count=None msg=Successfully assigned compute/eval-sanitize-30-r2-145-kxlk6 to kind-worker
0.4563,Event,ADDED,eval-sanitize-30-r2-145-kxlk6.18d4f81cdd8838ac,"reason=Pulled count=1 msg=Container image ""busybox:musl"" already present on machine"
0.4566,Event,ADDED,eval-sanitize-30-r2-145-kxlk6.18d4f81ce1f64506,reason=Created count=1 msg=Created container: task
0.4569,Event,ADDED,eval-sanitize-30-r2-145-kxlk6.18d4f81ce7b89400,reason=Started count=1 msg=Started container task
0.4571,Event,ADDED,eval-sanitize-30-r2-145.18d4f816ef82db0c,reason=SuccessfulCreate count=1 msg=Created pod: eval-sanitize-30-r2-145-kxlk6
0.4578,Event,ADDED,eval-sanitize-30-r2-145.18d4f823c75fdfe7,reason=Completed count=1 msg=Job completed
0.4582,Event,ADDED,eval-sanitize-30-r2-146-k5kzr.18d4f8171c4a41e0,"reason=FailedScheduling count=None msg=0/6 nodes are available: 6 node(s) had untolerated taint(s). no new claims to deallocate, preemption: 0/6 nodes are available: 6 Preemption is not helpful for scheduling."
0.4586,Event,ADDED,eval-sanitize-30-r2-146-k5kzr.18d4f81cbf68007a,reason=Scheduled count=None msg=Successfully assigned compute/eval-sanitize-30-r2-146-k5kzr to kind-worker
0.4589,Event,ADDED,eval-sanitize-30-r2-146-k5kzr.18d4f81cdd458596,"reason=Pulled count=1 msg=Container image ""busybox:musl"" already present on machine"
0.4595,Event,ADDED,eval-sanitize-30-r2-146-k5kzr.18d4f81ce161be72,reason=Created count=1 msg=Created container: task
0.4598,Event,ADDED,eval-sanitize-30-r2-146-k5kzr.18d4f81ce70014fc,reason=Started count=1 msg=Started container task
0.46,Event,ADDED,eval-sanitize-30-r2-146.18d4f8171c390c96,reason=SuccessfulCreate count=1 msg=Created pod: eval-sanitize-30-r2-146-k5kzr
0.4606,Event,ADDED,eval-sanitize-30-r2-146.18d4f823cd60ff6d,reason=Completed count=1 msg=Job completed
0.4611,Event,ADDED,eval-sanitize-30-r2-147-7xjrn.18d4f8173d66997c,"reason=FailedScheduling count=None msg=0/6 nodes are available: 6 node(s) had untolerated taint(s). no new claims to deallocate, preemption: 0/6 nodes are available: 6 Preemption is not helpful for scheduling."
0.4616,Event,ADDED,eval-sanitize-30-r2-147-7xjrn.18d4f81cc46318e8,reason=Scheduled count=None msg=Successfully assigned compute/eval-sanitize-30-r2-147-7xjrn to kind-worker
0.462,Event,ADDED,eval-sanitize-30-r2-147-7xjrn.18d4f81ce03a1919,"reason=Pulled count=1 msg=Container image ""busybox:musl"" already present on machine"
0.4627,Event,ADDED,eval-sanitize-30-r2-147-7xjrn.18d4f81ce2d48aa6,reason=Created count=1 msg=Created container: task
0.4629,Event,ADDED,eval-sanitize-30-r2-147-7xjrn.18d4f81ce7b80ec1,reason=Started count=1 msg=Started container task
0.4631,Event,ADDED,eval-sanitize-30-r2-147.18d4f8173d5fa3d2,reason=SuccessfulCreate count=1 msg=Created pod: eval-sanitize-30-r2-147-7xjrn
0.4636,Event,ADDED,eval-sanitize-30-r2-147.18d4f823d8f98556,reason=Completed count=1 msg=Job completed
0.464,Event,ADDED,eval-sanitize-30-r2-148-7kq52.18d4f8175c9e3b38,"reason=FailedScheduling count=None msg=0/6 nodes are available: 6 node(s) had untolerated taint(s). no new claims to deallocate, preemption: 0/6 nodes are available: 6 Preemption is not helpful for scheduling."
0.4643,Event,ADDED,eval-sanitize-30-r2-148-7kq52.18d4f81cc49db501,reason=Scheduled count=None msg=Successfully assigned compute/eval-sanitize-30-r2-148-7kq52 to kind-worker
0.4647,Event,ADDED,eval-sanitize-30-r2-148-7kq52.18d4f81ce550ff35,"reason=Pulled count=1 msg=Container image ""busybox:musl"" already present on machine"
0.4652,Event,ADDED,eval-sanitize-30-r2-148-7kq52.18d4f81ce976512c,reason=Created count=1 msg=Created container: task
0.466,Event,ADDED,eval-sanitize-30-r2-148-7kq52.18d4f81cefce4220,reason=Started count=1 msg=Started container task
0.4664,Event,ADDED,eval-sanitize-30-r2-148.18d4f8175c98bcc0,reason=SuccessfulCreate count=1 msg=Created pod: eval-sanitize-30-r2-148-7kq52
0.4667,Event,ADDED,eval-sanitize-30-r2-148.18d4f8223935c024,reason=Completed count=1 msg=Job completed
0.467,Event,ADDED,eval-sanitize-30-r2-149-5f6ng.18d4f8177e7ae4d3,"reason=FailedScheduling count=None msg=0/6 nodes are available: 6 node(s) had untolerated taint(s). no new claims to deallocate, preemption: 0/6 nodes are available: 6 Preemption is not helpful for scheduling."
0.4671,Event,ADDED,eval-sanitize-30-r2-149-5f6ng.18d4f81cc498616c,"reason=FailedScheduling count=None msg=0/6 nodes are available: 1 c_wall violated: 2 conflicting context pair(s) with node memory, 5 node(s) had untolerated taint(s). no new claims to deallocate, preemption: 0/6 nodes are available: 1 No preemption victims found for incoming pod, 5 Preemption is not helpful for scheduling."
0.4673,Event,ADDED,eval-sanitize-30-r2-149-5f6ng.18d4f81cff2cc9fd,"reason=FailedScheduling count=None msg=0/6 nodes are available: 1 c_wall violated: 1 conflicting context pair(s) with node memory, 1 c_wall violated: 2 conflicting context pair(s) with node memory, 4 node(s) had untolerated taint(s). no new claims to deallocate, preemption: 0/6 nodes are available: 2 No preemption victims found for incoming pod, 4 Preemption is not helpful for scheduling."
0.4677,Event,ADDED,eval-sanitize-30-r2-149-5f6ng.18d4f81d4cf510ab,"reason=FailedScheduling count=None msg=0/6 nodes are available: 1 c_wall violated: 1 conflicting context pair(s) with node memory, 2 c_wall violated: 2 conflicting context pair(s) with node memory, 3 node(s) had untolerated taint(s). no new claims to deallocate, preemption: 0/6 nodes are available: 3 No preemption victims found for incoming pod, 3 Preemption is not helpful for scheduling."
0.468,Event,ADDED,eval-sanitize-30-r2-149-5f6ng.18d4f81da8301e9a,reason=Scheduled count=None msg=Successfully assigned compute/eval-sanitize-30-r2-149-5f6ng to kind-worker2
0.4683,Event,ADDED,eval-sanitize-30-r2-149-5f6ng.18d4f81dc2c26f96,"reason=Pulled count=1 msg=Container image ""busybox:musl"" already present on machine"
0.4689,Event,ADDED,eval-sanitize-30-r2-149-5f6ng.18d4f81dc4314cc8,reason=Created count=1 msg=Created container: task
0.4694,Event,ADDED,eval-sanitize-30-r2-149-5f6ng.18d4f81dc7fbf965,reason=Started count=1 msg=Started container task
0.4698,Event,ADDED,eval-sanitize-30-r2-149.18d4f8177e6a6fbc,reason=SuccessfulCreate count=1 msg=Created pod: eval-sanitize-30-r2-149-5f6ng
0.4702,Event,ADDED,eval-sanitize-30-r2-149.18d4f8250d2bdc0f,reason=Completed count=1 msg=Job completed
0.4708,Event,ADDED,eval-sanitize-30-r2-150-7zqgn.18d4f817a4cb89f4,"reason=FailedScheduling count=None msg=0/6 nodes are available: 6 node(s) had untolerated taint(s). no new claims to deallocate, preemption: 0/6 nodes are available: 6 Preemption is not helpful for scheduling."
0.4711,Event,ADDED,eval-sanitize-30-r2-150-7zqgn.18d4f81cc5d97bf0,reason=Scheduled count=None msg=Successfully assigned compute/eval-sanitize-30-r2-150-7zqgn to kind-worker
0.4715,Event,ADDED,eval-sanitize-30-r2-150-7zqgn.18d4f81ce8a89538,"reason=Pulled count=1 msg=Container image ""busybox:musl"" already present on machine"
0.4718,Event,ADDED,eval-sanitize-30-r2-150-7zqgn.18d4f81cea6ef394,reason=Created count=1 msg=Created container: task
0.4723,Event,ADDED,eval-sanitize-30-r2-150-7zqgn.18d4f81cf1dbd3ac,reason=Started count=1 msg=Started container task
0.4726,Event,ADDED,eval-sanitize-30-r2-150.18d4f817a4c0e5a1,reason=SuccessfulCreate count=1 msg=Created pod: eval-sanitize-30-r2-150-7zqgn
0.4729,Event,ADDED,eval-sanitize-30-r2-150.18d4f82238855e5a,reason=Completed count=1 msg=Job completed
0.4734,Event,ADDED,eval-sanitize-30-r2-151-7927h.18d4f817cf171da3,"reason=FailedScheduling count=None msg=0/6 nodes are available: 6 node(s) had untolerated taint(s). no new claims to deallocate, preemption: 0/6 nodes are available: 6 Preemption is not helpful for scheduling."
0.4737,Event,ADDED,eval-sanitize-30-r2-151-7927h.18d4f81cca34a188,reason=Scheduled count=None msg=Successfully assigned compute/eval-sanitize-30-r2-151-7927h to kind-worker
0.4739,Event,ADDED,eval-sanitize-30-r2-151-7927h.18d4f81cee2366c2,"reason=Pulled count=1 msg=Container image ""busybox:musl"" already present on machine"
0.4743,Event,ADDED,eval-sanitize-30-r2-151-7927h.18d4f81cf0fa4eba,reason=Created count=1 msg=Created container: task
0.4752,Event,ADDED,eval-sanitize-30-r2-151-7927h.18d4f81cf4859489,reason=Started count=1 msg=Started container task
0.4757,Event,ADDED,eval-sanitize-30-r2-151.18d4f817cf0da0c8,reason=SuccessfulCreate count=1 msg=Created pod: eval-sanitize-30-r2-151-7927h
0.4759,Event,ADDED,eval-sanitize-30-r2-151.18d4f8223933475a,reason=Completed count=1 msg=Job completed
0.4765,Event,ADDED,eval-sanitize-30-r2-152-4fvcl.18d4f81810701594,"reason=FailedScheduling count=None msg=0/6 nodes are available: 6 node(s) had untolerated taint(s). no new claims to deallocate, preemption: 0/6 nodes are available: 6 Preemption is not helpful for scheduling."
0.4768,Event,ADDED,eval-sanitize-30-r2-152-4fvcl.18d4f81cca86fe58,reason=Scheduled count=None msg=Successfully assigned compute/eval-sanitize-30-r2-152-4fvcl to kind-worker
0.4777,Event,ADDED,eval-sanitize-30-r2-152-4fvcl.18d4f81cefd8350d,"reason=Pulled count=1 msg=Container image ""busybox:musl"" already present on machine"
0.4781,Event,ADDED,eval-sanitize-30-r2-152-4fvcl.18d4f81cf3cf2cff,reason=Created count=1 msg=Created container: task
0.4787,Event,ADDED,eval-sanitize-30-r2-152-4fvcl.18d4f81cf754c9a7,reason=Started count=1 msg=Started container task
0.4797,Event,ADDED,eval-sanitize-30-r2-152.18d4f81810682a0b,reason=SuccessfulCreate count=1 msg=Created pod: eval-sanitize-30-r2-152-4fvcl
0.4803,Event,ADDED,eval-sanitize-30-r2-152.18d4f823dbf77954,reason=Completed count=1 msg=Job completed
0.4807,Event,ADDED,eval-sanitize-30-r2-153-m67r6.18d4f818463f8c82,"reason=FailedScheduling count=None msg=0/6 nodes are available: 6 node(s) had untolerated taint(s). no new claims to deallocate, preemption: 0/6 nodes are available: 6 Preemption is not helpful for scheduling."
0.4811,Event,ADDED,eval-sanitize-30-r2-153-m67r6.18d4f81ccadb6be3,reason=Scheduled count=None msg=Successfully assigned compute/eval-sanitize-30-r2-153-m67r6 to kind-worker
0.4818,Event,ADDED,eval-sanitize-30-r2-153-m67r6.18d4f81cef403ad2,"reason=Pulled count=1 msg=Container image ""busybox:musl"" already present on machine"
0.483,Event,ADDED,eval-sanitize-30-r2-153-m67r6.18d4f81cf2345a09,reason=Created count=1 msg=Created container: task
0.4838,Event,ADDED,eval-sanitize-30-r2-153-m67r6.18d4f81cf5e387a2,reason=Started count=1 msg=Started container task
0.4842,Event,ADDED,eval-sanitize-30-r2-153.18d4f8184637147e,reason=SuccessfulCreate count=1 msg=Created pod: eval-sanitize-30-r2-153-m67r6
0.4847,Event,ADDED,eval-sanitize-30-r2-153.18d4f8242ce1c165,reason=Completed count=1 msg=Job completed
0.4851,Event,ADDED,eval-sanitize-30-r2-154-pr8mm.18d4f8187b91c854,"reason=FailedScheduling count=None msg=0/6 nodes are available: 6 node(s) had untolerated taint(s). no new claims to deallocate, preemption: 0/6 nodes are available: 6 Preemption is not helpful for scheduling."
0.4858,Event,ADDED,eval-sanitize-30-r2-154-pr8mm.18d4f81ccb32879e,reason=Scheduled count=None msg=Successfully assigned compute/eval-sanitize-30-r2-154-pr8mm to kind-worker
0.4861,Event,ADDED,eval-sanitize-30-r2-154-pr8mm.18d4f81cefd661d9,"reason=Pulled count=1 msg=Container image ""busybox:musl"" already present on machine"
0.4864,Event,ADDED,eval-sanitize-30-r2-154-pr8mm.18d4f81cf31e9cf0,reason=Created count=1 msg=Created container: task
0.4866,Event,ADDED,eval-sanitize-30-r2-154-pr8mm.18d4f81cf6ff3e17,reason=Started count=1 msg=Started container task
0.487,Event,ADDED,eval-sanitize-30-r2-154.18d4f8187b8940c5,reason=SuccessfulCreate count=1 msg=Created pod: eval-sanitize-30-r2-154-pr8mm
0.4874,Event,ADDED,eval-sanitize-30-r2-154.18d4f82417a6fa33,reason=Completed count=1 msg=Job completed
0.4876,Event,ADDED,eval-sanitize-30-r2-155-4fr5l.18d4f818b9881064,"reason=FailedScheduling count=None msg=0/6 nodes are available: 6 node(s) had untolerated taint(s). no new claims to deallocate, preemption: 0/6 nodes are available: 6 Preemption is not helpful for scheduling."
0.488,Event,ADDED,eval-sanitize-30-r2-155-4fr5l.18d4f81ccadd4833,"reason=FailedScheduling count=None msg=0/6 nodes are available: 1 c_wall violated: 2 conflicting context pair(s) with node memory, 5 node(s) had untolerated taint(s). no new claims to deallocate, preemption: 0/6 nodes are available: 1 No preemption victims found for incoming pod, 5 Preemption is not helpful for scheduling."
0.4881,Event,ADDED,eval-sanitize-30-r2-155-4fr5l.18d4f81d00186c54,"reason=FailedScheduling count=None msg=0/6 nodes are available: 2 c_wall violated: 2 conflicting context pair(s) with node memory, 4 node(s) had untolerated taint(s). no new claims to deallocate, preemption: 0/6 nodes are available: 2 No preemption victims found for incoming pod, 4 Preemption is not helpful for scheduling."
0.4883,Event,ADDED,eval-sanitize-30-r2-155-4fr5l.18d4f81d52df89c7,"reason=FailedScheduling count=None msg=0/6 nodes are available: 1 c_wall violated: 1 conflicting context pair(s) with node memory, 2 c_wall violated: 2 conflicting context pair(s) with node memory, 3 node(s) had untolerated taint(s). no new claims to deallocate, preemption: 0/6 nodes are available: 3 No preemption victims found for incoming pod, 3 Preemption is not helpful for scheduling."
0.4886,Event,ADDED,eval-sanitize-30-r2-155-4fr5l.18d4f81dca715ed9,reason=Scheduled count=None msg=Successfully assigned compute/eval-sanitize-30-r2-155-4fr5l to kind-worker5
0.4889,Event,ADDED,eval-sanitize-30-r2-155-4fr5l.18d4f81de83c9d61,"reason=Pulled count=1 msg=Container image ""busybox:musl"" already present on machine"
0.4891,Event,ADDED,eval-sanitize-30-r2-155-4fr5l.18d4f81dea92a81e,reason=Created count=1 msg=Created container: task
0.4893,Event,ADDED,eval-sanitize-30-r2-155-4fr5l.18d4f81defd7c6a5,reason=Started count=1 msg=Started container task
0.4899,Event,ADDED,eval-sanitize-30-r2-155.18d4f818b97c0f11,reason=SuccessfulCreate count=1 msg=Created pod: eval-sanitize-30-r2-155-4fr5l
0.4905,Event,ADDED,eval-sanitize-30-r2-155.18d4f825129d8553,reason=Completed count=1 msg=Job completed
0.4909,Event,ADDED,eval-sanitize-30-r2-156-h54mk.18d4f818f4e249c8,"reason=FailedScheduling count=None msg=0/6 nodes are available: 6 node(s) had untolerated taint(s). no new claims to deallocate, preemption: 0/6 nodes are available: 6 Preemption is not helpful for scheduling."
0.4913,Event,ADDED,eval-sanitize-30-r2-156-h54mk.18d4f81ccfab1829,"reason=FailedScheduling count=None msg=0/6 nodes are available: 1 c_wall violated: 2 conflicting context pair(s) with node memory, 5 node(s) had untolerated taint(s). no new claims to deallocate, preemption: 0/6 nodes are available: 1 No preemption victims found for incoming pod, 5 Preemption is not helpful for scheduling."
0.4915,Event,ADDED,eval-sanitize-30-r2-156-h54mk.18d4f81d010e93ab,"reason=FailedScheduling count=None msg=0/6 nodes are available: 2 c_wall violated: 2 conflicting context pair(s) with node memory, 4 node(s) had untolerated taint(s). no new claims to deallocate, preemption: 0/6 nodes are available: 2 No preemption victims found for incoming pod, 4 Preemption is not helpful for scheduling."
0.4918,Event,ADDED,eval-sanitize-30-r2-156-h54mk.18d4f81d594f5125,reason=Scheduled count=None msg=Successfully assigned compute/eval-sanitize-30-r2-156-h54mk to kind-worker3
0.492,Event,ADDED,eval-sanitize-30-r2-156-h54mk.18d4f81d751ed9d5,"reason=Pulled count=1 msg=Container image ""busybox:musl"" already present on machine"
0.4923,Event,ADDED,eval-sanitize-30-r2-156-h54mk.18d4f81d7697fb9c,reason=Created count=1 msg=Created container: task
0.4925,Event,ADDED,eval-sanitize-30-r2-156-h54mk.18d4f81d7b5b9e86,reason=Started count=1 msg=Started container task
0.4927,Event,ADDED,eval-sanitize-30-r2-156.18d4f818f4d79cad,reason=SuccessfulCreate count=1 msg=Created pod: eval-sanitize-30-r2-156-h54mk
0.4931,Event,ADDED,eval-sanitize-30-r2-156.18d4f824be9760f6,reason=Completed count=1 msg=Job completed
0.4933,Event,ADDED,eval-sanitize-30-r2-157-xmzx6.18d4f8192def3fc7,"reason=FailedScheduling count=None msg=0/6 nodes are available: 6 node(s) had untolerated taint(s). no new claims to deallocate, preemption: 0/6 nodes are available: 6 Preemption is not helpful for scheduling."
0.4934,Event,ADDED,eval-sanitize-30-r2-157-xmzx6.18d4f81cd0790c4a,"reason=FailedScheduling count=None msg=0/6 nodes are available: 1 c_wall violated: 2 conflicting context pair(s) with node memory, 5 node(s) had untolerated taint(s). no new claims to deallocate, preemption: 0/6 nodes are available: 1 No preemption victims found for incoming pod, 5 Preemption is not helpful for scheduling."
0.4939,Event,ADDED,eval-sanitize-30-r2-157-xmzx6.18d4f81d06761332,"reason=FailedScheduling count=None msg=0/6 nodes are available: 1 c_wall violated: 1 conflicting context pair(s) with node memory, 1 c_wall violated: 2 conflicting context pair(s) with node memory, 4 node(s) had untolerated taint(s). no new claims to deallocate, preemption: 0/6 nodes are available: 2 No preemption victims found for incoming pod, 4 Preemption is not helpful for scheduling."
0.4944,Event,ADDED,eval-sanitize-30-r2-157-xmzx6.18d4f81d5efe6614,reason=Scheduled count=None msg=Successfully assigned compute/eval-sanitize-30-r2-157-xmzx6 to kind-worker5
0.4947,Event,ADDED,eval-sanitize-30-r2-157-xmzx6.18d4f81d79fbed8a,"reason=Pulled count=1 msg=Container image ""busybox:musl"" already present on machine"
0.495,Event,ADDED,eval-sanitize-30-r2-157-xmzx6.18d4f81d7ba3219a,reason=Created count=1 msg=Created container: task
0.4956,Event,ADDED,eval-sanitize-30-r2-157-xmzx6.18d4f81d81560432,reason=Started count=1 msg=Started container task
0.4959,Event,ADDED,eval-sanitize-30-r2-157.18d4f8192de61b7c,reason=SuccessfulCreate count=1 msg=Created pod: eval-sanitize-30-r2-157-xmzx6
0.4964,Event,ADDED,eval-sanitize-30-r2-157.18d4f824c7f01a9f,reason=Completed count=1 msg=Job completed
0.4967,Event,ADDED,eval-sanitize-30-r2-158-9lqfr.18d4f8196972adb0,"reason=FailedScheduling count=None msg=0/6 nodes are available: 6 node(s) had untolerated taint(s). no new claims to deallocate, preemption: 0/6 nodes are available: 6 Preemption is not helpful for scheduling."
0.4971,Event,ADDED,eval-sanitize-30-r2-158-9lqfr.18d4f81cd111ceb8,"reason=FailedScheduling count=None msg=0/6 nodes are available: 1 c_wall violated: 2 conflicting context pair(s) with node memory, 5 node(s) had untolerated taint(s). no new claims to deallocate, preemption: 0/6 nodes are available: 1 No preemption victims found for incoming pod, 5 Preemption is not helpful for scheduling."
0.4974,Event,ADDED,eval-sanitize-30-r2-158-9lqfr.18d4f81d0c100ecf,"reason=FailedScheduling count=None msg=0/6 nodes are available: 1 c_wall violated: 1 conflicting context pair(s) with node memory, 1 c_wall violated: 2 conflicting context pair(s) with node memory, 4 node(s) had untolerated taint(s). no new claims to deallocate, preemption: 0/6 nodes are available: 2 No preemption victims found for incoming pod, 4 Preemption is not helpful for scheduling."
0.4977,Event,ADDED,eval-sanitize-30-r2-158-9lqfr.18d4f81d65e1873f,reason=Scheduled count=None msg=Successfully assigned compute/eval-sanitize-30-r2-158-9lqfr to kind-worker5
0.4981,Event,ADDED,eval-sanitize-30-r2-158-9lqfr.18d4f81d82fe86fe,"reason=Pulled count=1 msg=Container image ""busybox:musl"" already present on machine"
0.5062,Event,ADDED,eval-sanitize-30-r2-158-9lqfr.18d4f81d847d6d06,reason=Created count=1 msg=Created container: task
0.507,Event,ADDED,eval-sanitize-30-r2-158-9lqfr.18d4f81d86db9477,reason=Started count=1 msg=Started container task
0.5076,Event,ADDED,eval-sanitize-30-r2-158.18d4f8196967fdee,reason=SuccessfulCreate count=1 msg=Created pod: eval-sanitize-30-r2-158-9lqfr
0.5082,Event,ADDED,eval-sanitize-30-r2-158.18d4f824ca646c3a,reason=Completed count=1 msg=Job completed
0.5085,Event,ADDED,eval-sanitize-30-r2-159-hqhpj.18d4f819a59cf269,"reason=FailedScheduling count=None msg=0/6 nodes are available: 6 node(s) had untolerated taint(s). no new claims to deallocate, preemption: 0/6 nodes are available: 6 Preemption is not helpful for scheduling."
0.5088,Event,ADDED,eval-sanitize-30-r2-159-hqhpj.18d4f81cd273e21c,reason=Scheduled count=None msg=Successfully assigned compute/eval-sanitize-30-r2-159-hqhpj to kind-worker
0.5093,Event,ADDED,eval-sanitize-30-r2-159-hqhpj.18d4f81cf3d16596,"reason=Pulled count=1 msg=Container image ""busybox:musl"" already present on machine"
0.5097,Event,ADDED,eval-sanitize-30-r2-159-hqhpj.18d4f81cf66e1ae4,reason=Created count=1 msg=Created container: task
0.5101,Event,ADDED,eval-sanitize-30-r2-159-hqhpj.18d4f81cfbdb59b5,reason=Started count=1 msg=Started container task
0.5105,Event,ADDED,eval-sanitize-30-r2-159.18d4f819a5973a8c,reason=SuccessfulCreate count=1 msg=Created pod: eval-sanitize-30-r2-159-hqhpj
0.5114,Event,ADDED,eval-sanitize-30-r2-159.18d4f823b2edc834,reason=Completed count=1 msg=Job completed
0.5116,Event,ADDED,eval-sanitize-30-r2-160-mwdvx.18d4f819e20f8b2e,"reason=FailedScheduling count=None msg=0/6 nodes are available: 6 node(s) had untolerated taint(s). no new claims to deallocate, preemption: 0/6 nodes are available: 6 Preemption is not helpful for scheduling."
0.5119,Event,ADDED,eval-sanitize-30-r2-160-mwdvx.18d4f81cd59d6ec4,"reason=FailedScheduling count=None msg=0/6 nodes are available: 1 c_wall violated: 2 conflicting context pair(s) with node memory, 5 node(s) had untolerated taint(s). no new claims to deallocate, preemption: 0/6 nodes are available: 1 No preemption victims found for incoming pod, 5 Preemption is not helpful for scheduling."
0.5123,Event,ADDED,eval-sanitize-30-r2-160-mwdvx.18d4f81d0d7cb663,reason=Scheduled count=None msg=Successfully assigned compute/eval-sanitize-30-r2-160-mwdvx to kind-worker3
0.5126,Event,ADDED,eval-sanitize-30-r2-160-mwdvx.18d4f81d2e3ea8e7,"reason=Pulled count=1 msg=Container image ""busybox:musl"" already present on machine"
0.5129,Event,ADDED,eval-sanitize-30-r2-160-mwdvx.18d4f81d2fc3251a,reason=Created count=1 msg=Created container: task
0.5132,Event,ADDED,eval-sanitize-30-r2-160-mwdvx.18d4f81d3292d7c0,reason=Started count=1 msg=Started container task
0.5137,Event,ADDED,eval-sanitize-30-r2-160.18d4f819e200f748,reason=SuccessfulCreate count=1 msg=Created pod: eval-sanitize-30-r2-160-mwdvx
0.514,Event,ADDED,eval-sanitize-30-r2-160.18d4f824327af9ea,reason=Completed count=1 msg=Job completed
0.5143,Event,ADDED,eval-sanitize-30-r2-161-5nkcd.18d4f81a1c327b8c,"reason=FailedScheduling count=None msg=0/6 nodes are available: 6 node(s) had untolerated taint(s). no new claims to deallocate, preemption: 0/6 nodes are available: 6 Preemption is not helpful for scheduling."
0.5147,Event,ADDED,eval-sanitize-30-r2-161-5nkcd.18d4f81cd67fd103,"reason=FailedScheduling count=None msg=0/6 nodes are available: 1 c_wall violated: 2 conflicting context pair(s) with node memory, 5 node(s) had untolerated taint(s). no new claims to deallocate, preemption: 0/6 nodes are available: 1 No preemption victims found for incoming pod, 5 Preemption is not helpful for scheduling."
0.5152,Event,ADDED,eval-sanitize-30-r2-161-5nkcd.18d4f81d12eb3aa5,reason=Scheduled count=None msg=Successfully assigned compute/eval-sanitize-30-r2-161-5nkcd to kind-worker3
0.5162,Event,ADDED,eval-sanitize-30-r2-161-5nkcd.18d4f81d2fc96e19,"reason=Pulled count=1 msg=Container image ""busybox:musl"" already present on machine"
0.5165,Event,ADDED,eval-sanitize-30-r2-161-5nkcd.18d4f81d31c187ec,reason=Created count=1 msg=Created container: task
0.5171,Event,ADDED,eval-sanitize-30-r2-161-5nkcd.18d4f81d346c91e9,reason=Started count=1 msg=Started container task
0.5176,Event,ADDED,eval-sanitize-30-r2-161.18d4f81a1c287bdf,reason=SuccessfulCreate count=1 msg=Created pod: eval-sanitize-30-r2-161-5nkcd
0.5179,Event,ADDED,eval-sanitize-30-r2-161.18d4f82480d5a0c8,reason=Completed count=1 msg=Job completed
0.5182,Event,ADDED,eval-sanitize-30-r2-162-xpcdj.18d4f81a57efe14f,"reason=FailedScheduling count=None msg=0/6 nodes are available: 6 node(s) had untolerated taint(s). no new claims to deallocate, preemption: 0/6 nodes are available: 6 Preemption is not helpful for scheduling."
0.5185,Event,ADDED,eval-sanitize-30-r2-162-xpcdj.18d4f81cd7388006,"reason=FailedScheduling count=None msg=0/6 nodes are available: 1 c_wall violated: 2 conflicting context pair(s) with node memory, 5 node(s) had untolerated taint(s). no new claims to deallocate, preemption: 0/6 nodes are available: 1 No preemption victims found for incoming pod, 5 Preemption is not helpful for scheduling."
0.5187,Event,ADDED,eval-sanitize-30-r2-162-xpcdj.18d4f81d18c91278,reason=Scheduled count=None msg=Successfully assigned compute/eval-sanitize-30-r2-162-xpcdj to kind-worker3
0.5188,Event,ADDED,eval-sanitize-30-r2-162-xpcdj.18d4f81d31c72e66,"reason=Pulled count=1 msg=Container image ""busybox:musl"" already present on machine"
0.5192,Event,ADDED,eval-sanitize-30-r2-162-xpcdj.18d4f81d3365ff70,reason=Created count=1 msg=Created container: task
0.5194,Event,ADDED,eval-sanitize-30-r2-162-xpcdj.18d4f81d3821c70b,reason=Started count=1 msg=Started container task
0.5196,Event,ADDED,eval-sanitize-30-r2-162.18d4f81a57ea21e5,reason=SuccessfulCreate count=1 msg=Created pod: eval-sanitize-30-r2-162-xpcdj
0.5198,Event,ADDED,eval-sanitize-30-r2-162.18d4f8247ced7630,reason=Completed count=1 msg=Job completed
0.52,Event,ADDED,eval-sanitize-30-r2-163-764gq.18d4f81a93564519,"reason=FailedScheduling count=None msg=0/6 nodes are available: 6 node(s) had untolerated taint(s). no new claims to deallocate, preemption: 0/6 nodes are available: 6 Preemption is not helpful for scheduling."
0.5203,Event,ADDED,eval-sanitize-30-r2-163-764gq.18d4f81cd816d882,"reason=FailedScheduling count=None msg=0/6 nodes are available: 1 c_wall violated: 2 conflicting context pair(s) with node memory, 5 node(s) had untolerated taint(s). no new claims to deallocate, preemption: 0/6 nodes are available: 1 No preemption victims found for incoming pod, 5 Preemption is not helpful for scheduling."
0.5205,Event,ADDED,eval-sanitize-30-r2-163-764gq.18d4f81d1de93012,"reason=FailedScheduling count=None msg=0/6 nodes are available: 1 c_wall violated: 1 conflicting context pair(s) with node memory, 2 c_wall violated: 2 conflicting context pair(s) with node memory, 3 node(s) had untolerated taint(s). no new claims to deallocate, preemption: 0/6 nodes are available: 3 No preemption victims found for incoming pod, 3 Preemption is not helpful for scheduling."
0.5206,Event,ADDED,eval-sanitize-30-r2-163-764gq.18d4f81d77cf7a26,reason=Scheduled count=None msg=Successfully assigned compute/eval-sanitize-30-r2-163-764gq to kind-worker5
0.5211,Event,ADDED,eval-sanitize-30-r2-163-764gq.18d4f81d9344eef3,"reason=Pulled count=1 msg=Container image ""busybox:musl"" already present on machine"
0.5216,Event,ADDED,eval-sanitize-30-r2-163-764gq.18d4f81d94c7385c,reason=Created count=1 msg=Created container: task
0.5224,Event,ADDED,eval-sanitize-30-r2-163-764gq.18d4f81d990d461b,reason=Started count=1 msg=Started container task
0.5229,Event,ADDED,eval-sanitize-30-r2-163.18d4f81a9349ba6a,reason=SuccessfulCreate count=1 msg=Created pod: eval-sanitize-30-r2-163-764gq
0.5234,Event,ADDED,eval-sanitize-30-r2-163.18d4f82500a1fb49,reason=Completed count=1 msg=Job completed
0.5239,Event,ADDED,eval-sanitize-30-r2-164-blr68.18d4f81ad0a9d964,"reason=FailedScheduling count=None msg=0/6 nodes are available: 6 node(s) had untolerated taint(s). no new claims to deallocate, preemption: 0/6 nodes are available: 6 Preemption is not helpful for scheduling."
0.5242,Event,ADDED,eval-sanitize-30-r2-164-blr68.18d4f81cdb9acc30,"reason=FailedScheduling count=None msg=0/6 nodes are available: 1 c_wall violated: 2 conflicting context pair(s) with node memory, 5 node(s) had untolerated taint(s). no new claims to deallocate, preemption: 0/6 nodes are available: 1 No preemption victims found for incoming pod, 5 Preemption is not helpful for scheduling."
0.5244,Event,ADDED,eval-sanitize-30-r2-164-blr68.18d4f81d24863b6f,reason=Scheduled count=None msg=Successfully assigned compute/eval-sanitize-30-r2-164-blr68 to kind-worker3
0.5247,Event,ADDED,eval-sanitize-30-r2-164-blr68.18d4f81d3f95a689,"reason=Pulled count=1 msg=Container image ""busybox:musl"" already present on machine"
0.525,Event,ADDED,eval-sanitize-30-r2-164-blr68.18d4f81d4145496b,reason=Created count=1 msg=Created container: task
0.5252,Event,ADDED,eval-sanitize-30-r2-164-blr68.18d4f81d479996b9,reason=Started count=1 msg=Started container task
0.5257,Event,ADDED,eval-sanitize-30-r2-164.18d4f81ad08a69b3,reason=SuccessfulCreate count=1 msg=Created pod: eval-sanitize-30-r2-164-blr68
0.526,Event,ADDED,eval-sanitize-30-r2-164.18d4f8244575ecfe,reason=Completed count=1 msg=Job completed
0.5262,Event,ADDED,eval-sanitize-30-r2-165-skcnc.18d4f81b0d3d7400,"reason=FailedScheduling count=None msg=0/6 nodes are available: 6 node(s) had untolerated taint(s). no new claims to deallocate, preemption: 0/6 nodes are available: 6 Preemption is not helpful for scheduling."
0.5264,Event,ADDED,eval-sanitize-30-r2-165-skcnc.18d4f81cdc941c40,"reason=FailedScheduling count=None msg=0/6 nodes are available: 1 c_wall violated: 2 conflicting context pair(s) with node memory, 5 node(s) had untolerated taint(s). no new claims to deallocate, preemption: 0/6 nodes are available: 1 No preemption victims found for incoming pod, 5 Preemption is not helpful for scheduling."
0.5268,Event,ADDED,eval-sanitize-30-r2-165-skcnc.18d4f81d29e56713,"reason=FailedScheduling count=None msg=0/6 nodes are available: 1 c_wall violated: 1 conflicting context pair(s) with node memory, 2 c_wall violated: 2 conflicting context pair(s) with node memory, 3 node(s) had untolerated taint(s). no new claims to deallocate, preemption: 0/6 nodes are available: 3 No preemption victims found for incoming pod, 3 Preemption is not helpful for scheduling."
0.5271,Event,ADDED,eval-sanitize-30-r2-165-skcnc.18d4f81d7e0b2e5e,reason=Scheduled count=None msg=Successfully assigned compute/eval-sanitize-30-r2-165-skcnc to kind-worker2
0.5277,Event,ADDED,eval-sanitize-30-r2-165-skcnc.18d4f81d99367028,"reason=Pulled count=1 msg=Container image ""busybox:musl"" already present on machine"
0.5282,Event,ADDED,eval-sanitize-30-r2-165-skcnc.18d4f81d9a9292e0,reason=Created count=1 msg=Created container: task
0.5287,Event,ADDED,eval-sanitize-30-r2-165-skcnc.18d4f81da027de31,reason=Started count=1 msg=Started container task
0.5291,Event,ADDED,eval-sanitize-30-r2-165.18d4f81b0d305393,reason=SuccessfulCreate count=1 msg=Created pod: eval-sanitize-30-r2-165-skcnc
0.5295,Event,ADDED,eval-sanitize-30-r2-165.18d4f824e82e3be3,reason=Completed count=1 msg=Job completed
0.5299,Event,ADDED,eval-sanitize-30-r2-166-tktl6.18d4f81b48ab6f73,"reason=FailedScheduling count=None msg=0/6 nodes are available: 6 node(s) had untolerated taint(s). no new claims to deallocate, preemption: 0/6 nodes are available: 6 Preemption is not helpful for scheduling."
0.5303,Event,ADDED,eval-sanitize-30-r2-166-tktl6.18d4f81cde09fd15,reason=Scheduled count=None msg=Successfully assigned compute/eval-sanitize-30-r2-166-tktl6 to kind-worker
0.5307,Event,ADDED,eval-sanitize-30-r2-166-tktl6.18d4f81cfc52c46d,"reason=Pulled count=1 msg=Container image ""busybox:musl"" already present on machine"
0.5311,Event,ADDED,eval-sanitize-30-r2-166-tktl6.18d4f81cfd9fb436,reason=Created count=1 msg=Created container: task
0.5313,Event,ADDED,eval-sanitize-30-r2-166-tktl6.18d4f81d03aaf6da,reason=Started count=1 msg=Started container task
0.5315,Event,ADDED,eval-sanitize-30-r2-166.18d4f81b4896a0d7,reason=SuccessfulCreate count=1 msg=Created pod: eval-sanitize-30-r2-166-tktl6
0.5319,Event,ADDED,eval-sanitize-30-r2-166.18d4f8246817c6da,reason=Completed count=1 msg=Job completed
0.5323,Event,ADDED,eval-sanitize-30-r2-167-z7j2d.18d4f81b81d56d9a,"reason=FailedScheduling count=None msg=0/6 nodes are available: 6 node(s) had untolerated taint(s). no new claims to deallocate, preemption: 0/6 nodes are available: 6 Preemption is not helpful for scheduling."
0.5331,Event,ADDED,eval-sanitize-30-r2-167-z7j2d.18d4f81ce2193428,reason=Scheduled count=None msg=Successfully assigned compute/eval-sanitize-30-r2-167-z7j2d to kind-worker
0.5337,Event,ADDED,eval-sanitize-30-r2-167-z7j2d.18d4f81d03a2503d,"reason=Pulled count=1 msg=Container image ""busybox:musl"" already present on machine"
0.5343,Event,ADDED,eval-sanitize-30-r2-167-z7j2d.18d4f81d053b387f,reason=Created count=1 msg=Created container: task
0.535,Event,ADDED,eval-sanitize-30-r2-167-z7j2d.18d4f81d0886cab4,reason=Started count=1 msg=Started container task
0.5353,Event,ADDED,eval-sanitize-30-r2-167.18d4f81b81cc5125,reason=SuccessfulCreate count=1 msg=Created pod: eval-sanitize-30-r2-167-z7j2d
0.5357,Event,ADDED,eval-sanitize-30-r2-167.18d4f822389149c4,reason=Completed count=1 msg=Job completed
0.5361,Event,ADDED,eval-sanitize-30-r2-168-5jml9.18d4f81bbdd5fb7c,"reason=FailedScheduling count=None msg=0/6 nodes are available: 6 node(s) had untolerated taint(s). no new claims to deallocate, preemption: 0/6 nodes are available: 6 Preemption is not helpful for scheduling."
0.5363,Event,ADDED,eval-sanitize-30-r2-168-5jml9.18d4f81ce3b5730d,"reason=FailedScheduling count=None msg=0/6 nodes are available: 1 c_wall violated: 2 conflicting context pair(s) with node memory, 5 node(s) had untolerated taint(s). no new claims to deallocate, preemption: 0/6 nodes are available: 1 No preemption victims found for incoming pod, 5 Preemption is not helpful for scheduling."
0.5365,Event,ADDED,eval-sanitize-30-r2-168-5jml9.18d4f81d35cfc156,"reason=FailedScheduling count=None msg=0/6 nodes are available: 1 c_wall violated: 1 conflicting context pair(s) with node memory, 2 c_wall violated: 2 conflicting context pair(s) with node memory, 3 node(s) had untolerated taint(s). no new claims to deallocate, preemption: 0/6 nodes are available: 3 No preemption victims found for incoming pod, 3 Preemption is not helpful for scheduling."
0.5368,Event,ADDED,eval-sanitize-30-r2-168-5jml9.18d4f81d8fa789b7,"reason=FailedScheduling count=None msg=0/6 nodes are available: 1 node(s) had untolerated taint(s), 2 c_wall violated: 2 conflicting context pair(s) with node memory, 3 c_wall violated: 1 conflicting context pair(s) with node memory. no new claims to deallocate, preemption: 0/6 nodes are available: 1 Preemption is not helpful for scheduling, 5 No preemption victims found for incoming pod."
0.537,Event,ADDED,eval-sanitize-30-r2-168-5jml9.18d4f81dd1279213,"reason=FailedScheduling count=None msg=0/6 nodes are available: 1 node(s) had untolerated taint(s), 2 c_wall violated: 1 conflicting context pair(s) with node memory, 3 c_wall violated: 2 conflicting context pair(s) with node memory. no new claims to deallocate, preemption: 0/6 nodes are available: 1 Preemption is not helpful for scheduling, 5 No preemption victims found for incoming pod."
0.5373,Event,ADDED,eval-sanitize-30-r2-168-5jml9.18d4f81ddcea2977,"reason=FailedScheduling count=None msg=0/6 nodes are available: 1 node(s) had untolerated taint(s), 2 c_wall violated: 1 conflicting context pair(s) with node memory, 3 c_wall violated: 2 conflicting context pair(s) with node memory. no new claims to deallocate, preemption: 0/6 nodes are available: 1 Preemption is not helpful for scheduling, 5 No preemption victims found for incoming pod."
0.5374,Event,ADDED,eval-sanitize-30-r2-168-5jml9.18d4f823f10c08fa,reason=Scheduled count=None msg=Successfully assigned compute/eval-sanitize-30-r2-168-5jml9 to kind-worker
0.5377,Event,ADDED,eval-sanitize-30-r2-168-5jml9.18d4f8240c186971,"reason=Pulled count=1 msg=Container image ""busybox:musl"" already present on machine"
0.538,Event,ADDED,eval-sanitize-30-r2-168-5jml9.18d4f8240d759cb5,reason=Created count=1 msg=Created container: task
0.5381,Event,ADDED,eval-sanitize-30-r2-168-5jml9.18d4f824131a0ed7,reason=Started count=1 msg=Started container task
0.5384,Event,ADDED,eval-sanitize-30-r2-168.18d4f81bbdcb6ada,reason=SuccessfulCreate count=1 msg=Created pod: eval-sanitize-30-r2-168-5jml9
0.5387,Event,ADDED,eval-sanitize-30-r2-168.18d4f829b04788de,reason=Completed count=1 msg=Job completed
0.539,Event,ADDED,eval-sanitize-30-r2-169-jmtw6.18d4f81bf92c3a54,"reason=FailedScheduling count=None msg=0/6 nodes are available: 6 node(s) had untolerated taint(s). no new claims to deallocate, preemption: 0/6 nodes are available: 6 Preemption is not helpful for scheduling."
0.5392,Event,ADDED,eval-sanitize-30-r2-169-jmtw6.18d4f81cec6432dc,reason=Scheduled count=None msg=Successfully assigned compute/eval-sanitize-30-r2-169-jmtw6 to kind-worker4
0.5396,Event,ADDED,eval-sanitize-30-r2-169-jmtw6.18d4f81d048cd24d,"reason=Pulled count=1 msg=Container image ""busybox:musl"" already present on machine"
0.5398,Event,ADDED,eval-sanitize-30-r2-169-jmtw6.18d4f81d0650b885,reason=Created count=1 msg=Created container: task
0.54,Event,ADDED,eval-sanitize-30-r2-169-jmtw6.18d4f81d0a541c7d,reason=Started count=1 msg=Started container task
0.5403,Event,ADDED,eval-sanitize-30-r2-169.18d4f81bf922eccf,reason=SuccessfulCreate count=1 msg=Created pod: eval-sanitize-30-r2-169-jmtw6
0.5406,Event,ADDED,eval-sanitize-30-r2-169.18d4f823e1f09b8e,reason=Completed count=1 msg=Job completed
0.5409,Event,ADDED,eval-sanitize-30-r2-170-l8rf2.18d4f81c3578a1ba,"reason=FailedScheduling count=None msg=0/6 nodes are available: 6 node(s) had untolerated taint(s). no new claims to deallocate, preemption: 0/6 nodes are available: 6 Preemption is not helpful for scheduling."
0.5412,Event,ADDED,eval-sanitize-30-r2-170-l8rf2.18d4f81ced511c46,reason=Scheduled count=None msg=Successfully assigned compute/eval-sanitize-30-r2-170-l8rf2 to kind-worker4
0.5417,Event,ADDED,eval-sanitize-30-r2-170-l8rf2.18d4f81d081c1e49,"reason=Pulled count=1 msg=Container image ""busybox:musl"" already present on machine"
0.5419,Event,ADDED,eval-sanitize-30-r2-170-l8rf2.18d4f81d0a08a08e,reason=Created count=1 msg=Created container: task
0.5421,Event,ADDED,eval-sanitize-30-r2-170-l8rf2.18d4f81d10223aff,reason=Started count=1 msg=Started container task
0.5425,Event,ADDED,eval-sanitize-30-r2-170.18d4f81c356cddba,reason=SuccessfulCreate count=1 msg=Created pod: eval-sanitize-30-r2-170-l8rf2
0.5427,Event,ADDED,eval-sanitize-30-r2-170.18d4f824d971463e,reason=Completed count=1 msg=Job completed
0.5428,Event,ADDED,eval-sanitize-30-r2-171-78khk.18d4f81c7033c540,"reason=FailedScheduling count=None msg=0/6 nodes are available: 6 node(s) had untolerated taint(s). no new claims to deallocate, preemption: 0/6 nodes are available: 6 Preemption is not helpful for scheduling."
0.543,Event,ADDED,eval-sanitize-30-r2-171-78khk.18d4f81cf0033027,reason=Scheduled count=None msg=Successfully assigned compute/eval-sanitize-30-r2-171-78khk to kind-worker4
0.5434,Event,ADDED,eval-sanitize-30-r2-171-78khk.18d4f81d0bd5d32e,"reason=Pulled count=1 msg=Container image ""busybox:musl"" already present on machine"
0.5435,Event,ADDED,eval-sanitize-30-r2-171-78khk.18d4f81d0d6239e1,reason=Created count=1 msg=Created container: task
0.5437,Event,ADDED,eval-sanitize-30-r2-171-78khk.18d4f81d12798ed0,reason=Started count=1 msg=Started container task
0.5439,Event,ADDED,eval-sanitize-30-r2-171.18d4f81c702d0f1c,reason=SuccessfulCreate count=1 msg=Created pod: eval-sanitize-30-r2-171-78khk
0.5443,Event,ADDED,eval-sanitize-30-r2-171.18d4f824e5df9e9e,reason=Completed count=1 msg=Job completed
0.5447,Event,ADDED,eval-sanitize-30-r2-172-l8xfh.18d4f81cac1d35dd,"reason=FailedScheduling count=None msg=0/6 nodes are available: 6 node(s) had untolerated taint(s). no new claims to deallocate, preemption: 0/6 nodes are available: 6 Preemption is not helpful for scheduling."
0.5451,Event,ADDED,eval-sanitize-30-r2-172-l8xfh.18d4f81cf57ee19d,reason=Scheduled count=None msg=Successfully assigned compute/eval-sanitize-30-r2-172-l8xfh to kind-worker4
0.5458,Event,ADDED,eval-sanitize-30-r2-172-l8xfh.18d4f81d11d49a4b,"reason=Pulled count=1 msg=Container image ""busybox:musl"" already present on machine"
0.546,Event,ADDED,eval-sanitize-30-r2-172-l8xfh.18d4f81d138c39c7,reason=Created count=1 msg=Created container: task
0.5462,Event,ADDED,eval-sanitize-30-r2-172-l8xfh.18d4f81d193a4bec,reason=Started count=1 msg=Started container task
0.5463,Event,ADDED,eval-sanitize-30-r2-172.18d4f81cac0ff04c,reason=SuccessfulCreate count=1 msg=Created pod: eval-sanitize-30-r2-172-l8xfh
0.5468,Event,ADDED,eval-sanitize-30-r2-172.18d4f824d6a17d36,reason=Completed count=1 msg=Job completed
0.5471,Event,ADDED,eval-sanitize-30-r2-173-7xnws.18d4f81cf0279d06,"reason=FailedScheduling count=None msg=0/6 nodes are available: 1 c_wall violated: 1 conflicting context pair(s) with node memory, 1 c_wall violated: 2 conflicting context pair(s) with node memory, 4 node(s) had untolerated taint(s). no new claims to deallocate, preemption: 0/6 nodes are available: 2 No preemption victims found for incoming pod, 4 Preemption is not helpful for scheduling."
0.5475,Event,ADDED,eval-sanitize-30-r2-173-7xnws.18d4f81d3b6c8bd9,reason=Scheduled count=None msg=Successfully assigned compute/eval-sanitize-30-r2-173-7xnws to kind-worker3
0.5479,Event,ADDED,eval-sanitize-30-r2-173-7xnws.18d4f81d5875d3d2,"reason=Pulled count=1 msg=Container image ""busybox:musl"" already present on machine"
0.5482,Event,ADDED,eval-sanitize-30-r2-173-7xnws.18d4f81d5a396c72,reason=Created count=1 msg=Created container: task
0.5485,Event,ADDED,eval-sanitize-30-r2-173-7xnws.18d4f81d5e643cd2,reason=Started count=1 msg=Started container task
0.5487,Event,ADDED,eval-sanitize-30-r2-173.18d4f81ce95efffd,reason=SuccessfulCreate count=1 msg=Created pod: eval-sanitize-30-r2-173-7xnws
0.5491,Event,ADDED,eval-sanitize-30-r2-173.18d4f824af9535a4,reason=Completed count=1 msg=Job completed
0.5493,Event,ADDED,eval-sanitize-30-r2-174-6lgdb.18d4f81d3000174e,"reason=FailedScheduling count=None msg=0/6 nodes are available: 1 c_wall violated: 1 conflicting context pair(s) with node memory, 2 c_wall violated: 2 conflicting context pair(s) with node memory, 3 node(s) had untolerated taint(s). no new claims to deallocate, preemption: 0/6 nodes are available: 3 No preemption victims found for incoming pod, 3 Preemption is not helpful for scheduling."
0.5495,Event,ADDED,eval-sanitize-30-r2-174-6lgdb.18d4f81d89e8cdd8,reason=Scheduled count=None msg=Successfully assigned compute/eval-sanitize-30-r2-174-6lgdb to kind-worker5
0.55,Event,ADDED,eval-sanitize-30-r2-174-6lgdb.18d4f81da6049e14,"reason=Pulled count=1 msg=Container image ""busybox:musl"" already present on machine"
0.5502,Event,ADDED,eval-sanitize-30-r2-174-6lgdb.18d4f81da8c5ce30,reason=Created count=1 msg=Created container: task
0.5506,Event,ADDED,eval-sanitize-30-r2-174-6lgdb.18d4f81dadba97c0,reason=Started count=1 msg=Started container task
0.5514,Event,ADDED,eval-sanitize-30-r2-174.18d4f81d28ea1d20,reason=SuccessfulCreate count=1 msg=Created pod: eval-sanitize-30-r2-174-6lgdb
0.5518,Event,ADDED,eval-sanitize-30-r2-174.18d4f824fa7aef52,reason=Completed count=1 msg=Job completed
0.552,Event,ADDED,eval-sanitize-30-r2-175-6mnbh.18d4f81d6ca987bb,reason=Scheduled count=None msg=Successfully assigned compute/eval-sanitize-30-r2-175-6mnbh to kind-worker4
0.5522,Event,ADDED,eval-sanitize-30-r2-175-6mnbh.18d4f81d85bc5dee,"reason=Pulled count=1 msg=Container image ""busybox:musl"" already present on machine"
0.5523,Event,ADDED,eval-sanitize-30-r2-175-6mnbh.18d4f81d8701b090,reason=Created count=1 msg=Created container: task
0.5528,Event,ADDED,eval-sanitize-30-r2-175-6mnbh.18d4f81d89f83530,reason=Started count=1 msg=Started container task
0.5531,Event,ADDED,eval-sanitize-30-r2-175.18d4f81d5f418411,reason=SuccessfulCreate count=1 msg=Created pod: eval-sanitize-30-r2-175-6mnbh
0.5535,Event,ADDED,eval-sanitize-30-r2-175.18d4f824f71766a4,reason=Completed count=1 msg=Job completed
0.5538,Event,ADDED,eval-sanitize-30-r2-176-5rxt7.18d4f81dbe94b6d8,reason=Scheduled count=None msg=Successfully assigned compute/eval-sanitize-30-r2-176-5rxt7 to kind-worker3
0.554,Event,ADDED,eval-sanitize-30-r2-176-5rxt7.18d4f81ddae46e55,"reason=Pulled count=1 msg=Container image ""busybox:musl"" already present on machine"
0.5542,Event,ADDED,eval-sanitize-30-r2-176-5rxt7.18d4f81ddc3db3f1,reason=Created count=1 msg=Created container: task
0.5544,Event,ADDED,eval-sanitize-30-r2-176-5rxt7.18d4f81de125dc48,reason=Started count=1 msg=Started container task
0.5547,Event,ADDED,eval-sanitize-30-r2-176.18d4f81da065c8d4,reason=SuccessfulCreate count=1 msg=Created pod: eval-sanitize-30-r2-176-5rxt7
0.5549,Event,ADDED,eval-sanitize-30-r2-176.18d4f8250ef14fd6,reason=Completed count=1 msg=Job completed
0.5551,Event,ADDED,eval-sanitize-30-r2-177-sxs5c.18d4f81de87b8367,reason=Scheduled count=None msg=Successfully assigned compute/eval-sanitize-30-r2-177-sxs5c to kind-worker5
0.5552,Event,ADDED,eval-sanitize-30-r2-177-sxs5c.18d4f81e05513ec6,"reason=Pulled count=1 msg=Container image ""busybox:musl"" already present on machine"
0.5556,Event,ADDED,eval-sanitize-30-r2-177-sxs5c.18d4f81e071e0c1a,reason=Created count=1 msg=Created container: task
0.5562,Event,ADDED,eval-sanitize-30-r2-177-sxs5c.18d4f81e0e2dab5b,reason=Started count=1 msg=Started container task
0.5566,Event,ADDED,eval-sanitize-30-r2-177.18d4f81ddf3bfe22,reason=SuccessfulCreate count=1 msg=Created pod: eval-sanitize-30-r2-177-sxs5c
0.5569,Event,ADDED,eval-sanitize-30-r2-177.18d4f8251e50a4c1,reason=Completed count=1 msg=Job completed
0.5571,Event,ADDED,eval-sanitize-30-r2-178-27jd7.18d4f81e21375293,reason=Scheduled count=None msg=Successfully assigned compute/eval-sanitize-30-r2-178-27jd7 to kind-worker3
0.5574,Event,ADDED,eval-sanitize-30-r2-178-27jd7.18d4f81e40815bfe,"reason=Pulled count=1 msg=Container image ""busybox:musl"" already present on machine"
0.5577,Event,ADDED,eval-sanitize-30-r2-178-27jd7.18d4f81e427eb823,reason=Created count=1 msg=Created container: task
0.558,Event,ADDED,eval-sanitize-30-r2-178-27jd7.18d4f81e49eb281d,reason=Started count=1 msg=Started container task
0.5582,Event,ADDED,eval-sanitize-30-r2-178.18d4f81e11bf797c,reason=SuccessfulCreate count=1 msg=Created pod: eval-sanitize-30-r2-178-27jd7
0.5585,Event,ADDED,eval-sanitize-30-r2-178.18d4f82526caae26,reason=Completed count=1 msg=Job completed
0.5587,Event,ADDED,eval-sanitize-30-r2-179-rc2ct.18d4f81e56fa786d,reason=Scheduled count=None msg=Successfully assigned compute/eval-sanitize-30-r2-179-rc2ct to kind-worker2
0.5591,Event,ADDED,eval-sanitize-30-r2-179-rc2ct.18d4f81e746d5b26,"reason=Pulled count=1 msg=Container image ""busybox:musl"" already present on machine"
0.5593,Event,ADDED,eval-sanitize-30-r2-179-rc2ct.18d4f81e75ca88f2,reason=Created count=1 msg=Created container: task
0.5595,Event,ADDED,eval-sanitize-30-r2-179-rc2ct.18d4f81e7ac5daee,reason=Started count=1 msg=Started container task
0.5599,Event,ADDED,eval-sanitize-30-r2-179.18d4f81e4d61ee2e,reason=SuccessfulCreate count=1 msg=Created pod: eval-sanitize-30-r2-179-rc2ct
0.5602,Event,ADDED,eval-sanitize-30-r2-179.18d4f82535a835ed,reason=Completed count=1 msg=Job completed
0.5606,Event,ADDED,eval-sanitize-30-r2-180-vx2km.18d4f81e956bac59,"reason=FailedScheduling count=None msg=0/6 nodes are available: 1 node(s) had untolerated taint(s), 2 c_wall violated: 1 conflicting context pair(s) with node memory, 3 c_wall violated: 2 conflicting context pair(s) with node memory. no new claims to deallocate, preemption: 0/6 nodes are available: 1 Preemption is not helpful for scheduling, 5 No preemption victims found for incoming pod."
0.5612,Event,ADDED,eval-sanitize-30-r2-180-vx2km.18d4f81e9bd2b517,"reason=FailedScheduling count=None msg=0/6 nodes are available: 1 node(s) had untolerated taint(s), 2 c_wall violated: 1 conflicting context pair(s) with node memory, 3 c_wall violated: 2 conflicting context pair(s) with node memory. no new claims to deallocate, preemption: 0/6 nodes are available: 1 Preemption is not helpful for scheduling, 5 No preemption victims found for incoming pod."
0.5617,Event,ADDED,eval-sanitize-30-r2-180-vx2km.18d4f823fd2d7ecf,reason=Scheduled count=None msg=Successfully assigned compute/eval-sanitize-30-r2-180-vx2km to kind-worker
0.5623,Event,ADDED,eval-sanitize-30-r2-180-vx2km.18d4f8241f8a39f6,"reason=Pulled count=1 msg=Container image ""busybox:musl"" already present on machine"
0.5627,Event,ADDED,eval-sanitize-30-r2-180-vx2km.18d4f82421b15c9d,reason=Created count=1 msg=Created container: task
0.563,Event,ADDED,eval-sanitize-30-r2-180-vx2km.18d4f82426dde486,reason=Started count=1 msg=Started container task
0.5633,Event,ADDED,eval-sanitize-30-r2-180.18d4f81e89813602,reason=SuccessfulCreate count=1 msg=Created pod: eval-sanitize-30-r2-180-vx2km
0.5635,Event,ADDED,eval-sanitize-30-r2-180.18d4f829b121ef12,reason=Completed count=1 msg=Job completed
0.5636,Event,ADDED,eval-sanitize-30-r2-181-sjq6p.18d4f81ecb8dad99,"reason=FailedScheduling count=None msg=0/6 nodes are available: 1 node(s) had untolerated taint(s), 2 c_wall violated: 1 conflicting context pair(s) with node memory, 3 c_wall violated: 2 conflicting context pair(s) with node memory. no new claims to deallocate, preemption: 0/6 nodes are available: 1 Preemption is not helpful for scheduling, 5 No preemption victims found for incoming pod."
0.564,Event,ADDED,eval-sanitize-30-r2-181-sjq6p.18d4f81ed7348891,"reason=FailedScheduling count=None msg=0/6 nodes are available: 1 node(s) had untolerated taint(s), 2 c_wall violated: 1 conflicting context pair(s) with node memory, 3 c_wall violated: 2 conflicting context pair(s) with node memory. no new claims to deallocate, preemption: 0/6 nodes are available: 1 Preemption is not helpful for scheduling, 5 No preemption victims found for incoming pod."
0.5643,Event,ADDED,eval-sanitize-30-r2-181-sjq6p.18d4f8240e80e7a0,reason=Scheduled count=None msg=Successfully assigned compute/eval-sanitize-30-r2-181-sjq6p to kind-worker
0.5645,Event,ADDED,eval-sanitize-30-r2-181-sjq6p.18d4f8242cb5253e,"reason=Pulled count=1 msg=Container image ""busybox:musl"" already present on machine"
0.565,Event,ADDED,eval-sanitize-30-r2-181-sjq6p.18d4f8242e166b1f,reason=Created count=1 msg=Created container: task
0.5653,Event,ADDED,eval-sanitize-30-r2-181-sjq6p.18d4f8243430239e,reason=Started count=1 msg=Started container task
0.5656,Event,ADDED,eval-sanitize-30-r2-181.18d4f81ec5dd82ae,reason=SuccessfulCreate count=1 msg=Created pod: eval-sanitize-30-r2-181-sjq6p
0.5659,Event,ADDED,eval-sanitize-30-r2-181.18d4f829b07a851e,reason=Completed count=1 msg=Job completed
0.5662,Event,ADDED,eval-sanitize-30-r2-182-947ws.18d4f81f07556890,reason=Scheduled count=None msg=Successfully assigned compute/eval-sanitize-30-r2-182-947ws to kind-worker2
0.5664,Event,ADDED,eval-sanitize-30-r2-182-947ws.18d4f81f22985d2b,"reason=Pulled count=1 msg=Container image ""busybox:musl"" already present on machine"
0.5666,Event,ADDED,eval-sanitize-30-r2-182-947ws.18d4f81f23e88c1f,reason=Created count=1 msg=Created container: task
0.5669,Event,ADDED,eval-sanitize-30-r2-182-947ws.18d4f81f2909e776,reason=Started count=1 msg=Started container task
0.5672,Event,ADDED,eval-sanitize-30-r2-182.18d4f81f00a25968,reason=SuccessfulCreate count=1 msg=Created pod: eval-sanitize-30-r2-182-947ws
0.5674,Event,ADDED,eval-sanitize-30-r2-182.18d4f8256321f8de,reason=Completed count=1 msg=Job completed
0.5677,Event,ADDED,eval-sanitize-30-r2-183-sbm9x.18d4f81f42da23a4,"reason=FailedScheduling count=None msg=0/6 nodes are available: 1 node(s) had untolerated taint(s), 2 c_wall violated: 1 conflicting context pair(s) with node memory, 3 c_wall violated: 2 conflicting context pair(s) with node memory. no new claims to deallocate, preemption: 0/6 nodes are available: 1 Preemption is not helpful for scheduling, 5 No preemption victims found for incoming pod."
0.5682,Event,ADDED,eval-sanitize-30-r2-183-sbm9x.18d4f81f4e6083a7,"reason=FailedScheduling count=None msg=0/6 nodes are available: 1 node(s) had untolerated taint(s), 2 c_wall violated: 1 conflicting context pair(s) with node memory, 3 c_wall violated: 2 conflicting context pair(s) with node memory. no new claims to deallocate, preemption: 0/6 nodes are available: 1 Preemption is not helpful for scheduling, 5 No preemption victims found for incoming pod."
0.5686,Event,ADDED,eval-sanitize-30-r2-183-sbm9x.18d4f823f6e18605,reason=Scheduled count=None msg=Successfully assigned compute/eval-sanitize-30-r2-183-sbm9x to kind-worker
0.569,Event,ADDED,eval-sanitize-30-r2-183-sbm9x.18d4f82413252f78,"reason=Pulled count=1 msg=Container image ""busybox:musl"" already present on machine"
0.5696,Event,ADDED,eval-sanitize-30-r2-183-sbm9x.18d4f82414c9e306,reason=Created count=1 msg=Created container: task
0.5698,Event,ADDED,eval-sanitize-30-r2-183-sbm9x.18d4f8241a12caf9,reason=Started count=1 msg=Started container task
0.57,Event,ADDED,eval-sanitize-30-r2-183.18d4f81f3d5f118c,reason=SuccessfulCreate count=1 msg=Created pod: eval-sanitize-30-r2-183-sbm9x
0.5703,Event,ADDED,eval-sanitize-30-r2-183.18d4f82976e12be0,reason=Completed count=1 msg=Job completed
0.5707,Event,ADDED,eval-sanitize-30-r2-184-pznt6.18d4f81f85c72144,reason=Scheduled count=None msg=Successfully assigned compute/eval-sanitize-30-r2-184-pznt6 to kind-worker2
0.5709,Event,ADDED,eval-sanitize-30-r2-184-pznt6.18d4f81fa3cf3d92,"reason=Pulled count=1 msg=Container image ""busybox:musl"" already present on machine"
0.5712,Event,ADDED,eval-sanitize-30-r2-184-pznt6.18d4f81fa551e12e,reason=Created count=1 msg=Created container: task
0.5716,Event,ADDED,eval-sanitize-30-r2-184-pznt6.18d4f81fab1cead6,reason=Started count=1 msg=Started container task
0.5719,Event,ADDED,eval-sanitize-30-r2-184.18d4f81f77e574cc,reason=SuccessfulCreate count=1 msg=Created pod: eval-sanitize-30-r2-184-pznt6
0.5722,Event,ADDED,eval-sanitize-30-r2-184.18d4f825479601a2,reason=Completed count=1 msg=Job completed
0.5724,Event,ADDED,eval-sanitize-30-r2-185-bsqwl.18d4f81fc662d7bb,reason=Scheduled count=None msg=Successfully assigned compute/eval-sanitize-30-r2-185-bsqwl to kind-worker2
0.5728,Event,ADDED,eval-sanitize-30-r2-185-bsqwl.18d4f81fe1526d19,"reason=Pulled count=1 msg=Container image ""busybox:musl"" already present on machine"
0.5731,Event,ADDED,eval-sanitize-30-r2-185-bsqwl.18d4f81fe2a97380,reason=Created count=1 msg=Created container: task
0.5734,Event,ADDED,eval-sanitize-30-r2-185-bsqwl.18d4f81feb5a240e,reason=Started count=1 msg=Started container task
0.5741,Event,ADDED,eval-sanitize-30-r2-185.18d4f81fb45c41a1,reason=SuccessfulCreate count=1 msg=Created pod: eval-sanitize-30-r2-185-bsqwl
0.5749,Event,ADDED,eval-sanitize-30-r2-185.18d4f8258a684236,reason=Completed count=1 msg=Job completed
0.5752,Event,ADDED,eval-sanitize-30-r2-186-74d65.18d4f82007bc9c68,reason=Scheduled count=None msg=Successfully assigned compute/eval-sanitize-30-r2-186-74d65 to kind-worker5
0.5755,Event,ADDED,eval-sanitize-30-r2-186-74d65.18d4f82023755068,"reason=Pulled count=1 msg=Container image ""busybox:musl"" already present on machine"
0.5759,Event,ADDED,eval-sanitize-30-r2-186-74d65.18d4f82024bffc95,reason=Created count=1 msg=Created container: task
0.5762,Event,ADDED,eval-sanitize-30-r2-186-74d65.18d4f820277adb00,reason=Started count=1 msg=Started container task
0.5765,Event,ADDED,eval-sanitize-30-r2-186.18d4f81ff336ca2e,reason=SuccessfulCreate count=1 msg=Created pod: eval-sanitize-30-r2-186-74d65
0.5769,Event,ADDED,eval-sanitize-30-r2-186.18d4f825c854736d,reason=Completed count=1 msg=Job completed
0.5773,Event,ADDED,eval-sanitize-30-r2-187-7dxmq.18d4f820434129f7,reason=Scheduled count=None msg=Successfully assigned compute/eval-sanitize-30-r2-187-7dxmq to kind-worker4
0.5776,Event,ADDED,eval-sanitize-30-r2-187-7dxmq.18d4f82062ce79f1,"reason=Pulled count=1 msg=Container image ""busybox:musl"" already present on machine"
0.5779,Event,ADDED,eval-sanitize-30-r2-187-7dxmq.18d4f8206451ce86,reason=Created count=1 msg=Created container: task
0.5782,Event,ADDED,eval-sanitize-30-r2-187-7dxmq.18d4f82068e1f51f,reason=Started count=1 msg=Started container task
0.5784,Event,ADDED,eval-sanitize-30-r2-187.18d4f82032dcfa00,reason=SuccessfulCreate count=1 msg=Created pod: eval-sanitize-30-r2-187-7dxmq
0.5786,Event,ADDED,eval-sanitize-30-r2-187.18d4f825f380a8a1,reason=Completed count=1 msg=Job completed
0.5788,Event,ADDED,eval-sanitize-30-r2-188-4v2fh.18d4f820730e476a,reason=Scheduled count=None msg=Successfully assigned compute/eval-sanitize-30-r2-188-4v2fh to kind-worker3
0.5793,Event,ADDED,eval-sanitize-30-r2-188-4v2fh.18d4f8208d4ec2f6,"reason=Pulled count=1 msg=Container image ""busybox:musl"" already present on machine"
0.5797,Event,ADDED,eval-sanitize-30-r2-188-4v2fh.18d4f8208f0790f7,reason=Created count=1 msg=Created container: task
0.58,Event,ADDED,eval-sanitize-30-r2-188-4v2fh.18d4f82092fce170,reason=Started count=1 msg=Started container task
0.5803,Event,ADDED,eval-sanitize-30-r2-188.18d4f82065b9562c,reason=SuccessfulCreate count=1 msg=Created pod: eval-sanitize-30-r2-188-4v2fh
0.5808,Event,ADDED,eval-sanitize-30-r2-188.18d4f825fe168ce7,reason=Completed count=1 msg=Job completed
0.581,Event,ADDED,eval-sanitize-30-r2-189-js7jj.18d4f820ae97fa79,reason=Scheduled count=None msg=Successfully assigned compute/eval-sanitize-30-r2-189-js7jj to kind-worker3
0.5812,Event,ADDED,eval-sanitize-30-r2-189-js7jj.18d4f820ca569381,"reason=Pulled count=1 msg=Container image ""busybox:musl"" already present on machine"
0.5817,Event,ADDED,eval-sanitize-30-r2-189-js7jj.18d4f820cbb79ba6,reason=Created count=1 msg=Created container: task
0.5819,Event,ADDED,eval-sanitize-30-r2-189-js7jj.18d4f820d0c4ae2a,reason=Started count=1 msg=Started container task
0.5822,Event,ADDED,eval-sanitize-30-r2-189.18d4f820a5021352,reason=SuccessfulCreate count=1 msg=Created pod: eval-sanitize-30-r2-189-js7jj
0.5824,Event,ADDED,eval-sanitize-30-r2-189.18d4f82637634c52,reason=Completed count=1 msg=Job completed
0.583,Event,ADDED,eval-sanitize-30-r2-190-q7dwj.18d4f820efdc59c1,reason=Scheduled count=None msg=Successfully assigned compute/eval-sanitize-30-r2-190-q7dwj to kind-worker5
0.5833,Event,ADDED,eval-sanitize-30-r2-190-q7dwj.18d4f8210b04a150,"reason=Pulled count=1 msg=Container image ""busybox:musl"" already present on machine"
0.5835,Event,ADDED,eval-sanitize-30-r2-190-q7dwj.18d4f8210c732b5b,reason=Created count=1 msg=Created container: task
0.5837,Event,ADDED,eval-sanitize-30-r2-190-q7dwj.18d4f8211050e928,reason=Started count=1 msg=Started container task
0.5841,Event,ADDED,eval-sanitize-30-r2-190.18d4f820e0560373,reason=SuccessfulCreate count=1 msg=Created pod: eval-sanitize-30-r2-190-q7dwj
0.5843,Event,ADDED,eval-sanitize-30-r2-190.18d4f82673a8096d,reason=Completed count=1 msg=Job completed
0.5845,Event,ADDED,eval-sanitize-30-r2-191-9f9wm.18d4f82125808ddd,reason=Scheduled count=None msg=Successfully assigned compute/eval-sanitize-30-r2-191-9f9wm to kind-worker5
0.585,Event,ADDED,eval-sanitize-30-r2-191-9f9wm.18d4f821411461bf,"reason=Pulled count=1 msg=Container image ""busybox:musl"" already present on machine"
0.5856,Event,ADDED,eval-sanitize-30-r2-191-9f9wm.18d4f82142980b4d,reason=Created count=1 msg=Created container: task
0.5861,Event,ADDED,eval-sanitize-30-r2-191-9f9wm.18d4f82146493761,reason=Started count=1 msg=Started container task
0.5864,Event,ADDED,eval-sanitize-30-r2-191.18d4f821189964c3,reason=SuccessfulCreate count=1 msg=Created pod: eval-sanitize-30-r2-191-9f9wm
0.5868,Event,ADDED,eval-sanitize-30-r2-191.18d4f826b02104cb,reason=Completed count=1 msg=Job completed
0.587,Event,ADDED,eval-sanitize-30-r2-192-xdsq5.18d4f8216d879023,reason=Scheduled count=None msg=Successfully assigned compute/eval-sanitize-30-r2-192-xdsq5 to kind-worker4
0.5872,Event,ADDED,eval-sanitize-30-r2-192-xdsq5.18d4f8218c3ba73c,"reason=Pulled count=1 msg=Container image ""busybox:musl"" already present on machine"
0.5874,Event,ADDED,eval-sanitize-30-r2-192-xdsq5.18d4f8218d9610bf,reason=Created count=1 msg=Created container: task
0.5877,Event,ADDED,eval-sanitize-30-r2-192-xdsq5.18d4f821967b9ba4,reason=Started count=1 msg=Started container task
0.588,Event,ADDED,eval-sanitize-30-r2-192.18d4f8215d0b58ea,reason=SuccessfulCreate count=1 msg=Created pod: eval-sanitize-30-r2-192-xdsq5
0.5884,Event,ADDED,eval-sanitize-30-r2-192.18d4f8272068facf,reason=Completed count=1 msg=Job completed
0.5887,Event,ADDED,eval-sanitize-30-r2-193-mpkqn.18d4f8219df58194,reason=Scheduled count=None msg=Successfully assigned compute/eval-sanitize-30-r2-193-mpkqn to kind-worker3
0.5893,Event,ADDED,eval-sanitize-30-r2-193-mpkqn.18d4f821be779c35,"reason=Pulled count=1 msg=Container image ""busybox:musl"" already present on machine"
0.5899,Event,ADDED,eval-sanitize-30-r2-193-mpkqn.18d4f821c04b90db,reason=Created count=1 msg=Created container: task
0.5901,Event,ADDED,eval-sanitize-30-r2-193-mpkqn.18d4f821cccfd3fa,reason=Started count=1 msg=Started container task
0.5907,Event,ADDED,eval-sanitize-30-r2-193.18d4f8218fb39cd2,reason=SuccessfulCreate count=1 msg=Created pod: eval-sanitize-30-r2-193-mpkqn
0.5913,Event,ADDED,eval-sanitize-30-r2-193.18d4f827619902d6,reason=Completed count=1 msg=Job completed
0.5916,Event,ADDED,eval-sanitize-30-r2-194-6wz7x.18d4f821de02997d,"reason=FailedScheduling count=None msg=0/6 nodes are available: 1 node(s) had untolerated taint(s), 2 c_wall violated: 1 conflicting context pair(s) with node memory, 3 c_wall violated: 2 conflicting context pair(s) with node memory. no new claims to deallocate, preemption: 0/6 nodes are available: 1 Preemption is not helpful for scheduling, 5 No preemption victims found for incoming pod."
0.5921,Event,ADDED,eval-sanitize-30-r2-194-6wz7x.18d4f821fc1bbd55,"reason=FailedScheduling count=None msg=0/6 nodes are available: 1 node(s) had untolerated taint(s), 2 c_wall violated: 1 conflicting context pair(s) with node memory, 3 c_wall violated: 2 conflicting context pair(s) with node memory. no new claims to deallocate, preemption: 0/6 nodes are available: 1 Preemption is not helpful for scheduling, 5 No preemption victims found for incoming pod."
0.5924,Event,ADDED,eval-sanitize-30-r2-194-6wz7x.18d4f824034672d1,reason=Scheduled count=None msg=Successfully assigned compute/eval-sanitize-30-r2-194-6wz7x to kind-worker
0.5927,Event,ADDED,eval-sanitize-30-r2-194-6wz7x.18d4f8241fb325cb,"reason=Pulled count=1 msg=Container image ""busybox:musl"" already present on machine"
0.5929,Event,ADDED,eval-sanitize-30-r2-194-6wz7x.18d4f824222f9e26,reason=Created count=1 msg=Created container: task
0.5934,Event,ADDED,eval-sanitize-30-r2-194-6wz7x.18d4f8242758315e,reason=Started count=1 msg=Started container task
0.5937,Event,ADDED,eval-sanitize-30-r2-194.18d4f821cf6b8dc4,reason=SuccessfulCreate count=1 msg=Created pod: eval-sanitize-30-r2-194-6wz7x
0.5939,Event,ADDED,eval-sanitize-30-r2-194.18d4f82975d5c31c,reason=Completed count=1 msg=Job completed
0.5941,Event,ADDED,eval-sanitize-30-r2-195-rwnn9.18d4f8221ff3ef99,reason=Scheduled count=None msg=Successfully assigned compute/eval-sanitize-30-r2-195-rwnn9 to kind-worker3
0.5945,Event,ADDED,eval-sanitize-30-r2-195-rwnn9.18d4f82242ad2d0a,"reason=Pulled count=1 msg=Container image ""busybox:musl"" already present on machine"
0.5948,Event,ADDED,eval-sanitize-30-r2-195-rwnn9.18d4f82244a33989,reason=Created count=1 msg=Created container: task
0.595,Event,ADDED,eval-sanitize-30-r2-195-rwnn9.18d4f8224eb4a850,reason=Started count=1 msg=Started container task
0.5955,Event,ADDED,eval-sanitize-30-r2-195.18d4f8220cc8e495,reason=SuccessfulCreate count=1 msg=Created pod: eval-sanitize-30-r2-195-rwnn9
0.5957,Event,ADDED,eval-sanitize-30-r2-195.18d4f827db637a7d,reason=Completed count=1 msg=Job completed
0.5959,Event,ADDED,eval-sanitize-30-r2-196-8ffgp.18d4f822af2f8496,"reason=FailedScheduling count=None msg=0/6 nodes are available: 1 node(s) had untolerated taint(s), 2 c_wall violated: 1 conflicting context pair(s) with node memory, 3 c_wall violated: 2 conflicting context pair(s) with node memory. no new claims to deallocate, preemption: 0/6 nodes are available: 1 Preemption is not helpful for scheduling, 5 No preemption victims found for incoming pod."
0.5965,Event,ADDED,eval-sanitize-30-r2-196-8ffgp.18d4f822eff49473,"reason=FailedScheduling count=None msg=0/6 nodes are available: 1 node(s) had untolerated taint(s), 2 c_wall violated: 1 conflicting context pair(s) with node memory, 3 c_wall violated: 2 conflicting context pair(s) with node memory. no new claims to deallocate, preemption: 0/6 nodes are available: 1 Preemption is not helpful for scheduling, 5 No preemption victims found for incoming pod."
0.5974,Event,ADDED,eval-sanitize-30-r2-196-8ffgp.18d4f823ed1b5ad0,reason=Scheduled count=None msg=Successfully assigned compute/eval-sanitize-30-r2-196-8ffgp to kind-worker
0.598,Event,ADDED,eval-sanitize-30-r2-196-8ffgp.18d4f82408aba1bc,"reason=Pulled count=1 msg=Container image ""busybox:musl"" already present on machine"
0.5983,Event,ADDED,eval-sanitize-30-r2-196-8ffgp.18d4f8240a4f24db,reason=Created count=1 msg=Created container: task
0.5987,Event,ADDED,eval-sanitize-30-r2-196-8ffgp.18d4f8240d229a8f,reason=Started count=1 msg=Started container task
0.5989,Event,ADDED,eval-sanitize-30-r2-196.18d4f822a0655d34,reason=SuccessfulCreate count=1 msg=Created pod: eval-sanitize-30-r2-196-8ffgp
0.5991,Event,ADDED,eval-sanitize-30-r2-196.18d4f82975373e5b,reason=Completed count=1 msg=Job completed
0.5992,Event,ADDED,eval-sanitize-30-r2-197-smjss.18d4f82337d5f413,reason=Scheduled count=None msg=Successfully assigned compute/eval-sanitize-30-r2-197-smjss to kind-worker3
0.5995,Event,ADDED,eval-sanitize-30-r2-197-smjss.18d4f8235299f158,"reason=Pulled count=1 msg=Container image ""busybox:musl"" already present on machine"
0.5997,Event,ADDED,eval-sanitize-30-r2-197-smjss.18d4f8235413f5d8,reason=Created count=1 msg=Created container: task
0.5998,Event,ADDED,eval-sanitize-30-r2-197-smjss.18d4f823589f423d,reason=Started count=1 msg=Started container task
0.6,Event,ADDED,eval-sanitize-30-r2-197.18d4f823176c9113,reason=SuccessfulCreate count=1 msg=Created pod: eval-sanitize-30-r2-197-smjss
0.6002,Event,ADDED,eval-sanitize-30-r2-197.18d4f8288bc79c37,reason=Completed count=1 msg=Job completed
0.6003,Event,ADDED,eval-sanitize-30-r2-198-2tp48.18d4f82385c2be45,reason=Scheduled count=None msg=Successfully assigned compute/eval-sanitize-30-r2-198-2tp48 to kind-worker5
0.6005,Event,ADDED,eval-sanitize-30-r2-198-2tp48.18d4f823a01c4171,"reason=Pulled count=1 msg=Container image ""busybox:musl"" already present on machine"
0.6007,Event,ADDED,eval-sanitize-30-r2-198-2tp48.18d4f823a17e56dc,reason=Created count=1 msg=Created container: task
0.6009,Event,ADDED,eval-sanitize-30-r2-198-2tp48.18d4f823a6dedb31,reason=Started count=1 msg=Started container task
0.6011,Event,ADDED,eval-sanitize-30-r2-198.18d4f82376d86a38,reason=SuccessfulCreate count=1 msg=Created pod: eval-sanitize-30-r2-198-2tp48
0.6013,Event,ADDED,eval-sanitize-30-r2-198.18d4f82943681272,reason=Completed count=1 msg=Job completed
0.6017,Event,ADDED,eval-sanitize-30-r2-199-pv25j.18d4f823cd25586b,reason=Scheduled count=None msg=Successfully assigned compute/eval-sanitize-30-r2-199-pv25j to kind-worker5
0.602,Event,ADDED,eval-sanitize-30-r2-199-pv25j.18d4f823e7d740ea,"reason=Pulled count=1 msg=Container image ""busybox:musl"" already present on machine"
0.6023,Event,ADDED,eval-sanitize-30-r2-199-pv25j.18d4f823e92817db,reason=Created count=1 msg=Created container: task
0.6026,Event,ADDED,eval-sanitize-30-r2-199-pv25j.18d4f823ed352a27,reason=Started count=1 msg=Started container task
0.603,Event,ADDED,eval-sanitize-30-r2-199.18d4f823c1619f77,reason=SuccessfulCreate count=1 msg=Created pod: eval-sanitize-30-r2-199-pv25j
0.6033,Event,ADDED,eval-sanitize-30-r2-199.18d4f82982d79302,reason=Completed count=1 msg=Job completed
0.6035,Event,ADDED,eval-sanitize-30-r3-000-zljnt.18d4f834555dc668,reason=Scheduled count=None msg=Successfully assigned compute/eval-sanitize-30-r3-000-zljnt to kind-worker5
0.6039,Event,ADDED,eval-sanitize-30-r3-000-zljnt.18d4f83470916d5f,"reason=Pulled count=1 msg=Container image ""busybox:musl"" already present on machine"
0.6041,Event,ADDED,eval-sanitize-30-r3-000-zljnt.18d4f8347202fe85,reason=Created count=1 msg=Created container: task
0.6043,Event,ADDED,eval-sanitize-30-r3-000-zljnt.18d4f834762b3621,reason=Started count=1 msg=Started container task
0.6045,Event,ADDED,eval-sanitize-30-r3-000.18d4f834543b34b9,reason=SuccessfulCreate count=1 msg=Created pod: eval-sanitize-30-r3-000-zljnt
0.6047,Event,ADDED,eval-sanitize-30-r3-000.18d4f83a1242a309,reason=Completed count=1 msg=Job completed
0.6049,Event,ADDED,eval-sanitize-30-r3-001-bzd2k.18d4f834919fd015,reason=Scheduled count=None msg=Successfully assigned compute/eval-sanitize-30-r3-001-bzd2k to kind-worker
0.6051,Event,ADDED,eval-sanitize-30-r3-001-bzd2k.18d4f834abcf8a54,"reason=Pulled count=1 msg=Container image ""busybox:musl"" already present on machine"
0.6052,Event,ADDED,eval-sanitize-30-r3-001-bzd2k.18d4f834ad0aa9f9,reason=Created count=1 msg=Created container: task
0.6054,Event,ADDED,eval-sanitize-30-r3-001-bzd2k.18d4f834af386f50,reason=Started count=1 msg=Started container task
0.6057,Event,ADDED,eval-sanitize-30-r3-001.18d4f834906d7221,reason=SuccessfulCreate count=1 msg=Created pod: eval-sanitize-30-r3-001-bzd2k
0.6059,Event,ADDED,eval-sanitize-30-r3-001.18d4f83a43fa71b1,reason=Completed count=1 msg=Job completed
0.6062,Event,ADDED,eval-sanitize-30-r3-002-8xz2h.18d4f834cd1ad924,reason=Scheduled count=None msg=Successfully assigned compute/eval-sanitize-30-r3-002-8xz2h to kind-worker4
0.6063,Event,ADDED,eval-sanitize-30-r3-002-8xz2h.18d4f834ecd0f02a,"reason=Pulled count=1 msg=Container image ""busybox:musl"" already present on machine"
0.6065,Event,ADDED,eval-sanitize-30-r3-002-8xz2h.18d4f834ee0d7ce8,reason=Created count=1 msg=Created container: task
0.6067,Event,ADDED,eval-sanitize-30-r3-002-8xz2h.18d4f834faf7c08e,reason=Started count=1 msg=Started container task
0.6069,Event,ADDED,eval-sanitize-30-r3-002.18d4f834cbdf01b7,reason=SuccessfulCreate count=1 msg=Created pod: eval-sanitize-30-r3-002-8xz2h
0.607,Event,ADDED,eval-sanitize-30-r3-002.18d4f83a7cb7213f,reason=Completed count=1 msg=Job completed
0.6072,Event,ADDED,eval-sanitize-30-r3-003-4s6fz.18d4f835072df444,reason=Scheduled count=None msg=Successfully assigned compute/eval-sanitize-30-r3-003-4s6fz to kind-worker2
0.6074,Event,ADDED,eval-sanitize-30-r3-003-4s6fz.18d4f8352881bc0d,"reason=Pulled count=1 msg=Container image ""busybox:musl"" already present on machine"
0.6075,Event,ADDED,eval-sanitize-30-r3-003-4s6fz.18d4f83529a05512,reason=Created count=1 msg=Created container: task
0.6077,Event,ADDED,eval-sanitize-30-r3-003-4s6fz.18d4f8352ddf971d,reason=Started count=1 msg=Started container task
0.6079,Event,ADDED,eval-sanitize-30-r3-003.18d4f83505f5a177,reason=SuccessfulCreate count=1 msg=Created pod: eval-sanitize-30-r3-003-4s6fz
0.6081,Event,ADDED,eval-sanitize-30-r3-003.18d4f83ab1283800,reason=Completed count=1 msg=Job completed
0.6084,Event,ADDED,eval-sanitize-30-r3-004-bj7hn.18d4f835466f1266,reason=Scheduled count=None msg=Successfully assigned compute/eval-sanitize-30-r3-004-bj7hn to kind-worker3
0.6087,Event,ADDED,eval-sanitize-30-r3-004-bj7hn.18d4f83562c55d8e,"reason=Pulled count=1 msg=Container image ""busybox:musl"" already present on machine"
0.6091,Event,ADDED,eval-sanitize-30-r3-004-bj7hn.18d4f83563e0fec6,reason=Created count=1 msg=Created container: task
0.6097,Event,ADDED,eval-sanitize-30-r3-004-bj7hn.18d4f835687d62db,reason=Started count=1 msg=Started container task
0.61,Event,ADDED,eval-sanitize-30-r3-004.18d4f8353e074cfc,reason=SuccessfulCreate count=1 msg=Created pod: eval-sanitize-30-r3-004-bj7hn
0.6102,Event,ADDED,eval-sanitize-30-r3-004.18d4f83affa45b19,reason=Completed count=1 msg=Job completed
0.6105,Event,ADDED,eval-sanitize-30-r3-005-7q77b.18d4f83582e5ffa6,reason=Scheduled count=None msg=Successfully assigned compute/eval-sanitize-30-r3-005-7q77b to kind-worker4
0.6107,Event,ADDED,eval-sanitize-30-r3-005-7q77b.18d4f8359c245954,"reason=Pulled count=1 msg=Container image ""busybox:musl"" already present on machine"
0.6108,Event,ADDED,eval-sanitize-30-r3-005-7q77b.18d4f8359d3b0516,reason=Created count=1 msg=Created container: task
0.611,Event,ADDED,eval-sanitize-30-r3-005-7q77b.18d4f8359fa792f3,reason=Started count=1 msg=Started container task
0.6115,Event,ADDED,eval-sanitize-30-r3-005.18d4f83578c4551d,reason=SuccessfulCreate count=1 msg=Created pod: eval-sanitize-30-r3-005-7q77b
0.6117,Event,ADDED,eval-sanitize-30-r3-005.18d4f83b3150ae7c,reason=Completed count=1 msg=Job completed
0.6118,Event,ADDED,eval-sanitize-30-r3-006-5dn8p.18d4f835ba0ea5ed,reason=Scheduled count=None msg=Successfully assigned compute/eval-sanitize-30-r3-006-5dn8p to kind-worker
0.612,Event,ADDED,eval-sanitize-30-r3-006-5dn8p.18d4f835d3cd1cf0,"reason=Pulled count=1 msg=Container image ""busybox:musl"" already present on machine"
0.6122,Event,ADDED,eval-sanitize-30-r3-006-5dn8p.18d4f835d51ca45d,reason=Created count=1 msg=Created container: task
0.6124,Event,ADDED,eval-sanitize-30-r3-006-5dn8p.18d4f835da281f02,reason=Started count=1 msg=Started container task
0.6126,Event,ADDED,eval-sanitize-30-r3-006.18d4f835b4672021,reason=SuccessfulCreate count=1 msg=Created pod: eval-sanitize-30-r3-006-5dn8p
0.6128,Event,ADDED,eval-sanitize-30-r3-006.18d4f83b6f3c42db,reason=Completed count=1 msg=Job completed
0.613,Event,ADDED,eval-sanitize-30-r3-007-hc44f.18d4f835f5f86798,reason=Scheduled count=None msg=Successfully assigned compute/eval-sanitize-30-r3-007-hc44f to kind-worker3
0.6132,Event,ADDED,eval-sanitize-30-r3-007-hc44f.18d4f8360f8e8ea3,"reason=Pulled count=1 msg=Container image ""busybox:musl"" already present on machine"
0.6135,Event,ADDED,eval-sanitize-30-r3-007-hc44f.18d4f83610d0a3d8,reason=Created count=1 msg=Created container: task
0.6138,Event,ADDED,eval-sanitize-30-r3-007-hc44f.18d4f83616cc4d7b,reason=Started count=1 msg=Started container task
0.614,Event,ADDED,eval-sanitize-30-r3-007.18d4f835f11afb65,reason=SuccessfulCreate count=1 msg=Created pod: eval-sanitize-30-r3-007-hc44f
0.6142,Event,ADDED,eval-sanitize-30-r3-007.18d4f83bb4702b0e,reason=Completed count=1 msg=Job completed
0.6144,Event,ADDED,eval-sanitize-30-r3-008-7qg57.18d4f83631ef9b5b,reason=Scheduled count=None msg=Successfully assigned compute/eval-sanitize-30-r3-008-7qg57 to kind-worker5
0.6147,Event,ADDED,eval-sanitize-30-r3-008-7qg57.18d4f8364e5ee209,"reason=Pulled count=1 msg=Container image ""busybox:musl"" already present on machine"
0.6151,Event,ADDED,eval-sanitize-30-r3-008-7qg57.18d4f8364fc1e5e6,reason=Created count=1 msg=Created container: task
0.6154,Event,ADDED,eval-sanitize-30-r3-008-7qg57.18d4f83656af71bc,reason=Started count=1 msg=Started container task
0.6157,Event,ADDED,eval-sanitize-30-r3-008.18d4f8362c54ec0f,reason=SuccessfulCreate count=1 msg=Created pod: eval-sanitize-30-r3-008-7qg57
0.6159,Event,ADDED,eval-sanitize-30-r3-008.18d4f83bf2b3eb4e,reason=Completed count=1 msg=Job completed
0.6162,Event,ADDED,eval-sanitize-30-r3-009-6vjbk.18d4f83671778122,reason=Scheduled count=None msg=Successfully assigned compute/eval-sanitize-30-r3-009-6vjbk to kind-worker2
0.6164,Event,ADDED,eval-sanitize-30-r3-009-6vjbk.18d4f8368bd5cfb5,"reason=Pulled count=1 msg=Container image ""busybox:musl"" already present on machine"
0.6166,Event,ADDED,eval-sanitize-30-r3-009-6vjbk.18d4f8368d0631e0,reason=Created count=1 msg=Created container: task
0.6168,Event,ADDED,eval-sanitize-30-r3-009-6vjbk.18d4f8369203b59c,reason=Started count=1 msg=Started container task
0.617,Event,ADDED,eval-sanitize-30-r3-009.18d4f83667b519eb,reason=SuccessfulCreate count=1 msg=Created pod: eval-sanitize-30-r3-009-6vjbk
0.6172,Event,ADDED,eval-sanitize-30-r3-009.18d4f83c17e5130c,reason=Completed count=1 msg=Job completed
0.6175,Event,ADDED,eval-sanitize-30-r3-010-ctqsr.18d4f836a98cd4dd,reason=Scheduled count=None msg=Successfully assigned compute/eval-sanitize-30-r3-010-ctqsr to kind-worker
0.6177,Event,ADDED,eval-sanitize-30-r3-010-ctqsr.18d4f836c57f9ff3,"reason=Pulled count=1 msg=Container image ""busybox:musl"" already present on machine"
0.6179,Event,ADDED,eval-sanitize-30-r3-010-ctqsr.18d4f836c6b7f94e,reason=Created count=1 msg=Created container: task
0.6182,Event,ADDED,eval-sanitize-30-r3-010-ctqsr.18d4f836cbd95666,reason=Started count=1 msg=Started container task
0.6184,Event,ADDED,eval-sanitize-30-r3-010.18d4f836a3dfc8a0,reason=SuccessfulCreate count=1 msg=Created pod: eval-sanitize-30-r3-010-ctqsr
0.6186,Event,ADDED,eval-sanitize-30-r3-010.18d4f83c649079e4,reason=Completed count=1 msg=Job completed
0.6188,Event,ADDED,eval-sanitize-30-r3-011-czdt6.18d4f836e696e40c,reason=Scheduled count=None msg=Successfully assigned compute/eval-sanitize-30-r3-011-czdt6 to kind-worker5
0.619,Event,ADDED,eval-sanitize-30-r3-011-czdt6.18d4f837003aba34,"reason=Pulled count=1 msg=Container image ""busybox:musl"" already present on machine"
0.6192,Event,ADDED,eval-sanitize-30-r3-011-czdt6.18d4f8370198a210,reason=Created count=1 msg=Created container: task
0.6193,Event,ADDED,eval-sanitize-30-r3-011-czdt6.18d4f8370688bbfe,reason=Started count=1 msg=Started container task
0.6195,Event,ADDED,eval-sanitize-30-r3-011.18d4f836dfd9c384,reason=SuccessfulCreate count=1 msg=Created pod: eval-sanitize-30-r3-011-czdt6
0.6197,Event,ADDED,eval-sanitize-30-r3-011.18d4f83ca3fa69a0,reason=Completed count=1 msg=Job completed
0.6198,Event,ADDED,eval-sanitize-30-r3-012-h2wtg.18d4f8371f9f2759,reason=Scheduled count=None msg=Successfully assigned compute/eval-sanitize-30-r3-012-h2wtg to kind-worker4
0.62,Event,ADDED,eval-sanitize-30-r3-012-h2wtg.18d4f8373b8207e5,"reason=Pulled count=1 msg=Container image ""busybox:musl"" already present on machine"
0.6204,Event,ADDED,eval-sanitize-30-r3-012-h2wtg.18d4f8373d726fe7,reason=Created count=1 msg=Created container: task
0.6207,Event,ADDED,eval-sanitize-30-r3-012-h2wtg.18d4f837422f9f3b,reason=Started count=1 msg=Started container task
0.6209,Event,ADDED,eval-sanitize-30-r3-012.18d4f8371ab61a15,reason=SuccessfulCreate count=1 msg=Created pod: eval-sanitize-30-r3-012-h2wtg
0.6212,Event,ADDED,eval-sanitize-30-r3-012.18d4f83cd870d037,reason=Completed count=1 msg=Job completed
0.6214,Event,ADDED,eval-sanitize-30-r3-013-6kwnf.18d4f8375e849b9f,reason=Scheduled count=None msg=Successfully assigned compute/eval-sanitize-30-r3-013-6kwnf to kind-worker2
0.6217,Event,ADDED,eval-sanitize-30-r3-013-6kwnf.18d4f83779f089b5,"reason=Pulled count=1 msg=Container image ""busybox:musl"" already present on machine"
0.6219,Event,ADDED,eval-sanitize-30-r3-013-6kwnf.18d4f8377b12d490,reason=Created count=1 msg=Created container: task
0.6222,Event,ADDED,eval-sanitize-30-r3-013-6kwnf.18d4f8378174b3a6,reason=Started count=1 msg=Started container task
0.6223,Event,ADDED,eval-sanitize-30-r3-013.18d4f8375726a29b,reason=SuccessfulCreate count=1 msg=Created pod: eval-sanitize-30-r3-013-6kwnf
0.6225,Event,ADDED,eval-sanitize-30-r3-013.18d4f83d092c0395,reason=Completed count=1 msg=Job completed
0.6228,Event,ADDED,eval-sanitize-30-r3-014-fr68t.18d4f83797b528ee,reason=Scheduled count=None msg=Successfully assigned compute/eval-sanitize-30-r3-014-fr68t to kind-worker5
0.623,Event,ADDED,eval-sanitize-30-r3-014-fr68t.18d4f837b3fcb43b,"reason=Pulled count=1 msg=Container image ""busybox:musl"" already present on machine"
0.6232,Event,ADDED,eval-sanitize-30-r3-014-fr68t.18d4f837b7462e29,reason=Created count=1 msg=Created container: task
0.6234,Event,ADDED,eval-sanitize-30-r3-014-fr68t.18d4f837bd4eec83,reason=Started count=1 msg=Started container task
0.6235,Event,ADDED,eval-sanitize-30-r3-014.18d4f83792d74af8,reason=SuccessfulCreate count=1 msg=Created pod: eval-sanitize-30-r3-014-fr68t
0.6237,Event,ADDED,eval-sanitize-30-r3-014.18d4f83d533a0dd1,reason=Completed count=1 msg=Job completed
0.6238,Event,ADDED,eval-sanitize-30-r3-015-jwqmj.18d4f837d2853fbb,reason=Scheduled count=None msg=Successfully assigned compute/eval-sanitize-30-r3-015-jwqmj to kind-worker5
0.624,Event,ADDED,eval-sanitize-30-r3-015-jwqmj.18d4f837ee33bee0,"reason=Pulled count=1 msg=Container image ""busybox:musl"" already present on machine"
0.6243,Event,ADDED,eval-sanitize-30-r3-015-jwqmj.18d4f837efab5ebd,reason=Created count=1 msg=Created container: task
0.6245,Event,ADDED,eval-sanitize-30-r3-015-jwqmj.18d4f837f28bbcf1,reason=Started count=1 msg=Started container task
0.6248,Event,ADDED,eval-sanitize-30-r3-015.18d4f837cd987449,reason=SuccessfulCreate count=1 msg=Created pod: eval-sanitize-30-r3-015-jwqmj
0.625,Event,ADDED,eval-sanitize-30-r3-015.18d4f83d52a30ab6,reason=Completed count=1 msg=Job completed
0.6253,Event,ADDED,eval-sanitize-30-r3-016-65rbc.18d4f8380e5e5233,reason=Scheduled count=None msg=Successfully assigned compute/eval-sanitize-30-r3-016-65rbc to kind-worker
0.6254,Event,ADDED,eval-sanitize-30-r3-016-65rbc.18d4f8382b75080d,"reason=Pulled count=1 msg=Container image ""busybox:musl"" already present on machine"
0.6256,Event,ADDED,eval-sanitize-30-r3-016-65rbc.18d4f8382cc331b2,reason=Created count=1 msg=Created container: task
0.6258,Event,ADDED,eval-sanitize-30-r3-016-65rbc.18d4f83831fbe2c2,reason=Started count=1 msg=Started container task
0.6261,Event,ADDED,eval-sanitize-30-r3-016.18d4f83809f4849c,reason=SuccessfulCreate count=1 msg=Created pod: eval-sanitize-30-r3-016-65rbc
0.6263,Event,ADDED,eval-sanitize-30-r3-016.18d4f83dc1f86c87,reason=Completed count=1 msg=Job completed
0.6266,Event,ADDED,eval-sanitize-30-r3-017-kch6m.18d4f838499fb0a9,reason=Scheduled count=None msg=Successfully assigned compute/eval-sanitize-30-r3-017-kch6m to kind-worker
0.6268,Event,ADDED,eval-sanitize-30-r3-017-kch6m.18d4f83866fd6b48,"reason=Pulled count=1 msg=Container image ""busybox:musl"" already present on machine"
0.6271,Event,ADDED,eval-sanitize-30-r3-017-kch6m.18d4f83868369dd4,reason=Created count=1 msg=Created container: task
0.6273,Event,ADDED,eval-sanitize-30-r3-017-kch6m.18d4f8386d47be3c,reason=Started count=1 msg=Started container task
0.6275,Event,ADDED,eval-sanitize-30-r3-017.18d4f838478f6bfc,reason=SuccessfulCreate count=1 msg=Created pod: eval-sanitize-30-r3-017-kch6m
0.6279,Event,ADDED,eval-sanitize-30-r3-017.18d4f83dfe50d689,reason=Completed count=1 msg=Job completed
0.6281,Event,ADDED,eval-sanitize-30-r3-018-v6rd2.18d4f838857e5f2b,reason=Scheduled count=None msg=Successfully assigned compute/eval-sanitize-30-r3-018-v6rd2 to kind-worker2
0.6283,Event,ADDED,eval-sanitize-30-r3-018-v6rd2.18d4f838a54ce35d,"reason=Pulled count=1 msg=Container image ""busybox:musl"" already present on machine"
0.6284,Event,ADDED,eval-sanitize-30-r3-018-v6rd2.18d4f838a688477d,reason=Created count=1 msg=Created container: task
0.6287,Event,ADDED,eval-sanitize-30-r3-018-v6rd2.18d4f838ae362163,reason=Started count=1 msg=Started container task
0.6289,Event,ADDED,eval-sanitize-30-r3-018.18d4f8388108955c,reason=SuccessfulCreate count=1 msg=Created pod: eval-sanitize-30-r3-018-v6rd2
0.6292,Event,ADDED,eval-sanitize-30-r3-018.18d4f83e30575223,reason=Completed count=1 msg=Job completed
0.6294,Event,ADDED,eval-sanitize-30-r3-019-gprwf.18d4f838c8025b5c,reason=Scheduled count=None msg=Successfully assigned compute/eval-sanitize-30-r3-019-gprwf to kind-worker3
0.6298,Event,ADDED,eval-sanitize-30-r3-019-gprwf.18d4f838e3a5ebf2,"reason=Pulled count=1 msg=Container image ""busybox:musl"" already present on machine"
0.6301,Event,ADDED,eval-sanitize-30-r3-019-gprwf.18d4f838e4e8d73e,reason=Created count=1 msg=Created container: task
0.6303,Event,ADDED,eval-sanitize-30-r3-019-gprwf.18d4f838e9e4053c,reason=Started count=1 msg=Started container task
0.6305,Event,ADDED,eval-sanitize-30-r3-019.18d4f838bfc2db67,reason=SuccessfulCreate count=1 msg=Created pod: eval-sanitize-30-r3-019-gprwf
0.6307,Event,ADDED,eval-sanitize-30-r3-019.18d4f83e7fea1edf,reason=Completed count=1 msg=Job completed
0.6309,Event,ADDED,eval-sanitize-30-r3-020-dbkjx.18d4f838ff4136db,reason=Scheduled count=None msg=Successfully assigned compute/eval-sanitize-30-r3-020-dbkjx to kind-worker5
0.631,Event,ADDED,eval-sanitize-30-r3-020-dbkjx.18d4f83918e070c9,"reason=Pulled count=1 msg=Container image ""busybox:musl"" already present on machine"
0.6313,Event,ADDED,eval-sanitize-30-r3-020-dbkjx.18d4f8391a1dd367,reason=Created count=1 msg=Created container: task
0.6315,Event,ADDED,eval-sanitize-30-r3-020-dbkjx.18d4f8391eccc174,reason=Started count=1 msg=Started container task
0.6317,Event,ADDED,eval-sanitize-30-r3-020.18d4f838f8d94692,reason=SuccessfulCreate count=1 msg=Created pod: eval-sanitize-30-r3-020-dbkjx
0.6319,Event,ADDED,eval-sanitize-30-r3-020.18d4f83ebc5787b0,reason=Completed count=1 msg=Job completed
0.6323,Event,ADDED,eval-sanitize-30-r3-021-j2xvp.18d4f839346d8d87,reason=Scheduled count=None msg=Successfully assigned compute/eval-sanitize-30-r3-021-j2xvp to kind-worker5
0.6325,Event,ADDED,eval-sanitize-30-r3-021-j2xvp.18d4f8394e6f4765,"reason=Pulled count=1 msg=Container image ""busybox:musl"" already present on machine"
0.6327,Event,ADDED,eval-sanitize-30-r3-021-j2xvp.18d4f8394fcb878a,reason=Created count=1 msg=Created container: task
0.633,Event,ADDED,eval-sanitize-30-r3-021-j2xvp.18d4f83954249c90,reason=Started count=1 msg=Started container task
0.6333,Event,ADDED,eval-sanitize-30-r3-021.18d4f8393393816c,reason=SuccessfulCreate count=1 msg=Created pod: eval-sanitize-30-r3-021-j2xvp
0.6334,Event,ADDED,eval-sanitize-30-r3-021.18d4f83ebc3faf89,reason=Completed count=1 msg=Job completed
0.6337,Event,ADDED,eval-sanitize-30-r3-022-2rvm9.18d4f839708ca9ce,"reason=FailedScheduling count=None msg=0/6 nodes are available: 1 c_wall violated: 2 conflicting context pair(s) with node memory, 5 node(s) had untolerated taint(s). no new claims to deallocate, preemption: 0/6 nodes are available: 1 No preemption victims found for incoming pod, 5 Preemption is not helpful for scheduling."
0.6343,Event,ADDED,eval-sanitize-30-r3-022-2rvm9.18d4f83971627581,"reason=FailedScheduling count=None msg=0/6 nodes are available: 1 c_wall violated: 2 conflicting context pair(s) with node memory, 5 node(s) had untolerated taint(s). no new claims to deallocate, preemption: 0/6 nodes are available: 1 No preemption victims found for incoming pod, 5 Preemption is not helpful for scheduling."
0.6345,Event,ADDED,eval-sanitize-30-r3-022-2rvm9.18d4f840025c38b7,reason=Scheduled count=None msg=Successfully assigned compute/eval-sanitize-30-r3-022-2rvm9 to kind-worker
0.6347,Event,ADDED,eval-sanitize-30-r3-022-2rvm9.18d4f8401f73d7a6,"reason=Pulled count=1 msg=Container image ""busybox:musl"" already present on machine"
0.6352,Event,ADDED,eval-sanitize-30-r3-022-2rvm9.18d4f84022c0d2e9,reason=Created count=1 msg=Created container: task
0.6356,Event,ADDED,eval-sanitize-30-r3-022-2rvm9.18d4f84028e8aa40,reason=Started count=1 msg=Started container task
0.6359,Event,ADDED,eval-sanitize-30-r3-022.18d4f839702eb504,reason=SuccessfulCreate count=1 msg=Created pod: eval-sanitize-30-r3-022-2rvm9
0.6361,Event,ADDED,eval-sanitize-30-r3-022.18d4f84578a97e9d,reason=Completed count=1 msg=Job completed
0.6364,Event,ADDED,eval-sanitize-30-r3-023-xr55f.18d4f839acbbff5f,"reason=FailedScheduling count=None msg=0/6 nodes are available: 6 node(s) had untolerated taint(s). no new claims to deallocate, preemption: 0/6 nodes are available: 6 Preemption is not helpful for scheduling."
0.6366,Event,ADDED,eval-sanitize-30-r3-023-xr55f.18d4f8400371820d,reason=Scheduled count=None msg=Successfully assigned compute/eval-sanitize-30-r3-023-xr55f to kind-worker
0.637,Event,ADDED,eval-sanitize-30-r3-023-xr55f.18d4f8401fc61a19,"reason=Pulled count=1 msg=Container image ""busybox:musl"" already present on machine"
0.6375,Event,ADDED,eval-sanitize-30-r3-023-xr55f.18d4f840238c2b8d,reason=Created count=1 msg=Created container: task
0.6378,Event,ADDED,eval-sanitize-30-r3-023-xr55f.18d4f84028e91a0d,reason=Started count=1 msg=Started container task
0.6382,Event,ADDED,eval-sanitize-30-r3-023.18d4f839acab2047,reason=SuccessfulCreate count=1 msg=Created pod: eval-sanitize-30-r3-023-xr55f
0.6386,Event,ADDED,eval-sanitize-30-r3-023.18d4f84750407689,reason=Completed count=1 msg=Job completed
0.639,Event,ADDED,eval-sanitize-30-r3-024-q4nmb.18d4f839e83548d5,"reason=FailedScheduling count=None msg=0/6 nodes are available: 6 node(s) had untolerated taint(s). no new claims to deallocate, preemption: 0/6 nodes are available: 6 Preemption is not helpful for scheduling."
0.6392,Event,ADDED,eval-sanitize-30-r3-024-q4nmb.18d4f84002f820e5,"reason=FailedScheduling count=None msg=0/6 nodes are available: 1 c_wall violated: 1 conflicting context pair(s) with node memory, 5 node(s) had untolerated taint(s). no new claims to deallocate, preemption: 0/6 nodes are available: 1 No preemption victims found for incoming pod, 5 Preemption is not helpful for scheduling."
0.6395,Event,ADDED,eval-sanitize-30-r3-024-q4nmb.18d4f84045313d0a,reason=Scheduled count=None msg=Successfully assigned compute/eval-sanitize-30-r3-024-q4nmb to kind-worker3
0.6398,Event,ADDED,eval-sanitize-30-r3-024-q4nmb.18d4f84060f7555b,"reason=Pulled count=1 msg=Container image ""busybox:musl"" already present on machine"
0.64,Event,ADDED,eval-sanitize-30-r3-024-q4nmb.18d4f84062e42a02,reason=Created count=1 msg=Created container: task
0.6402,Event,ADDED,eval-sanitize-30-r3-024-q4nmb.18d4f8406b3e67c0,reason=Started count=1 msg=Started container task
0.6406,Event,ADDED,eval-sanitize-30-r3-024.18d4f839e82bfa67,reason=SuccessfulCreate count=1 msg=Created pod: eval-sanitize-30-r3-024-q4nmb
0.6413,Event,ADDED,eval-sanitize-30-r3-024.18d4f8477ff33f66,reason=Completed count=1 msg=Job completed
0.6417,Event,ADDED,eval-sanitize-30-r3-025-bsmbf.18d4f83a21cc20b2,"reason=FailedScheduling count=None msg=0/6 nodes are available: 6 node(s) had untolerated taint(s). no new claims to deallocate, preemption: 0/6 nodes are available: 6 Preemption is not helpful for scheduling."
0.642,Event,ADDED,eval-sanitize-30-r3-025-bsmbf.18d4f84004316c4b,"reason=FailedScheduling count=None msg=0/6 nodes are available: 1 c_wall violated: 1 conflicting context pair(s) with node memory, 5 node(s) had untolerated taint(s). no new claims to deallocate, preemption: 0/6 nodes are available: 1 No preemption victims found for incoming pod, 5 Preemption is not helpful for scheduling."
0.6424,Event,ADDED,eval-sanitize-30-r3-025-bsmbf.18d4f8404b2ef0ae,reason=Scheduled count=None msg=Successfully assigned compute/eval-sanitize-30-r3-025-bsmbf to kind-worker3
0.6426,Event,ADDED,eval-sanitize-30-r3-025-bsmbf.18d4f8406b41b675,"reason=Pulled count=1 msg=Container image ""busybox:musl"" already present on machine"
0.6428,Event,ADDED,eval-sanitize-30-r3-025-bsmbf.18d4f8406d192b52,reason=Created count=1 msg=Created container: task
0.643,Event,ADDED,eval-sanitize-30-r3-025-bsmbf.18d4f84070c58af6,reason=Started count=1 msg=Started container task
0.6437,Event,ADDED,eval-sanitize-30-r3-025.18d4f83a21c19421,reason=SuccessfulCreate count=1 msg=Created pod: eval-sanitize-30-r3-025-bsmbf
0.6444,Event,ADDED,eval-sanitize-30-r3-025.18d4f8477405848f,reason=Completed count=1 msg=Job completed
0.6452,Event,ADDED,eval-sanitize-30-r3-026-7846h.18d4f83a5e508a05,"reason=FailedScheduling count=None msg=0/6 nodes are available: 6 node(s) had untolerated taint(s). no new claims to deallocate, preemption: 0/6 nodes are available: 6 Preemption is not helpful for scheduling."
0.6455,Event,ADDED,eval-sanitize-30-r3-026-7846h.18d4f840056ac884,reason=Scheduled count=None msg=Successfully assigned compute/eval-sanitize-30-r3-026-7846h to kind-worker
0.646,Event,ADDED,eval-sanitize-30-r3-026-7846h.18d4f84020b25965,"reason=Pulled count=1 msg=Container image ""busybox:musl"" already present on machine"
0.6463,Event,ADDED,eval-sanitize-30-r3-026-7846h.18d4f84024606544,reason=Created count=1 msg=Created container: task
0.6465,Event,ADDED,eval-sanitize-30-r3-026-7846h.18d4f84028a2712b,reason=Started count=1 msg=Started container task
0.6468,Event,ADDED,eval-sanitize-30-r3-026.18d4f83a5e3de6c6,reason=SuccessfulCreate count=1 msg=Created pod: eval-sanitize-30-r3-026-7846h
0.647,Event,ADDED,eval-sanitize-30-r3-026.18d4f847593ba608,reason=Completed count=1 msg=Job completed
0.6472,Event,ADDED,eval-sanitize-30-r3-027-rlvj6.18d4f83a9c4ce87f,"reason=FailedScheduling count=None msg=0/6 nodes are available: 6 node(s) had untolerated taint(s). no new claims to deallocate, preemption: 0/6 nodes are available: 6 Preemption is not helpful for scheduling."
0.6473,Event,ADDED,eval-sanitize-30-r3-027-rlvj6.18d4f840052d0518,"reason=FailedScheduling count=None msg=0/6 nodes are available: 1 c_wall violated: 2 conflicting context pair(s) with node memory, 5 node(s) had untolerated taint(s). no new claims to deallocate, preemption: 0/6 nodes are available: 1 No preemption victims found for incoming pod, 5 Preemption is not helpful for scheduling."
0.6477,Event,ADDED,eval-sanitize-30-r3-027-rlvj6.18d4f840504d5142,"reason=FailedScheduling count=None msg=0/6 nodes are available: 1 c_wall violated: 3 conflicting context pair(s) with node memory, 2 c_wall violated: 2 conflicting context pair(s) with node memory, 3 node(s) had untolerated taint(s). no new claims to deallocate, preemption: 0/6 nodes are available: 3 No preemption victims found for incoming pod, 3 Preemption is not helpful for scheduling."
0.648,Event,ADDED,eval-sanitize-30-r3-027-rlvj6.18d4f84083cd669c,reason=Scheduled count=None msg=Successfully assigned compute/eval-sanitize-30-r3-027-rlvj6 to kind-worker5
0.6482,Event,ADDED,eval-sanitize-30-r3-027-rlvj6.18d4f840a8837799,"reason=Pulled count=1 msg=Container image ""busybox:musl"" already present on machine"
0.6485,Event,ADDED,eval-sanitize-30-r3-027-rlvj6.18d4f840ab0dde8d,reason=Created count=1 msg=Created container: task
0.6487,Event,ADDED,eval-sanitize-30-r3-027-rlvj6.18d4f840b231c260,reason=Started count=1 msg=Started container task
0.6489,Event,ADDED,eval-sanitize-30-r3-027.18d4f83a9c55df8e,reason=SuccessfulCreate count=1 msg=Created pod: eval-sanitize-30-r3-027-rlvj6
0.6492,Event,ADDED,eval-sanitize-30-r3-027.18d4f847fa4f67c7,reason=Completed count=1 msg=Job completed
0.6497,Event,ADDED,eval-sanitize-30-r3-028-gpg4m.18d4f83ad8c59449,"reason=FailedScheduling count=None msg=0/6 nodes are available: 6 node(s) had untolerated taint(s). no new claims to deallocate, preemption: 0/6 nodes are available: 6 Preemption is not helpful for scheduling."
0.6501,Event,ADDED,eval-sanitize-30-r3-028-gpg4m.18d4f840093bf3dd,reason=Scheduled count=None msg=Successfully assigned compute/eval-sanitize-30-r3-028-gpg4m to kind-worker
0.6504,Event,ADDED,eval-sanitize-30-r3-028-gpg4m.18d4f8402786fe49,"reason=Pulled count=1 msg=Container image ""busybox:musl"" already present on machine"
0.6508,Event,ADDED,eval-sanitize-30-r3-028-gpg4m.18d4f8402927c22f,reason=Created count=1 msg=Created container: task
0.6511,Event,ADDED,eval-sanitize-30-r3-028-gpg4m.18d4f8402de38523,reason=Started count=1 msg=Started container task
0.6515,Event,ADDED,eval-sanitize-30-r3-028.18d4f83ad8ba4e36,reason=SuccessfulCreate count=1 msg=Created pod: eval-sanitize-30-r3-028-gpg4m
0.6519,Event,ADDED,eval-sanitize-30-r3-028.18d4f84578edb7d2,reason=Completed count=1 msg=Job completed
0.6522,Event,ADDED,eval-sanitize-30-r3-029-7gjnz.18d4f83b10c0d5b9,"reason=FailedScheduling count=None msg=0/6 nodes are available: 6 node(s) had untolerated taint(s). no new claims to deallocate, preemption: 0/6 nodes are available: 6 Preemption is not helpful for scheduling."
0.6525,Event,ADDED,eval-sanitize-30-r3-029-7gjnz.18d4f840090fd791,"reason=FailedScheduling count=None msg=0/6 nodes are available: 1 c_wall violated: 1 conflicting context pair(s) with node memory, 5 node(s) had untolerated taint(s). no new claims to deallocate, preemption: 0/6 nodes are available: 1 No preemption victims found for incoming pod, 5 Preemption is not helpful for scheduling."
0.6528,Event,ADDED,eval-sanitize-30-r3-029-7gjnz.18d4f84052ad06d1,"reason=FailedScheduling count=None msg=0/6 nodes are available: 1 c_wall violated: 1 conflicting context pair(s) with node memory, 1 c_wall violated: 2 conflicting context pair(s) with node memory, 1 c_wall violated: 3 conflicting context pair(s) with node memory, 3 node(s) had untolerated taint(s). no new claims to deallocate, preemption: 0/6 nodes are available: 3 No preemption victims found for incoming pod, 3 Preemption is not helpful for scheduling."
0.6533,Event,ADDED,eval-sanitize-30-r3-029-7gjnz.18d4f84087836a11,reason=Scheduled count=None msg=Successfully assigned compute/eval-sanitize-30-r3-029-7gjnz to kind-worker5
0.6539,Event,ADDED,eval-sanitize-30-r3-029-7gjnz.18d4f840a8a1d356,"reason=Pulled count=1 msg=Container image ""busybox:musl"" already present on machine"
0.6543,Event,ADDED,eval-sanitize-30-r3-029-7gjnz.18d4f840abff1083,reason=Created count=1 msg=Created container: task
0.6545,Event,ADDED,eval-sanitize-30-r3-029-7gjnz.18d4f840b23261f7,reason=Started count=1 msg=Started container task
0.6548,Event,ADDED,eval-sanitize-30-r3-029.18d4f83b10b5f95c,reason=SuccessfulCreate count=1 msg=Created pod: eval-sanitize-30-r3-029-7gjnz
0.655,Event,ADDED,eval-sanitize-30-r3-029.18d4f847f18c2eec,reason=Completed count=1 msg=Job completed
0.6552,Event,ADDED,eval-sanitize-30-r3-030-f6mxr.18d4f83b4efaa46c,"reason=FailedScheduling count=None msg=0/6 nodes are available: 6 node(s) had untolerated taint(s). no new claims to deallocate, preemption: 0/6 nodes are available: 6 Preemption is not helpful for scheduling."
0.6556,Event,ADDED,eval-sanitize-30-r3-030-f6mxr.18d4f8400a1d32db,reason=Scheduled count=None msg=Successfully assigned compute/eval-sanitize-30-r3-030-f6mxr to kind-worker
0.656,Event,ADDED,eval-sanitize-30-r3-030-f6mxr.18d4f8402b1ef9e2,"reason=Pulled count=1 msg=Container image ""busybox:musl"" already present on machine"
0.6563,Event,ADDED,eval-sanitize-30-r3-030-f6mxr.18d4f8402dde31a5,reason=Created count=1 msg=Created container: task
0.6566,Event,ADDED,eval-sanitize-30-r3-030-f6mxr.18d4f84032d11aee,reason=Started count=1 msg=Started container task
0.6571,Event,ADDED,eval-sanitize-30-r3-030.18d4f83b4ef1df22,reason=SuccessfulCreate count=1 msg=Created pod: eval-sanitize-30-r3-030-f6mxr
0.6573,Event,ADDED,eval-sanitize-30-r3-030.18d4f84578a82e03,reason=Completed count=1 msg=Job completed
0.6577,Event,ADDED,eval-sanitize-30-r3-031-g7gkv.18d4f83b88cd2fdc,"reason=FailedScheduling count=None msg=0/6 nodes are available: 6 node(s) had untolerated taint(s). no new claims to deallocate, preemption: 0/6 nodes are available: 6 Preemption is not helpful for scheduling."
0.658,Event,ADDED,eval-sanitize-30-r3-031-g7gkv.18d4f84009f52025,"reason=FailedScheduling count=None msg=0/6 nodes are available: 1 c_wall violated: 1 conflicting context pair(s) with node memory, 5 node(s) had untolerated taint(s). no new claims to deallocate, preemption: 0/6 nodes are available: 1 No preemption victims found for incoming pod, 5 Preemption is not helpful for scheduling."
0.6583,Event,ADDED,eval-sanitize-30-r3-031-g7gkv.18d4f840587c4875,reason=Scheduled count=None msg=Successfully assigned compute/eval-sanitize-30-r3-031-g7gkv to kind-worker3
0.6589,Event,ADDED,eval-sanitize-30-r3-031-g7gkv.18d4f84072251809,"reason=Pulled count=1 msg=Container image ""busybox:musl"" already present on machine"
0.6593,Event,ADDED,eval-sanitize-30-r3-031-g7gkv.18d4f840736e2eb7,reason=Created count=1 msg=Created container: task
0.6598,Event,ADDED,eval-sanitize-30-r3-031-g7gkv.18d4f8407a87f39f,reason=Started count=1 msg=Started container task
0.66,Event,ADDED,eval-sanitize-30-r3-031.18d4f83b88c68d51,reason=SuccessfulCreate count=1 msg=Created pod: eval-sanitize-30-r3-031-g7gkv
0.6602,Event,ADDED,eval-sanitize-30-r3-031.18d4f84765544582,reason=Completed count=1 msg=Job completed
0.6604,Event,ADDED,eval-sanitize-30-r3-032-wpwtg.18d4f83bc4eeaf05,"reason=FailedScheduling count=None msg=0/6 nodes are available: 6 node(s) had untolerated taint(s). no new claims to deallocate, preemption: 0/6 nodes are available: 6 Preemption is not helpful for scheduling."
0.6606,Event,ADDED,eval-sanitize-30-r3-032-wpwtg.18d4f8400e17bd3e,"reason=FailedScheduling count=None msg=0/6 nodes are available: 1 c_wall violated: 1 conflicting context pair(s) with node memory, 5 node(s) had untolerated taint(s). no new claims to deallocate, preemption: 0/6 nodes are available: 1 No preemption victims found for incoming pod, 5 Preemption is not helpful for scheduling."
0.6608,Event,ADDED,eval-sanitize-30-r3-032-wpwtg.18d4f8405d65253b,"reason=FailedScheduling count=None msg=0/6 nodes are available: 1 c_wall violated: 1 conflicting context pair(s) with node memory, 1 c_wall violated: 2 conflicting context pair(s) with node memory, 1 c_wall violated: 3 conflicting context pair(s) with node memory, 3 node(s) had untolerated taint(s). no new claims to deallocate, preemption: 0/6 nodes are available: 3 No preemption victims found for incoming pod, 3 Preemption is not helpful for scheduling."
0.661,Event,ADDED,eval-sanitize-30-r3-032-wpwtg.18d4f8408dafcdc5,reason=Scheduled count=None msg=Successfully assigned compute/eval-sanitize-30-r3-032-wpwtg to kind-worker5
0.6614,Event,ADDED,eval-sanitize-30-r3-032-wpwtg.18d4f840a8cbe9ce,"reason=Pulled count=1 msg=Container image ""busybox:musl"" already present on machine"
0.662,Event,ADDED,eval-sanitize-30-r3-032-wpwtg.18d4f840abe59f53,reason=Created count=1 msg=Created container: task
0.6623,Event,ADDED,eval-sanitize-30-r3-032-wpwtg.18d4f840b23176b3,reason=Started count=1 msg=Started container task
0.6627,Event,ADDED,eval-sanitize-30-r3-032.18d4f83bc4e4b34e,reason=SuccessfulCreate count=1 msg=Created pod: eval-sanitize-30-r3-032-wpwtg
0.6629,Event,ADDED,eval-sanitize-30-r3-032.18d4f847ee3e81e6,reason=Completed count=1 msg=Job completed
0.6632,Event,ADDED,eval-sanitize-30-r3-033-j2kk7.18d4f83c01fcdbbe,"reason=FailedScheduling count=None msg=0/6 nodes are available: 6 node(s) had untolerated taint(s). no new claims to deallocate, preemption: 0/6 nodes are available: 6 Preemption is not helpful for scheduling."
0.6634,Event,ADDED,eval-sanitize-30-r3-033-j2kk7.18d4f8400f091b75,reason=Scheduled count=None msg=Successfully assigned compute/eval-sanitize-30-r3-033-j2kk7 to kind-worker
0.6637,Event,ADDED,eval-sanitize-30-r3-033-j2kk7.18d4f8402d832942,"reason=Pulled count=1 msg=Container image ""busybox:musl"" already present on machine"
0.6639,Event,ADDED,eval-sanitize-30-r3-033-j2kk7.18d4f8402f552ca0,reason=Created count=1 msg=Created container: task
0.6641,Event,ADDED,eval-sanitize-30-r3-033-j2kk7.18d4f840331cbfe3,reason=Started count=1 msg=Started container task
0.6642,Event,ADDED,eval-sanitize-30-r3-033.18d4f83c01f68755,reason=SuccessfulCreate count=1 msg=Created pod: eval-sanitize-30-r3-033-j2kk7
0.6646,Event,ADDED,eval-sanitize-30-r3-033.18d4f847061c9f05,reason=Completed count=1 msg=Job completed
0.6647,Event,ADDED,eval-sanitize-30-r3-034-pkpml.18d4f83c3a26dfd7,"reason=FailedScheduling count=None msg=0/6 nodes are available: 6 node(s) had untolerated taint(s). no new claims to deallocate, preemption: 0/6 nodes are available: 6 Preemption is not helpful for scheduling."
0.665,Event,ADDED,eval-sanitize-30-r3-034-pkpml.18d4f8400ee973bc,"reason=FailedScheduling count=None msg=0/6 nodes are available: 1 c_wall violated: 1 conflicting context pair(s) with node memory, 5 node(s) had untolerated taint(s). no new claims to deallocate, preemption: 0/6 nodes are available: 1 No preemption victims found for incoming pod, 5 Preemption is not helpful for scheduling."
0.6653,Event,ADDED,eval-sanitize-30-r3-034-pkpml.18d4f840641a6620,reason=Scheduled count=None msg=Successfully assigned compute/eval-sanitize-30-r3-034-pkpml to kind-worker3
0.6658,Event,ADDED,eval-sanitize-30-r3-034-pkpml.18d4f8408401f50a,"reason=Pulled count=1 msg=Container image ""busybox:musl"" already present on machine"
0.6661,Event,ADDED,eval-sanitize-30-r3-034-pkpml.18d4f84086693cf6,reason=Created count=1 msg=Created container: task
0.6664,Event,ADDED,eval-sanitize-30-r3-034-pkpml.18d4f8408c15f7a0,reason=Started count=1 msg=Started container task
0.6669,Event,ADDED,eval-sanitize-30-r3-034.18d4f83c3a21cf09,reason=SuccessfulCreate count=1 msg=Created pod: eval-sanitize-30-r3-034-pkpml
0.6673,Event,ADDED,eval-sanitize-30-r3-034.18d4f847a0ccad86,reason=Completed count=1 msg=Job completed
0.6679,Event,ADDED,eval-sanitize-30-r3-035-xvrtw.18d4f83c7aecc046,"reason=FailedScheduling count=None msg=0/6 nodes are available: 6 node(s) had untolerated taint(s). no new claims to deallocate, preemption: 0/6 nodes are available: 6 Preemption is not helpful for scheduling."
0.6685,Event,ADDED,eval-sanitize-30-r3-035-xvrtw.18d4f8400fb3d028,"reason=FailedScheduling count=None msg=0/6 nodes are available: 1 c_wall violated: 1 conflicting context pair(s) with node memory, 5 node(s) had untolerated taint(s). no new claims to deallocate, preemption: 0/6 nodes are available: 1 No preemption victims found for incoming pod, 5 Preemption is not helpful for scheduling."
0.6687,Event,ADDED,eval-sanitize-30-r3-035-xvrtw.18d4f8406b7c6deb,reason=Scheduled count=None msg=Successfully assigned compute/eval-sanitize-30-r3-035-xvrtw to kind-worker3
0.669,Event,ADDED,eval-sanitize-30-r3-035-xvrtw.18d4f8408c3fe422,"reason=Pulled count=1 msg=Container image ""busybox:musl"" already present on machine"
0.6692,Event,ADDED,eval-sanitize-30-r3-035-xvrtw.18d4f8408dd714f1,reason=Created count=1 msg=Created container: task
0.6694,Event,ADDED,eval-sanitize-30-r3-035-xvrtw.18d4f84092a9d374,reason=Started count=1 msg=Started container task
0.6698,Event,ADDED,eval-sanitize-30-r3-035.18d4f83c7ae5814d,reason=SuccessfulCreate count=1 msg=Created pod: eval-sanitize-30-r3-035-xvrtw
0.6699,Event,ADDED,eval-sanitize-30-r3-035.18d4f847d6a97c54,reason=Completed count=1 msg=Job completed
0.6702,Event,ADDED,eval-sanitize-30-r3-036-z8lhz.18d4f83cb2b64fd5,"reason=FailedScheduling count=None msg=0/6 nodes are available: 6 node(s) had untolerated taint(s). no new claims to deallocate, preemption: 0/6 nodes are available: 6 Preemption is not helpful for scheduling."
0.6704,Event,ADDED,eval-sanitize-30-r3-036-z8lhz.18d4f84011362307,"reason=FailedScheduling count=None msg=0/6 nodes are available: 1 c_wall violated: 2 conflicting context pair(s) with node memory, 5 node(s) had untolerated taint(s). no new claims to deallocate, preemption: 0/6 nodes are available: 1 No preemption victims found for incoming pod, 5 Preemption is not helpful for scheduling."
0.6705,Event,ADDED,eval-sanitize-30-r3-036-z8lhz.18d4f8406ef15cb8,"reason=FailedScheduling count=None msg=0/6 nodes are available: 1 c_wall violated: 3 conflicting context pair(s) with node memory, 2 c_wall violated: 2 conflicting context pair(s) with node memory, 3 node(s) had untolerated taint(s). no new claims to deallocate, preemption: 0/6 nodes are available: 3 No preemption victims found for incoming pod, 3 Preemption is not helpful for scheduling."
0.6707,Event,ADDED,eval-sanitize-30-r3-036-z8lhz.18d4f840940aa88c,reason=Scheduled count=None msg=Successfully assigned compute/eval-sanitize-30-r3-036-z8lhz to kind-worker2
0.6709,Event,ADDED,eval-sanitize-30-r3-036-z8lhz.18d4f840b22caff7,"reason=Pulled count=1 msg=Container image ""busybox:musl"" already present on machine"
0.6711,Event,ADDED,eval-sanitize-30-r3-036-z8lhz.18d4f840b47ffc29,reason=Created count=1 msg=Created container: task
0.6712,Event,ADDED,eval-sanitize-30-r3-036-z8lhz.18d4f840bd32e1fa,reason=Started count=1 msg=Started container task
0.6714,Event,ADDED,eval-sanitize-30-r3-036.18d4f83cb29f30b0,reason=SuccessfulCreate count=1 msg=Created pod: eval-sanitize-30-r3-036-z8lhz
0.6717,Event,ADDED,eval-sanitize-30-r3-036.18d4f84791cf7d57,reason=Completed count=1 msg=Job completed
0.6719,Event,ADDED,eval-sanitize-30-r3-037-wn6cn.18d4f83cedf3cc52,"reason=FailedScheduling count=None msg=0/6 nodes are available: 6 node(s) had untolerated taint(s). no new claims to deallocate, preemption: 0/6 nodes are available: 6 Preemption is not helpful for scheduling."
0.6723,Event,ADDED,eval-sanitize-30-r3-037-wn6cn.18d4f84013c60a2d,"reason=FailedScheduling count=None msg=0/6 nodes are available: 1 c_wall violated: 2 conflicting context pair(s) with node memory, 5 node(s) had untolerated taint(s). no new claims to deallocate, preemption: 0/6 nodes are available: 1 No preemption victims found for incoming pod, 5 Preemption is not helpful for scheduling."
0.6727,Event,ADDED,eval-sanitize-30-r3-037-wn6cn.18d4f8407a7ce451,reason=Scheduled count=None msg=Successfully assigned compute/eval-sanitize-30-r3-037-wn6cn to kind-worker3
0.6731,Event,ADDED,eval-sanitize-30-r3-037-wn6cn.18d4f840948a171d,"reason=Pulled count=1 msg=Container image ""busybox:musl"" already present on machine"
0.6736,Event,ADDED,eval-sanitize-30-r3-037-wn6cn.18d4f840964c7650,reason=Created count=1 msg=Created container: task
0.6743,Event,ADDED,eval-sanitize-30-r3-037-wn6cn.18d4f8409fa3c7f6,reason=Started count=1 msg=Started container task
0.6746,Event,ADDED,eval-sanitize-30-r3-037.18d4f83cede6ac47,reason=SuccessfulCreate count=1 msg=Created pod: eval-sanitize-30-r3-037-wn6cn
0.6748,Event,ADDED,eval-sanitize-30-r3-037.18d4f847e84f0fd0,reason=Completed count=1 msg=Job completed
0.675,Event,ADDED,eval-sanitize-30-r3-038-gh99x.18d4f83d28fe52fb,"reason=FailedScheduling count=None msg=0/6 nodes are available: 6 node(s) had untolerated taint(s). no new claims to deallocate, preemption: 0/6 nodes are available: 6 Preemption is not helpful for scheduling."
0.6753,Event,ADDED,eval-sanitize-30-r3-038-gh99x.18d4f84014d0532a,reason=Scheduled count=None msg=Successfully assigned compute/eval-sanitize-30-r3-038-gh99x to kind-worker4
0.6756,Event,ADDED,eval-sanitize-30-r3-038-gh99x.18d4f84032f9b890,"reason=Pulled count=1 msg=Container image ""busybox:musl"" already present on machine"
0.6761,Event,ADDED,eval-sanitize-30-r3-038-gh99x.18d4f84035dae86a,reason=Created count=1 msg=Created container: task
0.6765,Event,ADDED,eval-sanitize-30-r3-038-gh99x.18d4f8403a38bab7,reason=Started count=1 msg=Started container task
0.6769,Event,ADDED,eval-sanitize-30-r3-038.18d4f83d28f17ab3,reason=SuccessfulCreate count=1 msg=Created pod: eval-sanitize-30-r3-038-gh99x
0.6773,Event,ADDED,eval-sanitize-30-r3-038.18d4f845779fc71d,reason=Completed count=1 msg=Job completed
0.6776,Event,ADDED,eval-sanitize-30-r3-039-dfs64.18d4f83d65d3b0df,"reason=FailedScheduling count=None msg=0/6 nodes are available: 6 node(s) had untolerated taint(s). no new claims to deallocate, preemption: 0/6 nodes are available: 6 Preemption is not helpful for scheduling."
0.678,Event,ADDED,eval-sanitize-30-r3-039-dfs64.18d4f8401638ed05,reason=Scheduled count=None msg=Successfully assigned compute/eval-sanitize-30-r3-039-dfs64 to kind-worker4
0.6783,Event,ADDED,eval-sanitize-30-r3-039-dfs64.18d4f840335316b0,"reason=Pulled count=1 msg=Container image ""busybox:musl"" already present on machine"
0.679,Event,ADDED,eval-sanitize-30-r3-039-dfs64.18d4f8403641841b,reason=Created count=1 msg=Created container: task
0.6794,Event,ADDED,eval-sanitize-30-r3-039-dfs64.18d4f84039889f96,reason=Started count=1 msg=Started container task
0.6797,Event,ADDED,eval-sanitize-30-r3-039.18d4f83d65ca7bb4,reason=SuccessfulCreate count=1 msg=Created pod: eval-sanitize-30-r3-039-dfs64
0.6799,Event,ADDED,eval-sanitize-30-r3-039.18d4f846e7eb6612,reason=Completed count=1 msg=Job completed
0.6802,Event,ADDED,eval-sanitize-30-r3-040-bkxzq.18d4f83da1e7650e,"reason=FailedScheduling count=None msg=0/6 nodes are available: 6 node(s) had untolerated taint(s). no new claims to deallocate, preemption: 0/6 nodes are available: 6 Preemption is not helpful for scheduling."
0.6804,Event,ADDED,eval-sanitize-30-r3-040-bkxzq.18d4f8401af9304c,reason=Scheduled count=None msg=Successfully assigned compute/eval-sanitize-30-r3-040-bkxzq to kind-worker4
0.6806,Event,ADDED,eval-sanitize-30-r3-040-bkxzq.18d4f84038e9dc59,"reason=Pulled count=1 msg=Container image ""busybox:musl"" already present on machine"
0.6809,Event,ADDED,eval-sanitize-30-r3-040-bkxzq.18d4f8403da38fe5,reason=Created count=1 msg=Created container: task
0.6813,Event,ADDED,eval-sanitize-30-r3-040-bkxzq.18d4f8404473aad8,reason=Started count=1 msg=Started container task
0.6816,Event,ADDED,eval-sanitize-30-r3-040.18d4f83da1dc2abe,reason=SuccessfulCreate count=1 msg=Created pod: eval-sanitize-30-r3-040-bkxzq
0.6818,Event,ADDED,eval-sanitize-30-r3-040.18d4f846d91c5ec2,reason=Completed count=1 msg=Job completed
0.6821,Event,ADDED,eval-sanitize-30-r3-041-g8pfg.18d4f83dddf602f0,"reason=FailedScheduling count=None msg=0/6 nodes are available: 6 node(s) had untolerated taint(s). no new claims to deallocate, preemption: 0/6 nodes are available: 6 Preemption is not helpful for scheduling."
0.6823,Event,ADDED,eval-sanitize-30-r3-041-g8pfg.18d4f8401c035f1c,reason=Scheduled count=None msg=Successfully assigned compute/eval-sanitize-30-r3-041-g8pfg to kind-worker4
0.6824,Event,ADDED,eval-sanitize-30-r3-041-g8pfg.18d4f8403a894541,"reason=Pulled count=1 msg=Container image ""busybox:musl"" already present on machine"
0.6828,Event,ADDED,eval-sanitize-30-r3-041-g8pfg.18d4f8403f086ee8,reason=Created count=1 msg=Created container: task
0.6831,Event,ADDED,eval-sanitize-30-r3-041-g8pfg.18d4f84043f3e0ac,reason=Started count=1 msg=Started container task
0.6833,Event,ADDED,eval-sanitize-30-r3-041.18d4f83dddeab0f5,reason=SuccessfulCreate count=1 msg=Created pod: eval-sanitize-30-r3-041-g8pfg
0.6835,Event,ADDED,eval-sanitize-30-r3-041.18d4f846f0d039a6,reason=Completed count=1 msg=Job completed
0.6838,Event,ADDED,eval-sanitize-30-r3-042-wvxz5.18d4f83e16c17964,"reason=FailedScheduling count=None msg=0/6 nodes are available: 6 node(s) had untolerated taint(s). no new claims to deallocate, preemption: 0/6 nodes are available: 6 Preemption is not helpful for scheduling."
0.684,Event,ADDED,eval-sanitize-30-r3-042-wvxz5.18d4f8401cf17377,reason=Scheduled count=None msg=Successfully assigned compute/eval-sanitize-30-r3-042-wvxz5 to kind-worker4
0.6843,Event,ADDED,eval-sanitize-30-r3-042-wvxz5.18d4f8403afc9917,"reason=Pulled count=1 msg=Container image ""busybox:musl"" already present on machine"
0.6847,Event,ADDED,eval-sanitize-30-r3-042-wvxz5.18d4f8403ece5b4e,reason=Created count=1 msg=Created container: task
0.6851,Event,ADDED,eval-sanitize-30-r3-042-wvxz5.18d4f8404474230c,reason=Started count=1 msg=Started container task
0.6854,Event,ADDED,eval-sanitize-30-r3-042.18d4f83e16b90f4c,reason=SuccessfulCreate count=1 msg=Created pod: eval-sanitize-30-r3-042-wvxz5
0.6857,Event,ADDED,eval-sanitize-30-r3-042.18d4f8473b51d8a6,reason=Completed count=1 msg=Job completed
0.686,Event,ADDED,eval-sanitize-30-r3-043-55g5v.18d4f83e55263178,"reason=FailedScheduling count=None msg=0/6 nodes are available: 6 node(s) had untolerated taint(s). no new claims to deallocate, preemption: 0/6 nodes are available: 6 Preemption is not helpful for scheduling."
0.6861,Event,ADDED,eval-sanitize-30-r3-043-55g5v.18d4f84022266a53,reason=Scheduled count=None msg=Successfully assigned compute/eval-sanitize-30-r3-043-55g5v to kind-worker4
0.6863,Event,ADDED,eval-sanitize-30-r3-043-55g5v.18d4f84042413b63,"reason=Pulled count=1 msg=Container image ""busybox:musl"" already present on machine"
0.6865,Event,ADDED,eval-sanitize-30-r3-043-55g5v.18d4f840448554ae,reason=Created count=1 msg=Created container: task
0.6867,Event,ADDED,eval-sanitize-30-r3-043-55g5v.18d4f84048074e95,reason=Started count=1 msg=Started container task
0.6868,Event,ADDED,eval-sanitize-30-r3-043.18d4f83e55229515,reason=SuccessfulCreate count=1 msg=Created pod: eval-sanitize-30-r3-043-55g5v
0.687,Event,ADDED,eval-sanitize-30-r3-043.18d4f846df1e9374,reason=Completed count=1 msg=Job completed
0.6872,Event,ADDED,eval-sanitize-30-r3-044-lk9nk.18d4f83e8e7ea618,"reason=FailedScheduling count=None msg=0/6 nodes are available: 6 node(s) had untolerated taint(s). no new claims to deallocate, preemption: 0/6 nodes are available: 6 Preemption is not helpful for scheduling."
0.6874,Event,ADDED,eval-sanitize-30-r3-044-lk9nk.18d4f84025a7af19,reason=Scheduled count=None msg=Successfully assigned compute/eval-sanitize-30-r3-044-lk9nk to kind-worker4
0.6875,Event,ADDED,eval-sanitize-30-r3-044-lk9nk.18d4f84044bce184,"reason=Pulled count=1 msg=Container image ""busybox:musl"" already present on machine"
0.6877,Event,ADDED,eval-sanitize-30-r3-044-lk9nk.18d4f84046d4dfe1,reason=Created count=1 msg=Created container: task
0.6879,Event,ADDED,eval-sanitize-30-r3-044-lk9nk.18d4f84049fc5aab,reason=Started count=1 msg=Started container task
0.6881,Event,ADDED,eval-sanitize-30-r3-044.18d4f83e8e70656e,reason=SuccessfulCreate count=1 msg=Created pod: eval-sanitize-30-r3-044-lk9nk
0.6883,Event,ADDED,eval-sanitize-30-r3-044.18d4f846ffbebb4e,reason=Completed count=1 msg=Job completed
0.6884,Event,ADDED,eval-sanitize-30-r3-045-p7nlv.18d4f83eca0ded40,"reason=FailedScheduling count=None msg=0/6 nodes are available: 6 node(s) had untolerated taint(s). no new claims to deallocate, preemption: 0/6 nodes are available: 6 Preemption is not helpful for scheduling."
0.6887,Event,ADDED,eval-sanitize-30-r3-045-p7nlv.18d4f8402bb0ddf5,reason=Scheduled count=None msg=Successfully assigned compute/eval-sanitize-30-r3-045-p7nlv to kind-worker4
0.6889,Event,ADDED,eval-sanitize-30-r3-045-p7nlv.18d4f84044e3296f,"reason=Pulled count=1 msg=Container image ""busybox:musl"" already present on machine"
0.6891,Event,ADDED,eval-sanitize-30-r3-045-p7nlv.18d4f840470a7ecd,reason=Created count=1 msg=Created container: task
0.6893,Event,ADDED,eval-sanitize-30-r3-045-p7nlv.18d4f84049fc5ac9,reason=Started count=1 msg=Started container task
0.6896,Event,ADDED,eval-sanitize-30-r3-045.18d4f83eca04cad7,reason=SuccessfulCreate count=1 msg=Created pod: eval-sanitize-30-r3-045-p7nlv
0.6898,Event,ADDED,eval-sanitize-30-r3-045.18d4f84578d09ab3,reason=Completed count=1 msg=Job completed
0.69,Event,ADDED,eval-sanitize-30-r3-046-rhc88.18d4f83f057cca01,"reason=FailedScheduling count=None msg=0/6 nodes are available: 6 node(s) had untolerated taint(s). no new claims to deallocate, preemption: 0/6 nodes are available: 6 Preemption is not helpful for scheduling."
0.6905,Event,ADDED,eval-sanitize-30-r3-046-rhc88.18d4f8402c115b0a,reason=Scheduled count=None msg=Successfully assigned compute/eval-sanitize-30-r3-046-rhc88 to kind-worker4
0.6909,Event,ADDED,eval-sanitize-30-r3-046-rhc88.18d4f840470b024a,"reason=Pulled count=1 msg=Container image ""busybox:musl"" already present on machine"
0.6912,Event,ADDED,eval-sanitize-30-r3-046-rhc88.18d4f84048db3804,reason=Created count=1 msg=Created container: task
0.6915,Event,ADDED,eval-sanitize-30-r3-046-rhc88.18d4f8404ba8172c,reason=Started count=1 msg=Started container task
0.6918,Event,ADDED,eval-sanitize-30-r3-046.18d4f83f057848ae,reason=SuccessfulCreate count=1 msg=Created pod: eval-sanitize-30-r3-046-rhc88
0.692,Event,ADDED,eval-sanitize-30-r3-046.18d4f847b2a10701,reason=Completed count=1 msg=Job completed
0.6922,Event,ADDED,eval-sanitize-30-r3-047-5mxdj.18d4f83f40cff3fa,"reason=FailedScheduling count=None msg=0/6 nodes are available: 6 node(s) had untolerated taint(s). no new claims to deallocate, preemption: 0/6 nodes are available: 6 Preemption is not helpful for scheduling."
0.6926,Event,ADDED,eval-sanitize-30-r3-047-5mxdj.18d4f8402d48d4a2,reason=Scheduled count=None msg=Successfully assigned compute/eval-sanitize-30-r3-047-5mxdj to kind-worker4
0.6928,Event,ADDED,eval-sanitize-30-r3-047-5mxdj.18d4f84048119a26,"reason=Pulled count=1 msg=Container image ""busybox:musl"" already present on machine"
0.693,Event,ADDED,eval-sanitize-30-r3-047-5mxdj.18d4f84049f6012f,reason=Created count=1 msg=Created container: task
0.6934,Event,ADDED,eval-sanitize-30-r3-047-5mxdj.18d4f8404ca31109,reason=Started count=1 msg=Started container task
0.6938,Event,ADDED,eval-sanitize-30-r3-047.18d4f83f40bef18b,reason=SuccessfulCreate count=1 msg=Created pod: eval-sanitize-30-r3-047-5mxdj
0.694,Event,ADDED,eval-sanitize-30-r3-047.18d4f847c475c41c,reason=Completed count=1 msg=Job completed
0.6941,Event,ADDED,eval-sanitize-30-r3-048-d96gz.18d4f83f7de06129,"reason=FailedScheduling count=None msg=0/6 nodes are available: 6 node(s) had untolerated taint(s). no new claims to deallocate, preemption: 0/6 nodes are available: 6 Preemption is not helpful for scheduling."
0.6944,Event,ADDED,eval-sanitize-30-r3-048-d96gz.18d4f8403295ad73,"reason=FailedScheduling count=None msg=0/6 nodes are available: 1 c_wall violated: 1 conflicting context pair(s) with node memory, 1 c_wall violated: 3 conflicting context pair(s) with node memory, 4 node(s) had untolerated taint(s). no new claims to deallocate, preemption: 0/6 nodes are available: 2 No preemption victims found for incoming pod, 4 Preemption is not helpful for scheduling."
0.6945,Event,ADDED,eval-sanitize-30-r3-048-d96gz.18d4f8407b81b840,reason=Scheduled count=None msg=Successfully assigned compute/eval-sanitize-30-r3-048-d96gz to kind-worker5
0.6947,Event,ADDED,eval-sanitize-30-r3-048-d96gz.18d4f840963b538a,"reason=Pulled count=1 msg=Container image ""busybox:musl"" already present on machine"
0.6949,Event,ADDED,eval-sanitize-30-r3-048-d96gz.18d4f8409804004e,reason=Created count=1 msg=Created container: task
0.6951,Event,ADDED,eval-sanitize-30-r3-048-d96gz.18d4f8409fa3c7ea,reason=Started count=1 msg=Started container task
0.6953,Event,ADDED,eval-sanitize-30-r3-048.18d4f83f7dd9e5f6,reason=SuccessfulCreate count=1 msg=Created pod: eval-sanitize-30-r3-048-d96gz
0.6955,Event,ADDED,eval-sanitize-30-r3-048.18d4f847f426db2f,reason=Completed count=1 msg=Job completed
0.6959,Event,ADDED,eval-sanitize-30-r3-049-vgzkf.18d4f83fb8a76bc6,"reason=FailedScheduling count=None msg=0/6 nodes are available: 6 node(s) had untolerated taint(s). no new claims to deallocate, preemption: 0/6 nodes are available: 6 Preemption is not helpful for scheduling."
0.6963,Event,ADDED,eval-sanitize-30-r3-049-vgzkf.18d4f8403a49bfa0,reason=Scheduled count=None msg=Successfully assigned compute/eval-sanitize-30-r3-049-vgzkf to kind-worker3
0.6966,Event,ADDED,eval-sanitize-30-r3-049-vgzkf.18d4f84057d99b56,"reason=Pulled count=1 msg=Container image ""busybox:musl"" already present on machine"
0.697,Event,ADDED,eval-sanitize-30-r3-049-vgzkf.18d4f84059c85308,reason=Created count=1 msg=Created container: task
0.6974,Event,ADDED,eval-sanitize-30-r3-049-vgzkf.18d4f8405c21b8e8,reason=Started count=1 msg=Started container task
0.6978,Event,ADDED,eval-sanitize-30-r3-049.18d4f83fb8a58e1b,reason=SuccessfulCreate count=1 msg=Created pod: eval-sanitize-30-r3-049-vgzkf
0.698,Event,ADDED,eval-sanitize-30-r3-049.18d4f84776f3689c,reason=Completed count=1 msg=Job completed
0.6982,Event,ADDED,eval-sanitize-30-r3-050-krpks.18d4f83ff3da2c14,"reason=FailedScheduling count=None msg=0/6 nodes are available: 6 node(s) had untolerated taint(s). no new claims to deallocate, preemption: 0/6 nodes are available: 6 Preemption is not helpful for scheduling."
0.6985,Event,ADDED,eval-sanitize-30-r3-050-krpks.18d4f8403f52b105,reason=Scheduled count=None msg=Successfully assigned compute/eval-sanitize-30-r3-050-krpks to kind-worker3
0.6987,Event,ADDED,eval-sanitize-30-r3-050-krpks.18d4f8405acee148,"reason=Pulled count=1 msg=Container image ""busybox:musl"" already present on machine"
0.6988,Event,ADDED,eval-sanitize-30-r3-050-krpks.18d4f8405c1856fe,reason=Created count=1 msg=Created container: task
0.6991,Event,ADDED,eval-sanitize-30-r3-050-krpks.18d4f84060f27590,reason=Started count=1 msg=Started container task
0.6994,Event,ADDED,eval-sanitize-30-r3-050.18d4f83ff3d60b54,reason=SuccessfulCreate count=1 msg=Created pod: eval-sanitize-30-r3-050-krpks
0.6997,Event,ADDED,eval-sanitize-30-r3-050.18d4f8476b0f66a1,reason=Completed count=1 msg=Job completed
0.6999,Event,ADDED,eval-sanitize-30-r3-051-7p78w.18d4f84034cefd54,reason=Scheduled count=None msg=Successfully assigned compute/eval-sanitize-30-r3-051-7p78w to kind-worker3
0.7003,Event,ADDED,eval-sanitize-30-r3-051-7p78w.18d4f84051d0e91d,"reason=Pulled count=1 msg=Container image ""busybox:musl"" already present on machine"
0.7005,Event,ADDED,eval-sanitize-30-r3-051-7p78w.18d4f8405468686b,reason=Created count=1 msg=Created container: task
0.7007,Event,ADDED,eval-sanitize-30-r3-051-7p78w.18d4f840586782bc,reason=Started count=1 msg=Started container task
0.701,Event,ADDED,eval-sanitize-30-r3-051.18d4f8403030e78d,reason=SuccessfulCreate count=1 msg=Created pod: eval-sanitize-30-r3-051-7p78w
0.7013,Event,ADDED,eval-sanitize-30-r3-051.18d4f8477cf49bf3,reason=Completed count=1 msg=Job completed
0.7015,Event,ADDED,eval-sanitize-30-r3-052-j4d6m.18d4f84070eeae75,reason=Scheduled count=None msg=Successfully assigned compute/eval-sanitize-30-r3-052-j4d6m to kind-worker3
0.7018,Event,ADDED,eval-sanitize-30-r3-052-j4d6m.18d4f8408da7918f,"reason=Pulled count=1 msg=Container image ""busybox:musl"" already present on machine"
0.7022,Event,ADDED,eval-sanitize-30-r3-052-j4d6m.18d4f8408fbce69b,reason=Created count=1 msg=Created container: task
0.7026,Event,ADDED,eval-sanitize-30-r3-052-j4d6m.18d4f84092cc8b46,reason=Started count=1 msg=Started container task
0.703,Event,ADDED,eval-sanitize-30-r3-052.18d4f8406df2fe37,reason=SuccessfulCreate count=1 msg=Created pod: eval-sanitize-30-r3-052-j4d6m
0.7032,Event,ADDED,eval-sanitize-30-r3-052.18d4f847d99311a8,reason=Completed count=1 msg=Job completed
0.7035,Event,ADDED,eval-sanitize-30-r3-053-j2p6t.18d4f840b2666c09,reason=Scheduled count=None msg=Successfully assigned compute/eval-sanitize-30-r3-053-j2p6t to kind-worker5
0.7038,Event,ADDED,eval-sanitize-30-r3-053-j2p6t.18d4f840d579599b,"reason=Pulled count=1 msg=Container image ""busybox:musl"" already present on machine"
0.7041,Event,ADDED,eval-sanitize-30-r3-053-j2p6t.18d4f840d77a7319,reason=Created count=1 msg=Created container: task
0.7045,Event,ADDED,eval-sanitize-30-r3-053-j2p6t.18d4f840dfacc79c,reason=Started count=1 msg=Started container task
0.7048,Event,ADDED,eval-sanitize-30-r3-053.18d4f840aac1e9a2,reason=SuccessfulCreate count=1 msg=Created pod: eval-sanitize-30-r3-053-j2p6t
0.705,Event,ADDED,eval-sanitize-30-r3-053.18d4f84826c717ba,reason=Completed count=1 msg=Job completed
0.7052,Event,ADDED,eval-sanitize-30-r3-054-qcvzn.18d4f840ea054577,reason=Scheduled count=None msg=Successfully assigned compute/eval-sanitize-30-r3-054-qcvzn to kind-worker
0.7056,Event,ADDED,eval-sanitize-30-r3-054-qcvzn.18d4f84108e8cd55,"reason=Pulled count=1 msg=Container image ""busybox:musl"" already present on machine"
0.7059,Event,ADDED,eval-sanitize-30-r3-054-qcvzn.18d4f8410a03f0fe,reason=Created count=1 msg=Created container: task
0.7061,Event,ADDED,eval-sanitize-30-r3-054-qcvzn.18d4f84114a9926b,reason=Started count=1 msg=Started container task
0.7063,Event,ADDED,eval-sanitize-30-r3-054.18d4f840e2762c6d,reason=SuccessfulCreate count=1 msg=Created pod: eval-sanitize-30-r3-054-qcvzn
0.7067,Event,ADDED,eval-sanitize-30-r3-054.18d4f848361722cf,reason=Completed count=1 msg=Job completed
0.7072,Event,ADDED,eval-sanitize-30-r3-055-5thbc.18d4f84127a58ce0,reason=Scheduled count=None msg=Successfully assigned compute/eval-sanitize-30-r3-055-5thbc to kind-worker
0.7078,Event,ADDED,eval-sanitize-30-r3-055-5thbc.18d4f84159a279bf,"reason=Pulled count=1 msg=Container image ""busybox:musl"" already present on machine"
0.7085,Event,ADDED,eval-sanitize-30-r3-055-5thbc.18d4f8415b18f427,reason=Created count=1 msg=Created container: task
0.7093,Event,ADDED,eval-sanitize-30-r3-055-5thbc.18d4f8416bbfd1e0,reason=Started count=1 msg=Started container task
0.7099,Event,ADDED,eval-sanitize-30-r3-055.18d4f8411f061de2,reason=SuccessfulCreate count=1 msg=Created pod: eval-sanitize-30-r3-055-5thbc
0.7101,Event,ADDED,eval-sanitize-30-r3-055.18d4f848478071d0,reason=Completed count=1 msg=Job completed
0.7104,Event,ADDED,eval-sanitize-30-r3-056-vcbqr.18d4f8416bb3cbce,reason=Scheduled count=None msg=Successfully assigned compute/eval-sanitize-30-r3-056-vcbqr to kind-worker5
0.7106,Event,ADDED,eval-sanitize-30-r3-056-vcbqr.18d4f841899cb247,"reason=Pulled count=1 msg=Container image ""busybox:musl"" already present on machine"
0.7108,Event,ADDED,eval-sanitize-30-r3-056-vcbqr.18d4f8418acaeebd,reason=Created count=1 msg=Created container: task
0.711,Event,ADDED,eval-sanitize-30-r3-056-vcbqr.18d4f84190162b5e,reason=Started count=1 msg=Started container task
0.7112,Event,ADDED,eval-sanitize-30-r3-056.18d4f8415b4e2a69,reason=SuccessfulCreate count=1 msg=Created pod: eval-sanitize-30-r3-056-vcbqr
0.7114,Event,ADDED,eval-sanitize-30-r3-056.18d4f8485c4d0d40,reason=Completed count=1 msg=Job completed
0.7115,Event,ADDED,eval-sanitize-30-r3-057-h6z6z.18d4f841a18e7aa1,reason=Scheduled count=None msg=Successfully assigned compute/eval-sanitize-30-r3-057-h6z6z to kind-worker5
0.7117,Event,ADDED,eval-sanitize-30-r3-057-h6z6z.18d4f841c1848e6d,"reason=Pulled count=1 msg=Container image ""busybox:musl"" already present on machine"
0.7119,Event,ADDED,eval-sanitize-30-r3-057-h6z6z.18d4f841c2db665d,reason=Created count=1 msg=Created container: task
0.7121,Event,ADDED,eval-sanitize-30-r3-057-h6z6z.18d4f841cab8c996,reason=Started count=1 msg=Started container task
0.7123,Event,ADDED,eval-sanitize-30-r3-057.18d4f84198d88c52,reason=SuccessfulCreate count=1 msg=Created pod: eval-sanitize-30-r3-057-h6z6z
0.7125,Event,ADDED,eval-sanitize-30-r3-057.18d4f8487181b24b,reason=Completed count=1 msg=Job completed
0.7126,Event,ADDED,eval-sanitize-30-r3-058-slqnj.18d4f841dd86e9cb,reason=Scheduled count=None msg=Successfully assigned compute/eval-sanitize-30-r3-058-slqnj to kind-worker2
0.7128,Event,ADDED,eval-sanitize-30-r3-058-slqnj.18d4f842001ba55b,"reason=Pulled count=1 msg=Container image ""busybox:musl"" already present on machine"
0.7129,Event,ADDED,eval-sanitize-30-r3-058-slqnj.18d4f842016b8795,reason=Created count=1 msg=Created container: task
0.7131,Event,ADDED,eval-sanitize-30-r3-058-slqnj.18d4f84206321c60,reason=Started count=1 msg=Started container task
0.7134,Event,ADDED,eval-sanitize-30-r3-058.18d4f841d509455f,reason=SuccessfulCreate count=1 msg=Created pod: eval-sanitize-30-r3-058-slqnj
0.7137,Event,ADDED,eval-sanitize-30-r3-058.18d4f848890300e7,reason=Completed count=1 msg=Job completed
0.714,Event,ADDED,eval-sanitize-30-r3-059-hwtbr.18d4f84211468762,reason=Scheduled count=None msg=Successfully assigned compute/eval-sanitize-30-r3-059-hwtbr to kind-worker5
0.7145,Event,ADDED,eval-sanitize-30-r3-059-hwtbr.18d4f84230c7119e,"reason=Pulled count=1 msg=Container image ""busybox:musl"" already present on machine"
0.7148,Event,ADDED,eval-sanitize-30-r3-059-hwtbr.18d4f84231e8416a,reason=Created count=1 msg=Created container: task
0.715,Event,ADDED,eval-sanitize-30-r3-059-hwtbr.18d4f84236c81b96,reason=Started count=1 msg=Started container task
0.7154,Event,ADDED,eval-sanitize-30-r3-059.18d4f8420c6b5878,reason=SuccessfulCreate count=1 msg=Created pod: eval-sanitize-30-r3-059-hwtbr
0.7155,Event,ADDED,eval-sanitize-30-r3-059.18d4f84891e70822,reason=Completed count=1 msg=Job completed
0.7158,Event,ADDED,eval-sanitize-30-r3-060-rwbg2.18d4f84251a7f5d6,reason=Scheduled count=None msg=Successfully assigned compute/eval-sanitize-30-r3-060-rwbg2 to kind-worker2
0.716,Event,ADDED,eval-sanitize-30-r3-060-rwbg2.18d4f8426ed78332,"reason=Pulled count=1 msg=Container image ""busybox:musl"" already present on machine"
0.7166,Event,ADDED,eval-sanitize-30-r3-060-rwbg2.18d4f84270176c72,reason=Created count=1 msg=Created container: task
0.7169,Event,ADDED,eval-sanitize-30-r3-060-rwbg2.18d4f84278d35d79,reason=Started count=1 msg=Started container task
0.7172,Event,ADDED,eval-sanitize-30-r3-060.18d4f84248b4db84,reason=SuccessfulCreate count=1 msg=Created pod: eval-sanitize-30-r3-060-rwbg2
0.7175,Event,ADDED,eval-sanitize-30-r3-060.18d4f848a6cdc3eb,reason=Completed count=1 msg=Job completed
0.7178,Event,ADDED,eval-sanitize-30-r3-061-gpzg5.18d4f842942bf7e2,reason=Scheduled count=None msg=Successfully assigned compute/eval-sanitize-30-r3-061-gpzg5 to kind-worker5
0.7181,Event,ADDED,eval-sanitize-30-r3-061-gpzg5.18d4f842ada24289,"reason=Pulled count=1 msg=Container image ""busybox:musl"" already present on machine"
0.7185,Event,ADDED,eval-sanitize-30-r3-061-gpzg5.18d4f842aef1c5bc,reason=Created count=1 msg=Created container: task
